{
  "version": 8,
  "blockIdVersion": 11,
  "anchorX": 0,
  "anchorY": 0,
  "anchorZ": 0,
  "blocks": [
    {
      "x": -2,
      "y": 6,
      "z": -5,
      "name": "Rock_Ice_Permafrost"
    },
    {
      "x": -2,
      "y": 7,
      "z": -5,
      "name": "Rock_Ice_Permafrost"
    },
    {
      "x": -2,
      "y": 8,
      "z": -5,
      "name": "Rock_Ice_Permafrost"
    },
    {
      "x": -2,
      "y": 4,
      "z": -4,
      "name": "Rock_Ice_Permafrost"
    },
    {
      "x": -2,
      "y": 5,
      "z": -4,
      "name": "Rock_Ice_Permafrost"
    },
    {
      "x": -2,
      "y": 6,
      "z": -4,
      "name": "Rock_Ice_Permafrost"
    },
    {
      "x": -2,
      "y": 7,
      "z": -4,
      "name": "Rock_Ice_Permafrost"
    },
    {
      "x": -2,
      "y": 8,
      "z": -4,
      "name": "Rock_Ice_Permafrost"
    },
    {
      "x": -2,
      "y": 4,
      "z": -3,
      "name": "Rock_Ice_Permafrost"
    },
    {
      "x": -2,
      "y": 5,
      "z": -3,
      "name": "Rock_Ice_Permafrost"
    },
    {
      "x": -2,
      "y": 6,
      "z": -3,
      "name": "Rock_Ice_Permafrost"
    },
    {
      "x": -2,
      "y": 7,
      "z": -3,
      "name": "Rock_Ice_Permafrost"
    },
    {
      "x": -2,
      "y": 8,
      "z": -3,
      "name": "Rock_Ice_Permafrost"
    },
    {
      "x": -2,
      "y": 2,
      "z": -2,
      "name": "Rock_Ice_Permafrost"
    },
    {
      "x": -2,
      "y": 3,
      "z": -2,
      "name": "Rock_Ice_Permafrost"
    },
    {
      "x": -2,
      "y": 4,
      "z": -2,
      "name": "Rock_Ice_Permafrost"
    },
    {
      "x": -2,
      "y": 5,
      "z": -2,
      "name": "Rock_Ice_Permafrost"
    },
    {
      "x": -2,
      "y": 6,
      "z": -2,
      "name": "Rock_Ice_Permafrost"
    },
    {
      "x": -2,
      "y": 2,
      "z": -1,
      "name": "Rock_Ice_Permafrost"
    },
    {
      "x": -2,
      "y": 3,
      "z": -1,
      "name": "Rock_Ice_Permafrost"
    },
    {
      "x": -2,
      "y": 4,
      "z": -1,
      "name": "Rock_Ice_Permafrost"
    },
    {
      "x": -2,
      "y": 1,
      "z": 0,
      "name": "Rock_Ice_Permafrost"
    },
    {
      "x": -2,
      "y": 2,
      "z": 0,
      "name": "Rock_Ice_Permafrost"
    },
    {
      "x": -2,
      "y": 3,
      "z": 0,
      "name": "Rock_Ice_Permafrost"
    },
    {
      "x": -2,
      "y": 4,
      "z": 0,
      "name": "Rock_Ice_Permafrost"
    },
    {
      "x": -2,
      "y": -6,
      "z": 1,
      "name": "Rock_Ice_Permafrost"
    },
    {
      "x": -2,
      "y": -5,
      "z": 1,
      "name": "Rock_Ice_Permafrost"
    },
    {
      "x": -2,
      "y": -4,
      "z": 1,
      "name": "Rock_Ice_Permafrost"
    },
    {
      "x": -2,
      "y": -3,
      "z": 1,
      "name": "Rock_Ice_Permafrost"
    },
    {
      "x": -2,
      "y": -2,
      "z": 1,
      "name": "Rock_Ice_Permafrost"
    },
    {
      "x": -2,
      "y": -1,
      "z": 1,
      "name": "Rock_Ice_Permafrost"
    },
    {
      "x": -2,
      "y": 0,
      "z": 1,
      "name": "Rock_Ice_Permafrost"
    },
    {
      "x": -2,
      "y": 1,
      "z": 1,
      "name": "Rock_Ice_Permafrost"
    },
    {
      "x": -2,
      "y": 2,
      "z": 1,
      "name": "Rock_Ice_Permafrost"
    },
    {
      "x": -2,
      "y": 3,
      "z": 1,
      "name": "Rock_Ice_Permafrost"
    },
    {
      "x": -2,
      "y": -6,
      "z": 2,
      "name": "Rock_Ice_Permafrost"
    },
    {
      "x": -2,
      "y": -5,
      "z": 2,
      "name": "Rock_Ice_Permafrost"
    },
    {
      "x": -2,
      "y": -4,
      "z": 2,
      "name": "Rock_Ice_Permafrost"
    },
    {
      "x": -2,
      "y": -3,
      "z": 2,
      "name": "Rock_Ice_Permafrost"
    },
    {
      "x": -2,
      "y": -2,
      "z": 2,
      "name": "Rock_Ice_Permafrost"
    },
    {
      "x": -2,
      "y": -1,
      "z": 2,
      "name": "Rock_Ice_Permafrost"
    },
    {
      "x": -2,
      "y": 0,
      "z": 2,
      "name": "Rock_Ice_Permafrost"
    },
    {
      "x": -2,
      "y": 1,
      "z": 2,
      "name": "Rock_Ice_Permafrost"
    },
    {
      "x": -2,
      "y": 2,
      "z": 2,
      "name": "Rock_Ice_Permafrost"
    },
    {
      "x": -1,
      "y": 10,
      "z": -6,
      "name": "Rock_Ice_Icicles",
      "rotation": 8
    },
    {
      "x": -1,
      "y": 11,
      "z": -6,
      "name": "Rock_Ice_Permafrost",
      "rotation": 3
    },
    {
      "x": -1,
      "y": 12,
      "z": -6,
      "name": "Rock_Ice_Permafrost",
      "rotation": 3
    },
    {
      "x": -1,
      "y": 13,
      "z": -6,
      "name": "Rock_Ice_Permafrost",
      "rotation": 3
    },
    {
      "x": -1,
      "y": 14,
      "z": -6,
      "name": "Rock_Ice_Permafrost",
      "rotation": 3
    },
    {
      "x": -1,
      "y": 3,
      "z": -5,
      "name": "Rock_Ice_Icicles",
      "rotation": 33
    },
    {
      "x": -1,
      "y": 4,
      "z": -5,
      "name": "Rock_Ice_Permafrost",
      "rotation": 3
    },
    {
      "x": -1,
      "y": 5,
      "z": -5,
      "name": "Rock_Ice_Permafrost",
      "rotation": 3
    },
    {
      "x": -1,
      "y": 6,
      "z": -5,
      "name": "Rock_Ice_Permafrost"
    },
    {
      "x": -1,
      "y": 7,
      "z": -5,
      "name": "Rock_Ice_Permafrost"
    },
    {
      "x": -1,
      "y": 8,
      "z": -5,
      "name": "Rock_Ice_Permafrost"
    },
    {
      "x": -1,
      "y": 9,
      "z": -5,
      "name": "Rock_Ice_Permafrost",
      "rotation": 3
    },
    {
      "x": -1,
      "y": 10,
      "z": -5,
      "name": "Rock_Ice_Permafrost",
      "rotation": 3
    },
    {
      "x": -1,
      "y": 11,
      "z": -5,
      "name": "Rock_Ice_Permafrost",
      "rotation": 3
    },
    {
      "x": -1,
      "y": 12,
      "z": -5,
      "name": "Rock_Ice_Permafrost",
      "rotation": 3
    },
    {
      "x": -1,
      "y": 13,
      "z": -5,
      "name": "Rock_Ice_Permafrost",
      "rotation": 3
    },
    {
      "x": -1,
      "y": 14,
      "z": -5,
      "name": "Fullmetal_Blue_Crystal_Lamp"
    },
    {
      "x": -1,
      "y": 2,
      "z": -4,
      "name": "Rock_Ice_Permafrost",
      "rotation": 3
    },
    {
      "x": -1,
      "y": 3,
      "z": -4,
      "name": "Rock_Ice_Permafrost",
      "rotation": 3
    },
    {
      "x": -1,
      "y": 4,
      "z": -4,
      "name": "Rock_Ice_Permafrost"
    },
    {
      "x": -1,
      "y": 5,
      "z": -4,
      "name": "Rock_Ice_Permafrost"
    },
    {
      "x": -1,
      "y": 6,
      "z": -4,
      "name": "Rock_Ice_Permafrost"
    },
    {
      "x": -1,
      "y": 7,
      "z": -4,
      "name": "Rock_Ice_Permafrost"
    },
    {
      "x": -1,
      "y": 8,
      "z": -4,
      "name": "Rock_Ice_Permafrost"
    },
    {
      "x": -1,
      "y": 9,
      "z": -4,
      "name": "Rock_Ice_Permafrost",
      "rotation": 3
    },
    {
      "x": -1,
      "y": 10,
      "z": -4,
      "name": "Rock_Ice_Permafrost",
      "rotation": 3
    },
    {
      "x": -1,
      "y": 11,
      "z": -4,
      "name": "Rock_Ice_Permafrost",
      "rotation": 3
    },
    {
      "x": -1,
      "y": 12,
      "z": -4,
      "name": "Rock_Ice_Permafrost",
      "rotation": 3
    },
    {
      "x": -1,
      "y": 1,
      "z": -3,
      "name": "Rock_Ice_Permafrost",
      "rotation": 3
    },
    {
      "x": -1,
      "y": 2,
      "z": -3,
      "name": "Rock_Ice_Permafrost",
      "rotation": 3
    },
    {
      "x": -1,
      "y": 3,
      "z": -3,
      "name": "Rock_Ice_Permafrost",
      "rotation": 3
    },
    {
      "x": -1,
      "y": 4,
      "z": -3,
      "name": "Rock_Ice_Permafrost"
    },
    {
      "x": -1,
      "y": 5,
      "z": -3,
      "name": "Rock_Ice_Permafrost"
    },
    {
      "x": -1,
      "y": 6,
      "z": -3,
      "name": "Rock_Ice_Permafrost"
    },
    {
      "x": -1,
      "y": 7,
      "z": -3,
      "name": "Rock_Ice_Permafrost"
    },
    {
      "x": -1,
      "y": 8,
      "z": -3,
      "name": "Rock_Ice_Permafrost"
    },
    {
      "x": -1,
      "y": 9,
      "z": -3,
      "name": "Rock_Ice_Permafrost",
      "rotation": 3
    },
    {
      "x": -1,
      "y": 10,
      "z": -3,
      "name": "Rock_Ice_Permafrost",
      "rotation": 3
    },
    {
      "x": -1,
      "y": -1,
      "z": -2,
      "name": "Rock_Ice_Permafrost"
    },
    {
      "x": -1,
      "y": 0,
      "z": -2,
      "name": "Rock_Ice_Permafrost",
      "rotation": 3
    },
    {
      "x": -1,
      "y": 1,
      "z": -2,
      "name": "Rock_Ice_Permafrost",
      "rotation": 3
    },
    {
      "x": -1,
      "y": 2,
      "z": -2,
      "name": "Rock_Ice_Permafrost"
    },
    {
      "x": -1,
      "y": 3,
      "z": -2,
      "name": "Rock_Ice_Permafrost"
    },
    {
      "x": -1,
      "y": 4,
      "z": -2,
      "name": "Rock_Ice_Permafrost"
    },
    {
      "x": -1,
      "y": 5,
      "z": -2,
      "name": "Rock_Ice_Permafrost"
    },
    {
      "x": -1,
      "y": 6,
      "z": -2,
      "name": "Rock_Ice_Permafrost"
    },
    {
      "x": -1,
      "y": 7,
      "z": -2,
      "name": "Rock_Ice_Permafrost",
      "rotation": 3
    },
    {
      "x": -1,
      "y": 8,
      "z": -2,
      "name": "Rock_Ice_Permafrost",
      "rotation": 3
    },
    {
      "x": -1,
      "y": -4,
      "z": -1,
      "name": "Rock_Ice_Permafrost"
    },
    {
      "x": -1,
      "y": -3,
      "z": -1,
      "name": "Rock_Ice_Permafrost"
    },
    {
      "x": -1,
      "y": -2,
      "z": -1,
      "name": "Rock_Ice_Permafrost"
    },
    {
      "x": -1,
      "y": -1,
      "z": -1,
      "name": "Rock_Ice_Permafrost"
    },
    {
      "x": -1,
      "y": 0,
      "z": -1,
      "name": "Rock_Ice_Permafrost",
      "rotation": 3
    },
    {
      "x": -1,
      "y": 1,
      "z": -1,
      "name": "Rock_Ice_Permafrost",
      "rotation": 3
    },
    {
      "x": -1,
      "y": 2,
      "z": -1,
      "name": "Rock_Ice_Permafrost"
    },
    {
      "x": -1,
      "y": 3,
      "z": -1,
      "name": "Rock_Ice_Permafrost"
    },
    {
      "x": -1,
      "y": 4,
      "z": -1,
      "name": "Rock_Ice_Permafrost"
    },
    {
      "x": -1,
      "y": 5,
      "z": -1,
      "name": "Rock_Ice_Permafrost",
      "rotation": 3
    },
    {
      "x": -1,
      "y": -9,
      "z": 0,
      "name": "Rock_Ice_Permafrost"
    },
    {
      "x": -1,
      "y": -8,
      "z": 0,
      "name": "Rock_Ice_Permafrost"
    },
    {
      "x": -1,
      "y": -7,
      "z": 0,
      "name": "Rock_Ice_Permafrost"
    },
    {
      "x": -1,
      "y": -6,
      "z": 0,
      "name": "Rock_Ice_Permafrost"
    },
    {
      "x": -1,
      "y": -5,
      "z": 0,
      "name": "Rock_Ice_Permafrost"
    },
    {
      "x": -1,
      "y": -4,
      "z": 0,
      "name": "Rock_Ice_Permafrost"
    },
    {
      "x": -1,
      "y": -3,
      "z": 0,
      "name": "Rock_Ice_Permafrost"
    },
    {
      "x": -1,
      "y": -2,
      "z": 0,
      "name": "Rock_Ice_Permafrost"
    },
    {
      "x": -1,
      "y": -1,
      "z": 0,
      "name": "Rock_Ice_Permafrost"
    },
    {
      "x": -1,
      "y": 0,
      "z": 0,
      "name": "Rock_Ice_Permafrost",
      "rotation": 3
    },
    {
      "x": -1,
      "y": 1,
      "z": 0,
      "name": "Rock_Ice_Permafrost"
    },
    {
      "x": -1,
      "y": 2,
      "z": 0,
      "name": "Rock_Ice_Permafrost"
    },
    {
      "x": -1,
      "y": 3,
      "z": 0,
      "name": "Rock_Ice_Permafrost"
    },
    {
      "x": -1,
      "y": 4,
      "z": 0,
      "name": "Rock_Ice_Permafrost"
    },
    {
      "x": -1,
      "y": -6,
      "z": 1,
      "name": "Rock_Ice_Permafrost"
    },
    {
      "x": -1,
      "y": -5,
      "z": 1,
      "name": "Rock_Ice_Permafrost"
    },
    {
      "x": -1,
      "y": -4,
      "z": 1,
      "name": "Rock_Ice_Permafrost"
    },
    {
      "x": -1,
      "y": -3,
      "z": 1,
      "name": "Rock_Ice_Permafrost"
    },
    {
      "x": -1,
      "y": -2,
      "z": 1,
      "name": "Rock_Ice_Permafrost"
    },
    {
      "x": -1,
      "y": -1,
      "z": 1,
      "name": "Rock_Ice_Permafrost"
    },
    {
      "x": -1,
      "y": 0,
      "z": 1,
      "name": "Rock_Ice_Permafrost",
      "rotation": 3
    },
    {
      "x": -1,
      "y": 1,
      "z": 1,
      "name": "Rock_Ice_Permafrost"
    },
    {
      "x": -1,
      "y": 2,
      "z": 1,
      "name": "Rock_Ice_Permafrost"
    },
    {
      "x": -1,
      "y": 3,
      "z": 1,
      "name": "Rock_Ice_Permafrost"
    },
    {
      "x": -1,
      "y": -6,
      "z": 2,
      "name": "Rock_Ice_Permafrost"
    },
    {
      "x": -1,
      "y": -5,
      "z": 2,
      "name": "Rock_Ice_Permafrost"
    },
    {
      "x": -1,
      "y": -4,
      "z": 2,
      "name": "Rock_Ice_Permafrost"
    },
    {
      "x": -1,
      "y": -3,
      "z": 2,
      "name": "Rock_Ice_Permafrost"
    },
    {
      "x": -1,
      "y": -2,
      "z": 2,
      "name": "Rock_Ice_Permafrost"
    },
    {
      "x": -1,
      "y": -1,
      "z": 2,
      "name": "Rock_Ice_Permafrost"
    },
    {
      "x": -1,
      "y": 0,
      "z": 2,
      "name": "Rock_Ice_Permafrost"
    },
    {
      "x": -1,
      "y": 1,
      "z": 2,
      "name": "Rock_Ice_Permafrost"
    },
    {
      "x": -1,
      "y": 2,
      "z": 2,
      "name": "Rock_Ice_Permafrost"
    },
    {
      "x": -1,
      "y": -1,
      "z": 3,
      "name": "Rock_Ice_Permafrost"
    },
    {
      "x": -1,
      "y": 0,
      "z": 3,
      "name": "Rock_Ice_Permafrost"
    },
    {
      "x": -1,
      "y": 1,
      "z": 3,
      "name": "Rock_Ice_Permafrost"
    },
    {
      "x": 0,
      "y": 9,
      "z": -7,
      "name": "Rock_Ice_Icicles",
      "rotation": 8
    },
    {
      "x": 0,
      "y": 10,
      "z": -7,
      "name": "Rock_Ice_Permafrost"
    },
    {
      "x": 0,
      "y": 11,
      "z": -7,
      "name": "Rock_Ice_Permafrost"
    },
    {
      "x": 0,
      "y": 12,
      "z": -7,
      "name": "Rock_Ice_Permafrost"
    },
    {
      "x": 0,
      "y": 13,
      "z": -7,
      "name": "Rock_Ice_Permafrost"
    },
    {
      "x": 0,
      "y": 14,
      "z": -7,
      "name": "Rock_Ice_Permafrost"
    },
    {
      "x": 0,
      "y": 15,
      "z": -7,
      "name": "Rock_Ice_Permafrost"
    },
    {
      "x": 0,
      "y": 6,
      "z": -6,
      "name": "Rock_Ice_Permafrost",
      "rotation": 3
    },
    {
      "x": 0,
      "y": 7,
      "z": -6,
      "name": "Rock_Ice_Permafrost",
      "rotation": 3
    },
    {
      "x": 0,
      "y": 8,
      "z": -6,
      "name": "Rock_Ice_Permafrost",
      "rotation": 3
    },
    {
      "x": 0,
      "y": 9,
      "z": -6,
      "name": "Rock_Ice_Permafrost",
      "rotation": 3
    },
    {
      "x": 0,
      "y": 10,
      "z": -6,
      "name": "Rock_Ice_Permafrost",
      "rotation": 3
    },
    {
      "x": 0,
      "y": 11,
      "z": -6,
      "name": "Rock_Ice_Permafrost",
      "rotation": 3
    },
    {
      "x": 0,
      "y": 12,
      "z": -6,
      "name": "Rock_Ice_Permafrost",
      "rotation": 3
    },
    {
      "x": 0,
      "y": 13,
      "z": -6,
      "name": "Rock_Ice_Permafrost",
      "rotation": 3
    },
    {
      "x": 0,
      "y": 14,
      "z": -6,
      "name": "Rock_Ice_Permafrost",
      "rotation": 3
    },
    {
      "x": 0,
      "y": 15,
      "z": -6,
      "name": "Rock_Ice_Permafrost",
      "rotation": 3
    },
    {
      "x": 0,
      "y": 16,
      "z": -6,
      "name": "Rock_Ice_Permafrost",
      "rotation": 3
    },
    {
      "x": 0,
      "y": 17,
      "z": -6,
      "name": "Fullmetal_Blue_Crystal_Lamp"
    },
    {
      "x": 0,
      "y": 3,
      "z": -5,
      "name": "Rock_Ice_Permafrost",
      "rotation": 3
    },
    {
      "x": 0,
      "y": 4,
      "z": -5,
      "name": "Rock_Ice_Permafrost",
      "rotation": 3
    },
    {
      "x": 0,
      "y": 5,
      "z": -5,
      "name": "Rock_Ice_Permafrost",
      "rotation": 3
    },
    {
      "x": 0,
      "y": 6,
      "z": -5,
      "name": "Rock_Ice_Permafrost",
      "rotation": 3
    },
    {
      "x": 0,
      "y": 7,
      "z": -5,
      "name": "Rock_Ice_Permafrost",
      "rotation": 3
    },
    {
      "x": 0,
      "y": 8,
      "z": -5,
      "name": "Rock_Ice_Permafrost",
      "rotation": 3
    },
    {
      "x": 0,
      "y": 9,
      "z": -5,
      "name": "Rock_Ice_Permafrost",
      "rotation": 3
    },
    {
      "x": 0,
      "y": 10,
      "z": -5,
      "name": "Rock_Ice_Permafrost",
      "rotation": 3
    },
    {
      "x": 0,
      "y": 11,
      "z": -5,
      "name": "Rock_Ice_Permafrost",
      "rotation": 3
    },
    {
      "x": 0,
      "y": 12,
      "z": -5,
      "name": "Rock_Ice_Permafrost",
      "rotation": 3
    },
    {
      "x": 0,
      "y": 13,
      "z": -5,
      "name": "Rock_Ice_Permafrost",
      "rotation": 3
    },
    {
      "x": 0,
      "y": 14,
      "z": -5,
      "name": "Rock_Ice_Permafrost",
      "rotation": 3
    },
    {
      "x": 0,
      "y": 15,
      "z": -5,
      "name": "Rock_Ice_Permafrost",
      "rotation": 3
    },
    {
      "x": 0,
      "y": 16,
      "z": -5,
      "name": "Rock_Ice_Permafrost",
      "rotation": 3
    },
    {
      "x": 0,
      "y": 17,
      "z": -5,
      "name": "Rock_Ice_Permafrost",
      "rotation": 3
    },
    {
      "x": 0,
      "y": 18,
      "z": -5,
      "name": "Rock_Ice_Permafrost",
      "rotation": 3
    },
    {
      "x": 0,
      "y": 19,
      "z": -5,
      "name": "Fullmetal_White_Crystal_Lamp"
    },
    {
      "x": 0,
      "y": 2,
      "z": -4,
      "name": "Rock_Ice_Permafrost",
      "rotation": 3
    },
    {
      "x": 0,
      "y": 3,
      "z": -4,
      "name": "Rock_Ice_Permafrost",
      "rotation": 3
    },
    {
      "x": 0,
      "y": 4,
      "z": -4,
      "name": "Rock_Ice_Permafrost",
      "rotation": 3
    },
    {
      "x": 0,
      "y": 5,
      "z": -4,
      "name": "Rock_Ice_Permafrost",
      "rotation": 3
    },
    {
      "x": 0,
      "y": 6,
      "z": -4,
      "name": "Rock_Ice_Permafrost",
      "rotation": 3
    },
    {
      "x": 0,
      "y": 7,
      "z": -4,
      "name": "Rock_Ice_Permafrost",
      "rotation": 3
    },
    {
      "x": 0,
      "y": 8,
      "z": -4,
      "name": "Rock_Ice_Permafrost",
      "rotation": 3
    },
    {
      "x": 0,
      "y": 9,
      "z": -4,
      "name": "Rock_Ice_Permafrost",
      "rotation": 3
    },
    {
      "x": 0,
      "y": 10,
      "z": -4,
      "name": "Rock_Ice_Permafrost",
      "rotation": 3
    },
    {
      "x": 0,
      "y": 11,
      "z": -4,
      "name": "Rock_Ice_Permafrost",
      "rotation": 3
    },
    {
      "x": 0,
      "y": 12,
      "z": -4,
      "name": "Rock_Ice_Permafrost",
      "rotation": 3
    },
    {
      "x": 0,
      "y": 0,
      "z": -3,
      "name": "Rock_Ice_Permafrost",
      "rotation": 3
    },
    {
      "x": 0,
      "y": 1,
      "z": -3,
      "name": "Rock_Ice_Permafrost",
      "rotation": 3
    },
    {
      "x": 0,
      "y": 2,
      "z": -3,
      "name": "Rock_Ice_Permafrost",
      "rotation": 3
    },
    {
      "x": 0,
      "y": 3,
      "z": -3,
      "name": "Rock_Ice_Permafrost",
      "rotation": 3
    },
    {
      "x": 0,
      "y": 4,
      "z": -3,
      "name": "Rock_Ice_Permafrost",
      "rotation": 3
    },
    {
      "x": 0,
      "y": 5,
      "z": -3,
      "name": "Rock_Ice_Permafrost",
      "rotation": 3
    },
    {
      "x": 0,
      "y": 6,
      "z": -3,
      "name": "Rock_Ice_Permafrost",
      "rotation": 3
    },
    {
      "x": 0,
      "y": 7,
      "z": -3,
      "name": "Rock_Ice_Permafrost",
      "rotation": 3
    },
    {
      "x": 0,
      "y": 8,
      "z": -3,
      "name": "Rock_Ice_Permafrost",
      "rotation": 3
    },
    {
      "x": 0,
      "y": 9,
      "z": -3,
      "name": "Rock_Ice_Permafrost",
      "rotation": 3
    },
    {
      "x": 0,
      "y": 10,
      "z": -3,
      "name": "Rock_Ice_Permafrost",
      "rotation": 3
    },
    {
      "x": 0,
      "y": -3,
      "z": -2,
      "name": "Rock_Ice_Permafrost",
      "rotation": 3
    },
    {
      "x": 0,
      "y": -2,
      "z": -2,
      "name": "Rock_Ice_Permafrost",
      "rotation": 3
    },
    {
      "x": 0,
      "y": -1,
      "z": -2,
      "name": "Rock_Ice_Permafrost",
      "rotation": 3
    },
    {
      "x": 0,
      "y": 0,
      "z": -2,
      "name": "Rock_Ice_Permafrost",
      "rotation": 3
    },
    {
      "x": 0,
      "y": 1,
      "z": -2,
      "name": "Rock_Ice_Permafrost",
      "rotation": 3
    },
    {
      "x": 0,
      "y": 2,
      "z": -2,
      "name": "Rock_Ice_Permafrost",
      "rotation": 3
    },
    {
      "x": 0,
      "y": 3,
      "z": -2,
      "name": "Rock_Ice_Permafrost",
      "rotation": 3
    },
    {
      "x": 0,
      "y": 4,
      "z": -2,
      "name": "Rock_Ice_Permafrost",
      "rotation": 3
    },
    {
      "x": 0,
      "y": 5,
      "z": -2,
      "name": "Rock_Ice_Permafrost",
      "rotation": 3
    },
    {
      "x": 0,
      "y": 6,
      "z": -2,
      "name": "Rock_Ice_Permafrost",
      "rotation": 3
    },
    {
      "x": 0,
      "y": 7,
      "z": -2,
      "name": "Rock_Ice_Permafrost",
      "rotation": 3
    },
    {
      "x": 0,
      "y": 8,
      "z": -2,
      "name": "Rock_Ice_Permafrost",
      "rotation": 3
    },
    {
      "x": 0,
      "y": 9,
      "z": -2,
      "name": "Rock_Ice_Permafrost",
      "rotation": 3
    },
    {
      "x": 0,
      "y": -6,
      "z": -1,
      "name": "Rock_Ice_Permafrost",
      "rotation": 3
    },
    {
      "x": 0,
      "y": -5,
      "z": -1,
      "name": "Rock_Ice_Permafrost",
      "rotation": 3
    },
    {
      "x": 0,
      "y": -4,
      "z": -1,
      "name": "Rock_Ice_Permafrost",
      "rotation": 3
    },
    {
      "x": 0,
      "y": -3,
      "z": -1,
      "name": "Rock_Ice_Permafrost",
      "rotation": 3
    },
    {
      "x": 0,
      "y": -2,
      "z": -1,
      "name": "Rock_Ice_Permafrost",
      "rotation": 3
    },
    {
      "x": 0,
      "y": -1,
      "z": -1,
      "name": "Rock_Ice_Permafrost",
      "rotation": 3
    },
    {
      "x": 0,
      "y": 0,
      "z": -1,
      "name": "Rock_Ice_Permafrost",
      "rotation": 3
    },
    {
      "x": 0,
      "y": 1,
      "z": -1,
      "name": "Rock_Ice_Permafrost",
      "rotation": 3
    },
    {
      "x": 0,
      "y": 2,
      "z": -1,
      "name": "Rock_Ice_Permafrost",
      "rotation": 3
    },
    {
      "x": 0,
      "y": 3,
      "z": -1,
      "name": "Rock_Ice_Permafrost",
      "rotation": 3
    },
    {
      "x": 0,
      "y": 4,
      "z": -1,
      "name": "Rock_Ice_Permafrost",
      "rotation": 3
    },
    {
      "x": 0,
      "y": 5,
      "z": -1,
      "name": "Rock_Ice_Permafrost",
      "rotation": 3
    },
    {
      "x": 0,
      "y": 6,
      "z": -1,
      "name": "Rock_Ice_Permafrost",
      "rotation": 3
    },
    {
      "x": 0,
      "y": -10,
      "z": 0,
      "name": "Rock_Ice_Permafrost",
      "rotation": 3
    },
    {
      "x": 0,
      "y": -9,
      "z": 0,
      "name": "Rock_Ice_Permafrost",
      "rotation": 3
    },
    {
      "x": 0,
      "y": -8,
      "z": 0,
      "name": "Rock_Ice_Permafrost",
      "rotation": 3
    },
    {
      "x": 0,
      "y": -7,
      "z": 0,
      "name": "Rock_Ice_Permafrost",
      "rotation": 3
    },
    {
      "x": 0,
      "y": -6,
      "z": 0,
      "name": "Rock_Ice_Permafrost",
      "rotation": 3
    },
    {
      "x": 0,
      "y": -5,
      "z": 0,
      "name": "Rock_Ice_Permafrost",
      "rotation": 3
    },
    {
      "x": 0,
      "y": -4,
      "z": 0,
      "name": "Rock_Ice_Permafrost",
      "rotation": 3
    },
    {
      "x": 0,
      "y": -3,
      "z": 0,
      "name": "Rock_Ice_Permafrost",
      "rotation": 3
    },
    {
      "x": 0,
      "y": -2,
      "z": 0,
      "name": "Rock_Ice_Permafrost",
      "rotation": 3
    },
    {
      "x": 0,
      "y": -1,
      "z": 0,
      "name": "Rock_Ice_Permafrost",
      "rotation": 3
    },
    {
      "x": 0,
      "y": 0,
      "z": 0,
      "name": "Rock_Ice_Permafrost",
      "rotation": 3
    },
    {
      "x": 0,
      "y": 1,
      "z": 0,
      "name": "Rock_Ice_Permafrost",
      "rotation": 3
    },
    {
      "x": 0,
      "y": 2,
      "z": 0,
      "name": "Rock_Ice_Permafrost",
      "rotation": 3
    },
    {
      "x": 0,
      "y": 3,
      "z": 0,
      "name": "Rock_Ice_Permafrost",
      "rotation": 3
    },
    {
      "x": 0,
      "y": 4,
      "z": 0,
      "name": "Rock_Ice_Permafrost",
      "rotation": 3
    },
    {
      "x": 0,
      "y": -6,
      "z": 1,
      "name": "Rock_Ice_Permafrost",
      "rotation": 3
    },
    {
      "x": 0,
      "y": -5,
      "z": 1,
      "name": "Rock_Ice_Permafrost",
      "rotation": 3
    },
    {
      "x": 0,
      "y": -4,
      "z": 1,
      "name": "Rock_Ice_Permafrost",
      "rotation": 3
    },
    {
      "x": 0,
      "y": -3,
      "z": 1,
      "name": "Rock_Ice_Permafrost",
      "rotation": 3
    },
    {
      "x": 0,
      "y": -2,
      "z": 1,
      "name": "Rock_Ice_Permafrost",
      "rotation": 3
    },
    {
      "x": 0,
      "y": -1,
      "z": 1,
      "name": "Rock_Ice_Permafrost",
      "rotation": 3
    },
    {
      "x": 0,
      "y": 0,
      "z": 1,
      "name": "Rock_Ice_Permafrost",
      "rotation": 3
    },
    {
      "x": 0,
      "y": 1,
      "z": 1,
      "name": "Rock_Ice_Permafrost",
      "rotation": 3
    },
    {
      "x": 0,
      "y": 2,
      "z": 1,
      "name": "Rock_Ice_Permafrost",
      "rotation": 3
    },
    {
      "x": 0,
      "y": 3,
      "z": 1,
      "name": "Rock_Ice_Permafrost",
      "rotation": 3
    },
    {
      "x": 0,
      "y": -7,
      "z": 2,
      "name": "Rock_Ice_Permafrost"
    },
    {
      "x": 0,
      "y": -6,
      "z": 2,
      "name": "Rock_Ice_Permafrost",
      "rotation": 3
    },
    {
      "x": 0,
      "y": -5,
      "z": 2,
      "name": "Rock_Ice_Permafrost",
      "rotation": 3
    },
    {
      "x": 0,
      "y": -4,
      "z": 2,
      "name": "Rock_Ice_Permafrost",
      "rotation": 3
    },
    {
      "x": 0,
      "y": -3,
      "z": 2,
      "name": "Rock_Ice_Permafrost",
      "rotation": 3
    },
    {
      "x": 0,
      "y": -2,
      "z": 2,
      "name": "Rock_Ice_Permafrost",
      "rotation": 3
    },
    {
      "x": 0,
      "y": -1,
      "z": 2,
      "name": "Rock_Ice_Permafrost",
      "rotation": 3
    },
    {
      "x": 0,
      "y": 0,
      "z": 2,
      "name": "Rock_Ice_Permafrost",
      "rotation": 3
    },
    {
      "x": 0,
      "y": 1,
      "z": 2,
      "name": "Rock_Ice_Permafrost",
      "rotation": 3
    },
    {
      "x": 0,
      "y": 2,
      "z": 2,
      "name": "Rock_Ice_Permafrost",
      "rotation": 3
    },
    {
      "x": 0,
      "y": -6,
      "z": 3,
      "name": "Rock_Ice_Permafrost"
    },
    {
      "x": 0,
      "y": -5,
      "z": 3,
      "name": "Rock_Ice_Permafrost"
    },
    {
      "x": 0,
      "y": -4,
      "z": 3,
      "name": "Rock_Ice_Permafrost"
    },
    {
      "x": 0,
      "y": -3,
      "z": 3,
      "name": "Rock_Ice_Permafrost"
    },
    {
      "x": 0,
      "y": -2,
      "z": 3,
      "name": "Rock_Ice_Permafrost"
    },
    {
      "x": 0,
      "y": -1,
      "z": 3,
      "name": "Rock_Ice_Permafrost"
    },
    {
      "x": 0,
      "y": 0,
      "z": 3,
      "name": "Rock_Ice_Permafrost"
    },
    {
      "x": 0,
      "y": 1,
      "z": 3,
      "name": "Rock_Ice_Permafrost"
    },
    {
      "x": 0,
      "y": -3,
      "z": 4,
      "name": "Rock_Ice_Permafrost"
    },
    {
      "x": 0,
      "y": -2,
      "z": 4,
      "name": "Rock_Ice_Permafrost"
    },
    {
      "x": 0,
      "y": -1,
      "z": 4,
      "name": "Rock_Ice_Permafrost"
    },
    {
      "x": 0,
      "y": 0,
      "z": 4,
      "name": "Rock_Ice_Permafrost"
    },
    {
      "x": 1,
      "y": 8,
      "z": -6,
      "name": "Fullmetal_White_Crystal_Lamp",
      "rotation": 8
    },
    {
      "x": 1,
      "y": 9,
      "z": -6,
      "name": "Rock_Ice_Permafrost",
      "rotation": 3
    },
    {
      "x": 1,
      "y": 10,
      "z": -6,
      "name": "Rock_Ice_Permafrost",
      "rotation": 3
    },
    {
      "x": 1,
      "y": 11,
      "z": -6,
      "name": "Rock_Ice_Permafrost",
      "rotation": 3
    },
    {
      "x": 1,
      "y": 12,
      "z": -6,
      "name": "Rock_Ice_Permafrost",
      "rotation": 3
    },
    {
      "x": 1,
      "y": 13,
      "z": -6,
      "name": "Rock_Ice_Permafrost",
      "rotation": 3
    },
    {
      "x": 1,
      "y": 14,
      "z": -6,
      "name": "Rock_Ice_Permafrost",
      "rotation": 3
    },
    {
      "x": 1,
      "y": 15,
      "z": -6,
      "name": "Rock_Ice_Permafrost",
      "rotation": 3
    },
    {
      "x": 1,
      "y": 3,
      "z": -5,
      "name": "Rock_Ice_Icicles",
      "rotation": 33
    },
    {
      "x": 1,
      "y": 4,
      "z": -5,
      "name": "Rock_Ice_Permafrost",
      "rotation": 3
    },
    {
      "x": 1,
      "y": 5,
      "z": -5,
      "name": "Rock_Ice_Permafrost",
      "rotation": 3
    },
    {
      "x": 1,
      "y": 6,
      "z": -5,
      "name": "Rock_Ice_Permafrost",
      "rotation": 3
    },
    {
      "x": 1,
      "y": 7,
      "z": -5,
      "name": "Rock_Ice_Permafrost",
      "rotation": 3
    },
    {
      "x": 1,
      "y": 8,
      "z": -5,
      "name": "Rock_Ice_Permafrost",
      "rotation": 3
    },
    {
      "x": 1,
      "y": 9,
      "z": -5,
      "name": "Rock_Ice_Permafrost",
      "rotation": 3
    },
    {
      "x": 1,
      "y": 10,
      "z": -5,
      "name": "Rock_Ice_Permafrost",
      "rotation": 3
    },
    {
      "x": 1,
      "y": 11,
      "z": -5,
      "name": "Rock_Ice_Permafrost",
      "rotation": 3
    },
    {
      "x": 1,
      "y": 12,
      "z": -5,
      "name": "Rock_Ice_Permafrost",
      "rotation": 3
    },
    {
      "x": 1,
      "y": 13,
      "z": -5,
      "name": "Rock_Ice_Permafrost",
      "rotation": 3
    },
    {
      "x": 1,
      "y": 2,
      "z": -4,
      "name": "Rock_Ice_Permafrost",
      "rotation": 3
    },
    {
      "x": 1,
      "y": 3,
      "z": -4,
      "name": "Rock_Ice_Permafrost",
      "rotation": 3
    },
    {
      "x": 1,
      "y": 4,
      "z": -4,
      "name": "Rock_Ice_Permafrost",
      "rotation": 3
    },
    {
      "x": 1,
      "y": 5,
      "z": -4,
      "name": "Rock_Ice_Permafrost",
      "rotation": 3
    },
    {
      "x": 1,
      "y": 6,
      "z": -4,
      "name": "Rock_Ice_Permafrost",
      "rotation": 3
    },
    {
      "x": 1,
      "y": 7,
      "z": -4,
      "name": "Rock_Ice_Permafrost",
      "rotation": 3
    },
    {
      "x": 1,
      "y": 8,
      "z": -4,
      "name": "Rock_Ice_Permafrost",
      "rotation": 3
    },
    {
      "x": 1,
      "y": 9,
      "z": -4,
      "name": "Rock_Ice_Permafrost",
      "rotation": 3
    },
    {
      "x": 1,
      "y": 10,
      "z": -4,
      "name": "Rock_Ice_Permafrost",
      "rotation": 3
    },
    {
      "x": 1,
      "y": 11,
      "z": -4,
      "name": "Rock_Ice_Permafrost",
      "rotation": 3
    },
    {
      "x": 1,
      "y": 1,
      "z": -3,
      "name": "Rock_Ice_Permafrost",
      "rotation": 3
    },
    {
      "x": 1,
      "y": 2,
      "z": -3,
      "name": "Rock_Ice_Permafrost",
      "rotation": 3
    },
    {
      "x": 1,
      "y": 3,
      "z": -3,
      "name": "Rock_Ice_Permafrost",
      "rotation": 3
    },
    {
      "x": 1,
      "y": 4,
      "z": -3,
      "name": "Rock_Ice_Permafrost",
      "rotation": 3
    },
    {
      "x": 1,
      "y": 5,
      "z": -3,
      "name": "Rock_Ice_Permafrost",
      "rotation": 3
    },
    {
      "x": 1,
      "y": 6,
      "z": -3,
      "name": "Rock_Ice_Permafrost",
      "rotation": 3
    },
    {
      "x": 1,
      "y": 7,
      "z": -3,
      "name": "Rock_Ice_Permafrost",
      "rotation": 3
    },
    {
      "x": 1,
      "y": 8,
      "z": -3,
      "name": "Rock_Ice_Permafrost",
      "rotation": 3
    },
    {
      "x": 1,
      "y": 9,
      "z": -3,
      "name": "Rock_Ice_Permafrost",
      "rotation": 3
    },
    {
      "x": 1,
      "y": 10,
      "z": -3,
      "name": "Rock_Ice_Permafrost",
      "rotation": 3
    },
    {
      "x": 1,
      "y": -1,
      "z": -2,
      "name": "Rock_Ice_Permafrost",
      "rotation": 3
    },
    {
      "x": 1,
      "y": 0,
      "z": -2,
      "name": "Rock_Ice_Permafrost",
      "rotation": 3
    },
    {
      "x": 1,
      "y": 1,
      "z": -2,
      "name": "Rock_Ice_Permafrost",
      "rotation": 3
    },
    {
      "x": 1,
      "y": 2,
      "z": -2,
      "name": "Rock_Ice_Permafrost",
      "rotation": 3
    },
    {
      "x": 1,
      "y": 3,
      "z": -2,
      "name": "Rock_Ice_Permafrost",
      "rotation": 3
    },
    {
      "x": 1,
      "y": 4,
      "z": -2,
      "name": "Rock_Ice_Permafrost",
      "rotation": 3
    },
    {
      "x": 1,
      "y": 5,
      "z": -2,
      "name": "Rock_Ice_Permafrost",
      "rotation": 3
    },
    {
      "x": 1,
      "y": 6,
      "z": -2,
      "name": "Rock_Ice_Permafrost",
      "rotation": 3
    },
    {
      "x": 1,
      "y": 7,
      "z": -2,
      "name": "Rock_Ice_Permafrost",
      "rotation": 3
    },
    {
      "x": 1,
      "y": 8,
      "z": -2,
      "name": "Rock_Ice_Permafrost",
      "rotation": 3
    },
    {
      "x": 1,
      "y": 9,
      "z": -2,
      "name": "Rock_Ice_Permafrost",
      "rotation": 3
    },
    {
      "x": 1,
      "y": -5,
      "z": -1,
      "name": "Rock_Ice_Permafrost",
      "rotation": 3
    },
    {
      "x": 1,
      "y": -4,
      "z": -1,
      "name": "Rock_Ice_Permafrost",
      "rotation": 3
    },
    {
      "x": 1,
      "y": -3,
      "z": -1,
      "name": "Rock_Ice_Permafrost",
      "rotation": 3
    },
    {
      "x": 1,
      "y": -2,
      "z": -1,
      "name": "Rock_Ice_Permafrost",
      "rotation": 3
    },
    {
      "x": 1,
      "y": -1,
      "z": -1,
      "name": "Rock_Ice_Permafrost",
      "rotation": 3
    },
    {
      "x": 1,
      "y": 0,
      "z": -1,
      "name": "Rock_Ice_Permafrost",
      "rotation": 3
    },
    {
      "x": 1,
      "y": 1,
      "z": -1,
      "name": "Rock_Ice_Permafrost",
      "rotation": 3
    },
    {
      "x": 1,
      "y": 2,
      "z": -1,
      "name": "Rock_Ice_Permafrost",
      "rotation": 3
    },
    {
      "x": 1,
      "y": 3,
      "z": -1,
      "name": "Rock_Ice_Permafrost",
      "rotation": 3
    },
    {
      "x": 1,
      "y": 4,
      "z": -1,
      "name": "Rock_Ice_Permafrost",
      "rotation": 3
    },
    {
      "x": 1,
      "y": 5,
      "z": -1,
      "name": "Rock_Ice_Permafrost",
      "rotation": 3
    },
    {
      "x": 1,
      "y": 6,
      "z": -1,
      "name": "Rock_Ice_Permafrost",
      "rotation": 3
    },
    {
      "x": 1,
      "y": -9,
      "z": 0,
      "name": "Rock_Ice_Permafrost",
      "rotation": 3
    },
    {
      "x": 1,
      "y": -8,
      "z": 0,
      "name": "Rock_Ice_Permafrost",
      "rotation": 3
    },
    {
      "x": 1,
      "y": -7,
      "z": 0,
      "name": "Rock_Ice_Permafrost",
      "rotation": 3
    },
    {
      "x": 1,
      "y": -6,
      "z": 0,
      "name": "Rock_Ice_Permafrost",
      "rotation": 3
    },
    {
      "x": 1,
      "y": -5,
      "z": 0,
      "name": "Rock_Ice_Permafrost",
      "rotation": 3
    },
    {
      "x": 1,
      "y": -4,
      "z": 0,
      "name": "Rock_Ice_Permafrost",
      "rotation": 3
    },
    {
      "x": 1,
      "y": -3,
      "z": 0,
      "name": "Rock_Ice_Permafrost",
      "rotation": 3
    },
    {
      "x": 1,
      "y": -2,
      "z": 0,
      "name": "Rock_Ice_Permafrost",
      "rotation": 3
    },
    {
      "x": 1,
      "y": -1,
      "z": 0,
      "name": "Rock_Ice_Permafrost",
      "rotation": 3
    },
    {
      "x": 1,
      "y": 0,
      "z": 0,
      "name": "Rock_Ice_Permafrost",
      "rotation": 3
    },
    {
      "x": 1,
      "y": 1,
      "z": 0,
      "name": "Rock_Ice_Permafrost",
      "rotation": 3
    },
    {
      "x": 1,
      "y": 2,
      "z": 0,
      "name": "Rock_Ice_Permafrost",
      "rotation": 3
    },
    {
      "x": 1,
      "y": 3,
      "z": 0,
      "name": "Rock_Ice_Permafrost",
      "rotation": 3
    },
    {
      "x": 1,
      "y": 4,
      "z": 0,
      "name": "Rock_Ice_Permafrost",
      "rotation": 3
    },
    {
      "x": 1,
      "y": -6,
      "z": 1,
      "name": "Rock_Ice_Permafrost",
      "rotation": 3
    },
    {
      "x": 1,
      "y": -5,
      "z": 1,
      "name": "Rock_Ice_Permafrost",
      "rotation": 3
    },
    {
      "x": 1,
      "y": -4,
      "z": 1,
      "name": "Rock_Ice_Permafrost",
      "rotation": 3
    },
    {
      "x": 1,
      "y": -3,
      "z": 1,
      "name": "Rock_Ice_Permafrost",
      "rotation": 3
    },
    {
      "x": 1,
      "y": -2,
      "z": 1,
      "name": "Rock_Ice_Permafrost",
      "rotation": 3
    },
    {
      "x": 1,
      "y": -1,
      "z": 1,
      "name": "Rock_Ice_Permafrost",
      "rotation": 3
    },
    {
      "x": 1,
      "y": 0,
      "z": 1,
      "name": "Rock_Ice_Permafrost",
      "rotation": 3
    },
    {
      "x": 1,
      "y": 1,
      "z": 1,
      "name": "Rock_Ice_Permafrost",
      "rotation": 3
    },
    {
      "x": 1,
      "y": 2,
      "z": 1,
      "name": "Rock_Ice_Permafrost",
      "rotation": 3
    },
    {
      "x": 1,
      "y": 3,
      "z": 1,
      "name": "Rock_Ice_Permafrost",
      "rotation": 3
    },
    {
      "x": 1,
      "y": -8,
      "z": 2,
      "name": "Rock_Ice_Permafrost"
    },
    {
      "x": 1,
      "y": -7,
      "z": 2,
      "name": "Rock_Ice_Permafrost"
    },
    {
      "x": 1,
      "y": -6,
      "z": 2,
      "name": "Rock_Ice_Permafrost",
      "rotation": 3
    },
    {
      "x": 1,
      "y": -5,
      "z": 2,
      "name": "Rock_Ice_Permafrost",
      "rotation": 3
    },
    {
      "x": 1,
      "y": -4,
      "z": 2,
      "name": "Rock_Ice_Permafrost",
      "rotation": 3
    },
    {
      "x": 1,
      "y": -3,
      "z": 2,
      "name": "Rock_Ice_Permafrost",
      "rotation": 3
    },
    {
      "x": 1,
      "y": -2,
      "z": 2,
      "name": "Rock_Ice_Permafrost",
      "rotation": 3
    },
    {
      "x": 1,
      "y": -1,
      "z": 2,
      "name": "Rock_Ice_Permafrost",
      "rotation": 3
    },
    {
      "x": 1,
      "y": 0,
      "z": 2,
      "name": "Rock_Ice_Permafrost",
      "rotation": 3
    },
    {
      "x": 1,
      "y": 1,
      "z": 2,
      "name": "Rock_Ice_Permafrost",
      "rotation": 3
    },
    {
      "x": 1,
      "y": 2,
      "z": 2,
      "name": "Rock_Ice_Permafrost",
      "rotation": 3
    },
    {
      "x": 1,
      "y": -5,
      "z": 3,
      "name": "Rock_Ice_Permafrost"
    },
    {
      "x": 1,
      "y": -4,
      "z": 3,
      "name": "Rock_Ice_Permafrost"
    },
    {
      "x": 1,
      "y": -3,
      "z": 3,
      "name": "Rock_Ice_Permafrost"
    },
    {
      "x": 1,
      "y": -2,
      "z": 3,
      "name": "Rock_Ice_Permafrost"
    },
    {
      "x": 1,
      "y": -1,
      "z": 3,
      "name": "Rock_Ice_Permafrost"
    },
    {
      "x": 1,
      "y": 0,
      "z": 3,
      "name": "Rock_Ice_Permafrost"
    },
    {
      "x": 1,
      "y": 1,
      "z": 3,
      "name": "Rock_Ice_Permafrost"
    },
    {
      "x": 1,
      "y": -2,
      "z": 4,
      "name": "Rock_Ice_Permafrost"
    },
    {
      "x": 1,
      "y": -1,
      "z": 4,
      "name": "Rock_Ice_Permafrost"
    },
    {
      "x": 1,
      "y": 0,
      "z": 4,
      "name": "Rock_Ice_Permafrost"
    },
    {
      "x": 2,
      "y": 5,
      "z": -5,
      "name": "Rock_Ice_Icicles",
      "rotation": 33
    },
    {
      "x": 2,
      "y": 6,
      "z": -5,
      "name": "Rock_Ice_Permafrost",
      "rotation": 3
    },
    {
      "x": 2,
      "y": 7,
      "z": -5,
      "name": "Rock_Ice_Permafrost",
      "rotation": 3
    },
    {
      "x": 2,
      "y": 8,
      "z": -5,
      "name": "Rock_Ice_Permafrost",
      "rotation": 3
    },
    {
      "x": 2,
      "y": 3,
      "z": -4,
      "name": "Rock_Ice_Icicles",
      "rotation": 33
    },
    {
      "x": 2,
      "y": 4,
      "z": -4,
      "name": "Rock_Ice_Permafrost",
      "rotation": 3
    },
    {
      "x": 2,
      "y": 5,
      "z": -4,
      "name": "Rock_Ice_Permafrost",
      "rotation": 3
    },
    {
      "x": 2,
      "y": 6,
      "z": -4,
      "name": "Rock_Ice_Permafrost",
      "rotation": 3
    },
    {
      "x": 2,
      "y": 7,
      "z": -4,
      "name": "Rock_Ice_Permafrost",
      "rotation": 3
    },
    {
      "x": 2,
      "y": 8,
      "z": -4,
      "name": "Rock_Ice_Permafrost",
      "rotation": 3
    },
    {
      "x": 2,
      "y": 3,
      "z": -3,
      "name": "Rock_Ice_Icicles",
      "rotation": 33
    },
    {
      "x": 2,
      "y": 4,
      "z": -3,
      "name": "Rock_Ice_Permafrost",
      "rotation": 3
    },
    {
      "x": 2,
      "y": 5,
      "z": -3,
      "name": "Rock_Ice_Permafrost",
      "rotation": 3
    },
    {
      "x": 2,
      "y": 6,
      "z": -3,
      "name": "Rock_Ice_Permafrost",
      "rotation": 3
    },
    {
      "x": 2,
      "y": 7,
      "z": -3,
      "name": "Rock_Ice_Permafrost",
      "rotation": 3
    },
    {
      "x": 2,
      "y": 8,
      "z": -3,
      "name": "Rock_Ice_Permafrost",
      "rotation": 3
    },
    {
      "x": 2,
      "y": 2,
      "z": -2,
      "name": "Rock_Ice_Permafrost",
      "rotation": 3
    },
    {
      "x": 2,
      "y": 3,
      "z": -2,
      "name": "Rock_Ice_Permafrost",
      "rotation": 3
    },
    {
      "x": 2,
      "y": 4,
      "z": -2,
      "name": "Rock_Ice_Permafrost",
      "rotation": 3
    },
    {
      "x": 2,
      "y": 5,
      "z": -2,
      "name": "Rock_Ice_Permafrost",
      "rotation": 3
    },
    {
      "x": 2,
      "y": 6,
      "z": -2,
      "name": "Rock_Ice_Permafrost",
      "rotation": 3
    },
    {
      "x": 2,
      "y": 2,
      "z": -1,
      "name": "Rock_Ice_Permafrost",
      "rotation": 3
    },
    {
      "x": 2,
      "y": 3,
      "z": -1,
      "name": "Rock_Ice_Permafrost",
      "rotation": 3
    },
    {
      "x": 2,
      "y": 4,
      "z": -1,
      "name": "Rock_Ice_Permafrost",
      "rotation": 3
    },
    {
      "x": 2,
      "y": 1,
      "z": 0,
      "name": "Rock_Ice_Permafrost",
      "rotation": 3
    },
    {
      "x": 2,
      "y": 2,
      "z": 0,
      "name": "Rock_Ice_Permafrost",
      "rotation": 3
    },
    {
      "x": 2,
      "y": 3,
      "z": 0,
      "name": "Rock_Ice_Permafrost",
      "rotation": 3
    },
    {
      "x": 2,
      "y": 4,
      "z": 0,
      "name": "Rock_Ice_Permafrost",
      "rotation": 3
    },
    {
      "x": 2,
      "y": -6,
      "z": 1,
      "name": "Rock_Ice_Permafrost",
      "rotation": 3
    },
    {
      "x": 2,
      "y": -5,
      "z": 1,
      "name": "Rock_Ice_Permafrost",
      "rotation": 3
    },
    {
      "x": 2,
      "y": -4,
      "z": 1,
      "name": "Rock_Ice_Permafrost",
      "rotation": 3
    },
    {
      "x": 2,
      "y": -3,
      "z": 1,
      "name": "Rock_Ice_Permafrost",
      "rotation": 3
    },
    {
      "x": 2,
      "y": -2,
      "z": 1,
      "name": "Rock_Ice_Permafrost",
      "rotation": 3
    },
    {
      "x": 2,
      "y": -1,
      "z": 1,
      "name": "Rock_Ice_Permafrost",
      "rotation": 3
    },
    {
      "x": 2,
      "y": 0,
      "z": 1,
      "name": "Rock_Ice_Permafrost",
      "rotation": 3
    },
    {
      "x": 2,
      "y": 1,
      "z": 1,
      "name": "Rock_Ice_Permafrost",
      "rotation": 3
    },
    {
      "x": 2,
      "y": 2,
      "z": 1,
      "name": "Rock_Ice_Permafrost",
      "rotation": 3
    },
    {
      "x": 2,
      "y": -6,
      "z": 2,
      "name": "Rock_Ice_Permafrost",
      "rotation": 3
    },
    {
      "x": 2,
      "y": -5,
      "z": 2,
      "name": "Rock_Ice_Permafrost",
      "rotation": 3
    },
    {
      "x": 2,
      "y": -4,
      "z": 2,
      "name": "Rock_Ice_Permafrost",
      "rotation": 3
    },
    {
      "x": 2,
      "y": -3,
      "z": 2,
      "name": "Rock_Ice_Permafrost",
      "rotation": 3
    },
    {
      "x": 2,
      "y": -2,
      "z": 2,
      "name": "Rock_Ice_Permafrost",
      "rotation": 3
    },
    {
      "x": 2,
      "y": -1,
      "z": 2,
      "name": "Rock_Ice_Permafrost",
      "rotation": 3
    },
    {
      "x": 2,
      "y": 0,
      "z": 2,
      "name": "Rock_Ice_Permafrost",
      "rotation": 3
    },
    {
      "x": 2,
      "y": 1,
      "z": 2,
      "name": "Rock_Ice_Permafrost",
      "rotation": 3
    },
    {
      "x": 2,
      "y": 2,
      "z": 2,
      "name": "Rock_Ice_Permafrost",
      "rotation": 3
    },
    {
      "x": 3,
      "y": 1,
      "z": 0,
      "name": "Rock_Ice_Permafrost",
      "rotation": 3
    },
    {
      "x": 3,
      "y": 2,
      "z": 0,
      "name": "Rock_Ice_Permafrost",
      "rotation": 3
    },
    {
      "x": 3,
      "y": -3,
      "z": 1,
      "name": "Rock_Ice_Permafrost",
      "rotation": 3
    },
    {
      "x": 3,
      "y": -2,
      "z": 1,
      "name": "Rock_Ice_Permafrost",
      "rotation": 3
    },
    {
      "x": 3,
      "y": -1,
      "z": 1,
      "name": "Rock_Ice_Permafrost",
      "rotation": 3
    },
    {
      "x": 3,
      "y": 0,
      "z": 1,
      "name": "Rock_Ice_Permafrost",
      "rotation": 3
    },
    {
      "x": 3,
      "y": 1,
      "z": 1,
      "name": "Rock_Ice_Permafrost",
      "rotation": 3
    },
    {
      "x": 3,
      "y": 2,
      "z": 1,
      "name": "Rock_Ice_Permafrost",
      "rotation": 3
    },
    {
      "x": 3,
      "y": -6,
      "z": 2,
      "name": "Rock_Ice_Permafrost",
      "rotation": 3
    },
    {
      "x": 3,
      "y": -5,
      "z": 2,
      "name": "Rock_Ice_Permafrost",
      "rotation": 3
    },
    {
      "x": 3,
      "y": -4,
      "z": 2,
      "name": "Rock_Ice_Permafrost",
      "rotation": 3
    },
    {
      "x": 3,
      "y": -3,
      "z": 2,
      "name": "Rock_Ice_Permafrost",
      "rotation": 3
    },
    {
      "x": 3,
      "y": -2,
      "z": 2,
      "name": "Rock_Ice_Permafrost",
      "rotation": 3
    }
  ]
}