{
  "version": 8,
  "blockIdVersion": 11,
  "anchorX": 0,
  "anchorY": 0,
  "anchorZ": 0,
  "blocks": [
    {
      "x": -8,
      "y": -8,
      "z": -1,
      "name": "Rock_Ice_Permafrost",
      "rotation": 3
    },
    {
      "x": -8,
      "y": -7,
      "z": -1,
      "name": "Rock_Ice_Permafrost",
      "rotation": 3
    },
    {
      "x": -8,
      "y": -6,
      "z": -1,
      "name": "Rock_Ice_Permafrost",
      "rotation": 3
    },
    {
      "x": -8,
      "y": -8,
      "z": 0,
      "name": "Rock_Ice_Permafrost",
      "rotation": 3
    },
    {
      "x": -8,
      "y": -7,
      "z": 0,
      "name": "Rock_Ice_Permafrost",
      "rotation": 3
    },
    {
      "x": -8,
      "y": -6,
      "z": 0,
      "name": "Rock_Ice_Permafrost",
      "rotation": 2
    },
    {
      "x": -7,
      "y": -8,
      "z": -2,
      "name": "Rock_Ice_Permafrost"
    },
    {
      "x": -7,
      "y": -7,
      "z": -2,
      "name": "Rock_Ice_Permafrost"
    },
    {
      "x": -7,
      "y": -9,
      "z": -1,
      "name": "Rock_Ice_Permafrost",
      "rotation": 3
    },
    {
      "x": -7,
      "y": -8,
      "z": -1,
      "name": "Rock_Ice_Permafrost",
      "rotation": 3
    },
    {
      "x": -7,
      "y": -7,
      "z": -1,
      "name": "Rock_Ice_Permafrost",
      "rotation": 3
    },
    {
      "x": -7,
      "y": -6,
      "z": -1,
      "name": "Rock_Ice_Permafrost",
      "rotation": 3
    },
    {
      "x": -7,
      "y": -5,
      "z": -1,
      "name": "Rock_Ice_Permafrost",
      "rotation": 3
    },
    {
      "x": -7,
      "y": -9,
      "z": 0,
      "name": "Rock_Ice_Permafrost",
      "rotation": 3
    },
    {
      "x": -7,
      "y": -8,
      "z": 0,
      "name": "Rock_Ice_Permafrost",
      "rotation": 3
    },
    {
      "x": -7,
      "y": -7,
      "z": 0,
      "name": "Rock_Ice_Permafrost",
      "rotation": 3
    },
    {
      "x": -7,
      "y": -6,
      "z": 0,
      "name": "Rock_Ice_Permafrost",
      "rotation": 2
    },
    {
      "x": -7,
      "y": -5,
      "z": 0,
      "name": "Rock_Ice_Permafrost",
      "rotation": 2
    },
    {
      "x": -7,
      "y": -4,
      "z": 0,
      "name": "Rock_Ice_Permafrost",
      "rotation": 2
    },
    {
      "x": -7,
      "y": -6,
      "z": 1,
      "name": "Rock_Ice_Permafrost"
    },
    {
      "x": -6,
      "y": -7,
      "z": -2,
      "name": "Rock_Ice_Permafrost"
    },
    {
      "x": -6,
      "y": -10,
      "z": -1,
      "name": "Rock_Ice_Permafrost",
      "rotation": 2
    },
    {
      "x": -6,
      "y": -9,
      "z": -1,
      "name": "Rock_Ice_Permafrost",
      "rotation": 3
    },
    {
      "x": -6,
      "y": -8,
      "z": -1,
      "name": "Rock_Ice_Permafrost",
      "rotation": 3
    },
    {
      "x": -6,
      "y": -7,
      "z": -1,
      "name": "Rock_Ice_Permafrost",
      "rotation": 3
    },
    {
      "x": -6,
      "y": -6,
      "z": -1,
      "name": "Rock_Ice_Permafrost",
      "rotation": 3
    },
    {
      "x": -6,
      "y": -5,
      "z": -1,
      "name": "Rock_Ice_Permafrost",
      "rotation": 3
    },
    {
      "x": -6,
      "y": -4,
      "z": -1,
      "name": "Rock_Ice_Permafrost",
      "rotation": 3
    },
    {
      "x": -6,
      "y": -10,
      "z": 0,
      "name": "Rock_Ice_Permafrost",
      "rotation": 2
    },
    {
      "x": -6,
      "y": -9,
      "z": 0,
      "name": "Rock_Ice_Permafrost",
      "rotation": 2
    },
    {
      "x": -6,
      "y": -8,
      "z": 0,
      "name": "Rock_Ice_Permafrost",
      "rotation": 2
    },
    {
      "x": -6,
      "y": -7,
      "z": 0,
      "name": "Rock_Ice_Permafrost",
      "rotation": 2
    },
    {
      "x": -6,
      "y": -6,
      "z": 0,
      "name": "Rock_Ice_Permafrost",
      "rotation": 2
    },
    {
      "x": -6,
      "y": -5,
      "z": 0,
      "name": "Rock_Ice_Permafrost",
      "rotation": 2
    },
    {
      "x": -6,
      "y": -4,
      "z": 0,
      "name": "Rock_Ice_Permafrost",
      "rotation": 2
    },
    {
      "x": -6,
      "y": -3,
      "z": 0,
      "name": "Rock_Ice_Permafrost",
      "rotation": 2
    },
    {
      "x": -6,
      "y": -6,
      "z": 1,
      "name": "Rock_Ice_Permafrost"
    },
    {
      "x": -6,
      "y": -5,
      "z": 1,
      "name": "Rock_Ice_Permafrost"
    },
    {
      "x": -5,
      "y": -7,
      "z": -2,
      "name": "Rock_Ice_Permafrost"
    },
    {
      "x": -5,
      "y": -6,
      "z": -2,
      "name": "Rock_Ice_Permafrost"
    },
    {
      "x": -5,
      "y": -10,
      "z": -1,
      "name": "Rock_Ice_Permafrost",
      "rotation": 2
    },
    {
      "x": -5,
      "y": -9,
      "z": -1,
      "name": "Rock_Ice_Permafrost",
      "rotation": 3
    },
    {
      "x": -5,
      "y": -8,
      "z": -1,
      "name": "Rock_Ice_Permafrost",
      "rotation": 3
    },
    {
      "x": -5,
      "y": -7,
      "z": -1,
      "name": "Rock_Ice_Permafrost",
      "rotation": 3
    },
    {
      "x": -5,
      "y": -6,
      "z": -1,
      "name": "Rock_Ice_Permafrost",
      "rotation": 3
    },
    {
      "x": -5,
      "y": -5,
      "z": -1,
      "name": "Rock_Ice_Permafrost",
      "rotation": 3
    },
    {
      "x": -5,
      "y": -4,
      "z": -1,
      "name": "Rock_Ice_Permafrost",
      "rotation": 3
    },
    {
      "x": -5,
      "y": -3,
      "z": -1,
      "name": "Rock_Ice_Permafrost",
      "rotation": 3
    },
    {
      "x": -5,
      "y": -10,
      "z": 0,
      "name": "Rock_Ice_Permafrost",
      "rotation": 2
    },
    {
      "x": -5,
      "y": -9,
      "z": 0,
      "name": "Rock_Ice_Permafrost",
      "rotation": 2
    },
    {
      "x": -5,
      "y": -8,
      "z": 0,
      "name": "Rock_Ice_Permafrost",
      "rotation": 2
    },
    {
      "x": -5,
      "y": -7,
      "z": 0,
      "name": "Rock_Ice_Permafrost",
      "rotation": 2
    },
    {
      "x": -5,
      "y": -6,
      "z": 0,
      "name": "Rock_Ice_Permafrost",
      "rotation": 2
    },
    {
      "x": -5,
      "y": -5,
      "z": 0,
      "name": "Rock_Ice_Permafrost",
      "rotation": 2
    },
    {
      "x": -5,
      "y": -4,
      "z": 0,
      "name": "Rock_Ice_Permafrost",
      "rotation": 2
    },
    {
      "x": -5,
      "y": -3,
      "z": 0,
      "name": "Rock_Ice_Permafrost",
      "rotation": 2
    },
    {
      "x": -5,
      "y": -2,
      "z": 0,
      "name": "Rock_Ice_Permafrost",
      "rotation": 2
    },
    {
      "x": -5,
      "y": -7,
      "z": 1,
      "name": "Rock_Ice_Permafrost"
    },
    {
      "x": -5,
      "y": -6,
      "z": 1,
      "name": "Rock_Ice_Permafrost"
    },
    {
      "x": -5,
      "y": -5,
      "z": 1,
      "name": "Rock_Ice_Permafrost"
    },
    {
      "x": -5,
      "y": -4,
      "z": 1,
      "name": "Rock_Ice_Permafrost"
    },
    {
      "x": -4,
      "y": -6,
      "z": -2,
      "name": "Rock_Ice_Permafrost"
    },
    {
      "x": -4,
      "y": -5,
      "z": -2,
      "name": "Rock_Ice_Permafrost"
    },
    {
      "x": -4,
      "y": -10,
      "z": -1,
      "name": "Rock_Ice_Permafrost",
      "rotation": 3
    },
    {
      "x": -4,
      "y": -9,
      "z": -1,
      "name": "Rock_Ice_Permafrost",
      "rotation": 3
    },
    {
      "x": -4,
      "y": -8,
      "z": -1,
      "name": "Rock_Ice_Permafrost",
      "rotation": 3
    },
    {
      "x": -4,
      "y": -7,
      "z": -1,
      "name": "Rock_Ice_Permafrost",
      "rotation": 3
    },
    {
      "x": -4,
      "y": -6,
      "z": -1,
      "name": "Rock_Ice_Permafrost",
      "rotation": 3
    },
    {
      "x": -4,
      "y": -5,
      "z": -1,
      "name": "Rock_Ice_Permafrost",
      "rotation": 3
    },
    {
      "x": -4,
      "y": -4,
      "z": -1,
      "name": "Rock_Ice_Permafrost",
      "rotation": 3
    },
    {
      "x": -4,
      "y": -3,
      "z": -1,
      "name": "Rock_Ice_Permafrost",
      "rotation": 3
    },
    {
      "x": -4,
      "y": -2,
      "z": -1,
      "name": "Rock_Ice_Permafrost",
      "rotation": 3
    },
    {
      "x": -4,
      "y": -10,
      "z": 0,
      "name": "Rock_Ice_Permafrost",
      "rotation": 3
    },
    {
      "x": -4,
      "y": -9,
      "z": 0,
      "name": "Rock_Ice_Permafrost",
      "rotation": 3
    },
    {
      "x": -4,
      "y": -8,
      "z": 0,
      "name": "Rock_Ice_Permafrost",
      "rotation": 3
    },
    {
      "x": -4,
      "y": -7,
      "z": 0,
      "name": "Rock_Ice_Permafrost",
      "rotation": 3
    },
    {
      "x": -4,
      "y": -6,
      "z": 0,
      "name": "Rock_Ice_Permafrost",
      "rotation": 2
    },
    {
      "x": -4,
      "y": -5,
      "z": 0,
      "name": "Rock_Ice_Permafrost",
      "rotation": 2
    },
    {
      "x": -4,
      "y": -4,
      "z": 0,
      "name": "Rock_Ice_Permafrost",
      "rotation": 2
    },
    {
      "x": -4,
      "y": -3,
      "z": 0,
      "name": "Rock_Ice_Permafrost",
      "rotation": 2
    },
    {
      "x": -4,
      "y": -2,
      "z": 0,
      "name": "Rock_Ice_Permafrost",
      "rotation": 2
    },
    {
      "x": -4,
      "y": -8,
      "z": 1,
      "name": "Rock_Ice_Permafrost"
    },
    {
      "x": -4,
      "y": -7,
      "z": 1,
      "name": "Rock_Ice_Permafrost"
    },
    {
      "x": -4,
      "y": -6,
      "z": 1,
      "name": "Rock_Ice_Permafrost"
    },
    {
      "x": -4,
      "y": -5,
      "z": 1,
      "name": "Rock_Ice_Permafrost"
    },
    {
      "x": -4,
      "y": -4,
      "z": 1,
      "name": "Rock_Ice_Permafrost"
    },
    {
      "x": -3,
      "y": -5,
      "z": -2,
      "name": "Rock_Ice_Permafrost"
    },
    {
      "x": -3,
      "y": -4,
      "z": -2,
      "name": "Rock_Ice_Permafrost"
    },
    {
      "x": -3,
      "y": -10,
      "z": -1,
      "name": "Rock_Ice_Permafrost",
      "rotation": 3
    },
    {
      "x": -3,
      "y": -9,
      "z": -1,
      "name": "Rock_Ice_Permafrost",
      "rotation": 3
    },
    {
      "x": -3,
      "y": -8,
      "z": -1,
      "name": "Rock_Ice_Permafrost",
      "rotation": 3
    },
    {
      "x": -3,
      "y": -7,
      "z": -1,
      "name": "Rock_Ice_Permafrost",
      "rotation": 3
    },
    {
      "x": -3,
      "y": -6,
      "z": -1,
      "name": "Rock_Ice_Permafrost",
      "rotation": 3
    },
    {
      "x": -3,
      "y": -5,
      "z": -1,
      "name": "Rock_Ice_Permafrost",
      "rotation": 3
    },
    {
      "x": -3,
      "y": -4,
      "z": -1,
      "name": "Rock_Ice_Permafrost",
      "rotation": 3
    },
    {
      "x": -3,
      "y": -3,
      "z": -1,
      "name": "Rock_Ice_Permafrost",
      "rotation": 3
    },
    {
      "x": -3,
      "y": -2,
      "z": -1,
      "name": "Rock_Ice_Permafrost",
      "rotation": 3
    },
    {
      "x": -3,
      "y": -10,
      "z": 0,
      "name": "Rock_Ice_Permafrost",
      "rotation": 3
    },
    {
      "x": -3,
      "y": -9,
      "z": 0,
      "name": "Rock_Ice_Permafrost",
      "rotation": 3
    },
    {
      "x": -3,
      "y": -8,
      "z": 0,
      "name": "Rock_Ice_Permafrost",
      "rotation": 3
    },
    {
      "x": -3,
      "y": -7,
      "z": 0,
      "name": "Rock_Ice_Permafrost",
      "rotation": 3
    },
    {
      "x": -3,
      "y": -6,
      "z": 0,
      "name": "Rock_Ice_Permafrost",
      "rotation": 2
    },
    {
      "x": -3,
      "y": -5,
      "z": 0,
      "name": "Rock_Ice_Permafrost",
      "rotation": 2
    },
    {
      "x": -3,
      "y": -4,
      "z": 0,
      "name": "Rock_Ice_Permafrost",
      "rotation": 2
    },
    {
      "x": -3,
      "y": -3,
      "z": 0,
      "name": "Rock_Ice_Permafrost",
      "rotation": 2
    },
    {
      "x": -3,
      "y": -2,
      "z": 0,
      "name": "Rock_Ice_Permafrost",
      "rotation": 2
    },
    {
      "x": -3,
      "y": -1,
      "z": 0,
      "name": "Rock_Ice_Permafrost"
    },
    {
      "x": -3,
      "y": -9,
      "z": 1,
      "name": "Rock_Ice_Permafrost"
    },
    {
      "x": -3,
      "y": -8,
      "z": 1,
      "name": "Rock_Ice_Permafrost"
    },
    {
      "x": -3,
      "y": -7,
      "z": 1,
      "name": "Rock_Ice_Permafrost"
    },
    {
      "x": -3,
      "y": -6,
      "z": 1,
      "name": "Rock_Ice_Permafrost"
    },
    {
      "x": -3,
      "y": -5,
      "z": 1,
      "name": "Rock_Ice_Permafrost"
    },
    {
      "x": -3,
      "y": -4,
      "z": 1,
      "name": "Rock_Ice_Permafrost"
    },
    {
      "x": -3,
      "y": -3,
      "z": 1,
      "name": "Rock_Ice_Permafrost"
    },
    {
      "x": -3,
      "y": -2,
      "z": 1,
      "name": "Rock_Ice_Permafrost"
    },
    {
      "x": -2,
      "y": -5,
      "z": -2,
      "name": "Rock_Ice_Permafrost"
    },
    {
      "x": -2,
      "y": -4,
      "z": -2,
      "name": "Rock_Ice_Permafrost"
    },
    {
      "x": -2,
      "y": -3,
      "z": -2,
      "name": "Rock_Ice_Permafrost"
    },
    {
      "x": -2,
      "y": -10,
      "z": -1,
      "name": "Rock_Ice_Permafrost",
      "rotation": 3
    },
    {
      "x": -2,
      "y": -9,
      "z": -1,
      "name": "Rock_Ice_Permafrost",
      "rotation": 3
    },
    {
      "x": -2,
      "y": -8,
      "z": -1,
      "name": "Rock_Ice_Permafrost",
      "rotation": 3
    },
    {
      "x": -2,
      "y": -7,
      "z": -1,
      "name": "Rock_Ice_Permafrost",
      "rotation": 3
    },
    {
      "x": -2,
      "y": -6,
      "z": -1,
      "name": "Rock_Ice_Permafrost",
      "rotation": 3
    },
    {
      "x": -2,
      "y": -5,
      "z": -1,
      "name": "Rock_Ice_Permafrost",
      "rotation": 3
    },
    {
      "x": -2,
      "y": -4,
      "z": -1,
      "name": "Rock_Ice_Permafrost",
      "rotation": 2
    },
    {
      "x": -2,
      "y": -3,
      "z": -1,
      "name": "Rock_Ice_Permafrost",
      "rotation": 3
    },
    {
      "x": -2,
      "y": -2,
      "z": -1,
      "name": "Rock_Ice_Permafrost",
      "rotation": 3
    },
    {
      "x": -2,
      "y": -1,
      "z": -1,
      "name": "Rock_Ice_Permafrost"
    },
    {
      "x": -2,
      "y": -10,
      "z": 0,
      "name": "Rock_Ice_Permafrost",
      "rotation": 3
    },
    {
      "x": -2,
      "y": -9,
      "z": 0,
      "name": "Rock_Ice_Permafrost",
      "rotation": 3
    },
    {
      "x": -2,
      "y": -8,
      "z": 0,
      "name": "Rock_Ice_Permafrost",
      "rotation": 3
    },
    {
      "x": -2,
      "y": -7,
      "z": 0,
      "name": "Rock_Ice_Permafrost",
      "rotation": 3
    },
    {
      "x": -2,
      "y": -6,
      "z": 0,
      "name": "Rock_Ice_Permafrost",
      "rotation": 3
    },
    {
      "x": -2,
      "y": -5,
      "z": 0,
      "name": "Rock_Ice_Permafrost",
      "rotation": 3
    },
    {
      "x": -2,
      "y": -4,
      "z": 0,
      "name": "Rock_Ice_Permafrost",
      "rotation": 2
    },
    {
      "x": -2,
      "y": -3,
      "z": 0,
      "name": "Rock_Ice_Permafrost",
      "rotation": 2
    },
    {
      "x": -2,
      "y": -2,
      "z": 0,
      "name": "Rock_Ice_Permafrost",
      "rotation": 2
    },
    {
      "x": -2,
      "y": -1,
      "z": 0,
      "name": "Rock_Ice_Permafrost",
      "rotation": 2
    },
    {
      "x": -2,
      "y": 0,
      "z": 0,
      "name": "Rock_Ice_Permafrost"
    },
    {
      "x": -2,
      "y": 1,
      "z": 0,
      "name": "Rock_Ice_Permafrost"
    },
    {
      "x": -2,
      "y": -5,
      "z": 1,
      "name": "Rock_Ice_Permafrost"
    },
    {
      "x": -2,
      "y": -4,
      "z": 1,
      "name": "Rock_Ice_Permafrost"
    },
    {
      "x": -2,
      "y": -3,
      "z": 1,
      "name": "Rock_Ice_Permafrost"
    },
    {
      "x": -2,
      "y": -2,
      "z": 1,
      "name": "Rock_Ice_Permafrost"
    },
    {
      "x": -1,
      "y": -3,
      "z": -2,
      "name": "Rock_Ice_Permafrost"
    },
    {
      "x": -1,
      "y": -2,
      "z": -2,
      "name": "Rock_Ice_Permafrost"
    },
    {
      "x": -1,
      "y": -10,
      "z": -1,
      "name": "Rock_Ice_Permafrost",
      "rotation": 3
    },
    {
      "x": -1,
      "y": -9,
      "z": -1,
      "name": "Rock_Ice_Permafrost",
      "rotation": 3
    },
    {
      "x": -1,
      "y": -8,
      "z": -1,
      "name": "Rock_Ice_Permafrost",
      "rotation": 3
    },
    {
      "x": -1,
      "y": -7,
      "z": -1,
      "name": "Rock_Ice_Permafrost",
      "rotation": 3
    },
    {
      "x": -1,
      "y": -6,
      "z": -1,
      "name": "Rock_Ice_Permafrost",
      "rotation": 3
    },
    {
      "x": -1,
      "y": -5,
      "z": -1,
      "name": "Rock_Ice_Permafrost",
      "rotation": 3
    },
    {
      "x": -1,
      "y": -4,
      "z": -1,
      "name": "Rock_Ice_Permafrost",
      "rotation": 2
    },
    {
      "x": -1,
      "y": -3,
      "z": -1,
      "name": "Rock_Ice_Permafrost",
      "rotation": 3
    },
    {
      "x": -1,
      "y": -2,
      "z": -1,
      "name": "Rock_Ice_Permafrost",
      "rotation": 3
    },
    {
      "x": -1,
      "y": -1,
      "z": -1,
      "name": "Rock_Ice_Permafrost",
      "rotation": 3
    },
    {
      "x": -1,
      "y": 0,
      "z": -1,
      "name": "Rock_Ice_Permafrost"
    },
    {
      "x": -1,
      "y": -10,
      "z": 0,
      "name": "Rock_Ice_Permafrost",
      "rotation": 3
    },
    {
      "x": -1,
      "y": -9,
      "z": 0,
      "name": "Rock_Ice_Permafrost",
      "rotation": 3
    },
    {
      "x": -1,
      "y": -8,
      "z": 0,
      "name": "Rock_Ice_Permafrost",
      "rotation": 3
    },
    {
      "x": -1,
      "y": -7,
      "z": 0,
      "name": "Rock_Ice_Permafrost",
      "rotation": 3
    },
    {
      "x": -1,
      "y": -6,
      "z": 0,
      "name": "Rock_Ice_Permafrost",
      "rotation": 3
    },
    {
      "x": -1,
      "y": -5,
      "z": 0,
      "name": "Rock_Ice_Permafrost",
      "rotation": 3
    },
    {
      "x": -1,
      "y": -4,
      "z": 0,
      "name": "Rock_Ice_Permafrost",
      "rotation": 2
    },
    {
      "x": -1,
      "y": -3,
      "z": 0,
      "name": "Rock_Ice_Permafrost",
      "rotation": 2
    },
    {
      "x": -1,
      "y": -2,
      "z": 0,
      "name": "Rock_Ice_Permafrost",
      "rotation": 3
    },
    {
      "x": -1,
      "y": -1,
      "z": 0,
      "name": "Rock_Ice_Permafrost",
      "rotation": 3
    },
    {
      "x": -1,
      "y": 0,
      "z": 0,
      "name": "Rock_Ice_Permafrost"
    },
    {
      "x": -1,
      "y": 1,
      "z": 0,
      "name": "Rock_Ice_Permafrost"
    },
    {
      "x": -1,
      "y": 2,
      "z": 0,
      "name": "Rock_Ice_Permafrost"
    },
    {
      "x": -1,
      "y": 3,
      "z": 0,
      "name": "Rock_Ice_Permafrost"
    },
    {
      "x": -1,
      "y": -4,
      "z": 1,
      "name": "Rock_Ice_Permafrost"
    },
    {
      "x": -1,
      "y": -3,
      "z": 1,
      "name": "Rock_Ice_Permafrost"
    },
    {
      "x": -1,
      "y": -2,
      "z": 1,
      "name": "Rock_Ice_Permafrost"
    },
    {
      "x": 0,
      "y": -3,
      "z": -2,
      "name": "Rock_Ice_Permafrost"
    },
    {
      "x": 0,
      "y": -2,
      "z": -2,
      "name": "Rock_Ice_Permafrost"
    },
    {
      "x": 0,
      "y": -1,
      "z": -2,
      "name": "Rock_Ice_Permafrost"
    },
    {
      "x": 0,
      "y": -8,
      "z": -1,
      "name": "Rock_Ice_Permafrost",
      "rotation": 3
    },
    {
      "x": 0,
      "y": -7,
      "z": -1,
      "name": "Rock_Ice_Permafrost",
      "rotation": 3
    },
    {
      "x": 0,
      "y": -6,
      "z": -1,
      "name": "Rock_Ice_Permafrost",
      "rotation": 3
    },
    {
      "x": 0,
      "y": -5,
      "z": -1,
      "name": "Rock_Ice_Permafrost",
      "rotation": 3
    },
    {
      "x": 0,
      "y": -4,
      "z": -1,
      "name": "Rock_Ice_Permafrost",
      "rotation": 2
    },
    {
      "x": 0,
      "y": -3,
      "z": -1,
      "name": "Rock_Ice_Permafrost",
      "rotation": 2
    },
    {
      "x": 0,
      "y": -2,
      "z": -1,
      "name": "Rock_Ice_Permafrost",
      "rotation": 3
    },
    {
      "x": 0,
      "y": -1,
      "z": -1,
      "name": "Rock_Ice_Permafrost",
      "rotation": 3
    },
    {
      "x": 0,
      "y": 0,
      "z": -1,
      "name": "Rock_Ice_Permafrost"
    },
    {
      "x": 0,
      "y": 1,
      "z": -1,
      "name": "Rock_Ice_Permafrost"
    },
    {
      "x": 0,
      "y": 2,
      "z": -1,
      "name": "Rock_Ice_Permafrost"
    },
    {
      "x": 0,
      "y": -9,
      "z": 0,
      "name": "Rock_Ice_Permafrost",
      "rotation": 3
    },
    {
      "x": 0,
      "y": -8,
      "z": 0,
      "name": "Rock_Ice_Permafrost",
      "rotation": 3
    },
    {
      "x": 0,
      "y": -7,
      "z": 0,
      "name": "Rock_Ice_Permafrost",
      "rotation": 3
    },
    {
      "x": 0,
      "y": -6,
      "z": 0,
      "name": "Rock_Ice_Permafrost",
      "rotation": 3
    },
    {
      "x": 0,
      "y": -5,
      "z": 0,
      "name": "Rock_Ice_Permafrost",
      "rotation": 3
    },
    {
      "x": 0,
      "y": -4,
      "z": 0,
      "name": "Rock_Ice_Permafrost",
      "rotation": 2
    },
    {
      "x": 0,
      "y": -3,
      "z": 0,
      "name": "Rock_Ice_Permafrost",
      "rotation": 2
    },
    {
      "x": 0,
      "y": -2,
      "z": 0,
      "name": "Rock_Ice_Permafrost",
      "rotation": 3
    },
    {
      "x": 0,
      "y": -1,
      "z": 0,
      "name": "Rock_Ice_Permafrost",
      "rotation": 3
    },
    {
      "x": 0,
      "y": 0,
      "z": 0,
      "name": "Rock_Ice_Permafrost",
      "rotation": 3
    },
    {
      "x": 0,
      "y": 1,
      "z": 0,
      "name": "Rock_Ice_Permafrost"
    },
    {
      "x": 0,
      "y": 2,
      "z": 0,
      "name": "Rock_Ice_Permafrost"
    },
    {
      "x": 0,
      "y": 3,
      "z": 0,
      "name": "Rock_Ice_Permafrost"
    },
    {
      "x": 0,
      "y": 4,
      "z": 0,
      "name": "Rock_Ice_Permafrost"
    },
    {
      "x": 0,
      "y": -3,
      "z": 1,
      "name": "Rock_Ice_Permafrost"
    },
    {
      "x": 0,
      "y": -2,
      "z": 1,
      "name": "Rock_Ice_Permafrost"
    },
    {
      "x": 1,
      "y": -2,
      "z": -2,
      "name": "Rock_Ice_Permafrost",
      "rotation": 3
    },
    {
      "x": 1,
      "y": -1,
      "z": -2,
      "name": "Rock_Ice_Permafrost",
      "rotation": 3
    },
    {
      "x": 1,
      "y": 0,
      "z": -2,
      "name": "Rock_Ice_Permafrost",
      "rotation": 3
    },
    {
      "x": 1,
      "y": 1,
      "z": -2,
      "name": "Rock_Ice_Permafrost",
      "rotation": 3
    },
    {
      "x": 1,
      "y": 2,
      "z": -2,
      "name": "Rock_Ice_Permafrost",
      "rotation": 3
    },
    {
      "x": 1,
      "y": -5,
      "z": -1,
      "name": "Rock_Ice_Permafrost",
      "rotation": 3
    },
    {
      "x": 1,
      "y": -4,
      "z": -1,
      "name": "Rock_Ice_Permafrost",
      "rotation": 2
    },
    {
      "x": 1,
      "y": -3,
      "z": -1,
      "name": "Rock_Ice_Permafrost",
      "rotation": 2
    },
    {
      "x": 1,
      "y": -2,
      "z": -1,
      "name": "Rock_Ice_Permafrost",
      "rotation": 3
    },
    {
      "x": 1,
      "y": -1,
      "z": -1,
      "name": "Rock_Ice_Permafrost",
      "rotation": 3
    },
    {
      "x": 1,
      "y": 0,
      "z": -1,
      "name": "Rock_Ice_Permafrost",
      "rotation": 3
    },
    {
      "x": 1,
      "y": 1,
      "z": -1,
      "name": "Rock_Ice_Permafrost",
      "rotation": 3
    },
    {
      "x": 1,
      "y": 2,
      "z": -1,
      "name": "Rock_Ice_Permafrost",
      "rotation": 3
    },
    {
      "x": 1,
      "y": 3,
      "z": -1,
      "name": "Rock_Ice_Permafrost",
      "rotation": 2
    },
    {
      "x": 1,
      "y": 4,
      "z": -1,
      "name": "Rock_Ice_Permafrost"
    },
    {
      "x": 1,
      "y": -7,
      "z": 0,
      "name": "Rock_Ice_Permafrost",
      "rotation": 3
    },
    {
      "x": 1,
      "y": -6,
      "z": 0,
      "name": "Rock_Ice_Permafrost",
      "rotation": 3
    },
    {
      "x": 1,
      "y": -5,
      "z": 0,
      "name": "Rock_Ice_Permafrost",
      "rotation": 2
    },
    {
      "x": 1,
      "y": -4,
      "z": 0,
      "name": "Rock_Ice_Permafrost",
      "rotation": 2
    },
    {
      "x": 1,
      "y": -3,
      "z": 0,
      "name": "Rock_Ice_Permafrost",
      "rotation": 2
    },
    {
      "x": 1,
      "y": -2,
      "z": 0,
      "name": "Rock_Ice_Permafrost",
      "rotation": 3
    },
    {
      "x": 1,
      "y": -1,
      "z": 0,
      "name": "Rock_Ice_Permafrost",
      "rotation": 3
    },
    {
      "x": 1,
      "y": 0,
      "z": 0,
      "name": "Rock_Ice_Permafrost",
      "rotation": 3
    },
    {
      "x": 1,
      "y": 1,
      "z": 0,
      "name": "Rock_Ice_Permafrost",
      "rotation": 3
    },
    {
      "x": 1,
      "y": 2,
      "z": 0,
      "name": "Rock_Ice_Permafrost",
      "rotation": 3
    },
    {
      "x": 1,
      "y": 3,
      "z": 0,
      "name": "Rock_Ice_Permafrost",
      "rotation": 2
    },
    {
      "x": 1,
      "y": 4,
      "z": 0,
      "name": "Rock_Ice_Permafrost"
    },
    {
      "x": 1,
      "y": 5,
      "z": 0,
      "name": "Rock_Ice_Permafrost"
    },
    {
      "x": 1,
      "y": 6,
      "z": 0,
      "name": "Rock_Ice_Permafrost"
    },
    {
      "x": 1,
      "y": -5,
      "z": 1,
      "name": "Rock_Ice_Permafrost",
      "rotation": 2
    },
    {
      "x": 1,
      "y": -4,
      "z": 1,
      "name": "Rock_Ice_Permafrost",
      "rotation": 2
    },
    {
      "x": 1,
      "y": -3,
      "z": 1,
      "name": "Rock_Ice_Permafrost",
      "rotation": 2
    },
    {
      "x": 1,
      "y": -2,
      "z": 1,
      "name": "Rock_Ice_Permafrost",
      "rotation": 2
    },
    {
      "x": 1,
      "y": -1,
      "z": 1,
      "name": "Rock_Ice_Permafrost",
      "rotation": 2
    },
    {
      "x": 1,
      "y": 0,
      "z": 1,
      "name": "Rock_Ice_Permafrost",
      "rotation": 2
    },
    {
      "x": 1,
      "y": 1,
      "z": 1,
      "name": "Rock_Ice_Permafrost",
      "rotation": 2
    },
    {
      "x": 1,
      "y": 2,
      "z": 1,
      "name": "Rock_Ice_Permafrost",
      "rotation": 2
    },
    {
      "x": 1,
      "y": 3,
      "z": 1,
      "name": "Rock_Ice_Permafrost",
      "rotation": 2
    },
    {
      "x": 1,
      "y": 4,
      "z": 1,
      "name": "Rock_Ice_Permafrost",
      "rotation": 3
    },
    {
      "x": 1,
      "y": -2,
      "z": 2,
      "name": "Rock_Ice_Permafrost",
      "rotation": 2
    },
    {
      "x": 1,
      "y": -1,
      "z": 2,
      "name": "Rock_Ice_Permafrost",
      "rotation": 2
    },
    {
      "x": 1,
      "y": 0,
      "z": 2,
      "name": "Rock_Ice_Permafrost",
      "rotation": 2
    },
    {
      "x": 1,
      "y": 1,
      "z": 2,
      "name": "Rock_Ice_Permafrost",
      "rotation": 2
    },
    {
      "x": 1,
      "y": 2,
      "z": 2,
      "name": "Rock_Ice_Permafrost",
      "rotation": 3
    },
    {
      "x": 2,
      "y": 0,
      "z": -2,
      "name": "Rock_Ice_Permafrost",
      "rotation": 3
    },
    {
      "x": 2,
      "y": 1,
      "z": -2,
      "name": "Rock_Ice_Permafrost",
      "rotation": 3
    },
    {
      "x": 2,
      "y": 2,
      "z": -2,
      "name": "Rock_Ice_Permafrost",
      "rotation": 3
    },
    {
      "x": 2,
      "y": 3,
      "z": -2,
      "name": "Rock_Ice_Permafrost",
      "rotation": 3
    },
    {
      "x": 2,
      "y": 4,
      "z": -2,
      "name": "Rock_Ice_Permafrost",
      "rotation": 3
    },
    {
      "x": 2,
      "y": -3,
      "z": -1,
      "name": "Rock_Ice_Permafrost",
      "rotation": 2
    },
    {
      "x": 2,
      "y": -2,
      "z": -1,
      "name": "Rock_Ice_Permafrost",
      "rotation": 2
    },
    {
      "x": 2,
      "y": -1,
      "z": -1,
      "name": "Rock_Ice_Permafrost",
      "rotation": 2
    },
    {
      "x": 2,
      "y": 0,
      "z": -1,
      "name": "Rock_Ice_Permafrost",
      "rotation": 3
    },
    {
      "x": 2,
      "y": 1,
      "z": -1,
      "name": "Rock_Ice_Permafrost",
      "rotation": 3
    },
    {
      "x": 2,
      "y": 2,
      "z": -1,
      "name": "Rock_Ice_Permafrost",
      "rotation": 3
    },
    {
      "x": 2,
      "y": 3,
      "z": -1,
      "name": "Rock_Ice_Permafrost",
      "rotation": 3
    },
    {
      "x": 2,
      "y": 4,
      "z": -1,
      "name": "Rock_Ice_Permafrost",
      "rotation": 3
    },
    {
      "x": 2,
      "y": 5,
      "z": -1,
      "name": "Rock_Ice_Permafrost",
      "rotation": 2
    },
    {
      "x": 2,
      "y": 6,
      "z": -1,
      "name": "Rock_Ice_Permafrost",
      "rotation": 2
    },
    {
      "x": 2,
      "y": -4,
      "z": 0,
      "name": "Rock_Ice_Permafrost",
      "rotation": 3
    },
    {
      "x": 2,
      "y": -3,
      "z": 0,
      "name": "Rock_Ice_Permafrost",
      "rotation": 2
    },
    {
      "x": 2,
      "y": -2,
      "z": 0,
      "name": "Rock_Ice_Permafrost",
      "rotation": 2
    },
    {
      "x": 2,
      "y": -1,
      "z": 0,
      "name": "Rock_Ice_Permafrost",
      "rotation": 2
    },
    {
      "x": 2,
      "y": 0,
      "z": 0,
      "name": "Rock_Ice_Permafrost",
      "rotation": 3
    },
    {
      "x": 2,
      "y": 1,
      "z": 0,
      "name": "Rock_Ice_Permafrost",
      "rotation": 3
    },
    {
      "x": 2,
      "y": 2,
      "z": 0,
      "name": "Rock_Ice_Permafrost",
      "rotation": 3
    },
    {
      "x": 2,
      "y": 3,
      "z": 0,
      "name": "Rock_Ice_Permafrost",
      "rotation": 3
    },
    {
      "x": 2,
      "y": 4,
      "z": 0,
      "name": "Rock_Ice_Permafrost",
      "rotation": 3
    },
    {
      "x": 2,
      "y": 5,
      "z": 0,
      "name": "Rock_Ice_Permafrost",
      "rotation": 2
    },
    {
      "x": 2,
      "y": 6,
      "z": 0,
      "name": "Rock_Ice_Permafrost",
      "rotation": 2
    },
    {
      "x": 2,
      "y": 7,
      "z": 0,
      "name": "Rock_Ice_Permafrost",
      "rotation": 3
    },
    {
      "x": 2,
      "y": -3,
      "z": 1,
      "name": "Rock_Ice_Permafrost",
      "rotation": 2
    },
    {
      "x": 2,
      "y": -2,
      "z": 1,
      "name": "Rock_Ice_Permafrost",
      "rotation": 2
    },
    {
      "x": 2,
      "y": -1,
      "z": 1,
      "name": "Rock_Ice_Permafrost",
      "rotation": 2
    },
    {
      "x": 2,
      "y": 0,
      "z": 1,
      "name": "Rock_Ice_Permafrost",
      "rotation": 2
    },
    {
      "x": 2,
      "y": 1,
      "z": 1,
      "name": "Rock_Ice_Permafrost",
      "rotation": 2
    },
    {
      "x": 2,
      "y": 2,
      "z": 1,
      "name": "Rock_Ice_Permafrost",
      "rotation": 2
    },
    {
      "x": 2,
      "y": 3,
      "z": 1,
      "name": "Rock_Ice_Permafrost",
      "rotation": 2
    },
    {
      "x": 2,
      "y": 4,
      "z": 1,
      "name": "Rock_Ice_Permafrost",
      "rotation": 2
    },
    {
      "x": 2,
      "y": 5,
      "z": 1,
      "name": "Rock_Ice_Permafrost",
      "rotation": 2
    },
    {
      "x": 2,
      "y": 6,
      "z": 1,
      "name": "Rock_Ice_Permafrost",
      "rotation": 2
    },
    {
      "x": 2,
      "y": 0,
      "z": 2,
      "name": "Rock_Ice_Permafrost",
      "rotation": 2
    },
    {
      "x": 2,
      "y": 1,
      "z": 2,
      "name": "Rock_Ice_Permafrost",
      "rotation": 2
    },
    {
      "x": 2,
      "y": 2,
      "z": 2,
      "name": "Rock_Ice_Permafrost",
      "rotation": 2
    },
    {
      "x": 2,
      "y": 3,
      "z": 2,
      "name": "Rock_Ice_Permafrost",
      "rotation": 2
    },
    {
      "x": 2,
      "y": 4,
      "z": 2,
      "name": "Rock_Ice_Permafrost",
      "rotation": 3
    },
    {
      "x": 3,
      "y": 0,
      "z": -2,
      "name": "Rock_Ice_Permafrost",
      "rotation": 3
    },
    {
      "x": 3,
      "y": 1,
      "z": -2,
      "name": "Rock_Ice_Permafrost",
      "rotation": 3
    },
    {
      "x": 3,
      "y": 2,
      "z": -2,
      "name": "Rock_Ice_Permafrost",
      "rotation": 3
    },
    {
      "x": 3,
      "y": 3,
      "z": -2,
      "name": "Rock_Ice_Permafrost",
      "rotation": 3
    },
    {
      "x": 3,
      "y": 4,
      "z": -2,
      "name": "Rock_Ice_Permafrost",
      "rotation": 3
    },
    {
      "x": 3,
      "y": -2,
      "z": -1,
      "name": "Rock_Ice_Permafrost",
      "rotation": 2
    },
    {
      "x": 3,
      "y": -1,
      "z": -1,
      "name": "Rock_Ice_Permafrost",
      "rotation": 2
    },
    {
      "x": 3,
      "y": 0,
      "z": -1,
      "name": "Rock_Ice_Permafrost",
      "rotation": 3
    },
    {
      "x": 3,
      "y": 1,
      "z": -1,
      "name": "Rock_Ice_Permafrost",
      "rotation": 3
    },
    {
      "x": 3,
      "y": 2,
      "z": -1,
      "name": "Rock_Ice_Permafrost",
      "rotation": 3
    },
    {
      "x": 3,
      "y": 3,
      "z": -1,
      "name": "Rock_Ice_Permafrost",
      "rotation": 3
    },
    {
      "x": 3,
      "y": 4,
      "z": -1,
      "name": "Rock_Ice_Permafrost",
      "rotation": 3
    },
    {
      "x": 3,
      "y": 5,
      "z": -1,
      "name": "Rock_Ice_Permafrost",
      "rotation": 2
    },
    {
      "x": 3,
      "y": 6,
      "z": -1,
      "name": "Rock_Ice_Permafrost",
      "rotation": 2
    },
    {
      "x": 3,
      "y": 7,
      "z": -1,
      "name": "Rock_Ice_Permafrost",
      "rotation": 2
    },
    {
      "x": 3,
      "y": 8,
      "z": -1,
      "name": "Rock_Ice_Permafrost",
      "rotation": 2
    },
    {
      "x": 3,
      "y": -2,
      "z": 0,
      "name": "Rock_Ice_Permafrost",
      "rotation": 2
    },
    {
      "x": 3,
      "y": -1,
      "z": 0,
      "name": "Rock_Ice_Permafrost",
      "rotation": 2
    },
    {
      "x": 3,
      "y": 0,
      "z": 0,
      "name": "Rock_Ice_Permafrost",
      "rotation": 3
    },
    {
      "x": 3,
      "y": 1,
      "z": 0,
      "name": "Rock_Ice_Permafrost",
      "rotation": 3
    },
    {
      "x": 3,
      "y": 2,
      "z": 0,
      "name": "Rock_Ice_Permafrost",
      "rotation": 3
    },
    {
      "x": 3,
      "y": 3,
      "z": 0,
      "name": "Rock_Ice_Permafrost",
      "rotation": 3
    },
    {
      "x": 3,
      "y": 4,
      "z": 0,
      "name": "Rock_Ice_Permafrost",
      "rotation": 3
    },
    {
      "x": 3,
      "y": 5,
      "z": 0,
      "name": "Rock_Ice_Permafrost",
      "rotation": 2
    },
    {
      "x": 3,
      "y": 6,
      "z": 0,
      "name": "Rock_Ice_Permafrost",
      "rotation": 2
    },
    {
      "x": 3,
      "y": 7,
      "z": 0,
      "name": "Rock_Ice_Permafrost",
      "rotation": 2
    },
    {
      "x": 3,
      "y": 8,
      "z": 0,
      "name": "Rock_Ice_Permafrost",
      "rotation": 2
    },
    {
      "x": 3,
      "y": -2,
      "z": 1,
      "name": "Rock_Ice_Permafrost",
      "rotation": 2
    },
    {
      "x": 3,
      "y": -1,
      "z": 1,
      "name": "Rock_Ice_Permafrost",
      "rotation": 2
    },
    {
      "x": 3,
      "y": 0,
      "z": 1,
      "name": "Rock_Ice_Permafrost",
      "rotation": 2
    },
    {
      "x": 3,
      "y": 1,
      "z": 1,
      "name": "Rock_Ice_Permafrost",
      "rotation": 2
    },
    {
      "x": 3,
      "y": 2,
      "z": 1,
      "name": "Rock_Ice_Permafrost",
      "rotation": 2
    },
    {
      "x": 3,
      "y": 3,
      "z": 1,
      "name": "Rock_Ice_Permafrost",
      "rotation": 2
    },
    {
      "x": 3,
      "y": 4,
      "z": 1,
      "name": "Rock_Ice_Permafrost",
      "rotation": 2
    },
    {
      "x": 3,
      "y": 5,
      "z": 1,
      "name": "Rock_Ice_Permafrost",
      "rotation": 2
    },
    {
      "x": 3,
      "y": 6,
      "z": 1,
      "name": "Rock_Ice_Permafrost",
      "rotation": 2
    },
    {
      "x": 3,
      "y": 7,
      "z": 1,
      "name": "Rock_Ice_Permafrost",
      "rotation": 2
    },
    {
      "x": 3,
      "y": 8,
      "z": 1,
      "name": "Rock_Ice_Permafrost",
      "rotation": 2
    },
    {
      "x": 3,
      "y": 0,
      "z": 2,
      "name": "Rock_Ice_Permafrost",
      "rotation": 2
    },
    {
      "x": 3,
      "y": 1,
      "z": 2,
      "name": "Rock_Ice_Permafrost",
      "rotation": 2
    },
    {
      "x": 3,
      "y": 2,
      "z": 2,
      "name": "Rock_Ice_Permafrost",
      "rotation": 2
    },
    {
      "x": 3,
      "y": 3,
      "z": 2,
      "name": "Rock_Ice_Permafrost",
      "rotation": 2
    },
    {
      "x": 3,
      "y": 4,
      "z": 2,
      "name": "Rock_Ice_Permafrost",
      "rotation": 2
    },
    {
      "x": 4,
      "y": 2,
      "z": -2,
      "name": "Rock_Ice_Permafrost",
      "rotation": 3
    },
    {
      "x": 4,
      "y": 3,
      "z": -2,
      "name": "Rock_Ice_Permafrost",
      "rotation": 3
    },
    {
      "x": 4,
      "y": 4,
      "z": -2,
      "name": "Rock_Ice_Permafrost",
      "rotation": 3
    },
    {
      "x": 4,
      "y": 0,
      "z": -1,
      "name": "Rock_Ice_Permafrost",
      "rotation": 2
    },
    {
      "x": 4,
      "y": 1,
      "z": -1,
      "name": "Rock_Ice_Permafrost",
      "rotation": 2
    },
    {
      "x": 4,
      "y": 2,
      "z": -1,
      "name": "Rock_Ice_Permafrost",
      "rotation": 3
    },
    {
      "x": 4,
      "y": 3,
      "z": -1,
      "name": "Rock_Ice_Permafrost",
      "rotation": 3
    },
    {
      "x": 4,
      "y": 4,
      "z": -1,
      "name": "Rock_Ice_Permafrost"
    },
    {
      "x": 4,
      "y": 5,
      "z": -1,
      "name": "Rock_Ice_Permafrost",
      "rotation": 2
    },
    {
      "x": 4,
      "y": 6,
      "z": -1,
      "name": "Rock_Ice_Permafrost",
      "rotation": 2
    },
    {
      "x": 4,
      "y": 7,
      "z": -1,
      "name": "Rock_Ice_Permafrost",
      "rotation": 2
    },
    {
      "x": 4,
      "y": 8,
      "z": -1,
      "name": "Rock_Ice_Permafrost",
      "rotation": 2
    },
    {
      "x": 4,
      "y": 9,
      "z": -1,
      "name": "Rock_Ice_Permafrost",
      "rotation": 2
    },
    {
      "x": 4,
      "y": -1,
      "z": 0,
      "name": "Rock_Ice_Permafrost",
      "rotation": 2
    },
    {
      "x": 4,
      "y": 0,
      "z": 0,
      "name": "Rock_Ice_Permafrost",
      "rotation": 2
    },
    {
      "x": 4,
      "y": 1,
      "z": 0,
      "name": "Rock_Ice_Permafrost",
      "rotation": 2
    },
    {
      "x": 4,
      "y": 2,
      "z": 0,
      "name": "Rock_Ice_Permafrost",
      "rotation": 3
    },
    {
      "x": 4,
      "y": 3,
      "z": 0,
      "name": "Rock_Ice_Permafrost",
      "rotation": 3
    },
    {
      "x": 4,
      "y": 4,
      "z": 0,
      "name": "Rock_Ice_Permafrost",
      "rotation": 3
    },
    {
      "x": 4,
      "y": 5,
      "z": 0,
      "name": "Rock_Ice_Permafrost",
      "rotation": 2
    },
    {
      "x": 4,
      "y": 6,
      "z": 0,
      "name": "Rock_Ice_Permafrost",
      "rotation": 2
    },
    {
      "x": 4,
      "y": 7,
      "z": 0,
      "name": "Rock_Ice_Permafrost",
      "rotation": 2
    },
    {
      "x": 4,
      "y": 8,
      "z": 0,
      "name": "Rock_Ice_Permafrost",
      "rotation": 2
    },
    {
      "x": 4,
      "y": 9,
      "z": 0,
      "name": "Rock_Ice_Permafrost",
      "rotation": 2
    },
    {
      "x": 4,
      "y": 10,
      "z": 0,
      "name": "Rock_Ice_Permafrost",
      "rotation": 2
    },
    {
      "x": 4,
      "y": 11,
      "z": 0,
      "name": "Rock_Ice_Permafrost",
      "rotation": 2
    },
    {
      "x": 4,
      "y": 12,
      "z": 0,
      "name": "Rock_Ice_Permafrost",
      "rotation": 2
    },
    {
      "x": 4,
      "y": 13,
      "z": 0,
      "name": "Rock_Ice_Permafrost",
      "rotation": 2
    },
    {
      "x": 4,
      "y": 14,
      "z": 0,
      "name": "Rock_Ice_Permafrost",
      "rotation": 2
    },
    {
      "x": 4,
      "y": 15,
      "z": 0,
      "name": "Rock_Ice_Permafrost",
      "rotation": 2
    },
    {
      "x": 4,
      "y": 16,
      "z": 0,
      "name": "Rock_Ice_Permafrost",
      "rotation": 3
    },
    {
      "x": 4,
      "y": 17,
      "z": 0,
      "name": "Fullmetal_White_Crystal_Lamp"
    },
    {
      "x": 4,
      "y": 0,
      "z": 1,
      "name": "Rock_Ice_Permafrost",
      "rotation": 2
    },
    {
      "x": 4,
      "y": 1,
      "z": 1,
      "name": "Rock_Ice_Permafrost",
      "rotation": 2
    },
    {
      "x": 4,
      "y": 2,
      "z": 1,
      "name": "Rock_Ice_Permafrost",
      "rotation": 2
    },
    {
      "x": 4,
      "y": 3,
      "z": 1,
      "name": "Rock_Ice_Permafrost",
      "rotation": 2
    },
    {
      "x": 4,
      "y": 4,
      "z": 1,
      "name": "Rock_Ice_Permafrost",
      "rotation": 2
    },
    {
      "x": 4,
      "y": 5,
      "z": 1,
      "name": "Rock_Ice_Permafrost",
      "rotation": 2
    },
    {
      "x": 4,
      "y": 6,
      "z": 1,
      "name": "Rock_Ice_Permafrost",
      "rotation": 2
    },
    {
      "x": 4,
      "y": 7,
      "z": 1,
      "name": "Rock_Ice_Permafrost",
      "rotation": 2
    },
    {
      "x": 4,
      "y": 8,
      "z": 1,
      "name": "Rock_Ice_Permafrost",
      "rotation": 2
    },
    {
      "x": 4,
      "y": 9,
      "z": 1,
      "name": "Rock_Ice_Permafrost",
      "rotation": 2
    },
    {
      "x": 4,
      "y": 1,
      "z": 2,
      "name": "Rock_Ice_Icicles",
      "rotation": 33
    },
    {
      "x": 4,
      "y": 2,
      "z": 2,
      "name": "Rock_Ice_Permafrost",
      "rotation": 2
    },
    {
      "x": 4,
      "y": 3,
      "z": 2,
      "name": "Rock_Ice_Permafrost",
      "rotation": 2
    },
    {
      "x": 4,
      "y": 4,
      "z": 2,
      "name": "Rock_Ice_Permafrost",
      "rotation": 2
    },
    {
      "x": 5,
      "y": 7,
      "z": -1,
      "name": "Rock_Ice_Icicles",
      "rotation": 8
    },
    {
      "x": 5,
      "y": 8,
      "z": -1,
      "name": "Rock_Ice_Permafrost",
      "rotation": 2
    },
    {
      "x": 5,
      "y": 9,
      "z": -1,
      "name": "Rock_Ice_Permafrost",
      "rotation": 2
    },
    {
      "x": 5,
      "y": 10,
      "z": -1,
      "name": "Rock_Ice_Permafrost",
      "rotation": 2
    },
    {
      "x": 5,
      "y": 1,
      "z": 0,
      "name": "Rock_Ice_Icicles",
      "rotation": 33
    },
    {
      "x": 5,
      "y": 2,
      "z": 0,
      "name": "Rock_Ice_Permafrost",
      "rotation": 2
    },
    {
      "x": 5,
      "y": 3,
      "z": 0,
      "name": "Rock_Ice_Permafrost",
      "rotation": 2
    },
    {
      "x": 5,
      "y": 4,
      "z": 0,
      "name": "Rock_Ice_Permafrost",
      "rotation": 2
    },
    {
      "x": 5,
      "y": 5,
      "z": 0,
      "name": "Rock_Ice_Permafrost",
      "rotation": 2
    },
    {
      "x": 5,
      "y": 6,
      "z": 0,
      "name": "Rock_Ice_Permafrost",
      "rotation": 2
    },
    {
      "x": 5,
      "y": 7,
      "z": 0,
      "name": "Rock_Ice_Permafrost",
      "rotation": 2
    },
    {
      "x": 5,
      "y": 8,
      "z": 0,
      "name": "Rock_Ice_Permafrost",
      "rotation": 2
    },
    {
      "x": 5,
      "y": 9,
      "z": 0,
      "name": "Rock_Ice_Permafrost",
      "rotation": 2
    },
    {
      "x": 5,
      "y": 10,
      "z": 0,
      "name": "Rock_Ice_Permafrost",
      "rotation": 2
    },
    {
      "x": 5,
      "y": 11,
      "z": 0,
      "name": "Rock_Ice_Permafrost",
      "rotation": 2
    },
    {
      "x": 5,
      "y": 12,
      "z": 0,
      "name": "Rock_Ice_Permafrost",
      "rotation": 2
    },
    {
      "x": 5,
      "y": 13,
      "z": 0,
      "name": "Rock_Ice_Permafrost",
      "rotation": 3
    },
    {
      "x": 5,
      "y": 14,
      "z": 0,
      "name": "Fullmetal_Cyan_Crystal_Lamp"
    },
    {
      "x": 5,
      "y": 4,
      "z": 1,
      "name": "Rock_Ice_Icicles",
      "rotation": 33
    },
    {
      "x": 5,
      "y": 5,
      "z": 1,
      "name": "Rock_Ice_Permafrost",
      "rotation": 2
    },
    {
      "x": 5,
      "y": 6,
      "z": 1,
      "name": "Rock_Ice_Permafrost",
      "rotation": 2
    },
    {
      "x": 5,
      "y": 7,
      "z": 1,
      "name": "Rock_Ice_Permafrost",
      "rotation": 2
    },
    {
      "x": 5,
      "y": 8,
      "z": 1,
      "name": "Rock_Ice_Permafrost",
      "rotation": 2
    },
    {
      "x": 5,
      "y": 9,
      "z": 1,
      "name": "Rock_Ice_Permafrost",
      "rotation": 2
    },
    {
      "x": 5,
      "y": 10,
      "z": 1,
      "name": "Rock_Ice_Permafrost",
      "rotation": 2
    },
    {
      "x": 5,
      "y": 11,
      "z": 1,
      "name": "Rock_Ice_Permafrost",
      "rotation": 3
    },
    {
      "x": 5,
      "y": 12,
      "z": 1,
      "name": "Fullmetal_Cyan_Crystal_Lamp"
    },
    {
      "x": 6,
      "y": 7,
      "z": 0,
      "name": "Fullmetal_Blue_Crystal_Lamp",
      "rotation": 8
    },
    {
      "x": 6,
      "y": 8,
      "z": 0,
      "name": "Rock_Ice_Permafrost"
    },
    {
      "x": 6,
      "y": 9,
      "z": 0,
      "name": "Rock_Ice_Permafrost"
    }
  ]
}