{
  "version": 8,
  "blockIdVersion": 11,
  "anchorX": 0,
  "anchorY": 0,
  "anchorZ": 0,
  "blocks": [
    {
      "x": -18,
      "y": -24,
      "z": 12,
      "name": "Rock_Ice"
    },
    {
      "x": -18,
      "y": -23,
      "z": 12,
      "name": "Rock_Ice"
    },
    {
      "x": -18,
      "y": -22,
      "z": 12,
      "name": "Rock_Ice"
    },
    {
      "x": -18,
      "y": -21,
      "z": 12,
      "name": "Rock_Ice"
    },
    {
      "x": -17,
      "y": -25,
      "z": 10,
      "name": "Rock_Ice"
    },
    {
      "x": -17,
      "y": -24,
      "z": 10,
      "name": "Rock_Ice"
    },
    {
      "x": -17,
      "y": -23,
      "z": 10,
      "name": "Rock_Ice"
    },
    {
      "x": -17,
      "y": -22,
      "z": 10,
      "name": "Rock_Ice"
    },
    {
      "x": -17,
      "y": -21,
      "z": 10,
      "name": "Rock_Ice"
    },
    {
      "x": -17,
      "y": -26,
      "z": 11,
      "name": "Rock_Ice"
    },
    {
      "x": -17,
      "y": -25,
      "z": 11,
      "name": "Rock_Ice"
    },
    {
      "x": -17,
      "y": -24,
      "z": 11,
      "name": "Rock_Ice"
    },
    {
      "x": -17,
      "y": -23,
      "z": 11,
      "name": "Rock_Ice"
    },
    {
      "x": -17,
      "y": -22,
      "z": 11,
      "name": "Rock_Ice"
    },
    {
      "x": -17,
      "y": -21,
      "z": 11,
      "name": "Rock_Ice"
    },
    {
      "x": -17,
      "y": -20,
      "z": 11,
      "name": "Rock_Ice"
    },
    {
      "x": -17,
      "y": -25,
      "z": 12,
      "name": "Rock_Ice"
    },
    {
      "x": -17,
      "y": -24,
      "z": 12,
      "name": "Rock_Ice"
    },
    {
      "x": -17,
      "y": -23,
      "z": 12,
      "name": "Rock_Ice"
    },
    {
      "x": -17,
      "y": -22,
      "z": 12,
      "name": "Rock_Ice"
    },
    {
      "x": -17,
      "y": -21,
      "z": 12,
      "name": "Rock_Ice"
    },
    {
      "x": -17,
      "y": -20,
      "z": 12,
      "name": "Rock_Ice"
    },
    {
      "x": -17,
      "y": -19,
      "z": 12,
      "name": "Rock_Ice"
    },
    {
      "x": -16,
      "y": -24,
      "z": 9,
      "name": "Rock_Ice"
    },
    {
      "x": -16,
      "y": -23,
      "z": 9,
      "name": "Rock_Ice"
    },
    {
      "x": -16,
      "y": -22,
      "z": 9,
      "name": "Rock_Ice"
    },
    {
      "x": -16,
      "y": -21,
      "z": 9,
      "name": "Rock_Ice"
    },
    {
      "x": -16,
      "y": -20,
      "z": 9,
      "name": "Rock_Ice"
    },
    {
      "x": -16,
      "y": -25,
      "z": 10,
      "name": "Rock_Ice"
    },
    {
      "x": -16,
      "y": -24,
      "z": 10,
      "name": "Rock_Ice"
    },
    {
      "x": -16,
      "y": -23,
      "z": 10,
      "name": "Rock_Ice"
    },
    {
      "x": -16,
      "y": -22,
      "z": 10,
      "name": "Rock_Ice"
    },
    {
      "x": -16,
      "y": -21,
      "z": 10,
      "name": "Rock_Ice"
    },
    {
      "x": -16,
      "y": -20,
      "z": 10,
      "name": "Rock_Ice"
    },
    {
      "x": -16,
      "y": -19,
      "z": 10,
      "name": "Rock_Ice"
    },
    {
      "x": -16,
      "y": -26,
      "z": 11,
      "name": "Rock_Ice"
    },
    {
      "x": -16,
      "y": -25,
      "z": 11,
      "name": "Rock_Ice"
    },
    {
      "x": -16,
      "y": -24,
      "z": 11,
      "name": "Rock_Ice"
    },
    {
      "x": -16,
      "y": -23,
      "z": 11,
      "name": "Rock_Ice"
    },
    {
      "x": -16,
      "y": -22,
      "z": 11,
      "name": "Rock_Ice"
    },
    {
      "x": -16,
      "y": -21,
      "z": 11,
      "name": "Rock_Ice"
    },
    {
      "x": -16,
      "y": -20,
      "z": 11,
      "name": "Rock_Ice"
    },
    {
      "x": -16,
      "y": -19,
      "z": 11,
      "name": "Rock_Ice"
    },
    {
      "x": -16,
      "y": -18,
      "z": 11,
      "name": "Rock_Ice"
    },
    {
      "x": -16,
      "y": -27,
      "z": 12,
      "name": "Rock_Ice"
    },
    {
      "x": -16,
      "y": -26,
      "z": 12,
      "name": "Rock_Ice"
    },
    {
      "x": -16,
      "y": -25,
      "z": 12,
      "name": "Rock_Ice"
    },
    {
      "x": -16,
      "y": -24,
      "z": 12,
      "name": "Rock_Ice"
    },
    {
      "x": -16,
      "y": -23,
      "z": 12,
      "name": "Rock_Ice"
    },
    {
      "x": -16,
      "y": -22,
      "z": 12,
      "name": "Rock_Ice"
    },
    {
      "x": -16,
      "y": -21,
      "z": 12,
      "name": "Rock_Ice"
    },
    {
      "x": -16,
      "y": -20,
      "z": 12,
      "name": "Rock_Ice"
    },
    {
      "x": -16,
      "y": -19,
      "z": 12,
      "name": "Rock_Ice"
    },
    {
      "x": -16,
      "y": -18,
      "z": 12,
      "name": "Rock_Ice"
    },
    {
      "x": -15,
      "y": -25,
      "z": 8,
      "name": "Rock_Ice"
    },
    {
      "x": -15,
      "y": -24,
      "z": 8,
      "name": "Rock_Ice"
    },
    {
      "x": -15,
      "y": -23,
      "z": 8,
      "name": "Rock_Ice"
    },
    {
      "x": -15,
      "y": -26,
      "z": 9,
      "name": "Rock_Ice"
    },
    {
      "x": -15,
      "y": -25,
      "z": 9,
      "name": "Rock_Ice"
    },
    {
      "x": -15,
      "y": -24,
      "z": 9,
      "name": "Rock_Ice"
    },
    {
      "x": -15,
      "y": -23,
      "z": 9,
      "name": "Rock_Ice"
    },
    {
      "x": -15,
      "y": -22,
      "z": 9,
      "name": "Rock_Ice"
    },
    {
      "x": -15,
      "y": -21,
      "z": 9,
      "name": "Rock_Ice"
    },
    {
      "x": -15,
      "y": -20,
      "z": 9,
      "name": "Rock_Ice"
    },
    {
      "x": -15,
      "y": -19,
      "z": 9,
      "name": "Rock_Ice"
    },
    {
      "x": -15,
      "y": -18,
      "z": 9,
      "name": "Rock_Ice"
    },
    {
      "x": -15,
      "y": -17,
      "z": 9,
      "name": "Rock_Ice"
    },
    {
      "x": -15,
      "y": -28,
      "z": 10,
      "name": "Rock_Ice"
    },
    {
      "x": -15,
      "y": -27,
      "z": 10,
      "name": "Rock_Ice"
    },
    {
      "x": -15,
      "y": -26,
      "z": 10,
      "name": "Rock_Ice"
    },
    {
      "x": -15,
      "y": -25,
      "z": 10,
      "name": "Rock_Ice"
    },
    {
      "x": -15,
      "y": -24,
      "z": 10,
      "name": "Rock_Ice"
    },
    {
      "x": -15,
      "y": -23,
      "z": 10,
      "name": "Rock_Ice"
    },
    {
      "x": -15,
      "y": -22,
      "z": 10,
      "name": "Rock_Ice"
    },
    {
      "x": -15,
      "y": -21,
      "z": 10,
      "name": "Rock_Ice"
    },
    {
      "x": -15,
      "y": -20,
      "z": 10,
      "name": "Rock_Ice"
    },
    {
      "x": -15,
      "y": -19,
      "z": 10,
      "name": "Rock_Ice"
    },
    {
      "x": -15,
      "y": -18,
      "z": 10,
      "name": "Rock_Ice"
    },
    {
      "x": -15,
      "y": -17,
      "z": 10,
      "name": "Rock_Ice"
    },
    {
      "x": -15,
      "y": -16,
      "z": 10,
      "name": "Rock_Ice"
    },
    {
      "x": -15,
      "y": -29,
      "z": 11,
      "name": "Rock_Ice"
    },
    {
      "x": -15,
      "y": -28,
      "z": 11,
      "name": "Rock_Ice"
    },
    {
      "x": -15,
      "y": -27,
      "z": 11,
      "name": "Rock_Ice"
    },
    {
      "x": -15,
      "y": -26,
      "z": 11,
      "name": "Rock_Ice"
    },
    {
      "x": -15,
      "y": -25,
      "z": 11,
      "name": "Rock_Ice"
    },
    {
      "x": -15,
      "y": -24,
      "z": 11,
      "name": "Rock_Ice"
    },
    {
      "x": -15,
      "y": -23,
      "z": 11,
      "name": "Rock_Ice"
    },
    {
      "x": -15,
      "y": -22,
      "z": 11,
      "name": "Rock_Ice"
    },
    {
      "x": -15,
      "y": -21,
      "z": 11,
      "name": "Rock_Ice"
    },
    {
      "x": -15,
      "y": -20,
      "z": 11,
      "name": "Rock_Ice"
    },
    {
      "x": -15,
      "y": -19,
      "z": 11,
      "name": "Rock_Ice"
    },
    {
      "x": -15,
      "y": -18,
      "z": 11,
      "name": "Rock_Ice"
    },
    {
      "x": -15,
      "y": -17,
      "z": 11,
      "name": "Rock_Ice"
    },
    {
      "x": -15,
      "y": -24,
      "z": 12,
      "name": "Rock_Ice"
    },
    {
      "x": -15,
      "y": -23,
      "z": 12,
      "name": "Rock_Ice"
    },
    {
      "x": -15,
      "y": -22,
      "z": 12,
      "name": "Rock_Ice"
    },
    {
      "x": -15,
      "y": -21,
      "z": 12,
      "name": "Rock_Ice"
    },
    {
      "x": -15,
      "y": -20,
      "z": 12,
      "name": "Rock_Ice"
    },
    {
      "x": -15,
      "y": -19,
      "z": 12,
      "name": "Rock_Ice"
    },
    {
      "x": -15,
      "y": -18,
      "z": 12,
      "name": "Rock_Ice"
    },
    {
      "x": -15,
      "y": -17,
      "z": 12,
      "name": "Rock_Ice"
    },
    {
      "x": -15,
      "y": -18,
      "z": 13,
      "name": "Rock_Ice"
    },
    {
      "x": -14,
      "y": -23,
      "z": 7,
      "name": "Rock_Ice"
    },
    {
      "x": -14,
      "y": -23,
      "z": 8,
      "name": "Rock_Ice"
    },
    {
      "x": -14,
      "y": -22,
      "z": 8,
      "name": "Rock_Ice"
    },
    {
      "x": -14,
      "y": -21,
      "z": 8,
      "name": "Rock_Ice"
    },
    {
      "x": -14,
      "y": -20,
      "z": 8,
      "name": "Rock_Ice"
    },
    {
      "x": -14,
      "y": -19,
      "z": 8,
      "name": "Rock_Ice"
    },
    {
      "x": -14,
      "y": -18,
      "z": 8,
      "name": "Rock_Ice"
    },
    {
      "x": -14,
      "y": -17,
      "z": 8,
      "name": "Rock_Ice"
    },
    {
      "x": -14,
      "y": -16,
      "z": 8,
      "name": "Rock_Ice"
    },
    {
      "x": -14,
      "y": -28,
      "z": 9,
      "name": "Rock_Ice"
    },
    {
      "x": -14,
      "y": -27,
      "z": 9,
      "name": "Rock_Ice"
    },
    {
      "x": -14,
      "y": -26,
      "z": 9,
      "name": "Rock_Ice"
    },
    {
      "x": -14,
      "y": -25,
      "z": 9,
      "name": "Rock_Ice"
    },
    {
      "x": -14,
      "y": -24,
      "z": 9,
      "name": "Rock_Ice"
    },
    {
      "x": -14,
      "y": -23,
      "z": 9,
      "name": "Rock_Ice"
    },
    {
      "x": -14,
      "y": -22,
      "z": 9,
      "name": "Rock_Ice"
    },
    {
      "x": -14,
      "y": -21,
      "z": 9,
      "name": "Rock_Ice"
    },
    {
      "x": -14,
      "y": -20,
      "z": 9,
      "name": "Rock_Ice"
    },
    {
      "x": -14,
      "y": -19,
      "z": 9,
      "name": "Rock_Ice"
    },
    {
      "x": -14,
      "y": -18,
      "z": 9,
      "name": "Rock_Ice"
    },
    {
      "x": -14,
      "y": -17,
      "z": 9,
      "name": "Rock_Ice"
    },
    {
      "x": -14,
      "y": -16,
      "z": 9,
      "name": "Rock_Ice"
    },
    {
      "x": -14,
      "y": -35,
      "z": 10,
      "name": "Rock_Ice"
    },
    {
      "x": -14,
      "y": -34,
      "z": 10,
      "name": "Rock_Ice"
    },
    {
      "x": -14,
      "y": -33,
      "z": 10,
      "name": "Rock_Ice"
    },
    {
      "x": -14,
      "y": -32,
      "z": 10,
      "name": "Rock_Ice"
    },
    {
      "x": -14,
      "y": -31,
      "z": 10,
      "name": "Rock_Ice"
    },
    {
      "x": -14,
      "y": -30,
      "z": 10,
      "name": "Rock_Ice"
    },
    {
      "x": -14,
      "y": -29,
      "z": 10,
      "name": "Rock_Ice"
    },
    {
      "x": -14,
      "y": -28,
      "z": 10,
      "name": "Rock_Ice"
    },
    {
      "x": -14,
      "y": -27,
      "z": 10,
      "name": "Rock_Ice"
    },
    {
      "x": -14,
      "y": -26,
      "z": 10,
      "name": "Rock_Ice"
    },
    {
      "x": -14,
      "y": -25,
      "z": 10,
      "name": "Rock_Ice"
    },
    {
      "x": -14,
      "y": -24,
      "z": 10,
      "name": "Rock_Ice"
    },
    {
      "x": -14,
      "y": -23,
      "z": 10,
      "name": "Rock_Ice"
    },
    {
      "x": -14,
      "y": -22,
      "z": 10,
      "name": "Rock_Ice"
    },
    {
      "x": -14,
      "y": -21,
      "z": 10,
      "name": "Rock_Ice"
    },
    {
      "x": -14,
      "y": -20,
      "z": 10,
      "name": "Rock_Ice"
    },
    {
      "x": -14,
      "y": -19,
      "z": 10,
      "name": "Rock_Ice"
    },
    {
      "x": -14,
      "y": -18,
      "z": 10,
      "name": "Rock_Ice"
    },
    {
      "x": -14,
      "y": -17,
      "z": 10,
      "name": "Rock_Ice"
    },
    {
      "x": -14,
      "y": -16,
      "z": 10,
      "name": "Rock_Ice"
    },
    {
      "x": -14,
      "y": -34,
      "z": 11,
      "name": "Rock_Ice"
    },
    {
      "x": -14,
      "y": -33,
      "z": 11,
      "name": "Rock_Ice"
    },
    {
      "x": -14,
      "y": -32,
      "z": 11,
      "name": "Rock_Ice"
    },
    {
      "x": -14,
      "y": -31,
      "z": 11,
      "name": "Rock_Ice"
    },
    {
      "x": -14,
      "y": -30,
      "z": 11,
      "name": "Rock_Ice"
    },
    {
      "x": -14,
      "y": -29,
      "z": 11,
      "name": "Rock_Ice"
    },
    {
      "x": -14,
      "y": -28,
      "z": 11,
      "name": "Rock_Ice"
    },
    {
      "x": -14,
      "y": -27,
      "z": 11,
      "name": "Rock_Ice"
    },
    {
      "x": -14,
      "y": -26,
      "z": 11,
      "name": "Rock_Ice"
    },
    {
      "x": -14,
      "y": -25,
      "z": 11,
      "name": "Rock_Ice"
    },
    {
      "x": -14,
      "y": -24,
      "z": 11,
      "name": "Rock_Ice"
    },
    {
      "x": -14,
      "y": -23,
      "z": 11,
      "name": "Rock_Ice"
    },
    {
      "x": -14,
      "y": -22,
      "z": 11,
      "name": "Rock_Ice"
    },
    {
      "x": -14,
      "y": -21,
      "z": 11,
      "name": "Rock_Ice"
    },
    {
      "x": -14,
      "y": -20,
      "z": 11,
      "name": "Rock_Ice"
    },
    {
      "x": -14,
      "y": -19,
      "z": 11,
      "name": "Rock_Ice"
    },
    {
      "x": -14,
      "y": -18,
      "z": 11,
      "name": "Rock_Ice"
    },
    {
      "x": -14,
      "y": -17,
      "z": 11,
      "name": "Rock_Ice"
    },
    {
      "x": -14,
      "y": -16,
      "z": 11,
      "name": "Rock_Ice"
    },
    {
      "x": -14,
      "y": -22,
      "z": 12,
      "name": "Rock_Ice"
    },
    {
      "x": -14,
      "y": -21,
      "z": 12,
      "name": "Rock_Ice"
    },
    {
      "x": -14,
      "y": -20,
      "z": 12,
      "name": "Rock_Ice"
    },
    {
      "x": -14,
      "y": -19,
      "z": 12,
      "name": "Rock_Ice"
    },
    {
      "x": -14,
      "y": -18,
      "z": 12,
      "name": "Rock_Ice"
    },
    {
      "x": -14,
      "y": -17,
      "z": 12,
      "name": "Rock_Ice"
    },
    {
      "x": -13,
      "y": -20,
      "z": 6,
      "name": "Rock_Ice"
    },
    {
      "x": -13,
      "y": -19,
      "z": 6,
      "name": "Rock_Ice"
    },
    {
      "x": -13,
      "y": -18,
      "z": 6,
      "name": "Rock_Ice"
    },
    {
      "x": -13,
      "y": -17,
      "z": 6,
      "name": "Rock_Ice"
    },
    {
      "x": -13,
      "y": -16,
      "z": 6,
      "name": "Rock_Ice"
    },
    {
      "x": -13,
      "y": -35,
      "z": 7,
      "name": "Rock_Ice"
    },
    {
      "x": -13,
      "y": -34,
      "z": 7,
      "name": "Rock_Ice"
    },
    {
      "x": -13,
      "y": -33,
      "z": 7,
      "name": "Rock_Ice"
    },
    {
      "x": -13,
      "y": -22,
      "z": 7,
      "name": "Rock_Ice"
    },
    {
      "x": -13,
      "y": -21,
      "z": 7,
      "name": "Rock_Ice"
    },
    {
      "x": -13,
      "y": -20,
      "z": 7,
      "name": "Rock_Ice"
    },
    {
      "x": -13,
      "y": -19,
      "z": 7,
      "name": "Rock_Ice"
    },
    {
      "x": -13,
      "y": -18,
      "z": 7,
      "name": "Rock_Ice"
    },
    {
      "x": -13,
      "y": -17,
      "z": 7,
      "name": "Rock_Ice"
    },
    {
      "x": -13,
      "y": -16,
      "z": 7,
      "name": "Rock_Ice"
    },
    {
      "x": -13,
      "y": -35,
      "z": 8,
      "name": "Rock_Ice"
    },
    {
      "x": -13,
      "y": -34,
      "z": 8,
      "name": "Rock_Ice"
    },
    {
      "x": -13,
      "y": -33,
      "z": 8,
      "name": "Rock_Ice"
    },
    {
      "x": -13,
      "y": -32,
      "z": 8,
      "name": "Rock_Ice"
    },
    {
      "x": -13,
      "y": -31,
      "z": 8,
      "name": "Rock_Ice"
    },
    {
      "x": -13,
      "y": -30,
      "z": 8,
      "name": "Rock_Ice"
    },
    {
      "x": -13,
      "y": -25,
      "z": 8,
      "name": "Rock_Ice"
    },
    {
      "x": -13,
      "y": -24,
      "z": 8,
      "name": "Rock_Ice"
    },
    {
      "x": -13,
      "y": -23,
      "z": 8,
      "name": "Rock_Ice"
    },
    {
      "x": -13,
      "y": -22,
      "z": 8,
      "name": "Rock_Ice"
    },
    {
      "x": -13,
      "y": -21,
      "z": 8,
      "name": "Rock_Ice"
    },
    {
      "x": -13,
      "y": -20,
      "z": 8,
      "name": "Rock_Ice"
    },
    {
      "x": -13,
      "y": -19,
      "z": 8,
      "name": "Rock_Ice"
    },
    {
      "x": -13,
      "y": -18,
      "z": 8,
      "name": "Rock_Ice"
    },
    {
      "x": -13,
      "y": -17,
      "z": 8,
      "name": "Rock_Ice"
    },
    {
      "x": -13,
      "y": -16,
      "z": 8,
      "name": "Rock_Ice"
    },
    {
      "x": -13,
      "y": -15,
      "z": 8,
      "name": "Rock_Ice"
    },
    {
      "x": -13,
      "y": -35,
      "z": 9,
      "name": "Rock_Ice"
    },
    {
      "x": -13,
      "y": -34,
      "z": 9,
      "name": "Rock_Ice"
    },
    {
      "x": -13,
      "y": -33,
      "z": 9,
      "name": "Rock_Ice"
    },
    {
      "x": -13,
      "y": -32,
      "z": 9,
      "name": "Rock_Ice"
    },
    {
      "x": -13,
      "y": -31,
      "z": 9,
      "name": "Rock_Ice"
    },
    {
      "x": -13,
      "y": -30,
      "z": 9,
      "name": "Rock_Ice"
    },
    {
      "x": -13,
      "y": -29,
      "z": 9,
      "name": "Rock_Ice"
    },
    {
      "x": -13,
      "y": -28,
      "z": 9,
      "name": "Rock_Ice"
    },
    {
      "x": -13,
      "y": -27,
      "z": 9,
      "name": "Rock_Ice"
    },
    {
      "x": -13,
      "y": -26,
      "z": 9,
      "name": "Rock_Ice"
    },
    {
      "x": -13,
      "y": -25,
      "z": 9,
      "name": "Rock_Ice"
    },
    {
      "x": -13,
      "y": -24,
      "z": 9,
      "name": "Rock_Ice"
    },
    {
      "x": -13,
      "y": -23,
      "z": 9,
      "name": "Rock_Ice"
    },
    {
      "x": -13,
      "y": -22,
      "z": 9,
      "name": "Rock_Ice"
    },
    {
      "x": -13,
      "y": -21,
      "z": 9,
      "name": "Rock_Ice"
    },
    {
      "x": -13,
      "y": -20,
      "z": 9,
      "name": "Rock_Ice"
    },
    {
      "x": -13,
      "y": -19,
      "z": 9,
      "name": "Rock_Ice"
    },
    {
      "x": -13,
      "y": -18,
      "z": 9,
      "name": "Rock_Ice"
    },
    {
      "x": -13,
      "y": -17,
      "z": 9,
      "name": "Rock_Ice"
    },
    {
      "x": -13,
      "y": -16,
      "z": 9,
      "name": "Rock_Ice"
    },
    {
      "x": -13,
      "y": -15,
      "z": 9,
      "name": "Rock_Ice"
    },
    {
      "x": -13,
      "y": -35,
      "z": 10,
      "name": "Rock_Ice"
    },
    {
      "x": -13,
      "y": -34,
      "z": 10,
      "name": "Rock_Ice"
    },
    {
      "x": -13,
      "y": -33,
      "z": 10,
      "name": "Rock_Ice"
    },
    {
      "x": -13,
      "y": -32,
      "z": 10,
      "name": "Rock_Ice"
    },
    {
      "x": -13,
      "y": -31,
      "z": 10,
      "name": "Rock_Ice"
    },
    {
      "x": -13,
      "y": -30,
      "z": 10,
      "name": "Rock_Ice"
    },
    {
      "x": -13,
      "y": -29,
      "z": 10,
      "name": "Rock_Ice"
    },
    {
      "x": -13,
      "y": -28,
      "z": 10,
      "name": "Rock_Ice"
    },
    {
      "x": -13,
      "y": -27,
      "z": 10,
      "name": "Rock_Ice"
    },
    {
      "x": -13,
      "y": -26,
      "z": 10,
      "name": "Rock_Ice"
    },
    {
      "x": -13,
      "y": -25,
      "z": 10,
      "name": "Rock_Ice"
    },
    {
      "x": -13,
      "y": -24,
      "z": 10,
      "name": "Rock_Ice"
    },
    {
      "x": -13,
      "y": -23,
      "z": 10,
      "name": "Rock_Ice"
    },
    {
      "x": -13,
      "y": -22,
      "z": 10,
      "name": "Rock_Ice"
    },
    {
      "x": -13,
      "y": -21,
      "z": 10,
      "name": "Rock_Ice"
    },
    {
      "x": -13,
      "y": -20,
      "z": 10,
      "name": "Rock_Ice"
    },
    {
      "x": -13,
      "y": -19,
      "z": 10,
      "name": "Rock_Ice"
    },
    {
      "x": -13,
      "y": -18,
      "z": 10,
      "name": "Rock_Ice"
    },
    {
      "x": -13,
      "y": -17,
      "z": 10,
      "name": "Rock_Ice"
    },
    {
      "x": -13,
      "y": -16,
      "z": 10,
      "name": "Rock_Ice"
    },
    {
      "x": -13,
      "y": -15,
      "z": 10,
      "name": "Rock_Ice"
    },
    {
      "x": -13,
      "y": -35,
      "z": 11,
      "name": "Rock_Ice"
    },
    {
      "x": -13,
      "y": -34,
      "z": 11,
      "name": "Rock_Ice"
    },
    {
      "x": -13,
      "y": -33,
      "z": 11,
      "name": "Rock_Ice"
    },
    {
      "x": -13,
      "y": -32,
      "z": 11,
      "name": "Rock_Ice"
    },
    {
      "x": -13,
      "y": -31,
      "z": 11,
      "name": "Rock_Ice"
    },
    {
      "x": -13,
      "y": -30,
      "z": 11,
      "name": "Rock_Ice"
    },
    {
      "x": -13,
      "y": -29,
      "z": 11,
      "name": "Rock_Ice"
    },
    {
      "x": -13,
      "y": -28,
      "z": 11,
      "name": "Rock_Ice"
    },
    {
      "x": -13,
      "y": -27,
      "z": 11,
      "name": "Rock_Ice"
    },
    {
      "x": -13,
      "y": -26,
      "z": 11,
      "name": "Rock_Ice"
    },
    {
      "x": -13,
      "y": -25,
      "z": 11,
      "name": "Rock_Ice"
    },
    {
      "x": -13,
      "y": -24,
      "z": 11,
      "name": "Rock_Ice"
    },
    {
      "x": -13,
      "y": -23,
      "z": 11,
      "name": "Rock_Ice"
    },
    {
      "x": -13,
      "y": -22,
      "z": 11,
      "name": "Rock_Ice"
    },
    {
      "x": -13,
      "y": -21,
      "z": 11,
      "name": "Rock_Ice"
    },
    {
      "x": -13,
      "y": -20,
      "z": 11,
      "name": "Rock_Ice"
    },
    {
      "x": -13,
      "y": -19,
      "z": 11,
      "name": "Rock_Ice"
    },
    {
      "x": -13,
      "y": -18,
      "z": 11,
      "name": "Rock_Ice"
    },
    {
      "x": -13,
      "y": -17,
      "z": 11,
      "name": "Rock_Ice"
    },
    {
      "x": -13,
      "y": -16,
      "z": 11,
      "name": "Rock_Ice"
    },
    {
      "x": -13,
      "y": -24,
      "z": 12,
      "name": "Rock_Ice"
    },
    {
      "x": -13,
      "y": -23,
      "z": 12,
      "name": "Rock_Ice"
    },
    {
      "x": -13,
      "y": -22,
      "z": 12,
      "name": "Rock_Ice"
    },
    {
      "x": -13,
      "y": -21,
      "z": 12,
      "name": "Rock_Ice"
    },
    {
      "x": -13,
      "y": -20,
      "z": 12,
      "name": "Rock_Ice"
    },
    {
      "x": -13,
      "y": -19,
      "z": 12,
      "name": "Rock_Ice"
    },
    {
      "x": -13,
      "y": -18,
      "z": 12,
      "name": "Rock_Ice"
    },
    {
      "x": -13,
      "y": -17,
      "z": 12,
      "name": "Rock_Ice"
    },
    {
      "x": -13,
      "y": -16,
      "z": 12,
      "name": "Rock_Ice"
    },
    {
      "x": -12,
      "y": -21,
      "z": 6,
      "name": "Rock_Ice"
    },
    {
      "x": -12,
      "y": -20,
      "z": 6,
      "name": "Rock_Ice"
    },
    {
      "x": -12,
      "y": -19,
      "z": 6,
      "name": "Rock_Ice"
    },
    {
      "x": -12,
      "y": -18,
      "z": 6,
      "name": "Rock_Ice"
    },
    {
      "x": -12,
      "y": -17,
      "z": 6,
      "name": "Rock_Ice"
    },
    {
      "x": -12,
      "y": -16,
      "z": 6,
      "name": "Rock_Ice"
    },
    {
      "x": -12,
      "y": -15,
      "z": 6,
      "name": "Rock_Ice"
    },
    {
      "x": -12,
      "y": -33,
      "z": 7,
      "name": "Rock_Ice"
    },
    {
      "x": -12,
      "y": -32,
      "z": 7,
      "name": "Rock_Ice"
    },
    {
      "x": -12,
      "y": -31,
      "z": 7,
      "name": "Rock_Ice"
    },
    {
      "x": -12,
      "y": -24,
      "z": 7,
      "name": "Rock_Ice"
    },
    {
      "x": -12,
      "y": -23,
      "z": 7,
      "name": "Rock_Ice"
    },
    {
      "x": -12,
      "y": -22,
      "z": 7,
      "name": "Rock_Ice"
    },
    {
      "x": -12,
      "y": -21,
      "z": 7,
      "name": "Rock_Ice"
    },
    {
      "x": -12,
      "y": -20,
      "z": 7,
      "name": "Rock_Ice"
    },
    {
      "x": -12,
      "y": -19,
      "z": 7,
      "name": "Rock_Ice"
    },
    {
      "x": -12,
      "y": -18,
      "z": 7,
      "name": "Rock_Ice"
    },
    {
      "x": -12,
      "y": -17,
      "z": 7,
      "name": "Rock_Ice"
    },
    {
      "x": -12,
      "y": -16,
      "z": 7,
      "name": "Rock_Ice"
    },
    {
      "x": -12,
      "y": -15,
      "z": 7,
      "name": "Rock_Ice"
    },
    {
      "x": -12,
      "y": -14,
      "z": 7,
      "name": "Rock_Ice"
    },
    {
      "x": -12,
      "y": -35,
      "z": 8,
      "name": "Rock_Ice"
    },
    {
      "x": -12,
      "y": -34,
      "z": 8,
      "name": "Rock_Ice"
    },
    {
      "x": -12,
      "y": -33,
      "z": 8,
      "name": "Rock_Ice"
    },
    {
      "x": -12,
      "y": -32,
      "z": 8,
      "name": "Rock_Ice"
    },
    {
      "x": -12,
      "y": -31,
      "z": 8,
      "name": "Rock_Ice"
    },
    {
      "x": -12,
      "y": -30,
      "z": 8,
      "name": "Rock_Ice"
    },
    {
      "x": -12,
      "y": -25,
      "z": 8,
      "name": "Rock_Ice"
    },
    {
      "x": -12,
      "y": -24,
      "z": 8,
      "name": "Rock_Ice"
    },
    {
      "x": -12,
      "y": -23,
      "z": 8,
      "name": "Rock_Ice"
    },
    {
      "x": -12,
      "y": -22,
      "z": 8,
      "name": "Rock_Ice"
    },
    {
      "x": -12,
      "y": -21,
      "z": 8,
      "name": "Rock_Ice"
    },
    {
      "x": -12,
      "y": -20,
      "z": 8,
      "name": "Rock_Ice"
    },
    {
      "x": -12,
      "y": -19,
      "z": 8,
      "name": "Rock_Ice"
    },
    {
      "x": -12,
      "y": -18,
      "z": 8,
      "name": "Rock_Ice"
    },
    {
      "x": -12,
      "y": -17,
      "z": 8,
      "name": "Rock_Ice"
    },
    {
      "x": -12,
      "y": -16,
      "z": 8,
      "name": "Rock_Ice"
    },
    {
      "x": -12,
      "y": -15,
      "z": 8,
      "name": "Rock_Ice"
    },
    {
      "x": -12,
      "y": -35,
      "z": 9,
      "name": "Rock_Ice"
    },
    {
      "x": -12,
      "y": -34,
      "z": 9,
      "name": "Rock_Ice"
    },
    {
      "x": -12,
      "y": -33,
      "z": 9,
      "name": "Rock_Ice"
    },
    {
      "x": -12,
      "y": -32,
      "z": 9,
      "name": "Rock_Ice"
    },
    {
      "x": -12,
      "y": -31,
      "z": 9,
      "name": "Rock_Ice"
    },
    {
      "x": -12,
      "y": -30,
      "z": 9,
      "name": "Rock_Ice"
    },
    {
      "x": -12,
      "y": -29,
      "z": 9,
      "name": "Rock_Ice"
    },
    {
      "x": -12,
      "y": -28,
      "z": 9,
      "name": "Rock_Ice"
    },
    {
      "x": -12,
      "y": -27,
      "z": 9,
      "name": "Rock_Ice"
    },
    {
      "x": -12,
      "y": -26,
      "z": 9,
      "name": "Rock_Ice"
    },
    {
      "x": -12,
      "y": -25,
      "z": 9,
      "name": "Rock_Ice"
    },
    {
      "x": -12,
      "y": -24,
      "z": 9,
      "name": "Rock_Ice"
    },
    {
      "x": -12,
      "y": -23,
      "z": 9,
      "name": "Rock_Ice"
    },
    {
      "x": -12,
      "y": -22,
      "z": 9,
      "name": "Rock_Ice"
    },
    {
      "x": -12,
      "y": -21,
      "z": 9,
      "name": "Rock_Ice"
    },
    {
      "x": -12,
      "y": -20,
      "z": 9,
      "name": "Rock_Ice"
    },
    {
      "x": -12,
      "y": -19,
      "z": 9,
      "name": "Rock_Ice"
    },
    {
      "x": -12,
      "y": -18,
      "z": 9,
      "name": "Rock_Ice"
    },
    {
      "x": -12,
      "y": -17,
      "z": 9,
      "name": "Rock_Ice"
    },
    {
      "x": -12,
      "y": -16,
      "z": 9,
      "name": "Rock_Ice"
    },
    {
      "x": -12,
      "y": -15,
      "z": 9,
      "name": "Rock_Ice"
    },
    {
      "x": -12,
      "y": -14,
      "z": 9,
      "name": "Rock_Ice"
    },
    {
      "x": -12,
      "y": -35,
      "z": 10,
      "name": "Rock_Ice"
    },
    {
      "x": -12,
      "y": -34,
      "z": 10,
      "name": "Rock_Ice"
    },
    {
      "x": -12,
      "y": -33,
      "z": 10,
      "name": "Rock_Ice"
    },
    {
      "x": -12,
      "y": -32,
      "z": 10,
      "name": "Rock_Ice"
    },
    {
      "x": -12,
      "y": -31,
      "z": 10,
      "name": "Rock_Ice"
    },
    {
      "x": -12,
      "y": -30,
      "z": 10,
      "name": "Rock_Ice"
    },
    {
      "x": -12,
      "y": -29,
      "z": 10,
      "name": "Rock_Ice"
    },
    {
      "x": -12,
      "y": -28,
      "z": 10,
      "name": "Rock_Ice"
    },
    {
      "x": -12,
      "y": -27,
      "z": 10,
      "name": "Rock_Ice"
    },
    {
      "x": -12,
      "y": -26,
      "z": 10,
      "name": "Rock_Ice"
    },
    {
      "x": -12,
      "y": -25,
      "z": 10,
      "name": "Rock_Ice"
    },
    {
      "x": -12,
      "y": -24,
      "z": 10,
      "name": "Rock_Ice"
    },
    {
      "x": -12,
      "y": -23,
      "z": 10,
      "name": "Rock_Ice"
    },
    {
      "x": -12,
      "y": -22,
      "z": 10,
      "name": "Rock_Ice"
    },
    {
      "x": -12,
      "y": -21,
      "z": 10,
      "name": "Rock_Ice"
    },
    {
      "x": -12,
      "y": -20,
      "z": 10,
      "name": "Rock_Ice"
    },
    {
      "x": -12,
      "y": -19,
      "z": 10,
      "name": "Rock_Ice"
    },
    {
      "x": -12,
      "y": -18,
      "z": 10,
      "name": "Rock_Ice"
    },
    {
      "x": -12,
      "y": -17,
      "z": 10,
      "name": "Rock_Ice"
    },
    {
      "x": -12,
      "y": -16,
      "z": 10,
      "name": "Rock_Ice"
    },
    {
      "x": -12,
      "y": -15,
      "z": 10,
      "name": "Rock_Ice"
    },
    {
      "x": -12,
      "y": -28,
      "z": 11,
      "name": "Rock_Ice"
    },
    {
      "x": -12,
      "y": -27,
      "z": 11,
      "name": "Rock_Ice"
    },
    {
      "x": -12,
      "y": -26,
      "z": 11,
      "name": "Rock_Ice"
    },
    {
      "x": -12,
      "y": -25,
      "z": 11,
      "name": "Rock_Ice"
    },
    {
      "x": -12,
      "y": -24,
      "z": 11,
      "name": "Rock_Ice"
    },
    {
      "x": -12,
      "y": -23,
      "z": 11,
      "name": "Rock_Ice"
    },
    {
      "x": -12,
      "y": -22,
      "z": 11,
      "name": "Rock_Ice"
    },
    {
      "x": -12,
      "y": -21,
      "z": 11,
      "name": "Rock_Ice"
    },
    {
      "x": -12,
      "y": -20,
      "z": 11,
      "name": "Rock_Ice"
    },
    {
      "x": -12,
      "y": -19,
      "z": 11,
      "name": "Rock_Ice"
    },
    {
      "x": -12,
      "y": -18,
      "z": 11,
      "name": "Rock_Ice"
    },
    {
      "x": -12,
      "y": -17,
      "z": 11,
      "name": "Rock_Ice"
    },
    {
      "x": -12,
      "y": -16,
      "z": 11,
      "name": "Rock_Ice"
    },
    {
      "x": -12,
      "y": -15,
      "z": 11,
      "name": "Rock_Ice"
    },
    {
      "x": -12,
      "y": -17,
      "z": 12,
      "name": "Rock_Ice"
    },
    {
      "x": -12,
      "y": -16,
      "z": 12,
      "name": "Rock_Ice"
    },
    {
      "x": -11,
      "y": -19,
      "z": 5,
      "name": "Rock_Ice"
    },
    {
      "x": -11,
      "y": -18,
      "z": 5,
      "name": "Rock_Ice"
    },
    {
      "x": -11,
      "y": -17,
      "z": 5,
      "name": "Rock_Ice"
    },
    {
      "x": -11,
      "y": -16,
      "z": 5,
      "name": "Rock_Ice"
    },
    {
      "x": -11,
      "y": -15,
      "z": 5,
      "name": "Rock_Ice"
    },
    {
      "x": -11,
      "y": -14,
      "z": 5,
      "name": "Rock_Ice"
    },
    {
      "x": -11,
      "y": -21,
      "z": 6,
      "name": "Rock_Ice"
    },
    {
      "x": -11,
      "y": -20,
      "z": 6,
      "name": "Rock_Ice"
    },
    {
      "x": -11,
      "y": -19,
      "z": 6,
      "name": "Rock_Ice"
    },
    {
      "x": -11,
      "y": -18,
      "z": 6,
      "name": "Rock_Ice"
    },
    {
      "x": -11,
      "y": -17,
      "z": 6,
      "name": "Rock_Ice"
    },
    {
      "x": -11,
      "y": -16,
      "z": 6,
      "name": "Rock_Ice"
    },
    {
      "x": -11,
      "y": -15,
      "z": 6,
      "name": "Rock_Ice"
    },
    {
      "x": -11,
      "y": -14,
      "z": 6,
      "name": "Rock_Ice"
    },
    {
      "x": -11,
      "y": -23,
      "z": 7,
      "name": "Rock_Ice"
    },
    {
      "x": -11,
      "y": -22,
      "z": 7,
      "name": "Rock_Ice"
    },
    {
      "x": -11,
      "y": -21,
      "z": 7,
      "name": "Rock_Ice"
    },
    {
      "x": -11,
      "y": -20,
      "z": 7,
      "name": "Rock_Ice"
    },
    {
      "x": -11,
      "y": -19,
      "z": 7,
      "name": "Rock_Ice"
    },
    {
      "x": -11,
      "y": -18,
      "z": 7,
      "name": "Rock_Ice"
    },
    {
      "x": -11,
      "y": -17,
      "z": 7,
      "name": "Rock_Ice"
    },
    {
      "x": -11,
      "y": -16,
      "z": 7,
      "name": "Rock_Ice"
    },
    {
      "x": -11,
      "y": -15,
      "z": 7,
      "name": "Rock_Ice"
    },
    {
      "x": -11,
      "y": -14,
      "z": 7,
      "name": "Rock_Ice"
    },
    {
      "x": -11,
      "y": -13,
      "z": 7,
      "name": "Rock_Ice"
    },
    {
      "x": -11,
      "y": -35,
      "z": 8,
      "name": "Rock_Ice"
    },
    {
      "x": -11,
      "y": -34,
      "z": 8,
      "name": "Rock_Ice"
    },
    {
      "x": -11,
      "y": -33,
      "z": 8,
      "name": "Rock_Ice"
    },
    {
      "x": -11,
      "y": -32,
      "z": 8,
      "name": "Rock_Ice"
    },
    {
      "x": -11,
      "y": -31,
      "z": 8,
      "name": "Rock_Ice"
    },
    {
      "x": -11,
      "y": -30,
      "z": 8,
      "name": "Rock_Ice"
    },
    {
      "x": -11,
      "y": -29,
      "z": 8,
      "name": "Rock_Ice"
    },
    {
      "x": -11,
      "y": -28,
      "z": 8,
      "name": "Rock_Ice"
    },
    {
      "x": -11,
      "y": -27,
      "z": 8,
      "name": "Rock_Ice"
    },
    {
      "x": -11,
      "y": -26,
      "z": 8,
      "name": "Rock_Ice"
    },
    {
      "x": -11,
      "y": -25,
      "z": 8,
      "name": "Rock_Ice"
    },
    {
      "x": -11,
      "y": -24,
      "z": 8,
      "name": "Rock_Ice"
    },
    {
      "x": -11,
      "y": -23,
      "z": 8,
      "name": "Rock_Ice"
    },
    {
      "x": -11,
      "y": -22,
      "z": 8,
      "name": "Rock_Ice"
    },
    {
      "x": -11,
      "y": -21,
      "z": 8,
      "name": "Rock_Ice"
    },
    {
      "x": -11,
      "y": -20,
      "z": 8,
      "name": "Rock_Ice"
    },
    {
      "x": -11,
      "y": -19,
      "z": 8,
      "name": "Rock_Ice"
    },
    {
      "x": -11,
      "y": -18,
      "z": 8,
      "name": "Rock_Ice"
    },
    {
      "x": -11,
      "y": -17,
      "z": 8,
      "name": "Rock_Ice"
    },
    {
      "x": -11,
      "y": -16,
      "z": 8,
      "name": "Rock_Ice"
    },
    {
      "x": -11,
      "y": -15,
      "z": 8,
      "name": "Rock_Ice"
    },
    {
      "x": -11,
      "y": -14,
      "z": 8,
      "name": "Rock_Ice"
    },
    {
      "x": -11,
      "y": -35,
      "z": 9,
      "name": "Rock_Ice"
    },
    {
      "x": -11,
      "y": -34,
      "z": 9,
      "name": "Rock_Ice"
    },
    {
      "x": -11,
      "y": -33,
      "z": 9,
      "name": "Rock_Ice"
    },
    {
      "x": -11,
      "y": -32,
      "z": 9,
      "name": "Rock_Ice"
    },
    {
      "x": -11,
      "y": -31,
      "z": 9,
      "name": "Rock_Ice"
    },
    {
      "x": -11,
      "y": -30,
      "z": 9,
      "name": "Rock_Ice"
    },
    {
      "x": -11,
      "y": -29,
      "z": 9,
      "name": "Rock_Ice"
    },
    {
      "x": -11,
      "y": -28,
      "z": 9,
      "name": "Rock_Ice"
    },
    {
      "x": -11,
      "y": -27,
      "z": 9,
      "name": "Rock_Ice"
    },
    {
      "x": -11,
      "y": -26,
      "z": 9,
      "name": "Rock_Ice"
    },
    {
      "x": -11,
      "y": -25,
      "z": 9,
      "name": "Rock_Ice"
    },
    {
      "x": -11,
      "y": -24,
      "z": 9,
      "name": "Rock_Ice"
    },
    {
      "x": -11,
      "y": -23,
      "z": 9,
      "name": "Rock_Ice"
    },
    {
      "x": -11,
      "y": -22,
      "z": 9,
      "name": "Rock_Ice"
    },
    {
      "x": -11,
      "y": -21,
      "z": 9,
      "name": "Rock_Ice"
    },
    {
      "x": -11,
      "y": -20,
      "z": 9,
      "name": "Rock_Ice"
    },
    {
      "x": -11,
      "y": -19,
      "z": 9,
      "name": "Rock_Ice"
    },
    {
      "x": -11,
      "y": -18,
      "z": 9,
      "name": "Rock_Ice"
    },
    {
      "x": -11,
      "y": -17,
      "z": 9,
      "name": "Rock_Ice"
    },
    {
      "x": -11,
      "y": -16,
      "z": 9,
      "name": "Rock_Ice"
    },
    {
      "x": -11,
      "y": -15,
      "z": 9,
      "name": "Rock_Ice"
    },
    {
      "x": -11,
      "y": -14,
      "z": 9,
      "name": "Rock_Ice"
    },
    {
      "x": -11,
      "y": -13,
      "z": 9,
      "name": "Rock_Ice"
    },
    {
      "x": -11,
      "y": -35,
      "z": 10,
      "name": "Rock_Ice"
    },
    {
      "x": -11,
      "y": -34,
      "z": 10,
      "name": "Rock_Ice"
    },
    {
      "x": -11,
      "y": -33,
      "z": 10,
      "name": "Rock_Ice"
    },
    {
      "x": -11,
      "y": -32,
      "z": 10,
      "name": "Rock_Ice"
    },
    {
      "x": -11,
      "y": -31,
      "z": 10,
      "name": "Rock_Ice"
    },
    {
      "x": -11,
      "y": -30,
      "z": 10,
      "name": "Rock_Ice"
    },
    {
      "x": -11,
      "y": -29,
      "z": 10,
      "name": "Rock_Ice"
    },
    {
      "x": -11,
      "y": -28,
      "z": 10,
      "name": "Rock_Ice"
    },
    {
      "x": -11,
      "y": -27,
      "z": 10,
      "name": "Rock_Ice"
    },
    {
      "x": -11,
      "y": -26,
      "z": 10,
      "name": "Rock_Ice"
    },
    {
      "x": -11,
      "y": -25,
      "z": 10,
      "name": "Rock_Ice"
    },
    {
      "x": -11,
      "y": -24,
      "z": 10,
      "name": "Rock_Ice"
    },
    {
      "x": -11,
      "y": -23,
      "z": 10,
      "name": "Rock_Ice"
    },
    {
      "x": -11,
      "y": -22,
      "z": 10,
      "name": "Rock_Ice"
    },
    {
      "x": -11,
      "y": -21,
      "z": 10,
      "name": "Rock_Ice"
    },
    {
      "x": -11,
      "y": -20,
      "z": 10,
      "name": "Rock_Ice"
    },
    {
      "x": -11,
      "y": -19,
      "z": 10,
      "name": "Rock_Ice"
    },
    {
      "x": -11,
      "y": -18,
      "z": 10,
      "name": "Rock_Ice"
    },
    {
      "x": -11,
      "y": -17,
      "z": 10,
      "name": "Rock_Ice"
    },
    {
      "x": -11,
      "y": -16,
      "z": 10,
      "name": "Rock_Ice"
    },
    {
      "x": -11,
      "y": -15,
      "z": 10,
      "name": "Rock_Ice"
    },
    {
      "x": -11,
      "y": -14,
      "z": 10,
      "name": "Rock_Ice"
    },
    {
      "x": -11,
      "y": -26,
      "z": 11,
      "name": "Rock_Ice"
    },
    {
      "x": -11,
      "y": -25,
      "z": 11,
      "name": "Rock_Ice"
    },
    {
      "x": -11,
      "y": -24,
      "z": 11,
      "name": "Rock_Ice"
    },
    {
      "x": -11,
      "y": -23,
      "z": 11,
      "name": "Rock_Ice"
    },
    {
      "x": -11,
      "y": -22,
      "z": 11,
      "name": "Rock_Ice"
    },
    {
      "x": -11,
      "y": -21,
      "z": 11,
      "name": "Rock_Ice"
    },
    {
      "x": -11,
      "y": -20,
      "z": 11,
      "name": "Rock_Ice"
    },
    {
      "x": -11,
      "y": -19,
      "z": 11,
      "name": "Rock_Ice"
    },
    {
      "x": -11,
      "y": -18,
      "z": 11,
      "name": "Rock_Ice"
    },
    {
      "x": -11,
      "y": -17,
      "z": 11,
      "name": "Rock_Ice"
    },
    {
      "x": -11,
      "y": -16,
      "z": 11,
      "name": "Rock_Ice"
    },
    {
      "x": -11,
      "y": -15,
      "z": 11,
      "name": "Rock_Ice"
    },
    {
      "x": -11,
      "y": -14,
      "z": 11,
      "name": "Rock_Ice"
    },
    {
      "x": -11,
      "y": -15,
      "z": 12,
      "name": "Rock_Ice"
    },
    {
      "x": -10,
      "y": -19,
      "z": 4,
      "name": "Rock_Ice"
    },
    {
      "x": -10,
      "y": -18,
      "z": 4,
      "name": "Rock_Ice"
    },
    {
      "x": -10,
      "y": -17,
      "z": 4,
      "name": "Rock_Ice"
    },
    {
      "x": -10,
      "y": -16,
      "z": 4,
      "name": "Rock_Ice"
    },
    {
      "x": -10,
      "y": -15,
      "z": 4,
      "name": "Rock_Ice"
    },
    {
      "x": -10,
      "y": -14,
      "z": 4,
      "name": "Rock_Ice"
    },
    {
      "x": -10,
      "y": -13,
      "z": 4,
      "name": "Rock_Ice"
    },
    {
      "x": -10,
      "y": -21,
      "z": 5,
      "name": "Rock_Ice"
    },
    {
      "x": -10,
      "y": -20,
      "z": 5,
      "name": "Rock_Ice"
    },
    {
      "x": -10,
      "y": -19,
      "z": 5,
      "name": "Rock_Ice"
    },
    {
      "x": -10,
      "y": -18,
      "z": 5,
      "name": "Rock_Ice"
    },
    {
      "x": -10,
      "y": -17,
      "z": 5,
      "name": "Rock_Ice"
    },
    {
      "x": -10,
      "y": -16,
      "z": 5,
      "name": "Rock_Ice"
    },
    {
      "x": -10,
      "y": -15,
      "z": 5,
      "name": "Rock_Ice"
    },
    {
      "x": -10,
      "y": -14,
      "z": 5,
      "name": "Rock_Ice"
    },
    {
      "x": -10,
      "y": -13,
      "z": 5,
      "name": "Rock_Ice"
    },
    {
      "x": -10,
      "y": -23,
      "z": 6,
      "name": "Rock_Ice"
    },
    {
      "x": -10,
      "y": -22,
      "z": 6,
      "name": "Rock_Ice"
    },
    {
      "x": -10,
      "y": -21,
      "z": 6,
      "name": "Rock_Ice"
    },
    {
      "x": -10,
      "y": -20,
      "z": 6,
      "name": "Rock_Ice"
    },
    {
      "x": -10,
      "y": -19,
      "z": 6,
      "name": "Rock_Ice"
    },
    {
      "x": -10,
      "y": -18,
      "z": 6,
      "name": "Rock_Ice"
    },
    {
      "x": -10,
      "y": -17,
      "z": 6,
      "name": "Rock_Ice"
    },
    {
      "x": -10,
      "y": -16,
      "z": 6,
      "name": "Rock_Ice"
    },
    {
      "x": -10,
      "y": -15,
      "z": 6,
      "name": "Rock_Ice"
    },
    {
      "x": -10,
      "y": -14,
      "z": 6,
      "name": "Rock_Ice"
    },
    {
      "x": -10,
      "y": -13,
      "z": 6,
      "name": "Rock_Ice"
    },
    {
      "x": -10,
      "y": -30,
      "z": 7,
      "name": "Rock_Ice"
    },
    {
      "x": -10,
      "y": -29,
      "z": 7,
      "name": "Rock_Ice"
    },
    {
      "x": -10,
      "y": -28,
      "z": 7,
      "name": "Rock_Ice"
    },
    {
      "x": -10,
      "y": -27,
      "z": 7,
      "name": "Rock_Ice"
    },
    {
      "x": -10,
      "y": -26,
      "z": 7,
      "name": "Rock_Ice"
    },
    {
      "x": -10,
      "y": -25,
      "z": 7,
      "name": "Rock_Ice"
    },
    {
      "x": -10,
      "y": -24,
      "z": 7,
      "name": "Rock_Ice"
    },
    {
      "x": -10,
      "y": -23,
      "z": 7,
      "name": "Rock_Ice"
    },
    {
      "x": -10,
      "y": -22,
      "z": 7,
      "name": "Rock_Ice"
    },
    {
      "x": -10,
      "y": -21,
      "z": 7,
      "name": "Rock_Ice"
    },
    {
      "x": -10,
      "y": -20,
      "z": 7,
      "name": "Rock_Ice"
    },
    {
      "x": -10,
      "y": -19,
      "z": 7,
      "name": "Rock_Ice"
    },
    {
      "x": -10,
      "y": -18,
      "z": 7,
      "name": "Rock_Ice"
    },
    {
      "x": -10,
      "y": -17,
      "z": 7,
      "name": "Rock_Ice"
    },
    {
      "x": -10,
      "y": -16,
      "z": 7,
      "name": "Rock_Ice"
    },
    {
      "x": -10,
      "y": -15,
      "z": 7,
      "name": "Rock_Ice"
    },
    {
      "x": -10,
      "y": -14,
      "z": 7,
      "name": "Rock_Ice"
    },
    {
      "x": -10,
      "y": -13,
      "z": 7,
      "name": "Rock_Ice"
    },
    {
      "x": -10,
      "y": -12,
      "z": 7,
      "name": "Rock_Ice"
    },
    {
      "x": -10,
      "y": -32,
      "z": 8,
      "name": "Rock_Ice"
    },
    {
      "x": -10,
      "y": -31,
      "z": 8,
      "name": "Rock_Ice"
    },
    {
      "x": -10,
      "y": -30,
      "z": 8,
      "name": "Rock_Ice"
    },
    {
      "x": -10,
      "y": -29,
      "z": 8,
      "name": "Rock_Ice"
    },
    {
      "x": -10,
      "y": -28,
      "z": 8,
      "name": "Rock_Ice"
    },
    {
      "x": -10,
      "y": -27,
      "z": 8,
      "name": "Rock_Ice"
    },
    {
      "x": -10,
      "y": -26,
      "z": 8,
      "name": "Rock_Ice"
    },
    {
      "x": -10,
      "y": -25,
      "z": 8,
      "name": "Rock_Ice"
    },
    {
      "x": -10,
      "y": -24,
      "z": 8,
      "name": "Rock_Ice"
    },
    {
      "x": -10,
      "y": -23,
      "z": 8,
      "name": "Rock_Ice"
    },
    {
      "x": -10,
      "y": -22,
      "z": 8,
      "name": "Rock_Ice"
    },
    {
      "x": -10,
      "y": -21,
      "z": 8,
      "name": "Rock_Ice"
    },
    {
      "x": -10,
      "y": -20,
      "z": 8,
      "name": "Rock_Ice"
    },
    {
      "x": -10,
      "y": -19,
      "z": 8,
      "name": "Rock_Ice"
    },
    {
      "x": -10,
      "y": -18,
      "z": 8,
      "name": "Rock_Ice"
    },
    {
      "x": -10,
      "y": -17,
      "z": 8,
      "name": "Rock_Ice"
    },
    {
      "x": -10,
      "y": -16,
      "z": 8,
      "name": "Rock_Ice"
    },
    {
      "x": -10,
      "y": -15,
      "z": 8,
      "name": "Rock_Ice"
    },
    {
      "x": -10,
      "y": -14,
      "z": 8,
      "name": "Rock_Ice"
    },
    {
      "x": -10,
      "y": -13,
      "z": 8,
      "name": "Rock_Ice"
    },
    {
      "x": -10,
      "y": -35,
      "z": 9,
      "name": "Rock_Ice"
    },
    {
      "x": -10,
      "y": -34,
      "z": 9,
      "name": "Rock_Ice"
    },
    {
      "x": -10,
      "y": -33,
      "z": 9,
      "name": "Rock_Ice"
    },
    {
      "x": -10,
      "y": -32,
      "z": 9,
      "name": "Rock_Ice"
    },
    {
      "x": -10,
      "y": -31,
      "z": 9,
      "name": "Rock_Ice"
    },
    {
      "x": -10,
      "y": -30,
      "z": 9,
      "name": "Rock_Ice"
    },
    {
      "x": -10,
      "y": -29,
      "z": 9,
      "name": "Rock_Ice"
    },
    {
      "x": -10,
      "y": -28,
      "z": 9,
      "name": "Rock_Ice"
    },
    {
      "x": -10,
      "y": -27,
      "z": 9,
      "name": "Rock_Ice"
    },
    {
      "x": -10,
      "y": -26,
      "z": 9,
      "name": "Rock_Ice"
    },
    {
      "x": -10,
      "y": -25,
      "z": 9,
      "name": "Rock_Ice"
    },
    {
      "x": -10,
      "y": -24,
      "z": 9,
      "name": "Rock_Ice"
    },
    {
      "x": -10,
      "y": -23,
      "z": 9,
      "name": "Rock_Ice"
    },
    {
      "x": -10,
      "y": -22,
      "z": 9,
      "name": "Rock_Ice"
    },
    {
      "x": -10,
      "y": -21,
      "z": 9,
      "name": "Rock_Ice"
    },
    {
      "x": -10,
      "y": -20,
      "z": 9,
      "name": "Rock_Ice"
    },
    {
      "x": -10,
      "y": -19,
      "z": 9,
      "name": "Rock_Ice"
    },
    {
      "x": -10,
      "y": -18,
      "z": 9,
      "name": "Rock_Ice"
    },
    {
      "x": -10,
      "y": -17,
      "z": 9,
      "name": "Rock_Ice"
    },
    {
      "x": -10,
      "y": -16,
      "z": 9,
      "name": "Rock_Ice"
    },
    {
      "x": -10,
      "y": -15,
      "z": 9,
      "name": "Rock_Ice"
    },
    {
      "x": -10,
      "y": -14,
      "z": 9,
      "name": "Rock_Ice"
    },
    {
      "x": -10,
      "y": -13,
      "z": 9,
      "name": "Rock_Ice"
    },
    {
      "x": -10,
      "y": -35,
      "z": 10,
      "name": "Rock_Ice"
    },
    {
      "x": -10,
      "y": -34,
      "z": 10,
      "name": "Rock_Ice"
    },
    {
      "x": -10,
      "y": -33,
      "z": 10,
      "name": "Rock_Ice"
    },
    {
      "x": -10,
      "y": -32,
      "z": 10,
      "name": "Rock_Ice"
    },
    {
      "x": -10,
      "y": -31,
      "z": 10,
      "name": "Rock_Ice"
    },
    {
      "x": -10,
      "y": -30,
      "z": 10,
      "name": "Rock_Ice"
    },
    {
      "x": -10,
      "y": -29,
      "z": 10,
      "name": "Rock_Ice"
    },
    {
      "x": -10,
      "y": -28,
      "z": 10,
      "name": "Rock_Ice"
    },
    {
      "x": -10,
      "y": -27,
      "z": 10,
      "name": "Rock_Ice"
    },
    {
      "x": -10,
      "y": -26,
      "z": 10,
      "name": "Rock_Ice"
    },
    {
      "x": -10,
      "y": -25,
      "z": 10,
      "name": "Rock_Ice"
    },
    {
      "x": -10,
      "y": -24,
      "z": 10,
      "name": "Rock_Ice"
    },
    {
      "x": -10,
      "y": -23,
      "z": 10,
      "name": "Rock_Ice"
    },
    {
      "x": -10,
      "y": -22,
      "z": 10,
      "name": "Rock_Ice"
    },
    {
      "x": -10,
      "y": -21,
      "z": 10,
      "name": "Rock_Ice"
    },
    {
      "x": -10,
      "y": -20,
      "z": 10,
      "name": "Rock_Ice"
    },
    {
      "x": -10,
      "y": -19,
      "z": 10,
      "name": "Rock_Ice"
    },
    {
      "x": -10,
      "y": -18,
      "z": 10,
      "name": "Rock_Ice"
    },
    {
      "x": -10,
      "y": -17,
      "z": 10,
      "name": "Rock_Ice"
    },
    {
      "x": -10,
      "y": -16,
      "z": 10,
      "name": "Rock_Ice"
    },
    {
      "x": -10,
      "y": -15,
      "z": 10,
      "name": "Rock_Ice"
    },
    {
      "x": -10,
      "y": -14,
      "z": 10,
      "name": "Rock_Ice"
    },
    {
      "x": -10,
      "y": -13,
      "z": 10,
      "name": "Rock_Ice"
    },
    {
      "x": -10,
      "y": -21,
      "z": 11,
      "name": "Rock_Ice"
    },
    {
      "x": -10,
      "y": -20,
      "z": 11,
      "name": "Rock_Ice"
    },
    {
      "x": -10,
      "y": -19,
      "z": 11,
      "name": "Rock_Ice"
    },
    {
      "x": -10,
      "y": -18,
      "z": 11,
      "name": "Rock_Ice"
    },
    {
      "x": -10,
      "y": -17,
      "z": 11,
      "name": "Rock_Ice"
    },
    {
      "x": -10,
      "y": -16,
      "z": 11,
      "name": "Rock_Ice"
    },
    {
      "x": -10,
      "y": -15,
      "z": 11,
      "name": "Rock_Ice"
    },
    {
      "x": -10,
      "y": -14,
      "z": 11,
      "name": "Rock_Ice"
    },
    {
      "x": -10,
      "y": -17,
      "z": 12,
      "name": "Rock_Ice"
    },
    {
      "x": -10,
      "y": -16,
      "z": 12,
      "name": "Rock_Ice"
    },
    {
      "x": -10,
      "y": -15,
      "z": 12,
      "name": "Rock_Ice"
    },
    {
      "x": -9,
      "y": -19,
      "z": 3,
      "name": "Rock_Ice"
    },
    {
      "x": -9,
      "y": -18,
      "z": 3,
      "name": "Rock_Ice"
    },
    {
      "x": -9,
      "y": -19,
      "z": 4,
      "name": "Rock_Ice"
    },
    {
      "x": -9,
      "y": -18,
      "z": 4,
      "name": "Rock_Ice"
    },
    {
      "x": -9,
      "y": -17,
      "z": 4,
      "name": "Rock_Ice"
    },
    {
      "x": -9,
      "y": -16,
      "z": 4,
      "name": "Rock_Ice"
    },
    {
      "x": -9,
      "y": -15,
      "z": 4,
      "name": "Rock_Ice"
    },
    {
      "x": -9,
      "y": -14,
      "z": 4,
      "name": "Rock_Ice"
    },
    {
      "x": -9,
      "y": -13,
      "z": 4,
      "name": "Rock_Ice"
    },
    {
      "x": -9,
      "y": -12,
      "z": 4,
      "name": "Rock_Ice"
    },
    {
      "x": -9,
      "y": -21,
      "z": 5,
      "name": "Rock_Ice"
    },
    {
      "x": -9,
      "y": -20,
      "z": 5,
      "name": "Rock_Ice"
    },
    {
      "x": -9,
      "y": -19,
      "z": 5,
      "name": "Rock_Ice"
    },
    {
      "x": -9,
      "y": -18,
      "z": 5,
      "name": "Rock_Ice"
    },
    {
      "x": -9,
      "y": -17,
      "z": 5,
      "name": "Rock_Ice"
    },
    {
      "x": -9,
      "y": -16,
      "z": 5,
      "name": "Rock_Ice"
    },
    {
      "x": -9,
      "y": -15,
      "z": 5,
      "name": "Rock_Ice"
    },
    {
      "x": -9,
      "y": -14,
      "z": 5,
      "name": "Rock_Ice"
    },
    {
      "x": -9,
      "y": -13,
      "z": 5,
      "name": "Rock_Ice"
    },
    {
      "x": -9,
      "y": -12,
      "z": 5,
      "name": "Rock_Ice"
    },
    {
      "x": -9,
      "y": -23,
      "z": 6,
      "name": "Rock_Ice"
    },
    {
      "x": -9,
      "y": -22,
      "z": 6,
      "name": "Rock_Ice"
    },
    {
      "x": -9,
      "y": -21,
      "z": 6,
      "name": "Rock_Ice"
    },
    {
      "x": -9,
      "y": -20,
      "z": 6,
      "name": "Rock_Ice"
    },
    {
      "x": -9,
      "y": -19,
      "z": 6,
      "name": "Rock_Ice"
    },
    {
      "x": -9,
      "y": -18,
      "z": 6,
      "name": "Rock_Ice"
    },
    {
      "x": -9,
      "y": -17,
      "z": 6,
      "name": "Rock_Ice"
    },
    {
      "x": -9,
      "y": -16,
      "z": 6,
      "name": "Rock_Ice"
    },
    {
      "x": -9,
      "y": -15,
      "z": 6,
      "name": "Rock_Ice"
    },
    {
      "x": -9,
      "y": -14,
      "z": 6,
      "name": "Rock_Ice"
    },
    {
      "x": -9,
      "y": -13,
      "z": 6,
      "name": "Rock_Ice"
    },
    {
      "x": -9,
      "y": -12,
      "z": 6,
      "name": "Rock_Ice"
    },
    {
      "x": -9,
      "y": -28,
      "z": 7,
      "name": "Rock_Ice"
    },
    {
      "x": -9,
      "y": -27,
      "z": 7,
      "name": "Rock_Ice"
    },
    {
      "x": -9,
      "y": -26,
      "z": 7,
      "name": "Rock_Ice"
    },
    {
      "x": -9,
      "y": -25,
      "z": 7,
      "name": "Rock_Ice"
    },
    {
      "x": -9,
      "y": -24,
      "z": 7,
      "name": "Rock_Ice"
    },
    {
      "x": -9,
      "y": -23,
      "z": 7,
      "name": "Rock_Ice"
    },
    {
      "x": -9,
      "y": -22,
      "z": 7,
      "name": "Rock_Ice"
    },
    {
      "x": -9,
      "y": -21,
      "z": 7,
      "name": "Rock_Ice"
    },
    {
      "x": -9,
      "y": -20,
      "z": 7,
      "name": "Rock_Ice"
    },
    {
      "x": -9,
      "y": -19,
      "z": 7,
      "name": "Rock_Ice"
    },
    {
      "x": -9,
      "y": -18,
      "z": 7,
      "name": "Rock_Ice"
    },
    {
      "x": -9,
      "y": -17,
      "z": 7,
      "name": "Rock_Ice"
    },
    {
      "x": -9,
      "y": -16,
      "z": 7,
      "name": "Rock_Ice"
    },
    {
      "x": -9,
      "y": -15,
      "z": 7,
      "name": "Rock_Ice"
    },
    {
      "x": -9,
      "y": -14,
      "z": 7,
      "name": "Rock_Ice"
    },
    {
      "x": -9,
      "y": -13,
      "z": 7,
      "name": "Rock_Ice"
    },
    {
      "x": -9,
      "y": -12,
      "z": 7,
      "name": "Rock_Ice"
    },
    {
      "x": -9,
      "y": -11,
      "z": 7,
      "name": "Rock_Ice"
    },
    {
      "x": -9,
      "y": -31,
      "z": 8,
      "name": "Rock_Ice"
    },
    {
      "x": -9,
      "y": -30,
      "z": 8,
      "name": "Rock_Ice"
    },
    {
      "x": -9,
      "y": -29,
      "z": 8,
      "name": "Rock_Ice"
    },
    {
      "x": -9,
      "y": -28,
      "z": 8,
      "name": "Rock_Ice"
    },
    {
      "x": -9,
      "y": -27,
      "z": 8,
      "name": "Rock_Ice"
    },
    {
      "x": -9,
      "y": -26,
      "z": 8,
      "name": "Rock_Ice"
    },
    {
      "x": -9,
      "y": -25,
      "z": 8,
      "name": "Rock_Ice"
    },
    {
      "x": -9,
      "y": -24,
      "z": 8,
      "name": "Rock_Ice"
    },
    {
      "x": -9,
      "y": -23,
      "z": 8,
      "name": "Rock_Ice"
    },
    {
      "x": -9,
      "y": -22,
      "z": 8,
      "name": "Rock_Ice"
    },
    {
      "x": -9,
      "y": -21,
      "z": 8,
      "name": "Rock_Ice"
    },
    {
      "x": -9,
      "y": -20,
      "z": 8,
      "name": "Rock_Ice"
    },
    {
      "x": -9,
      "y": -19,
      "z": 8,
      "name": "Rock_Ice"
    },
    {
      "x": -9,
      "y": -18,
      "z": 8,
      "name": "Rock_Ice"
    },
    {
      "x": -9,
      "y": -17,
      "z": 8,
      "name": "Rock_Ice"
    },
    {
      "x": -9,
      "y": -16,
      "z": 8,
      "name": "Rock_Ice"
    },
    {
      "x": -9,
      "y": -15,
      "z": 8,
      "name": "Rock_Ice"
    },
    {
      "x": -9,
      "y": -14,
      "z": 8,
      "name": "Rock_Ice"
    },
    {
      "x": -9,
      "y": -13,
      "z": 8,
      "name": "Rock_Ice"
    },
    {
      "x": -9,
      "y": -12,
      "z": 8,
      "name": "Rock_Ice"
    },
    {
      "x": -9,
      "y": -35,
      "z": 9,
      "name": "Rock_Ice"
    },
    {
      "x": -9,
      "y": -34,
      "z": 9,
      "name": "Rock_Ice"
    },
    {
      "x": -9,
      "y": -33,
      "z": 9,
      "name": "Rock_Ice"
    },
    {
      "x": -9,
      "y": -32,
      "z": 9,
      "name": "Rock_Ice"
    },
    {
      "x": -9,
      "y": -31,
      "z": 9,
      "name": "Rock_Ice"
    },
    {
      "x": -9,
      "y": -30,
      "z": 9,
      "name": "Rock_Ice"
    },
    {
      "x": -9,
      "y": -29,
      "z": 9,
      "name": "Rock_Ice"
    },
    {
      "x": -9,
      "y": -28,
      "z": 9,
      "name": "Rock_Ice"
    },
    {
      "x": -9,
      "y": -27,
      "z": 9,
      "name": "Rock_Ice"
    },
    {
      "x": -9,
      "y": -26,
      "z": 9,
      "name": "Rock_Ice"
    },
    {
      "x": -9,
      "y": -25,
      "z": 9,
      "name": "Rock_Ice"
    },
    {
      "x": -9,
      "y": -24,
      "z": 9,
      "name": "Rock_Ice"
    },
    {
      "x": -9,
      "y": -23,
      "z": 9,
      "name": "Rock_Ice"
    },
    {
      "x": -9,
      "y": -22,
      "z": 9,
      "name": "Rock_Ice"
    },
    {
      "x": -9,
      "y": -21,
      "z": 9,
      "name": "Rock_Ice"
    },
    {
      "x": -9,
      "y": -20,
      "z": 9,
      "name": "Rock_Ice"
    },
    {
      "x": -9,
      "y": -19,
      "z": 9,
      "name": "Rock_Ice"
    },
    {
      "x": -9,
      "y": -18,
      "z": 9,
      "name": "Rock_Ice"
    },
    {
      "x": -9,
      "y": -17,
      "z": 9,
      "name": "Rock_Ice"
    },
    {
      "x": -9,
      "y": -16,
      "z": 9,
      "name": "Rock_Ice"
    },
    {
      "x": -9,
      "y": -15,
      "z": 9,
      "name": "Rock_Ice"
    },
    {
      "x": -9,
      "y": -14,
      "z": 9,
      "name": "Rock_Ice"
    },
    {
      "x": -9,
      "y": -13,
      "z": 9,
      "name": "Rock_Ice"
    },
    {
      "x": -9,
      "y": -12,
      "z": 9,
      "name": "Rock_Ice"
    },
    {
      "x": -9,
      "y": -35,
      "z": 10,
      "name": "Rock_Ice"
    },
    {
      "x": -9,
      "y": -34,
      "z": 10,
      "name": "Rock_Ice"
    },
    {
      "x": -9,
      "y": -33,
      "z": 10,
      "name": "Rock_Ice"
    },
    {
      "x": -9,
      "y": -32,
      "z": 10,
      "name": "Rock_Ice"
    },
    {
      "x": -9,
      "y": -21,
      "z": 10,
      "name": "Rock_Ice"
    },
    {
      "x": -9,
      "y": -20,
      "z": 10,
      "name": "Rock_Ice"
    },
    {
      "x": -9,
      "y": -19,
      "z": 10,
      "name": "Rock_Ice"
    },
    {
      "x": -9,
      "y": -18,
      "z": 10,
      "name": "Rock_Ice"
    },
    {
      "x": -9,
      "y": -17,
      "z": 10,
      "name": "Rock_Ice"
    },
    {
      "x": -9,
      "y": -16,
      "z": 10,
      "name": "Rock_Ice"
    },
    {
      "x": -9,
      "y": -15,
      "z": 10,
      "name": "Rock_Ice"
    },
    {
      "x": -9,
      "y": -14,
      "z": 10,
      "name": "Rock_Ice"
    },
    {
      "x": -9,
      "y": -13,
      "z": 10,
      "name": "Rock_Ice"
    },
    {
      "x": -9,
      "y": -16,
      "z": 11,
      "name": "Rock_Ice"
    },
    {
      "x": -9,
      "y": -15,
      "z": 11,
      "name": "Rock_Ice"
    },
    {
      "x": -9,
      "y": -14,
      "z": 11,
      "name": "Rock_Ice"
    },
    {
      "x": -9,
      "y": -13,
      "z": 11,
      "name": "Rock_Ice"
    },
    {
      "x": -9,
      "y": -15,
      "z": 12,
      "name": "Rock_Ice"
    },
    {
      "x": -9,
      "y": -14,
      "z": 12,
      "name": "Rock_Ice"
    },
    {
      "x": -8,
      "y": -19,
      "z": 2,
      "name": "Rock_Ice"
    },
    {
      "x": -8,
      "y": -18,
      "z": 2,
      "name": "Rock_Ice"
    },
    {
      "x": -8,
      "y": -19,
      "z": 3,
      "name": "Rock_Ice"
    },
    {
      "x": -8,
      "y": -18,
      "z": 3,
      "name": "Rock_Ice"
    },
    {
      "x": -8,
      "y": -17,
      "z": 3,
      "name": "Rock_Ice"
    },
    {
      "x": -8,
      "y": -16,
      "z": 3,
      "name": "Rock_Ice"
    },
    {
      "x": -8,
      "y": -15,
      "z": 3,
      "name": "Rock_Ice"
    },
    {
      "x": -8,
      "y": -14,
      "z": 3,
      "name": "Rock_Ice"
    },
    {
      "x": -8,
      "y": -13,
      "z": 3,
      "name": "Rock_Ice"
    },
    {
      "x": -8,
      "y": -12,
      "z": 3,
      "name": "Rock_Ice"
    },
    {
      "x": -8,
      "y": -11,
      "z": 3,
      "name": "Rock_Ice"
    },
    {
      "x": -8,
      "y": -21,
      "z": 4,
      "name": "Rock_Ice"
    },
    {
      "x": -8,
      "y": -20,
      "z": 4,
      "name": "Rock_Ice"
    },
    {
      "x": -8,
      "y": -19,
      "z": 4,
      "name": "Rock_Ice"
    },
    {
      "x": -8,
      "y": -18,
      "z": 4,
      "name": "Rock_Ice"
    },
    {
      "x": -8,
      "y": -17,
      "z": 4,
      "name": "Rock_Ice"
    },
    {
      "x": -8,
      "y": -16,
      "z": 4,
      "name": "Rock_Ice"
    },
    {
      "x": -8,
      "y": -15,
      "z": 4,
      "name": "Rock_Ice"
    },
    {
      "x": -8,
      "y": -14,
      "z": 4,
      "name": "Rock_Ice"
    },
    {
      "x": -8,
      "y": -13,
      "z": 4,
      "name": "Rock_Ice"
    },
    {
      "x": -8,
      "y": -12,
      "z": 4,
      "name": "Rock_Ice"
    },
    {
      "x": -8,
      "y": -11,
      "z": 4,
      "name": "Rock_Ice"
    },
    {
      "x": -8,
      "y": -10,
      "z": 4,
      "name": "Rock_Ice"
    },
    {
      "x": -8,
      "y": -23,
      "z": 5,
      "name": "Rock_Ice"
    },
    {
      "x": -8,
      "y": -22,
      "z": 5,
      "name": "Rock_Ice"
    },
    {
      "x": -8,
      "y": -21,
      "z": 5,
      "name": "Rock_Ice"
    },
    {
      "x": -8,
      "y": -20,
      "z": 5,
      "name": "Rock_Ice"
    },
    {
      "x": -8,
      "y": -19,
      "z": 5,
      "name": "Rock_Ice"
    },
    {
      "x": -8,
      "y": -18,
      "z": 5,
      "name": "Rock_Ice"
    },
    {
      "x": -8,
      "y": -17,
      "z": 5,
      "name": "Rock_Ice"
    },
    {
      "x": -8,
      "y": -16,
      "z": 5,
      "name": "Rock_Ice"
    },
    {
      "x": -8,
      "y": -15,
      "z": 5,
      "name": "Rock_Ice"
    },
    {
      "x": -8,
      "y": -14,
      "z": 5,
      "name": "Rock_Ice"
    },
    {
      "x": -8,
      "y": -13,
      "z": 5,
      "name": "Rock_Ice"
    },
    {
      "x": -8,
      "y": -12,
      "z": 5,
      "name": "Rock_Ice"
    },
    {
      "x": -8,
      "y": -11,
      "z": 5,
      "name": "Rock_Ice"
    },
    {
      "x": -8,
      "y": -27,
      "z": 6,
      "name": "Rock_Ice"
    },
    {
      "x": -8,
      "y": -26,
      "z": 6,
      "name": "Rock_Ice"
    },
    {
      "x": -8,
      "y": -25,
      "z": 6,
      "name": "Rock_Ice"
    },
    {
      "x": -8,
      "y": -24,
      "z": 6,
      "name": "Rock_Ice"
    },
    {
      "x": -8,
      "y": -23,
      "z": 6,
      "name": "Rock_Ice"
    },
    {
      "x": -8,
      "y": -22,
      "z": 6,
      "name": "Rock_Ice"
    },
    {
      "x": -8,
      "y": -21,
      "z": 6,
      "name": "Rock_Ice"
    },
    {
      "x": -8,
      "y": -20,
      "z": 6,
      "name": "Rock_Ice"
    },
    {
      "x": -8,
      "y": -19,
      "z": 6,
      "name": "Rock_Ice"
    },
    {
      "x": -8,
      "y": -18,
      "z": 6,
      "name": "Rock_Ice"
    },
    {
      "x": -8,
      "y": -17,
      "z": 6,
      "name": "Rock_Ice"
    },
    {
      "x": -8,
      "y": -16,
      "z": 6,
      "name": "Rock_Ice"
    },
    {
      "x": -8,
      "y": -15,
      "z": 6,
      "name": "Rock_Ice"
    },
    {
      "x": -8,
      "y": -14,
      "z": 6,
      "name": "Rock_Ice"
    },
    {
      "x": -8,
      "y": -13,
      "z": 6,
      "name": "Rock_Ice"
    },
    {
      "x": -8,
      "y": -12,
      "z": 6,
      "name": "Rock_Ice"
    },
    {
      "x": -8,
      "y": -11,
      "z": 6,
      "name": "Rock_Ice"
    },
    {
      "x": -8,
      "y": -10,
      "z": 6,
      "name": "Rock_Ice"
    },
    {
      "x": -8,
      "y": -29,
      "z": 7,
      "name": "Rock_Ice"
    },
    {
      "x": -8,
      "y": -28,
      "z": 7,
      "name": "Rock_Ice"
    },
    {
      "x": -8,
      "y": -27,
      "z": 7,
      "name": "Rock_Ice"
    },
    {
      "x": -8,
      "y": -26,
      "z": 7,
      "name": "Rock_Ice"
    },
    {
      "x": -8,
      "y": -25,
      "z": 7,
      "name": "Rock_Ice"
    },
    {
      "x": -8,
      "y": -24,
      "z": 7,
      "name": "Rock_Ice"
    },
    {
      "x": -8,
      "y": -23,
      "z": 7,
      "name": "Rock_Ice"
    },
    {
      "x": -8,
      "y": -22,
      "z": 7,
      "name": "Rock_Ice"
    },
    {
      "x": -8,
      "y": -21,
      "z": 7,
      "name": "Rock_Ice"
    },
    {
      "x": -8,
      "y": -20,
      "z": 7,
      "name": "Rock_Ice"
    },
    {
      "x": -8,
      "y": -19,
      "z": 7,
      "name": "Rock_Ice"
    },
    {
      "x": -8,
      "y": -18,
      "z": 7,
      "name": "Rock_Ice"
    },
    {
      "x": -8,
      "y": -17,
      "z": 7,
      "name": "Rock_Ice"
    },
    {
      "x": -8,
      "y": -16,
      "z": 7,
      "name": "Rock_Ice"
    },
    {
      "x": -8,
      "y": -15,
      "z": 7,
      "name": "Rock_Ice"
    },
    {
      "x": -8,
      "y": -14,
      "z": 7,
      "name": "Rock_Ice"
    },
    {
      "x": -8,
      "y": -13,
      "z": 7,
      "name": "Rock_Ice"
    },
    {
      "x": -8,
      "y": -12,
      "z": 7,
      "name": "Rock_Ice"
    },
    {
      "x": -8,
      "y": -11,
      "z": 7,
      "name": "Rock_Ice"
    },
    {
      "x": -8,
      "y": -29,
      "z": 8,
      "name": "Rock_Ice"
    },
    {
      "x": -8,
      "y": -28,
      "z": 8,
      "name": "Rock_Ice"
    },
    {
      "x": -8,
      "y": -27,
      "z": 8,
      "name": "Rock_Ice"
    },
    {
      "x": -8,
      "y": -26,
      "z": 8,
      "name": "Rock_Ice"
    },
    {
      "x": -8,
      "y": -25,
      "z": 8,
      "name": "Rock_Ice"
    },
    {
      "x": -8,
      "y": -24,
      "z": 8,
      "name": "Rock_Ice"
    },
    {
      "x": -8,
      "y": -23,
      "z": 8,
      "name": "Rock_Ice"
    },
    {
      "x": -8,
      "y": -22,
      "z": 8,
      "name": "Rock_Ice"
    },
    {
      "x": -8,
      "y": -21,
      "z": 8,
      "name": "Rock_Ice"
    },
    {
      "x": -8,
      "y": -20,
      "z": 8,
      "name": "Rock_Ice"
    },
    {
      "x": -8,
      "y": -19,
      "z": 8,
      "name": "Rock_Ice"
    },
    {
      "x": -8,
      "y": -18,
      "z": 8,
      "name": "Rock_Ice"
    },
    {
      "x": -8,
      "y": -17,
      "z": 8,
      "name": "Rock_Ice"
    },
    {
      "x": -8,
      "y": -16,
      "z": 8,
      "name": "Rock_Ice"
    },
    {
      "x": -8,
      "y": -15,
      "z": 8,
      "name": "Rock_Ice"
    },
    {
      "x": -8,
      "y": -14,
      "z": 8,
      "name": "Rock_Ice"
    },
    {
      "x": -8,
      "y": -13,
      "z": 8,
      "name": "Rock_Ice"
    },
    {
      "x": -8,
      "y": -12,
      "z": 8,
      "name": "Rock_Ice"
    },
    {
      "x": -8,
      "y": -11,
      "z": 8,
      "name": "Rock_Ice"
    },
    {
      "x": -8,
      "y": -35,
      "z": 9,
      "name": "Rock_Ice"
    },
    {
      "x": -8,
      "y": -34,
      "z": 9,
      "name": "Rock_Ice"
    },
    {
      "x": -8,
      "y": -33,
      "z": 9,
      "name": "Rock_Ice"
    },
    {
      "x": -8,
      "y": -32,
      "z": 9,
      "name": "Rock_Ice"
    },
    {
      "x": -8,
      "y": -31,
      "z": 9,
      "name": "Rock_Ice"
    },
    {
      "x": -8,
      "y": -30,
      "z": 9,
      "name": "Rock_Ice"
    },
    {
      "x": -8,
      "y": -29,
      "z": 9,
      "name": "Rock_Ice"
    },
    {
      "x": -8,
      "y": -28,
      "z": 9,
      "name": "Rock_Ice"
    },
    {
      "x": -8,
      "y": -27,
      "z": 9,
      "name": "Rock_Ice"
    },
    {
      "x": -8,
      "y": -26,
      "z": 9,
      "name": "Rock_Ice"
    },
    {
      "x": -8,
      "y": -25,
      "z": 9,
      "name": "Rock_Ice"
    },
    {
      "x": -8,
      "y": -24,
      "z": 9,
      "name": "Rock_Ice"
    },
    {
      "x": -8,
      "y": -23,
      "z": 9,
      "name": "Rock_Ice"
    },
    {
      "x": -8,
      "y": -22,
      "z": 9,
      "name": "Rock_Ice"
    },
    {
      "x": -8,
      "y": -21,
      "z": 9,
      "name": "Rock_Ice"
    },
    {
      "x": -8,
      "y": -20,
      "z": 9,
      "name": "Rock_Ice"
    },
    {
      "x": -8,
      "y": -19,
      "z": 9,
      "name": "Rock_Ice"
    },
    {
      "x": -8,
      "y": -18,
      "z": 9,
      "name": "Rock_Ice"
    },
    {
      "x": -8,
      "y": -17,
      "z": 9,
      "name": "Rock_Ice"
    },
    {
      "x": -8,
      "y": -16,
      "z": 9,
      "name": "Rock_Ice"
    },
    {
      "x": -8,
      "y": -15,
      "z": 9,
      "name": "Rock_Ice"
    },
    {
      "x": -8,
      "y": -14,
      "z": 9,
      "name": "Rock_Ice"
    },
    {
      "x": -8,
      "y": -13,
      "z": 9,
      "name": "Rock_Ice"
    },
    {
      "x": -8,
      "y": -12,
      "z": 9,
      "name": "Rock_Ice"
    },
    {
      "x": -8,
      "y": -35,
      "z": 10,
      "name": "Rock_Ice"
    },
    {
      "x": -8,
      "y": -34,
      "z": 10,
      "name": "Rock_Ice"
    },
    {
      "x": -8,
      "y": -19,
      "z": 10,
      "name": "Rock_Ice"
    },
    {
      "x": -8,
      "y": -18,
      "z": 10,
      "name": "Rock_Ice"
    },
    {
      "x": -8,
      "y": -17,
      "z": 10,
      "name": "Rock_Ice"
    },
    {
      "x": -8,
      "y": -16,
      "z": 10,
      "name": "Rock_Ice"
    },
    {
      "x": -8,
      "y": -15,
      "z": 10,
      "name": "Rock_Ice"
    },
    {
      "x": -8,
      "y": -14,
      "z": 10,
      "name": "Rock_Ice"
    },
    {
      "x": -8,
      "y": -13,
      "z": 10,
      "name": "Rock_Ice"
    },
    {
      "x": -8,
      "y": -12,
      "z": 10,
      "name": "Rock_Ice"
    },
    {
      "x": -8,
      "y": -15,
      "z": 11,
      "name": "Rock_Ice"
    },
    {
      "x": -8,
      "y": -14,
      "z": 11,
      "name": "Rock_Ice"
    },
    {
      "x": -8,
      "y": -13,
      "z": 11,
      "name": "Rock_Ice"
    },
    {
      "x": -8,
      "y": -14,
      "z": 12,
      "name": "Rock_Ice"
    },
    {
      "x": -8,
      "y": -13,
      "z": 12,
      "name": "Rock_Ice"
    },
    {
      "x": -7,
      "y": -18,
      "z": 0,
      "name": "Rock_Ice"
    },
    {
      "x": -7,
      "y": -19,
      "z": 1,
      "name": "Rock_Ice"
    },
    {
      "x": -7,
      "y": -18,
      "z": 1,
      "name": "Rock_Ice"
    },
    {
      "x": -7,
      "y": -17,
      "z": 1,
      "name": "Rock_Ice"
    },
    {
      "x": -7,
      "y": -16,
      "z": 1,
      "name": "Rock_Ice"
    },
    {
      "x": -7,
      "y": -15,
      "z": 1,
      "name": "Rock_Ice"
    },
    {
      "x": -7,
      "y": -14,
      "z": 1,
      "name": "Rock_Ice"
    },
    {
      "x": -7,
      "y": -13,
      "z": 1,
      "name": "Rock_Ice"
    },
    {
      "x": -7,
      "y": -12,
      "z": 1,
      "name": "Rock_Ice"
    },
    {
      "x": -7,
      "y": -11,
      "z": 1,
      "name": "Rock_Ice"
    },
    {
      "x": -7,
      "y": -10,
      "z": 1,
      "name": "Rock_Ice"
    },
    {
      "x": -7,
      "y": -9,
      "z": 1,
      "name": "Rock_Ice"
    },
    {
      "x": -7,
      "y": -20,
      "z": 2,
      "name": "Rock_Ice"
    },
    {
      "x": -7,
      "y": -19,
      "z": 2,
      "name": "Rock_Ice"
    },
    {
      "x": -7,
      "y": -18,
      "z": 2,
      "name": "Rock_Ice"
    },
    {
      "x": -7,
      "y": -17,
      "z": 2,
      "name": "Rock_Ice"
    },
    {
      "x": -7,
      "y": -16,
      "z": 2,
      "name": "Rock_Ice"
    },
    {
      "x": -7,
      "y": -15,
      "z": 2,
      "name": "Rock_Ice"
    },
    {
      "x": -7,
      "y": -14,
      "z": 2,
      "name": "Rock_Ice"
    },
    {
      "x": -7,
      "y": -13,
      "z": 2,
      "name": "Rock_Ice"
    },
    {
      "x": -7,
      "y": -12,
      "z": 2,
      "name": "Rock_Ice"
    },
    {
      "x": -7,
      "y": -11,
      "z": 2,
      "name": "Rock_Ice"
    },
    {
      "x": -7,
      "y": -10,
      "z": 2,
      "name": "Rock_Ice"
    },
    {
      "x": -7,
      "y": -9,
      "z": 2,
      "name": "Rock_Ice"
    },
    {
      "x": -7,
      "y": -21,
      "z": 3,
      "name": "Rock_Ice"
    },
    {
      "x": -7,
      "y": -20,
      "z": 3,
      "name": "Rock_Ice"
    },
    {
      "x": -7,
      "y": -19,
      "z": 3,
      "name": "Rock_Ice"
    },
    {
      "x": -7,
      "y": -18,
      "z": 3,
      "name": "Rock_Ice"
    },
    {
      "x": -7,
      "y": -17,
      "z": 3,
      "name": "Rock_Ice"
    },
    {
      "x": -7,
      "y": -16,
      "z": 3,
      "name": "Rock_Ice"
    },
    {
      "x": -7,
      "y": -15,
      "z": 3,
      "name": "Rock_Ice"
    },
    {
      "x": -7,
      "y": -14,
      "z": 3,
      "name": "Rock_Ice"
    },
    {
      "x": -7,
      "y": -13,
      "z": 3,
      "name": "Rock_Ice"
    },
    {
      "x": -7,
      "y": -12,
      "z": 3,
      "name": "Rock_Ice"
    },
    {
      "x": -7,
      "y": -11,
      "z": 3,
      "name": "Rock_Ice"
    },
    {
      "x": -7,
      "y": -10,
      "z": 3,
      "name": "Rock_Ice"
    },
    {
      "x": -7,
      "y": -9,
      "z": 3,
      "name": "Rock_Ice"
    },
    {
      "x": -7,
      "y": -21,
      "z": 4,
      "name": "Rock_Ice"
    },
    {
      "x": -7,
      "y": -20,
      "z": 4,
      "name": "Rock_Ice"
    },
    {
      "x": -7,
      "y": -19,
      "z": 4,
      "name": "Rock_Ice"
    },
    {
      "x": -7,
      "y": -18,
      "z": 4,
      "name": "Rock_Ice"
    },
    {
      "x": -7,
      "y": -17,
      "z": 4,
      "name": "Rock_Ice"
    },
    {
      "x": -7,
      "y": -16,
      "z": 4,
      "name": "Rock_Ice"
    },
    {
      "x": -7,
      "y": -15,
      "z": 4,
      "name": "Rock_Ice"
    },
    {
      "x": -7,
      "y": -14,
      "z": 4,
      "name": "Rock_Ice"
    },
    {
      "x": -7,
      "y": -13,
      "z": 4,
      "name": "Rock_Ice"
    },
    {
      "x": -7,
      "y": -12,
      "z": 4,
      "name": "Rock_Ice"
    },
    {
      "x": -7,
      "y": -11,
      "z": 4,
      "name": "Rock_Ice"
    },
    {
      "x": -7,
      "y": -10,
      "z": 4,
      "name": "Rock_Ice"
    },
    {
      "x": -7,
      "y": -9,
      "z": 4,
      "name": "Rock_Ice"
    },
    {
      "x": -7,
      "y": -23,
      "z": 5,
      "name": "Rock_Ice"
    },
    {
      "x": -7,
      "y": -22,
      "z": 5,
      "name": "Rock_Ice"
    },
    {
      "x": -7,
      "y": -21,
      "z": 5,
      "name": "Rock_Ice"
    },
    {
      "x": -7,
      "y": -20,
      "z": 5,
      "name": "Rock_Ice"
    },
    {
      "x": -7,
      "y": -19,
      "z": 5,
      "name": "Rock_Ice"
    },
    {
      "x": -7,
      "y": -18,
      "z": 5,
      "name": "Rock_Ice"
    },
    {
      "x": -7,
      "y": -17,
      "z": 5,
      "name": "Rock_Ice"
    },
    {
      "x": -7,
      "y": -16,
      "z": 5,
      "name": "Rock_Ice"
    },
    {
      "x": -7,
      "y": -15,
      "z": 5,
      "name": "Rock_Ice"
    },
    {
      "x": -7,
      "y": -14,
      "z": 5,
      "name": "Rock_Ice"
    },
    {
      "x": -7,
      "y": -13,
      "z": 5,
      "name": "Rock_Ice"
    },
    {
      "x": -7,
      "y": -12,
      "z": 5,
      "name": "Rock_Ice"
    },
    {
      "x": -7,
      "y": -11,
      "z": 5,
      "name": "Rock_Ice"
    },
    {
      "x": -7,
      "y": -10,
      "z": 5,
      "name": "Rock_Ice"
    },
    {
      "x": -7,
      "y": -27,
      "z": 6,
      "name": "Rock_Ice"
    },
    {
      "x": -7,
      "y": -26,
      "z": 6,
      "name": "Rock_Ice"
    },
    {
      "x": -7,
      "y": -25,
      "z": 6,
      "name": "Rock_Ice"
    },
    {
      "x": -7,
      "y": -24,
      "z": 6,
      "name": "Rock_Ice"
    },
    {
      "x": -7,
      "y": -23,
      "z": 6,
      "name": "Rock_Ice"
    },
    {
      "x": -7,
      "y": -22,
      "z": 6,
      "name": "Rock_Ice"
    },
    {
      "x": -7,
      "y": -21,
      "z": 6,
      "name": "Rock_Ice"
    },
    {
      "x": -7,
      "y": -20,
      "z": 6,
      "name": "Rock_Ice"
    },
    {
      "x": -7,
      "y": -19,
      "z": 6,
      "name": "Rock_Ice"
    },
    {
      "x": -7,
      "y": -18,
      "z": 6,
      "name": "Rock_Ice"
    },
    {
      "x": -7,
      "y": -17,
      "z": 6,
      "name": "Rock_Ice"
    },
    {
      "x": -7,
      "y": -16,
      "z": 6,
      "name": "Rock_Ice"
    },
    {
      "x": -7,
      "y": -15,
      "z": 6,
      "name": "Rock_Ice"
    },
    {
      "x": -7,
      "y": -14,
      "z": 6,
      "name": "Rock_Ice"
    },
    {
      "x": -7,
      "y": -13,
      "z": 6,
      "name": "Rock_Ice"
    },
    {
      "x": -7,
      "y": -12,
      "z": 6,
      "name": "Rock_Ice"
    },
    {
      "x": -7,
      "y": -11,
      "z": 6,
      "name": "Rock_Ice"
    },
    {
      "x": -7,
      "y": -10,
      "z": 6,
      "name": "Rock_Ice"
    },
    {
      "x": -7,
      "y": -9,
      "z": 6,
      "name": "Rock_Ice"
    },
    {
      "x": -7,
      "y": -28,
      "z": 7,
      "name": "Rock_Ice"
    },
    {
      "x": -7,
      "y": -27,
      "z": 7,
      "name": "Rock_Ice"
    },
    {
      "x": -7,
      "y": -26,
      "z": 7,
      "name": "Rock_Ice"
    },
    {
      "x": -7,
      "y": -25,
      "z": 7,
      "name": "Rock_Ice"
    },
    {
      "x": -7,
      "y": -24,
      "z": 7,
      "name": "Rock_Ice"
    },
    {
      "x": -7,
      "y": -23,
      "z": 7,
      "name": "Rock_Ice"
    },
    {
      "x": -7,
      "y": -22,
      "z": 7,
      "name": "Rock_Ice"
    },
    {
      "x": -7,
      "y": -21,
      "z": 7,
      "name": "Rock_Ice"
    },
    {
      "x": -7,
      "y": -20,
      "z": 7,
      "name": "Rock_Ice"
    },
    {
      "x": -7,
      "y": -19,
      "z": 7,
      "name": "Rock_Ice"
    },
    {
      "x": -7,
      "y": -18,
      "z": 7,
      "name": "Rock_Ice"
    },
    {
      "x": -7,
      "y": -17,
      "z": 7,
      "name": "Rock_Ice"
    },
    {
      "x": -7,
      "y": -16,
      "z": 7,
      "name": "Rock_Ice"
    },
    {
      "x": -7,
      "y": -15,
      "z": 7,
      "name": "Rock_Ice"
    },
    {
      "x": -7,
      "y": -14,
      "z": 7,
      "name": "Rock_Ice"
    },
    {
      "x": -7,
      "y": -13,
      "z": 7,
      "name": "Rock_Ice"
    },
    {
      "x": -7,
      "y": -12,
      "z": 7,
      "name": "Rock_Ice"
    },
    {
      "x": -7,
      "y": -11,
      "z": 7,
      "name": "Rock_Ice"
    },
    {
      "x": -7,
      "y": -10,
      "z": 7,
      "name": "Rock_Ice"
    },
    {
      "x": -7,
      "y": -30,
      "z": 8,
      "name": "Rock_Ice"
    },
    {
      "x": -7,
      "y": -29,
      "z": 8,
      "name": "Rock_Ice"
    },
    {
      "x": -7,
      "y": -28,
      "z": 8,
      "name": "Rock_Ice"
    },
    {
      "x": -7,
      "y": -27,
      "z": 8,
      "name": "Rock_Ice"
    },
    {
      "x": -7,
      "y": -26,
      "z": 8,
      "name": "Rock_Ice"
    },
    {
      "x": -7,
      "y": -25,
      "z": 8,
      "name": "Rock_Ice"
    },
    {
      "x": -7,
      "y": -24,
      "z": 8,
      "name": "Rock_Ice"
    },
    {
      "x": -7,
      "y": -23,
      "z": 8,
      "name": "Rock_Ice"
    },
    {
      "x": -7,
      "y": -22,
      "z": 8,
      "name": "Rock_Ice"
    },
    {
      "x": -7,
      "y": -21,
      "z": 8,
      "name": "Rock_Ice"
    },
    {
      "x": -7,
      "y": -20,
      "z": 8,
      "name": "Rock_Ice"
    },
    {
      "x": -7,
      "y": -19,
      "z": 8,
      "name": "Rock_Ice"
    },
    {
      "x": -7,
      "y": -18,
      "z": 8,
      "name": "Rock_Ice"
    },
    {
      "x": -7,
      "y": -17,
      "z": 8,
      "name": "Rock_Ice"
    },
    {
      "x": -7,
      "y": -16,
      "z": 8,
      "name": "Rock_Ice"
    },
    {
      "x": -7,
      "y": -15,
      "z": 8,
      "name": "Rock_Ice"
    },
    {
      "x": -7,
      "y": -14,
      "z": 8,
      "name": "Rock_Ice"
    },
    {
      "x": -7,
      "y": -13,
      "z": 8,
      "name": "Rock_Ice"
    },
    {
      "x": -7,
      "y": -12,
      "z": 8,
      "name": "Rock_Ice"
    },
    {
      "x": -7,
      "y": -11,
      "z": 8,
      "name": "Rock_Ice"
    },
    {
      "x": -7,
      "y": -10,
      "z": 8,
      "name": "Rock_Ice"
    },
    {
      "x": -7,
      "y": -9,
      "z": 8,
      "name": "Rock_Ice"
    },
    {
      "x": -7,
      "y": -35,
      "z": 9,
      "name": "Rock_Ice"
    },
    {
      "x": -7,
      "y": -34,
      "z": 9,
      "name": "Rock_Ice"
    },
    {
      "x": -7,
      "y": -33,
      "z": 9,
      "name": "Rock_Ice"
    },
    {
      "x": -7,
      "y": -32,
      "z": 9,
      "name": "Rock_Ice"
    },
    {
      "x": -7,
      "y": -31,
      "z": 9,
      "name": "Rock_Ice"
    },
    {
      "x": -7,
      "y": -30,
      "z": 9,
      "name": "Rock_Ice"
    },
    {
      "x": -7,
      "y": -29,
      "z": 9,
      "name": "Rock_Ice"
    },
    {
      "x": -7,
      "y": -28,
      "z": 9,
      "name": "Rock_Ice"
    },
    {
      "x": -7,
      "y": -27,
      "z": 9,
      "name": "Rock_Ice"
    },
    {
      "x": -7,
      "y": -26,
      "z": 9,
      "name": "Rock_Ice"
    },
    {
      "x": -7,
      "y": -25,
      "z": 9,
      "name": "Rock_Ice"
    },
    {
      "x": -7,
      "y": -24,
      "z": 9,
      "name": "Rock_Ice"
    },
    {
      "x": -7,
      "y": -23,
      "z": 9,
      "name": "Rock_Ice"
    },
    {
      "x": -7,
      "y": -22,
      "z": 9,
      "name": "Rock_Ice"
    },
    {
      "x": -7,
      "y": -21,
      "z": 9,
      "name": "Rock_Ice"
    },
    {
      "x": -7,
      "y": -20,
      "z": 9,
      "name": "Rock_Ice"
    },
    {
      "x": -7,
      "y": -19,
      "z": 9,
      "name": "Rock_Ice"
    },
    {
      "x": -7,
      "y": -18,
      "z": 9,
      "name": "Rock_Ice"
    },
    {
      "x": -7,
      "y": -17,
      "z": 9,
      "name": "Rock_Ice"
    },
    {
      "x": -7,
      "y": -16,
      "z": 9,
      "name": "Rock_Ice"
    },
    {
      "x": -7,
      "y": -15,
      "z": 9,
      "name": "Rock_Ice"
    },
    {
      "x": -7,
      "y": -14,
      "z": 9,
      "name": "Rock_Ice"
    },
    {
      "x": -7,
      "y": -13,
      "z": 9,
      "name": "Rock_Ice"
    },
    {
      "x": -7,
      "y": -12,
      "z": 9,
      "name": "Rock_Ice"
    },
    {
      "x": -7,
      "y": -11,
      "z": 9,
      "name": "Rock_Ice"
    },
    {
      "x": -7,
      "y": -35,
      "z": 10,
      "name": "Rock_Ice"
    },
    {
      "x": -7,
      "y": -34,
      "z": 10,
      "name": "Rock_Ice"
    },
    {
      "x": -7,
      "y": -33,
      "z": 10,
      "name": "Rock_Ice"
    },
    {
      "x": -7,
      "y": -32,
      "z": 10,
      "name": "Rock_Ice"
    },
    {
      "x": -7,
      "y": -21,
      "z": 10,
      "name": "Rock_Ice"
    },
    {
      "x": -7,
      "y": -20,
      "z": 10,
      "name": "Rock_Ice"
    },
    {
      "x": -7,
      "y": -19,
      "z": 10,
      "name": "Rock_Ice"
    },
    {
      "x": -7,
      "y": -18,
      "z": 10,
      "name": "Rock_Ice"
    },
    {
      "x": -7,
      "y": -17,
      "z": 10,
      "name": "Rock_Ice"
    },
    {
      "x": -7,
      "y": -16,
      "z": 10,
      "name": "Rock_Ice"
    },
    {
      "x": -7,
      "y": -15,
      "z": 10,
      "name": "Rock_Ice"
    },
    {
      "x": -7,
      "y": -14,
      "z": 10,
      "name": "Rock_Ice"
    },
    {
      "x": -7,
      "y": -13,
      "z": 10,
      "name": "Rock_Ice"
    },
    {
      "x": -7,
      "y": -12,
      "z": 10,
      "name": "Rock_Ice"
    },
    {
      "x": -7,
      "y": -11,
      "z": 10,
      "name": "Rock_Ice"
    },
    {
      "x": -7,
      "y": -16,
      "z": 11,
      "name": "Rock_Ice"
    },
    {
      "x": -7,
      "y": -15,
      "z": 11,
      "name": "Rock_Ice"
    },
    {
      "x": -7,
      "y": -14,
      "z": 11,
      "name": "Rock_Ice"
    },
    {
      "x": -7,
      "y": -13,
      "z": 11,
      "name": "Rock_Ice"
    },
    {
      "x": -7,
      "y": -12,
      "z": 11,
      "name": "Rock_Ice"
    },
    {
      "x": -7,
      "y": -15,
      "z": 12,
      "name": "Rock_Ice"
    },
    {
      "x": -7,
      "y": -14,
      "z": 12,
      "name": "Rock_Ice"
    },
    {
      "x": -7,
      "y": -13,
      "z": 12,
      "name": "Rock_Ice"
    },
    {
      "x": -7,
      "y": -12,
      "z": 12,
      "name": "Rock_Ice"
    },
    {
      "x": -7,
      "y": -16,
      "z": 13,
      "name": "Rock_Ice"
    },
    {
      "x": -7,
      "y": -15,
      "z": 13,
      "name": "Rock_Ice"
    },
    {
      "x": -7,
      "y": -14,
      "z": 13,
      "name": "Rock_Ice"
    },
    {
      "x": -7,
      "y": -13,
      "z": 13,
      "name": "Rock_Ice"
    },
    {
      "x": -6,
      "y": -16,
      "z": 0,
      "name": "Rock_Ice"
    },
    {
      "x": -6,
      "y": -15,
      "z": 0,
      "name": "Rock_Ice"
    },
    {
      "x": -6,
      "y": -14,
      "z": 0,
      "name": "Rock_Ice"
    },
    {
      "x": -6,
      "y": -13,
      "z": 0,
      "name": "Rock_Ice"
    },
    {
      "x": -6,
      "y": -12,
      "z": 0,
      "name": "Rock_Ice"
    },
    {
      "x": -6,
      "y": -11,
      "z": 0,
      "name": "Rock_Ice"
    },
    {
      "x": -6,
      "y": -10,
      "z": 0,
      "name": "Rock_Ice"
    },
    {
      "x": -6,
      "y": -9,
      "z": 0,
      "name": "Rock_Ice"
    },
    {
      "x": -6,
      "y": -18,
      "z": 1,
      "name": "Rock_Ice"
    },
    {
      "x": -6,
      "y": -17,
      "z": 1,
      "name": "Rock_Ice"
    },
    {
      "x": -6,
      "y": -16,
      "z": 1,
      "name": "Rock_Ice"
    },
    {
      "x": -6,
      "y": -15,
      "z": 1,
      "name": "Rock_Ice"
    },
    {
      "x": -6,
      "y": -14,
      "z": 1,
      "name": "Rock_Ice"
    },
    {
      "x": -6,
      "y": -13,
      "z": 1,
      "name": "Rock_Ice"
    },
    {
      "x": -6,
      "y": -12,
      "z": 1,
      "name": "Rock_Ice"
    },
    {
      "x": -6,
      "y": -11,
      "z": 1,
      "name": "Rock_Ice"
    },
    {
      "x": -6,
      "y": -10,
      "z": 1,
      "name": "Rock_Ice"
    },
    {
      "x": -6,
      "y": -9,
      "z": 1,
      "name": "Rock_Ice"
    },
    {
      "x": -6,
      "y": -6,
      "z": 1,
      "name": "Rock_Ice"
    },
    {
      "x": -6,
      "y": -5,
      "z": 1,
      "name": "Rock_Ice"
    },
    {
      "x": -6,
      "y": -20,
      "z": 2,
      "name": "Rock_Ice"
    },
    {
      "x": -6,
      "y": -19,
      "z": 2,
      "name": "Rock_Ice"
    },
    {
      "x": -6,
      "y": -18,
      "z": 2,
      "name": "Rock_Ice"
    },
    {
      "x": -6,
      "y": -17,
      "z": 2,
      "name": "Rock_Ice"
    },
    {
      "x": -6,
      "y": -16,
      "z": 2,
      "name": "Rock_Ice"
    },
    {
      "x": -6,
      "y": -15,
      "z": 2,
      "name": "Rock_Ice"
    },
    {
      "x": -6,
      "y": -14,
      "z": 2,
      "name": "Rock_Ice"
    },
    {
      "x": -6,
      "y": -13,
      "z": 2,
      "name": "Rock_Ice"
    },
    {
      "x": -6,
      "y": -12,
      "z": 2,
      "name": "Rock_Ice"
    },
    {
      "x": -6,
      "y": -11,
      "z": 2,
      "name": "Rock_Ice"
    },
    {
      "x": -6,
      "y": -10,
      "z": 2,
      "name": "Rock_Ice"
    },
    {
      "x": -6,
      "y": -9,
      "z": 2,
      "name": "Rock_Ice"
    },
    {
      "x": -6,
      "y": -8,
      "z": 2,
      "name": "Rock_Ice"
    },
    {
      "x": -6,
      "y": -7,
      "z": 2,
      "name": "Rock_Ice"
    },
    {
      "x": -6,
      "y": -6,
      "z": 2,
      "name": "Rock_Ice"
    },
    {
      "x": -6,
      "y": -5,
      "z": 2,
      "name": "Rock_Ice"
    },
    {
      "x": -6,
      "y": -4,
      "z": 2,
      "name": "Rock_Ice"
    },
    {
      "x": -6,
      "y": -21,
      "z": 3,
      "name": "Rock_Ice"
    },
    {
      "x": -6,
      "y": -20,
      "z": 3,
      "name": "Rock_Ice"
    },
    {
      "x": -6,
      "y": -19,
      "z": 3,
      "name": "Rock_Ice"
    },
    {
      "x": -6,
      "y": -18,
      "z": 3,
      "name": "Rock_Ice"
    },
    {
      "x": -6,
      "y": -17,
      "z": 3,
      "name": "Rock_Ice"
    },
    {
      "x": -6,
      "y": -16,
      "z": 3,
      "name": "Rock_Ice"
    },
    {
      "x": -6,
      "y": -15,
      "z": 3,
      "name": "Rock_Ice"
    },
    {
      "x": -6,
      "y": -14,
      "z": 3,
      "name": "Rock_Ice"
    },
    {
      "x": -6,
      "y": -13,
      "z": 3,
      "name": "Rock_Ice"
    },
    {
      "x": -6,
      "y": -12,
      "z": 3,
      "name": "Rock_Ice"
    },
    {
      "x": -6,
      "y": -11,
      "z": 3,
      "name": "Rock_Ice"
    },
    {
      "x": -6,
      "y": -10,
      "z": 3,
      "name": "Rock_Ice"
    },
    {
      "x": -6,
      "y": -9,
      "z": 3,
      "name": "Rock_Ice"
    },
    {
      "x": -6,
      "y": -8,
      "z": 3,
      "name": "Rock_Ice"
    },
    {
      "x": -6,
      "y": -7,
      "z": 3,
      "name": "Rock_Ice"
    },
    {
      "x": -6,
      "y": -6,
      "z": 3,
      "name": "Rock_Ice"
    },
    {
      "x": -6,
      "y": -24,
      "z": 4,
      "name": "Rock_Ice"
    },
    {
      "x": -6,
      "y": -23,
      "z": 4,
      "name": "Rock_Ice"
    },
    {
      "x": -6,
      "y": -22,
      "z": 4,
      "name": "Rock_Ice"
    },
    {
      "x": -6,
      "y": -21,
      "z": 4,
      "name": "Rock_Ice"
    },
    {
      "x": -6,
      "y": -20,
      "z": 4,
      "name": "Rock_Ice"
    },
    {
      "x": -6,
      "y": -19,
      "z": 4,
      "name": "Rock_Ice"
    },
    {
      "x": -6,
      "y": -18,
      "z": 4,
      "name": "Rock_Ice"
    },
    {
      "x": -6,
      "y": -17,
      "z": 4,
      "name": "Rock_Ice"
    },
    {
      "x": -6,
      "y": -16,
      "z": 4,
      "name": "Rock_Ice"
    },
    {
      "x": -6,
      "y": -15,
      "z": 4,
      "name": "Rock_Ice"
    },
    {
      "x": -6,
      "y": -14,
      "z": 4,
      "name": "Rock_Ice"
    },
    {
      "x": -6,
      "y": -13,
      "z": 4,
      "name": "Rock_Ice"
    },
    {
      "x": -6,
      "y": -12,
      "z": 4,
      "name": "Rock_Ice"
    },
    {
      "x": -6,
      "y": -11,
      "z": 4,
      "name": "Rock_Ice"
    },
    {
      "x": -6,
      "y": -10,
      "z": 4,
      "name": "Rock_Ice"
    },
    {
      "x": -6,
      "y": -9,
      "z": 4,
      "name": "Rock_Ice"
    },
    {
      "x": -6,
      "y": -8,
      "z": 4,
      "name": "Rock_Ice"
    },
    {
      "x": -6,
      "y": -7,
      "z": 4,
      "name": "Rock_Ice"
    },
    {
      "x": -6,
      "y": -6,
      "z": 4,
      "name": "Rock_Ice"
    },
    {
      "x": -6,
      "y": -5,
      "z": 4,
      "name": "Rock_Ice"
    },
    {
      "x": -6,
      "y": -26,
      "z": 5,
      "name": "Rock_Ice"
    },
    {
      "x": -6,
      "y": -25,
      "z": 5,
      "name": "Rock_Ice"
    },
    {
      "x": -6,
      "y": -24,
      "z": 5,
      "name": "Rock_Ice"
    },
    {
      "x": -6,
      "y": -23,
      "z": 5,
      "name": "Rock_Ice"
    },
    {
      "x": -6,
      "y": -22,
      "z": 5,
      "name": "Rock_Ice"
    },
    {
      "x": -6,
      "y": -21,
      "z": 5,
      "name": "Rock_Ice"
    },
    {
      "x": -6,
      "y": -20,
      "z": 5,
      "name": "Rock_Ice"
    },
    {
      "x": -6,
      "y": -19,
      "z": 5,
      "name": "Rock_Ice"
    },
    {
      "x": -6,
      "y": -18,
      "z": 5,
      "name": "Rock_Ice"
    },
    {
      "x": -6,
      "y": -17,
      "z": 5,
      "name": "Rock_Ice"
    },
    {
      "x": -6,
      "y": -16,
      "z": 5,
      "name": "Rock_Ice"
    },
    {
      "x": -6,
      "y": -15,
      "z": 5,
      "name": "Rock_Ice"
    },
    {
      "x": -6,
      "y": -14,
      "z": 5,
      "name": "Rock_Ice"
    },
    {
      "x": -6,
      "y": -13,
      "z": 5,
      "name": "Rock_Ice"
    },
    {
      "x": -6,
      "y": -12,
      "z": 5,
      "name": "Rock_Ice"
    },
    {
      "x": -6,
      "y": -11,
      "z": 5,
      "name": "Rock_Ice"
    },
    {
      "x": -6,
      "y": -10,
      "z": 5,
      "name": "Rock_Ice"
    },
    {
      "x": -6,
      "y": -9,
      "z": 5,
      "name": "Rock_Ice"
    },
    {
      "x": -6,
      "y": -8,
      "z": 5,
      "name": "Rock_Ice"
    },
    {
      "x": -6,
      "y": -27,
      "z": 6,
      "name": "Rock_Ice"
    },
    {
      "x": -6,
      "y": -26,
      "z": 6,
      "name": "Rock_Ice"
    },
    {
      "x": -6,
      "y": -25,
      "z": 6,
      "name": "Rock_Ice"
    },
    {
      "x": -6,
      "y": -24,
      "z": 6,
      "name": "Rock_Ice"
    },
    {
      "x": -6,
      "y": -23,
      "z": 6,
      "name": "Rock_Ice"
    },
    {
      "x": -6,
      "y": -22,
      "z": 6,
      "name": "Rock_Ice"
    },
    {
      "x": -6,
      "y": -21,
      "z": 6,
      "name": "Rock_Ice"
    },
    {
      "x": -6,
      "y": -20,
      "z": 6,
      "name": "Rock_Ice"
    },
    {
      "x": -6,
      "y": -19,
      "z": 6,
      "name": "Rock_Ice"
    },
    {
      "x": -6,
      "y": -18,
      "z": 6,
      "name": "Rock_Ice"
    },
    {
      "x": -6,
      "y": -17,
      "z": 6,
      "name": "Rock_Ice"
    },
    {
      "x": -6,
      "y": -16,
      "z": 6,
      "name": "Rock_Ice"
    },
    {
      "x": -6,
      "y": -15,
      "z": 6,
      "name": "Rock_Ice"
    },
    {
      "x": -6,
      "y": -14,
      "z": 6,
      "name": "Rock_Ice"
    },
    {
      "x": -6,
      "y": -13,
      "z": 6,
      "name": "Rock_Ice"
    },
    {
      "x": -6,
      "y": -12,
      "z": 6,
      "name": "Rock_Ice"
    },
    {
      "x": -6,
      "y": -11,
      "z": 6,
      "name": "Rock_Ice"
    },
    {
      "x": -6,
      "y": -10,
      "z": 6,
      "name": "Rock_Ice"
    },
    {
      "x": -6,
      "y": -9,
      "z": 6,
      "name": "Rock_Ice"
    },
    {
      "x": -6,
      "y": -8,
      "z": 6,
      "name": "Rock_Ice"
    },
    {
      "x": -6,
      "y": -7,
      "z": 6,
      "name": "Rock_Ice"
    },
    {
      "x": -6,
      "y": -29,
      "z": 7,
      "name": "Rock_Ice"
    },
    {
      "x": -6,
      "y": -28,
      "z": 7,
      "name": "Rock_Ice"
    },
    {
      "x": -6,
      "y": -27,
      "z": 7,
      "name": "Rock_Ice"
    },
    {
      "x": -6,
      "y": -26,
      "z": 7,
      "name": "Rock_Ice"
    },
    {
      "x": -6,
      "y": -25,
      "z": 7,
      "name": "Rock_Ice"
    },
    {
      "x": -6,
      "y": -24,
      "z": 7,
      "name": "Rock_Ice"
    },
    {
      "x": -6,
      "y": -23,
      "z": 7,
      "name": "Rock_Ice"
    },
    {
      "x": -6,
      "y": -22,
      "z": 7,
      "name": "Rock_Ice"
    },
    {
      "x": -6,
      "y": -21,
      "z": 7,
      "name": "Rock_Ice"
    },
    {
      "x": -6,
      "y": -20,
      "z": 7,
      "name": "Rock_Ice"
    },
    {
      "x": -6,
      "y": -19,
      "z": 7,
      "name": "Rock_Ice"
    },
    {
      "x": -6,
      "y": -18,
      "z": 7,
      "name": "Rock_Ice"
    },
    {
      "x": -6,
      "y": -17,
      "z": 7,
      "name": "Rock_Ice"
    },
    {
      "x": -6,
      "y": -16,
      "z": 7,
      "name": "Rock_Ice"
    },
    {
      "x": -6,
      "y": -15,
      "z": 7,
      "name": "Rock_Ice"
    },
    {
      "x": -6,
      "y": -14,
      "z": 7,
      "name": "Rock_Ice"
    },
    {
      "x": -6,
      "y": -13,
      "z": 7,
      "name": "Rock_Ice"
    },
    {
      "x": -6,
      "y": -12,
      "z": 7,
      "name": "Rock_Ice"
    },
    {
      "x": -6,
      "y": -11,
      "z": 7,
      "name": "Rock_Ice"
    },
    {
      "x": -6,
      "y": -10,
      "z": 7,
      "name": "Rock_Ice"
    },
    {
      "x": -6,
      "y": -9,
      "z": 7,
      "name": "Rock_Ice"
    },
    {
      "x": -6,
      "y": -8,
      "z": 7,
      "name": "Rock_Ice"
    },
    {
      "x": -6,
      "y": -29,
      "z": 8,
      "name": "Rock_Ice"
    },
    {
      "x": -6,
      "y": -28,
      "z": 8,
      "name": "Rock_Ice"
    },
    {
      "x": -6,
      "y": -27,
      "z": 8,
      "name": "Rock_Ice"
    },
    {
      "x": -6,
      "y": -26,
      "z": 8,
      "name": "Rock_Ice"
    },
    {
      "x": -6,
      "y": -25,
      "z": 8,
      "name": "Rock_Ice"
    },
    {
      "x": -6,
      "y": -24,
      "z": 8,
      "name": "Rock_Ice"
    },
    {
      "x": -6,
      "y": -23,
      "z": 8,
      "name": "Rock_Ice"
    },
    {
      "x": -6,
      "y": -22,
      "z": 8,
      "name": "Rock_Ice"
    },
    {
      "x": -6,
      "y": -21,
      "z": 8,
      "name": "Rock_Ice"
    },
    {
      "x": -6,
      "y": -20,
      "z": 8,
      "name": "Rock_Ice"
    },
    {
      "x": -6,
      "y": -19,
      "z": 8,
      "name": "Rock_Ice"
    },
    {
      "x": -6,
      "y": -18,
      "z": 8,
      "name": "Rock_Ice"
    },
    {
      "x": -6,
      "y": -17,
      "z": 8,
      "name": "Rock_Ice"
    },
    {
      "x": -6,
      "y": -16,
      "z": 8,
      "name": "Rock_Ice"
    },
    {
      "x": -6,
      "y": -15,
      "z": 8,
      "name": "Rock_Ice"
    },
    {
      "x": -6,
      "y": -14,
      "z": 8,
      "name": "Rock_Ice"
    },
    {
      "x": -6,
      "y": -13,
      "z": 8,
      "name": "Rock_Ice"
    },
    {
      "x": -6,
      "y": -12,
      "z": 8,
      "name": "Rock_Ice"
    },
    {
      "x": -6,
      "y": -11,
      "z": 8,
      "name": "Rock_Ice"
    },
    {
      "x": -6,
      "y": -10,
      "z": 8,
      "name": "Rock_Ice"
    },
    {
      "x": -6,
      "y": -9,
      "z": 8,
      "name": "Rock_Ice"
    },
    {
      "x": -6,
      "y": -8,
      "z": 8,
      "name": "Rock_Ice"
    },
    {
      "x": -6,
      "y": -32,
      "z": 9,
      "name": "Rock_Ice"
    },
    {
      "x": -6,
      "y": -31,
      "z": 9,
      "name": "Rock_Ice"
    },
    {
      "x": -6,
      "y": -30,
      "z": 9,
      "name": "Rock_Ice"
    },
    {
      "x": -6,
      "y": -29,
      "z": 9,
      "name": "Rock_Ice"
    },
    {
      "x": -6,
      "y": -28,
      "z": 9,
      "name": "Rock_Ice"
    },
    {
      "x": -6,
      "y": -27,
      "z": 9,
      "name": "Rock_Ice"
    },
    {
      "x": -6,
      "y": -26,
      "z": 9,
      "name": "Rock_Ice"
    },
    {
      "x": -6,
      "y": -25,
      "z": 9,
      "name": "Rock_Ice"
    },
    {
      "x": -6,
      "y": -24,
      "z": 9,
      "name": "Rock_Ice"
    },
    {
      "x": -6,
      "y": -23,
      "z": 9,
      "name": "Rock_Ice"
    },
    {
      "x": -6,
      "y": -22,
      "z": 9,
      "name": "Rock_Ice"
    },
    {
      "x": -6,
      "y": -21,
      "z": 9,
      "name": "Rock_Ice"
    },
    {
      "x": -6,
      "y": -20,
      "z": 9,
      "name": "Rock_Ice"
    },
    {
      "x": -6,
      "y": -19,
      "z": 9,
      "name": "Rock_Ice"
    },
    {
      "x": -6,
      "y": -18,
      "z": 9,
      "name": "Rock_Ice"
    },
    {
      "x": -6,
      "y": -17,
      "z": 9,
      "name": "Rock_Ice"
    },
    {
      "x": -6,
      "y": -16,
