{
  "version": 8,
  "blockIdVersion": 11,
  "anchorX": 0,
  "anchorY": 0,
  "anchorZ": 0,
  "blocks": [
    {
      "x": -3,
      "y": -4,
      "z": -3,
      "name": "Rock_Ice_Permafrost",
      "rotation": 2
    },
    {
      "x": -3,
      "y": -3,
      "z": -3,
      "name": "Rock_Ice_Permafrost",
      "rotation": 2
    },
    {
      "x": -3,
      "y": -2,
      "z": -3,
      "name": "Rock_Ice_Permafrost",
      "rotation": 2
    },
    {
      "x": -3,
      "y": -1,
      "z": -3,
      "name": "Rock_Ice_Permafrost",
      "rotation": 2
    },
    {
      "x": -3,
      "y": 0,
      "z": -3,
      "name": "Rock_Ice_Permafrost",
      "rotation": 2
    },
    {
      "x": -3,
      "y": 1,
      "z": -3,
      "name": "Rock_Ice_Permafrost",
      "rotation": 2
    },
    {
      "x": -3,
      "y": 2,
      "z": -3,
      "name": "Rock_Ice_Permafrost",
      "rotation": 2
    },
    {
      "x": -3,
      "y": 3,
      "z": -3,
      "name": "Rock_Ice_Permafrost",
      "rotation": 2
    },
    {
      "x": -3,
      "y": 4,
      "z": -3,
      "name": "Rock_Ice_Permafrost",
      "rotation": 2
    },
    {
      "x": -3,
      "y": -4,
      "z": -2,
      "name": "Rock_Ice_Permafrost",
      "rotation": 2
    },
    {
      "x": -3,
      "y": -3,
      "z": -2,
      "name": "Rock_Ice_Permafrost",
      "rotation": 2
    },
    {
      "x": -3,
      "y": -2,
      "z": -2,
      "name": "Rock_Ice_Permafrost",
      "rotation": 2
    },
    {
      "x": -3,
      "y": -1,
      "z": -2,
      "name": "Rock_Ice_Permafrost",
      "rotation": 2
    },
    {
      "x": -3,
      "y": 0,
      "z": -2,
      "name": "Rock_Ice_Permafrost",
      "rotation": 2
    },
    {
      "x": -3,
      "y": 1,
      "z": -2,
      "name": "Rock_Ice_Permafrost",
      "rotation": 2
    },
    {
      "x": -3,
      "y": 2,
      "z": -2,
      "name": "Rock_Ice_Permafrost",
      "rotation": 2
    },
    {
      "x": -3,
      "y": 3,
      "z": -2,
      "name": "Rock_Ice_Permafrost",
      "rotation": 2
    },
    {
      "x": -3,
      "y": 4,
      "z": -2,
      "name": "Rock_Ice_Permafrost",
      "rotation": 2
    },
    {
      "x": -3,
      "y": -10,
      "z": -1,
      "name": "Rock_Ice_Permafrost",
      "rotation": 2
    },
    {
      "x": -3,
      "y": -9,
      "z": -1,
      "name": "Rock_Ice_Permafrost",
      "rotation": 2
    },
    {
      "x": -3,
      "y": -8,
      "z": -1,
      "name": "Rock_Ice_Permafrost",
      "rotation": 2
    },
    {
      "x": -3,
      "y": -7,
      "z": -1,
      "name": "Rock_Ice_Permafrost",
      "rotation": 2
    },
    {
      "x": -3,
      "y": -6,
      "z": -1,
      "name": "Rock_Ice_Permafrost",
      "rotation": 2
    },
    {
      "x": -3,
      "y": -5,
      "z": -1,
      "name": "Rock_Ice_Permafrost",
      "rotation": 2
    },
    {
      "x": -3,
      "y": -4,
      "z": -1,
      "name": "Rock_Ice_Permafrost",
      "rotation": 2
    },
    {
      "x": -3,
      "y": -3,
      "z": -1,
      "name": "Rock_Ice_Permafrost",
      "rotation": 2
    },
    {
      "x": -3,
      "y": -2,
      "z": -1,
      "name": "Rock_Ice_Permafrost",
      "rotation": 2
    },
    {
      "x": -3,
      "y": -1,
      "z": -1,
      "name": "Rock_Ice_Permafrost",
      "rotation": 2
    },
    {
      "x": -3,
      "y": 0,
      "z": -1,
      "name": "Rock_Ice_Permafrost",
      "rotation": 2
    },
    {
      "x": -3,
      "y": 1,
      "z": -1,
      "name": "Rock_Ice_Permafrost",
      "rotation": 2
    },
    {
      "x": -3,
      "y": 2,
      "z": -1,
      "name": "Rock_Ice_Permafrost",
      "rotation": 2
    },
    {
      "x": -3,
      "y": 3,
      "z": -1,
      "name": "Rock_Ice_Permafrost",
      "rotation": 2
    },
    {
      "x": -3,
      "y": 4,
      "z": -1,
      "name": "Rock_Ice_Permafrost",
      "rotation": 2
    },
    {
      "x": -3,
      "y": 5,
      "z": -1,
      "name": "Rock_Ice_Permafrost",
      "rotation": 2
    },
    {
      "x": -3,
      "y": -8,
      "z": 0,
      "name": "Rock_Ice_Permafrost",
      "rotation": 2
    },
    {
      "x": -3,
      "y": -7,
      "z": 0,
      "name": "Rock_Ice_Permafrost",
      "rotation": 2
    },
    {
      "x": -3,
      "y": -6,
      "z": 0,
      "name": "Rock_Ice_Permafrost",
      "rotation": 2
    },
    {
      "x": -3,
      "y": -5,
      "z": 0,
      "name": "Rock_Ice_Permafrost",
      "rotation": 2
    },
    {
      "x": -3,
      "y": 0,
      "z": 0,
      "name": "Rock_Ice_Permafrost",
      "rotation": 2
    },
    {
      "x": -3,
      "y": 1,
      "z": 0,
      "name": "Rock_Ice_Permafrost",
      "rotation": 2
    },
    {
      "x": -3,
      "y": 2,
      "z": 0,
      "name": "Rock_Ice_Permafrost",
      "rotation": 2
    },
    {
      "x": -3,
      "y": 3,
      "z": 0,
      "name": "Rock_Ice_Permafrost",
      "rotation": 2
    },
    {
      "x": -3,
      "y": 4,
      "z": 0,
      "name": "Rock_Ice_Permafrost",
      "rotation": 2
    },
    {
      "x": -2,
      "y": -4,
      "z": -3,
      "name": "Rock_Ice_Permafrost",
      "rotation": 2
    },
    {
      "x": -2,
      "y": -3,
      "z": -3,
      "name": "Rock_Ice_Permafrost",
      "rotation": 2
    },
    {
      "x": -2,
      "y": -2,
      "z": -3,
      "name": "Rock_Ice_Permafrost",
      "rotation": 2
    },
    {
      "x": -2,
      "y": -1,
      "z": -3,
      "name": "Rock_Ice_Permafrost",
      "rotation": 2
    },
    {
      "x": -2,
      "y": 0,
      "z": -3,
      "name": "Rock_Ice_Permafrost",
      "rotation": 2
    },
    {
      "x": -2,
      "y": 1,
      "z": -3,
      "name": "Rock_Ice_Permafrost",
      "rotation": 2
    },
    {
      "x": -2,
      "y": 2,
      "z": -3,
      "name": "Rock_Ice_Permafrost",
      "rotation": 2
    },
    {
      "x": -2,
      "y": 3,
      "z": -3,
      "name": "Rock_Ice_Permafrost",
      "rotation": 2
    },
    {
      "x": -2,
      "y": 4,
      "z": -3,
      "name": "Rock_Ice_Permafrost",
      "rotation": 2
    },
    {
      "x": -2,
      "y": -4,
      "z": -2,
      "name": "Rock_Ice_Permafrost",
      "rotation": 2
    },
    {
      "x": -2,
      "y": -3,
      "z": -2,
      "name": "Rock_Ice_Permafrost",
      "rotation": 2
    },
    {
      "x": -2,
      "y": -2,
      "z": -2,
      "name": "Rock_Ice_Permafrost",
      "rotation": 2
    },
    {
      "x": -2,
      "y": -1,
      "z": -2,
      "name": "Rock_Ice_Permafrost",
      "rotation": 2
    },
    {
      "x": -2,
      "y": 0,
      "z": -2,
      "name": "Rock_Ice_Permafrost",
      "rotation": 2
    },
    {
      "x": -2,
      "y": 1,
      "z": -2,
      "name": "Rock_Ice_Permafrost",
      "rotation": 2
    },
    {
      "x": -2,
      "y": 2,
      "z": -2,
      "name": "Rock_Ice_Permafrost",
      "rotation": 2
    },
    {
      "x": -2,
      "y": 3,
      "z": -2,
      "name": "Rock_Ice_Permafrost",
      "rotation": 2
    },
    {
      "x": -2,
      "y": 4,
      "z": -2,
      "name": "Rock_Ice_Permafrost",
      "rotation": 2
    },
    {
      "x": -2,
      "y": 5,
      "z": -2,
      "name": "Rock_Ice_Permafrost",
      "rotation": 2
    },
    {
      "x": -2,
      "y": -10,
      "z": -1,
      "name": "Rock_Ice_Permafrost",
      "rotation": 2
    },
    {
      "x": -2,
      "y": -9,
      "z": -1,
      "name": "Rock_Ice_Permafrost",
      "rotation": 2
    },
    {
      "x": -2,
      "y": -8,
      "z": -1,
      "name": "Rock_Ice_Permafrost",
      "rotation": 2
    },
    {
      "x": -2,
      "y": -7,
      "z": -1,
      "name": "Rock_Ice_Permafrost",
      "rotation": 2
    },
    {
      "x": -2,
      "y": -6,
      "z": -1,
      "name": "Rock_Ice_Permafrost",
      "rotation": 2
    },
    {
      "x": -2,
      "y": -5,
      "z": -1,
      "name": "Rock_Ice_Permafrost",
      "rotation": 2
    },
    {
      "x": -2,
      "y": -4,
      "z": -1,
      "name": "Rock_Ice_Permafrost",
      "rotation": 2
    },
    {
      "x": -2,
      "y": -3,
      "z": -1,
      "name": "Rock_Ice_Permafrost",
      "rotation": 2
    },
    {
      "x": -2,
      "y": -2,
      "z": -1,
      "name": "Rock_Ice_Permafrost",
      "rotation": 2
    },
    {
      "x": -2,
      "y": -1,
      "z": -1,
      "name": "Rock_Ice_Permafrost",
      "rotation": 2
    },
    {
      "x": -2,
      "y": 0,
      "z": -1,
      "name": "Rock_Ice_Permafrost",
      "rotation": 2
    },
    {
      "x": -2,
      "y": 1,
      "z": -1,
      "name": "Rock_Ice_Permafrost",
      "rotation": 2
    },
    {
      "x": -2,
      "y": 2,
      "z": -1,
      "name": "Rock_Ice_Permafrost",
      "rotation": 2
    },
    {
      "x": -2,
      "y": 3,
      "z": -1,
      "name": "Rock_Ice_Permafrost",
      "rotation": 2
    },
    {
      "x": -2,
      "y": 4,
      "z": -1,
      "name": "Rock_Ice_Permafrost",
      "rotation": 2
    },
    {
      "x": -2,
      "y": 5,
      "z": -1,
      "name": "Rock_Ice_Permafrost",
      "rotation": 2
    },
    {
      "x": -2,
      "y": -8,
      "z": 0,
      "name": "Rock_Ice_Permafrost",
      "rotation": 2
    },
    {
      "x": -2,
      "y": -7,
      "z": 0,
      "name": "Rock_Ice_Permafrost",
      "rotation": 2
    },
    {
      "x": -2,
      "y": -6,
      "z": 0,
      "name": "Rock_Ice_Permafrost",
      "rotation": 2
    },
    {
      "x": -2,
      "y": -5,
      "z": 0,
      "name": "Rock_Ice_Permafrost",
      "rotation": 2
    },
    {
      "x": -2,
      "y": -4,
      "z": 0,
      "name": "Rock_Ice_Permafrost",
      "rotation": 2
    },
    {
      "x": -2,
      "y": -3,
      "z": 0,
      "name": "Rock_Ice_Permafrost",
      "rotation": 2
    },
    {
      "x": -2,
      "y": -2,
      "z": 0,
      "name": "Rock_Ice_Permafrost",
      "rotation": 2
    },
    {
      "x": -2,
      "y": -1,
      "z": 0,
      "name": "Rock_Ice_Permafrost",
      "rotation": 2
    },
    {
      "x": -2,
      "y": 0,
      "z": 0,
      "name": "Rock_Ice_Permafrost",
      "rotation": 2
    },
    {
      "x": -2,
      "y": 1,
      "z": 0,
      "name": "Rock_Ice_Permafrost",
      "rotation": 2
    },
    {
      "x": -2,
      "y": 2,
      "z": 0,
      "name": "Rock_Ice_Permafrost",
      "rotation": 2
    },
    {
      "x": -2,
      "y": 3,
      "z": 0,
      "name": "Rock_Ice_Permafrost",
      "rotation": 2
    },
    {
      "x": -2,
      "y": 4,
      "z": 0,
      "name": "Rock_Ice_Permafrost",
      "rotation": 2
    },
    {
      "x": -2,
      "y": 5,
      "z": 0,
      "name": "Rock_Ice_Permafrost",
      "rotation": 2
    },
    {
      "x": -2,
      "y": 1,
      "z": 1,
      "name": "Rock_Ice_Permafrost",
      "rotation": 2
    },
    {
      "x": -2,
      "y": 2,
      "z": 1,
      "name": "Rock_Ice_Permafrost",
      "rotation": 2
    },
    {
      "x": -2,
      "y": 3,
      "z": 1,
      "name": "Rock_Ice_Permafrost",
      "rotation": 2
    },
    {
      "x": -2,
      "y": 4,
      "z": 1,
      "name": "Rock_Ice_Permafrost",
      "rotation": 2
    },
    {
      "x": -1,
      "y": -4,
      "z": -3,
      "name": "Rock_Ice_Permafrost",
      "rotation": 2
    },
    {
      "x": -1,
      "y": 0,
      "z": -3,
      "name": "Rock_Ice_Permafrost",
      "rotation": 2
    },
    {
      "x": -1,
      "y": 1,
      "z": -3,
      "name": "Rock_Ice_Permafrost",
      "rotation": 2
    },
    {
      "x": -1,
      "y": 2,
      "z": -3,
      "name": "Rock_Ice_Permafrost",
      "rotation": 2
    },
    {
      "x": -1,
      "y": 3,
      "z": -3,
      "name": "Rock_Ice_Permafrost",
      "rotation": 2
    },
    {
      "x": -1,
      "y": 4,
      "z": -3,
      "name": "Rock_Ice_Permafrost",
      "rotation": 2
    },
    {
      "x": -1,
      "y": -4,
      "z": -2,
      "name": "Rock_Ice_Permafrost",
      "rotation": 2
    },
    {
      "x": -1,
      "y": -3,
      "z": -2,
      "name": "Rock_Ice_Permafrost",
      "rotation": 2
    },
    {
      "x": -1,
      "y": -2,
      "z": -2,
      "name": "Rock_Ice_Permafrost",
      "rotation": 2
    },
    {
      "x": -1,
      "y": -1,
      "z": -2,
      "name": "Rock_Ice_Permafrost",
      "rotation": 2
    },
    {
      "x": -1,
      "y": 0,
      "z": -2,
      "name": "Rock_Ice_Permafrost",
      "rotation": 2
    },
    {
      "x": -1,
      "y": 1,
      "z": -2,
      "name": "Rock_Ice_Permafrost",
      "rotation": 2
    },
    {
      "x": -1,
      "y": 2,
      "z": -2,
      "name": "Rock_Ice_Permafrost",
      "rotation": 2
    },
    {
      "x": -1,
      "y": 3,
      "z": -2,
      "name": "Rock_Ice_Permafrost",
      "rotation": 2
    },
    {
      "x": -1,
      "y": 4,
      "z": -2,
      "name": "Rock_Ice_Permafrost",
      "rotation": 2
    },
    {
      "x": -1,
      "y": -8,
      "z": -1,
      "name": "Rock_Ice_Permafrost",
      "rotation": 2
    },
    {
      "x": -1,
      "y": -7,
      "z": -1,
      "name": "Rock_Ice_Permafrost",
      "rotation": 2
    },
    {
      "x": -1,
      "y": -6,
      "z": -1,
      "name": "Rock_Ice_Permafrost",
      "rotation": 2
    },
    {
      "x": -1,
      "y": -5,
      "z": -1,
      "name": "Rock_Ice_Permafrost",
      "rotation": 2
    },
    {
      "x": -1,
      "y": -4,
      "z": -1,
      "name": "Rock_Ice_Permafrost",
      "rotation": 2
    },
    {
      "x": -1,
      "y": -3,
      "z": -1,
      "name": "Rock_Ice_Permafrost",
      "rotation": 2
    },
    {
      "x": -1,
      "y": -2,
      "z": -1,
      "name": "Rock_Ice_Permafrost",
      "rotation": 2
    },
    {
      "x": -1,
      "y": -1,
      "z": -1,
      "name": "Rock_Ice_Permafrost",
      "rotation": 2
    },
    {
      "x": -1,
      "y": 0,
      "z": -1,
      "name": "Rock_Ice_Permafrost",
      "rotation": 2
    },
    {
      "x": -1,
      "y": 1,
      "z": -1,
      "name": "Rock_Ice_Permafrost",
      "rotation": 2
    },
    {
      "x": -1,
      "y": 2,
      "z": -1,
      "name": "Rock_Ice_Permafrost",
      "rotation": 2
    },
    {
      "x": -1,
      "y": 3,
      "z": -1,
      "name": "Rock_Ice_Permafrost",
      "rotation": 2
    },
    {
      "x": -1,
      "y": 4,
      "z": -1,
      "name": "Rock_Ice_Permafrost",
      "rotation": 2
    },
    {
      "x": -1,
      "y": 5,
      "z": -1,
      "name": "Rock_Ice_Permafrost",
      "rotation": 2
    },
    {
      "x": -1,
      "y": -6,
      "z": 0,
      "name": "Rock_Ice_Permafrost",
      "rotation": 2
    },
    {
      "x": -1,
      "y": -5,
      "z": 0,
      "name": "Rock_Ice_Permafrost",
      "rotation": 2
    },
    {
      "x": -1,
      "y": -4,
      "z": 0,
      "name": "Rock_Ice_Permafrost",
      "rotation": 2
    },
    {
      "x": -1,
      "y": -3,
      "z": 0,
      "name": "Rock_Ice_Permafrost",
      "rotation": 2
    },
    {
      "x": -1,
      "y": -2,
      "z": 0,
      "name": "Rock_Ice_Permafrost",
      "rotation": 2
    },
    {
      "x": -1,
      "y": -1,
      "z": 0,
      "name": "Rock_Ice_Permafrost",
      "rotation": 2
    },
    {
      "x": -1,
      "y": 0,
      "z": 0,
      "name": "Rock_Ice_Permafrost",
      "rotation": 2
    },
    {
      "x": -1,
      "y": 1,
      "z": 0,
      "name": "Rock_Ice_Permafrost",
      "rotation": 2
    },
    {
      "x": -1,
      "y": 2,
      "z": 0,
      "name": "Rock_Ice_Permafrost",
      "rotation": 2
    },
    {
      "x": -1,
      "y": 3,
      "z": 0,
      "name": "Rock_Ice_Permafrost",
      "rotation": 2
    },
    {
      "x": -1,
      "y": 4,
      "z": 0,
      "name": "Rock_Ice_Permafrost",
      "rotation": 2
    },
    {
      "x": -1,
      "y": 5,
      "z": 0,
      "name": "Rock_Ice_Permafrost",
      "rotation": 2
    },
    {
      "x": -1,
      "y": -4,
      "z": 1,
      "name": "Rock_Ice_Permafrost",
      "rotation": 2
    },
    {
      "x": -1,
      "y": -3,
      "z": 1,
      "name": "Rock_Ice_Permafrost",
      "rotation": 2
    },
    {
      "x": -1,
      "y": -2,
      "z": 1,
      "name": "Rock_Ice_Permafrost",
      "rotation": 2
    },
    {
      "x": -1,
      "y": -1,
      "z": 1,
      "name": "Rock_Ice_Permafrost",
      "rotation": 2
    },
    {
      "x": -1,
      "y": 0,
      "z": 1,
      "name": "Rock_Ice_Permafrost",
      "rotation": 2
    },
    {
      "x": -1,
      "y": 1,
      "z": 1,
      "name": "Rock_Ice_Permafrost",
      "rotation": 2
    },
    {
      "x": -1,
      "y": 2,
      "z": 1,
      "name": "Rock_Ice_Permafrost",
      "rotation": 2
    },
    {
      "x": -1,
      "y": 3,
      "z": 1,
      "name": "Rock_Ice_Permafrost",
      "rotation": 2
    },
    {
      "x": -1,
      "y": 4,
      "z": 1,
      "name": "Rock_Ice_Permafrost",
      "rotation": 2
    },
    {
      "x": -1,
      "y": 5,
      "z": 1,
      "name": "Rock_Ice_Permafrost",
      "rotation": 2
    },
    {
      "x": -1,
      "y": 1,
      "z": 2,
      "name": "Rock_Ice_Permafrost",
      "rotation": 2
    },
    {
      "x": -1,
      "y": 2,
      "z": 2,
      "name": "Rock_Ice_Permafrost",
      "rotation": 2
    },
    {
      "x": -1,
      "y": 3,
      "z": 2,
      "name": "Rock_Ice_Permafrost",
      "rotation": 2
    },
    {
      "x": -1,
      "y": 4,
      "z": 2,
      "name": "Rock_Ice_Permafrost",
      "rotation": 2
    },
    {
      "x": -1,
      "y": 5,
      "z": 2,
      "name": "Rock_Ice_Permafrost",
      "rotation": 2
    },
    {
      "x": 0,
      "y": 0,
      "z": -1,
      "name": "Rock_Ice_Permafrost",
      "rotation": 2
    },
    {
      "x": 0,
      "y": 1,
      "z": -1,
      "name": "Rock_Ice_Permafrost",
      "rotation": 2
    },
    {
      "x": 0,
      "y": 2,
      "z": -1,
      "name": "Rock_Ice_Permafrost",
      "rotation": 2
    },
    {
      "x": 0,
      "y": 3,
      "z": -1,
      "name": "Rock_Ice_Permafrost",
      "rotation": 2
    },
    {
      "x": 0,
      "y": 4,
      "z": -1,
      "name": "Rock_Ice_Permafrost",
      "rotation": 2
    },
    {
      "x": 0,
      "y": -4,
      "z": 0,
      "name": "Rock_Ice_Permafrost",
      "rotation": 2
    },
    {
      "x": 0,
      "y": -3,
      "z": 0,
      "name": "Rock_Ice_Permafrost",
      "rotation": 2
    },
    {
      "x": 0,
      "y": -2,
      "z": 0,
      "name": "Rock_Ice_Permafrost",
      "rotation": 2
    },
    {
      "x": 0,
      "y": -1,
      "z": 0,
      "name": "Rock_Ice_Permafrost",
      "rotation": 2
    },
    {
      "x": 0,
      "y": 0,
      "z": 0,
      "name": "Rock_Ice_Permafrost",
      "rotation": 2
    },
    {
      "x": 0,
      "y": 1,
      "z": 0,
      "name": "Rock_Ice_Permafrost",
      "rotation": 2
    },
    {
      "x": 0,
      "y": 2,
      "z": 0,
      "name": "Rock_Ice_Permafrost",
      "rotation": 2
    },
    {
      "x": 0,
      "y": 3,
      "z": 0,
      "name": "Rock_Ice_Permafrost",
      "rotation": 2
    },
    {
      "x": 0,
      "y": 4,
      "z": 0,
      "name": "Rock_Ice_Permafrost",
      "rotation": 2
    },
    {
      "x": 0,
      "y": 5,
      "z": 0,
      "name": "Rock_Ice_Permafrost",
      "rotation": 2
    },
    {
      "x": 0,
      "y": -3,
      "z": 1,
      "name": "Rock_Ice_Permafrost",
      "rotation": 2
    },
    {
      "x": 0,
      "y": -2,
      "z": 1,
      "name": "Rock_Ice_Permafrost",
      "rotation": 2
    },
    {
      "x": 0,
      "y": -1,
      "z": 1,
      "name": "Rock_Ice_Permafrost",
      "rotation": 2
    },
    {
      "x": 0,
      "y": 0,
      "z": 1,
      "name": "Rock_Ice_Permafrost",
      "rotation": 2
    },
    {
      "x": 0,
      "y": 1,
      "z": 1,
      "name": "Rock_Ice_Permafrost",
      "rotation": 2
    },
    {
      "x": 0,
      "y": 2,
      "z": 1,
      "name": "Rock_Ice_Permafrost",
      "rotation": 2
    },
    {
      "x": 0,
      "y": 3,
      "z": 1,
      "name": "Rock_Ice_Permafrost",
      "rotation": 2
    },
    {
      "x": 0,
      "y": 4,
      "z": 1,
      "name": "Rock_Ice_Permafrost",
      "rotation": 2
    },
    {
      "x": 0,
      "y": 5,
      "z": 1,
      "name": "Rock_Ice_Permafrost",
      "rotation": 2
    },
    {
      "x": 0,
      "y": 6,
      "z": 1,
      "name": "Rock_Ice_Permafrost"
    },
    {
      "x": 0,
      "y": -2,
      "z": 2,
      "name": "Rock_Ice_Permafrost",
      "rotation": 2
    },
    {
      "x": 0,
      "y": -1,
      "z": 2,
      "name": "Rock_Ice_Permafrost",
      "rotation": 2
    },
    {
      "x": 0,
      "y": 0,
      "z": 2,
      "name": "Rock_Ice_Permafrost",
      "rotation": 2
    },
    {
      "x": 0,
      "y": 1,
      "z": 2,
      "name": "Rock_Ice_Permafrost",
      "rotation": 2
    },
    {
      "x": 0,
      "y": 2,
      "z": 2,
      "name": "Rock_Ice_Permafrost",
      "rotation": 2
    },
    {
      "x": 0,
      "y": 3,
      "z": 2,
      "name": "Rock_Ice_Permafrost",
      "rotation": 2
    },
    {
      "x": 0,
      "y": 4,
      "z": 2,
      "name": "Rock_Ice_Permafrost",
      "rotation": 2
    },
    {
      "x": 0,
      "y": 5,
      "z": 2,
      "name": "Rock_Ice_Permafrost",
      "rotation": 2
    },
    {
      "x": 0,
      "y": 6,
      "z": 2,
      "name": "Rock_Ice_Permafrost"
    },
    {
      "x": 0,
      "y": 2,
      "z": 3,
      "name": "Rock_Ice_Permafrost",
      "rotation": 2
    },
    {
      "x": 0,
      "y": 3,
      "z": 3,
      "name": "Rock_Ice_Permafrost",
      "rotation": 2
    },
    {
      "x": 0,
      "y": 4,
      "z": 3,
      "name": "Rock_Ice_Permafrost",
      "rotation": 2
    },
    {
      "x": 0,
      "y": 5,
      "z": 3,
      "name": "Rock_Ice_Permafrost",
      "rotation": 2
    },
    {
      "x": 0,
      "y": 3,
      "z": 4,
      "name": "Rock_Ice_Permafrost",
      "rotation": 2
    },
    {
      "x": 0,
      "y": 4,
      "z": 4,
      "name": "Rock_Ice_Permafrost",
      "rotation": 2
    },
    {
      "x": 0,
      "y": 5,
      "z": 4,
      "name": "Rock_Ice_Permafrost",
      "rotation": 2
    },
    {
      "x": 1,
      "y": 0,
      "z": 0,
      "name": "Rock_Ice_Permafrost",
      "rotation": 2
    },
    {
      "x": 1,
      "y": 1,
      "z": 0,
      "name": "Rock_Ice_Permafrost",
      "rotation": 2
    },
    {
      "x": 1,
      "y": 2,
      "z": 0,
      "name": "Rock_Ice_Permafrost",
      "rotation": 2
    },
    {
      "x": 1,
      "y": 3,
      "z": 0,
      "name": "Rock_Ice_Permafrost",
      "rotation": 2
    },
    {
      "x": 1,
      "y": 4,
      "z": 0,
      "name": "Rock_Ice_Permafrost",
      "rotation": 2
    },
    {
      "x": 1,
      "y": 5,
      "z": 0,
      "name": "Rock_Ice_Permafrost",
      "rotation": 2
    },
    {
      "x": 1,
      "y": -2,
      "z": 1,
      "name": "Rock_Ice_Permafrost",
      "rotation": 2
    },
    {
      "x": 1,
      "y": -1,
      "z": 1,
      "name": "Rock_Ice_Permafrost",
      "rotation": 2
    },
    {
      "x": 1,
      "y": 0,
      "z": 1,
      "name": "Rock_Ice_Permafrost",
      "rotation": 2
    },
    {
      "x": 1,
      "y": 1,
      "z": 1,
      "name": "Rock_Ice_Permafrost",
      "rotation": 2
    },
    {
      "x": 1,
      "y": 2,
      "z": 1,
      "name": "Rock_Ice_Permafrost",
      "rotation": 2
    },
    {
      "x": 1,
      "y": 3,
      "z": 1,
      "name": "Rock_Ice_Permafrost",
      "rotation": 2
    },
    {
      "x": 1,
      "y": 4,
      "z": 1,
      "name": "Rock_Ice_Permafrost",
      "rotation": 2
    },
    {
      "x": 1,
      "y": 5,
      "z": 1,
      "name": "Rock_Ice_Permafrost",
      "rotation": 2
    },
    {
      "x": 1,
      "y": 6,
      "z": 1,
      "name": "Rock_Ice_Permafrost"
    },
    {
      "x": 1,
      "y": -1,
      "z": 2,
      "name": "Rock_Ice_Permafrost",
      "rotation": 2
    },
    {
      "x": 1,
      "y": 0,
      "z": 2,
      "name": "Rock_Ice_Permafrost",
      "rotation": 2
    },
    {
      "x": 1,
      "y": 1,
      "z": 2,
      "name": "Rock_Ice_Permafrost",
      "rotation": 2
    },
    {
      "x": 1,
      "y": 2,
      "z": 2,
      "name": "Rock_Ice_Permafrost",
      "rotation": 2
    },
    {
      "x": 1,
      "y": 3,
      "z": 2,
      "name": "Rock_Ice_Permafrost",
      "rotation": 2
    },
    {
      "x": 1,
      "y": 4,
      "z": 2,
      "name": "Rock_Ice_Permafrost",
      "rotation": 2
    },
    {
      "x": 1,
      "y": 5,
      "z": 2,
      "name": "Rock_Ice_Permafrost",
      "rotation": 2
    },
    {
      "x": 1,
      "y": 6,
      "z": 2,
      "name": "Rock_Ice_Permafrost"
    },
    {
      "x": 1,
      "y": 7,
      "z": 2,
      "name": "Rock_Ice_Permafrost"
    },
    {
      "x": 1,
      "y": 0,
      "z": 3,
      "name": "Rock_Ice_Permafrost",
      "rotation": 2
    },
    {
      "x": 1,
      "y": 1,
      "z": 3,
      "name": "Rock_Ice_Permafrost",
      "rotation": 2
    },
    {
      "x": 1,
      "y": 2,
      "z": 3,
      "name": "Rock_Ice_Permafrost",
      "rotation": 2
    },
    {
      "x": 1,
      "y": 3,
      "z": 3,
      "name": "Rock_Ice_Permafrost",
      "rotation": 2
    },
    {
      "x": 1,
      "y": 4,
      "z": 3,
      "name": "Rock_Ice_Permafrost",
      "rotation": 2
    },
    {
      "x": 1,
      "y": 5,
      "z": 3,
      "name": "Rock_Ice_Permafrost",
      "rotation": 2
    },
    {
      "x": 1,
      "y": 6,
      "z": 3,
      "name": "Rock_Ice_Permafrost",
      "rotation": 2
    },
    {
      "x": 1,
      "y": 7,
      "z": 3,
      "name": "Rock_Ice_Permafrost"
    },
    {
      "x": 1,
      "y": 2,
      "z": 4,
      "name": "Rock_Ice_Permafrost",
      "rotation": 2
    },
    {
      "x": 1,
      "y": 3,
      "z": 4,
      "name": "Rock_Ice_Permafrost",
      "rotation": 2
    },
    {
      "x": 1,
      "y": 4,
      "z": 4,
      "name": "Rock_Ice_Permafrost",
      "rotation": 2
    },
    {
      "x": 1,
      "y": 5,
      "z": 4,
      "name": "Rock_Ice_Permafrost",
      "rotation": 2
    },
    {
      "x": 2,
      "y": 2,
      "z": 1,
      "name": "Rock_Ice_Permafrost",
      "rotation": 2
    },
    {
      "x": 2,
      "y": 3,
      "z": 1,
      "name": "Rock_Ice_Permafrost",
      "rotation": 2
    },
    {
      "x": 2,
      "y": 4,
      "z": 1,
      "name": "Rock_Ice_Permafrost",
      "rotation": 2
    },
    {
      "x": 2,
      "y": 5,
      "z": 1,
      "name": "Rock_Ice_Permafrost",
      "rotation": 2
    },
    {
      "x": 2,
      "y": 0,
      "z": 2,
      "name": "Rock_Ice_Permafrost",
      "rotation": 2
    },
    {
      "x": 2,
      "y": 1,
      "z": 2,
      "name": "Rock_Ice_Permafrost",
      "rotation": 2
    },
    {
      "x": 2,
      "y": 2,
      "z": 2,
      "name": "Rock_Ice_Permafrost",
      "rotation": 2
    },
    {
      "x": 2,
      "y": 3,
      "z": 2,
      "name": "Rock_Ice_Permafrost",
      "rotation": 2
    },
    {
      "x": 2,
      "y": 4,
      "z": 2,
      "name": "Rock_Ice_Permafrost",
      "rotation": 2
    },
    {
      "x": 2,
      "y": 5,
      "z": 2,
      "name": "Rock_Ice_Permafrost",
      "rotation": 2
    },
    {
      "x": 2,
      "y": 6,
      "z": 2,
      "name": "Rock_Ice_Permafrost",
      "rotation": 2
    },
    {
      "x": 2,
      "y": 0,
      "z": 3,
      "name": "Rock_Ice_Permafrost",
      "rotation": 2
    },
    {
      "x": 2,
      "y": 1,
      "z": 3,
      "name": "Rock_Ice_Permafrost",
      "rotation": 2
    },
    {
      "x": 2,
      "y": 2,
      "z": 3,
      "name": "Rock_Ice_Permafrost",
      "rotation": 2
    },
    {
      "x": 2,
      "y": 3,
      "z": 3,
      "name": "Rock_Ice_Permafrost",
      "rotation": 2
    },
    {
      "x": 2,
      "y": 4,
      "z": 3,
      "name": "Rock_Ice_Permafrost",
      "rotation": 2
    },
    {
      "x": 2,
      "y": 5,
      "z": 3,
      "name": "Rock_Ice_Permafrost",
      "rotation": 2
    },
    {
      "x": 2,
      "y": 6,
      "z": 3,
      "name": "Rock_Ice_Permafrost",
      "rotation": 2
    },
    {
      "x": 2,
      "y": 7,
      "z": 3,
      "name": "Rock_Ice_Permafrost"
    },
    {
      "x": 2,
      "y": 8,
      "z": 3,
      "name": "Rock_Ice_Permafrost"
    },
    {
      "x": 2,
      "y": 2,
      "z": 4,
      "name": "Rock_Ice_Permafrost",
      "rotation": 2
    },
    {
      "x": 2,
      "y": 3,
      "z": 4,
      "name": "Rock_Ice_Permafrost",
      "rotation": 2
    },
    {
      "x": 2,
      "y": 4,
      "z": 4,
      "name": "Rock_Ice_Permafrost",
      "rotation": 2
    },
    {
      "x": 2,
      "y": 5,
      "z": 4,
      "name": "Rock_Ice_Permafrost",
      "rotation": 2
    },
    {
      "x": 2,
      "y": 6,
      "z": 4,
      "name": "Rock_Ice_Permafrost",
      "rotation": 2
    },
    {
      "x": 2,
      "y": 7,
      "z": 4,
      "name": "Rock_Ice_Permafrost",
      "rotation": 2
    },
    {
      "x": 2,
      "y": 8,
      "z": 4,
      "name": "Rock_Ice_Permafrost",
      "rotation": 2
    },
    {
      "x": 2,
      "y": 9,
      "z": 4,
      "name": "Rock_Ice_Permafrost",
      "rotation": 2
    },
    {
      "x": 2,
      "y": 5,
      "z": 5,
      "name": "Rock_Ice_Permafrost",
      "rotation": 2
    },
    {
      "x": 2,
      "y": 6,
      "z": 5,
      "name": "Rock_Ice_Permafrost",
      "rotation": 2
    },
    {
      "x": 2,
      "y": 7,
      "z": 5,
      "name": "Rock_Ice_Permafrost",
      "rotation": 2
    },
    {
      "x": 3,
      "y": 3,
      "z": 1,
      "name": "Rock_Ice_Permafrost",
      "rotation": 2
    },
    {
      "x": 3,
      "y": 4,
      "z": 1,
      "name": "Rock_Ice_Permafrost",
      "rotation": 2
    },
    {
      "x": 3,
      "y": 5,
      "z": 1,
      "name": "Rock_Ice_Permafrost",
      "rotation": 2
    },
    {
      "x": 3,
      "y": 2,
      "z": 2,
      "name": "Rock_Ice_Permafrost",
      "rotation": 2
    },
    {
      "x": 3,
      "y": 3,
      "z": 2,
      "name": "Rock_Ice_Permafrost",
      "rotation": 2
    },
    {
      "x": 3,
      "y": 4,
      "z": 2,
      "name": "Rock_Ice_Permafrost",
      "rotation": 2
    },
    {
      "x": 3,
      "y": 5,
      "z": 2,
      "name": "Rock_Ice_Permafrost",
      "rotation": 2
    },
    {
      "x": 3,
      "y": 1,
      "z": 3,
      "name": "Rock_Ice_Permafrost",
      "rotation": 2
    },
    {
      "x": 3,
      "y": 2,
      "z": 3,
      "name": "Rock_Ice_Permafrost",
      "rotation": 2
    },
    {
      "x": 3,
      "y": 3,
      "z": 3,
      "name": "Rock_Ice_Permafrost",
      "rotation": 2
    },
    {
      "x": 3,
      "y": 4,
      "z": 3,
      "name": "Rock_Ice_Permafrost",
      "rotation": 2
    },
    {
      "x": 3,
      "y": 5,
      "z": 3,
      "name": "Rock_Ice_Permafrost",
      "rotation": 2
    },
    {
      "x": 3,
      "y": 6,
      "z": 3,
      "name": "Rock_Ice_Permafrost",
      "rotation": 2
    },
    {
      "x": 3,
      "y": 7,
      "z": 3,
      "name": "Rock_Ice_Permafrost",
      "rotation": 2
    },
    {
      "x": 3,
      "y": 8,
      "z": 3,
      "name": "Rock_Ice_Permafrost",
      "rotation": 2
    },
    {
      "x": 3,
      "y": 9,
      "z": 3,
      "name": "Rock_Ice_Permafrost",
      "rotation": 2
    },
    {
      "x": 3,
      "y": 10,
      "z": 3,
      "name": "Rock_Ice_Permafrost"
    },
    {
      "x": 3,
      "y": 2,
      "z": 4,
      "name": "Rock_Ice_Permafrost",
      "rotation": 2
    },
    {
      "x": 3,
      "y": 3,
      "z": 4,
      "name": "Rock_Ice_Permafrost",
      "rotation": 2
    },
    {
      "x": 3,
      "y": 4,
      "z": 4,
      "name": "Rock_Ice_Permafrost",
      "rotation": 2
    },
    {
      "x": 3,
      "y": 5,
      "z": 4,
      "name": "Rock_Ice_Permafrost",
      "rotation": 2
    },
    {
      "x": 3,
      "y": 6,
      "z": 4,
      "name": "Rock_Ice_Permafrost",
      "rotation": 2
    },
    {
      "x": 3,
      "y": 7,
      "z": 4,
      "name": "Rock_Ice_Permafrost",
      "rotation": 2
    },
    {
      "x": 3,
      "y": 8,
      "z": 4,
      "name": "Rock_Ice_Permafrost",
      "rotation": 2
    },
    {
      "x": 3,
      "y": 9,
      "z": 4,
      "name": "Rock_Ice_Permafrost",
      "rotation": 2
    },
    {
      "x": 3,
      "y": 10,
      "z": 4,
      "name": "Rock_Ice_Permafrost",
      "rotation": 2
    },
    {
      "x": 3,
      "y": 11,
      "z": 4,
      "name": "Rock_Ice_Permafrost",
      "rotation": 2
    },
    {
      "x": 3,
      "y": 12,
      "z": 4,
      "name": "Rock_Ice_Permafrost",
      "rotation": 2
    },
    {
      "x": 3,
      "y": 13,
      "z": 4,
      "name": "Rock_Ice_Permafrost",
      "rotation": 2
    },
    {
      "x": 3,
      "y": 14,
      "z": 4,
      "name": "Fullmetal_Cyan_Crystal_Lamp"
    },
    {
      "x": 3,
      "y": 3,
      "z": 5,
      "name": "Rock_Ice_Permafrost",
      "rotation": 2
    },
    {
      "x": 3,
      "y": 4,
      "z": 5,
      "name": "Rock_Ice_Permafrost",
      "rotation": 2
    },
    {
      "x": 3,
      "y": 5,
      "z": 5,
      "name": "Rock_Ice_Permafrost",
      "rotation": 2
    },
    {
      "x": 3,
      "y": 6,
      "z": 5,
      "name": "Rock_Ice_Permafrost",
      "rotation": 2
    },
    {
      "x": 3,
      "y": 7,
      "z": 5,
      "name": "Rock_Ice_Permafrost",
      "rotation": 2
    },
    {
      "x": 3,
      "y": 8,
      "z": 5,
      "name": "Rock_Ice_Permafrost",
      "rotation": 2
    },
    {
      "x": 3,
      "y": 9,
      "z": 5,
      "name": "Rock_Ice_Permafrost",
      "rotation": 2
    },
    {
      "x": 3,
      "y": 10,
      "z": 5,
      "name": "Rock_Ice_Permafrost",
      "rotation": 2
    },
    {
      "x": 3,
      "y": 11,
      "z": 5,
      "name": "Rock_Ice_Permafrost",
      "rotation": 2
    },
    {
      "x": 3,
      "y": 12,
      "z": 5,
      "name": "Fullmetal_Cyan_Crystal_Lamp"
    },
    {
      "x": 3,
      "y": 5,
      "z": 6,
      "name": "Fullmetal_White_Crystal_Lamp",
      "rotation": 8
    },
    {
      "x": 3,
      "y": 6,
      "z": 6,
      "name": "Rock_Ice_Permafrost",
      "rotation": 2
    },
    {
      "x": 3,
      "y": 7,
      "z": 6,
      "name": "Rock_Ice_Permafrost",
      "rotation": 2
    },
    {
      "x": 3,
      "y": 8,
      "z": 6,
      "name": "Rock_Ice_Permafrost",
      "rotation": 2
    },
    {
      "x": 3,
      "y": 9,
      "z": 6,
      "name": "Rock_Ice_Permafrost",
      "rotation": 2
    },
    {
      "x": 4,
      "y": 5,
      "z": 3,
      "name": "Rock_Ice_Permafrost",
      "rotation": 2
    },
    {
      "x": 4,
      "y": 6,
      "z": 3,
      "name": "Rock_Ice_Permafrost",
      "rotation": 2
    },
    {
      "x": 4,
      "y": 7,
      "z": 3,
      "name": "Rock_Ice_Permafrost",
      "rotation": 2
    },
    {
      "x": 4,
      "y": 3,
      "z": 4,
      "name": "Rock_Ice_Permafrost",
      "rotation": 2
    },
    {
      "x": 4,
      "y": 4,
      "z": 4,
      "name": "Rock_Ice_Permafrost",
      "rotation": 2
    },
    {
      "x": 4,
      "y": 5,
      "z": 4,
      "name": "Rock_Ice_Permafrost",
      "rotation": 2
    },
    {
      "x": 4,
      "y": 6,
      "z": 4,
      "name": "Rock_Ice_Permafrost",
      "rotation": 2
    },
    {
      "x": 4,
      "y": 7,
      "z": 4,
      "name": "Rock_Ice_Permafrost",
      "rotation": 2
    },
    {
      "x": 4,
      "y": 8,
      "z": 4,
      "name": "Rock_Ice_Permafrost",
      "rotation": 2
    },
    {
      "x": 4,
      "y": 9,
      "z": 4,
      "name": "Rock_Ice_Permafrost",
      "rotation": 2
    },
    {
      "x": 4,
      "y": 10,
      "z": 4,
      "name": "Rock_Ice_Permafrost",
      "rotation": 2
    },
    {
      "x": 4,
      "y": 11,
      "z": 4,
      "name": "Rock_Ice_Permafrost",
      "rotation": 2
    },
    {
      "x": 4,
      "y": 12,
      "z": 4,
      "name": "Fullmetal_Cyan_Crystal_Lamp"
    },
    {
      "x": 4,
      "y": 4,
      "z": 5,
      "name": "Rock_Ice_Permafrost",
      "rotation": 2
    },
    {
      "x": 4,
      "y": 5,
      "z": 5,
      "name": "Rock_Ice_Permafrost",
      "rotation": 2
    },
    {
      "x": 4,
      "y": 6,
      "z": 5,
      "name": "Rock_Ice_Permafrost",
      "rotation": 2
    },
    {
      "x": 4,
      "y": 7,
      "z": 5,
      "name": "Rock_Ice_Permafrost",
      "rotation": 2
    },
    {
      "x": 4,
      "y": 8,
      "z": 5,
      "name": "Rock_Ice_Permafrost",
      "rotation": 2
    },
    {
      "x": 4,
      "y": 9,
      "z": 5,
      "name": "Rock_Ice_Permafrost",
      "rotation": 2
    },
    {
      "x": 4,
      "y": 10,
      "z": 5,
      "name": "Rock_Ice_Permafrost",
      "rotation": 2
    },
    {
      "x": 5,
      "y": 7,
      "z": 4,
      "name": "Rock_Ice_Icicles",
      "rotation": 8
    },
    {
      "x": 5,
      "y": 8,
      "z": 4,
      "name": "Rock_Ice_Permafrost",
      "rotation": 2
    },
    {
      "x": 5,
      "y": 9,
      "z": 4,
      "name": "Rock_Ice_Permafrost",
      "rotation": 2
    }
  ]
}