{
  "version": 8,
  "blockIdVersion": 11,
  "anchorX": 0,
  "anchorY": 0,
  "anchorZ": 0,
  "blocks": [
    {
      "x": -18,
      "y": -26,
      "z": 9,
      "name": "Rock_Ice"
    },
    {
      "x": -18,
      "y": -25,
      "z": 9,
      "name": "Rock_Ice"
    },
    {
      "x": -18,
      "y": -24,
      "z": 9,
      "name": "Rock_Ice"
    },
    {
      "x": -18,
      "y": -23,
      "z": 9,
      "name": "Rock_Ice"
    },
    {
      "x": -17,
      "y": -28,
      "z": 7,
      "name": "Rock_Ice"
    },
    {
      "x": -17,
      "y": -27,
      "z": 7,
      "name": "Rock_Ice"
    },
    {
      "x": -17,
      "y": -26,
      "z": 7,
      "name": "Rock_Ice"
    },
    {
      "x": -17,
      "y": -25,
      "z": 7,
      "name": "Rock_Ice"
    },
    {
      "x": -17,
      "y": -24,
      "z": 7,
      "name": "Rock_Ice"
    },
    {
      "x": -17,
      "y": -23,
      "z": 7,
      "name": "Rock_Ice"
    },
    {
      "x": -17,
      "y": -28,
      "z": 8,
      "name": "Rock_Ice"
    },
    {
      "x": -17,
      "y": -27,
      "z": 8,
      "name": "Rock_Ice"
    },
    {
      "x": -17,
      "y": -26,
      "z": 8,
      "name": "Rock_Ice"
    },
    {
      "x": -17,
      "y": -25,
      "z": 8,
      "name": "Rock_Ice"
    },
    {
      "x": -17,
      "y": -24,
      "z": 8,
      "name": "Rock_Ice"
    },
    {
      "x": -17,
      "y": -23,
      "z": 8,
      "name": "Rock_Ice"
    },
    {
      "x": -17,
      "y": -27,
      "z": 9,
      "name": "Rock_Ice"
    },
    {
      "x": -17,
      "y": -26,
      "z": 9,
      "name": "Rock_Ice"
    },
    {
      "x": -17,
      "y": -25,
      "z": 9,
      "name": "Rock_Ice"
    },
    {
      "x": -17,
      "y": -24,
      "z": 9,
      "name": "Rock_Ice"
    },
    {
      "x": -17,
      "y": -23,
      "z": 9,
      "name": "Rock_Ice"
    },
    {
      "x": -17,
      "y": -22,
      "z": 9,
      "name": "Rock_Ice"
    },
    {
      "x": -17,
      "y": -22,
      "z": 10,
      "name": "Rock_Ice"
    },
    {
      "x": -16,
      "y": -28,
      "z": 5,
      "name": "Rock_Ice"
    },
    {
      "x": -16,
      "y": -27,
      "z": 5,
      "name": "Rock_Ice"
    },
    {
      "x": -16,
      "y": -26,
      "z": 5,
      "name": "Rock_Ice"
    },
    {
      "x": -16,
      "y": -25,
      "z": 5,
      "name": "Rock_Ice"
    },
    {
      "x": -16,
      "y": -26,
      "z": 6,
      "name": "Rock_Ice"
    },
    {
      "x": -16,
      "y": -25,
      "z": 6,
      "name": "Rock_Ice"
    },
    {
      "x": -16,
      "y": -24,
      "z": 6,
      "name": "Rock_Ice"
    },
    {
      "x": -16,
      "y": -23,
      "z": 6,
      "name": "Rock_Ice"
    },
    {
      "x": -16,
      "y": -28,
      "z": 7,
      "name": "Rock_Ice"
    },
    {
      "x": -16,
      "y": -27,
      "z": 7,
      "name": "Rock_Ice"
    },
    {
      "x": -16,
      "y": -26,
      "z": 7,
      "name": "Rock_Ice"
    },
    {
      "x": -16,
      "y": -25,
      "z": 7,
      "name": "Rock_Ice"
    },
    {
      "x": -16,
      "y": -24,
      "z": 7,
      "name": "Rock_Ice"
    },
    {
      "x": -16,
      "y": -23,
      "z": 7,
      "name": "Rock_Ice"
    },
    {
      "x": -16,
      "y": -22,
      "z": 7,
      "name": "Rock_Ice"
    },
    {
      "x": -16,
      "y": -29,
      "z": 8,
      "name": "Rock_Ice"
    },
    {
      "x": -16,
      "y": -28,
      "z": 8,
      "name": "Rock_Ice"
    },
    {
      "x": -16,
      "y": -27,
      "z": 8,
      "name": "Rock_Ice"
    },
    {
      "x": -16,
      "y": -26,
      "z": 8,
      "name": "Rock_Ice"
    },
    {
      "x": -16,
      "y": -25,
      "z": 8,
      "name": "Rock_Ice"
    },
    {
      "x": -16,
      "y": -24,
      "z": 8,
      "name": "Rock_Ice"
    },
    {
      "x": -16,
      "y": -23,
      "z": 8,
      "name": "Rock_Ice"
    },
    {
      "x": -16,
      "y": -22,
      "z": 8,
      "name": "Rock_Ice"
    },
    {
      "x": -16,
      "y": -21,
      "z": 8,
      "name": "Rock_Ice"
    },
    {
      "x": -16,
      "y": -28,
      "z": 9,
      "name": "Rock_Ice"
    },
    {
      "x": -16,
      "y": -27,
      "z": 9,
      "name": "Rock_Ice"
    },
    {
      "x": -16,
      "y": -26,
      "z": 9,
      "name": "Rock_Ice"
    },
    {
      "x": -16,
      "y": -25,
      "z": 9,
      "name": "Rock_Ice"
    },
    {
      "x": -16,
      "y": -24,
      "z": 9,
      "name": "Rock_Ice"
    },
    {
      "x": -16,
      "y": -23,
      "z": 9,
      "name": "Rock_Ice"
    },
    {
      "x": -16,
      "y": -22,
      "z": 9,
      "name": "Rock_Ice"
    },
    {
      "x": -16,
      "y": -21,
      "z": 9,
      "name": "Rock_Ice"
    },
    {
      "x": -16,
      "y": -20,
      "z": 9,
      "name": "Rock_Ice"
    },
    {
      "x": -16,
      "y": -22,
      "z": 10,
      "name": "Rock_Ice"
    },
    {
      "x": -16,
      "y": -21,
      "z": 10,
      "name": "Rock_Ice"
    },
    {
      "x": -16,
      "y": -20,
      "z": 10,
      "name": "Rock_Ice"
    },
    {
      "x": -15,
      "y": -25,
      "z": 4,
      "name": "Rock_Ice"
    },
    {
      "x": -15,
      "y": -36,
      "z": 5,
      "name": "Rock_Ice"
    },
    {
      "x": -15,
      "y": -35,
      "z": 5,
      "name": "Rock_Ice"
    },
    {
      "x": -15,
      "y": -34,
      "z": 5,
      "name": "Rock_Ice"
    },
    {
      "x": -15,
      "y": -30,
      "z": 5,
      "name": "Rock_Ice"
    },
    {
      "x": -15,
      "y": -29,
      "z": 5,
      "name": "Rock_Ice"
    },
    {
      "x": -15,
      "y": -28,
      "z": 5,
      "name": "Rock_Ice"
    },
    {
      "x": -15,
      "y": -25,
      "z": 5,
      "name": "Rock_Ice"
    },
    {
      "x": -15,
      "y": -24,
      "z": 5,
      "name": "Rock_Ice"
    },
    {
      "x": -15,
      "y": -23,
      "z": 5,
      "name": "Rock_Ice"
    },
    {
      "x": -15,
      "y": -30,
      "z": 6,
      "name": "Rock_Ice"
    },
    {
      "x": -15,
      "y": -29,
      "z": 6,
      "name": "Rock_Ice"
    },
    {
      "x": -15,
      "y": -28,
      "z": 6,
      "name": "Rock_Ice"
    },
    {
      "x": -15,
      "y": -27,
      "z": 6,
      "name": "Rock_Ice"
    },
    {
      "x": -15,
      "y": -26,
      "z": 6,
      "name": "Rock_Ice"
    },
    {
      "x": -15,
      "y": -25,
      "z": 6,
      "name": "Rock_Ice"
    },
    {
      "x": -15,
      "y": -24,
      "z": 6,
      "name": "Rock_Ice"
    },
    {
      "x": -15,
      "y": -23,
      "z": 6,
      "name": "Rock_Ice"
    },
    {
      "x": -15,
      "y": -31,
      "z": 7,
      "name": "Rock_Ice"
    },
    {
      "x": -15,
      "y": -30,
      "z": 7,
      "name": "Rock_Ice"
    },
    {
      "x": -15,
      "y": -29,
      "z": 7,
      "name": "Rock_Ice"
    },
    {
      "x": -15,
      "y": -28,
      "z": 7,
      "name": "Rock_Ice"
    },
    {
      "x": -15,
      "y": -27,
      "z": 7,
      "name": "Rock_Ice"
    },
    {
      "x": -15,
      "y": -26,
      "z": 7,
      "name": "Rock_Ice"
    },
    {
      "x": -15,
      "y": -25,
      "z": 7,
      "name": "Rock_Ice"
    },
    {
      "x": -15,
      "y": -24,
      "z": 7,
      "name": "Rock_Ice"
    },
    {
      "x": -15,
      "y": -23,
      "z": 7,
      "name": "Rock_Ice"
    },
    {
      "x": -15,
      "y": -22,
      "z": 7,
      "name": "Rock_Ice"
    },
    {
      "x": -15,
      "y": -21,
      "z": 7,
      "name": "Rock_Ice"
    },
    {
      "x": -15,
      "y": -20,
      "z": 7,
      "name": "Rock_Ice"
    },
    {
      "x": -15,
      "y": -19,
      "z": 7,
      "name": "Rock_Ice"
    },
    {
      "x": -15,
      "y": -28,
      "z": 8,
      "name": "Rock_Ice"
    },
    {
      "x": -15,
      "y": -27,
      "z": 8,
      "name": "Rock_Ice"
    },
    {
      "x": -15,
      "y": -26,
      "z": 8,
      "name": "Rock_Ice"
    },
    {
      "x": -15,
      "y": -25,
      "z": 8,
      "name": "Rock_Ice"
    },
    {
      "x": -15,
      "y": -24,
      "z": 8,
      "name": "Rock_Ice"
    },
    {
      "x": -15,
      "y": -23,
      "z": 8,
      "name": "Rock_Ice"
    },
    {
      "x": -15,
      "y": -22,
      "z": 8,
      "name": "Rock_Ice"
    },
    {
      "x": -15,
      "y": -21,
      "z": 8,
      "name": "Rock_Ice"
    },
    {
      "x": -15,
      "y": -20,
      "z": 8,
      "name": "Rock_Ice"
    },
    {
      "x": -15,
      "y": -19,
      "z": 8,
      "name": "Rock_Ice"
    },
    {
      "x": -15,
      "y": -18,
      "z": 8,
      "name": "Rock_Ice"
    },
    {
      "x": -15,
      "y": -26,
      "z": 9,
      "name": "Rock_Ice"
    },
    {
      "x": -15,
      "y": -25,
      "z": 9,
      "name": "Rock_Ice"
    },
    {
      "x": -15,
      "y": -24,
      "z": 9,
      "name": "Rock_Ice"
    },
    {
      "x": -15,
      "y": -23,
      "z": 9,
      "name": "Rock_Ice"
    },
    {
      "x": -15,
      "y": -22,
      "z": 9,
      "name": "Rock_Ice"
    },
    {
      "x": -15,
      "y": -21,
      "z": 9,
      "name": "Rock_Ice"
    },
    {
      "x": -15,
      "y": -20,
      "z": 9,
      "name": "Rock_Ice"
    },
    {
      "x": -15,
      "y": -19,
      "z": 9,
      "name": "Rock_Ice"
    },
    {
      "x": -15,
      "y": -22,
      "z": 10,
      "name": "Rock_Ice"
    },
    {
      "x": -15,
      "y": -21,
      "z": 10,
      "name": "Rock_Ice"
    },
    {
      "x": -15,
      "y": -20,
      "z": 10,
      "name": "Rock_Ice"
    },
    {
      "x": -15,
      "y": -19,
      "z": 10,
      "name": "Rock_Ice"
    },
    {
      "x": -15,
      "y": -21,
      "z": 11,
      "name": "Rock_Ice"
    },
    {
      "x": -14,
      "y": -36,
      "z": 1,
      "name": "Rock_Ice"
    },
    {
      "x": -14,
      "y": -35,
      "z": 1,
      "name": "Rock_Ice"
    },
    {
      "x": -14,
      "y": -34,
      "z": 1,
      "name": "Rock_Ice"
    },
    {
      "x": -14,
      "y": -36,
      "z": 2,
      "name": "Rock_Ice"
    },
    {
      "x": -14,
      "y": -35,
      "z": 2,
      "name": "Rock_Ice"
    },
    {
      "x": -14,
      "y": -34,
      "z": 2,
      "name": "Rock_Ice"
    },
    {
      "x": -14,
      "y": -36,
      "z": 3,
      "name": "Rock_Ice"
    },
    {
      "x": -14,
      "y": -35,
      "z": 3,
      "name": "Rock_Ice"
    },
    {
      "x": -14,
      "y": -34,
      "z": 3,
      "name": "Rock_Ice"
    },
    {
      "x": -14,
      "y": -33,
      "z": 3,
      "name": "Rock_Ice"
    },
    {
      "x": -14,
      "y": -32,
      "z": 3,
      "name": "Rock_Ice"
    },
    {
      "x": -14,
      "y": -24,
      "z": 3,
      "name": "Rock_Ice"
    },
    {
      "x": -14,
      "y": -23,
      "z": 3,
      "name": "Rock_Ice"
    },
    {
      "x": -14,
      "y": -22,
      "z": 3,
      "name": "Rock_Ice"
    },
    {
      "x": -14,
      "y": -21,
      "z": 3,
      "name": "Rock_Ice"
    },
    {
      "x": -14,
      "y": -20,
      "z": 3,
      "name": "Rock_Ice"
    },
    {
      "x": -14,
      "y": -19,
      "z": 3,
      "name": "Rock_Ice"
    },
    {
      "x": -14,
      "y": -18,
      "z": 3,
      "name": "Rock_Ice"
    },
    {
      "x": -14,
      "y": -17,
      "z": 3,
      "name": "Rock_Ice"
    },
    {
      "x": -14,
      "y": -36,
      "z": 4,
      "name": "Rock_Ice"
    },
    {
      "x": -14,
      "y": -35,
      "z": 4,
      "name": "Rock_Ice"
    },
    {
      "x": -14,
      "y": -34,
      "z": 4,
      "name": "Rock_Ice"
    },
    {
      "x": -14,
      "y": -33,
      "z": 4,
      "name": "Rock_Ice"
    },
    {
      "x": -14,
      "y": -32,
      "z": 4,
      "name": "Rock_Ice"
    },
    {
      "x": -14,
      "y": -31,
      "z": 4,
      "name": "Rock_Ice"
    },
    {
      "x": -14,
      "y": -30,
      "z": 4,
      "name": "Rock_Ice"
    },
    {
      "x": -14,
      "y": -29,
      "z": 4,
      "name": "Rock_Ice"
    },
    {
      "x": -14,
      "y": -28,
      "z": 4,
      "name": "Rock_Ice"
    },
    {
      "x": -14,
      "y": -27,
      "z": 4,
      "name": "Rock_Ice"
    },
    {
      "x": -14,
      "y": -26,
      "z": 4,
      "name": "Rock_Ice"
    },
    {
      "x": -14,
      "y": -25,
      "z": 4,
      "name": "Rock_Ice"
    },
    {
      "x": -14,
      "y": -24,
      "z": 4,
      "name": "Rock_Ice"
    },
    {
      "x": -14,
      "y": -23,
      "z": 4,
      "name": "Rock_Ice"
    },
    {
      "x": -14,
      "y": -22,
      "z": 4,
      "name": "Rock_Ice"
    },
    {
      "x": -14,
      "y": -21,
      "z": 4,
      "name": "Rock_Ice"
    },
    {
      "x": -14,
      "y": -20,
      "z": 4,
      "name": "Rock_Ice"
    },
    {
      "x": -14,
      "y": -19,
      "z": 4,
      "name": "Rock_Ice"
    },
    {
      "x": -14,
      "y": -18,
      "z": 4,
      "name": "Rock_Ice"
    },
    {
      "x": -14,
      "y": -36,
      "z": 5,
      "name": "Rock_Ice"
    },
    {
      "x": -14,
      "y": -35,
      "z": 5,
      "name": "Rock_Ice"
    },
    {
      "x": -14,
      "y": -34,
      "z": 5,
      "name": "Rock_Ice"
    },
    {
      "x": -14,
      "y": -33,
      "z": 5,
      "name": "Rock_Ice"
    },
    {
      "x": -14,
      "y": -32,
      "z": 5,
      "name": "Rock_Ice"
    },
    {
      "x": -14,
      "y": -31,
      "z": 5,
      "name": "Rock_Ice"
    },
    {
      "x": -14,
      "y": -30,
      "z": 5,
      "name": "Rock_Ice"
    },
    {
      "x": -14,
      "y": -29,
      "z": 5,
      "name": "Rock_Ice"
    },
    {
      "x": -14,
      "y": -28,
      "z": 5,
      "name": "Rock_Ice"
    },
    {
      "x": -14,
      "y": -27,
      "z": 5,
      "name": "Rock_Ice"
    },
    {
      "x": -14,
      "y": -26,
      "z": 5,
      "name": "Rock_Ice"
    },
    {
      "x": -14,
      "y": -25,
      "z": 5,
      "name": "Rock_Ice"
    },
    {
      "x": -14,
      "y": -24,
      "z": 5,
      "name": "Rock_Ice"
    },
    {
      "x": -14,
      "y": -23,
      "z": 5,
      "name": "Rock_Ice"
    },
    {
      "x": -14,
      "y": -22,
      "z": 5,
      "name": "Rock_Ice"
    },
    {
      "x": -14,
      "y": -21,
      "z": 5,
      "name": "Rock_Ice"
    },
    {
      "x": -14,
      "y": -20,
      "z": 5,
      "name": "Rock_Ice"
    },
    {
      "x": -14,
      "y": -19,
      "z": 5,
      "name": "Rock_Ice"
    },
    {
      "x": -14,
      "y": -18,
      "z": 5,
      "name": "Rock_Ice"
    },
    {
      "x": -14,
      "y": -17,
      "z": 5,
      "name": "Rock_Ice"
    },
    {
      "x": -14,
      "y": -33,
      "z": 6,
      "name": "Rock_Ice"
    },
    {
      "x": -14,
      "y": -32,
      "z": 6,
      "name": "Rock_Ice"
    },
    {
      "x": -14,
      "y": -31,
      "z": 6,
      "name": "Rock_Ice"
    },
    {
      "x": -14,
      "y": -30,
      "z": 6,
      "name": "Rock_Ice"
    },
    {
      "x": -14,
      "y": -29,
      "z": 6,
      "name": "Rock_Ice"
    },
    {
      "x": -14,
      "y": -28,
      "z": 6,
      "name": "Rock_Ice"
    },
    {
      "x": -14,
      "y": -27,
      "z": 6,
      "name": "Rock_Ice"
    },
    {
      "x": -14,
      "y": -26,
      "z": 6,
      "name": "Rock_Ice"
    },
    {
      "x": -14,
      "y": -25,
      "z": 6,
      "name": "Rock_Ice"
    },
    {
      "x": -14,
      "y": -24,
      "z": 6,
      "name": "Rock_Ice"
    },
    {
      "x": -14,
      "y": -23,
      "z": 6,
      "name": "Rock_Ice"
    },
    {
      "x": -14,
      "y": -22,
      "z": 6,
      "name": "Rock_Ice"
    },
    {
      "x": -14,
      "y": -21,
      "z": 6,
      "name": "Rock_Ice"
    },
    {
      "x": -14,
      "y": -20,
      "z": 6,
      "name": "Rock_Ice"
    },
    {
      "x": -14,
      "y": -19,
      "z": 6,
      "name": "Rock_Ice"
    },
    {
      "x": -14,
      "y": -18,
      "z": 6,
      "name": "Rock_Ice"
    },
    {
      "x": -14,
      "y": -33,
      "z": 7,
      "name": "Rock_Ice"
    },
    {
      "x": -14,
      "y": -32,
      "z": 7,
      "name": "Rock_Ice"
    },
    {
      "x": -14,
      "y": -31,
      "z": 7,
      "name": "Rock_Ice"
    },
    {
      "x": -14,
      "y": -30,
      "z": 7,
      "name": "Rock_Ice"
    },
    {
      "x": -14,
      "y": -29,
      "z": 7,
      "name": "Rock_Ice"
    },
    {
      "x": -14,
      "y": -28,
      "z": 7,
      "name": "Rock_Ice"
    },
    {
      "x": -14,
      "y": -27,
      "z": 7,
      "name": "Rock_Ice"
    },
    {
      "x": -14,
      "y": -26,
      "z": 7,
      "name": "Rock_Ice"
    },
    {
      "x": -14,
      "y": -25,
      "z": 7,
      "name": "Rock_Ice"
    },
    {
      "x": -14,
      "y": -24,
      "z": 7,
      "name": "Rock_Ice"
    },
    {
      "x": -14,
      "y": -23,
      "z": 7,
      "name": "Rock_Ice"
    },
    {
      "x": -14,
      "y": -22,
      "z": 7,
      "name": "Rock_Ice"
    },
    {
      "x": -14,
      "y": -21,
      "z": 7,
      "name": "Rock_Ice"
    },
    {
      "x": -14,
      "y": -20,
      "z": 7,
      "name": "Rock_Ice"
    },
    {
      "x": -14,
      "y": -19,
      "z": 7,
      "name": "Rock_Ice"
    },
    {
      "x": -14,
      "y": -18,
      "z": 7,
      "name": "Rock_Ice"
    },
    {
      "x": -14,
      "y": -28,
      "z": 8,
      "name": "Rock_Ice"
    },
    {
      "x": -14,
      "y": -27,
      "z": 8,
      "name": "Rock_Ice"
    },
    {
      "x": -14,
      "y": -26,
      "z": 8,
      "name": "Rock_Ice"
    },
    {
      "x": -14,
      "y": -25,
      "z": 8,
      "name": "Rock_Ice"
    },
    {
      "x": -14,
      "y": -24,
      "z": 8,
      "name": "Rock_Ice"
    },
    {
      "x": -14,
      "y": -23,
      "z": 8,
      "name": "Rock_Ice"
    },
    {
      "x": -14,
      "y": -22,
      "z": 8,
      "name": "Rock_Ice"
    },
    {
      "x": -14,
      "y": -21,
      "z": 8,
      "name": "Rock_Ice"
    },
    {
      "x": -14,
      "y": -20,
      "z": 8,
      "name": "Rock_Ice"
    },
    {
      "x": -14,
      "y": -19,
      "z": 8,
      "name": "Rock_Ice"
    },
    {
      "x": -14,
      "y": -18,
      "z": 8,
      "name": "Rock_Ice"
    },
    {
      "x": -14,
      "y": -24,
      "z": 9,
      "name": "Rock_Ice"
    },
    {
      "x": -14,
      "y": -23,
      "z": 9,
      "name": "Rock_Ice"
    },
    {
      "x": -14,
      "y": -22,
      "z": 9,
      "name": "Rock_Ice"
    },
    {
      "x": -14,
      "y": -21,
      "z": 9,
      "name": "Rock_Ice"
    },
    {
      "x": -14,
      "y": -20,
      "z": 9,
      "name": "Rock_Ice"
    },
    {
      "x": -14,
      "y": -19,
      "z": 9,
      "name": "Rock_Ice"
    },
    {
      "x": -14,
      "y": -18,
      "z": 9,
      "name": "Rock_Ice"
    },
    {
      "x": -14,
      "y": -22,
      "z": 10,
      "name": "Rock_Ice"
    },
    {
      "x": -14,
      "y": -21,
      "z": 10,
      "name": "Rock_Ice"
    },
    {
      "x": -14,
      "y": -20,
      "z": 10,
      "name": "Rock_Ice"
    },
    {
      "x": -14,
      "y": -19,
      "z": 10,
      "name": "Rock_Ice"
    },
    {
      "x": -13,
      "y": -34,
      "z": 1,
      "name": "Rock_Ice"
    },
    {
      "x": -13,
      "y": -36,
      "z": 2,
      "name": "Rock_Ice"
    },
    {
      "x": -13,
      "y": -35,
      "z": 2,
      "name": "Rock_Ice"
    },
    {
      "x": -13,
      "y": -34,
      "z": 2,
      "name": "Rock_Ice"
    },
    {
      "x": -13,
      "y": -33,
      "z": 2,
      "name": "Rock_Ice"
    },
    {
      "x": -13,
      "y": -32,
      "z": 2,
      "name": "Rock_Ice"
    },
    {
      "x": -13,
      "y": -22,
      "z": 2,
      "name": "Rock_Ice"
    },
    {
      "x": -13,
      "y": -36,
      "z": 3,
      "name": "Rock_Ice"
    },
    {
      "x": -13,
      "y": -35,
      "z": 3,
      "name": "Rock_Ice"
    },
    {
      "x": -13,
      "y": -34,
      "z": 3,
      "name": "Rock_Ice"
    },
    {
      "x": -13,
      "y": -33,
      "z": 3,
      "name": "Rock_Ice"
    },
    {
      "x": -13,
      "y": -32,
      "z": 3,
      "name": "Rock_Ice"
    },
    {
      "x": -13,
      "y": -26,
      "z": 3,
      "name": "Rock_Ice"
    },
    {
      "x": -13,
      "y": -25,
      "z": 3,
      "name": "Rock_Ice"
    },
    {
      "x": -13,
      "y": -24,
      "z": 3,
      "name": "Rock_Ice"
    },
    {
      "x": -13,
      "y": -23,
      "z": 3,
      "name": "Rock_Ice"
    },
    {
      "x": -13,
      "y": -22,
      "z": 3,
      "name": "Rock_Ice"
    },
    {
      "x": -13,
      "y": -21,
      "z": 3,
      "name": "Rock_Ice"
    },
    {
      "x": -13,
      "y": -20,
      "z": 3,
      "name": "Rock_Ice"
    },
    {
      "x": -13,
      "y": -19,
      "z": 3,
      "name": "Rock_Ice"
    },
    {
      "x": -13,
      "y": -18,
      "z": 3,
      "name": "Rock_Ice"
    },
    {
      "x": -13,
      "y": -17,
      "z": 3,
      "name": "Rock_Ice"
    },
    {
      "x": -13,
      "y": -36,
      "z": 4,
      "name": "Rock_Ice"
    },
    {
      "x": -13,
      "y": -35,
      "z": 4,
      "name": "Rock_Ice"
    },
    {
      "x": -13,
      "y": -34,
      "z": 4,
      "name": "Rock_Ice"
    },
    {
      "x": -13,
      "y": -33,
      "z": 4,
      "name": "Rock_Ice"
    },
    {
      "x": -13,
      "y": -32,
      "z": 4,
      "name": "Rock_Ice"
    },
    {
      "x": -13,
      "y": -31,
      "z": 4,
      "name": "Rock_Ice"
    },
    {
      "x": -13,
      "y": -30,
      "z": 4,
      "name": "Rock_Ice"
    },
    {
      "x": -13,
      "y": -29,
      "z": 4,
      "name": "Rock_Ice"
    },
    {
      "x": -13,
      "y": -28,
      "z": 4,
      "name": "Rock_Ice"
    },
    {
      "x": -13,
      "y": -27,
      "z": 4,
      "name": "Rock_Ice"
    },
    {
      "x": -13,
      "y": -26,
      "z": 4,
      "name": "Rock_Ice"
    },
    {
      "x": -13,
      "y": -25,
      "z": 4,
      "name": "Rock_Ice"
    },
    {
      "x": -13,
      "y": -24,
      "z": 4,
      "name": "Rock_Ice"
    },
    {
      "x": -13,
      "y": -23,
      "z": 4,
      "name": "Rock_Ice"
    },
    {
      "x": -13,
      "y": -22,
      "z": 4,
      "name": "Rock_Ice"
    },
    {
      "x": -13,
      "y": -21,
      "z": 4,
      "name": "Rock_Ice"
    },
    {
      "x": -13,
      "y": -20,
      "z": 4,
      "name": "Rock_Ice"
    },
    {
      "x": -13,
      "y": -19,
      "z": 4,
      "name": "Rock_Ice"
    },
    {
      "x": -13,
      "y": -18,
      "z": 4,
      "name": "Rock_Ice"
    },
    {
      "x": -13,
      "y": -17,
      "z": 4,
      "name": "Rock_Ice"
    },
    {
      "x": -13,
      "y": -33,
      "z": 5,
      "name": "Rock_Ice"
    },
    {
      "x": -13,
      "y": -32,
      "z": 5,
      "name": "Rock_Ice"
    },
    {
      "x": -13,
      "y": -31,
      "z": 5,
      "name": "Rock_Ice"
    },
    {
      "x": -13,
      "y": -30,
      "z": 5,
      "name": "Rock_Ice"
    },
    {
      "x": -13,
      "y": -29,
      "z": 5,
      "name": "Rock_Ice"
    },
    {
      "x": -13,
      "y": -28,
      "z": 5,
      "name": "Rock_Ice"
    },
    {
      "x": -13,
      "y": -27,
      "z": 5,
      "name": "Rock_Ice"
    },
    {
      "x": -13,
      "y": -26,
      "z": 5,
      "name": "Rock_Ice"
    },
    {
      "x": -13,
      "y": -25,
      "z": 5,
      "name": "Rock_Ice"
    },
    {
      "x": -13,
      "y": -24,
      "z": 5,
      "name": "Rock_Ice"
    },
    {
      "x": -13,
      "y": -23,
      "z": 5,
      "name": "Rock_Ice"
    },
    {
      "x": -13,
      "y": -22,
      "z": 5,
      "name": "Rock_Ice"
    },
    {
      "x": -13,
      "y": -21,
      "z": 5,
      "name": "Rock_Ice"
    },
    {
      "x": -13,
      "y": -20,
      "z": 5,
      "name": "Rock_Ice"
    },
    {
      "x": -13,
      "y": -19,
      "z": 5,
      "name": "Rock_Ice"
    },
    {
      "x": -13,
      "y": -18,
      "z": 5,
      "name": "Rock_Ice"
    },
    {
      "x": -13,
      "y": -17,
      "z": 5,
      "name": "Rock_Ice"
    },
    {
      "x": -13,
      "y": -16,
      "z": 5,
      "name": "Rock_Ice"
    },
    {
      "x": -13,
      "y": -33,
      "z": 6,
      "name": "Rock_Ice"
    },
    {
      "x": -13,
      "y": -32,
      "z": 6,
      "name": "Rock_Ice"
    },
    {
      "x": -13,
      "y": -31,
      "z": 6,
      "name": "Rock_Ice"
    },
    {
      "x": -13,
      "y": -30,
      "z": 6,
      "name": "Rock_Ice"
    },
    {
      "x": -13,
      "y": -29,
      "z": 6,
      "name": "Rock_Ice"
    },
    {
      "x": -13,
      "y": -28,
      "z": 6,
      "name": "Rock_Ice"
    },
    {
      "x": -13,
      "y": -27,
      "z": 6,
      "name": "Rock_Ice"
    },
    {
      "x": -13,
      "y": -26,
      "z": 6,
      "name": "Rock_Ice"
    },
    {
      "x": -13,
      "y": -25,
      "z": 6,
      "name": "Rock_Ice"
    },
    {
      "x": -13,
      "y": -24,
      "z": 6,
      "name": "Rock_Ice"
    },
    {
      "x": -13,
      "y": -23,
      "z": 6,
      "name": "Rock_Ice"
    },
    {
      "x": -13,
      "y": -22,
      "z": 6,
      "name": "Rock_Ice"
    },
    {
      "x": -13,
      "y": -21,
      "z": 6,
      "name": "Rock_Ice"
    },
    {
      "x": -13,
      "y": -20,
      "z": 6,
      "name": "Rock_Ice"
    },
    {
      "x": -13,
      "y": -19,
      "z": 6,
      "name": "Rock_Ice"
    },
    {
      "x": -13,
      "y": -18,
      "z": 6,
      "name": "Rock_Ice"
    },
    {
      "x": -13,
      "y": -17,
      "z": 6,
      "name": "Rock_Ice"
    },
    {
      "x": -13,
      "y": -28,
      "z": 7,
      "name": "Rock_Ice"
    },
    {
      "x": -13,
      "y": -27,
      "z": 7,
      "name": "Rock_Ice"
    },
    {
      "x": -13,
      "y": -26,
      "z": 7,
      "name": "Rock_Ice"
    },
    {
      "x": -13,
      "y": -25,
      "z": 7,
      "name": "Rock_Ice"
    },
    {
      "x": -13,
      "y": -24,
      "z": 7,
      "name": "Rock_Ice"
    },
    {
      "x": -13,
      "y": -23,
      "z": 7,
      "name": "Rock_Ice"
    },
    {
      "x": -13,
      "y": -22,
      "z": 7,
      "name": "Rock_Ice"
    },
    {
      "x": -13,
      "y": -21,
      "z": 7,
      "name": "Rock_Ice"
    },
    {
      "x": -13,
      "y": -20,
      "z": 7,
      "name": "Rock_Ice"
    },
    {
      "x": -13,
      "y": -19,
      "z": 7,
      "name": "Rock_Ice"
    },
    {
      "x": -13,
      "y": -18,
      "z": 7,
      "name": "Rock_Ice"
    },
    {
      "x": -13,
      "y": -17,
      "z": 7,
      "name": "Rock_Ice"
    },
    {
      "x": -13,
      "y": -26,
      "z": 8,
      "name": "Rock_Ice"
    },
    {
      "x": -13,
      "y": -25,
      "z": 8,
      "name": "Rock_Ice"
    },
    {
      "x": -13,
      "y": -24,
      "z": 8,
      "name": "Rock_Ice"
    },
    {
      "x": -13,
      "y": -23,
      "z": 8,
      "name": "Rock_Ice"
    },
    {
      "x": -13,
      "y": -22,
      "z": 8,
      "name": "Rock_Ice"
    },
    {
      "x": -13,
      "y": -21,
      "z": 8,
      "name": "Rock_Ice"
    },
    {
      "x": -13,
      "y": -20,
      "z": 8,
      "name": "Rock_Ice"
    },
    {
      "x": -13,
      "y": -19,
      "z": 8,
      "name": "Rock_Ice"
    },
    {
      "x": -13,
      "y": -18,
      "z": 8,
      "name": "Rock_Ice"
    },
    {
      "x": -13,
      "y": -22,
      "z": 9,
      "name": "Rock_Ice"
    },
    {
      "x": -13,
      "y": -21,
      "z": 9,
      "name": "Rock_Ice"
    },
    {
      "x": -13,
      "y": -20,
      "z": 9,
      "name": "Rock_Ice"
    },
    {
      "x": -13,
      "y": -19,
      "z": 9,
      "name": "Rock_Ice"
    },
    {
      "x": -13,
      "y": -18,
      "z": 9,
      "name": "Rock_Ice"
    },
    {
      "x": -12,
      "y": -36,
      "z": 2,
      "name": "Rock_Ice"
    },
    {
      "x": -12,
      "y": -35,
      "z": 2,
      "name": "Rock_Ice"
    },
    {
      "x": -12,
      "y": -34,
      "z": 2,
      "name": "Rock_Ice"
    },
    {
      "x": -12,
      "y": -22,
      "z": 2,
      "name": "Rock_Ice"
    },
    {
      "x": -12,
      "y": -20,
      "z": 2,
      "name": "Rock_Ice"
    },
    {
      "x": -12,
      "y": -19,
      "z": 2,
      "name": "Rock_Ice"
    },
    {
      "x": -12,
      "y": -18,
      "z": 2,
      "name": "Rock_Ice"
    },
    {
      "x": -12,
      "y": -17,
      "z": 2,
      "name": "Rock_Ice"
    },
    {
      "x": -12,
      "y": -36,
      "z": 3,
      "name": "Rock_Ice"
    },
    {
      "x": -12,
      "y": -35,
      "z": 3,
      "name": "Rock_Ice"
    },
    {
      "x": -12,
      "y": -34,
      "z": 3,
      "name": "Rock_Ice"
    },
    {
      "x": -12,
      "y": -33,
      "z": 3,
      "name": "Rock_Ice"
    },
    {
      "x": -12,
      "y": -32,
      "z": 3,
      "name": "Rock_Ice"
    },
    {
      "x": -12,
      "y": -31,
      "z": 3,
      "name": "Rock_Ice"
    },
    {
      "x": -12,
      "y": -30,
      "z": 3,
      "name": "Rock_Ice"
    },
    {
      "x": -12,
      "y": -29,
      "z": 3,
      "name": "Rock_Ice"
    },
    {
      "x": -12,
      "y": -28,
      "z": 3,
      "name": "Rock_Ice"
    },
    {
      "x": -12,
      "y": -25,
      "z": 3,
      "name": "Rock_Ice"
    },
    {
      "x": -12,
      "y": -24,
      "z": 3,
      "name": "Rock_Ice"
    },
    {
      "x": -12,
      "y": -23,
      "z": 3,
      "name": "Rock_Ice"
    },
    {
      "x": -12,
      "y": -22,
      "z": 3,
      "name": "Rock_Ice"
    },
    {
      "x": -12,
      "y": -21,
      "z": 3,
      "name": "Rock_Ice"
    },
    {
      "x": -12,
      "y": -20,
      "z": 3,
      "name": "Rock_Ice"
    },
    {
      "x": -12,
      "y": -19,
      "z": 3,
      "name": "Rock_Ice"
    },
    {
      "x": -12,
      "y": -18,
      "z": 3,
      "name": "Rock_Ice"
    },
    {
      "x": -12,
      "y": -17,
      "z": 3,
      "name": "Rock_Ice"
    },
    {
      "x": -12,
      "y": -16,
      "z": 3,
      "name": "Rock_Ice"
    },
    {
      "x": -12,
      "y": -15,
      "z": 3,
      "name": "Rock_Ice"
    },
    {
      "x": -12,
      "y": -36,
      "z": 4,
      "name": "Rock_Ice"
    },
    {
      "x": -12,
      "y": -35,
      "z": 4,
      "name": "Rock_Ice"
    },
    {
      "x": -12,
      "y": -34,
      "z": 4,
      "name": "Rock_Ice"
    },
    {
      "x": -12,
      "y": -33,
      "z": 4,
      "name": "Rock_Ice"
    },
    {
      "x": -12,
      "y": -32,
      "z": 4,
      "name": "Rock_Ice"
    },
    {
      "x": -12,
      "y": -31,
      "z": 4,
      "name": "Rock_Ice"
    },
    {
      "x": -12,
      "y": -30,
      "z": 4,
      "name": "Rock_Ice"
    },
    {
      "x": -12,
      "y": -29,
      "z": 4,
      "name": "Rock_Ice"
    },
    {
      "x": -12,
      "y": -28,
      "z": 4,
      "name": "Rock_Ice"
    },
    {
      "x": -12,
      "y": -27,
      "z": 4,
      "name": "Rock_Ice"
    },
    {
      "x": -12,
      "y": -26,
      "z": 4,
      "name": "Rock_Ice"
    },
    {
      "x": -12,
      "y": -25,
      "z": 4,
      "name": "Rock_Ice"
    },
    {
      "x": -12,
      "y": -24,
      "z": 4,
      "name": "Rock_Ice"
    },
    {
      "x": -12,
      "y": -23,
      "z": 4,
      "name": "Rock_Ice"
    },
    {
      "x": -12,
      "y": -22,
      "z": 4,
      "name": "Rock_Ice"
    },
    {
      "x": -12,
      "y": -21,
      "z": 4,
      "name": "Rock_Ice"
    },
    {
      "x": -12,
      "y": -20,
      "z": 4,
      "name": "Rock_Ice"
    },
    {
      "x": -12,
      "y": -19,
      "z": 4,
      "name": "Rock_Ice"
    },
    {
      "x": -12,
      "y": -18,
      "z": 4,
      "name": "Rock_Ice"
    },
    {
      "x": -12,
      "y": -17,
      "z": 4,
      "name": "Rock_Ice"
    },
    {
      "x": -12,
      "y": -16,
      "z": 4,
      "name": "Rock_Ice"
    },
    {
      "x": -12,
      "y": -33,
      "z": 5,
      "name": "Rock_Ice"
    },
    {
      "x": -12,
      "y": -32,
      "z": 5,
      "name": "Rock_Ice"
    },
    {
      "x": -12,
      "y": -31,
      "z": 5,
      "name": "Rock_Ice"
    },
    {
      "x": -12,
      "y": -30,
      "z": 5,
      "name": "Rock_Ice"
    },
    {
      "x": -12,
      "y": -29,
      "z": 5,
      "name": "Rock_Ice"
    },
    {
      "x": -12,
      "y": -28,
      "z": 5,
      "name": "Rock_Ice"
    },
    {
      "x": -12,
      "y": -27,
      "z": 5,
      "name": "Rock_Ice"
    },
    {
      "x": -12,
      "y": -26,
      "z": 5,
      "name": "Rock_Ice"
    },
    {
      "x": -12,
      "y": -25,
      "z": 5,
      "name": "Rock_Ice"
    },
    {
      "x": -12,
      "y": -24,
      "z": 5,
      "name": "Rock_Ice"
    },
    {
      "x": -12,
      "y": -23,
      "z": 5,
      "name": "Rock_Ice"
    },
    {
      "x": -12,
      "y": -22,
      "z": 5,
      "name": "Rock_Ice"
    },
    {
      "x": -12,
      "y": -21,
      "z": 5,
      "name": "Rock_Ice"
    },
    {
      "x": -12,
      "y": -20,
      "z": 5,
      "name": "Rock_Ice"
    },
    {
      "x": -12,
      "y": -19,
      "z": 5,
      "name": "Rock_Ice"
    },
    {
      "x": -12,
      "y": -18,
      "z": 5,
      "name": "Rock_Ice"
    },
    {
      "x": -12,
      "y": -17,
      "z": 5,
      "name": "Rock_Ice"
    },
    {
      "x": -12,
      "y": -16,
      "z": 5,
      "name": "Rock_Ice"
    },
    {
      "x": -12,
      "y": -15,
      "z": 5,
      "name": "Rock_Ice"
    },
    {
      "x": -12,
      "y": -30,
      "z": 6,
      "name": "Rock_Ice"
    },
    {
      "x": -12,
      "y": -29,
      "z": 6,
      "name": "Rock_Ice"
    },
    {
      "x": -12,
      "y": -28,
      "z": 6,
      "name": "Rock_Ice"
    },
    {
      "x": -12,
      "y": -27,
      "z": 6,
      "name": "Rock_Ice"
    },
    {
      "x": -12,
      "y": -26,
      "z": 6,
      "name": "Rock_Ice"
    },
    {
      "x": -12,
      "y": -25,
      "z": 6,
      "name": "Rock_Ice"
    },
    {
      "x": -12,
      "y": -24,
      "z": 6,
      "name": "Rock_Ice"
    },
    {
      "x": -12,
      "y": -23,
      "z": 6,
      "name": "Rock_Ice"
    },
    {
      "x": -12,
      "y": -22,
      "z": 6,
      "name": "Rock_Ice"
    },
    {
      "x": -12,
      "y": -21,
      "z": 6,
      "name": "Rock_Ice"
    },
    {
      "x": -12,
      "y": -20,
      "z": 6,
      "name": "Rock_Ice"
    },
    {
      "x": -12,
      "y": -19,
      "z": 6,
      "name": "Rock_Ice"
    },
    {
      "x": -12,
      "y": -18,
      "z": 6,
      "name": "Rock_Ice"
    },
    {
      "x": -12,
      "y": -17,
      "z": 6,
      "name": "Rock_Ice"
    },
    {
      "x": -12,
      "y": -28,
      "z": 7,
      "name": "Rock_Ice"
    },
    {
      "x": -12,
      "y": -27,
      "z": 7,
      "name": "Rock_Ice"
    },
    {
      "x": -12,
      "y": -26,
      "z": 7,
      "name": "Rock_Ice"
    },
    {
      "x": -12,
      "y": -25,
      "z": 7,
      "name": "Rock_Ice"
    },
    {
      "x": -12,
      "y": -24,
      "z": 7,
      "name": "Rock_Ice"
    },
    {
      "x": -12,
      "y": -23,
      "z": 7,
      "name": "Rock_Ice"
    },
    {
      "x": -12,
      "y": -22,
      "z": 7,
      "name": "Rock_Ice"
    },
    {
      "x": -12,
      "y": -21,
      "z": 7,
      "name": "Rock_Ice"
    },
    {
      "x": -12,
      "y": -20,
      "z": 7,
      "name": "Rock_Ice"
    },
    {
      "x": -12,
      "y": -19,
      "z": 7,
      "name": "Rock_Ice"
    },
    {
      "x": -12,
      "y": -18,
      "z": 7,
      "name": "Rock_Ice"
    },
    {
      "x": -12,
      "y": -17,
      "z": 7,
      "name": "Rock_Ice"
    },
    {
      "x": -12,
      "y": -16,
      "z": 7,
      "name": "Rock_Ice"
    },
    {
      "x": -12,
      "y": -22,
      "z": 8,
      "name": "Rock_Ice"
    },
    {
      "x": -12,
      "y": -21,
      "z": 8,
      "name": "Rock_Ice"
    },
    {
      "x": -12,
      "y": -20,
      "z": 8,
      "name": "Rock_Ice"
    },
    {
      "x": -12,
      "y": -19,
      "z": 8,
      "name": "Rock_Ice"
    },
    {
      "x": -12,
      "y": -18,
      "z": 8,
      "name": "Rock_Ice"
    },
    {
      "x": -12,
      "y": -17,
      "z": 8,
      "name": "Rock_Ice"
    },
    {
      "x": -12,
      "y": -19,
      "z": 9,
      "name": "Rock_Ice"
    },
    {
      "x": -12,
      "y": -18,
      "z": 9,
      "name": "Rock_Ice"
    },
    {
      "x": -11,
      "y": -22,
      "z": 1,
      "name": "Rock_Ice"
    },
    {
      "x": -11,
      "y": -20,
      "z": 1,
      "name": "Rock_Ice"
    },
    {
      "x": -11,
      "y": -19,
      "z": 1,
      "name": "Rock_Ice"
    },
    {
      "x": -11,
      "y": -18,
      "z": 1,
      "name": "Rock_Ice"
    },
    {
      "x": -11,
      "y": -17,
      "z": 1,
      "name": "Rock_Ice"
    },
    {
      "x": -11,
      "y": -31,
      "z": 2,
      "name": "Rock_Ice"
    },
    {
      "x": -11,
      "y": -30,
      "z": 2,
      "name": "Rock_Ice"
    },
    {
      "x": -11,
      "y": -29,
      "z": 2,
      "name": "Rock_Ice"
    },
    {
      "x": -11,
      "y": -28,
      "z": 2,
      "name": "Rock_Ice"
    },
    {
      "x": -11,
      "y": -24,
      "z": 2,
      "name": "Rock_Ice"
    },
    {
      "x": -11,
      "y": -23,
      "z": 2,
      "name": "Rock_Ice"
    },
    {
      "x": -11,
      "y": -22,
      "z": 2,
      "name": "Rock_Ice"
    },
    {
      "x": -11,
      "y": -21,
      "z": 2,
      "name": "Rock_Ice"
    },
    {
      "x": -11,
      "y": -20,
      "z": 2,
      "name": "Rock_Ice"
    },
    {
      "x": -11,
      "y": -19,
      "z": 2,
      "name": "Rock_Ice"
    },
    {
      "x": -11,
      "y": -18,
      "z": 2,
      "name": "Rock_Ice"
    },
    {
      "x": -11,
      "y": -17,
      "z": 2,
      "name": "Rock_Ice"
    },
    {
      "x": -11,
      "y": -16,
      "z": 2,
      "name": "Rock_Ice"
    },
    {
      "x": -11,
      "y": -15,
      "z": 2,
      "name": "Rock_Ice"
    },
    {
      "x": -11,
      "y": -14,
      "z": 2,
      "name": "Rock_Ice"
    },
    {
      "x": -11,
      "y": -36,
      "z": 3,
      "name": "Rock_Ice"
    },
    {
      "x": -11,
      "y": -35,
      "z": 3,
      "name": "Rock_Ice"
    },
    {
      "x": -11,
      "y": -34,
      "z": 3,
      "name": "Rock_Ice"
    },
    {
      "x": -11,
      "y": -33,
      "z": 3,
      "name": "Rock_Ice"
    },
    {
      "x": -11,
      "y": -32,
      "z": 3,
      "name": "Rock_Ice"
    },
    {
      "x": -11,
      "y": -31,
      "z": 3,
      "name": "Rock_Ice"
    },
    {
      "x": -11,
      "y": -30,
      "z": 3,
      "name": "Rock_Ice"
    },
    {
      "x": -11,
      "y": -29,
      "z": 3,
      "name": "Rock_Ice"
    },
    {
      "x": -11,
      "y": -28,
      "z": 3,
      "name": "Rock_Ice"
    },
    {
      "x": -11,
      "y": -27,
      "z": 3,
      "name": "Rock_Ice"
    },
    {
      "x": -11,
      "y": -26,
      "z": 3,
      "name": "Rock_Ice"
    },
    {
      "x": -11,
      "y": -25,
      "z": 3,
      "name": "Rock_Ice"
    },
    {
      "x": -11,
      "y": -24,
      "z": 3,
      "name": "Rock_Ice"
    },
    {
      "x": -11,
      "y": -23,
      "z": 3,
      "name": "Rock_Ice"
    },
    {
      "x": -11,
      "y": -22,
      "z": 3,
      "name": "Rock_Ice"
    },
    {
      "x": -11,
      "y": -21,
      "z": 3,
      "name": "Rock_Ice"
    },
    {
      "x": -11,
      "y": -20,
      "z": 3,
      "name": "Rock_Ice"
    },
    {
      "x": -11,
      "y": -19,
      "z": 3,
      "name": "Rock_Ice"
    },
    {
      "x": -11,
      "y": -18,
      "z": 3,
      "name": "Rock_Ice"
    },
    {
      "x": -11,
      "y": -17,
      "z": 3,
      "name": "Rock_Ice"
    },
    {
      "x": -11,
      "y": -16,
      "z": 3,
      "name": "Rock_Ice"
    },
    {
      "x": -11,
      "y": -15,
      "z": 3,
      "name": "Rock_Ice"
    },
    {
      "x": -11,
      "y": -14,
      "z": 3,
      "name": "Rock_Ice"
    },
    {
      "x": -11,
      "y": -36,
      "z": 4,
      "name": "Rock_Ice"
    },
    {
      "x": -11,
      "y": -35,
      "z": 4,
      "name": "Rock_Ice"
    },
    {
      "x": -11,
      "y": -34,
      "z": 4,
      "name": "Rock_Ice"
    },
    {
      "x": -11,
      "y": -33,
      "z": 4,
      "name": "Rock_Ice"
    },
    {
      "x": -11,
      "y": -32,
      "z": 4,
      "name": "Rock_Ice"
    },
    {
      "x": -11,
      "y": -31,
      "z": 4,
      "name": "Rock_Ice"
    },
    {
      "x": -11,
      "y": -30,
      "z": 4,
      "name": "Rock_Ice"
    },
    {
      "x": -11,
      "y": -29,
      "z": 4,
      "name": "Rock_Ice"
    },
    {
      "x": -11,
      "y": -28,
      "z": 4,
      "name": "Rock_Ice"
    },
    {
      "x": -11,
      "y": -27,
      "z": 4,
      "name": "Rock_Ice"
    },
    {
      "x": -11,
      "y": -26,
      "z": 4,
      "name": "Rock_Ice"
    },
    {
      "x": -11,
      "y": -25,
      "z": 4,
      "name": "Rock_Ice"
    },
    {
      "x": -11,
      "y": -24,
      "z": 4,
      "name": "Rock_Ice"
    },
    {
      "x": -11,
      "y": -23,
      "z": 4,
      "name": "Rock_Ice"
    },
    {
      "x": -11,
      "y": -22,
      "z": 4,
      "name": "Rock_Ice"
    },
    {
      "x": -11,
      "y": -21,
      "z": 4,
      "name": "Rock_Ice"
    },
    {
      "x": -11,
      "y": -20,
      "z": 4,
      "name": "Rock_Ice"
    },
    {
      "x": -11,
      "y": -19,
      "z": 4,
      "name": "Rock_Ice"
    },
    {
      "x": -11,
      "y": -18,
      "z": 4,
      "name": "Rock_Ice"
    },
    {
      "x": -11,
      "y": -17,
      "z": 4,
      "name": "Rock_Ice"
    },
    {
      "x": -11,
      "y": -16,
      "z": 4,
      "name": "Rock_Ice"
    },
    {
      "x": -11,
      "y": -15,
      "z": 4,
      "name": "Rock_Ice"
    },
    {
      "x": -11,
      "y": -33,
      "z": 5,
      "name": "Rock_Ice"
    },
    {
      "x": -11,
      "y": -32,
      "z": 5,
      "name": "Rock_Ice"
    },
    {
      "x": -11,
      "y": -31,
      "z": 5,
      "name": "Rock_Ice"
    },
    {
      "x": -11,
      "y": -30,
      "z": 5,
      "name": "Rock_Ice"
    },
    {
      "x": -11,
      "y": -29,
      "z": 5,
      "name": "Rock_Ice"
    },
    {
      "x": -11,
      "y": -28,
      "z": 5,
      "name": "Rock_Ice"
    },
    {
      "x": -11,
      "y": -27,
      "z": 5,
      "name": "Rock_Ice"
    },
    {
      "x": -11,
      "y": -26,
      "z": 5,
      "name": "Rock_Ice"
    },
    {
      "x": -11,
      "y": -25,
      "z": 5,
      "name": "Rock_Ice"
    },
    {
      "x": -11,
      "y": -24,
      "z": 5,
      "name": "Rock_Ice"
    },
    {
      "x": -11,
      "y": -23,
      "z": 5,
      "name": "Rock_Ice"
    },
    {
      "x": -11,
      "y": -22,
      "z": 5,
      "name": "Rock_Ice"
    },
    {
      "x": -11,
      "y": -21,
      "z": 5,
      "name": "Rock_Ice"
    },
    {
      "x": -11,
      "y": -20,
      "z": 5,
      "name": "Rock_Ice"
    },
    {
      "x": -11,
      "y": -19,
      "z": 5,
      "name": "Rock_Ice"
    },
    {
      "x": -11,
      "y": -18,
      "z": 5,
      "name": "Rock_Ice"
    },
    {
      "x": -11,
      "y": -17,
      "z": 5,
      "name": "Rock_Ice"
    },
    {
      "x": -11,
      "y": -16,
      "z": 5,
      "name": "Rock_Ice"
    },
    {
      "x": -11,
      "y": -15,
      "z": 5,
      "name": "Rock_Ice"
    },
    {
      "x": -11,
      "y": -14,
      "z": 5,
      "name": "Rock_Ice"
    },
    {
      "x": -11,
      "y": -28,
      "z": 6,
      "name": "Rock_Ice"
    },
    {
      "x": -11,
      "y": -27,
      "z": 6,
      "name": "Rock_Ice"
    },
    {
      "x": -11,
      "y": -26,
      "z": 6,
      "name": "Rock_Ice"
    },
    {
      "x": -11,
      "y": -25,
      "z": 6,
      "name": "Rock_Ice"
    },
    {
      "x": -11,
      "y": -24,
      "z": 6,
      "name": "Rock_Ice"
    },
    {
      "x": -11,
      "y": -23,
      "z": 6,
      "name": "Rock_Ice"
    },
    {
      "x": -11,
      "y": -22,
      "z": 6,
      "name": "Rock_Ice"
    },
    {
      "x": -11,
      "y": -21,
      "z": 6,
      "name": "Rock_Ice"
    },
    {
      "x": -11,
      "y": -20,
      "z": 6,
      "name": "Rock_Ice"
    },
    {
      "x": -11,
      "y": -19,
      "z": 6,
      "name": "Rock_Ice"
    },
    {
      "x": -11,
      "y": -18,
      "z": 6,
      "name": "Rock_Ice"
    },
    {
      "x": -11,
      "y": -17,
      "z": 6,
      "name": "Rock_Ice"
    },
    {
      "x": -11,
      "y": -16,
      "z": 6,
      "name": "Rock_Ice"
    },
    {
      "x": -11,
      "y": -28,
      "z": 7,
      "name": "Rock_Ice"
    },
    {
      "x": -11,
      "y": -27,
      "z": 7,
      "name": "Rock_Ice"
    },
    {
      "x": -11,
      "y": -26,
      "z": 7,
      "name": "Rock_Ice"
    },
    {
      "x": -11,
      "y": -25,
      "z": 7,
      "name": "Rock_Ice"
    },
    {
      "x": -11,
      "y": -24,
      "z": 7,
      "name": "Rock_Ice"
    },
    {
      "x": -11,
      "y": -23,
      "z": 7,
      "name": "Rock_Ice"
    },
    {
      "x": -11,
      "y": -22,
      "z": 7,
      "name": "Rock_Ice"
    },
    {
      "x": -11,
      "y": -21,
      "z": 7,
      "name": "Rock_Ice"
    },
    {
      "x": -11,
      "y": -20,
      "z": 7,
      "name": "Rock_Ice"
    },
    {
      "x": -11,
      "y": -19,
      "z": 7,
      "name": "Rock_Ice"
    },
    {
      "x": -11,
      "y": -18,
      "z": 7,
      "name": "Rock_Ice"
    },
    {
      "x": -11,
      "y": -17,
      "z": 7,
      "name": "Rock_Ice"
    },
    {
      "x": -11,
      "y": -16,
      "z": 7,
      "name": "Rock_Ice"
    },
    {
      "x": -11,
      "y": -15,
      "z": 7,
      "name": "Rock_Ice"
    },
    {
      "x": -11,
      "y": -22,
      "z": 8,
      "name": "Rock_Ice"
    },
    {
      "x": -11,
      "y": -21,
      "z": 8,
      "name": "Rock_Ice"
    },
    {
      "x": -11,
      "y": -20,
      "z": 8,
      "name": "Rock_Ice"
    },
    {
      "x": -11,
      "y": -19,
      "z": 8,
      "name": "Rock_Ice"
    },
    {
      "x": -11,
      "y": -18,
      "z": 8,
      "name": "Rock_Ice"
    },
    {
      "x": -11,
      "y": -17,
      "z": 8,
      "name": "Rock_Ice"
    },
    {
      "x": -11,
      "y": -16,
      "z": 8,
      "name": "Rock_Ice"
    },
    {
      "x": -11,
      "y": -17,
      "z": 9,
      "name": "Rock_Ice"
    },
    {
      "x": -11,
      "y": -16,
      "z": 9,
      "name": "Rock_Ice"
    },
    {
      "x": -10,
      "y": -20,
      "z": -1,
      "name": "Rock_Ice"
    },
    {
      "x": -10,
      "y": -19,
      "z": -1,
      "name": "Rock_Ice"
    },
    {
      "x": -10,
      "y": -20,
      "z": 0,
      "name": "Rock_Ice"
    },
    {
      "x": -10,
      "y": -19,
      "z": 0,
      "name": "Rock_Ice"
    },
    {
      "x": -10,
      "y": -22,
      "z": 1,
      "name": "Rock_Ice"
    },
    {
      "x": -10,
      "y": -20,
      "z": 1,
      "name": "Rock_Ice"
    },
    {
      "x": -10,
      "y": -19,
      "z": 1,
      "name": "Rock_Ice"
    },
    {
      "x": -10,
      "y": -18,
      "z": 1,
      "name": "Rock_Ice"
    },
    {
      "x": -10,
      "y": -17,
      "z": 1,
      "name": "Rock_Ice"
    },
    {
      "x": -10,
      "y": -29,
      "z": 2,
      "name": "Rock_Ice"
    },
    {
      "x": -10,
      "y": -28,
      "z": 2,
      "name": "Rock_Ice"
    },
    {
      "x": -10,
      "y": -24,
      "z": 2,
      "name": "Rock_Ice"
    },
    {
      "x": -10,
      "y": -23,
      "z": 2,
      "name": "Rock_Ice"
    },
    {
      "x": -10,
      "y": -22,
      "z": 2,
      "name": "Rock_Ice"
    },
    {
      "x": -10,
      "y": -21,
      "z": 2,
      "name": "Rock_Ice"
    },
    {
      "x": -10,
      "y": -20,
      "z": 2,
      "name": "Rock_Ice"
    },
    {
      "x": -10,
      "y": -19,
      "z": 2,
      "name": "Rock_Ice"
    },
    {
      "x": -10,
      "y": -18,
      "z": 2,
      "name": "Rock_Ice"
    },
    {
      "x": -10,
      "y": -17,
      "z": 2,
      "name": "Rock_Ice"
    },
    {
      "x": -10,
      "y": -16,
      "z": 2,
      "name": "Rock_Ice"
    },
    {
      "x": -10,
      "y": -15,
      "z": 2,
      "name": "Rock_Ice"
    },
    {
      "x": -10,
      "y": -14,
      "z": 2,
      "name": "Rock_Ice"
    },
    {
      "x": -10,
      "y": -13,
      "z": 2,
      "name": "Rock_Ice"
    },
    {
      "x": -10,
      "y": -36,
      "z": 3,
      "name": "Rock_Ice"
    },
    {
      "x": -10,
      "y": -35,
      "z": 3,
      "name": "Rock_Ice"
    },
    {
      "x": -10,
      "y": -34,
      "z": 3,
      "name": "Rock_Ice"
    },
    {
      "x": -10,
      "y": -33,
      "z": 3,
      "name": "Rock_Ice"
    },
    {
      "x": -10,
      "y": -32,
      "z": 3,
      "name": "Rock_Ice"
    },
    {
      "x": -10,
      "y": -31,
      "z": 3,
      "name": "Rock_Ice"
    },
    {
      "x": -10,
      "y": -30,
      "z": 3,
      "name": "Rock_Ice"
    },
    {
      "x": -10,
      "y": -29,
      "z": 3,
      "name": "Rock_Ice"
    },
    {
      "x": -10,
      "y": -28,
      "z": 3,
      "name": "Rock_Ice"
    },
    {
      "x": -10,
      "y": -27,
      "z": 3,
      "name": "Rock_Ice"
    },
    {
      "x": -10,
      "y": -26,
      "z": 3,
      "name": "Rock_Ice"
    },
    {
      "x": -10,
      "y": -25,
      "z": 3,
      "name": "Rock_Ice"
    },
    {
      "x": -10,
      "y": -24,
      "z": 3,
      "name": "Rock_Ice"
    },
    {
      "x": -10,
      "y": -23,
      "z": 3,
      "name": "Rock_Ice"
    },
    {
      "x": -10,
      "y": -22,
      "z": 3,
      "name": "Rock_Ice"
    },
    {
      "x": -10,
      "y": -21,
      "z": 3,
      "name": "Rock_Ice"
    },
    {
      "x": -10,
      "y": -20,
      "z": 3,
      "name": "Rock_Ice"
    },
    {
      "x": -10,
      "y": -19,
      "z": 3,
      "name": "Rock_Ice"
    },
    {
      "x": -10,
      "y": -18,
      "z": 3,
      "name": "Rock_Ice"
    },
    {
      "x": -10,
      "y": -17,
      "z": 3,
      "name": "Rock_Ice"
    },
    {
      "x": -10,
      "y": -16,
      "z": 3,
      "name": "Rock_Ice"
    },
    {
      "x": -10,
      "y": -15,
      "z": 3,
      "name": "Rock_Ice"
    },
    {
      "x": -10,
      "y": -14,
      "z": 3,
      "name": "Rock_Ice"
    },
    {
      "x": -10,
      "y": -13,
      "z": 3,
      "name": "Rock_Ice"
    },
    {
      "x": -10,
      "y": -36,
      "z": 4,
      "name": "Rock_Ice"
    },
    {
      "x": -10,
      "y": -35,
      "z": 4,
      "name": "Rock_Ice"
    },
    {
      "x": -10,
      "y": -34,
      "z": 4,
      "name": "Rock_Ice"
    },
    {
      "x": -10,
      "y": -33,
      "z": 4,
      "name": "Rock_Ice"
    },
    {
      "x": -10,
      "y": -32,
      "z": 4,
      "name": "Rock_Ice"
    },
    {
      "x": -10,
      "y": -31,
      "z": 4,
      "name": "Rock_Ice"
    },
    {
      "x": -10,
      "y": -30,
      "z": 4,
      "name": "Rock_Ice"
    },
    {
      "x": -10,
      "y": -29,
      "z": 4,
      "name": "Rock_Ice"
    },
    {
      "x": -10,
      "y": -28,
      "z": 4,
      "name": "Rock_Ice"
    },
    {
      "x": -10,
      "y": -27,
      "z": 4,
      "name": "Rock_Ice"
    },
    {
      "x": -10,
      "y": -26,
      "z": 4,
      "name": "Rock_Ice"
    },
    {
      "x": -10,
      "y": -25,
      "z": 4,
      "name": "Rock_Ice"
    },
    {
      "x": -10,
      "y": -24,
      "z": 4,
      "name": "Rock_Ice"
    },
    {
      "x": -10,
      "y": -23,
      "z": 4,
      "name": "Rock_Ice"
    },
    {
      "x": -10,
      "y": -22,
      "z": 4,
      "name": "Rock_Ice"
    },
    {
      "x": -10,
      "y": -21,
      "z": 4,
      "name": "Rock_Ice"
    },
    {
      "x": -10,
      "y": -20,
      "z": 4,
      "name": "Rock_Ice"
    },
    {
      "x": -10,
      "y": -19,
      "z": 4,
      "name": "Rock_Ice"
    },
    {
      "x": -10,
      "y": -18,
      "z": 4,
      "name": "Rock_Ice"
    },
    {
      "x": -10,
      "y": -17,
      "z": 4,
      "name": "Rock_Ice"
    },
    {
      "x": -10,
      "y": -16,
      "z": 4,
      "name": "Rock_Ice"
    },
    {
      "x": -10,
      "y": -15,
      "z": 4,
      "name": "Rock_Ice"
    },
    {
      "x": -10,
      "y": -14,
      "z": 4,
      "name": "Rock_Ice"
    },
    {
      "x": -10,
      "y": -27,
      "z": 5,
      "name": "Rock_Ice"
    },
    {
      "x": -10,
      "y": -26,
      "z": 5,
      "name": "Rock_Ice"
    },
    {
      "x": -10,
      "y": -25,
      "z": 5,
      "name": "Rock_Ice"
    },
    {
      "x": -10,
      "y": -24,
      "z": 5,
      "name": "Rock_Ice"
    },
    {
      "x": -10,
      "y": -23,
      "z": 5,
      "name": "Rock_Ice"
    },
    {
      "x": -10,
      "y": -22,
      "z": 5,
      "name": "Rock_Ice"
    },
    {
      "x": -10,
      "y": -21,
      "z": 5,
      "name": "Rock_Ice"
    },
    {
      "x": -10,
      "y": -20,
      "z": 5,
      "name": "Rock_Ice"
    },
    {
      "x": -10,
      "y": -19,
      "z": 5,
      "name": "Rock_Ice"
    },
    {
      "x": -10,
      "y": -18,
      "z": 5,
      "name": "Rock_Ice"
    },
    {
      "x": -10,
      "y": -17,
      "z": 5,
      "name": "Rock_Ice"
    },
    {
      "x": -10,
      "y": -16,
      "z": 5,
      "name": "Rock_Ice"
    },
    {
      "x": -10,
      "y": -15,
      "z": 5,
      "name": "Rock_Ice"
    },
    {
      "x": -10,
      "y": -14,
      "z": 5,
      "name": "Rock_Ice"
    },
    {
      "x": -10,
      "y": -13,
      "z": 5,
      "name": "Rock_Ice"
    },
    {
      "x": -10,
      "y": -27,
      "z": 6,
      "name": "Rock_Ice"
    },
    {
      "x": -10,
      "y": -26,
      "z": 6,
      "name": "Rock_Ice"
    },
    {
      "x": -10,
      "y": -25,
      "z": 6,
      "name": "Rock_Ice"
    },
    {
      "x": -10,
      "y": -24,
      "z": 6,
      "name": "Rock_Ice"
    },
    {
      "x": -10,
      "y": -23,
      "z": 6,
      "name": "Rock_Ice"
    },
    {
      "x": -10,
      "y": -22,
      "z": 6,
      "name": "Rock_Ice"
    },
    {
      "x": -10,
      "y": -21,
      "z": 6,
      "name": "Rock_Ice"
    },
    {
      "x": -10,
      "y": -20,
      "z": 6,
      "name": "Rock_Ice"
    },
    {
      "x": -10,
      "y": -19,
      "z": 6,
      "name": "Rock_Ice"
    },
    {
      "x": -10,
      "y": -18,
      "z": 6,
      "name": "Rock_Ice"
    },
    {
      "x": -10,
      "y": -17,
      "z": 6,
      "name": "Rock_Ice"
    },
    {
      "x": -10,
      "y": -16,
      "z": 6,
      "name": "Rock_Ice"
    },
    {
      "x": -10,
      "y": -15,
      "z": 6,
      "name": "Rock_Ice"
    },
    {
      "x": -10,
      "y": -23,
      "z": 7,
      "name": "Rock_Ice"
    },
    {
      "x": -10,
      "y": -22,
      "z": 7,
      "name": "Rock_Ice"
    },
    {
      "x": -10,
      "y": -21,
      "z": 7,
      "name": "Rock_Ice"
    },
    {
      "x": -10,
      "y": -20,
      "z": 7,
      "name": "Rock_Ice"
    },
    {
      "x": -10,
      "y": -19,
      "z": 7,
      "name": "Rock_Ice"
    },
    {
      "x": -10,
      "y": -18,
      "z": 7,
      "name": "Rock_Ice"
    },
    {
      "x": -10,
      "y": -17,
      "z": 7,
      "name": "Rock_Ice"
    },
    {
      "x": -10,
      "y": -16,
      "z": 7,
      "name": "Rock_Ice"
    },
    {
      "x": -10,
      "y": -15,
      "z": 7,
      "name": "Rock_Ice"
    },
    {
      "x": -10,
      "y": -22,
      "z": 8,
      "name": "Rock_Ice"
    },
    {
      "x": -10,
      "y": -21,
      "z": 8,
      "name": "Rock_Ice"
    },
    {
      "x": -10,
      "y": -20,
      "z": 8,
      "name": "Rock_Ice"
    },
    {
      "x": -10,
      "y": -19,
      "z": 8,
      "name": "Rock_Ice"
    },
    {
      "x": -10,
      "y": -18,
      "z": 8,
      "name": "Rock_Ice"
    },
    {
      "x": -10,
      "y": -17,
      "z": 8,
      "name": "Rock_Ice"
    },
    {
      "x": -10,
      "y": -16,
      "z": 8,
      "name": "Rock_Ice"
    },
    {
      "x": -10,
      "y": -15,
      "z": 8,
      "name": "Rock_Ice"
    },
    {
      "x": -10,
      "y": -19,
      "z": 9,
      "name": "Rock_Ice"
    },
    {
      "x": -10,
      "y": -18,
      "z": 9,
      "name": "Rock_Ice"
    },
    {
      "x": -10,
      "y": -17,
      "z": 9,
      "name": "Rock_Ice"
    },
    {
      "x": -10,
      "y": -16,
      "z": 9,
      "name": "Rock_Ice"
    },
    {
      "x": -9,
      "y": -18,
      "z": -4,
      "name": "Rock_Ice"
    },
    {
      "x": -9,
      "y": -20,
      "z": -3,
      "name": "Rock_Ice"
    },
    {
      "x": -9,
      "y": -19,
      "z": -3,
      "name": "Rock_Ice"
    },
    {
      "x": -9,
      "y": -18,
      "z": -3,
      "name": "Rock_Ice"
    },
    {
      "x": -9,
      "y": -17,
      "z": -3,
      "name": "Rock_Ice"
    },
    {
      "x": -9,
      "y": -16,
      "z": -3,
      "name": "Rock_Ice"
    },
    {
      "x": -9,
      "y": -20,
      "z": -2,
      "name": "Rock_Ice"
    },
    {
      "x": -9,
      "y": -19,
      "z": -2,
      "name": "Rock_Ice"
    },
    {
      "x": -9,
      "y": -18,
      "z": -2,
      "name": "Rock_Ice"
    },
    {
      "x": -9,
      "y": -17,
      "z": -2,
      "name": "Rock_Ice"
    },
    {
      "x": -9,
      "y": -16,
      "z": -2,
      "name": "Rock_Ice"
    },
    {
      "x": -9,
      "y": -22,
      "z": -1,
      "name": "Rock_Ice"
    },
    {
      "x": -9,
      "y": -21,
      "z": -1,
      "name": "Rock_Ice"
    },
    {
      "x": -9,
      "y": -20,
      "z": -1,
      "name": "Rock_Ice"
    },
    {
      "x": -9,
      "y": -19,
      "z": -1,
      "name": "Rock_Ice"
    },
    {
      "x": -9,
      "y": -18,
      "z": -1,
      "name": "Rock_Ice"
    },
    {
      "x": -9,
      "y": -17,
      "z": -1,
      "name": "Rock_Ice"
    },
    {
      "x": -9,
      "y": -16,
      "z": -1,
      "name": "Rock_Ice"
    },
    {
      "x": -9,
      "y": -15,
      "z": -1,
      "name": "Rock_Ice"
    },
    {
      "x": -9,
      "y": -14,
      "z": -1,
      "name": "Rock_Ice"
    },
    {
      "x": -9,
      "y": -13,
      "z": -1,
      "name": "Rock_Ice"
    },
    {
      "x": -9,
      "y": -12,
      "z": -1,
      "name": "Rock_Ice"
    },
    {
      "x": -9,
      "y": -11,
      "z": -1,
      "name": "Rock_Ice"
    },
    {
      "x": -9,
      "y": -22,
      "z": 0,
      "name": "Rock_Ice"
    },
    {
      "x": -9,
      "y": -20,
      "z": 0,
      "name": "Rock_Ice"
    },
    {
      "x": -9,
      "y": -19,
      "z": 0,
      "name": "Rock_Ice"
    },
    {
      "x": -9,
      "y": -18,
      "z": 0,
      "name": "Rock_Ice"
    },
    {
      "x": -9,
      "y": -17,
      "z": 0,
      "name": "Rock_Ice"
    },
    {
      "x": -9,
      "y": -16,
      "z": 0,
      "name": "Rock_Ice"
    },
    {
      "x": -9,
      "y": -28,
      "z": 1,
      "name": "Rock_Ice"
    },
    {
      "x": -9,
      "y": -24,
      "z": 1,
      "name": "Rock_Ice"
    },
    {
      "x": -9,
      "y": -23,
      "z": 1,
      "name": "Rock_Ice"
    },
    {
      "x": -9,
      "y": -22,
      "z": 1,
      "name": "Rock_Ice"
    },
    {
      "x": -9,
      "y": -21,
      "z": 1,
      "name": "Rock_Ice"
    },
    {
      "x": -9,
      "y": -20,
      "z": 1,
      "name": "Rock_Ice"
    },
    {
      "x": -9,
      "y": -19,
      "z": 1,
      "name": "Rock_Ice"
    },
    {
      "x": -9,
      "y": -18,
      "z": 1,
      "name": "Rock_Ice"
    },
    {
      "x": -9,
      "y": -17,
      "z": 1,
      "name": "Rock_Ice"
    },
    {
      "x": -9,
      "y": -16,
      "z": 1,
      "name": "Rock_Ice"
    },
    {
      "x": -9,
      "y": -15,
      "z": 1,
      "name": "Rock_Ice"
    },
    {
      "x": -9,
      "y": -14,
      "z": 1,
      "name": "Rock_Ice"
    },
    {
      "x": -9,
      "y": -13,
      "z": 1,
      "name": "Rock_Ice"
    },
    {
      "x": -9,
      "y": -12,
      "z": 1,
      "name": "Rock_Ice"
    },
    {
      "x": -9,
      "y": -30,
      "z": 2,
      "name": "Rock_Ice"
    },
    {
      "x": -9,
      "y": -29,
      "z": 2,
      "name": "Rock_Ice"
    },
    {
      "x": -9,
      "y": -28,
      "z": 2,
      "name": "Rock_Ice"
    },
    {
      "x": -9,
      "y": -27,
      "z": 2,
      "name": "Rock_Ice"
    },
    {
      "x": -9,
      "y": -26,
      "z": 2,
      "name": "Rock_Ice"
    },
    {
      "x": -9,
      "y": -25,
      "z": 2,
      "name": "Rock_Ice"
    },
    {
      "x": -9,
      "y": -24,
      "z": 2,
      "name": "Rock_Ice"
    },
    {
      "x": -9,
      "y": -23,
      "z": 2,
      "name": "Rock_Ice"
    },
    {
      "x": -9,
      "y": -22,
      "z": 2,
      "name": "Rock_Ice"
    },
    {
      "x": -9,
      "y": -21,
      "z": 2,
      "name": "Rock_Ice"
    },
    {
      "x": -9,
      "y": -20,
      "z": 2,
      "name": "Rock_Ice"
    },
    {
      "x": -9,
      "y": -19,
      "z": 2,
      "name": "Rock_Ice"
    },
    {
      "x": -9,
      "y": -18,
      "z": 2,
      "name": "Rock_Ice"
    },
    {
      "x": -9,
      "y": -17,
      "z": 2,
      "name": "Rock_Ice"
    },
    {
      "x": -9,
      "y": -16,
      "z": 2,
      "name": "Rock_Ice"
    },
    {
      "x": -9,
      "y": -15,
      "z": 2,
      "name": "Rock_Ice"
    },
    {
      "x": -9,
      "y": -14,
      "z": 2,
      "name": "Rock_Ice"
    },
    {
      "x": -9,
      "y": -13,
      "z": 2,
      "name": "Rock_Ice"
    },
    {
      "x": -9,
      "y": -12,
      "z": 2,
      "name": "Rock_Ice"
    },
    {
      "x": -9,
      "y": -11,
      "z": 2,
      "name": "Rock_Ice"
    },
    {
      "x": -9,
      "y": -36,
      "z": 3,
      "name": "Rock_Ice"
    },
    {
      "x": -9,
      "y": -35,
      "z": 3,
      "name": "Rock_Ice"
    },
    {
      "x": -9,
      "y": -34,
      "z": 3,
      "name": "Rock_Ice"
    },
    {
      "x": -9,
      "y": -31,
      "z": 3,
      "name": "Rock_Ice"
    },
    {
      "x": -9,
      "y": -30,
      "z": 3,
      "name": "Rock_Ice"
    },
    {
      "x": -9,
      "y": -29,
      "z": 3,
      "name": "Rock_Ice"
    },
    {
      "x": -9,
      "y": -28,
      "z": 3,
      "name": "Rock_Ice"
    },
    {
      "x": -9,
      "y": -27,
      "z": 3,
      "name": "Rock_Ice"
    },
    {
      "x": -9,
      "y": -26,
      "z": 3,
      "name": "Rock_Ice"
    },
    {
      "x": -9,
      "y": -25,
      "z": 3,
      "name": "Rock_Ice"
    },
    {
      "x": -9,
      "y": -24,
      "z": 3,
      "name": "Rock_Ice"
    },
    {
      "x": -9,
      "y": -23,
      "z": 3,
      "name": "Rock_Ice"
    },
    {
      "x": -9,
      "y": -22,
      "z": 3,
      "name": "Rock_Ice"
    },
    {
      "x": -9,
      "y": -21,
      "z": 3,
      "name": "Rock_Ice"
    },
    {
      "x": -9,
      "y": -20,
      "z": 3,
      "name": "Rock_Ice"
    },
    {
      "x": -9,
      "y": -19,
      "z": 3,
      "name": "Rock_Ice"
    },
    {
      "x": -9,
      "y": -18,
      "z": 3,
      "name": "Rock_Ice"
    },
    {
      "x": -9,
      "y": -17,
      "z": 3,
      "name": "Rock_Ice"
    },
    {
      "x": -9,
      "y": -16,
      "z": 3,
      "name": "Rock_Ice"
    },
    {
      "x": -9,
      "y": -15,
      "z": 3,
      "name": "Rock_Ice"
    },
    {
      "x": -9,
      "y": -14,
      "z": 3,
      "name": "Rock_Ice"
    },
    {
      "x": -9,
      "y": -13,
      "z": 3,
      "name": "Rock_Ice"
    },
    {
      "x": -9,
      "y": -12,
      "z": 3,
      "name": "Rock_Ice"
    },
    {
      "x": -9,
      "y": -36,
      "z": 4,
      "name": "Rock_Ice"
    },
    {
      "x": -9,
      "y": -33,
      "z": 4,
      "name": "Rock_Ice"
    },
    {
      "x": -9,
      "y": -32,
      "z": 4,
      "name": "Rock_Ice"
    },
    {
      "x": -9,
      "y": -31,
      "z": 4,
      "name": "Rock_Ice"
    },
    {
      "x": -9,
      "y": -30,
      "z": 4,
      "name": "Rock_Ice"
    },
    {
      "x": -9,
      "y": -29,
      "z": 4,
      "name": "Rock_Ice"
    },
    {
      "x": -9,
      "y": -28,
      "z": 4,
      "name": "Rock_Ice"
    },
    {
      "x": -9,
      "y": -27,
      "z": 4,
      "name": "Rock_Ice"
    },
    {
      "x": -9,
      "y": -26,
      "z": 4,
      "name": "Rock_Ice"
    },
    {
      "x": -9,
      "y": -25,
      "z": 4,
      "name": "Rock_Ice"
    },
    {
      "x": -9,
      "y": -24,
      "z": 4,
      "name": "Rock_Ice"
    },
    {
      "x": -9,
      "y": -23,
      "z": 4,
      "name": "Rock_Ice"
    },
    {
      "x": -9,
      "y": -22,
      "z": 4,
      "name": "Rock_Ice"
    },
    {
      "x": -9,
      "y": -21,
      "z": 4,
      "name": "Rock_Ice"
    },
    {
      "x": -9,
      "y": -20,
      "z": 4,
      "name": "Rock_Ice"
    },
    {
      "x": -9,
      "y": -19,
      "z": 4,
      "name": "Rock_Ice"
    },
    {
      "x": -9,
      "y": -18,
      "z": 4,
      "name": "Rock_Ice"
    },
    {
      "x": -9,
      "y": -17,
      "z": 4,
      "name": "Rock_Ice"
    },
    {
      "x": -9,
      "y": -16,
      "z": 4,
      "name": "Rock_Ice"
    },
    {
      "x": -9,
      "y": -15,
      "z": 4,
      "name": "Rock_Ice"
    },
    {
      "x": -9,
      "y": -14,
      "z": 4,
      "name": "Rock_Ice"
    },
    {
      "x": -9,
      "y": -13,
      "z": 4,
      "name": "Rock_Ice"
    },
    {
      "x": -9,
      "y": -12,
      "z": 4,
      "name": "Rock_Ice"
    },
    {
      "x": -9,
      "y": -11,
      "z": 4,
      "name": "Rock_Ice"
    },
    {
      "x": -9,
      "y": -27,
      "z": 5,
      "name": "Rock_Ice"
    },
    {
      "x": -9,
      "y": -26,
      "z": 5,
      "name": "Rock_Ice"
    },
    {
      "x": -9,
      "y": -25,
      "z": 5,
      "name": "Rock_Ice"
    },
    {
      "x": -9,
      "y": -24,
      "z": 5,
      "name": "Rock_Ice"
    },
    {
      "x": -9,
      "y": -23,
      "z": 5,
      "name": "Rock_Ice"
    },
    {
      "x": -9,
      "y": -22,
      "z": 5,
      "name": "Rock_Ice"
    },
    {
      "x": -9,
      "y": -21,
      "z": 5,
      "name": "Rock_Ice"
    },
    {
      "x": -9,
      "y": -20,
      "z": 5,
      "name": "Rock_Ice"
    },
    {
      "x": -9,
      "y": -19,
      "z": 5,
      "name": "Rock_Ice"
    },
    {
      "x": -9,
      "y": -18,
      "z": 5,
      "name": "Rock_Ice"
    },
    {
      "x": -9,
      "y": -17,
      "z": 5,
      "name": "Rock_Ice"
    },
    {
      "x": -9,
      "y": -16,
      "z": 5,
      "name": "Rock_Ice"
    },
    {
      "x": -9,
      "y": -15,
      "z": 5,
      "name": "Rock_Ice"
    },
    {
      "x": -9,
      "y": -14,
      "z": 5,
      "name": "Rock_Ice"
    },
    {
      "x": -9,
      "y": -13,
      "z": 5,
      "name": "Rock_Ice"
    },
    {
      "x": -9,
      "y": -23,
      "z": 6,
      "name": "Rock_Ice"
    },
    {
      "x": -9,
      "y": -22,
      "z": 6,
      "name": "Rock_Ice"
    },
    {
      "x": -9,
      "y": -21,
      "z": 6,
      "name": "Rock_Ice"
    },
    {
      "x": -9,
      "y": -20,
      "z": 6,
      "name": "Rock_Ice"
    },
    {
      "x": -9,
      "y": -19,
      "z": 6,
      "name": "Rock_Ice"
    },
    {
      "x": -9,
      "y": -18,
      "z": 6,
      "name": "Rock_Ice"
    },
    {
      "x": -9,
      "y": -17,
      "z": 6,
      "name": "Rock_Ice"
    },
    {
      "x": -9,
      "y": -16,
      "z": 6,
      "name": "Rock_Ice"
    },
    {
      "x": -9,
      "y": -15,
      "z": 6,
      "name": "Rock_Ice"
    },
    {
      "x": -9,
      "y": -14,
      "z": 6,
      "name": "Rock_Ice"
    },
    {
      "x": -9,
      "y": -22,
      "z": 7,
      "name": "Rock_Ice"
    },
    {
      "x": -9,
      "y": -21,
      "z": 7,
      "name": "Rock_Ice"
    },
    {
      "x": -9,
      "y": -20,
      "z": 7,
      "name": "Rock_Ice"
    },
    {
      "x": -9,
      "y": -19,
      "z": 7,
      "name": "Rock_Ice"
    },
    {
      "x": -9,
      "y": -18,
      "z": 7,
      "name": "Rock_Ice"
    },
    {
      "x": -9,
      "y": -17,
      "z": 7,
      "name": "Rock_Ice"
    },
    {
      "x": -9,
      "y": -16,
      "z": 7,
      "name": "Rock_Ice"
    },
    {
      "x": -9,
      "y": -15,
      "z": 7,
      "name": "Rock_Ice"
    },
    {
      "x": -9,
      "y": -14,
      "z": 7,
      "name": "Rock_Ice"
    },
    {
      "x": -9,
      "y": -18,
      "z": 8,
      "name": "Rock_Ice"
    },
    {
      "x": -9,
      "y": -17,
      "z": 8,
      "name": "Rock_Ice"
    },
    {
      "x": -9,
      "y": -16,
      "z": 8,
      "name": "Rock_Ice"
    },
    {
      "x": -9,
      "y": -15,
      "z": 8,
      "name": "Rock_Ice"
    },
    {
      "x": -9,
      "y": -17,
      "z": 9,
      "name": "Rock_Ice"
    },
    {
      "x": -9,
      "y": -16,
      "z": 9,
      "name": "Rock_Ice"
    },
    {
      "x": -9,
      "y": -15,
      "z": 9,
      "name": "Rock_Ice"
    },
    {
      "x": -8,
      "y": -16,
      "z": -4,
      "name": "Rock_Ice"
    },
    {
      "x": -8,
      "y": -19,
      "z": -3,
      "name": "Rock_Ice"
    },
    {
      "x": -8,
      "y": -18,
      "z": -3,
      "name": "Rock_Ice"
    },
    {
      "x": -8,
      "y": -17,
      "z": -3,
      "name": "Rock_Ice"
    },
    {
      "x": -8,
      "y": -16,
      "z": -3,
      "name": "Rock_Ice"
    },
    {
      "x": -8,
      "y": -15,
      "z": -3,
      "name": "Rock_Ice"
    },
    {
      "x": -8,
      "y": -14,
      "z": -3,
      "name": "Rock_Ice"
    },
    {
      "x": -8,
      "y": -13,
      "z": -3,
      "name": "Rock_Ice"
    },
    {
      "x": -8,
      "y": -12,
      "z": -3,
      "name": "Rock_Ice"
    },
    {
      "x": -8,
      "y": -11,
      "z": -3,
      "name": "Rock_Ice"
    },
    {
      "x": -8,
      "y": -10,
      "z": -3,
      "name": "Rock_Ice"
    },
    {
      "x": -8,
      "y": -22,
      "z": -2,
      "name": "Rock_Ice"
    },
    {
      "x": -8,
      "y": -21,
      "z": -2,
      "name": "Rock_Ice"
    },
    {
      "x": -8,
      "y": -20,
      "z": -2,
      "name": "Rock_Ice"
    },
    {
      "x": -8,
      "y": -19,
      "z": -2,
      "name": "Rock_Ice"
    },
    {
      "x": -8,
      "y": -18,
      "z": -2,
      "name": "Rock_Ice"
    },
    {
      "x": -8,
      "y": -17,
      "z": -2,
      "name": "Rock_Ice"
    },
    {
      "x": -8,
      "y": -16,
      "z": -2,
      "name": "Rock_Ice"
    },
    {
      "x": -8,
      "y": -15,
      "z": -2,
      "name": "Rock_Ice"
    },
    {
      "x": -8,
      "y": -14,
      "z": -2,
      "name": "Rock_Ice"
    },
    {
      "x": -8,
      "y": -13,
      "z": -2,
      "name": "Rock_Ice"
    },
    {
      "x": -8,
      "y": -12,
      "z": -2,
      "name": "Rock_Ice"
    },
    {
      "x": -8,
      "y": -11,
      "z": -2,
      "name": "Rock_Ice"
    },
    {
      "x": -8,
      "y": -10,
      "z": -2,
      "name": "Rock_Ice"
    },
    {
      "x": -8,
      "y": -25,
      "z": -1,
      "name": "Rock_Ice"
    },
    {
      "x": -8,
      "y": -24,
      "z": -1,
      "name": "Rock_Ice"
    },
    {
      "x": -8,
      "y": -23,
      "z": -1,
      "name": "Rock_Ice"
    },
    {
      "x": -8,
      "y": -22,
      "z": -1,
      "name": "Rock_Ice"
    },
    {
      "x": -8,
      "y": -21,
      "z": -1,
      "name": "Rock_Ice"
    },
    {
      "x": -8,
      "y": -20,
      "z": -1,
      "name": "Rock_Ice"
    },
    {
      "x": -8,
      "y": -19,
      "z": -1,
      "name": "Rock_Ice"
    },
    {
      "x": -8,
      "y": -18,
      "z": -1,
      "name": "Rock_Ice"
    },
    {
      "x": -8,
      "y": -17,
      "z": -1,
      "name": "Rock_Ice"
    },
    {
      "x": -8,
      "y": -16,
      "z": -1,
      "name": "Rock_Ice"
    },
    {
      "x": -8,
      "y": -15,
      "z": -1,
      "name": "Rock_Ice"
    },
    {
      "x": -8,
      "y": -14,
      "z": -1,
      "name": "Rock_Ice"
    },
    {
      "x": -8,
      "y": -13,
      "z": -1,
      "name": "Rock_Ice"
    },
    {
      "x": -8,
      "y": -12,
      "z": -1,
      "name": "Rock_Ice"
    },
    {
      "x": -8,
      "y": -11,
      "z": -1,
      "name": "Rock_Ice"
    },
    {
      "x": -8,
      "y": -10,
      "z": -1,
      "name": "Rock_Ice"
    },
    {
      "x": -8,
      "y": -7,
      "z": -1,
      "name": "Rock_Ice"
    },
    {
      "x": -8,
      "y": -6,
      "z": -1,
      "name": "Rock_Ice"
    },
    {
      "x": -8,
      "y": -28,
      "z": 0,
      "name": "Rock_Ice"
    },
    {
      "x": -8,
      "y": -24,
      "z": 0,
      "name": "Rock_Ice"
    },
    {
      "x": -8,
      "y": -23,
      "z": 0,
      "name": "Rock_Ice"
    },
    {
      "x": -8,
      "y": -22,
      "z": 0,
      "name": "Rock_Ice"
    },
    {
      "x": -8,
      "y": -21,
      "z": 0,
      "name": "Rock_Ice"
    },
    {
      "x": -8,
      "y": -20,
      "z": 0,
      "name": "Rock_Ice"
    },
    {
      "x": -8,
      "y": -19,
      "z": 0,
      "name": "Rock_Ice"
    },
    {
      "x": -8,
      "y": -18,
      "z": 0,
      "name": "Rock_Ice"
    },
    {
      "x": -8,
      "y": -17,
      "z": 0,
      "name": "Rock_Ice"
    },
    {
      "x": -8,
      "y": -16,
      "z": 0,
      "name": "Rock_Ice"
    },
    {
      "x": -8,
      "y": -15,
      "z": 0,
      "name": "Rock_Ice"
    },
    {
      "x": -8,
      "y": -14,
      "z": 0,
      "name": "Rock_Ice"
    },
    {
      "x": -8,
      "y": -13,
      "z": 0,
      "name": "Rock_Ice"
    },
    {
      "x": -8,
      "y": -12,
      "z": 0,
      "name": "Rock_Ice"
    },
    {
      "x": -8,
      "y": -11,
      "z": 0,
      "name": "Rock_Ice"
    },
    {
      "x": -8,
      "y": -10,
      "z": 0,
      "name": "Rock_Ice"
    },
    {
      "x": -8,
      "y": -29,
      "z": 1,
      "name": "Rock_Ice"
    },
    {
      "x": -8,
      "y": -28,
      "z": 1,
      "name": "Rock_Ice"
    },
    {
      "x": -8,
      "y": -27,
      "z": 1,
      "name": "Rock_Ice"
    },
    {
      "x": -8,
      "y": -26,
      "z": 1,
      "name": "Rock_Ice"
    },
    {
      "x": -8,
      "y": -25,
      "z": 1,
      "name": "Rock_Ice"
    },
    {
      "x": -8,
      "y": -24,
      "z": 1,
      "name": "Rock_Ice"
    },
    {
      "x": -8,
      "y": -23,
      "z": 1,
      "name": "Rock_Ice"
    },
    {
      "x": -8,
      "y": -22,
      "z": 1,
      "name": "Rock_Ice"
    },
    {
      "x": -8,
      "y": -21,
      "z": 1,
      "name": "Rock_Ice"
    },
    {
      "x": -8,
      "y": -20,
      "z": 1,
      "name": "Rock_Ice"
    },
    {
      "x": -8,
      "y": -19,
      "z": 1,
      "name": "Rock_Ice"
    },
    {
      "x": -8,
      "y": -18,
      "z": 1,
      "name": "Rock_Ice"
    },
    {
      "x": -8,
      "y": -17,
      "z": 1,
      "name": "Rock_Ice"
    },
    {
      "x": -8,
      "y": -16,
      "z": 1,
      "name": "Rock_Ice"
    },
    {
      "x": -8,
      "y": -15,
      "z": 1,
      "name": "Rock_Ice"
    },
    {
      "x": -8,
      "y": -14,
      "z": 1,
      "name": "Rock_Ice"
    },
    {
      "x": -8,
      "y": -13,
      "z": 1,
      "name": "Rock_Ice"
    },
    {
      "x": -8,
      "y": -12,
      "z": 1,
      "name": "Rock_Ice"
    },
    {
      "x": -8,
      "y": -11,
      "z": 1,
      "name": "Rock_Ice"
    },
    {
      "x": -8,
      "y": -10,
      "z": 1,
      "name": "Rock_Ice"
    },
    {
      "x": -8,
      "y": -36,
      "z": 2,
      "name": "Rock_Ice"
    },
    {
      "x": -8,
      "y": -35,
      "z": 2,
      "name": "Rock_Ice"
    },
    {
      "x": -8,
      "y": -34,
      "z": 2,
      "name": "Rock_Ice"
    },
    {
      "x": -8,
      "y": -32,
      "z": 2,
      "name": "Rock_Ice"
    },
    {
      "x": -8,
      "y": -31,
      "z": 2,
      "name": "Rock_Ice"
    },
    {
      "x": -8,
      "y": -30,
      "z": 2,
      "name": "Rock_Ice"
    },
    {
      "x": -8,
      "y": -29,
      "z": 2,
      "name": "Rock_Ice"
    },
    {
      "x": -8,
      "y": -28,
      "z": 2,
      "name": "Rock_Ice"
    },
    {
      "x": -8,
      "y": -27,
      "z": 2,
      "name": "Rock_Ice"
    },
    {
      "x": -8,
      "y": -26,
      "z": 2,
      "name": "Rock_Ice"
    },
    {
      "x": -8,
      "y": -25,
      "z": 2,
      "name": "Rock_Ice"
    },
    {
      "x": -8,
      "y": -24,
      "z": 2,
      "name": "Rock_Ice"
    },
    {
      "x": -8,
      "y": -23,
      "z": 2,
      "name": "Rock_Ice"
    },
    {
      "x": -8,
      "y": -22,
      "z": 2,
      "name": "Rock_Ice"
    },
    {
      "x": -8,
      "y": -21,
      "z": 2,
      "name": "Rock_Ice"
    },
    {
      "x": -8,
      "y": -20,
      "z": 2,
      "name": "Rock_Ice"
    },
    {
      "x": -8,
      "y": -19,
      "z": 2,
      "name": "Rock_Ice"
    },
    {
      "x": -8,
      "y": -18,
      "z": 2,
      "name": "Rock_Ice"
    },
    {
      "x": -8,
      "y": -17,
      "z": 2,
      "name": "Rock_Ice"
    },
    {
      "x": -8,
      "y": -16,
      "z": 2,
      "name": "Rock_Ice"
    },
    {
      "x": -8,
      "y": -15,
      "z": 2,
      "name": "Rock_Ice"
    },
    {
      "x": -8,
      "y": -14,
      "z": 2,
      "name": "Rock_Ice"
    },
    {
      "x": -8,
      "y": -13,
      "z": 2,
      "name": "Rock_Ice"
    },
    {
      "x": -8,
      "y": -12,
      "z": 2,
      "name": "Rock_Ice"
    },
    {
      "x": -8,
      "y": -11,
      "z": 2,
      "name": "Rock_Ice"
    },
    {
      "x": -8,
      "y": -10,
      "z": 2,
      "name": "Rock_Ice"
    },
    {
      "x": -8,
      "y": -36,
      "z": 3,
      "name": "Rock_Ice"
    },
    {
      "x": -8,
      "y": -35,
      "z": 3,
      "name": "Rock_Ice"
    },
    {
      "x": -8,
      "y": -34,
      "z": 3,
      "name": "Rock_Ice"
    },
    {
      "x": -8,
      "y": -33,
      "z": 3,
      "name": "Rock_Ice"
    },
    {
      "x": -8,
      "y": -32,
      "z": 3,
      "name": "Rock_Ice"
    },
    {
      "x": -8,
      "y": -31,
      "z": 3,
      "name": "Rock_Ice"
    },
    {
      "x": -8,
      "y": -30,
      "z": 3,
      "name": "Rock_Ice"
    },
    {
      "x": -8,
      "y": -29,
      "z": 3,
      "name": "Rock_Ice"
    },
    {
      "x": -8,
      "y": -28,
      "z": 3,
      "name": "Rock_Ice"
    },
    {
      "x": -8,
      "y": -27,
      "z": 3,
      "name": "Rock_Ice"
    },
    {
      "x": -8,
      "y": -26,
      "z": 3,
      "name": "Rock_Ice"
    },
    {
      "x": -8,
      "y": -25,
      "z": 3,
      "name": "Rock_Ice"
    },
    {
      "x": -8,
      "y": -24,
      "z": 3,
      "name": "Rock_Ice"
    },
    {
      "x": -8,
      "y": -23,
      "z": 3,
      "name": "Rock_Ice"
    },
    {
      "x": -8,
      "y": -22,
      "z": 3,
      "name": "Rock_Ice"
    },
    {
      "x": -8,
      "y": -21,
      "z": 3,
      "name": "Rock_Ice"
    },
    {
      "x": -8,
      "y": -20,
      "z": 3,
      "name": "Rock_Ice"
    },
    {
      "x": -8,
      "y": -19,
      "z": 3,
      "name": "Rock_Ice"
    },
    {
      "x": -8,
      "y": -18,
      "z": 3,
      "name": "Rock_Ice"
    },
    {
      "x": -8,
      "y": -17,
      "z": 3,
      "name": "Rock_Ice"
    },
    {
      "x": -8,
      "y": -16,
      "z": 3,
      "name": "Rock_Ice"
    },
    {
      "x": -8,
      "y": -15,
      "z": 3,
      "name": "Rock_Ice"
    },
    {
      "x": -8,
      "y": -14,
      "z": 3,
      "name": "Rock_Ice"
    },
    {
      "x": -8,
      "y": -13,
      "z": 3,
      "name": "Rock_Ice"
    },
    {
      "x": -8,
      "y": -12,
      "z": 3,
      "name": "Rock_Ice"
    },
    {
      "x": -8,
      "y": -11,
      "z": 3,
      "name": "Rock_Ice"
    },
    {
      "x": -8,
      "y": -27,
      "z": 4,
      "name": "Rock_Ice"
    },
    {
      "x": -8,
      "y": -26,
      "z": 4,
      "name": "Rock_Ice"
    },
    {
      "x": -8,
      "y": -25,
      "z": 4,
      "name": "Rock_Ice"
    },
    {
      "x": -8,
      "y": -24,
      "z": 4,
      "name": "Rock_Ice"
    },
    {
      "x": -8,
      "y": -23,
      "z": 4,
      "name": "Rock_Ice"
    },
    {
      "x": -8,
      "y": -22,
      "z": 4,
      "name": "Rock_Ice"
    },
    {
      "x": -8,
      "y": -21,
      "z": 4,
      "name": "Rock_Ice"
    },
    {
      "x": -8,
      "y": -20,
      "z": 4,
      "name": "Rock_Ice"
    },
    {
      "x": -8,
      "y": -19,
      "z": 4,
      "name": "Rock_Ice"
    },
    {
      "x": -8,
      "y": -18,
      "z": 4,
      "name": "Rock_Ice"
    },
    {
      "x": -8,
      "y": -17,
      "z": 4,
      "name": "Rock_Ice"
    },
    {
      "x": -8,
      "y": -16,
      "z": 4,
      "name": "Rock_Ice"
    },
    {
      "x": -8,
      "y": -15,
      "z": 4,
      "name": "Rock_Ice"
    },
    {
      "x": -8,
      "y": -14,
      "z": 4,
      "name": "Rock_Ice"
    },
    {
      "x": -8,
      "y": -13,
      "z": 4,
      "name": "Rock_Ice"
    },
    {
      "x": -8,
      "y": -12,
      "z": 4,
      "name": "Rock_Ice"
    },
    {
      "x": -8,
      "y": -22,
      "z": 5,
      "name": "Rock_Ice"
    },
    {
      "x": -8,
      "y": -21,
      "z": 5,
      "name": "Rock_Ice"
    },
    {
      "x": -8,
      "y": -20,
      "z": 5,
      "name": "Rock_Ice"
    },
    {
      "x": -8,
      "y": -19,
      "z": 5,
      "name": "Rock_Ice"
    },
    {
      "x": -8,
      "y": -18,
      "z": 5,
      "name": "Rock_Ice"
    },
    {
      "x": -8,
      "y": -17,
      "z": 5,
      "name": "Rock_Ice"
    },
    {
      "x": -8,
      "y": -16,
      "z": 5,
      "name": "Rock_Ice"
    },
    {
      "x": -8,
      "y": -15,
      "z": 5,
      "name": "Rock_Ice"
    },
    {
      "x": -8,
      "y": -14,
      "z": 5,
      "name": "Rock_Ice"
    },
    {
      "x": -8,
      "y": -13,
      "z": 5,
      "name": "Rock_Ice"
    },
    {
      "x": -8,
      "y": -21,
      "z": 6,
      "name": "Rock_Ice"
    },
    {
      "x": -8,
      "y": -20,
      "z": 6,
      "name": "Rock_Ice"
    },
    {
      "x": -8,
      "y": -19,
      "z": 6,
      "name": "Rock_Ice"
    },
    {
      "x": -8,
      "y": -18,
      "z": 6,
      "name": "Rock_Ice"
    },
    {
      "x": -8,
      "y": -17,
      "z": 6,
      "name": "Rock_Ice"
    },
    {
      "x": -8,
      "y": -16,
      "z": 6,
      "name": "Rock_Ice"
    },
    {
      "x": -8,
      "y": -15,
      "z": 6,
      "name": "Rock_Ice"
    },
    {
      "x": -8,
      "y": -14,
      "z": 6,
      "name": "Rock_Ice"
    },
    {
      "x": -8,
      "y": -17,
      "z": 7,
      "name": "Rock_Ice"
    },
    {
      "x": -8,
      "y": -16,
      "z": 7,
      "name": "Rock_Ice"
    },
    {
      "x": -8,
      "y": -15,
      "z": 7,
      "name": "Rock_Ice"
    },
    {
      "x": -8,
      "y": -14,
      "z": 7,
      "name": "Rock_Ice"
    },
    {
      "x": -8,
      "y": -16,
      "z": 8,
      "name": "Rock_Ice"
    },
    {
      "x": -8,
      "y": -15,
      "z": 8,
      "name": "Rock_Ice"
    },
    {
      "x": -8,
      "y": -16,
      "z": 9,
      "name": "Rock_Ice"
    },
    {
      "x": -8,
      "y": -16,
      "z": 10,
      "name": "Rock_Ice"
    },
    {
      "x": -7,
      "y": -18,
      "z": -3,
      "name": "Rock_Ice"
    },
    {
      "x": -7,
      "y": -17,
      "z": -3,
      "name": "Rock_Ice"
    },
    {
      "x": -7,
      "y": -16,
      "z": -3,
      "name": "Rock_Ice"
    },
    {
      "x": -7,
      "y": -15,
      "z": -3,
      "name": "Rock_Ice"
    },
    {
      "x": -7,
      "y": -14,
      "z": -3,
      "name": "Rock_Ice"
    },
    {
      "x": -7,
      "y": -13,
      "z": -3,
      "name": "Rock_Ice"
    },
    {
      "x": -7,
      "y": -12,
      "z": -3,
      "name": "Rock_Ice"
    },
    {
      "x": -7,
      "y": -11,
      "z": -3,
      "name": "Rock_Ice"
    },
    {
      "x": -7,
      "y": -10,
      "z": -3,
      "name": "Rock_Ice"
    },
    {
      "x": -7,
      "y": -26,
      "z": -2,
      "name": "Rock_Ice"
    },
    {
      "x": -7,
      "y": -25,
      "z": -2,
      "name": "Rock_Ice"
    },
    {
      "x": -7,
      "y": -24,
      "z": -2,
      "name": "Rock_Ice"
    },
    {
      "x": -7,
      "y": -23,
      "z": -2,
      "name": "Rock_Ice"
    },
    {
      "x": -7,
      "y": -22,
      "z": -2,
      "name": "Rock_Ice"
    },
    {
      "x": -7,
      "y": -19,
      "z": -2,
      "name": "Rock_Ice"
    },
    {
      "x": -7,
      "y": -18,
      "z": -2,
      "name": "Rock_Ice"
    },
    {
      "x": -7,
      "y": -17,
      "z": -2,
      "name": "Rock_Ice"
    },
    {
      "x": -7,
      "y": -16,
      "z": -2,
      "name": "Rock_Ice"
    },
    {
      "x": -7,
      "y": -15,
      "z": -2,
      "name": "Rock_Ice"
    },
    {
      "x": -7,
      "y": -14,
      "z": -2,
      "name": "Rock_Ice"
    },
    {
      "x": -7,
      "y": -13,
      "z": -2,
      "name": "Rock_Ice"
    },
    {
      "x": -7,
      "y": -12,
      "z": -2,
      "name": "Rock_Ice"
    },
    {
      "x": -7,
      "y": -11,
      "z": -2,
      "name": "Rock_Ice"
    },
    {
      "x": -7,
      "y": -10,
      "z": -2,
      "name": "Rock_Ice"
    },
    {
      "x": -7,
      "y": -7,
      "z": -2,
      "name": "Rock_Ice"
    },
    {
      "x": -7,
      "y": -6,
      "z": -2,
      "name": "Rock_Ice"
    },
    {
      "x": -7,
      "y": -5,
      "z": -2,
      "name": "Rock_Ice"
    },
    {
      "x": -7,
      "y": -26,
      "z": -1,
      "name": "Rock_Ice"
    },
    {
      "x": -7,
      "y": -25,
      "z": -1,
      "name": "Rock_Ice"
    },
    {
      "x": -7,
      "y": -24,
      "z": -1,
      "name": "Rock_Ice"
    },
    {
      "x": -7,
      "y": -23,
      "z": -1,
      "name": "Rock_Ice"
    },
    {
      "x": -7,
      "y": -22,
      "z": -1,
      "name": "Rock_Ice"
    },
    {
      "x": -7,
      "y": -21,
      "z": -1,
      "name": "Rock_Ice"
    },
    {
      "x": -7,
      "y": -20,
      "z": -1,
      "name": "Rock_Ice"
    },
    {
      "x": -7,
      "y": -19,
      "z": -1,
      "name": "Rock_Ice"
    },
    {
      "x": -7,
      "y": -18,
      "z": -1,
      "name": "Rock_Ice"
    },
    {
      "x": -7,
      "y": -17,
      "z": -1,
      "name": "Rock_Ice"
    },
    {
      "x": -7,
      "y": -16,
      "z": -1,
      "name": "Rock_Ice"
    },
    {
      "x": -7,
      "y": -15,
      "z": -1,
      "name": "Rock_Ice"
    },
    {
      "x": -7,
      "y": -14,
      "z": -1,
      "name": "Rock_Ice"
    },
    {
      "x": -7,
      "y": -13,
      "z": -1,
      "name": "Rock_Ice"
    },
    {
      "x": -7,
      "y": -12,
      "z": -1,
      "name": "Rock_Ice"
    },
    {
      "x": -7,
      "y": -11,
      "z": -1,
      "name": "Rock_Ice"
    },
    {
      "x": -7,
      "y": -10,
      "z": -1,
      "name": "Rock_Ice"
    },
    {
      "x": -7,
      "y": -9,
      "z": -1,
      "name": "Rock_Ice"
    },
    {
      "x": -7,
      "y": -8,
      "z": -1,
      "name": "Rock_Ice"
    },
    {
      "x": -7,
      "y": -7,
      "z": -1,
      "name": "Rock_Ice"
    },
    {
      "x": -7,
      "y": -6,
      "z": -1,
      "name": "Rock_Ice"
    },
    {
      "x": -7,
      "y": -5,
      "z": -1,
      "name": "Rock_Ice"
    },
    {
      "x": -7,
      "y": -4,
      "z": -1,
      "name": "Rock_Ice"
    },
    {
      "x": -7,
      "y": -3,
      "z": -1,
      "name": "Rock_Ice"
    },
    {
      "x": -7,
      "y": -2,
      "z": -1,
      "name": "Rock_Ice"
    },
    {
      "x": -7,
      "y": -28,
      "z": 0,
      "name": "Rock_Ice"
    },
    {
      "x": -7,
      "y": -27,
      "z": 0,
      "name": "Rock_Ice"
    },
    {
      "x": -7,
      "y": -26,
      "z": 0,
      "name": "Rock_Ice"
    },
    {
      "x": -7,
      "y": -25,
      "z": 0,
      "name": "Rock_Ice"
    },
    {
      "x": -7,
      "y": -24,
      "z": 0,
      "name": "Rock_Ice"
    },
    {
      "x": -7,
      "y": -23,
      "z": 0,
      "name": "Rock_Ice"
    },
    {
      "x": -7,
      "y": -22,
      "z": 0,
      "name": "Rock_Ice"
    },
    {
      "x": -7,
      "y": -21,
      "z": 0,
      "name": "Rock_Ice"
    },
    {
      "x": -7,
      "y": -20,
      "z": 0,
      "name": "Rock_Ice"
    },
    {
      "x": -7,
      "y": -19,
      "z": 0,
      "name": "Rock_Ice"
    },
    {
      "x": -7,
      "y": -18,
      "z": 0,
      "name": "Rock_Ice"
    },
    {
      "x": -7,
      "y": -17,
      "z": 0,
      "name": "Rock_Ice"
    },
    {
      "x": -7,
      "y": -16,
      "z": 0,
      "name": "Rock_Ice"
    },
    {
      "x": -7,
      "y": -15,
      "z": 0,
      "name": "Rock_Ice"
    },
    {
      "x": -7,
      "y": -14,
      "z": 0,
      "name": "Rock_Ice"
    },
    {
      "x": -7,
      "y": -13,
      "z": 0,
      "name": "Rock_Ice"
    },
    {
      "x": -7,
      "y": -12,
      "z": 0,
      "name": "Rock_Ice"
    },
    {
      "x": -7,
      "y": -11,
      "z": 0,
      "name": "Rock_Ice"
    },
    {
      "x": -7,
      "y": -10,
      "z": 0,
      "name": "Rock_Ice"
    },
    {
      "x": -7,
      "y": -9,
      "z": 0,
      "name": "Rock_Ice"
    },
    {
      "x": -7,
      "y": -8,
      "z": 0,
      "name": "Rock_Ice"
    },
    {
      "x": -7,
      "y": -7,
      "z": 0,
      "name": "Rock_Ice"
    },
    {
      "x": -7,
      "y": -6,
      "z": 0,
      "name": "Rock_Ice"
    },
    {
      "x": -7,
      "y": -5,
      "z": 0,
      "name": "Rock_Ice"
    },
    {
      "x": -7,
      "y": -30,
      "z": 1,
      "name": "Rock_Ice"
    },
    {
      "x": -7,
      "y": -29,
      "z": 1,
      "name": "Rock_Ice"
    },
    {
      "x": -7,
      "y": -28,
      "z": 1,
      "name": "Rock_Ice"
    },
    {
      "x": -7,
      "y": -27,
      "z": 1,
      "name": "Rock_Ice"
    },
    {
      "x": -7,
      "y": -26,
      "z": 1,
      "name": "Rock_Ice"
    },
    {
      "x": -7,
      "y": -25,
      "z": 1,
      "name": "Rock_Ice"
    },
    {
      "x": -7,
      "y": -24,
      "z": 1,
      "name": "Rock_Ice"
    },
    {
      "x": -7,
      "y": -23,
      "z": 1,
      "name": "Rock_Ice"
    },
    {
      "x": -7,
      "y": -22,
      "z": 1,
      "name": "Rock_Ice"
    },
    {
      "x": -7,
      "y": -21,
      "z": 1,
      "name": "Rock_Ice"
    },
    {
      "x": -7,
      "y": -20,
      "z": 1,
      "name": "Rock_Ice"
    },
    {
      "x": -7,
      "y": -19,
      "z": 1,
      "name": "Rock_Ice"
    },
    {
      "x": -7,
      "y": -18,
      "z": 1,
      "name": "Rock_Ice"
    },
    {
      "x": -7,
      "y": -17,
      "z": 1,
      "name": "Rock_Ice"
    },
    {
      "x": -7,
      "y": -16,
      "z": 1,
      "name": "Rock_Ice"
    },
    {
      "x": -7,
      "y": -15,
      "z": 1,
      "name": "Rock_Ice"
    },
    {
      "x": -7,
      "y": -14,
      "z": 1,
      "name": "Rock_Ice"
    },
    {
      "x": -7,
      "y": -13,
      "z": 1,
      "name": "Rock_Ice"
    },
    {
      "x": -7,
      "y": -12,
      "z": 1,
      "name": "Rock_Ice"
    },
    {
      "x": -7,
      "y": -11,
      "z": 1,
      "name": "Rock_Ice"
    },
    {
      "x": -7,
      "y": -10,
      "z": 1,
      "name": "Rock_Ice"
    },
    {
      "x": -7,
      "y": -9,
      "z": 1,
      "name": "Rock_Ice"
    },
    {
      "x": -7,
      "y": -8,
      "z": 1,
      "name": "Rock_Ice"
    },
    {
      "x": -7,
      "y": -7,
      "z": 1,
      "name": "Rock_Ice"
    },
    {
      "x": -7,
      "y": -34,
      "z": 2,
      "name": "Rock_Ice"
    },
    {
      "x": -7,
      "y": -31,
      "z": 2,
      "name": "Rock_Ice"
    },
    {
      "x": -7,
      "y": -30,
      "z": 2,
      "name": "Rock_Ice"
    },
    {
      "x": -7,
      "y": -29,
      "z": 2,
      "name": "Rock_Ice"
    },
    {
      "x": -7,
      "y": -28,
      "z": 2,
      "name": "Rock_Ice"
    },
    {
      "x": -7,
      "y": -27,
      "z": 2,
      "name": "Rock_Ice"
    },
    {
      "x": -7,
      "y": -26,
      "z": 2,
      "name": "Rock_Ice"
    },
    {
      "x": -7,
      "y": -25,
      "z": 2,
      "name": "Rock_Ice"
    },
    {
      "x": -7,
      "y": -24,
      "z": 2,
      "name": "Rock_Ice"
    },
    {
      "x": -7,
      "y": -23,
      "z": 2,
      "name": "Rock_Ice"
    },
    {
      "x": -7,
      "y": -22,
      "z": 2,
      "name": "Rock_Ice"
    },
    {
      "x": -7,
      "y": -21,
      "z": 2,
      "name": "Rock_Ice"
    },
    {
      "x": -7,
      "y": -20,
      "z": 2,
      "name": "Rock_Ice"
    },
    {
      "x": -7,
      "y": -19,
      "z": 2,
      "name": "Rock_Ice"
    },
    {
      "x": -7,
      "y": -18,
      "z": 2,
      "name": "Rock_Ice"
    },
    {
      "x": -7,
      "y": -17,
      "z": 2,
      "name": "Rock_Ice"
    },
    {
      "x": -7,
      "y": -16,
      "z": 2,
      "name": "Rock_Ice"
    },
    {
      "x": -7,
      "y": -15,
      "z": 2,
      "name": "Rock_Ice"
    },
    {
      "x": -7,
      "y": -14,
      "z": 2,
      "name": "Rock_Ice"
    },
    {
      "x": -7,
      "y": -13,
      "z": 2,
      "name": "Rock_Ice"
    },
    {
      "x": -7,
      "y": -12,
      "z": 2,
      "name": "Rock_Ice"
    },
    {
      "x": -7,
      "y": -11,
      "z": 2,
      "name": "Rock_Ice"
    },
    {
      "x": -7,
      "y": -10,
      "z": 2,
      "name": "Rock_Ice"
    },
    {
      "x": -7,
      "y": -9,
      "z": 2,
      "name": "Rock_Ice"
    },
    {
      "x": -7,
      "y": -8,
      "z": 2,
      "name": "Rock_Ice"
    },
    {
      "x": -7,
      "y": -7,
      "z": 2,
      "name": "Rock_Ice"
    },
    {
      "x": -7,
      "y": -6,
      "z": 2,
      "name": "Rock_Ice"
    },
    {
      "x": -7,
      "y": -33,
      "z": 3,
      "name": "Rock_Ice"
    },
    {
      "x": -7,
      "y": -32,
      "z": 3,
      "name": "Rock_Ice"
    },
    {
      "x": -7,
      "y": -31,
      "z": 3,
      "name": "Rock_Ice"
    },
    {
      "x": -7,
      "y": -30,
      "z": 3,
      "name": "Rock_Ice"
    },
    {
      "x": -7,
      "y": -29,
      "z": 3,
      "name": "Rock_Ice"
    },
    {
      "x": -7,
      "y": -28,
      "z": 3,
      "name": "Rock_Ice"
    },
    {
      "x": -7,
      "y": -27,
      "z": 3,
      "name": "Rock_Ice"
    },
    {
      "x": -7,
      "y": -26,
      "z": 3,
      "name": "Rock_Ice"
    },
    {
      "x": -7,
      "y": -25,
      "z": 3,
      "name": "Rock_Ice"
    },
    {
      "x": -7,
      "y": -24,
      "z": 3,
      "name": "Rock_Ice"
    },
    {
      "x": -7,
      "y": -23,
      "z": 3,
      "name": "Rock_Ice"
    },
    {
      "x": -7,
      "y": -22,
      "z": 3,
      "name": "Rock_Ice"
    },
    {
      "x": -7,
      "y": -21,
      "z": 3,
      "name": "Rock_Ice"
    },
    {
      "x": -7,
      "y": -20,
      "z": 3,
      "name": "Rock_Ice"
    },
    {
      "x": -7,
      "y": -19,
      "z": 3,
      "name": "Rock_Ice"
    },
    {
      "x": -7,
      "y": -18,
      "z": 3,
      "name": "Rock_Ice"
    },
    {
      "x": -7,
      "y": -17,
      "z": 3,
      "name": "Rock_Ice"
    },
    {
      "x": -7,
      "y": -16,
      "z": 3,
      "name": "Rock_Ice"
    },
    {
      "x": -7,
      "y": -15,
      "z": 3,
      "name": "Rock_Ice"
    },
    {
      "x": -7,
      "y": -14,
      "z": 3,
      "name": "Rock_Ice"
    },
    {
      "x": -7,
      "y": -13,
      "z": 3,
      "name": "Rock_Ice"
    },
    {
      "x": -7,
      "y": -12,
      "z": 3,
      "name": "Rock_Ice"
    },
    {
      "x": -7,
      "y": -11,
      "z": 3,
      "name": "Rock_Ice"
    },
    {
      "x": -7,
      "y": -10,
      "z": 3,
      "name": "Rock_Ice"
    },
    {
      "x": -7,
      "y": -9,
      "z": 3,
      "name": "Rock_Ice"
    },
    {
      "x": -7,
      "y": -29,
      "z": 4,
      "name": "Rock_Ice"
    },
    {
      "x": -7,
      "y": -28,
      "z": 4,
      "name": "Rock_Ice"
    },
    {
      "x": -7,
      "y": -27,
      "z": 4,
      "name": "Rock_Ice"
    },
    {
      "x": -7,
      "y": -26,
      "z": 4,
      "name": "Rock_Ice"
    },
    {
      "x": -7,
      "y": -25,
      "z": 4,
      "name": "Rock_Ice"
    },
    {
      "x": -7,
      "y": -24,
      "z": 4,
      "name": "Rock_Ice"
    },
    {
      "x": -7,
      "y": -23,
      "z": 4,
      "name": "Rock_Ice"
    },
    {
      "x": -7,
      "y": -22,
      "z": 4,
      "name": "Rock_Ice"
    },
    {
      "x": -7,
      "y": -21,
      "z": 4,
      "name": "Rock_Ice"
    },
    {
      "x": -7,
      "y": -20,
      "z": 4,
      "name": "Rock_Ice"
    },
    {
      "x": -7,
      "y": -19,
      "z": 4,
      "name": "Rock_Ice"
    },
    {
      "x": -7,
      "y": -18,
      "z": 4,
      "name": "Rock_Ice"
    },
    {
      "x": -7,
      "y": -17,
      "z": 4,
      "name": "Rock_Ice"
    },
    {
      "x": -7,
      "y": -16,
      "z": 4,
      "name": "Rock_Ice"
    },
    {
      "x": -7,
      "y": -15,
      "z": 4,
      "name": "Rock_Ice"
    },
    {
      "x": -7,
      "y": -14,
      "z": 4,
      "name": "Rock_Ice"
    },
    {
      "x": -7,
      "y": -13,
      "z": 4,
      "name": "Rock_Ice"
    },
    {
      "x": -7,
      "y": -12,
      "z": 4,
      "name": "Rock_Ice"
    },
    {
      "x": -7,
      "y": -11,
      "z": 4,
      "name": "Rock_Ice"
    },
    {
      "x": -7,
      "y": -10,
      "z": 4,
      "name": "Rock_Ice"
    },
    {
      "x": -7,
      "y": -9,
      "z": 4,
      "name": "Rock_Ice"
    },
    {
      "x": -7,
      "y": -23,
      "z": 5,
      "name": "Rock_Ice"
    },
    {
      "x": -7,
      "y": -22,
      "z": 5,
      "name": "Rock_Ice"
    },
    {
      "x": -7,
      "y": -21,
      "z": 5,
      "name": "Rock_Ice"
    },
    {
      "x": -7,
      "y": -20,
      "z": 5,
      "name": "Rock_Ice"
    },
    {
      "x": -7,
      "y": -19,
      "z": 5,
      "name": "Rock_Ice"
    },
    {
      "x": -7,
      "y": -18,
      "z": 5,
      "name": "Rock_Ice"
    },
    {
      "x": -7,
      "y": -17,
      "z": 5,
      "name": "Rock_Ice"
    },
    {
      "x": -7,
      "y": -16,
      "z": 5,
      "name": "Rock_Ice"
    },
    {
      "x": -7,
      "y": -15,
      "z": 5,
      "name": "Rock_Ice"
    },
    {
      "x": -7,
      "y": -14,
      "z": 5,
      "name": "Rock_Ice"
    },
    {
      "x": -7,
      "y": -13,
      "z": 5,
      "name": "Rock_Ice"
    },
    {
      "x": -7,
      "y": -12,
      "z": 5,
      "name": "Rock_Ice"
    },
    {
      "x": -7,
      "y": -11,
      "z": 5,
      "name": "Rock_Ice"
    },
    {
      "x": -7,
      "y": -22,
      "z": 6,
      "name": "Rock_Ice"
    },
    {
      "x": -7,
      "y": -21,
      "z": 6,
      "name": "Rock_Ice"
    },
    {
      "x": -7,
      "y": -20,
      "z": 6,
      "name": "Rock_Ice"
    },
    {
      "x": -7,
      "y": -19,
      "z": 6,
      "name": "Rock_Ice"
    },
    {
      "x": -7,
      "y": -18,
      "z": 6,
      "name": "Rock_Ice"
    },
    {
      "x": -7,
      "y": -17,
      "z": 6,
      "name": "Rock_Ice"
    },
    {
      "x": -7,
      "y": -16,
      "z": 6,
      "name": "Rock_Ice"
    },
    {
      "x": -7,
      "y": -15,
      "z": 6,
      "name": "Rock_Ice"
    },
    {
      "x": -7,
      "y": -14,
      "z": 6,
      "name": "Rock_Ice"
    },
    {
      "x": -7,
      "y": -13,
      "z": 6,
      "name": "Rock_Ice"
    },
    {
      "x": -7,
      "y": -18,
      "z": 7,
      "name": "Rock_Ice"
    },
    {
      "x": -7,
      "y": -17,
      "z": 7,
      "name": "Rock_Ice"
    },
    {
      "x": -7,
      "y": -16,
      "z": 7,
      "name": "Rock_Ice"
    },
    {
