{
  "version": 8,
  "blockIdVersion": 11,
  "anchorX": 0,
  "anchorY": 0,
  "anchorZ": 0,
  "blocks": [
    {
      "x": -1,
      "y": 0,
      "z": 1,
      "name": "Soil_Sand_Red"
    },
    {
      "x": 0,
      "y": 0,
      "z": 0,
      "name": "Soil_Sand_Red"
    },
    {
      "x": 0,
      "y": 0,
      "z": 1,
      "name": "Soil_Sand_Red"
    },
    {
      "x": 0,
      "y": 1,
      "z": 1,
      "name": "Plant_Bramble_Dry_Sandthorn"
    },
    {
      "x": 0,
      "y": 0,
      "z": 2,
      "name": "Soil_Sand_Red"
    },
    {
      "x": 0,
      "y": 1,
      "z": 2,
      "name": "Soil_Sand_Red"
    },
    {
      "x": 1,
      "y": 0,
      "z": -1,
      "name": "Soil_Sand_Red"
    },
    {
      "x": 1,
      "y": 1,
      "z": -1,
      "name": "Plant_Bramble_Dry_Sandthorn"
    },
    {
      "x": 1,
      "y": 0,
      "z": 0,
      "name": "Soil_Sand_Red"
    },
    {
      "x": 1,
      "y": 1,
      "z": 0,
      "name": "Soil_Sand_Red"
    },
    {
      "x": 1,
      "y": 2,
      "z": 0,
      "name": "Plant_Bramble_Dry_Sandthorn"
    },
    {
      "x": 1,
      "y": 0,
      "z": 1,
      "name": "Soil_Sand_Red"
    },
    {
      "x": 1,
      "y": 1,
      "z": 1,
      "name": "Soil_Sand_Red"
    },
    {
      "x": 1,
      "y": 2,
      "z": 1,
      "name": "Plant_Flower_Bushy_Yellow"
    },
    {
      "x": 1,
      "y": 0,
      "z": 2,
      "name": "Soil_Sand_Red"
    },
    {
      "x": 1,
      "y": 1,
      "z": 2,
      "name": "Soil_Sand_Red"
    },
    {
      "x": 1,
      "y": 2,
      "z": 2,
      "name": "Plant_Flower_Bushy_Yellow"
    },
    {
      "x": 1,
      "y": 0,
      "z": 3,
      "name": "Soil_Sand_Red"
    },
    {
      "x": 2,
      "y": 0,
      "z": -1,
      "name": "Soil_Sand_Red"
    },
    {
      "x": 2,
      "y": 1,
      "z": -1,
      "name": "Plant_Bramble_Dry_Twisted"
    },
    {
      "x": 2,
      "y": 0,
      "z": 0,
      "name": "Soil_Sand_Red"
    },
    {
      "x": 2,
      "y": 1,
      "z": 0,
      "name": "Soil_Sand_Red"
    },
    {
      "x": 2,
      "y": 2,
      "z": 0,
      "name": "Plant_Bramble_Dry_Twisted"
    },
    {
      "x": 2,
      "y": 0,
      "z": 1,
      "name": "Soil_Sand_Red"
    },
    {
      "x": 2,
      "y": 1,
      "z": 1,
      "name": "Soil_Sand_Red"
    },
    {
      "x": 2,
      "y": 2,
      "z": 1,
      "name": "Plant_Flower_Bushy_Yellow"
    },
    {
      "x": 2,
      "y": 0,
      "z": 2,
      "name": "Soil_Sand_Red"
    },
    {
      "x": 2,
      "y": 1,
      "z": 2,
      "name": "Plant_Flower_Bushy_Yellow"
    },
    {
      "x": 3,
      "y": 0,
      "z": 0,
      "name": "Soil_Sand_Red"
    },
    {
      "x": 3,
      "y": 1,
      "z": 0,
      "name": "Plant_Bramble_Dry_Twisted"
    },
    {
      "x": 3,
      "y": 0,
      "z": 1,
      "name": "Soil_Sand_Red"
    }
  ],
  "fluids": [
    {
      "x": -1,
      "y": 0,
      "z": 1,
      "name": "Empty",
      "level": 0
    },
    {
      "x": 0,
      "y": 0,
      "z": 0,
      "name": "Empty",
      "level": 0
    },
    {
      "x": 0,
      "y": 0,
      "z": 1,
      "name": "Empty",
      "level": 0
    },
    {
      "x": 0,
      "y": 1,
      "z": 1,
      "name": "Empty",
      "level": 0
    },
    {
      "x": 0,
      "y": 0,
      "z": 2,
      "name": "Empty",
      "level": 0
    },
    {
      "x": 0,
      "y": 1,
      "z": 2,
      "name": "Empty",
      "level": 0
    },
    {
      "x": 1,
      "y": 0,
      "z": -1,
      "name": "Empty",
      "level": 0
    },
    {
      "x": 1,
      "y": 1,
      "z": -1,
      "name": "Empty",
      "level": 0
    },
    {
      "x": 1,
      "y": 0,
      "z": 0,
      "name": "Empty",
      "level": 0
    },
    {
      "x": 1,
      "y": 1,
      "z": 0,
      "name": "Empty",
      "level": 0
    },
    {
      "x": 1,
      "y": 2,
      "z": 0,
      "name": "Empty",
      "level": 0
    },
    {
      "x": 1,
      "y": 0,
      "z": 1,
      "name": "Empty",
      "level": 0
    },
    {
      "x": 1,
      "y": 1,
      "z": 1,
      "name": "Empty",
      "level": 0
    },
    {
      "x": 1,
      "y": 2,
      "z": 1,
      "name": "Empty",
      "level": 0
    },
    {
      "x": 1,
      "y": 0,
      "z": 2,
      "name": "Empty",
      "level": 0
    },
    {
      "x": 1,
      "y": 1,
      "z": 2,
      "name": "Empty",
      "level": 0
    },
    {
      "x": 1,
      "y": 2,
      "z": 2,
      "name": "Empty",
      "level": 0
    },
    {
      "x": 1,
      "y": 0,
      "z": 3,
      "name": "Empty",
      "level": 0
    },
    {
      "x": 2,
      "y": 0,
      "z": -1,
      "name": "Empty",
      "level": 0
    },
    {
      "x": 2,
      "y": 1,
      "z": -1,
      "name": "Empty",
      "level": 0
    },
    {
      "x": 2,
      "y": 0,
      "z": 0,
      "name": "Empty",
      "level": 0
    },
    {
      "x": 2,
      "y": 1,
      "z": 0,
      "name": "Empty",
      "level": 0
    },
    {
      "x": 2,
      "y": 2,
      "z": 0,
      "name": "Empty",
      "level": 0
    },
    {
      "x": 2,
      "y": 0,
      "z": 1,
      "name": "Empty",
      "level": 0
    },
    {
      "x": 2,
      "y": 1,
      "z": 1,
      "name": "Empty",
      "level": 0
    },
    {
      "x": 2,
      "y": 2,
      "z": 1,
      "name": "Empty",
      "level": 0
    },
    {
      "x": 2,
      "y": 0,
      "z": 2,
      "name": "Empty",
      "level": 0
    },
    {
      "x": 2,
      "y": 1,
      "z": 2,
      "name": "Empty",
      "level": 0
    },
    {
      "x": 3,
      "y": 0,
      "z": 0,
      "name": "Empty",
      "level": 0
    },
    {
      "x": 3,
      "y": 1,
      "z": 0,
      "name": "Empty",
      "level": 0
    },
    {
      "x": 3,
      "y": 0,
      "z": 1,
      "name": "Empty",
      "level": 0
    }
  ]
}