{
  "version": 8,
  "blockIdVersion": 11,
  "anchorX": 0,
  "anchorY": 0,
  "anchorZ": 0,
  "blocks": [
    {
      "x": -37,
      "y": 29,
      "z": -3,
      "name": "Plant_Moss_Wall_Green_Dark",
      "support": 15,
      "rotation": 3
    },
    {
      "x": -36,
      "y": 28,
      "z": -8,
      "name": "Metal_Iron_Half"
    },
    {
      "x": -36,
      "y": 28,
      "z": -7,
      "name": "Metal_Iron"
    },
    {
      "x": -36,
      "y": 28,
      "z": -6,
      "name": "Metal_Iron"
    },
    {
      "x": -36,
      "y": 29,
      "z": -6,
      "name": "Metal_Iron_Half"
    },
    {
      "x": -36,
      "y": 28,
      "z": -5,
      "name": "Metal_Iron"
    },
    {
      "x": -36,
      "y": 29,
      "z": -5,
      "name": "Metal_Iron_Half"
    },
    {
      "x": -36,
      "y": 28,
      "z": -4,
      "name": "Metal_Iron_Half",
      "rotation": 8
    },
    {
      "x": -36,
      "y": 29,
      "z": -4,
      "name": "Metal_Iron"
    },
    {
      "x": -36,
      "y": 28,
      "z": -3,
      "name": "Metal_Iron_Half",
      "rotation": 8
    },
    {
      "x": -36,
      "y": 29,
      "z": -3,
      "name": "Metal_Iron"
    },
    {
      "x": -36,
      "y": 29,
      "z": -2,
      "name": "Metal_Iron"
    },
    {
      "x": -36,
      "y": 29,
      "z": -1,
      "name": "Metal_Iron"
    },
    {
      "x": -36,
      "y": 29,
      "z": 0,
      "name": "Metal_Iron_Half",
      "rotation": 8
    },
    {
      "x": -36,
      "y": 29,
      "z": 2,
      "name": "Plant_Moss_Wall_Green_Dark",
      "support": 15,
      "rotation": 3
    },
    {
      "x": -35,
      "y": 28,
      "z": -13,
      "name": "Plant_Moss_Wall_Green_Dark",
      "support": 15,
      "rotation": 3
    },
    {
      "x": -35,
      "y": 27,
      "z": -11,
      "name": "Metal_Iron"
    },
    {
      "x": -35,
      "y": 28,
      "z": -11,
      "name": "Metal_Iron"
    },
    {
      "x": -35,
      "y": 27,
      "z": -10,
      "name": "Metal_Iron"
    },
    {
      "x": -35,
      "y": 28,
      "z": -10,
      "name": "Metal_Iron"
    },
    {
      "x": -35,
      "y": 29,
      "z": -10,
      "name": "Metal_Iron_Half"
    },
    {
      "x": -35,
      "y": 27,
      "z": -9,
      "name": "Metal_Iron"
    },
    {
      "x": -35,
      "y": 28,
      "z": -9,
      "name": "Metal_Iron"
    },
    {
      "x": -35,
      "y": 29,
      "z": -9,
      "name": "Metal_Iron"
    },
    {
      "x": -35,
      "y": 27,
      "z": -8,
      "name": "Metal_Iron"
    },
    {
      "x": -35,
      "y": 28,
      "z": -8,
      "name": "Metal_Iron"
    },
    {
      "x": -35,
      "y": 29,
      "z": -8,
      "name": "Metal_Iron"
    },
    {
      "x": -35,
      "y": 27,
      "z": -7,
      "name": "Metal_Iron"
    },
    {
      "x": -35,
      "y": 28,
      "z": -7,
      "name": "Metal_Iron"
    },
    {
      "x": -35,
      "y": 29,
      "z": -7,
      "name": "Metal_Iron"
    },
    {
      "x": -35,
      "y": 30,
      "z": -7,
      "name": "Metal_Iron_Half"
    },
    {
      "x": -35,
      "y": 27,
      "z": -6,
      "name": "Metal_Iron"
    },
    {
      "x": -35,
      "y": 28,
      "z": -6,
      "name": "Metal_Iron"
    },
    {
      "x": -35,
      "y": 29,
      "z": -6,
      "name": "Metal_Iron"
    },
    {
      "x": -35,
      "y": 30,
      "z": -6,
      "name": "Metal_Iron_Half"
    },
    {
      "x": -35,
      "y": 27,
      "z": -5,
      "name": "Metal_Iron"
    },
    {
      "x": -35,
      "y": 28,
      "z": -5,
      "name": "Metal_Iron"
    },
    {
      "x": -35,
      "y": 29,
      "z": -5,
      "name": "Metal_Iron"
    },
    {
      "x": -35,
      "y": 30,
      "z": -5,
      "name": "Metal_Iron"
    },
    {
      "x": -35,
      "y": 27,
      "z": -4,
      "name": "Metal_Iron"
    },
    {
      "x": -35,
      "y": 28,
      "z": -4,
      "name": "Metal_Iron"
    },
    {
      "x": -35,
      "y": 29,
      "z": -4,
      "name": "Metal_Iron"
    },
    {
      "x": -35,
      "y": 30,
      "z": -4,
      "name": "Metal_Iron"
    },
    {
      "x": -35,
      "y": 27,
      "z": -3,
      "name": "Metal_Iron_Half",
      "rotation": 8
    },
    {
      "x": -35,
      "y": 28,
      "z": -3,
      "name": "Metal_Iron"
    },
    {
      "x": -35,
      "y": 29,
      "z": -3,
      "name": "Metal_Iron"
    },
    {
      "x": -35,
      "y": 30,
      "z": -3,
      "name": "Metal_Iron"
    },
    {
      "x": -35,
      "y": 27,
      "z": -2,
      "name": "Metal_Iron_Half",
      "rotation": 8
    },
    {
      "x": -35,
      "y": 28,
      "z": -2,
      "name": "Metal_Iron"
    },
    {
      "x": -35,
      "y": 29,
      "z": -2,
      "name": "Metal_Iron"
    },
    {
      "x": -35,
      "y": 30,
      "z": -2,
      "name": "Metal_Iron"
    },
    {
      "x": -35,
      "y": 27,
      "z": -1,
      "name": "Metal_Iron_Half",
      "rotation": 8
    },
    {
      "x": -35,
      "y": 28,
      "z": -1,
      "name": "Metal_Iron"
    },
    {
      "x": -35,
      "y": 29,
      "z": -1,
      "name": "Metal_Iron"
    },
    {
      "x": -35,
      "y": 30,
      "z": -1,
      "name": "Metal_Iron"
    },
    {
      "x": -35,
      "y": 28,
      "z": 0,
      "name": "Metal_Iron"
    },
    {
      "x": -35,
      "y": 29,
      "z": 0,
      "name": "Metal_Iron"
    },
    {
      "x": -35,
      "y": 30,
      "z": 0,
      "name": "Metal_Iron"
    },
    {
      "x": -35,
      "y": 28,
      "z": 1,
      "name": "Metal_Iron"
    },
    {
      "x": -35,
      "y": 29,
      "z": 1,
      "name": "Metal_Iron"
    },
    {
      "x": -35,
      "y": 30,
      "z": 1,
      "name": "Metal_Iron"
    },
    {
      "x": -35,
      "y": 28,
      "z": 2,
      "name": "Metal_Iron_Half",
      "rotation": 8
    },
    {
      "x": -35,
      "y": 29,
      "z": 2,
      "name": "Metal_Iron"
    },
    {
      "x": -35,
      "y": 30,
      "z": 2,
      "name": "Metal_Iron"
    },
    {
      "x": -35,
      "y": 29,
      "z": 3,
      "name": "Metal_Iron"
    },
    {
      "x": -35,
      "y": 30,
      "z": 3,
      "name": "Metal_Iron"
    },
    {
      "x": -35,
      "y": 29,
      "z": 4,
      "name": "Metal_Iron_Half",
      "rotation": 8
    },
    {
      "x": -35,
      "y": 30,
      "z": 4,
      "name": "Metal_Iron"
    },
    {
      "x": -35,
      "y": 30,
      "z": 5,
      "name": "Metal_Iron_Half",
      "rotation": 8
    },
    {
      "x": -34,
      "y": 27,
      "z": -13,
      "name": "Metal_Iron"
    },
    {
      "x": -34,
      "y": 28,
      "z": -13,
      "name": "Metal_Iron"
    },
    {
      "x": -34,
      "y": 26,
      "z": -12,
      "name": "Metal_Iron"
    },
    {
      "x": -34,
      "y": 27,
      "z": -12,
      "name": "Metal_Iron"
    },
    {
      "x": -34,
      "y": 28,
      "z": -12,
      "name": "Metal_Iron"
    },
    {
      "x": -34,
      "y": 29,
      "z": -12,
      "name": "Metal_Iron_Half"
    },
    {
      "x": -34,
      "y": 26,
      "z": -11,
      "name": "Metal_Iron"
    },
    {
      "x": -34,
      "y": 27,
      "z": -11,
      "name": "Metal_Iron"
    },
    {
      "x": -34,
      "y": 28,
      "z": -11,
      "name": "Metal_Iron"
    },
    {
      "x": -34,
      "y": 29,
      "z": -11,
      "name": "Metal_Iron_Half"
    },
    {
      "x": -34,
      "y": 26,
      "z": -10,
      "name": "Metal_Iron"
    },
    {
      "x": -34,
      "y": 27,
      "z": -10,
      "name": "Metal_Iron"
    },
    {
      "x": -34,
      "y": 28,
      "z": -10,
      "name": "Metal_Iron"
    },
    {
      "x": -34,
      "y": 29,
      "z": -10,
      "name": "Metal_Iron"
    },
    {
      "x": -34,
      "y": 26,
      "z": -9,
      "name": "Metal_Iron"
    },
    {
      "x": -34,
      "y": 27,
      "z": -9,
      "name": "Metal_Iron"
    },
    {
      "x": -34,
      "y": 28,
      "z": -9,
      "name": "Metal_Iron"
    },
    {
      "x": -34,
      "y": 29,
      "z": -9,
      "name": "Metal_Iron"
    },
    {
      "x": -34,
      "y": 26,
      "z": -8,
      "name": "Metal_Iron"
    },
    {
      "x": -34,
      "y": 27,
      "z": -8,
      "name": "Metal_Iron"
    },
    {
      "x": -34,
      "y": 29,
      "z": -8,
      "name": "Metal_Iron"
    },
    {
      "x": -34,
      "y": 30,
      "z": -8,
      "name": "Metal_Iron_Half"
    },
    {
      "x": -34,
      "y": 26,
      "z": -7,
      "name": "Metal_Iron"
    },
    {
      "x": -34,
      "y": 27,
      "z": -7,
      "name": "Metal_Iron"
    },
    {
      "x": -34,
      "y": 29,
      "z": -7,
      "name": "Metal_Iron"
    },
    {
      "x": -34,
      "y": 30,
      "z": -7,
      "name": "Metal_Iron_Half"
    },
    {
      "x": -34,
      "y": 26,
      "z": -6,
      "name": "Metal_Iron"
    },
    {
      "x": -34,
      "y": 27,
      "z": -6,
      "name": "Metal_Iron"
    },
    {
      "x": -34,
      "y": 29,
      "z": -6,
      "name": "Metal_Iron"
    },
    {
      "x": -34,
      "y": 30,
      "z": -6,
      "name": "Metal_Iron"
    },
    {
      "x": -34,
      "y": 26,
      "z": -5,
      "name": "Metal_Iron"
    },
    {
      "x": -34,
      "y": 27,
      "z": -5,
      "name": "Metal_Iron"
    },
    {
      "x": -34,
      "y": 29,
      "z": -5,
      "name": "Metal_Iron"
    },
    {
      "x": -34,
      "y": 30,
      "z": -5,
      "name": "Metal_Iron"
    },
    {
      "x": -34,
      "y": 26,
      "z": -4,
      "name": "Metal_Iron_Half",
      "rotation": 8
    },
    {
      "x": -34,
      "y": 27,
      "z": -4,
      "name": "Metal_Iron"
    },
    {
      "x": -34,
      "y": 29,
      "z": -4,
      "name": "Metal_Iron"
    },
    {
      "x": -34,
      "y": 30,
      "z": -4,
      "name": "Metal_Iron"
    },
    {
      "x": -34,
      "y": 27,
      "z": -3,
      "name": "Metal_Iron"
    },
    {
      "x": -34,
      "y": 29,
      "z": -3,
      "name": "Metal_Iron"
    },
    {
      "x": -34,
      "y": 30,
      "z": -3,
      "name": "Metal_Iron"
    },
    {
      "x": -34,
      "y": 27,
      "z": -2,
      "name": "Metal_Iron_Half",
      "rotation": 8
    },
    {
      "x": -34,
      "y": 28,
      "z": -2,
      "name": "Metal_Iron"
    },
    {
      "x": -34,
      "y": 30,
      "z": -2,
      "name": "Metal_Iron"
    },
    {
      "x": -34,
      "y": 27,
      "z": -1,
      "name": "Metal_Iron_Half",
      "rotation": 8
    },
    {
      "x": -34,
      "y": 28,
      "z": -1,
      "name": "Metal_Iron"
    },
    {
      "x": -34,
      "y": 30,
      "z": -1,
      "name": "Metal_Iron"
    },
    {
      "x": -34,
      "y": 27,
      "z": 0,
      "name": "Metal_Iron_Half",
      "rotation": 8
    },
    {
      "x": -34,
      "y": 28,
      "z": 0,
      "name": "Metal_Iron"
    },
    {
      "x": -34,
      "y": 30,
      "z": 0,
      "name": "Metal_Iron"
    },
    {
      "x": -34,
      "y": 31,
      "z": 0,
      "name": "Metal_Iron_Half"
    },
    {
      "x": -34,
      "y": 28,
      "z": 1,
      "name": "Metal_Iron"
    },
    {
      "x": -34,
      "y": 29,
      "z": 1,
      "name": "Metal_Iron"
    },
    {
      "x": -34,
      "y": 30,
      "z": 1,
      "name": "Metal_Iron"
    },
    {
      "x": -34,
      "y": 31,
      "z": 1,
      "name": "Metal_Iron_Half"
    },
    {
      "x": -34,
      "y": 28,
      "z": 2,
      "name": "Metal_Iron"
    },
    {
      "x": -34,
      "y": 29,
      "z": 2,
      "name": "Metal_Iron"
    },
    {
      "x": -34,
      "y": 30,
      "z": 2,
      "name": "Metal_Iron"
    },
    {
      "x": -34,
      "y": 31,
      "z": 2,
      "name": "Metal_Iron"
    },
    {
      "x": -34,
      "y": 28,
      "z": 3,
      "name": "Metal_Iron_Half",
      "rotation": 8
    },
    {
      "x": -34,
      "y": 29,
      "z": 3,
      "name": "Metal_Iron"
    },
    {
      "x": -34,
      "y": 30,
      "z": 3,
      "name": "Metal_Iron"
    },
    {
      "x": -34,
      "y": 31,
      "z": 3,
      "name": "Metal_Iron"
    },
    {
      "x": -34,
      "y": 29,
      "z": 4,
      "name": "Metal_Iron"
    },
    {
      "x": -34,
      "y": 30,
      "z": 4,
      "name": "Metal_Iron"
    },
    {
      "x": -34,
      "y": 31,
      "z": 4,
      "name": "Metal_Iron"
    },
    {
      "x": -34,
      "y": 29,
      "z": 5,
      "name": "Metal_Iron"
    },
    {
      "x": -34,
      "y": 30,
      "z": 5,
      "name": "Metal_Iron"
    },
    {
      "x": -34,
      "y": 31,
      "z": 5,
      "name": "Metal_Iron"
    },
    {
      "x": -34,
      "y": 29,
      "z": 6,
      "name": "Metal_Iron_Half",
      "rotation": 8
    },
    {
      "x": -34,
      "y": 30,
      "z": 6,
      "name": "Metal_Iron"
    },
    {
      "x": -34,
      "y": 31,
      "z": 6,
      "name": "Metal_Iron"
    },
    {
      "x": -34,
      "y": 30,
      "z": 7,
      "name": "Metal_Iron"
    },
    {
      "x": -34,
      "y": 31,
      "z": 7,
      "name": "Metal_Iron"
    },
    {
      "x": -34,
      "y": 30,
      "z": 8,
      "name": "Metal_Iron"
    },
    {
      "x": -34,
      "y": 31,
      "z": 8,
      "name": "Metal_Iron"
    },
    {
      "x": -34,
      "y": 30,
      "z": 9,
      "name": "Metal_Iron_Half",
      "rotation": 8
    },
    {
      "x": -34,
      "y": 31,
      "z": 9,
      "name": "Metal_Iron"
    },
    {
      "x": -34,
      "y": 31,
      "z": 10,
      "name": "Metal_Iron"
    },
    {
      "x": -34,
      "y": 31,
      "z": 11,
      "name": "Metal_Iron_Half",
      "rotation": 8
    },
    {
      "x": -33,
      "y": 26,
      "z": -15,
      "name": "Metal_Iron"
    },
    {
      "x": -33,
      "y": 27,
      "z": -15,
      "name": "Metal_Iron"
    },
    {
      "x": -33,
      "y": 26,
      "z": -14,
      "name": "Metal_Iron"
    },
    {
      "x": -33,
      "y": 27,
      "z": -14,
      "name": "Metal_Iron"
    },
    {
      "x": -33,
      "y": 28,
      "z": -14,
      "name": "Metal_Iron"
    },
    {
      "x": -33,
      "y": 26,
      "z": -13,
      "name": "Metal_Iron"
    },
    {
      "x": -33,
      "y": 27,
      "z": -13,
      "name": "Metal_Iron"
    },
    {
      "x": -33,
      "y": 28,
      "z": -13,
      "name": "Metal_Iron"
    },
    {
      "x": -33,
      "y": 29,
      "z": -13,
      "name": "Metal_Iron_Half"
    },
    {
      "x": -33,
      "y": 26,
      "z": -12,
      "name": "Metal_Iron"
    },
    {
      "x": -33,
      "y": 27,
      "z": -12,
      "name": "Metal_Iron"
    },
    {
      "x": -33,
      "y": 28,
      "z": -12,
      "name": "Metal_Iron"
    },
    {
      "x": -33,
      "y": 29,
      "z": -12,
      "name": "Metal_Iron_Half"
    },
    {
      "x": -33,
      "y": 26,
      "z": -11,
      "name": "Metal_Iron"
    },
    {
      "x": -33,
      "y": 28,
      "z": -11,
      "name": "Metal_Iron"
    },
    {
      "x": -33,
      "y": 29,
      "z": -11,
      "name": "Metal_Iron"
    },
    {
      "x": -33,
      "y": 26,
      "z": -10,
      "name": "Metal_Iron"
    },
    {
      "x": -33,
      "y": 28,
      "z": -10,
      "name": "Metal_Iron"
    },
    {
      "x": -33,
      "y": 29,
      "z": -10,
      "name": "Metal_Iron"
    },
    {
      "x": -33,
      "y": 26,
      "z": -9,
      "name": "Metal_Iron"
    },
    {
      "x": -33,
      "y": 29,
      "z": -9,
      "name": "Metal_Iron"
    },
    {
      "x": -33,
      "y": 26,
      "z": -8,
      "name": "Metal_Iron"
    },
    {
      "x": -33,
      "y": 27,
      "z": -8,
      "name": "Metal_Iron"
    },
    {
      "x": -33,
      "y": 29,
      "z": -8,
      "name": "Metal_Iron"
    },
    {
      "x": -33,
      "y": 26,
      "z": -7,
      "name": "Metal_Iron"
    },
    {
      "x": -33,
      "y": 27,
      "z": -7,
      "name": "Metal_Iron"
    },
    {
      "x": -33,
      "y": 29,
      "z": -7,
      "name": "Metal_Iron"
    },
    {
      "x": -33,
      "y": 30,
      "z": -7,
      "name": "Metal_Iron_Half"
    },
    {
      "x": -33,
      "y": 26,
      "z": -6,
      "name": "Metal_Iron"
    },
    {
      "x": -33,
      "y": 27,
      "z": -6,
      "name": "Metal_Iron"
    },
    {
      "x": -33,
      "y": 29,
      "z": -6,
      "name": "Metal_Iron"
    },
    {
      "x": -33,
      "y": 30,
      "z": -6,
      "name": "Metal_Iron_Half"
    },
    {
      "x": -33,
      "y": 26,
      "z": -5,
      "name": "Metal_Iron"
    },
    {
      "x": -33,
      "y": 27,
      "z": -5,
      "name": "Metal_Iron"
    },
    {
      "x": -33,
      "y": 29,
      "z": -5,
      "name": "Metal_Iron"
    },
    {
      "x": -33,
      "y": 30,
      "z": -5,
      "name": "Metal_Iron"
    },
    {
      "x": -33,
      "y": 26,
      "z": -4,
      "name": "Metal_Iron_Half",
      "rotation": 8
    },
    {
      "x": -33,
      "y": 27,
      "z": -4,
      "name": "Metal_Iron"
    },
    {
      "x": -33,
      "y": 29,
      "z": -4,
      "name": "Metal_Iron"
    },
    {
      "x": -33,
      "y": 30,
      "z": -4,
      "name": "Metal_Iron"
    },
    {
      "x": -33,
      "y": 27,
      "z": -3,
      "name": "Metal_Iron"
    },
    {
      "x": -33,
      "y": 29,
      "z": -3,
      "name": "Metal_Iron"
    },
    {
      "x": -33,
      "y": 30,
      "z": -3,
      "name": "Metal_Iron"
    },
    {
      "x": -33,
      "y": 27,
      "z": -2,
      "name": "Metal_Iron"
    },
    {
      "x": -33,
      "y": 28,
      "z": -2,
      "name": "Metal_Iron"
    },
    {
      "x": -33,
      "y": 29,
      "z": -2,
      "name": "Metal_Iron"
    },
    {
      "x": -33,
      "y": 30,
      "z": -2,
      "name": "Metal_Iron"
    },
    {
      "x": -33,
      "y": 27,
      "z": -1,
      "name": "Metal_Iron_Half",
      "rotation": 8
    },
    {
      "x": -33,
      "y": 28,
      "z": -1,
      "name": "Metal_Iron"
    },
    {
      "x": -33,
      "y": 30,
      "z": -1,
      "name": "Metal_Iron"
    },
    {
      "x": -33,
      "y": 27,
      "z": 0,
      "name": "Metal_Iron_Half",
      "rotation": 8
    },
    {
      "x": -33,
      "y": 28,
      "z": 0,
      "name": "Metal_Iron"
    },
    {
      "x": -33,
      "y": 30,
      "z": 0,
      "name": "Metal_Iron"
    },
    {
      "x": -33,
      "y": 28,
      "z": 1,
      "name": "Metal_Iron"
    },
    {
      "x": -33,
      "y": 30,
      "z": 1,
      "name": "Metal_Iron"
    },
    {
      "x": -33,
      "y": 31,
      "z": 1,
      "name": "Metal_Iron_Half"
    },
    {
      "x": -33,
      "y": 28,
      "z": 2,
      "name": "Metal_Iron"
    },
    {
      "x": -33,
      "y": 29,
      "z": 2,
      "name": "Metal_Iron"
    },
    {
      "x": -33,
      "y": 30,
      "z": 2,
      "name": "Metal_Iron"
    },
    {
      "x": -33,
      "y": 31,
      "z": 2,
      "name": "Metal_Iron_Half"
    },
    {
      "x": -33,
      "y": 28,
      "z": 3,
      "name": "Metal_Iron"
    },
    {
      "x": -33,
      "y": 29,
      "z": 3,
      "name": "Metal_Iron"
    },
    {
      "x": -33,
      "y": 30,
      "z": 3,
      "name": "Metal_Iron"
    },
    {
      "x": -33,
      "y": 31,
      "z": 3,
      "name": "Metal_Iron"
    },
    {
      "x": -33,
      "y": 28,
      "z": 4,
      "name": "Metal_Iron_Half",
      "rotation": 8
    },
    {
      "x": -33,
      "y": 29,
      "z": 4,
      "name": "Metal_Iron"
    },
    {
      "x": -33,
      "y": 30,
      "z": 4,
      "name": "Metal_Iron"
    },
    {
      "x": -33,
      "y": 31,
      "z": 4,
      "name": "Metal_Iron"
    },
    {
      "x": -33,
      "y": 29,
      "z": 5,
      "name": "Metal_Iron"
    },
    {
      "x": -33,
      "y": 31,
      "z": 5,
      "name": "Metal_Iron"
    },
    {
      "x": -33,
      "y": 29,
      "z": 6,
      "name": "Metal_Iron"
    },
    {
      "x": -33,
      "y": 30,
      "z": 6,
      "name": "Metal_Iron"
    },
    {
      "x": -33,
      "y": 31,
      "z": 6,
      "name": "Metal_Iron"
    },
    {
      "x": -33,
      "y": 29,
      "z": 7,
      "name": "Metal_Iron_Half",
      "rotation": 8
    },
    {
      "x": -33,
      "y": 30,
      "z": 7,
      "name": "Metal_Iron"
    },
    {
      "x": -33,
      "y": 31,
      "z": 7,
      "name": "Metal_Iron"
    },
    {
      "x": -33,
      "y": 32,
      "z": 7,
      "name": "Metal_Iron_Half"
    },
    {
      "x": -33,
      "y": 29,
      "z": 8,
      "name": "Metal_Iron_Half",
      "rotation": 8
    },
    {
      "x": -33,
      "y": 30,
      "z": 8,
      "name": "Metal_Iron"
    },
    {
      "x": -33,
      "y": 31,
      "z": 8,
      "name": "Metal_Iron"
    },
    {
      "x": -33,
      "y": 32,
      "z": 8,
      "name": "Metal_Iron_Half"
    },
    {
      "x": -33,
      "y": 30,
      "z": 9,
      "name": "Metal_Iron"
    },
    {
      "x": -33,
      "y": 31,
      "z": 9,
      "name": "Metal_Iron"
    },
    {
      "x": -33,
      "y": 32,
      "z": 9,
      "name": "Metal_Iron"
    },
    {
      "x": -33,
      "y": 30,
      "z": 10,
      "name": "Metal_Iron_Half",
      "rotation": 8
    },
    {
      "x": -33,
      "y": 31,
      "z": 10,
      "name": "Metal_Iron"
    },
    {
      "x": -33,
      "y": 32,
      "z": 10,
      "name": "Metal_Iron"
    },
    {
      "x": -33,
      "y": 31,
      "z": 11,
      "name": "Metal_Iron"
    },
    {
      "x": -33,
      "y": 32,
      "z": 11,
      "name": "Metal_Iron"
    },
    {
      "x": -33,
      "y": 31,
      "z": 12,
      "name": "Metal_Iron_Half",
      "rotation": 8
    },
    {
      "x": -33,
      "y": 32,
      "z": 12,
      "name": "Metal_Iron"
    },
    {
      "x": -33,
      "y": 32,
      "z": 13,
      "name": "Metal_Iron_Half",
      "rotation": 8
    },
    {
      "x": -32,
      "y": 26,
      "z": -16,
      "name": "Metal_Iron"
    },
    {
      "x": -32,
      "y": 27,
      "z": -16,
      "name": "Metal_Iron"
    },
    {
      "x": -32,
      "y": 28,
      "z": -16,
      "name": "Metal_Iron"
    },
    {
      "x": -32,
      "y": 26,
      "z": -15,
      "name": "Metal_Iron"
    },
    {
      "x": -32,
      "y": 27,
      "z": -15,
      "name": "Metal_Iron"
    },
    {
      "x": -32,
      "y": 28,
      "z": -15,
      "name": "Metal_Iron"
    },
    {
      "x": -32,
      "y": 25,
      "z": -14,
      "name": "Metal_Iron"
    },
    {
      "x": -32,
      "y": 26,
      "z": -14,
      "name": "Metal_Iron"
    },
    {
      "x": -32,
      "y": 27,
      "z": -14,
      "name": "Metal_Iron"
    },
    {
      "x": -32,
      "y": 28,
      "z": -14,
      "name": "Metal_Iron"
    },
    {
      "x": -32,
      "y": 29,
      "z": -14,
      "name": "Metal_Iron_Half"
    },
    {
      "x": -32,
      "y": 25,
      "z": -13,
      "name": "Metal_Iron"
    },
    {
      "x": -32,
      "y": 26,
      "z": -13,
      "name": "Metal_Iron"
    },
    {
      "x": -32,
      "y": 28,
      "z": -13,
      "name": "Metal_Iron"
    },
    {
      "x": -32,
      "y": 29,
      "z": -13,
      "name": "Metal_Iron_Half"
    },
    {
      "x": -32,
      "y": 25,
      "z": -12,
      "name": "Metal_Iron"
    },
    {
      "x": -32,
      "y": 26,
      "z": -12,
      "name": "Metal_Iron"
    },
    {
      "x": -32,
      "y": 28,
      "z": -12,
      "name": "Metal_Iron"
    },
    {
      "x": -32,
      "y": 29,
      "z": -12,
      "name": "Metal_Iron"
    },
    {
      "x": -32,
      "y": 25,
      "z": -11,
      "name": "Metal_Iron_Half",
      "rotation": 8
    },
    {
      "x": -32,
      "y": 26,
      "z": -11,
      "name": "Metal_Iron"
    },
    {
      "x": -32,
      "y": 28,
      "z": -11,
      "name": "Metal_Iron"
    },
    {
      "x": -32,
      "y": 29,
      "z": -11,
      "name": "Metal_Iron"
    },
    {
      "x": -32,
      "y": 25,
      "z": -10,
      "name": "Metal_Iron_Half",
      "rotation": 8
    },
    {
      "x": -32,
      "y": 26,
      "z": -10,
      "name": "Metal_Iron"
    },
    {
      "x": -32,
      "y": 28,
      "z": -10,
      "name": "Metal_Iron"
    },
    {
      "x": -32,
      "y": 29,
      "z": -10,
      "name": "Metal_Iron"
    },
    {
      "x": -32,
      "y": 25,
      "z": -9,
      "name": "Metal_Iron_Half",
      "rotation": 8
    },
    {
      "x": -32,
      "y": 26,
      "z": -9,
      "name": "Metal_Iron"
    },
    {
      "x": -32,
      "y": 28,
      "z": -9,
      "name": "Metal_Iron"
    },
    {
      "x": -32,
      "y": 29,
      "z": -9,
      "name": "Metal_Iron"
    },
    {
      "x": -32,
      "y": 26,
      "z": -8,
      "name": "Metal_Iron"
    },
    {
      "x": -32,
      "y": 29,
      "z": -8,
      "name": "Metal_Iron"
    },
    {
      "x": -32,
      "y": 26,
      "z": -7,
      "name": "Metal_Iron"
    },
    {
      "x": -32,
      "y": 27,
      "z": -7,
      "name": "Metal_Iron"
    },
    {
      "x": -32,
      "y": 29,
      "z": -7,
      "name": "Metal_Iron"
    },
    {
      "x": -32,
      "y": 26,
      "z": -6,
      "name": "Metal_Iron"
    },
    {
      "x": -32,
      "y": 27,
      "z": -6,
      "name": "Metal_Iron"
    },
    {
      "x": -32,
      "y": 29,
      "z": -6,
      "name": "Metal_Iron"
    },
    {
      "x": -32,
      "y": 30,
      "z": -6,
      "name": "Metal_Iron_Half"
    },
    {
      "x": -32,
      "y": 26,
      "z": -5,
      "name": "Metal_Iron_Half",
      "rotation": 8
    },
    {
      "x": -32,
      "y": 27,
      "z": -5,
      "name": "Metal_Iron"
    },
    {
      "x": -32,
      "y": 29,
      "z": -5,
      "name": "Metal_Iron"
    },
    {
      "x": -32,
      "y": 30,
      "z": -5,
      "name": "Metal_Iron_Half"
    },
    {
      "x": -32,
      "y": 26,
      "z": -4,
      "name": "Metal_Iron_Half",
      "rotation": 8
    },
    {
      "x": -32,
      "y": 27,
      "z": -4,
      "name": "Metal_Iron"
    },
    {
      "x": -32,
      "y": 29,
      "z": -4,
      "name": "Metal_Iron"
    },
    {
      "x": -32,
      "y": 30,
      "z": -4,
      "name": "Metal_Iron_Half"
    },
    {
      "x": -32,
      "y": 27,
      "z": -3,
      "name": "Metal_Iron"
    },
    {
      "x": -32,
      "y": 29,
      "z": -3,
      "name": "Metal_Iron"
    },
    {
      "x": -32,
      "y": 30,
      "z": -3,
      "name": "Metal_Iron_Half"
    },
    {
      "x": -32,
      "y": 27,
      "z": -2,
      "name": "Metal_Iron"
    },
    {
      "x": -32,
      "y": 28,
      "z": -2,
      "name": "Metal_Iron"
    },
    {
      "x": -32,
      "y": 29,
      "z": -2,
      "name": "Metal_Iron"
    },
    {
      "x": -32,
      "y": 30,
      "z": -2,
      "name": "Metal_Iron"
    },
    {
      "x": -32,
      "y": 27,
      "z": -1,
      "name": "Metal_Iron_Half",
      "rotation": 8
    },
    {
      "x": -32,
      "y": 28,
      "z": -1,
      "name": "Metal_Iron"
    },
    {
      "x": -32,
      "y": 29,
      "z": -1,
      "name": "Metal_Iron"
    },
    {
      "x": -32,
      "y": 30,
      "z": -1,
      "name": "Metal_Iron"
    },
    {
      "x": -32,
      "y": 27,
      "z": 0,
      "name": "Metal_Iron_Half",
      "rotation": 8
    },
    {
      "x": -32,
      "y": 28,
      "z": 0,
      "name": "Metal_Iron"
    },
    {
      "x": -32,
      "y": 29,
      "z": 0,
      "name": "Metal_Iron"
    },
    {
      "x": -32,
      "y": 30,
      "z": 0,
      "name": "Metal_Iron"
    },
    {
      "x": -32,
      "y": 28,
      "z": 1,
      "name": "Metal_Iron"
    },
    {
      "x": -32,
      "y": 29,
      "z": 1,
      "name": "Metal_Iron"
    },
    {
      "x": -32,
      "y": 30,
      "z": 1,
      "name": "Metal_Iron"
    },
    {
      "x": -32,
      "y": 28,
      "z": 2,
      "name": "Metal_Iron"
    },
    {
      "x": -32,
      "y": 29,
      "z": 2,
      "name": "Metal_Iron"
    },
    {
      "x": -32,
      "y": 30,
      "z": 2,
      "name": "Metal_Iron"
    },
    {
      "x": -32,
      "y": 31,
      "z": 2,
      "name": "Metal_Iron_Half"
    },
    {
      "x": -32,
      "y": 28,
      "z": 3,
      "name": "Metal_Iron_Half",
      "rotation": 8
    },
    {
      "x": -32,
      "y": 29,
      "z": 3,
      "name": "Metal_Iron"
    },
    {
      "x": -32,
      "y": 30,
      "z": 3,
      "name": "Metal_Iron"
    },
    {
      "x": -32,
      "y": 31,
      "z": 3,
      "name": "Metal_Iron_Half"
    },
    {
      "x": -32,
      "y": 28,
      "z": 4,
      "name": "Metal_Iron_Half",
      "rotation": 8
    },
    {
      "x": -32,
      "y": 29,
      "z": 4,
      "name": "Metal_Iron"
    },
    {
      "x": -32,
      "y": 30,
      "z": 4,
      "name": "Metal_Iron"
    },
    {
      "x": -32,
      "y": 31,
      "z": 4,
      "name": "Metal_Iron_Half"
    },
    {
      "x": -32,
      "y": 29,
      "z": 5,
      "name": "Metal_Iron"
    },
    {
      "x": -32,
      "y": 30,
      "z": 5,
      "name": "Metal_Iron"
    },
    {
      "x": -32,
      "y": 31,
      "z": 5,
      "name": "Metal_Iron_Half"
    },
    {
      "x": -32,
      "y": 29,
      "z": 6,
      "name": "Metal_Iron"
    },
    {
      "x": -32,
      "y": 30,
      "z": 6,
      "name": "Metal_Iron"
    },
    {
      "x": -32,
      "y": 31,
      "z": 6,
      "name": "Metal_Iron"
    },
    {
      "x": -32,
      "y": 29,
      "z": 7,
      "name": "Metal_Iron_Half",
      "rotation": 8
    },
    {
      "x": -32,
      "y": 30,
      "z": 7,
      "name": "Metal_Iron"
    },
    {
      "x": -32,
      "y": 31,
      "z": 7,
      "name": "Metal_Iron"
    },
    {
      "x": -32,
      "y": 32,
      "z": 7,
      "name": "Metal_Iron_Half"
    },
    {
      "x": -32,
      "y": 30,
      "z": 8,
      "name": "Metal_Iron"
    },
    {
      "x": -32,
      "y": 31,
      "z": 8,
      "name": "Metal_Iron"
    },
    {
      "x": -32,
      "y": 32,
      "z": 8,
      "name": "Metal_Iron_Half"
    },
    {
      "x": -32,
      "y": 30,
      "z": 9,
      "name": "Metal_Iron"
    },
    {
      "x": -32,
      "y": 31,
      "z": 9,
      "name": "Metal_Iron"
    },
    {
      "x": -32,
      "y": 32,
      "z": 9,
      "name": "Metal_Iron_Half"
    },
    {
      "x": -32,
      "y": 30,
      "z": 10,
      "name": "Metal_Iron_Half",
      "rotation": 8
    },
    {
      "x": -32,
      "y": 31,
      "z": 10,
      "name": "Metal_Iron"
    },
    {
      "x": -32,
      "y": 32,
      "z": 10,
      "name": "Metal_Iron"
    },
    {
      "x": -32,
      "y": 30,
      "z": 11,
      "name": "Metal_Iron_Half",
      "rotation": 8
    },
    {
      "x": -32,
      "y": 31,
      "z": 11,
      "name": "Metal_Iron"
    },
    {
      "x": -32,
      "y": 32,
      "z": 11,
      "name": "Metal_Iron"
    },
    {
      "x": -32,
      "y": 30,
      "z": 12,
      "name": "Metal_Iron_Half",
      "rotation": 8
    },
    {
      "x": -32,
      "y": 31,
      "z": 12,
      "name": "Metal_Iron"
    },
    {
      "x": -32,
      "y": 32,
      "z": 12,
      "name": "Metal_Iron"
    },
    {
      "x": -32,
      "y": 33,
      "z": 12,
      "name": "Metal_Iron_Half"
    },
    {
      "x": -32,
      "y": 31,
      "z": 13,
      "name": "Metal_Iron_Half",
      "rotation": 8
    },
    {
      "x": -32,
      "y": 32,
      "z": 13,
      "name": "Metal_Iron"
    },
    {
      "x": -32,
      "y": 33,
      "z": 13,
      "name": "Metal_Iron_Half"
    },
    {
      "x": -32,
      "y": 32,
      "z": 14,
      "name": "Metal_Iron_Half",
      "rotation": 8
    },
    {
      "x": -32,
      "y": 33,
      "z": 14,
      "name": "Metal_Iron_Half"
    },
    {
      "x": -32,
      "y": 33,
      "z": 15,
      "name": "Metal_Iron_Half"
    },
    {
      "x": -31,
      "y": 26,
      "z": -17,
      "name": "Metal_Iron"
    },
    {
      "x": -31,
      "y": 27,
      "z": -17,
      "name": "Metal_Iron"
    },
    {
      "x": -31,
      "y": 28,
      "z": -17,
      "name": "Metal_Iron"
    },
    {
      "x": -31,
      "y": 25,
      "z": -16,
      "name": "Metal_Iron"
    },
    {
      "x": -31,
      "y": 26,
      "z": -16,
      "name": "Metal_Iron"
    },
    {
      "x": -31,
      "y": 27,
      "z": -16,
      "name": "Metal_Iron"
    },
    {
      "x": -31,
      "y": 28,
      "z": -16,
      "name": "Metal_Iron"
    },
    {
      "x": -31,
      "y": 25,
      "z": -15,
      "name": "Metal_Iron"
    },
    {
      "x": -31,
      "y": 26,
      "z": -15,
      "name": "Metal_Iron"
    },
    {
      "x": -31,
      "y": 28,
      "z": -15,
      "name": "Metal_Iron"
    },
    {
      "x": -31,
      "y": 25,
      "z": -14,
      "name": "Metal_Iron"
    },
    {
      "x": -31,
      "y": 26,
      "z": -14,
      "name": "Metal_Iron"
    },
    {
      "x": -31,
      "y": 28,
      "z": -14,
      "name": "Metal_Iron"
    },
    {
      "x": -31,
      "y": 29,
      "z": -14,
      "name": "Metal_Iron_Half"
    },
    {
      "x": -31,
      "y": 25,
      "z": -13,
      "name": "Metal_Iron"
    },
    {
      "x": -31,
      "y": 26,
      "z": -13,
      "name": "Metal_Iron"
    },
    {
      "x": -31,
      "y": 28,
      "z": -13,
      "name": "Metal_Iron"
    },
    {
      "x": -31,
      "y": 29,
      "z": -13,
      "name": "Metal_Iron_Half"
    },
    {
      "x": -31,
      "y": 25,
      "z": -12,
      "name": "Metal_Iron"
    },
    {
      "x": -31,
      "y": 26,
      "z": -12,
      "name": "Metal_Iron"
    },
    {
      "x": -31,
      "y": 28,
      "z": -12,
      "name": "Metal_Iron"
    },
    {
      "x": -31,
      "y": 29,
      "z": -12,
      "name": "Metal_Iron"
    },
    {
      "x": -31,
      "y": 25,
      "z": -11,
      "name": "Metal_Iron"
    },
    {
      "x": -31,
      "y": 26,
      "z": -11,
      "name": "Metal_Iron"
    },
    {
      "x": -31,
      "y": 28,
      "z": -11,
      "name": "Metal_Iron"
    },
    {
      "x": -31,
      "y": 29,
      "z": -11,
      "name": "Metal_Iron"
    },
    {
      "x": -31,
      "y": 25,
      "z": -10,
      "name": "Metal_Iron_Half",
      "rotation": 8
    },
    {
      "x": -31,
      "y": 26,
      "z": -10,
      "name": "Metal_Iron"
    },
    {
      "x": -31,
      "y": 28,
      "z": -10,
      "name": "Metal_Iron"
    },
    {
      "x": -31,
      "y": 29,
      "z": -10,
      "name": "Metal_Iron"
    },
    {
      "x": -31,
      "y": 25,
      "z": -9,
      "name": "Metal_Iron_Half",
      "rotation": 8
    },
    {
      "x": -31,
      "y": 26,
      "z": -9,
      "name": "Metal_Iron"
    },
    {
      "x": -31,
      "y": 28,
      "z": -9,
      "name": "Metal_Iron"
    },
    {
      "x": -31,
      "y": 29,
      "z": -9,
      "name": "Metal_Iron"
    },
    {
      "x": -31,
      "y": 26,
      "z": -8,
      "name": "Metal_Iron"
    },
    {
      "x": -31,
      "y": 28,
      "z": -8,
      "name": "Metal_Iron"
    },
    {
      "x": -31,
      "y": 29,
      "z": -8,
      "name": "Metal_Iron"
    },
    {
      "x": -31,
      "y": 26,
      "z": -7,
      "name": "Metal_Iron"
    },
    {
      "x": -31,
      "y": 27,
      "z": -7,
      "name": "Metal_Iron"
    },
    {
      "x": -31,
      "y": 28,
      "z": -7,
      "name": "Metal_Iron"
    },
    {
      "x": -31,
      "y": 29,
      "z": -7,
      "name": "Metal_Iron"
    },
    {
      "x": -31,
      "y": 26,
      "z": -6,
      "name": "Metal_Iron_Half",
      "rotation": 8
    },
    {
      "x": -31,
      "y": 27,
      "z": -6,
      "name": "Metal_Iron"
    },
    {
      "x": -31,
      "y": 28,
      "z": -6,
      "name": "Metal_Iron"
    },
    {
      "x": -31,
      "y": 29,
      "z": -6,
      "name": "Metal_Iron"
    },
    {
      "x": -31,
      "y": 26,
      "z": -5,
      "name": "Metal_Iron_Half",
      "rotation": 8
    },
    {
      "x": -31,
      "y": 27,
      "z": -5,
      "name": "Metal_Iron"
    },
    {
      "x": -31,
      "y": 29,
      "z": -5,
      "name": "Metal_Iron"
    },
    {
      "x": -31,
      "y": 27,
      "z": -4,
      "name": "Metal_Iron"
    },
    {
      "x": -31,
      "y": 29,
      "z": -4,
      "name": "Metal_Iron"
    },
    {
      "x": -31,
      "y": 27,
      "z": -3,
      "name": "Metal_Iron"
    },
    {
      "x": -31,
      "y": 28,
      "z": -3,
      "name": "Metal_Iron"
    },
    {
      "x": -31,
      "y": 29,
      "z": -3,
      "name": "Metal_Iron"
    },
    {
      "x": -31,
      "y": 30,
      "z": -3,
      "name": "Metal_Iron_Half"
    },
    {
      "x": -31,
      "y": 27,
      "z": -2,
      "name": "Metal_Iron"
    },
    {
      "x": -31,
      "y": 28,
      "z": -2,
      "name": "Metal_Iron"
    },
    {
      "x": -31,
      "y": 29,
      "z": -2,
      "name": "Metal_Iron"
    },
    {
      "x": -31,
      "y": 30,
      "z": -2,
      "name": "Metal_Iron_Half"
    },
    {
      "x": -31,
      "y": 27,
      "z": -1,
      "name": "Metal_Iron_Half",
      "rotation": 8
    },
    {
      "x": -31,
      "y": 28,
      "z": -1,
      "name": "Metal_Iron"
    },
    {
      "x": -31,
      "y": 29,
      "z": -1,
      "name": "Metal_Iron"
    },
    {
      "x": -31,
      "y": 30,
      "z": -1,
      "name": "Metal_Iron_Half"
    },
    {
      "x": -31,
      "y": 28,
      "z": 0,
      "name": "Metal_Iron"
    },
    {
      "x": -31,
      "y": 29,
      "z": 0,
      "name": "Metal_Iron"
    },
    {
      "x": -31,
      "y": 30,
      "z": 0,
      "name": "Metal_Iron_Half"
    },
    {
      "x": -31,
      "y": 28,
      "z": 1,
      "name": "Metal_Iron"
    },
    {
      "x": -31,
      "y": 29,
      "z": 1,
      "name": "Metal_Iron"
    },
    {
      "x": -31,
      "y": 30,
      "z": 1,
      "name": "Metal_Iron"
    },
    {
      "x": -31,
      "y": 28,
      "z": 2,
      "name": "Metal_Iron_Half",
      "rotation": 8
    },
    {
      "x": -31,
      "y": 29,
      "z": 2,
      "name": "Metal_Iron"
    },
    {
      "x": -31,
      "y": 30,
      "z": 2,
      "name": "Metal_Iron"
    },
    {
      "x": -31,
      "y": 29,
      "z": 3,
      "name": "Metal_Iron"
    },
    {
      "x": -31,
      "y": 30,
      "z": 3,
      "name": "Metal_Iron"
    },
    {
      "x": -31,
      "y": 29,
      "z": 4,
      "name": "Metal_Iron"
    },
    {
      "x": -31,
      "y": 30,
      "z": 4,
      "name": "Metal_Iron"
    },
    {
      "x": -31,
      "y": 29,
      "z": 5,
      "name": "Metal_Iron"
    },
    {
      "x": -31,
      "y": 30,
      "z": 5,
      "name": "Metal_Iron"
    },
    {
      "x": -31,
      "y": 31,
      "z": 5,
      "name": "Metal_Iron_Half"
    },
    {
      "x": -31,
      "y": 29,
      "z": 6,
      "name": "Metal_Iron"
    },
    {
      "x": -31,
      "y": 30,
      "z": 6,
      "name": "Metal_Iron"
    },
    {
      "x": -31,
      "y": 31,
      "z": 6,
      "name": "Metal_Iron_Half"
    },
    {
      "x": -31,
      "y": 29,
      "z": 7,
      "name": "Metal_Iron_Half",
      "rotation": 8
    },
    {
      "x": -31,
      "y": 30,
      "z": 7,
      "name": "Metal_Iron"
    },
    {
      "x": -31,
      "y": 31,
      "z": 7,
      "name": "Metal_Iron"
    },
    {
      "x": -31,
      "y": 30,
      "z": 8,
      "name": "Metal_Iron"
    },
    {
      "x": -31,
      "y": 31,
      "z": 8,
      "name": "Metal_Iron"
    },
    {
      "x": -31,
      "y": 30,
      "z": 9,
      "name": "Metal_Iron_Half",
      "rotation": 8
    },
    {
      "x": -31,
      "y": 31,
      "z": 9,
      "name": "Metal_Iron"
    },
    {
      "x": -31,
      "y": 32,
      "z": 9,
      "name": "Metal_Iron_Half"
    },
    {
      "x": -31,
      "y": 30,
      "z": 10,
      "name": "Metal_Iron_Half",
      "rotation": 8
    },
    {
      "x": -31,
      "y": 31,
      "z": 10,
      "name": "Metal_Iron"
    },
    {
      "x": -31,
      "y": 32,
      "z": 10,
      "name": "Metal_Iron"
    },
    {
      "x": -31,
      "y": 30,
      "z": 11,
      "name": "Metal_Iron_Half",
      "rotation": 8
    },
    {
      "x": -31,
      "y": 31,
      "z": 11,
      "name": "Metal_Iron"
    },
    {
      "x": -31,
      "y": 32,
      "z": 11,
      "name": "Metal_Iron"
    },
    {
      "x": -31,
      "y": 31,
      "z": 12,
      "name": "Metal_Iron_Half",
      "rotation": 8
    },
    {
      "x": -31,
      "y": 32,
      "z": 12,
      "name": "Metal_Iron"
    },
    {
      "x": -31,
      "y": 32,
      "z": 13,
      "name": "Metal_Iron_Half",
      "rotation": 8
    },
    {
      "x": -30,
      "y": 26,
      "z": -19,
      "name": "Plant_Moss_Wall_Green_Dark",
      "support": 15,
      "rotation": 3
    },
    {
      "x": -30,
      "y": 25,
      "z": -18,
      "name": "Metal_Iron"
    },
    {
      "x": -30,
      "y": 26,
      "z": -18,
      "name": "Metal_Iron"
    },
    {
      "x": -30,
      "y": 27,
      "z": -18,
      "name": "Metal_Iron"
    },
    {
      "x": -30,
      "y": 25,
      "z": -17,
      "name": "Metal_Iron"
    },
    {
      "x": -30,
      "y": 26,
      "z": -17,
      "name": "Metal_Iron"
    },
    {
      "x": -30,
      "y": 27,
      "z": -17,
      "name": "Metal_Iron"
    },
    {
      "x": -30,
      "y": 28,
      "z": -17,
      "name": "Metal_Iron"
    },
    {
      "x": -30,
      "y": 25,
      "z": -16,
      "name": "Metal_Iron"
    },
    {
      "x": -30,
      "y": 26,
      "z": -16,
      "name": "Metal_Iron"
    },
    {
      "x": -30,
      "y": 27,
      "z": -16,
      "name": "Metal_Iron"
    },
    {
      "x": -30,
      "y": 28,
      "z": -16,
      "name": "Metal_Iron"
    },
    {
      "x": -30,
      "y": 25,
      "z": -15,
      "name": "Metal_Iron"
    },
    {
      "x": -30,
      "y": 26,
      "z": -15,
      "name": "Metal_Iron"
    },
    {
      "x": -30,
      "y": 28,
      "z": -15,
      "name": "Metal_Iron"
    },
    {
      "x": -30,
      "y": 25,
      "z": -14,
      "name": "Metal_Iron"
    },
    {
      "x": -30,
      "y": 26,
      "z": -14,
      "name": "Metal_Iron"
    },
    {
      "x": -30,
      "y": 28,
      "z": -14,
      "name": "Metal_Iron"
    },
    {
      "x": -30,
      "y": 25,
      "z": -13,
      "name": "Metal_Iron"
    },
    {
      "x": -30,
      "y": 26,
      "z": -13,
      "name": "Metal_Iron"
    },
    {
      "x": -30,
      "y": 28,
      "z": -13,
      "name": "Metal_Iron"
    },
    {
      "x": -30,
      "y": 25,
      "z": -12,
      "name": "Metal_Iron"
    },
    {
      "x": -30,
      "y": 26,
      "z": -12,
      "name": "Metal_Iron"
    },
    {
      "x": -30,
      "y": 28,
      "z": -12,
      "name": "Metal_Iron"
    },
    {
      "x": -30,
      "y": 29,
      "z": -12,
      "name": "Metal_Iron_Half"
    },
    {
      "x": -30,
      "y": 25,
      "z": -11,
      "name": "Metal_Iron"
    },
    {
      "x": -30,
      "y": 26,
      "z": -11,
      "name": "Metal_Iron"
    },
    {
      "x": -30,
      "y": 28,
      "z": -11,
      "name": "Metal_Iron"
    },
    {
      "x": -30,
      "y": 29,
      "z": -11,
      "name": "Metal_Iron_Half"
    },
    {
      "x": -30,
      "y": 25,
      "z": -10,
      "name": "Metal_Iron_Half",
      "rotation": 8
    },
    {
      "x": -30,
      "y": 26,
      "z": -10,
      "name": "Metal_Iron"
    },
    {
      "x": -30,
      "y": 28,
      "z": -10,
      "name": "Metal_Iron"
    },
    {
      "x": -30,
      "y": 29,
      "z": -10,
      "name": "Metal_Iron_Half"
    },
    {
      "x": -30,
      "y": 26,
      "z": -9,
      "name": "Metal_Iron"
    },
    {
      "x": -30,
      "y": 28,
      "z": -9,
      "name": "Metal_Iron"
    },
    {
      "x": -30,
      "y": 29,
      "z": -9,
      "name": "Metal_Iron_Half"
    },
    {
      "x": -30,
      "y": 26,
      "z": -8,
      "name": "Metal_Iron"
    },
    {
      "x": -30,
      "y": 27,
      "z": -8,
      "name": "Metal_Iron"
    },
    {
      "x": -30,
      "y": 28,
      "z": -8,
      "name": "Metal_Iron"
    },
    {
      "x": -30,
      "y": 29,
      "z": -8,
      "name": "Metal_Iron_Half"
    },
    {
      "x": -30,
      "y": 26,
      "z": -7,
      "name": "Metal_Iron"
    },
    {
      "x": -30,
      "y": 27,
      "z": -7,
      "name": "Metal_Iron"
    },
    {
      "x": -30,
      "y": 28,
      "z": -7,
      "name": "Metal_Iron"
    },
    {
      "x": -30,
      "y": 29,
      "z": -7,
      "name": "Metal_Iron"
    },
    {
      "x": -30,
      "y": 26,
      "z": -6,
      "name": "Metal_Iron_Half",
      "rotation": 8
    },
    {
      "x": -30,
      "y": 27,
      "z": -6,
      "name": "Metal_Iron"
    },
    {
      "x": -30,
      "y": 28,
      "z": -6,
      "name": "Metal_Iron"
    },
    {
      "x": -30,
      "y": 29,
      "z": -6,
      "name": "Metal_Iron"
    },
    {
      "x": -30,
      "y": 27,
      "z": -5,
      "name": "Metal_Iron"
    },
    {
      "x": -30,
      "y": 28,
      "z": -5,
      "name": "Metal_Iron"
    },
    {
      "x": -30,
      "y": 29,
      "z": -5,
      "name": "Metal_Iron"
    },
    {
      "x": -30,
      "y": 27,
      "z": -4,
      "name": "Metal_Iron"
    },
    {
      "x": -30,
      "y": 28,
      "z": -4,
      "name": "Metal_Iron"
    },
    {
      "x": -30,
      "y": 29,
      "z": -4,
      "name": "Metal_Iron"
    },
    {
      "x": -30,
      "y": 27,
      "z": -3,
      "name": "Metal_Iron"
    },
    {
      "x": -30,
      "y": 28,
      "z": -3,
      "name": "Metal_Iron"
    },
    {
      "x": -30,
      "y": 29,
      "z": -3,
      "name": "Metal_Iron"
    },
    {
      "x": -30,
      "y": 28,
      "z": -2,
      "name": "Metal_Iron"
    },
    {
      "x": -30,
      "y": 29,
      "z": -2,
      "name": "Metal_Iron"
    },
    {
      "x": -30,
      "y": 28,
      "z": -1,
      "name": "Metal_Iron"
    },
    {
      "x": -30,
      "y": 29,
      "z": -1,
      "name": "Metal_Iron"
    },
    {
      "x": -30,
      "y": 28,
      "z": 0,
      "name": "Metal_Iron_Half",
      "rotation": 8
    },
    {
      "x": -30,
      "y": 29,
      "z": 0,
      "name": "Metal_Iron"
    },
    {
      "x": -30,
      "y": 29,
      "z": 1,
      "name": "Metal_Iron"
    },
    {
      "x": -30,
      "y": 29,
      "z": 2,
      "name": "Metal_Iron_Half",
      "rotation": 8
    },
    {
      "x": -29,
      "y": 25,
      "z": -19,
      "name": "Metal_Iron"
    },
    {
      "x": -29,
      "y": 26,
      "z": -19,
      "name": "Metal_Iron"
    },
    {
      "x": -29,
      "y": 27,
      "z": -19,
      "name": "Metal_Iron"
    },
    {
      "x": -29,
      "y": 25,
      "z": -18,
      "name": "Metal_Iron"
    },
    {
      "x": -29,
      "y": 26,
      "z": -18,
      "name": "Metal_Iron"
    },
    {
      "x": -29,
      "y": 27,
      "z": -18,
      "name": "Metal_Iron"
    },
    {
      "x": -29,
      "y": 28,
      "z": -18,
      "name": "Metal_Iron"
    },
    {
      "x": -29,
      "y": 25,
      "z": -17,
      "name": "Metal_Iron"
    },
    {
      "x": -29,
      "y": 26,
      "z": -17,
      "name": "Metal_Iron"
    },
    {
      "x": -29,
      "y": 27,
      "z": -17,
      "name": "Metal_Iron"
    },
    {
      "x": -29,
      "y": 28,
      "z": -17,
      "name": "Metal_Iron"
    },
    {
      "x": -29,
      "y": 25,
      "z": -16,
      "name": "Metal_Iron"
    },
    {
      "x": -29,
      "y": 27,
      "z": -16,
      "name": "Metal_Iron"
    },
    {
      "x": -29,
      "y": 28,
      "z": -16,
      "name": "Metal_Iron"
    },
    {
      "x": -29,
      "y": 24,
      "z": -15,
      "name": "Metal_Iron_Half",
      "rotation": 8
    },
    {
      "x": -29,
      "y": 25,
      "z": -15,
      "name": "Metal_Iron"
    },
    {
      "x": -29,
      "y": 27,
      "z": -15,
      "name": "Metal_Iron"
    },
    {
      "x": -29,
      "y": 28,
      "z": -15,
      "name": "Metal_Iron"
    },
    {
      "x": -29,
      "y": 24,
      "z": -14,
      "name": "Metal_Iron_Half",
      "rotation": 8
    },
    {
      "x": -29,
      "y": 25,
      "z": -14,
      "name": "Metal_Iron"
    },
    {
      "x": -29,
      "y": 27,
      "z": -14,
      "name": "Metal_Iron"
    },
    {
      "x": -29,
      "y": 28,
      "z": -14,
      "name": "Metal_Iron"
    },
    {
      "x": -29,
      "y": 24,
      "z": -13,
      "name": "Metal_Iron_Half",
      "rotation": 8
    },
    {
      "x": -29,
      "y": 25,
      "z": -13,
      "name": "Metal_Iron"
    },
    {
      "x": -29,
      "y": 26,
      "z": -13,
      "name": "Metal_Iron"
    },
    {
      "x": -29,
      "y": 27,
      "z": -13,
      "name": "Metal_Iron"
    },
    {
      "x": -29,
      "y": 28,
      "z": -13,
      "name": "Metal_Iron"
    },
    {
      "x": -29,
      "y": 25,
      "z": -12,
      "name": "Metal_Iron"
    },
    {
      "x": -29,
      "y": 26,
      "z": -12,
      "name": "Metal_Iron"
    },
    {
      "x": -29,
      "y": 28,
      "z": -12,
      "name": "Metal_Iron"
    },
    {
      "x": -29,
      "y": 25,
      "z": -11,
      "name": "Metal_Iron"
    },
    {
      "x": -29,
      "y": 26,
      "z": -11,
      "name": "Metal_Iron"
    },
    {
      "x": -29,
      "y": 28,
      "z": -11,
      "name": "Metal_Iron"
    },
    {
      "x": -29,
      "y": 25,
      "z": -10,
      "name": "Metal_Iron_Half",
      "rotation": 8
    },
    {
      "x": -29,
      "y": 26,
      "z": -10,
      "name": "Metal_Iron"
    },
    {
      "x": -29,
      "y": 28,
      "z": -10,
      "name": "Metal_Iron"
    },
    {
      "x": -29,
      "y": 26,
      "z": -9,
      "name": "Metal_Iron"
    },
    {
      "x": -29,
      "y": 28,
      "z": -9,
      "name": "Metal_Iron"
    },
    {
      "x": -29,
      "y": 26,
      "z": -8,
      "name": "Metal_Iron"
    },
    {
      "x": -29,
      "y": 27,
      "z": -8,
      "name": "Metal_Iron"
    },
    {
      "x": -29,
      "y": 28,
      "z": -8,
      "name": "Metal_Iron"
    },
    {
      "x": -29,
      "y": 29,
      "z": -8,
      "name": "Metal_Iron_Half"
    },
    {
      "x": -29,
      "y": 26,
      "z": -7,
      "name": "Metal_Iron_Half",
      "rotation": 8
    },
    {
      "x": -29,
      "y": 27,
      "z": -7,
      "name": "Metal_Iron"
    },
    {
      "x": -29,
      "y": 28,
      "z": -7,
      "name": "Metal_Iron"
    },
    {
      "x": -29,
      "y": 29,
      "z": -7,
      "name": "Metal_Iron_Half"
    },
    {
      "x": -29,
      "y": 26,
      "z": -6,
      "name": "Metal_Iron_Half",
      "rotation": 8
    },
    {
      "x": -29,
      "y": 27,
      "z": -6,
      "name": "Metal_Iron"
    },
    {
      "x": -29,
      "y": 28,
      "z": -6,
      "name": "Metal_Iron"
    },
    {
      "x": -29,
      "y": 29,
      "z": -6,
      "name": "Metal_Iron_Half"
    },
    {
      "x": -29,
      "y": 27,
      "z": -5,
      "name": "Metal_Iron"
    },
    {
      "x": -29,
      "y": 28,
      "z": -5,
      "name": "Metal_Iron"
    },
    {
      "x": -29,
      "y": 29,
      "z": -5,
      "name": "Metal_Iron"
    },
    {
      "x": -29,
      "y": 27,
      "z": -4,
      "name": "Metal_Iron"
    },
    {
      "x": -29,
      "y": 28,
      "z": -4,
      "name": "Metal_Iron"
    },
    {
      "x": -29,
      "y": 29,
      "z": -4,
      "name": "Metal_Iron"
    },
    {
      "x": -29,
      "y": 28,
      "z": -3,
      "name": "Metal_Iron"
    },
    {
      "x": -29,
      "y": 29,
      "z": -3,
      "name": "Metal_Iron"
    },
    {
      "x": -28,
      "y": 25,
      "z": -20,
      "name": "Metal_Iron"
    },
    {
      "x": -28,
      "y": 26,
      "z": -20,
      "name": "Metal_Iron"
    },
    {
      "x": -28,
      "y": 27,
      "z": -20,
      "name": "Metal_Iron"
    },
    {
      "x": -28,
      "y": 25,
      "z": -19,
      "name": "Metal_Iron"
    },
    {
      "x": -28,
      "y": 26,
      "z": -19,
      "name": "Metal_Iron"
    },
    {
      "x": -28,
      "y": 27,
      "z": -19,
      "name": "Metal_Iron"
    },
    {
      "x": -28,
      "y": 28,
      "z": -19,
      "name": "Metal_Iron_Half"
    },
    {
      "x": -28,
      "y": 25,
      "z": -18,
      "name": "Metal_Iron"
    },
    {
      "x": -28,
      "y": 26,
      "z": -18,
      "name": "Metal_Iron"
    },
    {
      "x": -28,
      "y": 27,
      "z": -18,
      "name": "Metal_Iron"
    },
    {
      "x": -28,
      "y": 28,
      "z": -18,
      "name": "Metal_Iron"
    },
    {
      "x": -28,
      "y": 25,
      "z": -17,
      "name": "Metal_Iron"
    },
    {
      "x": -28,
      "y": 27,
      "z": -17,
      "name": "Metal_Iron"
    },
    {
      "x": -28,
      "y": 28,
      "z": -17,
      "name": "Metal_Iron"
    },
    {
      "x": -28,
      "y": 24,
      "z": -16,
      "name": "Metal_Iron_Half",
      "rotation": 8
    },
    {
      "x": -28,
      "y": 25,
      "z": -16,
      "name": "Metal_Iron"
    },
    {
      "x": -28,
      "y": 27,
      "z": -16,
      "name": "Metal_Iron"
    },
    {
      "x": -28,
      "y": 28,
      "z": -16,
      "name": "Metal_Iron"
    },
    {
      "x": -28,
      "y": 24,
      "z": -15,
      "name": "Metal_Iron_Half",
      "rotation": 8
    },
    {
      "x": -28,
      "y": 25,
      "z": -15,
      "name": "Metal_Iron"
    },
    {
      "x": -28,
      "y": 27,
      "z": -15,
      "name": "Metal_Iron"
    },
    {
      "x": -28,
      "y": 28,
      "z": -15,
      "name": "Metal_Iron"
    },
    {
      "x": -28,
      "y": 24,
      "z": -14,
      "name": "Metal_Iron_Half",
      "rotation": 8
    },
    {
      "x": -28,
      "y": 25,
      "z": -14,
      "name": "Metal_Iron"
    },
    {
      "x": -28,
      "y": 27,
      "z": -14,
      "name": "Metal_Iron"
    },
    {
      "x": -28,
      "y": 28,
      "z": -14,
      "name": "Metal_Iron"
    },
    {
      "x": -28,
      "y": 25,
      "z": -13,
      "name": "Metal_Iron"
    },
    {
      "x": -28,
      "y": 26,
      "z": -13,
      "name": "Metal_Iron"
    },
    {
      "x": -28,
      "y": 27,
      "z": -13,
      "name": "Metal_Iron"
    },
    {
      "x": -28,
      "y": 28,
      "z": -13,
      "name": "Metal_Iron"
    },
    {
      "x": -28,
      "y": 25,
      "z": -12,
      "name": "Metal_Iron"
    },
    {
      "x": -28,
      "y": 26,
      "z": -12,
      "name": "Metal_Iron"
    },
    {
      "x": -28,
      "y": 27,
      "z": -12,
      "name": "Metal_Iron"
    },
    {
      "x": -28,
      "y": 28,
      "z": -12,
      "name": "Metal_Iron"
    },
    {
      "x": -28,
      "y": 25,
      "z": -11,
      "name": "Metal_Iron_Half",
      "rotation": 8
    },
    {
      "x": -28,
      "y": 26,
      "z": -11,
      "name": "Metal_Iron"
    },
    {
      "x": -28,
      "y": 27,
      "z": -11,
      "name": "Metal_Iron"
    },
    {
      "x": -28,
      "y": 28,
      "z": -11,
      "name": "Metal_Iron"
    },
    {
      "x": -28,
      "y": 25,
      "z": -10,
      "name": "Metal_Iron_Half",
      "rotation": 8
    },
    {
      "x": -28,
      "y": 26,
      "z": -10,
      "name": "Metal_Iron"
    },
    {
      "x": -28,
      "y": 27,
      "z": -10,
      "name": "Metal_Iron"
    },
    {
      "x": -28,
      "y": 28,
      "z": -10,
      "name": "Metal_Iron"
    },
    {
      "x": -28,
      "y": 26,
      "z": -9,
      "name": "Metal_Iron"
    },
    {
      "x": -28,
      "y": 27,
      "z": -9,
      "name": "Metal_Iron"
    },
    {
      "x": -28,
      "y": 28,
      "z": -9,
      "name": "Metal_Iron"
    },
    {
      "x": -28,
      "y": 26,
      "z": -8,
      "name": "Metal_Iron"
    },
    {
      "x": -28,
      "y": 27,
      "z": -8,
      "name": "Metal_Iron"
    },
    {
      "x": -28,
      "y": 28,
      "z": -8,
      "name": "Metal_Iron"
    },
    {
      "x": -28,
      "y": 26,
      "z": -7,
      "name": "Metal_Iron_Half",
      "rotation": 8
    },
    {
      "x": -28,
      "y": 27,
      "z": -7,
      "name": "Metal_Iron"
    },
    {
      "x": -28,
      "y": 28,
      "z": -7,
      "name": "Metal_Iron"
    },
    {
      "x": -28,
      "y": 27,
      "z": -6,
      "name": "Metal_Iron"
    },
    {
      "x": -28,
      "y": 28,
      "z": -6,
      "name": "Metal_Iron"
    },
    {
      "x": -28,
      "y": 27,
      "z": -5,
      "name": "Metal_Iron"
    },
    {
      "x": -28,
      "y": 28,
      "z": -5,
      "name": "Metal_Iron"
    },
    {
      "x": -27,
      "y": 25,
      "z": -21,
      "name": "Metal_Iron"
    },
    {
      "x": -27,
      "y": 26,
      "z": -21,
      "name": "Metal_Iron"
    },
    {
      "x": -27,
      "y": 25,
      "z": -20,
      "name": "Metal_Iron"
    },
    {
      "x": -27,
      "y": 26,
      "z": -20,
      "name": "Metal_Iron"
    },
    {
      "x": -27,
      "y": 27,
      "z": -20,
      "name": "Metal_Iron"
    },
    {
      "x": -27,
      "y": 25,
      "z": -19,
      "name": "Metal_Iron"
    },
    {
      "x": -27,
      "y": 26,
      "z": -19,
      "name": "Metal_Iron"
    },
    {
      "x": -27,
      "y": 27,
      "z": -19,
      "name": "Metal_Iron"
    },
    {
      "x": -27,
      "y": 28,
      "z": -19,
      "name": "Metal_Iron_Half"
    },
    {
      "x": -27,
      "y": 24,
      "z": -18,
      "name": "Metal_Iron_Half",
      "rotation": 8
    },
    {
      "x": -27,
      "y": 25,
      "z": -18,
      "name": "Metal_Iron"
    },
    {
      "x": -27,
      "y": 27,
      "z": -18,
      "name": "Metal_Iron"
    },
    {
      "x": -27,
      "y": 28,
      "z": -18,
      "name": "Metal_Iron_Half"
    },
    {
      "x": -27,
      "y": 24,
      "z": -17,
      "name": "Metal_Iron_Half",
      "rotation": 8
    },
    {
      "x": -27,
      "y": 25,
      "z": -17,
      "name": "Metal_Iron"
    },
    {
      "x": -27,
      "y": 27,
      "z": -17,
      "name": "Metal_Iron"
    },
    {
      "x": -27,
      "y": 28,
      "z": -17,
      "name": "Metal_Iron"
    },
    {
      "x": -27,
      "y": 24,
      "z": -16,
      "name": "Metal_Iron_Half",
      "rotation": 8
    },
    {
      "x": -27,
      "y": 25,
      "z": -16,
      "name": "Metal_Iron"
    },
    {
      "x": -27,
      "y": 27,
      "z": -16,
      "name": "Metal_Iron"
    },
    {
      "x": -27,
      "y": 28,
      "z": -16,
      "name": "Metal_Iron"
    },
    {
      "x": -27,
      "y": 24,
      "z": -15,
      "name": "Metal_Iron_Half",
      "rotation": 8
    },
    {
      "x": -27,
      "y": 25,
      "z": -15,
      "name": "Metal_Iron"
    },
    {
      "x": -27,
      "y": 27,
      "z": -15,
      "name": "Metal_Iron"
    },
    {
      "x": -27,
      "y": 28,
      "z": -15,
      "name": "Metal_Iron"
    },
    {
      "x": -27,
      "y": 25,
      "z": -14,
      "name": "Metal_Iron"
    },
    {
      "x": -27,
      "y": 27,
      "z": -14,
      "name": "Metal_Iron"
    },
    {
      "x": -27,
      "y": 28,
      "z": -14,
      "name": "Metal_Iron"
    },
    {
      "x": -27,
      "y": 25,
      "z": -13,
      "name": "Metal_Iron"
    },
    {
      "x": -27,
      "y": 26,
      "z": -13,
      "name": "Metal_Iron"
    },
    {
      "x": -27,
      "y": 27,
      "z": -13,
      "name": "Metal_Iron"
    },
    {
      "x": -27,
      "y": 28,
      "z": -13,
      "name": "Metal_Iron"
    },
    {
      "x": -27,
      "y": 25,
      "z": -12,
      "name": "Metal_Iron"
    },
    {
      "x": -27,
      "y": 26,
      "z": -12,
      "name": "Metal_Iron"
    },
    {
      "x": -27,
      "y": 27,
      "z": -12,
      "name": "Metal_Iron"
    },
    {
      "x": -27,
      "y": 28,
      "z": -12,
      "name": "Metal_Iron"
    },
    {
      "x": -27,
      "y": 25,
      "z": -11,
      "name": "Metal_Iron_Half",
      "rotation": 8
    },
    {
      "x": -27,
      "y": 26,
      "z": -11,
      "name": "Metal_Iron"
    },
    {
      "x": -27,
      "y": 27,
      "z": -11,
      "name": "Metal_Iron"
    },
    {
      "x": -27,
      "y": 28,
      "z": -11,
      "name": "Metal_Iron"
    },
    {
      "x": -27,
      "y": 26,
      "z": -10,
      "name": "Metal_Iron"
    },
    {
      "x": -27,
      "y": 27,
      "z": -10,
      "name": "Metal_Iron"
    },
    {
      "x": -27,
      "y": 28,
      "z": -10,
      "name": "Metal_Iron"
    },
    {
      "x": -27,
      "y": 26,
      "z": -9,
      "name": "Metal_Iron_Half",
      "rotation": 8
    },
    {
      "x": -27,
      "y": 27,
      "z": -9,
      "name": "Metal_Iron"
    },
    {
      "x": -27,
      "y": 28,
      "z": -9,
      "name": "Metal_Iron"
    },
    {
      "x": -27,
      "y": 26,
      "z": -8,
      "name": "Metal_Iron_Half",
      "rotation": 8
    },
    {
      "x": -27,
      "y": 27,
      "z": -8,
      "name": "Metal_Iron"
    },
    {
      "x": -27,
      "y": 28,
      "z": -8,
      "name": "Metal_Iron"
    },
    {
      "x": -27,
      "y": 27,
      "z": -7,
      "name": "Metal_Iron"
    },
    {
      "x": -27,
      "y": 28,
      "z": -7,
      "name": "Metal_Iron"
    },
    {
      "x": -26,
      "y": 26,
      "z": -22,
      "name": "Metal_Iron"
    },
    {
      "x": -26,
      "y": 25,
      "z": -21,
      "name": "Metal_Iron"
    },
    {
      "x": -26,
      "y": 26,
      "z": -21,
      "name": "Metal_Iron"
    },
    {
      "x": -26,
      "y": 27,
      "z": -21,
      "name": "Metal_Iron_Half"
    },
    {
      "x": -26,
      "y": 25,
      "z": -20,
      "name": "Metal_Iron"
    },
    {
      "x": -26,
      "y": 26,
      "z": -20,
      "name": "Metal_Iron"
    },
    {
      "x": -26,
      "y": 27,
      "z": -20,
      "name": "Metal_Iron"
    },
    {
      "x": -26,
      "y": 24,
      "z": -19,
      "name": "Metal_Iron_Half",
      "rotation": 8
    },
    {
      "x": -26,
      "y": 25,
      "z": -19,
      "name": "Metal_Iron"
    },
    {
      "x": -26,
      "y": 27,
      "z": -19,
      "name": "Metal_Iron"
    },
    {
      "x": -26,
      "y": 24,
      "z": -18,
      "name": "Metal_Iron_Half",
      "rotation": 8
    },
    {
      "x": -26,
      "y": 25,
      "z": -18,
      "name": "Metal_Iron"
    },
    {
      "x": -26,
      "y": 27,
      "z": -18,
      "name": "Metal_Iron"
    },
    {
      "x": -26,
      "y": 28,
      "z": -18,
      "name": "Metal_Iron_Half"
    },
    {
      "x": -26,
      "y": 24,
      "z": -17,
      "name": "Metal_Iron"
    },
    {
      "x": -26,
      "y": 25,
      "z": -17,
      "name": "Metal_Iron"
    },
    {
      "x": -26,
      "y": 27,
      "z": -17,
      "name": "Metal_Iron"
    },
    {
      "x": -26,
      "y": 28,
      "z": -17,
      "name": "Metal_Iron_Half"
    },
    {
      "x": -26,
      "y": 24,
      "z": -16,
      "name": "Metal_Iron_Half",
      "rotation": 8
    },
    {
      "x": -26,
      "y": 25,
      "z": -16,
      "name": "Metal_Iron"
    },
    {
      "x": -26,
      "y": 27,
      "z": -16,
      "name": "Metal_Iron"
    },
    {
      "x": -26,
      "y": 28,
      "z": -16,
      "name": "Metal_Iron_Half"
    },
    {
      "x": -26,
      "y": 25,
      "z": -15,
      "name": "Metal_Iron"
    },
    {
      "x": -26,
      "y": 27,
      "z": -15,
      "name": "Metal_Iron"
    },
    {
      "x": -26,
      "y": 28,
      "z": -15,
      "name": "Metal_Iron_Half"
    },
    {
      "x": -26,
      "y": 25,
      "z": -14,
      "name": "Metal_Iron"
    },
    {
      "x": -26,
      "y": 27,
      "z": -14,
      "name": "Metal_Iron"
    },
    {
      "x": -26,
      "y": 28,
      "z": -14,
      "name": "Metal_Iron_Half"
    },
    {
      "x": -26,
      "y": 25,
      "z": -13,
      "name": "Metal_Iron"
    },
    {
      "x": -26,
      "y": 26,
      "z": -13,
      "name": "Metal_Iron"
    },
    {
      "x": -26,
      "y": 27,
      "z": -13,
      "name": "Metal_Iron"
    },
    {
      "x": -26,
      "y": 28,
      "z": -13,
      "name": "Metal_Iron_Half"
    },
    {
      "x": -26,
      "y": 25,
      "z": -12,
      "name": "Metal_Iron_Half",
      "rotation": 8
    },
    {
      "x": -26,
      "y": 26,
      "z": -12,
      "name": "Metal_Iron"
    },
    {
      "x": -26,
      "y": 27,
      "z": -12,
      "name": "Metal_Iron"
    },
    {
      "x": -26,
      "y": 28,
      "z": -12,
      "name": "Metal_Iron_Half"
    },
    {
      "x": -26,
      "y": 25,
      "z": -11,
      "name": "Metal_Iron_Half",
      "rotation": 8
    },
    {
      "x": -26,
      "y": 26,
      "z": -11,
      "name": "Metal_Iron"
    },
    {
      "x": -26,
      "y": 27,
      "z": -11,
      "name": "Metal_Iron"
    },
    {
      "x": -26,
      "y": 28,
      "z": -11,
      "name": "Metal_Iron_Half"
    },
    {
      "x": -26,
      "y": 26,
      "z": -10,
      "name": "Metal_Iron_Half",
      "rotation": 8
    },
    {
      "x": -26,
      "y": 27,
      "z": -10,
      "name": "Metal_Iron"
    },
    {
      "x": -26,
      "y": 28,
      "z": -10,
      "name": "Metal_Iron_Half"
    },
    {
      "x": -26,
      "y": 26,
      "z": -9,
      "name": "Metal_Iron_Half",
      "rotation": 8
    },
    {
      "x": -26,
      "y": 27,
      "z": -9,
      "name": "Metal_Iron"
    },
    {
      "x": -26,
      "y": 27,
      "z": -8,
      "name": "Metal_Iron"
    },
    {
      "x": -25,
      "y": 25,
      "z": -22,
      "name": "Metal_Iron"
    },
    {
      "x": -25,
      "y": 26,
      "z": -22,
      "name": "Metal_Iron"
    },
    {
      "x": -25,
      "y": 25,
      "z": -21,
      "name": "Metal_Iron"
    },
    {
      "x": -25,
      "y": 26,
      "z": -21,
      "name": "Metal_Iron"
    },
    {
      "x": -25,
      "y": 27,
      "z": -21,
      "name": "Metal_Iron_Half"
    },
    {
      "x": -25,
      "y": 24,
      "z": -20,
      "name": "Metal_Iron_Half",
      "rotation": 8
    },
    {
      "x": -25,
      "y": 25,
      "z": -20,
      "name": "Metal_Iron"
    },
    {
      "x": -25,
      "y": 27,
      "z": -20,
      "name": "Metal_Iron"
    },
    {
      "x": -25,
      "y": 24,
      "z": -19,
      "name": "Metal_Iron_Half",
      "rotation": 8
    },
    {
      "x": -25,
      "y": 25,
      "z": -19,
      "name": "Metal_Iron"
    },
    {
      "x": -25,
      "y": 27,
      "z": -19,
      "name": "Metal_Iron"
    },
    {
      "x": -25,
      "y": 24,
      "z": -18,
      "name": "Metal_Iron"
    },
    {
      "x": -25,
      "y": 25,
      "z": -18,
      "name": "Metal_Iron"
    },
    {
      "x": -25,
      "y": 27,
      "z": -18,
      "name": "Metal_Iron"
    },
    {
      "x": -25,
      "y": 24,
      "z": -17,
      "name": "Metal_Iron"
    },
    {
      "x": -25,
      "y": 25,
      "z": -17,
      "name": "Metal_Iron"
    },
    {
      "x": -25,
      "y": 27,
      "z": -17,
      "name": "Metal_Iron"
    },
    {
      "x": -25,
      "y": 24,
      "z": -16,
      "name": "Metal_Iron_Half",
      "rotation": 8
    },
    {
      "x": -25,
      "y": 25,
      "z": -16,
      "name": "Metal_Iron"
    },
    {
      "x": -25,
      "y": 27,
      "z": -16,
      "name": "Metal_Iron"
    },
    {
      "x": -25,
      "y": 25,
      "z": -15,
      "name": "Metal_Iron"
    },
    {
      "x": -25,
      "y": 27,
      "z": -15,
      "name": "Metal_Iron"
    },
    {
      "x": -25,
      "y": 25,
      "z": -14,
      "name": "Metal_Iron"
    },
    {
      "x": -25,
      "y": 26,
      "z": -14,
      "name": "Metal_Iron"
    },
    {
      "x": -25,
      "y": 27,
      "z": -14,
      "name": "Metal_Iron"
    },
    {
      "x": -25,
      "y": 25,
      "z": -13,
      "name": "Metal_Iron"
    },
    {
      "x": -25,
      "y": 26,
      "z": -13,
      "name": "Metal_Iron"
    },
    {
      "x": -25,
      "y": 27,
      "z": -13,
      "name": "Metal_Iron"
    },
    {
      "x": -25,
      "y": 25,
      "z": -12,
      "name": "Metal_Iron_Half",
      "rotation": 8
    },
    {
      "x": -25,
      "y": 26,
      "z": -12,
      "name": "Metal_Iron"
    },
    {
      "x": -25,
      "y": 27,
      "z": -12,
      "name": "Metal_Iron"
    },
    {
      "x": -25,
      "y": 26,
      "z": -11,
      "name": "Metal_Iron"
    },
    {
      "x": -25,
      "y": 27,
      "z": -11,
      "name": "Metal_Iron"
    },
    {
      "x": -25,
      "y": 26,
      "z": -10,
      "name": "Metal_Iron_Half",
      "rotation": 8
    },
    {
      "x": -25,
      "y": 27,
      "z": -10,
      "name": "Metal_Iron"
    },
    {
      "x": -25,
      "y": 27,
      "z": -9,
      "name": "Metal_Iron"
    },
    {
      "x": -24,
      "y": 25,
      "z": -23,
      "name": "Metal_Iron"
    },
    {
      "x": -24,
      "y": 26,
      "z": -23,
      "name": "Metal_Iron"
    },
    {
      "x": -24,
      "y": 25,
      "z": -22,
      "name": "Metal_Iron"
    },
    {
      "x": -24,
      "y": 26,
      "z": -22,
      "name": "Metal_Iron"
    },
    {
      "x": -24,
      "y": 27,
      "z": -22,
      "name": "Metal_Iron_Half"
    },
    {
      "x": -24,
      "y": 25,
      "z": -21,
      "name": "Metal_Iron"
    },
    {
      "x": -24,
      "y": 26,
      "z": -21,
      "name": "Metal_Iron"
    },
    {
      "x": -24,
      "y": 27,
      "z": -21,
      "name": "Metal_Iron"
    },
    {
      "x": -24,
      "y": 24,
      "z": -20,
      "name": "Metal_Iron_Half",
      "rotation": 8
    },
    {
      "x": -24,
      "y": 25,
      "z": -20,
      "name": "Metal_Iron"
    },
    {
      "x": -24,
      "y": 26,
      "z": -20,
      "name": "Metal_Iron"
    },
    {
      "x": -24,
      "y": 27,
      "z": -20,
      "name": "Metal_Iron"
    },
    {
      "x": -24,
      "y": 24,
      "z": -19,
      "name": "Metal_Iron"
    },
    {
      "x": -24,
      "y": 25,
      "z": -19,
      "name": "Metal_Iron"
    },
    {
      "x": -24,
      "y": 27,
      "z": -19,
      "name": "Metal_Iron"
    },
    {
      "x": -24,
      "y": 24,
      "z": -18,
      "name": "Metal_Iron"
    },
    {
      "x": -24,
      "y": 25,
      "z": -18,
      "name": "Metal_Iron"
    },
    {
      "x": -24,
      "y": 27,
      "z": -18,
      "name": "Metal_Iron"
    },
    {
      "x": -24,
      "y": 24,
      "z": -17,
      "name": "Metal_Iron"
    },
    {
      "x": -24,
      "y": 25,
      "z": -17,
      "name": "Metal_Iron"
    },
    {
      "x": -24,
      "y": 26,
      "z": -17,
      "name": "Metal_Iron"
    },
    {
      "x": -24,
      "y": 27,
      "z": -17,
      "name": "Metal_Iron"
    },
    {
      "x": -24,
      "y": 24,
      "z": -16,
      "name": "Metal_Iron_Half",
      "rotation": 8
    },
    {
      "x": -24,
      "y": 25,
      "z": -16,
      "name": "Metal_Iron"
    },
    {
      "x": -24,
      "y": 26,
      "z": -16,
      "name": "Metal_Iron"
    },
    {
      "x": -24,
      "y": 27,
      "z": -16,
      "name": "Metal_Iron"
    },
    {
      "x": -24,
      "y": 25,
      "z": -15,
      "name": "Metal_Iron"
    },
    {
      "x": -24,
      "y": 26,
      "z": -15,
      "name": "Metal_Iron"
    },
    {
      "x": -24,
      "y": 27,
      "z": -15,
      "name": "Metal_Iron"
    },
    {
      "x": -24,
      "y": 25,
      "z": -14,
      "name": "Metal_Iron"
    },
    {
      "x": -24,
      "y": 26,
      "z": -14,
      "name": "Metal_Iron"
    },
    {
      "x": -24,
      "y": 27,
      "z": -14,
      "name": "Metal_Iron"
    },
    {
      "x": -24,
      "y": 25,
      "z": -13,
      "name": "Metal_Iron"
    },
    {
      "x": -24,
      "y": 26,
      "z": -13,
      "name": "Metal_Iron"
    },
    {
      "x": -24,
      "y": 27,
      "z": -13,
      "name": "Metal_Iron"
    },
    {
      "x": -24,
      "y": 25,
      "z": -12,
      "name": "Metal_Iron_Half",
      "rotation": 8
    },
    {
      "x": -24,
      "y": 26,
      "z": -12,
      "name": "Metal_Iron"
    },
    {
      "x": -24,
      "y": 27,
      "z": -12,
      "name": "Metal_Iron"
    },
    {
      "x": -24,
      "y": 26,
      "z": -11,
      "name": "Metal_Iron"
    },
    {
      "x": -24,
      "y": 27,
      "z": -11,
      "name": "Metal_Iron"
    },
    {
      "x": -24,
      "y": 26,
      "z": -10,
      "name": "Metal_Iron_Half",
      "rotation": 8
    },
    {
      "x": -24,
      "y": 27,
      "z": -10,
      "name": "Metal_Iron"
    },
    {
      "x": -23,
      "y": 25,
      "z": -23,
      "name": "Metal_Iron"
    },
    {
      "x": -23,
      "y": 26,
      "z": -23,
      "name": "Metal_Iron"
    },
    {
      "x": -23,
      "y": 25,
      "z": -22,
      "name": "Metal_Iron"
    },
    {
      "x": -23,
      "y": 26,
      "z": -22,
      "name": "Metal_Iron"
    },
    {
      "x": -23,
      "y": 27,
      "z": -22,
      "name": "Metal_Iron_Half"
    },
    {
      "x": -23,
      "y": 24,
      "z": -21,
      "name": "Metal_Iron_Half",
      "rotation": 8
    },
    {
      "x": -23,
      "y": 25,
      "z": -21,
      "name": "Metal_Iron"
    },
    {
      "x": -23,
      "y": 26,
      "z": -21,
      "name": "Metal_Iron"
    },
    {
      "x": -23,
      "y": 27,
      "z": -21,
      "name": "Metal_Iron"
    },
    {
      "x": -23,
      "y": 24,
      "z": -20,
      "name": "Metal_Iron"
    },
    {
      "x": -23,
      "y": 25,
      "z": -20,
      "name": "Metal_Iron"
    },
    {
      "x": -23,
      "y": 26,
      "z": -20,
      "name": "Metal_Iron"
    },
    {
      "x": -23,
      "y": 27,
      "z": -20,
      "name": "Metal_Iron"
    },
    {
      "x": -23,
      "y": 24,
      "z": -19,
      "name": "Metal_Iron"
    },
    {
      "x": -23,
      "y": 25,
      "z": -19,
      "name": "Metal_Iron"
    },
    {
      "x": -23,
      "y": 26,
      "z": -19,
      "name": "Metal_Iron"
    },
    {
      "x": -23,
      "y": 27,
      "z": -19,
      "name": "Metal_Iron"
    },
    {
      "x": -23,
      "y": 24,
      "z": -18,
      "name": "Metal_Iron"
    },
    {
      "x": -23,
      "y": 25,
      "z": -18,
      "name": "Metal_Iron"
    },
    {
      "x": -23,
      "y": 26,
      "z": -18,
      "name": "Metal_Iron"
    },
    {
      "x": -23,
      "y": 27,
      "z": -18,
      "name": "Metal_Iron"
    },
    {
      "x": -23,
      "y": 24,
      "z": -17,
      "name": "Metal_Iron"
    },
    {
      "x": -23,
      "y": 25,
      "z": -17,
      "name": "Metal_Iron"
    },
    {
      "x": -23,
      "y": 26,
      "z": -17,
      "name": "Metal_Iron"
    },
    {
      "x": -23,
      "y": 27,
      "z": -17,
      "name": "Metal_Iron"
    },
    {
      "x": -23,
      "y": 24,
      "z": -16,
      "name": "Metal_Iron_Half",
      "rotation": 8
    },
    {
      "x": -23,
      "y": 25,
      "z": -16,
      "name": "Metal_Iron"
    },
    {
      "x": -23,
      "y": 26,
      "z": -16,
      "name": "Metal_Iron"
    },
    {
      "x": -23,
      "y": 27,
      "z": -16,
      "name": "Metal_Iron"
    },
    {
      "x": -23,
      "y": 25,
      "z": -15,
      "name": "Metal_Iron"
    },
    {
      "x": -23,
      "y": 26,
      "z": -15,
      "name": "Metal_Iron"
    },
    {
      "x": -23,
      "y": 27,
      "z": -15,
      "name": "Metal_Iron"
    },
    {
      "x": -23,
      "y": 25,
      "z": -14,
      "name": "Metal_Iron"
    },
    {
      "x": -23,
      "y": 26,
      "z": -14,
      "name": "Metal_Iron"
    },
    {
      "x": -23,
      "y": 27,
      "z": -14,
      "name": "Metal_Iron"
    },
    {
      "x": -23,
      "y": 25,
      "z": -13,
      "name": "Metal_Iron"
    },
    {
      "x": -23,
      "y": 26,
      "z": -13,
      "name": "Metal_Iron"
    },
    {
      "x": -23,
      "y": 27,
      "z": -13,
      "name": "Metal_Iron"
    },
    {
      "x": -23,
      "y": 25,
      "z": -12,
      "name": "Metal_Iron_Half",
      "rotation": 8
    },
    {
      "x": -23,
      "y": 26,
      "z": -12,
      "name": "Metal_Iron"
    },
    {
      "x": -23,
      "y": 27,
      "z": -12,
      "name": "Metal_Iron"
    },
    {
      "x": -23,
      "y": 26,
      "z": -11,
      "name": "Metal_Iron_Half",
      "rotation": 8
    },
    {
      "x": -22,
      "y": 25,
      "z": -24,
      "name": "Metal_Iron"
    },
    {
      "x": -22,
      "y": 25,
      "z": -23,
      "name": "Metal_Iron"
    },
    {
      "x": -22,
      "y": 26,
      "z": -23,
      "name": "Metal_Iron_Half"
    },
    {
      "x": -22,
      "y": 24,
      "z": -22,
      "name": "Metal_Iron_Half",
      "rotation": 8
    },
    {
      "x": -22,
      "y": 25,
      "z": -22,
      "name": "Metal_Iron"
    },
    {
      "x": -22,
      "y": 26,
      "z": -22,
      "name": "Metal_Iron"
    },
    {
      "x": -22,
      "y": 27,
      "z": -22,
      "name": "Metal_Iron_Half"
    },
    {
      "x": -22,
      "y": 24,
      "z": -21,
      "name": "Metal_Iron_Half",
      "rotation": 8
    },
    {
      "x": -22,
      "y": 25,
      "z": -21,
      "name": "Metal_Iron"
    },
    {
      "x": -22,
      "y": 26,
      "z": -21,
      "name": "Metal_Iron"
    },
    {
      "x": -22,
      "y": 27,
      "z": -21,
      "name": "Metal_Iron"
    },
    {
      "x": -22,
      "y": 24,
      "z": -20,
      "name": "Metal_Iron"
    },
    {
      "x": -22,
      "y": 25,
      "z": -20,
      "name": "Metal_Iron"
    },
    {
      "x": -22,
      "y": 26,
      "z": -20,
      "name": "Metal_Iron"
    },
    {
      "x": -22,
      "y": 27,
      "z": -20,
      "name": "Metal_Iron"
    },
    {
      "x": -22,
      "y": 24,
      "z": -19,
      "name": "Metal_Iron"
    },
    {
      "x": -22,
      "y": 25,
      "z": -19,
      "name": "Metal_Iron"
    },
    {
      "x": -22,
      "y": 26,
      "z": -19,
      "name": "Metal_Iron"
    },
    {
      "x": -22,
      "y": 27,
      "z": -19,
      "name": "Metal_Iron"
    },
    {
      "x": -22,
      "y": 24,
      "z": -18,
      "name": "Metal_Iron"
    },
    {
      "x": -22,
      "y": 25,
      "z": -18,
      "name": "Metal_Iron"
    },
    {
      "x": -22,
      "y": 26,
      "z": -18,
      "name": "Metal_Iron"
    },
    {
      "x": -22,
      "y": 27,
      "z": -18,
      "name": "Metal_Iron"
    },
    {
      "x": -22,
      "y": 24,
      "z": -17,
      "name": "Metal_Iron"
    },
    {
      "x": -22,
      "y": 25,
      "z": -17,
      "name": "Metal_Iron"
    },
    {
      "x": -22,
      "y": 26,
      "z": -17,
      "name": "Metal_Iron"
    },
    {
      "x": -22,
      "y": 27,
      "z": -17,
      "name": "Metal_Iron"
    },
    {
      "x": -22,
      "y": 24,
      "z": -16,
      "name": "Metal_Iron_Half",
      "rotation": 8
    },
    {
      "x": -22,
      "y": 25,
      "z": -16,
      "name": "Metal_Iron"
    },
    {
      "x": -22,
      "y": 26,
      "z": -16,
      "name": "Metal_Iron"
    },
    {
      "x": -22,
      "y": 27,
      "z": -16,
      "name": "Metal_Iron"
    },
    {
      "x": -22,
      "y": 25,
      "z": -15,
      "name": "Metal_Iron"
    },
    {
      "x": -22,
      "y": 26,
      "z": -15,
      "name": "Metal_Iron"
    },
    {
      "x": -22,
      "y": 27,
      "z": -15,
      "name": "Metal_Iron"
    },
    {
      "x": -22,
      "y": 25,
      "z": -14,
      "name": "Metal_Iron"
    },
    {
      "x": -22,
      "y": 26,
      "z": -14,
      "name": "Metal_Iron"
    },
    {
      "x": -22,
      "y": 27,
      "z": -14,
      "name": "Metal_Iron"
    },
    {
      "x": -22,
      "y": 25,
      "z": -13,
      "name": "Metal_Iron"
    },
    {
      "x": -22,
      "y": 26,
      "z": -13,
      "name": "Metal_Iron"
    },
    {
      "x": -22,
      "y": 27,
      "z": -13,
      "name": "Metal_Iron"
    },
    {
      "x": -22,
      "y": 26,
      "z": -12,
      "name": "Metal_Iron"
    },
    {
      "x": -22,
      "y": 27,
      "z": -12,
      "name": "Metal_Iron"
    },
    {
      "x": -21,
      "y": 25,
      "z": -24,
      "name": "Metal_Iron"
    },
    {
      "x": -21,
      "y": 26,
      "z": -24,
      "name": "Metal_Iron_Half"
    },
    {
      "x": -21,
      "y": 24,
      "z": -23,
      "name": "Metal_Iron_Half",
      "rotation": 8
    },
    {
      "x": -21,
      "y": 25,
      "z": -23,
      "name": "Metal_Iron"
    },
    {
      "x": -21,
      "y": 26,
      "z": -23,
      "name": "Metal_Iron"
    },
    {
      "x": -21,
      "y": 24,
      "z": -22,
      "name": "Metal_Iron_Half",
      "rotation": 8
    },
    {
      "x": -21,
      "y": 25,
      "z": -22,
      "name": "Metal_Iron"
    },
    {
      "x": -21,
      "y": 26,
      "z": -22,
      "name": "Metal_Iron"
    },
    {
      "x": -21,
      "y": 27,
      "z": -22,
      "name": "Metal_Iron_Half"
    },
    {
      "x": -21,
      "y": 24,
      "z": -21,
      "name": "Metal_Iron"
    },
    {
      "x": -21,
      "y": 25,
      "z": -21,
      "name": "Metal_Iron"
    },
    {
      "x": -21,
      "y": 26,
      "z": -21,
      "name": "Metal_Iron"
    },
    {
      "x": -21,
      "y": 27,
      "z": -21,
      "name": "Metal_Iron_Half"
    },
    {
      "x": -21,
      "y": 24,
      "z": -20,
      "name": "Metal_Iron"
    },
    {
      "x": -21,
      "y": 25,
      "z": -20,
      "name": "Metal_Iron"
    },
    {
      "x": -21,
      "y": 26,
      "z": -20,
      "name": "Metal_Iron"
    },
    {
      "x": -21,
      "y": 27,
      "z": -20,
      "name": "Metal_Iron"
    },
    {
      "x": -21,
      "y": 24,
      "z": -19,
      "name": "Metal_Iron"
    },
    {
      "x": -21,
      "y": 25,
      "z": -19,
      "name": "Metal_Iron"
    },
    {
      "x": -21,
      "y": 26,
      "z": -19,
      "name": "Metal_Iron"
    },
    {
      "x": -21,
      "y": 27,
      "z": -19,
      "name": "Metal_Iron"
    },
    {
      "x": -21,
      "y": 24,
      "z": -18,
      "name": "Metal_Iron"
    },
    {
      "x": -21,
      "y": 25,
      "z": -18,
      "name": "Metal_Iron"
    },
    {
      "x": -21,
      "y": 26,
      "z": -18,
      "name": "Metal_Iron"
    },
    {
      "x": -21,
      "y": 27,
      "z": -18,
      "name": "Metal_Iron"
    },
    {
      "x": -21,
      "y": 24,
      "z": -17,
      "name": "Metal_Iron"
    },
    {
      "x": -21,
      "y": 25,
      "z": -17,
      "name": "Metal_Iron"
    },
    {
      "x": -21,
      "y": 26,
      "z": -17,
      "name": "Metal_Iron"
    },
    {
      "x": -21,
      "y": 27,
      "z": -17,
      "name": "Metal_Iron"
    },
    {
      "x": -21,
      "y": 24,
      "z": -16,
      "name": "Metal_Iron_Half",
      "rotation": 8
    },
    {
      "x": -21,
      "y": 25,
      "z": -16,
      "name": "Metal_Iron"
    },
    {
      "x": -21,
      "y": 26,
      "z": -16,
      "name": "Metal_Iron"
    },
    {
      "x": -21,
      "y": 27,
      "z": -16,
      "name": "Metal_Iron"
    },
    {
      "x": -21,
      "y": 25,
      "z": -15,
      "name": "Metal_Iron"
    },
    {
      "x": -21,
      "y": 26,
      "z": -15,
      "name": "Metal_Iron"
    },
    {
      "x": -21,
      "y": 27,
      "z": -15,
      "name": "Metal_Iron"
    },
    {
      "x": -21,
      "y": 25,
      "z": -14,
      "name": "Metal_Iron"
    },
    {
      "x": -21,
      "y": 26,
      "z": -14,
      "name": "Metal_Iron"
    },
    {
      "x": -21,
      "y": 27,
      "z": -14,
      "name": "Metal_Iron"
    },
    {
      "x": -21,
      "y": 25,
      "z": -13,
      "name": "Metal_Iron"
    },
    {
      "x": -21,
      "y": 26,
      "z": -13,
      "name": "Metal_Iron"
    },
    {
      "x": -21,
      "y": 27,
      "z": -13,
      "name": "Metal_Iron"
    },
    {
      "x": -20,
      "y": 25,
      "z": -25,
      "name": "Metal_Iron"
    },
    {
      "x": -20,
      "y": 24,
      "z": -24,
      "name": "Metal_Iron_Half",
      "rotation": 8
    },
    {
      "x": -20,
      "y": 25,
      "z": -24,
      "name": "Metal_Iron"
    },
    {
      "x": -20,
      "y": 26,
      "z": -24,
      "name": "Metal_Iron_Half"
    },
    {
      "x": -20,
      "y": 24,
      "z": -23,
      "name": "Metal_Iron_Half",
      "rotation": 8
    },
    {
      "x": -20,
      "y": 25,
      "z": -23,
      "name": "Metal_Iron"
    },
    {
      "x": -20,
      "y": 26,
      "z": -23,
      "name": "Metal_Iron"
    },
    {
      "x": -20,
      "y": 24,
      "z": -22,
      "name": "Metal_Iron"
    },
    {
      "x": -20,
      "y": 25,
      "z": -22,
      "name": "Metal_Iron"
    },
    {
      "x": -20,
      "y": 26,
      "z": -22,
      "name": "Metal_Iron"
    },
    {
      "x": -20,
      "y": 24,
      "z": -21,
      "name": "Metal_Iron"
    },
    {
      "x": -20,
      "y": 25,
      "z": -21,
      "name": "Metal_Iron"
    },
    {
      "x": -20,
      "y": 26,
      "z": -21,
      "name": "Metal_Iron"
    },
    {
      "x": -20,
      "y": 27,
      "z": -21,
      "name": "Metal_Iron_Half"
    },
    {
      "x": -20,
      "y": 24,
      "z": -20,
      "name": "Metal_Iron"
    },
    {
      "x": -20,
      "y": 25,
      "z": -20,
      "name": "Metal_Iron"
    },
    {
      "x": -20,
      "y": 26,
      "z": -20,
      "name": "Metal_Iron"
    },
    {
      "x": -20,
      "y": 27,
      "z": -20,
      "name": "Metal_Iron_Half"
    },
    {
      "x": -20,
      "y": 24,
      "z": -19,
      "name": "Metal_Iron"
    },
    {
      "x": -20,
      "y": 25,
      "z": -19,
      "name": "Metal_Iron"
    },
    {
      "x": -20,
      "y": 26,
      "z": -19,
      "name": "Metal_Iron"
    },
    {
      "x": -20,
      "y": 27,
      "z": -19,
      "name": "Metal_Iron_Half"
    },
    {
      "x": -20,
      "y": 24,
      "z": -18,
      "name": "Metal_Iron"
    },
    {
      "x": -20,
      "y": 25,
      "z": -18,
      "name": "Metal_Iron"
    },
    {
      "x": -20,
      "y": 26,
      "z": -18,
      "name": "Metal_Iron"
    },
    {
      "x": -20,
      "y": 27,
      "z": -18,
      "name": "Metal_Iron"
    },
    {
      "x": -20,
      "y": 24,
      "z": -17,
      "name": "Metal_Iron_Half",
      "rotation": 8
    },
    {
      "x": -20,
      "y": 25,
      "z": -17,
      "name": "Metal_Iron"
    },
    {
      "x": -20,
      "y": 26,
      "z": -17,
      "name": "Metal_Iron"
    },
    {
      "x": -20,
      "y": 27,
      "z": -17,
      "name": "Metal_Iron"
    },
    {
      "x": -20,
      "y": 24,
      "z": -16,
      "name": "Metal_Iron_Half",
      "rotation": 8
    },
    {
      "x": -20,
      "y": 25,
      "z": -16,
      "name": "Metal_Iron"
    },
    {
      "x": -20,
      "y": 26,
      "z": -16,
      "name": "Metal_Iron"
    },
    {
      "x": -20,
      "y": 27,
      "z": -16,
      "name": "Metal_Iron"
    },
    {
      "x": -20,
      "y": 25,
      "z": -15,
      "name": "Metal_Iron"
    },
    {
      "x": -20,
      "y": 26,
      "z": -15,
      "name": "Metal_Iron"
    },
    {
      "x": -20,
      "y": 27,
      "z": -15,
      "name": "Metal_Iron"
    },
    {
      "x": -20,
      "y": 25,
      "z": -14,
      "name": "Metal_Iron"
    },
    {
      "x": -20,
      "y": 26,
      "z": -14,
      "name": "Metal_Iron"
    },
    {
      "x": -20,
      "y": 27,
      "z": -14,
      "name": "Metal_Iron"
    },
    {
      "x": -20,
      "y": 25,
      "z": -13,
      "name": "Metal_Iron"
    },
    {
      "x": -20,
      "y": 26,
      "z": -13,
      "name": "Metal_Iron"
    },
    {
      "x": -19,
      "y": 24,
      "z": -25,
      "name": "Metal_Iron_Half",
      "rotation": 8
    },
    {
      "x": -19,
      "y": 25,
      "z": -25,
      "name": "Metal_Iron"
    },
    {
      "x": -19,
      "y": 24,
      "z": -24,
      "name": "Metal_Iron_Half",
      "rotation": 8
    },
    {
      "x": -19,
      "y": 25,
      "z": -24,
      "name": "Metal_Iron"
    },
    {
      "x": -19,
      "y": 26,
      "z": -24,
      "name": "Metal_Iron"
    },
    {
      "x": -19,
      "y": 24,
      "z": -23,
      "name": "Metal_Iron"
    },
    {
      "x": -19,
      "y": 25,
      "z": -23,
      "name": "Metal_Iron"
    },
    {
      "x": -19,
      "y": 26,
      "z": -23,
      "name": "Metal_Iron"
    },
    {
      "x": -19,
      "y": 24,
      "z": -22,
      "name": "Metal_Iron"
    },
    {
      "x": -19,
      "y": 25,
      "z": -22,
      "name": "Metal_Iron"
    },
    {
      "x": -19,
      "y": 26,
      "z": -22,
      "name": "Metal_Iron"
    },
    {
      "x": -19,
      "y": 24,
      "z": -21,
      "name": "Metal_Iron"
    },
    {
      "x": -19,
      "y": 25,
      "z": -21,
      "name": "Metal_Iron"
    },
    {
      "x": -19,
      "y": 26,
      "z": -21,
      "name": "Metal_Iron"
    },
    {
      "x": -19,
      "y": 24,
      "z": -20,
      "name": "Metal_Iron"
    },
    {
      "x": -19,
      "y": 25,
      "z": -20,
      "name": "Metal_Iron"
    },
    {
      "x": -19,
      "y": 26,
      "z": -20,
      "name": "Metal_Iron"
    },
    {
      "x": -19,
      "y": 24,
      "z": -19,
      "name": "Metal_Iron"
    },
    {
      "x": -19,
      "y": 25,
      "z": -19,
      "name": "Metal_Iron"
    },
    {
      "x": -19,
      "y": 26,
      "z": -19,
      "name": "Metal_Iron"
    },
    {
      "x": -19,
      "y": 27,
      "z": -19,
      "name": "Metal_Iron_Half"
    },
    {
      "x": -19,
      "y": 24,
      "z": -18,
      "name": "Metal_Iron"
    },
    {
      "x": -19,
      "y": 25,
      "z": -18,
      "name": "Metal_Iron"
    },
    {
      "x": -19,
      "y": 26,
      "z": -18,
      "name": "Metal_Iron"
    },
    {
      "x": -19,
      "y": 27,
      "z": -18,
      "name": "Metal_Iron_Half"
    },
    {
      "x": -19,
      "y": 24,
      "z": -17,
      "name": "Metal_Iron_Half",
      "rotation": 8
    },
    {
      "x": -19,
      "y": 25,
      "z": -17,
      "name": "Metal_Iron"
    },
    {
      "x": -19,
      "y": 26,
      "z": -17,
      "name": "Metal_Iron"
    },
    {
      "x": -19,
      "y": 27,
      "z": -17,
      "name": "Metal_Iron_Half"
    },
    {
      "x": -19,
      "y": 25,
      "z": -16,
      "name": "Metal_Iron"
    },
    {
      "x": -19,
      "y": 26,
      "z": -16,
      "name": "Metal_Iron"
    },
    {
      "x": -19,
      "y": 27,
      "z": -16,
      "name": "Metal_Iron_Half"
    },
    {
      "x": -19,
      "y": 25,
      "z": -15,
      "name": "Metal_Iron"
    },
    {
      "x": -19,
      "y": 26,
      "z": -15,
      "name": "Metal_Iron"
    },
    {
      "x": -19,
      "y": 27,
      "z": -15,
      "name": "Metal_Iron_Half"
    },
    {
      "x": -19,
      "y": 25,
      "z": -14,
      "name": "Metal_Iron"
    },
    {
      "x": -19,
      "y": 26,
      "z": -14,
      "name": "Metal_Iron"
    },
    {
      "x": -19,
      "y": 26,
      "z": -13,
      "name": "Metal_Iron"
    },
    {
      "x": -18,
      "y": 25,
      "z": -26,
      "name": "Metal_Iron"
    },
    {
      "x": -18,
      "y": 24,
      "z": -25,
      "name": "Metal_Iron_Half",
      "rotation": 8
    },
    {
      "x": -18,
      "y": 25,
      "z": -25,
      "name": "Metal_Iron"
    },
    {
      "x": -18,
      "y": 26,
      "z": -25,
      "name": "Metal_Iron_Half"
    },
    {
      "x": -18,
      "y": 24,
      "z": -24,
      "name": "Metal_Iron"
    },
    {
      "x": -18,
      "y": 25,
      "z": -24,
      "name": "Metal_Iron"
    },
    {
      "x": -18,
      "y": 26,
      "z": -24,
      "name": "Metal_Iron"
    },
    {
      "x": -18,
      "y": 24,
      "z": -23,
      "name": "Metal_Iron"
    },
    {
      "x": -18,
      "y": 25,
      "z": -23,
      "name": "Metal_Iron"
    },
    {
      "x": -18,
      "y": 26,
      "z": -23,
      "name": "Metal_Iron"
    },
    {
      "x": -18,
      "y": 24,
      "z": -22,
      "name": "Metal_Iron"
    },
    {
      "x": -18,
      "y": 25,
      "z": -22,
      "name": "Metal_Iron"
    },
    {
      "x": -18,
      "y": 26,
      "z": -22,
      "name": "Metal_Iron"
    },
    {
      "x": -18,
      "y": 24,
      "z": -21,
      "name": "Metal_Iron"
    },
    {
      "x": -18,
      "y": 25,
      "z": -21,
      "name": "Metal_Iron"
    },
    {
      "x": -18,
      "y": 26,
      "z": -21,
      "name": "Metal_Iron"
    },
    {
      "x": -18,
      "y": 24,
      "z": -20,
      "name": "Metal_Iron_Half",
      "rotation": 8
    },
    {
      "x": -18,
      "y": 25,
      "z": -20,
      "name": "Metal_Iron"
    },
    {
      "x": -18,
      "y": 26,
      "z": -20,
      "name": "Metal_Iron"
    },
    {
      "x": -18,
      "y": 24,
      "z": -19,
      "name": "Metal_Iron_Half",
      "rotation": 8
    },
    {
      "x": -18,
      "y": 25,
      "z": -19,
      "name": "Metal_Iron"
    },
    {
      "x": -18,
      "y": 26,
      "z": -19,
      "name": "Metal_Iron"
    },
    {
      "x": -18,
      "y": 24,
      "z": -18,
      "name": "Metal_Iron_Half",
      "rotation": 8
    },
    {
      "x": -18,
      "y": 25,
      "z": -18,
      "name": "Metal_Iron"
    },
    {
      "x": -18,
      "y": 26,
      "z": -18,
      "name": "Metal_Iron"
    },
    {
      "x": -18,
      "y": 25,
      "z": -17,
      "name": "Metal_Iron"
    },
    {
      "x": -18,
      "y": 26,
      "z": -17,
      "name": "Metal_Iron"
    },
    {
      "x": -18,
      "y": 25,
      "z": -16,
      "name": "Metal_Iron"
    },
    {
      "x": -18,
      "y": 26,
      "z": -16,
      "name": "Metal_Iron"
    },
    {
      "x": -18,
      "y": 25,
      "z": -15,
      "name": "Metal_Iron"
    },
    {
      "x": -18,
      "y": 26,
      "z": -15,
      "name": "Metal_Iron"
    },
    {
      "x": -18,
      "y": 25,
      "z": -14,
      "name": "Metal_Iron_Half",
      "rotation": 8
    },
    {
      "x": -18,
      "y": 26,
      "z": -14,
      "name": "Metal_Iron_Half"
    },
    {
      "x": -18,
      "y": 33,
      "z": -8,
      "name": "Cloth_Block_Wool_Red"
    },
    {
      "x": -18,
      "y": 32,
      "z": -7,
      "name": "Cloth_Block_Wool_Red"
    },
    {
      "x": -18,
      "y": 33,
      "z": -7,
      "name": "Cloth_Block_Wool_Red"
    },
    {
      "x": -18,
      "y": 34,
      "z": -7,
      "name": "Cloth_Block_Wool_Red"
    },
    {
      "x": -18,
      "y": 31,
      "z": -6,
      "name": "Cloth_Block_Wool_Red"
    },
    {
      "x": -18,
      "y": 32,
      "z": -6,
      "name": "Cloth_Block_Wool_Red"
    },
    {
      "x": -18,
      "y": 33,
      "z": -6,
      "name": "Cloth_Block_Wool_Red"
    },
    {
      "x": -18,
      "y": 34,
      "z": -6,
      "name": "Cloth_Block_Wool_Red"
    },
    {
      "x": -18,
      "y": 35,
      "z": -6,
      "name": "Cloth_Block_Wool_Red"
    },
    {
      "x": -18,
      "y": 30,
      "z": -5,
      "name": "Cloth_Block_Wool_Red"
    },
    {
      "x": -18,
      "y": 31,
      "z": -5,
      "name": "Cloth_Block_Wool_Red"
    },
    {
      "x": -18,
      "y": 32,
      "z": -5,
      "name": "Cloth_Block_Wool_Red"
    },
    {
      "x": -18,
      "y": 33,
      "z": -5,
      "name": "Cloth_Block_Wool_Red"
    },
    {
      "x": -18,
      "y": 34,
      "z": -5,
      "name": "Cloth_Block_Wool_Red"
    },
    {
      "x": -18,
      "y": 35,
      "z": -5,
      "name": "Cloth_Block_Wool_Red"
    },
    {
      "x": -18,
      "y": 36,
      "z": -5,
      "name": "Cloth_Block_Wool_Red"
    },
    {
      "x": -18,
      "y": 28,
      "z": -4,
      "name": "Cloth_Block_Wool_Red"
    },
    {
      "x": -18,
      "y": 29,
      "z": -4,
      "name": "Cloth_Block_Wool_Red"
    },
    {
      "x": -18,
      "y": 30,
      "z": -4,
      "name": "Cloth_Block_Wool_Red"
    },
    {
      "x": -18,
      "y": 31,
      "z": -4,
      "name": "Cloth_Block_Wool_Red"
    },
    {
      "x": -18,
      "y": 32,
      "z": -4,
      "name": "Cloth_Block_Wool_Red"
    },
    {
      "x": -18,
      "y": 33,
      "z": -4,
      "name": "Cloth_Block_Wool_Red"
    },
    {
      "x": -18,
      "y": 34,
      "z": -4,
      "name": "Cloth_Block_Wool_Red"
    },
    {
      "x": -18,
      "y": 35,
      "z": -4,
      "name": "Cloth_Block_Wool_Red"
    },
    {
      "x": -18,
      "y": 36,
      "z": -4,
      "name": "Cloth_Block_Wool_Red"
    },
    {
      "x": -18,
      "y": 27,
      "z": -3,
      "name": "Cloth_Block_Wool_Red"
    },
    {
      "x": -18,
      "y": 28,
      "z": -3,
      "name": "Cloth_Block_Wool_Red"
    },
    {
      "x": -18,
      "y": 29,
      "z": -3,
      "name": "Cloth_Block_Wool_Red"
    },
    {
      "x": -18,
      "y": 30,
      "z": -3,
      "name": "Cloth_Block_Wool_Red"
    },
    {
      "x": -18,
      "y": 31,
      "z": -3,
      "name": "Cloth_Block_Wool_Red"
    },
    {
      "x": -18,
      "y": 32,
      "z": -3,
      "name": "Cloth_Block_Wool_Red"
    },
    {
      "x": -18,
      "y": 33,
      "z": -3,
      "name": "Cloth_Block_Wool_Red"
    },
    {
      "x": -18,
      "y": 34,
      "z": -3,
      "name": "Cloth_Block_Wool_Red"
    },
    {
      "x": -18,
      "y": 35,
      "z": -3,
      "name": "Cloth_Block_Wool_Red"
    },
    {
      "x": -18,
      "y": 36,
      "z": -3,
      "name": "Cloth_Block_Wool_Red"
    },
    {
      "x": -18,
      "y": 37,
      "z": -3,
      "name": "Cloth_Block_Wool_Red"
    },
    {
      "x": -18,
      "y": 26,
      "z": -2,
      "name": "Cloth_Block_Wool_Red"
    },
    {
      "x": -18,
      "y": 27,
      "z": -2,
      "name": "Cloth_Block_Wool_Red"
    },
    {
      "x": -18,
      "y": 28,
      "z": -2,
      "name": "Cloth_Block_Wool_Red"
    },
    {
      "x": -18,
      "y": 29,
      "z": -2,
      "name": "Cloth_Block_Wool_Red"
    },
    {
      "x": -18,
      "y": 30,
      "z": -2,
      "name": "Cloth_Block_Wool_Red"
    },
    {
      "x": -18,
      "y": 31,
      "z": -2,
      "name": "Cloth_Block_Wool_Red"
    },
    {
      "x": -18,
      "y": 32,
      "z": -2,
      "name": "Cloth_Block_Wool_Red"
    },
    {
      "x": -18,
      "y": 33,
      "z": -2,
      "name": "Cloth_Block_Wool_Red"
    },
    {
      "x": -18,
      "y": 34,
      "z": -2,
      "name": "Cloth_Block_Wool_Red"
    },
    {
      "x": -18,
      "y": 35,
      "z": -2,
      "name": "Cloth_Block_Wool_Red"
    },
    {
      "x": -18,
      "y": 36,
      "z": -2,
      "name": "Cloth_Block_Wool_Red"
    },
    {
      "x": -18,
      "y": 37,
      "z": -2,
      "name": "Cloth_Block_Wool_Red"
    },
    {
      "x": -18,
      "y": 25,
      "z": -1,
      "name": "Cloth_Block_Wool_Red"
    },
    {
      "x": -18,
      "y": 26,
      "z": -1,
      "name": "Cloth_Block_Wool_Red"
    },
    {
      "x": -18,
      "y": 27,
      "z": -1,
      "name": "Cloth_Block_Wool_Red"
    },
    {
      "x": -18,
      "y": 28,
      "z": -1,
      "name": "Cloth_Block_Wool_Red"
    },
    {
      "x": -18,
      "y": 29,
      "z": -1,
      "name": "Cloth_Block_Wool_Red"
    },
    {
      "x": -18,
      "y": 30,
      "z": -1,
      "name": "Cloth_Block_Wool_Red"
    },
    {
      "x": -18,
      "y": 31,
      "z": -1,
      "name": "Cloth_Block_Wool_Red"
    },
    {
      "x": -18,
      "y": 32,
      "z": -1,
      "name": "Cloth_Block_Wool_Red"
    },
    {
      "x": -18,
      "y": 33,
      "z": -1,
      "name": "Cloth_Block_Wool_Red"
    },
    {
      "x": -18,
      "y": 34,
      "z": -1,
      "name": "Cloth_Block_Wool_Red"
    },
    {
      "x": -18,
      "y": 35,
      "z": -1,
      "name": "Cloth_Block_Wool_Red"
    },
    {
      "x": -18,
      "y": 36,
      "z": -1,
      "name": "Cloth_Block_Wool_Red"
    },
    {
      "x": -18,
      "y": 37,
      "z": -1,
      "name": "Cloth_Block_Wool_Red"
    },
    {
      "x": -18,
      "y": 38,
      "z": -1,
      "name": "Cloth_Block_Wool_Red"
    },
    {
      "x": -18,
      "y": 24,
      "z": 0,
      "name": "Cloth_Block_Wool_Red"
    },
    {
      "x": -18,
      "y": 25,
      "z": 0,
      "name": "Cloth_Block_Wool_Red"
    },
    {
      "x": -18,
      "y": 26,
      "z": 0,
      "name": "Cloth_Block_Wool_Red"
    },
    {
      "x": -18,
      "y": 27,
