{
  "version": 8,
  "blockIdVersion": 11,
  "anchorX": 0,
  "anchorY": 0,
  "anchorZ": 0,
  "blocks": [
    {
      "x": -59,
      "y": 34,
      "z": -4,
      "name": "Rock_Stone"
    },
    {
      "x": -59,
      "y": 34,
      "z": -3,
      "name": "Rock_Stone"
    },
    {
      "x": -58,
      "y": 33,
      "z": -4,
      "name": "Rock_Stone"
    },
    {
      "x": -58,
      "y": 34,
      "z": -4,
      "name": "Rock_Stone"
    },
    {
      "x": -58,
      "y": 35,
      "z": -4,
      "name": "Rock_Stone"
    },
    {
      "x": -58,
      "y": 33,
      "z": -3,
      "name": "Rock_Stone"
    },
    {
      "x": -58,
      "y": 34,
      "z": -3,
      "name": "Rock_Stone"
    },
    {
      "x": -58,
      "y": 35,
      "z": -3,
      "name": "Rock_Stone"
    },
    {
      "x": -57,
      "y": 34,
      "z": -5,
      "name": "Rock_Stone"
    },
    {
      "x": -57,
      "y": 33,
      "z": -4,
      "name": "Rock_Stone"
    },
    {
      "x": -57,
      "y": 34,
      "z": -4,
      "name": "Rock_Stone"
    },
    {
      "x": -57,
      "y": 35,
      "z": -4,
      "name": "Rock_Stone"
    },
    {
      "x": -57,
      "y": 33,
      "z": -3,
      "name": "Rock_Stone"
    },
    {
      "x": -57,
      "y": 34,
      "z": -3,
      "name": "Rock_Stone"
    },
    {
      "x": -57,
      "y": 35,
      "z": -3,
      "name": "Rock_Stone"
    },
    {
      "x": -57,
      "y": 34,
      "z": -2,
      "name": "Rock_Stone"
    },
    {
      "x": -56,
      "y": 34,
      "z": -5,
      "name": "Rock_Stone"
    },
    {
      "x": -56,
      "y": 33,
      "z": -4,
      "name": "Rock_Stone"
    },
    {
      "x": -56,
      "y": 34,
      "z": -4,
      "name": "Rock_Stone"
    },
    {
      "x": -56,
      "y": 35,
      "z": -4,
      "name": "Rock_Stone"
    },
    {
      "x": -56,
      "y": 33,
      "z": -3,
      "name": "Rock_Stone"
    },
    {
      "x": -56,
      "y": 34,
      "z": -3,
      "name": "Rock_Stone"
    },
    {
      "x": -56,
      "y": 35,
      "z": -3,
      "name": "Rock_Stone"
    },
    {
      "x": -56,
      "y": 34,
      "z": -2,
      "name": "Rock_Stone"
    },
    {
      "x": -55,
      "y": 33,
      "z": -5,
      "name": "Rock_Stone"
    },
    {
      "x": -55,
      "y": 34,
      "z": -5,
      "name": "Rock_Stone"
    },
    {
      "x": -55,
      "y": 35,
      "z": -5,
      "name": "Rock_Stone"
    },
    {
      "x": -55,
      "y": 33,
      "z": -4,
      "name": "Rock_Stone"
    },
    {
      "x": -55,
      "y": 34,
      "z": -4,
      "name": "Rock_Stone"
    },
    {
      "x": -55,
      "y": 35,
      "z": -4,
      "name": "Rock_Stone"
    },
    {
      "x": -55,
      "y": 33,
      "z": -3,
      "name": "Rock_Stone"
    },
    {
      "x": -55,
      "y": 34,
      "z": -3,
      "name": "Rock_Stone"
    },
    {
      "x": -55,
      "y": 35,
      "z": -3,
      "name": "Rock_Stone"
    },
    {
      "x": -55,
      "y": 33,
      "z": -2,
      "name": "Rock_Stone"
    },
    {
      "x": -55,
      "y": 34,
      "z": -2,
      "name": "Rock_Stone"
    },
    {
      "x": -55,
      "y": 35,
      "z": -2,
      "name": "Rock_Stone"
    },
    {
      "x": -54,
      "y": 34,
      "z": -6,
      "name": "Rock_Stone"
    },
    {
      "x": -54,
      "y": 33,
      "z": -5,
      "name": "Rock_Stone"
    },
    {
      "x": -54,
      "y": 34,
      "z": -5,
      "name": "Rock_Stone"
    },
    {
      "x": -54,
      "y": 35,
      "z": -5,
      "name": "Rock_Stone"
    },
    {
      "x": -54,
      "y": 32,
      "z": -4,
      "name": "Rock_Stone"
    },
    {
      "x": -54,
      "y": 33,
      "z": -4,
      "name": "Rock_Stone"
    },
    {
      "x": -54,
      "y": 34,
      "z": -4,
      "name": "Rock_Stone"
    },
    {
      "x": -54,
      "y": 35,
      "z": -4,
      "name": "Rock_Stone"
    },
    {
      "x": -54,
      "y": 32,
      "z": -3,
      "name": "Rock_Stone"
    },
    {
      "x": -54,
      "y": 33,
      "z": -3,
      "name": "Rock_Stone"
    },
    {
      "x": -54,
      "y": 34,
      "z": -3,
      "name": "Rock_Stone"
    },
    {
      "x": -54,
      "y": 35,
      "z": -3,
      "name": "Rock_Stone"
    },
    {
      "x": -54,
      "y": 33,
      "z": -2,
      "name": "Rock_Stone"
    },
    {
      "x": -54,
      "y": 34,
      "z": -2,
      "name": "Rock_Stone"
    },
    {
      "x": -54,
      "y": 35,
      "z": -2,
      "name": "Rock_Stone"
    },
    {
      "x": -53,
      "y": 33,
      "z": -6,
      "name": "Rock_Stone"
    },
    {
      "x": -53,
      "y": 34,
      "z": -6,
      "name": "Rock_Stone"
    },
    {
      "x": -53,
      "y": 33,
      "z": -5,
      "name": "Rock_Stone"
    },
    {
      "x": -53,
      "y": 34,
      "z": -5,
      "name": "Rock_Stone"
    },
    {
      "x": -53,
      "y": 35,
      "z": -5,
      "name": "Rock_Stone"
    },
    {
      "x": -53,
      "y": 32,
      "z": -4,
      "name": "Rock_Stone"
    },
    {
      "x": -53,
      "y": 33,
      "z": -4,
      "name": "Rock_Stone"
    },
    {
      "x": -53,
      "y": 35,
      "z": -4,
      "name": "Rock_Stone"
    },
    {
      "x": -53,
      "y": 36,
      "z": -4,
      "name": "Rock_Stone"
    },
    {
      "x": -53,
      "y": 32,
      "z": -3,
      "name": "Rock_Stone"
    },
    {
      "x": -53,
      "y": 33,
      "z": -3,
      "name": "Rock_Stone"
    },
    {
      "x": -53,
      "y": 34,
      "z": -3,
      "name": "Rock_Stone"
    },
    {
      "x": -53,
      "y": 35,
      "z": -3,
      "name": "Rock_Stone"
    },
    {
      "x": -53,
      "y": 33,
      "z": -2,
      "name": "Rock_Stone"
    },
    {
      "x": -53,
      "y": 34,
      "z": -2,
      "name": "Rock_Stone"
    },
    {
      "x": -53,
      "y": 35,
      "z": -2,
      "name": "Rock_Stone"
    },
    {
      "x": -53,
      "y": 33,
      "z": -1,
      "name": "Rock_Stone"
    },
    {
      "x": -53,
      "y": 34,
      "z": -1,
      "name": "Rock_Stone"
    },
    {
      "x": -52,
      "y": 33,
      "z": -6,
      "name": "Rock_Stone"
    },
    {
      "x": -52,
      "y": 34,
      "z": -6,
      "name": "Rock_Stone"
    },
    {
      "x": -52,
      "y": 35,
      "z": -6,
      "name": "Rock_Stone"
    },
    {
      "x": -52,
      "y": 33,
      "z": -5,
      "name": "Rock_Stone"
    },
    {
      "x": -52,
      "y": 34,
      "z": -5,
      "name": "Rock_Stone"
    },
    {
      "x": -52,
      "y": 35,
      "z": -5,
      "name": "Rock_Stone"
    },
    {
      "x": -52,
      "y": 32,
      "z": -4,
      "name": "Rock_Stone"
    },
    {
      "x": -52,
      "y": 33,
      "z": -4,
      "name": "Rock_Stone"
    },
    {
      "x": -52,
      "y": 35,
      "z": -4,
      "name": "Rock_Stone"
    },
    {
      "x": -52,
      "y": 36,
      "z": -4,
      "name": "Rock_Stone"
    },
    {
      "x": -52,
      "y": 32,
      "z": -3,
      "name": "Rock_Stone"
    },
    {
      "x": -52,
      "y": 33,
      "z": -3,
      "name": "Rock_Stone"
    },
    {
      "x": -52,
      "y": 35,
      "z": -3,
      "name": "Rock_Stone"
    },
    {
      "x": -52,
      "y": 36,
      "z": -3,
      "name": "Rock_Stone"
    },
    {
      "x": -52,
      "y": 33,
      "z": -2,
      "name": "Rock_Stone"
    },
    {
      "x": -52,
      "y": 34,
      "z": -2,
      "name": "Rock_Stone"
    },
    {
      "x": -52,
      "y": 35,
      "z": -2,
      "name": "Rock_Stone"
    },
    {
      "x": -52,
      "y": 33,
      "z": -1,
      "name": "Rock_Stone"
    },
    {
      "x": -52,
      "y": 34,
      "z": -1,
      "name": "Rock_Stone"
    },
    {
      "x": -51,
      "y": 34,
      "z": -7,
      "name": "Rock_Stone"
    },
    {
      "x": -51,
      "y": 33,
      "z": -6,
      "name": "Rock_Stone"
    },
    {
      "x": -51,
      "y": 34,
      "z": -6,
      "name": "Rock_Stone"
    },
    {
      "x": -51,
      "y": 35,
      "z": -6,
      "name": "Rock_Stone"
    },
    {
      "x": -51,
      "y": 32,
      "z": -5,
      "name": "Rock_Stone"
    },
    {
      "x": -51,
      "y": 33,
      "z": -5,
      "name": "Rock_Stone"
    },
    {
      "x": -51,
      "y": 34,
      "z": -5,
      "name": "Rock_Stone"
    },
    {
      "x": -51,
      "y": 35,
      "z": -5,
      "name": "Rock_Stone"
    },
    {
      "x": -51,
      "y": 32,
      "z": -4,
      "name": "Rock_Stone"
    },
    {
      "x": -51,
      "y": 33,
      "z": -4,
      "name": "Rock_Stone"
    },
    {
      "x": -51,
      "y": 35,
      "z": -4,
      "name": "Rock_Stone"
    },
    {
      "x": -51,
      "y": 36,
      "z": -4,
      "name": "Rock_Stone"
    },
    {
      "x": -51,
      "y": 32,
      "z": -3,
      "name": "Rock_Stone"
    },
    {
      "x": -51,
      "y": 33,
      "z": -3,
      "name": "Rock_Stone"
    },
    {
      "x": -51,
      "y": 35,
      "z": -3,
      "name": "Rock_Stone"
    },
    {
      "x": -51,
      "y": 36,
      "z": -3,
      "name": "Rock_Stone"
    },
    {
      "x": -51,
      "y": 32,
      "z": -2,
      "name": "Rock_Stone"
    },
    {
      "x": -51,
      "y": 33,
      "z": -2,
      "name": "Rock_Stone"
    },
    {
      "x": -51,
      "y": 34,
      "z": -2,
      "name": "Rock_Stone"
    },
    {
      "x": -51,
      "y": 35,
      "z": -2,
      "name": "Rock_Stone"
    },
    {
      "x": -51,
      "y": 33,
      "z": -1,
      "name": "Rock_Stone"
    },
    {
      "x": -51,
      "y": 34,
      "z": -1,
      "name": "Rock_Stone"
    },
    {
      "x": -51,
      "y": 35,
      "z": -1,
      "name": "Rock_Stone"
    },
    {
      "x": -51,
      "y": 34,
      "z": 0,
      "name": "Rock_Stone"
    },
    {
      "x": -50,
      "y": 33,
      "z": -7,
      "name": "Rock_Stone"
    },
    {
      "x": -50,
      "y": 34,
      "z": -7,
      "name": "Rock_Stone"
    },
    {
      "x": -50,
      "y": 33,
      "z": -6,
      "name": "Rock_Stone"
    },
    {
      "x": -50,
      "y": 34,
      "z": -6,
      "name": "Rock_Stone"
    },
    {
      "x": -50,
      "y": 35,
      "z": -6,
      "name": "Rock_Stone"
    },
    {
      "x": -50,
      "y": 32,
      "z": -5,
      "name": "Rock_Stone"
    },
    {
      "x": -50,
      "y": 33,
      "z": -5,
      "name": "Rock_Stone"
    },
    {
      "x": -50,
      "y": 34,
      "z": -5,
      "name": "Rock_Stone"
    },
    {
      "x": -50,
      "y": 35,
      "z": -5,
      "name": "Rock_Stone"
    },
    {
      "x": -50,
      "y": 36,
      "z": -5,
      "name": "Rock_Stone"
    },
    {
      "x": -50,
      "y": 31,
      "z": -4,
      "name": "Rock_Stone"
    },
    {
      "x": -50,
      "y": 32,
      "z": -4,
      "name": "Rock_Stone"
    },
    {
      "x": -50,
      "y": 35,
      "z": -4,
      "name": "Rock_Stone"
    },
    {
      "x": -50,
      "y": 36,
      "z": -4,
      "name": "Rock_Stone"
    },
    {
      "x": -50,
      "y": 31,
      "z": -3,
      "name": "Rock_Stone"
    },
    {
      "x": -50,
      "y": 32,
      "z": -3,
      "name": "Rock_Stone"
    },
    {
      "x": -50,
      "y": 33,
      "z": -3,
      "name": "Rock_Stone"
    },
    {
      "x": -50,
      "y": 35,
      "z": -3,
      "name": "Rock_Stone"
    },
    {
      "x": -50,
      "y": 36,
      "z": -3,
      "name": "Rock_Stone"
    },
    {
      "x": -50,
      "y": 32,
      "z": -2,
      "name": "Rock_Stone"
    },
    {
      "x": -50,
      "y": 33,
      "z": -2,
      "name": "Rock_Stone"
    },
    {
      "x": -50,
      "y": 34,
      "z": -2,
      "name": "Rock_Stone"
    },
    {
      "x": -50,
      "y": 35,
      "z": -2,
      "name": "Rock_Stone"
    },
    {
      "x": -50,
      "y": 33,
      "z": -1,
      "name": "Rock_Stone"
    },
    {
      "x": -50,
      "y": 34,
      "z": -1,
      "name": "Rock_Stone"
    },
    {
      "x": -50,
      "y": 35,
      "z": -1,
      "name": "Rock_Stone"
    },
    {
      "x": -50,
      "y": 33,
      "z": 0,
      "name": "Rock_Stone"
    },
    {
      "x": -50,
      "y": 34,
      "z": 0,
      "name": "Rock_Stone"
    },
    {
      "x": -49,
      "y": 33,
      "z": -7,
      "name": "Rock_Stone"
    },
    {
      "x": -49,
      "y": 34,
      "z": -7,
      "name": "Rock_Stone"
    },
    {
      "x": -49,
      "y": 35,
      "z": -7,
      "name": "Rock_Stone"
    },
    {
      "x": -49,
      "y": 32,
      "z": -6,
      "name": "Rock_Stone"
    },
    {
      "x": -49,
      "y": 33,
      "z": -6,
      "name": "Rock_Stone"
    },
    {
      "x": -49,
      "y": 34,
      "z": -6,
      "name": "Rock_Stone"
    },
    {
      "x": -49,
      "y": 35,
      "z": -6,
      "name": "Rock_Stone"
    },
    {
      "x": -49,
      "y": 32,
      "z": -5,
      "name": "Rock_Stone"
    },
    {
      "x": -49,
      "y": 33,
      "z": -5,
      "name": "Rock_Stone"
    },
    {
      "x": -49,
      "y": 35,
      "z": -5,
      "name": "Rock_Stone"
    },
    {
      "x": -49,
      "y": 36,
      "z": -5,
      "name": "Rock_Stone"
    },
    {
      "x": -49,
      "y": 31,
      "z": -4,
      "name": "Rock_Stone"
    },
    {
      "x": -49,
      "y": 32,
      "z": -4,
      "name": "Rock_Stone"
    },
    {
      "x": -49,
      "y": 35,
      "z": -4,
      "name": "Rock_Stone"
    },
    {
      "x": -49,
      "y": 36,
      "z": -4,
      "name": "Rock_Stone"
    },
    {
      "x": -49,
      "y": 31,
      "z": -3,
      "name": "Rock_Stone"
    },
    {
      "x": -49,
      "y": 32,
      "z": -3,
      "name": "Rock_Stone"
    },
    {
      "x": -49,
      "y": 35,
      "z": -3,
      "name": "Rock_Stone"
    },
    {
      "x": -49,
      "y": 36,
      "z": -3,
      "name": "Rock_Stone"
    },
    {
      "x": -49,
      "y": 32,
      "z": -2,
      "name": "Rock_Stone"
    },
    {
      "x": -49,
      "y": 33,
      "z": -2,
      "name": "Rock_Stone"
    },
    {
      "x": -49,
      "y": 35,
      "z": -2,
      "name": "Rock_Stone"
    },
    {
      "x": -49,
      "y": 36,
      "z": -2,
      "name": "Rock_Stone"
    },
    {
      "x": -49,
      "y": 33,
      "z": -1,
      "name": "Rock_Stone"
    },
    {
      "x": -49,
      "y": 34,
      "z": -1,
      "name": "Rock_Stone"
    },
    {
      "x": -49,
      "y": 35,
      "z": -1,
      "name": "Rock_Stone"
    },
    {
      "x": -49,
      "y": 33,
      "z": 0,
      "name": "Rock_Stone"
    },
    {
      "x": -49,
      "y": 34,
      "z": 0,
      "name": "Rock_Stone"
    },
    {
      "x": -48,
      "y": 34,
      "z": -8,
      "name": "Rock_Stone"
    },
    {
      "x": -48,
      "y": 33,
      "z": -7,
      "name": "Rock_Stone"
    },
    {
      "x": -48,
      "y": 34,
      "z": -7,
      "name": "Rock_Stone"
    },
    {
      "x": -48,
      "y": 35,
      "z": -7,
      "name": "Rock_Stone"
    },
    {
      "x": -48,
      "y": 32,
      "z": -6,
      "name": "Rock_Stone"
    },
    {
      "x": -48,
      "y": 33,
      "z": -6,
      "name": "Rock_Stone"
    },
    {
      "x": -48,
      "y": 34,
      "z": -6,
      "name": "Rock_Stone"
    },
    {
      "x": -48,
      "y": 35,
      "z": -6,
      "name": "Rock_Stone"
    },
    {
      "x": -48,
      "y": 31,
      "z": -5,
      "name": "Rock_Stone"
    },
    {
      "x": -48,
      "y": 32,
      "z": -5,
      "name": "Rock_Stone"
    },
    {
      "x": -48,
      "y": 33,
      "z": -5,
      "name": "Rock_Stone"
    },
    {
      "x": -48,
      "y": 35,
      "z": -5,
      "name": "Rock_Stone"
    },
    {
      "x": -48,
      "y": 36,
      "z": -5,
      "name": "Rock_Stone"
    },
    {
      "x": -48,
      "y": 31,
      "z": -4,
      "name": "Rock_Stone"
    },
    {
      "x": -48,
      "y": 32,
      "z": -4,
      "name": "Rock_Stone"
    },
    {
      "x": -48,
      "y": 35,
      "z": -4,
      "name": "Rock_Stone"
    },
    {
      "x": -48,
      "y": 36,
      "z": -4,
      "name": "Rock_Stone"
    },
    {
      "x": -48,
      "y": 31,
      "z": -3,
      "name": "Rock_Stone"
    },
    {
      "x": -48,
      "y": 32,
      "z": -3,
      "name": "Rock_Stone"
    },
    {
      "x": -48,
      "y": 35,
      "z": -3,
      "name": "Rock_Stone"
    },
    {
      "x": -48,
      "y": 36,
      "z": -3,
      "name": "Rock_Stone"
    },
    {
      "x": -48,
      "y": 32,
      "z": -2,
      "name": "Rock_Stone"
    },
    {
      "x": -48,
      "y": 33,
      "z": -2,
      "name": "Rock_Stone"
    },
    {
      "x": -48,
      "y": 35,
      "z": -2,
      "name": "Rock_Stone"
    },
    {
      "x": -48,
      "y": 36,
      "z": -2,
      "name": "Rock_Stone"
    },
    {
      "x": -48,
      "y": 32,
      "z": -1,
      "name": "Rock_Stone"
    },
    {
      "x": -48,
      "y": 33,
      "z": -1,
      "name": "Rock_Stone"
    },
    {
      "x": -48,
      "y": 34,
      "z": -1,
      "name": "Rock_Stone"
    },
    {
      "x": -48,
      "y": 35,
      "z": -1,
      "name": "Rock_Stone"
    },
    {
      "x": -48,
      "y": 33,
      "z": 0,
      "name": "Rock_Stone"
    },
    {
      "x": -48,
      "y": 34,
      "z": 0,
      "name": "Rock_Stone"
    },
    {
      "x": -48,
      "y": 35,
      "z": 0,
      "name": "Rock_Stone"
    },
    {
      "x": -48,
      "y": 34,
      "z": 1,
      "name": "Rock_Stone"
    },
    {
      "x": -47,
      "y": 33,
      "z": -8,
      "name": "Rock_Stone"
    },
    {
      "x": -47,
      "y": 34,
      "z": -8,
      "name": "Rock_Stone"
    },
    {
      "x": -47,
      "y": 33,
      "z": -7,
      "name": "Rock_Stone"
    },
    {
      "x": -47,
      "y": 34,
      "z": -7,
      "name": "Rock_Stone"
    },
    {
      "x": -47,
      "y": 35,
      "z": -7,
      "name": "Rock_Stone"
    },
    {
      "x": -47,
      "y": 32,
      "z": -6,
      "name": "Rock_Stone"
    },
    {
      "x": -47,
      "y": 33,
      "z": -6,
      "name": "Rock_Stone"
    },
    {
      "x": -47,
      "y": 34,
      "z": -6,
      "name": "Rock_Stone"
    },
    {
      "x": -47,
      "y": 35,
      "z": -6,
      "name": "Rock_Stone"
    },
    {
      "x": -47,
      "y": 36,
      "z": -6,
      "name": "Rock_Stone"
    },
    {
      "x": -47,
      "y": 31,
      "z": -5,
      "name": "Rock_Stone"
    },
    {
      "x": -47,
      "y": 32,
      "z": -5,
      "name": "Rock_Stone"
    },
    {
      "x": -47,
      "y": 35,
      "z": -5,
      "name": "Rock_Stone"
    },
    {
      "x": -47,
      "y": 36,
      "z": -5,
      "name": "Rock_Stone"
    },
    {
      "x": -47,
      "y": 30,
      "z": -4,
      "name": "Rock_Stone"
    },
    {
      "x": -47,
      "y": 31,
      "z": -4,
      "name": "Rock_Stone"
    },
    {
      "x": -47,
      "y": 32,
      "z": -4,
      "name": "Rock_Stone"
    },
    {
      "x": -47,
      "y": 36,
      "z": -4,
      "name": "Rock_Stone"
    },
    {
      "x": -47,
      "y": 37,
      "z": -4,
      "name": "Rock_Stone"
    },
    {
      "x": -47,
      "y": 30,
      "z": -3,
      "name": "Rock_Stone"
    },
    {
      "x": -47,
      "y": 31,
      "z": -3,
      "name": "Rock_Stone"
    },
    {
      "x": -47,
      "y": 32,
      "z": -3,
      "name": "Rock_Stone"
    },
    {
      "x": -47,
      "y": 36,
      "z": -3,
      "name": "Rock_Stone"
    },
    {
      "x": -47,
      "y": 37,
      "z": -3,
      "name": "Rock_Stone"
    },
    {
      "x": -47,
      "y": 31,
      "z": -2,
      "name": "Rock_Stone"
    },
    {
      "x": -47,
      "y": 32,
      "z": -2,
      "name": "Rock_Stone"
    },
    {
      "x": -47,
      "y": 33,
      "z": -2,
      "name": "Rock_Stone"
    },
    {
      "x": -47,
      "y": 35,
      "z": -2,
      "name": "Rock_Stone"
    },
    {
      "x": -47,
      "y": 36,
      "z": -2,
      "name": "Rock_Stone"
    },
    {
      "x": -47,
      "y": 32,
      "z": -1,
      "name": "Rock_Stone"
    },
    {
      "x": -47,
      "y": 33,
      "z": -1,
      "name": "Rock_Stone"
    },
    {
      "x": -47,
      "y": 34,
      "z": -1,
      "name": "Rock_Stone"
    },
    {
      "x": -47,
      "y": 35,
      "z": -1,
      "name": "Rock_Stone"
    },
    {
      "x": -47,
      "y": 33,
      "z": 0,
      "name": "Rock_Stone"
    },
    {
      "x": -47,
      "y": 34,
      "z": 0,
      "name": "Rock_Stone"
    },
    {
      "x": -47,
      "y": 35,
      "z": 0,
      "name": "Rock_Stone"
    },
    {
      "x": -47,
      "y": 33,
      "z": 1,
      "name": "Rock_Stone"
    },
    {
      "x": -47,
      "y": 34,
      "z": 1,
      "name": "Rock_Stone"
    },
    {
      "x": -46,
      "y": 33,
      "z": -8,
      "name": "Rock_Stone"
    },
    {
      "x": -46,
      "y": 34,
      "z": -8,
      "name": "Rock_Stone"
    },
    {
      "x": -46,
      "y": 35,
      "z": -8,
      "name": "Rock_Stone"
    },
    {
      "x": -46,
      "y": 32,
      "z": -7,
      "name": "Rock_Stone"
    },
    {
      "x": -46,
      "y": 33,
      "z": -7,
      "name": "Rock_Stone"
    },
    {
      "x": -46,
      "y": 34,
      "z": -7,
      "name": "Rock_Stone"
    },
    {
      "x": -46,
      "y": 35,
      "z": -7,
      "name": "Rock_Stone"
    },
    {
      "x": -46,
      "y": 32,
      "z": -6,
      "name": "Rock_Stone"
    },
    {
      "x": -46,
      "y": 33,
      "z": -6,
      "name": "Rock_Stone"
    },
    {
      "x": -46,
      "y": 35,
      "z": -6,
      "name": "Rock_Stone"
    },
    {
      "x": -46,
      "y": 36,
      "z": -6,
      "name": "Rock_Stone"
    },
    {
      "x": -46,
      "y": 31,
      "z": -5,
      "name": "Rock_Stone"
    },
    {
      "x": -46,
      "y": 32,
      "z": -5,
      "name": "Rock_Stone"
    },
    {
      "x": -46,
      "y": 35,
      "z": -5,
      "name": "Rock_Stone"
    },
    {
      "x": -46,
      "y": 36,
      "z": -5,
      "name": "Rock_Stone"
    },
    {
      "x": -46,
      "y": 30,
      "z": -4,
      "name": "Rock_Stone"
    },
    {
      "x": -46,
      "y": 31,
      "z": -4,
      "name": "Rock_Stone"
    },
    {
      "x": -46,
      "y": 36,
      "z": -4,
      "name": "Rock_Stone"
    },
    {
      "x": -46,
      "y": 37,
      "z": -4,
      "name": "Rock_Stone"
    },
    {
      "x": -46,
      "y": 30,
      "z": -3,
      "name": "Rock_Stone"
    },
    {
      "x": -46,
      "y": 31,
      "z": -3,
      "name": "Rock_Stone"
    },
    {
      "x": -46,
      "y": 32,
      "z": -3,
      "name": "Rock_Stone"
    },
    {
      "x": -46,
      "y": 36,
      "z": -3,
      "name": "Rock_Stone"
    },
    {
      "x": -46,
      "y": 37,
      "z": -3,
      "name": "Rock_Stone"
    },
    {
      "x": -46,
      "y": 31,
      "z": -2,
      "name": "Rock_Stone"
    },
    {
      "x": -46,
      "y": 32,
      "z": -2,
      "name": "Rock_Stone"
    },
    {
      "x": -46,
      "y": 35,
      "z": -2,
      "name": "Rock_Stone"
    },
    {
      "x": -46,
      "y": 36,
      "z": -2,
      "name": "Rock_Stone"
    },
    {
      "x": -46,
      "y": 32,
      "z": -1,
      "name": "Rock_Stone"
    },
    {
      "x": -46,
      "y": 33,
      "z": -1,
      "name": "Rock_Stone"
    },
    {
      "x": -46,
      "y": 35,
      "z": -1,
      "name": "Rock_Stone"
    },
    {
      "x": -46,
      "y": 36,
      "z": -1,
      "name": "Rock_Stone"
    },
    {
      "x": -46,
      "y": 33,
      "z": 0,
      "name": "Rock_Stone"
    },
    {
      "x": -46,
      "y": 34,
      "z": 0,
      "name": "Rock_Stone"
    },
    {
      "x": -46,
      "y": 35,
      "z": 0,
      "name": "Rock_Stone"
    },
    {
      "x": -46,
      "y": 33,
      "z": 1,
      "name": "Rock_Stone"
    },
    {
      "x": -46,
      "y": 34,
      "z": 1,
      "name": "Rock_Stone"
    },
    {
      "x": -45,
      "y": 34,
      "z": -9,
      "name": "Rock_Stone"
    },
    {
      "x": -45,
      "y": 33,
      "z": -8,
      "name": "Rock_Stone"
    },
    {
      "x": -45,
      "y": 34,
      "z": -8,
      "name": "Rock_Stone"
    },
    {
      "x": -45,
      "y": 35,
      "z": -8,
      "name": "Rock_Stone"
    },
    {
      "x": -45,
      "y": 32,
      "z": -7,
      "name": "Rock_Stone"
    },
    {
      "x": -45,
      "y": 33,
      "z": -7,
      "name": "Rock_Stone"
    },
    {
      "x": -45,
      "y": 34,
      "z": -7,
      "name": "Rock_Stone"
    },
    {
      "x": -45,
      "y": 35,
      "z": -7,
      "name": "Rock_Stone"
    },
    {
      "x": -45,
      "y": 32,
      "z": -6,
      "name": "Rock_Stone"
    },
    {
      "x": -45,
      "y": 33,
      "z": -6,
      "name": "Rock_Stone"
    },
    {
      "x": -45,
      "y": 35,
      "z": -6,
      "name": "Rock_Stone"
    },
    {
      "x": -45,
      "y": 36,
      "z": -6,
      "name": "Rock_Stone"
    },
    {
      "x": -45,
      "y": 31,
      "z": -5,
      "name": "Rock_Stone"
    },
    {
      "x": -45,
      "y": 32,
      "z": -5,
      "name": "Rock_Stone"
    },
    {
      "x": -45,
      "y": 35,
      "z": -5,
      "name": "Rock_Stone"
    },
    {
      "x": -45,
      "y": 36,
      "z": -5,
      "name": "Rock_Stone"
    },
    {
      "x": -45,
      "y": 29,
      "z": -4,
      "name": "Rock_Stone"
    },
    {
      "x": -45,
      "y": 30,
      "z": -4,
      "name": "Rock_Stone"
    },
    {
      "x": -45,
      "y": 31,
      "z": -4,
      "name": "Rock_Stone"
    },
    {
      "x": -45,
      "y": 36,
      "z": -4,
      "name": "Rock_Stone"
    },
    {
      "x": -45,
      "y": 37,
      "z": -4,
      "name": "Rock_Stone"
    },
    {
      "x": -45,
      "y": 29,
      "z": -3,
      "name": "Rock_Stone"
    },
    {
      "x": -45,
      "y": 30,
      "z": -3,
      "name": "Rock_Stone"
    },
    {
      "x": -45,
      "y": 31,
      "z": -3,
      "name": "Rock_Stone"
    },
    {
      "x": -45,
      "y": 36,
      "z": -3,
      "name": "Rock_Stone"
    },
    {
      "x": -45,
      "y": 37,
      "z": -3,
      "name": "Rock_Stone"
    },
    {
      "x": -45,
      "y": 31,
      "z": -2,
      "name": "Rock_Stone"
    },
    {
      "x": -45,
      "y": 32,
      "z": -2,
      "name": "Rock_Stone"
    },
    {
      "x": -45,
      "y": 35,
      "z": -2,
      "name": "Rock_Stone"
    },
    {
      "x": -45,
      "y": 36,
      "z": -2,
      "name": "Rock_Stone"
    },
    {
      "x": -45,
      "y": 32,
      "z": -1,
      "name": "Rock_Stone"
    },
    {
      "x": -45,
      "y": 33,
      "z": -1,
      "name": "Rock_Stone"
    },
    {
      "x": -45,
      "y": 35,
      "z": -1,
      "name": "Rock_Stone"
    },
    {
      "x": -45,
      "y": 36,
      "z": -1,
      "name": "Rock_Stone"
    },
    {
      "x": -45,
      "y": 32,
      "z": 0,
      "name": "Rock_Stone"
    },
    {
      "x": -45,
      "y": 33,
      "z": 0,
      "name": "Rock_Stone"
    },
    {
      "x": -45,
      "y": 34,
      "z": 0,
      "name": "Rock_Stone"
    },
    {
      "x": -45,
      "y": 35,
      "z": 0,
      "name": "Rock_Stone"
    },
    {
      "x": -45,
      "y": 33,
      "z": 1,
      "name": "Rock_Stone"
    },
    {
      "x": -45,
      "y": 34,
      "z": 1,
      "name": "Rock_Stone"
    },
    {
      "x": -45,
      "y": 35,
      "z": 1,
      "name": "Rock_Stone"
    },
    {
      "x": -45,
      "y": 34,
      "z": 2,
      "name": "Rock_Stone"
    },
    {
      "x": -44,
      "y": 33,
      "z": -9,
      "name": "Rock_Stone"
    },
    {
      "x": -44,
      "y": 34,
      "z": -9,
      "name": "Rock_Stone"
    },
    {
      "x": -44,
      "y": 33,
      "z": -8,
      "name": "Rock_Stone"
    },
    {
      "x": -44,
      "y": 34,
      "z": -8,
      "name": "Rock_Stone"
    },
    {
      "x": -44,
      "y": 35,
      "z": -8,
      "name": "Rock_Stone"
    },
    {
      "x": -44,
      "y": 32,
      "z": -7,
      "name": "Rock_Stone"
    },
    {
      "x": -44,
      "y": 33,
      "z": -7,
      "name": "Rock_Stone"
    },
    {
      "x": -44,
      "y": 34,
      "z": -7,
      "name": "Rock_Stone"
    },
    {
      "x": -44,
      "y": 35,
      "z": -7,
      "name": "Rock_Stone"
    },
    {
      "x": -44,
      "y": 31,
      "z": -6,
      "name": "Rock_Stone"
    },
    {
      "x": -44,
      "y": 32,
      "z": -6,
      "name": "Rock_Stone"
    },
    {
      "x": -44,
      "y": 33,
      "z": -6,
      "name": "Rock_Stone"
    },
    {
      "x": -44,
      "y": 35,
      "z": -6,
      "name": "Rock_Stone"
    },
    {
      "x": -44,
      "y": 36,
      "z": -6,
      "name": "Rock_Stone"
    },
    {
      "x": -44,
      "y": 31,
      "z": -5,
      "name": "Rock_Stone"
    },
    {
      "x": -44,
      "y": 32,
      "z": -5,
      "name": "Rock_Stone"
    },
    {
      "x": -44,
      "y": 35,
      "z": -5,
      "name": "Rock_Stone"
    },
    {
      "x": -44,
      "y": 36,
      "z": -5,
      "name": "Rock_Stone"
    },
    {
      "x": -44,
      "y": 29,
      "z": -4,
      "name": "Rock_Stone"
    },
    {
      "x": -44,
      "y": 30,
      "z": -4,
      "name": "Rock_Stone"
    },
    {
      "x": -44,
      "y": 31,
      "z": -4,
      "name": "Rock_Stone"
    },
    {
      "x": -44,
      "y": 36,
      "z": -4,
      "name": "Rock_Stone"
    },
    {
      "x": -44,
      "y": 37,
      "z": -4,
      "name": "Rock_Stone"
    },
    {
      "x": -44,
      "y": 38,
      "z": -4,
      "name": "Rock_Stone"
    },
    {
      "x": -44,
      "y": 29,
      "z": -3,
      "name": "Rock_Stone"
    },
    {
      "x": -44,
      "y": 30,
      "z": -3,
      "name": "Rock_Stone"
    },
    {
      "x": -44,
      "y": 31,
      "z": -3,
      "name": "Rock_Stone"
    },
    {
      "x": -44,
      "y": 36,
      "z": -3,
      "name": "Rock_Stone"
    },
    {
      "x": -44,
      "y": 37,
      "z": -3,
      "name": "Rock_Stone"
    },
    {
      "x": -44,
      "y": 38,
      "z": -3,
      "name": "Rock_Stone"
    },
    {
      "x": -44,
      "y": 31,
      "z": -2,
      "name": "Rock_Stone"
    },
    {
      "x": -44,
      "y": 32,
      "z": -2,
      "name": "Rock_Stone"
    },
    {
      "x": -44,
      "y": 35,
      "z": -2,
      "name": "Rock_Stone"
    },
    {
      "x": -44,
      "y": 36,
      "z": -2,
      "name": "Rock_Stone"
    },
    {
      "x": -44,
      "y": 32,
      "z": -1,
      "name": "Rock_Stone"
    },
    {
      "x": -44,
      "y": 33,
      "z": -1,
      "name": "Rock_Stone"
    },
    {
      "x": -44,
      "y": 35,
      "z": -1,
      "name": "Rock_Stone"
    },
    {
      "x": -44,
      "y": 36,
      "z": -1,
      "name": "Rock_Stone"
    },
    {
      "x": -44,
      "y": 32,
      "z": 0,
      "name": "Rock_Stone"
    },
    {
      "x": -44,
      "y": 33,
      "z": 0,
      "name": "Rock_Stone"
    },
    {
      "x": -44,
      "y": 34,
      "z": 0,
      "name": "Rock_Stone"
    },
    {
      "x": -44,
      "y": 35,
      "z": 0,
      "name": "Rock_Stone"
    },
    {
      "x": -44,
      "y": 33,
      "z": 1,
      "name": "Rock_Stone"
    },
    {
      "x": -44,
      "y": 34,
      "z": 1,
      "name": "Rock_Stone"
    },
    {
      "x": -44,
      "y": 35,
      "z": 1,
      "name": "Rock_Stone"
    },
    {
      "x": -44,
      "y": 33,
      "z": 2,
      "name": "Rock_Stone"
    },
    {
      "x": -44,
      "y": 34,
      "z": 2,
      "name": "Rock_Stone"
    },
    {
      "x": -43,
      "y": 33,
      "z": -9,
      "name": "Rock_Stone"
    },
    {
      "x": -43,
      "y": 34,
      "z": -9,
      "name": "Rock_Stone"
    },
    {
      "x": -43,
      "y": 33,
      "z": -8,
      "name": "Rock_Stone"
    },
    {
      "x": -43,
      "y": 34,
      "z": -8,
      "name": "Rock_Stone"
    },
    {
      "x": -43,
      "y": 35,
      "z": -8,
      "name": "Rock_Stone"
    },
    {
      "x": -43,
      "y": 32,
      "z": -7,
      "name": "Rock_Stone"
    },
    {
      "x": -43,
      "y": 33,
      "z": -7,
      "name": "Rock_Stone"
    },
    {
      "x": -43,
      "y": 34,
      "z": -7,
      "name": "Rock_Stone"
    },
    {
      "x": -43,
      "y": 35,
      "z": -7,
      "name": "Rock_Stone"
    },
    {
      "x": -43,
      "y": 31,
      "z": -6,
      "name": "Rock_Stone"
    },
    {
      "x": -43,
      "y": 32,
      "z": -6,
      "name": "Rock_Stone"
    },
    {
      "x": -43,
      "y": 35,
      "z": -6,
      "name": "Rock_Stone"
    },
    {
      "x": -43,
      "y": 36,
      "z": -6,
      "name": "Rock_Stone"
    },
    {
      "x": -43,
      "y": 30,
      "z": -5,
      "name": "Rock_Stone"
    },
    {
      "x": -43,
      "y": 31,
      "z": -5,
      "name": "Rock_Stone"
    },
    {
      "x": -43,
      "y": 32,
      "z": -5,
      "name": "Rock_Stone"
    },
    {
      "x": -43,
      "y": 35,
      "z": -5,
      "name": "Rock_Stone"
    },
    {
      "x": -43,
      "y": 36,
      "z": -5,
      "name": "Rock_Stone"
    },
    {
      "x": -43,
      "y": 28,
      "z": -4,
      "name": "Rock_Stone"
    },
    {
      "x": -43,
      "y": 29,
      "z": -4,
      "name": "Rock_Stone"
    },
    {
      "x": -43,
      "y": 30,
      "z": -4,
      "name": "Rock_Stone"
    },
    {
      "x": -43,
      "y": 31,
      "z": -4,
      "name": "Rock_Stone"
    },
    {
      "x": -43,
      "y": 36,
      "z": -4,
      "name": "Rock_Stone"
    },
    {
      "x": -43,
      "y": 37,
      "z": -4,
      "name": "Rock_Stone"
    },
    {
      "x": -43,
      "y": 38,
      "z": -4,
      "name": "Rock_Stone"
    },
    {
      "x": -43,
      "y": 28,
      "z": -3,
      "name": "Rock_Stone"
    },
    {
      "x": -43,
      "y": 29,
      "z": -3,
      "name": "Rock_Stone"
    },
    {
      "x": -43,
      "y": 30,
      "z": -3,
      "name": "Rock_Stone"
    },
    {
      "x": -43,
      "y": 31,
      "z": -3,
      "name": "Rock_Stone"
    },
    {
      "x": -43,
      "y": 36,
      "z": -3,
      "name": "Rock_Stone"
    },
    {
      "x": -43,
      "y": 37,
      "z": -3,
      "name": "Rock_Stone"
    },
    {
      "x": -43,
      "y": 38,
      "z": -3,
      "name": "Rock_Stone"
    },
    {
      "x": -43,
      "y": 31,
      "z": -2,
      "name": "Rock_Stone"
    },
    {
      "x": -43,
      "y": 32,
      "z": -2,
      "name": "Rock_Stone"
    },
    {
      "x": -43,
      "y": 35,
      "z": -2,
      "name": "Rock_Stone"
    },
    {
      "x": -43,
      "y": 36,
      "z": -2,
      "name": "Rock_Stone"
    },
    {
      "x": -43,
      "y": 32,
      "z": -1,
      "name": "Rock_Stone"
    },
    {
      "x": -43,
      "y": 33,
      "z": -1,
      "name": "Rock_Stone"
    },
    {
      "x": -43,
      "y": 35,
      "z": -1,
      "name": "Rock_Stone"
    },
    {
      "x": -43,
      "y": 36,
      "z": -1,
      "name": "Rock_Stone"
    },
    {
      "x": -43,
      "y": 32,
      "z": 0,
      "name": "Rock_Stone"
    },
    {
      "x": -43,
      "y": 33,
      "z": 0,
      "name": "Rock_Stone"
    },
    {
      "x": -43,
      "y": 34,
      "z": 0,
      "name": "Rock_Stone"
    },
    {
      "x": -43,
      "y": 35,
      "z": 0,
      "name": "Rock_Stone"
    },
    {
      "x": -43,
      "y": 33,
      "z": 1,
      "name": "Rock_Stone"
    },
    {
      "x": -43,
      "y": 34,
      "z": 1,
      "name": "Rock_Stone"
    },
    {
      "x": -43,
      "y": 35,
      "z": 1,
      "name": "Rock_Stone"
    },
    {
      "x": -43,
      "y": 33,
      "z": 2,
      "name": "Rock_Stone"
    },
    {
      "x": -43,
      "y": 34,
      "z": 2,
      "name": "Rock_Stone"
    },
    {
      "x": -42,
      "y": 34,
      "z": -10,
      "name": "Rock_Stone"
    },
    {
      "x": -42,
      "y": 33,
      "z": -9,
      "name": "Rock_Stone"
    },
    {
      "x": -42,
      "y": 34,
      "z": -9,
      "name": "Rock_Stone"
    },
    {
      "x": -42,
      "y": 32,
      "z": -8,
      "name": "Rock_Stone"
    },
    {
      "x": -42,
      "y": 33,
      "z": -8,
      "name": "Rock_Stone"
    },
    {
      "x": -42,
      "y": 34,
      "z": -8,
      "name": "Rock_Stone"
    },
    {
      "x": -42,
      "y": 35,
      "z": -8,
      "name": "Rock_Stone"
    },
    {
      "x": -42,
      "y": 32,
      "z": -7,
      "name": "Rock_Stone"
    },
    {
      "x": -42,
      "y": 33,
      "z": -7,
      "name": "Rock_Stone"
    },
    {
      "x": -42,
      "y": 35,
      "z": -7,
      "name": "Rock_Stone"
    },
    {
      "x": -42,
      "y": 31,
      "z": -6,
      "name": "Rock_Stone"
    },
    {
      "x": -42,
      "y": 32,
      "z": -6,
      "name": "Rock_Stone"
    },
    {
      "x": -42,
      "y": 35,
      "z": -6,
      "name": "Rock_Stone"
    },
    {
      "x": -42,
      "y": 36,
      "z": -6,
      "name": "Rock_Stone"
    },
    {
      "x": -42,
      "y": 29,
      "z": -5,
      "name": "Rock_Stone"
    },
    {
      "x": -42,
      "y": 30,
      "z": -5,
      "name": "Rock_Stone"
    },
    {
      "x": -42,
      "y": 31,
      "z": -5,
      "name": "Rock_Stone"
    },
    {
      "x": -42,
      "y": 32,
      "z": -5,
      "name": "Rock_Stone"
    },
    {
      "x": -42,
      "y": 36,
      "z": -5,
      "name": "Rock_Stone"
    },
    {
      "x": -42,
      "y": 28,
      "z": -4,
      "name": "Rock_Stone"
    },
    {
      "x": -42,
      "y": 29,
      "z": -4,
      "name": "Rock_Stone"
    },
    {
      "x": -42,
      "y": 30,
      "z": -4,
      "name": "Rock_Stone"
    },
    {
      "x": -42,
      "y": 31,
      "z": -4,
      "name": "Rock_Stone"
    },
    {
      "x": -42,
      "y": 36,
      "z": -4,
      "name": "Rock_Stone"
    },
    {
      "x": -42,
      "y": 37,
      "z": -4,
      "name": "Rock_Stone"
    },
    {
      "x": -42,
      "y": 38,
      "z": -4,
      "name": "Rock_Stone"
    },
    {
      "x": -42,
      "y": 39,
      "z": -4,
      "name": "Rock_Stone"
    },
    {
      "x": -42,
      "y": 28,
      "z": -3,
      "name": "Rock_Stone"
    },
    {
      "x": -42,
      "y": 29,
      "z": -3,
      "name": "Rock_Stone"
    },
    {
      "x": -42,
      "y": 30,
      "z": -3,
      "name": "Rock_Stone"
    },
    {
      "x": -42,
      "y": 31,
      "z": -3,
      "name": "Rock_Stone"
    },
    {
      "x": -42,
      "y": 36,
      "z": -3,
      "name": "Rock_Stone"
    },
    {
      "x": -42,
      "y": 37,
      "z": -3,
      "name": "Rock_Stone"
    },
    {
      "x": -42,
      "y": 38,
      "z": -3,
      "name": "Rock_Stone"
    },
    {
      "x": -42,
      "y": 31,
      "z": -2,
      "name": "Rock_Stone"
    },
    {
      "x": -42,
      "y": 32,
      "z": -2,
      "name": "Rock_Stone"
    },
    {
      "x": -42,
      "y": 35,
      "z": -2,
      "name": "Rock_Stone"
    },
    {
      "x": -42,
      "y": 36,
      "z": -2,
      "name": "Rock_Stone"
    },
    {
      "x": -42,
      "y": 32,
      "z": -1,
      "name": "Rock_Stone"
    },
    {
      "x": -42,
      "y": 33,
      "z": -1,
      "name": "Rock_Stone"
    },
    {
      "x": -42,
      "y": 35,
      "z": -1,
      "name": "Rock_Stone"
    },
    {
      "x": -42,
      "y": 36,
      "z": -1,
      "name": "Rock_Stone"
    },
    {
      "x": -42,
      "y": 32,
      "z": 0,
      "name": "Rock_Stone"
    },
    {
      "x": -42,
      "y": 33,
      "z": 0,
      "name": "Rock_Stone"
    },
    {
      "x": -42,
      "y": 34,
      "z": 0,
      "name": "Rock_Stone"
    },
    {
      "x": -42,
      "y": 35,
      "z": 0,
      "name": "Rock_Stone"
    },
    {
      "x": -42,
      "y": 33,
      "z": 1,
      "name": "Rock_Stone"
    },
    {
      "x": -42,
      "y": 34,
      "z": 1,
      "name": "Rock_Stone"
    },
    {
      "x": -42,
      "y": 35,
      "z": 1,
      "name": "Rock_Stone"
    },
    {
      "x": -42,
      "y": 33,
      "z": 2,
      "name": "Rock_Stone"
    },
    {
      "x": -42,
      "y": 34,
      "z": 2,
      "name": "Rock_Stone"
    },
    {
      "x": -41,
      "y": 33,
      "z": -10,
      "name": "Rock_Stone"
    },
    {
      "x": -41,
      "y": 34,
      "z": -10,
      "name": "Rock_Stone"
    },
    {
      "x": -41,
      "y": 33,
      "z": -9,
      "name": "Rock_Stone"
    },
    {
      "x": -41,
      "y": 34,
      "z": -9,
      "name": "Rock_Stone"
    },
    {
      "x": -41,
      "y": 35,
      "z": -9,
      "name": "Rock_Stone"
    },
    {
      "x": -41,
      "y": 32,
      "z": -8,
      "name": "Rock_Stone"
    },
    {
      "x": -41,
      "y": 33,
      "z": -8,
      "name": "Rock_Stone"
    },
    {
      "x": -41,
      "y": 34,
      "z": -8,
      "name": "Rock_Stone"
    },
    {
      "x": -41,
      "y": 35,
      "z": -8,
      "name": "Rock_Stone"
    },
    {
      "x": -41,
      "y": 32,
      "z": -7,
      "name": "Rock_Stone"
    },
    {
      "x": -41,
      "y": 33,
      "z": -7,
      "name": "Rock_Stone"
    },
    {
      "x": -41,
      "y": 35,
      "z": -7,
      "name": "Rock_Stone"
    },
    {
      "x": -41,
      "y": 36,
      "z": -7,
      "name": "Rock_Stone"
    },
    {
      "x": -41,
      "y": 31,
      "z": -6,
      "name": "Rock_Stone"
    },
    {
      "x": -41,
      "y": 32,
      "z": -6,
      "name": "Rock_Stone"
    },
    {
      "x": -41,
      "y": 35,
      "z": -6,
      "name": "Rock_Stone"
    },
    {
      "x": -41,
      "y": 36,
      "z": -6,
      "name": "Rock_Stone"
    },
    {
      "x": -41,
      "y": 28,
      "z": -5,
      "name": "Rock_Stone"
    },
    {
      "x": -41,
      "y": 29,
      "z": -5,
      "name": "Rock_Stone"
    },
    {
      "x": -41,
      "y": 30,
      "z": -5,
      "name": "Rock_Stone"
    },
    {
      "x": -41,
      "y": 31,
      "z": -5,
      "name": "Rock_Stone"
    },
    {
      "x": -41,
      "y": 32,
      "z": -5,
      "name": "Rock_Stone"
    },
    {
      "x": -41,
      "y": 36,
      "z": -5,
      "name": "Rock_Stone"
    },
    {
      "x": -41,
      "y": 37,
      "z": -5,
      "name": "Rock_Stone"
    },
    {
      "x": -41,
      "y": 38,
      "z": -5,
      "name": "Rock_Stone"
    },
    {
      "x": -41,
      "y": 27,
      "z": -4,
      "name": "Rock_Stone"
    },
    {
      "x": -41,
      "y": 28,
      "z": -4,
      "name": "Rock_Stone"
    },
    {
      "x": -41,
      "y": 29,
      "z": -4,
      "name": "Rock_Stone"
    },
    {
      "x": -41,
      "y": 30,
      "z": -4,
      "name": "Rock_Stone"
    },
    {
      "x": -41,
      "y": 36,
      "z": -4,
      "name": "Rock_Stone"
    },
    {
      "x": -41,
      "y": 37,
      "z": -4,
      "name": "Rock_Stone"
    },
    {
      "x": -41,
      "y": 38,
      "z": -4,
      "name": "Rock_Stone"
    },
    {
      "x": -41,
      "y": 39,
      "z": -4,
      "name": "Rock_Stone"
    },
    {
      "x": -41,
      "y": 28,
      "z": -3,
      "name": "Rock_Stone"
    },
    {
      "x": -41,
      "y": 29,
      "z": -3,
      "name": "Rock_Stone"
    },
    {
      "x": -41,
      "y": 30,
      "z": -3,
      "name": "Rock_Stone"
    },
    {
      "x": -41,
      "y": 31,
      "z": -3,
      "name": "Rock_Stone"
    },
    {
      "x": -41,
      "y": 36,
      "z": -3,
      "name": "Rock_Stone"
    },
    {
      "x": -41,
      "y": 37,
      "z": -3,
      "name": "Rock_Stone"
    },
    {
      "x": -41,
      "y": 38,
      "z": -3,
      "name": "Rock_Stone"
    },
    {
      "x": -41,
      "y": 39,
      "z": -3,
      "name": "Rock_Stone"
    },
    {
      "x": -41,
      "y": 31,
      "z": -2,
      "name": "Rock_Stone"
    },
    {
      "x": -41,
      "y": 32,
      "z": -2,
      "name": "Rock_Stone"
    },
    {
      "x": -41,
      "y": 36,
      "z": -2,
      "name": "Rock_Stone"
    },
    {
      "x": -41,
      "y": 37,
      "z": -2,
      "name": "Rock_Stone"
    },
    {
      "x": -41,
      "y": 31,
      "z": -1,
      "name": "Rock_Stone"
    },
    {
      "x": -41,
      "y": 32,
      "z": -1,
      "name": "Rock_Stone"
    },
    {
      "x": -41,
      "y": 35,
      "z": -1,
      "name": "Rock_Stone"
    },
    {
      "x": -41,
      "y": 36,
      "z": -1,
      "name": "Rock_Stone"
    },
    {
      "x": -41,
      "y": 32,
      "z": 0,
      "name": "Rock_Stone"
    },
    {
      "x": -41,
      "y": 33,
      "z": 0,
      "name": "Rock_Stone"
    },
    {
      "x": -41,
      "y": 35,
      "z": 0,
      "name": "Rock_Stone"
    },
    {
      "x": -41,
      "y": 36,
      "z": 0,
      "name": "Rock_Stone"
    },
    {
      "x": -41,
      "y": 32,
      "z": 1,
      "name": "Rock_Stone"
    },
    {
      "x": -41,
      "y": 33,
      "z": 1,
      "name": "Rock_Stone"
    },
    {
      "x": -41,
      "y": 34,
      "z": 1,
      "name": "Rock_Stone"
    },
    {
      "x": -41,
      "y": 35,
      "z": 1,
      "name": "Rock_Stone"
    },
    {
      "x": -41,
      "y": 33,
      "z": 2,
      "name": "Rock_Stone"
    },
    {
      "x": -41,
      "y": 34,
      "z": 2,
      "name": "Rock_Stone"
    },
    {
      "x": -41,
      "y": 35,
      "z": 2,
      "name": "Rock_Stone"
    },
    {
      "x": -41,
      "y": 33,
      "z": 3,
      "name": "Rock_Stone"
    },
    {
      "x": -41,
      "y": 34,
      "z": 3,
      "name": "Rock_Stone"
    },
    {
      "x": -40,
      "y": 33,
      "z": -10,
      "name": "Rock_Stone"
    },
    {
      "x": -40,
      "y": 34,
      "z": -10,
      "name": "Rock_Stone"
    },
    {
      "x": -40,
      "y": 33,
      "z": -9,
      "name": "Rock_Stone"
    },
    {
      "x": -40,
      "y": 34,
      "z": -9,
      "name": "Rock_Stone"
    },
    {
      "x": -40,
      "y": 35,
      "z": -9,
      "name": "Rock_Stone"
    },
    {
      "x": -40,
      "y": 32,
      "z": -8,
      "name": "Rock_Stone"
    },
    {
      "x": -40,
      "y": 33,
      "z": -8,
      "name": "Rock_Stone"
    },
    {
      "x": -40,
      "y": 34,
      "z": -8,
      "name": "Rock_Stone"
    },
    {
      "x": -40,
      "y": 35,
      "z": -8,
      "name": "Rock_Stone"
    },
    {
      "x": -40,
      "y": 31,
      "z": -7,
      "name": "Rock_Stone"
    },
    {
      "x": -40,
      "y": 32,
      "z": -7,
      "name": "Rock_Stone"
    },
    {
      "x": -40,
      "y": 35,
      "z": -7,
      "name": "Rock_Stone"
    },
    {
      "x": -40,
      "y": 36,
      "z": -7,
      "name": "Rock_Stone"
    },
    {
      "x": -40,
      "y": 31,
      "z": -6,
      "name": "Rock_Stone"
    },
    {
      "x": -40,
      "y": 32,
      "z": -6,
      "name": "Rock_Stone"
    },
    {
      "x": -40,
      "y": 35,
      "z": -6,
      "name": "Rock_Stone"
    },
    {
      "x": -40,
      "y": 36,
      "z": -6,
      "name": "Rock_Stone"
    },
    {
      "x": -40,
      "y": 28,
      "z": -5,
      "name": "Rock_Stone"
    },
    {
      "x": -40,
      "y": 29,
      "z": -5,
      "name": "Rock_Stone"
    },
    {
      "x": -40,
      "y": 30,
      "z": -5,
      "name": "Rock_Stone"
    },
    {
      "x": -40,
      "y": 31,
      "z": -5,
      "name": "Rock_Stone"
    },
    {
      "x": -40,
      "y": 36,
      "z": -5,
      "name": "Rock_Stone"
    },
    {
      "x": -40,
      "y": 37,
      "z": -5,
      "name": "Rock_Stone"
    },
    {
      "x": -40,
      "y": 38,
      "z": -5,
      "name": "Rock_Stone"
    },
    {
      "x": -40,
      "y": 39,
      "z": -5,
      "name": "Rock_Stone"
    },
    {
      "x": -40,
      "y": 27,
      "z": -4,
      "name": "Rock_Stone"
    },
    {
      "x": -40,
      "y": 28,
      "z": -4,
      "name": "Rock_Stone"
    },
    {
      "x": -40,
      "y": 29,
      "z": -4,
      "name": "Rock_Stone"
    },
    {
      "x": -40,
      "y": 30,
      "z": -4,
      "name": "Rock_Stone"
    },
    {
      "x": -40,
      "y": 36,
      "z": -4,
      "name": "Rock_Stone"
    },
    {
      "x": -40,
      "y": 37,
      "z": -4,
      "name": "Rock_Stone"
    },
    {
      "x": -40,
      "y": 38,
      "z": -4,
      "name": "Rock_Stone"
    },
    {
      "x": -40,
      "y": 39,
      "z": -4,
      "name": "Rock_Stone"
    },
    {
      "x": -40,
      "y": 27,
      "z": -3,
      "name": "Rock_Stone"
    },
    {
      "x": -40,
      "y": 28,
      "z": -3,
      "name": "Rock_Stone"
    },
    {
      "x": -40,
      "y": 29,
      "z": -3,
      "name": "Rock_Stone"
    },
    {
      "x": -40,
      "y": 30,
      "z": -3,
      "name": "Rock_Stone"
    },
    {
      "x": -40,
      "y": 31,
      "z": -3,
      "name": "Rock_Stone"
    },
    {
      "x": -40,
      "y": 36,
      "z": -3,
      "name": "Rock_Stone"
    },
    {
      "x": -40,
      "y": 37,
      "z": -3,
      "name": "Rock_Stone"
    },
    {
      "x": -40,
      "y": 38,
      "z": -3,
      "name": "Rock_Stone"
    },
    {
      "x": -40,
      "y": 39,
      "z": -3,
      "name": "Rock_Stone"
    },
    {
      "x": -40,
      "y": 28,
      "z": -2,
      "name": "Rock_Stone"
    },
    {
      "x": -40,
      "y": 29,
      "z": -2,
      "name": "Rock_Stone"
    },
    {
      "x": -40,
      "y": 30,
      "z": -2,
      "name": "Rock_Stone"
    },
    {
      "x": -40,
      "y": 31,
      "z": -2,
      "name": "Rock_Stone"
    },
    {
      "x": -40,
      "y": 32,
      "z": -2,
      "name": "Rock_Stone"
    },
    {
      "x": -40,
      "y": 36,
      "z": -2,
      "name": "Rock_Stone"
    },
    {
      "x": -40,
      "y": 37,
      "z": -2,
      "name": "Rock_Stone"
    },
    {
      "x": -40,
      "y": 38,
      "z": -2,
      "name": "Rock_Stone"
    },
    {
      "x": -40,
      "y": 39,
      "z": -2,
      "name": "Rock_Stone"
    },
    {
      "x": -40,
      "y": 31,
      "z": -1,
      "name": "Rock_Stone"
    },
    {
      "x": -40,
      "y": 32,
      "z": -1,
      "name": "Rock_Stone"
    },
    {
      "x": -40,
      "y": 35,
      "z": -1,
      "name": "Rock_Stone"
    },
    {
      "x": -40,
      "y": 36,
      "z": -1,
      "name": "Rock_Stone"
    },
    {
      "x": -40,
      "y": 32,
      "z": 0,
      "name": "Rock_Stone"
    },
    {
      "x": -40,
      "y": 33,
      "z": 0,
      "name": "Rock_Stone"
    },
    {
      "x": -40,
      "y": 35,
      "z": 0,
      "name": "Rock_Stone"
    },
    {
      "x": -40,
      "y": 36,
      "z": 0,
      "name": "Rock_Stone"
    },
    {
      "x": -40,
      "y": 32,
      "z": 1,
      "name": "Rock_Stone"
    },
    {
      "x": -40,
      "y": 33,
      "z": 1,
      "name": "Rock_Stone"
    },
    {
      "x": -40,
      "y": 34,
      "z": 1,
      "name": "Rock_Stone"
    },
    {
      "x": -40,
      "y": 35,
      "z": 1,
      "name": "Rock_Stone"
    },
    {
      "x": -40,
      "y": 33,
      "z": 2,
      "name": "Rock_Stone"
    },
    {
      "x": -40,
      "y": 34,
      "z": 2,
      "name": "Rock_Stone"
    },
    {
      "x": -40,
      "y": 35,
      "z": 2,
      "name": "Rock_Stone"
    },
    {
      "x": -40,
      "y": 33,
      "z": 3,
      "name": "Rock_Stone"
    },
    {
      "x": -40,
      "y": 34,
      "z": 3,
      "name": "Rock_Stone"
    },
    {
      "x": -39,
      "y": 34,
      "z": -11,
      "name": "Rock_Stone"
    },
    {
      "x": -39,
      "y": 33,
      "z": -10,
      "name": "Rock_Stone"
    },
    {
      "x": -39,
      "y": 34,
      "z": -10,
      "name": "Rock_Stone"
    },
    {
      "x": -39,
      "y": 32,
      "z": -9,
      "name": "Rock_Stone"
    },
    {
      "x": -39,
      "y": 33,
      "z": -9,
      "name": "Rock_Stone"
    },
    {
      "x": -39,
      "y": 34,
      "z": -9,
      "name": "Rock_Stone"
    },
    {
      "x": -39,
      "y": 35,
      "z": -9,
      "name": "Rock_Stone"
    },
    {
      "x": -39,
      "y": 32,
      "z": -8,
      "name": "Rock_Stone"
    },
    {
      "x": -39,
      "y": 33,
      "z": -8,
      "name": "Rock_Stone"
    },
    {
      "x": -39,
      "y": 34,
      "z": -8,
      "name": "Rock_Stone"
    },
    {
      "x": -39,
      "y": 35,
      "z": -8,
      "name": "Rock_Stone"
    },
    {
      "x": -39,
      "y": 31,
      "z": -7,
      "name": "Rock_Stone"
    },
    {
      "x": -39,
      "y": 32,
      "z": -7,
      "name": "Rock_Stone"
    },
    {
      "x": -39,
      "y": 35,
      "z": -7,
      "name": "Rock_Stone"
    },
    {
      "x": -39,
      "y": 36,
      "z": -7,
      "name": "Rock_Stone"
    },
    {
      "x": -39,
      "y": 31,
      "z": -6,
      "name": "Rock_Stone"
    },
    {
      "x": -39,
      "y": 32,
      "z": -6,
      "name": "Rock_Stone"
    },
    {
      "x": -39,
      "y": 35,
      "z": -6,
      "name": "Rock_Stone"
    },
    {
      "x": -39,
      "y": 36,
      "z": -6,
      "name": "Rock_Stone"
    },
    {
      "x": -39,
      "y": 27,
      "z": -5,
      "name": "Rock_Stone"
    },
    {
      "x": -39,
      "y": 28,
      "z": -5,
      "name": "Rock_Stone"
    },
    {
      "x": -39,
      "y": 29,
      "z": -5,
      "name": "Rock_Stone"
    },
    {
      "x": -39,
      "y": 30,
      "z": -5,
      "name": "Rock_Stone"
    },
    {
      "x": -39,
      "y": 31,
      "z": -5,
      "name": "Rock_Stone"
    },
    {
      "x": -39,
      "y": 36,
      "z": -5,
      "name": "Rock_Stone"
    },
    {
      "x": -39,
      "y": 37,
      "z": -5,
      "name": "Rock_Stone"
    },
    {
      "x": -39,
      "y": 38,
      "z": -5,
      "name": "Rock_Stone"
    },
    {
      "x": -39,
      "y": 39,
      "z": -5,
      "name": "Rock_Stone"
    },
    {
      "x": -39,
      "y": 27,
      "z": -4,
      "name": "Rock_Stone"
    },
    {
      "x": -39,
      "y": 28,
      "z": -4,
      "name": "Rock_Stone"
    },
    {
      "x": -39,
      "y": 29,
      "z": -4,
      "name": "Rock_Stone"
    },
    {
      "x": -39,
      "y": 30,
      "z": -4,
      "name": "Rock_Stone"
    },
    {
      "x": -39,
      "y": 37,
      "z": -4,
      "name": "Rock_Stone"
    },
    {
      "x": -39,
      "y": 38,
      "z": -4,
      "name": "Rock_Stone"
    },
    {
      "x": -39,
      "y": 39,
      "z": -4,
      "name": "Rock_Stone"
    },
    {
      "x": -39,
      "y": 40,
      "z": -4,
      "name": "Rock_Stone"
    },
    {
      "x": -39,
      "y": 27,
      "z": -3,
      "name": "Rock_Stone"
    },
    {
      "x": -39,
      "y": 28,
      "z": -3,
      "name": "Rock_Stone"
    },
    {
      "x": -39,
      "y": 29,
      "z": -3,
      "name": "Rock_Stone"
    },
    {
      "x": -39,
      "y": 30,
      "z": -3,
      "name": "Rock_Stone"
    },
    {
      "x": -39,
      "y": 31,
      "z": -3,
      "name": "Rock_Stone"
    },
    {
      "x": -39,
      "y": 36,
      "z": -3,
      "name": "Rock_Stone"
    },
    {
      "x": -39,
      "y": 37,
      "z": -3,
      "name": "Rock_Stone"
    },
    {
      "x": -39,
      "y": 38,
      "z": -3,
      "name": "Rock_Stone"
    },
    {
      "x": -39,
      "y": 39,
      "z": -3,
      "name": "Rock_Stone"
    },
    {
      "x": -39,
      "y": 40,
      "z": -3,
      "name": "Rock_Stone"
    },
    {
      "x": -39,
      "y": 28,
      "z": -2,
      "name": "Rock_Stone"
    },
    {
      "x": -39,
      "y": 29,
      "z": -2,
      "name": "Rock_Stone"
    },
    {
      "x": -39,
      "y": 30,
      "z": -2,
      "name": "Rock_Stone"
    },
    {
      "x": -39,
      "y": 31,
      "z": -2,
      "name": "Rock_Stone"
    },
    {
      "x": -39,
      "y": 36,
      "z": -2,
      "name": "Rock_Stone"
    },
    {
      "x": -39,
      "y": 37,
      "z": -2,
      "name": "Rock_Stone"
    },
    {
      "x": -39,
      "y": 38,
      "z": -2,
      "name": "Rock_Stone"
    },
    {
      "x": -39,
      "y": 39,
      "z": -2,
      "name": "Rock_Stone"
    },
    {
      "x": -39,
      "y": 31,
      "z": -1,
      "name": "Rock_Stone"
    },
    {
      "x": -39,
      "y": 32,
      "z": -1,
      "name": "Rock_Stone"
    },
    {
      "x": -39,
      "y": 35,
      "z": -1,
      "name": "Rock_Stone"
    },
    {
      "x": -39,
      "y": 36,
      "z": -1,
      "name": "Rock_Stone"
    },
    {
      "x": -39,
      "y": 31,
      "z": 0,
      "name": "Rock_Stone"
    },
    {
      "x": -39,
      "y": 32,
      "z": 0,
      "name": "Rock_Stone"
    },
    {
      "x": -39,
      "y": 35,
      "z": 0,
      "name": "Rock_Stone"
    },
    {
      "x": -39,
      "y": 36,
      "z": 0,
      "name": "Rock_Stone"
    },
    {
      "x": -39,
      "y": 32,
      "z": 1,
      "name": "Rock_Stone"
    },
    {
      "x": -39,
      "y": 33,
      "z": 1,
      "name": "Rock_Stone"
    },
    {
      "x": -39,
      "y": 34,
      "z": 1,
      "name": "Rock_Stone"
    },
    {
      "x": -39,
      "y": 35,
      "z": 1,
      "name": "Rock_Stone"
    },
    {
      "x": -39,
      "y": 32,
      "z": 2,
      "name": "Rock_Stone"
    },
    {
      "x": -39,
      "y": 33,
      "z": 2,
      "name": "Rock_Stone"
    },
    {
      "x": -39,
      "y": 34,
      "z": 2,
      "name": "Rock_Stone"
    },
    {
      "x": -39,
      "y": 35,
      "z": 2,
      "name": "Rock_Stone"
    },
    {
      "x": -39,
      "y": 33,
      "z": 3,
      "name": "Rock_Stone"
    },
    {
      "x": -39,
      "y": 34,
      "z": 3,
      "name": "Rock_Stone"
    },
    {
      "x": -39,
      "y": 34,
      "z": 4,
      "name": "Rock_Stone"
    },
    {
      "x": -38,
      "y": 33,
      "z": -11,
      "name": "Rock_Stone"
    },
    {
      "x": -38,
      "y": 34,
      "z": -11,
      "name": "Rock_Stone"
    },
    {
      "x": -38,
      "y": 33,
      "z": -10,
      "name": "Rock_Stone"
    },
    {
      "x": -38,
      "y": 34,
      "z": -10,
      "name": "Rock_Stone"
    },
    {
      "x": -38,
      "y": 32,
      "z": -9,
      "name": "Rock_Stone"
    },
    {
      "x": -38,
      "y": 33,
      "z": -9,
      "name": "Rock_Stone"
    },
    {
      "x": -38,
      "y": 34,
      "z": -9,
      "name": "Rock_Stone"
    },
    {
      "x": -38,
      "y": 35,
      "z": -9,
      "name": "Rock_Stone"
    },
    {
      "x": -38,
      "y": 32,
      "z": -8,
      "name": "Rock_Stone"
    },
    {
      "x": -38,
      "y": 33,
      "z": -8,
      "name": "Rock_Stone"
    },
    {
      "x": -38,
      "y": 34,
      "z": -8,
      "name": "Rock_Stone"
    },
    {
      "x": -38,
      "y": 35,
      "z": -8,
      "name": "Rock_Stone"
    },
    {
      "x": -38,
      "y": 31,
      "z": -7,
      "name": "Rock_Stone"
    },
    {
      "x": -38,
      "y": 32,
      "z": -7,
      "name": "Rock_Stone"
    },
    {
      "x": -38,
      "y": 35,
      "z": -7,
      "name": "Rock_Stone"
    },
    {
      "x": -38,
      "y": 36,
      "z": -7,
      "name": "Rock_Stone"
    },
    {
      "x": -38,
      "y": 31,
      "z": -6,
      "name": "Rock_Stone"
    },
    {
      "x": -38,
      "y": 32,
      "z": -6,
      "name": "Rock_Stone"
    },
    {
      "x": -38,
      "y": 35,
      "z": -6,
      "name": "Rock_Stone"
    },
    {
      "x": -38,
      "y": 36,
      "z": -6,
      "name": "Rock_Stone"
    },
    {
      "x": -38,
      "y": 27,
      "z": -5,
      "name": "Rock_Stone"
    },
    {
      "x": -38,
      "y": 28,
      "z": -5,
      "name": "Rock_Stone"
    },
    {
      "x": -38,
      "y": 29,
      "z": -5,
      "name": "Rock_Stone"
    },
    {
      "x": -38,
      "y": 30,
      "z": -5,
      "name": "Rock_Stone"
    },
    {
      "x": -38,
      "y": 31,
      "z": -5,
      "name": "Rock_Stone"
    },
    {
      "x": -38,
      "y": 36,
      "z": -5,
      "name": "Rock_Stone"
    },
    {
      "x": -38,
      "y": 37,
      "z": -5,
      "name": "Rock_Stone"
    },
    {
      "x": -38,
      "y": 38,
      "z": -5,
      "name": "Rock_Stone"
    },
    {
      "x": -38,
      "y": 39,
      "z": -5,
      "name": "Rock_Stone"
    },
    {
      "x": -38,
      "y": 26,
      "z": -4,
      "name": "Rock_Stone"
    },
    {
      "x": -38,
      "y": 27,
      "z": -4,
      "name": "Rock_Stone"
    },
    {
      "x": -38,
      "y": 28,
      "z": -4,
      "name": "Rock_Stone"
    },
    {
      "x": -38,
      "y": 29,
      "z": -4,
      "name": "Rock_Stone"
    },
    {
      "x": -38,
      "y": 30,
      "z": -4,
      "name": "Rock_Stone"
    },
    {
      "x": -38,
      "y": 37,
      "z": -4,
      "name": "Rock_Stone"
    },
    {
      "x": -38,
      "y": 38,
      "z": -4,
      "name": "Rock_Stone"
    },
    {
      "x": -38,
      "y": 39,
      "z": -4,
      "name": "Rock_Stone"
    },
    {
      "x": -38,
      "y": 40,
      "z": -4,
      "name": "Rock_Stone"
    },
    {
      "x": -38,
      "y": 26,
      "z": -3,
      "name": "Rock_Stone"
    },
    {
      "x": -38,
      "y": 27,
      "z": -3,
      "name": "Rock_Stone"
    },
    {
      "x": -38,
      "y": 28,
      "z": -3,
      "name": "Rock_Stone"
    },
    {
      "x": -38,
      "y": 29,
      "z": -3,
      "name": "Rock_Stone"
    },
    {
      "x": -38,
      "y": 30,
      "z": -3,
      "name": "Rock_Stone"
    },
    {
      "x": -38,
      "y": 31,
      "z": -3,
      "name": "Rock_Stone"
    },
    {
      "x": -38,
      "y": 36,
      "z": -3,
      "name": "Rock_Stone"
    },
    {
      "x": -38,
      "y": 37,
      "z": -3,
      "name": "Rock_Stone"
    },
    {
      "x": -38,
      "y": 38,
      "z": -3,
      "name": "Rock_Stone"
    },
    {
      "x": -38,
      "y": 39,
      "z": -3,
      "name": "Rock_Stone"
    },
    {
      "x": -38,
      "y": 40,
      "z": -3,
      "name": "Rock_Stone"
    },
    {
      "x": -38,
      "y": 27,
      "z": -2,
      "name": "Rock_Stone"
    },
    {
      "x": -38,
      "y": 28,
      "z": -2,
      "name": "Rock_Stone"
    },
    {
      "x": -38,
      "y": 29,
      "z": -2,
      "name": "Rock_Stone"
    },
    {
      "x": -38,
      "y": 30,
      "z": -2,
      "name": "Rock_Stone"
    },
    {
      "x": -38,
      "y": 31,
      "z": -2,
      "name": "Rock_Stone"
    },
    {
      "x": -38,
      "y": 36,
      "z": -2,
      "name": "Rock_Stone"
    },
    {
      "x": -38,
      "y": 37,
      "z": -2,
      "name": "Rock_Stone"
    },
    {
      "x": -38,
      "y": 38,
      "z": -2,
      "name": "Rock_Stone"
    },
    {
      "x": -38,
      "y": 39,
      "z": -2,
      "name": "Rock_Stone"
    },
    {
      "x": -38,
      "y": 31,
      "z": -1,
      "name": "Rock_Stone"
    },
    {
      "x": -38,
      "y": 32,
      "z": -1,
      "name": "Rock_Stone"
    },
    {
      "x": -38,
      "y": 35,
      "z": -1,
      "name": "Rock_Stone"
    },
    {
      "x": -38,
      "y": 36,
      "z": -1,
      "name": "Rock_Stone"
    },
    {
      "x": -38,
      "y": 31,
      "z": 0,
      "name": "Rock_Stone"
    },
    {
      "x": -38,
      "y": 32,
      "z": 0,
      "name": "Rock_Stone"
    },
    {
      "x": -38,
      "y": 35,
      "z": 0,
      "name": "Rock_Stone"
    },
    {
      "x": -38,
      "y": 36,
      "z": 0,
      "name": "Rock_Stone"
    },
    {
      "x": -38,
      "y": 32,
      "z": 1,
      "name": "Rock_Stone"
    },
    {
      "x": -38,
      "y": 33,
      "z": 1,
      "name": "Rock_Stone"
    },
    {
      "x": -38,
      "y": 34,
      "z": 1,
      "name": "Rock_Stone"
    },
    {
      "x": -38,
      "y": 35,
      "z": 1,
      "name": "Rock_Stone"
    },
    {
      "x": -38,
      "y": 32,
      "z": 2,
      "name": "Rock_Stone"
    },
    {
      "x": -38,
      "y": 33,
      "z": 2,
      "name": "Rock_Stone"
    },
    {
      "x": -38,
      "y": 34,
      "z": 2,
      "name": "Rock_Stone"
    },
    {
      "x": -38,
      "y": 35,
      "z": 2,
      "name": "Rock_Stone"
    },
    {
      "x": -38,
      "y": 33,
      "z": 3,
      "name": "Rock_Stone"
    },
    {
      "x": -38,
      "y": 34,
      "z": 3,
      "name": "Rock_Stone"
    },
    {
      "x": -38,
      "y": 33,
      "z": 4,
      "name": "Rock_Stone"
    },
    {
      "x": -38,
      "y": 34,
      "z": 4,
      "name": "Rock_Stone"
    },
    {
      "x": -37,
      "y": 33,
      "z": -11,
      "name": "Rock_Stone"
    },
    {
      "x": -37,
      "y": 34,
      "z": -11,
      "name": "Rock_Stone"
    },
    {
      "x": -37,
      "y": 33,
      "z": -10,
      "name": "Rock_Stone"
    },
    {
      "x": -37,
      "y": 34,
      "z": -10,
      "name": "Rock_Stone"
    },
    {
      "x": -37,
      "y": 35,
      "z": -10,
      "name": "Rock_Stone"
    },
    {
      "x": -37,
      "y": 32,
      "z": -9,
      "name": "Rock_Stone"
    },
    {
      "x": -37,
      "y": 33,
      "z": -9,
      "name": "Rock_Stone"
    },
    {
      "x": -37,
      "y": 34,
      "z": -9,
      "name": "Rock_Stone"
    },
    {
      "x": -37,
      "y": 35,
      "z": -9,
      "name": "Rock_Stone"
    },
    {
      "x": -37,
      "y": 31,
      "z": -8,
      "name": "Rock_Stone"
    },
    {
      "x": -37,
      "y": 32,
      "z": -8,
      "name": "Rock_Stone"
    },
    {
      "x": -37,
      "y": 35,
      "z": -8,
      "name": "Rock_Stone"
    },
    {
      "x": -37,
      "y": 31,
      "z": -7,
      "name": "Rock_Stone"
    },
    {
      "x": -37,
      "y": 32,
      "z": -7,
      "name": "Rock_Stone"
    },
    {
      "x": -37,
      "y": 35,
      "z": -7,
      "name": "Rock_Stone"
    },
    {
      "x": -37,
      "y": 36,
      "z": -7,
      "name": "Rock_Stone"
    },
    {
      "x": -37,
      "y": 30,
      "z": -6,
      "name": "Rock_Stone"
    },
    {
      "x": -37,
      "y": 31,
      "z": -6,
      "name": "Rock_Stone"
    },
    {
      "x": -37,
      "y": 35,
      "z": -6,
      "name": "Rock_Stone"
    },
    {
      "x": -37,
      "y": 36,
      "z": -6,
      "name": "Rock_Stone"
    },
    {
      "x": -37,
      "y": 26,
      "z": -5,
      "name": "Rock_Stone"
    },
    {
      "x": -37,
      "y": 27,
      "z": -5,
      "name": "Rock_Stone"
    },
    {
      "x": -37,
      "y": 28,
      "z": -5,
      "name": "Rock_Stone"
    },
    {
      "x": -37,
      "y": 29,
      "z": -5,
      "name": "Rock_Stone"
    },
    {
      "x": -37,
      "y": 30,
      "z": -5,
      "name": "Rock_Stone"
    },
    {
      "x": -37,
      "y": 31,
      "z": -5,
      "name": "Rock_Stone"
    },
    {
      "x": -37,
      "y": 36,
      "z": -5,
      "name": "Rock_Stone"
    },
    {
      "x": -37,
      "y": 37,
      "z": -5,
      "name": "Rock_Stone"
    },
    {
      "x": -37,
      "y": 38,
      "z": -5,
      "name": "Rock_Stone"
    },
    {
      "x": -37,
      "y": 39,
      "z": -5,
      "name": "Rock_Stone"
    },
    {
      "x": -37,
      "y": 40,
      "z": -5,
      "name": "Rock_Stone"
    },
    {
      "x": -37,
      "y": 26,
      "z": -4,
      "name": "Rock_Stone"
    },
    {
      "x": -37,
      "y": 27,
      "z": -4,
      "name": "Rock_Stone"
    },
    {
      "x": -37,
      "y": 28,
      "z": -4,
      "name": "Rock_Stone"
    },
    {
      "x": -37,
      "y": 29,
      "z": -4,
      "name": "Rock_Stone"
    },
    {
      "x": -37,
      "y": 30,
      "z": -4,
      "name": "Rock_Stone"
    },
    {
      "x": -37,
      "y": 37,
      "z": -4,
      "name": "Rock_Stone"
    },
    {
      "x": -37,
      "y": 38,
      "z": -4,
      "name": "Rock_Stone"
    },
    {
      "x": -37,
      "y": 39,
      "z": -4,
      "name": "Rock_Stone"
    },
    {
      "x": -37,
      "y": 40,
      "z": -4,
      "name": "Rock_Stone"
    },
    {
      "x": -37,
      "y": 26,
      "z": -3,
      "name": "Rock_Stone"
    },
    {
      "x": -37,
      "y": 27,
      "z": -3,
      "name": "Rock_Stone"
    },
    {
      "x": -37,
      "y": 28,
      "z": -3,
      "name": "Rock_Stone"
    },
    {
      "x": -37,
      "y": 29,
      "z": -3,
      "name": "Rock_Stone"
    },
    {
      "x": -37,
      "y": 30,
      "z": -3,
      "name": "Rock_Stone"
    },
    {
      "x": -37,
      "y": 37,
      "z": -3,
      "name": "Rock_Stone"
    },
    {
      "x": -37,
      "y": 38,
      "z": -3,
      "name": "Rock_Stone"
    },
    {
      "x": -37,
      "y": 39,
      "z": -3,
      "name": "Rock_Stone"
    },
    {
      "x": -37,
      "y": 40,
      "z": -3,
      "name": "Rock_Stone"
    },
    {
      "x": -37,
      "y": 27,
      "z": -2,
      "name": "Rock_Stone"
    },
    {
      "x": -37,
      "y": 28,
      "z": -2,
      "name": "Rock_Stone"
    },
    {
      "x": -37,
      "y": 29,
      "z": -2,
      "name": "Rock_Stone"
    },
    {
      "x": -37,
      "y": 30,
      "z": -2,
      "name": "Rock_Stone"
    },
    {
      "x": -37,
      "y": 31,
      "z": -2,
      "name": "Rock_Stone"
    },
    {
      "x": -37,
      "y": 36,
      "z": -2,
      "name": "Rock_Stone"
    },
    {
      "x": -37,
      "y": 37,
      "z": -2,
      "name": "Rock_Stone"
    },
    {
      "x": -37,
      "y": 38,
      "z": -2,
      "name": "Rock_Stone"
    },
    {
      "x": -37,
      "y": 39,
      "z": -2,
      "name": "Rock_Stone"
    },
    {
      "x": -37,
      "y": 40,
      "z": -2,
      "name": "Rock_Stone"
    },
    {
      "x": -37,
      "y": 31,
      "z": -1,
      "name": "Rock_Stone"
    },
    {
      "x": -37,
      "y": 32,
      "z": -1,
      "name": "Rock_Stone"
    },
    {
      "x": -37,
      "y": 35,
      "z": -1,
      "name": "Rock_Stone"
    },
    {
      "x": -37,
      "y": 36,
      "z": -1,
      "name": "Rock_Stone"
    },
    {
      "x": -37,
      "y": 31,
      "z": 0,
      "name": "Rock_Stone"
    },
    {
      "x": -37,
      "y": 32,
      "z": 0,
      "name": "Rock_Stone"
    },
    {
      "x": -37,
      "y": 35,
      "z": 0,
      "name": "Rock_Stone"
    },
    {
      "x": -37,
      "y": 36,
      "z": 0,
      "name": "Rock_Stone"
    },
    {
      "x": -37,
      "y": 32,
      "z": 1,
      "name": "Rock_Stone"
    },
    {
      "x": -37,
      "y": 33,
      "z": 1,
      "name": "Rock_Stone"
    },
    {
      "x": -37,
      "y": 34,
      "z": 1,
      "name": "Rock_Stone"
    },
    {
      "x": -37,
      "y": 35,
      "z": 1,
      "name": "Rock_Stone"
    },
    {
      "x": -37,
      "y": 32,
      "z": 2,
      "name": "Rock_Stone"
    },
    {
      "x": -37,
      "y": 33,
      "z": 2,
      "name": "Rock_Stone"
    },
    {
      "x": -37,
      "y": 34,
      "z": 2,
      "name": "Rock_Stone"
    },
    {
      "x": -37,
      "y": 35,
      "z": 2,
      "name": "Rock_Stone"
    },
    {
      "x": -37,
      "y": 33,
      "z": 3,
      "name": "Rock_Stone"
    },
    {
      "x": -37,
      "y": 34,
      "z": 3,
      "name": "Rock_Stone"
    },
    {
      "x": -37,
      "y": 35,
      "z": 3,
      "name": "Rock_Stone"
    },
    {
      "x": -37,
      "y": 33,
      "z": 4,
      "name": "Rock_Stone"
    },
    {
      "x": -37,
      "y": 34,
      "z": 4,
      "name": "Rock_Stone"
    },
    {
      "x": -36,
      "y": 33,
      "z": -11,
      "name": "Rock_Stone"
    },
    {
      "x": -36,
      "y": 34,
      "z": -11,
      "name": "Rock_Stone"
    },
    {
      "x": -36,
      "y": 32,
      "z": -10,
      "name": "Rock_Stone"
    },
    {
      "x": -36,
      "y": 33,
      "z": -10,
      "name": "Rock_Stone"
    },
    {
      "x": -36,
      "y": 34,
      "z": -10,
      "name": "Rock_Stone"
    },
    {
      "x": -36,
      "y": 35,
      "z": -10,
      "name": "Rock_Stone"
    },
    {
      "x": -36,
      "y": 32,
      "z": -9,
      "name": "Rock_Stone"
    },
    {
      "x": -36,
      "y": 33,
      "z": -9,
      "name": "Rock_Stone"
    },
    {
      "x": -36,
      "y": 34,
      "z": -9,
      "name": "Rock_Stone"
    },
    {
      "x": -36,
      "y": 35,
      "z": -9,
      "name": "Rock_Stone"
    },
    {
      "x": -36,
      "y": 31,
      "z": -8,
      "name": "Rock_Stone"
    },
    {
      "x": -36,
      "y": 32,
      "z": -8,
      "name": "Rock_Stone"
    },
    {
      "x": -36,
      "y": 35,
      "z": -8,
      "name": "Rock_Stone"
    },
    {
      "x": -36,
      "y": 36,
      "z": -8,
      "name": "Rock_Stone"
    },
    {
      "x": -36,
      "y": 31,
      "z": -7,
      "name": "Rock_Stone"
    },
    {
      "x": -36,
      "y": 32,
      "z": -7,
      "name": "Rock_Stone"
    },
    {
      "x": -36,
      "y": 35,
      "z": -7,
      "name": "Rock_Stone"
    },
    {
      "x": -36,
      "y": 36,
      "z": -7,
      "name": "Rock_Stone"
    },
    {
      "x": -36,
      "y": 30,
      "z": -6,
      "name": "Rock_Stone"
    },
    {
      "x": -36,
      "y": 31,
      "z": -6,
      "name": "Rock_Stone"
    },
    {
      "x": -36,
      "y": 35,
      "z": -6,
      "name": "Rock_Stone"
    },
    {
      "x": -36,
      "y": 36,
      "z": -6,
      "name": "Rock_Stone"
    },
    {
      "x": -36,
      "y": 26,
      "z": -5,
      "name": "Rock_Stone"
    },
    {
      "x": -36,
      "y": 27,
      "z": -5,
      "name": "Rock_Stone"
    },
    {
      "x": -36,
      "y": 28,
      "z": -5,
      "name": "Rock_Stone"
    },
    {
      "x": -36,
      "y": 29,
      "z": -5,
      "name": "Rock_Stone"
    },
    {
      "x": -36,
      "y": 30,
      "z": -5,
      "name": "Rock_Stone"
    },
    {
      "x": -36,
      "y": 31,
      "z": -5,
      "name": "Rock_Stone"
    },
    {
      "x": -36,
      "y": 36,
      "z": -5,
      "name": "Rock_Stone"
    },
    {
      "x": -36,
      "y": 37,
      "z": -5,
      "name": "Rock_Stone"
    },
    {
      "x": -36,
      "y": 38,
      "z": -5,
      "name": "Rock_Stone"
    },
    {
      "x": -36,
      "y": 39,
      "z": -5,
      "name": "Rock_Stone"
    },
    {
      "x": -36,
      "y": 40,
      "z": -5,
      "name": "Rock_Stone"
    },
    {
      "x": -36,
      "y": 25,
      "z": -4,
      "name": "Rock_Stone"
    },
    {
      "x": -36,
      "y": 26,
      "z": -4,
      "name": "Rock_Stone"
    },
    {
      "x": -36,
      "y": 27,
      "z": -4,
      "name": "Rock_Stone"
    },
    {
      "x": -36,
      "y": 28,
      "z": -4,
      "name": "Rock_Stone"
    },
    {
      "x": -36,
      "y": 29,
      "z": -4,
      "name": "Rock_Stone"
    },
    {
      "x": -36,
      "y": 30,
      "z": -4,
      "name": "Rock_Stone"
    },
    {
      "x": -36,
      "y": 37,
      "z": -4,
      "name": "Rock_Stone"
    },
    {
      "x": -36,
      "y": 38,
      "z": -4,
      "name": "Rock_Stone"
    },
    {
      "x": -36,
      "y": 39,
      "z": -4,
      "name": "Rock_Stone"
    },
    {
      "x": -36,
      "y": 40,
      "z": -4,
      "name": "Rock_Stone"
    },
    {
      "x": -36,
      "y": 41,
      "z": -4,
      "name": "Rock_Stone"
    },
    {
      "x": -36,
      "y": 25,
      "z": -3,
      "name": "Rock_Stone"
    },
    {
      "x": -36,
      "y": 26,
      "z": -3,
      "name": "Rock_Stone"
    },
    {
      "x": -36,
      "y": 27,
      "z": -3,
      "name": "Rock_Stone"
    },
    {
      "x": -36,
      "y": 28,
      "z": -3,
      "name": "Rock_Stone"
    },
    {
      "x": -36,
      "y": 29,
      "z": -3,
      "name": "Rock_Stone"
    },
    {
      "x": -36,
      "y": 30,
      "z": -3,
      "name": "Rock_Stone"
    },
    {
      "x": -36,
      "y": 37,
      "z": -3,
      "name": "Rock_Stone"
    },
    {
      "x": -36,
      "y": 38,
      "z": -3,
      "name": "Rock_Stone"
    },
    {
      "x": -36,
      "y": 39,
      "z": -3,
      "name": "Rock_Stone"
    },
    {
      "x": -36,
      "y": 40,
      "z": -3,
      "name": "Rock_Stone"
    },
    {
      "x": -36,
      "y": 41,
      "z": -3,
      "name": "Rock_Stone"
    },
    {
      "x": -36,
      "y": 26,
      "z": -2,
      "name": "Rock_Stone"
    },
    {
      "x": -36,
      "y": 27,
      "z": -2,
      "name": "Rock_Stone"
    },
    {
      "x": -36,
      "y": 28,
      "z": -2,
      "name": "Rock_Stone"
    },
    {
      "x": -36,
      "y": 29,
      "z": -2,
      "name": "Rock_Stone"
    },
    {
      "x": -36,
      "y": 30,
      "z": -2,
      "name": "Rock_Stone"
    },
    {
      "x": -36,
      "y": 31,
      "z": -2,
      "name": "Rock_Stone"
    },
    {
      "x": -36,
      "y": 36,
      "z": -2,
      "name": "Rock_Stone"
    },
    {
      "x": -36,
      "y": 37,
      "z": -2,
      "name": "Rock_Stone"
    },
    {
      "x": -36,
      "y": 38,
      "z": -2,
      "name": "Rock_Stone"
    },
    {
      "x": -36,
      "y": 39,
      "z": -2,
      "name": "Rock_Stone"
    },
    {
      "x": -36,
      "y": 40,
      "z": -2,
      "name": "Rock_Stone"
    },
    {
      "x": -36,
      "y": 30,
      "z": -1,
      "name": "Rock_Stone"
    },
    {
      "x": -36,
      "y": 31,
      "z": -1,
      "name": "Rock_Stone"
    },
    {
      "x": -36,
      "y": 35,
      "z": -1,
      "name": "Rock_Stone"
    },
    {
      "x": -36,
      "y": 36,
      "z": -1,
      "name": "Rock_Stone"
    },
    {
      "x": -36,
      "y": 31,
      "z": 0,
      "name": "Rock_Stone"
    },
    {
      "x": -36,
      "y": 32,
      "z": 0,
      "name": "Rock_Stone"
    },
    {
      "x": -36,
      "y": 35,
      "z": 0,
      "name": "Rock_Stone"
    },
    {
      "x": -36,
      "y": 36,
      "z": 0,
      "name": "Rock_Stone"
    },
    {
      "x": -36,
      "y": 31,
      "z": 1,
      "name": "Rock_Stone"
    },
    {
      "x": -36,
      "y": 32,
      "z": 1,
      "name": "Rock_Stone"
    },
    {
      "x": -36,
      "y": 35,
      "z": 1,
      "name": "Rock_Stone"
    },
    {
      "x": -36,
      "y": 32,
      "z": 2,
      "name": "Rock_Stone"
    },
    {
      "x": -36,
      "y": 33,
      "z": 2,
      "name": "Rock_Stone"
    },
    {
      "x": -36,
      "y": 34,
      "z": 2,
      "name": "Rock_Stone"
    },
    {
      "x": -36,
      "y": 35,
      "z": 2,
      "name": "Rock_Stone"
    },
    {
      "x": -36,
      "y": 32,
      "z": 3,
      "name": "Rock_Stone"
    },
    {
      "x": -36,
      "y": 33,
      "z": 3,
      "name": "Rock_Stone"
    },
    {
      "x": -36,
      "y": 34,
      "z": 3,
      "name": "Rock_Stone"
    },
    {
      "x": -36,
      "y": 35,
      "z": 3,
      "name": "Rock_Stone"
    },
    {
      "x": -36,
      "y": 33,
      "z": 4,
      "name": "Rock_Stone"
    },
    {
      "x": -36,
      "y": 34,
      "z": 4,
      "name": "Rock_Stone"
    },
    {
      "x": -35,
      "y": 33,
      "z": -12,
      "name": "Rock_Stone"
    },
    {
      "x": -35,
      "y": 34,
      "z": -12,
      "name": "Rock_Stone"
    },
    {
      "x": -35,
      "y": 33,
      "z": -11,
      "name": "Rock_Stone"
    },
    {
      "x": -35,
      "y": 34,
      "z": -11,
      "name": "Rock_Stone"
    },
    {
      "x": -35,
      "y": 32,
      "z": -10,
      "name": "Rock_Stone"
    },
    {
      "x": -35,
      "y": 33,
      "z": -10,
      "name": "Rock_Stone"
    },
    {
      "x": -35,
      "y": 34,
      "z": -10,
      "name": "Rock_Stone"
    },
    {
      "x": -35,
      "y": 35,
      "z": -10,
      "name": "Rock_Stone"
    },
    {
      "x": -35,
      "y": 32,
      "z": -9,
      "name": "Rock_Stone"
    },
    {
      "x": -35,
      "y": 33,
      "z": -9,
      "name": "Rock_Stone"
    },
    {
      "x": -35,
      "y": 34,
      "z": -9,
      "name": "Rock_Stone"
    },
    {
      "x": -35,
      "y": 35,
      "z": -9,
      "name": "Rock_Stone"
    },
    {
      "x": -35,
      "y": 31,
      "z": -8,
      "name": "Rock_Stone"
    },
    {
      "x": -35,
      "y": 32,
      "z": -8,
      "name": "Rock_Stone"
    },
    {
      "x": -35,
      "y": 35,
      "z": -8,
      "name": "Rock_Stone"
    },
    {
      "x": -35,
      "y": 36,
      "z": -8,
      "name": "Rock_Stone"
    },
    {
      "x": -35,
      "y": 31,
      "z": -7,
      "name": "Rock_Stone"
    },
    {
      "x": -35,
      "y": 32,
      "z": -7,
      "name": "Rock_Stone"
    },
    {
      "x": -35,
      "y": 35,
      "z": -7,
      "name": "Rock_Stone"
    },
    {
      "x": -35,
      "y": 36,
      "z": -7,
      "name": "Rock_Stone"
    },
    {
      "x": -35,
      "y": 30,
      "z": -6,
      "name": "Rock_Stone"
    },
    {
      "x": -35,
      "y": 31,
      "z": -6,
      "name": "Rock_Stone"
    },
    {
      "x": -35,
      "y": 36,
      "z": -6,
      "name": "Rock_Stone"
    },
    {
      "x": -35,
      "y": 25,
      "z": -5,
      "name": "Rock_Stone"
    },
    {
      "x": -35,
      "y": 26,
      "z": -5,
      "name": "Rock_Stone"
    },
    {
      "x": -35,
      "y": 27,
      "z": -5,
      "name": "Rock_Stone"
    },
    {
      "x": -35,
      "y": 28,
      "z": -5,
      "name": "Rock_Stone"
    },
    {
      "x": -35,
      "y": 29,
      "z": -5,
      "name": "Rock_Stone"
    },
    {
      "x": -35,
      "y": 30,
      "z": -5,
      "name": "Rock_Stone"
    },
    {
      "x": -35,
      "y": 31,
      "z": -5,
      "name": "Rock_Stone"
    },
    {
      "x": -35,
      "y": 36,
      "z": -5,
      "name": "Rock_Stone"
    },
    {
      "x": -35,
      "y": 37,
      "z": -5,
      "name": "Rock_Stone"
    },
    {
      "x": -35,
      "y": 38,
      "z": -5,
      "name": "Rock_Stone"
    },
    {
      "x": -35,
      "y": 39,
      "z": -5,
      "name": "Rock_Stone"
    },
    {
      "x": -35,
      "y": 40,
      "z": -5,
      "name": "Rock_Stone"
    },
    {
      "x": -35,
      "y": 41,
      "z": -5,
      "name": "Rock_Stone"
    },
    {
      "x": -35,
      "y": 24,
      "z": -4,
      "name": "Rock_Stone"
    },
    {
      "x": -35,
      "y": 25,
      "z": -4,
      "name": "Rock_Stone"
    },
    {
      "x": -35,
      "y": 26,
      "z": -4,
      "name": "Rock_Stone"
    },
    {
      "x": -35,
      "y": 27,
      "z": -4,
      "name": "Rock_Stone"
    },
    {
      "x": -35,
      "y": 28,
      "z": -4,
      "name": "Rock_Stone"
    },
    {
      "x": -35,
      "y": 29,
      "z": -4,
      "name": "Rock_Stone"
    },
    {
      "x": -35,
      "y": 30,
      "z": -4,
      "name": "Rock_Stone"
    },
    {
      "x": -35,
      "y": 37,
      "z": -4,
      "name": "Rock_Stone"
    },
    {
      "x": -35,
      "y": 38,
      "z": -4,
      "name": "Rock_Stone"
    },
    {
      "x": -35,
      "y": 39,
      "z": -4,
      "name": "Rock_Stone"
    },
    {
      "x": -35,
      "y": 40,
      "z": -4,
      "name": "Rock_Stone"
    },
    {
      "x": -35,
      "y": 41,
      "z": -4,
      "name": "Rock_Stone"
    },
    {
      "x": -35,
      "y": 24,
      "z": -3,
      "name": "Rock_Stone"
    },
    {
      "x": -35,
      "y": 25,
      "z": -3,
      "name": "Rock_Stone"
    },
    {
      "x": -35,
      "y": 26,
      "z": -3,
      "name": "Rock_Stone"
    },
    {
      "x": -35,
      "y": 27,
      "z": -3,
      "name": "Rock_Stone"
    },
    {
      "x": -35,
      "y": 28,
      "z": -3,
      "name": "Rock_Stone"
    },
    {
      "x": -35,
      "y": 29,
      "z": -3,
      "name": "Rock_Stone"
    },
    {
      "x": -35,
      "y": 30,
      "z": -3,
      "name": "Rock_Stone"
    },
    {
      "x": -35,
      "y": 37,
      "z": -3,
      "name": "Rock_Stone"
    },
    {
      "x": -35,
      "y": 38,
      "z": -3,
      "name": "Rock_Stone"
    },
    {
      "x": -35,
      "y": 39,
      "z": -3,
      "name": "Rock_Stone"
    },
    {
      "x": -35,
      "y": 40,
      "z": -3,
      "name": "Rock_Stone"
    },
    {
      "x": -35,
      "y": 41,
      "z": -3,
      "name": "Rock_Stone"
    },
    {
      "x": -35,
      "y": 25,
      "z": -2,
      "name": "Rock_Stone"
    },
    {
      "x": -35,
      "y": 26,
      "z": -2,
      "name": "Rock_Stone"
    },
    {
      "x": -35,
      "y": 27,
      "z": -2,
      "name": "Rock_Stone"
    },
    {
      "x": -35,
      "y": 28,
      "z": -2,
      "name": "Rock_Stone"
    },
    {
      "x": -35,
      "y": 29,
      "z": -2,
      "name": "Rock_Stone"
    },
    {
      "x": -35,
      "y": 30,
      "z": -2,
      "name": "Rock_Stone"
    },
    {
      "x": -35,
      "y": 31,
      "z": -2,
      "name": "Rock_Stone"
    },
    {
      "x": -35,
      "y": 36,
      "z": -2,
      "name": "Rock_Stone"
    },
    {
      "x": -35,
      "y": 37,
      "z": -2,
      "name": "Rock_Stone"
    },
    {
      "x": -35,
      "y": 38,
      "z": -2,
      "name": "Rock_Stone"
    },
    {
      "x": -35,
      "y": 39,
      "z": -2,
      "name": "Rock_Stone"
    },
    {
      "x": -35,
      "y": 40,
      "z": -2,
      "name": "Rock_Stone"
    },
    {
      "x": -35,
      "y": 30,
      "z": -1,
      "name": "Rock_Stone"
    },
    {
      "x": -35,
      "y": 31,
      "z": -1,
      "name": "Rock_Stone"
    },
    {
      "x": -35,
      "y": 36,
      "z": -1,
      "name": "Rock_Stone"
    },
    {
      "x": -35,
      "y": 31,
      "z": 0,
      "name": "Rock_Stone"
    },
    {
      "x": -35,
      "y": 32,
      "z": 0,
      "name": "Rock_Stone"
    },
    {
      "x": -35,
      "y": 35,
      "z": 0,
      "name": "Rock_Stone"
    },
    {
      "x": -35,
      "y": 36,
      "z": 0,
      "name": "Rock_Stone"
    },
    {
      "x": -35,
      "y": 31,
      "z": 1,
      "name": "Rock_Stone"
    },
    {
      "x": -35,
      "y": 32,
      "z": 1,
      "name": "Rock_Stone"
    },
    {
      "x": -35,
      "y": 35,
      "z": 1,
      "name": "Rock_Stone"
    },
    {
      "x": -35,
      "y": 36,
      "z": 1,
      "name": "Rock_Stone"
    },
    {
      "x": -35,
      "y": 32,
      "z": 2,
      "name": "Rock_Stone"
    },
    {
      "x": -35,
      "y": 33,
      "z": 2,
      "name": "Rock_Stone"
    },
    {
      "x": -35,
      "y": 34,
      "z": 2,
      "name": "Rock_Stone"
    },
    {
      "x": -35,
      "y": 35,
      "z": 2,
      "name": "Rock_Stone"
    },
    {
      "x": -35,
      "y": 32,
      "z": 3,
      "name": "Rock_Stone"
    },
    {
      "x": -35,
      "y": 33,
      "z": 3,
      "name": "Rock_Stone"
    },
    {
      "x": -35,
      "y": 34,
      "z": 3,
      "name": "Rock_Stone"
    },
    {
      "x": -35,
      "y": 35,
      "z": 3,
      "name": "Rock_Stone"
    },
    {
      "x": -35,
      "y": 33,
      "z": 4,
      "name": "Rock_Stone"
    },
    {
      "x": -35,
      "y": 34,
      "z": 4,
      "name": "Rock_Stone"
    },
    {
      "x": -35,
      "y": 33,
      "z": 5,
      "name": "Rock_Stone"
    },
    {
      "x": -35,
      "y": 34,
      "z": 5,
      "name": "Rock_Stone"
    },
    {
      "x": -34,
      "y": 33,
      "z": -12,
      "name": "Rock_Stone"
    },
    {
      "x": -34,
      "y": 34,
      "z": -12,
      "name": "Rock_Stone"
    },
    {
      "x": -34,
      "y": 32,
      "z": -11,
      "name": "Rock_Stone"
    },
    {
      "x": -34,
      "y": 33,
      "z": -11,
      "name": "Rock_Stone"
    },
    {
      "x": -34,
      "y": 34,
      "z": -11,
      "name": "Rock_Stone"
    },
    {
      "x": -34,
      "y": 32,
      "z": -10,
      "name": "Rock_Stone"
    },
    {
      "x": -34,
      "y": 33,
      "z": -10,
      "name": "Rock_Stone"
    },
    {
      "x": -34,
      "y": 34,
      "z": -10,
      "name": "Rock_Stone"
    },
    {
      "x": -34,
      "y": 35,
      "z": -10,
      "name": "Rock_Stone"
    },
    {
      "x": -34,
      "y": 31,
      "z": -9,
      "name": "Rock_Stone"
    },
    {
      "x": -34,
      "y": 32,
      "z": -9,
      "name": "Rock_Stone"
    },
    {
      "x": -34,
      "y": 34,
      "z": -9,
      "name": "Rock_Stone"
    },
    {
      "x": -34,
      "y": 35,
      "z": -9,
      "name": "Rock_Stone"
    },
    {
      "x": -34,
      "y": 31,
      "z": -8,
      "name": "Rock_Stone"
    },
    {
      "x": -34,
      "y": 32,
      "z": -8,
      "name": "Rock_Stone"
    },
    {
      "x": -34,
      "y": 35,
      "z": -8,
      "name": "Rock_Stone"
    },
    {
      "x": -34,
      "y": 36,
      "z": -8,
      "name": "Rock_Stone"
    },
    {
      "x": -34,
      "y": 31,
      "z": -7,
      "name": "Rock_Stone"
    },
    {
      "x": -34,
      "y": 35,
      "z": -7,
      "name": "Rock_Stone"
    },
    {
      "x": -34,
      "y": 36,
      "z": -7,
      "name": "Rock_Stone"
    },
    {
      "x": -34,
      "y": 30,
      "z": -6,
      "name": "Rock_Stone"
    },
    {
      "x": -34,
      "y": 31,
      "z": -6,
      "name": "Rock_Stone"
    },
    {
      "x": -34,
      "y": 36,
      "z": -6,
      "name": "Rock_Stone"
    },
    {
      "x": -34,
      "y": 37,
      "z": -6,
      "name": "Rock_Stone"
    },
    {
      "x": -34,
      "y": 24,
      "z": -5,
      "name": "Rock_Stone"
    },
    {
      "x": -34,
      "y": 25,
      "z": -5,
      "name": "Rock_Stone"
    },
    {
      "x": -34,
      "y": 26,
      "z": -5,
      "name": "Rock_Stone"
    },
    {
      "x": -34,
      "y": 27,
      "z": -5,
      "name": "Rock_Stone"
    },
    {
      "x": -34,
      "y": 28,
      "z": -5,
      "name": "Rock_Stone"
    },
    {
      "x": -34,
      "y": 29,
      "z": -5,
      "name": "Rock_Stone"
    },
    {
      "x": -34,
      "y": 30,
      "z": -5,
      "name": "Rock_Stone"
    },
    {
      "x": -34,
      "y": 31,
      "z": -5,
      "name": "Rock_Stone"
    },
    {
      "x": -34,
      "y": 36,
      "z": -5,
      "name": "Rock_Stone"
    },
    {
      "x": -34,
      "y": 37,
      "z": -5,
      "name": "Rock_Stone"
    },
    {
      "x": -34,
      "y": 38,
      "z": -5,
      "name": "Rock_Stone"
    },
    {
      "x": -34,
      "y": 39,
      "z": -5,
      "name": "Rock_Stone"
    },
    {
      "x": -34,
      "y": 40,
      "z": -5,
      "name": "Rock_Stone"
    },
    {
      "x": -34,
      "y": 41,
      "z": -5,
      "name": "Rock_Stone"
    },
    {
      "x": -34,
      "y": 23,
      "z": -4,
      "name": "Rock_Stone"
    },
    {
      "x": -34,
      "y": 24,
      "z": -4,
      "name": "Rock_Stone"
    },
    {
      "x": -34,
      "y": 25,
      "z": -4,
      "name": "Rock_Stone"
    },
    {
      "x": -34,
      "y": 26,
      "z": -4,
      "name": "Rock_Stone"
    },
    {
      "x": -34,
      "y": 27,
      "z": -4,
      "name": "Rock_Stone"
    },
    {
      "x": -34,
      "y": 28,
      "z": -4,
      "name": "Rock_Stone"
    },
    {
      "x": -34,
      "y": 29,
      "z": -4,
      "name": "Rock_Stone"
    },
    {
      "x": -34,
      "y": 30,
      "z": -4,
      "name": "Rock_Stone"
    },
    {
      "x": -34,
      "y": 37,
      "z": -4,
      "name": "Rock_Stone"
    },
    {
      "x": -34,
      "y": 38,
      "z": -4,
      "name": "Rock_Stone"
    },
    {
      "x": -34,
      "y": 39,
      "z": -4,
      "name": "Rock_Stone"
    },
    {
      "x": -34,
      "y": 40,
      "z": -4,
      "name": "Rock_Stone"
    },
    {
      "x": -34,
      "y": 41,
      "z": -4,
      "name": "Rock_Stone"
    },
    {
      "x": -34,
      "y": 42,
      "z": -4,
      "name": "Rock_Stone"
    },
    {
      "x": -34,
      "y": 23,
      "z": -3,
      "name": "Rock_Stone"
    },
    {
      "x": -34,
      "y": 24,
      "z": -3,
      "name": "Rock_Stone"
    },
    {
      "x": -34,
      "y": 25,
      "z": -3,
      "name": "Rock_Stone"
    },
    {
      "x": -34,
      "y": 26,
      "z": -3,
      "name": "Rock_Stone"
    },
    {
      "x": -34,
      "y": 27,
      "z": -3,
      "name": "Rock_Stone"
    },
    {
      "x": -34,
      "y": 28,
      "z": -3,
      "name": "Rock_Stone"
    },
    {
      "x": -34,
      "y": 29,
      "z": -3,
      "name": "Rock_Stone"
    },
    {
      "x": -34,
      "y": 30,
      "z": -3,
      "name": "Rock_Stone"
    },
    {
      "x": -34,
      "y": 37,
      "z": -3,
      "name": "Rock_Stone"
    },
    {
      "x": -34,
      "y": 38,
      "z": -3,
      "name": "Rock_Stone"
    },
    {
      "x": -34,
      "y": 39,
      "z": -3,
      "name": "Rock_Stone"
    },
    {
      "x": -34,
      "y": 40,
      "z": -3,
      "name": "Rock_Stone"
    },
    {
      "x": -34,
      "y": 41,
      "z": -3,
      "name": "Rock_Stone"
    },
    {
      "x": -34,
      "y": 42,
      "z": -3,
      "name": "Rock_Stone"
    },
    {
      "x": -34,
      "y": 25,
      "z": -2,
      "name": "Rock_Stone"
    },
    {
      "x": -34,
      "y": 26,
      "z": -2,
      "name": "Rock_Stone"
    },
    {
      "x": -34,
      "y": 27,
      "z": -2,
      "name": "Rock_Stone"
    },
    {
      "x": -34,
      "y": 28,
      "z": -2,
      "name": "Rock_Stone"
    },
    {
      "x": -34,
      "y": 29,
      "z": -2,
      "name": "Rock_Stone"
    },
    {
      "x": -34,
      "y": 30,
      "z": -2,
      "name": "Rock_Stone"
    },
    {
      "x": -34,
      "y": 31,
      "z": -2,
      "name": "Rock_Stone"
    },
    {
      "x": -34,
      "y": 36,
      "z": -2,
      "name": "Rock_Stone"
    },
    {
      "x": -34,
      "y": 37,
      "z": -2,
      "name": "Rock_Stone"
    },
    {
      "x": -34,
      "y": 38,
      "z": -2,
      "name": "Rock_Stone"
    },
    {
      "x": -34,
      "y": 39,
      "z": -2,
      "name": "Rock_Stone"
    },
    {
      "x": -34,
      "y": 40,
      "z": -2,
      "name": "Rock_Stone"
    },
    {
      "x": -34,
      "y": 41,
      "z": -2,
      "name": "Rock_Stone"
    },
    {
      "x": -34,
      "y": 30,
      "z": -1,
      "name": "Rock_Stone"
    },
    {
      "x": -34,
      "y": 31,
      "z": -1,
      "name": "Rock_Stone"
    },
    {
      "x": -34,
      "y": 36,
      "z": -1,
      "name": "Rock_Stone"
    },
    {
      "x": -34,
      "y": 37,
      "z": -1,
      "name": "Rock_Stone"
    },
    {
      "x": -34,
      "y": 31,
      "z": 0,
      "name": "Rock_Stone"
    },
    {
      "x": -34,
      "y": 32,
      "z": 0,
      "name": "Rock_Stone"
    },
    {
      "x": -34,
      "y": 35,
      "z": 0,
      "name": "Rock_Stone"
    },
    {
      "x": -34,
      "y": 36,
      "z": 0,
      "name": "Rock_Stone"
    },
    {
      "x": -34,
      "y": 31,
      "z": 1,
      "name": "Rock_Stone"
    },
    {
      "x": -34,
      "y": 32,
      "z": 1,
      "name": "Rock_Stone"
    },
    {
      "x": -34,
      "y": 35,
      "z": 1,
      "name": "Rock_Stone"
    },
    {
      "x": -34,
      "y": 36,
      "z": 1,
      "name": "Rock_Stone"
    },
    {
      "x": -34,
      "y": 32,
      "z": 2,
      "name": "Rock_Stone"
    },
    {
      "x": -34,
      "y": 34,
      "z": 2,
      "name": "Rock_Stone"
    },
    {
      "x": -34,
      "y": 35,
      "z": 2,
      "name": "Rock_Stone"
    },
    {
      "x": -34,
      "y": 32,
      "z": 3,
      "name": "Rock_Stone"
    },
    {
      "x": -34,
      "y": 33,
      "z": 3,
      "name": "Rock_Stone"
    },
    {
      "x": -34,
      "y": 34,
      "z": 3,
      "name": "Rock_Stone"
    },
    {
      "x": -34,
      "y": 35,
      "z": 3,
      "name": "Rock_Stone"
    },
    {
      "x": -34,
      "y": 32,
      "z": 4,
      "name": "Rock_Stone"
    },
    {
      "x": -34,
      "y": 33,
      "z": 4,
      "name": "Rock_Stone"
    },
    {
      "x": -34,
      "y": 34,
      "z": 4,
      "name": "Rock_Stone"
    },
    {
      "x": -34,
      "y": 33,
      "z": 5,
      "name": "Rock_Stone"
    },
    {
      "x": -34,
      "y": 34,
      "z": 5,
      "name": "Rock_Stone"
    },
    {
      "x": -33,
      "y": 33,
      "z": -12,
      "name": "Rock_Stone"
    },
    {
      "x": -33,
      "y": 34,
      "z": -12,
      "name": "Rock_Stone"
    },
    {
      "x": -33,
      "y": 32,
      "z": -11,
      "name": "Rock_Stone"
    },
    {
      "x": -33,
      "y": 33,
      "z": -11,
      "name": "Rock_Stone"
    },
    {
      "x": -33,
      "y": 34,
      "z": -11,
      "name": "Rock_Stone"
    },
    {
      "x": -33,
      "y": 35,
      "z": -11,
      "name": "Rock_Stone"
    },
    {
      "x": -33,
      "y": 32,
      "z": -10,
      "name": "Rock_Stone"
    },
    {
      "x": -33,
      "y": 33,
      "z": -10,
      "name": "Rock_Stone"
    },
    {
      "x": -33,
      "y": 34,
      "z": -10,
      "name": "Rock_Stone"
    },
    {
      "x": -33,
      "y": 35,
      "z": -10,
      "name": "Rock_Stone"
    },
    {
      "x": -33,
      "y": 31,
      "z": -9,
      "name": "Rock_Stone"
    },
    {
      "x": -33,
      "y": 32,
      "z": -9,
      "name": "Rock_Stone"
    },
    {
      "x": -33,
      "y": 34,
      "z": -9,
      "name": "Rock_Stone"
    },
    {
      "x": -33,
      "y": 35,
      "z": -9,
      "name": "Rock_Stone"
    },
    {
      "x": -33,
      "y": 31,
      "z": -8,
      "name": "Rock_Stone"
    },
    {
      "x": -33,
      "y": 32,
      "z": -8,
      "name": "Rock_Stone"
    },
    {
      "x": -33,
      "y": 35,
      "z": -8,
      "name": "Rock_Stone"
    },
    {
      "x": -33,
      "y": 36,
      "z": -8,
      "name": "Rock_Stone"
    },
    {
      "x": -33,
      "y": 30,
      "z": -7,
      "name": "Rock_Stone"
    },
    {
      "x": -33,
      "y": 31,
      "z": -7,
      "name": "Rock_Stone"
    },
    {
      "x": -33,
      "y": 35,
      "z": -7,
      "name": "Rock_Stone"
    },
    {
      "x": -33,
      "y": 36,
      "z": -7,
      "name": "Rock_Stone"
    },
    {
      "x": -33,
      "y": 30,
      "z": -6,
      "name": "Rock_Stone"
    },
    {
      "x": -33,
      "y": 31,
      "z": -6,
      "name": "Rock_Stone"
    },
    {
      "x": -33,
      "y": 36,
      "z": -6,
      "name": "Rock_Stone"
    },
    {
      "x": -33,
      "y": 37,
      "z": -6,
      "name": "Rock_Stone"
    },
    {
      "x": -33,
      "y": 24,
      "z": -5,
      "name": "Rock_Stone"
    },
    {
      "x": -33,
      "y": 25,
      "z": -5,
      "name": "Rock_Stone"
    },
    {
      "x": -33,
      "y": 26,
      "z": -5,
      "name": "Rock_Stone"
    },
    {
      "x": -33,
      "y": 27,
      "z": -5,
      "name": "Rock_Stone"
    },
    {
      "x": -33,
      "y": 28,
      "z": -5,
      "name": "Rock_Stone"
    },
    {
      "x": -33,
      "y": 29,
      "z": -5,
      "name": "Rock_Stone"
    },
    {
      "x": -33,
      "y": 30,
      "z": -5,
      "name": "Rock_Stone"
    },
    {
      "x": -33,
      "y": 36,
      "z": -5,
      "name": "Rock_Stone"
    },
    {
      "x": -33,
      "y": 37,
      "z": -5,
      "name": "Rock_Stone"
    },
    {
      "x": -33,
      "y": 38,
      "z": -5,
      "name": "Rock_Stone"
    },
    {
      "x": -33,
      "y": 39,
      "z": -5,
      "name": "Rock_Stone"
    },
    {
      "x": -33,
      "y": 40,
      "z": -5,
      "name": "Rock_Stone"
    },
    {
      "x": -33,
      "y": 41,
      "z": -5,
      "name": "Rock_Stone"
    },
    {
      "x": -33,
      "y": 22,
      "z": -4,
      "name": "Rock_Stone"
    },
    {
      "x": -33,
      "y": 23,
      "z": -4,
      "name": "Rock_Stone"
    },
    {
      "x": -33,
      "y": 24,
      "z": -4,
      "name": "Rock_Stone"
    },
    {
      "x": -33,
      "y": 25,
      "z": -4,
      "name": "Rock_Stone"
    },
    {
      "x": -33,
      "y": 26,
      "z": -4,
      "name": "Rock_Stone"
    },
    {
      "x": -33,
      "y": 27,
      "z": -4,
      "name": "Rock_Stone"
    },
    {
      "x": -33,
      "y": 28,
      "z": -4,
      "name": "Rock_Stone"
    },
    {
      "x": -33,
      "y": 29,
      "z": -4,
      "name": "Rock_Stone"
    },
    {
      "x": -33,
      "y": 30,
      "z": -4,
      "name": "Rock_Stone"
    },
    {
      "x": -33,
      "y": 37,
      "z": -4,
      "name": "Rock_Stone"
    },
    {
      "x": -33,
      "y": 38,
      "z": -4,
      "name": "Rock_Stone"
    },
    {
      "x": -33,
      "y": 39,
      "z": -4,
      "name": "Rock_Stone"
    },
    {
      "x": -33,
      "y": 40,
      "z": -4,
      "name": "Rock_Stone"
    },
    {
