{
  "version": 8,
  "blockIdVersion": 11,
  "anchorX": 0,
  "anchorY": 0,
  "anchorZ": 0,
  "blocks": [
    {
      "x": -15,
      "y": 0,
      "z": -15,
      "name": "Rock_Volcanic"
    },
    {
      "x": -15,
      "y": 1,
      "z": -15,
      "name": "Rock_Volcanic_Cobble"
    },
    {
      "x": -15,
      "y": 2,
      "z": -15,
      "name": "Rock_Volcanic_Cobble"
    },
    {
      "x": -15,
      "y": 3,
      "z": -15,
      "name": "Rock_Volcanic_Brick_Smooth"
    },
    {
      "x": -15,
      "y": 4,
      "z": -15,
      "name": "Rock_Volcanic_Brick_Ornate"
    },
    {
      "x": -15,
      "y": 5,
      "z": -15,
      "name": "Rock_Volcanic_Brick_Decorative"
    },
    {
      "x": -15,
      "y": 6,
      "z": -15,
      "name": "Rock_Volcanic_Brick_Decorative"
    },
    {
      "x": -15,
      "y": 7,
      "z": -15,
      "name": "Rock_Volcanic_Brick_Decorative"
    },
    {
      "x": -15,
      "y": 8,
      "z": -15,
      "name": "Rock_Volcanic_Brick_Ornate"
    },
    {
      "x": -15,
      "y": 9,
      "z": -15,
      "name": "Rock_Volcanic_Brick"
    },
    {
      "x": -15,
      "y": 10,
      "z": -15,
      "name": "Rock_Volcanic_Brick"
    },
    {
      "x": -15,
      "y": 11,
      "z": -15,
      "name": "Rock_Volcanic_Brick"
    },
    {
      "x": -15,
      "y": 12,
      "z": -15,
      "name": "Rock_Volcanic_Brick_Smooth"
    },
    {
      "x": -15,
      "y": 13,
      "z": -15,
      "name": "Rock_Volcanic_Brick"
    },
    {
      "x": -15,
      "y": 14,
      "z": -15,
      "name": "Rock_Volcanic_Brick"
    },
    {
      "x": -15,
      "y": 15,
      "z": -15,
      "name": "Rock_Volcanic_Brick_Ornate"
    },
    {
      "x": -15,
      "y": 16,
      "z": -15,
      "name": "Rock_Volcanic_Brick_Decorative"
    },
    {
      "x": -15,
      "y": 17,
      "z": -15,
      "name": "Rock_Volcanic_Brick_Decorative"
    },
    {
      "x": -15,
      "y": 18,
      "z": -15,
      "name": "Rock_Volcanic_Brick_Decorative"
    },
    {
      "x": -15,
      "y": 19,
      "z": -15,
      "name": "Rock_Volcanic_Brick_Ornate"
    },
    {
      "x": -15,
      "y": 20,
      "z": -15,
      "name": "Rock_Volcanic_Brick"
    },
    {
      "x": -15,
      "y": 21,
      "z": -15,
      "name": "Rock_Volcanic_Brick_Smooth"
    },
    {
      "x": -15,
      "y": 111,
      "z": -15,
      "name": "Rock_Sandstone_Brick_Ornate"
    },
    {
      "x": -15,
      "y": 112,
      "z": -15,
      "name": "Rock_Sandstone_Brick"
    },
    {
      "x": -15,
      "y": 113,
      "z": -15,
      "name": "Rock_Sandstone_Brick_Smooth"
    },
    {
      "x": -15,
      "y": 114,
      "z": -15,
      "name": "Rock_Sandstone_Brick"
    },
    {
      "x": -15,
      "y": 115,
      "z": -15,
      "name": "Rock_Sandstone_Brick_Ornate"
    },
    {
      "x": -15,
      "y": 116,
      "z": -15,
      "name": "Rock_Sandstone_Brick_Decorative"
    },
    {
      "x": -15,
      "y": 117,
      "z": -15,
      "name": "Rock_Sandstone_Brick_Decorative"
    },
    {
      "x": -15,
      "y": 118,
      "z": -15,
      "name": "Rock_Sandstone_Brick_Decorative"
    },
    {
      "x": -15,
      "y": 119,
      "z": -15,
      "name": "Rock_Sandstone_Brick_Ornate"
    },
    {
      "x": -15,
      "y": 120,
      "z": -15,
      "name": "Rock_Sandstone_Brick"
    },
    {
      "x": -15,
      "y": 121,
      "z": -15,
      "name": "Rock_Sandstone_Brick_Smooth"
    },
    {
      "x": -15,
      "y": 122,
      "z": -15,
      "name": "Rock_Sandstone_Brick"
    },
    {
      "x": -15,
      "y": 123,
      "z": -15,
      "name": "Rock_Sandstone_Brick_Ornate"
    },
    {
      "x": -15,
      "y": 124,
      "z": -15,
      "name": "Rock_Sandstone_Brick_Decorative"
    },
    {
      "x": -15,
      "y": 125,
      "z": -15,
      "name": "Rock_Sandstone_Brick_Decorative"
    },
    {
      "x": -15,
      "y": 126,
      "z": -15,
      "name": "Rock_Sandstone_Brick_Decorative"
    },
    {
      "x": -15,
      "y": 127,
      "z": -15,
      "name": "Rock_Sandstone_Brick_Ornate"
    },
    {
      "x": -15,
      "y": 128,
      "z": -15,
      "name": "Rock_Sandstone_Brick"
    },
    {
      "x": -15,
      "y": 129,
      "z": -15,
      "name": "Rock_Sandstone_Brick_Smooth"
    },
    {
      "x": -15,
      "y": 130,
      "z": -15,
      "name": "Rock_Sandstone"
    },
    {
      "x": -15,
      "y": 0,
      "z": -14,
      "name": "Rock_Volcanic"
    },
    {
      "x": -15,
      "y": 1,
      "z": -14,
      "name": "Rock_Volcanic_Cobble"
    },
    {
      "x": -15,
      "y": 2,
      "z": -14,
      "name": "Rock_Volcanic_Cobble"
    },
    {
      "x": -15,
      "y": 3,
      "z": -14,
      "name": "Rock_Volcanic_Brick_Smooth"
    },
    {
      "x": -15,
      "y": 4,
      "z": -14,
      "name": "Rock_Volcanic_Brick_Ornate"
    },
    {
      "x": -15,
      "y": 5,
      "z": -14,
      "name": "Rock_Volcanic_Brick_Decorative"
    },
    {
      "x": -15,
      "y": 6,
      "z": -14,
      "name": "Rock_Volcanic_Brick_Decorative"
    },
    {
      "x": -15,
      "y": 7,
      "z": -14,
      "name": "Rock_Volcanic_Brick_Decorative"
    },
    {
      "x": -15,
      "y": 8,
      "z": -14,
      "name": "Rock_Volcanic_Brick_Ornate"
    },
    {
      "x": -15,
      "y": 9,
      "z": -14,
      "name": "Rock_Volcanic_Brick"
    },
    {
      "x": -15,
      "y": 10,
      "z": -14,
      "name": "Rock_Volcanic_Brick"
    },
    {
      "x": -15,
      "y": 11,
      "z": -14,
      "name": "Rock_Volcanic_Brick"
    },
    {
      "x": -15,
      "y": 12,
      "z": -14,
      "name": "Rock_Volcanic_Brick_Smooth"
    },
    {
      "x": -15,
      "y": 13,
      "z": -14,
      "name": "Rock_Volcanic_Brick"
    },
    {
      "x": -15,
      "y": 14,
      "z": -14,
      "name": "Rock_Volcanic_Brick"
    },
    {
      "x": -15,
      "y": 15,
      "z": -14,
      "name": "Rock_Volcanic_Brick_Ornate"
    },
    {
      "x": -15,
      "y": 16,
      "z": -14,
      "name": "Rock_Volcanic_Brick_Decorative"
    },
    {
      "x": -15,
      "y": 17,
      "z": -14,
      "name": "Rock_Volcanic_Brick_Decorative"
    },
    {
      "x": -15,
      "y": 18,
      "z": -14,
      "name": "Rock_Volcanic_Brick_Decorative"
    },
    {
      "x": -15,
      "y": 19,
      "z": -14,
      "name": "Rock_Volcanic_Brick_Ornate"
    },
    {
      "x": -15,
      "y": 20,
      "z": -14,
      "name": "Rock_Volcanic_Brick"
    },
    {
      "x": -15,
      "y": 21,
      "z": -14,
      "name": "Rock_Volcanic_Brick_Smooth"
    },
    {
      "x": -15,
      "y": 111,
      "z": -14,
      "name": "Rock_Sandstone_Brick_Ornate"
    },
    {
      "x": -15,
      "y": 112,
      "z": -14,
      "name": "Rock_Sandstone_Brick"
    },
    {
      "x": -15,
      "y": 113,
      "z": -14,
      "name": "Rock_Sandstone_Brick_Smooth"
    },
    {
      "x": -15,
      "y": 114,
      "z": -14,
      "name": "Rock_Sandstone_Brick"
    },
    {
      "x": -15,
      "y": 115,
      "z": -14,
      "name": "Rock_Sandstone_Brick_Ornate"
    },
    {
      "x": -15,
      "y": 116,
      "z": -14,
      "name": "Rock_Sandstone_Brick_Decorative"
    },
    {
      "x": -15,
      "y": 117,
      "z": -14,
      "name": "Rock_Sandstone_Brick_Decorative"
    },
    {
      "x": -15,
      "y": 118,
      "z": -14,
      "name": "Rock_Sandstone_Brick_Decorative"
    },
    {
      "x": -15,
      "y": 119,
      "z": -14,
      "name": "Rock_Sandstone_Brick_Ornate"
    },
    {
      "x": -15,
      "y": 120,
      "z": -14,
      "name": "Rock_Sandstone_Brick"
    },
    {
      "x": -15,
      "y": 121,
      "z": -14,
      "name": "Rock_Sandstone_Brick_Smooth"
    },
    {
      "x": -15,
      "y": 122,
      "z": -14,
      "name": "Rock_Sandstone_Brick"
    },
    {
      "x": -15,
      "y": 123,
      "z": -14,
      "name": "Rock_Sandstone_Brick_Ornate"
    },
    {
      "x": -15,
      "y": 124,
      "z": -14,
      "name": "Rock_Sandstone_Brick_Decorative"
    },
    {
      "x": -15,
      "y": 125,
      "z": -14,
      "name": "Rock_Sandstone_Brick_Decorative"
    },
    {
      "x": -15,
      "y": 126,
      "z": -14,
      "name": "Rock_Sandstone_Brick_Decorative"
    },
    {
      "x": -15,
      "y": 127,
      "z": -14,
      "name": "Rock_Sandstone_Brick_Ornate"
    },
    {
      "x": -15,
      "y": 128,
      "z": -14,
      "name": "Rock_Sandstone_Brick"
    },
    {
      "x": -15,
      "y": 129,
      "z": -14,
      "name": "Rock_Sandstone_Brick_Smooth"
    },
    {
      "x": -15,
      "y": 130,
      "z": -14,
      "name": "Rock_Sandstone"
    },
    {
      "x": -15,
      "y": 0,
      "z": -13,
      "name": "Rock_Volcanic"
    },
    {
      "x": -15,
      "y": 1,
      "z": -13,
      "name": "Rock_Volcanic_Cobble"
    },
    {
      "x": -15,
      "y": 2,
      "z": -13,
      "name": "Rock_Volcanic_Cobble"
    },
    {
      "x": -15,
      "y": 12,
      "z": -13,
      "name": "Rock_Volcanic_Brick_Smooth"
    },
    {
      "x": -15,
      "y": 113,
      "z": -13,
      "name": "Rock_Sandstone_Brick_Smooth"
    },
    {
      "x": -15,
      "y": 121,
      "z": -13,
      "name": "Rock_Sandstone_Brick_Smooth"
    },
    {
      "x": -15,
      "y": 129,
      "z": -13,
      "name": "Rock_Sandstone_Brick_Smooth"
    },
    {
      "x": -15,
      "y": 130,
      "z": -13,
      "name": "Rock_Sandstone"
    },
    {
      "x": -15,
      "y": 0,
      "z": -12,
      "name": "Rock_Volcanic"
    },
    {
      "x": -15,
      "y": 1,
      "z": -12,
      "name": "Rock_Volcanic_Cobble"
    },
    {
      "x": -15,
      "y": 2,
      "z": -12,
      "name": "Rock_Volcanic_Cobble"
    },
    {
      "x": -15,
      "y": 12,
      "z": -12,
      "name": "Rock_Volcanic_Brick_Smooth"
    },
    {
      "x": -15,
      "y": 113,
      "z": -12,
      "name": "Rock_Sandstone_Brick_Smooth"
    },
    {
      "x": -15,
      "y": 121,
      "z": -12,
      "name": "Rock_Sandstone_Brick_Smooth"
    },
    {
      "x": -15,
      "y": 129,
      "z": -12,
      "name": "Rock_Sandstone_Brick_Smooth"
    },
    {
      "x": -15,
      "y": 130,
      "z": -12,
      "name": "Rock_Sandstone"
    },
    {
      "x": -15,
      "y": 0,
      "z": -11,
      "name": "Rock_Volcanic"
    },
    {
      "x": -15,
      "y": 1,
      "z": -11,
      "name": "Rock_Volcanic_Cobble"
    },
    {
      "x": -15,
      "y": 2,
      "z": -11,
      "name": "Rock_Volcanic_Cobble"
    },
    {
      "x": -15,
      "y": 12,
      "z": -11,
      "name": "Rock_Volcanic_Brick_Smooth"
    },
    {
      "x": -15,
      "y": 113,
      "z": -11,
      "name": "Rock_Sandstone_Brick_Smooth"
    },
    {
      "x": -15,
      "y": 121,
      "z": -11,
      "name": "Rock_Sandstone_Brick_Smooth"
    },
    {
      "x": -15,
      "y": 129,
      "z": -11,
      "name": "Rock_Sandstone_Brick_Smooth"
    },
    {
      "x": -15,
      "y": 130,
      "z": -11,
      "name": "Rock_Sandstone"
    },
    {
      "x": -15,
      "y": 0,
      "z": -10,
      "name": "Rock_Volcanic_Cracked_Lava"
    },
    {
      "x": -15,
      "y": 1,
      "z": -10,
      "name": "Rock_Volcanic_Cobble"
    },
    {
      "x": -15,
      "y": 2,
      "z": -10,
      "name": "Rock_Volcanic_Cobble"
    },
    {
      "x": -15,
      "y": 12,
      "z": -10,
      "name": "Rock_Volcanic_Brick_Smooth"
    },
    {
      "x": -15,
      "y": 113,
      "z": -10,
      "name": "Rock_Sandstone_Brick_Smooth"
    },
    {
      "x": -15,
      "y": 121,
      "z": -10,
      "name": "Rock_Sandstone_Brick_Smooth"
    },
    {
      "x": -15,
      "y": 129,
      "z": -10,
      "name": "Rock_Sandstone_Brick_Smooth"
    },
    {
      "x": -15,
      "y": 130,
      "z": -10,
      "name": "Rock_Sandstone"
    },
    {
      "x": -15,
      "y": 0,
      "z": -9,
      "name": "Rock_Volcanic"
    },
    {
      "x": -15,
      "y": 1,
      "z": -9,
      "name": "Rock_Volcanic_Cobble"
    },
    {
      "x": -15,
      "y": 2,
      "z": -9,
      "name": "Rock_Volcanic_Cobble"
    },
    {
      "x": -15,
      "y": 12,
      "z": -9,
      "name": "Rock_Volcanic_Brick_Smooth"
    },
    {
      "x": -15,
      "y": 113,
      "z": -9,
      "name": "Rock_Sandstone_Brick_Smooth"
    },
    {
      "x": -15,
      "y": 121,
      "z": -9,
      "name": "Rock_Sandstone_Brick_Smooth"
    },
    {
      "x": -15,
      "y": 129,
      "z": -9,
      "name": "Rock_Sandstone_Brick_Smooth"
    },
    {
      "x": -15,
      "y": 130,
      "z": -9,
      "name": "Rock_Sandstone"
    },
    {
      "x": -15,
      "y": 0,
      "z": -8,
      "name": "Rock_Volcanic"
    },
    {
      "x": -15,
      "y": 1,
      "z": -8,
      "name": "Rock_Volcanic_Cobble"
    },
    {
      "x": -15,
      "y": 2,
      "z": -8,
      "name": "Rock_Volcanic_Cobble"
    },
    {
      "x": -15,
      "y": 12,
      "z": -8,
      "name": "Rock_Volcanic_Brick_Smooth"
    },
    {
      "x": -15,
      "y": 113,
      "z": -8,
      "name": "Rock_Sandstone_Brick_Smooth"
    },
    {
      "x": -15,
      "y": 121,
      "z": -8,
      "name": "Rock_Sandstone_Brick_Smooth"
    },
    {
      "x": -15,
      "y": 129,
      "z": -8,
      "name": "Rock_Sandstone_Brick_Smooth"
    },
    {
      "x": -15,
      "y": 130,
      "z": -8,
      "name": "Rock_Sandstone"
    },
    {
      "x": -15,
      "y": 0,
      "z": -7,
      "name": "Rock_Volcanic_Cracked_Lava"
    },
    {
      "x": -15,
      "y": 1,
      "z": -7,
      "name": "Rock_Volcanic_Cobble"
    },
    {
      "x": -15,
      "y": 2,
      "z": -7,
      "name": "Rock_Volcanic_Cobble"
    },
    {
      "x": -15,
      "y": 12,
      "z": -7,
      "name": "Rock_Volcanic_Brick_Smooth"
    },
    {
      "x": -15,
      "y": 113,
      "z": -7,
      "name": "Rock_Sandstone_Brick_Smooth"
    },
    {
      "x": -15,
      "y": 121,
      "z": -7,
      "name": "Rock_Sandstone_Brick_Smooth"
    },
    {
      "x": -15,
      "y": 129,
      "z": -7,
      "name": "Rock_Sandstone_Brick_Smooth"
    },
    {
      "x": -15,
      "y": 130,
      "z": -7,
      "name": "Rock_Sandstone"
    },
    {
      "x": -15,
      "y": 0,
      "z": -6,
      "name": "Rock_Volcanic"
    },
    {
      "x": -15,
      "y": 1,
      "z": -6,
      "name": "Rock_Volcanic_Cobble"
    },
    {
      "x": -15,
      "y": 2,
      "z": -6,
      "name": "Rock_Volcanic_Cobble"
    },
    {
      "x": -15,
      "y": 12,
      "z": -6,
      "name": "Rock_Volcanic_Brick_Smooth"
    },
    {
      "x": -15,
      "y": 113,
      "z": -6,
      "name": "Rock_Sandstone_Brick_Smooth"
    },
    {
      "x": -15,
      "y": 121,
      "z": -6,
      "name": "Rock_Sandstone_Brick_Smooth"
    },
    {
      "x": -15,
      "y": 129,
      "z": -6,
      "name": "Rock_Sandstone_Brick_Smooth"
    },
    {
      "x": -15,
      "y": 130,
      "z": -6,
      "name": "Rock_Sandstone"
    },
    {
      "x": -15,
      "y": 0,
      "z": -5,
      "name": "Rock_Volcanic_Cracked_Lava"
    },
    {
      "x": -15,
      "y": 1,
      "z": -5,
      "name": "Rock_Volcanic_Cobble"
    },
    {
      "x": -15,
      "y": 2,
      "z": -5,
      "name": "Rock_Volcanic_Cobble"
    },
    {
      "x": -15,
      "y": 12,
      "z": -5,
      "name": "Rock_Volcanic_Brick_Smooth"
    },
    {
      "x": -15,
      "y": 113,
      "z": -5,
      "name": "Rock_Sandstone_Brick_Smooth"
    },
    {
      "x": -15,
      "y": 121,
      "z": -5,
      "name": "Rock_Sandstone_Brick_Smooth"
    },
    {
      "x": -15,
      "y": 129,
      "z": -5,
      "name": "Rock_Sandstone_Brick_Smooth"
    },
    {
      "x": -15,
      "y": 130,
      "z": -5,
      "name": "Rock_Sandstone"
    },
    {
      "x": -15,
      "y": 0,
      "z": -4,
      "name": "Rock_Volcanic"
    },
    {
      "x": -15,
      "y": 1,
      "z": -4,
      "name": "Rock_Volcanic_Cobble"
    },
    {
      "x": -15,
      "y": 2,
      "z": -4,
      "name": "Rock_Volcanic_Cobble"
    },
    {
      "x": -15,
      "y": 12,
      "z": -4,
      "name": "Rock_Volcanic_Brick_Smooth"
    },
    {
      "x": -15,
      "y": 113,
      "z": -4,
      "name": "Rock_Sandstone_Brick_Smooth"
    },
    {
      "x": -15,
      "y": 121,
      "z": -4,
      "name": "Rock_Sandstone_Brick_Smooth"
    },
    {
      "x": -15,
      "y": 129,
      "z": -4,
      "name": "Rock_Sandstone_Brick_Smooth"
    },
    {
      "x": -15,
      "y": 130,
      "z": -4,
      "name": "Rock_Sandstone"
    },
    {
      "x": -15,
      "y": 0,
      "z": -3,
      "name": "Rock_Volcanic"
    },
    {
      "x": -15,
      "y": 1,
      "z": -3,
      "name": "Rock_Volcanic_Cobble"
    },
    {
      "x": -15,
      "y": 2,
      "z": -3,
      "name": "Rock_Volcanic_Cobble"
    },
    {
      "x": -15,
      "y": 3,
      "z": -3,
      "name": "Rubble_Volcanic_Medium"
    },
    {
      "x": -15,
      "y": 12,
      "z": -3,
      "name": "Rock_Volcanic_Brick_Smooth"
    },
    {
      "x": -15,
      "y": 113,
      "z": -3,
      "name": "Rock_Sandstone_Brick_Smooth"
    },
    {
      "x": -15,
      "y": 121,
      "z": -3,
      "name": "Rock_Sandstone_Brick_Smooth"
    },
    {
      "x": -15,
      "y": 129,
      "z": -3,
      "name": "Rock_Sandstone_Brick_Smooth"
    },
    {
      "x": -15,
      "y": 130,
      "z": -3,
      "name": "Rock_Sandstone"
    },
    {
      "x": -15,
      "y": 0,
      "z": -2,
      "name": "Rock_Volcanic_Cracked_Lava"
    },
    {
      "x": -15,
      "y": 1,
      "z": -2,
      "name": "Rock_Volcanic_Cobble"
    },
    {
      "x": -15,
      "y": 2,
      "z": -2,
      "name": "Rock_Volcanic_Cobble"
    },
    {
      "x": -15,
      "y": 3,
      "z": -2,
      "name": "Rock_Volcanic"
    },
    {
      "x": -15,
      "y": 12,
      "z": -2,
      "name": "Rock_Volcanic_Brick_Smooth"
    },
    {
      "x": -15,
      "y": 113,
      "z": -2,
      "name": "Rock_Sandstone_Brick_Smooth"
    },
    {
      "x": -15,
      "y": 121,
      "z": -2,
      "name": "Rock_Sandstone_Brick_Smooth"
    },
    {
      "x": -15,
      "y": 129,
      "z": -2,
      "name": "Rock_Sandstone_Brick_Smooth"
    },
    {
      "x": -15,
      "y": 130,
      "z": -2,
      "name": "Rock_Sandstone"
    },
    {
      "x": -15,
      "y": 0,
      "z": -1,
      "name": "Rock_Volcanic"
    },
    {
      "x": -15,
      "y": 1,
      "z": -1,
      "name": "Rock_Volcanic_Cobble"
    },
    {
      "x": -15,
      "y": 2,
      "z": -1,
      "name": "Rock_Volcanic_Cobble"
    },
    {
      "x": -15,
      "y": 3,
      "z": -1,
      "name": "Rock_Volcanic"
    },
    {
      "x": -15,
      "y": 4,
      "z": -1,
      "name": "Rock_Volcanic"
    },
    {
      "x": -15,
      "y": 5,
      "z": -1,
      "name": "Rock_Volcanic"
    },
    {
      "x": -15,
      "y": 9,
      "z": -1,
      "name": "Deco_SpiderWeb_Flat",
      "rotation": 7
    },
    {
      "x": -15,
      "y": 12,
      "z": -1,
      "name": "Rock_Volcanic_Brick_Smooth"
    },
    {
      "x": -15,
      "y": 13,
      "z": -1,
      "name": "Rubble_Volcanic"
    },
    {
      "x": -15,
      "y": 113,
      "z": -1,
      "name": "Rock_Sandstone_Brick_Smooth"
    },
    {
      "x": -15,
      "y": 121,
      "z": -1,
      "name": "Rock_Sandstone_Brick_Smooth"
    },
    {
      "x": -15,
      "y": 129,
      "z": -1,
      "name": "Rock_Sandstone_Brick_Smooth"
    },
    {
      "x": -15,
      "y": 130,
      "z": -1,
      "name": "Rock_Sandstone"
    },
    {
      "x": -15,
      "y": 0,
      "z": 0,
      "name": "Rock_Volcanic"
    },
    {
      "x": -15,
      "y": 1,
      "z": 0,
      "name": "Rock_Volcanic_Cobble"
    },
    {
      "x": -15,
      "y": 2,
      "z": 0,
      "name": "Rock_Volcanic_Cobble"
    },
    {
      "x": -15,
      "y": 3,
      "z": 0,
      "name": "Rock_Volcanic"
    },
    {
      "x": -15,
      "y": 4,
      "z": 0,
      "name": "Rock_Volcanic"
    },
    {
      "x": -15,
      "y": 5,
      "z": 0,
      "name": "Rock_Volcanic"
    },
    {
      "x": -15,
      "y": 6,
      "z": 0,
      "name": "Rock_Volcanic"
    },
    {
      "x": -15,
      "y": 7,
      "z": 0,
      "name": "Rubble_Volcanic"
    },
    {
      "x": -15,
      "y": 12,
      "z": 0,
      "name": "Rock_Volcanic_Brick_Smooth"
    },
    {
      "x": -15,
      "y": 113,
      "z": 0,
      "name": "Rock_Sandstone_Brick_Smooth"
    },
    {
      "x": -15,
      "y": 121,
      "z": 0,
      "name": "Rock_Sandstone_Brick_Smooth"
    },
    {
      "x": -15,
      "y": 129,
      "z": 0,
      "name": "Rock_Sandstone_Brick_Smooth"
    },
    {
      "x": -15,
      "y": 130,
      "z": 0,
      "name": "Rock_Sandstone"
    },
    {
      "x": -15,
      "y": 0,
      "z": 1,
      "name": "Rock_Volcanic"
    },
    {
      "x": -15,
      "y": 1,
      "z": 1,
      "name": "Rock_Volcanic_Cobble"
    },
    {
      "x": -15,
      "y": 2,
      "z": 1,
      "name": "Rock_Volcanic_Cobble"
    },
    {
      "x": -15,
      "y": 3,
      "z": 1,
      "name": "Rock_Volcanic"
    },
    {
      "x": -15,
      "y": 4,
      "z": 1,
      "name": "Rock_Volcanic"
    },
    {
      "x": -15,
      "y": 5,
      "z": 1,
      "name": "Rock_Volcanic"
    },
    {
      "x": -15,
      "y": 6,
      "z": 1,
      "name": "Rubble_Volcanic"
    },
    {
      "x": -15,
      "y": 8,
      "z": 1,
      "name": "Deco_SpiderWeb_Flat",
      "rotation": 7
    },
    {
      "x": -15,
      "y": 12,
      "z": 1,
      "name": "Rock_Volcanic_Brick_Smooth"
    },
    {
      "x": -15,
      "y": 113,
      "z": 1,
      "name": "Rock_Sandstone_Brick_Smooth"
    },
    {
      "x": -15,
      "y": 121,
      "z": 1,
      "name": "Rock_Sandstone_Brick_Smooth"
    },
    {
      "x": -15,
      "y": 129,
      "z": 1,
      "name": "Rock_Sandstone_Brick_Smooth"
    },
    {
      "x": -15,
      "y": 130,
      "z": 1,
      "name": "Rock_Sandstone"
    },
    {
      "x": -15,
      "y": 0,
      "z": 2,
      "name": "Rock_Volcanic_Cracked_Lava"
    },
    {
      "x": -15,
      "y": 1,
      "z": 2,
      "name": "Rock_Volcanic_Cobble"
    },
    {
      "x": -15,
      "y": 2,
      "z": 2,
      "name": "Rock_Volcanic_Cobble"
    },
    {
      "x": -15,
      "y": 3,
      "z": 2,
      "name": "Rock_Volcanic_Cracked_Poisoned"
    },
    {
      "x": -15,
      "y": 7,
      "z": 2,
      "name": "Deco_SpiderWeb_Flat",
      "rotation": 7
    },
    {
      "x": -15,
      "y": 12,
      "z": 2,
      "name": "Rock_Volcanic_Brick_Smooth"
    },
    {
      "x": -15,
      "y": 113,
      "z": 2,
      "name": "Rock_Sandstone_Brick_Smooth"
    },
    {
      "x": -15,
      "y": 121,
      "z": 2,
      "name": "Rock_Sandstone_Brick_Smooth"
    },
    {
      "x": -15,
      "y": 129,
      "z": 2,
      "name": "Rock_Sandstone_Brick_Smooth"
    },
    {
      "x": -15,
      "y": 130,
      "z": 2,
      "name": "Rock_Sandstone"
    },
    {
      "x": -15,
      "y": 0,
      "z": 3,
      "name": "Rock_Volcanic_Cracked_Lava"
    },
    {
      "x": -15,
      "y": 1,
      "z": 3,
      "name": "Rock_Volcanic_Cobble"
    },
    {
      "x": -15,
      "y": 2,
      "z": 3,
      "name": "Rock_Volcanic_Cobble"
    },
    {
      "x": -15,
      "y": 3,
      "z": 3,
      "name": "Rubble_Volcanic_Medium"
    },
    {
      "x": -15,
      "y": 12,
      "z": 3,
      "name": "Rock_Volcanic_Brick_Smooth"
    },
    {
      "x": -15,
      "y": 113,
      "z": 3,
      "name": "Rock_Sandstone_Brick_Smooth"
    },
    {
      "x": -15,
      "y": 121,
      "z": 3,
      "name": "Rock_Sandstone_Brick_Smooth"
    },
    {
      "x": -15,
      "y": 129,
      "z": 3,
      "name": "Rock_Sandstone_Brick_Smooth"
    },
    {
      "x": -15,
      "y": 130,
      "z": 3,
      "name": "Rock_Sandstone"
    },
    {
      "x": -15,
      "y": 0,
      "z": 4,
      "name": "Rock_Volcanic"
    },
    {
      "x": -15,
      "y": 1,
      "z": 4,
      "name": "Rock_Volcanic_Cobble"
    },
    {
      "x": -15,
      "y": 2,
      "z": 4,
      "name": "Rock_Volcanic_Cobble"
    },
    {
      "x": -15,
      "y": 12,
      "z": 4,
      "name": "Rock_Volcanic_Brick_Smooth"
    },
    {
      "x": -15,
      "y": 113,
      "z": 4,
      "name": "Rock_Sandstone_Brick_Smooth"
    },
    {
      "x": -15,
      "y": 121,
      "z": 4,
      "name": "Rock_Sandstone_Brick_Smooth"
    },
    {
      "x": -15,
      "y": 129,
      "z": 4,
      "name": "Rock_Sandstone_Brick_Smooth"
    },
    {
      "x": -15,
      "y": 130,
      "z": 4,
      "name": "Rock_Sandstone"
    },
    {
      "x": -15,
      "y": 0,
      "z": 5,
      "name": "Rock_Volcanic"
    },
    {
      "x": -15,
      "y": 1,
      "z": 5,
      "name": "Rock_Volcanic_Cobble"
    },
    {
      "x": -15,
      "y": 2,
      "z": 5,
      "name": "Rock_Volcanic_Cobble"
    },
    {
      "x": -15,
      "y": 12,
      "z": 5,
      "name": "Rock_Volcanic_Brick_Smooth"
    },
    {
      "x": -15,
      "y": 113,
      "z": 5,
      "name": "Rock_Sandstone_Brick_Smooth"
    },
    {
      "x": -15,
      "y": 121,
      "z": 5,
      "name": "Rock_Sandstone_Brick_Smooth"
    },
    {
      "x": -15,
      "y": 129,
      "z": 5,
      "name": "Rock_Sandstone_Brick_Smooth"
    },
    {
      "x": -15,
      "y": 130,
      "z": 5,
      "name": "Rock_Sandstone"
    },
    {
      "x": -15,
      "y": 0,
      "z": 6,
      "name": "Rock_Volcanic"
    },
    {
      "x": -15,
      "y": 1,
      "z": 6,
      "name": "Rock_Volcanic_Cobble"
    },
    {
      "x": -15,
      "y": 2,
      "z": 6,
      "name": "Rock_Volcanic_Cobble"
    },
    {
      "x": -15,
      "y": 12,
      "z": 6,
      "name": "Rock_Volcanic_Brick_Smooth"
    },
    {
      "x": -15,
      "y": 113,
      "z": 6,
      "name": "Rock_Sandstone_Brick_Smooth"
    },
    {
      "x": -15,
      "y": 121,
      "z": 6,
      "name": "Rock_Sandstone_Brick_Smooth"
    },
    {
      "x": -15,
      "y": 129,
      "z": 6,
      "name": "Rock_Sandstone_Brick_Smooth"
    },
    {
      "x": -15,
      "y": 130,
      "z": 6,
      "name": "Rock_Sandstone"
    },
    {
      "x": -15,
      "y": 0,
      "z": 7,
      "name": "Rock_Volcanic"
    },
    {
      "x": -15,
      "y": 1,
      "z": 7,
      "name": "Rock_Volcanic_Cobble"
    },
    {
      "x": -15,
      "y": 2,
      "z": 7,
      "name": "Rock_Volcanic_Cobble"
    },
    {
      "x": -15,
      "y": 12,
      "z": 7,
      "name": "Rock_Volcanic_Brick_Smooth"
    },
    {
      "x": -15,
      "y": 113,
      "z": 7,
      "name": "Rock_Sandstone_Brick_Smooth"
    },
    {
      "x": -15,
      "y": 121,
      "z": 7,
      "name": "Rock_Sandstone_Brick_Smooth"
    },
    {
      "x": -15,
      "y": 129,
      "z": 7,
      "name": "Rock_Sandstone_Brick_Smooth"
    },
    {
      "x": -15,
      "y": 130,
      "z": 7,
      "name": "Rock_Sandstone"
    },
    {
      "x": -15,
      "y": 0,
      "z": 8,
      "name": "Rock_Volcanic"
    },
    {
      "x": -15,
      "y": 1,
      "z": 8,
      "name": "Rock_Volcanic_Cobble"
    },
    {
      "x": -15,
      "y": 2,
      "z": 8,
      "name": "Rock_Volcanic_Cobble"
    },
    {
      "x": -15,
      "y": 12,
      "z": 8,
      "name": "Rock_Volcanic_Brick_Smooth"
    },
    {
      "x": -15,
      "y": 113,
      "z": 8,
      "name": "Rock_Sandstone_Brick_Smooth"
    },
    {
      "x": -15,
      "y": 121,
      "z": 8,
      "name": "Rock_Sandstone_Brick_Smooth"
    },
    {
      "x": -15,
      "y": 129,
      "z": 8,
      "name": "Rock_Sandstone_Brick_Smooth"
    },
    {
      "x": -15,
      "y": 130,
      "z": 8,
      "name": "Rock_Sandstone"
    },
    {
      "x": -15,
      "y": 0,
      "z": 9,
      "name": "Rock_Volcanic_Cracked_Lava"
    },
    {
      "x": -15,
      "y": 1,
      "z": 9,
      "name": "Rock_Volcanic_Cobble"
    },
    {
      "x": -15,
      "y": 2,
      "z": 9,
      "name": "Rock_Volcanic_Cobble"
    },
    {
      "x": -15,
      "y": 3,
      "z": 9,
      "name": "Rock_Volcanic_Brick_Smooth"
    },
    {
      "x": -15,
      "y": 4,
      "z": 9,
      "name": "Rock_Volcanic_Brick_Ornate"
    },
    {
      "x": -15,
      "y": 5,
      "z": 9,
      "name": "Rock_Volcanic_Brick_Decorative"
    },
    {
      "x": -15,
      "y": 6,
      "z": 9,
      "name": "Rock_Volcanic_Brick_Decorative"
    },
    {
      "x": -15,
      "y": 7,
      "z": 9,
      "name": "Rock_Volcanic_Brick_Decorative"
    },
    {
      "x": -15,
      "y": 8,
      "z": 9,
      "name": "Rock_Volcanic_Brick_Ornate"
    },
    {
      "x": -15,
      "y": 9,
      "z": 9,
      "name": "Rock_Volcanic_Brick"
    },
    {
      "x": -15,
      "y": 10,
      "z": 9,
      "name": "Rock_Volcanic_Brick"
    },
    {
      "x": -15,
      "y": 11,
      "z": 9,
      "name": "Rock_Volcanic_Brick"
    },
    {
      "x": -15,
      "y": 12,
      "z": 9,
      "name": "Rock_Volcanic_Brick_Smooth"
    },
    {
      "x": -15,
      "y": 13,
      "z": 9,
      "name": "Rock_Volcanic_Brick"
    },
    {
      "x": -15,
      "y": 14,
      "z": 9,
      "name": "Rock_Volcanic_Brick"
    },
    {
      "x": -15,
      "y": 15,
      "z": 9,
      "name": "Rock_Volcanic_Brick_Ornate"
    },
    {
      "x": -15,
      "y": 16,
      "z": 9,
      "name": "Rock_Volcanic_Brick_Decorative"
    },
    {
      "x": -15,
      "y": 17,
      "z": 9,
      "name": "Rock_Volcanic_Brick_Decorative"
    },
    {
      "x": -15,
      "y": 18,
      "z": 9,
      "name": "Rock_Volcanic_Brick_Decorative"
    },
    {
      "x": -15,
      "y": 19,
      "z": 9,
      "name": "Rock_Volcanic_Brick_Ornate"
    },
    {
      "x": -15,
      "y": 20,
      "z": 9,
      "name": "Rock_Volcanic_Brick"
    },
    {
      "x": -15,
      "y": 21,
      "z": 9,
      "name": "Rock_Volcanic_Brick_Smooth"
    },
    {
      "x": -15,
      "y": 22,
      "z": 9,
      "name": "Plant_Crop_Mushroom_Glowing_Green"
    },
    {
      "x": -15,
      "y": 111,
      "z": 9,
      "name": "Rock_Sandstone_Brick_Ornate"
    },
    {
      "x": -15,
      "y": 112,
      "z": 9,
      "name": "Rock_Sandstone_Brick"
    },
    {
      "x": -15,
      "y": 113,
      "z": 9,
      "name": "Rock_Sandstone_Brick_Smooth"
    },
    {
      "x": -15,
      "y": 114,
      "z": 9,
      "name": "Rock_Sandstone_Brick"
    },
    {
      "x": -15,
      "y": 115,
      "z": 9,
      "name": "Rock_Sandstone_Brick_Ornate"
    },
    {
      "x": -15,
      "y": 116,
      "z": 9,
      "name": "Rock_Sandstone_Brick_Decorative"
    },
    {
      "x": -15,
      "y": 117,
      "z": 9,
      "name": "Rock_Sandstone_Brick_Decorative"
    },
    {
      "x": -15,
      "y": 118,
      "z": 9,
      "name": "Rock_Sandstone_Brick_Decorative"
    },
    {
      "x": -15,
      "y": 119,
      "z": 9,
      "name": "Rock_Sandstone_Brick_Ornate"
    },
    {
      "x": -15,
      "y": 120,
      "z": 9,
      "name": "Rock_Sandstone_Brick"
    },
    {
      "x": -15,
      "y": 121,
      "z": 9,
      "name": "Rock_Sandstone_Brick_Smooth"
    },
    {
      "x": -15,
      "y": 122,
      "z": 9,
      "name": "Rock_Sandstone_Brick"
    },
    {
      "x": -15,
      "y": 123,
      "z": 9,
      "name": "Rock_Sandstone_Brick_Ornate"
    },
    {
      "x": -15,
      "y": 124,
      "z": 9,
      "name": "Rock_Sandstone_Brick_Decorative"
    },
    {
      "x": -15,
      "y": 125,
      "z": 9,
      "name": "Rock_Sandstone_Brick_Decorative"
    },
    {
      "x": -15,
      "y": 126,
      "z": 9,
      "name": "Rock_Sandstone_Brick_Decorative"
    },
    {
      "x": -15,
      "y": 127,
      "z": 9,
      "name": "Rock_Sandstone_Brick_Ornate"
    },
    {
      "x": -15,
      "y": 128,
      "z": 9,
      "name": "Rock_Sandstone_Brick"
    },
    {
      "x": -15,
      "y": 129,
      "z": 9,
      "name": "Rock_Sandstone_Brick_Smooth"
    },
    {
      "x": -15,
      "y": 130,
      "z": 9,
      "name": "Rock_Sandstone"
    },
    {
      "x": -15,
      "y": 0,
      "z": 10,
      "name": "Rock_Volcanic"
    },
    {
      "x": -15,
      "y": 1,
      "z": 10,
      "name": "Rock_Volcanic_Cobble"
    },
    {
      "x": -15,
      "y": 2,
      "z": 10,
      "name": "Rock_Volcanic_Cobble"
    },
    {
      "x": -15,
      "y": 3,
      "z": 10,
      "name": "Rock_Volcanic_Brick_Smooth"
    },
    {
      "x": -15,
      "y": 4,
      "z": 10,
      "name": "Rock_Volcanic_Brick_Ornate"
    },
    {
      "x": -15,
      "y": 5,
      "z": 10,
      "name": "Rock_Volcanic_Brick_Decorative"
    },
    {
      "x": -15,
      "y": 6,
      "z": 10,
      "name": "Rock_Volcanic_Brick_Decorative"
    },
    {
      "x": -15,
      "y": 7,
      "z": 10,
      "name": "Rock_Volcanic_Brick_Decorative"
    },
    {
      "x": -15,
      "y": 8,
      "z": 10,
      "name": "Rock_Volcanic_Brick_Ornate"
    },
    {
      "x": -15,
      "y": 9,
      "z": 10,
      "name": "Rock_Volcanic_Brick"
    },
    {
      "x": -15,
      "y": 10,
      "z": 10,
      "name": "Rock_Volcanic_Brick"
    },
    {
      "x": -15,
      "y": 11,
      "z": 10,
      "name": "Rock_Volcanic_Brick"
    },
    {
      "x": -15,
      "y": 12,
      "z": 10,
      "name": "Rock_Volcanic_Brick_Smooth"
    },
    {
      "x": -15,
      "y": 13,
      "z": 10,
      "name": "Rock_Volcanic_Brick"
    },
    {
      "x": -15,
      "y": 14,
      "z": 10,
      "name": "Rock_Volcanic_Brick"
    },
    {
      "x": -15,
      "y": 15,
      "z": 10,
      "name": "Rock_Volcanic_Brick_Ornate"
    },
    {
      "x": -15,
      "y": 16,
      "z": 10,
      "name": "Rock_Volcanic_Brick_Decorative"
    },
    {
      "x": -15,
      "y": 17,
      "z": 10,
      "name": "Rock_Volcanic_Brick_Decorative"
    },
    {
      "x": -15,
      "y": 18,
      "z": 10,
      "name": "Rock_Volcanic_Brick_Decorative"
    },
    {
      "x": -15,
      "y": 19,
      "z": 10,
      "name": "Rock_Volcanic_Brick_Ornate"
    },
    {
      "x": -15,
      "y": 20,
      "z": 10,
      "name": "Rock_Volcanic_Brick"
    },
    {
      "x": -15,
      "y": 21,
      "z": 10,
      "name": "Rock_Volcanic_Brick_Smooth"
    },
    {
      "x": -15,
      "y": 111,
      "z": 10,
      "name": "Rock_Sandstone_Brick_Ornate"
    },
    {
      "x": -15,
      "y": 112,
      "z": 10,
      "name": "Rock_Sandstone_Brick"
    },
    {
      "x": -15,
      "y": 113,
      "z": 10,
      "name": "Rock_Sandstone_Brick_Smooth"
    },
    {
      "x": -15,
      "y": 114,
      "z": 10,
      "name": "Rock_Sandstone_Brick"
    },
    {
      "x": -15,
      "y": 115,
      "z": 10,
      "name": "Rock_Sandstone_Brick_Ornate"
    },
    {
      "x": -15,
      "y": 116,
      "z": 10,
      "name": "Rock_Sandstone_Brick_Decorative"
    },
    {
      "x": -15,
      "y": 117,
      "z": 10,
      "name": "Rock_Sandstone_Brick_Decorative"
    },
    {
      "x": -15,
      "y": 118,
      "z": 10,
      "name": "Rock_Sandstone_Brick_Decorative"
    },
    {
      "x": -15,
      "y": 119,
      "z": 10,
      "name": "Rock_Sandstone_Brick_Ornate"
    },
    {
      "x": -15,
      "y": 120,
      "z": 10,
      "name": "Rock_Sandstone_Brick"
    },
    {
      "x": -15,
      "y": 121,
      "z": 10,
      "name": "Rock_Sandstone_Brick_Smooth"
    },
    {
      "x": -15,
      "y": 122,
      "z": 10,
      "name": "Rock_Sandstone_Brick"
    },
    {
      "x": -15,
      "y": 123,
      "z": 10,
      "name": "Rock_Sandstone_Brick_Ornate"
    },
    {
      "x": -15,
      "y": 124,
      "z": 10,
      "name": "Rock_Sandstone_Brick_Decorative"
    },
    {
      "x": -15,
      "y": 125,
      "z": 10,
      "name": "Rock_Sandstone_Brick_Decorative"
    },
    {
      "x": -15,
      "y": 126,
      "z": 10,
      "name": "Rock_Sandstone_Brick_Decorative"
    },
    {
      "x": -15,
      "y": 127,
      "z": 10,
      "name": "Rock_Sandstone_Brick_Ornate"
    },
    {
      "x": -15,
      "y": 128,
      "z": 10,
      "name": "Rock_Sandstone_Brick"
    },
    {
      "x": -15,
      "y": 129,
      "z": 10,
      "name": "Rock_Sandstone_Brick_Smooth"
    },
    {
      "x": -15,
      "y": 130,
      "z": 10,
      "name": "Rock_Sandstone"
    },
    {
      "x": -15,
      "y": 0,
      "z": 11,
      "name": "Rock_Volcanic"
    },
    {
      "x": -15,
      "y": 1,
      "z": 11,
      "name": "Rock_Volcanic_Cobble"
    },
    {
      "x": -15,
      "y": 2,
      "z": 11,
      "name": "Rock_Volcanic_Cobble"
    },
    {
      "x": -15,
      "y": 12,
      "z": 11,
      "name": "Rock_Volcanic_Brick_Smooth"
    },
    {
      "x": -15,
      "y": 18,
      "z": 11,
      "name": "Deco_SpiderWeb_Flat",
      "rotation": 4
    },
    {
      "x": -15,
      "y": 113,
      "z": 11,
      "name": "Rock_Sandstone_Brick_Smooth"
    },
    {
      "x": -15,
      "y": 121,
      "z": 11,
      "name": "Rock_Sandstone_Brick_Smooth"
    },
    {
      "x": -15,
      "y": 129,
      "z": 11,
      "name": "Rock_Sandstone_Brick_Smooth"
    },
    {
      "x": -15,
      "y": 130,
      "z": 11,
      "name": "Rock_Sandstone"
    },
    {
      "x": -15,
      "y": 0,
      "z": 12,
      "name": "Rock_Volcanic_Cracked_Lava"
    },
    {
      "x": -15,
      "y": 1,
      "z": 12,
      "name": "Rock_Volcanic_Cobble"
    },
    {
      "x": -15,
      "y": 2,
      "z": 12,
      "name": "Rock_Volcanic_Cobble"
    },
    {
      "x": -15,
      "y": 12,
      "z": 12,
      "name": "Rock_Volcanic_Brick_Smooth"
    },
    {
      "x": -15,
      "y": 113,
      "z": 12,
      "name": "Rock_Sandstone_Brick_Smooth"
    },
    {
      "x": -15,
      "y": 121,
      "z": 12,
      "name": "Rock_Sandstone_Brick_Smooth"
    },
    {
      "x": -15,
      "y": 129,
      "z": 12,
      "name": "Rock_Sandstone_Brick_Smooth"
    },
    {
      "x": -15,
      "y": 130,
      "z": 12,
      "name": "Rock_Sandstone"
    },
    {
      "x": -15,
      "y": 0,
      "z": 13,
      "name": "Rock_Volcanic"
    },
    {
      "x": -15,
      "y": 1,
      "z": 13,
      "name": "Rock_Volcanic_Cobble"
    },
    {
      "x": -15,
      "y": 2,
      "z": 13,
      "name": "Rock_Volcanic_Cobble"
    },
    {
      "x": -15,
      "y": 12,
      "z": 13,
      "name": "Rock_Volcanic_Brick_Smooth"
    },
    {
      "x": -15,
      "y": 113,
      "z": 13,
      "name": "Rock_Sandstone_Brick_Smooth"
    },
    {
      "x": -15,
      "y": 121,
      "z": 13,
      "name": "Rock_Sandstone_Brick_Smooth"
    },
    {
      "x": -15,
      "y": 129,
      "z": 13,
      "name": "Rock_Sandstone_Brick_Smooth"
    },
    {
      "x": -15,
      "y": 130,
      "z": 13,
      "name": "Rock_Sandstone"
    },
    {
      "x": -15,
      "y": 0,
      "z": 14,
      "name": "Rock_Volcanic"
    },
    {
      "x": -15,
      "y": 1,
      "z": 14,
      "name": "Rock_Volcanic_Cobble"
    },
    {
      "x": -15,
      "y": 2,
      "z": 14,
      "name": "Rock_Volcanic_Cobble"
    },
    {
      "x": -15,
      "y": 12,
      "z": 14,
      "name": "Rock_Volcanic_Brick_Smooth"
    },
    {
      "x": -15,
      "y": 113,
      "z": 14,
      "name": "Rock_Sandstone_Brick_Smooth"
    },
    {
      "x": -15,
      "y": 121,
      "z": 14,
      "name": "Rock_Sandstone_Brick_Smooth"
    },
    {
      "x": -15,
      "y": 129,
      "z": 14,
      "name": "Rock_Sandstone_Brick_Smooth"
    },
    {
      "x": -15,
      "y": 130,
      "z": 14,
      "name": "Rock_Sandstone"
    },
    {
      "x": -15,
      "y": 0,
      "z": 15,
      "name": "Rock_Volcanic"
    },
    {
      "x": -15,
      "y": 1,
      "z": 15,
      "name": "Rock_Volcanic_Cobble"
    },
    {
      "x": -15,
      "y": 2,
      "z": 15,
      "name": "Rock_Volcanic_Cobble"
    },
    {
      "x": -15,
      "y": 12,
      "z": 15,
      "name": "Rock_Volcanic_Brick_Smooth"
    },
    {
      "x": -15,
      "y": 113,
      "z": 15,
      "name": "Rock_Sandstone_Brick_Smooth"
    },
    {
      "x": -15,
      "y": 121,
      "z": 15,
      "name": "Rock_Sandstone_Brick_Smooth"
    },
    {
      "x": -15,
      "y": 129,
      "z": 15,
      "name": "Rock_Sandstone_Brick_Smooth"
    },
    {
      "x": -15,
      "y": 130,
      "z": 15,
      "name": "Rock_Sandstone"
    },
    {
      "x": -14,
      "y": 0,
      "z": -15,
      "name": "Rock_Volcanic"
    },
    {
      "x": -14,
      "y": 1,
      "z": -15,
      "name": "Rock_Volcanic_Cobble"
    },
    {
      "x": -14,
      "y": 2,
      "z": -15,
      "name": "Rock_Volcanic_Cobble"
    },
    {
      "x": -14,
      "y": 12,
      "z": -15,
      "name": "Rock_Volcanic_Brick_Smooth"
    },
    {
      "x": -14,
      "y": 13,
      "z": -15,
      "name": "Furniture_Ancient_Crate",
      "rotation": 2
    },
    {
      "x": -14,
      "y": 113,
      "z": -15,
      "name": "Rock_Sandstone_Brick_Smooth"
    },
    {
      "x": -14,
      "y": 121,
      "z": -15,
      "name": "Rock_Sandstone_Brick_Smooth"
    },
    {
      "x": -14,
      "y": 129,
      "z": -15,
      "name": "Rock_Sandstone_Brick_Smooth"
    },
    {
      "x": -14,
      "y": 130,
      "z": -15,
      "name": "Rock_Sandstone"
    },
    {
      "x": -14,
      "y": 0,
      "z": -14,
      "name": "Rock_Volcanic"
    },
    {
      "x": -14,
      "y": 1,
      "z": -14,
      "name": "Rock_Volcanic_Cobble"
    },
    {
      "x": -14,
      "y": 2,
      "z": -14,
      "name": "Rock_Volcanic_Cobble"
    },
    {
      "x": -14,
      "y": 3,
      "z": -14,
      "name": "Rock_Volcanic_Brick_Smooth"
    },
    {
      "x": -14,
      "y": 4,
      "z": -14,
      "name": "Rock_Volcanic_Brick_Ornate"
    },
    {
      "x": -14,
      "y": 5,
      "z": -14,
      "name": "Rock_Volcanic_Brick_Decorative"
    },
    {
      "x": -14,
      "y": 6,
      "z": -14,
      "name": "Rock_Volcanic_Brick_Decorative"
    },
    {
      "x": -14,
      "y": 7,
      "z": -14,
      "name": "Rock_Volcanic_Brick_Decorative"
    },
    {
      "x": -14,
      "y": 8,
      "z": -14,
      "name": "Rock_Volcanic_Brick_Ornate"
    },
    {
      "x": -14,
      "y": 9,
      "z": -14,
      "name": "Rock_Volcanic_Brick"
    },
    {
      "x": -14,
      "y": 10,
      "z": -14,
      "name": "Rock_Volcanic_Brick"
    },
    {
      "x": -14,
      "y": 11,
      "z": -14,
      "name": "Rock_Volcanic_Brick"
    },
    {
      "x": -14,
      "y": 12,
      "z": -14,
      "name": "Rock_Volcanic_Brick_Smooth"
    },
    {
      "x": -14,
      "y": 13,
      "z": -14,
      "name": "Rock_Volcanic_Brick"
    },
    {
      "x": -14,
      "y": 14,
      "z": -14,
      "name": "Rock_Volcanic_Brick"
    },
    {
      "x": -14,
      "y": 15,
      "z": -14,
      "name": "Rock_Volcanic_Brick_Ornate"
    },
    {
      "x": -14,
      "y": 16,
      "z": -14,
      "name": "Rock_Volcanic_Brick_Decorative"
    },
    {
      "x": -14,
      "y": 17,
      "z": -14,
      "name": "Rock_Volcanic_Brick_Decorative"
    },
    {
      "x": -14,
      "y": 18,
      "z": -14,
      "name": "Rock_Volcanic_Brick_Decorative"
    },
    {
      "x": -14,
      "y": 19,
      "z": -14,
      "name": "Rock_Volcanic_Brick_Ornate"
    },
    {
      "x": -14,
      "y": 20,
      "z": -14,
      "name": "Rock_Volcanic_Brick"
    },
    {
      "x": -14,
      "y": 21,
      "z": -14,
      "name": "Rock_Volcanic_Brick_Smooth"
    },
    {
      "x": -14,
      "y": 111,
      "z": -14,
      "name": "Rock_Sandstone_Brick_Ornate"
    },
    {
      "x": -14,
      "y": 112,
      "z": -14,
      "name": "Rock_Sandstone_Brick"
    },
    {
      "x": -14,
      "y": 113,
      "z": -14,
      "name": "Rock_Sandstone_Brick_Smooth"
    },
    {
      "x": -14,
      "y": 114,
      "z": -14,
      "name": "Rock_Sandstone_Brick"
    },
    {
      "x": -14,
      "y": 115,
      "z": -14,
      "name": "Rock_Sandstone_Brick_Ornate"
    },
    {
      "x": -14,
      "y": 116,
      "z": -14,
      "name": "Rock_Sandstone_Brick_Decorative"
    },
    {
      "x": -14,
      "y": 117,
      "z": -14,
      "name": "Rock_Sandstone_Brick_Decorative"
    },
    {
      "x": -14,
      "y": 118,
      "z": -14,
      "name": "Rock_Sandstone_Brick_Decorative"
    },
    {
      "x": -14,
      "y": 119,
      "z": -14,
      "name": "Rock_Sandstone_Brick_Ornate"
    },
    {
      "x": -14,
      "y": 120,
      "z": -14,
      "name": "Rock_Sandstone_Brick"
    },
    {
      "x": -14,
      "y": 121,
      "z": -14,
      "name": "Rock_Sandstone_Brick_Smooth"
    },
    {
      "x": -14,
      "y": 122,
      "z": -14,
      "name": "Rock_Sandstone_Brick"
    },
    {
      "x": -14,
      "y": 123,
      "z": -14,
      "name": "Rock_Sandstone_Brick_Ornate"
    },
    {
      "x": -14,
      "y": 124,
      "z": -14,
      "name": "Rock_Sandstone_Brick_Decorative"
    },
    {
      "x": -14,
      "y": 125,
      "z": -14,
      "name": "Rock_Sandstone_Brick_Decorative"
    },
    {
      "x": -14,
      "y": 126,
      "z": -14,
      "name": "Rock_Sandstone_Brick_Decorative"
    },
    {
      "x": -14,
      "y": 127,
      "z": -14,
      "name": "Rock_Sandstone_Brick_Ornate"
    },
    {
      "x": -14,
      "y": 128,
      "z": -14,
      "name": "Rock_Sandstone_Brick"
    },
    {
      "x": -14,
      "y": 129,
      "z": -14,
      "name": "Rock_Sandstone_Brick_Smooth"
    },
    {
      "x": -14,
      "y": 130,
      "z": -14,
      "name": "Rock_Sandstone"
    },
    {
      "x": -14,
      "y": 0,
      "z": -13,
      "name": "Rock_Volcanic"
    },
    {
      "x": -14,
      "y": 1,
      "z": -13,
      "name": "Rock_Volcanic_Cobble"
    },
    {
      "x": -14,
      "y": 2,
      "z": -13,
      "name": "Rock_Volcanic_Cobble"
    },
    {
      "x": -14,
      "y": 12,
      "z": -13,
      "name": "Rock_Volcanic_Brick_Smooth"
    },
    {
      "x": -14,
      "y": 113,
      "z": -13,
      "name": "Rock_Sandstone_Brick_Smooth"
    },
    {
      "x": -14,
      "y": 121,
      "z": -13,
      "name": "Rock_Sandstone_Brick_Smooth"
    },
    {
      "x": -14,
      "y": 129,
      "z": -13,
      "name": "Rock_Sandstone_Brick_Smooth"
    },
    {
      "x": -14,
      "y": 130,
      "z": -13,
      "name": "Rock_Sandstone"
    },
    {
      "x": -14,
      "y": 0,
      "z": -12,
      "name": "Rock_Volcanic"
    },
    {
      "x": -14,
      "y": 1,
      "z": -12,
      "name": "Rock_Volcanic_Cobble"
    },
    {
      "x": -14,
      "y": 2,
      "z": -12,
      "name": "Rock_Volcanic_Cobble"
    },
    {
      "x": -14,
      "y": 12,
      "z": -12,
      "name": "Rock_Volcanic_Brick_Smooth"
    },
    {
      "x": -14,
      "y": 113,
      "z": -12,
      "name": "Rock_Sandstone_Brick_Smooth"
    },
    {
      "x": -14,
      "y": 121,
      "z": -12,
      "name": "Rock_Sandstone_Brick_Smooth"
    },
    {
      "x": -14,
      "y": 129,
      "z": -12,
      "name": "Rock_Sandstone_Brick_Smooth"
    },
    {
      "x": -14,
      "y": 130,
      "z": -12,
      "name": "Rock_Sandstone"
    },
    {
      "x": -14,
      "y": 0,
      "z": -11,
      "name": "Rock_Volcanic"
    },
    {
      "x": -14,
      "y": 1,
      "z": -11,
      "name": "Rock_Volcanic_Cobble"
    },
    {
      "x": -14,
      "y": 2,
      "z": -11,
      "name": "Rock_Volcanic_Cobble"
    },
    {
      "x": -14,
      "y": 12,
      "z": -11,
      "name": "Rock_Volcanic_Brick_Smooth"
    },
    {
      "x": -14,
      "y": 113,
      "z": -11,
      "name": "Rock_Sandstone_Brick_Smooth"
    },
    {
      "x": -14,
      "y": 121,
      "z": -11,
      "name": "Rock_Sandstone_Brick_Smooth"
    },
    {
      "x": -14,
      "y": 129,
      "z": -11,
      "name": "Rock_Sandstone_Brick_Smooth"
    },
    {
      "x": -14,
      "y": 130,
      "z": -11,
      "name": "Rock_Sandstone"
    },
    {
      "x": -14,
      "y": 0,
      "z": -10,
      "name": "Rock_Volcanic_Cracked_Lava"
    },
    {
      "x": -14,
      "y": 1,
      "z": -10,
      "name": "Rock_Volcanic_Cobble"
    },
    {
      "x": -14,
      "y": 2,
      "z": -10,
      "name": "Rock_Volcanic_Cobble"
    },
    {
      "x": -14,
      "y": 3,
      "z": -10,
      "name": "Rubble_Volcanic_Medium"
    },
    {
      "x": -14,
      "y": 12,
      "z": -10,
      "name": "Rock_Volcanic_Brick_Smooth"
    },
    {
      "x": -14,
      "y": 17,
      "z": -10,
      "name": "Deco_SpiderWeb_Flat",
      "rotation": 7
    },
    {
      "x": -14,
      "y": 113,
      "z": -10,
      "name": "Rock_Sandstone_Brick_Smooth"
    },
    {
      "x": -14,
      "y": 114,
      "z": -10,
      "name": "Furniture_Village_Pot"
    },
    {
      "x": -14,
      "y": 121,
      "z": -10,
      "name": "Rock_Sandstone_Brick_Smooth"
    },
    {
      "x": -14,
      "y": 129,
      "z": -10,
      "name": "Rock_Sandstone_Brick_Smooth"
    },
    {
      "x": -14,
      "y": 130,
      "z": -10,
      "name": "Rock_Sandstone"
    },
    {
      "x": -14,
      "y": 0,
      "z": -9,
      "name": "Rock_Volcanic_Cracked_Lava"
    },
    {
      "x": -14,
      "y": 1,
      "z": -9,
      "name": "Rock_Volcanic_Cobble"
    },
    {
      "x": -14,
      "y": 2,
      "z": -9,
      "name": "Rock_Volcanic_Cobble"
    },
    {
      "x": -14,
      "y": 12,
      "z": -9,
      "name": "Rock_Volcanic_Brick_Smooth"
    },
    {
      "x": -14,
      "y": 113,
      "z": -9,
      "name": "Rock_Sandstone_Brick_Smooth"
    },
    {
      "x": -14,
      "y": 121,
      "z": -9,
      "name": "Rock_Sandstone_Brick_Smooth"
    },
    {
      "x": -14,
      "y": 129,
      "z": -9,
      "name": "Rock_Sandstone_Brick_Smooth"
    },
    {
      "x": -14,
      "y": 130,
      "z": -9,
      "name": "Rock_Sandstone"
    },
    {
      "x": -14,
      "y": 0,
      "z": -8,
      "name": "Rock_Volcanic"
    },
    {
      "x": -14,
      "y": 1,
      "z": -8,
      "name": "Rock_Volcanic_Cobble"
    },
    {
      "x": -14,
      "y": 2,
      "z": -8,
      "name": "Rock_Volcanic_Cobble"
    },
    {
      "x": -14,
      "y": 3,
      "z": -8,
      "name": "Furniture_Ancient_Barrel"
    },
    {
      "x": -14,
      "y": 12,
      "z": -8,
      "name": "Rock_Volcanic_Brick_Smooth"
    },
    {
      "x": -14,
      "y": 113,
      "z": -8,
      "name": "Rock_Sandstone_Brick_Smooth"
    },
    {
      "x": -14,
      "y": 121,
      "z": -8,
      "name": "Rock_Sandstone_Brick_Smooth"
    },
    {
      "x": -14,
      "y": 129,
      "z": -8,
      "name": "Rock_Sandstone_Brick_Smooth"
    },
    {
      "x": -14,
      "y": 130,
      "z": -8,
      "name": "Rock_Sandstone"
    },
    {
      "x": -14,
      "y": 0,
      "z": -7,
      "name": "Rock_Volcanic_Cracked_Lava"
    },
    {
      "x": -14,
      "y": 1,
      "z": -7,
      "name": "Rock_Volcanic_Cobble"
    },
    {
      "x": -14,
      "y": 2,
      "z": -7,
      "name": "Rock_Volcanic_Cobble"
    },
    {
      "x": -14,
      "y": 3,
      "z": -7,
      "name": "Rubble_Volcanic_Medium"
    },
    {
      "x": -14,
      "y": 12,
      "z": -7,
      "name": "Rock_Volcanic_Brick_Smooth"
    },
    {
      "x": -14,
      "y": 113,
      "z": -7,
      "name": "Rock_Sandstone_Brick_Smooth"
    },
    {
      "x": -14,
      "y": 121,
      "z": -7,
      "name": "Rock_Sandstone_Brick_Smooth"
    },
    {
      "x": -14,
      "y": 129,
      "z": -7,
      "name": "Rock_Sandstone_Brick_Smooth"
    },
    {
      "x": -14,
      "y": 130,
      "z": -7,
      "name": "Rock_Sandstone"
    },
    {
      "x": -14,
      "y": 0,
      "z": -6,
      "name": "Rock_Volcanic"
    },
    {
      "x": -14,
      "y": 1,
      "z": -6,
      "name": "Rock_Volcanic_Cobble"
    },
    {
      "x": -14,
      "y": 2,
      "z": -6,
      "name": "Rock_Volcanic_Cobble"
    },
    {
      "x": -14,
      "y": 12,
      "z": -6,
      "name": "Rock_Volcanic_Brick_Smooth"
    },
    {
      "x": -14,
      "y": 113,
      "z": -6,
      "name": "Rock_Sandstone_Brick_Smooth"
    },
    {
      "x": -14,
      "y": 121,
      "z": -6,
      "name": "Rock_Sandstone_Brick_Smooth"
    },
    {
      "x": -14,
      "y": 129,
      "z": -6,
      "name": "Rock_Sandstone_Brick_Smooth",
      "rotation": 1
    },
    {
      "x": -14,
      "y": 130,
      "z": -6,
      "name": "Rock_Sandstone",
      "rotation": 1
    },
    {
      "x": -14,
      "y": 0,
      "z": -5,
      "name": "Rock_Volcanic"
    },
    {
      "x": -14,
      "y": 1,
      "z": -5,
      "name": "Rock_Volcanic_Cobble"
    },
    {
      "x": -14,
      "y": 2,
      "z": -5,
      "name": "Rock_Volcanic_Cobble"
    },
    {
      "x": -14,
      "y": 3,
      "z": -5,
      "name": "Rubble_Volcanic_Medium"
    },
    {
      "x": -14,
      "y": 12,
      "z": -5,
      "name": "Rock_Volcanic_Brick_Smooth"
    },
    {
      "x": -14,
      "y": 16,
      "z": -5,
      "name": "Deco_SpiderWeb_Flat",
      "rotation": 7
    },
    {
      "x": -14,
      "y": 113,
      "z": -5,
      "name": "Rock_Sandstone_Brick_Smooth"
    },
    {
      "x": -14,
      "y": 121,
      "z": -5,
      "name": "Rock_Sandstone_Brick_Smooth"
    },
    {
      "x": -14,
      "y": 129,
      "z": -5,
      "name": "Rock_Sandstone_Brick_Smooth",
      "rotation": 1
    },
    {
      "x": -14,
      "y": 130,
      "z": -5,
      "name": "Rock_Sandstone",
      "rotation": 1
    },
    {
      "x": -14,
      "y": 0,
      "z": -4,
      "name": "Rock_Volcanic_Cracked_Lava"
    },
    {
      "x": -14,
      "y": 1,
      "z": -4,
      "name": "Rock_Volcanic_Cobble"
    },
    {
      "x": -14,
      "y": 2,
      "z": -4,
      "name": "Rock_Volcanic_Cobble"
    },
    {
      "x": -14,
      "y": 3,
      "z": -4,
      "name": "Rock_Volcanic"
    },
    {
      "x": -14,
      "y": 12,
      "z": -4,
      "name": "Rock_Volcanic_Brick_Smooth"
    },
    {
      "x": -14,
      "y": 13,
      "z": -4,
      "name": "Furniture_Ancient_Barrel"
    },
    {
      "x": -14,
      "y": 113,
      "z": -4,
      "name": "Rock_Sandstone_Brick_Smooth"
    },
    {
      "x": -14,
      "y": 114,
      "z": -4,
      "name": "Furniture_Village_Pot"
    },
    {
      "x": -14,
      "y": 121,
      "z": -4,
      "name": "Rock_Sandstone_Brick_Smooth"
    },
    {
      "x": -14,
      "y": 129,
      "z": -4,
      "name": "Rock_Sandstone_Brick_Smooth",
      "rotation": 1
    },
    {
      "x": -14,
      "y": 130,
      "z": -4,
      "name": "Rock_Sandstone",
      "rotation": 1
    },
    {
      "x": -14,
      "y": 0,
      "z": -3,
      "name": "Rock_Volcanic"
    },
    {
      "x": -14,
      "y": 1,
      "z": -3,
      "name": "Rock_Volcanic_Cobble"
    },
    {
      "x": -14,
      "y": 2,
      "z": -3,
      "name": "Rock_Volcanic_Cobble"
    },
    {
      "x": -14,
      "y": 3,
      "z": -3,
      "name": "Rock_Volcanic"
    },
    {
      "x": -14,
      "y": 4,
      "z": -3,
      "name": "Rock_Volcanic"
    },
    {
      "x": -14,
      "y": 5,
      "z": -3,
      "name": "Rock_Volcanic"
    },
    {
      "x": -14,
      "y": 6,
      "z": -3,
      "name": "Rock_Volcanic"
    },
    {
      "x": -14,
      "y": 7,
      "z": -3,
      "name": "Rock_Volcanic"
    },
    {
      "x": -14,
      "y": 12,
      "z": -3,
      "name": "Rock_Volcanic_Brick_Smooth"
    },
    {
      "x": -14,
      "y": 13,
      "z": -3,
      "name": "Rubble_Volcanic_Medium"
    },
    {
      "x": -14,
      "y": 113,
      "z": -3,
      "name": "Rock_Sandstone_Brick_Smooth"
    },
    {
      "x": -14,
      "y": 114,
      "z": -3,
      "name": "Furniture_Temple_Wind_Pot"
    },
    {
      "x": -14,
      "y": 115,
      "z": -3,
      "name": "Furniture_Temple_Wind_Pot",
      "filler": 1024
    },
    {
      "x": -14,
      "y": 121,
      "z": -3,
      "name": "Rock_Sandstone_Brick_Smooth"
    },
    {
      "x": -14,
      "y": 129,
      "z": -3,
      "name": "Rock_Sandstone_Brick_Smooth",
      "rotation": 1
    },
    {
      "x": -14,
      "y": 130,
      "z": -3,
      "name": "Rock_Sandstone",
      "rotation": 1
    },
    {
      "x": -14,
      "y": 0,
      "z": -2,
      "name": "Rock_Volcanic"
    },
    {
      "x": -14,
      "y": 1,
      "z": -2,
      "name": "Rock_Volcanic_Cobble"
    },
    {
      "x": -14,
      "y": 2,
      "z": -2,
      "name": "Rock_Volcanic_Cobble"
    },
    {
      "x": -14,
      "y": 3,
      "z": -2,
      "name": "Rock_Volcanic"
    },
    {
      "x": -14,
      "y": 4,
      "z": -2,
      "name": "Rock_Volcanic"
    },
    {
      "x": -14,
      "y": 5,
      "z": -2,
      "name": "Rock_Volcanic"
    },
    {
      "x": -14,
      "y": 6,
      "z": -2,
      "name": "Rock_Volcanic"
    },
    {
      "x": -14,
      "y": 7,
      "z": -2,
      "name": "Rock_Volcanic"
    },
    {
      "x": -14,
      "y": 8,
      "z": -2,
      "name": "Rock_Volcanic"
    },
    {
      "x": -14,
      "y": 9,
      "z": -2,
      "name": "Rock_Volcanic"
    },
    {
      "x": -14,
      "y": 10,
      "z": -2,
      "name": "Rock_Volcanic"
    },
    {
      "x": -14,
      "y": 11,
      "z": -2,
      "name": "Rock_Gem_Emerald",
      "rotation": 7
    },
    {
      "x": -14,
      "y": 12,
      "z": -2,
      "name": "Rock_Volcanic_Brick_Smooth"
    },
    {
      "x": -14,
      "y": 113,
      "z": -2,
      "name": "Rock_Sandstone_Brick_Smooth"
    },
    {
      "x": -14,
      "y": 121,
      "z": -2,
      "name": "Rock_Sandstone_Brick_Smooth"
    },
    {
      "x": -14,
      "y": 129,
      "z": -2,
      "name": "Rock_Sandstone_Brick_Smooth",
      "rotation": 1
    },
    {
      "x": -14,
      "y": 130,
      "z": -2,
      "name": "Rock_Sandstone",
      "rotation": 1
    },
    {
      "x": -14,
      "y": 0,
      "z": -1,
      "name": "Rock_Volcanic"
    },
    {
      "x": -14,
      "y": 1,
      "z": -1,
      "name": "Rock_Volcanic_Cobble"
    },
    {
      "x": -14,
      "y": 2,
      "z": -1,
      "name": "Rock_Volcanic_Cobble"
    },
    {
      "x": -14,
      "y": 3,
      "z": -1,
      "name": "Rock_Volcanic"
    },
    {
      "x": -14,
      "y": 4,
      "z": -1,
      "name": "Rock_Volcanic"
    },
    {
      "x": -14,
      "y": 5,
      "z": -1,
      "name": "Rock_Volcanic"
    },
    {
      "x": -14,
      "y": 6,
      "z": -1,
      "name": "Rock_Volcanic"
    },
    {
      "x": -14,
      "y": 7,
      "z": -1,
      "name": "Rock_Volcanic"
    },
    {
      "x": -14,
      "y": 8,
      "z": -1,
      "name": "Rock_Volcanic"
    },
    {
      "x": -14,
      "y": 9,
      "z": -1,
      "name": "Rock_Volcanic"
    },
    {
      "x": -14,
      "y": 10,
      "z": -1,
      "name": "Rock_Volcanic"
    },
    {
      "x": -14,
      "y": 11,
      "z": -1,
      "name": "Rock_Volcanic_Cracked_Poisoned"
    },
    {
      "x": -14,
      "y": 12,
      "z": -1,
      "name": "Rock_Volcanic"
    },
    {
      "x": -14,
      "y": 13,
      "z": -1,
      "name": "Rock_Volcanic_Cracked_Poisoned"
    },
    {
      "x": -14,
      "y": 113,
      "z": -1,
      "name": "Rock_Sandstone_Brick_Smooth"
    },
    {
      "x": -14,
      "y": 121,
      "z": -1,
      "name": "Rock_Sandstone_Brick_Smooth"
    },
    {
      "x": -14,
      "y": 122,
      "z": -1,
      "name": "Furniture_Temple_Wind_Pot"
    },
    {
      "x": -14,
      "y": 123,
      "z": -1,
      "name": "Furniture_Temple_Wind_Pot",
      "filler": 1024
    },
    {
      "x": -14,
      "y": 129,
      "z": -1,
      "name": "Rock_Sandstone_Brick_Smooth",
      "rotation": 1
    },
    {
      "x": -14,
      "y": 130,
      "z": -1,
      "name": "Rock_Sandstone",
      "rotation": 1
    },
    {
      "x": -14,
      "y": 0,
      "z": 0,
      "name": "Rock_Volcanic"
    },
    {
      "x": -14,
      "y": 1,
      "z": 0,
      "name": "Rock_Volcanic_Cobble"
    },
    {
      "x": -14,
      "y": 2,
      "z": 0,
      "name": "Rock_Volcanic_Cobble"
    },
    {
      "x": -14,
      "y": 3,
      "z": 0,
      "name": "Rock_Volcanic_Cracked_Poisoned"
    },
    {
      "x": -14,
      "y": 4,
      "z": 0,
      "name": "Rock_Volcanic"
    },
    {
      "x": -14,
      "y": 5,
      "z": 0,
      "name": "Rock_Volcanic"
    },
    {
      "x": -14,
      "y": 6,
      "z": 0,
      "name": "Rock_Volcanic_Cracked_Poisoned"
    },
    {
      "x": -14,
      "y": 7,
      "z": 0,
      "name": "Rock_Volcanic"
    },
    {
      "x": -14,
      "y": 8,
      "z": 0,
      "name": "Rock_Volcanic"
    },
    {
      "x": -14,
      "y": 9,
      "z": 0,
      "name": "Rock_Volcanic"
    },
    {
      "x": -14,
      "y": 10,
      "z": 0,
      "name": "Rock_Volcanic_Cracked_Poisoned"
    },
    {
      "x": -14,
      "y": 11,
      "z": 0,
      "name": "Rock_Volcanic"
    },
    {
      "x": -14,
      "y": 12,
      "z": 0,
      "name": "Rock_Volcanic"
    },
    {
      "x": -14,
      "y": 13,
      "z": 0,
      "name": "Rock_Volcanic"
    },
    {
      "x": -14,
      "y": 16,
      "z": 0,
      "name": "Rock_Crystal_Green_Medium",
      "rotation": 7
    },
    {
      "x": -14,
      "y": 111,
      "z": 0,
      "name": "Rock_Sandstone_Brick_Ornate",
      "rotation": 1
    },
    {
      "x": -14,
      "y": 112,
      "z": 0,
      "name": "Rock_Sandstone_Brick",
      "rotation": 1
    },
    {
      "x": -14,
      "y": 113,
      "z": 0,
      "name": "Rock_Sandstone_Brick_Smooth"
    },
    {
      "x": -14,
      "y": 114,
      "z": 0,
      "name": "Rock_Sandstone_Brick",
      "rotation": 1
    },
    {
      "x": -14,
      "y": 115,
      "z": 0,
      "name": "Rock_Sandstone_Brick_Ornate",
      "rotation": 1
    },
    {
      "x": -14,
      "y": 116,
      "z": 0,
      "name": "Rock_Sandstone_Brick_Decorative",
      "rotation": 1
    },
    {
      "x": -14,
      "y": 117,
      "z": 0,
      "name": "Rock_Sandstone_Brick_Decorative",
      "rotation": 1
    },
    {
      "x": -14,
      "y": 118,
      "z": 0,
      "name": "Rock_Sandstone_Brick_Decorative",
      "rotation": 1
    },
    {
      "x": -14,
      "y": 119,
      "z": 0,
      "name": "Rock_Sandstone_Brick_Ornate",
      "rotation": 1
    },
    {
      "x": -14,
      "y": 120,
      "z": 0,
      "name": "Rock_Sandstone_Brick",
      "rotation": 1
    },
    {
      "x": -14,
      "y": 121,
      "z": 0,
      "name": "Rock_Sandstone_Brick_Smooth"
    },
    {
      "x": -14,
      "y": 122,
      "z": 0,
      "name": "Rock_Sandstone_Brick",
      "rotation": 1
    },
    {
      "x": -14,
      "y": 123,
      "z": 0,
      "name": "Rock_Sandstone_Brick_Ornate",
      "rotation": 1
    },
    {
      "x": -14,
      "y": 124,
      "z": 0,
      "name": "Rock_Sandstone_Brick_Decorative",
      "rotation": 1
    },
    {
      "x": -14,
      "y": 125,
      "z": 0,
      "name": "Rock_Sandstone_Brick_Decorative",
      "rotation": 1
    },
    {
      "x": -14,
      "y": 126,
      "z": 0,
      "name": "Rock_Sandstone_Brick_Decorative",
      "rotation": 1
    },
    {
      "x": -14,
      "y": 127,
      "z": 0,
      "name": "Rock_Sandstone_Brick_Ornate",
      "rotation": 1
    },
    {
      "x": -14,
      "y": 128,
      "z": 0,
      "name": "Rock_Sandstone_Brick",
      "rotation": 1
    },
    {
      "x": -14,
      "y": 129,
      "z": 0,
      "name": "Rock_Sandstone_Brick_Smooth",
      "rotation": 1
    },
    {
      "x": -14,
      "y": 130,
      "z": 0,
      "name": "Rock_Sandstone",
      "rotation": 1
    },
    {
      "x": -14,
      "y": 0,
      "z": 1,
      "name": "Rock_Volcanic_Cracked_Lava"
    },
    {
      "x": -14,
      "y": 1,
      "z": 1,
      "name": "Rock_Volcanic_Cobble"
    },
    {
      "x": -14,
      "y": 2,
      "z": 1,
      "name": "Rock_Volcanic_Cobble"
    },
    {
      "x": -14,
      "y": 3,
      "z": 1,
      "name": "Rock_Volcanic"
    },
    {
      "x": -14,
      "y": 4,
      "z": 1,
      "name": "Rock_Volcanic"
    },
    {
      "x": -14,
      "y": 5,
      "z": 1,
      "name": "Rock_Volcanic"
    },
    {
      "x": -14,
      "y": 6,
      "z": 1,
      "name": "Rock_Volcanic"
    },
    {
      "x": -14,
      "y": 7,
      "z": 1,
      "name": "Rock_Volcanic"
    },
    {
      "x": -14,
      "y": 8,
      "z": 1,
      "name": "Rock_Volcanic_Cracked_Poisoned"
    },
    {
      "x": -14,
      "y": 9,
      "z": 1,
      "name": "Rock_Volcanic"
    },
    {
      "x": -14,
      "y": 10,
      "z": 1,
      "name": "Rock_Volcanic"
    },
    {
      "x": -14,
      "y": 11,
      "z": 1,
      "name": "Rock_Volcanic"
    },
    {
      "x": -14,
      "y": 12,
      "z": 1,
      "name": "Rock_Volcanic"
    },
    {
      "x": -14,
      "y": 13,
      "z": 1,
      "name": "Ore_Gold_Volcanic"
    },
    {
      "x": -14,
      "y": 14,
      "z": 1,
      "name": "Rubble_Volcanic_Medium"
    },
    {
      "x": -14,
      "y": 17,
      "z": 1,
      "name": "Deco_SpiderWeb_Flat",
      "rotation": 7
    },
    {
      "x": -14,
      "y": 113,
      "z": 1,
      "name": "Rock_Sandstone_Brick_Smooth"
    },
    {
      "x": -14,
      "y": 121,
      "z": 1,
      "name": "Rock_Sandstone_Brick_Smooth"
    },
    {
      "x": -14,
      "y": 129,
      "z": 1,
      "name": "Rock_Sandstone_Brick_Smooth"
    },
    {
      "x": -14,
      "y": 130,
      "z": 1,
      "name": "Rock_Sandstone"
    },
    {
      "x": -14,
      "y": 0,
      "z": 2,
      "name": "Rock_Volcanic"
    },
    {
      "x": -14,
      "y": 1,
      "z": 2,
      "name": "Rock_Volcanic_Cobble"
    },
    {
      "x": -14,
      "y": 2,
      "z": 2,
      "name": "Rock_Volcanic_Cobble"
    },
    {
      "x": -14,
      "y": 3,
      "z": 2,
      "name": "Rock_Volcanic_Cracked_Poisoned"
    },
    {
      "x": -14,
      "y": 4,
      "z": 2,
      "name": "Rock_Volcanic"
    },
    {
      "x": -14,
      "y": 5,
      "z": 2,
      "name": "Rock_Volcanic_Cracked_Poisoned"
    },
    {
      "x": -14,
      "y": 6,
      "z": 2,
      "name": "Rock_Volcanic"
    },
    {
      "x": -14,
      "y": 7,
      "z": 2,
      "name": "Rock_Volcanic"
    },
    {
      "x": -14,
      "y": 8,
      "z": 2,
      "name": "Rock_Volcanic"
    },
    {
      "x": -14,
      "y": 9,
      "z": 2,
      "name": "Rock_Volcanic"
    },
    {
      "x": -14,
      "y": 10,
      "z": 2,
      "name": "Rock_Volcanic"
    },
    {
      "x": -14,
      "y": 12,
      "z": 2,
      "name": "Rock_Volcanic_Brick_Smooth"
    },
    {
      "x": -14,
      "y": 13,
      "z": 2,
      "name": "Rubble_Volcanic"
    },
    {
      "x": -14,
      "y": 113,
      "z": 2,
      "name": "Rock_Sandstone_Brick_Smooth"
    },
    {
      "x": -14,
      "y": 121,
      "z": 2,
      "name": "Rock_Sandstone_Brick_Smooth"
    },
    {
      "x": -14,
      "y": 129,
      "z": 2,
      "name": "Rock_Sandstone_Brick_Smooth"
    },
    {
      "x": -14,
      "y": 130,
      "z": 2,
      "name": "Rock_Sandstone"
    },
    {
      "x": -14,
      "y": 0,
      "z": 3,
      "name": "Rock_Volcanic"
    },
    {
      "x": -14,
      "y": 1,
      "z": 3,
      "name": "Rock_Volcanic_Cobble"
    },
    {
      "x": -14,
      "y": 2,
      "z": 3,
      "name": "Rock_Volcanic_Cobble"
    },
    {
      "x": -14,
      "y": 3,
      "z": 3,
      "name": "Rock_Volcanic"
    },
    {
      "x": -14,
      "y": 4,
      "z": 3,
      "name": "Rock_Volcanic"
    },
    {
      "x": -14,
      "y": 5,
      "z": 3,
      "name": "Rock_Volcanic"
    },
    {
      "x": -14,
      "y": 6,
      "z": 3,
      "name": "Rock_Volcanic"
    },
    {
      "x": -14,
      "y": 7,
      "z": 3,
      "name": "Rock_Volcanic"
    },
    {
      "x": -14,
      "y": 12,
      "z": 3,
      "name": "Rock_Volcanic_Brick_Smooth"
    },
    {
      "x": -14,
      "y": 113,
      "z": 3,
      "name": "Rock_Sandstone_Brick_Smooth"
    },
    {
      "x": -14,
      "y": 121,
      "z": 3,
      "name": "Rock_Sandstone_Brick_Smooth"
    },
    {
      "x": -14,
      "y": 129,
      "z": 3,
      "name": "Rock_Sandstone_Brick_Smooth"
    },
    {
      "x": -14,
      "y": 130,
      "z": 3,
      "name": "Rock_Sandstone"
    },
    {
      "x": -14,
      "y": 0,
      "z": 4,
      "name": "Rock_Volcanic"
    },
    {
      "x": -14,
      "y": 1,
      "z": 4,
      "name": "Rock_Volcanic_Cobble"
    },
    {
      "x": -14,
      "y": 2,
      "z": 4,
      "name": "Rock_Volcanic_Cobble"
    },
    {
      "x": -14,
      "y": 3,
      "z": 4,
      "name": "Rock_Volcanic"
    },
    {
      "x": -14,
      "y": 12,
      "z": 4,
      "name": "Rock_Volcanic_Brick_Smooth"
    },
    {
      "x": -14,
      "y": 113,
      "z": 4,
      "name": "Rock_Sandstone_Brick_Smooth"
    },
    {
      "x": -14,
      "y": 121,
      "z": 4,
      "name": "Rock_Sandstone_Brick_Smooth"
    },
    {
      "x": -14,
      "y": 129,
      "z": 4,
      "name": "Rock_Sandstone_Brick_Smooth"
    },
    {
      "x": -14,
      "y": 130,
      "z": 4,
      "name": "Rock_Sandstone"
    },
    {
      "x": -14,
      "y": 0,
      "z": 5,
      "name": "Rock_Volcanic"
    },
    {
      "x": -14,
      "y": 1,
      "z": 5,
      "name": "Rock_Volcanic_Cobble"
    },
    {
      "x": -14,
      "y": 2,
      "z": 5,
      "name": "Rock_Volcanic_Cobble"
    },
    {
      "x": -14,
      "y": 12,
      "z": 5,
      "name": "Rock_Volcanic_Brick_Smooth"
    },
    {
      "x": -14,
      "y": 113,
      "z": 5,
      "name": "Rock_Sandstone_Brick_Smooth"
    },
    {
      "x": -14,
      "y": 121,
      "z": 5,
      "name": "Rock_Sandstone_Brick_Smooth"
    },
    {
      "x": -14,
      "y": 129,
      "z": 5,
      "name": "Rock_Sandstone_Brick_Smooth"
    },
    {
      "x": -14,
      "y": 130,
      "z": 5,
      "name": "Rock_Sandstone"
    },
    {
      "x": -14,
      "y": 0,
      "z": 6,
      "name": "Rock_Volcanic_Cracked_Lava"
    },
    {
      "x": -14,
      "y": 1,
      "z": 6,
      "name": "Rock_Volcanic_Cobble"
    },
    {
      "x": -14,
      "y": 2,
      "z": 6,
      "name": "Rock_Volcanic_Cobble"
    },
    {
      "x": -14,
      "y": 12,
      "z": 6,
      "name": "Rock_Volcanic_Brick_Smooth"
    },
    {
      "x": -14,
      "y": 113,
      "z": 6,
      "name": "Rock_Sandstone_Brick_Smooth"
    },
    {
      "x": -14,
      "y": 121,
      "z": 6,
      "name": "Rock_Sandstone_Brick_Smooth"
    },
    {
      "x": -14,
      "y": 129,
      "z": 6,
      "name": "Rock_Sandstone_Brick_Smooth"
    },
    {
      "x": -14,
      "y": 130,
      "z": 6,
      "name": "Rock_Sandstone"
    },
    {
      "x": -14,
      "y": 0,
      "z": 7,
      "name": "Rock_Volcanic"
    },
    {
      "x": -14,
      "y": 1,
      "z": 7,
      "name": "Rock_Volcanic_Cobble"
    },
    {
      "x": -14,
      "y": 2,
      "z": 7,
      "name": "Rock_Volcanic_Cobble"
    },
    {
      "x": -14,
      "y": 12,
      "z": 7,
      "name": "Rock_Volcanic_Brick_Smooth"
    },
    {
      "x": -14,
      "y": 113,
      "z": 7,
      "name": "Rock_Sandstone_Brick_Smooth"
    },
    {
      "x": -14,
      "y": 121,
      "z": 7,
      "name": "Rock_Sandstone_Brick_Smooth"
    },
    {
      "x": -14,
      "y": 129,
      "z": 7,
      "name": "Rock_Sandstone_Brick_Smooth"
    },
    {
      "x": -14,
      "y": 130,
      "z": 7,
      "name": "Rock_Sandstone"
    },
    {
      "x": -14,
      "y": 0,
      "z": 8,
      "name": "Rock_Volcanic_Cracked_Lava"
    },
    {
      "x": -14,
      "y": 1,
      "z": 8,
      "name": "Rock_Volcanic_Cobble"
    },
    {
      "x": -14,
      "y": 2,
      "z": 8,
      "name": "Rock_Volcanic_Cobble"
    },
    {
      "x": -14,
      "y": 12,
      "z": 8,
      "name": "Rock_Volcanic_Brick_Smooth"
    },
    {
      "x": -14,
      "y": 113,
      "z": 8,
      "name": "Rock_Sandstone_Brick_Smooth"
    },
    {
      "x": -14,
      "y": 121,
      "z": 8,
      "name": "Rock_Sandstone_Brick_Smooth"
    },
    {
      "x": -14,
      "y": 129,
      "z": 8,
      "name": "Rock_Sandstone_Brick_Smooth"
    },
    {
      "x": -14,
      "y": 130,
      "z": 8,
      "name": "Rock_Sandstone"
    },
    {
      "x": -14,
      "y": 0,
      "z": 9,
      "name": "Rock_Volcanic_Cracked_Lava"
    },
    {
      "x": -14,
      "y": 1,
      "z": 9,
      "name": "Rock_Volcanic_Cobble"
    },
    {
      "x": -14,
      "y": 2,
      "z": 9,
      "name": "Rock_Volcanic_Cobble"
    },
    {
      "x": -14,
      "y": 12,
      "z": 9,
      "name": "Rock_Volcanic_Brick_Smooth"
    },
    {
      "x": -14,
      "y": 113,
      "z": 9,
      "name": "Rock_Sandstone_Brick_Smooth"
    },
    {
      "x": -14,
      "y": 121,
      "z": 9,
      "name": "Rock_Sandstone_Brick_Smooth"
    },
    {
      "x": -14,
      "y": 129,
      "z": 9,
      "name": "Rock_Sandstone_Brick_Smooth"
    },
    {
      "x": -14,
      "y": 130,
      "z": 9,
      "name": "Rock_Sandstone"
    },
    {
      "x": -14,
      "y": 0,
      "z": 10,
      "name": "Rock_Volcanic_Cracked_Lava"
    },
    {
      "x": -14,
      "y": 1,
      "z": 10,
      "name": "Rock_Volcanic_Cobble"
    },
    {
      "x": -14,
      "y": 2,
      "z": 10,
      "name": "Rock_Volcanic_Cobble"
    },
    {
      "x": -14,
      "y": 3,
      "z": 10,
      "name": "Rock_Volcanic_Brick_Smooth"
    },
    {
      "x": -14,
      "y": 4,
      "z": 10,
      "name": "Rock_Volcanic_Brick_Ornate"
    },
    {
      "x": -14,
      "y": 5,
      "z": 10,
      "name": "Rock_Volcanic_Brick_Decorative"
    },
    {
      "x": -14,
      "y": 6,
      "z": 10,
      "name": "Rock_Volcanic_Brick_Decorative"
    },
    {
      "x": -14,
      "y": 7,
      "z": 10,
      "name": "Rock_Volcanic_Brick_Decorative"
    },
    {
      "x": -14,
      "y": 8,
      "z": 10,
      "name": "Rock_Volcanic_Brick_Ornate"
    },
    {
      "x": -14,
      "y": 9,
      "z": 10,
      "name": "Rock_Volcanic_Brick"
    },
    {
      "x": -14,
      "y": 10,
      "z": 10,
      "name": "Rock_Volcanic_Brick"
    },
    {
      "x": -14,
      "y": 11,
      "z": 10,
      "name": "Rock_Volcanic_Brick"
    },
    {
      "x": -14,
      "y": 12,
      "z": 10,
      "name": "Rock_Volcanic_Brick_Smooth"
    },
    {
      "x": -14,
      "y": 13,
      "z": 10,
      "name": "Rock_Volcanic_Brick"
    },
    {
      "x": -14,
      "y": 14,
      "z": 10,
      "name": "Rock_Volcanic_Brick"
    },
    {
      "x": -14,
      "y": 15,
      "z": 10,
      "name": "Rock_Volcanic_Brick_Ornate"
    },
    {
      "x": -14,
      "y": 16,
      "z": 10,
      "name": "Rock_Volcanic_Brick_Decorative"
    },
    {
      "x": -14,
      "y": 17,
      "z": 10,
      "name": "Rock_Volcanic_Brick_Decorative"
    },
    {
      "x": -14,
      "y": 18,
      "z": 10,
      "name": "Rock_Volcanic_Brick_Decorative"
    },
    {
      "x": -14,
      "y": 19,
      "z": 10,
      "name": "Rock_Volcanic_Brick_Ornate"
    },
    {
      "x": -14,
      "y": 20,
      "z": 10,
      "name": "Rock_Volcanic_Brick"
    },
    {
      "x": -14,
      "y": 21,
      "z": 10,
      "name": "Rock_Volcanic_Brick_Smooth"
    },
    {
      "x": -14,
      "y": 111,
      "z": 10,
      "name": "Rock_Sandstone_Brick_Ornate"
    },
    {
      "x": -14,
      "y": 112,
      "z": 10,
      "name": "Rock_Sandstone_Brick"
    },
    {
      "x": -14,
      "y": 113,
      "z": 10,
      "name": "Rock_Sandstone_Brick_Smooth"
    },
    {
      "x": -14,
      "y": 114,
      "z": 10,
      "name": "Rock_Sandstone_Brick"
    },
    {
      "x": -14,
      "y": 115,
      "z": 10,
      "name": "Rock_Sandstone_Brick_Ornate"
    },
    {
      "x": -14,
      "y": 116,
      "z": 10,
      "name": "Rock_Sandstone_Brick_Decorative"
    },
    {
      "x": -14,
      "y": 117,
      "z": 10,
      "name": "Rock_Sandstone_Brick_Decorative"
    },
    {
      "x": -14,
      "y": 118,
      "z": 10,
      "name": "Rock_Sandstone_Brick_Decorative"
    },
    {
      "x": -14,
      "y": 119,
      "z": 10,
      "name": "Rock_Sandstone_Brick_Ornate"
    },
    {
      "x": -14,
      "y": 120,
      "z": 10,
      "name": "Rock_Sandstone_Brick"
    },
    {
      "x": -14,
      "y": 121,
      "z": 10,
      "name": "Rock_Sandstone_Brick_Smooth"
    },
    {
      "x": -14,
      "y": 122,
      "z": 10,
      "name": "Rock_Sandstone_Brick"
    },
    {
      "x": -14,
      "y": 123,
      "z": 10,
      "name": "Rock_Sandstone_Brick_Ornate"
    },
    {
      "x": -14,
      "y": 124,
      "z": 10,
      "name": "Rock_Sandstone_Brick_Decorative"
    },
    {
      "x": -14,
      "y": 125,
      "z": 10,
      "name": "Rock_Sandstone_Brick_Decorative"
    },
    {
      "x": -14,
      "y": 126,
      "z": 10,
      "name": "Rock_Sandstone_Brick_Decorative"
    },
    {
      "x": -14,
      "y": 127,
      "z": 10,
      "name": "Rock_Sandstone_Brick_Ornate"
    },
    {
      "x": -14,
      "y": 128,
      "z": 10,
      "name": "Rock_Sandstone_Brick"
    },
    {
      "x": -14,
      "y": 129,
      "z": 10,
      "name": "Rock_Sandstone_Brick_Smooth"
    },
    {
      "x": -14,
      "y": 130,
      "z": 10,
      "name": "Rock_Sandstone"
    },
    {
      "x": -14,
      "y": 0,
      "z": 11,
      "name": "Rock_Volcanic"
    },
    {
      "x": -14,
      "y": 1,
      "z": 11,
      "name": "Rock_Volcanic_Cobble"
    },
    {
      "x": -14,
      "y": 2,
      "z": 11,
      "name": "Rock_Volcanic_Cobble"
    },
    {
      "x": -14,
      "y": 12,
      "z": 11,
      "name": "Rock_Volcanic_Brick_Smooth"
    },
    {
      "x": -14,
      "y": 113,
      "z": 11,
      "name": "Rock_Sandstone_Brick_Smooth"
    },
    {
      "x": -14,
      "y": 121,
      "z": 11,
      "name": "Rock_Sandstone_Brick_Smooth"
    },
    {
      "x": -14,
      "y": 129,
      "z": 11,
      "name": "Rock_Sandstone_Brick_Smooth"
    },
    {
      "x": -14,
      "y": 130,
      "z": 11,
      "name": "Rock_Sandstone"
    },
    {
      "x": -14,
      "y": 0,
      "z": 12,
      "name": "Rock_Volcanic"
    },
    {
      "x": -14,
      "y": 1,
      "z": 12,
      "name": "Rock_Volcanic_Cobble"
    },
    {
      "x": -14,
      "y": 2,
      "z": 12,
      "name": "Rock_Volcanic_Cobble"
    },
    {
      "x": -14,
      "y": 12,
      "z": 12,
      "name": "Rock_Volcanic_Brick_Smooth"
    },
    {
      "x": -14,
      "y": 113,
      "z": 12,
      "name": "Rock_Sandstone_Brick_Smooth"
    },
    {
      "x": -14,
      "y": 121,
      "z": 12,
      "name": "Rock_Sandstone_Brick_Smooth"
    },
    {
      "x": -14,
      "y": 129,
      "z": 12,
      "name": "Rock_Sandstone_Brick_Smooth"
    },
    {
      "x": -14,
      "y": 130,
      "z": 12,
      "name": "Rock_Sandstone"
    },
    {
      "x": -14,
      "y": 0,
      "z": 13,
      "name": "Rock_Volcanic"
    },
    {
      "x": -14,
      "y": 1,
      "z": 13,
      "name": "Rock_Volcanic_Cobble"
    },
    {
      "x": -14,
      "y": 2,
      "z": 13,
      "name": "Rock_Volcanic_Cobble"
    },
    {
      "x": -14,
      "y": 12,
      "z": 13,
      "name": "Rock_Volcanic_Brick_Smooth"
    },
    {
      "x": -14,
      "y": 113,
      "z": 13,
      "name": "Rock_Sandstone_Brick_Smooth"
    },
    {
      "x": -14,
      "y": 121,
      "z": 13,
      "name": "Rock_Sandstone_Brick_Smooth"
    },
    {
      "x": -14,
      "y": 129,
      "z": 13,
      "name": "Rock_Sandstone_Brick_Smooth"
    },
    {
      "x": -14,
      "y": 130,
      "z": 13,
      "name": "Rock_Sandstone"
    },
    {
      "x": -14,
      "y": 0,
      "z": 14,
      "name": "Rock_Volcanic_Cracked_Lava"
    },
    {
      "x": -14,
      "y": 1,
      "z": 14,
      "name": "Rock_Volcanic_Cobble"
    },
    {
      "x": -14,
      "y": 2,
      "z": 14,
      "name": "Rock_Volcanic_Cobble"
    },
    {
      "x": -14,
      "y": 3,
      "z": 14,
      "name": "Rubble_Volcanic_Medium"
    },
    {
      "x": -14,
      "y": 12,
      "z": 14,
      "name": "Rock_Volcanic_Brick_Smooth"
    },
    {
      "x": -14,
      "y": 113,
      "z": 14,
      "name": "Rock_Sandstone_Brick_Smooth"
    },
    {
      "x": -14,
      "y": 121,
      "z": 14,
      "name": "Rock_Sandstone_Brick_Smooth"
    },
    {
      "x": -14,
      "y": 129,
      "z": 14,
      "name": "Rock_Sandstone_Brick_Smooth"
    },
    {
      "x": -14,
      "y": 130,
      "z": 14,
      "name": "Rock_Sandstone"
    },
    {
      "x": -14,
      "y": 0,
      "z": 15,
      "name": "Rock_Volcanic"
    },
    {
      "x": -14,
      "y": 1,
      "z": 15,
      "name": "Rock_Volcanic_Cobble"
    },
    {
      "x": -14,
      "y": 2,
      "z": 15,
      "name": "Rock_Volcanic_Cobble"
    },
    {
      "x": -14,
      "y": 12,
      "z": 15,
      "name": "Rock_Volcanic_Brick_Smooth"
    },
    {
      "x": -14,
      "y": 113,
      "z": 15,
      "name": "Rock_Sandstone_Brick_Smooth"
    },
    {
      "x": -14,
      "y": 121,
      "z": 15,
      "name": "Rock_Sandstone_Brick_Smooth"
    },
    {
      "x": -14,
      "y": 129,
      "z": 15,
      "name": "Rock_Sandstone_Brick_Smooth"
    },
    {
      "x": -14,
      "y": 130,
      "z": 15,
      "name": "Rock_Sandstone"
    },
    {
      "x": -13,
      "y": 0,
      "z": -15,
      "name": "Rock_Volcanic"
    },
    {
      "x": -13,
      "y": 1,
      "z": -15,
      "name": "Rock_Volcanic_Cobble"
    },
    {
      "x": -13,
      "y": 2,
      "z": -15,
      "name": "Rock_Volcanic_Cobble"
    },
    {
      "x": -13,
      "y": 12,
      "z": -15,
      "name": "Rock_Volcanic_Brick_Smooth"
    },
    {
      "x": -13,
      "y": 113,
      "z": -15,
      "name": "Rock_Sandstone_Brick_Smooth"
    },
    {
      "x": -13,
      "y": 121,
      "z": -15,
      "name": "Rock_Sandstone_Brick_Smooth"
    },
    {
      "x": -13,
      "y": 129,
      "z": -15,
      "name": "Rock_Sandstone_Brick_Smooth"
    },
    {
      "x": -13,
      "y": 130,
      "z": -15,
      "name": "Rock_Sandstone"
    },
    {
      "x": -13,
      "y": 0,
      "z": -14,
      "name": "Rock_Volcanic"
    },
    {
      "x": -13,
      "y": 1,
      "z": -14,
      "name": "Rock_Volcanic_Cobble"
    },
    {
      "x": -13,
      "y": 2,
      "z": -14,
      "name": "Rock_Volcanic_Cobble"
    },
    {
      "x": -13,
      "y": 12,
      "z": -14,
      "name": "Rock_Volcanic_Brick_Smooth"
    },
    {
      "x": -13,
      "y": 113,
      "z": -14,
      "name": "Rock_Sandstone_Brick_Smooth"
    },
    {
      "x": -13,
      "y": 121,
      "z": -14,
      "name": "Rock_Sandstone_Brick_Smooth"
    },
    {
      "x": -13,
      "y": 129,
      "z": -14,
      "name": "Rock_Sandstone_Brick_Smooth"
    },
    {
      "x": -13,
      "y": 130,
      "z": -14,
      "name": "Rock_Sandstone"
    },
    {
      "x": -13,
      "y": 0,
      "z": -13,
      "name": "Rock_Volcanic"
    },
    {
      "x": -13,
      "y": 1,
      "z": -13,
      "name": "Rock_Volcanic_Cobble"
    },
    {
      "x": -13,
      "y": 2,
      "z": -13,
      "name": "Rock_Volcanic_Cobble"
    },
    {
      "x": -13,
      "y": 12,
      "z": -13,
      "name": "Rock_Volcanic_Brick_Smooth"
    },
    {
      "x": -13,
      "y": 113,
      "z": -13,
      "name": "Rock_Sandstone_Brick_Smooth"
    },
    {
      "x": -13,
      "y": 121,
      "z": -13,
      "name": "Rock_Sandstone_Brick_Smooth"
    },
    {
      "x": -13,
      "y": 129,
      "z": -13,
      "name": "Rock_Sandstone_Brick_Smooth"
    },
    {
      "x": -13,
      "y": 130,
      "z": -13,
      "name": "Rock_Sandstone"
    },
    {
      "x": -13,
      "y": 0,
      "z": -12,
      "name": "Rock_Volcanic"
    },
    {
      "x": -13,
      "y": 1,
      "z": -12,
      "name": "Rock_Volcanic_Cobble"
    },
    {
      "x": -13,
      "y": 2,
      "z": -12,
      "name": "Rock_Volcanic_Cobble"
    },
    {
      "x": -13,
      "y": 12,
      "z": -12,
      "name": "Rock_Volcanic_Brick_Smooth"
    },
    {
      "x": -13,
      "y": 113,
      "z": -12,
      "name": "Rock_Sandstone_Brick_Smooth"
    },
    {
      "x": -13,
      "y": 114,
      "z": -12,
      "name": "Furniture_Village_Pot"
    },
    {
      "x": -13,
      "y": 121,
      "z": -12,
      "name": "Rock_Sandstone_Brick_Smooth"
    },
    {
      "x": -13,
      "y": 129,
      "z": -12,
      "name": "Rock_Sandstone_Brick_Smooth"
    },
    {
      "x": -13,
      "y": 130,
      "z": -12,
      "name": "Rock_Sandstone"
    },
    {
      "x": -13,
      "y": 0,
      "z": -11,
      "name": "Rock_Volcanic"
    },
    {
      "x": -13,
      "y": 1,
      "z": -11,
      "name": "Rock_Volcanic_Cobble"
    },
    {
      "x": -13,
      "y": 2,
      "z": -11,
      "name": "Rock_Volcanic_Cobble"
    },
    {
      "x": -13,
      "y": 3,
      "z": -11,
      "name": "Rock_Volcanic_Brick_Smooth"
    },
    {
      "x": -13,
      "y": 4,
      "z": -11,
      "name": "Rock_Volcanic_Brick_Ornate"
    },
    {
      "x": -13,
      "y": 5,
      "z": -11,
      "name": "Rock_Volcanic_Brick_Decorative"
    },
    {
      "x": -13,
      "y": 6,
      "z": -11,
      "name": "Rock_Volcanic_Brick_Decorative"
    },
    {
      "x": -13,
      "y": 7,
      "z": -11,
      "name": "Rock_Volcanic_Brick_Decorative"
    },
    {
      "x": -13,
      "y": 8,
      "z": -11,
      "name": "Rock_Volcanic_Brick_Ornate"
    },
    {
      "x": -13,
      "y": 9,
      "z": -11,
      "name": "Rock_Volcanic_Brick"
    },
    {
      "x": -13,
      "y": 10,
      "z": -11,
      "name": "Rock_Volcanic_Brick"
    },
    {
      "x": -13,
      "y": 11,
      "z": -11,
      "name": "Rock_Volcanic_Brick"
    },
    {
      "x": -13,
      "y": 12,
      "z": -11,
      "name": "Rock_Volcanic_Brick_Smooth"
    },
    {
      "x": -13,
      "y": 13,
      "z": -11,
      "name": "Rock_Volcanic_Brick"
    },
    {
      "x": -13,
      "y": 14,
      "z": -11,
      "name": "Rock_Volcanic_Brick"
    },
    {
      "x": -13,
      "y": 15,
      "z": -11,
      "name": "Rock_Volcanic_Brick_Ornate"
    },
    {
      "x": -13,
      "y": 16,
      "z": -11,
      "name": "Rock_Volcanic_Brick_Decorative"
    },
    {
      "x": -13,
      "y": 17,
      "z": -11,
      "name": "Rock_Volcanic_Brick_Decorative"
    },
    {
      "x": -13,
      "y": 18,
      "z": -11,
      "name": "Rock_Volcanic_Brick_Decorative"
    },
    {
      "x": -13,
      "y": 19,
      "z": -11,
      "name": "Rock_Volcanic_Brick_Ornate"
    },
    {
      "x": -13,
      "y": 20,
      "z": -11,
      "name": "Rock_Volcanic_Brick"
    },
    {
      "x": -13,
      "y": 21,
      "z": -11,
      "name": "Rock_Volcanic_Brick_Smooth"
    },
    {
      "x": -13,
      "y": 111,
      "z": -11,
      "name": "Rock_Sandstone_Brick_Ornate"
    },
    {
      "x": -13,
      "y": 112,
      "z": -11,
      "name": "Rock_Sandstone_Brick"
    },
    {
      "x": -13,
      "y": 113,
      "z": -11,
      "name": "Rock_Sandstone_Brick_Smooth"
    },
    {
      "x": -13,
      "y": 114,
      "z": -11,
      "name": "Rock_Sandstone_Brick"
    },
    {
      "x": -13,
      "y": 115,
      "z": -11,
      "name": "Rock_Sandstone_Brick_Ornate"
    },
    {
      "x": -13,
      "y": 116,
      "z": -11,
      "name": "Rock_Sandstone_Brick_Decorative"
    },
    {
      "x": -13,
      "y": 117,
      "z": -11,
      "name": "Rock_Sandstone_Brick_Decorative"
    },
    {
      "x": -13,
      "y": 118,
      "z": -11,
      "name": "Rock_Sandstone_Brick_Decorative"
    },
    {
      "x": -13,
      "y": 119,
      "z": -11,
      "name": "Rock_Sandstone_Brick_Ornate"
    },
    {
      "x": -13,
      "y": 120,
      "z": -11,
      "name": "Rock_Sandstone_Brick"
    },
    {
      "x": -13,
      "y": 121,
      "z": -11,
      "name": "Rock_Sandstone_Brick_Smooth"
    },
    {
      "x": -13,
      "y": 122,
      "z": -11,
      "name": "Rock_Sandstone_Brick"
    },
    {
      "x": -13,
      "y": 123,
      "z": -11,
      "name": "Rock_Sandstone_Brick_Ornate"
    },
    {
      "x": -13,
      "y": 124,
      "z": -11,
      "name": "Rock_Sandstone_Brick_Decorative"
    },
    {
      "x": -13,
      "y": 125,
      "z": -11,
      "name": "Rock_Sandstone_Brick_Decorative"
    },
    {
      "x": -13,
      "y": 126,
      "z": -11,
      "name": "Rock_Sandstone_Brick_Decorative"
    },
    {
      "x": -13,
      "y": 127,
      "z": -11,
      "name": "Rock_Sandstone_Brick_Ornate"
    },
    {
      "x": -13,
      "y": 128,
      "z": -11,
      "name": "Rock_Sandstone_Brick"
    },
    {
      "x": -13,
      "y": 129,
      "z": -11,
      "name": "Rock_Sandstone_Brick_Smooth",
      "rotation": 1
    },
    {
      "x": -13,
      "y": 130,
      "z": -11,
      "name": "Rock_Sandstone",
      "rotation": 1
    },
    {
      "x": -13,
      "y": 0,
      "z": -10,
      "name": "Rock_Volcanic"
    },
    {
      "x": -13,
      "y": 1,
      "z": -10,
      "name": "Rock_Volcanic_Cobble"
    },
    {
      "x": -13,
      "y": 2,
      "z": -10,
      "name": "Rock_Volcanic_Cobble"
    },
    {
      "x": -13,
      "y": 3,
      "z": -10,
      "name": "Rock_Volcanic"
    },
    {
      "x": -13,
      "y": 4,
      "z": -10,
      "name": "Rock_Volcanic_Brick_Ornate"
    },
    {
      "x": -13,
      "y": 5,
      "z": -10,
      "name": "Rock_Volcanic_Brick_Decorative"
    },
    {
      "x": -13,
      "y": 6,
      "z": -10,
      "name": "Rock_Volcanic_Brick_Decorative"
    },
    {
      "x": -13,
      "y": 7,
      "z": -10,
      "name": "Rock_Volcanic_Brick_Decorative"
    },
    {
      "x": -13,
      "y": 8,
      "z": -10,
      "name": "Rock_Volcanic_Brick_Ornate"
    },
    {
      "x": -13,
      "y": 9,
      "z": -10,
      "name": "Rock_Volcanic_Brick"
    },
    {
      "x": -13,
      "y": 10,
      "z": -10,
      "name": "Rock_Volcanic_Brick"
    },
    {
      "x": -13,
      "y": 11,
      "z": -10,
      "name": "Rock_Volcanic_Brick"
    },
    {
      "x": -13,
      "y": 12,
      "z": -10,
      "name": "Rock_Volcanic_Brick_Smooth"
    },
    {
      "x": -13,
      "y": 13,
      "z": -10,
      "name": "Rock_Volcanic_Brick"
    },
    {
      "x": -13,
      "y": 14,
      "z": -10,
      "name": "Rock_Volcanic_Brick"
    },
    {
      "x": -13,
      "y": 15,
      "z": -10,
      "name": "Rock_Volcanic_Brick_Ornate"
    },
    {
      "x": -13,
      "y": 16,
      "z": -10,
      "name": "Rock_Volcanic_Brick_Decorative"
    },
    {
      "x": -13,
      "y": 17,
      "z": -10,
      "name": "Rock_Volcanic_Brick_Decorative"
    },
    {
      "x": -13,
      "y": 18,
      "z": -10,
      "name": "Rock_Volcanic_Brick_Decorative"
    },
    {
      "x": -13,
      "y": 19,
      "z": -10,
      "name": "Rock_Volcanic_Brick_Ornate"
    },
    {
      "x": -13,
      "y": 20,
      "z": -10,
      "name": "Rock_Volcanic_Brick"
    },
    {
      "x": -13,
      "y": 21,
      "z": -10,
      "name": "Rock_Volcanic_Brick_Smooth"
    },
    {
      "x": -13,
      "y": 111,
      "z": -10,
      "name": "Rock_Sandstone_Brick_Ornate"
    },
    {
      "x": -13,
      "y": 112,
      "z": -10,
      "name": "Rock_Sandstone_Brick"
    },
    {
      "x": -13,
      "y": 113,
      "z": -10,
      "name": "Rock_Sandstone_Brick_Smooth"
    },
    {
      "x": -13,
      "y": 114,
      "z": -10,
      "name": "Rock_Sandstone_Brick"
    },
    {
      "x": -13,
      "y": 115,
      "z": -10,
      "name": "Rock_Sandstone_Brick_Ornate"
    },
    {
      "x": -13,
      "y": 116,
      "z": -10,
      "name": "Rock_Sandstone_Brick_Decorative"
    },
    {
      "x": -13,
      "y": 117,
      "z": -10,
      "name": "Rock_Sandstone_Brick_Decorative"
    },
    {
      "x": -13,
      "y": 118,
      "z": -10,
      "name": "Rock_Sandstone_Brick_Decorative"
    },
    {
      "x": -13,
      "y": 119,
      "z": -10,
      "name": "Rock_Sandstone_Brick_Ornate"
    },
    {
      "x": -13,
      "y": 120,
      "z": -10,
      "name": "Rock_Sandstone_Brick"
    },
    {
      "x": -13,
      "y": 121,
      "z": -10,
      "name": "Rock_Sandstone_Brick_Smooth"
    },
    {
      "x": -13,
      "y": 122,
      "z": -10,
      "name": "Rock_Sandstone_Brick"
    },
    {
      "x": -13,
      "y": 123,
      "z": -10,
      "name": "Rock_Sandstone_Brick_Ornate"
    },
    {
      "x": -13,
      "y": 124,
      "z": -10,
      "name": "Rock_Sandstone_Brick_Decorative"
    },
    {
      "x": -13,
      "y": 125,
      "z": -10,
      "name": "Rock_Sandstone_Brick_Decorative"
    },
    {
      "x": -13,
      "y": 126,
      "z": -10,
      "name": "Rock_Sandstone_Brick_Decorative"
    },
    {
      "x": -13,
      "y": 127,
      "z": -10,
      "name": "Rock_Sandstone_Brick_Ornate"
    },
    {
      "x": -13,
      "y": 128,
      "z": -10,
      "name": "Rock_Sandstone_Brick"
    },
    {
      "x": -13,
      "y": 129,
      "z": -10,
      "name": "Rock_Sandstone_Brick_Smooth",
      "rotation": 1
    },
    {
      "x": -13,
      "y": 130,
      "z": -10,
      "name": "Rock_Sandstone",
      "rotation": 1
    },
    {
      "x": -13,
      "y": 0,
      "z": -9,
      "name": "Rock_Volcanic"
    },
    {
      "x": -13,
      "y": 1,
      "z": -9,
      "name": "Rock_Volcanic_Cobble"
    },
    {
      "x": -13,
      "y": 2,
      "z": -9,
      "name": "Rock_Volcanic_Cobble"
    },
    {
      "x": -13,
      "y": 3,
      "z": -9,
      "name": "Rock_Volcanic"
    },
    {
      "x": -13,
      "y": 4,
      "z": -9,
      "name": "Rock_Volcanic"
    },
    {
      "x": -13,
      "y": 5,
      "z": -9,
      "name": "Rock_Volcanic"
    },
    {
      "x": -13,
      "y": 12,
      "z": -9,
      "name": "Rock_Volcanic_Brick_Smooth"
    },
    {
      "x": -13,
      "y": 17,
      "z": -9,
      "name": "Deco_SpiderWeb_Flat",
      "rotation": 7
    },
    {
      "x": -13,
      "y": 113,
      "z": -9,
      "name": "Rock_Sandstone_Brick_Smooth"
    },
    {
      "x": -13,
      "y": 121,
      "z": -9,
      "name": "Rock_Sandstone_Brick_Smooth"
    },
    {
      "x": -13,
      "y": 129,
      "z": -9,
      "name": "Rock_Sandstone_Brick_Smooth",
      "rotation": 1
    },
    {
      "x": -13,
      "y": 130,
      "z": -9,
      "name": "Rock_Sandstone",
      "rotation": 1
    },
    {
      "x": -13,
      "y": 0,
      "z": -8,
      "name": "Rock_Volcanic"
    },
    {
      "x": -13,
      "y": 1,
      "z": -8,
      "name": "Rock_Volcanic_Cobble"
    },
    {
      "x": -13,
      "y": 2,
      "z": -8,
      "name": "Rock_Volcanic_Cobble"
    },
    {
      "x": -13,
      "y": 3,
      "z": -8,
      "name": "Rock_Volcanic"
    },
    {
      "x": -13,
      "y": 4,
      "z": -8,
      "name": "Rock_Volcanic"
    },
    {
      "x": -13,
      "y": 5,
      "z": -8,
      "name": "Rock_Volcanic"
    },
    {
      "x": -13,
      "y": 6,
      "z": -8,
      "name": "Rock_Volcanic"
    },
    {
      "x": -13,
      "y": 12,
      "z": -8,
      "name": "Rock_Volcanic_Brick_Smooth"
    },
    {
      "x": -13,
      "y": 113,
      "z": -8,
      "name": "Rock_Sandstone_Brick_Smooth"
    },
    {
      "x": -13,
      "y": 121,
      "z": -8,
      "name": "Rock_Sandstone_Brick_Smooth"
    },
    {
      "x": -13,
      "y": 129,
      "z": -8,
      "name": "Rock_Sandstone_Brick_Smooth",
      "rotation": 1
    },
    {
      "x": -13,
      "y": 130,
      "z": -8,
      "name": "Rock_Sandstone",
      "rotation": 1
    },
    {
      "x": -13,
      "y": 0,
      "z": -7,
      "name": "Rock_Volcanic"
    },
    {
      "x": -13,
      "y": 1,
      "z": -7,
      "name": "Rock_Volcanic_Cobble"
    },
    {
      "x": -13,
      "y": 2,
      "z": -7,
      "name": "Rock_Volcanic_Cobble"
    },
    {
      "x": -13,
      "y": 3,
      "z": -7,
      "name": "Rock_Volcanic"
    },
    {
      "x": -13,
      "y": 4,
      "z": -7,
      "name": "Rock_Volcanic_Cracked_Poisoned"
    },
    {
      "x": -13,
      "y": 5,
      "z": -7,
      "name": "Rock_Volcanic"
    },
    {
      "x": -13,
      "y": 12,
      "z": -7,
      "name": "Rock_Volcanic_Brick_Smooth"
    },
    {
      "x": -13,
      "y": 13,
      "z": -7,
      "name": "Rubble_Volcanic_Medium"
    },
    {
      "x": -13,
      "y": 113,
      "z": -7,
      "name": "Rock_Sandstone_Brick_Smooth"
    },
    {
      "x": -13,
      "y": 121,
      "z": -7,
      "name": "Rock_Sandstone_Brick_Smooth"
    },
    {
      "x": -13,
      "y": 129,
      "z": -7,
      "name": "Rock_Sandstone_Brick_Smooth",
      "rotation": 1
    },
    {
      "x": -13,
      "y": 130,
      "z": -7,
      "name": "Rock_Sandstone",
      "rotation": 1
    },
    {
      "x": -13,
      "y": 0,
      "z": -6,
      "name": "Rock_Volcanic"
    },
    {
      "x": -13,
      "y": 1,
      "z": -6,
      "name": "Rock_Volcanic_Cobble"
    },
    {
      "x": -13,
      "y": 2,
      "z": -6,
      "name": "Rock_Volcanic_Cobble"
    },
    {
      "x": -13,
      "y": 3,
      "z": -6,
      "name": "Rock_Volcanic"
    },
    {
      "x": -13,
      "y": 12,
      "z": -6,
      "name": "Rock_Volcanic_Brick_Smooth"
    },
    {
      "x": -13,
      "y": 13,
      "z": -6,
      "name": "Furniture_Ancient_Crate",
      "rotation": 2
    },
    {
      "x": -13,
      "y": 16,
      "z": -6,
      "name": "Deco_SpiderWeb_Flat",
      "rotation": 7
    },
    {
      "x": -13,
      "y": 113,
      "z": -6,
      "name": "Rock_Sandstone_Brick_Smooth"
    },
    {
      "x": -13,
      "y": 121,
      "z": -6,
      "name": "Rock_Sandstone_Brick_Smooth"
    },
    {
      "x": -13,
      "y": 129,
      "z": -6,
      "name": "Rock_Sandstone_Brick_Smooth",
      "rotation": 1
    },
    {
      "x": -13,
      "y": 130,
      "z": -6,
      "name": "Rock_Sandstone",
      "rotation": 1
    },
    {
      "x": -13,
      "y": 0,
      "z": -5,
      "name": "Rock_Volcanic"
    },
    {
      "x": -13,
      "y": 1,
      "z": -5,
      "name": "Rock_Volcanic_Cobble"
    },
    {
      "x": -13,
      "y": 2,
      "z": -5,
      "name": "Rock_Volcanic_Cobble"
    },
    {
      "x": -13,
      "y": 3,
      "z": -5,
      "name": "Rock_Volcanic"
    },
    {
      "x": -13,
      "y": 4,
      "z": -5,
      "name": "Rock_Volcanic_Brick_Ornate",
      "rotation": 1
    },
    {
      "x": -13,
      "y": 5,
      "z": -5,
      "name": "Rock_Volcanic_Brick_Decorative",
      "rotation": 1
    },
    {
      "x": -13,
      "y": 6,
      "z": -5,
      "name": "Rock_Volcanic_Brick_Decorative",
      "rotation": 1
    },
    {
      "x": -13,
      "y": 7,
      "z": -5,
      "name": "Rock_Volcanic_Brick_Decorative",
      "rotation": 1
    },
    {
      "x": -13,
      "y": 8,
      "z": -5,
      "name": "Rock_Volcanic_Brick_Ornate",
      "rotation": 1
    },
    {
      "x": -13,
      "y": 9,
      "z": -5,
      "name": "Rock_Volcanic_Brick",
      "rotation": 1
    },
    {
      "x": -13,
      "y": 10,
      "z": -5,
      "name": "Rock_Volcanic_Brick",
      "rotation": 1
    },
    {
      "x": -13,
      "y": 11,
      "z": -5,
      "name": "Rock_Volcanic_Brick",
      "rotation": 1
    },
    {
      "x": -13,
      "y": 12,
      "z": -5,
      "name": "Rock_Volcanic_Brick_Smooth",
      "rotation": 1
    },
    {
      "x": -13,
      "y": 13,
      "z": -5,
      "name": "Rock_Volcanic_Brick",
      "rotation": 1
    },
    {
      "x": -13,
      "y": 14,
      "z": -5,
      "name": "Rock_Volcanic_Brick",
      "rotation": 1
    },
    {
      "x": -13,
      "y": 15,
      "z": -5,
      "name": "Rock_Volcanic_Brick_Ornate",
      "rotation": 1
    },
    {
      "x": -13,
      "y": 16,
      "z": -5,
      "name": "Rock_Volcanic_Brick_Decorative",
