{
  "version": 8,
  "blockIdVersion": 11,
  "anchorX": 0,
  "anchorY": 0,
  "anchorZ": 0,
  "blocks": [
    {
      "x": -66,
      "y": 16,
      "z": 7,
      "name": "Rock_Ice_Permafrost"
    },
    {
      "x": -66,
      "y": 17,
      "z": 7,
      "name": "Rock_Ice_Permafrost"
    },
    {
      "x": -66,
      "y": 17,
      "z": 8,
      "name": "Rock_Ice_Permafrost"
    },
    {
      "x": -65,
      "y": 16,
      "z": 7,
      "name": "Rock_Ice_Permafrost"
    },
    {
      "x": -65,
      "y": 17,
      "z": 7,
      "name": "Rock_Ice_Permafrost"
    },
    {
      "x": -65,
      "y": 16,
      "z": 8,
      "name": "Rock_Ice_Permafrost"
    },
    {
      "x": -65,
      "y": 17,
      "z": 8,
      "name": "Rock_Ice_Permafrost"
    },
    {
      "x": -64,
      "y": 15,
      "z": 7,
      "name": "Rock_Ice_Permafrost"
    },
    {
      "x": -64,
      "y": 16,
      "z": 7,
      "name": "Rock_Ice_Permafrost"
    },
    {
      "x": -64,
      "y": 16,
      "z": 8,
      "name": "Rock_Ice_Permafrost"
    },
    {
      "x": -63,
      "y": 26,
      "z": -9,
      "name": "Rock_Ice_Permafrost"
    },
    {
      "x": -63,
      "y": 27,
      "z": -9,
      "name": "Rock_Ice_Permafrost"
    },
    {
      "x": -63,
      "y": 26,
      "z": -8,
      "name": "Rock_Ice_Permafrost"
    },
    {
      "x": -63,
      "y": 27,
      "z": -8,
      "name": "Rock_Ice_Permafrost"
    },
    {
      "x": -63,
      "y": 15,
      "z": 7,
      "name": "Rock_Ice_Permafrost"
    },
    {
      "x": -63,
      "y": 16,
      "z": 7,
      "name": "Rock_Ice_Permafrost"
    },
    {
      "x": -63,
      "y": 15,
      "z": 8,
      "name": "Rock_Ice_Permafrost"
    },
    {
      "x": -63,
      "y": 16,
      "z": 8,
      "name": "Rock_Ice_Permafrost"
    },
    {
      "x": -62,
      "y": 25,
      "z": -9,
      "name": "Rock_Ice_Permafrost"
    },
    {
      "x": -62,
      "y": 26,
      "z": -9,
      "name": "Rock_Ice_Permafrost"
    },
    {
      "x": -62,
      "y": 25,
      "z": -8,
      "name": "Rock_Ice_Permafrost"
    },
    {
      "x": -62,
      "y": 26,
      "z": -8,
      "name": "Rock_Ice_Permafrost"
    },
    {
      "x": -62,
      "y": 15,
      "z": 6,
      "name": "Rock_Ice_Permafrost"
    },
    {
      "x": -62,
      "y": 14,
      "z": 7,
      "name": "Rock_Ice_Permafrost"
    },
    {
      "x": -62,
      "y": 15,
      "z": 7,
      "name": "Rock_Ice_Permafrost"
    },
    {
      "x": -62,
      "y": 16,
      "z": 7,
      "name": "Rock_Ice_Permafrost"
    },
    {
      "x": -62,
      "y": 15,
      "z": 8,
      "name": "Rock_Ice_Permafrost"
    },
    {
      "x": -61,
      "y": 25,
      "z": -9,
      "name": "Rock_Ice_Permafrost"
    },
    {
      "x": -61,
      "y": 26,
      "z": -9,
      "name": "Rock_Ice_Permafrost"
    },
    {
      "x": -61,
      "y": 25,
      "z": -8,
      "name": "Rock_Ice_Permafrost"
    },
    {
      "x": -61,
      "y": 26,
      "z": -8,
      "name": "Rock_Ice_Permafrost"
    },
    {
      "x": -61,
      "y": 14,
      "z": 6,
      "name": "Rock_Ice_Permafrost"
    },
    {
      "x": -61,
      "y": 15,
      "z": 6,
      "name": "Rock_Ice_Permafrost"
    },
    {
      "x": -61,
      "y": 14,
      "z": 7,
      "name": "Rock_Ice_Permafrost"
    },
    {
      "x": -61,
      "y": 15,
      "z": 7,
      "name": "Rock_Ice_Permafrost"
    },
    {
      "x": -61,
      "y": 16,
      "z": 7,
      "name": "Rock_Ice_Permafrost"
    },
    {
      "x": -61,
      "y": 15,
      "z": 8,
      "name": "Rock_Ice_Permafrost"
    },
    {
      "x": -60,
      "y": 24,
      "z": -9,
      "name": "Rock_Ice_Permafrost"
    },
    {
      "x": -60,
      "y": 25,
      "z": -9,
      "name": "Rock_Ice_Permafrost"
    },
    {
      "x": -60,
      "y": 24,
      "z": -8,
      "name": "Rock_Ice_Permafrost"
    },
    {
      "x": -60,
      "y": 25,
      "z": -8,
      "name": "Rock_Ice_Permafrost"
    },
    {
      "x": -60,
      "y": 14,
      "z": 6,
      "name": "Rock_Ice_Permafrost"
    },
    {
      "x": -60,
      "y": 15,
      "z": 6,
      "name": "Rock_Ice_Permafrost"
    },
    {
      "x": -60,
      "y": 13,
      "z": 7,
      "name": "Rock_Ice_Permafrost"
    },
    {
      "x": -60,
      "y": 14,
      "z": 7,
      "name": "Rock_Ice_Permafrost"
    },
    {
      "x": -60,
      "y": 15,
      "z": 7,
      "name": "Rock_Ice_Permafrost"
    },
    {
      "x": -60,
      "y": 14,
      "z": 8,
      "name": "Rock_Ice_Permafrost"
    },
    {
      "x": -59,
      "y": 24,
      "z": -9,
      "name": "Rock_Ice_Permafrost"
    },
    {
      "x": -59,
      "y": 23,
      "z": -8,
      "name": "Rock_Ice_Permafrost"
    },
    {
      "x": -59,
      "y": 24,
      "z": -8,
      "name": "Rock_Ice_Permafrost"
    },
    {
      "x": -59,
      "y": 25,
      "z": -8,
      "name": "Rock_Ice_Permafrost"
    },
    {
      "x": -59,
      "y": 24,
      "z": -7,
      "name": "Rock_Ice_Permafrost"
    },
    {
      "x": -59,
      "y": 13,
      "z": 6,
      "name": "Rock_Ice_Permafrost"
    },
    {
      "x": -59,
      "y": 14,
      "z": 6,
      "name": "Rock_Ice_Permafrost"
    },
    {
      "x": -59,
      "y": 15,
      "z": 6,
      "name": "Rock_Ice_Permafrost"
    },
    {
      "x": -59,
      "y": 13,
      "z": 7,
      "name": "Rock_Ice_Permafrost"
    },
    {
      "x": -59,
      "y": 14,
      "z": 7,
      "name": "Rock_Ice_Permafrost"
    },
    {
      "x": -59,
      "y": 15,
      "z": 7,
      "name": "Rock_Ice_Permafrost"
    },
    {
      "x": -59,
      "y": 14,
      "z": 8,
      "name": "Rock_Ice_Permafrost"
    },
    {
      "x": -58,
      "y": 23,
      "z": -9,
      "name": "Rock_Ice_Permafrost"
    },
    {
      "x": -58,
      "y": 24,
      "z": -9,
      "name": "Rock_Ice_Permafrost"
    },
    {
      "x": -58,
      "y": 23,
      "z": -8,
      "name": "Rock_Ice_Permafrost"
    },
    {
      "x": -58,
      "y": 24,
      "z": -8,
      "name": "Rock_Ice_Permafrost"
    },
    {
      "x": -58,
      "y": 25,
      "z": -8,
      "name": "Rock_Ice_Permafrost"
    },
    {
      "x": -58,
      "y": 23,
      "z": -7,
      "name": "Rock_Ice_Permafrost"
    },
    {
      "x": -58,
      "y": 24,
      "z": -7,
      "name": "Rock_Ice_Permafrost"
    },
    {
      "x": -58,
      "y": 13,
      "z": 6,
      "name": "Rock_Ice_Permafrost"
    },
    {
      "x": -58,
      "y": 14,
      "z": 6,
      "name": "Rock_Ice_Permafrost"
    },
    {
      "x": -58,
      "y": 12,
      "z": 7,
      "name": "Rock_Ice_Permafrost"
    },
    {
      "x": -58,
      "y": 13,
      "z": 7,
      "name": "Rock_Ice_Permafrost"
    },
    {
      "x": -58,
      "y": 14,
      "z": 7,
      "name": "Rock_Ice_Permafrost"
    },
    {
      "x": -57,
      "y": 23,
      "z": -9,
      "name": "Rock_Ice_Permafrost"
    },
    {
      "x": -57,
      "y": 22,
      "z": -8,
      "name": "Rock_Ice_Permafrost"
    },
    {
      "x": -57,
      "y": 23,
      "z": -8,
      "name": "Rock_Ice_Permafrost"
    },
    {
      "x": -57,
      "y": 24,
      "z": -8,
      "name": "Rock_Ice_Permafrost"
    },
    {
      "x": -57,
      "y": 22,
      "z": -7,
      "name": "Rock_Ice_Permafrost"
    },
    {
      "x": -57,
      "y": 23,
      "z": -7,
      "name": "Rock_Ice_Permafrost"
    },
    {
      "x": -57,
      "y": 24,
      "z": -7,
      "name": "Rock_Ice_Permafrost"
    },
    {
      "x": -57,
      "y": 12,
      "z": 6,
      "name": "Rock_Ice_Permafrost"
    },
    {
      "x": -57,
      "y": 13,
      "z": 6,
      "name": "Rock_Ice_Permafrost"
    },
    {
      "x": -57,
      "y": 14,
      "z": 6,
      "name": "Rock_Ice_Permafrost"
    },
    {
      "x": -57,
      "y": 12,
      "z": 7,
      "name": "Rock_Ice_Permafrost"
    },
    {
      "x": -57,
      "y": 13,
      "z": 7,
      "name": "Rock_Ice_Permafrost"
    },
    {
      "x": -57,
      "y": 14,
      "z": 7,
      "name": "Rock_Ice_Permafrost"
    },
    {
      "x": -57,
      "y": 13,
      "z": 8,
      "name": "Rock_Ice_Permafrost"
    },
    {
      "x": -56,
      "y": 21,
      "z": -8,
      "name": "Rock_Ice_Permafrost"
    },
    {
      "x": -56,
      "y": 22,
      "z": -8,
      "name": "Rock_Ice_Permafrost"
    },
    {
      "x": -56,
      "y": 23,
      "z": -8,
      "name": "Rock_Ice_Permafrost"
    },
    {
      "x": -56,
      "y": 24,
      "z": -8,
      "name": "Rock_Ice_Permafrost"
    },
    {
      "x": -56,
      "y": 21,
      "z": -7,
      "name": "Rock_Ice_Permafrost"
    },
    {
      "x": -56,
      "y": 22,
      "z": -7,
      "name": "Rock_Ice_Permafrost"
    },
    {
      "x": -56,
      "y": 23,
      "z": -7,
      "name": "Rock_Ice_Permafrost"
    },
    {
      "x": -56,
      "y": 12,
      "z": 5,
      "name": "Rock_Ice_Permafrost"
    },
    {
      "x": -56,
      "y": 13,
      "z": 5,
      "name": "Rock_Ice_Permafrost"
    },
    {
      "x": -56,
      "y": 12,
      "z": 6,
      "name": "Rock_Ice_Permafrost"
    },
    {
      "x": -56,
      "y": 13,
      "z": 6,
      "name": "Rock_Ice_Permafrost"
    },
    {
      "x": -56,
      "y": 14,
      "z": 6,
      "name": "Rock_Ice_Permafrost"
    },
    {
      "x": -56,
      "y": 11,
      "z": 7,
      "name": "Rock_Ice_Permafrost"
    },
    {
      "x": -56,
      "y": 12,
      "z": 7,
      "name": "Rock_Ice_Permafrost"
    },
    {
      "x": -56,
      "y": 13,
      "z": 7,
      "name": "Rock_Ice_Permafrost"
    },
    {
      "x": -56,
      "y": 14,
      "z": 7,
      "name": "Rock_Ice_Permafrost"
    },
    {
      "x": -56,
      "y": 13,
      "z": 8,
      "name": "Rock_Ice_Permafrost"
    },
    {
      "x": -55,
      "y": 21,
      "z": -8,
      "name": "Rock_Ice_Permafrost"
    },
    {
      "x": -55,
      "y": 22,
      "z": -8,
      "name": "Rock_Ice_Permafrost"
    },
    {
      "x": -55,
      "y": 23,
      "z": -8,
      "name": "Rock_Ice_Permafrost"
    },
    {
      "x": -55,
      "y": 20,
      "z": -7,
      "name": "Rock_Ice_Permafrost"
    },
    {
      "x": -55,
      "y": 21,
      "z": -7,
      "name": "Rock_Ice_Permafrost"
    },
    {
      "x": -55,
      "y": 22,
      "z": -7,
      "name": "Rock_Ice_Permafrost"
    },
    {
      "x": -55,
      "y": 23,
      "z": -7,
      "name": "Rock_Ice_Permafrost"
    },
    {
      "x": -55,
      "y": 21,
      "z": -6,
      "name": "Rock_Ice_Permafrost"
    },
    {
      "x": -55,
      "y": 22,
      "z": -6,
      "name": "Rock_Ice_Permafrost"
    },
    {
      "x": -55,
      "y": 11,
      "z": 5,
      "name": "Rock_Ice_Permafrost"
    },
    {
      "x": -55,
      "y": 12,
      "z": 5,
      "name": "Rock_Ice_Permafrost"
    },
    {
      "x": -55,
      "y": 13,
      "z": 5,
      "name": "Rock_Ice_Permafrost"
    },
    {
      "x": -55,
      "y": 11,
      "z": 6,
      "name": "Rock_Ice_Permafrost"
    },
    {
      "x": -55,
      "y": 12,
      "z": 6,
      "name": "Rock_Ice_Permafrost"
    },
    {
      "x": -55,
      "y": 13,
      "z": 6,
      "name": "Rock_Ice_Permafrost"
    },
    {
      "x": -55,
      "y": 11,
      "z": 7,
      "name": "Rock_Ice_Permafrost"
    },
    {
      "x": -55,
      "y": 12,
      "z": 7,
      "name": "Rock_Ice_Permafrost"
    },
    {
      "x": -55,
      "y": 13,
      "z": 7,
      "name": "Rock_Ice_Permafrost"
    },
    {
      "x": -54,
      "y": 20,
      "z": -8,
      "name": "Rock_Ice_Permafrost"
    },
    {
      "x": -54,
      "y": 21,
      "z": -8,
      "name": "Rock_Ice_Permafrost"
    },
    {
      "x": -54,
      "y": 22,
      "z": -8,
      "name": "Rock_Ice_Permafrost"
    },
    {
      "x": -54,
      "y": 20,
      "z": -7,
      "name": "Rock_Ice_Permafrost"
    },
    {
      "x": -54,
      "y": 21,
      "z": -7,
      "name": "Rock_Ice_Permafrost"
    },
    {
      "x": -54,
      "y": 22,
      "z": -7,
      "name": "Rock_Ice_Permafrost"
    },
    {
      "x": -54,
      "y": 23,
      "z": -7,
      "name": "Rock_Ice_Permafrost"
    },
    {
      "x": -54,
      "y": 20,
      "z": -6,
      "name": "Rock_Ice_Permafrost"
    },
    {
      "x": -54,
      "y": 21,
      "z": -6,
      "name": "Rock_Ice_Permafrost"
    },
    {
      "x": -54,
      "y": 22,
      "z": -6,
      "name": "Rock_Ice_Permafrost"
    },
    {
      "x": -54,
      "y": 11,
      "z": 5,
      "name": "Rock_Ice_Permafrost"
    },
    {
      "x": -54,
      "y": 12,
      "z": 5,
      "name": "Rock_Ice_Permafrost"
    },
    {
      "x": -54,
      "y": 13,
      "z": 5,
      "name": "Rock_Ice_Permafrost"
    },
    {
      "x": -54,
      "y": 11,
      "z": 6,
      "name": "Rock_Ice_Permafrost"
    },
    {
      "x": -54,
      "y": 12,
      "z": 6,
      "name": "Rock_Ice_Permafrost"
    },
    {
      "x": -54,
      "y": 13,
      "z": 6,
      "name": "Rock_Ice_Permafrost"
    },
    {
      "x": -54,
      "y": 10,
      "z": 7,
      "name": "Rock_Ice_Permafrost"
    },
    {
      "x": -54,
      "y": 11,
      "z": 7,
      "name": "Rock_Ice_Permafrost"
    },
    {
      "x": -54,
      "y": 12,
      "z": 7,
      "name": "Rock_Ice_Permafrost"
    },
    {
      "x": -54,
      "y": 13,
      "z": 7,
      "name": "Rock_Ice_Permafrost"
    },
    {
      "x": -53,
      "y": 19,
      "z": -8,
      "name": "Rock_Ice_Permafrost"
    },
    {
      "x": -53,
      "y": 20,
      "z": -8,
      "name": "Rock_Ice_Permafrost"
    },
    {
      "x": -53,
      "y": 21,
      "z": -8,
      "name": "Rock_Ice_Permafrost"
    },
    {
      "x": -53,
      "y": 22,
      "z": -8,
      "name": "Rock_Ice_Permafrost"
    },
    {
      "x": -53,
      "y": 19,
      "z": -7,
      "name": "Rock_Ice_Permafrost"
    },
    {
      "x": -53,
      "y": 20,
      "z": -7,
      "name": "Rock_Ice_Permafrost"
    },
    {
      "x": -53,
      "y": 21,
      "z": -7,
      "name": "Rock_Ice_Permafrost"
    },
    {
      "x": -53,
      "y": 22,
      "z": -7,
      "name": "Rock_Ice_Permafrost"
    },
    {
      "x": -53,
      "y": 19,
      "z": -6,
      "name": "Rock_Ice_Permafrost"
    },
    {
      "x": -53,
      "y": 20,
      "z": -6,
      "name": "Rock_Ice_Permafrost"
    },
    {
      "x": -53,
      "y": 21,
      "z": -6,
      "name": "Rock_Ice_Permafrost"
    },
    {
      "x": -53,
      "y": 22,
      "z": -6,
      "name": "Rock_Ice_Permafrost"
    },
    {
      "x": -53,
      "y": 10,
      "z": 5,
      "name": "Rock_Ice_Permafrost"
    },
    {
      "x": -53,
      "y": 11,
      "z": 5,
      "name": "Rock_Ice_Permafrost"
    },
    {
      "x": -53,
      "y": 12,
      "z": 5,
      "name": "Rock_Ice_Permafrost"
    },
    {
      "x": -53,
      "y": 10,
      "z": 6,
      "name": "Rock_Ice_Permafrost"
    },
    {
      "x": -53,
      "y": 11,
      "z": 6,
      "name": "Rock_Ice_Permafrost"
    },
    {
      "x": -53,
      "y": 12,
      "z": 6,
      "name": "Rock_Ice_Permafrost"
    },
    {
      "x": -53,
      "y": 13,
      "z": 6,
      "name": "Rock_Ice_Permafrost"
    },
    {
      "x": -53,
      "y": 10,
      "z": 7,
      "name": "Rock_Ice_Permafrost"
    },
    {
      "x": -53,
      "y": 11,
      "z": 7,
      "name": "Rock_Ice_Permafrost"
    },
    {
      "x": -53,
      "y": 12,
      "z": 7,
      "name": "Rock_Ice_Permafrost"
    },
    {
      "x": -53,
      "y": 13,
      "z": 7,
      "name": "Rock_Ice_Permafrost"
    },
    {
      "x": -52,
      "y": 19,
      "z": -8,
      "name": "Rock_Ice_Permafrost"
    },
    {
      "x": -52,
      "y": 20,
      "z": -8,
      "name": "Rock_Ice_Permafrost"
    },
    {
      "x": -52,
      "y": 21,
      "z": -8,
      "name": "Rock_Ice_Permafrost"
    },
    {
      "x": -52,
      "y": 18,
      "z": -7,
      "name": "Rock_Ice_Permafrost"
    },
    {
      "x": -52,
      "y": 19,
      "z": -7,
      "name": "Rock_Ice_Permafrost"
    },
    {
      "x": -52,
      "y": 20,
      "z": -7,
      "name": "Rock_Ice_Permafrost"
    },
    {
      "x": -52,
      "y": 21,
      "z": -7,
      "name": "Rock_Ice_Permafrost"
    },
    {
      "x": -52,
      "y": 22,
      "z": -7,
      "name": "Rock_Ice_Permafrost"
    },
    {
      "x": -52,
      "y": 18,
      "z": -6,
      "name": "Rock_Ice_Permafrost"
    },
    {
      "x": -52,
      "y": 19,
      "z": -6,
      "name": "Rock_Ice_Permafrost"
    },
    {
      "x": -52,
      "y": 20,
      "z": -6,
      "name": "Rock_Ice_Permafrost"
    },
    {
      "x": -52,
      "y": 21,
      "z": -6,
      "name": "Rock_Ice_Permafrost"
    },
    {
      "x": -52,
      "y": 20,
      "z": -5,
      "name": "Rock_Ice_Permafrost"
    },
    {
      "x": -52,
      "y": 10,
      "z": 5,
      "name": "Rock_Ice_Permafrost"
    },
    {
      "x": -52,
      "y": 11,
      "z": 5,
      "name": "Rock_Ice_Permafrost"
    },
    {
      "x": -52,
      "y": 12,
      "z": 5,
      "name": "Rock_Ice_Permafrost"
    },
    {
      "x": -52,
      "y": 10,
      "z": 6,
      "name": "Rock_Ice_Permafrost"
    },
    {
      "x": -52,
      "y": 12,
      "z": 6,
      "name": "Rock_Ice_Permafrost"
    },
    {
      "x": -52,
      "y": 13,
      "z": 6,
      "name": "Rock_Ice_Permafrost"
    },
    {
      "x": -52,
      "y": 9,
      "z": 7,
      "name": "Rock_Ice_Permafrost"
    },
    {
      "x": -52,
      "y": 10,
      "z": 7,
      "name": "Rock_Ice_Permafrost"
    },
    {
      "x": -52,
      "y": 11,
      "z": 7,
      "name": "Rock_Ice_Permafrost"
    },
    {
      "x": -52,
      "y": 12,
      "z": 7,
      "name": "Rock_Ice_Permafrost"
    },
    {
      "x": -52,
      "y": 13,
      "z": 7,
      "name": "Rock_Ice_Permafrost"
    },
    {
      "x": -51,
      "y": 18,
      "z": -8,
      "name": "Rock_Ice_Permafrost"
    },
    {
      "x": -51,
      "y": 19,
      "z": -8,
      "name": "Rock_Ice_Permafrost"
    },
    {
      "x": -51,
      "y": 20,
      "z": -8,
      "name": "Rock_Ice_Permafrost"
    },
    {
      "x": -51,
      "y": 18,
      "z": -7,
      "name": "Rock_Ice_Permafrost"
    },
    {
      "x": -51,
      "y": 19,
      "z": -7,
      "name": "Rock_Ice_Permafrost"
    },
    {
      "x": -51,
      "y": 20,
      "z": -7,
      "name": "Rock_Ice_Permafrost"
    },
    {
      "x": -51,
      "y": 21,
      "z": -7,
      "name": "Rock_Ice_Permafrost"
    },
    {
      "x": -51,
      "y": 18,
      "z": -6,
      "name": "Rock_Ice_Permafrost"
    },
    {
      "x": -51,
      "y": 19,
      "z": -6,
      "name": "Rock_Ice_Permafrost"
    },
    {
      "x": -51,
      "y": 20,
      "z": -6,
      "name": "Rock_Ice_Permafrost"
    },
    {
      "x": -51,
      "y": 21,
      "z": -6,
      "name": "Rock_Ice_Permafrost"
    },
    {
      "x": -51,
      "y": 19,
      "z": -5,
      "name": "Rock_Ice_Permafrost"
    },
    {
      "x": -51,
      "y": 20,
      "z": -5,
      "name": "Rock_Ice_Permafrost"
    },
    {
      "x": -51,
      "y": 10,
      "z": 4,
      "name": "Rock_Ice_Permafrost"
    },
    {
      "x": -51,
      "y": 11,
      "z": 4,
      "name": "Rock_Ice_Permafrost"
    },
    {
      "x": -51,
      "y": 9,
      "z": 5,
      "name": "Rock_Ice_Permafrost"
    },
    {
      "x": -51,
      "y": 10,
      "z": 5,
      "name": "Rock_Ice_Permafrost"
    },
    {
      "x": -51,
      "y": 11,
      "z": 5,
      "name": "Rock_Ice_Permafrost"
    },
    {
      "x": -51,
      "y": 12,
      "z": 5,
      "name": "Rock_Ice_Permafrost"
    },
    {
      "x": -51,
      "y": 9,
      "z": 6,
      "name": "Rock_Ice_Permafrost"
    },
    {
      "x": -51,
      "y": 10,
      "z": 6,
      "name": "Rock_Ice_Permafrost"
    },
    {
      "x": -51,
      "y": 11,
      "z": 6,
      "name": "Rock_Ice_Permafrost"
    },
    {
      "x": -51,
      "y": 12,
      "z": 6,
      "name": "Rock_Ice_Permafrost"
    },
    {
      "x": -51,
      "y": 9,
      "z": 7,
      "name": "Rock_Ice_Permafrost"
    },
    {
      "x": -51,
      "y": 10,
      "z": 7,
      "name": "Rock_Ice_Permafrost"
    },
    {
      "x": -51,
      "y": 11,
      "z": 7,
      "name": "Rock_Ice_Permafrost"
    },
    {
      "x": -51,
      "y": 12,
      "z": 7,
      "name": "Rock_Ice_Permafrost"
    },
    {
      "x": -50,
      "y": 18,
      "z": -8,
      "name": "Rock_Ice_Permafrost"
    },
    {
      "x": -50,
      "y": 19,
      "z": -8,
      "name": "Rock_Ice_Permafrost"
    },
    {
      "x": -50,
      "y": 17,
      "z": -7,
      "name": "Rock_Ice_Permafrost"
    },
    {
      "x": -50,
      "y": 18,
      "z": -7,
      "name": "Rock_Ice_Permafrost"
    },
    {
      "x": -50,
      "y": 19,
      "z": -7,
      "name": "Rock_Ice_Permafrost"
    },
    {
      "x": -50,
      "y": 20,
      "z": -7,
      "name": "Rock_Ice_Permafrost"
    },
    {
      "x": -50,
      "y": 21,
      "z": -7,
      "name": "Rock_Ice_Permafrost"
    },
    {
      "x": -50,
      "y": 17,
      "z": -6,
      "name": "Rock_Ice_Permafrost"
    },
    {
      "x": -50,
      "y": 18,
      "z": -6,
      "name": "Rock_Ice_Permafrost"
    },
    {
      "x": -50,
      "y": 19,
      "z": -6,
      "name": "Rock_Ice_Permafrost"
    },
    {
      "x": -50,
      "y": 20,
      "z": -6,
      "name": "Rock_Ice_Permafrost"
    },
    {
      "x": -50,
      "y": 21,
      "z": -6,
      "name": "Rock_Ice_Permafrost"
    },
    {
      "x": -50,
      "y": 18,
      "z": -5,
      "name": "Rock_Ice_Permafrost"
    },
    {
      "x": -50,
      "y": 19,
      "z": -5,
      "name": "Rock_Ice_Permafrost"
    },
    {
      "x": -50,
      "y": 20,
      "z": -5,
      "name": "Rock_Ice_Permafrost"
    },
    {
      "x": -50,
      "y": 9,
      "z": 4,
      "name": "Rock_Ice_Permafrost"
    },
    {
      "x": -50,
      "y": 10,
      "z": 4,
      "name": "Rock_Ice_Permafrost"
    },
    {
      "x": -50,
      "y": 11,
      "z": 4,
      "name": "Rock_Ice_Permafrost"
    },
    {
      "x": -50,
      "y": 9,
      "z": 5,
      "name": "Rock_Ice_Permafrost"
    },
    {
      "x": -50,
      "y": 10,
      "z": 5,
      "name": "Rock_Ice_Permafrost"
    },
    {
      "x": -50,
      "y": 11,
      "z": 5,
      "name": "Rock_Ice_Permafrost"
    },
    {
      "x": -50,
      "y": 12,
      "z": 5,
      "name": "Rock_Ice_Permafrost"
    },
    {
      "x": -50,
      "y": 9,
      "z": 6,
      "name": "Rock_Ice_Permafrost"
    },
    {
      "x": -50,
      "y": 11,
      "z": 6,
      "name": "Rock_Ice_Permafrost"
    },
    {
      "x": -50,
      "y": 12,
      "z": 6,
      "name": "Rock_Ice_Permafrost"
    },
    {
      "x": -50,
      "y": 8,
      "z": 7,
      "name": "Rock_Ice_Permafrost"
    },
    {
      "x": -50,
      "y": 9,
      "z": 7,
      "name": "Rock_Ice_Permafrost"
    },
    {
      "x": -50,
      "y": 10,
      "z": 7,
      "name": "Rock_Ice_Permafrost"
    },
    {
      "x": -50,
      "y": 11,
      "z": 7,
      "name": "Rock_Ice_Permafrost"
    },
    {
      "x": -50,
      "y": 12,
      "z": 7,
      "name": "Rock_Ice_Permafrost"
    },
    {
      "x": -49,
      "y": 17,
      "z": -8,
      "name": "Rock_Ice_Permafrost"
    },
    {
      "x": -49,
      "y": 18,
      "z": -8,
      "name": "Rock_Ice_Permafrost"
    },
    {
      "x": -49,
      "y": 19,
      "z": -8,
      "name": "Rock_Ice_Permafrost"
    },
    {
      "x": -49,
      "y": 16,
      "z": -7,
      "name": "Rock_Ice_Permafrost"
    },
    {
      "x": -49,
      "y": 17,
      "z": -7,
      "name": "Rock_Ice_Permafrost"
    },
    {
      "x": -49,
      "y": 18,
      "z": -7,
      "name": "Rock_Ice_Permafrost"
    },
    {
      "x": -49,
      "y": 19,
      "z": -7,
      "name": "Rock_Ice_Permafrost"
    },
    {
      "x": -49,
      "y": 20,
      "z": -7,
      "name": "Rock_Ice_Permafrost"
    },
    {
      "x": -49,
      "y": 21,
      "z": -7,
      "name": "Rock_Ice_Permafrost"
    },
    {
      "x": -49,
      "y": 16,
      "z": -6,
      "name": "Rock_Ice_Permafrost"
    },
    {
      "x": -49,
      "y": 17,
      "z": -6,
      "name": "Rock_Ice_Permafrost"
    },
    {
      "x": -49,
      "y": 18,
      "z": -6,
      "name": "Rock_Ice_Permafrost"
    },
    {
      "x": -49,
      "y": 19,
      "z": -6,
      "name": "Rock_Ice_Permafrost"
    },
    {
      "x": -49,
      "y": 20,
      "z": -6,
      "name": "Rock_Ice_Permafrost"
    },
    {
      "x": -49,
      "y": 17,
      "z": -5,
      "name": "Rock_Ice_Permafrost"
    },
    {
      "x": -49,
      "y": 18,
      "z": -5,
      "name": "Rock_Ice_Permafrost"
    },
    {
      "x": -49,
      "y": 19,
      "z": -5,
      "name": "Rock_Ice_Permafrost"
    },
    {
      "x": -49,
      "y": 20,
      "z": -5,
      "name": "Rock_Ice_Permafrost"
    },
    {
      "x": -49,
      "y": 19,
      "z": -4,
      "name": "Rock_Ice_Permafrost"
    },
    {
      "x": -49,
      "y": 9,
      "z": 4,
      "name": "Rock_Ice_Permafrost"
    },
    {
      "x": -49,
      "y": 10,
      "z": 4,
      "name": "Rock_Ice_Permafrost"
    },
    {
      "x": -49,
      "y": 8,
      "z": 5,
      "name": "Rock_Ice_Permafrost"
    },
    {
      "x": -49,
      "y": 9,
      "z": 5,
      "name": "Rock_Ice_Permafrost"
    },
    {
      "x": -49,
      "y": 10,
      "z": 5,
      "name": "Rock_Ice_Permafrost"
    },
    {
      "x": -49,
      "y": 11,
      "z": 5,
      "name": "Rock_Ice_Permafrost"
    },
    {
      "x": -49,
      "y": 8,
      "z": 6,
      "name": "Rock_Ice_Permafrost"
    },
    {
      "x": -49,
      "y": 9,
      "z": 6,
      "name": "Rock_Ice_Permafrost"
    },
    {
      "x": -49,
      "y": 11,
      "z": 6,
      "name": "Rock_Ice_Permafrost"
    },
    {
      "x": -49,
      "y": 12,
      "z": 6,
      "name": "Rock_Ice_Permafrost"
    },
    {
      "x": -49,
      "y": 8,
      "z": 7,
      "name": "Rock_Ice_Permafrost"
    },
    {
      "x": -49,
      "y": 9,
      "z": 7,
      "name": "Rock_Ice_Permafrost"
    },
    {
      "x": -49,
      "y": 10,
      "z": 7,
      "name": "Rock_Ice_Permafrost"
    },
    {
      "x": -49,
      "y": 11,
      "z": 7,
      "name": "Rock_Ice_Permafrost"
    },
    {
      "x": -49,
      "y": 12,
      "z": 7,
      "name": "Rock_Ice_Permafrost"
    },
    {
      "x": -48,
      "y": 17,
      "z": -8,
      "name": "Rock_Ice_Permafrost"
    },
    {
      "x": -48,
      "y": 18,
      "z": -8,
      "name": "Rock_Ice_Permafrost"
    },
    {
      "x": -48,
      "y": 16,
      "z": -7,
      "name": "Rock_Ice_Permafrost"
    },
    {
      "x": -48,
      "y": 17,
      "z": -7,
      "name": "Rock_Ice_Permafrost"
    },
    {
      "x": -48,
      "y": 18,
      "z": -7,
      "name": "Rock_Ice_Permafrost"
    },
    {
      "x": -48,
      "y": 19,
      "z": -7,
      "name": "Rock_Ice_Permafrost"
    },
    {
      "x": -48,
      "y": 20,
      "z": -7,
      "name": "Rock_Ice_Permafrost"
    },
    {
      "x": -48,
      "y": 16,
      "z": -6,
      "name": "Rock_Ice_Permafrost"
    },
    {
      "x": -48,
      "y": 17,
      "z": -6,
      "name": "Rock_Ice_Permafrost"
    },
    {
      "x": -48,
      "y": 19,
      "z": -6,
      "name": "Rock_Ice_Permafrost"
    },
    {
      "x": -48,
      "y": 20,
      "z": -6,
      "name": "Rock_Ice_Permafrost"
    },
    {
      "x": -48,
      "y": 16,
      "z": -5,
      "name": "Rock_Ice_Permafrost"
    },
    {
      "x": -48,
      "y": 17,
      "z": -5,
      "name": "Rock_Ice_Permafrost"
    },
    {
      "x": -48,
      "y": 18,
      "z": -5,
      "name": "Rock_Ice_Permafrost"
    },
    {
      "x": -48,
      "y": 19,
      "z": -5,
      "name": "Rock_Ice_Permafrost"
    },
    {
      "x": -48,
      "y": 18,
      "z": -4,
      "name": "Rock_Ice_Permafrost"
    },
    {
      "x": -48,
      "y": 19,
      "z": -4,
      "name": "Rock_Ice_Permafrost"
    },
    {
      "x": -48,
      "y": 8,
      "z": 4,
      "name": "Rock_Ice_Permafrost"
    },
    {
      "x": -48,
      "y": 9,
      "z": 4,
      "name": "Rock_Ice_Permafrost"
    },
    {
      "x": -48,
      "y": 10,
      "z": 4,
      "name": "Rock_Ice_Permafrost"
    },
    {
      "x": -48,
      "y": 8,
      "z": 5,
      "name": "Rock_Ice_Permafrost"
    },
    {
      "x": -48,
      "y": 9,
      "z": 5,
      "name": "Rock_Ice_Permafrost"
    },
    {
      "x": -48,
      "y": 10,
      "z": 5,
      "name": "Rock_Ice_Permafrost"
    },
    {
      "x": -48,
      "y": 11,
      "z": 5,
      "name": "Rock_Ice_Permafrost"
    },
    {
      "x": -48,
      "y": 8,
      "z": 6,
      "name": "Rock_Ice_Permafrost"
    },
    {
      "x": -48,
      "y": 9,
      "z": 6,
      "name": "Rock_Ice_Permafrost"
    },
    {
      "x": -48,
      "y": 10,
      "z": 6,
      "name": "Rock_Ice_Permafrost"
    },
    {
      "x": -48,
      "y": 11,
      "z": 6,
      "name": "Rock_Ice_Permafrost"
    },
    {
      "x": -48,
      "y": 8,
      "z": 7,
      "name": "Rock_Ice_Permafrost"
    },
    {
      "x": -48,
      "y": 9,
      "z": 7,
      "name": "Rock_Ice_Permafrost"
    },
    {
      "x": -48,
      "y": 10,
      "z": 7,
      "name": "Rock_Ice_Permafrost"
    },
    {
      "x": -48,
      "y": 11,
      "z": 7,
      "name": "Rock_Ice_Permafrost"
    },
    {
      "x": -47,
      "y": 17,
      "z": -8,
      "name": "Rock_Ice_Permafrost"
    },
    {
      "x": -47,
      "y": 15,
      "z": -7,
      "name": "Rock_Ice_Permafrost"
    },
    {
      "x": -47,
      "y": 16,
      "z": -7,
      "name": "Rock_Ice_Permafrost"
    },
    {
      "x": -47,
      "y": 17,
      "z": -7,
      "name": "Rock_Ice_Permafrost"
    },
    {
      "x": -47,
      "y": 18,
      "z": -7,
      "name": "Rock_Ice_Permafrost"
    },
    {
      "x": -47,
      "y": 19,
      "z": -7,
      "name": "Rock_Ice_Permafrost"
    },
    {
      "x": -47,
      "y": 15,
      "z": -6,
      "name": "Rock_Ice_Permafrost"
    },
    {
      "x": -47,
      "y": 16,
      "z": -6,
      "name": "Rock_Ice_Permafrost"
    },
    {
      "x": -47,
      "y": 18,
      "z": -6,
      "name": "Rock_Ice_Permafrost"
    },
    {
      "x": -47,
      "y": 19,
      "z": -6,
      "name": "Rock_Ice_Permafrost"
    },
    {
      "x": -47,
      "y": 20,
      "z": -6,
      "name": "Rock_Ice_Permafrost"
    },
    {
      "x": -47,
      "y": 15,
      "z": -5,
      "name": "Rock_Ice_Permafrost"
    },
    {
      "x": -47,
      "y": 16,
      "z": -5,
      "name": "Rock_Ice_Permafrost"
    },
    {
      "x": -47,
      "y": 17,
      "z": -5,
      "name": "Rock_Ice_Permafrost"
    },
    {
      "x": -47,
      "y": 18,
      "z": -5,
      "name": "Rock_Ice_Permafrost"
    },
    {
      "x": -47,
      "y": 19,
      "z": -5,
      "name": "Rock_Ice_Permafrost"
    },
    {
      "x": -47,
      "y": 16,
      "z": -4,
      "name": "Rock_Ice_Permafrost"
    },
    {
      "x": -47,
      "y": 17,
      "z": -4,
      "name": "Rock_Ice_Permafrost"
    },
    {
      "x": -47,
      "y": 18,
      "z": -4,
      "name": "Rock_Ice_Permafrost"
    },
    {
      "x": -47,
      "y": 7,
      "z": 4,
      "name": "Rock_Ice_Permafrost"
    },
    {
      "x": -47,
      "y": 8,
      "z": 4,
      "name": "Rock_Ice_Permafrost"
    },
    {
      "x": -47,
      "y": 9,
      "z": 4,
      "name": "Rock_Ice_Permafrost"
    },
    {
      "x": -47,
      "y": 10,
      "z": 4,
      "name": "Rock_Ice_Permafrost"
    },
    {
      "x": -47,
      "y": 7,
      "z": 5,
      "name": "Rock_Ice_Permafrost"
    },
    {
      "x": -47,
      "y": 8,
      "z": 5,
      "name": "Rock_Ice_Permafrost"
    },
    {
      "x": -47,
      "y": 10,
      "z": 5,
      "name": "Rock_Ice_Permafrost"
    },
    {
      "x": -47,
      "y": 11,
      "z": 5,
      "name": "Rock_Ice_Permafrost"
    },
    {
      "x": -47,
      "y": 7,
      "z": 6,
      "name": "Rock_Ice_Permafrost"
    },
    {
      "x": -47,
      "y": 8,
      "z": 6,
      "name": "Rock_Ice_Permafrost"
    },
    {
      "x": -47,
      "y": 9,
      "z": 6,
      "name": "Rock_Ice_Permafrost"
    },
    {
      "x": -47,
      "y": 10,
      "z": 6,
      "name": "Rock_Ice_Permafrost"
    },
    {
      "x": -47,
      "y": 11,
      "z": 6,
      "name": "Rock_Ice_Permafrost"
    },
    {
      "x": -47,
      "y": 7,
      "z": 7,
      "name": "Rock_Ice_Permafrost"
    },
    {
      "x": -47,
      "y": 8,
      "z": 7,
      "name": "Rock_Ice_Permafrost"
    },
    {
      "x": -47,
      "y": 9,
      "z": 7,
      "name": "Rock_Ice_Permafrost"
    },
    {
      "x": -47,
      "y": 10,
      "z": 7,
      "name": "Rock_Ice_Permafrost"
    },
    {
      "x": -47,
      "y": 11,
      "z": 7,
      "name": "Rock_Ice_Permafrost"
    },
    {
      "x": -46,
      "y": 14,
      "z": -7,
      "name": "Rock_Ice_Permafrost"
    },
    {
      "x": -46,
      "y": 15,
      "z": -7,
      "name": "Rock_Ice_Permafrost"
    },
    {
      "x": -46,
      "y": 16,
      "z": -7,
      "name": "Rock_Ice_Permafrost"
    },
    {
      "x": -46,
      "y": 17,
      "z": -7,
      "name": "Rock_Ice_Permafrost"
    },
    {
      "x": -46,
      "y": 18,
      "z": -7,
      "name": "Rock_Ice_Permafrost"
    },
    {
      "x": -46,
      "y": 14,
      "z": -6,
      "name": "Rock_Ice_Permafrost"
    },
    {
      "x": -46,
      "y": 15,
      "z": -6,
      "name": "Rock_Ice_Permafrost"
    },
    {
      "x": -46,
      "y": 17,
      "z": -6,
      "name": "Rock_Ice_Permafrost"
    },
    {
      "x": -46,
      "y": 18,
      "z": -6,
      "name": "Rock_Ice_Permafrost"
    },
    {
      "x": -46,
      "y": 19,
      "z": -6,
      "name": "Rock_Ice_Permafrost"
    },
    {
      "x": -46,
      "y": 14,
      "z": -5,
      "name": "Rock_Ice_Permafrost"
    },
    {
      "x": -46,
      "y": 15,
      "z": -5,
      "name": "Rock_Ice_Permafrost"
    },
    {
      "x": -46,
      "y": 16,
      "z": -5,
      "name": "Rock_Ice_Permafrost"
    },
    {
      "x": -46,
      "y": 17,
      "z": -5,
      "name": "Rock_Ice_Permafrost"
    },
    {
      "x": -46,
      "y": 18,
      "z": -5,
      "name": "Rock_Ice_Permafrost"
    },
    {
      "x": -46,
      "y": 19,
      "z": -5,
      "name": "Rock_Ice_Permafrost"
    },
    {
      "x": -46,
      "y": 15,
      "z": -4,
      "name": "Rock_Ice_Permafrost"
    },
    {
      "x": -46,
      "y": 16,
      "z": -4,
      "name": "Rock_Ice_Permafrost"
    },
    {
      "x": -46,
      "y": 17,
      "z": -4,
      "name": "Rock_Ice_Permafrost"
    },
    {
      "x": -46,
      "y": 18,
      "z": -4,
      "name": "Rock_Ice_Permafrost"
    },
    {
      "x": -46,
      "y": 8,
      "z": 3,
      "name": "Rock_Ice_Permafrost"
    },
    {
      "x": -46,
      "y": 9,
      "z": 3,
      "name": "Rock_Ice_Permafrost"
    },
    {
      "x": -46,
      "y": 7,
      "z": 4,
      "name": "Rock_Ice_Permafrost"
    },
    {
      "x": -46,
      "y": 8,
      "z": 4,
      "name": "Rock_Ice_Permafrost"
    },
    {
      "x": -46,
      "y": 9,
      "z": 4,
      "name": "Rock_Ice_Permafrost"
    },
    {
      "x": -46,
      "y": 10,
      "z": 4,
      "name": "Rock_Ice_Permafrost"
    },
    {
      "x": -46,
      "y": 7,
      "z": 5,
      "name": "Rock_Ice_Permafrost"
    },
    {
      "x": -46,
      "y": 8,
      "z": 5,
      "name": "Rock_Ice_Permafrost"
    },
    {
      "x": -46,
      "y": 9,
      "z": 5,
      "name": "Rock_Ice_Permafrost"
    },
    {
      "x": -46,
      "y": 10,
      "z": 5,
      "name": "Rock_Ice_Permafrost"
    },
    {
      "x": -46,
      "y": 7,
      "z": 6,
      "name": "Rock_Ice_Permafrost"
    },
    {
      "x": -46,
      "y": 8,
      "z": 6,
      "name": "Rock_Ice_Permafrost"
    },
    {
      "x": -46,
      "y": 9,
      "z": 6,
      "name": "Rock_Ice_Permafrost"
    },
    {
      "x": -46,
      "y": 10,
      "z": 6,
      "name": "Rock_Ice_Permafrost"
    },
    {
      "x": -46,
      "y": 11,
      "z": 6,
      "name": "Rock_Ice_Permafrost"
    },
    {
      "x": -46,
      "y": 7,
      "z": 7,
      "name": "Rock_Ice_Permafrost"
    },
    {
      "x": -46,
      "y": 8,
      "z": 7,
      "name": "Rock_Ice_Permafrost"
    },
    {
      "x": -46,
      "y": 9,
      "z": 7,
      "name": "Rock_Ice_Permafrost"
    },
    {
      "x": -46,
      "y": 10,
      "z": 7,
      "name": "Rock_Ice_Permafrost"
    },
    {
      "x": -45,
      "y": 14,
      "z": -7,
      "name": "Rock_Ice_Permafrost"
    },
    {
      "x": -45,
      "y": 15,
      "z": -7,
      "name": "Rock_Ice_Permafrost"
    },
    {
      "x": -45,
      "y": 16,
      "z": -7,
      "name": "Rock_Ice_Permafrost"
    },
    {
      "x": -45,
      "y": 17,
      "z": -7,
      "name": "Rock_Ice_Permafrost"
    },
    {
      "x": -45,
      "y": 18,
      "z": -7,
      "name": "Rock_Ice_Permafrost"
    },
    {
      "x": -45,
      "y": 14,
      "z": -6,
      "name": "Rock_Ice_Permafrost"
    },
    {
      "x": -45,
      "y": 15,
      "z": -6,
      "name": "Rock_Ice_Permafrost"
    },
    {
      "x": -45,
      "y": 17,
      "z": -6,
      "name": "Rock_Ice_Permafrost"
    },
    {
      "x": -45,
      "y": 18,
      "z": -6,
      "name": "Rock_Ice_Permafrost"
    },
    {
      "x": -45,
      "y": 19,
      "z": -6,
      "name": "Rock_Ice_Permafrost"
    },
    {
      "x": -45,
      "y": 13,
      "z": -5,
      "name": "Rock_Ice_Permafrost"
    },
    {
      "x": -45,
      "y": 14,
      "z": -5,
      "name": "Rock_Ice_Permafrost"
    },
    {
      "x": -45,
      "y": 15,
      "z": -5,
      "name": "Rock_Ice_Permafrost"
    },
    {
      "x": -45,
      "y": 17,
      "z": -5,
      "name": "Rock_Ice_Permafrost"
    },
    {
      "x": -45,
      "y": 18,
      "z": -5,
      "name": "Rock_Ice_Permafrost"
    },
    {
      "x": -45,
      "y": 14,
      "z": -4,
      "name": "Rock_Ice_Permafrost"
    },
    {
      "x": -45,
      "y": 15,
      "z": -4,
      "name": "Rock_Ice_Permafrost"
    },
    {
      "x": -45,
      "y": 16,
      "z": -4,
      "name": "Rock_Ice_Permafrost"
    },
    {
      "x": -45,
      "y": 17,
      "z": -4,
      "name": "Rock_Ice_Permafrost"
    },
    {
      "x": -45,
      "y": 18,
      "z": -4,
      "name": "Rock_Ice_Permafrost"
    },
    {
      "x": -45,
      "y": 17,
      "z": -3,
      "name": "Rock_Ice_Permafrost"
    },
    {
      "x": -45,
      "y": 7,
      "z": 3,
      "name": "Rock_Ice_Permafrost"
    },
    {
      "x": -45,
      "y": 8,
      "z": 3,
      "name": "Rock_Ice_Permafrost"
    },
    {
      "x": -45,
      "y": 6,
      "z": 4,
      "name": "Rock_Ice_Permafrost"
    },
    {
      "x": -45,
      "y": 7,
      "z": 4,
      "name": "Rock_Ice_Permafrost"
    },
    {
      "x": -45,
      "y": 8,
      "z": 4,
      "name": "Rock_Ice_Permafrost"
    },
    {
      "x": -45,
      "y": 9,
      "z": 4,
      "name": "Rock_Ice_Permafrost"
    },
    {
      "x": -45,
      "y": 10,
      "z": 4,
      "name": "Rock_Ice_Permafrost"
    },
    {
      "x": -45,
      "y": 6,
      "z": 5,
      "name": "Rock_Ice_Permafrost"
    },
    {
      "x": -45,
      "y": 7,
      "z": 5,
      "name": "Rock_Ice_Permafrost"
    },
    {
      "x": -45,
      "y": 9,
      "z": 5,
      "name": "Rock_Ice_Permafrost"
    },
    {
      "x": -45,
      "y": 10,
      "z": 5,
      "name": "Rock_Ice_Permafrost"
    },
    {
      "x": -45,
      "y": 6,
      "z": 6,
      "name": "Rock_Ice_Permafrost"
    },
    {
      "x": -45,
      "y": 7,
      "z": 6,
      "name": "Rock_Ice_Permafrost"
    },
    {
      "x": -45,
      "y": 8,
      "z": 6,
      "name": "Rock_Ice_Permafrost"
    },
    {
      "x": -45,
      "y": 9,
      "z": 6,
      "name": "Rock_Ice_Permafrost"
    },
    {
      "x": -45,
      "y": 10,
      "z": 6,
      "name": "Rock_Ice_Permafrost"
    },
    {
      "x": -45,
      "y": 11,
      "z": 6,
      "name": "Rock_Ice_Permafrost"
    },
    {
      "x": -45,
      "y": 6,
      "z": 7,
      "name": "Rock_Ice_Permafrost"
    },
    {
      "x": -45,
      "y": 7,
      "z": 7,
      "name": "Rock_Ice_Permafrost"
    },
    {
      "x": -45,
      "y": 8,
      "z": 7,
      "name": "Rock_Ice_Permafrost"
    },
    {
      "x": -45,
      "y": 9,
      "z": 7,
      "name": "Rock_Ice_Permafrost"
    },
    {
      "x": -45,
      "y": 10,
      "z": 7,
      "name": "Rock_Ice_Permafrost"
    },
    {
      "x": -44,
      "y": 13,
      "z": -7,
      "name": "Rock_Ice_Permafrost"
    },
    {
      "x": -44,
      "y": 14,
      "z": -7,
      "name": "Rock_Ice_Permafrost"
    },
    {
      "x": -44,
      "y": 15,
      "z": -7,
      "name": "Rock_Ice_Permafrost"
    },
    {
      "x": -44,
      "y": 16,
      "z": -7,
      "name": "Rock_Ice_Permafrost"
    },
    {
      "x": -44,
      "y": 17,
      "z": -7,
      "name": "Rock_Ice_Permafrost"
    },
    {
      "x": -44,
      "y": 13,
      "z": -6,
      "name": "Rock_Ice_Permafrost"
    },
    {
      "x": -44,
      "y": 14,
      "z": -6,
      "name": "Rock_Ice_Permafrost"
    },
    {
      "x": -44,
      "y": 16,
      "z": -6,
      "name": "Rock_Ice_Permafrost"
    },
    {
      "x": -44,
      "y": 17,
      "z": -6,
      "name": "Rock_Ice_Permafrost"
    },
    {
      "x": -44,
      "y": 18,
      "z": -6,
      "name": "Rock_Ice_Permafrost"
    },
    {
      "x": -44,
      "y": 13,
      "z": -5,
      "name": "Rock_Ice_Permafrost"
    },
    {
      "x": -44,
      "y": 14,
      "z": -5,
      "name": "Rock_Ice_Permafrost"
    },
    {
      "x": -44,
      "y": 17,
      "z": -5,
      "name": "Rock_Ice_Permafrost"
    },
    {
      "x": -44,
      "y": 18,
      "z": -5,
      "name": "Rock_Ice_Permafrost"
    },
    {
      "x": -44,
      "y": 13,
      "z": -4,
      "name": "Rock_Ice_Permafrost"
    },
    {
      "x": -44,
      "y": 14,
      "z": -4,
      "name": "Rock_Ice_Permafrost"
    },
    {
      "x": -44,
      "y": 15,
      "z": -4,
      "name": "Rock_Ice_Permafrost"
    },
    {
      "x": -44,
      "y": 16,
      "z": -4,
      "name": "Rock_Ice_Permafrost"
    },
    {
      "x": -44,
      "y": 17,
      "z": -4,
      "name": "Rock_Ice_Permafrost"
    },
    {
      "x": -44,
      "y": 15,
      "z": -3,
      "name": "Rock_Ice_Permafrost"
    },
    {
      "x": -44,
      "y": 16,
      "z": -3,
      "name": "Rock_Ice_Permafrost"
    },
    {
      "x": -44,
      "y": 17,
      "z": -3,
      "name": "Rock_Ice_Permafrost"
    },
    {
      "x": -44,
      "y": 7,
      "z": 3,
      "name": "Rock_Ice_Permafrost"
    },
    {
      "x": -44,
      "y": 8,
      "z": 3,
      "name": "Rock_Ice_Permafrost"
    },
    {
      "x": -44,
      "y": 6,
      "z": 4,
      "name": "Rock_Ice_Permafrost"
    },
    {
      "x": -44,
      "y": 7,
      "z": 4,
      "name": "Rock_Ice_Permafrost"
    },
    {
      "x": -44,
      "y": 8,
      "z": 4,
      "name": "Rock_Ice_Permafrost"
    },
    {
      "x": -44,
      "y": 9,
      "z": 4,
      "name": "Rock_Ice_Permafrost"
    },
    {
      "x": -44,
      "y": 6,
      "z": 5,
      "name": "Rock_Ice_Permafrost"
    },
    {
      "x": -44,
      "y": 7,
      "z": 5,
      "name": "Rock_Ice_Permafrost"
    },
    {
      "x": -44,
      "y": 9,
      "z": 5,
      "name": "Rock_Ice_Permafrost"
    },
    {
      "x": -44,
      "y": 10,
      "z": 5,
      "name": "Rock_Ice_Permafrost"
    },
    {
      "x": -44,
      "y": 6,
      "z": 6,
      "name": "Rock_Ice_Permafrost"
    },
    {
      "x": -44,
      "y": 7,
      "z": 6,
      "name": "Rock_Ice_Permafrost"
    },
    {
      "x": -44,
      "y": 8,
      "z": 6,
      "name": "Rock_Ice_Permafrost"
    },
    {
      "x": -44,
      "y": 9,
      "z": 6,
      "name": "Rock_Ice_Permafrost"
    },
    {
      "x": -44,
      "y": 10,
      "z": 6,
      "name": "Rock_Ice_Permafrost"
    },
    {
      "x": -44,
      "y": 6,
      "z": 7,
      "name": "Rock_Ice_Permafrost"
    },
    {
      "x": -44,
      "y": 7,
      "z": 7,
      "name": "Rock_Ice_Permafrost"
    },
    {
      "x": -44,
      "y": 8,
      "z": 7,
      "name": "Rock_Ice_Permafrost"
    },
    {
      "x": -44,
      "y": 9,
      "z": 7,
      "name": "Rock_Ice_Permafrost"
    },
    {
      "x": -43,
      "y": 13,
      "z": -7,
      "name": "Rock_Ice_Permafrost"
    },
    {
      "x": -43,
      "y": 14,
      "z": -7,
      "name": "Rock_Ice_Permafrost"
    },
    {
      "x": -43,
      "y": 15,
      "z": -7,
      "name": "Rock_Ice_Permafrost"
    },
    {
      "x": -43,
      "y": 16,
      "z": -7,
      "name": "Rock_Ice_Permafrost"
    },
    {
      "x": -43,
      "y": 12,
      "z": -6,
      "name": "Rock_Ice_Permafrost"
    },
    {
      "x": -43,
      "y": 13,
      "z": -6,
      "name": "Rock_Ice_Permafrost"
    },
    {
      "x": -43,
      "y": 14,
      "z": -6,
      "name": "Rock_Ice_Permafrost"
    },
    {
      "x": -43,
      "y": 15,
      "z": -6,
      "name": "Rock_Ice_Permafrost"
    },
    {
      "x": -43,
      "y": 16,
      "z": -6,
      "name": "Rock_Ice_Permafrost"
    },
    {
      "x": -43,
      "y": 17,
      "z": -6,
      "name": "Rock_Ice_Permafrost"
    },
    {
      "x": -43,
      "y": 18,
      "z": -6,
      "name": "Rock_Ice_Permafrost"
    },
    {
      "x": -43,
      "y": 12,
      "z": -5,
      "name": "Rock_Ice_Permafrost"
    },
    {
      "x": -43,
      "y": 13,
      "z": -5,
      "name": "Rock_Ice_Permafrost"
    },
    {
      "x": -43,
      "y": 16,
      "z": -5,
      "name": "Rock_Ice_Permafrost"
    },
    {
      "x": -43,
      "y": 17,
      "z": -5,
      "name": "Rock_Ice_Permafrost"
    },
    {
      "x": -43,
      "y": 18,
      "z": -5,
      "name": "Rock_Ice_Permafrost"
    },
    {
      "x": -43,
      "y": 12,
      "z": -4,
      "name": "Rock_Ice_Permafrost"
    },
    {
      "x": -43,
      "y": 13,
      "z": -4,
      "name": "Rock_Ice_Permafrost"
    },
    {
      "x": -43,
      "y": 14,
      "z": -4,
      "name": "Rock_Ice_Permafrost"
    },
    {
      "x": -43,
      "y": 15,
      "z": -4,
      "name": "Rock_Ice_Permafrost"
    },
    {
      "x": -43,
      "y": 16,
      "z": -4,
      "name": "Rock_Ice_Permafrost"
    },
    {
      "x": -43,
      "y": 17,
      "z": -4,
      "name": "Rock_Ice_Permafrost"
    },
    {
      "x": -43,
      "y": 14,
      "z": -3,
      "name": "Rock_Ice_Permafrost"
    },
    {
      "x": -43,
      "y": 15,
      "z": -3,
      "name": "Rock_Ice_Permafrost"
    },
    {
      "x": -43,
      "y": 16,
      "z": -3,
      "name": "Rock_Ice_Permafrost"
    },
    {
      "x": -43,
      "y": 6,
      "z": 3,
      "name": "Rock_Ice_Permafrost"
    },
    {
      "x": -43,
      "y": 7,
      "z": 3,
      "name": "Rock_Ice_Permafrost"
    },
    {
      "x": -43,
      "y": 8,
      "z": 3,
      "name": "Rock_Ice_Permafrost"
    },
    {
      "x": -43,
      "y": 5,
      "z": 4,
      "name": "Rock_Ice_Permafrost"
    },
    {
      "x": -43,
      "y": 6,
      "z": 4,
      "name": "Rock_Ice_Permafrost"
    },
    {
      "x": -43,
      "y": 7,
      "z": 4,
      "name": "Rock_Ice_Permafrost"
    },
    {
      "x": -43,
      "y": 8,
      "z": 4,
      "name": "Rock_Ice_Permafrost"
    },
    {
      "x": -43,
      "y": 9,
      "z": 4,
      "name": "Rock_Ice_Permafrost"
    },
    {
      "x": -43,
      "y": 5,
      "z": 5,
      "name": "Rock_Ice_Permafrost"
    },
    {
      "x": -43,
      "y": 6,
      "z": 5,
      "name": "Rock_Ice_Permafrost"
    },
    {
      "x": -43,
      "y": 9,
      "z": 5,
      "name": "Rock_Ice_Permafrost"
    },
    {
      "x": -43,
      "y": 5,
      "z": 6,
      "name": "Rock_Ice_Permafrost"
    },
    {
      "x": -43,
      "y": 6,
      "z": 6,
      "name": "Rock_Ice_Permafrost"
    },
    {
      "x": -43,
      "y": 7,
      "z": 6,
      "name": "Rock_Ice_Permafrost"
    },
    {
      "x": -43,
      "y": 8,
      "z": 6,
      "name": "Rock_Ice_Permafrost"
    },
    {
      "x": -43,
      "y": 9,
      "z": 6,
      "name": "Rock_Ice_Permafrost"
    },
    {
      "x": -43,
      "y": 10,
      "z": 6,
      "name": "Rock_Ice_Permafrost"
    },
    {
      "x": -43,
      "y": 5,
      "z": 7,
      "name": "Rock_Ice_Permafrost"
    },
    {
      "x": -43,
      "y": 6,
      "z": 7,
      "name": "Rock_Ice_Permafrost"
    },
    {
      "x": -43,
      "y": 7,
      "z": 7,
      "name": "Rock_Ice_Permafrost"
    },
    {
      "x": -43,
      "y": 8,
      "z": 7,
      "name": "Rock_Ice_Permafrost"
    },
    {
      "x": -43,
      "y": 9,
      "z": 7,
      "name": "Rock_Ice_Permafrost"
    },
    {
      "x": -42,
      "y": 12,
      "z": -7,
      "name": "Rock_Ice_Permafrost"
    },
    {
      "x": -42,
      "y": 13,
      "z": -7,
      "name": "Rock_Ice_Permafrost"
    },
    {
      "x": -42,
      "y": 14,
      "z": -7,
      "name": "Rock_Ice_Permafrost"
    },
    {
      "x": -42,
      "y": 15,
      "z": -7,
      "name": "Rock_Ice_Permafrost"
    },
    {
      "x": -42,
      "y": 12,
      "z": -6,
      "name": "Rock_Ice_Permafrost"
    },
    {
      "x": -42,
      "y": 13,
      "z": -6,
      "name": "Rock_Ice_Permafrost"
    },
    {
      "x": -42,
      "y": 14,
      "z": -6,
      "name": "Rock_Ice_Permafrost"
    },
    {
      "x": -42,
      "y": 15,
      "z": -6,
      "name": "Rock_Ice_Permafrost"
    },
    {
      "x": -42,
      "y": 16,
      "z": -6,
      "name": "Rock_Ice_Permafrost"
    },
    {
      "x": -42,
      "y": 17,
      "z": -6,
      "name": "Rock_Ice_Permafrost"
    },
    {
      "x": -42,
      "y": 11,
      "z": -5,
      "name": "Rock_Ice_Permafrost"
    },
    {
      "x": -42,
      "y": 12,
      "z": -5,
      "name": "Rock_Ice_Permafrost"
    },
    {
      "x": -42,
      "y": 16,
      "z": -5,
      "name": "Rock_Ice_Permafrost"
    },
    {
      "x": -42,
      "y": 17,
      "z": -5,
      "name": "Rock_Ice_Permafrost"
    },
    {
      "x": -42,
      "y": 11,
      "z": -4,
      "name": "Rock_Ice_Permafrost"
    },
    {
      "x": -42,
      "y": 12,
      "z": -4,
      "name": "Rock_Ice_Permafrost"
    },
    {
      "x": -42,
      "y": 13,
      "z": -4,
      "name": "Rock_Ice_Permafrost"
    },
    {
      "x": -42,
      "y": 14,
      "z": -4,
      "name": "Rock_Ice_Permafrost"
    },
    {
      "x": -42,
      "y": 15,
      "z": -4,
      "name": "Rock_Ice_Permafrost"
    },
    {
      "x": -42,
      "y": 16,
      "z": -4,
      "name": "Rock_Ice_Permafrost"
    },
    {
      "x": -42,
      "y": 17,
      "z": -4,
      "name": "Rock_Ice_Permafrost"
    },
    {
      "x": -42,
      "y": 13,
      "z": -3,
      "name": "Rock_Ice_Permafrost"
    },
    {
      "x": -42,
      "y": 14,
      "z": -3,
      "name": "Rock_Ice_Permafrost"
    },
    {
      "x": -42,
      "y": 15,
      "z": -3,
      "name": "Rock_Ice_Permafrost"
    },
    {
      "x": -42,
      "y": 16,
      "z": -3,
      "name": "Rock_Ice_Permafrost"
    },
    {
      "x": -42,
      "y": 7,
      "z": 2,
      "name": "Rock_Ice_Permafrost"
    },
    {
      "x": -42,
      "y": 5,
      "z": 3,
      "name": "Rock_Ice_Permafrost"
    },
    {
      "x": -42,
      "y": 6,
      "z": 3,
      "name": "Rock_Ice_Permafrost"
    },
    {
      "x": -42,
      "y": 7,
      "z": 3,
      "name": "Rock_Ice_Permafrost"
    },
    {
      "x": -42,
      "y": 8,
      "z": 3,
      "name": "Rock_Ice_Permafrost"
    },
    {
      "x": -42,
      "y": 5,
      "z": 4,
      "name": "Rock_Ice_Permafrost"
    },
    {
      "x": -42,
      "y": 6,
      "z": 4,
      "name": "Rock_Ice_Permafrost"
    },
    {
      "x": -42,
      "y": 7,
      "z": 4,
      "name": "Rock_Ice_Permafrost"
    },
    {
      "x": -42,
      "y": 8,
      "z": 4,
      "name": "Rock_Ice_Permafrost"
    },
    {
      "x": -42,
      "y": 9,
      "z": 4,
      "name": "Rock_Ice_Permafrost"
    },
    {
      "x": -42,
      "y": 5,
      "z": 5,
      "name": "Rock_Ice_Permafrost"
    },
    {
      "x": -42,
      "y": 6,
      "z": 5,
      "name": "Rock_Ice_Permafrost"
    },
    {
      "x": -42,
      "y": 8,
      "z": 5,
      "name": "Rock_Ice_Permafrost"
    },
    {
      "x": -42,
      "y": 9,
      "z": 5,
      "name": "Rock_Ice_Permafrost"
    },
    {
      "x": -42,
      "y": 5,
      "z": 6,
      "name": "Rock_Ice_Permafrost"
    },
    {
      "x": -42,
      "y": 6,
      "z": 6,
      "name": "Rock_Ice_Permafrost"
    },
    {
      "x": -42,
      "y": 7,
      "z": 6,
      "name": "Rock_Ice_Permafrost"
    },
    {
      "x": -42,
      "y": 8,
      "z": 6,
      "name": "Rock_Ice_Permafrost"
    },
    {
      "x": -42,
      "y": 9,
      "z": 6,
      "name": "Rock_Ice_Permafrost"
    },
    {
      "x": -42,
      "y": 5,
      "z": 7,
      "name": "Rock_Ice_Permafrost"
    },
    {
      "x": -42,
      "y": 6,
      "z": 7,
      "name": "Rock_Ice_Permafrost"
    },
    {
      "x": -42,
      "y": 7,
      "z": 7,
      "name": "Rock_Ice_Permafrost"
    },
    {
      "x": -42,
      "y": 8,
      "z": 7,
      "name": "Rock_Ice_Permafrost"
    },
    {
      "x": -41,
      "y": 12,
      "z": -7,
      "name": "Rock_Ice_Permafrost"
    },
    {
      "x": -41,
      "y": 13,
      "z": -7,
      "name": "Rock_Ice_Permafrost"
    },
    {
      "x": -41,
      "y": 14,
      "z": -7,
      "name": "Rock_Ice_Permafrost"
    },
    {
      "x": -41,
      "y": 15,
      "z": -7,
      "name": "Rock_Ice_Permafrost"
    },
    {
      "x": -41,
      "y": 11,
      "z": -6,
      "name": "Rock_Ice_Permafrost"
    },
    {
      "x": -41,
      "y": 12,
      "z": -6,
      "name": "Rock_Ice_Permafrost"
    },
    {
      "x": -41,
      "y": 13,
      "z": -6,
      "name": "Rock_Ice_Permafrost"
    },
    {
      "x": -41,
      "y": 14,
      "z": -6,
      "name": "Rock_Ice_Permafrost"
    },
    {
      "x": -41,
      "y": 15,
      "z": -6,
      "name": "Rock_Ice_Permafrost"
    },
    {
      "x": -41,
      "y": 16,
      "z": -6,
      "name": "Rock_Ice_Permafrost"
    },
    {
      "x": -41,
      "y": 11,
      "z": -5,
      "name": "Rock_Ice_Permafrost"
    },
    {
      "x": -41,
      "y": 12,
      "z": -5,
      "name": "Rock_Ice_Permafrost"
    },
    {
      "x": -41,
      "y": 15,
      "z": -5,
      "name": "Rock_Ice_Permafrost"
    },
    {
      "x": -41,
      "y": 16,
      "z": -5,
      "name": "Rock_Ice_Permafrost"
    },
    {
      "x": -41,
      "y": 17,
      "z": -5,
      "name": "Rock_Ice_Permafrost"
    },
    {
      "x": -41,
      "y": 11,
      "z": -4,
      "name": "Rock_Ice_Permafrost"
    },
    {
      "x": -41,
      "y": 12,
      "z": -4,
      "name": "Rock_Ice_Permafrost"
    },
    {
      "x": -41,
      "y": 13,
      "z": -4,
      "name": "Rock_Ice_Permafrost"
    },
    {
      "x": -41,
      "y": 15,
      "z": -4,
      "name": "Rock_Ice_Permafrost"
    },
    {
      "x": -41,
      "y": 16,
      "z": -4,
      "name": "Rock_Ice_Permafrost"
    },
    {
      "x": -41,
      "y": 12,
      "z": -3,
      "name": "Rock_Ice_Permafrost"
    },
    {
      "x": -41,
      "y": 13,
      "z": -3,
      "name": "Rock_Ice_Permafrost"
    },
    {
      "x": -41,
      "y": 14,
      "z": -3,
      "name": "Rock_Ice_Permafrost"
    },
    {
      "x": -41,
      "y": 15,
      "z": -3,
      "name": "Rock_Ice_Permafrost"
    },
    {
      "x": -41,
      "y": 16,
      "z": -3,
      "name": "Rock_Ice_Permafrost"
    },
    {
      "x": -41,
      "y": 14,
      "z": -2,
      "name": "Rock_Ice_Permafrost"
    },
    {
      "x": -41,
      "y": 6,
      "z": 2,
      "name": "Rock_Ice_Permafrost"
    },
    {
      "x": -41,
      "y": 7,
      "z": 2,
      "name": "Rock_Ice_Permafrost"
    },
    {
      "x": -41,
      "y": 4,
      "z": 3,
      "name": "Rock_Ice_Permafrost"
    },
    {
      "x": -41,
      "y": 5,
      "z": 3,
      "name": "Rock_Ice_Permafrost"
    },
    {
      "x": -41,
      "y": 6,
      "z": 3,
      "name": "Rock_Ice_Permafrost"
    },
    {
      "x": -41,
      "y": 7,
      "z": 3,
      "name": "Rock_Ice_Permafrost"
    },
    {
      "x": -41,
      "y": 8,
      "z": 3,
      "name": "Rock_Ice_Permafrost"
    },
    {
      "x": -41,
      "y": 4,
      "z": 4,
      "name": "Rock_Ice_Permafrost"
    },
    {
      "x": -41,
      "y": 5,
      "z": 4,
      "name": "Rock_Ice_Permafrost"
    },
    {
      "x": -41,
      "y": 7,
      "z": 4,
      "name": "Rock_Ice_Permafrost"
    },
    {
      "x": -41,
      "y": 8,
      "z": 4,
      "name": "Rock_Ice_Permafrost"
    },
    {
      "x": -41,
      "y": 4,
      "z": 5,
      "name": "Rock_Ice_Permafrost"
    },
    {
      "x": -41,
      "y": 5,
      "z": 5,
      "name": "Rock_Ice_Permafrost"
    },
    {
      "x": -41,
      "y": 8,
      "z": 5,
      "name": "Rock_Ice_Permafrost"
    },
    {
      "x": -41,
      "y": 9,
      "z": 5,
      "name": "Rock_Ice_Permafrost"
    },
    {
      "x": -41,
      "y": 4,
      "z": 6,
      "name": "Rock_Ice_Permafrost"
    },
    {
      "x": -41,
      "y": 5,
      "z": 6,
      "name": "Rock_Ice_Permafrost"
    },
    {
      "x": -41,
      "y": 6,
      "z": 6,
      "name": "Rock_Ice_Permafrost"
    },
    {
      "x": -41,
      "y": 7,
      "z": 6,
      "name": "Rock_Ice_Permafrost"
    },
    {
      "x": -41,
      "y": 8,
      "z": 6,
      "name": "Rock_Ice_Permafrost"
    },
    {
      "x": -41,
      "y": 9,
      "z": 6,
      "name": "Rock_Ice_Permafrost"
    },
    {
      "x": -41,
      "y": 4,
      "z": 7,
      "name": "Rock_Ice_Permafrost"
    },
    {
      "x": -41,
      "y": 5,
      "z": 7,
      "name": "Rock_Ice_Permafrost"
    },
    {
      "x": -41,
      "y": 6,
      "z": 7,
      "name": "Rock_Ice_Permafrost"
    },
    {
      "x": -41,
      "y": 7,
      "z": 7,
      "name": "Rock_Ice_Permafrost"
    },
    {
      "x": -41,
      "y": 8,
      "z": 7,
      "name": "Rock_Ice_Permafrost"
    },
    {
      "x": -40,
      "y": 11,
      "z": -7,
      "name": "Rock_Ice_Permafrost"
    },
    {
      "x": -40,
      "y": 12,
      "z": -7,
      "name": "Rock_Ice_Permafrost"
    },
    {
      "x": -40,
      "y": 13,
      "z": -7,
      "name": "Rock_Ice_Permafrost"
    },
    {
      "x": -40,
      "y": 14,
      "z": -7,
      "name": "Rock_Ice_Permafrost"
    },
    {
      "x": -40,
      "y": 10,
      "z": -6,
      "name": "Rock_Ice_Permafrost"
    },
    {
      "x": -40,
      "y": 11,
      "z": -6,
      "name": "Rock_Ice_Permafrost"
    },
    {
      "x": -40,
      "y": 12,
      "z": -6,
      "name": "Rock_Ice_Permafrost"
    },
    {
      "x": -40,
      "y": 13,
      "z": -6,
      "name": "Rock_Ice_Permafrost"
    },
    {
      "x": -40,
      "y": 14,
      "z": -6,
      "name": "Rock_Ice_Permafrost"
    },
    {
      "x": -40,
      "y": 15,
      "z": -6,
      "name": "Rock_Ice_Permafrost"
    },
    {
      "x": -40,
      "y": 16,
      "z": -6,
      "name": "Rock_Ice_Permafrost"
    },
    {
      "x": -40,
      "y": 10,
      "z": -5,
      "name": "Rock_Ice_Permafrost"
    },
    {
      "x": -40,
      "y": 11,
      "z": -5,
      "name": "Rock_Ice_Permafrost"
    },
    {
      "x": -40,
      "y": 15,
      "z": -5,
      "name": "Rock_Ice_Permafrost"
    },
    {
      "x": -40,
      "y": 16,
      "z": -5,
      "name": "Rock_Ice_Permafrost"
    },
    {
      "x": -40,
      "y": 17,
      "z": -5,
      "name": "Rock_Ice_Permafrost"
    },
    {
      "x": -40,
      "y": 10,
      "z": -4,
      "name": "Rock_Ice_Permafrost"
    },
    {
      "x": -40,
      "y": 11,
      "z": -4,
      "name": "Rock_Ice_Permafrost"
    },
    {
      "x": -40,
      "y": 12,
      "z": -4,
      "name": "Rock_Ice_Permafrost"
    },
    {
      "x": -40,
      "y": 15,
      "z": -4,
      "name": "Rock_Ice_Permafrost"
    },
    {
      "x": -40,
      "y": 16,
      "z": -4,
      "name": "Rock_Ice_Permafrost"
    },
    {
      "x": -40,
      "y": 11,
      "z": -3,
      "name": "Rock_Ice_Permafrost"
    },
    {
      "x": -40,
      "y": 12,
      "z": -3,
      "name": "Rock_Ice_Permafrost"
    },
    {
      "x": -40,
      "y": 13,
      "z": -3,
      "name": "Rock_Ice_Permafrost"
    },
    {
      "x": -40,
      "y": 14,
      "z": -3,
      "name": "Rock_Ice_Permafrost"
    },
    {
      "x": -40,
      "y": 15,
      "z": -3,
      "name": "Rock_Ice_Permafrost"
    },
    {
      "x": -40,
      "y": 12,
      "z": -2,
      "name": "Rock_Ice_Permafrost"
    },
    {
      "x": -40,
      "y": 13,
      "z": -2,
      "name": "Rock_Ice_Permafrost"
    },
    {
      "x": -40,
      "y": 14,
      "z": -2,
      "name": "Rock_Ice_Permafrost"
    },
    {
      "x": -40,
      "y": 15,
      "z": -2,
      "name": "Rock_Ice_Permafrost"
    },
    {
      "x": -40,
      "y": 5,
      "z": 2,
      "name": "Rock_Ice_Permafrost"
    },
    {
      "x": -40,
      "y": 6,
      "z": 2,
      "name": "Rock_Ice_Permafrost"
    },
    {
      "x": -40,
      "y": 4,
      "z": 3,
      "name": "Rock_Ice_Permafrost"
    },
    {
      "x": -40,
      "y": 5,
      "z": 3,
      "name": "Rock_Ice_Permafrost"
    },
    {
      "x": -40,
      "y": 6,
      "z": 3,
      "name": "Rock_Ice_Permafrost"
    },
    {
      "x": -40,
      "y": 7,
      "z": 3,
      "name": "Rock_Ice_Permafrost"
    },
    {
      "x": -40,
      "y": 8,
      "z": 3,
      "name": "Rock_Ice_Permafrost"
    },
    {
      "x": -40,
      "y": 4,
      "z": 4,
      "name": "Rock_Ice_Permafrost"
    },
    {
      "x": -40,
      "y": 5,
      "z": 4,
      "name": "Rock_Ice_Permafrost"
    },
    {
      "x": -40,
      "y": 7,
      "z": 4,
      "name": "Rock_Ice_Permafrost"
    },
    {
      "x": -40,
      "y": 8,
      "z": 4,
      "name": "Rock_Ice_Permafrost"
    },
    {
      "x": -40,
      "y": 4,
      "z": 5,
      "name": "Rock_Ice_Permafrost"
    },
    {
      "x": -40,
      "y": 5,
      "z": 5,
      "name": "Rock_Ice_Permafrost"
    },
    {
      "x": -40,
      "y": 8,
      "z": 5,
      "name": "Rock_Ice_Permafrost"
    },
    {
      "x": -40,
      "y": 9,
      "z": 5,
      "name": "Rock_Ice_Permafrost"
    },
    {
      "x": -40,
      "y": 4,
      "z": 6,
      "name": "Rock_Ice_Permafrost"
    },
    {
      "x": -40,
      "y": 5,
      "z": 6,
      "name": "Rock_Ice_Permafrost"
    },
    {
      "x": -40,
      "y": 6,
      "z": 6,
      "name": "Rock_Ice_Permafrost"
    },
    {
      "x": -40,
      "y": 7,
      "z": 6,
      "name": "Rock_Ice_Permafrost"
    },
    {
      "x": -40,
      "y": 8,
      "z": 6,
      "name": "Rock_Ice_Permafrost"
    },
    {
      "x": -40,
      "y": 9,
      "z": 6,
      "name": "Rock_Ice_Permafrost"
    },
    {
      "x": -40,
      "y": 4,
      "z": 7,
      "name": "Rock_Ice_Permafrost"
    },
    {
      "x": -40,
      "y": 5,
      "z": 7,
      "name": "Rock_Ice_Permafrost"
    },
    {
      "x": -40,
      "y": 6,
      "z": 7,
      "name": "Rock_Ice_Permafrost"
    },
    {
      "x": -40,
      "y": 7,
      "z": 7,
      "name": "Rock_Ice_Permafrost"
    },
    {
      "x": -39,
      "y": -40,
      "z": -17,
      "name": "Rock_Ice_Permafrost"
    },
    {
      "x": -39,
      "y": -40,
      "z": -16,
      "name": "Rock_Ice_Permafrost"
    },
    {
      "x": -39,
      "y": -39,
      "z": -16,
      "name": "Rock_Ice_Permafrost"
    },
    {
      "x": -39,
      "y": 11,
      "z": -7,
      "name": "Rock_Ice_Permafrost"
    },
    {
      "x": -39,
      "y": 12,
      "z": -7,
      "name": "Rock_Ice_Permafrost"
    },
    {
      "x": -39,
      "y": 13,
      "z": -7,
      "name": "Rock_Ice_Permafrost"
    },
    {
      "x": -39,
      "y": 10,
      "z": -6,
      "name": "Rock_Ice_Permafrost"
    },
    {
      "x": -39,
      "y": 11,
      "z": -6,
      "name": "Rock_Ice_Permafrost"
    },
    {
      "x": -39,
      "y": 12,
      "z": -6,
      "name": "Rock_Ice_Permafrost"
    },
    {
      "x": -39,
      "y": 13,
      "z": -6,
      "name": "Rock_Ice_Permafrost"
    },
    {
      "x": -39,
      "y": 14,
      "z": -6,
      "name": "Rock_Ice_Permafrost"
    },
    {
      "x": -39,
      "y": 15,
      "z": -6,
      "name": "Rock_Ice_Permafrost"
    },
    {
      "x": -39,
      "y": 9,
      "z": -5,
      "name": "Rock_Ice_Permafrost"
    },
    {
      "x": -39,
      "y": 10,
      "z": -5,
      "name": "Rock_Ice_Permafrost"
    },
    {
      "x": -39,
      "y": 11,
      "z": -5,
      "name": "Rock_Ice_Permafrost"
    },
    {
      "x": -39,
      "y": 14,
      "z": -5,
      "name": "Rock_Ice_Permafrost"
    },
    {
      "x": -39,
      "y": 15,
      "z": -5,
      "name": "Rock_Ice_Permafrost"
    },
    {
      "x": -39,
      "y": 16,
      "z": -5,
      "name": "Rock_Ice_Permafrost"
    },
    {
      "x": -39,
      "y": 9,
      "z": -4,
      "name": "Rock_Ice_Permafrost"
    },
    {
      "x": -39,
      "y": 10,
      "z": -4,
      "name": "Rock_Ice_Permafrost"
    },
    {
      "x": -39,
      "y": 11,
      "z": -4,
      "name": "Rock_Ice_Permafrost"
    },
    {
      "x": -39,
      "y": 14,
      "z": -4,
      "name": "Rock_Ice_Permafrost"
    },
    {
      "x": -39,
      "y": 15,
      "z": -4,
      "name": "Rock_Ice_Permafrost"
    },
    {
      "x": -39,
      "y": 16,
      "z": -4,
      "name": "Rock_Ice_Permafrost"
    },
    {
      "x": -39,
      "y": 10,
      "z": -3,
      "name": "Rock_Ice_Permafrost"
    },
    {
      "x": -39,
      "y": 11,
      "z": -3,
      "name": "Rock_Ice_Permafrost"
    },
    {
      "x": -39,
      "y": 12,
      "z": -3,
      "name": "Rock_Ice_Permafrost"
    },
    {
      "x": -39,
      "y": 13,
      "z": -3,
      "name": "Rock_Ice_Permafrost"
    },
    {
      "x": -39,
      "y": 14,
      "z": -3,
      "name": "Rock_Ice_Permafrost"
    },
    {
      "x": -39,
      "y": 15,
      "z": -3,
      "name": "Rock_Ice_Permafrost"
    },
    {
      "x": -39,
      "y": 11,
      "z": -2,
      "name": "Rock_Ice_Permafrost"
    },
    {
      "x": -39,
      "y": 12,
      "z": -2,
      "name": "Rock_Ice_Permafrost"
    },
    {
      "x": -39,
      "y": 13,
      "z": -2,
      "name": "Rock_Ice_Permafrost"
    },
    {
      "x": -39,
      "y": 14,
      "z": -2,
      "name": "Rock_Ice_Permafrost"
    },
    {
      "x": -39,
      "y": -22,
      "z": 1,
      "name": "Rock_Ice_Permafrost"
    },
    {
      "x": -39,
      "y": -21,
      "z": 1,
      "name": "Rock_Ice_Permafrost"
    },
    {
      "x": -39,
      "y": 5,
      "z": 2,
      "name": "Rock_Ice_Permafrost"
    },
    {
      "x": -39,
      "y": 6,
      "z": 2,
      "name": "Rock_Ice_Permafrost"
    },
    {
      "x": -39,
      "y": 3,
      "z": 3,
      "name": "Rock_Ice_Permafrost"
    },
    {
      "x": -39,
      "y": 4,
      "z": 3,
      "name": "Rock_Ice_Permafrost"
    },
    {
      "x": -39,
      "y": 5,
      "z": 3,
      "name": "Rock_Ice_Permafrost"
    },
    {
      "x": -39,
      "y": 6,
      "z": 3,
      "name": "Rock_Ice_Permafrost"
    },
    {
      "x": -39,
      "y": 7,
      "z": 3,
      "name": "Rock_Ice_Permafrost"
    },
    {
      "x": -39,
      "y": 3,
      "z": 4,
      "name": "Rock_Ice_Permafrost"
    },
    {
      "x": -39,
      "y": 4,
      "z": 4,
      "name": "Rock_Ice_Permafrost"
    },
    {
      "x": -39,
      "y": 7,
      "z": 4,
      "name": "Rock_Ice_Permafrost"
    },
    {
      "x": -39,
      "y": 8,
      "z": 4,
      "name": "Rock_Ice_Permafrost"
    },
    {
      "x": -39,
      "y": 3,
      "z": 5,
      "name": "Rock_Ice_Permafrost"
    },
    {
      "x": -39,
      "y": 4,
      "z": 5,
      "name": "Rock_Ice_Permafrost"
    },
    {
      "x": -39,
      "y": 7,
      "z": 5,
      "name": "Rock_Ice_Permafrost"
    },
    {
      "x": -39,
      "y": 8,
      "z": 5,
      "name": "Rock_Ice_Permafrost"
    },
    {
      "x": -39,
      "y": 3,
      "z": 6,
      "name": "Rock_Ice_Permafrost"
    },
    {
      "x": -39,
      "y": 4,
      "z": 6,
      "name": "Rock_Ice_Permafrost"
    },
    {
      "x": -39,
      "y": 5,
      "z": 6,
      "name": "Rock_Ice_Permafrost"
    },
    {
      "x": -39,
      "y": 6,
      "z": 6,
      "name": "Rock_Ice_Permafrost"
    },
    {
      "x": -39,
      "y": 7,
      "z": 6,
      "name": "Rock_Ice_Permafrost"
    },
    {
      "x": -39,
      "y": 8,
      "z": 6,
      "name": "Rock_Ice_Permafrost"
    },
    {
      "x": -39,
      "y": 4,
      "z": 7,
      "name": "Rock_Ice_Permafrost"
    },
    {
      "x": -39,
      "y": 5,
      "z": 7,
      "name": "Rock_Ice_Permafrost"
    },
    {
      "x": -39,
      "y": 6,
      "z": 7,
      "name": "Rock_Ice_Permafrost"
    },
    {
      "x": -39,
      "y": 7,
      "z": 7,
      "name": "Rock_Ice_Permafrost"
    },
    {
      "x": -38,
      "y": -39,
      "z": -16,
      "name": "Rock_Ice_Permafrost"
    },
    {
      "x": -38,
      "y": -38,
      "z": -16,
      "name": "Rock_Ice_Permafrost"
    },
    {
      "x": -38,
      "y": -39,
      "z": -15,
      "name": "Rock_Ice_Permafrost"
    },
    {
      "x": -38,
      "y": -38,
      "z": -15,
      "name": "Rock_Ice_Permafrost"
    },
    {
      "x": -38,
      "y": 11,
      "z": -7,
      "name": "Rock_Ice_Permafrost"
    },
    {
      "x": -38,
      "y": 12,
      "z": -7,
      "name": "Rock_Ice_Permafrost"
    },
    {
      "x": -38,
      "y": 9,
      "z": -6,
      "name": "Rock_Ice_Permafrost"
    },
    {
      "x": -38,
      "y": 10,
      "z": -6,
      "name": "Rock_Ice_Permafrost"
    },
    {
      "x": -38,
      "y": 11,
      "z": -6,
      "name": "Rock_Ice_Permafrost"
    },
    {
      "x": -38,
      "y": 12,
      "z": -6,
      "name": "Rock_Ice_Permafrost"
    },
    {
      "x": -38,
      "y": 13,
      "z": -6,
      "name": "Rock_Ice_Permafrost"
    },
    {
      "x": -38,
      "y": 14,
      "z": -6,
      "name": "Rock_Ice_Permafrost"
    },
    {
      "x": -38,
      "y": 9,
      "z": -5,
      "name": "Rock_Ice_Permafrost"
    },
    {
      "x": -38,
      "y": 10,
      "z": -5,
      "name": "Rock_Ice_Permafrost"
    },
    {
      "x": -38,
      "y": 13,
      "z": -5,
      "name": "Rock_Ice_Permafrost"
    },
    {
      "x": -38,
      "y": 14,
      "z": -5,
      "name": "Rock_Ice_Permafrost"
    },
    {
      "x": -38,
      "y": 15,
      "z": -5,
      "name": "Rock_Ice_Permafrost"
    },
    {
      "x": -38,
      "y": 16,
      "z": -5,
      "name": "Rock_Ice_Permafrost"
    },
    {
      "x": -38,
      "y": 9,
      "z": -4,
      "name": "Rock_Ice_Permafrost"
    },
    {
      "x": -38,
      "y": 10,
      "z": -4,
      "name": "Rock_Ice_Permafrost"
    },
    {
      "x": -38,
      "y": 14,
      "z": -4,
      "name": "Rock_Ice_Permafrost"
    },
    {
      "x": -38,
      "y": 15,
      "z": -4,
      "name": "Rock_Ice_Permafrost"
    },
    {
      "x": -38,
      "y": 9,
      "z": -3,
      "name": "Rock_Ice_Permafrost"
    },
    {
      "x": -38,
      "y": 10,
      "z": -3,
      "name": "Rock_Ice_Permafrost"
    },
    {
      "x": -38,
      "y": 11,
      "z": -3,
      "name": "Rock_Ice_Permafrost"
    },
    {
      "x": -38,
      "y": 12,
      "z": -3,
      "name": "Rock_Ice_Permafrost"
    },
    {
      "x": -38,
      "y": 13,
      "z": -3,
      "name": "Rock_Ice_Permafrost"
    },
    {
      "x": -38,
      "y": 14,
      "z": -3,
      "name": "Rock_Ice_Permafrost"
    },
    {
      "x": -38,
      "y": 15,
      "z": -3,
      "name": "Rock_Ice_Permafrost"
    },
    {
      "x": -38,
      "y": 10,
      "z": -2,
      "name": "Rock_Ice_Permafrost"
    },
    {
      "x": -38,
      "y": 11,
      "z": -2,
      "name": "Rock_Ice_Permafrost"
    },
    {
      "x": -38,
      "y": 12,
      "z": -2,
      "name": "Rock_Ice_Permafrost"
    },
    {
      "x": -38,
      "y": 13,
      "z": -2,
      "name": "Rock_Ice_Permafrost"
    },
    {
      "x": -38,
      "y": 14,
      "z": -2,
      "name": "Rock_Ice_Permafrost"
    },
    {
      "x": -38,
      "y": 13,
      "z": -1,
      "name": "Rock_Ice_Permafrost"
    },
    {
      "x": -38,
      "y": -22,
      "z": 1,
      "name": "Rock_Ice_Permafrost"
    },
    {
      "x": -38,
      "y": -21,
      "z": 1,
      "name": "Rock_Ice_Permafrost"
    },
    {
      "x": -38,
      "y": -22,
      "z": 2,
      "name": "Rock_Ice_Permafrost"
    },
    {
      "x": -38,
      "y": 4,
      "z": 2,
      "name": "Rock_Ice_Permafrost"
    },
    {
      "x": -38,
      "y": 5,
      "z": 2,
      "name": "Rock_Ice_Permafrost"
    },
    {
      "x": -38,
      "y": 6,
      "z": 2,
      "name": "Rock_Ice_Permafrost"
    },
    {
      "x": -38,
      "y": 3,
      "z": 3,
      "name": "Rock_Ice_Permafrost"
    },
    {
      "x": -38,
      "y": 4,
      "z": 3,
      "name": "Rock_Ice_Permafrost"
    },
    {
      "x": -38,
      "y": 5,
      "z": 3,
      "name": "Rock_Ice_Permafrost"
    },
    {
      "x": -38,
      "y": 6,
      "z": 3,
      "name": "Rock_Ice_Permafrost"
    },
    {
      "x": -38,
      "y": 7,
      "z": 3,
      "name": "Rock_Ice_Permafrost"
    },
    {
      "x": -38,
      "y": 3,
      "z": 4,
      "name": "Rock_Ice_Permafrost"
    },
    {
      "x": -38,
      "y": 4,
      "z": 4,
      "name": "Rock_Ice_Permafrost"
    },
    {
      "x": -38,
      "y": 7,
      "z": 4,
      "name": "Rock_Ice_Permafrost"
    },
    {
      "x": -38,
      "y": 8,
      "z": 4,
      "name": "Rock_Ice_Permafrost"
    },
    {
      "x": -38,
      "y": 3,
      "z": 5,
      "name": "Rock_Ice_Permafrost"
    },
    {
      "x": -38,
      "y": 4,
      "z": 5,
      "name": "Rock_Ice_Permafrost"
    },
    {
      "x": -38,
      "y": 7,
      "z": 5,
      "name": "Rock_Ice_Permafrost"
    },
    {
      "x": -38,
      "y": 8,
      "z": 5,
      "name": "Rock_Ice_Permafrost"
    },
    {
      "x": -38,
      "y": 3,
      "z": 6,
      "name": "Rock_Ice_Permafrost"
    },
    {
      "x": -38,
      "y": 4,
      "z": 6,
      "name": "Rock_Ice_Permafrost"
    },
    {
      "x": -38,
      "y": 5,
      "z": 6,
      "name": "Rock_Ice_Permafrost"
    },
    {
      "x": -38,
      "y": 6,
      "z": 6,
      "name": "Rock_Ice_Permafrost"
    },
    {
      "x": -38,
      "y": 7,
      "z": 6,
      "name": "Rock_Ice_Permafrost"
    },
    {
      "x": -38,
      "y": 8,
      "z": 6,
      "name": "Rock_Ice_Permafrost"
    },
    {
      "x": -38,
      "y": 4,
      "z": 7,
      "name": "Rock_Ice_Permafrost"
    },
    {
      "x": -38,
      "y": 5,
      "z": 7,
      "name": "Rock_Ice_Permafrost"
    },
    {
      "x": -38,
      "y": 6,
      "z": 7,
      "name": "Rock_Ice_Permafrost"
    },
    {
      "x": -38,
      "y": 7,
      "z": 7,
      "name": "Rock_Ice_Permafrost"
    },
    {
      "x": -37,
      "y": -38,
      "z": -16,
      "name": "Rock_Ice_Permafrost"
    },
    {
      "x": -37,
      "y": -38,
      "z": -15,
      "name": "Rock_Ice_Permafrost"
    },
    {
      "x": -37,
      "y": -37,
      "z": -15,
      "name": "Rock_Ice_Permafrost"
    },
    {
      "x": -37,
      "y": -36,
      "z": -15,
      "name": "Rock_Ice_Permafrost"
    },
    {
      "x": -37,
      "y": -38,
      "z": -14,
      "name": "Rock_Ice_Permafrost"
    },
    {
      "x": -37,
      "y": -37,
      "z": -14,
      "name": "Rock_Ice_Permafrost"
    },
    {
      "x": -37,
      "y": 11,
      "z": -7,
      "name": "Rock_Ice_Permafrost"
    },
    {
      "x": -37,
      "y": 12,
      "z": -7,
      "name": "Rock_Ice_Permafrost"
    },
    {
      "x": -37,
      "y": 8,
      "z": -6,
      "name": "Rock_Ice_Permafrost"
    },
    {
      "x": -37,
      "y": 9,
      "z": -6,
      "name": "Rock_Ice_Permafrost"
    },
    {
      "x": -37,
      "y": 10,
      "z": -6,
      "name": "Rock_Ice_Permafrost"
    },
    {
      "x": -37,
      "y": 11,
      "z": -6,
      "name": "Rock_Ice_Permafrost"
    },
    {
      "x": -37,
      "y": 12,
      "z": -6,
      "name": "Rock_Ice_Permafrost"
    },
    {
      "x": -37,
      "y": 13,
      "z": -6,
      "name": "Rock_Ice_Permafrost"
    },
    {
      "x": -37,
      "y": 8,
      "z": -5,
      "name": "Rock_Ice_Permafrost"
    },
    {
      "x": -37,
      "y": 9,
      "z": -5,
      "name": "Rock_Ice_Permafrost"
    },
    {
      "x": -37,
      "y": 12,
      "z": -5,
      "name": "Rock_Ice_Permafrost"
    },
    {
      "x": -37,
      "y": 13,
      "z": -5,
      "name": "Rock_Ice_Permafrost"
    },
    {
      "x": -37,
      "y": 14,
      "z": -5,
      "name": "Rock_Ice_Permafrost"
    },
    {
      "x": -37,
      "y": 15,
      "z": -5,
      "name": "Rock_Ice_Permafrost"
    },
    {
      "x": -37,
      "y": 8,
      "z": -4,
      "name": "Rock_Ice_Permafrost"
    },
    {
      "x": -37,
      "y": 9,
      "z": -4,
      "name": "Rock_Ice_Permafrost"
    },
    {
      "x": -37,
      "y": 14,
      "z": -4,
      "name": "Rock_Ice_Permafrost"
    },
    {
      "x": -37,
      "y": 15,
      "z": -4,
      "name": "Rock_Ice_Permafrost"
    },
    {
      "x": -37,
      "y": 8,
      "z": -3,
      "name": "Rock_Ice_Permafrost"
    },
    {
      "x": -37,
      "y": 9,
      "z": -3,
      "name": "Rock_Ice_Permafrost"
    },
    {
      "x": -37,
      "y": 10,
      "z": -3,
      "name": "Rock_Ice_Permafrost"
    },
    {
      "x": -37,
      "y": 13,
      "z": -3,
      "name": "Rock_Ice_Permafrost"
    },
    {
      "x": -37,
      "y": 14,
      "z": -3,
      "name": "Rock_Ice_Permafrost"
    },
    {
      "x": -37,
      "y": 9,
      "z": -2,
      "name": "Rock_Ice_Permafrost"
    },
    {
      "x": -37,
      "y": 10,
      "z": -2,
      "name": "Rock_Ice_Permafrost"
    },
    {
      "x": -37,
      "y": 11,
      "z": -2,
      "name": "Rock_Ice_Permafrost"
    },
    {
      "x": -37,
      "y": 12,
      "z": -2,
      "name": "Rock_Ice_Permafrost"
    },
    {
      "x": -37,
      "y": 13,
      "z": -2,
      "name": "Rock_Ice_Permafrost"
    },
    {
      "x": -37,
      "y": 14,
      "z": -2,
      "name": "Rock_Ice_Permafrost"
    },
    {
      "x": -37,
      "y": 12,
      "z": -1,
      "name": "Rock_Ice_Permafrost"
    },
    {
      "x": -37,
      "y": 13,
      "z": -1,
      "name": "Rock_Ice_Permafrost"
    },
    {
      "x": -37,
      "y": -21,
      "z": 0,
      "name": "Rock_Ice_Permafrost"
    },
    {
      "x": -37,
      "y": -22,
      "z": 1,
      "name": "Rock_Ice_Permafrost"
    },
    {
      "x": -37,
      "y": -21,
      "z": 1,
      "name": "Rock_Ice_Permafrost"
    },
    {
      "x": -37,
      "y": -20,
      "z": 1,
      "name": "Rock_Ice_Permafrost"
    },
    {
      "x": -37,
      "y": 5,
      "z": 1,
      "name": "Rock_Ice_Permafrost"
    },
    {
      "x": -37,
      "y": -21,
      "z": 2,
      "name": "Rock_Ice_Permafrost"
    },
    {
      "x": -37,
      "y": 3,
      "z": 2,
      "name": "Rock_Ice_Permafrost"
    },
    {
      "x": -37,
      "y": 4,
      "z": 2,
      "name": "Rock_Ice_Permafrost"
    },
    {
      "x": -37,
      "y": 5,
      "z": 2,
      "name": "Rock_Ice_Permafrost"
    },
    {
      "x": -37,
      "y": 6,
      "z": 2,
      "name": "Rock_Ice_Permafrost"
    },
    {
      "x": -37,
      "y": 2,
      "z": 3,
      "name": "Rock_Ice_Permafrost"
    },
    {
      "x": -37,
      "y": 3,
      "z": 3,
      "name": "Rock_Ice_Permafrost"
    },
    {
      "x": -37,
      "y": 4,
      "z": 3,
      "name": "Rock_Ice_Permafrost"
    },
    {
      "x": -37,
      "y": 5,
      "z": 3,
      "name": "Rock_Ice_Permafrost"
    },
    {
      "x": -37,
      "y": 6,
      "z": 3,
      "name": "Rock_Ice_Permafrost"
    },
    {
      "x": -37,
      "y": 7,
      "z": 3,
      "name": "Rock_Ice_Permafrost"
    },
    {
      "x": -37,
      "y": 2,
      "z": 4,
      "name": "Rock_Ice_Permafrost"
    },
    {
      "x": -37,
      "y": 3,
      "z": 4,
      "name": "Rock_Ice_Permafrost"
    },
    {
      "x": -37,
      "y": 6,
      "z": 4,
      "name": "Rock_Ice_Permafrost"
    },
    {
      "x": -37,
      "y": 7,
      "z": 4,
      "name": "Rock_Ice_Permafrost"
    },
    {
      "x": -37,
      "y": 2,
      "z": 5,
      "name": "Rock_Ice_Permafrost"
    },
    {
      "x": -37,
      "y": 3,
      "z": 5,
      "name": "Rock_Ice_Permafrost"
    },
    {
      "x": -37,
      "y": 7,
      "z": 5,
      "name": "Rock_Ice_Permafrost"
    },
    {
      "x": -37,
      "y": 8,
      "z": 5,
      "name": "Rock_Ice_Permafrost"
    },
    {
      "x": -37,
      "y": 2,
      "z": 6,
      "name": "Rock_Ice_Permafrost"
    },
    {
      "x": -37,
      "y": 3,
      "z": 6,
      "name": "Rock_Ice_Permafrost"
    },
    {
      "x": -37,
      "y": 4,
      "z": 6,
      "name": "Rock_Ice_Permafrost"
    },
    {
      "x": -37,
      "y": 5,
      "z": 6,
      "name": "Rock_Ice_Permafrost"
    },
    {
      "x": -37,
      "y": 6,
      "z": 6,
      "name": "Rock_Ice_Permafrost"
    },
    {
      "x": -37,
      "y": 7,
      "z": 6,
      "name": "Rock_Ice_Permafrost"
    },
    {
      "x": -37,
      "y": 8,
      "z": 6,
      "name": "Rock_Ice_Permafrost"
    },
    {
      "x": -37,
      "y": 3,
      "z": 7,
      "name": "Rock_Ice_Permafrost"
    },
    {
      "x": -37,
      "y": 4,
      "z": 7,
      "name": "Rock_Ice_Permafrost"
    },
    {
      "x": -37,
      "y": 5,
      "z": 7,
      "name": "Rock_Ice_Permafrost"
    },
    {
      "x": -37,
      "y": 6,
      "z": 7,
      "name": "Rock_Ice_Permafrost"
    },
    {
      "x": -37,
      "y": -9,
      "z": 22,
      "name": "Rock_Ice_Permafrost"
    },
    {
      "x": -37,
      "y": -8,
      "z": 22,
      "name": "Rock_Ice_Permafrost"
    },
    {
      "x": -37,
      "y": -9,
      "z": 23,
      "name": "Rock_Ice_Permafrost"
    },
    {
      "x": -36,
      "y": -38,
      "z": -15,
      "name": "Rock_Ice_Permafrost"
    },
    {
      "x": -36,
      "y": -37,
      "z": -15,
      "name": "Rock_Ice_Permafrost"
    },
    {
      "x": -36,
      "y": -36,
      "z": -15,
      "name": "Rock_Ice_Permafrost"
    },
    {
      "x": -36,
      "y": -37,
      "z": -14,
      "name": "Rock_Ice_Permafrost"
    },
    {
      "x": -36,
      "y": -36,
      "z": -14,
      "name": "Rock_Ice_Permafrost"
    },
    {
      "x": -36,
      "y": -35,
      "z": -14,
      "name": "Rock_Ice_Permafrost"
    },
    {
      "x": -36,
      "y": -37,
      "z": -13,
      "name": "Rock_Ice_Permafrost"
    },
    {
      "x": -36,
      "y": -36,
      "z": -13,
      "name": "Rock_Ice_Permafrost"
    },
    {
      "x": -36,
      "y": 11,
      "z": -7,
      "name": "Rock_Ice_Permafrost"
    },
    {
      "x": -36,
      "y": 8,
      "z": -6,
      "name": "Rock_Ice_Permafrost"
    },
    {
      "x": -36,
      "y": 9,
      "z": -6,
      "name": "Rock_Ice_Permafrost"
    },
    {
      "x": -36,
      "y": 10,
      "z": -6,
      "name": "Rock_Ice_Permafrost"
    },
    {
      "x": -36,
      "y": 11,
      "z": -6,
      "name": "Rock_Ice_Permafrost"
    },
    {
      "x": -36,
      "y": 12,
      "z": -6,
      "name": "Rock_Ice_Permafrost"
    },
    {
      "x": -36,
      "y": 13,
      "z": -6,
      "name": "Rock_Ice_Permafrost"
    },
    {
      "x": -36,
      "y": 7,
      "z": -5,
      "name": "Rock_Ice_Permafrost"
    },
    {
      "x": -36,
      "y": 8,
      "z": -5,
      "name": "Rock_Ice_Permafrost"
    },
    {
      "x": -36,
      "y": 9,
      "z": -5,
      "name": "Rock_Ice_Permafrost"
    },
    {
      "x": -36,
      "y": 12,
      "z": -5,
      "name": "Rock_Ice_Permafrost"
    },
    {
      "x": -36,
      "y": 13,
      "z": -5,
      "name": "Rock_Ice_Permafrost"
    },
    {
      "x": -36,
      "y": 14,
      "z": -5,
      "name": "Rock_Ice_Permafrost"
    },
    {
      "x": -36,
      "y": 15,
      "z": -5,
      "name": "Rock_Ice_Permafrost"
    },
    {
      "x": -36,
      "y": 7,
      "z": -4,
      "name": "Rock_Ice_Permafrost"
    },
    {
      "x": -36,
      "y": 8,
      "z": -4,
      "name": "Rock_Ice_Permafrost"
    },
    {
      "x": -36,
      "y": 13,
      "z": -4,
      "name": "Rock_Ice_Permafrost"
    },
    {
      "x": -36,
      "y": 14,
      "z": -4,
      "name": "Rock_Ice_Permafrost"
    },
    {
      "x": -36,
      "y": 15,
      "z": -4,
      "name": "Rock_Ice_Permafrost"
    },
    {
      "x": -36,
      "y": 7,
      "z": -3,
      "name": "Rock_Ice_Permafrost"
    },
    {
      "x": -36,
      "y": 8,
      "z": -3,
      "name": "Rock_Ice_Permafrost"
    },
    {
      "x": -36,
      "y": 9,
      "z": -3,
      "name": "Rock_Ice_Permafrost"
    },
    {
      "x": -36,
      "y": 13,
      "z": -3,
      "name": "Rock_Ice_Permafrost"
    },
    {
      "x": -36,
      "y": 14,
      "z": -3,
      "name": "Rock_Ice_Permafrost"
    },
    {
      "x": -36,
      "y": 8,
      "z": -2,
      "name": "Rock_Ice_Permafrost"
    },
    {
      "x": -36,
      "y": 9,
      "z": -2,
      "name": "Rock_Ice_Permafrost"
    },
    {
      "x": -36,
      "y": 10,
      "z": -2,
      "name": "Rock_Ice_Permafrost"
    },
    {
      "x": -36,
      "y": 11,
      "z": -2,
      "name": "Rock_Ice_Permafrost"
    },
    {
      "x": -36,
      "y": 12,
      "z": -2,
      "name": "Rock_Ice_Permafrost"
    },
    {
      "x": -36,
      "y": 13,
      "z": -2,
      "name": "Rock_Ice_Permafrost"
    },
    {
      "x": -36,
      "y": 10,
      "z": -1,
      "name": "Rock_Ice_Permafrost"
    },
    {
      "x": -36,
      "y": 11,
      "z": -1,
      "name": "Rock_Ice_Permafrost"
    },
    {
      "x": -36,
      "y": 12,
      "z": -1,
      "name": "Rock_Ice_Permafrost"
    },
    {
      "x": -36,
      "y": 13,
      "z": -1,
      "name": "Rock_Ice_Permafrost"
    },
    {
      "x": -36,
      "y": -21,
      "z": 0,
      "name": "Rock_Ice_Permafrost"
    },
    {
      "x": -36,
      "y": -20,
      "z": 0,
      "name": "Rock_Ice_Permafrost"
    },
    {
      "x": -36,
      "y": -22,
      "z": 1,
      "name": "Rock_Ice_Permafrost"
    },
    {
      "x": -36,
      "y": -21,
      "z": 1,
      "name": "Rock_Ice_Permafrost"
    },
    {
      "x": -36,
      "y": -20,
      "z": 1,
      "name": "Rock_Ice_Permafrost"
    },
    {
      "x": -36,
      "y": 4,
      "z": 1,
      "name": "Rock_Ice_Permafrost"
    },
    {
      "x": -36,
      "y": -21,
      "z": 2,
      "name": "Rock_Ice_Permafrost"
    },
    {
      "x": -36,
      "y": -20,
      "z": 2,
      "name": "Rock_Ice_Permafrost"
    },
    {
      "x": -36,
      "y": 2,
      "z": 2,
      "name": "Rock_Ice_Permafrost"
    },
    {
      "x": -36,
      "y": 3,
      "z": 2,
      "name": "Rock_Ice_Permafrost"
    },
    {
      "x": -36,
      "y": 4,
      "z": 2,
      "name": "Rock_Ice_Permafrost"
    },
    {
      "x": -36,
      "y": 5,
      "z": 2,
      "name": "Rock_Ice_Permafrost"
    },
    {
      "x": -36,
      "y": 6,
      "z": 2,
      "name": "Rock_Ice_Permafrost"
    },
    {
      "x": -36,
      "y": 2,
      "z": 3,
      "name": "Rock_Ice_Permafrost"
    },
    {
      "x": -36,
      "y": 3,
      "z": 3,
      "name": "Rock_Ice_Permafrost"
    },
    {
      "x": -36,
      "y": 5,
      "z": 3,
      "name": "Rock_Ice_Permafrost"
    },
    {
      "x": -36,
      "y": 6,
      "z": 3,
      "name": "Rock_Ice_Permafrost"
    },
    {
      "x": -36,
      "y": 7,
      "z": 3,
      "name": "Rock_Ice_Permafrost"
    },
    {
      "x": -36,
      "y": 2,
      "z": 4,
      "name": "Rock_Ice_Permafrost"
    },
    {
      "x": -36,
      "y": 3,
      "z": 4,
      "name": "Rock_Ice_Permafrost"
    },
    {
      "x": -36,
      "y": 6,
      "z": 4,
      "name": "Rock_Ice_Permafrost"
    },
    {
      "x": -36,
      "y": 7,
      "z": 4,
      "name": "Rock_Ice_Permafrost"
    },
    {
      "x": -36,
      "y": 2,
      "z": 5,
      "name": "Rock_Ice_Permafrost"
    },
    {
      "x": -36,
      "y": 3,
      "z": 5,
      "name": "Rock_Ice_Permafrost"
    },
    {
      "x": -36,
      "y": 6,
      "z": 5,
      "name": "Rock_Ice_Permafrost"
    },
    {
      "x": -36,
      "y": 7,
      "z": 5,
      "name": "Rock_Ice_Permafrost"
    },
    {
      "x": -36,
      "y": 2,
      "z": 6,
      "name": "Rock_Ice_Permafrost"
    },
    {
      "x": -36,
      "y": 3,
      "z": 6,
      "name": "Rock_Ice_Permafrost"
    },
    {
      "x": -36,
      "y": 4,
      "z": 6,
      "name": "Rock_Ice_Permafrost"
    },
    {
      "x": -36,
      "y": 5,
      "z": 6,
      "name": "Rock_Ice_Permafrost"
    },
    {
      "x": -36,
      "y": 6,
      "z": 6,
      "name": "Rock_Ice_Permafrost"
    },
    {
      "x": -36,
      "y": 7,
      "z": 6,
      "name": "Rock_Ice_Permafrost"
    },
    {
      "x": -36,
      "y": 3,
      "z": 7,
      "name": "Rock_Ice_Permafrost"
    },
    {
      "x": -36,
      "y": 4,
      "z": 7,
      "name": "Rock_Ice_Permafrost"
    },
    {
      "x": -36,
      "y": 5,
      "z": 7,
      "name": "Rock_Ice_Permafrost"
    },
    {
      "x": -36,
      "y": 6,
      "z": 7,
      "name": "Rock_Ice_Permafrost"
    },
    {
      "x": -36,
      "y": -9,
      "z": 21,
      "name": "Rock_Ice_Permafrost"
    },
    {
      "x": -36,
      "y": -9,
      "z": 22,
      "name": "Rock_Ice_Permafrost"
    },
    {
      "x": -36,
      "y": -8,
      "z": 22,
      "name": "Rock_Ice_Permafrost"
    },
    {
      "x": -36,
      "y": -21,
      "z": 32,
      "name": "Rock_Ice_Permafrost"
    },
    {
      "x": -36,
      "y": -21,
      "z": 33,
      "name": "Rock_Ice_Permafrost"
    },
    {
      "x": -35,
      "y": -37,
      "z": -15,
      "name": "Rock_Ice_Permafrost"
    },
    {
      "x": -35,
      "y": -36,
      "z": -15,
      "name": "Rock_Ice_Permafrost"
    },
    {
      "x": -35,
      "y": -35,
      "z": -15,
      "name": "Rock_Ice_Permafrost"
    },
    {
      "x": -35,
      "y": -37,
      "z": -14,
      "name": "Rock_Ice_Permafrost"
    },
    {
      "x": -35,
      "y": -36,
      "z": -14,
      "name": "Rock_Ice_Permafrost"
    },
    {
      "x": -35,
      "y": -35,
      "z": -14,
      "name": "Rock_Ice_Permafrost"
    },
    {
      "x": -35,
      "y": -34,
      "z": -14,
      "name": "Rock_Ice_Permafrost"
    },
    {
      "x": -35,
      "y": -36,
      "z": -13,
      "name": "Rock_Ice_Permafrost"
    },
    {
      "x": -35,
      "y": -35,
      "z": -13,
      "name": "Rock_Ice_Permafrost"
    },
    {
      "x": -35,
      "y": -34,
      "z": -13,
      "name": "Rock_Ice_Permafrost"
    },
    {
      "x": -35,
      "y": 10,
      "z": -7,
      "name": "Rock_Ice_Permafrost"
    },
    {
      "x": -35,
      "y": 7,
      "z": -6,
      "name": "Rock_Ice_Permafrost"
    },
    {
      "x": -35,
      "y": 8,
      "z": -6,
      "name": "Rock_Ice_Permafrost"
    },
    {
      "x": -35,
      "y": 9,
      "z": -6,
      "name": "Rock_Ice_Permafrost"
    },
    {
      "x": -35,
      "y": 10,
      "z": -6,
      "name": "Rock_Ice_Permafrost"
    },
    {
      "x": -35,
      "y": 11,
      "z": -6,
      "name": "Rock_Ice_Permafrost"
    },
    {
      "x": -35,
      "y": 12,
      "z": -6,
      "name": "Rock_Ice_Permafrost"
    },
    {
      "x": -35,
      "y": 7,
      "z": -5,
      "name": "Rock_Ice_Permafrost"
    },
    {
      "x": -35,
      "y": 8,
      "z": -5,
      "name": "Rock_Ice_Permafrost"
    },
    {
      "x": -35,
      "y": 11,
      "z": -5,
      "name": "Rock_Ice_Permafrost"
    },
    {
      "x": -35,
      "y": 12,
      "z": -5,
      "name": "Rock_Ice_Permafrost"
    },
    {
      "x": -35,
      "y": 13,
      "z": -5,
      "name": "Rock_Ice_Permafrost"
    },
    {
      "x": -35,
      "y": 14,
      "z": -5,
      "name": "Rock_Ice_Permafrost"
    },
    {
      "x": -35,
      "y": 7,
      "z": -4,
      "name": "Rock_Ice_Permafrost"
    },
    {
      "x": -35,
      "y": 8,
      "z": -4,
      "name": "Rock_Ice_Permafrost"
    },
    {
      "x": -35,
      "y": 13,
      "z": -4,
      "name": "Rock_Ice_Permafrost"
    },
    {
      "x": -35,
      "y": 14,
      "z": -4,
      "name": "Rock_Ice_Permafrost"
    },
    {
      "x": -35,
      "y": 6,
      "z": -3,
      "name": "Rock_Ice_Permafrost"
    },
    {
      "x": -35,
      "y": 7,
      "z": -3,
      "name": "Rock_Ice_Permafrost"
    },
    {
      "x": -35,
      "y": 8,
      "z": -3,
      "name": "Rock_Ice_Permafrost"
    },
    {
      "x": -35,
      "y": 12,
      "z": -3,
      "name": "Rock_Ice_Permafrost"
    },
    {
      "x": -35,
      "y": 13,
      "z": -3,
      "name": "Rock_Ice_Permafrost"
    },
    {
      "x": -35,
      "y": 14,
      "z": -3,
      "name": "Rock_Ice_Permafrost"
    },
    {
      "x": -35,
      "y": 7,
      "z": -2,
      "name": "Rock_Ice_Permafrost"
    },
    {
      "x": -35,
      "y": 8,
      "z": -2,
      "name": "Rock_Ice_Permafrost"
    },
    {
      "x": -35,
      "y": 9,
      "z": -2,
      "name": "Rock_Ice_Permafrost"
    },
    {
      "x": -35,
      "y": 10,
      "z": -2,
      "name": "Rock_Ice_Permafrost"
    },
    {
      "x": -35,
      "y": 11,
      "z": -2,
      "name": "Rock_Ice_Permafrost"
    },
    {
      "x": -35,
      "y": 12,
      "z": -2,
      "name": "Rock_Ice_Permafrost"
    },
    {
      "x": -35,
      "y": 13,
      "z": -2,
      "name": "Rock_Ice_Permafrost"
    },
    {
      "x": -35,
      "y": 9,
      "z": -1,
      "name": "Rock_Ice_Permafrost"
    },
    {
      "x": -35,
      "y": 10,
      "z": -1,
      "name": "Rock_Ice_Permafrost"
    },
    {
      "x": -35,
      "y": 11,
      "z": -1,
      "name": "Rock_Ice_Permafrost"
    },
    {
      "x": -35,
      "y": 12,
      "z": -1,
      "name": "Rock_Ice_Permafrost"
    },
    {
      "x": -35,
      "y": -21,
      "z": 0,
      "name": "Rock_Ice_Permafrost"
    },
    {
      "x": -35,
      "y": -20,
      "z": 0,
      "name": "Rock_Ice_Permafrost"
    },
    {
      "x": -35,
      "y": -21,
      "z": 1,
      "name": "Rock_Ice_Permafrost"
    },
    {
      "x": -35,
      "y": -20,
      "z": 1,
      "name": "Rock_Ice_Permafrost"
    },
    {
      "x": -35,
      "y": -19,
      "z": 1,
      "name": "Rock_Ice_Permafrost"
    },
    {
      "x": -35,
      "y": 3,
      "z": 1,
      "name": "Rock_Ice_Permafrost"
    },
    {
      "x": -35,
      "y": 4,
      "z": 1,
      "name": "Rock_Ice_Permafrost"
    },
    {
      "x": -35,
      "y": -21,
      "z": 2,
      "name": "Rock_Ice_Permafrost"
    },
    {
      "x": -35,
      "y": -20,
      "z": 2,
      "name": "Rock_Ice_Permafrost"
    },
    {
      "x": -35,
      "y": -19,
      "z": 2,
      "name": "Rock_Ice_Permafrost"
    },
    {
      "x": -35,
      "y": 2,
      "z": 2,
      "name": "Rock_Ice_Permafrost"
    },
    {
      "x": -35,
      "y": 3,
      "z": 2,
      "name": "Rock_Ice_Permafrost"
    },
    {
      "x": -35,
      "y": 4,
      "z": 2,
      "name": "Rock_Ice_Permafrost"
    },
    {
      "x": -35,
      "y": 5,
      "z": 2,
      "name": "Rock_Ice_Permafrost"
    },
    {
      "x": -35,
      "y": 1,
      "z": 3,
      "name": "Rock_Ice_Permafrost"
    },
    {
      "x": -35,
      "y": 2,
      "z": 3,
      "name": "Rock_Ice_Permafrost"
    },
    {
      "x": -35,
      "y": 3,
      "z": 3,
      "name": "Rock_Ice_Permafrost"
    },
    {
      "x": -35,
      "y": 5,
      "z": 3,
      "name": "Rock_Ice_Permafrost"
    },
    {
      "x": -35,
      "y": 6,
      "z": 3,
      "name": "Rock_Ice_Permafrost"
    },
    {
      "x": -35,
      "y": 1,
      "z": 4,
      "name": "Rock_Ice_Permafrost"
    },
    {
      "x": -35,
      "y": 2,
      "z": 4,
      "name": "Rock_Ice_Permafrost"
    },
    {
      "x": -35,
      "y": 6,
      "z": 4,
      "name": "Rock_Ice_Permafrost"
    },
    {
      "x": -35,
      "y": 7,
      "z": 4,
      "name": "Rock_Ice_Permafrost"
    },
    {
      "x": -35,
      "y": 1,
      "z": 5,
      "name": "Rock_Ice_Permafrost"
    },
    {
      "x": -35,
      "y": 2,
      "z": 5,
      "name": "Rock_Ice_Permafrost"
    },
    {
      "x": -35,
      "y": 6,
      "z": 5,
      "name": "Rock_Ice_Permafrost"
    },
    {
      "x": -35,
      "y": 7,
      "z": 5,
      "name": "Rock_Ice_Permafrost"
    },
    {
      "x": -35,
      "y": 1,
      "z": 6,
      "name": "Rock_Ice_Permafrost"
    },
    {
      "x": -35,
      "y": 2,
      "z": 6,
      "name": "Rock_Ice_Permafrost"
    },
    {
      "x": -35,
      "y": 3,
      "z": 6,
      "name": "Rock_Ice_Permafrost"
    },
    {
      "x": -35,
      "y": 4,
      "z": 6,
      "name": "Rock_Ice_Permafrost"
    },
    {
      "x": -35,
      "y": 5,
      "z": 6,
      "name": "Rock_Ice_Permafrost"
    },
    {
      "x": -35,
      "y": 6,
      "z": 6,
      "name": "Rock_Ice_Permafrost"
    },
    {
      "x": -35,
      "y": 7,
      "z": 6,
      "name": "Rock_Ice_Permafrost"
    },
    {
      "x": -35,
      "y": 3,
      "z": 7,
      "name": "Rock_Ice_Permafrost"
    },
    {
      "x": -35,
      "y": 4,
      "z": 7,
      "name": "Rock_Ice_Permafrost"
    },
    {
      "x": -35,
      "y": 5,
      "z": 7,
      "name": "Rock_Ice_Permafrost"
    },
    {
      "x": -35,
      "y": -10,
      "z": 20,
      "name": "Rock_Ice_Permafrost"
    },
    {
      "x": -35,
      "y": -9,
      "z": 20,
      "name": "Rock_Ice_Permafrost"
    },
    {
      "x": -35,
      "y": -8,
      "z": 20,
      "name": "Rock_Ice_Permafrost"
    },
    {
      "x": -35,
      "y": -10,
      "z": 21,
      "name": "Rock_Ice_Permafrost"
    },
    {
      "x": -35,
      "y": -9,
      "z": 21,
      "name": "Rock_Ice_Permafrost"
    },
    {
      "x": -35,
      "y": -8,
      "z": 21,
      "name": "Rock_Ice_Permafrost"
    },
    {
      "x": -35,
      "y": -9,
      "z": 22,
      "name": "Rock_Ice_Permafrost"
    },
    {
      "x": -35,
      "y": -8,
      "z": 22,
      "name": "Rock_Ice_Permafrost"
    },
    {
      "x": -35,
      "y": -21,
      "z": 31,
      "name": "Rock_Ice_Permafrost"
    },
    {
      "x": -35,
      "y": -22,
      "z": 32,
      "name": "Rock_Ice_Permafrost"
    },
    {
      "x": -35,
      "y": -21,
      "z": 32,
      "name": "Rock_Ice_Permafrost"
    },
    {
      "x": -35,
      "y": -20,
      "z": 32,
      "name": "Rock_Ice_Permafrost"
    },
    {
      "x": -34,
      "y": -36,
      "z": -15,
      "name": "Rock_Ice_Permafrost"
    },
    {
      "x": -34,
      "y": -35,
      "z": -15,
      "name": "Rock_Ice_Permafrost"
    },
    {
      "x": -34,
      "y": -36,
      "z": -14,
      "name": "Rock_Ice_Permafrost"
    },
    {
      "x": -34,
      "y": -35,
      "z": -14,
      "name": "Rock_Ice_Permafrost"
    },
    {
      "x": -34,
      "y": -34,
      "z": -14,
      "name": "Rock_Ice_Permafrost"
    },
    {
      "x": -34,
      "y": -33,
      "z": -14,
      "name": "Rock_Ice_Permafrost"
    },
    {
      "x": -34,
      "y": -36,
      "z": -13,
      "name": "Rock_Ice_Permafrost"
    },
    {
      "x": -34,
      "y": -35,
      "z": -13,
      "name": "Rock_Ice_Permafrost"
    },
    {
      "x": -34,
      "y": -34,
      "z": -13,
      "name": "Rock_Ice_Permafrost"
    },
    {
      "x": -34,
      "y": -33,
      "z": -13,
      "name": "Rock_Ice_Permafrost"
    },
    {
      "x": -34,
      "y": -35,
      "z": -12,
      "name": "Rock_Ice_Permafrost"
    },
    {
      "x": -34,
