{
  "version": 8,
  "blockIdVersion": 11,
  "anchorX": 0,
  "anchorY": 0,
  "anchorZ": 0,
  "blocks": [
    {
      "x": -41,
      "y": 1,
      "z": 13,
      "name": "Rock_Ice_Permafrost"
    },
    {
      "x": -41,
      "y": 1,
      "z": 14,
      "name": "Rock_Ice_Permafrost"
    },
    {
      "x": -40,
      "y": 1,
      "z": 13,
      "name": "Rock_Ice_Permafrost"
    },
    {
      "x": -40,
      "y": 1,
      "z": 14,
      "name": "Rock_Ice_Permafrost"
    },
    {
      "x": -39,
      "y": 0,
      "z": 12,
      "name": "Rock_Ice_Permafrost"
    },
    {
      "x": -39,
      "y": 1,
      "z": 12,
      "name": "Rock_Ice_Permafrost"
    },
    {
      "x": -39,
      "y": 0,
      "z": 13,
      "name": "Rock_Ice_Permafrost"
    },
    {
      "x": -39,
      "y": 1,
      "z": 13,
      "name": "Rock_Ice_Permafrost"
    },
    {
      "x": -39,
      "y": 0,
      "z": 14,
      "name": "Rock_Ice_Permafrost"
    },
    {
      "x": -39,
      "y": 1,
      "z": 14,
      "name": "Rock_Ice_Permafrost"
    },
    {
      "x": -38,
      "y": 0,
      "z": 12,
      "name": "Rock_Ice_Permafrost"
    },
    {
      "x": -38,
      "y": 1,
      "z": 12,
      "name": "Rock_Ice_Permafrost"
    },
    {
      "x": -38,
      "y": 0,
      "z": 13,
      "name": "Rock_Ice_Permafrost"
    },
    {
      "x": -38,
      "y": 1,
      "z": 13,
      "name": "Rock_Ice_Permafrost"
    },
    {
      "x": -38,
      "y": 0,
      "z": 14,
      "name": "Rock_Ice_Permafrost"
    },
    {
      "x": -37,
      "y": 0,
      "z": 11,
      "name": "Rock_Ice_Permafrost"
    },
    {
      "x": -37,
      "y": 0,
      "z": 12,
      "name": "Rock_Ice_Permafrost"
    },
    {
      "x": -37,
      "y": 1,
      "z": 12,
      "name": "Rock_Ice_Permafrost"
    },
    {
      "x": -37,
      "y": -1,
      "z": 13,
      "name": "Rock_Ice_Permafrost"
    },
    {
      "x": -37,
      "y": 0,
      "z": 13,
      "name": "Rock_Ice_Permafrost"
    },
    {
      "x": -37,
      "y": 1,
      "z": 13,
      "name": "Rock_Ice_Permafrost"
    },
    {
      "x": -36,
      "y": 0,
      "z": 10,
      "name": "Rock_Ice_Permafrost"
    },
    {
      "x": -36,
      "y": -1,
      "z": 11,
      "name": "Rock_Ice_Permafrost"
    },
    {
      "x": -36,
      "y": 0,
      "z": 11,
      "name": "Rock_Ice_Permafrost"
    },
    {
      "x": -36,
      "y": -1,
      "z": 12,
      "name": "Rock_Ice_Permafrost"
    },
    {
      "x": -36,
      "y": 0,
      "z": 12,
      "name": "Rock_Ice_Permafrost"
    },
    {
      "x": -36,
      "y": 1,
      "z": 12,
      "name": "Rock_Ice_Permafrost"
    },
    {
      "x": -36,
      "y": -1,
      "z": 13,
      "name": "Rock_Ice_Permafrost"
    },
    {
      "x": -36,
      "y": 0,
      "z": 13,
      "name": "Rock_Ice_Permafrost"
    },
    {
      "x": -36,
      "y": 1,
      "z": 13,
      "name": "Rock_Ice_Permafrost"
    },
    {
      "x": -35,
      "y": -1,
      "z": 10,
      "name": "Rock_Ice_Permafrost"
    },
    {
      "x": -35,
      "y": 0,
      "z": 10,
      "name": "Rock_Ice_Permafrost"
    },
    {
      "x": -35,
      "y": -1,
      "z": 11,
      "name": "Rock_Ice_Permafrost"
    },
    {
      "x": -35,
      "y": 0,
      "z": 11,
      "name": "Rock_Ice_Permafrost"
    },
    {
      "x": -35,
      "y": 1,
      "z": 11,
      "name": "Rock_Ice_Permafrost"
    },
    {
      "x": -35,
      "y": -1,
      "z": 12,
      "name": "Rock_Ice_Permafrost"
    },
    {
      "x": -35,
      "y": 0,
      "z": 12,
      "name": "Rock_Ice_Permafrost"
    },
    {
      "x": -35,
      "y": 1,
      "z": 12,
      "name": "Rock_Ice_Permafrost"
    },
    {
      "x": -35,
      "y": -1,
      "z": 13,
      "name": "Rock_Ice_Permafrost"
    },
    {
      "x": -35,
      "y": 0,
      "z": 13,
      "name": "Rock_Ice_Permafrost"
    },
    {
      "x": -34,
      "y": -1,
      "z": 10,
      "name": "Rock_Ice_Permafrost"
    },
    {
      "x": -34,
      "y": 0,
      "z": 10,
      "name": "Rock_Ice_Permafrost"
    },
    {
      "x": -34,
      "y": -1,
      "z": 11,
      "name": "Rock_Ice_Permafrost"
    },
    {
      "x": -34,
      "y": 0,
      "z": 11,
      "name": "Rock_Ice_Permafrost"
    },
    {
      "x": -34,
      "y": 1,
      "z": 11,
      "name": "Rock_Ice_Permafrost"
    },
    {
      "x": -34,
      "y": -2,
      "z": 12,
      "name": "Rock_Ice_Permafrost"
    },
    {
      "x": -34,
      "y": -1,
      "z": 12,
      "name": "Rock_Ice_Permafrost"
    },
    {
      "x": -34,
      "y": 0,
      "z": 12,
      "name": "Rock_Ice_Permafrost"
    },
    {
      "x": -34,
      "y": 1,
      "z": 12,
      "name": "Rock_Ice_Permafrost"
    },
    {
      "x": -34,
      "y": -1,
      "z": 13,
      "name": "Rock_Ice_Permafrost"
    },
    {
      "x": -34,
      "y": 0,
      "z": 13,
      "name": "Rock_Ice_Permafrost"
    },
    {
      "x": -33,
      "y": -1,
      "z": 9,
      "name": "Rock_Ice_Permafrost"
    },
    {
      "x": -33,
      "y": -1,
      "z": 10,
      "name": "Rock_Ice_Permafrost"
    },
    {
      "x": -33,
      "y": 0,
      "z": 10,
      "name": "Rock_Ice_Permafrost"
    },
    {
      "x": -33,
      "y": -2,
      "z": 11,
      "name": "Rock_Ice_Permafrost"
    },
    {
      "x": -33,
      "y": -1,
      "z": 11,
      "name": "Rock_Ice_Permafrost"
    },
    {
      "x": -33,
      "y": 0,
      "z": 11,
      "name": "Rock_Ice_Permafrost"
    },
    {
      "x": -33,
      "y": 1,
      "z": 11,
      "name": "Rock_Ice_Permafrost"
    },
    {
      "x": -33,
      "y": -2,
      "z": 12,
      "name": "Rock_Ice_Permafrost"
    },
    {
      "x": -33,
      "y": -1,
      "z": 12,
      "name": "Rock_Ice_Permafrost"
    },
    {
      "x": -33,
      "y": 0,
      "z": 12,
      "name": "Rock_Ice_Permafrost"
    },
    {
      "x": -33,
      "y": 1,
      "z": 12,
      "name": "Rock_Ice_Permafrost"
    },
    {
      "x": -32,
      "y": -1,
      "z": 8,
      "name": "Rock_Ice_Permafrost"
    },
    {
      "x": -32,
      "y": 26,
      "z": 8,
      "name": "Rock_Ice_Permafrost"
    },
    {
      "x": -32,
      "y": 27,
      "z": 8,
      "name": "Rock_Ice_Permafrost"
    },
    {
      "x": -32,
      "y": -2,
      "z": 9,
      "name": "Rock_Ice_Permafrost"
    },
    {
      "x": -32,
      "y": -1,
      "z": 9,
      "name": "Rock_Ice_Permafrost"
    },
    {
      "x": -32,
      "y": 0,
      "z": 9,
      "name": "Rock_Ice_Permafrost"
    },
    {
      "x": -32,
      "y": -2,
      "z": 10,
      "name": "Rock_Ice_Permafrost"
    },
    {
      "x": -32,
      "y": -1,
      "z": 10,
      "name": "Rock_Ice_Permafrost"
    },
    {
      "x": -32,
      "y": 0,
      "z": 10,
      "name": "Rock_Ice_Permafrost"
    },
    {
      "x": -32,
      "y": -3,
      "z": 11,
      "name": "Rock_Ice_Permafrost"
    },
    {
      "x": -32,
      "y": -2,
      "z": 11,
      "name": "Rock_Ice_Permafrost"
    },
    {
      "x": -32,
      "y": -1,
      "z": 11,
      "name": "Rock_Ice_Permafrost"
    },
    {
      "x": -32,
      "y": 0,
      "z": 11,
      "name": "Rock_Ice_Permafrost"
    },
    {
      "x": -32,
      "y": 1,
      "z": 11,
      "name": "Rock_Ice_Permafrost"
    },
    {
      "x": -32,
      "y": -2,
      "z": 12,
      "name": "Rock_Ice_Permafrost"
    },
    {
      "x": -32,
      "y": -1,
      "z": 12,
      "name": "Rock_Ice_Permafrost"
    },
    {
      "x": -32,
      "y": 0,
      "z": 12,
      "name": "Rock_Ice_Permafrost"
    },
    {
      "x": -31,
      "y": 24,
      "z": 7,
      "name": "Rock_Ice_Permafrost"
    },
    {
      "x": -31,
      "y": 25,
      "z": 7,
      "name": "Rock_Ice_Permafrost"
    },
    {
      "x": -31,
      "y": -2,
      "z": 8,
      "name": "Rock_Ice_Permafrost"
    },
    {
      "x": -31,
      "y": -1,
      "z": 8,
      "name": "Rock_Ice_Permafrost"
    },
    {
      "x": -31,
      "y": 24,
      "z": 8,
      "name": "Rock_Ice_Permafrost"
    },
    {
      "x": -31,
      "y": 25,
      "z": 8,
      "name": "Rock_Ice_Permafrost"
    },
    {
      "x": -31,
      "y": 26,
      "z": 8,
      "name": "Rock_Ice_Permafrost"
    },
    {
      "x": -31,
      "y": -2,
      "z": 9,
      "name": "Rock_Ice_Permafrost"
    },
    {
      "x": -31,
      "y": -1,
      "z": 9,
      "name": "Rock_Ice_Permafrost"
    },
    {
      "x": -31,
      "y": 0,
      "z": 9,
      "name": "Rock_Ice_Permafrost"
    },
    {
      "x": -31,
      "y": -2,
      "z": 10,
      "name": "Rock_Ice_Permafrost"
    },
    {
      "x": -31,
      "y": -1,
      "z": 10,
      "name": "Rock_Ice_Permafrost"
    },
    {
      "x": -31,
      "y": 0,
      "z": 10,
      "name": "Rock_Ice_Permafrost"
    },
    {
      "x": -31,
      "y": -3,
      "z": 11,
      "name": "Rock_Ice_Permafrost"
    },
    {
      "x": -31,
      "y": -2,
      "z": 11,
      "name": "Rock_Ice_Permafrost"
    },
    {
      "x": -31,
      "y": -1,
      "z": 11,
      "name": "Rock_Ice_Permafrost"
    },
    {
      "x": -31,
      "y": 0,
      "z": 11,
      "name": "Rock_Ice_Permafrost"
    },
    {
      "x": -31,
      "y": -3,
      "z": 12,
      "name": "Rock_Ice_Permafrost"
    },
    {
      "x": -31,
      "y": -2,
      "z": 12,
      "name": "Rock_Ice_Permafrost"
    },
    {
      "x": -31,
      "y": -1,
      "z": 12,
      "name": "Rock_Ice_Permafrost"
    },
    {
      "x": -31,
      "y": 0,
      "z": 12,
      "name": "Rock_Ice_Permafrost"
    },
    {
      "x": -30,
      "y": -2,
      "z": 7,
      "name": "Rock_Ice_Permafrost"
    },
    {
      "x": -30,
      "y": 23,
      "z": 7,
      "name": "Rock_Ice_Permafrost"
    },
    {
      "x": -30,
      "y": 24,
      "z": 7,
      "name": "Rock_Ice_Permafrost"
    },
    {
      "x": -30,
      "y": -2,
      "z": 8,
      "name": "Rock_Ice_Permafrost"
    },
    {
      "x": -30,
      "y": -1,
      "z": 8,
      "name": "Rock_Ice_Permafrost"
    },
    {
      "x": -30,
      "y": 23,
      "z": 8,
      "name": "Rock_Ice_Permafrost"
    },
    {
      "x": -30,
      "y": 24,
      "z": 8,
      "name": "Rock_Ice_Permafrost"
    },
    {
      "x": -30,
      "y": 25,
      "z": 8,
      "name": "Rock_Ice_Permafrost"
    },
    {
      "x": -30,
      "y": -2,
      "z": 9,
      "name": "Rock_Ice_Permafrost"
    },
    {
      "x": -30,
      "y": -1,
      "z": 9,
      "name": "Rock_Ice_Permafrost"
    },
    {
      "x": -30,
      "y": 0,
      "z": 9,
      "name": "Rock_Ice_Permafrost"
    },
    {
      "x": -30,
      "y": -3,
      "z": 10,
      "name": "Rock_Ice_Permafrost"
    },
    {
      "x": -30,
      "y": -2,
      "z": 10,
      "name": "Rock_Ice_Permafrost"
    },
    {
      "x": -30,
      "y": 0,
      "z": 10,
      "name": "Rock_Ice_Permafrost"
    },
    {
      "x": -30,
      "y": 11,
      "z": 10,
      "name": "Rock_Ice_Permafrost"
    },
    {
      "x": -30,
      "y": 12,
      "z": 10,
      "name": "Rock_Ice_Permafrost"
    },
    {
      "x": -30,
      "y": -3,
      "z": 11,
      "name": "Rock_Ice_Permafrost"
    },
    {
      "x": -30,
      "y": -2,
      "z": 11,
      "name": "Rock_Ice_Permafrost"
    },
    {
      "x": -30,
      "y": -1,
      "z": 11,
      "name": "Rock_Ice_Permafrost"
    },
    {
      "x": -30,
      "y": 0,
      "z": 11,
      "name": "Rock_Ice_Permafrost"
    },
    {
      "x": -30,
      "y": -3,
      "z": 12,
      "name": "Rock_Ice_Permafrost"
    },
    {
      "x": -30,
      "y": -2,
      "z": 12,
      "name": "Rock_Ice_Permafrost"
    },
    {
      "x": -30,
      "y": -1,
      "z": 12,
      "name": "Rock_Ice_Permafrost"
    },
    {
      "x": -29,
      "y": -2,
      "z": 7,
      "name": "Rock_Ice_Permafrost"
    },
    {
      "x": -29,
      "y": -1,
      "z": 7,
      "name": "Rock_Ice_Permafrost"
    },
    {
      "x": -29,
      "y": 22,
      "z": 7,
      "name": "Rock_Ice_Permafrost"
    },
    {
      "x": -29,
      "y": 23,
      "z": 7,
      "name": "Rock_Ice_Permafrost"
    },
    {
      "x": -29,
      "y": 24,
      "z": 7,
      "name": "Rock_Ice_Permafrost"
    },
    {
      "x": -29,
      "y": -3,
      "z": 8,
      "name": "Rock_Ice_Permafrost"
    },
    {
      "x": -29,
      "y": -2,
      "z": 8,
      "name": "Rock_Ice_Permafrost"
    },
    {
      "x": -29,
      "y": -1,
      "z": 8,
      "name": "Rock_Ice_Permafrost"
    },
    {
      "x": -29,
      "y": 23,
      "z": 8,
      "name": "Rock_Ice_Permafrost"
    },
    {
      "x": -29,
      "y": 24,
      "z": 8,
      "name": "Rock_Ice_Permafrost"
    },
    {
      "x": -29,
      "y": -3,
      "z": 9,
      "name": "Rock_Ice_Permafrost"
    },
    {
      "x": -29,
      "y": -2,
      "z": 9,
      "name": "Rock_Ice_Permafrost"
    },
    {
      "x": -29,
      "y": -1,
      "z": 9,
      "name": "Rock_Ice_Permafrost"
    },
    {
      "x": -29,
      "y": 0,
      "z": 9,
      "name": "Rock_Ice_Permafrost"
    },
    {
      "x": -29,
      "y": 10,
      "z": 9,
      "name": "Rock_Ice_Permafrost"
    },
    {
      "x": -29,
      "y": 11,
      "z": 9,
      "name": "Rock_Ice_Permafrost"
    },
    {
      "x": -29,
      "y": -3,
      "z": 10,
      "name": "Rock_Ice_Permafrost"
    },
    {
      "x": -29,
      "y": -2,
      "z": 10,
      "name": "Rock_Ice_Permafrost"
    },
    {
      "x": -29,
      "y": -1,
      "z": 10,
      "name": "Rock_Ice_Permafrost"
    },
    {
      "x": -29,
      "y": 0,
      "z": 10,
      "name": "Rock_Ice_Permafrost"
    },
    {
      "x": -29,
      "y": -4,
      "z": 11,
      "name": "Rock_Ice_Permafrost"
    },
    {
      "x": -29,
      "y": -3,
      "z": 11,
      "name": "Rock_Ice_Permafrost"
    },
    {
      "x": -29,
      "y": -2,
      "z": 11,
      "name": "Rock_Ice_Permafrost"
    },
    {
      "x": -29,
      "y": -1,
      "z": 11,
      "name": "Rock_Ice_Permafrost"
    },
    {
      "x": -29,
      "y": 0,
      "z": 11,
      "name": "Rock_Ice_Permafrost"
    },
    {
      "x": -29,
      "y": -3,
      "z": 12,
      "name": "Rock_Ice_Permafrost"
    },
    {
      "x": -28,
      "y": -3,
      "z": 6,
      "name": "Rock_Ice_Permafrost"
    },
    {
      "x": -28,
      "y": -2,
      "z": 6,
      "name": "Rock_Ice_Permafrost"
    },
    {
      "x": -28,
      "y": 22,
      "z": 6,
      "name": "Rock_Ice_Permafrost"
    },
    {
      "x": -28,
      "y": -3,
      "z": 7,
      "name": "Rock_Ice_Permafrost"
    },
    {
      "x": -28,
      "y": -2,
      "z": 7,
      "name": "Rock_Ice_Permafrost"
    },
    {
      "x": -28,
      "y": -1,
      "z": 7,
      "name": "Rock_Ice_Permafrost"
    },
    {
      "x": -28,
      "y": 21,
      "z": 7,
      "name": "Rock_Ice_Permafrost"
    },
    {
      "x": -28,
      "y": 22,
      "z": 7,
      "name": "Rock_Ice_Permafrost"
    },
    {
      "x": -28,
      "y": 23,
      "z": 7,
      "name": "Rock_Ice_Permafrost"
    },
    {
      "x": -28,
      "y": -3,
      "z": 8,
      "name": "Rock_Ice_Permafrost"
    },
    {
      "x": -28,
      "y": -2,
      "z": 8,
      "name": "Rock_Ice_Permafrost"
    },
    {
      "x": -28,
      "y": -1,
      "z": 8,
      "name": "Rock_Ice_Permafrost"
    },
    {
      "x": -28,
      "y": 0,
      "z": 8,
      "name": "Rock_Ice_Permafrost"
    },
    {
      "x": -28,
      "y": 10,
      "z": 8,
      "name": "Rock_Ice_Permafrost"
    },
    {
      "x": -28,
      "y": 22,
      "z": 8,
      "name": "Rock_Ice_Permafrost"
    },
    {
      "x": -28,
      "y": -3,
      "z": 9,
      "name": "Rock_Ice_Permafrost"
    },
    {
      "x": -28,
      "y": -2,
      "z": 9,
      "name": "Rock_Ice_Permafrost"
    },
    {
      "x": -28,
      "y": -1,
      "z": 9,
      "name": "Rock_Ice_Permafrost"
    },
    {
      "x": -28,
      "y": 0,
      "z": 9,
      "name": "Rock_Ice_Permafrost"
    },
    {
      "x": -28,
      "y": 10,
      "z": 9,
      "name": "Rock_Ice_Permafrost"
    },
    {
      "x": -28,
      "y": 11,
      "z": 9,
      "name": "Rock_Ice_Permafrost"
    },
    {
      "x": -28,
      "y": -4,
      "z": 10,
      "name": "Rock_Ice_Permafrost"
    },
    {
      "x": -28,
      "y": -3,
      "z": 10,
      "name": "Rock_Ice_Permafrost"
    },
    {
      "x": -28,
      "y": -2,
      "z": 10,
      "name": "Rock_Ice_Permafrost"
    },
    {
      "x": -28,
      "y": -1,
      "z": 10,
      "name": "Rock_Ice_Permafrost"
    },
    {
      "x": -28,
      "y": 0,
      "z": 10,
      "name": "Rock_Ice_Permafrost"
    },
    {
      "x": -28,
      "y": -4,
      "z": 11,
      "name": "Rock_Ice_Permafrost"
    },
    {
      "x": -28,
      "y": -3,
      "z": 11,
      "name": "Rock_Ice_Permafrost"
    },
    {
      "x": -28,
      "y": -2,
      "z": 11,
      "name": "Rock_Ice_Permafrost"
    },
    {
      "x": -28,
      "y": -1,
      "z": 11,
      "name": "Rock_Ice_Permafrost"
    },
    {
      "x": -28,
      "y": 0,
      "z": 11,
      "name": "Rock_Ice_Permafrost"
    },
    {
      "x": -27,
      "y": -3,
      "z": 6,
      "name": "Rock_Ice_Permafrost"
    },
    {
      "x": -27,
      "y": -2,
      "z": 6,
      "name": "Rock_Ice_Permafrost"
    },
    {
      "x": -27,
      "y": 20,
      "z": 6,
      "name": "Rock_Ice_Permafrost"
    },
    {
      "x": -27,
      "y": 21,
      "z": 6,
      "name": "Rock_Ice_Permafrost"
    },
    {
      "x": -27,
      "y": 22,
      "z": 6,
      "name": "Rock_Ice_Permafrost"
    },
    {
      "x": -27,
      "y": -3,
      "z": 7,
      "name": "Rock_Ice_Permafrost"
    },
    {
      "x": -27,
      "y": -2,
      "z": 7,
      "name": "Rock_Ice_Permafrost"
    },
    {
      "x": -27,
      "y": -1,
      "z": 7,
      "name": "Rock_Ice_Permafrost"
    },
    {
      "x": -27,
      "y": 20,
      "z": 7,
      "name": "Rock_Ice_Permafrost"
    },
    {
      "x": -27,
      "y": 21,
      "z": 7,
      "name": "Rock_Ice_Permafrost"
    },
    {
      "x": -27,
      "y": 22,
      "z": 7,
      "name": "Rock_Ice_Permafrost"
    },
    {
      "x": -27,
      "y": -3,
      "z": 8,
      "name": "Rock_Ice_Permafrost"
    },
    {
      "x": -27,
      "y": -2,
      "z": 8,
      "name": "Rock_Ice_Permafrost"
    },
    {
      "x": -27,
      "y": -1,
      "z": 8,
      "name": "Rock_Ice_Permafrost"
    },
    {
      "x": -27,
      "y": 0,
      "z": 8,
      "name": "Rock_Ice_Permafrost"
    },
    {
      "x": -27,
      "y": 9,
      "z": 8,
      "name": "Rock_Ice_Permafrost"
    },
    {
      "x": -27,
      "y": 10,
      "z": 8,
      "name": "Rock_Ice_Permafrost"
    },
    {
      "x": -27,
      "y": -4,
      "z": 9,
      "name": "Rock_Ice_Permafrost"
    },
    {
      "x": -27,
      "y": -3,
      "z": 9,
      "name": "Rock_Ice_Permafrost"
    },
    {
      "x": -27,
      "y": -1,
      "z": 9,
      "name": "Rock_Ice_Permafrost"
    },
    {
      "x": -27,
      "y": 0,
      "z": 9,
      "name": "Rock_Ice_Permafrost"
    },
    {
      "x": -27,
      "y": 9,
      "z": 9,
      "name": "Rock_Ice_Permafrost"
    },
    {
      "x": -27,
      "y": 10,
      "z": 9,
      "name": "Rock_Ice_Permafrost"
    },
    {
      "x": -27,
      "y": -4,
      "z": 10,
      "name": "Rock_Ice_Permafrost"
    },
    {
      "x": -27,
      "y": -3,
      "z": 10,
      "name": "Rock_Ice_Permafrost"
    },
    {
      "x": -27,
      "y": -2,
      "z": 10,
      "name": "Rock_Ice_Permafrost"
    },
    {
      "x": -27,
      "y": -1,
      "z": 10,
      "name": "Rock_Ice_Permafrost"
    },
    {
      "x": -27,
      "y": 0,
      "z": 10,
      "name": "Rock_Ice_Permafrost"
    },
    {
      "x": -27,
      "y": -4,
      "z": 11,
      "name": "Rock_Ice_Permafrost"
    },
    {
      "x": -27,
      "y": -3,
      "z": 11,
      "name": "Rock_Ice_Permafrost"
    },
    {
      "x": -27,
      "y": -2,
      "z": 11,
      "name": "Rock_Ice_Permafrost"
    },
    {
      "x": -27,
      "y": -1,
      "z": 11,
      "name": "Rock_Ice_Permafrost"
    },
    {
      "x": -26,
      "y": -3,
      "z": 5,
      "name": "Rock_Ice_Permafrost"
    },
    {
      "x": -26,
      "y": -2,
      "z": 5,
      "name": "Rock_Ice_Permafrost"
    },
    {
      "x": -26,
      "y": -3,
      "z": 6,
      "name": "Rock_Ice_Permafrost"
    },
    {
      "x": -26,
      "y": -2,
      "z": 6,
      "name": "Rock_Ice_Permafrost"
    },
    {
      "x": -26,
      "y": 19,
      "z": 6,
      "name": "Rock_Ice_Permafrost"
    },
    {
      "x": -26,
      "y": 20,
      "z": 6,
      "name": "Rock_Ice_Permafrost"
    },
    {
      "x": -26,
      "y": 21,
      "z": 6,
      "name": "Rock_Ice_Permafrost"
    },
    {
      "x": -26,
      "y": 22,
      "z": 6,
      "name": "Rock_Ice_Permafrost"
    },
    {
      "x": -26,
      "y": -3,
      "z": 7,
      "name": "Rock_Ice_Permafrost"
    },
    {
      "x": -26,
      "y": -2,
      "z": 7,
      "name": "Rock_Ice_Permafrost"
    },
    {
      "x": -26,
      "y": -1,
      "z": 7,
      "name": "Rock_Ice_Permafrost"
    },
    {
      "x": -26,
      "y": 8,
      "z": 7,
      "name": "Rock_Ice_Permafrost"
    },
    {
      "x": -26,
      "y": 9,
      "z": 7,
      "name": "Rock_Ice_Permafrost"
    },
    {
      "x": -26,
      "y": 19,
      "z": 7,
      "name": "Rock_Ice_Permafrost"
    },
    {
      "x": -26,
      "y": 20,
      "z": 7,
      "name": "Rock_Ice_Permafrost"
    },
    {
      "x": -26,
      "y": 21,
      "z": 7,
      "name": "Rock_Ice_Permafrost"
    },
    {
      "x": -26,
      "y": 22,
      "z": 7,
      "name": "Rock_Ice_Permafrost"
    },
    {
      "x": -26,
      "y": -4,
      "z": 8,
      "name": "Rock_Ice_Permafrost"
    },
    {
      "x": -26,
      "y": -3,
      "z": 8,
      "name": "Rock_Ice_Permafrost"
    },
    {
      "x": -26,
      "y": -1,
      "z": 8,
      "name": "Rock_Ice_Permafrost"
    },
    {
      "x": -26,
      "y": 0,
      "z": 8,
      "name": "Rock_Ice_Permafrost"
    },
    {
      "x": -26,
      "y": 8,
      "z": 8,
      "name": "Rock_Ice_Permafrost"
    },
    {
      "x": -26,
      "y": 9,
      "z": 8,
      "name": "Rock_Ice_Permafrost"
    },
    {
      "x": -26,
      "y": 10,
      "z": 8,
      "name": "Rock_Ice_Permafrost"
    },
    {
      "x": -26,
      "y": -4,
      "z": 9,
      "name": "Rock_Ice_Permafrost"
    },
    {
      "x": -26,
      "y": -3,
      "z": 9,
      "name": "Rock_Ice_Permafrost"
    },
    {
      "x": -26,
      "y": -1,
      "z": 9,
      "name": "Rock_Ice_Permafrost"
    },
    {
      "x": -26,
      "y": 0,
      "z": 9,
      "name": "Rock_Ice_Permafrost"
    },
    {
      "x": -26,
      "y": 9,
      "z": 9,
      "name": "Rock_Ice_Permafrost"
    },
    {
      "x": -26,
      "y": 10,
      "z": 9,
      "name": "Rock_Ice_Permafrost"
    },
    {
      "x": -26,
      "y": -5,
      "z": 10,
      "name": "Rock_Ice_Permafrost"
    },
    {
      "x": -26,
      "y": -4,
      "z": 10,
      "name": "Rock_Ice_Permafrost"
    },
    {
      "x": -26,
      "y": -3,
      "z": 10,
      "name": "Rock_Ice_Permafrost"
    },
    {
      "x": -26,
      "y": -2,
      "z": 10,
      "name": "Rock_Ice_Permafrost"
    },
    {
      "x": -26,
      "y": -1,
      "z": 10,
      "name": "Rock_Ice_Permafrost"
    },
    {
      "x": -26,
      "y": 0,
      "z": 10,
      "name": "Rock_Ice_Permafrost"
    },
    {
      "x": -26,
      "y": -5,
      "z": 11,
      "name": "Rock_Ice_Permafrost"
    },
    {
      "x": -26,
      "y": -4,
      "z": 11,
      "name": "Rock_Ice_Permafrost"
    },
    {
      "x": -26,
      "y": -3,
      "z": 11,
      "name": "Rock_Ice_Permafrost"
    },
    {
      "x": -26,
      "y": -2,
      "z": 11,
      "name": "Rock_Ice_Permafrost"
    },
    {
      "x": -26,
      "y": -1,
      "z": 11,
      "name": "Rock_Ice_Permafrost"
    },
    {
      "x": -25,
      "y": 5,
      "z": -4,
      "name": "Rock_Ice_Permafrost"
    },
    {
      "x": -25,
      "y": 6,
      "z": -4,
      "name": "Rock_Ice_Permafrost"
    },
    {
      "x": -25,
      "y": 7,
      "z": -4,
      "name": "Rock_Ice_Permafrost"
    },
    {
      "x": -25,
      "y": 5,
      "z": -3,
      "name": "Rock_Ice_Permafrost"
    },
    {
      "x": -25,
      "y": 6,
      "z": -3,
      "name": "Rock_Ice_Permafrost"
    },
    {
      "x": -25,
      "y": 7,
      "z": -3,
      "name": "Rock_Ice_Permafrost"
    },
    {
      "x": -25,
      "y": -3,
      "z": 4,
      "name": "Rock_Ice_Permafrost"
    },
    {
      "x": -25,
      "y": -3,
      "z": 5,
      "name": "Rock_Ice_Permafrost"
    },
    {
      "x": -25,
      "y": -2,
      "z": 5,
      "name": "Rock_Ice_Permafrost"
    },
    {
      "x": -25,
      "y": 19,
      "z": 5,
      "name": "Rock_Ice_Permafrost"
    },
    {
      "x": -25,
      "y": 20,
      "z": 5,
      "name": "Rock_Ice_Permafrost"
    },
    {
      "x": -25,
      "y": -4,
      "z": 6,
      "name": "Rock_Ice_Permafrost"
    },
    {
      "x": -25,
      "y": -3,
      "z": 6,
      "name": "Rock_Ice_Permafrost"
    },
    {
      "x": -25,
      "y": -2,
      "z": 6,
      "name": "Rock_Ice_Permafrost"
    },
    {
      "x": -25,
      "y": -1,
      "z": 6,
      "name": "Rock_Ice_Permafrost"
    },
    {
      "x": -25,
      "y": 7,
      "z": 6,
      "name": "Rock_Ice_Permafrost"
    },
    {
      "x": -25,
      "y": 8,
      "z": 6,
      "name": "Rock_Ice_Permafrost"
    },
    {
      "x": -25,
      "y": 18,
      "z": 6,
      "name": "Rock_Ice_Permafrost"
    },
    {
      "x": -25,
      "y": 19,
      "z": 6,
      "name": "Rock_Ice_Permafrost"
    },
    {
      "x": -25,
      "y": 20,
      "z": 6,
      "name": "Rock_Ice_Permafrost"
    },
    {
      "x": -25,
      "y": 21,
      "z": 6,
      "name": "Rock_Ice_Permafrost"
    },
    {
      "x": -25,
      "y": -4,
      "z": 7,
      "name": "Rock_Ice_Permafrost"
    },
    {
      "x": -25,
      "y": -3,
      "z": 7,
      "name": "Rock_Ice_Permafrost"
    },
    {
      "x": -25,
      "y": -2,
      "z": 7,
      "name": "Rock_Ice_Permafrost"
    },
    {
      "x": -25,
      "y": -1,
      "z": 7,
      "name": "Rock_Ice_Permafrost"
    },
    {
      "x": -25,
      "y": 7,
      "z": 7,
      "name": "Rock_Ice_Permafrost"
    },
    {
      "x": -25,
      "y": 8,
      "z": 7,
      "name": "Rock_Ice_Permafrost"
    },
    {
      "x": -25,
      "y": 9,
      "z": 7,
      "name": "Rock_Ice_Permafrost"
    },
    {
      "x": -25,
      "y": 18,
      "z": 7,
      "name": "Rock_Ice_Permafrost"
    },
    {
      "x": -25,
      "y": 19,
      "z": 7,
      "name": "Rock_Ice_Permafrost"
    },
    {
      "x": -25,
      "y": 20,
      "z": 7,
      "name": "Rock_Ice_Permafrost"
    },
    {
      "x": -25,
      "y": 21,
      "z": 7,
      "name": "Rock_Ice_Permafrost"
    },
    {
      "x": -25,
      "y": -4,
      "z": 8,
      "name": "Rock_Ice_Permafrost"
    },
    {
      "x": -25,
      "y": -3,
      "z": 8,
      "name": "Rock_Ice_Permafrost"
    },
    {
      "x": -25,
      "y": -1,
      "z": 8,
      "name": "Rock_Ice_Permafrost"
    },
    {
      "x": -25,
      "y": 0,
      "z": 8,
      "name": "Rock_Ice_Permafrost"
    },
    {
      "x": -25,
      "y": 7,
      "z": 8,
      "name": "Rock_Ice_Permafrost"
    },
    {
      "x": -25,
      "y": 8,
      "z": 8,
      "name": "Rock_Ice_Permafrost"
    },
    {
      "x": -25,
      "y": 9,
      "z": 8,
      "name": "Rock_Ice_Permafrost"
    },
    {
      "x": -25,
      "y": 10,
      "z": 8,
      "name": "Rock_Ice_Permafrost"
    },
    {
      "x": -25,
      "y": -5,
      "z": 9,
      "name": "Rock_Ice_Permafrost"
    },
    {
      "x": -25,
      "y": -4,
      "z": 9,
      "name": "Rock_Ice_Permafrost"
    },
    {
      "x": -25,
      "y": -3,
      "z": 9,
      "name": "Rock_Ice_Permafrost"
    },
    {
      "x": -25,
      "y": -1,
      "z": 9,
      "name": "Rock_Ice_Permafrost"
    },
    {
      "x": -25,
      "y": 0,
      "z": 9,
      "name": "Rock_Ice_Permafrost"
    },
    {
      "x": -25,
      "y": 8,
      "z": 9,
      "name": "Rock_Ice_Permafrost"
    },
    {
      "x": -25,
      "y": 9,
      "z": 9,
      "name": "Rock_Ice_Permafrost"
    },
    {
      "x": -25,
      "y": -5,
      "z": 10,
      "name": "Rock_Ice_Permafrost"
    },
    {
      "x": -25,
      "y": -4,
      "z": 10,
      "name": "Rock_Ice_Permafrost"
    },
    {
      "x": -25,
      "y": -3,
      "z": 10,
      "name": "Rock_Ice_Permafrost"
    },
    {
      "x": -25,
      "y": -2,
      "z": 10,
      "name": "Rock_Ice_Permafrost"
    },
    {
      "x": -25,
      "y": -1,
      "z": 10,
      "name": "Rock_Ice_Permafrost"
    },
    {
      "x": -25,
      "y": 0,
      "z": 10,
      "name": "Rock_Ice_Permafrost"
    },
    {
      "x": -25,
      "y": -5,
      "z": 11,
      "name": "Rock_Ice_Permafrost"
    },
    {
      "x": -25,
      "y": -4,
      "z": 11,
      "name": "Rock_Ice_Permafrost"
    },
    {
      "x": -24,
      "y": 8,
      "z": -5,
      "name": "Rock_Ice_Permafrost"
    },
    {
      "x": -24,
      "y": 9,
      "z": -5,
      "name": "Rock_Ice_Permafrost"
    },
    {
      "x": -24,
      "y": 10,
      "z": -5,
      "name": "Rock_Ice_Permafrost"
    },
    {
      "x": -24,
      "y": 11,
      "z": -5,
      "name": "Rock_Ice_Permafrost"
    },
    {
      "x": -24,
      "y": 5,
      "z": -4,
      "name": "Rock_Ice_Permafrost"
    },
    {
      "x": -24,
      "y": 6,
      "z": -4,
      "name": "Rock_Ice_Permafrost"
    },
    {
      "x": -24,
      "y": 7,
      "z": -4,
      "name": "Rock_Ice_Permafrost"
    },
    {
      "x": -24,
      "y": 8,
      "z": -4,
      "name": "Rock_Ice_Permafrost"
    },
    {
      "x": -24,
      "y": 9,
      "z": -4,
      "name": "Rock_Ice_Permafrost"
    },
    {
      "x": -24,
      "y": 10,
      "z": -4,
      "name": "Rock_Ice_Permafrost"
    },
    {
      "x": -24,
      "y": 11,
      "z": -4,
      "name": "Rock_Ice_Permafrost"
    },
    {
      "x": -24,
      "y": 5,
      "z": -3,
      "name": "Rock_Ice_Permafrost"
    },
    {
      "x": -24,
      "y": 6,
      "z": -3,
      "name": "Rock_Ice_Permafrost"
    },
    {
      "x": -24,
      "y": 7,
      "z": -3,
      "name": "Rock_Ice_Permafrost"
    },
    {
      "x": -24,
      "y": 12,
      "z": -3,
      "name": "Rock_Ice_Permafrost"
    },
    {
      "x": -24,
      "y": -4,
      "z": 4,
      "name": "Rock_Ice_Permafrost"
    },
    {
      "x": -24,
      "y": -3,
      "z": 4,
      "name": "Rock_Ice_Permafrost"
    },
    {
      "x": -24,
      "y": -4,
      "z": 5,
      "name": "Rock_Ice_Permafrost"
    },
    {
      "x": -24,
      "y": -3,
      "z": 5,
      "name": "Rock_Ice_Permafrost"
    },
    {
      "x": -24,
      "y": -2,
      "z": 5,
      "name": "Rock_Ice_Permafrost"
    },
    {
      "x": -24,
      "y": 7,
      "z": 5,
      "name": "Rock_Ice_Permafrost"
    },
    {
      "x": -24,
      "y": 17,
      "z": 5,
      "name": "Rock_Ice_Permafrost"
    },
    {
      "x": -24,
      "y": 18,
      "z": 5,
      "name": "Rock_Ice_Permafrost"
    },
    {
      "x": -24,
      "y": 19,
      "z": 5,
      "name": "Rock_Ice_Permafrost"
    },
    {
      "x": -24,
      "y": 20,
      "z": 5,
      "name": "Rock_Ice_Permafrost"
    },
    {
      "x": -24,
      "y": -4,
      "z": 6,
      "name": "Rock_Ice_Permafrost"
    },
    {
      "x": -24,
      "y": -3,
      "z": 6,
      "name": "Rock_Ice_Permafrost"
    },
    {
      "x": -24,
      "y": -2,
      "z": 6,
      "name": "Rock_Ice_Permafrost"
    },
    {
      "x": -24,
      "y": -1,
      "z": 6,
      "name": "Rock_Ice_Permafrost"
    },
    {
      "x": -24,
      "y": 7,
      "z": 6,
      "name": "Rock_Ice_Permafrost"
    },
    {
      "x": -24,
      "y": 8,
      "z": 6,
      "name": "Rock_Ice_Permafrost"
    },
    {
      "x": -24,
      "y": 17,
      "z": 6,
      "name": "Rock_Ice_Permafrost"
    },
    {
      "x": -24,
      "y": 18,
      "z": 6,
      "name": "Rock_Ice_Permafrost"
    },
    {
      "x": -24,
      "y": 19,
      "z": 6,
      "name": "Rock_Ice_Permafrost"
    },
    {
      "x": -24,
      "y": 20,
      "z": 6,
      "name": "Rock_Ice_Permafrost"
    },
    {
      "x": -24,
      "y": -4,
      "z": 7,
      "name": "Rock_Ice_Permafrost"
    },
    {
      "x": -24,
      "y": -3,
      "z": 7,
      "name": "Rock_Ice_Permafrost"
    },
    {
      "x": -24,
      "y": -2,
      "z": 7,
      "name": "Rock_Ice_Permafrost"
    },
    {
      "x": -24,
      "y": -1,
      "z": 7,
      "name": "Rock_Ice_Permafrost"
    },
    {
      "x": -24,
      "y": 0,
      "z": 7,
      "name": "Rock_Ice_Permafrost"
    },
    {
      "x": -24,
      "y": 7,
      "z": 7,
      "name": "Rock_Ice_Permafrost"
    },
    {
      "x": -24,
      "y": 8,
      "z": 7,
      "name": "Rock_Ice_Permafrost"
    },
    {
      "x": -24,
      "y": 9,
      "z": 7,
      "name": "Rock_Ice_Permafrost"
    },
    {
      "x": -24,
      "y": 18,
      "z": 7,
      "name": "Rock_Ice_Permafrost"
    },
    {
      "x": -24,
      "y": 19,
      "z": 7,
      "name": "Rock_Ice_Permafrost"
    },
    {
      "x": -24,
      "y": 20,
      "z": 7,
      "name": "Rock_Ice_Permafrost"
    },
    {
      "x": -24,
      "y": -35,
      "z": 8,
      "name": "Rock_Ice_Permafrost"
    },
    {
      "x": -24,
      "y": -34,
      "z": 8,
      "name": "Rock_Ice_Permafrost"
    },
    {
      "x": -24,
      "y": -5,
      "z": 8,
      "name": "Rock_Ice_Permafrost"
    },
    {
      "x": -24,
      "y": -4,
      "z": 8,
      "name": "Rock_Ice_Permafrost"
    },
    {
      "x": -24,
      "y": -3,
      "z": 8,
      "name": "Rock_Ice_Permafrost"
    },
    {
      "x": -24,
      "y": -1,
      "z": 8,
      "name": "Rock_Ice_Permafrost"
    },
    {
      "x": -24,
      "y": 0,
      "z": 8,
      "name": "Rock_Ice_Permafrost"
    },
    {
      "x": -24,
      "y": 7,
      "z": 8,
      "name": "Rock_Ice_Permafrost"
    },
    {
      "x": -24,
      "y": 8,
      "z": 8,
      "name": "Rock_Ice_Permafrost"
    },
    {
      "x": -24,
      "y": 9,
      "z": 8,
      "name": "Rock_Ice_Permafrost"
    },
    {
      "x": -24,
      "y": -35,
      "z": 9,
      "name": "Rock_Ice_Permafrost"
    },
    {
      "x": -24,
      "y": -5,
      "z": 9,
      "name": "Rock_Ice_Permafrost"
    },
    {
      "x": -24,
      "y": -4,
      "z": 9,
      "name": "Rock_Ice_Permafrost"
    },
    {
      "x": -24,
      "y": -3,
      "z": 9,
      "name": "Rock_Ice_Permafrost"
    },
    {
      "x": -24,
      "y": -2,
      "z": 9,
      "name": "Rock_Ice_Permafrost"
    },
    {
      "x": -24,
      "y": -1,
      "z": 9,
      "name": "Rock_Ice_Permafrost"
    },
    {
      "x": -24,
      "y": 0,
      "z": 9,
      "name": "Rock_Ice_Permafrost"
    },
    {
      "x": -24,
      "y": 8,
      "z": 9,
      "name": "Rock_Ice_Permafrost"
    },
    {
      "x": -24,
      "y": 9,
      "z": 9,
      "name": "Rock_Ice_Permafrost"
    },
    {
      "x": -24,
      "y": -6,
      "z": 10,
      "name": "Rock_Ice_Permafrost"
    },
    {
      "x": -24,
      "y": -5,
      "z": 10,
      "name": "Rock_Ice_Permafrost"
    },
    {
      "x": -24,
      "y": -4,
      "z": 10,
      "name": "Rock_Ice_Permafrost"
    },
    {
      "x": -24,
      "y": -3,
      "z": 10,
      "name": "Rock_Ice_Permafrost"
    },
    {
      "x": -24,
      "y": -2,
      "z": 10,
      "name": "Rock_Ice_Permafrost"
    },
    {
      "x": -24,
      "y": -1,
      "z": 10,
      "name": "Rock_Ice_Permafrost"
    },
    {
      "x": -23,
      "y": 8,
      "z": -5,
      "name": "Rock_Ice_Permafrost"
    },
    {
      "x": -23,
      "y": 9,
      "z": -5,
      "name": "Rock_Ice_Permafrost"
    },
    {
      "x": -23,
      "y": 10,
      "z": -5,
      "name": "Rock_Ice_Permafrost"
    },
    {
      "x": -23,
      "y": 11,
      "z": -5,
      "name": "Rock_Ice_Permafrost"
    },
    {
      "x": -23,
      "y": 4,
      "z": -4,
      "name": "Rock_Ice_Permafrost"
    },
    {
      "x": -23,
      "y": 5,
      "z": -4,
      "name": "Rock_Ice_Permafrost"
    },
    {
      "x": -23,
      "y": 6,
      "z": -4,
      "name": "Rock_Ice_Permafrost"
    },
    {
      "x": -23,
      "y": 7,
      "z": -4,
      "name": "Rock_Ice_Permafrost"
    },
    {
      "x": -23,
      "y": 8,
      "z": -4,
      "name": "Rock_Ice_Permafrost"
    },
    {
      "x": -23,
      "y": 9,
      "z": -4,
      "name": "Rock_Ice_Permafrost"
    },
    {
      "x": -23,
      "y": 10,
      "z": -4,
      "name": "Rock_Ice_Permafrost"
    },
    {
      "x": -23,
      "y": 11,
      "z": -4,
      "name": "Rock_Ice_Permafrost"
    },
    {
      "x": -23,
      "y": 12,
      "z": -4,
      "name": "Rock_Ice_Permafrost"
    },
    {
      "x": -23,
      "y": 3,
      "z": -3,
      "name": "Rock_Ice_Permafrost"
    },
    {
      "x": -23,
      "y": 4,
      "z": -3,
      "name": "Rock_Ice_Permafrost"
    },
    {
      "x": -23,
      "y": 5,
      "z": -3,
      "name": "Rock_Ice_Permafrost"
    },
    {
      "x": -23,
      "y": 6,
      "z": -3,
      "name": "Rock_Ice_Permafrost"
    },
    {
      "x": -23,
      "y": 7,
      "z": -3,
      "name": "Rock_Ice_Permafrost"
    },
    {
      "x": -23,
      "y": 11,
      "z": -3,
      "name": "Rock_Ice_Permafrost"
    },
    {
      "x": -23,
      "y": 12,
      "z": -3,
      "name": "Rock_Ice_Permafrost"
    },
    {
      "x": -23,
      "y": 13,
      "z": -3,
      "name": "Rock_Ice_Permafrost"
    },
    {
      "x": -23,
      "y": 12,
      "z": -2,
      "name": "Rock_Ice_Permafrost"
    },
    {
      "x": -23,
      "y": 13,
      "z": -2,
      "name": "Rock_Ice_Permafrost"
    },
    {
      "x": -23,
      "y": 14,
      "z": -2,
      "name": "Rock_Ice_Permafrost"
    },
    {
      "x": -23,
      "y": 13,
      "z": -1,
      "name": "Rock_Ice_Permafrost"
    },
    {
      "x": -23,
      "y": 14,
      "z": -1,
      "name": "Rock_Ice_Permafrost"
    },
    {
      "x": -23,
      "y": -5,
      "z": 4,
      "name": "Rock_Ice_Permafrost"
    },
    {
      "x": -23,
      "y": -4,
      "z": 4,
      "name": "Rock_Ice_Permafrost"
    },
    {
      "x": -23,
      "y": -3,
      "z": 4,
      "name": "Rock_Ice_Permafrost"
    },
    {
      "x": -23,
      "y": -2,
      "z": 4,
      "name": "Rock_Ice_Permafrost"
    },
    {
      "x": -23,
      "y": 6,
      "z": 4,
      "name": "Rock_Ice_Permafrost"
    },
    {
      "x": -23,
      "y": 17,
      "z": 4,
      "name": "Rock_Ice_Permafrost"
    },
    {
      "x": -23,
      "y": -4,
      "z": 5,
      "name": "Rock_Ice_Permafrost"
    },
    {
      "x": -23,
      "y": -3,
      "z": 5,
      "name": "Rock_Ice_Permafrost"
    },
    {
      "x": -23,
      "y": -2,
      "z": 5,
      "name": "Rock_Ice_Permafrost"
    },
    {
      "x": -23,
      "y": 6,
      "z": 5,
      "name": "Rock_Ice_Permafrost"
    },
    {
      "x": -23,
      "y": 7,
      "z": 5,
      "name": "Rock_Ice_Permafrost"
    },
    {
      "x": -23,
      "y": 16,
      "z": 5,
      "name": "Rock_Ice_Permafrost"
    },
    {
      "x": -23,
      "y": 17,
      "z": 5,
      "name": "Rock_Ice_Permafrost"
    },
    {
      "x": -23,
      "y": 18,
      "z": 5,
      "name": "Rock_Ice_Permafrost"
    },
    {
      "x": -23,
      "y": 19,
      "z": 5,
      "name": "Rock_Ice_Permafrost"
    },
    {
      "x": -23,
      "y": -4,
      "z": 6,
      "name": "Rock_Ice_Permafrost"
    },
    {
      "x": -23,
      "y": -3,
      "z": 6,
      "name": "Rock_Ice_Permafrost"
    },
    {
      "x": -23,
      "y": -2,
      "z": 6,
      "name": "Rock_Ice_Permafrost"
    },
    {
      "x": -23,
      "y": -1,
      "z": 6,
      "name": "Rock_Ice_Permafrost"
    },
    {
      "x": -23,
      "y": 6,
      "z": 6,
      "name": "Rock_Ice_Permafrost"
    },
    {
      "x": -23,
      "y": 7,
      "z": 6,
      "name": "Rock_Ice_Permafrost"
    },
    {
      "x": -23,
      "y": 8,
      "z": 6,
      "name": "Rock_Ice_Permafrost"
    },
    {
      "x": -23,
      "y": 16,
      "z": 6,
      "name": "Rock_Ice_Permafrost"
    },
    {
      "x": -23,
      "y": 17,
      "z": 6,
      "name": "Rock_Ice_Permafrost"
    },
    {
      "x": -23,
      "y": 18,
      "z": 6,
      "name": "Rock_Ice_Permafrost"
    },
    {
      "x": -23,
      "y": 19,
      "z": 6,
      "name": "Rock_Ice_Permafrost"
    },
    {
      "x": -23,
      "y": -5,
      "z": 7,
      "name": "Rock_Ice_Permafrost"
    },
    {
      "x": -23,
      "y": -4,
      "z": 7,
      "name": "Rock_Ice_Permafrost"
    },
    {
      "x": -23,
      "y": -2,
      "z": 7,
      "name": "Rock_Ice_Permafrost"
    },
    {
      "x": -23,
      "y": -1,
      "z": 7,
      "name": "Rock_Ice_Permafrost"
    },
    {
      "x": -23,
      "y": 0,
      "z": 7,
      "name": "Rock_Ice_Permafrost"
    },
    {
      "x": -23,
      "y": 6,
      "z": 7,
      "name": "Rock_Ice_Permafrost"
    },
    {
      "x": -23,
      "y": 7,
      "z": 7,
      "name": "Rock_Ice_Permafrost"
    },
    {
      "x": -23,
      "y": 8,
      "z": 7,
      "name": "Rock_Ice_Permafrost"
    },
    {
      "x": -23,
      "y": 9,
      "z": 7,
      "name": "Rock_Ice_Permafrost"
    },
    {
      "x": -23,
      "y": 17,
      "z": 7,
      "name": "Rock_Ice_Permafrost"
    },
    {
      "x": -23,
      "y": 18,
      "z": 7,
      "name": "Rock_Ice_Permafrost"
    },
    {
      "x": -23,
      "y": 19,
      "z": 7,
      "name": "Rock_Ice_Permafrost"
    },
    {
      "x": -23,
      "y": -35,
      "z": 8,
      "name": "Rock_Ice_Permafrost"
    },
    {
      "x": -23,
      "y": -34,
      "z": 8,
      "name": "Rock_Ice_Permafrost"
    },
    {
      "x": -23,
      "y": -33,
      "z": 8,
      "name": "Rock_Ice_Permafrost"
    },
    {
      "x": -23,
      "y": -5,
      "z": 8,
      "name": "Rock_Ice_Permafrost"
    },
    {
      "x": -23,
      "y": -4,
      "z": 8,
      "name": "Rock_Ice_Permafrost"
    },
    {
      "x": -23,
      "y": -1,
      "z": 8,
      "name": "Rock_Ice_Permafrost"
    },
    {
      "x": -23,
      "y": 0,
      "z": 8,
      "name": "Rock_Ice_Permafrost"
    },
    {
      "x": -23,
      "y": 6,
      "z": 8,
      "name": "Rock_Ice_Permafrost"
    },
    {
      "x": -23,
      "y": 7,
      "z": 8,
      "name": "Rock_Ice_Permafrost"
    },
    {
      "x": -23,
      "y": 8,
      "z": 8,
      "name": "Rock_Ice_Permafrost"
    },
    {
      "x": -23,
      "y": 9,
      "z": 8,
      "name": "Rock_Ice_Permafrost"
    },
    {
      "x": -23,
      "y": -6,
      "z": 9,
      "name": "Rock_Ice_Permafrost"
    },
    {
      "x": -23,
      "y": -5,
      "z": 9,
      "name": "Rock_Ice_Permafrost"
    },
    {
      "x": -23,
      "y": -4,
      "z": 9,
      "name": "Rock_Ice_Permafrost"
    },
    {
      "x": -23,
      "y": -3,
      "z": 9,
      "name": "Rock_Ice_Permafrost"
    },
    {
      "x": -23,
      "y": -2,
      "z": 9,
      "name": "Rock_Ice_Permafrost"
    },
    {
      "x": -23,
      "y": -1,
      "z": 9,
      "name": "Rock_Ice_Permafrost"
    },
    {
      "x": -23,
      "y": 0,
      "z": 9,
      "name": "Rock_Ice_Permafrost"
    },
    {
      "x": -23,
      "y": 8,
      "z": 9,
      "name": "Rock_Ice_Permafrost"
    },
    {
      "x": -23,
      "y": -6,
      "z": 10,
      "name": "Rock_Ice_Permafrost"
    },
    {
      "x": -23,
      "y": -5,
      "z": 10,
      "name": "Rock_Ice_Permafrost"
    },
    {
      "x": -23,
      "y": -4,
      "z": 10,
      "name": "Rock_Ice_Permafrost"
    },
    {
      "x": -23,
      "y": -3,
      "z": 10,
      "name": "Rock_Ice_Permafrost"
    },
    {
      "x": -23,
      "y": -2,
      "z": 10,
      "name": "Rock_Ice_Permafrost"
    },
    {
      "x": -22,
      "y": 2,
      "z": -9,
      "name": "Rock_Ice_Permafrost"
    },
    {
      "x": -22,
      "y": 1,
      "z": -8,
      "name": "Rock_Ice_Permafrost"
    },
    {
      "x": -22,
      "y": 7,
      "z": -5,
      "name": "Rock_Ice_Permafrost"
    },
    {
      "x": -22,
      "y": 8,
      "z": -5,
      "name": "Rock_Ice_Permafrost"
    },
    {
      "x": -22,
      "y": 9,
      "z": -5,
      "name": "Rock_Ice_Permafrost"
    },
    {
      "x": -22,
      "y": 10,
      "z": -5,
      "name": "Rock_Ice_Permafrost"
    },
    {
      "x": -22,
      "y": 3,
      "z": -4,
      "name": "Rock_Ice_Permafrost"
    },
    {
      "x": -22,
      "y": 4,
      "z": -4,
      "name": "Rock_Ice_Permafrost"
    },
    {
      "x": -22,
      "y": 5,
      "z": -4,
      "name": "Rock_Ice_Permafrost"
    },
    {
      "x": -22,
      "y": 6,
      "z": -4,
      "name": "Rock_Ice_Permafrost"
    },
    {
      "x": -22,
      "y": 7,
      "z": -4,
      "name": "Rock_Ice_Permafrost"
    },
    {
      "x": -22,
      "y": 8,
      "z": -4,
      "name": "Rock_Ice_Permafrost"
    },
    {
      "x": -22,
      "y": 9,
      "z": -4,
      "name": "Rock_Ice_Permafrost"
    },
    {
      "x": -22,
      "y": 10,
      "z": -4,
      "name": "Rock_Ice_Permafrost"
    },
    {
      "x": -22,
      "y": 11,
      "z": -4,
      "name": "Rock_Ice_Permafrost"
    },
    {
      "x": -22,
      "y": 2,
      "z": -3,
      "name": "Rock_Ice_Permafrost"
    },
    {
      "x": -22,
      "y": 3,
      "z": -3,
      "name": "Rock_Ice_Permafrost"
    },
    {
      "x": -22,
      "y": 4,
      "z": -3,
      "name": "Rock_Ice_Permafrost"
    },
    {
      "x": -22,
      "y": 5,
      "z": -3,
      "name": "Rock_Ice_Permafrost"
    },
    {
      "x": -22,
      "y": 6,
      "z": -3,
      "name": "Rock_Ice_Permafrost"
    },
    {
      "x": -22,
      "y": 7,
      "z": -3,
      "name": "Rock_Ice_Permafrost"
    },
    {
      "x": -22,
      "y": 8,
      "z": -3,
      "name": "Rock_Ice_Permafrost"
    },
    {
      "x": -22,
      "y": 10,
      "z": -3,
      "name": "Rock_Ice_Permafrost"
    },
    {
      "x": -22,
      "y": 11,
      "z": -3,
      "name": "Rock_Ice_Permafrost"
    },
    {
      "x": -22,
      "y": 12,
      "z": -3,
      "name": "Rock_Ice_Permafrost"
    },
    {
      "x": -22,
      "y": 3,
      "z": -2,
      "name": "Rock_Ice_Permafrost"
    },
    {
      "x": -22,
      "y": 4,
      "z": -2,
      "name": "Rock_Ice_Permafrost"
    },
    {
      "x": -22,
      "y": 11,
      "z": -2,
      "name": "Rock_Ice_Permafrost"
    },
    {
      "x": -22,
      "y": 12,
      "z": -2,
      "name": "Rock_Ice_Permafrost"
    },
    {
      "x": -22,
      "y": 13,
      "z": -2,
      "name": "Rock_Ice_Permafrost"
    },
    {
      "x": -22,
      "y": 14,
      "z": -2,
      "name": "Rock_Ice_Permafrost"
    },
    {
      "x": -22,
      "y": 12,
      "z": -1,
      "name": "Rock_Ice_Permafrost"
    },
    {
      "x": -22,
      "y": 13,
      "z": -1,
      "name": "Rock_Ice_Permafrost"
    },
    {
      "x": -22,
      "y": 14,
      "z": -1,
      "name": "Rock_Ice_Permafrost"
    },
    {
      "x": -22,
      "y": -5,
      "z": 3,
      "name": "Rock_Ice_Permafrost"
    },
    {
      "x": -22,
      "y": -4,
      "z": 3,
      "name": "Rock_Ice_Permafrost"
    },
    {
      "x": -22,
      "y": -3,
      "z": 3,
      "name": "Rock_Ice_Permafrost"
    },
    {
      "x": -22,
      "y": 6,
      "z": 3,
      "name": "Rock_Ice_Permafrost"
    },
    {
      "x": -22,
      "y": -5,
      "z": 4,
      "name": "Rock_Ice_Permafrost"
    },
    {
      "x": -22,
      "y": -4,
      "z": 4,
      "name": "Rock_Ice_Permafrost"
    },
    {
      "x": -22,
      "y": -3,
      "z": 4,
      "name": "Rock_Ice_Permafrost"
    },
    {
      "x": -22,
      "y": -2,
      "z": 4,
      "name": "Rock_Ice_Permafrost"
    },
    {
      "x": -22,
      "y": 5,
      "z": 4,
      "name": "Rock_Ice_Permafrost"
    },
    {
      "x": -22,
      "y": 6,
      "z": 4,
      "name": "Rock_Ice_Permafrost"
    },
    {
      "x": -22,
      "y": 16,
      "z": 4,
      "name": "Rock_Ice_Permafrost"
    },
    {
      "x": -22,
      "y": 17,
      "z": 4,
      "name": "Rock_Ice_Permafrost"
    },
    {
      "x": -22,
      "y": 18,
      "z": 4,
      "name": "Rock_Ice_Permafrost"
    },
    {
      "x": -22,
      "y": -5,
      "z": 5,
      "name": "Rock_Ice_Permafrost"
    },
    {
      "x": -22,
      "y": -4,
      "z": 5,
      "name": "Rock_Ice_Permafrost"
    },
    {
      "x": -22,
      "y": -3,
      "z": 5,
      "name": "Rock_Ice_Permafrost"
    },
    {
      "x": -22,
      "y": -2,
      "z": 5,
      "name": "Rock_Ice_Permafrost"
    },
    {
      "x": -22,
      "y": 5,
      "z": 5,
      "name": "Rock_Ice_Permafrost"
    },
    {
      "x": -22,
      "y": 6,
      "z": 5,
      "name": "Rock_Ice_Permafrost"
    },
    {
      "x": -22,
      "y": 7,
      "z": 5,
      "name": "Rock_Ice_Permafrost"
    },
    {
      "x": -22,
      "y": 15,
      "z": 5,
      "name": "Rock_Ice_Permafrost"
    },
    {
      "x": -22,
      "y": 16,
      "z": 5,
      "name": "Rock_Ice_Permafrost"
    },
    {
      "x": -22,
      "y": 17,
      "z": 5,
      "name": "Rock_Ice_Permafrost"
    },
    {
      "x": -22,
      "y": 18,
      "z": 5,
      "name": "Rock_Ice_Permafrost"
    },
    {
      "x": -22,
      "y": 19,
      "z": 5,
      "name": "Rock_Ice_Permafrost"
    },
    {
      "x": -22,
      "y": -5,
      "z": 6,
      "name": "Rock_Ice_Permafrost"
    },
    {
      "x": -22,
      "y": -4,
      "z": 6,
      "name": "Rock_Ice_Permafrost"
    },
    {
      "x": -22,
      "y": -2,
      "z": 6,
      "name": "Rock_Ice_Permafrost"
    },
    {
      "x": -22,
      "y": -1,
      "z": 6,
      "name": "Rock_Ice_Permafrost"
    },
    {
      "x": -22,
      "y": 5,
      "z": 6,
      "name": "Rock_Ice_Permafrost"
    },
    {
      "x": -22,
      "y": 6,
      "z": 6,
      "name": "Rock_Ice_Permafrost"
    },
    {
      "x": -22,
      "y": 7,
      "z": 6,
      "name": "Rock_Ice_Permafrost"
    },
    {
      "x": -22,
      "y": 8,
      "z": 6,
      "name": "Rock_Ice_Permafrost"
    },
    {
      "x": -22,
      "y": 15,
      "z": 6,
      "name": "Rock_Ice_Permafrost"
    },
    {
      "x": -22,
      "y": 16,
      "z": 6,
      "name": "Rock_Ice_Permafrost"
    },
    {
      "x": -22,
      "y": 17,
      "z": 6,
      "name": "Rock_Ice_Permafrost"
    },
    {
      "x": -22,
      "y": 18,
      "z": 6,
      "name": "Rock_Ice_Permafrost"
    },
    {
      "x": -22,
      "y": 19,
      "z": 6,
      "name": "Rock_Ice_Permafrost"
    },
    {
      "x": -22,
      "y": -33,
      "z": 7,
      "name": "Rock_Ice_Permafrost"
    },
    {
      "x": -22,
      "y": -32,
      "z": 7,
      "name": "Rock_Ice_Permafrost"
    },
    {
      "x": -22,
      "y": -5,
      "z": 7,
      "name": "Rock_Ice_Permafrost"
    },
    {
      "x": -22,
      "y": -4,
      "z": 7,
      "name": "Rock_Ice_Permafrost"
    },
    {
      "x": -22,
      "y": -1,
      "z": 7,
      "name": "Rock_Ice_Permafrost"
    },
    {
      "x": -22,
      "y": 0,
      "z": 7,
      "name": "Rock_Ice_Permafrost"
    },
    {
      "x": -22,
      "y": 5,
      "z": 7,
      "name": "Rock_Ice_Permafrost"
    },
    {
      "x": -22,
      "y": 6,
      "z": 7,
      "name": "Rock_Ice_Permafrost"
    },
    {
      "x": -22,
      "y": 8,
      "z": 7,
      "name": "Rock_Ice_Permafrost"
    },
    {
      "x": -22,
      "y": 9,
      "z": 7,
      "name": "Rock_Ice_Permafrost"
    },
    {
      "x": -22,
      "y": 16,
      "z": 7,
      "name": "Rock_Ice_Permafrost"
    },
    {
      "x": -22,
      "y": 17,
      "z": 7,
      "name": "Rock_Ice_Permafrost"
    },
    {
      "x": -22,
      "y": 18,
      "z": 7,
      "name": "Rock_Ice_Permafrost"
    },
    {
      "x": -22,
      "y": -34,
      "z": 8,
      "name": "Rock_Ice_Permafrost"
    },
    {
      "x": -22,
      "y": -33,
      "z": 8,
      "name": "Rock_Ice_Permafrost"
    },
    {
      "x": -22,
      "y": -32,
      "z": 8,
      "name": "Rock_Ice_Permafrost"
    },
    {
      "x": -22,
      "y": -6,
      "z": 8,
      "name": "Rock_Ice_Permafrost"
    },
    {
      "x": -22,
      "y": -5,
      "z": 8,
      "name": "Rock_Ice_Permafrost"
    },
    {
      "x": -22,
      "y": -4,
      "z": 8,
      "name": "Rock_Ice_Permafrost"
    },
    {
      "x": -22,
      "y": -1,
      "z": 8,
      "name": "Rock_Ice_Permafrost"
    },
    {
      "x": -22,
      "y": 0,
      "z": 8,
      "name": "Rock_Ice_Permafrost"
    },
    {
      "x": -22,
      "y": 6,
      "z": 8,
      "name": "Rock_Ice_Permafrost"
    },
    {
      "x": -22,
      "y": 7,
      "z": 8,
      "name": "Rock_Ice_Permafrost"
    },
    {
      "x": -22,
      "y": 8,
      "z": 8,
      "name": "Rock_Ice_Permafrost"
    },
    {
      "x": -22,
      "y": 9,
      "z": 8,
      "name": "Rock_Ice_Permafrost"
    },
    {
      "x": -22,
      "y": -6,
      "z": 9,
      "name": "Rock_Ice_Permafrost"
    },
    {
      "x": -22,
      "y": -5,
      "z": 9,
      "name": "Rock_Ice_Permafrost"
    },
    {
      "x": -22,
      "y": -4,
      "z": 9,
      "name": "Rock_Ice_Permafrost"
    },
    {
      "x": -22,
      "y": -3,
      "z": 9,
      "name": "Rock_Ice_Permafrost"
    },
    {
      "x": -22,
      "y": -2,
      "z": 9,
      "name": "Rock_Ice_Permafrost"
    },
    {
      "x": -22,
      "y": -1,
      "z": 9,
      "name": "Rock_Ice_Permafrost"
    },
    {
      "x": -22,
      "y": 0,
      "z": 9,
      "name": "Rock_Ice_Permafrost"
    },
    {
      "x": -22,
      "y": -6,
      "z": 10,
      "name": "Rock_Ice_Permafrost"
    },
    {
      "x": -22,
      "y": -5,
      "z": 10,
      "name": "Rock_Ice_Permafrost"
    },
    {
      "x": -22,
      "y": -4,
      "z": 10,
      "name": "Rock_Ice_Permafrost"
    },
    {
      "x": -22,
      "y": -3,
      "z": 10,
      "name": "Rock_Ice_Permafrost"
    },
    {
      "x": -22,
      "y": -2,
      "z": 10,
      "name": "Rock_Ice_Permafrost"
    },
    {
      "x": -21,
      "y": 1,
      "z": -9,
      "name": "Rock_Ice_Permafrost"
    },
    {
      "x": -21,
      "y": 1,
      "z": -8,
      "name": "Rock_Ice_Permafrost"
    },
    {
      "x": -21,
      "y": 2,
      "z": -8,
      "name": "Rock_Ice_Permafrost"
    },
    {
      "x": -21,
      "y": 6,
      "z": -5,
      "name": "Rock_Ice_Permafrost"
    },
    {
      "x": -21,
      "y": 7,
      "z": -5,
      "name": "Rock_Ice_Permafrost"
    },
    {
      "x": -21,
      "y": 8,
      "z": -5,
      "name": "Rock_Ice_Permafrost"
    },
    {
      "x": -21,
      "y": 9,
      "z": -5,
      "name": "Rock_Ice_Permafrost"
    },
    {
      "x": -21,
      "y": 10,
      "z": -5,
      "name": "Rock_Ice_Permafrost"
    },
    {
      "x": -21,
      "y": 3,
      "z": -4,
      "name": "Rock_Ice_Permafrost"
    },
    {
      "x": -21,
      "y": 4,
      "z": -4,
      "name": "Rock_Ice_Permafrost"
    },
    {
      "x": -21,
      "y": 5,
      "z": -4,
      "name": "Rock_Ice_Permafrost"
    },
    {
      "x": -21,
      "y": 6,
      "z": -4,
      "name": "Rock_Ice_Permafrost"
    },
    {
      "x": -21,
      "y": 7,
      "z": -4,
      "name": "Rock_Ice_Permafrost"
    },
    {
      "x": -21,
      "y": 8,
      "z": -4,
      "name": "Rock_Ice_Permafrost"
    },
    {
      "x": -21,
      "y": 9,
      "z": -4,
      "name": "Rock_Ice_Permafrost"
    },
    {
      "x": -21,
      "y": 10,
      "z": -4,
      "name": "Rock_Ice_Permafrost"
    },
    {
      "x": -21,
      "y": 11,
      "z": -4,
      "name": "Rock_Ice_Permafrost"
    },
    {
      "x": -21,
      "y": 2,
      "z": -3,
      "name": "Rock_Ice_Permafrost"
    },
    {
      "x": -21,
      "y": 3,
      "z": -3,
      "name": "Rock_Ice_Permafrost"
    },
    {
      "x": -21,
      "y": 4,
      "z": -3,
      "name": "Rock_Ice_Permafrost"
    },
    {
      "x": -21,
      "y": 5,
      "z": -3,
      "name": "Rock_Ice_Permafrost"
    },
    {
      "x": -21,
      "y": 6,
      "z": -3,
      "name": "Rock_Ice_Permafrost"
    },
    {
      "x": -21,
      "y": 7,
      "z": -3,
      "name": "Rock_Ice_Permafrost"
    },
    {
      "x": -21,
      "y": 8,
      "z": -3,
      "name": "Rock_Ice_Permafrost"
    },
    {
      "x": -21,
      "y": 9,
      "z": -3,
      "name": "Rock_Ice_Permafrost"
    },
    {
      "x": -21,
      "y": 10,
      "z": -3,
      "name": "Rock_Ice_Permafrost"
    },
    {
      "x": -21,
      "y": 11,
      "z": -3,
      "name": "Rock_Ice_Permafrost"
    },
    {
      "x": -21,
      "y": 12,
      "z": -3,
      "name": "Rock_Ice_Permafrost"
    },
    {
      "x": -21,
      "y": 2,
      "z": -2,
      "name": "Rock_Ice_Permafrost"
    },
    {
      "x": -21,
      "y": 3,
      "z": -2,
      "name": "Rock_Ice_Permafrost"
    },
    {
      "x": -21,
      "y": 4,
      "z": -2,
      "name": "Rock_Ice_Permafrost"
    },
    {
      "x": -21,
      "y": 5,
      "z": -2,
      "name": "Rock_Ice_Permafrost"
    },
    {
      "x": -21,
      "y": 10,
      "z": -2,
      "name": "Rock_Ice_Permafrost"
    },
    {
      "x": -21,
      "y": 11,
      "z": -2,
      "name": "Rock_Ice_Permafrost"
    },
    {
      "x": -21,
      "y": 12,
      "z": -2,
      "name": "Rock_Ice_Permafrost"
    },
    {
      "x": -21,
      "y": 13,
      "z": -2,
      "name": "Rock_Ice_Permafrost"
    },
    {
      "x": -21,
      "y": 11,
      "z": -1,
      "name": "Rock_Ice_Permafrost"
    },
    {
      "x": -21,
      "y": 12,
      "z": -1,
      "name": "Rock_Ice_Permafrost"
    },
    {
      "x": -21,
      "y": 13,
      "z": -1,
      "name": "Rock_Ice_Permafrost"
    },
    {
      "x": -21,
      "y": -5,
      "z": 3,
      "name": "Rock_Ice_Permafrost"
    },
    {
      "x": -21,
      "y": -4,
      "z": 3,
      "name": "Rock_Ice_Permafrost"
    },
    {
      "x": -21,
      "y": -3,
      "z": 3,
      "name": "Rock_Ice_Permafrost"
    },
    {
      "x": -21,
      "y": -2,
      "z": 3,
      "name": "Rock_Ice_Permafrost"
    },
    {
      "x": -21,
      "y": 5,
      "z": 3,
      "name": "Rock_Ice_Permafrost"
    },
    {
      "x": -21,
      "y": 6,
      "z": 3,
      "name": "Rock_Ice_Permafrost"
    },
    {
      "x": -21,
      "y": -5,
      "z": 4,
      "name": "Rock_Ice_Permafrost"
    },
    {
      "x": -21,
      "y": -4,
      "z": 4,
      "name": "Rock_Ice_Permafrost"
    },
    {
      "x": -21,
      "y": -3,
      "z": 4,
      "name": "Rock_Ice_Permafrost"
    },
    {
      "x": -21,
      "y": -2,
      "z": 4,
      "name": "Rock_Ice_Permafrost"
    },
    {
      "x": -21,
      "y": 5,
      "z": 4,
      "name": "Rock_Ice_Permafrost"
    },
    {
      "x": -21,
      "y": 6,
      "z": 4,
      "name": "Rock_Ice_Permafrost"
    },
    {
      "x": -21,
      "y": 14,
      "z": 4,
      "name": "Rock_Ice_Permafrost"
    },
    {
      "x": -21,
      "y": 15,
      "z": 4,
      "name": "Rock_Ice_Permafrost"
    },
    {
      "x": -21,
      "y": 16,
      "z": 4,
      "name": "Rock_Ice_Permafrost"
    },
    {
      "x": -21,
      "y": 17,
      "z": 4,
      "name": "Rock_Ice_Permafrost"
    },
    {
      "x": -21,
      "y": -5,
      "z": 5,
      "name": "Rock_Ice_Permafrost"
    },
    {
      "x": -21,
      "y": -4,
      "z": 5,
      "name": "Rock_Ice_Permafrost"
    },
    {
      "x": -21,
      "y": -3,
      "z": 5,
      "name": "Rock_Ice_Permafrost"
    },
    {
      "x": -21,
      "y": -2,
      "z": 5,
      "name": "Rock_Ice_Permafrost"
    },
    {
      "x": -21,
      "y": -1,
      "z": 5,
      "name": "Rock_Ice_Permafrost"
    },
    {
      "x": -21,
      "y": 4,
      "z": 5,
      "name": "Rock_Ice_Permafrost"
    },
    {
      "x": -21,
      "y": 5,
      "z": 5,
      "name": "Rock_Ice_Permafrost"
    },
    {
      "x": -21,
      "y": 6,
      "z": 5,
      "name": "Rock_Ice_Permafrost"
    },
    {
      "x": -21,
      "y": 7,
      "z": 5,
      "name": "Rock_Ice_Permafrost"
    },
    {
      "x": -21,
      "y": 14,
      "z": 5,
      "name": "Rock_Ice_Permafrost"
    },
    {
      "x": -21,
      "y": 15,
      "z": 5,
      "name": "Rock_Ice_Permafrost"
    },
    {
      "x": -21,
      "y": 16,
      "z": 5,
      "name": "Rock_Ice_Permafrost"
    },
    {
      "x": -21,
      "y": 17,
      "z": 5,
      "name": "Rock_Ice_Permafrost"
    },
    {
      "x": -21,
      "y": 18,
      "z": 5,
      "name": "Rock_Ice_Permafrost"
    },
    {
      "x": -21,
      "y": -5,
      "z": 6,
      "name": "Rock_Ice_Permafrost"
    },
    {
      "x": -21,
      "y": -4,
      "z": 6,
      "name": "Rock_Ice_Permafrost"
    },
    {
      "x": -21,
      "y": -2,
      "z": 6,
      "name": "Rock_Ice_Permafrost"
    },
    {
      "x": -21,
      "y": -1,
      "z": 6,
      "name": "Rock_Ice_Permafrost"
    },
    {
      "x": -21,
      "y": 4,
      "z": 6,
      "name": "Rock_Ice_Permafrost"
    },
    {
      "x": -21,
      "y": 5,
      "z": 6,
      "name": "Rock_Ice_Permafrost"
    },
    {
      "x": -21,
      "y": 6,
      "z": 6,
      "name": "Rock_Ice_Permafrost"
    },
    {
      "x": -21,
      "y": 7,
      "z": 6,
      "name": "Rock_Ice_Permafrost"
    },
    {
      "x": -21,
      "y": 8,
      "z": 6,
      "name": "Rock_Ice_Permafrost"
    },
    {
      "x": -21,
      "y": 14,
      "z": 6,
      "name": "Rock_Ice_Permafrost"
    },
    {
      "x": -21,
      "y": 15,
      "z": 6,
      "name": "Rock_Ice_Permafrost"
    },
    {
      "x": -21,
      "y": 16,
      "z": 6,
      "name": "Rock_Ice_Permafrost"
    },
    {
      "x": -21,
      "y": 17,
      "z": 6,
      "name": "Rock_Ice_Permafrost"
    },
    {
      "x": -21,
      "y": 18,
      "z": 6,
      "name": "Rock_Ice_Permafrost"
    },
    {
      "x": -21,
      "y": -33,
      "z": 7,
      "name": "Rock_Ice_Permafrost"
    },
    {
      "x": -21,
      "y": -32,
      "z": 7,
      "name": "Rock_Ice_Permafrost"
    },
    {
      "x": -21,
      "y": -31,
      "z": 7,
      "name": "Rock_Ice_Permafrost"
    },
    {
      "x": -21,
      "y": -30,
      "z": 7,
      "name": "Rock_Ice_Permafrost"
    },
    {
      "x": -21,
      "y": -6,
      "z": 7,
      "name": "Rock_Ice_Permafrost"
    },
    {
      "x": -21,
      "y": -5,
      "z": 7,
      "name": "Rock_Ice_Permafrost"
    },
    {
      "x": -21,
      "y": -4,
      "z": 7,
      "name": "Rock_Ice_Permafrost"
    },
    {
      "x": -21,
      "y": -1,
      "z": 7,
      "name": "Rock_Ice_Permafrost"
    },
    {
      "x": -21,
      "y": 0,
      "z": 7,
      "name": "Rock_Ice_Permafrost"
    },
    {
      "x": -21,
      "y": 5,
      "z": 7,
      "name": "Rock_Ice_Permafrost"
    },
    {
      "x": -21,
      "y": 6,
      "z": 7,
      "name": "Rock_Ice_Permafrost"
    },
    {
      "x": -21,
      "y": 7,
      "z": 7,
      "name": "Rock_Ice_Permafrost"
    },
    {
      "x": -21,
      "y": 8,
      "z": 7,
      "name": "Rock_Ice_Permafrost"
    },
    {
      "x": -21,
      "y": 16,
      "z": 7,
      "name": "Rock_Ice_Permafrost"
    },
    {
      "x": -21,
      "y": 17,
      "z": 7,
      "name": "Rock_Ice_Permafrost"
    },
    {
      "x": -21,
      "y": -33,
      "z": 8,
      "name": "Rock_Ice_Permafrost"
    },
    {
      "x": -21,
      "y": -32,
      "z": 8,
      "name": "Rock_Ice_Permafrost"
    },
    {
      "x": -21,
      "y": -31,
      "z": 8,
      "name": "Rock_Ice_Permafrost"
    },
    {
      "x": -21,
      "y": -30,
      "z": 8,
      "name": "Rock_Ice_Permafrost"
    },
    {
      "x": -21,
      "y": -6,
      "z": 8,
      "name": "Rock_Ice_Permafrost"
    },
    {
      "x": -21,
      "y": -5,
      "z": 8,
      "name": "Rock_Ice_Permafrost"
    },
    {
      "x": -21,
      "y": -2,
      "z": 8,
      "name": "Rock_Ice_Permafrost"
    },
    {
      "x": -21,
      "y": -1,
      "z": 8,
      "name": "Rock_Ice_Permafrost"
    },
    {
      "x": -21,
      "y": 0,
      "z": 8,
      "name": "Rock_Ice_Permafrost"
    },
    {
      "x": -21,
      "y": 5,
      "z": 8,
      "name": "Rock_Ice_Permafrost"
    },
    {
      "x": -21,
      "y": 6,
      "z": 8,
      "name": "Rock_Ice_Permafrost"
    },
    {
      "x": -21,
      "y": 7,
      "z": 8,
      "name": "Rock_Ice_Permafrost"
    },
    {
      "x": -21,
      "y": 8,
      "z": 8,
      "name": "Rock_Ice_Permafrost"
    },
    {
      "x": -21,
      "y": -7,
      "z": 9,
      "name": "Rock_Ice_Permafrost"
    },
    {
      "x": -21,
      "y": -6,
      "z": 9,
      "name": "Rock_Ice_Permafrost"
    },
    {
      "x": -21,
      "y": -5,
      "z": 9,
      "name": "Rock_Ice_Permafrost"
    },
    {
      "x": -21,
      "y": -4,
      "z": 9,
      "name": "Rock_Ice_Permafrost"
    },
    {
      "x": -21,
      "y": -3,
      "z": 9,
      "name": "Rock_Ice_Permafrost"
    },
    {
      "x": -21,
      "y": -2,
      "z": 9,
      "name": "Rock_Ice_Permafrost"
    },
    {
      "x": -21,
      "y": -1,
      "z": 9,
      "name": "Rock_Ice_Permafrost"
    },
    {
      "x": -21,
      "y": -6,
      "z": 10,
      "name": "Rock_Ice_Permafrost"
    },
    {
      "x": -21,
      "y": -5,
      "z": 10,
      "name": "Rock_Ice_Permafrost"
    },
    {
      "x": -21,
      "y": -4,
      "z": 10,
      "name": "Rock_Ice_Permafrost"
    },
    {
      "x": -20,
      "y": 0,
      "z": -9,
      "name": "Rock_Ice_Permafrost"
    },
    {
      "x": -20,
      "y": 1,
      "z": -9,
      "name": "Rock_Ice_Permafrost"
    },
    {
      "x": -20,
      "y": 0,
      "z": -8,
      "name": "Rock_Ice_Permafrost"
    },
    {
      "x": -20,
      "y": 1,
      "z": -8,
      "name": "Rock_Ice_Permafrost"
    },
    {
      "x": -20,
      "y": 2,
      "z": -8,
      "name": "Rock_Ice_Permafrost"
    },
    {
      "x": -20,
      "y": 0,
      "z": -7,
      "name": "Rock_Ice_Permafrost"
    },
    {
      "x": -20,
      "y": 1,
      "z": -7,
      "name": "Rock_Ice_Permafrost"
    },
    {
      "x": -20,
      "y": 5,
      "z": -5,
      "name": "Rock_Ice_Permafrost"
    },
    {
      "x": -20,
      "y": 6,
      "z": -5,
      "name": "Rock_Ice_Permafrost"
    },
    {
      "x": -20,
      "y": 7,
      "z": -5,
      "name": "Rock_Ice_Permafrost"
    },
    {
      "x": -20,
      "y": 8,
      "z": -5,
      "name": "Rock_Ice_Permafrost"
    },
    {
      "x": -20,
      "y": 9,
      "z": -5,
      "name": "Rock_Ice_Permafrost"
    },
    {
      "x": -20,
      "y": 2,
      "z": -4,
      "name": "Rock_Ice_Permafrost"
    },
    {
      "x": -20,
      "y": 3,
      "z": -4,
      "name": "Rock_Ice_Permafrost"
    },
    {
      "x": -20,
      "y": 4,
      "z": -4,
      "name": "Rock_Ice_Permafrost"
    },
    {
      "x": -20,
      "y": 5,
      "z": -4,
      "name": "Rock_Ice_Permafrost"
    },
    {
      "x": -20,
      "y": 6,
      "z": -4,
      "name": "Rock_Ice_Permafrost"
    },
    {
      "x": -20,
      "y": 7,
      "z": -4,
      "name": "Rock_Ice_Permafrost"
    },
    {
      "x": -20,
      "y": 8,
      "z": -4,
      "name": "Rock_Ice_Permafrost"
    },
    {
      "x": -20,
      "y": 9,
      "z": -4,
      "name": "Rock_Ice_Permafrost"
    },
    {
      "x": -20,
      "y": 10,
      "z": -4,
      "name": "Rock_Ice_Permafrost"
    },
    {
      "x": -20,
      "y": 1,
      "z": -3,
      "name": "Rock_Ice_Permafrost"
    },
    {
      "x": -20,
      "y": 2,
      "z": -3,
      "name": "Rock_Ice_Permafrost"
    },
    {
      "x": -20,
      "y": 3,
      "z": -3,
      "name": "Rock_Ice_Permafrost"
    },
    {
      "x": -20,
      "y": 4,
      "z": -3,
      "name": "Rock_Ice_Permafrost"
    },
    {
      "x": -20,
      "y": 5,
      "z": -3,
      "name": "Rock_Ice_Permafrost"
    },
    {
      "x": -20,
      "y": 6,
      "z": -3,
      "name": "Rock_Ice_Permafrost"
    },
    {
      "x": -20,
      "y": 7,
      "z": -3,
      "name": "Rock_Ice_Permafrost"
    },
    {
      "x": -20,
      "y": 8,
      "z": -3,
      "name": "Rock_Ice_Permafrost"
    },
    {
      "x": -20,
      "y": 9,
      "z": -3,
      "name": "Rock_Ice_Permafrost"
    },
    {
      "x": -20,
      "y": 10,
      "z": -3,
      "name": "Rock_Ice_Permafrost"
    },
    {
      "x": -20,
      "y": 11,
      "z": -3,
      "name": "Rock_Ice_Permafrost"
    },
    {
      "x": -20,
      "y": 0,
      "z": -2,
      "name": "Rock_Ice_Permafrost"
    },
    {
      "x": -20,
      "y": 1,
      "z": -2,
      "name": "Rock_Ice_Permafrost"
    },
    {
      "x": -20,
      "y": 2,
      "z": -2,
      "name": "Rock_Ice_Permafrost"
    },
    {
      "x": -20,
      "y": 3,
      "z": -2,
      "name": "Rock_Ice_Permafrost"
    },
    {
      "x": -20,
      "y": 4,
      "z": -2,
      "name": "Rock_Ice_Permafrost"
    },
    {
      "x": -20,
      "y": 5,
      "z": -2,
      "name": "Rock_Ice_Permafrost"
    },
    {
      "x": -20,
      "y": 6,
      "z": -2,
      "name": "Rock_Ice_Permafrost"
    },
    {
      "x": -20,
      "y": 9,
      "z": -2,
      "name": "Rock_Ice_Permafrost"
    },
    {
      "x": -20,
      "y": 10,
      "z": -2,
      "name": "Rock_Ice_Permafrost"
    },
    {
      "x": -20,
      "y": 11,
      "z": -2,
      "name": "Rock_Ice_Permafrost"
    },
    {
      "x": -20,
      "y": 12,
      "z": -2,
      "name": "Rock_Ice_Permafrost"
    },
    {
      "x": -20,
      "y": 13,
      "z": -2,
      "name": "Rock_Ice_Permafrost"
    },
    {
      "x": -20,
      "y": 10,
      "z": -1,
      "name": "Rock_Ice_Permafrost"
    },
    {
      "x": -20,
      "y": 11,
      "z": -1,
      "name": "Rock_Ice_Permafrost"
    },
    {
      "x": -20,
      "y": 12,
      "z": -1,
      "name": "Rock_Ice_Permafrost"
    },
    {
      "x": -20,
      "y": 13,
      "z": -1,
      "name": "Rock_Ice_Permafrost"
    },
    {
      "x": -20,
      "y": 11,
      "z": 0,
      "name": "Rock_Ice_Permafrost"
    },
    {
      "x": -20,
      "y": -6,
      "z": 2,
      "name": "Rock_Ice_Permafrost"
    },
    {
      "x": -20,
      "y": -5,
      "z": 2,
      "name": "Rock_Ice_Permafrost"
    },
    {
      "x": -20,
      "y": -4,
      "z": 2,
      "name": "Rock_Ice_Permafrost"
    },
    {
      "x": -20,
      "y": -6,
      "z": 3,
      "name": "Rock_Ice_Permafrost"
    },
    {
      "x": -20,
      "y": -5,
      "z": 3,
      "name": "Rock_Ice_Permafrost"
    },
    {
      "x": -20,
      "y": -4,
      "z": 3,
      "name": "Rock_Ice_Permafrost"
    },
    {
      "x": -20,
      "y": -3,
      "z": 3,
      "name": "Rock_Ice_Permafrost"
    },
    {
      "x": -20,
      "y": -2,
      "z": 3,
      "name": "Rock_Ice_Permafrost"
    },
    {
      "x": -20,
      "y": 3,
      "z": 3,
      "name": "Rock_Ice_Permafrost"
    },
    {
      "x": -20,
      "y": 4,
      "z": 3,
      "name": "Rock_Ice_Permafrost"
    },
    {
      "x": -20,
      "y": 5,
      "z": 3,
      "name": "Rock_Ice_Permafrost"
    },
    {
      "x": -20,
      "y": 6,
      "z": 3,
      "name": "Rock_Ice_Permafrost"
    },
    {
      "x": -20,
      "y": 15,
      "z": 3,
      "name": "Rock_Ice_Permafrost"
    },
    {
      "x": -20,
      "y": -6,
      "z": 4,
      "name": "Rock_Ice_Permafrost"
    },
    {
      "x": -20,
      "y": -5,
      "z": 4,
      "name": "Rock_Ice_Permafrost"
    },
    {
      "x": -20,
      "y": -4,
      "z": 4,
      "name": "Rock_Ice_Permafrost"
    },
    {
      "x": -20,
      "y": -3,
      "z": 4,
      "name": "Rock_Ice_Permafrost"
    },
    {
      "x": -20,
      "y": -2,
      "z": 4,
      "name": "Rock_Ice_Permafrost"
    },
    {
      "x": -20,
      "y": 4,
      "z": 4,
      "name": "Rock_Ice_Permafrost"
    },
    {
      "x": -20,
      "y": 5,
      "z": 4,
      "name": "Rock_Ice_Permafrost"
    },
    {
      "x": -20,
      "y": 6,
      "z": 4,
      "name": "Rock_Ice_Permafrost"
    },
    {
      "x": -20,
      "y": 13,
      "z": 4,
      "name": "Rock_Ice_Permafrost"
    },
    {
      "x": -20,
      "y": 14,
      "z": 4,
      "name": "Rock_Ice_Permafrost"
    },
    {
      "x": -20,
      "y": 15,
      "z": 4,
      "name": "Rock_Ice_Permafrost"
    },
    {
      "x": -20,
      "y": 16,
      "z": 4,
      "name": "Rock_Ice_Permafrost"
    },
    {
      "x": -20,
      "y": 17,
      "z": 4,
      "name": "Rock_Ice_Permafrost"
    },
    {
      "x": -20,
      "y": -5,
      "z": 5,
      "name": "Rock_Ice_Permafrost"
    },
    {
      "x": -20,
      "y": -4,
      "z": 5,
      "name": "Rock_Ice_Permafrost"
    },
    {
      "x": -20,
      "y": -3,
      "z": 5,
      "name": "Rock_Ice_Permafrost"
    },
    {
      "x": -20,
      "y": -2,
      "z": 5,
      "name": "Rock_Ice_Permafrost"
    },
    {
      "x": -20,
      "y": -1,
      "z": 5,
      "name": "Rock_Ice_Permafrost"
    },
    {
      "x": -20,
      "y": 4,
      "z": 5,
      "name": "Rock_Ice_Permafrost"
    },
    {
      "x": -20,
      "y": 5,
      "z": 5,
      "name": "Rock_Ice_Permafrost"
    },
    {
      "x": -20,
      "y": 6,
      "z": 5,
      "name": "Rock_Ice_Permafrost"
    },
    {
      "x": -20,
      "y": 7,
      "z": 5,
      "name": "Rock_Ice_Permafrost"
    },
    {
      "x": -20,
      "y": 13,
      "z": 5,
      "name": "Rock_Ice_Permafrost"
    },
    {
      "x": -20,
      "y": 14,
      "z": 5,
      "name": "Rock_Ice_Permafrost"
    },
    {
      "x": -20,
      "y": 16,
      "z": 5,
      "name": "Rock_Ice_Permafrost"
    },
    {
      "x": -20,
      "y": 17,
      "z": 5,
      "name": "Rock_Ice_Permafrost"
    },
    {
      "x": -20,
      "y": -32,
      "z": 6,
      "name": "Rock_Ice_Permafrost"
    },
    {
      "x": -20,
      "y": -31,
      "z": 6,
      "name": "Rock_Ice_Permafrost"
    },
    {
      "x": -20,
      "y": -30,
      "z": 6,
      "name": "Rock_Ice_Permafrost"
    },
    {
      "x": -20,
      "y": -5,
      "z": 6,
      "name": "Rock_Ice_Permafrost"
    },
    {
      "x": -20,
      "y": -2,
      "z": 6,
      "name": "Rock_Ice_Permafrost"
    },
    {
      "x": -20,
      "y": -1,
      "z": 6,
      "name": "Rock_Ice_Permafrost"
    },
    {
      "x": -20,
      "y": 4,
      "z": 6,
      "name": "Rock_Ice_Permafrost"
    },
    {
      "x": -20,
      "y": 5,
      "z": 6,
      "name": "Rock_Ice_Permafrost"
    },
    {
      "x": -20,
      "y": 7,
      "z": 6,
      "name": "Rock_Ice_Permafrost"
    },
    {
      "x": -20,
      "y": 8,
      "z": 6,
      "name": "Rock_Ice_Permafrost"
    },
    {
      "x": -20,
      "y": 13,
      "z": 6,
      "name": "Rock_Ice_Permafrost"
    },
    {
      "x": -20,
      "y": 14,
      "z": 6,
      "name": "Rock_Ice_Permafrost"
    },
    {
      "x": -20,
      "y": 15,
      "z": 6,
      "name": "Rock_Ice_Permafrost"
    },
    {
      "x": -20,
      "y": 16,
      "z": 6,
      "name": "Rock_Ice_Permafrost"
    },
    {
      "x": -20,
      "y": 17,
      "z": 6,
      "name": "Rock_Ice_Permafrost"
    },
    {
      "x": -20,
      "y": -33,
      "z": 7,
      "name": "Rock_Ice_Permafrost"
    },
    {
      "x": -20,
      "y": -32,
      "z": 7,
      "name": "Rock_Ice_Permafrost"
    },
    {
      "x": -20,
      "y": -31,
      "z": 7,
      "name": "Rock_Ice_Permafrost"
    },
    {
      "x": -20,
      "y": -30,
      "z": 7,
      "name": "Rock_Ice_Permafrost"
    },
    {
      "x": -20,
      "y": -29,
      "z": 7,
      "name": "Rock_Ice_Permafrost"
    },
    {
      "x": -20,
      "y": -6,
      "z": 7,
      "name": "Rock_Ice_Permafrost"
    },
    {
      "x": -20,
      "y": -5,
      "z": 7,
      "name": "Rock_Ice_Permafrost"
    },
    {
      "x": -20,
      "y": -1,
      "z": 7,
      "name": "Rock_Ice_Permafrost"
    },
    {
      "x": -20,
      "y": 0,
      "z": 7,
      "name": "Rock_Ice_Permafrost"
    },
    {
      "x": -20,
      "y": 4,
      "z": 7,
      "name": "Rock_Ice_Permafrost"
    },
    {
      "x": -20,
      "y": 5,
      "z": 7,
      "name": "Rock_Ice_Permafrost"
    },
    {
      "x": -20,
      "y": 6,
      "z": 7,
      "name": "Rock_Ice_Permafrost"
    },
    {
      "x": -20,
      "y": 7,
      "z": 7,
      "name": "Rock_Ice_Permafrost"
    },
    {
      "x": -20,
      "y": 8,
      "z": 7,
      "name": "Rock_Ice_Permafrost"
    },
    {
      "x": -20,
      "y": 16,
      "z": 7,
      "name": "Rock_Ice_Permafrost"
    },
    {
      "x": -20,
      "y": -33,
      "z": 8,
      "name": "Rock_Ice_Permafrost"
    },
    {
      "x": -20,
      "y": -32,
      "z": 8,
      "name": "Rock_Ice_Permafrost"
    },
    {
      "x": -20,
      "y": -31,
      "z": 8,
      "name": "Rock_Ice_Permafrost"
    },
    {
      "x": -20,
      "y": -30,
      "z": 8,
      "name": "Rock_Ice_Permafrost"
    },
    {
      "x": -20,
      "y": -29,
      "z": 8,
      "name": "Rock_Ice_Permafrost"
    },
    {
      "x": -20,
      "y": -7,
      "z": 8,
      "name": "Rock_Ice_Permafrost"
    },
    {
      "x": -20,
      "y": -6,
      "z": 8,
      "name": "Rock_Ice_Permafrost"
    },
    {
      "x": -20,
      "y": -5,
      "z": 8,
      "name": "Rock_Ice_Permafrost"
    },
    {
      "x": -20,
      "y": -4,
      "z": 8,
      "name": "Rock_Ice_Permafrost"
    },
    {
      "x": -20,
      "y": -3,
      "z": 8,
      "name": "Rock_Ice_Permafrost"
    },
    {
      "x": -20,
      "y": -2,
      "z": 8,
      "name": "Rock_Ice_Permafrost"
    },
    {
      "x": -20,
      "y": -1,
      "z": 8,
      "name": "Rock_Ice_Permafrost"
    },
    {
      "x": -20,
      "y": 5,
      "z": 8,
      "name": "Rock_Ice_Permafrost"
    },
    {
      "x": -20,
      "y": 6,
      "z": 8,
      "name": "Rock_Ice_Permafrost"
    },
    {
      "x": -20,
      "y": 7,
      "z": 8,
      "name": "Rock_Ice_Permafrost"
    },
    {
      "x": -20,
      "y": -7,
      "z": 9,
      "name": "Rock_Ice_Permafrost"
    },
    {
      "x": -20,
      "y": -6,
      "z": 9,
      "name": "Rock_Ice_Permafrost"
    },
    {
      "x": -20,
      "y": -5,
      "z": 9,
      "name": "Rock_Ice_Permafrost"
    },
    {
      "x": -20,
      "y": -4,
      "z": 9,
      "name": "Rock_Ice_Permafrost"
    },
    {
      "x": -20,
      "y": -3,
      "z": 9,
      "name": "Rock_Ice_Permafrost"
    },
    {
      "x": -20,
      "y": -2,
      "z": 9,
      "name": "Rock_Ice_Permafrost"
    },
    {
      "x": -20,
      "y": -7,
      "z": 10,
      "name": "Rock_Ice_Permafrost"
    },
    {
      "x": -20,
      "y": -6,
      "z": 10,
      "name": "Rock_Ice_Permafrost"
    },
    {
      "x": -20,
      "y": 18,
      "z": 23,
      "name": "Rock_Ice_Permafrost"
    },
    {
      "x": -20,
      "y": 19,
      "z": 23,
      "name": "Rock_Ice_Permafrost"
    },
    {
      "x": -20,
      "y": 19,
      "z": 24,
      "name": "Rock_Ice_Permafrost"
    },
    {
      "x": -19,
      "y": 0,
      "z": -9,
      "name": "Rock_Ice_Permafrost"
    },
    {
      "x": -19,
      "y": 1,
      "z": -9,
      "name": "Rock_Ice_Permafrost"
    },
    {
      "x": -19,
      "y": -1,
      "z": -8,
      "name": "Rock_Ice_Permafrost"
    },
    {
      "x": -19,
      "y": 0,
      "z": -8,
      "name": "Rock_Ice_Permafrost"
    },
    {
      "x": -19,
      "y": 1,
      "z": -8,
      "name": "Rock_Ice_Permafrost"
    },
    {
      "x": -19,
      "y": 2,
      "z": -8,
      "name": "Rock_Ice_Permafrost"
    },
    {
      "x": -19,
      "y": 20,
      "z": -8,
      "name": "Rock_Ice_Permafrost"
    },
    {
      "x": -19,
      "y": 21,
      "z": -8,
      "name": "Rock_Ice_Permafrost"
    },
    {
      "x": -19,
      "y": -1,
      "z": -7,
      "name": "Rock_Ice_Permafrost"
    },
    {
      "x": -19,
      "y": 0,
      "z": -7,
      "name": "Rock_Ice_Permafrost"
    },
    {
      "x": -19,
      "y": 1,
      "z": -7,
      "name": "Rock_Ice_Permafrost"
    },
    {
      "x": -19,
      "y": 4,
      "z": -5,
      "name": "Rock_Ice_Permafrost"
    },
    {
      "x": -19,
      "y": 5,
      "z": -5,
      "name": "Rock_Ice_Permafrost"
    },
    {
      "x": -19,
      "y": 6,
      "z": -5,
      "name": "Rock_Ice_Permafrost"
    },
    {
      "x": -19,
      "y": 7,
      "z": -5,
      "name": "Rock_Ice_Permafrost"
    },
    {
      "x": -19,
      "y": 8,
      "z": -5,
      "name": "Rock_Ice_Permafrost"
    },
    {
      "x": -19,
      "y": 9,
      "z": -5,
      "name": "Rock_Ice_Permafrost"
    },
    {
      "x": -19,
      "y": 1,
      "z": -4,
      "name": "Rock_Ice_Permafrost"
    },
    {
      "x": -19,
      "y": 2,
      "z": -4,
      "name": "Rock_Ice_Permafrost"
    },
    {
      "x": -19,
      "y": 3,
      "z": -4,
      "name": "Rock_Ice_Permafrost"
    },
    {
      "x": -19,
      "y": 4,
      "z": -4,
      "name": "Rock_Ice_Permafrost"
    },
    {
      "x": -19,
      "y": 5,
      "z": -4,
      "name": "Rock_Ice_Permafrost"
    },
    {
      "x": -19,
      "y": 6,
      "z": -4,
      "name": "Rock_Ice_Permafrost"
    },
    {
      "x": -19,
      "y": 7,
      "z": -4,
      "name": "Rock_Ice_Permafrost"
    },
    {
      "x": -19,
      "y": 8,
      "z": -4,
      "name": "Rock_Ice_Permafrost"
    },
    {
      "x": -19,
      "y": 9,
      "z": -4,
      "name": "Rock_Ice_Permafrost"
    },
    {
      "x": -19,
      "y": 10,
      "z": -4,
      "name": "Rock_Ice_Permafrost"
    },
    {
      "x": -19,
      "y": 0,
      "z": -3,
      "name": "Rock_Ice_Permafrost"
    },
    {
      "x": -19,
      "y": 1,
      "z": -3,
      "name": "Rock_Ice_Permafrost"
    },
    {
      "x": -19,
      "y": 2,
      "z": -3,
      "name": "Rock_Ice_Permafrost"
    },
    {
      "x": -19,
      "y": 4,
      "z": -3,
      "name": "Rock_Ice_Permafrost"
    },
    {
      "x": -19,
      "y": 5,
      "z": -3,
      "name": "Rock_Ice_Permafrost"
    },
    {
      "x": -19,
      "y": 6,
      "z": -3,
      "name": "Rock_Ice_Permafrost"
    },
    {
      "x": -19,
      "y": 7,
      "z": -3,
      "name": "Rock_Ice_Permafrost"
    },
    {
      "x": -19,
      "y": 8,
      "z": -3,
      "name": "Rock_Ice_Permafrost"
    },
    {
      "x": -19,
      "y": 9,
      "z": -3,
      "name": "Rock_Ice_Permafrost"
    },
    {
      "x": -19,
      "y": 10,
      "z": -3,
      "name": "Rock_Ice_Permafrost"
    },
    {
      "x": -19,
      "y": 11,
      "z": -3,
      "name": "Rock_Ice_Permafrost"
    },
    {
      "x": -19,
      "y": -1,
      "z": -2,
      "name": "Rock_Ice_Permafrost"
    },
    {
      "x": -19,
      "y": 0,
      "z": -2,
      "name": "Rock_Ice_Permafrost"
    },
    {
      "x": -19,
      "y": 1,
      "z": -2,
      "name": "Rock_Ice_Permafrost"
    },
    {
      "x": -19,
      "y": 2,
      "z": -2,
      "name": "Rock_Ice_Permafrost"
    },
    {
      "x": -19,
      "y": 3,
      "z": -2,
      "name": "Rock_Ice_Permafrost"
    },
    {
      "x": -19,
      "y": 4,
      "z": -2,
      "name": "Rock_Ice_Permafrost"
    },
    {
      "x": -19,
      "y": 5,
      "z": -2,
      "name": "Rock_Ice_Permafrost"
    },
    {
      "x": -19,
      "y": 6,
      "z": -2,
      "name": "Rock_Ice_Permafrost"
    },
    {
      "x": -19,
      "y": 7,
      "z": -2,
      "name": "Rock_Ice_Permafrost"
    },
    {
      "x": -19,
      "y": 8,
      "z": -2,
      "name": "Rock_Ice_Permafrost"
    },
    {
      "x": -19,
      "y": 9,
      "z": -2,
      "name": "Rock_Ice_Permafrost"
    },
    {
      "x": -19,
      "y": 10,
      "z": -2,
      "name": "Rock_Ice_Permafrost"
    },
    {
      "x": -19,
      "y": 11,
      "z": -2,
      "name": "Rock_Ice_Permafrost"
    },
    {
      "x": -19,
      "y": 12,
      "z": -2,
      "name": "Rock_Ice_Permafrost"
    },
    {
      "x": -19,
      "y": -1,
      "z": -1,
      "name": "Rock_Ice_Permafrost"
    },
    {
      "x": -19,
      "y": 0,
      "z": -1,
      "name": "Rock_Ice_Permafrost"
    },
    {
      "x": -19,
      "y": 1,
      "z": -1,
      "name": "Rock_Ice_Permafrost"
    },
    {
      "x": -19,
      "y": 8,
      "z": -1,
      "name": "Rock_Ice_Permafrost"
    },
    {
      "x": -19,
      "y": 9,
      "z": -1,
      "name": "Rock_Ice_Permafrost"
    },
    {
      "x": -19,
      "y": 10,
      "z": -1,
      "name": "Rock_Ice_Permafrost"
    },
    {
      "x": -19,
      "y": 11,
      "z": -1,
      "name": "Rock_Ice_Permafrost"
    },
    {
      "x": -19,
      "y": 12,
      "z": -1,
      "name": "Rock_Ice_Permafrost"
    },
    {
      "x": -19,
      "y": -12,
      "z": 0,
      "name": "Rock_Ice_Permafrost"
    },
    {
      "x": -19,
      "y": 9,
      "z": 0,
      "name": "Rock_Ice_Permafrost"
    },
    {
      "x": -19,
      "y": 10,
      "z": 0,
      "name": "Rock_Ice_Permafrost"
    },
    {
      "x": -19,
      "y": 11,
      "z": 0,
      "name": "Rock_Ice_Permafrost"
    },
    {
      "x": -19,
      "y": -13,
      "z": 1,
      "name": "Rock_Ice_Permafrost"
    },
    {
      "x": -19,
      "y": -12,
      "z": 1,
      "name": "Rock_Ice_Permafrost"
    },
    {
      "x": -19,
      "y": -11,
      "z": 1,
      "name": "Rock_Ice_Permafrost"
    },
    {
      "x": -19,
      "y": -7,
      "z": 2,
      "name": "Rock_Ice_Permafrost"
    },
    {
      "x": -19,
      "y": -6,
      "z": 2,
      "name": "Rock_Ice_Permafrost"
    },
    {
      "x": -19,
      "y": -5,
      "z": 2,
      "name": "Rock_Ice_Permafrost"
    },
    {
      "x": -19,
      "y": -4,
      "z": 2,
      "name": "Rock_Ice_Permafrost"
    },
    {
      "x": -19,
      "y": -3,
      "z": 2,
      "name": "Rock_Ice_Permafrost"
    },
    {
      "x": -19,
      "y": -2,
      "z": 2,
      "name": "Rock_Ice_Permafrost"
    },
    {
      "x": -19,
      "y": 2,
      "z": 2,
      "name": "Rock_Ice_Permafrost"
    },
    {
      "x": -19,
      "y": 3,
      "z": 2,
      "name": "Rock_Ice_Permafrost"
    },
    {
      "x": -19,
      "y": 4,
      "z": 2,
      "name": "Rock_Ice_Permafrost"
    },
    {
      "x": -19,
      "y": 5,
      "z": 2,
      "name": "Rock_Ice_Permafrost"
    },
    {
      "x": -19,
      "y": -7,
      "z": 3,
      "name": "Rock_Ice_Permafrost"
    },
    {
      "x": -19,
      "y": -6,
      "z": 3,
      "name": "Rock_Ice_Permafrost"
    },
    {
      "x": -19,
      "y": -5,
      "z": 3,
      "name": "Rock_Ice_Permafrost"
    },
    {
      "x": -19,
      "y": -4,
      "z": 3,
      "name": "Rock_Ice_Permafrost"
    },
    {
      "x": -19,
      "y": -3,
      "z": 3,
      "name": "Rock_Ice_Permafrost"
    },
    {
      "x": -19,
      "y": -2,
      "z": 3,
      "name": "Rock_Ice_Permafrost"
    },
    {
      "x": -19,
      "y": 2,
      "z": 3,
      "name": "Rock_Ice_Permafrost"
    },
    {
      "x": -19,
      "y": 3,
      "z": 3,
      "name": "Rock_Ice_Permafrost"
    },
    {
      "x": -19,
      "y": 4,
      "z": 3,
      "name": "Rock_Ice_Permafrost"
    },
    {
      "x": -19,
      "y": 5,
      "z": 3,
      "name": "Rock_Ice_Permafrost"
    },
    {
      "x": -19,
      "y": 13,
      "z": 3,
      "name": "Rock_Ice_Permafrost"
    },
    {
      "x": -19,
      "y": 14,
      "z": 3,
      "name": "Rock_Ice_Permafrost"
    },
    {
      "x": -19,
      "y": 15,
      "z": 3,
      "name": "Rock_Ice_Permafrost"
    },
    {
      "x": -19,
      "y": 16,
      "z": 3,
      "name": "Rock_Ice_Permafrost"
    },
    {
      "x": -19,
      "y": -6,
      "z": 4,
      "name": "Rock_Ice_Permafrost"
    },
    {
      "x": -19,
      "y": -5,
      "z": 4,
      "name": "Rock_Ice_Permafrost"
    },
    {
      "x": -19,
      "y": -3,
      "z": 4,
      "name": "Rock_Ice_Permafrost"
    },
    {
      "x": -19,
      "y": -2,
      "z": 4,
      "name": "Rock_Ice_Permafrost"
    },
    {
      "x": -19,
      "y": 3,
      "z": 4,
      "name": "Rock_Ice_Permafrost"
    },
    {
      "x": -19,
      "y": 4,
      "z": 4,
      "name": "Rock_Ice_Permafrost"
    },
    {
      "x": -19,
      "y": 5,
      "z": 4,
      "name": "Rock_Ice_Permafrost"
    },
    {
      "x": -19,
      "y": 6,
      "z": 4,
      "name": "Rock_Ice_Permafrost"
    },
    {
      "x": -19,
      "y": 12,
      "z": 4,
      "name": "Rock_Ice_Permafrost"
    },
    {
      "x": -19,
      "y": 13,
      "z": 4,
      "name": "Rock_Ice_Permafrost"
    },
    {
      "x": -19,
      "y": 14,
      "z": 4,
      "name": "Rock_Ice_Permafrost"
    },
    {
      "x": -19,
      "y": 15,
      "z": 4,
      "name": "Rock_Ice_Permafrost"
    },
    {
      "x": -19,
      "y": 16,
      "z": 4,
      "name": "Rock_Ice_Permafrost"
    },
    {
      "x": -19,
      "y": -30,
      "z": 5,
      "name": "Rock_Ice_Permafrost"
    },
    {
      "x": -19,
      "y": -6,
      "z": 5,
      "name": "Rock_Ice_Permafrost"
    },
    {
      "x": -19,
      "y": -5,
      "z": 5,
      "name": "Rock_Ice_Permafrost"
    },
    {
      "x": -19,
      "y": -2,
      "z": 5,
      "name": "Rock_Ice_Permafrost"
    },
    {
      "x": -19,
      "y": -1,
      "z": 5,
      "name": "Rock_Ice_Permafrost"
    },
    {
      "x": -19,
      "y": 3,
      "z": 5,
      "name": "Rock_Ice_Permafrost"
    },
    {
      "x": -19,
      "y": 4,
      "z": 5,
      "name": "Rock_Ice_Permafrost"
    },
    {
      "x": -19,
      "y": 6,
      "z": 5,
      "name": "Rock_Ice_Permafrost"
    },
    {
      "x": -19,
      "y": 7,
      "z": 5,
      "name": "Rock_Ice_Permafrost"
    },
    {
      "x": -19,
      "y": 12,
      "z": 5,
      "name": "Rock_Ice_Permafrost"
    },
    {
      "x": -19,
      "y": 13,
      "z": 5,
      "name": "Rock_Ice_Permafrost"
    },
    {
      "x": -19,
      "y": 15,
      "z": 5,
      "name": "Rock_Ice_Permafrost"
    },
    {
      "x": -19,
      "y": 16,
      "z": 5,
      "name": "Rock_Ice_Permafrost"
    },
    {
      "x": -19,
      "y": 17,
      "z": 5,
      "name": "Rock_Ice_Permafrost"
    },
    {
      "x": -19,
      "y": -31,
      "z": 6,
      "name": "Rock_Ice_Permafrost"
    },
    {
      "x": -19,
      "y": -30,
      "z": 6,
      "name": "Rock_Ice_Permafrost"
    },
    {
      "x": -19,
      "y": -29,
      "z": 6,
      "name": "Rock_Ice_Permafrost"
    },
    {
      "x": -19,
      "y": -28,
      "z": 6,
      "name": "Rock_Ice_Permafrost"
    },
    {
      "x": -19,
      "y": -6,
      "z": 6,
      "name": "Rock_Ice_Permafrost"
    },
    {
      "x": -19,
      "y": -5,
      "z": 6,
      "name": "Rock_Ice_Permafrost"
    },
    {
      "x": -19,
      "y": -2,
      "z": 6,
      "name": "Rock_Ice_Permafrost"
    },
    {
      "x": -19,
      "y": -1,
      "z": 6,
      "name": "Rock_Ice_Permafrost"
    },
    {
      "x": -19,
      "y": 3,
      "z": 6,
      "name": "Rock_Ice_Permafrost"
    },
    {
      "x": -19,
      "y": 4,
      "z": 6,
      "name": "Rock_Ice_Permafrost"
    },
    {
      "x": -19,
      "y": 7,
      "z": 6,
      "name": "Rock_Ice_Permafrost"
    },
    {
      "x": -19,
      "y": 13,
      "z": 6,
      "name": "Rock_Ice_Permafrost"
    },
    {
      "x": -19,
      "y": 14,
      "z": 6,
      "name": "Rock_Ice_Permafrost"
    },
    {
      "x": -19,
      "y": 15,
      "z": 6,
      "name": "Rock_Ice_Permafrost"
    },
    {
      "x": -19,
      "y": 16,
      "z": 6,
      "name": "Rock_Ice_Permafrost"
    },
    {
      "x": -19,
      "y": -32,
      "z": 7,
      "name": "Rock_Ice_Permafrost"
    },
    {
      "x": -19,
      "y": -31,
      "z": 7,
      "name": "Rock_Ice_Permafrost"
    },
    {
      "x": -19,
      "y": -30,
      "z": 7,
      "name": "Rock_Ice_Permafrost"
    },
    {
      "x": -19,
      "y": -29,
      "z": 7,
      "name": "Rock_Ice_Permafrost"
    },
    {
      "x": -19,
      "y": -28,
      "z": 7,
      "name": "Rock_Ice_Permafrost"
    },
    {
      "x": -19,
      "y": -27,
      "z": 7,
      "name": "Rock_Ice_Permafrost"
    },
    {
      "x": -19,
      "y": -7,
      "z": 7,
      "name": "Rock_Ice_Permafrost"
    },
    {
      "x": -19,
      "y": -6,
      "z": 7,
      "name": "Rock_Ice_Permafrost"
    },
    {
      "x": -19,
      "y": -5,
      "z": 7,
      "name": "Rock_Ice_Permafrost"
    },
    {
      "x": -19,
      "y": -1,
      "z": 7,
      "name": "Rock_Ice_Permafrost"
    },
    {
      "x": -19,
      "y": 0,
      "z": 7,
      "name": "Rock_Ice_Permafrost"
    },
    {
      "x": -19,
      "y": 4,
      "z": 7,
      "name": "Rock_Ice_Permafrost"
    },
    {
      "x": -19,
      "y": 5,
      "z": 7,
      "name": "Rock_Ice_Permafrost"
    },
    {
      "x": -19,
      "y": 6,
      "z": 7,
      "name": "Rock_Ice_Permafrost"
    },
    {
      "x": -19,
      "y": 7,
      "z": 7,
      "name": "Rock_Ice_Permafrost"
    },
    {
      "x": -19,
      "y": -32,
      "z": 8,
      "name": "Rock_Ice_Permafrost"
    },
    {
      "x": -19,
      "y": -31,
      "z": 8,
      "name": "Rock_Ice_Permafrost"
    },
    {
      "x": -19,
      "y": -30,
      "z": 8,
      "name": "Rock_Ice_Permafrost"
    },
    {
      "x": -19,
      "y": -29,
      "z": 8,
      "name": "Rock_Ice_Permafrost"
    },
    {
      "x": -19,
      "y": -28,
      "z": 8,
      "name": "Rock_Ice_Permafrost"
    },
    {
      "x": -19,
      "y": -7,
      "z": 8,
      "name": "Rock_Ice_Permafrost"
    },
    {
      "x": -19,
      "y": -6,
      "z": 8,
      "name": "Rock_Ice_Permafrost"
    },
    {
      "x": -19,
      "y": -5,
      "z": 8,
      "name": "Rock_Ice_Permafrost"
    },
    {
      "x": -19,
      "y": -4,
      "z": 8,
      "name": "Rock_Ice_Permafrost"
    },
    {
      "x": -19,
      "y": -3,
      "z": 8,
      "name": "Rock_Ice_Permafrost"
    },
    {
      "x": -19,
      "y": -2,
      "z": 8,
      "name": "Rock_Ice_Permafrost"
    },
    {
      "x": -19,
      "y": -1,
      "z": 8,
      "name": "Rock_Ice_Permafrost"
    },
    {
      "x": -19,
      "y": 5,
      "z": 8,
      "name": "Rock_Ice_Permafrost"
    },
    {
      "x": -19,
      "y": 6,
      "z": 8,
      "name": "Rock_Ice_Permafrost"
    },
    {
      "x": -19,
      "y": 7,
      "z": 8,
      "name": "Rock_Ice_Permafrost"
    },
    {
      "x": -19,
      "y": -8,
      "z": 9,
      "name": "Rock_Ice_Permafrost"
    },
    {
      "x": -19,
      "y": -7,
      "z": 9,
      "name": "Rock_Ice_Permafrost"
    },
    {
      "x": -19,
      "y": -6,
      "z": 9,
      "name": "Rock_Ice_Permafrost"
    },
    {
      "x": -19,
      "y": -5,
      "z": 9,
      "name": "Rock_Ice_Permafrost"
    },
    {
      "x": -19,
      "y": -4,
      "z": 9,
      "name": "Rock_Ice_Permafrost"
    },
    {
      "x": -19,
      "y": -3,
      "z": 9,
      "name": "Rock_Ice_Permafrost"
    },
    {
      "x": -19,
      "y": -2,
      "z": 9,
      "name": "Rock_Ice_Permafrost"
    },
    {
      "x": -19,
      "y": -22,
      "z": 12,
      "name": "Rock_Ice_Permafrost"
    },
    {
      "x": -19,
      "y": -22,
      "z": 13,
      "name": "Rock_Ice_Permafrost"
    },
    {
      "x": -19,
      "y": 17,
      "z": 22,
      "name": "Rock_Ice_Permafrost"
    },
    {
      "x": -19,
      "y": 18,
      "z": 22,
      "name": "Rock_Ice_Permafrost"
    },
    {
      "x": -19,
      "y": 19,
      "z": 22,
      "name": "Rock_Ice_Permafrost"
    },
    {
      "x": -19,
      "y": 18,
      "z": 23,
      "name": "Rock_Ice_Permafrost"
    },
    {
      "x": -18,
      "y": 3,
      "z": -20,
      "name": "Rock_Ice_Permafrost"
    },
    {
      "x": -18,
      "y": 4,
      "z": -20,
      "name": "Rock_Ice_Permafrost"
    },
    {
      "x": -18,
      "y": 27,
      "z": -19,
      "name": "Rock_Ice_Permafrost"
    },
    {
      "x": -18,
      "y": 28,
      "z": -19,
      "name": "Rock_Ice_Permafrost"
    },
    {
      "x": -18,
      "y": 29,
      "z": -19,
      "name": "Rock_Ice_Permafrost"
    },
    {
      "x": -18,
      "y": 27,
      "z": -18,
      "name": "Rock_Ice_Permafrost"
    },
    {
      "x": -18,
      "y": 28,
      "z": -18,
      "name": "Rock_Ice_Permafrost"
    },
    {
      "x": -18,
      "y": 0,
      "z": -9,
      "name": "Rock_Ice_Permafrost"
    },
    {
      "x": -18,
      "y": 1,
      "z": -9,
      "name": "Rock_Ice_Permafrost"
    },
    {
      "x": -18,
      "y": -1,
      "z": -8,
      "name": "Rock_Ice_Permafrost"
    },
    {
      "x": -18,
      "y": 0,
      "z": -8,
      "name": "Rock_Ice_Permafrost"
    },
    {
      "x": -18,
      "y": 1,
      "z": -8,
      "name": "Rock_Ice_Permafrost"
    },
    {
      "x": -18,
      "y": 2,
      "z": -8,
      "name": "Rock_Ice_Permafrost"
    },
    {
      "x": -18,
      "y": 18,
      "z": -8,
      "name": "Rock_Ice_Permafrost"
    },
    {
      "x": -18,
      "y": 19,
      "z": -8,
      "name": "Rock_Ice_Permafrost"
    },
    {
      "x": -18,
      "y": 20,
      "z": -8,
      "name": "Rock_Ice_Permafrost"
    },
    {
      "x": -18,
      "y": -12,
      "z": -7,
      "name": "Rock_Ice_Permafrost"
    },
    {
      "x": -18,
      "y": -1,
      "z": -7,
      "name": "Rock_Ice_Permafrost"
    },
    {
      "x": -18,
      "y": 0,
      "z": -7,
      "name": "Rock_Ice_Permafrost"
    },
    {
      "x": -18,
      "y": 1,
      "z": -7,
      "name": "Rock_Ice_Permafrost"
    },
    {
      "x": -18,
      "y": 2,
      "z": -7,
      "name": "Rock_Ice_Permafrost"
    },
    {
      "x": -18,
      "y": 19,
      "z": -7,
      "name": "Rock_Ice_Permafrost"
    },
    {
      "x": -18,
      "y": -12,
      "z": -6,
      "name": "Rock_Ice_Permafrost"
    },
    {
      "x": -18,
      "y": 0,
      "z": -6,
      "name": "Rock_Ice_Permafrost"
    },
    {
      "x": -18,
      "y": 1,
      "z": -6,
      "name": "Rock_Ice_Permafrost"
    },
    {
      "x": -18,
      "y": 3,
      "z": -5,
      "name": "Rock_Ice_Permafrost"
    },
    {
      "x": -18,
      "y": 4,
      "z": -5,
      "name": "Rock_Ice_Permafrost"
    },
    {
      "x": -18,
      "y": 5,
      "z": -5,
      "name": "Rock_Ice_Permafrost"
    },
    {
      "x": -18,
      "y": 6,
      "z": -5,
      "name": "Rock_Ice_Permafrost"
    },
    {
      "x": -18,
      "y": 7,
      "z": -5,
      "name": "Rock_Ice_Permafrost"
    },
    {
      "x": -18,
      "y": 8,
      "z": -5,
      "name": "Rock_Ice_Permafrost"
    },
    {
      "x": -18,
      "y": 1,
      "z": -4,
      "name": "Rock_Ice_Permafrost"
    },
    {
      "x": -18,
      "y": 2,
      "z": -4,
      "name": "Rock_Ice_Permafrost"
    },
    {
      "x": -18,
      "y": 3,
      "z": -4,
      "name": "Rock_Ice_Permafrost"
    },
    {
      "x": -18,
      "y": 4,
      "z": -4,
      "name": "Rock_Ice_Permafrost"
    },
    {
      "x": -18,
      "y": 5,
      "z": -4,
      "name": "Rock_Ice_Permafrost"
    },
    {
      "x": -18,
      "y": 6,
      "z": -4,
      "name": "Rock_Ice_Permafrost"
    },
    {
      "x": -18,
      "y": 8,
      "z": -4,
      "name": "Rock_Ice_Permafrost"
    },
    {
      "x": -18,
      "y": 9,
      "z": -4,
      "name": "Rock_Ice_Permafrost"
    },
    {
      "x": -18,
      "y": 0,
      "z": -3,
      "name": "Rock_Ice_Permafrost"
    },
    {
      "x": -18,
      "y": 1,
      "z": -3,
      "name": "Rock_Ice_Permafrost"
    },
    {
      "x": -18,
      "y": 2,
      "z": -3,
      "name": "Rock_Ice_Permafrost"
    },
    {
      "x": -18,
      "y": 5,
      "z": -3,
      "name": "Rock_Ice_Permafrost"
    },
    {
      "x": -18,
      "y": 6,
      "z": -3,
      "name": "Rock_Ice_Permafrost"
    },
    {
      "x": -18,
      "y": 7,
      "z": -3,
