{
  "version": 8,
  "blockIdVersion": 11,
  "anchorX": 0,
  "anchorY": 0,
  "anchorZ": 0,
  "blocks": [
    {
      "x": -53,
      "y": -19,
      "z": 34,
      "name": "Rock_Ice_Permafrost"
    },
    {
      "x": -53,
      "y": -18,
      "z": 34,
      "name": "Rock_Ice_Permafrost"
    },
    {
      "x": -53,
      "y": -19,
      "z": 35,
      "name": "Rock_Ice_Permafrost"
    },
    {
      "x": -53,
      "y": -18,
      "z": 35,
      "name": "Rock_Ice_Permafrost"
    },
    {
      "x": -52,
      "y": -19,
      "z": 33,
      "name": "Rock_Ice_Permafrost"
    },
    {
      "x": -52,
      "y": -18,
      "z": 33,
      "name": "Rock_Ice_Permafrost"
    },
    {
      "x": -52,
      "y": -19,
      "z": 34,
      "name": "Rock_Ice_Permafrost"
    },
    {
      "x": -52,
      "y": -18,
      "z": 34,
      "name": "Rock_Ice_Permafrost"
    },
    {
      "x": -51,
      "y": -18,
      "z": 32,
      "name": "Rock_Ice_Permafrost"
    },
    {
      "x": -51,
      "y": -17,
      "z": 32,
      "name": "Rock_Ice_Permafrost"
    },
    {
      "x": -51,
      "y": -18,
      "z": 33,
      "name": "Rock_Ice_Permafrost"
    },
    {
      "x": -51,
      "y": -17,
      "z": 33,
      "name": "Rock_Ice_Permafrost"
    },
    {
      "x": -51,
      "y": -18,
      "z": 34,
      "name": "Rock_Ice_Permafrost"
    },
    {
      "x": -50,
      "y": -17,
      "z": 31,
      "name": "Rock_Ice_Permafrost"
    },
    {
      "x": -50,
      "y": -16,
      "z": 31,
      "name": "Rock_Ice_Permafrost"
    },
    {
      "x": -50,
      "y": -18,
      "z": 32,
      "name": "Rock_Ice_Permafrost"
    },
    {
      "x": -50,
      "y": -17,
      "z": 32,
      "name": "Rock_Ice_Permafrost"
    },
    {
      "x": -50,
      "y": -16,
      "z": 32,
      "name": "Rock_Ice_Permafrost"
    },
    {
      "x": -50,
      "y": -18,
      "z": 33,
      "name": "Rock_Ice_Permafrost"
    },
    {
      "x": -50,
      "y": -17,
      "z": 33,
      "name": "Rock_Ice_Permafrost"
    },
    {
      "x": -49,
      "y": -18,
      "z": 31,
      "name": "Rock_Ice_Permafrost"
    },
    {
      "x": -49,
      "y": -17,
      "z": 31,
      "name": "Rock_Ice_Permafrost"
    },
    {
      "x": -49,
      "y": -16,
      "z": 31,
      "name": "Rock_Ice_Permafrost"
    },
    {
      "x": -49,
      "y": -18,
      "z": 32,
      "name": "Rock_Ice_Permafrost"
    },
    {
      "x": -49,
      "y": -17,
      "z": 32,
      "name": "Rock_Ice_Permafrost"
    },
    {
      "x": -49,
      "y": -16,
      "z": 32,
      "name": "Rock_Ice_Permafrost"
    },
    {
      "x": -49,
      "y": -18,
      "z": 33,
      "name": "Rock_Ice_Permafrost"
    },
    {
      "x": -49,
      "y": -17,
      "z": 33,
      "name": "Rock_Ice_Permafrost"
    },
    {
      "x": -48,
      "y": -28,
      "z": 16,
      "name": "Rock_Ice_Permafrost"
    },
    {
      "x": -48,
      "y": -29,
      "z": 17,
      "name": "Rock_Ice_Permafrost"
    },
    {
      "x": -48,
      "y": -28,
      "z": 17,
      "name": "Rock_Ice_Permafrost"
    },
    {
      "x": -48,
      "y": -18,
      "z": 30,
      "name": "Rock_Ice_Permafrost"
    },
    {
      "x": -48,
      "y": -17,
      "z": 30,
      "name": "Rock_Ice_Permafrost"
    },
    {
      "x": -48,
      "y": -16,
      "z": 30,
      "name": "Rock_Ice_Permafrost"
    },
    {
      "x": -48,
      "y": -15,
      "z": 30,
      "name": "Rock_Ice_Permafrost"
    },
    {
      "x": -48,
      "y": -18,
      "z": 31,
      "name": "Rock_Ice_Permafrost"
    },
    {
      "x": -48,
      "y": -17,
      "z": 31,
      "name": "Rock_Ice_Permafrost"
    },
    {
      "x": -48,
      "y": -16,
      "z": 31,
      "name": "Rock_Ice_Permafrost"
    },
    {
      "x": -48,
      "y": -15,
      "z": 31,
      "name": "Rock_Ice_Permafrost"
    },
    {
      "x": -48,
      "y": -18,
      "z": 32,
      "name": "Rock_Ice_Permafrost"
    },
    {
      "x": -48,
      "y": -17,
      "z": 32,
      "name": "Rock_Ice_Permafrost"
    },
    {
      "x": -48,
      "y": -16,
      "z": 32,
      "name": "Rock_Ice_Permafrost"
    },
    {
      "x": -47,
      "y": -10,
      "z": 15,
      "name": "Rock_Ice_Permafrost"
    },
    {
      "x": -47,
      "y": -9,
      "z": 15,
      "name": "Rock_Ice_Permafrost"
    },
    {
      "x": -47,
      "y": -28,
      "z": 16,
      "name": "Rock_Ice_Permafrost"
    },
    {
      "x": -47,
      "y": -27,
      "z": 16,
      "name": "Rock_Ice_Permafrost"
    },
    {
      "x": -47,
      "y": -9,
      "z": 16,
      "name": "Rock_Ice_Permafrost"
    },
    {
      "x": -47,
      "y": -28,
      "z": 17,
      "name": "Rock_Ice_Permafrost"
    },
    {
      "x": -47,
      "y": -27,
      "z": 17,
      "name": "Rock_Ice_Permafrost"
    },
    {
      "x": -47,
      "y": -17,
      "z": 29,
      "name": "Rock_Ice_Permafrost"
    },
    {
      "x": -47,
      "y": -16,
      "z": 29,
      "name": "Rock_Ice_Permafrost"
    },
    {
      "x": -47,
      "y": -15,
      "z": 29,
      "name": "Rock_Ice_Permafrost"
    },
    {
      "x": -47,
      "y": -14,
      "z": 29,
      "name": "Rock_Ice_Permafrost"
    },
    {
      "x": -47,
      "y": -18,
      "z": 30,
      "name": "Rock_Ice_Permafrost"
    },
    {
      "x": -47,
      "y": -17,
      "z": 30,
      "name": "Rock_Ice_Permafrost"
    },
    {
      "x": -47,
      "y": -16,
      "z": 30,
      "name": "Rock_Ice_Permafrost"
    },
    {
      "x": -47,
      "y": -15,
      "z": 30,
      "name": "Rock_Ice_Permafrost"
    },
    {
      "x": -47,
      "y": -18,
      "z": 31,
      "name": "Rock_Ice_Permafrost"
    },
    {
      "x": -47,
      "y": -17,
      "z": 31,
      "name": "Rock_Ice_Permafrost"
    },
    {
      "x": -47,
      "y": -16,
      "z": 31,
      "name": "Rock_Ice_Permafrost"
    },
    {
      "x": -47,
      "y": -17,
      "z": 32,
      "name": "Rock_Ice_Permafrost"
    },
    {
      "x": -46,
      "y": -9,
      "z": 14,
      "name": "Rock_Ice_Permafrost"
    },
    {
      "x": -46,
      "y": -27,
      "z": 15,
      "name": "Rock_Ice_Permafrost"
    },
    {
      "x": -46,
      "y": -10,
      "z": 15,
      "name": "Rock_Ice_Permafrost"
    },
    {
      "x": -46,
      "y": -9,
      "z": 15,
      "name": "Rock_Ice_Permafrost"
    },
    {
      "x": -46,
      "y": -28,
      "z": 16,
      "name": "Rock_Ice_Permafrost"
    },
    {
      "x": -46,
      "y": -27,
      "z": 16,
      "name": "Rock_Ice_Permafrost"
    },
    {
      "x": -46,
      "y": -26,
      "z": 16,
      "name": "Rock_Ice_Permafrost"
    },
    {
      "x": -46,
      "y": -9,
      "z": 16,
      "name": "Rock_Ice_Permafrost"
    },
    {
      "x": -46,
      "y": -27,
      "z": 17,
      "name": "Rock_Ice_Permafrost"
    },
    {
      "x": -46,
      "y": -16,
      "z": 28,
      "name": "Rock_Ice_Permafrost"
    },
    {
      "x": -46,
      "y": -15,
      "z": 28,
      "name": "Rock_Ice_Permafrost"
    },
    {
      "x": -46,
      "y": -14,
      "z": 28,
      "name": "Rock_Ice_Permafrost"
    },
    {
      "x": -46,
      "y": -18,
      "z": 29,
      "name": "Rock_Ice_Permafrost"
    },
    {
      "x": -46,
      "y": -17,
      "z": 29,
      "name": "Rock_Ice_Permafrost"
    },
    {
      "x": -46,
      "y": -16,
      "z": 29,
      "name": "Rock_Ice_Permafrost"
    },
    {
      "x": -46,
      "y": -15,
      "z": 29,
      "name": "Rock_Ice_Permafrost"
    },
    {
      "x": -46,
      "y": -14,
      "z": 29,
      "name": "Rock_Ice_Permafrost"
    },
    {
      "x": -46,
      "y": -18,
      "z": 30,
      "name": "Rock_Ice_Permafrost"
    },
    {
      "x": -46,
      "y": -17,
      "z": 30,
      "name": "Rock_Ice_Permafrost"
    },
    {
      "x": -46,
      "y": -16,
      "z": 30,
      "name": "Rock_Ice_Permafrost"
    },
    {
      "x": -46,
      "y": -15,
      "z": 30,
      "name": "Rock_Ice_Permafrost"
    },
    {
      "x": -46,
      "y": -17,
      "z": 31,
      "name": "Rock_Ice_Permafrost"
    },
    {
      "x": -46,
      "y": -16,
      "z": 31,
      "name": "Rock_Ice_Permafrost"
    },
    {
      "x": -45,
      "y": -10,
      "z": 14,
      "name": "Rock_Ice_Permafrost"
    },
    {
      "x": -45,
      "y": -9,
      "z": 14,
      "name": "Rock_Ice_Permafrost"
    },
    {
      "x": -45,
      "y": -8,
      "z": 14,
      "name": "Rock_Ice_Permafrost"
    },
    {
      "x": -45,
      "y": -27,
      "z": 15,
      "name": "Rock_Ice_Permafrost"
    },
    {
      "x": -45,
      "y": -26,
      "z": 15,
      "name": "Rock_Ice_Permafrost"
    },
    {
      "x": -45,
      "y": -25,
      "z": 15,
      "name": "Rock_Ice_Permafrost"
    },
    {
      "x": -45,
      "y": -10,
      "z": 15,
      "name": "Rock_Ice_Permafrost"
    },
    {
      "x": -45,
      "y": -9,
      "z": 15,
      "name": "Rock_Ice_Permafrost"
    },
    {
      "x": -45,
      "y": -8,
      "z": 15,
      "name": "Rock_Ice_Permafrost"
    },
    {
      "x": -45,
      "y": -27,
      "z": 16,
      "name": "Rock_Ice_Permafrost"
    },
    {
      "x": -45,
      "y": -26,
      "z": 16,
      "name": "Rock_Ice_Permafrost"
    },
    {
      "x": -45,
      "y": -25,
      "z": 16,
      "name": "Rock_Ice_Permafrost"
    },
    {
      "x": -45,
      "y": -9,
      "z": 16,
      "name": "Rock_Ice_Permafrost"
    },
    {
      "x": -45,
      "y": -26,
      "z": 17,
      "name": "Rock_Ice_Permafrost"
    },
    {
      "x": -45,
      "y": -15,
      "z": 27,
      "name": "Rock_Ice_Permafrost"
    },
    {
      "x": -45,
      "y": -14,
      "z": 27,
      "name": "Rock_Ice_Permafrost"
    },
    {
      "x": -45,
      "y": -18,
      "z": 28,
      "name": "Rock_Ice_Permafrost"
    },
    {
      "x": -45,
      "y": -17,
      "z": 28,
      "name": "Rock_Ice_Permafrost"
    },
    {
      "x": -45,
      "y": -16,
      "z": 28,
      "name": "Rock_Ice_Permafrost"
    },
    {
      "x": -45,
      "y": -15,
      "z": 28,
      "name": "Rock_Ice_Permafrost"
    },
    {
      "x": -45,
      "y": -14,
      "z": 28,
      "name": "Rock_Ice_Permafrost"
    },
    {
      "x": -45,
      "y": -18,
      "z": 29,
      "name": "Rock_Ice_Permafrost"
    },
    {
      "x": -45,
      "y": -17,
      "z": 29,
      "name": "Rock_Ice_Permafrost"
    },
    {
      "x": -45,
      "y": -16,
      "z": 29,
      "name": "Rock_Ice_Permafrost"
    },
    {
      "x": -45,
      "y": -15,
      "z": 29,
      "name": "Rock_Ice_Permafrost"
    },
    {
      "x": -45,
      "y": -14,
      "z": 29,
      "name": "Rock_Ice_Permafrost"
    },
    {
      "x": -45,
      "y": -17,
      "z": 30,
      "name": "Rock_Ice_Permafrost"
    },
    {
      "x": -45,
      "y": -16,
      "z": 30,
      "name": "Rock_Ice_Permafrost"
    },
    {
      "x": -45,
      "y": -15,
      "z": 30,
      "name": "Rock_Ice_Permafrost"
    },
    {
      "x": -44,
      "y": -9,
      "z": 13,
      "name": "Rock_Ice_Permafrost"
    },
    {
      "x": -44,
      "y": -26,
      "z": 14,
      "name": "Rock_Ice_Permafrost"
    },
    {
      "x": -44,
      "y": -25,
      "z": 14,
      "name": "Rock_Ice_Permafrost"
    },
    {
      "x": -44,
      "y": -10,
      "z": 14,
      "name": "Rock_Ice_Permafrost"
    },
    {
      "x": -44,
      "y": -9,
      "z": 14,
      "name": "Rock_Ice_Permafrost"
    },
    {
      "x": -44,
      "y": -8,
      "z": 14,
      "name": "Rock_Ice_Permafrost"
    },
    {
      "x": -44,
      "y": -27,
      "z": 15,
      "name": "Rock_Ice_Permafrost"
    },
    {
      "x": -44,
      "y": -26,
      "z": 15,
      "name": "Rock_Ice_Permafrost"
    },
    {
      "x": -44,
      "y": -25,
      "z": 15,
      "name": "Rock_Ice_Permafrost"
    },
    {
      "x": -44,
      "y": -24,
      "z": 15,
      "name": "Rock_Ice_Permafrost"
    },
    {
      "x": -44,
      "y": -9,
      "z": 15,
      "name": "Rock_Ice_Permafrost"
    },
    {
      "x": -44,
      "y": -8,
      "z": 15,
      "name": "Rock_Ice_Permafrost"
    },
    {
      "x": -44,
      "y": -27,
      "z": 16,
      "name": "Rock_Ice_Permafrost"
    },
    {
      "x": -44,
      "y": -26,
      "z": 16,
      "name": "Rock_Ice_Permafrost"
    },
    {
      "x": -44,
      "y": -25,
      "z": 16,
      "name": "Rock_Ice_Permafrost"
    },
    {
      "x": -44,
      "y": -9,
      "z": 16,
      "name": "Rock_Ice_Permafrost"
    },
    {
      "x": -44,
      "y": -26,
      "z": 17,
      "name": "Rock_Ice_Permafrost"
    },
    {
      "x": -44,
      "y": -14,
      "z": 26,
      "name": "Rock_Ice_Permafrost"
    },
    {
      "x": -44,
      "y": -13,
      "z": 26,
      "name": "Rock_Ice_Permafrost"
    },
    {
      "x": -44,
      "y": -17,
      "z": 27,
      "name": "Rock_Ice_Permafrost"
    },
    {
      "x": -44,
      "y": -16,
      "z": 27,
      "name": "Rock_Ice_Permafrost"
    },
    {
      "x": -44,
      "y": -15,
      "z": 27,
      "name": "Rock_Ice_Permafrost"
    },
    {
      "x": -44,
      "y": -14,
      "z": 27,
      "name": "Rock_Ice_Permafrost"
    },
    {
      "x": -44,
      "y": -13,
      "z": 27,
      "name": "Rock_Ice_Permafrost"
    },
    {
      "x": -44,
      "y": -18,
      "z": 28,
      "name": "Rock_Ice_Permafrost"
    },
    {
      "x": -44,
      "y": -17,
      "z": 28,
      "name": "Rock_Ice_Permafrost"
    },
    {
      "x": -44,
      "y": -16,
      "z": 28,
      "name": "Rock_Ice_Permafrost"
    },
    {
      "x": -44,
      "y": -15,
      "z": 28,
      "name": "Rock_Ice_Permafrost"
    },
    {
      "x": -44,
      "y": -14,
      "z": 28,
      "name": "Rock_Ice_Permafrost"
    },
    {
      "x": -44,
      "y": -17,
      "z": 29,
      "name": "Rock_Ice_Permafrost"
    },
    {
      "x": -44,
      "y": -16,
      "z": 29,
      "name": "Rock_Ice_Permafrost"
    },
    {
      "x": -44,
      "y": -15,
      "z": 29,
      "name": "Rock_Ice_Permafrost"
    },
    {
      "x": -44,
      "y": -14,
      "z": 29,
      "name": "Rock_Ice_Permafrost"
    },
    {
      "x": -44,
      "y": -16,
      "z": 30,
      "name": "Rock_Ice_Permafrost"
    },
    {
      "x": -44,
      "y": -15,
      "z": 30,
      "name": "Rock_Ice_Permafrost"
    },
    {
      "x": -43,
      "y": -10,
      "z": 13,
      "name": "Rock_Ice_Permafrost"
    },
    {
      "x": -43,
      "y": -9,
      "z": 13,
      "name": "Rock_Ice_Permafrost"
    },
    {
      "x": -43,
      "y": -8,
      "z": 13,
      "name": "Rock_Ice_Permafrost"
    },
    {
      "x": -43,
      "y": -26,
      "z": 14,
      "name": "Rock_Ice_Permafrost"
    },
    {
      "x": -43,
      "y": -25,
      "z": 14,
      "name": "Rock_Ice_Permafrost"
    },
    {
      "x": -43,
      "y": -24,
      "z": 14,
      "name": "Rock_Ice_Permafrost"
    },
    {
      "x": -43,
      "y": -23,
      "z": 14,
      "name": "Rock_Ice_Permafrost"
    },
    {
      "x": -43,
      "y": -10,
      "z": 14,
      "name": "Rock_Ice_Permafrost"
    },
    {
      "x": -43,
      "y": -9,
      "z": 14,
      "name": "Rock_Ice_Permafrost"
    },
    {
      "x": -43,
      "y": -8,
      "z": 14,
      "name": "Rock_Ice_Permafrost"
    },
    {
      "x": -43,
      "y": -26,
      "z": 15,
      "name": "Rock_Ice_Permafrost"
    },
    {
      "x": -43,
      "y": -25,
      "z": 15,
      "name": "Rock_Ice_Permafrost"
    },
    {
      "x": -43,
      "y": -24,
      "z": 15,
      "name": "Rock_Ice_Permafrost"
    },
    {
      "x": -43,
      "y": -9,
      "z": 15,
      "name": "Rock_Ice_Permafrost"
    },
    {
      "x": -43,
      "y": -8,
      "z": 15,
      "name": "Rock_Ice_Permafrost"
    },
    {
      "x": -43,
      "y": -26,
      "z": 16,
      "name": "Rock_Ice_Permafrost"
    },
    {
      "x": -43,
      "y": -25,
      "z": 16,
      "name": "Rock_Ice_Permafrost"
    },
    {
      "x": -43,
      "y": -24,
      "z": 16,
      "name": "Rock_Ice_Permafrost"
    },
    {
      "x": -43,
      "y": -9,
      "z": 16,
      "name": "Rock_Ice_Permafrost"
    },
    {
      "x": -43,
      "y": -8,
      "z": 16,
      "name": "Rock_Ice_Permafrost"
    },
    {
      "x": -43,
      "y": -13,
      "z": 25,
      "name": "Rock_Ice_Permafrost"
    },
    {
      "x": -43,
      "y": -12,
      "z": 25,
      "name": "Rock_Ice_Permafrost"
    },
    {
      "x": -43,
      "y": -17,
      "z": 26,
      "name": "Rock_Ice_Permafrost"
    },
    {
      "x": -43,
      "y": -16,
      "z": 26,
      "name": "Rock_Ice_Permafrost"
    },
    {
      "x": -43,
      "y": -15,
      "z": 26,
      "name": "Rock_Ice_Permafrost"
    },
    {
      "x": -43,
      "y": -14,
      "z": 26,
      "name": "Rock_Ice_Permafrost"
    },
    {
      "x": -43,
      "y": -13,
      "z": 26,
      "name": "Rock_Ice_Permafrost"
    },
    {
      "x": -43,
      "y": -12,
      "z": 26,
      "name": "Rock_Ice_Permafrost"
    },
    {
      "x": -43,
      "y": -17,
      "z": 27,
      "name": "Rock_Ice_Permafrost"
    },
    {
      "x": -43,
      "y": -16,
      "z": 27,
      "name": "Rock_Ice_Permafrost"
    },
    {
      "x": -43,
      "y": -15,
      "z": 27,
      "name": "Rock_Ice_Permafrost"
    },
    {
      "x": -43,
      "y": -14,
      "z": 27,
      "name": "Rock_Ice_Permafrost"
    },
    {
      "x": -43,
      "y": -13,
      "z": 27,
      "name": "Rock_Ice_Permafrost"
    },
    {
      "x": -43,
      "y": -17,
      "z": 28,
      "name": "Rock_Ice_Permafrost"
    },
    {
      "x": -43,
      "y": -16,
      "z": 28,
      "name": "Rock_Ice_Permafrost"
    },
    {
      "x": -43,
      "y": -15,
      "z": 28,
      "name": "Rock_Ice_Permafrost"
    },
    {
      "x": -43,
      "y": -14,
      "z": 28,
      "name": "Rock_Ice_Permafrost"
    },
    {
      "x": -43,
      "y": -13,
      "z": 28,
      "name": "Rock_Ice_Permafrost"
    },
    {
      "x": -43,
      "y": -16,
      "z": 29,
      "name": "Rock_Ice_Permafrost"
    },
    {
      "x": -43,
      "y": -15,
      "z": 29,
      "name": "Rock_Ice_Permafrost"
    },
    {
      "x": -43,
      "y": -14,
      "z": 29,
      "name": "Rock_Ice_Permafrost"
    },
    {
      "x": -43,
      "y": -15,
      "z": 30,
      "name": "Rock_Ice_Permafrost"
    },
    {
      "x": -42,
      "y": 4,
      "z": 12,
      "name": "Rock_Ice_Permafrost"
    },
    {
      "x": -42,
      "y": -24,
      "z": 13,
      "name": "Rock_Ice_Permafrost"
    },
    {
      "x": -42,
      "y": -10,
      "z": 13,
      "name": "Rock_Ice_Permafrost"
    },
    {
      "x": -42,
      "y": -9,
      "z": 13,
      "name": "Rock_Ice_Permafrost"
    },
    {
      "x": -42,
      "y": -8,
      "z": 13,
      "name": "Rock_Ice_Permafrost"
    },
    {
      "x": -42,
      "y": -7,
      "z": 13,
      "name": "Rock_Ice_Permafrost"
    },
    {
      "x": -42,
      "y": 4,
      "z": 13,
      "name": "Rock_Ice_Permafrost"
    },
    {
      "x": -42,
      "y": 5,
      "z": 13,
      "name": "Rock_Ice_Permafrost"
    },
    {
      "x": -42,
      "y": -26,
      "z": 14,
      "name": "Rock_Ice_Permafrost"
    },
    {
      "x": -42,
      "y": -25,
      "z": 14,
      "name": "Rock_Ice_Permafrost"
    },
    {
      "x": -42,
      "y": -24,
      "z": 14,
      "name": "Rock_Ice_Permafrost"
    },
    {
      "x": -42,
      "y": -23,
      "z": 14,
      "name": "Rock_Ice_Permafrost"
    },
    {
      "x": -42,
      "y": -10,
      "z": 14,
      "name": "Rock_Ice_Permafrost"
    },
    {
      "x": -42,
      "y": -9,
      "z": 14,
      "name": "Rock_Ice_Permafrost"
    },
    {
      "x": -42,
      "y": -8,
      "z": 14,
      "name": "Rock_Ice_Permafrost"
    },
    {
      "x": -42,
      "y": -7,
      "z": 14,
      "name": "Rock_Ice_Permafrost"
    },
    {
      "x": -42,
      "y": -26,
      "z": 15,
      "name": "Rock_Ice_Permafrost"
    },
    {
      "x": -42,
      "y": -25,
      "z": 15,
      "name": "Rock_Ice_Permafrost"
    },
    {
      "x": -42,
      "y": -24,
      "z": 15,
      "name": "Rock_Ice_Permafrost"
    },
    {
      "x": -42,
      "y": -23,
      "z": 15,
      "name": "Rock_Ice_Permafrost"
    },
    {
      "x": -42,
      "y": -9,
      "z": 15,
      "name": "Rock_Ice_Permafrost"
    },
    {
      "x": -42,
      "y": -8,
      "z": 15,
      "name": "Rock_Ice_Permafrost"
    },
    {
      "x": -42,
      "y": -25,
      "z": 16,
      "name": "Rock_Ice_Permafrost"
    },
    {
      "x": -42,
      "y": -24,
      "z": 16,
      "name": "Rock_Ice_Permafrost"
    },
    {
      "x": -42,
      "y": -8,
      "z": 16,
      "name": "Rock_Ice_Permafrost"
    },
    {
      "x": -42,
      "y": -12,
      "z": 24,
      "name": "Rock_Ice_Permafrost"
    },
    {
      "x": -42,
      "y": -16,
      "z": 25,
      "name": "Rock_Ice_Permafrost"
    },
    {
      "x": -42,
      "y": -15,
      "z": 25,
      "name": "Rock_Ice_Permafrost"
    },
    {
      "x": -42,
      "y": -14,
      "z": 25,
      "name": "Rock_Ice_Permafrost"
    },
    {
      "x": -42,
      "y": -13,
      "z": 25,
      "name": "Rock_Ice_Permafrost"
    },
    {
      "x": -42,
      "y": -12,
      "z": 25,
      "name": "Rock_Ice_Permafrost"
    },
    {
      "x": -42,
      "y": -17,
      "z": 26,
      "name": "Rock_Ice_Permafrost"
    },
    {
      "x": -42,
      "y": -16,
      "z": 26,
      "name": "Rock_Ice_Permafrost"
    },
    {
      "x": -42,
      "y": -15,
      "z": 26,
      "name": "Rock_Ice_Permafrost"
    },
    {
      "x": -42,
      "y": -14,
      "z": 26,
      "name": "Rock_Ice_Permafrost"
    },
    {
      "x": -42,
      "y": -13,
      "z": 26,
      "name": "Rock_Ice_Permafrost"
    },
    {
      "x": -42,
      "y": -12,
      "z": 26,
      "name": "Rock_Ice_Permafrost"
    },
    {
      "x": -42,
      "y": -17,
      "z": 27,
      "name": "Rock_Ice_Permafrost"
    },
    {
      "x": -42,
      "y": -16,
      "z": 27,
      "name": "Rock_Ice_Permafrost"
    },
    {
      "x": -42,
      "y": -14,
      "z": 27,
      "name": "Rock_Ice_Permafrost"
    },
    {
      "x": -42,
      "y": -13,
      "z": 27,
      "name": "Rock_Ice_Permafrost"
    },
    {
      "x": -42,
      "y": -16,
      "z": 28,
      "name": "Rock_Ice_Permafrost"
    },
    {
      "x": -42,
      "y": -15,
      "z": 28,
      "name": "Rock_Ice_Permafrost"
    },
    {
      "x": -42,
      "y": -14,
      "z": 28,
      "name": "Rock_Ice_Permafrost"
    },
    {
      "x": -42,
      "y": -13,
      "z": 28,
      "name": "Rock_Ice_Permafrost"
    },
    {
      "x": -42,
      "y": -16,
      "z": 29,
      "name": "Rock_Ice_Permafrost"
    },
    {
      "x": -42,
      "y": -15,
      "z": 29,
      "name": "Rock_Ice_Permafrost"
    },
    {
      "x": -42,
      "y": -14,
      "z": 29,
      "name": "Rock_Ice_Permafrost"
    },
    {
      "x": -41,
      "y": -9,
      "z": 12,
      "name": "Rock_Ice_Permafrost"
    },
    {
      "x": -41,
      "y": -8,
      "z": 12,
      "name": "Rock_Ice_Permafrost"
    },
    {
      "x": -41,
      "y": -7,
      "z": 12,
      "name": "Rock_Ice_Permafrost"
    },
    {
      "x": -41,
      "y": 3,
      "z": 12,
      "name": "Rock_Ice_Permafrost"
    },
    {
      "x": -41,
      "y": 4,
      "z": 12,
      "name": "Rock_Ice_Permafrost"
    },
    {
      "x": -41,
      "y": 5,
      "z": 12,
      "name": "Rock_Ice_Permafrost"
    },
    {
      "x": -41,
      "y": -25,
      "z": 13,
      "name": "Rock_Ice_Permafrost"
    },
    {
      "x": -41,
      "y": -24,
      "z": 13,
      "name": "Rock_Ice_Permafrost"
    },
    {
      "x": -41,
      "y": -23,
      "z": 13,
      "name": "Rock_Ice_Permafrost"
    },
    {
      "x": -41,
      "y": -22,
      "z": 13,
      "name": "Rock_Ice_Permafrost"
    },
    {
      "x": -41,
      "y": -10,
      "z": 13,
      "name": "Rock_Ice_Permafrost"
    },
    {
      "x": -41,
      "y": -9,
      "z": 13,
      "name": "Rock_Ice_Permafrost"
    },
    {
      "x": -41,
      "y": -8,
      "z": 13,
      "name": "Rock_Ice_Permafrost"
    },
    {
      "x": -41,
      "y": -7,
      "z": 13,
      "name": "Rock_Ice_Permafrost"
    },
    {
      "x": -41,
      "y": 4,
      "z": 13,
      "name": "Rock_Ice_Permafrost"
    },
    {
      "x": -41,
      "y": -25,
      "z": 14,
      "name": "Rock_Ice_Permafrost"
    },
    {
      "x": -41,
      "y": -24,
      "z": 14,
      "name": "Rock_Ice_Permafrost"
    },
    {
      "x": -41,
      "y": -23,
      "z": 14,
      "name": "Rock_Ice_Permafrost"
    },
    {
      "x": -41,
      "y": -22,
      "z": 14,
      "name": "Rock_Ice_Permafrost"
    },
    {
      "x": -41,
      "y": -10,
      "z": 14,
      "name": "Rock_Ice_Permafrost"
    },
    {
      "x": -41,
      "y": -9,
      "z": 14,
      "name": "Rock_Ice_Permafrost"
    },
    {
      "x": -41,
      "y": -8,
      "z": 14,
      "name": "Rock_Ice_Permafrost"
    },
    {
      "x": -41,
      "y": -7,
      "z": 14,
      "name": "Rock_Ice_Permafrost"
    },
    {
      "x": -41,
      "y": -26,
      "z": 15,
      "name": "Rock_Ice_Permafrost"
    },
    {
      "x": -41,
      "y": -25,
      "z": 15,
      "name": "Rock_Ice_Permafrost"
    },
    {
      "x": -41,
      "y": -24,
      "z": 15,
      "name": "Rock_Ice_Permafrost"
    },
    {
      "x": -41,
      "y": -23,
      "z": 15,
      "name": "Rock_Ice_Permafrost"
    },
    {
      "x": -41,
      "y": -22,
      "z": 15,
      "name": "Rock_Ice_Permafrost"
    },
    {
      "x": -41,
      "y": -9,
      "z": 15,
      "name": "Rock_Ice_Permafrost"
    },
    {
      "x": -41,
      "y": -8,
      "z": 15,
      "name": "Rock_Ice_Permafrost"
    },
    {
      "x": -41,
      "y": -7,
      "z": 15,
      "name": "Rock_Ice_Permafrost"
    },
    {
      "x": -41,
      "y": -25,
      "z": 16,
      "name": "Rock_Ice_Permafrost"
    },
    {
      "x": -41,
      "y": -24,
      "z": 16,
      "name": "Rock_Ice_Permafrost"
    },
    {
      "x": -41,
      "y": -23,
      "z": 16,
      "name": "Rock_Ice_Permafrost"
    },
    {
      "x": -41,
      "y": -8,
      "z": 16,
      "name": "Rock_Ice_Permafrost"
    },
    {
      "x": -41,
      "y": -15,
      "z": 24,
      "name": "Rock_Ice_Permafrost"
    },
    {
      "x": -41,
      "y": -14,
      "z": 24,
      "name": "Rock_Ice_Permafrost"
    },
    {
      "x": -41,
      "y": -13,
      "z": 24,
      "name": "Rock_Ice_Permafrost"
    },
    {
      "x": -41,
      "y": -12,
      "z": 24,
      "name": "Rock_Ice_Permafrost"
    },
    {
      "x": -41,
      "y": -11,
      "z": 24,
      "name": "Rock_Ice_Permafrost"
    },
    {
      "x": -41,
      "y": -17,
      "z": 25,
      "name": "Rock_Ice_Permafrost"
    },
    {
      "x": -41,
      "y": -16,
      "z": 25,
      "name": "Rock_Ice_Permafrost"
    },
    {
      "x": -41,
      "y": -15,
      "z": 25,
      "name": "Rock_Ice_Permafrost"
    },
    {
      "x": -41,
      "y": -14,
      "z": 25,
      "name": "Rock_Ice_Permafrost"
    },
    {
      "x": -41,
      "y": -13,
      "z": 25,
      "name": "Rock_Ice_Permafrost"
    },
    {
      "x": -41,
      "y": -12,
      "z": 25,
      "name": "Rock_Ice_Permafrost"
    },
    {
      "x": -41,
      "y": -11,
      "z": 25,
      "name": "Rock_Ice_Permafrost"
    },
    {
      "x": -41,
      "y": -17,
      "z": 26,
      "name": "Rock_Ice_Permafrost"
    },
    {
      "x": -41,
      "y": -16,
      "z": 26,
      "name": "Rock_Ice_Permafrost"
    },
    {
      "x": -41,
      "y": -15,
      "z": 26,
      "name": "Rock_Ice_Permafrost"
    },
    {
      "x": -41,
      "y": -13,
      "z": 26,
      "name": "Rock_Ice_Permafrost"
    },
    {
      "x": -41,
      "y": -12,
      "z": 26,
      "name": "Rock_Ice_Permafrost"
    },
    {
      "x": -41,
      "y": -16,
      "z": 27,
      "name": "Rock_Ice_Permafrost"
    },
    {
      "x": -41,
      "y": -15,
      "z": 27,
      "name": "Rock_Ice_Permafrost"
    },
    {
      "x": -41,
      "y": -14,
      "z": 27,
      "name": "Rock_Ice_Permafrost"
    },
    {
      "x": -41,
      "y": -13,
      "z": 27,
      "name": "Rock_Ice_Permafrost"
    },
    {
      "x": -41,
      "y": -16,
      "z": 28,
      "name": "Rock_Ice_Permafrost"
    },
    {
      "x": -41,
      "y": -15,
      "z": 28,
      "name": "Rock_Ice_Permafrost"
    },
    {
      "x": -41,
      "y": -14,
      "z": 28,
      "name": "Rock_Ice_Permafrost"
    },
    {
      "x": -41,
      "y": -13,
      "z": 28,
      "name": "Rock_Ice_Permafrost"
    },
    {
      "x": -41,
      "y": -15,
      "z": 29,
      "name": "Rock_Ice_Permafrost"
    },
    {
      "x": -40,
      "y": 43,
      "z": -7,
      "name": "Rock_Ice_Permafrost"
    },
    {
      "x": -40,
      "y": 44,
      "z": -7,
      "name": "Rock_Ice_Permafrost"
    },
    {
      "x": -40,
      "y": 42,
      "z": -6,
      "name": "Rock_Ice_Permafrost"
    },
    {
      "x": -40,
      "y": 43,
      "z": -6,
      "name": "Rock_Ice_Permafrost"
    },
    {
      "x": -40,
      "y": 44,
      "z": -6,
      "name": "Rock_Ice_Permafrost"
    },
    {
      "x": -40,
      "y": 45,
      "z": -6,
      "name": "Rock_Ice_Permafrost"
    },
    {
      "x": -40,
      "y": -8,
      "z": 11,
      "name": "Rock_Ice_Permafrost"
    },
    {
      "x": -40,
      "y": -23,
      "z": 12,
      "name": "Rock_Ice_Permafrost"
    },
    {
      "x": -40,
      "y": -22,
      "z": 12,
      "name": "Rock_Ice_Permafrost"
    },
    {
      "x": -40,
      "y": -10,
      "z": 12,
      "name": "Rock_Ice_Permafrost"
    },
    {
      "x": -40,
      "y": -9,
      "z": 12,
      "name": "Rock_Ice_Permafrost"
    },
    {
      "x": -40,
      "y": -8,
      "z": 12,
      "name": "Rock_Ice_Permafrost"
    },
    {
      "x": -40,
      "y": -7,
      "z": 12,
      "name": "Rock_Ice_Permafrost"
    },
    {
      "x": -40,
      "y": -6,
      "z": 12,
      "name": "Rock_Ice_Permafrost"
    },
    {
      "x": -40,
      "y": 3,
      "z": 12,
      "name": "Rock_Ice_Permafrost"
    },
    {
      "x": -40,
      "y": 4,
      "z": 12,
      "name": "Rock_Ice_Permafrost"
    },
    {
      "x": -40,
      "y": 5,
      "z": 12,
      "name": "Rock_Ice_Permafrost"
    },
    {
      "x": -40,
      "y": -25,
      "z": 13,
      "name": "Rock_Ice_Permafrost"
    },
    {
      "x": -40,
      "y": -24,
      "z": 13,
      "name": "Rock_Ice_Permafrost"
    },
    {
      "x": -40,
      "y": -23,
      "z": 13,
      "name": "Rock_Ice_Permafrost"
    },
    {
      "x": -40,
      "y": -22,
      "z": 13,
      "name": "Rock_Ice_Permafrost"
    },
    {
      "x": -40,
      "y": -21,
      "z": 13,
      "name": "Rock_Ice_Permafrost"
    },
    {
      "x": -40,
      "y": -10,
      "z": 13,
      "name": "Rock_Ice_Permafrost"
    },
    {
      "x": -40,
      "y": -9,
      "z": 13,
      "name": "Rock_Ice_Permafrost"
    },
    {
      "x": -40,
      "y": -7,
      "z": 13,
      "name": "Rock_Ice_Permafrost"
    },
    {
      "x": -40,
      "y": -6,
      "z": 13,
      "name": "Rock_Ice_Permafrost"
    },
    {
      "x": -40,
      "y": 3,
      "z": 13,
      "name": "Rock_Ice_Permafrost"
    },
    {
      "x": -40,
      "y": 4,
      "z": 13,
      "name": "Rock_Ice_Permafrost"
    },
    {
      "x": -40,
      "y": 5,
      "z": 13,
      "name": "Rock_Ice_Permafrost"
    },
    {
      "x": -40,
      "y": -25,
      "z": 14,
      "name": "Rock_Ice_Permafrost"
    },
    {
      "x": -40,
      "y": -24,
      "z": 14,
      "name": "Rock_Ice_Permafrost"
    },
    {
      "x": -40,
      "y": -23,
      "z": 14,
      "name": "Rock_Ice_Permafrost"
    },
    {
      "x": -40,
      "y": -22,
      "z": 14,
      "name": "Rock_Ice_Permafrost"
    },
    {
      "x": -40,
      "y": -21,
      "z": 14,
      "name": "Rock_Ice_Permafrost"
    },
    {
      "x": -40,
      "y": -9,
      "z": 14,
      "name": "Rock_Ice_Permafrost"
    },
    {
      "x": -40,
      "y": -8,
      "z": 14,
      "name": "Rock_Ice_Permafrost"
    },
    {
      "x": -40,
      "y": -7,
      "z": 14,
      "name": "Rock_Ice_Permafrost"
    },
    {
      "x": -40,
      "y": -25,
      "z": 15,
      "name": "Rock_Ice_Permafrost"
    },
    {
      "x": -40,
      "y": -24,
      "z": 15,
      "name": "Rock_Ice_Permafrost"
    },
    {
      "x": -40,
      "y": -23,
      "z": 15,
      "name": "Rock_Ice_Permafrost"
    },
    {
      "x": -40,
      "y": -22,
      "z": 15,
      "name": "Rock_Ice_Permafrost"
    },
    {
      "x": -40,
      "y": -9,
      "z": 15,
      "name": "Rock_Ice_Permafrost"
    },
    {
      "x": -40,
      "y": -8,
      "z": 15,
      "name": "Rock_Ice_Permafrost"
    },
    {
      "x": -40,
      "y": -7,
      "z": 15,
      "name": "Rock_Ice_Permafrost"
    },
    {
      "x": -40,
      "y": -24,
      "z": 16,
      "name": "Rock_Ice_Permafrost"
    },
    {
      "x": -40,
      "y": -23,
      "z": 16,
      "name": "Rock_Ice_Permafrost"
    },
    {
      "x": -40,
      "y": -8,
      "z": 16,
      "name": "Rock_Ice_Permafrost"
    },
    {
      "x": -40,
      "y": -7,
      "z": 16,
      "name": "Rock_Ice_Permafrost"
    },
    {
      "x": -40,
      "y": -14,
      "z": 23,
      "name": "Rock_Ice_Permafrost"
    },
    {
      "x": -40,
      "y": -13,
      "z": 23,
      "name": "Rock_Ice_Permafrost"
    },
    {
      "x": -40,
      "y": -12,
      "z": 23,
      "name": "Rock_Ice_Permafrost"
    },
    {
      "x": -40,
      "y": -11,
      "z": 23,
      "name": "Rock_Ice_Permafrost"
    },
    {
      "x": -40,
      "y": -10,
      "z": 23,
      "name": "Rock_Ice_Permafrost"
    },
    {
      "x": -40,
      "y": -17,
      "z": 24,
      "name": "Rock_Ice_Permafrost"
    },
    {
      "x": -40,
      "y": -16,
      "z": 24,
      "name": "Rock_Ice_Permafrost"
    },
    {
      "x": -40,
      "y": -15,
      "z": 24,
      "name": "Rock_Ice_Permafrost"
    },
    {
      "x": -40,
      "y": -14,
      "z": 24,
      "name": "Rock_Ice_Permafrost"
    },
    {
      "x": -40,
      "y": -13,
      "z": 24,
      "name": "Rock_Ice_Permafrost"
    },
    {
      "x": -40,
      "y": -12,
      "z": 24,
      "name": "Rock_Ice_Permafrost"
    },
    {
      "x": -40,
      "y": -11,
      "z": 24,
      "name": "Rock_Ice_Permafrost"
    },
    {
      "x": -40,
      "y": -17,
      "z": 25,
      "name": "Rock_Ice_Permafrost"
    },
    {
      "x": -40,
      "y": -16,
      "z": 25,
      "name": "Rock_Ice_Permafrost"
    },
    {
      "x": -40,
      "y": -15,
      "z": 25,
      "name": "Rock_Ice_Permafrost"
    },
    {
      "x": -40,
      "y": -14,
      "z": 25,
      "name": "Rock_Ice_Permafrost"
    },
    {
      "x": -40,
      "y": -13,
      "z": 25,
      "name": "Rock_Ice_Permafrost"
    },
    {
      "x": -40,
      "y": -12,
      "z": 25,
      "name": "Rock_Ice_Permafrost"
    },
    {
      "x": -40,
      "y": -11,
      "z": 25,
      "name": "Rock_Ice_Permafrost"
    },
    {
      "x": -40,
      "y": -17,
      "z": 26,
      "name": "Rock_Ice_Permafrost"
    },
    {
      "x": -40,
      "y": -16,
      "z": 26,
      "name": "Rock_Ice_Permafrost"
    },
    {
      "x": -40,
      "y": -15,
      "z": 26,
      "name": "Rock_Ice_Permafrost"
    },
    {
      "x": -40,
      "y": -13,
      "z": 26,
      "name": "Rock_Ice_Permafrost"
    },
    {
      "x": -40,
      "y": -12,
      "z": 26,
      "name": "Rock_Ice_Permafrost"
    },
    {
      "x": -40,
      "y": -16,
      "z": 27,
      "name": "Rock_Ice_Permafrost"
    },
    {
      "x": -40,
      "y": -15,
      "z": 27,
      "name": "Rock_Ice_Permafrost"
    },
    {
      "x": -40,
      "y": -14,
      "z": 27,
      "name": "Rock_Ice_Permafrost"
    },
    {
      "x": -40,
      "y": -13,
      "z": 27,
      "name": "Rock_Ice_Permafrost"
    },
    {
      "x": -40,
      "y": -15,
      "z": 28,
      "name": "Rock_Ice_Permafrost"
    },
    {
      "x": -40,
      "y": -14,
      "z": 28,
      "name": "Rock_Ice_Permafrost"
    },
    {
      "x": -39,
      "y": 42,
      "z": -7,
      "name": "Rock_Ice_Permafrost"
    },
    {
      "x": -39,
      "y": 43,
      "z": -7,
      "name": "Rock_Ice_Permafrost"
    },
    {
      "x": -39,
      "y": 41,
      "z": -6,
      "name": "Rock_Ice_Permafrost"
    },
    {
      "x": -39,
      "y": 42,
      "z": -6,
      "name": "Rock_Ice_Permafrost"
    },
    {
      "x": -39,
      "y": 43,
      "z": -6,
      "name": "Rock_Ice_Permafrost"
    },
    {
      "x": -39,
      "y": -9,
      "z": 11,
      "name": "Rock_Ice_Permafrost"
    },
    {
      "x": -39,
      "y": -8,
      "z": 11,
      "name": "Rock_Ice_Permafrost"
    },
    {
      "x": -39,
      "y": -7,
      "z": 11,
      "name": "Rock_Ice_Permafrost"
    },
    {
      "x": -39,
      "y": -6,
      "z": 11,
      "name": "Rock_Ice_Permafrost"
    },
    {
      "x": -39,
      "y": 3,
      "z": 11,
      "name": "Rock_Ice_Permafrost"
    },
    {
      "x": -39,
      "y": 4,
      "z": 11,
      "name": "Rock_Ice_Permafrost"
    },
    {
      "x": -39,
      "y": -24,
      "z": 12,
      "name": "Rock_Ice_Permafrost"
    },
    {
      "x": -39,
      "y": -23,
      "z": 12,
      "name": "Rock_Ice_Permafrost"
    },
    {
      "x": -39,
      "y": -22,
      "z": 12,
      "name": "Rock_Ice_Permafrost"
    },
    {
      "x": -39,
      "y": -21,
      "z": 12,
      "name": "Rock_Ice_Permafrost"
    },
    {
      "x": -39,
      "y": -20,
      "z": 12,
      "name": "Rock_Ice_Permafrost"
    },
    {
      "x": -39,
      "y": -10,
      "z": 12,
      "name": "Rock_Ice_Permafrost"
    },
    {
      "x": -39,
      "y": -9,
      "z": 12,
      "name": "Rock_Ice_Permafrost"
    },
    {
      "x": -39,
      "y": -8,
      "z": 12,
      "name": "Rock_Ice_Permafrost"
    },
    {
      "x": -39,
      "y": -7,
      "z": 12,
      "name": "Rock_Ice_Permafrost"
    },
    {
      "x": -39,
      "y": -6,
      "z": 12,
      "name": "Rock_Ice_Permafrost"
    },
    {
      "x": -39,
      "y": 3,
      "z": 12,
      "name": "Rock_Ice_Permafrost"
    },
    {
      "x": -39,
      "y": 4,
      "z": 12,
      "name": "Rock_Ice_Permafrost"
    },
    {
      "x": -39,
      "y": 5,
      "z": 12,
      "name": "Rock_Ice_Permafrost"
    },
    {
      "x": -39,
      "y": 6,
      "z": 12,
      "name": "Rock_Ice_Permafrost"
    },
    {
      "x": -39,
      "y": -25,
      "z": 13,
      "name": "Rock_Ice_Permafrost"
    },
    {
      "x": -39,
      "y": -24,
      "z": 13,
      "name": "Rock_Ice_Permafrost"
    },
    {
      "x": -39,
      "y": -23,
      "z": 13,
      "name": "Rock_Ice_Permafrost"
    },
    {
      "x": -39,
      "y": -22,
      "z": 13,
      "name": "Rock_Ice_Permafrost"
    },
    {
      "x": -39,
      "y": -21,
      "z": 13,
      "name": "Rock_Ice_Permafrost"
    },
    {
      "x": -39,
      "y": -20,
      "z": 13,
      "name": "Rock_Ice_Permafrost"
    },
    {
      "x": -39,
      "y": -10,
      "z": 13,
      "name": "Rock_Ice_Permafrost"
    },
    {
      "x": -39,
      "y": -9,
      "z": 13,
      "name": "Rock_Ice_Permafrost"
    },
    {
      "x": -39,
      "y": -7,
      "z": 13,
      "name": "Rock_Ice_Permafrost"
    },
    {
      "x": -39,
      "y": -6,
      "z": 13,
      "name": "Rock_Ice_Permafrost"
    },
    {
      "x": -39,
      "y": 3,
      "z": 13,
      "name": "Rock_Ice_Permafrost"
    },
    {
      "x": -39,
      "y": 4,
      "z": 13,
      "name": "Rock_Ice_Permafrost"
    },
    {
      "x": -39,
      "y": 5,
      "z": 13,
      "name": "Rock_Ice_Permafrost"
    },
    {
      "x": -39,
      "y": 6,
      "z": 13,
      "name": "Rock_Ice_Permafrost"
    },
    {
      "x": -39,
      "y": -25,
      "z": 14,
      "name": "Rock_Ice_Permafrost"
    },
    {
      "x": -39,
      "y": -24,
      "z": 14,
      "name": "Rock_Ice_Permafrost"
    },
    {
      "x": -39,
      "y": -22,
      "z": 14,
      "name": "Rock_Ice_Permafrost"
    },
    {
      "x": -39,
      "y": -21,
      "z": 14,
      "name": "Rock_Ice_Permafrost"
    },
    {
      "x": -39,
      "y": -9,
      "z": 14,
      "name": "Rock_Ice_Permafrost"
    },
    {
      "x": -39,
      "y": -8,
      "z": 14,
      "name": "Rock_Ice_Permafrost"
    },
    {
      "x": -39,
      "y": -7,
      "z": 14,
      "name": "Rock_Ice_Permafrost"
    },
    {
      "x": -39,
      "y": -6,
      "z": 14,
      "name": "Rock_Ice_Permafrost"
    },
    {
      "x": -39,
      "y": -24,
      "z": 15,
      "name": "Rock_Ice_Permafrost"
    },
    {
      "x": -39,
      "y": -23,
      "z": 15,
      "name": "Rock_Ice_Permafrost"
    },
    {
      "x": -39,
      "y": -22,
      "z": 15,
      "name": "Rock_Ice_Permafrost"
    },
    {
      "x": -39,
      "y": -21,
      "z": 15,
      "name": "Rock_Ice_Permafrost"
    },
    {
      "x": -39,
      "y": -9,
      "z": 15,
      "name": "Rock_Ice_Permafrost"
    },
    {
      "x": -39,
      "y": -8,
      "z": 15,
      "name": "Rock_Ice_Permafrost"
    },
    {
      "x": -39,
      "y": -7,
      "z": 15,
      "name": "Rock_Ice_Permafrost"
    },
    {
      "x": -39,
      "y": -23,
      "z": 16,
      "name": "Rock_Ice_Permafrost"
    },
    {
      "x": -39,
      "y": -22,
      "z": 16,
      "name": "Rock_Ice_Permafrost"
    },
    {
      "x": -39,
      "y": -8,
      "z": 16,
      "name": "Rock_Ice_Permafrost"
    },
    {
      "x": -39,
      "y": -7,
      "z": 16,
      "name": "Rock_Ice_Permafrost"
    },
    {
      "x": -39,
      "y": -13,
      "z": 22,
      "name": "Rock_Ice_Permafrost"
    },
    {
      "x": -39,
      "y": -12,
      "z": 22,
      "name": "Rock_Ice_Permafrost"
    },
    {
      "x": -39,
      "y": -11,
      "z": 22,
      "name": "Rock_Ice_Permafrost"
    },
    {
      "x": -39,
      "y": -10,
      "z": 22,
      "name": "Rock_Ice_Permafrost"
    },
    {
      "x": -39,
      "y": -16,
      "z": 23,
      "name": "Rock_Ice_Permafrost"
    },
    {
      "x": -39,
      "y": -15,
      "z": 23,
      "name": "Rock_Ice_Permafrost"
    },
    {
      "x": -39,
      "y": -14,
      "z": 23,
      "name": "Rock_Ice_Permafrost"
    },
    {
      "x": -39,
      "y": -13,
      "z": 23,
      "name": "Rock_Ice_Permafrost"
    },
    {
      "x": -39,
      "y": -12,
      "z": 23,
      "name": "Rock_Ice_Permafrost"
    },
    {
      "x": -39,
      "y": -11,
      "z": 23,
      "name": "Rock_Ice_Permafrost"
    },
    {
      "x": -39,
      "y": -10,
      "z": 23,
      "name": "Rock_Ice_Permafrost"
    },
    {
      "x": -39,
      "y": -17,
      "z": 24,
      "name": "Rock_Ice_Permafrost"
    },
    {
      "x": -39,
      "y": -16,
      "z": 24,
      "name": "Rock_Ice_Permafrost"
    },
    {
      "x": -39,
      "y": -15,
      "z": 24,
      "name": "Rock_Ice_Permafrost"
    },
    {
      "x": -39,
      "y": -14,
      "z": 24,
      "name": "Rock_Ice_Permafrost"
    },
    {
      "x": -39,
      "y": -13,
      "z": 24,
      "name": "Rock_Ice_Permafrost"
    },
    {
      "x": -39,
      "y": -12,
      "z": 24,
      "name": "Rock_Ice_Permafrost"
    },
    {
      "x": -39,
      "y": -11,
      "z": 24,
      "name": "Rock_Ice_Permafrost"
    },
    {
      "x": -39,
      "y": -17,
      "z": 25,
      "name": "Rock_Ice_Permafrost"
    },
    {
      "x": -39,
      "y": -16,
      "z": 25,
      "name": "Rock_Ice_Permafrost"
    },
    {
      "x": -39,
      "y": -15,
      "z": 25,
      "name": "Rock_Ice_Permafrost"
    },
    {
      "x": -39,
      "y": -13,
      "z": 25,
      "name": "Rock_Ice_Permafrost"
    },
    {
      "x": -39,
      "y": -12,
      "z": 25,
      "name": "Rock_Ice_Permafrost"
    },
    {
      "x": -39,
      "y": -11,
      "z": 25,
      "name": "Rock_Ice_Permafrost"
    },
    {
      "x": -39,
      "y": -16,
      "z": 26,
      "name": "Rock_Ice_Permafrost"
    },
    {
      "x": -39,
      "y": -15,
      "z": 26,
      "name": "Rock_Ice_Permafrost"
    },
    {
      "x": -39,
      "y": -14,
      "z": 26,
      "name": "Rock_Ice_Permafrost"
    },
    {
      "x": -39,
      "y": -13,
      "z": 26,
      "name": "Rock_Ice_Permafrost"
    },
    {
      "x": -39,
      "y": -12,
      "z": 26,
      "name": "Rock_Ice_Permafrost"
    },
    {
      "x": -39,
      "y": -15,
      "z": 27,
      "name": "Rock_Ice_Permafrost"
    },
    {
      "x": -39,
      "y": -14,
      "z": 27,
      "name": "Rock_Ice_Permafrost"
    },
    {
      "x": -39,
      "y": -13,
      "z": 27,
      "name": "Rock_Ice_Permafrost"
    },
    {
      "x": -38,
      "y": 41,
      "z": -7,
      "name": "Rock_Ice_Permafrost"
    },
    {
      "x": -38,
      "y": 42,
      "z": -7,
      "name": "Rock_Ice_Permafrost"
    },
    {
      "x": -38,
      "y": 40,
      "z": -6,
      "name": "Rock_Ice_Permafrost"
    },
    {
      "x": -38,
      "y": 41,
      "z": -6,
      "name": "Rock_Ice_Permafrost"
    },
    {
      "x": -38,
      "y": 42,
      "z": -6,
      "name": "Rock_Ice_Permafrost"
    },
    {
      "x": -38,
      "y": 40,
      "z": -5,
      "name": "Rock_Ice_Permafrost"
    },
    {
      "x": -38,
      "y": 3,
      "z": 10,
      "name": "Rock_Ice_Permafrost"
    },
    {
      "x": -38,
      "y": -22,
      "z": 11,
      "name": "Rock_Ice_Permafrost"
    },
    {
      "x": -38,
      "y": -21,
      "z": 11,
      "name": "Rock_Ice_Permafrost"
    },
    {
      "x": -38,
      "y": -10,
      "z": 11,
      "name": "Rock_Ice_Permafrost"
    },
    {
      "x": -38,
      "y": -9,
      "z": 11,
      "name": "Rock_Ice_Permafrost"
    },
    {
      "x": -38,
      "y": -8,
      "z": 11,
      "name": "Rock_Ice_Permafrost"
    },
    {
      "x": -38,
      "y": -7,
      "z": 11,
      "name": "Rock_Ice_Permafrost"
    },
    {
      "x": -38,
      "y": -6,
      "z": 11,
      "name": "Rock_Ice_Permafrost"
    },
    {
      "x": -38,
      "y": 2,
      "z": 11,
      "name": "Rock_Ice_Permafrost"
    },
    {
      "x": -38,
      "y": 3,
      "z": 11,
      "name": "Rock_Ice_Permafrost"
    },
    {
      "x": -38,
      "y": 4,
      "z": 11,
      "name": "Rock_Ice_Permafrost"
    },
    {
      "x": -38,
      "y": 5,
      "z": 11,
      "name": "Rock_Ice_Permafrost"
    },
    {
      "x": -38,
      "y": -24,
      "z": 12,
      "name": "Rock_Ice_Permafrost"
    },
    {
      "x": -38,
      "y": -23,
      "z": 12,
      "name": "Rock_Ice_Permafrost"
    },
    {
      "x": -38,
      "y": -22,
      "z": 12,
      "name": "Rock_Ice_Permafrost"
    },
    {
      "x": -38,
      "y": -21,
      "z": 12,
      "name": "Rock_Ice_Permafrost"
    },
    {
      "x": -38,
      "y": -20,
      "z": 12,
      "name": "Rock_Ice_Permafrost"
    },
    {
      "x": -38,
      "y": -19,
      "z": 12,
      "name": "Rock_Ice_Permafrost"
    },
    {
      "x": -38,
      "y": -10,
      "z": 12,
      "name": "Rock_Ice_Permafrost"
    },
    {
      "x": -38,
      "y": -9,
      "z": 12,
      "name": "Rock_Ice_Permafrost"
    },
    {
      "x": -38,
      "y": -8,
      "z": 12,
      "name": "Rock_Ice_Permafrost"
    },
    {
      "x": -38,
      "y": -7,
      "z": 12,
      "name": "Rock_Ice_Permafrost"
    },
    {
      "x": -38,
      "y": -6,
      "z": 12,
      "name": "Rock_Ice_Permafrost"
    },
    {
      "x": -38,
      "y": 2,
      "z": 12,
      "name": "Rock_Ice_Permafrost"
    },
    {
      "x": -38,
      "y": 3,
      "z": 12,
      "name": "Rock_Ice_Permafrost"
    },
    {
      "x": -38,
      "y": 4,
      "z": 12,
      "name": "Rock_Ice_Permafrost"
    },
    {
      "x": -38,
      "y": 5,
      "z": 12,
      "name": "Rock_Ice_Permafrost"
    },
    {
      "x": -38,
      "y": 6,
      "z": 12,
      "name": "Rock_Ice_Permafrost"
    },
    {
      "x": -38,
      "y": -24,
      "z": 13,
      "name": "Rock_Ice_Permafrost"
    },
    {
      "x": -38,
      "y": -23,
      "z": 13,
      "name": "Rock_Ice_Permafrost"
    },
    {
      "x": -38,
      "y": -21,
      "z": 13,
      "name": "Rock_Ice_Permafrost"
    },
    {
      "x": -38,
      "y": -20,
      "z": 13,
      "name": "Rock_Ice_Permafrost"
    },
    {
      "x": -38,
      "y": -9,
      "z": 13,
      "name": "Rock_Ice_Permafrost"
    },
    {
      "x": -38,
      "y": -7,
      "z": 13,
      "name": "Rock_Ice_Permafrost"
    },
    {
      "x": -38,
      "y": -6,
      "z": 13,
      "name": "Rock_Ice_Permafrost"
    },
    {
      "x": -38,
      "y": 4,
      "z": 13,
      "name": "Rock_Ice_Permafrost"
    },
    {
      "x": -38,
      "y": 5,
      "z": 13,
      "name": "Rock_Ice_Permafrost"
    },
    {
      "x": -38,
      "y": 6,
      "z": 13,
      "name": "Rock_Ice_Permafrost"
    },
    {
      "x": -38,
      "y": -24,
      "z": 14,
      "name": "Rock_Ice_Permafrost"
    },
    {
      "x": -38,
      "y": -23,
      "z": 14,
      "name": "Rock_Ice_Permafrost"
    },
    {
      "x": -38,
      "y": -21,
      "z": 14,
      "name": "Rock_Ice_Permafrost"
    },
    {
      "x": -38,
      "y": -20,
      "z": 14,
      "name": "Rock_Ice_Permafrost"
    },
    {
      "x": -38,
      "y": -9,
      "z": 14,
      "name": "Rock_Ice_Permafrost"
    },
    {
      "x": -38,
      "y": -8,
      "z": 14,
      "name": "Rock_Ice_Permafrost"
    },
    {
      "x": -38,
      "y": -7,
      "z": 14,
      "name": "Rock_Ice_Permafrost"
    },
    {
      "x": -38,
      "y": -6,
      "z": 14,
      "name": "Rock_Ice_Permafrost"
    },
    {
      "x": -38,
      "y": -24,
      "z": 15,
      "name": "Rock_Ice_Permafrost"
    },
    {
      "x": -38,
      "y": -23,
      "z": 15,
      "name": "Rock_Ice_Permafrost"
    },
    {
      "x": -38,
      "y": -22,
      "z": 15,
      "name": "Rock_Ice_Permafrost"
    },
    {
      "x": -38,
      "y": -21,
      "z": 15,
      "name": "Rock_Ice_Permafrost"
    },
    {
      "x": -38,
      "y": -8,
      "z": 15,
      "name": "Rock_Ice_Permafrost"
    },
    {
      "x": -38,
      "y": -7,
      "z": 15,
      "name": "Rock_Ice_Permafrost"
    },
    {
      "x": -38,
      "y": -23,
      "z": 16,
      "name": "Rock_Ice_Permafrost"
    },
    {
      "x": -38,
      "y": -22,
      "z": 16,
      "name": "Rock_Ice_Permafrost"
    },
    {
      "x": -38,
      "y": -8,
      "z": 16,
      "name": "Rock_Ice_Permafrost"
    },
    {
      "x": -38,
      "y": -7,
      "z": 16,
      "name": "Rock_Ice_Permafrost"
    },
    {
      "x": -38,
      "y": -12,
      "z": 21,
      "name": "Rock_Ice_Permafrost"
    },
    {
      "x": -38,
      "y": -11,
      "z": 21,
      "name": "Rock_Ice_Permafrost"
    },
    {
      "x": -38,
      "y": -10,
      "z": 21,
      "name": "Rock_Ice_Permafrost"
    },
    {
      "x": -38,
      "y": -9,
      "z": 21,
      "name": "Rock_Ice_Permafrost"
    },
    {
      "x": -38,
      "y": -15,
      "z": 22,
      "name": "Rock_Ice_Permafrost"
    },
    {
      "x": -38,
      "y": -14,
      "z": 22,
      "name": "Rock_Ice_Permafrost"
    },
    {
      "x": -38,
      "y": -13,
      "z": 22,
      "name": "Rock_Ice_Permafrost"
    },
    {
      "x": -38,
      "y": -12,
      "z": 22,
      "name": "Rock_Ice_Permafrost"
    },
    {
      "x": -38,
      "y": -11,
      "z": 22,
      "name": "Rock_Ice_Permafrost"
    },
    {
      "x": -38,
      "y": -10,
      "z": 22,
      "name": "Rock_Ice_Permafrost"
    },
    {
      "x": -38,
      "y": -9,
      "z": 22,
      "name": "Rock_Ice_Permafrost"
    },
    {
      "x": -38,
      "y": -17,
      "z": 23,
      "name": "Rock_Ice_Permafrost"
    },
    {
      "x": -38,
      "y": -16,
      "z": 23,
      "name": "Rock_Ice_Permafrost"
    },
    {
      "x": -38,
      "y": -15,
      "z": 23,
      "name": "Rock_Ice_Permafrost"
    },
    {
      "x": -38,
      "y": -14,
      "z": 23,
      "name": "Rock_Ice_Permafrost"
    },
    {
      "x": -38,
      "y": -13,
      "z": 23,
      "name": "Rock_Ice_Permafrost"
    },
    {
      "x": -38,
      "y": -12,
      "z": 23,
      "name": "Rock_Ice_Permafrost"
    },
    {
      "x": -38,
      "y": -11,
      "z": 23,
      "name": "Rock_Ice_Permafrost"
    },
    {
      "x": -38,
      "y": -10,
      "z": 23,
      "name": "Rock_Ice_Permafrost"
    },
    {
      "x": -38,
      "y": -17,
      "z": 24,
      "name": "Rock_Ice_Permafrost"
    },
    {
      "x": -38,
      "y": -16,
      "z": 24,
      "name": "Rock_Ice_Permafrost"
    },
    {
      "x": -38,
      "y": -15,
      "z": 24,
      "name": "Rock_Ice_Permafrost"
    },
    {
      "x": -38,
      "y": -12,
      "z": 24,
      "name": "Rock_Ice_Permafrost"
    },
    {
      "x": -38,
      "y": -11,
      "z": 24,
      "name": "Rock_Ice_Permafrost"
    },
    {
      "x": -38,
      "y": -16,
      "z": 25,
      "name": "Rock_Ice_Permafrost"
    },
    {
      "x": -38,
      "y": -15,
      "z": 25,
      "name": "Rock_Ice_Permafrost"
    },
    {
      "x": -38,
      "y": -14,
      "z": 25,
      "name": "Rock_Ice_Permafrost"
    },
    {
      "x": -38,
      "y": -13,
      "z": 25,
      "name": "Rock_Ice_Permafrost"
    },
    {
      "x": -38,
      "y": -12,
      "z": 25,
      "name": "Rock_Ice_Permafrost"
    },
    {
      "x": -38,
      "y": -11,
      "z": 25,
      "name": "Rock_Ice_Permafrost"
    },
    {
      "x": -38,
      "y": -15,
      "z": 26,
      "name": "Rock_Ice_Permafrost"
    },
    {
      "x": -38,
      "y": -14,
      "z": 26,
      "name": "Rock_Ice_Permafrost"
    },
    {
      "x": -38,
      "y": -13,
      "z": 26,
      "name": "Rock_Ice_Permafrost"
    },
    {
      "x": -38,
      "y": -12,
      "z": 26,
      "name": "Rock_Ice_Permafrost"
    },
    {
      "x": -38,
      "y": -14,
      "z": 27,
      "name": "Rock_Ice_Permafrost"
    },
    {
      "x": -38,
      "y": -13,
      "z": 27,
      "name": "Rock_Ice_Permafrost"
    },
    {
      "x": -37,
      "y": 39,
      "z": -7,
      "name": "Rock_Ice_Permafrost"
    },
    {
      "x": -37,
      "y": 40,
      "z": -7,
      "name": "Rock_Ice_Permafrost"
    },
    {
      "x": -37,
      "y": 41,
      "z": -7,
      "name": "Rock_Ice_Permafrost"
    },
    {
      "x": -37,
      "y": 38,
      "z": -6,
      "name": "Rock_Ice_Permafrost"
    },
    {
      "x": -37,
      "y": 39,
      "z": -6,
      "name": "Rock_Ice_Permafrost"
    },
    {
      "x": -37,
      "y": 40,
      "z": -6,
      "name": "Rock_Ice_Permafrost"
    },
    {
      "x": -37,
      "y": 41,
      "z": -6,
      "name": "Rock_Ice_Permafrost"
    },
    {
      "x": -37,
      "y": 39,
      "z": -5,
      "name": "Rock_Ice_Permafrost"
    },
    {
      "x": -37,
      "y": 40,
      "z": -5,
      "name": "Rock_Ice_Permafrost"
    },
    {
      "x": -37,
      "y": -9,
      "z": 10,
      "name": "Rock_Ice_Permafrost"
    },
    {
      "x": -37,
      "y": -8,
      "z": 10,
      "name": "Rock_Ice_Permafrost"
    },
    {
      "x": -37,
      "y": -7,
      "z": 10,
      "name": "Rock_Ice_Permafrost"
    },
    {
      "x": -37,
      "y": -6,
      "z": 10,
      "name": "Rock_Ice_Permafrost"
    },
    {
      "x": -37,
      "y": -5,
      "z": 10,
      "name": "Rock_Ice_Permafrost"
    },
    {
      "x": -37,
      "y": 2,
      "z": 10,
      "name": "Rock_Ice_Permafrost"
    },
    {
      "x": -37,
      "y": 3,
      "z": 10,
      "name": "Rock_Ice_Permafrost"
    },
    {
      "x": -37,
      "y": 4,
      "z": 10,
      "name": "Rock_Ice_Permafrost"
    },
    {
      "x": -37,
      "y": -22,
      "z": 11,
      "name": "Rock_Ice_Permafrost"
    },
    {
      "x": -37,
      "y": -21,
      "z": 11,
      "name": "Rock_Ice_Permafrost"
    },
    {
      "x": -37,
      "y": -20,
      "z": 11,
      "name": "Rock_Ice_Permafrost"
    },
    {
      "x": -37,
      "y": -19,
      "z": 11,
      "name": "Rock_Ice_Permafrost"
    },
    {
      "x": -37,
      "y": -10,
      "z": 11,
      "name": "Rock_Ice_Permafrost"
    },
    {
      "x": -37,
      "y": -9,
      "z": 11,
      "name": "Rock_Ice_Permafrost"
    },
    {
      "x": -37,
      "y": -8,
      "z": 11,
      "name": "Rock_Ice_Permafrost"
    },
    {
      "x": -37,
      "y": -7,
      "z": 11,
      "name": "Rock_Ice_Permafrost"
    },
    {
      "x": -37,
      "y": -6,
      "z": 11,
      "name": "Rock_Ice_Permafrost"
    },
    {
      "x": -37,
      "y": -5,
      "z": 11,
      "name": "Rock_Ice_Permafrost"
    },
    {
      "x": -37,
      "y": 2,
      "z": 11,
      "name": "Rock_Ice_Permafrost"
    },
    {
      "x": -37,
      "y": 3,
      "z": 11,
      "name": "Rock_Ice_Permafrost"
    },
    {
      "x": -37,
      "y": 4,
      "z": 11,
      "name": "Rock_Ice_Permafrost"
    },
    {
      "x": -37,
      "y": 5,
      "z": 11,
      "name": "Rock_Ice_Permafrost"
    },
    {
      "x": -37,
      "y": -24,
      "z": 12,
      "name": "Rock_Ice_Permafrost"
    },
    {
      "x": -37,
      "y": -23,
      "z": 12,
      "name": "Rock_Ice_Permafrost"
    },
    {
      "x": -37,
      "y": -22,
      "z": 12,
      "name": "Rock_Ice_Permafrost"
    },
    {
      "x": -37,
      "y": -21,
      "z": 12,
      "name": "Rock_Ice_Permafrost"
    },
    {
      "x": -37,
      "y": -20,
      "z": 12,
      "name": "Rock_Ice_Permafrost"
    },
    {
      "x": -37,
      "y": -19,
      "z": 12,
      "name": "Rock_Ice_Permafrost"
    },
    {
      "x": -37,
      "y": -10,
      "z": 12,
      "name": "Rock_Ice_Permafrost"
    },
    {
      "x": -37,
      "y": -9,
      "z": 12,
      "name": "Rock_Ice_Permafrost"
    },
    {
      "x": -37,
      "y": -6,
      "z": 12,
      "name": "Rock_Ice_Permafrost"
    },
    {
      "x": -37,
      "y": -5,
      "z": 12,
      "name": "Rock_Ice_Permafrost"
    },
    {
      "x": -37,
      "y": 2,
      "z": 12,
      "name": "Rock_Ice_Permafrost"
    },
    {
      "x": -37,
      "y": 3,
      "z": 12,
      "name": "Rock_Ice_Permafrost"
    },
    {
      "x": -37,
      "y": 4,
      "z": 12,
      "name": "Rock_Ice_Permafrost"
    },
    {
      "x": -37,
      "y": 5,
      "z": 12,
      "name": "Rock_Ice_Permafrost"
    },
    {
      "x": -37,
      "y": 6,
      "z": 12,
      "name": "Rock_Ice_Permafrost"
    },
    {
      "x": -37,
      "y": 7,
      "z": 12,
      "name": "Rock_Ice_Permafrost"
    },
    {
      "x": -37,
      "y": -24,
      "z": 13,
      "name": "Rock_Ice_Permafrost"
    },
    {
      "x": -37,
      "y": -23,
      "z": 13,
      "name": "Rock_Ice_Permafrost"
    },
    {
      "x": -37,
      "y": -20,
      "z": 13,
      "name": "Rock_Ice_Permafrost"
    },
    {
      "x": -37,
      "y": -19,
      "z": 13,
      "name": "Rock_Ice_Permafrost"
    },
    {
      "x": -37,
      "y": -9,
      "z": 13,
      "name": "Rock_Ice_Permafrost"
    },
    {
      "x": -37,
      "y": -8,
      "z": 13,
      "name": "Rock_Ice_Permafrost"
    },
    {
      "x": -37,
      "y": -6,
      "z": 13,
      "name": "Rock_Ice_Permafrost"
    },
    {
      "x": -37,
      "y": -5,
      "z": 13,
      "name": "Rock_Ice_Permafrost"
    },
    {
      "x": -37,
      "y": 4,
      "z": 13,
      "name": "Rock_Ice_Permafrost"
    },
    {
      "x": -37,
      "y": 5,
      "z": 13,
      "name": "Rock_Ice_Permafrost"
    },
    {
      "x": -37,
      "y": 6,
      "z": 13,
      "name": "Rock_Ice_Permafrost"
    },
    {
      "x": -37,
      "y": 7,
      "z": 13,
      "name": "Rock_Ice_Permafrost"
    },
    {
      "x": -37,
      "y": -24,
      "z": 14,
      "name": "Rock_Ice_Permafrost"
    },
    {
      "x": -37,
      "y": -23,
      "z": 14,
      "name": "Rock_Ice_Permafrost"
    },
    {
      "x": -37,
      "y": -22,
      "z": 14,
      "name": "Rock_Ice_Permafrost"
    },
    {
      "x": -37,
      "y": -21,
      "z": 14,
      "name": "Rock_Ice_Permafrost"
    },
    {
      "x": -37,
      "y": -20,
      "z": 14,
      "name": "Rock_Ice_Permafrost"
    },
    {
      "x": -37,
      "y": -19,
      "z": 14,
      "name": "Rock_Ice_Permafrost"
    },
    {
      "x": -37,
      "y": -9,
      "z": 14,
      "name": "Rock_Ice_Permafrost"
    },
    {
      "x": -37,
      "y": -8,
      "z": 14,
      "name": "Rock_Ice_Permafrost"
    },
    {
      "x": -37,
      "y": -7,
      "z": 14,
      "name": "Rock_Ice_Permafrost"
    },
    {
      "x": -37,
      "y": -6,
      "z": 14,
      "name": "Rock_Ice_Permafrost"
    },
    {
      "x": -37,
      "y": -23,
      "z": 15,
      "name": "Rock_Ice_Permafrost"
    },
    {
      "x": -37,
      "y": -22,
      "z": 15,
      "name": "Rock_Ice_Permafrost"
    },
    {
      "x": -37,
      "y": -21,
      "z": 15,
      "name": "Rock_Ice_Permafrost"
    },
    {
      "x": -37,
      "y": -20,
      "z": 15,
      "name": "Rock_Ice_Permafrost"
    },
    {
      "x": -37,
      "y": -8,
      "z": 15,
      "name": "Rock_Ice_Permafrost"
    },
    {
      "x": -37,
      "y": -7,
      "z": 15,
      "name": "Rock_Ice_Permafrost"
    },
    {
      "x": -37,
      "y": -6,
      "z": 15,
      "name": "Rock_Ice_Permafrost"
    },
    {
      "x": -37,
      "y": -22,
      "z": 16,
      "name": "Rock_Ice_Permafrost"
    },
    {
      "x": -37,
      "y": -21,
      "z": 16,
      "name": "Rock_Ice_Permafrost"
    },
    {
      "x": -37,
      "y": -8,
      "z": 16,
      "name": "Rock_Ice_Permafrost"
    },
    {
      "x": -37,
      "y": -7,
      "z": 16,
      "name": "Rock_Ice_Permafrost"
    },
    {
      "x": -37,
      "y": -10,
      "z": 20,
      "name": "Rock_Ice_Permafrost"
    },
    {
      "x": -37,
      "y": -9,
      "z": 20,
      "name": "Rock_Ice_Permafrost"
    },
    {
      "x": -37,
      "y": -14,
      "z": 21,
      "name": "Rock_Ice_Permafrost"
    },
    {
      "x": -37,
      "y": -13,
      "z": 21,
      "name": "Rock_Ice_Permafrost"
    },
    {
      "x": -37,
      "y": -12,
      "z": 21,
      "name": "Rock_Ice_Permafrost"
    },
    {
      "x": -37,
      "y": -11,
      "z": 21,
      "name": "Rock_Ice_Permafrost"
    },
    {
      "x": -37,
      "y": -10,
      "z": 21,
      "name": "Rock_Ice_Permafrost"
    },
    {
      "x": -37,
      "y": -9,
      "z": 21,
      "name": "Rock_Ice_Permafrost"
    },
    {
      "x": -37,
      "y": -16,
      "z": 22,
      "name": "Rock_Ice_Permafrost"
    },
    {
      "x": -37,
      "y": -15,
      "z": 22,
      "name": "Rock_Ice_Permafrost"
    },
    {
      "x": -37,
      "y": -14,
      "z": 22,
      "name": "Rock_Ice_Permafrost"
    },
    {
      "x": -37,
      "y": -13,
      "z": 22,
      "name": "Rock_Ice_Permafrost"
    },
    {
      "x": -37,
      "y": -12,
      "z": 22,
      "name": "Rock_Ice_Permafrost"
    },
    {
      "x": -37,
      "y": -11,
      "z": 22,
      "name": "Rock_Ice_Permafrost"
    },
    {
      "x": -37,
      "y": -10,
      "z": 22,
      "name": "Rock_Ice_Permafrost"
    },
    {
      "x": -37,
      "y": -9,
      "z": 22,
      "name": "Rock_Ice_Permafrost"
    },
    {
      "x": -37,
      "y": -17,
      "z": 23,
      "name": "Rock_Ice_Permafrost"
    },
    {
      "x": -37,
      "y": -16,
      "z": 23,
      "name": "Rock_Ice_Permafrost"
    },
    {
      "x": -37,
      "y": -15,
      "z": 23,
      "name": "Rock_Ice_Permafrost"
    },
    {
      "x": -37,
      "y": -11,
      "z": 23,
      "name": "Rock_Ice_Permafrost"
    },
    {
      "x": -37,
      "y": -10,
      "z": 23,
      "name": "Rock_Ice_Permafrost"
    },
    {
      "x": -37,
      "y": -16,
      "z": 24,
      "name": "Rock_Ice_Permafrost"
    },
    {
      "x": -37,
      "y": -15,
      "z": 24,
      "name": "Rock_Ice_Permafrost"
    },
    {
      "x": -37,
      "y": -14,
      "z": 24,
      "name": "Rock_Ice_Permafrost"
    },
    {
      "x": -37,
      "y": -12,
      "z": 24,
      "name": "Rock_Ice_Permafrost"
    },
    {
      "x": -37,
      "y": -11,
      "z": 24,
      "name": "Rock_Ice_Permafrost"
    },
    {
      "x": -37,
      "y": -15,
      "z": 25,
      "name": "Rock_Ice_Permafrost"
    },
    {
      "x": -37,
      "y": -14,
      "z": 25,
      "name": "Rock_Ice_Permafrost"
    },
    {
      "x": -37,
      "y": -13,
      "z": 25,
      "name": "Rock_Ice_Permafrost"
    },
    {
      "x": -37,
      "y": -12,
      "z": 25,
      "name": "Rock_Ice_Permafrost"
    },
    {
      "x": -37,
      "y": -11,
      "z": 25,
      "name": "Rock_Ice_Permafrost"
    },
    {
      "x": -37,
      "y": 14,
      "z": 25,
      "name": "Rock_Ice_Permafrost"
    },
    {
      "x": -37,
      "y": -14,
      "z": 26,
      "name": "Rock_Ice_Permafrost"
    },
    {
      "x": -37,
      "y": -13,
      "z": 26,
      "name": "Rock_Ice_Permafrost"
    },
    {
      "x": -37,
      "y": -12,
      "z": 26,
      "name": "Rock_Ice_Permafrost"
    },
    {
      "x": -37,
      "y": 14,
      "z": 26,
      "name": "Rock_Ice_Permafrost"
    },
    {
      "x": -37,
      "y": 13,
      "z": 27,
      "name": "Rock_Ice_Permafrost"
    },
    {
      "x": -37,
      "y": 14,
      "z": 27,
      "name": "Rock_Ice_Permafrost"
    },
    {
      "x": -37,
      "y": 12,
      "z": 28,
      "name": "Rock_Ice_Permafrost"
    },
    {
      "x": -37,
      "y": 13,
      "z": 28,
      "name": "Rock_Ice_Permafrost"
    },
    {
      "x": -37,
      "y": 14,
      "z": 28,
      "name": "Rock_Ice_Permafrost"
    },
    {
      "x": -37,
      "y": 11,
      "z": 29,
      "name": "Rock_Ice_Permafrost"
    },
    {
      "x": -37,
      "y": 12,
      "z": 29,
      "name": "Rock_Ice_Permafrost"
    },
    {
      "x": -37,
      "y": 13,
      "z": 29,
      "name": "Rock_Ice_Permafrost"
    },
    {
      "x": -37,
      "y": 12,
      "z": 30,
      "name": "Rock_Ice_Permafrost"
    },
    {
      "x": -37,
      "y": 13,
      "z": 30,
      "name": "Rock_Ice_Permafrost"
    },
    {
      "x": -37,
      "y": 12,
      "z": 31,
      "name": "Rock_Ice_Permafrost"
    },
    {
      "x": -36,
      "y": 38,
      "z": -7,
      "name": "Rock_Ice_Permafrost"
    },
    {
      "x": -36,
      "y": 39,
      "z": -7,
      "name": "Rock_Ice_Permafrost"
    },
    {
      "x": -36,
      "y": 40,
      "z": -7,
      "name": "Rock_Ice_Permafrost"
    },
    {
      "x": -36,
      "y": 37,
      "z": -6,
      "name": "Rock_Ice_Permafrost"
    },
    {
      "x": -36,
      "y": 38,
      "z": -6,
      "name": "Rock_Ice_Permafrost"
    },
    {
      "x": -36,
      "y": 39,
      "z": -6,
      "name": "Rock_Ice_Permafrost"
    },
    {
      "x": -36,
      "y": 40,
      "z": -6,
      "name": "Rock_Ice_Permafrost"
    },
    {
      "x": -36,
      "y": 37,
      "z": -5,
      "name": "Rock_Ice_Permafrost"
    },
    {
      "x": -36,
      "y": 38,
      "z": -5,
      "name": "Rock_Ice_Permafrost"
    },
    {
      "x": -36,
      "y": 39,
      "z": -5,
      "name": "Rock_Ice_Permafrost"
    },
    {
      "x": -36,
      "y": 40,
      "z": -5,
      "name": "Rock_Ice_Permafrost"
    },
    {
      "x": -36,
      "y": 37,
      "z": -4,
      "name": "Rock_Ice_Permafrost"
    },
    {
      "x": -36,
      "y": -7,
      "z": 9,
      "name": "Rock_Ice_Permafrost"
    },
    {
      "x": -36,
      "y": 3,
      "z": 9,
      "name": "Rock_Ice_Permafrost"
    },
    {
      "x": -36,
      "y": -21,
      "z": 10,
      "name": "Rock_Ice_Permafrost"
    },
    {
      "x": -36,
      "y": -20,
      "z": 10,
      "name": "Rock_Ice_Permafrost"
    },
    {
      "x": -36,
      "y": -10,
      "z": 10,
      "name": "Rock_Ice_Permafrost"
    },
    {
      "x": -36,
      "y": -9,
      "z": 10,
      "name": "Rock_Ice_Permafrost"
    },
    {
      "x": -36,
      "y": -8,
      "z": 10,
      "name": "Rock_Ice_Permafrost"
    },
    {
      "x": -36,
      "y": -7,
      "z": 10,
      "name": "Rock_Ice_Permafrost"
    },
    {
      "x": -36,
      "y": -6,
      "z": 10,
      "name": "Rock_Ice_Permafrost"
    },
    {
      "x": -36,
      "y": -5,
      "z": 10,
      "name": "Rock_Ice_Permafrost"
    },
    {
      "x": -36,
      "y": 2,
      "z": 10,
      "name": "Rock_Ice_Permafrost"
    },
    {
      "x": -36,
      "y": 3,
      "z": 10,
      "name": "Rock_Ice_Permafrost"
    },
    {
      "x": -36,
      "y": 4,
      "z": 10,
      "name": "Rock_Ice_Permafrost"
    },
    {
      "x": -36,
      "y": -23,
      "z": 11,
      "name": "Rock_Ice_Permafrost"
    },
    {
      "x": -36,
      "y": -22,
      "z": 11,
      "name": "Rock_Ice_Permafrost"
    },
    {
      "x": -36,
      "y": -21,
      "z": 11,
      "name": "Rock_Ice_Permafrost"
    },
    {
      "x": -36,
      "y": -20,
      "z": 11,
      "name": "Rock_Ice_Permafrost"
    },
    {
      "x": -36,
      "y": -19,
      "z": 11,
      "name": "Rock_Ice_Permafrost"
    },
    {
      "x": -36,
      "y": -18,
      "z": 11,
      "name": "Rock_Ice_Permafrost"
    },
    {
      "x": -36,
      "y": -10,
      "z": 11,
      "name": "Rock_Ice_Permafrost"
    },
    {
      "x": -36,
      "y": -9,
      "z": 11,
      "name": "Rock_Ice_Permafrost"
    },
    {
      "x": -36,
      "y": -8,
      "z": 11,
      "name": "Rock_Ice_Permafrost"
    },
    {
      "x": -36,
      "y": -6,
      "z": 11,
      "name": "Rock_Ice_Permafrost"
    },
    {
      "x": -36,
      "y": -5,
      "z": 11,
      "name": "Rock_Ice_Permafrost"
    },
    {
      "x": -36,
      "y": 2,
      "z": 11,
      "name": "Rock_Ice_Permafrost"
    },
    {
      "x": -36,
      "y": 3,
      "z": 11,
      "name": "Rock_Ice_Permafrost"
    },
    {
      "x": -36,
      "y": 4,
      "z": 11,
      "name": "Rock_Ice_Permafrost"
    },
    {
      "x": -36,
      "y": 5,
      "z": 11,
      "name": "Rock_Ice_Permafrost"
    },
    {
      "x": -36,
      "y": 6,
      "z": 11,
      "name": "Rock_Ice_Permafrost"
    },
    {
      "x": -36,
      "y": -23,
      "z": 12,
      "name": "Rock_Ice_Permafrost"
    },
    {
      "x": -36,
      "y": -22,
      "z": 12,
      "name": "Rock_Ice_Permafrost"
    },
    {
      "x": -36,
      "y": -19,
      "z": 12,
      "name": "Rock_Ice_Permafrost"
    },
    {
      "x": -36,
      "y": -18,
      "z": 12,
      "name": "Rock_Ice_Permafrost"
    },
    {
      "x": -36,
      "y": -10,
      "z": 12,
      "name": "Rock_Ice_Permafrost"
    },
    {
      "x": -36,
      "y": -9,
      "z": 12,
      "name": "Rock_Ice_Permafrost"
    },
    {
      "x": -36,
      "y": -6,
      "z": 12,
      "name": "Rock_Ice_Permafrost"
    },
    {
      "x": -36,
      "y": -5,
      "z": 12,
      "name": "Rock_Ice_Permafrost"
    },
    {
      "x": -36,
      "y": 2,
      "z": 12,
      "name": "Rock_Ice_Permafrost"
    },
    {
      "x": -36,
      "y": 3,
      "z": 12,
      "name": "Rock_Ice_Permafrost"
    },
    {
      "x": -36,
      "y": 4,
      "z": 12,
      "name": "Rock_Ice_Permafrost"
    },
    {
      "x": -36,
      "y": 5,
      "z": 12,
      "name": "Rock_Ice_Permafrost"
    },
    {
      "x": -36,
      "y": 6,
      "z": 12,
      "name": "Rock_Ice_Permafrost"
    },
    {
      "x": -36,
      "y": 7,
      "z": 12,
      "name": "Rock_Ice_Permafrost"
    },
    {
      "x": -36,
      "y": -23,
      "z": 13,
      "name": "Rock_Ice_Permafrost"
    },
    {
      "x": -36,
      "y": -20,
      "z": 13,
      "name": "Rock_Ice_Permafrost"
    },
    {
      "x": -36,
      "y": -19,
      "z": 13,
      "name": "Rock_Ice_Permafrost"
    },
    {
      "x": -36,
      "y": -18,
      "z": 13,
      "name": "Rock_Ice_Permafrost"
    },
    {
      "x": -36,
      "y": -9,
      "z": 13,
      "name": "Rock_Ice_Permafrost"
    },
    {
      "x": -36,
      "y": -8,
      "z": 13,
      "name": "Rock_Ice_Permafrost"
    },
    {
      "x": -36,
      "y": -6,
      "z": 13,
      "name": "Rock_Ice_Permafrost"
    },
    {
      "x": -36,
      "y": -5,
      "z": 13,
      "name": "Rock_Ice_Permafrost"
    },
    {
      "x": -36,
      "y": 4,
      "z": 13,
      "name": "Rock_Ice_Permafrost"
    },
    {
      "x": -36,
      "y": 5,
      "z": 13,
      "name": "Rock_Ice_Permafrost"
    },
    {
      "x": -36,
      "y": 6,
      "z": 13,
      "name": "Rock_Ice_Permafrost"
    },
    {
      "x": -36,
      "y": 7,
      "z": 13,
      "name": "Rock_Ice_Permafrost"
    },
    {
      "x": -36,
      "y": -24,
      "z": 14,
      "name": "Rock_Ice_Permafrost"
    },
    {
      "x": -36,
      "y": -23,
      "z": 14,
      "name": "Rock_Ice_Permafrost"
    },
    {
      "x": -36,
      "y": -22,
      "z": 14,
      "name": "Rock_Ice_Permafrost"
    },
    {
      "x": -36,
      "y": -21,
      "z": 14,
      "name": "Rock_Ice_Permafrost"
    },
    {
      "x": -36,
      "y": -20,
      "z": 14,
      "name": "Rock_Ice_Permafrost"
    },
    {
      "x": -36,
      "y": -19,
      "z": 14,
      "name": "Rock_Ice_Permafrost"
    },
    {
      "x": -36,
      "y": -9,
      "z": 14,
      "name": "Rock_Ice_Permafrost"
    },
    {
      "x": -36,
      "y": -8,
      "z": 14,
      "name": "Rock_Ice_Permafrost"
    },
    {
      "x": -36,
      "y": -7,
      "z": 14,
      "name": "Rock_Ice_Permafrost"
    },
    {
      "x": -36,
      "y": -6,
      "z": 14,
      "name": "Rock_Ice_Permafrost"
    },
    {
      "x": -36,
      "y": -22,
      "z": 15,
      "name": "Rock_Ice_Permafrost"
    },
    {
      "x": -36,
      "y": -21,
      "z": 15,
      "name": "Rock_Ice_Permafrost"
    },
    {
      "x": -36,
      "y": -20,
      "z": 15,
      "name": "Rock_Ice_Permafrost"
    },
    {
      "x": -36,
      "y": -8,
      "z": 15,
      "name": "Rock_Ice_Permafrost"
    },
    {
      "x": -36,
      "y": -7,
      "z": 15,
      "name": "Rock_Ice_Permafrost"
    },
    {
      "x": -36,
      "y": -6,
      "z": 15,
      "name": "Rock_Ice_Permafrost"
    },
    {
      "x": -36,
      "y": -21,
      "z": 16,
      "name": "Rock_Ice_Permafrost"
    },
    {
      "x": -36,
      "y": -8,
      "z": 16,
      "name": "Rock_Ice_Permafrost"
    },
    {
      "x": -36,
      "y": -7,
      "z": 16,
      "name": "Rock_Ice_Permafrost"
    },
    {
      "x": -36,
      "y": -6,
      "z": 16,
      "name": "Rock_Ice_Permafrost"
    },
    {
      "x": -36,
      "y": -9,
      "z": 19,
      "name": "Rock_Ice_Permafrost"
    },
    {
      "x": -36,
      "y": -8,
      "z": 19,
      "name": "Rock_Ice_Permafrost"
    },
    {
      "x": -36,
      "y": -13,
      "z": 20,
      "name": "Rock_Ice_Permafrost"
    },
    {
      "x": -36,
      "y": -12,
      "z": 20,
      "name": "Rock_Ice_Permafrost"
    },
    {
      "x": -36,
      "y": -11,
      "z": 20,
      "name": "Rock_Ice_Permafrost"
    },
    {
      "x": -36,
      "y": -10,
      "z": 20,
      "name": "Rock_Ice_Permafrost"
    },
    {
      "x": -36,
      "y": -9,
      "z": 20,
      "name": "Rock_Ice_Permafrost"
    },
    {
      "x": -36,
      "y": -8,
      "z": 20,
      "name": "Rock_Ice_Permafrost"
    },
    {
      "x": -36,
      "y": -16,
      "z": 21,
      "name": "Rock_Ice_Permafrost"
    },
    {
      "x": -36,
      "y": -15,
      "z": 21,
      "name": "Rock_Ice_Permafrost"
    },
    {
      "x": -36,
      "y": -14,
      "z": 21,
      "name": "Rock_Ice_Permafrost"
    },
    {
      "x": -36,
      "y": -13,
      "z": 21,
      "name": "Rock_Ice_Permafrost"
    },
    {
      "x": -36,
      "y": -12,
      "z": 21,
      "name": "Rock_Ice_Permafrost"
    },
    {
      "x": -36,
      "y": -11,
      "z": 21,
      "name": "Rock_Ice_Permafrost"
    },
    {
      "x": -36,
      "y": -10,
      "z": 21,
      "name": "Rock_Ice_Permafrost"
    },
    {
      "x": -36,
      "y": -9,
      "z": 21,
      "name": "Rock_Ice_Permafrost"
    },
    {
      "x": -36,
      "y": -16,
      "z": 22,
      "name": "Rock_Ice_Permafrost"
    },
    {
      "x": -36,
      "y": -15,
      "z": 22,
      "name": "Rock_Ice_Permafrost"
    },
    {
      "x": -36,
      "y": -14,
      "z": 22,
      "name": "Rock_Ice_Permafrost"
    },
    {
      "x": -36,
      "y": -10,
      "z": 22,
      "name": "Rock_Ice_Permafrost"
    },
    {
      "x": -36,
      "y": -9,
      "z": 22,
      "name": "Rock_Ice_Permafrost"
    },
    {
      "x": -36,
      "y": 16,
      "z": 22,
      "name": "Rock_Ice_Permafrost"
    },
    {
      "x": -36,
      "y": -16,
      "z": 23,
      "name": "Rock_Ice_Permafrost"
    },
    {
      "x": -36,
      "y": -15,
      "z": 23,
      "name": "Rock_Ice_Permafrost"
    },
    {
      "x": -36,
      "y": -11,
      "z": 23,
      "name": "Rock_Ice_Permafrost"
    },
    {
      "x": -36,
      "y": -10,
      "z": 23,
      "name": "Rock_Ice_Permafrost"
    },
    {
      "x": -36,
      "y": 15,
      "z": 23,
      "name": "Rock_Ice_Permafrost"
    },
    {
      "x": -36,
      "y": 16,
      "z": 23,
      "name": "Rock_Ice_Permafrost"
    },
    {
      "x": -36,
      "y": -15,
      "z": 24,
      "name": "Rock_Ice_Permafrost"
    },
    {
      "x": -36,
      "y": -14,
      "z": 24,
      "name": "Rock_Ice_Permafrost"
    },
    {
      "x": -36,
      "y": -12,
      "z": 24,
      "name": "Rock_Ice_Permafrost"
    },
    {
      "x": -36,
      "y": -11,
      "z": 24,
      "name": "Rock_Ice_Permafrost"
    },
    {
      "x": -36,
      "y": 14,
      "z": 24,
      "name": "Rock_Ice_Permafrost"
    },
    {
      "x": -36,
      "y": 15,
      "z": 24,
      "name": "Rock_Ice_Permafrost"
    },
    {
      "x": -36,
      "y": 16,
      "z": 24,
      "name": "Rock_Ice_Permafrost"
    },
    {
      "x": -36,
      "y": -14,
      "z": 25,
      "name": "Rock_Ice_Permafrost"
    },
    {
      "x": -36,
      "y": -13,
      "z": 25,
      "name": "Rock_Ice_Permafrost"
    },
    {
      "x": -36,
      "y": -12,
      "z": 25,
      "name": "Rock_Ice_Permafrost"
    },
    {
      "x": -36,
      "y": 14,
      "z": 25,
      "name": "Rock_Ice_Permafrost"
    },
    {
      "x": -36,
      "y": 15,
      "z": 25,
      "name": "Rock_Ice_Permafrost"
    },
    {
      "x": -36,
      "y": -13,
      "z": 26,
      "name": "Rock_Ice_Permafrost"
    },
    {
      "x": -36,
      "y": 13,
      "z": 26,
      "name": "Rock_Ice_Permafrost"
    },
    {
      "x": -36,
      "y": 14,
      "z": 26,
      "name": "Rock_Ice_Permafrost"
    },
    {
      "x": -36,
      "y": 15,
      "z": 26,
      "name": "Rock_Ice_Permafrost"
    },
    {
      "x": -36,
      "y": 11,
      "z": 27,
      "name": "Rock_Ice_Permafrost"
    },
    {
      "x": -36,
      "y": 12,
      "z": 27,
      "name": "Rock_Ice_Permafrost"
    },
    {
      "x": -36,
      "y": 13,
      "z": 27,
      "name": "Rock_Ice_Permafrost"
    },
    {
      "x": -36,
      "y": 14,
      "z": 27,
      "name": "Rock_Ice_Permafrost"
    },
    {
      "x": -36,
      "y": 11,
      "z": 28,
      "name": "Rock_Ice_Permafrost"
    },
    {
      "x": -36,
      "y": 12,
      "z": 28,
      "name": "Rock_Ice_Permafrost"
    },
    {
      "x": -36,
      "y": 13,
      "z": 28,
      "name": "Rock_Ice_Permafrost"
    },
    {
      "x": -36,
      "y": 14,
      "z": 28,
      "name": "Rock_Ice_Permafrost"
    },
    {
      "x": -36,
      "y": 11,
      "z": 29,
      "name": "Rock_Ice_Permafrost"
    },
    {
      "x": -36,
      "y": 12,
      "z": 29,
      "name": "Rock_Ice_Permafrost"
    },
    {
      "x": -35,
      "y": -23,
      "z": -38,
      "name": "Rock_Ice_Permafrost"
    },
    {
      "x": -35,
      "y": -22,
      "z": -38,
      "name": "Rock_Ice_Permafrost"
    },
    {
      "x": -35,
      "y": -23,
      "z": -37,
      "name": "Rock_Ice_Permafrost"
    },
    {
      "x": -35,
      "y": -22,
      "z": -37,
      "name": "Rock_Ice_Permafrost"
    },
    {
      "x": -35,
      "y": 37,
      "z": -7,
      "name": "Rock_Ice_Permafrost"
    },
    {
      "x": -35,
      "y": 38,
      "z": -7,
      "name": "Rock_Ice_Permafrost"
    },
    {
      "x": -35,
      "y": 39,
      "z": -7,
      "name": "Rock_Ice_Permafrost"
    },
    {
      "x": -35,
      "y": 36,
      "z": -6,
      "name": "Rock_Ice_Permafrost"
    },
    {
      "x": -35,
      "y": 37,
      "z": -6,
      "name": "Rock_Ice_Permafrost"
    },
    {
      "x": -35,
      "y": 38,
      "z": -6,
      "name": "Rock_Ice_Permafrost"
    },
    {
      "x": -35,
      "y": 39,
      "z": -6,
      "name": "Rock_Ice_Permafrost"
    },
    {
      "x": -35,
      "y": 35,
      "z": -5,
      "name": "Rock_Ice_Permafrost"
    },
    {
      "x": -35,
      "y": 36,
      "z": -5,
      "name": "Rock_Ice_Permafrost"
    },
    {
      "x": -35,
      "y": 37,
      "z": -5,
      "name": "Rock_Ice_Permafrost"
    },
    {
      "x": -35,
      "y": 38,
      "z": -5,
      "name": "Rock_Ice_Permafrost"
    },
    {
      "x": -35,
      "y": 39,
      "z": -5,
      "name": "Rock_Ice_Permafrost"
    },
    {
      "x": -35,
      "y": 36,
      "z": -4,
      "name": "Rock_Ice_Permafrost"
    },
    {
      "x": -35,
      "y": 37,
      "z": -4,
      "name": "Rock_Ice_Permafrost"
    },
    {
      "x": -35,
      "y": 38,
      "z": -4,
      "name": "Rock_Ice_Permafrost"
    },
    {
      "x": -35,
      "y": -8,
      "z": 9,
      "name": "Rock_Ice_Permafrost"
    },
    {
      "x": -35,
      "y": -7,
      "z": 9,
      "name": "Rock_Ice_Permafrost"
    },
    {
      "x": -35,
      "y": -6,
      "z": 9,
      "name": "Rock_Ice_Permafrost"
    },
    {
      "x": -35,
      "y": -5,
      "z": 9,
      "name": "Rock_Ice_Permafrost"
    },
    {
      "x": -35,
      "y": 1,
      "z": 9,
      "name": "Rock_Ice_Permafrost"
    },
    {
      "x": -35,
      "y": 2,
      "z": 9,
      "name": "Rock_Ice_Permafrost"
    },
    {
      "x": -35,
      "y": 3,
      "z": 9,
      "name": "Rock_Ice_Permafrost"
    },
    {
      "x": -35,
      "y": 4,
      "z": 9,
      "name": "Rock_Ice_Permafrost"
    },
    {
      "x": -35,
      "y": -21,
      "z": 10,
      "name": "Rock_Ice_Permafrost"
    },
    {
      "x": -35,
      "y": -20,
      "z": 10,
      "name": "Rock_Ice_Permafrost"
    },
    {
      "x": -35,
      "y": -19,
      "z": 10,
      "name": "Rock_Ice_Permafrost"
    },
    {
      "x": -35,
      "y": -18,
      "z": 10,
      "name": "Rock_Ice_Permafrost"
    },
    {
      "x": -35,
      "y": -17,
      "z": 10,
      "name": "Rock_Ice_Permafrost"
    },
    {
      "x": -35,
      "y": -10,
      "z": 10,
      "name": "Rock_Ice_Permafrost"
    },
    {
      "x": -35,
      "y": -9,
      "z": 10,
      "name": "Rock_Ice_Permafrost"
    },
    {
      "x": -35,
      "y": -8,
      "z": 10,
      "name": "Rock_Ice_Permafrost"
    },
    {
      "x": -35,
      "y": -7,
      "z": 10,
      "name": "Rock_Ice_Permafrost"
    },
    {
      "x": -35,
      "y": -6,
      "z": 10,
      "name": "Rock_Ice_Permafrost"
    },
    {
      "x": -35,
      "y": -5,
      "z": 10,
      "name": "Rock_Ice_Permafrost"
    },
    {
      "x": -35,
      "y": 1,
      "z": 10,
      "name": "Rock_Ice_Permafrost"
    },
    {
      "x": -35,
      "y": 2,
      "z": 10,
      "name": "Rock_Ice_Permafrost"
    },
    {
      "x": -35,
      "y": 3,
      "z": 10,
      "name": "Rock_Ice_Permafrost"
    },
    {
      "x": -35,
      "y": 4,
      "z": 10,
      "name": "Rock_Ice_Permafrost"
    },
    {
      "x": -35,
      "y": 5,
      "z": 10,
      "name": "Rock_Ice_Permafrost"
    },
    {
      "x": -35,
      "y": -23,
      "z": 11,
      "name": "Rock_Ice_Permafrost"
    },
    {
      "x": -35,
      "y": -22,
      "z": 11,
      "name": "Rock_Ice_Permafrost"
    },
    {
      "x": -35,
      "y": -21,
      "z": 11,
      "name": "Rock_Ice_Permafrost"
    },
    {
      "x": -35,
      "y": -20,
      "z": 11,
      "name": "Rock_Ice_Permafrost"
    },
    {
      "x": -35,
      "y": -19,
      "z": 11,
      "name": "Rock_Ice_Permafrost"
    },
    {
      "x": -35,
      "y": -18,
      "z": 11,
      "name": "Rock_Ice_Permafrost"
    },
    {
      "x": -35,
      "y": -17,
      "z": 11,
      "name": "Rock_Ice_Permafrost"
    },
    {
      "x": -35,
      "y": -10,
      "z": 11,
      "name": "Rock_Ice_Permafrost"
    },
    {
      "x": -35,
      "y": -9,
      "z": 11,
      "name": "Rock_Ice_Permafrost"
    },
    {
      "x": -35,
      "y": -5,
      "z": 11,
      "name": "Rock_Ice_Permafrost"
    },
    {
      "x": -35,
      "y": 1,
      "z": 11,
      "name": "Rock_Ice_Permafrost"
    },
    {
      "x": -35,
      "y": 2,
      "z": 11,
      "name": "Rock_Ice_Permafrost"
    },
    {
      "x": -35,
      "y": 3,
      "z": 11,
      "name": "Rock_Ice_Permafrost"
    },
    {
      "x": -35,
      "y": 4,
      "z": 11,
      "name": "Rock_Ice_Permafrost"
    },
    {
      "x": -35,
      "y": 5,
      "z": 11,
      "name": "Rock_Ice_Permafrost"
    },
    {
      "x": -35,
      "y": 6,
      "z": 11,
      "name": "Rock_Ice_Permafrost"
    },
    {
      "x": -35,
      "y": -23,
      "z": 12,
      "name": "Rock_Ice_Permafrost"
    },
    {
      "x": -35,
      "y": -22,
      "z": 12,
      "name": "Rock_Ice_Permafrost"
    },
    {
      "x": -35,
      "y": -19,
      "z": 12,
      "name": "Rock_Ice_Permafrost"
    },
    {
      "x": -35,
      "y": -18,
      "z": 12,
      "name": "Rock_Ice_Permafrost"
    },
    {
      "x": -35,
      "y": -17,
      "z": 12,
      "name": "Rock_Ice_Permafrost"
    },
    {
      "x": -35,
      "y": -9,
      "z": 12,
      "name": "Rock_Ice_Permafrost"
    },
    {
      "x": -35,
      "y": -6,
      "z": 12,
      "name": "Rock_Ice_Permafrost"
    },
    {
      "x": -35,
      "y": -5,
      "z": 12,
      "name": "Rock_Ice_Permafrost"
    },
    {
      "x": -35,
      "y": 1,
      "z": 12,
      "name": "Rock_Ice_Permafrost"
    },
    {
      "x": -35,
      "y": 2,
      "z": 12,
      "name": "Rock_Ice_Permafrost"
    },
    {
      "x": -35,
      "y": 3,
      "z": 12,
      "name": "Rock_Ice_Permafrost"
    },
    {
      "x": -35,
      "y": 4,
      "z": 12,
      "name": "Rock_Ice_Permafrost"
    },
    {
      "x": -35,
      "y": 5,
      "z": 12,
      "name": "Rock_Ice_Permafrost"
    },
    {
      "x": -35,
      "y": 6,
      "z": 12,
      "name": "Rock_Ice_Permafrost"
    },
    {
      "x": -35,
      "y": 7,
      "z": 12,
      "name": "Rock_Ice_Permafrost"
    },
    {
      "x": -35,
      "y": 8,
      "z": 12,
      "name": "Rock_Ice_Permafrost"
    },
    {
      "x": -35,
      "y": -23,
      "z": 13,
      "name": "Rock_Ice_Permafrost"
    },
    {
      "x": -35,
      "y": -22,
      "z": 13,
      "name": "Rock_Ice_Permafrost"
    },
    {
      "x": -35,
      "y": -19,
      "z": 13,
      "name": "Rock_Ice_Permafrost"
    },
    {
      "x": -35,
      "y": -18,
      "z": 13,
      "name": "Rock_Ice_Permafrost"
    },
    {
      "x": -35,
      "y": -9,
      "z": 13,
      "name": "Rock_Ice_Permafrost"
    },
    {
      "x": -35,
      "y": -8,
      "z": 13,
      "name": "Rock_Ice_Permafrost"
    },
    {
      "x": -35,
      "y": -6,
      "z": 13,
      "name": "Rock_Ice_Permafrost"
    },
    {
      "x": -35,
      "y": -5,
      "z": 13,
      "name": "Rock_Ice_Permafrost"
    },
    {
      "x": -35,
      "y": 5,
      "z": 13,
      "name": "Rock_Ice_Permafrost"
    },
    {
      "x": -35,
      "y": 6,
      "z": 13,
      "name": "Rock_Ice_Permafrost"
    },
    {
      "x": -35,
      "y": 7,
      "z": 13,
      "name": "Rock_Ice_Permafrost"
    },
    {
      "x": -35,
      "y": 8,
      "z": 13,
      "name": "Rock_Ice_Permafrost"
    },
    {
      "x": -35,
      "y": -23,
      "z": 14,
      "name": "Rock_Ice_Permafrost"
    },
    {
      "x": -35,
      "y": -22,
      "z": 14,
      "name": "Rock_Ice_Permafrost"
    },
    {
      "x": -35,
      "y": -21,
      "z": 14,
      "name": "Rock_Ice_Permafrost"
    },
    {
      "x": -35,
      "y": -20,
      "z": 14,
      "name": "Rock_Ice_Permafrost"
    },
    {
      "x": -35,
      "y": -19,
      "z": 14,
      "name": "Rock_Ice_Permafrost"
    },
    {
      "x": -35,
      "y": -18,
      "z": 14,
      "name": "Rock_Ice_Permafrost"
    },
    {
      "x": -35,
      "y": -8,
      "z": 14,
      "name": "Rock_Ice_Permafrost"
    },
    {
      "x": -35,
      "y": -7,
      "z": 14,
      "name": "Rock_Ice_Permafrost"
    },
    {
      "x": -35,
      "y": -6,
      "z": 14,
      "name": "Rock_Ice_Permafrost"
    },
    {
      "x": -35,
      "y": -5,
      "z": 14,
      "name": "Rock_Ice_Permafrost"
    },
    {
      "x": -35,
      "y": -22,
      "z": 15,
      "name": "Rock_Ice_Permafrost"
    },
    {
      "x": -35,
      "y": -21,
      "z": 15,
      "name": "Rock_Ice_Permafrost"
    },
    {
      "x": -35,
      "y": -20,
      "z": 15,
      "name": "Rock_Ice_Permafrost"
    },
    {
      "x": -35,
      "y": -19,
      "z": 15,
      "name": "Rock_Ice_Permafrost"
    },
    {
      "x": -35,
      "y": -8,
      "z": 15,
      "name": "Rock_Ice_Permafrost"
    },
    {
      "x": -35,
      "y": -7,
      "z": 15,
      "name": "Rock_Ice_Permafrost"
    },
    {
      "x": -35,
      "y": -6,
      "z": 15,
      "name": "Rock_Ice_Permafrost"
    },
    {
      "x": -35,
      "y": -20,
      "z": 16,
      "name": "Rock_Ice_Permafrost"
    },
    {
      "x": -35,
      "y": -7,
      "z": 16,
      "name": "Rock_Ice_Permafrost"
    },
    {
      "x": -35,
      "y": -6,
      "z": 16,
      "name": "Rock_Ice_Permafrost"
    },
    {
      "x": -35,
      "y": -7,
      "z": 17,
      "name": "Rock_Ice_Permafrost"
    },
    {
      "x": -35,
      "y": -8,
      "z": 18,
      "name": "Rock_Ice_Permafrost"
    },
    {
      "x": -35,
      "y": -13,
      "z": 19,
      "name": "Rock_Ice_Permafrost"
    },
    {
      "x": -35,
      "y": -12,
      "z": 19,
      "name": "Rock_Ice_Permafrost"
    },
    {
      "x": -35,
      "y": -11,
      "z": 19,
      "name": "Rock_Ice_Permafrost"
    },
    {
      "x": -35,
      "y": -10,
      "z": 19,
      "name": "Rock_Ice_Permafrost"
    },
    {
      "x": -35,
      "y": -9,
      "z": 19,
      "name": "Rock_Ice_Permafrost"
    },
    {
      "x": -35,
      "y": -8,
      "z": 19,
      "name": "Rock_Ice_Permafrost"
    },
    {
      "x": -35,
      "y": -7,
      "z": 19,
      "name": "Rock_Ice_Permafrost"
    },
    {
      "x": -35,
      "y": -15,
      "z": 20,
      "name": "Rock_Ice_Permafrost"
    },
    {
      "x": -35,
      "y": -14,
      "z": 20,
      "name": "Rock_Ice_Permafrost"
    },
    {
      "x": -35,
      "y": -13,
      "z": 20,
      "name": "Rock_Ice_Permafrost"
    },
    {
      "x": -35,
      "y": -12,
      "z": 20,
      "name": "Rock_Ice_Permafrost"
    },
    {
      "x": -35,
      "y": -11,
      "z": 20,
      "name": "Rock_Ice_Permafrost"
    },
    {
      "x": -35,
      "y": -10,
      "z": 20,
      "name": "Rock_Ice_Permafrost"
    },
    {
      "x": -35,
      "y": -9,
      "z": 20,
      "name": "Rock_Ice_Permafrost"
    },
    {
      "x": -35,
      "y": -8,
      "z": 20,
      "name": "Rock_Ice_Permafrost"
    },
    {
      "x": -35,
      "y": -16,
      "z": 21,
      "name": "Rock_Ice_Permafrost"
    },
    {
      "x": -35,
      "y": -15,
      "z": 21,
      "name": "Rock_Ice_Permafrost"
    },
    {
      "x": -35,
      "y": -14,
      "z": 21,
      "name": "Rock_Ice_Permafrost"
    },
    {
      "x": -35,
      "y": -13,
      "z": 21,
      "name": "Rock_Ice_Permafrost"
    },
    {
      "x": -35,
      "y": -10,
      "z": 21,
      "name": "Rock_Ice_Permafrost"
    },
    {
      "x": -35,
      "y": -9,
      "z": 21,
      "name": "Rock_Ice_Permafrost"
    },
    {
      "x": -35,
      "y": -16,
      "z": 22,
      "name": "Rock_Ice_Permafrost"
    },
    {
      "x": -35,
      "y": -15,
      "z": 22,
      "name": "Rock_Ice_Permafrost"
    },
    {
      "x": -35,
      "y": -10,
      "z": 22,
      "name": "Rock_Ice_Permafrost"
    },
    {
      "x": -35,
      "y": -9,
      "z": 22,
      "name": "Rock_Ice_Permafrost"
    },
    {
      "x": -35,
      "y": 15,
      "z": 22,
      "name": "Rock_Ice_Permafrost"
    },
    {
      "x": -35,
      "y": 16,
      "z": 22,
      "name": "Rock_Ice_Permafrost"
    },
    {
      "x": -35,
      "y": 17,
      "z": 22,
      "name": "Rock_Ice_Permafrost"
    },
    {
      "x": -35,
      "y": -15,
      "z": 23,
      "name": "Rock_Ice_Permafrost"
    },
    {
      "x": -35,
      "y": -14,
      "z": 23,
      "name": "Rock_Ice_Permafrost"
    },
    {
      "x": -35,
      "y": -11,
      "z": 23,
      "name": "Rock_Ice_Permafrost"
    },
    {
      "x": -35,
      "y": -10,
      "z": 23,
      "name": "Rock_Ice_Permafrost"
    },
    {
      "x": -35,
      "y": 14,
      "z": 23,
      "name": "Rock_Ice_Permafrost"
    },
    {
      "x": -35,
      "y": 15,
      "z": 23,
      "name": "Rock_Ice_Permafrost"
    },
    {
      "x": -35,
      "y": 16,
      "z": 23,
      "name": "Rock_Ice_Permafrost"
    },
    {
      "x": -35,
      "y": 17,
      "z": 23,
      "name": "Rock_Ice_Permafrost"
    },
    {
      "x": -35,
      "y": -15,
      "z": 24,
      "name": "Rock_Ice_Permafrost"
    },
    {
      "x": -35,
      "y": -14,
      "z": 24,
      "name": "Rock_Ice_Permafrost"
    },
    {
      "x": -35,
      "y": -13,
      "z": 24,
      "name": "Rock_Ice_Permafrost"
    },
    {
      "x": -35,
      "y": -12,
      "z": 24,
      "name": "Rock_Ice_Permafrost"
    },
    {
      "x": -35,
      "y": -11,
      "z": 24,
      "name": "Rock_Ice_Permafrost"
    },
    {
      "x": -35,
      "y": 13,
      "z": 24,
      "name": "Rock_Ice_Permafrost"
    },
    {
      "x": -35,
      "y": 14,
      "z": 24,
      "name": "Rock_Ice_Permafrost"
    },
    {
      "x": -35,
      "y": 15,
      "z": 24,
      "name": "Rock_Ice_Permafrost"
    },
    {
      "x": -35,
      "y": 16,
      "z": 24,
      "name": "Rock_Ice_Permafrost"
    },
    {
      "x": -35,
      "y": -14,
      "z": 25,
      "name": "Rock_Ice_Permafrost"
    },
    {
      "x": -35,
      "y": -13,
      "z": 25,
      "name": "Rock_Ice_Permafrost"
    },
    {
      "x": -35,
      "y": -12,
      "z": 25,
      "name": "Rock_Ice_Permafrost"
    },
    {
      "x": -35,
      "y": 12,
      "z": 25,
      "name": "Rock_Ice_Permafrost"
    },
    {
      "x": -35,
      "y": 13,
      "z": 25,
      "name": "Rock_Ice_Permafrost"
    },
    {
      "x": -35,
      "y": 14,
      "z": 25,
      "name": "Rock_Ice_Permafrost"
    },
    {
      "x": -35,
      "y": 15,
      "z": 25,
      "name": "Rock_Ice_Permafrost"
    },
    {
      "x": -35,
      "y": 11,
      "z": 26,
      "name": "Rock_Ice_Permafrost"
    },
    {
      "x": -35,
      "y": 12,
      "z": 26,
      "name": "Rock_Ice_Permafrost"
    },
    {
      "x": -35,
      "y": 13,
      "z": 26,
      "name": "Rock_Ice_Permafrost"
    },
    {
      "x": -35,
      "y": 14,
      "z": 26,
      "name": "Rock_Ice_Permafrost"
    },
    {
      "x": -35,
      "y": 10,
      "z": 27,
      "name": "Rock_Ice_Permafrost"
    },
    {
      "x": -35,
      "y": 11,
      "z": 27,
      "name": "Rock_Ice_Permafrost"
    },
    {
      "x": -35,
      "y": 12,
      "z": 27,
      "name": "Rock_Ice_Permafrost"
    },
    {
      "x": -35,
      "y": 13,
      "z": 27,
      "name": "Rock_Ice_Permafrost"
    },
    {
      "x": -35,
      "y": 10,
      "z": 28,
      "name": "Rock_Ice_Permafrost"
    },
    {
      "x": -35,
      "y": 11,
      "z": 28,
      "name": "Rock_Ice_Permafrost"
    },
    {
      "x": -35,
      "y": 12,
      "z": 28,
      "name": "Rock_Ice_Permafrost"
    },
    {
      "x": -35,
      "y": 11,
      "z": 29,
      "name": "Rock_Ice_Permafrost"
    },
    {
      "x": -34,
      "y": -22,
      "z": -37,
      "name": "Rock_Ice_Permafrost"
    },
    {
      "x": -34,
      "y": -21,
      "z": -37,
      "name": "Rock_Ice_Permafrost"
    },
    {
      "x": -34,
      "y": -22,
      "z": -36,
      "name": "Rock_Ice_Permafrost"
    },
    {
      "x": -34,
      "y": -21,
      "z": -36,
      "name": "Rock_Ice_Permafrost"
    },
    {
      "x": -34,
      "y": -22,
      "z": -35,
      "name": "Rock_Ice_Permafrost"
    },
    {
      "x": -34,
      "y": -21,
      "z": -35,
      "name": "Rock_Ice_Permafrost"
    },
    {
      "x": -34,
      "y": -21,
      "z": -34,
      "name": "Rock_Ice_Permafrost"
    },
    {
      "x": -34,
      "y": 8,
      "z": -10,
      "name": "Rock_Ice_Permafrost"
    },
    {
      "x": -34,
      "y": 37,
      "z": -8,
      "name": "Rock_Ice_Permafrost"
    },
    {
      "x": -34,
      "y": 35,
      "z": -7,
      "name": "Rock_Ice_Permafrost"
    },
    {
      "x": -34,
      "y": 36,
      "z": -7,
      "name": "Rock_Ice_Permafrost"
    },
    {
      "x": -34,
      "y": 37,
      "z": -7,
      "name": "Rock_Ice_Permafrost"
    },
    {
      "x": -34,
      "y": 38,
      "z": -7,
      "name": "Rock_Ice_Permafrost"
    },
    {
      "x": -34,
      "y": 34,
      "z": -6,
      "name": "Rock_Ice_Permafrost"
    },
    {
      "x": -34,
      "y": 35,
      "z": -6,
      "name": "Rock_Ice_Permafrost"
    },
    {
      "x": -34,
      "y": 36,
      "z": -6,
      "name": "Rock_Ice_Permafrost"
    },
    {
      "x": -34,
      "y": 37,
      "z": -6,
      "name": "Rock_Ice_Permafrost"
    },
    {
      "x": -34,
      "y": 38,
      "z": -6,
      "name": "Rock_Ice_Permafrost"
    },
    {
      "x": -34,
      "y": 34,
      "z": -5,
      "name": "Rock_Ice_Permafrost"
    },
    {
      "x": -34,
      "y": 35,
      "z": -5,
      "name": "Rock_Ice_Permafrost"
    },
    {
      "x": -34,
      "y": 36,
      "z": -5,
      "name": "Rock_Ice_Permafrost"
    },
    {
      "x": -34,
      "y": 37,
      "z": -5,
      "name": "Rock_Ice_Permafrost"
    },
    {
      "x": -34,
      "y": 38,
      "z": -5,
      "name": "Rock_Ice_Permafrost"
    },
    {
      "x": -34,
      "y": 34,
      "z": -4,
      "name": "Rock_Ice_Permafrost"
    },
    {
      "x": -34,
      "y": 35,
      "z": -4,
      "name": "Rock_Ice_Permafrost"
    },
    {
      "x": -34,
      "y": 36,
      "z": -4,
      "name": "Rock_Ice_Permafrost"
    },
    {
      "x": -34,
      "y": 37,
      "z": -4,
      "name": "Rock_Ice_Permafrost"
    },
    {
      "x": -34,
      "y": -7,
      "z": 8,
      "name": "Rock_Ice_Permafrost"
    },
    {
      "x": -34,
      "y": 2,
      "z": 8,
      "name": "Rock_Ice_Permafrost"
    },
    {
      "x": -34,
      "y": 3,
      "z": 8,
      "name": "Rock_Ice_Permafrost"
    },
    {
      "x": -34,
      "y": -20,
      "z": 9,
      "name": "Rock_Ice_Permafrost"
    },
    {
      "x": -34,
      "y": -19,
      "z": 9,
      "name": "Rock_Ice_Permafrost"
    },
    {
      "x": -34,
      "y": -18,
      "z": 9,
      "name": "Rock_Ice_Permafrost"
    },
    {
      "x": -34,
      "y": -10,
      "z": 9,
      "name": "Rock_Ice_Permafrost"
    },
    {
      "x": -34,
      "y": -9,
      "z": 9,
      "name": "Rock_Ice_Permafrost"
    },
    {
      "x": -34,
      "y": -8,
      "z": 9,
      "name": "Rock_Ice_Permafrost"
    },
    {
      "x": -34,
      "y": -7,
      "z": 9,
      "name": "Rock_Ice_Permafrost"
    },
    {
      "x": -34,
      "y": -6,
      "z": 9,
      "name": "Rock_Ice_Permafrost"
    },
    {
      "x": -34,
      "y": -5,
      "z": 9,
      "name": "Rock_Ice_Permafrost"
    },
    {
      "x": -34,
      "y": -4,
      "z": 9,
      "name": "Rock_Ice_Permafrost"
    },
    {
      "x": -34,
      "y": 1,
