{
  "version": 8,
  "blockIdVersion": 11,
  "anchorX": 0,
  "anchorY": 0,
  "anchorZ": 0,
  "blocks": [
    {
      "x": -7,
      "y": -4,
      "z": -2,
      "name": "Ore_Silver_Sandstone"
    },
    {
      "x": -7,
      "y": -3,
      "z": -2,
      "name": "Ore_Silver_Sandstone"
    },
    {
      "x": -7,
      "y": -4,
      "z": -1,
      "name": "Ore_Silver_Sandstone"
    },
    {
      "x": -7,
      "y": -3,
      "z": -1,
      "name": "Ore_Silver_Sandstone"
    },
    {
      "x": -7,
      "y": -5,
      "z": 0,
      "name": "Ore_Silver_Sandstone"
    },
    {
      "x": -7,
      "y": -4,
      "z": 0,
      "name": "Ore_Silver_Sandstone"
    },
    {
      "x": -6,
      "y": -3,
      "z": -3,
      "name": "Rock_Sandstone"
    },
    {
      "x": -6,
      "y": -2,
      "z": -3,
      "name": "Rock_Sandstone"
    },
    {
      "x": -6,
      "y": -1,
      "z": -3,
      "name": "Rock_Sandstone"
    },
    {
      "x": -6,
      "y": 0,
      "z": -3,
      "name": "Rock_Sandstone"
    },
    {
      "x": -6,
      "y": 1,
      "z": -3,
      "name": "Soil_Sand_Ashen"
    },
    {
      "x": -6,
      "y": 2,
      "z": -3,
      "name": "Empty"
    },
    {
      "x": -6,
      "y": 3,
      "z": -3,
      "name": "Empty"
    },
    {
      "x": -6,
      "y": 4,
      "z": -3,
      "name": "Empty"
    },
    {
      "x": -6,
      "y": 5,
      "z": -3,
      "name": "Empty"
    },
    {
      "x": -6,
      "y": -7,
      "z": -2,
      "name": "Rock_Sandstone"
    },
    {
      "x": -6,
      "y": -6,
      "z": -2,
      "name": "Rock_Sandstone"
    },
    {
      "x": -6,
      "y": -5,
      "z": -2,
      "name": "Rock_Sandstone"
    },
    {
      "x": -6,
      "y": -4,
      "z": -2,
      "name": "Rock_Sandstone"
    },
    {
      "x": -6,
      "y": -3,
      "z": -2,
      "name": "Rock_Sandstone"
    },
    {
      "x": -6,
      "y": -2,
      "z": -2,
      "name": "Rock_Sandstone"
    },
    {
      "x": -6,
      "y": -1,
      "z": -2,
      "name": "Rock_Sandstone"
    },
    {
      "x": -6,
      "y": 0,
      "z": -2,
      "name": "Rock_Sandstone"
    },
    {
      "x": -6,
      "y": 1,
      "z": -2,
      "name": "Soil_Sand_Ashen"
    },
    {
      "x": -6,
      "y": 2,
      "z": -2,
      "name": "Plant_Crop_Mushroom_Glowing_Violet"
    },
    {
      "x": -6,
      "y": 3,
      "z": -2,
      "name": "Empty"
    },
    {
      "x": -6,
      "y": 4,
      "z": -2,
      "name": "Empty"
    },
    {
      "x": -6,
      "y": 5,
      "z": -2,
      "name": "Empty"
    },
    {
      "x": -6,
      "y": -7,
      "z": -1,
      "name": "Rock_Sandstone"
    },
    {
      "x": -6,
      "y": -6,
      "z": -1,
      "name": "Rock_Sandstone"
    },
    {
      "x": -6,
      "y": -5,
      "z": -1,
      "name": "Rock_Sandstone"
    },
    {
      "x": -6,
      "y": -4,
      "z": -1,
      "name": "Rock_Sandstone"
    },
    {
      "x": -6,
      "y": -3,
      "z": -1,
      "name": "Rock_Sandstone"
    },
    {
      "x": -6,
      "y": -2,
      "z": -1,
      "name": "Rock_Sandstone"
    },
    {
      "x": -6,
      "y": -1,
      "z": -1,
      "name": "Rock_Sandstone"
    },
    {
      "x": -6,
      "y": 0,
      "z": -1,
      "name": "Rock_Sandstone"
    },
    {
      "x": -6,
      "y": 1,
      "z": -1,
      "name": "Soil_Sand_Ashen"
    },
    {
      "x": -6,
      "y": 2,
      "z": -1,
      "name": "Plant_Moss_Rug_Pink",
      "support": 15
    },
    {
      "x": -6,
      "y": 3,
      "z": -1,
      "name": "Empty"
    },
    {
      "x": -6,
      "y": 4,
      "z": -1,
      "name": "Empty"
    },
    {
      "x": -6,
      "y": 5,
      "z": -1,
      "name": "Empty"
    },
    {
      "x": -6,
      "y": -7,
      "z": 0,
      "name": "Rock_Sandstone"
    },
    {
      "x": -6,
      "y": -6,
      "z": 0,
      "name": "Ore_Silver_Sandstone"
    },
    {
      "x": -6,
      "y": -5,
      "z": 0,
      "name": "Ore_Silver_Sandstone"
    },
    {
      "x": -6,
      "y": -4,
      "z": 0,
      "name": "Rock_Sandstone"
    },
    {
      "x": -6,
      "y": -3,
      "z": 0,
      "name": "Rock_Sandstone"
    },
    {
      "x": -6,
      "y": -2,
      "z": 0,
      "name": "Rock_Sandstone"
    },
    {
      "x": -6,
      "y": -1,
      "z": 0,
      "name": "Rock_Sandstone"
    },
    {
      "x": -6,
      "y": 0,
      "z": 0,
      "name": "Rock_Sandstone"
    },
    {
      "x": -6,
      "y": 1,
      "z": 0,
      "name": "Soil_Sand_Ashen"
    },
    {
      "x": -6,
      "y": 2,
      "z": 0,
      "name": "Plant_Moss_Rug_Pink",
      "support": 15
    },
    {
      "x": -6,
      "y": 3,
      "z": 0,
      "name": "Empty"
    },
    {
      "x": -6,
      "y": 4,
      "z": 0,
      "name": "Empty"
    },
    {
      "x": -6,
      "y": 5,
      "z": 0,
      "name": "Empty"
    },
    {
      "x": -6,
      "y": -6,
      "z": 1,
      "name": "Ore_Silver_Sandstone"
    },
    {
      "x": -6,
      "y": -5,
      "z": 1,
      "name": "Ore_Silver_Sandstone"
    },
    {
      "x": -6,
      "y": -4,
      "z": 1,
      "name": "Ore_Silver_Sandstone"
    },
    {
      "x": -6,
      "y": -3,
      "z": 1,
      "name": "Rock_Sandstone"
    },
    {
      "x": -6,
      "y": -2,
      "z": 1,
      "name": "Rock_Sandstone"
    },
    {
      "x": -6,
      "y": -1,
      "z": 1,
      "name": "Rock_Sandstone"
    },
    {
      "x": -6,
      "y": 0,
      "z": 1,
      "name": "Rock_Sandstone"
    },
    {
      "x": -6,
      "y": 1,
      "z": 1,
      "name": "Soil_Sand_Ashen"
    },
    {
      "x": -6,
      "y": 2,
      "z": 1,
      "name": "Empty"
    },
    {
      "x": -6,
      "y": 3,
      "z": 1,
      "name": "Empty"
    },
    {
      "x": -6,
      "y": 4,
      "z": 1,
      "name": "Empty"
    },
    {
      "x": -6,
      "y": 5,
      "z": 1,
      "name": "Empty"
    },
    {
      "x": -5,
      "y": 0,
      "z": -5,
      "name": "Rock_Sandstone"
    },
    {
      "x": -5,
      "y": 1,
      "z": -5,
      "name": "Soil_Sand_Ashen"
    },
    {
      "x": -5,
      "y": 2,
      "z": -5,
      "name": "Empty"
    },
    {
      "x": -5,
      "y": 3,
      "z": -5,
      "name": "Empty"
    },
    {
      "x": -5,
      "y": 4,
      "z": -5,
      "name": "Empty"
    },
    {
      "x": -5,
      "y": 5,
      "z": -5,
      "name": "Empty"
    },
    {
      "x": -5,
      "y": -9,
      "z": -4,
      "name": "Rock_Sandstone"
    },
    {
      "x": -5,
      "y": -8,
      "z": -4,
      "name": "Rock_Sandstone"
    },
    {
      "x": -5,
      "y": -7,
      "z": -4,
      "name": "Rock_Sandstone"
    },
    {
      "x": -5,
      "y": -6,
      "z": -4,
      "name": "Rock_Sandstone"
    },
    {
      "x": -5,
      "y": -5,
      "z": -4,
      "name": "Rock_Sandstone"
    },
    {
      "x": -5,
      "y": -4,
      "z": -4,
      "name": "Rock_Sandstone"
    },
    {
      "x": -5,
      "y": -3,
      "z": -4,
      "name": "Rock_Sandstone"
    },
    {
      "x": -5,
      "y": -2,
      "z": -4,
      "name": "Rock_Sandstone"
    },
    {
      "x": -5,
      "y": -1,
      "z": -4,
      "name": "Rock_Sandstone"
    },
    {
      "x": -5,
      "y": 0,
      "z": -4,
      "name": "Rock_Sandstone"
    },
    {
      "x": -5,
      "y": 1,
      "z": -4,
      "name": "Soil_Sand_Ashen"
    },
    {
      "x": -5,
      "y": 2,
      "z": -4,
      "name": "Plant_Moss_Rug_Pink",
      "support": 15
    },
    {
      "x": -5,
      "y": 3,
      "z": -4,
      "name": "Empty"
    },
    {
      "x": -5,
      "y": 4,
      "z": -4,
      "name": "Empty"
    },
    {
      "x": -5,
      "y": 5,
      "z": -4,
      "name": "Empty"
    },
    {
      "x": -5,
      "y": -12,
      "z": -3,
      "name": "Rock_Sandstone"
    },
    {
      "x": -5,
      "y": -11,
      "z": -3,
      "name": "Rock_Sandstone"
    },
    {
      "x": -5,
      "y": -10,
      "z": -3,
      "name": "Rock_Sandstone"
    },
    {
      "x": -5,
      "y": -9,
      "z": -3,
      "name": "Rock_Sandstone"
    },
    {
      "x": -5,
      "y": -8,
      "z": -3,
      "name": "Rock_Sandstone"
    },
    {
      "x": -5,
      "y": -7,
      "z": -3,
      "name": "Rock_Sandstone"
    },
    {
      "x": -5,
      "y": -6,
      "z": -3,
      "name": "Rock_Sandstone"
    },
    {
      "x": -5,
      "y": -5,
      "z": -3,
      "name": "Rock_Sandstone"
    },
    {
      "x": -5,
      "y": -4,
      "z": -3,
      "name": "Rock_Sandstone"
    },
    {
      "x": -5,
      "y": -3,
      "z": -3,
      "name": "Rock_Sandstone"
    },
    {
      "x": -5,
      "y": -2,
      "z": -3,
      "name": "Rock_Sandstone"
    },
    {
      "x": -5,
      "y": -1,
      "z": -3,
      "name": "Rock_Sandstone"
    },
    {
      "x": -5,
      "y": 0,
      "z": -3,
      "name": "Rock_Sandstone"
    },
    {
      "x": -5,
      "y": 1,
      "z": -3,
      "name": "Soil_Sand_Ashen"
    },
    {
      "x": -5,
      "y": 2,
      "z": -3,
      "name": "Plant_Flower_Bushy_Violet"
    },
    {
      "x": -5,
      "y": 3,
      "z": -3,
      "name": "Empty"
    },
    {
      "x": -5,
      "y": 4,
      "z": -3,
      "name": "Empty"
    },
    {
      "x": -5,
      "y": 5,
      "z": -3,
      "name": "Empty"
    },
    {
      "x": -5,
      "y": -14,
      "z": -2,
      "name": "Rock_Sandstone"
    },
    {
      "x": -5,
      "y": -13,
      "z": -2,
      "name": "Rock_Sandstone"
    },
    {
      "x": -5,
      "y": -12,
      "z": -2,
      "name": "Rock_Sandstone"
    },
    {
      "x": -5,
      "y": -11,
      "z": -2,
      "name": "Rock_Sandstone"
    },
    {
      "x": -5,
      "y": -10,
      "z": -2,
      "name": "Rock_Sandstone"
    },
    {
      "x": -5,
      "y": -9,
      "z": -2,
      "name": "Rock_Sandstone"
    },
    {
      "x": -5,
      "y": -8,
      "z": -2,
      "name": "Rock_Sandstone"
    },
    {
      "x": -5,
      "y": -7,
      "z": -2,
      "name": "Rock_Sandstone"
    },
    {
      "x": -5,
      "y": -6,
      "z": -2,
      "name": "Rock_Sandstone"
    },
    {
      "x": -5,
      "y": -5,
      "z": -2,
      "name": "Rock_Sandstone"
    },
    {
      "x": -5,
      "y": -4,
      "z": -2,
      "name": "Rock_Sandstone"
    },
    {
      "x": -5,
      "y": -3,
      "z": -2,
      "name": "Rock_Sandstone"
    },
    {
      "x": -5,
      "y": -2,
      "z": -2,
      "name": "Soil_Sand_Ashen"
    },
    {
      "x": -5,
      "y": -1,
      "z": -2,
      "name": "Plant_Crop_Mushroom_Glowing_Purple"
    },
    {
      "x": -5,
      "y": 0,
      "z": -2,
      "name": "Empty"
    },
    {
      "x": -5,
      "y": 1,
      "z": -2,
      "name": "Empty"
    },
    {
      "x": -5,
      "y": 2,
      "z": -2,
      "name": "Empty"
    },
    {
      "x": -5,
      "y": 3,
      "z": -2,
      "name": "Empty"
    },
    {
      "x": -5,
      "y": 4,
      "z": -2,
      "name": "Empty"
    },
    {
      "x": -5,
      "y": 5,
      "z": -2,
      "name": "Empty"
    },
    {
      "x": -5,
      "y": -14,
      "z": -1,
      "name": "Rock_Sandstone"
    },
    {
      "x": -5,
      "y": -13,
      "z": -1,
      "name": "Rock_Sandstone"
    },
    {
      "x": -5,
      "y": -12,
      "z": -1,
      "name": "Rock_Sandstone"
    },
    {
      "x": -5,
      "y": -11,
      "z": -1,
      "name": "Rock_Sandstone"
    },
    {
      "x": -5,
      "y": -10,
      "z": -1,
      "name": "Rock_Sandstone"
    },
    {
      "x": -5,
      "y": -9,
      "z": -1,
      "name": "Rock_Sandstone"
    },
    {
      "x": -5,
      "y": -8,
      "z": -1,
      "name": "Rock_Sandstone"
    },
    {
      "x": -5,
      "y": -7,
      "z": -1,
      "name": "Rock_Sandstone"
    },
    {
      "x": -5,
      "y": -6,
      "z": -1,
      "name": "Rock_Sandstone_Stalactite_Large"
    },
    {
      "x": -5,
      "y": -5,
      "z": -1,
      "name": "Rock_Sandstone_Stalactite_Large",
      "filler": 1024
    },
    {
      "x": -5,
      "y": -4,
      "z": -1,
      "name": "Empty"
    },
    {
      "x": -5,
      "y": -3,
      "z": -1,
      "name": "Empty"
    },
    {
      "x": -5,
      "y": -2,
      "z": -1,
      "name": "Empty"
    },
    {
      "x": -5,
      "y": -1,
      "z": -1,
      "name": "Empty"
    },
    {
      "x": -5,
      "y": 0,
      "z": -1,
      "name": "Empty"
    },
    {
      "x": -5,
      "y": 1,
      "z": -1,
      "name": "Empty"
    },
    {
      "x": -5,
      "y": 2,
      "z": -1,
      "name": "Empty"
    },
    {
      "x": -5,
      "y": 3,
      "z": -1,
      "name": "Empty"
    },
    {
      "x": -5,
      "y": 4,
      "z": -1,
      "name": "Empty"
    },
    {
      "x": -5,
      "y": 5,
      "z": -1,
      "name": "Empty"
    },
    {
      "x": -5,
      "y": -14,
      "z": 0,
      "name": "Rock_Sandstone"
    },
    {
      "x": -5,
      "y": -13,
      "z": 0,
      "name": "Rock_Sandstone"
    },
    {
      "x": -5,
      "y": -12,
      "z": 0,
      "name": "Rock_Sandstone"
    },
    {
      "x": -5,
      "y": -11,
      "z": 0,
      "name": "Rock_Sandstone"
    },
    {
      "x": -5,
      "y": -10,
      "z": 0,
      "name": "Rock_Sandstone"
    },
    {
      "x": -5,
      "y": -9,
      "z": 0,
      "name": "Rock_Sandstone"
    },
    {
      "x": -5,
      "y": -8,
      "z": 0,
      "name": "Rock_Sandstone"
    },
    {
      "x": -5,
      "y": -7,
      "z": 0,
      "name": "Rock_Sandstone"
    },
    {
      "x": -5,
      "y": -6,
      "z": 0,
      "name": "Ore_Silver_Sandstone"
    },
    {
      "x": -5,
      "y": -5,
      "z": 0,
      "name": "Ore_Silver_Sandstone"
    },
    {
      "x": -5,
      "y": -4,
      "z": 0,
      "name": "Rock_Sandstone"
    },
    {
      "x": -5,
      "y": -3,
      "z": 0,
      "name": "Rock_Sandstone"
    },
    {
      "x": -5,
      "y": -2,
      "z": 0,
      "name": "Soil_Sand_Ashen"
    },
    {
      "x": -5,
      "y": -1,
      "z": 0,
      "name": "Plant_Flower_Bushy_Poisoned"
    },
    {
      "x": -5,
      "y": 0,
      "z": 0,
      "name": "Empty"
    },
    {
      "x": -5,
      "y": 1,
      "z": 0,
      "name": "Empty"
    },
    {
      "x": -5,
      "y": 2,
      "z": 0,
      "name": "Empty"
    },
    {
      "x": -5,
      "y": 3,
      "z": 0,
      "name": "Empty"
    },
    {
      "x": -5,
      "y": 4,
      "z": 0,
      "name": "Empty"
    },
    {
      "x": -5,
      "y": 5,
      "z": 0,
      "name": "Empty"
    },
    {
      "x": -5,
      "y": -12,
      "z": 1,
      "name": "Rock_Sandstone"
    },
    {
      "x": -5,
      "y": -11,
      "z": 1,
      "name": "Rock_Sandstone"
    },
    {
      "x": -5,
      "y": -10,
      "z": 1,
      "name": "Rock_Sandstone"
    },
    {
      "x": -5,
      "y": -9,
      "z": 1,
      "name": "Rock_Sandstone"
    },
    {
      "x": -5,
      "y": -8,
      "z": 1,
      "name": "Rock_Sandstone"
    },
    {
      "x": -5,
      "y": -7,
      "z": 1,
      "name": "Rock_Sandstone"
    },
    {
      "x": -5,
      "y": -6,
      "z": 1,
      "name": "Rock_Sandstone"
    },
    {
      "x": -5,
      "y": -5,
      "z": 1,
      "name": "Rock_Sandstone"
    },
    {
      "x": -5,
      "y": -4,
      "z": 1,
      "name": "Rock_Sandstone"
    },
    {
      "x": -5,
      "y": -3,
      "z": 1,
      "name": "Rock_Sandstone"
    },
    {
      "x": -5,
      "y": -2,
      "z": 1,
      "name": "Rock_Sandstone"
    },
    {
      "x": -5,
      "y": -1,
      "z": 1,
      "name": "Rock_Sandstone"
    },
    {
      "x": -5,
      "y": 0,
      "z": 1,
      "name": "Rock_Sandstone"
    },
    {
      "x": -5,
      "y": 1,
      "z": 1,
      "name": "Soil_Sand_Ashen"
    },
    {
      "x": -5,
      "y": 2,
      "z": 1,
      "name": "Plant_Flower_Bushy_Violet"
    },
    {
      "x": -5,
      "y": 3,
      "z": 1,
      "name": "Empty"
    },
    {
      "x": -5,
      "y": 4,
      "z": 1,
      "name": "Empty"
    },
    {
      "x": -5,
      "y": 5,
      "z": 1,
      "name": "Empty"
    },
    {
      "x": -5,
      "y": -9,
      "z": 2,
      "name": "Rock_Sandstone"
    },
    {
      "x": -5,
      "y": -8,
      "z": 2,
      "name": "Rock_Sandstone"
    },
    {
      "x": -5,
      "y": -7,
      "z": 2,
      "name": "Rock_Sandstone"
    },
    {
      "x": -5,
      "y": -6,
      "z": 2,
      "name": "Rock_Sandstone"
    },
    {
      "x": -5,
      "y": -5,
      "z": 2,
      "name": "Rock_Sandstone"
    },
    {
      "x": -5,
      "y": -4,
      "z": 2,
      "name": "Rock_Sandstone"
    },
    {
      "x": -5,
      "y": -3,
      "z": 2,
      "name": "Rock_Sandstone"
    },
    {
      "x": -5,
      "y": -2,
      "z": 2,
      "name": "Rock_Sandstone"
    },
    {
      "x": -5,
      "y": -1,
      "z": 2,
      "name": "Rock_Sandstone"
    },
    {
      "x": -5,
      "y": 0,
      "z": 2,
      "name": "Rock_Sandstone"
    },
    {
      "x": -5,
      "y": 1,
      "z": 2,
      "name": "Soil_Sand_Ashen"
    },
    {
      "x": -5,
      "y": 2,
      "z": 2,
      "name": "Plant_Moss_Rug_Pink",
      "support": 15
    },
    {
      "x": -5,
      "y": 3,
      "z": 2,
      "name": "Empty"
    },
    {
      "x": -5,
      "y": 4,
      "z": 2,
      "name": "Empty"
    },
    {
      "x": -5,
      "y": 5,
      "z": 2,
      "name": "Empty"
    },
    {
      "x": -5,
      "y": 0,
      "z": 3,
      "name": "Rock_Sandstone"
    },
    {
      "x": -5,
      "y": 1,
      "z": 3,
      "name": "Soil_Sand_Ashen"
    },
    {
      "x": -5,
      "y": 2,
      "z": 3,
      "name": "Empty"
    },
    {
      "x": -5,
      "y": 3,
      "z": 3,
      "name": "Empty"
    },
    {
      "x": -5,
      "y": 4,
      "z": 3,
      "name": "Empty"
    },
    {
      "x": -5,
      "y": 5,
      "z": 3,
      "name": "Empty"
    },
    {
      "x": -4,
      "y": 0,
      "z": -6,
      "name": "Rock_Sandstone"
    },
    {
      "x": -4,
      "y": 1,
      "z": -6,
      "name": "Soil_Sand_Ashen"
    },
    {
      "x": -4,
      "y": 2,
      "z": -6,
      "name": "Empty"
    },
    {
      "x": -4,
      "y": 3,
      "z": -6,
      "name": "Empty"
    },
    {
      "x": -4,
      "y": 4,
      "z": -6,
      "name": "Empty"
    },
    {
      "x": -4,
      "y": 5,
      "z": -6,
      "name": "Empty"
    },
    {
      "x": -4,
      "y": -10,
      "z": -5,
      "name": "Rock_Sandstone"
    },
    {
      "x": -4,
      "y": -9,
      "z": -5,
      "name": "Rock_Sandstone"
    },
    {
      "x": -4,
      "y": -8,
      "z": -5,
      "name": "Rock_Sandstone"
    },
    {
      "x": -4,
      "y": -7,
      "z": -5,
      "name": "Rock_Sandstone"
    },
    {
      "x": -4,
      "y": -6,
      "z": -5,
      "name": "Rock_Sandstone"
    },
    {
      "x": -4,
      "y": -5,
      "z": -5,
      "name": "Rock_Sandstone"
    },
    {
      "x": -4,
      "y": -4,
      "z": -5,
      "name": "Rock_Sandstone"
    },
    {
      "x": -4,
      "y": -3,
      "z": -5,
      "name": "Rock_Sandstone"
    },
    {
      "x": -4,
      "y": -2,
      "z": -5,
      "name": "Rock_Sandstone"
    },
    {
      "x": -4,
      "y": -1,
      "z": -5,
      "name": "Rock_Sandstone"
    },
    {
      "x": -4,
      "y": 0,
      "z": -5,
      "name": "Rock_Sandstone"
    },
    {
      "x": -4,
      "y": 1,
      "z": -5,
      "name": "Soil_Sand_Ashen"
    },
    {
      "x": -4,
      "y": 2,
      "z": -5,
      "name": "Plant_Flower_Bushy_Poisoned"
    },
    {
      "x": -4,
      "y": 3,
      "z": -5,
      "name": "Empty"
    },
    {
      "x": -4,
      "y": 4,
      "z": -5,
      "name": "Empty"
    },
    {
      "x": -4,
      "y": 5,
      "z": -5,
      "name": "Empty"
    },
    {
      "x": -4,
      "y": -14,
      "z": -4,
      "name": "Rock_Sandstone"
    },
    {
      "x": -4,
      "y": -13,
      "z": -4,
      "name": "Rock_Sandstone"
    },
    {
      "x": -4,
      "y": -12,
      "z": -4,
      "name": "Rock_Sandstone"
    },
    {
      "x": -4,
      "y": -11,
      "z": -4,
      "name": "Rock_Sandstone"
    },
    {
      "x": -4,
      "y": -10,
      "z": -4,
      "name": "Rock_Sandstone"
    },
    {
      "x": -4,
      "y": -9,
      "z": -4,
      "name": "Rock_Sandstone"
    },
    {
      "x": -4,
      "y": -8,
      "z": -4,
      "name": "Rock_Sandstone"
    },
    {
      "x": -4,
      "y": -7,
      "z": -4,
      "name": "Rock_Sandstone"
    },
    {
      "x": -4,
      "y": -6,
      "z": -4,
      "name": "Rock_Sandstone"
    },
    {
      "x": -4,
      "y": -5,
      "z": -4,
      "name": "Rock_Sandstone"
    },
    {
      "x": -4,
      "y": -4,
      "z": -4,
      "name": "Rock_Sandstone"
    },
    {
      "x": -4,
      "y": -3,
      "z": -4,
      "name": "Rock_Sandstone"
    },
    {
      "x": -4,
      "y": -2,
      "z": -4,
      "name": "Rock_Sandstone"
    },
    {
      "x": -4,
      "y": -1,
      "z": -4,
      "name": "Rock_Sandstone"
    },
    {
      "x": -4,
      "y": 0,
      "z": -4,
      "name": "Rock_Sandstone"
    },
    {
      "x": -4,
      "y": 1,
      "z": -4,
      "name": "Soil_Sand_Ashen"
    },
    {
      "x": -4,
      "y": 2,
      "z": -4,
      "name": "Plant_Moss_Rug_Pink",
      "support": 15
    },
    {
      "x": -4,
      "y": 3,
      "z": -4,
      "name": "Empty"
    },
    {
      "x": -4,
      "y": 4,
      "z": -4,
      "name": "Empty"
    },
    {
      "x": -4,
      "y": 5,
      "z": -4,
      "name": "Empty"
    },
    {
      "x": -4,
      "y": -17,
      "z": -3,
      "name": "Rock_Sandstone"
    },
    {
      "x": -4,
      "y": -16,
      "z": -3,
      "name": "Rock_Sandstone"
    },
    {
      "x": -4,
      "y": -15,
      "z": -3,
      "name": "Rock_Sandstone"
    },
    {
      "x": -4,
      "y": -14,
      "z": -3,
      "name": "Rock_Sandstone"
    },
    {
      "x": -4,
      "y": -13,
      "z": -3,
      "name": "Rock_Sandstone"
    },
    {
      "x": -4,
      "y": -12,
      "z": -3,
      "name": "Rock_Sandstone"
    },
    {
      "x": -4,
      "y": -11,
      "z": -3,
      "name": "Rock_Sandstone"
    },
    {
      "x": -4,
      "y": -10,
      "z": -3,
      "name": "Rock_Sandstone"
    },
    {
      "x": -4,
      "y": -9,
      "z": -3,
      "name": "Rock_Sandstone"
    },
    {
      "x": -4,
      "y": -8,
      "z": -3,
      "name": "Rock_Sandstone_Stalactite_Large"
    },
    {
      "x": -4,
      "y": -7,
      "z": -3,
      "name": "Rock_Sandstone_Stalactite_Large",
      "filler": 1024
    },
    {
      "x": -4,
      "y": -6,
      "z": -3,
      "name": "Empty"
    },
    {
      "x": -4,
      "y": -5,
      "z": -3,
      "name": "Empty"
    },
    {
      "x": -4,
      "y": -4,
      "z": -3,
      "name": "Plant_Crop_Mushroom_Shelve_Yellow"
    },
    {
      "x": -4,
      "y": -3,
      "z": -3,
      "name": "Empty"
    },
    {
      "x": -4,
      "y": -2,
      "z": -3,
      "name": "Empty"
    },
    {
      "x": -4,
      "y": -1,
      "z": -3,
      "name": "Empty"
    },
    {
      "x": -4,
      "y": 0,
      "z": -3,
      "name": "Empty"
    },
    {
      "x": -4,
      "y": 1,
      "z": -3,
      "name": "Empty"
    },
    {
      "x": -4,
      "y": 2,
      "z": -3,
      "name": "Empty"
    },
    {
      "x": -4,
      "y": 3,
      "z": -3,
      "name": "Empty"
    },
    {
      "x": -4,
      "y": 4,
      "z": -3,
      "name": "Empty"
    },
    {
      "x": -4,
      "y": 5,
      "z": -3,
      "name": "Empty"
    },
    {
      "x": -4,
      "y": -18,
      "z": -2,
      "name": "Rock_Sandstone"
    },
    {
      "x": -4,
      "y": -17,
      "z": -2,
      "name": "Rock_Sandstone"
    },
    {
      "x": -4,
      "y": -16,
      "z": -2,
      "name": "Rock_Sandstone"
    },
    {
      "x": -4,
      "y": -15,
      "z": -2,
      "name": "Rock_Sandstone"
    },
    {
      "x": -4,
      "y": -14,
      "z": -2,
      "name": "Rock_Sandstone"
    },
    {
      "x": -4,
      "y": -13,
      "z": -2,
      "name": "Rock_Sandstone"
    },
    {
      "x": -4,
      "y": -12,
      "z": -2,
      "name": "Rock_Sandstone"
    },
    {
      "x": -4,
      "y": -11,
      "z": -2,
      "name": "Rock_Sandstone_Stalactite_Small"
    },
    {
      "x": -4,
      "y": -10,
      "z": -2,
      "name": "Empty"
    },
    {
      "x": -4,
      "y": -9,
      "z": -2,
      "name": "Empty"
    },
    {
      "x": -4,
      "y": -8,
      "z": -2,
      "name": "Empty"
    },
    {
      "x": -4,
      "y": -7,
      "z": -2,
      "name": "Empty"
    },
    {
      "x": -4,
      "y": -6,
      "z": -2,
      "name": "Empty"
    },
    {
      "x": -4,
      "y": -5,
      "z": -2,
      "name": "Empty"
    },
    {
      "x": -4,
      "y": -4,
      "z": -2,
      "name": "Plant_Crop_Mushroom_Shelve_Yellow"
    },
    {
      "x": -4,
      "y": -3,
      "z": -2,
      "name": "Empty"
    },
    {
      "x": -4,
      "y": -2,
      "z": -2,
      "name": "Empty"
    },
    {
      "x": -4,
      "y": -1,
      "z": -2,
      "name": "Empty"
    },
    {
      "x": -4,
      "y": 0,
      "z": -2,
      "name": "Empty"
    },
    {
      "x": -4,
      "y": 1,
      "z": -2,
      "name": "Empty"
    },
    {
      "x": -4,
      "y": 2,
      "z": -2,
      "name": "Empty"
    },
    {
      "x": -4,
      "y": 3,
      "z": -2,
      "name": "Empty"
    },
    {
      "x": -4,
      "y": 4,
      "z": -2,
      "name": "Empty"
    },
    {
      "x": -4,
      "y": 5,
      "z": -2,
      "name": "Empty"
    },
    {
      "x": -4,
      "y": -18,
      "z": -1,
      "name": "Rock_Sandstone"
    },
    {
      "x": -4,
      "y": -17,
      "z": -1,
      "name": "Rock_Sandstone"
    },
    {
      "x": -4,
      "y": -16,
      "z": -1,
      "name": "Rock_Sandstone"
    },
    {
      "x": -4,
      "y": -15,
      "z": -1,
      "name": "Rock_Sandstone"
    },
    {
      "x": -4,
      "y": -14,
      "z": -1,
      "name": "Rock_Sandstone"
    },
    {
      "x": -4,
      "y": -13,
      "z": -1,
      "name": "Rock_Sandstone_Stalactite_Small"
    },
    {
      "x": -4,
      "y": -12,
      "z": -1,
      "name": "Empty"
    },
    {
      "x": -4,
      "y": -11,
      "z": -1,
      "name": "Empty"
    },
    {
      "x": -4,
      "y": -10,
      "z": -1,
      "name": "Empty"
    },
    {
      "x": -4,
      "y": -9,
      "z": -1,
      "name": "Empty"
    },
    {
      "x": -4,
      "y": -8,
      "z": -1,
      "name": "Empty"
    },
    {
      "x": -4,
      "y": -7,
      "z": -1,
      "name": "Empty"
    },
    {
      "x": -4,
      "y": -6,
      "z": -1,
      "name": "Empty"
    },
    {
      "x": -4,
      "y": -5,
      "z": -1,
      "name": "Empty"
    },
    {
      "x": -4,
      "y": -4,
      "z": -1,
      "name": "Empty"
    },
    {
      "x": -4,
      "y": -3,
      "z": -1,
      "name": "Empty"
    },
    {
      "x": -4,
      "y": -2,
      "z": -1,
      "name": "Empty"
    },
    {
      "x": -4,
      "y": -1,
      "z": -1,
      "name": "Empty"
    },
    {
      "x": -4,
      "y": 0,
      "z": -1,
      "name": "Empty"
    },
    {
      "x": -4,
      "y": 1,
      "z": -1,
      "name": "Empty"
    },
    {
      "x": -4,
      "y": 2,
      "z": -1,
      "name": "Empty"
    },
    {
      "x": -4,
      "y": 3,
      "z": -1,
      "name": "Empty"
    },
    {
      "x": -4,
      "y": 4,
      "z": -1,
      "name": "Empty"
    },
    {
      "x": -4,
      "y": 5,
      "z": -1,
      "name": "Empty"
    },
    {
      "x": -4,
      "y": -18,
      "z": 0,
      "name": "Rock_Sandstone"
    },
    {
      "x": -4,
      "y": -17,
      "z": 0,
      "name": "Rock_Sandstone"
    },
    {
      "x": -4,
      "y": -16,
      "z": 0,
      "name": "Rock_Sandstone"
    },
    {
      "x": -4,
      "y": -15,
      "z": 0,
      "name": "Rock_Sandstone"
    },
    {
      "x": -4,
      "y": -14,
      "z": 0,
      "name": "Rock_Sandstone"
    },
    {
      "x": -4,
      "y": -13,
      "z": 0,
      "name": "Rock_Sandstone"
    },
    {
      "x": -4,
      "y": -12,
      "z": 0,
      "name": "Rock_Sandstone"
    },
    {
      "x": -4,
      "y": -11,
      "z": 0,
      "name": "Rock_Sandstone_Stalactite_Large"
    },
    {
      "x": -4,
      "y": -10,
      "z": 0,
      "name": "Rock_Sandstone_Stalactite_Large",
      "filler": 1024
    },
    {
      "x": -4,
      "y": -9,
      "z": 0,
      "name": "Empty"
    },
    {
      "x": -4,
      "y": -8,
      "z": 0,
      "name": "Empty"
    },
    {
      "x": -4,
      "y": -7,
      "z": 0,
      "name": "Empty"
    },
    {
      "x": -4,
      "y": -6,
      "z": 0,
      "name": "Empty"
    },
    {
      "x": -4,
      "y": -5,
      "z": 0,
      "name": "Empty"
    },
    {
      "x": -4,
      "y": -4,
      "z": 0,
      "name": "Empty"
    },
    {
      "x": -4,
      "y": -3,
      "z": 0,
      "name": "Empty"
    },
    {
      "x": -4,
      "y": -2,
      "z": 0,
      "name": "Empty"
    },
    {
      "x": -4,
      "y": -1,
      "z": 0,
      "name": "Empty"
    },
    {
      "x": -4,
      "y": 0,
      "z": 0,
      "name": "Empty"
    },
    {
      "x": -4,
      "y": 1,
      "z": 0,
      "name": "Empty"
    },
    {
      "x": -4,
      "y": 2,
      "z": 0,
      "name": "Empty"
    },
    {
      "x": -4,
      "y": 3,
      "z": 0,
      "name": "Empty"
    },
    {
      "x": -4,
      "y": 4,
      "z": 0,
      "name": "Empty"
    },
    {
      "x": -4,
      "y": 5,
      "z": 0,
      "name": "Empty"
    },
    {
      "x": -4,
      "y": -17,
      "z": 1,
      "name": "Rock_Sandstone"
    },
    {
      "x": -4,
      "y": -16,
      "z": 1,
      "name": "Rock_Sandstone"
    },
    {
      "x": -4,
      "y": -15,
      "z": 1,
      "name": "Rock_Sandstone"
    },
    {
      "x": -4,
      "y": -14,
      "z": 1,
      "name": "Rock_Sandstone"
    },
    {
      "x": -4,
      "y": -13,
      "z": 1,
      "name": "Rock_Sandstone"
    },
    {
      "x": -4,
      "y": -12,
      "z": 1,
      "name": "Rock_Sandstone"
    },
    {
      "x": -4,
      "y": -11,
      "z": 1,
      "name": "Rock_Sandstone"
    },
    {
      "x": -4,
      "y": -10,
      "z": 1,
      "name": "Rock_Sandstone"
    },
    {
      "x": -4,
      "y": -9,
      "z": 1,
      "name": "Rock_Sandstone"
    },
    {
      "x": -4,
      "y": -8,
      "z": 1,
      "name": "Rock_Sandstone_Stalactite_Small"
    },
    {
      "x": -4,
      "y": -7,
      "z": 1,
      "name": "Empty"
    },
    {
      "x": -4,
      "y": -6,
      "z": 1,
      "name": "Empty"
    },
    {
      "x": -4,
      "y": -5,
      "z": 1,
      "name": "Empty"
    },
    {
      "x": -4,
      "y": -4,
      "z": 1,
      "name": "Empty"
    },
    {
      "x": -4,
      "y": -3,
      "z": 1,
      "name": "Plant_Crop_Mushroom_Shelve_Yellow"
    },
    {
      "x": -4,
      "y": -2,
      "z": 1,
      "name": "Empty"
    },
    {
      "x": -4,
      "y": -1,
      "z": 1,
      "name": "Empty"
    },
    {
      "x": -4,
      "y": 0,
      "z": 1,
      "name": "Empty"
    },
    {
      "x": -4,
      "y": 1,
      "z": 1,
      "name": "Empty"
    },
    {
      "x": -4,
      "y": 2,
      "z": 1,
      "name": "Empty"
    },
    {
      "x": -4,
      "y": 3,
      "z": 1,
      "name": "Empty"
    },
    {
      "x": -4,
      "y": 4,
      "z": 1,
      "name": "Empty"
    },
    {
      "x": -4,
      "y": 5,
      "z": 1,
      "name": "Empty"
    },
    {
      "x": -4,
      "y": -14,
      "z": 2,
      "name": "Rock_Sandstone"
    },
    {
      "x": -4,
      "y": -13,
      "z": 2,
      "name": "Rock_Sandstone"
    },
    {
      "x": -4,
      "y": -12,
      "z": 2,
      "name": "Rock_Sandstone"
    },
    {
      "x": -4,
      "y": -11,
      "z": 2,
      "name": "Rock_Sandstone"
    },
    {
      "x": -4,
      "y": -10,
      "z": 2,
      "name": "Rock_Sandstone"
    },
    {
      "x": -4,
      "y": -9,
      "z": 2,
      "name": "Rock_Sandstone"
    },
    {
      "x": -4,
      "y": -8,
      "z": 2,
      "name": "Rock_Sandstone"
    },
    {
      "x": -4,
      "y": -7,
      "z": 2,
      "name": "Rock_Sandstone"
    },
    {
      "x": -4,
      "y": -6,
      "z": 2,
      "name": "Rock_Sandstone"
    },
    {
      "x": -4,
      "y": -5,
      "z": 2,
      "name": "Rock_Sandstone"
    },
    {
      "x": -4,
      "y": -4,
      "z": 2,
      "name": "Rock_Sandstone"
    },
    {
      "x": -4,
      "y": -3,
      "z": 2,
      "name": "Rock_Sandstone"
    },
    {
      "x": -4,
      "y": -2,
      "z": 2,
      "name": "Rock_Sandstone"
    },
    {
      "x": -4,
      "y": -1,
      "z": 2,
      "name": "Rock_Sandstone"
    },
    {
      "x": -4,
      "y": 0,
      "z": 2,
      "name": "Soil_Sand_Ashen"
    },
    {
      "x": -4,
      "y": 1,
      "z": 2,
      "name": "Plant_Crop_Mushroom_Glowing_Violet"
    },
    {
      "x": -4,
      "y": 2,
      "z": 2,
      "name": "Empty"
    },
    {
      "x": -4,
      "y": 3,
      "z": 2,
      "name": "Empty"
    },
    {
      "x": -4,
      "y": 4,
      "z": 2,
      "name": "Empty"
    },
    {
      "x": -4,
      "y": 5,
      "z": 2,
      "name": "Empty"
    },
    {
      "x": -4,
      "y": -10,
      "z": 3,
      "name": "Rock_Sandstone"
    },
    {
      "x": -4,
      "y": -9,
      "z": 3,
      "name": "Rock_Sandstone"
    },
    {
      "x": -4,
      "y": -8,
      "z": 3,
      "name": "Rock_Sandstone"
    },
    {
      "x": -4,
      "y": -7,
      "z": 3,
      "name": "Rock_Sandstone"
    },
    {
      "x": -4,
      "y": -6,
      "z": 3,
      "name": "Rock_Sandstone"
    },
    {
      "x": -4,
      "y": -5,
      "z": 3,
      "name": "Rock_Sandstone"
    },
    {
      "x": -4,
      "y": -4,
      "z": 3,
      "name": "Rock_Sandstone"
    },
    {
      "x": -4,
      "y": -3,
      "z": 3,
      "name": "Rock_Sandstone"
    },
    {
      "x": -4,
      "y": -2,
      "z": 3,
      "name": "Rock_Sandstone"
    },
    {
      "x": -4,
      "y": -1,
      "z": 3,
      "name": "Rock_Sandstone"
    },
    {
      "x": -4,
      "y": 0,
      "z": 3,
      "name": "Rock_Sandstone"
    },
    {
      "x": -4,
      "y": 1,
      "z": 3,
      "name": "Soil_Sand_Ashen"
    },
    {
      "x": -4,
      "y": 2,
      "z": 3,
      "name": "Empty"
    },
    {
      "x": -4,
      "y": 3,
      "z": 3,
      "name": "Empty"
    },
    {
      "x": -4,
      "y": 4,
      "z": 3,
      "name": "Empty"
    },
    {
      "x": -4,
      "y": 5,
      "z": 3,
      "name": "Empty"
    },
    {
      "x": -4,
      "y": 0,
      "z": 4,
      "name": "Rock_Sandstone"
    },
    {
      "x": -4,
      "y": 1,
      "z": 4,
      "name": "Soil_Sand_Ashen"
    },
    {
      "x": -4,
      "y": 2,
      "z": 4,
      "name": "Plant_Crop_Mushroom_Glowing_Purple"
    },
    {
      "x": -4,
      "y": 3,
      "z": 4,
      "name": "Empty"
    },
    {
      "x": -4,
      "y": 4,
      "z": 4,
      "name": "Empty"
    },
    {
      "x": -4,
      "y": 5,
      "z": 4,
      "name": "Empty"
    },
    {
      "x": -3,
      "y": -9,
      "z": -6,
      "name": "Rock_Sandstone"
    },
    {
      "x": -3,
      "y": -8,
      "z": -6,
      "name": "Rock_Sandstone"
    },
    {
      "x": -3,
      "y": -7,
      "z": -6,
      "name": "Rock_Sandstone"
    },
    {
      "x": -3,
      "y": -6,
      "z": -6,
      "name": "Rock_Sandstone"
    },
    {
      "x": -3,
      "y": -5,
      "z": -6,
      "name": "Rock_Sandstone"
    },
    {
      "x": -3,
      "y": -4,
      "z": -6,
      "name": "Rock_Sandstone"
    },
    {
      "x": -3,
      "y": -3,
      "z": -6,
      "name": "Rock_Sandstone"
    },
    {
      "x": -3,
      "y": -2,
      "z": -6,
      "name": "Rock_Sandstone"
    },
    {
      "x": -3,
      "y": -1,
      "z": -6,
      "name": "Rock_Sandstone"
    },
    {
      "x": -3,
      "y": 0,
      "z": -6,
      "name": "Rock_Sandstone"
    },
    {
      "x": -3,
      "y": 1,
      "z": -6,
      "name": "Soil_Sand_Ashen"
    },
    {
      "x": -3,
      "y": 2,
      "z": -6,
      "name": "Plant_Crop_Mushroom_Glowing_Purple"
    },
    {
      "x": -3,
      "y": 3,
      "z": -6,
      "name": "Empty"
    },
    {
      "x": -3,
      "y": 4,
      "z": -6,
      "name": "Empty"
    },
    {
      "x": -3,
      "y": 5,
      "z": -6,
      "name": "Empty"
    },
    {
      "x": -3,
      "y": -15,
      "z": -5,
      "name": "Ore_Thorium_Sandstone"
    },
    {
      "x": -3,
      "y": -14,
      "z": -5,
      "name": "Rock_Sandstone"
    },
    {
      "x": -3,
      "y": -13,
      "z": -5,
      "name": "Rock_Sandstone"
    },
    {
      "x": -3,
      "y": -12,
      "z": -5,
      "name": "Rock_Sandstone"
    },
    {
      "x": -3,
      "y": -11,
      "z": -5,
      "name": "Rock_Sandstone"
    },
    {
      "x": -3,
      "y": -10,
      "z": -5,
      "name": "Rock_Sandstone"
    },
    {
      "x": -3,
      "y": -9,
      "z": -5,
      "name": "Rock_Sandstone"
    },
    {
      "x": -3,
      "y": -8,
      "z": -5,
      "name": "Rock_Sandstone"
    },
    {
      "x": -3,
      "y": -7,
      "z": -5,
      "name": "Rock_Sandstone"
    },
    {
      "x": -3,
      "y": -6,
      "z": -5,
      "name": "Rock_Sandstone"
    },
    {
      "x": -3,
      "y": -5,
      "z": -5,
      "name": "Rock_Sandstone"
    },
    {
      "x": -3,
      "y": -4,
      "z": -5,
      "name": "Rock_Sandstone"
    },
    {
      "x": -3,
      "y": -3,
      "z": -5,
      "name": "Rock_Sandstone"
    },
    {
      "x": -3,
      "y": -2,
      "z": -5,
      "name": "Rock_Sandstone"
    },
    {
      "x": -3,
      "y": -1,
      "z": -5,
      "name": "Rock_Sandstone"
    },
    {
      "x": -3,
      "y": 0,
      "z": -5,
      "name": "Rock_Sandstone"
    },
    {
      "x": -3,
      "y": 1,
      "z": -5,
      "name": "Soil_Sand_Ashen"
    },
    {
      "x": -3,
      "y": 2,
      "z": -5,
      "name": "Plant_Moss_Rug_Pink",
      "support": 15
    },
    {
      "x": -3,
      "y": 3,
      "z": -5,
      "name": "Empty"
    },
    {
      "x": -3,
      "y": 4,
      "z": -5,
      "name": "Empty"
    },
    {
      "x": -3,
      "y": 5,
      "z": -5,
      "name": "Empty"
    },
    {
      "x": -3,
      "y": -18,
      "z": -4,
      "name": "Rock_Sandstone"
    },
    {
      "x": -3,
      "y": -17,
      "z": -4,
      "name": "Rock_Sandstone"
    },
    {
      "x": -3,
      "y": -16,
      "z": -4,
      "name": "Rock_Sandstone"
    },
    {
      "x": -3,
      "y": -15,
      "z": -4,
      "name": "Rock_Sandstone"
    },
    {
      "x": -3,
      "y": -14,
      "z": -4,
      "name": "Rock_Sandstone"
    },
    {
      "x": -3,
      "y": -13,
      "z": -4,
      "name": "Rock_Sandstone"
    },
    {
      "x": -3,
      "y": -12,
      "z": -4,
      "name": "Rock_Sandstone"
    },
    {
      "x": -3,
      "y": -11,
      "z": -4,
      "name": "Rock_Sandstone"
    },
    {
      "x": -3,
      "y": -10,
      "z": -4,
      "name": "Rock_Sandstone"
    },
    {
      "x": -3,
      "y": -9,
      "z": -4,
      "name": "Rock_Sandstone_Stalactite_Large"
    },
    {
      "x": -3,
      "y": -8,
      "z": -4,
      "name": "Rock_Sandstone_Stalactite_Large",
      "filler": 1024
    },
    {
      "x": -3,
      "y": -7,
      "z": -4,
      "name": "Empty"
    },
    {
      "x": -3,
      "y": -6,
      "z": -4,
      "name": "Empty"
    },
    {
      "x": -3,
      "y": -5,
      "z": -4,
      "name": "Empty"
    },
    {
      "x": -3,
      "y": -4,
      "z": -4,
      "name": "Empty"
    },
    {
      "x": -3,
      "y": -3,
      "z": -4,
      "name": "Empty"
    },
    {
      "x": -3,
      "y": -2,
      "z": -4,
      "name": "Empty"
    },
    {
      "x": -3,
      "y": -1,
      "z": -4,
      "name": "Empty"
    },
    {
      "x": -3,
      "y": 0,
      "z": -4,
      "name": "Empty"
    },
    {
      "x": -3,
      "y": 1,
      "z": -4,
      "name": "Empty"
    },
    {
      "x": -3,
      "y": 2,
      "z": -4,
      "name": "Empty"
    },
    {
      "x": -3,
      "y": 3,
      "z": -4,
      "name": "Empty"
    },
    {
      "x": -3,
      "y": 4,
      "z": -4,
      "name": "Empty"
    },
    {
      "x": -3,
      "y": 5,
      "z": -4,
      "name": "Empty"
    },
    {
      "x": -3,
      "y": -20,
      "z": -3,
      "name": "Rock_Sandstone"
    },
    {
      "x": -3,
      "y": -19,
      "z": -3,
      "name": "Rock_Sandstone"
    },
    {
      "x": -3,
      "y": -18,
      "z": -3,
      "name": "Rock_Sandstone"
    },
    {
      "x": -3,
      "y": -17,
      "z": -3,
      "name": "Rock_Sandstone"
    },
    {
      "x": -3,
      "y": -16,
      "z": -3,
      "name": "Rock_Sandstone"
    },
    {
      "x": -3,
      "y": -15,
      "z": -3,
      "name": "Rock_Sandstone"
    },
    {
      "x": -3,
      "y": -14,
      "z": -3,
      "name": "Rock_Sandstone"
    },
    {
      "x": -3,
      "y": -13,
      "z": -3,
      "name": "Rock_Sandstone_Stalactite_Small"
    },
    {
      "x": -3,
      "y": -12,
      "z": -3,
      "name": "Empty"
    },
    {
      "x": -3,
      "y": -11,
      "z": -3,
      "name": "Empty"
    },
    {
      "x": -3,
      "y": -10,
      "z": -3,
      "name": "Empty"
    },
    {
      "x": -3,
      "y": -9,
      "z": -3,
      "name": "Empty"
    },
    {
      "x": -3,
      "y": -8,
      "z": -3,
      "name": "Empty"
    },
    {
      "x": -3,
      "y": -7,
      "z": -3,
      "name": "Empty"
    },
    {
      "x": -3,
      "y": -6,
      "z": -3,
      "name": "Empty"
    },
    {
      "x": -3,
      "y": -5,
      "z": -3,
      "name": "Empty"
    },
    {
      "x": -3,
      "y": -4,
      "z": -3,
      "name": "Empty"
    },
    {
      "x": -3,
      "y": -3,
      "z": -3,
      "name": "Empty"
    },
    {
      "x": -3,
      "y": -2,
      "z": -3,
      "name": "Empty"
    },
    {
      "x": -3,
      "y": -1,
      "z": -3,
      "name": "Empty"
    },
    {
      "x": -3,
      "y": 0,
      "z": -3,
      "name": "Empty"
    },
    {
      "x": -3,
      "y": 1,
      "z": -3,
      "name": "Empty"
    },
    {
      "x": -3,
      "y": 2,
      "z": -3,
      "name": "Empty"
    },
    {
      "x": -3,
      "y": 3,
      "z": -3,
      "name": "Empty"
    },
    {
      "x": -3,
      "y": 4,
      "z": -3,
      "name": "Empty"
    },
    {
      "x": -3,
      "y": 5,
      "z": -3,
      "name": "Empty"
    },
    {
      "x": -3,
      "y": -23,
      "z": -2,
      "name": "Ore_Thorium_Sandstone"
    },
    {
      "x": -3,
      "y": -21,
      "z": -2,
      "name": "Rock_Sandstone"
    },
    {
      "x": -3,
      "y": -20,
      "z": -2,
      "name": "Rock_Sandstone"
    },
    {
      "x": -3,
      "y": -19,
      "z": -2,
      "name": "Rock_Sandstone"
    },
    {
      "x": -3,
      "y": -18,
      "z": -2,
      "name": "Rock_Sandstone"
    },
    {
      "x": -3,
      "y": -17,
      "z": -2,
      "name": "Empty"
    },
    {
      "x": -3,
      "y": -16,
      "z": -2,
      "name": "Empty"
    },
    {
      "x": -3,
      "y": -15,
      "z": -2,
      "name": "Empty"
    },
    {
      "x": -3,
      "y": -14,
      "z": -2,
      "name": "Empty"
    },
    {
      "x": -3,
      "y": -13,
      "z": -2,
      "name": "Empty"
    },
    {
      "x": -3,
      "y": -12,
      "z": -2,
      "name": "Empty"
    },
    {
      "x": -3,
      "y": -11,
      "z": -2,
      "name": "Empty"
    },
    {
      "x": -3,
      "y": -10,
      "z": -2,
      "name": "Empty"
    },
    {
      "x": -3,
      "y": -9,
      "z": -2,
      "name": "Empty"
    },
    {
      "x": -3,
      "y": -8,
      "z": -2,
      "name": "Empty"
    },
    {
      "x": -3,
      "y": -7,
      "z": -2,
      "name": "Empty"
    },
    {
      "x": -3,
      "y": -6,
      "z": -2,
      "name": "Empty"
    },
    {
      "x": -3,
      "y": -5,
      "z": -2,
      "name": "Empty"
    },
    {
      "x": -3,
      "y": -4,
      "z": -2,
      "name": "Empty"
    },
    {
      "x": -3,
      "y": -3,
      "z": -2,
      "name": "Empty"
    },
    {
      "x": -3,
      "y": -2,
      "z": -2,
      "name": "Empty"
    },
    {
      "x": -3,
      "y": -1,
      "z": -2,
      "name": "Empty"
    },
    {
      "x": -3,
      "y": 0,
      "z": -2,
      "name": "Empty"
    },
    {
      "x": -3,
      "y": 1,
      "z": -2,
      "name": "Empty"
    },
    {
      "x": -3,
      "y": 2,
      "z": -2,
      "name": "Empty"
    },
    {
      "x": -3,
      "y": 3,
      "z": -2,
      "name": "Empty"
    },
    {
      "x": -3,
      "y": 4,
      "z": -2,
      "name": "Empty"
    },
    {
      "x": -3,
      "y": 5,
      "z": -2,
      "name": "Empty"
    },
    {
      "x": -3,
      "y": -23,
      "z": -1,
      "name": "Ore_Thorium_Sandstone"
    },
    {
      "x": -3,
      "y": -21,
      "z": -1,
      "name": "Rock_Sandstone"
    },
    {
      "x": -3,
      "y": -20,
      "z": -1,
      "name": "Rock_Sandstone"
    },
    {
      "x": -3,
      "y": -19,
      "z": -1,
      "name": "Rock_Sandstone"
    },
    {
      "x": -3,
      "y": -18,
      "z": -1,
      "name": "Empty"
    },
    {
      "x": -3,
      "y": -17,
      "z": -1,
      "name": "Empty"
    },
    {
      "x": -3,
      "y": -16,
      "z": -1,
      "name": "Empty"
    },
    {
      "x": -3,
      "y": -15,
      "z": -1,
      "name": "Empty"
    },
    {
      "x": -3,
      "y": -14,
      "z": -1,
      "name": "Empty"
    },
    {
      "x": -3,
      "y": -13,
      "z": -1,
      "name": "Empty"
    },
    {
      "x": -3,
      "y": -12,
      "z": -1,
      "name": "Rock_Crystal_Purple_Small",
      "rotation": 7
    },
    {
      "x": -3,
      "y": -11,
      "z": -1,
      "name": "Empty"
    },
    {
      "x": -3,
      "y": -10,
      "z": -1,
      "name": "Empty"
    },
    {
      "x": -3,
      "y": -9,
      "z": -1,
      "name": "Empty"
    },
    {
      "x": -3,
      "y": -8,
      "z": -1,
      "name": "Empty"
    },
    {
      "x": -3,
      "y": -7,
      "z": -1,
      "name": "Empty"
    },
    {
      "x": -3,
      "y": -6,
      "z": -1,
      "name": "Empty"
    },
    {
      "x": -3,
      "y": -5,
      "z": -1,
      "name": "Empty"
    },
    {
      "x": -3,
      "y": -4,
      "z": -1,
      "name": "Empty"
    },
    {
      "x": -3,
      "y": -3,
      "z": -1,
      "name": "Empty"
    },
    {
      "x": -3,
      "y": -2,
      "z": -1,
      "name": "Empty"
    },
    {
      "x": -3,
      "y": -1,
      "z": -1,
      "name": "Empty"
    },
    {
      "x": -3,
      "y": 0,
      "z": -1,
      "name": "Empty"
    },
    {
      "x": -3,
      "y": 1,
      "z": -1,
      "name": "Empty"
    },
    {
      "x": -3,
      "y": 2,
      "z": -1,
      "name": "Empty"
    },
    {
      "x": -3,
      "y": 3,
      "z": -1,
      "name": "Empty"
    },
    {
      "x": -3,
      "y": 4,
      "z": -1,
      "name": "Empty"
    },
    {
      "x": -3,
      "y": 5,
      "z": -1,
      "name": "Empty"
    },
    {
      "x": -3,
      "y": -21,
      "z": 0,
      "name": "Rock_Sandstone"
    },
    {
      "x": -3,
      "y": -20,
      "z": 0,
      "name": "Rock_Sandstone"
    },
    {
      "x": -3,
      "y": -19,
      "z": 0,
      "name": "Rock_Sandstone"
    },
    {
      "x": -3,
      "y": -18,
      "z": 0,
      "name": "Rock_Sandstone"
    },
    {
      "x": -3,
      "y": -17,
      "z": 0,
      "name": "Empty"
    },
    {
      "x": -3,
      "y": -16,
      "z": 0,
      "name": "Empty"
    },
    {
      "x": -3,
      "y": -15,
      "z": 0,
      "name": "Empty"
    },
    {
      "x": -3,
      "y": -14,
      "z": 0,
      "name": "Empty"
    },
    {
      "x": -3,
      "y": -13,
      "z": 0,
      "name": "Empty"
    },
    {
      "x": -3,
      "y": -12,
      "z": 0,
      "name": "Empty"
    },
    {
      "x": -3,
      "y": -11,
      "z": 0,
      "name": "Empty"
    },
    {
      "x": -3,
      "y": -10,
      "z": 0,
      "name": "Empty"
    },
    {
      "x": -3,
      "y": -9,
      "z": 0,
      "name": "Empty"
    },
    {
      "x": -3,
      "y": -8,
      "z": 0,
      "name": "Empty"
    },
    {
      "x": -3,
      "y": -7,
      "z": 0,
      "name": "Empty"
    },
    {
      "x": -3,
      "y": -6,
      "z": 0,
      "name": "Empty"
    },
    {
      "x": -3,
      "y": -5,
      "z": 0,
      "name": "Empty"
    },
    {
      "x": -3,
      "y": -4,
      "z": 0,
      "name": "Empty"
    },
    {
      "x": -3,
      "y": -3,
      "z": 0,
      "name": "Empty"
    },
    {
      "x": -3,
      "y": -2,
      "z": 0,
      "name": "Empty"
    },
    {
      "x": -3,
      "y": -1,
      "z": 0,
      "name": "Empty"
    },
    {
      "x": -3,
      "y": 0,
      "z": 0,
      "name": "Empty"
    },
    {
      "x": -3,
      "y": 1,
      "z": 0,
      "name": "Empty"
    },
    {
      "x": -3,
      "y": 2,
      "z": 0,
      "name": "Empty"
    },
    {
      "x": -3,
      "y": 3,
      "z": 0,
      "name": "Empty"
    },
    {
      "x": -3,
      "y": 4,
      "z": 0,
      "name": "Empty"
    },
    {
      "x": -3,
      "y": 5,
      "z": 0,
      "name": "Empty"
    },
    {
      "x": -3,
      "y": -20,
      "z": 1,
      "name": "Rock_Sandstone"
    },
    {
      "x": -3,
      "y": -19,
      "z": 1,
      "name": "Rock_Sandstone"
    },
    {
      "x": -3,
      "y": -18,
      "z": 1,
      "name": "Rock_Sandstone"
    },
    {
      "x": -3,
      "y": -17,
      "z": 1,
      "name": "Rock_Sandstone"
    },
    {
      "x": -3,
      "y": -16,
      "z": 1,
      "name": "Rock_Sandstone"
    },
    {
      "x": -3,
      "y": -15,
      "z": 1,
      "name": "Rock_Sandstone"
    },
    {
      "x": -3,
      "y": -14,
      "z": 1,
      "name": "Rock_Sandstone"
    },
    {
      "x": -3,
      "y": -13,
      "z": 1,
      "name": "Rock_Sandstone_Stalactite_Small"
    },
    {
      "x": -3,
      "y": -12,
      "z": 1,
      "name": "Empty"
    },
    {
      "x": -3,
      "y": -11,
      "z": 1,
      "name": "Empty"
    },
    {
      "x": -3,
      "y": -10,
      "z": 1,
      "name": "Empty"
    },
    {
      "x": -3,
      "y": -9,
      "z": 1,
      "name": "Empty"
    },
    {
      "x": -3,
      "y": -8,
      "z": 1,
      "name": "Empty"
    },
    {
      "x": -3,
      "y": -7,
      "z": 1,
      "name": "Empty"
    },
    {
      "x": -3,
      "y": -6,
      "z": 1,
      "name": "Empty"
    },
    {
      "x": -3,
      "y": -5,
      "z": 1,
      "name": "Empty"
    },
    {
      "x": -3,
      "y": -4,
      "z": 1,
      "name": "Empty"
    },
    {
      "x": -3,
      "y": -3,
      "z": 1,
      "name": "Empty"
    },
    {
      "x": -3,
      "y": -2,
      "z": 1,
      "name": "Empty"
    },
    {
      "x": -3,
      "y": -1,
      "z": 1,
      "name": "Empty"
    },
    {
      "x": -3,
      "y": 0,
      "z": 1,
      "name": "Empty"
    },
    {
      "x": -3,
      "y": 1,
      "z": 1,
      "name": "Empty"
    },
    {
      "x": -3,
      "y": 2,
      "z": 1,
      "name": "Empty"
    },
    {
      "x": -3,
      "y": 3,
      "z": 1,
      "name": "Empty"
    },
    {
      "x": -3,
      "y": 4,
      "z": 1,
      "name": "Empty"
    },
    {
      "x": -3,
      "y": 5,
      "z": 1,
      "name": "Empty"
    },
    {
      "x": -3,
      "y": -18,
      "z": 2,
      "name": "Rock_Sandstone"
    },
    {
      "x": -3,
      "y": -17,
      "z": 2,
      "name": "Rock_Sandstone"
    },
    {
      "x": -3,
      "y": -16,
      "z": 2,
      "name": "Rock_Sandstone"
    },
    {
      "x": -3,
      "y": -15,
      "z": 2,
      "name": "Rock_Sandstone"
    },
    {
      "x": -3,
      "y": -14,
      "z": 2,
      "name": "Rock_Sandstone"
    },
    {
      "x": -3,
      "y": -13,
      "z": 2,
      "name": "Rock_Sandstone"
    },
    {
      "x": -3,
      "y": -12,
      "z": 2,
      "name": "Rock_Sandstone"
    },
    {
      "x": -3,
      "y": -11,
      "z": 2,
      "name": "Rock_Sandstone"
    },
    {
      "x": -3,
      "y": -10,
      "z": 2,
      "name": "Rock_Sandstone"
    },
    {
      "x": -3,
      "y": -9,
      "z": 2,
      "name": "Rock_Sandstone_Stalactite_Small"
    },
    {
      "x": -3,
      "y": -8,
      "z": 2,
      "name": "Empty"
    },
    {
      "x": -3,
      "y": -7,
      "z": 2,
      "name": "Empty"
    },
    {
      "x": -3,
      "y": -6,
      "z": 2,
      "name": "Empty"
    },
    {
      "x": -3,
      "y": -5,
      "z": 2,
      "name": "Empty"
    },
    {
      "x": -3,
      "y": -4,
      "z": 2,
      "name": "Plant_Crop_Mushroom_Shelve_Yellow"
    },
    {
      "x": -3,
      "y": -3,
      "z": 2,
      "name": "Empty"
    },
    {
      "x": -3,
      "y": -2,
      "z": 2,
      "name": "Empty"
    },
    {
      "x": -3,
      "y": -1,
      "z": 2,
      "name": "Empty"
    },
    {
      "x": -3,
      "y": 0,
      "z": 2,
      "name": "Empty"
    },
    {
      "x": -3,
      "y": 1,
      "z": 2,
      "name": "Empty"
    },
    {
      "x": -3,
      "y": 2,
      "z": 2,
      "name": "Empty"
    },
    {
      "x": -3,
      "y": 3,
      "z": 2,
      "name": "Empty"
    },
    {
      "x": -3,
      "y": 4,
      "z": 2,
      "name": "Empty"
    },
    {
      "x": -3,
      "y": 5,
      "z": 2,
      "name": "Empty"
    },
    {
      "x": -3,
      "y": -14,
      "z": 3,
      "name": "Rock_Sandstone"
    },
    {
      "x": -3,
      "y": -13,
      "z": 3,
      "name": "Rock_Sandstone"
    },
    {
      "x": -3,
      "y": -12,
      "z": 3,
      "name": "Rock_Sandstone"
    },
    {
      "x": -3,
      "y": -11,
      "z": 3,
      "name": "Rock_Sandstone"
    },
    {
      "x": -3,
      "y": -10,
      "z": 3,
      "name": "Rock_Sandstone"
    },
    {
      "x": -3,
      "y": -9,
      "z": 3,
      "name": "Rock_Sandstone"
    },
    {
      "x": -3,
      "y": -8,
      "z": 3,
      "name": "Rock_Sandstone"
    },
    {
      "x": -3,
      "y": -7,
      "z": 3,
      "name": "Rock_Sandstone"
    },
    {
      "x": -3,
      "y": -6,
      "z": 3,
      "name": "Rock_Sandstone"
    },
    {
      "x": -3,
      "y": -5,
      "z": 3,
      "name": "Rock_Sandstone"
    },
    {
      "x": -3,
      "y": -4,
      "z": 3,
      "name": "Rock_Sandstone"
    },
    {
      "x": -3,
      "y": -3,
      "z": 3,
      "name": "Rock_Sandstone"
    },
    {
      "x": -3,
      "y": -2,
      "z": 3,
      "name": "Rock_Sandstone"
    },
    {
      "x": -3,
      "y": -1,
      "z": 3,
      "name": "Soil_Sand_Ashen"
    },
    {
      "x": -3,
      "y": 0,
      "z": 3,
      "name": "Plant_Flower_Bushy_Poisoned"
    },
    {
      "x": -3,
      "y": 1,
      "z": 3,
      "name": "Empty"
    },
    {
      "x": -3,
      "y": 2,
      "z": 3,
      "name": "Empty"
    },
    {
      "x": -3,
      "y": 3,
      "z": 3,
      "name": "Empty"
    },
    {
      "x": -3,
      "y": 4,
      "z": 3,
      "name": "Empty"
    },
    {
      "x": -3,
      "y": 5,
      "z": 3,
      "name": "Empty"
    },
    {
      "x": -3,
      "y": -9,
      "z": 4,
      "name": "Rock_Sandstone"
    },
    {
      "x": -3,
      "y": -8,
      "z": 4,
      "name": "Rock_Sandstone"
    },
    {
      "x": -3,
      "y": -7,
      "z": 4,
      "name": "Rock_Sandstone"
    },
    {
      "x": -3,
      "y": -6,
      "z": 4,
      "name": "Rock_Sandstone"
    },
    {
      "x": -3,
      "y": -5,
      "z": 4,
      "name": "Rock_Sandstone"
    },
    {
      "x": -3,
      "y": -4,
      "z": 4,
      "name": "Rock_Sandstone"
    },
    {
      "x": -3,
      "y": -3,
      "z": 4,
      "name": "Rock_Sandstone"
    },
    {
      "x": -3,
      "y": -2,
      "z": 4,
      "name": "Rock_Sandstone"
    },
    {
      "x": -3,
      "y": -1,
      "z": 4,
      "name": "Rock_Sandstone"
    },
    {
      "x": -3,
      "y": 0,
      "z": 4,
      "name": "Soil_Sand_Ashen"
    },
    {
      "x": -3,
      "y": 1,
      "z": 4,
      "name": "Plant_Flower_Bushy_Purple"
    },
    {
      "x": -3,
      "y": 2,
      "z": 4,
      "name": "Empty"
    },
    {
      "x": -3,
      "y": 3,
      "z": 4,
      "name": "Empty"
    },
    {
      "x": -3,
      "y": 4,
      "z": 4,
      "name": "Empty"
    },
    {
      "x": -3,
      "y": 5,
      "z": 4,
      "name": "Empty"
    },
    {
      "x": -3,
      "y": -1,
      "z": 5,
      "name": "Rock_Sandstone"
    },
    {
      "x": -3,
      "y": 0,
      "z": 5,
      "name": "Rock_Sandstone"
    },
    {
      "x": -3,
      "y": 1,
      "z": 5,
      "name": "Soil_Sand_Ashen"
    },
    {
      "x": -3,
      "y": 2,
      "z": 5,
      "name": "Empty"
    },
    {
      "x": -3,
      "y": 3,
      "z": 5,
      "name": "Empty"
    },
    {
      "x": -3,
      "y": 4,
      "z": 5,
      "name": "Empty"
    },
    {
      "x": -3,
      "y": 5,
      "z": 5,
      "name": "Empty"
    },
    {
      "x": -2,
      "y": -3,
      "z": -7,
      "name": "Rock_Sandstone"
    },
    {
      "x": -2,
      "y": -2,
      "z": -7,
      "name": "Rock_Sandstone"
    },
    {
      "x": -2,
      "y": -1,
      "z": -7,
      "name": "Rock_Sandstone"
    },
    {
      "x": -2,
      "y": 0,
      "z": -7,
      "name": "Rock_Sandstone"
    },
    {
      "x": -2,
      "y": 1,
      "z": -7,
      "name": "Soil_Sand_Ashen"
    },
    {
      "x": -2,
      "y": 2,
      "z": -7,
      "name": "Empty"
    },
    {
      "x": -2,
      "y": 3,
      "z": -7,
      "name": "Empty"
    },
    {
      "x": -2,
      "y": 4,
      "z": -7,
      "name": "Empty"
    },
    {
      "x": -2,
      "y": 5,
      "z": -7,
      "name": "Empty"
    },
    {
      "x": -2,
      "y": -15,
      "z": -6,
      "name": "Ore_Thorium_Sandstone"
    },
    {
      "x": -2,
      "y": -12,
      "z": -6,
      "name": "Rock_Sandstone"
    },
    {
      "x": -2,
      "y": -11,
      "z": -6,
      "name": "Rock_Sandstone"
    },
    {
      "x": -2,
      "y": -10,
      "z": -6,
      "name": "Rock_Sandstone"
    },
    {
      "x": -2,
      "y": -9,
      "z": -6,
      "name": "Rock_Sandstone"
    },
    {
      "x": -2,
      "y": -8,
      "z": -6,
      "name": "Rock_Sandstone"
    },
    {
      "x": -2,
      "y": -7,
      "z": -6,
      "name": "Rock_Sandstone"
    },
    {
      "x": -2,
      "y": -6,
      "z": -6,
      "name": "Rock_Sandstone"
    },
    {
      "x": -2,
      "y": -5,
      "z": -6,
      "name": "Rock_Sandstone"
    },
    {
      "x": -2,
      "y": -4,
      "z": -6,
      "name": "Rock_Sandstone"
    },
    {
      "x": -2,
      "y": -3,
      "z": -6,
      "name": "Rock_Sandstone"
    },
    {
      "x": -2,
      "y": -2,
      "z": -6,
      "name": "Rock_Sandstone"
    },
    {
      "x": -2,
      "y": -1,
      "z": -6,
      "name": "Rock_Sandstone"
    },
    {
      "x": -2,
      "y": 0,
      "z": -6,
      "name": "Rock_Sandstone"
    },
    {
      "x": -2,
      "y": 1,
      "z": -6,
      "name": "Soil_Sand_Ashen"
    },
    {
      "x": -2,
      "y": 2,
      "z": -6,
      "name": "Plant_Crop_Mushroom_Glowing_Violet"
    },
    {
      "x": -2,
      "y": 3,
      "z": -6,
      "name": "Empty"
    },
    {
      "x": -2,
      "y": 4,
      "z": -6,
      "name": "Empty"
    },
    {
      "x": -2,
      "y": 5,
      "z": -6,
      "name": "Empty"
    },
    {
      "x": -2,
      "y": -17,
      "z": -5,
      "name": "Rock_Sandstone"
    },
    {
      "x": -2,
      "y": -16,
      "z": -5,
      "name": "Rock_Sandstone"
    },
    {
      "x": -2,
      "y": -15,
      "z": -5,
      "name": "Ore_Thorium_Sandstone"
    },
    {
      "x": -2,
      "y": -14,
      "z": -5,
      "name": "Rock_Sandstone"
    },
    {
      "x": -2,
      "y": -13,
      "z": -5,
      "name": "Rock_Sandstone"
    },
    {
      "x": -2,
      "y": -12,
      "z": -5,
      "name": "Rock_Sandstone"
    },
    {
      "x": -2,
      "y": -11,
      "z": -5,
      "name": "Rock_Sandstone"
    },
    {
      "x": -2,
      "y": -10,
      "z": -5,
      "name": "Rock_Sandstone"
    },
    {
      "x": -2,
      "y": -9,
      "z": -5,
      "name": "Rock_Sandstone"
    },
    {
      "x": -2,
      "y": -8,
      "z": -5,
      "name": "Soil_Sand_Ashen"
    },
    {
      "x": -2,
      "y": -7,
      "z": -5,
      "name": "Plant_Moss_Rug_Pink",
      "support": 15
    },
    {
      "x": -2,
      "y": -6,
      "z": -5,
      "name": "Empty"
    },
    {
      "x": -2,
      "y": -5,
      "z": -5,
      "name": "Empty"
    },
    {
      "x": -2,
      "y": -4,
      "z": -5,
      "name": "Plant_Crop_Mushroom_Shelve_Yellow"
    },
    {
      "x": -2,
      "y": -3,
      "z": -5,
      "name": "Empty"
    },
    {
      "x": -2,
      "y": -2,
      "z": -5,
      "name": "Empty"
    },
    {
      "x": -2,
      "y": -1,
      "z": -5,
      "name": "Empty"
    },
    {
      "x": -2,
      "y": 0,
      "z": -5,
      "name": "Empty"
    },
    {
      "x": -2,
      "y": 1,
      "z": -5,
      "name": "Empty"
    },
    {
      "x": -2,
      "y": 2,
      "z": -5,
      "name": "Empty"
    },
    {
      "x": -2,
      "y": 3,
      "z": -5,
      "name": "Empty"
    },
    {
      "x": -2,
      "y": 4,
      "z": -5,
      "name": "Empty"
    },
    {
      "x": -2,
      "y": 5,
      "z": -5,
      "name": "Empty"
    },
    {
      "x": -2,
      "y": -20,
      "z": -4,
      "name": "Rock_Sandstone"
    },
    {
      "x": -2,
      "y": -19,
      "z": -4,
      "name": "Rock_Sandstone"
    },
    {
      "x": -2,
      "y": -18,
      "z": -4,
      "name": "Rock_Sandstone"
    },
    {
      "x": -2,
      "y": -17,
      "z": -4,
      "name": "Rock_Sandstone"
    },
    {
      "x": -2,
      "y": -16,
      "z": -4,
      "name": "Rock_Sandstone"
    },
    {
      "x": -2,
      "y": -15,
      "z": -4,
      "name": "Ore_Thorium_Sandstone"
    },
    {
      "x": -2,
      "y": -14,
      "z": -4,
      "name": "Rock_Sandstone"
    },
    {
      "x": -2,
      "y": -13,
      "z": -4,
      "name": "Rock_Sandstone_Stalactite_Small"
    },
    {
      "x": -2,
      "y": -12,
      "z": -4,
      "name": "Empty"
    },
    {
      "x": -2,
      "y": -11,
      "z": -4,
      "name": "Empty"
    },
    {
      "x": -2,
      "y": -10,
      "z": -4,
      "name": "Empty"
    },
    {
      "x": -2,
      "y": -9,
      "z": -4,
      "name": "Empty"
    },
    {
      "x": -2,
      "y": -8,
      "z": -4,
      "name": "Empty"
    },
    {
      "x": -2,
      "y": -7,
      "z": -4,
      "name": "Empty"
    },
    {
      "x": -2,
      "y": -6,
      "z": -4,
      "name": "Empty"
    },
    {
      "x": -2,
      "y": -5,
      "z": -4,
      "name": "Empty"
    },
    {
      "x": -2,
      "y": -4,
      "z": -4,
      "name": "Empty"
    },
    {
      "x": -2,
      "y": -3,
      "z": -4,
      "name": "Empty"
    },
    {
      "x": -2,
      "y": -2,
      "z": -4,
      "name": "Empty"
    },
    {
      "x": -2,
      "y": -1,
      "z": -4,
      "name": "Empty"
    },
    {
      "x": -2,
      "y": 0,
      "z": -4,
      "name": "Empty"
    },
    {
      "x": -2,
      "y": 1,
      "z": -4,
      "name": "Empty"
    },
    {
      "x": -2,
      "y": 2,
      "z": -4,
      "name": "Empty"
    },
    {
      "x": -2,
      "y": 3,
      "z": -4,
      "name": "Empty"
    },
    {
      "x": -2,
      "y": 4,
      "z": -4,
      "name": "Empty"
    },
    {
      "x": -2,
      "y": 5,
      "z": -4,
      "name": "Empty"
    },
    {
      "x": -2,
      "y": -23,
      "z": -3,
      "name": "Ore_Thorium_Sandstone"
    },
    {
      "x": -2,
      "y": -21,
      "z": -3,
      "name": "Rock_Sandstone"
    },
    {
      "x": -2,
      "y": -20,
      "z": -3,
      "name": "Rock_Sandstone"
    },
    {
      "x": -2,
      "y": -19,
      "z": -3,
      "name": "Rock_Sandstone"
    },
    {
      "x": -2,
      "y": -18,
      "z": -3,
      "name": "Rock_Sandstone"
    },
    {
      "x": -2,
      "y": -17,
      "z": -3,
      "name": "Rock_Sandstone_Stalactite_Small"
    },
    {
      "x": -2,
      "y": -16,
      "z": -3,
      "name": "Empty"
    },
    {
      "x": -2,
      "y": -15,
      "z": -3,
      "name": "Empty"
    },
    {
      "x": -2,
      "y": -14,
      "z": -3,
      "name": "Empty"
    },
    {
      "x": -2,
      "y": -13,
      "z": -3,
      "name": "Empty"
    },
    {
      "x": -2,
      "y": -12,
      "z": -3,
      "name": "Empty"
    },
    {
      "x": -2,
      "y": -11,
      "z": -3,
      "name": "Empty"
    },
    {
      "x": -2,
      "y": -10,
      "z": -3,
      "name": "Empty"
    },
    {
      "x": -2,
      "y": -9,
      "z": -3,
      "name": "Empty"
    },
    {
      "x": -2,
      "y": -8,
      "z": -3,
      "name": "Empty"
    },
    {
      "x": -2,
      "y": -7,
      "z": -3,
      "name": "Empty"
    },
    {
      "x": -2,
      "y": -6,
      "z": -3,
      "name": "Empty"
    },
    {
      "x": -2,
      "y": -5,
      "z": -3,
      "name": "Empty"
    },
    {
      "x": -2,
      "y": -4,
      "z": -3,
      "name": "Empty"
    },
    {
      "x": -2,
      "y": -3,
      "z": -3,
      "name": "Empty"
    },
    {
      "x": -2,
      "y": -2,
      "z": -3,
      "name": "Empty"
    },
    {
      "x": -2,
      "y": -1,
      "z": -3,
      "name": "Empty"
    },
    {
      "x": -2,
      "y": 0,
      "z": -3,
      "name": "Empty"
    },
    {
      "x": -2,
      "y": 1,
      "z": -3,
      "name": "Empty"
    },
    {
      "x": -2,
      "y": 2,
      "z": -3,
      "name": "Empty"
    },
    {
      "x": -2,
      "y": 3,
      "z": -3,
      "name": "Empty"
    },
    {
      "x": -2,
      "y": 4,
      "z": -3,
      "name": "Empty"
    },
    {
      "x": -2,
      "y": 5,
      "z": -3,
      "name": "Empty"
    },
    {
      "x": -2,
      "y": -23,
      "z": -2,
      "name": "Ore_Thorium_Sandstone"
    },
    {
      "x": -2,
      "y": -22,
      "z": -2,
      "name": "Rock_Sandstone"
    },
    {
      "x": -2,
      "y": -21,
      "z": -2,
      "name": "Rock_Sandstone"
    },
    {
      "x": -2,
      "y": -20,
      "z": -2,
      "name": "Rock_Sandstone"
    },
    {
      "x": -2,
      "y": -19,
      "z": -2,
      "name": "Rock_Gem_Voidstone"
    },
    {
      "x": -2,
      "y": -18,
      "z": -2,
      "name": "Empty"
    },
    {
      "x": -2,
      "y": -17,
      "z": -2,
      "name": "Empty"
    },
    {
      "x": -2,
      "y": -16,
      "z": -2,
      "name": "Empty"
    },
    {
      "x": -2,
      "y": -15,
      "z": -2,
      "name": "Rock_Crystal_Purple_Medium",
      "rotation": 7
    },
    {
      "x": -2,
      "y": -14,
      "z": -2,
      "name": "Rock_Crystal_Purple_Small",
      "rotation": 6
    },
    {
      "x": -2,
      "y": -13,
      "z": -2,
      "name": "Empty"
    },
    {
      "x": -2,
      "y": -12,
      "z": -2,
      "name": "Rock_Crystal_Purple_Medium",
      "rotation": 6
    },
    {
      "x": -2,
      "y": -11,
      "z": -2,
      "name": "Empty"
    },
    {
      "x": -2,
      "y": -10,
      "z": -2,
      "name": "Empty"
    },
    {
      "x": -2,
      "y": -9,
      "z": -2,
      "name": "Empty"
    },
    {
      "x": -2,
      "y": -8,
      "z": -2,
      "name": "Empty"
    },
    {
      "x": -2,
      "y": -7,
      "z": -2,
      "name": "Empty"
    },
    {
      "x": -2,
      "y": -6,
      "z": -2,
      "name": "Empty"
    },
    {
      "x": -2,
      "y": -5,
      "z": -2,
      "name": "Empty"
    },
    {
      "x": -2,
      "y": -4,
      "z": -2,
      "name": "Empty"
    },
    {
      "x": -2,
      "y": -3,
      "z": -2,
      "name": "Empty"
    },
    {
      "x": -2,
      "y": -2,
      "z": -2,
      "name": "Empty"
    },
    {
      "x": -2,
      "y": -1,
      "z": -2,
      "name": "Empty"
    },
    {
      "x": -2,
      "y": 0,
      "z": -2,
      "name": "Empty"
    },
    {
      "x": -2,
      "y": 1,
      "z": -2,
      "name": "Empty"
    },
    {
      "x": -2,
      "y": 2,
      "z": -2,
      "name": "Empty"
    },
    {
      "x": -2,
      "y": 3,
      "z": -2,
      "name": "Empty"
    },
    {
      "x": -2,
      "y": 4,
      "z": -2,
      "name": "Empty"
    },
    {
      "x": -2,
      "y": 5,
      "z": -2,
      "name": "Empty"
    },
    {
      "x": -2,
      "y": -23,
      "z": -1,
      "name": "Rock_Sandstone"
    },
    {
      "x": -2,
      "y": -22,
      "z": -1,
      "name": "Rock_Sandstone"
    },
    {
      "x": -2,
      "y": -21,
      "z": -1,
      "name": "Rock_Sandstone"
    },
    {
      "x": -2,
      "y": -20,
      "z": -1,
      "name": "Rock_Crystal_Purple_Block"
    },
    {
      "x": -2,
      "y": -19,
      "z": -1,
      "name": "Rock_Crystal_Purple_Block"
    },
    {
      "x": -2,
      "y": -18,
      "z": -1,
      "name": "Rock_Crystal_Purple_Block"
    },
    {
      "x": -2,
      "y": -17,
      "z": -1,
      "name": "Rock_Crystal_Purple_Block"
    },
    {
      "x": -2,
      "y": -16,
      "z": -1,
      "name": "Rock_Crystal_Purple_Block"
    },
    {
      "x": -2,
      "y": -15,
      "z": -1,
      "name": "Rock_Crystal_Purple_Block"
    },
    {
      "x": -2,
      "y": -14,
      "z": -1,
      "name": "Rock_Crystal_Purple_Block"
    },
    {
      "x": -2,
      "y": -13,
      "z": -1,
      "name": "Rock_Crystal_Purple_Block"
    },
    {
      "x": -2,
      "y": -12,
      "z": -1,
      "name": "Rock_Crystal_Purple_Block"
    },
    {
      "x": -2,
      "y": -11,
      "z": -1,
      "name": "Rock_Crystal_Purple_Block"
    },
    {
      "x": -2,
      "y": -10,
      "z": -1,
      "name": "Rock_Crystal_Purple_Large",
      "rotation": 7
    },
    {
      "x": -2,
      "y": -9,
      "z": -1,
      "name": "Empty"
    },
    {
      "x": -2,
      "y": -8,
      "z": -1,
      "name": "Empty"
    },
    {
      "x": -2,
      "y": -7,
      "z": -1,
      "name": "Empty"
    },
    {
      "x": -2,
      "y": -6,
      "z": -1,
      "name": "Empty"
    },
    {
      "x": -2,
      "y": -5,
      "z": -1,
      "name": "Empty"
    },
    {
      "x": -2,
      "y": -4,
      "z": -1,
      "name": "Empty"
    },
    {
      "x": -2,
      "y": -3,
      "z": -1,
      "name": "Empty"
    },
    {
      "x": -2,
      "y": -2,
      "z": -1,
      "name": "Empty"
    },
    {
      "x": -2,
      "y": -1,
      "z": -1,
      "name": "Empty"
    },
    {
      "x": -2,
      "y": 0,
      "z": -1,
      "name": "Empty"
    },
    {
      "x": -2,
      "y": 1,
      "z": -1,
      "name": "Empty"
    },
    {
      "x": -2,
      "y": 2,
      "z": -1,
      "name": "Empty"
    },
    {
      "x": -2,
      "y": 3,
      "z": -1,
      "name": "Empty"
    },
    {
      "x": -2,
      "y": 4,
      "z": -1,
      "name": "Empty"
    },
    {
      "x": -2,
      "y": 5,
      "z": -1,
      "name": "Empty"
    },
    {
      "x": -2,
      "y": -23,
      "z": 0,
      "name": "Ore_Thorium_Sandstone"
    },
    {
      "x": -2,
      "y": -22,
      "z": 0,
      "name": "Rock_Sandstone"
    },
    {
      "x": -2,
      "y": -21,
      "z": 0,
      "name": "Rock_Sandstone"
    },
    {
      "x": -2,
      "y": -20,
      "z": 0,
      "name": "Rock_Sandstone"
    },
    {
      "x": -2,
      "y": -19,
      "z": 0,
      "name": "Empty"
    },
    {
      "x": -2,
      "y": -18,
      "z": 0,
      "name": "Empty"
    },
    {
      "x": -2,
      "y": -17,
      "z": 0,
      "name": "Empty"
    },
    {
      "x": -2,
      "y": -16,
      "z": 0,
      "name": "Empty"
    },
    {
      "x": -2,
      "y": -15,
      "z": 0,
      "name": "Empty"
    },
    {
      "x": -2,
      "y": -14,
      "z": 0,
      "name": "Rock_Crystal_Purple_Medium",
      "rotation": 4
    },
    {
      "x": -2,
      "y": -13,
      "z": 0,
      "name": "Rock_Crystal_Purple_Medium",
      "rotation": 7
    },
    {
      "x": -2,
      "y": -12,
      "z": 0,
      "name": "Rock_Crystal_Purple_Medium",
      "rotation": 4
    },
    {
      "x": -2,
      "y": -11,
      "z": 0,
      "name": "Empty"
    },
    {
      "x": -2,
      "y": -10,
      "z": 0,
      "name": "Rock_Crystal_Purple_Small",
      "rotation": 7
    },
    {
      "x": -2,
      "y": -9,
      "z": 0,
      "name": "Empty"
    },
    {
      "x": -2,
      "y": -8,
      "z": 0,
      "name": "Empty"
    },
    {
      "x": -2,
      "y": -7,
      "z": 0,
      "name": "Empty"
    },
    {
      "x": -2,
      "y": -6,
      "z": 0,
      "name": "Empty"
    },
    {
      "x": -2,
      "y": -5,
      "z": 0,
      "name": "Empty"
    },
    {
      "x": -2,
      "y": -4,
      "z": 0,
      "name": "Empty"
    },
    {
      "x": -2,
      "y": -3,
      "z": 0,
      "name": "Empty"
    },
    {
      "x": -2,
      "y": -2,
      "z": 0,
      "name": "Empty"
    },
    {
      "x": -2,
      "y": -1,
      "z": 0,
      "name": "Empty"
    },
    {
      "x": -2,
      "y": 0,
      "z": 0,
      "name": "Empty"
    },
    {
      "x": -2,
      "y": 1,
      "z": 0,
      "name": "Empty"
    },
    {
      "x": -2,
      "y": 2,
      "z": 0,
      "name": "Empty"
    },
    {
      "x": -2,
      "y": 3,
      "z": 0,
      "name": "Empty"
    },
    {
      "x": -2,
      "y": 4,
      "z": 0,
      "name": "Empty"
    },
    {
      "x": -2,
      "y": 5,
      "z": 0,
      "name": "Empty"
    },
    {
      "x": -2,
      "y": -23,
      "z": 1,
      "name": "Ore_Thorium_Sandstone"
    },
    {
      "x": -2,
      "y": -21,
      "z": 1,
      "name": "Rock_Sandstone"
    },
    {
      "x": -2,
      "y": -20,
      "z": 1,
      "name": "Rock_Sandstone"
    },
    {
      "x": -2,
      "y": -19,
      "z": 1,
      "name": "Rock_Sandstone"
    },
    {
      "x": -2,
      "y": -18,
      "z": 1,
      "name": "Rock_Sandstone"
    },
    {
      "x": -2,
      "y": -17,
      "z": 1,
      "name": "Empty"
    },
    {
      "x": -2,
      "y": -16,
      "z": 1,
      "name": "Empty"
    },
    {
      "x": -2,
      "y": -15,
      "z": 1,
      "name": "Empty"
    },
    {
      "x": -2,
      "y": -14,
      "z": 1,
      "name": "Empty"
    },
    {
      "x": -2,
      "y": -13,
      "z": 1,
      "name": "Empty"
    },
    {
      "x": -2,
      "y": -12,
      "z": 1,
      "name": "Empty"
    },
    {
      "x": -2,
      "y": -11,
      "z": 1,
      "name": "Empty"
    },
    {
      "x": -2,
      "y": -10,
      "z": 1,
      "name": "Empty"
    },
    {
      "x": -2,
      "y": -9,
      "z": 1,
      "name": "Empty"
    },
    {
      "x": -2,
      "y": -8,
      "z": 1,
      "name": "Empty"
    },
    {
      "x": -2,
      "y": -7,
      "z": 1,
      "name": "Empty"
    },
    {
      "x": -2,
      "y": -6,
      "z": 1,
      "name": "Empty"
    },
    {
      "x": -2,
      "y": -5,
      "z": 1,
      "name": "Empty"
    },
    {
      "x": -2,
      "y": -4,
      "z": 1,
      "name": "Empty"
    },
    {
      "x": -2,
      "y": -3,
      "z": 1,
      "name": "Empty"
    },
    {
      "x": -2,
      "y": -2,
      "z": 1,
      "name": "Empty"
    },
    {
      "x": -2,
      "y": -1,
      "z": 1,
      "name": "Empty"
    },
    {
      "x": -2,
      "y": 0,
      "z": 1,
      "name": "Empty"
    },
    {
      "x": -2,
      "y": 1,
      "z": 1,
      "name": "Empty"
    },
    {
      "x": -2,
      "y": 2,
      "z": 1,
      "name": "Empty"
    },
    {
      "x": -2,
      "y": 3,
      "z": 1,
      "name": "Empty"
    },
    {
      "x": -2,
      "y": 4,
      "z": 1,
      "name": "Empty"
    },
    {
      "x": -2,
      "y": 5,
      "z": 1,
      "name": "Empty"
    },
    {
      "x": -2,
      "y": -20,
      "z": 2,
      "name": "Rock_Sandstone"
    },
    {
      "x": -2,
      "y": -19,
      "z": 2,
      "name": "Rock_Sandstone"
    },
    {
      "x": -2,
      "y": -18,
      "z": 2,
      "name": "Rock_Sandstone"
    },
    {
      "x": -2,
      "y": -17,
      "z": 2,
      "name": "Rock_Sandstone"
    },
    {
      "x": -2,
      "y": -16,
      "z": 2,
      "name": "Rock_Sandstone"
    },
    {
      "x": -2,
      "y": -15,
      "z": 2,
      "name": "Rock_Sandstone"
    },
    {
      "x": -2,
      "y": -14,
      "z": 2,
      "name": "Rock_Sandstone"
    },
    {
      "x": -2,
      "y": -13,
      "z": 2,
      "name": "Empty"
    },
    {
      "x": -2,
      "y": -12,
      "z": 2,
      "name": "Empty"
    },
    {
      "x": -2,
      "y": -11,
      "z": 2,
      "name": "Empty"
    },
    {
      "x": -2,
      "y": -10,
      "z": 2,
      "name": "Empty"
    },
    {
      "x": -2,
      "y": -9,
      "z": 2,
      "name": "Empty"
    },
    {
      "x": -2,
      "y": -8,
      "z": 2,
      "name": "Empty"
    },
    {
      "x": -2,
      "y": -7,
      "z": 2,
      "name": "Empty"
    },
    {
      "x": -2,
      "y": -6,
      "z": 2,
      "name": "Empty"
    },
    {
      "x": -2,
      "y": -5,
      "z": 2,
      "name": "Empty"
    },
    {
      "x": -2,
      "y": -4,
      "z": 2,
      "name": "Empty"
    },
    {
      "x": -2,
      "y": -3,
      "z": 2,
      "name": "Empty"
    },
    {
      "x": -2,
      "y": -2,
      "z": 2,
      "name": "Empty"
    },
    {
      "x": -2,
      "y": -1,
      "z": 2,
      "name": "Empty"
    },
    {
      "x": -2,
      "y": 0,
      "z": 2,
      "name": "Empty"
    },
    {
      "x": -2,
      "y": 1,
      "z": 2,
      "name": "Empty"
    },
    {
      "x": -2,
      "y": 2,
      "z": 2,
      "name": "Empty"
    },
    {
      "x": -2,
      "y": 3,
      "z": 2,
      "name": "Empty"
    },
    {
      "x": -2,
      "y": 4,
      "z": 2,
      "name": "Empty"
    },
    {
      "x": -2,
      "y": 5,
      "z": 2,
      "name": "Empty"
    },
    {
      "x": -2,
      "y": -17,
      "z": 3,
      "name": "Rock_Sandstone"
    },
    {
      "x": -2,
      "y": -16,
      "z": 3,
      "name": "Rock_Sandstone"
    },
    {
      "x": -2,
      "y": -15,
      "z": 3,
      "name": "Rock_Sandstone"
    },
    {
      "x": -2,
      "y": -14,
      "z": 3,
      "name": "Rock_Sandstone"
    },
    {
      "x": -2,
      "y": -13,
      "z": 3,
      "name": "Rock_Sandstone"
    },
    {
      "x": -2,
      "y": -12,
      "z": 3,
      "name": "Rock_Sandstone"
    },
    {
      "x": -2,
      "y": -11,
      "z": 3,
      "name": "Rock_Sandstone"
    },
    {
      "x": -2,
      "y": -10,
      "z": 3,
      "name": "Rock_Sandstone"
    },
    {
      "x": -2,
      "y": -9,
      "z": 3,
      "name": "Rock_Sandstone"
    },
    {
      "x": -2,
      "y": -8,
      "z": 3,
      "name": "Rock_Sandstone_Stalactite_Large"
    },
    {
      "x": -2,
      "y": -7,
      "z": 3,
      "name": "Rock_Sandstone_Stalactite_Large",
      "filler": 1024
    },
    {
      "x": -2,
      "y": -6,
      "z": 3,
      "name": "Empty"
    },
    {
      "x": -2,
      "y": -5,
      "z": 3,
      "name": "Empty"
    },
    {
      "x": -2,
      "y": -4,
      "z": 3,
      "name": "Plant_Crop_Mushroom_Shelve_Yellow"
    },
    {
      "x": -2,
      "y": -3,
      "z": 3,
      "name": "Empty"
    },
    {
      "x": -2,
      "y": -2,
      "z": 3,
      "name": "Empty"
    },
    {
      "x": -2,
      "y": -1,
      "z": 3,
      "name": "Empty"
    },
    {
      "x": -2,
      "y": 0,
      "z": 3,
      "name": "Empty"
    },
    {
      "x": -2,
      "y": 1,
      "z": 3,
      "name": "Empty"
    },
    {
      "x": -2,
      "y": 2,
      "z": 3,
      "name": "Empty"
    },
    {
      "x": -2,
      "y": 3,
      "z": 3,
      "name": "Empty"
    },
    {
      "x": -2,
      "y": 4,
      "z": 3,
      "name": "Empty"
    },
    {
      "x": -2,
      "y": 5,
      "z": 3,
      "name": "Empty"
    },
    {
      "x": -2,
      "y": -12,
      "z": 4,
      "name": "Rock_Sandstone"
    },
    {
      "x": -2,
      "y": -11,
      "z": 4,
      "name": "Rock_Sandstone"
    },
    {
      "x": -2,
      "y": -10,
      "z": 4,
      "name": "Rock_Sandstone"
    },
    {
      "x": -2,
      "y": -9,
      "z": 4,
      "name": "Rock_Sandstone"
    },
    {
      "x": -2,
      "y": -8,
      "z": 4,
      "name": "Rock_Sandstone"
    },
    {
      "x": -2,
      "y": -7,
      "z": 4,
      "name": "Rock_Sandstone"
    },
    {
      "x": -2,
      "y": -6,
      "z": 4,
      "name": "Rock_Sandstone"
    },
    {
      "x": -2,
      "y": -5,
      "z": 4,
      "name": "Rock_Sandstone"
    },
    {
      "x": -2,
      "y": -4,
      "z": 4,
      "name": "Rock_Sandstone"
    },
    {
      "x": -2,
      "y": -3,
      "z": 4,
      "name": "Rock_Sandstone"
    },
    {
      "x": -2,
      "y": -2,
      "z": 4,
      "name": "Rock_Sandstone"
    },
    {
      "x": -2,
      "y": -1,
      "z": 4,
      "name": "Soil_Sand_Ashen"
    },
    {
      "x": -2,
      "y": 0,
      "z": 4,
      "name": "Soil_Sand_Ashen"
    },
    {
      "x": -2,
      "y": 1,
      "z": 4,
      "name": "Plant_Moss_Rug_Pink",
      "support": 15
    },
    {
      "x": -2,
      "y": 2,
      "z": 4,
      "name": "Empty"
    },
    {
      "x": -2,
      "y": 3,
      "z": 4,
      "name": "Empty"
    },
    {
      "x": -2,
      "y": 4,
      "z": 4,
      "name": "Empty"
    },
    {
      "x": -2,
      "y": 5,
      "z": 4,
      "name": "Empty"
    },
    {
      "x": -2,
      "y": -4,
      "z": 5,
      "name": "Ore_Copper_Sandstone"
    },
    {
      "x": -2,
      "y": -3,
      "z": 5,
      "name": "Rock_Sandstone"
    },
    {
      "x": -2,
      "y": -2,
      "z": 5,
      "name": "Rock_Sandstone"
    },
    {
      "x": -2,
      "y": -1,
      "z": 5,
      "name": "Rock_Sandstone"
    },
    {
      "x": -2,
      "y": 0,
      "z": 5,
      "name": "Rock_Sandstone"
    },
    {
      "x": -2,
      "y": 1,
      "z": 5,
      "name": "Soil_Sand_Ashen"
    },
    {
      "x": -2,
      "y": 2,
      "z": 5,
      "name": "Plant_Crop_Mushroom_Glowing_Violet"
    },
    {
      "x": -2,
      "y": 3,
      "z": 5,
      "name": "Empty"
    },
    {
      "x": -2,
      "y": 4,
      "z": 5,
      "name": "Empty"
    },
    {
      "x": -2,
      "y": 5,
      "z": 5,
      "name": "Empty"
    },
    {
      "x": -2,
      "y": 0,
      "z": 6,
      "name": "Rock_Sandstone"
    },
    {
      "x": -2,
      "y": 1,
      "z": 6,
      "name": "Soil_Sand_Ashen"
    },
    {
      "x": -2,
      "y": 2,
      "z": 6,
      "name": "Empty"
    },
    {
      "x": -2,
      "y": 3,
      "z": 6,
      "name": "Empty"
    },
    {
      "x": -2,
      "y": 4,
      "z": 6,
      "name": "Empty"
    },
    {
      "x": -2,
      "y": 5,
      "z": 6,
      "name": "Empty"
    },
    {
      "x": -1,
      "y": -7,
      "z": -7,
      "name": "Rock_Sandstone"
    },
    {
      "x": -1,
      "y": -6,
      "z": -7,
      "name": "Rock_Sandstone"
    },
    {
      "x": -1,
      "y": -5,
      "z": -7,
      "name": "Rock_Sandstone"
    },
    {
      "x": -1,
      "y": -4,
      "z": -7,
      "name": "Rock_Sandstone"
    },
    {
      "x": -1,
      "y": -3,
      "z": -7,
      "name": "Rock_Sandstone"
    },
    {
      "x": -1,
      "y": -2,
      "z": -7,
      "name": "Rock_Sandstone"
    },
    {
      "x": -1,
      "y": -1,
      "z": -7,
      "name": "Rock_Sandstone"
    },
    {
      "x": -1,
      "y": 0,
      "z": -7,
      "name": "Rock_Sandstone"
    },
    {
      "x": -1,
      "y": 1,
      "z": -7,
      "name": "Soil_Sand_Ashen"
    },
    {
      "x": -1,
      "y": 2,
      "z": -7,
      "name": "Plant_Moss_Rug_Pink",
      "support": 15
    },
    {
      "x": -1,
      "y": 3,
      "z": -7,
      "name": "Empty"
    },
    {
      "x": -1,
      "y": 4,
      "z": -7,
      "name": "Empty"
    },
    {
      "x": -1,
      "y": 5,
      "z": -7,
      "name": "Empty"
    },
    {
      "x": -1,
      "y": -15,
      "z": -6,
      "name": "Ore_Thorium_Sandstone"
    },
    {
      "x": -1,
      "y": -14,
      "z": -6,
      "name": "Rock_Sandstone"
    },
    {
      "x": -1,
      "y": -13,
      "z": -6,
      "name": "Rock_Sandstone"
    },
    {
      "x": -1,
      "y": -12,
      "z": -6,
      "name": "Rock_Sandstone"
    },
    {
      "x": -1,
      "y": -11,
      "z": -6,
      "name": "Rock_Sandstone"
    },
    {
      "x": -1,
      "y": -10,
      "z": -6,
      "name": "Rock_Sandstone"
    },
    {
      "x": -1,
      "y": -9,
      "z": -6,
      "name": "Rock_Sandstone"
    },
    {
      "x": -1,
      "y": -8,
      "z": -6,
      "name": "Rock_Sandstone"
    },
    {
      "x": -1,
      "y": -7,
      "z": -6,
      "name": "Rock_Sandstone"
    },
    {
      "x": -1,
      "y": -6,
      "z": -6,
      "name": "Rock_Sandstone"
    },
    {
      "x": -1,
      "y": -5,
      "z": -6,
      "name": "Rock_Sandstone"
    },
    {
      "x": -1,
      "y": -4,
      "z": -6,
      "name": "Rock_Sandstone"
    },
    {
      "x": -1,
      "y": -3,
      "z": -6,
      "name": "Soil_Sand_Ashen"
    },
    {
      "x": -1,
      "y": -2,
      "z": -6,
      "name": "Soil_Sand_Ashen"
    },
    {
      "x": -1,
      "y": -1,
      "z": -6,
      "name": "Plant_Crop_Mushroom_Glowing_Purple"
    },
    {
      "x": -1,
      "y": 0,
      "z": -6,
      "name": "Empty"
    },
    {
      "x": -1,
      "y": 1,
      "z": -6,
      "name": "Empty"
    },
    {
      "x": -1,
      "y": 2,
      "z": -6,
      "name": "Empty"
    },
    {
      "x": -1,
      "y": 3,
      "z": -6,
      "name": "Empty"
    },
    {
      "x": -1,
      "y": 4,
      "z": -6,
      "name": "Empty"
    },
    {
      "x": -1,
      "y": 5,
      "z": -6,
      "name": "Empty"
    },
    {
      "x": -1,
      "y": -18,
      "z": -5,
      "name": "Rock_Sandstone"
    },
    {
      "x": -1,
      "y": -17,
      "z": -5,
      "name": "Rock_Sandstone"
    },
    {
      "x": -1,
      "y": -16,
      "z": -5,
      "name": "Rock_Sandstone"
    },
    {
      "x": -1,
      "y": -15,
      "z": -5,
      "name": "Rock_Sandstone"
    },
    {
      "x": -1,
      "y": -14,
      "z": -5,
      "name": "Rock_Sandstone"
    },
    {
      "x": -1,
      "y": -13,
      "z": -5,
      "name": "Rock_Sandstone"
    },
    {
      "x": -1,
      "y": -12,
      "z": -5,
      "name": "Rock_Sandstone"
    },
    {
      "x": -1,
      "y": -11,
      "z": -5,
      "name": "Soil_Sand_Ashen"
    },
    {
      "x": -1,
      "y": -10,
      "z": -5,
      "name": "Plant_Moss_Rug_Pink",
      "support": 15
    },
    {
      "x": -1,
      "y": -9,
      "z": -5,
      "name": "Empty"
    },
    {
      "x": -1,
      "y": -8,
      "z": -5,
      "name": "Empty"
    },
    {
      "x": -1,
      "y": -7,
      "z": -5,
      "name": "Empty"
    },
    {
      "x": -1,
      "y": -6,
      "z": -5,
      "name": "Empty"
    },
    {
      "x": -1,
      "y": -5,
      "z": -5,
      "name": "Empty"
    },
    {
      "x": -1,
      "y": -4,
      "z": -5,
      "name": "Empty"
    },
    {
      "x": -1,
      "y": -3,
      "z": -5,
      "name": "Empty"
    },
    {
      "x": -1,
      "y": -2,
      "z": -5,
      "name": "Empty"
    },
    {
      "x": -1,
      "y": -1,
      "z": -5,
      "name": "Empty"
    },
    {
      "x": -1,
      "y": 0,
      "z": -5,
      "name": "Empty"
    },
    {
      "x": -1,
      "y": 1,
      "z": -5,
      "name": "Empty"
    },
    {
      "x": -1,
      "y": 2,
      "z": -5,
      "name": "Empty"
    },
    {
      "x": -1,
      "y": 3,
      "z": -5,
      "name": "Empty"
    },
    {
      "x": -1,
      "y": 4,
      "z": -5,
      "name": "Empty"
    },
    {
      "x": -1,
      "y": 5,
      "z": -5,
      "name": "Empty"
    },
    {
      "x": -1,
      "y": -21,
      "z": -4,
      "name": "Rock_Sandstone"
    },
    {
      "x": -1,
      "y": -20,
      "z": -4,
      "name": "Rock_Sandstone"
    },
    {
      "x": -1,
      "y": -19,
      "z": -4,
      "name": "Rock_Sandstone"
    },
    {
      "x": -1,
      "y": -18,
      "z": -4,
      "name": "Rock_Sandstone"
    },
    {
      "x": -1,
      "y": -17,
      "z": -4,
      "name": "Rock_Sandstone"
    },
    {
      "x": -1,
      "y": -16,
      "z": -4,
      "name": "Rock_Sandstone_Stalactite_Small"
    },
    {
      "x": -1,
      "y": -15,
      "z": -4,
      "name": "Empty"
    },
    {
      "x": -1,
      "y": -14,
      "z": -4,
      "name": "Empty"
    },
    {
      "x": -1,
      "y": -13,
      "z": -4,
      "name": "Empty"
    },
    {
      "x": -1,
      "y": -12,
      "z": -4,
      "name": "Empty"
    },
    {
      "x": -1,
      "y": -11,
      "z": -4,
      "name": "Empty"
    },
    {
      "x": -1,
      "y": -10,
      "z": -4,
      "name": "Empty"
    },
    {
      "x": -1,
      "y": -9,
      "z": -4,
      "name": "Empty"
    },
    {
      "x": -1,
      "y": -8,
      "z": -4,
      "name": "Empty"
    },
    {
      "x": -1,
      "y": -7,
      "z": -4,
      "name": "Empty"
    },
    {
      "x": -1,
      "y": -6,
      "z": -4,
      "name": "Empty"
    },
    {
      "x": -1,
      "y": -5,
      "z": -4,
      "name": "Empty"
    },
    {
      "x": -1,
      "y": -4,
      "z": -4,
      "name": "Empty"
    },
    {
      "x": -1,
      "y": -3,
      "z": -4,
      "name": "Empty"
    },
    {
      "x": -1,
      "y": -2,
      "z": -4,
      "name": "Empty"
    },
    {
      "x": -1,
      "y": -1,
      "z": -4,
      "name": "Empty"
    },
    {
      "x": -1,
      "y": 0,
      "z": -4,
      "name": "Empty"
    },
    {
      "x": -1,
      "y": 1,
      "z": -4,
      "name": "Empty"
    },
    {
      "x": -1,
      "y": 2,
      "z": -4,
      "name": "Empty"
    },
    {
      "x": -1,
      "y": 3,
      "z": -4,
      "name": "Empty"
    },
    {
      "x": -1,
      "y": 4,
      "z": -4,
      "name": "Empty"
    },
    {
      "x": -1,
      "y": 5,
      "z": -4,
      "name": "Empty"
    },
    {
      "x": -1,
      "y": -23,
      "z": -3,
      "name": "Ore_Thorium_Sandstone"
    },
    {
      "x": -1,
      "y": -22,
      "z": -3,
      "name": "Rock_Sandstone"
    },
    {
      "x": -1,
      "y": -21,
      "z": -3,
      "name": "Rock_Sandstone"
    },
    {
      "x": -1,
      "y": -20,
      "z": -3,
      "name": "Rock_Sandstone"
    },
    {
      "x": -1,
      "y": -19,
      "z": -3,
      "name": "Rock_Gem_Voidstone"
    },
    {
      "x": -1,
      "y": -18,
      "z": -3,
      "name": "Empty"
    },
    {
      "x": -1,
      "y": -17,
      "z": -3,
      "name": "Empty"
    },
    {
      "x": -1,
      "y": -16,
      "z": -3,
      "name": "Empty"
    },
    {
      "x": -1,
      "y": -15,
      "z": -3,
      "name": "Empty"
    },
    {
      "x": -1,
      "y": -14,
      "z": -3,
      "name": "Empty"
    },
    {
      "x": -1,
      "y": -13,
      "z": -3,
      "name": "Rock_Crystal_Purple_Medium",
      "rotation": 6
    },
    {
      "x": -1,
      "y": -12,
      "z": -3,
      "name": "Empty"
    },
    {
      "x": -1,
      "y": -11,
      "z": -3,
      "name": "Empty"
    },
    {
      "x": -1,
      "y": -10,
      "z": -3,
      "name": "Empty"
    },
    {
      "x": -1,
      "y": -9,
      "z": -3,
      "name": "Empty"
    },
    {
      "x": -1,
      "y": -8,
      "z": -3,
      "name": "Empty"
    },
    {
      "x": -1,
      "y": -7,
      "z": -3,
      "name": "Empty"
    },
    {
      "x": -1,
      "y": -6,
      "z": -3,
      "name": "Empty"
    },
    {
      "x": -1,
      "y": -5,
      "z": -3,
      "name": "Empty"
    },
    {
      "x": -1,
      "y": -4,
      "z": -3,
      "name": "Empty"
    },
    {
      "x": -1,
      "y": -3,
      "z": -3,
      "name": "Empty"
    },
    {
      "x": -1,
      "y": -2,
      "z": -3,
      "name": "Empty"
    },
    {
      "x": -1,
      "y": -1,
      "z": -3,
      "name": "Empty"
    },
    {
      "x": -1,
      "y": 0,
      "z": -3,
      "name": "Empty"
    },
    {
      "x": -1,
      "y": 1,
      "z": -3,
      "name": "Empty"
    },
    {
      "x": -1,
      "y": 2,
      "z": -3,
      "name": "Empty"
    },
    {
      "x": -1,
      "y": 3,
      "z": -3,
      "name": "Empty"
    },
    {
      "x": -1,
      "y": 4,
      "z": -3,
      "name": "Empty"
    },
    {
      "x": -1,
      "y": 5,
      "z": -3,
      "name": "Empty"
    },
    {
      "x": -1,
      "y": -23,
      "z": -2,
      "name": "Rock_Sandstone"
    },
    {
      "x": -1,
      "y": -22,
      "z": -2,
      "name": "Rock_Sandstone"
    },
    {
      "x": -1,
      "y": -21,
      "z": -2,
      "name": "Rock_Sandstone"
    },
    {
      "x": -1,
      "y": -20,
      "z": -2,
      "name": "Rock_Crystal_Purple_Block"
    },
    {
      "x": -1,
      "y": -19,
      "z": -2,
      "name": "Rock_Crystal_Purple_Block"
    },
    {
      "x": -1,
      "y": -18,
      "z": -2,
      "name": "Rock_Crystal_Purple_Block"
    },
    {
      "x": -1,
      "y": -17,
      "z": -2,
      "name": "Rock_Crystal_Purple_Block"
    },
    {
      "x": -1,
      "y": -16,
      "z": -2,
      "name": "Rock_Crystal_Purple_Block"
    },
    {
      "x": -1,
      "y": -15,
      "z": -2,
      "name": "Rock_Crystal_Purple_Block"
    },
    {
      "x": -1,
      "y": -14,
      "z": -2,
      "name": "Rock_Crystal_Purple_Block"
    },
    {
      "x": -1,
      "y": -13,
      "z": -2,
      "name": "Rock_Crystal_Purple_Block"
    },
    {
      "x": -1,
      "y": -12,
      "z": -2,
      "name": "Rock_Crystal_Purple_Block"
    },
    {
      "x": -1,
      "y": -11,
      "z": -2,
      "name": "Rock_Crystal_Purple_Block"
    },
    {
      "x": -1,
      "y": -10,
      "z": -2,
      "name": "Rock_Crystal_Purple_Large"
    },
    {
      "x": -1,
      "y": -9,
      "z": -2,
      "name": "Rock_Crystal_Purple_Small",
      "rotation": 6
    },
    {
      "x": -1,
      "y": -8,
      "z": -2,
      "name": "Empty"
    },
    {
      "x": -1,
      "y": -7,
      "z": -2,
      "name": "Empty"
    },
    {
      "x": -1,
      "y": -6,
      "z": -2,
      "name": "Empty"
    },
    {
      "x": -1,
      "y": -5,
      "z": -2,
      "name": "Empty"
    },
    {
      "x": -1,
      "y": -4,
      "z": -2,
      "name": "Empty"
    },
    {
      "x": -1,
      "y": -3,
      "z": -2,
      "name": "Empty"
    },
    {
      "x": -1,
      "y": -2,
      "z": -2,
      "name": "Empty"
    },
    {
      "x": -1,
      "y": -1,
      "z": -2,
      "name": "Empty"
    },
    {
      "x": -1,
      "y": 0,
      "z": -2,
      "name": "Empty"
    },
    {
      "x": -1,
      "y": 1,
      "z": -2,
      "name": "Empty"
    },
    {
      "x": -1,
      "y": 2,
      "z": -2,
      "name": "Empty"
    },
    {
      "x": -1,
      "y": 3,
      "z": -2,
      "name": "Empty"
    },
    {
      "x": -1,
      "y": 4,
      "z": -2,
      "name": "Empty"
    },
    {
      "x": -1,
      "y": 5,
      "z": -2,
      "name": "Empty"
    },
    {
      "x": -1,
      "y": -23,
      "z": -1,
      "name": "Rock_Sandstone"
    },
    {
      "x": -1,
      "y": -22,
      "z": -1,
      "name": "Rock_Sandstone"
    },
    {
      "x": -1,
      "y": -21,
      "z": -1,
      "name": "Rock_Crystal_Purple_Block"
    },
    {
      "x": -1,
      "y": -20,
      "z": -1,
      "name": "Rock_Crystal_Purple_Block"
    },
    {
      "x": -1,
      "y": -19,
      "z": -1,
      "name": "Rock_Crystal_Purple_Block"
    },
    {
      "x": -1,
      "y": -18,
      "z": -1,
      "name": "Rock_Crystal_Purple_Block"
    },
    {
      "x": -1,
      "y": -17,
      "z": -1,
      "name": "Rock_Crystal_Purple_Block"
    },
    {
      "x": -1,
      "y": -16,
      "z": -1,
      "name": "Rock_Crystal_Purple_Block"
    },
    {
      "x": -1,
      "y": -15,
      "z": -1,
      "name": "Rock_Crystal_Purple_Block"
    },
    {
      "x": -1,
      "y": -14,
      "z": -1,
      "name": "Rock_Crystal_Purple_Block"
    },
    {
      "x": -1,
      "y": -13,
      "z": -1,
      "name": "Rock_Crystal_Purple_Block"
    },
    {
      "x": -1,
      "y": -12,
      "z": -1,
      "name": "Rock_Crystal_Purple_Block"
    },
    {
      "x": -1,
      "y": -11,
      "z": -1,
      "name": "Rock_Crystal_Purple_Block"
    },
    {
      "x": -1,
      "y": -10,
      "z": -1,
      "name": "Rock_Crystal_Purple_Block"
    },
    {
      "x": -1,
      "y": -9,
      "z": -1,
      "name": "Rock_Crystal_Purple_Block"
    },
    {
      "x": -1,
      "y": -8,
      "z": -1,
      "name": "Rock_Crystal_Purple_Large"
    },
    {
      "x": -1,
      "y": -7,
      "z": -1,
      "name": "Rock_Crystal_Purple_Large",
      "rotation": 7
    },
    {
      "x": -1,
      "y": -6,
      "z": -1,
      "name": "Empty"
    },
    {
      "x": -1,
      "y": -5,
      "z": -1,
      "name": "Empty"
    },
    {
      "x": -1,
      "y": -4,
      "z": -1,
      "name": "Empty"
    },
    {
      "x": -1,
      "y": -3,
      "z": -1,
      "name": "Empty"
    },
    {
      "x": -1,
      "y": -2,
      "z": -1,
      "name": "Empty"
    },
    {
      "x": -1,
      "y": -1,
      "z": -1,
      "name": "Empty"
    },
    {
      "x": -1,
      "y": 0,
      "z": -1,
      "name": "Empty"
    },
    {
      "x": -1,
      "y": 1,
      "z": -1,
      "name": "Empty"
    },
    {
      "x": -1,
      "y": 2,
      "z": -1,
      "name": "Empty"
    },
    {
      "x": -1,
      "y": 3,
      "z": -1,
      "name": "Empty"
    },
    {
      "x": -1,
      "y": 4,
      "z": -1,
      "name": "Empty"
    },
    {
      "x": -1,
      "y": 5,
      "z": -1,
      "name": "Empty"
    },
    {
      "x": -1,
      "y": -23,
      "z": 0,
      "name": "Rock_Sandstone"
    },
    {
      "x": -1,
      "y": -22,
      "z": 0,
      "name": "Rock_Sandstone"
    },
    {
      "x": -1,
      "y": -21,
      "z": 0,
      "name": "Rock_Sandstone"
    },
    {
      "x": -1,
      "y": -20,
      "z": 0,
      "name": "Rock_Crystal_Purple_Block"
    },
    {
      "x": -1,
      "y": -19,
      "z": 0,
      "name": "Rock_Crystal_Purple_Block"
    },
    {
      "x": -1,
      "y": -18,
      "z": 0,
      "name": "Rock_Crystal_Purple_Block"
    },
    {
      "x": -1,
      "y": -17,
      "z": 0,
      "name": "Rock_Crystal_Purple_Block"
    },
    {
      "x": -1,
      "y": -16,
      "z": 0,
      "name": "Rock_Crystal_Purple_Block"
    },
    {
      "x": -1,
      "y": -15,
      "z": 0,
      "name": "Rock_Crystal_Purple_Block"
    },
    {
      "x": -1,
      "y": -14,
      "z": 0,
      "name": "Rock_Crystal_Purple_Block"
    },
    {
      "x": -1,
      "y": -13,
      "z": 0,
      "name": "Rock_Crystal_Purple_Block"
    },
    {
      "x": -1,
      "y": -12,
      "z": 0,
      "name": "Rock_Crystal_Purple_Block"
    },
    {
      "x": -1,
      "y": -11,
      "z": 0,
      "name": "Rock_Crystal_Purple_Block"
    },
    {
      "x": -1,
      "y": -10,
      "z": 0,
      "name": "Rock_Crystal_Purple_Block"
    },
    {
      "x": -1,
      "y": -9,
      "z": 0,
      "name": "Rock_Crystal_Purple_Small"
    },
    {
      "x": -1,
      "y": -8,
      "z": 0,
      "name": "Empty"
    },
    {
      "x": -1,
      "y": -7,
      "z": 0,
      "name": "Empty"
    },
    {
      "x": -1,
      "y": -6,
      "z": 0,
      "name": "Empty"
    },
    {
      "x": -1,
      "y": -5,
      "z": 0,
      "name": "Empty"
    },
    {
      "x": -1,
      "y": -4,
      "z": 0,
