{
  "version": 8,
  "blockIdVersion": 11,
  "anchorX": 0,
  "anchorY": 0,
  "anchorZ": 0,
  "blocks": [
    {
      "x": -10,
      "y": 0,
      "z": -8,
      "name": "Soil_Sand_Ashen"
    },
    {
      "x": -10,
      "y": 1,
      "z": -8,
      "name": "Soil_Sand_Ashen"
    },
    {
      "x": -10,
      "y": 0,
      "z": -7,
      "name": "Soil_Sand_Ashen"
    },
    {
      "x": -10,
      "y": 1,
      "z": -7,
      "name": "Soil_Sand_Ashen"
    },
    {
      "x": -10,
      "y": 2,
      "z": -7,
      "name": "Soil_Ash"
    },
    {
      "x": -10,
      "y": 0,
      "z": -6,
      "name": "Soil_Sand_Ashen"
    },
    {
      "x": -10,
      "y": 1,
      "z": -6,
      "name": "Soil_Sand_Ashen"
    },
    {
      "x": -10,
      "y": 2,
      "z": -6,
      "name": "Soil_Ash"
    },
    {
      "x": -10,
      "y": 0,
      "z": -5,
      "name": "Soil_Sand_Ashen"
    },
    {
      "x": -10,
      "y": 1,
      "z": -5,
      "name": "Soil_Sand_Ashen"
    },
    {
      "x": -10,
      "y": 2,
      "z": -5,
      "name": "Soil_Ash"
    },
    {
      "x": -10,
      "y": 0,
      "z": -4,
      "name": "Soil_Sand_Ashen"
    },
    {
      "x": -10,
      "y": 1,
      "z": -4,
      "name": "Soil_Sand_Ashen"
    },
    {
      "x": -10,
      "y": 0,
      "z": 3,
      "name": "Soil_Sand_Ashen"
    },
    {
      "x": -10,
      "y": 1,
      "z": 3,
      "name": "Soil_Sand_Ashen"
    },
    {
      "x": -10,
      "y": 0,
      "z": 4,
      "name": "Soil_Sand_Ashen"
    },
    {
      "x": -10,
      "y": 1,
      "z": 4,
      "name": "Soil_Sand_Ashen"
    },
    {
      "x": -10,
      "y": 2,
      "z": 4,
      "name": "Soil_Ash"
    },
    {
      "x": -10,
      "y": 0,
      "z": 5,
      "name": "Soil_Sand_Ashen"
    },
    {
      "x": -10,
      "y": 1,
      "z": 5,
      "name": "Soil_Sand_Ashen"
    },
    {
      "x": -10,
      "y": 2,
      "z": 5,
      "name": "Soil_Sand_Ashen"
    },
    {
      "x": -10,
      "y": 3,
      "z": 5,
      "name": "Soil_Ash"
    },
    {
      "x": -10,
      "y": 0,
      "z": 6,
      "name": "Soil_Sand_Ashen"
    },
    {
      "x": -10,
      "y": 1,
      "z": 6,
      "name": "Soil_Sand_Ashen"
    },
    {
      "x": -10,
      "y": 2,
      "z": 6,
      "name": "Soil_Sand_Ashen"
    },
    {
      "x": -10,
      "y": 3,
      "z": 6,
      "name": "Soil_Ash"
    },
    {
      "x": -10,
      "y": 0,
      "z": 7,
      "name": "Soil_Sand_Ashen"
    },
    {
      "x": -10,
      "y": 1,
      "z": 7,
      "name": "Soil_Sand_Ashen"
    },
    {
      "x": -9,
      "y": 0,
      "z": -10,
      "name": "Soil_Sand_Ashen"
    },
    {
      "x": -9,
      "y": 0,
      "z": -9,
      "name": "Soil_Sand_Ashen"
    },
    {
      "x": -9,
      "y": 1,
      "z": -9,
      "name": "Soil_Sand_Ashen"
    },
    {
      "x": -9,
      "y": 2,
      "z": -9,
      "name": "Soil_Sand_Ashen"
    },
    {
      "x": -9,
      "y": 0,
      "z": -8,
      "name": "Soil_Sand_Ashen"
    },
    {
      "x": -9,
      "y": 1,
      "z": -8,
      "name": "Soil_Sand_Ashen"
    },
    {
      "x": -9,
      "y": 2,
      "z": -8,
      "name": "Soil_Mud"
    },
    {
      "x": -9,
      "y": 3,
      "z": -8,
      "name": "Soil_Mud"
    },
    {
      "x": -9,
      "y": 0,
      "z": -7,
      "name": "Soil_Sand_Ashen"
    },
    {
      "x": -9,
      "y": 1,
      "z": -7,
      "name": "Soil_Sand_Ashen"
    },
    {
      "x": -9,
      "y": 2,
      "z": -7,
      "name": "Soil_Mud"
    },
    {
      "x": -9,
      "y": 3,
      "z": -7,
      "name": "Soil_Ash"
    },
    {
      "x": -9,
      "y": 0,
      "z": -6,
      "name": "Soil_Sand_Ashen"
    },
    {
      "x": -9,
      "y": 1,
      "z": -6,
      "name": "Soil_Sand_Ashen"
    },
    {
      "x": -9,
      "y": 2,
      "z": -6,
      "name": "Soil_Mud"
    },
    {
      "x": -9,
      "y": 3,
      "z": -6,
      "name": "Soil_Ash"
    },
    {
      "x": -9,
      "y": 4,
      "z": -6,
      "name": "Soil_Ash"
    },
    {
      "x": -9,
      "y": 5,
      "z": -6,
      "name": "Plant_Crop_Wheat_Stage_4_Burnt"
    },
    {
      "x": -9,
      "y": 6,
      "z": -6,
      "name": "Plant_Crop_Wheat_Stage_4_Burnt",
      "filler": 1024
    },
    {
      "x": -9,
      "y": 0,
      "z": -5,
      "name": "Soil_Sand_Ashen"
    },
    {
      "x": -9,
      "y": 1,
      "z": -5,
      "name": "Soil_Sand_Ashen"
    },
    {
      "x": -9,
      "y": 2,
      "z": -5,
      "name": "Soil_Mud"
    },
    {
      "x": -9,
      "y": 3,
      "z": -5,
      "name": "Soil_Mud"
    },
    {
      "x": -9,
      "y": 4,
      "z": -5,
      "name": "Plant_Crop_Wheat_Stage_4_Burnt"
    },
    {
      "x": -9,
      "y": 5,
      "z": -5,
      "name": "Plant_Crop_Wheat_Stage_4_Burnt",
      "filler": 1024
    },
    {
      "x": -9,
      "y": 0,
      "z": -4,
      "name": "Soil_Sand_Ashen"
    },
    {
      "x": -9,
      "y": 1,
      "z": -4,
      "name": "Soil_Sand_Ashen"
    },
    {
      "x": -9,
      "y": 2,
      "z": -4,
      "name": "Soil_Mud"
    },
    {
      "x": -9,
      "y": 3,
      "z": -4,
      "name": "Soil_Mud"
    },
    {
      "x": -9,
      "y": 0,
      "z": -3,
      "name": "Soil_Sand_Ashen"
    },
    {
      "x": -9,
      "y": 1,
      "z": -3,
      "name": "Soil_Sand_Ashen"
    },
    {
      "x": -9,
      "y": 2,
      "z": -3,
      "name": "Soil_Mud"
    },
    {
      "x": -9,
      "y": 3,
      "z": -3,
      "name": "Plant_Bush_Dead_Tall"
    },
    {
      "x": -9,
      "y": 0,
      "z": -2,
      "name": "Soil_Sand_Ashen"
    },
    {
      "x": -9,
      "y": 0,
      "z": 1,
      "name": "Soil_Sand_Ashen"
    },
    {
      "x": -9,
      "y": 0,
      "z": 2,
      "name": "Soil_Sand_Ashen"
    },
    {
      "x": -9,
      "y": 1,
      "z": 2,
      "name": "Soil_Sand_Ashen"
    },
    {
      "x": -9,
      "y": 2,
      "z": 2,
      "name": "Soil_Ash"
    },
    {
      "x": -9,
      "y": 0,
      "z": 3,
      "name": "Soil_Sand_Ashen"
    },
    {
      "x": -9,
      "y": 1,
      "z": 3,
      "name": "Soil_Sand_Ashen"
    },
    {
      "x": -9,
      "y": 2,
      "z": 3,
      "name": "Soil_Ash"
    },
    {
      "x": -9,
      "y": 3,
      "z": 3,
      "name": "Soil_Ash"
    },
    {
      "x": -9,
      "y": 0,
      "z": 4,
      "name": "Soil_Sand_Ashen"
    },
    {
      "x": -9,
      "y": 1,
      "z": 4,
      "name": "Soil_Sand_Ashen"
    },
    {
      "x": -9,
      "y": 2,
      "z": 4,
      "name": "Soil_Mud"
    },
    {
      "x": -9,
      "y": 3,
      "z": 4,
      "name": "Soil_Ash"
    },
    {
      "x": -9,
      "y": 0,
      "z": 5,
      "name": "Soil_Sand_Ashen"
    },
    {
      "x": -9,
      "y": 1,
      "z": 5,
      "name": "Soil_Sand_Ashen"
    },
    {
      "x": -9,
      "y": 2,
      "z": 5,
      "name": "Soil_Mud"
    },
    {
      "x": -9,
      "y": 3,
      "z": 5,
      "name": "Soil_Mud"
    },
    {
      "x": -9,
      "y": 4,
      "z": 5,
      "name": "Soil_Mud"
    },
    {
      "x": -9,
      "y": 0,
      "z": 6,
      "name": "Soil_Sand_Ashen"
    },
    {
      "x": -9,
      "y": 1,
      "z": 6,
      "name": "Soil_Sand_Ashen"
    },
    {
      "x": -9,
      "y": 2,
      "z": 6,
      "name": "Soil_Mud"
    },
    {
      "x": -9,
      "y": 3,
      "z": 6,
      "name": "Soil_Mud"
    },
    {
      "x": -9,
      "y": 4,
      "z": 6,
      "name": "Soil_Ash"
    },
    {
      "x": -9,
      "y": 0,
      "z": 7,
      "name": "Soil_Sand_Ashen"
    },
    {
      "x": -9,
      "y": 1,
      "z": 7,
      "name": "Soil_Sand_Ashen"
    },
    {
      "x": -9,
      "y": 2,
      "z": 7,
      "name": "Soil_Sand_Ashen"
    },
    {
      "x": -9,
      "y": 3,
      "z": 7,
      "name": "Soil_Sand_Ashen"
    },
    {
      "x": -9,
      "y": 4,
      "z": 7,
      "name": "Soil_Ash"
    },
    {
      "x": -9,
      "y": 5,
      "z": 7,
      "name": "Plant_Bush_Dead_Tall"
    },
    {
      "x": -9,
      "y": 0,
      "z": 8,
      "name": "Soil_Sand_Ashen"
    },
    {
      "x": -9,
      "y": 1,
      "z": 8,
      "name": "Soil_Sand_Ashen"
    },
    {
      "x": -9,
      "y": 2,
      "z": 8,
      "name": "Soil_Sand_Ashen"
    },
    {
      "x": -9,
      "y": 3,
      "z": 8,
      "name": "Soil_Ash"
    },
    {
      "x": -9,
      "y": 0,
      "z": 9,
      "name": "Soil_Sand_Ashen"
    },
    {
      "x": -8,
      "y": 0,
      "z": -11,
      "name": "Soil_Sand_Ashen"
    },
    {
      "x": -8,
      "y": 0,
      "z": -10,
      "name": "Soil_Sand_Ashen"
    },
    {
      "x": -8,
      "y": 1,
      "z": -10,
      "name": "Soil_Sand_Ashen"
    },
    {
      "x": -8,
      "y": 2,
      "z": -10,
      "name": "Soil_Mud"
    },
    {
      "x": -8,
      "y": 3,
      "z": -10,
      "name": "Soil_Mud"
    },
    {
      "x": -8,
      "y": 0,
      "z": -9,
      "name": "Soil_Sand_Ashen"
    },
    {
      "x": -8,
      "y": 1,
      "z": -9,
      "name": "Soil_Sand_Ashen"
    },
    {
      "x": -8,
      "y": 2,
      "z": -9,
      "name": "Soil_Mud"
    },
    {
      "x": -8,
      "y": 3,
      "z": -9,
      "name": "Soil_Mud"
    },
    {
      "x": -8,
      "y": 4,
      "z": -9,
      "name": "Soil_Mud"
    },
    {
      "x": -8,
      "y": 0,
      "z": -8,
      "name": "Soil_Sand_Ashen"
    },
    {
      "x": -8,
      "y": 1,
      "z": -8,
      "name": "Soil_Sand_Ashen"
    },
    {
      "x": -8,
      "y": 2,
      "z": -8,
      "name": "Soil_Mud"
    },
    {
      "x": -8,
      "y": 3,
      "z": -8,
      "name": "Soil_Mud"
    },
    {
      "x": -8,
      "y": 4,
      "z": -8,
      "name": "Soil_Mud"
    },
    {
      "x": -8,
      "y": 5,
      "z": -8,
      "name": "Plant_Bush_Dead_Tall"
    },
    {
      "x": -8,
      "y": 0,
      "z": -7,
      "name": "Soil_Sand_Ashen"
    },
    {
      "x": -8,
      "y": 1,
      "z": -7,
      "name": "Soil_Sand_Ashen"
    },
    {
      "x": -8,
      "y": 2,
      "z": -7,
      "name": "Soil_Mud"
    },
    {
      "x": -8,
      "y": 3,
      "z": -7,
      "name": "Soil_Mud"
    },
    {
      "x": -8,
      "y": 4,
      "z": -7,
      "name": "Soil_Ash"
    },
    {
      "x": -8,
      "y": 5,
      "z": -7,
      "name": "Plant_Crop_Wheat_Stage_4_Burnt"
    },
    {
      "x": -8,
      "y": 6,
      "z": -7,
      "name": "Plant_Crop_Wheat_Stage_4_Burnt",
      "filler": 1024
    },
    {
      "x": -8,
      "y": 0,
      "z": -6,
      "name": "Soil_Sand_Ashen"
    },
    {
      "x": -8,
      "y": 1,
      "z": -6,
      "name": "Soil_Sand_Ashen"
    },
    {
      "x": -8,
      "y": 2,
      "z": -6,
      "name": "Soil_Mud"
    },
    {
      "x": -8,
      "y": 3,
      "z": -6,
      "name": "Soil_Mud"
    },
    {
      "x": -8,
      "y": 4,
      "z": -6,
      "name": "Soil_Mud"
    },
    {
      "x": -8,
      "y": 5,
      "z": -6,
      "name": "Soil_Ash"
    },
    {
      "x": -8,
      "y": 6,
      "z": -6,
      "name": "Plant_Crop_Wheat_Stage_4_Burnt"
    },
    {
      "x": -8,
      "y": 7,
      "z": -6,
      "name": "Plant_Crop_Wheat_Stage_4_Burnt",
      "filler": 1024
    },
    {
      "x": -8,
      "y": 0,
      "z": -5,
      "name": "Soil_Sand_Ashen"
    },
    {
      "x": -8,
      "y": 1,
      "z": -5,
      "name": "Soil_Sand_Ashen"
    },
    {
      "x": -8,
      "y": 2,
      "z": -5,
      "name": "Soil_Mud"
    },
    {
      "x": -8,
      "y": 3,
      "z": -5,
      "name": "Soil_Mud"
    },
    {
      "x": -8,
      "y": 4,
      "z": -5,
      "name": "Soil_Mud"
    },
    {
      "x": -8,
      "y": 0,
      "z": -4,
      "name": "Soil_Sand_Ashen"
    },
    {
      "x": -8,
      "y": 1,
      "z": -4,
      "name": "Soil_Sand_Ashen"
    },
    {
      "x": -8,
      "y": 2,
      "z": -4,
      "name": "Soil_Mud"
    },
    {
      "x": -8,
      "y": 3,
      "z": -4,
      "name": "Soil_Mud"
    },
    {
      "x": -8,
      "y": 4,
      "z": -4,
      "name": "Soil_Mud"
    },
    {
      "x": -8,
      "y": 0,
      "z": -3,
      "name": "Soil_Sand_Ashen"
    },
    {
      "x": -8,
      "y": 1,
      "z": -3,
      "name": "Soil_Sand_Ashen"
    },
    {
      "x": -8,
      "y": 2,
      "z": -3,
      "name": "Soil_Mud"
    },
    {
      "x": -8,
      "y": 3,
      "z": -3,
      "name": "Soil_Mud"
    },
    {
      "x": -8,
      "y": 4,
      "z": -3,
      "name": "Soil_Mud"
    },
    {
      "x": -8,
      "y": 0,
      "z": -2,
      "name": "Soil_Sand_Ashen"
    },
    {
      "x": -8,
      "y": 1,
      "z": -2,
      "name": "Soil_Sand_Ashen"
    },
    {
      "x": -8,
      "y": 2,
      "z": -2,
      "name": "Soil_Mud"
    },
    {
      "x": -8,
      "y": 3,
      "z": -2,
      "name": "Soil_Mud"
    },
    {
      "x": -8,
      "y": 0,
      "z": -1,
      "name": "Soil_Sand_Ashen"
    },
    {
      "x": -8,
      "y": 0,
      "z": 0,
      "name": "Soil_Sand_Ashen"
    },
    {
      "x": -8,
      "y": 0,
      "z": 1,
      "name": "Soil_Sand_Ashen"
    },
    {
      "x": -8,
      "y": 1,
      "z": 1,
      "name": "Soil_Sand_Ashen"
    },
    {
      "x": -8,
      "y": 2,
      "z": 1,
      "name": "Soil_Mud"
    },
    {
      "x": -8,
      "y": 3,
      "z": 1,
      "name": "Soil_Mud"
    },
    {
      "x": -8,
      "y": 0,
      "z": 2,
      "name": "Soil_Sand_Ashen"
    },
    {
      "x": -8,
      "y": 1,
      "z": 2,
      "name": "Soil_Sand_Ashen"
    },
    {
      "x": -8,
      "y": 2,
      "z": 2,
      "name": "Soil_Mud"
    },
    {
      "x": -8,
      "y": 3,
      "z": 2,
      "name": "Soil_Mud"
    },
    {
      "x": -8,
      "y": 4,
      "z": 2,
      "name": "Soil_Mud"
    },
    {
      "x": -8,
      "y": 0,
      "z": 3,
      "name": "Soil_Sand_Ashen"
    },
    {
      "x": -8,
      "y": 1,
      "z": 3,
      "name": "Soil_Sand_Ashen"
    },
    {
      "x": -8,
      "y": 2,
      "z": 3,
      "name": "Soil_Mud"
    },
    {
      "x": -8,
      "y": 3,
      "z": 3,
      "name": "Soil_Mud"
    },
    {
      "x": -8,
      "y": 4,
      "z": 3,
      "name": "Soil_Ash"
    },
    {
      "x": -8,
      "y": 5,
      "z": 3,
      "name": "Plant_Bush_Dead_Tall"
    },
    {
      "x": -8,
      "y": 0,
      "z": 4,
      "name": "Soil_Sand_Ashen"
    },
    {
      "x": -8,
      "y": 1,
      "z": 4,
      "name": "Soil_Sand_Ashen"
    },
    {
      "x": -8,
      "y": 2,
      "z": 4,
      "name": "Soil_Mud"
    },
    {
      "x": -8,
      "y": 3,
      "z": 4,
      "name": "Soil_Mud"
    },
    {
      "x": -8,
      "y": 4,
      "z": 4,
      "name": "Soil_Mud"
    },
    {
      "x": -8,
      "y": 0,
      "z": 5,
      "name": "Soil_Sand_Ashen"
    },
    {
      "x": -8,
      "y": 1,
      "z": 5,
      "name": "Soil_Sand_Ashen"
    },
    {
      "x": -8,
      "y": 2,
      "z": 5,
      "name": "Soil_Mud"
    },
    {
      "x": -8,
      "y": 3,
      "z": 5,
      "name": "Soil_Mud"
    },
    {
      "x": -8,
      "y": 4,
      "z": 5,
      "name": "Soil_Mud"
    },
    {
      "x": -8,
      "y": 5,
      "z": 5,
      "name": "Soil_Ash"
    },
    {
      "x": -8,
      "y": 0,
      "z": 6,
      "name": "Soil_Sand_Ashen"
    },
    {
      "x": -8,
      "y": 1,
      "z": 6,
      "name": "Soil_Sand_Ashen"
    },
    {
      "x": -8,
      "y": 2,
      "z": 6,
      "name": "Soil_Mud"
    },
    {
      "x": -8,
      "y": 3,
      "z": 6,
      "name": "Soil_Mud"
    },
    {
      "x": -8,
      "y": 4,
      "z": 6,
      "name": "Soil_Mud"
    },
    {
      "x": -8,
      "y": 5,
      "z": 6,
      "name": "Soil_Ash"
    },
    {
      "x": -8,
      "y": 0,
      "z": 7,
      "name": "Soil_Sand_Ashen"
    },
    {
      "x": -8,
      "y": 1,
      "z": 7,
      "name": "Soil_Sand_Ashen"
    },
    {
      "x": -8,
      "y": 2,
      "z": 7,
      "name": "Soil_Mud"
    },
    {
      "x": -8,
      "y": 3,
      "z": 7,
      "name": "Soil_Mud"
    },
    {
      "x": -8,
      "y": 4,
      "z": 7,
      "name": "Soil_Mud"
    },
    {
      "x": -8,
      "y": 5,
      "z": 7,
      "name": "Soil_Ash"
    },
    {
      "x": -8,
      "y": 0,
      "z": 8,
      "name": "Soil_Sand_Ashen"
    },
    {
      "x": -8,
      "y": 1,
      "z": 8,
      "name": "Soil_Sand_Ashen"
    },
    {
      "x": -8,
      "y": 2,
      "z": 8,
      "name": "Soil_Mud"
    },
    {
      "x": -8,
      "y": 3,
      "z": 8,
      "name": "Soil_Mud"
    },
    {
      "x": -8,
      "y": 4,
      "z": 8,
      "name": "Soil_Mud"
    },
    {
      "x": -8,
      "y": 5,
      "z": 8,
      "name": "Soil_Ash"
    },
    {
      "x": -8,
      "y": 0,
      "z": 9,
      "name": "Soil_Sand_Ashen"
    },
    {
      "x": -8,
      "y": 1,
      "z": 9,
      "name": "Soil_Sand_Ashen"
    },
    {
      "x": -8,
      "y": 2,
      "z": 9,
      "name": "Soil_Sand_Ashen"
    },
    {
      "x": -8,
      "y": 3,
      "z": 9,
      "name": "Soil_Sand_Ashen"
    },
    {
      "x": -8,
      "y": 4,
      "z": 9,
      "name": "Soil_Ash"
    },
    {
      "x": -8,
      "y": 0,
      "z": 10,
      "name": "Soil_Sand_Ashen"
    },
    {
      "x": -7,
      "y": 0,
      "z": -11,
      "name": "Soil_Sand_Ashen"
    },
    {
      "x": -7,
      "y": 1,
      "z": -11,
      "name": "Soil_Sand_Ashen"
    },
    {
      "x": -7,
      "y": 2,
      "z": -11,
      "name": "Soil_Sand_Ashen"
    },
    {
      "x": -7,
      "y": 0,
      "z": -10,
      "name": "Soil_Sand_Ashen"
    },
    {
      "x": -7,
      "y": 1,
      "z": -10,
      "name": "Soil_Sand_Ashen"
    },
    {
      "x": -7,
      "y": 2,
      "z": -10,
      "name": "Soil_Mud"
    },
    {
      "x": -7,
      "y": 3,
      "z": -10,
      "name": "Soil_Mud"
    },
    {
      "x": -7,
      "y": 4,
      "z": -10,
      "name": "Soil_Mud"
    },
    {
      "x": -7,
      "y": 0,
      "z": -9,
      "name": "Soil_Sand_Ashen"
    },
    {
      "x": -7,
      "y": 1,
      "z": -9,
      "name": "Soil_Sand_Ashen"
    },
    {
      "x": -7,
      "y": 2,
      "z": -9,
      "name": "Soil_Mud"
    },
    {
      "x": -7,
      "y": 3,
      "z": -9,
      "name": "Soil_Mud"
    },
    {
      "x": -7,
      "y": 4,
      "z": -9,
      "name": "Soil_Mud"
    },
    {
      "x": -7,
      "y": 0,
      "z": -8,
      "name": "Soil_Sand_Ashen"
    },
    {
      "x": -7,
      "y": 1,
      "z": -8,
      "name": "Soil_Sand_Ashen"
    },
    {
      "x": -7,
      "y": 2,
      "z": -8,
      "name": "Soil_Mud"
    },
    {
      "x": -7,
      "y": 3,
      "z": -8,
      "name": "Soil_Mud"
    },
    {
      "x": -7,
      "y": 4,
      "z": -8,
      "name": "Soil_Mud"
    },
    {
      "x": -7,
      "y": 5,
      "z": -8,
      "name": "Soil_Mud"
    },
    {
      "x": -7,
      "y": 6,
      "z": -8,
      "name": "Deco_Bone_Skulls"
    },
    {
      "x": -7,
      "y": 0,
      "z": -7,
      "name": "Soil_Sand_Ashen"
    },
    {
      "x": -7,
      "y": 1,
      "z": -7,
      "name": "Soil_Sand_Ashen"
    },
    {
      "x": -7,
      "y": 2,
      "z": -7,
      "name": "Soil_Mud"
    },
    {
      "x": -7,
      "y": 3,
      "z": -7,
      "name": "Soil_Mud"
    },
    {
      "x": -7,
      "y": 4,
      "z": -7,
      "name": "Soil_Mud"
    },
    {
      "x": -7,
      "y": 5,
      "z": -7,
      "name": "Soil_Ash"
    },
    {
      "x": -7,
      "y": 6,
      "z": -7,
      "name": "Plant_Crop_Wheat_Stage_4_Burnt"
    },
    {
      "x": -7,
      "y": 7,
      "z": -7,
      "name": "Plant_Crop_Wheat_Stage_4_Burnt",
      "filler": 1024
    },
    {
      "x": -7,
      "y": 0,
      "z": -6,
      "name": "Soil_Sand_Ashen"
    },
    {
      "x": -7,
      "y": 1,
      "z": -6,
      "name": "Soil_Sand_Ashen"
    },
    {
      "x": -7,
      "y": 2,
      "z": -6,
      "name": "Soil_Mud"
    },
    {
      "x": -7,
      "y": 3,
      "z": -6,
      "name": "Soil_Mud"
    },
    {
      "x": -7,
      "y": 4,
      "z": -6,
      "name": "Soil_Mud"
    },
    {
      "x": -7,
      "y": 5,
      "z": -6,
      "name": "Soil_Ash"
    },
    {
      "x": -7,
      "y": 6,
      "z": -6,
      "name": "Soil_Ash"
    },
    {
      "x": -7,
      "y": 7,
      "z": -6,
      "name": "Plant_Crop_Wheat_Stage_4_Burnt"
    },
    {
      "x": -7,
      "y": 8,
      "z": -6,
      "name": "Plant_Crop_Wheat_Stage_4_Burnt",
      "filler": 1024
    },
    {
      "x": -7,
      "y": 0,
      "z": -5,
      "name": "Soil_Sand_Ashen"
    },
    {
      "x": -7,
      "y": 1,
      "z": -5,
      "name": "Soil_Sand_Ashen"
    },
    {
      "x": -7,
      "y": 2,
      "z": -5,
      "name": "Soil_Mud"
    },
    {
      "x": -7,
      "y": 3,
      "z": -5,
      "name": "Soil_Mud"
    },
    {
      "x": -7,
      "y": 4,
      "z": -5,
      "name": "Soil_Mud"
    },
    {
      "x": -7,
      "y": 5,
      "z": -5,
      "name": "Soil_Mud"
    },
    {
      "x": -7,
      "y": 0,
      "z": -4,
      "name": "Soil_Sand_Ashen"
    },
    {
      "x": -7,
      "y": 1,
      "z": -4,
      "name": "Soil_Sand_Ashen"
    },
    {
      "x": -7,
      "y": 2,
      "z": -4,
      "name": "Soil_Mud"
    },
    {
      "x": -7,
      "y": 3,
      "z": -4,
      "name": "Soil_Mud"
    },
    {
      "x": -7,
      "y": 4,
      "z": -4,
      "name": "Soil_Mud"
    },
    {
      "x": -7,
      "y": 5,
      "z": -4,
      "name": "Soil_Mud"
    },
    {
      "x": -7,
      "y": 0,
      "z": -3,
      "name": "Soil_Sand_Ashen"
    },
    {
      "x": -7,
      "y": 1,
      "z": -3,
      "name": "Soil_Sand_Ashen"
    },
    {
      "x": -7,
      "y": 2,
      "z": -3,
      "name": "Soil_Mud"
    },
    {
      "x": -7,
      "y": 3,
      "z": -3,
      "name": "Soil_Mud"
    },
    {
      "x": -7,
      "y": 4,
      "z": -3,
      "name": "Soil_Mud"
    },
    {
      "x": -7,
      "y": 0,
      "z": -2,
      "name": "Soil_Sand_Ashen"
    },
    {
      "x": -7,
      "y": 1,
      "z": -2,
      "name": "Soil_Sand_Ashen"
    },
    {
      "x": -7,
      "y": 2,
      "z": -2,
      "name": "Soil_Mud"
    },
    {
      "x": -7,
      "y": 3,
      "z": -2,
      "name": "Soil_Mud"
    },
    {
      "x": -7,
      "y": 4,
      "z": -2,
      "name": "Soil_Mud"
    },
    {
      "x": -7,
      "y": 0,
      "z": -1,
      "name": "Soil_Sand_Ashen"
    },
    {
      "x": -7,
      "y": 1,
      "z": -1,
      "name": "Soil_Sand_Ashen"
    },
    {
      "x": -7,
      "y": 2,
      "z": -1,
      "name": "Soil_Mud"
    },
    {
      "x": -7,
      "y": 0,
      "z": 0,
      "name": "Soil_Sand_Ashen"
    },
    {
      "x": -7,
      "y": 1,
      "z": 0,
      "name": "Soil_Sand_Ashen"
    },
    {
      "x": -7,
      "y": 2,
      "z": 0,
      "name": "Soil_Mud"
    },
    {
      "x": -7,
      "y": 3,
      "z": 0,
      "name": "Plant_Bush_Dead_Tall"
    },
    {
      "x": -7,
      "y": 0,
      "z": 1,
      "name": "Soil_Sand_Ashen"
    },
    {
      "x": -7,
      "y": 1,
      "z": 1,
      "name": "Soil_Sand_Ashen"
    },
    {
      "x": -7,
      "y": 2,
      "z": 1,
      "name": "Soil_Mud"
    },
    {
      "x": -7,
      "y": 3,
      "z": 1,
      "name": "Soil_Mud"
    },
    {
      "x": -7,
      "y": 4,
      "z": 1,
      "name": "Soil_Mud"
    },
    {
      "x": -7,
      "y": 0,
      "z": 2,
      "name": "Soil_Sand_Ashen"
    },
    {
      "x": -7,
      "y": 1,
      "z": 2,
      "name": "Soil_Sand_Ashen"
    },
    {
      "x": -7,
      "y": 2,
      "z": 2,
      "name": "Soil_Mud"
    },
    {
      "x": -7,
      "y": 3,
      "z": 2,
      "name": "Soil_Mud"
    },
    {
      "x": -7,
      "y": 4,
      "z": 2,
      "name": "Soil_Mud"
    },
    {
      "x": -7,
      "y": 0,
      "z": 3,
      "name": "Soil_Sand_Ashen"
    },
    {
      "x": -7,
      "y": 1,
      "z": 3,
      "name": "Soil_Sand_Ashen"
    },
    {
      "x": -7,
      "y": 2,
      "z": 3,
      "name": "Soil_Mud"
    },
    {
      "x": -7,
      "y": 3,
      "z": 3,
      "name": "Soil_Ash"
    },
    {
      "x": -7,
      "y": 4,
      "z": 3,
      "name": "Soil_Mud"
    },
    {
      "x": -7,
      "y": 5,
      "z": 3,
      "name": "Soil_Ash"
    },
    {
      "x": -7,
      "y": 0,
      "z": 4,
      "name": "Soil_Sand_Ashen"
    },
    {
      "x": -7,
      "y": 1,
      "z": 4,
      "name": "Soil_Sand_Ashen"
    },
    {
      "x": -7,
      "y": 2,
      "z": 4,
      "name": "Soil_Mud"
    },
    {
      "x": -7,
      "y": 3,
      "z": 4,
      "name": "Soil_Mud"
    },
    {
      "x": -7,
      "y": 4,
      "z": 4,
      "name": "Soil_Mud"
    },
    {
      "x": -7,
      "y": 5,
      "z": 4,
      "name": "Soil_Ash"
    },
    {
      "x": -7,
      "y": 0,
      "z": 5,
      "name": "Soil_Sand_Ashen"
    },
    {
      "x": -7,
      "y": 1,
      "z": 5,
      "name": "Soil_Sand_Ashen"
    },
    {
      "x": -7,
      "y": 2,
      "z": 5,
      "name": "Soil_Mud"
    },
    {
      "x": -7,
      "y": 3,
      "z": 5,
      "name": "Soil_Mud"
    },
    {
      "x": -7,
      "y": 4,
      "z": 5,
      "name": "Soil_Mud"
    },
    {
      "x": -7,
      "y": 5,
      "z": 5,
      "name": "Soil_Sand_Ashen"
    },
    {
      "x": -7,
      "y": 0,
      "z": 6,
      "name": "Soil_Sand_Ashen"
    },
    {
      "x": -7,
      "y": 1,
      "z": 6,
      "name": "Soil_Sand_Ashen"
    },
    {
      "x": -7,
      "y": 2,
      "z": 6,
      "name": "Soil_Mud"
    },
    {
      "x": -7,
      "y": 3,
      "z": 6,
      "name": "Soil_Mud"
    },
    {
      "x": -7,
      "y": 4,
      "z": 6,
      "name": "Soil_Mud"
    },
    {
      "x": -7,
      "y": 5,
      "z": 6,
      "name": "Soil_Sand_Ashen"
    },
    {
      "x": -7,
      "y": 0,
      "z": 7,
      "name": "Soil_Sand_Ashen"
    },
    {
      "x": -7,
      "y": 1,
      "z": 7,
      "name": "Soil_Sand_Ashen"
    },
    {
      "x": -7,
      "y": 2,
      "z": 7,
      "name": "Soil_Mud"
    },
    {
      "x": -7,
      "y": 3,
      "z": 7,
      "name": "Soil_Mud"
    },
    {
      "x": -7,
      "y": 4,
      "z": 7,
      "name": "Soil_Mud"
    },
    {
      "x": -7,
      "y": 5,
      "z": 7,
      "name": "Soil_Sand_Ashen"
    },
    {
      "x": -7,
      "y": 0,
      "z": 8,
      "name": "Soil_Sand_Ashen"
    },
    {
      "x": -7,
      "y": 1,
      "z": 8,
      "name": "Soil_Sand_Ashen"
    },
    {
      "x": -7,
      "y": 2,
      "z": 8,
      "name": "Soil_Mud"
    },
    {
      "x": -7,
      "y": 3,
      "z": 8,
      "name": "Soil_Mud"
    },
    {
      "x": -7,
      "y": 4,
      "z": 8,
      "name": "Soil_Mud"
    },
    {
      "x": -7,
      "y": 5,
      "z": 8,
      "name": "Soil_Ash"
    },
    {
      "x": -7,
      "y": 0,
      "z": 9,
      "name": "Soil_Sand_Ashen"
    },
    {
      "x": -7,
      "y": 1,
      "z": 9,
      "name": "Soil_Sand_Ashen"
    },
    {
      "x": -7,
      "y": 2,
      "z": 9,
      "name": "Soil_Mud"
    },
    {
      "x": -7,
      "y": 3,
      "z": 9,
      "name": "Soil_Mud"
    },
    {
      "x": -7,
      "y": 4,
      "z": 9,
      "name": "Soil_Mud"
    },
    {
      "x": -7,
      "y": 5,
      "z": 9,
      "name": "Soil_Ash"
    },
    {
      "x": -7,
      "y": 0,
      "z": 10,
      "name": "Soil_Sand_Ashen"
    },
    {
      "x": -7,
      "y": 1,
      "z": 10,
      "name": "Soil_Sand_Ashen"
    },
    {
      "x": -7,
      "y": 2,
      "z": 10,
      "name": "Soil_Sand_Ashen"
    },
    {
      "x": -7,
      "y": 3,
      "z": 10,
      "name": "Plant_Flower_Bushy_Grey"
    },
    {
      "x": -7,
      "y": 4,
      "z": 10,
      "name": "Plant_Flower_Bushy_Grey",
      "filler": 1024
    },
    {
      "x": -6,
      "y": 0,
      "z": -12,
      "name": "Soil_Sand_Ashen"
    },
    {
      "x": -6,
      "y": 1,
      "z": -12,
      "name": "Soil_Sand_Ashen"
    },
    {
      "x": -6,
      "y": 0,
      "z": -11,
      "name": "Soil_Sand_Ashen"
    },
    {
      "x": -6,
      "y": 1,
      "z": -11,
      "name": "Soil_Sand_Ashen"
    },
    {
      "x": -6,
      "y": 2,
      "z": -11,
      "name": "Soil_Sand_Ashen"
    },
    {
      "x": -6,
      "y": 3,
      "z": -11,
      "name": "Soil_Sand_Ashen"
    },
    {
      "x": -6,
      "y": 4,
      "z": -11,
      "name": "Plant_Flower_Bushy_Grey"
    },
    {
      "x": -6,
      "y": 5,
      "z": -11,
      "name": "Plant_Flower_Bushy_Grey",
      "filler": 1024
    },
    {
      "x": -6,
      "y": 0,
      "z": -10,
      "name": "Soil_Sand_Ashen"
    },
    {
      "x": -6,
      "y": 1,
      "z": -10,
      "name": "Soil_Sand_Ashen"
    },
    {
      "x": -6,
      "y": 2,
      "z": -10,
      "name": "Soil_Mud"
    },
    {
      "x": -6,
      "y": 3,
      "z": -10,
      "name": "Soil_Mud"
    },
    {
      "x": -6,
      "y": 4,
      "z": -10,
      "name": "Soil_Mud"
    },
    {
      "x": -6,
      "y": 5,
      "z": -10,
      "name": "Plant_Bush_Dead_Tall"
    },
    {
      "x": -6,
      "y": 0,
      "z": -9,
      "name": "Soil_Sand_Ashen"
    },
    {
      "x": -6,
      "y": 1,
      "z": -9,
      "name": "Soil_Sand_Ashen"
    },
    {
      "x": -6,
      "y": 2,
      "z": -9,
      "name": "Soil_Mud"
    },
    {
      "x": -6,
      "y": 3,
      "z": -9,
      "name": "Soil_Mud"
    },
    {
      "x": -6,
      "y": 4,
      "z": -9,
      "name": "Soil_Mud"
    },
    {
      "x": -6,
      "y": 5,
      "z": -9,
      "name": "Soil_Mud"
    },
    {
      "x": -6,
      "y": 6,
      "z": -9,
      "name": "Deco_Bone_Skulls"
    },
    {
      "x": -6,
      "y": 0,
      "z": -8,
      "name": "Soil_Sand_Ashen"
    },
    {
      "x": -6,
      "y": 1,
      "z": -8,
      "name": "Soil_Sand_Ashen"
    },
    {
      "x": -6,
      "y": 2,
      "z": -8,
      "name": "Soil_Mud"
    },
    {
      "x": -6,
      "y": 3,
      "z": -8,
      "name": "Soil_Mud"
    },
    {
      "x": -6,
      "y": 4,
      "z": -8,
      "name": "Soil_Mud"
    },
    {
      "x": -6,
      "y": 5,
      "z": -8,
      "name": "Soil_Mud"
    },
    {
      "x": -6,
      "y": 6,
      "z": -8,
      "name": "Deco_Bone_Skulls_Wall",
      "rotation": 2
    },
    {
      "x": -6,
      "y": 0,
      "z": -7,
      "name": "Soil_Sand_Ashen"
    },
    {
      "x": -6,
      "y": 1,
      "z": -7,
      "name": "Soil_Sand_Ashen"
    },
    {
      "x": -6,
      "y": 2,
      "z": -7,
      "name": "Soil_Mud"
    },
    {
      "x": -6,
      "y": 3,
      "z": -7,
      "name": "Soil_Mud"
    },
    {
      "x": -6,
      "y": 4,
      "z": -7,
      "name": "Soil_Mud"
    },
    {
      "x": -6,
      "y": 5,
      "z": -7,
      "name": "Soil_Mud"
    },
    {
      "x": -6,
      "y": 6,
      "z": -7,
      "name": "Soil_Mud"
    },
    {
      "x": -6,
      "y": 0,
      "z": -6,
      "name": "Soil_Sand_Ashen"
    },
    {
      "x": -6,
      "y": 1,
      "z": -6,
      "name": "Soil_Sand_Ashen"
    },
    {
      "x": -6,
      "y": 2,
      "z": -6,
      "name": "Soil_Mud"
    },
    {
      "x": -6,
      "y": 3,
      "z": -6,
      "name": "Soil_Mud"
    },
    {
      "x": -6,
      "y": 4,
      "z": -6,
      "name": "Soil_Mud"
    },
    {
      "x": -6,
      "y": 5,
      "z": -6,
      "name": "Soil_Mud"
    },
    {
      "x": -6,
      "y": 6,
      "z": -6,
      "name": "Soil_Ash"
    },
    {
      "x": -6,
      "y": 0,
      "z": -5,
      "name": "Soil_Sand_Ashen"
    },
    {
      "x": -6,
      "y": 1,
      "z": -5,
      "name": "Soil_Sand_Ashen"
    },
    {
      "x": -6,
      "y": 2,
      "z": -5,
      "name": "Soil_Mud"
    },
    {
      "x": -6,
      "y": 3,
      "z": -5,
      "name": "Soil_Mud"
    },
    {
      "x": -6,
      "y": 4,
      "z": -5,
      "name": "Soil_Mud"
    },
    {
      "x": -6,
      "y": 5,
      "z": -5,
      "name": "Soil_Mud"
    },
    {
      "x": -6,
      "y": 6,
      "z": -5,
      "name": "Soil_Mud"
    },
    {
      "x": -6,
      "y": 0,
      "z": -4,
      "name": "Soil_Sand_Ashen"
    },
    {
      "x": -6,
      "y": 1,
      "z": -4,
      "name": "Soil_Sand_Ashen"
    },
    {
      "x": -6,
      "y": 2,
      "z": -4,
      "name": "Soil_Mud"
    },
    {
      "x": -6,
      "y": 3,
      "z": -4,
      "name": "Soil_Mud"
    },
    {
      "x": -6,
      "y": 4,
      "z": -4,
      "name": "Soil_Mud"
    },
    {
      "x": -6,
      "y": 5,
      "z": -4,
      "name": "Soil_Mud"
    },
    {
      "x": -6,
      "y": 0,
      "z": -3,
      "name": "Soil_Sand_Ashen"
    },
    {
      "x": -6,
      "y": 1,
      "z": -3,
      "name": "Soil_Sand_Ashen"
    },
    {
      "x": -6,
      "y": 2,
      "z": -3,
      "name": "Soil_Mud"
    },
    {
      "x": -6,
      "y": 3,
      "z": -3,
      "name": "Soil_Mud"
    },
    {
      "x": -6,
      "y": 4,
      "z": -3,
      "name": "Soil_Mud"
    },
    {
      "x": -6,
      "y": 5,
      "z": -3,
      "name": "Soil_Mud"
    },
    {
      "x": -6,
      "y": 0,
      "z": -2,
      "name": "Soil_Sand_Ashen"
    },
    {
      "x": -6,
      "y": 1,
      "z": -2,
      "name": "Soil_Sand_Ashen"
    },
    {
      "x": -6,
      "y": 2,
      "z": -2,
      "name": "Soil_Mud"
    },
    {
      "x": -6,
      "y": 3,
      "z": -2,
      "name": "Soil_Mud"
    },
    {
      "x": -6,
      "y": 4,
      "z": -2,
      "name": "Soil_Mud"
    },
    {
      "x": -6,
      "y": 0,
      "z": -1,
      "name": "Soil_Sand_Ashen"
    },
    {
      "x": -6,
      "y": 1,
      "z": -1,
      "name": "Soil_Sand_Ashen"
    },
    {
      "x": -6,
      "y": 2,
      "z": -1,
      "name": "Soil_Mud"
    },
    {
      "x": -6,
      "y": 3,
      "z": -1,
      "name": "Soil_Mud"
    },
    {
      "x": -6,
      "y": 4,
      "z": -1,
      "name": "Deco_Bone_Skulls_Feran"
    },
    {
      "x": -6,
      "y": 0,
      "z": 0,
      "name": "Soil_Sand_Ashen"
    },
    {
      "x": -6,
      "y": 1,
      "z": 0,
      "name": "Soil_Sand_Ashen"
    },
    {
      "x": -6,
      "y": 2,
      "z": 0,
      "name": "Soil_Mud"
    },
    {
      "x": -6,
      "y": 3,
      "z": 0,
      "name": "Soil_Mud"
    },
    {
      "x": -6,
      "y": 0,
      "z": 1,
      "name": "Soil_Sand_Ashen"
    },
    {
      "x": -6,
      "y": 1,
      "z": 1,
      "name": "Soil_Sand_Ashen"
    },
    {
      "x": -6,
      "y": 2,
      "z": 1,
      "name": "Soil_Mud"
    },
    {
      "x": -6,
      "y": 3,
      "z": 1,
      "name": "Soil_Mud"
    },
    {
      "x": -6,
      "y": 4,
      "z": 1,
      "name": "Soil_Mud"
    },
    {
      "x": -6,
      "y": 0,
      "z": 2,
      "name": "Soil_Sand_Ashen"
    },
    {
      "x": -6,
      "y": 1,
      "z": 2,
      "name": "Soil_Sand_Ashen"
    },
    {
      "x": -6,
      "y": 2,
      "z": 2,
      "name": "Soil_Mud"
    },
    {
      "x": -6,
      "y": 3,
      "z": 2,
      "name": "Soil_Mud"
    },
    {
      "x": -6,
      "y": 4,
      "z": 2,
      "name": "Soil_Mud"
    },
    {
      "x": -6,
      "y": 5,
      "z": 2,
      "name": "Soil_Mud"
    },
    {
      "x": -6,
      "y": 0,
      "z": 3,
      "name": "Soil_Sand_Ashen"
    },
    {
      "x": -6,
      "y": 1,
      "z": 3,
      "name": "Soil_Sand_Ashen"
    },
    {
      "x": -6,
      "y": 2,
      "z": 3,
      "name": "Soil_Mud"
    },
    {
      "x": -6,
      "y": 3,
      "z": 3,
      "name": "Soil_Mud"
    },
    {
      "x": -6,
      "y": 4,
      "z": 3,
      "name": "Soil_Mud"
    },
    {
      "x": -6,
      "y": 5,
      "z": 3,
      "name": "Soil_Mud"
    },
    {
      "x": -6,
      "y": 0,
      "z": 4,
      "name": "Soil_Sand_Ashen"
    },
    {
      "x": -6,
      "y": 1,
      "z": 4,
      "name": "Soil_Sand_Ashen"
    },
    {
      "x": -6,
      "y": 2,
      "z": 4,
      "name": "Soil_Mud"
    },
    {
      "x": -6,
      "y": 3,
      "z": 4,
      "name": "Soil_Mud"
    },
    {
      "x": -6,
      "y": 4,
      "z": 4,
      "name": "Soil_Mud"
    },
    {
      "x": -6,
      "y": 5,
      "z": 4,
      "name": "Soil_Mud"
    },
    {
      "x": -6,
      "y": 6,
      "z": 4,
      "name": "Soil_Ash"
    },
    {
      "x": -6,
      "y": 0,
      "z": 5,
      "name": "Soil_Sand_Ashen"
    },
    {
      "x": -6,
      "y": 1,
      "z": 5,
      "name": "Soil_Sand_Ashen"
    },
    {
      "x": -6,
      "y": 2,
      "z": 5,
      "name": "Soil_Mud"
    },
    {
      "x": -6,
      "y": 3,
      "z": 5,
      "name": "Soil_Mud"
    },
    {
      "x": -6,
      "y": 4,
      "z": 5,
      "name": "Soil_Mud"
    },
    {
      "x": -6,
      "y": 5,
      "z": 5,
      "name": "Soil_Mud"
    },
    {
      "x": -6,
      "y": 6,
      "z": 5,
      "name": "Soil_Sand_Ashen"
    },
    {
      "x": -6,
      "y": 0,
      "z": 6,
      "name": "Soil_Sand_Ashen"
    },
    {
      "x": -6,
      "y": 1,
      "z": 6,
      "name": "Soil_Sand_Ashen"
    },
    {
      "x": -6,
      "y": 2,
      "z": 6,
      "name": "Soil_Mud"
    },
    {
      "x": -6,
      "y": 3,
      "z": 6,
      "name": "Soil_Mud"
    },
    {
      "x": -6,
      "y": 4,
      "z": 6,
      "name": "Soil_Mud"
    },
    {
      "x": -6,
      "y": 5,
      "z": 6,
      "name": "Soil_Mud"
    },
    {
      "x": -6,
      "y": 6,
      "z": 6,
      "name": "Soil_Sand_Ashen"
    },
    {
      "x": -6,
      "y": 0,
      "z": 7,
      "name": "Soil_Sand_Ashen"
    },
    {
      "x": -6,
      "y": 1,
      "z": 7,
      "name": "Soil_Sand_Ashen"
    },
    {
      "x": -6,
      "y": 2,
      "z": 7,
      "name": "Soil_Mud"
    },
    {
      "x": -6,
      "y": 3,
      "z": 7,
      "name": "Soil_Mud"
    },
    {
      "x": -6,
      "y": 4,
      "z": 7,
      "name": "Soil_Mud"
    },
    {
      "x": -6,
      "y": 5,
      "z": 7,
      "name": "Soil_Sand_Ashen"
    },
    {
      "x": -6,
      "y": 0,
      "z": 8,
      "name": "Soil_Sand_Ashen"
    },
    {
      "x": -6,
      "y": 1,
      "z": 8,
      "name": "Soil_Sand_Ashen"
    },
    {
      "x": -6,
      "y": 2,
      "z": 8,
      "name": "Soil_Mud"
    },
    {
      "x": -6,
      "y": 3,
      "z": 8,
      "name": "Soil_Mud"
    },
    {
      "x": -6,
      "y": 4,
      "z": 8,
      "name": "Soil_Mud"
    },
    {
      "x": -6,
      "y": 5,
      "z": 8,
      "name": "Soil_Sand_Ashen"
    },
    {
      "x": -6,
      "y": 6,
      "z": 8,
      "name": "Plant_Bush_Dead_Tall"
    },
    {
      "x": -6,
      "y": 0,
      "z": 9,
      "name": "Soil_Sand_Ashen"
    },
    {
      "x": -6,
      "y": 1,
      "z": 9,
      "name": "Soil_Sand_Ashen"
    },
    {
      "x": -6,
      "y": 2,
      "z": 9,
      "name": "Soil_Mud"
    },
    {
      "x": -6,
      "y": 3,
      "z": 9,
      "name": "Soil_Mud"
    },
    {
      "x": -6,
      "y": 4,
      "z": 9,
      "name": "Soil_Mud"
    },
    {
      "x": -6,
      "y": 5,
      "z": 9,
      "name": "Soil_Ash"
    },
    {
      "x": -6,
      "y": 6,
      "z": 9,
      "name": "Plant_Crop_Wheat_Stage_4_Burnt"
    },
    {
      "x": -6,
      "y": 7,
      "z": 9,
      "name": "Plant_Crop_Wheat_Stage_4_Burnt",
      "filler": 1024
    },
    {
      "x": -6,
      "y": 0,
      "z": 10,
      "name": "Soil_Sand_Ashen"
    },
    {
      "x": -6,
      "y": 1,
      "z": 10,
      "name": "Soil_Sand_Ashen"
    },
    {
      "x": -6,
      "y": 2,
      "z": 10,
      "name": "Soil_Sand_Ashen"
    },
    {
      "x": -6,
      "y": 3,
      "z": 10,
      "name": "Soil_Mud"
    },
    {
      "x": -6,
      "y": 4,
      "z": 10,
      "name": "Soil_Ash"
    },
    {
      "x": -6,
      "y": 5,
      "z": 10,
      "name": "Plant_Crop_Wheat_Stage_4_Burnt"
    },
    {
      "x": -6,
      "y": 6,
      "z": 10,
      "name": "Plant_Crop_Wheat_Stage_4_Burnt",
      "filler": 1024
    },
    {
      "x": -6,
      "y": 0,
      "z": 11,
      "name": "Soil_Sand_Ashen"
    },
    {
      "x": -6,
      "y": 1,
      "z": 11,
      "name": "Soil_Sand_Ashen"
    },
    {
      "x": -6,
      "y": 2,
      "z": 11,
      "name": "Soil_Sand_Ashen"
    },
    {
      "x": -6,
      "y": 3,
      "z": 11,
      "name": "Plant_Flower_Bushy_Grey"
    },
    {
      "x": -6,
      "y": 4,
      "z": 11,
      "name": "Plant_Flower_Bushy_Grey",
      "filler": 1024
    },
    {
      "x": -5,
      "y": 0,
      "z": -12,
      "name": "Soil_Sand_Ashen"
    },
    {
      "x": -5,
      "y": 1,
      "z": -12,
      "name": "Soil_Sand_Ashen"
    },
    {
      "x": -5,
      "y": 2,
      "z": -12,
      "name": "Soil_Mud"
    },
    {
      "x": -5,
      "y": 3,
      "z": -12,
      "name": "Plant_Bush_Dead_Hanging"
    },
    {
      "x": -5,
      "y": 0,
      "z": -11,
      "name": "Soil_Sand_Ashen"
    },
    {
      "x": -5,
      "y": 1,
      "z": -11,
      "name": "Soil_Sand_Ashen"
    },
    {
      "x": -5,
      "y": 2,
      "z": -11,
      "name": "Soil_Mud"
    },
    {
      "x": -5,
      "y": 3,
      "z": -11,
      "name": "Soil_Mud"
    },
    {
      "x": -5,
      "y": 4,
      "z": -11,
      "name": "Plant_Bush_Dead_Hanging"
    },
    {
      "x": -5,
      "y": 0,
      "z": -10,
      "name": "Soil_Sand_Ashen"
    },
    {
      "x": -5,
      "y": 1,
      "z": -10,
      "name": "Soil_Sand_Ashen"
    },
    {
      "x": -5,
      "y": 2,
      "z": -10,
      "name": "Soil_Mud"
    },
    {
      "x": -5,
      "y": 3,
      "z": -10,
      "name": "Soil_Mud"
    },
    {
      "x": -5,
      "y": 4,
      "z": -10,
      "name": "Soil_Mud"
    },
    {
      "x": -5,
      "y": 0,
      "z": -9,
      "name": "Soil_Sand_Ashen"
    },
    {
      "x": -5,
      "y": 1,
      "z": -9,
      "name": "Soil_Sand_Ashen"
    },
    {
      "x": -5,
      "y": 2,
      "z": -9,
      "name": "Soil_Mud"
    },
    {
      "x": -5,
      "y": 3,
      "z": -9,
      "name": "Soil_Mud"
    },
    {
      "x": -5,
      "y": 4,
      "z": -9,
      "name": "Soil_Mud"
    },
    {
      "x": -5,
      "y": 5,
      "z": -9,
      "name": "Soil_Mud"
    },
    {
      "x": -5,
      "y": 6,
      "z": -9,
      "name": "Deco_Bone_Skulls"
    },
    {
      "x": -5,
      "y": 0,
      "z": -8,
      "name": "Soil_Sand_Ashen"
    },
    {
      "x": -5,
      "y": 1,
      "z": -8,
      "name": "Soil_Sand_Ashen"
    },
    {
      "x": -5,
      "y": 2,
      "z": -8,
      "name": "Soil_Mud"
    },
    {
      "x": -5,
      "y": 3,
      "z": -8,
      "name": "Soil_Mud"
    },
    {
      "x": -5,
      "y": 4,
      "z": -8,
      "name": "Soil_Mud"
    },
    {
      "x": -5,
      "y": 5,
      "z": -8,
      "name": "Soil_Mud"
    },
    {
      "x": -5,
      "y": 6,
      "z": -8,
      "name": "Soil_Mud"
    },
    {
      "x": -5,
      "y": 0,
      "z": -7,
      "name": "Soil_Sand_Ashen"
    },
    {
      "x": -5,
      "y": 1,
      "z": -7,
      "name": "Soil_Sand_Ashen"
    },
    {
      "x": -5,
      "y": 2,
      "z": -7,
      "name": "Soil_Mud"
    },
    {
      "x": -5,
      "y": 3,
      "z": -7,
      "name": "Soil_Mud"
    },
    {
      "x": -5,
      "y": 4,
      "z": -7,
      "name": "Soil_Mud"
    },
    {
      "x": -5,
      "y": 5,
      "z": -7,
      "name": "Soil_Mud"
    },
    {
      "x": -5,
      "y": 6,
      "z": -7,
      "name": "Soil_Ash"
    },
    {
      "x": -5,
      "y": 0,
      "z": -6,
      "name": "Soil_Sand_Ashen"
    },
    {
      "x": -5,
      "y": 1,
      "z": -6,
      "name": "Soil_Sand_Ashen"
    },
    {
      "x": -5,
      "y": 2,
      "z": -6,
      "name": "Soil_Mud"
    },
    {
      "x": -5,
      "y": 3,
      "z": -6,
      "name": "Soil_Mud"
    },
    {
      "x": -5,
      "y": 4,
      "z": -6,
      "name": "Soil_Mud"
    },
    {
      "x": -5,
      "y": 5,
      "z": -6,
      "name": "Soil_Mud"
    },
    {
      "x": -5,
      "y": 6,
      "z": -6,
      "name": "Soil_Ash"
    },
    {
      "x": -5,
      "y": 0,
      "z": -5,
      "name": "Soil_Sand_Ashen"
    },
    {
      "x": -5,
      "y": 1,
      "z": -5,
      "name": "Soil_Sand_Ashen"
    },
    {
      "x": -5,
      "y": 2,
      "z": -5,
      "name": "Soil_Mud"
    },
    {
      "x": -5,
      "y": 3,
      "z": -5,
      "name": "Soil_Mud"
    },
    {
      "x": -5,
      "y": 4,
      "z": -5,
      "name": "Soil_Mud"
    },
    {
      "x": -5,
      "y": 5,
      "z": -5,
      "name": "Soil_Mud"
    },
    {
      "x": -5,
      "y": 6,
      "z": -5,
      "name": "Soil_Ash"
    },
    {
      "x": -5,
      "y": 0,
      "z": -4,
      "name": "Soil_Sand_Ashen"
    },
    {
      "x": -5,
      "y": 1,
      "z": -4,
      "name": "Soil_Sand_Ashen"
    },
    {
      "x": -5,
      "y": 2,
      "z": -4,
      "name": "Soil_Mud"
    },
    {
      "x": -5,
      "y": 3,
      "z": -4,
      "name": "Soil_Mud"
    },
    {
      "x": -5,
      "y": 4,
      "z": -4,
      "name": "Soil_Mud"
    },
    {
      "x": -5,
      "y": 5,
      "z": -4,
      "name": "Soil_Ash"
    },
    {
      "x": -5,
      "y": 0,
      "z": -3,
      "name": "Soil_Sand_Ashen"
    },
    {
      "x": -5,
      "y": 1,
      "z": -3,
      "name": "Soil_Sand_Ashen"
    },
    {
      "x": -5,
      "y": 2,
      "z": -3,
      "name": "Soil_Mud"
    },
    {
      "x": -5,
      "y": 3,
      "z": -3,
      "name": "Soil_Mud"
    },
    {
      "x": -5,
      "y": 4,
      "z": -3,
      "name": "Soil_Ash"
    },
    {
      "x": -5,
      "y": 0,
      "z": -2,
      "name": "Soil_Sand_Ashen"
    },
    {
      "x": -5,
      "y": 1,
      "z": -2,
      "name": "Soil_Sand_Ashen"
    },
    {
      "x": -5,
      "y": 2,
      "z": -2,
      "name": "Soil_Mud"
    },
    {
      "x": -5,
      "y": 3,
      "z": -2,
      "name": "Soil_Mud"
    },
    {
      "x": -5,
      "y": 4,
      "z": -2,
      "name": "Soil_Ash"
    },
    {
      "x": -5,
      "y": 0,
      "z": -1,
      "name": "Soil_Sand_Ashen"
    },
    {
      "x": -5,
      "y": 1,
      "z": -1,
      "name": "Soil_Sand_Ashen"
    },
    {
      "x": -5,
      "y": 2,
      "z": -1,
      "name": "Soil_Mud"
    },
    {
      "x": -5,
      "y": 3,
      "z": -1,
      "name": "Soil_Mud"
    },
    {
      "x": -5,
      "y": 0,
      "z": 0,
      "name": "Soil_Sand_Ashen"
    },
    {
      "x": -5,
      "y": 1,
      "z": 0,
      "name": "Soil_Sand_Ashen"
    },
    {
      "x": -5,
      "y": 2,
      "z": 0,
      "name": "Soil_Mud"
    },
    {
      "x": -5,
      "y": 3,
      "z": 0,
      "name": "Soil_Mud"
    },
    {
      "x": -5,
      "y": 0,
      "z": 1,
      "name": "Soil_Sand_Ashen"
    },
    {
      "x": -5,
      "y": 1,
      "z": 1,
      "name": "Soil_Sand_Ashen"
    },
    {
      "x": -5,
      "y": 2,
      "z": 1,
      "name": "Soil_Mud"
    },
    {
      "x": -5,
      "y": 3,
      "z": 1,
      "name": "Soil_Mud"
    },
    {
      "x": -5,
      "y": 4,
      "z": 1,
      "name": "Soil_Mud"
    },
    {
      "x": -5,
      "y": 5,
      "z": 1,
      "name": "Rock_Crystal_Purple_Medium",
      "rotation": 7
    },
    {
      "x": -5,
      "y": 0,
      "z": 2,
      "name": "Soil_Sand_Ashen"
    },
    {
      "x": -5,
      "y": 1,
      "z": 2,
      "name": "Soil_Sand_Ashen"
    },
    {
      "x": -5,
      "y": 2,
      "z": 2,
      "name": "Soil_Mud"
    },
    {
      "x": -5,
      "y": 3,
      "z": 2,
      "name": "Soil_Mud"
    },
    {
      "x": -5,
      "y": 4,
      "z": 2,
      "name": "Soil_Mud"
    },
    {
      "x": -5,
      "y": 5,
      "z": 2,
      "name": "Soil_Mud"
    },
    {
      "x": -5,
      "y": 0,
      "z": 3,
      "name": "Soil_Sand_Ashen"
    },
    {
      "x": -5,
      "y": 1,
      "z": 3,
      "name": "Soil_Sand_Ashen"
    },
    {
      "x": -5,
      "y": 2,
      "z": 3,
      "name": "Soil_Mud"
    },
    {
      "x": -5,
      "y": 3,
      "z": 3,
      "name": "Soil_Mud"
    },
    {
      "x": -5,
      "y": 4,
      "z": 3,
      "name": "Soil_Mud"
    },
    {
      "x": -5,
      "y": 5,
      "z": 3,
      "name": "Soil_Mud"
    },
    {
      "x": -5,
      "y": 6,
      "z": 3,
      "name": "Soil_Ash"
    },
    {
      "x": -5,
      "y": 0,
      "z": 4,
      "name": "Soil_Sand_Ashen"
    },
    {
      "x": -5,
      "y": 1,
      "z": 4,
      "name": "Soil_Sand_Ashen"
    },
    {
      "x": -5,
      "y": 2,
      "z": 4,
      "name": "Soil_Mud"
    },
    {
      "x": -5,
      "y": 3,
      "z": 4,
      "name": "Soil_Mud"
    },
    {
      "x": -5,
      "y": 4,
      "z": 4,
      "name": "Soil_Mud"
    },
    {
      "x": -5,
      "y": 5,
      "z": 4,
      "name": "Soil_Mud"
    },
    {
      "x": -5,
      "y": 6,
      "z": 4,
      "name": "Soil_Ash"
    },
    {
      "x": -5,
      "y": 0,
      "z": 5,
      "name": "Soil_Sand_Ashen"
    },
    {
      "x": -5,
      "y": 1,
      "z": 5,
      "name": "Soil_Sand_Ashen"
    },
    {
      "x": -5,
      "y": 2,
      "z": 5,
      "name": "Soil_Mud"
    },
    {
      "x": -5,
      "y": 3,
      "z": 5,
      "name": "Soil_Mud"
    },
    {
      "x": -5,
      "y": 4,
      "z": 5,
      "name": "Soil_Mud"
    },
    {
      "x": -5,
      "y": 5,
      "z": 5,
      "name": "Soil_Mud"
    },
    {
      "x": -5,
      "y": 6,
      "z": 5,
      "name": "Soil_Sand_Ashen"
    },
    {
      "x": -5,
      "y": 0,
      "z": 6,
      "name": "Soil_Sand_Ashen"
    },
    {
      "x": -5,
      "y": 1,
      "z": 6,
      "name": "Soil_Sand_Ashen"
    },
    {
      "x": -5,
      "y": 2,
      "z": 6,
      "name": "Soil_Mud"
    },
    {
      "x": -5,
      "y": 3,
      "z": 6,
      "name": "Soil_Mud"
    },
    {
      "x": -5,
      "y": 4,
      "z": 6,
      "name": "Soil_Mud"
    },
    {
      "x": -5,
      "y": 5,
      "z": 6,
      "name": "Soil_Sand_Ashen"
    },
    {
      "x": -5,
      "y": 6,
      "z": 6,
      "name": "Soil_Sand_Ashen"
    },
    {
      "x": -5,
      "y": 0,
      "z": 7,
      "name": "Soil_Sand_Ashen"
    },
    {
      "x": -5,
      "y": 1,
      "z": 7,
      "name": "Soil_Sand_Ashen"
    },
    {
      "x": -5,
      "y": 2,
      "z": 7,
      "name": "Soil_Mud"
    },
    {
      "x": -5,
      "y": 3,
      "z": 7,
      "name": "Soil_Mud"
    },
    {
      "x": -5,
      "y": 4,
      "z": 7,
      "name": "Soil_Mud"
    },
    {
      "x": -5,
      "y": 5,
      "z": 7,
      "name": "Soil_Mud"
    },
    {
      "x": -5,
      "y": 6,
      "z": 7,
      "name": "Soil_Sand_Ashen"
    },
    {
      "x": -5,
      "y": 0,
      "z": 8,
      "name": "Soil_Sand_Ashen"
    },
    {
      "x": -5,
      "y": 1,
      "z": 8,
      "name": "Soil_Sand_Ashen"
    },
    {
      "x": -5,
      "y": 2,
      "z": 8,
      "name": "Soil_Mud"
    },
    {
      "x": -5,
      "y": 3,
      "z": 8,
      "name": "Soil_Mud"
    },
    {
      "x": -5,
      "y": 4,
      "z": 8,
      "name": "Soil_Mud"
    },
    {
      "x": -5,
      "y": 5,
      "z": 8,
      "name": "Soil_Sand_Ashen"
    },
    {
      "x": -5,
      "y": 0,
      "z": 9,
      "name": "Soil_Sand_Ashen"
    },
    {
      "x": -5,
      "y": 1,
      "z": 9,
      "name": "Soil_Sand_Ashen"
    },
    {
      "x": -5,
      "y": 2,
      "z": 9,
      "name": "Soil_Mud"
    },
    {
      "x": -5,
      "y": 3,
      "z": 9,
      "name": "Soil_Mud"
    },
    {
      "x": -5,
      "y": 4,
      "z": 9,
      "name": "Soil_Mud"
    },
    {
      "x": -5,
      "y": 5,
      "z": 9,
      "name": "Soil_Ash"
    },
    {
      "x": -5,
      "y": 6,
      "z": 9,
      "name": "Plant_Crop_Wheat_Stage_4_Burnt"
    },
    {
      "x": -5,
      "y": 7,
      "z": 9,
      "name": "Plant_Crop_Wheat_Stage_4_Burnt",
      "filler": 1024
    },
    {
      "x": -5,
      "y": 0,
      "z": 10,
      "name": "Soil_Sand_Ashen"
    },
    {
      "x": -5,
      "y": 1,
      "z": 10,
      "name": "Soil_Sand_Ashen"
    },
    {
      "x": -5,
      "y": 2,
      "z": 10,
      "name": "Soil_Mud"
    },
    {
      "x": -5,
      "y": 3,
      "z": 10,
      "name": "Soil_Mud"
    },
    {
      "x": -5,
      "y": 4,
      "z": 10,
      "name": "Soil_Ash"
    },
    {
      "x": -5,
      "y": 5,
      "z": 10,
      "name": "Plant_Crop_Wheat_Stage_4_Burnt"
    },
    {
      "x": -5,
      "y": 6,
      "z": 10,
      "name": "Plant_Crop_Wheat_Stage_4_Burnt",
      "filler": 1024
    },
    {
      "x": -5,
      "y": 0,
      "z": 11,
      "name": "Soil_Sand_Ashen"
    },
    {
      "x": -5,
      "y": 1,
      "z": 11,
      "name": "Soil_Sand_Ashen"
    },
    {
      "x": -5,
      "y": 2,
      "z": 11,
      "name": "Soil_Mud"
    },
    {
      "x": -5,
      "y": 3,
      "z": 11,
      "name": "Plant_Bush_Dead_Hanging"
    },
    {
      "x": -4,
      "y": 0,
      "z": -12,
      "name": "Soil_Sand_Ashen"
    },
    {
      "x": -4,
      "y": 1,
      "z": -12,
      "name": "Soil_Sand_Ashen"
    },
    {
      "x": -4,
      "y": 2,
      "z": -12,
      "name": "Soil_Mud"
    },
    {
      "x": -4,
      "y": 3,
      "z": -12,
      "name": "Plant_Bush_Dead_Hanging"
    },
    {
      "x": -4,
      "y": 0,
      "z": -11,
      "name": "Soil_Sand_Ashen"
    },
    {
      "x": -4,
      "y": 1,
      "z": -11,
      "name": "Soil_Sand_Ashen"
    },
    {
      "x": -4,
      "y": 2,
      "z": -11,
      "name": "Soil_Mud"
    },
    {
      "x": -4,
      "y": 3,
      "z": -11,
      "name": "Soil_Mud"
    },
    {
      "x": -4,
      "y": 4,
      "z": -11,
      "name": "Soil_Mud"
    },
    {
      "x": -4,
      "y": 0,
      "z": -10,
      "name": "Soil_Sand_Ashen"
    },
    {
      "x": -4,
      "y": 1,
      "z": -10,
      "name": "Soil_Sand_Ashen"
    },
    {
      "x": -4,
      "y": 2,
      "z": -10,
      "name": "Soil_Mud"
    },
    {
      "x": -4,
      "y": 3,
      "z": -10,
      "name": "Soil_Mud"
    },
    {
      "x": -4,
      "y": 4,
      "z": -10,
      "name": "Soil_Mud"
    },
    {
      "x": -4,
      "y": 5,
      "z": -10,
      "name": "Soil_Mud"
    },
    {
      "x": -4,
      "y": 0,
      "z": -9,
      "name": "Soil_Sand_Ashen"
    },
    {
      "x": -4,
      "y": 1,
      "z": -9,
      "name": "Soil_Sand_Ashen"
    },
    {
      "x": -4,
      "y": 2,
      "z": -9,
      "name": "Soil_Mud"
    },
    {
      "x": -4,
      "y": 3,
      "z": -9,
      "name": "Soil_Mud"
    },
    {
      "x": -4,
      "y": 4,
      "z": -9,
      "name": "Soil_Mud"
    },
    {
      "x": -4,
      "y": 5,
      "z": -9,
      "name": "Soil_Mud"
    },
    {
      "x": -4,
      "y": 0,
      "z": -8,
      "name": "Soil_Sand_Ashen"
    },
    {
      "x": -4,
      "y": 1,
      "z": -8,
      "name": "Soil_Sand_Ashen"
    },
    {
      "x": -4,
      "y": 2,
      "z": -8,
      "name": "Soil_Mud"
    },
    {
      "x": -4,
      "y": 3,
      "z": -8,
      "name": "Soil_Mud"
    },
    {
      "x": -4,
      "y": 4,
      "z": -8,
      "name": "Soil_Mud"
    },
    {
      "x": -4,
      "y": 5,
      "z": -8,
      "name": "Soil_Mud"
    },
    {
      "x": -4,
      "y": 6,
      "z": -8,
      "name": "Soil_Mud"
    },
    {
      "x": -4,
      "y": 0,
      "z": -7,
      "name": "Soil_Sand_Ashen"
    },
    {
      "x": -4,
      "y": 1,
      "z": -7,
      "name": "Soil_Sand_Ashen"
    },
    {
      "x": -4,
      "y": 2,
      "z": -7,
      "name": "Soil_Mud"
    },
    {
      "x": -4,
      "y": 3,
      "z": -7,
      "name": "Soil_Mud"
    },
    {
      "x": -4,
      "y": 4,
      "z": -7,
      "name": "Soil_Mud"
    },
    {
      "x": -4,
      "y": 5,
      "z": -7,
      "name": "Soil_Mud"
    },
    {
      "x": -4,
      "y": 6,
      "z": -7,
      "name": "Soil_Ash"
    },
    {
      "x": -4,
      "y": 0,
      "z": -6,
      "name": "Soil_Sand_Ashen"
    },
    {
      "x": -4,
      "y": 1,
      "z": -6,
      "name": "Soil_Sand_Ashen"
    },
    {
      "x": -4,
      "y": 2,
      "z": -6,
      "name": "Soil_Mud"
    },
    {
      "x": -4,
      "y": 3,
      "z": -6,
      "name": "Soil_Mud"
    },
    {
      "x": -4,
      "y": 4,
      "z": -6,
      "name": "Soil_Mud"
    },
    {
      "x": -4,
      "y": 5,
      "z": -6,
      "name": "Soil_Mud"
    },
    {
      "x": -4,
      "y": 6,
      "z": -6,
      "name": "Soil_Ash"
    },
    {
      "x": -4,
      "y": 7,
      "z": -6,
      "name": "Plant_Crop_Wheat_Stage_4_Burnt"
    },
    {
      "x": -4,
      "y": 8,
      "z": -6,
      "name": "Plant_Crop_Wheat_Stage_4_Burnt",
      "filler": 1024
    },
    {
      "x": -4,
      "y": 0,
      "z": -5,
      "name": "Soil_Sand_Ashen"
    },
    {
      "x": -4,
      "y": 1,
      "z": -5,
      "name": "Soil_Sand_Ashen"
    },
    {
      "x": -4,
      "y": 2,
      "z": -5,
      "name": "Soil_Mud"
    },
    {
      "x": -4,
      "y": 3,
      "z": -5,
      "name": "Soil_Mud"
    },
    {
      "x": -4,
      "y": 4,
      "z": -5,
      "name": "Soil_Mud"
    },
    {
      "x": -4,
      "y": 5,
      "z": -5,
      "name": "Soil_Ash"
    },
    {
      "x": -4,
      "y": 0,
      "z": -4,
      "name": "Soil_Sand_Ashen"
    },
    {
      "x": -4,
      "y": 1,
      "z": -4,
      "name": "Soil_Sand_Ashen"
    },
    {
      "x": -4,
      "y": 2,
      "z": -4,
      "name": "Soil_Mud"
    },
    {
      "x": -4,
      "y": 3,
      "z": -4,
      "name": "Soil_Mud"
    },
    {
      "x": -4,
      "y": 4,
      "z": -4,
      "name": "Soil_Ash"
    },
    {
      "x": -4,
      "y": 0,
      "z": -3,
      "name": "Soil_Sand_Ashen"
    },
    {
      "x": -4,
      "y": 1,
      "z": -3,
      "name": "Soil_Sand_Ashen"
    },
    {
      "x": -4,
      "y": 2,
      "z": -3,
      "name": "Soil_Mud"
    },
    {
      "x": -4,
      "y": 3,
      "z": -3,
      "name": "Soil_Mud"
    },
    {
      "x": -4,
      "y": 4,
      "z": -3,
      "name": "Soil_Ash"
    },
    {
      "x": -4,
      "y": 0,
      "z": -2,
      "name": "Soil_Sand_Ashen"
    },
    {
      "x": -4,
      "y": 1,
      "z": -2,
      "name": "Soil_Sand_Ashen"
    },
    {
      "x": -4,
      "y": 2,
      "z": -2,
      "name": "Soil_Mud"
    },
    {
      "x": -4,
      "y": 3,
      "z": -2,
      "name": "Soil_Ash"
    },
    {
      "x": -4,
      "y": 0,
      "z": -1,
      "name": "Soil_Sand_Ashen"
    },
    {
      "x": -4,
      "y": 1,
      "z": -1,
      "name": "Soil_Sand_Ashen"
    },
    {
      "x": -4,
      "y": 2,
      "z": -1,
      "name": "Soil_Mud"
    },
    {
      "x": -4,
      "y": 3,
      "z": -1,
      "name": "Soil_Ash"
    },
    {
      "x": -4,
      "y": 0,
      "z": 0,
      "name": "Soil_Sand_Ashen"
    },
    {
      "x": -4,
      "y": 1,
      "z": 0,
      "name": "Soil_Sand_Ashen"
    },
    {
      "x": -4,
      "y": 2,
      "z": 0,
      "name": "Soil_Mud"
    },
    {
      "x": -4,
      "y": 3,
      "z": 0,
      "name": "Soil_Ash"
    },
    {
      "x": -4,
      "y": 4,
      "z": 0,
      "name": "Rock_Crystal_Purple_Block"
    },
    {
      "x": -4,
      "y": 5,
      "z": 0,
      "name": "Rock_Crystal_Purple_Medium"
    },
    {
      "x": -4,
      "y": 0,
      "z": 1,
      "name": "Soil_Sand_Ashen"
    },
    {
      "x": -4,
      "y": 1,
      "z": 1,
      "name": "Soil_Sand_Ashen"
    },
    {
      "x": -4,
      "y": 2,
      "z": 1,
      "name": "Soil_Mud"
    },
    {
      "x": -4,
      "y": 3,
      "z": 1,
      "name": "Soil_Mud"
    },
    {
      "x": -4,
      "y": 4,
      "z": 1,
      "name": "Soil_Ash"
    },
    {
      "x": -4,
      "y": 5,
      "z": 1,
      "name": "Rock_Crystal_Purple_Block"
    },
    {
      "x": -4,
      "y": 6,
      "z": 1,
      "name": "Rock_Crystal_Purple_Block"
    },
    {
      "x": -4,
      "y": 7,
      "z": 1,
      "name": "Rock_Crystal_Purple_Large"
    },
    {
      "x": -4,
      "y": 0,
      "z": 2,
      "name": "Soil_Sand_Ashen"
    },
    {
      "x": -4,
      "y": 1,
      "z": 2,
      "name": "Soil_Sand_Ashen"
    },
    {
      "x": -4,
      "y": 2,
      "z": 2,
      "name": "Soil_Mud"
    },
    {
      "x": -4,
      "y": 3,
      "z": 2,
      "name": "Soil_Mud"
    },
    {
      "x": -4,
      "y": 4,
      "z": 2,
      "name": "Soil_Mud"
    },
    {
      "x": -4,
      "y": 5,
      "z": 2,
      "name": "Soil_Ash"
    },
    {
      "x": -4,
      "y": 0,
      "z": 3,
      "name": "Soil_Sand_Ashen"
    },
    {
      "x": -4,
      "y": 1,
      "z": 3,
      "name": "Soil_Sand_Ashen"
    },
    {
      "x": -4,
      "y": 2,
      "z": 3,
      "name": "Soil_Mud"
    },
    {
      "x": -4,
      "y": 3,
      "z": 3,
      "name": "Soil_Mud"
    },
    {
      "x": -4,
      "y": 4,
      "z": 3,
      "name": "Soil_Mud"
    },
    {
      "x": -4,
      "y": 5,
      "z": 3,
      "name": "Soil_Mud"
    },
    {
      "x": -4,
      "y": 6,
      "z": 3,
      "name": "Soil_Ash"
    },
    {
      "x": -4,
      "y": 0,
      "z": 4,
      "name": "Soil_Sand_Ashen"
    },
    {
      "x": -4,
      "y": 1,
      "z": 4,
      "name": "Soil_Sand_Ashen"
    },
    {
      "x": -4,
      "y": 2,
      "z": 4,
      "name": "Soil_Mud"
    },
    {
      "x": -4,
      "y": 3,
      "z": 4,
      "name": "Soil_Mud"
    },
    {
      "x": -4,
      "y": 4,
      "z": 4,
      "name": "Soil_Mud"
    },
    {
      "x": -4,
      "y": 5,
      "z": 4,
      "name": "Soil_Mud"
    },
    {
      "x": -4,
      "y": 6,
      "z": 4,
      "name": "Soil_Sand_Ashen"
    },
    {
      "x": -4,
      "y": 0,
      "z": 5,
      "name": "Soil_Sand_Ashen"
    },
    {
      "x": -4,
      "y": 1,
      "z": 5,
      "name": "Soil_Sand_Ashen"
    },
    {
      "x": -4,
      "y": 2,
      "z": 5,
      "name": "Soil_Mud"
    },
    {
      "x": -4,
      "y": 3,
      "z": 5,
      "name": "Soil_Mud"
    },
    {
      "x": -4,
      "y": 4,
      "z": 5,
      "name": "Soil_Mud"
    },
    {
      "x": -4,
      "y": 5,
      "z": 5,
      "name": "Soil_Mud"
    },
    {
      "x": -4,
      "y": 6,
      "z": 5,
      "name": "Soil_Sand_Ashen"
    },
    {
      "x": -4,
      "y": 0,
      "z": 6,
      "name": "Soil_Sand_Ashen"
    },
    {
      "x": -4,
      "y": 1,
      "z": 6,
      "name": "Soil_Sand_Ashen"
    },
    {
      "x": -4,
      "y": 2,
      "z": 6,
      "name": "Soil_Mud"
    },
    {
      "x": -4,
      "y": 3,
      "z": 6,
      "name": "Soil_Mud"
    },
    {
      "x": -4,
      "y": 4,
      "z": 6,
      "name": "Soil_Mud"
    },
    {
      "x": -4,
      "y": 5,
      "z": 6,
      "name": "Soil_Mud"
    },
    {
      "x": -4,
      "y": 6,
      "z": 6,
      "name": "Soil_Sand_Ashen"
    },
    {
      "x": -4,
      "y": 7,
      "z": 6,
      "name": "Plant_Flower_Bushy_Grey"
    },
    {
      "x": -4,
      "y": 8,
      "z": 6,
      "name": "Plant_Flower_Bushy_Grey",
      "filler": 1024
    },
    {
      "x": -4,
      "y": 0,
      "z": 7,
      "name": "Soil_Sand_Ashen"
    },
    {
      "x": -4,
      "y": 1,
      "z": 7,
      "name": "Soil_Sand_Ashen"
    },
    {
      "x": -4,
      "y": 2,
      "z": 7,
      "name": "Soil_Mud"
    },
    {
      "x": -4,
      "y": 3,
      "z": 7,
      "name": "Soil_Mud"
    },
    {
      "x": -4,
      "y": 4,
      "z": 7,
      "name": "Soil_Mud"
    },
    {
      "x": -4,
      "y": 5,
      "z": 7,
      "name": "Soil_Mud"
    },
    {
      "x": -4,
      "y": 6,
      "z": 7,
      "name": "Soil_Sand_Ashen"
    },
    {
      "x": -4,
      "y": 0,
      "z": 8,
      "name": "Soil_Sand_Ashen"
    },
    {
      "x": -4,
      "y": 1,
      "z": 8,
      "name": "Soil_Sand_Ashen"
    },
    {
      "x": -4,
      "y": 2,
      "z": 8,
      "name": "Soil_Mud"
    },
    {
      "x": -4,
      "y": 3,
      "z": 8,
      "name": "Soil_Mud"
    },
    {
      "x": -4,
      "y": 4,
      "z": 8,
      "name": "Soil_Mud"
    },
    {
      "x": -4,
      "y": 5,
      "z": 8,
      "name": "Soil_Sand_Ashen"
    },
    {
      "x": -4,
      "y": 0,
      "z": 9,
      "name": "Soil_Sand_Ashen"
    },
    {
      "x": -4,
      "y": 1,
      "z": 9,
      "name": "Soil_Sand_Ashen"
    },
    {
      "x": -4,
      "y": 2,
      "z": 9,
      "name": "Soil_Mud"
    },
    {
      "x": -4,
      "y": 3,
      "z": 9,
      "name": "Soil_Mud"
    },
    {
      "x": -4,
      "y": 4,
      "z": 9,
      "name": "Soil_Mud"
    },
    {
      "x": -4,
      "y": 5,
      "z": 9,
      "name": "Soil_Sand_Ashen"
    },
    {
      "x": -4,
      "y": 0,
      "z": 10,
      "name": "Soil_Sand_Ashen"
    },
    {
      "x": -4,
      "y": 1,
      "z": 10,
      "name": "Soil_Sand_Ashen"
    },
    {
      "x": -4,
      "y": 2,
      "z": 10,
      "name": "Soil_Mud"
    },
    {
      "x": -4,
      "y": 3,
      "z": 10,
      "name": "Soil_Mud"
    },
    {
      "x": -4,
      "y": 4,
      "z": 10,
      "name": "Soil_Mud"
    },
    {
      "x": -4,
      "y": 5,
      "z": 10,
      "name": "Soil_Ash"
    },
    {
      "x": -4,
      "y": 6,
      "z": 10,
      "name": "Plant_Crop_Wheat_Stage_4_Burnt"
    },
    {
      "x": -4,
      "y": 7,
      "z": 10,
      "name": "Plant_Crop_Wheat_Stage_4_Burnt",
      "filler": 1024
    },
    {
      "x": -4,
      "y": 0,
      "z": 11,
      "name": "Soil_Sand_Ashen"
    },
    {
      "x": -4,
      "y": 1,
      "z": 11,
      "name": "Soil_Sand_Ashen"
    },
    {
      "x": -4,
      "y": 2,
      "z": 11,
      "name": "Soil_Mud"
    },
    {
      "x": -4,
      "y": 3,
      "z": 11,
      "name": "Plant_Bush_Dead_Hanging"
    },
    {
      "x": -4,
      "y": 4,
      "z": 11,
      "name": "Plant_Bush_Dead_Hanging"
    },
    {
      "x": -3,
      "y": 0,
      "z": -12,
      "name": "Soil_Sand_Ashen"
    },
    {
      "x": -3,
      "y": 1,
      "z": -12,
      "name": "Soil_Sand_Ashen"
    },
    {
      "x": -3,
      "y": 2,
      "z": -12,
      "name": "Soil_Mud"
    },
    {
      "x": -3,
      "y": 0,
      "z": -11,
      "name": "Soil_Sand_Ashen"
    },
    {
      "x": -3,
      "y": 1,
      "z": -11,
      "name": "Soil_Sand_Ashen"
    },
    {
      "x": -3,
      "y": 2,
      "z": -11,
      "name": "Soil_Mud"
    },
    {
      "x": -3,
      "y": 3,
      "z": -11,
      "name": "Soil_Mud"
    },
    {
      "x": -3,
      "y": 0,
      "z": -10,
      "name": "Soil_Sand_Ashen"
    },
    {
      "x": -3,
      "y": 1,
      "z": -10,
      "name": "Soil_Sand_Ashen"
    },
    {
      "x": -3,
      "y": 2,
      "z": -10,
      "name": "Soil_Mud"
    },
    {
      "x": -3,
      "y": 3,
      "z": -10,
      "name": "Soil_Mud"
    },
    {
      "x": -3,
      "y": 4,
      "z": -10,
      "name": "Soil_Ash"
    },
    {
      "x": -3,
      "y": 5,
      "z": -10,
      "name": "Plant_Bush_Dead_Tall"
    },
    {
      "x": -3,
      "y": 0,
      "z": -9,
      "name": "Soil_Sand_Ashen"
    },
    {
      "x": -3,
      "y": 1,
      "z": -9,
      "name": "Soil_Sand_Ashen"
    },
    {
      "x": -3,
      "y": 2,
      "z": -9,
      "name": "Soil_Mud"
    },
    {
      "x": -3,
      "y": 3,
      "z": -9,
      "name": "Soil_Mud"
    },
    {
      "x": -3,
      "y": 4,
      "z": -9,
      "name": "Soil_Mud"
    },
    {
      "x": -3,
      "y": 5,
      "z": -9,
      "name": "Soil_Ash"
    },
    {
      "x": -3,
      "y": 6,
      "z": -9,
      "name": "Plant_Crop_Wheat_Stage_4_Burnt"
    },
    {
      "x": -3,
      "y": 7,
      "z": -9,
      "name": "Plant_Crop_Wheat_Stage_4_Burnt",
      "filler": 1024
    },
    {
      "x": -3,
      "y": 0,
      "z": -8,
      "name": "Soil_Sand_Ashen"
    },
    {
      "x": -3,
      "y": 1,
      "z": -8,
      "name": "Soil_Sand_Ashen"
    },
    {
      "x": -3,
      "y": 2,
      "z": -8,
      "name": "Soil_Mud"
    },
    {
      "x": -3,
      "y": 3,
      "z": -8,
      "name": "Soil_Mud"
    },
    {
      "x": -3,
      "y": 4,
      "z": -8,
      "name": "Soil_Mud"
    },
    {
      "x": -3,
      "y": 5,
      "z": -8,
      "name": "Soil_Mud"
    },
    {
      "x": -3,
      "y": 6,
      "z": -8,
      "name": "Soil_Ash"
    },
    {
      "x": -3,
      "y": 7,
      "z": -8,
      "name": "Plant_Crop_Wheat_Stage_4_Burnt"
    },
    {
      "x": -3,
      "y": 8,
      "z": -8,
      "name": "Plant_Crop_Wheat_Stage_4_Burnt",
      "filler": 1024
    },
    {
      "x": -3,
      "y": 0,
      "z": -7,
      "name": "Soil_Sand_Ashen"
    },
    {
      "x": -3,
      "y": 1,
      "z": -7,
      "name": "Soil_Sand_Ashen"
    },
    {
      "x": -3,
      "y": 2,
      "z": -7,
      "name": "Soil_Mud"
    },
    {
      "x": -3,
      "y": 3,
      "z": -7,
      "name": "Soil_Mud"
    },
    {
      "x": -3,
      "y": 4,
      "z": -7,
      "name": "Soil_Mud"
    },
    {
      "x": -3,
      "y": 5,
      "z": -7,
      "name": "Soil_Mud"
    },
    {
      "x": -3,
      "y": 6,
      "z": -7,
      "name": "Soil_Ash"
    },
    {
      "x": -3,
      "y": 7,
      "z": -7,
      "name": "Plant_Crop_Wheat_Stage_4_Burnt"
    },
    {
      "x": -3,
      "y": 8,
      "z": -7,
      "name": "Plant_Crop_Wheat_Stage_4_Burnt",
      "filler": 1024
    },
    {
      "x": -3,
      "y": 0,
      "z": -6,
      "name": "Soil_Sand_Ashen"
    },
    {
      "x": -3,
      "y": 1,
      "z": -6,
      "name": "Soil_Sand_Ashen"
    },
    {
      "x": -3,
      "y": 2,
      "z": -6,
      "name": "Soil_Mud"
    },
    {
      "x": -3,
      "y": 3,
      "z": -6,
      "name": "Soil_Mud"
    },
    {
      "x": -3,
      "y": 4,
      "z": -6,
      "name": "Soil_Mud"
    },
    {
      "x": -3,
      "y": 5,
      "z": -6,
      "name": "Soil_Mud"
    },
    {
      "x": -3,
      "y": 6,
      "z": -6,
      "name": "Soil_Ash"
    },
    {
      "x": -3,
      "y": 0,
      "z": -5,
      "name": "Soil_Sand_Ashen"
    },
    {
      "x": -3,
      "y": 1,
      "z": -5,
      "name": "Soil_Sand_Ashen"
    },
    {
      "x": -3,
      "y": 2,
      "z": -5,
      "name": "Soil_Mud"
    },
    {
      "x": -3,
      "y": 3,
      "z": -5,
      "name": "Soil_Mud"
    },
    {
      "x": -3,
      "y": 4,
      "z": -5,
      "name": "Soil_Mud"
    },
    {
      "x": -3,
      "y": 5,
      "z": -5,
      "name": "Soil_Ash"
    },
    {
      "x": -3,
      "y": 0,
      "z": -4,
      "name": "Soil_Sand_Ashen"
    },
    {
      "x": -3,
      "y": 1,
      "z": -4,
      "name": "Soil_Sand_Ashen"
    },
    {
      "x": -3,
      "y": 2,
      "z": -4,
      "name": "Soil_Mud"
    },
    {
      "x": -3,
      "y": 3,
      "z": -4,
      "name": "Soil_Mud"
    },
    {
      "x": -3,
      "y": 4,
      "z": -4,
      "name": "Soil_Ash"
    },
    {
      "x": -3,
      "y": 0,
      "z": -3,
      "name": "Soil_Sand_Ashen"
    },
    {
      "x": -3,
      "y": 1,
      "z": -3,
      "name": "Soil_Sand_Ashen"
    },
    {
      "x": -3,
      "y": 2,
      "z": -3,
      "name": "Soil_Mud"
    },
    {
      "x": -3,
      "y": 3,
      "z": -3,
      "name": "Soil_Ash"
    },
    {
      "x": -3,
      "y": 0,
      "z": -2,
      "name": "Soil_Sand_Ashen"
    },
    {
      "x": -3,
      "y": 1,
      "z": -2,
      "name": "Soil_Sand_Ashen"
    },
    {
      "x": -3,
      "y": 2,
      "z": -2,
      "name": "Soil_Mud"
    },
    {
      "x": -3,
      "y": 3,
      "z": -2,
      "name": "Soil_Ash"
    },
    {
      "x": -3,
      "y": 0,
      "z": -1,
      "name": "Soil_Sand_Ashen"
    },
    {
      "x": -3,
      "y": 1,
      "z": -1,
      "name": "Soil_Sand_Ashen"
    },
    {
      "x": -3,
      "y": 2,
      "z": -1,
      "name": "Soil_Mud"
    },
    {
      "x": -3,
      "y": 3,
      "z": -1,
      "name": "Soil_Ash"
    },
    {
      "x": -3,
      "y": 0,
      "z": 0,
      "name": "Soil_Sand_Ashen"
    },
    {
      "x": -3,
      "y": 1,
      "z": 0,
      "name": "Soil_Sand_Ashen"
    },
    {
      "x": -3,
      "y": 2,
      "z": 0,
      "name": "Soil_Mud"
    },
    {
      "x": -3,
      "y": 3,
      "z": 0,
      "name": "Soil_Ash"
    },
    {
      "x": -3,
      "y": 4,
      "z": 0,
      "name": "Rock_Gem_Voidstone",
      "rotation": 6
    },
    {
      "x": -3,
      "y": 5,
      "z": 0,
      "name": "Rock_Crystal_Purple_Medium",
      "rotation": 6
    },
    {
      "x": -3,
      "y": 0,
      "z": 1,
      "name": "Soil_Sand_Ashen"
    },
    {
      "x": -3,
      "y": 1,
      "z": 1,
      "name": "Soil_Sand_Ashen"
    },
    {
      "x": -3,
      "y": 2,
      "z": 1,
      "name": "Soil_Mud"
    },
    {
      "x": -3,
      "y": 3,
      "z": 1,
      "name": "Soil_Mud"
    },
    {
      "x": -3,
      "y": 4,
      "z": 1,
      "name": "Rock_Crystal_Purple_Block"
    },
    {
      "x": -3,
      "y": 5,
      "z": 1,
      "name": "Rock_Crystal_Purple_Block"
    },
    {
      "x": -3,
      "y": 6,
      "z": 1,
      "name": "Rock_Crystal_Purple_Large"
    },
    {
      "x": -3,
      "y": 0,
      "z": 2,
      "name": "Soil_Sand_Ashen"
    },
    {
      "x": -3,
      "y": 1,
      "z": 2,
      "name": "Soil_Sand_Ashen"
    },
    {
      "x": -3,
      "y": 2,
      "z": 2,
      "name": "Soil_Mud"
    },
    {
      "x": -3,
      "y": 3,
      "z": 2,
      "name": "Soil_Mud"
    },
    {
      "x": -3,
      "y": 4,
      "z": 2,
      "name": "Soil_Ash"
    },
    {
      "x": -3,
      "y": 5,
      "z": 2,
      "name": "Soil_Ash"
    },
    {
      "x": -3,
      "y": 0,
      "z": 3,
      "name": "Soil_Sand_Ashen"
    },
    {
      "x": -3,
      "y": 1,
      "z": 3,
      "name": "Soil_Sand_Ashen"
    },
    {
      "x": -3,
      "y": 2,
      "z": 3,
      "name": "Soil_Mud"
    },
    {
      "x": -3,
      "y": 3,
      "z": 3,
      "name": "Soil_Mud"
    },
    {
      "x": -3,
      "y": 4,
      "z": 3,
      "name": "Soil_Mud"
    },
    {
      "x": -3,
      "y": 5,
      "z": 3,
      "name": "Soil_Mud"
    },
    {
      "x": -3,
      "y": 6,
      "z": 3,
      "name": "Soil_Sand_Ashen"
    },
    {
      "x": -3,
      "y": 0,
      "z": 4,
      "name": "Soil_Sand_Ashen"
    },
    {
      "x": -3,
      "y": 1,
      "z": 4,
      "name": "Soil_Sand_Ashen"
    },
    {
      "x": -3,
      "y": 2,
      "z": 4,
      "name": "Soil_Mud"
    },
    {
      "x": -3,
      "y": 3,
      "z": 4,
      "name": "Soil_Mud"
    },
    {
      "x": -3,
      "y": 4,
      "z": 4,
      "name": "Soil_Mud"
    },
    {
      "x": -3,
      "y": 5,
      "z": 4,
      "name": "Soil_Mud"
    },
    {
      "x": -3,
      "y": 6,
      "z": 4,
      "name": "Soil_Sand_Ashen"
    },
    {
      "x": -3,
      "y": 0,
      "z": 5,
      "name": "Soil_Sand_Ashen"
    },
    {
      "x": -3,
      "y": 1,
      "z": 5,
      "name": "Soil_Sand_Ashen"
    },
    {
      "x": -3,
      "y": 2,
      "z": 5,
      "name": "Soil_Mud"
    },
    {
      "x": -3,
      "y": 3,
      "z": 5,
      "name": "Soil_Mud"
    },
    {
      "x": -3,
      "y": 4,
      "z": 5,
      "name": "Soil_Mud"
    },
    {
      "x": -3,
      "y": 5,
      "z": 5,
      "name": "Soil_Mud"
    },
    {
      "x": -3,
      "y": 6,
      "z": 5,
      "name": "Soil_Sand_Ashen"
    },
    {
      "x": -3,
      "y": 7,
      "z": 5,
      "name": "Plant_Flower_Bushy_Grey"
    },
    {
      "x": -3,
      "y": 8,
      "z": 5,
      "name": "Plant_Flower_Bushy_Grey",
      "filler": 1024
    },
    {
      "x": -3,
      "y": 0,
      "z": 6,
      "name": "Soil_Sand_Ashen"
    },
    {
      "x": -3,
      "y": 1,
      "z": 6,
      "name": "Soil_Sand_Ashen"
    },
    {
      "x": -3,
      "y": 2,
      "z": 6,
      "name": "Soil_Mud"
    },
    {
      "x": -3,
      "y": 3,
      "z": 6,
      "name": "Soil_Mud"
    },
    {
      "x": -3,
      "y": 4,
      "z": 6,
      "name": "Soil_Mud"
    },
    {
      "x": -3,
      "y": 5,
      "z": 6,
      "name": "Soil_Mud"
    },
    {
      "x": -3,
      "y": 6,
      "z": 6,
      "name": "Soil_Sand_Ashen"
    },
    {
      "x": -3,
      "y": 0,
      "z": 7,
      "name": "Soil_Sand_Ashen"
    },
    {
      "x": -3,
      "y": 1,
      "z": 7,
      "name": "Soil_Sand_Ashen"
    },
    {
      "x": -3,
      "y": 2,
      "z": 7,
      "name": "Soil_Mud"
    },
    {
      "x": -3,
      "y": 3,
      "z": 7,
      "name": "Soil_Mud"
    },
    {
      "x": -3,
      "y": 4,
      "z": 7,
      "name": "Soil_Mud"
    },
    {
      "x": -3,
      "y": 5,
      "z": 7,
      "name": "Soil_Mud"
    },
    {
      "x": -3,
      "y": 6,
      "z": 7,
      "name": "Soil_Sand_Ashen"
    },
    {
      "x": -3,
      "y": 0,
      "z": 8,
      "name": "Soil_Sand_Ashen"
    },
    {
      "x": -3,
      "y": 1,
      "z": 8,
      "name": "Soil_Sand_Ashen"
    },
    {
      "x": -3,
      "y": 2,
      "z": 8,
      "name": "Soil_Mud"
    },
    {
      "x": -3,
      "y": 3,
      "z": 8,
      "name": "Soil_Mud"
    },
    {
      "x": -3,
      "y": 4,
      "z": 8,
      "name": "Soil_Mud"
    },
    {
      "x": -3,
      "y": 5,
      "z": 8,
      "name": "Soil_Sand_Ashen"
    },
    {
      "x": -3,
      "y": 0,
      "z": 9,
      "name": "Soil_Sand_Ashen"
    },
    {
      "x": -3,
      "y": 1,
      "z": 9,
      "name": "Soil_Sand_Ashen"
    },
    {
      "x": -3,
      "y": 2,
      "z": 9,
      "name": "Soil_Mud"
    },
    {
      "x": -3,
      "y": 3,
      "z": 9,
      "name": "Soil_Mud"
    },
    {
      "x": -3,
      "y": 4,
      "z": 9,
      "name": "Soil_Mud"
    },
    {
      "x": -3,
      "y": 5,
      "z": 9,
      "name": "Soil_Ash"
    },
    {
      "x": -3,
      "y": 0,
      "z": 10,
      "name": "Soil_Sand_Ashen"
    },
    {
      "x": -3,
      "y": 1,
      "z": 10,
      "name": "Soil_Sand_Ashen"
    },
    {
      "x": -3,
      "y": 2,
      "z": 10,
      "name": "Soil_Mud"
    },
    {
      "x": -3,
      "y": 3,
      "z": 10,
      "name": "Soil_Mud"
    },
    {
      "x": -3,
      "y": 4,
      "z": 10,
      "name": "Soil_Ash"
    },
    {
      "x": -3,
      "y": 5,
      "z": 10,
      "name": "Plant_Crop_Wheat_Stage_4_Burnt"
    },
    {
      "x": -3,
      "y": 6,
      "z": 10,
      "name": "Plant_Crop_Wheat_Stage_4_Burnt",
      "filler": 1024
    },
    {
      "x": -3,
      "y": 0,
      "z": 11,
      "name": "Soil_Sand_Ashen"
    },
    {
      "x": -3,
      "y": 1,
      "z": 11,
      "name": "Soil_Sand_Ashen"
    },
    {
      "x": -3,
      "y": 2,
      "z": 11,
      "name": "Soil_Mud"
    },
    {
      "x": -3,
      "y": 3,
      "z": 11,
      "name": "Plant_Bush_Dead_Hanging"
    },
    {
      "x": -2,
      "y": 0,
      "z": -12,
      "name": "Soil_Sand_Ashen"
    },
    {
      "x": -2,
      "y": 1,
      "z": -12,
      "name": "Soil_Sand_Ashen"
    },
    {
      "x": -2,
      "y": 0,
      "z": -11,
      "name": "Soil_Sand_Ashen"
    },
    {
      "x": -2,
      "y": 1,
      "z": -11,
      "name": "Soil_Sand_Ashen"
    },
    {
      "x": -2,
      "y": 2,
      "z": -11,
      "name": "Soil_Mud"
    },
    {
      "x": -2,
      "y": 3,
      "z": -11,
      "name": "Soil_Mud"
    },
    {
      "x": -2,
      "y": 0,
      "z": -10,
      "name": "Soil_Sand_Ashen"
    },
    {
      "x": -2,
      "y": 1,
      "z": -10,
      "name": "Soil_Sand_Ashen"
    },
    {
      "x": -2,
      "y": 2,
      "z": -10,
      "name": "Soil_Mud"
    },
    {
      "x": -2,
      "y": 3,
      "z": -10,
      "name": "Soil_Mud"
    },
    {
      "x": -2,
      "y": 4,
      "z": -10,
      "name": "Soil_Ash"
    },
    {
      "x": -2,
      "y": 0,
      "z": -9,
      "name": "Soil_Sand_Ashen"
    },
    {
      "x": -2,
      "y": 1,
      "z": -9,
      "name": "Soil_Sand_Ashen"
    },
    {
      "x": -2,
      "y": 2,
      "z": -9,
      "name": "Soil_Mud"
    },
    {
      "x": -2,
      "y": 3,
      "z": -9,
      "name": "Soil_Mud"
    },
    {
      "x": -2,
      "y": 4,
      "z": -9,
      "name": "Soil_Ash"
    },
    {
      "x": -2,
      "y": 0,
      "z": -8,
      "name": "Soil_Sand_Ashen"
    },
    {
      "x": -2,
      "y": 1,
      "z": -8,
      "name": "Soil_Sand_Ashen"
    },
    {
      "x": -2,
      "y": 2,
      "z": -8,
      "name": "Soil_Mud"
    },
    {
      "x": -2,
      "y": 3,
      "z": -8,
      "name": "Soil_Mud"
    },
    {
      "x": -2,
      "y": 4,
      "z": -8,
      "name": "Soil_Mud"
    },
    {
      "x": -2,
      "y": 5,
      "z": -8,
      "name": "Soil_Ash"
    },
    {
      "x": -2,
      "y": 0,
      "z": -7,
      "name": "Soil_Sand_Ashen"
    },
    {
      "x": -2,
      "y": 1,
      "z": -7,
      "name": "Soil_Sand_Ashen"
    },
    {
      "x": -2,
      "y": 2,
      "z": -7,
      "name": "Soil_Mud"
    },
    {
      "x": -2,
      "y": 3,
      "z": -7,
      "name": "Soil_Mud"
    },
    {
      "x": -2,
      "y": 4,
      "z": -7,
      "name": "Soil_Mud"
    },
    {
      "x": -2,
      "y": 5,
      "z": -7,
      "name": "Soil_Mud"
    },
    {
      "x": -2,
      "y": 6,
      "z": -7,
      "name": "Soil_Ash"
    },
    {
      "x": -2,
      "y": 0,
      "z": -6,
      "name": "Soil_Sand_Ashen"
    },
    {
      "x": -2,
      "y": 1,
      "z": -6,
      "name": "Soil_Sand_Ashen"
    },
    {
      "x": -2,
      "y": 2,
      "z": -6,
      "name": "Soil_Mud"
    },
    {
      "x": -2,
      "y": 3,
      "z": -6,
      "name": "Soil_Mud"
    },
    {
      "x": -2,
      "y": 4,
      "z": -6,
      "name": "Soil_Mud"
    },
    {
      "x": -2,
      "y": 5,
      "z": -6,
      "name": "Soil_Mud"
    },
    {
      "x": -2,
      "y": 6,
      "z": -6,
      "name": "Soil_Mud"
    },
    {
      "x": -2,
      "y": 0,
      "z": -5,
      "name": "Soil_Sand_Ashen"
    },
    {
      "x": -2,
      "y": 1,
      "z": -5,
      "name": "Soil_Sand_Ashen"
    },
    {
      "x": -2,
      "y": 2,
      "z": -5,
      "name": "Soil_Mud"
    },
    {
      "x": -2,
      "y": 3,
      "z": -5,
      "name": "Soil_Mud"
    },
    {
      "x": -2,
      "y": 4,
      "z": -5,
      "name": "Soil_Mud"
    },
    {
      "x": -2,
      "y": 5,
      "z": -5,
      "name": "Soil_Mud"
    },
    {
      "x": -2,
      "y": 0,
      "z": -4,
      "name": "Soil_Sand_Ashen"
    },
    {
      "x": -2,
      "y": 1,
      "z": -4,
      "name": "Soil_Sand_Ashen"
    },
    {
      "x": -2,
      "y": 2,
      "z": -4,
      "name": "Soil_Mud"
    },
    {
      "x": -2,
      "y": 3,
      "z": -4,
      "name": "Soil_Mud"
    },
    {
      "x": -2,
      "y": 4,
      "z": -4,
      "name": "Soil_Mud"
    },
    {
      "x": -2,
      "y": 0,
      "z": -3,
      "name": "Soil_Sand_Ashen"
    },
    {
      "x": -2,
      "y": 1,
      "z": -3,
      "name": "Soil_Sand_Ashen"
    },
    {
      "x": -2,
      "y": 2,
      "z": -3,
      "name": "Soil_Mud"
    },
    {
      "x": -2,
      "y": 3,
      "z": -3,
      "name": "Soil_Mud"
    },
    {
      "x": -2,
      "y": 4,
      "z": -3,
      "name": "Deco_Bone_Skulls_Feran"
    },
    {
      "x": -2,
      "y": 0,
      "z": -2,
      "name": "Soil_Sand_Ashen"
    },
    {
      "x": -2,
      "y": 1,
      "z": -2,
      "name": "Soil_Sand_Ashen"
    },
    {
      "x": -2,
      "y": 2,
      "z": -2,
      "name": "Soil_Mud"
    },
    {
      "x": -2,
      "y": 3,
      "z": -2,
      "name": "Soil_Ash"
    },
    {
      "x": -2,
      "y": 0,
      "z": -1,
      "name": "Soil_Sand_Ashen"
    },
    {
      "x": -2,
      "y": 1,
      "z": -1,
      "name": "Soil_Sand_Ashen"
    },
    {
      "x": -2,
      "y": 2,
      "z": -1,
      "name": "Soil_Mud"
    },
    {
      "x": -2,
      "y": 3,
      "z": -1,
      "name": "Soil_Ash"
    },
    {
      "x": -2,
      "y": 0,
      "z": 0,
      "name": "Soil_Sand_Ashen"
    },
    {
      "x": -2,
      "y": 1,
      "z": 0,
      "name": "Soil_Sand_Ashen"
    },
    {
      "x": -2,
      "y": 2,
      "z": 0,
      "name": "Soil_Mud"
    },
    {
      "x": -2,
      "y": 3,
      "z": 0,
      "name": "Soil_Sand_Ashen"
    },
    {
      "x": -2,
      "y": 0,
      "z": 1,
      "name": "Soil_Sand_Ashen"
    },
    {
      "x": -2,
      "y": 1,
      "z": 1,
      "name": "Soil_Sand_Ashen"
    },
    {
      "x": -2,
      "y": 2,
      "z": 1,
      "name": "Soil_Mud"
    },
    {
      "x": -2,
      "y": 3,
      "z": 1,
      "name": "Soil_Sand_Ashen"
    },
    {
      "x": -2,
      "y": 0,
      "z": 2,
      "name": "Soil_Sand_Ashen"
    },
    {
      "x": -2,
      "y": 1,
      "z": 2,
      "name": "Soil_Sand_Ashen"
    },
    {
      "x": -2,
      "y": 2,
      "z": 2,
      "name": "Soil_Mud"
    },
    {
      "x": -2,
      "y": 3,
      "z": 2,
      "name": "Soil_Mud"
    },
    {
      "x": -2,
      "y": 4,
      "z": 2,
      "name": "Soil_Sand_Ashen"
    },
    {
      "x": -2,
      "y": 5,
      "z": 2,
      "name": "Soil_Sand_Ashen"
    },
    {
      "x": -2,
      "y": 0,
      "z": 3,
      "name": "Soil_Sand_Ashen"
    },
    {
      "x": -2,
      "y": 1,
      "z": 3,
      "name": "Soil_Sand_Ashen"
    },
    {
      "x": -2,
      "y": 2,
      "z": 3,
      "name": "Soil_Mud"
    },
    {
      "x": -2,
      "y": 3,
      "z": 3,
      "name": "Soil_Mud"
    },
    {
      "x": -2,
      "y": 4,
      "z": 3,
      "name": "Soil_Mud"
    },
    {
      "x": -2,
      "y": 5,
      "z": 3,
      "name": "Soil_Mud"
    },
    {
      "x": -2,
      "y": 6,
      "z": 3,
      "name": "Soil_Sand_Ashen"
    },
    {
      "x": -2,
      "y": 7,
      "z": 3,
      "name": "Plant_Flower_Bushy_Grey"
    },
    {
      "x": -2,
      "y": 8,
      "z": 3,
      "name": "Plant_Flower_Bushy_Grey",
      "filler": 1024
    },
    {
      "x": -2,
      "y": 0,
      "z": 4,
      "name": "Soil_Sand_Ashen"
    },
    {
      "x": -2,
      "y": 1,
      "z": 4,
      "name": "Soil_Sand_Ashen"
    },
    {
      "x": -2,
      "y": 2,
      "z": 4,
      "name": "Soil_Mud"
    },
    {
      "x": -2,
      "y": 3,
      "z": 4,
      "name": "Soil_Mud"
    },
    {
      "x": -2,
      "y": 4,
      "z": 4,
      "name": "Soil_Mud"
    },
    {
      "x": -2,
      "y": 5,
      "z": 4,
      "name": "Soil_Mud"
    },
    {
      "x": -2,
      "y": 6,
      "z": 4,
      "name": "Soil_Sand_Ashen"
    },
    {
      "x": -2,
      "y": 0,
      "z": 5,
      "name": "Soil_Sand_Ashen"
    },
    {
      "x": -2,
      "y": 1,
      "z": 5,
      "name": "Soil_Sand_Ashen"
    },
    {
      "x": -2,
      "y": 2,
      "z": 5,
      "name": "Soil_Mud"
    },
    {
      "x": -2,
      "y": 3,
      "z": 5,
      "name": "Soil_Mud"
    },
    {
      "x": -2,
      "y": 4,
      "z": 5,
      "name": "Soil_Mud"
    },
    {
      "x": -2,
      "y": 5,
      "z": 5,
      "name": "Soil_Mud"
    },
    {
      "x": -2,
      "y": 6,
      "z": 5,
      "name": "Soil_Sand_Ashen"
    },
    {
      "x": -2,
      "y": 0,
      "z": 6,
      "name": "Soil_Sand_Ashen"
    },
    {
      "x": -2,
      "y": 1,
      "z": 6,
      "name": "Soil_Sand_Ashen"
    },
    {
      "x": -2,
      "y": 2,
      "z": 6,
      "name": "Soil_Mud"
    },
    {
      "x": -2,
      "y": 3,
      "z": 6,
      "name": "Soil_Mud"
    },
    {
      "x": -2,
      "y": 4,
      "z": 6,
      "name": "Soil_Mud"
    },
    {
      "x": -2,
      "y": 5,
      "z": 6,
      "name": "Soil_Mud"
    },
    {
      "x": -2,
      "y": 6,
      "z": 6,
      "name": "Soil_Sand_Ashen"
    },
    {
      "x": -2,
      "y": 0,
      "z": 7,
      "name": "Soil_Sand_Ashen"
    },
    {
      "x": -2,
      "y": 1,
      "z": 7,
      "name": "Soil_Sand_Ashen"
    },
    {
      "x": -2,
      "y": 2,
      "z": 7,
      "name": "Soil_Mud"
    },
    {
      "x": -2,
      "y": 3,
      "z": 7,
      "name": "Soil_Mud"
    },
    {
      "x": -2,
      "y": 4,
      "z": 7,
      "name": "Soil_Mud"
    },
    {
      "x": -2,
      "y": 5,
      "z": 7,
      "name": "Soil_Sand_Ashen"
    },
    {
      "x": -2,
      "y": 0,
      "z": 8,
      "name": "Soil_Sand_Ashen"
    },
    {
      "x": -2,
      "y": 1,
      "z": 8,
      "name": "Soil_Sand_Ashen"
    },
    {
      "x": -2,
      "y": 2,
      "z": 8,
      "name": "Soil_Mud"
    },
    {
      "x": -2,
      "y": 3,
      "z": 8,
      "name": "Soil_Mud"
    },
    {
      "x": -2,
      "y": 4,
      "z": 8,
      "name": "Soil_Mud"
    },
    {
      "x": -2,
      "y": 5,
      "z": 8,
      "name": "Soil_Ash"
    },
    {
      "x": -2,
      "y": 0,
      "z": 9,
      "name": "Soil_Sand_Ashen"
    },
    {
      "x": -2,
      "y": 1,
      "z": 9,
      "name": "Soil_Sand_Ashen"
    },
    {
      "x": -2,
      "y": 2,
      "z": 9,
      "name": "Soil_Mud"
    },
    {
      "x": -2,
      "y": 3,
      "z": 9,
      "name": "Soil_Mud"
    },
    {
      "x": -2,
      "y": 4,
      "z": 9,
      "name": "Soil_Mud"
    },
    {
      "x": -2,
      "y": 0,
      "z": 10,
      "name": "Soil_Sand_Ashen"
    },
    {
      "x": -2,
      "y": 1,
      "z": 10,
      "name": "Soil_Sand_Ashen"
    },
    {
      "x": -2,
      "y": 2,
      "z": 10,
      "name": "Soil_Mud"
    },
    {
      "x": -2,
      "y": 3,
      "z": 10,
      "name": "Soil_Mud"
    },
    {
      "x": -2,
      "y": 4,
      "z": 10,
      "name": "Plant_Bush_Dead_Tall"
    },
    {
      "x": -2,
      "y": 0,
      "z": 11,
      "name": "Soil_Sand_Ashen"
    },
    {
      "x": -2,
      "y": 1,
      "z": 11,
      "name": "Soil_Sand_Ashen"
    },
    {
      "x": -1,
      "y": 0,
      "z": -11,
      "name": "Soil_Sand_Ashen"
    },
    {
      "x": -1,
      "y": 1,
      "z": -11,
      "name": "Soil_Sand_Ashen"
    },
    {
      "x": -1,
      "y": 2,
      "z": -11,
      "name": "Soil_Mud"
    },
    {
      "x": -1,
      "y": 3,
      "z": -11,
      "name": "Plant_Bush_Dead_Hanging"
    },
    {
      "x": -1,
      "y": 0,
      "z": -10,
      "name": "Soil_Sand_Ashen"
    },
    {
      "x": -1,
      "y": 1,
      "z": -10,
      "name": "Soil_Sand_Ashen"
    },
    {
      "x": -1,
      "y": 2,
      "z": -10,
      "name": "Soil_Mud"
    },
    {
      "x": -1,
      "y": 3,
      "z": -10,
      "name": "Soil_Ash"
    },
    {
      "x": -1,
      "y": 4,
      "z": -10,
      "name": "Plant_Bush_Dead_Tall"
    },
    {
      "x": -1,
      "y": 0,
      "z": -9,
      "name": "Soil_Sand_Ashen"
    },
    {
      "x": -1,
      "y": 1,
      "z": -9,
      "name": "Soil_Sand_Ashen"
    },
    {
      "x": -1,
      "y": 2,
      "z": -9,
      "name": "Soil_Mud"
    },
    {
      "x": -1,
      "y": 3,
      "z": -9,
      "name": "Soil_Mud"
    },
    {
      "x": -1,
      "y": 4,
      "z": -9,
      "name": "Soil_Ash"
    },
    {
      "x": -1,
      "y": 0,
      "z": -8,
      "name": "Soil_Sand_Ashen"
    },
    {
      "x": -1,
      "y": 1,
      "z": -8,
      "name": "Soil_Sand_Ashen"
    },
    {
      "x": -1,
      "y": 2,
      "z": -8,
      "name": "Soil_Mud"
    },
    {
      "x": -1,
      "y": 3,
      "z": -8,
      "name": "Soil_Mud"
    },
    {
      "x": -1,
      "y": 4,
      "z": -8,
      "name": "Soil_Mud"
    },
    {
      "x": -1,
      "y": 5,
      "z": -8,
      "name": "Soil_Mud"
    },
    {
      "x": -1,
      "y": 0,
      "z": -7,
      "name": "Soil_Sand_Ashen"
    },
    {
      "x": -1,
      "y": 1,
      "z": -7,
      "name": "Soil_Sand_Ashen"
    },
    {
      "x": -1,
      "y": 2,
      "z": -7,
      "name": "Soil_Mud"
    },
    {
      "x": -1,
      "y": 3,
      "z": -7,
      "name": "Soil_Mud"
    },
    {
      "x": -1,
      "y": 4,
      "z": -7,
      "name": "Soil_Mud"
    },
    {
      "x": -1,
      "y": 5,
      "z": -7,
      "name": "Soil_Mud"
    },
    {
      "x": -1,
      "y": 0,
      "z": -6,
      "name": "Soil_Sand_Ashen"
    },
    {
      "x": -1,
      "y": 1,
      "z": -6,
      "name": "Soil_Sand_Ashen"
    },
    {
      "x": -1,
      "y": 2,
      "z": -6,
      "name": "Soil_Mud"
    },
    {
      "x": -1,
      "y": 3,
      "z": -6,
      "name": "Soil_Mud"
    },
    {
      "x": -1,
      "y": 4,
      "z": -6,
      "name": "Soil_Mud"
    },
    {
      "x": -1,
      "y": 5,
      "z": -6,
      "name": "Soil_Mud"
    },
    {
      "x": -1,
      "y": 0,
      "z": -5,
      "name": "Soil_Sand_Ashen"
    },
    {
      "x": -1,
      "y": 1,
      "z": -5,
      "name": "Soil_Sand_Ashen"
    },
    {
      "x": -1,
      "y": 2,
      "z": -5,
      "name": "Soil_Mud"
    },
    {
      "x": -1,
      "y": 3,
      "z": -5,
      "name": "Soil_Mud"
    },
    {
      "x": -1,
      "y": 4,
      "z": -5,
      "name": "Soil_Mud"
    },
    {
      "x": -1,
      "y": 5,
      "z": -5,
      "name": "Soil_Mud"
    },
    {
      "x": -1,
      "y": 0,
      "z": -4,
      "name": "Soil_Sand_Ashen"
    },
    {
      "x": -1,
      "y": 1,
      "z": -4,
      "name": "Soil_Sand_Ashen"
    },
    {
      "x": -1,
      "y": 2,
      "z": -4,
      "name": "Soil_Mud"
    },
    {
      "x": -1,
      "y": 3,
      "z": -4,
      "name": "Soil_Mud"
    },
    {
      "x": -1,
      "y": 0,
      "z": -3,
      "name": "Soil_Sand_Ashen"
    },
    {
      "x": -1,
      "y": 1,
      "z": -3,
      "name": "Soil_Sand_Ashen"
    },
    {
      "x": -1,
      "y": 2,
      "z": -3,
      "name": "Soil_Mud"
    },
    {
      "x": -1,
      "y": 3,
      "z": -3,
      "name": "Soil_Mud"
    },
    {
      "x": -1,
      "y": 0,
      "z": -2,
      "name": "Soil_Sand_Ashen"
    },
    {
      "x": -1,
      "y": 1,
      "z": -2,
      "name": "Soil_Sand_Ashen"
    },
    {
      "x": -1,
      "y": 2,
      "z": -2,
      "name": "Soil_Mud"
    },
    {
      "x": -1,
      "y": 3,
      "z": -2,
      "name": "Soil_Ash"
    },
    {
      "x": -1,
      "y": 0,
      "z": -1,
      "name": "Soil_Sand_Ashen"
    },
    {
      "x": -1,
      "y": 1,
      "z": -1,
      "name": "Soil_Sand_Ashen"
    },
    {
      "x": -1,
      "y": 2,
      "z": -1,
      "name": "Soil_Mud"
    },
    {
      "x": -1,
      "y": 3,
      "z": -1,
      "name": "Soil_Ash"
    },
    {
      "x": -1,
      "y": 0,
      "z": 0,
      "name": "Soil_Sand_Ashen"
    },
    {
      "x": -1,
      "y": 1,
      "z": 0,
      "name": "Soil_Sand_Ashen"
    },
    {
      "x": -1,
      "y": 2,
      "z": 0,
      "name": "Soil_Mud"
    },
    {
      "x": -1,
      "y": 3,
      "z": 0,
      "name": "Soil_Ash"
    },
    {
      "x": -1,
      "y": 0,
      "z": 1,
      "name": "Soil_Sand_Ashen"
    },
    {
      "x": -1,
      "y": 1,
      "z": 1,
      "name": "Soil_Sand_Ashen"
    },
    {
      "x": -1,
      "y": 2,
      "z": 1,
      "name": "Soil_Mud"
    },
    {
      "x": -1,
      "y": 3,
      "z": 1,
      "name": "Soil_Sand_Ashen"
    },
    {
      "x": -1,
      "y": 0,
      "z": 2,
      "name": "Soil_Sand_Ashen"
    },
    {
      "x": -1,
      "y": 1,
      "z": 2,
      "name": "Soil_Sand_Ashen"
    },
    {
      "x": -1,
      "y": 2,
      "z": 2,
      "name": "Soil_Mud"
    },
    {
      "x": -1,
      "y": 3,
      "z": 2,
      "name": "Soil_Mud"
    },
    {
      "x": -1,
      "y": 4,
      "z": 2,
      "name": "Soil_Sand_Ashen"
    },
    {
      "x": -1,
      "y": 0,
      "z": 3,
      "name": "Soil_Sand_Ashen"
    },
    {
      "x": -1,
      "y": 1,
      "z": 3,
      "name": "Soil_Sand_Ashen"
    },
    {
      "x": -1,
      "y": 2,
      "z": 3,
      "name": "Soil_Mud"
    },
    {
      "x": -1,
      "y": 3,
      "z": 3,
      "name": "Soil_Mud"
    },
    {
      "x": -1,
      "y": 4,
      "z": 3,
      "name": "Soil_Mud"
    },
    {
      "x": -1,
      "y": 5,
      "z": 3,
      "name": "Soil_Sand_Ashen"
    },
    {
      "x": -1,
      "y": 0,
      "z": 4,
      "name": "Soil_Sand_Ashen"
    },
    {
      "x": -1,
      "y": 1,
      "z": 4,
      "name": "Soil_Sand_Ashen"
    },
    {
      "x": -1,
      "y": 2,
      "z": 4,
      "name": "Soil_Mud"
    },
    {
      "x": -1,
      "y": 3,
      "z": 4,
      "name": "Soil_Mud"
    },
    {
      "x": -1,
      "y": 4,
      "z": 4,
      "name": "Soil_Mud"
    },
    {
      "x": -1,
      "y": 5,
      "z": 4,
      "name": "Soil_Sand_Ashen"
    },
    {
      "x": -1,
      "y": 0,
      "z": 5,
      "name": "Soil_Sand_Ashen"
    },
    {
      "x": -1,
      "y": 1,
      "z": 5,
      "name": "Soil_Sand_Ashen"
    },
    {
      "x": -1,
      "y": 2,
      "z": 5,
      "name": "Soil_Mud"
    },
    {
      "x": -1,
      "y": 3,
      "z": 5,
      "name": "Soil_Mud"
    },
    {
      "x": -1,
      "y": 4,
      "z": 5,
      "name": "Soil_Mud"
    },
    {
      "x": -1,
      "y": 5,
      "z": 5,
      "name": "Soil_Sand_Ashen"
    },
    {
      "x": -1,
      "y": 0,
      "z": 6,
      "name": "Soil_Sand_Ashen"
    },
    {
      "x": -1,
      "y": 1,
      "z": 6,
      "name": "Soil_Sand_Ashen"
    },
    {
      "x": -1,
      "y": 2,
      "z": 6,
      "name": "Soil_Mud"
    },
    {
      "x": -1,
      "y": 3,
      "z": 6,
      "name": "Soil_Mud"
    },
    {
      "x": -1,
      "y": 4,
      "z": 6,
      "name": "Soil_Mud"
    },
    {
      "x": -1,
      "y": 5,
      "z": 6,
      "name": "Soil_Sand_Ashen"
    },
    {
      "x": -1,
      "y": 0,
      "z": 7,
      "name": "Soil_Sand_Ashen"
    },
    {
      "x": -1,
      "y": 1,
      "z": 7,
      "name": "Soil_Sand_Ashen"
    },
    {
      "x": -1,
      "y": 2,
      "z": 7,
      "name": "Soil_Mud"
    },
    {
      "x": -1,
      "y": 3,
      "z": 7,
      "name": "Soil_Mud"
    },
    {
      "x": -1,
      "y": 4,
      "z": 7,
      "name": "Soil_Mud"
    },
    {
      "x": -1,
      "y": 5,
      "z": 7,
      "name": "Soil_Ash"
    },
    {
      "x": -1,
      "y": 0,
      "z": 8,
      "name": "Soil_Sand_Ashen"
    },
    {
      "x": -1,
      "y": 1,
      "z": 8,
      "name": "Soil_Sand_Ashen"
    },
    {
      "x": -1,
      "y": 2,
      "z": 8,
      "name": "Soil_Mud"
    },
    {
      "x": -1,
      "y": 3,
      "z": 8,
      "name": "Soil_Mud"
    },
    {
      "x": -1,
      "y": 4,
      "z": 8,
      "name": "Soil_Mud"
    },
    {
      "x": -1,
      "y": 5,
      "z": 8,
      "name": "Plant_Bush_Dead_Tall"
    },
    {
      "x": -1,
      "y": 0,
      "z": 9,
      "name": "Soil_Sand_Ashen"
    },
    {
      "x": -1,
      "y": 1,
      "z": 9,
      "name": "Soil_Sand_Ashen"
    },
    {
      "x": -1,
      "y": 2,
      "z": 9,
      "name": "Soil_Mud"
    },
    {
      "x": -1,
      "y": 3,
      "z": 9,
      "name": "Soil_Sand_Ashen"
    },
    {
      "x": -1,
      "y": 4,
      "z": 9,
      "name": "Soil_Sand_Ashen"
    },
    {
      "x": -1,
      "y": 0,
      "z": 10,
      "name": "Soil_Sand_Ashen"
    },
    {
      "x": 0,
      "y": 0,
      "z": -11,
      "name": "Soil_Sand_Ashen"
    },
    {
      "x": 0,
      "y": 0,
      "z": -10,
      "name": "Soil_Sand_Ashen"
    },
    {
      "x": 0,
      "y": 1,
      "z": -10,
      "name": "Soil_Sand_Ashen"
    },
    {
      "x": 0,
      "y": 2,
      "z": -10,
      "name": "Soil_Mud"
    },
    {
      "x": 0,
      "y": 3,
      "z": -10,
      "name": "Soil_Ash"
    },
    {
      "x": 0,
      "y": 0,
      "z": -9,
      "name": "Soil_Sand_Ashen"
    },
    {
      "x": 0,
      "y": 1,
      "z": -9,
      "name": "Soil_Sand_Ashen"
    },
    {
      "x": 0,
      "y": 2,
      "z": -9,
      "name": "Soil_Mud"
    },
    {
      "x": 0,
      "y": 3,
      "z": -9,
      "name": "Soil_Mud"
    },
    {
      "x": 0,
      "y": 4,
      "z": -9,
      "name": "Soil_Ash"
    },
    {
      "x": 0,
      "y": 0,
      "z": -8,
      "name": "Soil_Sand_Ashen"
    },
    {
      "x": 0,
      "y": 1,
      "z": -8,
      "name": "Soil_Sand_Ashen"
    },
    {
      "x": 0,
      "y": 2,
