{
  "version": 8,
  "blockIdVersion": 11,
  "anchorX": 0,
  "anchorY": 0,
  "anchorZ": 0,
  "blocks": [
    {
      "x": -11,
      "y": 0,
      "z": -5,
      "name": "Soil_Ash"
    },
    {
      "x": -11,
      "y": 1,
      "z": -5,
      "name": "Soil_Ash"
    },
    {
      "x": -11,
      "y": 0,
      "z": -4,
      "name": "Soil_Ash"
    },
    {
      "x": -11,
      "y": 1,
      "z": -4,
      "name": "Soil_Ash"
    },
    {
      "x": -11,
      "y": 0,
      "z": -3,
      "name": "Soil_Ash"
    },
    {
      "x": -11,
      "y": 1,
      "z": -3,
      "name": "Soil_Ash"
    },
    {
      "x": -11,
      "y": 0,
      "z": 0,
      "name": "Soil_Ash"
    },
    {
      "x": -11,
      "y": 0,
      "z": 3,
      "name": "Soil_Ash"
    },
    {
      "x": -11,
      "y": 1,
      "z": 3,
      "name": "Soil_Ash"
    },
    {
      "x": -11,
      "y": 0,
      "z": 4,
      "name": "Soil_Ash"
    },
    {
      "x": -11,
      "y": 1,
      "z": 4,
      "name": "Soil_Ash"
    },
    {
      "x": -11,
      "y": 0,
      "z": 5,
      "name": "Soil_Ash"
    },
    {
      "x": -11,
      "y": 1,
      "z": 5,
      "name": "Soil_Ash"
    },
    {
      "x": -10,
      "y": 0,
      "z": -7,
      "name": "Soil_Ash"
    },
    {
      "x": -10,
      "y": 0,
      "z": -6,
      "name": "Soil_Ash"
    },
    {
      "x": -10,
      "y": 1,
      "z": -6,
      "name": "Soil_Ash"
    },
    {
      "x": -10,
      "y": 0,
      "z": -5,
      "name": "Soil_Ash"
    },
    {
      "x": -10,
      "y": 1,
      "z": -5,
      "name": "Soil_Sand_Ashen"
    },
    {
      "x": -10,
      "y": 0,
      "z": -4,
      "name": "Soil_Ash"
    },
    {
      "x": -10,
      "y": 1,
      "z": -4,
      "name": "Soil_Sand_Ashen"
    },
    {
      "x": -10,
      "y": 0,
      "z": -3,
      "name": "Soil_Ash"
    },
    {
      "x": -10,
      "y": 1,
      "z": -3,
      "name": "Soil_Sand_Ashen"
    },
    {
      "x": -10,
      "y": 0,
      "z": -2,
      "name": "Soil_Ash"
    },
    {
      "x": -10,
      "y": 1,
      "z": -2,
      "name": "Soil_Ash"
    },
    {
      "x": -10,
      "y": 0,
      "z": -1,
      "name": "Soil_Ash"
    },
    {
      "x": -10,
      "y": 1,
      "z": -1,
      "name": "Soil_Ash"
    },
    {
      "x": -10,
      "y": 0,
      "z": 0,
      "name": "Soil_Ash"
    },
    {
      "x": -10,
      "y": 1,
      "z": 0,
      "name": "Soil_Ash"
    },
    {
      "x": -10,
      "y": 0,
      "z": 1,
      "name": "Soil_Ash"
    },
    {
      "x": -10,
      "y": 1,
      "z": 1,
      "name": "Soil_Ash"
    },
    {
      "x": -10,
      "y": 0,
      "z": 2,
      "name": "Soil_Ash"
    },
    {
      "x": -10,
      "y": 1,
      "z": 2,
      "name": "Soil_Ash"
    },
    {
      "x": -10,
      "y": 0,
      "z": 3,
      "name": "Soil_Ash"
    },
    {
      "x": -10,
      "y": 1,
      "z": 3,
      "name": "Soil_Sand_Ashen"
    },
    {
      "x": -10,
      "y": 0,
      "z": 4,
      "name": "Soil_Ash"
    },
    {
      "x": -10,
      "y": 1,
      "z": 4,
      "name": "Soil_Sand_Ashen"
    },
    {
      "x": -10,
      "y": 0,
      "z": 5,
      "name": "Soil_Ash"
    },
    {
      "x": -10,
      "y": 1,
      "z": 5,
      "name": "Soil_Sand_Ashen"
    },
    {
      "x": -10,
      "y": 0,
      "z": 6,
      "name": "Soil_Ash"
    },
    {
      "x": -10,
      "y": 1,
      "z": 6,
      "name": "Soil_Ash"
    },
    {
      "x": -10,
      "y": 0,
      "z": 7,
      "name": "Soil_Ash"
    },
    {
      "x": -10,
      "y": 1,
      "z": 7,
      "name": "Soil_Ash"
    },
    {
      "x": -9,
      "y": 0,
      "z": -7,
      "name": "Soil_Ash"
    },
    {
      "x": -9,
      "y": 1,
      "z": -7,
      "name": "Soil_Ash"
    },
    {
      "x": -9,
      "y": 0,
      "z": -6,
      "name": "Soil_Ash"
    },
    {
      "x": -9,
      "y": 1,
      "z": -6,
      "name": "Soil_Sand_Ashen"
    },
    {
      "x": -9,
      "y": 0,
      "z": -5,
      "name": "Soil_Ash"
    },
    {
      "x": -9,
      "y": 1,
      "z": -5,
      "name": "Soil_Sand_Ashen"
    },
    {
      "x": -9,
      "y": 2,
      "z": -5,
      "name": "Soil_Sand_Ashen"
    },
    {
      "x": -9,
      "y": 0,
      "z": -4,
      "name": "Soil_Ash"
    },
    {
      "x": -9,
      "y": 1,
      "z": -4,
      "name": "Soil_Sand_Ashen"
    },
    {
      "x": -9,
      "y": 2,
      "z": -4,
      "name": "Soil_Sand_Ashen"
    },
    {
      "x": -9,
      "y": 0,
      "z": -3,
      "name": "Soil_Ash"
    },
    {
      "x": -9,
      "y": 1,
      "z": -3,
      "name": "Soil_Sand_Ashen"
    },
    {
      "x": -9,
      "y": 2,
      "z": -3,
      "name": "Soil_Sand_Ashen"
    },
    {
      "x": -9,
      "y": 0,
      "z": -2,
      "name": "Soil_Ash"
    },
    {
      "x": -9,
      "y": 1,
      "z": -2,
      "name": "Soil_Sand_Ashen"
    },
    {
      "x": -9,
      "y": 2,
      "z": -2,
      "name": "Soil_Sand_Ashen"
    },
    {
      "x": -9,
      "y": 0,
      "z": -1,
      "name": "Soil_Ash"
    },
    {
      "x": -9,
      "y": 1,
      "z": -1,
      "name": "Soil_Sand_Ashen"
    },
    {
      "x": -9,
      "y": 2,
      "z": -1,
      "name": "Soil_Sand_Ashen"
    },
    {
      "x": -9,
      "y": 3,
      "z": -1,
      "name": "Soil_Mud"
    },
    {
      "x": -9,
      "y": 0,
      "z": 0,
      "name": "Soil_Ash"
    },
    {
      "x": -9,
      "y": 1,
      "z": 0,
      "name": "Soil_Sand_Ashen"
    },
    {
      "x": -9,
      "y": 2,
      "z": 0,
      "name": "Soil_Sand_Ashen"
    },
    {
      "x": -9,
      "y": 0,
      "z": 1,
      "name": "Soil_Ash"
    },
    {
      "x": -9,
      "y": 1,
      "z": 1,
      "name": "Soil_Sand_Ashen"
    },
    {
      "x": -9,
      "y": 0,
      "z": 2,
      "name": "Soil_Ash"
    },
    {
      "x": -9,
      "y": 1,
      "z": 2,
      "name": "Soil_Sand_Ashen"
    },
    {
      "x": -9,
      "y": 2,
      "z": 2,
      "name": "Plant_Bush_Dead_Hanging"
    },
    {
      "x": -9,
      "y": 3,
      "z": 2,
      "name": "Plant_Bush_Dead_Hanging"
    },
    {
      "x": -9,
      "y": 0,
      "z": 3,
      "name": "Soil_Ash"
    },
    {
      "x": -9,
      "y": 1,
      "z": 3,
      "name": "Soil_Sand_Ashen"
    },
    {
      "x": -9,
      "y": 2,
      "z": 3,
      "name": "Soil_Sand_Ashen"
    },
    {
      "x": -9,
      "y": 3,
      "z": 3,
      "name": "Plant_Bush_Dead_Hanging"
    },
    {
      "x": -9,
      "y": 4,
      "z": 3,
      "name": "Plant_Bush_Dead_Hanging"
    },
    {
      "x": -9,
      "y": 0,
      "z": 4,
      "name": "Soil_Ash"
    },
    {
      "x": -9,
      "y": 1,
      "z": 4,
      "name": "Soil_Sand_Ashen"
    },
    {
      "x": -9,
      "y": 2,
      "z": 4,
      "name": "Soil_Sand_Ashen"
    },
    {
      "x": -9,
      "y": 0,
      "z": 5,
      "name": "Soil_Ash"
    },
    {
      "x": -9,
      "y": 1,
      "z": 5,
      "name": "Soil_Sand_Ashen"
    },
    {
      "x": -9,
      "y": 2,
      "z": 5,
      "name": "Soil_Sand_Ashen"
    },
    {
      "x": -9,
      "y": 3,
      "z": 5,
      "name": "Soil_Mud"
    },
    {
      "x": -9,
      "y": 4,
      "z": 5,
      "name": "Plant_Moss_Rug_Pink"
    },
    {
      "x": -9,
      "y": 0,
      "z": 6,
      "name": "Soil_Ash"
    },
    {
      "x": -9,
      "y": 1,
      "z": 6,
      "name": "Soil_Sand_Ashen"
    },
    {
      "x": -9,
      "y": 2,
      "z": 6,
      "name": "Soil_Sand_Ashen"
    },
    {
      "x": -9,
      "y": 3,
      "z": 6,
      "name": "Plant_Moss_Rug_Pink"
    },
    {
      "x": -9,
      "y": 0,
      "z": 7,
      "name": "Soil_Ash"
    },
    {
      "x": -9,
      "y": 1,
      "z": 7,
      "name": "Soil_Ash"
    },
    {
      "x": -8,
      "y": 0,
      "z": -9,
      "name": "Soil_Ash"
    },
    {
      "x": -8,
      "y": 1,
      "z": -9,
      "name": "Soil_Ash"
    },
    {
      "x": -8,
      "y": 0,
      "z": -8,
      "name": "Soil_Ash"
    },
    {
      "x": -8,
      "y": 1,
      "z": -8,
      "name": "Soil_Ash"
    },
    {
      "x": -8,
      "y": 0,
      "z": -7,
      "name": "Soil_Ash"
    },
    {
      "x": -8,
      "y": 1,
      "z": -7,
      "name": "Soil_Sand_Ashen"
    },
    {
      "x": -8,
      "y": 0,
      "z": -6,
      "name": "Soil_Ash"
    },
    {
      "x": -8,
      "y": 1,
      "z": -6,
      "name": "Soil_Sand_Ashen"
    },
    {
      "x": -8,
      "y": 2,
      "z": -6,
      "name": "Soil_Sand_Ashen"
    },
    {
      "x": -8,
      "y": 0,
      "z": -5,
      "name": "Soil_Ash"
    },
    {
      "x": -8,
      "y": 1,
      "z": -5,
      "name": "Soil_Sand_Ashen"
    },
    {
      "x": -8,
      "y": 2,
      "z": -5,
      "name": "Soil_Sand_Ashen"
    },
    {
      "x": -8,
      "y": 0,
      "z": -4,
      "name": "Soil_Ash"
    },
    {
      "x": -8,
      "y": 1,
      "z": -4,
      "name": "Soil_Sand_Ashen"
    },
    {
      "x": -8,
      "y": 2,
      "z": -4,
      "name": "Soil_Sand_Ashen"
    },
    {
      "x": -8,
      "y": 0,
      "z": -3,
      "name": "Soil_Ash"
    },
    {
      "x": -8,
      "y": 1,
      "z": -3,
      "name": "Soil_Sand_Ashen"
    },
    {
      "x": -8,
      "y": 2,
      "z": -3,
      "name": "Soil_Sand_Ashen"
    },
    {
      "x": -8,
      "y": 3,
      "z": -3,
      "name": "Soil_Mud"
    },
    {
      "x": -8,
      "y": 4,
      "z": -3,
      "name": "Plant_Moss_Rug_Pink"
    },
    {
      "x": -8,
      "y": 0,
      "z": -2,
      "name": "Soil_Ash"
    },
    {
      "x": -8,
      "y": 1,
      "z": -2,
      "name": "Soil_Sand_Ashen"
    },
    {
      "x": -8,
      "y": 2,
      "z": -2,
      "name": "Soil_Sand_Ashen"
    },
    {
      "x": -8,
      "y": 3,
      "z": -2,
      "name": "Soil_Mud"
    },
    {
      "x": -8,
      "y": 4,
      "z": -2,
      "name": "Plant_Crop_Mushroom_Glowing_Purple"
    },
    {
      "x": -8,
      "y": 0,
      "z": -1,
      "name": "Soil_Ash"
    },
    {
      "x": -8,
      "y": 1,
      "z": -1,
      "name": "Soil_Sand_Ashen"
    },
    {
      "x": -8,
      "y": 2,
      "z": -1,
      "name": "Soil_Sand_Ashen"
    },
    {
      "x": -8,
      "y": 3,
      "z": -1,
      "name": "Soil_Mud"
    },
    {
      "x": -8,
      "y": 0,
      "z": 0,
      "name": "Soil_Ash"
    },
    {
      "x": -8,
      "y": 1,
      "z": 0,
      "name": "Soil_Sand_Ashen"
    },
    {
      "x": -8,
      "y": 2,
      "z": 0,
      "name": "Soil_Sand_Ashen"
    },
    {
      "x": -8,
      "y": 3,
      "z": 0,
      "name": "Soil_Mud"
    },
    {
      "x": -8,
      "y": 0,
      "z": 1,
      "name": "Soil_Ash"
    },
    {
      "x": -8,
      "y": 1,
      "z": 1,
      "name": "Soil_Sand_Ashen"
    },
    {
      "x": -8,
      "y": 2,
      "z": 1,
      "name": "Soil_Sand_Ashen"
    },
    {
      "x": -8,
      "y": 3,
      "z": 1,
      "name": "Soil_Mud"
    },
    {
      "x": -8,
      "y": 4,
      "z": 1,
      "name": "Plant_Crop_Mushroom_Glowing_Purple"
    },
    {
      "x": -8,
      "y": 0,
      "z": 2,
      "name": "Soil_Ash"
    },
    {
      "x": -8,
      "y": 1,
      "z": 2,
      "name": "Soil_Sand_Ashen"
    },
    {
      "x": -8,
      "y": 2,
      "z": 2,
      "name": "Soil_Sand_Ashen"
    },
    {
      "x": -8,
      "y": 3,
      "z": 2,
      "name": "Plant_Bush_Dead_Hanging"
    },
    {
      "x": -8,
      "y": 4,
      "z": 2,
      "name": "Plant_Bush_Dead_Hanging"
    },
    {
      "x": -8,
      "y": 0,
      "z": 3,
      "name": "Soil_Ash"
    },
    {
      "x": -8,
      "y": 1,
      "z": 3,
      "name": "Soil_Sand_Ashen"
    },
    {
      "x": -8,
      "y": 2,
      "z": 3,
      "name": "Soil_Sand_Ashen"
    },
    {
      "x": -8,
      "y": 3,
      "z": 3,
      "name": "Soil_Mud"
    },
    {
      "x": -8,
      "y": 4,
      "z": 3,
      "name": "Plant_Bush_Dead_Hanging"
    },
    {
      "x": -8,
      "y": 0,
      "z": 4,
      "name": "Soil_Ash"
    },
    {
      "x": -8,
      "y": 1,
      "z": 4,
      "name": "Soil_Sand_Ashen"
    },
    {
      "x": -8,
      "y": 2,
      "z": 4,
      "name": "Soil_Sand_Ashen"
    },
    {
      "x": -8,
      "y": 3,
      "z": 4,
      "name": "Soil_Mud"
    },
    {
      "x": -8,
      "y": 0,
      "z": 5,
      "name": "Soil_Ash"
    },
    {
      "x": -8,
      "y": 1,
      "z": 5,
      "name": "Soil_Sand_Ashen"
    },
    {
      "x": -8,
      "y": 2,
      "z": 5,
      "name": "Soil_Sand_Ashen"
    },
    {
      "x": -8,
      "y": 3,
      "z": 5,
      "name": "Soil_Mud"
    },
    {
      "x": -8,
      "y": 4,
      "z": 5,
      "name": "Plant_Moss_Rug_Pink"
    },
    {
      "x": -8,
      "y": 0,
      "z": 6,
      "name": "Soil_Ash"
    },
    {
      "x": -8,
      "y": 1,
      "z": 6,
      "name": "Soil_Sand_Ashen"
    },
    {
      "x": -8,
      "y": 2,
      "z": 6,
      "name": "Soil_Sand_Ashen"
    },
    {
      "x": -8,
      "y": 3,
      "z": 6,
      "name": "Soil_Mud"
    },
    {
      "x": -8,
      "y": 4,
      "z": 6,
      "name": "Plant_Moss_Rug_Pink"
    },
    {
      "x": -8,
      "y": 0,
      "z": 7,
      "name": "Soil_Ash"
    },
    {
      "x": -8,
      "y": 1,
      "z": 7,
      "name": "Soil_Sand_Ashen"
    },
    {
      "x": -8,
      "y": 2,
      "z": 7,
      "name": "Soil_Sand_Ashen"
    },
    {
      "x": -8,
      "y": 3,
      "z": 7,
      "name": "Soil_Mud"
    },
    {
      "x": -8,
      "y": 4,
      "z": 7,
      "name": "Plant_Moss_Rug_Pink"
    },
    {
      "x": -8,
      "y": 0,
      "z": 8,
      "name": "Soil_Ash"
    },
    {
      "x": -8,
      "y": 1,
      "z": 8,
      "name": "Soil_Ash"
    },
    {
      "x": -8,
      "y": 0,
      "z": 9,
      "name": "Soil_Ash"
    },
    {
      "x": -7,
      "y": 0,
      "z": -11,
      "name": "Soil_Ash"
    },
    {
      "x": -7,
      "y": 0,
      "z": -10,
      "name": "Soil_Ash"
    },
    {
      "x": -7,
      "y": 1,
      "z": -10,
      "name": "Soil_Ash"
    },
    {
      "x": -7,
      "y": 0,
      "z": -9,
      "name": "Soil_Ash"
    },
    {
      "x": -7,
      "y": 1,
      "z": -9,
      "name": "Soil_Sand_Ashen"
    },
    {
      "x": -7,
      "y": 0,
      "z": -8,
      "name": "Soil_Ash"
    },
    {
      "x": -7,
      "y": 1,
      "z": -8,
      "name": "Soil_Sand_Ashen"
    },
    {
      "x": -7,
      "y": 0,
      "z": -7,
      "name": "Soil_Ash"
    },
    {
      "x": -7,
      "y": 1,
      "z": -7,
      "name": "Soil_Sand_Ashen"
    },
    {
      "x": -7,
      "y": 0,
      "z": -6,
      "name": "Soil_Ash"
    },
    {
      "x": -7,
      "y": 1,
      "z": -6,
      "name": "Soil_Sand_Ashen"
    },
    {
      "x": -7,
      "y": 2,
      "z": -6,
      "name": "Soil_Sand_Ashen"
    },
    {
      "x": -7,
      "y": 0,
      "z": -5,
      "name": "Soil_Ash"
    },
    {
      "x": -7,
      "y": 1,
      "z": -5,
      "name": "Soil_Sand_Ashen"
    },
    {
      "x": -7,
      "y": 2,
      "z": -5,
      "name": "Soil_Sand_Ashen"
    },
    {
      "x": -7,
      "y": 0,
      "z": -4,
      "name": "Soil_Ash"
    },
    {
      "x": -7,
      "y": 1,
      "z": -4,
      "name": "Soil_Sand_Ashen"
    },
    {
      "x": -7,
      "y": 2,
      "z": -4,
      "name": "Soil_Sand_Ashen"
    },
    {
      "x": -7,
      "y": 3,
      "z": -4,
      "name": "Soil_Mud"
    },
    {
      "x": -7,
      "y": 4,
      "z": -4,
      "name": "Plant_Moss_Rug_Pink"
    },
    {
      "x": -7,
      "y": 0,
      "z": -3,
      "name": "Soil_Ash"
    },
    {
      "x": -7,
      "y": 1,
      "z": -3,
      "name": "Soil_Sand_Ashen"
    },
    {
      "x": -7,
      "y": 2,
      "z": -3,
      "name": "Soil_Sand_Ashen"
    },
    {
      "x": -7,
      "y": 3,
      "z": -3,
      "name": "Soil_Mud"
    },
    {
      "x": -7,
      "y": 4,
      "z": -3,
      "name": "Plant_Moss_Rug_Pink"
    },
    {
      "x": -7,
      "y": 0,
      "z": -2,
      "name": "Soil_Ash"
    },
    {
      "x": -7,
      "y": 1,
      "z": -2,
      "name": "Soil_Sand_Ashen"
    },
    {
      "x": -7,
      "y": 2,
      "z": -2,
      "name": "Soil_Sand_Ashen"
    },
    {
      "x": -7,
      "y": 3,
      "z": -2,
      "name": "Soil_Mud"
    },
    {
      "x": -7,
      "y": 4,
      "z": -2,
      "name": "Soil_Mud"
    },
    {
      "x": -7,
      "y": 5,
      "z": -2,
      "name": "Plant_Moss_Rug_Pink"
    },
    {
      "x": -7,
      "y": 0,
      "z": -1,
      "name": "Soil_Ash"
    },
    {
      "x": -7,
      "y": 1,
      "z": -1,
      "name": "Soil_Sand_Ashen"
    },
    {
      "x": -7,
      "y": 2,
      "z": -1,
      "name": "Soil_Sand_Ashen"
    },
    {
      "x": -7,
      "y": 3,
      "z": -1,
      "name": "Soil_Mud"
    },
    {
      "x": -7,
      "y": 4,
      "z": -1,
      "name": "Soil_Mud"
    },
    {
      "x": -7,
      "y": 5,
      "z": -1,
      "name": "Plant_Crop_Mushroom_Glowing_Purple"
    },
    {
      "x": -7,
      "y": 0,
      "z": 0,
      "name": "Soil_Ash"
    },
    {
      "x": -7,
      "y": 1,
      "z": 0,
      "name": "Soil_Sand_Ashen"
    },
    {
      "x": -7,
      "y": 2,
      "z": 0,
      "name": "Soil_Sand_Ashen"
    },
    {
      "x": -7,
      "y": 3,
      "z": 0,
      "name": "Soil_Mud"
    },
    {
      "x": -7,
      "y": 4,
      "z": 0,
      "name": "Soil_Mud"
    },
    {
      "x": -7,
      "y": 5,
      "z": 0,
      "name": "Plant_Grass_Cave_Short"
    },
    {
      "x": -7,
      "y": 0,
      "z": 1,
      "name": "Soil_Ash"
    },
    {
      "x": -7,
      "y": 1,
      "z": 1,
      "name": "Soil_Sand_Ashen"
    },
    {
      "x": -7,
      "y": 2,
      "z": 1,
      "name": "Soil_Sand_Ashen"
    },
    {
      "x": -7,
      "y": 3,
      "z": 1,
      "name": "Soil_Mud"
    },
    {
      "x": -7,
      "y": 0,
      "z": 2,
      "name": "Soil_Ash"
    },
    {
      "x": -7,
      "y": 1,
      "z": 2,
      "name": "Soil_Sand_Ashen"
    },
    {
      "x": -7,
      "y": 2,
      "z": 2,
      "name": "Soil_Sand_Ashen"
    },
    {
      "x": -7,
      "y": 3,
      "z": 2,
      "name": "Soil_Mud"
    },
    {
      "x": -7,
      "y": 4,
      "z": 2,
      "name": "Plant_Bush_Dead_Hanging"
    },
    {
      "x": -7,
      "y": 5,
      "z": 2,
      "name": "Plant_Bush_Dead_Hanging"
    },
    {
      "x": -7,
      "y": 0,
      "z": 3,
      "name": "Soil_Ash"
    },
    {
      "x": -7,
      "y": 1,
      "z": 3,
      "name": "Soil_Sand_Ashen"
    },
    {
      "x": -7,
      "y": 2,
      "z": 3,
      "name": "Soil_Sand_Ashen"
    },
    {
      "x": -7,
      "y": 3,
      "z": 3,
      "name": "Soil_Mud"
    },
    {
      "x": -7,
      "y": 4,
      "z": 3,
      "name": "Plant_Bush_Dead_Hanging"
    },
    {
      "x": -7,
      "y": 0,
      "z": 4,
      "name": "Soil_Ash"
    },
    {
      "x": -7,
      "y": 1,
      "z": 4,
      "name": "Soil_Sand_Ashen"
    },
    {
      "x": -7,
      "y": 2,
      "z": 4,
      "name": "Soil_Sand_Ashen"
    },
    {
      "x": -7,
      "y": 3,
      "z": 4,
      "name": "Soil_Mud"
    },
    {
      "x": -7,
      "y": 4,
      "z": 4,
      "name": "Soil_Mud"
    },
    {
      "x": -7,
      "y": 5,
      "z": 4,
      "name": "Plant_Grass_Cave_Short"
    },
    {
      "x": -7,
      "y": 0,
      "z": 5,
      "name": "Soil_Ash"
    },
    {
      "x": -7,
      "y": 1,
      "z": 5,
      "name": "Soil_Sand_Ashen"
    },
    {
      "x": -7,
      "y": 2,
      "z": 5,
      "name": "Soil_Sand_Ashen"
    },
    {
      "x": -7,
      "y": 3,
      "z": 5,
      "name": "Soil_Mud"
    },
    {
      "x": -7,
      "y": 4,
      "z": 5,
      "name": "Soil_Mud"
    },
    {
      "x": -7,
      "y": 5,
      "z": 5,
      "name": "Plant_Crop_Mushroom_Glowing_Purple"
    },
    {
      "x": -7,
      "y": 0,
      "z": 6,
      "name": "Soil_Ash"
    },
    {
      "x": -7,
      "y": 1,
      "z": 6,
      "name": "Soil_Sand_Ashen"
    },
    {
      "x": -7,
      "y": 2,
      "z": 6,
      "name": "Soil_Sand_Ashen"
    },
    {
      "x": -7,
      "y": 3,
      "z": 6,
      "name": "Soil_Mud"
    },
    {
      "x": -7,
      "y": 4,
      "z": 6,
      "name": "Soil_Mud"
    },
    {
      "x": -7,
      "y": 5,
      "z": 6,
      "name": "Plant_Moss_Rug_Pink"
    },
    {
      "x": -7,
      "y": 0,
      "z": 7,
      "name": "Soil_Ash"
    },
    {
      "x": -7,
      "y": 1,
      "z": 7,
      "name": "Soil_Sand_Ashen"
    },
    {
      "x": -7,
      "y": 2,
      "z": 7,
      "name": "Soil_Sand_Ashen"
    },
    {
      "x": -7,
      "y": 3,
      "z": 7,
      "name": "Soil_Mud"
    },
    {
      "x": -7,
      "y": 4,
      "z": 7,
      "name": "Plant_Moss_Rug_Pink"
    },
    {
      "x": -7,
      "y": 0,
      "z": 8,
      "name": "Soil_Ash"
    },
    {
      "x": -7,
      "y": 1,
      "z": 8,
      "name": "Soil_Sand_Ashen"
    },
    {
      "x": -7,
      "y": 2,
      "z": 8,
      "name": "Soil_Sand_Ashen"
    },
    {
      "x": -7,
      "y": 3,
      "z": 8,
      "name": "Soil_Mud"
    },
    {
      "x": -7,
      "y": 4,
      "z": 8,
      "name": "Plant_Moss_Rug_Pink"
    },
    {
      "x": -7,
      "y": 0,
      "z": 9,
      "name": "Soil_Ash"
    },
    {
      "x": -7,
      "y": 1,
      "z": 9,
      "name": "Soil_Ash"
    },
    {
      "x": -7,
      "y": 2,
      "z": 9,
      "name": "Plant_Crop_Mushroom_Glowing_Purple"
    },
    {
      "x": -7,
      "y": 0,
      "z": 10,
      "name": "Soil_Ash"
    },
    {
      "x": -7,
      "y": 0,
      "z": 11,
      "name": "Soil_Ash"
    },
    {
      "x": -6,
      "y": 0,
      "z": -11,
      "name": "Soil_Ash"
    },
    {
      "x": -6,
      "y": 1,
      "z": -11,
      "name": "Soil_Ash"
    },
    {
      "x": -6,
      "y": 0,
      "z": -10,
      "name": "Soil_Ash"
    },
    {
      "x": -6,
      "y": 1,
      "z": -10,
      "name": "Soil_Sand_Ashen"
    },
    {
      "x": -6,
      "y": 0,
      "z": -9,
      "name": "Soil_Ash"
    },
    {
      "x": -6,
      "y": 1,
      "z": -9,
      "name": "Soil_Sand_Ashen"
    },
    {
      "x": -6,
      "y": 2,
      "z": -9,
      "name": "Soil_Sand_Ashen"
    },
    {
      "x": -6,
      "y": 0,
      "z": -8,
      "name": "Soil_Ash"
    },
    {
      "x": -6,
      "y": 1,
      "z": -8,
      "name": "Soil_Sand_Ashen"
    },
    {
      "x": -6,
      "y": 2,
      "z": -8,
      "name": "Soil_Ash"
    },
    {
      "x": -6,
      "y": 0,
      "z": -7,
      "name": "Soil_Ash"
    },
    {
      "x": -6,
      "y": 1,
      "z": -7,
      "name": "Soil_Sand_Ashen"
    },
    {
      "x": -6,
      "y": 2,
      "z": -7,
      "name": "Soil_Ash"
    },
    {
      "x": -6,
      "y": 0,
      "z": -6,
      "name": "Soil_Ash"
    },
    {
      "x": -6,
      "y": 1,
      "z": -6,
      "name": "Soil_Sand_Ashen"
    },
    {
      "x": -6,
      "y": 2,
      "z": -6,
      "name": "Soil_Ash"
    },
    {
      "x": -6,
      "y": 3,
      "z": -6,
      "name": "Plant_Moss_Rug_Pink"
    },
    {
      "x": -6,
      "y": 0,
      "z": -5,
      "name": "Soil_Ash"
    },
    {
      "x": -6,
      "y": 1,
      "z": -5,
      "name": "Soil_Sand_Ashen"
    },
    {
      "x": -6,
      "y": 2,
      "z": -5,
      "name": "Soil_Sand_Ashen"
    },
    {
      "x": -6,
      "y": 3,
      "z": -5,
      "name": "Soil_Ash"
    },
    {
      "x": -6,
      "y": 4,
      "z": -5,
      "name": "Plant_Moss_Rug_Pink"
    },
    {
      "x": -6,
      "y": 0,
      "z": -4,
      "name": "Soil_Ash"
    },
    {
      "x": -6,
      "y": 1,
      "z": -4,
      "name": "Soil_Sand_Ashen"
    },
    {
      "x": -6,
      "y": 2,
      "z": -4,
      "name": "Soil_Sand_Ashen"
    },
    {
      "x": -6,
      "y": 3,
      "z": -4,
      "name": "Soil_Ash"
    },
    {
      "x": -6,
      "y": 4,
      "z": -4,
      "name": "Plant_Moss_Rug_Pink"
    },
    {
      "x": -6,
      "y": 0,
      "z": -3,
      "name": "Soil_Ash"
    },
    {
      "x": -6,
      "y": 1,
      "z": -3,
      "name": "Soil_Sand_Ashen"
    },
    {
      "x": -6,
      "y": 2,
      "z": -3,
      "name": "Soil_Sand_Ashen"
    },
    {
      "x": -6,
      "y": 3,
      "z": -3,
      "name": "Soil_Mud"
    },
    {
      "x": -6,
      "y": 4,
      "z": -3,
      "name": "Soil_Ash"
    },
    {
      "x": -6,
      "y": 5,
      "z": -3,
      "name": "Plant_Moss_Rug_Pink"
    },
    {
      "x": -6,
      "y": 0,
      "z": -2,
      "name": "Soil_Ash"
    },
    {
      "x": -6,
      "y": 1,
      "z": -2,
      "name": "Soil_Sand_Ashen"
    },
    {
      "x": -6,
      "y": 2,
      "z": -2,
      "name": "Soil_Sand_Ashen"
    },
    {
      "x": -6,
      "y": 3,
      "z": -2,
      "name": "Soil_Mud"
    },
    {
      "x": -6,
      "y": 4,
      "z": -2,
      "name": "Soil_Ash"
    },
    {
      "x": -6,
      "y": 0,
      "z": -1,
      "name": "Soil_Ash"
    },
    {
      "x": -6,
      "y": 1,
      "z": -1,
      "name": "Soil_Sand_Ashen"
    },
    {
      "x": -6,
      "y": 2,
      "z": -1,
      "name": "Soil_Sand_Ashen"
    },
    {
      "x": -6,
      "y": 3,
      "z": -1,
      "name": "Soil_Mud"
    },
    {
      "x": -6,
      "y": 4,
      "z": -1,
      "name": "Soil_Ash"
    },
    {
      "x": -6,
      "y": 5,
      "z": -1,
      "name": "Plant_Grass_Cave_Short"
    },
    {
      "x": -6,
      "y": 0,
      "z": 0,
      "name": "Soil_Ash"
    },
    {
      "x": -6,
      "y": 1,
      "z": 0,
      "name": "Soil_Sand_Ashen"
    },
    {
      "x": -6,
      "y": 2,
      "z": 0,
      "name": "Soil_Sand_Ashen"
    },
    {
      "x": -6,
      "y": 3,
      "z": 0,
      "name": "Soil_Mud"
    },
    {
      "x": -6,
      "y": 4,
      "z": 0,
      "name": "Soil_Mud"
    },
    {
      "x": -6,
      "y": 0,
      "z": 1,
      "name": "Soil_Ash"
    },
    {
      "x": -6,
      "y": 1,
      "z": 1,
      "name": "Soil_Sand_Ashen"
    },
    {
      "x": -6,
      "y": 2,
      "z": 1,
      "name": "Soil_Sand_Ashen"
    },
    {
      "x": -6,
      "y": 3,
      "z": 1,
      "name": "Soil_Mud"
    },
    {
      "x": -6,
      "y": 4,
      "z": 1,
      "name": "Soil_Mud"
    },
    {
      "x": -6,
      "y": 0,
      "z": 2,
      "name": "Soil_Ash"
    },
    {
      "x": -6,
      "y": 1,
      "z": 2,
      "name": "Soil_Sand_Ashen"
    },
    {
      "x": -6,
      "y": 2,
      "z": 2,
      "name": "Soil_Sand_Ashen"
    },
    {
      "x": -6,
      "y": 3,
      "z": 2,
      "name": "Soil_Ash"
    },
    {
      "x": -6,
      "y": 4,
      "z": 2,
      "name": "Plant_Bush_Dead_Hanging"
    },
    {
      "x": -6,
      "y": 0,
      "z": 3,
      "name": "Soil_Ash"
    },
    {
      "x": -6,
      "y": 1,
      "z": 3,
      "name": "Soil_Sand_Ashen"
    },
    {
      "x": -6,
      "y": 2,
      "z": 3,
      "name": "Soil_Sand_Ashen"
    },
    {
      "x": -6,
      "y": 3,
      "z": 3,
      "name": "Soil_Mud"
    },
    {
      "x": -6,
      "y": 4,
      "z": 3,
      "name": "Soil_Mud"
    },
    {
      "x": -6,
      "y": 0,
      "z": 4,
      "name": "Soil_Ash"
    },
    {
      "x": -6,
      "y": 1,
      "z": 4,
      "name": "Soil_Sand_Ashen"
    },
    {
      "x": -6,
      "y": 2,
      "z": 4,
      "name": "Soil_Sand_Ashen"
    },
    {
      "x": -6,
      "y": 3,
      "z": 4,
      "name": "Soil_Mud"
    },
    {
      "x": -6,
      "y": 4,
      "z": 4,
      "name": "Soil_Mud"
    },
    {
      "x": -6,
      "y": 0,
      "z": 5,
      "name": "Soil_Ash"
    },
    {
      "x": -6,
      "y": 1,
      "z": 5,
      "name": "Soil_Sand_Ashen"
    },
    {
      "x": -6,
      "y": 2,
      "z": 5,
      "name": "Soil_Sand_Ashen"
    },
    {
      "x": -6,
      "y": 3,
      "z": 5,
      "name": "Soil_Mud"
    },
    {
      "x": -6,
      "y": 4,
      "z": 5,
      "name": "Soil_Mud"
    },
    {
      "x": -6,
      "y": 5,
      "z": 5,
      "name": "Plant_Grass_Cave_Short"
    },
    {
      "x": -6,
      "y": 0,
      "z": 6,
      "name": "Soil_Ash"
    },
    {
      "x": -6,
      "y": 1,
      "z": 6,
      "name": "Soil_Sand_Ashen"
    },
    {
      "x": -6,
      "y": 2,
      "z": 6,
      "name": "Soil_Sand_Ashen"
    },
    {
      "x": -6,
      "y": 3,
      "z": 6,
      "name": "Soil_Mud"
    },
    {
      "x": -6,
      "y": 4,
      "z": 6,
      "name": "Soil_Mud"
    },
    {
      "x": -6,
      "y": 5,
      "z": 6,
      "name": "Plant_Crop_Mushroom_Glowing_Purple"
    },
    {
      "x": -6,
      "y": 0,
      "z": 7,
      "name": "Soil_Ash"
    },
    {
      "x": -6,
      "y": 1,
      "z": 7,
      "name": "Soil_Sand_Ashen"
    },
    {
      "x": -6,
      "y": 2,
      "z": 7,
      "name": "Soil_Sand_Ashen"
    },
    {
      "x": -6,
      "y": 3,
      "z": 7,
      "name": "Soil_Mud"
    },
    {
      "x": -6,
      "y": 4,
      "z": 7,
      "name": "Soil_Mud"
    },
    {
      "x": -6,
      "y": 5,
      "z": 7,
      "name": "Plant_Flower_Common_Purple2"
    },
    {
      "x": -6,
      "y": 0,
      "z": 8,
      "name": "Soil_Ash"
    },
    {
      "x": -6,
      "y": 1,
      "z": 8,
      "name": "Soil_Sand_Ashen"
    },
    {
      "x": -6,
      "y": 2,
      "z": 8,
      "name": "Soil_Sand_Ashen"
    },
    {
      "x": -6,
      "y": 3,
      "z": 8,
      "name": "Soil_Mud"
    },
    {
      "x": -6,
      "y": 4,
      "z": 8,
      "name": "Plant_Flower_Common_Purple2"
    },
    {
      "x": -6,
      "y": 0,
      "z": 9,
      "name": "Soil_Ash"
    },
    {
      "x": -6,
      "y": 1,
      "z": 9,
      "name": "Soil_Sand_Ashen"
    },
    {
      "x": -6,
      "y": 2,
      "z": 9,
      "name": "Soil_Sand_Ashen"
    },
    {
      "x": -6,
      "y": 0,
      "z": 10,
      "name": "Soil_Ash"
    },
    {
      "x": -6,
      "y": 1,
      "z": 10,
      "name": "Soil_Ash"
    },
    {
      "x": -6,
      "y": 0,
      "z": 11,
      "name": "Soil_Ash"
    },
    {
      "x": -6,
      "y": 0,
      "z": 12,
      "name": "Soil_Ash"
    },
    {
      "x": -5,
      "y": 0,
      "z": -12,
      "name": "Soil_Ash"
    },
    {
      "x": -5,
      "y": 0,
      "z": -11,
      "name": "Soil_Ash"
    },
    {
      "x": -5,
      "y": 1,
      "z": -11,
      "name": "Soil_Ash"
    },
    {
      "x": -5,
      "y": 0,
      "z": -10,
      "name": "Soil_Ash"
    },
    {
      "x": -5,
      "y": 1,
      "z": -10,
      "name": "Soil_Sand_Ashen"
    },
    {
      "x": -5,
      "y": 2,
      "z": -10,
      "name": "Soil_Sand_Ashen"
    },
    {
      "x": -5,
      "y": 0,
      "z": -9,
      "name": "Soil_Ash"
    },
    {
      "x": -5,
      "y": 1,
      "z": -9,
      "name": "Soil_Sand_Ashen"
    },
    {
      "x": -5,
      "y": 2,
      "z": -9,
      "name": "Soil_Sand_Ashen"
    },
    {
      "x": -5,
      "y": 0,
      "z": -8,
      "name": "Soil_Ash"
    },
    {
      "x": -5,
      "y": 1,
      "z": -8,
      "name": "Soil_Sand_Ashen"
    },
    {
      "x": -5,
      "y": 2,
      "z": -8,
      "name": "Soil_Ash"
    },
    {
      "x": -5,
      "y": 3,
      "z": -8,
      "name": "Plant_Crop_Wheat_Stage_4_Burnt"
    },
    {
      "x": -5,
      "y": 4,
      "z": -8,
      "name": "Plant_Crop_Wheat_Stage_4_Burnt",
      "filler": 1024
    },
    {
      "x": -5,
      "y": 0,
      "z": -7,
      "name": "Soil_Ash"
    },
    {
      "x": -5,
      "y": 1,
      "z": -7,
      "name": "Soil_Sand_Ashen"
    },
    {
      "x": -5,
      "y": 2,
      "z": -7,
      "name": "Soil_Sand_Ashen"
    },
    {
      "x": -5,
      "y": 0,
      "z": -6,
      "name": "Soil_Ash"
    },
    {
      "x": -5,
      "y": 1,
      "z": -6,
      "name": "Soil_Sand_Ashen"
    },
    {
      "x": -5,
      "y": 2,
      "z": -6,
      "name": "Soil_Sand_Ashen"
    },
    {
      "x": -5,
      "y": 0,
      "z": -5,
      "name": "Soil_Ash"
    },
    {
      "x": -5,
      "y": 1,
      "z": -5,
      "name": "Soil_Sand_Ashen"
    },
    {
      "x": -5,
      "y": 2,
      "z": -5,
      "name": "Soil_Sand_Ashen"
    },
    {
      "x": -5,
      "y": 3,
      "z": -5,
      "name": "Soil_Mud"
    },
    {
      "x": -5,
      "y": 4,
      "z": -5,
      "name": "Plant_Moss_Rug_Pink"
    },
    {
      "x": -5,
      "y": 0,
      "z": -4,
      "name": "Soil_Ash"
    },
    {
      "x": -5,
      "y": 1,
      "z": -4,
      "name": "Soil_Sand_Ashen"
    },
    {
      "x": -5,
      "y": 2,
      "z": -4,
      "name": "Soil_Sand_Ashen"
    },
    {
      "x": -5,
      "y": 3,
      "z": -4,
      "name": "Soil_Mud"
    },
    {
      "x": -5,
      "y": 4,
      "z": -4,
      "name": "Plant_Moss_Rug_Pink"
    },
    {
      "x": -5,
      "y": 0,
      "z": -3,
      "name": "Soil_Ash"
    },
    {
      "x": -5,
      "y": 1,
      "z": -3,
      "name": "Soil_Sand_Ashen"
    },
    {
      "x": -5,
      "y": 2,
      "z": -3,
      "name": "Soil_Sand_Ashen"
    },
    {
      "x": -5,
      "y": 3,
      "z": -3,
      "name": "Soil_Mud"
    },
    {
      "x": -5,
      "y": 4,
      "z": -3,
      "name": "Soil_Mud"
    },
    {
      "x": -5,
      "y": 5,
      "z": -3,
      "name": "Plant_Moss_Rug_Pink"
    },
    {
      "x": -5,
      "y": 0,
      "z": -2,
      "name": "Soil_Ash"
    },
    {
      "x": -5,
      "y": 1,
      "z": -2,
      "name": "Soil_Sand_Ashen"
    },
    {
      "x": -5,
      "y": 2,
      "z": -2,
      "name": "Soil_Sand_Ashen"
    },
    {
      "x": -5,
      "y": 3,
      "z": -2,
      "name": "Soil_Mud"
    },
    {
      "x": -5,
      "y": 4,
      "z": -2,
      "name": "Soil_Mud"
    },
    {
      "x": -5,
      "y": 5,
      "z": -2,
      "name": "Plant_Crop_Mushroom_Glowing_Purple"
    },
    {
      "x": -5,
      "y": 0,
      "z": -1,
      "name": "Soil_Ash"
    },
    {
      "x": -5,
      "y": 1,
      "z": -1,
      "name": "Soil_Sand_Ashen"
    },
    {
      "x": -5,
      "y": 2,
      "z": -1,
      "name": "Soil_Sand_Ashen"
    },
    {
      "x": -5,
      "y": 3,
      "z": -1,
      "name": "Soil_Mud"
    },
    {
      "x": -5,
      "y": 4,
      "z": -1,
      "name": "Soil_Ash"
    },
    {
      "x": -5,
      "y": 0,
      "z": 0,
      "name": "Soil_Ash"
    },
    {
      "x": -5,
      "y": 1,
      "z": 0,
      "name": "Soil_Sand_Ashen"
    },
    {
      "x": -5,
      "y": 2,
      "z": 0,
      "name": "Soil_Sand_Ashen"
    },
    {
      "x": -5,
      "y": 3,
      "z": 0,
      "name": "Soil_Mud"
    },
    {
      "x": -5,
      "y": 4,
      "z": 0,
      "name": "Soil_Ash"
    },
    {
      "x": -5,
      "y": 0,
      "z": 1,
      "name": "Soil_Ash"
    },
    {
      "x": -5,
      "y": 1,
      "z": 1,
      "name": "Soil_Sand_Ashen"
    },
    {
      "x": -5,
      "y": 2,
      "z": 1,
      "name": "Soil_Sand_Ashen"
    },
    {
      "x": -5,
      "y": 3,
      "z": 1,
      "name": "Soil_Mud"
    },
    {
      "x": -5,
      "y": 4,
      "z": 1,
      "name": "Soil_Ash"
    },
    {
      "x": -5,
      "y": 0,
      "z": 2,
      "name": "Soil_Ash"
    },
    {
      "x": -5,
      "y": 1,
      "z": 2,
      "name": "Soil_Sand_Ashen"
    },
    {
      "x": -5,
      "y": 2,
      "z": 2,
      "name": "Soil_Sand_Ashen"
    },
    {
      "x": -5,
      "y": 3,
      "z": 2,
      "name": "Soil_Mud"
    },
    {
      "x": -5,
      "y": 4,
      "z": 2,
      "name": "Soil_Ash"
    },
    {
      "x": -5,
      "y": 0,
      "z": 3,
      "name": "Soil_Ash"
    },
    {
      "x": -5,
      "y": 1,
      "z": 3,
      "name": "Soil_Sand_Ashen"
    },
    {
      "x": -5,
      "y": 2,
      "z": 3,
      "name": "Soil_Sand_Ashen"
    },
    {
      "x": -5,
      "y": 3,
      "z": 3,
      "name": "Soil_Mud"
    },
    {
      "x": -5,
      "y": 4,
      "z": 3,
      "name": "Soil_Ash"
    },
    {
      "x": -5,
      "y": 0,
      "z": 4,
      "name": "Soil_Ash"
    },
    {
      "x": -5,
      "y": 1,
      "z": 4,
      "name": "Soil_Sand_Ashen"
    },
    {
      "x": -5,
      "y": 2,
      "z": 4,
      "name": "Soil_Sand_Ashen"
    },
    {
      "x": -5,
      "y": 3,
      "z": 4,
      "name": "Soil_Mud"
    },
    {
      "x": -5,
      "y": 4,
      "z": 4,
      "name": "Soil_Ash"
    },
    {
      "x": -5,
      "y": 0,
      "z": 5,
      "name": "Soil_Ash"
    },
    {
      "x": -5,
      "y": 1,
      "z": 5,
      "name": "Soil_Sand_Ashen"
    },
    {
      "x": -5,
      "y": 2,
      "z": 5,
      "name": "Soil_Sand_Ashen"
    },
    {
      "x": -5,
      "y": 3,
      "z": 5,
      "name": "Soil_Mud"
    },
    {
      "x": -5,
      "y": 4,
      "z": 5,
      "name": "Soil_Ash"
    },
    {
      "x": -5,
      "y": 5,
      "z": 5,
      "name": "Plant_Leaves_Poisoned"
    },
    {
      "x": -5,
      "y": 0,
      "z": 6,
      "name": "Soil_Ash"
    },
    {
      "x": -5,
      "y": 1,
      "z": 6,
      "name": "Soil_Sand_Ashen"
    },
    {
      "x": -5,
      "y": 2,
      "z": 6,
      "name": "Soil_Sand_Ashen"
    },
    {
      "x": -5,
      "y": 3,
      "z": 6,
      "name": "Soil_Mud"
    },
    {
      "x": -5,
      "y": 4,
      "z": 6,
      "name": "Soil_Mud"
    },
    {
      "x": -5,
      "y": 5,
      "z": 6,
      "name": "Plant_Leaves_Poisoned"
    },
    {
      "x": -5,
      "y": 0,
      "z": 7,
      "name": "Soil_Ash"
    },
    {
      "x": -5,
      "y": 1,
      "z": 7,
      "name": "Soil_Sand_Ashen"
    },
    {
      "x": -5,
      "y": 2,
      "z": 7,
      "name": "Soil_Sand_Ashen"
    },
    {
      "x": -5,
      "y": 3,
      "z": 7,
      "name": "Soil_Mud"
    },
    {
      "x": -5,
      "y": 4,
      "z": 7,
      "name": "Soil_Ash"
    },
    {
      "x": -5,
      "y": 5,
      "z": 7,
      "name": "Plant_Crop_Wheat_Stage_4_Burnt"
    },
    {
      "x": -5,
      "y": 6,
      "z": 7,
      "name": "Plant_Crop_Wheat_Stage_4_Burnt",
      "filler": 1024
    },
    {
      "x": -5,
      "y": 0,
      "z": 8,
      "name": "Soil_Ash"
    },
    {
      "x": -5,
      "y": 1,
      "z": 8,
      "name": "Soil_Sand_Ashen"
    },
    {
      "x": -5,
      "y": 2,
      "z": 8,
      "name": "Soil_Sand_Ashen"
    },
    {
      "x": -5,
      "y": 3,
      "z": 8,
      "name": "Soil_Ash"
    },
    {
      "x": -5,
      "y": 4,
      "z": 8,
      "name": "Plant_Crop_Wheat_Stage_4_Burnt"
    },
    {
      "x": -5,
      "y": 5,
      "z": 8,
      "name": "Plant_Crop_Wheat_Stage_4_Burnt",
      "filler": 1024
    },
    {
      "x": -5,
      "y": 0,
      "z": 9,
      "name": "Soil_Ash"
    },
    {
      "x": -5,
      "y": 1,
      "z": 9,
      "name": "Soil_Sand_Ashen"
    },
    {
      "x": -5,
      "y": 2,
      "z": 9,
      "name": "Soil_Sand_Ashen"
    },
    {
      "x": -5,
      "y": 3,
      "z": 9,
      "name": "Plant_Crop_Mushroom_Glowing_Purple"
    },
    {
      "x": -5,
      "y": 0,
      "z": 10,
      "name": "Soil_Ash"
    },
    {
      "x": -5,
      "y": 1,
      "z": 10,
      "name": "Soil_Sand_Ashen"
    },
    {
      "x": -5,
      "y": 0,
      "z": 11,
      "name": "Soil_Ash"
    },
    {
      "x": -5,
      "y": 1,
      "z": 11,
      "name": "Soil_Ash"
    },
    {
      "x": -5,
      "y": 0,
      "z": 12,
      "name": "Soil_Ash"
    },
    {
      "x": -4,
      "y": 0,
      "z": -12,
      "name": "Soil_Ash"
    },
    {
      "x": -4,
      "y": 1,
      "z": -12,
      "name": "Soil_Ash"
    },
    {
      "x": -4,
      "y": 0,
      "z": -11,
      "name": "Soil_Ash"
    },
    {
      "x": -4,
      "y": 1,
      "z": -11,
      "name": "Soil_Ash"
    },
    {
      "x": -4,
      "y": 0,
      "z": -10,
      "name": "Soil_Ash"
    },
    {
      "x": -4,
      "y": 1,
      "z": -10,
      "name": "Soil_Sand_Ashen"
    },
    {
      "x": -4,
      "y": 2,
      "z": -10,
      "name": "Soil_Ash"
    },
    {
      "x": -4,
      "y": 3,
      "z": -10,
      "name": "Plant_Crop_Wheat_Stage_4_Burnt"
    },
    {
      "x": -4,
      "y": 4,
      "z": -10,
      "name": "Plant_Crop_Wheat_Stage_4_Burnt",
      "filler": 1024
    },
    {
      "x": -4,
      "y": 0,
      "z": -9,
      "name": "Soil_Ash"
    },
    {
      "x": -4,
      "y": 1,
      "z": -9,
      "name": "Soil_Sand_Ashen"
    },
    {
      "x": -4,
      "y": 2,
      "z": -9,
      "name": "Soil_Ash"
    },
    {
      "x": -4,
      "y": 3,
      "z": -9,
      "name": "Plant_Crop_Wheat_Stage_4_Burnt"
    },
    {
      "x": -4,
      "y": 4,
      "z": -9,
      "name": "Plant_Crop_Wheat_Stage_4_Burnt",
      "filler": 1024
    },
    {
      "x": -4,
      "y": 0,
      "z": -8,
      "name": "Soil_Ash"
    },
    {
      "x": -4,
      "y": 1,
      "z": -8,
      "name": "Soil_Sand_Ashen"
    },
    {
      "x": -4,
      "y": 2,
      "z": -8,
      "name": "Soil_Ash"
    },
    {
      "x": -4,
      "y": 3,
      "z": -8,
      "name": "Plant_Crop_Wheat_Stage_4_Burnt"
    },
    {
      "x": -4,
      "y": 4,
      "z": -8,
      "name": "Plant_Crop_Wheat_Stage_4_Burnt",
      "filler": 1024
    },
    {
      "x": -4,
      "y": 0,
      "z": -7,
      "name": "Soil_Ash"
    },
    {
      "x": -4,
      "y": 1,
      "z": -7,
      "name": "Soil_Sand_Ashen"
    },
    {
      "x": -4,
      "y": 2,
      "z": -7,
      "name": "Soil_Sand_Ashen"
    },
    {
      "x": -4,
      "y": 0,
      "z": -6,
      "name": "Soil_Ash"
    },
    {
      "x": -4,
      "y": 1,
      "z": -6,
      "name": "Soil_Sand_Ashen"
    },
    {
      "x": -4,
      "y": 2,
      "z": -6,
      "name": "Soil_Sand_Ashen"
    },
    {
      "x": -4,
      "y": 0,
      "z": -5,
      "name": "Soil_Ash"
    },
    {
      "x": -4,
      "y": 1,
      "z": -5,
      "name": "Soil_Sand_Ashen"
    },
    {
      "x": -4,
      "y": 2,
      "z": -5,
      "name": "Soil_Sand_Ashen"
    },
    {
      "x": -4,
      "y": 0,
      "z": -4,
      "name": "Soil_Ash"
    },
    {
      "x": -4,
      "y": 1,
      "z": -4,
      "name": "Soil_Sand_Ashen"
    },
    {
      "x": -4,
      "y": 2,
      "z": -4,
      "name": "Soil_Sand_Ashen"
    },
    {
      "x": -4,
      "y": 3,
      "z": -4,
      "name": "Soil_Mud"
    },
    {
      "x": -4,
      "y": 4,
      "z": -4,
      "name": "Soil_Mud"
    },
    {
      "x": -4,
      "y": 5,
      "z": -4,
      "name": "Plant_Flower_Common_Purple2"
    },
    {
      "x": -4,
      "y": 0,
      "z": -3,
      "name": "Soil_Ash"
    },
    {
      "x": -4,
      "y": 1,
      "z": -3,
      "name": "Soil_Sand_Ashen"
    },
    {
      "x": -4,
      "y": 2,
      "z": -3,
      "name": "Soil_Sand_Ashen"
    },
    {
      "x": -4,
      "y": 3,
      "z": -3,
      "name": "Soil_Mud"
    },
    {
      "x": -4,
      "y": 4,
      "z": -3,
      "name": "Soil_Mud"
    },
    {
      "x": -4,
      "y": 0,
      "z": -2,
      "name": "Soil_Ash"
    },
    {
      "x": -4,
      "y": 1,
      "z": -2,
      "name": "Soil_Sand_Ashen"
    },
    {
      "x": -4,
      "y": 2,
      "z": -2,
      "name": "Soil_Sand_Ashen"
    },
    {
      "x": -4,
      "y": 3,
      "z": -2,
      "name": "Soil_Mud"
    },
    {
      "x": -4,
      "y": 4,
      "z": -2,
      "name": "Soil_Mud"
    },
    {
      "x": -4,
      "y": 5,
      "z": -2,
      "name": "Soil_Mud"
    },
    {
      "x": -4,
      "y": 0,
      "z": -1,
      "name": "Soil_Ash"
    },
    {
      "x": -4,
      "y": 1,
      "z": -1,
      "name": "Soil_Sand_Ashen"
    },
    {
      "x": -4,
      "y": 2,
      "z": -1,
      "name": "Soil_Sand_Ashen"
    },
    {
      "x": -4,
      "y": 3,
      "z": -1,
      "name": "Soil_Mud"
    },
    {
      "x": -4,
      "y": 4,
      "z": -1,
      "name": "Soil_Mud"
    },
    {
      "x": -4,
      "y": 5,
      "z": -1,
      "name": "Soil_Mud"
    },
    {
      "x": -4,
      "y": 0,
      "z": 0,
      "name": "Soil_Ash"
    },
    {
      "x": -4,
      "y": 1,
      "z": 0,
      "name": "Soil_Sand_Ashen"
    },
    {
      "x": -4,
      "y": 2,
      "z": 0,
      "name": "Soil_Sand_Ashen"
    },
    {
      "x": -4,
      "y": 3,
      "z": 0,
      "name": "Soil_Mud"
    },
    {
      "x": -4,
      "y": 4,
      "z": 0,
      "name": "Soil_Mud"
    },
    {
      "x": -4,
      "y": 5,
      "z": 0,
      "name": "Soil_Mud"
    },
    {
      "x": -4,
      "y": 0,
      "z": 1,
      "name": "Soil_Ash"
    },
    {
      "x": -4,
      "y": 1,
      "z": 1,
      "name": "Soil_Sand_Ashen"
    },
    {
      "x": -4,
      "y": 2,
      "z": 1,
      "name": "Soil_Sand_Ashen"
    },
    {
      "x": -4,
      "y": 3,
      "z": 1,
      "name": "Soil_Mud"
    },
    {
      "x": -4,
      "y": 4,
      "z": 1,
      "name": "Soil_Mud"
    },
    {
      "x": -4,
      "y": 0,
      "z": 2,
      "name": "Soil_Ash"
    },
    {
      "x": -4,
      "y": 1,
      "z": 2,
      "name": "Soil_Sand_Ashen"
    },
    {
      "x": -4,
      "y": 2,
      "z": 2,
      "name": "Soil_Sand_Ashen"
    },
    {
      "x": -4,
      "y": 3,
      "z": 2,
      "name": "Soil_Mud"
    },
    {
      "x": -4,
      "y": 4,
      "z": 2,
      "name": "Soil_Ash"
    },
    {
      "x": -4,
      "y": 0,
      "z": 3,
      "name": "Soil_Ash"
    },
    {
      "x": -4,
      "y": 1,
      "z": 3,
      "name": "Soil_Sand_Ashen"
    },
    {
      "x": -4,
      "y": 2,
      "z": 3,
      "name": "Soil_Sand_Ashen"
    },
    {
      "x": -4,
      "y": 3,
      "z": 3,
      "name": "Soil_Mud"
    },
    {
      "x": -4,
      "y": 4,
      "z": 3,
      "name": "Soil_Mud"
    },
    {
      "x": -4,
      "y": 0,
      "z": 4,
      "name": "Soil_Ash"
    },
    {
      "x": -4,
      "y": 1,
      "z": 4,
      "name": "Soil_Sand_Ashen"
    },
    {
      "x": -4,
      "y": 2,
      "z": 4,
      "name": "Soil_Sand_Ashen"
    },
    {
      "x": -4,
      "y": 3,
      "z": 4,
      "name": "Soil_Mud"
    },
    {
      "x": -4,
      "y": 4,
      "z": 4,
      "name": "Soil_Mud"
    },
    {
      "x": -4,
      "y": 5,
      "z": 4,
      "name": "Plant_Leaves_Poisoned"
    },
    {
      "x": -4,
      "y": 0,
      "z": 5,
      "name": "Soil_Ash"
    },
    {
      "x": -4,
      "y": 1,
      "z": 5,
      "name": "Soil_Sand_Ashen"
    },
    {
      "x": -4,
      "y": 2,
      "z": 5,
      "name": "Soil_Sand_Ashen"
    },
    {
      "x": -4,
      "y": 3,
      "z": 5,
      "name": "Soil_Mud"
    },
    {
      "x": -4,
      "y": 4,
      "z": 5,
      "name": "Soil_Ash"
    },
    {
      "x": -4,
      "y": 5,
      "z": 5,
      "name": "Plant_Leaves_Poisoned"
    },
    {
      "x": -4,
      "y": 6,
      "z": 5,
      "name": "Plant_Leaves_Poisoned"
    },
    {
      "x": -4,
      "y": 0,
      "z": 6,
      "name": "Soil_Ash"
    },
    {
      "x": -4,
      "y": 1,
      "z": 6,
      "name": "Soil_Sand_Ashen"
    },
    {
      "x": -4,
      "y": 2,
      "z": 6,
      "name": "Soil_Sand_Ashen"
    },
    {
      "x": -4,
      "y": 3,
      "z": 6,
      "name": "Soil_Mud"
    },
    {
      "x": -4,
      "y": 4,
      "z": 6,
      "name": "Soil_Ash"
    },
    {
      "x": -4,
      "y": 5,
      "z": 6,
      "name": "Plant_Crop_Mushroom_Glowing_Purple"
    },
    {
      "x": -4,
      "y": 0,
      "z": 7,
      "name": "Soil_Ash"
    },
    {
      "x": -4,
      "y": 1,
      "z": 7,
      "name": "Soil_Sand_Ashen"
    },
    {
      "x": -4,
      "y": 2,
      "z": 7,
      "name": "Soil_Sand_Ashen"
    },
    {
      "x": -4,
      "y": 3,
      "z": 7,
      "name": "Soil_Mud"
    },
    {
      "x": -4,
      "y": 4,
      "z": 7,
      "name": "Soil_Ash"
    },
    {
      "x": -4,
      "y": 5,
      "z": 7,
      "name": "Plant_Crop_Wheat_Stage_4_Burnt"
    },
    {
      "x": -4,
      "y": 6,
      "z": 7,
      "name": "Plant_Crop_Wheat_Stage_4_Burnt",
      "filler": 1024
    },
    {
      "x": -4,
      "y": 0,
      "z": 8,
      "name": "Soil_Ash"
    },
    {
      "x": -4,
      "y": 1,
      "z": 8,
      "name": "Soil_Sand_Ashen"
    },
    {
      "x": -4,
      "y": 2,
      "z": 8,
      "name": "Soil_Sand_Ashen"
    },
    {
      "x": -4,
      "y": 3,
      "z": 8,
      "name": "Soil_Ash"
    },
    {
      "x": -4,
      "y": 4,
      "z": 8,
      "name": "Plant_Crop_Wheat_Stage_4_Burnt"
    },
    {
      "x": -4,
      "y": 5,
      "z": 8,
      "name": "Plant_Crop_Wheat_Stage_4_Burnt",
      "filler": 1024
    },
    {
      "x": -4,
      "y": 0,
      "z": 9,
      "name": "Soil_Ash"
    },
    {
      "x": -4,
      "y": 1,
      "z": 9,
      "name": "Soil_Sand_Ashen"
    },
    {
      "x": -4,
      "y": 2,
      "z": 9,
      "name": "Soil_Ash"
    },
    {
      "x": -4,
      "y": 3,
      "z": 9,
      "name": "Plant_Crop_Wheat_Stage_4_Burnt"
    },
    {
      "x": -4,
      "y": 4,
      "z": 9,
      "name": "Plant_Crop_Wheat_Stage_4_Burnt",
      "filler": 1024
    },
    {
      "x": -4,
      "y": 0,
      "z": 10,
      "name": "Soil_Ash"
    },
    {
      "x": -4,
      "y": 1,
      "z": 10,
      "name": "Soil_Ash"
    },
    {
      "x": -4,
      "y": 2,
      "z": 10,
      "name": "Plant_Crop_Wheat_Stage_4_Burnt"
    },
    {
      "x": -4,
      "y": 3,
      "z": 10,
      "name": "Plant_Crop_Wheat_Stage_4_Burnt",
      "filler": 1024
    },
    {
      "x": -4,
      "y": 0,
      "z": 11,
      "name": "Soil_Ash"
    },
    {
      "x": -4,
      "y": 1,
      "z": 11,
      "name": "Soil_Ash"
    },
    {
      "x": -4,
      "y": 0,
      "z": 12,
      "name": "Soil_Ash"
    },
    {
      "x": -4,
      "y": 0,
      "z": 13,
      "name": "Soil_Ash"
    },
    {
      "x": -3,
      "y": 0,
      "z": -12,
      "name": "Soil_Ash"
    },
    {
      "x": -3,
      "y": 0,
      "z": -11,
      "name": "Soil_Ash"
    },
    {
      "x": -3,
      "y": 1,
      "z": -11,
      "name": "Soil_Ash"
    },
    {
      "x": -3,
      "y": 0,
      "z": -10,
      "name": "Soil_Ash"
    },
    {
      "x": -3,
      "y": 1,
      "z": -10,
      "name": "Soil_Sand_Ashen"
    },
    {
      "x": -3,
      "y": 2,
      "z": -10,
      "name": "Soil_Sand_Ashen"
    },
    {
      "x": -3,
      "y": 0,
      "z": -9,
      "name": "Soil_Ash"
    },
    {
      "x": -3,
      "y": 1,
      "z": -9,
      "name": "Soil_Sand_Ashen"
    },
    {
      "x": -3,
      "y": 2,
      "z": -9,
      "name": "Soil_Sand_Ashen"
    },
    {
      "x": -3,
      "y": 0,
      "z": -8,
      "name": "Soil_Ash"
    },
    {
      "x": -3,
      "y": 1,
      "z": -8,
      "name": "Soil_Sand_Ashen"
    },
    {
      "x": -3,
      "y": 2,
      "z": -8,
      "name": "Soil_Sand_Ashen"
    },
    {
      "x": -3,
      "y": 0,
      "z": -7,
      "name": "Soil_Ash"
    },
    {
      "x": -3,
      "y": 1,
      "z": -7,
      "name": "Soil_Sand_Ashen"
    },
    {
      "x": -3,
      "y": 2,
      "z": -7,
      "name": "Soil_Sand_Ashen"
    },
    {
      "x": -3,
      "y": 0,
      "z": -6,
      "name": "Soil_Ash"
    },
    {
      "x": -3,
      "y": 1,
      "z": -6,
      "name": "Soil_Sand_Ashen"
    },
    {
      "x": -3,
      "y": 2,
      "z": -6,
      "name": "Soil_Sand_Ashen"
    },
    {
      "x": -3,
      "y": 3,
      "z": -6,
      "name": "Plant_Leaves_Poisoned"
    },
    {
      "x": -3,
      "y": 0,
      "z": -5,
      "name": "Soil_Ash"
    },
    {
      "x": -3,
      "y": 1,
      "z": -5,
      "name": "Soil_Sand_Ashen"
    },
    {
      "x": -3,
      "y": 2,
      "z": -5,
      "name": "Soil_Sand_Ashen"
    },
    {
      "x": -3,
      "y": 3,
      "z": -5,
      "name": "Soil_Mud"
    },
    {
      "x": -3,
      "y": 4,
      "z": -5,
      "name": "Plant_Flower_Common_Purple2"
    },
    {
      "x": -3,
      "y": 0,
      "z": -4,
      "name": "Soil_Ash"
    },
    {
      "x": -3,
      "y": 1,
      "z": -4,
      "name": "Soil_Sand_Ashen"
    },
    {
      "x": -3,
      "y": 2,
      "z": -4,
      "name": "Soil_Sand_Ashen"
    },
    {
      "x": -3,
      "y": 3,
      "z": -4,
      "name": "Soil_Mud"
    },
    {
      "x": -3,
      "y": 4,
      "z": -4,
      "name": "Soil_Mud"
    },
    {
      "x": -3,
      "y": 0,
      "z": -3,
      "name": "Soil_Ash"
    },
    {
      "x": -3,
      "y": 1,
      "z": -3,
      "name": "Soil_Sand_Ashen"
    },
    {
      "x": -3,
      "y": 2,
      "z": -3,
      "name": "Soil_Sand_Ashen"
    },
    {
      "x": -3,
      "y": 3,
      "z": -3,
      "name": "Soil_Mud"
    },
    {
      "x": -3,
      "y": 4,
      "z": -3,
      "name": "Soil_Mud"
    },
    {
      "x": -3,
      "y": 5,
      "z": -3,
      "name": "Soil_Mud"
    },
    {
      "x": -3,
      "y": 0,
      "z": -2,
      "name": "Soil_Ash"
    },
    {
      "x": -3,
      "y": 1,
      "z": -2,
      "name": "Soil_Sand_Ashen"
    },
    {
      "x": -3,
      "y": 2,
      "z": -2,
      "name": "Soil_Sand_Ashen"
    },
    {
      "x": -3,
      "y": 3,
      "z": -2,
      "name": "Soil_Mud"
    },
    {
      "x": -3,
      "y": 4,
      "z": -2,
      "name": "Soil_Mud"
    },
    {
      "x": -3,
      "y": 5,
      "z": -2,
      "name": "Soil_Mud"
    },
    {
      "x": -3,
      "y": 0,
      "z": -1,
      "name": "Soil_Ash"
    },
    {
      "x": -3,
      "y": 1,
      "z": -1,
      "name": "Soil_Sand_Ashen"
    },
    {
      "x": -3,
      "y": 2,
      "z": -1,
      "name": "Soil_Sand_Ashen"
    },
    {
      "x": -3,
      "y": 3,
      "z": -1,
      "name": "Soil_Mud"
    },
    {
      "x": -3,
      "y": 4,
      "z": -1,
      "name": "Soil_Mud"
    },
    {
      "x": -3,
      "y": 5,
      "z": -1,
      "name": "Soil_Mud"
    },
    {
      "x": -3,
      "y": 0,
      "z": 0,
      "name": "Soil_Ash"
    },
    {
      "x": -3,
      "y": 1,
      "z": 0,
      "name": "Soil_Sand_Ashen"
    },
    {
      "x": -3,
      "y": 2,
      "z": 0,
      "name": "Soil_Sand_Ashen"
    },
    {
      "x": -3,
      "y": 3,
      "z": 0,
      "name": "Soil_Mud"
    },
    {
      "x": -3,
      "y": 4,
      "z": 0,
      "name": "Soil_Mud"
    },
    {
      "x": -3,
      "y": 5,
      "z": 0,
      "name": "Soil_Mud"
    },
    {
      "x": -3,
      "y": 0,
      "z": 1,
      "name": "Soil_Ash"
    },
    {
      "x": -3,
      "y": 1,
      "z": 1,
      "name": "Soil_Sand_Ashen"
    },
    {
      "x": -3,
      "y": 2,
      "z": 1,
      "name": "Soil_Sand_Ashen"
    },
    {
      "x": -3,
      "y": 3,
      "z": 1,
      "name": "Soil_Mud"
    },
    {
      "x": -3,
      "y": 4,
      "z": 1,
      "name": "Soil_Mud"
    },
    {
      "x": -3,
      "y": 5,
      "z": 1,
      "name": "Soil_Mud"
    },
    {
      "x": -3,
      "y": 0,
      "z": 2,
      "name": "Soil_Ash"
    },
    {
      "x": -3,
      "y": 1,
      "z": 2,
      "name": "Soil_Sand_Ashen"
    },
    {
      "x": -3,
      "y": 2,
      "z": 2,
      "name": "Soil_Sand_Ashen"
    },
    {
      "x": -3,
      "y": 3,
      "z": 2,
      "name": "Soil_Mud"
    },
    {
      "x": -3,
      "y": 4,
      "z": 2,
      "name": "Soil_Ash"
    },
    {
      "x": -3,
      "y": 0,
      "z": 3,
      "name": "Soil_Ash"
    },
    {
      "x": -3,
      "y": 1,
      "z": 3,
      "name": "Soil_Sand_Ashen"
    },
    {
      "x": -3,
      "y": 2,
      "z": 3,
      "name": "Soil_Sand_Ashen"
    },
    {
      "x": -3,
      "y": 3,
      "z": 3,
      "name": "Soil_Mud"
    },
    {
      "x": -3,
      "y": 4,
      "z": 3,
      "name": "Soil_Mud"
    },
    {
      "x": -3,
      "y": 0,
      "z": 4,
      "name": "Soil_Ash"
    },
    {
      "x": -3,
      "y": 1,
      "z": 4,
      "name": "Soil_Sand_Ashen"
    },
    {
      "x": -3,
      "y": 2,
      "z": 4,
      "name": "Soil_Sand_Ashen"
    },
    {
      "x": -3,
      "y": 3,
      "z": 4,
      "name": "Soil_Mud"
    },
    {
      "x": -3,
      "y": 4,
      "z": 4,
      "name": "Soil_Mud"
    },
    {
      "x": -3,
      "y": 5,
      "z": 4,
      "name": "Soil_Mud"
    },
    {
      "x": -3,
      "y": 0,
      "z": 5,
      "name": "Soil_Ash"
    },
    {
      "x": -3,
      "y": 1,
      "z": 5,
      "name": "Soil_Sand_Ashen"
    },
    {
      "x": -3,
      "y": 2,
      "z": 5,
      "name": "Soil_Sand_Ashen"
    },
    {
      "x": -3,
      "y": 3,
      "z": 5,
      "name": "Soil_Mud"
    },
    {
      "x": -3,
      "y": 4,
      "z": 5,
      "name": "Soil_Mud"
    },
    {
      "x": -3,
      "y": 5,
      "z": 5,
      "name": "Soil_Mud"
    },
    {
      "x": -3,
      "y": 0,
      "z": 6,
      "name": "Soil_Ash"
    },
    {
      "x": -3,
      "y": 1,
      "z": 6,
      "name": "Soil_Sand_Ashen"
    },
    {
      "x": -3,
      "y": 2,
      "z": 6,
      "name": "Soil_Sand_Ashen"
    },
    {
      "x": -3,
      "y": 3,
      "z": 6,
      "name": "Soil_Mud"
    },
    {
      "x": -3,
      "y": 4,
      "z": 6,
      "name": "Soil_Mud"
    },
    {
      "x": -3,
      "y": 5,
      "z": 6,
      "name": "Soil_Mud"
    },
    {
      "x": -3,
      "y": 0,
      "z": 7,
      "name": "Soil_Ash"
    },
    {
      "x": -3,
      "y": 1,
      "z": 7,
      "name": "Soil_Sand_Ashen"
    },
    {
      "x": -3,
      "y": 2,
      "z": 7,
      "name": "Soil_Sand_Ashen"
    },
    {
      "x": -3,
      "y": 3,
      "z": 7,
      "name": "Soil_Mud"
    },
    {
      "x": -3,
      "y": 4,
      "z": 7,
      "name": "Soil_Mud"
    },
    {
      "x": -3,
      "y": 0,
      "z": 8,
      "name": "Soil_Ash"
    },
    {
      "x": -3,
      "y": 1,
      "z": 8,
      "name": "Soil_Sand_Ashen"
    },
    {
      "x": -3,
      "y": 2,
      "z": 8,
      "name": "Soil_Sand_Ashen"
    },
    {
      "x": -3,
      "y": 3,
      "z": 8,
      "name": "Soil_Mud"
    },
    {
      "x": -3,
      "y": 4,
      "z": 8,
      "name": "Soil_Mud"
    },
    {
      "x": -3,
      "y": 0,
      "z": 9,
      "name": "Soil_Ash"
    },
    {
      "x": -3,
      "y": 1,
      "z": 9,
      "name": "Soil_Sand_Ashen"
    },
    {
      "x": -3,
      "y": 2,
      "z": 9,
      "name": "Soil_Sand_Ashen"
    },
    {
      "x": -3,
      "y": 0,
      "z": 10,
      "name": "Soil_Ash"
    },
    {
      "x": -3,
      "y": 1,
      "z": 10,
      "name": "Soil_Sand_Ashen"
    },
    {
      "x": -3,
      "y": 0,
      "z": 11,
      "name": "Soil_Ash"
    },
    {
      "x": -3,
      "y": 1,
      "z": 11,
      "name": "Soil_Sand_Ashen"
    },
    {
      "x": -3,
      "y": 0,
      "z": 12,
      "name": "Soil_Ash"
    },
    {
      "x": -2,
      "y": 0,
      "z": -11,
      "name": "Soil_Ash"
    },
    {
      "x": -2,
      "y": 1,
      "z": -11,
      "name": "Soil_Ash"
    },
    {
      "x": -2,
      "y": 0,
      "z": -10,
      "name": "Soil_Ash"
    },
    {
      "x": -2,
      "y": 1,
      "z": -10,
      "name": "Soil_Sand_Ashen"
    },
    {
      "x": -2,
      "y": 0,
      "z": -9,
      "name": "Soil_Ash"
    },
    {
      "x": -2,
      "y": 1,
      "z": -9,
      "name": "Soil_Sand_Ashen"
    },
    {
      "x": -2,
      "y": 2,
      "z": -9,
      "name": "Soil_Sand_Ashen"
    },
    {
      "x": -2,
      "y": 0,
      "z": -8,
      "name": "Soil_Ash"
    },
    {
      "x": -2,
      "y": 1,
      "z": -8,
      "name": "Soil_Sand_Ashen"
    },
    {
      "x": -2,
      "y": 2,
      "z": -8,
      "name": "Soil_Sand_Ashen"
    },
    {
      "x": -2,
      "y": 0,
      "z": -7,
      "name": "Soil_Ash"
    },
    {
      "x": -2,
      "y": 1,
      "z": -7,
      "name": "Soil_Sand_Ashen"
    },
    {
      "x": -2,
      "y": 2,
      "z": -7,
      "name": "Soil_Sand_Ashen"
    },
    {
      "x": -2,
      "y": 3,
      "z": -7,
      "name": "Plant_Leaves_Poisoned"
    },
    {
      "x": -2,
      "y": 0,
      "z": -6,
      "name": "Soil_Ash"
    },
    {
      "x": -2,
      "y": 1,
      "z": -6,
      "name": "Soil_Sand_Ashen"
    },
    {
      "x": -2,
      "y": 2,
      "z": -6,
      "name": "Soil_Sand_Ashen"
    },
    {
      "x": -2,
      "y": 3,
      "z": -6,
      "name": "Plant_Leaves_Poisoned"
    },
    {
      "x": -2,
      "y": 4,
      "z": -6,
      "name": "Plant_Leaves_Poisoned"
    },
    {
      "x": -2,
      "y": 0,
      "z": -5,
      "name": "Soil_Ash"
    },
    {
      "x": -2,
      "y": 1,
      "z": -5,
      "name": "Soil_Sand_Ashen"
    },
    {
      "x": -2,
      "y": 2,
      "z": -5,
      "name": "Soil_Sand_Ashen"
    },
    {
      "x": -2,
      "y": 3,
      "z": -5,
      "name": "Soil_Mud"
    },
    {
      "x": -2,
      "y": 4,
      "z": -5,
      "name": "Soil_Mud"
    },
    {
      "x": -2,
      "y": 5,
      "z": -5,
      "name": "Plant_Flower_Common_Purple2"
    },
    {
      "x": -2,
      "y": 0,
      "z": -4,
      "name": "Soil_Ash"
    },
    {
      "x": -2,
      "y": 1,
      "z": -4,
      "name": "Soil_Sand_Ashen"
    },
    {
      "x": -2,
      "y": 2,
      "z": -4,
      "name": "Soil_Sand_Ashen"
    },
    {
      "x": -2,
      "y": 3,
      "z": -4,
      "name": "Soil_Mud"
    },
    {
      "x": -2,
      "y": 4,
      "z": -4,
      "name": "Soil_Mud"
    },
    {
      "x": -2,
      "y": 0,
      "z": -3,
      "name": "Soil_Ash"
    },
    {
      "x": -2,
      "y": 1,
      "z": -3,
      "name": "Soil_Sand_Ashen"
    },
    {
      "x": -2,
      "y": 2,
      "z": -3,
      "name": "Soil_Sand_Ashen"
    },
    {
      "x": -2,
      "y": 3,
      "z": -3,
      "name": "Soil_Mud"
    },
    {
      "x": -2,
      "y": 4,
      "z": -3,
      "name": "Soil_Mud"
    },
    {
      "x": -2,
      "y": 5,
      "z": -3,
      "name": "Soil_Mud"
    },
    {
      "x": -2,
      "y": 0,
      "z": -2,
      "name": "Soil_Ash"
    },
    {
      "x": -2,
      "y": 1,
      "z": -2,
      "name": "Soil_Sand_Ashen"
    },
    {
      "x": -2,
      "y": 2,
      "z": -2,
      "name": "Soil_Sand_Ashen"
    },
    {
      "x": -2,
      "y": 3,
      "z": -2,
      "name": "Soil_Mud"
    },
    {
      "x": -2,
      "y": 4,
      "z": -2,
      "name": "Soil_Mud"
    },
    {
      "x": -2,
      "y": 5,
      "z": -2,
      "name": "Soil_Mud"
    },
    {
      "x": -2,
      "y": 0,
      "z": -1,
      "name": "Soil_Ash"
    },
    {
      "x": -2,
      "y": 1,
      "z": -1,
      "name": "Soil_Sand_Ashen"
    },
    {
      "x": -2,
      "y": 2,
      "z": -1,
      "name": "Soil_Sand_Ashen"
    },
    {
      "x": -2,
      "y": 3,
      "z": -1,
      "name": "Soil_Mud"
    },
    {
      "x": -2,
      "y": 4,
      "z": -1,
      "name": "Soil_Mud"
    },
    {
      "x": -2,
      "y": 5,
      "z": -1,
      "name": "Soil_Mud"
    },
    {
      "x": -2,
      "y": 0,
      "z": 0,
      "name": "Soil_Ash"
    },
    {
      "x": -2,
      "y": 1,
      "z": 0,
      "name": "Soil_Sand_Ashen"
    },
    {
      "x": -2,
      "y": 2,
      "z": 0,
      "name": "Soil_Sand_Ashen"
    },
    {
      "x": -2,
      "y": 3,
      "z": 0,
      "name": "Soil_Mud"
    },
    {
      "x": -2,
      "y": 4,
      "z": 0,
      "name": "Soil_Mud"
    },
    {
      "x": -2,
      "y": 5,
      "z": 0,
      "name": "Soil_Mud"
    },
    {
      "x": -2,
      "y": 0,
      "z": 1,
      "name": "Soil_Ash"
    },
    {
      "x": -2,
      "y": 1,
      "z": 1,
      "name": "Soil_Sand_Ashen"
    },
    {
      "x": -2,
      "y": 2,
      "z": 1,
      "name": "Soil_Sand_Ashen"
    },
    {
      "x": -2,
      "y": 3,
      "z": 1,
      "name": "Soil_Mud"
    },
    {
      "x": -2,
      "y": 4,
      "z": 1,
      "name": "Soil_Mud"
    },
    {
      "x": -2,
      "y": 5,
      "z": 1,
      "name": "Soil_Ash"
    },
    {
      "x": -2,
      "y": 0,
      "z": 2,
      "name": "Soil_Ash"
    },
    {
      "x": -2,
      "y": 1,
      "z": 2,
      "name": "Soil_Sand_Ashen"
    },
    {
      "x": -2,
      "y": 2,
      "z": 2,
      "name": "Soil_Sand_Ashen"
    },
    {
      "x": -2,
      "y": 3,
      "z": 2,
      "name": "Soil_Mud"
    },
    {
      "x": -2,
      "y": 4,
      "z": 2,
      "name": "Soil_Mud"
    },
    {
      "x": -2,
      "y": 5,
      "z": 2,
      "name": "Soil_Ash"
    },
    {
      "x": -2,
      "y": 0,
      "z": 3,
      "name": "Soil_Ash"
    },
    {
      "x": -2,
      "y": 1,
      "z": 3,
      "name": "Soil_Sand_Ashen"
    },
    {
      "x": -2,
      "y": 2,
      "z": 3,
      "name": "Soil_Sand_Ashen"
    },
    {
      "x": -2,
      "y": 3,
      "z": 3,
      "name": "Soil_Mud"
    },
    {
      "x": -2,
      "y": 4,
      "z": 3,
      "name": "Soil_Mud"
    },
    {
      "x": -2,
      "y": 5,
      "z": 3,
      "name": "Soil_Mud"
    },
    {
      "x": -2,
      "y": 0,
      "z": 4,
      "name": "Soil_Ash"
    },
    {
      "x": -2,
      "y": 1,
      "z": 4,
      "name": "Soil_Sand_Ashen"
    },
    {
      "x": -2,
      "y": 2,
      "z": 4,
      "name": "Soil_Sand_Ashen"
    },
    {
      "x": -2,
      "y": 3,
      "z": 4,
      "name": "Soil_Mud"
    },
    {
      "x": -2,
      "y": 4,
      "z": 4,
      "name": "Soil_Mud"
    },
    {
      "x": -2,
      "y": 5,
      "z": 4,
      "name": "Soil_Mud"
    },
    {
      "x": -2,
      "y": 0,
      "z": 5,
      "name": "Soil_Ash"
    },
    {
      "x": -2,
      "y": 1,
      "z": 5,
      "name": "Soil_Sand_Ashen"
    },
    {
      "x": -2,
      "y": 2,
      "z": 5,
      "name": "Soil_Sand_Ashen"
    },
    {
      "x": -2,
      "y": 3,
      "z": 5,
      "name": "Soil_Mud"
    },
    {
      "x": -2,
      "y": 4,
      "z": 5,
      "name": "Soil_Mud"
    },
    {
      "x": -2,
      "y": 5,
      "z": 5,
      "name": "Soil_Mud"
    },
    {
      "x": -2,
      "y": 0,
      "z": 6,
      "name": "Soil_Ash"
    },
    {
      "x": -2,
      "y": 1,
      "z": 6,
      "name": "Soil_Sand_Ashen"
    },
    {
      "x": -2,
      "y": 2,
      "z": 6,
      "name": "Soil_Sand_Ashen"
    },
    {
      "x": -2,
      "y": 3,
      "z": 6,
      "name": "Soil_Mud"
    },
    {
      "x": -2,
      "y": 4,
      "z": 6,
      "name": "Soil_Mud"
    },
    {
      "x": -2,
      "y": 5,
      "z": 6,
      "name": "Soil_Mud"
    },
    {
      "x": -2,
      "y": 6,
      "z": 6,
      "name": "Plant_Grass_Cave_Short"
    },
    {
      "x": -2,
      "y": 0,
      "z": 7,
      "name": "Soil_Ash"
    },
    {
      "x": -2,
      "y": 1,
      "z": 7,
      "name": "Soil_Sand_Ashen"
    },
    {
      "x": -2,
      "y": 2,
      "z": 7,
      "name": "Soil_Sand_Ashen"
    },
    {
      "x": -2,
      "y": 3,
      "z": 7,
      "name": "Soil_Mud"
    },
    {
      "x": -2,
      "y": 4,
      "z": 7,
      "name": "Soil_Mud"
    },
    {
      "x": -2,
      "y": 5,
      "z": 7,
      "name": "Soil_Mud"
    },
    {
      "x": -2,
      "y": 6,
      "z": 7,
      "name": "Plant_Moss_Rug_Red"
    },
    {
      "x": -2,
      "y": 0,
      "z": 8,
      "name": "Soil_Ash"
    },
    {
      "x": -2,
      "y": 1,
      "z": 8,
      "name": "Soil_Sand_Ashen"
    },
    {
      "x": -2,
      "y": 2,
      "z": 8,
      "name": "Soil_Sand_Ashen"
    },
    {
      "x": -2,
      "y": 3,
      "z": 8,
      "name": "Soil_Mud"
    },
    {
      "x": -2,
      "y": 4,
      "z": 8,
      "name": "Soil_Mud"
    },
    {
      "x": -2,
      "y": 5,
      "z": 8,
      "name": "Plant_Moss_Rug_Red"
    },
    {
      "x": -2,
      "y": 0,
      "z": 9,
      "name": "Soil_Ash"
    },
    {
      "x": -2,
      "y": 1,
      "z": 9,
      "name": "Soil_Sand_Ashen"
    },
    {
      "x": -2,
      "y": 2,
      "z": 9,
      "name": "Soil_Sand_Ashen"
    },
    {
      "x": -2,
      "y": 3,
      "z": 9,
      "name": "Soil_Mud"
    },
    {
      "x": -2,
      "y": 4,
      "z": 9,
      "name": "Plant_Moss_Rug_Red"
    },
    {
      "x": -2,
      "y": 0,
      "z": 10,
      "name": "Soil_Ash"
    },
    {
      "x": -2,
      "y": 1,
      "z": 10,
      "name": "Soil_Sand_Ashen"
    },
    {
      "x": -2,
      "y": 3,
      "z": 10,
      "name": "Plant_Moss_Wall_Red"
    },
    {
      "x": -2,
      "y": 0,
      "z": 11,
      "name": "Soil_Ash"
    },
    {
      "x": -2,
      "y": 0,
      "z": 12,
      "name": "Soil_Ash"
    },
    {
      "x": -1,
      "y": 0,
      "z": -11,
      "name": "Soil_Ash"
    },
    {
      "x": -1,
      "y": 0,
      "z": -10,
      "name": "Soil_Ash"
    },
    {
      "x": -1,
      "y": 1,
      "z": -10,
      "name": "Soil_Sand_Ashen"
    },
    {
      "x": -1,
      "y": 0,
      "z": -9,
      "name": "Soil_Ash"
    },
    {
      "x": -1,
      "y": 1,
      "z": -9,
      "name": "Soil_Sand_Ashen"
    },
    {
      "x": -1,
      "y": 0,
      "z": -8,
      "name": "Soil_Ash"
    },
    {
      "x": -1,
      "y": 1,
      "z": -8,
      "name": "Soil_Sand_Ashen"
    },
    {
      "x": -1,
      "y": 0,
      "z": -7,
      "name": "Soil_Ash"
    },
    {
      "x": -1,
      "y": 1,
      "z": -7,
      "name": "Soil_Sand_Ashen"
    },
    {
      "x": -1,
      "y": 2,
      "z": -7,
      "name": "Soil_Sand_Ashen"
    },
    {
      "x": -1,
      "y": 0,
      "z": -6,
      "name": "Soil_Ash"
    },
    {
      "x": -1,
      "y": 1,
      "z": -6,
      "name": "Soil_Sand_Ashen"
    },
    {
      "x": -1,
      "y": 2,
      "z": -6,
      "name": "Soil_Sand_Ashen"
    },
    {
      "x": -1,
      "y": 3,
      "z": -6,
      "name": "Plant_Leaves_Poisoned"
    },
    {
      "x": -1,
      "y": 0,
      "z": -5,
      "name": "Soil_Ash"
    },
    {
      "x": -1,
      "y": 1,
      "z": -5,
      "name": "Soil_Sand_Ashen"
    },
    {
      "x": -1,
      "y": 2,
      "z": -5,
      "name": "Soil_Sand_Ashen"
    },
    {
      "x": -1,
      "y": 3,
      "z": -5,
      "name": "Soil_Mud"
    },
    {
      "x": -1,
      "y": 0,
      "z": -4,
      "name": "Soil_Ash"
    },
    {
      "x": -1,
      "y": 1,
      "z": -4,
      "name": "Soil_Sand_Ashen"
    },
    {
      "x": -1,
      "y": 2,
      "z": -4,
      "name": "Soil_Sand_Ashen"
    },
    {
      "x": -1,
      "y": 3,
      "z": -4,
      "name": "Soil_Mud"
    },
    {
      "x": -1,
      "y": 4,
      "z": -4,
      "name": "Soil_Mud"
    },
    {
      "x": -1,
      "y": 0,
      "z": -3,
      "name": "Soil_Ash"
    },
    {
      "x": -1,
      "y": 1,
      "z": -3,
      "name": "Soil_Sand_Ashen"
    },
    {
      "x": -1,
      "y": 2,
      "z": -3,
      "name": "Soil_Sand_Ashen"
    },
    {
      "x": -1,
      "y": 3,
      "z": -3,
      "name": "Soil_Mud"
    },
    {
      "x": -1,
      "y": 4,
      "z": -3,
      "name": "Soil_Mud"
    },
    {
      "x": -1,
      "y": 5,
      "z": -3,
      "name": "Soil_Mud"
    },
    {
      "x": -1,
      "y": 0,
      "z": -2,
      "name": "Soil_Ash"
    },
    {
      "x": -1,
      "y": 1,
      "z": -2,
      "name": "Soil_Sand_Ashen"
    },
    {
      "x": -1,
      "y": 2,
      "z": -2,
      "name": "Soil_Sand_Ashen"
    },
    {
      "x": -1,
      "y": 3,
      "z": -2,
      "name": "Soil_Mud"
    },
    {
      "x": -1,
      "y": 4,
      "z": -2,
      "name": "Soil_Mud"
    },
    {
      "x": -1,
      "y": 5,
      "z": -2,
      "name": "Soil_Mud"
    },
    {
      "x": -1,
      "y": 0,
      "z": -1,
      "name": "Soil_Ash"
    },
    {
      "x": -1,
      "y": 1,
      "z": -1,
      "name": "Soil_Sand_Ashen"
    },
    {
      "x": -1,
      "y": 2,
      "z": -1,
      "name": "Soil_Sand_Ashen"
    },
    {
      "x": -1,
      "y": 3,
      "z": -1,
      "name": "Soil_Mud"
    },
    {
      "x": -1,
      "y": 4,
      "z": -1,
      "name": "Soil_Mud"
    },
    {
      "x": -1,
      "y": 5,
      "z": -1,
      "name": "Soil_Mud"
    },
    {
      "x": -1,
      "y": 0,
      "z": 0,
      "name": "Soil_Ash"
    },
    {
      "x": -1,
      "y": 1,
      "z": 0,
      "name": "Soil_Sand_Ashen"
    },
    {
      "x": -1,
      "y": 2,
      "z": 0,
      "name": "Soil_Sand_Ashen"
    },
    {
      "x": -1,
      "y": 3,
      "z": 0,
      "name": "Soil_Mud"
    },
    {
      "x": -1,
      "y": 4,
      "z": 0,
      "name": "Soil_Mud"
    },
    {
      "x": -1,
      "y": 5,
      "z": 0,
      "name": "Soil_Mud"
    },
    {
      "x": -1,
      "y": 0,
      "z": 1,
      "name": "Soil_Ash"
    },
    {
      "x": -1,
      "y": 1,
      "z": 1,
      "name": "Soil_Sand_Ashen"
    },
    {
      "x": -1,
      "y": 2,
      "z": 1,
      "name": "Soil_Sand_Ashen"
    },
    {
      "x": -1,
      "y": 3,
      "z": 1,
      "name": "Soil_Mud"
    },
    {
      "x": -1,
      "y": 4,
      "z": 1,
      "name": "Soil_Mud"
    },
    {
      "x": -1,
      "y": 5,
      "z": 1,
      "name": "Soil_Ash"
    },
    {
      "x": -1,
      "y": 0,
      "z": 2,
      "name": "Soil_Ash"
    },
    {
      "x": -1,
      "y": 1,
      "z": 2,
      "name": "Soil_Sand_Ashen"
    },
    {
      "x": -1,
      "y": 2,
      "z": 2,
      "name": "Soil_Sand_Ashen"
    },
    {
      "x": -1,
      "y": 3,
      "z": 2,
      "name": "Soil_Mud"
    },
    {
      "x": -1,
      "y": 4,
      "z": 2,
      "name": "Soil_Mud"
    },
    {
      "x": -1,
      "y": 5,
      "z": 2,
      "name": "Soil_Mud"
    },
    {
      "x": -1,
      "y": 0,
      "z": 3,
      "name": "Soil_Ash"
    },
    {
      "x": -1,
      "y": 1,
      "z": 3,
      "name": "Soil_Sand_Ashen"
    },
    {
      "x": -1,
      "y": 2,
      "z": 3,
      "name": "Soil_Sand_Ashen"
    },
    {
      "x": -1,
      "y": 3,
      "z": 3,
      "name": "Soil_Mud"
    },
    {
      "x": -1,
      "y": 4,
      "z": 3,
      "name": "Soil_Mud"
    },
    {
      "x": -1,
      "y": 5,
      "z": 3,
      "name": "Soil_Mud"
    },
    {
      "x": -1,
      "y": 0,
      "z": 4,
      "name": "Soil_Ash"
    },
    {
      "x": -1,
      "y": 1,
      "z": 4,
      "name": "Soil_Sand_Ashen"
    },
    {
      "x": -1,
      "y": 2,
      "z": 4,
      "name": "Soil_Sand_Ashen"
    },
    {
      "x": -1,
      "y": 3,
      "z": 4,
      "name": "Soil_Mud"
    },
    {
      "x": -1,
      "y": 4,
      "z": 4,
      "name": "Soil_Mud"
    },
    {
      "x": -1,
      "y": 5,
      "z": 4,
      "name": "Soil_Mud"
    },
    {
      "x": -1,
      "y": 0,
      "z": 5,
      "name": "Soil_Ash"
    },
    {
      "x": -1,
      "y": 1,
      "z": 5,
      "name": "Soil_Sand_Ashen"
    },
    {
      "x": -1,
      "y": 2,
      "z": 5,
      "name": "Soil_Sand_Ashen"
    },
    {
      "x": -1,
      "y": 3,
      "z": 5,
      "name": "Soil_Mud"
    },
    {
      "x": -1,
      "y": 4,
      "z": 5,
      "name": "Soil_Mud"
    },
    {
      "x": -1,
      "y": 5,
      "z": 5,
      "name": "Soil_Mud"
    },
    {
      "x": -1,
      "y": 0,
      "z": 6,
      "name": "Soil_Ash"
    },
    {
      "x": -1,
      "y": 1,
      "z": 6,
      "name": "Soil_Sand_Ashen"
    },
    {
      "x": -1,
      "y": 2,
      "z": 6,
      "name": "Soil_Sand_Ashen"
    },
    {
      "x": -1,
      "y": 3,
      "z": 6,
      "name": "Soil_Mud"
    },
    {
      "x": -1,
      "y": 4,
      "z": 6,
      "name": "Soil_Mud"
    },
    {
      "x": -1,
      "y": 5,
      "z": 6,
      "name": "Soil_Mud"
    },
    {
      "x": -1,
      "y": 6,
      "z": 6,
      "name": "Plant_Grass_Cave_Short"
    },
    {
      "x": -1,
      "y": 0,
      "z": 7,
      "name": "Soil_Ash"
    },
    {
      "x": -1,
      "y": 1,
      "z": 7,
      "name": "Soil_Sand_Ashen"
    },
    {
      "x": -1,
      "y": 2,
      "z": 7,
      "name": "Soil_Sand_Ashen"
    },
    {
      "x": -1,
      "y": 3,
      "z": 7,
      "name": "Soil_Mud"
    },
    {
      "x": -1,
      "y": 4,
      "z": 7,
      "name": "Soil_Mud"
    },
    {
      "x": -1,
      "y": 5,
      "z": 7,
      "name": "Soil_Mud"
    },
    {
      "x": -1,
      "y": 6,
      "z": 7,
      "name": "Plant_Moss_Rug_Red"
    },
    {
      "x": -1,
      "y": 0,
      "z": 8,
      "name": "Soil_Ash"
    },
    {
      "x": -1,
      "y": 1,
      "z": 8,
      "name": "Soil_Sand_Ashen"
    },
    {
      "x": -1,
      "y": 2,
      "z": 8,
      "name": "Soil_Sand_Ashen"
    },
    {
      "x": -1,
      "y": 3,
      "z": 8,
      "name": "Soil_Mud"
    },
    {
      "x": -1,
      "y": 4,
      "z": 8,
      "name": "Soil_Mud"
    },
    {
      "x": -1,
      "y": 5,
      "z": 8,
      "name": "Plant_Moss_Rug_Red"
    },
    {
      "x": -1,
      "y": 0,
      "z": 9,
      "name": "Soil_Ash"
    },
    {
      "x": -1,
      "y": 1,
      "z": 9,
      "name": "Soil_Sand_Ashen"
    },
    {
      "x": -1,
      "y": 2,
      "z": 9,
      "name": "Soil_Sand_Ashen"
    },
    {
      "x": -1,
      "y": 3,
      "z": 9,
      "name": "Soil_Mud"
    },
    {
      "x": -1,
      "y": 4,
      "z": 9,
      "name": "Soil_Mud"
    },
    {
      "x": -1,
      "y": 5,
      "z": 9,
      "name": "Plant_Moss_Rug_Red"
    },
    {
      "x": -1,
      "y": 0,
      "z": 10,
      "name": "Soil_Ash"
    },
    {
      "x": -1,
      "y": 1,
      "z": 10,
      "name": "Soil_Sand_Ashen"
    },
    {
      "x": -1,
      "y": 3,
      "z": 10,
      "name": "Plant_Moss_Wall_Red"
    },
    {
      "x": -1,
      "y": 4,
      "z": 10,
      "name": "Plant_Moss_Wall_Red"
    },
    {
      "x": -1,
      "y": 0,
      "z": 11,
      "name": "Soil_Ash"
    },
    {
      "x": 0,
      "y": 0,
      "z": -9,
      "name": "Soil_Ash"
    },
    {
      "x": 0,
      "y": 0,
      "z": -8,
      "name": "Soil_Ash"
    },
    {
      "x": 0,
      "y": 1,
      "z": -8,
      "name": "Soil_Sand_Ashen"
    },
    {
      "x": 0,
      "y": 0,
      "z": -7,
      "name": "Soil_Ash"
    },
    {
      "x": 0,
      "y": 1,
      "z": -7,
      "name": "Soil_Sand_Ashen"
    },
    {
      "x": 0,
      "y": 2,
      "z": -7,
      "name": "Soil_Sand_Ashen"
    },
    {
      "x": 0,
      "y": 3,
      "z": -7,
      "name": "Plant_Bush_Dead_Hanging"
    },
    {
      "x": 0,
      "y": 0,
      "z": -6,
      "name": "Soil_Ash"
    },
    {
      "x": 0,
      "y": 1,
      "z": -6,
      "name": "Soil_Sand_Ashen"
    },
    {
      "x": 0,
      "y": 2,
      "z": -6,
      "name": "Soil_Sand_Ashen"
    },
    {
      "x": 0,
      "y": 3,
      "z": -6,
      "name": "Soil_Mud"
    },
    {
      "x": 0,
      "y": 4,
      "z": -6,
      "name": "Plant_Bush_Dead_Hanging"
    },
    {
      "x": 0,
      "y": 0,
      "z": -5,
      "name": "Soil_Ash"
    },
    {
      "x": 0,
      "y": 1,
      "z": -5,
      "name": "Soil_Sand_Ashen"
    },
    {
      "x": 0,
      "y": 2,
      "z": -5,
      "name": "Soil_Sand_Ashen"
    },
    {
      "x": 0,
      "y": 3,
      "z": -5,
      "name": "Soil_Mud"
    },
    {
      "x": 0,
      "y": 4,
      "z": -5,
      "name": "Plant_Bush_Dead_Hanging"
    },
    {
      "x": 0,
      "y": 0,
      "z": -4,
      "name": "Soil_Ash"
    },
    {
      "x": 0,
      "y": 1,
      "z": -4,
      "name": "Soil_Sand_Ashen"
    },
    {
      "x": 0,
      "y": 2,
      "z": -4,
      "name": "Soil_Sand_Ashen"
    },
    {
      "x": 0,
      "y": 3,
      "z": -4,
      "name": "Soil_Mud"
    },
    {
      "x": 0,
      "y": 4,
      "z": -4,
      "name": "Soil_Mud"
    },
    {
      "x": 0,
      "y": 0,
      "z": -3,
      "name": "Soil_Ash"
    },
    {
      "x": 0,
      "y": 1,
      "z": -3,
      "name": "Soil_Sand_Ashen"
    },
    {
      "x": 0,
      "y": 2,
      "z": -3,
      "name": "Soil_Sand_Ashen"
    },
    {
      "x": 0,
      "y": 3,
      "z": -3,
      "name": "Soil_Mud"
    },
    {
      "x": 0,
      "y": 4,
      "z": -3,
      "name": "Soil_Mud"
    },
    {
      "x": 0,
      "y": 0,
      "z": -2,
      "name": "Soil_Ash"
    },
    {
      "x": 0,
      "y": 1,
      "z": -2,
      "name": "Soil_Sand_Ashen"
    },
    {
      "x": 0,
      "y": 2,
      "z": -2,
      "name": "Soil_Sand_Ashen"
    },
    {
      "x": 0,
      "y": 3,
      "z": -2,
      "name": "Soil_Mud"
    },
    {
      "x": 0,
      "y": 4,
      "z": -2,
      "name": "Soil_Mud"
    },
    {
      "x": 0,
      "y": 5,
      "z": -2,
      "name": "Soil_Mud"
    },
    {
      "x": 0,
      "y": 0,
      "z": -1,
      "name": "Soil_Ash"
    },
    {
      "x": 0,
      "y": 1,
      "z": -1,
      "name": "Soil_Sand_Ashen"
    },
    {
      "x": 0,
      "y": 2,
      "z": -1,
      "name": "Soil_Sand_Ashen"
    },
    {
      "x": 0,
      "y": 3,
      "z": -1,
      "name": "Soil_Mud"
    },
    {
      "x": 0,
      "y": 4,
      "z": -1,
      "name": "Soil_Mud"
    },
    {
      "x": 0,
      "y": 5,
      "z": -1,
      "name": "Soil_Mud"
    },
    {
      "x": 0,
      "y": 0,
      "z": 0,
      "name": "Soil_Ash"
    },
    {
      "x": 0,
      "y": 1,
      "z": 0,
      "name": "Soil_Sand_Ashen"
    },
    {
      "x": 0,
      "y": 2,
      "z": 0,
      "name": "Soil_Sand_Ashen"
    },
    {
      "x": 0,
      "y": 3,
      "z": 0,
      "name": "Soil_Mud"
    },
    {
      "x": 0,
      "y": 4,
      "z": 0,
      "name": "Soil_Mud"
    },
    {
      "x": 0,
      "y": 5,
      "z": 0,
      "name": "Soil_Ash"
    },
    {
      "x": 0,
      "y": 0,
      "z": 1,
      "name": "Soil_Ash"
    },
    {
      "x": 0,
      "y": 1,
      "z": 1,
      "name": "Soil_Sand_Ashen"
    },
    {
      "x": 0,
      "y": 2,
      "z": 1,
      "name": "Soil_Sand_Ashen"
    },
    {
      "x": 0,
      "y": 3,
      "z": 1,
      "name": "Soil_Mud"
    },
    {
      "x": 0,
      "y": 4,
      "z": 1,
      "name": "Soil_Mud"
    },
    {
      "x": 0,
      "y": 5,
      "z": 1,
      "name": "Soil_Ash"
    },
    {
      "x": 0,
      "y": 0,
      "z": 2,
      "name": "Soil_Ash"
    },
    {
      "x": 0,
      "y": 1,
      "z": 2,
      "name": "Soil_Sand_Ashen"
    },
    {
      "x": 0,
      "y": 2,
      "z": 2,
      "name": "Soil_Sand_Ashen"
    },
    {
      "x": 0,
      "y": 3,
      "z": 2,
      "name": "Soil_Mud"
    },
    {
      "x": 0,
      "y": 4,
      "z": 2,
      "name": "Soil_Mud"
    },
    {
      "x": 0,
      "y": 5,
      "z": 2,
      "name": "Soil_Mud"
    },
    {
      "x": 0,
      "y": 0,
      "z": 3,
      "name": "Soil_Ash"
    },
    {
      "x": 0,
      "y": 1,
      "z": 3,
      "name": "Soil_Sand_Ashen"
    },
    {
      "x": 0,
      "y": 2,
      "z": 3,
      "name": "Soil_Sand_Ashen"
    },
    {
      "x": 0,
      "y": 3,
      "z": 3,
      "name": "Soil_Mud"
    },
    {
      "x": 0,
      "y": 4,
      "z": 3,
      "name": "Soil_Mud"
    },
    {
      "x": 0,
      "y": 5,
      "z": 3,
      "name": "Soil_Mud"
    },
    {
      "x": 0,
      "y": 0,
      "z": 4,
      "name": "Soil_Ash"
    },
    {
      "x": 0,
      "y": 1,
      "z": 4,
      "name": "Soil_Sand_Ashen"
    },
    {
      "x": 0,
      "y": 2,
      "z": 4,
      "name": "Soil_Sand_Ashen"
    },
    {
      "x": 0,
      "y": 3,
      "z": 4,
      "name": "Soil_Mud"
    },
    {
      "x": 0,
      "y": 4,
      "z": 4,
      "name": "Soil_Mud"
    },
    {
      "x": 0,
      "y": 5,
      "z": 4,
      "name": "Soil_Mud"
    },
    {
      "x": 0,
      "y": 0,
      "z": 5,
      "name": "Soil_Ash"
    },
    {
      "x": 0,
      "y": 1,
      "z": 5,
      "name": "Soil_Sand_Ashen"
    },
    {
      "x": 0,
      "y": 2,
      "z": 5,
      "name": "Soil_Sand_Ashen"
    },
    {
      "x": 0,
      "y": 3,
      "z": 5,
      "name": "Soil_Mud"
    },
    {
      "x": 0,
      "y": 4,
      "z": 5,
      "name": "Soil_Mud"
    },
    {
      "x": 0,
      "y": 5,
      "z": 5,
      "name": "Soil_Mud"
    },
    {
      "x": 0,
      "y": 0,
      "z": 6,
      "name": "Soil_Ash"
    },
    {
      "x": 0,
      "y": 1,
      "z": 6,
      "name": "Soil_Sand_Ashen"
    },
    {
      "x": 0,
      "y": 2,
      "z": 6,
      "name": "Soil_Sand_Ashen"
    },
    {
      "x": 0,
      "y": 3,
      "z": 6,
      "name": "Soil_Mud"
    },
    {
      "x": 0,
      "y": 4,
      "z": 6,
      "name": "Soil_Mud"
    },
    {
      "x": 0,
      "y": 5,
      "z": 6,
      "name": "Soil_Mud"
    },
    {
      "x": 0,
      "y": 0,
      "z": 7,
      "name": "Soil_Ash"
    },
    {
      "x": 0,
      "y": 1,
      "z": 7,
      "name": "Soil_Sand_Ashen"
    },
    {
      "x": 0,
      "y": 2,
      "z": 7,
      "name": "Soil_Sand_Ashen"
    },
    {
      "x": 0,
      "y": 3,
      "z": 7,
      "name": "Soil_Mud"
    },
    {
      "x": 0,
      "y": 4,
      "z": 7,
      "name": "Soil_Mud"
    },
    {
      "x": 0,
      "y": 5,
      "z": 7,
      "name": "Soil_Mud"
    },
    {
      "x": 0,
      "y": 6,
      "z": 7,
      "name": "Plant_Grass_Cave_Short"
    },
    {
      "x": 0,
      "y": 0,
      "z": 8,
      "name": "Soil_Ash"
    },
    {
      "x": 0,
      "y": 1,
      "z": 8,
      "name": "Soil_Sand_Ashen"
    },
    {
      "x": 0,
      "y": 2,
      "z": 8,
      "name": "Soil_Sand_Ashen"
    },
    {
      "x": 0,
      "y": 3,
      "z": 8,
      "name": "Soil_Mud"
    },
    {
      "x": 0,
      "y": 4,
      "z": 8,
      "name": "Soil_Mud"
    },
    {
      "x": 0,
      "y": 5,
      "z": 8,
      "name": "Plant_Moss_Rug_Red"
    },
    {
      "x": 0,
      "y": 0,
      "z": 9,
      "name": "Soil_Ash"
    },
    {
      "x": 0,
      "y": 1,
      "z": 9,
      "name": "Soil_Sand_Ashen"
    },
    {
      "x": 0,
      "y": 2,
      "z": 9,
      "name": "Soil_Sand_Ashen"
    },
    {
      "x": 0,
      "y": 3,
      "z": 9,
      "name": "Soil_Mud"
    },
    {
      "x": 0,
      "y": 0,
      "z": 10,
      "name": "Soil_Ash"
    },
    {
      "x": 0,
      "y": 1,
      "z": 10,
      "name": "Soil_Sand_Ashen"
    },
    {
      "x": 0,
      "y": 0,
      "z": 11,
      "name": "Soil_Ash"
    },
    {
      "x": 0,
      "y": 1,
      "z": 11,
      "name": "Soil_Sand_Ashen"
    },
    {
      "x": 1,
      "y": 0,
      "z": -8,
      "name": "Soil_Ash"
    },
    {
      "x": 1,
      "y": 1,
      "z": -8,
      "name": "Soil_Ash"
    },
    {
      "x": 1,
      "y": 0,
      "z": -7,
      "name": "Soil_Ash"
    },
    {
      "x": 1,
      "y": 1,
      "z": -7,
      "name": "Soil_Sand_Ashen"
    },
    {
      "x": 1,
      "y": 2,
      "z": -7,
      "name": "Soil_Ash"
    },
    {
      "x": 1,
      "y": 3,
      "z": -7,
      "name": "Plant_Bush_Dead_Hanging"
    },
    {
      "x": 1,
      "y": 4,
      "z": -7,
      "name": "Plant_Bush_Dead_Hanging"
    },
    {
      "x": 1,
      "y": 0,
      "z": -6,
      "name": "Soil_Ash"
    },
    {
      "x": 1,
      "y": 1,
      "z": -6,
      "name": "Soil_Sand_Ashen"
    },
    {
      "x": 1,
      "y": 2,
      "z": -6,
      "name": "Soil_Sand_Ashen"
    },
    {
      "x": 1,
      "y": 3,
      "z": -6,
      "name": "Soil_Ash"
    },
    {
      "x": 1,
      "y": 4,
      "z": -6,
      "name": "Plant_Bush_Dead_Hanging"
    },
    {
      "x": 1,
      "y": 0,
      "z": -5,
      "name": "Soil_Ash"
    },
    {
      "x": 1,
      "y": 1,
      "z": -5,
      "name": "Soil_Sand_Ashen"
    },
    {
      "x": 1,
      "y": 2,
      "z": -5,
      "name": "Soil_Sand_Ashen"
    },
    {
      "x": 1,
      "y": 3,
      "z": -5,
      "name": "Soil_Mud"
    },
    {
      "x": 1,
      "y": 4,
      "z": -5,
      "name": "Soil_Mud"
    },
    {
      "x": 1,
      "y": 0,
      "z": -4,
      "name": "Soil_Ash"
    },
    {
      "x": 1,
      "y": 1,
      "z": -4,
      "name": "Soil_Sand_Ashen"
    },
    {
      "x": 1,
      "y": 2,
      "z": -4,
      "name": "Soil_Sand_Ashen"
    },
    {
      "x": 1,
      "y": 3,
      "z": -4,
      "name": "Soil_Mud"
    },
    {
      "x": 1,
      "y": 4,
      "z": -4,
      "name": "Soil_Mud"
    },
    {
      "x": 1,
      "y": 0,
      "z": -3,
      "name": "Soil_Ash"
    },
    {
      "x": 1,
      "y": 1,
      "z": -3,
      "name": "Soil_Sand_Ashen"
    },
    {
      "x": 1,
      "y": 2,
      "z": -3,
      "name": "Soil_Sand_Ashen"
    },
    {
      "x": 1,
      "y": 3,
      "z": -3,
      "name": "Soil_Mud"
    },
    {
      "x": 1,
      "y": 4,
      "z": -3,
      "name": "Soil_Mud"
    },
    {
      "x": 1,
      "y": 0,
      "z": -2,
      "name": "Soil_Ash"
    },
    {
      "x": 1,
      "y": 1,
      "z": -2,
      "name": "Soil_Sand_Ashen"
    },
    {
      "x": 1,
      "y": 2,
      "z": -2,
      "name": "Soil_Sand_Ashen"
    },
    {
      "x": 1,
      "y": 3,
      "z": -2,
      "name": "Soil_Mud"
    },
    {
      "x": 1,
      "y": 4,
      "z": -2,
      "name": "Soil_Mud"
    },
    {
      "x": 1,
      "y": 0,
      "z": -1,
      "name": "Soil_Ash"
    },
    {
      "x": 1,
      "y": 1,
      "z": -1,
      "name": "Soil_Sand_Ashen"
    },
    {
      "x": 1,
      "y": 2,
      "z": -1,
      "name": "Soil_Sand_Ashen"
    },
    {
      "x": 1,
      "y": 3,
      "z": -1,
      "name": "Soil_Mud"
    },
    {
      "x": 1,
      "y": 4,
      "z": -1,
      "name": "Soil_Mud"
    },
    {
      "x": 1,
      "y": 5,
      "z": -1,
      "name": "Soil_Mud"
    },
    {
      "x": 1,
      "y": 0,
      "z": 0,
      "name": "Soil_Ash"
    },
    {
      "x": 1,
      "y": 1,
      "z": 0,
      "name": "Soil_Sand_Ashen"
    },
    {
      "x": 1,
      "y": 2,
      "z": 0,
      "name": "Soil_Sand_Ashen"
    },
    {
      "x": 1,
      "y": 3,
      "z": 0,
      "name": "Soil_Mud"
    },
    {
      "x": 1,
      "y": 4,
      "z": 0,
      "name": "Soil_Mud"
    },
    {
      "x": 1,
      "y": 5,
      "z": 0,
      "name": "Soil_Ash"
    },
    {
      "x": 1,
      "y": 0,
      "z": 1,
      "name": "Soil_Ash"
    },
    {
      "x": 1,
      "y": 1,
      "z": 1,
      "name": "Soil_Sand_Ashen"
    },
    {
      "x": 1,
      "y": 2,
      "z": 1,
      "name": "Soil_Sand_Ashen"
    },
    {
      "x": 1,
      "y": 3,
      "z": 1,
      "name": "Soil_Mud"
    },
    {
      "x": 1,
      "y": 4,
      "z": 1,
      "name": "Soil_Mud"
    },
    {
      "x": 1,
      "y": 5,
      "z": 1,
      "name": "Soil_Mud"
    },
    {
      "x": 1,
      "y": 0,
      "z": 2,
      "name": "Soil_Ash"
    },
    {
      "x": 1,
      "y": 1,
      "z": 2,
      "name": "Soil_Sand_Ashen"
    },
    {
      "x": 1,
      "y": 2,
      "z": 2,
      "name": "Soil_Sand_Ashen"
    },
    {
      "x": 1,
      "y": 3,
      "z": 2,
      "name": "Soil_Mud"
    },
    {
      "x": 1,
      "y": 4,
      "z": 2,
      "name": "Soil_Mud"
    },
    {
      "x": 1,
      "y": 5,
      "z": 2,
      "name": "Soil_Mud"
    },
    {
      "x": 1,
      "y": 0,
      "z": 3,
      "name": "Soil_Ash"
    },
    {
      "x": 1,
      "y": 1,
      "z": 3,
      "name": "Soil_Sand_Ashen"
    },
    {
      "x": 1,
      "y": 2,
      "z": 3,
      "name": "Soil_Sand_Ashen"
    },
    {
      "x": 1,
      "y": 3,
      "z": 3,
      "name": "Soil_Mud"
    },
    {
      "x": 1,
      "y": 4,
      "z": 3,
      "name": "Soil_Mud"
    },
    {
      "x": 1,
      "y": 5,
      "z": 3,
      "name": "Soil_Mud"
    },
    {
      "x": 1,
      "y": 0,
      "z": 4,
      "name": "Soil_Ash"
    },
    {
      "x": 1,
      "y": 1,
      "z": 4,
      "name": "Soil_Sand_Ashen"
    },
    {
      "x": 1,
      "y": 2,
      "z": 4,
      "name": "Soil_Sand_Ashen"
    },
    {
      "x": 1,
      "y": 3,
      "z": 4,
      "name": "Soil_Mud"
    },
    {
      "x": 1,
      "y": 4,
      "z": 4,
      "name": "Soil_Mud"
    },
    {
      "x": 1,
      "y": 5,
      "z": 4,
      "name": "Soil_Mud"
    },
    {
      "x": 1,
      "y": 0,
      "z": 5,
      "name": "Soil_Ash"
    },
    {
      "x": 1,
      "y": 1,
      "z": 5,
      "name": "Soil_Sand_Ashen"
    },
    {
      "x": 1,
      "y": 2,
      "z": 5,
      "name": "Soil_Sand_Ashen"
    },
    {
      "x": 1,
      "y": 3,
      "z": 5,
      "name": "Soil_Mud"
    },
    {
      "x": 1,
      "y": 4,
      "z": 5,
      "name": "Soil_Mud"
    },
    {
      "x": 1,
      "y": 5,
      "z": 5,
      "name": "Soil_Mud"
    },
    {
      "x": 1,
      "y": 0,
      "z": 6,
      "name": "Soil_Ash"
    },
    {
      "x": 1,
      "y": 1,
      "z": 6,
      "name": "Soil_Sand_Ashen"
    },
    {
      "x": 1,
      "y": 2,
      "z": 6,
      "name": "Soil_Sand_Ashen"
    },
    {
      "x": 1,
      "y": 3,
      "z": 6,
      "name": "Soil_Mud"
    },
    {
      "x": 1,
      "y": 4,
      "z": 6,
      "name": "Soil_Mud"
    },
    {
      "x": 1,
      "y": 5,
      "z": 6,
      "name": "Soil_Mud"
    },
    {
      "x": 1,
      "y": 0,
      "z": 7,
      "name": "Soil_Ash"
    },
    {
      "x": 1,
      "y": 1,
      "z": 7,
      "name": "Soil_Sand_Ashen"
    },
    {
      "x": 1,
      "y": 2,
      "z": 7,
      "name": "Soil_Sand_Ashen"
    },
    {
      "x": 1,
      "y": 3,
      "z": 7,
      "name": "Soil_Mud"
    },
    {
      "x": 1,
      "y": 4,
      "z": 7,
      "name": "Soil_Mud"
    },
    {
      "x": 1,
      "y": 5,
      "z": 7,
      "name": "Plant_Grass_Cave_Short"
    },
    {
      "x": 1,
      "y": 0,
      "z": 8,
      "name": "Soil_Ash"
    },
    {
      "x": 1,
      "y": 1,
      "z": 8,
      "name": "Soil_Sand_Ashen"
    },
    {
      "x": 1,
      "y": 2,
      "z": 8,
      "name": "Soil_Sand_Ashen"
    },
    {
      "x": 1,
      "y": 3,
      "z": 8,
      "name": "Soil_Mud"
    },
    {
      "x": 1,
      "y": 4,
      "z": 8,
      "name": "Soil_Mud"
    },
    {
      "x": 1,
      "y": 0,
      "z": 9,
      "name": "Soil_Ash"
    },
    {
      "x": 1,
      "y": 1,
      "z": 9,
      "name": "Soil_Sand_Ashen"
    },
    {
      "x": 1,
      "y": 2,
      "z": 9,
      "name": "Soil_Sand_Ashen"
    },
    {
      "x": 1,
      "y": 0,
      "z": 10,
      "name": "Soil_Ash"
    },
    {
      "x": 1,
      "y": 1,
      "z": 10,
      "name": "Soil_Sand_Ashen"
    },
    {
      "x": 1,
      "y": 0,
      "z": 11,
      "name": "Soil_Ash"
    },
    {
      "x": 2,
      "y": 0,
      "z": -8,
      "name": "Soil_Ash"
    },
    {
      "x": 2,
      "y": 0,
      "z": -7,
      "name": "Soil_Ash"
    },
    {
      "x": 2,
      "y": 1,
      "z": -7,
      "name": "Soil_Sand_Ashen"
    },
    {
      "x": 2,
      "y": 2,
      "z": -7,
      "name": "Soil_Sand_Ashen"
    },
    {
      "x": 2,
      "y": 3,
      "z": -7,
      "name": "Soil_Mud"
    },
    {
      "x": 2,
      "y": 0,
      "z": -6,
      "name": "Soil_Ash"
    },
    {
      "x": 2,
      "y": 1,
      "z": -6,
      "name": "Soil_Sand_Ashen"
    },
    {
      "x": 2,
      "y": 2,
      "z": -6,
      "name": "Soil_Sand_Ashen"
    },
    {
      "x": 2,
      "y": 3,
      "z": -6,
      "name": "Soil_Ash"
    },
    {
      "x": 2,
      "y": 4,
      "z": -6,
      "name": "Plant_Grass_Cave_Short"
    },
    {
      "x": 2,
      "y": 0,
      "z": -5,
      "name": "Soil_Ash"
    },
    {
      "x": 2,
      "y": 1,
      "z": -5,
      "name": "Soil_Sand_Ashen"
    },
    {
      "x": 2,
      "y": 2,
      "z": -5,
      "name": "Soil_Sand_Ashen"
    },
    {
      "x": 2,
      "y": 3,
      "z": -5,
      "name": "Soil_Mud"
    },
    {
      "x": 2,
      "y": 4,
      "z": -5,
      "name": "Soil_Ash"
    },
    {
      "x": 2,
      "y": 0,
      "z": -4,
      "name": "Soil_Ash"
    },
    {
      "x": 2,
      "y": 1,
      "z": -4,
      "name": "Soil_Sand_Ashen"
    },
    {
      "x": 2,
      "y": 2,
      "z": -4,
      "name": "Soil_Sand_Ashen"
    },
    {
      "x": 2,
      "y": 3,
      "z": -4,
      "name": "Soil_Mud"
    },
    {
      "x": 2,
      "y": 4,
      "z": -4,
      "name": "Soil_Ash"
    },
    {
      "x": 2,
      "y": 5,
      "z": -4,
      "name": "Plant_Grass_Cave_Short"
    },
    {
      "x": 2,
      "y": 0,
      "z": -3,
      "name": "Soil_Ash"
    },
    {
      "x": 2,
      "y": 1,
      "z": -3,
      "name": "Soil_Sand_Ashen"
    },
    {
      "x": 2,
      "y": 2,
      "z": -3,
      "name": "Soil_Sand_Ashen"
    },
    {
      "x": 2,
      "y": 3,
      "z": -3,
      "name": "Soil_Mud"
    },
    {
      "x": 2,
      "y": 4,
      "z": -3,
      "name": "Soil_Ash"
    },
    {
      "x": 2,
      "y": 0,
      "z": -2,
      "name": "Soil_Ash"
    },
    {
      "x": 2,
      "y": 1,
      "z": -2,
      "name": "Soil_Sand_Ashen"
    },
    {
      "x": 2,
      "y": 2,
      "z": -2,
      "name": "Soil_Sand_Ashen"
    },
    {
      "x": 2,
      "y": 3,
      "z": -2,
      "name": "Soil_Mud"
    },
    {
      "x": 2,
      "y": 4,
      "z": -2,
      "name": "Soil_Ash"
    },
    {
      "x": 2,
      "y": 0,
      "z": -1,
      "name": "Soil_Ash"
    },
    {
      "x": 2,
      "y": 1,
      "z": -1,
      "name": "Soil_Sand_Ashen"
    },
    {
      "x": 2,
      "y": 2,
      "z": -1,
      "name": "Soil_Sand_Ashen"
    },
    {
      "x": 2,
      "y": 3,
      "z": -1,
      "name": "Soil_Mud"
    },
    {
      "x": 2,
      "y": 4,
      "z": -1,
      "name": "Soil_Mud"
    },
    {
      "x": 2,
      "y": 5,
      "z": -1,
      "name": "Soil_Ash"
    },
    {
      "x": 2,
      "y": 0,
      "z": 0,
      "name": "Soil_Ash"
    },
    {
      "x": 2,
      "y": 1,
      "z": 0,
      "name": "Soil_Sand_Ashen"
    },
    {
      "x": 2,
      "y": 2,
      "z": 0,
      "name": "Soil_Sand_Ashen"
    },
    {
      "x": 2,
      "y": 3,
      "z": 0,
      "name": "Soil_Mud"
    },
    {
      "x": 2,
      "y": 4,
      "z": 0,
      "name": "Soil_Mud"
    },
    {
      "x": 2,
      "y": 5,
      "z": 0,
      "name": "Soil_Ash"
    },
    {
      "x": 2,
      "y": 0,
      "z": 1,
      "name": "Soil_Ash"
    },
    {
      "x": 2,
      "y": 1,
      "z": 1,
      "name": "Soil_Sand_Ashen"
    },
    {
      "x": 2,
      "y": 2,
      "z": 1,
      "name": "Soil_Sand_Ashen"
    },
    {
      "x": 2,
      "y": 3,
      "z": 1,
      "name": "Soil_Mud"
    },
    {
      "x": 2,
      "y": 4,
      "z": 1,
      "name": "Soil_Mud"
    },
    {
      "x": 2,
      "y": 5,
      "z": 1,
      "name": "Soil_Mud"
    },
    {
      "x": 2,
      "y": 0,
      "z": 2,
      "name": "Soil_Ash"
    },
    {
      "x": 2,
      "y": 1,
      "z": 2,
      "name": "Soil_Sand_Ashen"
    },
    {
      "x": 2,
      "y": 2,
      "z": 2,
      "name": "Soil_Sand_Ashen"
    },
    {
      "x": 2,
      "y": 3,
      "z": 2,
      "name": "Soil_Mud"
    },
    {
      "x": 2,
      "y": 4,
      "z": 2,
      "name": "Soil_Mud"
    },
    {
      "x": 2,
      "y": 5,
      "z": 2,
      "name": "Soil_Mud"
    },
    {
      "x": 2,
      "y": 0,
      "z": 3,
      "name": "Soil_Ash"
    },
    {
      "x": 2,
      "y": 1,
      "z": 3,
      "name": "Soil_Sand_Ashen"
    },
    {
      "x": 2,
      "y": 2,
      "z": 3,
      "name": "Soil_Sand_Ashen"
    },
    {
      "x": 2,
      "y": 3,
      "z": 3,
      "name": "Soil_Mud"
    },
    {
      "x": 2,
      "y": 4,
      "z": 3,
      "name": "Soil_Mud"
    },
    {
      "x": 2,
      "y": 5,
      "z": 3,
      "name": "Soil_Mud"
    },
    {
      "x": 2,
      "y": 0,
      "z": 4,
      "name": "Soil_Ash"
    },
    {
      "x": 2,
      "y": 1,
      "z": 4,
      "name": "Soil_Sand_Ashen"
    },
    {
      "x": 2,
      "y": 2,
      "z": 4,
      "name": "Soil_Sand_Ashen"
    },
    {
      "x": 2,
      "y": 3,
      "z": 4,
      "name": "Soil_Mud"
    },
    {
      "x": 2,
      "y": 4,
      "z": 4,
      "name": "Soil_Mud"
    },
    {
      "x": 2,
      "y": 5,
      "z": 4,
      "name": "Soil_Mud"
    },
    {
      "x": 2,
      "y": 0,
      "z": 5,
      "name": "Soil_Ash"
    },
    {
      "x": 2,
      "y": 1,
      "z": 5,
      "name": "Soil_Sand_Ashen"
    },
    {
      "x": 2,
      "y": 2,
      "z": 5,
      "name": "Soil_Sand_Ashen"
    },
    {
      "x": 2,
      "y": 3,
      "z": 5,
      "name": "Soil_Mud"
    },
    {
