{
  "version": 8,
  "blockIdVersion": 11,
  "anchorX": 0,
  "anchorY": 0,
  "anchorZ": 0,
  "blocks": [
    {
      "x": -52,
      "y": 28,
      "z": 10,
      "name": "Wood_Hardwood_Planks",
      "rotation": 50
    },
    {
      "x": -51,
      "y": 28,
      "z": 10,
      "name": "Wood_Hardwood_Planks",
      "rotation": 50
    },
    {
      "x": -50,
      "y": 28,
      "z": 10,
      "name": "Wood_Hardwood_Planks",
      "rotation": 50
    },
    {
      "x": -49,
      "y": 28,
      "z": 10,
      "name": "Wood_Hardwood_Planks",
      "rotation": 50
    },
    {
      "x": -48,
      "y": 27,
      "z": 10,
      "name": "Wood_Hardwood_Planks",
      "rotation": 50
    },
    {
      "x": -47,
      "y": 21,
      "z": 4,
      "name": "Cloth_Block_Wool_Gray_Light_Half",
      "rotation": 7
    },
    {
      "x": -47,
      "y": 22,
      "z": 4,
      "name": "Cloth_Block_Wool_Gray_Light_Half",
      "rotation": 7
    },
    {
      "x": -47,
      "y": 23,
      "z": 4,
      "name": "Cloth_Block_Wool_Gray_Light_Half",
      "rotation": 7
    },
    {
      "x": -47,
      "y": 24,
      "z": 4,
      "name": "Cloth_Block_Wool_Gray_Light_Half",
      "rotation": 7
    },
    {
      "x": -47,
      "y": 25,
      "z": 4,
      "name": "Cloth_Block_Wool_Gray_Light_Half",
      "rotation": 7
    },
    {
      "x": -47,
      "y": 22,
      "z": 5,
      "name": "*Cloth_Block_Wool_Gray_Light_Half_State_Definitions_Block",
      "rotation": 7
    },
    {
      "x": -47,
      "y": 23,
      "z": 5,
      "name": "*Cloth_Block_Wool_Gray_Light_Half_State_Definitions_Block",
      "rotation": 7
    },
    {
      "x": -47,
      "y": 24,
      "z": 5,
      "name": "*Cloth_Block_Wool_Gray_Light_Half_State_Definitions_Block",
      "rotation": 7
    },
    {
      "x": -47,
      "y": 25,
      "z": 5,
      "name": "*Cloth_Block_Wool_Gray_Light_Half_State_Definitions_Block",
      "rotation": 7
    },
    {
      "x": -47,
      "y": 19,
      "z": 6,
      "name": "Cloth_Block_Wool_Gray_Light_Half",
      "rotation": 7
    },
    {
      "x": -47,
      "y": 20,
      "z": 6,
      "name": "Cloth_Block_Wool_Gray_Light_Half",
      "rotation": 7
    },
    {
      "x": -47,
      "y": 21,
      "z": 6,
      "name": "Cloth_Block_Wool_Gray_Light_Half",
      "rotation": 7
    },
    {
      "x": -47,
      "y": 22,
      "z": 6,
      "name": "Cloth_Block_Wool_Gray_Light_Half",
      "rotation": 7
    },
    {
      "x": -47,
      "y": 23,
      "z": 6,
      "name": "Cloth_Block_Wool_Gray_Light_Half",
      "rotation": 7
    },
    {
      "x": -47,
      "y": 24,
      "z": 6,
      "name": "Cloth_Block_Wool_Gray_Light_Half",
      "rotation": 7
    },
    {
      "x": -47,
      "y": 25,
      "z": 6,
      "name": "Cloth_Block_Wool_Gray_Light_Half",
      "rotation": 7
    },
    {
      "x": -47,
      "y": 26,
      "z": 6,
      "name": "Cloth_Block_Wool_Gray_Light_Half",
      "rotation": 7
    },
    {
      "x": -47,
      "y": 23,
      "z": 7,
      "name": "Cloth_Block_Wool_Gray_Light_Half",
      "rotation": 7
    },
    {
      "x": -47,
      "y": 24,
      "z": 7,
      "name": "Cloth_Block_Wool_Gray_Light_Half",
      "rotation": 7
    },
    {
      "x": -47,
      "y": 25,
      "z": 7,
      "name": "Cloth_Block_Wool_Gray_Light_Half",
      "rotation": 7
    },
    {
      "x": -47,
      "y": 26,
      "z": 7,
      "name": "Cloth_Block_Wool_Gray_Light_Half",
      "rotation": 7
    },
    {
      "x": -47,
      "y": 21,
      "z": 8,
      "name": "*Cloth_Block_Wool_Gray_Light_Half_State_Definitions_Block",
      "rotation": 7
    },
    {
      "x": -47,
      "y": 22,
      "z": 8,
      "name": "*Cloth_Block_Wool_Gray_Light_Half_State_Definitions_Block",
      "rotation": 7
    },
    {
      "x": -47,
      "y": 23,
      "z": 8,
      "name": "*Cloth_Block_Wool_Gray_Light_Half_State_Definitions_Block",
      "rotation": 7
    },
    {
      "x": -47,
      "y": 24,
      "z": 8,
      "name": "*Cloth_Block_Wool_Gray_Light_Half_State_Definitions_Block",
      "rotation": 7
    },
    {
      "x": -47,
      "y": 25,
      "z": 8,
      "name": "*Cloth_Block_Wool_Gray_Light_Half_State_Definitions_Block",
      "rotation": 7
    },
    {
      "x": -47,
      "y": 26,
      "z": 8,
      "name": "*Cloth_Block_Wool_Gray_Light_Half_State_Definitions_Block",
      "rotation": 7
    },
    {
      "x": -47,
      "y": 20,
      "z": 9,
      "name": "Cloth_Block_Wool_Gray_Light_Half",
      "rotation": 7
    },
    {
      "x": -47,
      "y": 21,
      "z": 9,
      "name": "Cloth_Block_Wool_Gray_Light_Half",
      "rotation": 7
    },
    {
      "x": -47,
      "y": 22,
      "z": 9,
      "name": "Cloth_Block_Wool_Gray_Light_Half",
      "rotation": 7
    },
    {
      "x": -47,
      "y": 23,
      "z": 9,
      "name": "Cloth_Block_Wool_Gray_Light_Half",
      "rotation": 7
    },
    {
      "x": -47,
      "y": 24,
      "z": 9,
      "name": "Cloth_Block_Wool_Gray_Light_Half",
      "rotation": 7
    },
    {
      "x": -47,
      "y": 25,
      "z": 9,
      "name": "Cloth_Block_Wool_Gray_Light_Half",
      "rotation": 7
    },
    {
      "x": -47,
      "y": 26,
      "z": 9,
      "name": "Cloth_Block_Wool_Gray_Light_Half",
      "rotation": 7
    },
    {
      "x": -47,
      "y": 27,
      "z": 9,
      "name": "Cloth_Block_Wool_Gray_Light_Half",
      "rotation": 7
    },
    {
      "x": -47,
      "y": 27,
      "z": 10,
      "name": "Wood_Hardwood_Planks",
      "rotation": 50
    },
    {
      "x": -47,
      "y": 25,
      "z": 11,
      "name": "Cloth_Block_Wool_Gray_Light_Half",
      "rotation": 7
    },
    {
      "x": -47,
      "y": 26,
      "z": 11,
      "name": "Cloth_Block_Wool_Gray_Light_Half",
      "rotation": 7
    },
    {
      "x": -47,
      "y": 27,
      "z": 11,
      "name": "Cloth_Block_Wool_Gray_Light_Half",
      "rotation": 7
    },
    {
      "x": -47,
      "y": 26,
      "z": 12,
      "name": "Cloth_Block_Wool_Gray_Light_Half",
      "rotation": 7
    },
    {
      "x": -47,
      "y": 27,
      "z": 12,
      "name": "Cloth_Block_Wool_Gray_Light_Half",
      "rotation": 7
    },
    {
      "x": -47,
      "y": 28,
      "z": 12,
      "name": "Cloth_Block_Wool_Gray_Light_Half",
      "rotation": 7
    },
    {
      "x": -47,
      "y": 27,
      "z": 13,
      "name": "Cloth_Block_Wool_Gray_Light_Half",
      "rotation": 7
    },
    {
      "x": -47,
      "y": 28,
      "z": 13,
      "name": "Cloth_Block_Wool_Gray_Light_Half",
      "rotation": 7
    },
    {
      "x": -47,
      "y": 24,
      "z": 14,
      "name": "Cloth_Block_Wool_Gray_Light_Half",
      "rotation": 7
    },
    {
      "x": -47,
      "y": 25,
      "z": 14,
      "name": "Cloth_Block_Wool_Gray_Light_Half",
      "rotation": 7
    },
    {
      "x": -47,
      "y": 26,
      "z": 14,
      "name": "Cloth_Block_Wool_Gray_Light_Half",
      "rotation": 7
    },
    {
      "x": -47,
      "y": 27,
      "z": 14,
      "name": "Cloth_Block_Wool_Gray_Light_Half",
      "rotation": 7
    },
    {
      "x": -47,
      "y": 28,
      "z": 14,
      "name": "Cloth_Block_Wool_Gray_Light_Half",
      "rotation": 7
    },
    {
      "x": -47,
      "y": 25,
      "z": 15,
      "name": "*Cloth_Block_Wool_Gray_Light_Half_State_Definitions_Block",
      "rotation": 7
    },
    {
      "x": -47,
      "y": 26,
      "z": 15,
      "name": "*Cloth_Block_Wool_Gray_Light_Half_State_Definitions_Block",
      "rotation": 7
    },
    {
      "x": -47,
      "y": 27,
      "z": 15,
      "name": "*Cloth_Block_Wool_Gray_Light_Half_State_Definitions_Block",
      "rotation": 7
    },
    {
      "x": -47,
      "y": 28,
      "z": 15,
      "name": "*Cloth_Block_Wool_Gray_Light_Half_State_Definitions_Block",
      "rotation": 7
    },
    {
      "x": -47,
      "y": 29,
      "z": 15,
      "name": "*Cloth_Block_Wool_Gray_Light_Half_State_Definitions_Block",
      "rotation": 7
    },
    {
      "x": -47,
      "y": 22,
      "z": 16,
      "name": "Cloth_Block_Wool_Gray_Light_Half",
      "rotation": 7
    },
    {
      "x": -47,
      "y": 23,
      "z": 16,
      "name": "Cloth_Block_Wool_Gray_Light_Half",
      "rotation": 7
    },
    {
      "x": -47,
      "y": 24,
      "z": 16,
      "name": "Cloth_Block_Wool_Gray_Light_Half",
      "rotation": 7
    },
    {
      "x": -47,
      "y": 25,
      "z": 16,
      "name": "Cloth_Block_Wool_Gray_Light_Half",
      "rotation": 7
    },
    {
      "x": -47,
      "y": 26,
      "z": 16,
      "name": "Cloth_Block_Wool_Gray_Light_Half",
      "rotation": 7
    },
    {
      "x": -47,
      "y": 27,
      "z": 16,
      "name": "Cloth_Block_Wool_Gray_Light_Half",
      "rotation": 7
    },
    {
      "x": -47,
      "y": 28,
      "z": 16,
      "name": "Cloth_Block_Wool_Gray_Light_Half",
      "rotation": 7
    },
    {
      "x": -47,
      "y": 29,
      "z": 16,
      "name": "Cloth_Block_Wool_Gray_Light_Half",
      "rotation": 7
    },
    {
      "x": -46,
      "y": 25,
      "z": 4,
      "name": "Wood_Deadwood_Planks",
      "rotation": 16
    },
    {
      "x": -46,
      "y": 25,
      "z": 5,
      "name": "Wood_Deadwood_Planks",
      "rotation": 16
    },
    {
      "x": -46,
      "y": 26,
      "z": 6,
      "name": "Wood_Deadwood_Planks",
      "rotation": 16
    },
    {
      "x": -46,
      "y": 26,
      "z": 7,
      "name": "Wood_Deadwood_Planks",
      "rotation": 16
    },
    {
      "x": -46,
      "y": 26,
      "z": 8,
      "name": "Wood_Deadwood_Planks",
      "rotation": 16
    },
    {
      "x": -46,
      "y": 27,
      "z": 9,
      "name": "Wood_Deadwood_Planks",
      "rotation": 16
    },
    {
      "x": -46,
      "y": 27,
      "z": 10,
      "name": "Wood_Hardwood_Planks",
      "rotation": 50
    },
    {
      "x": -46,
      "y": 27,
      "z": 11,
      "name": "Wood_Deadwood_Planks",
      "rotation": 16
    },
    {
      "x": -46,
      "y": 28,
      "z": 12,
      "name": "Wood_Deadwood_Planks",
      "rotation": 16
    },
    {
      "x": -46,
      "y": 28,
      "z": 13,
      "name": "Wood_Deadwood_Planks",
      "rotation": 16
    },
    {
      "x": -46,
      "y": 28,
      "z": 14,
      "name": "Wood_Deadwood_Planks",
      "rotation": 16
    },
    {
      "x": -46,
      "y": 29,
      "z": 15,
      "name": "Wood_Deadwood_Planks",
      "rotation": 16
    },
    {
      "x": -46,
      "y": 29,
      "z": 16,
      "name": "Wood_Deadwood_Planks",
      "rotation": 16
    },
    {
      "x": -45,
      "y": 25,
      "z": 4,
      "name": "Wood_Hardwood_Planks",
      "rotation": 50
    },
    {
      "x": -45,
      "y": 25,
      "z": 5,
      "name": "Wood_Hardwood_Planks",
      "rotation": 50
    },
    {
      "x": -45,
      "y": 26,
      "z": 6,
      "name": "Wood_Hardwood_Planks",
      "rotation": 50
    },
    {
      "x": -45,
      "y": 26,
      "z": 7,
      "name": "Wood_Hardwood_Planks",
      "rotation": 50
    },
    {
      "x": -45,
      "y": 26,
      "z": 8,
      "name": "Wood_Hardwood_Planks",
      "rotation": 50
    },
    {
      "x": -45,
      "y": 27,
      "z": 9,
      "name": "Wood_Hardwood_Planks",
      "rotation": 50
    },
    {
      "x": -45,
      "y": 27,
      "z": 10,
      "name": "Wood_Hardwood_Planks",
      "rotation": 50
    },
    {
      "x": -45,
      "y": 27,
      "z": 11,
      "name": "Wood_Hardwood_Planks",
      "rotation": 50
    },
    {
      "x": -45,
      "y": 28,
      "z": 12,
      "name": "Wood_Hardwood_Planks",
      "rotation": 50
    },
    {
      "x": -45,
      "y": 28,
      "z": 13,
      "name": "Wood_Hardwood_Planks",
      "rotation": 50
    },
    {
      "x": -45,
      "y": 28,
      "z": 14,
      "name": "Wood_Hardwood_Planks",
      "rotation": 50
    },
    {
      "x": -45,
      "y": 29,
      "z": 15,
      "name": "Wood_Hardwood_Planks",
      "rotation": 50
    },
    {
      "x": -45,
      "y": 29,
      "z": 16,
      "name": "Wood_Hardwood_Planks",
      "rotation": 50
    },
    {
      "x": -44,
      "y": 27,
      "z": 10,
      "name": "Wood_Hardwood_Planks",
      "rotation": 50
    },
    {
      "x": -43,
      "y": 26,
      "z": 10,
      "name": "Wood_Hardwood_Planks",
      "rotation": 50
    },
    {
      "x": -43,
      "y": 27,
      "z": 10,
      "name": "Wood_Hardwood_Planks",
      "rotation": 50
    },
    {
      "x": -42,
      "y": 26,
      "z": 10,
      "name": "Wood_Hardwood_Planks",
      "rotation": 50
    },
    {
      "x": -41,
      "y": 26,
      "z": 10,
      "name": "Wood_Hardwood_Planks",
      "rotation": 50
    },
    {
      "x": -40,
      "y": 25,
      "z": 9,
      "name": "Wood_Hardwood_Planks",
      "rotation": 13
    },
    {
      "x": -40,
      "y": 26,
      "z": 9,
      "name": "Wood_Hardwood_Planks",
      "rotation": 7
    },
    {
      "x": -40,
      "y": 25,
      "z": 10,
      "name": "Wood_Hardwood_Planks",
      "rotation": 13
    },
    {
      "x": -40,
      "y": 26,
      "z": 10,
      "name": "Wood_Hardwood_Planks",
      "rotation": 50
    },
    {
      "x": -40,
      "y": 25,
      "z": 11,
      "name": "Wood_Hardwood_Planks",
      "rotation": 13
    },
    {
      "x": -40,
      "y": 26,
      "z": 11,
      "name": "Wood_Hardwood_Planks",
      "rotation": 7
    },
    {
      "x": -39,
      "y": 25,
      "z": 9,
      "name": "Wood_Hardwood_Planks",
      "rotation": 16
    },
    {
      "x": -39,
      "y": 26,
      "z": 9,
      "name": "Wood_Hardwood_Planks",
      "rotation": 16
    },
    {
      "x": -39,
      "y": 27,
      "z": 9,
      "name": "Wood_Hardwood_Planks",
      "rotation": 16
    },
    {
      "x": -39,
      "y": 25,
      "z": 10,
      "name": "Wood_Hardwood_Planks",
      "rotation": 16
    },
    {
      "x": -39,
      "y": 26,
      "z": 10,
      "name": "Wood_Hardwood_Planks",
      "rotation": 50
    },
    {
      "x": -39,
      "y": 27,
      "z": 10,
      "name": "Wood_Hardwood_Planks",
      "rotation": 16
    },
    {
      "x": -39,
      "y": 25,
      "z": 11,
      "name": "Wood_Hardwood_Planks",
      "rotation": 16
    },
    {
      "x": -39,
      "y": 26,
      "z": 11,
      "name": "Wood_Hardwood_Planks",
      "rotation": 16
    },
    {
      "x": -39,
      "y": 27,
      "z": 11,
      "name": "Wood_Hardwood_Planks",
      "rotation": 16
    },
    {
      "x": -38,
      "y": 31,
      "z": 4,
      "name": "Cloth_Block_Wool_Gray_Light_Half",
      "rotation": 7
    },
    {
      "x": -38,
      "y": 32,
      "z": 4,
      "name": "Cloth_Block_Wool_Gray_Light_Half",
      "rotation": 7
    },
    {
      "x": -38,
      "y": 33,
      "z": 4,
      "name": "Cloth_Block_Wool_Gray_Light_Half",
      "rotation": 7
    },
    {
      "x": -38,
      "y": 34,
      "z": 4,
      "name": "Cloth_Block_Wool_Gray_Light_Half",
      "rotation": 7
    },
    {
      "x": -38,
      "y": 35,
      "z": 4,
      "name": "Cloth_Block_Wool_Gray_Light_Half",
      "rotation": 7
    },
    {
      "x": -38,
      "y": 36,
      "z": 4,
      "name": "Cloth_Block_Wool_Gray_Light_Half",
      "rotation": 7
    },
    {
      "x": -38,
      "y": 37,
      "z": 4,
      "name": "Cloth_Block_Wool_Gray_Light_Half",
      "rotation": 7
    },
    {
      "x": -38,
      "y": 38,
      "z": 4,
      "name": "Cloth_Block_Wool_Gray_Light_Half",
      "rotation": 7
    },
    {
      "x": -38,
      "y": 33,
      "z": 5,
      "name": "Cloth_Block_Wool_Gray_Light_Half",
      "rotation": 7
    },
    {
      "x": -38,
      "y": 34,
      "z": 5,
      "name": "Cloth_Block_Wool_Gray_Light_Half",
      "rotation": 7
    },
    {
      "x": -38,
      "y": 35,
      "z": 5,
      "name": "Cloth_Block_Wool_Gray_Light_Half",
      "rotation": 7
    },
    {
      "x": -38,
      "y": 36,
      "z": 5,
      "name": "Cloth_Block_Wool_Gray_Light_Half",
      "rotation": 7
    },
    {
      "x": -38,
      "y": 37,
      "z": 5,
      "name": "Cloth_Block_Wool_Gray_Light_Half",
      "rotation": 7
    },
    {
      "x": -38,
      "y": 38,
      "z": 5,
      "name": "Cloth_Block_Wool_Gray_Light_Half",
      "rotation": 7
    },
    {
      "x": -38,
      "y": 32,
      "z": 6,
      "name": "Cloth_Block_Wool_Gray_Light_Half",
      "rotation": 7
    },
    {
      "x": -38,
      "y": 33,
      "z": 6,
      "name": "Cloth_Block_Wool_Gray_Light_Half",
      "rotation": 7
    },
    {
      "x": -38,
      "y": 34,
      "z": 6,
      "name": "Cloth_Block_Wool_Gray_Light_Half",
      "rotation": 7
    },
    {
      "x": -38,
      "y": 35,
      "z": 6,
      "name": "Cloth_Block_Wool_Gray_Light_Half",
      "rotation": 7
    },
    {
      "x": -38,
      "y": 36,
      "z": 6,
      "name": "Cloth_Block_Wool_Gray_Light_Half",
      "rotation": 7
    },
    {
      "x": -38,
      "y": 37,
      "z": 6,
      "name": "Cloth_Block_Wool_Gray_Light_Half",
      "rotation": 7
    },
    {
      "x": -38,
      "y": 38,
      "z": 6,
      "name": "Cloth_Block_Wool_Gray_Light_Half",
      "rotation": 7
    },
    {
      "x": -38,
      "y": 39,
      "z": 6,
      "name": "Cloth_Block_Wool_Gray_Light_Half",
      "rotation": 7
    },
    {
      "x": -38,
      "y": 33,
      "z": 7,
      "name": "*Cloth_Block_Wool_Gray_Light_Half_State_Definitions_Block",
      "rotation": 7
    },
    {
      "x": -38,
      "y": 34,
      "z": 7,
      "name": "*Cloth_Block_Wool_Gray_Light_Half_State_Definitions_Block",
      "rotation": 7
    },
    {
      "x": -38,
      "y": 35,
      "z": 7,
      "name": "*Cloth_Block_Wool_Gray_Light_Half_State_Definitions_Block",
      "rotation": 7
    },
    {
      "x": -38,
      "y": 36,
      "z": 7,
      "name": "*Cloth_Block_Wool_Gray_Light_Half_State_Definitions_Block",
      "rotation": 7
    },
    {
      "x": -38,
      "y": 37,
      "z": 7,
      "name": "*Cloth_Block_Wool_Gray_Light_Half_State_Definitions_Block",
      "rotation": 7
    },
    {
      "x": -38,
      "y": 38,
      "z": 7,
      "name": "*Cloth_Block_Wool_Gray_Light_Half_State_Definitions_Block",
      "rotation": 7
    },
    {
      "x": -38,
      "y": 39,
      "z": 7,
      "name": "*Cloth_Block_Wool_Gray_Light_Half_State_Definitions_Block",
      "rotation": 7
    },
    {
      "x": -38,
      "y": 36,
      "z": 8,
      "name": "Cloth_Block_Wool_Gray_Light_Half",
      "rotation": 7
    },
    {
      "x": -38,
      "y": 37,
      "z": 8,
      "name": "Cloth_Block_Wool_Gray_Light_Half",
      "rotation": 7
    },
    {
      "x": -38,
      "y": 38,
      "z": 8,
      "name": "Cloth_Block_Wool_Gray_Light_Half",
      "rotation": 7
    },
    {
      "x": -38,
      "y": 39,
      "z": 8,
      "name": "Cloth_Block_Wool_Gray_Light_Half",
      "rotation": 7
    },
    {
      "x": -38,
      "y": 33,
      "z": 9,
      "name": "Cloth_Block_Wool_Gray_Light_Half",
      "rotation": 7
    },
    {
      "x": -38,
      "y": 34,
      "z": 9,
      "name": "Cloth_Block_Wool_Gray_Light_Half",
      "rotation": 7
    },
    {
      "x": -38,
      "y": 35,
      "z": 9,
      "name": "Cloth_Block_Wool_Gray_Light_Half",
      "rotation": 7
    },
    {
      "x": -38,
      "y": 36,
      "z": 9,
      "name": "Cloth_Block_Wool_Gray_Light_Half",
      "rotation": 7
    },
    {
      "x": -38,
      "y": 37,
      "z": 9,
      "name": "Cloth_Block_Wool_Gray_Light_Half",
      "rotation": 7
    },
    {
      "x": -38,
      "y": 38,
      "z": 9,
      "name": "Cloth_Block_Wool_Gray_Light_Half",
      "rotation": 7
    },
    {
      "x": -38,
      "y": 39,
      "z": 9,
      "name": "Cloth_Block_Wool_Gray_Light_Half",
      "rotation": 7
    },
    {
      "x": -38,
      "y": 40,
      "z": 9,
      "name": "Cloth_Block_Wool_Gray_Light_Half",
      "rotation": 7
    },
    {
      "x": -38,
      "y": 25,
      "z": 10,
      "name": "Wood_Hardwood_Planks",
      "rotation": 50
    },
    {
      "x": -38,
      "y": 26,
      "z": 10,
      "name": "Wood_Hardwood_Planks",
      "rotation": 50
    },
    {
      "x": -38,
      "y": 40,
      "z": 10,
      "name": "Wood_Hardwood_Planks",
      "rotation": 50
    },
    {
      "x": -38,
      "y": 33,
      "z": 11,
      "name": "Cloth_Block_Wool_Gray_Light_Half",
      "rotation": 7
    },
    {
      "x": -38,
      "y": 34,
      "z": 11,
      "name": "Cloth_Block_Wool_Gray_Light_Half",
      "rotation": 7
    },
    {
      "x": -38,
      "y": 35,
      "z": 11,
      "name": "Cloth_Block_Wool_Gray_Light_Half",
      "rotation": 7
    },
    {
      "x": -38,
      "y": 36,
      "z": 11,
      "name": "Cloth_Block_Wool_Gray_Light_Half",
      "rotation": 7
    },
    {
      "x": -38,
      "y": 37,
      "z": 11,
      "name": "Cloth_Block_Wool_Gray_Light_Half",
      "rotation": 7
    },
    {
      "x": -38,
      "y": 38,
      "z": 11,
      "name": "Cloth_Block_Wool_Gray_Light_Half",
      "rotation": 7
    },
    {
      "x": -38,
      "y": 39,
      "z": 11,
      "name": "Cloth_Block_Wool_Gray_Light_Half",
      "rotation": 7
    },
    {
      "x": -38,
      "y": 40,
      "z": 11,
      "name": "Cloth_Block_Wool_Gray_Light_Half",
      "rotation": 7
    },
    {
      "x": -37,
      "y": 38,
      "z": 4,
      "name": "Wood_Deadwood_Planks",
      "rotation": 16
    },
    {
      "x": -37,
      "y": 38,
      "z": 5,
      "name": "Wood_Deadwood_Planks",
      "rotation": 16
    },
    {
      "x": -37,
      "y": 39,
      "z": 6,
      "name": "Wood_Deadwood_Planks",
      "rotation": 16
    },
    {
      "x": -37,
      "y": 39,
      "z": 7,
      "name": "Wood_Deadwood_Planks",
      "rotation": 16
    },
    {
      "x": -37,
      "y": 39,
      "z": 8,
      "name": "Wood_Deadwood_Planks",
      "rotation": 16
    },
    {
      "x": -37,
      "y": 40,
      "z": 9,
      "name": "Wood_Deadwood_Planks",
      "rotation": 16
    },
    {
      "x": -37,
      "y": 24,
      "z": 10,
      "name": "Wood_Hardwood_Planks",
      "rotation": 50
    },
    {
      "x": -37,
      "y": 25,
      "z": 10,
      "name": "Wood_Hardwood_Planks",
      "rotation": 50
    },
    {
      "x": -37,
      "y": 32,
      "z": 10,
      "name": "*Cloth_Block_Wool_Gray_Light_Half_State_Definitions_Block",
      "rotation": 7
    },
    {
      "x": -37,
      "y": 33,
      "z": 10,
      "name": "*Cloth_Block_Wool_Gray_Light_Half_State_Definitions_Block",
      "rotation": 7
    },
    {
      "x": -37,
      "y": 34,
      "z": 10,
      "name": "*Cloth_Block_Wool_Gray_Light_Half_State_Definitions_Block",
      "rotation": 7
    },
    {
      "x": -37,
      "y": 35,
      "z": 10,
      "name": "*Cloth_Block_Wool_Gray_Light_Half_State_Definitions_Block",
      "rotation": 7
    },
    {
      "x": -37,
      "y": 36,
      "z": 10,
      "name": "*Cloth_Block_Wool_Gray_Light_Half_State_Definitions_Block",
      "rotation": 7
    },
    {
      "x": -37,
      "y": 37,
      "z": 10,
      "name": "*Cloth_Block_Wool_Gray_Light_Half_State_Definitions_Block",
      "rotation": 7
    },
    {
      "x": -37,
      "y": 38,
      "z": 10,
      "name": "*Cloth_Block_Wool_Gray_Light_Half_State_Definitions_Block",
      "rotation": 7
    },
    {
      "x": -37,
      "y": 39,
      "z": 10,
      "name": "*Cloth_Block_Wool_Gray_Light_Half_State_Definitions_Block",
      "rotation": 7
    },
    {
      "x": -37,
      "y": 40,
      "z": 10,
      "name": "Wood_Hardwood_Planks",
      "rotation": 50
    },
    {
      "x": -37,
      "y": 40,
      "z": 11,
      "name": "Wood_Deadwood_Planks",
      "rotation": 16
    },
    {
      "x": -37,
      "y": 34,
      "z": 12,
      "name": "*Cloth_Block_Wool_Gray_Light_Half_State_Definitions_Block",
      "rotation": 7
    },
    {
      "x": -37,
      "y": 35,
      "z": 12,
      "name": "*Cloth_Block_Wool_Gray_Light_Half_State_Definitions_Block",
      "rotation": 7
    },
    {
      "x": -37,
      "y": 36,
      "z": 12,
      "name": "*Cloth_Block_Wool_Gray_Light_Half_State_Definitions_Block",
      "rotation": 7
    },
    {
      "x": -37,
      "y": 37,
      "z": 12,
      "name": "*Cloth_Block_Wool_Gray_Light_Half_State_Definitions_Block",
      "rotation": 7
    },
    {
      "x": -37,
      "y": 38,
      "z": 12,
      "name": "*Cloth_Block_Wool_Gray_Light_Half_State_Definitions_Block",
      "rotation": 7
    },
    {
      "x": -37,
      "y": 39,
      "z": 12,
      "name": "*Cloth_Block_Wool_Gray_Light_Half_State_Definitions_Block",
      "rotation": 7
    },
    {
      "x": -37,
      "y": 40,
      "z": 12,
      "name": "*Cloth_Block_Wool_Gray_Light_Half_State_Definitions_Block",
      "rotation": 7
    },
    {
      "x": -37,
      "y": 41,
      "z": 12,
      "name": "Cloth_Block_Wool_Gray_Light_Half",
      "rotation": 7
    },
    {
      "x": -37,
      "y": 34,
      "z": 13,
      "name": "Cloth_Block_Wool_Gray_Light_Half",
      "rotation": 7
    },
    {
      "x": -37,
      "y": 35,
      "z": 13,
      "name": "Cloth_Block_Wool_Gray_Light_Half",
      "rotation": 7
    },
    {
      "x": -37,
      "y": 36,
      "z": 13,
      "name": "Cloth_Block_Wool_Gray_Light_Half",
      "rotation": 7
    },
    {
      "x": -37,
      "y": 37,
      "z": 13,
      "name": "Cloth_Block_Wool_Gray_Light_Half",
      "rotation": 7
    },
    {
      "x": -37,
      "y": 38,
      "z": 13,
      "name": "Cloth_Block_Wool_Gray_Light_Half",
      "rotation": 7
    },
    {
      "x": -37,
      "y": 39,
      "z": 13,
      "name": "Cloth_Block_Wool_Gray_Light_Half",
      "rotation": 7
    },
    {
      "x": -37,
      "y": 40,
      "z": 13,
      "name": "Cloth_Block_Wool_Gray_Light_Half",
      "rotation": 7
    },
    {
      "x": -37,
      "y": 41,
      "z": 13,
      "name": "Cloth_Block_Wool_Gray_Light_Half",
      "rotation": 7
    },
    {
      "x": -37,
      "y": 36,
      "z": 14,
      "name": "Cloth_Block_Wool_Gray_Light_Half",
      "rotation": 7
    },
    {
      "x": -37,
      "y": 37,
      "z": 14,
      "name": "Cloth_Block_Wool_Gray_Light_Half",
      "rotation": 7
    },
    {
      "x": -37,
      "y": 38,
      "z": 14,
      "name": "Cloth_Block_Wool_Gray_Light_Half",
      "rotation": 7
    },
    {
      "x": -37,
      "y": 39,
      "z": 14,
      "name": "Cloth_Block_Wool_Gray_Light_Half",
      "rotation": 7
    },
    {
      "x": -37,
      "y": 40,
      "z": 14,
      "name": "Cloth_Block_Wool_Gray_Light_Half",
      "rotation": 7
    },
    {
      "x": -37,
      "y": 41,
      "z": 14,
      "name": "Cloth_Block_Wool_Gray_Light_Half",
      "rotation": 7
    },
    {
      "x": -37,
      "y": 39,
      "z": 15,
      "name": "Cloth_Block_Wool_Gray_Light_Half",
      "rotation": 7
    },
    {
      "x": -37,
      "y": 40,
      "z": 15,
      "name": "Cloth_Block_Wool_Gray_Light_Half",
      "rotation": 7
    },
    {
      "x": -37,
      "y": 41,
      "z": 15,
      "name": "Cloth_Block_Wool_Gray_Light_Half",
      "rotation": 7
    },
    {
      "x": -37,
      "y": 42,
      "z": 15,
      "name": "Cloth_Block_Wool_Gray_Light_Half",
      "rotation": 7
    },
    {
      "x": -37,
      "y": 35,
      "z": 16,
      "name": "Cloth_Block_Wool_Gray_Light_Half",
      "rotation": 7
    },
    {
      "x": -37,
      "y": 36,
      "z": 16,
      "name": "Cloth_Block_Wool_Gray_Light_Half",
      "rotation": 7
    },
    {
      "x": -37,
      "y": 37,
      "z": 16,
      "name": "Cloth_Block_Wool_Gray_Light_Half",
      "rotation": 7
    },
    {
      "x": -37,
      "y": 38,
      "z": 16,
      "name": "Cloth_Block_Wool_Gray_Light_Half",
      "rotation": 7
    },
    {
      "x": -37,
      "y": 39,
      "z": 16,
      "name": "Cloth_Block_Wool_Gray_Light_Half",
      "rotation": 7
    },
    {
      "x": -37,
      "y": 40,
      "z": 16,
      "name": "Cloth_Block_Wool_Gray_Light_Half",
      "rotation": 7
    },
    {
      "x": -37,
      "y": 41,
      "z": 16,
      "name": "Cloth_Block_Wool_Gray_Light_Half",
      "rotation": 7
    },
    {
      "x": -37,
      "y": 42,
      "z": 16,
      "name": "Cloth_Block_Wool_Gray_Light_Half",
      "rotation": 7
    },
    {
      "x": -36,
      "y": 37,
      "z": 4,
      "name": "Wood_Hardwood_Planks",
      "rotation": 50
    },
    {
      "x": -36,
      "y": 37,
      "z": 5,
      "name": "Wood_Hardwood_Planks",
      "rotation": 50
    },
    {
      "x": -36,
      "y": 38,
      "z": 6,
      "name": "Wood_Hardwood_Planks",
      "rotation": 50
    },
    {
      "x": -36,
      "y": 38,
      "z": 7,
      "name": "Wood_Hardwood_Planks",
      "rotation": 50
    },
    {
      "x": -36,
      "y": 38,
      "z": 8,
      "name": "Wood_Hardwood_Planks",
      "rotation": 50
    },
    {
      "x": -36,
      "y": 39,
      "z": 9,
      "name": "Wood_Hardwood_Planks",
      "rotation": 50
    },
    {
      "x": -36,
      "y": 24,
      "z": 10,
      "name": "Wood_Hardwood_Planks",
      "rotation": 50
    },
    {
      "x": -36,
      "y": 39,
      "z": 10,
      "name": "Wood_Hardwood_Planks",
      "rotation": 50
    },
    {
      "x": -36,
      "y": 39,
      "z": 11,
      "name": "Wood_Hardwood_Planks",
      "rotation": 50
    },
    {
      "x": -36,
      "y": 40,
      "z": 12,
      "name": "Wood_Hardwood_Planks",
      "rotation": 50
    },
    {
      "x": -36,
      "y": 41,
      "z": 12,
      "name": "Wood_Deadwood_Planks",
      "rotation": 16
    },
    {
      "x": -36,
      "y": 40,
      "z": 13,
      "name": "Wood_Hardwood_Planks",
      "rotation": 50
    },
    {
      "x": -36,
      "y": 41,
      "z": 13,
      "name": "Wood_Deadwood_Planks",
      "rotation": 16
    },
    {
      "x": -36,
      "y": 40,
      "z": 14,
      "name": "Wood_Hardwood_Planks",
      "rotation": 50
    },
    {
      "x": -36,
      "y": 41,
      "z": 14,
      "name": "Wood_Deadwood_Planks",
      "rotation": 16
    },
    {
      "x": -36,
      "y": 42,
      "z": 15,
      "name": "Wood_Deadwood_Planks",
      "rotation": 16
    },
    {
      "x": -36,
      "y": 42,
      "z": 16,
      "name": "Wood_Deadwood_Planks",
      "rotation": 16
    },
    {
      "x": -35,
      "y": 16,
      "z": 1,
      "name": "Cloth_Block_Wool_Gray_Light_Half",
      "rotation": 7
    },
    {
      "x": -35,
      "y": 17,
      "z": 1,
      "name": "Cloth_Block_Wool_Gray_Light_Half",
      "rotation": 7
    },
    {
      "x": -35,
      "y": 18,
      "z": 1,
      "name": "Cloth_Block_Wool_Gray_Light_Half",
      "rotation": 7
    },
    {
      "x": -35,
      "y": 19,
      "z": 1,
      "name": "Cloth_Block_Wool_Gray_Light_Half",
      "rotation": 7
    },
    {
      "x": -35,
      "y": 20,
      "z": 1,
      "name": "Cloth_Block_Wool_Gray_Light_Half",
      "rotation": 7
    },
    {
      "x": -35,
      "y": 21,
      "z": 1,
      "name": "Cloth_Block_Wool_Gray_Light_Half",
      "rotation": 7
    },
    {
      "x": -35,
      "y": 18,
      "z": 2,
      "name": "Cloth_Block_Wool_Gray_Light_Half",
      "rotation": 7
    },
    {
      "x": -35,
      "y": 19,
      "z": 2,
      "name": "Cloth_Block_Wool_Gray_Light_Half",
      "rotation": 7
    },
    {
      "x": -35,
      "y": 20,
      "z": 2,
      "name": "Cloth_Block_Wool_Gray_Light_Half",
      "rotation": 7
    },
    {
      "x": -35,
      "y": 21,
      "z": 2,
      "name": "Cloth_Block_Wool_Gray_Light_Half",
      "rotation": 7
    },
    {
      "x": -35,
      "y": 17,
      "z": 3,
      "name": "Cloth_Block_Wool_Gray_Light_Half",
      "rotation": 7
    },
    {
      "x": -35,
      "y": 18,
      "z": 3,
      "name": "Cloth_Block_Wool_Gray_Light_Half",
      "rotation": 7
    },
    {
      "x": -35,
      "y": 19,
      "z": 3,
      "name": "Cloth_Block_Wool_Gray_Light_Half",
      "rotation": 7
    },
    {
      "x": -35,
      "y": 20,
      "z": 3,
      "name": "Cloth_Block_Wool_Gray_Light_Half",
      "rotation": 7
    },
    {
      "x": -35,
      "y": 21,
      "z": 3,
      "name": "Cloth_Block_Wool_Gray_Light_Half",
      "rotation": 7
    },
    {
      "x": -35,
      "y": 22,
      "z": 3,
      "name": "Cloth_Block_Wool_Gray_Light_Half",
      "rotation": 7
    },
    {
      "x": -35,
      "y": 15,
      "z": 4,
      "name": "Cloth_Block_Wool_Gray_Light_Half",
      "rotation": 7
    },
    {
      "x": -35,
      "y": 16,
      "z": 4,
      "name": "Cloth_Block_Wool_Gray_Light_Half",
      "rotation": 7
    },
    {
      "x": -35,
      "y": 17,
      "z": 4,
      "name": "Cloth_Block_Wool_Gray_Light_Half",
      "rotation": 7
    },
    {
      "x": -35,
      "y": 18,
      "z": 4,
      "name": "Cloth_Block_Wool_Gray_Light_Half",
      "rotation": 7
    },
    {
      "x": -35,
      "y": 19,
      "z": 4,
      "name": "Cloth_Block_Wool_Gray_Light_Half",
      "rotation": 7
    },
    {
      "x": -35,
      "y": 20,
      "z": 4,
      "name": "Cloth_Block_Wool_Gray_Light_Half",
      "rotation": 7
    },
    {
      "x": -35,
      "y": 21,
      "z": 4,
      "name": "Cloth_Block_Wool_Gray_Light_Half",
      "rotation": 7
    },
    {
      "x": -35,
      "y": 22,
      "z": 4,
      "name": "Cloth_Block_Wool_Gray_Light_Half",
      "rotation": 7
    },
    {
      "x": -35,
      "y": 16,
      "z": 5,
      "name": "Cloth_Block_Wool_Gray_Light_Half",
      "rotation": 7
    },
    {
      "x": -35,
      "y": 17,
      "z": 5,
      "name": "Cloth_Block_Wool_Gray_Light_Half",
      "rotation": 7
    },
    {
      "x": -35,
      "y": 18,
      "z": 5,
      "name": "Cloth_Block_Wool_Gray_Light_Half",
      "rotation": 7
    },
    {
      "x": -35,
      "y": 19,
      "z": 5,
      "name": "Cloth_Block_Wool_Gray_Light_Half",
      "rotation": 7
    },
    {
      "x": -35,
      "y": 20,
      "z": 5,
      "name": "Cloth_Block_Wool_Gray_Light_Half",
      "rotation": 7
    },
    {
      "x": -35,
      "y": 21,
      "z": 5,
      "name": "Cloth_Block_Wool_Gray_Light_Half",
      "rotation": 7
    },
    {
      "x": -35,
      "y": 22,
      "z": 5,
      "name": "Cloth_Block_Wool_Gray_Light_Half",
      "rotation": 7
    },
    {
      "x": -35,
      "y": 24,
      "z": 10,
      "name": "Wood_Hardwood_Planks",
      "rotation": 50
    },
    {
      "x": -35,
      "y": 39,
      "z": 10,
      "name": "Wood_Hardwood_Planks",
      "rotation": 50
    },
    {
      "x": -35,
      "y": 40,
      "z": 12,
      "name": "Wood_Hardwood_Planks",
      "rotation": 50
    },
    {
      "x": -35,
      "y": 40,
      "z": 13,
      "name": "Wood_Hardwood_Planks",
      "rotation": 50
    },
    {
      "x": -35,
      "y": 40,
      "z": 14,
      "name": "Wood_Hardwood_Planks",
      "rotation": 50
    },
    {
      "x": -35,
      "y": 41,
      "z": 15,
      "name": "Wood_Hardwood_Planks",
      "rotation": 50
    },
    {
      "x": -35,
      "y": 41,
      "z": 16,
      "name": "Wood_Hardwood_Planks",
      "rotation": 50
    },
    {
      "x": -34,
      "y": 21,
      "z": 1,
      "name": "Wood_Deadwood_Planks",
      "rotation": 16
    },
    {
      "x": -34,
      "y": 21,
      "z": 2,
      "name": "Wood_Deadwood_Planks",
      "rotation": 16
    },
    {
      "x": -34,
      "y": 22,
      "z": 3,
      "name": "Wood_Deadwood_Planks",
      "rotation": 16
    },
    {
      "x": -34,
      "y": 22,
      "z": 4,
      "name": "Wood_Deadwood_Planks",
      "rotation": 16
    },
    {
      "x": -34,
      "y": 22,
      "z": 5,
      "name": "Wood_Deadwood_Planks",
      "rotation": 16
    },
    {
      "x": -34,
      "y": 16,
      "z": 6,
      "name": "*Cloth_Block_Wool_Gray_Light_Half_State_Definitions_Block",
      "rotation": 7
    },
    {
      "x": -34,
      "y": 17,
      "z": 6,
      "name": "*Cloth_Block_Wool_Gray_Light_Half_State_Definitions_Block",
      "rotation": 7
    },
    {
      "x": -34,
      "y": 18,
      "z": 6,
      "name": "*Cloth_Block_Wool_Gray_Light_Half_State_Definitions_Block",
      "rotation": 7
    },
    {
      "x": -34,
      "y": 19,
      "z": 6,
      "name": "*Cloth_Block_Wool_Gray_Light_Half_State_Definitions_Block",
      "rotation": 7
    },
    {
      "x": -34,
      "y": 20,
      "z": 6,
      "name": "*Cloth_Block_Wool_Gray_Light_Half_State_Definitions_Block",
      "rotation": 7
    },
    {
      "x": -34,
      "y": 21,
      "z": 6,
      "name": "*Cloth_Block_Wool_Gray_Light_Half_State_Definitions_Block",
      "rotation": 7
    },
    {
      "x": -34,
      "y": 22,
      "z": 6,
      "name": "*Cloth_Block_Wool_Gray_Light_Half_State_Definitions_Block",
      "rotation": 7
    },
    {
      "x": -34,
      "y": 23,
      "z": 6,
      "name": "Cloth_Block_Wool_Gray_Light_Half",
      "rotation": 7
    },
    {
      "x": -34,
      "y": 20,
      "z": 7,
      "name": "Cloth_Block_Wool_Gray_Light_Half",
      "rotation": 7
    },
    {
      "x": -34,
      "y": 21,
      "z": 7,
      "name": "Cloth_Block_Wool_Gray_Light_Half",
      "rotation": 7
    },
    {
      "x": -34,
      "y": 22,
      "z": 7,
      "name": "Cloth_Block_Wool_Gray_Light_Half",
      "rotation": 7
    },
    {
      "x": -34,
      "y": 23,
      "z": 7,
      "name": "Cloth_Block_Wool_Gray_Light_Half",
      "rotation": 7
    },
    {
      "x": -34,
      "y": 18,
      "z": 8,
      "name": "Cloth_Block_Wool_Gray_Light_Half",
      "rotation": 7
    },
    {
      "x": -34,
      "y": 19,
      "z": 8,
      "name": "Cloth_Block_Wool_Gray_Light_Half",
      "rotation": 7
    },
    {
      "x": -34,
      "y": 20,
      "z": 8,
      "name": "Cloth_Block_Wool_Gray_Light_Half",
      "rotation": 7
    },
    {
      "x": -34,
      "y": 21,
      "z": 8,
      "name": "Cloth_Block_Wool_Gray_Light_Half",
      "rotation": 7
    },
    {
      "x": -34,
      "y": 22,
      "z": 8,
      "name": "Cloth_Block_Wool_Gray_Light_Half",
      "rotation": 7
    },
    {
      "x": -34,
      "y": 23,
      "z": 8,
      "name": "Cloth_Block_Wool_Gray_Light_Half",
      "rotation": 7
    },
    {
      "x": -34,
      "y": 17,
      "z": 9,
      "name": "Cloth_Block_Wool_Gray_Light_Half",
      "rotation": 7
    },
    {
      "x": -34,
      "y": 18,
      "z": 9,
      "name": "Cloth_Block_Wool_Gray_Light_Half",
      "rotation": 7
    },
    {
      "x": -34,
      "y": 19,
      "z": 9,
      "name": "Cloth_Block_Wool_Gray_Light_Half",
      "rotation": 7
    },
    {
      "x": -34,
      "y": 20,
      "z": 9,
      "name": "Cloth_Block_Wool_Gray_Light_Half",
      "rotation": 7
    },
    {
      "x": -34,
      "y": 21,
      "z": 9,
      "name": "Cloth_Block_Wool_Gray_Light_Half",
      "rotation": 7
    },
    {
      "x": -34,
      "y": 22,
      "z": 9,
      "name": "Cloth_Block_Wool_Gray_Light_Half",
      "rotation": 7
    },
    {
      "x": -34,
      "y": 23,
      "z": 9,
      "name": "Cloth_Block_Wool_Gray_Light_Half",
      "rotation": 7
    },
    {
      "x": -34,
      "y": 24,
      "z": 9,
      "name": "Cloth_Block_Wool_Gray_Light_Half",
      "rotation": 7
    },
    {
      "x": -34,
      "y": 24,
      "z": 10,
      "name": "Wood_Hardwood_Planks",
      "rotation": 50
    },
    {
      "x": -34,
      "y": 39,
      "z": 10,
      "name": "Wood_Hardwood_Planks",
      "rotation": 50
    },
    {
      "x": -34,
      "y": 17,
      "z": 11,
      "name": "Cloth_Block_Wool_Gray_Light_Half",
      "rotation": 7
    },
    {
      "x": -34,
      "y": 18,
      "z": 11,
      "name": "Cloth_Block_Wool_Gray_Light_Half",
      "rotation": 7
    },
    {
      "x": -34,
      "y": 19,
      "z": 11,
      "name": "Cloth_Block_Wool_Gray_Light_Half",
      "rotation": 7
    },
    {
      "x": -34,
      "y": 20,
      "z": 11,
      "name": "Cloth_Block_Wool_Gray_Light_Half",
      "rotation": 7
    },
    {
      "x": -34,
      "y": 21,
      "z": 11,
      "name": "Cloth_Block_Wool_Gray_Light_Half",
      "rotation": 7
    },
    {
      "x": -34,
      "y": 22,
      "z": 11,
      "name": "Cloth_Block_Wool_Gray_Light_Half",
      "rotation": 7
    },
    {
      "x": -34,
      "y": 23,
      "z": 11,
      "name": "Cloth_Block_Wool_Gray_Light_Half",
      "rotation": 7
    },
    {
      "x": -34,
      "y": 24,
      "z": 11,
      "name": "Cloth_Block_Wool_Gray_Light_Half",
      "rotation": 7
    },
    {
      "x": -34,
      "y": 19,
      "z": 12,
      "name": "Cloth_Block_Wool_Gray_Light_Half",
      "rotation": 7
    },
    {
      "x": -34,
      "y": 20,
      "z": 12,
      "name": "Cloth_Block_Wool_Gray_Light_Half",
      "rotation": 7
    },
    {
      "x": -34,
      "y": 21,
      "z": 12,
      "name": "Cloth_Block_Wool_Gray_Light_Half",
      "rotation": 7
    },
    {
      "x": -34,
      "y": 22,
      "z": 12,
      "name": "Cloth_Block_Wool_Gray_Light_Half",
      "rotation": 7
    },
    {
      "x": -34,
      "y": 23,
      "z": 12,
      "name": "Cloth_Block_Wool_Gray_Light_Half",
      "rotation": 7
    },
    {
      "x": -34,
      "y": 24,
      "z": 12,
      "name": "Cloth_Block_Wool_Gray_Light_Half",
      "rotation": 7
    },
    {
      "x": -34,
      "y": 25,
      "z": 12,
      "name": "Cloth_Block_Wool_Gray_Light_Half",
      "rotation": 7
    },
    {
      "x": -34,
      "y": 21,
      "z": 13,
      "name": "*Cloth_Block_Wool_Gray_Light_Half_State_Definitions_Block",
      "rotation": 7
    },
    {
      "x": -34,
      "y": 22,
      "z": 13,
      "name": "*Cloth_Block_Wool_Gray_Light_Half_State_Definitions_Block",
      "rotation": 7
    },
    {
      "x": -34,
      "y": 23,
      "z": 13,
      "name": "*Cloth_Block_Wool_Gray_Light_Half_State_Definitions_Block",
      "rotation": 7
    },
    {
      "x": -34,
      "y": 24,
      "z": 13,
      "name": "*Cloth_Block_Wool_Gray_Light_Half_State_Definitions_Block",
      "rotation": 7
    },
    {
      "x": -34,
      "y": 25,
      "z": 13,
      "name": "*Cloth_Block_Wool_Gray_Light_Half_State_Definitions_Block",
      "rotation": 7
    },
    {
      "x": -34,
      "y": 18,
      "z": 14,
      "name": "Cloth_Block_Wool_Gray_Light_Half",
      "rotation": 7
    },
    {
      "x": -34,
      "y": 19,
      "z": 14,
      "name": "Cloth_Block_Wool_Gray_Light_Half",
      "rotation": 7
    },
    {
      "x": -34,
      "y": 20,
      "z": 14,
      "name": "Cloth_Block_Wool_Gray_Light_Half",
      "rotation": 7
    },
    {
      "x": -34,
      "y": 21,
      "z": 14,
      "name": "Cloth_Block_Wool_Gray_Light_Half",
      "rotation": 7
    },
    {
      "x": -34,
      "y": 22,
      "z": 14,
      "name": "Cloth_Block_Wool_Gray_Light_Half",
      "rotation": 7
    },
    {
      "x": -34,
      "y": 23,
      "z": 14,
      "name": "Cloth_Block_Wool_Gray_Light_Half",
      "rotation": 7
    },
    {
      "x": -34,
      "y": 24,
      "z": 14,
      "name": "Cloth_Block_Wool_Gray_Light_Half",
      "rotation": 7
    },
    {
      "x": -34,
      "y": 25,
      "z": 14,
      "name": "Cloth_Block_Wool_Gray_Light_Half",
      "rotation": 7
    },
    {
      "x": -34,
      "y": 19,
      "z": 15,
      "name": "Cloth_Block_Wool_Gray_Light_Half",
      "rotation": 7
    },
    {
      "x": -34,
      "y": 20,
      "z": 15,
      "name": "Cloth_Block_Wool_Gray_Light_Half",
      "rotation": 7
    },
    {
      "x": -34,
      "y": 21,
      "z": 15,
      "name": "Cloth_Block_Wool_Gray_Light_Half",
      "rotation": 7
    },
    {
      "x": -34,
      "y": 22,
      "z": 15,
      "name": "Cloth_Block_Wool_Gray_Light_Half",
      "rotation": 7
    },
    {
      "x": -34,
      "y": 23,
      "z": 15,
      "name": "Cloth_Block_Wool_Gray_Light_Half",
      "rotation": 7
    },
    {
      "x": -34,
      "y": 24,
      "z": 15,
      "name": "Cloth_Block_Wool_Gray_Light_Half",
      "rotation": 7
    },
    {
      "x": -34,
      "y": 25,
      "z": 15,
      "name": "Cloth_Block_Wool_Gray_Light_Half",
      "rotation": 7
    },
    {
      "x": -34,
      "y": 26,
      "z": 15,
      "name": "Cloth_Block_Wool_Gray_Light_Half",
      "rotation": 7
    },
    {
      "x": -34,
      "y": 20,
      "z": 16,
      "name": "*Cloth_Block_Wool_Gray_Light_Half_State_Definitions_Block",
      "rotation": 7
    },
    {
      "x": -34,
      "y": 21,
      "z": 16,
      "name": "*Cloth_Block_Wool_Gray_Light_Half_State_Definitions_Block",
      "rotation": 7
    },
    {
      "x": -34,
      "y": 22,
      "z": 16,
      "name": "*Cloth_Block_Wool_Gray_Light_Half_State_Definitions_Block",
      "rotation": 7
    },
    {
      "x": -34,
      "y": 23,
      "z": 16,
      "name": "*Cloth_Block_Wool_Gray_Light_Half_State_Definitions_Block",
      "rotation": 7
    },
    {
      "x": -34,
      "y": 24,
      "z": 16,
      "name": "*Cloth_Block_Wool_Gray_Light_Half_State_Definitions_Block",
      "rotation": 7
    },
    {
      "x": -34,
      "y": 25,
      "z": 16,
      "name": "*Cloth_Block_Wool_Gray_Light_Half_State_Definitions_Block",
      "rotation": 7
    },
    {
      "x": -34,
      "y": 26,
      "z": 16,
      "name": "*Cloth_Block_Wool_Gray_Light_Half_State_Definitions_Block",
      "rotation": 7
    },
    {
      "x": -34,
      "y": 23,
      "z": 17,
      "name": "Cloth_Block_Wool_Gray_Light_Half",
      "rotation": 7
    },
    {
      "x": -34,
      "y": 24,
      "z": 17,
      "name": "Cloth_Block_Wool_Gray_Light_Half",
      "rotation": 7
    },
    {
      "x": -34,
      "y": 25,
      "z": 17,
      "name": "Cloth_Block_Wool_Gray_Light_Half",
      "rotation": 7
    },
    {
      "x": -34,
      "y": 26,
      "z": 17,
      "name": "Cloth_Block_Wool_Gray_Light_Half",
      "rotation": 7
    },
    {
      "x": -34,
      "y": 20,
      "z": 18,
      "name": "Cloth_Block_Wool_Gray_Light_Half",
      "rotation": 7
    },
    {
      "x": -34,
      "y": 21,
      "z": 18,
      "name": "Cloth_Block_Wool_Gray_Light_Half",
      "rotation": 7
    },
    {
      "x": -34,
      "y": 22,
      "z": 18,
      "name": "Cloth_Block_Wool_Gray_Light_Half",
      "rotation": 7
    },
    {
      "x": -34,
      "y": 23,
      "z": 18,
      "name": "Cloth_Block_Wool_Gray_Light_Half",
      "rotation": 7
    },
    {
      "x": -34,
      "y": 24,
      "z": 18,
      "name": "Cloth_Block_Wool_Gray_Light_Half",
      "rotation": 7
    },
    {
      "x": -34,
      "y": 25,
      "z": 18,
      "name": "Cloth_Block_Wool_Gray_Light_Half",
      "rotation": 7
    },
    {
      "x": -34,
      "y": 26,
      "z": 18,
      "name": "Cloth_Block_Wool_Gray_Light_Half",
      "rotation": 7
    },
    {
      "x": -34,
      "y": 27,
      "z": 18,
      "name": "Cloth_Block_Wool_Gray_Light_Half",
      "rotation": 7
    },
    {
      "x": -34,
      "y": 21,
      "z": 19,
      "name": "Cloth_Block_Wool_Gray_Light_Half",
      "rotation": 7
    },
    {
      "x": -34,
      "y": 22,
      "z": 19,
      "name": "Cloth_Block_Wool_Gray_Light_Half",
      "rotation": 7
    },
    {
      "x": -34,
      "y": 23,
      "z": 19,
      "name": "Cloth_Block_Wool_Gray_Light_Half",
      "rotation": 7
    },
    {
      "x": -34,
      "y": 24,
      "z": 19,
      "name": "Cloth_Block_Wool_Gray_Light_Half",
      "rotation": 7
    },
    {
      "x": -34,
      "y": 25,
      "z": 19,
      "name": "Cloth_Block_Wool_Gray_Light_Half",
      "rotation": 7
    },
    {
      "x": -34,
      "y": 26,
      "z": 19,
      "name": "Cloth_Block_Wool_Gray_Light_Half",
      "rotation": 7
    },
    {
      "x": -34,
      "y": 27,
      "z": 19,
      "name": "Cloth_Block_Wool_Gray_Light_Half",
      "rotation": 7
    },
    {
      "x": -33,
      "y": 21,
      "z": 1,
      "name": "Wood_Hardwood_Planks",
      "rotation": 50
    },
    {
      "x": -33,
      "y": 21,
      "z": 2,
      "name": "Wood_Hardwood_Planks",
      "rotation": 50
    },
    {
      "x": -33,
      "y": 22,
      "z": 3,
      "name": "Wood_Hardwood_Planks",
      "rotation": 50
    },
    {
      "x": -33,
      "y": 22,
      "z": 4,
      "name": "Wood_Hardwood_Planks",
      "rotation": 50
    },
    {
      "x": -33,
      "y": 22,
      "z": 5,
      "name": "Wood_Hardwood_Planks",
      "rotation": 50
    },
    {
      "x": -33,
      "y": 23,
      "z": 6,
      "name": "Wood_Deadwood_Planks",
      "rotation": 16
    },
    {
      "x": -33,
      "y": 23,
      "z": 7,
      "name": "Wood_Deadwood_Planks",
      "rotation": 16
    },
    {
      "x": -33,
      "y": 23,
      "z": 8,
      "name": "Wood_Deadwood_Planks",
      "rotation": 16
    },
    {
      "x": -33,
      "y": 24,
      "z": 9,
      "name": "Wood_Deadwood_Planks",
      "rotation": 16
    },
    {
      "x": -33,
      "y": 24,
      "z": 10,
      "name": "Wood_Hardwood_Planks",
      "rotation": 50
    },
    {
      "x": -33,
      "y": 39,
      "z": 10,
      "name": "Wood_Hardwood_Planks",
      "rotation": 50
    },
    {
      "x": -33,
      "y": 24,
      "z": 11,
      "name": "Wood_Deadwood_Planks",
      "rotation": 16
    },
    {
      "x": -33,
      "y": 25,
      "z": 12,
      "name": "Wood_Deadwood_Planks",
      "rotation": 16
    },
    {
      "x": -33,
      "y": 25,
      "z": 13,
      "name": "Wood_Deadwood_Planks",
      "rotation": 16
    },
    {
      "x": -33,
      "y": 25,
      "z": 14,
      "name": "Wood_Deadwood_Planks",
      "rotation": 16
    },
    {
      "x": -33,
      "y": 26,
      "z": 15,
      "name": "Wood_Deadwood_Planks",
      "rotation": 16
    },
    {
      "x": -33,
      "y": 26,
      "z": 16,
      "name": "Wood_Deadwood_Planks",
      "rotation": 16
    },
    {
      "x": -33,
      "y": 26,
      "z": 17,
      "name": "Wood_Deadwood_Planks",
      "rotation": 16
    },
    {
      "x": -33,
      "y": 27,
      "z": 18,
      "name": "Wood_Deadwood_Planks",
      "rotation": 16
    },
    {
      "x": -33,
      "y": 27,
      "z": 19,
      "name": "Wood_Deadwood_Planks",
      "rotation": 16
    },
    {
      "x": -32,
      "y": 23,
      "z": 6,
      "name": "Wood_Hardwood_Planks",
      "rotation": 50
    },
    {
      "x": -32,
      "y": 23,
      "z": 7,
      "name": "Wood_Hardwood_Planks",
      "rotation": 50
    },
    {
      "x": -32,
      "y": 23,
      "z": 8,
      "name": "Wood_Hardwood_Planks",
      "rotation": 50
    },
    {
      "x": -32,
      "y": 24,
      "z": 9,
      "name": "Wood_Hardwood_Planks",
      "rotation": 50
    },
    {
      "x": -32,
      "y": 24,
      "z": 10,
      "name": "Wood_Hardwood_Planks",
      "rotation": 50
    },
    {
      "x": -32,
      "y": 39,
      "z": 10,
      "name": "Wood_Hardwood_Planks",
      "rotation": 50
    },
    {
      "x": -32,
      "y": 24,
      "z": 11,
      "name": "Wood_Hardwood_Planks",
      "rotation": 50
    },
    {
      "x": -32,
      "y": 50,
      "z": 11,
      "name": "Wood_Deadwood_Planks",
      "rotation": 16
    },
    {
      "x": -32,
      "y": 25,
      "z": 12,
      "name": "Wood_Hardwood_Planks",
      "rotation": 50
    },
    {
      "x": -32,
      "y": 25,
      "z": 13,
      "name": "Wood_Hardwood_Planks",
      "rotation": 50
    },
    {
      "x": -32,
      "y": 25,
      "z": 14,
      "name": "Wood_Hardwood_Planks",
      "rotation": 50
    },
    {
      "x": -32,
      "y": 26,
      "z": 15,
      "name": "Wood_Hardwood_Planks",
      "rotation": 50
    },
    {
      "x": -32,
      "y": 26,
      "z": 16,
      "name": "Wood_Hardwood_Planks",
      "rotation": 50
    },
    {
      "x": -32,
      "y": 26,
      "z": 17,
      "name": "Wood_Hardwood_Planks",
      "rotation": 50
    },
    {
      "x": -32,
      "y": 27,
      "z": 18,
      "name": "Wood_Hardwood_Planks",
      "rotation": 50
    },
    {
      "x": -32,
      "y": 27,
      "z": 19,
      "name": "Wood_Hardwood_Planks",
      "rotation": 50
    },
    {
      "x": -31,
      "y": 23,
      "z": 10,
      "name": "Wood_Hardwood_Planks",
      "rotation": 50
    },
    {
      "x": -31,
      "y": 39,
      "z": 10,
      "name": "Wood_Hardwood_Planks",
      "rotation": 50
    },
    {
      "x": -31,
      "y": 49,
      "z": 11,
      "name": "Wood_Hardwood_Planks",
      "rotation": 7
    },
    {
      "x": -31,
      "y": 50,
      "z": 11,
      "name": "Wood_Hardwood_Planks",
      "rotation": 50
    },
    {
      "x": -30,
      "y": 23,
      "z": 10,
      "name": "Wood_Hardwood_Planks",
      "rotation": 50
    },
    {
      "x": -30,
      "y": 38,
      "z": 10,
      "name": "Wood_Hardwood_Planks",
      "rotation": 50
    },
    {
      "x": -30,
      "y": 48,
      "z": 11,
      "name": "Wood_Hardwood_Planks",
      "rotation": 7
    },
    {
      "x": -30,
      "y": 49,
      "z": 11,
      "name": "Wood_Hardwood_Planks",
      "rotation": 50
    },
    {
      "x": -29,
      "y": 23,
      "z": 10,
      "name": "Wood_Hardwood_Planks",
      "rotation": 50
    },
    {
      "x": -29,
      "y": 38,
      "z": 10,
      "name": "Wood_Hardwood_Planks",
      "rotation": 50
    },
    {
      "x": -29,
      "y": 45,
      "z": 11,
      "name": "Wood_Hardwood_Planks",
      "rotation": 7
    },
    {
      "x": -29,
      "y": 46,
      "z": 11,
      "name": "Wood_Hardwood_Planks",
      "rotation": 7
    },
    {
      "x": -29,
      "y": 47,
      "z": 11,
      "name": "Wood_Hardwood_Planks",
      "rotation": 50
    },
    {
      "x": -28,
      "y": 28,
      "z": 1,
      "name": "Cloth_Block_Wool_Gray_Light_Half",
      "rotation": 7
    },
    {
      "x": -28,
      "y": 29,
      "z": 1,
      "name": "Cloth_Block_Wool_Gray_Light_Half",
      "rotation": 7
    },
    {
      "x": -28,
      "y": 30,
      "z": 1,
      "name": "Cloth_Block_Wool_Gray_Light_Half",
      "rotation": 7
    },
    {
      "x": -28,
      "y": 31,
      "z": 1,
      "name": "Cloth_Block_Wool_Gray_Light_Half",
      "rotation": 7
    },
    {
      "x": -28,
      "y": 32,
      "z": 1,
      "name": "Cloth_Block_Wool_Gray_Light_Half",
      "rotation": 7
    },
    {
      "x": -28,
      "y": 33,
      "z": 1,
      "name": "Cloth_Block_Wool_Gray_Light_Half",
      "rotation": 7
    },
    {
      "x": -28,
      "y": 34,
      "z": 1,
      "name": "Cloth_Block_Wool_Gray_Light_Half",
      "rotation": 7
    },
    {
      "x": -28,
      "y": 35,
      "z": 1,
      "name": "Cloth_Block_Wool_Gray_Light_Half",
      "rotation": 7
    },
    {
      "x": -28,
      "y": 30,
      "z": 2,
      "name": "*Cloth_Block_Wool_Gray_Light_Half_State_Definitions_Block",
      "rotation": 7
    },
    {
      "x": -28,
      "y": 31,
      "z": 2,
      "name": "*Cloth_Block_Wool_Gray_Light_Half_State_Definitions_Block",
      "rotation": 7
    },
    {
      "x": -28,
      "y": 32,
      "z": 2,
      "name": "*Cloth_Block_Wool_Gray_Light_Half_State_Definitions_Block",
      "rotation": 7
    },
    {
      "x": -28,
      "y": 33,
      "z": 2,
      "name": "*Cloth_Block_Wool_Gray_Light_Half_State_Definitions_Block",
      "rotation": 7
    },
    {
      "x": -28,
      "y": 34,
      "z": 2,
      "name": "*Cloth_Block_Wool_Gray_Light_Half_State_Definitions_Block",
      "rotation": 7
    },
    {
      "x": -28,
      "y": 35,
      "z": 2,
      "name": "*Cloth_Block_Wool_Gray_Light_Half_State_Definitions_Block",
      "rotation": 7
    },
    {
      "x": -28,
      "y": 31,
      "z": 3,
      "name": "Cloth_Block_Wool_Gray_Light_Half",
      "rotation": 7
    },
    {
      "x": -28,
      "y": 32,
      "z": 3,
      "name": "Cloth_Block_Wool_Gray_Light_Half",
      "rotation": 7
    },
    {
      "x": -28,
      "y": 33,
      "z": 3,
      "name": "Cloth_Block_Wool_Gray_Light_Half",
      "rotation": 7
    },
    {
      "x": -28,
      "y": 34,
      "z": 3,
      "name": "Cloth_Block_Wool_Gray_Light_Half",
      "rotation": 7
    },
    {
      "x": -28,
      "y": 35,
      "z": 3,
      "name": "Cloth_Block_Wool_Gray_Light_Half",
      "rotation": 7
    },
    {
      "x": -28,
      "y": 36,
      "z": 3,
      "name": "Cloth_Block_Wool_Gray_Light_Half",
      "rotation": 7
    },
    {
      "x": -28,
      "y": 29,
      "z": 4,
      "name": "Cloth_Block_Wool_Gray_Light_Half",
      "rotation": 7
    },
    {
      "x": -28,
      "y": 30,
      "z": 4,
      "name": "Cloth_Block_Wool_Gray_Light_Half",
      "rotation": 7
    },
    {
      "x": -28,
      "y": 31,
      "z": 4,
      "name": "Cloth_Block_Wool_Gray_Light_Half",
      "rotation": 7
    },
    {
      "x": -28,
      "y": 32,
      "z": 4,
      "name": "Cloth_Block_Wool_Gray_Light_Half",
      "rotation": 7
    },
    {
      "x": -28,
      "y": 33,
      "z": 4,
      "name": "Cloth_Block_Wool_Gray_Light_Half",
      "rotation": 7
    },
    {
      "x": -28,
      "y": 34,
      "z": 4,
      "name": "Cloth_Block_Wool_Gray_Light_Half",
      "rotation": 7
    },
    {
      "x": -28,
      "y": 35,
      "z": 4,
      "name": "Cloth_Block_Wool_Gray_Light_Half",
      "rotation": 7
    },
    {
      "x": -28,
      "y": 36,
      "z": 4,
      "name": "Cloth_Block_Wool_Gray_Light_Half",
      "rotation": 7
    },
    {
      "x": -28,
      "y": 32,
      "z": 5,
      "name": "*Cloth_Block_Wool_Gray_Light_Half_State_Definitions_Block",
      "rotation": 7
    },
    {
      "x": -28,
      "y": 33,
      "z": 5,
      "name": "*Cloth_Block_Wool_Gray_Light_Half_State_Definitions_Block",
      "rotation": 7
    },
    {
      "x": -28,
      "y": 34,
      "z": 5,
      "name": "*Cloth_Block_Wool_Gray_Light_Half_State_Definitions_Block",
      "rotation": 7
    },
    {
      "x": -28,
      "y": 35,
      "z": 5,
      "name": "*Cloth_Block_Wool_Gray_Light_Half_State_Definitions_Block",
      "rotation": 7
    },
    {
      "x": -28,
      "y": 36,
      "z": 5,
      "name": "*Cloth_Block_Wool_Gray_Light_Half_State_Definitions_Block",
      "rotation": 7
    },
    {
      "x": -28,
      "y": 30,
      "z": 6,
      "name": "Cloth_Block_Wool_Gray_Light_Half",
      "rotation": 7
    },
    {
      "x": -28,
      "y": 31,
      "z": 6,
      "name": "Cloth_Block_Wool_Gray_Light_Half",
      "rotation": 7
    },
    {
      "x": -28,
      "y": 32,
      "z": 6,
      "name": "Cloth_Block_Wool_Gray_Light_Half",
      "rotation": 7
    },
    {
      "x": -28,
      "y": 33,
      "z": 6,
      "name": "Cloth_Block_Wool_Gray_Light_Half",
      "rotation": 7
    },
    {
      "x": -28,
      "y": 34,
      "z": 6,
      "name": "Cloth_Block_Wool_Gray_Light_Half",
      "rotation": 7
    },
    {
      "x": -28,
      "y": 35,
      "z": 6,
      "name": "Cloth_Block_Wool_Gray_Light_Half",
      "rotation": 7
    },
    {
      "x": -28,
      "y": 36,
      "z": 6,
      "name": "Cloth_Block_Wool_Gray_Light_Half",
      "rotation": 7
    },
    {
      "x": -28,
      "y": 37,
      "z": 6,
      "name": "Cloth_Block_Wool_Gray_Light_Half",
      "rotation": 7
    },
    {
      "x": -28,
      "y": 30,
      "z": 7,
      "name": "Cloth_Block_Wool_Gray_Light_Half",
      "rotation": 7
    },
    {
      "x": -28,
      "y": 31,
      "z": 7,
      "name": "Cloth_Block_Wool_Gray_Light_Half",
      "rotation": 7
    },
    {
      "x": -28,
      "y": 32,
      "z": 7,
      "name": "Cloth_Block_Wool_Gray_Light_Half",
      "rotation": 7
    },
    {
      "x": -28,
      "y": 33,
      "z": 7,
      "name": "Cloth_Block_Wool_Gray_Light_Half",
      "rotation": 7
    },
    {
      "x": -28,
      "y": 34,
      "z": 7,
      "name": "Cloth_Block_Wool_Gray_Light_Half",
      "rotation": 7
    },
    {
      "x": -28,
      "y": 35,
      "z": 7,
      "name": "Cloth_Block_Wool_Gray_Light_Half",
      "rotation": 7
    },
    {
      "x": -28,
      "y": 36,
      "z": 7,
      "name": "Cloth_Block_Wool_Gray_Light_Half",
      "rotation": 7
    },
    {
      "x": -28,
      "y": 37,
      "z": 7,
      "name": "Cloth_Block_Wool_Gray_Light_Half",
      "rotation": 7
    },
    {
      "x": -28,
      "y": 33,
      "z": 8,
      "name": "Cloth_Block_Wool_Gray_Light_Half",
      "rotation": 7
    },
    {
      "x": -28,
      "y": 34,
      "z": 8,
      "name": "Cloth_Block_Wool_Gray_Light_Half",
      "rotation": 7
    },
    {
      "x": -28,
      "y": 35,
      "z": 8,
      "name": "Cloth_Block_Wool_Gray_Light_Half",
      "rotation": 7
    },
    {
      "x": -28,
      "y": 36,
      "z": 8,
      "name": "Cloth_Block_Wool_Gray_Light_Half",
      "rotation": 7
    },
    {
      "x": -28,
      "y": 37,
      "z": 8,
      "name": "Cloth_Block_Wool_Gray_Light_Half",
      "rotation": 7
    },
    {
      "x": -28,
      "y": 31,
      "z": 9,
      "name": "Cloth_Block_Wool_Gray_Light_Half",
      "rotation": 7
    },
    {
      "x": -28,
      "y": 32,
      "z": 9,
      "name": "Cloth_Block_Wool_Gray_Light_Half",
      "rotation": 7
    },
    {
      "x": -28,
      "y": 33,
      "z": 9,
      "name": "Cloth_Block_Wool_Gray_Light_Half",
      "rotation": 7
    },
    {
      "x": -28,
      "y": 34,
      "z": 9,
      "name": "Cloth_Block_Wool_Gray_Light_Half",
      "rotation": 7
    },
    {
      "x": -28,
      "y": 35,
      "z": 9,
      "name": "Cloth_Block_Wool_Gray_Light_Half",
      "rotation": 7
    },
    {
      "x": -28,
      "y": 36,
      "z": 9,
      "name": "Cloth_Block_Wool_Gray_Light_Half",
      "rotation": 7
    },
    {
      "x": -28,
      "y": 37,
      "z": 9,
      "name": "Cloth_Block_Wool_Gray_Light_Half",
      "rotation": 7
    },
    {
      "x": -28,
      "y": 38,
      "z": 9,
      "name": "Cloth_Block_Wool_Gray_Light_Half",
      "rotation": 7
    },
    {
      "x": -28,
      "y": 23,
      "z": 10,
      "name": "Wood_Hardwood_Planks",
      "rotation": 50
    },
    {
      "x": -28,
      "y": 30,
      "z": 10,
      "name": "Cloth_Block_Wool_Gray_Light_Half",
      "rotation": 7
    },
    {
      "x": -28,
      "y": 31,
      "z": 10,
      "name": "Cloth_Block_Wool_Gray_Light_Half",
      "rotation": 7
    },
    {
      "x": -28,
      "y": 32,
      "z": 10,
      "name": "Cloth_Block_Wool_Gray_Light_Half",
      "rotation": 7
    },
    {
      "x": -28,
      "y": 33,
      "z": 10,
      "name": "Cloth_Block_Wool_Gray_Light_Half",
      "rotation": 7
    },
    {
      "x": -28,
      "y": 34,
      "z": 10,
      "name": "Cloth_Block_Wool_Gray_Light_Half",
      "rotation": 7
    },
    {
      "x": -28,
      "y": 35,
      "z": 10,
      "name": "Cloth_Block_Wool_Gray_Light_Half",
      "rotation": 7
    },
    {
      "x": -28,
      "y": 36,
      "z": 10,
      "name": "Cloth_Block_Wool_Gray_Light_Half",
      "rotation": 7
    },
    {
      "x": -28,
      "y": 37,
      "z": 10,
      "name": "Cloth_Block_Wool_Gray_Light_Half",
      "rotation": 7
    },
    {
      "x": -28,
      "y": 38,
      "z": 10,
      "name": "Wood_Hardwood_Planks",
      "rotation": 50
    },
    {
      "x": -28,
      "y": 34,
      "z": 11,
      "name": "Cloth_Block_Wool_Gray_Light_Half",
      "rotation": 7
    },
    {
      "x": -28,
      "y": 35,
      "z": 11,
      "name": "Cloth_Block_Wool_Gray_Light_Half",
      "rotation": 7
    },
    {
      "x": -28,
      "y": 36,
      "z": 11,
      "name": "Cloth_Block_Wool_Gray_Light_Half",
      "rotation": 7
    },
    {
      "x": -28,
      "y": 37,
      "z": 11,
      "name": "Cloth_Block_Wool_Gray_Light_Half",
      "rotation": 7
    },
    {
      "x": -28,
      "y": 38,
      "z": 11,
      "name": "Cloth_Block_Wool_Gray_Light_Half",
      "rotation": 7
    },
    {
      "x": -28,
      "y": 44,
      "z": 11,
      "name": "Wood_Hardwood_Planks",
      "rotation": 7
    },
    {
      "x": -28,
      "y": 45,
      "z": 11,
      "name": "Wood_Hardwood_Planks",
      "rotation": 50
    },
    {
      "x": -28,
      "y": 46,
      "z": 11,
      "name": "Wood_Hardwood_Planks",
      "rotation": 50
    },
    {
      "x": -28,
      "y": 33,
      "z": 12,
      "name": "Cloth_Block_Wool_Gray_Light_Half",
      "rotation": 7
    },
    {
      "x": -28,
      "y": 34,
      "z": 12,
      "name": "Cloth_Block_Wool_Gray_Light_Half",
      "rotation": 7
    },
    {
      "x": -28,
      "y": 35,
      "z": 12,
      "name": "Cloth_Block_Wool_Gray_Light_Half",
      "rotation": 7
    },
    {
      "x": -28,
      "y": 36,
      "z": 12,
      "name": "Cloth_Block_Wool_Gray_Light_Half",
      "rotation": 7
    },
    {
      "x": -28,
      "y": 37,
      "z": 12,
      "name": "Cloth_Block_Wool_Gray_Light_Half",
      "rotation": 7
    },
    {
      "x": -28,
      "y": 38,
      "z": 12,
      "name": "Cloth_Block_Wool_Gray_Light_Half",
      "rotation": 7
    },
    {
      "x": -28,
      "y": 39,
      "z": 12,
      "name": "Cloth_Block_Wool_Gray_Light_Half",
      "rotation": 7
    },
    {
      "x": -28,
      "y": 32,
      "z": 13,
      "name": "Cloth_Block_Wool_Gray_Light_Half",
      "rotation": 7
    },
    {
      "x": -28,
      "y": 33,
      "z": 13,
      "name": "Cloth_Block_Wool_Gray_Light_Half",
      "rotation": 7
    },
    {
      "x": -28,
      "y": 34,
      "z": 13,
      "name": "Cloth_Block_Wool_Gray_Light_Half",
      "rotation": 7
    },
    {
      "x": -28,
      "y": 35,
      "z": 13,
      "name": "Cloth_Block_Wool_Gray_Light_Half",
      "rotation": 7
    },
    {
      "x": -28,
      "y": 36,
      "z": 13,
      "name": "Cloth_Block_Wool_Gray_Light_Half",
      "rotation": 7
    },
    {
      "x": -28,
      "y": 37,
      "z": 13,
      "name": "Cloth_Block_Wool_Gray_Light_Half",
      "rotation": 7
    },
    {
      "x": -28,
      "y": 38,
      "z": 13,
      "name": "Cloth_Block_Wool_Gray_Light_Half",
      "rotation": 7
    },
    {
      "x": -28,
      "y": 39,
      "z": 13,
      "name": "Cloth_Block_Wool_Gray_Light_Half",
      "rotation": 7
    },
    {
      "x": -28,
      "y": 32,
      "z": 14,
      "name": "Cloth_Block_Wool_Gray_Light_Half",
      "rotation": 7
    },
    {
      "x": -28,
      "y": 33,
      "z": 14,
      "name": "Cloth_Block_Wool_Gray_Light_Half",
      "rotation": 7
    },
    {
      "x": -28,
      "y": 34,
      "z": 14,
      "name": "Cloth_Block_Wool_Gray_Light_Half",
      "rotation": 7
    },
    {
      "x": -28,
      "y": 35,
      "z": 14,
      "name": "Cloth_Block_Wool_Gray_Light_Half",
      "rotation": 7
    },
    {
      "x": -28,
      "y": 36,
      "z": 14,
      "name": "Cloth_Block_Wool_Gray_Light_Half",
      "rotation": 7
    },
    {
      "x": -28,
      "y": 37,
      "z": 14,
      "name": "Cloth_Block_Wool_Gray_Light_Half",
      "rotation": 7
    },
    {
      "x": -28,
      "y": 38,
      "z": 14,
      "name": "Cloth_Block_Wool_Gray_Light_Half",
      "rotation": 7
    },
    {
      "x": -28,
      "y": 39,
      "z": 14,
      "name": "Cloth_Block_Wool_Gray_Light_Half",
      "rotation": 7
    },
    {
      "x": -27,
      "y": 35,
      "z": 1,
      "name": "Wood_Deadwood_Planks",
      "rotation": 16
    },
    {
      "x": -27,
      "y": 35,
      "z": 2,
      "name": "Wood_Deadwood_Planks",
      "rotation": 16
    },
    {
      "x": -27,
      "y": 36,
      "z": 3,
      "name": "Wood_Deadwood_Planks",
      "rotation": 16
    },
    {
      "x": -27,
      "y": 36,
      "z": 4,
      "name": "Wood_Deadwood_Planks",
      "rotation": 16
    },
    {
      "x": -27,
      "y": 36,
      "z": 5,
      "name": "Wood_Deadwood_Planks",
      "rotation": 16
    },
    {
      "x": -27,
      "y": 37,
      "z": 6,
      "name": "Wood_Deadwood_Planks",
      "rotation": 16
    },
    {
      "x": -27,
      "y": 37,
      "z": 7,
      "name": "Wood_Deadwood_Planks",
      "rotation": 16
    },
    {
      "x": -27,
      "y": 37,
      "z": 8,
      "name": "Wood_Deadwood_Planks",
      "rotation": 16
    },
    {
      "x": -27,
      "y": 38,
      "z": 9,
      "name": "Wood_Deadwood_Planks",
      "rotation": 16
    },
    {
      "x": -27,
      "y": 23,
      "z": 10,
      "name": "Wood_Hardwood_Planks",
      "rotation": 50
    },
    {
      "x": -27,
      "y": 38,
      "z": 10,
      "name": "Wood_Hardwood_Planks",
      "rotation": 50
    },
    {
      "x": -27,
      "y": 38,
      "z": 11,
      "name": "Wood_Deadwood_Planks",
      "rotation": 16
    },
    {
      "x": -27,
      "y": 43,
      "z": 11,
      "name": "Wood_Hardwood_Planks",
      "rotation": 7
    },
    {
      "x": -27,
      "y": 44,
      "z": 11,
      "name": "Wood_Hardwood_Planks",
      "rotation": 50
    },
    {
      "x": -27,
      "y": 39,
      "z": 12,
      "name": "Wood_Deadwood_Planks",
      "rotation": 16
    },
    {
      "x": -27,
      "y": 39,
      "z": 13,
      "name": "Wood_Deadwood_Planks",
      "rotation": 16
    },
    {
      "x": -27,
      "y": 39,
      "z": 14,
      "name": "Wood_Deadwood_Planks",
      "rotation": 16
    },
    {
      "x": -27,
      "y": 33,
      "z": 15,
      "name": "*Cloth_Block_Wool_Gray_Light_Half_State_Definitions_Block",
      "rotation": 7
    },
    {
      "x": -27,
      "y": 34,
      "z": 15,
      "name": "*Cloth_Block_Wool_Gray_Light_Half_State_Definitions_Block",
      "rotation": 7
    },
    {
      "x": -27,
      "y": 35,
      "z": 15,
      "name": "*Cloth_Block_Wool_Gray_Light_Half_State_Definitions_Block",
      "rotation": 7
    },
    {
      "x": -27,
      "y": 36,
      "z": 15,
      "name": "*Cloth_Block_Wool_Gray_Light_Half_State_Definitions_Block",
      "rotation": 7
    },
    {
      "x": -27,
      "y": 37,
      "z": 15,
      "name": "*Cloth_Block_Wool_Gray_Light_Half_State_Definitions_Block",
      "rotation": 7
    },
    {
      "x": -27,
      "y": 38,
      "z": 15,
      "name": "*Cloth_Block_Wool_Gray_Light_Half_State_Definitions_Block",
      "rotation": 7
    },
    {
      "x": -27,
      "y": 39,
      "z": 15,
      "name": "*Cloth_Block_Wool_Gray_Light_Half_State_Definitions_Block",
      "rotation": 7
    },
    {
      "x": -27,
      "y": 40,
      "z": 15,
      "name": "*Cloth_Block_Wool_Gray_Light_Half_State_Definitions_Block",
      "rotation": 7
    },
    {
      "x": -27,
      "y": 35,
      "z": 16,
      "name": "Cloth_Block_Wool_Gray_Light_Half",
      "rotation": 7
    },
    {
      "x": -27,
      "y": 36,
      "z": 16,
      "name": "Cloth_Block_Wool_Gray_Light_Half",
      "rotation": 7
    },
    {
      "x": -27,
      "y": 37,
      "z": 16,
      "name": "Cloth_Block_Wool_Gray_Light_Half",
      "rotation": 7
    },
    {
      "x": -27,
      "y": 38,
      "z": 16,
      "name": "Cloth_Block_Wool_Gray_Light_Half",
      "rotation": 7
    },
    {
      "x": -27,
      "y": 39,
      "z": 16,
      "name": "Cloth_Block_Wool_Gray_Light_Half",
      "rotation": 7
    },
    {
      "x": -27,
      "y": 40,
      "z": 16,
      "name": "Cloth_Block_Wool_Gray_Light_Half",
      "rotation": 7
    },
    {
      "x": -27,
      "y": 34,
      "z": 17,
      "name": "Cloth_Block_Wool_Gray_Light_Half",
      "rotation": 7
    },
    {
      "x": -27,
      "y": 35,
      "z": 17,
      "name": "Cloth_Block_Wool_Gray_Light_Half",
      "rotation": 7
    },
    {
      "x": -27,
      "y": 36,
      "z": 17,
      "name": "Cloth_Block_Wool_Gray_Light_Half",
      "rotation": 7
    },
    {
      "x": -27,
      "y": 37,
      "z": 17,
      "name": "Cloth_Block_Wool_Gray_Light_Half",
      "rotation": 7
    },
    {
      "x": -27,
      "y": 38,
      "z": 17,
      "name": "Cloth_Block_Wool_Gray_Light_Half",
      "rotation": 7
    },
    {
      "x": -27,
      "y": 39,
      "z": 17,
      "name": "Cloth_Block_Wool_Gray_Light_Half",
      "rotation": 7
    },
    {
      "x": -27,
      "y": 40,
      "z": 17,
      "name": "Cloth_Block_Wool_Gray_Light_Half",
      "rotation": 7
    },
    {
      "x": -27,
      "y": 36,
      "z": 18,
      "name": "*Cloth_Block_Wool_Gray_Light_Half_State_Definitions_Block",
      "rotation": 7
    },
    {
      "x": -27,
      "y": 37,
      "z": 18,
      "name": "*Cloth_Block_Wool_Gray_Light_Half_State_Definitions_Block",
      "rotation": 7
    },
    {
      "x": -27,
      "y": 38,
      "z": 18,
      "name": "*Cloth_Block_Wool_Gray_Light_Half_State_Definitions_Block",
      "rotation": 7
    },
    {
      "x": -27,
      "y": 39,
      "z": 18,
      "name": "*Cloth_Block_Wool_Gray_Light_Half_State_Definitions_Block",
      "rotation": 7
    },
    {
      "x": -27,
      "y": 40,
      "z": 18,
      "name": "*Cloth_Block_Wool_Gray_Light_Half_State_Definitions_Block",
      "rotation": 7
    },
    {
      "x": -27,
      "y": 41,
      "z": 18,
      "name": "*Cloth_Block_Wool_Gray_Light_Half_State_Definitions_Block",
      "rotation": 7
    },
    {
      "x": -27,
      "y": 34,
      "z": 19,
      "name": "Cloth_Block_Wool_Gray_Light_Half",
      "rotation": 7
    },
    {
      "x": -27,
      "y": 35,
      "z": 19,
      "name": "Cloth_Block_Wool_Gray_Light_Half",
      "rotation": 7
    },
    {
      "x": -27,
      "y": 36,
      "z": 19,
      "name": "Cloth_Block_Wool_Gray_Light_Half",
      "rotation": 7
    },
    {
      "x": -27,
      "y": 37,
      "z": 19,
      "name": "Cloth_Block_Wool_Gray_Light_Half",
      "rotation": 7
    },
    {
      "x": -27,
      "y": 38,
      "z": 19,
      "name": "Cloth_Block_Wool_Gray_Light_Half",
      "rotation": 7
    },
    {
      "x": -27,
      "y": 39,
      "z": 19,
      "name": "Cloth_Block_Wool_Gray_Light_Half",
      "rotation": 7
    },
    {
      "x": -27,
      "y": 40,
      "z": 19,
      "name": "Cloth_Block_Wool_Gray_Light_Half",
      "rotation": 7
    },
    {
      "x": -27,
      "y": 41,
      "z": 19,
      "name": "Cloth_Block_Wool_Gray_Light_Half",
      "rotation": 7
    },
    {
      "x": -26,
      "y": 35,
      "z": 1,
      "name": "Wood_Hardwood_Planks",
      "rotation": 50
    },
    {
      "x": -26,
      "y": 35,
      "z": 2,
      "name": "Wood_Hardwood_Planks",
      "rotation": 50
    },
    {
      "x": -26,
      "y": 36,
      "z": 3,
      "name": "Wood_Hardwood_Planks",
      "rotation": 50
    },
    {
      "x": -26,
      "y": 36,
      "z": 4,
      "name": "Wood_Hardwood_Planks",
      "rotation": 50
    },
    {
      "x": -26,
      "y": 36,
      "z": 5,
      "name": "Wood_Hardwood_Planks",
      "rotation": 50
    },
    {
      "x": -26,
      "y": 37,
      "z": 6,
      "name": "Wood_Hardwood_Planks",
      "rotation": 50
    },
    {
      "x": -26,
      "y": 37,
      "z": 7,
      "name": "Wood_Hardwood_Planks",
      "rotation": 50
    },
    {
      "x": -26,
      "y": 37,
      "z": 8,
      "name": "Wood_Hardwood_Planks",
      "rotation": 50
    },
    {
      "x": -26,
      "y": 38,
      "z": 9,
      "name": "Wood_Hardwood_Planks",
      "rotation": 50
    },
    {
      "x": -26,
      "y": 22,
      "z": 10,
      "name": "Wood_Hardwood_Planks",
      "rotation": 50
    },
    {
      "x": -26,
      "y": 38,
      "z": 10,
      "name": "Wood_Hardwood_Planks",
      "rotation": 50
    },
    {
      "x": -26,
      "y": 38,
      "z": 11,
      "name": "Wood_Hardwood_Planks",
      "rotation": 50
    },
    {
      "x": -26,
      "y": 42,
      "z": 11,
      "name": "Wood_Hardwood_Planks",
      "rotation": 7
    },
    {
      "x": -26,
      "y": 43,
      "z": 11,
      "name": "Wood_Hardwood_Planks",
      "rotation": 50
    },
    {
      "x": -26,
      "y": 39,
      "z": 12,
      "name": "Wood_Hardwood_Planks",
      "rotation": 50
    },
    {
      "x": -26,
      "y": 39,
      "z": 13,
      "name": "Wood_Hardwood_Planks",
      "rotation": 50
    },
    {
      "x": -26,
      "y": 39,
      "z": 14,
      "name": "Wood_Hardwood_Planks",
      "rotation": 50
    },
    {
      "x": -26,
      "y": 40,
      "z": 15,
      "name": "Wood_Deadwood_Planks",
      "rotation": 16
    },
    {
      "x": -26,
      "y": 40,
      "z": 16,
      "name": "Wood_Deadwood_Planks",
      "rotation": 16
    },
    {
      "x": -26,
      "y": 40,
      "z": 17,
      "name": "Wood_Deadwood_Planks",
      "rotation": 16
    },
    {
      "x": -26,
      "y": 41,
      "z": 18,
      "name": "Wood_Deadwood_Planks",
      "rotation": 16
    },
    {
      "x": -26,
      "y": 41,
      "z": 19,
      "name": "Wood_Deadwood_Planks",
      "rotation": 16
    },
    {
      "x": -25,
      "y": 22,
      "z": 10,
      "name": "Wood_Hardwood_Planks",
      "rotation": 50
    },
    {
      "x": -25,
      "y": 38,
      "z": 10,
      "name": "Wood_Hardwood_Planks",
      "rotation": 50
    },
    {
      "x": -25,
      "y": 41,
      "z": 11,
      "name": "Wood_Hardwood_Planks",
      "rotation": 7
    },
    {
      "x": -25,
      "y": 42,
      "z": 11,
      "name": "Wood_Hardwood_Planks",
      "rotation": 50
    },
    {
      "x": -25,
      "y": 40,
      "z": 15,
      "name": "Wood_Hardwood_Planks",
      "rotation": 50
    },
    {
      "x": -25,
      "y": 40,
      "z": 16,
      "name": "Wood_Hardwood_Planks",
      "rotation": 50
    },
    {
      "x": -25,
      "y": 40,
      "z": 17,
      "name": "Wood_Hardwood_Planks",
      "rotation": 50
    },
    {
      "x": -25,
      "y": 41,
      "z": 18,
      "name": "Wood_Hardwood_Planks",
      "rotation": 50
    },
    {
      "x": -25,
      "y": 41,
      "z": 19,
      "name": "Wood_Hardwood_Planks",
      "rotation": 50
    },
    {
      "x": -24,
      "y": 22,
      "z": 10,
      "name": "Wood_Hardwood_Planks",
      "rotation": 50
    },
    {
      "x": -24,
      "y": 37,
      "z": 10,
      "name": "Wood_Hardwood_Planks",
      "rotation": 50
    },
    {
      "x": -24,
      "y": 38,
      "z": 11,
      "name": "Wood_Hardwood_Planks",
      "rotation": 7
    },
    {
      "x": -24,
      "y": 39,
      "z": 11,
      "name": "Wood_Hardwood_Planks",
      "rotation": 7
    },
    {
      "x": -24,
      "y": 40,
      "z": 11,
      "name": "Wood_Hardwood_Planks",
      "rotation": 50
    },
    {
      "x": -23,
      "y": 21,
      "z": 10,
      "name": "Wood_Hardwood_Planks",
      "rotation": 50
    },
    {
      "x": -23,
      "y": 22,
      "z": 10,
      "name": "Wood_Hardwood_Planks",
      "rotation": 50
    },
    {
      "x": -23,
      "y": 36,
      "z": 10,
      "name": "Wood_Hardwood_Planks",
      "rotation": 50
    },
    {
      "x": -23,
      "y": 37,
      "z": 10,
      "name": "Wood_Hardwood_Planks",
      "rotation": 50
    },
    {
      "x": -23,
      "y": 37,
      "z": 11,
      "name": "Wood_Hardwood_Planks",
      "rotation": 7
    },
    {
      "x": -23,
      "y": 38,
      "z": 11,
      "name": "Wood_Hardwood_Planks",
      "rotation": 50
    },
    {
      "x": -23,
      "y": 39,
      "z": 11,
      "name": "Wood_Hardwood_Planks",
      "rotation": 50
    },
    {
      "x": -22,
      "y": 21,
      "z": 10,
      "name": "Wood_Hardwood_Planks",
      "rotation": 50
    },
    {
      "x": -22,
      "y": 22,
      "z": 10,
      "name": "Wood_Hardwood_Planks",
      "rotation": 50
    },
    {
      "x": -22,
      "y": 36,
      "z": 10,
      "name": "Wood_Hardwood_Planks",
      "rotation": 50
    },
    {
      "x": -22,
      "y": 37,
      "z": 10,
      "name": "Wood_Hardwood_Planks",
      "rotation": 50
    },
    {
      "x": -22,
      "y": 36,
      "z": 11,
      "name": "Wood_Hardwood_Planks",
      "rotation": 7
    },
    {
      "x": -22,
      "y": 37,
      "z": 11,
      "name": "Wood_Hardwood_Planks",
      "rotation": 50
    },
    {
      "x": -21,
      "y": 21,
      "z": 10,
      "name": "Wood_Hardwood_Planks",
      "rotation": 50
    },
    {
      "x": -21,
      "y": 22,
      "z": 10,
      "name": "Wood_Hardwood_Planks",
      "rotation": 50
    },
    {
      "x": -21,
      "y": 36,
      "z": 10,
      "name": "Wood_Hardwood_Planks",
      "rotation": 50
    },
    {
      "x": -21,
      "y": 35,
      "z": 11,
      "name": "Wood_Hardwood_Planks",
      "rotation": 7
    },
    {
      "x": -21,
      "y": 36,
      "z": 11,
      "name": "Wood_Hardwood_Planks",
      "rotation": 50
    },
    {
      "x": -20,
      "y": 19,
      "z": 8,
      "name": "Wood_Hardwood_Planks",
      "rotation": 16
    },
    {
      "x": -20,
      "y": 20,
      "z": 8,
      "name": "Wood_Hardwood_Planks",
      "rotation": 16
    },
    {
      "x": -20,
      "y": 21,
      "z": 8,
      "name": "Wood_Hardwood_Planks",
      "rotation": 16
    },
    {
      "x": -20,
      "y": 18,
      "z": 9,
      "name": "Wood_Hardwood_Planks",
      "rotation": 16
    },
    {
      "x": -20,
      "y": 18,
      "z": 10,
      "name": "Wood_Hardwood_Planks",
      "rotation": 13
    },
    {
      "x": -20,
      "y": 20,
      "z": 10,
      "name": "Wood_Hardwood_Planks",
      "rotation": 50
    },
    {
      "x": -20,
      "y": 36,
      "z": 10,
      "name": "Wood_Hardwood_Planks",
      "rotation": 50
    },
    {
      "x": -20,
      "y": 18,
      "z": 11,
      "name": "Wood_Hardwood_Planks",
      "rotation": 16
    },
    {
      "x": -20,
      "y": 34,
      "z": 11,
      "name": "Wood_Hardwood_Planks",
      "rotation": 7
    },
    {
      "x": -20,
      "y": 35,
      "z": 11,
      "name": "Wood_Hardwood_Planks",
      "rotation": 50
    },
    {
      "x": -20,
      "y": 19,
      "z": 12,
      "name": "Wood_Hardwood_Planks",
      "rotation": 16
    },
    {
      "x": -20,
      "y": 20,
      "z": 12,
      "name": "Wood_Hardwood_Planks",
      "rotation": 50
    },
    {
      "x": -20,
      "y": 21,
      "z": 12,
      "name": "Wood_Hardwood_Planks",
      "rotation": 16
    },
    {
      "x": -19,
      "y": 12,
      "z": -3,
      "name": "Rock_Ice"
    },
    {
      "x": -19,
      "y": 13,
      "z": -3,
      "name": "Rock_Ice"
    },
    {
      "x": -19,
      "y": 14,
      "z": -3,
      "name": "Rock_Ice"
    },
    {
      "x": -19,
      "y": 15,
      "z": -3,
      "name": "Fullmetal_Cyan_Crystal_Lamp"
    },
    {
      "x": -19,
      "y": 11,
      "z": -2,
      "name": "Cloth_Block_Wool_Gray_Light_Half",
      "rotation": 7
    },
    {
      "x": -19,
      "y": 12,
      "z": -2,
      "name": "Cloth_Block_Wool_Gray_Light_Half",
      "rotation": 7
    },
    {
      "x": -19,
      "y": 13,
      "z": -2,
      "name": "Cloth_Block_Wool_Gray_Light_Half",
      "rotation": 7
    },
    {
      "x": -19,
      "y": 14,
      "z": -2,
      "name": "Cloth_Block_Wool_Gray_Light_Half",
      "rotation": 7
    },
    {
      "x": -19,
      "y": 15,
      "z": -2,
      "name": "Cloth_Block_Wool_Gray_Light_Half",
      "rotation": 7
    },
    {
      "x": -19,
      "y": 16,
      "z": -2,
      "name": "Cloth_Block_Wool_Gray_Light_Half",
      "rotation": 7
    },
    {
      "x": -19,
      "y": 9,
      "z": -1,
      "name": "*Cloth_Block_Wool_Gray_Light_Half_State_Definitions_Block",
      "rotation": 7
    },
    {
      "x": -19,
      "y": 10,
      "z": -1,
      "name": "*Cloth_Block_Wool_Gray_Light_Half_State_Definitions_Block",
      "rotation": 7
    },
    {
      "x": -19,
      "y": 11,
      "z": -1,
      "name": "*Cloth_Block_Wool_Gray_Light_Half_State_Definitions_Block",
      "rotation": 7
    },
    {
      "x": -19,
      "y": 12,
      "z": -1,
      "name": "*Cloth_Block_Wool_Gray_Light_Half_State_Definitions_Block",
      "rotation": 7
    },
    {
      "x": -19,
      "y": 13,
      "z": -1,
      "name": "*Cloth_Block_Wool_Gray_Light_Half_State_Definitions_Block",
      "rotation": 7
    },
    {
      "x": -19,
      "y": 14,
      "z": -1,
      "name": "*Cloth_Block_Wool_Gray_Light_Half_State_Definitions_Block",
      "rotation": 7
    },
    {
      "x": -19,
      "y": 15,
      "z": -1,
      "name": "*Cloth_Block_Wool_Gray_Light_Half_State_Definitions_Block",
      "rotation": 7
    },
    {
      "x": -19,
      "y": 16,
      "z": -1,
      "name": "*Cloth_Block_Wool_Gray_Light_Half_State_Definitions_Block",
      "rotation": 7
    },
    {
      "x": -19,
      "y": 10,
      "z": 0,
      "name": "Cloth_Block_Wool_Gray_Light_Half",
      "rotation": 7
    },
    {
      "x": -19,
      "y": 11,
      "z": 0,
      "name": "Cloth_Block_Wool_Gray_Light_Half",
      "rotation": 7
    },
    {
      "x": -19,
      "y": 12,
      "z": 0,
      "name": "Cloth_Block_Wool_Gray_Light_Half",
      "rotation": 7
    },
    {
      "x": -19,
      "y": 13,
      "z": 0,
      "name": "Cloth_Block_Wool_Gray_Light_Half",
      "rotation": 7
    },
    {
      "x": -19,
      "y": 14,
      "z": 0,
      "name": "Cloth_Block_Wool_Gray_Light_Half",
      "rotation": 7
    },
    {
      "x": -19,
      "y": 15,
      "z": 0,
      "name": "Cloth_Block_Wool_Gray_Light_Half",
      "rotation": 7
    },
    {
      "x": -19,
      "y": 16,
      "z": 0,
      "name": "Cloth_Block_Wool_Gray_Light_Half",
      "rotation": 7
    },
    {
      "x": -19,
      "y": 17,
      "z": 0,
      "name": "Cloth_Block_Wool_Gray_Light_Half",
      "rotation": 7
    },
    {
      "x": -19,
      "y": 13,
      "z": 1,
      "name": "Cloth_Block_Wool_Gray_Light_Half",
      "rotation": 7
    },
    {
      "x": -19,
      "y": 14,
      "z": 1,
      "name": "Cloth_Block_Wool_Gray_Light_Half",
      "rotation": 7
    },
    {
      "x": -19,
      "y": 15,
      "z": 1,
      "name": "Cloth_Block_Wool_Gray_Light_Half",
      "rotation": 7
    },
    {
      "x": -19,
      "y": 16,
      "z": 1,
      "name": "Cloth_Block_Wool_Gray_Light_Half",
      "rotation": 7
    },
    {
      "x": -19,
      "y": 17,
      "z": 1,
      "name": "Cloth_Block_Wool_Gray_Light_Half",
      "rotation": 7
    },
    {
      "x": -19,
      "y": 10,
      "z": 2,
      "name": "*Cloth_Block_Wool_Gray_Light_Half_State_Definitions_Block",
      "rotation": 7
    },
    {
      "x": -19,
      "y": 11,
      "z": 2,
      "name": "*Cloth_Block_Wool_Gray_Light_Half_State_Definitions_Block",
      "rotation": 7
    },
    {
      "x": -19,
      "y": 12,
      "z": 2,
      "name": "*Cloth_Block_Wool_Gray_Light_Half_State_Definitions_Block",
      "rotation": 7
    },
    {
      "x": -19,
      "y": 13,
      "z": 2,
      "name": "*Cloth_Block_Wool_Gray_Light_Half_State_Definitions_Block",
      "rotation": 7
    },
    {
      "x": -19,
      "y": 14,
      "z": 2,
      "name": "*Cloth_Block_Wool_Gray_Light_Half_State_Definitions_Block",
      "rotation": 7
    },
    {
      "x": -19,
      "y": 15,
      "z": 2,
      "name": "*Cloth_Block_Wool_Gray_Light_Half_State_Definitions_Block",
      "rotation": 7
    },
    {
      "x": -19,
      "y": 16,
      "z": 2,
      "name": "*Cloth_Block_Wool_Gray_Light_Half_State_Definitions_Block",
      "rotation": 7
    },
    {
      "x": -19,
      "y": 17,
      "z": 2,
      "name": "*Cloth_Block_Wool_Gray_Light_Half_State_Definitions_Block",
      "rotation": 7
    },
    {
      "x": -19,
      "y": 11,
      "z": 3,
      "name": "Cloth_Block_Wool_Gray_Light_Half",
      "rotation": 7
    },
    {
      "x": -19,
      "y": 12,
      "z": 3,
      "name": "Cloth_Block_Wool_Gray_Light_Half",
      "rotation": 7
    },
    {
      "x": -19,
      "y": 13,
      "z": 3,
      "name": "Cloth_Block_Wool_Gray_Light_Half",
      "rotation": 7
    },
    {
      "x": -19,
      "y": 14,
      "z": 3,
      "name": "Cloth_Block_Wool_Gray_Light_Half",
      "rotation": 7
    },
    {
      "x": -19,
      "y": 15,
      "z": 3,
      "name": "Cloth_Block_Wool_Gray_Light_Half",
      "rotation": 7
    },
    {
      "x": -19,
      "y": 16,
      "z": 3,
      "name": "Cloth_Block_Wool_Gray_Light_Half",
      "rotation": 7
    },
    {
      "x": -19,
      "y": 17,
      "z": 3,
      "name": "Cloth_Block_Wool_Gray_Light_Half",
      "rotation": 7
    },
    {
      "x": -19,
      "y": 18,
      "z": 3,
      "name": "Cloth_Block_Wool_Gray_Light_Half",
      "rotation": 7
    },
    {
      "x": -19,
      "y": 17,
      "z": 4,
      "name": "Cloth_Block_Wool_Gray_Light_Half",
      "rotation": 7
    },
    {
      "x": -19,
      "y": 18,
      "z": 4,
      "name": "Cloth_Block_Wool_Gray_Light_Half",
      "rotation": 7
    },
    {
      "x": -19,
      "y": 14,
      "z": 5,
      "name": "Cloth_Block_Wool_Gray_Light_Half",
      "rotation": 7
    },
    {
      "x": -19,
      "y": 15,
      "z": 5,
      "name": "Cloth_Block_Wool_Gray_Light_Half",
      "rotation": 7
    },
    {
      "x": -19,
      "y": 16,
      "z": 5,
      "name": "Cloth_Block_Wool_Gray_Light_Half",
      "rotation": 7
    },
    {
      "x": -19,
      "y": 17,
      "z": 5,
      "name": "Cloth_Block_Wool_Gray_Light_Half",
      "rotation": 7
    },
    {
      "x": -19,
      "y": 18,
      "z": 5,
      "name": "Cloth_Block_Wool_Gray_Light_Half",
      "rotation": 7
    },
    {
      "x": -19,
      "y": 12,
      "z": 6,
      "name": "Cloth_Block_Wool_Gray_Light_Half",
      "rotation": 7
    },
    {
      "x": -19,
      "y": 13,
      "z": 6,
      "name": "Cloth_Block_Wool_Gray_Light_Half",
      "rotation": 7
    },
    {
      "x": -19,
      "y": 14,
      "z": 6,
      "name": "Cloth_Block_Wool_Gray_Light_Half",
      "rotation": 7
    },
    {
      "x": -19,
      "y": 15,
      "z": 6,
      "name": "Cloth_Block_Wool_Gray_Light_Half",
      "rotation": 7
    },
    {
      "x": -19,
      "y": 16,
      "z": 6,
      "name": "Cloth_Block_Wool_Gray_Light_Half",
      "rotation": 7
    },
    {
      "x": -19,
      "y": 17,
      "z": 6,
      "name": "Cloth_Block_Wool_Gray_Light_Half",
      "rotation": 7
    },
    {
      "x": -19,
      "y": 18,
      "z": 6,
      "name": "Cloth_Block_Wool_Gray_Light_Half",
      "rotation": 7
    },
    {
      "x": -19,
      "y": 19,
      "z": 6,
      "name": "Cloth_Block_Wool_Gray_Light_Half",
      "rotation": 7
    },
    {
      "x": -19,
      "y": 13,
      "z": 7,
      "name": "Cloth_Block_Wool_Gray_Light_Half",
      "rotation": 7
    },
    {
      "x": -19,
      "y": 14,
      "z": 7,
      "name": "Cloth_Block_Wool_Gray_Light_Half",
      "rotation": 7
    },
    {
      "x": -19,
      "y": 15,
      "z": 7,
      "name": "Cloth_Block_Wool_Gray_Light_Half",
      "rotation": 7
    },
    {
      "x": -19,
      "y": 16,
      "z": 7,
      "name": "Cloth_Block_Wool_Gray_Light_Half",
      "rotation": 7
    },
    {
      "x": -19,
      "y": 17,
      "z": 7,
      "name": "Cloth_Block_Wool_Gray_Light_Half",
      "rotation": 7
    },
    {
      "x": -19,
      "y": 18,
      "z": 7,
      "name": "Cloth_Block_Wool_Gray_Light_Half",
      "rotation": 7
    },
    {
      "x": -19,
      "y": 19,
      "z": 7,
      "name": "Cloth_Block_Wool_Gray_Light_Half",
      "rotation": 7
    },
    {
      "x": -19,
      "y": 12,
      "z": 8,
      "name": "Cloth_Block_Wool_Gray_Light_Half",
      "rotation": 7
    },
    {
      "x": -19,
      "y": 13,
      "z": 8,
      "name": "Cloth_Block_Wool_Gray_Light_Half",
      "rotation": 7
    },
    {
      "x": -19,
      "y": 14,
      "z": 8,
      "name": "Cloth_Block_Wool_Gray_Light_Half",
      "rotation": 7
    },
    {
      "x": -19,
      "y": 15,
      "z": 8,
      "name": "Cloth_Block_Wool_Gray_Light_Half",
      "rotation": 7
    },
    {
      "x": -19,
      "y": 16,
      "z": 8,
      "name": "Cloth_Block_Wool_Gray_Light_Half",
      "rotation": 7
    },
    {
      "x": -19,
      "y": 17,
      "z": 8,
      "name": "Cloth_Block_Wool_Gray_Light_Half",
      "rotation": 7
    },
    {
      "x": -19,
      "y": 18,
      "z": 8,
      "name": "Cloth_Block_Wool_Gray_Light_Half",
      "rotation": 7
    },
    {
      "x": -19,
      "y": 19,
      "z": 8,
      "name": "Cloth_Block_Wool_Gray_Light_Half",
      "rotation": 7
    },
    {
      "x": -19,
      "y": 20,
      "z": 8,
      "name": "Wood_Hardwood_Planks",
      "rotation": 50
    },
    {
      "x": -19,
      "y": 19,
      "z": 9,
      "name": "Wood_Hardwood_Planks",
      "rotation": 16
    },
    {
      "x": -19,
      "y": 20,
      "z": 9,
      "name": "Wood_Hardwood_Planks",
      "rotation": 16
    },
    {
      "x": -19,
      "y": 21,
      "z": 9,
      "name": "Wood_Hardwood_Planks",
      "rotation": 16
    },
    {
      "x": -19,
      "y": 22,
      "z": 9,
      "name": "Wood_Hardwood_Planks",
      "rotation": 16
    },
    {
      "x": -19,
      "y": 18,
      "z": 10,
      "name": "Wood_Hardwood_Planks",
      "rotation": 7
    },
    {
      "x": -19,
      "y": 19,
      "z": 10,
      "name": "Wood_Hardwood_Planks",
      "rotation": 16
    },
    {
      "x": -19,
      "y": 20,
      "z": 10,
      "name": "Wood_Hardwood_Planks",
      "rotation": 50
    },
    {
      "x": -19,
      "y": 21,
      "z": 10,
      "name": "Wood_Hardwood_Planks",
      "rotation": 16
    },
    {
      "x": -19,
      "y": 22,
      "z": 10,
      "name": "Wood_Hardwood_Planks",
      "rotation": 7
    },
    {
      "x": -19,
      "y": 35,
      "z": 10,
      "name": "Wood_Hardwood_Planks",
      "rotation": 50
    },
    {
      "x": -19,
      "y": 19,
      "z": 11,
      "name": "Wood_Hardwood_Planks",
      "rotation": 16
    },
    {
      "x": -19,
      "y": 20,
      "z": 11,
      "name": "Wood_Hardwood_Planks",
      "rotation": 16
    },
    {
      "x": -19,
      "y": 21,
      "z": 11,
      "name": "Wood_Hardwood_Planks",
      "rotation": 16
    },
    {
      "x": -19,
      "y": 22,
      "z": 11,
      "name": "Wood_Hardwood_Planks",
      "rotation": 16
    },
    {
      "x": -19,
      "y": 31,
      "z": 11,
      "name": "Wood_Hardwood_Planks",
      "rotation": 7
    },
    {
      "x": -19,
      "y": 32,
      "z": 11,
      "name": "Wood_Hardwood_Planks",
      "rotation": 50
    },
    {
      "x": -19,
      "y": 33,
      "z": 11,
      "name": "Wood_Hardwood_Planks",
      "rotation": 50
    },
    {
      "x": -19,
      "y": 14,
      "z": 12,
      "name": "Cloth_Block_Wool_Gray_Light_Half",
      "rotation": 7
    },
    {
      "x": -19,
      "y": 15,
      "z": 12,
      "name": "Cloth_Block_Wool_Gray_Light_Half",
      "rotation": 7
    },
    {
      "x": -19,
      "y": 16,
      "z": 12,
      "name": "Cloth_Block_Wool_Gray_Light_Half",
      "rotation": 7
    },
    {
      "x": -19,
      "y": 17,
      "z": 12,
      "name": "Cloth_Block_Wool_Gray_Light_Half",
      "rotation": 7
    },
    {
      "x": -19,
      "y": 18,
      "z": 12,
      "name": "Cloth_Block_Wool_Gray_Light_Half",
      "rotation": 7
    },
    {
      "x": -19,
      "y": 19,
      "z": 12,
      "name": "Cloth_Block_Wool_Gray_Light_Half",
      "rotation": 7
    },
    {
      "x": -19,
      "y": 20,
      "z": 12,
      "name": "Cloth_Block_Wool_Gray_Light_Half",
      "rotation": 7
    },
    {
      "x": -19,
      "y": 21,
      "z": 12,
      "name": "Cloth_Block_Wool_Gray_Light_Half",
      "rotation": 7
    },
    {
      "x": -19,
      "y": 16,
      "z": 13,
      "name": "Cloth_Block_Wool_Gray_Light_Half",
      "rotation": 7
    },
    {
      "x": -19,
      "y": 17,
      "z": 13,
      "name": "Cloth_Block_Wool_Gray_Light_Half",
      "rotation": 7
    },
    {
      "x": -19,
      "y": 18,
      "z": 13,
      "name": "Cloth_Block_Wool_Gray_Light_Half",
      "rotation": 7
    },
    {
      "x": -19,
      "y": 19,
      "z": 13,
      "name": "Cloth_Block_Wool_Gray_Light_Half",
      "rotation": 7
    },
    {
      "x": -19,
      "y": 20,
      "z": 13,
      "name": "Cloth_Block_Wool_Gray_Light_Half",
      "rotation": 7
    },
    {
      "x": -19,
      "y": 21,
      "z": 13,
      "name": "Cloth_Block_Wool_Gray_Light_Half",
      "rotation": 7
    },
    {
      "x": -19,
      "y": 14,
      "z": 14,
      "name": "Cloth_Block_Wool_Gray_Light_Half",
      "rotation": 7
    },
    {
      "x": -19,
      "y": 15,
      "z": 14,
      "name": "Cloth_Block_Wool_Gray_Light_Half",
      "rotation": 7
    },
    {
      "x": -19,
      "y": 16,
      "z": 14,
      "name": "Cloth_Block_Wool_Gray_Light_Half",
      "rotation": 7
    },
    {
      "x": -19,
      "y": 17,
      "z": 14,
      "name": "Cloth_Block_Wool_Gray_Light_Half",
      "rotation": 7
    },
    {
      "x": -19,
      "y": 18,
      "z": 14,
      "name": "Cloth_Block_Wool_Gray_Light_Half",
      "rotation": 7
    },
    {
      "x": -19,
      "y": 19,
      "z": 14,
      "name": "Cloth_Block_Wool_Gray_Light_Half",
      "rotation": 7
    },
    {
      "x": -19,
      "y": 20,
      "z": 14,
      "name": "Cloth_Block_Wool_Gray_Light_Half",
      "rotation": 7
    },
    {
      "x": -19,
      "y": 21,
      "z": 14,
      "name": "Cloth_Block_Wool_Gray_Light_Half",
      "rotation": 7
    },
    {
      "x": -18,
      "y": 15,
      "z": -8,
      "name": "Rock_Ice"
    },
    {
      "x": -18,
      "y": 16,
      "z": -8,
      "name": "Rock_Ice"
    },
    {
      "x": -18,
      "y": 17,
      "z": -8,
      "name": "Rock_Ice"
    },
    {
      "x": -18,
      "y": 13,
      "z": -7,
      "name": "Rock_Ice"
    },
    {
      "x": -18,
      "y": 14,
      "z": -7,
      "name": "Rock_Ice"
    },
    {
      "x": -18,
      "y": 15,
      "z": -7,
      "name": "Rock_Ice"
    },
    {
      "x": -18,
      "y": 16,
      "z": -7,
      "name": "Rock_Ice"
    },
    {
      "x": -18,
      "y": 17,
      "z": -7,
      "name": "Rock_Ice"
    },
    {
      "x": -18,
      "y": 18,
      "z": -7,
      "name": "Rock_Ice"
    },
    {
      "x": -18,
      "y": 19,
      "z": -7,
      "name": "Rock_Ice"
    },
    {
      "x": -18,
      "y": 12,
      "z": -6,
      "name": "Rock_Ice"
    },
    {
      "x": -18,
      "y": 13,
      "z": -6,
      "name": "Rock_Ice"
    },
    {
      "x": -18,
      "y": 14,
      "z": -6,
      "name": "Rock_Ice"
    },
    {
      "x": -18,
      "y": 15,
      "z": -6,
      "name": "Rock_Ice"
    },
    {
      "x": -18,
      "y": 16,
      "z": -6,
      "name": "Rock_Ice"
    },
    {
      "x": -18,
      "y": 17,
      "z": -6,
      "name": "Rock_Ice"
    },
    {
      "x": -18,
      "y": 18,
      "z": -6,
      "name": "Rock_Ice"
    },
    {
      "x": -18,
      "y": 19,
      "z": -6,
      "name": "Rock_Ice"
    },
    {
      "x": -18,
      "y": 20,
      "z": -6,
      "name": "Rock_Ice"
    },
    {
      "x": -18,
      "y": 13,
      "z": -5,
      "name": "Rock_Ice"
    },
    {
      "x": -18,
      "y": 14,
      "z": -5,
      "name": "Rock_Ice"
    },
    {
      "x": -18,
      "y": 15,
      "z": -5,
      "name": "Rock_Ice"
    },
    {
      "x": -18,
      "y": 16,
      "z": -5,
      "name": "Rock_Ice"
    },
    {
      "x": -18,
      "y": 17,
      "z": -5,
      "name": "Rock_Ice"
    },
    {
      "x": -18,
      "y": 18,
      "z": -5,
      "name": "Rock_Ice"
    },
    {
      "x": -18,
      "y": 19,
      "z": -5,
      "name": "Rock_Ice"
    },
    {
      "x": -18,
      "y": 9,
      "z": -4,
      "name": "Rock_Ice"
    },
    {
      "x": -18,
      "y": 10,
      "z": -4,
      "name": "Rock_Ice"
    },
    {
      "x": -18,
      "y": 11,
      "z": -4,
      "name": "Rock_Ice"
    },
    {
      "x": -18,
      "y": 12,
      "z": -4,
      "name": "Rock_Ice"
    },
    {
      "x": -18,
      "y": 13,
      "z": -4,
      "name": "Rock_Ice"
    },
    {
      "x": -18,
      "y": 14,
      "z": -4,
      "name": "Rock_Ice"
    },
    {
      "x": -18,
      "y": 15,
      "z": -4,
      "name": "Rock_Ice"
    },
    {
      "x": -18,
      "y": 16,
      "z": -4,
      "name": "Rock_Ice"
    },
    {
      "x": -18,
      "y": 17,
      "z": -4,
      "name": "Rock_Ice"
    },
    {
      "x": -18,
      "y": 7,
      "z": -3,
      "name": "Rock_Ice"
    },
    {
      "x": -18,
      "y": 8,
      "z": -3,
      "name": "Rock_Ice"
    },
    {
      "x": -18,
      "y": 9,
      "z": -3,
      "name": "Rock_Ice"
    },
    {
      "x": -18,
      "y": 10,
      "z": -3,
      "name": "Rock_Ice"
    },
    {
      "x": -18,
      "y": 11,
      "z": -3,
      "name": "Rock_Ice"
    },
