{
  "version": 8,
  "blockIdVersion": 11,
  "anchorX": 0,
  "anchorY": 0,
  "anchorZ": 0,
  "blocks": [
    {
      "x": -27,
      "y": 18,
      "z": -9,
      "name": "Wood_Hardwood_Planks",
      "rotation": 14
    },
    {
      "x": -27,
      "y": 19,
      "z": -9,
      "name": "Wood_Hardwood_Planks",
      "rotation": 14
    },
    {
      "x": -26,
      "y": 11,
      "z": -10,
      "name": "Wood_Hardwood_Planks",
      "rotation": 14
    },
    {
      "x": -26,
      "y": 18,
      "z": -9,
      "name": "Wood_Hardwood_Planks",
      "rotation": 14
    },
    {
      "x": -26,
      "y": 19,
      "z": -9,
      "name": "Wood_Hardwood_Planks",
      "rotation": 14
    },
    {
      "x": -26,
      "y": 7,
      "z": 1,
      "name": "Wood_Hardwood_Planks",
      "rotation": 14
    },
    {
      "x": -26,
      "y": 10,
      "z": 4,
      "name": "Wood_Hardwood_Planks",
      "rotation": 14
    },
    {
      "x": -25,
      "y": 11,
      "z": -10,
      "name": "Wood_Hardwood_Planks",
      "rotation": 14
    },
    {
      "x": -25,
      "y": 17,
      "z": -9,
      "name": "Wood_Hardwood_Planks",
      "rotation": 14
    },
    {
      "x": -25,
      "y": 18,
      "z": -9,
      "name": "Wood_Hardwood_Planks",
      "rotation": 14
    },
    {
      "x": -25,
      "y": 19,
      "z": -9,
      "name": "Wood_Hardwood_Planks",
      "rotation": 14
    },
    {
      "x": -25,
      "y": 19,
      "z": -8,
      "name": "Wood_Hardwood_Planks",
      "rotation": 14
    },
    {
      "x": -25,
      "y": 17,
      "z": -3,
      "name": "Wood_Hardwood_Planks",
      "rotation": 14
    },
    {
      "x": -25,
      "y": 18,
      "z": -2,
      "name": "Wood_Hardwood_Planks",
      "rotation": 14
    },
    {
      "x": -25,
      "y": 7,
      "z": 1,
      "name": "Wood_Hardwood_Planks",
      "rotation": 14
    },
    {
      "x": -25,
      "y": 9,
      "z": 4,
      "name": "Wood_Hardwood_Planks",
      "rotation": 14
    },
    {
      "x": -25,
      "y": 10,
      "z": 4,
      "name": "Wood_Hardwood_Planks",
      "rotation": 14
    },
    {
      "x": -25,
      "y": 9,
      "z": 5,
      "name": "Wood_Hardwood_Planks",
      "rotation": 14
    },
    {
      "x": -24,
      "y": 9,
      "z": -10,
      "name": "Wood_Hardwood_Planks",
      "rotation": 14
    },
    {
      "x": -24,
      "y": 10,
      "z": -10,
      "name": "Wood_Hardwood_Planks"
    },
    {
      "x": -24,
      "y": 11,
      "z": -10,
      "name": "Wood_Hardwood_Planks",
      "rotation": 14
    },
    {
      "x": -24,
      "y": 12,
      "z": -10,
      "name": "Wood_Sticks",
      "support": 15
    },
    {
      "x": -24,
      "y": 8,
      "z": -9,
      "name": "Wood_Hardwood_Planks",
      "rotation": 14
    },
    {
      "x": -24,
      "y": 9,
      "z": -9,
      "name": "Wood_Hardwood_Planks",
      "rotation": 14
    },
    {
      "x": -24,
      "y": 17,
      "z": -9,
      "name": "Wood_Hardwood_Planks",
      "rotation": 14
    },
    {
      "x": -24,
      "y": 18,
      "z": -9,
      "name": "Wood_Hardwood_Planks",
      "rotation": 14
    },
    {
      "x": -24,
      "y": 19,
      "z": -9,
      "name": "Wood_Hardwood_Planks",
      "rotation": 14
    },
    {
      "x": -24,
      "y": 6,
      "z": -8,
      "name": "Wood_Hardwood_Planks",
      "rotation": 14
    },
    {
      "x": -24,
      "y": 7,
      "z": -8,
      "name": "Wood_Hardwood_Planks",
      "rotation": 14
    },
    {
      "x": -24,
      "y": 8,
      "z": -8,
      "name": "Wood_Hardwood_Planks",
      "rotation": 14
    },
    {
      "x": -24,
      "y": 16,
      "z": -8,
      "name": "Wood_Hardwood_Planks",
      "rotation": 14
    },
    {
      "x": -24,
      "y": 19,
      "z": -8,
      "name": "Wood_Hardwood_Planks",
      "rotation": 4
    },
    {
      "x": -24,
      "y": 20,
      "z": -8,
      "name": "Wood_Hardwood_Planks",
      "rotation": 14
    },
    {
      "x": -24,
      "y": 6,
      "z": -7,
      "name": "Wood_Hardwood_Planks",
      "rotation": 14
    },
    {
      "x": -24,
      "y": 7,
      "z": -7,
      "name": "Wood_Hardwood_Planks",
      "rotation": 14
    },
    {
      "x": -24,
      "y": 15,
      "z": -7,
      "name": "Wood_Hardwood_Planks",
      "rotation": 14
    },
    {
      "x": -24,
      "y": 5,
      "z": -6,
      "name": "Wood_Hardwood_Planks",
      "rotation": 14
    },
    {
      "x": -24,
      "y": 6,
      "z": -6,
      "name": "Wood_Hardwood_Planks",
      "rotation": 14
    },
    {
      "x": -24,
      "y": 19,
      "z": -6,
      "name": "Wood_Hardwood_Planks",
      "rotation": 14
    },
    {
      "x": -24,
      "y": 20,
      "z": -6,
      "name": "Wood_Hardwood_Planks",
      "rotation": 14
    },
    {
      "x": -24,
      "y": 5,
      "z": -5,
      "name": "Wood_Hardwood_Planks",
      "rotation": 14
    },
    {
      "x": -24,
      "y": 18,
      "z": -5,
      "name": "Wood_Hardwood_Planks",
      "rotation": 14
    },
    {
      "x": -24,
      "y": 19,
      "z": -5,
      "name": "Wood_Hardwood_Planks",
      "rotation": 14
    },
    {
      "x": -24,
      "y": 5,
      "z": -4,
      "name": "Wood_Hardwood_Planks",
      "rotation": 14
    },
    {
      "x": -24,
      "y": 6,
      "z": -4,
      "name": "Wood_Sticks",
      "support": 15
    },
    {
      "x": -24,
      "y": 17,
      "z": -4,
      "name": "Wood_Hardwood_Planks",
      "rotation": 14
    },
    {
      "x": -24,
      "y": 18,
      "z": -4,
      "name": "Wood_Hardwood_Planks",
      "rotation": 14
    },
    {
      "x": -24,
      "y": 4,
      "z": -3,
      "name": "Wood_Hardwood_Planks",
      "rotation": 14
    },
    {
      "x": -24,
      "y": 11,
      "z": -3,
      "name": "Wood_Hardwood_Planks",
      "rotation": 14
    },
    {
      "x": -24,
      "y": 17,
      "z": -3,
      "name": "Wood_Hardwood_Planks",
      "rotation": 14
    },
    {
      "x": -24,
      "y": 21,
      "z": -3,
      "name": "Wood_Hardwood_Planks",
      "rotation": 14
    },
    {
      "x": -24,
      "y": 17,
      "z": -2,
      "name": "Wood_Hardwood_Planks",
      "rotation": 14
    },
    {
      "x": -24,
      "y": 18,
      "z": -2,
      "name": "Wood_Hardwood_Planks",
      "rotation": 4
    },
    {
      "x": -24,
      "y": 20,
      "z": -2,
      "name": "Wood_Deadwood_Planks",
      "rotation": 14
    },
    {
      "x": -24,
      "y": 4,
      "z": -1,
      "name": "Wood_Hardwood_Planks",
      "rotation": 14
    },
    {
      "x": -24,
      "y": 16,
      "z": -1,
      "name": "Wood_Hardwood_Planks",
      "rotation": 14
    },
    {
      "x": -24,
      "y": 17,
      "z": -1,
      "name": "Wood_Hardwood_Planks",
      "rotation": 14
    },
    {
      "x": -24,
      "y": 18,
      "z": -1,
      "name": "Wood_Hardwood_Planks",
      "rotation": 14
    },
    {
      "x": -24,
      "y": 19,
      "z": -1,
      "name": "Wood_Hardwood_Planks",
      "rotation": 4
    },
    {
      "x": -24,
      "y": 4,
      "z": 0,
      "name": "Wood_Hardwood_Planks",
      "rotation": 14
    },
    {
      "x": -24,
      "y": 8,
      "z": 0,
      "name": "Wood_Hardwood_Planks",
      "rotation": 14
    },
    {
      "x": -24,
      "y": 17,
      "z": 0,
      "name": "Wood_Hardwood_Planks",
      "rotation": 14
    },
    {
      "x": -24,
      "y": 18,
      "z": 0,
      "name": "Wood_Hardwood_Planks",
      "rotation": 14
    },
    {
      "x": -24,
      "y": 7,
      "z": 1,
      "name": "Wood_Hardwood_Planks",
      "rotation": 14
    },
    {
      "x": -24,
      "y": 5,
      "z": 2,
      "name": "Wood_Hardwood_Planks",
      "rotation": 14
    },
    {
      "x": -24,
      "y": 6,
      "z": 2,
      "name": "Wood_Hardwood_Planks",
      "rotation": 14
    },
    {
      "x": -24,
      "y": 11,
      "z": 2,
      "name": "Wood_Hardwood_Planks",
      "rotation": 14
    },
    {
      "x": -24,
      "y": 13,
      "z": 2,
      "name": "Wood_Hardwood_Planks",
      "rotation": 14
    },
    {
      "x": -24,
      "y": 10,
      "z": 3,
      "name": "Wood_Hardwood_Planks",
      "rotation": 14
    },
    {
      "x": -24,
      "y": 11,
      "z": 3,
      "name": "Wood_Hardwood_Planks",
      "rotation": 14
    },
    {
      "x": -24,
      "y": 12,
      "z": 3,
      "name": "Wood_Hardwood_Planks",
      "rotation": 4
    },
    {
      "x": -24,
      "y": 13,
      "z": 3,
      "name": "Wood_Hardwood_Planks",
      "rotation": 14
    },
    {
      "x": -24,
      "y": 14,
      "z": 3,
      "name": "Wood_Hardwood_Planks",
      "rotation": 14
    },
    {
      "x": -24,
      "y": 6,
      "z": 4,
      "name": "Wood_Hardwood_Planks",
      "rotation": 14
    },
    {
      "x": -24,
      "y": 9,
      "z": 4,
      "name": "Wood_Hardwood_Planks",
      "rotation": 14
    },
    {
      "x": -24,
      "y": 10,
      "z": 4,
      "name": "Wood_Hardwood_Planks",
      "rotation": 14
    },
    {
      "x": -24,
      "y": 13,
      "z": 4,
      "name": "Wood_Hardwood_Planks",
      "rotation": 4
    },
    {
      "x": -24,
      "y": 14,
      "z": 4,
      "name": "Wood_Hardwood_Planks",
      "rotation": 14
    },
    {
      "x": -24,
      "y": 7,
      "z": 5,
      "name": "Wood_Hardwood_Planks",
      "rotation": 14
    },
    {
      "x": -24,
      "y": 8,
      "z": 5,
      "name": "Wood_Hardwood_Planks",
      "rotation": 14
    },
    {
      "x": -24,
      "y": 9,
      "z": 5,
      "name": "Wood_Hardwood_Planks",
      "rotation": 14
    },
    {
      "x": -24,
      "y": 13,
      "z": 5,
      "name": "Wood_Deadwood_Planks",
      "rotation": 14
    },
    {
      "x": -24,
      "y": 14,
      "z": 5,
      "name": "Wood_Deadwood_Planks",
      "rotation": 14
    },
    {
      "x": -24,
      "y": 12,
      "z": 6,
      "name": "Wood_Deadwood_Planks",
      "rotation": 14
    },
    {
      "x": -23,
      "y": 9,
      "z": -10,
      "name": "Wood_Hardwood_Planks",
      "rotation": 14
    },
    {
      "x": -23,
      "y": 10,
      "z": -10,
      "name": "Wood_Hardwood_Planks"
    },
    {
      "x": -23,
      "y": 11,
      "z": -10,
      "name": "Wood_Hardwood_Planks",
      "rotation": 14
    },
    {
      "x": -23,
      "y": 8,
      "z": -9,
      "name": "Wood_Hardwood_Planks",
      "rotation": 14
    },
    {
      "x": -23,
      "y": 9,
      "z": -9,
      "name": "Wood_Hardwood_Planks",
      "rotation": 14
    },
    {
      "x": -23,
      "y": 10,
      "z": -9,
      "name": "Wood_Hardwood_Planks",
      "rotation": 4
    },
    {
      "x": -23,
      "y": 17,
      "z": -9,
      "name": "Wood_Hardwood_Planks",
      "rotation": 14
    },
    {
      "x": -23,
      "y": 18,
      "z": -9,
      "name": "Wood_Hardwood_Planks",
      "rotation": 14
    },
    {
      "x": -23,
      "y": 19,
      "z": -9,
      "name": "Wood_Hardwood_Planks",
      "rotation": 14
    },
    {
      "x": -23,
      "y": 6,
      "z": -8,
      "name": "Wood_Hardwood_Planks",
      "rotation": 14
    },
    {
      "x": -23,
      "y": 7,
      "z": -8,
      "name": "Wood_Hardwood_Planks",
      "rotation": 14
    },
    {
      "x": -23,
      "y": 8,
      "z": -8,
      "name": "Wood_Hardwood_Planks",
      "rotation": 14
    },
    {
      "x": -23,
      "y": 16,
      "z": -8,
      "name": "Wood_Hardwood_Planks",
      "rotation": 14
    },
    {
      "x": -23,
      "y": 19,
      "z": -8,
      "name": "Wood_Hardwood_Planks",
      "rotation": 14
    },
    {
      "x": -23,
      "y": 20,
      "z": -8,
      "name": "Wood_Hardwood_Planks",
      "rotation": 14
    },
    {
      "x": -23,
      "y": 6,
      "z": -7,
      "name": "Wood_Hardwood_Planks",
      "rotation": 14
    },
    {
      "x": -23,
      "y": 7,
      "z": -7,
      "name": "Wood_Hardwood_Planks",
      "rotation": 14
    },
    {
      "x": -23,
      "y": 15,
      "z": -7,
      "name": "Wood_Hardwood_Planks",
      "rotation": 14
    },
    {
      "x": -23,
      "y": 20,
      "z": -7,
      "name": "Wood_Hardwood_Decorative",
      "rotation": 14
    },
    {
      "x": -23,
      "y": 21,
      "z": -7,
      "name": "Wood_Hardwood_Decorative",
      "rotation": 14
    },
    {
      "x": -23,
      "y": 5,
      "z": -6,
      "name": "Wood_Hardwood_Planks",
      "rotation": 14
    },
    {
      "x": -23,
      "y": 6,
      "z": -6,
      "name": "Wood_Hardwood_Planks",
      "rotation": 14
    },
    {
      "x": -23,
      "y": 19,
      "z": -6,
      "name": "Wood_Hardwood_Planks",
      "rotation": 14
    },
    {
      "x": -23,
      "y": 20,
      "z": -6,
      "name": "Wood_Hardwood_Planks",
      "rotation": 14
    },
    {
      "x": -23,
      "y": 5,
      "z": -5,
      "name": "Wood_Hardwood_Planks",
      "rotation": 14
    },
    {
      "x": -23,
      "y": 6,
      "z": -5,
      "name": "Wood_Hardwood_Planks",
      "rotation": 14
    },
    {
      "x": -23,
      "y": 18,
      "z": -5,
      "name": "Wood_Hardwood_Planks",
      "rotation": 14
    },
    {
      "x": -23,
      "y": 19,
      "z": -5,
      "name": "Wood_Hardwood_Planks",
      "rotation": 14
    },
    {
      "x": -23,
      "y": 20,
      "z": -5,
      "name": "Wood_Hardwood_Planks",
      "rotation": 14
    },
    {
      "x": -23,
      "y": 5,
      "z": -4,
      "name": "Wood_Hardwood_Planks",
      "rotation": 14
    },
    {
      "x": -23,
      "y": 12,
      "z": -4,
      "name": "Wood_Hardwood_Planks",
      "rotation": 14
    },
    {
      "x": -23,
      "y": 19,
      "z": -4,
      "name": "Wood_Hardwood_Planks",
      "rotation": 4
    },
    {
      "x": -23,
      "y": 20,
      "z": -4,
      "name": "Wood_Hardwood_Planks",
      "rotation": 14
    },
    {
      "x": -23,
      "y": 21,
      "z": -4,
      "name": "Wood_Hardwood_Planks",
      "rotation": 14
    },
    {
      "x": -23,
      "y": 22,
      "z": -4,
      "name": "Wood_Hardwood_Planks",
      "rotation": 17
    },
    {
      "x": -23,
      "y": 4,
      "z": -3,
      "name": "Wood_Hardwood_Planks",
      "rotation": 14
    },
    {
      "x": -23,
      "y": 11,
      "z": -3,
      "name": "Wood_Hardwood_Planks",
      "rotation": 14
    },
    {
      "x": -23,
      "y": 18,
      "z": -3,
      "name": "Wood_Hardwood_Planks",
      "rotation": 14
    },
    {
      "x": -23,
      "y": 19,
      "z": -3,
      "name": "Wood_Hardwood_Planks",
      "rotation": 14
    },
    {
      "x": -23,
      "y": 20,
      "z": -3,
      "name": "Wood_Hardwood_Planks",
      "rotation": 4
    },
    {
      "x": -23,
      "y": 21,
      "z": -3,
      "name": "Wood_Hardwood_Planks",
      "rotation": 17
    },
    {
      "x": -23,
      "y": 17,
      "z": -2,
      "name": "Wood_Hardwood_Planks",
      "rotation": 14
    },
    {
      "x": -23,
      "y": 19,
      "z": -2,
      "name": "Wood_Hardwood_Planks",
      "rotation": 14
    },
    {
      "x": -23,
      "y": 20,
      "z": -2,
      "name": "Wood_Hardwood_Planks",
      "rotation": 14
    },
    {
      "x": -23,
      "y": 21,
      "z": -2,
      "name": "Wood_Deadwood_Planks",
      "rotation": 14
    },
    {
      "x": -23,
      "y": 4,
      "z": -1,
      "name": "Wood_Hardwood_Planks",
      "rotation": 14
    },
    {
      "x": -23,
      "y": 9,
      "z": -1,
      "name": "Wood_Hardwood_Planks",
      "rotation": 14
    },
    {
      "x": -23,
      "y": 16,
      "z": -1,
      "name": "Wood_Hardwood_Planks",
      "rotation": 14
    },
    {
      "x": -23,
      "y": 4,
      "z": 0,
      "name": "Wood_Hardwood_Planks",
      "rotation": 14
    },
    {
      "x": -23,
      "y": 5,
      "z": 0,
      "name": "Furniture_Ancient_Barrel"
    },
    {
      "x": -23,
      "y": 8,
      "z": 0,
      "name": "Wood_Hardwood_Planks",
      "rotation": 14
    },
    {
      "x": -23,
      "y": 7,
      "z": 1,
      "name": "Wood_Hardwood_Planks",
      "rotation": 14
    },
    {
      "x": -23,
      "y": 5,
      "z": 2,
      "name": "Wood_Hardwood_Planks",
      "rotation": 14
    },
    {
      "x": -23,
      "y": 6,
      "z": 2,
      "name": "Wood_Hardwood_Planks",
      "rotation": 14
    },
    {
      "x": -23,
      "y": 13,
      "z": 2,
      "name": "Wood_Hardwood_Planks",
      "rotation": 14
    },
    {
      "x": -23,
      "y": 12,
      "z": 3,
      "name": "Wood_Hardwood_Planks",
      "rotation": 14
    },
    {
      "x": -23,
      "y": 6,
      "z": 4,
      "name": "Wood_Hardwood_Planks",
      "rotation": 14
    },
    {
      "x": -23,
      "y": 9,
      "z": 4,
      "name": "Wood_Hardwood_Planks",
      "rotation": 14
    },
    {
      "x": -23,
      "y": 10,
      "z": 4,
      "name": "Wood_Hardwood_Planks",
      "rotation": 14
    },
    {
      "x": -23,
      "y": 11,
      "z": 4,
      "name": "Wood_Hardwood_Planks",
      "rotation": 14
    },
    {
      "x": -23,
      "y": 12,
      "z": 4,
      "name": "Wood_Hardwood_Planks",
      "rotation": 14
    },
    {
      "x": -23,
      "y": 7,
      "z": 5,
      "name": "Wood_Hardwood_Planks",
      "rotation": 14
    },
    {
      "x": -23,
      "y": 8,
      "z": 5,
      "name": "Wood_Hardwood_Planks",
      "rotation": 14
    },
    {
      "x": -23,
      "y": 9,
      "z": 5,
      "name": "Wood_Hardwood_Planks",
      "rotation": 14
    },
    {
      "x": -23,
      "y": 10,
      "z": 5,
      "name": "Wood_Hardwood_Planks",
      "rotation": 14
    },
    {
      "x": -23,
      "y": 11,
      "z": 5,
      "name": "Wood_Hardwood_Planks",
      "rotation": 4
    },
    {
      "x": -23,
      "y": 12,
      "z": 5,
      "name": "Wood_Hardwood_Planks",
      "rotation": 14
    },
    {
      "x": -23,
      "y": 13,
      "z": 5,
      "name": "Wood_Hardwood_Planks",
      "rotation": 14
    },
    {
      "x": -23,
      "y": 8,
      "z": 6,
      "name": "Wood_Hardwood_Decorative",
      "rotation": 14
    },
    {
      "x": -23,
      "y": 9,
      "z": 6,
      "name": "Wood_Hardwood_Planks",
      "rotation": 14
    },
    {
      "x": -23,
      "y": 10,
      "z": 6,
      "name": "Wood_Hardwood_Planks",
      "rotation": 14
    },
    {
      "x": -23,
      "y": 11,
      "z": 6,
      "name": "Wood_Hardwood_Planks",
      "rotation": 14
    },
    {
      "x": -23,
      "y": 12,
      "z": 6,
      "name": "Wood_Hardwood_Planks",
      "rotation": 4
    },
    {
      "x": -22,
      "y": 9,
      "z": -10,
      "name": "Wood_Hardwood_Planks",
      "rotation": 14
    },
    {
      "x": -22,
      "y": 10,
      "z": -10,
      "name": "Wood_Hardwood_Planks"
    },
    {
      "x": -22,
      "y": 11,
      "z": -10,
      "name": "Wood_Hardwood_Planks",
      "rotation": 14
    },
    {
      "x": -22,
      "y": 12,
      "z": -10,
      "name": "Wood_Sticks",
      "support": 15
    },
    {
      "x": -22,
      "y": 16,
      "z": -10,
      "name": "Wood_Hardwood_Planks",
      "rotation": 14
    },
    {
      "x": -22,
      "y": 18,
      "z": -10,
      "name": "Wood_Hardwood_Planks",
      "rotation": 14
    },
    {
      "x": -22,
      "y": 8,
      "z": -9,
      "name": "Wood_Hardwood_Planks",
      "rotation": 14
    },
    {
      "x": -22,
      "y": 9,
      "z": -9,
      "name": "Wood_Hardwood_Planks",
      "rotation": 14
    },
    {
      "x": -22,
      "y": 10,
      "z": -9,
      "name": "Wood_Hardwood_Planks",
      "rotation": 4
    },
    {
      "x": -22,
      "y": 17,
      "z": -9,
      "name": "Wood_Hardwood_Planks",
      "rotation": 14
    },
    {
      "x": -22,
      "y": 18,
      "z": -9,
      "name": "Wood_Hardwood_Planks",
      "rotation": 14
    },
    {
      "x": -22,
      "y": 19,
      "z": -9,
      "name": "Wood_Hardwood_Planks",
      "rotation": 14
    },
    {
      "x": -22,
      "y": 6,
      "z": -8,
      "name": "Wood_Hardwood_Planks",
      "rotation": 14
    },
    {
      "x": -22,
      "y": 7,
      "z": -8,
      "name": "Wood_Hardwood_Planks",
      "rotation": 14
    },
    {
      "x": -22,
      "y": 8,
      "z": -8,
      "name": "Wood_Hardwood_Planks",
      "rotation": 14
    },
    {
      "x": -22,
      "y": 9,
      "z": -8,
      "name": "Wood_Sticks",
      "support": 15
    },
    {
      "x": -22,
      "y": 16,
      "z": -8,
      "name": "Wood_Hardwood_Planks",
      "rotation": 14
    },
    {
      "x": -22,
      "y": 19,
      "z": -8,
      "name": "Wood_Hardwood_Planks",
      "rotation": 4
    },
    {
      "x": -22,
      "y": 20,
      "z": -8,
      "name": "Wood_Hardwood_Planks",
      "rotation": 14
    },
    {
      "x": -22,
      "y": 6,
      "z": -7,
      "name": "Wood_Hardwood_Planks",
      "rotation": 14
    },
    {
      "x": -22,
      "y": 7,
      "z": -7,
      "name": "Wood_Hardwood_Planks",
      "rotation": 14
    },
    {
      "x": -22,
      "y": 15,
      "z": -7,
      "name": "Wood_Hardwood_Planks",
      "rotation": 14
    },
    {
      "x": -22,
      "y": 20,
      "z": -7,
      "name": "Wood_Hardwood_Decorative",
      "rotation": 14
    },
    {
      "x": -22,
      "y": 21,
      "z": -7,
      "name": "Wood_Hardwood_Decorative",
      "rotation": 14
    },
    {
      "x": -22,
      "y": 5,
      "z": -6,
      "name": "Wood_Hardwood_Planks",
      "rotation": 14
    },
    {
      "x": -22,
      "y": 6,
      "z": -6,
      "name": "Wood_Hardwood_Planks",
      "rotation": 14
    },
    {
      "x": -22,
      "y": 14,
      "z": -6,
      "name": "Wood_Hardwood_Planks",
      "rotation": 14
    },
    {
      "x": -22,
      "y": 21,
      "z": -6,
      "name": "Wood_Hardwood_Planks",
      "rotation": 14
    },
    {
      "x": -22,
      "y": 5,
      "z": -5,
      "name": "Wood_Hardwood_Planks",
      "rotation": 14
    },
    {
      "x": -22,
      "y": 6,
      "z": -5,
      "name": "Wood_Hardwood_Planks",
      "rotation": 14
    },
    {
      "x": -22,
      "y": 13,
      "z": -5,
      "name": "Wood_Hardwood_Planks",
      "rotation": 14
    },
    {
      "x": -22,
      "y": 20,
      "z": -5,
      "name": "Wood_Hardwood_Planks",
      "rotation": 14
    },
    {
      "x": -22,
      "y": 5,
      "z": -4,
      "name": "Wood_Hardwood_Planks",
      "rotation": 14
    },
    {
      "x": -22,
      "y": 12,
      "z": -4,
      "name": "Wood_Hardwood_Planks",
      "rotation": 14
    },
    {
      "x": -22,
      "y": 19,
      "z": -4,
      "name": "Wood_Hardwood_Planks",
      "rotation": 14
    },
    {
      "x": -22,
      "y": 20,
      "z": -4,
      "name": "Wood_Hardwood_Planks",
      "rotation": 14
    },
    {
      "x": -22,
      "y": 21,
      "z": -4,
      "name": "Wood_Hardwood_Planks",
      "rotation": 14
    },
    {
      "x": -22,
      "y": 4,
      "z": -3,
      "name": "Wood_Hardwood_Planks",
      "rotation": 14
    },
    {
      "x": -22,
      "y": 5,
      "z": -3,
      "name": "Wood_Sticks",
      "support": 15
    },
    {
      "x": -22,
      "y": 11,
      "z": -3,
      "name": "Wood_Hardwood_Planks",
      "rotation": 14
    },
    {
      "x": -22,
      "y": 18,
      "z": -3,
      "name": "Wood_Hardwood_Planks",
      "rotation": 14
    },
    {
      "x": -22,
      "y": 20,
      "z": -3,
      "name": "Wood_Hardwood_Planks",
      "rotation": 4
    },
    {
      "x": -22,
      "y": 4,
      "z": -2,
      "name": "Wood_Hardwood_Planks",
      "rotation": 14
    },
    {
      "x": -22,
      "y": 17,
      "z": -2,
      "name": "Wood_Hardwood_Planks",
      "rotation": 14
    },
    {
      "x": -22,
      "y": 4,
      "z": -1,
      "name": "Wood_Hardwood_Planks",
      "rotation": 14
    },
    {
      "x": -22,
      "y": 9,
      "z": -1,
      "name": "Wood_Hardwood_Planks",
      "rotation": 14
    },
    {
      "x": -22,
      "y": 16,
      "z": -1,
      "name": "Wood_Hardwood_Planks",
      "rotation": 14
    },
    {
      "x": -22,
      "y": 4,
      "z": 0,
      "name": "Wood_Hardwood_Planks",
      "rotation": 14
    },
    {
      "x": -22,
      "y": 8,
      "z": 0,
      "name": "Wood_Hardwood_Planks",
      "rotation": 14
    },
    {
      "x": -22,
      "y": 4,
      "z": 1,
      "name": "Wood_Hardwood_Planks",
      "rotation": 14
    },
    {
      "x": -22,
      "y": 7,
      "z": 1,
      "name": "Wood_Hardwood_Planks",
      "rotation": 14
    },
    {
      "x": -22,
      "y": 8,
      "z": 1,
      "name": "Wood_Sticks",
      "support": 15
    },
    {
      "x": -22,
      "y": 5,
      "z": 2,
      "name": "Wood_Hardwood_Planks",
      "rotation": 14
    },
    {
      "x": -22,
      "y": 6,
      "z": 2,
      "name": "Wood_Hardwood_Planks",
      "rotation": 14
    },
    {
      "x": -22,
      "y": 13,
      "z": 2,
      "name": "Wood_Hardwood_Planks",
      "rotation": 14
    },
    {
      "x": -22,
      "y": 5,
      "z": 3,
      "name": "Wood_Hardwood_Planks",
      "rotation": 14
    },
    {
      "x": -22,
      "y": 6,
      "z": 3,
      "name": "Furniture_Ancient_Crate",
      "rotation": 1
    },
    {
      "x": -22,
      "y": 12,
      "z": 3,
      "name": "Wood_Hardwood_Planks",
      "rotation": 14
    },
    {
      "x": -22,
      "y": 6,
      "z": 4,
      "name": "Wood_Hardwood_Planks",
      "rotation": 14
    },
    {
      "x": -22,
      "y": 11,
      "z": 4,
      "name": "Wood_Hardwood_Planks",
      "rotation": 14
    },
    {
      "x": -22,
      "y": 7,
      "z": 5,
      "name": "Wood_Hardwood_Planks",
      "rotation": 14
    },
    {
      "x": -22,
      "y": 10,
      "z": 5,
      "name": "Wood_Hardwood_Planks",
      "rotation": 14
    },
    {
      "x": -22,
      "y": 11,
      "z": 5,
      "name": "Wood_Hardwood_Planks",
      "rotation": 4
    },
    {
      "x": -22,
      "y": 8,
      "z": 6,
      "name": "Wood_Hardwood_Decorative",
      "rotation": 14
    },
    {
      "x": -22,
      "y": 9,
      "z": 6,
      "name": "Wood_Hardwood_Planks",
      "rotation": 14
    },
    {
      "x": -22,
      "y": 10,
      "z": 6,
      "name": "Wood_Hardwood_Planks",
      "rotation": 14
    },
    {
      "x": -22,
      "y": 11,
      "z": 6,
      "name": "Wood_Hardwood_Planks",
      "rotation": 14
    },
    {
      "x": -22,
      "y": 12,
      "z": 6,
      "name": "Wood_Deadwood_Planks",
      "rotation": 14
    },
    {
      "x": -22,
      "y": 10,
      "z": 7,
      "name": "Wood_Hardwood_Planks",
      "rotation": 14
    },
    {
      "x": -21,
      "y": 14,
      "z": -11,
      "name": "Wood_Hardwood_Planks",
      "rotation": 14
    },
    {
      "x": -21,
      "y": 9,
      "z": -10,
      "name": "Wood_Hardwood_Planks",
      "rotation": 14
    },
    {
      "x": -21,
      "y": 10,
      "z": -10,
      "name": "Wood_Hardwood_Planks"
    },
    {
      "x": -21,
      "y": 11,
      "z": -10,
      "name": "Wood_Hardwood_Planks",
      "rotation": 14
    },
    {
      "x": -21,
      "y": 12,
      "z": -10,
      "name": "Wood_Hardwood_Planks"
    },
    {
      "x": -21,
      "y": 14,
      "z": -10,
      "name": "Wood_Hardwood_Planks",
      "rotation": 14
    },
    {
      "x": -21,
      "y": 16,
      "z": -10,
      "name": "Wood_Hardwood_Planks",
      "rotation": 14
    },
    {
      "x": -21,
      "y": 18,
      "z": -10,
      "name": "Wood_Hardwood_Planks",
      "rotation": 14
    },
    {
      "x": -21,
      "y": 8,
      "z": -9,
      "name": "Wood_Hardwood_Planks",
      "rotation": 14
    },
    {
      "x": -21,
      "y": 9,
      "z": -9,
      "name": "Wood_Hardwood_Planks",
      "rotation": 14
    },
    {
      "x": -21,
      "y": 10,
      "z": -9,
      "name": "Wood_Hardwood_Planks",
      "rotation": 4
    },
    {
      "x": -21,
      "y": 17,
      "z": -9,
      "name": "Wood_Hardwood_Planks",
      "rotation": 14
    },
    {
      "x": -21,
      "y": 18,
      "z": -9,
      "name": "Wood_Hardwood_Ornate",
      "rotation": 14
    },
    {
      "x": -21,
      "y": 19,
      "z": -9,
      "name": "Wood_Hardwood_Ornate",
      "rotation": 14
    },
    {
      "x": -21,
      "y": 6,
      "z": -8,
      "name": "Wood_Hardwood_Planks",
      "rotation": 14
    },
    {
      "x": -21,
      "y": 7,
      "z": -8,
      "name": "Wood_Hardwood_Planks",
      "rotation": 14
    },
    {
      "x": -21,
      "y": 8,
      "z": -8,
      "name": "Wood_Hardwood_Planks",
      "rotation": 14
    },
    {
      "x": -21,
      "y": 16,
      "z": -8,
      "name": "Wood_Hardwood_Planks",
      "rotation": 14
    },
    {
      "x": -21,
      "y": 19,
      "z": -8,
      "name": "Wood_Hardwood_Planks",
      "rotation": 6
    },
    {
      "x": -21,
      "y": 20,
      "z": -8,
      "name": "Wood_Hardwood_Planks",
      "rotation": 14
    },
    {
      "x": -21,
      "y": 6,
      "z": -7,
      "name": "Wood_Hardwood_Planks",
      "rotation": 14
    },
    {
      "x": -21,
      "y": 7,
      "z": -7,
      "name": "Wood_Hardwood_Planks",
      "rotation": 14
    },
    {
      "x": -21,
      "y": 15,
      "z": -7,
      "name": "Wood_Hardwood_Planks",
      "rotation": 14
    },
    {
      "x": -21,
      "y": 20,
      "z": -7,
      "name": "Wood_Hardwood_Decorative",
      "rotation": 14
    },
    {
      "x": -21,
      "y": 21,
      "z": -7,
      "name": "Wood_Hardwood_Decorative",
      "rotation": 14
    },
    {
      "x": -21,
      "y": 5,
      "z": -6,
      "name": "Wood_Hardwood_Planks",
      "rotation": 14
    },
    {
      "x": -21,
      "y": 6,
      "z": -6,
      "name": "Wood_Hardwood_Planks",
      "rotation": 14
    },
    {
      "x": -21,
      "y": 14,
      "z": -6,
      "name": "Wood_Hardwood_Planks",
      "rotation": 14
    },
    {
      "x": -21,
      "y": 21,
      "z": -6,
      "name": "Wood_Hardwood_Planks",
      "rotation": 4
    },
    {
      "x": -21,
      "y": 5,
      "z": -5,
      "name": "Wood_Hardwood_Planks",
      "rotation": 14
    },
    {
      "x": -21,
      "y": 6,
      "z": -5,
      "name": "Wood_Hardwood_Planks",
      "rotation": 14
    },
    {
      "x": -21,
      "y": 13,
      "z": -5,
      "name": "Wood_Hardwood_Planks",
      "rotation": 14
    },
    {
      "x": -21,
      "y": 20,
      "z": -5,
      "name": "Wood_Hardwood_Planks",
      "rotation": 14
    },
    {
      "x": -21,
      "y": 21,
      "z": -5,
      "name": "Wood_Hardwood_Planks",
      "rotation": 17
    },
    {
      "x": -21,
      "y": 5,
      "z": -4,
      "name": "Wood_Hardwood_Planks",
      "rotation": 14
    },
    {
      "x": -21,
      "y": 12,
      "z": -4,
      "name": "Wood_Hardwood_Planks",
      "rotation": 14
    },
    {
      "x": -21,
      "y": 19,
      "z": -4,
      "name": "Wood_Hardwood_Planks",
      "rotation": 14
    },
    {
      "x": -21,
      "y": 20,
      "z": -4,
      "name": "Wood_Hardwood_Planks",
      "rotation": 17
    },
    {
      "x": -21,
      "y": 21,
      "z": -4,
      "name": "Wood_Hardwood_Planks",
      "rotation": 17
    },
    {
      "x": -21,
      "y": 4,
      "z": -3,
      "name": "Wood_Hardwood_Planks",
      "rotation": 14
    },
    {
      "x": -21,
      "y": 5,
      "z": -3,
      "name": "Wood_Sticks",
      "support": 15
    },
    {
      "x": -21,
      "y": 11,
      "z": -3,
      "name": "Wood_Hardwood_Planks",
      "rotation": 14
    },
    {
      "x": -21,
      "y": 18,
      "z": -3,
      "name": "Wood_Hardwood_Planks",
      "rotation": 14
    },
    {
      "x": -21,
      "y": 20,
      "z": -3,
      "name": "Wood_Hardwood_Planks",
      "rotation": 4
    },
    {
      "x": -21,
      "y": 4,
      "z": -2,
      "name": "Wood_Hardwood_Planks",
      "rotation": 14
    },
    {
      "x": -21,
      "y": 10,
      "z": -2,
      "name": "Wood_Hardwood_Planks",
      "rotation": 14
    },
    {
      "x": -21,
      "y": 17,
      "z": -2,
      "name": "Wood_Hardwood_Planks",
      "rotation": 14
    },
    {
      "x": -21,
      "y": 4,
      "z": -1,
      "name": "Wood_Hardwood_Planks",
      "rotation": 14
    },
    {
      "x": -21,
      "y": 9,
      "z": -1,
      "name": "Wood_Hardwood_Planks",
      "rotation": 14
    },
    {
      "x": -21,
      "y": 16,
      "z": -1,
      "name": "Wood_Hardwood_Planks",
      "rotation": 14
    },
    {
      "x": -21,
      "y": 17,
      "z": -1,
      "name": "Wood_Deadwood_Planks",
      "rotation": 14
    },
    {
      "x": -21,
      "y": 4,
      "z": 0,
      "name": "Wood_Hardwood_Planks",
      "rotation": 14
    },
    {
      "x": -21,
      "y": 8,
      "z": 0,
      "name": "Wood_Hardwood_Planks",
      "rotation": 14
    },
    {
      "x": -21,
      "y": 16,
      "z": 0,
      "name": "Wood_Deadwood_Planks",
      "rotation": 14
    },
    {
      "x": -21,
      "y": 17,
      "z": 0,
      "name": "Wood_Deadwood_Planks",
      "rotation": 14
    },
    {
      "x": -21,
      "y": 4,
      "z": 1,
      "name": "Wood_Hardwood_Planks",
      "rotation": 14
    },
    {
      "x": -21,
      "y": 5,
      "z": 1,
      "name": "Furniture_Ancient_Barrel"
    },
    {
      "x": -21,
      "y": 7,
      "z": 1,
      "name": "Wood_Hardwood_Planks",
      "rotation": 14
    },
    {
      "x": -21,
      "y": 5,
      "z": 2,
      "name": "Wood_Hardwood_Planks",
      "rotation": 14
    },
    {
      "x": -21,
      "y": 6,
      "z": 2,
      "name": "Wood_Hardwood_Planks",
      "rotation": 14
    },
    {
      "x": -21,
      "y": 7,
      "z": 2,
      "name": "Wood_Sticks",
      "support": 15
    },
    {
      "x": -21,
      "y": 13,
      "z": 2,
      "name": "Wood_Hardwood_Planks",
      "rotation": 14
    },
    {
      "x": -21,
      "y": 5,
      "z": 3,
      "name": "Wood_Hardwood_Planks",
      "rotation": 14
    },
    {
      "x": -21,
      "y": 6,
      "z": 3,
      "name": "Furniture_Ancient_Crate",
      "rotation": 1
    },
    {
      "x": -21,
      "y": 12,
      "z": 3,
      "name": "Wood_Hardwood_Planks",
      "rotation": 14
    },
    {
      "x": -21,
      "y": 6,
      "z": 4,
      "name": "Wood_Hardwood_Ornate",
      "rotation": 14
    },
    {
      "x": -21,
      "y": 7,
      "z": 4,
      "name": "Furniture_Ancient_Barrel"
    },
    {
      "x": -21,
      "y": 11,
      "z": 4,
      "name": "Wood_Hardwood_Planks",
      "rotation": 14
    },
    {
      "x": -21,
      "y": 7,
      "z": 5,
      "name": "Wood_Hardwood_Planks",
      "rotation": 14
    },
    {
      "x": -21,
      "y": 10,
      "z": 5,
      "name": "Wood_Hardwood_Planks",
      "rotation": 14
    },
    {
      "x": -21,
      "y": 11,
      "z": 5,
      "name": "Wood_Hardwood_Planks",
      "rotation": 4
    },
    {
      "x": -21,
      "y": 8,
      "z": 6,
      "name": "Wood_Hardwood_Decorative",
      "rotation": 14
    },
    {
      "x": -21,
      "y": 9,
      "z": 6,
      "name": "Wood_Hardwood_Planks",
      "rotation": 14
    },
    {
      "x": -21,
      "y": 10,
      "z": 6,
      "name": "Wood_Hardwood_Planks",
      "rotation": 17
    },
    {
      "x": -21,
      "y": 11,
      "z": 6,
      "name": "Wood_Hardwood_Planks",
      "rotation": 17
    },
    {
      "x": -21,
      "y": 12,
      "z": 6,
      "name": "Wood_Deadwood_Planks",
      "rotation": 14
    },
    {
      "x": -21,
      "y": 10,
      "z": 7,
      "name": "Wood_Hardwood_Planks",
      "rotation": 17
    },
    {
      "x": -21,
      "y": 10,
      "z": 8,
      "name": "Wood_Hardwood_Planks",
      "rotation": 14
    },
    {
      "x": -21,
      "y": 9,
      "z": 9,
      "name": "Wood_Deadwood_Planks",
      "rotation": 14
    },
    {
      "x": -20,
      "y": 14,
      "z": -11,
      "name": "Wood_Hardwood_Planks",
      "rotation": 14
    },
    {
      "x": -20,
      "y": 15,
      "z": -11,
      "name": "Wood_Hardwood_Planks"
    },
    {
      "x": -20,
      "y": 16,
      "z": -11,
      "name": "Wood_Hardwood_Planks"
    },
    {
      "x": -20,
      "y": 17,
      "z": -11,
      "name": "Wood_Hardwood_Planks",
      "rotation": 14
    },
    {
      "x": -20,
      "y": 9,
      "z": -10,
      "name": "Wood_Hardwood_Planks",
      "rotation": 14
    },
    {
      "x": -20,
      "y": 10,
      "z": -10,
      "name": "Wood_Hardwood_Planks"
    },
    {
      "x": -20,
      "y": 11,
      "z": -10,
      "name": "Wood_Hardwood_Planks",
      "rotation": 14
    },
    {
      "x": -20,
      "y": 12,
      "z": -10,
      "name": "Wood_Hardwood_Planks",
      "rotation": 51
    },
    {
      "x": -20,
      "y": 13,
      "z": -10,
      "name": "Wood_Deadwood_Planks",
      "rotation": 14
    },
    {
      "x": -20,
      "y": 14,
      "z": -10,
      "name": "Wood_Hardwood_Planks",
      "rotation": 14
    },
    {
      "x": -20,
      "y": 15,
      "z": -10,
      "name": "Wood_Hardwood_Planks"
    },
    {
      "x": -20,
      "y": 16,
      "z": -10,
      "name": "Wood_Hardwood_Planks"
    },
    {
      "x": -20,
      "y": 17,
      "z": -10,
      "name": "Wood_Hardwood_Planks",
      "rotation": 14
    },
    {
      "x": -20,
      "y": 18,
      "z": -10,
      "name": "Wood_Hardwood_Planks",
      "rotation": 14
    },
    {
      "x": -20,
      "y": 8,
      "z": -9,
      "name": "Wood_Hardwood_Planks",
      "rotation": 14
    },
    {
      "x": -20,
      "y": 9,
      "z": -9,
      "name": "Wood_Hardwood_Planks",
      "rotation": 14
    },
    {
      "x": -20,
      "y": 11,
      "z": -9,
      "name": "Wood_Hardwood_Planks",
      "rotation": 14
    },
    {
      "x": -20,
      "y": 17,
      "z": -9,
      "name": "Wood_Hardwood_Planks",
      "rotation": 14
    },
    {
      "x": -20,
      "y": 18,
      "z": -9,
      "name": "Wood_Hardwood_Planks",
      "rotation": 4
    },
    {
      "x": -20,
      "y": 19,
      "z": -9,
      "name": "Wood_Hardwood_Planks",
      "rotation": 4
    },
    {
      "x": -20,
      "y": 6,
      "z": -8,
      "name": "Wood_Hardwood_Planks",
      "rotation": 14
    },
    {
      "x": -20,
      "y": 7,
      "z": -8,
      "name": "Wood_Hardwood_Planks",
      "rotation": 14
    },
    {
      "x": -20,
      "y": 8,
      "z": -8,
      "name": "Wood_Hardwood_Planks",
      "rotation": 14
    },
    {
      "x": -20,
      "y": 12,
      "z": -8,
      "name": "Wood_Deadwood_Planks",
      "rotation": 14
    },
    {
      "x": -20,
      "y": 16,
      "z": -8,
      "name": "Wood_Hardwood_Planks",
      "rotation": 14
    },
    {
      "x": -20,
      "y": 19,
      "z": -8,
      "name": "Wood_Hardwood_Planks",
      "rotation": 4
    },
    {
      "x": -20,
      "y": 20,
      "z": -8,
      "name": "Wood_Hardwood_Planks",
      "rotation": 14
    },
    {
      "x": -20,
      "y": 6,
      "z": -7,
      "name": "Wood_Hardwood_Planks",
      "rotation": 14
    },
    {
      "x": -20,
      "y": 7,
      "z": -7,
      "name": "Wood_Hardwood_Planks",
      "rotation": 14
    },
    {
      "x": -20,
      "y": 15,
      "z": -7,
      "name": "Wood_Hardwood_Planks",
      "rotation": 14
    },
    {
      "x": -20,
      "y": 20,
      "z": -7,
      "name": "Wood_Hardwood_Planks",
      "rotation": 14
    },
    {
      "x": -20,
      "y": 21,
      "z": -7,
      "name": "Wood_Hardwood_Planks",
      "rotation": 14
    },
    {
      "x": -20,
      "y": 5,
      "z": -6,
      "name": "Wood_Hardwood_Planks",
      "rotation": 14
    },
    {
      "x": -20,
      "y": 6,
      "z": -6,
      "name": "Wood_Hardwood_Planks",
      "rotation": 14
    },
    {
      "x": -20,
      "y": 7,
      "z": -6,
      "name": "Furniture_Ancient_Barrel"
    },
    {
      "x": -20,
      "y": 14,
      "z": -6,
      "name": "Wood_Hardwood_Planks",
      "rotation": 14
    },
    {
      "x": -20,
      "y": 21,
      "z": -6,
      "name": "Wood_Hardwood_Decorative",
      "rotation": 14
    },
    {
      "x": -20,
      "y": 22,
      "z": -6,
      "name": "Wood_Hardwood_Planks",
      "rotation": 14
    },
    {
      "x": -20,
      "y": 5,
      "z": -5,
      "name": "Wood_Hardwood_Planks",
      "rotation": 14
    },
    {
      "x": -20,
      "y": 6,
      "z": -5,
      "name": "Wood_Sticks",
      "support": 15
    },
    {
      "x": -20,
      "y": 13,
      "z": -5,
      "name": "Wood_Hardwood_Planks",
      "rotation": 14
    },
    {
      "x": -20,
      "y": 20,
      "z": -5,
      "name": "Wood_Hardwood_Planks",
      "rotation": 14
    },
    {
      "x": -20,
      "y": 21,
      "z": -5,
      "name": "Wood_Hardwood_Planks"
    },
    {
      "x": -20,
      "y": 22,
      "z": -5,
      "name": "Wood_Hardwood_Planks",
      "rotation": 14
    },
    {
      "x": -20,
      "y": 5,
      "z": -4,
      "name": "Wood_Hardwood_Planks",
      "rotation": 14
    },
    {
      "x": -20,
      "y": 12,
      "z": -4,
      "name": "Wood_Hardwood_Planks",
      "rotation": 14
    },
    {
      "x": -20,
      "y": 19,
      "z": -4,
      "name": "Wood_Hardwood_Planks",
      "rotation": 14
    },
    {
      "x": -20,
      "y": 4,
      "z": -3,
      "name": "Wood_Hardwood_Planks",
      "rotation": 14
    },
    {
      "x": -20,
      "y": 5,
      "z": -3,
      "name": "Wood_Hardwood_Planks",
      "rotation": 51
    },
    {
      "x": -20,
      "y": 6,
      "z": -3,
      "name": "Wood_Deadwood_Planks",
      "rotation": 14
    },
    {
      "x": -20,
      "y": 11,
      "z": -3,
      "name": "Wood_Hardwood_Planks",
      "rotation": 14
    },
    {
      "x": -20,
      "y": 18,
      "z": -3,
      "name": "Wood_Hardwood_Planks",
      "rotation": 14
    },
    {
      "x": -20,
      "y": 4,
      "z": -2,
      "name": "Wood_Hardwood_Planks",
      "rotation": 14
    },
    {
      "x": -20,
      "y": 10,
      "z": -2,
      "name": "Wood_Hardwood_Planks",
      "rotation": 14
    },
    {
      "x": -20,
      "y": 17,
      "z": -2,
      "name": "Wood_Hardwood_Planks",
      "rotation": 14
    },
    {
      "x": -20,
      "y": 4,
      "z": -1,
      "name": "Wood_Hardwood_Planks",
      "rotation": 14
    },
    {
      "x": -20,
      "y": 5,
      "z": -1,
      "name": "Wood_Deadwood_Planks",
      "rotation": 14
    },
    {
      "x": -20,
      "y": 9,
      "z": -1,
      "name": "Wood_Hardwood_Planks",
      "rotation": 14
    },
    {
      "x": -20,
      "y": 18,
      "z": -1,
      "name": "Wood_Deadwood_Planks",
      "rotation": 14
    },
    {
      "x": -20,
      "y": 4,
      "z": 0,
      "name": "Wood_Hardwood_Planks",
      "rotation": 14
    },
    {
      "x": -20,
      "y": 4,
      "z": 1,
      "name": "Wood_Hardwood_Planks",
      "rotation": 14
    },
    {
      "x": -20,
      "y": 7,
      "z": 1,
      "name": "Wood_Hardwood_Planks",
      "rotation": 14
    },
    {
      "x": -20,
      "y": 4,
      "z": 2,
      "name": "Wood_Hardwood_Planks",
      "rotation": 14
    },
    {
      "x": -20,
      "y": 6,
      "z": 2,
      "name": "Wood_Hardwood_Planks",
      "rotation": 14
    },
    {
      "x": -20,
      "y": 7,
      "z": 2,
      "name": "Furniture_Ancient_Crate",
      "rotation": 1
    },
    {
      "x": -20,
      "y": 13,
      "z": 2,
      "name": "Wood_Hardwood_Planks",
      "rotation": 14
    },
    {
      "x": -20,
      "y": 5,
      "z": 3,
      "name": "Wood_Hardwood_Planks",
      "rotation": 14
    },
    {
      "x": -20,
      "y": 12,
      "z": 3,
      "name": "Wood_Hardwood_Planks",
      "rotation": 14
    },
    {
      "x": -20,
      "y": 13,
      "z": 3,
      "name": "Wood_Deadwood_Planks",
      "rotation": 14
    },
    {
      "x": -20,
      "y": 14,
      "z": 3,
      "name": "Wood_Deadwood_Planks",
      "rotation": 14
    },
    {
      "x": -20,
      "y": 6,
      "z": 4,
      "name": "Wood_Hardwood_Planks",
      "rotation": 4
    },
    {
      "x": -20,
      "y": 11,
      "z": 4,
      "name": "Wood_Hardwood_Planks",
      "rotation": 14
    },
    {
      "x": -20,
      "y": 7,
      "z": 5,
      "name": "Wood_Hardwood_Planks",
      "rotation": 14
    },
    {
      "x": -20,
      "y": 10,
      "z": 5,
      "name": "Wood_Hardwood_Planks",
      "rotation": 14
    },
    {
      "x": -20,
      "y": 8,
      "z": 6,
      "name": "Wood_Hardwood_Planks",
      "rotation": 14
    },
    {
      "x": -20,
      "y": 9,
      "z": 6,
      "name": "Wood_Hardwood_Planks",
      "rotation": 14
    },
    {
      "x": -20,
      "y": 9,
      "z": 7,
      "name": "Wood_Hardwood_Planks",
      "rotation": 14
    },
    {
      "x": -20,
      "y": 10,
      "z": 8,
      "name": "Wood_Hardwood_Planks",
      "rotation": 14
    },
    {
      "x": -20,
      "y": 9,
      "z": 9,
      "name": "Wood_Deadwood_Planks",
      "rotation": 14
    },
    {
      "x": -19,
      "y": 14,
      "z": -11,
      "name": "Wood_Hardwood_Planks",
      "rotation": 14
    },
    {
      "x": -19,
      "y": 15,
      "z": -11,
      "name": "Wood_Hardwood_Planks"
    },
    {
      "x": -19,
      "y": 16,
      "z": -11,
      "name": "Wood_Hardwood_Planks"
    },
    {
      "x": -19,
      "y": 17,
      "z": -11,
      "name": "Wood_Hardwood_Planks",
      "rotation": 14
    },
    {
      "x": -19,
      "y": 9,
      "z": -10,
      "name": "Wood_Hardwood_Planks",
      "rotation": 14
    },
    {
      "x": -19,
      "y": 10,
      "z": -10,
      "name": "Wood_Hardwood_Planks"
    },
    {
      "x": -19,
      "y": 11,
      "z": -10,
      "name": "Wood_Hardwood_Planks",
      "rotation": 14
    },
    {
      "x": -19,
      "y": 12,
      "z": -10,
      "name": "Wood_Hardwood_Planks",
      "rotation": 14
    },
    {
      "x": -19,
      "y": 13,
      "z": -10,
      "name": "Wood_Hardwood_Planks",
      "rotation": 14
    },
    {
      "x": -19,
      "y": 14,
      "z": -10,
      "name": "Wood_Hardwood_Planks",
      "rotation": 14
    },
    {
      "x": -19,
      "y": 15,
      "z": -10,
      "name": "Wood_Hardwood_Planks"
    },
    {
      "x": -19,
      "y": 16,
      "z": -10,
      "name": "Wood_Hardwood_Planks"
    },
    {
      "x": -19,
      "y": 17,
      "z": -10,
      "name": "Wood_Hardwood_Planks",
      "rotation": 14
    },
    {
      "x": -19,
      "y": 18,
      "z": -10,
      "name": "Wood_Hardwood_Planks",
      "rotation": 14
    },
    {
      "x": -19,
      "y": 8,
      "z": -9,
      "name": "Wood_Hardwood_Planks",
      "rotation": 14
    },
    {
      "x": -19,
      "y": 9,
      "z": -9,
      "name": "Wood_Hardwood_Planks",
      "rotation": 14
    },
    {
      "x": -19,
      "y": 11,
      "z": -9,
      "name": "Wood_Hardwood_Planks",
      "rotation": 14
    },
    {
      "x": -19,
      "y": 12,
      "z": -9,
      "name": "Wood_Hardwood_Planks",
      "rotation": 51
    },
    {
      "x": -19,
      "y": 13,
      "z": -9,
      "name": "Wood_Hardwood_Planks",
      "rotation": 51
    },
    {
      "x": -19,
      "y": 14,
      "z": -9,
      "name": "Wood_Deadwood_Planks",
      "rotation": 14
    },
    {
      "x": -19,
      "y": 17,
      "z": -9,
      "name": "Wood_Hardwood_Planks",
      "rotation": 14
    },
    {
      "x": -19,
      "y": 18,
      "z": -9,
      "name": "Wood_Hardwood_Planks",
      "rotation": 4
    },
    {
      "x": -19,
      "y": 19,
      "z": -9,
      "name": "Wood_Hardwood_Planks",
      "rotation": 4
    },
    {
      "x": -19,
      "y": 6,
      "z": -8,
      "name": "Wood_Hardwood_Planks",
      "rotation": 14
    },
    {
      "x": -19,
      "y": 7,
      "z": -8,
      "name": "Wood_Hardwood_Planks",
      "rotation": 14
    },
    {
      "x": -19,
      "y": 8,
      "z": -8,
      "name": "Wood_Hardwood_Planks",
      "rotation": 14
    },
    {
      "x": -19,
      "y": 9,
      "z": -8,
      "name": "Furniture_Ancient_Barrel"
    },
    {
      "x": -19,
      "y": 12,
      "z": -8,
      "name": "Wood_Hardwood_Planks",
      "rotation": 14
    },
    {
      "x": -19,
      "y": 16,
      "z": -8,
      "name": "Wood_Hardwood_Planks",
      "rotation": 14
    },
    {
      "x": -19,
      "y": 19,
      "z": -8,
      "name": "Wood_Hardwood_Planks",
      "rotation": 14
    },
    {
      "x": -19,
      "y": 20,
      "z": -8,
      "name": "Wood_Hardwood_Planks",
      "rotation": 14
    },
    {
      "x": -19,
      "y": 6,
      "z": -7,
      "name": "Wood_Hardwood_Planks",
      "rotation": 14
    },
    {
      "x": -19,
      "y": 7,
      "z": -7,
      "name": "Wood_Hardwood_Planks",
      "rotation": 14
    },
    {
      "x": -19,
      "y": 20,
      "z": -7,
      "name": "Wood_Hardwood_Planks",
      "rotation": 14
    },
    {
      "x": -19,
      "y": 21,
      "z": -7,
      "name": "Wood_Hardwood_Planks",
      "rotation": 14
    },
    {
      "x": -19,
      "y": 5,
      "z": -6,
      "name": "Wood_Hardwood_Planks",
      "rotation": 14
    },
    {
      "x": -19,
      "y": 6,
      "z": -6,
      "name": "Wood_Hardwood_Planks",
      "rotation": 14
    },
    {
      "x": -19,
      "y": 14,
      "z": -6,
      "name": "Wood_Hardwood_Planks",
      "rotation": 14
    },
    {
      "x": -19,
      "y": 21,
      "z": -6,
      "name": "Wood_Hardwood_Decorative",
      "rotation": 14
    },
    {
      "x": -19,
      "y": 22,
      "z": -6,
      "name": "Wood_Hardwood_Planks",
      "rotation": 14
    },
    {
      "x": -19,
      "y": 5,
      "z": -5,
      "name": "Wood_Hardwood_Planks",
      "rotation": 14
    },
    {
      "x": -19,
      "y": 6,
      "z": -5,
      "name": "Wood_Sticks",
      "support": 15
    },
    {
      "x": -19,
      "y": 13,
      "z": -5,
      "name": "Wood_Hardwood_Planks",
      "rotation": 14
    },
    {
      "x": -19,
      "y": 20,
      "z": -5,
      "name": "Wood_Hardwood_Planks",
      "rotation": 14
    },
    {
      "x": -19,
      "y": 21,
      "z": -5,
      "name": "Wood_Hardwood_Planks"
    },
    {
      "x": -19,
      "y": 22,
      "z": -5,
      "name": "Wood_Hardwood_Planks",
      "rotation": 14
    },
    {
      "x": -19,
      "y": 5,
      "z": -4,
      "name": "Wood_Hardwood_Planks",
      "rotation": 14
    },
    {
      "x": -19,
      "y": 12,
      "z": -4,
      "name": "Wood_Hardwood_Planks",
      "rotation": 14
    },
    {
      "x": -19,
      "y": 19,
      "z": -4,
      "name": "Wood_Hardwood_Planks",
      "rotation": 14
    },
    {
      "x": -19,
      "y": 4,
      "z": -3,
      "name": "Wood_Hardwood_Planks",
      "rotation": 14
    },
    {
      "x": -19,
      "y": 5,
      "z": -3,
      "name": "Wood_Hardwood_Planks",
      "rotation": 14
    },
    {
      "x": -19,
      "y": 6,
      "z": -3,
      "name": "Wood_Hardwood_Planks",
      "rotation": 14
    },
    {
      "x": -19,
      "y": 11,
      "z": -3,
      "name": "Wood_Hardwood_Planks",
      "rotation": 14
    },
    {
      "x": -19,
      "y": 18,
      "z": -3,
      "name": "Wood_Hardwood_Planks",
      "rotation": 14
    },
    {
      "x": -19,
      "y": 4,
      "z": -2,
      "name": "Wood_Hardwood_Planks",
      "rotation": 14
    },
    {
      "x": -19,
      "y": 5,
      "z": -2,
      "name": "Wood_Hardwood_Planks",
      "rotation": 51
    },
    {
      "x": -19,
      "y": 6,
      "z": -2,
      "name": "Wood_Hardwood_Planks",
      "rotation": 51
    },
    {
      "x": -19,
      "y": 7,
      "z": -2,
      "name": "Wood_Deadwood_Planks",
      "rotation": 14
    },
    {
      "x": -19,
      "y": 10,
      "z": -2,
      "name": "Wood_Hardwood_Planks",
      "rotation": 14
    },
    {
      "x": -19,
      "y": 17,
      "z": -2,
      "name": "Wood_Hardwood_Planks",
      "rotation": 14
    },
    {
      "x": -19,
      "y": 4,
      "z": -1,
      "name": "Wood_Hardwood_Planks",
      "rotation": 14
    },
    {
      "x": -19,
      "y": 5,
      "z": -1,
      "name": "Wood_Hardwood_Planks",
      "rotation": 14
    },
    {
      "x": -19,
      "y": 9,
      "z": -1,
      "name": "Wood_Hardwood_Planks",
      "rotation": 14
    },
    {
      "x": -19,
      "y": 18,
      "z": -1,
      "name": "Wood_Deadwood_Planks",
      "rotation": 14
    },
    {
      "x": -19,
      "y": 4,
      "z": 0,
      "name": "Wood_Hardwood_Planks",
      "rotation": 14
    },
    {
      "x": -19,
      "y": 4,
      "z": 1,
      "name": "Wood_Hardwood_Planks",
      "rotation": 14
    },
    {
      "x": -19,
      "y": 7,
      "z": 1,
      "name": "Wood_Hardwood_Planks",
      "rotation": 14
    },
    {
      "x": -19,
      "y": 4,
      "z": 2,
      "name": "Wood_Hardwood_Planks",
      "rotation": 14
    },
    {
      "x": -19,
      "y": 6,
      "z": 2,
      "name": "Wood_Hardwood_Planks",
      "rotation": 14
    },
    {
      "x": -19,
      "y": 13,
      "z": 2,
      "name": "Wood_Hardwood_Planks",
      "rotation": 14
    },
    {
      "x": -19,
      "y": 5,
      "z": 3,
      "name": "Wood_Hardwood_Planks",
      "rotation": 14
    },
    {
      "x": -19,
      "y": 12,
      "z": 3,
      "name": "Wood_Hardwood_Planks",
      "rotation": 14
    },
    {
      "x": -19,
      "y": 13,
      "z": 3,
      "name": "Wood_Deadwood_Planks",
      "rotation": 14
    },
    {
      "x": -19,
      "y": 14,
      "z": 3,
      "name": "Wood_Deadwood_Planks",
      "rotation": 14
    },
    {
      "x": -19,
      "y": 6,
      "z": 4,
      "name": "Wood_Hardwood_Planks",
      "rotation": 4
    },
    {
      "x": -19,
      "y": 11,
      "z": 4,
      "name": "Wood_Hardwood_Planks",
      "rotation": 14
    },
    {
      "x": -19,
      "y": 7,
      "z": 5,
      "name": "Wood_Hardwood_Planks",
      "rotation": 14
    },
    {
      "x": -19,
      "y": 10,
      "z": 5,
      "name": "Wood_Hardwood_Planks",
      "rotation": 14
    },
    {
      "x": -19,
      "y": 11,
      "z": 5,
      "name": "Wood_Sticks",
      "support": 15
    },
    {
      "x": -19,
      "y": 8,
      "z": 6,
      "name": "Wood_Hardwood_Planks",
      "rotation": 14
    },
    {
      "x": -19,
      "y": 9,
      "z": 6,
      "name": "Wood_Hardwood_Planks",
      "rotation": 14
    },
    {
      "x": -19,
      "y": 9,
      "z": 7,
      "name": "Wood_Hardwood_Planks",
      "rotation": 14
    },
    {
      "x": -19,
      "y": 10,
      "z": 8,
      "name": "Wood_Hardwood_Planks",
      "rotation": 14
    },
    {
      "x": -19,
      "y": 9,
      "z": 9,
      "name": "Wood_Deadwood_Planks",
      "rotation": 14
    },
    {
      "x": -18,
      "y": 14,
      "z": -11,
      "name": "Wood_Hardwood_Planks",
      "rotation": 14
    },
    {
      "x": -18,
      "y": 15,
      "z": -11,
      "name": "Wood_Hardwood_Planks"
    },
    {
      "x": -18,
      "y": 16,
      "z": -11,
      "name": "Wood_Hardwood_Planks"
    },
    {
      "x": -18,
      "y": 17,
      "z": -11,
      "name": "Wood_Hardwood_Planks",
      "rotation": 14
    },
    {
      "x": -18,
      "y": 9,
      "z": -10,
      "name": "Wood_Hardwood_Planks",
      "rotation": 14
    },
    {
      "x": -18,
      "y": 10,
      "z": -10,
      "name": "Wood_Hardwood_Planks"
    },
    {
      "x": -18,
      "y": 11,
      "z": -10,
      "name": "Wood_Hardwood_Planks",
      "rotation": 14
    },
    {
      "x": -18,
      "y": 12,
      "z": -10,
      "name": "Wood_Hardwood_Planks",
      "rotation": 14
    },
    {
      "x": -18,
      "y": 13,
      "z": -10,
      "name": "Wood_Hardwood_Planks",
      "rotation": 14
    },
    {
      "x": -18,
      "y": 14,
      "z": -10,
      "name": "Wood_Hardwood_Planks",
      "rotation": 14
    },
    {
      "x": -18,
      "y": 15,
      "z": -10,
      "name": "Wood_Hardwood_Planks"
    },
    {
      "x": -18,
      "y": 16,
      "z": -10,
      "name": "Wood_Hardwood_Planks"
    },
    {
      "x": -18,
      "y": 17,
      "z": -10,
      "name": "Wood_Hardwood_Planks",
      "rotation": 14
    },
    {
      "x": -18,
      "y": 18,
      "z": -10,
      "name": "Wood_Hardwood_Planks",
      "rotation": 14
    },
    {
      "x": -18,
      "y": 8,
      "z": -9,
      "name": "Wood_Hardwood_Planks",
      "rotation": 14
    },
    {
      "x": -18,
      "y": 9,
      "z": -9,
      "name": "Wood_Hardwood_Planks",
      "rotation": 14
    },
    {
      "x": -18,
      "y": 11,
      "z": -9,
      "name": "Wood_Hardwood_Planks",
      "rotation": 14
    },
    {
      "x": -18,
      "y": 12,
      "z": -9,
      "name": "Wood_Hardwood_Planks",
      "rotation": 14
    },
    {
      "x": -18,
      "y": 13,
      "z": -9,
      "name": "Wood_Hardwood_Planks",
      "rotation": 14
    },
    {
      "x": -18,
      "y": 14,
      "z": -9,
      "name": "Wood_Hardwood_Planks",
      "rotation": 14
    },
    {
      "x": -18,
      "y": 17,
      "z": -9,
      "name": "Wood_Hardwood_Planks",
      "rotation": 14
    },
    {
      "x": -18,
      "y": 18,
      "z": -9,
      "name": "Wood_Hardwood_Planks",
      "rotation": 4
    },
    {
      "x": -18,
      "y": 19,
      "z": -9,
      "name": "Wood_Hardwood_Planks",
      "rotation": 4
    },
    {
      "x": -18,
      "y": 6,
      "z": -8,
      "name": "Wood_Hardwood_Planks",
      "rotation": 14
    },
    {
      "x": -18,
      "y": 7,
      "z": -8,
      "name": "Wood_Hardwood_Planks",
      "rotation": 14
    },
    {
      "x": -18,
      "y": 8,
      "z": -8,
      "name": "Wood_Hardwood_Planks",
      "rotation": 14
    },
    {
      "x": -18,
      "y": 12,
      "z": -8,
      "name": "Wood_Hardwood_Planks",
      "rotation": 14
    },
    {
      "x": -18,
      "y": 13,
      "z": -8,
      "name": "Wood_Hardwood_Planks",
      "rotation": 51
    },
    {
      "x": -18,
      "y": 15,
      "z": -8,
      "name": "Wood_Deadwood_Planks",
      "rotation": 14
    },
    {
      "x": -18,
      "y": 16,
      "z": -8,
      "name": "Wood_Hardwood_Planks",
      "rotation": 14
    },
    {
      "x": -18,
      "y": 19,
      "z": -8,
      "name": "Wood_Hardwood_Planks",
      "rotation": 14
    },
    {
      "x": -18,
      "y": 20,
      "z": -8,
      "name": "Wood_Hardwood_Planks",
      "rotation": 14
    },
    {
      "x": -18,
      "y": 6,
      "z": -7,
      "name": "Wood_Hardwood_Planks",
      "rotation": 14
    },
    {
      "x": -18,
      "y": 7,
      "z": -7,
      "name": "Wood_Hardwood_Planks",
      "rotation": 14
    },
    {
      "x": -18,
      "y": 13,
      "z": -7,
      "name": "Wood_Deadwood_Planks",
      "rotation": 14
    },
    {
      "x": -18,
      "y": 20,
      "z": -7,
      "name": "Wood_Hardwood_Planks",
      "rotation": 4
    },
    {
      "x": -18,
      "y": 21,
      "z": -7,
      "name": "Wood_Hardwood_Planks",
      "rotation": 4
    },
    {
      "x": -18,
      "y": 5,
      "z": -6,
      "name": "Wood_Hardwood_Planks",
      "rotation": 14
    },
    {
      "x": -18,
      "y": 6,
      "z": -6,
      "name": "Wood_Hardwood_Planks",
      "rotation": 14
    },
    {
      "x": -18,
      "y": 14,
      "z": -6,
      "name": "Wood_Hardwood_Planks",
      "rotation": 14
    },
    {
      "x": -18,
      "y": 21,
      "z": -6,
      "name": "Wood_Hardwood_Planks",
      "rotation": 14
    },
    {
      "x": -18,
      "y": 22,
      "z": -6,
      "name": "Wood_Hardwood_Planks",
      "rotation": 14
    },
    {
      "x": -18,
      "y": 23,
      "z": -6,
      "name": "Wood_Deadwood_Planks",
      "rotation": 14
    },
    {
      "x": -18,
      "y": 5,
      "z": -5,
      "name": "Wood_Hardwood_Planks",
      "rotation": 14
    },
    {
      "x": -18,
      "y": 6,
      "z": -5,
      "name": "Furniture_Ancient_Crate",
      "rotation": 3
    },
    {
      "x": -18,
      "y": 13,
      "z": -5,
      "name": "Wood_Hardwood_Planks",
      "rotation": 14
    },
    {
      "x": -18,
      "y": 20,
      "z": -5,
      "name": "Wood_Hardwood_Planks",
      "rotation": 14
    },
    {
      "x": -18,
      "y": 21,
      "z": -5,
      "name": "Wood_Hardwood_Planks"
    },
    {
      "x": -18,
      "y": 22,
      "z": -5,
      "name": "Wood_Hardwood_Planks",
      "rotation": 14
    },
    {
      "x": -18,
      "y": 23,
      "z": -5,
      "name": "Wood_Hardwood_Planks",
      "rotation": 17
    },
    {
      "x": -18,
      "y": 5,
      "z": -4,
      "name": "Wood_Hardwood_Planks",
      "rotation": 14
    },
    {
      "x": -18,
      "y": 12,
      "z": -4,
      "name": "Wood_Hardwood_Planks",
      "rotation": 14
    },
    {
      "x": -18,
      "y": 19,
      "z": -4,
      "name": "Wood_Hardwood_Planks",
      "rotation": 14
    },
    {
      "x": -18,
      "y": 4,
      "z": -3,
      "name": "Wood_Hardwood_Planks",
      "rotation": 14
    },
    {
      "x": -18,
      "y": 5,
      "z": -3,
      "name": "Wood_Hardwood_Planks",
      "rotation": 14
    },
    {
      "x": -18,
      "y": 6,
      "z": -3,
      "name": "Wood_Hardwood_Planks",
      "rotation": 14
    },
    {
      "x": -18,
      "y": 7,
      "z": -3,
      "name": "Furniture_Ancient_Crate",
      "rotation": 3
    },
    {
      "x": -18,
      "y": 11,
      "z": -3,
      "name": "Wood_Hardwood_Planks",
      "rotation": 14
    },
    {
      "x": -18,
      "y": 12,
      "z": -3,
      "name": "Furniture_Ancient_Barrel"
    },
    {
      "x": -18,
      "y": 18,
      "z": -3,
      "name": "Wood_Hardwood_Planks",
      "rotation": 14
    },
    {
      "x": -18,
      "y": 4,
      "z": -2,
      "name": "Wood_Hardwood_Planks",
      "rotation": 14
    },
    {
      "x": -18,
      "y": 5,
      "z": -2,
      "name": "Wood_Hardwood_Planks",
      "rotation": 14
    },
    {
      "x": -18,
      "y": 6,
      "z": -2,
      "name": "Wood_Hardwood_Planks",
      "rotation": 14
    },
    {
      "x": -18,
      "y": 7,
      "z": -2,
      "name": "Wood_Hardwood_Planks",
      "rotation": 14
    },
    {
      "x": -18,
      "y": 10,
      "z": -2,
      "name": "Wood_Hardwood_Planks",
      "rotation": 14
    },
    {
      "x": -18,
      "y": 17,
      "z": -2,
      "name": "Wood_Hardwood_Planks",
      "rotation": 14
    },
    {
      "x": -18,
      "y": 4,
      "z": -1,
      "name": "Wood_Hardwood_Planks",
      "rotation": 14
    },
    {
      "x": -18,
      "y": 5,
      "z": -1,
      "name": "Wood_Hardwood_Planks",
      "rotation": 14
    },
    {
      "x": -18,
      "y": 6,
      "z": -1,
      "name": "Wood_Hardwood_Planks",
      "rotation": 51
    },
    {
      "x": -18,
      "y": 7,
      "z": -1,
      "name": "Wood_Sticks",
      "support": 15
    },
    {
      "x": -18,
      "y": 8,
      "z": -1,
      "name": "Wood_Deadwood_Planks",
      "rotation": 14
    },
    {
      "x": -18,
      "y": 9,
      "z": -1,
      "name": "Wood_Hardwood_Planks",
      "rotation": 14
    },
    {
      "x": -18,
      "y": 18,
      "z": -1,
      "name": "Wood_Deadwood_Planks",
      "rotation": 14
    },
    {
      "x": -18,
      "y": 4,
      "z": 0,
      "name": "Wood_Hardwood_Planks",
      "rotation": 14
    },
    {
      "x": -18,
      "y": 6,
      "z": 0,
      "name": "Wood_Deadwood_Planks",
      "rotation": 14
    },
    {
      "x": -18,
      "y": 4,
      "z": 1,
      "name": "Wood_Hardwood_Planks",
      "rotation": 14
    },
    {
      "x": -18,
      "y": 7,
      "z": 1,
      "name": "Wood_Hardwood_Planks",
      "rotation": 14
    },
    {
      "x": -18,
      "y": 8,
      "z": 1,
      "name": "Wood_Sticks",
      "support": 15
    },
    {
      "x": -18,
      "y": 4,
      "z": 2,
      "name": "Wood_Hardwood_Planks",
      "rotation": 14
    },
    {
      "x": -18,
      "y": 6,
      "z": 2,
      "name": "Wood_Hardwood_Planks",
      "rotation": 14
    },
    {
      "x": -18,
      "y": 13,
      "z": 2,
      "name": "Wood_Hardwood_Planks",
      "rotation": 14
    },
    {
      "x": -18,
      "y": 5,
      "z": 3,
      "name": "Wood_Hardwood_Planks",
      "rotation": 14
    },
    {
      "x": -18,
      "y": 12,
      "z": 3,
      "name": "Wood_Hardwood_Planks",
      "rotation": 14
    },
    {
      "x": -18,
      "y": 13,
      "z": 3,
      "name": "Wood_Deadwood_Planks",
      "rotation": 14
    },
    {
      "x": -18,
      "y": 14,
      "z": 3,
      "name": "Wood_Deadwood_Planks",
      "rotation": 14
    },
    {
      "x": -18,
      "y": 6,
      "z": 4,
      "name": "Wood_Hardwood_Planks",
      "rotation": 4
    },
    {
      "x": -18,
      "y": 11,
      "z": 4,
      "name": "Wood_Hardwood_Planks",
      "rotation": 14
    },
    {
      "x": -18,
      "y": 12,
      "z": 4,
      "name": "Wood_Sticks",
      "support": 15
    },
    {
      "x": -18,
      "y": 7,
      "z": 5,
      "name": "Wood_Hardwood_Planks",
      "rotation": 14
    },
    {
      "x": -18,
      "y": 10,
      "z": 5,
      "name": "Wood_Hardwood_Planks",
      "rotation": 14
    },
    {
      "x": -18,
      "y": 8,
      "z": 6,
      "name": "Wood_Hardwood_Planks",
      "rotation": 4
    },
    {
      "x": -18,
      "y": 9,
      "z": 6,
      "name": "Wood_Hardwood_Planks",
      "rotation": 14
    },
    {
      "x": -18,
      "y": 9,
      "z": 7,
      "name": "Wood_Hardwood_Planks",
      "rotation": 14
    },
    {
      "x": -18,
      "y": 8,
      "z": 8,
      "name": "Wood_Deadwood_Planks",
      "rotation": 14
    },
    {
      "x": -18,
      "y": 9,
      "z": 8,
      "name": "Wood_Deadwood_Planks",
      "rotation": 14
    },
    {
      "x": -18,
      "y": 10,
      "z": 8,
      "name": "Wood_Hardwood_Planks",
      "rotation": 17
    },
    {
      "x": -17,
      "y": 14,
      "z": -11,
      "name": "Wood_Hardwood_Planks",
      "rotation": 14
    },
    {
      "x": -17,
      "y": 15,
      "z": -11,
      "name": "Wood_Hardwood_Planks"
    },
    {
      "x": -17,
      "y": 16,
      "z": -11,
      "name": "Wood_Hardwood_Planks"
    },
    {
      "x": -17,
      "y": 17,
      "z": -11,
      "name": "Wood_Hardwood_Planks",
      "rotation": 14
    },
    {
      "x": -17,
      "y": 9,
      "z": -10,
      "name": "Wood_Hardwood_Planks",
      "rotation": 14
    },
    {
      "x": -17,
      "y": 10,
      "z": -10,
      "name": "Wood_Hardwood_Planks"
    },
    {
      "x": -17,
      "y": 11,
      "z": -10,
      "name": "Wood_Hardwood_Planks",
      "rotation": 14
    },
    {
      "x": -17,
      "y": 12,
      "z": -10,
      "name": "Wood_Hardwood_Planks"
    },
    {
      "x": -17,
      "y": 13,
      "z": -10,
      "name": "Wood_Hardwood_Planks",
      "rotation": 14
    },
    {
      "x": -17,
      "y": 14,
      "z": -10,
      "name": "Wood_Hardwood_Planks",
      "rotation": 14
    },
    {
      "x": -17,
      "y": 15,
      "z": -10,
      "name": "Wood_Hardwood_Planks"
    },
    {
      "x": -17,
      "y": 16,
      "z": -10,
      "name": "Wood_Hardwood_Planks"
    },
    {
      "x": -17,
      "y": 17,
      "z": -10,
      "name": "Wood_Hardwood_Planks",
      "rotation": 14
    },
    {
      "x": -17,
      "y": 18,
      "z": -10,
      "name": "Wood_Hardwood_Planks",
      "rotation": 14
    },
    {
      "x": -17,
      "y": 8,
      "z": -9,
      "name": "Wood_Hardwood_Planks",
      "rotation": 14
    },
    {
      "x": -17,
      "y": 9,
      "z": -9,
      "name": "Wood_Hardwood_Planks",
      "rotation": 14
    },
    {
      "x": -17,
      "y": 11,
      "z": -9,
      "name": "Wood_Hardwood_Planks",
      "rotation": 14
    },
    {
      "x": -17,
      "y": 14,
      "z": -9,
      "name": "Wood_Hardwood_Planks",
      "rotation": 14
    },
    {
      "x": -17,
      "y": 17,
      "z": -9,
      "name": "Wood_Hardwood_Planks",
      "rotation": 14
    },
    {
      "x": -17,
      "y": 18,
      "z": -9,
      "name": "Wood_Hardwood_Ornate",
      "rotation": 14
    },
    {
      "x": -17,
      "y": 19,
      "z": -9,
      "name": "Wood_Hardwood_Ornate",
      "rotation": 14
    },
    {
      "x": -17,
      "y": 6,
      "z": -8,
      "name": "Wood_Hardwood_Planks",
      "rotation": 14
    },
    {
      "x": -17,
      "y": 7,
      "z": -8,
      "name": "Wood_Hardwood_Planks",
      "rotation": 14
    },
    {
      "x": -17,
      "y": 8,
      "z": -8,
      "name": "Wood_Hardwood_Planks",
      "rotation": 14
    },
    {
      "x": -17,
      "y": 12,
      "z": -8,
      "name": "Wood_Hardwood_Planks",
      "rotation": 14
    },
    {
      "x": -17,
      "y": 13,
      "z": -8,
      "name": "Wood_Hardwood_Planks",
      "rotation": 14
    },
    {
      "x": -17,
      "y": 14,
      "z": -8,
      "name": "Wood_Hardwood_Planks",
      "rotation": 51
    },
    {
      "x": -17,
      "y": 15,
      "z": -8,
      "name": "Wood_Hardwood_Planks",
      "rotation": 14
    },
    {
      "x": -17,
      "y": 16,
      "z": -8,
      "name": "Wood_Hardwood_Planks",
      "rotation": 14
    },
    {
      "x": -17,
      "y": 19,
      "z": -8,
      "name": "Wood_Hardwood_Planks",
      "rotation": 6
    },
    {
      "x": -17,
      "y": 20,
      "z": -8,
      "name": "Wood_Hardwood_Planks",
      "rotation": 14
    },
    {
      "x": -17,
      "y": 6,
      "z": -7,
      "name": "Wood_Hardwood_Planks",
      "rotation": 14
    },
    {
      "x": -17,
      "y": 7,
      "z": -7,
      "name": "Wood_Hardwood_Planks",
      "rotation": 14
    },
    {
      "x": -17,
      "y": 8,
      "z": -7,
      "name": "Furniture_Ancient_Crate",
      "rotation": 3
    },
    {
      "x": -17,
      "y": 13,
      "z": -7,
      "name": "Wood_Hardwood_Planks",
      "rotation": 14
    },
    {
      "x": -17,
      "y": 14,
      "z": -7,
      "name": "Wood_Hardwood_Planks",
      "rotation": 51
    },
    {
      "x": -17,
      "y": 15,
      "z": -7,
      "name": "Block_Spawner_Block",
      "components": {
        "Components": {
          "PlacedByInteraction": {
            "WhoPlacedUuid": {
              "$binary": "3XRzOktQTQGfL/+8x7+CHA==",
              "$type": "04"
            }
          },
          "BlockSpawner": {
            "BlockSpawnerId": "Zone4_Encounters_Tier4"
          }
        }
      }
    },
    {
      "x": -17,
      "y": 20,
      "z": -7,
      "name": "Wood_Hardwood_Planks",
      "rotation": 4
    },
    {
      "x": -17,
      "y": 21,
      "z": -7,
      "name": "Wood_Hardwood_Planks",
      "rotation": 4
    },
    {
      "x": -17,
      "y": 5,
      "z": -6,
      "name": "Wood_Hardwood_Planks",
      "rotation": 14
    },
    {
      "x": -17,
      "y": 6,
      "z": -6,
      "name": "Wood_Hardwood_Planks",
      "rotation": 14
    },
    {
      "x": -17,
      "y": 7,
      "z": -6,
      "name": "Furniture_Ancient_Crate",
      "rotation": 3
    },
    {
      "x": -17,
      "y": 14,
      "z": -6,
      "name": "Wood_Hardwood_Planks",
      "rotation": 14
    },
    {
      "x": -17,
      "y": 21,
      "z": -6,
      "name": "Wood_Hardwood_Planks",
      "rotation": 14
    },
    {
      "x": -17,
      "y": 22,
      "z": -6,
      "name": "Wood_Hardwood_Planks",
      "rotation": 14
    },
    {
      "x": -17,
      "y": 23,
      "z": -6,
      "name": "Wood_Deadwood_Planks",
      "rotation": 14
    },
    {
      "x": -17,
      "y": 5,
      "z": -5,
      "name": "Wood_Hardwood_Planks",
      "rotation": 14
    },
    {
      "x": -17,
      "y": 6,
      "z": -5,
      "name": "Furniture_Ancient_Crate",
      "rotation": 3
    },
    {
      "x": -17,
      "y": 13,
      "z": -5,
      "name": "Wood_Hardwood_Planks",
      "rotation": 14
    },
    {
      "x": -17,
      "y": 20,
      "z": -5,
      "name": "Wood_Hardwood_Planks",
      "rotation": 14
    },
    {
      "x": -17,
      "y": 21,
      "z": -5,
      "name": "Wood_Hardwood_Planks"
    },
    {
      "x": -17,
      "y": 22,
      "z": -5,
      "name": "Wood_Hardwood_Planks",
      "rotation": 14
    },
    {
      "x": -17,
      "y": 23,
      "z": -5,
      "name": "Wood_Hardwood_Planks",
      "rotation": 14
    },
    {
      "x": -17,
      "y": 5,
      "z": -4,
      "name": "Wood_Hardwood_Planks",
      "rotation": 14
    },
    {
      "x": -17,
      "y": 6,
      "z": -4,
      "name": "Furniture_Ancient_Crate",
      "rotation": 3
    },
    {
      "x": -17,
      "y": 12,
      "z": -4,
      "name": "Wood_Hardwood_Planks",
      "rotation": 14
    },
    {
      "x": -17,
      "y": 19,
      "z": -4,
      "name": "Wood_Hardwood_Planks",
      "rotation": 14
    },
    {
      "x": -17,
      "y": 4,
      "z": -3,
      "name": "Wood_Hardwood_Planks",
      "rotation": 14
    },
    {
      "x": -17,
      "y": 6,
      "z": -3,
      "name": "Wood_Hardwood_Planks",
      "rotation": 14
    },
    {
      "x": -17,
      "y": 11,
      "z": -3,
      "name": "Wood_Hardwood_Planks",
      "rotation": 14
    },
    {
      "x": -17,
      "y": 18,
      "z": -3,
      "name": "Wood_Hardwood_Planks",
      "rotation": 14
    },
    {
      "x": -17,
      "y": 4,
      "z": -2,
      "name": "Wood_Hardwood_Planks",
      "rotation": 14
    },
    {
      "x": -17,
      "y": 7,
      "z": -2,
      "name": "Wood_Hardwood_Planks",
      "rotation": 14
    },
    {
      "x": -17,
      "y": 10,
      "z": -2,
      "name": "Wood_Hardwood_Planks",
      "rotation": 14
    },
    {
      "x": -17,
      "y": 11,
      "z": -2,
      "name": "Furniture_Ancient_Barrel"
    },
    {
      "x": -17,
      "y": 17,
      "z": -2,
      "name": "Wood_Hardwood_Planks",
      "rotation": 14
    },
    {
      "x": -17,
      "y": 4,
      "z": -1,
      "name": "Wood_Hardwood_Planks",
      "rotation": 14
    },
    {
      "x": -17,
      "y": 5,
      "z": -1,
      "name": "Wood_Hardwood_Planks",
      "rotation": 14
    },
    {
      "x": -17,
      "y": 6,
      "z": -1,
      "name": "Wood_Hardwood_Planks",
      "rotation": 14
    },
    {
      "x": -17,
      "y": 7,
      "z": -1,
      "name": "Wood_Hardwood_Planks",
      "rotation": 51
    },
    {
      "x": -17,
      "y": 8,
      "z": -1,
      "name": "Wood_Hardwood_Planks",
      "rotation": 14
    },
    {
      "x": -17,
      "y": 9,
      "z": -1,
      "name": "Wood_Hardwood_Planks",
      "rotation": 14
    },
    {
      "x": -17,
      "y": 18,
      "z": -1,
      "name": "Wood_Deadwood_Planks",
      "rotation": 14
    },
    {
      "x": -17,
      "y": 4,
      "z": 0,
      "name": "Wood_Hardwood_Planks",
      "rotation": 14
    },
    {
      "x": -17,
      "y": 6,
      "z": 0,
      "name": "Wood_Hardwood_Planks",
      "rotation": 14
    },
    {
      "x": -17,
      "y": 7,
      "z": 0,
      "name": "Wood_Hardwood_Planks",
      "rotation": 51
    },
    {
      "x": -17,
      "y": 4,
      "z": 1,
      "name": "Wood_Hardwood_Planks",
      "rotation": 14
    },
    {
      "x": -17,
      "y": 7,
      "z": 1,
      "name": "Wood_Hardwood_Planks",
      "rotation": 14
    },
    {
      "x": -17,
      "y": 4,
      "z": 2,
      "name": "Wood_Hardwood_Planks",
      "rotation": 14
    },
    {
      "x": -17,
      "y": 6,
      "z": 2,
      "name": "Wood_Hardwood_Planks",
      "rotation": 14
    },
    {
      "x": -17,
      "y": 13,
      "z": 2,
      "name": "Wood_Hardwood_Planks",
      "rotation": 14
    },
    {
      "x": -17,
      "y": 5,
      "z": 3,
      "name": "Wood_Hardwood_Planks",
      "rotation": 14
    },
    {
      "x": -17,
      "y": 12,
      "z": 3,
      "name": "Wood_Hardwood_Planks",
      "rotation": 14
    },
    {
      "x": -17,
      "y": 13,
      "z": 3,
      "name": "Wood_Deadwood_Planks",
      "rotation": 14
    },
    {
      "x": -17,
      "y": 14,
      "z": 3,
      "name": "Wood_Deadwood_Planks",
      "rotation": 14
    },
    {
      "x": -17,
      "y": 6,
      "z": 4,
      "name": "Wood_Hardwood_Ornate",
      "rotation": 14
    },
    {
      "x": -17,
      "y": 11,
      "z": 4,
      "name": "Wood_Hardwood_Planks",
      "rotation": 14
    },
    {
      "x": -17,
      "y": 7,
      "z": 5,
      "name": "Wood_Hardwood_Planks",
      "rotation": 14
    },
    {
      "x": -17,
      "y": 10,
      "z": 5,
      "name": "Wood_Hardwood_Planks",
      "rotation": 14
    },
    {
      "x": -17,
      "y": 8,
      "z": 6,
      "name": "Wood_Hardwood_Planks",
      "rotation": 4
    },
    {
      "x": -17,
      "y": 9,
      "z": 6,
      "name": "Wood_Hardwood_Planks",
      "rotation": 14
    },
    {
      "x": -17,
      "y": 38,
      "z": 6,
      "name": "Wood_Hardwood_Planks",
      "rotation": 4
    },
    {
      "x": -17,
      "y": 9,
      "z": 7,
      "name": "Wood_Hardwood_Planks",
      "rotation": 14
    },
    {
      "x": -17,
      "y": 37,
      "z": 7,
      "name": "Wood_Hardwood_Planks",
      "rotation": 4
    },
    {
      "x": -17,
      "y": 38,
      "z": 7,
      "name": "Wood_Hardwood_Planks",
      "rotation": 4
    },
    {
      "x": -17,
      "y": 39,
      "z": 7,
      "name": "Wood_Deadwood_Planks",
      "rotation": 14
    },
    {
      "x": -17,
      "y": 8,
      "z": 8,
      "name": "Wood_Deadwood_Planks",
      "rotation": 14
    },
    {
      "x": -17,
      "y": 9,
      "z": 8,
      "name": "Wood_Deadwood_Planks",
      "rotation": 14
    },
    {
      "x": -17,
      "y": 10,
      "z": 8,
      "name": "Wood_Hardwood_Planks",
      "rotation": 14
    },
    {
      "x": -17,
      "y": 38,
      "z": 8,
      "name": "Wood_Deadwood_Planks",
      "rotation": 14
    },
    {
      "x": -17,
      "y": 49,
      "z": 20,
      "name": "Wood_Hardwood_Planks",
      "rotation": 4
    },
    {
      "x": -17,
      "y": 48,
      "z": 21,
      "name": "Wood_Hardwood_Planks",
      "rotation": 4
    },
    {
      "x": -17,
      "y": 49,
      "z": 21,
      "name": "Wood_Deadwood_Planks",
      "rotation": 14
    },
    {
      "x": -17,
      "y": 48,
      "z": 22,
      "name": "Wood_Deadwood_Planks",
      "rotation": 14
    },
    {
      "x": -17,
      "y": 56,
      "z": 32,
      "name": "Wood_Hardwood_Planks",
      "rotation": 4
    },
    {
      "x": -17,
      "y": 57,
      "z": 32,
      "name": "Wood_Hardwood_Planks",
      "rotation": 4
    },
    {
      "x": -17,
      "y": 48,
      "z": 33,
      "name": "Wood_Hardwood_Planks",
      "rotation": 14
    },
    {
      "x": -17,
      "y": 55,
      "z": 33,
      "name": "Wood_Hardwood_Planks",
      "rotation": 4
    },
    {
      "x": -17,
      "y": 56,
      "z": 33,
      "name": "Wood_Hardwood_Planks",
      "rotation": 4
    },
    {
      "x": -17,
      "y": 57,
      "z": 33,
      "name": "Wood_Deadwood_Planks",
      "rotation": 14
    },
    {
      "x": -17,
      "y": 48,
      "z": 34,
      "name": "Wood_Hardwood_Planks",
      "rotation": 14
    },
    {
      "x": -17,
      "y": 54,
      "z": 34,
      "name": "Wood_Hardwood_Planks"
    },
    {
      "x": -17,
      "y": 55,
      "z": 34,
      "name": "Wood_Hardwood_Planks"
    },
    {
      "x": -17,
      "y": 56,
      "z": 34,
      "name": "Wood_Deadwood_Planks",
      "rotation": 14
    },
    {
      "x": -17,
      "y": 53,
      "z": 35,
      "name": "Wood_Hardwood_Planks"
    },
    {
      "x": -16,
      "y": 14,
      "z": -11,
      "name": "Wood_Hardwood_Planks",
      "rotation": 14
    },
    {
      "x": -16,
      "y": 15,
      "z": -11,
      "name": "Wood_Hardwood_Planks"
    },
    {
      "x": -16,
      "y": 16,
      "z": -11,
      "name": "Wood_Hardwood_Planks"
    },
    {
      "x": -16,
      "y": 17,
      "z": -11,
      "name": "Wood_Hardwood_Planks",
      "rotation": 14
    },
    {
      "x": -16,
      "y": 9,
      "z": -10,
      "name": "Wood_Hardwood_Planks",
      "rotation": 14
    },
    {
      "x": -16,
      "y": 10,
      "z": -10,
      "name": "Wood_Hardwood_Planks"
    },
    {
      "x": -16,
      "y": 11,
      "z": -10,
      "name": "Wood_Hardwood_Planks",
      "rotation": 14
    },
    {
      "x": -16,
      "y": 12,
      "z": -10,
      "name": "Wood_Hardwood_Planks",
      "rotation": 17
    },
    {
      "x": -16,
      "y": 13,
      "z": -10,
      "name": "Wood_Hardwood_Planks",
      "rotation": 14
    },
    {
      "x": -16,
      "y": 14,
      "z": -10,
      "name": "Wood_Hardwood_Planks",
      "rotation": 14
    },
    {
      "x": -16,
      "y": 15,
      "z": -10,
      "name": "Wood_Hardwood_Planks"
    },
    {
      "x": -16,
      "y": 16,
      "z": -10,
      "name": "Wood_Hardwood_Planks"
    },
    {
      "x": -16,
      "y": 17,
      "z": -10,
      "name": "Wood_Hardwood_Planks",
      "rotation": 14
    },
    {
      "x": -16,
      "y": 18,
      "z": -10,
      "name": "Wood_Hardwood_Planks",
      "rotation": 14
    },
    {
      "x": -16,
      "y": 8,
      "z": -9,
      "name": "Wood_Hardwood_Planks",
      "rotation": 14
    },
    {
      "x": -16,
      "y": 9,
      "z": -9,
      "name": "Wood_Hardwood_Planks",
      "rotation": 14
    },
    {
      "x": -16,
      "y": 11,
      "z": -9,
      "name": "Wood_Hardwood_Planks",
      "rotation": 14
    },
    {
      "x": -16,
      "y": 12,
      "z": -9,
      "name": "Wood_Hardwood_Planks",
      "rotation": 17
    },
    {
      "x": -16,
      "y": 13,
      "z": -9,
      "name": "Wood_Hardwood_Planks",
      "rotation": 17
    },
    {
      "x": -16,
      "y": 14,
      "z": -9,
      "name": "Wood_Hardwood_Planks",
      "rotation": 14
    },
    {
      "x": -16,
      "y": 17,
      "z": -9,
      "name": "Wood_Hardwood_Planks",
      "rotation": 14
    },
    {
      "x": -16,
      "y": 18,
      "z": -9,
      "name": "Wood_Hardwood_Planks",
      "rotation": 4
    },
    {
      "x": -16,
      "y": 19,
      "z": -9,
      "name": "Wood_Hardwood_Planks",
      "rotation": 4
    },
    {
      "x": -16,
      "y": 0,
      "z": -8,
      "name": "Rock_Ice"
    },
    {
      "x": -16,
      "y": 1,
      "z": -8,
      "name": "Rock_Ice"
    },
    {
      "x": -16,
      "y": 2,
      "z": -8,
      "name": "Rock_Ice"
    },
    {
      "x": -16,
      "y": 6,
      "z": -8,
      "name": "Wood_Hardwood_Planks",
      "rotation": 14
    },
    {
      "x": -16,
      "y": 7,
      "z": -8,
      "name": "Wood_Hardwood_Planks",
      "rotation": 14
    },
    {
      "x": -16,
      "y": 8,
      "z": -8,
      "name": "Wood_Hardwood_Planks",
      "rotation": 14
    },
    {
      "x": -16,
      "y": 12,
      "z": -8,
      "name": "Wood_Hardwood_Planks",
      "rotation": 14
    },
    {
      "x": -16,
      "y": 13,
      "z": -8,
      "name": "Wood_Hardwood_Planks",
      "rotation": 17
    },
    {
      "x": -16,
      "y": 14,
      "z": -8,
      "name": "Wood_Hardwood_Planks",
      "rotation": 17
    },
    {
      "x": -16,
      "y": 15,
      "z": -8,
      "name": "Wood_Hardwood_Planks",
      "rotation": 14
    },
    {
      "x": -16,
      "y": 16,
      "z": -8,
      "name": "Wood_Hardwood_Planks",
      "rotation": 14
    },
    {
      "x": -16,
      "y": 19,
      "z": -8,
      "name": "Wood_Hardwood_Planks",
      "rotation": 14
    },
    {
      "x": -16,
      "y": 20,
      "z": -8,
      "name": "Wood_Hardwood_Planks",
      "rotation": 14
    },
    {
      "x": -16,
      "y": -2,
      "z": -7,
      "name": "Rock_Ice"
    },
    {
      "x": -16,
      "y": -1,
      "z": -7,
      "name": "Rock_Ice"
    },
    {
      "x": -16,
      "y": 0,
      "z": -7,
      "name": "Rock_Ice"
    },
    {
      "x": -16,
      "y": 1,
      "z": -7,
      "name": "Rock_Ice"
    },
    {
      "x": -16,
      "y": 2,
      "z": -7,
      "name": "Rock_Ice"
    },
    {
      "x": -16,
      "y": 3,
      "z": -7,
      "name": "Rock_Ice"
    },
    {
      "x": -16,
      "y": 4,
      "z": -7,
      "name": "Rock_Ice"
    },
    {
      "x": -16,
      "y": 6,
      "z": -7,
      "name": "Wood_Hardwood_Planks",
      "rotation": 14
    },
    {
      "x": -16,
      "y": 7,
      "z": -7,
      "name": "Wood_Hardwood_Planks",
      "rotation": 14
    },
    {
      "x": -16,
      "y": 8,
      "z": -7,
      "name": "Furniture_Ancient_Crate",
      "rotation": 3
    },
    {
      "x": -16,
      "y": 13,
      "z": -7,
      "name": "Wood_Hardwood_Planks",
      "rotation": 14
    },
    {
      "x": -16,
      "y": 14,
      "z": -7,
      "name": "Wood_Hardwood_Planks",
      "rotation": 17
    },
    {
      "x": -16,
      "y": 15,
      "z": -7,
      "name": "Wood_Hardwood_Planks",
      "rotation": 51
    },
    {
      "x": -16,
      "y": 20,
      "z": -7,
      "name": "Wood_Hardwood_Planks",
      "rotation": 4
    },
    {
      "x": -16,
      "y": 21,
      "z": -7,
      "name": "Wood_Hardwood_Planks",
      "rotation": 4
    },
    {
      "x": -16,
      "y": -3,
      "z": -6,
      "name": "Rock_Ice"
    },
    {
      "x": -16,
      "y": -2,
      "z": -6,
      "name": "Rock_Ice"
    },
    {
      "x": -16,
      "y": -1,
      "z": -6,
      "name": "Rock_Ice"
    },
    {
      "x": -16,
      "y": 0,
      "z": -6,
      "name": "Rock_Ice"
    },
    {
      "x": -16,
      "y": 1,
      "z": -6,
      "name": "Rock_Ice"
    },
    {
      "x": -16,
      "y": 2,
      "z": -6,
      "name": "Rock_Ice"
    },
    {
      "x": -16,
      "y": 3,
      "z": -6,
      "name": "Rock_Ice"
    },
    {
      "x": -16,
      "y": 4,
      "z": -6,
      "name": "Rock_Ice"
    },
    {
      "x": -16,
      "y": 5,
      "z": -6,
      "name": "Wood_Hardwood_Planks",
      "rotation": 14
    },
    {
      "x": -16,
      "y": 6,
      "z": -6,
      "name": "Wood_Hardwood_Planks",
      "rotation": 14
    },
    {
      "x": -16,
      "y": 7,
      "z": -6,
      "name": "Furniture_Ancient_Crate",
      "rotation": 3
    },
    {
      "x": -16,
      "y": 14,
      "z": -6,
      "name": "Wood_Hardwood_Planks",
      "rotation": 14
    },
    {
      "x": -16,
      "y": 21,
      "z": -6,
      "name": "Wood_Hardwood_Planks",
      "rotation": 14
    },
    {
      "x": -16,
      "y": 22,
      "z": -6,
      "name": "Wood_Hardwood_Planks",
      "rotation": 14
    },
    {
      "x": -16,
      "y": 23,
      "z": -6,
      "name": "Wood_Deadwood_Planks",
      "rotation": 14
    },
    {
      "x": -16,
      "y": -2,
      "z": -5,
      "name": "Rock_Ice"
    },
    {
      "x": -16,
      "y": -1,
      "z": -5,
      "name": "Rock_Ice"
    },
    {
      "x": -16,
      "y": 0,
      "z": -5,
      "name": "Rock_Ice"
    },
    {
      "x": -16,
      "y": 1,
      "z": -5,
      "name": "Rock_Ice"
    },
    {
      "x": -16,
      "y": 2,
      "z": -5,
      "name": "Rock_Ice"
    },
    {
      "x": -16,
      "y": 3,
      "z": -5,
      "name": "Rock_Ice"
    },
    {
      "x": -16,
      "y": 4,
      "z": -5,
      "name": "Rock_Ice"
    },
    {
      "x": -16,
      "y": 5,
      "z": -5,
      "name": "Wood_Hardwood_Planks",
      "rotation": 14
    },
    {
      "x": -16,
      "y": 6,
      "z": -5,
      "name": "Furniture_Ancient_Crate",
      "rotation": 3
    },
    {
      "x": -16,
      "y": 7,
      "z": -5,
      "name": "Furniture_Ancient_Crate",
      "rotation": 3
    },
    {
      "x": -16,
      "y": 13,
      "z": -5,
      "name": "Wood_Hardwood_Planks",
      "rotation": 14
    },
    {
      "x": -16,
      "y": 20,
      "z": -5,
      "name": "Wood_Hardwood_Planks",
      "rotation": 14
    },
    {
      "x": -16,
      "y": 21,
      "z": -5,
      "name": "Wood_Hardwood_Planks"
    },
    {
      "x": -16,
      "y": 22,
      "z": -5,
      "name": "Wood_Hardwood_Planks",
      "rotation": 14
    },
    {
      "x": -16,
      "y": 0,
      "z": -4,
      "name": "Rock_Ice"
    },
    {
      "x": -16,
      "y": 1,
      "z": -4,
      "name": "Rock_Ice"
    },
    {
      "x": -16,
      "y": 2,
      "z": -4,
      "name": "Rock_Ice"
    },
    {
      "x": -16,
      "y": 5,
      "z": -4,
      "name": "Wood_Hardwood_Planks",
      "rotation": 14
    },
    {
      "x": -16,
      "y": 6,
      "z": -4,
      "name": "Furniture_Ancient_Crate",
      "rotation": 3
    },
    {
      "x": -16,
      "y": 7,
      "z": -4,
      "name": "Furniture_Ancient_Crate",
      "rotation": 3
    },
    {
      "x": -16,
      "y": 12,
      "z": -4,
      "name": "Wood_Hardwood_Planks",
      "rotation": 14
    },
    {
      "x": -16,
      "y": 19,
      "z": -4,
      "name": "Wood_Hardwood_Planks",
      "rotation": 14
    },
    {
      "x": -16,
      "y": 4,
      "z": -3,
      "name": "Wood_Hardwood_Planks",
      "rotation": 14
    },
    {
      "x": -16,
      "y": 5,
      "z": -3,
      "name": "Wood_Hardwood_Planks",
      "rotation": 17
    },
    {
      "x": -16,
      "y": 6,
      "z": -3,
      "name": "Wood_Hardwood_Planks",
      "rotation": 14
    },
    {
      "x": -16,
      "y": 11,
      "z": -3,
      "name": "Wood_Hardwood_Planks",
      "rotation": 14
    },
    {
      "x": -16,
      "y": 18,
      "z": -3,
      "name": "Wood_Hardwood_Planks",
      "rotation": 14
    },
    {
      "x": -16,
      "y": 4,
      "z": -2,
      "name": "Wood_Hardwood_Planks",
      "rotation": 14
    },
    {
      "x": -16,
      "y": 5,
      "z": -2,
      "name": "Wood_Hardwood_Planks",
      "rotation": 17
    },
    {
      "x": -16,
      "y": 6,
      "z": -2,
      "name": "Wood_Hardwood_Planks",
      "rotation": 17
    },
    {
      "x": -16,
      "y": 7,
      "z": -2,
      "name": "Wood_Hardwood_Planks",
      "rotation": 14
    },
    {
      "x": -16,
      "y": 10,
      "z": -2,
      "name": "Wood_Hardwood_Planks",
      "rotation": 14
    },
    {
      "x": -16,
      "y": 17,
      "z": -2,
      "name": "Wood_Hardwood_Planks",
      "rotation": 14
    },
    {
      "x": -16,
      "y": 4,
      "z": -1,
      "name": "Wood_Hardwood_Planks",
      "rotation": 14
    },
    {
      "x": -16,
      "y": 5,
      "z": -1,
      "name": "Wood_Hardwood_Planks",
      "rotation": 14
    },
    {
      "x": -16,
      "y": 6,
      "z": -1,
      "name": "Wood_Hardwood_Planks",
      "rotation": 17
    },
    {
      "x": -16,
      "y": 7,
      "z": -1,
      "name": "Wood_Hardwood_Planks",
      "rotation": 17
    },
    {
      "x": -16,
      "y": 8,
      "z": -1,
      "name": "Wood_Hardwood_Planks",
      "rotation": 14
    },
    {
      "x": -16,
      "y": 9,
      "z": -1,
      "name": "Wood_Hardwood_Planks",
      "rotation": 14
    },
    {
      "x": -16,
      "y": 16,
      "z": -1,
      "name": "Wood_Hardwood_Planks",
      "rotation": 14
    },
    {
      "x": -16,
      "y": 17,
      "z": -1,
      "name": "Wood_Deadwood_Planks",
      "rotation": 14
    },
    {
      "x": -16,
      "y": 4,
      "z": 0,
      "name": "Wood_Hardwood_Planks",
      "rotation": 14
    },
    {
      "x": -16,
      "y": 6,
      "z": 0,
      "name": "Wood_Hardwood_Planks",
      "rotation": 14
    },
    {
      "x": -16,
      "y": 7,
      "z": 0,
      "name": "Wood_Hardwood_Planks",
      "rotation": 17
    },
    {
      "x": -16,
      "y": 8,
      "z": 0,
      "name": "Wood_Hardwood_Planks",
      "rotation": 51
    },
    {
      "x": -16,
      "y": 15,
      "z": 0,
      "name": "Wood_Hardwood_Planks",
      "rotation": 14
    },
    {
      "x": -16,
      "y": 16,
      "z": 0,
      "name": "Wood_Deadwood_Planks",
      "rotation": 14
    },
    {
      "x": -16,
      "y": 17,
      "z": 0,
      "name": "Wood_Deadwood_Planks",
      "rotation": 14
    },
    {
      "x": -16,
      "y": 4,
      "z": 1,
      "name": "Wood_Hardwood_Planks",
      "rotation": 14
    },
    {
      "x": -16,
      "y": 7,
      "z": 1,
      "name": "Wood_Hardwood_Planks",
      "rotation": 14
    },
    {
      "x": -16,
      "y": 14,
      "z": 1,
      "name": "Wood_Hardwood_Planks",
      "rotation": 14
    },
    {
      "x": -16,
      "y": 15,
      "z": 1,
      "name": "Wood_Deadwood_Planks",
      "rotation": 14
    },
    {
      "x": -16,
      "y": 16,
      "z": 1,
      "name": "Wood_Deadwood_Planks",
      "rotation": 14
    },
    {
      "x": -16,
      "y": 4,
      "z": 2,
      "name": "Wood_Hardwood_Planks",
      "rotation": 14
    },
    {
      "x": -16,
      "y": 6,
      "z": 2,
      "name": "Wood_Hardwood_Planks",
      "rotation": 14
    },
    {
      "x": -16,
      "y": 7,
      "z": 2,
      "name": "Furniture_Ancient_Barrel"
    },
    {
      "x": -16,
      "y": 13,
      "z": 2,
      "name": "Wood_Hardwood_Planks",
      "rotation": 14
    },
    {
      "x": -16,
      "y": 14,
      "z": 2,
      "name": "Wood_Deadwood_Planks",
      "rotation": 14
    },
    {
      "x": -16,
      "y": 15,
      "z": 2,
      "name": "Wood_Deadwood_Planks",
      "rotation": 14
    },
    {
      "x": -16,
      "y": 5,
      "z": 3,
      "name": "Wood_Hardwood_Planks",
      "rotation": 14
    },
    {
      "x": -16,
      "y": 6,
      "z": 3,
      "name": "Wood_Sticks",
      "support": 15
    },
    {
      "x": -16,
      "y": 12,
      "z": 3,
      "name": "Wood_Hardwood_Planks",
      "rotation": 14
    },
    {
      "x": -16,
      "y": 6,
      "z": 4,
      "name": "Wood_Hardwood_Planks",
      "rotation": 4
    },
    {
      "x": -16,
      "y": 11,
      "z": 4,
      "name": "Wood_Hardwood_Planks",
      "rotation": 14
    },
    {
      "x": -16,
      "y": 7,
      "z": 5,
      "name": "Wood_Hardwood_Planks",
      "rotation": 14
    },
    {
      "x": -16,
      "y": 10,
      "z": 5,
      "name": "Wood_Hardwood_Planks",
      "rotation": 14
    },
    {
      "x": -16,
      "y": 11,
      "z": 5,
      "name": "Wood_Sticks",
      "support": 15
    },
    {
      "x": -16,
      "y": 8,
      "z": 6,
      "name": "Wood_Hardwood_Planks",
      "rotation": 4
    },
    {
      "x": -16,
      "y": 9,
      "z": 6,
      "name": "Wood_Hardwood_Planks",
      "rotation": 14
    },
    {
      "x": -16,
      "y": 31,
      "z": 6,
      "name": "Cloth_Block_Wool_Gray_Light_Half",
      "rotation": 5
    },
    {
      "x": -16,
      "y": 32,
      "z": 6,
      "name": "Cloth_Block_Wool_Gray_Light_Half",
      "rotation": 5
    },
    {
      "x": -16,
      "y": 33,
      "z": 6,
      "name": "Cloth_Block_Wool_Gray_Light_Half",
      "rotation": 5
    },
    {
      "x": -16,
      "y": 34,
      "z": 6,
      "name": "Cloth_Block_Wool_Gray_Light_Half",
      "rotation": 5
    },
    {
      "x": -16,
      "y": 35,
      "z": 6,
      "name": "Cloth_Block_Wool_Gray_Light_Half",
      "rotation": 5
    },
    {
      "x": -16,
      "y": 36,
      "z": 6,
      "name": "Cloth_Block_Wool_Gray_Light_Half",
      "rotation": 5
    },
    {
      "x": -16,
      "y": 37,
      "z": 6,
      "name": "Cloth_Block_Wool_Gray_Light_Half",
      "rotation": 5
    },
    {
      "x": -16,
      "y": 38,
      "z": 6,
      "name": "Cloth_Block_Wool_Gray_Light_Half",
      "rotation": 5
    },
    {
      "x": -16,
      "y": 8,
      "z": 7,
      "name": "Wood_Hardwood_Planks",
      "rotation": 14
    },
    {
      "x": -16,
      "y": 9,
      "z": 7,
      "name": "Wood_Hardwood_Planks",
      "rotation": 14
    },
    {
      "x": -16,
      "y": 32,
      "z": 7,
      "name": "*Cloth_Block_Wool_Gray_Light_Half_State_Definitions_Block",
      "rotation": 5
    },
    {
      "x": -16,
      "y": 33,
      "z": 7,
      "name": "*Cloth_Block_Wool_Gray_Light_Half_State_Definitions_Block",
      "rotation": 5
    },
    {
      "x": -16,
      "y": 34,
      "z": 7,
      "name": "*Cloth_Block_Wool_Gray_Light_Half_State_Definitions_Block",
      "rotation": 5
    },
    {
      "x": -16,
      "y": 35,
      "z": 7,
      "name": "*Cloth_Block_Wool_Gray_Light_Half_State_Definitions_Block",
      "rotation": 5
    },
    {
      "x": -16,
      "y": 36,
      "z": 7,
      "name": "*Cloth_Block_Wool_Gray_Light_Half_State_Definitions_Block",
      "rotation": 5
    },
    {
      "x": -16,
      "y": 37,
      "z": 7,
      "name": "*Cloth_Block_Wool_Gray_Light_Half_State_Definitions_Block",
      "rotation": 5
    },
    {
      "x": -16,
      "y": 38,
      "z": 7,
      "name": "*Cloth_Block_Wool_Gray_Light_Half_State_Definitions_Block",
      "rotation": 5
    },
    {
      "x": -16,
      "y": 39,
      "z": 7,
      "name": "Cloth_Block_Wool_Gray_Light_Half",
      "rotation": 5
    },
    {
      "x": -16,
      "y": 7,
      "z": 8,
      "name": "Wood_Hardwood_Planks",
      "rotation": 14
    },
    {
      "x": -16,
      "y": 8,
      "z": 8,
      "name": "Wood_Deadwood_Planks",
      "rotation": 14
    },
    {
      "x": -16,
      "y": 9,
      "z": 8,
      "name": "Wood_Deadwood_Planks",
      "rotation": 14
    },
    {
      "x": -16,
      "y": 36,
      "z": 8,
      "name": "Wood_Hardwood_Planks",
      "rotation": 4
    },
    {
      "x": -16,
      "y": 37,
      "z": 8,
      "name": "Wood_Hardwood_Planks",
      "rotation": 4
    },
    {
      "x": -16,
      "y": 38,
      "z": 8,
      "name": "*Cloth_Block_Wool_Gray_Light_Half_State_Definitions_Block",
      "rotation": 5
    },
    {
      "x": -16,
      "y": 35,
      "z": 9,
      "name": "Wood_Hardwood_Planks",
      "rotation": 4
    },
    {
      "x": -16,
      "y": 36,
      "z": 9,
      "name": "Wood_Hardwood_Planks",
      "rotation": 4
    },
    {
      "x": -16,
      "y": 37,
      "z": 9,
      "name": "Wood_Deadwood_Planks",
      "rotation": 14
    },
    {
      "x": -16,
      "y": 36,
      "z": 10,
      "name": "Wood_Deadwood_Planks",
      "rotation": 14
    },
    {
      "x": -16,
      "y": 42,
      "z": 20,
      "name": "Cloth_Block_Wool_Gray_Light_Half",
      "rotation": 5
    },
    {
      "x": -16,
      "y": 43,
      "z": 20,
      "name": "Cloth_Block_Wool_Gray_Light_Half",
      "rotation": 5
    },
    {
      "x": -16,
      "y": 44,
      "z": 20,
      "name": "Cloth_Block_Wool_Gray_Light_Half",
      "rotation": 5
    },
    {
      "x": -16,
      "y": 45,
      "z": 20,
      "name": "Cloth_Block_Wool_Gray_Light_Half",
      "rotation": 5
    },
    {
      "x": -16,
      "y": 46,
      "z": 20,
      "name": "Cloth_Block_Wool_Gray_Light_Half",
      "rotation": 5
    },
    {
      "x": -16,
      "y": 47,
      "z": 20,
      "name": "Cloth_Block_Wool_Gray_Light_Half",
      "rotation": 5
    },
    {
      "x": -16,
      "y": 48,
      "z": 20,
      "name": "Cloth_Block_Wool_Gray_Light_Half",
      "rotation": 5
    },
    {
      "x": -16,
      "y": 49,
      "z": 20,
      "name": "Cloth_Block_Wool_Gray_Light_Half",
      "rotation": 5
    },
    {
      "x": -16,
      "y": 45,
      "z": 21,
      "name": "*Cloth_Block_Wool_Gray_Light_Half_State_Definitions_Block",
      "rotation": 5
    },
    {
      "x": -16,
      "y": 46,
      "z": 21,
      "name": "*Cloth_Block_Wool_Gray_Light_Half_State_Definitions_Block",
      "rotation": 5
    },
    {
      "x": -16,
      "y": 47,
      "z": 21,
      "name": "*Cloth_Block_Wool_Gray_Light_Half_State_Definitions_Block",
      "rotation": 5
    },
    {
      "x": -16,
      "y": 48,
      "z": 21,
      "name": "*Cloth_Block_Wool_Gray_Light_Half_State_Definitions_Block",
      "rotation": 5
    },
    {
      "x": -16,
      "y": 49,
      "z": 21,
      "name": "*Cloth_Block_Wool_Gray_Light_Half_State_Definitions_Block",
      "rotation": 5
    },
    {
      "x": -16,
      "y": 47,
      "z": 22,
      "name": "Wood_Hardwood_Planks",
      "rotation": 4
    },
    {
      "x": -16,
      "y": 48,
      "z": 22,
      "name": "*Cloth_Block_Wool_Gray_Light_Half_State_Definitions_Block",
      "rotation": 5
    },
    {
      "x": -16,
      "y": 46,
      "z": 23,
      "name": "Wood_Hardwood_Planks",
      "rotation": 4
    },
    {
      "x": -16,
      "y": 47,
      "z": 23,
      "name": "Wood_Deadwood_Planks",
      "rotation": 14
    },
    {
      "x": -16,
      "y": 45,
      "z": 24,
      "name": "Wood_Hardwood_Planks",
      "rotation": 4
    },
    {
