{
  "version": 8,
  "blockIdVersion": 11,
  "anchorX": 0,
  "anchorY": 0,
  "anchorZ": 0,
  "blocks": [
    {
      "x": -18,
      "y": 33,
      "z": 1,
      "name": "Wood_Deadwood_Planks",
      "rotation": 1
    },
    {
      "x": -18,
      "y": 32,
      "z": 2,
      "name": "Wood_Hardwood_Planks",
      "rotation": 3
    },
    {
      "x": -18,
      "y": 33,
      "z": 2,
      "name": "Wood_Hardwood_Planks",
      "rotation": 3
    },
    {
      "x": -18,
      "y": 26,
      "z": 3,
      "name": "Cloth_Block_Wool_Gray_Light_Half",
      "rotation": 4
    },
    {
      "x": -18,
      "y": 27,
      "z": 3,
      "name": "Cloth_Block_Wool_Gray_Light_Half",
      "rotation": 4
    },
    {
      "x": -18,
      "y": 28,
      "z": 3,
      "name": "Cloth_Block_Wool_Gray_Light_Half",
      "rotation": 4
    },
    {
      "x": -18,
      "y": 29,
      "z": 3,
      "name": "Cloth_Block_Wool_Gray_Light_Half",
      "rotation": 4
    },
    {
      "x": -18,
      "y": 30,
      "z": 3,
      "name": "Cloth_Block_Wool_Gray_Light_Half",
      "rotation": 4
    },
    {
      "x": -18,
      "y": 31,
      "z": 3,
      "name": "Cloth_Block_Wool_Gray_Light_Half",
      "rotation": 4
    },
    {
      "x": -18,
      "y": 32,
      "z": 3,
      "name": "Cloth_Block_Wool_Gray_Light_Half",
      "rotation": 4
    },
    {
      "x": -18,
      "y": 33,
      "z": 3,
      "name": "Cloth_Block_Wool_Gray_Light_Half",
      "rotation": 4
    },
    {
      "x": -18,
      "y": 5,
      "z": 7,
      "name": "Rock_Ice",
      "rotation": 2
    },
    {
      "x": -18,
      "y": 6,
      "z": 7,
      "name": "Rock_Ice",
      "rotation": 2
    },
    {
      "x": -18,
      "y": 7,
      "z": 7,
      "name": "Rock_Ice",
      "rotation": 2
    },
    {
      "x": -18,
      "y": 8,
      "z": 7,
      "name": "Rock_Ice",
      "rotation": 2
    },
    {
      "x": -18,
      "y": 9,
      "z": 7,
      "name": "Rock_Ice",
      "rotation": 2
    },
    {
      "x": -18,
      "y": 5,
      "z": 8,
      "name": "Rock_Ice",
      "rotation": 2
    },
    {
      "x": -18,
      "y": 6,
      "z": 8,
      "name": "Rock_Ice",
      "rotation": 2
    },
    {
      "x": -18,
      "y": 7,
      "z": 8,
      "name": "Rock_Ice",
      "rotation": 2
    },
    {
      "x": -18,
      "y": 8,
      "z": 8,
      "name": "Rock_Ice",
      "rotation": 2
    },
    {
      "x": -18,
      "y": 9,
      "z": 8,
      "name": "Rock_Ice",
      "rotation": 2
    },
    {
      "x": -18,
      "y": 10,
      "z": 8,
      "name": "Rock_Ice",
      "rotation": 2
    },
    {
      "x": -18,
      "y": 5,
      "z": 9,
      "name": "Rock_Ice",
      "rotation": 2
    },
    {
      "x": -18,
      "y": 6,
      "z": 9,
      "name": "Rock_Ice",
      "rotation": 2
    },
    {
      "x": -18,
      "y": 4,
      "z": 12,
      "name": "Rock_Ice",
      "rotation": 2
    },
    {
      "x": -18,
      "y": 4,
      "z": 13,
      "name": "Rock_Ice",
      "rotation": 2
    },
    {
      "x": -17,
      "y": 33,
      "z": 1,
      "name": "Wood_Deadwood_Planks",
      "rotation": 1
    },
    {
      "x": -17,
      "y": 32,
      "z": 2,
      "name": "Wood_Hardwood_Planks",
      "rotation": 3
    },
    {
      "x": -17,
      "y": 33,
      "z": 2,
      "name": "Wood_Hardwood_Planks",
      "rotation": 3
    },
    {
      "x": -17,
      "y": 28,
      "z": 3,
      "name": "Cloth_Block_Wool_Gray_Light_Half",
      "rotation": 4
    },
    {
      "x": -17,
      "y": 29,
      "z": 3,
      "name": "Cloth_Block_Wool_Gray_Light_Half",
      "rotation": 4
    },
    {
      "x": -17,
      "y": 30,
      "z": 3,
      "name": "Cloth_Block_Wool_Gray_Light_Half",
      "rotation": 4
    },
    {
      "x": -17,
      "y": 31,
      "z": 3,
      "name": "Cloth_Block_Wool_Gray_Light_Half",
      "rotation": 4
    },
    {
      "x": -17,
      "y": 32,
      "z": 3,
      "name": "Cloth_Block_Wool_Gray_Light_Half",
      "rotation": 4
    },
    {
      "x": -17,
      "y": 33,
      "z": 3,
      "name": "Cloth_Block_Wool_Gray_Light_Half",
      "rotation": 4
    },
    {
      "x": -17,
      "y": 6,
      "z": 6,
      "name": "Rock_Ice",
      "rotation": 2
    },
    {
      "x": -17,
      "y": 7,
      "z": 6,
      "name": "Rock_Ice",
      "rotation": 2
    },
    {
      "x": -17,
      "y": 8,
      "z": 6,
      "name": "Rock_Ice",
      "rotation": 2
    },
    {
      "x": -17,
      "y": 9,
      "z": 6,
      "name": "Rock_Ice",
      "rotation": 2
    },
    {
      "x": -17,
      "y": 5,
      "z": 7,
      "name": "Rock_Ice",
      "rotation": 2
    },
    {
      "x": -17,
      "y": 6,
      "z": 7,
      "name": "Rock_Ice",
      "rotation": 2
    },
    {
      "x": -17,
      "y": 7,
      "z": 7,
      "name": "Rock_Ice",
      "rotation": 2
    },
    {
      "x": -17,
      "y": 8,
      "z": 7,
      "name": "Rock_Ice",
      "rotation": 2
    },
    {
      "x": -17,
      "y": 9,
      "z": 7,
      "name": "Rock_Ice",
      "rotation": 2
    },
    {
      "x": -17,
      "y": 10,
      "z": 7,
      "name": "Rock_Ice",
      "rotation": 2
    },
    {
      "x": -17,
      "y": 4,
      "z": 8,
      "name": "Rock_Ice",
      "rotation": 2
    },
    {
      "x": -17,
      "y": 5,
      "z": 8,
      "name": "Rock_Ice",
      "rotation": 2
    },
    {
      "x": -17,
      "y": 6,
      "z": 8,
      "name": "Rock_Ice",
      "rotation": 2
    },
    {
      "x": -17,
      "y": 7,
      "z": 8,
      "name": "Rock_Ice",
      "rotation": 2
    },
    {
      "x": -17,
      "y": 8,
      "z": 8,
      "name": "Rock_Ice",
      "rotation": 2
    },
    {
      "x": -17,
      "y": 9,
      "z": 8,
      "name": "Rock_Ice",
      "rotation": 2
    },
    {
      "x": -17,
      "y": 10,
      "z": 8,
      "name": "Rock_Ice",
      "rotation": 2
    },
    {
      "x": -17,
      "y": 11,
      "z": 8,
      "name": "Rock_Ice",
      "rotation": 2
    },
    {
      "x": -17,
      "y": 12,
      "z": 8,
      "name": "Rock_Ice",
      "rotation": 2
    },
    {
      "x": -17,
      "y": 4,
      "z": 9,
      "name": "Rock_Ice",
      "rotation": 2
    },
    {
      "x": -17,
      "y": 5,
      "z": 9,
      "name": "Rock_Ice",
      "rotation": 2
    },
    {
      "x": -17,
      "y": 6,
      "z": 9,
      "name": "Rock_Ice",
      "rotation": 2
    },
    {
      "x": -17,
      "y": 7,
      "z": 9,
      "name": "Rock_Ice",
      "rotation": 2
    },
    {
      "x": -17,
      "y": 8,
      "z": 9,
      "name": "Rock_Ice",
      "rotation": 2
    },
    {
      "x": -17,
      "y": 9,
      "z": 9,
      "name": "Rock_Ice",
      "rotation": 2
    },
    {
      "x": -17,
      "y": 10,
      "z": 9,
      "name": "Rock_Ice",
      "rotation": 2
    },
    {
      "x": -17,
      "y": 11,
      "z": 9,
      "name": "Rock_Ice",
      "rotation": 2
    },
    {
      "x": -17,
      "y": 12,
      "z": 9,
      "name": "Rock_Ice",
      "rotation": 2
    },
    {
      "x": -17,
      "y": 13,
      "z": 9,
      "name": "Rock_Ice",
      "rotation": 2
    },
    {
      "x": -17,
      "y": 14,
      "z": 9,
      "name": "Rock_Ice",
      "rotation": 2
    },
    {
      "x": -17,
      "y": 3,
      "z": 10,
      "name": "Rock_Ice",
      "rotation": 2
    },
    {
      "x": -17,
      "y": 4,
      "z": 10,
      "name": "Rock_Ice",
      "rotation": 2
    },
    {
      "x": -17,
      "y": 5,
      "z": 10,
      "name": "Rock_Ice",
      "rotation": 2
    },
    {
      "x": -17,
      "y": 6,
      "z": 10,
      "name": "Rock_Ice",
      "rotation": 2
    },
    {
      "x": -17,
      "y": 7,
      "z": 10,
      "name": "Rock_Ice",
      "rotation": 2
    },
    {
      "x": -17,
      "y": 8,
      "z": 10,
      "name": "Rock_Ice",
      "rotation": 2
    },
    {
      "x": -17,
      "y": 9,
      "z": 10,
      "name": "Rock_Ice",
      "rotation": 2
    },
    {
      "x": -17,
      "y": 10,
      "z": 10,
      "name": "Rock_Ice",
      "rotation": 2
    },
    {
      "x": -17,
      "y": 12,
      "z": 10,
      "name": "Rock_Ice",
      "rotation": 2
    },
    {
      "x": -17,
      "y": 13,
      "z": 10,
      "name": "Rock_Ice",
      "rotation": 2
    },
    {
      "x": -17,
      "y": 14,
      "z": 10,
      "name": "Rock_Ice",
      "rotation": 2
    },
    {
      "x": -17,
      "y": 15,
      "z": 10,
      "name": "Rock_Ice",
      "rotation": 2
    },
    {
      "x": -17,
      "y": 3,
      "z": 11,
      "name": "Rock_Ice",
      "rotation": 2
    },
    {
      "x": -17,
      "y": 4,
      "z": 11,
      "name": "Rock_Ice",
      "rotation": 2
    },
    {
      "x": -17,
      "y": 5,
      "z": 11,
      "name": "Rock_Ice",
      "rotation": 2
    },
    {
      "x": -17,
      "y": 6,
      "z": 11,
      "name": "Rock_Ice",
      "rotation": 2
    },
    {
      "x": -17,
      "y": 7,
      "z": 11,
      "name": "Rock_Ice",
      "rotation": 2
    },
    {
      "x": -17,
      "y": 8,
      "z": 11,
      "name": "Rock_Ice",
      "rotation": 2
    },
    {
      "x": -17,
      "y": 9,
      "z": 11,
      "name": "Rock_Ice",
      "rotation": 2
    },
    {
      "x": -17,
      "y": 10,
      "z": 11,
      "name": "Rock_Ice",
      "rotation": 2
    },
    {
      "x": -17,
      "y": 2,
      "z": 12,
      "name": "Rock_Ice",
      "rotation": 2
    },
    {
      "x": -17,
      "y": 3,
      "z": 12,
      "name": "Rock_Ice",
      "rotation": 2
    },
    {
      "x": -17,
      "y": 4,
      "z": 12,
      "name": "Rock_Ice",
      "rotation": 2
    },
    {
      "x": -17,
      "y": 5,
      "z": 12,
      "name": "Rock_Ice",
      "rotation": 2
    },
    {
      "x": -17,
      "y": 6,
      "z": 12,
      "name": "Rock_Ice",
      "rotation": 2
    },
    {
      "x": -17,
      "y": 7,
      "z": 12,
      "name": "Rock_Ice",
      "rotation": 2
    },
    {
      "x": -17,
      "y": 8,
      "z": 12,
      "name": "Rock_Ice",
      "rotation": 2
    },
    {
      "x": -17,
      "y": 9,
      "z": 12,
      "name": "Rock_Ice",
      "rotation": 2
    },
    {
      "x": -17,
      "y": 3,
      "z": 13,
      "name": "Rock_Ice",
      "rotation": 2
    },
    {
      "x": -17,
      "y": 4,
      "z": 13,
      "name": "Rock_Ice",
      "rotation": 2
    },
    {
      "x": -17,
      "y": 5,
      "z": 13,
      "name": "Rock_Ice",
      "rotation": 2
    },
    {
      "x": -17,
      "y": 6,
      "z": 13,
      "name": "Rock_Ice",
      "rotation": 2
    },
    {
      "x": -17,
      "y": 7,
      "z": 13,
      "name": "Rock_Ice",
      "rotation": 2
    },
    {
      "x": -17,
      "y": 8,
      "z": 13,
      "name": "Rock_Ice",
      "rotation": 2
    },
    {
      "x": -17,
      "y": 3,
      "z": 14,
      "name": "Rock_Ice",
      "rotation": 2
    },
    {
      "x": -17,
      "y": 4,
      "z": 14,
      "name": "Rock_Ice",
      "rotation": 2
    },
    {
      "x": -17,
      "y": 5,
      "z": 14,
      "name": "Rock_Ice",
      "rotation": 2
    },
    {
      "x": -17,
      "y": 6,
      "z": 14,
      "name": "Rock_Ice",
      "rotation": 2
    },
    {
      "x": -17,
      "y": 7,
      "z": 14,
      "name": "Rock_Ice",
      "rotation": 2
    },
    {
      "x": -17,
      "y": 3,
      "z": 15,
      "name": "Rock_Ice",
      "rotation": 2
    },
    {
      "x": -17,
      "y": 4,
      "z": 15,
      "name": "Rock_Ice",
      "rotation": 2
    },
    {
      "x": -17,
      "y": 5,
      "z": 15,
      "name": "Rock_Ice",
      "rotation": 2
    },
    {
      "x": -17,
      "y": 6,
      "z": 15,
      "name": "Rock_Ice",
      "rotation": 2
    },
    {
      "x": -17,
      "y": 7,
      "z": 15,
      "name": "Rock_Ice",
      "rotation": 2
    },
    {
      "x": -16,
      "y": 33,
      "z": 1,
      "name": "Wood_Deadwood_Planks",
      "rotation": 1
    },
    {
      "x": -16,
      "y": 32,
      "z": 2,
      "name": "Wood_Hardwood_Planks",
      "rotation": 3
    },
    {
      "x": -16,
      "y": 33,
      "z": 2,
      "name": "Wood_Hardwood_Planks",
      "rotation": 3
    },
    {
      "x": -16,
      "y": 29,
      "z": 3,
      "name": "Cloth_Block_Wool_Gray_Light_Half",
      "rotation": 4
    },
    {
      "x": -16,
      "y": 30,
      "z": 3,
      "name": "Cloth_Block_Wool_Gray_Light_Half",
      "rotation": 4
    },
    {
      "x": -16,
      "y": 31,
      "z": 3,
      "name": "Cloth_Block_Wool_Gray_Light_Half",
      "rotation": 4
    },
    {
      "x": -16,
      "y": 32,
      "z": 3,
      "name": "Cloth_Block_Wool_Gray_Light_Half",
      "rotation": 4
    },
    {
      "x": -16,
      "y": 33,
      "z": 3,
      "name": "Cloth_Block_Wool_Gray_Light_Half",
      "rotation": 4
    },
    {
      "x": -16,
      "y": 10,
      "z": 5,
      "name": "Rock_Ice",
      "rotation": 2
    },
    {
      "x": -16,
      "y": 5,
      "z": 6,
      "name": "Rock_Ice",
      "rotation": 2
    },
    {
      "x": -16,
      "y": 6,
      "z": 6,
      "name": "Rock_Ice",
      "rotation": 2
    },
    {
      "x": -16,
      "y": 7,
      "z": 6,
      "name": "Rock_Ice",
      "rotation": 2
    },
    {
      "x": -16,
      "y": 8,
      "z": 6,
      "name": "Rock_Ice",
      "rotation": 2
    },
    {
      "x": -16,
      "y": 9,
      "z": 6,
      "name": "Rock_Ice",
      "rotation": 2
    },
    {
      "x": -16,
      "y": 10,
      "z": 6,
      "name": "Rock_Ice",
      "rotation": 2
    },
    {
      "x": -16,
      "y": 4,
      "z": 7,
      "name": "Rock_Ice",
      "rotation": 2
    },
    {
      "x": -16,
      "y": 5,
      "z": 7,
      "name": "Rock_Ice",
      "rotation": 2
    },
    {
      "x": -16,
      "y": 6,
      "z": 7,
      "name": "Rock_Ice",
      "rotation": 2
    },
    {
      "x": -16,
      "y": 7,
      "z": 7,
      "name": "Rock_Ice",
      "rotation": 2
    },
    {
      "x": -16,
      "y": 8,
      "z": 7,
      "name": "Rock_Ice",
      "rotation": 2
    },
    {
      "x": -16,
      "y": 9,
      "z": 7,
      "name": "Rock_Ice",
      "rotation": 2
    },
    {
      "x": -16,
      "y": 10,
      "z": 7,
      "name": "Rock_Ice",
      "rotation": 2
    },
    {
      "x": -16,
      "y": 11,
      "z": 7,
      "name": "Rock_Ice",
      "rotation": 2
    },
    {
      "x": -16,
      "y": 12,
      "z": 7,
      "name": "Rock_Ice",
      "rotation": 2
    },
    {
      "x": -16,
      "y": 4,
      "z": 8,
      "name": "Rock_Ice",
      "rotation": 2
    },
    {
      "x": -16,
      "y": 5,
      "z": 8,
      "name": "Rock_Ice",
      "rotation": 2
    },
    {
      "x": -16,
      "y": 6,
      "z": 8,
      "name": "Rock_Ice",
      "rotation": 2
    },
    {
      "x": -16,
      "y": 7,
      "z": 8,
      "name": "Rock_Ice",
      "rotation": 2
    },
    {
      "x": -16,
      "y": 8,
      "z": 8,
      "name": "Rock_Ice",
      "rotation": 2
    },
    {
      "x": -16,
      "y": 9,
      "z": 8,
      "name": "Rock_Ice",
      "rotation": 2
    },
    {
      "x": -16,
      "y": 10,
      "z": 8,
      "name": "Rock_Ice",
      "rotation": 2
    },
    {
      "x": -16,
      "y": 11,
      "z": 8,
      "name": "Rock_Ice",
      "rotation": 2
    },
    {
      "x": -16,
      "y": 12,
      "z": 8,
      "name": "Rock_Ice",
      "rotation": 2
    },
    {
      "x": -16,
      "y": 13,
      "z": 8,
      "name": "Rock_Ice",
      "rotation": 2
    },
    {
      "x": -16,
      "y": 14,
      "z": 8,
      "name": "Rock_Ice",
      "rotation": 2
    },
    {
      "x": -16,
      "y": 0,
      "z": 9,
      "name": "Rock_Ice",
      "rotation": 2
    },
    {
      "x": -16,
      "y": 2,
      "z": 9,
      "name": "Rock_Ice",
      "rotation": 2
    },
    {
      "x": -16,
      "y": 3,
      "z": 9,
      "name": "Rock_Ice",
      "rotation": 2
    },
    {
      "x": -16,
      "y": 4,
      "z": 9,
      "name": "Rock_Ice",
      "rotation": 2
    },
    {
      "x": -16,
      "y": 5,
      "z": 9,
      "name": "Rock_Ice",
      "rotation": 2
    },
    {
      "x": -16,
      "y": 6,
      "z": 9,
      "name": "Rock_Ice",
      "rotation": 2
    },
    {
      "x": -16,
      "y": 7,
      "z": 9,
      "name": "Rock_Ice",
      "rotation": 2
    },
    {
      "x": -16,
      "y": 8,
      "z": 9,
      "name": "Rock_Ice",
      "rotation": 2
    },
    {
      "x": -16,
      "y": 9,
      "z": 9,
      "name": "Rock_Ice",
      "rotation": 2
    },
    {
      "x": -16,
      "y": 10,
      "z": 9,
      "name": "Rock_Ice",
      "rotation": 2
    },
    {
      "x": -16,
      "y": 11,
      "z": 9,
      "name": "Rock_Ice",
      "rotation": 2
    },
    {
      "x": -16,
      "y": 12,
      "z": 9,
      "name": "Rock_Ice",
      "rotation": 2
    },
    {
      "x": -16,
      "y": 13,
      "z": 9,
      "name": "Rock_Ice",
      "rotation": 2
    },
    {
      "x": -16,
      "y": 14,
      "z": 9,
      "name": "Rock_Ice",
      "rotation": 2
    },
    {
      "x": -16,
      "y": 15,
      "z": 9,
      "name": "Rock_Ice",
      "rotation": 2
    },
    {
      "x": -16,
      "y": -2,
      "z": 10,
      "name": "Rock_Ice",
      "rotation": 2
    },
    {
      "x": -16,
      "y": 0,
      "z": 10,
      "name": "Rock_Ice",
      "rotation": 2
    },
    {
      "x": -16,
      "y": 1,
      "z": 10,
      "name": "Rock_Ice",
      "rotation": 2
    },
    {
      "x": -16,
      "y": 2,
      "z": 10,
      "name": "Rock_Ice",
      "rotation": 2
    },
    {
      "x": -16,
      "y": 3,
      "z": 10,
      "name": "Rock_Ice",
      "rotation": 2
    },
    {
      "x": -16,
      "y": 4,
      "z": 10,
      "name": "Rock_Ice",
      "rotation": 2
    },
    {
      "x": -16,
      "y": 5,
      "z": 10,
      "name": "Rock_Ice",
      "rotation": 2
    },
    {
      "x": -16,
      "y": 6,
      "z": 10,
      "name": "Rock_Ice",
      "rotation": 2
    },
    {
      "x": -16,
      "y": 7,
      "z": 10,
      "name": "Rock_Ice",
      "rotation": 2
    },
    {
      "x": -16,
      "y": 8,
      "z": 10,
      "name": "Rock_Ice",
      "rotation": 2
    },
    {
      "x": -16,
      "y": 9,
      "z": 10,
      "name": "Rock_Ice",
      "rotation": 2
    },
    {
      "x": -16,
      "y": 10,
      "z": 10,
      "name": "Rock_Ice",
      "rotation": 2
    },
    {
      "x": -16,
      "y": 11,
      "z": 10,
      "name": "Rock_Ice",
      "rotation": 2
    },
    {
      "x": -16,
      "y": 12,
      "z": 10,
      "name": "Rock_Ice",
      "rotation": 2
    },
    {
      "x": -16,
      "y": 13,
      "z": 10,
      "name": "Rock_Ice",
      "rotation": 2
    },
    {
      "x": -16,
      "y": 14,
      "z": 10,
      "name": "Rock_Ice",
      "rotation": 2
    },
    {
      "x": -16,
      "y": 15,
      "z": 10,
      "name": "Rock_Ice",
      "rotation": 2
    },
    {
      "x": -16,
      "y": 16,
      "z": 10,
      "name": "Rock_Ice",
      "rotation": 2
    },
    {
      "x": -16,
      "y": -1,
      "z": 11,
      "name": "Rock_Ice",
      "rotation": 2
    },
    {
      "x": -16,
      "y": 0,
      "z": 11,
      "name": "Rock_Ice",
      "rotation": 2
    },
    {
      "x": -16,
      "y": 1,
      "z": 11,
      "name": "Rock_Ice",
      "rotation": 2
    },
    {
      "x": -16,
      "y": 2,
      "z": 11,
      "name": "Rock_Ice",
      "rotation": 2
    },
    {
      "x": -16,
      "y": 3,
      "z": 11,
      "name": "Rock_Ice",
      "rotation": 2
    },
    {
      "x": -16,
      "y": 4,
      "z": 11,
      "name": "Rock_Ice",
      "rotation": 2
    },
    {
      "x": -16,
      "y": 5,
      "z": 11,
      "name": "Rock_Ice",
      "rotation": 2
    },
    {
      "x": -16,
      "y": 6,
      "z": 11,
      "name": "Rock_Ice",
      "rotation": 2
    },
    {
      "x": -16,
      "y": 7,
      "z": 11,
      "name": "Rock_Ice",
      "rotation": 2
    },
    {
      "x": -16,
      "y": 8,
      "z": 11,
      "name": "Rock_Ice",
      "rotation": 2
    },
    {
      "x": -16,
      "y": 9,
      "z": 11,
      "name": "Rock_Ice",
      "rotation": 2
    },
    {
      "x": -16,
      "y": 10,
      "z": 11,
      "name": "Rock_Ice",
      "rotation": 2
    },
    {
      "x": -16,
      "y": 11,
      "z": 11,
      "name": "Rock_Ice",
      "rotation": 2
    },
    {
      "x": -16,
      "y": 12,
      "z": 11,
      "name": "Rock_Ice",
      "rotation": 2
    },
    {
      "x": -16,
      "y": 13,
      "z": 11,
      "name": "Rock_Ice",
      "rotation": 2
    },
    {
      "x": -16,
      "y": 14,
      "z": 11,
      "name": "Rock_Ice",
      "rotation": 2
    },
    {
      "x": -16,
      "y": 15,
      "z": 11,
      "name": "Rock_Ice",
      "rotation": 2
    },
    {
      "x": -16,
      "y": 16,
      "z": 11,
      "name": "Rock_Ice",
      "rotation": 2
    },
    {
      "x": -16,
      "y": 0,
      "z": 12,
      "name": "Rock_Ice",
      "rotation": 2
    },
    {
      "x": -16,
      "y": 1,
      "z": 12,
      "name": "Rock_Ice",
      "rotation": 2
    },
    {
      "x": -16,
      "y": 2,
      "z": 12,
      "name": "Rock_Ice",
      "rotation": 2
    },
    {
      "x": -16,
      "y": 3,
      "z": 12,
      "name": "Rock_Ice",
      "rotation": 2
    },
    {
      "x": -16,
      "y": 4,
      "z": 12,
      "name": "Rock_Ice",
      "rotation": 2
    },
    {
      "x": -16,
      "y": 5,
      "z": 12,
      "name": "Rock_Ice",
      "rotation": 2
    },
    {
      "x": -16,
      "y": 6,
      "z": 12,
      "name": "Rock_Ice",
      "rotation": 2
    },
    {
      "x": -16,
      "y": 7,
      "z": 12,
      "name": "Rock_Ice",
      "rotation": 2
    },
    {
      "x": -16,
      "y": 8,
      "z": 12,
      "name": "Rock_Ice",
      "rotation": 2
    },
    {
      "x": -16,
      "y": 9,
      "z": 12,
      "name": "Rock_Ice",
      "rotation": 2
    },
    {
      "x": -16,
      "y": 10,
      "z": 12,
      "name": "Rock_Ice",
      "rotation": 2
    },
    {
      "x": -16,
      "y": 11,
      "z": 12,
      "name": "Rock_Ice",
      "rotation": 2
    },
    {
      "x": -16,
      "y": 12,
      "z": 12,
      "name": "Rock_Ice",
      "rotation": 2
    },
    {
      "x": -16,
      "y": 13,
      "z": 12,
      "name": "Wood_Hardwood_Planks",
      "rotation": 1
    },
    {
      "x": -16,
      "y": 14,
      "z": 12,
      "name": "Rock_Ice",
      "rotation": 2
    },
    {
      "x": -16,
      "y": 15,
      "z": 12,
      "name": "Rock_Ice",
      "rotation": 2
    },
    {
      "x": -16,
      "y": 1,
      "z": 13,
      "name": "Rock_Ice",
      "rotation": 2
    },
    {
      "x": -16,
      "y": 2,
      "z": 13,
      "name": "Rock_Ice",
      "rotation": 2
    },
    {
      "x": -16,
      "y": 3,
      "z": 13,
      "name": "Rock_Ice",
      "rotation": 2
    },
    {
      "x": -16,
      "y": 4,
      "z": 13,
      "name": "Rock_Ice",
      "rotation": 2
    },
    {
      "x": -16,
      "y": 5,
      "z": 13,
      "name": "Rock_Ice",
      "rotation": 2
    },
    {
      "x": -16,
      "y": 6,
      "z": 13,
      "name": "Rock_Ice",
      "rotation": 2
    },
    {
      "x": -16,
      "y": 7,
      "z": 13,
      "name": "Rock_Ice",
      "rotation": 2
    },
    {
      "x": -16,
      "y": 8,
      "z": 13,
      "name": "Rock_Ice",
      "rotation": 2
    },
    {
      "x": -16,
      "y": 9,
      "z": 13,
      "name": "Rock_Ice",
      "rotation": 2
    },
    {
      "x": -16,
      "y": 10,
      "z": 13,
      "name": "Rock_Ice",
      "rotation": 2
    },
    {
      "x": -16,
      "y": 11,
      "z": 13,
      "name": "Rock_Ice",
      "rotation": 2
    },
    {
      "x": -16,
      "y": 12,
      "z": 13,
      "name": "Rock_Ice",
      "rotation": 2
    },
    {
      "x": -16,
      "y": 13,
      "z": 13,
      "name": "Rock_Ice",
      "rotation": 2
    },
    {
      "x": -16,
      "y": 14,
      "z": 13,
      "name": "Wood_Hardwood_Planks",
      "rotation": 1
    },
    {
      "x": -16,
      "y": -6,
      "z": 14,
      "name": "Rock_Ice",
      "rotation": 2
    },
    {
      "x": -16,
      "y": -5,
      "z": 14,
      "name": "Rock_Ice",
      "rotation": 2
    },
    {
      "x": -16,
      "y": -4,
      "z": 14,
      "name": "Rock_Ice",
      "rotation": 2
    },
    {
      "x": -16,
      "y": 1,
      "z": 14,
      "name": "Rock_Ice",
      "rotation": 2
    },
    {
      "x": -16,
      "y": 2,
      "z": 14,
      "name": "Rock_Ice",
      "rotation": 2
    },
    {
      "x": -16,
      "y": 3,
      "z": 14,
      "name": "Rock_Ice",
      "rotation": 2
    },
    {
      "x": -16,
      "y": 4,
      "z": 14,
      "name": "Rock_Ice",
      "rotation": 2
    },
    {
      "x": -16,
      "y": 5,
      "z": 14,
      "name": "Rock_Ice",
      "rotation": 2
    },
    {
      "x": -16,
      "y": 6,
      "z": 14,
      "name": "Rock_Ice",
      "rotation": 2
    },
    {
      "x": -16,
      "y": 7,
      "z": 14,
      "name": "Rock_Ice",
      "rotation": 2
    },
    {
      "x": -16,
      "y": 8,
      "z": 14,
      "name": "Rock_Ice",
      "rotation": 2
    },
    {
      "x": -16,
      "y": 9,
      "z": 14,
      "name": "Rock_Ice",
      "rotation": 2
    },
    {
      "x": -16,
      "y": 10,
      "z": 14,
      "name": "Rock_Ice",
      "rotation": 2
    },
    {
      "x": -16,
      "y": 11,
      "z": 14,
      "name": "Rock_Ice",
      "rotation": 2
    },
    {
      "x": -16,
      "y": 12,
      "z": 14,
      "name": "Rock_Ice",
      "rotation": 2
    },
    {
      "x": -16,
      "y": 13,
      "z": 14,
      "name": "Rock_Ice",
      "rotation": 2
    },
    {
      "x": -16,
      "y": 14,
      "z": 14,
      "name": "Rock_Ice",
      "rotation": 2
    },
    {
      "x": -16,
      "y": 15,
      "z": 14,
      "name": "Wood_Hardwood_Planks",
      "rotation": 1
    },
    {
      "x": -16,
      "y": -6,
      "z": 15,
      "name": "Rock_Ice",
      "rotation": 2
    },
    {
      "x": -16,
      "y": -5,
      "z": 15,
      "name": "Rock_Ice",
      "rotation": 2
    },
    {
      "x": -16,
      "y": 1,
      "z": 15,
      "name": "Rock_Ice",
      "rotation": 2
    },
    {
      "x": -16,
      "y": 2,
      "z": 15,
      "name": "Rock_Ice",
      "rotation": 2
    },
    {
      "x": -16,
      "y": 3,
      "z": 15,
      "name": "Rock_Ice",
      "rotation": 2
    },
    {
      "x": -16,
      "y": 4,
      "z": 15,
      "name": "Rock_Ice",
      "rotation": 2
    },
    {
      "x": -16,
      "y": 5,
      "z": 15,
      "name": "Rock_Ice",
      "rotation": 2
    },
    {
      "x": -16,
      "y": 6,
      "z": 15,
      "name": "Rock_Ice",
      "rotation": 2
    },
    {
      "x": -16,
      "y": 7,
      "z": 15,
      "name": "Rock_Ice",
      "rotation": 2
    },
    {
      "x": -16,
      "y": 8,
      "z": 15,
      "name": "Rock_Ice",
      "rotation": 2
    },
    {
      "x": -16,
      "y": 9,
      "z": 15,
      "name": "Rock_Ice",
      "rotation": 2
    },
    {
      "x": -16,
      "y": 10,
      "z": 15,
      "name": "Rock_Ice",
      "rotation": 2
    },
    {
      "x": -16,
      "y": 14,
      "z": 15,
      "name": "Rock_Ice",
      "rotation": 2
    },
    {
      "x": -16,
      "y": 16,
      "z": 15,
      "name": "Wood_Hardwood_Planks",
      "rotation": 1
    },
    {
      "x": -16,
      "y": 2,
      "z": 16,
      "name": "Rock_Ice",
      "rotation": 2
    },
    {
      "x": -16,
      "y": 3,
      "z": 16,
      "name": "Rock_Ice",
      "rotation": 2
    },
    {
      "x": -16,
      "y": 4,
      "z": 16,
      "name": "Rock_Ice",
      "rotation": 2
    },
    {
      "x": -16,
      "y": 5,
      "z": 16,
      "name": "Rock_Ice",
      "rotation": 2
    },
    {
      "x": -16,
      "y": 6,
      "z": 16,
      "name": "Rock_Ice",
      "rotation": 2
    },
    {
      "x": -16,
      "y": 7,
      "z": 16,
      "name": "Rock_Ice",
      "rotation": 2
    },
    {
      "x": -16,
      "y": 8,
      "z": 16,
      "name": "Rock_Ice",
      "rotation": 2
    },
    {
      "x": -16,
      "y": 2,
      "z": 17,
      "name": "Rock_Ice",
      "rotation": 2
    },
    {
      "x": -16,
      "y": 0,
      "z": 21,
      "name": "Rock_Ice",
      "rotation": 2
    },
    {
      "x": -16,
      "y": 2,
      "z": 21,
      "name": "Rock_Ice",
      "rotation": 2
    },
    {
      "x": -16,
      "y": -2,
      "z": 22,
      "name": "Rock_Ice",
      "rotation": 2
    },
    {
      "x": -16,
      "y": -1,
      "z": 22,
      "name": "Rock_Ice",
      "rotation": 2
    },
    {
      "x": -16,
      "y": 0,
      "z": 22,
      "name": "Rock_Ice",
      "rotation": 2
    },
    {
      "x": -16,
      "y": 1,
      "z": 22,
      "name": "Rock_Ice",
      "rotation": 2
    },
    {
      "x": -16,
      "y": 2,
      "z": 22,
      "name": "Rock_Ice",
      "rotation": 2
    },
    {
      "x": -16,
      "y": 3,
      "z": 22,
      "name": "Rock_Ice",
      "rotation": 2
    },
    {
      "x": -16,
      "y": -2,
      "z": 23,
      "name": "Rock_Ice",
      "rotation": 2
    },
    {
      "x": -16,
      "y": -1,
      "z": 23,
      "name": "Rock_Ice",
      "rotation": 2
    },
    {
      "x": -16,
      "y": 0,
      "z": 23,
      "name": "Rock_Ice",
      "rotation": 2
    },
    {
      "x": -16,
      "y": 1,
      "z": 23,
      "name": "Rock_Ice",
      "rotation": 2
    },
    {
      "x": -16,
      "y": 2,
      "z": 23,
      "name": "Rock_Ice",
      "rotation": 2
    },
    {
      "x": -16,
      "y": 3,
      "z": 23,
      "name": "Rock_Ice",
      "rotation": 2
    },
    {
      "x": -16,
      "y": -1,
      "z": 24,
      "name": "Rock_Ice",
      "rotation": 2
    },
    {
      "x": -16,
      "y": 1,
      "z": 24,
      "name": "Rock_Ice",
      "rotation": 2
    },
    {
      "x": -16,
      "y": 2,
      "z": 24,
      "name": "Rock_Ice",
      "rotation": 2
    },
    {
      "x": -16,
      "y": 3,
      "z": 24,
      "name": "Rock_Ice",
      "rotation": 2
    },
    {
      "x": -16,
      "y": 4,
      "z": 24,
      "name": "Rock_Ice",
      "rotation": 2
    },
    {
      "x": -16,
      "y": 1,
      "z": 25,
      "name": "Rock_Ice",
      "rotation": 2
    },
    {
      "x": -16,
      "y": 2,
      "z": 25,
      "name": "Rock_Ice",
      "rotation": 2
    },
    {
      "x": -16,
      "y": 3,
      "z": 25,
      "name": "Rock_Ice",
      "rotation": 2
    },
    {
      "x": -16,
      "y": 4,
      "z": 25,
      "name": "Rock_Ice",
      "rotation": 2
    },
    {
      "x": -16,
      "y": 2,
      "z": 26,
      "name": "Rock_Ice",
      "rotation": 2
    },
    {
      "x": -16,
      "y": 3,
      "z": 26,
      "name": "Rock_Ice",
      "rotation": 2
    },
    {
      "x": -16,
      "y": 4,
      "z": 26,
      "name": "Rock_Ice",
      "rotation": 2
    },
    {
      "x": -16,
      "y": 2,
      "z": 27,
      "name": "Rock_Ice",
      "rotation": 2
    },
    {
      "x": -16,
      "y": 3,
      "z": 27,
      "name": "Rock_Ice",
      "rotation": 2
    },
    {
      "x": -16,
      "y": 4,
      "z": 27,
      "name": "Rock_Ice",
      "rotation": 2
    },
    {
      "x": -15,
      "y": 44,
      "z": -12,
      "name": "Wood_Deadwood_Planks",
      "rotation": 1
    },
    {
      "x": -15,
      "y": 37,
      "z": -11,
      "name": "Cloth_Block_Wool_Gray_Light_Half",
      "rotation": 4
    },
    {
      "x": -15,
      "y": 38,
      "z": -11,
      "name": "Cloth_Block_Wool_Gray_Light_Half",
      "rotation": 4
    },
    {
      "x": -15,
      "y": 39,
      "z": -11,
      "name": "Cloth_Block_Wool_Gray_Light_Half",
      "rotation": 4
    },
    {
      "x": -15,
      "y": 40,
      "z": -11,
      "name": "Cloth_Block_Wool_Gray_Light_Half",
      "rotation": 4
    },
    {
      "x": -15,
      "y": 41,
      "z": -11,
      "name": "Cloth_Block_Wool_Gray_Light_Half",
      "rotation": 4
    },
    {
      "x": -15,
      "y": 42,
      "z": -11,
      "name": "Cloth_Block_Wool_Gray_Light_Half",
      "rotation": 4
    },
    {
      "x": -15,
      "y": 43,
      "z": -11,
      "name": "Cloth_Block_Wool_Gray_Light_Half",
      "rotation": 4
    },
    {
      "x": -15,
      "y": 44,
      "z": -11,
      "name": "Cloth_Block_Wool_Gray_Light_Half",
      "rotation": 4
    },
    {
      "x": -15,
      "y": 16,
      "z": -5,
      "name": "Rock_Ice"
    },
    {
      "x": -15,
      "y": 17,
      "z": -5,
      "name": "Rock_Ice"
    },
    {
      "x": -15,
      "y": 18,
      "z": -5,
      "name": "Rock_Ice_Stalactite_Large"
    },
    {
      "x": -15,
      "y": 19,
      "z": -5,
      "name": "Rock_Ice_Stalactite_Large",
      "filler": 1024
    },
    {
      "x": -15,
      "y": 32,
      "z": 1,
      "name": "Wood_Hardwood_Planks",
      "rotation": 3
    },
    {
      "x": -15,
      "y": 25,
      "z": 2,
      "name": "Cloth_Block_Wool_Gray_Light_Half",
      "rotation": 4
    },
    {
      "x": -15,
      "y": 26,
      "z": 2,
      "name": "*Cloth_Block_Wool_Gray_Light_Half_State_Definitions_Block",
      "rotation": 4
    },
    {
      "x": -15,
      "y": 27,
      "z": 2,
      "name": "*Cloth_Block_Wool_Gray_Light_Half_State_Definitions_Block",
      "rotation": 4
    },
    {
      "x": -15,
      "y": 28,
      "z": 2,
      "name": "*Cloth_Block_Wool_Gray_Light_Half_State_Definitions_Block",
      "rotation": 4
    },
    {
      "x": -15,
      "y": 29,
      "z": 2,
      "name": "*Cloth_Block_Wool_Gray_Light_Half_State_Definitions_Block",
      "rotation": 4
    },
    {
      "x": -15,
      "y": 30,
      "z": 2,
      "name": "*Cloth_Block_Wool_Gray_Light_Half_State_Definitions_Block",
      "rotation": 4
    },
    {
      "x": -15,
      "y": 31,
      "z": 2,
      "name": "*Cloth_Block_Wool_Gray_Light_Half_State_Definitions_Block",
      "rotation": 4
    },
    {
      "x": -15,
      "y": 32,
      "z": 2,
      "name": "*Cloth_Block_Wool_Gray_Light_Half_State_Definitions_Block",
      "rotation": 4
    },
    {
      "x": -15,
      "y": 10,
      "z": 4,
      "name": "Rock_Ice",
      "rotation": 2
    },
    {
      "x": -15,
      "y": 11,
      "z": 4,
      "name": "Rock_Ice",
      "rotation": 2
    },
    {
      "x": -15,
      "y": 12,
      "z": 4,
      "name": "Rock_Ice",
      "rotation": 2
    },
    {
      "x": -15,
      "y": 7,
      "z": 5,
      "name": "Rock_Ice",
      "rotation": 2
    },
    {
      "x": -15,
      "y": 8,
      "z": 5,
      "name": "Rock_Ice",
      "rotation": 2
    },
    {
      "x": -15,
      "y": 9,
      "z": 5,
      "name": "Rock_Ice",
      "rotation": 2
    },
    {
      "x": -15,
      "y": 10,
      "z": 5,
      "name": "Rock_Ice",
      "rotation": 2
    },
    {
      "x": -15,
      "y": 11,
      "z": 5,
      "name": "Rock_Ice",
      "rotation": 2
    },
    {
      "x": -15,
      "y": 12,
      "z": 5,
      "name": "Rock_Ice",
      "rotation": 2
    },
    {
      "x": -15,
      "y": 5,
      "z": 6,
      "name": "Rock_Ice",
      "rotation": 2
    },
    {
      "x": -15,
      "y": 6,
      "z": 6,
      "name": "Rock_Ice",
      "rotation": 2
    },
    {
      "x": -15,
      "y": 7,
      "z": 6,
      "name": "Rock_Ice",
      "rotation": 2
    },
    {
      "x": -15,
      "y": 8,
      "z": 6,
      "name": "Rock_Ice",
      "rotation": 2
    },
    {
      "x": -15,
      "y": 9,
      "z": 6,
      "name": "Rock_Ice",
      "rotation": 2
    },
    {
      "x": -15,
      "y": 10,
      "z": 6,
      "name": "Rock_Ice",
      "rotation": 2
    },
    {
      "x": -15,
      "y": 11,
      "z": 6,
      "name": "Rock_Ice",
      "rotation": 2
    },
    {
      "x": -15,
      "y": 12,
      "z": 6,
      "name": "Rock_Ice",
      "rotation": 2
    },
    {
      "x": -15,
      "y": 4,
      "z": 7,
      "name": "Rock_Ice",
      "rotation": 2
    },
    {
      "x": -15,
      "y": 5,
      "z": 7,
      "name": "Rock_Ice",
      "rotation": 2
    },
    {
      "x": -15,
      "y": 6,
      "z": 7,
      "name": "Rock_Ice",
      "rotation": 2
    },
    {
      "x": -15,
      "y": 7,
      "z": 7,
      "name": "Rock_Ice",
      "rotation": 2
    },
    {
      "x": -15,
      "y": 8,
      "z": 7,
      "name": "Rock_Ice",
      "rotation": 2
    },
    {
      "x": -15,
      "y": 9,
      "z": 7,
      "name": "Rock_Ice",
      "rotation": 2
    },
    {
      "x": -15,
      "y": 10,
      "z": 7,
      "name": "Rock_Ice",
      "rotation": 2
    },
    {
      "x": -15,
      "y": 11,
      "z": 7,
      "name": "Wood_Deadwood_Planks",
      "rotation": 1
    },
    {
      "x": -15,
      "y": 12,
      "z": 7,
      "name": "Rock_Ice",
      "rotation": 2
    },
    {
      "x": -15,
      "y": 13,
      "z": 7,
      "name": "Rock_Ice",
      "rotation": 2
    },
    {
      "x": -15,
      "y": 14,
      "z": 7,
      "name": "Rock_Ice",
      "rotation": 2
    },
    {
      "x": -15,
      "y": 0,
      "z": 8,
      "name": "Rock_Ice",
      "rotation": 2
    },
    {
      "x": -15,
      "y": 1,
      "z": 8,
      "name": "Rock_Ice",
      "rotation": 2
    },
    {
      "x": -15,
      "y": 2,
      "z": 8,
      "name": "Rock_Ice",
      "rotation": 2
    },
    {
      "x": -15,
      "y": 3,
      "z": 8,
      "name": "Rock_Ice",
      "rotation": 2
    },
    {
      "x": -15,
      "y": 4,
      "z": 8,
      "name": "Rock_Ice",
      "rotation": 2
    },
    {
      "x": -15,
      "y": 5,
      "z": 8,
      "name": "Rock_Ice",
      "rotation": 2
    },
    {
      "x": -15,
      "y": 6,
      "z": 8,
      "name": "Rock_Ice",
      "rotation": 2
    },
    {
      "x": -15,
      "y": 7,
      "z": 8,
      "name": "Rock_Ice",
      "rotation": 2
    },
    {
      "x": -15,
      "y": 8,
      "z": 8,
      "name": "Rock_Ice",
      "rotation": 2
    },
    {
      "x": -15,
      "y": 9,
      "z": 8,
      "name": "Rock_Ice",
      "rotation": 2
    },
    {
      "x": -15,
      "y": 10,
      "z": 8,
      "name": "Rock_Ice",
      "rotation": 2
    },
    {
      "x": -15,
      "y": 11,
      "z": 8,
      "name": "Rock_Ice",
      "rotation": 2
    },
    {
      "x": -15,
      "y": 12,
      "z": 8,
      "name": "Wood_Deadwood_Planks",
      "rotation": 1
    },
    {
      "x": -15,
      "y": 13,
      "z": 8,
      "name": "Rock_Ice",
      "rotation": 2
    },
    {
      "x": -15,
      "y": 14,
      "z": 8,
      "name": "Rock_Ice",
      "rotation": 2
    },
    {
      "x": -15,
      "y": 15,
      "z": 8,
      "name": "Rock_Ice",
      "rotation": 2
    },
    {
      "x": -15,
      "y": -4,
      "z": 9,
      "name": "Rock_Ice",
      "rotation": 2
    },
    {
      "x": -15,
      "y": -3,
      "z": 9,
      "name": "Rock_Ice",
      "rotation": 2
    },
    {
      "x": -15,
      "y": -2,
      "z": 9,
      "name": "Rock_Ice",
      "rotation": 2
    },
    {
      "x": -15,
      "y": -1,
      "z": 9,
      "name": "Rock_Ice",
      "rotation": 2
    },
    {
      "x": -15,
      "y": 0,
      "z": 9,
      "name": "Rock_Ice",
      "rotation": 2
    },
    {
      "x": -15,
      "y": 1,
      "z": 9,
      "name": "Rock_Ice",
      "rotation": 2
    },
    {
      "x": -15,
      "y": 2,
      "z": 9,
      "name": "Rock_Ice",
      "rotation": 2
    },
    {
      "x": -15,
      "y": 3,
      "z": 9,
      "name": "Rock_Ice",
      "rotation": 2
    },
    {
      "x": -15,
      "y": 4,
      "z": 9,
      "name": "Rock_Ice",
      "rotation": 2
    },
    {
      "x": -15,
      "y": 5,
      "z": 9,
      "name": "Rock_Ice",
      "rotation": 2
    },
    {
      "x": -15,
      "y": 6,
      "z": 9,
      "name": "Rock_Ice",
      "rotation": 2
    },
    {
      "x": -15,
      "y": 7,
      "z": 9,
      "name": "Rock_Ice",
      "rotation": 2
    },
    {
      "x": -15,
      "y": 8,
      "z": 9,
      "name": "Rock_Ice",
      "rotation": 2
    },
    {
      "x": -15,
      "y": 9,
      "z": 9,
      "name": "Rock_Ice",
      "rotation": 2
    },
    {
      "x": -15,
      "y": 10,
      "z": 9,
      "name": "Rock_Ice",
      "rotation": 2
    },
    {
      "x": -15,
      "y": 11,
      "z": 9,
      "name": "Rock_Ice",
      "rotation": 2
    },
    {
      "x": -15,
      "y": 12,
      "z": 9,
      "name": "Rock_Ice",
      "rotation": 2
    },
    {
      "x": -15,
      "y": 13,
      "z": 9,
      "name": "Rock_Ice",
      "rotation": 2
    },
    {
      "x": -15,
      "y": 14,
      "z": 9,
      "name": "Rock_Ice",
      "rotation": 2
    },
    {
      "x": -15,
      "y": 15,
      "z": 9,
      "name": "Rock_Ice",
      "rotation": 2
    },
    {
      "x": -15,
      "y": 16,
      "z": 9,
      "name": "Rock_Ice",
      "rotation": 2
    },
    {
      "x": -15,
      "y": -4,
      "z": 10,
      "name": "Rock_Ice",
      "rotation": 2
    },
    {
      "x": -15,
      "y": -3,
      "z": 10,
      "name": "Rock_Ice",
      "rotation": 2
    },
    {
      "x": -15,
      "y": -2,
      "z": 10,
      "name": "Rock_Ice",
      "rotation": 2
    },
    {
      "x": -15,
      "y": -1,
      "z": 10,
      "name": "Rock_Ice",
      "rotation": 2
    },
    {
      "x": -15,
      "y": 0,
      "z": 10,
      "name": "Rock_Ice",
      "rotation": 2
    },
    {
      "x": -15,
      "y": 1,
      "z": 10,
      "name": "Rock_Ice",
      "rotation": 2
    },
    {
      "x": -15,
      "y": 2,
      "z": 10,
      "name": "Rock_Ice",
      "rotation": 2
    },
    {
      "x": -15,
      "y": 3,
      "z": 10,
      "name": "Rock_Ice",
      "rotation": 2
    },
    {
      "x": -15,
      "y": 4,
      "z": 10,
      "name": "Rock_Ice",
      "rotation": 2
    },
    {
      "x": -15,
      "y": 5,
      "z": 10,
      "name": "Rock_Ice",
      "rotation": 2
    },
    {
      "x": -15,
      "y": 6,
      "z": 10,
      "name": "Rock_Ice",
      "rotation": 2
    },
    {
      "x": -15,
      "y": 7,
      "z": 10,
      "name": "Rock_Ice",
      "rotation": 2
    },
    {
      "x": -15,
      "y": 8,
      "z": 10,
      "name": "Rock_Ice",
      "rotation": 2
    },
    {
      "x": -15,
      "y": 9,
      "z": 10,
      "name": "Rock_Ice",
      "rotation": 2
    },
    {
      "x": -15,
      "y": 10,
      "z": 10,
      "name": "Rock_Ice",
      "rotation": 2
    },
    {
      "x": -15,
      "y": 11,
      "z": 10,
      "name": "Rock_Ice",
      "rotation": 2
    },
    {
      "x": -15,
      "y": 12,
      "z": 10,
      "name": "Wood_Deadwood_Planks",
      "rotation": 1
    },
    {
      "x": -15,
      "y": 13,
      "z": 10,
      "name": "Wood_Deadwood_Planks",
      "rotation": 1
    },
    {
      "x": -15,
      "y": 14,
      "z": 10,
      "name": "Rock_Ice",
      "rotation": 2
    },
    {
      "x": -15,
      "y": 15,
      "z": 10,
      "name": "Rock_Ice",
      "rotation": 2
    },
    {
      "x": -15,
      "y": 16,
      "z": 10,
      "name": "Rock_Ice",
      "rotation": 2
    },
    {
      "x": -15,
      "y": 17,
      "z": 10,
      "name": "Rock_Ice",
      "rotation": 2
    },
    {
      "x": -15,
      "y": -7,
      "z": 11,
      "name": "Rock_Ice",
      "rotation": 2
    },
    {
      "x": -15,
      "y": -6,
      "z": 11,
      "name": "Rock_Ice",
      "rotation": 2
    },
    {
      "x": -15,
      "y": -5,
      "z": 11,
      "name": "Rock_Ice",
      "rotation": 2
    },
    {
      "x": -15,
      "y": -4,
      "z": 11,
      "name": "Rock_Ice",
      "rotation": 2
    },
    {
      "x": -15,
      "y": -3,
      "z": 11,
      "name": "Rock_Ice",
      "rotation": 2
    },
    {
      "x": -15,
      "y": -2,
      "z": 11,
      "name": "Rock_Ice",
      "rotation": 2
    },
    {
      "x": -15,
      "y": -1,
      "z": 11,
      "name": "Rock_Ice",
      "rotation": 2
    },
    {
      "x": -15,
      "y": 0,
      "z": 11,
      "name": "Rock_Ice",
      "rotation": 2
    },
    {
      "x": -15,
      "y": 1,
      "z": 11,
      "name": "Rock_Ice",
      "rotation": 2
    },
    {
      "x": -15,
      "y": 2,
      "z": 11,
      "name": "Rock_Ice",
      "rotation": 2
    },
    {
      "x": -15,
      "y": 3,
      "z": 11,
      "name": "Rock_Ice",
      "rotation": 2
    },
    {
      "x": -15,
      "y": 4,
      "z": 11,
      "name": "Rock_Ice",
      "rotation": 2
    },
    {
      "x": -15,
      "y": 5,
      "z": 11,
      "name": "Rock_Ice",
      "rotation": 2
    },
    {
      "x": -15,
      "y": 6,
      "z": 11,
      "name": "Rock_Ice",
      "rotation": 2
    },
    {
      "x": -15,
      "y": 7,
      "z": 11,
      "name": "Rock_Ice",
      "rotation": 2
    },
    {
      "x": -15,
      "y": 8,
      "z": 11,
      "name": "Rock_Ice",
      "rotation": 2
    },
    {
      "x": -15,
      "y": 9,
      "z": 11,
      "name": "Rock_Ice",
      "rotation": 2
    },
    {
      "x": -15,
      "y": 10,
      "z": 11,
      "name": "Rock_Ice",
      "rotation": 2
    },
    {
      "x": -15,
      "y": 11,
      "z": 11,
      "name": "Rock_Ice",
      "rotation": 2
    },
    {
      "x": -15,
      "y": 12,
      "z": 11,
      "name": "Rock_Ice",
      "rotation": 2
    },
    {
      "x": -15,
      "y": 13,
      "z": 11,
      "name": "Wood_Deadwood_Planks",
      "rotation": 1
    },
    {
      "x": -15,
      "y": 14,
      "z": 11,
      "name": "Wood_Deadwood_Planks",
      "rotation": 1
    },
    {
      "x": -15,
      "y": 15,
      "z": 11,
      "name": "Rock_Ice",
      "rotation": 2
    },
    {
      "x": -15,
      "y": 16,
      "z": 11,
      "name": "Rock_Ice",
      "rotation": 2
    },
    {
      "x": -15,
      "y": 17,
      "z": 11,
      "name": "Rock_Ice",
      "rotation": 2
    },
    {
      "x": -15,
      "y": -7,
      "z": 12,
      "name": "Rock_Ice",
      "rotation": 2
    },
    {
      "x": -15,
      "y": -6,
      "z": 12,
      "name": "Rock_Ice",
      "rotation": 2
    },
    {
      "x": -15,
      "y": -5,
      "z": 12,
      "name": "Rock_Ice",
      "rotation": 2
    },
    {
      "x": -15,
      "y": -4,
      "z": 12,
      "name": "Rock_Ice",
      "rotation": 2
    },
    {
      "x": -15,
      "y": -3,
      "z": 12,
      "name": "Rock_Ice",
      "rotation": 2
    },
    {
      "x": -15,
      "y": -2,
      "z": 12,
      "name": "Rock_Ice",
      "rotation": 2
    },
    {
      "x": -15,
      "y": -1,
      "z": 12,
      "name": "Rock_Ice",
      "rotation": 2
    },
    {
      "x": -15,
      "y": 0,
      "z": 12,
      "name": "Rock_Ice",
      "rotation": 2
    },
    {
      "x": -15,
      "y": 1,
      "z": 12,
      "name": "Rock_Ice",
      "rotation": 2
    },
    {
      "x": -15,
      "y": 2,
      "z": 12,
      "name": "Rock_Ice",
      "rotation": 2
    },
    {
      "x": -15,
      "y": 3,
      "z": 12,
      "name": "Rock_Ice",
      "rotation": 2
    },
    {
      "x": -15,
      "y": 4,
      "z": 12,
      "name": "Rock_Ice",
      "rotation": 2
    },
    {
      "x": -15,
      "y": 5,
      "z": 12,
      "name": "Rock_Ice",
      "rotation": 2
    },
    {
      "x": -15,
      "y": 6,
      "z": 12,
      "name": "Rock_Ice",
      "rotation": 2
    },
    {
      "x": -15,
      "y": 7,
      "z": 12,
      "name": "Rock_Ice",
      "rotation": 2
    },
    {
      "x": -15,
      "y": 8,
      "z": 12,
      "name": "Rock_Ice",
      "rotation": 2
    },
    {
      "x": -15,
      "y": 9,
      "z": 12,
      "name": "Rock_Ice",
      "rotation": 2
    },
    {
      "x": -15,
      "y": 10,
      "z": 12,
      "name": "Rock_Ice",
      "rotation": 2
    },
    {
      "x": -15,
      "y": 11,
      "z": 12,
      "name": "Rock_Ice",
      "rotation": 2
    },
    {
      "x": -15,
      "y": 12,
      "z": 12,
      "name": "Rock_Ice",
      "rotation": 2
    },
    {
      "x": -15,
      "y": 13,
      "z": 12,
      "name": "Wood_Hardwood_Planks",
      "rotation": 1
    },
    {
      "x": -15,
      "y": 14,
      "z": 12,
      "name": "Wood_Deadwood_Planks",
      "rotation": 1
    },
    {
      "x": -15,
      "y": 15,
      "z": 12,
      "name": "Wood_Deadwood_Planks",
      "rotation": 1
    },
    {
      "x": -15,
      "y": 16,
      "z": 12,
      "name": "Rock_Ice",
      "rotation": 2
    },
    {
      "x": -15,
      "y": -8,
      "z": 13,
      "name": "Rock_Ice",
      "rotation": 2
    },
    {
      "x": -15,
      "y": -7,
      "z": 13,
      "name": "Rock_Ice",
      "rotation": 2
    },
    {
      "x": -15,
      "y": -6,
      "z": 13,
      "name": "Rock_Ice",
      "rotation": 2
    },
    {
      "x": -15,
      "y": -5,
      "z": 13,
      "name": "Rock_Ice",
      "rotation": 2
    },
    {
      "x": -15,
      "y": -4,
      "z": 13,
      "name": "Rock_Ice",
      "rotation": 2
    },
    {
      "x": -15,
      "y": -3,
      "z": 13,
      "name": "Rock_Ice",
      "rotation": 2
    },
    {
      "x": -15,
      "y": -2,
      "z": 13,
      "name": "Rock_Ice",
      "rotation": 2
    },
    {
      "x": -15,
      "y": -1,
      "z": 13,
      "name": "Rock_Ice",
      "rotation": 2
    },
    {
      "x": -15,
      "y": 0,
      "z": 13,
      "name": "Rock_Ice",
      "rotation": 2
    },
    {
      "x": -15,
      "y": 1,
      "z": 13,
      "name": "Rock_Ice",
      "rotation": 2
    },
    {
      "x": -15,
      "y": 2,
      "z": 13,
      "name": "Rock_Ice",
      "rotation": 2
    },
    {
      "x": -15,
      "y": 3,
      "z": 13,
      "name": "Rock_Ice",
      "rotation": 2
    },
    {
      "x": -15,
      "y": 4,
      "z": 13,
      "name": "Rock_Ice",
      "rotation": 2
    },
    {
      "x": -15,
      "y": 5,
      "z": 13,
      "name": "Rock_Ice",
      "rotation": 2
    },
    {
      "x": -15,
      "y": 6,
      "z": 13,
      "name": "Rock_Ice",
      "rotation": 2
    },
    {
      "x": -15,
      "y": 7,
      "z": 13,
      "name": "Rock_Ice",
      "rotation": 2
    },
    {
      "x": -15,
      "y": 8,
      "z": 13,
      "name": "Rock_Ice",
      "rotation": 2
    },
    {
      "x": -15,
      "y": 9,
      "z": 13,
      "name": "Rock_Ice",
      "rotation": 2
    },
    {
      "x": -15,
      "y": 10,
      "z": 13,
      "name": "Rock_Ice",
      "rotation": 2
    },
    {
      "x": -15,
      "y": 11,
      "z": 13,
      "name": "Rock_Ice",
      "rotation": 2
    },
    {
      "x": -15,
      "y": 12,
      "z": 13,
      "name": "Rock_Ice",
      "rotation": 2
    },
    {
      "x": -15,
      "y": 13,
      "z": 13,
      "name": "Rock_Ice",
      "rotation": 2
    },
    {
      "x": -15,
      "y": 14,
      "z": 13,
      "name": "Wood_Deadwood_Planks",
      "rotation": 35
    },
    {
      "x": -15,
      "y": 15,
      "z": 13,
      "name": "Wood_Deadwood_Planks",
      "rotation": 1
    },
    {
      "x": -15,
      "y": 16,
      "z": 13,
      "name": "Wood_Deadwood_Planks",
      "rotation": 1
    },
    {
      "x": -15,
      "y": -11,
      "z": 14,
      "name": "Rock_Ice",
      "rotation": 2
    },
    {
      "x": -15,
      "y": -10,
      "z": 14,
      "name": "Rock_Ice",
      "rotation": 2
    },
    {
      "x": -15,
      "y": -8,
      "z": 14,
      "name": "Rock_Ice",
      "rotation": 2
    },
    {
      "x": -15,
      "y": -7,
      "z": 14,
      "name": "Rock_Ice",
      "rotation": 2
    },
    {
      "x": -15,
      "y": -6,
      "z": 14,
      "name": "Rock_Ice",
      "rotation": 2
    },
    {
      "x": -15,
      "y": -5,
      "z": 14,
      "name": "Rock_Ice",
      "rotation": 2
    },
    {
      "x": -15,
      "y": -4,
      "z": 14,
      "name": "Rock_Ice",
      "rotation": 2
    },
    {
      "x": -15,
      "y": -3,
      "z": 14,
      "name": "Rock_Ice",
      "rotation": 2
    },
    {
      "x": -15,
      "y": -2,
      "z": 14,
      "name": "Rock_Ice",
      "rotation": 2
    },
    {
      "x": -15,
      "y": -1,
      "z": 14,
      "name": "Rock_Ice",
      "rotation": 2
    },
    {
      "x": -15,
      "y": 0,
      "z": 14,
      "name": "Rock_Ice",
      "rotation": 2
    },
    {
      "x": -15,
      "y": 1,
      "z": 14,
      "name": "Rock_Ice",
      "rotation": 2
    },
    {
      "x": -15,
      "y": 2,
      "z": 14,
      "name": "Rock_Ice",
      "rotation": 2
    },
    {
      "x": -15,
      "y": 3,
      "z": 14,
      "name": "Rock_Ice",
      "rotation": 2
    },
    {
      "x": -15,
      "y": 4,
      "z": 14,
      "name": "Rock_Ice",
      "rotation": 2
    },
    {
      "x": -15,
      "y": 5,
      "z": 14,
      "name": "Rock_Ice",
      "rotation": 2
    },
    {
      "x": -15,
      "y": 6,
      "z": 14,
      "name": "Rock_Ice",
      "rotation": 2
    },
    {
      "x": -15,
      "y": 7,
      "z": 14,
      "name": "Rock_Ice",
      "rotation": 2
    },
    {
      "x": -15,
      "y": 8,
      "z": 14,
      "name": "Rock_Ice",
      "rotation": 2
    },
    {
      "x": -15,
      "y": 9,
      "z": 14,
      "name": "Rock_Ice",
      "rotation": 2
    },
    {
      "x": -15,
      "y": 10,
      "z": 14,
      "name": "Rock_Ice",
      "rotation": 2
    },
    {
      "x": -15,
      "y": 11,
      "z": 14,
      "name": "Rock_Ice",
      "rotation": 2
    },
    {
      "x": -15,
      "y": 12,
      "z": 14,
      "name": "Rock_Ice",
      "rotation": 2
    },
    {
      "x": -15,
      "y": 13,
      "z": 14,
      "name": "Rock_Ice",
      "rotation": 2
    },
    {
      "x": -15,
      "y": 14,
      "z": 14,
      "name": "Rock_Ice",
      "rotation": 2
    },
    {
      "x": -15,
      "y": 15,
      "z": 14,
      "name": "Wood_Deadwood_Planks",
      "rotation": 35
    },
    {
      "x": -15,
      "y": 16,
      "z": 14,
      "name": "Wood_Deadwood_Planks",
      "rotation": 1
    },
    {
      "x": -15,
      "y": 17,
      "z": 14,
      "name": "Wood_Deadwood_Planks",
      "rotation": 1
    },
    {
      "x": -15,
      "y": -8,
      "z": 15,
      "name": "Rock_Ice",
      "rotation": 2
    },
    {
      "x": -15,
      "y": -7,
      "z": 15,
      "name": "Rock_Ice",
      "rotation": 2
    },
    {
      "x": -15,
      "y": -6,
      "z": 15,
      "name": "Rock_Ice",
      "rotation": 2
    },
    {
      "x": -15,
      "y": -5,
      "z": 15,
      "name": "Rock_Ice",
      "rotation": 2
    },
    {
      "x": -15,
      "y": -4,
      "z": 15,
      "name": "Rock_Ice",
      "rotation": 2
    },
    {
      "x": -15,
      "y": -3,
      "z": 15,
      "name": "Rock_Ice",
      "rotation": 2
    },
    {
      "x": -15,
      "y": 0,
      "z": 15,
      "name": "Rock_Ice",
      "rotation": 2
    },
    {
      "x": -15,
      "y": 1,
      "z": 15,
      "name": "Rock_Ice",
      "rotation": 2
    },
    {
      "x": -15,
      "y": 2,
      "z": 15,
      "name": "Rock_Ice",
      "rotation": 2
    },
    {
      "x": -15,
      "y": 3,
      "z": 15,
      "name": "Rock_Ice",
      "rotation": 2
    },
    {
      "x": -15,
      "y": 4,
      "z": 15,
      "name": "Rock_Ice",
      "rotation": 2
    },
    {
      "x": -15,
      "y": 5,
      "z": 15,
      "name": "Rock_Ice",
      "rotation": 2
    },
    {
      "x": -15,
      "y": 6,
      "z": 15,
      "name": "Rock_Ice",
      "rotation": 2
    },
    {
      "x": -15,
      "y": 7,
      "z": 15,
      "name": "Rock_Ice",
      "rotation": 2
    },
    {
      "x": -15,
      "y": 8,
      "z": 15,
      "name": "Rock_Ice",
      "rotation": 2
    },
    {
      "x": -15,
      "y": 9,
      "z": 15,
      "name": "Rock_Ice",
      "rotation": 2
    },
    {
      "x": -15,
      "y": 10,
      "z": 15,
      "name": "Rock_Ice",
      "rotation": 2
    },
    {
      "x": -15,
      "y": 11,
      "z": 15,
      "name": "Rock_Ice",
      "rotation": 2
    },
    {
      "x": -15,
      "y": 12,
      "z": 15,
      "name": "Rock_Ice",
      "rotation": 2
    },
    {
      "x": -15,
      "y": 13,
      "z": 15,
      "name": "Rock_Ice",
      "rotation": 2
    },
    {
      "x": -15,
      "y": 14,
      "z": 15,
      "name": "Rock_Ice",
      "rotation": 2
    },
    {
      "x": -15,
      "y": 15,
      "z": 15,
      "name": "Rock_Ice",
      "rotation": 2
    },
    {
      "x": -15,
      "y": 16,
      "z": 15,
      "name": "Wood_Deadwood_Planks",
      "rotation": 35
    },
    {
      "x": -15,
      "y": 17,
      "z": 15,
      "name": "Wood_Deadwood_Planks",
      "rotation": 1
    },
    {
      "x": -15,
      "y": 18,
      "z": 15,
      "name": "Wood_Deadwood_Planks",
      "rotation": 1
    },
    {
      "x": -15,
      "y": -8,
      "z": 16,
      "name": "Rock_Ice",
      "rotation": 2
    },
    {
      "x": -15,
      "y": -7,
      "z": 16,
      "name": "Rock_Ice",
      "rotation": 2
    },
    {
      "x": -15,
      "y": -6,
      "z": 16,
      "name": "Rock_Ice",
      "rotation": 2
    },
    {
      "x": -15,
      "y": -5,
      "z": 16,
      "name": "Rock_Ice",
      "rotation": 2
    },
    {
      "x": -15,
      "y": 0,
      "z": 16,
      "name": "Rock_Ice",
      "rotation": 2
    },
    {
      "x": -15,
      "y": 1,
      "z": 16,
      "name": "Rock_Ice",
      "rotation": 2
    },
    {
      "x": -15,
      "y": 2,
      "z": 16,
      "name": "Rock_Ice",
      "rotation": 2
    },
    {
      "x": -15,
      "y": 3,
      "z": 16,
      "name": "Rock_Ice",
      "rotation": 2
    },
    {
      "x": -15,
      "y": 4,
      "z": 16,
      "name": "Rock_Ice",
      "rotation": 2
    },
    {
      "x": -15,
      "y": 5,
      "z": 16,
      "name": "Rock_Ice",
      "rotation": 2
    },
    {
      "x": -15,
      "y": 6,
      "z": 16,
      "name": "Rock_Ice",
      "rotation": 2
    },
    {
      "x": -15,
      "y": 7,
      "z": 16,
      "name": "Rock_Ice",
      "rotation": 2
    },
    {
      "x": -15,
      "y": 8,
      "z": 16,
      "name": "Rock_Ice",
      "rotation": 2
    },
    {
      "x": -15,
      "y": 9,
      "z": 16,
      "name": "Rock_Ice",
      "rotation": 2
    },
    {
      "x": -15,
      "y": 10,
      "z": 16,
      "name": "Rock_Ice",
      "rotation": 2
    },
    {
      "x": -15,
      "y": 11,
      "z": 16,
      "name": "Rock_Ice",
      "rotation": 2
    },
    {
      "x": -15,
      "y": 13,
      "z": 16,
      "name": "Rock_Ice",
      "rotation": 2
    },
    {
      "x": -15,
      "y": 14,
      "z": 16,
      "name": "Rock_Ice",
      "rotation": 2
    },
    {
      "x": -15,
      "y": 15,
      "z": 16,
      "name": "Rock_Ice",
      "rotation": 2
    },
    {
      "x": -15,
      "y": 17,
      "z": 16,
      "name": "Wood_Deadwood_Planks",
      "rotation": 35
    },
    {
      "x": -15,
      "y": 18,
      "z": 16,
      "name": "Wood_Deadwood_Planks",
      "rotation": 1
    },
    {
      "x": -15,
      "y": 19,
      "z": 16,
      "name": "Wood_Deadwood_Planks",
      "rotation": 1
    },
    {
      "x": -15,
      "y": 51,
      "z": 16,
      "name": "Wood_Deadwood_Planks",
      "rotation": 1
    },
    {
      "x": -15,
      "y": 0,
      "z": 17,
      "name": "Rock_Ice",
      "rotation": 2
    },
    {
      "x": -15,
      "y": 1,
      "z": 17,
      "name": "Rock_Ice",
      "rotation": 2
    },
    {
      "x": -15,
      "y": 2,
      "z": 17,
      "name": "Rock_Ice",
      "rotation": 2
    },
    {
      "x": -15,
      "y": 3,
      "z": 17,
      "name": "Rock_Ice",
      "rotation": 2
    },
    {
      "x": -15,
      "y": 4,
      "z": 17,
      "name": "Rock_Ice",
      "rotation": 2
    },
    {
      "x": -15,
      "y": 5,
      "z": 17,
      "name": "Rock_Ice",
      "rotation": 2
    },
    {
      "x": -15,
      "y": 6,
      "z": 17,
      "name": "Rock_Ice",
      "rotation": 2
    },
    {
      "x": -15,
      "y": 7,
      "z": 17,
      "name": "Rock_Ice",
      "rotation": 2
    },
    {
      "x": -15,
      "y": 8,
      "z": 17,
      "name": "Rock_Ice",
      "rotation": 2
    },
    {
      "x": -15,
      "y": 9,
      "z": 17,
      "name": "Rock_Ice",
      "rotation": 2
    },
    {
      "x": -15,
      "y": 19,
      "z": 17,
      "name": "Wood_Deadwood_Planks",
      "rotation": 1
    },
    {
      "x": -15,
      "y": 20,
      "z": 17,
      "name": "Wood_Deadwood_Planks",
      "rotation": 1
    },
    {
      "x": -15,
      "y": 50,
      "z": 17,
      "name": "Wood_Hardwood_Planks",
      "rotation": 3
    },
    {
      "x": -15,
      "y": -1,
      "z": 18,
      "name": "Rock_Ice",
      "rotation": 2
    },
    {
      "x": -15,
      "y": 0,
      "z": 18,
      "name": "Rock_Ice",
      "rotation": 2
    },
    {
      "x": -15,
      "y": 1,
      "z": 18,
      "name": "Rock_Ice",
      "rotation": 2
    },
    {
      "x": -15,
      "y": 2,
      "z": 18,
      "name": "Rock_Ice",
      "rotation": 2
    },
    {
      "x": -15,
      "y": 3,
      "z": 18,
      "name": "Rock_Ice",
      "rotation": 2
    },
    {
      "x": -15,
      "y": 4,
      "z": 18,
      "name": "Rock_Ice",
      "rotation": 2
    },
    {
      "x": -15,
      "y": 5,
      "z": 18,
      "name": "Rock_Ice",
      "rotation": 2
    },
    {
      "x": -15,
      "y": 6,
      "z": 18,
      "name": "Rock_Ice",
      "rotation": 2
    },
    {
      "x": -15,
      "y": 20,
      "z": 18,
      "name": "Wood_Deadwood_Planks",
      "rotation": 1
    },
    {
      "x": -15,
      "y": 21,
      "z": 18,
      "name": "Wood_Deadwood_Planks",
      "rotation": 1
    },
    {
      "x": -15,
      "y": 22,
      "z": 18,
      "name": "Wood_Deadwood_Planks",
      "rotation": 1
    },
    {
      "x": -15,
      "y": 43,
      "z": 18,
      "name": "Cloth_Block_Wool_Gray_Light_Half",
      "rotation": 4
    },
    {
      "x": -15,
      "y": 44,
      "z": 18,
      "name": "Cloth_Block_Wool_Gray_Light_Half",
      "rotation": 4
    },
    {
      "x": -15,
      "y": 45,
      "z": 18,
      "name": "Cloth_Block_Wool_Gray_Light_Half",
      "rotation": 4
    },
    {
      "x": -15,
      "y": 46,
      "z": 18,
      "name": "Cloth_Block_Wool_Gray_Light_Half",
      "rotation": 4
    },
    {
      "x": -15,
      "y": 47,
      "z": 18,
      "name": "Cloth_Block_Wool_Gray_Light_Half",
      "rotation": 4
    },
    {
      "x": -15,
      "y": 48,
      "z": 18,
      "name": "Cloth_Block_Wool_Gray_Light_Half",
      "rotation": 4
    },
    {
      "x": -15,
      "y": 49,
      "z": 18,
      "name": "Cloth_Block_Wool_Gray_Light_Half",
      "rotation": 4
    },
    {
      "x": -15,
      "y": 50,
      "z": 18,
      "name": "Cloth_Block_Wool_Gray_Light_Half",
      "rotation": 4
    },
    {
      "x": -15,
      "y": -3,
      "z": 19,
      "name": "Rock_Ice",
      "rotation": 2
    },
    {
      "x": -15,
      "y": -2,
      "z": 19,
      "name": "Rock_Ice",
      "rotation": 2
    },
    {
      "x": -15,
      "y": -1,
      "z": 19,
      "name": "Rock_Ice",
      "rotation": 2
    },
    {
      "x": -15,
      "y": 0,
      "z": 19,
      "name": "Rock_Ice",
      "rotation": 2
    },
    {
      "x": -15,
      "y": 2,
      "z": 19,
      "name": "Rock_Ice",
      "rotation": 2
    },
    {
      "x": -15,
      "y": 3,
      "z": 19,
      "name": "Rock_Ice",
      "rotation": 2
    },
    {
      "x": -15,
      "y": 4,
      "z": 19,
      "name": "Rock_Ice",
      "rotation": 2
    },
    {
      "x": -15,
      "y": 23,
      "z": 19,
      "name": "Wood_Deadwood_Planks",
      "rotation": 1
    },
    {
      "x": -15,
      "y": -3,
      "z": 20,
      "name": "Rock_Ice",
      "rotation": 2
    },
    {
      "x": -15,
      "y": -2,
      "z": 20,
      "name": "Rock_Ice",
      "rotation": 2
    },
    {
      "x": -15,
      "y": -1,
      "z": 20,
      "name": "Rock_Ice",
      "rotation": 2
    },
    {
      "x": -15,
      "y": 0,
      "z": 20,
      "name": "Rock_Ice",
      "rotation": 2
    },
    {
      "x": -15,
      "y": 1,
      "z": 20,
      "name": "Rock_Ice",
      "rotation": 2
    },
    {
      "x": -15,
      "y": 2,
      "z": 20,
      "name": "Rock_Ice",
      "rotation": 2
    },
    {
      "x": -15,
      "y": 3,
      "z": 20,
      "name": "Rock_Ice",
      "rotation": 2
    },
    {
      "x": -15,
      "y": 4,
      "z": 20,
      "name": "Rock_Ice",
      "rotation": 2
    },
    {
      "x": -15,
      "y": 24,
      "z": 20,
      "name": "Wood_Hardwood_Planks",
      "rotation": 1
    },
    {
      "x": -15,
      "y": -3,
      "z": 21,
      "name": "Rock_Ice",
      "rotation": 2
    },
    {
      "x": -15,
      "y": -2,
      "z": 21,
      "name": "Rock_Ice",
      "rotation": 2
    },
    {
      "x": -15,
      "y": -1,
      "z": 21,
      "name": "Rock_Ice",
      "rotation": 2
    },
    {
      "x": -15,
      "y": 0,
      "z": 21,
      "name": "Rock_Ice",
      "rotation": 2
    },
    {
      "x": -15,
      "y": 1,
      "z": 21,
      "name": "Rock_Ice",
      "rotation": 2
    },
    {
      "x": -15,
      "y": 2,
      "z": 21,
      "name": "Rock_Ice",
      "rotation": 2
    },
    {
      "x": -15,
      "y": 3,
      "z": 21,
      "name": "Rock_Ice",
      "rotation": 2
    },
    {
      "x": -15,
      "y": 4,
      "z": 21,
      "name": "Rock_Ice",
      "rotation": 2
    },
    {
      "x": -15,
      "y": 5,
      "z": 21,
      "name": "Rock_Ice",
      "rotation": 2
    },
    {
      "x": -15,
      "y": 25,
      "z": 21,
      "name": "Wood_Hardwood_Planks",
      "rotation": 1
    },
    {
      "x": -15,
      "y": -2,
      "z": 22,
      "name": "Rock_Ice",
      "rotation": 2
    },
    {
      "x": -15,
      "y": -1,
      "z": 22,
      "name": "Rock_Ice",
      "rotation": 2
    },
    {
      "x": -15,
      "y": 0,
      "z": 22,
      "name": "Rock_Ice",
      "rotation": 2
    },
    {
      "x": -15,
      "y": 1,
      "z": 22,
      "name": "Rock_Ice",
      "rotation": 2
    },
    {
      "x": -15,
      "y": 2,
      "z": 22,
      "name": "Rock_Ice",
      "rotation": 2
    },
    {
      "x": -15,
      "y": 3,
      "z": 22,
      "name": "Rock_Ice",
      "rotation": 2
    },
    {
      "x": -15,
      "y": 4,
      "z": 22,
      "name": "Rock_Ice",
      "rotation": 2
    },
    {
      "x": -15,
      "y": 5,
      "z": 22,
      "name": "Rock_Ice",
      "rotation": 2
    },
    {
      "x": -15,
      "y": 26,
      "z": 22,
      "name": "Wood_Hardwood_Planks",
      "rotation": 1
    },
    {
      "x": -15,
      "y": -2,
      "z": 23,
      "name": "Rock_Ice",
      "rotation": 2
    },
    {
      "x": -15,
      "y": -1,
      "z": 23,
      "name": "Rock_Ice",
      "rotation": 2
    },
    {
      "x": -15,
      "y": 0,
      "z": 23,
      "name": "Rock_Ice",
      "rotation": 2
    },
    {
      "x": -15,
      "y": 1,
      "z": 23,
      "name": "Rock_Ice",
      "rotation": 2
    },
    {
      "x": -15,
      "y": 2,
      "z": 23,
      "name": "Rock_Ice",
      "rotation": 2
    },
    {
      "x": -15,
      "y": 3,
      "z": 23,
      "name": "Rock_Ice",
      "rotation": 2
    },
    {
      "x": -15,
      "y": 4,
      "z": 23,
      "name": "Rock_Ice",
      "rotation": 2
    },
    {
      "x": -15,
      "y": 5,
      "z": 23,
      "name": "Rock_Ice",
      "rotation": 2
    },
    {
      "x": -15,
      "y": 6,
      "z": 23,
      "name": "Rock_Ice",
      "rotation": 2
    },
    {
      "x": -15,
      "y": -2,
      "z": 24,
      "name": "Rock_Ice",
      "rotation": 2
    },
    {
      "x": -15,
      "y": -1,
      "z": 24,
      "name": "Rock_Ice",
      "rotation": 2
    },
    {
      "x": -15,
      "y": 0,
      "z": 24,
      "name": "Rock_Ice",
      "rotation": 2
    },
    {
      "x": -15,
      "y": 1,
      "z": 24,
      "name": "Rock_Ice",
      "rotation": 2
    },
    {
      "x": -15,
      "y": 2,
      "z": 24,
      "name": "Rock_Ice",
      "rotation": 2
    },
    {
      "x": -15,
      "y": 3,
      "z": 24,
      "name": "Rock_Ice",
      "rotation": 2
    },
    {
      "x": -15,
      "y": 4,
      "z": 24,
      "name": "Rock_Ice",
      "rotation": 2
    },
    {
      "x": -15,
      "y": 5,
      "z": 24,
      "name": "Rock_Ice",
      "rotation": 2
    },
    {
      "x": -15,
      "y": 6,
      "z": 24,
      "name": "Rock_Ice",
      "rotation": 2
    },
    {
      "x": -15,
      "y": -1,
      "z": 25,
      "name": "Rock_Ice",
      "rotation": 2
    },
    {
      "x": -15,
      "y": 0,
      "z": 25,
      "name": "Rock_Ice",
      "rotation": 2
    },
    {
      "x": -15,
      "y": 1,
      "z": 25,
      "name": "Rock_Ice",
      "rotation": 2
    },
    {
      "x": -15,
      "y": 2,
      "z": 25,
      "name": "Rock_Ice",
      "rotation": 2
    },
    {
      "x": -15,
      "y": 3,
      "z": 25,
      "name": "Rock_Ice",
      "rotation": 2
    },
    {
      "x": -15,
      "y": 4,
      "z": 25,
      "name": "Rock_Ice",
      "rotation": 2
    },
    {
      "x": -15,
      "y": 5,
      "z": 25,
      "name": "Rock_Ice",
      "rotation": 2
    },
    {
      "x": -15,
      "y": 6,
      "z": 25,
      "name": "Rock_Ice",
      "rotation": 2
    },
    {
      "x": -15,
      "y": 1,
      "z": 26,
      "name": "Rock_Ice",
      "rotation": 2
    },
    {
      "x": -15,
      "y": 2,
      "z": 26,
      "name": "Rock_Ice",
      "rotation": 2
    },
    {
      "x": -15,
      "y": 3,
      "z": 26,
      "name": "Rock_Ice",
      "rotation": 2
    },
    {
      "x": -15,
      "y": 4,
      "z": 26,
      "name": "Rock_Ice",
      "rotation": 2
    },
    {
      "x": -15,
      "y": 5,
      "z": 26,
      "name": "Rock_Ice",
      "rotation": 2
    },
    {
      "x": -15,
      "y": 6,
      "z": 26,
      "name": "Rock_Ice",
      "rotation": 2
    },
    {
      "x": -15,
      "y": 7,
      "z": 26,
      "name": "Rock_Ice",
      "rotation": 2
    },
    {
      "x": -15,
      "y": 1,
      "z": 27,
      "name": "Rock_Ice",
      "rotation": 2
    },
    {
      "x": -15,
      "y": 2,
      "z": 27,
      "name": "Rock_Ice",
      "rotation": 2
    },
    {
      "x": -15,
      "y": 3,
      "z": 27,
      "name": "Rock_Ice",
      "rotation": 2
    },
    {
      "x": -15,
      "y": 4,
      "z": 27,
      "name": "Rock_Ice",
      "rotation": 2
    },
    {
      "x": -15,
      "y": 5,
      "z": 27,
      "name": "Rock_Ice",
      "rotation": 2
    },
    {
      "x": -15,
      "y": 6,
      "z": 27,
      "name": "Rock_Ice",
      "rotation": 2
    },
    {
      "x": -15,
      "y": 7,
      "z": 27,
      "name": "Rock_Ice",
      "rotation": 2
    },
    {
      "x": -15,
      "y": 2,
      "z": 28,
      "name": "Rock_Ice",
      "rotation": 2
    },
    {
      "x": -15,
      "y": 3,
      "z": 28,
      "name": "Rock_Ice",
      "rotation": 2
    },
    {
      "x": -15,
      "y": 4,
      "z": 28,
      "name": "Rock_Ice",
      "rotation": 2
    },
    {
      "x": -15,
      "y": 5,
      "z": 28,
      "name": "Rock_Ice",
      "rotation": 2
    },
    {
      "x": -15,
      "y": 6,
      "z": 28,
      "name": "Rock_Ice",
      "rotation": 2
    },
    {
      "x": -14,
      "y": 44,
      "z": -12,
      "name": "Wood_Deadwood_Planks",
      "rotation": 1
    },
    {
      "x": -14,
      "y": 39,
      "z": -11,
      "name": "Cloth_Block_Wool_Gray_Light_Half",
      "rotation": 4
    },
    {
      "x": -14,
      "y": 40,
      "z": -11,
      "name": "Cloth_Block_Wool_Gray_Light_Half",
      "rotation": 4
    },
    {
      "x": -14,
      "y": 41,
      "z": -11,
      "name": "Cloth_Block_Wool_Gray_Light_Half",
      "rotation": 4
    },
    {
      "x": -14,
      "y": 42,
      "z": -11,
      "name": "Cloth_Block_Wool_Gray_Light_Half",
      "rotation": 4
    },
    {
      "x": -14,
      "y": 43,
      "z": -11,
      "name": "Cloth_Block_Wool_Gray_Light_Half",
      "rotation": 4
    },
    {
      "x": -14,
      "y": 44,
      "z": -11,
      "name": "Cloth_Block_Wool_Gray_Light_Half",
      "rotation": 4
    },
    {
      "x": -14,
      "y": 15,
      "z": -8,
      "name": "Rock_Ice"
    },
    {
      "x": -14,
      "y": 16,
      "z": -8,
      "name": "Rock_Ice"
    },
    {
      "x": -14,
      "y": 17,
      "z": -8,
      "name": "Rock_Ice_Stalactite_Large"
    },
    {
      "x": -14,
      "y": 18,
      "z": -8,
      "name": "Rock_Ice_Stalactite_Large",
      "filler": 1024
    },
    {
      "x": -14,
      "y": 15,
      "z": -7,
      "name": "Rock_Ice"
    },
    {
      "x": -14,
      "y": 16,
      "z": -7,
      "name": "Rock_Ice"
    },
    {
      "x": -14,
      "y": 17,
      "z": -7,
      "name": "Rock_Ice"
    },
    {
      "x": -14,
      "y": 13,
      "z": -6,
      "name": "Rock_Ice",
      "rotation": 1
    },
    {
      "x": -14,
      "y": 14,
      "z": -6,
      "name": "Rock_Ice"
    },
    {
      "x": -14,
      "y": 15,
      "z": -6,
      "name": "Rock_Ice"
    },
    {
      "x": -14,
      "y": 16,
      "z": -6,
      "name": "Rock_Ice"
    },
    {
      "x": -14,
      "y": 14,
      "z": -5,
      "name": "Rock_Ice"
    },
    {
      "x": -14,
      "y": 15,
      "z": -5,
      "name": "Rock_Ice"
    },
    {
      "x": -14,
      "y": 16,
      "z": -5,
      "name": "Rock_Ice"
    },
    {
      "x": -14,
      "y": 17,
      "z": -5,
      "name": "Rock_Ice"
    },
    {
      "x": -14,
      "y": 18,
      "z": -5,
      "name": "Rock_Ice"
    },
    {
      "x": -14,
      "y": 19,
      "z": -5,
      "name": "Rock_Ice"
    },
    {
      "x": -14,
      "y": 14,
      "z": -4,
      "name": "Rock_Ice"
    },
    {
      "x": -14,
      "y": 15,
      "z": -4,
      "name": "Rock_Ice"
    },
    {
      "x": -14,
      "y": 16,
      "z": -4,
      "name": "Rock_Ice"
    },
    {
      "x": -14,
      "y": 17,
      "z": -4,
      "name": "Rock_Ice"
    },
    {
      "x": -14,
      "y": 18,
      "z": -4,
      "name": "Rock_Ice"
    },
    {
      "x": -14,
      "y": 16,
      "z": -3,
      "name": "Rock_Ice"
    },
    {
      "x": -14,
      "y": 17,
      "z": -3,
      "name": "Rock_Ice"
    },
    {
      "x": -14,
      "y": 17,
      "z": -2,
      "name": "Rock_Ice"
    },
    {
      "x": -14,
      "y": 18,
      "z": -2,
      "name": "Rock_Ice"
    },
    {
      "x": -14,
      "y": 32,
      "z": 1,
      "name": "Wood_Hardwood_Planks",
      "rotation": 3
    },
    {
      "x": -14,
      "y": 26,
      "z": 2,
      "name": "Cloth_Block_Wool_Gray_Light_Half",
      "rotation": 4
    },
    {
      "x": -14,
      "y": 27,
      "z": 2,
      "name": "Cloth_Block_Wool_Gray_Light_Half",
      "rotation": 4
    },
    {
      "x": -14,
      "y": 28,
      "z": 2,
      "name": "Cloth_Block_Wool_Gray_Light_Half",
      "rotation": 4
    },
    {
      "x": -14,
      "y": 29,
      "z": 2,
      "name": "Cloth_Block_Wool_Gray_Light_Half",
      "rotation": 4
    },
    {
      "x": -14,
      "y": 30,
      "z": 2,
      "name": "Cloth_Block_Wool_Gray_Light_Half",
      "rotation": 4
    },
    {
      "x": -14,
      "y": 31,
      "z": 2,
      "name": "Cloth_Block_Wool_Gray_Light_Half",
      "rotation": 4
    },
    {
      "x": -14,
      "y": 32,
      "z": 2,
      "name": "Cloth_Block_Wool_Gray_Light_Half",
      "rotation": 4
    },
    {
      "x": -14,
      "y": 10,
      "z": 3,
      "name": "Rock_Ice",
      "rotation": 2
    },
    {
      "x": -14,
      "y": 11,
      "z": 3,
      "name": "Rock_Ice",
      "rotation": 2
    },
    {
      "x": -14,
      "y": 9,
      "z": 4,
      "name": "Rock_Ice",
      "rotation": 2
    },
    {
      "x": -14,
      "y": 10,
      "z": 4,
      "name": "Rock_Ice",
      "rotation": 2
    },
    {
      "x": -14,
      "y": 11,
      "z": 4,
      "name": "Rock_Ice",
      "rotation": 2
    },
    {
      "x": -14,
      "y": 12,
      "z": 4,
      "name": "Rock_Ice",
      "rotation": 2
    },
    {
      "x": -14,
      "y": 13,
      "z": 4,
      "name": "Rock_Ice",
      "rotation": 2
    },
    {
      "x": -14,
      "y": 6,
      "z": 5,
      "name": "Rock_Ice",
      "rotation": 2
    },
    {
      "x": -14,
      "y": 7,
      "z": 5,
      "name": "Rock_Ice",
      "rotation": 2
    },
    {
      "x": -14,
      "y": 8,
      "z": 5,
      "name": "Rock_Ice",
      "rotation": 2
    },
    {
      "x": -14,
      "y": 9,
      "z": 5,
      "name": "Rock_Ice",
      "rotation": 2
    },
    {
      "x": -14,
      "y": 10,
      "z": 5,
      "name": "Rock_Ice",
      "rotation": 2
    },
    {
      "x": -14,
      "y": 11,
      "z": 5,
      "name": "Rock_Ice",
      "rotation": 2
    },
    {
      "x": -14,
      "y": 12,
      "z": 5,
      "name": "Rock_Ice",
      "rotation": 2
    },
    {
      "x": -14,
      "y": 13,
      "z": 5,
      "name": "Rock_Ice",
      "rotation": 2
    },
    {
      "x": -14,
      "y": 3,
      "z": 6,
      "name": "Rock_Ice",
      "rotation": 2
    },
    {
      "x": -14,
      "y": 4,
      "z": 6,
      "name": "Rock_Ice",
      "rotation": 2
    },
    {
      "x": -14,
      "y": 5,
      "z": 6,
      "name": "Rock_Ice",
      "rotation": 2
    },
    {
      "x": -14,
      "y": 6,
      "z": 6,
      "name": "Rock_Ice",
      "rotation": 2
    },
    {
      "x": -14,
      "y": 7,
      "z": 6,
      "name": "Rock_Ice",
      "rotation": 2
    },
    {
      "x": -14,
      "y": 8,
      "z": 6,
      "name": "Rock_Ice",
      "rotation": 2
    },
    {
      "x": -14,
      "y": 9,
      "z": 6,
      "name": "Rock_Ice",
      "rotation": 2
    },
    {
      "x": -14,
      "y": 10,
      "z": 6,
      "name": "Rock_Ice",
      "rotation": 2
    },
    {
      "x": -14,
      "y": 11,
      "z": 6,
      "name": "Wood_Hardwood_Planks",
      "rotation": 1
    },
    {
      "x": -14,
      "y": 12,
      "z": 6,
      "name": "Rock_Ice",
      "rotation": 2
    },
    {
      "x": -14,
      "y": 13,
      "z": 6,
      "name": "Rock_Ice",
      "rotation": 2
    },
    {
      "x": -14,
      "y": 14,
      "z": 6,
      "name": "Rock_Ice",
      "rotation": 2
    },
    {
      "x": -14,
      "y": 15,
      "z": 6,
      "name": "Rock_Ice",
      "rotation": 2
    },
    {
      "x": -14,
      "y": 16,
      "z": 6,
      "name": "Rock_Ice",
      "rotation": 2
    },
    {
      "x": -14,
      "y": -2,
      "z": 7,
      "name": "Rock_Ice",
      "rotation": 2
    },
    {
      "x": -14,
      "y": -1,
      "z": 7,
      "name": "Rock_Ice",
      "rotation": 2
    },
    {
      "x": -14,
      "y": 0,
      "z": 7,
      "name": "Rock_Ice",
      "rotation": 2
    },
    {
      "x": -14,
      "y": 1,
      "z": 7,
      "name": "Rock_Ice",
      "rotation": 2
    },
    {
      "x": -14,
      "y": 2,
      "z": 7,
      "name": "Rock_Ice",
      "rotation": 2
    },
    {
      "x": -14,
      "y": 3,
      "z": 7,
      "name": "Rock_Ice",
      "rotation": 2
    },
    {
      "x": -14,
      "y": 4,
      "z": 7,
      "name": "Rock_Ice",
      "rotation": 2
    },
    {
      "x": -14,
      "y": 5,
      "z": 7,
      "name": "Rock_Ice",
      "rotation": 2
    },
    {
      "x": -14,
      "y": 6,
      "z": 7,
      "name": "Rock_Ice",
      "rotation": 2
    },
    {
      "x": -14,
      "y": 7,
      "z": 7,
      "name": "Rock_Ice",
      "rotation": 2
    },
    {
      "x": -14,
      "y": 8,
      "z": 7,
      "name": "Rock_Ice",
      "rotation": 2
    },
    {
      "x": -14,
      "y": 9,
      "z": 7,
      "name": "Rock_Ice",
      "rotation": 2
    },
    {
      "x": -14,
      "y": 10,
      "z": 7,
      "name": "Rock_Ice",
      "rotation": 2
    },
    {
      "x": -14,
      "y": 11,
      "z": 7,
      "name": "Wood_Hardwood_Planks",
      "rotation": 1
    },
    {
      "x": -14,
      "y": 12,
      "z": 7,
      "name": "Rock_Ice",
      "rotation": 2
    },
    {
      "x": -14,
      "y": 13,
      "z": 7,
      "name": "Rock_Ice",
      "rotation": 2
    },
    {
      "x": -14,
      "y": 14,
      "z": 7,
      "name": "Rock_Ice",
      "rotation": 2
    },
    {
      "x": -14,
      "y": 15,
      "z": 7,
      "name": "Rock_Ice",
      "rotation": 2
    },
    {
      "x": -14,
      "y": 16,
      "z": 7,
      "name": "Rock_Ice",
      "rotation": 2
    },
    {
      "x": -14,
      "y": 17,
      "z": 7,
      "name": "Rock_Ice",
      "rotation": 2
    },
    {
      "x": -14,
      "y": -6,
      "z": 8,
      "name": "Rock_Ice",
      "rotation": 2
    },
    {
      "x": -14,
      "y": -5,
      "z": 8,
      "name": "Rock_Ice",
      "rotation": 2
    },
    {
      "x": -14,
      "y": -4,
      "z": 8,
      "name": "Rock_Ice",
      "rotation": 2
    },
    {
      "x": -14,
      "y": -3,
      "z": 8,
      "name": "Rock_Ice",
      "rotation": 2
    },
    {
      "x": -14,
      "y": -2,
      "z": 8,
      "name": "Rock_Ice",
      "rotation": 2
    },
    {
      "x": -14,
      "y": -1,
      "z": 8,
      "name": "Rock_Ice",
      "rotation": 2
    },
    {
      "x": -14,
      "y": 0,
      "z": 8,
      "name": "Rock_Ice",
      "rotation": 2
    },
    {
      "x": -14,
      "y": 1,
      "z": 8,
      "name": "Rock_Ice",
      "rotation": 2
    },
    {
      "x": -14,
      "y": 2,
      "z": 8,
      "name": "Rock_Ice",
      "rotation": 2
    },
    {
      "x": -14,
      "y": 3,
      "z": 8,
      "name": "Rock_Ice",
      "rotation": 2
    },
    {
      "x": -14,
      "y": 4,
      "z": 8,
      "name": "Rock_Ice",
      "rotation": 2
    },
    {
      "x": -14,
      "y": 5,
      "z": 8,
      "name": "Wood_Hardwood_Planks",
      "rotation": 3
    },
    {
      "x": -14,
      "y": 6,
      "z": 8,
      "name": "Wood_Hardwood_Planks",
      "rotation": 1
    },
    {
      "x": -14,
      "y": 7,
      "z": 8,
      "name": "Wood_Hardwood_Decorative",
      "rotation": 1
    },
    {
      "x": -14,
      "y": 8,
      "z": 8,
      "name": "Wood_Hardwood_Decorative",
      "rotation": 1
    },
    {
      "x": -14,
      "y": 9,
      "z": 8,
      "name": "Wood_Hardwood_Planks",
      "rotation": 3
    },
    {
      "x": -14,
      "y": 10,
      "z": 8,
      "name": "Rock_Ice",
      "rotation": 2
    },
    {
      "x": -14,
      "y": 11,
      "z": 8,
      "name": "Wood_Hardwood_Planks",
      "rotation": 1
    },
    {
      "x": -14,
      "y": 12,
      "z": 8,
      "name": "Wood_Hardwood_Planks",
      "rotation": 1
    },
    {
      "x": -14,
      "y": 13,
      "z": 8,
      "name": "Rock_Ice",
      "rotation": 2
    },
    {
      "x": -14,
      "y": 14,
      "z": 8,
      "name": "Rock_Ice",
      "rotation": 2
    },
    {
      "x": -14,
      "y": 15,
      "z": 8,
      "name": "Rock_Ice",
      "rotation": 2
    },
    {
      "x": -14,
      "y": 16,
      "z": 8,
      "name": "Rock_Ice",
      "rotation": 2
    },
    {
      "x": -14,
      "y": 17,
      "z": 8,
      "name": "Rock_Ice",
      "rotation": 2
    },
    {
      "x": -14,
      "y": -7,
      "z": 9,
      "name": "Rock_Ice",
      "rotation": 2
    },
    {
      "x": -14,
      "y": -6,
      "z": 9,
      "name": "Rock_Ice",
      "rotation": 2
    },
    {
      "x": -14,
      "y": -5,
      "z": 9,
      "name": "Rock_Ice",
      "rotation": 2
    },
    {
      "x": -14,
      "y": -4,
      "z": 9,
      "name": "Rock_Ice",
      "rotation": 2
    },
    {
      "x": -14,
      "y": -3,
      "z": 9,
      "name": "Rock_Ice",
      "rotation": 2
    },
    {
      "x": -14,
      "y": -2,
      "z": 9,
      "name": "Rock_Ice",
      "rotation": 2
    },
    {
      "x": -14,
      "y": -1,
      "z": 9,
      "name": "Rock_Ice",
      "rotation": 2
    },
    {
      "x": -14,
      "y": 0,
      "z": 9,
      "name": "Rock_Ice",
      "rotation": 2
    },
    {
      "x": -14,
      "y": 1,
      "z": 9,
      "name": "Rock_Ice",
      "rotation": 2
    },
    {
      "x": -14,
      "y": 2,
      "z": 9,
      "name": "Rock_Ice",
      "rotation": 2
    },
    {
      "x": -14,
      "y": 3,
      "z": 9,
      "name": "Rock_Ice",
      "rotation": 2
    },
    {
      "x": -14,
      "y": 4,
      "z": 9,
      "name": "Wood_Hardwood_Planks",
      "rotation": 1
    },
    {
      "x": -14,
      "y": 5,
      "z": 9,
      "name": "Wood_Hardwood_Planks",
      "rotation": 1
    },
    {
      "x": -14,
      "y": 6,
      "z": 9,
      "name": "Wood_Hardwood_Planks",
      "rotation": 3
    },
    {
      "x": -14,
      "y": 7,
      "z": 9,
      "name": "Wood_Hardwood_Planks",
      "rotation": 1
    },
    {
      "x": -14,
      "y": 8,
      "z": 9,
      "name": "Wood_Hardwood_Decorative",
      "rotation": 1
    },
    {
      "x": -14,
      "y": 9,
      "z": 9,
      "name": "Wood_Hardwood_Decorative",
      "rotation": 1
    },
    {
      "x": -14,
      "y": 10,
      "z": 9,
      "name": "Wood_Hardwood_Decorative",
      "rotation": 1
    },
    {
      "x": -14,
      "y": 11,
      "z": 9,
      "name": "Wood_Hardwood_Planks",
      "rotation": 1
    },
    {
      "x": -14,
      "y": 12,
      "z": 9,
      "name": "Wood_Hardwood_Planks",
      "rotation": 1
    },
    {
      "x": -14,
      "y": 13,
      "z": 9,
      "name": "Wood_Hardwood_Planks"
    },
    {
      "x": -14,
      "y": 14,
      "z": 9,
      "name": "Rock_Ice",
      "rotation": 2
    },
    {
      "x": -14,
      "y": 15,
      "z": 9,
      "name": "Rock_Ice",
      "rotation": 2
    },
    {
      "x": -14,
      "y": 16,
      "z": 9,
      "name": "Rock_Ice",
      "rotation": 2
    },
    {
      "x": -14,
      "y": 17,
      "z": 9,
      "name": "Rock_Ice",
      "rotation": 2
    },
    {
      "x": -14,
      "y": 18,
      "z": 9,
      "name": "Rock_Ice",
      "rotation": 2
    },
    {
      "x": -14,
      "y": -8,
      "z": 10,
      "name": "Rock_Ice",
      "rotation": 2
    },
    {
      "x": -14,
      "y": -7,
      "z": 10,
      "name": "Rock_Ice",
      "rotation": 2
    },
    {
      "x": -14,
      "y": -6,
      "z": 10,
      "name": "Rock_Ice",
      "rotation": 2
    },
    {
      "x": -14,
      "y": -5,
      "z": 10,
      "name": "Rock_Ice",
      "rotation": 2
    },
    {
      "x": -14,
      "y": -4,
      "z": 10,
      "name": "Rock_Ice",
      "rotation": 2
    },
    {
      "x": -14,
      "y": -3,
      "z": 10,
      "name": "Rock_Ice",
      "rotation": 2
    },
    {
      "x": -14,
      "y": -2,
      "z": 10,
      "name": "Rock_Ice",
      "rotation": 2
    },
    {
      "x": -14,
      "y": -1,
      "z": 10,
      "name": "Rock_Ice",
      "rotation": 2
    },
    {
      "x": -14,
      "y": 0,
      "z": 10,
      "name": "Rock_Ice",
      "rotation": 2
    },
    {
      "x": -14,
      "y": 1,
      "z": 10,
      "name": "Rock_Ice",
      "rotation": 2
    },
    {
      "x": -14,
      "y": 2,
      "z": 10,
      "name": "Rock_Ice",
      "rotation": 2
    },
    {
      "x": -14,
      "y": 3,
      "z": 10,
      "name": "Rock_Ice",
      "rotation": 2
    },
    {
      "x": -14,
      "y": 4,
      "z": 10,
      "name": "Rock_Ice",
      "rotation": 2
    },
    {
      "x": -14,
      "y": 5,
      "z": 10,
      "name": "Wood_Hardwood_Planks",
      "rotation": 1
    },
    {
      "x": -14,
      "y": 6,
      "z": 10,
      "name": "Wood_Hardwood_Planks",
      "rotation": 1
    },
    {
      "x": -14,
      "y": 7,
      "z": 10,
      "name": "Wood_Hardwood_Planks",
      "rotation": 35
    },
    {
      "x": -14,
      "y": 8,
      "z": 10,
      "name": "Wood_Hardwood_Planks",
      "rotation": 1
    },
    {
      "x": -14,
      "y": 9,
      "z": 10,
      "name": "Wood_Hardwood_Planks",
      "rotation": 1
    },
    {
      "x": -14,
      "y": 10,
      "z": 10,
      "name": "Wood_Hardwood_Planks",
      "rotation": 1
    },
    {
      "x": -14,
      "y": 11,
      "z": 10,
      "name": "Wood_Hardwood_Decorative",
      "rotation": 1
    },
    {
      "x": -14,
      "y": 12,
      "z": 10,
      "name": "Wood_Hardwood_Planks",
      "rotation": 1
    },
    {
      "x": -14,
      "y": 13,
      "z": 10,
      "name": "Wood_Hardwood_Planks",
      "rotation": 1
    },
    {
      "x": -14,
      "y": 14,
      "z": 10,
      "name": "Wood_Hardwood_Planks",
      "rotation": 1
    },
    {
      "x": -14,
      "y": 15,
      "z": 10,
      "name": "Rock_Ice",
      "rotation": 2
    },
    {
      "x": -14,
      "y": 16,
      "z": 10,
      "name": "Rock_Ice",
      "rotation": 2
    },
    {
      "x": -14,
      "y": 17,
      "z": 10,
      "name": "Rock_Ice",
      "rotation": 2
    },
    {
      "x": -14,
      "y": 18,
      "z": 10,
      "name": "Rock_Ice",
      "rotation": 2
    },
    {
      "x": -14,
      "y": -8,
      "z": 11,
      "name": "Rock_Ice",
      "rotation": 2
    },
    {
      "x": -14,
      "y": -7,
      "z": 11,
      "name": "Rock_Ice",
      "rotation": 2
    },
    {
      "x": -14,
      "y": -6,
      "z": 11,
      "name": "Rock_Ice",
      "rotation": 2
    },
    {
      "x": -14,
      "y": -5,
      "z": 11,
      "name": "Rock_Ice",
      "rotation": 2
    },
    {
      "x": -14,
      "y": -4,
      "z": 11,
      "name": "Rock_Ice",
      "rotation": 2
    },
    {
      "x": -14,
      "y": -3,
      "z": 11,
      "name": "Rock_Ice",
      "rotation": 2
    },
    {
      "x": -14,
      "y": -2,
      "z": 11,
      "name": "Rock_Ice",
      "rotation": 2
    },
    {
      "x": -14,
      "y": -1,
      "z": 11,
      "name": "Rock_Ice",
      "rotation": 2
    },
    {
      "x": -14,
      "y": 0,
      "z": 11,
      "name": "Rock_Ice",
      "rotation": 2
    },
    {
      "x": -14,
      "y": 1,
      "z": 11,
      "name": "Rock_Ice",
      "rotation": 2
    },
    {
      "x": -14,
      "y": 2,
      "z": 11,
      "name": "Rock_Ice",
      "rotation": 2
    },
    {
      "x": -14,
      "y": 3,
      "z": 11,
      "name": "Rock_Ice",
      "rotation": 2
    },
    {
      "x": -14,
      "y": 4,
      "z": 11,
      "name": "Rock_Ice",
      "rotation": 2
    },
    {
      "x": -14,
      "y": 5,
      "z": 11,
      "name": "Wood_Hardwood_Planks",
      "rotation": 1
    },
    {
      "x": -14,
      "y": 6,
      "z": 11,
      "name": "Wood_Hardwood_Ornate",
      "rotation": 1
    },
    {
      "x": -14,
      "y": 7,
      "z": 11,
      "name": "Wood_Hardwood_Ornate",
      "rotation": 1
    },
    {
      "x": -14,
      "y": 8,
      "z": 11,
      "name": "Wood_Hardwood_Planks",
      "rotation": 3
    },
    {
      "x": -14,
      "y": 9,
      "z": 11,
      "name": "Wood_Hardwood_Planks",
      "rotation": 1
    },
    {
      "x": -14,
      "y": 10,
      "z": 11,
      "name": "Wood_Hardwood_Planks",
      "rotation": 1
    },
    {
      "x": -14,
      "y": 11,
      "z": 11,
      "name": "Wood_Hardwood_Planks",
      "rotation": 3
    },
    {
      "x": -14,
      "y": 12,
      "z": 11,
      "name": "Wood_Hardwood_Planks",
      "rotation": 1
    },
    {
      "x": -14,
      "y": 13,
      "z": 11,
      "name": "Wood_Hardwood_Planks",
      "rotation": 1
    },
    {
      "x": -14,
      "y": 14,
      "z": 11,
      "name": "Wood_Hardwood_Planks",
      "rotation": 1
    },
    {
      "x": -14,
      "y": 15,
      "z": 11,
      "name": "Rock_Ice",
      "rotation": 2
    },
    {
      "x": -14,
      "y": 16,
      "z": 11,
      "name": "Rock_Ice",
      "rotation": 2
    },
    {
      "x": -14,
      "y": 17,
      "z": 11,
      "name": "Rock_Ice",
      "rotation": 2
    },
    {
      "x": -14,
      "y": 18,
      "z": 11,
      "name": "Rock_Ice_Stalactite_Large"
    },
    {
      "x": -14,
      "y": 19,
      "z": 11,
      "name": "Rock_Ice_Stalactite_Large",
      "filler": 1024
    },
    {
      "x": -14,
      "y": -9,
      "z": 12,
      "name": "Rock_Ice",
      "rotation": 2
    },
    {
      "x": -14,
      "y": -8,
      "z": 12,
      "name": "Rock_Ice",
      "rotation": 2
    },
    {
      "x": -14,
      "y": -7,
      "z": 12,
      "name": "Rock_Ice",
      "rotation": 2
    },
    {
      "x": -14,
      "y": -6,
      "z": 12,
      "name": "Rock_Ice",
      "rotation": 2
    },
    {
      "x": -14,
      "y": -5,
      "z": 12,
      "name": "Rock_Ice",
      "rotation": 2
    },
    {
      "x": -14,
      "y": -4,
      "z": 12,
      "name": "Rock_Ice",
      "rotation": 2
    },
    {
      "x": -14,
      "y": -3,
      "z": 12,
      "name": "Rock_Ice",
      "rotation": 2
    },
    {
      "x": -14,
      "y": -2,
      "z": 12,
      "name": "Rock_Ice",
      "rotation": 2
    },
    {
      "x": -14,
      "y": -1,
      "z": 12,
      "name": "Rock_Ice",
      "rotation": 2
    },
    {
      "x": -14,
      "y": 0,
      "z": 12,
      "name": "Rock_Ice",
      "rotation": 2
    },
    {
      "x": -14,
      "y": 1,
      "z": 12,
      "name": "Rock_Ice",
      "rotation": 2
    },
    {
      "x": -14,
      "y": 2,
      "z": 12,
      "name": "Rock_Ice",
      "rotation": 2
    },
    {
      "x": -14,
      "y": 3,
      "z": 12,
      "name": "Rock_Ice",
      "rotation": 2
    },
    {
      "x": -14,
      "y": 4,
      "z": 12,
      "name": "Rock_Ice",
      "rotation": 2
    },
    {
      "x": -14,
      "y": 5,
      "z": 12,
      "name": "Rock_Ice",
      "rotation": 2
    },
    {
      "x": -14,
      "y": 6,
      "z": 12,
      "name": "Wood_Hardwood_Planks",
      "rotation": 1
    },
    {
      "x": -14,
      "y": 7,
      "z": 12,
      "name": "Wood_Hardwood_Planks",
      "rotation": 3
    },
    {
      "x": -14,
      "y": 8,
      "z": 12,
      "name": "Wood_Hardwood_Planks",
      "rotation": 3
    },
    {
      "x": -14,
      "y": 9,
      "z": 12,
      "name": "Wood_Hardwood_Planks",
      "rotation": 1
    },
    {
      "x": -14,
      "y": 10,
      "z": 12,
      "name": "Wood_Hardwood_Planks",
      "rotation": 1
    },
    {
      "x": -14,
      "y": 11,
      "z": 12,
      "name": "Wood_Hardwood_Planks",
      "rotation": 3
    },
    {
      "x": -14,
      "y": 12,
      "z": 12,
      "name": "Wood_Hardwood_Planks",
      "rotation": 3
    },
    {
      "x": -14,
      "y": 13,
      "z": 12,
      "name": "Wood_Hardwood_Planks",
      "rotation": 1
    },
    {
      "x": -14,
      "y": 14,
      "z": 12,
      "name": "Wood_Hardwood_Planks",
      "rotation": 1
    },
    {
      "x": -14,
      "y": 15,
      "z": 12,
      "name": "Wood_Hardwood_Planks",
      "rotation": 1
    },
    {
      "x": -14,
      "y": 16,
      "z": 12,
      "name": "Rock_Ice",
      "rotation": 2
    },
    {
      "x": -14,
      "y": 17,
      "z": 12,
      "name": "Rock_Ice_Icicles"
    },
    {
      "x": -14,
      "y": -11,
      "z": 13,
      "name": "Rock_Ice",
      "rotation": 2
    },
    {
      "x": -14,
      "y": -10,
      "z": 13,
      "name": "Rock_Ice",
      "rotation": 2
    },
    {
      "x": -14,
      "y": -9,
      "z": 13,
      "name": "Rock_Ice",
      "rotation": 2
    },
    {
      "x": -14,
      "y": -8,
      "z": 13,
      "name": "Rock_Ice",
      "rotation": 2
    },
    {
      "x": -14,
      "y": -7,
      "z": 13,
      "name": "Rock_Ice",
      "rotation": 2
    },
    {
      "x": -14,
      "y": -6,
      "z": 13,
      "name": "Rock_Ice",
      "rotation": 2
    },
    {
      "x": -14,
      "y": -5,
      "z": 13,
      "name": "Rock_Ice",
      "rotation": 2
    },
    {
      "x": -14,
      "y": -4,
      "z": 13,
      "name": "Rock_Ice",
      "rotation": 2
    },
    {
      "x": -14,
      "y": -3,
      "z": 13,
      "name": "Rock_Ice",
      "rotation": 2
    },
    {
      "x": -14,
      "y": -2,
      "z": 13,
      "name": "Rock_Ice",
      "rotation": 2
    },
    {
      "x": -14,
      "y": -1,
      "z": 13,
      "name": "Rock_Ice",
      "rotation": 2
    },
    {
      "x": -14,
      "y": 0,
      "z": 13,
      "name": "Rock_Ice",
      "rotation": 2
    },
    {
      "x": -14,
      "y": 1,
      "z": 13,
      "name": "Rock_Ice",
      "rotation": 2
    },
    {
      "x": -14,
      "y": 2,
      "z": 13,
      "name": "Rock_Ice",
      "rotation": 2
    },
    {
      "x": -14,
      "y": 3,
      "z": 13,
      "name": "Rock_Ice",
      "rotation": 2
    },
    {
      "x": -14,
      "y": 4,
      "z": 13,
      "name": "Rock_Ice",
      "rotation": 2
    },
    {
      "x": -14,
      "y": 5,
      "z": 13,
      "name": "Rock_Ice",
      "rotation": 2
    },
    {
      "x": -14,
      "y": 6,
      "z": 13,
      "name": "Wood_Hardwood_Planks",
      "rotation": 1
    },
    {
      "x": -14,
      "y": 7,
      "z": 13,
      "name": "Wood_Hardwood_Planks",
      "rotation": 1
    },
    {
      "x": -14,
      "y": 8,
      "z": 13,
      "name": "Wood_Hardwood_Planks",
      "rotation": 3
    },
    {
      "x": -14,
      "y": 9,
      "z": 13,
      "name": "Wood_Hardwood_Planks",
      "rotation": 3
    },
    {
      "x": -14,
      "y": 10,
      "z": 13,
      "name": "Wood_Hardwood_Planks",
      "rotation": 35
    },
    {
      "x": -14,
      "y": 11,
      "z": 13,
      "name": "Wood_Hardwood_Planks",
      "rotation": 1
    },
    {
      "x": -14,
      "y": 12,
      "z": 13,
      "name": "Wood_Hardwood_Planks",
      "rotation": 3
    },
    {
      "x": -14,
      "y": 13,
      "z": 13,
      "name": "Wood_Hardwood_Planks",
      "rotation": 3
    },
    {
      "x": -14,
      "y": 14,
      "z": 13,
      "name": "Wood_Hardwood_Planks",
      "rotation": 1
    },
    {
      "x": -14,
      "y": 15,
      "z": 13,
      "name": "Wood_Hardwood_Planks",
      "rotation": 1
    },
    {
      "x": -14,
      "y": 16,
      "z": 13,
      "name": "Wood_Hardwood_Planks",
      "rotation": 1
    },
    {
      "x": -14,
      "y": -12,
      "z": 14,
      "name": "Rock_Ice",
      "rotation": 2
    },
    {
      "x": -14,
      "y": -11,
      "z": 14,
      "name": "Rock_Ice",
      "rotation": 2
    },
    {
      "x": -14,
      "y": -10,
      "z": 14,
      "name": "Rock_Ice",
      "rotation": 2
    },
    {
      "x": -14,
      "y": -9,
      "z": 14,
      "name": "Rock_Ice",
      "rotation": 2
    },
    {
      "x": -14,
      "y": -8,
      "z": 14,
      "name": "Rock_Ice",
      "rotation": 2
    },
    {
      "x": -14,
      "y": -7,
      "z": 14,
      "name": "Rock_Ice",
      "rotation": 2
    },
    {
      "x": -14,
      "y": -6,
      "z": 14,
      "name": "Rock_Ice",
      "rotation": 2
    },
    {
      "x": -14,
      "y": -5,
      "z": 14,
      "name": "Rock_Ice",
      "rotation": 2
    },
    {
      "x": -14,
      "y": -4,
      "z": 14,
      "name": "Rock_Ice",
      "rotation": 2
    },
    {
      "x": -14,
      "y": -3,
      "z": 14,
      "name": "Rock_Ice",
      "rotation": 2
    },
    {
      "x": -14,
      "y": -2,
      "z": 14,
      "name": "Rock_Ice",
      "rotation": 2
    },
    {
      "x": -14,
      "y": -1,
      "z": 14,
      "name": "Rock_Ice",
      "rotation": 2
    },
    {
      "x": -14,
      "y": 0,
      "z": 14,
      "name": "Rock_Ice",
      "rotation": 2
    },
    {
      "x": -14,
      "y": 1,
      "z": 14,
      "name": "Rock_Ice",
      "rotation": 2
    },
    {
      "x": -14,
      "y": 2,
      "z": 14,
      "name": "Rock_Ice",
      "rotation": 2
    },
    {
      "x": -14,
      "y": 3,
      "z": 14,
      "name": "Rock_Ice",
      "rotation": 2
    },
    {
      "x": -14,
      "y": 4,
      "z": 14,
      "name": "Rock_Ice",
      "rotation": 2
    },
    {
      "x": -14,
      "y": 5,
      "z": 14,
      "name": "Rock_Ice",
      "rotation": 2
    },
    {
      "x": -14,
      "y": 6,
      "z": 14,
      "name": "Wood_Hardwood_Planks",
      "rotation": 1
    },
    {
      "x": -14,
      "y": 7,
      "z": 14,
      "name": "Wood_Hardwood_Planks",
