{
  "version": 8,
  "blockIdVersion": 11,
  "anchorX": 0,
  "anchorY": 0,
  "anchorZ": 0,
  "blocks": [
    {
      "x": -30,
      "y": 0,
      "z": -2,
      "name": "Soil_Ash"
    },
    {
      "x": -30,
      "y": 0,
      "z": -1,
      "name": "Soil_Ash"
    },
    {
      "x": -30,
      "y": 0,
      "z": 0,
      "name": "Soil_Sand_Ashen"
    },
    {
      "x": -30,
      "y": 0,
      "z": 1,
      "name": "Soil_Ash"
    },
    {
      "x": -30,
      "y": 19,
      "z": 1,
      "name": "Rock_Magma_Cooled"
    },
    {
      "x": -30,
      "y": 20,
      "z": 1,
      "name": "Plant_Moss_Rug_Pink",
      "support": 15
    },
    {
      "x": -30,
      "y": 0,
      "z": 2,
      "name": "Soil_Sand_Ashen"
    },
    {
      "x": -30,
      "y": 19,
      "z": 2,
      "name": "Rock_Magma_Cooled"
    },
    {
      "x": -30,
      "y": 20,
      "z": 2,
      "name": "Plant_Moss_Rug_Pink",
      "support": 15
    },
    {
      "x": -30,
      "y": 0,
      "z": 3,
      "name": "Soil_Ash"
    },
    {
      "x": -30,
      "y": 19,
      "z": 3,
      "name": "Rock_Magma_Cooled"
    },
    {
      "x": -30,
      "y": 0,
      "z": 4,
      "name": "Soil_Sand_Ashen"
    },
    {
      "x": -30,
      "y": 0,
      "z": 5,
      "name": "Soil_Ash"
    },
    {
      "x": -30,
      "y": 0,
      "z": 6,
      "name": "Soil_Ash"
    },
    {
      "x": -30,
      "y": 0,
      "z": 7,
      "name": "Soil_Ash"
    },
    {
      "x": -30,
      "y": 0,
      "z": 8,
      "name": "Soil_Ash"
    },
    {
      "x": -30,
      "y": 42,
      "z": 13,
      "name": "Plant_Vine_Wall_Poisoned",
      "support": 15,
      "rotation": 2
    },
    {
      "x": -30,
      "y": 43,
      "z": 13,
      "name": "Plant_Vine_Wall_Poisoned",
      "support": 15,
      "rotation": 2
    },
    {
      "x": -30,
      "y": 44,
      "z": 13,
      "name": "Plant_Vine_Wall_Poisoned",
      "support": 15,
      "rotation": 2
    },
    {
      "x": -30,
      "y": 42,
      "z": 14,
      "name": "Rock_Magma_Cooled",
      "rotation": 1
    },
    {
      "x": -30,
      "y": 43,
      "z": 14,
      "name": "Rock_Magma_Cooled",
      "rotation": 1
    },
    {
      "x": -30,
      "y": 44,
      "z": 14,
      "name": "Rock_Magma_Cooled",
      "rotation": 1
    },
    {
      "x": -30,
      "y": 45,
      "z": 14,
      "name": "Rock_Magma_Cooled",
      "rotation": 1
    },
    {
      "x": -30,
      "y": 46,
      "z": 14,
      "name": "Plant_Moss_Rug_Pink",
      "support": 15
    },
    {
      "x": -30,
      "y": 40,
      "z": 15,
      "name": "Rock_Magma_Cooled",
      "rotation": 1
    },
    {
      "x": -30,
      "y": 41,
      "z": 15,
      "name": "Rock_Magma_Cooled",
      "rotation": 1
    },
    {
      "x": -30,
      "y": 42,
      "z": 15,
      "name": "Rock_Magma_Cooled",
      "rotation": 1
    },
    {
      "x": -30,
      "y": 43,
      "z": 15,
      "name": "Rock_Magma_Cooled",
      "rotation": 1
    },
    {
      "x": -30,
      "y": 44,
      "z": 15,
      "name": "Plant_Moss_Rug_Pink",
      "support": 15
    },
    {
      "x": -29,
      "y": 0,
      "z": -4,
      "name": "Soil_Ash"
    },
    {
      "x": -29,
      "y": 0,
      "z": -3,
      "name": "Soil_Sand_Ashen"
    },
    {
      "x": -29,
      "y": 0,
      "z": -2,
      "name": "Soil_Ash"
    },
    {
      "x": -29,
      "y": 0,
      "z": -1,
      "name": "Soil_Ash"
    },
    {
      "x": -29,
      "y": 0,
      "z": 0,
      "name": "Soil_Ash"
    },
    {
      "x": -29,
      "y": 1,
      "z": 0,
      "name": "Soil_Sand_Ashen"
    },
    {
      "x": -29,
      "y": 19,
      "z": 0,
      "name": "Rock_Magma_Cooled"
    },
    {
      "x": -29,
      "y": 20,
      "z": 0,
      "name": "Plant_Moss_Rug_Pink",
      "support": 15
    },
    {
      "x": -29,
      "y": 0,
      "z": 1,
      "name": "Soil_Ash"
    },
    {
      "x": -29,
      "y": 1,
      "z": 1,
      "name": "Soil_Ash"
    },
    {
      "x": -29,
      "y": 18,
      "z": 1,
      "name": "Ore_Adamantite_Magma_Cracked"
    },
    {
      "x": -29,
      "y": 19,
      "z": 1,
      "name": "Rock_Magma_Cooled"
    },
    {
      "x": -29,
      "y": 20,
      "z": 1,
      "name": "Ore_Adamantite_Magma_Cracked"
    },
    {
      "x": -29,
      "y": 21,
      "z": 1,
      "name": "Plant_Moss_Rug_Pink",
      "support": 15
    },
    {
      "x": -29,
      "y": 0,
      "z": 2,
      "name": "Soil_Ash"
    },
    {
      "x": -29,
      "y": 1,
      "z": 2,
      "name": "Soil_Ash"
    },
    {
      "x": -29,
      "y": 17,
      "z": 2,
      "name": "Ore_Adamantite_Magma_Cracked"
    },
    {
      "x": -29,
      "y": 18,
      "z": 2,
      "name": "Rock_Magma_Cooled"
    },
    {
      "x": -29,
      "y": 19,
      "z": 2,
      "name": "Rock_Magma_Cooled"
    },
    {
      "x": -29,
      "y": 20,
      "z": 2,
      "name": "Rock_Magma_Cooled"
    },
    {
      "x": -29,
      "y": 21,
      "z": 2,
      "name": "Plant_Moss_Rug_Pink",
      "support": 15
    },
    {
      "x": -29,
      "y": 0,
      "z": 3,
      "name": "Soil_Ash"
    },
    {
      "x": -29,
      "y": 1,
      "z": 3,
      "name": "Soil_Ash"
    },
    {
      "x": -29,
      "y": 17,
      "z": 3,
      "name": "Rock_Magma_Cooled"
    },
    {
      "x": -29,
      "y": 18,
      "z": 3,
      "name": "Ore_Adamantite_Magma_Cracked"
    },
    {
      "x": -29,
      "y": 19,
      "z": 3,
      "name": "Ore_Adamantite_Magma_Cracked"
    },
    {
      "x": -29,
      "y": 20,
      "z": 3,
      "name": "Rock_Magma_Cooled"
    },
    {
      "x": -29,
      "y": 0,
      "z": 4,
      "name": "Soil_Ash"
    },
    {
      "x": -29,
      "y": 1,
      "z": 4,
      "name": "Soil_Ash"
    },
    {
      "x": -29,
      "y": 17,
      "z": 4,
      "name": "Rock_Magma_Cooled"
    },
    {
      "x": -29,
      "y": 18,
      "z": 4,
      "name": "Ore_Adamantite_Magma_Cracked"
    },
    {
      "x": -29,
      "y": 19,
      "z": 4,
      "name": "Rock_Magma_Cooled"
    },
    {
      "x": -29,
      "y": 20,
      "z": 4,
      "name": "Rock_Magma_Cooled"
    },
    {
      "x": -29,
      "y": 0,
      "z": 5,
      "name": "Soil_Ash"
    },
    {
      "x": -29,
      "y": 1,
      "z": 5,
      "name": "Soil_Ash"
    },
    {
      "x": -29,
      "y": 17,
      "z": 5,
      "name": "Ore_Adamantite_Magma_Cracked"
    },
    {
      "x": -29,
      "y": 18,
      "z": 5,
      "name": "Rock_Magma_Cooled"
    },
    {
      "x": -29,
      "y": 20,
      "z": 5,
      "name": "Ore_Adamantite_Magma_Cracked"
    },
    {
      "x": -29,
      "y": 21,
      "z": 5,
      "name": "Ore_Adamantite_Magma_Cracked"
    },
    {
      "x": -29,
      "y": 22,
      "z": 5,
      "name": "Plant_Moss_Rug_Pink",
      "support": 15
    },
    {
      "x": -29,
      "y": 0,
      "z": 6,
      "name": "Soil_Ash"
    },
    {
      "x": -29,
      "y": 1,
      "z": 6,
      "name": "Soil_Ash"
    },
    {
      "x": -29,
      "y": 17,
      "z": 6,
      "name": "Ore_Adamantite_Magma_Cracked"
    },
    {
      "x": -29,
      "y": 21,
      "z": 6,
      "name": "Rock_Magma_Cooled"
    },
    {
      "x": -29,
      "y": 0,
      "z": 7,
      "name": "Soil_Ash"
    },
    {
      "x": -29,
      "y": 0,
      "z": 8,
      "name": "Soil_Ash"
    },
    {
      "x": -29,
      "y": 0,
      "z": 9,
      "name": "Soil_Sand_Ashen"
    },
    {
      "x": -29,
      "y": 39,
      "z": 14,
      "name": "Plant_Vine_Wall_Poisoned",
      "support": 15,
      "rotation": 2
    },
    {
      "x": -29,
      "y": 42,
      "z": 14,
      "name": "Plant_Vine_Wall_Poisoned",
      "support": 15,
      "rotation": 2
    },
    {
      "x": -29,
      "y": 39,
      "z": 15,
      "name": "Rock_Magma_Cooled",
      "rotation": 1
    },
    {
      "x": -29,
      "y": 40,
      "z": 15,
      "name": "Rock_Magma_Cooled",
      "rotation": 1
    },
    {
      "x": -29,
      "y": 41,
      "z": 15,
      "name": "Rock_Magma_Cooled",
      "rotation": 1
    },
    {
      "x": -29,
      "y": 42,
      "z": 15,
      "name": "Rock_Magma_Cooled",
      "rotation": 1
    },
    {
      "x": -29,
      "y": 43,
      "z": 15,
      "name": "Plant_Moss_Rug_Pink",
      "support": 15
    },
    {
      "x": -29,
      "y": 38,
      "z": 16,
      "name": "Rock_Magma_Cooled",
      "rotation": 1
    },
    {
      "x": -29,
      "y": 39,
      "z": 16,
      "name": "Ore_Adamantite_Magma_Cracked",
      "rotation": 1
    },
    {
      "x": -29,
      "y": 40,
      "z": 16,
      "name": "Rock_Magma_Cooled",
      "rotation": 1
    },
    {
      "x": -29,
      "y": 41,
      "z": 16,
      "name": "Plant_Moss_Rug_Pink",
      "support": 15
    },
    {
      "x": -29,
      "y": 36,
      "z": 17,
      "name": "Rock_Magma_Cooled",
      "rotation": 1
    },
    {
      "x": -29,
      "y": 37,
      "z": 17,
      "name": "Ore_Adamantite_Magma_Cracked",
      "rotation": 1
    },
    {
      "x": -29,
      "y": 38,
      "z": 17,
      "name": "Ore_Adamantite_Magma_Cracked",
      "rotation": 1
    },
    {
      "x": -29,
      "y": 39,
      "z": 17,
      "name": "Rock_Magma_Cooled",
      "rotation": 1
    },
    {
      "x": -29,
      "y": 40,
      "z": 17,
      "name": "Plant_Moss_Rug_Pink",
      "support": 15
    },
    {
      "x": -29,
      "y": 37,
      "z": 18,
      "name": "Rock_Magma_Cooled",
      "rotation": 1
    },
    {
      "x": -29,
      "y": 38,
      "z": 18,
      "name": "Rock_Magma_Cooled",
      "rotation": 1
    },
    {
      "x": -28,
      "y": 0,
      "z": -5,
      "name": "Soil_Ash"
    },
    {
      "x": -28,
      "y": 0,
      "z": -4,
      "name": "Soil_Ash"
    },
    {
      "x": -28,
      "y": 0,
      "z": -3,
      "name": "Soil_Ash"
    },
    {
      "x": -28,
      "y": 1,
      "z": -3,
      "name": "Soil_Ash"
    },
    {
      "x": -28,
      "y": 0,
      "z": -2,
      "name": "Soil_Ash"
    },
    {
      "x": -28,
      "y": 1,
      "z": -2,
      "name": "Soil_Ash"
    },
    {
      "x": -28,
      "y": 0,
      "z": -1,
      "name": "Soil_Ash"
    },
    {
      "x": -28,
      "y": 1,
      "z": -1,
      "name": "Soil_Ash"
    },
    {
      "x": -28,
      "y": 0,
      "z": 0,
      "name": "Soil_Ash"
    },
    {
      "x": -28,
      "y": 1,
      "z": 0,
      "name": "Soil_Ash"
    },
    {
      "x": -28,
      "y": 18,
      "z": 0,
      "name": "Rock_Magma_Cooled"
    },
    {
      "x": -28,
      "y": 19,
      "z": 0,
      "name": "Plant_Moss_Rug_Pink",
      "support": 15
    },
    {
      "x": -28,
      "y": 0,
      "z": 1,
      "name": "Soil_Ash"
    },
    {
      "x": -28,
      "y": 1,
      "z": 1,
      "name": "Soil_Ash"
    },
    {
      "x": -28,
      "y": 17,
      "z": 1,
      "name": "Rock_Magma_Cooled"
    },
    {
      "x": -28,
      "y": 18,
      "z": 1,
      "name": "Rock_Magma_Cooled"
    },
    {
      "x": -28,
      "y": 19,
      "z": 1,
      "name": "Ore_Adamantite_Magma_Cracked"
    },
    {
      "x": -28,
      "y": 20,
      "z": 1,
      "name": "Plant_Moss_Rug_Pink",
      "support": 15
    },
    {
      "x": -28,
      "y": 0,
      "z": 2,
      "name": "Soil_Ash"
    },
    {
      "x": -28,
      "y": 1,
      "z": 2,
      "name": "Soil_Ash"
    },
    {
      "x": -28,
      "y": 2,
      "z": 2,
      "name": "Soil_Ash"
    },
    {
      "x": -28,
      "y": 16,
      "z": 2,
      "name": "Rock_Magma_Cooled"
    },
    {
      "x": -28,
      "y": 17,
      "z": 2,
      "name": "Ore_Adamantite_Magma_Cracked"
    },
    {
      "x": -28,
      "y": 18,
      "z": 2,
      "name": "Rock_Magma_Cooled"
    },
    {
      "x": -28,
      "y": 19,
      "z": 2,
      "name": "Ore_Adamantite_Magma_Cracked"
    },
    {
      "x": -28,
      "y": 20,
      "z": 2,
      "name": "Plant_Moss_Rug_Pink",
      "support": 15
    },
    {
      "x": -28,
      "y": 0,
      "z": 3,
      "name": "Soil_Ash"
    },
    {
      "x": -28,
      "y": 1,
      "z": 3,
      "name": "Soil_Ash"
    },
    {
      "x": -28,
      "y": 2,
      "z": 3,
      "name": "Soil_Ash"
    },
    {
      "x": -28,
      "y": 16,
      "z": 3,
      "name": "Ore_Adamantite_Magma_Cracked"
    },
    {
      "x": -28,
      "y": 17,
      "z": 3,
      "name": "Rock_Magma_Cooled"
    },
    {
      "x": -28,
      "y": 18,
      "z": 3,
      "name": "Ore_Adamantite_Magma_Cracked"
    },
    {
      "x": -28,
      "y": 19,
      "z": 3,
      "name": "Ore_Adamantite_Magma_Cracked"
    },
    {
      "x": -28,
      "y": 20,
      "z": 3,
      "name": "Ore_Adamantite_Magma_Cracked"
    },
    {
      "x": -28,
      "y": 0,
      "z": 4,
      "name": "Soil_Ash"
    },
    {
      "x": -28,
      "y": 1,
      "z": 4,
      "name": "Soil_Ash"
    },
    {
      "x": -28,
      "y": 2,
      "z": 4,
      "name": "Soil_Ash"
    },
    {
      "x": -28,
      "y": 16,
      "z": 4,
      "name": "Rock_Magma_Cooled"
    },
    {
      "x": -28,
      "y": 17,
      "z": 4,
      "name": "Ore_Adamantite_Magma_Cracked"
    },
    {
      "x": -28,
      "y": 18,
      "z": 4,
      "name": "Ore_Adamantite_Magma_Cracked"
    },
    {
      "x": -28,
      "y": 19,
      "z": 4,
      "name": "Rock_Magma_Cooled"
    },
    {
      "x": -28,
      "y": 20,
      "z": 4,
      "name": "Ore_Adamantite_Magma_Cracked"
    },
    {
      "x": -28,
      "y": 21,
      "z": 4,
      "name": "Rock_Magma_Cooled"
    },
    {
      "x": -28,
      "y": 0,
      "z": 5,
      "name": "Soil_Ash"
    },
    {
      "x": -28,
      "y": 1,
      "z": 5,
      "name": "Soil_Ash"
    },
    {
      "x": -28,
      "y": 16,
      "z": 5,
      "name": "Ore_Adamantite_Magma_Cracked"
    },
    {
      "x": -28,
      "y": 17,
      "z": 5,
      "name": "Ore_Adamantite_Magma_Cracked"
    },
    {
      "x": -28,
      "y": 18,
      "z": 5,
      "name": "Ore_Adamantite_Magma_Cracked"
    },
    {
      "x": -28,
      "y": 19,
      "z": 5,
      "name": "Rock_Magma_Cooled"
    },
    {
      "x": -28,
      "y": 20,
      "z": 5,
      "name": "Rock_Magma_Cooled"
    },
    {
      "x": -28,
      "y": 21,
      "z": 5,
      "name": "Ore_Adamantite_Magma_Cracked"
    },
    {
      "x": -28,
      "y": 22,
      "z": 5,
      "name": "Ore_Adamantite_Magma_Cracked"
    },
    {
      "x": -28,
      "y": 23,
      "z": 5,
      "name": "Plant_Moss_Rug_Pink",
      "support": 15
    },
    {
      "x": -28,
      "y": 0,
      "z": 6,
      "name": "Soil_Ash"
    },
    {
      "x": -28,
      "y": 1,
      "z": 6,
      "name": "Soil_Ash"
    },
    {
      "x": -28,
      "y": 16,
      "z": 6,
      "name": "Ore_Adamantite_Magma_Cracked"
    },
    {
      "x": -28,
      "y": 17,
      "z": 6,
      "name": "Ore_Adamantite_Magma_Cracked"
    },
    {
      "x": -28,
      "y": 18,
      "z": 6,
      "name": "Ore_Adamantite_Magma_Cracked"
    },
    {
      "x": -28,
      "y": 20,
      "z": 6,
      "name": "Rock_Magma_Cooled"
    },
    {
      "x": -28,
      "y": 21,
      "z": 6,
      "name": "Ore_Adamantite_Magma_Cracked"
    },
    {
      "x": -28,
      "y": 22,
      "z": 6,
      "name": "Ore_Adamantite_Magma_Cracked"
    },
    {
      "x": -28,
      "y": 0,
      "z": 7,
      "name": "Soil_Ash"
    },
    {
      "x": -28,
      "y": 1,
      "z": 7,
      "name": "Soil_Ash"
    },
    {
      "x": -28,
      "y": 17,
      "z": 7,
      "name": "Ore_Adamantite_Magma_Cracked"
    },
    {
      "x": -28,
      "y": 0,
      "z": 8,
      "name": "Soil_Ash"
    },
    {
      "x": -28,
      "y": 1,
      "z": 8,
      "name": "Soil_Ash"
    },
    {
      "x": -28,
      "y": 0,
      "z": 9,
      "name": "Soil_Ash"
    },
    {
      "x": -28,
      "y": 0,
      "z": 10,
      "name": "Soil_Ash"
    },
    {
      "x": -28,
      "y": 37,
      "z": 15,
      "name": "Plant_Vine_Wall_Poisoned",
      "support": 15,
      "rotation": 2
    },
    {
      "x": -28,
      "y": 39,
      "z": 15,
      "name": "Plant_Vine_Wall_Poisoned",
      "support": 15,
      "rotation": 2
    },
    {
      "x": -28,
      "y": 34,
      "z": 16,
      "name": "Rock_Magma_Cooled",
      "rotation": 1
    },
    {
      "x": -28,
      "y": 35,
      "z": 16,
      "name": "Rock_Magma_Cooled",
      "rotation": 1
    },
    {
      "x": -28,
      "y": 36,
      "z": 16,
      "name": "Ore_Adamantite_Magma_Cracked",
      "rotation": 1
    },
    {
      "x": -28,
      "y": 37,
      "z": 16,
      "name": "Rock_Magma_Cooled",
      "rotation": 1
    },
    {
      "x": -28,
      "y": 38,
      "z": 16,
      "name": "Rock_Magma_Cooled",
      "rotation": 1
    },
    {
      "x": -28,
      "y": 39,
      "z": 16,
      "name": "Rock_Magma_Cooled",
      "rotation": 1
    },
    {
      "x": -28,
      "y": 33,
      "z": 17,
      "name": "Rock_Magma_Cooled",
      "rotation": 1
    },
    {
      "x": -28,
      "y": 34,
      "z": 17,
      "name": "Rock_Magma_Cooled",
      "rotation": 1
    },
    {
      "x": -28,
      "y": 35,
      "z": 17,
      "name": "Ore_Adamantite_Magma_Cracked",
      "rotation": 1
    },
    {
      "x": -28,
      "y": 36,
      "z": 17,
      "name": "Ore_Adamantite_Magma_Cracked",
      "rotation": 1
    },
    {
      "x": -28,
      "y": 37,
      "z": 17,
      "name": "Rock_Magma_Cooled",
      "rotation": 1
    },
    {
      "x": -28,
      "y": 38,
      "z": 17,
      "name": "Rock_Magma_Cooled",
      "rotation": 1
    },
    {
      "x": -28,
      "y": 33,
      "z": 18,
      "name": "Rock_Magma_Cooled",
      "rotation": 1
    },
    {
      "x": -28,
      "y": 34,
      "z": 18,
      "name": "Rock_Magma_Cooled",
      "rotation": 1
    },
    {
      "x": -28,
      "y": 35,
      "z": 18,
      "name": "Rock_Magma_Cooled",
      "rotation": 1
    },
    {
      "x": -28,
      "y": 36,
      "z": 18,
      "name": "Rock_Magma_Cooled",
      "rotation": 1
    },
    {
      "x": -28,
      "y": 37,
      "z": 18,
      "name": "Rock_Magma_Cooled",
      "rotation": 1
    },
    {
      "x": -28,
      "y": 34,
      "z": 19,
      "name": "Rock_Magma_Cooled",
      "rotation": 1
    },
    {
      "x": -28,
      "y": 35,
      "z": 19,
      "name": "Rock_Magma_Cooled",
      "rotation": 1
    },
    {
      "x": -27,
      "y": 0,
      "z": -9,
      "name": "Soil_Sand_Ashen"
    },
    {
      "x": -27,
      "y": 1,
      "z": -9,
      "name": "Soil_Sand_Ashen"
    },
    {
      "x": -27,
      "y": 0,
      "z": -8,
      "name": "Soil_Ash"
    },
    {
      "x": -27,
      "y": 1,
      "z": -8,
      "name": "Soil_Sand_Ashen"
    },
    {
      "x": -27,
      "y": 0,
      "z": -7,
      "name": "Soil_Ash"
    },
    {
      "x": -27,
      "y": 1,
      "z": -7,
      "name": "Soil_Ash"
    },
    {
      "x": -27,
      "y": 0,
      "z": -6,
      "name": "Soil_Ash"
    },
    {
      "x": -27,
      "y": 1,
      "z": -6,
      "name": "Soil_Sand_Ashen"
    },
    {
      "x": -27,
      "y": 0,
      "z": -5,
      "name": "Soil_Ash"
    },
    {
      "x": -27,
      "y": 1,
      "z": -5,
      "name": "Soil_Ash"
    },
    {
      "x": -27,
      "y": 0,
      "z": -4,
      "name": "Soil_Ash"
    },
    {
      "x": -27,
      "y": 1,
      "z": -4,
      "name": "Soil_Ash"
    },
    {
      "x": -27,
      "y": 0,
      "z": -3,
      "name": "Soil_Ash"
    },
    {
      "x": -27,
      "y": 1,
      "z": -3,
      "name": "Soil_Ash"
    },
    {
      "x": -27,
      "y": 2,
      "z": -3,
      "name": "Soil_Ash"
    },
    {
      "x": -27,
      "y": 0,
      "z": -2,
      "name": "Soil_Ash"
    },
    {
      "x": -27,
      "y": 1,
      "z": -2,
      "name": "Soil_Ash"
    },
    {
      "x": -27,
      "y": 2,
      "z": -2,
      "name": "Soil_Ash"
    },
    {
      "x": -27,
      "y": 0,
      "z": -1,
      "name": "Soil_Ash"
    },
    {
      "x": -27,
      "y": 1,
      "z": -1,
      "name": "Soil_Ash"
    },
    {
      "x": -27,
      "y": 2,
      "z": -1,
      "name": "Soil_Ash"
    },
    {
      "x": -27,
      "y": 0,
      "z": 0,
      "name": "Soil_Ash"
    },
    {
      "x": -27,
      "y": 1,
      "z": 0,
      "name": "Soil_Ash"
    },
    {
      "x": -27,
      "y": 2,
      "z": 0,
      "name": "Soil_Ash"
    },
    {
      "x": -27,
      "y": 17,
      "z": 0,
      "name": "Rock_Magma_Cooled"
    },
    {
      "x": -27,
      "y": 18,
      "z": 0,
      "name": "Plant_Vine_Wall_Poisoned",
      "support": 15,
      "rotation": 2
    },
    {
      "x": -27,
      "y": 0,
      "z": 1,
      "name": "Soil_Ash"
    },
    {
      "x": -27,
      "y": 1,
      "z": 1,
      "name": "Soil_Ash"
    },
    {
      "x": -27,
      "y": 2,
      "z": 1,
      "name": "Soil_Ash"
    },
    {
      "x": -27,
      "y": 16,
      "z": 1,
      "name": "Ore_Adamantite_Magma_Cracked"
    },
    {
      "x": -27,
      "y": 17,
      "z": 1,
      "name": "Rock_Magma_Cooled"
    },
    {
      "x": -27,
      "y": 18,
      "z": 1,
      "name": "Rock_Magma_Cooled"
    },
    {
      "x": -27,
      "y": 0,
      "z": 2,
      "name": "Soil_Ash"
    },
    {
      "x": -27,
      "y": 1,
      "z": 2,
      "name": "Soil_Ash"
    },
    {
      "x": -27,
      "y": 2,
      "z": 2,
      "name": "Soil_Ash"
    },
    {
      "x": -27,
      "y": 16,
      "z": 2,
      "name": "Ore_Adamantite_Magma_Cracked"
    },
    {
      "x": -27,
      "y": 17,
      "z": 2,
      "name": "Rock_Magma_Cooled"
    },
    {
      "x": -27,
      "y": 18,
      "z": 2,
      "name": "Rock_Magma_Cooled"
    },
    {
      "x": -27,
      "y": 19,
      "z": 2,
      "name": "Ore_Adamantite_Magma_Cracked"
    },
    {
      "x": -27,
      "y": 20,
      "z": 2,
      "name": "Plant_Moss_Rug_Pink",
      "support": 15
    },
    {
      "x": -27,
      "y": 0,
      "z": 3,
      "name": "Soil_Ash"
    },
    {
      "x": -27,
      "y": 1,
      "z": 3,
      "name": "Soil_Ash"
    },
    {
      "x": -27,
      "y": 2,
      "z": 3,
      "name": "Soil_Ash"
    },
    {
      "x": -27,
      "y": 16,
      "z": 3,
      "name": "Rock_Magma_Cooled"
    },
    {
      "x": -27,
      "y": 17,
      "z": 3,
      "name": "Ore_Adamantite_Magma_Cracked"
    },
    {
      "x": -27,
      "y": 18,
      "z": 3,
      "name": "Ore_Adamantite_Magma_Cracked"
    },
    {
      "x": -27,
      "y": 19,
      "z": 3,
      "name": "Ore_Adamantite_Magma_Cracked"
    },
    {
      "x": -27,
      "y": 20,
      "z": 3,
      "name": "Rock_Magma_Cooled"
    },
    {
      "x": -27,
      "y": 21,
      "z": 3,
      "name": "Ore_Adamantite_Magma_Cracked"
    },
    {
      "x": -27,
      "y": 0,
      "z": 4,
      "name": "Soil_Ash"
    },
    {
      "x": -27,
      "y": 1,
      "z": 4,
      "name": "Soil_Ash"
    },
    {
      "x": -27,
      "y": 2,
      "z": 4,
      "name": "Soil_Ash"
    },
    {
      "x": -27,
      "y": 16,
      "z": 4,
      "name": "Ore_Adamantite_Magma_Cracked"
    },
    {
      "x": -27,
      "y": 17,
      "z": 4,
      "name": "Ore_Adamantite_Magma_Cracked"
    },
    {
      "x": -27,
      "y": 18,
      "z": 4,
      "name": "Ore_Adamantite_Magma_Cracked"
    },
    {
      "x": -27,
      "y": 19,
      "z": 4,
      "name": "Rock_Magma_Cooled"
    },
    {
      "x": -27,
      "y": 20,
      "z": 4,
      "name": "Ore_Adamantite_Magma_Cracked"
    },
    {
      "x": -27,
      "y": 21,
      "z": 4,
      "name": "Ore_Adamantite_Magma_Cracked"
    },
    {
      "x": -27,
      "y": 0,
      "z": 5,
      "name": "Soil_Ash"
    },
    {
      "x": -27,
      "y": 1,
      "z": 5,
      "name": "Soil_Ash"
    },
    {
      "x": -27,
      "y": 2,
      "z": 5,
      "name": "Soil_Ash"
    },
    {
      "x": -27,
      "y": 16,
      "z": 5,
      "name": "Ore_Adamantite_Magma_Cracked"
    },
    {
      "x": -27,
      "y": 17,
      "z": 5,
      "name": "Rock_Magma_Cooled"
    },
    {
      "x": -27,
      "y": 18,
      "z": 5,
      "name": "Ore_Adamantite_Magma_Cracked"
    },
    {
      "x": -27,
      "y": 20,
      "z": 5,
      "name": "Ore_Adamantite_Magma_Cracked"
    },
    {
      "x": -27,
      "y": 21,
      "z": 5,
      "name": "Rock_Magma_Cooled"
    },
    {
      "x": -27,
      "y": 0,
      "z": 6,
      "name": "Soil_Ash"
    },
    {
      "x": -27,
      "y": 1,
      "z": 6,
      "name": "Soil_Ash"
    },
    {
      "x": -27,
      "y": 2,
      "z": 6,
      "name": "Soil_Ash"
    },
    {
      "x": -27,
      "y": 16,
      "z": 6,
      "name": "Rock_Magma_Cooled"
    },
    {
      "x": -27,
      "y": 17,
      "z": 6,
      "name": "Rock_Magma_Cooled"
    },
    {
      "x": -27,
      "y": 18,
      "z": 6,
      "name": "Rock_Magma_Cooled"
    },
    {
      "x": -27,
      "y": 21,
      "z": 6,
      "name": "Rock_Magma_Cooled"
    },
    {
      "x": -27,
      "y": 0,
      "z": 7,
      "name": "Soil_Ash"
    },
    {
      "x": -27,
      "y": 1,
      "z": 7,
      "name": "Soil_Ash"
    },
    {
      "x": -27,
      "y": 2,
      "z": 7,
      "name": "Soil_Ash"
    },
    {
      "x": -27,
      "y": 17,
      "z": 7,
      "name": "Ore_Adamantite_Magma_Cracked"
    },
    {
      "x": -27,
      "y": 0,
      "z": 8,
      "name": "Soil_Ash"
    },
    {
      "x": -27,
      "y": 1,
      "z": 8,
      "name": "Soil_Ash"
    },
    {
      "x": -27,
      "y": 2,
      "z": 8,
      "name": "Soil_Ash"
    },
    {
      "x": -27,
      "y": 0,
      "z": 9,
      "name": "Soil_Ash"
    },
    {
      "x": -27,
      "y": 1,
      "z": 9,
      "name": "Soil_Ash"
    },
    {
      "x": -27,
      "y": 0,
      "z": 10,
      "name": "Soil_Ash"
    },
    {
      "x": -27,
      "y": 1,
      "z": 10,
      "name": "Soil_Sand_Ashen"
    },
    {
      "x": -27,
      "y": 36,
      "z": 15,
      "name": "Plant_Vine_Wall_Poisoned",
      "support": 15,
      "rotation": 2
    },
    {
      "x": -27,
      "y": 37,
      "z": 15,
      "name": "Plant_Vine_Wall_Poisoned",
      "support": 15,
      "rotation": 2
    },
    {
      "x": -27,
      "y": 35,
      "z": 16,
      "name": "Rock_Magma_Cooled",
      "rotation": 1
    },
    {
      "x": -27,
      "y": 36,
      "z": 16,
      "name": "Rock_Magma_Cooled",
      "rotation": 1
    },
    {
      "x": -27,
      "y": 37,
      "z": 16,
      "name": "Rock_Magma_Cooled",
      "rotation": 1
    },
    {
      "x": -27,
      "y": 33,
      "z": 17,
      "name": "Rock_Magma_Cooled",
      "rotation": 1
    },
    {
      "x": -27,
      "y": 34,
      "z": 17,
      "name": "Rock_Magma_Cooled",
      "rotation": 1
    },
    {
      "x": -27,
      "y": 35,
      "z": 17,
      "name": "Rock_Magma_Cooled",
      "rotation": 1
    },
    {
      "x": -27,
      "y": 36,
      "z": 17,
      "name": "Rock_Magma_Cooled",
      "rotation": 1
    },
    {
      "x": -27,
      "y": 33,
      "z": 18,
      "name": "Rock_Magma_Cooled",
      "rotation": 1
    },
    {
      "x": -27,
      "y": 34,
      "z": 18,
      "name": "Rock_Magma_Cooled",
      "rotation": 1
    },
    {
      "x": -27,
      "y": 35,
      "z": 18,
      "name": "Rock_Magma_Cooled",
      "rotation": 1
    },
    {
      "x": -27,
      "y": 36,
      "z": 18,
      "name": "Rock_Magma_Cooled",
      "rotation": 1
    },
    {
      "x": -27,
      "y": 37,
      "z": 18,
      "name": "Ore_Adamantite_Magma_Cracked"
    },
    {
      "x": -27,
      "y": 38,
      "z": 18,
      "name": "Plant_Moss_Rug_Pink",
      "support": 15
    },
    {
      "x": -27,
      "y": 33,
      "z": 19,
      "name": "Rock_Magma_Cooled",
      "rotation": 1
    },
    {
      "x": -27,
      "y": 34,
      "z": 19,
      "name": "Rock_Magma_Cooled",
      "rotation": 1
    },
    {
      "x": -27,
      "y": 35,
      "z": 19,
      "name": "Ore_Adamantite_Magma_Cracked",
      "rotation": 1
    },
    {
      "x": -27,
      "y": 37,
      "z": 19,
      "name": "Ore_Adamantite_Magma_Cracked"
    },
    {
      "x": -27,
      "y": 38,
      "z": 19,
      "name": "Plant_Moss_Rug_Pink",
      "support": 15
    },
    {
      "x": -27,
      "y": 33,
      "z": 20,
      "name": "Rock_Magma_Cooled",
      "rotation": 1
    },
    {
      "x": -27,
      "y": 34,
      "z": 20,
      "name": "Rock_Magma_Cooled",
      "rotation": 1
    },
    {
      "x": -26,
      "y": 0,
      "z": -9,
      "name": "Soil_Sand_Ashen"
    },
    {
      "x": -26,
      "y": 1,
      "z": -9,
      "name": "Soil_Sand_Ashen"
    },
    {
      "x": -26,
      "y": 2,
      "z": -9,
      "name": "Soil_Sand_Ashen"
    },
    {
      "x": -26,
      "y": 0,
      "z": -8,
      "name": "Soil_Sand_Ashen"
    },
    {
      "x": -26,
      "y": 1,
      "z": -8,
      "name": "Soil_Sand_Ashen"
    },
    {
      "x": -26,
      "y": 2,
      "z": -8,
      "name": "Soil_Sand_Ashen"
    },
    {
      "x": -26,
      "y": 0,
      "z": -7,
      "name": "Soil_Sand_Ashen"
    },
    {
      "x": -26,
      "y": 1,
      "z": -7,
      "name": "Soil_Sand_Ashen"
    },
    {
      "x": -26,
      "y": 2,
      "z": -7,
      "name": "Soil_Sand_Ashen"
    },
    {
      "x": -26,
      "y": 3,
      "z": -7,
      "name": "Soil_Sand_Ashen"
    },
    {
      "x": -26,
      "y": 0,
      "z": -6,
      "name": "Soil_Ash"
    },
    {
      "x": -26,
      "y": 1,
      "z": -6,
      "name": "Soil_Sand_Ashen"
    },
    {
      "x": -26,
      "y": 2,
      "z": -6,
      "name": "Soil_Sand_Ashen"
    },
    {
      "x": -26,
      "y": 0,
      "z": -5,
      "name": "Soil_Ash"
    },
    {
      "x": -26,
      "y": 1,
      "z": -5,
      "name": "Soil_Ash"
    },
    {
      "x": -26,
      "y": 2,
      "z": -5,
      "name": "Soil_Ash"
    },
    {
      "x": -26,
      "y": 0,
      "z": -4,
      "name": "Soil_Ash"
    },
    {
      "x": -26,
      "y": 1,
      "z": -4,
      "name": "Soil_Ash"
    },
    {
      "x": -26,
      "y": 2,
      "z": -4,
      "name": "Soil_Ash"
    },
    {
      "x": -26,
      "y": 0,
      "z": -3,
      "name": "Soil_Ash"
    },
    {
      "x": -26,
      "y": 1,
      "z": -3,
      "name": "Soil_Ash"
    },
    {
      "x": -26,
      "y": 2,
      "z": -3,
      "name": "Soil_Ash"
    },
    {
      "x": -26,
      "y": 0,
      "z": -2,
      "name": "Soil_Ash"
    },
    {
      "x": -26,
      "y": 1,
      "z": -2,
      "name": "Soil_Ash"
    },
    {
      "x": -26,
      "y": 2,
      "z": -2,
      "name": "Soil_Ash"
    },
    {
      "x": -26,
      "y": 0,
      "z": -1,
      "name": "Soil_Ash"
    },
    {
      "x": -26,
      "y": 1,
      "z": -1,
      "name": "Soil_Ash"
    },
    {
      "x": -26,
      "y": 2,
      "z": -1,
      "name": "Soil_Ash"
    },
    {
      "x": -26,
      "y": 3,
      "z": -1,
      "name": "Soil_Ash"
    },
    {
      "x": -26,
      "y": 0,
      "z": 0,
      "name": "Soil_Ash"
    },
    {
      "x": -26,
      "y": 1,
      "z": 0,
      "name": "Soil_Ash"
    },
    {
      "x": -26,
      "y": 2,
      "z": 0,
      "name": "Soil_Ash"
    },
    {
      "x": -26,
      "y": 3,
      "z": 0,
      "name": "Soil_Ash"
    },
    {
      "x": -26,
      "y": 17,
      "z": 0,
      "name": "Plant_Vine_Wall_Poisoned",
      "support": 15,
      "rotation": 2
    },
    {
      "x": -26,
      "y": 0,
      "z": 1,
      "name": "Soil_Ash"
    },
    {
      "x": -26,
      "y": 1,
      "z": 1,
      "name": "Soil_Ash"
    },
    {
      "x": -26,
      "y": 2,
      "z": 1,
      "name": "Soil_Ash"
    },
    {
      "x": -26,
      "y": 3,
      "z": 1,
      "name": "Soil_Ash"
    },
    {
      "x": -26,
      "y": 17,
      "z": 1,
      "name": "Ore_Adamantite_Magma_Cracked"
    },
    {
      "x": -26,
      "y": 0,
      "z": 2,
      "name": "Soil_Ash"
    },
    {
      "x": -26,
      "y": 1,
      "z": 2,
      "name": "Soil_Ash"
    },
    {
      "x": -26,
      "y": 2,
      "z": 2,
      "name": "Soil_Ash"
    },
    {
      "x": -26,
      "y": 3,
      "z": 2,
      "name": "Soil_Ash"
    },
    {
      "x": -26,
      "y": 17,
      "z": 2,
      "name": "Ore_Adamantite_Magma_Cracked"
    },
    {
      "x": -26,
      "y": 18,
      "z": 2,
      "name": "Rock_Magma_Cooled"
    },
    {
      "x": -26,
      "y": 19,
      "z": 2,
      "name": "Ore_Adamantite_Magma_Cracked"
    },
    {
      "x": -26,
      "y": 20,
      "z": 2,
      "name": "Ore_Adamantite_Magma_Cracked"
    },
    {
      "x": -26,
      "y": 0,
      "z": 3,
      "name": "Soil_Ash"
    },
    {
      "x": -26,
      "y": 1,
      "z": 3,
      "name": "Soil_Ash"
    },
    {
      "x": -26,
      "y": 2,
      "z": 3,
      "name": "Soil_Ash"
    },
    {
      "x": -26,
      "y": 3,
      "z": 3,
      "name": "Soil_Ash"
    },
    {
      "x": -26,
      "y": 16,
      "z": 3,
      "name": "Rock_Magma_Cooled"
    },
    {
      "x": -26,
      "y": 17,
      "z": 3,
      "name": "Rock_Magma_Cooled"
    },
    {
      "x": -26,
      "y": 18,
      "z": 3,
      "name": "Rock_Magma_Cooled"
    },
    {
      "x": -26,
      "y": 19,
      "z": 3,
      "name": "Rock_Magma_Cooled"
    },
    {
      "x": -26,
      "y": 20,
      "z": 3,
      "name": "Rock_Magma_Cooled"
    },
    {
      "x": -26,
      "y": 0,
      "z": 4,
      "name": "Soil_Ash"
    },
    {
      "x": -26,
      "y": 1,
      "z": 4,
      "name": "Soil_Ash"
    },
    {
      "x": -26,
      "y": 2,
      "z": 4,
      "name": "Soil_Ash"
    },
    {
      "x": -26,
      "y": 3,
      "z": 4,
      "name": "Soil_Ash"
    },
    {
      "x": -26,
      "y": 16,
      "z": 4,
      "name": "Ore_Adamantite_Magma_Cracked"
    },
    {
      "x": -26,
      "y": 17,
      "z": 4,
      "name": "Rock_Magma_Cooled"
    },
    {
      "x": -26,
      "y": 18,
      "z": 4,
      "name": "Ore_Adamantite_Magma_Cracked"
    },
    {
      "x": -26,
      "y": 20,
      "z": 4,
      "name": "Rock_Magma_Cooled"
    },
    {
      "x": -26,
      "y": 0,
      "z": 5,
      "name": "Soil_Ash"
    },
    {
      "x": -26,
      "y": 1,
      "z": 5,
      "name": "Soil_Ash"
    },
    {
      "x": -26,
      "y": 2,
      "z": 5,
      "name": "Soil_Ash"
    },
    {
      "x": -26,
      "y": 3,
      "z": 5,
      "name": "Soil_Ash"
    },
    {
      "x": -26,
      "y": 4,
      "z": 5,
      "name": "Plant_Crop_Mushroom_Glowing_Violet"
    },
    {
      "x": -26,
      "y": 16,
      "z": 5,
      "name": "Rock_Magma_Cooled"
    },
    {
      "x": -26,
      "y": 17,
      "z": 5,
      "name": "Ore_Adamantite_Magma_Cracked"
    },
    {
      "x": -26,
      "y": 18,
      "z": 5,
      "name": "Rock_Magma_Cooled"
    },
    {
      "x": -26,
      "y": 0,
      "z": 6,
      "name": "Soil_Ash"
    },
    {
      "x": -26,
      "y": 1,
      "z": 6,
      "name": "Soil_Ash"
    },
    {
      "x": -26,
      "y": 2,
      "z": 6,
      "name": "Soil_Ash"
    },
    {
      "x": -26,
      "y": 3,
      "z": 6,
      "name": "Soil_Ash"
    },
    {
      "x": -26,
      "y": 16,
      "z": 6,
      "name": "Ore_Adamantite_Magma_Cracked"
    },
    {
      "x": -26,
      "y": 17,
      "z": 6,
      "name": "Ore_Adamantite_Magma_Cracked"
    },
    {
      "x": -26,
      "y": 18,
      "z": 6,
      "name": "Ore_Adamantite_Magma_Cracked"
    },
    {
      "x": -26,
      "y": 0,
      "z": 7,
      "name": "Soil_Ash"
    },
    {
      "x": -26,
      "y": 1,
      "z": 7,
      "name": "Soil_Ash"
    },
    {
      "x": -26,
      "y": 2,
      "z": 7,
      "name": "Soil_Ash"
    },
    {
      "x": -26,
      "y": 3,
      "z": 7,
      "name": "Soil_Ash"
    },
    {
      "x": -26,
      "y": 16,
      "z": 7,
      "name": "Ore_Adamantite_Magma_Cracked"
    },
    {
      "x": -26,
      "y": 17,
      "z": 7,
      "name": "Ore_Adamantite_Magma_Cracked"
    },
    {
      "x": -26,
      "y": 18,
      "z": 7,
      "name": "Rock_Magma_Cooled"
    },
    {
      "x": -26,
      "y": 0,
      "z": 8,
      "name": "Soil_Ash"
    },
    {
      "x": -26,
      "y": 1,
      "z": 8,
      "name": "Soil_Ash"
    },
    {
      "x": -26,
      "y": 2,
      "z": 8,
      "name": "Soil_Ash"
    },
    {
      "x": -26,
      "y": 3,
      "z": 8,
      "name": "Soil_Ash"
    },
    {
      "x": -26,
      "y": 17,
      "z": 8,
      "name": "Rock_Magma_Cooled"
    },
    {
      "x": -26,
      "y": 0,
      "z": 9,
      "name": "Soil_Ash"
    },
    {
      "x": -26,
      "y": 1,
      "z": 9,
      "name": "Soil_Ash"
    },
    {
      "x": -26,
      "y": 2,
      "z": 9,
      "name": "Soil_Ash"
    },
    {
      "x": -26,
      "y": 0,
      "z": 10,
      "name": "Soil_Ash"
    },
    {
      "x": -26,
      "y": 1,
      "z": 10,
      "name": "Soil_Ash"
    },
    {
      "x": -26,
      "y": 1,
      "z": 11,
      "name": "Soil_Ash"
    },
    {
      "x": -26,
      "y": 35,
      "z": 16,
      "name": "Plant_Vine_Wall_Poisoned",
      "support": 15,
      "rotation": 2
    },
    {
      "x": -26,
      "y": 34,
      "z": 17,
      "name": "Rock_Magma_Cooled",
      "rotation": 1
    },
    {
      "x": -26,
      "y": 35,
      "z": 17,
      "name": "Rock_Magma_Cooled",
      "rotation": 1
    },
    {
      "x": -26,
      "y": 36,
      "z": 17,
      "name": "Rock_Magma_Cooled",
      "rotation": 1
    },
    {
      "x": -26,
      "y": 37,
      "z": 17,
      "name": "Ore_Adamantite_Magma_Cracked"
    },
    {
      "x": -26,
      "y": 33,
      "z": 18,
      "name": "Rock_Magma_Cooled",
      "rotation": 1
    },
    {
      "x": -26,
      "y": 34,
      "z": 18,
      "name": "Rock_Magma_Cooled",
      "rotation": 1
    },
    {
      "x": -26,
      "y": 35,
      "z": 18,
      "name": "Ore_Adamantite_Magma_Cracked"
    },
    {
      "x": -26,
      "y": 36,
      "z": 18,
      "name": "Ore_Adamantite_Magma_Cracked"
    },
    {
      "x": -26,
      "y": 37,
      "z": 18,
      "name": "Rock_Magma_Cooled"
    },
    {
      "x": -26,
      "y": 38,
      "z": 18,
      "name": "Rock_Magma_Cooled"
    },
    {
      "x": -26,
      "y": 39,
      "z": 18,
      "name": "Plant_Moss_Rug_Pink",
      "support": 15
    },
    {
      "x": -26,
      "y": 33,
      "z": 19,
      "name": "Rock_Magma_Cooled",
      "rotation": 1
    },
    {
      "x": -26,
      "y": 34,
      "z": 19,
      "name": "Rock_Magma_Cooled",
      "rotation": 1
    },
    {
      "x": -26,
      "y": 35,
      "z": 19,
      "name": "Rock_Magma_Cooled"
    },
    {
      "x": -26,
      "y": 36,
      "z": 19,
      "name": "Rock_Magma_Cooled"
    },
    {
      "x": -26,
      "y": 37,
      "z": 19,
      "name": "Rock_Magma_Cooled"
    },
    {
      "x": -26,
      "y": 38,
      "z": 19,
      "name": "Rock_Magma_Cooled"
    },
    {
      "x": -26,
      "y": 39,
      "z": 19,
      "name": "Plant_Moss_Rug_Pink",
      "support": 15
    },
    {
      "x": -26,
      "y": 33,
      "z": 20,
      "name": "Rock_Magma_Cooled",
      "rotation": 1
    },
    {
      "x": -26,
      "y": 34,
      "z": 20,
      "name": "Rock_Magma_Cooled",
      "rotation": 1
    },
    {
      "x": -26,
      "y": 35,
      "z": 20,
      "name": "Ore_Adamantite_Magma_Cracked"
    },
    {
      "x": -26,
      "y": 36,
      "z": 20,
      "name": "Rock_Magma_Cooled"
    },
    {
      "x": -26,
      "y": 37,
      "z": 20,
      "name": "Rock_Magma_Cooled"
    },
    {
      "x": -25,
      "y": 0,
      "z": -10,
      "name": "Soil_Sand_Ashen"
    },
    {
      "x": -25,
      "y": 1,
      "z": -10,
      "name": "Soil_Sand_Ashen"
    },
    {
      "x": -25,
      "y": 2,
      "z": -10,
      "name": "Soil_Sand_Ashen"
    },
    {
      "x": -25,
      "y": 3,
      "z": -10,
      "name": "Soil_Sand_Ashen"
    },
    {
      "x": -25,
      "y": 0,
      "z": -9,
      "name": "Soil_Ash"
    },
    {
      "x": -25,
      "y": 1,
      "z": -9,
      "name": "Soil_Sand_Ashen"
    },
    {
      "x": -25,
      "y": 2,
      "z": -9,
      "name": "Soil_Sand_Ashen"
    },
    {
      "x": -25,
      "y": 3,
      "z": -9,
      "name": "Soil_Sand_Ashen"
    },
    {
      "x": -25,
      "y": 0,
      "z": -8,
      "name": "Soil_Ash"
    },
    {
      "x": -25,
      "y": 1,
      "z": -8,
      "name": "Soil_Sand_Ashen"
    },
    {
      "x": -25,
      "y": 2,
      "z": -8,
      "name": "Soil_Sand_Ashen"
    },
    {
      "x": -25,
      "y": 3,
      "z": -8,
      "name": "Soil_Sand_Ashen"
    },
    {
      "x": -25,
      "y": 0,
      "z": -7,
      "name": "Soil_Sand_Ashen"
    },
    {
      "x": -25,
      "y": 1,
      "z": -7,
      "name": "Soil_Sand_Ashen"
    },
    {
      "x": -25,
      "y": 2,
      "z": -7,
      "name": "Soil_Sand_Ashen"
    },
    {
      "x": -25,
      "y": 3,
      "z": -7,
      "name": "Soil_Sand_Ashen"
    },
    {
      "x": -25,
      "y": 0,
      "z": -6,
      "name": "Soil_Ash"
    },
    {
      "x": -25,
      "y": 1,
      "z": -6,
      "name": "Soil_Sand_Ashen"
    },
    {
      "x": -25,
      "y": 2,
      "z": -6,
      "name": "Soil_Sand_Ashen"
    },
    {
      "x": -25,
      "y": 3,
      "z": -6,
      "name": "Soil_Sand_Ashen"
    },
    {
      "x": -25,
      "y": 0,
      "z": -5,
      "name": "Soil_Ash"
    },
    {
      "x": -25,
      "y": 1,
      "z": -5,
      "name": "Soil_Ash"
    },
    {
      "x": -25,
      "y": 2,
      "z": -5,
      "name": "Soil_Ash"
    },
    {
      "x": -25,
      "y": 3,
      "z": -5,
      "name": "Soil_Sand_Ashen"
    },
    {
      "x": -25,
      "y": 0,
      "z": -4,
      "name": "Soil_Ash"
    },
    {
      "x": -25,
      "y": 1,
      "z": -4,
      "name": "Soil_Ash"
    },
    {
      "x": -25,
      "y": 2,
      "z": -4,
      "name": "Soil_Ash"
    },
    {
      "x": -25,
      "y": 3,
      "z": -4,
      "name": "Soil_Ash"
    },
    {
      "x": -25,
      "y": 0,
      "z": -3,
      "name": "Soil_Ash"
    },
    {
      "x": -25,
      "y": 1,
      "z": -3,
      "name": "Soil_Ash"
    },
    {
      "x": -25,
      "y": 2,
      "z": -3,
      "name": "Soil_Ash"
    },
    {
      "x": -25,
      "y": 3,
      "z": -3,
      "name": "Soil_Ash"
    },
    {
      "x": -25,
      "y": 0,
      "z": -2,
      "name": "Soil_Ash"
    },
    {
      "x": -25,
      "y": 1,
      "z": -2,
      "name": "Soil_Ash"
    },
    {
      "x": -25,
      "y": 2,
      "z": -2,
      "name": "Soil_Ash"
    },
    {
      "x": -25,
      "y": 3,
      "z": -2,
      "name": "Soil_Ash"
    },
    {
      "x": -25,
      "y": 0,
      "z": -1,
      "name": "Soil_Ash"
    },
    {
      "x": -25,
      "y": 1,
      "z": -1,
      "name": "Soil_Ash"
    },
    {
      "x": -25,
      "y": 2,
      "z": -1,
      "name": "Soil_Ash"
    },
    {
      "x": -25,
      "y": 3,
      "z": -1,
      "name": "Soil_Ash"
    },
    {
      "x": -25,
      "y": 4,
      "z": -1,
      "name": "Soil_Ash"
    },
    {
      "x": -25,
      "y": 0,
      "z": 0,
      "name": "Soil_Ash"
    },
    {
      "x": -25,
      "y": 1,
      "z": 0,
      "name": "Soil_Ash"
    },
    {
      "x": -25,
      "y": 2,
      "z": 0,
      "name": "Soil_Ash"
    },
    {
      "x": -25,
      "y": 3,
      "z": 0,
      "name": "Soil_Ash"
    },
    {
      "x": -25,
      "y": 4,
      "z": 0,
      "name": "Soil_Ash"
    },
    {
      "x": -25,
      "y": 5,
      "z": 0,
      "name": "Plant_Flower_Bushy_Poisoned"
    },
    {
      "x": -25,
      "y": 0,
      "z": 1,
      "name": "Soil_Ash"
    },
    {
      "x": -25,
      "y": 1,
      "z": 1,
      "name": "Soil_Ash"
    },
    {
      "x": -25,
      "y": 2,
      "z": 1,
      "name": "Soil_Ash"
    },
    {
      "x": -25,
      "y": 3,
      "z": 1,
      "name": "Soil_Ash"
    },
    {
      "x": -25,
      "y": 4,
      "z": 1,
      "name": "Soil_Ash"
    },
    {
      "x": -25,
      "y": 13,
      "z": 1,
      "name": "Ore_Adamantite_Magma_Cracked"
    },
    {
      "x": -25,
      "y": 17,
      "z": 1,
      "name": "Rock_Magma_Cooled"
    },
    {
      "x": -25,
      "y": 18,
      "z": 1,
      "name": "Rock_Magma_Cooled"
    },
    {
      "x": -25,
      "y": 0,
      "z": 2,
      "name": "Soil_Ash"
    },
    {
      "x": -25,
      "y": 1,
      "z": 2,
      "name": "Soil_Ash"
    },
    {
      "x": -25,
      "y": 2,
      "z": 2,
      "name": "Soil_Ash"
    },
    {
      "x": -25,
      "y": 3,
      "z": 2,
      "name": "Soil_Ash"
    },
    {
      "x": -25,
      "y": 4,
      "z": 2,
      "name": "Soil_Ash"
    },
    {
      "x": -25,
      "y": 12,
      "z": 2,
      "name": "Rock_Magma_Cooled"
    },
    {
      "x": -25,
      "y": 13,
      "z": 2,
      "name": "Ore_Adamantite_Magma_Cracked"
    },
    {
      "x": -25,
      "y": 14,
      "z": 2,
      "name": "Rock_Magma_Cooled"
    },
    {
      "x": -25,
      "y": 16,
      "z": 2,
      "name": "Rock_Magma_Cooled"
    },
    {
      "x": -25,
      "y": 17,
      "z": 2,
      "name": "Ore_Adamantite_Magma_Cracked"
    },
    {
      "x": -25,
      "y": 18,
      "z": 2,
      "name": "Rock_Magma_Cooled"
    },
    {
      "x": -25,
      "y": 19,
      "z": 2,
      "name": "Rock_Magma_Cooled"
    },
    {
      "x": -25,
      "y": 0,
      "z": 3,
      "name": "Soil_Ash"
    },
    {
      "x": -25,
      "y": 1,
      "z": 3,
      "name": "Soil_Ash"
    },
    {
      "x": -25,
      "y": 2,
      "z": 3,
      "name": "Soil_Ash"
    },
    {
      "x": -25,
      "y": 3,
      "z": 3,
      "name": "Soil_Ash"
    },
    {
      "x": -25,
      "y": 4,
      "z": 3,
      "name": "Soil_Ash"
    },
    {
      "x": -25,
      "y": 5,
      "z": 3,
      "name": "Plant_Crop_Mushroom_Glowing_Violet"
    },
    {
      "x": -25,
      "y": 12,
      "z": 3,
      "name": "Ore_Adamantite_Magma_Cracked"
    },
    {
      "x": -25,
      "y": 13,
      "z": 3,
      "name": "Ore_Adamantite_Magma_Cracked"
    },
    {
      "x": -25,
      "y": 14,
      "z": 3,
      "name": "Ore_Adamantite_Magma_Cracked"
    },
    {
      "x": -25,
      "y": 16,
      "z": 3,
      "name": "Rock_Magma_Cooled"
    },
    {
      "x": -25,
      "y": 17,
      "z": 3,
      "name": "Rock_Magma_Cooled"
    },
    {
      "x": -25,
      "y": 18,
      "z": 3,
      "name": "Ore_Adamantite_Magma_Cracked"
    },
    {
      "x": -25,
      "y": 19,
      "z": 3,
      "name": "Rock_Magma_Cooled"
    },
    {
      "x": -25,
      "y": 0,
      "z": 4,
      "name": "Soil_Ash"
    },
    {
      "x": -25,
      "y": 1,
      "z": 4,
      "name": "Soil_Ash"
    },
    {
      "x": -25,
      "y": 2,
      "z": 4,
      "name": "Soil_Ash"
    },
    {
      "x": -25,
      "y": 3,
      "z": 4,
      "name": "Soil_Ash"
    },
    {
      "x": -25,
      "y": 4,
      "z": 4,
      "name": "Soil_Ash"
    },
    {
      "x": -25,
      "y": 12,
      "z": 4,
      "name": "Ore_Adamantite_Magma_Cracked"
    },
    {
      "x": -25,
      "y": 13,
      "z": 4,
      "name": "Ore_Adamantite_Magma_Cracked"
    },
    {
      "x": -25,
      "y": 14,
      "z": 4,
      "name": "Ore_Adamantite_Magma_Cracked"
    },
    {
      "x": -25,
      "y": 16,
      "z": 4,
      "name": "Rock_Magma_Cooled"
    },
    {
      "x": -25,
      "y": 17,
      "z": 4,
      "name": "Rock_Magma_Cooled"
    },
    {
      "x": -25,
      "y": 18,
      "z": 4,
      "name": "Rock_Magma_Cooled"
    },
    {
      "x": -25,
      "y": 19,
      "z": 4,
      "name": "Rock_Magma_Cooled"
    },
    {
      "x": -25,
      "y": 0,
      "z": 5,
      "name": "Soil_Ash"
    },
    {
      "x": -25,
      "y": 1,
      "z": 5,
      "name": "Soil_Ash"
    },
    {
      "x": -25,
      "y": 2,
      "z": 5,
      "name": "Soil_Ash"
    },
    {
      "x": -25,
      "y": 3,
      "z": 5,
      "name": "Soil_Ash"
    },
    {
      "x": -25,
      "y": 4,
      "z": 5,
      "name": "Soil_Ash"
    },
    {
      "x": -25,
      "y": 13,
      "z": 5,
      "name": "Ore_Adamantite_Magma_Cracked"
    },
    {
      "x": -25,
      "y": 16,
      "z": 5,
      "name": "Ore_Adamantite_Magma_Cracked"
    },
    {
      "x": -25,
      "y": 17,
      "z": 5,
      "name": "Ore_Adamantite_Magma_Cracked"
    },
    {
      "x": -25,
      "y": 18,
      "z": 5,
      "name": "Rock_Magma_Cooled"
    },
    {
      "x": -25,
      "y": 0,
      "z": 6,
      "name": "Soil_Ash"
    },
    {
      "x": -25,
      "y": 1,
      "z": 6,
      "name": "Soil_Ash"
    },
    {
      "x": -25,
      "y": 2,
      "z": 6,
      "name": "Soil_Ash"
    },
    {
      "x": -25,
      "y": 3,
      "z": 6,
      "name": "Soil_Ash"
    },
    {
      "x": -25,
      "y": 4,
      "z": 6,
      "name": "Soil_Ash"
    },
    {
      "x": -25,
      "y": 5,
      "z": 6,
      "name": "Plant_Flower_Bushy_Poisoned"
    },
    {
      "x": -25,
      "y": 16,
      "z": 6,
      "name": "Ore_Adamantite_Magma_Cracked"
    },
    {
      "x": -25,
      "y": 17,
      "z": 6,
      "name": "Ore_Adamantite_Magma_Cracked"
    },
    {
      "x": -25,
      "y": 18,
      "z": 6,
      "name": "Ore_Adamantite_Magma_Cracked"
    },
    {
      "x": -25,
      "y": 0,
      "z": 7,
      "name": "Soil_Ash"
    },
    {
      "x": -25,
      "y": 1,
      "z": 7,
      "name": "Soil_Ash"
    },
    {
      "x": -25,
      "y": 2,
      "z": 7,
      "name": "Soil_Ash"
    },
    {
      "x": -25,
      "y": 3,
      "z": 7,
      "name": "Soil_Ash"
    },
    {
      "x": -25,
      "y": 4,
      "z": 7,
      "name": "Soil_Ash"
    },
    {
      "x": -25,
      "y": 16,
      "z": 7,
      "name": "Ore_Adamantite_Magma_Cracked"
    },
    {
      "x": -25,
      "y": 17,
      "z": 7,
      "name": "Rock_Magma_Cooled"
    },
    {
      "x": -25,
      "y": 0,
      "z": 8,
      "name": "Soil_Ash"
    },
    {
      "x": -25,
      "y": 1,
      "z": 8,
      "name": "Soil_Ash"
    },
    {
      "x": -25,
      "y": 2,
      "z": 8,
      "name": "Soil_Ash"
    },
    {
      "x": -25,
      "y": 3,
      "z": 8,
      "name": "Soil_Ash"
    },
    {
      "x": -25,
      "y": 4,
      "z": 8,
      "name": "Soil_Ash"
    },
    {
      "x": -25,
      "y": 0,
      "z": 9,
      "name": "Soil_Ash"
    },
    {
      "x": -25,
      "y": 1,
      "z": 9,
      "name": "Soil_Ash"
    },
    {
      "x": -25,
      "y": 2,
      "z": 9,
      "name": "Soil_Ash"
    },
    {
      "x": -25,
      "y": 3,
      "z": 9,
      "name": "Soil_Ash"
    },
    {
      "x": -25,
      "y": 0,
      "z": 10,
      "name": "Soil_Ash"
    },
    {
      "x": -25,
      "y": 1,
      "z": 10,
      "name": "Soil_Ash"
    },
    {
      "x": -25,
      "y": 2,
      "z": 10,
      "name": "Soil_Ash"
    },
    {
      "x": -25,
      "y": 3,
      "z": 10,
      "name": "Soil_Ash"
    },
    {
      "x": -25,
      "y": 0,
      "z": 11,
      "name": "Soil_Ash"
    },
    {
      "x": -25,
      "y": 1,
      "z": 11,
      "name": "Soil_Ash"
    },
    {
      "x": -25,
      "y": 1,
      "z": 12,
      "name": "Soil_Ash"
    },
    {
      "x": -25,
      "y": 33,
      "z": 17,
      "name": "Plant_Vine_Wall_Poisoned",
      "support": 15,
      "rotation": 2
    },
    {
      "x": -25,
      "y": 36,
      "z": 17,
      "name": "Rock_Magma_Cooled"
    },
    {
      "x": -25,
      "y": 33,
      "z": 18,
      "name": "Rock_Magma_Cooled",
      "rotation": 1
    },
    {
      "x": -25,
      "y": 34,
      "z": 18,
      "name": "Rock_Magma_Cooled",
      "rotation": 1
    },
    {
      "x": -25,
      "y": 35,
      "z": 18,
      "name": "Rock_Magma_Cooled"
    },
    {
      "x": -25,
      "y": 36,
      "z": 18,
      "name": "Ore_Adamantite_Magma_Cracked"
    },
    {
      "x": -25,
      "y": 37,
      "z": 18,
      "name": "Ore_Adamantite_Magma_Cracked"
    },
    {
      "x": -25,
      "y": 33,
      "z": 19,
      "name": "Rock_Magma_Cooled",
      "rotation": 1
    },
    {
      "x": -25,
      "y": 34,
      "z": 19,
      "name": "Rock_Magma_Cooled",
      "rotation": 1
    },
    {
      "x": -25,
      "y": 35,
      "z": 19,
      "name": "Ore_Adamantite_Magma_Cracked"
    },
    {
      "x": -25,
      "y": 36,
      "z": 19,
      "name": "Rock_Magma_Cooled"
    },
    {
      "x": -25,
      "y": 37,
      "z": 19,
      "name": "Ore_Adamantite_Magma_Cracked"
    },
    {
      "x": -25,
      "y": 33,
      "z": 20,
      "name": "Rock_Magma_Cooled",
      "rotation": 1
    },
    {
      "x": -25,
      "y": 34,
      "z": 20,
      "name": "Ore_Adamantite_Magma_Cracked"
    },
    {
      "x": -25,
      "y": 35,
      "z": 20,
      "name": "Ore_Adamantite_Magma_Cracked"
    },
    {
      "x": -25,
      "y": 36,
      "z": 20,
      "name": "Rock_Magma_Cooled"
    },
    {
      "x": -25,
      "y": 37,
      "z": 20,
      "name": "Rock_Magma_Cooled"
    },
    {
      "x": -25,
      "y": 38,
      "z": 20,
      "name": "Plant_Moss_Rug_Pink",
      "support": 15
    },
    {
      "x": -24,
      "y": 0,
      "z": -11,
      "name": "Soil_Sand_Ashen"
    },
    {
      "x": -24,
      "y": 1,
      "z": -11,
      "name": "Soil_Sand_Ashen"
    },
    {
      "x": -24,
      "y": 2,
      "z": -11,
      "name": "Soil_Sand_Ashen"
    },
    {
      "x": -24,
      "y": 0,
      "z": -10,
      "name": "Soil_Sand_Ashen"
    },
    {
      "x": -24,
      "y": 1,
      "z": -10,
      "name": "Soil_Sand_Ashen"
    },
    {
      "x": -24,
      "y": 2,
      "z": -10,
      "name": "Soil_Sand_Ashen"
    },
    {
      "x": -24,
      "y": 3,
      "z": -10,
      "name": "Soil_Sand_Ashen"
    },
    {
      "x": -24,
      "y": 0,
      "z": -9,
      "name": "Soil_Sand_Ashen"
    },
    {
      "x": -24,
      "y": 1,
      "z": -9,
      "name": "Soil_Sand_Ashen"
    },
    {
      "x": -24,
      "y": 2,
      "z": -9,
      "name": "Soil_Sand_Ashen"
    },
    {
      "x": -24,
      "y": 3,
      "z": -9,
      "name": "Soil_Sand_Ashen"
    },
    {
      "x": -24,
      "y": 0,
      "z": -8,
      "name": "Soil_Sand_Ashen"
    },
    {
      "x": -24,
      "y": 1,
      "z": -8,
      "name": "Soil_Sand_Ashen"
    },
    {
      "x": -24,
      "y": 2,
      "z": -8,
      "name": "Soil_Sand_Ashen"
    },
    {
      "x": -24,
      "y": 3,
      "z": -8,
      "name": "Soil_Sand_Ashen"
    },
    {
      "x": -24,
      "y": 4,
      "z": -8,
      "name": "Soil_Sand_Ashen"
    },
    {
      "x": -24,
      "y": 0,
      "z": -7,
      "name": "Soil_Sand_Ashen"
    },
    {
      "x": -24,
      "y": 1,
      "z": -7,
      "name": "Soil_Sand_Ashen"
    },
    {
      "x": -24,
      "y": 2,
      "z": -7,
      "name": "Soil_Sand_Ashen"
    },
    {
      "x": -24,
      "y": 3,
      "z": -7,
      "name": "Soil_Sand_Ashen"
    },
    {
      "x": -24,
      "y": 4,
      "z": -7,
      "name": "Soil_Sand_Ashen"
    },
    {
      "x": -24,
      "y": 5,
      "z": -7,
      "name": "Plant_Bramble_Dead_Twisted"
    },
    {
      "x": -24,
      "y": 0,
      "z": -6,
      "name": "Soil_Ash"
    },
    {
      "x": -24,
      "y": 1,
      "z": -6,
      "name": "Soil_Sand_Ashen"
    },
    {
      "x": -24,
      "y": 2,
      "z": -6,
      "name": "Soil_Sand_Ashen"
    },
    {
      "x": -24,
      "y": 3,
      "z": -6,
      "name": "Soil_Sand_Ashen"
    },
    {
      "x": -24,
      "y": 4,
      "z": -6,
      "name": "Soil_Ash"
    },
    {
      "x": -24,
      "y": 0,
      "z": -5,
      "name": "Soil_Ash"
    },
    {
      "x": -24,
      "y": 1,
      "z": -5,
      "name": "Soil_Ash"
    },
    {
      "x": -24,
      "y": 2,
      "z": -5,
      "name": "Soil_Ash"
    },
    {
      "x": -24,
      "y": 3,
      "z": -5,
      "name": "Soil_Sand_Ashen"
    },
    {
      "x": -24,
      "y": 4,
      "z": -5,
      "name": "Soil_Ash"
    },
    {
      "x": -24,
      "y": 0,
      "z": -4,
      "name": "Soil_Ash"
    },
    {
      "x": -24,
      "y": 1,
      "z": -4,
      "name": "Soil_Ash"
    },
    {
      "x": -24,
      "y": 2,
      "z": -4,
      "name": "Soil_Ash"
    },
    {
      "x": -24,
      "y": 3,
      "z": -4,
      "name": "Soil_Ash"
    },
    {
      "x": -24,
      "y": 0,
      "z": -3,
      "name": "Soil_Ash"
    },
    {
      "x": -24,
      "y": 1,
      "z": -3,
      "name": "Soil_Ash"
    },
    {
      "x": -24,
      "y": 2,
      "z": -3,
      "name": "Soil_Ash"
    },
    {
      "x": -24,
      "y": 3,
      "z": -3,
      "name": "Soil_Ash"
    },
    {
      "x": -24,
      "y": 4,
      "z": -3,
      "name": "Soil_Ash"
    },
    {
      "x": -24,
      "y": 0,
      "z": -2,
      "name": "Soil_Ash"
    },
    {
      "x": -24,
      "y": 1,
      "z": -2,
      "name": "Soil_Ash"
    },
    {
      "x": -24,
      "y": 2,
      "z": -2,
      "name": "Soil_Ash"
    },
    {
      "x": -24,
      "y": 3,
      "z": -2,
      "name": "Soil_Ash"
    },
    {
      "x": -24,
      "y": 4,
      "z": -2,
      "name": "Soil_Ash"
    },
    {
      "x": -24,
      "y": 0,
      "z": -1,
      "name": "Soil_Ash"
    },
    {
      "x": -24,
      "y": 1,
      "z": -1,
      "name": "Soil_Ash"
    },
    {
      "x": -24,
      "y": 2,
      "z": -1,
      "name": "Soil_Ash"
    },
    {
      "x": -24,
      "y": 3,
      "z": -1,
      "name": "Soil_Ash"
    },
    {
      "x": -24,
      "y": 4,
      "z": -1,
      "name": "Soil_Ash"
    },
    {
      "x": -24,
      "y": 5,
      "z": -1,
      "name": "Plant_Flower_Bushy_Poisoned"
    },
    {
      "x": -24,
      "y": 13,
      "z": -1,
      "name": "Ore_Adamantite_Magma_Cracked"
    },
    {
      "x": -24,
      "y": 0,
      "z": 0,
      "name": "Soil_Ash"
    },
    {
      "x": -24,
      "y": 1,
      "z": 0,
      "name": "Soil_Ash"
    },
    {
      "x": -24,
      "y": 2,
      "z": 0,
      "name": "Soil_Ash"
    },
    {
      "x": -24,
      "y": 3,
      "z": 0,
      "name": "Soil_Ash"
    },
    {
      "x": -24,
      "y": 4,
      "z": 0,
      "name": "Soil_Ash"
    },
    {
      "x": -24,
      "y": 5,
      "z": 0,
      "name": "Soil_Ash"
    },
    {
      "x": -24,
      "y": 12,
      "z": 0,
      "name": "Ore_Adamantite_Magma_Cracked"
    },
    {
      "x": -24,
      "y": 13,
      "z": 0,
      "name": "Ore_Adamantite_Magma_Cracked"
    },
    {
      "x": -24,
      "y": 14,
      "z": 0,
      "name": "Rock_Magma_Cooled"
    },
    {
      "x": -24,
      "y": 0,
      "z": 1,
      "name": "Soil_Ash"
    },
    {
      "x": -24,
      "y": 1,
      "z": 1,
      "name": "Soil_Ash"
    },
    {
      "x": -24,
      "y": 2,
      "z": 1,
      "name": "Soil_Ash"
    },
    {
      "x": -24,
      "y": 3,
      "z": 1,
      "name": "Soil_Ash"
    },
    {
      "x": -24,
      "y": 4,
      "z": 1,
      "name": "Soil_Ash"
    },
    {
      "x": -24,
      "y": 5,
      "z": 1,
      "name": "Soil_Ash"
    },
    {
      "x": -24,
      "y": 12,
      "z": 1,
      "name": "Rock_Magma_Cooled"
    },
    {
      "x": -24,
      "y": 13,
      "z": 1,
      "name": "Ore_Adamantite_Magma_Cracked"
    },
    {
      "x": -24,
      "y": 14,
      "z": 1,
      "name": "Rock_Magma_Cooled"
    },
    {
      "x": -24,
      "y": 16,
      "z": 1,
      "name": "Rock_Magma_Cooled"
    },
    {
      "x": -24,
      "y": 17,
      "z": 1,
      "name": "Rock_Magma_Cooled"
    },
    {
      "x": -24,
      "y": 18,
      "z": 1,
      "name": "Rock_Magma_Cooled"
    },
    {
      "x": -24,
      "y": 19,
      "z": 1,
      "name": "Ore_Adamantite_Magma_Cracked"
    },
    {
      "x": -24,
      "y": 0,
      "z": 2,
      "name": "Soil_Ash"
    },
    {
      "x": -24,
      "y": 1,
      "z": 2,
      "name": "Soil_Ash"
    },
    {
      "x": -24,
      "y": 2,
      "z": 2,
      "name": "Soil_Ash"
    },
    {
      "x": -24,
      "y": 3,
      "z": 2,
      "name": "Soil_Ash"
    },
    {
      "x": -24,
      "y": 4,
      "z": 2,
      "name": "Soil_Ash"
    },
    {
      "x": -24,
      "y": 5,
      "z": 2,
      "name": "Soil_Ash"
    },
    {
      "x": -24,
      "y": 11,
      "z": 2,
      "name": "Rock_Magma_Cooled"
    },
    {
      "x": -24,
      "y": 12,
      "z": 2,
      "name": "Ore_Adamantite_Magma_Cracked"
    },
    {
      "x": -24,
      "y": 13,
      "z": 2,
      "name": "Rock_Magma_Cooled"
    },
    {
      "x": -24,
      "y": 14,
      "z": 2,
      "name": "Rock_Magma_Cooled"
    },
    {
      "x": -24,
      "y": 15,
      "z": 2,
      "name": "Rock_Magma_Cooled"
    },
    {
      "x": -24,
      "y": 16,
      "z": 2,
      "name": "Rock_Magma_Cooled"
    },
    {
      "x": -24,
      "y": 17,
      "z": 2,
      "name": "Ore_Adamantite_Magma_Cracked"
    },
    {
      "x": -24,
      "y": 18,
      "z": 2,
      "name": "Rock_Magma_Cooled"
    },
    {
      "x": -24,
      "y": 19,
      "z": 2,
      "name": "Ore_Adamantite_Magma_Cracked"
    },
    {
      "x": -24,
      "y": 0,
      "z": 3,
      "name": "Soil_Ash"
    },
    {
      "x": -24,
      "y": 1,
      "z": 3,
      "name": "Soil_Ash"
    },
    {
      "x": -24,
      "y": 2,
      "z": 3,
      "name": "Soil_Ash"
    },
    {
      "x": -24,
      "y": 3,
      "z": 3,
      "name": "Soil_Ash"
    },
    {
      "x": -24,
      "y": 4,
      "z": 3,
      "name": "Soil_Ash"
    },
    {
      "x": -24,
      "y": 5,
      "z": 3,
      "name": "Soil_Ash"
    },
    {
      "x": -24,
      "y": 11,
      "z": 3,
      "name": "Rock_Magma_Cooled"
    },
    {
      "x": -24,
      "y": 12,
      "z": 3,
      "name": "Ore_Adamantite_Magma_Cracked"
    },
    {
      "x": -24,
      "y": 13,
      "z": 3,
      "name": "Ore_Adamantite_Magma_Cracked"
    },
    {
      "x": -24,
      "y": 14,
      "z": 3,
      "name": "Rock_Magma_Cooled"
    },
    {
      "x": -24,
      "y": 15,
      "z": 3,
      "name": "Ore_Adamantite_Magma_Cracked"
    },
    {
      "x": -24,
      "y": 16,
      "z": 3,
      "name": "Rock_Magma_Cooled"
    },
    {
      "x": -24,
      "y": 17,
      "z": 3,
      "name": "Ore_Adamantite_Magma_Cracked"
    },
    {
      "x": -24,
      "y": 18,
      "z": 3,
      "name": "Ore_Adamantite_Magma_Cracked"
    },
    {
      "x": -24,
      "y": 19,
      "z": 3,
      "name": "Rock_Magma_Cooled"
    },
    {
      "x": -24,
      "y": 0,
      "z": 4,
      "name": "Soil_Ash"
    },
    {
      "x": -24,
      "y": 1,
      "z": 4,
      "name": "Soil_Ash"
    },
    {
      "x": -24,
      "y": 2,
      "z": 4,
      "name": "Soil_Ash"
    },
    {
      "x": -24,
      "y": 3,
      "z": 4,
      "name": "Soil_Ash"
    },
    {
      "x": -24,
      "y": 4,
      "z": 4,
      "name": "Soil_Ash"
    },
    {
      "x": -24,
      "y": 5,
      "z": 4,
      "name": "Soil_Ash"
    },
    {
      "x": -24,
      "y": 11,
      "z": 4,
      "name": "Rock_Magma_Cooled"
    },
    {
      "x": -24,
      "y": 12,
      "z": 4,
      "name": "Ore_Adamantite_Magma_Cracked"
    },
    {
      "x": -24,
      "y": 13,
      "z": 4,
      "name": "Rock_Magma_Cooled"
    },
    {
      "x": -24,
      "y": 14,
      "z": 4,
      "name": "Ore_Adamantite_Magma_Cracked"
    },
    {
      "x": -24,
      "y": 15,
      "z": 4,
      "name": "Rock_Magma_Cooled"
    },
    {
      "x": -24,
      "y": 16,
      "z": 4,
      "name": "Rock_Magma_Cooled"
    },
    {
      "x": -24,
      "y": 17,
      "z": 4,
      "name": "Ore_Adamantite_Magma_Cracked"
    },
    {
      "x": -24,
      "y": 18,
      "z": 4,
      "name": "Rock_Magma_Cooled"
    },
    {
      "x": -24,
      "y": 19,
      "z": 4,
      "name": "Ore_Adamantite_Magma_Cracked"
    },
    {
      "x": -24,
      "y": 0,
      "z": 5,
      "name": "Soil_Ash"
    },
    {
      "x": -24,
      "y": 1,
      "z": 5,
      "name": "Soil_Ash"
    },
    {
      "x": -24,
      "y": 2,
      "z": 5,
      "name": "Soil_Ash"
    },
    {
      "x": -24,
      "y": 3,
      "z": 5,
      "name": "Soil_Ash"
    },
    {
      "x": -24,
      "y": 4,
      "z": 5,
      "name": "Soil_Ash"
    },
    {
      "x": -24,
      "y": 5,
      "z": 5,
      "name": "Soil_Ash"
    },
    {
      "x": -24,
      "y": 6,
      "z": 5,
      "name": "Plant_Crop_Mushroom_Glowing_Violet"
    },
    {
      "x": -24,
      "y": 12,
      "z": 5,
      "name": "Ore_Adamantite_Magma_Cracked"
    },
    {
      "x": -24,
      "y": 13,
      "z": 5,
      "name": "Rock_Magma_Cooled"
    },
    {
      "x": -24,
      "y": 14,
      "z": 5,
      "name": "Rock_Magma_Cooled"
    },
    {
      "x": -24,
      "y": 15,
      "z": 5,
      "name": "Ore_Adamantite_Magma_Cracked"
    },
    {
      "x": -24,
      "y": 16,
      "z": 5,
      "name": "Rock_Magma_Cooled"
    },
    {
      "x": -24,
      "y": 17,
      "z": 5,
      "name": "Ore_Adamantite_Magma_Cracked"
    },
    {
      "x": -24,
      "y": 18,
      "z": 5,
      "name": "Rock_Magma_Cooled"
    },
    {
      "x": -24,
      "y": 0,
      "z": 6,
      "name": "Soil_Ash"
    },
    {
      "x": -24,
      "y": 1,
      "z": 6,
      "name": "Soil_Ash"
    },
    {
      "x": -24,
      "y": 2,
      "z": 6,
      "name": "Soil_Ash"
    },
    {
      "x": -24,
      "y": 3,
      "z": 6,
      "name": "Soil_Ash"
    },
    {
      "x": -24,
      "y": 4,
      "z": 6,
      "name": "Soil_Ash"
    },
    {
      "x": -24,
      "y": 5,
      "z": 6,
      "name": "Soil_Ash"
    },
    {
      "x": -24,
      "y": 12,
      "z": 6,
      "name": "Rock_Magma_Cooled"
    },
    {
      "x": -24,
      "y": 13,
      "z": 6,
      "name": "Ore_Adamantite_Magma_Cracked"
    },
    {
      "x": -24,
      "y": 14,
      "z": 6,
      "name": "Rock_Magma_Cooled"
    },
    {
      "x": -24,
      "y": 15,
      "z": 6,
      "name": "Rock_Magma_Cooled"
    },
    {
      "x": -24,
      "y": 16,
      "z": 6,
      "name": "Rock_Magma_Cooled"
    },
    {
      "x": -24,
      "y": 17,
      "z": 6,
      "name": "Rock_Magma_Cooled"
    },
    {
      "x": -24,
      "y": 0,
      "z": 7,
      "name": "Soil_Ash"
    },
    {
      "x": -24,
      "y": 1,
      "z": 7,
      "name": "Soil_Ash"
    },
    {
      "x": -24,
      "y": 2,
      "z": 7,
      "name": "Soil_Ash"
    },
    {
      "x": -24,
      "y": 3,
      "z": 7,
      "name": "Soil_Ash"
    },
    {
      "x": -24,
      "y": 4,
      "z": 7,
      "name": "Soil_Ash"
    },
    {
      "x": -24,
      "y": 5,
      "z": 7,
      "name": "Soil_Ash"
    },
    {
      "x": -24,
      "y": 6,
      "z": 7,
      "name": "Plant_Flower_Bushy_Poisoned"
    },
    {
      "x": -24,
      "y": 13,
      "z": 7,
      "name": "Ore_Adamantite_Magma_Cracked"
    },
    {
      "x": -24,
      "y": 14,
      "z": 7,
      "name": "Rock_Magma_Cooled"
    },
    {
      "x": -24,
      "y": 15,
      "z": 7,
      "name": "Rock_Magma_Cooled"
    },
    {
      "x": -24,
      "y": 16,
      "z": 7,
      "name": "Ore_Adamantite_Magma_Cracked"
    },
    {
      "x": -24,
      "y": 17,
      "z": 7,
      "name": "Ore_Adamantite_Magma_Cracked"
    },
    {
      "x": -24,
      "y": 0,
      "z": 8,
      "name": "Soil_Ash"
    },
    {
      "x": -24,
      "y": 1,
      "z": 8,
      "name": "Soil_Ash"
    },
    {
      "x": -24,
      "y": 2,
      "z": 8,
      "name": "Soil_Ash"
    },
    {
      "x": -24,
      "y": 3,
      "z": 8,
      "name": "Soil_Ash"
    },
    {
      "x": -24,
      "y": 4,
      "z": 8,
      "name": "Soil_Ash"
    },
    {
      "x": -24,
      "y": 5,
      "z": 8,
      "name": "Soil_Ash"
    },
    {
      "x": -24,
      "y": 15,
      "z": 8,
      "name": "Rock_Magma_Cooled"
    },
    {
      "x": -24,
      "y": 16,
      "z": 8,
      "name": "Rock_Magma_Cooled"
    },
    {
      "x": -24,
      "y": 0,
      "z": 9,
      "name": "Soil_Ash"
    },
    {
      "x": -24,
      "y": 1,
      "z": 9,
      "name": "Soil_Ash"
    },
    {
      "x": -24,
      "y": 2,
      "z": 9,
      "name": "Soil_Ash"
    },
    {
      "x": -24,
      "y": 3,
      "z": 9,
      "name": "Soil_Ash"
    },
    {
      "x": -24,
      "y": 4,
      "z": 9,
      "name": "Soil_Ash"
    },
    {
      "x": -24,
      "y": 5,
      "z": 9,
      "name": "Plant_Flower_Bushy_Purple"
    },
    {
      "x": -24,
      "y": 0,
      "z": 10,
      "name": "Soil_Ash"
    },
    {
      "x": -24,
      "y": 1,
      "z": 10,
      "name": "Soil_Ash"
    },
    {
      "x": -24,
      "y": 2,
      "z": 10,
      "name": "Soil_Ash"
    },
    {
      "x": -24,
      "y": 3,
      "z": 10,
      "name": "Soil_Ash"
    },
    {
      "x": -24,
      "y": 4,
      "z": 10,
      "name": "Soil_Ash"
    },
    {
      "x": -24,
      "y": 0,
      "z": 11,
      "name": "Soil_Ash"
    },
    {
      "x": -24,
      "y": 1,
      "z": 11,
      "name": "Soil_Ash"
    },
    {
      "x": -24,
      "y": 2,
      "z": 11,
      "name": "Soil_Ash"
    },
    {
      "x": -24,
      "y": 3,
      "z": 11,
      "name": "Soil_Ash"
    },
    {
      "x": -24,
      "y": 0,
      "z": 12,
      "name": "Soil_Ash"
    },
    {
      "x": -24,
      "y": 1,
      "z": 12,
      "name": "Soil_Ash"
    },
    {
      "x": -24,
      "y": 2,
      "z": 12,
      "name": "Soil_Ash"
    },
    {
      "x": -24,
      "y": 1,
      "z": 13,
      "name": "Soil_Ash"
    },
    {
      "x": -24,
      "y": 34,
      "z": 17,
      "name": "Plant_Vine_Wall_Poisoned",
      "support": 15,
      "rotation": 2
    },
    {
      "x": -24,
      "y": 34,
      "z": 18,
      "name": "Ore_Adamantite_Magma_Cracked"
    },
    {
      "x": -24,
      "y": 35,
      "z": 18,
      "name": "Ore_Adamantite_Magma_Cracked"
    },
    {
      "x": -24,
      "y": 36,
      "z": 18,
      "name": "Rock_Magma_Cooled"
    },
    {
      "x": -24,
      "y": 34,
      "z": 19,
      "name": "Ore_Adamantite_Magma_Cracked"
    },
    {
      "x": -24,
      "y": 35,
      "z": 19,
      "name": "Ore_Adamantite_Magma_Cracked"
    },
    {
      "x": -24,
      "y": 36,
      "z": 19,
      "name": "Rock_Magma_Cooled"
    },
    {
      "x": -24,
      "y": 31,
      "z": 20,
      "name": "Rock_Magma_Cooled"
    },
    {
      "x": -24,
      "y": 33,
      "z": 20,
      "name": "Plant_Vine_Wall_Poisoned",
      "support": 15,
      "rotation": 3
    },
    {
      "x": -24,
      "y": 34,
      "z": 20,
      "name": "Rock_Magma_Cooled"
    },
    {
      "x": -24,
      "y": 35,
      "z": 20,
      "name": "Ore_Adamantite_Magma_Cracked"
    },
    {
      "x": -24,
      "y": 31,
      "z": 21,
      "name": "Rock_Magma_Cooled"
    },
    {
      "x": -24,
      "y": 32,
      "z": 21,
      "name": "Plant_Vine_Wall_Poisoned",
      "support": 15,
      "rotation": 3
    },
    {
      "x": -24,
      "y": 34,
      "z": 21,
      "name": "Rock_Magma_Cooled"
    },
    {
      "x": -24,
      "y": 31,
      "z": 22,
      "name": "Ore_Adamantite_Magma_Cracked"
    },
    {
      "x": -24,
      "y": 31,
      "z": 23,
      "name": "Ore_Adamantite_Magma_Cracked"
    },
    {
      "x": -24,
      "y": 32,
      "z": 23,
      "name": "Ore_Adamantite_Magma_Cracked"
    },
    {
      "x": -24,
      "y": 31,
      "z": 24,
      "name": "Ore_Adamantite_Magma_Cracked"
    },
    {
      "x": -24,
      "y": 32,
      "z": 24,
      "name": "Ore_Adamantite_Magma_Cracked"
    },
    {
      "x": -24,
      "y": 33,
      "z": 24,
      "name": "Rock_Magma_Cooled",
      "rotation": 1
    },
    {
      "x": -24,
      "y": 31,
      "z": 25,
      "name": "Rock_Magma_Cooled"
    },
    {
      "x": -24,
      "y": 32,
      "z": 25,
      "name": "Rock_Magma_Cooled"
    },
    {
      "x": -24,
      "y": 33,
      "z": 25,
      "name": "Ore_Adamantite_Magma_Cracked",
      "rotation": 1
    },
    {
      "x": -24,
      "y": 34,
      "z": 25,
      "name": "Rock_Magma_Cooled",
      "rotation": 1
    },
    {
      "x": -24,
      "y": 35,
      "z": 25,
      "name": "Ore_Adamantite_Magma_Cracked",
      "rotation": 1
    },
    {
      "x": -24,
      "y": 37,
      "z": 25,
      "name": "Plant_Vine_Wall_Poisoned",
      "support": 15,
      "rotation": 3
    },
    {
      "x": -24,
      "y": 35,
      "z": 26,
      "name": "Rock_Magma_Cooled",
      "rotation": 1
    },
    {
      "x": -24,
      "y": 36,
      "z": 26,
      "name": "Rock_Magma_Cooled",
      "rotation": 1
    },
    {
      "x": -23,
      "y": 0,
      "z": -11,
      "name": "Soil_Ash"
    },
    {
      "x": -23,
      "y": 1,
      "z": -11,
      "name": "Soil_Sand_Ashen"
    },
    {
      "x": -23,
      "y": 2,
      "z": -11,
      "name": "Soil_Sand_Ashen"
    },
    {
      "x": -23,
      "y": 3,
      "z": -11,
      "name": "Soil_Ash"
    },
    {
      "x": -23,
      "y": 0,
      "z": -10,
      "name": "Soil_Sand_Ashen"
    },
    {
      "x": -23,
      "y": 1,
      "z": -10,
      "name": "Soil_Sand_Ashen"
    },
    {
      "x": -23,
      "y": 2,
      "z": -10,
      "name": "Soil_Sand_Ashen"
    },
    {
      "x": -23,
      "y": 3,
      "z": -10,
      "name": "Soil_Sand_Ashen"
    },
    {
      "x": -23,
      "y": 0,
      "z": -9,
      "name": "Soil_Sand_Ashen"
    },
    {
      "x": -23,
      "y": 1,
      "z": -9,
      "name": "Soil_Sand_Ashen"
    },
    {
      "x": -23,
      "y": 2,
      "z": -9,
      "name": "Soil_Sand_Ashen"
    },
    {
      "x": -23,
      "y": 3,
      "z": -9,
      "name": "Soil_Sand_Ashen"
    },
    {
      "x": -23,
      "y": 4,
      "z": -9,
      "name": "Soil_Sand_Ashen"
    },
    {
      "x": -23,
      "y": 0,
      "z": -8,
      "name": "Soil_Ash"
    },
    {
      "x": -23,
      "y": 1,
      "z": -8,
      "name": "Soil_Sand_Ashen"
    },
    {
      "x": -23,
      "y": 2,
      "z": -8,
      "name": "Soil_Sand_Ashen"
    },
    {
      "x": -23,
      "y": 3,
      "z": -8,
      "name": "Soil_Sand_Ashen"
    },
    {
      "x": -23,
      "y": 4,
      "z": -8,
      "name": "Soil_Sand_Ashen"
    },
    {
      "x": -23,
      "y": 0,
      "z": -7,
      "name": "Soil_Sand_Ashen"
    },
    {
      "x": -23,
      "y": 1,
      "z": -7,
      "name": "Soil_Sand_Ashen"
    },
    {
      "x": -23,
      "y": 2,
      "z": -7,
      "name": "Soil_Sand_Ashen"
    },
    {
      "x": -23,
      "y": 3,
      "z": -7,
      "name": "Soil_Sand_Ashen"
    },
    {
      "x": -23,
      "y": 4,
      "z": -7,
      "name": "Soil_Sand_Ashen"
    },
    {
      "x": -23,
      "y": 5,
      "z": -7,
      "name": "Plant_Bramble_Dead_Twisted"
    },
    {
      "x": -23,
      "y": 0,
      "z": -6,
      "name": "Soil_Ash"
    },
    {
      "x": -23,
      "y": 1,
      "z": -6,
      "name": "Soil_Ash"
    },
    {
      "x": -23,
      "y": 2,
      "z": -6,
      "name": "Soil_Sand_Ashen"
    },
    {
      "x": -23,
      "y": 3,
      "z": -6,
      "name": "Soil_Sand_Ashen"
    },
    {
      "x": -23,
      "y": 4,
      "z": -6,
      "name": "Soil_Sand_Ashen"
    },
    {
      "x": -23,
      "y": 0,
      "z": -5,
      "name": "Soil_Ash"
    },
    {
      "x": -23,
      "y": 1,
      "z": -5,
      "name": "Soil_Ash"
    },
    {
      "x": -23,
      "y": 2,
      "z": -5,
      "name": "Soil_Ash"
    },
    {
      "x": -23,
      "y": 3,
      "z": -5,
      "name": "Soil_Sand_Ashen"
    },
    {
      "x": -23,
      "y": 4,
      "z": -5,
      "name": "Soil_Sand_Ashen"
    },
    {
      "x": -23,
      "y": 0,
      "z": -4,
      "name": "Soil_Ash"
    },
    {
      "x": -23,
      "y": 1,
      "z": -4,
      "name": "Soil_Ash"
    },
    {
      "x": -23,
      "y": 2,
      "z": -4,
      "name": "Soil_Ash"
    },
    {
      "x": -23,
      "y": 3,
      "z": -4,
      "name": "Soil_Ash"
    },
    {
      "x": -23,
      "y": 4,
      "z": -4,
      "name": "Soil_Ash"
    },
    {
      "x": -23,
      "y": 0,
      "z": -3,
      "name": "Soil_Ash"
    },
    {
      "x": -23,
      "y": 1,
      "z": -3,
      "name": "Soil_Ash"
    },
    {
      "x": -23,
      "y": 2,
      "z": -3,
      "name": "Soil_Ash"
    },
    {
      "x": -23,
      "y": 3,
      "z": -3,
      "name": "Soil_Ash"
    },
    {
      "x": -23,
      "y": 4,
      "z": -3,
      "name": "Soil_Ash"
    },
    {
      "x": -23,
      "y": 5,
      "z": -3,
      "name": "Soil_Ash"
    },
    {
      "x": -23,
      "y": 0,
      "z": -2,
      "name": "Soil_Ash"
    },
    {
      "x": -23,
      "y": 1,
      "z": -2,
      "name": "Soil_Ash"
    },
    {
      "x": -23,
      "y": 2,
      "z": -2,
      "name": "Soil_Ash"
    },
    {
      "x": -23,
      "y": 3,
      "z": -2,
      "name": "Soil_Ash"
    },
    {
      "x": -23,
      "y": 4,
      "z": -2,
      "name": "Soil_Ash"
    },
    {
      "x": -23,
      "y": 5,
      "z": -2,
      "name": "Soil_Ash"
    },
    {
      "x": -23,
      "y": 13,
      "z": -2,
      "name": "Rock_Magma_Cooled"
    },
    {
      "x": -23,
      "y": 0,
      "z": -1,
      "name": "Soil_Ash"
    },
    {
      "x": -23,
      "y": 1,
      "z": -1,
      "name": "Soil_Ash"
    },
    {
      "x": -23,
      "y": 2,
      "z": -1,
      "name": "Soil_Ash"
    },
    {
      "x": -23,
      "y": 3,
      "z": -1,
      "name": "Soil_Ash"
    },
    {
      "x": -23,
      "y": 4,
      "z": -1,
      "name": "Soil_Ash"
    },
    {
      "x": -23,
      "y": 5,
      "z": -1,
      "name": "Soil_Ash"
    },
    {
      "x": -23,
      "y": 12,
      "z": -1,
      "name": "Rock_Magma_Cooled"
    },
    {
      "x": -23,
      "y": 13,
      "z": -1,
      "name": "Ore_Adamantite_Magma_Cracked"
    },
    {
      "x": -23,
      "y": 14,
      "z": -1,
      "name": "Rock_Magma_Cooled"
    },
    {
      "x": -23,
      "y": 0,
      "z": 0,
      "name": "Soil_Ash"
    },
    {
      "x": -23,
      "y": 1,
      "z": 0,
      "name": "Soil_Ash"
    },
    {
      "x": -23,
      "y": 2,
      "z": 0,
      "name": "Soil_Ash"
    },
    {
      "x": -23,
      "y": 3,
      "z": 0,
      "name": "Soil_Ash"
    },
    {
      "x": -23,
      "y": 4,
      "z": 0,
      "name": "Soil_Ash"
    },
    {
      "x": -23,
      "y": 5,
      "z": 0,
      "name": "Soil_Ash"
    },
    {
      "x": -23,
      "y": 6,
      "z": 0,
      "name": "Soil_Ash"
    },
    {
      "x": -23,
      "y": 12,
      "z": 0,
      "name": "Ore_Adamantite_Magma_Cracked"
    },
    {
      "x": -23,
      "y": 13,
      "z": 0,
      "name": "Rock_Magma_Cooled"
    },
    {
      "x": -23,
      "y": 14,
      "z": 0,
      "name": "Ore_Adamantite_Magma_Cracked"
    },
    {
      "x": -23,
      "y": 0,
      "z": 1,
      "name": "Soil_Ash"
    },
    {
      "x": -23,
      "y": 1,
      "z": 1,
      "name": "Soil_Ash"
    },
    {
      "x": -23,
      "y": 2,
      "z": 1,
      "name": "Soil_Ash"
    },
    {
      "x": -23,
      "y": 3,
      "z": 1,
      "name": "Soil_Ash"
    },
    {
      "x": -23,
      "y": 4,
      "z": 1,
      "name": "Soil_Ash"
    },
    {
      "x": -23,
      "y": 5,
      "z": 1,
      "name": "Soil_Ash"
    },
    {
      "x": -23,
      "y": 6,
      "z": 1,
      "name": "Soil_Ash"
    },
    {
      "x": -23,
      "y": 11,
      "z": 1,
      "name": "Ore_Adamantite_Magma_Cracked"
    },
    {
      "x": -23,
      "y": 12,
      "z": 1,
      "name": "Rock_Magma_Cooled"
    },
    {
      "x": -23,
      "y": 13,
      "z": 1,
      "name": "Rock_Magma_Cooled"
    },
    {
      "x": -23,
      "y": 14,
      "z": 1,
      "name": "Rock_Magma_Cooled"
    },
    {
      "x": -23,
      "y": 15,
      "z": 1,
      "name": "Rock_Magma_Cooled"
    },
    {
      "x": -23,
      "y": 18,
      "z": 1,
      "name": "Rock_Magma_Cooled"
    },
    {
      "x": -23,
      "y": 0,
      "z": 2,
      "name": "Soil_Ash"
    },
    {
      "x": -23,
      "y": 1,
      "z": 2,
      "name": "Soil_Ash"
    },
    {
      "x": -23,
      "y": 2,
      "z": 2,
      "name": "Soil_Ash"
    },
    {
      "x": -23,
      "y": 3,
      "z": 2,
      "name": "Soil_Ash"
    },
    {
      "x": -23,
      "y": 4,
      "z": 2,
      "name": "Soil_Ash"
    },
    {
      "x": -23,
      "y": 5,
      "z": 2,
      "name": "Soil_Ash"
    },
    {
      "x": -23,
      "y": 6,
      "z": 2,
      "name": "Soil_Ash"
    },
    {
      "x": -23,
      "y": 11,
      "z": 2,
      "name": "Ore_Adamantite_Magma_Cracked"
    },
    {
      "x": -23,
      "y": 12,
      "z": 2,
      "name": "Rock_Magma_Cooled"
    },
    {
      "x": -23,
      "y": 13,
      "z": 2,
      "name": "Ore_Adamantite_Magma_Cracked"
    },
    {
      "x": -23,
      "y": 14,
      "z": 2,
      "name": "Rock_Magma_Cooled"
    },
    {
      "x": -23,
      "y": 15,
      "z": 2,
      "name": "Rock_Magma_Cooled"
    },
    {
      "x": -23,
      "y": 16,
      "z": 2,
      "name": "Ore_Adamantite_Magma_Cracked"
    },
    {
      "x": -23,
      "y": 17,
      "z": 2,
      "name": "Plant_Crop_Mushroom_Glowing_Purple"
    },
    {
      "x": -23,
      "y": 18,
      "z": 2,
      "name": "Ore_Adamantite_Magma_Cracked"
    },
    {
      "x": -23,
      "y": 0,
      "z": 3,
      "name": "Soil_Ash"
    },
    {
      "x": -23,
      "y": 1,
      "z": 3,
      "name": "Soil_Ash"
    },
    {
      "x": -23,
      "y": 2,
      "z": 3,
      "name": "Soil_Ash"
    },
    {
      "x": -23,
      "y": 3,
      "z": 3,
      "name": "Soil_Ash"
    },
    {
      "x": -23,
      "y": 4,
      "z": 3,
      "name": "Soil_Ash"
    },
    {
      "x": -23,
      "y": 5,
      "z": 3,
      "name": "Soil_Ash"
    },
    {
      "x": -23,
      "y": 6,
      "z": 3,
      "name": "Soil_Ash"
    },
    {
      "x": -23,
      "y": 11,
      "z": 3,
      "name": "Rock_Magma_Cooled"
    },
    {
      "x": -23,
      "y": 12,
      "z": 3,
      "name": "Ore_Adamantite_Magma_Cracked"
    },
    {
      "x": -23,
      "y": 13,
      "z": 3,
      "name": "Rock_Magma_Cooled"
    },
    {
      "x": -23,
      "y": 14,
      "z": 3,
      "name": "Ore_Adamantite_Magma_Cracked"
    },
    {
      "x": -23,
      "y": 15,
      "z": 3,
      "name": "Rock_Magma_Cooled"
    },
    {
      "x": -23,
      "y": 16,
      "z": 3,
      "name": "Ore_Adamantite_Magma_Cracked"
    },
    {
      "x": -23,
      "y": 17,
      "z": 3,
      "name": "Ore_Adamantite_Magma_Cracked"
    },
    {
      "x": -23,
      "y": 18,
      "z": 3,
      "name": "Ore_Adamantite_Magma_Cracked"
    },
    {
      "x": -23,
      "y": 0,
      "z": 4,
      "name": "Soil_Ash"
    },
    {
      "x": -23,
      "y": 1,
      "z": 4,
      "name": "Soil_Ash"
    },
    {
      "x": -23,
      "y": 2,
      "z": 4,
      "name": "Soil_Ash"
    },
    {
      "x": -23,
      "y": 3,
      "z": 4,
      "name": "Soil_Ash"
    },
    {
      "x": -23,
      "y": 4,
      "z": 4,
      "name": "Soil_Ash"
    },
    {
      "x": -23,
      "y": 5,
      "z": 4,
      "name": "Soil_Ash"
    },
    {
      "x": -23,
      "y": 6,
      "z": 4,
      "name": "Soil_Ash"
    },
    {
      "x": -23,
      "y": 11,
      "z": 4,
      "name": "Ore_Adamantite_Magma_Cracked"
    },
    {
      "x": -23,
      "y": 12,
      "z": 4,
      "name": "Rock_Magma_Cooled"
    },
    {
      "x": -23,
      "y": 13,
      "z": 4,
      "name": "Rock_Magma_Cooled"
    },
    {
      "x": -23,
      "y": 14,
      "z": 4,
      "name": "Ore_Adamantite_Magma_Cracked"
    },
    {
      "x": -23,
      "y": 15,
      "z": 4,
      "name": "Rock_Magma_Cooled"
    },
    {
      "x": -23,
      "y": 16,
      "z": 4,
      "name": "Ore_Adamantite_Magma_Cracked"
    },
    {
      "x": -23,
      "y": 17,
      "z": 4,
      "name": "Ore_Adamantite_Magma_Cracked"
    },
    {
      "x": -23,
      "y": 18,
      "z": 4,
      "name": "Rock_Magma_Cooled"
    },
    {
      "x": -23,
      "y": 0,
      "z": 5,
      "name": "Soil_Ash"
    },
    {
      "x": -23,
      "y": 1,
      "z": 5,
      "name": "Soil_Ash"
    },
    {
      "x": -23,
      "y": 2,
      "z": 5,
      "name": "Soil_Ash"
    },
    {
      "x": -23,
      "y": 3,
      "z": 5,
      "name": "Soil_Ash"
    },
    {
      "x": -23,
      "y": 4,
      "z": 5,
      "name": "Soil_Ash"
    },
    {
      "x": -23,
      "y": 5,
      "z": 5,
      "name": "Soil_Ash"
    },
    {
      "x": -23,
      "y": 6,
      "z": 5,
      "name": "Soil_Ash"
    },
    {
      "x": -23,
      "y": 11,
      "z": 5,
      "name": "Rock_Magma_Cooled"
    },
    {
      "x": -23,
      "y": 12,
      "z": 5,
      "name": "Ore_Adamantite_Magma_Cracked"
    },
    {
      "x": -23,
      "y": 13,
      "z": 5,
      "name": "Ore_Adamantite_Magma_Cracked"
    },
    {
      "x": -23,
      "y": 14,
      "z": 5,
      "name": "Rock_Magma_Cooled"
    },
    {
      "x": -23,
      "y": 15,
      "z": 5,
      "name": "Ore_Adamantite_Magma_Cracked"
    },
    {
      "x": -23,
      "y": 16,
      "z": 5,
      "name": "Rock_Magma_Cooled"
    },
    {
      "x": -23,
      "y": 17,
      "z": 5,
      "name": "Ore_Adamantite_Magma_Cracked"
    },
    {
      "x": -23,
      "y": 0,
      "z": 6,
      "name": "Soil_Ash"
    },
    {
      "x": -23,
      "y": 1,
      "z": 6,
      "name": "Soil_Ash"
    },
    {
      "x": -23,
      "y": 2,
      "z": 6,
      "name": "Soil_Ash"
    },
    {
      "x": -23,
      "y": 3,
      "z": 6,
      "name": "Soil_Ash"
    },
    {
      "x": -23,
      "y": 4,
      "z": 6,
      "name": "Soil_Ash"
    },
    {
      "x": -23,
      "y": 5,
      "z": 6,
      "name": "Soil_Ash"
    },
    {
      "x": -23,
      "y": 6,
      "z": 6,
      "name": "Soil_Ash"
    },
    {
      "x": -23,
      "y": 12,
      "z": 6,
      "name": "Ore_Adamantite_Magma_Cracked"
    },
    {
      "x": -23,
      "y": 13,
      "z": 6,
      "name": "Rock_Magma_Cooled"
    },
    {
      "x": -23,
      "y": 14,
      "z": 6,
      "name": "Rock_Magma_Cooled"
    },
    {
      "x": -23,
      "y": 15,
      "z": 6,
      "name": "Ore_Adamantite_Magma_Cracked"
    },
    {
      "x": -23,
      "y": 16,
      "z": 6,
      "name": "Rock_Magma_Cooled"
    },
    {
      "x": -23,
      "y": 17,
      "z": 6,
      "name": "Ore_Adamantite_Magma_Cracked"
    },
    {
      "x": -23,
      "y": 0,
      "z": 7,
      "name": "Soil_Ash"
    },
    {
      "x": -23,
      "y": 1,
      "z": 7,
      "name": "Soil_Ash"
    },
    {
      "x": -23,
      "y": 2,
      "z": 7,
      "name": "Soil_Ash"
    },
    {
      "x": -23,
      "y": 3,
      "z": 7,
      "name": "Soil_Ash"
    },
    {
      "x": -23,
      "y": 4,
      "z": 7,
      "name": "Soil_Ash"
    },
    {
      "x": -23,
      "y": 5,
      "z": 7,
      "name": "Soil_Ash"
    },
    {
      "x": -23,
      "y": 6,
      "z": 7,
      "name": "Soil_Ash"
    },
    {
      "x": -23,
      "y": 12,
      "z": 7,
      "name": "Rock_Magma_Cooled"
    },
    {
      "x": -23,
      "y": 13,
      "z": 7,
      "name": "Ore_Adamantite_Magma_Cracked"
    },
    {
      "x": -23,
      "y": 14,
      "z": 7,
      "name": "Ore_Adamantite_Magma_Cracked"
    },
    {
      "x": -23,
      "y": 15,
      "z": 7,
      "name": "Rock_Magma_Cooled"
    },
    {
      "x": -23,
      "y": 16,
      "z": 7,
      "name": "Rock_Magma_Cooled"
    },
    {
      "x": -23,
      "y": 17,
      "z": 7,
      "name": "Rock_Magma_Cooled"
    },
    {
      "x": -23,
      "y": 0,
      "z": 8,
      "name": "Soil_Ash"
    },
    {
      "x": -23,
      "y": 1,
      "z": 8,
      "name": "Soil_Ash"
    },
    {
      "x": -23,
      "y": 2,
      "z": 8,
      "name": "Soil_Ash"
    },
    {
      "x": -23,
      "y": 3,
      "z": 8,
      "name": "Soil_Ash"
    },
    {
      "x": -23,
      "y": 4,
      "z": 8,
      "name": "Soil_Ash"
    },
    {
      "x": -23,
      "y": 5,
      "z": 8,
      "name": "Soil_Ash"
    },
    {
      "x": -23,
      "y": 6,
      "z": 8,
      "name": "Soil_Ash"
    },
    {
      "x": -23,
      "y": 14,
      "z": 8,
      "name": "Ore_Adamantite_Magma_Cracked"
    },
    {
      "x": -23,
      "y": 15,
      "z": 8,
      "name": "Rock_Magma_Cooled"
    },
    {
      "x": -23,
      "y": 16,
      "z": 8,
      "name": "Ore_Adamantite_Magma_Cracked"
    },
    {
      "x": -23,
      "y": 0,
      "z": 9,
      "name": "Soil_Ash"
    },
    {
      "x": -23,
      "y": 1,
      "z": 9,
      "name": "Soil_Ash"
    },
    {
      "x": -23,
      "y": 2,
      "z": 9,
      "name": "Soil_Ash"
    },
    {
      "x": -23,
      "y": 3,
      "z": 9,
      "name": "Soil_Ash"
    },
    {
      "x": -23,
      "y": 4,
      "z": 9,
      "name": "Soil_Ash"
    },
    {
      "x": -23,
      "y": 5,
      "z": 9,
      "name": "Soil_Ash"
    },
    {
      "x": -23,
      "y": 6,
      "z": 9,
      "name": "Plant_Flower_Bushy_Poisoned"
    },
    {
      "x": -23,
      "y": 15,
      "z": 9,
      "name": "Rock_Magma_Cooled"
    },
    {
      "x": -23,
      "y": 0,
      "z": 10,
      "name": "Soil_Ash"
    },
    {
      "x": -23,
      "y": 1,
      "z": 10,
      "name": "Soil_Ash"
    },
    {
      "x": -23,
      "y": 2,
      "z": 10,
      "name": "Soil_Ash"
    },
    {
      "x": -23,
      "y": 3,
      "z": 10,
      "name": "Soil_Ash"
    },
    {
      "x": -23,
      "y": 4,
      "z": 10,
      "name": "Soil_Ash"
    },
    {
      "x": -23,
      "y": 5,
      "z": 10,
      "name": "Soil_Ash"
    },
    {
      "x": -23,
      "y": 0,
      "z": 11,
      "name": "Soil_Ash"
    },
    {
      "x": -23,
      "y": 1,
      "z": 11,
      "name": "Soil_Ash"
    },
    {
      "x": -23,
      "y": 2,
      "z": 11,
      "name": "Soil_Ash"
    },
    {
      "x": -23,
      "y": 3,
      "z": 11,
      "name": "Soil_Ash"
    },
    {
      "x": -23,
      "y": 4,
      "z": 11,
      "name": "Soil_Ash"
    },
    {
      "x": -23,
      "y": 0,
      "z": 12,
      "name": "Soil_Ash"
    },
    {
      "x": -23,
      "y": 1,
      "z": 12,
      "name": "Soil_Ash"
    },
    {
      "x": -23,
      "y": 2,
      "z": 12,
      "name": "Soil_Ash"
    },
    {
      "x": -23,
      "y": 3,
      "z": 12,
      "name": "Soil_Ash"
    },
    {
      "x": -23,
      "y": 0,
      "z": 13,
      "name": "Soil_Ash"
    },
    {
      "x": -23,
      "y": 1,
      "z": 13,
      "name": "Soil_Ash"
    },
    {
      "x": -23,
      "y": 2,
      "z": 13,
      "name": "Soil_Ash"
    },
    {
      "x": -23,
      "y": 1,
      "z": 14,
      "name": "Soil_Ash"
    },
    {
      "x": -23,
      "y": 35,
      "z": 18,
      "name": "Ore_Adamantite_Magma_Cracked"
    },
    {
      "x": -23,
      "y": 30,
      "z": 19,
      "name": "Ore_Adamantite_Magma_Cracked"
    },
    {
      "x": -23,
      "y": 31,
      "z": 19,
      "name": "Rock_Magma_Cooled"
    },
    {
      "x": -23,
      "y": 32,
      "z": 19,
      "name": "Plant_Vine_Wall_Poisoned",
      "support": 15,
      "rotation": 2
    },
    {
      "x": -23,
      "y": 33,
      "z": 19,
      "name": "Ore_Adamantite_Magma_Cracked"
    },
    {
      "x": -23,
      "y": 34,
      "z": 19,
      "name": "Rock_Magma_Cooled"
    },
    {
      "x": -23,
      "y": 35,
      "z": 19,
      "name": "Ore_Adamantite_Magma_Cracked"
    },
    {
      "x": -23,
      "y": 30,
      "z": 20,
      "name": "Ore_Adamantite_Magma_Cracked"
    },
    {
      "x": -23,
      "y": 31,
      "z": 20,
      "name": "Rock_Magma_Cooled"
    },
    {
      "x": -23,
      "y": 32,
      "z": 20,
      "name": "Rock_Magma_Cooled"
    },
    {
      "x": -23,
      "y": 33,
      "z": 20,
      "name": "Ore_Adamantite_Magma_Cracked"
    },
    {
      "x": -23,
      "y": 34,
      "z": 20,
      "name": "Ore_Adamantite_Magma_Cracked"
    },
    {
      "x": -23,
      "y": 35,
      "z": 20,
      "name": "Ore_Adamantite_Magma_Cracked"
    },
    {
      "x": -23,
      "y": 30,
      "z": 21,
      "name": "Ore_Adamantite_Magma_Cracked"
    },
    {
      "x": -23,
      "y": 31,
      "z": 21,
      "name": "Ore_Adamantite_Magma_Cracked"
    },
    {
      "x": -23,
      "y": 32,
      "z": 21,
      "name": "Rock_Magma_Cooled"
    },
    {
      "x": -23,
      "y": 33,
      "z": 21,
      "name": "Ore_Adamantite_Magma_Cracked"
    },
    {
      "x": -23,
      "y": 34,
      "z": 21,
      "name": "Ore_Adamantite_Magma_Cracked"
    },
    {
      "x": -23,
      "y": 35,
      "z": 21,
      "name": "Ore_Adamantite_Magma_Cracked"
    },
    {
      "x": -23,
      "y": 29,
      "z": 22,
      "name": "Plant_Vine_Wall_Poisoned",
      "support": 15,
      "rotation": 3
    },
    {
      "x": -23,
      "y": 30,
      "z": 22,
      "name": "Ore_Adamantite_Magma_Cracked"
    },
    {
      "x": -23,
      "y": 31,
      "z": 22,
      "name": "Rock_Magma_Cooled"
    },
    {
      "x": -23,
      "y": 32,
      "z": 22,
      "name": "Rock_Magma_Cooled"
    },
    {
      "x": -23,
      "y": 33,
      "z": 22,
      "name": "Rock_Magma_Cooled"
    },
    {
      "x": -23,
      "y": 30,
      "z": 23,
      "name": "Rock_Magma_Cooled"
    },
    {
      "x": -23,
      "y": 31,
      "z": 23,
      "name": "Ore_Adamantite_Magma_Cracked"
    },
    {
      "x": -23,
      "y": 32,
      "z": 23,
      "name": "Ore_Adamantite_Magma_Cracked"
    },
    {
      "x": -23,
      "y": 33,
      "z": 23,
      "name": "Ore_Adamantite_Magma_Cracked"
    },
    {
      "x": -23,
      "y": 30,
      "z": 24,
      "name": "Ore_Adamantite_Magma_Cracked"
    },
    {
      "x": -23,
      "y": 31,
      "z": 24,
      "name": "Ore_Adamantite_Magma_Cracked"
    },
    {
      "x": -23,
      "y": 32,
      "z": 24,
      "name": "Ore_Adamantite_Magma_Cracked"
    },
    {
      "x": -23,
      "y": 33,
      "z": 24,
      "name": "Rock_Magma_Cooled",
      "rotation": 1
    },
    {
      "x": -23,
      "y": 34,
      "z": 24,
      "name": "Rock_Magma_Cooled",
      "rotation": 1
    },
    {
      "x": -23,
      "y": 30,
      "z": 25,
      "name": "Rock_Magma_Cooled"
    },
    {
      "x": -23,
      "y": 31,
      "z": 25,
      "name": "Ore_Adamantite_Magma_Cracked"
    },
    {
      "x": -23,
      "y": 32,
      "z": 25,
      "name": "Ore_Adamantite_Magma_Cracked"
    },
    {
      "x": -23,
      "y": 33,
      "z": 25,
      "name": "Rock_Magma_Cooled",
      "rotation": 1
    },
    {
      "x": -23,
      "y": 34,
      "z": 25,
      "name": "Rock_Magma_Cooled",
      "rotation": 1
    },
    {
      "x": -23,
      "y": 35,
      "z": 25,
      "name": "Rock_Magma_Cooled",
      "rotation": 1
    },
    {
      "x": -23,
      "y": 36,
      "z": 25,
      "name": "Rock_Magma_Cooled",
      "rotation": 1
    },
    {
      "x": -23,
      "y": 37,
      "z": 25,
      "name": "Rock_Magma_Cooled",
      "rotation": 1
    },
    {
      "x": -23,
      "y": 31,
      "z": 26,
      "name": "Rock_Magma_Cooled"
    },
    {
      "x": -23,
      "y": 32,
      "z": 26,
      "name": "Rock_Magma_Cooled"
    },
    {
      "x": -23,
      "y": 33,
      "z": 26,
      "name": "Plant_Moss_Rug_Pink",
      "support": 15
    },
    {
      "x": -23,
      "y": 34,
      "z": 26,
      "name": "Ore_Adamantite_Magma_Cracked",
      "rotation": 1
    },
    {
      "x": -23,
      "y": 35,
      "z": 26,
      "name": "Rock_Magma_Cooled",
      "rotation": 1
    },
    {
      "x": -23,
      "y": 36,
      "z": 26,
      "name": "Rock_Magma_Cooled",
      "rotation": 1
    },
    {
      "x": -23,
      "y": 37,
      "z": 26,
      "name": "Ore_Adamantite_Magma_Cracked",
      "rotation": 1
    },
    {
      "x": -23,
      "y": 38,
      "z": 26,
      "name": "Rock_Magma_Cooled",
      "rotation": 1
    },
    {
      "x": -23,
      "y": 39,
      "z": 26,
      "name": "Rock_Magma_Cooled",
      "rotation": 1
    },
    {
      "x": -23,
      "y": 40,
      "z": 26,
      "name": "Plant_Moss_Rug_Pink",
      "support": 15
    },
    {
      "x": -22,
      "y": 0,
      "z": -11,
      "name": "Soil_Sand_Ashen"
    },
    {
      "x": -22,
      "y": 1,
      "z": -11,
      "name": "Soil_Sand_Ashen"
    },
    {
      "x": -22,
      "y": 2,
      "z": -11,
      "name": "Soil_Sand_Ashen"
    },
    {
      "x": -22,
      "y": 3,
      "z": -11,
      "name": "Soil_Ash"
    },
    {
      "x": -22,
      "y": 0,
      "z": -10,
      "name": "Soil_Sand_Ashen"
    },
    {
      "x": -22,
      "y": 1,
      "z": -10,
      "name": "Soil_Sand_Ashen"
    },
    {
      "x": -22,
      "y": 2,
      "z": -10,
      "name": "Soil_Sand_Ashen"
    },
    {
      "x": -22,
      "y": 3,
      "z": -10,
      "name": "Soil_Sand_Ashen"
    },
    {
      "x": -22,
      "y": 0,
      "z": -9,
      "name": "Soil_Sand_Ashen"
    },
    {
      "x": -22,
      "y": 1,
      "z": -9,
      "name": "Soil_Sand_Ashen"
    },
    {
      "x": -22,
      "y": 2,
      "z": -9,
      "name": "Soil_Sand_Ashen"
    },
    {
      "x": -22,
      "y": 3,
      "z": -9,
      "name": "Soil_Sand_Ashen"
    },
    {
      "x": -22,
      "y": 4,
      "z": -9,
      "name": "Soil_Ash"
    },
    {
      "x": -22,
      "y": 5,
      "z": -9,
      "name": "Plant_Bramble_Dead_Twisted"
    },
    {
      "x": -22,
      "y": 0,
      "z": -8,
      "name": "Soil_Sand_Ashen"
    },
    {
      "x": -22,
      "y": 1,
      "z": -8,
      "name": "Soil_Sand_Ashen"
    },
    {
      "x": -22,
      "y": 2,
      "z": -8,
      "name": "Soil_Sand_Ashen"
    },
    {
      "x": -22,
      "y": 3,
      "z": -8,
      "name": "Soil_Sand_Ashen"
    },
    {
      "x": -22,
      "y": 4,
      "z": -8,
      "name": "Soil_Sand_Ashen"
    },
    {
      "x": -22,
      "y": 0,
      "z": -7,
      "name": "Soil_Sand_Ashen"
    },
    {
      "x": -22,
      "y": 1,
      "z": -7,
      "name": "Soil_Sand_Ashen"
    },
    {
      "x": -22,
      "y": 2,
      "z": -7,
      "name": "Soil_Sand_Ashen"
    },
    {
      "x": -22,
      "y": 3,
      "z": -7,
      "name": "Soil_Sand_Ashen"
    },
    {
      "x": -22,
      "y": 4,
      "z": -7,
      "name": "Soil_Sand_Ashen"
    },
    {
      "x": -22,
      "y": 0,
      "z": -6,
      "name": "Soil_Ash"
    },
    {
      "x": -22,
      "y": 1,
      "z": -6,
      "name": "Soil_Ash"
    },
    {
      "x": -22,
      "y": 2,
      "z": -6,
      "name": "Soil_Sand_Ashen"
    },
    {
      "x": -22,
      "y": 3,
      "z": -6,
      "name": "Soil_Sand_Ashen"
    },
    {
      "x": -22,
      "y": 4,
      "z": -6,
      "name": "Soil_Sand_Ashen"
    },
    {
      "x": -22,
      "y": 0,
      "z": -5,
      "name": "Soil_Ash"
    },
    {
      "x": -22,
      "y": 1,
      "z": -5,
      "name": "Soil_Ash"
    },
    {
      "x": -22,
      "y": 2,
      "z": -5,
      "name": "Soil_Ash"
    },
    {
      "x": -22,
      "y": 3,
      "z": -5,
      "name": "Soil_Ash"
    },
    {
      "x": -22,
      "y": 4,
      "z": -5,
      "name": "Soil_Ash"
    },
    {
      "x": -22,
      "y": 0,
      "z": -4,
      "name": "Soil_Ash"
    },
    {
      "x": -22,
      "y": 1,
      "z": -4,
      "name": "Soil_Ash"
    },
    {
      "x": -22,
      "y": 2,
      "z": -4,
      "name": "Soil_Ash"
    },
    {
      "x": -22,
      "y": 3,
      "z": -4,
      "name": "Soil_Ash"
    },
    {
      "x": -22,
      "y": 4,
      "z": -4,
      "name": "Soil_Ash"
    },
    {
      "x": -22,
      "y": 5,
      "z": -4,
      "name": "Soil_Ash"
    },
    {
      "x": -22,
      "y": 0,
      "z": -3,
      "name": "Soil_Ash"
    },
    {
      "x": -22,
      "y": 1,
      "z": -3,
      "name": "Soil_Ash"
    },
    {
      "x": -22,
      "y": 2,
      "z": -3,
      "name": "Soil_Ash"
    },
    {
      "x": -22,
      "y": 3,
      "z": -3,
      "name": "Soil_Ash"
    },
    {
      "x": -22,
      "y": 4,
      "z": -3,
      "name": "Soil_Ash"
    },
    {
