{
  "version": 8,
  "blockIdVersion": 11,
  "anchorX": 0,
  "anchorY": 0,
  "anchorZ": 0,
  "blocks": [
    {
      "x": -34,
      "y": 30,
      "z": -1,
      "name": "Plant_Vine_Wall_Poisoned",
      "support": 15,
      "rotation": 3
    },
    {
      "x": -34,
      "y": 29,
      "z": 0,
      "name": "Plant_Vine_Wall_Poisoned",
      "support": 15,
      "rotation": 3
    },
    {
      "x": -33,
      "y": 29,
      "z": -1,
      "name": "Rock_Magma_Cooled",
      "rotation": 1
    },
    {
      "x": -33,
      "y": 30,
      "z": -1,
      "name": "Rock_Magma_Cooled",
      "rotation": 1
    },
    {
      "x": -33,
      "y": 31,
      "z": -1,
      "name": "Rock_Magma_Cooled",
      "rotation": 1
    },
    {
      "x": -33,
      "y": 32,
      "z": -1,
      "name": "Rock_Magma_Cooled",
      "rotation": 1
    },
    {
      "x": -33,
      "y": 33,
      "z": -1,
      "name": "Plant_Moss_Rug_Pink",
      "support": 15
    },
    {
      "x": -33,
      "y": 27,
      "z": 0,
      "name": "Rock_Magma_Cooled",
      "rotation": 1
    },
    {
      "x": -33,
      "y": 28,
      "z": 0,
      "name": "Rock_Magma_Cooled",
      "rotation": 1
    },
    {
      "x": -33,
      "y": 29,
      "z": 0,
      "name": "Rock_Magma_Cooled",
      "rotation": 1
    },
    {
      "x": -33,
      "y": 30,
      "z": 0,
      "name": "Rock_Magma_Cooled",
      "rotation": 1
    },
    {
      "x": -33,
      "y": 31,
      "z": 0,
      "name": "Plant_Moss_Rug_Pink",
      "support": 15
    },
    {
      "x": -32,
      "y": 26,
      "z": 0,
      "name": "Rock_Magma_Cooled",
      "rotation": 1
    },
    {
      "x": -32,
      "y": 27,
      "z": 0,
      "name": "Rock_Magma_Cooled",
      "rotation": 1
    },
    {
      "x": -32,
      "y": 28,
      "z": 0,
      "name": "Rock_Magma_Cooled",
      "rotation": 1
    },
    {
      "x": -32,
      "y": 29,
      "z": 0,
      "name": "Rock_Magma_Cooled",
      "rotation": 1
    },
    {
      "x": -32,
      "y": 30,
      "z": 0,
      "name": "Plant_Moss_Rug_Pink",
      "support": 15
    },
    {
      "x": -32,
      "y": 26,
      "z": 1,
      "name": "Plant_Vine_Wall_Poisoned",
      "support": 15
    },
    {
      "x": -32,
      "y": 28,
      "z": 1,
      "name": "Plant_Vine_Wall_Poisoned",
      "support": 15,
      "rotation": 3
    },
    {
      "x": -31,
      "y": 25,
      "z": 0,
      "name": "Rock_Magma_Cooled",
      "rotation": 1
    },
    {
      "x": -31,
      "y": 26,
      "z": 0,
      "name": "Rock_Magma_Cooled",
      "rotation": 1
    },
    {
      "x": -31,
      "y": 25,
      "z": 1,
      "name": "Ore_Adamantite_Magma_Cracked",
      "rotation": 1
    },
    {
      "x": -31,
      "y": 26,
      "z": 1,
      "name": "Rock_Magma_Cooled",
      "rotation": 1
    },
    {
      "x": -31,
      "y": 27,
      "z": 1,
      "name": "Ore_Adamantite_Magma_Cracked",
      "rotation": 1
    },
    {
      "x": -31,
      "y": 28,
      "z": 1,
      "name": "Rock_Magma_Cooled",
      "rotation": 1
    },
    {
      "x": -31,
      "y": 29,
      "z": 1,
      "name": "Plant_Moss_Rug_Pink",
      "support": 15
    },
    {
      "x": -31,
      "y": 25,
      "z": 2,
      "name": "Plant_Vine_Wall_Poisoned",
      "support": 15,
      "rotation": 3
    },
    {
      "x": -30,
      "y": 36,
      "z": -2,
      "name": "Plant_Vine_Wall_Poisoned",
      "support": 15,
      "rotation": 3
    },
    {
      "x": -30,
      "y": 25,
      "z": 1,
      "name": "Ore_Adamantite_Magma_Cracked",
      "rotation": 1
    },
    {
      "x": -30,
      "y": 25,
      "z": 2,
      "name": "Rock_Magma_Cooled",
      "rotation": 1
    },
    {
      "x": -30,
      "y": 26,
      "z": 2,
      "name": "Rock_Magma_Cooled",
      "rotation": 1
    },
    {
      "x": -29,
      "y": 38,
      "z": -3,
      "name": "Rock_Magma_Cooled"
    },
    {
      "x": -29,
      "y": 39,
      "z": -3,
      "name": "Rock_Magma_Cooled"
    },
    {
      "x": -29,
      "y": 40,
      "z": -3,
      "name": "Rock_Magma_Cooled"
    },
    {
      "x": -29,
      "y": 41,
      "z": -3,
      "name": "Plant_Moss_Rug_Pink",
      "support": 15
    },
    {
      "x": -29,
      "y": 36,
      "z": -2,
      "name": "Rock_Magma_Cooled"
    },
    {
      "x": -29,
      "y": 37,
      "z": -2,
      "name": "Rock_Magma_Cooled"
    },
    {
      "x": -29,
      "y": 38,
      "z": -2,
      "name": "Rock_Magma_Cooled"
    },
    {
      "x": -29,
      "y": 39,
      "z": -2,
      "name": "Rock_Magma_Cooled"
    },
    {
      "x": -29,
      "y": 40,
      "z": -2,
      "name": "Plant_Moss_Rug_Pink",
      "support": 15
    },
    {
      "x": -29,
      "y": 31,
      "z": -1,
      "name": "Rock_Magma_Cooled"
    },
    {
      "x": -29,
      "y": 32,
      "z": -1,
      "name": "Ore_Adamantite_Magma_Cracked"
    },
    {
      "x": -29,
      "y": 33,
      "z": -1,
      "name": "Plant_Moss_Rug_Pink",
      "support": 15
    },
    {
      "x": -29,
      "y": 31,
      "z": 0,
      "name": "Rock_Magma_Cooled"
    },
    {
      "x": -29,
      "y": 32,
      "z": 0,
      "name": "Plant_Moss_Rug_Pink",
      "support": 15
    },
    {
      "x": -29,
      "y": 24,
      "z": 1,
      "name": "Rock_Magma_Cooled"
    },
    {
      "x": -29,
      "y": 25,
      "z": 1,
      "name": "Rock_Magma_Cooled",
      "rotation": 1
    },
    {
      "x": -29,
      "y": 26,
      "z": 1,
      "name": "Rock_Magma_Cooled"
    },
    {
      "x": -29,
      "y": 25,
      "z": 2,
      "name": "Rock_Magma_Cooled",
      "rotation": 1
    },
    {
      "x": -29,
      "y": 26,
      "z": 2,
      "name": "Rock_Magma_Cooled"
    },
    {
      "x": -28,
      "y": 35,
      "z": -3,
      "name": "Plant_Vine_Wall_Poisoned",
      "support": 15,
      "rotation": 2
    },
    {
      "x": -28,
      "y": 30,
      "z": -2,
      "name": "Ore_Adamantite_Magma_Cracked"
    },
    {
      "x": -28,
      "y": 31,
      "z": -2,
      "name": "Plant_Moss_Rug_Pink",
      "support": 15
    },
    {
      "x": -28,
      "y": 34,
      "z": -2,
      "name": "Rock_Magma_Cooled",
      "rotation": 1
    },
    {
      "x": -28,
      "y": 35,
      "z": -2,
      "name": "Rock_Magma_Cooled",
      "rotation": 1
    },
    {
      "x": -28,
      "y": 36,
      "z": -2,
      "name": "Rock_Magma_Cooled",
      "rotation": 1
    },
    {
      "x": -28,
      "y": 37,
      "z": -2,
      "name": "Rock_Magma_Cooled",
      "rotation": 1
    },
    {
      "x": -28,
      "y": 38,
      "z": -2,
      "name": "Plant_Moss_Rug_Pink",
      "support": 15
    },
    {
      "x": -28,
      "y": 30,
      "z": -1,
      "name": "Rock_Magma_Cooled"
    },
    {
      "x": -28,
      "y": 31,
      "z": -1,
      "name": "Rock_Magma_Cooled"
    },
    {
      "x": -28,
      "y": 32,
      "z": -1,
      "name": "Rock_Magma_Cooled",
      "rotation": 1
    },
    {
      "x": -28,
      "y": 33,
      "z": -1,
      "name": "Rock_Magma_Cooled",
      "rotation": 1
    },
    {
      "x": -28,
      "y": 34,
      "z": -1,
      "name": "Rock_Magma_Cooled",
      "rotation": 1
    },
    {
      "x": -28,
      "y": 35,
      "z": -1,
      "name": "Rock_Magma_Cooled",
      "rotation": 1
    },
    {
      "x": -28,
      "y": 36,
      "z": -1,
      "name": "Plant_Moss_Rug_Pink",
      "support": 15
    },
    {
      "x": -28,
      "y": 27,
      "z": 0,
      "name": "Rock_Magma_Cooled"
    },
    {
      "x": -28,
      "y": 29,
      "z": 0,
      "name": "Rock_Magma_Cooled"
    },
    {
      "x": -28,
      "y": 30,
      "z": 0,
      "name": "Rock_Magma_Cooled"
    },
    {
      "x": -28,
      "y": 31,
      "z": 0,
      "name": "Ore_Adamantite_Magma_Cracked"
    },
    {
      "x": -28,
      "y": 32,
      "z": 0,
      "name": "Rock_Magma_Cooled"
    },
    {
      "x": -28,
      "y": 33,
      "z": 0,
      "name": "Plant_Moss_Rug_Pink",
      "support": 15
    },
    {
      "x": -28,
      "y": 25,
      "z": 1,
      "name": "Rock_Magma_Cooled"
    },
    {
      "x": -28,
      "y": 26,
      "z": 1,
      "name": "Rock_Magma_Cooled"
    },
    {
      "x": -28,
      "y": 28,
      "z": 1,
      "name": "Plant_Vine_Wall_Poisoned",
      "support": 15,
      "rotation": 3
    },
    {
      "x": -28,
      "y": 29,
      "z": 1,
      "name": "Plant_Vine_Wall_Poisoned",
      "support": 15,
      "rotation": 3
    },
    {
      "x": -28,
      "y": 30,
      "z": 1,
      "name": "Plant_Moss_Rug_Pink",
      "support": 15
    },
    {
      "x": -28,
      "y": 25,
      "z": 2,
      "name": "Rock_Magma_Cooled"
    },
    {
      "x": -28,
      "y": 26,
      "z": 2,
      "name": "Rock_Magma_Cooled"
    },
    {
      "x": -28,
      "y": 29,
      "z": 2,
      "name": "Plant_Vine_Wall_Poisoned",
      "support": 15,
      "rotation": 3
    },
    {
      "x": -28,
      "y": 30,
      "z": 2,
      "name": "Plant_Moss_Rug_Pink",
      "support": 15
    },
    {
      "x": -27,
      "y": 27,
      "z": -2,
      "name": "Ore_Adamantite_Magma_Cracked"
    },
    {
      "x": -27,
      "y": 29,
      "z": -2,
      "name": "Ore_Adamantite_Magma_Cracked"
    },
    {
      "x": -27,
      "y": 30,
      "z": -2,
      "name": "Rock_Magma_Cooled"
    },
    {
      "x": -27,
      "y": 31,
      "z": -2,
      "name": "Rock_Magma_Cooled"
    },
    {
      "x": -27,
      "y": 32,
      "z": -2,
      "name": "Plant_Moss_Rug_Pink",
      "support": 15
    },
    {
      "x": -27,
      "y": 34,
      "z": -2,
      "name": "Plant_Vine_Wall_Poisoned",
      "support": 15,
      "rotation": 2
    },
    {
      "x": -27,
      "y": 26,
      "z": -1,
      "name": "Ore_Adamantite_Magma"
    },
    {
      "x": -27,
      "y": 27,
      "z": -1,
      "name": "Rock_Magma_Cooled"
    },
    {
      "x": -27,
      "y": 28,
      "z": -1,
      "name": "Rock_Magma_Cooled"
    },
    {
      "x": -27,
      "y": 29,
      "z": -1,
      "name": "Ore_Adamantite_Magma_Cracked"
    },
    {
      "x": -27,
      "y": 30,
      "z": -1,
      "name": "Rock_Magma_Cooled"
    },
    {
      "x": -27,
      "y": 31,
      "z": -1,
      "name": "Rock_Magma_Cooled",
      "rotation": 1
    },
    {
      "x": -27,
      "y": 32,
      "z": -1,
      "name": "Rock_Magma_Cooled",
      "rotation": 1
    },
    {
      "x": -27,
      "y": 33,
      "z": -1,
      "name": "Ore_Adamantite_Magma_Cracked",
      "rotation": 1
    },
    {
      "x": -27,
      "y": 34,
      "z": -1,
      "name": "Rock_Magma_Cooled",
      "rotation": 1
    },
    {
      "x": -27,
      "y": 35,
      "z": -1,
      "name": "Plant_Moss_Rug_Pink",
      "support": 15
    },
    {
      "x": -27,
      "y": 26,
      "z": 0,
      "name": "Rock_Magma_Cooled"
    },
    {
      "x": -27,
      "y": 27,
      "z": 0,
      "name": "Ore_Adamantite_Magma_Cracked"
    },
    {
      "x": -27,
      "y": 28,
      "z": 0,
      "name": "Ore_Adamantite_Magma_Cracked"
    },
    {
      "x": -27,
      "y": 29,
      "z": 0,
      "name": "Plant_Vine_Wall_Poisoned",
      "support": 15,
      "rotation": 3
    },
    {
      "x": -27,
      "y": 30,
      "z": 0,
      "name": "Rock_Magma_Cooled",
      "rotation": 1
    },
    {
      "x": -27,
      "y": 31,
      "z": 0,
      "name": "Ore_Adamantite_Magma_Cracked",
      "rotation": 1
    },
    {
      "x": -27,
      "y": 32,
      "z": 0,
      "name": "Ore_Adamantite_Magma_Cracked",
      "rotation": 1
    },
    {
      "x": -27,
      "y": 33,
      "z": 0,
      "name": "Plant_Moss_Rug_Pink",
      "support": 15
    },
    {
      "x": -27,
      "y": 25,
      "z": 1,
      "name": "Rock_Magma_Cooled"
    },
    {
      "x": -27,
      "y": 26,
      "z": 1,
      "name": "Ore_Adamantite_Magma_Cracked"
    },
    {
      "x": -27,
      "y": 28,
      "z": 1,
      "name": "Rock_Magma_Cooled",
      "rotation": 1
    },
    {
      "x": -27,
      "y": 29,
      "z": 1,
      "name": "Rock_Magma_Cooled",
      "rotation": 1
    },
    {
      "x": -27,
      "y": 30,
      "z": 1,
      "name": "Rock_Magma_Cooled",
      "rotation": 1
    },
    {
      "x": -27,
      "y": 31,
      "z": 1,
      "name": "Rock_Magma_Cooled",
      "rotation": 1
    },
    {
      "x": -27,
      "y": 32,
      "z": 1,
      "name": "Plant_Moss_Rug_Pink",
      "support": 15
    },
    {
      "x": -27,
      "y": 25,
      "z": 2,
      "name": "Rock_Magma_Cooled"
    },
    {
      "x": -27,
      "y": 26,
      "z": 2,
      "name": "Rock_Magma_Cooled"
    },
    {
      "x": -27,
      "y": 28,
      "z": 2,
      "name": "Rock_Magma_Cooled"
    },
    {
      "x": -27,
      "y": 29,
      "z": 2,
      "name": "Rock_Magma_Cooled",
      "rotation": 1
    },
    {
      "x": -27,
      "y": 30,
      "z": 2,
      "name": "Ore_Adamantite_Magma_Cracked",
      "rotation": 1
    },
    {
      "x": -27,
      "y": 31,
      "z": 2,
      "name": "Plant_Moss_Rug_Pink",
      "support": 15
    },
    {
      "x": -26,
      "y": 26,
      "z": -2,
      "name": "Ore_Adamantite_Magma_Cracked"
    },
    {
      "x": -26,
      "y": 27,
      "z": -2,
      "name": "Rock_Magma_Cooled"
    },
    {
      "x": -26,
      "y": 28,
      "z": -2,
      "name": "Ore_Adamantite_Magma_Cracked"
    },
    {
      "x": -26,
      "y": 30,
      "z": -2,
      "name": "Ore_Adamantite_Magma_Cracked"
    },
    {
      "x": -26,
      "y": 31,
      "z": -2,
      "name": "Plant_Moss_Rug_Pink",
      "support": 15
    },
    {
      "x": -26,
      "y": 25,
      "z": -1,
      "name": "Ore_Adamantite_Magma"
    },
    {
      "x": -26,
      "y": 26,
      "z": -1,
      "name": "Ore_Adamantite_Magma_Cracked"
    },
    {
      "x": -26,
      "y": 27,
      "z": -1,
      "name": "Rock_Magma_Cooled"
    },
    {
      "x": -26,
      "y": 28,
      "z": -1,
      "name": "Ore_Adamantite_Magma_Cracked"
    },
    {
      "x": -26,
      "y": 29,
      "z": -1,
      "name": "Rock_Magma_Cooled"
    },
    {
      "x": -26,
      "y": 30,
      "z": -1,
      "name": "Ore_Adamantite_Magma_Cracked"
    },
    {
      "x": -26,
      "y": 31,
      "z": -1,
      "name": "Plant_Moss_Rug_Pink",
      "support": 15
    },
    {
      "x": -26,
      "y": 24,
      "z": 0,
      "name": "Ore_Adamantite_Magma"
    },
    {
      "x": -26,
      "y": 25,
      "z": 0,
      "name": "Ore_Adamantite_Magma_Cracked"
    },
    {
      "x": -26,
      "y": 26,
      "z": 0,
      "name": "Ore_Adamantite_Magma_Cracked",
      "rotation": 1
    },
    {
      "x": -26,
      "y": 27,
      "z": 0,
      "name": "Ore_Adamantite_Magma_Cracked",
      "rotation": 1
    },
    {
      "x": -26,
      "y": 28,
      "z": 0,
      "name": "Rock_Magma_Cooled",
      "rotation": 1
    },
    {
      "x": -26,
      "y": 29,
      "z": 0,
      "name": "Rock_Magma_Cooled",
      "rotation": 1
    },
    {
      "x": -26,
      "y": 30,
      "z": 0,
      "name": "Rock_Magma_Cooled",
      "rotation": 1
    },
    {
      "x": -26,
      "y": 31,
      "z": 0,
      "name": "Rock_Magma_Cooled",
      "rotation": 1
    },
    {
      "x": -26,
      "y": 32,
      "z": 0,
      "name": "Plant_Moss_Rug_Pink",
      "support": 15
    },
    {
      "x": -26,
      "y": 25,
      "z": 1,
      "name": "Rock_Magma_Cooled",
      "rotation": 1
    },
    {
      "x": -26,
      "y": 26,
      "z": 1,
      "name": "Rock_Magma_Cooled",
      "rotation": 1
    },
    {
      "x": -26,
      "y": 27,
      "z": 1,
      "name": "Rock_Magma_Cooled",
      "rotation": 1
    },
    {
      "x": -26,
      "y": 28,
      "z": 1,
      "name": "Rock_Magma_Cooled",
      "rotation": 1
    },
    {
      "x": -26,
      "y": 29,
      "z": 1,
      "name": "Ore_Adamantite_Magma_Cracked",
      "rotation": 1
    },
    {
      "x": -26,
      "y": 30,
      "z": 1,
      "name": "Rock_Magma_Cooled",
      "rotation": 1
    },
    {
      "x": -26,
      "y": 31,
      "z": 1,
      "name": "Plant_Moss_Rug_Pink",
      "support": 15
    },
    {
      "x": -26,
      "y": 25,
      "z": 2,
      "name": "Rock_Magma_Cooled",
      "rotation": 1
    },
    {
      "x": -26,
      "y": 26,
      "z": 2,
      "name": "Rock_Magma_Cooled",
      "rotation": 1
    },
    {
      "x": -26,
      "y": 27,
      "z": 2,
      "name": "Rock_Magma_Cooled",
      "rotation": 1
    },
    {
      "x": -26,
      "y": 28,
      "z": 2,
      "name": "Rock_Magma_Cooled",
      "rotation": 1
    },
    {
      "x": -26,
      "y": 29,
      "z": 2,
      "name": "Rock_Magma_Cooled",
      "rotation": 1
    },
    {
      "x": -26,
      "y": 30,
      "z": 2,
      "name": "Plant_Moss_Rug_Pink",
      "support": 15
    },
    {
      "x": -26,
      "y": 26,
      "z": 3,
      "name": "Ore_Adamantite_Magma_Cracked",
      "rotation": 1
    },
    {
      "x": -26,
      "y": 27,
      "z": 3,
      "name": "Rock_Magma_Cooled",
      "rotation": 1
    },
    {
      "x": -26,
      "y": 26,
      "z": 4,
      "name": "Rock_Magma_Cooled"
    },
    {
      "x": -25,
      "y": 0,
      "z": -8,
      "name": "Soil_Ash"
    },
    {
      "x": -25,
      "y": 0,
      "z": -7,
      "name": "Soil_Ash"
    },
    {
      "x": -25,
      "y": 0,
      "z": -6,
      "name": "Soil_Sand_Ashen"
    },
    {
      "x": -25,
      "y": 0,
      "z": -5,
      "name": "Soil_Ash"
    },
    {
      "x": -25,
      "y": 0,
      "z": -4,
      "name": "Soil_Sand_Ashen"
    },
    {
      "x": -25,
      "y": 0,
      "z": -3,
      "name": "Soil_Ash"
    },
    {
      "x": -25,
      "y": 1,
      "z": -3,
      "name": "Soil_Ash"
    },
    {
      "x": -25,
      "y": 24,
      "z": -3,
      "name": "Plant_Vine_Wall_Poisoned",
      "support": 15,
      "rotation": 2
    },
    {
      "x": -25,
      "y": 0,
      "z": -2,
      "name": "Soil_Sand_Ashen"
    },
    {
      "x": -25,
      "y": 1,
      "z": -2,
      "name": "Soil_Ash"
    },
    {
      "x": -25,
      "y": 24,
      "z": -2,
      "name": "Ore_Adamantite_Magma_Cracked"
    },
    {
      "x": -25,
      "y": 26,
      "z": -2,
      "name": "Rock_Magma_Cooled"
    },
    {
      "x": -25,
      "y": 27,
      "z": -2,
      "name": "Rock_Magma_Cooled"
    },
    {
      "x": -25,
      "y": 0,
      "z": -1,
      "name": "Soil_Ash"
    },
    {
      "x": -25,
      "y": 1,
      "z": -1,
      "name": "Soil_Ash"
    },
    {
      "x": -25,
      "y": 23,
      "z": -1,
      "name": "Ore_Adamantite_Magma"
    },
    {
      "x": -25,
      "y": 24,
      "z": -1,
      "name": "Rock_Magma_Cooled"
    },
    {
      "x": -25,
      "y": 25,
      "z": -1,
      "name": "Ore_Adamantite_Magma_Cracked"
    },
    {
      "x": -25,
      "y": 26,
      "z": -1,
      "name": "Ore_Adamantite_Magma_Cracked"
    },
    {
      "x": -25,
      "y": 27,
      "z": -1,
      "name": "Ore_Adamantite_Magma_Cracked"
    },
    {
      "x": -25,
      "y": 28,
      "z": -1,
      "name": "Rock_Magma_Cooled"
    },
    {
      "x": -25,
      "y": 0,
      "z": 0,
      "name": "Soil_Ash"
    },
    {
      "x": -25,
      "y": 1,
      "z": 0,
      "name": "Soil_Sand_Ashen"
    },
    {
      "x": -25,
      "y": 24,
      "z": 0,
      "name": "Ore_Adamantite_Magma_Cracked"
    },
    {
      "x": -25,
      "y": 25,
      "z": 0,
      "name": "Rock_Magma_Cooled"
    },
    {
      "x": -25,
      "y": 26,
      "z": 0,
      "name": "Plant_Vine_Wall_Poisoned",
      "support": 15,
      "rotation": 1
    },
    {
      "x": -25,
      "y": 27,
      "z": 0,
      "name": "Rock_Magma_Cooled",
      "rotation": 1
    },
    {
      "x": -25,
      "y": 28,
      "z": 0,
      "name": "Rock_Magma_Cooled",
      "rotation": 1
    },
    {
      "x": -25,
      "y": 29,
      "z": 0,
      "name": "Rock_Magma_Cooled",
      "rotation": 1
    },
    {
      "x": -25,
      "y": 0,
      "z": 1,
      "name": "Soil_Ash"
    },
    {
      "x": -25,
      "y": 1,
      "z": 1,
      "name": "Soil_Sand_Ashen"
    },
    {
      "x": -25,
      "y": 24,
      "z": 1,
      "name": "Rock_Magma_Cooled"
    },
    {
      "x": -25,
      "y": 25,
      "z": 1,
      "name": "Rock_Magma_Cooled",
      "rotation": 1
    },
    {
      "x": -25,
      "y": 26,
      "z": 1,
      "name": "Rock_Magma_Cooled",
      "rotation": 1
    },
    {
      "x": -25,
      "y": 27,
      "z": 1,
      "name": "Ore_Adamantite_Magma_Cracked",
      "rotation": 1
    },
    {
      "x": -25,
      "y": 28,
      "z": 1,
      "name": "Rock_Magma_Cooled",
      "rotation": 1
    },
    {
      "x": -25,
      "y": 0,
      "z": 2,
      "name": "Soil_Sand_Ashen"
    },
    {
      "x": -25,
      "y": 1,
      "z": 2,
      "name": "Soil_Sand_Ashen"
    },
    {
      "x": -25,
      "y": 24,
      "z": 2,
      "name": "Rock_Magma_Cooled"
    },
    {
      "x": -25,
      "y": 25,
      "z": 2,
      "name": "Rock_Magma_Cooled",
      "rotation": 1
    },
    {
      "x": -25,
      "y": 26,
      "z": 2,
      "name": "Rock_Magma_Cooled",
      "rotation": 1
    },
    {
      "x": -25,
      "y": 27,
      "z": 2,
      "name": "Ore_Adamantite_Magma_Cracked",
      "rotation": 1
    },
    {
      "x": -25,
      "y": 28,
      "z": 2,
      "name": "Rock_Magma_Cooled",
      "rotation": 1
    },
    {
      "x": -25,
      "y": 0,
      "z": 3,
      "name": "Soil_Ash"
    },
    {
      "x": -25,
      "y": 1,
      "z": 3,
      "name": "Soil_Ash"
    },
    {
      "x": -25,
      "y": 24,
      "z": 3,
      "name": "Ore_Adamantite_Magma_Cracked"
    },
    {
      "x": -25,
      "y": 25,
      "z": 3,
      "name": "Rock_Magma_Cooled",
      "rotation": 1
    },
    {
      "x": -25,
      "y": 26,
      "z": 3,
      "name": "Ore_Adamantite_Magma_Cracked",
      "rotation": 1
    },
    {
      "x": -25,
      "y": 27,
      "z": 3,
      "name": "Rock_Magma_Cooled",
      "rotation": 1
    },
    {
      "x": -25,
      "y": 25,
      "z": 4,
      "name": "Ore_Adamantite_Magma_Cracked"
    },
    {
      "x": -25,
      "y": 26,
      "z": 4,
      "name": "Ore_Adamantite_Magma_Cracked"
    },
    {
      "x": -25,
      "y": 27,
      "z": 4,
      "name": "Rock_Magma_Cooled"
    },
    {
      "x": -25,
      "y": 26,
      "z": 5,
      "name": "Rock_Magma_Cooled"
    },
    {
      "x": -25,
      "y": 27,
      "z": 5,
      "name": "Plant_Vine_Wall_Poisoned",
      "support": 15
    },
    {
      "x": -24,
      "y": 0,
      "z": -10,
      "name": "Soil_Ash"
    },
    {
      "x": -24,
      "y": 0,
      "z": -9,
      "name": "Soil_Sand_Ashen"
    },
    {
      "x": -24,
      "y": 0,
      "z": -8,
      "name": "Soil_Ash"
    },
    {
      "x": -24,
      "y": 0,
      "z": -7,
      "name": "Soil_Ash"
    },
    {
      "x": -24,
      "y": 0,
      "z": -6,
      "name": "Soil_Ash"
    },
    {
      "x": -24,
      "y": 1,
      "z": -6,
      "name": "Soil_Sand_Ashen"
    },
    {
      "x": -24,
      "y": 0,
      "z": -5,
      "name": "Soil_Ash"
    },
    {
      "x": -24,
      "y": 1,
      "z": -5,
      "name": "Soil_Ash"
    },
    {
      "x": -24,
      "y": 0,
      "z": -4,
      "name": "Soil_Ash"
    },
    {
      "x": -24,
      "y": 1,
      "z": -4,
      "name": "Soil_Ash"
    },
    {
      "x": -24,
      "y": 0,
      "z": -3,
      "name": "Soil_Ash"
    },
    {
      "x": -24,
      "y": 1,
      "z": -3,
      "name": "Soil_Sand_Ashen"
    },
    {
      "x": -24,
      "y": 0,
      "z": -2,
      "name": "Soil_Ash"
    },
    {
      "x": -24,
      "y": 1,
      "z": -2,
      "name": "Soil_Sand_Ashen"
    },
    {
      "x": -24,
      "y": 2,
      "z": -2,
      "name": "Soil_Sand_Ashen"
    },
    {
      "x": -24,
      "y": 23,
      "z": -2,
      "name": "Rock_Magma_Cooled"
    },
    {
      "x": -24,
      "y": 24,
      "z": -2,
      "name": "Ore_Adamantite_Magma_Cracked"
    },
    {
      "x": -24,
      "y": 25,
      "z": -2,
      "name": "Rock_Magma_Cooled"
    },
    {
      "x": -24,
      "y": 0,
      "z": -1,
      "name": "Soil_Ash"
    },
    {
      "x": -24,
      "y": 1,
      "z": -1,
      "name": "Soil_Sand_Ashen"
    },
    {
      "x": -24,
      "y": 2,
      "z": -1,
      "name": "Soil_Sand_Ashen"
    },
    {
      "x": -24,
      "y": 22,
      "z": -1,
      "name": "Rock_Magma_Cooled"
    },
    {
      "x": -24,
      "y": 23,
      "z": -1,
      "name": "Ore_Adamantite_Magma_Cracked"
    },
    {
      "x": -24,
      "y": 24,
      "z": -1,
      "name": "Ore_Adamantite_Magma_Cracked"
    },
    {
      "x": -24,
      "y": 25,
      "z": -1,
      "name": "Ore_Adamantite_Magma_Cracked"
    },
    {
      "x": -24,
      "y": 26,
      "z": -1,
      "name": "Rock_Magma_Cooled"
    },
    {
      "x": -24,
      "y": 0,
      "z": 0,
      "name": "Soil_Sand_Ashen"
    },
    {
      "x": -24,
      "y": 1,
      "z": 0,
      "name": "Soil_Sand_Ashen"
    },
    {
      "x": -24,
      "y": 2,
      "z": 0,
      "name": "Soil_Sand_Ashen"
    },
    {
      "x": -24,
      "y": 22,
      "z": 0,
      "name": "Rock_Magma_Cooled"
    },
    {
      "x": -24,
      "y": 23,
      "z": 0,
      "name": "Rock_Magma_Cooled"
    },
    {
      "x": -24,
      "y": 24,
      "z": 0,
      "name": "Rock_Magma_Cooled"
    },
    {
      "x": -24,
      "y": 25,
      "z": 0,
      "name": "Rock_Magma_Cooled"
    },
    {
      "x": -24,
      "y": 26,
      "z": 0,
      "name": "Rock_Magma_Cooled"
    },
    {
      "x": -24,
      "y": 27,
      "z": 0,
      "name": "Plant_Vine_Wall_Poisoned",
      "support": 15,
      "rotation": 1
    },
    {
      "x": -24,
      "y": 0,
      "z": 1,
      "name": "Soil_Sand_Ashen"
    },
    {
      "x": -24,
      "y": 1,
      "z": 1,
      "name": "Soil_Sand_Ashen"
    },
    {
      "x": -24,
      "y": 2,
      "z": 1,
      "name": "Soil_Sand_Ashen"
    },
    {
      "x": -24,
      "y": 22,
      "z": 1,
      "name": "Rock_Magma_Cooled"
    },
    {
      "x": -24,
      "y": 23,
      "z": 1,
      "name": "Rock_Magma_Cooled"
    },
    {
      "x": -24,
      "y": 24,
      "z": 1,
      "name": "Ore_Adamantite_Magma_Cracked"
    },
    {
      "x": -24,
      "y": 25,
      "z": 1,
      "name": "Ore_Adamantite_Magma"
    },
    {
      "x": -24,
      "y": 26,
      "z": 1,
      "name": "Rock_Magma_Cooled",
      "rotation": 1
    },
    {
      "x": -24,
      "y": 27,
      "z": 1,
      "name": "Rock_Magma_Cooled",
      "rotation": 1
    },
    {
      "x": -24,
      "y": 28,
      "z": 1,
      "name": "Ore_Adamantite_Magma_Cracked",
      "rotation": 1
    },
    {
      "x": -24,
      "y": 0,
      "z": 2,
      "name": "Soil_Ash"
    },
    {
      "x": -24,
      "y": 1,
      "z": 2,
      "name": "Soil_Sand_Ashen"
    },
    {
      "x": -24,
      "y": 2,
      "z": 2,
      "name": "Soil_Sand_Ashen"
    },
    {
      "x": -24,
      "y": 22,
      "z": 2,
      "name": "Ore_Adamantite_Magma_Cracked"
    },
    {
      "x": -24,
      "y": 23,
      "z": 2,
      "name": "Rock_Magma_Cooled"
    },
    {
      "x": -24,
      "y": 24,
      "z": 2,
      "name": "Ore_Adamantite_Magma_Cracked"
    },
    {
      "x": -24,
      "y": 25,
      "z": 2,
      "name": "Rock_Magma_Cooled",
      "rotation": 1
    },
    {
      "x": -24,
      "y": 26,
      "z": 2,
      "name": "Rock_Magma_Cooled",
      "rotation": 1
    },
    {
      "x": -24,
      "y": 0,
      "z": 3,
      "name": "Soil_Sand_Ashen"
    },
    {
      "x": -24,
      "y": 1,
      "z": 3,
      "name": "Soil_Sand_Ashen"
    },
    {
      "x": -24,
      "y": 2,
      "z": 3,
      "name": "Soil_Sand_Ashen"
    },
    {
      "x": -24,
      "y": 22,
      "z": 3,
      "name": "Ore_Adamantite_Magma_Cracked"
    },
    {
      "x": -24,
      "y": 23,
      "z": 3,
      "name": "Ore_Adamantite_Magma_Cracked"
    },
    {
      "x": -24,
      "y": 24,
      "z": 3,
      "name": "Rock_Magma_Cooled"
    },
    {
      "x": -24,
      "y": 25,
      "z": 3,
      "name": "Rock_Magma_Cooled",
      "rotation": 1
    },
    {
      "x": -24,
      "y": 26,
      "z": 3,
      "name": "Rock_Magma_Cooled",
      "rotation": 1
    },
    {
      "x": -24,
      "y": 0,
      "z": 4,
      "name": "Soil_Sand_Ashen"
    },
    {
      "x": -24,
      "y": 1,
      "z": 4,
      "name": "Soil_Sand_Ashen"
    },
    {
      "x": -24,
      "y": 24,
      "z": 4,
      "name": "Ore_Adamantite_Magma_Cracked"
    },
    {
      "x": -24,
      "y": 25,
      "z": 4,
      "name": "Ore_Adamantite_Magma"
    },
    {
      "x": -24,
      "y": 26,
      "z": 4,
      "name": "Rock_Magma_Cooled"
    },
    {
      "x": -24,
      "y": 0,
      "z": 5,
      "name": "Soil_Sand_Ashen"
    },
    {
      "x": -24,
      "y": 1,
      "z": 5,
      "name": "Soil_Ash"
    },
    {
      "x": -24,
      "y": 25,
      "z": 5,
      "name": "Plant_Vine_Wall_Poisoned",
      "support": 15
    },
    {
      "x": -23,
      "y": 0,
      "z": -11,
      "name": "Soil_Ash"
    },
    {
      "x": -23,
      "y": 0,
      "z": -10,
      "name": "Soil_Ash"
    },
    {
      "x": -23,
      "y": 0,
      "z": -9,
      "name": "Soil_Ash"
    },
    {
      "x": -23,
      "y": 1,
      "z": -9,
      "name": "Soil_Ash"
    },
    {
      "x": -23,
      "y": 0,
      "z": -8,
      "name": "Soil_Ash"
    },
    {
      "x": -23,
      "y": 1,
      "z": -8,
      "name": "Soil_Ash"
    },
    {
      "x": -23,
      "y": 0,
      "z": -7,
      "name": "Soil_Ash"
    },
    {
      "x": -23,
      "y": 1,
      "z": -7,
      "name": "Soil_Ash"
    },
    {
      "x": -23,
      "y": 0,
      "z": -6,
      "name": "Soil_Ash"
    },
    {
      "x": -23,
      "y": 1,
      "z": -6,
      "name": "Soil_Ash"
    },
    {
      "x": -23,
      "y": 2,
      "z": -6,
      "name": "Soil_Sand_Ashen"
    },
    {
      "x": -23,
      "y": 0,
      "z": -5,
      "name": "Soil_Ash"
    },
    {
      "x": -23,
      "y": 1,
      "z": -5,
      "name": "Soil_Ash"
    },
    {
      "x": -23,
      "y": 2,
      "z": -5,
      "name": "Soil_Sand_Ashen"
    },
    {
      "x": -23,
      "y": 0,
      "z": -4,
      "name": "Soil_Ash"
    },
    {
      "x": -23,
      "y": 1,
      "z": -4,
      "name": "Soil_Sand_Ashen"
    },
    {
      "x": -23,
      "y": 2,
      "z": -4,
      "name": "Soil_Sand_Ashen"
    },
    {
      "x": -23,
      "y": 0,
      "z": -3,
      "name": "Soil_Ash"
    },
    {
      "x": -23,
      "y": 1,
      "z": -3,
      "name": "Soil_Sand_Ashen"
    },
    {
      "x": -23,
      "y": 2,
      "z": -3,
      "name": "Soil_Sand_Ashen"
    },
    {
      "x": -23,
      "y": 22,
      "z": -3,
      "name": "Plant_Vine_Wall_Poisoned",
      "support": 15,
      "rotation": 2
    },
    {
      "x": -23,
      "y": 23,
      "z": -3,
      "name": "Rock_Magma_Cooled"
    },
    {
      "x": -23,
      "y": 0,
      "z": -2,
      "name": "Soil_Ash"
    },
    {
      "x": -23,
      "y": 1,
      "z": -2,
      "name": "Soil_Sand_Ashen"
    },
    {
      "x": -23,
      "y": 2,
      "z": -2,
      "name": "Soil_Sand_Ashen"
    },
    {
      "x": -23,
      "y": 3,
      "z": -2,
      "name": "Soil_Sand_Ashen"
    },
    {
      "x": -23,
      "y": 22,
      "z": -2,
      "name": "Ore_Adamantite_Magma_Cracked"
    },
    {
      "x": -23,
      "y": 23,
      "z": -2,
      "name": "Rock_Magma_Cooled"
    },
    {
      "x": -23,
      "y": 24,
      "z": -2,
      "name": "Rock_Magma_Cooled"
    },
    {
      "x": -23,
      "y": 0,
      "z": -1,
      "name": "Soil_Sand_Ashen"
    },
    {
      "x": -23,
      "y": 1,
      "z": -1,
      "name": "Soil_Sand_Ashen"
    },
    {
      "x": -23,
      "y": 2,
      "z": -1,
      "name": "Soil_Sand_Ashen"
    },
    {
      "x": -23,
      "y": 3,
      "z": -1,
      "name": "Soil_Sand_Ashen"
    },
    {
      "x": -23,
      "y": 21,
      "z": -1,
      "name": "Ore_Adamantite_Magma_Cracked"
    },
    {
      "x": -23,
      "y": 22,
      "z": -1,
      "name": "Rock_Magma_Cooled"
    },
    {
      "x": -23,
      "y": 23,
      "z": -1,
      "name": "Rock_Magma_Cooled"
    },
    {
      "x": -23,
      "y": 24,
      "z": -1,
      "name": "Ore_Adamantite_Magma_Cracked"
    },
    {
      "x": -23,
      "y": 0,
      "z": 0,
      "name": "Soil_Sand_Ashen"
    },
    {
      "x": -23,
      "y": 1,
      "z": 0,
      "name": "Soil_Sand_Ashen"
    },
    {
      "x": -23,
      "y": 2,
      "z": 0,
      "name": "Soil_Sand_Ashen"
    },
    {
      "x": -23,
      "y": 3,
      "z": 0,
      "name": "Soil_Sand_Ashen"
    },
    {
      "x": -23,
      "y": 21,
      "z": 0,
      "name": "Rock_Magma_Cooled"
    },
    {
      "x": -23,
      "y": 22,
      "z": 0,
      "name": "Ore_Adamantite_Magma_Cracked"
    },
    {
      "x": -23,
      "y": 23,
      "z": 0,
      "name": "Ore_Adamantite_Magma_Cracked"
    },
    {
      "x": -23,
      "y": 24,
      "z": 0,
      "name": "Rock_Magma_Cooled"
    },
    {
      "x": -23,
      "y": 25,
      "z": 0,
      "name": "Ore_Adamantite_Magma_Cracked"
    },
    {
      "x": -23,
      "y": 0,
      "z": 1,
      "name": "Soil_Sand_Ashen"
    },
    {
      "x": -23,
      "y": 1,
      "z": 1,
      "name": "Soil_Sand_Ashen"
    },
    {
      "x": -23,
      "y": 2,
      "z": 1,
      "name": "Soil_Sand_Ashen"
    },
    {
      "x": -23,
      "y": 3,
      "z": 1,
      "name": "Soil_Sand_Ashen"
    },
    {
      "x": -23,
      "y": 21,
      "z": 1,
      "name": "Rock_Magma_Cooled"
    },
    {
      "x": -23,
      "y": 22,
      "z": 1,
      "name": "Ore_Adamantite_Magma_Cracked"
    },
    {
      "x": -23,
      "y": 23,
      "z": 1,
      "name": "Ore_Adamantite_Magma_Cracked"
    },
    {
      "x": -23,
      "y": 24,
      "z": 1,
      "name": "Ore_Adamantite_Magma_Cracked"
    },
    {
      "x": -23,
      "y": 25,
      "z": 1,
      "name": "Ore_Adamantite_Magma_Cracked"
    },
    {
      "x": -23,
      "y": 0,
      "z": 2,
      "name": "Soil_Sand_Ashen"
    },
    {
      "x": -23,
      "y": 1,
      "z": 2,
      "name": "Soil_Sand_Ashen"
    },
    {
      "x": -23,
      "y": 2,
      "z": 2,
      "name": "Soil_Sand_Ashen"
    },
    {
      "x": -23,
      "y": 3,
      "z": 2,
      "name": "Soil_Sand_Ashen"
    },
    {
      "x": -23,
      "y": 21,
      "z": 2,
      "name": "Rock_Magma_Cooled"
    },
    {
      "x": -23,
      "y": 22,
      "z": 2,
      "name": "Ore_Adamantite_Magma_Cracked"
    },
    {
      "x": -23,
      "y": 23,
      "z": 2,
      "name": "Ore_Adamantite_Magma_Cracked"
    },
    {
      "x": -23,
      "y": 24,
      "z": 2,
      "name": "Ore_Adamantite_Magma_Cracked"
    },
    {
      "x": -23,
      "y": 25,
      "z": 2,
      "name": "Rock_Magma_Cooled",
      "rotation": 1
    },
    {
      "x": -23,
      "y": 26,
      "z": 2,
      "name": "Rock_Magma_Cooled",
      "rotation": 1
    },
    {
      "x": -23,
      "y": 0,
      "z": 3,
      "name": "Soil_Sand_Ashen"
    },
    {
      "x": -23,
      "y": 1,
      "z": 3,
      "name": "Soil_Sand_Ashen"
    },
    {
      "x": -23,
      "y": 2,
      "z": 3,
      "name": "Soil_Sand_Ashen"
    },
    {
      "x": -23,
      "y": 3,
      "z": 3,
      "name": "Soil_Sand_Ashen"
    },
    {
      "x": -23,
      "y": 21,
      "z": 3,
      "name": "Ore_Adamantite_Magma_Cracked"
    },
    {
      "x": -23,
      "y": 22,
      "z": 3,
      "name": "Ore_Adamantite_Magma_Cracked"
    },
    {
      "x": -23,
      "y": 23,
      "z": 3,
      "name": "Rock_Magma_Cooled"
    },
    {
      "x": -23,
      "y": 24,
      "z": 3,
      "name": "Rock_Magma_Cooled"
    },
    {
      "x": -23,
      "y": 25,
      "z": 3,
      "name": "Rock_Magma_Cooled",
      "rotation": 1
    },
    {
      "x": -23,
      "y": 26,
      "z": 3,
      "name": "Rock_Magma_Cooled",
      "rotation": 1
    },
    {
      "x": -23,
      "y": 0,
      "z": 4,
      "name": "Soil_Sand_Ashen"
    },
    {
      "x": -23,
      "y": 1,
      "z": 4,
      "name": "Soil_Sand_Ashen"
    },
    {
      "x": -23,
      "y": 2,
      "z": 4,
      "name": "Soil_Sand_Ashen"
    },
    {
      "x": -23,
      "y": 22,
      "z": 4,
      "name": "Ore_Adamantite_Magma_Cracked"
    },
    {
      "x": -23,
      "y": 23,
      "z": 4,
      "name": "Ore_Adamantite_Magma_Cracked"
    },
    {
      "x": -23,
      "y": 25,
      "z": 4,
      "name": "Rock_Magma_Cooled"
    },
    {
      "x": -23,
      "y": 0,
      "z": 5,
      "name": "Soil_Sand_Ashen"
    },
    {
      "x": -23,
      "y": 1,
      "z": 5,
      "name": "Soil_Sand_Ashen"
    },
    {
      "x": -23,
      "y": 2,
      "z": 5,
      "name": "Soil_Sand_Ashen"
    },
    {
      "x": -23,
      "y": 25,
      "z": 5,
      "name": "Plant_Vine_Wall_Poisoned",
      "support": 15
    },
    {
      "x": -23,
      "y": 0,
      "z": 6,
      "name": "Soil_Sand_Ashen"
    },
    {
      "x": -23,
      "y": 1,
      "z": 6,
      "name": "Soil_Ash"
    },
    {
      "x": -22,
      "y": 0,
      "z": -14,
      "name": "Soil_Ash"
    },
    {
      "x": -22,
      "y": 0,
      "z": -13,
      "name": "Soil_Ash"
    },
    {
      "x": -22,
      "y": 0,
      "z": -12,
      "name": "Soil_Ash"
    },
    {
      "x": -22,
      "y": 0,
      "z": -11,
      "name": "Soil_Ash"
    },
    {
      "x": -22,
      "y": 1,
      "z": -11,
      "name": "Soil_Ash"
    },
    {
      "x": -22,
      "y": 0,
      "z": -10,
      "name": "Soil_Ash"
    },
    {
      "x": -22,
      "y": 1,
      "z": -10,
      "name": "Soil_Ash"
    },
    {
      "x": -22,
      "y": 0,
      "z": -9,
      "name": "Soil_Ash"
    },
    {
      "x": -22,
      "y": 1,
      "z": -9,
      "name": "Soil_Ash"
    },
    {
      "x": -22,
      "y": 2,
      "z": -9,
      "name": "Soil_Sand_Ashen"
    },
    {
      "x": -22,
      "y": 0,
      "z": -8,
      "name": "Soil_Ash"
    },
    {
      "x": -22,
      "y": 1,
      "z": -8,
      "name": "Soil_Ash"
    },
    {
      "x": -22,
      "y": 2,
      "z": -8,
      "name": "Soil_Ash"
    },
    {
      "x": -22,
      "y": 0,
      "z": -7,
      "name": "Soil_Ash"
    },
    {
      "x": -22,
      "y": 1,
      "z": -7,
      "name": "Soil_Ash"
    },
    {
      "x": -22,
      "y": 2,
      "z": -7,
      "name": "Soil_Sand_Ashen"
    },
    {
      "x": -22,
      "y": 3,
      "z": -7,
      "name": "Plant_Flower_Bushy_Purple"
    },
    {
      "x": -22,
      "y": 0,
      "z": -6,
      "name": "Soil_Ash"
    },
    {
      "x": -22,
      "y": 1,
      "z": -6,
      "name": "Soil_Sand_Ashen"
    },
    {
      "x": -22,
      "y": 2,
      "z": -6,
      "name": "Soil_Sand_Ashen"
    },
    {
      "x": -22,
      "y": 3,
      "z": -6,
      "name": "Soil_Sand_Ashen"
    },
    {
      "x": -22,
      "y": 0,
      "z": -5,
      "name": "Soil_Ash"
    },
    {
      "x": -22,
      "y": 1,
      "z": -5,
      "name": "Soil_Ash"
    },
    {
      "x": -22,
      "y": 2,
      "z": -5,
      "name": "Soil_Sand_Ashen"
    },
    {
      "x": -22,
      "y": 3,
      "z": -5,
      "name": "Soil_Sand_Ashen"
    },
    {
      "x": -22,
      "y": 0,
      "z": -4,
      "name": "Soil_Ash"
    },
    {
      "x": -22,
      "y": 1,
      "z": -4,
      "name": "Soil_Sand_Ashen"
    },
    {
      "x": -22,
      "y": 2,
      "z": -4,
      "name": "Soil_Sand_Ashen"
    },
    {
      "x": -22,
      "y": 3,
      "z": -4,
      "name": "Soil_Sand_Ashen"
    },
    {
      "x": -22,
      "y": 0,
      "z": -3,
      "name": "Soil_Ash"
    },
    {
      "x": -22,
      "y": 1,
      "z": -3,
      "name": "Soil_Sand_Ashen"
    },
    {
      "x": -22,
      "y": 2,
      "z": -3,
      "name": "Soil_Sand_Ashen"
    },
    {
      "x": -22,
      "y": 3,
      "z": -3,
      "name": "Soil_Sand_Ashen"
    },
    {
      "x": -22,
      "y": 0,
      "z": -2,
      "name": "Soil_Ash"
    },
    {
      "x": -22,
      "y": 1,
      "z": -2,
      "name": "Soil_Sand_Ashen"
    },
    {
      "x": -22,
      "y": 2,
      "z": -2,
      "name": "Soil_Sand_Ashen"
    },
    {
      "x": -22,
      "y": 3,
      "z": -2,
      "name": "Soil_Sand_Ashen"
    },
    {
      "x": -22,
      "y": 22,
      "z": -2,
      "name": "Rock_Magma_Cooled"
    },
    {
      "x": -22,
      "y": 23,
      "z": -2,
      "name": "Ore_Adamantite_Magma_Cracked"
    },
    {
      "x": -22,
      "y": 0,
      "z": -1,
      "name": "Soil_Ash"
    },
    {
      "x": -22,
      "y": 1,
      "z": -1,
      "name": "Soil_Sand_Ashen"
    },
    {
      "x": -22,
      "y": 2,
      "z": -1,
      "name": "Soil_Sand_Ashen"
    },
    {
      "x": -22,
      "y": 3,
      "z": -1,
      "name": "Soil_Sand_Ashen"
    },
    {
      "x": -22,
      "y": 4,
      "z": -1,
      "name": "Soil_Sand_Ashen"
    },
    {
      "x": -22,
      "y": 21,
      "z": -1,
      "name": "Ore_Adamantite_Magma_Cracked"
    },
    {
      "x": -22,
      "y": 22,
      "z": -1,
      "name": "Ore_Adamantite_Magma_Cracked"
    },
    {
      "x": -22,
      "y": 23,
      "z": -1,
      "name": "Ore_Adamantite_Magma_Cracked"
    },
    {
      "x": -22,
      "y": 0,
      "z": 0,
      "name": "Soil_Sand_Ashen"
    },
    {
      "x": -22,
      "y": 1,
      "z": 0,
      "name": "Soil_Sand_Ashen"
    },
    {
      "x": -22,
      "y": 2,
      "z": 0,
      "name": "Soil_Sand_Ashen"
    },
    {
      "x": -22,
      "y": 3,
      "z": 0,
      "name": "Soil_Sand_Ashen"
    },
    {
      "x": -22,
      "y": 21,
      "z": 0,
      "name": "Rock_Magma_Cooled"
    },
    {
      "x": -22,
      "y": 22,
      "z": 0,
      "name": "Ore_Adamantite_Magma_Cracked"
    },
    {
      "x": -22,
      "y": 23,
      "z": 0,
      "name": "Ore_Adamantite_Magma_Cracked"
    },
    {
      "x": -22,
      "y": 0,
      "z": 1,
      "name": "Soil_Sand_Ashen"
    },
    {
      "x": -22,
      "y": 1,
      "z": 1,
      "name": "Soil_Sand_Ashen"
    },
    {
      "x": -22,
      "y": 2,
      "z": 1,
      "name": "Soil_Sand_Ashen"
    },
    {
      "x": -22,
      "y": 3,
      "z": 1,
      "name": "Soil_Sand_Ashen"
    },
    {
      "x": -22,
      "y": 21,
      "z": 1,
      "name": "Rock_Magma_Cooled"
    },
    {
      "x": -22,
      "y": 22,
      "z": 1,
      "name": "Ore_Adamantite_Magma_Cracked"
    },
    {
      "x": -22,
      "y": 23,
      "z": 1,
      "name": "Ore_Adamantite_Magma_Cracked"
    },
    {
      "x": -22,
      "y": 0,
      "z": 2,
      "name": "Soil_Sand_Ashen"
    },
    {
      "x": -22,
      "y": 1,
      "z": 2,
      "name": "Soil_Sand_Ashen"
    },
    {
      "x": -22,
      "y": 2,
      "z": 2,
      "name": "Soil_Sand_Ashen"
    },
    {
      "x": -22,
      "y": 3,
      "z": 2,
      "name": "Soil_Sand_Ashen"
    },
    {
      "x": -22,
      "y": 21,
      "z": 2,
      "name": "Rock_Magma_Cooled"
    },
    {
      "x": -22,
      "y": 22,
      "z": 2,
      "name": "Rock_Magma_Cooled"
    },
    {
      "x": -22,
      "y": 23,
      "z": 2,
      "name": "Rock_Magma_Cooled"
    },
    {
      "x": -22,
      "y": 24,
      "z": 2,
      "name": "Ore_Adamantite_Magma_Cracked"
    },
    {
      "x": -22,
      "y": 0,
      "z": 3,
      "name": "Soil_Sand_Ashen"
    },
    {
      "x": -22,
      "y": 1,
      "z": 3,
      "name": "Soil_Sand_Ashen"
    },
    {
      "x": -22,
      "y": 2,
      "z": 3,
      "name": "Soil_Sand_Ashen"
    },
    {
      "x": -22,
      "y": 3,
      "z": 3,
      "name": "Soil_Sand_Ashen"
    },
    {
      "x": -22,
      "y": 21,
      "z": 3,
      "name": "Rock_Magma_Cooled"
    },
    {
      "x": -22,
      "y": 22,
      "z": 3,
      "name": "Ore_Adamantite_Magma_Cracked"
    },
    {
      "x": -22,
      "y": 23,
      "z": 3,
      "name": "Rock_Magma_Cooled"
    },
    {
      "x": -22,
      "y": 24,
      "z": 3,
      "name": "Ore_Adamantite_Magma_Cracked"
    },
    {
      "x": -22,
      "y": 0,
      "z": 4,
      "name": "Soil_Sand_Ashen"
    },
    {
      "x": -22,
      "y": 1,
      "z": 4,
      "name": "Soil_Sand_Ashen"
    },
    {
      "x": -22,
      "y": 2,
      "z": 4,
      "name": "Soil_Sand_Ashen"
    },
    {
      "x": -22,
      "y": 3,
      "z": 4,
      "name": "Soil_Sand_Ashen"
    },
    {
      "x": -22,
      "y": 21,
      "z": 4,
      "name": "Rock_Magma_Cooled"
    },
    {
      "x": -22,
      "y": 22,
      "z": 4,
      "name": "Ore_Adamantite_Magma_Cracked"
    },
    {
      "x": -22,
      "y": 23,
      "z": 4,
      "name": "Rock_Magma_Cooled"
    },
    {
      "x": -22,
      "y": 24,
      "z": 4,
      "name": "Rock_Magma_Cooled"
    },
    {
      "x": -22,
      "y": 0,
      "z": 5,
      "name": "Soil_Ash"
    },
    {
      "x": -22,
      "y": 1,
      "z": 5,
      "name": "Soil_Sand_Ashen"
    },
    {
      "x": -22,
      "y": 2,
      "z": 5,
      "name": "Soil_Sand_Ashen"
    },
    {
      "x": -22,
      "y": 3,
      "z": 5,
      "name": "Soil_Sand_Ashen"
    },
    {
      "x": -22,
      "y": 22,
      "z": 5,
      "name": "Ore_Adamantite_Magma_Cracked"
    },
    {
      "x": -22,
      "y": 24,
      "z": 5,
      "name": "Plant_Vine_Wall_Poisoned",
      "support": 15
    },
    {
      "x": -22,
      "y": 0,
      "z": 6,
      "name": "Soil_Sand_Ashen"
    },
    {
      "x": -22,
      "y": 1,
      "z": 6,
      "name": "Soil_Sand_Ashen"
    },
    {
      "x": -22,
      "y": 0,
      "z": 7,
      "name": "Soil_Sand_Ashen"
    },
    {
      "x": -22,
      "y": 1,
      "z": 7,
      "name": "Soil_Sand_Ashen"
    },
    {
      "x": -21,
      "y": 0,
      "z": -15,
      "name": "Soil_Ash"
    },
    {
      "x": -21,
      "y": 0,
      "z": -14,
      "name": "Soil_Sand_Ashen"
    },
    {
      "x": -21,
      "y": 0,
      "z": -13,
      "name": "Soil_Ash"
    },
    {
      "x": -21,
      "y": 1,
      "z": -13,
      "name": "Soil_Ash"
    },
    {
      "x": -21,
      "y": 0,
      "z": -12,
      "name": "Soil_Ash"
    },
    {
      "x": -21,
      "y": 1,
      "z": -12,
      "name": "Soil_Ash"
    },
    {
      "x": -21,
      "y": 0,
      "z": -11,
      "name": "Soil_Ash"
    },
    {
      "x": -21,
      "y": 1,
      "z": -11,
      "name": "Soil_Ash"
    },
    {
      "x": -21,
      "y": 0,
      "z": -10,
      "name": "Soil_Ash"
    },
    {
      "x": -21,
      "y": 1,
      "z": -10,
      "name": "Soil_Ash"
    },
    {
      "x": -21,
      "y": 2,
      "z": -10,
      "name": "Soil_Ash"
    },
    {
      "x": -21,
      "y": 0,
      "z": -9,
      "name": "Soil_Ash"
    },
    {
      "x": -21,
      "y": 1,
      "z": -9,
      "name": "Soil_Ash"
    },
    {
      "x": -21,
      "y": 2,
      "z": -9,
      "name": "Soil_Ash"
    },
    {
      "x": -21,
      "y": 0,
      "z": -8,
      "name": "Soil_Ash"
    },
    {
      "x": -21,
      "y": 1,
      "z": -8,
      "name": "Soil_Ash"
    },
    {
      "x": -21,
      "y": 2,
      "z": -8,
      "name": "Soil_Ash"
    },
    {
      "x": -21,
      "y": 3,
      "z": -8,
      "name": "Soil_Sand_Ashen"
    },
    {
      "x": -21,
      "y": 0,
      "z": -7,
      "name": "Soil_Ash"
    },
    {
      "x": -21,
      "y": 1,
      "z": -7,
      "name": "Soil_Ash"
    },
    {
      "x": -21,
      "y": 2,
      "z": -7,
      "name": "Soil_Ash"
    },
    {
      "x": -21,
      "y": 3,
      "z": -7,
      "name": "Soil_Sand_Ashen"
    },
    {
      "x": -21,
      "y": 0,
      "z": -6,
      "name": "Soil_Ash"
    },
    {
      "x": -21,
      "y": 1,
      "z": -6,
      "name": "Soil_Sand_Ashen"
    },
    {
      "x": -21,
      "y": 2,
      "z": -6,
      "name": "Soil_Ash"
    },
    {
      "x": -21,
      "y": 3,
      "z": -6,
      "name": "Soil_Sand_Ashen"
    },
    {
      "x": -21,
      "y": 0,
      "z": -5,
      "name": "Soil_Ash"
    },
    {
      "x": -21,
      "y": 1,
      "z": -5,
      "name": "Soil_Sand_Ashen"
    },
    {
      "x": -21,
      "y": 2,
      "z": -5,
      "name": "Soil_Sand_Ashen"
    },
    {
      "x": -21,
      "y": 3,
      "z": -5,
      "name": "Soil_Sand_Ashen"
    },
    {
      "x": -21,
      "y": 4,
      "z": -5,
      "name": "Soil_Sand_Ashen"
    },
    {
      "x": -21,
      "y": 0,
      "z": -4,
      "name": "Soil_Ash"
    },
    {
      "x": -21,
      "y": 1,
      "z": -4,
      "name": "Soil_Sand_Ashen"
    },
    {
      "x": -21,
      "y": 2,
      "z": -4,
      "name": "Soil_Sand_Ashen"
    },
    {
      "x": -21,
      "y": 3,
      "z": -4,
      "name": "Soil_Sand_Ashen"
    },
    {
      "x": -21,
      "y": 4,
      "z": -4,
      "name": "Soil_Sand_Ashen"
    },
    {
      "x": -21,
      "y": 0,
      "z": -3,
      "name": "Soil_Ash"
    },
    {
      "x": -21,
      "y": 1,
      "z": -3,
      "name": "Soil_Sand_Ashen"
    },
    {
      "x": -21,
      "y": 2,
      "z": -3,
      "name": "Soil_Sand_Ashen"
    },
    {
      "x": -21,
      "y": 3,
      "z": -3,
      "name": "Soil_Sand_Ashen"
    },
    {
      "x": -21,
      "y": 4,
      "z": -3,
      "name": "Soil_Sand_Ashen"
    },
    {
      "x": -21,
      "y": 20,
      "z": -3,
      "name": "Plant_Vine_Wall_Poisoned",
      "support": 15,
      "rotation": 3
    },
    {
      "x": -21,
      "y": 21,
      "z": -3,
      "name": "Rock_Magma_Cooled"
    },
    {
      "x": -21,
      "y": 0,
      "z": -2,
      "name": "Soil_Ash"
    },
    {
      "x": -21,
      "y": 1,
      "z": -2,
      "name": "Soil_Sand_Ashen"
    },
    {
      "x": -21,
      "y": 2,
      "z": -2,
      "name": "Soil_Sand_Ashen"
    },
    {
      "x": -21,
      "y": 3,
      "z": -2,
      "name": "Soil_Sand_Ashen"
    },
    {
      "x": -21,
      "y": 4,
      "z": -2,
      "name": "Soil_Sand_Ashen"
    },
    {
      "x": -21,
      "y": 21,
      "z": -2,
      "name": "Ore_Adamantite_Magma_Cracked"
    },
    {
      "x": -21,
      "y": 0,
      "z": -1,
      "name": "Soil_Sand_Ashen"
    },
    {
      "x": -21,
      "y": 1,
      "z": -1,
      "name": "Soil_Sand_Ashen"
    },
    {
      "x": -21,
      "y": 2,
      "z": -1,
      "name": "Soil_Sand_Ashen"
    },
    {
      "x": -21,
      "y": 3,
      "z": -1,
      "name": "Soil_Sand_Ashen"
    },
    {
      "x": -21,
      "y": 4,
      "z": -1,
      "name": "Soil_Sand_Ashen"
    },
    {
      "x": -21,
      "y": 20,
      "z": -1,
      "name": "Rock_Magma_Cooled"
    },
    {
      "x": -21,
      "y": 21,
      "z": -1,
      "name": "Rock_Magma_Cooled"
    },
    {
      "x": -21,
      "y": 22,
      "z": -1,
      "name": "Ore_Adamantite_Magma_Cracked"
    },
    {
      "x": -21,
      "y": 0,
      "z": 0,
      "name": "Soil_Sand_Ashen"
    },
    {
      "x": -21,
      "y": 1,
      "z": 0,
      "name": "Soil_Sand_Ashen"
    },
    {
      "x": -21,
      "y": 2,
      "z": 0,
      "name": "Soil_Sand_Ashen"
    },
    {
      "x": -21,
      "y": 3,
      "z": 0,
      "name": "Soil_Sand_Ashen"
    },
    {
      "x": -21,
      "y": 4,
      "z": 0,
      "name": "Soil_Sand_Ashen"
    },
    {
      "x": -21,
      "y": 20,
      "z": 0,
      "name": "Rock_Magma_Cooled"
    },
    {
      "x": -21,
      "y": 21,
      "z": 0,
      "name": "Rock_Magma_Cooled"
    },
    {
      "x": -21,
      "y": 22,
      "z": 0,
      "name": "Rock_Magma_Cooled"
    },
    {
      "x": -21,
      "y": 23,
      "z": 0,
      "name": "Ore_Adamantite_Magma_Cracked"
    },
    {
      "x": -21,
      "y": 0,
      "z": 1,
      "name": "Soil_Sand_Ashen"
    },
    {
      "x": -21,
      "y": 1,
      "z": 1,
      "name": "Soil_Sand_Ashen"
    },
    {
      "x": -21,
      "y": 2,
      "z": 1,
      "name": "Soil_Sand_Ashen"
    },
    {
      "x": -21,
      "y": 3,
      "z": 1,
      "name": "Soil_Sand_Ashen"
    },
    {
      "x": -21,
      "y": 4,
      "z": 1,
      "name": "Soil_Sand_Ashen"
    },
    {
      "x": -21,
      "y": 20,
      "z": 1,
      "name": "Rock_Magma_Cooled"
    },
    {
      "x": -21,
      "y": 21,
      "z": 1,
      "name": "Ore_Adamantite_Magma_Cracked"
    },
    {
      "x": -21,
      "y": 22,
      "z": 1,
      "name": "Rock_Magma_Cooled"
    },
    {
      "x": -21,
      "y": 23,
      "z": 1,
      "name": "Rock_Magma_Cooled"
    },
    {
      "x": -21,
      "y": 0,
      "z": 2,
      "name": "Soil_Sand_Ashen"
    },
    {
      "x": -21,
      "y": 1,
      "z": 2,
      "name": "Soil_Sand_Ashen"
    },
    {
      "x": -21,
      "y": 2,
      "z": 2,
      "name": "Soil_Sand_Ashen"
    },
    {
      "x": -21,
      "y": 3,
      "z": 2,
      "name": "Soil_Sand_Ashen"
    },
    {
      "x": -21,
      "y": 4,
      "z": 2,
      "name": "Soil_Sand_Ashen"
    },
    {
      "x": -21,
      "y": 21,
      "z": 2,
      "name": "Rock_Magma_Cooled"
    },
    {
      "x": -21,
      "y": 22,
      "z": 2,
      "name": "Rock_Magma_Cooled"
    },
    {
      "x": -21,
      "y": 23,
      "z": 2,
      "name": "Rock_Magma_Cooled"
    },
    {
      "x": -21,
      "y": 0,
      "z": 3,
      "name": "Soil_Sand_Ashen"
    },
    {
      "x": -21,
      "y": 1,
      "z": 3,
      "name": "Soil_Sand_Ashen"
    },
    {
      "x": -21,
      "y": 2,
      "z": 3,
      "name": "Soil_Sand_Ashen"
    },
    {
      "x": -21,
      "y": 3,
      "z": 3,
      "name": "Soil_Sand_Ashen"
    },
    {
      "x": -21,
      "y": 4,
      "z": 3,
      "name": "Soil_Sand_Ashen"
    },
    {
      "x": -21,
      "y": 21,
      "z": 3,
      "name": "Rock_Magma_Cooled"
    },
    {
      "x": -21,
      "y": 22,
      "z": 3,
      "name": "Rock_Magma_Cooled"
    },
    {
      "x": -21,
      "y": 23,
      "z": 3,
      "name": "Ore_Adamantite_Magma_Cracked"
    },
    {
      "x": -21,
      "y": 0,
      "z": 4,
      "name": "Soil_Sand_Ashen"
    },
    {
      "x": -21,
      "y": 1,
      "z": 4,
      "name": "Soil_Sand_Ashen"
    },
    {
      "x": -21,
      "y": 2,
      "z": 4,
      "name": "Soil_Sand_Ashen"
    },
    {
      "x": -21,
      "y": 3,
      "z": 4,
      "name": "Soil_Sand_Ashen"
    },
    {
      "x": -21,
      "y": 4,
      "z": 4,
      "name": "Soil_Ash"
    },
    {
      "x": -21,
      "y": 21,
      "z": 4,
      "name": "Ore_Adamantite_Magma_Cracked"
    },
    {
      "x": -21,
      "y": 22,
      "z": 4,
      "name": "Ore_Adamantite_Magma_Cracked"
    },
    {
      "x": -21,
      "y": 23,
      "z": 4,
      "name": "Ore_Adamantite_Magma_Cracked"
    },
    {
      "x": -21,
      "y": 0,
      "z": 5,
      "name": "Soil_Sand_Ashen"
    },
    {
      "x": -21,
      "y": 1,
      "z": 5,
      "name": "Soil_Sand_Ashen"
    },
    {
      "x": -21,
      "y": 2,
      "z": 5,
      "name": "Soil_Sand_Ashen"
    },
    {
      "x": -21,
      "y": 3,
      "z": 5,
      "name": "Soil_Sand_Ashen"
    },
    {
      "x": -21,
      "y": 21,
      "z": 5,
      "name": "Ore_Adamantite_Magma_Cracked"
    },
    {
      "x": -21,
      "y": 22,
      "z": 5,
      "name": "Rock_Magma_Cooled"
    },
    {
      "x": -21,
      "y": 23,
      "z": 5,
      "name": "Rock_Magma_Cooled"
    },
    {
      "x": -21,
      "y": 0,
      "z": 6,
      "name": "Soil_Sand_Ashen"
    },
    {
      "x": -21,
      "y": 1,
      "z": 6,
      "name": "Soil_Sand_Ashen"
    },
    {
      "x": -21,
      "y": 2,
      "z": 6,
      "name": "Soil_Sand_Ashen"
    },
    {
      "x": -21,
      "y": 3,
      "z": 6,
      "name": "Soil_Sand_Ashen"
    },
    {
      "x": -21,
      "y": 23,
      "z": 6,
      "name": "Plant_Vine_Wall_Poisoned",
      "support": 15
    },
    {
      "x": -21,
      "y": 0,
      "z": 7,
      "name": "Soil_Sand_Ashen"
    },
    {
      "x": -21,
      "y": 1,
      "z": 7,
      "name": "Soil_Sand_Ashen"
    },
    {
      "x": -21,
      "y": 2,
      "z": 7,
      "name": "Soil_Sand_Ashen"
    },
    {
      "x": -21,
      "y": 0,
      "z": 8,
      "name": "Soil_Sand_Ashen"
    },
    {
      "x": -21,
      "y": 1,
      "z": 8,
      "name": "Soil_Ash"
    },
    {
      "x": -20,
      "y": 0,
      "z": -16,
      "name": "Soil_Ash"
    },
    {
      "x": -20,
      "y": 0,
      "z": -15,
      "name": "Soil_Ash"
    },
    {
      "x": -20,
      "y": 0,
      "z": -14,
      "name": "Soil_Ash"
    },
    {
      "x": -20,
      "y": 1,
      "z": -14,
      "name": "Soil_Ash"
    },
    {
      "x": -20,
      "y": 0,
      "z": -13,
      "name": "Soil_Ash"
    },
    {
      "x": -20,
      "y": 1,
      "z": -13,
      "name": "Soil_Ash"
    },
    {
      "x": -20,
      "y": 0,
      "z": -12,
      "name": "Soil_Ash"
    },
    {
      "x": -20,
      "y": 1,
      "z": -12,
      "name": "Soil_Ash"
    },
    {
      "x": -20,
      "y": 2,
      "z": -12,
      "name": "Soil_Ash"
    },
    {
      "x": -20,
      "y": 0,
      "z": -11,
      "name": "Soil_Ash"
    },
    {
      "x": -20,
      "y": 1,
      "z": -11,
      "name": "Soil_Ash"
    },
    {
      "x": -20,
      "y": 2,
      "z": -11,
      "name": "Soil_Ash"
    },
    {
      "x": -20,
      "y": 0,
      "z": -10,
      "name": "Soil_Ash"
    },
    {
      "x": -20,
      "y": 1,
      "z": -10,
      "name": "Soil_Ash"
    },
    {
      "x": -20,
      "y": 2,
      "z": -10,
      "name": "Soil_Ash"
    },
    {
      "x": -20,
      "y": 3,
      "z": -10,
      "name": "Soil_Sand_Ashen"
    },
    {
      "x": -20,
      "y": 0,
      "z": -9,
      "name": "Soil_Ash"
    },
    {
      "x": -20,
      "y": 1,
      "z": -9,
      "name": "Soil_Ash"
    },
    {
      "x": -20,
      "y": 2,
      "z": -9,
      "name": "Soil_Ash"
    },
    {
      "x": -20,
      "y": 3,
      "z": -9,
      "name": "Soil_Ash"
    },
    {
      "x": -20,
      "y": 0,
      "z": -8,
      "name": "Soil_Ash"
    },
    {
      "x": -20,
      "y": 1,
      "z": -8,
      "name": "Soil_Ash"
    },
    {
      "x": -20,
      "y": 2,
      "z": -8,
      "name": "Soil_Ash"
    },
    {
      "x": -20,
      "y": 3,
      "z": -8,
      "name": "Soil_Ash"
    },
    {
      "x": -20,
      "y": 0,
      "z": -7,
      "name": "Soil_Ash"
    },
    {
      "x": -20,
      "y": 1,
      "z": -7,
      "name": "Soil_Ash"
    },
    {
      "x": -20,
      "y": 2,
      "z": -7,
      "name": "Soil_Ash"
    },
    {
      "x": -20,
      "y": 3,
      "z": -7,
      "name": "Soil_Ash"
    },
    {
      "x": -20,
      "y": 4,
      "z": -7,
      "name": "Soil_Sand_Ashen"
    },
    {
      "x": -20,
      "y": 0,
      "z": -6,
      "name": "Soil_Ash"
    },
    {
      "x": -20,
      "y": 1,
      "z": -6,
      "name": "Soil_Ash"
    },
    {
      "x": -20,
      "y": 2,
      "z": -6,
      "name": "Soil_Ash"
    },
    {
      "x": -20,
      "y": 3,
      "z": -6,
      "name": "Soil_Sand_Ashen"
    },
    {
      "x": -20,
      "y": 4,
      "z": -6,
      "name": "Soil_Sand_Ashen"
    },
    {
      "x": -20,
      "y": 0,
      "z": -5,
      "name": "Soil_Ash"
    },
    {
      "x": -20,
      "y": 1,
      "z": -5,
      "name": "Soil_Ash"
    },
    {
      "x": -20,
      "y": 2,
      "z": -5,
      "name": "Soil_Ash"
    },
    {
      "x": -20,
      "y": 3,
      "z": -5,
      "name": "Soil_Sand_Ashen"
    },
    {
      "x": -20,
      "y": 4,
      "z": -5,
      "name": "Soil_Sand_Ashen"
    },
    {
      "x": -20,
      "y": 0,
      "z": -4,
      "name": "Soil_Ash"
    },
    {
      "x": -20,
      "y": 1,
      "z": -4,
      "name": "Soil_Sand_Ashen"
    },
    {
      "x": -20,
      "y": 2,
      "z": -4,
      "name": "Soil_Sand_Ashen"
    },
    {
      "x": -20,
      "y": 3,
      "z": -4,
      "name": "Soil_Sand_Ashen"
    },
    {
      "x": -20,
      "y": 4,
      "z": -4,
      "name": "Soil_Sand_Ashen"
    },
    {
      "x": -20,
      "y": 5,
      "z": -4,
      "name": "Soil_Sand_Ashen"
    },
    {
      "x": -20,
      "y": 21,
      "z": -4,
      "name": "Rock_Magma_Cooled"
    },
    {
      "x": -20,
      "y": 0,
      "z": -3,
      "name": "Soil_Ash"
    },
    {
      "x": -20,
      "y": 1,
      "z": -3,
      "name": "Soil_Sand_Ashen"
    },
    {
      "x": -20,
      "y": 2,
      "z": -3,
      "name": "Soil_Sand_Ashen"
    },
    {
      "x": -20,
      "y": 3,
      "z": -3,
      "name": "Soil_Sand_Ashen"
    },
    {
      "x": -20,
      "y": 4,
      "z": -3,
      "name": "Soil_Sand_Ashen"
    },
    {
      "x": -20,
      "y": 5,
      "z": -3,
      "name": "Soil_Sand_Ashen"
    },
    {
      "x": -20,
      "y": 15,
      "z": -3,
      "name": "Ore_Adamantite_Magma_Cracked"
    },
    {
      "x": -20,
      "y": 20,
      "z": -3,
      "name": "Rock_Magma_Cooled"
    },
    {
      "x": -20,
      "y": 21,
      "z": -3,
      "name": "Ore_Adamantite_Magma_Cracked"
    },
    {
      "x": -20,
      "y": 22,
      "z": -3,
      "name": "Ore_Adamantite_Magma_Cracked"
    },
    {
      "x": -20,
      "y": 0,
      "z": -2,
      "name": "Soil_Ash"
    },
    {
      "x": -20,
      "y": 1,
      "z": -2,
      "name": "Soil_Sand_Ashen"
    },
    {
      "x": -20,
      "y": 2,
      "z": -2,
      "name": "Soil_Sand_Ashen"
    },
    {
      "x": -20,
      "y": 3,
      "z": -2,
      "name": "Soil_Sand_Ashen"
    },
    {
      "x": -20,
      "y": 4,
      "z": -2,
      "name": "Soil_Sand_Ashen"
    },
    {
      "x": -20,
      "y": 5,
      "z": -2,
      "name": "Soil_Sand_Ashen"
    },
    {
      "x": -20,
      "y": 15,
      "z": -2,
      "name": "Rock_Magma_Cooled"
    },
    {
      "x": -20,
      "y": 20,
      "z": -2,
      "name": "Rock_Magma_Cooled"
    },
    {
      "x": -20,
      "y": 21,
      "z": -2,
      "name": "Ore_Adamantite_Magma_Cracked"
    },
    {
      "x": -20,
      "y": 22,
      "z": -2,
      "name": "Ore_Adamantite_Magma_Cracked"
    },
    {
      "x": -20,
      "y": 0,
      "z": -1,
      "name": "Soil_Ash"
    },
    {
      "x": -20,
      "y": 1,
      "z": -1,
      "name": "Soil_Sand_Ashen"
    },
    {
      "x": -20,
      "y": 2,
      "z": -1,
      "name": "Soil_Sand_Ashen"
    },
    {
      "x": -20,
      "y": 3,
      "z": -1,
      "name": "Soil_Sand_Ashen"
    },
    {
      "x": -20,
      "y": 4,
      "z": -1,
      "name": "Soil_Sand_Ashen"
    },
    {
      "x": -20,
      "y": 5,
      "z": -1,
      "name": "Soil_Sand_Ashen"
    },
    {
      "x": -20,
      "y": 15,
      "z": -1,
      "name": "Ore_Adamantite_Magma_Cracked"
    },
    {
      "x": -20,
      "y": 19,
      "z": -1,
      "name": "Ore_Adamantite_Magma_Cracked"
    },
    {
      "x": -20,
      "y": 20,
      "z": -1,
      "name": "Rock_Magma_Cooled"
    },
    {
      "x": -20,
      "y": 21,
      "z": -1,
      "name": "Rock_Magma_Cooled"
    },
    {
      "x": -20,
      "y": 22,
      "z": -1,
      "name": "Ore_Adamantite_Magma_Cracked"
    },
    {
      "x": -20,
      "y": 23,
      "z": -1,
      "name": "Ore_Adamantite_Magma_Cracked"
    },
    {
      "x": -20,
      "y": 0,
      "z": 0,
      "name": "Soil_Ash"
    },
    {
      "x": -20,
      "y": 1,
      "z": 0,
      "name": "Soil_Sand_Ashen"
    },
    {
      "x": -20,
      "y": 2,
      "z": 0,
      "name": "Soil_Sand_Ashen"
    },
    {
      "x": -20,
      "y": 3,
      "z": 0,
      "name": "Soil_Sand_Ashen"
    },
    {
      "x": -20,
      "y": 4,
      "z": 0,
      "name": "Soil_Sand_Ashen"
    },
    {
      "x": -20,
      "y": 19,
      "z": 0,
      "name": "Rock_Magma_Cooled"
    },
    {
      "x": -20,
      "y": 20,
      "z": 0,
      "name": "Ore_Adamantite_Magma_Cracked"
    },
    {
      "x": -20,
      "y": 21,
      "z": 0,
      "name": "Ore_Adamantite_Magma_Cracked"
    },
    {
      "x": -20,
      "y": 22,
      "z": 0,
      "name": "Rock_Magma_Cooled"
    },
    {
      "x": -20,
      "y": 23,
      "z": 0,
      "name": "Rock_Magma_Cooled"
    },
    {
      "x": -20,
      "y": 0,
      "z": 1,
      "name": "Soil_Sand_Ashen"
    },
    {
      "x": -20,
      "y": 1,
      "z": 1,
      "name": "Soil_Sand_Ashen"
    },
    {
      "x": -20,
      "y": 2,
      "z": 1,
      "name": "Soil_Sand_Ashen"
    },
    {
      "x": -20,
      "y": 3,
      "z": 1,
      "name": "Soil_Sand_Ashen"
    },
    {
      "x": -20,
      "y": 4,
      "z": 1,
      "name": "Soil_Sand_Ashen"
    },
    {
      "x": -20,
      "y": 19,
      "z": 1,
      "name": "Ore_Adamantite_Magma_Cracked"
    },
    {
      "x": -20,
      "y": 20,
      "z": 1,
      "name": "Ore_Adamantite_Magma_Cracked"
    },
    {
      "x": -20,
      "y": 21,
      "z": 1,
      "name": "Ore_Adamantite_Magma_Cracked"
    },
    {
      "x": -20,
      "y": 22,
      "z": 1,
      "name": "Rock_Magma_Cooled"
    },
    {
      "x": -20,
      "y": 23,
      "z": 1,
      "name": "Ore_Adamantite_Magma_Cracked"
    },
    {
      "x": -20,
      "y": 0,
      "z": 2,
      "name": "Soil_Sand_Ashen"
    },
    {
      "x": -20,
      "y": 1,
      "z": 2,
      "name": "Soil_Sand_Ashen"
    },
    {
      "x": -20,
      "y": 2,
      "z": 2,
      "name": "Soil_Sand_Ashen"
    },
    {
      "x": -20,
      "y": 3,
      "z": 2,
      "name": "Soil_Sand_Ashen"
    },
    {
      "x": -20,
      "y": 4,
      "z": 2,
      "name": "Soil_Sand_Ashen"
    },
    {
      "x": -20,
      "y": 20,
      "z": 2,
      "name": "Rock_Magma_Cooled"
    },
    {
      "x": -20,
      "y": 21,
      "z": 2,
      "name": "Ore_Adamantite_Magma_Cracked"
    },
    {
      "x": -20,
      "y": 22,
      "z": 2,
      "name": "Rock_Magma_Cooled"
    },
    {
      "x": -20,
      "y": 23,
      "z": 2,
      "name": "Rock_Magma_Cooled"
    },
    {
      "x": -20,
      "y": 0,
      "z": 3,
      "name": "Soil_Sand_Ashen"
    },
    {
      "x": -20,
      "y": 1,
      "z": 3,
      "name": "Soil_Sand_Ashen"
    },
    {
      "x": -20,
      "y": 2,
      "z": 3,
      "name": "Soil_Sand_Ashen"
    },
    {
      "x": -20,
      "y": 3,
      "z": 3,
      "name": "Soil_Sand_Ashen"
    },
    {
      "x": -20,
      "y": 4,
      "z": 3,
      "name": "Soil_Ash"
    },
    {
      "x": -20,
      "y": 20,
      "z": 3,
      "name": "Rock_Magma_Cooled"
    },
    {
      "x": -20,
      "y": 21,
      "z": 3,
      "name": "Rock_Magma_Cooled"
    },
    {
      "x": -20,
      "y": 22,
      "z": 3,
      "name": "Ore_Adamantite_Magma_Cracked"
    },
    {
      "x": -20,
      "y": 23,
      "z": 3,
      "name": "Ore_Adamantite_Magma_Cracked"
    },
    {
      "x": -20,
      "y": 0,
      "z": 4,
      "name": "Soil_Sand_Ashen"
    },
    {
      "x": -20,
      "y": 1,
      "z": 4,
      "name": "Soil_Sand_Ashen"
    },
    {
      "x": -20,
      "y": 2,
      "z": 4,
      "name": "Soil_Sand_Ashen"
    },
    {
      "x": -20,
      "y": 3,
      "z": 4,
      "name": "Soil_Sand_Ashen"
    },
    {
      "x": -20,
      "y": 4,
      "z": 4,
      "name": "Soil_Sand_Ashen"
    },
    {
      "x": -20,
      "y": 20,
      "z": 4,
      "name": "Rock_Magma_Cooled"
    },
    {
      "x": -20,
      "y": 21,
      "z": 4,
      "name": "Ore_Adamantite_Magma_Cracked"
    },
    {
      "x": -20,
      "y": 22,
      "z": 4,
      "name": "Ore_Adamantite_Magma_Cracked"
    },
    {
      "x": -20,
      "y": 23,
      "z": 4,
      "name": "Rock_Magma_Cooled"
    },
    {
      "x": -20,
      "y": 0,
      "z": 5,
      "name": "Soil_Sand_Ashen"
    },
    {
      "x": -20,
      "y": 1,
      "z": 5,
      "name": "Soil_Sand_Ashen"
    },
    {
      "x": -20,
      "y": 2,
      "z": 5,
      "name": "Soil_Sand_Ashen"
    },
    {
      "x": -20,
      "y": 3,
      "z": 5,
      "name": "Soil_Sand_Ashen"
    },
    {
      "x": -20,
      "y": 4,
      "z": 5,
      "name": "Soil_Ash"
    },
    {
      "x": -20,
      "y": 21,
      "z": 5,
      "name": "Ore_Adamantite_Magma_Cracked"
    },
    {
      "x": -20,
      "y": 22,
      "z": 5,
      "name": "Ore_Adamantite_Magma_Cracked"
    },
    {
      "x": -20,
      "y": 23,
      "z": 5,
      "name": "Ore_Adamantite_Magma_Cracked"
    },
    {
      "x": -20,
      "y": 0,
      "z": 6,
      "name": "Soil_Sand_Ashen"
    },
    {
      "x": -20,
      "y": 1,
      "z": 6,
      "name": "Soil_Sand_Ashen"
    },
    {
      "x": -20,
      "y": 2,
      "z": 6,
      "name": "Soil_Sand_Ashen"
    },
    {
      "x": -20,
      "y": 3,
      "z": 6,
      "name": "Soil_Sand_Ashen"
    },
    {
      "x": -20,
      "y": 0,
      "z": 7,
      "name": "Soil_Ash"
    },
    {
      "x": -20,
      "y": 1,
      "z": 7,
      "name": "Soil_Sand_Ashen"
    },
    {
      "x": -20,
      "y": 2,
      "z": 7,
      "name": "Soil_Sand_Ashen"
    },
    {
      "x": -20,
      "y": 3,
      "z": 7,
      "name": "Soil_Sand_Ashen"
    },
    {
      "x": -20,
      "y": 0,
      "z": 8,
      "name": "Soil_Sand_Ashen"
    },
    {
      "x": -20,
      "y": 1,
      "z": 8,
      "name": "Soil_Sand_Ashen"
    },
    {
      "x": -20,
      "y": 2,
      "z": 8,
      "name": "Soil_Sand_Ashen"
    },
    {
      "x": -20,
      "y": 0,
      "z": 9,
      "name": "Soil_Sand_Ashen"
    },
    {
      "x": -20,
      "y": 1,
      "z": 9,
      "name": "Soil_Ash"
    },
    {
      "x": -19,
      "y": 0,
      "z": -16,
      "name": "Soil_Ash"
    },
    {
      "x": -19,
      "y": 0,
      "z": -15,
      "name": "Soil_Ash"
    },
    {
      "x": -19,
      "y": 1,
      "z": -15,
      "name": "Soil_Ash"
    },
    {
      "x": -19,
      "y": 0,
      "z": -14,
      "name": "Soil_Ash"
    },
    {
      "x": -19,
      "y": 1,
      "z": -14,
      "name": "Soil_Ash"
    },
    {
      "x": -19,
      "y": 0,
      "z": -13,
      "name": "Soil_Ash"
    },
    {
      "x": -19,
      "y": 1,
      "z": -13,
      "name": "Soil_Ash"
    },
    {
      "x": -19,
      "y": 2,
      "z": -13,
      "name": "Soil_Ash"
    },
    {
      "x": -19,
      "y": 0,
      "z": -12,
      "name": "Soil_Ash"
    },
    {
      "x": -19,
      "y": 1,
      "z": -12,
      "name": "Soil_Ash"
    },
    {
      "x": -19,
      "y": 2,
      "z": -12,
      "name": "Soil_Ash"
    },
    {
      "x": -19,
      "y": 0,
      "z": -11,
      "name": "Soil_Ash"
    },
    {
      "x": -19,
      "y": 1,
      "z": -11,
      "name": "Soil_Ash"
    },
    {
      "x": -19,
      "y": 2,
      "z": -11,
      "name": "Soil_Ash"
    },
    {
      "x": -19,
      "y": 3,
      "z": -11,
      "name": "Soil_Ash"
    },
    {
      "x": -19,
      "y": 0,
      "z": -10,
      "name": "Soil_Ash"
    },
    {
      "x": -19,
      "y": 1,
      "z": -10,
      "name": "Soil_Ash"
    },
    {
      "x": -19,
      "y": 2,
      "z": -10,
      "name": "Soil_Ash"
    },
    {
      "x": -19,
      "y": 3,
      "z": -10,
      "name": "Soil_Ash"
    },
    {
      "x": -19,
      "y": 0,
      "z": -9,
      "name": "Soil_Ash"
    },
    {
      "x": -19,
      "y": 1,
      "z": -9,
      "name": "Soil_Ash"
    },
    {
      "x": -19,
      "y": 2,
      "z": -9,
      "name": "Soil_Ash"
    },
    {
      "x": -19,
      "y": 3,
      "z": -9,
      "name": "Soil_Ash"
    },
    {
      "x": -19,
      "y": 4,
      "z": -9,
      "name": "Soil_Ash"
    },
    {
      "x": -19,
      "y": 0,
      "z": -8,
      "name": "Soil_Ash"
    },
    {
      "x": -19,
      "y": 1,
      "z": -8,
      "name": "Soil_Ash"
    },
    {
      "x": -19,
      "y": 2,
      "z": -8,
      "name": "Soil_Ash"
    },
    {
      "x": -19,
      "y": 3,
      "z": -8,
      "name": "Soil_Ash"
    },
    {
      "x": -19,
      "y": 4,
      "z": -8,
      "name": "Soil_Ash"
    },
    {
      "x": -19,
      "y": 0,
      "z": -7,
      "name": "Soil_Ash"
    },
    {
      "x": -19,
      "y": 1,
      "z": -7,
      "name": "Soil_Ash"
    },
    {
      "x": -19,
      "y": 2,
      "z": -7,
      "name": "Soil_Ash"
    },
    {
      "x": -19,
      "y": 3,
      "z": -7,
      "name": "Soil_Ash"
    },
    {
      "x": -19,
      "y": 4,
      "z": -7,
      "name": "Soil_Ash"
    },
    {
      "x": -19,
      "y": 5,
      "z": -7,
      "name": "Plant_Flower_Bushy_Poisoned"
    },
    {
      "x": -19,
      "y": 0,
      "z": -6,
      "name": "Soil_Ash"
    },
    {
      "x": -19,
      "y": 1,
      "z": -6,
      "name": "Soil_Ash"
    },
    {
      "x": -19,
      "y": 2,
      "z": -6,
      "name": "Soil_Ash"
    },
    {
      "x": -19,
      "y": 3,
      "z": -6,
      "name": "Soil_Ash"
    },
    {
      "x": -19,
      "y": 4,
      "z": -6,
      "name": "Soil_Ash"
    },
    {
      "x": -19,
      "y": 5,
      "z": -6,
      "name": "Soil_Sand_Ashen"
    },
    {
      "x": -19,
      "y": 0,
      "z": -5,
      "name": "Soil_Ash"
    },
    {
      "x": -19,
      "y": 1,
      "z": -5,
      "name": "Soil_Ash"
    },
    {
      "x": -19,
      "y": 2,
      "z": -5,
      "name": "Soil_Ash"
    },
    {
      "x": -19,
      "y": 3,
      "z": -5,
      "name": "Soil_Ash"
    },
    {
      "x": -19,
      "y": 4,
      "z": -5,
      "name": "Soil_Ash"
    },
    {
      "x": -19,
      "y": 5,
      "z": -5,
      "name": "Soil_Sand_Ashen"
    },
    {
      "x": -19,
      "y": 0,
      "z": -4,
      "name": "Soil_Ash"
    },
    {
      "x": -19,
      "y": 1,
      "z": -4,
      "name": "Soil_Ash"
    },
    {
      "x": -19,
      "y": 2,
      "z": -4,
      "name": "Soil_Ash"
    },
    {
      "x": -19,
      "y": 3,
      "z": -4,
      "name": "Soil_Ash"
    },
    {
      "x": -19,
      "y": 4,
      "z": -4,
      "name": "Soil_Sand_Ashen"
    },
    {
      "x": -19,
      "y": 5,
      "z": -4,
      "name": "Soil_Sand_Ashen"
    },
    {
      "x": -19,
      "y": 20,
      "z": -4,
      "name": "Rock_Magma_Cooled"
    },
    {
      "x": -19,
      "y": 21,
      "z": -4,
      "name": "Ore_Adamantite_Magma_Cracked"
    },
    {
      "x": -19,
      "y": 22,
      "z": -4,
      "name": "Ore_Adamantite_Magma_Cracked"
    },
    {
      "x": -19,
      "y": 0,
      "z": -3,
      "name": "Soil_Ash"
    },
    {
      "x": -19,
      "y": 1,
      "z": -3,
      "name": "Soil_Ash"
    },
    {
      "x": -19,
      "y": 2,
      "z": -3,
      "name": "Soil_Ash"
    },
    {
      "x": -19,
      "y": 3,
      "z": -3,
      "name": "Soil_Sand_Ashen"
    },
    {
      "x": -19,
      "y": 4,
      "z": -3,
      "name": "Soil_Sand_Ashen"
    },
    {
      "x": -19,
      "y": 5,
      "z": -3,
      "name": "Soil_Sand_Ashen"
    },
    {
      "x": -19,
      "y": 14,
      "z": -3,
      "name": "Rock_Magma_Cooled"
    },
    {
      "x": -19,
      "y": 15,
      "z": -3,
      "name": "Ore_Adamantite_Magma_Cracked"
    },
    {
      "x": -19,
      "y": 16,
      "z": -3,
      "name": "Rock_Magma_Cooled"
    },
    {
      "x": -19,
      "y": 19,
      "z": -3,
      "name": "Plant_Vine_Wall_Poisoned",
      "support": 15,
      "rotation": 3
    },
    {
      "x": -19,
      "y": 20,
      "z": -3,
      "name": "Rock_Magma_Cooled"
    },
    {
      "x": -19,
      "y": 21,
      "z": -3,
      "name": "Ore_Adamantite_Magma_Cracked"
    },
    {
      "x": -19,
      "y": 22,
      "z": -3,
      "name": "Rock_Magma_Cooled"
    },
    {
      "x": -19,
      "y": 0,
      "z": -2,
      "name": "Soil_Ash"
    },
    {
      "x": -19,
      "y": 1,
      "z": -2,
      "name": "Soil_Sand_Ashen"
    },
    {
      "x": -19,
      "y": 2,
      "z": -2,
      "name": "Soil_Ash"
    },
    {
      "x": -19,
      "y": 3,
      "z": -2,
      "name": "Soil_Sand_Ashen"
    },
    {
      "x": -19,
      "y": 4,
      "z": -2,
      "name": "Soil_Sand_Ashen"
    },
    {
      "x": -19,
      "y": 5,
      "z": -2,
      "name": "Soil_Sand_Ashen"
    },
    {
      "x": -19,
      "y": 14,
      "z": -2,
      "name": "Ore_Adamantite_Magma_Cracked"
    },
    {
      "x": -19,
      "y": 15,
      "z": -2,
      "name": "Rock_Magma_Cooled"
    },
    {
      "x": -19,
      "y": 16,
      "z": -2,
      "name": "Rock_Magma_Cooled"
    },
    {
      "x": -19,
      "y": 19,
      "z": -2,
      "name": "Ore_Adamantite_Magma_Cracked"
    },
    {
      "x": -19,
      "y": 20,
      "z": -2,
      "name": "Rock_Magma_Cooled"
    },
    {
      "x": -19,
      "y": 21,
      "z": -2,
      "name": "Ore_Adamantite_Magma_Cracked"
    },
    {
      "x": -19,
      "y": 22,
      "z": -2,
      "name": "Ore_Adamantite_Magma_Cracked"
    },
    {
      "x": -19,
      "y": 23,
      "z": -2,
      "name": "Rock_Magma_Cooled"
    },
    {
      "x": -19,
      "y": 0,
      "z": -1,
      "name": "Soil_Ash"
    },
    {
      "x": -19,
      "y": 1,
      "z": -1,
      "name": "Soil_Sand_Ashen"
    },
    {
      "x": -19,
      "y": 2,
      "z": -1,
      "name": "Soil_Sand_Ashen"
    },
    {
      "x": -19,
      "y": 3,
      "z": -1,
      "name": "Soil_Sand_Ashen"
    },
    {
      "x": -19,
      "y": 4,
      "z": -1,
      "name": "Soil_Sand_Ashen"
    },
    {
      "x": -19,
      "y": 5,
      "z": -1,
      "name": "Soil_Ash"
    },
    {
      "x": -19,
      "y": 6,
      "z": -1,
      "name": "Plant_Bramble_Dead_Twisted"
    },
    {
      "x": -19,
      "y": 15,
      "z": -1,
      "name": "Ore_Adamantite_Magma_Cracked"
    },
    {
      "x": -19,
      "y": 19,
      "z": -1,
      "name": "Rock_Magma_Cooled"
    },
    {
      "x": -19,
      "y": 20,
      "z": -1,
      "name": "Rock_Magma_Cooled"
    },
    {
      "x": -19,
      "y": 21,
      "z": -1,
      "name": "Rock_Magma_Cooled"
    },
    {
      "x": -19,
      "y": 22,
      "z": -1,
      "name": "Rock_Magma_Cooled"
    },
    {
      "x": -19,
      "y": 23,
      "z": -1,
      "name": "Ore_Adamantite_Magma_Cracked"
    },
    {
      "x": -19,
      "y": 0,
      "z": 0,
      "name": "Soil_Ash"
    },
    {
      "x": -19,
      "y": 1,
      "z": 0,
      "name": "Soil_Sand_Ashen"
    },
    {
      "x": -19,
      "y": 2,
      "z": 0,
      "name": "Soil_Sand_Ashen"
    },
    {
      "x": -19,
      "y": 3,
      "z": 0,
      "name": "Soil_Sand_Ashen"
    },
    {
      "x": -19,
      "y": 4,
      "z": 0,
      "name": "Soil_Sand_Ashen"
    },
    {
      "x": -19,
      "y": 5,
      "z": 0,
      "name": "Soil_Ash"
    },
    {
      "x": -19,
      "y": 19,
      "z": 0,
      "name": "Ore_Adamantite_Magma_Cracked"
    },
    {
      "x": -19,
      "y": 20,
      "z": 0,
      "name": "Rock_Magma_Cooled"
    },
    {
      "x": -19,
      "y": 21,
      "z": 0,
      "name": "Rock_Magma_Cooled"
    },
    {
      "x": -19,
      "y": 22,
      "z": 0,
      "name": "Rock_Magma_Cooled"
    },
    {
      "x": -19,
      "y": 23,
      "z": 0,
      "name": "Rock_Magma_Cooled"
    },
    {
      "x": -19,
      "y": 0,
      "z": 1,
      "name": "Soil_Sand_Ashen"
    },
    {
      "x": -19,
      "y": 1,
      "z": 1,
      "name": "Soil_Sand_Ashen"
    },
    {
      "x": -19,
      "y": 2,
      "z": 1,
      "name": "Soil_Sand_Ashen"
    },
    {
      "x": -19,
      "y": 3,
      "z": 1,
      "name": "Soil_Sand_Ashen"
    },
    {
      "x": -19,
      "y": 4,
      "z": 1,
      "name": "Soil_Sand_Ashen"
    },
    {
      "x": -19,
      "y": 5,
      "z": 1,
      "name": "Soil_Ash"
    },
    {
      "x": -19,
      "y": 19,
      "z": 1,
      "name": "Rock_Magma_Cooled"
    },
    {
      "x": -19,
      "y": 20,
      "z": 1,
      "name": "Rock_Magma_Cooled"
    },
    {
      "x": -19,
      "y": 21,
      "z": 1,
      "name": "Ore_Adamantite_Magma_Cracked"
    },
    {
      "x": -19,
      "y": 22,
      "z": 1,
      "name": "Rock_Magma_Cooled"
    },
    {
      "x": -19,
      "y": 23,
      "z": 1,
      "name": "Ore_Adamantite_Magma_Cracked"
    },
    {
      "x": -19,
      "y": 0,
      "z": 2,
      "name": "Soil_Sand_Ashen"
    },
    {
      "x": -19,
      "y": 1,
      "z": 2,
      "name": "Soil_Sand_Ashen"
    },
    {
      "x": -19,
      "y": 2,
      "z": 2,
      "name": "Soil_Sand_Ashen"
    },
    {
      "x": -19,
      "y": 3,
      "z": 2,
      "name": "Soil_Sand_Ashen"
    },
    {
      "x": -19,
      "y": 4,
      "z": 2,
      "name": "Soil_Ash"
    },
    {
      "x": -19,
      "y": 5,
      "z": 2,
      "name": "Soil_Ash"
    },
    {
      "x": -19,
      "y": 19,
      "z": 2,
      "name": "Ore_Adamantite_Magma_Cracked"
    },
    {
      "x": -19,
      "y": 20,
      "z": 2,
      "name": "Ore_Adamantite_Magma_Cracked"
    },
    {
      "x": -19,
      "y": 21,
      "z": 2,
      "name": "Rock_Magma_Cooled"
    },
    {
      "x": -19,
      "y": 22,
      "z": 2,
      "name": "Rock_Magma_Cooled"
    },
    {
      "x": -19,
      "y": 23,
      "z": 2,
      "name": "Ore_Adamantite_Magma_Cracked"
    },
    {
      "x": -19,
      "y": 0,
      "z": 3,
      "name": "Soil_Ash"
    },
    {
      "x": -19,
      "y": 1,
      "z": 3,
      "name": "Soil_Sand_Ashen"
    },
    {
      "x": -19,
      "y": 2,
      "z": 3,
      "name": "Soil_Sand_Ashen"
    },
    {
      "x": -19,
      "y": 3,
      "z": 3,
      "name": "Soil_Sand_Ashen"
    },
    {
      "x": -19,
      "y": 4,
      "z": 3,
      "name": "Soil_Ash"
    },
    {
      "x": -19,
      "y": 5,
      "z": 3,
      "name": "Plant_Bramble_Dead_Twisted"
    },
    {
      "x": -19,
      "y": 20,
      "z": 3,
      "name": "Ore_Adamantite_Magma_Cracked"
    },
    {
      "x": -19,
      "y": 21,
      "z": 3,
      "name": "Rock_Magma_Cooled"
    },
    {
      "x": -19,
      "y": 22,
      "z": 3,
      "name": "Rock_Magma_Cooled"
    },
    {
      "x": -19,
      "y": 0,
      "z": 4,
      "name": "Soil_Sand_Ashen"
    },
    {
      "x": -19,
      "y": 1,
      "z": 4,
      "name": "Soil_Sand_Ashen"
    },
    {
      "x": -19,
      "y": 2,
      "z": 4,
      "name": "Soil_Sand_Ashen"
    },
    {
      "x": -19,
      "y": 3,
      "z": 4,
      "name": "Soil_Sand_Ashen"
    },
    {
      "x": -19,
      "y": 4,
      "z": 4,
      "name": "Soil_Ash"
    },
    {
      "x": -19,
      "y": 20,
      "z": 4,
      "name": "Ore_Adamantite_Magma_Cracked"
    },
    {
      "x": -19,
      "y": 21,
      "z": 4,
      "name": "Ore_Adamantite_Magma_Cracked"
    },
    {
      "x": -19,
      "y": 22,
      "z": 4,
      "name": "Rock_Magma_Cooled"
    },
    {
      "x": -19,
      "y": 0,
      "z": 5,
      "name": "Soil_Sand_Ashen"
    },
    {
      "x": -19,
      "y": 1,
      "z": 5,
      "name": "Soil_Sand_Ashen"
    },
    {
      "x": -19,
      "y": 2,
      "z": 5,
      "name": "Soil_Sand_Ashen"
    },
    {
      "x": -19,
      "y": 3,
      "z": 5,
      "name": "Soil_Sand_Ashen"
    },
    {
      "x": -19,
      "y": 4,
      "z": 5,
      "name": "Soil_Sand_Ashen"
    },
    {
      "x": -19,
      "y": 20,
      "z": 5,
      "name": "Ore_Adamantite_Magma_Cracked"
    },
    {
      "x": -19,
      "y": 21,
      "z": 5,
      "name": "Rock_Magma_Cooled"
    },
    {
      "x": -19,
      "y": 22,
      "z": 5,
      "name": "Ore_Adamantite_Magma_Cracked"
    },
    {
      "x": -19,
      "y": 0,
      "z": 6,
      "name": "Soil_Sand_Ashen"
    },
    {
      "x": -19,
      "y": 1,
      "z": 6,
      "name": "Soil_Sand_Ashen"
    },
    {
      "x": -19,
      "y": 2,
      "z": 6,
      "name": "Soil_Sand_Ashen"
    },
    {
      "x": -19,
      "y": 3,
      "z": 6,
      "name": "Soil_Sand_Ashen"
    },
    {
      "x": -19,
      "y": 4,
      "z": 6,
      "name": "Soil_Ash"
    },
    {
      "x": -19,
      "y": 22,
      "z": 6,
      "name": "Plant_Vine_Wall_Poisoned",
      "support": 15
    },
    {
      "x": -19,
      "y": 0,
      "z": 7,
      "name": "Soil_Sand_Ashen"
    },
    {
      "x": -19,
      "y": 1,
      "z": 7,
      "name": "Soil_Sand_Ashen"
    },
    {
      "x": -19,
      "y": 2,
      "z": 7,
      "name": "Soil_Sand_Ashen"
    },
    {
      "x": -19,
      "y": 3,
      "z": 7,
      "name": "Soil_Sand_Ashen"
    },
    {
      "x": -19,
      "y": 4,
      "z": 7,
      "name": "Soil_Sand_Ashen"
    },
    {
      "x": -19,
      "y": 0,
      "z": 8,
      "name": "Soil_Sand_Ashen"
    },
    {
      "x": -19,
      "y": 1,
      "z": 8,
      "name": "Soil_Sand_Ashen"
    },
    {
      "x": -19,
      "y": 2,
      "z": 8,
      "name": "Soil_Sand_Ashen"
    },
    {
      "x": -19,
      "y": 3,
      "z": 8,
      "name": "Soil_Sand_Ashen"
    },
    {
      "x": -19,
      "y": 0,
      "z": 9,
      "name": "Soil_Sand_Ashen"
    },
    {
      "x": -19,
      "y": 1,
      "z": 9,
      "name": "Soil_Sand_Ashen"
    },
    {
      "x": -19,
      "y": 2,
      "z": 9,
      "name": "Soil_Sand_Ashen"
    },
    {
      "x": -19,
      "y": 0,
      "z": 10,
      "name": "Soil_Ash"
    },
    {
      "x": -19,
      "y": 1,
      "z": 10,
      "name": "Soil_Sand_Ashen"
    },
    {
      "x": -18,
      "y": 0,
      "z": -16,
      "name": "Soil_Ash"
    },
    {
      "x": -18,
      "y": 0,
      "z": -15,
      "name": "Soil_Sand_Ashen"
    },
    {
      "x": -18,
      "y": 1,
      "z": -15,
      "name": "Soil_Ash"
    },
    {
      "x": -18,
      "y": 0,
      "z": -14,
      "name": "Soil_Ash"
    },
    {
      "x": -18,
      "y": 1,
      "z": -14,
      "name": "Soil_Ash"
    },
    {
      "x": -18,
      "y": 2,
      "z": -14,
      "name": "Soil_Ash"
    },
    {
      "x": -18,
      "y": 0,
      "z": -13,
      "name": "Soil_Ash"
    },
    {
      "x": -18,
      "y": 1,
      "z": -13,
      "name": "Soil_Ash"
    },
    {
      "x": -18,
      "y": 2,
      "z": -13,
      "name": "Soil_Ash"
    },
    {
      "x": -18,
      "y": 0,
      "z": -12,
      "name": "Soil_Ash"
    },
    {
      "x": -18,
      "y": 1,
      "z": -12,
      "name": "Soil_Ash"
    },
    {
      "x": -18,
      "y": 2,
      "z": -12,
      "name": "Soil_Ash"
    },
    {
      "x": -18,
      "y": 3,
      "z": -12,
      "name": "Soil_Ash"
    },
    {
      "x": -18,
      "y": 0,
      "z": -11,
      "name": "Soil_Ash"
    },
    {
      "x": -18,
      "y": 1,
      "z": -11,
      "name": "Soil_Ash"
    },
    {
      "x": -18,
      "y": 2,
      "z": -11,
      "name": "Soil_Ash"
    },
    {
      "x": -18,
      "y": 3,
      "z": -11,
      "name": "Soil_Ash"
    },
    {
      "x": -18,
      "y": 4,
      "z": -11,
      "name": "Soil_Ash"
    },
    {
      "x": -18,
      "y": 0,
      "z": -10,
      "name": "Soil_Ash"
    },
    {
      "x": -18,
      "y": 1,
      "z": -10,
      "name": "Soil_Ash"
    },
    {
      "x": -18,
      "y": 2,
      "z": -10,
      "name": "Soil_Ash"
    },
    {
      "x": -18,
      "y": 3,
      "z": -10,
      "name": "Soil_Ash"
    },
    {
      "x": -18,
      "y": 4,
      "z": -10,
      "name": "Soil_Ash"
    },
    {
      "x": -18,
      "y": 0,
      "z": -9,
      "name": "Soil_Ash"
    },
    {
      "x": -18,
      "y": 1,
      "z": -9,
      "name": "Soil_Ash"
    },
    {
      "x": -18,
      "y": 2,
      "z": -9,
      "name": "Soil_Ash"
    },
    {
      "x": -18,
      "y": 3,
      "z": -9,
      "name": "Soil_Ash"
    },
    {
      "x": -18,
      "y": 4,
      "z": -9,
      "name": "Soil_Ash"
    },
    {
      "x": -18,
      "y": 5,
      "z": -9,
      "name": "Soil_Ash"
    },
    {
      "x": -18,
      "y": 0,
      "z": -8,
      "name": "Soil_Ash"
    },
    {
      "x": -18,
      "y": 1,
      "z": -8,
      "name": "Soil_Ash"
    },
    {
      "x": -18,
      "y": 2,
      "z": -8,
      "name": "Soil_Ash"
    },
    {
      "x": -18,
      "y": 3,
      "z": -8,
      "name": "Soil_Ash"
    },
    {
      "x": -18,
      "y": 4,
      "z": -8,
      "name": "Soil_Ash"
    },
    {
      "x": -18,
      "y": 5,
      "z": -8,
      "name": "Soil_Ash"
    },
    {
      "x": -18,
      "y": 6,
      "z": -8,
      "name": "Plant_Bramble_Dead_Twisted"
    },
    {
      "x": -18,
      "y": 0,
      "z": -7,
      "name": "Soil_Ash"
    },
    {
      "x": -18,
      "y": 1,
      "z": -7,
      "name": "Soil_Ash"
    },
    {
      "x": -18,
      "y": 2,
      "z": -7,
      "name": "Soil_Ash"
    },
    {
      "x": -18,
      "y": 3,
      "z": -7,
      "name": "Soil_Ash"
    },
    {
      "x": -18,
      "y": 4,
      "z": -7,
      "name": "Soil_Ash"
    },
    {
      "x": -18,
      "y": 5,
      "z": -7,
      "name": "Soil_Ash"
    },
    {
      "x": -18,
      "y": 0,
      "z": -6,
      "name": "Soil_Ash"
    },
    {
      "x": -18,
      "y": 1,
      "z": -6,
      "name": "Soil_Ash"
    },
    {
      "x": -18,
      "y": 2,
      "z": -6,
      "name": "Soil_Ash"
    },
    {
      "x": -18,
      "y": 3,
      "z": -6,
      "name": "Soil_Ash"
    },
    {
      "x": -18,
      "y": 4,
      "z": -6,
      "name": "Soil_Ash"
    },
    {
      "x": -18,
      "y": 5,
      "z": -6,
      "name": "Soil_Ash"
    },
    {
      "x": -18,
      "y": 6,
      "z": -6,
      "name": "Soil_Ash"
    },
    {
      "x": -18,
      "y": 0,
      "z": -5,
      "name": "Soil_Ash"
    },
    {
      "x": -18,
      "y": 1,
      "z": -5,
      "name": "Soil_Ash"
    },
    {
      "x": -18,
      "y": 2,
      "z": -5,
      "name": "Soil_Ash"
    },
    {
      "x": -18,
      "y": 3,
      "z": -5,
      "name": "Soil_Ash"
    },
    {
      "x": -18,
      "y": 4,
      "z": -5,
      "name": "Soil_Ash"
    },
    {
      "x": -18,
      "y": 5,
      "z": -5,
      "name": "Soil_Ash"
    },
    {
      "x": -18,
      "y": 6,
      "z": -5,
      "name": "Soil_Ash"
    },
    {
      "x": -18,
      "y": 7,
      "z": -5,
      "name": "Plant_Bramble_Dead_Twisted"
    },
    {
      "x": -18,
      "y": 0,
      "z": -4,
      "name": "Soil_Ash"
    },
    {
      "x": -18,
      "y": 1,
      "z": -4,
      "name": "Soil_Ash"
    },
    {
      "x": -18,
      "y": 2,
      "z": -4,
      "name": "Soil_Ash"
    },
    {
      "x": -18,
      "y": 3,
      "z": -4,
      "name": "Soil_Ash"
    },
    {
      "x": -18,
      "y": 4,
      "z": -4,
      "name": "Soil_Ash"
    },
    {
      "x": -18,
      "y": 5,
      "z": -4,
      "name": "Soil_Ash"
    },
    {
      "x": -18,
      "y": 6,
      "z": -4,
      "name": "Soil_Ash"
    },
    {
      "x": -18,
      "y": 7,
      "z": -4,
      "name": "Plant_Bramble_Dead_Twisted"
    },
    {
      "x": -18,
      "y": 20,
      "z": -4,
      "name": "Rock_Magma_Cooled"
    },
    {
      "x": -18,
      "y": 21,
      "z": -4,
      "name": "Ore_Adamantite_Magma_Cracked"
    },
    {
      "x": -18,
      "y": 0,
      "z": -3,
      "name": "Soil_Ash"
    },
    {
      "x": -18,
      "y": 1,
      "z": -3,
      "name": "Soil_Ash"
    },
    {
      "x": -18,
      "y": 2,
      "z": -3,
      "name": "Soil_Ash"
    },
    {
      "x": -18,
      "y": 3,
      "z": -3,
      "name": "Soil_Ash"
    },
    {
      "x": -18,
      "y": 4,
      "z": -3,
      "name": "Soil_Ash"
    },
    {
      "x": -18,
      "y": 5,
      "z": -3,
      "name": "Soil_Ash"
    },
    {
      "x": -18,
      "y": 6,
      "z": -3,
      "name": "Soil_Ash"
    },
    {
      "x": -18,
      "y": 14,
      "z": -3,
      "name": "Rock_Magma_Cooled"
    },
    {
      "x": -18,
      "y": 15,
      "z": -3,
      "name": "Rock_Magma_Cooled"
    },
    {
      "x": -18,
      "y": 19,
      "z": -3,
      "name": "Rock_Magma_Cooled"
    },
    {
      "x": -18,
      "y": 20,
      "z": -3,
      "name": "Ore_Adamantite_Magma_Cracked"
    },
    {
      "x": -18,
      "y": 21,
      "z": -3,
      "name": "Rock_Magma_Cooled"
    },
    {
      "x": -18,
      "y": 22,
      "z": -3,
      "name": "Ore_Adamantite_Magma_Cracked"
    },
    {
      "x": -18,
      "y": 0,
      "z": -2,
      "name": "Soil_Ash"
    },
    {
      "x": -18,
      "y": 1,
      "z": -2,
      "name": "Soil_Ash"
    },
    {
      "x": -18,
      "y": 2,
      "z": -2,
      "name": "Soil_Ash"
    },
    {
      "x": -18,
      "y": 3,
      "z": -2,
      "name": "Soil_Ash"
    },
    {
      "x": -18,
      "y": 4,
      "z": -2,
      "name": "Soil_Ash"
    },
    {
      "x": -18,
      "y": 5,
      "z": -2,
      "name": "Soil_Ash"
    },
    {
      "x": -18,
      "y": 6,
      "z": -2,
      "name": "Soil_Ash"
    },
    {
      "x": -18,
      "y": 14,
      "z": -2,
      "name": "Ore_Adamantite_Magma_Cracked"
    },
    {
      "x": -18,
      "y": 15,
      "z": -2,
      "name": "Ore_Adamantite_Magma_Cracked"
    },
    {
      "x": -18,
      "y": 16,
      "z": -2,
      "name": "Rock_Magma_Cooled"
    },
    {
      "x": -18,
      "y": 19,
      "z": -2,
      "name": "Ore_Adamantite_Magma_Cracked"
    },
    {
      "x": -18,
      "y": 20,
      "z": -2,
      "name": "Ore_Adamantite_Magma_Cracked"
    },
    {
      "x": -18,
      "y": 21,
      "z": -2,
      "name": "Rock_Magma_Cooled"
    },
    {
      "x": -18,
      "y": 22,
      "z": -2,
      "name": "Ore_Adamantite_Magma_Cracked"
    },
    {
      "x": -18,
      "y": 0,
      "z": -1,
      "name": "Soil_Ash"
    },
    {
      "x": -18,
      "y": 1,
      "z": -1,
      "name": "Soil_Ash"
    },
    {
      "x": -18,
      "y": 2,
      "z": -1,
      "name": "Soil_Ash"
    },
    {
      "x": -18,
      "y": 3,
      "z": -1,
      "name": "Soil_Ash"
    },
    {
      "x": -18,
      "y": 4,
      "z": -1,
      "name": "Soil_Ash"
    },
    {
      "x": -18,
      "y": 5,
      "z": -1,
      "name": "Soil_Ash"
    },
    {
      "x": -18,
      "y": 6,
      "z": -1,
      "name": "Soil_Ash"
    },
    {
      "x": -18,
      "y": 14,
      "z": -1,
      "name": "Ore_Adamantite_Magma_Cracked"
    },
    {
      "x": -18,
      "y": 15,
      "z": -1,
      "name": "Ore_Adamantite_Magma_Cracked"
    },
    {
      "x": -18,
      "y": 16,
      "z": -1,
      "name": "Rock_Magma_Cooled"
    },
    {
      "x": -18,
      "y": 18,
      "z": -1,
      "name": "Rock_Magma_Cooled"
    },
    {
      "x": -18,
      "y": 19,
      "z": -1,
      "name": "Ore_Adamantite_Magma_Cracked"
    },
    {
      "x": -18,
      "y": 20,
      "z": -1,
      "name": "Ore_Adamantite_Magma_Cracked"
    },
    {
      "x": -18,
      "y": 21,
      "z": -1,
      "name": "Ore_Adamantite_Magma_Cracked"
    },
    {
      "x": -18,
      "y": 22,
      "z": -1,
      "name": "Ore_Adamantite_Magma_Cracked"
    },
    {
      "x": -18,
      "y": 23,
      "z": -1,
      "name": "Rock_Magma_Cooled"
    },
    {
      "x": -18,
      "y": 0,
      "z": 0,
      "name": "Soil_Ash"
    },
    {
      "x": -18,
      "y": 1,
      "z": 0,
      "name": "Soil_Ash"
    },
    {
      "x": -18,
      "y": 2,
      "z": 0,
      "name": "Soil_Ash"
    },
    {
      "x": -18,
      "y": 3,
      "z": 0,
      "name": "Soil_Ash"
    },
    {
      "x": -18,
      "y": 4,
      "z": 0,
      "name": "Soil_Ash"
    },
    {
      "x": -18,
      "y": 5,
      "z": 0,
      "name": "Soil_Ash"
    },
    {
      "x": -18,
      "y": 6,
      "z": 0,
      "name": "Soil_Ash"
    },
    {
      "x": -18,
      "y": 18,
      "z": 0,
      "name": "Rock_Magma_Cooled"
    },
    {
      "x": -18,
      "y": 19,
      "z": 0,
      "name": "Ore_Adamantite_Magma_Cracked"
    },
    {
      "x": -18,
      "y": 20,
      "z": 0,
      "name": "Rock_Magma_Cooled"
    },
    {
      "x": -18,
      "y": 21,
      "z": 0,
      "name": "Ore_Adamantite_Magma_Cracked"
    },
    {
      "x": -18,
      "y": 22,
      "z": 0,
      "name": "Rock_Magma_Cooled"
    },
    {
      "x": -18,
      "y": 23,
      "z": 0,
      "name": "Rock_Magma_Cooled"
    },
    {
      "x": -18,
      "y": 24,
      "z": 0,
      "name": "Plant_Crop_Mushroom_Glowing_Purple"
    },
    {
      "x": -18,
      "y": 0,
      "z": 1,
      "name": "Soil_Ash"
    },
    {
      "x": -18,
      "y": 1,
      "z": 1,
      "name": "Soil_Sand_Ashen"
    },
    {
      "x": -18,
      "y": 2,
      "z": 1,
      "name": "Soil_Ash"
    },
    {
      "x": -18,
      "y": 3,
      "z": 1,
      "name": "Soil_Ash"
    },
    {
      "x": -18,
      "y": 4,
      "z": 1,
      "name": "Soil_Ash"
    },
    {
      "x": -18,
      "y": 5,
      "z": 1,
      "name": "Soil_Ash"
    },
    {
      "x": -18,
      "y": 6,
      "z": 1,
      "name": "Soil_Ash"
    },
    {
      "x": -18,
      "y": 18,
      "z": 1,
      "name": "Ore_Adamantite_Magma_Cracked"
    },
    {
      "x": -18,
      "y": 19,
      "z": 1,
      "name": "Ore_Adamantite_Magma_Cracked"
    },
    {
      "x": -18,
      "y": 20,
      "z": 1,
      "name": "Rock_Magma_Cooled"
    },
    {
      "x": -18,
      "y": 21,
      "z": 1,
      "name": "Ore_Adamantite_Magma_Cracked"
    },
    {
      "x": -18,
      "y": 22,
      "z": 1,
      "name": "Ore_Adamantite_Magma_Cracked"
    },
    {
      "x": -18,
      "y": 23,
      "z": 1,
      "name": "Ore_Adamantite_Magma_Cracked"
    },
    {
      "x": -18,
      "y": 0,
      "z": 2,
      "name": "Soil_Ash"
    },
    {
      "x": -18,
      "y": 1,
      "z": 2,
      "name": "Soil_Sand_Ashen"
    },
    {
      "x": -18,
      "y": 2,
      "z": 2,
      "name": "Soil_Ash"
    },
    {
      "x": -18,
      "y": 3,
      "z": 2,
      "name": "Soil_Ash"
    },
    {
      "x": -18,
      "y": 4,
      "z": 2,
      "name": "Soil_Ash"
    },
    {
      "x": -18,
      "y": 5,
      "z": 2,
      "name": "Soil_Ash"
    },
    {
      "x": -18,
      "y": 6,
      "z": 2,
      "name": "Soil_Ash"
    },
    {
      "x": -18,
      "y": 19,
      "z": 2,
      "name": "Rock_Magma_Cooled"
    },
    {
      "x": -18,
      "y": 20,
      "z": 2,
      "name": "Ore_Adamantite_Magma_Cracked"
    },
    {
      "x": -18,
      "y": 21,
      "z": 2,
      "name": "Rock_Magma_Cooled"
    },
    {
      "x": -18,
      "y": 22,
      "z": 2,
      "name": "Ore_Adamantite_Magma_Cracked"
    },
    {
      "x": -18,
      "y": 23,
      "z": 2,
      "name": "Rock_Magma_Cooled"
    },
    {
      "x": -18,
      "y": 0,
      "z": 3,
      "name": "Soil_Ash"
    },
    {
      "x": -18,
      "y": 1,
      "z": 3,
      "name": "Soil_Sand_Ashen"
    },
    {
      "x": -18,
      "y": 2,
      "z": 3,
      "name": "Soil_Ash"
    },
    {
      "x": -18,
      "y": 3,
      "z": 3,
      "name": "Soil_Ash"
    },
    {
      "x": -18,
      "y": 4,
      "z": 3,
      "name": "Soil_Ash"
    },
    {
      "x": -18,
      "y": 5,
      "z": 3,
      "name": "Soil_Ash"
    },
    {
      "x": -18,
      "y": 19,
      "z": 3,
      "name": "Ore_Adamantite_Magma_Cracked"
    },
    {
      "x": -18,
      "y": 20,
      "z": 3,
      "name": "Rock_Magma_Cooled"
    },
    {
      "x": -18,
      "y": 21,
      "z": 3,
      "name": "Rock_Magma_Cooled"
    },
    {
      "x": -18,
      "y": 22,
      "z": 3,
      "name": "Rock_Magma_Cooled"
    },
    {
      "x": -18,
      "y": 23,
      "z": 3,
      "name": "Rock_Magma_Cooled"
    },
    {
      "x": -18,
      "y": 0,
      "z": 4,
      "name": "Soil_Sand_Ashen"
    },
    {
      "x": -18,
      "y": 1,
      "z": 4,
      "name": "Soil_Sand_Ashen"
    },
    {
      "x": -18,
      "y": 2,
      "z": 4,
      "name": "Soil_Sand_Ashen"
    },
    {
      "x": -18,
      "y": 3,
      "z": 4,
      "name": "Soil_Ash"
    },
    {
      "x": -18,
      "y": 4,
      "z": 4,
      "name": "Soil_Ash"
    },
    {
      "x": -18,
      "y": 5,
      "z": 4,
      "name": "Soil_Ash"
    },
    {
      "x": -18,
      "y": 20,
      "z": 4,
      "name": "Ore_Adamantite_Magma_Cracked"
    },
    {
      "x": -18,
      "y": 21,
      "z": 4,
      "name": "Rock_Magma_Cooled"
    },
    {
      "x": -18,
      "y": 22,
      "z": 4,
      "name": "Rock_Magma_Cooled"
    },
    {
      "x": -18,
      "y": 0,
      "z": 5,
      "name": "Soil_Ash"
    },
    {
      "x": -18,
