{
  "version": 8,
  "blockIdVersion": 11,
  "anchorX": 0,
  "anchorY": 0,
  "anchorZ": 0,
  "blocks": [
    {
      "x": -39,
      "y": 0,
      "z": 1,
      "name": "Soil_Ash"
    },
    {
      "x": -39,
      "y": 0,
      "z": 2,
      "name": "Soil_Ash"
    },
    {
      "x": -39,
      "y": 0,
      "z": 3,
      "name": "Soil_Sand_Ashen"
    },
    {
      "x": -39,
      "y": 0,
      "z": 4,
      "name": "Soil_Ash"
    },
    {
      "x": -39,
      "y": 0,
      "z": 5,
      "name": "Soil_Sand_Ashen"
    },
    {
      "x": -39,
      "y": 0,
      "z": 6,
      "name": "Soil_Ash"
    },
    {
      "x": -39,
      "y": 0,
      "z": 7,
      "name": "Soil_Sand_Ashen"
    },
    {
      "x": -39,
      "y": 0,
      "z": 8,
      "name": "Soil_Ash"
    },
    {
      "x": -39,
      "y": 0,
      "z": 9,
      "name": "Soil_Ash"
    },
    {
      "x": -39,
      "y": 0,
      "z": 10,
      "name": "Soil_Ash"
    },
    {
      "x": -39,
      "y": 0,
      "z": 11,
      "name": "Soil_Ash"
    },
    {
      "x": -39,
      "y": 23,
      "z": 12,
      "name": "Rock_Magma_Cooled"
    },
    {
      "x": -39,
      "y": 23,
      "z": 13,
      "name": "Rock_Magma_Cooled"
    },
    {
      "x": -39,
      "y": 24,
      "z": 13,
      "name": "Plant_Moss_Rug_Pink",
      "support": 15
    },
    {
      "x": -39,
      "y": 23,
      "z": 14,
      "name": "Ore_Adamantite_Magma_Cracked"
    },
    {
      "x": -38,
      "y": 0,
      "z": -2,
      "name": "Soil_Sand_Ashen"
    },
    {
      "x": -38,
      "y": 0,
      "z": -1,
      "name": "Soil_Ash"
    },
    {
      "x": -38,
      "y": 0,
      "z": 0,
      "name": "Soil_Ash"
    },
    {
      "x": -38,
      "y": 1,
      "z": 0,
      "name": "Soil_Sand_Ashen"
    },
    {
      "x": -38,
      "y": 0,
      "z": 1,
      "name": "Soil_Ash"
    },
    {
      "x": -38,
      "y": 1,
      "z": 1,
      "name": "Soil_Sand_Ashen"
    },
    {
      "x": -38,
      "y": 0,
      "z": 2,
      "name": "Soil_Ash"
    },
    {
      "x": -38,
      "y": 1,
      "z": 2,
      "name": "Soil_Sand_Ashen"
    },
    {
      "x": -38,
      "y": 0,
      "z": 3,
      "name": "Soil_Ash"
    },
    {
      "x": -38,
      "y": 1,
      "z": 3,
      "name": "Soil_Sand_Ashen"
    },
    {
      "x": -38,
      "y": 0,
      "z": 4,
      "name": "Soil_Ash"
    },
    {
      "x": -38,
      "y": 1,
      "z": 4,
      "name": "Soil_Sand_Ashen"
    },
    {
      "x": -38,
      "y": 0,
      "z": 5,
      "name": "Soil_Ash"
    },
    {
      "x": -38,
      "y": 1,
      "z": 5,
      "name": "Soil_Ash"
    },
    {
      "x": -38,
      "y": 0,
      "z": 6,
      "name": "Soil_Ash"
    },
    {
      "x": -38,
      "y": 1,
      "z": 6,
      "name": "Soil_Ash"
    },
    {
      "x": -38,
      "y": 0,
      "z": 7,
      "name": "Soil_Ash"
    },
    {
      "x": -38,
      "y": 1,
      "z": 7,
      "name": "Soil_Ash"
    },
    {
      "x": -38,
      "y": 0,
      "z": 8,
      "name": "Soil_Ash"
    },
    {
      "x": -38,
      "y": 1,
      "z": 8,
      "name": "Soil_Ash"
    },
    {
      "x": -38,
      "y": 0,
      "z": 9,
      "name": "Soil_Ash"
    },
    {
      "x": -38,
      "y": 1,
      "z": 9,
      "name": "Soil_Ash"
    },
    {
      "x": -38,
      "y": 0,
      "z": 10,
      "name": "Soil_Ash"
    },
    {
      "x": -38,
      "y": 0,
      "z": 11,
      "name": "Soil_Ash"
    },
    {
      "x": -38,
      "y": 23,
      "z": 11,
      "name": "Rock_Magma_Cooled"
    },
    {
      "x": -38,
      "y": 0,
      "z": 12,
      "name": "Soil_Sand_Ashen"
    },
    {
      "x": -38,
      "y": 22,
      "z": 12,
      "name": "Rock_Magma_Cooled"
    },
    {
      "x": -38,
      "y": 23,
      "z": 12,
      "name": "Rock_Magma_Cooled"
    },
    {
      "x": -38,
      "y": 24,
      "z": 12,
      "name": "Ore_Adamantite_Magma_Cracked"
    },
    {
      "x": -38,
      "y": 22,
      "z": 13,
      "name": "Rock_Magma_Cooled"
    },
    {
      "x": -38,
      "y": 23,
      "z": 13,
      "name": "Rock_Magma_Cooled"
    },
    {
      "x": -38,
      "y": 24,
      "z": 13,
      "name": "Ore_Adamantite_Magma_Cracked"
    },
    {
      "x": -38,
      "y": 25,
      "z": 13,
      "name": "Plant_Moss_Rug_Pink",
      "support": 15
    },
    {
      "x": -38,
      "y": 22,
      "z": 14,
      "name": "Ore_Adamantite_Magma_Cracked"
    },
    {
      "x": -38,
      "y": 23,
      "z": 14,
      "name": "Ore_Adamantite_Magma_Cracked"
    },
    {
      "x": -38,
      "y": 24,
      "z": 14,
      "name": "Ore_Adamantite_Magma_Cracked"
    },
    {
      "x": -38,
      "y": 25,
      "z": 14,
      "name": "Plant_Moss_Rug_Pink",
      "support": 15
    },
    {
      "x": -38,
      "y": 23,
      "z": 15,
      "name": "Ore_Adamantite_Magma_Cracked"
    },
    {
      "x": -38,
      "y": 24,
      "z": 15,
      "name": "Plant_Moss_Rug_Pink",
      "support": 15
    },
    {
      "x": -38,
      "y": 23,
      "z": 16,
      "name": "Ore_Adamantite_Magma_Cracked"
    },
    {
      "x": -38,
      "y": 24,
      "z": 16,
      "name": "Plant_Moss_Rug_Pink",
      "support": 15
    },
    {
      "x": -37,
      "y": 0,
      "z": -3,
      "name": "Soil_Sand_Ashen"
    },
    {
      "x": -37,
      "y": 1,
      "z": -3,
      "name": "Soil_Sand_Ashen"
    },
    {
      "x": -37,
      "y": 0,
      "z": -2,
      "name": "Soil_Sand_Ashen"
    },
    {
      "x": -37,
      "y": 1,
      "z": -2,
      "name": "Soil_Sand_Ashen"
    },
    {
      "x": -37,
      "y": 0,
      "z": -1,
      "name": "Soil_Sand_Ashen"
    },
    {
      "x": -37,
      "y": 1,
      "z": -1,
      "name": "Soil_Sand_Ashen"
    },
    {
      "x": -37,
      "y": 0,
      "z": 0,
      "name": "Soil_Sand_Ashen"
    },
    {
      "x": -37,
      "y": 1,
      "z": 0,
      "name": "Soil_Sand_Ashen"
    },
    {
      "x": -37,
      "y": 0,
      "z": 1,
      "name": "Soil_Sand_Ashen"
    },
    {
      "x": -37,
      "y": 1,
      "z": 1,
      "name": "Soil_Sand_Ashen"
    },
    {
      "x": -37,
      "y": 2,
      "z": 1,
      "name": "Soil_Sand_Ashen"
    },
    {
      "x": -37,
      "y": 0,
      "z": 2,
      "name": "Soil_Ash"
    },
    {
      "x": -37,
      "y": 1,
      "z": 2,
      "name": "Soil_Ash"
    },
    {
      "x": -37,
      "y": 2,
      "z": 2,
      "name": "Soil_Sand_Ashen"
    },
    {
      "x": -37,
      "y": 0,
      "z": 3,
      "name": "Soil_Ash"
    },
    {
      "x": -37,
      "y": 1,
      "z": 3,
      "name": "Soil_Sand_Ashen"
    },
    {
      "x": -37,
      "y": 2,
      "z": 3,
      "name": "Soil_Sand_Ashen"
    },
    {
      "x": -37,
      "y": 0,
      "z": 4,
      "name": "Soil_Ash"
    },
    {
      "x": -37,
      "y": 1,
      "z": 4,
      "name": "Soil_Ash"
    },
    {
      "x": -37,
      "y": 2,
      "z": 4,
      "name": "Soil_Sand_Ashen"
    },
    {
      "x": -37,
      "y": 0,
      "z": 5,
      "name": "Soil_Ash"
    },
    {
      "x": -37,
      "y": 1,
      "z": 5,
      "name": "Soil_Ash"
    },
    {
      "x": -37,
      "y": 2,
      "z": 5,
      "name": "Soil_Ash"
    },
    {
      "x": -37,
      "y": 0,
      "z": 6,
      "name": "Soil_Ash"
    },
    {
      "x": -37,
      "y": 1,
      "z": 6,
      "name": "Soil_Ash"
    },
    {
      "x": -37,
      "y": 2,
      "z": 6,
      "name": "Soil_Ash"
    },
    {
      "x": -37,
      "y": 0,
      "z": 7,
      "name": "Soil_Ash"
    },
    {
      "x": -37,
      "y": 1,
      "z": 7,
      "name": "Soil_Ash"
    },
    {
      "x": -37,
      "y": 2,
      "z": 7,
      "name": "Soil_Ash"
    },
    {
      "x": -37,
      "y": 0,
      "z": 8,
      "name": "Soil_Ash"
    },
    {
      "x": -37,
      "y": 1,
      "z": 8,
      "name": "Soil_Ash"
    },
    {
      "x": -37,
      "y": 0,
      "z": 9,
      "name": "Soil_Ash"
    },
    {
      "x": -37,
      "y": 1,
      "z": 9,
      "name": "Soil_Ash"
    },
    {
      "x": -37,
      "y": 0,
      "z": 10,
      "name": "Soil_Ash"
    },
    {
      "x": -37,
      "y": 1,
      "z": 10,
      "name": "Soil_Ash"
    },
    {
      "x": -37,
      "y": 0,
      "z": 11,
      "name": "Soil_Ash"
    },
    {
      "x": -37,
      "y": 1,
      "z": 11,
      "name": "Soil_Ash"
    },
    {
      "x": -37,
      "y": 23,
      "z": 11,
      "name": "Rock_Magma_Cooled"
    },
    {
      "x": -37,
      "y": 0,
      "z": 12,
      "name": "Soil_Ash"
    },
    {
      "x": -37,
      "y": 22,
      "z": 12,
      "name": "Rock_Magma_Cooled"
    },
    {
      "x": -37,
      "y": 23,
      "z": 12,
      "name": "Ore_Adamantite_Magma_Cracked"
    },
    {
      "x": -37,
      "y": 24,
      "z": 12,
      "name": "Ore_Adamantite_Magma_Cracked"
    },
    {
      "x": -37,
      "y": 25,
      "z": 12,
      "name": "Plant_Moss_Rug_Pink",
      "support": 15
    },
    {
      "x": -37,
      "y": 0,
      "z": 13,
      "name": "Soil_Ash"
    },
    {
      "x": -37,
      "y": 22,
      "z": 13,
      "name": "Rock_Magma_Cooled"
    },
    {
      "x": -37,
      "y": 23,
      "z": 13,
      "name": "Ore_Adamantite_Magma_Cracked"
    },
    {
      "x": -37,
      "y": 24,
      "z": 13,
      "name": "Rock_Magma_Cooled"
    },
    {
      "x": -37,
      "y": 25,
      "z": 13,
      "name": "Plant_Moss_Rug_Pink",
      "support": 15
    },
    {
      "x": -37,
      "y": 22,
      "z": 14,
      "name": "Rock_Magma_Cooled"
    },
    {
      "x": -37,
      "y": 23,
      "z": 14,
      "name": "Ore_Adamantite_Magma_Cracked"
    },
    {
      "x": -37,
      "y": 24,
      "z": 14,
      "name": "Ore_Adamantite_Magma_Cracked"
    },
    {
      "x": -37,
      "y": 22,
      "z": 15,
      "name": "Ore_Adamantite_Magma_Cracked"
    },
    {
      "x": -37,
      "y": 23,
      "z": 15,
      "name": "Rock_Magma_Cooled"
    },
    {
      "x": -37,
      "y": 24,
      "z": 15,
      "name": "Rock_Magma_Cooled"
    },
    {
      "x": -37,
      "y": 25,
      "z": 15,
      "name": "Plant_Moss_Rug_Pink",
      "support": 15
    },
    {
      "x": -37,
      "y": 22,
      "z": 16,
      "name": "Rock_Magma_Cooled"
    },
    {
      "x": -37,
      "y": 23,
      "z": 16,
      "name": "Rock_Magma_Cooled"
    },
    {
      "x": -37,
      "y": 24,
      "z": 16,
      "name": "Rock_Magma_Cooled"
    },
    {
      "x": -37,
      "y": 22,
      "z": 17,
      "name": "Ore_Adamantite_Magma_Cracked"
    },
    {
      "x": -37,
      "y": 23,
      "z": 17,
      "name": "Rock_Magma_Cooled"
    },
    {
      "x": -37,
      "y": 24,
      "z": 17,
      "name": "Plant_Moss_Rug_Pink",
      "support": 15
    },
    {
      "x": -36,
      "y": 0,
      "z": -5,
      "name": "Soil_Ash"
    },
    {
      "x": -36,
      "y": 0,
      "z": -4,
      "name": "Soil_Sand_Ashen"
    },
    {
      "x": -36,
      "y": 1,
      "z": -4,
      "name": "Soil_Sand_Ashen"
    },
    {
      "x": -36,
      "y": 0,
      "z": -3,
      "name": "Soil_Ash"
    },
    {
      "x": -36,
      "y": 1,
      "z": -3,
      "name": "Soil_Sand_Ashen"
    },
    {
      "x": -36,
      "y": 0,
      "z": -2,
      "name": "Soil_Ash"
    },
    {
      "x": -36,
      "y": 1,
      "z": -2,
      "name": "Soil_Sand_Ashen"
    },
    {
      "x": -36,
      "y": 2,
      "z": -2,
      "name": "Soil_Sand_Ashen"
    },
    {
      "x": -36,
      "y": 0,
      "z": -1,
      "name": "Soil_Sand_Ashen"
    },
    {
      "x": -36,
      "y": 1,
      "z": -1,
      "name": "Soil_Sand_Ashen"
    },
    {
      "x": -36,
      "y": 2,
      "z": -1,
      "name": "Soil_Sand_Ashen"
    },
    {
      "x": -36,
      "y": 0,
      "z": 0,
      "name": "Soil_Sand_Ashen"
    },
    {
      "x": -36,
      "y": 1,
      "z": 0,
      "name": "Soil_Sand_Ashen"
    },
    {
      "x": -36,
      "y": 2,
      "z": 0,
      "name": "Soil_Sand_Ashen"
    },
    {
      "x": -36,
      "y": 0,
      "z": 1,
      "name": "Soil_Sand_Ashen"
    },
    {
      "x": -36,
      "y": 1,
      "z": 1,
      "name": "Soil_Sand_Ashen"
    },
    {
      "x": -36,
      "y": 2,
      "z": 1,
      "name": "Soil_Sand_Ashen"
    },
    {
      "x": -36,
      "y": 3,
      "z": 1,
      "name": "Soil_Sand_Ashen"
    },
    {
      "x": -36,
      "y": 0,
      "z": 2,
      "name": "Soil_Sand_Ashen"
    },
    {
      "x": -36,
      "y": 1,
      "z": 2,
      "name": "Soil_Ash"
    },
    {
      "x": -36,
      "y": 2,
      "z": 2,
      "name": "Soil_Sand_Ashen"
    },
    {
      "x": -36,
      "y": 3,
      "z": 2,
      "name": "Soil_Sand_Ashen"
    },
    {
      "x": -36,
      "y": 0,
      "z": 3,
      "name": "Soil_Ash"
    },
    {
      "x": -36,
      "y": 1,
      "z": 3,
      "name": "Soil_Sand_Ashen"
    },
    {
      "x": -36,
      "y": 2,
      "z": 3,
      "name": "Soil_Ash"
    },
    {
      "x": -36,
      "y": 3,
      "z": 3,
      "name": "Soil_Ash"
    },
    {
      "x": -36,
      "y": 0,
      "z": 4,
      "name": "Soil_Ash"
    },
    {
      "x": -36,
      "y": 1,
      "z": 4,
      "name": "Soil_Ash"
    },
    {
      "x": -36,
      "y": 2,
      "z": 4,
      "name": "Soil_Ash"
    },
    {
      "x": -36,
      "y": 3,
      "z": 4,
      "name": "Soil_Sand_Ashen"
    },
    {
      "x": -36,
      "y": 0,
      "z": 5,
      "name": "Soil_Ash"
    },
    {
      "x": -36,
      "y": 1,
      "z": 5,
      "name": "Soil_Ash"
    },
    {
      "x": -36,
      "y": 2,
      "z": 5,
      "name": "Soil_Ash"
    },
    {
      "x": -36,
      "y": 0,
      "z": 6,
      "name": "Soil_Ash"
    },
    {
      "x": -36,
      "y": 1,
      "z": 6,
      "name": "Soil_Ash"
    },
    {
      "x": -36,
      "y": 2,
      "z": 6,
      "name": "Soil_Ash"
    },
    {
      "x": -36,
      "y": 0,
      "z": 7,
      "name": "Soil_Ash"
    },
    {
      "x": -36,
      "y": 1,
      "z": 7,
      "name": "Soil_Ash"
    },
    {
      "x": -36,
      "y": 2,
      "z": 7,
      "name": "Soil_Ash"
    },
    {
      "x": -36,
      "y": 0,
      "z": 8,
      "name": "Soil_Ash"
    },
    {
      "x": -36,
      "y": 1,
      "z": 8,
      "name": "Soil_Ash"
    },
    {
      "x": -36,
      "y": 2,
      "z": 8,
      "name": "Soil_Ash"
    },
    {
      "x": -36,
      "y": 0,
      "z": 9,
      "name": "Soil_Ash"
    },
    {
      "x": -36,
      "y": 1,
      "z": 9,
      "name": "Soil_Ash"
    },
    {
      "x": -36,
      "y": 2,
      "z": 9,
      "name": "Soil_Ash"
    },
    {
      "x": -36,
      "y": 0,
      "z": 10,
      "name": "Soil_Ash"
    },
    {
      "x": -36,
      "y": 1,
      "z": 10,
      "name": "Soil_Ash"
    },
    {
      "x": -36,
      "y": 2,
      "z": 10,
      "name": "Soil_Ash"
    },
    {
      "x": -36,
      "y": 0,
      "z": 11,
      "name": "Soil_Ash"
    },
    {
      "x": -36,
      "y": 1,
      "z": 11,
      "name": "Soil_Ash"
    },
    {
      "x": -36,
      "y": 2,
      "z": 11,
      "name": "Soil_Ash"
    },
    {
      "x": -36,
      "y": 0,
      "z": 12,
      "name": "Soil_Ash"
    },
    {
      "x": -36,
      "y": 1,
      "z": 12,
      "name": "Soil_Ash"
    },
    {
      "x": -36,
      "y": 22,
      "z": 12,
      "name": "Ore_Adamantite_Magma_Cracked"
    },
    {
      "x": -36,
      "y": 23,
      "z": 12,
      "name": "Rock_Magma_Cooled"
    },
    {
      "x": -36,
      "y": 0,
      "z": 13,
      "name": "Soil_Ash"
    },
    {
      "x": -36,
      "y": 1,
      "z": 13,
      "name": "Soil_Sand_Ashen"
    },
    {
      "x": -36,
      "y": 21,
      "z": 13,
      "name": "Ore_Adamantite_Magma_Cracked"
    },
    {
      "x": -36,
      "y": 22,
      "z": 13,
      "name": "Rock_Magma_Cooled"
    },
    {
      "x": -36,
      "y": 23,
      "z": 13,
      "name": "Rock_Magma_Cooled"
    },
    {
      "x": -36,
      "y": 19,
      "z": 14,
      "name": "Ore_Adamantite_Magma_Cracked"
    },
    {
      "x": -36,
      "y": 20,
      "z": 14,
      "name": "Ore_Adamantite_Magma_Cracked"
    },
    {
      "x": -36,
      "y": 21,
      "z": 14,
      "name": "Ore_Adamantite_Magma_Cracked"
    },
    {
      "x": -36,
      "y": 22,
      "z": 14,
      "name": "Ore_Adamantite_Magma_Cracked"
    },
    {
      "x": -36,
      "y": 23,
      "z": 14,
      "name": "Ore_Adamantite_Magma_Cracked"
    },
    {
      "x": -36,
      "y": 19,
      "z": 15,
      "name": "Ore_Adamantite_Magma_Cracked"
    },
    {
      "x": -36,
      "y": 20,
      "z": 15,
      "name": "Rock_Magma_Cooled"
    },
    {
      "x": -36,
      "y": 21,
      "z": 15,
      "name": "Ore_Adamantite_Magma_Cracked"
    },
    {
      "x": -36,
      "y": 22,
      "z": 15,
      "name": "Ore_Adamantite_Magma_Cracked"
    },
    {
      "x": -36,
      "y": 23,
      "z": 15,
      "name": "Ore_Adamantite_Magma_Cracked"
    },
    {
      "x": -36,
      "y": 19,
      "z": 16,
      "name": "Ore_Adamantite_Magma_Cracked"
    },
    {
      "x": -36,
      "y": 20,
      "z": 16,
      "name": "Ore_Adamantite_Magma_Cracked"
    },
    {
      "x": -36,
      "y": 21,
      "z": 16,
      "name": "Rock_Magma_Cooled"
    },
    {
      "x": -36,
      "y": 22,
      "z": 16,
      "name": "Rock_Magma_Cooled"
    },
    {
      "x": -36,
      "y": 23,
      "z": 16,
      "name": "Ore_Adamantite_Magma_Cracked"
    },
    {
      "x": -36,
      "y": 19,
      "z": 17,
      "name": "Ore_Adamantite_Magma_Cracked"
    },
    {
      "x": -36,
      "y": 20,
      "z": 17,
      "name": "Rock_Magma_Cooled"
    },
    {
      "x": -36,
      "y": 21,
      "z": 17,
      "name": "Ore_Adamantite_Magma_Cracked"
    },
    {
      "x": -36,
      "y": 22,
      "z": 17,
      "name": "Rock_Magma_Cooled"
    },
    {
      "x": -36,
      "y": 23,
      "z": 17,
      "name": "Rock_Magma_Cooled"
    },
    {
      "x": -36,
      "y": 24,
      "z": 17,
      "name": "Plant_Moss_Rug_Pink",
      "support": 15
    },
    {
      "x": -36,
      "y": 19,
      "z": 18,
      "name": "Ore_Adamantite_Magma_Cracked"
    },
    {
      "x": -36,
      "y": 20,
      "z": 18,
      "name": "Rock_Magma_Cooled"
    },
    {
      "x": -36,
      "y": 21,
      "z": 18,
      "name": "Rock_Magma_Cooled"
    },
    {
      "x": -36,
      "y": 22,
      "z": 18,
      "name": "Rock_Magma_Cooled"
    },
    {
      "x": -36,
      "y": 20,
      "z": 19,
      "name": "Rock_Magma_Cooled"
    },
    {
      "x": -35,
      "y": 0,
      "z": -6,
      "name": "Soil_Ash"
    },
    {
      "x": -35,
      "y": 0,
      "z": -5,
      "name": "Soil_Sand_Ashen"
    },
    {
      "x": -35,
      "y": 1,
      "z": -5,
      "name": "Soil_Sand_Ashen"
    },
    {
      "x": -35,
      "y": 0,
      "z": -4,
      "name": "Soil_Sand_Ashen"
    },
    {
      "x": -35,
      "y": 1,
      "z": -4,
      "name": "Soil_Sand_Ashen"
    },
    {
      "x": -35,
      "y": 0,
      "z": -3,
      "name": "Soil_Ash"
    },
    {
      "x": -35,
      "y": 1,
      "z": -3,
      "name": "Soil_Sand_Ashen"
    },
    {
      "x": -35,
      "y": 2,
      "z": -3,
      "name": "Soil_Sand_Ashen"
    },
    {
      "x": -35,
      "y": 0,
      "z": -2,
      "name": "Soil_Ash"
    },
    {
      "x": -35,
      "y": 1,
      "z": -2,
      "name": "Soil_Sand_Ashen"
    },
    {
      "x": -35,
      "y": 2,
      "z": -2,
      "name": "Soil_Sand_Ashen"
    },
    {
      "x": -35,
      "y": 3,
      "z": -2,
      "name": "Soil_Sand_Ashen"
    },
    {
      "x": -35,
      "y": 0,
      "z": -1,
      "name": "Soil_Sand_Ashen"
    },
    {
      "x": -35,
      "y": 1,
      "z": -1,
      "name": "Soil_Sand_Ashen"
    },
    {
      "x": -35,
      "y": 2,
      "z": -1,
      "name": "Soil_Sand_Ashen"
    },
    {
      "x": -35,
      "y": 3,
      "z": -1,
      "name": "Soil_Sand_Ashen"
    },
    {
      "x": -35,
      "y": 0,
      "z": 0,
      "name": "Soil_Ash"
    },
    {
      "x": -35,
      "y": 1,
      "z": 0,
      "name": "Soil_Sand_Ashen"
    },
    {
      "x": -35,
      "y": 2,
      "z": 0,
      "name": "Soil_Sand_Ashen"
    },
    {
      "x": -35,
      "y": 3,
      "z": 0,
      "name": "Soil_Sand_Ashen"
    },
    {
      "x": -35,
      "y": 0,
      "z": 1,
      "name": "Soil_Ash"
    },
    {
      "x": -35,
      "y": 1,
      "z": 1,
      "name": "Soil_Sand_Ashen"
    },
    {
      "x": -35,
      "y": 2,
      "z": 1,
      "name": "Soil_Sand_Ashen"
    },
    {
      "x": -35,
      "y": 3,
      "z": 1,
      "name": "Soil_Sand_Ashen"
    },
    {
      "x": -35,
      "y": 0,
      "z": 2,
      "name": "Soil_Ash"
    },
    {
      "x": -35,
      "y": 1,
      "z": 2,
      "name": "Soil_Sand_Ashen"
    },
    {
      "x": -35,
      "y": 2,
      "z": 2,
      "name": "Soil_Ash"
    },
    {
      "x": -35,
      "y": 3,
      "z": 2,
      "name": "Soil_Sand_Ashen"
    },
    {
      "x": -35,
      "y": 4,
      "z": 2,
      "name": "Plant_Bramble_Dead_Twisted"
    },
    {
      "x": -35,
      "y": 0,
      "z": 3,
      "name": "Soil_Ash"
    },
    {
      "x": -35,
      "y": 1,
      "z": 3,
      "name": "Soil_Ash"
    },
    {
      "x": -35,
      "y": 2,
      "z": 3,
      "name": "Soil_Ash"
    },
    {
      "x": -35,
      "y": 3,
      "z": 3,
      "name": "Soil_Ash"
    },
    {
      "x": -35,
      "y": 0,
      "z": 4,
      "name": "Soil_Ash"
    },
    {
      "x": -35,
      "y": 1,
      "z": 4,
      "name": "Soil_Ash"
    },
    {
      "x": -35,
      "y": 2,
      "z": 4,
      "name": "Soil_Ash"
    },
    {
      "x": -35,
      "y": 3,
      "z": 4,
      "name": "Soil_Ash"
    },
    {
      "x": -35,
      "y": 0,
      "z": 5,
      "name": "Soil_Ash"
    },
    {
      "x": -35,
      "y": 1,
      "z": 5,
      "name": "Soil_Ash"
    },
    {
      "x": -35,
      "y": 2,
      "z": 5,
      "name": "Soil_Ash"
    },
    {
      "x": -35,
      "y": 3,
      "z": 5,
      "name": "Soil_Ash"
    },
    {
      "x": -35,
      "y": 0,
      "z": 6,
      "name": "Soil_Ash"
    },
    {
      "x": -35,
      "y": 1,
      "z": 6,
      "name": "Soil_Ash"
    },
    {
      "x": -35,
      "y": 2,
      "z": 6,
      "name": "Soil_Ash"
    },
    {
      "x": -35,
      "y": 3,
      "z": 6,
      "name": "Soil_Ash"
    },
    {
      "x": -35,
      "y": 4,
      "z": 6,
      "name": "Plant_Bramble_Dead_Twisted"
    },
    {
      "x": -35,
      "y": 0,
      "z": 7,
      "name": "Soil_Ash"
    },
    {
      "x": -35,
      "y": 1,
      "z": 7,
      "name": "Soil_Ash"
    },
    {
      "x": -35,
      "y": 2,
      "z": 7,
      "name": "Soil_Ash"
    },
    {
      "x": -35,
      "y": 3,
      "z": 7,
      "name": "Soil_Ash"
    },
    {
      "x": -35,
      "y": 25,
      "z": 7,
      "name": "Ore_Adamantite_Magma_Cracked"
    },
    {
      "x": -35,
      "y": 26,
      "z": 7,
      "name": "Rubble_Magma_Cooled",
      "support": 15
    },
    {
      "x": -35,
      "y": 0,
      "z": 8,
      "name": "Soil_Ash"
    },
    {
      "x": -35,
      "y": 1,
      "z": 8,
      "name": "Soil_Ash"
    },
    {
      "x": -35,
      "y": 2,
      "z": 8,
      "name": "Soil_Ash"
    },
    {
      "x": -35,
      "y": 3,
      "z": 8,
      "name": "Soil_Ash"
    },
    {
      "x": -35,
      "y": 25,
      "z": 8,
      "name": "Ore_Adamantite_Magma_Cracked"
    },
    {
      "x": -35,
      "y": 0,
      "z": 9,
      "name": "Soil_Ash"
    },
    {
      "x": -35,
      "y": 1,
      "z": 9,
      "name": "Soil_Ash"
    },
    {
      "x": -35,
      "y": 2,
      "z": 9,
      "name": "Soil_Ash"
    },
    {
      "x": -35,
      "y": 3,
      "z": 9,
      "name": "Soil_Ash"
    },
    {
      "x": -35,
      "y": 25,
      "z": 9,
      "name": "Rock_Magma_Cooled"
    },
    {
      "x": -35,
      "y": 26,
      "z": 9,
      "name": "Rock_Magma_Cooled"
    },
    {
      "x": -35,
      "y": 27,
      "z": 9,
      "name": "Plant_Moss_Rug_Pink",
      "support": 15
    },
    {
      "x": -35,
      "y": 0,
      "z": 10,
      "name": "Soil_Ash"
    },
    {
      "x": -35,
      "y": 1,
      "z": 10,
      "name": "Soil_Ash"
    },
    {
      "x": -35,
      "y": 2,
      "z": 10,
      "name": "Soil_Ash"
    },
    {
      "x": -35,
      "y": 3,
      "z": 10,
      "name": "Soil_Ash"
    },
    {
      "x": -35,
      "y": 26,
      "z": 10,
      "name": "Rock_Magma_Cooled"
    },
    {
      "x": -35,
      "y": 0,
      "z": 11,
      "name": "Soil_Ash"
    },
    {
      "x": -35,
      "y": 1,
      "z": 11,
      "name": "Soil_Ash"
    },
    {
      "x": -35,
      "y": 2,
      "z": 11,
      "name": "Soil_Ash"
    },
    {
      "x": -35,
      "y": 3,
      "z": 11,
      "name": "Soil_Ash"
    },
    {
      "x": -35,
      "y": 0,
      "z": 12,
      "name": "Soil_Ash"
    },
    {
      "x": -35,
      "y": 1,
      "z": 12,
      "name": "Soil_Ash"
    },
    {
      "x": -35,
      "y": 2,
      "z": 12,
      "name": "Soil_Ash"
    },
    {
      "x": -35,
      "y": 21,
      "z": 12,
      "name": "Rock_Magma_Cooled"
    },
    {
      "x": -35,
      "y": 0,
      "z": 13,
      "name": "Soil_Ash"
    },
    {
      "x": -35,
      "y": 1,
      "z": 13,
      "name": "Soil_Ash"
    },
    {
      "x": -35,
      "y": 16,
      "z": 13,
      "name": "Plant_Vine_Wall_Poisoned",
      "support": 15,
      "rotation": 3
    },
    {
      "x": -35,
      "y": 19,
      "z": 13,
      "name": "Ore_Adamantite_Magma_Cracked"
    },
    {
      "x": -35,
      "y": 20,
      "z": 13,
      "name": "Rock_Magma_Cooled"
    },
    {
      "x": -35,
      "y": 21,
      "z": 13,
      "name": "Rock_Magma_Cooled"
    },
    {
      "x": -35,
      "y": 22,
      "z": 13,
      "name": "Ore_Adamantite_Magma_Cracked"
    },
    {
      "x": -35,
      "y": 0,
      "z": 14,
      "name": "Soil_Sand_Ashen"
    },
    {
      "x": -35,
      "y": 1,
      "z": 14,
      "name": "Soil_Ash"
    },
    {
      "x": -35,
      "y": 18,
      "z": 14,
      "name": "Rock_Magma_Cooled"
    },
    {
      "x": -35,
      "y": 19,
      "z": 14,
      "name": "Rock_Magma_Cooled"
    },
    {
      "x": -35,
      "y": 20,
      "z": 14,
      "name": "Ore_Adamantite_Magma_Cracked"
    },
    {
      "x": -35,
      "y": 21,
      "z": 14,
      "name": "Ore_Adamantite_Magma_Cracked"
    },
    {
      "x": -35,
      "y": 22,
      "z": 14,
      "name": "Rock_Magma_Cooled"
    },
    {
      "x": -35,
      "y": 18,
      "z": 15,
      "name": "Ore_Adamantite_Magma_Cracked"
    },
    {
      "x": -35,
      "y": 19,
      "z": 15,
      "name": "Rock_Magma_Cooled"
    },
    {
      "x": -35,
      "y": 20,
      "z": 15,
      "name": "Rock_Magma_Cooled"
    },
    {
      "x": -35,
      "y": 21,
      "z": 15,
      "name": "Ore_Adamantite_Magma_Cracked"
    },
    {
      "x": -35,
      "y": 22,
      "z": 15,
      "name": "Rock_Magma_Cooled"
    },
    {
      "x": -35,
      "y": 18,
      "z": 16,
      "name": "Rock_Magma_Cooled"
    },
    {
      "x": -35,
      "y": 19,
      "z": 16,
      "name": "Ore_Adamantite_Magma_Cracked"
    },
    {
      "x": -35,
      "y": 20,
      "z": 16,
      "name": "Ore_Adamantite_Magma_Cracked"
    },
    {
      "x": -35,
      "y": 21,
      "z": 16,
      "name": "Rock_Magma_Cooled"
    },
    {
      "x": -35,
      "y": 22,
      "z": 16,
      "name": "Ore_Adamantite_Magma_Cracked"
    },
    {
      "x": -35,
      "y": 18,
      "z": 17,
      "name": "Rock_Magma_Cooled"
    },
    {
      "x": -35,
      "y": 19,
      "z": 17,
      "name": "Ore_Adamantite_Magma_Cracked"
    },
    {
      "x": -35,
      "y": 20,
      "z": 17,
      "name": "Ore_Adamantite_Magma_Cracked"
    },
    {
      "x": -35,
      "y": 21,
      "z": 17,
      "name": "Ore_Adamantite_Magma_Cracked"
    },
    {
      "x": -35,
      "y": 22,
      "z": 17,
      "name": "Rock_Magma_Cooled"
    },
    {
      "x": -35,
      "y": 18,
      "z": 18,
      "name": "Rock_Magma_Cooled"
    },
    {
      "x": -35,
      "y": 19,
      "z": 18,
      "name": "Ore_Adamantite_Magma_Cracked"
    },
    {
      "x": -35,
      "y": 20,
      "z": 18,
      "name": "Rock_Magma_Cooled"
    },
    {
      "x": -35,
      "y": 21,
      "z": 18,
      "name": "Ore_Adamantite_Magma_Cracked"
    },
    {
      "x": -35,
      "y": 22,
      "z": 18,
      "name": "Rock_Magma_Cooled"
    },
    {
      "x": -35,
      "y": 18,
      "z": 19,
      "name": "Plant_Vine_Wall_Poisoned",
      "support": 15
    },
    {
      "x": -35,
      "y": 19,
      "z": 19,
      "name": "Ore_Adamantite_Magma_Cracked"
    },
    {
      "x": -35,
      "y": 20,
      "z": 19,
      "name": "Ore_Adamantite_Magma_Cracked"
    },
    {
      "x": -35,
      "y": 21,
      "z": 19,
      "name": "Ore_Adamantite_Magma_Cracked"
    },
    {
      "x": -35,
      "y": 19,
      "z": 20,
      "name": "Plant_Vine_Wall_Poisoned",
      "support": 15
    },
    {
      "x": -35,
      "y": 20,
      "z": 20,
      "name": "Ore_Adamantite_Magma_Cracked"
    },
    {
      "x": -34,
      "y": 0,
      "z": -7,
      "name": "Soil_Ash"
    },
    {
      "x": -34,
      "y": 0,
      "z": -6,
      "name": "Soil_Ash"
    },
    {
      "x": -34,
      "y": 1,
      "z": -6,
      "name": "Soil_Sand_Ashen"
    },
    {
      "x": -34,
      "y": 0,
      "z": -5,
      "name": "Soil_Ash"
    },
    {
      "x": -34,
      "y": 1,
      "z": -5,
      "name": "Soil_Sand_Ashen"
    },
    {
      "x": -34,
      "y": 0,
      "z": -4,
      "name": "Soil_Sand_Ashen"
    },
    {
      "x": -34,
      "y": 1,
      "z": -4,
      "name": "Soil_Ash"
    },
    {
      "x": -34,
      "y": 2,
      "z": -4,
      "name": "Soil_Sand_Ashen"
    },
    {
      "x": -34,
      "y": 0,
      "z": -3,
      "name": "Soil_Sand_Ashen"
    },
    {
      "x": -34,
      "y": 1,
      "z": -3,
      "name": "Soil_Sand_Ashen"
    },
    {
      "x": -34,
      "y": 2,
      "z": -3,
      "name": "Soil_Sand_Ashen"
    },
    {
      "x": -34,
      "y": 3,
      "z": -3,
      "name": "Soil_Sand_Ashen"
    },
    {
      "x": -34,
      "y": 0,
      "z": -2,
      "name": "Soil_Sand_Ashen"
    },
    {
      "x": -34,
      "y": 1,
      "z": -2,
      "name": "Soil_Sand_Ashen"
    },
    {
      "x": -34,
      "y": 2,
      "z": -2,
      "name": "Soil_Sand_Ashen"
    },
    {
      "x": -34,
      "y": 3,
      "z": -2,
      "name": "Soil_Sand_Ashen"
    },
    {
      "x": -34,
      "y": 4,
      "z": -2,
      "name": "Plant_Bramble_Dead_Twisted"
    },
    {
      "x": -34,
      "y": 0,
      "z": -1,
      "name": "Soil_Sand_Ashen"
    },
    {
      "x": -34,
      "y": 1,
      "z": -1,
      "name": "Soil_Sand_Ashen"
    },
    {
      "x": -34,
      "y": 2,
      "z": -1,
      "name": "Soil_Sand_Ashen"
    },
    {
      "x": -34,
      "y": 3,
      "z": -1,
      "name": "Soil_Sand_Ashen"
    },
    {
      "x": -34,
      "y": 4,
      "z": -1,
      "name": "Plant_Bramble_Dead_Twisted"
    },
    {
      "x": -34,
      "y": 0,
      "z": 0,
      "name": "Soil_Sand_Ashen"
    },
    {
      "x": -34,
      "y": 1,
      "z": 0,
      "name": "Soil_Sand_Ashen"
    },
    {
      "x": -34,
      "y": 2,
      "z": 0,
      "name": "Soil_Sand_Ashen"
    },
    {
      "x": -34,
      "y": 3,
      "z": 0,
      "name": "Soil_Sand_Ashen"
    },
    {
      "x": -34,
      "y": 4,
      "z": 0,
      "name": "Soil_Ash"
    },
    {
      "x": -34,
      "y": 0,
      "z": 1,
      "name": "Soil_Ash"
    },
    {
      "x": -34,
      "y": 1,
      "z": 1,
      "name": "Soil_Ash"
    },
    {
      "x": -34,
      "y": 2,
      "z": 1,
      "name": "Soil_Ash"
    },
    {
      "x": -34,
      "y": 3,
      "z": 1,
      "name": "Soil_Sand_Ashen"
    },
    {
      "x": -34,
      "y": 4,
      "z": 1,
      "name": "Soil_Sand_Ashen"
    },
    {
      "x": -34,
      "y": 0,
      "z": 2,
      "name": "Soil_Sand_Ashen"
    },
    {
      "x": -34,
      "y": 1,
      "z": 2,
      "name": "Soil_Ash"
    },
    {
      "x": -34,
      "y": 2,
      "z": 2,
      "name": "Soil_Ash"
    },
    {
      "x": -34,
      "y": 3,
      "z": 2,
      "name": "Soil_Ash"
    },
    {
      "x": -34,
      "y": 4,
      "z": 2,
      "name": "Soil_Sand_Ashen"
    },
    {
      "x": -34,
      "y": 0,
      "z": 3,
      "name": "Soil_Ash"
    },
    {
      "x": -34,
      "y": 1,
      "z": 3,
      "name": "Soil_Ash"
    },
    {
      "x": -34,
      "y": 2,
      "z": 3,
      "name": "Soil_Ash"
    },
    {
      "x": -34,
      "y": 3,
      "z": 3,
      "name": "Soil_Ash"
    },
    {
      "x": -34,
      "y": 4,
      "z": 3,
      "name": "Soil_Ash"
    },
    {
      "x": -34,
      "y": 0,
      "z": 4,
      "name": "Soil_Ash"
    },
    {
      "x": -34,
      "y": 1,
      "z": 4,
      "name": "Soil_Ash"
    },
    {
      "x": -34,
      "y": 2,
      "z": 4,
      "name": "Soil_Ash"
    },
    {
      "x": -34,
      "y": 3,
      "z": 4,
      "name": "Soil_Ash"
    },
    {
      "x": -34,
      "y": 4,
      "z": 4,
      "name": "Soil_Ash"
    },
    {
      "x": -34,
      "y": 0,
      "z": 5,
      "name": "Soil_Ash"
    },
    {
      "x": -34,
      "y": 1,
      "z": 5,
      "name": "Soil_Ash"
    },
    {
      "x": -34,
      "y": 2,
      "z": 5,
      "name": "Soil_Ash"
    },
    {
      "x": -34,
      "y": 3,
      "z": 5,
      "name": "Soil_Ash"
    },
    {
      "x": -34,
      "y": 4,
      "z": 5,
      "name": "Soil_Ash"
    },
    {
      "x": -34,
      "y": 0,
      "z": 6,
      "name": "Soil_Ash"
    },
    {
      "x": -34,
      "y": 1,
      "z": 6,
      "name": "Soil_Ash"
    },
    {
      "x": -34,
      "y": 2,
      "z": 6,
      "name": "Soil_Ash"
    },
    {
      "x": -34,
      "y": 3,
      "z": 6,
      "name": "Soil_Ash"
    },
    {
      "x": -34,
      "y": 4,
      "z": 6,
      "name": "Soil_Ash"
    },
    {
      "x": -34,
      "y": 24,
      "z": 6,
      "name": "Ore_Adamantite_Magma_Cracked"
    },
    {
      "x": -34,
      "y": 0,
      "z": 7,
      "name": "Soil_Ash"
    },
    {
      "x": -34,
      "y": 1,
      "z": 7,
      "name": "Soil_Ash"
    },
    {
      "x": -34,
      "y": 2,
      "z": 7,
      "name": "Soil_Ash"
    },
    {
      "x": -34,
      "y": 3,
      "z": 7,
      "name": "Soil_Ash"
    },
    {
      "x": -34,
      "y": 4,
      "z": 7,
      "name": "Soil_Ash"
    },
    {
      "x": -34,
      "y": 24,
      "z": 7,
      "name": "Rock_Magma_Cooled"
    },
    {
      "x": -34,
      "y": 25,
      "z": 7,
      "name": "Rock_Magma_Cooled"
    },
    {
      "x": -34,
      "y": 26,
      "z": 7,
      "name": "Rock_Magma_Cooled"
    },
    {
      "x": -34,
      "y": 27,
      "z": 7,
      "name": "Plant_Moss_Rug_Pink",
      "support": 15
    },
    {
      "x": -34,
      "y": 0,
      "z": 8,
      "name": "Soil_Ash"
    },
    {
      "x": -34,
      "y": 1,
      "z": 8,
      "name": "Soil_Ash"
    },
    {
      "x": -34,
      "y": 2,
      "z": 8,
      "name": "Soil_Ash"
    },
    {
      "x": -34,
      "y": 3,
      "z": 8,
      "name": "Soil_Ash"
    },
    {
      "x": -34,
      "y": 4,
      "z": 8,
      "name": "Soil_Ash"
    },
    {
      "x": -34,
      "y": 23,
      "z": 8,
      "name": "Plant_Flower_Common_Poisoned2",
      "rotation": 7
    },
    {
      "x": -34,
      "y": 24,
      "z": 8,
      "name": "Rock_Magma_Cooled"
    },
    {
      "x": -34,
      "y": 25,
      "z": 8,
      "name": "Ore_Adamantite_Magma_Cracked"
    },
    {
      "x": -34,
      "y": 26,
      "z": 8,
      "name": "Rock_Magma_Cooled"
    },
    {
      "x": -34,
      "y": 27,
      "z": 8,
      "name": "Plant_Moss_Rug_Pink",
      "support": 15
    },
    {
      "x": -34,
      "y": 0,
      "z": 9,
      "name": "Soil_Ash"
    },
    {
      "x": -34,
      "y": 1,
      "z": 9,
      "name": "Soil_Ash"
    },
    {
      "x": -34,
      "y": 2,
      "z": 9,
      "name": "Soil_Ash"
    },
    {
      "x": -34,
      "y": 3,
      "z": 9,
      "name": "Soil_Ash"
    },
    {
      "x": -34,
      "y": 4,
      "z": 9,
      "name": "Soil_Ash"
    },
    {
      "x": -34,
      "y": 24,
      "z": 9,
      "name": "Rock_Magma_Cooled"
    },
    {
      "x": -34,
      "y": 25,
      "z": 9,
      "name": "Ore_Adamantite_Magma_Cracked"
    },
    {
      "x": -34,
      "y": 26,
      "z": 9,
      "name": "Ore_Adamantite_Magma_Cracked"
    },
    {
      "x": -34,
      "y": 27,
      "z": 9,
      "name": "Ore_Adamantite_Magma_Cracked"
    },
    {
      "x": -34,
      "y": 28,
      "z": 9,
      "name": "Plant_Moss_Rug_Pink",
      "support": 15
    },
    {
      "x": -34,
      "y": 0,
      "z": 10,
      "name": "Soil_Ash"
    },
    {
      "x": -34,
      "y": 1,
      "z": 10,
      "name": "Soil_Ash"
    },
    {
      "x": -34,
      "y": 2,
      "z": 10,
      "name": "Soil_Ash"
    },
    {
      "x": -34,
      "y": 3,
      "z": 10,
      "name": "Soil_Ash"
    },
    {
      "x": -34,
      "y": 4,
      "z": 10,
      "name": "Soil_Ash"
    },
    {
      "x": -34,
      "y": 18,
      "z": 10,
      "name": "Rock_Magma_Cooled"
    },
    {
      "x": -34,
      "y": 19,
      "z": 10,
      "name": "Rock_Magma_Cooled"
    },
    {
      "x": -34,
      "y": 25,
      "z": 10,
      "name": "Ore_Adamantite_Magma_Cracked"
    },
    {
      "x": -34,
      "y": 26,
      "z": 10,
      "name": "Rock_Magma_Cooled"
    },
    {
      "x": -34,
      "y": 27,
      "z": 10,
      "name": "Ore_Adamantite_Magma_Cracked"
    },
    {
      "x": -34,
      "y": 0,
      "z": 11,
      "name": "Soil_Ash"
    },
    {
      "x": -34,
      "y": 1,
      "z": 11,
      "name": "Soil_Ash"
    },
    {
      "x": -34,
      "y": 2,
      "z": 11,
      "name": "Soil_Ash"
    },
    {
      "x": -34,
      "y": 3,
      "z": 11,
      "name": "Soil_Ash"
    },
    {
      "x": -34,
      "y": 4,
      "z": 11,
      "name": "Soil_Ash"
    },
    {
      "x": -34,
      "y": 17,
      "z": 11,
      "name": "Rock_Magma_Cooled"
    },
    {
      "x": -34,
      "y": 18,
      "z": 11,
      "name": "Rock_Magma_Cooled"
    },
    {
      "x": -34,
      "y": 19,
      "z": 11,
      "name": "Ore_Adamantite_Magma_Cracked"
    },
    {
      "x": -34,
      "y": 20,
      "z": 11,
      "name": "Rock_Magma_Cooled"
    },
    {
      "x": -34,
      "y": 26,
      "z": 11,
      "name": "Rock_Magma_Cooled"
    },
    {
      "x": -34,
      "y": 0,
      "z": 12,
      "name": "Soil_Ash"
    },
    {
      "x": -34,
      "y": 1,
      "z": 12,
      "name": "Soil_Ash"
    },
    {
      "x": -34,
      "y": 2,
      "z": 12,
      "name": "Soil_Ash"
    },
    {
      "x": -34,
      "y": 3,
      "z": 12,
      "name": "Soil_Ash"
    },
    {
      "x": -34,
      "y": 16,
      "z": 12,
      "name": "Rock_Magma_Cooled"
    },
    {
      "x": -34,
      "y": 17,
      "z": 12,
      "name": "Ore_Adamantite_Magma_Cracked"
    },
    {
      "x": -34,
      "y": 18,
      "z": 12,
      "name": "Ore_Adamantite_Magma_Cracked"
    },
    {
      "x": -34,
      "y": 19,
      "z": 12,
      "name": "Ore_Adamantite_Magma_Cracked"
    },
    {
      "x": -34,
      "y": 20,
      "z": 12,
      "name": "Ore_Adamantite_Magma_Cracked"
    },
    {
      "x": -34,
      "y": 0,
      "z": 13,
      "name": "Soil_Ash"
    },
    {
      "x": -34,
      "y": 1,
      "z": 13,
      "name": "Soil_Ash"
    },
    {
      "x": -34,
      "y": 2,
      "z": 13,
      "name": "Soil_Ash"
    },
    {
      "x": -34,
      "y": 3,
      "z": 13,
      "name": "Soil_Ash"
    },
    {
      "x": -34,
      "y": 16,
      "z": 13,
      "name": "Ore_Adamantite_Magma_Cracked"
    },
    {
      "x": -34,
      "y": 17,
      "z": 13,
      "name": "Rock_Magma_Cooled"
    },
    {
      "x": -34,
      "y": 18,
      "z": 13,
      "name": "Rock_Magma_Cooled"
    },
    {
      "x": -34,
      "y": 19,
      "z": 13,
      "name": "Rock_Magma_Cooled"
    },
    {
      "x": -34,
      "y": 20,
      "z": 13,
      "name": "Rock_Magma_Cooled"
    },
    {
      "x": -34,
      "y": 21,
      "z": 13,
      "name": "Rock_Magma_Cooled"
    },
    {
      "x": -34,
      "y": 0,
      "z": 14,
      "name": "Soil_Ash"
    },
    {
      "x": -34,
      "y": 1,
      "z": 14,
      "name": "Soil_Ash"
    },
    {
      "x": -34,
      "y": 2,
      "z": 14,
      "name": "Soil_Ash"
    },
    {
      "x": -34,
      "y": 16,
      "z": 14,
      "name": "Ore_Adamantite_Magma_Cracked"
    },
    {
      "x": -34,
      "y": 17,
      "z": 14,
      "name": "Ore_Adamantite_Magma_Cracked"
    },
    {
      "x": -34,
      "y": 18,
      "z": 14,
      "name": "Rock_Magma_Cooled"
    },
    {
      "x": -34,
      "y": 19,
      "z": 14,
      "name": "Rock_Magma_Cooled"
    },
    {
      "x": -34,
      "y": 20,
      "z": 14,
      "name": "Ore_Adamantite_Magma_Cracked"
    },
    {
      "x": -34,
      "y": 21,
      "z": 14,
      "name": "Ore_Adamantite_Magma_Cracked"
    },
    {
      "x": -34,
      "y": 0,
      "z": 15,
      "name": "Soil_Sand_Ashen"
    },
    {
      "x": -34,
      "y": 1,
      "z": 15,
      "name": "Soil_Ash"
    },
    {
      "x": -34,
      "y": 17,
      "z": 15,
      "name": "Rock_Magma_Cooled"
    },
    {
      "x": -34,
      "y": 18,
      "z": 15,
      "name": "Ore_Adamantite_Magma_Cracked"
    },
    {
      "x": -34,
      "y": 19,
      "z": 15,
      "name": "Rock_Magma_Cooled"
    },
    {
      "x": -34,
      "y": 20,
      "z": 15,
      "name": "Rock_Magma_Cooled"
    },
    {
      "x": -34,
      "y": 21,
      "z": 15,
      "name": "Rock_Magma_Cooled"
    },
    {
      "x": -34,
      "y": 17,
      "z": 16,
      "name": "Plant_Vine_Wall_Poisoned",
      "support": 15
    },
    {
      "x": -34,
      "y": 18,
      "z": 16,
      "name": "Ore_Adamantite_Magma_Cracked"
    },
    {
      "x": -34,
      "y": 19,
      "z": 16,
      "name": "Ore_Adamantite_Magma_Cracked"
    },
    {
      "x": -34,
      "y": 20,
      "z": 16,
      "name": "Ore_Adamantite_Magma_Cracked"
    },
    {
      "x": -34,
      "y": 21,
      "z": 16,
      "name": "Ore_Adamantite_Magma_Cracked"
    },
    {
      "x": -34,
      "y": 18,
      "z": 17,
      "name": "Ore_Adamantite_Magma_Cracked"
    },
    {
      "x": -34,
      "y": 19,
      "z": 17,
      "name": "Ore_Adamantite_Magma_Cracked"
    },
    {
      "x": -34,
      "y": 20,
      "z": 17,
      "name": "Rock_Magma_Cooled"
    },
    {
      "x": -34,
      "y": 21,
      "z": 17,
      "name": "Rock_Magma_Cooled"
    },
    {
      "x": -34,
      "y": 19,
      "z": 18,
      "name": "Ore_Adamantite_Magma_Cracked"
    },
    {
      "x": -34,
      "y": 20,
      "z": 18,
      "name": "Rock_Magma_Cooled"
    },
    {
      "x": -34,
      "y": 21,
      "z": 18,
      "name": "Ore_Adamantite_Magma_Cracked"
    },
    {
      "x": -34,
      "y": 20,
      "z": 19,
      "name": "Ore_Adamantite_Magma_Cracked"
    },
    {
      "x": -34,
      "y": 21,
      "z": 19,
      "name": "Plant_Vine_Wall_Poisoned",
      "support": 15
    },
    {
      "x": -34,
      "y": 20,
      "z": 20,
      "name": "Plant_Vine_Wall_Poisoned",
      "support": 15
    },
    {
      "x": -33,
      "y": 0,
      "z": -7,
      "name": "Soil_Ash"
    },
    {
      "x": -33,
      "y": 0,
      "z": -6,
      "name": "Soil_Ash"
    },
    {
      "x": -33,
      "y": 1,
      "z": -6,
      "name": "Soil_Ash"
    },
    {
      "x": -33,
      "y": 0,
      "z": -5,
      "name": "Soil_Ash"
    },
    {
      "x": -33,
      "y": 1,
      "z": -5,
      "name": "Soil_Sand_Ashen"
    },
    {
      "x": -33,
      "y": 2,
      "z": -5,
      "name": "Soil_Sand_Ashen"
    },
    {
      "x": -33,
      "y": 0,
      "z": -4,
      "name": "Soil_Ash"
    },
    {
      "x": -33,
      "y": 1,
      "z": -4,
      "name": "Soil_Sand_Ashen"
    },
    {
      "x": -33,
      "y": 2,
      "z": -4,
      "name": "Soil_Sand_Ashen"
    },
    {
      "x": -33,
      "y": 0,
      "z": -3,
      "name": "Soil_Ash"
    },
    {
      "x": -33,
      "y": 1,
      "z": -3,
      "name": "Soil_Ash"
    },
    {
      "x": -33,
      "y": 2,
      "z": -3,
      "name": "Soil_Sand_Ashen"
    },
    {
      "x": -33,
      "y": 3,
      "z": -3,
      "name": "Soil_Ash"
    },
    {
      "x": -33,
      "y": 0,
      "z": -2,
      "name": "Soil_Sand_Ashen"
    },
    {
      "x": -33,
      "y": 1,
      "z": -2,
      "name": "Soil_Ash"
    },
    {
      "x": -33,
      "y": 2,
      "z": -2,
      "name": "Soil_Sand_Ashen"
    },
    {
      "x": -33,
      "y": 3,
      "z": -2,
      "name": "Soil_Sand_Ashen"
    },
    {
      "x": -33,
      "y": 4,
      "z": -2,
      "name": "Soil_Sand_Ashen"
    },
    {
      "x": -33,
      "y": 0,
      "z": -1,
      "name": "Soil_Sand_Ashen"
    },
    {
      "x": -33,
      "y": 1,
      "z": -1,
      "name": "Soil_Ash"
    },
    {
      "x": -33,
      "y": 2,
      "z": -1,
      "name": "Soil_Ash"
    },
    {
      "x": -33,
      "y": 3,
      "z": -1,
      "name": "Soil_Sand_Ashen"
    },
    {
      "x": -33,
      "y": 4,
      "z": -1,
      "name": "Soil_Ash"
    },
    {
      "x": -33,
      "y": 0,
      "z": 0,
      "name": "Soil_Ash"
    },
    {
      "x": -33,
      "y": 1,
      "z": 0,
      "name": "Soil_Ash"
    },
    {
      "x": -33,
      "y": 2,
      "z": 0,
      "name": "Soil_Ash"
    },
    {
      "x": -33,
      "y": 3,
      "z": 0,
      "name": "Soil_Ash"
    },
    {
      "x": -33,
      "y": 4,
      "z": 0,
      "name": "Soil_Sand_Ashen"
    },
    {
      "x": -33,
      "y": 0,
      "z": 1,
      "name": "Soil_Ash"
    },
    {
      "x": -33,
      "y": 1,
      "z": 1,
      "name": "Soil_Ash"
    },
    {
      "x": -33,
      "y": 2,
      "z": 1,
      "name": "Soil_Ash"
    },
    {
      "x": -33,
      "y": 3,
      "z": 1,
      "name": "Soil_Ash"
    },
    {
      "x": -33,
      "y": 4,
      "z": 1,
      "name": "Soil_Ash"
    },
    {
      "x": -33,
      "y": 0,
      "z": 2,
      "name": "Soil_Ash"
    },
    {
      "x": -33,
      "y": 1,
      "z": 2,
      "name": "Soil_Ash"
    },
    {
      "x": -33,
      "y": 2,
      "z": 2,
      "name": "Soil_Ash"
    },
    {
      "x": -33,
      "y": 3,
      "z": 2,
      "name": "Soil_Ash"
    },
    {
      "x": -33,
      "y": 4,
      "z": 2,
      "name": "Soil_Ash"
    },
    {
      "x": -33,
      "y": 0,
      "z": 3,
      "name": "Soil_Ash"
    },
    {
      "x": -33,
      "y": 1,
      "z": 3,
      "name": "Soil_Ash"
    },
    {
      "x": -33,
      "y": 2,
      "z": 3,
      "name": "Soil_Ash"
    },
    {
      "x": -33,
      "y": 3,
      "z": 3,
      "name": "Soil_Ash"
    },
    {
      "x": -33,
      "y": 4,
      "z": 3,
      "name": "Soil_Ash"
    },
    {
      "x": -33,
      "y": 5,
      "z": 3,
      "name": "Soil_Ash"
    },
    {
      "x": -33,
      "y": 0,
      "z": 4,
      "name": "Soil_Ash"
    },
    {
      "x": -33,
      "y": 1,
      "z": 4,
      "name": "Soil_Ash"
    },
    {
      "x": -33,
      "y": 2,
      "z": 4,
      "name": "Soil_Ash"
    },
    {
      "x": -33,
      "y": 3,
      "z": 4,
      "name": "Soil_Ash"
    },
    {
      "x": -33,
      "y": 4,
      "z": 4,
      "name": "Soil_Ash"
    },
    {
      "x": -33,
      "y": 5,
      "z": 4,
      "name": "Soil_Ash"
    },
    {
      "x": -33,
      "y": 0,
      "z": 5,
      "name": "Soil_Ash"
    },
    {
      "x": -33,
      "y": 1,
      "z": 5,
      "name": "Soil_Ash"
    },
    {
      "x": -33,
      "y": 2,
      "z": 5,
      "name": "Soil_Ash"
    },
    {
      "x": -33,
      "y": 3,
      "z": 5,
      "name": "Soil_Ash"
    },
    {
      "x": -33,
      "y": 4,
      "z": 5,
      "name": "Soil_Ash"
    },
    {
      "x": -33,
      "y": 5,
      "z": 5,
      "name": "Soil_Ash"
    },
    {
      "x": -33,
      "y": 0,
      "z": 6,
      "name": "Soil_Ash"
    },
    {
      "x": -33,
      "y": 1,
      "z": 6,
      "name": "Soil_Ash"
    },
    {
      "x": -33,
      "y": 2,
      "z": 6,
      "name": "Soil_Ash"
    },
    {
      "x": -33,
      "y": 3,
      "z": 6,
      "name": "Soil_Ash"
    },
    {
      "x": -33,
      "y": 4,
      "z": 6,
      "name": "Soil_Ash"
    },
    {
      "x": -33,
      "y": 5,
      "z": 6,
      "name": "Soil_Ash"
    },
    {
      "x": -33,
      "y": 23,
      "z": 6,
      "name": "Ore_Adamantite_Magma_Cracked"
    },
    {
      "x": -33,
      "y": 24,
      "z": 6,
      "name": "Ore_Adamantite_Magma_Cracked"
    },
    {
      "x": -33,
      "y": 25,
      "z": 6,
      "name": "Ore_Adamantite_Magma_Cracked"
    },
    {
      "x": -33,
      "y": 26,
      "z": 6,
      "name": "Plant_Moss_Rug_Pink",
      "support": 15
    },
    {
      "x": -33,
      "y": 0,
      "z": 7,
      "name": "Soil_Ash"
    },
    {
      "x": -33,
      "y": 1,
      "z": 7,
      "name": "Soil_Ash"
    },
    {
      "x": -33,
      "y": 2,
      "z": 7,
      "name": "Soil_Ash"
    },
    {
      "x": -33,
      "y": 3,
      "z": 7,
      "name": "Soil_Ash"
    },
    {
      "x": -33,
      "y": 4,
      "z": 7,
      "name": "Soil_Ash"
    },
    {
      "x": -33,
      "y": 5,
      "z": 7,
      "name": "Soil_Ash"
    },
    {
      "x": -33,
      "y": 6,
      "z": 7,
      "name": "Plant_Bramble_Dead_Twisted"
    },
    {
      "x": -33,
      "y": 23,
      "z": 7,
      "name": "Ore_Adamantite_Magma_Cracked"
    },
    {
      "x": -33,
      "y": 24,
      "z": 7,
      "name": "Ore_Adamantite_Magma_Cracked"
    },
    {
      "x": -33,
      "y": 25,
      "z": 7,
      "name": "Ore_Adamantite_Magma_Cracked"
    },
    {
      "x": -33,
      "y": 26,
      "z": 7,
      "name": "Plant_Moss_Rug_Pink",
      "support": 15
    },
    {
      "x": -33,
      "y": 0,
      "z": 8,
      "name": "Soil_Ash"
    },
    {
      "x": -33,
      "y": 1,
      "z": 8,
      "name": "Soil_Ash"
    },
    {
      "x": -33,
      "y": 2,
      "z": 8,
      "name": "Soil_Ash"
    },
    {
      "x": -33,
      "y": 3,
      "z": 8,
      "name": "Soil_Ash"
    },
    {
      "x": -33,
      "y": 4,
      "z": 8,
      "name": "Soil_Ash"
    },
    {
      "x": -33,
      "y": 5,
      "z": 8,
      "name": "Soil_Ash"
    },
    {
      "x": -33,
      "y": 6,
      "z": 8,
      "name": "Plant_Bramble_Dead_Twisted"
    },
    {
      "x": -33,
      "y": 17,
      "z": 8,
      "name": "Plant_Flower_Common_Poisoned2",
      "rotation": 8
    },
    {
      "x": -33,
      "y": 18,
      "z": 8,
      "name": "Ore_Adamantite_Magma_Cracked"
    },
    {
      "x": -33,
      "y": 19,
      "z": 8,
      "name": "Rock_Magma_Cooled"
    },
    {
      "x": -33,
      "y": 23,
      "z": 8,
      "name": "Rock_Magma_Cooled"
    },
    {
      "x": -33,
      "y": 24,
      "z": 8,
      "name": "Rock_Magma_Cooled"
    },
    {
      "x": -33,
      "y": 25,
      "z": 8,
      "name": "Rock_Magma_Cooled"
    },
    {
      "x": -33,
      "y": 0,
      "z": 9,
      "name": "Soil_Ash"
    },
    {
      "x": -33,
      "y": 1,
      "z": 9,
      "name": "Soil_Ash"
    },
    {
      "x": -33,
      "y": 2,
      "z": 9,
      "name": "Soil_Ash"
    },
    {
      "x": -33,
      "y": 3,
      "z": 9,
      "name": "Soil_Ash"
    },
    {
      "x": -33,
      "y": 4,
      "z": 9,
      "name": "Soil_Ash"
    },
    {
      "x": -33,
      "y": 5,
      "z": 9,
      "name": "Soil_Ash"
    },
    {
      "x": -33,
      "y": 6,
      "z": 9,
      "name": "Plant_Bramble_Dead_Twisted"
    },
    {
      "x": -33,
      "y": 17,
      "z": 9,
      "name": "Rock_Magma_Cooled"
    },
    {
      "x": -33,
      "y": 18,
      "z": 9,
      "name": "Rock_Magma_Cooled"
    },
    {
      "x": -33,
      "y": 19,
      "z": 9,
      "name": "Rock_Magma_Cooled"
    },
    {
      "x": -33,
      "y": 20,
      "z": 9,
      "name": "Rock_Magma_Cooled"
    },
    {
      "x": -33,
      "y": 22,
      "z": 9,
      "name": "Rock_Magma_Cooled"
    },
    {
      "x": -33,
      "y": 23,
      "z": 9,
      "name": "Rock_Magma_Cooled"
    },
    {
      "x": -33,
      "y": 24,
      "z": 9,
      "name": "Ore_Adamantite_Magma_Cracked"
    },
    {
      "x": -33,
      "y": 25,
      "z": 9,
      "name": "Ore_Adamantite_Magma_Cracked"
    },
    {
      "x": -33,
      "y": 26,
      "z": 9,
      "name": "Rock_Magma_Cooled"
    },
    {
      "x": -33,
      "y": 27,
      "z": 9,
      "name": "Rubble_Magma_Cooled",
      "support": 15
    },
    {
      "x": -33,
      "y": 0,
      "z": 10,
      "name": "Soil_Ash"
    },
    {
      "x": -33,
      "y": 1,
      "z": 10,
      "name": "Soil_Ash"
    },
    {
      "x": -33,
      "y": 2,
      "z": 10,
      "name": "Soil_Ash"
    },
    {
      "x": -33,
      "y": 3,
      "z": 10,
      "name": "Soil_Ash"
    },
    {
      "x": -33,
      "y": 4,
      "z": 10,
      "name": "Soil_Ash"
    },
    {
      "x": -33,
      "y": 5,
      "z": 10,
      "name": "Soil_Ash"
    },
    {
      "x": -33,
      "y": 16,
      "z": 10,
      "name": "Rock_Magma_Cooled"
    },
    {
      "x": -33,
      "y": 17,
      "z": 10,
      "name": "Ore_Adamantite_Magma_Cracked"
    },
    {
      "x": -33,
      "y": 18,
      "z": 10,
      "name": "Ore_Adamantite_Magma_Cracked"
    },
    {
      "x": -33,
      "y": 19,
      "z": 10,
      "name": "Rock_Magma_Cooled"
    },
    {
      "x": -33,
      "y": 20,
      "z": 10,
      "name": "Ore_Adamantite_Magma_Cracked"
    },
    {
      "x": -33,
      "y": 21,
      "z": 10,
      "name": "Ore_Adamantite_Magma_Cracked"
    },
    {
      "x": -33,
      "y": 22,
      "z": 10,
      "name": "Ore_Adamantite_Magma_Cracked"
    },
    {
      "x": -33,
      "y": 23,
      "z": 10,
      "name": "Ore_Adamantite_Magma_Cracked"
    },
    {
      "x": -33,
      "y": 26,
      "z": 10,
      "name": "Rock_Magma_Cooled"
    },
    {
      "x": -33,
      "y": 0,
      "z": 11,
      "name": "Soil_Ash"
    },
    {
      "x": -33,
      "y": 1,
      "z": 11,
      "name": "Soil_Ash"
    },
    {
      "x": -33,
      "y": 2,
      "z": 11,
      "name": "Soil_Ash"
    },
    {
      "x": -33,
      "y": 3,
      "z": 11,
      "name": "Soil_Ash"
    },
    {
      "x": -33,
      "y": 4,
      "z": 11,
      "name": "Soil_Ash"
    },
    {
      "x": -33,
      "y": 5,
      "z": 11,
      "name": "Soil_Ash"
    },
    {
      "x": -33,
      "y": 16,
      "z": 11,
      "name": "Ore_Adamantite_Magma_Cracked"
    },
    {
      "x": -33,
      "y": 17,
      "z": 11,
      "name": "Ore_Adamantite_Magma_Cracked"
    },
    {
      "x": -33,
      "y": 18,
      "z": 11,
      "name": "Ore_Adamantite_Magma_Cracked"
    },
    {
      "x": -33,
      "y": 19,
      "z": 11,
      "name": "Rock_Magma_Cooled"
    },
    {
      "x": -33,
      "y": 20,
      "z": 11,
      "name": "Rock_Magma_Cooled"
    },
    {
      "x": -33,
      "y": 21,
      "z": 11,
      "name": "Rock_Magma_Cooled"
    },
    {
      "x": -33,
      "y": 22,
      "z": 11,
      "name": "Ore_Adamantite_Magma_Cracked"
    },
    {
      "x": -33,
      "y": 23,
      "z": 11,
      "name": "Ore_Adamantite_Magma_Cracked"
    },
    {
      "x": -33,
      "y": 0,
      "z": 12,
      "name": "Soil_Ash"
    },
    {
      "x": -33,
      "y": 1,
      "z": 12,
      "name": "Soil_Ash"
    },
    {
      "x": -33,
      "y": 2,
      "z": 12,
      "name": "Soil_Ash"
    },
    {
      "x": -33,
      "y": 3,
      "z": 12,
      "name": "Soil_Ash"
    },
    {
      "x": -33,
      "y": 4,
      "z": 12,
      "name": "Soil_Ash"
    },
    {
      "x": -33,
      "y": 14,
      "z": 12,
      "name": "Plant_Vine_Wall_Poisoned",
      "support": 15,
      "rotation": 3
    },
    {
      "x": -33,
      "y": 15,
      "z": 12,
      "name": "Rock_Magma_Cooled"
    },
    {
      "x": -33,
      "y": 16,
      "z": 12,
      "name": "Rock_Magma_Cooled"
    },
    {
      "x": -33,
      "y": 17,
      "z": 12,
      "name": "Ore_Adamantite_Magma_Cracked"
    },
    {
      "x": -33,
      "y": 18,
      "z": 12,
      "name": "Rock_Magma_Cooled"
    },
    {
      "x": -33,
      "y": 19,
      "z": 12,
      "name": "Ore_Adamantite_Magma_Cracked"
    },
    {
      "x": -33,
      "y": 20,
      "z": 12,
      "name": "Rock_Magma_Cooled"
    },
    {
      "x": -33,
      "y": 21,
      "z": 12,
      "name": "Ore_Adamantite_Magma_Cracked"
    },
    {
      "x": -33,
      "y": 22,
      "z": 12,
      "name": "Rock_Magma_Cooled"
    },
    {
      "x": -33,
      "y": 23,
      "z": 12,
      "name": "Rubble_Magma_Cooled",
      "support": 15
    },
    {
      "x": -33,
      "y": 0,
      "z": 13,
      "name": "Soil_Ash"
    },
    {
      "x": -33,
      "y": 1,
      "z": 13,
      "name": "Soil_Ash"
    },
    {
      "x": -33,
      "y": 2,
      "z": 13,
      "name": "Soil_Ash"
    },
    {
      "x": -33,
      "y": 3,
      "z": 13,
      "name": "Soil_Ash"
    },
    {
      "x": -33,
      "y": 4,
      "z": 13,
      "name": "Soil_Ash"
    },
    {
      "x": -33,
      "y": 15,
      "z": 13,
      "name": "Ore_Adamantite_Magma_Cracked"
    },
    {
      "x": -33,
      "y": 16,
      "z": 13,
      "name": "Ore_Adamantite_Magma_Cracked"
    },
    {
      "x": -33,
      "y": 17,
      "z": 13,
      "name": "Ore_Adamantite_Magma_Cracked"
    },
    {
      "x": -33,
      "y": 18,
      "z": 13,
      "name": "Rock_Magma_Cooled"
    },
    {
      "x": -33,
      "y": 19,
      "z": 13,
      "name": "Ore_Adamantite_Magma_Cracked"
    },
    {
      "x": -33,
      "y": 20,
      "z": 13,
      "name": "Ore_Adamantite_Magma_Cracked"
    },
    {
      "x": -33,
      "y": 21,
      "z": 13,
      "name": "Ore_Adamantite_Magma_Cracked"
    },
    {
      "x": -33,
      "y": 22,
      "z": 13,
      "name": "Plant_Crop_Mushroom_Glowing_Purple"
    },
    {
      "x": -33,
      "y": 0,
      "z": 14,
      "name": "Soil_Ash"
    },
    {
      "x": -33,
      "y": 1,
      "z": 14,
      "name": "Soil_Ash"
    },
    {
      "x": -33,
      "y": 2,
      "z": 14,
      "name": "Soil_Ash"
    },
    {
      "x": -33,
      "y": 3,
      "z": 14,
      "name": "Soil_Ash"
    },
    {
      "x": -33,
      "y": 15,
      "z": 14,
      "name": "Rock_Magma_Cooled"
    },
    {
      "x": -33,
      "y": 16,
      "z": 14,
      "name": "Rock_Magma_Cooled"
    },
    {
      "x": -33,
      "y": 17,
      "z": 14,
      "name": "Rock_Magma_Cooled"
    },
    {
      "x": -33,
      "y": 18,
      "z": 14,
      "name": "Ore_Adamantite_Magma_Cracked"
    },
    {
      "x": -33,
      "y": 19,
      "z": 14,
      "name": "Rock_Magma_Cooled"
    },
    {
      "x": -33,
      "y": 20,
      "z": 14,
      "name": "Rock_Magma_Cooled"
    },
    {
      "x": -33,
      "y": 21,
      "z": 14,
      "name": "Rock_Magma_Cooled"
    },
    {
      "x": -33,
      "y": 22,
      "z": 14,
      "name": "Plant_Crop_Mushroom_Glowing_Purple"
    },
    {
      "x": -33,
      "y": 0,
      "z": 15,
      "name": "Soil_Ash"
    },
    {
      "x": -33,
      "y": 1,
      "z": 15,
      "name": "Soil_Ash"
    },
    {
      "x": -33,
      "y": 2,
      "z": 15,
      "name": "Soil_Ash"
    },
    {
      "x": -33,
      "y": 15,
      "z": 15,
      "name": "Ore_Adamantite_Magma_Cracked"
    },
    {
      "x": -33,
      "y": 16,
      "z": 15,
      "name": "Rock_Magma_Cooled"
    },
    {
      "x": -33,
      "y": 17,
      "z": 15,
      "name": "Ore_Adamantite_Magma_Cracked"
    },
    {
      "x": -33,
      "y": 18,
      "z": 15,
      "name": "Ore_Adamantite_Magma_Cracked"
    },
    {
      "x": -33,
      "y": 19,
      "z": 15,
      "name": "Rock_Magma_Cooled"
    },
    {
      "x": -33,
      "y": 20,
      "z": 15,
      "name": "Ore_Adamantite_Magma_Cracked"
    },
    {
      "x": -33,
      "y": 0,
      "z": 16,
      "name": "Soil_Sand_Ashen"
    },
    {
      "x": -33,
      "y": 1,
      "z": 16,
      "name": "Soil_Ash"
    },
    {
      "x": -33,
      "y": 16,
      "z": 16,
      "name": "Ore_Adamantite_Magma_Cracked"
    },
    {
      "x": -33,
      "y": 17,
      "z": 16,
      "name": "Ore_Adamantite_Magma_Cracked"
    },
    {
      "x": -33,
      "y": 18,
      "z": 16,
      "name": "Ore_Adamantite_Magma_Cracked"
    },
    {
      "x": -33,
      "y": 19,
      "z": 16,
      "name": "Ore_Adamantite_Magma_Cracked"
    },
    {
      "x": -33,
      "y": 20,
      "z": 16,
      "name": "Ore_Adamantite_Magma_Cracked"
    },
    {
      "x": -33,
      "y": 17,
      "z": 17,
      "name": "Ore_Adamantite_Magma_Cracked"
    },
    {
      "x": -33,
      "y": 18,
      "z": 17,
      "name": "Ore_Adamantite_Magma_Cracked"
    },
    {
      "x": -33,
      "y": 19,
      "z": 17,
      "name": "Rock_Magma_Cooled"
    },
    {
      "x": -33,
      "y": 20,
      "z": 17,
      "name": "Ore_Adamantite_Magma_Cracked"
    },
    {
      "x": -33,
      "y": 18,
      "z": 18,
      "name": "Rock_Magma_Cooled"
    },
    {
      "x": -33,
      "y": 19,
      "z": 18,
      "name": "Ore_Adamantite_Magma_Cracked"
    },
    {
      "x": -33,
      "y": 20,
      "z": 18,
      "name": "Rock_Magma_Cooled"
    },
    {
      "x": -33,
      "y": 19,
      "z": 19,
      "name": "Ore_Adamantite_Magma_Cracked"
    },
    {
      "x": -32,
      "y": 0,
      "z": -7,
      "name": "Soil_Ash"
    },
    {
      "x": -32,
      "y": 0,
      "z": -6,
      "name": "Soil_Sand_Ashen"
    },
    {
      "x": -32,
      "y": 1,
      "z": -6,
      "name": "Soil_Sand_Ashen"
    },
    {
      "x": -32,
      "y": 0,
      "z": -5,
      "name": "Soil_Ash"
    },
    {
      "x": -32,
      "y": 1,
      "z": -5,
      "name": "Soil_Sand_Ashen"
    },
    {
      "x": -32,
      "y": 2,
      "z": -5,
      "name": "Soil_Ash"
    },
    {
      "x": -32,
      "y": 0,
      "z": -4,
      "name": "Soil_Ash"
    },
    {
      "x": -32,
      "y": 1,
      "z": -4,
      "name": "Soil_Sand_Ashen"
    },
    {
      "x": -32,
      "y": 2,
      "z": -4,
      "name": "Soil_Ash"
    },
    {
      "x": -32,
      "y": 3,
      "z": -4,
      "name": "Soil_Sand_Ashen"
    },
    {
      "x": -32,
      "y": 0,
      "z": -3,
      "name": "Soil_Ash"
    },
    {
      "x": -32,
      "y": 1,
      "z": -3,
      "name": "Soil_Ash"
    },
    {
      "x": -32,
      "y": 2,
      "z": -3,
      "name": "Soil_Ash"
    },
    {
      "x": -32,
      "y": 3,
      "z": -3,
      "name": "Soil_Sand_Ashen"
    },
    {
      "x": -32,
      "y": 0,
      "z": -2,
      "name": "Soil_Sand_Ashen"
    },
    {
      "x": -32,
      "y": 1,
      "z": -2,
      "name": "Soil_Ash"
    },
    {
      "x": -32,
      "y": 2,
      "z": -2,
      "name": "Soil_Ash"
    },
    {
      "x": -32,
      "y": 3,
      "z": -2,
      "name": "Soil_Ash"
    },
    {
      "x": -32,
      "y": 4,
      "z": -2,
      "name": "Soil_Sand_Ashen"
    },
    {
      "x": -32,
      "y": 0,
      "z": -1,
      "name": "Soil_Ash"
    },
    {
      "x": -32,
      "y": 1,
      "z": -1,
      "name": "Soil_Ash"
    },
    {
      "x": -32,
      "y": 2,
      "z": -1,
      "name": "Soil_Ash"
    },
    {
      "x": -32,
      "y": 3,
      "z": -1,
      "name": "Soil_Ash"
    },
    {
      "x": -32,
      "y": 4,
      "z": -1,
      "name": "Soil_Ash"
    },
    {
      "x": -32,
      "y": 0,
      "z": 0,
      "name": "Soil_Ash"
    },
    {
      "x": -32,
      "y": 1,
      "z": 0,
      "name": "Soil_Ash"
    },
    {
      "x": -32,
      "y": 2,
      "z": 0,
      "name": "Soil_Ash"
    },
    {
      "x": -32,
      "y": 3,
      "z": 0,
      "name": "Soil_Ash"
    },
    {
      "x": -32,
      "y": 4,
      "z": 0,
      "name": "Soil_Ash"
    },
    {
      "x": -32,
      "y": 5,
      "z": 0,
      "name": "Soil_Ash"
    },
    {
      "x": -32,
      "y": 0,
      "z": 1,
      "name": "Soil_Ash"
    },
    {
      "x": -32,
      "y": 1,
      "z": 1,
      "name": "Soil_Ash"
    },
    {
      "x": -32,
      "y": 2,
      "z": 1,
      "name": "Soil_Ash"
    },
    {
      "x": -32,
      "y": 3,
      "z": 1,
      "name": "Soil_Ash"
    },
    {
      "x": -32,
      "y": 4,
      "z": 1,
      "name": "Soil_Ash"
    },
    {
      "x": -32,
      "y": 5,
      "z": 1,
      "name": "Soil_Ash"
    },
    {
      "x": -32,
      "y": 0,
      "z": 2,
      "name": "Soil_Ash"
    },
    {
      "x": -32,
      "y": 1,
      "z": 2,
      "name": "Soil_Ash"
    },
    {
      "x": -32,
      "y": 2,
      "z": 2,
      "name": "Soil_Ash"
    },
    {
      "x": -32,
      "y": 3,
      "z": 2,
      "name": "Soil_Ash"
    },
    {
      "x": -32,
      "y": 4,
      "z": 2,
      "name": "Soil_Ash"
    },
    {
      "x": -32,
      "y": 5,
      "z": 2,
      "name": "Soil_Ash"
    },
    {
      "x": -32,
      "y": 0,
      "z": 3,
      "name": "Soil_Ash"
    },
    {
      "x": -32,
      "y": 1,
      "z": 3,
      "name": "Soil_Ash"
    },
    {
      "x": -32,
      "y": 2,
      "z": 3,
      "name": "Soil_Ash"
    },
    {
      "x": -32,
      "y": 3,
      "z": 3,
      "name": "Soil_Ash"
    },
    {
      "x": -32,
      "y": 4,
      "z": 3,
      "name": "Soil_Ash"
    },
    {
      "x": -32,
      "y": 5,
      "z": 3,
      "name": "Soil_Ash"
    },
    {
      "x": -32,
      "y": 6,
      "z": 3,
      "name": "Soil_Ash"
    },
    {
      "x": -32,
      "y": 7,
      "z": 3,
      "name": "Plant_Flower_Bushy_Purple"
    },
    {
      "x": -32,
      "y": 0,
      "z": 4,
      "name": "Soil_Ash"
    },
    {
      "x": -32,
      "y": 1,
      "z": 4,
      "name": "Soil_Ash"
    },
    {
      "x": -32,
      "y": 2,
      "z": 4,
      "name": "Soil_Ash"
    },
    {
      "x": -32,
      "y": 3,
      "z": 4,
      "name": "Soil_Ash"
    },
    {
      "x": -32,
      "y": 4,
      "z": 4,
      "name": "Soil_Ash"
    },
    {
      "x": -32,
      "y": 5,
      "z": 4,
      "name": "Soil_Ash"
    },
    {
      "x": -32,
      "y": 6,
      "z": 4,
      "name": "Soil_Ash"
    },
    {
      "x": -32,
      "y": 0,
      "z": 5,
      "name": "Soil_Ash"
    },
    {
      "x": -32,
      "y": 1,
      "z": 5,
      "name": "Soil_Ash"
    },
    {
      "x": -32,
      "y": 2,
      "z": 5,
      "name": "Soil_Ash"
    },
    {
      "x": -32,
      "y": 3,
      "z": 5,
      "name": "Soil_Ash"
    },
    {
      "x": -32,
      "y": 4,
      "z": 5,
      "name": "Soil_Ash"
    },
    {
      "x": -32,
      "y": 5,
      "z": 5,
      "name": "Soil_Ash"
    },
    {
      "x": -32,
      "y": 6,
      "z": 5,
      "name": "Soil_Ash"
    },
    {
      "x": -32,
      "y": 0,
      "z": 6,
      "name": "Soil_Ash"
    },
    {
      "x": -32,
      "y": 1,
      "z": 6,
      "name": "Soil_Ash"
    },
    {
      "x": -32,
      "y": 2,
      "z": 6,
      "name": "Soil_Ash"
    },
    {
      "x": -32,
      "y": 3,
      "z": 6,
      "name": "Soil_Ash"
    },
    {
      "x": -32,
      "y": 4,
      "z": 6,
      "name": "Soil_Ash"
    },
    {
      "x": -32,
      "y": 5,
      "z": 6,
      "name": "Soil_Ash"
    },
    {
      "x": -32,
      "y": 6,
      "z": 6,
      "name": "Soil_Ash"
    },
    {
      "x": -32,
      "y": 24,
      "z": 6,
      "name": "Rock_Magma_Cooled"
    },
    {
      "x": -32,
      "y": 25,
      "z": 6,
      "name": "Plant_Moss_Rug_Pink",
      "support": 15
    },
    {
      "x": -32,
      "y": 0,
      "z": 7,
      "name": "Soil_Ash"
    },
    {
      "x": -32,
      "y": 1,
      "z": 7,
      "name": "Soil_Ash"
    },
    {
      "x": -32,
      "y": 2,
      "z": 7,
      "name": "Soil_Ash"
    },
    {
      "x": -32,
      "y": 3,
      "z": 7,
      "name": "Soil_Ash"
    },
    {
      "x": -32,
      "y": 4,
      "z": 7,
      "name": "Soil_Ash"
    },
    {
      "x": -32,
      "y": 5,
      "z": 7,
      "name": "Soil_Ash"
    },
    {
      "x": -32,
      "y": 6,
      "z": 7,
      "name": "Soil_Ash"
    },
    {
      "x": -32,
      "y": 24,
      "z": 7,
      "name": "Ore_Adamantite_Magma_Cracked"
    },
    {
      "x": -32,
      "y": 25,
      "z": 7,
      "name": "Rubble_Magma_Cooled",
      "support": 15
    },
    {
      "x": -32,
      "y": 0,
      "z": 8,
      "name": "Soil_Ash"
    },
    {
      "x": -32,
      "y": 1,
      "z": 8,
      "name": "Soil_Ash"
    },
    {
      "x": -32,
      "y": 2,
      "z": 8,
      "name": "Soil_Ash"
    },
    {
      "x": -32,
      "y": 3,
      "z": 8,
      "name": "Soil_Ash"
    },
    {
      "x": -32,
      "y": 4,
      "z": 8,
      "name": "Soil_Ash"
    },
    {
      "x": -32,
      "y": 5,
      "z": 8,
      "name": "Soil_Ash"
    },
    {
      "x": -32,
      "y": 6,
      "z": 8,
      "name": "Soil_Ash"
    },
    {
      "x": -32,
      "y": 17,
      "z": 8,
      "name": "Ore_Adamantite_Magma_Cracked"
    },
    {
      "x": -32,
      "y": 18,
      "z": 8,
      "name": "Rock_Magma_Cooled"
    },
    {
      "x": -32,
      "y": 19,
      "z": 8,
      "name": "Rock_Magma_Cooled"
    },
    {
      "x": -32,
      "y": 20,
      "z": 8,
      "name": "Ore_Adamantite_Magma_Cracked"
    },
    {
      "x": -32,
      "y": 24,
      "z": 8,
      "name": "Rock_Magma_Cooled"
    },
    {
      "x": -32,
      "y": 0,
      "z": 9,
      "name": "Soil_Ash"
    },
    {
      "x": -32,
      "y": 1,
      "z": 9,
      "name": "Soil_Ash"
    },
    {
      "x": -32,
      "y": 2,
      "z": 9,
      "name": "Soil_Ash"
    },
    {
      "x": -32,
      "y": 3,
      "z": 9,
      "name": "Soil_Ash"
    },
    {
      "x": -32,
      "y": 4,
      "z": 9,
      "name": "Soil_Ash"
    },
    {
      "x": -32,
      "y": 5,
      "z": 9,
      "name": "Soil_Ash"
    },
    {
      "x": -32,
      "y": 6,
      "z": 9,
      "name": "Soil_Ash"
    },
    {
      "x": -32,
      "y": 16,
      "z": 9,
      "name": "Ore_Adamantite_Magma_Cracked"
    },
    {
      "x": -32,
      "y": 17,
      "z": 9,
      "name": "Rock_Magma_Cooled"
    },
    {
      "x": -32,
      "y": 18,
      "z": 9,
      "name": "Ore_Adamantite_Magma_Cracked"
    },
    {
      "x": -32,
      "y": 19,
      "z": 9,
      "name": "Ore_Adamantite_Magma_Cracked"
    },
    {
      "x": -32,
      "y": 20,
      "z": 9,
      "name": "Rock_Magma_Cooled"
    },
    {
      "x": -32,
      "y": 21,
      "z": 9,
      "name": "Ore_Adamantite_Magma_Cracked"
    },
    {
      "x": -32,
      "y": 22,
      "z": 9,
      "name": "Rock_Magma_Cooled"
    },
    {
      "x": -32,
      "y": 23,
      "z": 9,
      "name": "Ore_Adamantite_Magma_Cracked"
    },
    {
      "x": -32,
      "y": 24,
      "z": 9,
      "name": "Ore_Adamantite_Magma_Cracked"
    },
    {
      "x": -32,
      "y": 0,
      "z": 10,
      "name": "Soil_Ash"
    },
    {
      "x": -32,
      "y": 1,
      "z": 10,
      "name": "Soil_Ash"
    },
    {
      "x": -32,
      "y": 2,
      "z": 10,
      "name": "Soil_Ash"
    },
    {
      "x": -32,
      "y": 3,
      "z": 10,
      "name": "Soil_Ash"
    },
    {
      "x": -32,
      "y": 4,
      "z": 10,
      "name": "Soil_Ash"
    },
    {
      "x": -32,
      "y": 5,
      "z": 10,
      "name": "Soil_Ash"
    },
    {
      "x": -32,
      "y": 6,
      "z": 10,
      "name": "Soil_Ash"
    },
    {
      "x": -32,
      "y": 15,
      "z": 10,
      "name": "Rock_Magma_Cooled"
    },
    {
      "x": -32,
      "y": 16,
      "z": 10,
      "name": "Ore_Adamantite_Magma_Cracked"
    },
    {
      "x": -32,
      "y": 17,
      "z": 10,
      "name": "Rock_Magma_Cooled"
    },
    {
      "x": -32,
      "y": 18,
      "z": 10,
      "name": "Ore_Adamantite_Magma_Cracked"
    },
    {
      "x": -32,
      "y": 19,
      "z": 10,
      "name": "Rock_Magma_Cooled"
    },
    {
      "x": -32,
      "y": 20,
      "z": 10,
      "name": "Rock_Magma_Cooled"
    },
    {
      "x": -32,
      "y": 21,
      "z": 10,
      "name": "Rock_Magma_Cooled"
    },
    {
      "x": -32,
      "y": 22,
      "z": 10,
      "name": "Ore_Adamantite_Magma_Cracked"
    },
    {
      "x": -32,
      "y": 23,
      "z": 10,
      "name": "Rock_Magma_Cooled"
    },
    {
      "x": -32,
      "y": 24,
      "z": 10,
      "name": "Rock_Magma_Cooled"
    },
    {
      "x": -32,
      "y": 0,
      "z": 11,
      "name": "Soil_Ash"
    },
    {
      "x": -32,
      "y": 1,
      "z": 11,
      "name": "Soil_Ash"
    },
    {
      "x": -32,
      "y": 2,
      "z": 11,
      "name": "Soil_Ash"
    },
    {
      "x": -32,
      "y": 3,
      "z": 11,
      "name": "Soil_Ash"
    },
    {
      "x": -32,
      "y": 4,
      "z": 11,
      "name": "Soil_Ash"
    },
    {
      "x": -32,
      "y": 5,
      "z": 11,
      "name": "Soil_Ash"
    },
    {
      "x": -32,
      "y": 6,
      "z": 11,
      "name": "Soil_Ash"
    },
    {
      "x": -32,
      "y": 14,
      "z": 11,
      "name": "Ore_Adamantite_Magma_Cracked"
    },
    {
      "x": -32,
      "y": 15,
      "z": 11,
      "name": "Ore_Adamantite_Magma_Cracked"
    },
    {
      "x": -32,
      "y": 16,
      "z": 11,
      "name": "Rock_Magma_Cooled"
    },
    {
      "x": -32,
      "y": 17,
      "z": 11,
      "name": "Rock_Magma_Cooled"
    },
    {
      "x": -32,
      "y": 18,
      "z": 11,
      "name": "Ore_Adamantite_Magma_Cracked"
    },
    {
      "x": -32,
      "y": 19,
      "z": 11,
      "name": "Ore_Adamantite_Magma_Cracked"
    },
    {
      "x": -32,
      "y": 20,
      "z": 11,
      "name": "Rock_Magma_Cooled"
    },
    {
      "x": -32,
      "y": 21,
      "z": 11,
      "name": "Ore_Adamantite_Magma_Cracked"
    },
    {
      "x": -32,
      "y": 22,
      "z": 11,
      "name": "Ore_Adamantite_Magma_Cracked"
    },
    {
      "x": -32,
      "y": 23,
      "z": 11,
      "name": "Ore_Adamantite_Magma_Cracked"
    },
    {
      "x": -32,
      "y": 24,
      "z": 11,
      "name": "Ore_Adamantite_Magma_Cracked"
    },
    {
      "x": -32,
      "y": 0,
      "z": 12,
      "name": "Soil_Ash"
    },
    {
      "x": -32,
      "y": 1,
      "z": 12,
      "name": "Soil_Ash"
    },
    {
      "x": -32,
      "y": 2,
      "z": 12,
      "name": "Soil_Ash"
    },
    {
      "x": -32,
      "y": 3,
      "z": 12,
      "name": "Soil_Ash"
    },
    {
      "x": -32,
      "y": 4,
      "z": 12,
      "name": "Soil_Ash"
    },
    {
      "x": -32,
      "y": 5,
      "z": 12,
      "name": "Soil_Ash"
    },
    {
      "x": -32,
      "y": 14,
      "z": 12,
      "name": "Ore_Adamantite_Magma_Cracked"
    },
    {
      "x": -32,
      "y": 15,
      "z": 12,
      "name": "Rock_Magma_Cooled"
    },
    {
      "x": -32,
      "y": 16,
      "z": 12,
      "name": "Ore_Adamantite_Magma_Cracked"
    },
    {
      "x": -32,
      "y": 17,
      "z": 12,
      "name": "Rock_Magma_Cooled"
    },
    {
      "x": -32,
      "y": 18,
      "z": 12,
      "name": "Rock_Magma_Cooled"
    },
    {
      "x": -32,
      "y": 19,
      "z": 12,
      "name": "Rock_Magma_Cooled"
    },
    {
      "x": -32,
      "y": 20,
      "z": 12,
      "name": "Ore_Adamantite_Magma_Cracked"
    },
    {
      "x": -32,
      "y": 21,
      "z": 12,
      "name": "Ore_Adamantite_Magma_Cracked"
    },
    {
      "x": -32,
      "y": 22,
      "z": 12,
      "name": "Rock_Magma_Cooled"
    },
    {
      "x": -32,
      "y": 23,
      "z": 12,
      "name": "Rock_Magma_Cooled"
    },
    {
      "x": -32,
      "y": 0,
      "z": 13,
      "name": "Soil_Ash"
    },
    {
      "x": -32,
      "y": 1,
      "z": 13,
      "name": "Soil_Ash"
    },
    {
      "x": -32,
      "y": 2,
      "z": 13,
      "name": "Soil_Ash"
    },
    {
      "x": -32,
      "y": 3,
      "z": 13,
      "name": "Soil_Ash"
    },
    {
      "x": -32,
      "y": 4,
      "z": 13,
      "name": "Soil_Ash"
    },
    {
      "x": -32,
      "y": 5,
      "z": 13,
      "name": "Soil_Ash"
    },
    {
      "x": -32,
      "y": 14,
      "z": 13,
      "name": "Rock_Magma_Cooled"
    },
    {
      "x": -32,
      "y": 15,
      "z": 13,
      "name": "Ore_Adamantite_Magma_Cracked"
    },
    {
      "x": -32,
      "y": 16,
      "z": 13,
      "name": "Rock_Magma_Cooled"
    },
    {
      "x": -32,
      "y": 17,
      "z": 13,
      "name": "Ore_Adamantite_Magma_Cracked"
    },
    {
      "x": -32,
      "y": 18,
      "z": 13,
      "name": "Rock_Magma_Cooled"
    },
    {
      "x": -32,
      "y": 19,
      "z": 13,
      "name": "Rock_Magma_Cooled"
    },
    {
      "x": -32,
      "y": 20,
      "z": 13,
      "name": "Rock_Magma_Cooled"
    },
    {
      "x": -32,
      "y": 21,
      "z": 13,
      "name": "Rock_Magma_Cooled"
    },
    {
      "x": -32,
      "y": 22,
      "z": 13,
      "name": "Ore_Adamantite_Magma_Cracked"
    },
    {
      "x": -32,
      "y": 0,
      "z": 14,
      "name": "Soil_Ash"
    },
    {
      "x": -32,
      "y": 1,
      "z": 14,
      "name": "Soil_Ash"
    },
    {
      "x": -32,
      "y": 2,
      "z": 14,
      "name": "Soil_Ash"
    },
    {
      "x": -32,
      "y": 3,
      "z": 14,
      "name": "Soil_Ash"
    },
    {
      "x": -32,
      "y": 4,
      "z": 14,
      "name": "Soil_Ash"
    },
    {
      "x": -32,
      "y": 14,
      "z": 14,
      "name": "Ore_Adamantite_Magma_Cracked"
    },
    {
      "x": -32,
      "y": 15,
      "z": 14,
      "name": "Rock_Magma_Cooled"
    },
    {
      "x": -32,
      "y": 16,
      "z": 14,
      "name": "Ore_Adamantite_Magma_Cracked"
    },
    {
      "x": -32,
      "y": 17,
      "z": 14,
      "name": "Rock_Magma_Cooled"
    },
    {
      "x": -32,
      "y": 18,
      "z": 14,
      "name": "Rock_Magma_Cooled"
    },
    {
      "x": -32,
      "y": 19,
      "z": 14,
      "name": "Ore_Adamantite_Magma_Cracked"
    },
    {
      "x": -32,
      "y": 20,
      "z": 14,
      "name": "Rock_Magma_Cooled"
    },
    {
      "x": -32,
      "y": 21,
      "z": 14,
      "name": "Rock_Magma_Cooled"
    },
    {
      "x": -32,
      "y": 22,
      "z": 14,
      "name": "Ore_Adamantite_Magma_Cracked"
    },
    {
      "x": -32,
      "y": 0,
      "z": 15,
      "name": "Soil_Ash"
    },
    {
      "x": -32,
      "y": 1,
      "z": 15,
      "name": "Soil_Ash"
    },
    {
      "x": -32,
      "y": 2,
      "z": 15,
      "name": "Soil_Ash"
    },
    {
      "x": -32,
      "y": 3,
      "z": 15,
      "name": "Soil_Ash"
    },
    {
      "x": -32,
      "y": 4,
      "z": 15,
      "name": "Soil_Ash"
    },
    {
      "x": -32,
      "y": 14,
      "z": 15,
      "name": "Ore_Adamantite_Magma_Cracked"
    },
    {
      "x": -32,
      "y": 15,
      "z": 15,
      "name": "Rock_Magma_Cooled"
    },
    {
      "x": -32,
      "y": 16,
      "z": 15,
      "name": "Rock_Magma_Cooled"
    },
    {
      "x": -32,
      "y": 17,
      "z": 15,
      "name": "Ore_Adamantite_Magma_Cracked"
    },
    {
      "x": -32,
      "y": 18,
      "z": 15,
      "name": "Rock_Magma_Cooled"
    },
    {
      "x": -32,
      "y": 19,
      "z": 15,
      "name": "Ore_Adamantite_Magma_Cracked"
    },
    {
      "x": -32,
      "y": 20,
      "z": 15,
      "name": "Ore_Adamantite_Magma_Cracked"
    },
    {
      "x": -32,
      "y": 0,
      "z": 16,
      "name": "Soil_Ash"
    },
    {
      "x": -32,
      "y": 1,
      "z": 16,
      "name": "Soil_Ash"
    },
    {
      "x": -32,
      "y": 2,
      "z": 16,
      "name": "Soil_Ash"
    },
    {
      "x": -32,
      "y": 3,
      "z": 16,
      "name": "Soil_Ash"
    },
    {
      "x": -32,
      "y": 4,
      "z": 16,
      "name": "Plant_Bramble_Dead_Twisted"
    },
    {
      "x": -32,
      "y": 15,
      "z": 16,
      "name": "Ore_Adamantite_Magma_Cracked"
    },
    {
      "x": -32,
      "y": 16,
      "z": 16,
      "name": "Ore_Adamantite_Magma_Cracked"
    },
    {
      "x": -32,
      "y": 17,
      "z": 16,
      "name": "Rock_Magma_Cooled"
    },
    {
      "x": -32,
      "y": 18,
      "z": 16,
      "name": "Ore_Adamantite_Magma_Cracked"
    },
    {
      "x": -32,
      "y": 19,
      "z": 16,
      "name": "Rock_Magma_Cooled"
    },
    {
      "x": -32,
      "y": 20,
      "z": 16,
      "name": "Ore_Adamantite_Magma_Cracked"
    },
    {
      "x": -32,
      "y": 0,
      "z": 17,
      "name": "Soil_Sand_Ashen"
    },
    {
      "x": -32,
      "y": 1,
      "z": 17,
      "name": "Soil_Ash"
    },
    {
      "x": -32,
      "y": 15,
      "z": 17,
      "name": "Ore_Adamantite_Magma_Cracked"
    },
    {
      "x": -32,
      "y": 16,
      "z": 17,
      "name": "Ore_Adamantite_Magma_Cracked"
    },
    {
      "x": -32,
      "y": 17,
      "z": 17,
      "name": "Rock_Magma_Cooled"
    },
    {
      "x": -32,
      "y": 18,
      "z": 17,
      "name": "Rock_Magma_Cooled"
    },
    {
      "x": -32,
      "y": 19,
      "z": 17,
      "name": "Ore_Adamantite_Magma_Cracked"
    },
    {
      "x": -32,
      "y": 20,
      "z": 17,
      "name": "Plant_Vine_Wall_Poisoned",
      "support": 15
    },
    {
      "x": -32,
      "y": 16,
      "z": 18,
      "name": "Ore_Adamantite_Magma_Cracked"
    },
    {
      "x": -32,
      "y": 19,
      "z": 18,
      "name": "Rock_Magma_Cooled"
    },
    {
      "x": -31,
      "y": 0,
      "z": -7,
      "name": "Soil_Ash"
    },
    {
      "x": -31,
      "y": 1,
      "z": -7,
      "name": "Soil_Sand_Ashen"
    },
    {
      "x": -31,
      "y": 0,
      "z": -6,
      "name": "Soil_Ash"
    },
    {
      "x": -31,
      "y": 1,
      "z": -6,
      "name": "Soil_Ash"
    },
    {
      "x": -31,
      "y": 0,
      "z": -5,
      "name": "Soil_Ash"
    },
    {
      "x": -31,
      "y": 1,
      "z": -5,
      "name": "Soil_Sand_Ashen"
    },
    {
      "x": -31,
      "y": 2,
      "z": -5,
      "name": "Soil_Ash"
    },
    {
      "x": -31,
      "y": 0,
      "z": -4,
      "name": "Soil_Ash"
    },
    {
      "x": -31,
      "y": 1,
      "z": -4,
      "name": "Soil_Ash"
    },
    {
      "x": -31,
      "y": 2,
      "z": -4,
      "name": "Soil_Ash"
    },
    {
      "x": -31,
      "y": 3,
      "z": -4,
      "name": "Soil_Sand_Ashen"
    },
    {
      "x": -31,
      "y": 0,
      "z": -3,
      "name": "Soil_Ash"
    },
    {
      "x": -31,
      "y": 1,
      "z": -3,
      "name": "Soil_Ash"
    },
    {
      "x": -31,
      "y": 2,
      "z": -3,
      "name": "Soil_Ash"
    },
    {
      "x": -31,
      "y": 3,
      "z": -3,
      "name": "Soil_Ash"
    },
    {
      "x": -31,
      "y": 4,
      "z": -3,
      "name": "Soil_Ash"
    },
    {
      "x": -31,
      "y": 0,
      "z": -2,
      "name": "Soil_Ash"
    },
    {
      "x": -31,
      "y": 1,
      "z": -2,
      "name": "Soil_Ash"
    },
    {
      "x": -31,
      "y": 2,
      "z": -2,
      "name": "Soil_Ash"
    },
    {
      "x": -31,
      "y": 3,
      "z": -2,
      "name": "Soil_Ash"
    },
    {
      "x": -31,
      "y": 4,
      "z": -2,
      "name": "Soil_Ash"
    },
    {
      "x": -31,
      "y": 5,
      "z": -2,
      "name": "Plant_Bramble_Dead_Twisted"
    },
    {
      "x": -31,
      "y": 0,
      "z": -1,
      "name": "Soil_Ash"
    },
    {
      "x": -31,
      "y": 1,
      "z": -1,
      "name": "Soil_Ash"
    },
    {
      "x": -31,
      "y": 2,
      "z": -1,
      "name": "Soil_Ash"
    },
    {
      "x": -31,
      "y": 3,
      "z": -1,
      "name": "Soil_Ash"
    },
    {
      "x": -31,
      "y": 4,
      "z": -1,
      "name": "Soil_Ash"
    },
    {
      "x": -31,
      "y": 5,
      "z": -1,
      "name": "Soil_Ash"
    },
    {
      "x": -31,
      "y": 0,
      "z": 0,
      "name": "Soil_Ash"
    },
    {
      "x": -31,
      "y": 1,
      "z": 0,
      "name": "Soil_Ash"
    },
    {
      "x": -31,
      "y": 2,
      "z": 0,
      "name": "Soil_Ash"
    },
    {
      "x": -31,
      "y": 3,
      "z": 0,
      "name": "Soil_Ash"
    },
    {
      "x": -31,
      "y": 4,
      "z": 0,
      "name": "Soil_Ash"
    },
    {
      "x": -31,
      "y": 5,
      "z": 0,
      "name": "Soil_Ash"
    },
    {
      "x": -31,
      "y": 0,
      "z": 1,
      "name": "Soil_Ash"
    },
    {
      "x": -31,
      "y": 1,
      "z": 1,
      "name": "Soil_Ash"
    },
    {
      "x": -31,
      "y": 2,
      "z": 1,
      "name": "Soil_Ash"
    },
    {
      "x": -31,
      "y": 3,
      "z": 1,
      "name": "Soil_Ash"
    },
    {
      "x": -31,
      "y": 4,
      "z": 1,
      "name": "Soil_Ash"
    },
    {
      "x": -31,
      "y": 5,
      "z": 1,
      "name": "Soil_Ash"
    },
    {
      "x": -31,
      "y": 6,
      "z": 1,
      "name": "Soil_Ash"
    },
    {
      "x": -31,
      "y": 0,
      "z": 2,
      "name": "Soil_Ash"
    },
    {
      "x": -31,
      "y": 1,
      "z": 2,
      "name": "Soil_Ash"
    },
    {
      "x": -31,
      "y": 2,
      "z": 2,
      "name": "Soil_Ash"
    },
    {
      "x": -31,
      "y": 3,
      "z": 2,
      "name": "Soil_Ash"
    },
    {
      "x": -31,
      "y": 4,
      "z": 2,
      "name": "Soil_Ash"
    },
    {
      "x": -31,
      "y": 5,
      "z": 2,
      "name": "Soil_Ash"
    },
    {
      "x": -31,
      "y": 6,
      "z": 2,
      "name": "Soil_Ash"
    },
    {
      "x": -31,
      "y": 0,
      "z": 3,
      "name": "Soil_Ash"
    },
    {
      "x": -31,
      "y": 1,
      "z": 3,
      "name": "Soil_Ash"
    },
    {
      "x": -31,
      "y": 2,
      "z": 3,
      "name": "Soil_Ash"
    },
    {
      "x": -31,
      "y": 3,
      "z": 3,
      "name": "Soil_Ash"
    },
    {
      "x": -31,
      "y": 4,
      "z": 3,
      "name": "Soil_Ash"
    },
    {
      "x": -31,
      "y": 5,
      "z": 3,
      "name": "Soil_Ash"
    },
    {
      "x": -31,
      "y": 6,
      "z": 3,
      "name": "Soil_Ash"
    },
    {
      "x": -31,
      "y": 7,
      "z": 3,
      "name": "Soil_Ash"
    },
    {
      "x": -31,
      "y": 0,
      "z": 4,
      "name": "Soil_Ash"
    },
    {
      "x": -31,
      "y": 1,
      "z": 4,
      "name": "Soil_Ash"
    },
    {
      "x": -31,
      "y": 2,
      "z": 4,
      "name": "Soil_Ash"
    },
    {
      "x": -31,
      "y": 3,
      "z": 4,
      "name": "Soil_Ash"
    },
    {
      "x": -31,
      "y": 4,
      "z": 4,
      "name": "Soil_Ash"
    },
    {
      "x": -31,
      "y": 5,
      "z": 4,
      "name": "Soil_Ash"
    },
    {
      "x": -31,
      "y": 6,
      "z": 4,
      "name": "Soil_Ash"
    },
    {
      "x": -31,
      "y": 7,
      "z": 4,
      "name": "Soil_Ash"
    },
    {
      "x": -31,
      "y": 0,
      "z": 5,
      "name": "Soil_Ash"
    },
    {
      "x": -31,
      "y": 1,
      "z": 5,
      "name": "Soil_Ash"
    },
    {
      "x": -31,
      "y": 2,
      "z": 5,
      "name": "Soil_Ash"
    },
    {
      "x": -31,
      "y": 3,
      "z": 5,
      "name": "Soil_Ash"
    },
    {
      "x": -31,
      "y": 4,
      "z": 5,
      "name": "Soil_Ash"
    },
    {
      "x": -31,
      "y": 5,
      "z": 5,
      "name": "Soil_Ash"
    },
    {
      "x": -31,
      "y": 6,
      "z": 5,
      "name": "Soil_Ash"
    },
    {
      "x": -31,
      "y": 7,
      "z": 5,
      "name": "Soil_Ash"
    },
    {
      "x": -31,
      "y": 0,
      "z": 6,
      "name": "Soil_Ash"
    },
    {
      "x": -31,
      "y": 1,
      "z": 6,
      "name": "Soil_Ash"
    },
    {
      "x": -31,
      "y": 2,
      "z": 6,
      "name": "Soil_Ash"
    },
    {
      "x": -31,
      "y": 3,
      "z": 6,
      "name": "Soil_Ash"
    },
    {
      "x": -31,
      "y": 4,
      "z": 6,
      "name": "Soil_Ash"
    },
    {
      "x": -31,
      "y": 5,
      "z": 6,
      "name": "Soil_Ash"
    },
    {
      "x": -31,
      "y": 6,
      "z": 6,
      "name": "Soil_Ash"
    },
    {
      "x": -31,
      "y": 7,
      "z": 6,
      "name": "Soil_Ash"
    },
    {
      "x": -31,
      "y": 0,
      "z": 7,
      "name": "Soil_Ash"
    },
    {
      "x": -31,
      "y": 1,
      "z": 7,
      "name": "Soil_Ash"
    },
    {
      "x": -31,
      "y": 2,
      "z": 7,
      "name": "Soil_Ash"
    },
    {
      "x": -31,
      "y": 3,
      "z": 7,
      "name": "Soil_Ash"
    },
    {
      "x": -31,
      "y": 4,
      "z": 7,
      "name": "Soil_Ash"
    },
    {
      "x": -31,
      "y": 5,
      "z": 7,
      "name": "Soil_Ash"
    },
    {
      "x": -31,
      "y": 6,
      "z": 7,
      "name": "Soil_Ash"
    },
    {
      "x": -31,
      "y": 7,
      "z": 7,
      "name": "Soil_Ash"
    },
    {
      "x": -31,
      "y": 18,
      "z": 7,
      "name": "Plant_Flower_Common_Poisoned2",
      "rotation": 7
    },
    {
      "x": -31,
      "y": 19,
      "z": 7,
      "name": "Ore_Adamantite_Magma_Cracked"
    },
    {
      "x": -31,
      "y": 0,
      "z": 8,
      "name": "Soil_Ash"
    },
    {
      "x": -31,
      "y": 1,
      "z": 8,
      "name": "Soil_Ash"
    },
    {
      "x": -31,
      "y": 2,
      "z": 8,
      "name": "Soil_Ash"
    },
    {
      "x": -31,
      "y": 3,
      "z": 8,
      "name": "Soil_Ash"
    },
    {
      "x": -31,
      "y": 4,
      "z": 8,
      "name": "Soil_Ash"
    },
    {
      "x": -31,
      "y": 5,
      "z": 8,
      "name": "Soil_Ash"
    },
    {
      "x": -31,
      "y": 6,
      "z": 8,
      "name": "Soil_Ash"
    },
    {
      "x": -31,
      "y": 7,
      "z": 8,
      "name": "Soil_Ash"
    },
    {
      "x": -31,
      "y": 15,
      "z": 8,
      "name": "Rock_Magma_Cooled"
    },
    {
      "x": -31,
      "y": 18,
      "z": 8,
      "name": "Ore_Adamantite_Magma_Cracked"
    },
    {
      "x": -31,
      "y": 19,
      "z": 8,
      "name": "Rock_Magma_Cooled"
    },
    {
      "x": -31,
      "y": 20,
      "z": 8,
      "name": "Ore_Adamantite_Magma_Cracked"
    },
    {
      "x": -31,
      "y": 0,
      "z": 9,
      "name": "Soil_Ash"
    },
    {
      "x": -31,
      "y": 1,
      "z": 9,
      "name": "Soil_Ash"
    },
    {
      "x": -31,
      "y": 2,
      "z": 9,
      "name": "Soil_Ash"
    },
    {
      "x": -31,
      "y": 3,
      "z": 9,
      "name": "Soil_Ash"
    },
    {
      "x": -31,
      "y": 4,
      "z": 9,
      "name": "Soil_Ash"
    },
    {
      "x": -31,
      "y": 5,
      "z": 9,
      "name": "Soil_Ash"
    },
    {
      "x": -31,
      "y": 6,
      "z": 9,
      "name": "Soil_Ash"
    },
    {
      "x": -31,
      "y": 7,
      "z": 9,
      "name": "Soil_Ash"
    },
    {
      "x": -31,
      "y": 14,
      "z": 9,
      "name": "Rock_Magma_Cooled"
    },
    {
      "x": -31,
      "y": 15,
      "z": 9,
      "name": "Rock_Magma_Cooled"
    },
    {
      "x": -31,
      "y": 16,
      "z": 9,
      "name": "Rock_Magma_Cooled"
    },
    {
      "x": -31,
      "y": 17,
      "z": 9,
      "name": "Ore_Adamantite_Magma_Cracked"
    },
    {
      "x": -31,
      "y": 18,
      "z": 9,
      "name": "Rock_Magma_Cooled"
    },
    {
      "x": -31,
      "y": 19,
      "z": 9,
      "name": "Ore_Adamantite_Magma_Cracked"
    },
    {
      "x": -31,
      "y": 20,
      "z": 9,
      "name": "Rock_Magma_Cooled"
    },
    {
      "x": -31,
      "y": 21,
      "z": 9,
      "name": "Ore_Adamantite_Magma_Cracked"
    },
    {
      "x": -31,
      "y": 22,
      "z": 9,
      "name": "Ore_Adamantite_Magma_Cracked"
    },
    {
      "x": -31,
      "y": 23,
      "z": 9,
      "name": "Rock_Magma_Cooled"
    },
    {
      "x": -31,
      "y": 0,
      "z": 10,
      "name": "Soil_Ash"
    },
    {
      "x": -31,
      "y": 1,
      "z": 10,
      "name": "Soil_Ash"
    },
    {
      "x": -31,
      "y": 2,
      "z": 10,
      "name": "Soil_Ash"
    },
    {
      "x": -31,
      "y": 3,
      "z": 10,
      "name": "Soil_Ash"
    },
    {
      "x": -31,
      "y": 4,
      "z": 10,
      "name": "Soil_Ash"
    },
    {
      "x": -31,
      "y": 5,
      "z": 10,
      "name": "Soil_Ash"
    },
    {
      "x": -31,
      "y": 6,
      "z": 10,
      "name": "Soil_Ash"
    },
    {
      "x": -31,
      "y": 7,
      "z": 10,
      "name": "Soil_Ash"
    },
    {
      "x": -31,
      "y": 14,
      "z": 10,
      "name": "Ore_Adamantite_Magma_Cracked"
    },
    {
      "x": -31,
      "y": 15,
      "z": 10,
      "name": "Ore_Adamantite_Magma_Cracked"
    },
    {
      "x": -31,
      "y": 16,
      "z": 10,
      "name": "Rock_Magma_Cooled"
    },
    {
      "x": -31,
      "y": 17,
      "z": 10,
      "name": "Rock_Magma_Cooled"
    },
    {
      "x": -31,
      "y": 18,
      "z": 10,
      "name": "Rock_Magma_Cooled"
    },
    {
      "x": -31,
      "y": 19,
      "z": 10,
      "name": "Ore_Adamantite_Magma_Cracked"
    },
    {
      "x": -31,
      "y": 20,
      "z": 10,
      "name": "Rock_Magma_Cooled"
    },
    {
      "x": -31,
      "y": 21,
      "z": 10,
      "name": "Ore_Adamantite_Magma_Cracked"
    },
    {
      "x": -31,
      "y": 22,
      "z": 10,
      "name": "Rock_Magma_Cooled"
    },
    {
      "x": -31,
      "y": 23,
      "z": 10,
      "name": "Ore_Adamantite_Magma_Cracked"
    },
    {
      "x": -31,
      "y": 0,
      "z": 11,
      "name": "Soil_Ash"
    },
    {
      "x": -31,
      "y": 1,
      "z": 11,
      "name": "Soil_Ash"
    },
    {
      "x": -31,
      "y": 2,
      "z": 11,
      "name": "Soil_Ash"
    },
    {
      "x": -31,
      "y": 3,
      "z": 11,
      "name": "Soil_Ash"
    },
    {
      "x": -31,
      "y": 4,
      "z": 11,
      "name": "Soil_Ash"
    },
    {
      "x": -31,
      "y": 5,
      "z": 11,
      "name": "Soil_Ash"
    },
    {
      "x": -31,
      "y": 6,
      "z": 11,
      "name": "Soil_Ash"
    },
    {
      "x": -31,
      "y": 7,
      "z": 11,
      "name": "Soil_Ash"
    },
    {
      "x": -31,
      "y": 13,
      "z": 11,
      "name": "Rock_Magma_Cooled"
    },
    {
      "x": -31,
      "y": 14,
      "z": 11,
      "name": "Rock_Magma_Cooled"
    },
    {
      "x": -31,
      "y": 15,
      "z": 11,
      "name": "Ore_Adamantite_Magma_Cracked"
    },
    {
      "x": -31,
      "y": 16,
      "z": 11,
      "name": "Rock_Magma_Cooled"
    },
    {
      "x": -31,
      "y": 17,
      "z": 11,
      "name": "Ore_Adamantite_Magma_Cracked"
    },
    {
      "x": -31,
      "y": 18,
      "z": 11,
      "name": "Rock_Magma_Cooled"
    },
    {
      "x": -31,
      "y": 19,
      "z": 11,
      "name": "Ore_Adamantite_Magma_Cracked"
    },
    {
      "x": -31,
      "y": 20,
      "z": 11,
      "name": "Rock_Magma_Cooled"
    },
    {
      "x": -31,
      "y": 21,
      "z": 11,
      "name": "Ore_Adamantite_Magma_Cracked"
    },
    {
      "x": -31,
      "y": 22,
      "z": 11,
      "name": "Ore_Adamantite_Magma_Cracked"
    },
    {
      "x": -31,
      "y": 23,
      "z": 11,
      "name": "Ore_Adamantite_Magma_Cracked"
    },
    {
      "x": -31,
      "y": 0,
      "z": 12,
      "name": "Soil_Ash"
    },
    {
      "x": -31,
      "y": 1,
      "z": 12,
      "name": "Soil_Ash"
    },
    {
      "x": -31,
      "y": 2,
      "z": 12,
      "name": "Soil_Ash"
    },
    {
      "x": -31,
      "y": 3,
      "z": 12,
      "name": "Soil_Ash"
    },
    {
      "x": -31,
      "y": 4,
      "z": 12,
      "name": "Soil_Ash"
    },
    {
      "x": -31,
      "y": 5,
      "z": 12,
      "name": "Soil_Ash"
    },
    {
      "x": -31,
      "y": 6,
      "z": 12,
      "name": "Soil_Ash"
    },
    {
      "x": -31,
      "y": 12,
      "z": 12,
      "name": "Plant_Vine_Wall_Poisoned",
      "support": 15,
      "rotation": 3
    },
    {
      "x": -31,
      "y": 13,
      "z": 12,
      "name": "Ore_Adamantite_Magma_Cracked"
    },
    {
      "x": -31,
      "y": 14,
      "z": 12,
      "name": "Ore_Adamantite_Magma_Cracked"
    },
    {
      "x": -31,
      "y": 15,
      "z": 12,
      "name": "Ore_Adamantite_Magma_Cracked"
    },
    {
      "x": -31,
      "y": 16,
      "z": 12,
      "name": "Rock_Magma_Cooled"
    },
    {
      "x": -31,
      "y": 17,
      "z": 12,
      "name": "Ore_Adamantite_Magma_Cracked"
    },
    {
      "x": -31,
      "y": 18,
      "z": 12,
      "name": "Rock_Magma_Cooled"
    },
    {
      "x": -31,
      "y": 19,
      "z": 12,
      "name": "Rock_Magma_Cooled"
    },
    {
      "x": -31,
      "y": 20,
      "z": 12,
      "name": "Rock_Magma_Cooled"
    },
    {
      "x": -31,
      "y": 21,
      "z": 12,
      "name": "Rock_Magma_Cooled"
    },
    {
      "x": -31,
      "y": 22,
      "z": 12,
      "name": "Rock_Magma_Cooled"
    },
    {
      "x": -31,
      "y": 0,
      "z": 13,
      "name": "Soil_Ash"
    },
    {
      "x": -31,
      "y": 1,
      "z": 13,
      "name": "Soil_Ash"
    },
    {
      "x": -31,
      "y": 2,
      "z": 13,
      "name": "Soil_Ash"
    },
    {
      "x": -31,
      "y": 3,
      "z": 13,
      "name": "Soil_Ash"
    },
    {
      "x": -31,
      "y": 4,
      "z": 13,
      "name": "Soil_Ash"
    },
    {
      "x": -31,
      "y": 5,
      "z": 13,
      "name": "Soil_Ash"
    },
    {
      "x": -31,
      "y": 6,
      "z": 13,
      "name": "Soil_Ash"
    },
    {
      "x": -31,
      "y": 13,
      "z": 13,
      "name": "Rock_Magma_Cooled"
    },
    {
      "x": -31,
      "y": 14,
      "z": 13,
      "name": "Rock_Magma_Cooled"
    },
    {
      "x": -31,
      "y": 15,
      "z": 13,
      "name": "Rock_Magma_Cooled"
    },
    {
      "x": -31,
      "y": 16,
      "z": 13,
      "name": "Ore_Adamantite_Magma_Cracked"
    },
    {
      "x": -31,
      "y": 17,
      "z": 13,
      "name": "Rock_Magma_Cooled"
    },
    {
      "x": -31,
      "y": 18,
      "z": 13,
      "name": "Rock_Magma_Cooled"
    },
    {
      "x": -31,
      "y": 19,
      "z": 13,
      "name": "Rock_Magma_Cooled"
    },
    {
      "x": -31,
      "y": 20,
      "z": 13,
      "name": "Rock_Magma_Cooled"
    },
    {
      "x": -31,
      "y": 21,
      "z": 13,
      "name": "Rock_Magma_Cooled"
    },
    {
      "x": -31,
      "y": 22,
      "z": 13,
      "name": "Ore_Adamantite_Magma_Cracked"
    },
    {
      "x": -31,
      "y": 0,
      "z": 14,
      "name": "Soil_Ash"
    },
    {
      "x": -31,
      "y": 1,
      "z": 14,
      "name": "Soil_Ash"
    },
    {
      "x": -31,
      "y": 2,
      "z": 14,
      "name": "Soil_Ash"
    },
    {
      "x": -31,
      "y": 3,
      "z": 14,
      "name": "Soil_Ash"
    },
    {
      "x": -31,
      "y": 4,
      "z": 14,
      "name": "Soil_Ash"
    },
    {
      "x": -31,
      "y": 5,
      "z": 14,
      "name": "Soil_Ash"
    },
    {
      "x": -31,
      "y": 6,
      "z": 14,
      "name": "Plant_Crop_Mushroom_Glowing_Violet"
    },
    {
      "x": -31,
      "y": 14,
      "z": 14,
      "name": "Rock_Magma_Cooled"
    },
    {
      "x": -31,
      "y": 15,
      "z": 14,
      "name": "Rock_Magma_Cooled"
    },
    {
      "x": -31,
      "y": 16,
      "z": 14,
      "name": "Ore_Adamantite_Magma_Cracked"
    },
    {
      "x": -31,
      "y": 17,
      "z": 14,
      "name": "Ore_Adamantite_Magma_Cracked"
    },
    {
      "x": -31,
      "y": 18,
      "z": 14,
      "name": "Rock_Magma_Cooled"
    },
    {
      "x": -31,
      "y": 19,
      "z": 14,
      "name": "Rock_Magma_Cooled"
    },
    {
      "x": -31,
      "y": 20,
      "z": 14,
      "name": "Ore_Adamantite_Magma_Cracked"
    },
    {
      "x": -31,
      "y": 21,
      "z": 14,
      "name": "Ore_Adamantite_Magma_Cracked"
    },
    {
      "x": -31,
      "y": 0,
      "z": 15,
      "name": "Soil_Ash"
    },
    {
      "x": -31,
      "y": 1,
      "z": 15,
      "name": "Soil_Ash"
    },
    {
      "x": -31,
