{
  "version": 8,
  "blockIdVersion": 11,
  "anchorX": 0,
  "anchorY": 0,
  "anchorZ": 0,
  "blocks": [
    {
      "x": -34,
      "y": 29,
      "z": -3,
      "name": "Plant_Vine_Wall_Poisoned",
      "support": 15,
      "rotation": 3
    },
    {
      "x": -34,
      "y": 28,
      "z": -2,
      "name": "Plant_Vine_Wall_Poisoned",
      "support": 15,
      "rotation": 3
    },
    {
      "x": -33,
      "y": 28,
      "z": -3,
      "name": "Rock_Magma_Cooled",
      "rotation": 1
    },
    {
      "x": -33,
      "y": 29,
      "z": -3,
      "name": "Rock_Magma_Cooled",
      "rotation": 1
    },
    {
      "x": -33,
      "y": 30,
      "z": -3,
      "name": "Rock_Magma_Cooled",
      "rotation": 1
    },
    {
      "x": -33,
      "y": 31,
      "z": -3,
      "name": "Rock_Magma_Cooled",
      "rotation": 1
    },
    {
      "x": -33,
      "y": 32,
      "z": -3,
      "name": "Plant_Moss_Rug_Pink",
      "support": 15
    },
    {
      "x": -33,
      "y": 26,
      "z": -2,
      "name": "Rock_Magma_Cooled",
      "rotation": 1
    },
    {
      "x": -33,
      "y": 27,
      "z": -2,
      "name": "Rock_Magma_Cooled",
      "rotation": 1
    },
    {
      "x": -33,
      "y": 28,
      "z": -2,
      "name": "Rock_Magma_Cooled",
      "rotation": 1
    },
    {
      "x": -33,
      "y": 29,
      "z": -2,
      "name": "Rock_Magma_Cooled",
      "rotation": 1
    },
    {
      "x": -33,
      "y": 30,
      "z": -2,
      "name": "Plant_Moss_Rug_Pink",
      "support": 15
    },
    {
      "x": -32,
      "y": 25,
      "z": -2,
      "name": "Rock_Magma_Cooled",
      "rotation": 1
    },
    {
      "x": -32,
      "y": 26,
      "z": -2,
      "name": "Rock_Magma_Cooled",
      "rotation": 1
    },
    {
      "x": -32,
      "y": 27,
      "z": -2,
      "name": "Rock_Magma_Cooled",
      "rotation": 1
    },
    {
      "x": -32,
      "y": 28,
      "z": -2,
      "name": "Rock_Magma_Cooled",
      "rotation": 1
    },
    {
      "x": -32,
      "y": 29,
      "z": -2,
      "name": "Plant_Moss_Rug_Pink",
      "support": 15
    },
    {
      "x": -32,
      "y": 25,
      "z": -1,
      "name": "Plant_Vine_Wall_Poisoned",
      "support": 15
    },
    {
      "x": -32,
      "y": 27,
      "z": -1,
      "name": "Plant_Vine_Wall_Poisoned",
      "support": 15,
      "rotation": 3
    },
    {
      "x": -31,
      "y": 23,
      "z": -2,
      "name": "Rock_Magma_Cooled"
    },
    {
      "x": -31,
      "y": 24,
      "z": -2,
      "name": "Rock_Magma_Cooled",
      "rotation": 1
    },
    {
      "x": -31,
      "y": 25,
      "z": -2,
      "name": "Rock_Magma_Cooled",
      "rotation": 1
    },
    {
      "x": -31,
      "y": 24,
      "z": -1,
      "name": "Ore_Adamantite_Magma_Cracked",
      "rotation": 1
    },
    {
      "x": -31,
      "y": 25,
      "z": -1,
      "name": "Rock_Magma_Cooled",
      "rotation": 1
    },
    {
      "x": -31,
      "y": 26,
      "z": -1,
      "name": "Ore_Adamantite_Magma_Cracked",
      "rotation": 1
    },
    {
      "x": -31,
      "y": 27,
      "z": -1,
      "name": "Rock_Magma_Cooled",
      "rotation": 1
    },
    {
      "x": -31,
      "y": 28,
      "z": -1,
      "name": "Plant_Moss_Rug_Pink",
      "support": 15
    },
    {
      "x": -31,
      "y": 24,
      "z": 0,
      "name": "Plant_Vine_Wall_Poisoned",
      "support": 15,
      "rotation": 3
    },
    {
      "x": -30,
      "y": 24,
      "z": -2,
      "name": "Rock_Magma_Cooled"
    },
    {
      "x": -30,
      "y": 23,
      "z": -1,
      "name": "Rock_Magma_Cooled"
    },
    {
      "x": -30,
      "y": 24,
      "z": -1,
      "name": "Ore_Adamantite_Magma_Cracked",
      "rotation": 1
    },
    {
      "x": -30,
      "y": 23,
      "z": 0,
      "name": "Plant_Vine_Wall_Poisoned",
      "support": 15
    },
    {
      "x": -30,
      "y": 24,
      "z": 0,
      "name": "Rock_Magma_Cooled",
      "rotation": 1
    },
    {
      "x": -30,
      "y": 25,
      "z": 0,
      "name": "Rock_Magma_Cooled",
      "rotation": 1
    },
    {
      "x": -29,
      "y": 22,
      "z": -1,
      "name": "Rock_Magma_Cooled"
    },
    {
      "x": -29,
      "y": 23,
      "z": -1,
      "name": "Rock_Magma_Cooled"
    },
    {
      "x": -29,
      "y": 24,
      "z": -1,
      "name": "Rock_Magma_Cooled",
      "rotation": 1
    },
    {
      "x": -29,
      "y": 24,
      "z": 0,
      "name": "Rock_Magma_Cooled",
      "rotation": 1
    },
    {
      "x": -29,
      "y": 25,
      "z": 0,
      "name": "Rock_Magma_Cooled"
    },
    {
      "x": -29,
      "y": 25,
      "z": 1,
      "name": "Plant_Vine_Wall_Poisoned",
      "support": 15
    },
    {
      "x": -28,
      "y": 33,
      "z": -4,
      "name": "Rock_Magma_Cooled",
      "rotation": 1
    },
    {
      "x": -28,
      "y": 34,
      "z": -4,
      "name": "Rock_Magma_Cooled",
      "rotation": 1
    },
    {
      "x": -28,
      "y": 35,
      "z": -4,
      "name": "Rock_Magma_Cooled",
      "rotation": 1
    },
    {
      "x": -28,
      "y": 36,
      "z": -4,
      "name": "Rock_Magma_Cooled",
      "rotation": 1
    },
    {
      "x": -28,
      "y": 37,
      "z": -4,
      "name": "Plant_Moss_Rug_Pink",
      "support": 15
    },
    {
      "x": -28,
      "y": 31,
      "z": -3,
      "name": "Rock_Magma_Cooled",
      "rotation": 1
    },
    {
      "x": -28,
      "y": 32,
      "z": -3,
      "name": "Rock_Magma_Cooled",
      "rotation": 1
    },
    {
      "x": -28,
      "y": 33,
      "z": -3,
      "name": "Rock_Magma_Cooled",
      "rotation": 1
    },
    {
      "x": -28,
      "y": 34,
      "z": -3,
      "name": "Rock_Magma_Cooled",
      "rotation": 1
    },
    {
      "x": -28,
      "y": 35,
      "z": -3,
      "name": "Plant_Moss_Rug_Pink",
      "support": 15
    },
    {
      "x": -28,
      "y": 22,
      "z": -1,
      "name": "Rock_Magma_Cooled"
    },
    {
      "x": -28,
      "y": 23,
      "z": -1,
      "name": "Rock_Magma_Cooled"
    },
    {
      "x": -28,
      "y": 24,
      "z": -1,
      "name": "Rock_Magma_Cooled"
    },
    {
      "x": -28,
      "y": 27,
      "z": -1,
      "name": "Plant_Vine_Wall_Poisoned",
      "support": 15,
      "rotation": 3
    },
    {
      "x": -28,
      "y": 28,
      "z": -1,
      "name": "Plant_Vine_Wall_Poisoned",
      "support": 15,
      "rotation": 3
    },
    {
      "x": -28,
      "y": 25,
      "z": 0,
      "name": "Rock_Magma_Cooled"
    },
    {
      "x": -28,
      "y": 28,
      "z": 0,
      "name": "Plant_Vine_Wall_Poisoned",
      "support": 15,
      "rotation": 3
    },
    {
      "x": -27,
      "y": 30,
      "z": -3,
      "name": "Rock_Magma_Cooled",
      "rotation": 1
    },
    {
      "x": -27,
      "y": 31,
      "z": -3,
      "name": "Rock_Magma_Cooled",
      "rotation": 1
    },
    {
      "x": -27,
      "y": 32,
      "z": -3,
      "name": "Ore_Adamantite_Magma_Cracked",
      "rotation": 1
    },
    {
      "x": -27,
      "y": 33,
      "z": -3,
      "name": "Rock_Magma_Cooled",
      "rotation": 1
    },
    {
      "x": -27,
      "y": 34,
      "z": -3,
      "name": "Plant_Moss_Rug_Pink",
      "support": 15
    },
    {
      "x": -27,
      "y": 28,
      "z": -2,
      "name": "Plant_Vine_Wall_Poisoned",
      "support": 15,
      "rotation": 3
    },
    {
      "x": -27,
      "y": 29,
      "z": -2,
      "name": "Rock_Magma_Cooled",
      "rotation": 1
    },
    {
      "x": -27,
      "y": 30,
      "z": -2,
      "name": "Ore_Adamantite_Magma_Cracked",
      "rotation": 1
    },
    {
      "x": -27,
      "y": 31,
      "z": -2,
      "name": "Ore_Adamantite_Magma_Cracked",
      "rotation": 1
    },
    {
      "x": -27,
      "y": 32,
      "z": -2,
      "name": "Plant_Moss_Rug_Pink",
      "support": 15
    },
    {
      "x": -27,
      "y": 22,
      "z": -1,
      "name": "Rock_Magma_Cooled"
    },
    {
      "x": -27,
      "y": 23,
      "z": -1,
      "name": "Rock_Magma_Cooled"
    },
    {
      "x": -27,
      "y": 24,
      "z": -1,
      "name": "Rock_Magma_Cooled"
    },
    {
      "x": -27,
      "y": 25,
      "z": -1,
      "name": "Rock_Magma_Cooled"
    },
    {
      "x": -27,
      "y": 27,
      "z": -1,
      "name": "Rock_Magma_Cooled",
      "rotation": 1
    },
    {
      "x": -27,
      "y": 28,
      "z": -1,
      "name": "Rock_Magma_Cooled",
      "rotation": 1
    },
    {
      "x": -27,
      "y": 29,
      "z": -1,
      "name": "Rock_Magma_Cooled",
      "rotation": 1
    },
    {
      "x": -27,
      "y": 30,
      "z": -1,
      "name": "Rock_Magma_Cooled",
      "rotation": 1
    },
    {
      "x": -27,
      "y": 31,
      "z": -1,
      "name": "Plant_Moss_Rug_Pink",
      "support": 15
    },
    {
      "x": -27,
      "y": 25,
      "z": 0,
      "name": "Rock_Magma_Cooled"
    },
    {
      "x": -27,
      "y": 28,
      "z": 0,
      "name": "Rock_Magma_Cooled",
      "rotation": 1
    },
    {
      "x": -27,
      "y": 29,
      "z": 0,
      "name": "Ore_Adamantite_Magma_Cracked",
      "rotation": 1
    },
    {
      "x": -27,
      "y": 25,
      "z": 1,
      "name": "Rock_Magma_Cooled"
    },
    {
      "x": -27,
      "y": 26,
      "z": 1,
      "name": "Plant_Moss_Rug_Pink",
      "support": 15
    },
    {
      "x": -27,
      "y": 25,
      "z": 2,
      "name": "Ore_Adamantite_Magma_Cracked"
    },
    {
      "x": -27,
      "y": 25,
      "z": 3,
      "name": "Ore_Adamantite_Magma_Cracked"
    },
    {
      "x": -27,
      "y": 26,
      "z": 3,
      "name": "Plant_Moss_Rug_Pink",
      "support": 15
    },
    {
      "x": -27,
      "y": 25,
      "z": 4,
      "name": "Ore_Adamantite_Magma_Cracked"
    },
    {
      "x": -27,
      "y": 26,
      "z": 4,
      "name": "Plant_Moss_Rug_Pink",
      "support": 15
    },
    {
      "x": -26,
      "y": 25,
      "z": -2,
      "name": "Ore_Adamantite_Magma_Cracked",
      "rotation": 1
    },
    {
      "x": -26,
      "y": 26,
      "z": -2,
      "name": "Ore_Adamantite_Magma_Cracked",
      "rotation": 1
    },
    {
      "x": -26,
      "y": 27,
      "z": -2,
      "name": "Rock_Magma_Cooled",
      "rotation": 1
    },
    {
      "x": -26,
      "y": 28,
      "z": -2,
      "name": "Rock_Magma_Cooled",
      "rotation": 1
    },
    {
      "x": -26,
      "y": 29,
      "z": -2,
      "name": "Rock_Magma_Cooled",
      "rotation": 1
    },
    {
      "x": -26,
      "y": 30,
      "z": -2,
      "name": "Rock_Magma_Cooled",
      "rotation": 1
    },
    {
      "x": -26,
      "y": 31,
      "z": -2,
      "name": "Plant_Moss_Rug_Pink",
      "support": 15
    },
    {
      "x": -26,
      "y": 22,
      "z": -1,
      "name": "Rock_Magma_Cooled"
    },
    {
      "x": -26,
      "y": 23,
      "z": -1,
      "name": "Rock_Magma_Cooled"
    },
    {
      "x": -26,
      "y": 24,
      "z": -1,
      "name": "Rock_Magma_Cooled",
      "rotation": 1
    },
    {
      "x": -26,
      "y": 25,
      "z": -1,
      "name": "Rock_Magma_Cooled",
      "rotation": 1
    },
    {
      "x": -26,
      "y": 26,
      "z": -1,
      "name": "Rock_Magma_Cooled",
      "rotation": 1
    },
    {
      "x": -26,
      "y": 27,
      "z": -1,
      "name": "Rock_Magma_Cooled",
      "rotation": 1
    },
    {
      "x": -26,
      "y": 28,
      "z": -1,
      "name": "Ore_Adamantite_Magma_Cracked",
      "rotation": 1
    },
    {
      "x": -26,
      "y": 29,
      "z": -1,
      "name": "Rock_Magma_Cooled",
      "rotation": 1
    },
    {
      "x": -26,
      "y": 30,
      "z": -1,
      "name": "Plant_Moss_Rug_Pink",
      "support": 15
    },
    {
      "x": -26,
      "y": 24,
      "z": 0,
      "name": "Rock_Magma_Cooled",
      "rotation": 1
    },
    {
      "x": -26,
      "y": 25,
      "z": 0,
      "name": "Rock_Magma_Cooled",
      "rotation": 1
    },
    {
      "x": -26,
      "y": 26,
      "z": 0,
      "name": "Rock_Magma_Cooled",
      "rotation": 1
    },
    {
      "x": -26,
      "y": 27,
      "z": 0,
      "name": "Rock_Magma_Cooled",
      "rotation": 1
    },
    {
      "x": -26,
      "y": 28,
      "z": 0,
      "name": "Rock_Magma_Cooled",
      "rotation": 1
    },
    {
      "x": -26,
      "y": 24,
      "z": 1,
      "name": "Ore_Adamantite_Magma_Cracked"
    },
    {
      "x": -26,
      "y": 25,
      "z": 1,
      "name": "Ore_Adamantite_Magma_Cracked",
      "rotation": 1
    },
    {
      "x": -26,
      "y": 26,
      "z": 1,
      "name": "Rock_Magma_Cooled",
      "rotation": 1
    },
    {
      "x": -26,
      "y": 27,
      "z": 1,
      "name": "Plant_Moss_Rug_Pink",
      "support": 15
    },
    {
      "x": -26,
      "y": 24,
      "z": 2,
      "name": "Rock_Magma_Cooled"
    },
    {
      "x": -26,
      "y": 25,
      "z": 2,
      "name": "Ore_Adamantite_Magma_Cracked"
    },
    {
      "x": -26,
      "y": 26,
      "z": 2,
      "name": "Ore_Adamantite_Magma_Cracked"
    },
    {
      "x": -26,
      "y": 27,
      "z": 2,
      "name": "Plant_Moss_Rug_Pink",
      "support": 15
    },
    {
      "x": -26,
      "y": 24,
      "z": 3,
      "name": "Ore_Adamantite_Magma_Cracked"
    },
    {
      "x": -26,
      "y": 25,
      "z": 3,
      "name": "Rock_Magma_Cooled"
    },
    {
      "x": -26,
      "y": 26,
      "z": 3,
      "name": "Ore_Adamantite_Magma_Cracked"
    },
    {
      "x": -26,
      "y": 27,
      "z": 3,
      "name": "Plant_Moss_Rug_Pink",
      "support": 15
    },
    {
      "x": -26,
      "y": 24,
      "z": 4,
      "name": "Rock_Magma_Cooled"
    },
    {
      "x": -26,
      "y": 25,
      "z": 4,
      "name": "Rock_Magma_Cooled"
    },
    {
      "x": -26,
      "y": 26,
      "z": 4,
      "name": "Ore_Adamantite_Magma_Cracked"
    },
    {
      "x": -26,
      "y": 27,
      "z": 4,
      "name": "Plant_Moss_Rug_Pink",
      "support": 15
    },
    {
      "x": -26,
      "y": 24,
      "z": 5,
      "name": "Rock_Magma_Cooled"
    },
    {
      "x": -26,
      "y": 25,
      "z": 5,
      "name": "Rock_Magma_Cooled"
    },
    {
      "x": -26,
      "y": 26,
      "z": 5,
      "name": "Rock_Magma_Cooled"
    },
    {
      "x": -26,
      "y": 27,
      "z": 5,
      "name": "Plant_Moss_Rug_Pink",
      "support": 15
    },
    {
      "x": -25,
      "y": 0,
      "z": -2,
      "name": "Soil_Ash"
    },
    {
      "x": -25,
      "y": 16,
      "z": -2,
      "name": "Plant_Vine_Wall_Poisoned",
      "support": 15,
      "rotation": 3
    },
    {
      "x": -25,
      "y": 22,
      "z": -2,
      "name": "Plant_Vine_Wall_Poisoned",
      "support": 15,
      "rotation": 3
    },
    {
      "x": -25,
      "y": 23,
      "z": -2,
      "name": "Plant_Vine_Wall_Poisoned",
      "support": 15,
      "rotation": 2
    },
    {
      "x": -25,
      "y": 24,
      "z": -2,
      "name": "Ore_Adamantite_Magma_Cracked"
    },
    {
      "x": -25,
      "y": 25,
      "z": -2,
      "name": "Plant_Vine_Wall_Poisoned",
      "support": 15,
      "rotation": 1
    },
    {
      "x": -25,
      "y": 26,
      "z": -2,
      "name": "Rock_Magma_Cooled",
      "rotation": 1
    },
    {
      "x": -25,
      "y": 27,
      "z": -2,
      "name": "Rock_Magma_Cooled",
      "rotation": 1
    },
    {
      "x": -25,
      "y": 28,
      "z": -2,
      "name": "Rock_Magma_Cooled",
      "rotation": 1
    },
    {
      "x": -25,
      "y": 0,
      "z": -1,
      "name": "Soil_Ash"
    },
    {
      "x": -25,
      "y": 22,
      "z": -1,
      "name": "Rock_Magma_Cooled"
    },
    {
      "x": -25,
      "y": 23,
      "z": -1,
      "name": "Ore_Adamantite_Magma_Cracked"
    },
    {
      "x": -25,
      "y": 24,
      "z": -1,
      "name": "Rock_Magma_Cooled",
      "rotation": 1
    },
    {
      "x": -25,
      "y": 25,
      "z": -1,
      "name": "Rock_Magma_Cooled",
      "rotation": 1
    },
    {
      "x": -25,
      "y": 26,
      "z": -1,
      "name": "Ore_Adamantite_Magma_Cracked",
      "rotation": 1
    },
    {
      "x": -25,
      "y": 27,
      "z": -1,
      "name": "Rock_Magma_Cooled",
      "rotation": 1
    },
    {
      "x": -25,
      "y": 0,
      "z": 0,
      "name": "Soil_Sand_Ashen"
    },
    {
      "x": -25,
      "y": 17,
      "z": 0,
      "name": "Plant_Vine_Wall_Poisoned",
      "support": 15,
      "rotation": 3
    },
    {
      "x": -25,
      "y": 22,
      "z": 0,
      "name": "Rock_Magma_Cooled"
    },
    {
      "x": -25,
      "y": 23,
      "z": 0,
      "name": "Ore_Adamantite_Magma_Cracked"
    },
    {
      "x": -25,
      "y": 24,
      "z": 0,
      "name": "Rock_Magma_Cooled",
      "rotation": 1
    },
    {
      "x": -25,
      "y": 25,
      "z": 0,
      "name": "Rock_Magma_Cooled",
      "rotation": 1
    },
    {
      "x": -25,
      "y": 26,
      "z": 0,
      "name": "Ore_Adamantite_Magma_Cracked",
      "rotation": 1
    },
    {
      "x": -25,
      "y": 27,
      "z": 0,
      "name": "Rock_Magma_Cooled",
      "rotation": 1
    },
    {
      "x": -25,
      "y": 0,
      "z": 1,
      "name": "Soil_Ash"
    },
    {
      "x": -25,
      "y": 23,
      "z": 1,
      "name": "Ore_Adamantite_Magma_Cracked"
    },
    {
      "x": -25,
      "y": 24,
      "z": 1,
      "name": "Rock_Magma_Cooled",
      "rotation": 1
    },
    {
      "x": -25,
      "y": 25,
      "z": 1,
      "name": "Ore_Adamantite_Magma_Cracked",
      "rotation": 1
    },
    {
      "x": -25,
      "y": 26,
      "z": 1,
      "name": "Rock_Magma_Cooled",
      "rotation": 1
    },
    {
      "x": -25,
      "y": 0,
      "z": 2,
      "name": "Soil_Sand_Ashen"
    },
    {
      "x": -25,
      "y": 23,
      "z": 2,
      "name": "Rock_Magma_Cooled"
    },
    {
      "x": -25,
      "y": 24,
      "z": 2,
      "name": "Rock_Magma_Cooled"
    },
    {
      "x": -25,
      "y": 25,
      "z": 2,
      "name": "Rock_Magma_Cooled"
    },
    {
      "x": -25,
      "y": 0,
      "z": 3,
      "name": "Soil_Ash"
    },
    {
      "x": -25,
      "y": 23,
      "z": 3,
      "name": "Rock_Magma_Cooled"
    },
    {
      "x": -25,
      "y": 24,
      "z": 3,
      "name": "Ore_Adamantite_Magma_Cracked"
    },
    {
      "x": -25,
      "y": 25,
      "z": 3,
      "name": "Ore_Adamantite_Magma_Cracked"
    },
    {
      "x": -25,
      "y": 0,
      "z": 4,
      "name": "Soil_Sand_Ashen"
    },
    {
      "x": -25,
      "y": 24,
      "z": 4,
      "name": "Rock_Magma_Cooled"
    },
    {
      "x": -25,
      "y": 25,
      "z": 4,
      "name": "Rock_Magma_Cooled"
    },
    {
      "x": -25,
      "y": 0,
      "z": 5,
      "name": "Soil_Ash"
    },
    {
      "x": -25,
      "y": 25,
      "z": 5,
      "name": "Ore_Adamantite_Magma_Cracked"
    },
    {
      "x": -25,
      "y": 0,
      "z": 6,
      "name": "Soil_Ash"
    },
    {
      "x": -25,
      "y": 0,
      "z": 7,
      "name": "Soil_Ash"
    },
    {
      "x": -25,
      "y": 0,
      "z": 8,
      "name": "Soil_Ash"
    },
    {
      "x": -24,
      "y": 0,
      "z": -4,
      "name": "Soil_Ash"
    },
    {
      "x": -24,
      "y": 22,
      "z": -4,
      "name": "Plant_Vine_Wall_Poisoned",
      "support": 15,
      "rotation": 3
    },
    {
      "x": -24,
      "y": 24,
      "z": -4,
      "name": "Plant_Vine_Wall_Poisoned",
      "support": 15,
      "rotation": 2
    },
    {
      "x": -24,
      "y": 0,
      "z": -3,
      "name": "Soil_Sand_Ashen"
    },
    {
      "x": -24,
      "y": 24,
      "z": -3,
      "name": "Rock_Magma_Cooled"
    },
    {
      "x": -24,
      "y": 0,
      "z": -2,
      "name": "Soil_Ash"
    },
    {
      "x": -24,
      "y": 16,
      "z": -2,
      "name": "Ore_Adamantite_Magma_Cracked"
    },
    {
      "x": -24,
      "y": 23,
      "z": -2,
      "name": "Rock_Magma_Cooled"
    },
    {
      "x": -24,
      "y": 24,
      "z": -2,
      "name": "Ore_Adamantite_Magma_Cracked"
    },
    {
      "x": -24,
      "y": 25,
      "z": -2,
      "name": "Rock_Magma_Cooled"
    },
    {
      "x": -24,
      "y": 26,
      "z": -2,
      "name": "Plant_Vine_Wall_Poisoned",
      "support": 15,
      "rotation": 1
    },
    {
      "x": -24,
      "y": 0,
      "z": -1,
      "name": "Soil_Ash"
    },
    {
      "x": -24,
      "y": 16,
      "z": -1,
      "name": "Ore_Adamantite_Magma_Cracked"
    },
    {
      "x": -24,
      "y": 17,
      "z": -1,
      "name": "Ore_Adamantite_Magma_Cracked"
    },
    {
      "x": -24,
      "y": 18,
      "z": -1,
      "name": "Plant_Vine_Wall_Poisoned",
      "support": 15,
      "rotation": 3
    },
    {
      "x": -24,
      "y": 21,
      "z": -1,
      "name": "Plant_Flower_Common_Poisoned2",
      "rotation": 7
    },
    {
      "x": -24,
      "y": 22,
      "z": -1,
      "name": "Rock_Magma_Cooled"
    },
    {
      "x": -24,
      "y": 23,
      "z": -1,
      "name": "Ore_Adamantite_Magma_Cracked"
    },
    {
      "x": -24,
      "y": 24,
      "z": -1,
      "name": "Ore_Adamantite_Magma_Cracked"
    },
    {
      "x": -24,
      "y": 25,
      "z": -1,
      "name": "Rock_Magma_Cooled",
      "rotation": 1
    },
    {
      "x": -24,
      "y": 26,
      "z": -1,
      "name": "Rock_Magma_Cooled",
      "rotation": 1
    },
    {
      "x": -24,
      "y": 27,
      "z": -1,
      "name": "Ore_Adamantite_Magma_Cracked",
      "rotation": 1
    },
    {
      "x": -24,
      "y": 0,
      "z": 0,
      "name": "Soil_Ash"
    },
    {
      "x": -24,
      "y": 1,
      "z": 0,
      "name": "Soil_Sand_Ashen"
    },
    {
      "x": -24,
      "y": 17,
      "z": 0,
      "name": "Ore_Adamantite_Magma_Cracked"
    },
    {
      "x": -24,
      "y": 22,
      "z": 0,
      "name": "Rock_Magma_Cooled"
    },
    {
      "x": -24,
      "y": 23,
      "z": 0,
      "name": "Rock_Magma_Cooled"
    },
    {
      "x": -24,
      "y": 24,
      "z": 0,
      "name": "Rock_Magma_Cooled",
      "rotation": 1
    },
    {
      "x": -24,
      "y": 25,
      "z": 0,
      "name": "Rock_Magma_Cooled",
      "rotation": 1
    },
    {
      "x": -24,
      "y": 0,
      "z": 1,
      "name": "Soil_Ash"
    },
    {
      "x": -24,
      "y": 1,
      "z": 1,
      "name": "Soil_Ash"
    },
    {
      "x": -24,
      "y": 17,
      "z": 1,
      "name": "Rock_Magma_Cooled"
    },
    {
      "x": -24,
      "y": 18,
      "z": 1,
      "name": "Rock_Magma_Cooled"
    },
    {
      "x": -24,
      "y": 19,
      "z": 1,
      "name": "Plant_Flower_Common_Poisoned2",
      "rotation": 7
    },
    {
      "x": -24,
      "y": 23,
      "z": 1,
      "name": "Ore_Adamantite_Magma_Cracked"
    },
    {
      "x": -24,
      "y": 24,
      "z": 1,
      "name": "Rock_Magma_Cooled",
      "rotation": 1
    },
    {
      "x": -24,
      "y": 25,
      "z": 1,
      "name": "Rock_Magma_Cooled",
      "rotation": 1
    },
    {
      "x": -24,
      "y": 26,
      "z": 1,
      "name": "Plant_Moss_Rug_Pink",
      "support": 15
    },
    {
      "x": -24,
      "y": 0,
      "z": 2,
      "name": "Soil_Ash"
    },
    {
      "x": -24,
      "y": 1,
      "z": 2,
      "name": "Soil_Ash"
    },
    {
      "x": -24,
      "y": 16,
      "z": 2,
      "name": "Plant_Vine_Wall_Poisoned",
      "support": 15,
      "rotation": 3
    },
    {
      "x": -24,
      "y": 17,
      "z": 2,
      "name": "Plant_Vine_Wall_Poisoned",
      "support": 15,
      "rotation": 3
    },
    {
      "x": -24,
      "y": 18,
      "z": 2,
      "name": "Ore_Adamantite_Magma_Cracked"
    },
    {
      "x": -24,
      "y": 23,
      "z": 2,
      "name": "Ore_Adamantite_Magma_Cracked"
    },
    {
      "x": -24,
      "y": 24,
      "z": 2,
      "name": "Ore_Adamantite_Magma_Cracked"
    },
    {
      "x": -24,
      "y": 25,
      "z": 2,
      "name": "Ore_Adamantite_Magma_Cracked"
    },
    {
      "x": -24,
      "y": 26,
      "z": 2,
      "name": "Plant_Moss_Rug_Pink",
      "support": 15
    },
    {
      "x": -24,
      "y": 0,
      "z": 3,
      "name": "Soil_Ash"
    },
    {
      "x": -24,
      "y": 1,
      "z": 3,
      "name": "Soil_Ash"
    },
    {
      "x": -24,
      "y": 23,
      "z": 3,
      "name": "Ore_Adamantite_Magma_Cracked"
    },
    {
      "x": -24,
      "y": 24,
      "z": 3,
      "name": "Rock_Magma_Cooled"
    },
    {
      "x": -24,
      "y": 25,
      "z": 3,
      "name": "Ore_Adamantite_Magma_Cracked"
    },
    {
      "x": -24,
      "y": 0,
      "z": 4,
      "name": "Soil_Ash"
    },
    {
      "x": -24,
      "y": 1,
      "z": 4,
      "name": "Soil_Ash"
    },
    {
      "x": -24,
      "y": 17,
      "z": 4,
      "name": "Plant_Vine_Wall_Poisoned",
      "support": 15,
      "rotation": 3
    },
    {
      "x": -24,
      "y": 23,
      "z": 4,
      "name": "Ore_Adamantite_Magma_Cracked"
    },
    {
      "x": -24,
      "y": 24,
      "z": 4,
      "name": "Rock_Magma_Cooled"
    },
    {
      "x": -24,
      "y": 25,
      "z": 4,
      "name": "Rock_Magma_Cooled"
    },
    {
      "x": -24,
      "y": 0,
      "z": 5,
      "name": "Soil_Ash"
    },
    {
      "x": -24,
      "y": 1,
      "z": 5,
      "name": "Soil_Ash"
    },
    {
      "x": -24,
      "y": 24,
      "z": 5,
      "name": "Ore_Adamantite_Magma_Cracked"
    },
    {
      "x": -24,
      "y": 25,
      "z": 5,
      "name": "Plant_Vine_Wall_Poisoned",
      "support": 15
    },
    {
      "x": -24,
      "y": 0,
      "z": 6,
      "name": "Soil_Ash"
    },
    {
      "x": -24,
      "y": 1,
      "z": 6,
      "name": "Soil_Ash"
    },
    {
      "x": -24,
      "y": 0,
      "z": 7,
      "name": "Soil_Ash"
    },
    {
      "x": -24,
      "y": 0,
      "z": 8,
      "name": "Soil_Ash"
    },
    {
      "x": -24,
      "y": 0,
      "z": 9,
      "name": "Soil_Sand_Ashen"
    },
    {
      "x": -23,
      "y": 0,
      "z": -5,
      "name": "Soil_Ash"
    },
    {
      "x": -23,
      "y": 0,
      "z": -4,
      "name": "Soil_Ash"
    },
    {
      "x": -23,
      "y": 22,
      "z": -4,
      "name": "Rock_Magma_Cooled"
    },
    {
      "x": -23,
      "y": 0,
      "z": -3,
      "name": "Soil_Ash"
    },
    {
      "x": -23,
      "y": 1,
      "z": -3,
      "name": "Soil_Ash"
    },
    {
      "x": -23,
      "y": 15,
      "z": -3,
      "name": "Plant_Vine_Wall_Poisoned",
      "support": 15,
      "rotation": 2
    },
    {
      "x": -23,
      "y": 22,
      "z": -3,
      "name": "Ore_Adamantite_Magma_Cracked"
    },
    {
      "x": -23,
      "y": 23,
      "z": -3,
      "name": "Rock_Magma_Cooled"
    },
    {
      "x": -23,
      "y": 24,
      "z": -3,
      "name": "Plant_Vine_Wall_Poisoned",
      "support": 15,
      "rotation": 2
    },
    {
      "x": -23,
      "y": 0,
      "z": -2,
      "name": "Soil_Ash"
    },
    {
      "x": -23,
      "y": 1,
      "z": -2,
      "name": "Soil_Ash"
    },
    {
      "x": -23,
      "y": 15,
      "z": -2,
      "name": "Rock_Magma_Cooled"
    },
    {
      "x": -23,
      "y": 16,
      "z": -2,
      "name": "Rock_Magma_Cooled"
    },
    {
      "x": -23,
      "y": 17,
      "z": -2,
      "name": "Ore_Adamantite_Magma_Cracked"
    },
    {
      "x": -23,
      "y": 21,
      "z": -2,
      "name": "Plant_Vine_Wall_Poisoned",
      "support": 15,
      "rotation": 3
    },
    {
      "x": -23,
      "y": 22,
      "z": -2,
      "name": "Ore_Adamantite_Magma_Cracked"
    },
    {
      "x": -23,
      "y": 23,
      "z": -2,
      "name": "Rock_Magma_Cooled"
    },
    {
      "x": -23,
      "y": 24,
      "z": -2,
      "name": "Ore_Adamantite_Magma_Cracked"
    },
    {
      "x": -23,
      "y": 0,
      "z": -1,
      "name": "Soil_Ash"
    },
    {
      "x": -23,
      "y": 1,
      "z": -1,
      "name": "Soil_Ash"
    },
    {
      "x": -23,
      "y": 15,
      "z": -1,
      "name": "Ore_Adamantite_Magma_Cracked"
    },
    {
      "x": -23,
      "y": 16,
      "z": -1,
      "name": "Ore_Adamantite_Magma_Cracked"
    },
    {
      "x": -23,
      "y": 17,
      "z": -1,
      "name": "Rock_Magma_Cooled"
    },
    {
      "x": -23,
      "y": 18,
      "z": -1,
      "name": "Ore_Adamantite_Magma_Cracked"
    },
    {
      "x": -23,
      "y": 21,
      "z": -1,
      "name": "Ore_Adamantite_Magma_Cracked"
    },
    {
      "x": -23,
      "y": 22,
      "z": -1,
      "name": "Ore_Adamantite_Magma_Cracked"
    },
    {
      "x": -23,
      "y": 23,
      "z": -1,
      "name": "Rock_Magma_Cooled"
    },
    {
      "x": -23,
      "y": 24,
      "z": -1,
      "name": "Ore_Adamantite_Magma_Cracked"
    },
    {
      "x": -23,
      "y": 0,
      "z": 0,
      "name": "Soil_Ash"
    },
    {
      "x": -23,
      "y": 1,
      "z": 0,
      "name": "Soil_Ash"
    },
    {
      "x": -23,
      "y": 16,
      "z": 0,
      "name": "Ore_Adamantite_Magma_Cracked"
    },
    {
      "x": -23,
      "y": 17,
      "z": 0,
      "name": "Rock_Magma_Cooled"
    },
    {
      "x": -23,
      "y": 18,
      "z": 0,
      "name": "Rock_Magma_Cooled"
    },
    {
      "x": -23,
      "y": 21,
      "z": 0,
      "name": "Ore_Adamantite_Magma_Cracked"
    },
    {
      "x": -23,
      "y": 22,
      "z": 0,
      "name": "Ore_Adamantite_Magma_Cracked"
    },
    {
      "x": -23,
      "y": 23,
      "z": 0,
      "name": "Rock_Magma_Cooled"
    },
    {
      "x": -23,
      "y": 24,
      "z": 0,
      "name": "Rock_Magma_Cooled",
      "rotation": 1
    },
    {
      "x": -23,
      "y": 25,
      "z": 0,
      "name": "Rock_Magma_Cooled",
      "rotation": 1
    },
    {
      "x": -23,
      "y": 0,
      "z": 1,
      "name": "Soil_Ash"
    },
    {
      "x": -23,
      "y": 1,
      "z": 1,
      "name": "Soil_Ash"
    },
    {
      "x": -23,
      "y": 15,
      "z": 1,
      "name": "Plant_Vine_Wall_Poisoned",
      "support": 15,
      "rotation": 3
    },
    {
      "x": -23,
      "y": 16,
      "z": 1,
      "name": "Rock_Magma_Cooled"
    },
    {
      "x": -23,
      "y": 17,
      "z": 1,
      "name": "Rock_Magma_Cooled"
    },
    {
      "x": -23,
      "y": 18,
      "z": 1,
      "name": "Ore_Adamantite_Magma_Cracked"
    },
    {
      "x": -23,
      "y": 19,
      "z": 1,
      "name": "Ore_Adamantite_Magma_Cracked"
    },
    {
      "x": -23,
      "y": 20,
      "z": 1,
      "name": "Ore_Adamantite_Magma_Cracked"
    },
    {
      "x": -23,
      "y": 21,
      "z": 1,
      "name": "Rock_Magma_Cooled"
    },
    {
      "x": -23,
      "y": 22,
      "z": 1,
      "name": "Rock_Magma_Cooled"
    },
    {
      "x": -23,
      "y": 23,
      "z": 1,
      "name": "Rock_Magma_Cooled"
    },
    {
      "x": -23,
      "y": 24,
      "z": 1,
      "name": "Rock_Magma_Cooled",
      "rotation": 1
    },
    {
      "x": -23,
      "y": 25,
      "z": 1,
      "name": "Rock_Magma_Cooled",
      "rotation": 1
    },
    {
      "x": -23,
      "y": 0,
      "z": 2,
      "name": "Soil_Ash"
    },
    {
      "x": -23,
      "y": 1,
      "z": 2,
      "name": "Soil_Ash"
    },
    {
      "x": -23,
      "y": 2,
      "z": 2,
      "name": "Soil_Ash"
    },
    {
      "x": -23,
      "y": 16,
      "z": 2,
      "name": "Ore_Adamantite_Magma_Cracked"
    },
    {
      "x": -23,
      "y": 17,
      "z": 2,
      "name": "Ore_Adamantite_Magma_Cracked"
    },
    {
      "x": -23,
      "y": 18,
      "z": 2,
      "name": "Rock_Magma_Cooled"
    },
    {
      "x": -23,
      "y": 19,
      "z": 2,
      "name": "Rock_Magma_Cooled"
    },
    {
      "x": -23,
      "y": 20,
      "z": 2,
      "name": "Ore_Adamantite_Magma_Cracked"
    },
    {
      "x": -23,
      "y": 21,
      "z": 2,
      "name": "Rock_Magma_Cooled"
    },
    {
      "x": -23,
      "y": 22,
      "z": 2,
      "name": "Rock_Magma_Cooled"
    },
    {
      "x": -23,
      "y": 23,
      "z": 2,
      "name": "Ore_Adamantite_Magma_Cracked"
    },
    {
      "x": -23,
      "y": 24,
      "z": 2,
      "name": "Rock_Magma_Cooled"
    },
    {
      "x": -23,
      "y": 0,
      "z": 3,
      "name": "Soil_Ash"
    },
    {
      "x": -23,
      "y": 1,
      "z": 3,
      "name": "Soil_Ash"
    },
    {
      "x": -23,
      "y": 2,
      "z": 3,
      "name": "Soil_Ash"
    },
    {
      "x": -23,
      "y": 16,
      "z": 3,
      "name": "Ore_Adamantite_Magma_Cracked"
    },
    {
      "x": -23,
      "y": 17,
      "z": 3,
      "name": "Rock_Magma_Cooled"
    },
    {
      "x": -23,
      "y": 18,
      "z": 3,
      "name": "Rock_Magma_Cooled"
    },
    {
      "x": -23,
      "y": 19,
      "z": 3,
      "name": "Rock_Magma_Cooled"
    },
    {
      "x": -23,
      "y": 20,
      "z": 3,
      "name": "Ore_Adamantite_Magma_Cracked"
    },
    {
      "x": -23,
      "y": 22,
      "z": 3,
      "name": "Ore_Adamantite_Magma_Cracked"
    },
    {
      "x": -23,
      "y": 23,
      "z": 3,
      "name": "Rock_Magma_Cooled"
    },
    {
      "x": -23,
      "y": 24,
      "z": 3,
      "name": "Ore_Adamantite_Magma_Cracked"
    },
    {
      "x": -23,
      "y": 0,
      "z": 4,
      "name": "Soil_Ash"
    },
    {
      "x": -23,
      "y": 1,
      "z": 4,
      "name": "Soil_Ash"
    },
    {
      "x": -23,
      "y": 2,
      "z": 4,
      "name": "Soil_Ash"
    },
    {
      "x": -23,
      "y": 16,
      "z": 4,
      "name": "Plant_Flower_Common_Poisoned2",
      "rotation": 4
    },
    {
      "x": -23,
      "y": 17,
      "z": 4,
      "name": "Ore_Adamantite_Magma_Cracked"
    },
    {
      "x": -23,
      "y": 18,
      "z": 4,
      "name": "Ore_Adamantite_Magma_Cracked"
    },
    {
      "x": -23,
      "y": 19,
      "z": 4,
      "name": "Rock_Magma_Cooled"
    },
    {
      "x": -23,
      "y": 22,
      "z": 4,
      "name": "Ore_Adamantite_Magma_Cracked"
    },
    {
      "x": -23,
      "y": 23,
      "z": 4,
      "name": "Ore_Adamantite_Magma_Cracked"
    },
    {
      "x": -23,
      "y": 24,
      "z": 4,
      "name": "Ore_Adamantite_Magma_Cracked"
    },
    {
      "x": -23,
      "y": 0,
      "z": 5,
      "name": "Soil_Ash"
    },
    {
      "x": -23,
      "y": 1,
      "z": 5,
      "name": "Soil_Ash"
    },
    {
      "x": -23,
      "y": 18,
      "z": 5,
      "name": "Rock_Magma_Cooled"
    },
    {
      "x": -23,
      "y": 19,
      "z": 5,
      "name": "Plant_Vine_Wall_Poisoned",
      "support": 15
    },
    {
      "x": -23,
      "y": 0,
      "z": 6,
      "name": "Soil_Ash"
    },
    {
      "x": -23,
      "y": 1,
      "z": 6,
      "name": "Soil_Ash"
    },
    {
      "x": -23,
      "y": 17,
      "z": 6,
      "name": "Plant_Vine_Wall_Poisoned",
      "support": 15,
      "rotation": 3
    },
    {
      "x": -23,
      "y": 0,
      "z": 7,
      "name": "Soil_Ash"
    },
    {
      "x": -23,
      "y": 1,
      "z": 7,
      "name": "Soil_Ash"
    },
    {
      "x": -23,
      "y": 0,
      "z": 8,
      "name": "Soil_Ash"
    },
    {
      "x": -23,
      "y": 1,
      "z": 8,
      "name": "Soil_Ash"
    },
    {
      "x": -23,
      "y": 0,
      "z": 9,
      "name": "Soil_Ash"
    },
    {
      "x": -23,
      "y": 0,
      "z": 10,
      "name": "Soil_Ash"
    },
    {
      "x": -22,
      "y": 0,
      "z": -8,
      "name": "Soil_Ash"
    },
    {
      "x": -22,
      "y": 0,
      "z": -7,
      "name": "Soil_Ash"
    },
    {
      "x": -22,
      "y": 0,
      "z": -6,
      "name": "Soil_Ash"
    },
    {
      "x": -22,
      "y": 0,
      "z": -5,
      "name": "Soil_Ash"
    },
    {
      "x": -22,
      "y": 1,
      "z": -5,
      "name": "Soil_Ash"
    },
    {
      "x": -22,
      "y": 0,
      "z": -4,
      "name": "Soil_Ash"
    },
    {
      "x": -22,
      "y": 1,
      "z": -4,
      "name": "Soil_Ash"
    },
    {
      "x": -22,
      "y": 21,
      "z": -4,
      "name": "Rock_Magma_Cooled"
    },
    {
      "x": -22,
      "y": 22,
      "z": -4,
      "name": "Rock_Magma_Cooled"
    },
    {
      "x": -22,
      "y": 23,
      "z": -4,
      "name": "Rock_Magma_Cooled"
    },
    {
      "x": -22,
      "y": 0,
      "z": -3,
      "name": "Soil_Ash"
    },
    {
      "x": -22,
      "y": 1,
      "z": -3,
      "name": "Soil_Ash"
    },
    {
      "x": -22,
      "y": 21,
      "z": -3,
      "name": "Ore_Adamantite_Magma_Cracked"
    },
    {
      "x": -22,
      "y": 22,
      "z": -3,
      "name": "Ore_Adamantite_Magma_Cracked"
    },
    {
      "x": -22,
      "y": 23,
      "z": -3,
      "name": "Rock_Magma_Cooled"
    },
    {
      "x": -22,
      "y": 24,
      "z": -3,
      "name": "Ore_Adamantite_Magma_Cracked"
    },
    {
      "x": -22,
      "y": 0,
      "z": -2,
      "name": "Soil_Ash"
    },
    {
      "x": -22,
      "y": 1,
      "z": -2,
      "name": "Soil_Ash"
    },
    {
      "x": -22,
      "y": 2,
      "z": -2,
      "name": "Soil_Ash"
    },
    {
      "x": -22,
      "y": 16,
      "z": -2,
      "name": "Ore_Adamantite_Magma_Cracked"
    },
    {
      "x": -22,
      "y": 17,
      "z": -2,
      "name": "Ore_Adamantite_Magma_Cracked"
    },
    {
      "x": -22,
      "y": 21,
      "z": -2,
      "name": "Ore_Adamantite_Magma_Cracked"
    },
    {
      "x": -22,
      "y": 22,
      "z": -2,
      "name": "Ore_Adamantite_Magma_Cracked"
    },
    {
      "x": -22,
      "y": 23,
      "z": -2,
      "name": "Ore_Adamantite_Magma_Cracked"
    },
    {
      "x": -22,
      "y": 24,
      "z": -2,
      "name": "Rock_Magma_Cooled"
    },
    {
      "x": -22,
      "y": 0,
      "z": -1,
      "name": "Soil_Ash"
    },
    {
      "x": -22,
      "y": 1,
      "z": -1,
      "name": "Soil_Ash"
    },
    {
      "x": -22,
      "y": 2,
      "z": -1,
      "name": "Soil_Ash"
    },
    {
      "x": -22,
      "y": 16,
      "z": -1,
      "name": "Ore_Adamantite_Magma_Cracked"
    },
    {
      "x": -22,
      "y": 17,
      "z": -1,
      "name": "Rock_Magma_Cooled"
    },
    {
      "x": -22,
      "y": 18,
      "z": -1,
      "name": "Rock_Magma_Cooled"
    },
    {
      "x": -22,
      "y": 20,
      "z": -1,
      "name": "Rock_Magma_Cooled"
    },
    {
      "x": -22,
      "y": 21,
      "z": -1,
      "name": "Rock_Magma_Cooled"
    },
    {
      "x": -22,
      "y": 22,
      "z": -1,
      "name": "Ore_Adamantite_Magma_Cracked"
    },
    {
      "x": -22,
      "y": 23,
      "z": -1,
      "name": "Rock_Magma_Cooled"
    },
    {
      "x": -22,
      "y": 24,
      "z": -1,
      "name": "Ore_Adamantite_Magma_Cracked"
    },
    {
      "x": -22,
      "y": 0,
      "z": 0,
      "name": "Soil_Ash"
    },
    {
      "x": -22,
      "y": 1,
      "z": 0,
      "name": "Soil_Ash"
    },
    {
      "x": -22,
      "y": 2,
      "z": 0,
      "name": "Soil_Ash"
    },
    {
      "x": -22,
      "y": 16,
      "z": 0,
      "name": "Rock_Magma_Cooled"
    },
    {
      "x": -22,
      "y": 17,
      "z": 0,
      "name": "Ore_Adamantite_Magma_Cracked"
    },
    {
      "x": -22,
      "y": 18,
      "z": 0,
      "name": "Rock_Magma_Cooled"
    },
    {
      "x": -22,
      "y": 19,
      "z": 0,
      "name": "Ore_Adamantite_Magma_Cracked"
    },
    {
      "x": -22,
      "y": 20,
      "z": 0,
      "name": "Rock_Magma_Cooled"
    },
    {
      "x": -22,
      "y": 21,
      "z": 0,
      "name": "Rock_Magma_Cooled"
    },
    {
      "x": -22,
      "y": 22,
      "z": 0,
      "name": "Ore_Adamantite_Magma_Cracked"
    },
    {
      "x": -22,
      "y": 23,
      "z": 0,
      "name": "Rock_Magma_Cooled"
    },
    {
      "x": -22,
      "y": 24,
      "z": 0,
      "name": "Rock_Magma_Cooled"
    },
    {
      "x": -22,
      "y": 0,
      "z": 1,
      "name": "Soil_Ash"
    },
    {
      "x": -22,
      "y": 1,
      "z": 1,
      "name": "Soil_Ash"
    },
    {
      "x": -22,
      "y": 2,
      "z": 1,
      "name": "Soil_Ash"
    },
    {
      "x": -22,
      "y": 15,
      "z": 1,
      "name": "Ore_Adamantite_Magma_Cracked"
    },
    {
      "x": -22,
      "y": 16,
      "z": 1,
      "name": "Ore_Adamantite_Magma_Cracked"
    },
    {
      "x": -22,
      "y": 17,
      "z": 1,
      "name": "Rock_Magma_Cooled"
    },
    {
      "x": -22,
      "y": 18,
      "z": 1,
      "name": "Rock_Magma_Cooled"
    },
    {
      "x": -22,
      "y": 19,
      "z": 1,
      "name": "Ore_Adamantite_Magma_Cracked"
    },
    {
      "x": -22,
      "y": 20,
      "z": 1,
      "name": "Rock_Magma_Cooled"
    },
    {
      "x": -22,
      "y": 21,
      "z": 1,
      "name": "Rock_Magma_Cooled"
    },
    {
      "x": -22,
      "y": 22,
      "z": 1,
      "name": "Rock_Magma_Cooled"
    },
    {
      "x": -22,
      "y": 23,
      "z": 1,
      "name": "Ore_Adamantite_Magma_Cracked"
    },
    {
      "x": -22,
      "y": 24,
      "z": 1,
      "name": "Rock_Magma_Cooled"
    },
    {
      "x": -22,
      "y": 0,
      "z": 2,
      "name": "Soil_Ash"
    },
    {
      "x": -22,
      "y": 1,
      "z": 2,
      "name": "Soil_Ash"
    },
    {
      "x": -22,
      "y": 2,
      "z": 2,
      "name": "Soil_Ash"
    },
    {
      "x": -22,
      "y": 15,
      "z": 2,
      "name": "Ore_Adamantite_Magma_Cracked"
    },
    {
      "x": -22,
      "y": 16,
      "z": 2,
      "name": "Ore_Adamantite_Magma_Cracked"
    },
    {
      "x": -22,
      "y": 17,
      "z": 2,
      "name": "Ore_Adamantite_Magma_Cracked"
    },
    {
      "x": -22,
      "y": 18,
      "z": 2,
      "name": "Ore_Adamantite_Magma_Cracked"
    },
    {
      "x": -22,
      "y": 19,
      "z": 2,
      "name": "Ore_Adamantite_Magma_Cracked"
    },
    {
      "x": -22,
      "y": 20,
      "z": 2,
      "name": "Rock_Magma_Cooled"
    },
    {
      "x": -22,
      "y": 21,
      "z": 2,
      "name": "Ore_Adamantite_Magma_Cracked"
    },
    {
      "x": -22,
      "y": 22,
      "z": 2,
      "name": "Ore_Adamantite_Magma_Cracked"
    },
    {
      "x": -22,
      "y": 23,
      "z": 2,
      "name": "Ore_Adamantite_Magma_Cracked"
    },
    {
      "x": -22,
      "y": 0,
      "z": 3,
      "name": "Soil_Ash"
    },
    {
      "x": -22,
      "y": 1,
      "z": 3,
      "name": "Soil_Ash"
    },
    {
      "x": -22,
      "y": 2,
      "z": 3,
      "name": "Soil_Ash"
    },
    {
      "x": -22,
      "y": 15,
      "z": 3,
      "name": "Ore_Adamantite_Magma_Cracked"
    },
    {
      "x": -22,
      "y": 16,
      "z": 3,
      "name": "Ore_Adamantite_Magma_Cracked"
    },
    {
      "x": -22,
      "y": 17,
      "z": 3,
      "name": "Ore_Adamantite_Magma_Cracked"
    },
    {
      "x": -22,
      "y": 18,
      "z": 3,
      "name": "Ore_Adamantite_Magma_Cracked"
    },
    {
      "x": -22,
      "y": 19,
      "z": 3,
      "name": "Rock_Magma_Cooled"
    },
    {
      "x": -22,
      "y": 20,
      "z": 3,
      "name": "Rock_Magma_Cooled"
    },
    {
      "x": -22,
      "y": 21,
      "z": 3,
      "name": "Rock_Magma_Cooled"
    },
    {
      "x": -22,
      "y": 22,
      "z": 3,
      "name": "Ore_Adamantite_Magma_Cracked"
    },
    {
      "x": -22,
      "y": 23,
      "z": 3,
      "name": "Ore_Adamantite_Magma_Cracked"
    },
    {
      "x": -22,
      "y": 0,
      "z": 4,
      "name": "Soil_Ash"
    },
    {
      "x": -22,
      "y": 1,
      "z": 4,
      "name": "Soil_Ash"
    },
    {
      "x": -22,
      "y": 2,
      "z": 4,
      "name": "Soil_Ash"
    },
    {
      "x": -22,
      "y": 16,
      "z": 4,
      "name": "Rock_Magma_Cooled"
    },
    {
      "x": -22,
      "y": 17,
      "z": 4,
      "name": "Rock_Magma_Cooled"
    },
    {
      "x": -22,
      "y": 18,
      "z": 4,
      "name": "Ore_Adamantite_Magma_Cracked"
    },
    {
      "x": -22,
      "y": 19,
      "z": 4,
      "name": "Ore_Adamantite_Magma_Cracked"
    },
    {
      "x": -22,
      "y": 20,
      "z": 4,
      "name": "Rock_Magma_Cooled"
    },
    {
      "x": -22,
      "y": 21,
      "z": 4,
      "name": "Ore_Adamantite_Magma_Cracked"
    },
    {
      "x": -22,
      "y": 22,
      "z": 4,
      "name": "Ore_Adamantite_Magma_Cracked"
    },
    {
      "x": -22,
      "y": 23,
      "z": 4,
      "name": "Rock_Magma_Cooled"
    },
    {
      "x": -22,
      "y": 0,
      "z": 5,
      "name": "Soil_Ash"
    },
    {
      "x": -22,
      "y": 1,
      "z": 5,
      "name": "Soil_Ash"
    },
    {
      "x": -22,
      "y": 2,
      "z": 5,
      "name": "Soil_Ash"
    },
    {
      "x": -22,
      "y": 16,
      "z": 5,
      "name": "Ore_Adamantite_Magma_Cracked"
    },
    {
      "x": -22,
      "y": 17,
      "z": 5,
      "name": "Ore_Adamantite_Magma_Cracked"
    },
    {
      "x": -22,
      "y": 18,
      "z": 5,
      "name": "Ore_Adamantite_Magma_Cracked"
    },
    {
      "x": -22,
      "y": 19,
      "z": 5,
      "name": "Ore_Adamantite_Magma_Cracked"
    },
    {
      "x": -22,
      "y": 20,
      "z": 5,
      "name": "Ore_Adamantite_Magma_Cracked"
    },
    {
      "x": -22,
      "y": 21,
      "z": 5,
      "name": "Rock_Magma_Cooled"
    },
    {
      "x": -22,
      "y": 22,
      "z": 5,
      "name": "Rock_Magma_Cooled"
    },
    {
      "x": -22,
      "y": 23,
      "z": 5,
      "name": "Plant_Vine_Wall_Poisoned",
      "support": 15
    },
    {
      "x": -22,
      "y": 0,
      "z": 6,
      "name": "Soil_Ash"
    },
    {
      "x": -22,
      "y": 1,
      "z": 6,
      "name": "Soil_Ash"
    },
    {
      "x": -22,
      "y": 2,
      "z": 6,
      "name": "Soil_Ash"
    },
    {
      "x": -22,
      "y": 17,
      "z": 6,
      "name": "Rock_Magma_Cooled"
    },
    {
      "x": -22,
      "y": 18,
      "z": 6,
      "name": "Ore_Adamantite_Magma_Cracked"
    },
    {
      "x": -22,
      "y": 19,
      "z": 6,
      "name": "Rock_Magma_Cooled"
    },
    {
      "x": -22,
      "y": 20,
      "z": 6,
      "name": "Plant_Vine_Wall_Poisoned",
      "support": 15
    },
    {
      "x": -22,
      "y": 0,
      "z": 7,
      "name": "Soil_Ash"
    },
    {
      "x": -22,
      "y": 1,
      "z": 7,
      "name": "Soil_Ash"
    },
    {
      "x": -22,
      "y": 2,
      "z": 7,
      "name": "Soil_Ash"
    },
    {
      "x": -22,
      "y": 18,
      "z": 7,
      "name": "Ore_Adamantite_Magma_Cracked"
    },
    {
      "x": -22,
      "y": 0,
      "z": 8,
      "name": "Soil_Ash"
    },
    {
      "x": -22,
      "y": 1,
      "z": 8,
      "name": "Soil_Ash"
    },
    {
      "x": -22,
      "y": 2,
      "z": 8,
      "name": "Soil_Ash"
    },
    {
      "x": -22,
      "y": 0,
      "z": 9,
      "name": "Soil_Ash"
    },
    {
      "x": -22,
      "y": 1,
      "z": 9,
      "name": "Soil_Ash"
    },
    {
      "x": -22,
      "y": 0,
      "z": 10,
      "name": "Soil_Ash"
    },
    {
      "x": -22,
      "y": 1,
      "z": 10,
      "name": "Soil_Sand_Ashen"
    },
    {
      "x": -21,
      "y": 0,
      "z": -9,
      "name": "Soil_Ash"
    },
    {
      "x": -21,
      "y": 0,
      "z": -8,
      "name": "Soil_Sand_Ashen"
    },
    {
      "x": -21,
      "y": 0,
      "z": -7,
      "name": "Soil_Ash"
    },
    {
      "x": -21,
      "y": 1,
      "z": -7,
      "name": "Soil_Ash"
    },
    {
      "x": -21,
      "y": 0,
      "z": -6,
      "name": "Soil_Ash"
    },
    {
      "x": -21,
      "y": 1,
      "z": -6,
      "name": "Soil_Ash"
    },
    {
      "x": -21,
      "y": 0,
      "z": -5,
      "name": "Soil_Ash"
    },
    {
      "x": -21,
      "y": 1,
      "z": -5,
      "name": "Soil_Ash"
    },
    {
      "x": -21,
      "y": 22,
      "z": -5,
      "name": "Plant_Flower_Common_Poisoned2",
      "rotation": 6
    },
    {
      "x": -21,
      "y": 28,
      "z": -5,
      "name": "Ore_Adamantite_Magma_Cracked"
    },
    {
      "x": -21,
      "y": 0,
      "z": -4,
      "name": "Soil_Ash"
    },
    {
      "x": -21,
      "y": 1,
      "z": -4,
      "name": "Soil_Ash"
    },
    {
      "x": -21,
      "y": 2,
      "z": -4,
      "name": "Soil_Ash"
    },
    {
      "x": -21,
      "y": 22,
      "z": -4,
      "name": "Ore_Adamantite_Magma_Cracked"
    },
    {
      "x": -21,
      "y": 27,
      "z": -4,
      "name": "Rock_Magma_Cooled"
    },
    {
      "x": -21,
      "y": 28,
      "z": -4,
      "name": "Rock_Magma_Cooled"
    },
    {
      "x": -21,
      "y": 0,
      "z": -3,
      "name": "Soil_Ash"
    },
    {
      "x": -21,
      "y": 1,
      "z": -3,
      "name": "Soil_Ash"
    },
    {
      "x": -21,
      "y": 2,
      "z": -3,
      "name": "Soil_Ash"
    },
    {
      "x": -21,
      "y": 22,
      "z": -3,
      "name": "Rock_Magma_Cooled"
    },
    {
      "x": -21,
      "y": 23,
      "z": -3,
      "name": "Rock_Magma_Cooled"
    },
    {
      "x": -21,
      "y": 24,
      "z": -3,
      "name": "Plant_Vine_Wall_Poisoned",
      "support": 15,
      "rotation": 1
    },
    {
      "x": -21,
      "y": 26,
      "z": -3,
      "name": "Ore_Adamantite_Magma_Cracked"
    },
    {
      "x": -21,
      "y": 27,
      "z": -3,
      "name": "Ore_Adamantite_Magma_Cracked"
    },
    {
      "x": -21,
      "y": 28,
      "z": -3,
      "name": "Ore_Adamantite_Magma_Cracked"
    },
    {
      "x": -21,
      "y": 0,
      "z": -2,
      "name": "Soil_Ash"
    },
    {
      "x": -21,
      "y": 1,
      "z": -2,
      "name": "Soil_Ash"
    },
    {
      "x": -21,
      "y": 2,
      "z": -2,
      "name": "Soil_Ash"
    },
    {
      "x": -21,
      "y": 16,
      "z": -2,
      "name": "Rock_Magma_Cooled"
    },
    {
      "x": -21,
      "y": 17,
      "z": -2,
      "name": "Rock_Magma_Cooled"
    },
    {
      "x": -21,
      "y": 18,
      "z": -2,
      "name": "Ore_Adamantite_Magma_Cracked"
    },
    {
      "x": -21,
      "y": 22,
      "z": -2,
      "name": "Ore_Adamantite_Magma_Cracked"
    },
    {
      "x": -21,
      "y": 23,
      "z": -2,
      "name": "Rock_Magma_Cooled"
    },
    {
      "x": -21,
      "y": 24,
      "z": -2,
      "name": "Rock_Magma_Cooled"
    },
    {
      "x": -21,
      "y": 25,
      "z": -2,
      "name": "Rock_Magma_Cooled"
    },
    {
      "x": -21,
      "y": 26,
      "z": -2,
      "name": "Rock_Magma_Cooled"
    },
    {
      "x": -21,
      "y": 27,
      "z": -2,
      "name": "Ore_Adamantite_Magma_Cracked"
    },
    {
      "x": -21,
      "y": 0,
      "z": -1,
      "name": "Soil_Ash"
    },
    {
      "x": -21,
      "y": 1,
      "z": -1,
      "name": "Soil_Ash"
    },
    {
      "x": -21,
      "y": 2,
      "z": -1,
      "name": "Soil_Ash"
    },
    {
      "x": -21,
      "y": 3,
      "z": -1,
      "name": "Soil_Ash"
    },
    {
      "x": -21,
      "y": 16,
      "z": -1,
      "name": "Ore_Adamantite_Magma_Cracked"
    },
    {
      "x": -21,
      "y": 17,
      "z": -1,
      "name": "Ore_Adamantite_Magma_Cracked"
    },
    {
      "x": -21,
      "y": 18,
      "z": -1,
      "name": "Ore_Adamantite_Magma_Cracked"
    },
    {
      "x": -21,
      "y": 19,
      "z": -1,
      "name": "Ore_Adamantite_Magma_Cracked"
    },
    {
      "x": -21,
      "y": 20,
      "z": -1,
      "name": "Ore_Adamantite_Magma_Cracked"
    },
    {
      "x": -21,
      "y": 21,
      "z": -1,
      "name": "Rock_Magma_Cooled"
    },
    {
      "x": -21,
      "y": 22,
      "z": -1,
      "name": "Ore_Adamantite_Magma_Cracked"
    },
    {
      "x": -21,
      "y": 23,
      "z": -1,
      "name": "Rock_Magma_Cooled"
    },
    {
      "x": -21,
      "y": 24,
      "z": -1,
      "name": "Ore_Adamantite_Magma_Cracked"
    },
    {
      "x": -21,
      "y": 25,
      "z": -1,
      "name": "Ore_Adamantite_Magma_Cracked"
    },
    {
      "x": -21,
      "y": 26,
      "z": -1,
      "name": "Rock_Magma_Cooled"
    },
    {
      "x": -21,
      "y": 0,
      "z": 0,
      "name": "Soil_Ash"
    },
    {
      "x": -21,
      "y": 1,
      "z": 0,
      "name": "Soil_Ash"
    },
    {
      "x": -21,
      "y": 2,
      "z": 0,
      "name": "Soil_Ash"
    },
    {
      "x": -21,
      "y": 3,
      "z": 0,
      "name": "Soil_Ash"
    },
    {
      "x": -21,
      "y": 15,
      "z": 0,
      "name": "Rock_Magma_Cooled"
    },
    {
      "x": -21,
      "y": 16,
      "z": 0,
      "name": "Rock_Magma_Cooled"
    },
    {
      "x": -21,
      "y": 17,
      "z": 0,
      "name": "Ore_Adamantite_Magma_Cracked"
    },
    {
      "x": -21,
      "y": 18,
      "z": 0,
      "name": "Rock_Magma_Cooled"
    },
    {
      "x": -21,
      "y": 19,
      "z": 0,
      "name": "Ore_Adamantite_Magma_Cracked"
    },
    {
      "x": -21,
      "y": 20,
      "z": 0,
      "name": "Ore_Adamantite_Magma_Cracked"
    },
    {
      "x": -21,
      "y": 21,
      "z": 0,
      "name": "Ore_Adamantite_Magma_Cracked"
    },
    {
      "x": -21,
      "y": 22,
      "z": 0,
      "name": "Ore_Adamantite_Magma_Cracked"
    },
    {
      "x": -21,
      "y": 23,
      "z": 0,
      "name": "Rock_Magma_Cooled"
    },
    {
      "x": -21,
      "y": 24,
      "z": 0,
      "name": "Rock_Magma_Cooled"
    },
    {
      "x": -21,
      "y": 25,
      "z": 0,
      "name": "Ore_Adamantite_Magma_Cracked"
    },
    {
      "x": -21,
      "y": 0,
      "z": 1,
      "name": "Soil_Ash"
    },
    {
      "x": -21,
      "y": 1,
      "z": 1,
      "name": "Soil_Ash"
    },
    {
      "x": -21,
      "y": 2,
      "z": 1,
      "name": "Soil_Ash"
    },
    {
      "x": -21,
      "y": 3,
      "z": 1,
      "name": "Soil_Ash"
    },
    {
      "x": -21,
      "y": 15,
      "z": 1,
      "name": "Ore_Adamantite_Magma_Cracked"
    },
    {
      "x": -21,
      "y": 16,
      "z": 1,
      "name": "Rock_Magma_Cooled"
    },
    {
      "x": -21,
      "y": 17,
      "z": 1,
      "name": "Ore_Adamantite_Magma_Cracked"
    },
    {
      "x": -21,
      "y": 18,
      "z": 1,
      "name": "Ore_Adamantite_Magma_Cracked"
    },
    {
      "x": -21,
      "y": 19,
      "z": 1,
      "name": "Ore_Adamantite_Magma_Cracked"
    },
    {
      "x": -21,
      "y": 20,
      "z": 1,
      "name": "Rock_Magma_Cooled"
    },
    {
      "x": -21,
      "y": 21,
      "z": 1,
      "name": "Rock_Magma_Cooled"
    },
    {
      "x": -21,
      "y": 22,
      "z": 1,
      "name": "Ore_Adamantite_Magma_Cracked"
    },
    {
      "x": -21,
      "y": 23,
      "z": 1,
      "name": "Rock_Magma_Cooled"
    },
    {
      "x": -21,
      "y": 24,
      "z": 1,
      "name": "Ore_Adamantite_Magma_Cracked"
    },
    {
      "x": -21,
      "y": 25,
      "z": 1,
      "name": "Ore_Adamantite_Magma_Cracked"
    },
    {
      "x": -21,
      "y": 0,
      "z": 2,
      "name": "Soil_Ash"
    },
    {
      "x": -21,
      "y": 1,
      "z": 2,
      "name": "Soil_Ash"
    },
    {
      "x": -21,
      "y": 2,
      "z": 2,
      "name": "Soil_Ash"
    },
    {
      "x": -21,
      "y": 3,
      "z": 2,
      "name": "Soil_Ash"
    },
    {
      "x": -21,
      "y": 15,
      "z": 2,
      "name": "Ore_Adamantite_Magma_Cracked"
    },
    {
      "x": -21,
      "y": 16,
      "z": 2,
      "name": "Rock_Magma_Cooled"
    },
    {
      "x": -21,
      "y": 17,
      "z": 2,
      "name": "Rock_Magma_Cooled"
    },
    {
      "x": -21,
      "y": 18,
      "z": 2,
      "name": "Ore_Adamantite_Magma_Cracked"
    },
    {
      "x": -21,
      "y": 19,
      "z": 2,
      "name": "Rock_Magma_Cooled"
    },
    {
      "x": -21,
      "y": 20,
      "z": 2,
      "name": "Rock_Magma_Cooled"
    },
    {
      "x": -21,
      "y": 21,
      "z": 2,
      "name": "Ore_Adamantite_Magma_Cracked"
    },
    {
      "x": -21,
      "y": 22,
      "z": 2,
      "name": "Ore_Adamantite_Magma_Cracked"
    },
    {
      "x": -21,
      "y": 0,
      "z": 3,
      "name": "Soil_Ash"
    },
    {
      "x": -21,
      "y": 1,
      "z": 3,
      "name": "Soil_Ash"
    },
    {
      "x": -21,
      "y": 2,
      "z": 3,
      "name": "Soil_Ash"
    },
    {
      "x": -21,
      "y": 3,
      "z": 3,
      "name": "Soil_Ash"
    },
    {
      "x": -21,
      "y": 15,
      "z": 3,
      "name": "Ore_Adamantite_Magma_Cracked"
    },
    {
      "x": -21,
      "y": 16,
      "z": 3,
      "name": "Rock_Magma_Cooled"
    },
    {
      "x": -21,
      "y": 17,
      "z": 3,
      "name": "Ore_Adamantite_Magma_Cracked"
    },
    {
      "x": -21,
      "y": 18,
      "z": 3,
      "name": "Ore_Adamantite_Magma_Cracked"
    },
    {
      "x": -21,
      "y": 19,
      "z": 3,
      "name": "Ore_Adamantite_Magma_Cracked"
    },
    {
      "x": -21,
      "y": 20,
      "z": 3,
      "name": "Rock_Magma_Cooled"
    },
    {
      "x": -21,
      "y": 21,
      "z": 3,
      "name": "Ore_Adamantite_Magma_Cracked"
    },
    {
      "x": -21,
      "y": 22,
      "z": 3,
      "name": "Rock_Magma_Cooled"
    },
    {
      "x": -21,
      "y": 0,
      "z": 4,
      "name": "Soil_Ash"
    },
    {
      "x": -21,
      "y": 1,
      "z": 4,
      "name": "Soil_Ash"
    },
    {
      "x": -21,
      "y": 2,
      "z": 4,
      "name": "Soil_Ash"
    },
    {
      "x": -21,
      "y": 3,
      "z": 4,
      "name": "Soil_Ash"
    },
    {
      "x": -21,
      "y": 15,
      "z": 4,
      "name": "Rock_Magma_Cooled"
    },
    {
      "x": -21,
      "y": 16,
      "z": 4,
      "name": "Rock_Magma_Cooled"
    },
    {
      "x": -21,
      "y": 17,
      "z": 4,
      "name": "Ore_Adamantite_Magma_Cracked"
    },
    {
      "x": -21,
      "y": 18,
      "z": 4,
      "name": "Rock_Magma_Cooled"
    },
    {
      "x": -21,
      "y": 19,
      "z": 4,
      "name": "Rock_Magma_Cooled"
    },
    {
      "x": -21,
      "y": 20,
      "z": 4,
      "name": "Ore_Adamantite_Magma_Cracked"
    },
    {
      "x": -21,
      "y": 21,
      "z": 4,
      "name": "Ore_Adamantite_Magma_Cracked"
    },
    {
      "x": -21,
      "y": 22,
      "z": 4,
      "name": "Rock_Magma_Cooled"
    },
    {
      "x": -21,
      "y": 0,
      "z": 5,
      "name": "Soil_Ash"
    },
    {
      "x": -21,
      "y": 1,
      "z": 5,
      "name": "Soil_Ash"
    },
    {
      "x": -21,
      "y": 2,
      "z": 5,
      "name": "Soil_Ash"
    },
    {
      "x": -21,
      "y": 3,
      "z": 5,
      "name": "Soil_Ash"
    },
    {
      "x": -21,
      "y": 15,
      "z": 5,
      "name": "Rock_Magma_Cooled"
    },
    {
      "x": -21,
      "y": 16,
      "z": 5,
      "name": "Ore_Adamantite_Magma_Cracked"
    },
    {
      "x": -21,
      "y": 17,
      "z": 5,
      "name": "Rock_Magma_Cooled"
    },
    {
      "x": -21,
      "y": 18,
      "z": 5,
      "name": "Rock_Magma_Cooled"
    },
    {
      "x": -21,
      "y": 19,
      "z": 5,
      "name": "Ore_Adamantite_Magma_Cracked"
    },
    {
      "x": -21,
      "y": 20,
      "z": 5,
      "name": "Ore_Adamantite_Magma_Cracked"
    },
    {
      "x": -21,
      "y": 21,
      "z": 5,
      "name": "Rock_Magma_Cooled"
    },
    {
      "x": -21,
      "y": 22,
      "z": 5,
      "name": "Rock_Magma_Cooled"
    },
    {
      "x": -21,
      "y": 0,
      "z": 6,
      "name": "Soil_Ash"
    },
    {
      "x": -21,
      "y": 1,
      "z": 6,
      "name": "Soil_Ash"
    },
    {
      "x": -21,
      "y": 2,
      "z": 6,
      "name": "Soil_Ash"
    },
    {
      "x": -21,
      "y": 3,
      "z": 6,
      "name": "Soil_Ash"
    },
    {
      "x": -21,
      "y": 16,
      "z": 6,
      "name": "Ore_Adamantite_Magma_Cracked"
    },
    {
      "x": -21,
      "y": 17,
      "z": 6,
      "name": "Ore_Adamantite_Magma_Cracked"
    },
    {
      "x": -21,
      "y": 18,
      "z": 6,
      "name": "Rock_Magma_Cooled"
    },
    {
      "x": -21,
      "y": 19,
      "z": 6,
      "name": "Ore_Adamantite_Magma_Cracked"
    },
    {
      "x": -21,
      "y": 20,
      "z": 6,
      "name": "Rock_Magma_Cooled"
    },
    {
      "x": -21,
      "y": 21,
      "z": 6,
      "name": "Ore_Adamantite_Magma_Cracked"
    },
    {
      "x": -21,
      "y": 0,
      "z": 7,
      "name": "Soil_Ash"
    },
    {
      "x": -21,
      "y": 1,
      "z": 7,
      "name": "Soil_Ash"
    },
    {
      "x": -21,
      "y": 2,
      "z": 7,
      "name": "Soil_Ash"
    },
    {
      "x": -21,
      "y": 3,
      "z": 7,
      "name": "Soil_Ash"
    },
    {
      "x": -21,
      "y": 16,
      "z": 7,
      "name": "Ore_Adamantite_Magma_Cracked"
    },
    {
      "x": -21,
      "y": 17,
      "z": 7,
      "name": "Ore_Adamantite_Magma_Cracked"
    },
    {
      "x": -21,
      "y": 18,
      "z": 7,
      "name": "Ore_Adamantite_Magma_Cracked"
    },
    {
      "x": -21,
      "y": 19,
      "z": 7,
      "name": "Rock_Magma_Cooled"
    },
    {
      "x": -21,
      "y": 0,
      "z": 8,
      "name": "Soil_Ash"
    },
    {
      "x": -21,
      "y": 1,
      "z": 8,
      "name": "Soil_Ash"
    },
    {
      "x": -21,
      "y": 2,
      "z": 8,
      "name": "Soil_Ash"
    },
    {
      "x": -21,
      "y": 3,
      "z": 8,
      "name": "Soil_Ash"
    },
    {
      "x": -21,
      "y": 17,
      "z": 8,
      "name": "Rock_Magma_Cooled"
    },
    {
      "x": -21,
      "y": 19,
      "z": 8,
      "name": "Plant_Vine_Wall_Poisoned",
      "support": 15
    },
    {
      "x": -21,
      "y": 0,
      "z": 9,
      "name": "Soil_Ash"
    },
    {
      "x": -21,
      "y": 1,
      "z": 9,
      "name": "Soil_Ash"
    },
    {
      "x": -21,
      "y": 2,
      "z": 9,
      "name": "Soil_Ash"
    },
    {
      "x": -21,
      "y": 0,
      "z": 10,
      "name": "Soil_Ash"
    },
    {
      "x": -21,
      "y": 1,
      "z": 10,
      "name": "Soil_Ash"
    },
    {
      "x": -21,
      "y": 0,
      "z": 11,
      "name": "Soil_Sand_Ashen"
    },
    {
      "x": -21,
      "y": 1,
      "z": 11,
      "name": "Soil_Ash"
    },
    {
      "x": -20,
      "y": 0,
      "z": -10,
      "name": "Soil_Ash"
    },
    {
      "x": -20,
      "y": 0,
      "z": -9,
      "name": "Soil_Ash"
    },
    {
      "x": -20,
      "y": 0,
      "z": -8,
      "name": "Soil_Ash"
    },
    {
      "x": -20,
      "y": 1,
      "z": -8,
      "name": "Soil_Ash"
    },
    {
      "x": -20,
      "y": 0,
      "z": -7,
      "name": "Soil_Ash"
    },
    {
      "x": -20,
      "y": 1,
      "z": -7,
      "name": "Soil_Ash"
    },
    {
      "x": -20,
      "y": 0,
      "z": -6,
      "name": "Soil_Ash"
    },
    {
      "x": -20,
      "y": 1,
      "z": -6,
      "name": "Soil_Ash"
    },
    {
      "x": -20,
      "y": 2,
      "z": -6,
      "name": "Soil_Ash"
    },
    {
      "x": -20,
      "y": 29,
      "z": -6,
      "name": "Plant_Vine_Wall_Poisoned",
      "support": 15,
      "rotation": 2
    },
    {
      "x": -20,
      "y": 0,
      "z": -5,
      "name": "Soil_Ash"
    },
    {
      "x": -20,
      "y": 1,
      "z": -5,
      "name": "Soil_Ash"
    },
    {
      "x": -20,
      "y": 2,
      "z": -5,
      "name": "Soil_Ash"
    },
    {
      "x": -20,
      "y": 27,
      "z": -5,
      "name": "Rock_Magma_Cooled"
    },
    {
      "x": -20,
      "y": 28,
      "z": -5,
      "name": "Rock_Magma_Cooled"
    },
    {
      "x": -20,
      "y": 29,
      "z": -5,
      "name": "Ore_Adamantite_Magma_Cracked"
    },
    {
      "x": -20,
      "y": 0,
      "z": -4,
      "name": "Soil_Ash"
    },
    {
      "x": -20,
      "y": 1,
      "z": -4,
      "name": "Soil_Ash"
    },
    {
      "x": -20,
      "y": 2,
      "z": -4,
      "name": "Soil_Ash"
    },
    {
      "x": -20,
      "y": 3,
      "z": -4,
      "name": "Soil_Ash"
    },
    {
      "x": -20,
      "y": 26,
      "z": -4,
      "name": "Rock_Magma_Cooled"
    },
    {
      "x": -20,
      "y": 27,
      "z": -4,
      "name": "Ore_Adamantite_Magma_Cracked"
    },
    {
      "x": -20,
      "y": 28,
      "z": -4,
      "name": "Rock_Magma_Cooled"
    },
    {
      "x": -20,
      "y": 29,
      "z": -4,
      "name": "Rock_Magma_Cooled"
    },
    {
      "x": -20,
      "y": 0,
      "z": -3,
      "name": "Soil_Ash"
    },
    {
      "x": -20,
      "y": 1,
      "z": -3,
      "name": "Soil_Ash"
    },
    {
      "x": -20,
      "y": 2,
      "z": -3,
      "name": "Soil_Ash"
    },
    {
      "x": -20,
      "y": 3,
      "z": -3,
      "name": "Soil_Ash"
    },
    {
      "x": -20,
      "y": 25,
      "z": -3,
      "name": "Rock_Magma_Cooled"
    },
    {
      "x": -20,
      "y": 26,
      "z": -3,
      "name": "Rock_Magma_Cooled"
    },
    {
      "x": -20,
      "y": 27,
      "z": -3,
      "name": "Ore_Adamantite_Magma_Cracked"
    },
    {
      "x": -20,
      "y": 28,
      "z": -3,
      "name": "Ore_Adamantite_Magma_Cracked"
    },
    {
      "x": -20,
      "y": 29,
      "z": -3,
      "name": "Rock_Magma_Cooled"
    },
    {
      "x": -20,
      "y": 30,
      "z": -3,
      "name": "Plant_Moss_Rug_Pink",
      "support": 15
    },
    {
      "x": -20,
      "y": 31,
      "z": -3,
      "name": "Rock_Magma_Cooled"
    },
    {
      "x": -20,
      "y": 32,
      "z": -3,
      "name": "Plant_Moss_Rug_Pink",
      "support": 15
    },
    {
      "x": -20,
      "y": 0,
      "z": -2,
      "name": "Soil_Ash"
    },
    {
      "x": -20,
      "y": 1,
      "z": -2,
      "name": "Soil_Ash"
    },
    {
      "x": -20,
      "y": 2,
      "z": -2,
      "name": "Soil_Ash"
    },
    {
      "x": -20,
      "y": 3,
      "z": -2,
      "name": "Soil_Ash"
    },
    {
      "x": -20,
      "y": 17,
      "z": -2,
      "name": "Rock_Magma_Cooled"
    },
    {
      "x": -20,
      "y": 23,
      "z": -2,
      "name": "Ore_Adamantite_Magma_Cracked"
    },
    {
      "x": -20,
      "y": 24,
      "z": -2,
      "name": "Ore_Adamantite_Magma_Cracked"
    },
    {
      "x": -20,
      "y": 25,
      "z": -2,
      "name": "Ore_Adamantite_Magma_Cracked"
    },
    {
      "x": -20,
      "y": 26,
      "z": -2,
      "name": "Rock_Magma_Cooled"
    },
    {
      "x": -20,
      "y": 27,
      "z": -2,
      "name": "Ore_Adamantite_Magma_Cracked"
    },
    {
      "x": -20,
      "y": 28,
      "z": -2,
      "name": "Rock_Magma_Cooled"
    },
    {
      "x": -20,
      "y": 29,
      "z": -2,
      "name": "Rock_Magma_Cooled"
    },
    {
      "x": -20,
      "y": 30,
      "z": -2,
      "name": "Rock_Magma_Cooled"
    },
    {
      "x": -20,
      "y": 31,
      "z": -2,
      "name": "Rock_Magma_Cooled"
    },
    {
      "x": -20,
      "y": 0,
      "z": -1,
      "name": "Soil_Ash"
    },
    {
      "x": -20,
      "y": 1,
      "z": -1,
      "name": "Soil_Ash"
    },
    {
      "x": -20,
      "y": 2,
      "z": -1,
      "name": "Soil_Ash"
    },
    {
      "x": -20,
      "y": 3,
      "z": -1,
      "name": "Soil_Ash"
    },
    {
      "x": -20,
      "y": 4,
      "z": -1,
      "name": "Soil_Ash"
    },
    {
      "x": -20,
      "y": 16,
      "z": -1,
      "name": "Rock_Magma_Cooled"
    },
    {
      "x": -20,
      "y": 17,
      "z": -1,
      "name": "Rock_Magma_Cooled"
    },
    {
      "x": -20,
      "y": 18,
      "z": -1,
      "name": "Ore_Adamantite_Magma_Cracked"
    },
    {
      "x": -20,
      "y": 23,
      "z": -1,
      "name": "Rock_Magma_Cooled"
    },
    {
      "x": -20,
      "y": 24,
      "z": -1,
      "name": "Ore_Adamantite_Magma_Cracked"
    },
    {
      "x": -20,
      "y": 25,
      "z": -1,
      "name": "Rock_Magma_Cooled"
    },
    {
      "x": -20,
      "y": 26,
      "z": -1,
      "name": "Ore_Adamantite_Magma_Cracked"
    },
    {
      "x": -20,
      "y": 27,
      "z": -1,
      "name": "Ore_Adamantite_Magma_Cracked"
    },
    {
      "x": -20,
      "y": 29,
      "z": -1,
      "name": "Ore_Adamantite_Magma_Cracked"
    },
    {
      "x": -20,
      "y": 30,
      "z": -1,
      "name": "Ore_Adamantite_Magma_Cracked"
    },
    {
      "x": -20,
      "y": 0,
      "z": 0,
      "name": "Soil_Ash"
    },
    {
      "x": -20,
      "y": 1,
      "z": 0,
      "name": "Soil_Ash"
    },
    {
      "x": -20,
      "y": 2,
      "z": 0,
      "name": "Soil_Ash"
    },
    {
      "x": -20,
      "y": 3,
      "z": 0,
      "name": "Soil_Ash"
    },
    {
      "x": -20,
      "y": 4,
      "z": 0,
      "name": "Soil_Ash"
    },
    {
      "x": -20,
      "y": 16,
      "z": 0,
      "name": "Rock_Magma_Cooled"
    },
    {
      "x": -20,
      "y": 17,
      "z": 0,
      "name": "Rock_Magma_Cooled"
    },
    {
      "x": -20,
      "y": 18,
      "z": 0,
      "name": "Rock_Magma_Cooled"
    },
    {
      "x": -20,
      "y": 19,
      "z": 0,
      "name": "Rock_Magma_Cooled"
    },
    {
      "x": -20,
      "y": 20,
      "z": 0,
      "name": "Rock_Magma_Cooled"
    },
    {
      "x": -20,
      "y": 23,
      "z": 0,
      "name": "Rock_Magma_Cooled"
    },
    {
      "x": -20,
      "y": 24,
      "z": 0,
      "name": "Rock_Magma_Cooled"
    },
    {
      "x": -20,
      "y": 25,
      "z": 0,
      "name": "Rock_Magma_Cooled"
    },
    {
      "x": -20,
      "y": 26,
      "z": 0,
      "name": "Ore_Adamantite_Magma_Cracked"
    },
    {
      "x": -20,
      "y": 29,
      "z": 0,
      "name": "Rock_Magma_Cooled"
    },
    {
      "x": -20,
      "y": 0,
      "z": 1,
      "name": "Soil_Ash"
    },
    {
      "x": -20,
      "y": 1,
      "z": 1,
      "name": "Soil_Ash"
    },
    {
      "x": -20,
      "y": 2,
      "z": 1,
      "name": "Soil_Ash"
    },
    {
      "x": -20,
      "y": 3,
      "z": 1,
      "name": "Soil_Ash"
    },
    {
      "x": -20,
      "y": 4,
      "z": 1,
      "name": "Soil_Ash"
    },
    {
      "x": -20,
      "y": 15,
      "z": 1,
      "name": "Rock_Magma_Cooled"
    },
    {
      "x": -20,
      "y": 16,
      "z": 1,
      "name": "Rock_Magma_Cooled"
    },
    {
      "x": -20,
      "y": 17,
      "z": 1,
      "name": "Ore_Adamantite_Magma_Cracked"
    },
    {
      "x": -20,
      "y": 18,
      "z": 1,
      "name": "Ore_Adamantite_Magma_Cracked"
    },
    {
      "x": -20,
      "y": 19,
      "z": 1,
      "name": "Rock_Magma_Cooled"
    },
    {
      "x": -20,
      "y": 20,
      "z": 1,
      "name": "Rock_Magma_Cooled"
    },
    {
      "x": -20,
      "y": 21,
      "z": 1,
      "name": "Rock_Magma_Cooled"
    },
    {
      "x": -20,
      "y": 24,
      "z": 1,
      "name": "Ore_Adamantite_Magma_Cracked"
    },
    {
      "x": -20,
      "y": 0,
      "z": 2,
      "name": "Soil_Ash"
    },
    {
      "x": -20,
      "y": 1,
      "z": 2,
      "name": "Soil_Ash"
    },
    {
      "x": -20,
      "y": 2,
      "z": 2,
      "name": "Soil_Ash"
    },
    {
      "x": -20,
      "y": 3,
      "z": 2,
      "name": "Soil_Ash"
    },
    {
      "x": -20,
      "y": 4,
      "z": 2,
      "name": "Soil_Ash"
    },
    {
      "x": -20,
      "y": 15,
      "z": 2,
      "name": "Ore_Adamantite_Magma_Cracked"
    },
    {
      "x": -20,
      "y": 16,
      "z": 2,
      "name": "Rock_Magma_Cooled"
    },
    {
      "x": -20,
      "y": 17,
      "z": 2,
      "name": "Ore_Adamantite_Magma_Cracked"
    },
    {
      "x": -20,
      "y": 18,
      "z": 2,
      "name": "Rock_Magma_Cooled"
    },
    {
      "x": -20,
      "y": 19,
      "z": 2,
      "name": "Rock_Magma_Cooled"
    },
    {
      "x": -20,
      "y": 20,
      "z": 2,
      "name": "Ore_Adamantite_Magma_Cracked"
    },
    {
      "x": -20,
      "y": 21,
      "z": 2,
      "name": "Rock_Magma_Cooled"
    },
    {
      "x": -20,
      "y": 0,
      "z": 3,
      "name": "Soil_Ash"
    },
    {
      "x": -20,
      "y": 1,
      "z": 3,
      "name": "Soil_Ash"
    },
    {
      "x": -20,
      "y": 2,
      "z": 3,
      "name": "Soil_Ash"
    },
    {
      "x": -20,
      "y": 3,
      "z": 3,
      "name": "Soil_Ash"
    },
    {
      "x": -20,
      "y": 4,
      "z": 3,
      "name": "Soil_Ash"
    },
    {
      "x": -20,
      "y": 15,
      "z": 3,
      "name": "Rock_Magma_Cooled"
    },
    {
      "x": -20,
      "y": 16,
      "z": 3,
      "name": "Rock_Magma_Cooled"
    },
    {
      "x": -20,
      "y": 17,
      "z": 3,
      "name": "Rock_Magma_Cooled"
    },
    {
      "x": -20,
      "y": 18,
      "z": 3,
      "name": "Rock_Magma_Cooled"
    },
    {
      "x": -20,
      "y": 19,
      "z": 3,
      "name": "Ore_Adamantite_Magma_Cracked"
    },
    {
      "x": -20,
      "y": 20,
      "z": 3,
      "name": "Rock_Magma_Cooled"
    },
    {
      "x": -20,
      "y": 21,
      "z": 3,
      "name": "Ore_Adamantite_Magma_Cracked"
    },
    {
      "x": -20,
      "y": 0,
      "z": 4,
      "name": "Soil_Ash"
    },
    {
      "x": -20,
      "y": 1,
      "z": 4,
      "name": "Soil_Ash"
    },
    {
      "x": -20,
      "y": 2,
      "z": 4,
      "name": "Soil_Ash"
    },
    {
      "x": -20,
      "y": 3,
      "z": 4,
      "name": "Soil_Ash"
    },
    {
      "x": -20,
      "y": 4,
      "z": 4,
      "name": "Soil_Ash"
    },
    {
      "x": -20,
      "y": 15,
      "z": 4,
      "name": "Ore_Adamantite_Magma_Cracked"
    },
    {
      "x": -20,
      "y": 16,
      "z": 4,
      "name": "Rock_Magma_Cooled"
    },
    {
      "x": -20,
      "y": 17,
      "z": 4,
      "name": "Ore_Adamantite_Magma"
    },
    {
      "x": -20,
      "y": 18,
      "z": 4,
      "name": "Ore_Adamantite_Magma_Cracked"
    },
    {
      "x": -20,
      "y": 19,
      "z": 4,
      "name": "Ore_Adamantite_Magma_Cracked"
    },
    {
      "x": -20,
      "y": 20,
      "z": 4,
      "name": "Ore_Adamantite_Magma_Cracked"
    },
    {
      "x": -20,
      "y": 21,
      "z": 4,
      "name": "Rock_Magma_Cooled"
    },
    {
      "x": -20,
      "y": 0,
      "z": 5,
      "name": "Soil_Ash"
    },
    {
      "x": -20,
      "y": 1,
      "z": 5,
      "name": "Soil_Ash"
    },
    {
      "x": -20,
      "y": 2,
      "z": 5,
      "name": "Soil_Ash"
    },
    {
      "x": -20,
      "y": 3,
      "z": 5,
      "name": "Soil_Ash"
    },
    {
      "x": -20,
      "y": 4,
      "z": 5,
      "name": "Soil_Ash"
    },
    {
      "x": -20,
      "y": 15,
      "z": 5,
      "name": "Ore_Adamantite_Magma_Cracked"
    },
    {
      "x": -20,
      "y": 16,
      "z": 5,
      "name": "Rock_Magma_Cooled"
    },
    {
      "x": -20,
      "y": 17,
      "z": 5,
      "name": "Ore_Adamantite_Magma_Cracked"
    },
    {
      "x": -20,
      "y": 18,
      "z": 5,
      "name": "Rock_Magma_Cooled"
    },
    {
      "x": -20,
      "y": 19,
      "z": 5,
      "name": "Rock_Magma_Cooled"
    },
    {
      "x": -20,
      "y": 20,
      "z": 5,
      "name": "Rock_Magma_Cooled"
    },
    {
      "x": -20,
      "y": 21,
      "z": 5,
      "name": "Rock_Magma_Cooled"
    },
    {
      "x": -20,
      "y": 0,
      "z": 6,
      "name": "Soil_Ash"
    },
    {
      "x": -20,
      "y": 1,
      "z": 6,
      "name": "Soil_Ash"
    },
    {
      "x": -20,
      "y": 2,
      "z": 6,
      "name": "Soil_Ash"
    },
    {
      "x": -20,
      "y": 3,
      "z": 6,
      "name": "Soil_Ash"
    },
    {
      "x": -20,
      "y": 4,
      "z": 6,
      "name": "Soil_Ash"
    },
    {
      "x": -20,
      "y": 15,
      "z": 6,
      "name": "Ore_Adamantite_Magma_Cracked"
    },
    {
      "x": -20,
      "y": 16,
      "z": 6,
      "name": "Ore_Adamantite_Magma_Cracked"
    },
    {
      "x": -20,
      "y": 17,
      "z": 6,
      "name": "Ore_Adamantite_Magma_Cracked"
    },
    {
      "x": -20,
      "y": 18,
      "z": 6,
      "name": "Ore_Adamantite_Magma_Cracked"
    },
    {
      "x": -20,
      "y": 19,
      "z": 6,
      "name": "Ore_Adamantite_Magma_Cracked"
    },
    {
      "x": -20,
      "y": 21,
      "z": 6,
      "name": "Plant_Vine_Wall_Poisoned",
      "support": 15
    },
    {
      "x": -20,
      "y": 0,
      "z": 7,
      "name": "Soil_Ash"
    },
    {
      "x": -20,
      "y": 1,
      "z": 7,
      "name": "Soil_Ash"
    },
    {
      "x": -20,
      "y": 2,
      "z": 7,
      "name": "Soil_Ash"
    },
    {
      "x": -20,
      "y": 3,
      "z": 7,
      "name": "Soil_Ash"
    },
    {
      "x": -20,
      "y": 4,
      "z": 7,
      "name": "Soil_Ash"
    },
    {
      "x": -20,
      "y": 15,
      "z": 7,
      "name": "Plant_Flower_Common_Poisoned2",
      "rotation": 7
    },
    {
      "x": -20,
      "y": 16,
      "z": 7,
      "name": "Rock_Magma_Cooled"
    },
    {
      "x": -20,
      "y": 17,
      "z": 7,
      "name": "Rock_Magma_Cooled"
    },
    {
      "x": -20,
      "y": 18,
      "z": 7,
      "name": "Rock_Magma_Cooled"
    },
    {
      "x": -20,
      "y": 0,
      "z": 8,
      "name": "Soil_Ash"
    },
    {
      "x": -20,
      "y": 1,
      "z": 8,
      "name": "Soil_Ash"
    },
    {
      "x": -20,
      "y": 2,
      "z": 8,
      "name": "Soil_Ash"
    },
    {
      "x": -20,
      "y": 3,
      "z": 8,
      "name": "Soil_Ash"
    },
    {
      "x": -20,
      "y": 4,
      "z": 8,
      "name": "Soil_Ash"
    },
    {
      "x": -20,
      "y": 16,
      "z": 8,
      "name": "Rock_Magma_Cooled"
    },
    {
      "x": -20,
      "y": 17,
      "z": 8,
      "name": "Rock_Magma_Cooled"
    },
    {
      "x": -20,
      "y": 18,
      "z": 8,
      "name": "Ore_Adamantite_Magma_Cracked"
    },
    {
      "x": -20,
      "y": 0,
      "z": 9,
      "name": "Soil_Ash"
    },
    {
      "x": -20,
      "y": 1,
      "z": 9,
      "name": "Soil_Ash"
    },
    {
      "x": -20,
      "y": 2,
      "z": 9,
      "name": "Soil_Ash"
    },
    {
      "x": -20,
      "y": 3,
      "z": 9,
      "name": "Soil_Ash"
    },
    {
      "x": -20,
      "y": 17,
      "z": 9,
      "name": "Rock_Magma_Cooled"
    },
    {
      "x": -20,
      "y": 0,
      "z": 10,
      "name": "Soil_Ash"
    },
    {
      "x": -20,
      "y": 1,
      "z": 10,
      "name": "Soil_Ash"
    },
    {
      "x": -20,
      "y": 2,
      "z": 10,
      "name": "Soil_Ash"
    },
    {
      "x": -20,
      "y": 3,
      "z": 10,
      "name": "Soil_Ash"
    },
    {
      "x": -20,
      "y": 0,
      "z": 11,
      "name": "Soil_Ash"
    },
    {
      "x": -20,
      "y": 1,
      "z": 11,
      "name": "Soil_Ash"
    },
    {
      "x": -20,
      "y": 0,
      "z": 12,
      "name": "Soil_Sand_Ashen"
    },
    {
      "x": -20,
      "y": 1,
      "z": 12,
      "name": "Soil_Ash"
    },
    {
      "x": -19,
      "y": 0,
      "z": -10,
      "name": "Soil_Ash"
    },
    {
      "x": -19,
      "y": 0,
      "z": -9,
      "name": "Soil_Ash"
    },
    {
      "x": -19,
      "y": 1,
      "z": -9,
      "name": "Soil_Ash"
    },
    {
      "x": -19,
      "y": 0,
      "z": -8,
      "name": "Soil_Ash"
    },
    {
      "x": -19,
      "y": 1,
      "z": -8,
      "name": "Soil_Ash"
    },
    {
      "x": -19,
      "y": 0,
      "z": -7,
      "name": "Soil_Ash"
    },
    {
      "x": -19,
      "y": 1,
      "z": -7,
      "name": "Soil_Ash"
    },
    {
      "x": -19,
      "y": 2,
      "z": -7,
      "name": "Soil_Ash"
    },
    {
      "x": -19,
      "y": 0,
      "z": -6,
      "name": "Soil_Ash"
    },
    {
      "x": -19,
      "y": 1,
      "z": -6,
      "name": "Soil_Ash"
    },
    {
      "x": -19,
      "y": 2,
      "z": -6,
      "name": "Soil_Ash"
    },
    {
      "x": -19,
      "y": 28,
      "z": -6,
      "name": "Plant_Vine_Wall_Poisoned",
      "support": 15,
      "rotation": 2
    },
    {
      "x": -19,
      "y": 0,
      "z": -5,
      "name": "Soil_Ash"
    },
    {
      "x": -19,
      "y": 1,
      "z": -5,
      "name": "Soil_Ash"
    },
    {
      "x": -19,
      "y": 2,
      "z": -5,
      "name": "Soil_Ash"
    },
    {
      "x": -19,
      "y": 3,
      "z": -5,
      "name": "Soil_Ash"
    },
    {
      "x": -19,
      "y": 27,
      "z": -5,
      "name": "Plant_Vine_Wall_Poisoned",
      "support": 15,
      "rotation": 1
    },
    {
      "x": -19,
      "y": 28,
      "z": -5,
      "name": "Rock_Magma_Cooled"
    },
    {
      "x": -19,
      "y": 0,
      "z": -4,
      "name": "Soil_Ash"
    },
    {
      "x": -19,
      "y": 1,
      "z": -4,
      "name": "Soil_Ash"
    },
    {
      "x": -19,
      "y": 2,
      "z": -4,
      "name": "Soil_Ash"
    },
    {
      "x": -19,
      "y": 3,
      "z": -4,
      "name": "Soil_Ash"
    },
    {
      "x": -19,
      "y": 27,
      "z": -4,
      "name": "Rock_Magma_Cooled"
    },
    {
      "x": -19,
      "y": 28,
      "z": -4,
      "name": "Ore_Adamantite_Magma_Cracked"
    },
    {
      "x": -19,
      "y": 32,
      "z": -4,
      "name": "Ore_Adamantite_Magma_Cracked"
    },
    {
      "x": -19,
      "y": 33,
      "z": -4,
      "name": "Plant_Moss_Rug_Pink",
      "support": 15
    },
    {
      "x": -19,
      "y": 0,
      "z": -3,
      "name": "Soil_Ash"
    },
    {
      "x": -19,
      "y": 1,
      "z": -3,
      "name": "Soil_Ash"
    },
    {
      "x": -19,
      "y": 2,
      "z": -3,
      "name": "Soil_Ash"
    },
    {
      "x": -19,
      "y": 3,
      "z": -3,
      "name": "Soil_Ash"
    },
    {
      "x": -19,
      "y": 4,
      "z": -3,
      "name": "Soil_Ash"
    },
    {
      "x": -19,
      "y": 26,
      "z": -3,
      "name": "Ore_Adamantite_Magma_Cracked"
    },
    {
      "x": -19,
      "y": 27,
      "z": -3,
      "name": "Rock_Magma_Cooled"
    },
    {
      "x": -19,
      "y": 28,
      "z": -3,
      "name": "Rock_Magma_Cooled"
    },
    {
      "x": -19,
      "y": 29,
      "z": -3,
      "name": "Ore_Adamantite_Magma_Cracked"
    },
    {
      "x": -19,
      "y": 30,
      "z": -3,
      "name": "Rock_Magma_Cooled"
    },
    {
      "x": -19,
      "y": 31,
      "z": -3,
      "name": "Ore_Adamantite_Magma_Cracked"
    },
    {
      "x": -19,
      "y": 32,
      "z": -3,
      "name": "Ore_Adamantite_Magma_Cracked"
    },
    {
      "x": -19,
      "y": 33,
      "z": -3,
      "name": "Plant_Moss_Rug_Pink",
      "support": 15
    },
    {
      "x": -19,
      "y": 0,
      "z": -2,
      "name": "Soil_Ash"
    },
    {
      "x": -19,
      "y": 1,
      "z": -2,
      "name": "Soil_Ash"
    },
    {
      "x": -19,
      "y": 2,
      "z": -2,
      "name": "Soil_Ash"
    },
    {
      "x": -19,
      "y": 3,
      "z": -2,
      "name": "Soil_Ash"
    },
    {
      "x": -19,
      "y": 4,
      "z": -2,
      "name": "Soil_Ash"
    },
    {
      "x": -19,
      "y": 23,
      "z": -2,
      "name": "Plant_Vine_Wall_Poisoned",
      "support": 15,
      "rotation": 1
    },
    {
      "x": -19,
      "y": 25,
      "z": -2,
      "name": "Ore_Adamantite_Magma_Cracked"
    },
    {
      "x": -19,
      "y": 26,
      "z": -2,
      "name": "Ore_Adamantite_Magma_Cracked"
    },
    {
      "x": -19,
      "y": 27,
      "z": -2,
      "name": "Ore_Adamantite_Magma_Cracked"
    },
    {
      "x": -19,
      "y": 28,
      "z": -2,
      "name": "Rock_Magma_Cooled"
    },
    {
      "x": -19,
      "y": 29,
      "z": -2,
      "name": "Ore_Adamantite_Magma_Cracked"
    },
    {
      "x": -19,
      "y": 30,
      "z": -2,
      "name": "Ore_Adamantite_Magma_Cracked"
    },
    {
      "x": -19,
      "y": 31,
      "z": -2,
      "name": "Rock_Magma_Cooled"
    },
    {
      "x": -19,
      "y": 32,
      "z": -2,
      "name": "Rock_Magma_Cooled"
    },
    {
      "x": -19,
      "y": 33,
      "z": -2,
      "name": "Plant_Moss_Rug_Pink",
      "support": 15
    },
    {
      "x": -19,
      "y": 0,
      "z": -1,
      "name": "Soil_Ash"
    },
    {
      "x": -19,
      "y": 1,
      "z": -1,
      "name": "Soil_Ash"
    },
    {
      "x": -19,
      "y": 2,
      "z": -1,
      "name": "Soil_Ash"
    },
    {
      "x": -19,
      "y": 3,
      "z": -1,
      "name": "Soil_Ash"
    },
    {
      "x": -19,
      "y": 4,
      "z": -1,
      "name": "Soil_Ash"
    },
    {
      "x": -19,
      "y": 17,
      "z": -1,
      "name": "Ore_Adamantite_Magma_Cracked"
    },
    {
      "x": -19,
      "y": 25,
      "z": -1,
      "name": "Ore_Adamantite_Magma_Cracked"
    },
    {
      "x": -19,
      "y": 26,
      "z": -1,
      "name": "Ore_Adamantite_Magma_Cracked"
    },
    {
      "x": -19,
      "y": 28,
      "z": -1,
      "name": "Ore_Adamantite_Magma_Cracked"
    },
    {
      "x": -19,
      "y": 29,
      "z": -1,
      "name": "Rock_Magma_Cooled"
    },
    {
      "x": -19,
      "y": 30,
      "z": -1,
      "name": "Ore_Adamantite_Magma_Cracked"
    },
    {
      "x": -19,
      "y": 31,
      "z": -1,
      "name": "Ore_Adamantite_Magma_Cracked"
    },
    {
      "x": -19,
      "y": 0,
      "z": 0,
      "name": "Soil_Ash"
    },
    {
      "x": -19,
      "y": 1,
      "z": 0,
      "name": "Soil_Ash"
    },
    {
      "x": -19,
      "y": 2,
      "z": 0,
      "name": "Soil_Ash"
    },
    {
      "x": -19,
      "y": 3,
      "z": 0,
      "name": "Soil_Ash"
    },
    {
      "x": -19,
      "y": 4,
      "z": 0,
      "name": "Soil_Ash"
    },
    {
      "x": -19,
      "y": 5,
      "z": 0,
      "name": "Soil_Ash"
    },
    {
      "x": -19,
      "y": 16,
      "z": 0,
      "name": "Rock_Magma_Cooled"
    },
    {
      "x": -19,
      "y": 17,
      "z": 0,
      "name": "Ore_Adamantite_Magma_Cracked"
    },
    {
      "x": -19,
      "y": 18,
      "z": 0,
      "name": "Ore_Adamantite_Magma_Cracked"
    },
    {
      "x": -19,
      "y": 25,
      "z": 0,
      "name": "Ore_Adamantite_Magma_Cracked"
    },
    {
      "x": -19,
      "y": 28,
      "z": 0,
      "name": "Ore_Adamantite_Magma_Cracked"
    },
    {
      "x": -19,
      "y": 29,
      "z": 0,
      "name": "Rock_Magma_Cooled"
    },
    {
      "x": -19,
      "y": 30,
      "z": 0,
      "name": "Rock_Magma_Cooled"
    },
    {
      "x": -19,
      "y": 0,
      "z": 1,
      "name": "Soil_Ash"
    },
    {
      "x": -19,
      "y": 1,
      "z": 1,
      "name": "Soil_Ash"
    },
    {
      "x": -19,
      "y": 2,
      "z": 1,
      "name": "Soil_Ash"
    },
    {
      "x": -19,
      "y": 3,
      "z": 1,
      "name": "Soil_Ash"
    },
    {
      "x": -19,
      "y": 4,
      "z": 1,
      "name": "Soil_Ash"
    },
    {
      "x": -19,
      "y": 5,
      "z": 1,
      "name": "Soil_Ash"
    },
    {
      "x": -19,
      "y": 15,
      "z": 1,
      "name": "Ore_Adamantite_Magma_Cracked"
    },
    {
      "x": -19,
      "y": 16,
      "z": 1,
      "name": "Rock_Magma_Cooled"
    },
    {
      "x": -19,
      "y": 17,
      "z": 1,
      "name": "Ore_Adamantite_Magma_Cracked"
    },
    {
      "x": -19,
      "y": 18,
      "z": 1,
      "name": "Ore_Adamantite_Magma_Cracked"
    },
    {
      "x": -19,
      "y": 0,
      "z": 2,
      "name": "Soil_Ash"
    },
    {
      "x": -19,
      "y": 1,
      "z": 2,
      "name": "Soil_Ash"
    },
    {
      "x": -19,
      "y": 2,
      "z": 2,
      "name": "Soil_Ash"
    },
    {
      "x": -19,
      "y": 3,
      "z": 2,
      "name": "Soil_Ash"
    },
    {
      "x": -19,
      "y": 4,
      "z": 2,
      "name": "Soil_Ash"
    },
    {
      "x": -19,
      "y": 5,
      "z": 2,
      "name": "Soil_Ash"
    },
    {
      "x": -19,
      "y": 14,
      "z": 2,
      "name": "Ore_Adamantite_Magma_Cracked"
    },
    {
      "x": -19,
      "y": 15,
      "z": 2,
      "name": "Rock_Magma_Cooled"
    },
    {
      "x": -19,
      "y": 16,
      "z": 2,
      "name": "Ore_Adamantite_Magma_Cracked"
    },
    {
      "x": -19,
      "y": 17,
      "z": 2,
      "name": "Ore_Adamantite_Magma_Cracked"
    },
    {
      "x": -19,
      "y": 18,
      "z": 2,
      "name": "Rock_Magma_Cooled"
    },
    {
      "x": -19,
      "y": 19,
      "z": 2,
      "name": "Ore_Adamantite_Magma_Cracked"
    },
    {
      "x": -19,
      "y": 0,
      "z": 3,
      "name": "Soil_Ash"
    },
    {
      "x": -19,
      "y": 1,
      "z": 3,
      "name": "Soil_Ash"
    },
    {
      "x": -19,
      "y": 2,
      "z": 3,
      "name": "Soil_Ash"
    },
    {
      "x": -19,
      "y": 3,
      "z": 3,
      "name": "Soil_Ash"
    },
    {
      "x": -19,
      "y": 4,
      "z": 3,
      "name": "Soil_Ash"
    },
    {
      "x": -19,
      "y": 5,
      "z": 3,
      "name": "Soil_Ash"
    },
    {
      "x": -19,
      "y": 14,
      "z": 3,
      "name": "Rock_Magma_Cooled"
    },
    {
      "x": -19,
      "y": 15,
      "z": 3,
      "name": "Ore_Adamantite_Magma_Cracked"
    },
    {
      "x": -19,
      "y": 16,
      "z": 3,
      "name": "Rock_Magma_Cooled"
    },
    {
      "x": -19,
      "y": 17,
      "z": 3,
      "name": "Ore_Adamantite_Magma_Cracked"
    },
    {
      "x": -19,
      "y": 18,
      "z": 3,
      "name": "Rock_Magma_Cooled"
    },
    {
      "x": -19,
      "y": 19,
      "z": 3,
      "name": "Rock_Magma_Cooled"
    },
    {
      "x": -19,
      "y": 0,
      "z": 4,
      "name": "Soil_Ash"
    },
    {
      "x": -19,
      "y": 1,
      "z": 4,
      "name": "Soil_Ash"
    },
    {
      "x": -19,
      "y": 2,
      "z": 4,
      "name": "Soil_Ash"
    },
    {
      "x": -19,
      "y": 3,
      "z": 4,
      "name": "Soil_Ash"
    },
    {
      "x": -19,
      "y": 4,
      "z": 4,
      "name": "Soil_Ash"
    },
    {
      "x": -19,
      "y": 5,
      "z": 4,
      "name": "Soil_Ash"
    },
    {
      "x": -19,
      "y": 6,
      "z": 4,
      "name": "Plant_Bramble_Dead_Twisted"
    },
    {
      "x": -19,
      "y": 14,
      "z": 4,
      "name": "Rock_Magma_Cooled"
    },
    {
      "x": -19,
      "y": 15,
      "z": 4,
      "name": "Ore_Adamantite_Magma_Cracked"
    },
    {
      "x": -19,
      "y": 16,
      "z": 4,
      "name": "Ore_Adamantite_Magma_Cracked"
    },
    {
      "x": -19,
      "y": 17,
      "z": 4,
      "name": "Ore_Adamantite_Magma"
    },
    {
      "x": -19,
      "y": 18,
      "z": 4,
      "name": "Ore_Adamantite_Magma_Cracked"
    },
    {
      "x": -19,
      "y": 19,
      "z": 4,
      "name": "Ore_Adamantite_Magma_Cracked"
    },
    {
      "x": -19,
      "y": 0,
      "z": 5,
      "name": "Soil_Ash"
    },
    {
      "x": -19,
      "y": 1,
      "z": 5,
      "name": "Soil_Ash"
    },
    {
      "x": -19,
      "y": 2,
      "z": 5,
      "name": "Soil_Ash"
    },
    {
      "x": -19,
      "y": 3,
      "z": 5,
      "name": "Soil_Ash"
    },
    {
      "x": -19,
      "y": 4,
      "z": 5,
      "name": "Soil_Ash"
    },
    {
      "x": -19,
      "y": 5,
      "z": 5,
      "name": "Soil_Ash"
    },
    {
      "x": -19,
      "y": 6,
      "z": 5,
      "name": "Plant_Bramble_Dead_Twisted"
    },
    {
      "x": -19,
      "y": 14,
      "z": 5,
      "name": "Ore_Adamantite_Magma_Cracked"
    },
    {
      "x": -19,
      "y": 15,
      "z": 5,
      "name": "Rock_Magma_Cooled"
    },
    {
      "x": -19,
      "y": 16,
      "z": 5,
      "name": "Ore_Adamantite_Magma_Cracked"
    },
    {
      "x": -19,
      "y": 17,
      "z": 5,
      "name": "Rock_Magma_Cooled"
    },
    {
      "x": -19,
      "y": 18,
      "z": 5,
      "name": "Ore_Adamantite_Magma_Cracked"
    },
    {
      "x": -19,
      "y": 19,
      "z": 5,
      "name": "Rock_Magma_Cooled"
    },
    {
      "x": -19,
      "y": 0,
      "z": 6,
      "name": "Soil_Ash"
    },
    {
      "x": -19,
      "y": 1,
      "z": 6,
      "name": "Soil_Ash"
    },
    {
      "x": -19,
      "y": 2,
      "z": 6,
      "name": "Soil_Ash"
    },
    {
      "x": -19,
      "y": 3,
      "z": 6,
      "name": "Soil_Ash"
    },
    {
      "x": -19,
      "y": 4,
      "z": 6,
      "name": "Soil_Ash"
    },
    {
      "x": -19,
      "y": 5,
      "z": 6,
      "name": "Soil_Ash"
    },
    {
      "x": -19,
      "y": 6,
      "z": 6,
      "name": "Plant_Bramble_Dead_Twisted"
    },
    {
      "x": -19,
      "y": 15,
      "z": 6,
      "name": "Ore_Adamantite_Magma_Cracked"
    },
    {
      "x": -19,
      "y": 16,
      "z": 6,
      "name": "Ore_Adamantite_Magma_Cracked"
    },
    {
      "x": -19,
      "y": 17,
      "z": 6,
      "name": "Ore_Adamantite_Magma_Cracked"
    },
    {
      "x": -19,
      "y": 18,
      "z": 6,
      "name": "Rock_Magma_Cooled"
    },
    {
      "x": -19,
      "y": 19,
      "z": 6,
      "name": "Rock_Magma_Cooled"
    },
    {
      "x": -19,
      "y": 0,
      "z": 7,
      "name": "Soil_Ash"
    },
    {
      "x": -19,
      "y": 1,
      "z": 7,
      "name": "Soil_Ash"
    },
    {
      "x": -19,
      "y": 2,
      "z": 7,
      "name": "Soil_Ash"
    },
    {
      "x": -19,
      "y": 3,
      "z": 7,
      "name": "Soil_Ash"
    },
    {
      "x": -19,
      "y": 4,
      "z": 7,
      "name": "Soil_Ash"
    },
    {
      "x": -19,
      "y": 5,
      "z": 7,
      "name": "Soil_Ash"
    },
    {
      "x": -19,
      "y": 6,
      "z": 7,
      "name": "Plant_Bramble_Dead_Twisted"
    },
    {
      "x": -19,
      "y": 15,
      "z": 7,
      "name": "Rock_Magma_Cooled"
    },
    {
      "x": -19,
      "y": 16,
      "z": 7,
      "name": "Ore_Adamantite_Magma_Cracked"
    },
    {
      "x": -19,
      "y": 17,
      "z": 7,
      "name": "Ore_Adamantite_Magma_Cracked"
    },
    {
      "x": -19,
      "y": 18,
      "z": 7,
      "name": "Ore_Adamantite_Magma_Cracked"
    },
    {
      "x": -19,
      "y": 19,
      "z": 7,
      "name": "Ore_Adamantite_Magma_Cracked"
    },
    {
      "x": -19,
      "y": 0,
      "z": 8,
      "name": "Soil_Ash"
    },
    {
      "x": -19,
      "y": 1,
      "z": 8,
      "name": "Soil_Ash"
    },
    {
      "x": -19,
      "y": 2,
      "z": 8,
      "name": "Soil_Ash"
    },
    {
      "x": -19,
      "y": 3,
      "z": 8,
      "name": "Soil_Ash"
    },
    {
      "x": -19,
      "y": 4,
      "z": 8,
      "name": "Soil_Ash"
    },
    {
      "x": -19,
      "y": 5,
      "z": 8,
      "name": "Soil_Ash"
    },
    {
      "x": -19,
      "y": 6,
      "z": 8,
      "name": "Plant_Bramble_Dead_Twisted"
    },
    {
      "x": -19,
      "y": 16,
      "z": 8,
      "name": "Ore_Adamantite_Magma_Cracked"
    },
    {
      "x": -19,
      "y": 17,
      "z": 8,
      "name": "Rock_Magma_Cooled"
    },
    {
      "x": -19,
      "y": 18,
      "z": 8,
      "name": "Rock_Magma_Cooled"
    },
    {
      "x": -19,
      "y": 0,
      "z": 9,
      "name": "Soil_Ash"
    },
    {
      "x": -19,
      "y": 1,
      "z": 9,
      "name": "Soil_Ash"
    },
    {
      "x": -19,
      "y": 2,
      "z": 9,
      "name": "Soil_Ash"
    },
    {
      "x": -19,
      "y": 3,
      "z": 9,
      "name": "Soil_Ash"
    },
    {
      "x": -19,
      "y": 4,
      "z": 9,
      "name": "Soil_Ash"
    },
    {
      "x": -19,
      "y": 16,
      "z": 9,
      "name": "Ore_Adamantite_Magma_Cracked"
    },
    {
      "x": -19,
      "y": 17,
      "z": 9,
      "name": "Ore_Adamantite_Magma_Cracked"
    },
    {
      "x": -19,
      "y": 18,
      "z": 9,
      "name": "Ore_Adamantite_Magma_Cracked"
    },
    {
      "x": -19,
      "y": 0,
      "z": 10,
      "name": "Soil_Ash"
    },
    {
      "x": -19,
      "y": 1,
      "z": 10,
      "name": "Soil_Ash"
    },
    {
      "x": -19,
      "y": 2,
      "z": 10,
      "name": "Soil_Ash"
    },
    {
      "x": -19,
      "y": 3,
      "z": 10,
      "name": "Soil_Ash"
    },
    {
      "x": -19,
      "y": 4,
      "z": 10,
      "name": "Soil_Ash"
    },
    {
      "x": -19,
      "y": 17,
      "z": 10,
      "name": "Plant_Vine_Wall_Poisoned",
      "support": 15
    },
    {
      "x": -19,
      "y": 18,
      "z": 10,
      "name": "Plant_Vine_Wall_Poisoned",
      "support": 15
    },
    {
      "x": -19,
      "y": 0,
      "z": 11,
      "name": "Soil_Ash"
    },
    {
      "x": -19,
      "y": 1,
      "z": 11,
      "name": "Soil_Ash"
    },
    {
      "x": -19,
      "y": 2,
      "z": 11,
      "name": "Soil_Ash"
    },
    {
      "x": -19,
      "y": 3,
      "z": 11,
      "name": "Soil_Ash"
    },
    {
      "x": -19,
      "y": 0,
      "z": 12,
      "name": "Soil_Ash"
    },
    {
      "x": -19,
      "y": 1,
      "z": 12,
      "name": "Soil_Ash"
    },
    {
      "x": -19,
      "y": 2,
      "z": 12,
      "name": "Soil_Ash"
    },
    {
      "x": -19,
      "y": 0,
      "z": 13,
      "name": "Soil_Sand_Ashen"
    },
    {
      "x": -19,
      "y": 1,
      "z": 13,
      "name": "Soil_Ash"
    },
    {
      "x": -18,
      "y": 0,
      "z": -10,
      "name": "Soil_Ash"
    },
    {
      "x": -18,
      "y": 0,
      "z": -9,
      "name": "Soil_Sand_Ashen"
    },
    {
      "x": -18,
      "y": 1,
      "z": -9,
      "name": "Soil_Ash"
    },
    {
      "x": -18,
      "y": 0,
      "z": -8,
      "name": "Soil_Ash"
    },
    {
      "x": -18,
      "y": 1,
      "z": -8,
      "name": "Soil_Ash"
    },
    {
      "x": -18,
      "y": 2,
      "z": -8,
      "name": "Soil_Ash"
    },
    {
      "x": -18,
      "y": 0,
      "z": -7,
      "name": "Soil_Ash"
    },
    {
      "x": -18,
      "y": 1,
      "z": -7,
      "name": "Soil_Ash"
    },
    {
      "x": -18,
      "y": 2,
      "z": -7,
      "name": "Soil_Ash"
    },
    {
      "x": -18,
      "y": 0,
      "z": -6,
      "name": "Soil_Ash"
    },
    {
      "x": -18,
      "y": 1,
      "z": -6,
      "name": "Soil_Ash"
    },
    {
      "x": -18,
      "y": 2,
      "z": -6,
      "name": "Soil_Ash"
    },
    {
      "x": -18,
      "y": 3,
      "z": -6,
      "name": "Soil_Ash"
    },
    {
      "x": -18,
      "y": 0,
      "z": -5,
      "name": "Soil_Ash"
    },
    {
      "x": -18,
      "y": 1,
      "z": -5,
      "name": "Soil_Ash"
    },
    {
      "x": -18,
      "y": 2,
      "z": -5,
      "name": "Soil_Ash"
    },
    {
      "x": -18,
      "y": 3,
      "z": -5,
      "name": "Soil_Ash"
    },
    {
      "x": -18,
      "y": 4,
      "z": -5,
      "name": "Soil_Ash"
    },
    {
      "x": -18,
      "y": 0,
      "z": -4,
      "name": "Soil_Ash"
    },
    {
      "x": -18,
      "y": 1,
      "z": -4,
      "name": "Soil_Ash"
    },
    {
      "x": -18,
      "y": 2,
      "z": -4,
      "name": "Soil_Ash"
    },
    {
      "x": -18,
      "y": 3,
      "z": -4,
      "name": "Soil_Ash"
    },
    {
      "x": -18,
      "y": 4,
      "z": -4,
      "name": "Soil_Ash"
    },
    {
      "x": -18,
      "y": 31,
      "z": -4,
      "name": "Ore_Adamantite_Magma_Cracked"
    },
    {
      "x": -18,
      "y": 32,
      "z": -4,
      "name": "Ore_Adamantite_Magma_Cracked"
    },
    {
      "x": -18,
      "y": 33,
      "z": -4,
      "name": "Rock_Magma_Cooled"
    },
    {
      "x": -18,
      "y": 34,
      "z": -4,
      "name": "Plant_Moss_Rug_Pink",
      "support": 15
    },
    {
      "x": -18,
      "y": 0,
      "z": -3,
      "name": "Soil_Ash"
    },
    {
      "x": -18,
      "y": 1,
      "z": -3,
      "name": "Soil_Ash"
    },
    {
      "x": -18,
      "y": 2,
      "z": -3,
      "name": "Soil_Ash"
    },
    {
      "x": -18,
      "y": 3,
      "z": -3,
      "name": "Soil_Ash"
    },
    {
      "x": -18,
      "y": 4,
      "z": -3,
      "name": "Soil_Ash"
    },
    {
      "x": -18,
      "y": 5,
      "z": -3,
      "name": "Soil_Ash"
    },
    {
      "x": -18,
      "y": 29,
      "z": -3,
      "name": "Ore_Adamantite_Magma_Cracked"
    },
    {
      "x": -18,
      "y": 31,
      "z": -3,
      "name": "Rock_Magma_Cooled"
    },
    {
      "x": -18,
      "y": 32,
      "z": -3,
      "name": "Ore_Adamantite_Magma_Cracked"
    },
    {
      "x": -18,
      "y": 33,
      "z": -3,
      "name": "Rock_Magma_Cooled"
    },
    {
      "x": -18,
      "y": 34,
      "z": -3,
      "name": "Plant_Moss_Rug_Pink",
      "support": 15
    },
    {
      "x": -18,
      "y": 0,
      "z": -2,
      "name": "Soil_Ash"
    },
    {
      "x": -18,
      "y": 1,
      "z": -2,
      "name": "Soil_Ash"
    },
    {
      "x": -18,
      "y": 2,
      "z": -2,
      "name": "Soil_Ash"
    },
    {
      "x": -18,
      "y": 3,
      "z": -2,
      "name": "Soil_Ash"
    },
    {
      "x": -18,
      "y": 4,
      "z": -2,
      "name": "Soil_Ash"
    },
    {
