{
  "version": 8,
  "blockIdVersion": 11,
  "anchorX": 0,
  "anchorY": 0,
  "anchorZ": 0,
  "blocks": [
    {
      "x": -1,
      "y": 97,
      "z": -9,
      "name": "Rock_Crystal_Red_Block",
      "rotation": 4
    },
    {
      "x": -1,
      "y": 113,
      "z": -9,
      "name": "Rock_Crystal_Red_Block",
      "rotation": 4
    },
    {
      "x": -1,
      "y": 97,
      "z": -8,
      "name": "Rock_Crystal_Red_Block",
      "rotation": 6
    },
    {
      "x": -1,
      "y": 98,
      "z": -8,
      "name": "Rock_Crystal_Red_Block",
      "rotation": 4
    },
    {
      "x": -1,
      "y": 112,
      "z": -8,
      "name": "Rock_Crystal_Red_Block",
      "rotation": 4
    },
    {
      "x": -1,
      "y": 113,
      "z": -8,
      "name": "Rock_Crystal_Red_Block",
      "rotation": 6
    },
    {
      "x": -1,
      "y": 98,
      "z": -7,
      "name": "Rock_Crystal_Red_Block",
      "rotation": 6
    },
    {
      "x": -1,
      "y": 99,
      "z": -7,
      "name": "Rock_Crystal_Red_Block",
      "rotation": 4
    },
    {
      "x": -1,
      "y": 111,
      "z": -7,
      "name": "Rock_Crystal_Red_Block",
      "rotation": 4
    },
    {
      "x": -1,
      "y": 112,
      "z": -7,
      "name": "Rock_Crystal_Red_Block",
      "rotation": 6
    },
    {
      "x": -1,
      "y": 99,
      "z": -6,
      "name": "Rock_Crystal_Red_Block",
      "rotation": 6
    },
    {
      "x": -1,
      "y": 100,
      "z": -6,
      "name": "Rock_Crystal_Red_Block",
      "rotation": 4
    },
    {
      "x": -1,
      "y": 110,
      "z": -6,
      "name": "Rock_Crystal_Red_Block",
      "rotation": 4
    },
    {
      "x": -1,
      "y": 111,
      "z": -6,
      "name": "Rock_Crystal_Red_Block",
      "rotation": 6
    },
    {
      "x": -1,
      "y": 100,
      "z": -5,
      "name": "Rock_Crystal_Red_Block",
      "rotation": 6
    },
    {
      "x": -1,
      "y": 101,
      "z": -5,
      "name": "Rock_Crystal_Red_Block",
      "rotation": 4
    },
    {
      "x": -1,
      "y": 109,
      "z": -5,
      "name": "Rock_Crystal_Red_Block",
      "rotation": 4
    },
    {
      "x": -1,
      "y": 110,
      "z": -5,
      "name": "Rock_Crystal_Red_Block",
      "rotation": 6
    },
    {
      "x": -1,
      "y": 101,
      "z": -4,
      "name": "Rock_Crystal_Red_Block",
      "rotation": 6
    },
    {
      "x": -1,
      "y": 102,
      "z": -4,
      "name": "Rock_Crystal_Red_Block",
      "rotation": 4
    },
    {
      "x": -1,
      "y": 108,
      "z": -4,
      "name": "Rock_Crystal_Red_Block",
      "rotation": 4
    },
    {
      "x": -1,
      "y": 109,
      "z": -4,
      "name": "Rock_Crystal_Red_Block",
      "rotation": 6
    },
    {
      "x": -1,
      "y": 102,
      "z": -3,
      "name": "Rock_Crystal_Red_Block",
      "rotation": 6
    },
    {
      "x": -1,
      "y": 103,
      "z": -3,
      "name": "Rock_Crystal_Red_Block",
      "rotation": 4
    },
    {
      "x": -1,
      "y": 107,
      "z": -3,
      "name": "Rock_Crystal_Red_Block",
      "rotation": 4
    },
    {
      "x": -1,
      "y": 108,
      "z": -3,
      "name": "Rock_Crystal_Red_Block",
      "rotation": 6
    },
    {
      "x": -1,
      "y": 103,
      "z": -2,
      "name": "Rock_Crystal_Red_Block",
      "rotation": 6
    },
    {
      "x": -1,
      "y": 104,
      "z": -2,
      "name": "Rock_Crystal_Red_Block",
      "rotation": 4
    },
    {
      "x": -1,
      "y": 106,
      "z": -2,
      "name": "Rock_Crystal_Red_Block",
      "rotation": 4
    },
    {
      "x": -1,
      "y": 107,
      "z": -2,
      "name": "Rock_Crystal_Red_Block",
      "rotation": 6
    },
    {
      "x": -1,
      "y": 104,
      "z": -1,
      "name": "Rock_Crystal_Red_Block",
      "rotation": 6
    },
    {
      "x": -1,
      "y": 105,
      "z": -1,
      "name": "Rock_Crystal_Red_Block",
      "rotation": 4
    },
    {
      "x": -1,
      "y": 106,
      "z": -1,
      "name": "Rock_Crystal_Red_Block",
      "rotation": 6
    },
    {
      "x": -1,
      "y": 105,
      "z": 0,
      "name": "Rock_Crystal_Red_Block",
      "rotation": 6
    },
    {
      "x": -1,
      "y": 0,
      "z": 1,
      "name": "Rock_Crystal_Red_Block",
      "rotation": 6
    },
    {
      "x": -1,
      "y": 1,
      "z": 1,
      "name": "Rock_Crystal_Red_Block",
      "rotation": 6
    },
    {
      "x": -1,
      "y": 2,
      "z": 1,
      "name": "Rock_Crystal_Red_Block",
      "rotation": 6
    },
    {
      "x": -1,
      "y": 3,
      "z": 1,
      "name": "Rock_Crystal_Red_Block",
      "rotation": 6
    },
    {
      "x": -1,
      "y": 4,
      "z": 1,
      "name": "Rock_Crystal_Red_Block",
      "rotation": 6
    },
    {
      "x": -1,
      "y": 5,
      "z": 1,
      "name": "Rock_Crystal_Red_Block",
      "rotation": 6
    },
    {
      "x": -1,
      "y": 6,
      "z": 1,
      "name": "Rock_Crystal_Red_Block",
      "rotation": 6
    },
    {
      "x": -1,
      "y": 7,
      "z": 1,
      "name": "Rock_Crystal_Red_Block",
      "rotation": 6
    },
    {
      "x": -1,
      "y": 8,
      "z": 1,
      "name": "Rock_Crystal_Red_Block",
      "rotation": 6
    },
    {
      "x": -1,
      "y": 9,
      "z": 1,
      "name": "Rock_Crystal_Red_Block",
      "rotation": 6
    },
    {
      "x": -1,
      "y": 10,
      "z": 1,
      "name": "Rock_Crystal_Red_Block",
      "rotation": 6
    },
    {
      "x": -1,
      "y": 11,
      "z": 1,
      "name": "Rock_Crystal_Red_Block",
      "rotation": 6
    },
    {
      "x": -1,
      "y": 12,
      "z": 1,
      "name": "Rock_Crystal_Red_Block",
      "rotation": 6
    },
    {
      "x": -1,
      "y": 13,
      "z": 1,
      "name": "Rock_Crystal_Red_Block",
      "rotation": 6
    },
    {
      "x": -1,
      "y": 14,
      "z": 1,
      "name": "Rock_Crystal_Red_Block",
      "rotation": 6
    },
    {
      "x": -1,
      "y": 15,
      "z": 1,
      "name": "Rock_Crystal_Red_Block",
      "rotation": 6
    },
    {
      "x": -1,
      "y": 16,
      "z": 1,
      "name": "Rock_Crystal_Red_Block",
      "rotation": 6
    },
    {
      "x": -1,
      "y": 17,
      "z": 1,
      "name": "Rock_Crystal_Red_Block",
      "rotation": 6
    },
    {
      "x": -1,
      "y": 18,
      "z": 1,
      "name": "Rock_Crystal_Red_Block",
      "rotation": 6
    },
    {
      "x": -1,
      "y": 19,
      "z": 1,
      "name": "Rock_Crystal_Red_Block",
      "rotation": 6
    },
    {
      "x": -1,
      "y": 20,
      "z": 1,
      "name": "Rock_Crystal_Red_Block",
      "rotation": 6
    },
    {
      "x": -1,
      "y": 21,
      "z": 1,
      "name": "Rock_Crystal_Red_Block",
      "rotation": 6
    },
    {
      "x": -1,
      "y": 22,
      "z": 1,
      "name": "Rock_Crystal_Red_Block",
      "rotation": 6
    },
    {
      "x": -1,
      "y": 23,
      "z": 1,
      "name": "Rock_Crystal_Red_Block",
      "rotation": 6
    },
    {
      "x": -1,
      "y": 24,
      "z": 1,
      "name": "Rock_Crystal_Red_Block",
      "rotation": 6
    },
    {
      "x": -1,
      "y": 25,
      "z": 1,
      "name": "Rock_Crystal_Red_Block",
      "rotation": 6
    },
    {
      "x": -1,
      "y": 26,
      "z": 1,
      "name": "Rock_Crystal_Red_Block",
      "rotation": 6
    },
    {
      "x": -1,
      "y": 27,
      "z": 1,
      "name": "Rock_Crystal_Red_Block",
      "rotation": 6
    },
    {
      "x": -1,
      "y": 28,
      "z": 1,
      "name": "Rock_Crystal_Red_Block",
      "rotation": 6
    },
    {
      "x": -1,
      "y": 29,
      "z": 1,
      "name": "Rock_Crystal_Red_Block",
      "rotation": 6
    },
    {
      "x": -1,
      "y": 30,
      "z": 1,
      "name": "Rock_Crystal_Red_Block",
      "rotation": 6
    },
    {
      "x": -1,
      "y": 31,
      "z": 1,
      "name": "Rock_Crystal_Red_Block",
      "rotation": 6
    },
    {
      "x": -1,
      "y": 32,
      "z": 1,
      "name": "Rock_Crystal_Red_Block",
      "rotation": 6
    },
    {
      "x": -1,
      "y": 33,
      "z": 1,
      "name": "Rock_Crystal_Red_Block",
      "rotation": 6
    },
    {
      "x": -1,
      "y": 34,
      "z": 1,
      "name": "Rock_Crystal_Red_Block",
      "rotation": 6
    },
    {
      "x": -1,
      "y": 35,
      "z": 1,
      "name": "Rock_Crystal_Red_Block",
      "rotation": 6
    },
    {
      "x": -1,
      "y": 36,
      "z": 1,
      "name": "Rock_Crystal_Red_Block",
      "rotation": 6
    },
    {
      "x": -1,
      "y": 37,
      "z": 1,
      "name": "Rock_Crystal_Red_Block",
      "rotation": 6
    },
    {
      "x": -1,
      "y": 38,
      "z": 1,
      "name": "Rock_Crystal_Red_Block",
      "rotation": 6
    },
    {
      "x": -1,
      "y": 39,
      "z": 1,
      "name": "Rock_Crystal_Red_Block",
      "rotation": 6
    },
    {
      "x": -1,
      "y": 40,
      "z": 1,
      "name": "Rock_Crystal_Red_Block",
      "rotation": 6
    },
    {
      "x": -1,
      "y": 41,
      "z": 1,
      "name": "Rock_Crystal_Red_Block",
      "rotation": 6
    },
    {
      "x": -1,
      "y": 42,
      "z": 1,
      "name": "Rock_Crystal_Red_Block",
      "rotation": 6
    },
    {
      "x": -1,
      "y": 43,
      "z": 1,
      "name": "Rock_Crystal_Red_Block",
      "rotation": 6
    },
    {
      "x": -1,
      "y": 44,
      "z": 1,
      "name": "Rock_Crystal_Red_Block",
      "rotation": 6
    },
    {
      "x": -1,
      "y": 45,
      "z": 1,
      "name": "Rock_Crystal_Red_Block",
      "rotation": 6
    },
    {
      "x": -1,
      "y": 46,
      "z": 1,
      "name": "Rock_Crystal_Red_Block",
      "rotation": 6
    },
    {
      "x": -1,
      "y": 47,
      "z": 1,
      "name": "Rock_Crystal_Red_Block",
      "rotation": 6
    },
    {
      "x": -1,
      "y": 48,
      "z": 1,
      "name": "Rock_Crystal_Red_Block",
      "rotation": 6
    },
    {
      "x": -1,
      "y": 49,
      "z": 1,
      "name": "Rock_Crystal_Red_Block",
      "rotation": 6
    },
    {
      "x": -1,
      "y": 50,
      "z": 1,
      "name": "Rock_Crystal_Red_Block",
      "rotation": 6
    },
    {
      "x": -1,
      "y": 51,
      "z": 1,
      "name": "Rock_Crystal_Red_Block",
      "rotation": 6
    },
    {
      "x": -1,
      "y": 52,
      "z": 1,
      "name": "Rock_Crystal_Red_Block",
      "rotation": 6
    },
    {
      "x": -1,
      "y": 53,
      "z": 1,
      "name": "Rock_Crystal_Red_Block",
      "rotation": 6
    },
    {
      "x": -1,
      "y": 54,
      "z": 1,
      "name": "Rock_Crystal_Red_Block",
      "rotation": 6
    },
    {
      "x": -1,
      "y": 55,
      "z": 1,
      "name": "Rock_Crystal_Red_Block",
      "rotation": 6
    },
    {
      "x": -1,
      "y": 56,
      "z": 1,
      "name": "Rock_Crystal_Red_Block",
      "rotation": 6
    },
    {
      "x": -1,
      "y": 57,
      "z": 1,
      "name": "Rock_Crystal_Red_Block",
      "rotation": 6
    },
    {
      "x": -1,
      "y": 58,
      "z": 1,
      "name": "Rock_Crystal_Red_Block",
      "rotation": 6
    },
    {
      "x": -1,
      "y": 59,
      "z": 1,
      "name": "Rock_Crystal_Red_Block",
      "rotation": 6
    },
    {
      "x": -1,
      "y": 60,
      "z": 1,
      "name": "Rock_Crystal_Red_Block",
      "rotation": 6
    },
    {
      "x": -1,
      "y": 61,
      "z": 1,
      "name": "Rock_Crystal_Red_Block",
      "rotation": 6
    },
    {
      "x": -1,
      "y": 62,
      "z": 1,
      "name": "Rock_Crystal_Red_Block",
      "rotation": 6
    },
    {
      "x": -1,
      "y": 63,
      "z": 1,
      "name": "Rock_Crystal_Red_Block",
      "rotation": 6
    },
    {
      "x": -1,
      "y": 64,
      "z": 1,
      "name": "Rock_Crystal_Red_Block",
      "rotation": 6
    },
    {
      "x": -1,
      "y": 65,
      "z": 1,
      "name": "Rock_Crystal_Red_Block",
      "rotation": 6
    },
    {
      "x": -1,
      "y": 66,
      "z": 1,
      "name": "Rock_Crystal_Red_Block",
      "rotation": 6
    },
    {
      "x": -1,
      "y": 67,
      "z": 1,
      "name": "Rock_Crystal_Red_Block",
      "rotation": 6
    },
    {
      "x": -1,
      "y": 68,
      "z": 1,
      "name": "Rock_Crystal_Red_Block",
      "rotation": 6
    },
    {
      "x": -1,
      "y": 69,
      "z": 1,
      "name": "Rock_Crystal_Red_Block",
      "rotation": 6
    },
    {
      "x": -1,
      "y": 70,
      "z": 1,
      "name": "Rock_Crystal_Red_Block",
      "rotation": 6
    },
    {
      "x": -1,
      "y": 71,
      "z": 1,
      "name": "Rock_Crystal_Red_Block",
      "rotation": 6
    },
    {
      "x": -1,
      "y": 72,
      "z": 1,
      "name": "Rock_Crystal_Red_Block",
      "rotation": 6
    },
    {
      "x": -1,
      "y": 73,
      "z": 1,
      "name": "Rock_Crystal_Red_Block",
      "rotation": 6
    },
    {
      "x": -1,
      "y": 74,
      "z": 1,
      "name": "Rock_Crystal_Red_Block",
      "rotation": 6
    },
    {
      "x": -1,
      "y": 75,
      "z": 1,
      "name": "Rock_Crystal_Red_Block",
      "rotation": 6
    },
    {
      "x": -1,
      "y": 76,
      "z": 1,
      "name": "Rock_Crystal_Red_Block",
      "rotation": 6
    },
    {
      "x": -1,
      "y": 77,
      "z": 1,
      "name": "Rock_Crystal_Red_Block",
      "rotation": 6
    },
    {
      "x": -1,
      "y": 78,
      "z": 1,
      "name": "Rock_Crystal_Red_Block",
      "rotation": 6
    },
    {
      "x": -1,
      "y": 79,
      "z": 1,
      "name": "Rock_Crystal_Red_Block",
      "rotation": 6
    },
    {
      "x": -1,
      "y": 80,
      "z": 1,
      "name": "Rock_Crystal_Red_Block",
      "rotation": 6
    },
    {
      "x": -1,
      "y": 81,
      "z": 1,
      "name": "Rock_Crystal_Red_Block",
      "rotation": 6
    },
    {
      "x": -1,
      "y": 82,
      "z": 1,
      "name": "Rock_Crystal_Red_Block",
      "rotation": 6
    },
    {
      "x": -1,
      "y": 83,
      "z": 1,
      "name": "Rock_Crystal_Red_Block",
      "rotation": 6
    },
    {
      "x": -1,
      "y": 84,
      "z": 1,
      "name": "Rock_Crystal_Red_Block",
      "rotation": 6
    },
    {
      "x": -1,
      "y": 85,
      "z": 1,
      "name": "Rock_Crystal_Red_Block",
      "rotation": 6
    },
    {
      "x": -1,
      "y": 86,
      "z": 1,
      "name": "Rock_Crystal_Red_Block",
      "rotation": 6
    },
    {
      "x": -1,
      "y": 87,
      "z": 1,
      "name": "Rock_Crystal_Red_Block",
      "rotation": 6
    },
    {
      "x": -1,
      "y": 88,
      "z": 1,
      "name": "Rock_Crystal_Red_Block",
      "rotation": 6
    },
    {
      "x": -1,
      "y": 89,
      "z": 1,
      "name": "Rock_Crystal_Red_Block",
      "rotation": 6
    },
    {
      "x": -1,
      "y": 90,
      "z": 1,
      "name": "Rock_Crystal_Red_Block",
      "rotation": 6
    },
    {
      "x": -1,
      "y": 91,
      "z": 1,
      "name": "Rock_Crystal_Red_Block",
      "rotation": 6
    },
    {
      "x": -1,
      "y": 92,
      "z": 1,
      "name": "Rock_Crystal_Red_Block",
      "rotation": 6
    },
    {
      "x": -1,
      "y": 93,
      "z": 1,
      "name": "Rock_Crystal_Red_Block",
      "rotation": 6
    },
    {
      "x": -1,
      "y": 94,
      "z": 1,
      "name": "Rock_Crystal_Red_Block",
      "rotation": 6
    },
    {
      "x": -1,
      "y": 95,
      "z": 1,
      "name": "Rock_Crystal_Red_Block",
      "rotation": 6
    },
    {
      "x": -1,
      "y": 96,
      "z": 1,
      "name": "Rock_Crystal_Red_Block",
      "rotation": 6
    },
    {
      "x": -1,
      "y": 97,
      "z": 1,
      "name": "Rock_Crystal_Red_Block",
      "rotation": 6
    },
    {
      "x": -1,
      "y": 98,
      "z": 1,
      "name": "Rock_Crystal_Red_Block",
      "rotation": 6
    },
    {
      "x": -1,
      "y": 99,
      "z": 1,
      "name": "Rock_Crystal_Red_Block",
      "rotation": 6
    },
    {
      "x": -1,
      "y": 100,
      "z": 1,
      "name": "Rock_Crystal_Red_Block",
      "rotation": 6
    },
    {
      "x": -1,
      "y": 101,
      "z": 1,
      "name": "Rock_Crystal_Red_Block",
      "rotation": 6
    },
    {
      "x": -1,
      "y": 102,
      "z": 1,
      "name": "Rock_Crystal_Red_Block",
      "rotation": 6
    },
    {
      "x": -1,
      "y": 103,
      "z": 1,
      "name": "Rock_Crystal_Red_Block",
      "rotation": 6
    },
    {
      "x": -1,
      "y": 104,
      "z": 1,
      "name": "Rock_Crystal_Red_Block",
      "rotation": 4
    },
    {
      "x": -1,
      "y": 105,
      "z": 1,
      "name": "Rock_Gem_Ruby",
      "rotation": 7
    },
    {
      "x": -1,
      "y": 106,
      "z": 1,
      "name": "Rock_Crystal_Red_Block",
      "rotation": 6
    },
    {
      "x": -1,
      "y": 107,
      "z": 1,
      "name": "Rock_Crystal_Red_Block",
      "rotation": 6
    },
    {
      "x": -1,
      "y": 108,
      "z": 1,
      "name": "Rock_Crystal_Red_Block",
      "rotation": 6
    },
    {
      "x": -1,
      "y": 109,
      "z": 1,
      "name": "Rock_Crystal_Red_Block",
      "rotation": 6
    },
    {
      "x": -1,
      "y": 110,
      "z": 1,
      "name": "Rock_Crystal_Red_Block",
      "rotation": 6
    },
    {
      "x": -1,
      "y": 111,
      "z": 1,
      "name": "Rock_Crystal_Red_Block",
      "rotation": 6
    },
    {
      "x": -1,
      "y": 112,
      "z": 1,
      "name": "Rock_Crystal_Red_Block",
      "rotation": 6
    },
    {
      "x": -1,
      "y": 113,
      "z": 1,
      "name": "Rock_Crystal_Red_Block",
      "rotation": 6
    },
    {
      "x": -1,
      "y": 114,
      "z": 1,
      "name": "Rock_Crystal_Red_Block",
      "rotation": 6
    },
    {
      "x": -1,
      "y": 115,
      "z": 1,
      "name": "Rock_Crystal_Red_Block",
      "rotation": 6
    },
    {
      "x": -1,
      "y": 116,
      "z": 1,
      "name": "Rock_Crystal_Red_Block",
      "rotation": 4
    },
    {
      "x": -1,
      "y": 105,
      "z": 2,
      "name": "Rock_Crystal_Red_Block",
      "rotation": 6
    },
    {
      "x": -1,
      "y": 104,
      "z": 3,
      "name": "Rock_Crystal_Red_Block",
      "rotation": 6
    },
    {
      "x": -1,
      "y": 105,
      "z": 3,
      "name": "Rock_Crystal_Red_Block",
      "rotation": 4
    },
    {
      "x": -1,
      "y": 106,
      "z": 3,
      "name": "Rock_Crystal_Red_Block",
      "rotation": 6
    },
    {
      "x": -1,
      "y": 103,
      "z": 4,
      "name": "Rock_Crystal_Red_Block",
      "rotation": 6
    },
    {
      "x": -1,
      "y": 104,
      "z": 4,
      "name": "Rock_Crystal_Red_Block",
      "rotation": 4
    },
    {
      "x": -1,
      "y": 106,
      "z": 4,
      "name": "Rock_Crystal_Red_Block",
      "rotation": 4
    },
    {
      "x": -1,
      "y": 107,
      "z": 4,
      "name": "Rock_Crystal_Red_Block",
      "rotation": 6
    },
    {
      "x": -1,
      "y": 102,
      "z": 5,
      "name": "Rock_Crystal_Red_Block",
      "rotation": 6
    },
    {
      "x": -1,
      "y": 103,
      "z": 5,
      "name": "Rock_Crystal_Red_Block",
      "rotation": 4
    },
    {
      "x": -1,
      "y": 107,
      "z": 5,
      "name": "Rock_Crystal_Red_Block",
      "rotation": 4
    },
    {
      "x": -1,
      "y": 108,
      "z": 5,
      "name": "Rock_Crystal_Red_Block",
      "rotation": 6
    },
    {
      "x": -1,
      "y": 101,
      "z": 6,
      "name": "Rock_Crystal_Red_Block",
      "rotation": 6
    },
    {
      "x": -1,
      "y": 102,
      "z": 6,
      "name": "Rock_Crystal_Red_Block",
      "rotation": 4
    },
    {
      "x": -1,
      "y": 108,
      "z": 6,
      "name": "Rock_Crystal_Red_Block",
      "rotation": 4
    },
    {
      "x": -1,
      "y": 109,
      "z": 6,
      "name": "Rock_Crystal_Red_Block",
      "rotation": 6
    },
    {
      "x": -1,
      "y": 100,
      "z": 7,
      "name": "Rock_Crystal_Red_Block",
      "rotation": 6
    },
    {
      "x": -1,
      "y": 101,
      "z": 7,
      "name": "Rock_Crystal_Red_Block",
      "rotation": 4
    },
    {
      "x": -1,
      "y": 109,
      "z": 7,
      "name": "Rock_Crystal_Red_Block",
      "rotation": 4
    },
    {
      "x": -1,
      "y": 110,
      "z": 7,
      "name": "Rock_Crystal_Red_Block",
      "rotation": 6
    },
    {
      "x": -1,
      "y": 99,
      "z": 8,
      "name": "Rock_Crystal_Red_Block",
      "rotation": 6
    },
    {
      "x": -1,
      "y": 100,
      "z": 8,
      "name": "Rock_Crystal_Red_Block",
      "rotation": 4
    },
    {
      "x": -1,
      "y": 110,
      "z": 8,
      "name": "Rock_Crystal_Red_Block",
      "rotation": 4
    },
    {
      "x": -1,
      "y": 111,
      "z": 8,
      "name": "Rock_Crystal_Red_Block",
      "rotation": 6
    },
    {
      "x": -1,
      "y": 98,
      "z": 9,
      "name": "Rock_Crystal_Red_Block",
      "rotation": 6
    },
    {
      "x": -1,
      "y": 99,
      "z": 9,
      "name": "Rock_Crystal_Red_Block",
      "rotation": 4
    },
    {
      "x": -1,
      "y": 111,
      "z": 9,
      "name": "Rock_Crystal_Red_Block",
      "rotation": 4
    },
    {
      "x": -1,
      "y": 112,
      "z": 9,
      "name": "Rock_Crystal_Red_Block",
      "rotation": 6
    },
    {
      "x": -1,
      "y": 97,
      "z": 10,
      "name": "Rock_Crystal_Red_Block",
      "rotation": 6
    },
    {
      "x": -1,
      "y": 98,
      "z": 10,
      "name": "Rock_Crystal_Red_Block",
      "rotation": 4
    },
    {
      "x": -1,
      "y": 112,
      "z": 10,
      "name": "Rock_Crystal_Red_Block",
      "rotation": 4
    },
    {
      "x": -1,
      "y": 113,
      "z": 10,
      "name": "Rock_Crystal_Red_Block",
      "rotation": 6
    },
    {
      "x": -1,
      "y": 97,
      "z": 11,
      "name": "Rock_Crystal_Red_Block",
      "rotation": 4
    },
    {
      "x": -1,
      "y": 113,
      "z": 11,
      "name": "Rock_Crystal_Red_Block",
      "rotation": 4
    },
    {
      "x": 0,
      "y": 96,
      "z": -9,
      "name": "Plant_Coral_Block_Red",
      "rotation": 6
    },
    {
      "x": 0,
      "y": 97,
      "z": -9,
      "name": "Plant_Coral_Block_Red",
      "rotation": 6
    },
    {
      "x": 0,
      "y": 113,
      "z": -9,
      "name": "Plant_Coral_Block_Red",
      "rotation": 6
    },
    {
      "x": 0,
      "y": 114,
      "z": -9,
      "name": "Plant_Coral_Block_Red",
      "rotation": 6
    },
    {
      "x": 0,
      "y": 96,
      "z": -8,
      "name": "Plant_Coral_Block_Red",
      "rotation": 6
    },
    {
      "x": 0,
      "y": 97,
      "z": -8,
      "name": "Plant_Coral_Block_Red",
      "rotation": 6
    },
    {
      "x": 0,
      "y": 98,
      "z": -8,
      "name": "Plant_Coral_Block_Red",
      "rotation": 6
    },
    {
      "x": 0,
      "y": 112,
      "z": -8,
      "name": "Plant_Coral_Block_Red",
      "rotation": 6
    },
    {
      "x": 0,
      "y": 113,
      "z": -8,
      "name": "Plant_Coral_Block_Red",
      "rotation": 6
    },
    {
      "x": 0,
      "y": 114,
      "z": -8,
      "name": "Plant_Coral_Block_Red",
      "rotation": 6
    },
    {
      "x": 0,
      "y": 97,
      "z": -7,
      "name": "Plant_Coral_Block_Red",
      "rotation": 6
    },
    {
      "x": 0,
      "y": 98,
      "z": -7,
      "name": "Plant_Coral_Block_Red",
      "rotation": 6
    },
    {
      "x": 0,
      "y": 99,
      "z": -7,
      "name": "Plant_Coral_Block_Red",
      "rotation": 6
    },
    {
      "x": 0,
      "y": 111,
      "z": -7,
      "name": "Plant_Coral_Block_Red",
      "rotation": 6
    },
    {
      "x": 0,
      "y": 112,
      "z": -7,
      "name": "Plant_Coral_Block_Red",
      "rotation": 6
    },
    {
      "x": 0,
      "y": 113,
      "z": -7,
      "name": "Plant_Coral_Block_Red",
      "rotation": 6
    },
    {
      "x": 0,
      "y": 98,
      "z": -6,
      "name": "Plant_Coral_Block_Red",
      "rotation": 6
    },
    {
      "x": 0,
      "y": 99,
      "z": -6,
      "name": "Plant_Coral_Block_Red",
      "rotation": 6
    },
    {
      "x": 0,
      "y": 100,
      "z": -6,
      "name": "Plant_Coral_Block_Red",
      "rotation": 6
    },
    {
      "x": 0,
      "y": 110,
      "z": -6,
      "name": "Plant_Coral_Block_Red",
      "rotation": 6
    },
    {
      "x": 0,
      "y": 111,
      "z": -6,
      "name": "Plant_Coral_Block_Red",
      "rotation": 6
    },
    {
      "x": 0,
      "y": 112,
      "z": -6,
      "name": "Plant_Coral_Block_Red",
      "rotation": 6
    },
    {
      "x": 0,
      "y": 99,
      "z": -5,
      "name": "Plant_Coral_Block_Red",
      "rotation": 6
    },
    {
      "x": 0,
      "y": 100,
      "z": -5,
      "name": "Plant_Coral_Block_Red",
      "rotation": 6
    },
    {
      "x": 0,
      "y": 101,
      "z": -5,
      "name": "Plant_Coral_Block_Red",
      "rotation": 6
    },
    {
      "x": 0,
      "y": 109,
      "z": -5,
      "name": "Plant_Coral_Block_Red",
      "rotation": 6
    },
    {
      "x": 0,
      "y": 110,
      "z": -5,
      "name": "Plant_Coral_Block_Red",
      "rotation": 6
    },
    {
      "x": 0,
      "y": 111,
      "z": -5,
      "name": "Plant_Coral_Block_Red",
      "rotation": 6
    },
    {
      "x": 0,
      "y": 100,
      "z": -4,
      "name": "Plant_Coral_Block_Red",
      "rotation": 6
    },
    {
      "x": 0,
      "y": 101,
      "z": -4,
      "name": "Plant_Coral_Block_Red",
      "rotation": 6
    },
    {
      "x": 0,
      "y": 102,
      "z": -4,
      "name": "Plant_Coral_Block_Red",
      "rotation": 6
    },
    {
      "x": 0,
      "y": 108,
      "z": -4,
      "name": "Plant_Coral_Block_Red",
      "rotation": 6
    },
    {
      "x": 0,
      "y": 109,
      "z": -4,
      "name": "Plant_Coral_Block_Red",
      "rotation": 6
    },
    {
      "x": 0,
      "y": 110,
      "z": -4,
      "name": "Plant_Coral_Block_Red",
      "rotation": 6
    },
    {
      "x": 0,
      "y": 101,
      "z": -3,
      "name": "Plant_Coral_Block_Red",
      "rotation": 6
    },
    {
      "x": 0,
      "y": 102,
      "z": -3,
      "name": "Plant_Coral_Block_Red",
      "rotation": 6
    },
    {
      "x": 0,
      "y": 103,
      "z": -3,
      "name": "Plant_Coral_Block_Red",
      "rotation": 6
    },
    {
      "x": 0,
      "y": 107,
      "z": -3,
      "name": "Plant_Coral_Block_Red",
      "rotation": 6
    },
    {
      "x": 0,
      "y": 108,
      "z": -3,
      "name": "Plant_Coral_Block_Red",
      "rotation": 6
    },
    {
      "x": 0,
      "y": 109,
      "z": -3,
      "name": "Plant_Coral_Block_Red",
      "rotation": 6
    },
    {
      "x": 0,
      "y": 102,
      "z": -2,
      "name": "Plant_Coral_Block_Red",
      "rotation": 6
    },
    {
      "x": 0,
      "y": 103,
      "z": -2,
      "name": "Plant_Coral_Block_Red",
      "rotation": 6
    },
    {
      "x": 0,
      "y": 104,
      "z": -2,
      "name": "Plant_Coral_Block_Red",
      "rotation": 6
    },
    {
      "x": 0,
      "y": 106,
      "z": -2,
      "name": "Plant_Coral_Block_Red",
      "rotation": 6
    },
    {
      "x": 0,
      "y": 107,
      "z": -2,
      "name": "Plant_Coral_Block_Red",
      "rotation": 6
    },
    {
      "x": 0,
      "y": 108,
      "z": -2,
      "name": "Plant_Coral_Block_Red",
      "rotation": 6
    },
    {
      "x": 0,
      "y": 103,
      "z": -1,
      "name": "Plant_Coral_Block_Red",
      "rotation": 6
    },
    {
      "x": 0,
      "y": 104,
      "z": -1,
      "name": "Plant_Coral_Block_Red",
      "rotation": 6
    },
    {
      "x": 0,
      "y": 105,
      "z": -1,
      "name": "Plant_Coral_Block_Red",
      "rotation": 6
    },
    {
      "x": 0,
      "y": 106,
      "z": -1,
      "name": "Plant_Coral_Block_Red",
      "rotation": 6
    },
    {
      "x": 0,
      "y": 107,
      "z": -1,
      "name": "Plant_Coral_Block_Red",
      "rotation": 6
    },
    {
      "x": 0,
      "y": 0,
      "z": 0,
      "name": "Plant_Coral_Block_Red",
      "rotation": 6
    },
    {
      "x": 0,
      "y": 1,
      "z": 0,
      "name": "Plant_Coral_Block_Red",
      "rotation": 6
    },
    {
      "x": 0,
      "y": 2,
      "z": 0,
      "name": "Plant_Coral_Block_Red",
      "rotation": 6
    },
    {
      "x": 0,
      "y": 3,
      "z": 0,
      "name": "Plant_Coral_Block_Red",
      "rotation": 6
    },
    {
      "x": 0,
      "y": 4,
      "z": 0,
      "name": "Plant_Coral_Block_Red",
      "rotation": 6
    },
    {
      "x": 0,
      "y": 5,
      "z": 0,
      "name": "Plant_Coral_Block_Red",
      "rotation": 6
    },
    {
      "x": 0,
      "y": 6,
      "z": 0,
      "name": "Plant_Coral_Block_Red",
      "rotation": 6
    },
    {
      "x": 0,
      "y": 7,
      "z": 0,
      "name": "Plant_Coral_Block_Red",
      "rotation": 6
    },
    {
      "x": 0,
      "y": 8,
      "z": 0,
      "name": "Plant_Coral_Block_Red",
      "rotation": 6
    },
    {
      "x": 0,
      "y": 9,
      "z": 0,
      "name": "Plant_Coral_Block_Red",
      "rotation": 6
    },
    {
      "x": 0,
      "y": 10,
      "z": 0,
      "name": "Plant_Coral_Block_Red",
      "rotation": 6
    },
    {
      "x": 0,
      "y": 11,
      "z": 0,
      "name": "Plant_Coral_Block_Red",
      "rotation": 6
    },
    {
      "x": 0,
      "y": 12,
      "z": 0,
      "name": "Plant_Coral_Block_Red",
      "rotation": 6
    },
    {
      "x": 0,
      "y": 13,
      "z": 0,
      "name": "Plant_Coral_Block_Red",
      "rotation": 6
    },
    {
      "x": 0,
      "y": 14,
      "z": 0,
      "name": "Plant_Coral_Block_Red",
      "rotation": 6
    },
    {
      "x": 0,
      "y": 15,
      "z": 0,
      "name": "Plant_Coral_Block_Red",
      "rotation": 6
    },
    {
      "x": 0,
      "y": 16,
      "z": 0,
      "name": "Plant_Coral_Block_Red",
      "rotation": 6
    },
    {
      "x": 0,
      "y": 17,
      "z": 0,
      "name": "Plant_Coral_Block_Red",
      "rotation": 6
    },
    {
      "x": 0,
      "y": 18,
      "z": 0,
      "name": "Plant_Coral_Block_Red",
      "rotation": 6
    },
    {
      "x": 0,
      "y": 19,
      "z": 0,
      "name": "Plant_Coral_Block_Red",
      "rotation": 6
    },
    {
      "x": 0,
      "y": 20,
      "z": 0,
      "name": "Plant_Coral_Block_Red",
      "rotation": 6
    },
    {
      "x": 0,
      "y": 21,
      "z": 0,
      "name": "Plant_Coral_Block_Red",
      "rotation": 6
    },
    {
      "x": 0,
      "y": 22,
      "z": 0,
      "name": "Plant_Coral_Block_Red",
      "rotation": 6
    },
    {
      "x": 0,
      "y": 23,
      "z": 0,
      "name": "Plant_Coral_Block_Red",
      "rotation": 6
    },
    {
      "x": 0,
      "y": 24,
      "z": 0,
      "name": "Plant_Coral_Block_Red",
      "rotation": 6
    },
    {
      "x": 0,
      "y": 25,
      "z": 0,
      "name": "Plant_Coral_Block_Red",
      "rotation": 6
    },
    {
      "x": 0,
      "y": 26,
      "z": 0,
      "name": "Plant_Coral_Block_Red",
      "rotation": 6
    },
    {
      "x": 0,
      "y": 27,
      "z": 0,
      "name": "Plant_Coral_Block_Red",
      "rotation": 6
    },
    {
      "x": 0,
      "y": 28,
      "z": 0,
      "name": "Plant_Coral_Block_Red",
      "rotation": 6
    },
    {
      "x": 0,
      "y": 29,
      "z": 0,
      "name": "Plant_Coral_Block_Red",
      "rotation": 6
    },
    {
      "x": 0,
      "y": 30,
      "z": 0,
      "name": "Plant_Coral_Block_Red",
      "rotation": 6
    },
    {
      "x": 0,
      "y": 31,
      "z": 0,
      "name": "Plant_Coral_Block_Red",
      "rotation": 6
    },
    {
      "x": 0,
      "y": 32,
      "z": 0,
      "name": "Plant_Coral_Block_Red",
      "rotation": 6
    },
    {
      "x": 0,
      "y": 33,
      "z": 0,
      "name": "Plant_Coral_Block_Red",
      "rotation": 6
    },
    {
      "x": 0,
      "y": 34,
      "z": 0,
      "name": "Plant_Coral_Block_Red",
      "rotation": 6
    },
    {
      "x": 0,
      "y": 35,
      "z": 0,
      "name": "Plant_Coral_Block_Red",
      "rotation": 6
    },
    {
      "x": 0,
      "y": 36,
      "z": 0,
      "name": "Plant_Coral_Block_Red",
      "rotation": 6
    },
    {
      "x": 0,
      "y": 37,
      "z": 0,
      "name": "Plant_Coral_Block_Red",
      "rotation": 6
    },
    {
      "x": 0,
      "y": 38,
      "z": 0,
      "name": "Plant_Coral_Block_Red",
      "rotation": 6
    },
    {
      "x": 0,
      "y": 39,
      "z": 0,
      "name": "Plant_Coral_Block_Red",
      "rotation": 6
    },
    {
      "x": 0,
      "y": 40,
      "z": 0,
      "name": "Plant_Coral_Block_Red",
      "rotation": 6
    },
    {
      "x": 0,
      "y": 41,
      "z": 0,
      "name": "Plant_Coral_Block_Red",
      "rotation": 6
    },
    {
      "x": 0,
      "y": 42,
      "z": 0,
      "name": "Plant_Coral_Block_Red",
      "rotation": 6
    },
    {
      "x": 0,
      "y": 43,
      "z": 0,
      "name": "Plant_Coral_Block_Red",
      "rotation": 6
    },
    {
      "x": 0,
      "y": 44,
      "z": 0,
      "name": "Plant_Coral_Block_Red",
      "rotation": 6
    },
    {
      "x": 0,
      "y": 45,
      "z": 0,
      "name": "Plant_Coral_Block_Red",
      "rotation": 6
    },
    {
      "x": 0,
      "y": 46,
      "z": 0,
      "name": "Plant_Coral_Block_Red",
      "rotation": 6
    },
    {
      "x": 0,
      "y": 47,
      "z": 0,
      "name": "Plant_Coral_Block_Red",
      "rotation": 6
    },
    {
      "x": 0,
      "y": 48,
      "z": 0,
      "name": "Plant_Coral_Block_Red",
      "rotation": 6
    },
    {
      "x": 0,
      "y": 49,
      "z": 0,
      "name": "Plant_Coral_Block_Red",
      "rotation": 6
    },
    {
      "x": 0,
      "y": 50,
      "z": 0,
      "name": "Plant_Coral_Block_Red",
      "rotation": 6
    },
    {
      "x": 0,
      "y": 51,
      "z": 0,
      "name": "Plant_Coral_Block_Red",
      "rotation": 6
    },
    {
      "x": 0,
      "y": 52,
      "z": 0,
      "name": "Plant_Coral_Block_Red",
      "rotation": 6
    },
    {
      "x": 0,
      "y": 53,
      "z": 0,
      "name": "Plant_Coral_Block_Red",
      "rotation": 6
    },
    {
      "x": 0,
      "y": 54,
      "z": 0,
      "name": "Plant_Coral_Block_Red",
      "rotation": 6
    },
    {
      "x": 0,
      "y": 55,
      "z": 0,
      "name": "Plant_Coral_Block_Red",
      "rotation": 6
    },
    {
      "x": 0,
      "y": 56,
      "z": 0,
      "name": "Plant_Coral_Block_Red",
      "rotation": 6
    },
    {
      "x": 0,
      "y": 57,
      "z": 0,
      "name": "Plant_Coral_Block_Red",
      "rotation": 6
    },
    {
      "x": 0,
      "y": 58,
      "z": 0,
      "name": "Plant_Coral_Block_Red",
      "rotation": 6
    },
    {
      "x": 0,
      "y": 59,
      "z": 0,
      "name": "Plant_Coral_Block_Red",
      "rotation": 6
    },
    {
      "x": 0,
      "y": 60,
      "z": 0,
      "name": "Plant_Coral_Block_Red",
      "rotation": 6
    },
    {
      "x": 0,
      "y": 61,
      "z": 0,
      "name": "Plant_Coral_Block_Red",
      "rotation": 6
    },
    {
      "x": 0,
      "y": 62,
      "z": 0,
      "name": "Plant_Coral_Block_Red",
      "rotation": 6
    },
    {
      "x": 0,
      "y": 63,
      "z": 0,
      "name": "Plant_Coral_Block_Red",
      "rotation": 6
    },
    {
      "x": 0,
      "y": 64,
      "z": 0,
      "name": "Plant_Coral_Block_Red",
      "rotation": 6
    },
    {
      "x": 0,
      "y": 65,
      "z": 0,
      "name": "Plant_Coral_Block_Red",
      "rotation": 6
    },
    {
      "x": 0,
      "y": 66,
      "z": 0,
      "name": "Plant_Coral_Block_Red",
      "rotation": 6
    },
    {
      "x": 0,
      "y": 67,
      "z": 0,
      "name": "Plant_Coral_Block_Red",
      "rotation": 6
    },
    {
      "x": 0,
      "y": 68,
      "z": 0,
      "name": "Plant_Coral_Block_Red",
      "rotation": 6
    },
    {
      "x": 0,
      "y": 69,
      "z": 0,
      "name": "Plant_Coral_Block_Red",
      "rotation": 6
    },
    {
      "x": 0,
      "y": 70,
      "z": 0,
      "name": "Plant_Coral_Block_Red",
      "rotation": 6
    },
    {
      "x": 0,
      "y": 71,
      "z": 0,
      "name": "Plant_Coral_Block_Red",
      "rotation": 6
    },
    {
      "x": 0,
      "y": 72,
      "z": 0,
      "name": "Plant_Coral_Block_Red",
      "rotation": 6
    },
    {
      "x": 0,
      "y": 73,
      "z": 0,
      "name": "Plant_Coral_Block_Red",
      "rotation": 6
    },
    {
      "x": 0,
      "y": 74,
      "z": 0,
      "name": "Plant_Coral_Block_Red",
      "rotation": 6
    },
    {
      "x": 0,
      "y": 75,
      "z": 0,
      "name": "Plant_Coral_Block_Red",
      "rotation": 6
    },
    {
      "x": 0,
      "y": 76,
      "z": 0,
      "name": "Plant_Coral_Block_Red",
      "rotation": 6
    },
    {
      "x": 0,
      "y": 77,
      "z": 0,
      "name": "Plant_Coral_Block_Red",
      "rotation": 6
    },
    {
      "x": 0,
      "y": 78,
      "z": 0,
      "name": "Plant_Coral_Block_Red",
      "rotation": 6
    },
    {
      "x": 0,
      "y": 79,
      "z": 0,
      "name": "Plant_Coral_Block_Red",
      "rotation": 6
    },
    {
      "x": 0,
      "y": 80,
      "z": 0,
      "name": "Plant_Coral_Block_Red",
      "rotation": 6
    },
    {
      "x": 0,
      "y": 81,
      "z": 0,
      "name": "Plant_Coral_Block_Red",
      "rotation": 6
    },
    {
      "x": 0,
      "y": 82,
      "z": 0,
      "name": "Plant_Coral_Block_Red",
      "rotation": 6
    },
    {
      "x": 0,
      "y": 83,
      "z": 0,
      "name": "Plant_Coral_Block_Red",
      "rotation": 6
    },
    {
      "x": 0,
      "y": 84,
      "z": 0,
      "name": "Plant_Coral_Block_Red",
      "rotation": 6
    },
    {
      "x": 0,
      "y": 85,
      "z": 0,
      "name": "Plant_Coral_Block_Red",
      "rotation": 6
    },
    {
      "x": 0,
      "y": 86,
      "z": 0,
      "name": "Plant_Coral_Block_Red",
      "rotation": 6
    },
    {
      "x": 0,
      "y": 87,
      "z": 0,
      "name": "Plant_Coral_Block_Red",
      "rotation": 6
    },
    {
      "x": 0,
      "y": 88,
      "z": 0,
      "name": "Plant_Coral_Block_Red",
      "rotation": 6
    },
    {
      "x": 0,
      "y": 89,
      "z": 0,
      "name": "Plant_Coral_Block_Red",
      "rotation": 6
    },
    {
      "x": 0,
      "y": 90,
      "z": 0,
      "name": "Plant_Coral_Block_Red",
      "rotation": 6
    },
    {
      "x": 0,
      "y": 91,
      "z": 0,
      "name": "Plant_Coral_Block_Red",
      "rotation": 6
    },
    {
      "x": 0,
      "y": 92,
      "z": 0,
      "name": "Plant_Coral_Block_Red",
      "rotation": 6
    },
    {
      "x": 0,
      "y": 93,
      "z": 0,
      "name": "Plant_Coral_Block_Red",
      "rotation": 6
    },
    {
      "x": 0,
      "y": 94,
      "z": 0,
      "name": "Plant_Coral_Block_Red",
      "rotation": 6
    },
    {
      "x": 0,
      "y": 95,
      "z": 0,
      "name": "Plant_Coral_Block_Red",
      "rotation": 6
    },
    {
      "x": 0,
      "y": 96,
      "z": 0,
      "name": "Plant_Coral_Block_Red",
      "rotation": 6
    },
    {
      "x": 0,
      "y": 97,
      "z": 0,
      "name": "Plant_Coral_Block_Red",
      "rotation": 6
    },
    {
      "x": 0,
      "y": 98,
      "z": 0,
      "name": "Plant_Coral_Block_Red",
      "rotation": 6
    },
    {
      "x": 0,
      "y": 99,
      "z": 0,
      "name": "Plant_Coral_Block_Red",
      "rotation": 6
    },
    {
      "x": 0,
      "y": 100,
      "z": 0,
      "name": "Plant_Coral_Block_Red",
      "rotation": 6
    },
    {
      "x": 0,
      "y": 101,
      "z": 0,
      "name": "Plant_Coral_Block_Red",
      "rotation": 6
    },
    {
      "x": 0,
      "y": 102,
      "z": 0,
      "name": "Plant_Coral_Block_Red",
      "rotation": 6
    },
    {
      "x": 0,
      "y": 103,
      "z": 0,
      "name": "Plant_Coral_Block_Red",
      "rotation": 6
    },
    {
      "x": 0,
      "y": 104,
      "z": 0,
      "name": "Plant_Coral_Block_Red",
      "rotation": 6
    },
    {
      "x": 0,
      "y": 105,
      "z": 0,
      "name": "Plant_Coral_Block_Red",
      "rotation": 6
    },
    {
      "x": 0,
      "y": 106,
      "z": 0,
      "name": "Plant_Coral_Block_Red",
      "rotation": 6
    },
    {
      "x": 0,
      "y": 107,
      "z": 0,
      "name": "Plant_Coral_Block_Red",
      "rotation": 6
    },
    {
      "x": 0,
      "y": 108,
      "z": 0,
      "name": "Plant_Coral_Block_Red",
      "rotation": 6
    },
    {
      "x": 0,
      "y": 109,
      "z": 0,
      "name": "Plant_Coral_Block_Red",
      "rotation": 6
    },
    {
      "x": 0,
      "y": 110,
      "z": 0,
      "name": "Plant_Coral_Block_Red",
      "rotation": 6
    },
    {
      "x": 0,
      "y": 111,
      "z": 0,
      "name": "Plant_Coral_Block_Red",
      "rotation": 6
    },
    {
      "x": 0,
      "y": 112,
      "z": 0,
      "name": "Plant_Coral_Block_Red",
      "rotation": 6
    },
    {
      "x": 0,
      "y": 113,
      "z": 0,
      "name": "Plant_Coral_Block_Red",
      "rotation": 6
    },
    {
      "x": 0,
      "y": 114,
      "z": 0,
      "name": "Plant_Coral_Block_Red",
      "rotation": 6
    },
    {
      "x": 0,
      "y": 115,
      "z": 0,
      "name": "Plant_Coral_Block_Red",
      "rotation": 6
    },
    {
      "x": 0,
      "y": 116,
      "z": 0,
      "name": "Plant_Coral_Block_Red"
    },
    {
      "x": 0,
      "y": 117,
      "z": 0,
      "name": "Plant_Coral_Block_Red"
    },
    {
      "x": 0,
      "y": 0,
      "z": 1,
      "name": "Plant_Coral_Block_Red",
      "rotation": 6
    },
    {
      "x": 0,
      "y": 1,
      "z": 1,
      "name": "Plant_Coral_Block_Red",
      "rotation": 6
    },
    {
      "x": 0,
      "y": 2,
      "z": 1,
      "name": "Plant_Coral_Block_Red",
      "rotation": 6
    },
    {
      "x": 0,
      "y": 3,
      "z": 1,
      "name": "Plant_Coral_Block_Red",
      "rotation": 6
    },
    {
      "x": 0,
      "y": 4,
      "z": 1,
      "name": "Plant_Coral_Block_Red",
      "rotation": 6
    },
    {
      "x": 0,
      "y": 5,
      "z": 1,
      "name": "Plant_Coral_Block_Red",
      "rotation": 6
    },
    {
      "x": 0,
      "y": 6,
      "z": 1,
      "name": "Plant_Coral_Block_Red",
      "rotation": 6
    },
    {
      "x": 0,
      "y": 7,
      "z": 1,
      "name": "Plant_Coral_Block_Red",
      "rotation": 6
    },
    {
      "x": 0,
      "y": 8,
      "z": 1,
      "name": "Plant_Coral_Block_Red",
      "rotation": 6
    },
    {
      "x": 0,
      "y": 9,
      "z": 1,
      "name": "Plant_Coral_Block_Red",
      "rotation": 6
    },
    {
      "x": 0,
      "y": 10,
      "z": 1,
      "name": "Plant_Coral_Block_Red",
      "rotation": 6
    },
    {
      "x": 0,
      "y": 11,
      "z": 1,
      "name": "Plant_Coral_Block_Red",
      "rotation": 6
    },
    {
      "x": 0,
      "y": 12,
      "z": 1,
      "name": "Plant_Coral_Block_Red",
      "rotation": 6
    },
    {
      "x": 0,
      "y": 13,
      "z": 1,
      "name": "Plant_Coral_Block_Red",
      "rotation": 6
    },
    {
      "x": 0,
      "y": 14,
      "z": 1,
      "name": "Plant_Coral_Block_Red",
      "rotation": 6
    },
    {
      "x": 0,
      "y": 15,
      "z": 1,
      "name": "Plant_Coral_Block_Red",
      "rotation": 6
    },
    {
      "x": 0,
      "y": 16,
      "z": 1,
      "name": "Plant_Coral_Block_Red",
      "rotation": 6
    },
    {
      "x": 0,
      "y": 17,
      "z": 1,
      "name": "Plant_Coral_Block_Red",
      "rotation": 6
    },
    {
      "x": 0,
      "y": 18,
      "z": 1,
      "name": "Plant_Coral_Block_Red",
      "rotation": 6
    },
    {
      "x": 0,
      "y": 19,
      "z": 1,
      "name": "Plant_Coral_Block_Red",
      "rotation": 6
    },
    {
      "x": 0,
      "y": 20,
      "z": 1,
      "name": "Plant_Coral_Block_Red",
      "rotation": 6
    },
    {
      "x": 0,
      "y": 21,
      "z": 1,
      "name": "Plant_Coral_Block_Red",
      "rotation": 6
    },
    {
      "x": 0,
      "y": 22,
      "z": 1,
      "name": "Plant_Coral_Block_Red",
      "rotation": 6
    },
    {
      "x": 0,
      "y": 23,
      "z": 1,
      "name": "Plant_Coral_Block_Red",
      "rotation": 6
    },
    {
      "x": 0,
      "y": 24,
      "z": 1,
      "name": "Plant_Coral_Block_Red",
      "rotation": 6
    },
    {
      "x": 0,
      "y": 25,
      "z": 1,
      "name": "Plant_Coral_Block_Red",
      "rotation": 6
    },
    {
      "x": 0,
      "y": 26,
      "z": 1,
      "name": "Plant_Coral_Block_Red",
      "rotation": 6
    },
    {
      "x": 0,
      "y": 27,
      "z": 1,
      "name": "Plant_Coral_Block_Red",
      "rotation": 6
    },
    {
      "x": 0,
      "y": 28,
      "z": 1,
      "name": "Plant_Coral_Block_Red",
      "rotation": 6
    },
    {
      "x": 0,
      "y": 29,
      "z": 1,
      "name": "Plant_Coral_Block_Red",
      "rotation": 6
    },
    {
      "x": 0,
      "y": 30,
      "z": 1,
      "name": "Plant_Coral_Block_Red",
      "rotation": 6
    },
    {
      "x": 0,
      "y": 31,
      "z": 1,
      "name": "Plant_Coral_Block_Red",
      "rotation": 6
    },
    {
      "x": 0,
      "y": 32,
      "z": 1,
      "name": "Plant_Coral_Block_Red",
      "rotation": 6
    },
    {
      "x": 0,
      "y": 33,
      "z": 1,
      "name": "Plant_Coral_Block_Red",
      "rotation": 6
    },
    {
      "x": 0,
      "y": 34,
      "z": 1,
      "name": "Plant_Coral_Block_Red",
      "rotation": 6
    },
    {
      "x": 0,
      "y": 35,
      "z": 1,
      "name": "Plant_Coral_Block_Red",
      "rotation": 6
    },
    {
      "x": 0,
      "y": 36,
      "z": 1,
      "name": "Plant_Coral_Block_Red",
      "rotation": 6
    },
    {
      "x": 0,
      "y": 37,
      "z": 1,
      "name": "Plant_Coral_Block_Red",
      "rotation": 6
    },
    {
      "x": 0,
      "y": 38,
      "z": 1,
      "name": "Plant_Coral_Block_Red",
      "rotation": 6
    },
    {
      "x": 0,
      "y": 39,
      "z": 1,
      "name": "Plant_Coral_Block_Red",
      "rotation": 6
    },
    {
      "x": 0,
      "y": 40,
      "z": 1,
      "name": "Plant_Coral_Block_Red",
      "rotation": 6
    },
    {
      "x": 0,
      "y": 41,
      "z": 1,
      "name": "Plant_Coral_Block_Red",
      "rotation": 6
    },
    {
      "x": 0,
      "y": 42,
      "z": 1,
      "name": "Plant_Coral_Block_Red",
      "rotation": 6
    },
    {
      "x": 0,
      "y": 43,
      "z": 1,
      "name": "Plant_Coral_Block_Red",
      "rotation": 6
    },
    {
      "x": 0,
      "y": 44,
      "z": 1,
      "name": "Plant_Coral_Block_Red",
      "rotation": 6
    },
    {
      "x": 0,
      "y": 45,
      "z": 1,
      "name": "Plant_Coral_Block_Red",
      "rotation": 6
    },
    {
      "x": 0,
      "y": 46,
      "z": 1,
      "name": "Plant_Coral_Block_Red",
      "rotation": 6
    },
    {
      "x": 0,
      "y": 47,
      "z": 1,
      "name": "Plant_Coral_Block_Red",
      "rotation": 6
    },
    {
      "x": 0,
      "y": 48,
      "z": 1,
      "name": "Plant_Coral_Block_Red",
      "rotation": 6
    },
    {
      "x": 0,
      "y": 49,
      "z": 1,
      "name": "Plant_Coral_Block_Red",
      "rotation": 6
    },
    {
      "x": 0,
      "y": 50,
      "z": 1,
      "name": "Plant_Coral_Block_Red",
      "rotation": 6
    },
    {
      "x": 0,
      "y": 51,
      "z": 1,
      "name": "Plant_Coral_Block_Red",
      "rotation": 6
    },
    {
      "x": 0,
      "y": 52,
      "z": 1,
      "name": "Plant_Coral_Block_Red",
      "rotation": 6
    },
    {
      "x": 0,
      "y": 53,
      "z": 1,
      "name": "Plant_Coral_Block_Red",
      "rotation": 6
    },
    {
      "x": 0,
      "y": 54,
      "z": 1,
      "name": "Plant_Coral_Block_Red",
      "rotation": 6
    },
    {
      "x": 0,
      "y": 55,
      "z": 1,
      "name": "Plant_Coral_Block_Red",
      "rotation": 6
    },
    {
      "x": 0,
      "y": 56,
      "z": 1,
      "name": "Plant_Coral_Block_Red",
      "rotation": 6
    },
    {
      "x": 0,
      "y": 57,
      "z": 1,
      "name": "Plant_Coral_Block_Red",
      "rotation": 6
    },
    {
      "x": 0,
      "y": 58,
      "z": 1,
      "name": "Plant_Coral_Block_Red",
      "rotation": 6
    },
    {
      "x": 0,
      "y": 59,
      "z": 1,
      "name": "Plant_Coral_Block_Red",
      "rotation": 6
    },
    {
      "x": 0,
      "y": 60,
      "z": 1,
      "name": "Plant_Coral_Block_Red",
      "rotation": 6
    },
    {
      "x": 0,
      "y": 61,
      "z": 1,
      "name": "Plant_Coral_Block_Red",
      "rotation": 6
    },
    {
      "x": 0,
      "y": 62,
      "z": 1,
      "name": "Plant_Coral_Block_Red",
      "rotation": 6
    },
    {
      "x": 0,
      "y": 63,
      "z": 1,
      "name": "Plant_Coral_Block_Red",
      "rotation": 6
    },
    {
      "x": 0,
      "y": 64,
      "z": 1,
      "name": "Plant_Coral_Block_Red",
      "rotation": 6
    },
    {
      "x": 0,
      "y": 65,
      "z": 1,
      "name": "Plant_Coral_Block_Red",
      "rotation": 6
    },
    {
      "x": 0,
      "y": 66,
      "z": 1,
      "name": "Plant_Coral_Block_Red",
      "rotation": 6
    },
    {
      "x": 0,
      "y": 67,
      "z": 1,
      "name": "Plant_Coral_Block_Red",
      "rotation": 6
    },
    {
      "x": 0,
      "y": 68,
      "z": 1,
      "name": "Plant_Coral_Block_Red",
      "rotation": 6
    },
    {
      "x": 0,
      "y": 69,
      "z": 1,
      "name": "Plant_Coral_Block_Red",
      "rotation": 6
    },
    {
      "x": 0,
      "y": 70,
      "z": 1,
      "name": "Plant_Coral_Block_Red",
      "rotation": 6
    },
    {
      "x": 0,
      "y": 71,
      "z": 1,
      "name": "Plant_Coral_Block_Red",
      "rotation": 6
    },
    {
      "x": 0,
      "y": 72,
      "z": 1,
      "name": "Plant_Coral_Block_Red",
      "rotation": 6
    },
    {
      "x": 0,
      "y": 73,
      "z": 1,
      "name": "Plant_Coral_Block_Red",
      "rotation": 6
    },
    {
      "x": 0,
      "y": 74,
      "z": 1,
      "name": "Plant_Coral_Block_Red",
      "rotation": 6
    },
    {
      "x": 0,
      "y": 75,
      "z": 1,
      "name": "Plant_Coral_Block_Red",
      "rotation": 6
    },
    {
      "x": 0,
      "y": 76,
      "z": 1,
      "name": "Plant_Coral_Block_Red",
      "rotation": 6
    },
    {
      "x": 0,
      "y": 77,
      "z": 1,
      "name": "Plant_Coral_Block_Red",
      "rotation": 6
    },
    {
      "x": 0,
      "y": 78,
      "z": 1,
      "name": "Plant_Coral_Block_Red",
      "rotation": 6
    },
    {
      "x": 0,
      "y": 79,
      "z": 1,
      "name": "Plant_Coral_Block_Red",
      "rotation": 6
    },
    {
      "x": 0,
      "y": 80,
      "z": 1,
      "name": "Plant_Coral_Block_Red",
      "rotation": 6
    },
    {
      "x": 0,
      "y": 81,
      "z": 1,
      "name": "Plant_Coral_Block_Red",
      "rotation": 6
    },
    {
      "x": 0,
      "y": 82,
      "z": 1,
      "name": "Plant_Coral_Block_Red",
      "rotation": 6
    },
    {
      "x": 0,
      "y": 83,
      "z": 1,
      "name": "Plant_Coral_Block_Red",
      "rotation": 6
    },
    {
      "x": 0,
      "y": 84,
      "z": 1,
      "name": "Plant_Coral_Block_Red",
      "rotation": 6
    },
    {
      "x": 0,
      "y": 85,
      "z": 1,
      "name": "Plant_Coral_Block_Red",
      "rotation": 6
    },
    {
      "x": 0,
      "y": 86,
      "z": 1,
      "name": "Plant_Coral_Block_Red",
      "rotation": 6
    },
    {
      "x": 0,
      "y": 87,
      "z": 1,
      "name": "Plant_Coral_Block_Red",
      "rotation": 6
    },
    {
      "x": 0,
      "y": 88,
      "z": 1,
      "name": "Plant_Coral_Block_Red",
      "rotation": 6
    },
    {
      "x": 0,
      "y": 89,
      "z": 1,
      "name": "Plant_Coral_Block_Red",
      "rotation": 6
    },
    {
      "x": 0,
      "y": 90,
      "z": 1,
      "name": "Plant_Coral_Block_Red",
      "rotation": 6
    },
    {
      "x": 0,
      "y": 91,
      "z": 1,
      "name": "Plant_Coral_Block_Red",
      "rotation": 6
    },
    {
      "x": 0,
      "y": 92,
      "z": 1,
      "name": "Plant_Coral_Block_Red",
      "rotation": 6
    },
    {
      "x": 0,
      "y": 93,
      "z": 1,
      "name": "Plant_Coral_Block_Red",
      "rotation": 6
    },
    {
      "x": 0,
      "y": 94,
      "z": 1,
      "name": "Plant_Coral_Block_Red",
      "rotation": 6
    },
    {
      "x": 0,
      "y": 95,
      "z": 1,
      "name": "Plant_Coral_Block_Red",
      "rotation": 6
    },
    {
      "x": 0,
      "y": 96,
      "z": 1,
      "name": "Plant_Coral_Block_Red",
      "rotation": 6
    },
    {
      "x": 0,
      "y": 97,
      "z": 1,
      "name": "Plant_Coral_Block_Red",
      "rotation": 6
    },
    {
      "x": 0,
      "y": 98,
      "z": 1,
      "name": "Plant_Coral_Block_Red",
      "rotation": 6
    },
    {
      "x": 0,
      "y": 99,
      "z": 1,
      "name": "Plant_Coral_Block_Red",
      "rotation": 6
    },
    {
      "x": 0,
      "y": 100,
      "z": 1,
      "name": "Plant_Coral_Block_Red",
      "rotation": 6
    },
    {
      "x": 0,
      "y": 101,
      "z": 1,
      "name": "Plant_Coral_Block_Red",
      "rotation": 6
    },
    {
      "x": 0,
      "y": 102,
      "z": 1,
      "name": "Plant_Coral_Block_Red",
      "rotation": 6
    },
    {
      "x": 0,
      "y": 103,
      "z": 1,
      "name": "Plant_Coral_Block_Red",
      "rotation": 6
    },
    {
      "x": 0,
      "y": 104,
      "z": 1,
      "name": "Soil_Dirt"
    },
    {
      "x": 0,
      "y": 105,
      "z": 1,
      "name": "Spawn_Labyrinth_Red_Circle_Blood"
    },
    {
      "x": 0,
      "y": 106,
      "z": 1,
      "name": "Plant_Coral_Block_Red",
      "rotation": 6
    },
    {
      "x": 0,
      "y": 107,
      "z": 1,
      "name": "Plant_Coral_Block_Red",
      "rotation": 6
    },
    {
      "x": 0,
      "y": 108,
      "z": 1,
      "name": "Plant_Coral_Block_Red",
      "rotation": 6
    },
    {
      "x": 0,
      "y": 109,
      "z": 1,
      "name": "Plant_Coral_Block_Red",
      "rotation": 6
    },
    {
      "x": 0,
      "y": 110,
      "z": 1,
      "name": "Plant_Coral_Block_Red",
      "rotation": 6
    },
    {
      "x": 0,
      "y": 111,
      "z": 1,
      "name": "Plant_Coral_Block_Red",
      "rotation": 6
    },
    {
      "x": 0,
      "y": 112,
      "z": 1,
      "name": "Plant_Coral_Block_Red",
      "rotation": 6
    },
    {
      "x": 0,
      "y": 113,
      "z": 1,
      "name": "Plant_Coral_Block_Red",
      "rotation": 6
    },
    {
      "x": 0,
      "y": 114,
      "z": 1,
      "name": "Plant_Coral_Block_Red",
      "rotation": 6
    },
    {
      "x": 0,
      "y": 115,
      "z": 1,
      "name": "Plant_Coral_Block_Red",
      "rotation": 6
    },
    {
      "x": 0,
      "y": 116,
      "z": 1,
      "name": "Plant_Coral_Block_Red",
      "rotation": 6
    },
    {
      "x": 0,
      "y": 117,
      "z": 1,
      "name": "Plant_Coral_Block_Red"
    },
    {
      "x": 0,
      "y": 118,
      "z": 1,
      "name": "Plant_Coral_Block_Red"
    },
    {
      "x": 0,
      "y": 0,
      "z": 2,
      "name": "Plant_Coral_Block_Red",
      "rotation": 6
    },
    {
      "x": 0,
      "y": 1,
      "z": 2,
      "name": "Plant_Coral_Block_Red",
      "rotation": 6
    },
    {
      "x": 0,
      "y": 2,
      "z": 2,
      "name": "Plant_Coral_Block_Red",
      "rotation": 6
    },
    {
      "x": 0,
      "y": 3,
      "z": 2,
      "name": "Plant_Coral_Block_Red",
      "rotation": 6
    },
    {
      "x": 0,
      "y": 4,
      "z": 2,
      "name": "Plant_Coral_Block_Red",
      "rotation": 6
    },
    {
      "x": 0,
      "y": 5,
      "z": 2,
      "name": "Plant_Coral_Block_Red",
      "rotation": 6
    },
    {
      "x": 0,
      "y": 6,
      "z": 2,
      "name": "Plant_Coral_Block_Red",
      "rotation": 6
    },
    {
      "x": 0,
      "y": 7,
      "z": 2,
      "name": "Plant_Coral_Block_Red",
      "rotation": 6
    },
    {
      "x": 0,
      "y": 8,
      "z": 2,
      "name": "Plant_Coral_Block_Red",
      "rotation": 6
    },
    {
      "x": 0,
      "y": 9,
      "z": 2,
      "name": "Plant_Coral_Block_Red",
      "rotation": 6
    },
    {
      "x": 0,
      "y": 10,
      "z": 2,
      "name": "Plant_Coral_Block_Red",
      "rotation": 6
    },
    {
      "x": 0,
      "y": 11,
      "z": 2,
      "name": "Plant_Coral_Block_Red",
      "rotation": 6
    },
    {
      "x": 0,
      "y": 12,
      "z": 2,
      "name": "Plant_Coral_Block_Red",
      "rotation": 6
    },
    {
      "x": 0,
      "y": 13,
      "z": 2,
      "name": "Plant_Coral_Block_Red",
      "rotation": 6
    },
    {
      "x": 0,
      "y": 14,
      "z": 2,
      "name": "Plant_Coral_Block_Red",
      "rotation": 6
    },
    {
      "x": 0,
      "y": 15,
      "z": 2,
      "name": "Plant_Coral_Block_Red",
      "rotation": 6
    },
    {
      "x": 0,
      "y": 16,
      "z": 2,
      "name": "Plant_Coral_Block_Red",
      "rotation": 6
    },
    {
      "x": 0,
      "y": 17,
      "z": 2,
      "name": "Plant_Coral_Block_Red",
      "rotation": 6
    },
    {
      "x": 0,
      "y": 18,
      "z": 2,
      "name": "Plant_Coral_Block_Red",
      "rotation": 6
    },
    {
      "x": 0,
      "y": 19,
      "z": 2,
      "name": "Plant_Coral_Block_Red",
      "rotation": 6
    },
    {
      "x": 0,
      "y": 20,
      "z": 2,
      "name": "Plant_Coral_Block_Red",
      "rotation": 6
    },
    {
      "x": 0,
      "y": 21,
      "z": 2,
      "name": "Plant_Coral_Block_Red",
      "rotation": 6
    },
    {
      "x": 0,
      "y": 22,
      "z": 2,
      "name": "Plant_Coral_Block_Red",
      "rotation": 6
    },
    {
      "x": 0,
      "y": 23,
      "z": 2,
      "name": "Plant_Coral_Block_Red",
      "rotation": 6
    },
    {
      "x": 0,
      "y": 24,
      "z": 2,
      "name": "Plant_Coral_Block_Red",
      "rotation": 6
    },
    {
      "x": 0,
      "y": 25,
      "z": 2,
      "name": "Plant_Coral_Block_Red",
      "rotation": 6
    },
    {
      "x": 0,
      "y": 26,
      "z": 2,
      "name": "Plant_Coral_Block_Red",
      "rotation": 6
    },
    {
      "x": 0,
      "y": 27,
      "z": 2,
      "name": "Plant_Coral_Block_Red",
      "rotation": 6
    },
    {
      "x": 0,
      "y": 28,
      "z": 2,
      "name": "Plant_Coral_Block_Red",
      "rotation": 6
    },
    {
      "x": 0,
      "y": 29,
      "z": 2,
      "name": "Plant_Coral_Block_Red",
      "rotation": 6
    },
    {
      "x": 0,
      "y": 30,
      "z": 2,
      "name": "Plant_Coral_Block_Red",
      "rotation": 6
    },
    {
      "x": 0,
      "y": 31,
      "z": 2,
      "name": "Plant_Coral_Block_Red",
      "rotation": 6
    },
    {
      "x": 0,
      "y": 32,
      "z": 2,
      "name": "Plant_Coral_Block_Red",
      "rotation": 6
    },
    {
      "x": 0,
      "y": 33,
      "z": 2,
      "name": "Plant_Coral_Block_Red",
      "rotation": 6
    },
    {
      "x": 0,
      "y": 34,
      "z": 2,
      "name": "Plant_Coral_Block_Red",
      "rotation": 6
    },
    {
      "x": 0,
      "y": 35,
      "z": 2,
      "name": "Plant_Coral_Block_Red",
      "rotation": 6
    },
    {
      "x": 0,
      "y": 36,
      "z": 2,
      "name": "Plant_Coral_Block_Red",
      "rotation": 6
    },
    {
      "x": 0,
      "y": 37,
      "z": 2,
      "name": "Plant_Coral_Block_Red",
      "rotation": 6
    },
    {
      "x": 0,
      "y": 38,
      "z": 2,
      "name": "Plant_Coral_Block_Red",
      "rotation": 6
    },
    {
      "x": 0,
      "y": 39,
      "z": 2,
      "name": "Plant_Coral_Block_Red",
      "rotation": 6
    },
    {
      "x": 0,
      "y": 40,
      "z": 2,
      "name": "Plant_Coral_Block_Red",
      "rotation": 6
    },
    {
      "x": 0,
      "y": 41,
      "z": 2,
      "name": "Plant_Coral_Block_Red",
      "rotation": 6
    },
    {
      "x": 0,
      "y": 42,
      "z": 2,
      "name": "Plant_Coral_Block_Red",
      "rotation": 6
    },
    {
      "x": 0,
      "y": 43,
      "z": 2,
      "name": "Plant_Coral_Block_Red",
      "rotation": 6
    },
    {
      "x": 0,
      "y": 44,
      "z": 2,
      "name": "Plant_Coral_Block_Red",
      "rotation": 6
    },
    {
      "x": 0,
      "y": 45,
      "z": 2,
      "name": "Plant_Coral_Block_Red",
      "rotation": 6
    },
    {
      "x": 0,
      "y": 46,
      "z": 2,
      "name": "Plant_Coral_Block_Red",
      "rotation": 6
    },
    {
      "x": 0,
      "y": 47,
      "z": 2,
      "name": "Plant_Coral_Block_Red",
      "rotation": 6
    },
    {
      "x": 0,
      "y": 48,
      "z": 2,
      "name": "Plant_Coral_Block_Red",
      "rotation": 6
    },
    {
      "x": 0,
      "y": 49,
      "z": 2,
      "name": "Plant_Coral_Block_Red",
      "rotation": 6
    },
    {
      "x": 0,
      "y": 50,
      "z": 2,
      "name": "Plant_Coral_Block_Red",
      "rotation": 6
    },
    {
      "x": 0,
      "y": 51,
      "z": 2,
      "name": "Plant_Coral_Block_Red",
      "rotation": 6
    },
    {
      "x": 0,
      "y": 52,
      "z": 2,
      "name": "Plant_Coral_Block_Red",
      "rotation": 6
    },
    {
      "x": 0,
      "y": 53,
      "z": 2,
      "name": "Plant_Coral_Block_Red",
      "rotation": 6
    },
    {
      "x": 0,
      "y": 54,
      "z": 2,
      "name": "Plant_Coral_Block_Red",
      "rotation": 6
    },
    {
      "x": 0,
      "y": 55,
      "z": 2,
      "name": "Plant_Coral_Block_Red",
      "rotation": 6
    },
    {
      "x": 0,
      "y": 56,
      "z": 2,
      "name": "Plant_Coral_Block_Red",
      "rotation": 6
    },
    {
      "x": 0,
      "y": 57,
      "z": 2,
      "name": "Plant_Coral_Block_Red",
      "rotation": 6
    },
    {
      "x": 0,
      "y": 58,
      "z": 2,
      "name": "Plant_Coral_Block_Red",
      "rotation": 6
    },
    {
      "x": 0,
      "y": 59,
      "z": 2,
      "name": "Plant_Coral_Block_Red",
      "rotation": 6
    },
    {
      "x": 0,
      "y": 60,
      "z": 2,
      "name": "Plant_Coral_Block_Red",
      "rotation": 6
    },
    {
      "x": 0,
      "y": 61,
      "z": 2,
      "name": "Plant_Coral_Block_Red",
      "rotation": 6
    },
    {
      "x": 0,
      "y": 62,
      "z": 2,
      "name": "Plant_Coral_Block_Red",
      "rotation": 6
    },
    {
      "x": 0,
      "y": 63,
      "z": 2,
      "name": "Plant_Coral_Block_Red",
      "rotation": 6
    },
    {
      "x": 0,
      "y": 64,
      "z": 2,
      "name": "Plant_Coral_Block_Red",
      "rotation": 6
    },
    {
      "x": 0,
      "y": 65,
      "z": 2,
      "name": "Plant_Coral_Block_Red",
      "rotation": 6
    },
    {
      "x": 0,
      "y": 66,
      "z": 2,
      "name": "Plant_Coral_Block_Red",
      "rotation": 6
    },
    {
      "x": 0,
      "y": 67,
      "z": 2,
      "name": "Plant_Coral_Block_Red",
      "rotation": 6
    },
    {
      "x": 0,
      "y": 68,
      "z": 2,
      "name": "Plant_Coral_Block_Red",
      "rotation": 6
    },
    {
      "x": 0,
      "y": 69,
      "z": 2,
      "name": "Plant_Coral_Block_Red",
      "rotation": 6
    },
    {
      "x": 0,
      "y": 70,
      "z": 2,
      "name": "Plant_Coral_Block_Red",
      "rotation": 6
    },
    {
      "x": 0,
      "y": 71,
      "z": 2,
      "name": "Plant_Coral_Block_Red",
      "rotation": 6
    },
    {
      "x": 0,
      "y": 72,
      "z": 2,
      "name": "Plant_Coral_Block_Red",
      "rotation": 6
    },
    {
      "x": 0,
      "y": 73,
      "z": 2,
      "name": "Plant_Coral_Block_Red",
      "rotation": 6
    },
    {
      "x": 0,
      "y": 74,
      "z": 2,
      "name": "Plant_Coral_Block_Red",
      "rotation": 6
    },
    {
      "x": 0,
      "y": 75,
      "z": 2,
      "name": "Plant_Coral_Block_Red",
      "rotation": 6
    },
    {
      "x": 0,
      "y": 76,
      "z": 2,
      "name": "Plant_Coral_Block_Red",
      "rotation": 6
    },
    {
      "x": 0,
      "y": 77,
      "z": 2,
      "name": "Plant_Coral_Block_Red",
      "rotation": 6
    },
    {
      "x": 0,
      "y": 78,
      "z": 2,
      "name": "Plant_Coral_Block_Red",
      "rotation": 6
    },
    {
      "x": 0,
      "y": 79,
      "z": 2,
      "name": "Plant_Coral_Block_Red",
      "rotation": 6
    },
    {
      "x": 0,
      "y": 80,
      "z": 2,
      "name": "Plant_Coral_Block_Red",
      "rotation": 6
    },
    {
      "x": 0,
      "y": 81,
      "z": 2,
      "name": "Plant_Coral_Block_Red",
      "rotation": 6
    },
    {
      "x": 0,
      "y": 82,
      "z": 2,
      "name": "Plant_Coral_Block_Red",
      "rotation": 6
    },
    {
      "x": 0,
      "y": 83,
      "z": 2,
      "name": "Plant_Coral_Block_Red",
      "rotation": 6
    },
    {
      "x": 0,
      "y": 84,
      "z": 2,
      "name": "Plant_Coral_Block_Red",
      "rotation": 6
    },
    {
      "x": 0,
      "y": 85,
      "z": 2,
      "name": "Plant_Coral_Block_Red",
      "rotation": 6
    },
    {
      "x": 0,
      "y": 86,
      "z": 2,
      "name": "Plant_Coral_Block_Red",
      "rotation": 6
    },
    {
      "x": 0,
      "y": 87,
      "z": 2,
      "name": "Plant_Coral_Block_Red",
      "rotation": 6
    },
    {
      "x": 0,
      "y": 88,
      "z": 2,
      "name": "Plant_Coral_Block_Red",
      "rotation": 6
    },
    {
      "x": 0,
      "y": 89,
      "z": 2,
      "name": "Plant_Coral_Block_Red",
      "rotation": 6
    },
    {
      "x": 0,
      "y": 90,
      "z": 2,
      "name": "Plant_Coral_Block_Red",
      "rotation": 6
    },
    {
      "x": 0,
      "y": 91,
      "z": 2,
      "name": "Plant_Coral_Block_Red",
      "rotation": 6
    },
    {
      "x": 0,
      "y": 92,
      "z": 2,
      "name": "Plant_Coral_Block_Red",
      "rotation": 6
    },
    {
      "x": 0,
      "y": 93,
      "z": 2,
      "name": "Plant_Coral_Block_Red",
      "rotation": 6
    },
    {
      "x": 0,
      "y": 94,
      "z": 2,
      "name": "Plant_Coral_Block_Red",
      "rotation": 6
    },
    {
      "x": 0,
      "y": 95,
      "z": 2,
      "name": "Plant_Coral_Block_Red",
      "rotation": 6
    },
    {
      "x": 0,
      "y": 96,
      "z": 2,
      "name": "Plant_Coral_Block_Red",
      "rotation": 6
    },
    {
      "x": 0,
      "y": 97,
      "z": 2,
      "name": "Plant_Coral_Block_Red",
      "rotation": 6
    },
    {
      "x": 0,
      "y": 98,
      "z": 2,
      "name": "Plant_Coral_Block_Red",
      "rotation": 6
    },
    {
      "x": 0,
      "y": 99,
      "z": 2,
      "name": "Plant_Coral_Block_Red",
      "rotation": 6
    },
    {
      "x": 0,
      "y": 100,
      "z": 2,
      "name": "Plant_Coral_Block_Red",
      "rotation": 6
    },
    {
      "x": 0,
      "y": 101,
      "z": 2,
      "name": "Plant_Coral_Block_Red",
      "rotation": 6
    },
    {
      "x": 0,
      "y": 102,
      "z": 2,
      "name": "Plant_Coral_Block_Red",
      "rotation": 6
    },
    {
      "x": 0,
      "y": 103,
      "z": 2,
      "name": "Plant_Coral_Block_Red",
      "rotation": 6
    },
    {
      "x": 0,
      "y": 104,
      "z": 2,
      "name": "Plant_Coral_Block_Red",
      "rotation": 6
    },
    {
      "x": 0,
      "y": 105,
      "z": 2,
      "name": "Plant_Coral_Block_Red",
      "rotation": 6
    },
    {
      "x": 0,
      "y": 106,
      "z": 2,
      "name": "Plant_Coral_Block_Red",
      "rotation": 6
    },
    {
      "x": 0,
      "y": 107,
      "z": 2,
      "name": "Plant_Coral_Block_Red",
      "rotation": 6
    },
    {
      "x": 0,
      "y": 108,
      "z": 2,
      "name": "Plant_Coral_Block_Red",
      "rotation": 6
    },
    {
      "x": 0,
      "y": 109,
      "z": 2,
      "name": "Plant_Coral_Block_Red",
      "rotation": 6
    },
    {
      "x": 0,
      "y": 110,
      "z": 2,
      "name": "Plant_Coral_Block_Red",
      "rotation": 6
    },
    {
      "x": 0,
      "y": 111,
      "z": 2,
      "name": "Plant_Coral_Block_Red",
      "rotation": 6
    },
    {
      "x": 0,
      "y": 112,
      "z": 2,
      "name": "Plant_Coral_Block_Red",
      "rotation": 6
    },
    {
      "x": 0,
      "y": 113,
      "z": 2,
      "name": "Plant_Coral_Block_Red",
      "rotation": 6
    },
    {
      "x": 0,
      "y": 114,
      "z": 2,
      "name": "Plant_Coral_Block_Red",
      "rotation": 6
    },
    {
      "x": 0,
      "y": 115,
      "z": 2,
      "name": "Plant_Coral_Block_Red",
      "rotation": 6
    },
    {
      "x": 0,
      "y": 116,
      "z": 2,
      "name": "Plant_Coral_Block_Red"
    },
    {
      "x": 0,
      "y": 117,
      "z": 2,
      "name": "Plant_Coral_Block_Red"
    },
    {
      "x": 0,
      "y": 103,
      "z": 3,
      "name": "Plant_Coral_Block_Red",
      "rotation": 6
    },
    {
      "x": 0,
      "y": 104,
      "z": 3,
      "name": "Plant_Coral_Block_Red",
      "rotation": 6
    },
    {
      "x": 0,
      "y": 105,
      "z": 3,
      "name": "Plant_Coral_Block_Red",
      "rotation": 6
    },
    {
      "x": 0,
      "y": 106,
      "z": 3,
      "name": "Plant_Coral_Block_Red",
      "rotation": 6
    },
    {
      "x": 0,
      "y": 107,
      "z": 3,
      "name": "Plant_Coral_Block_Red",
      "rotation": 6
    },
    {
      "x": 0,
      "y": 102,
      "z": 4,
      "name": "Plant_Coral_Block_Red",
      "rotation": 6
    },
    {
      "x": 0,
      "y": 103,
      "z": 4,
      "name": "Plant_Coral_Block_Red",
      "rotation": 6
    },
    {
      "x": 0,
      "y": 104,
      "z": 4,
      "name": "Plant_Coral_Block_Red",
      "rotation": 6
    },
    {
      "x": 0,
      "y": 106,
      "z": 4,
      "name": "Plant_Coral_Block_Red",
      "rotation": 6
    },
    {
      "x": 0,
      "y": 107,
      "z": 4,
      "name": "Plant_Coral_Block_Red",
      "rotation": 6
    },
    {
      "x": 0,
      "y": 108,
      "z": 4,
      "name": "Plant_Coral_Block_Red",
      "rotation": 6
    },
    {
      "x": 0,
      "y": 101,
      "z": 5,
      "name": "Plant_Coral_Block_Red",
      "rotation": 6
    },
    {
      "x": 0,
      "y": 102,
      "z": 5,
      "name": "Plant_Coral_Block_Red",
      "rotation": 6
    },
    {
      "x": 0,
      "y": 103,
      "z": 5,
      "name": "Plant_Coral_Block_Red",
      "rotation": 6
    },
    {
      "x": 0,
      "y": 107,
      "z": 5,
      "name": "Plant_Coral_Block_Red",
      "rotation": 6
    },
    {
      "x": 0,
      "y": 108,
      "z": 5,
      "name": "Plant_Coral_Block_Red",
      "rotation": 6
    },
    {
      "x": 0,
      "y": 109,
      "z": 5,
      "name": "Plant_Coral_Block_Red",
      "rotation": 6
    },
    {
      "x": 0,
      "y": 100,
      "z": 6,
      "name": "Plant_Coral_Block_Red",
      "rotation": 6
    },
    {
      "x": 0,
      "y": 101,
      "z": 6,
      "name": "Plant_Coral_Block_Red",
      "rotation": 6
    },
    {
      "x": 0,
      "y": 102,
      "z": 6,
      "name": "Plant_Coral_Block_Red",
      "rotation": 6
    },
    {
      "x": 0,
      "y": 108,
      "z": 6,
      "name": "Plant_Coral_Block_Red",
      "rotation": 6
    },
    {
      "x": 0,
      "y": 109,
      "z": 6,
      "name": "Plant_Coral_Block_Red",
      "rotation": 6
    },
    {
      "x": 0,
      "y": 110,
      "z": 6,
      "name": "Plant_Coral_Block_Red",
      "rotation": 6
    },
    {
      "x": 0,
      "y": 99,
      "z": 7,
      "name": "Plant_Coral_Block_Red",
      "rotation": 6
    },
    {
      "x": 0,
      "y": 100,
      "z": 7,
      "name": "Plant_Coral_Block_Red",
      "rotation": 6
    },
    {
      "x": 0,
      "y": 101,
      "z": 7,
      "name": "Plant_Coral_Block_Red",
      "rotation": 6
    },
    {
      "x": 0,
      "y": 109,
      "z": 7,
      "name": "Plant_Coral_Block_Red",
      "rotation": 6
    },
    {
      "x": 0,
      "y": 110,
      "z": 7,
      "name": "Plant_Coral_Block_Red",
      "rotation": 6
    },
    {
      "x": 0,
      "y": 111,
      "z": 7,
      "name": "Plant_Coral_Block_Red",
      "rotation": 6
    },
    {
      "x": 0,
      "y": 98,
      "z": 8,
      "name": "Plant_Coral_Block_Red",
      "rotation": 6
    },
    {
      "x": 0,
      "y": 99,
      "z": 8,
      "name": "Plant_Coral_Block_Red",
      "rotation": 6
    },
    {
      "x": 0,
      "y": 100,
      "z": 8,
      "name": "Plant_Coral_Block_Red",
      "rotation": 6
    },
    {
      "x": 0,
      "y": 110,
      "z": 8,
      "name": "Plant_Coral_Block_Red",
      "rotation": 6
    },
    {
      "x": 0,
      "y": 111,
      "z": 8,
      "name": "Plant_Coral_Block_Red",
      "rotation": 6
    },
    {
      "x": 0,
      "y": 112,
      "z": 8,
      "name": "Plant_Coral_Block_Red",
      "rotation": 6
    },
    {
      "x": 0,
      "y": 97,
      "z": 9,
      "name": "Plant_Coral_Block_Red",
      "rotation": 6
    },
    {
      "x": 0,
      "y": 98,
      "z": 9,
      "name": "Plant_Coral_Block_Red",
      "rotation": 6
    },
    {
      "x": 0,
      "y": 99,
      "z": 9,
      "name": "Plant_Coral_Block_Red",
      "rotation": 6
    },
    {
      "x": 0,
      "y": 111,
      "z": 9,
      "name": "Plant_Coral_Block_Red",
      "rotation": 6
    },
    {
      "x": 0,
      "y": 112,
      "z": 9,
      "name": "Plant_Coral_Block_Red",
      "rotation": 6
    },
    {
      "x": 0,
      "y": 113,
      "z": 9,
      "name": "Plant_Coral_Block_Red",
      "rotation": 6
    },
    {
      "x": 0,
      "y": 96,
      "z": 10,
      "name": "Plant_Coral_Block_Red",
      "rotation": 6
    },
    {
      "x": 0,
      "y": 97,
      "z": 10,
      "name": "Plant_Coral_Block_Red",
      "rotation": 6
    },
    {
      "x": 0,
      "y": 98,
      "z": 10,
      "name": "Plant_Coral_Block_Red",
      "rotation": 6
    },
    {
      "x": 0,
      "y": 112,
      "z": 10,
      "name": "Plant_Coral_Block_Red",
      "rotation": 6
    },
    {
      "x": 0,
      "y": 113,
      "z": 10,
      "name": "Plant_Coral_Block_Red",
      "rotation": 6
    },
    {
      "x": 0,
      "y": 114,
      "z": 10,
      "name": "Plant_Coral_Block_Red",
      "rotation": 6
    },
    {
      "x": 0,
      "y": 96,
      "z": 11,
      "name": "Plant_Coral_Block_Red",
      "rotation": 6
    },
    {
      "x": 0,
      "y": 97,
      "z": 11,
      "name": "Plant_Coral_Block_Red",
      "rotation": 6
    },
    {
      "x": 0,
      "y": 113,
      "z": 11,
      "name": "Plant_Coral_Block_Red",
      "rotation": 6
    },
    {
      "x": 0,
      "y": 114,
      "z": 11,
      "name": "Plant_Coral_Block_Red",
      "rotation": 6
    },
    {
      "x": 1,
      "y": 97,
      "z": -9,
      "name": "Rock_Crystal_Red_Block",
      "rotation": 4
    },
    {
      "x": 1,
      "y": 113,
      "z": -9,
      "name": "Rock_Crystal_Red_Block",
      "rotation": 4
    },
    {
      "x": 1,
      "y": 97,
      "z": -8,
      "name": "Rock_Crystal_Red_Block",
      "rotation": 21
    },
    {
      "x": 1,
      "y": 98,
      "z": -8,
      "name": "Rock_Crystal_Red_Block",
      "rotation": 4
    },
    {
      "x": 1,
      "y": 112,
      "z": -8,
      "name": "Rock_Crystal_Red_Block",
      "rotation": 4
    },
    {
      "x": 1,
      "y": 113,
      "z": -8,
      "name": "Rock_Crystal_Red_Block",
      "rotation": 21
    },
    {
      "x": 1,
      "y": 98,
      "z": -7,
      "name": "Rock_Crystal_Red_Block",
      "rotation": 21
    },
    {
      "x": 1,
      "y": 99,
      "z": -7,
      "name": "Rock_Crystal_Red_Block",
      "rotation": 4
    },
    {
      "x": 1,
      "y": 111,
      "z": -7,
      "name": "Rock_Crystal_Red_Block",
      "rotation": 4
    },
    {
      "x": 1,
      "y": 112,
      "z": -7,
      "name": "Rock_Crystal_Red_Block",
      "rotation": 21
    },
    {
      "x": 1,
      "y": 99,
      "z": -6,
      "name": "Rock_Crystal_Red_Block",
      "rotation": 21
    },
    {
      "x": 1,
      "y": 100,
      "z": -6,
      "name": "Rock_Crystal_Red_Block",
      "rotation": 4
    },
    {
      "x": 1,
      "y": 110,
      "z": -6,
      "name": "Rock_Crystal_Red_Block",
      "rotation": 4
    },
    {
      "x": 1,
      "y": 111,
      "z": -6,
      "name": "Rock_Crystal_Red_Block",
      "rotation": 21
    },
    {
      "x": 1,
      "y": 100,
      "z": -5,
      "name": "Rock_Crystal_Red_Block",
      "rotation": 21
    },
    {
      "x": 1,
      "y": 101,
      "z": -5,
      "name": "Rock_Crystal_Red_Block",
      "rotation": 4
    },
    {
      "x": 1,
      "y": 109,
      "z": -5,
      "name": "Rock_Crystal_Red_Block",
      "rotation": 4
    },
    {
      "x": 1,
      "y": 110,
      "z": -5,
      "name": "Rock_Crystal_Red_Block",
      "rotation": 21
    },
    {
      "x": 1,
      "y": 101,
      "z": -4,
      "name": "Rock_Crystal_Red_Block",
      "rotation": 21
    },
    {
      "x": 1,
      "y": 102,
      "z": -4,
      "name": "Rock_Crystal_Red_Block",
      "rotation": 4
    },
    {
      "x": 1,
      "y": 108,
      "z": -4,
      "name": "Rock_Crystal_Red_Block",
      "rotation": 4
    },
    {
      "x": 1,
      "y": 109,
      "z": -4,
      "name": "Rock_Crystal_Red_Block",
      "rotation": 21
    },
    {
      "x": 1,
      "y": 102,
      "z": -3,
      "name": "Rock_Crystal_Red_Block",
      "rotation": 21
    },
    {
      "x": 1,
      "y": 103,
      "z": -3,
      "name": "Rock_Crystal_Red_Block",
      "rotation": 4
    },
    {
      "x": 1,
      "y": 107,
      "z": -3,
      "name": "Rock_Crystal_Red_Block",
      "rotation": 4
    },
    {
      "x": 1,
      "y": 108,
      "z": -3,
      "name": "Rock_Crystal_Red_Block",
      "rotation": 21
    },
    {
      "x": 1,
      "y": 103,
      "z": -2,
      "name": "Rock_Crystal_Red_Block",
      "rotation": 21
    },
    {
      "x": 1,
      "y": 104,
      "z": -2,
      "name": "Rock_Crystal_Red_Block",
      "rotation": 4
    },
    {
      "x": 1,
      "y": 106,
      "z": -2,
      "name": "Rock_Crystal_Red_Block",
      "rotation": 4
    },
    {
      "x": 1,
      "y": 107,
      "z": -2,
      "name": "Rock_Crystal_Red_Block",
      "rotation": 21
    },
    {
      "x": 1,
      "y": 104,
      "z": -1,
      "name": "Rock_Crystal_Red_Block",
      "rotation": 21
    },
    {
      "x": 1,
      "y": 105,
      "z": -1,
      "name": "Rock_Crystal_Red_Block",
      "rotation": 4
    },
    {
      "x": 1,
      "y": 106,
      "z": -1,
      "name": "Rock_Crystal_Red_Block",
      "rotation": 21
    },
    {
      "x": 1,
      "y": 105,
      "z": 0,
      "name": "Rock_Crystal_Red_Block",
      "rotation": 21
    },
    {
      "x": 1,
      "y": 0,
      "z": 1,
      "name": "Rock_Crystal_Red_Block",
      "rotation": 21
    },
    {
      "x": 1,
      "y": 1,
      "z": 1,
      "name": "Rock_Crystal_Red_Block",
      "rotation": 21
    },
    {
      "x": 1,
      "y": 2,
      "z": 1,
      "name": "Rock_Crystal_Red_Block",
      "rotation": 21
    },
    {
      "x": 1,
      "y": 3,
      "z": 1,
      "name": "Rock_Crystal_Red_Block",
      "rotation": 21
    },
    {
      "x": 1,
      "y": 4,
      "z": 1,
      "name": "Rock_Crystal_Red_Block",
      "rotation": 21
    },
    {
      "x": 1,
      "y": 5,
      "z": 1,
      "name": "Rock_Crystal_Red_Block",
      "rotation": 21
    },
    {
      "x": 1,
      "y": 6,
      "z": 1,
      "name": "Rock_Crystal_Red_Block",
      "rotation": 21
    },
    {
      "x": 1,
      "y": 7,
      "z": 1,
      "name": "Rock_Crystal_Red_Block",
      "rotation": 21
    },
    {
      "x": 1,
      "y": 8,
      "z": 1,
      "name": "Rock_Crystal_Red_Block",
      "rotation": 21
    },
    {
      "x": 1,
      "y": 9,
      "z": 1,
      "name": "Rock_Crystal_Red_Block",
      "rotation": 21
    },
    {
      "x": 1,
      "y": 10,
      "z": 1,
      "name": "Rock_Crystal_Red_Block",
      "rotation": 21
    },
    {
      "x": 1,
      "y": 11,
      "z": 1,
      "name": "Rock_Crystal_Red_Block",
      "rotation": 21
    },
    {
      "x": 1,
      "y": 12,
      "z": 1,
      "name": "Rock_Crystal_Red_Block",
      "rotation": 21
    },
    {
      "x": 1,
      "y": 13,
      "z": 1,
      "name": "Rock_Crystal_Red_Block",
      "rotation": 21
    },
    {
      "x": 1,
      "y": 14,
      "z": 1,
      "name": "Rock_Crystal_Red_Block",
      "rotation": 21
    },
    {
      "x": 1,
      "y": 15,
      "z": 1,
      "name": "Rock_Crystal_Red_Block",
      "rotation": 21
    },
    {
      "x": 1,
      "y": 16,
      "z": 1,
      "name": "Rock_Crystal_Red_Block",
      "rotation": 21
    },
    {
      "x": 1,
      "y": 17,
      "z": 1,
      "name": "Rock_Crystal_Red_Block",
      "rotation": 21
    },
    {
      "x": 1,
      "y": 18,
      "z": 1,
      "name": "Rock_Crystal_Red_Block",
      "rotation": 21
    },
    {
      "x": 1,
      "y": 19,
      "z": 1,
      "name": "Rock_Crystal_Red_Block",
      "rotation": 21
    },
    {
      "x": 1,
      "y": 20,
      "z": 1,
      "name": "Rock_Crystal_Red_Block",
      "rotation": 21
    },
    {
      "x": 1,
      "y": 21,
      "z": 1,
      "name": "Rock_Crystal_Red_Block",
      "rotation": 21
    },
    {
      "x": 1,
      "y": 22,
      "z": 1,
      "name": "Rock_Crystal_Red_Block",
      "rotation": 21
    },
    {
      "x": 1,
      "y": 23,
      "z": 1,
      "name": "Rock_Crystal_Red_Block",
      "rotation": 21
    },
    {
      "x": 1,
      "y": 24,
      "z": 1,
      "name": "Rock_Crystal_Red_Block",
      "rotation": 21
    },
    {
      "x": 1,
      "y": 25,
      "z": 1,
      "name": "Rock_Crystal_Red_Block",
      "rotation": 21
    },
    {
      "x": 1,
      "y": 26,
      "z": 1,
      "name": "Rock_Crystal_Red_Block",
      "rotation": 21
    },
    {
      "x": 1,
      "y": 27,
      "z": 1,
      "name": "Rock_Crystal_Red_Block",
      "rotation": 21
    },
    {
      "x": 1,
      "y": 28,
      "z": 1,
      "name": "Rock_Crystal_Red_Block",
      "rotation": 21
    },
    {
      "x": 1,
      "y": 29,
      "z": 1,
      "name": "Rock_Crystal_Red_Block",
      "rotation": 21
    },
    {
      "x": 1,
      "y": 30,
      "z": 1,
      "name": "Rock_Crystal_Red_Block",
      "rotation": 21
    },
    {
      "x": 1,
      "y": 31,
      "z": 1,
      "name": "Rock_Crystal_Red_Block",
      "rotation": 21
    },
    {
      "x": 1,
      "y": 32,
      "z": 1,
      "name": "Rock_Crystal_Red_Block",
      "rotation": 21
    },
    {
      "x": 1,
      "y": 33,
      "z": 1,
      "name": "Rock_Crystal_Red_Block",
      "rotation": 21
    },
    {
      "x": 1,
      "y": 34,
      "z": 1,
      "name": "Rock_Crystal_Red_Block",
      "rotation": 21
    },
    {
      "x": 1,
      "y": 35,
      "z": 1,
      "name": "Rock_Crystal_Red_Block",
      "rotation": 21
    },
    {
      "x": 1,
      "y": 36,
      "z": 1,
      "name": "Rock_Crystal_Red_Block",
      "rotation": 21
    },
    {
      "x": 1,
      "y": 37,
      "z": 1,
      "name": "Rock_Crystal_Red_Block",
      "rotation": 21
    },
    {
      "x": 1,
      "y": 38,
      "z": 1,
      "name": "Rock_Crystal_Red_Block",
      "rotation": 21
    },
    {
      "x": 1,
      "y": 39,
      "z": 1,
      "name": "Rock_Crystal_Red_Block",
      "rotation": 21
    },
    {
      "x": 1,
      "y": 40,
      "z": 1,
      "name": "Rock_Crystal_Red_Block",
      "rotation": 21
    },
    {
      "x": 1,
      "y": 41,
      "z": 1,
      "name": "Rock_Crystal_Red_Block",
      "rotation": 21
    },
    {
      "x": 1,
      "y": 42,
      "z": 1,
      "name": "Rock_Crystal_Red_Block",
      "rotation": 21
    },
    {
      "x": 1,
      "y": 43,
      "z": 1,
      "name": "Rock_Crystal_Red_Block",
      "rotation": 21
    },
    {
      "x": 1,
      "y": 44,
      "z": 1,
      "name": "Rock_Crystal_Red_Block",
      "rotation": 21
    },
    {
      "x": 1,
      "y": 45,
      "z": 1,
      "name": "Rock_Crystal_Red_Block",
      "rotation": 21
    },
    {
      "x": 1,
      "y": 46,
      "z": 1,
      "name": "Rock_Crystal_Red_Block",
      "rotation": 21
    },
    {
      "x": 1,
      "y": 47,
      "z": 1,
      "name": "Rock_Crystal_Red_Block",
      "rotation": 21
    },
    {
      "x": 1,
      "y": 48,
      "z": 1,
      "name": "Rock_Crystal_Red_Block",
      "rotation": 21
    },
    {
      "x": 1,
      "y": 49,
      "z": 1,
      "name": "Rock_Crystal_Red_Block",
      "rotation": 21
    },
    {
      "x": 1,
      "y": 50,
      "z": 1,
      "name": "Rock_Crystal_Red_Block",
      "rotation": 21
    },
    {
      "x": 1,
      "y": 51,
      "z": 1,
      "name": "Rock_Crystal_Red_Block",
      "rotation": 21
    },
    {
      "x": 1,
      "y": 52,
      "z": 1,
      "name": "Rock_Crystal_Red_Block",
      "rotation": 21
    },
    {
      "x": 1,
      "y": 53,
      "z": 1,
      "name": "Rock_Crystal_Red_Block",
      "rotation": 21
    },
    {
      "x": 1,
      "y": 54,
      "z": 1,
      "name": "Rock_Crystal_Red_Block",
      "rotation": 21
    },
    {
      "x": 1,
      "y": 55,
      "z": 1,
      "name": "Rock_Crystal_Red_Block",
      "rotation": 21
    },
    {
      "x": 1,
      "y": 56,
      "z": 1,
      "name": "Rock_Crystal_Red_Block",
      "rotation": 21
    },
    {
      "x": 1,
      "y": 57,
      "z": 1,
      "name": "Rock_Crystal_Red_Block",
      "rotation": 21
    },
    {
      "x": 1,
      "y": 58,
      "z": 1,
      "name": "Rock_Crystal_Red_Block",
      "rotation": 21
    },
    {
      "x": 1,
      "y": 59,
      "z": 1,
      "name": "Rock_Crystal_Red_Block",
      "rotation": 21
    },
    {
      "x": 1,
      "y": 60,
      "z": 1,
      "name": "Rock_Crystal_Red_Block",
      "rotation": 21
    },
    {
      "x": 1,
      "y": 61,
      "z": 1,
      "name": "Rock_Crystal_Red_Block",
      "rotation": 21
    },
    {
      "x": 1,
      "y": 62,
      "z": 1,
      "name": "Rock_Crystal_Red_Block",
      "rotation": 21
    },
    {
      "x": 1,
      "y": 63,
      "z": 1,
      "name": "Rock_Crystal_Red_Block",
      "rotation": 21
    },
    {
      "x": 1,
      "y": 64,
      "z": 1,
      "name": "Rock_Crystal_Red_Block",
      "rotation": 21
    },
    {
      "x": 1,
      "y": 65,
      "z": 1,
      "name": "Rock_Crystal_Red_Block",
      "rotation": 21
    },
    {
      "x": 1,
      "y": 66,
      "z": 1,
      "name": "Rock_Crystal_Red_Block",
      "rotation": 21
    },
    {
      "x": 1,
      "y": 67,
      "z": 1,
      "name": "Rock_Crystal_Red_Block",
      "rotation": 21
    },
    {
      "x": 1,
      "y": 68,
      "z": 1,
      "name": "Rock_Crystal_Red_Block",
      "rotation": 21
    },
    {
      "x": 1,
      "y": 69,
      "z": 1,
      "name": "Rock_Crystal_Red_Block",
      "rotation": 21
    },
    {
      "x": 1,
      "y": 70,
      "z": 1,
      "name": "Rock_Crystal_Red_Block",
      "rotation": 21
    },
    {
      "x": 1,
      "y": 71,
      "z": 1,
      "name": "Rock_Crystal_Red_Block",
      "rotation": 21
    },
    {
      "x": 1,
      "y": 72,
      "z": 1,
      "name": "Rock_Crystal_Red_Block",
      "rotation": 21
    },
    {
      "x": 1,
      "y": 73,
      "z": 1,
      "name": "Rock_Crystal_Red_Block",
      "rotation": 21
    },
    {
      "x": 1,
      "y": 74,
      "z": 1,
      "name": "Rock_Crystal_Red_Block",
      "rotation": 21
    },
    {
      "x": 1,
      "y": 75,
      "z": 1,
      "name": "Rock_Crystal_Red_Block",
      "rotation": 21
    },
    {
      "x": 1,
      "y": 76,
      "z": 1,
      "name": "Rock_Crystal_Red_Block",
      "rotation": 21
    },
    {
      "x": 1,
      "y": 77,
      "z": 1,
      "name": "Rock_Crystal_Red_Block",
      "rotation": 21
    },
    {
      "x": 1,
      "y": 78,
      "z": 1,
      "name": "Rock_Crystal_Red_Block",
      "rotation": 21
    },
    {
      "x": 1,
      "y": 79,
      "z": 1,
      "name": "Rock_Crystal_Red_Block",
      "rotation": 21
    },
    {
      "x": 1,
      "y": 80,
      "z": 1,
      "name": "Rock_Crystal_Red_Block",
      "rotation": 21
    },
    {
      "x": 1,
      "y": 81,
      "z": 1,
      "name": "Rock_Crystal_Red_Block",
      "rotation": 21
    },
    {
      "x": 1,
      "y": 82,
      "z": 1,
      "name": "Rock_Crystal_Red_Block",
      "rotation": 21
    },
    {
      "x": 1,
      "y": 83,
      "z": 1,
      "name": "Rock_Crystal_Red_Block",
      "rotation": 21
    },
    {
      "x": 1,
      "y": 84,
      "z": 1,
      "name": "Rock_Crystal_Red_Block",
      "rotation": 21
    },
    {
      "x": 1,
      "y": 85,
      "z": 1,
      "name": "Rock_Crystal_Red_Block",
      "rotation": 21
    },
    {
      "x": 1,
      "y": 86,
      "z": 1,
      "name": "Rock_Crystal_Red_Block",
      "rotation": 21
    },
    {
      "x": 1,
      "y": 87,
      "z": 1,
      "name": "Rock_Crystal_Red_Block",
      "rotation": 21
    },
    {
      "x": 1,
      "y": 88,
      "z": 1,
      "name": "Rock_Crystal_Red_Block",
      "rotation": 21
    },
    {
      "x": 1,
      "y": 89,
      "z": 1,
      "name": "Rock_Crystal_Red_Block",
      "rotation": 21
    },
    {
      "x": 1,
      "y": 90,
      "z": 1,
      "name": "Rock_Crystal_Red_Block",
      "rotation": 21
    },
    {
      "x": 1,
      "y": 91,
      "z": 1,
      "name": "Rock_Crystal_Red_Block",
      "rotation": 21
    },
    {
      "x": 1,
      "y": 92,
      "z": 1,
      "name": "Rock_Crystal_Red_Block",
      "rotation": 21
    },
    {
      "x": 1,
      "y": 93,
      "z": 1,
      "name": "Rock_Crystal_Red_Block",
      "rotation": 21
    },
    {
      "x": 1,
      "y": 94,
      "z": 1,
      "name": "Rock_Crystal_Red_Block",
      "rotation": 21
    },
    {
      "x": 1,
      "y": 95,
      "z": 1,
      "name": "Rock_Crystal_Red_Block",
      "rotation": 21
    },
    {
      "x": 1,
      "y": 96,
      "z": 1,
      "name": "Rock_Crystal_Red_Block",
      "rotation": 21
    },
    {
      "x": 1,
      "y": 97,
      "z": 1,
      "name": "Rock_Crystal_Red_Block",
      "rotation": 21
    },
    {
      "x": 1,
      "y": 98,
      "z": 1,
      "name": "Rock_Crystal_Red_Block",
      "rotation": 21
    },
    {
      "x": 1,
      "y": 99,
      "z": 1,
      "name": "Rock_Crystal_Red_Block",
      "rotation": 21
    },
    {
      "x": 1,
      "y": 100,
      "z": 1,
      "name": "Rock_Crystal_Red_Block",
      "rotation": 21
    },
    {
      "x": 1,
      "y": 101,
      "z": 1,
      "name": "Rock_Crystal_Red_Block",
      "rotation": 21
    },
    {
      "x": 1,
      "y": 102,
      "z": 1,
      "name": "Rock_Crystal_Red_Block",
      "rotation": 21
    },
    {
      "x": 1,
      "y": 103,
      "z": 1,
      "name": "Rock_Crystal_Red_Block",
      "rotation": 21
    },
    {
      "x": 1,
      "y": 104,
      "z": 1,
      "name": "Rock_Crystal_Red_Block",
      "rotation": 21
    },
    {
      "x": 1,
      "y": 105,
      "z": 1,
      "name": "Rock_Gem_Ruby",
      "rotation": 5
    },
    {
      "x": 1,
      "y": 106,
      "z": 1,
      "name": "Rock_Crystal_Red_Block",
      "rotation": 21
    },
    {
      "x": 1,
      "y": 107,
      "z": 1,
      "name": "Rock_Crystal_Red_Block",
      "rotation": 21
    },
    {
      "x": 1,
      "y": 108,
      "z": 1,
      "name": "Rock_Crystal_Red_Block",
      "rotation": 21
    },
    {
      "x": 1,
      "y": 109,
      "z": 1,
      "name": "Rock_Crystal_Red_Block",
      "rotation": 21
    },
    {
      "x": 1,
      "y": 110,
      "z": 1,
      "name": "Rock_Crystal_Red_Block",
      "rotation": 21
    },
    {
      "x": 1,
      "y": 111,
      "z": 1,
      "name": "Rock_Crystal_Red_Block",
      "rotation": 21
    },
    {
      "x": 1,
      "y": 112,
      "z": 1,
      "name": "Rock_Crystal_Red_Block",
      "rotation": 21
    },
    {
      "x": 1,
      "y": 113,
      "z": 1,
      "name": "Rock_Crystal_Red_Block",
      "rotation": 21
    },
    {
      "x": 1,
      "y": 114,
      "z": 1,
      "name": "Rock_Crystal_Red_Block",
      "rotation": 21
    },
    {
      "x": 1,
      "y": 115,
      "z": 1,
      "name": "Rock_Crystal_Red_Block",
      "rotation": 21
    },
    {
      "x": 1,
      "y": 116,
      "z": 1,
      "name": "Rock_Crystal_Red_Block",
      "rotation": 4
    },
    {
      "x": 1,
      "y": 105,
      "z": 2,
      "name": "Rock_Crystal_Red_Block",
      "rotation": 21
    },
    {
      "x": 1,
      "y": 104,
      "z": 3,
      "name": "Rock_Crystal_Red_Block",
      "rotation": 21
    },
    {
      "x": 1,
      "y": 105,
      "z": 3,
      "name": "Rock_Crystal_Red_Block",
      "rotation": 4
    },
    {
      "x": 1,
      "y": 106,
      "z": 3,
      "name": "Rock_Crystal_Red_Block",
      "rotation": 21
    },
    {
      "x": 1,
      "y": 103,
      "z": 4,
      "name": "Rock_Crystal_Red_Block",
      "rotation": 21
    },
    {
      "x": 1,
      "y": 104,
      "z": 4,
      "name": "Rock_Crystal_Red_Block",
      "rotation": 4
    },
    {
      "x": 1,
      "y": 106,
      "z": 4,
      "name": "Rock_Crystal_Red_Block",
      "rotation": 4
    },
    {
      "x": 1,
      "y": 107,
      "z": 4,
      "name": "Rock_Crystal_Red_Block",
      "rotation": 21
    },
    {
      "x": 1,
      "y": 102,
      "z": 5,
      "name": "Rock_Crystal_Red_Block",
      "rotation": 21
    },
    {
      "x": 1,
      "y": 103,
      "z": 5,
      "name": "Rock_Crystal_Red_Block",
      "rotation": 4
    },
    {
      "x": 1,
      "y": 107,
      "z": 5,
      "name": "Rock_Crystal_Red_Block",
      "rotation": 4
    },
    {
      "x": 1,
      "y": 108,
      "z": 5,
      "name": "Rock_Crystal_Red_Block",
      "rotation": 21
    },
    {
      "x": 1,
      "y": 101,
      "z": 6,
      "name": "Rock_Crystal_Red_Block",
      "rotation": 21
    },
    {
      "x": 1,
      "y": 102,
      "z": 6,
      "name": "Rock_Crystal_Red_Block",
      "rotation": 4
    },
    {
      "x": 1,
      "y": 108,
      "z": 6,
      "name": "Rock_Crystal_Red_Block",
      "rotation": 4
    },
    {
      "x": 1,
      "y": 109,
      "z": 6,
      "name": "Rock_Crystal_Red_Block",
      "rotation": 21
    },
    {
      "x": 1,
      "y": 100,
      "z": 7,
      "name": "Rock_Crystal_Red_Block",
      "rotation": 21
    },
    {
      "x": 1,
      "y": 101,
      "z": 7,
      "name": "Rock_Crystal_Red_Block",
      "rotation": 4
    },
    {
      "x": 1,
      "y": 109,
      "z": 7,
      "name": "Rock_Crystal_Red_Block",
      "rotation": 4
    },
    {
      "x": 1,
      "y": 110,
      "z": 7,
      "name": "Rock_Crystal_Red_Block",
      "rotation": 21
    },
    {
      "x": 1,
      "y": 99,
      "z": 8,
      "name": "Rock_Crystal_Red_Block",
      "rotation": 21
    },
    {
      "x": 1,
      "y": 100,
      "z": 8,
      "name": "Rock_Crystal_Red_Block",
      "rotation": 4
    },
    {
      "x": 1,
      "y": 110,
      "z": 8,
      "name": "Rock_Crystal_Red_Block",
      "rotation": 4
    },
    {
      "x": 1,
      "y": 111,
      "z": 8,
      "name": "Rock_Crystal_Red_Block",
      "rotation": 21
    },
    {
      "x": 1,
      "y": 98,
      "z": 9,
      "name": "Rock_Crystal_Red_Block",
      "rotation": 21
    },
    {
      "x": 1,
      "y": 99,
      "z": 9,
      "name": "Rock_Crystal_Red_Block",
      "rotation": 4
    },
    {
      "x": 1,
      "y": 111,
      "z": 9,
      "name": "Rock_Crystal_Red_Block",
      "rotation": 4
    },
    {
      "x": 1,
      "y": 112,
      "z": 9,
      "name": "Rock_Crystal_Red_Block",
      "rotation": 21
    },
    {
      "x": 1,
      "y": 97,
      "z": 10,
      "name": "Rock_Crystal_Red_Block",
      "rotation": 21
    },
    {
      "x": 1,
      "y": 98,
      "z": 10,
      "name": "Rock_Crystal_Red_Block",
      "rotation": 4
    },
    {
      "x": 1,
      "y": 112,
      "z": 10,
      "name": "Rock_Crystal_Red_Block",
      "rotation": 4
    },
    {
      "x": 1,
      "y": 113,
      "z": 10,
      "name": "Rock_Crystal_Red_Block",
      "rotation": 21
    },
    {
      "x": 1,
      "y": 97,
      "z": 11,
      "name": "Rock_Crystal_Red_Block",
      "rotation": 4
    },
    {
      "x": 1,
      "y": 113,
      "z": 11,
      "name": "Rock_Crystal_Red_Block",
      "rotation": 4
    }
  ],
  "fluids": [
    {
      "x": -1,
      "y": 97,
      "z": -9,
      "name": "Empty",
      "level": 0
    },
    {
      "x": -1,
      "y": 113,
      "z": -9,
      "name": "Empty",
      "level": 0
    },
    {
      "x": -1,
      "y": 97,
      "z": -8,
      "name": "Empty",
      "level": 0
    },
    {
      "x": -1,
      "y": 98,
      "z": -8,
      "name": "Empty",
      "level": 0
    },
    {
      "x": -1,
      "y": 112,
      "z": -8,
      "name": "Empty",
      "level": 0
    },
    {
      "x": -1,
      "y": 113,
      "z": -8,
      "name": "Empty",
      "level": 0
    },
    {
      "x": -1,
      "y": 98,
      "z": -7,
      "name": "Empty",
      "level": 0
    },
    {
      "x": -1,
      "y": 99,
      "z": -7,
      "name": "Empty",
      "level": 0
    },
    {
      "x": -1,
      "y": 111,
      "z": -7,
      "name": "Empty",
      "level": 0
    },
    {
      "x": -1,
      "y": 112,
      "z": -7,
      "name": "Empty",
      "level": 0
    },
    {
      "x": -1,
      "y": 99,
      "z": -6,
      "name": "Empty",
      "level": 0
    },
    {
      "x": -1,
      "y": 100,
      "z": -6,
      "name": "Empty",
      "level": 0
    },
    {
      "x": -1,
      "y": 110,
      "z": -6,
      "name": "Empty",
      "level": 0
    },
    {
      "x": -1,
      "y": 111,
      "z": -6,
      "name": "Empty",
      "level": 0
    },
    {
      "x": -1,
      "y": 100,
      "z": -5,
      "name": "Empty",
      "level": 0
    },
    {
      "x": -1,
      "y": 101,
      "z": -5,
      "name": "Empty",
      "level": 0
    },
    {
      "x": -1,
      "y": 109,
      "z": -5,
      "name": "Empty",
      "level": 0
    },
    {
      "x": -1,
      "y": 110,
      "z": -5,
      "name": "Empty",
      "level": 0
    },
    {
      "x": -1,
      "y": 101,
      "z": -4,
      "name": "Empty",
      "level": 0
    },
    {
      "x": -1,
      "y": 102,
      "z": -4,
      "name": "Empty",
      "level": 0
    },
    {
      "x": -1,
      "y": 108,
      "z": -4,
      "name": "Empty",
      "level": 0
    },
    {
      "x": -1,
      "y": 109,
      "z": -4,
      "name": "Empty",
      "level": 0
    },
    {
      "x": -1,
      "y": 102,
      "z": -3,
      "name": "Empty",
      "level": 0
    },
    {
      "x": -1,
      "y": 103,
      "z": -3,
      "name": "Empty",
      "level": 0
    },
    {
      "x": -1,
      "y": 107,
      "z": -3,
      "name": "Empty",
      "level": 0
    },
    {
      "x": -1,
      "y": 108,
      "z": -3,
      "name": "Empty",
      "level": 0
    },
    {
      "x": -1,
      "y": 103,
      "z": -2,
      "name": "Empty",
      "level": 0
    },
    {
      "x": -1,
      "y": 104,
      "z": -2,
      "name": "Empty",
      "level": 0
    },
    {
      "x": -1,
      "y": 106,
      "z": -2,
      "name": "Empty",
      "level": 0
    },
    {
      "x": -1,
      "y": 107,
      "z": -2,
      "name": "Empty",
      "level": 0
    },
    {
      "x": -1,
      "y": 104,
      "z": -1,
      "name": "Empty",
      "level": 0
    },
    {
      "x": -1,
      "y": 105,
      "z": -1,
      "name": "Empty",
      "level": 0
    },
    {
      "x": -1,
      "y": 106,
      "z": -1,
      "name": "Empty",
      "level": 0
    },
    {
      "x": -1,
      "y": 105,
      "z": 0,
      "name": "Empty",
      "level": 0
    },
    {
      "x": -1,
      "y": 0,
      "z": 1,
      "name": "Empty",
      "level": 0
    },
    {
      "x": -1,
      "y": 1,
      "z": 1,
      "name": "Empty",
      "level": 0
    },
    {
      "x": -1,
      "y": 2,
      "z": 1,
      "name": "Empty",
      "level": 0
    },
    {
      "x": -1,
      "y": 3,
      "z": 1,
      "name": "Empty",
      "level": 0
    },
    {
      "x": -1,
      "y": 4,
      "z": 1,
      "name": "Empty",
      "level": 0
    },
    {
      "x": -1,
      "y": 5,
