{
  "version": 8,
  "blockIdVersion": 11,
  "anchorX": 0,
  "anchorY": 0,
  "anchorZ": 0,
  "blocks": [
    {
      "x": -16,
      "y": 0,
      "z": 0,
      "name": "Rock_Crystal_Purple_Block"
    },
    {
      "x": -16,
      "y": 1,
      "z": 0,
      "name": "Rock_Crystal_Purple_Block"
    },
    {
      "x": -16,
      "y": 2,
      "z": 0,
      "name": "Rock_Crystal_Purple_Block"
    },
    {
      "x": -16,
      "y": 3,
      "z": 0,
      "name": "Rock_Crystal_Purple_Block"
    },
    {
      "x": -16,
      "y": 4,
      "z": 0,
      "name": "Rock_Crystal_Purple_Block"
    },
    {
      "x": -16,
      "y": 5,
      "z": 0,
      "name": "Rock_Crystal_Purple_Block"
    },
    {
      "x": -16,
      "y": 6,
      "z": 0,
      "name": "Rock_Crystal_Purple_Block"
    },
    {
      "x": -16,
      "y": 7,
      "z": 0,
      "name": "Rock_Crystal_Purple_Block"
    },
    {
      "x": -16,
      "y": 8,
      "z": 0,
      "name": "Rock_Crystal_Purple_Block"
    },
    {
      "x": -16,
      "y": 9,
      "z": 0,
      "name": "Rock_Crystal_Purple_Block"
    },
    {
      "x": -16,
      "y": 10,
      "z": 0,
      "name": "Rock_Crystal_Purple_Block"
    },
    {
      "x": -16,
      "y": 11,
      "z": 0,
      "name": "Rock_Crystal_Purple_Block"
    },
    {
      "x": -16,
      "y": 12,
      "z": 0,
      "name": "Rock_Crystal_Purple_Block"
    },
    {
      "x": -16,
      "y": 13,
      "z": 0,
      "name": "Rock_Crystal_Purple_Block"
    },
    {
      "x": -16,
      "y": 14,
      "z": 0,
      "name": "Rock_Crystal_Purple_Block"
    },
    {
      "x": -16,
      "y": 15,
      "z": 0,
      "name": "Rock_Crystal_Purple_Block"
    },
    {
      "x": -16,
      "y": 16,
      "z": 0,
      "name": "Rock_Crystal_Purple_Block"
    },
    {
      "x": -16,
      "y": 17,
      "z": 0,
      "name": "Rock_Crystal_Purple_Block"
    },
    {
      "x": -16,
      "y": 18,
      "z": 0,
      "name": "Rock_Crystal_Purple_Block"
    },
    {
      "x": -16,
      "y": 19,
      "z": 0,
      "name": "Rock_Crystal_Purple_Block"
    },
    {
      "x": -15,
      "y": 0,
      "z": -1,
      "name": "Rock_Crystal_Purple_Block"
    },
    {
      "x": -15,
      "y": 1,
      "z": -1,
      "name": "Rock_Crystal_Purple_Block"
    },
    {
      "x": -15,
      "y": 2,
      "z": -1,
      "name": "Rock_Crystal_Purple_Block"
    },
    {
      "x": -15,
      "y": 3,
      "z": -1,
      "name": "Rock_Crystal_Purple_Block"
    },
    {
      "x": -15,
      "y": 4,
      "z": -1,
      "name": "Rock_Crystal_Purple_Block"
    },
    {
      "x": -15,
      "y": 5,
      "z": -1,
      "name": "Rock_Crystal_Purple_Block"
    },
    {
      "x": -15,
      "y": 6,
      "z": -1,
      "name": "Rock_Crystal_Purple_Block"
    },
    {
      "x": -15,
      "y": 7,
      "z": -1,
      "name": "Rock_Crystal_Purple_Block"
    },
    {
      "x": -15,
      "y": 8,
      "z": -1,
      "name": "Rock_Crystal_Purple_Block"
    },
    {
      "x": -15,
      "y": 9,
      "z": -1,
      "name": "Rock_Crystal_Purple_Block"
    },
    {
      "x": -15,
      "y": 10,
      "z": -1,
      "name": "Rock_Crystal_Purple_Block"
    },
    {
      "x": -15,
      "y": 11,
      "z": -1,
      "name": "Rock_Crystal_Purple_Block"
    },
    {
      "x": -15,
      "y": 12,
      "z": -1,
      "name": "Rock_Crystal_Purple_Block"
    },
    {
      "x": -15,
      "y": 13,
      "z": -1,
      "name": "Rock_Crystal_Purple_Block"
    },
    {
      "x": -15,
      "y": 14,
      "z": -1,
      "name": "Rock_Crystal_Purple_Block"
    },
    {
      "x": -15,
      "y": 15,
      "z": -1,
      "name": "Rock_Crystal_Purple_Block"
    },
    {
      "x": -15,
      "y": 16,
      "z": -1,
      "name": "Rock_Crystal_Purple_Block"
    },
    {
      "x": -15,
      "y": 17,
      "z": -1,
      "name": "Rock_Crystal_Purple_Block"
    },
    {
      "x": -15,
      "y": 18,
      "z": -1,
      "name": "Rock_Crystal_Purple_Block"
    },
    {
      "x": -15,
      "y": 19,
      "z": -1,
      "name": "Rock_Crystal_Purple_Block"
    },
    {
      "x": -15,
      "y": 0,
      "z": 0,
      "name": "Rock_Crystal_Purple_Block"
    },
    {
      "x": -15,
      "y": 1,
      "z": 0,
      "name": "Rock_Crystal_Purple_Block"
    },
    {
      "x": -15,
      "y": 2,
      "z": 0,
      "name": "Rock_Crystal_Purple_Block"
    },
    {
      "x": -15,
      "y": 3,
      "z": 0,
      "name": "Rock_Crystal_Purple_Block"
    },
    {
      "x": -15,
      "y": 4,
      "z": 0,
      "name": "Rock_Crystal_Purple_Block"
    },
    {
      "x": -15,
      "y": 5,
      "z": 0,
      "name": "Rock_Crystal_Purple_Block"
    },
    {
      "x": -15,
      "y": 6,
      "z": 0,
      "name": "Rock_Crystal_Purple_Block"
    },
    {
      "x": -15,
      "y": 7,
      "z": 0,
      "name": "Rock_Crystal_Purple_Block"
    },
    {
      "x": -15,
      "y": 8,
      "z": 0,
      "name": "Rock_Crystal_Purple_Block"
    },
    {
      "x": -15,
      "y": 9,
      "z": 0,
      "name": "Rock_Crystal_Purple_Block"
    },
    {
      "x": -15,
      "y": 10,
      "z": 0,
      "name": "Rock_Crystal_Purple_Block"
    },
    {
      "x": -15,
      "y": 11,
      "z": 0,
      "name": "Rock_Crystal_Purple_Block"
    },
    {
      "x": -15,
      "y": 12,
      "z": 0,
      "name": "Rock_Crystal_Purple_Block"
    },
    {
      "x": -15,
      "y": 13,
      "z": 0,
      "name": "Rock_Crystal_Purple_Block"
    },
    {
      "x": -15,
      "y": 14,
      "z": 0,
      "name": "Rock_Crystal_Purple_Block"
    },
    {
      "x": -15,
      "y": 15,
      "z": 0,
      "name": "Rock_Crystal_Purple_Block"
    },
    {
      "x": -15,
      "y": 16,
      "z": 0,
      "name": "Rock_Crystal_Purple_Block"
    },
    {
      "x": -15,
      "y": 17,
      "z": 0,
      "name": "Rock_Crystal_Purple_Block"
    },
    {
      "x": -15,
      "y": 18,
      "z": 0,
      "name": "Rock_Crystal_Purple_Block"
    },
    {
      "x": -15,
      "y": 19,
      "z": 0,
      "name": "Rock_Crystal_Purple_Block"
    },
    {
      "x": -14,
      "y": 0,
      "z": -2,
      "name": "Rock_Crystal_Purple_Block"
    },
    {
      "x": -14,
      "y": 1,
      "z": -2,
      "name": "Rock_Crystal_Purple_Block"
    },
    {
      "x": -14,
      "y": 2,
      "z": -2,
      "name": "Rock_Crystal_Purple_Block"
    },
    {
      "x": -14,
      "y": 3,
      "z": -2,
      "name": "Rock_Crystal_Purple_Block"
    },
    {
      "x": -14,
      "y": 4,
      "z": -2,
      "name": "Rock_Crystal_Purple_Block"
    },
    {
      "x": -14,
      "y": 5,
      "z": -2,
      "name": "Rock_Crystal_Purple_Block"
    },
    {
      "x": -14,
      "y": 6,
      "z": -2,
      "name": "Rock_Crystal_Purple_Block"
    },
    {
      "x": -14,
      "y": 7,
      "z": -2,
      "name": "Rock_Crystal_Purple_Block"
    },
    {
      "x": -14,
      "y": 8,
      "z": -2,
      "name": "Rock_Crystal_Purple_Block"
    },
    {
      "x": -14,
      "y": 9,
      "z": -2,
      "name": "Rock_Crystal_Purple_Block"
    },
    {
      "x": -14,
      "y": 10,
      "z": -2,
      "name": "Rock_Crystal_Purple_Block"
    },
    {
      "x": -14,
      "y": 11,
      "z": -2,
      "name": "Rock_Crystal_Purple_Block"
    },
    {
      "x": -14,
      "y": 12,
      "z": -2,
      "name": "Rock_Crystal_Purple_Block"
    },
    {
      "x": -14,
      "y": 13,
      "z": -2,
      "name": "Rock_Crystal_Purple_Block"
    },
    {
      "x": -14,
      "y": 14,
      "z": -2,
      "name": "Rock_Crystal_Purple_Block"
    },
    {
      "x": -14,
      "y": 15,
      "z": -2,
      "name": "Rock_Crystal_Purple_Block"
    },
    {
      "x": -14,
      "y": 16,
      "z": -2,
      "name": "Rock_Crystal_Purple_Block"
    },
    {
      "x": -14,
      "y": 17,
      "z": -2,
      "name": "Rock_Crystal_Purple_Block"
    },
    {
      "x": -14,
      "y": 18,
      "z": -2,
      "name": "Rock_Crystal_Purple_Block"
    },
    {
      "x": -14,
      "y": 19,
      "z": -2,
      "name": "Rock_Crystal_Purple_Block"
    },
    {
      "x": -14,
      "y": 0,
      "z": -1,
      "name": "Rock_Crystal_Purple_Block"
    },
    {
      "x": -14,
      "y": 1,
      "z": -1,
      "name": "Rock_Crystal_Purple_Block"
    },
    {
      "x": -14,
      "y": 2,
      "z": -1,
      "name": "Rock_Crystal_Purple_Block"
    },
    {
      "x": -14,
      "y": 3,
      "z": -1,
      "name": "Rock_Crystal_Purple_Block"
    },
    {
      "x": -14,
      "y": 4,
      "z": -1,
      "name": "Rock_Crystal_Purple_Block"
    },
    {
      "x": -14,
      "y": 5,
      "z": -1,
      "name": "Rock_Crystal_Purple_Block"
    },
    {
      "x": -14,
      "y": 6,
      "z": -1,
      "name": "Rock_Crystal_Purple_Block"
    },
    {
      "x": -14,
      "y": 7,
      "z": -1,
      "name": "Rock_Crystal_Purple_Block"
    },
    {
      "x": -14,
      "y": 8,
      "z": -1,
      "name": "Rock_Crystal_Purple_Block"
    },
    {
      "x": -14,
      "y": 9,
      "z": -1,
      "name": "Rock_Crystal_Purple_Block"
    },
    {
      "x": -14,
      "y": 10,
      "z": -1,
      "name": "Rock_Crystal_Purple_Block"
    },
    {
      "x": -14,
      "y": 11,
      "z": -1,
      "name": "Rock_Crystal_Purple_Block"
    },
    {
      "x": -14,
      "y": 12,
      "z": -1,
      "name": "Rock_Crystal_Purple_Block"
    },
    {
      "x": -14,
      "y": 13,
      "z": -1,
      "name": "Rock_Crystal_Purple_Block"
    },
    {
      "x": -14,
      "y": 14,
      "z": -1,
      "name": "Rock_Crystal_Purple_Block"
    },
    {
      "x": -14,
      "y": 15,
      "z": -1,
      "name": "Rock_Crystal_Purple_Block"
    },
    {
      "x": -14,
      "y": 16,
      "z": -1,
      "name": "Rock_Crystal_Purple_Block"
    },
    {
      "x": -14,
      "y": 17,
      "z": -1,
      "name": "Rock_Crystal_Purple_Block"
    },
    {
      "x": -14,
      "y": 18,
      "z": -1,
      "name": "Rock_Crystal_Purple_Block"
    },
    {
      "x": -14,
      "y": 19,
      "z": -1,
      "name": "Rock_Crystal_Purple_Block"
    },
    {
      "x": -13,
      "y": 0,
      "z": -3,
      "name": "Rock_Crystal_Purple_Block"
    },
    {
      "x": -13,
      "y": 1,
      "z": -3,
      "name": "Rock_Crystal_Purple_Block"
    },
    {
      "x": -13,
      "y": 2,
      "z": -3,
      "name": "Rock_Crystal_Purple_Block"
    },
    {
      "x": -13,
      "y": 3,
      "z": -3,
      "name": "Rock_Crystal_Purple_Block"
    },
    {
      "x": -13,
      "y": 4,
      "z": -3,
      "name": "Rock_Crystal_Purple_Block"
    },
    {
      "x": -13,
      "y": 5,
      "z": -3,
      "name": "Rock_Crystal_Purple_Block"
    },
    {
      "x": -13,
      "y": 6,
      "z": -3,
      "name": "Rock_Crystal_Purple_Block"
    },
    {
      "x": -13,
      "y": 7,
      "z": -3,
      "name": "Rock_Crystal_Purple_Block"
    },
    {
      "x": -13,
      "y": 8,
      "z": -3,
      "name": "Rock_Crystal_Purple_Block"
    },
    {
      "x": -13,
      "y": 9,
      "z": -3,
      "name": "Rock_Crystal_Purple_Block"
    },
    {
      "x": -13,
      "y": 10,
      "z": -3,
      "name": "Rock_Crystal_Purple_Block"
    },
    {
      "x": -13,
      "y": 11,
      "z": -3,
      "name": "Rock_Crystal_Purple_Block"
    },
    {
      "x": -13,
      "y": 12,
      "z": -3,
      "name": "Rock_Crystal_Purple_Block"
    },
    {
      "x": -13,
      "y": 13,
      "z": -3,
      "name": "Rock_Crystal_Purple_Block"
    },
    {
      "x": -13,
      "y": 14,
      "z": -3,
      "name": "Rock_Crystal_Purple_Block"
    },
    {
      "x": -13,
      "y": 15,
      "z": -3,
      "name": "Rock_Crystal_Purple_Block"
    },
    {
      "x": -13,
      "y": 16,
      "z": -3,
      "name": "Rock_Crystal_Purple_Block"
    },
    {
      "x": -13,
      "y": 17,
      "z": -3,
      "name": "Rock_Crystal_Purple_Block"
    },
    {
      "x": -13,
      "y": 18,
      "z": -3,
      "name": "Rock_Crystal_Purple_Block"
    },
    {
      "x": -13,
      "y": 19,
      "z": -3,
      "name": "Rock_Crystal_Purple_Block"
    },
    {
      "x": -13,
      "y": 0,
      "z": -2,
      "name": "Rock_Crystal_Purple_Block"
    },
    {
      "x": -13,
      "y": 1,
      "z": -2,
      "name": "Rock_Crystal_Purple_Block"
    },
    {
      "x": -13,
      "y": 2,
      "z": -2,
      "name": "Rock_Crystal_Purple_Block"
    },
    {
      "x": -13,
      "y": 3,
      "z": -2,
      "name": "Rock_Crystal_Purple_Block"
    },
    {
      "x": -13,
      "y": 4,
      "z": -2,
      "name": "Rock_Crystal_Purple_Block"
    },
    {
      "x": -13,
      "y": 5,
      "z": -2,
      "name": "Rock_Crystal_Purple_Block"
    },
    {
      "x": -13,
      "y": 6,
      "z": -2,
      "name": "Rock_Crystal_Purple_Block"
    },
    {
      "x": -13,
      "y": 7,
      "z": -2,
      "name": "Rock_Crystal_Purple_Block"
    },
    {
      "x": -13,
      "y": 8,
      "z": -2,
      "name": "Rock_Crystal_Purple_Block"
    },
    {
      "x": -13,
      "y": 9,
      "z": -2,
      "name": "Rock_Crystal_Purple_Block"
    },
    {
      "x": -13,
      "y": 10,
      "z": -2,
      "name": "Rock_Crystal_Purple_Block"
    },
    {
      "x": -13,
      "y": 11,
      "z": -2,
      "name": "Rock_Crystal_Purple_Block"
    },
    {
      "x": -13,
      "y": 12,
      "z": -2,
      "name": "Rock_Crystal_Purple_Block"
    },
    {
      "x": -13,
      "y": 13,
      "z": -2,
      "name": "Rock_Crystal_Purple_Block"
    },
    {
      "x": -13,
      "y": 14,
      "z": -2,
      "name": "Rock_Crystal_Purple_Block"
    },
    {
      "x": -13,
      "y": 15,
      "z": -2,
      "name": "Rock_Crystal_Purple_Block"
    },
    {
      "x": -13,
      "y": 16,
      "z": -2,
      "name": "Rock_Crystal_Purple_Block"
    },
    {
      "x": -13,
      "y": 17,
      "z": -2,
      "name": "Rock_Crystal_Purple_Block"
    },
    {
      "x": -13,
      "y": 18,
      "z": -2,
      "name": "Rock_Crystal_Purple_Block"
    },
    {
      "x": -13,
      "y": 19,
      "z": -2,
      "name": "Rock_Crystal_Purple_Block"
    },
    {
      "x": -12,
      "y": 0,
      "z": -3,
      "name": "Rock_Crystal_Purple_Block"
    },
    {
      "x": -12,
      "y": 1,
      "z": -3,
      "name": "Rock_Crystal_Purple_Block"
    },
    {
      "x": -12,
      "y": 2,
      "z": -3,
      "name": "Rock_Crystal_Purple_Block"
    },
    {
      "x": -12,
      "y": 3,
      "z": -3,
      "name": "Rock_Crystal_Purple_Block"
    },
    {
      "x": -12,
      "y": 4,
      "z": -3,
      "name": "Rock_Crystal_Purple_Block"
    },
    {
      "x": -12,
      "y": 5,
      "z": -3,
      "name": "Rock_Crystal_Purple_Block"
    },
    {
      "x": -12,
      "y": 6,
      "z": -3,
      "name": "Rock_Crystal_Purple_Block"
    },
    {
      "x": -12,
      "y": 7,
      "z": -3,
      "name": "Rock_Crystal_Purple_Block"
    },
    {
      "x": -12,
      "y": 8,
      "z": -3,
      "name": "Rock_Crystal_Purple_Block"
    },
    {
      "x": -12,
      "y": 9,
      "z": -3,
      "name": "Rock_Crystal_Purple_Block"
    },
    {
      "x": -12,
      "y": 10,
      "z": -3,
      "name": "Rock_Crystal_Purple_Block"
    },
    {
      "x": -12,
      "y": 11,
      "z": -3,
      "name": "Rock_Crystal_Purple_Block"
    },
    {
      "x": -12,
      "y": 12,
      "z": -3,
      "name": "Rock_Crystal_Purple_Block"
    },
    {
      "x": -12,
      "y": 13,
      "z": -3,
      "name": "Rock_Crystal_Purple_Block"
    },
    {
      "x": -12,
      "y": 14,
      "z": -3,
      "name": "Rock_Crystal_Purple_Block"
    },
    {
      "x": -12,
      "y": 15,
      "z": -3,
      "name": "Rock_Crystal_Purple_Block"
    },
    {
      "x": -12,
      "y": 16,
      "z": -3,
      "name": "Rock_Crystal_Purple_Block"
    },
    {
      "x": -12,
      "y": 17,
      "z": -3,
      "name": "Rock_Crystal_Purple_Block"
    },
    {
      "x": -12,
      "y": 18,
      "z": -3,
      "name": "Rock_Crystal_Purple_Block"
    },
    {
      "x": -12,
      "y": 19,
      "z": -3,
      "name": "Rock_Crystal_Purple_Block"
    },
    {
      "x": -12,
      "y": 0,
      "z": 6,
      "name": "Rock_Crystal_Purple_Block"
    },
    {
      "x": -12,
      "y": 1,
      "z": 6,
      "name": "Rock_Crystal_Purple_Block"
    },
    {
      "x": -12,
      "y": 2,
      "z": 6,
      "name": "Rock_Crystal_Purple_Block"
    },
    {
      "x": -12,
      "y": 3,
      "z": 6,
      "name": "Rock_Crystal_Purple_Block"
    },
    {
      "x": -12,
      "y": 4,
      "z": 6,
      "name": "Rock_Crystal_Purple_Block"
    },
    {
      "x": -12,
      "y": 5,
      "z": 6,
      "name": "Rock_Crystal_Purple_Block"
    },
    {
      "x": -12,
      "y": 6,
      "z": 6,
      "name": "Rock_Crystal_Purple_Block"
    },
    {
      "x": -12,
      "y": 7,
      "z": 6,
      "name": "Rock_Crystal_Purple_Block"
    },
    {
      "x": -12,
      "y": 8,
      "z": 6,
      "name": "Rock_Crystal_Purple_Block"
    },
    {
      "x": -12,
      "y": 9,
      "z": 6,
      "name": "Rock_Crystal_Purple_Block"
    },
    {
      "x": -12,
      "y": 10,
      "z": 6,
      "name": "Rock_Crystal_Purple_Block"
    },
    {
      "x": -12,
      "y": 11,
      "z": 6,
      "name": "Rock_Crystal_Purple_Block"
    },
    {
      "x": -12,
      "y": 12,
      "z": 6,
      "name": "Rock_Crystal_Purple_Block"
    },
    {
      "x": -12,
      "y": 13,
      "z": 6,
      "name": "Rock_Crystal_Purple_Block"
    },
    {
      "x": -12,
      "y": 14,
      "z": 6,
      "name": "Rock_Crystal_Purple_Block"
    },
    {
      "x": -12,
      "y": 15,
      "z": 6,
      "name": "Rock_Crystal_Purple_Block"
    },
    {
      "x": -12,
      "y": 16,
      "z": 6,
      "name": "Rock_Crystal_Purple_Block"
    },
    {
      "x": -12,
      "y": 17,
      "z": 6,
      "name": "Rock_Crystal_Purple_Block"
    },
    {
      "x": -12,
      "y": 18,
      "z": 6,
      "name": "Rock_Crystal_Purple_Block"
    },
    {
      "x": -12,
      "y": 19,
      "z": 6,
      "name": "Rock_Crystal_Purple_Block"
    },
    {
      "x": -12,
      "y": 0,
      "z": 7,
      "name": "Rock_Crystal_Purple_Block"
    },
    {
      "x": -12,
      "y": 1,
      "z": 7,
      "name": "Rock_Crystal_Purple_Block"
    },
    {
      "x": -12,
      "y": 2,
      "z": 7,
      "name": "Rock_Crystal_Purple_Block"
    },
    {
      "x": -12,
      "y": 3,
      "z": 7,
      "name": "Rock_Crystal_Purple_Block"
    },
    {
      "x": -12,
      "y": 4,
      "z": 7,
      "name": "Rock_Crystal_Purple_Block"
    },
    {
      "x": -12,
      "y": 5,
      "z": 7,
      "name": "Rock_Crystal_Purple_Block"
    },
    {
      "x": -12,
      "y": 6,
      "z": 7,
      "name": "Rock_Crystal_Purple_Block"
    },
    {
      "x": -12,
      "y": 7,
      "z": 7,
      "name": "Rock_Crystal_Purple_Block"
    },
    {
      "x": -12,
      "y": 8,
      "z": 7,
      "name": "Rock_Crystal_Purple_Block"
    },
    {
      "x": -12,
      "y": 9,
      "z": 7,
      "name": "Rock_Crystal_Purple_Block"
    },
    {
      "x": -12,
      "y": 10,
      "z": 7,
      "name": "Rock_Crystal_Purple_Block"
    },
    {
      "x": -12,
      "y": 11,
      "z": 7,
      "name": "Rock_Crystal_Purple_Block"
    },
    {
      "x": -12,
      "y": 12,
      "z": 7,
      "name": "Rock_Crystal_Purple_Block"
    },
    {
      "x": -12,
      "y": 13,
      "z": 7,
      "name": "Rock_Crystal_Purple_Block"
    },
    {
      "x": -12,
      "y": 14,
      "z": 7,
      "name": "Rock_Crystal_Purple_Block"
    },
    {
      "x": -12,
      "y": 15,
      "z": 7,
      "name": "Rock_Crystal_Purple_Block"
    },
    {
      "x": -12,
      "y": 16,
      "z": 7,
      "name": "Rock_Crystal_Purple_Block"
    },
    {
      "x": -12,
      "y": 17,
      "z": 7,
      "name": "Rock_Crystal_Purple_Block"
    },
    {
      "x": -12,
      "y": 18,
      "z": 7,
      "name": "Rock_Crystal_Purple_Block"
    },
    {
      "x": -12,
      "y": 19,
      "z": 7,
      "name": "Rock_Crystal_Purple_Block"
    },
    {
      "x": -11,
      "y": 0,
      "z": -11,
      "name": "Rock_Crystal_Purple_Block"
    },
    {
      "x": -11,
      "y": 1,
      "z": -11,
      "name": "Rock_Crystal_Purple_Block"
    },
    {
      "x": -11,
      "y": 2,
      "z": -11,
      "name": "Rock_Crystal_Purple_Block"
    },
    {
      "x": -11,
      "y": 3,
      "z": -11,
      "name": "Rock_Crystal_Purple_Block"
    },
    {
      "x": -11,
      "y": 4,
      "z": -11,
      "name": "Rock_Crystal_Purple_Block"
    },
    {
      "x": -11,
      "y": 5,
      "z": -11,
      "name": "Rock_Crystal_Purple_Block"
    },
    {
      "x": -11,
      "y": 6,
      "z": -11,
      "name": "Rock_Crystal_Purple_Block"
    },
    {
      "x": -11,
      "y": 7,
      "z": -11,
      "name": "Rock_Crystal_Purple_Block"
    },
    {
      "x": -11,
      "y": 8,
      "z": -11,
      "name": "Rock_Crystal_Purple_Block"
    },
    {
      "x": -11,
      "y": 9,
      "z": -11,
      "name": "Rock_Crystal_Purple_Block"
    },
    {
      "x": -11,
      "y": 10,
      "z": -11,
      "name": "Rock_Crystal_Purple_Block"
    },
    {
      "x": -11,
      "y": 11,
      "z": -11,
      "name": "Rock_Crystal_Purple_Block"
    },
    {
      "x": -11,
      "y": 12,
      "z": -11,
      "name": "Rock_Crystal_Purple_Block"
    },
    {
      "x": -11,
      "y": 13,
      "z": -11,
      "name": "Rock_Crystal_Purple_Block"
    },
    {
      "x": -11,
      "y": 14,
      "z": -11,
      "name": "Rock_Crystal_Purple_Block"
    },
    {
      "x": -11,
      "y": 15,
      "z": -11,
      "name": "Rock_Crystal_Purple_Block"
    },
    {
      "x": -11,
      "y": 16,
      "z": -11,
      "name": "Rock_Crystal_Purple_Block"
    },
    {
      "x": -11,
      "y": 17,
      "z": -11,
      "name": "Rock_Crystal_Purple_Block"
    },
    {
      "x": -11,
      "y": 18,
      "z": -11,
      "name": "Rock_Crystal_Purple_Block"
    },
    {
      "x": -11,
      "y": 19,
      "z": -11,
      "name": "Rock_Crystal_Purple_Block"
    },
    {
      "x": -11,
      "y": 0,
      "z": -10,
      "name": "Rock_Crystal_Purple_Block"
    },
    {
      "x": -11,
      "y": 1,
      "z": -10,
      "name": "Rock_Crystal_Purple_Block"
    },
    {
      "x": -11,
      "y": 2,
      "z": -10,
      "name": "Rock_Crystal_Purple_Block"
    },
    {
      "x": -11,
      "y": 3,
      "z": -10,
      "name": "Rock_Crystal_Purple_Block"
    },
    {
      "x": -11,
      "y": 4,
      "z": -10,
      "name": "Rock_Crystal_Purple_Block"
    },
    {
      "x": -11,
      "y": 5,
      "z": -10,
      "name": "Rock_Crystal_Purple_Block"
    },
    {
      "x": -11,
      "y": 6,
      "z": -10,
      "name": "Rock_Crystal_Purple_Block"
    },
    {
      "x": -11,
      "y": 7,
      "z": -10,
      "name": "Rock_Crystal_Purple_Block"
    },
    {
      "x": -11,
      "y": 8,
      "z": -10,
      "name": "Rock_Crystal_Purple_Block"
    },
    {
      "x": -11,
      "y": 9,
      "z": -10,
      "name": "Rock_Crystal_Purple_Block"
    },
    {
      "x": -11,
      "y": 10,
      "z": -10,
      "name": "Rock_Crystal_Purple_Block"
    },
    {
      "x": -11,
      "y": 11,
      "z": -10,
      "name": "Rock_Crystal_Purple_Block"
    },
    {
      "x": -11,
      "y": 12,
      "z": -10,
      "name": "Rock_Crystal_Purple_Block"
    },
    {
      "x": -11,
      "y": 13,
      "z": -10,
      "name": "Rock_Crystal_Purple_Block"
    },
    {
      "x": -11,
      "y": 14,
      "z": -10,
      "name": "Rock_Crystal_Purple_Block"
    },
    {
      "x": -11,
      "y": 15,
      "z": -10,
      "name": "Rock_Crystal_Purple_Block"
    },
    {
      "x": -11,
      "y": 16,
      "z": -10,
      "name": "Rock_Crystal_Purple_Block"
    },
    {
      "x": -11,
      "y": 17,
      "z": -10,
      "name": "Rock_Crystal_Purple_Block"
    },
    {
      "x": -11,
      "y": 18,
      "z": -10,
      "name": "Rock_Crystal_Purple_Block"
    },
    {
      "x": -11,
      "y": 19,
      "z": -10,
      "name": "Rock_Crystal_Purple_Block"
    },
    {
      "x": -11,
      "y": 0,
      "z": -5,
      "name": "Rock_Crystal_Purple_Block"
    },
    {
      "x": -11,
      "y": 1,
      "z": -5,
      "name": "Rock_Crystal_Purple_Block"
    },
    {
      "x": -11,
      "y": 2,
      "z": -5,
      "name": "Rock_Crystal_Purple_Block"
    },
    {
      "x": -11,
      "y": 3,
      "z": -5,
      "name": "Rock_Crystal_Purple_Block"
    },
    {
      "x": -11,
      "y": 4,
      "z": -5,
      "name": "Rock_Crystal_Purple_Block"
    },
    {
      "x": -11,
      "y": 5,
      "z": -5,
      "name": "Rock_Crystal_Purple_Block"
    },
    {
      "x": -11,
      "y": 6,
      "z": -5,
      "name": "Rock_Crystal_Purple_Block"
    },
    {
      "x": -11,
      "y": 7,
      "z": -5,
      "name": "Rock_Crystal_Purple_Block"
    },
    {
      "x": -11,
      "y": 8,
      "z": -5,
      "name": "Rock_Crystal_Purple_Block"
    },
    {
      "x": -11,
      "y": 9,
      "z": -5,
      "name": "Rock_Crystal_Purple_Block"
    },
    {
      "x": -11,
      "y": 10,
      "z": -5,
      "name": "Rock_Crystal_Purple_Block"
    },
    {
      "x": -11,
      "y": 11,
      "z": -5,
      "name": "Rock_Crystal_Purple_Block"
    },
    {
      "x": -11,
      "y": 12,
      "z": -5,
      "name": "Rock_Crystal_Purple_Block"
    },
    {
      "x": -11,
      "y": 13,
      "z": -5,
      "name": "Rock_Crystal_Purple_Block"
    },
    {
      "x": -11,
      "y": 14,
      "z": -5,
      "name": "Rock_Crystal_Purple_Block"
    },
    {
      "x": -11,
      "y": 15,
      "z": -5,
      "name": "Rock_Crystal_Purple_Block"
    },
    {
      "x": -11,
      "y": 16,
      "z": -5,
      "name": "Rock_Crystal_Purple_Block"
    },
    {
      "x": -11,
      "y": 17,
      "z": -5,
      "name": "Rock_Crystal_Purple_Block"
    },
    {
      "x": -11,
      "y": 18,
      "z": -5,
      "name": "Rock_Crystal_Purple_Block"
    },
    {
      "x": -11,
      "y": 19,
      "z": -5,
      "name": "Rock_Crystal_Purple_Block"
    },
    {
      "x": -11,
      "y": 0,
      "z": -4,
      "name": "Rock_Crystal_Purple_Block"
    },
    {
      "x": -11,
      "y": 1,
      "z": -4,
      "name": "Rock_Crystal_Purple_Block"
    },
    {
      "x": -11,
      "y": 2,
      "z": -4,
      "name": "Rock_Crystal_Purple_Block"
    },
    {
      "x": -11,
      "y": 3,
      "z": -4,
      "name": "Rock_Crystal_Purple_Block"
    },
    {
      "x": -11,
      "y": 4,
      "z": -4,
      "name": "Rock_Crystal_Purple_Block"
    },
    {
      "x": -11,
      "y": 5,
      "z": -4,
      "name": "Rock_Crystal_Purple_Block"
    },
    {
      "x": -11,
      "y": 6,
      "z": -4,
      "name": "Rock_Crystal_Purple_Block"
    },
    {
      "x": -11,
      "y": 7,
      "z": -4,
      "name": "Rock_Crystal_Purple_Block"
    },
    {
      "x": -11,
      "y": 8,
      "z": -4,
      "name": "Rock_Crystal_Purple_Block"
    },
    {
      "x": -11,
      "y": 9,
      "z": -4,
      "name": "Rock_Crystal_Purple_Block"
    },
    {
      "x": -11,
      "y": 10,
      "z": -4,
      "name": "Rock_Crystal_Purple_Block"
    },
    {
      "x": -11,
      "y": 11,
      "z": -4,
      "name": "Rock_Crystal_Purple_Block"
    },
    {
      "x": -11,
      "y": 12,
      "z": -4,
      "name": "Rock_Crystal_Purple_Block"
    },
    {
      "x": -11,
      "y": 13,
      "z": -4,
      "name": "Rock_Crystal_Purple_Block"
    },
    {
      "x": -11,
      "y": 14,
      "z": -4,
      "name": "Rock_Crystal_Purple_Block"
    },
    {
      "x": -11,
      "y": 15,
      "z": -4,
      "name": "Rock_Crystal_Purple_Block"
    },
    {
      "x": -11,
      "y": 16,
      "z": -4,
      "name": "Rock_Crystal_Purple_Block"
    },
    {
      "x": -11,
      "y": 17,
      "z": -4,
      "name": "Rock_Crystal_Purple_Block"
    },
    {
      "x": -11,
      "y": 18,
      "z": -4,
      "name": "Rock_Crystal_Purple_Block"
    },
    {
      "x": -11,
      "y": 19,
      "z": -4,
      "name": "Rock_Crystal_Purple_Block"
    },
    {
      "x": -11,
      "y": 0,
      "z": -3,
      "name": "Rock_Crystal_Purple_Block"
    },
    {
      "x": -11,
      "y": 1,
      "z": -3,
      "name": "Rock_Crystal_Purple_Block"
    },
    {
      "x": -11,
      "y": 2,
      "z": -3,
      "name": "Rock_Crystal_Purple_Block"
    },
    {
      "x": -11,
      "y": 3,
      "z": -3,
      "name": "Rock_Crystal_Purple_Block"
    },
    {
      "x": -11,
      "y": 4,
      "z": -3,
      "name": "Rock_Crystal_Purple_Block"
    },
    {
      "x": -11,
      "y": 5,
      "z": -3,
      "name": "Rock_Crystal_Purple_Block"
    },
    {
      "x": -11,
      "y": 6,
      "z": -3,
      "name": "Rock_Crystal_Purple_Block"
    },
    {
      "x": -11,
      "y": 7,
      "z": -3,
      "name": "Rock_Crystal_Purple_Block"
    },
    {
      "x": -11,
      "y": 8,
      "z": -3,
      "name": "Rock_Crystal_Purple_Block"
    },
    {
      "x": -11,
      "y": 9,
      "z": -3,
      "name": "Rock_Crystal_Purple_Block"
    },
    {
      "x": -11,
      "y": 10,
      "z": -3,
      "name": "Rock_Crystal_Purple_Block"
    },
    {
      "x": -11,
      "y": 11,
      "z": -3,
      "name": "Rock_Crystal_Purple_Block"
    },
    {
      "x": -11,
      "y": 12,
      "z": -3,
      "name": "Rock_Crystal_Purple_Block"
    },
    {
      "x": -11,
      "y": 13,
      "z": -3,
      "name": "Rock_Crystal_Purple_Block"
    },
    {
      "x": -11,
      "y": 14,
      "z": -3,
      "name": "Rock_Crystal_Purple_Block"
    },
    {
      "x": -11,
      "y": 15,
      "z": -3,
      "name": "Rock_Crystal_Purple_Block"
    },
    {
      "x": -11,
      "y": 16,
      "z": -3,
      "name": "Rock_Crystal_Purple_Block"
    },
    {
      "x": -11,
      "y": 17,
      "z": -3,
      "name": "Rock_Crystal_Purple_Block"
    },
    {
      "x": -11,
      "y": 18,
      "z": -3,
      "name": "Rock_Crystal_Purple_Block"
    },
    {
      "x": -11,
      "y": 19,
      "z": -3,
      "name": "Rock_Crystal_Purple_Block"
    },
    {
      "x": -11,
      "y": 0,
      "z": 6,
      "name": "Rock_Crystal_Purple_Block"
    },
    {
      "x": -11,
      "y": 1,
      "z": 6,
      "name": "Rock_Crystal_Purple_Block"
    },
    {
      "x": -11,
      "y": 2,
      "z": 6,
      "name": "Rock_Crystal_Purple_Block"
    },
    {
      "x": -11,
      "y": 3,
      "z": 6,
      "name": "Rock_Crystal_Purple_Block"
    },
    {
      "x": -11,
      "y": 4,
      "z": 6,
      "name": "Rock_Crystal_Purple_Block"
    },
    {
      "x": -11,
      "y": 5,
      "z": 6,
      "name": "Rock_Crystal_Purple_Block"
    },
    {
      "x": -11,
      "y": 6,
      "z": 6,
      "name": "Rock_Crystal_Purple_Block"
    },
    {
      "x": -11,
      "y": 7,
      "z": 6,
      "name": "Rock_Crystal_Purple_Block"
    },
    {
      "x": -11,
      "y": 8,
      "z": 6,
      "name": "Rock_Crystal_Purple_Block"
    },
    {
      "x": -11,
      "y": 9,
      "z": 6,
      "name": "Rock_Crystal_Purple_Block"
    },
    {
      "x": -11,
      "y": 10,
      "z": 6,
      "name": "Rock_Crystal_Purple_Block"
    },
    {
      "x": -11,
      "y": 11,
      "z": 6,
      "name": "Rock_Crystal_Purple_Block"
    },
    {
      "x": -11,
      "y": 12,
      "z": 6,
      "name": "Rock_Crystal_Purple_Block"
    },
    {
      "x": -11,
      "y": 13,
      "z": 6,
      "name": "Rock_Crystal_Purple_Block"
    },
    {
      "x": -11,
      "y": 14,
      "z": 6,
      "name": "Rock_Crystal_Purple_Block"
    },
    {
      "x": -11,
      "y": 15,
      "z": 6,
      "name": "Rock_Crystal_Purple_Block"
    },
    {
      "x": -11,
      "y": 16,
      "z": 6,
      "name": "Rock_Crystal_Purple_Block"
    },
    {
      "x": -11,
      "y": 17,
      "z": 6,
      "name": "Rock_Crystal_Purple_Block"
    },
    {
      "x": -11,
      "y": 18,
      "z": 6,
      "name": "Rock_Crystal_Purple_Block"
    },
    {
      "x": -11,
      "y": 19,
      "z": 6,
      "name": "Rock_Crystal_Purple_Block"
    },
    {
      "x": -10,
      "y": 0,
      "z": -10,
      "name": "Rock_Crystal_Purple_Block"
    },
    {
      "x": -10,
      "y": 1,
      "z": -10,
      "name": "Rock_Crystal_Purple_Block"
    },
    {
      "x": -10,
      "y": 2,
      "z": -10,
      "name": "Rock_Crystal_Purple_Block"
    },
    {
      "x": -10,
      "y": 3,
      "z": -10,
      "name": "Rock_Crystal_Purple_Block"
    },
    {
      "x": -10,
      "y": 4,
      "z": -10,
      "name": "Rock_Crystal_Purple_Block"
    },
    {
      "x": -10,
      "y": 5,
      "z": -10,
      "name": "Rock_Crystal_Purple_Block"
    },
    {
      "x": -10,
      "y": 6,
      "z": -10,
      "name": "Rock_Crystal_Purple_Block"
    },
    {
      "x": -10,
      "y": 7,
      "z": -10,
      "name": "Rock_Crystal_Purple_Block"
    },
    {
      "x": -10,
      "y": 8,
      "z": -10,
      "name": "Rock_Crystal_Purple_Block"
    },
    {
      "x": -10,
      "y": 9,
      "z": -10,
      "name": "Rock_Crystal_Purple_Block"
    },
    {
      "x": -10,
      "y": 10,
      "z": -10,
      "name": "Rock_Crystal_Purple_Block"
    },
    {
      "x": -10,
      "y": 11,
      "z": -10,
      "name": "Rock_Crystal_Purple_Block"
    },
    {
      "x": -10,
      "y": 12,
      "z": -10,
      "name": "Rock_Crystal_Purple_Block"
    },
    {
      "x": -10,
      "y": 13,
      "z": -10,
      "name": "Rock_Crystal_Purple_Block"
    },
    {
      "x": -10,
      "y": 14,
      "z": -10,
      "name": "Rock_Crystal_Purple_Block"
    },
    {
      "x": -10,
      "y": 15,
      "z": -10,
      "name": "Rock_Crystal_Purple_Block"
    },
    {
      "x": -10,
      "y": 16,
      "z": -10,
      "name": "Rock_Crystal_Purple_Block"
    },
    {
      "x": -10,
      "y": 17,
      "z": -10,
      "name": "Rock_Crystal_Purple_Block"
    },
    {
      "x": -10,
      "y": 18,
      "z": -10,
      "name": "Rock_Crystal_Purple_Block"
    },
    {
      "x": -10,
      "y": 19,
      "z": -10,
      "name": "Rock_Crystal_Purple_Block"
    },
    {
      "x": -10,
      "y": 0,
      "z": -9,
      "name": "Rock_Crystal_Purple_Block"
    },
    {
      "x": -10,
      "y": 1,
      "z": -9,
      "name": "Rock_Crystal_Purple_Block"
    },
    {
      "x": -10,
      "y": 2,
      "z": -9,
      "name": "Rock_Crystal_Purple_Block"
    },
    {
      "x": -10,
      "y": 3,
      "z": -9,
      "name": "Rock_Crystal_Purple_Block"
    },
    {
      "x": -10,
      "y": 4,
      "z": -9,
      "name": "Rock_Crystal_Purple_Block"
    },
    {
      "x": -10,
      "y": 5,
      "z": -9,
      "name": "Rock_Crystal_Purple_Block"
    },
    {
      "x": -10,
      "y": 6,
      "z": -9,
      "name": "Rock_Crystal_Purple_Block"
    },
    {
      "x": -10,
      "y": 7,
      "z": -9,
      "name": "Rock_Crystal_Purple_Block"
    },
    {
      "x": -10,
      "y": 8,
      "z": -9,
      "name": "Rock_Crystal_Purple_Block"
    },
    {
      "x": -10,
      "y": 9,
      "z": -9,
      "name": "Rock_Crystal_Purple_Block"
    },
    {
      "x": -10,
      "y": 10,
      "z": -9,
      "name": "Rock_Crystal_Purple_Block"
    },
    {
      "x": -10,
      "y": 11,
      "z": -9,
      "name": "Rock_Crystal_Purple_Block"
    },
    {
      "x": -10,
      "y": 12,
      "z": -9,
      "name": "Rock_Crystal_Purple_Block"
    },
    {
      "x": -10,
      "y": 13,
      "z": -9,
      "name": "Rock_Crystal_Purple_Block"
    },
    {
      "x": -10,
      "y": 14,
      "z": -9,
      "name": "Rock_Crystal_Purple_Block"
    },
    {
      "x": -10,
      "y": 15,
      "z": -9,
      "name": "Rock_Crystal_Purple_Block"
    },
    {
      "x": -10,
      "y": 16,
      "z": -9,
      "name": "Rock_Crystal_Purple_Block"
    },
    {
      "x": -10,
      "y": 17,
      "z": -9,
      "name": "Rock_Crystal_Purple_Block"
    },
    {
      "x": -10,
      "y": 18,
      "z": -9,
      "name": "Rock_Crystal_Purple_Block"
    },
    {
      "x": -10,
      "y": 19,
      "z": -9,
      "name": "Rock_Crystal_Purple_Block"
    },
    {
      "x": -10,
      "y": 0,
      "z": -8,
      "name": "Rock_Crystal_Purple_Block"
    },
    {
      "x": -10,
      "y": 1,
      "z": -8,
      "name": "Rock_Crystal_Purple_Block"
    },
    {
      "x": -10,
      "y": 2,
      "z": -8,
      "name": "Rock_Crystal_Purple_Block"
    },
    {
      "x": -10,
      "y": 3,
      "z": -8,
      "name": "Rock_Crystal_Purple_Block"
    },
    {
      "x": -10,
      "y": 4,
      "z": -8,
      "name": "Rock_Crystal_Purple_Block"
    },
    {
      "x": -10,
      "y": 5,
      "z": -8,
      "name": "Rock_Crystal_Purple_Block"
    },
    {
      "x": -10,
      "y": 6,
      "z": -8,
      "name": "Rock_Crystal_Purple_Block"
    },
    {
      "x": -10,
      "y": 7,
      "z": -8,
      "name": "Rock_Crystal_Purple_Block"
    },
    {
      "x": -10,
      "y": 8,
      "z": -8,
      "name": "Rock_Crystal_Purple_Block"
    },
    {
      "x": -10,
      "y": 9,
      "z": -8,
      "name": "Rock_Crystal_Purple_Block"
    },
    {
      "x": -10,
      "y": 10,
      "z": -8,
      "name": "Rock_Crystal_Purple_Block"
    },
    {
      "x": -10,
      "y": 11,
      "z": -8,
      "name": "Rock_Crystal_Purple_Block"
    },
    {
      "x": -10,
      "y": 12,
      "z": -8,
      "name": "Rock_Crystal_Purple_Block"
    },
    {
      "x": -10,
      "y": 13,
      "z": -8,
      "name": "Rock_Crystal_Purple_Block"
    },
    {
      "x": -10,
      "y": 14,
      "z": -8,
      "name": "Rock_Crystal_Purple_Block"
    },
    {
      "x": -10,
      "y": 15,
      "z": -8,
      "name": "Rock_Crystal_Purple_Block"
    },
    {
      "x": -10,
      "y": 16,
      "z": -8,
      "name": "Rock_Crystal_Purple_Block"
    },
    {
      "x": -10,
      "y": 17,
      "z": -8,
      "name": "Rock_Crystal_Purple_Block"
    },
    {
      "x": -10,
      "y": 18,
      "z": -8,
      "name": "Rock_Crystal_Purple_Block"
    },
    {
      "x": -10,
      "y": 19,
      "z": -8,
      "name": "Rock_Crystal_Purple_Block"
    },
    {
      "x": -10,
      "y": 0,
      "z": -5,
      "name": "Rock_Crystal_Purple_Block"
    },
    {
      "x": -10,
      "y": 1,
      "z": -5,
      "name": "Rock_Crystal_Purple_Block"
    },
    {
      "x": -10,
      "y": 2,
      "z": -5,
      "name": "Rock_Crystal_Purple_Block"
    },
    {
      "x": -10,
      "y": 3,
      "z": -5,
      "name": "Rock_Crystal_Purple_Block"
    },
    {
      "x": -10,
      "y": 4,
      "z": -5,
      "name": "Rock_Crystal_Purple_Block"
    },
    {
      "x": -10,
      "y": 5,
      "z": -5,
      "name": "Rock_Crystal_Purple_Block"
    },
    {
      "x": -10,
      "y": 6,
      "z": -5,
      "name": "Rock_Crystal_Purple_Block"
    },
    {
      "x": -10,
      "y": 7,
      "z": -5,
      "name": "Rock_Crystal_Purple_Block"
    },
    {
      "x": -10,
      "y": 8,
      "z": -5,
      "name": "Rock_Crystal_Purple_Block"
    },
    {
      "x": -10,
      "y": 9,
      "z": -5,
      "name": "Rock_Crystal_Purple_Block"
    },
    {
      "x": -10,
      "y": 10,
      "z": -5,
      "name": "Rock_Crystal_Purple_Block"
    },
    {
      "x": -10,
      "y": 11,
      "z": -5,
      "name": "Rock_Crystal_Purple_Block"
    },
    {
      "x": -10,
      "y": 12,
      "z": -5,
      "name": "Rock_Crystal_Purple_Block"
    },
    {
      "x": -10,
      "y": 13,
      "z": -5,
      "name": "Rock_Crystal_Purple_Block"
    },
    {
      "x": -10,
      "y": 14,
      "z": -5,
      "name": "Rock_Crystal_Purple_Block"
    },
    {
      "x": -10,
      "y": 15,
      "z": -5,
      "name": "Rock_Crystal_Purple_Block"
    },
    {
      "x": -10,
      "y": 16,
      "z": -5,
      "name": "Rock_Crystal_Purple_Block"
    },
    {
      "x": -10,
      "y": 17,
      "z": -5,
      "name": "Rock_Crystal_Purple_Block"
    },
    {
      "x": -10,
      "y": 18,
      "z": -5,
      "name": "Rock_Crystal_Purple_Block"
    },
    {
      "x": -10,
      "y": 19,
      "z": -5,
      "name": "Rock_Crystal_Purple_Block"
    },
    {
      "x": -10,
      "y": 0,
      "z": 5,
      "name": "Rock_Crystal_Purple_Block"
    },
    {
      "x": -10,
      "y": 1,
      "z": 5,
      "name": "Rock_Crystal_Purple_Block"
    },
    {
      "x": -10,
      "y": 2,
      "z": 5,
      "name": "Rock_Crystal_Purple_Block"
    },
    {
      "x": -10,
      "y": 3,
      "z": 5,
      "name": "Rock_Crystal_Purple_Block"
    },
    {
      "x": -10,
      "y": 4,
      "z": 5,
      "name": "Rock_Crystal_Purple_Block"
    },
    {
      "x": -10,
      "y": 5,
      "z": 5,
      "name": "Rock_Crystal_Purple_Block"
    },
    {
      "x": -10,
      "y": 6,
      "z": 5,
      "name": "Rock_Crystal_Purple_Block"
    },
    {
      "x": -10,
      "y": 7,
      "z": 5,
      "name": "Rock_Crystal_Purple_Block"
    },
    {
      "x": -10,
      "y": 8,
      "z": 5,
      "name": "Rock_Crystal_Purple_Block"
    },
    {
      "x": -10,
      "y": 9,
      "z": 5,
      "name": "Rock_Crystal_Purple_Block"
    },
    {
      "x": -10,
      "y": 10,
      "z": 5,
      "name": "Rock_Crystal_Purple_Block"
    },
    {
      "x": -10,
      "y": 11,
      "z": 5,
      "name": "Rock_Crystal_Purple_Block"
    },
    {
      "x": -10,
      "y": 12,
      "z": 5,
      "name": "Rock_Crystal_Purple_Block"
    },
    {
      "x": -10,
      "y": 13,
      "z": 5,
      "name": "Rock_Crystal_Purple_Block"
    },
    {
      "x": -10,
      "y": 14,
      "z": 5,
      "name": "Rock_Crystal_Purple_Block"
    },
    {
      "x": -10,
      "y": 15,
      "z": 5,
      "name": "Rock_Crystal_Purple_Block"
    },
    {
      "x": -10,
      "y": 16,
      "z": 5,
      "name": "Rock_Crystal_Purple_Block"
    },
    {
      "x": -10,
      "y": 17,
      "z": 5,
      "name": "Rock_Crystal_Purple_Block"
    },
    {
      "x": -10,
      "y": 18,
      "z": 5,
      "name": "Rock_Crystal_Purple_Block"
    },
    {
      "x": -10,
      "y": 19,
      "z": 5,
      "name": "Rock_Crystal_Purple_Block"
    },
    {
      "x": -10,
      "y": 0,
      "z": 6,
      "name": "Rock_Crystal_Purple_Block"
    },
    {
      "x": -10,
      "y": 1,
      "z": 6,
      "name": "Rock_Crystal_Purple_Block"
    },
    {
      "x": -10,
      "y": 2,
      "z": 6,
      "name": "Rock_Crystal_Purple_Block"
    },
    {
      "x": -10,
      "y": 3,
      "z": 6,
      "name": "Rock_Crystal_Purple_Block"
    },
    {
      "x": -10,
      "y": 4,
      "z": 6,
      "name": "Rock_Crystal_Purple_Block"
    },
    {
      "x": -10,
      "y": 5,
      "z": 6,
      "name": "Rock_Crystal_Purple_Block"
    },
    {
      "x": -10,
      "y": 6,
      "z": 6,
      "name": "Rock_Crystal_Purple_Block"
    },
    {
      "x": -10,
      "y": 7,
      "z": 6,
      "name": "Rock_Crystal_Purple_Block"
    },
    {
      "x": -10,
      "y": 8,
      "z": 6,
      "name": "Rock_Crystal_Purple_Block"
    },
    {
      "x": -10,
      "y": 9,
      "z": 6,
      "name": "Rock_Crystal_Purple_Block"
    },
    {
      "x": -10,
      "y": 10,
      "z": 6,
      "name": "Rock_Crystal_Purple_Block"
    },
    {
      "x": -10,
      "y": 11,
      "z": 6,
      "name": "Rock_Crystal_Purple_Block"
    },
    {
      "x": -10,
      "y": 12,
      "z": 6,
      "name": "Rock_Crystal_Purple_Block"
    },
    {
      "x": -10,
      "y": 13,
      "z": 6,
      "name": "Rock_Crystal_Purple_Block"
    },
    {
      "x": -10,
      "y": 14,
      "z": 6,
      "name": "Rock_Crystal_Purple_Block"
    },
    {
      "x": -10,
      "y": 15,
      "z": 6,
      "name": "Rock_Crystal_Purple_Block"
    },
    {
      "x": -10,
      "y": 16,
      "z": 6,
      "name": "Rock_Crystal_Purple_Block"
    },
    {
      "x": -10,
      "y": 17,
      "z": 6,
      "name": "Rock_Crystal_Purple_Block"
    },
    {
      "x": -10,
      "y": 18,
      "z": 6,
      "name": "Rock_Crystal_Purple_Block"
    },
    {
      "x": -10,
      "y": 19,
      "z": 6,
      "name": "Rock_Crystal_Purple_Block"
    },
    {
      "x": -9,
      "y": 0,
      "z": -8,
      "name": "Rock_Crystal_Purple_Block"
    },
    {
      "x": -9,
      "y": 1,
      "z": -8,
      "name": "Rock_Crystal_Purple_Block"
    },
    {
      "x": -9,
      "y": 2,
      "z": -8,
      "name": "Rock_Crystal_Purple_Block"
    },
    {
      "x": -9,
      "y": 3,
      "z": -8,
      "name": "Rock_Crystal_Purple_Block"
    },
    {
      "x": -9,
      "y": 4,
      "z": -8,
      "name": "Rock_Crystal_Purple_Block"
    },
    {
      "x": -9,
      "y": 5,
      "z": -8,
      "name": "Rock_Crystal_Purple_Block"
    },
    {
      "x": -9,
      "y": 6,
      "z": -8,
      "name": "Rock_Crystal_Purple_Block"
    },
    {
      "x": -9,
      "y": 7,
      "z": -8,
      "name": "Rock_Crystal_Purple_Block"
    },
    {
      "x": -9,
      "y": 8,
      "z": -8,
      "name": "Rock_Crystal_Purple_Block"
    },
    {
      "x": -9,
      "y": 9,
      "z": -8,
      "name": "Rock_Crystal_Purple_Block"
    },
    {
      "x": -9,
      "y": 10,
      "z": -8,
      "name": "Rock_Crystal_Purple_Block"
    },
    {
      "x": -9,
      "y": 11,
      "z": -8,
      "name": "Rock_Crystal_Purple_Block"
    },
    {
      "x": -9,
      "y": 12,
      "z": -8,
      "name": "Rock_Crystal_Purple_Block"
    },
    {
      "x": -9,
      "y": 13,
      "z": -8,
      "name": "Rock_Crystal_Purple_Block"
    },
    {
      "x": -9,
      "y": 14,
      "z": -8,
      "name": "Rock_Crystal_Purple_Block"
    },
    {
      "x": -9,
      "y": 15,
      "z": -8,
      "name": "Rock_Crystal_Purple_Block"
    },
    {
      "x": -9,
      "y": 16,
      "z": -8,
      "name": "Rock_Crystal_Purple_Block"
    },
    {
      "x": -9,
      "y": 17,
      "z": -8,
      "name": "Rock_Crystal_Purple_Block"
    },
    {
      "x": -9,
      "y": 18,
      "z": -8,
      "name": "Rock_Crystal_Purple_Block"
    },
    {
      "x": -9,
      "y": 19,
      "z": -8,
      "name": "Rock_Crystal_Purple_Block"
    },
    {
      "x": -9,
      "y": 0,
      "z": -7,
      "name": "Rock_Crystal_Purple_Block"
    },
    {
      "x": -9,
      "y": 1,
      "z": -7,
      "name": "Rock_Crystal_Purple_Block"
    },
    {
      "x": -9,
      "y": 2,
      "z": -7,
      "name": "Rock_Crystal_Purple_Block"
    },
    {
      "x": -9,
      "y": 3,
      "z": -7,
      "name": "Rock_Crystal_Purple_Block"
    },
    {
      "x": -9,
      "y": 4,
      "z": -7,
      "name": "Rock_Crystal_Purple_Block"
    },
    {
      "x": -9,
      "y": 5,
      "z": -7,
      "name": "Rock_Crystal_Purple_Block"
    },
    {
      "x": -9,
      "y": 6,
      "z": -7,
      "name": "Rock_Crystal_Purple_Block"
    },
    {
      "x": -9,
      "y": 7,
      "z": -7,
      "name": "Rock_Crystal_Purple_Block"
    },
    {
      "x": -9,
      "y": 8,
      "z": -7,
      "name": "Rock_Crystal_Purple_Block"
    },
    {
      "x": -9,
      "y": 9,
      "z": -7,
      "name": "Rock_Crystal_Purple_Block"
    },
    {
      "x": -9,
      "y": 10,
      "z": -7,
      "name": "Rock_Crystal_Purple_Block"
    },
    {
      "x": -9,
      "y": 11,
      "z": -7,
      "name": "Rock_Crystal_Purple_Block"
    },
    {
      "x": -9,
      "y": 12,
      "z": -7,
      "name": "Rock_Crystal_Purple_Block"
    },
    {
      "x": -9,
      "y": 13,
      "z": -7,
      "name": "Rock_Crystal_Purple_Block"
    },
    {
      "x": -9,
      "y": 14,
      "z": -7,
      "name": "Rock_Crystal_Purple_Block"
    },
    {
      "x": -9,
      "y": 15,
      "z": -7,
      "name": "Rock_Crystal_Purple_Block"
    },
    {
      "x": -9,
      "y": 16,
      "z": -7,
      "name": "Rock_Crystal_Purple_Block"
    },
    {
      "x": -9,
      "y": 17,
      "z": -7,
      "name": "Rock_Crystal_Purple_Block"
    },
    {
      "x": -9,
      "y": 18,
      "z": -7,
      "name": "Rock_Crystal_Purple_Block"
    },
    {
      "x": -9,
      "y": 19,
      "z": -7,
      "name": "Rock_Crystal_Purple_Block"
    },
    {
      "x": -9,
      "y": 0,
      "z": -6,
      "name": "Rock_Crystal_Purple_Block"
    },
    {
      "x": -9,
      "y": 1,
      "z": -6,
      "name": "Rock_Crystal_Purple_Block"
    },
    {
      "x": -9,
      "y": 2,
      "z": -6,
      "name": "Rock_Crystal_Purple_Block"
    },
    {
      "x": -9,
      "y": 3,
      "z": -6,
      "name": "Rock_Crystal_Purple_Block"
    },
    {
      "x": -9,
      "y": 4,
      "z": -6,
      "name": "Rock_Crystal_Purple_Block"
    },
    {
      "x": -9,
      "y": 5,
      "z": -6,
      "name": "Rock_Crystal_Purple_Block"
    },
    {
      "x": -9,
      "y": 6,
      "z": -6,
      "name": "Rock_Crystal_Purple_Block"
    },
    {
      "x": -9,
      "y": 7,
      "z": -6,
      "name": "Rock_Crystal_Purple_Block"
    },
    {
      "x": -9,
      "y": 8,
      "z": -6,
      "name": "Rock_Crystal_Purple_Block"
    },
    {
      "x": -9,
      "y": 9,
      "z": -6,
      "name": "Rock_Crystal_Purple_Block"
    },
    {
      "x": -9,
      "y": 10,
      "z": -6,
      "name": "Rock_Crystal_Purple_Block"
    },
    {
      "x": -9,
      "y": 11,
      "z": -6,
      "name": "Rock_Crystal_Purple_Block"
    },
    {
      "x": -9,
      "y": 12,
      "z": -6,
      "name": "Rock_Crystal_Purple_Block"
    },
    {
      "x": -9,
      "y": 13,
      "z": -6,
      "name": "Rock_Crystal_Purple_Block"
    },
    {
      "x": -9,
      "y": 14,
      "z": -6,
      "name": "Rock_Crystal_Purple_Block"
    },
    {
      "x": -9,
      "y": 15,
      "z": -6,
      "name": "Rock_Crystal_Purple_Block"
    },
    {
      "x": -9,
      "y": 16,
      "z": -6,
      "name": "Rock_Crystal_Purple_Block"
    },
    {
      "x": -9,
      "y": 17,
      "z": -6,
      "name": "Rock_Crystal_Purple_Block"
    },
    {
      "x": -9,
      "y": 18,
      "z": -6,
      "name": "Rock_Crystal_Purple_Block"
    },
    {
      "x": -9,
      "y": 19,
      "z": -6,
      "name": "Rock_Crystal_Purple_Block"
    },
    {
      "x": -9,
      "y": 0,
      "z": -5,
      "name": "Rock_Crystal_Purple_Block"
    },
    {
      "x": -9,
      "y": 1,
      "z": -5,
      "name": "Rock_Crystal_Purple_Block"
    },
    {
      "x": -9,
      "y": 2,
      "z": -5,
      "name": "Rock_Crystal_Purple_Block"
    },
    {
      "x": -9,
      "y": 3,
      "z": -5,
      "name": "Rock_Crystal_Purple_Block"
    },
    {
      "x": -9,
      "y": 4,
      "z": -5,
      "name": "Rock_Crystal_Purple_Block"
    },
    {
      "x": -9,
      "y": 5,
      "z": -5,
      "name": "Rock_Crystal_Purple_Block"
    },
    {
      "x": -9,
      "y": 6,
      "z": -5,
      "name": "Rock_Crystal_Purple_Block"
    },
    {
      "x": -9,
      "y": 7,
      "z": -5,
      "name": "Rock_Crystal_Purple_Block"
    },
    {
      "x": -9,
      "y": 8,
      "z": -5,
      "name": "Rock_Crystal_Purple_Block"
    },
    {
      "x": -9,
      "y": 9,
      "z": -5,
      "name": "Rock_Crystal_Purple_Block"
    },
    {
      "x": -9,
      "y": 10,
      "z": -5,
      "name": "Rock_Crystal_Purple_Block"
    },
    {
      "x": -9,
      "y": 11,
      "z": -5,
      "name": "Rock_Crystal_Purple_Block"
    },
    {
      "x": -9,
      "y": 12,
      "z": -5,
      "name": "Rock_Crystal_Purple_Block"
    },
    {
      "x": -9,
      "y": 13,
      "z": -5,
      "name": "Rock_Crystal_Purple_Block"
    },
    {
      "x": -9,
      "y": 14,
      "z": -5,
      "name": "Rock_Crystal_Purple_Block"
    },
    {
      "x": -9,
      "y": 15,
      "z": -5,
      "name": "Rock_Crystal_Purple_Block"
    },
    {
      "x": -9,
      "y": 16,
      "z": -5,
      "name": "Rock_Crystal_Purple_Block"
    },
    {
      "x": -9,
      "y": 17,
      "z": -5,
      "name": "Rock_Crystal_Purple_Block"
    },
    {
      "x": -9,
      "y": 18,
      "z": -5,
      "name": "Rock_Crystal_Purple_Block"
    },
    {
      "x": -9,
      "y": 19,
      "z": -5,
      "name": "Rock_Crystal_Purple_Block"
    },
    {
      "x": -9,
      "y": 0,
      "z": -4,
      "name": "Rock_Crystal_Purple_Block"
    },
    {
      "x": -9,
      "y": 1,
      "z": -4,
      "name": "Rock_Crystal_Purple_Block"
    },
    {
      "x": -9,
      "y": 2,
      "z": -4,
      "name": "Rock_Crystal_Purple_Block"
    },
    {
      "x": -9,
      "y": 3,
      "z": -4,
      "name": "Rock_Crystal_Purple_Block"
    },
    {
      "x": -9,
      "y": 4,
      "z": -4,
      "name": "Rock_Crystal_Purple_Block"
    },
    {
      "x": -9,
      "y": 5,
      "z": -4,
      "name": "Rock_Crystal_Purple_Block"
    },
    {
      "x": -9,
      "y": 6,
      "z": -4,
      "name": "Rock_Crystal_Purple_Block"
    },
    {
      "x": -9,
      "y": 7,
      "z": -4,
      "name": "Rock_Crystal_Purple_Block"
    },
    {
      "x": -9,
      "y": 8,
      "z": -4,
      "name": "Rock_Crystal_Purple_Block"
    },
    {
      "x": -9,
      "y": 9,
      "z": -4,
      "name": "Rock_Crystal_Purple_Block"
    },
    {
      "x": -9,
      "y": 10,
      "z": -4,
      "name": "Rock_Crystal_Purple_Block"
    },
    {
      "x": -9,
      "y": 11,
      "z": -4,
      "name": "Rock_Crystal_Purple_Block"
    },
    {
      "x": -9,
      "y": 12,
      "z": -4,
      "name": "Rock_Crystal_Purple_Block"
    },
    {
      "x": -9,
      "y": 13,
      "z": -4,
      "name": "Rock_Crystal_Purple_Block"
    },
    {
      "x": -9,
      "y": 14,
      "z": -4,
      "name": "Rock_Crystal_Purple_Block"
    },
    {
      "x": -9,
      "y": 15,
      "z": -4,
      "name": "Rock_Crystal_Purple_Block"
    },
    {
      "x": -9,
      "y": 16,
      "z": -4,
      "name": "Rock_Crystal_Purple_Block"
    },
    {
      "x": -9,
      "y": 17,
      "z": -4,
      "name": "Rock_Crystal_Purple_Block"
    },
    {
      "x": -9,
      "y": 18,
      "z": -4,
      "name": "Rock_Crystal_Purple_Block"
    },
    {
      "x": -9,
      "y": 19,
      "z": -4,
      "name": "Rock_Crystal_Purple_Block"
    },
    {
      "x": -9,
      "y": 0,
      "z": -3,
      "name": "Rock_Crystal_Purple_Block"
    },
    {
      "x": -9,
      "y": 1,
      "z": -3,
      "name": "Rock_Crystal_Purple_Block"
    },
    {
      "x": -9,
      "y": 2,
      "z": -3,
      "name": "Rock_Crystal_Purple_Block"
    },
    {
      "x": -9,
      "y": 3,
      "z": -3,
      "name": "Rock_Crystal_Purple_Block"
    },
    {
      "x": -9,
      "y": 4,
      "z": -3,
      "name": "Rock_Crystal_Purple_Block"
    },
    {
      "x": -9,
      "y": 5,
      "z": -3,
      "name": "Rock_Crystal_Purple_Block"
    },
    {
      "x": -9,
      "y": 6,
      "z": -3,
      "name": "Rock_Crystal_Purple_Block"
    },
    {
      "x": -9,
      "y": 7,
      "z": -3,
      "name": "Rock_Crystal_Purple_Block"
    },
    {
      "x": -9,
      "y": 8,
      "z": -3,
      "name": "Rock_Crystal_Purple_Block"
    },
    {
      "x": -9,
      "y": 9,
      "z": -3,
      "name": "Rock_Crystal_Purple_Block"
    },
    {
      "x": -9,
      "y": 10,
      "z": -3,
      "name": "Rock_Crystal_Purple_Block"
    },
    {
      "x": -9,
      "y": 11,
      "z": -3,
      "name": "Rock_Crystal_Purple_Block"
    },
    {
      "x": -9,
      "y": 12,
      "z": -3,
      "name": "Rock_Crystal_Purple_Block"
    },
    {
      "x": -9,
      "y": 13,
      "z": -3,
      "name": "Rock_Crystal_Purple_Block"
    },
    {
      "x": -9,
      "y": 14,
      "z": -3,
      "name": "Rock_Crystal_Purple_Block"
    },
    {
      "x": -9,
      "y": 15,
      "z": -3,
      "name": "Rock_Crystal_Purple_Block"
    },
    {
      "x": -9,
      "y": 16,
      "z": -3,
      "name": "Rock_Crystal_Purple_Block"
    },
    {
      "x": -9,
      "y": 17,
      "z": -3,
      "name": "Rock_Crystal_Purple_Block"
    },
    {
      "x": -9,
      "y": 18,
      "z": -3,
      "name": "Rock_Crystal_Purple_Block"
    },
    {
      "x": -9,
      "y": 19,
      "z": -3,
      "name": "Rock_Crystal_Purple_Block"
    },
    {
      "x": -9,
      "y": 0,
      "z": 5,
      "name": "Rock_Crystal_Purple_Block"
    },
    {
      "x": -9,
      "y": 1,
      "z": 5,
      "name": "Rock_Crystal_Purple_Block"
    },
    {
      "x": -9,
      "y": 2,
      "z": 5,
      "name": "Rock_Crystal_Purple_Block"
    },
    {
      "x": -9,
      "y": 3,
      "z": 5,
      "name": "Rock_Crystal_Purple_Block"
    },
    {
      "x": -9,
      "y": 4,
      "z": 5,
      "name": "Rock_Crystal_Purple_Block"
    },
    {
      "x": -9,
      "y": 5,
      "z": 5,
      "name": "Rock_Crystal_Purple_Block"
    },
    {
      "x": -9,
      "y": 6,
      "z": 5,
      "name": "Rock_Crystal_Purple_Block"
    },
    {
      "x": -9,
      "y": 7,
      "z": 5,
      "name": "Rock_Crystal_Purple_Block"
    },
    {
      "x": -9,
      "y": 8,
      "z": 5,
      "name": "Rock_Crystal_Purple_Block"
    },
    {
      "x": -9,
      "y": 9,
      "z": 5,
      "name": "Rock_Crystal_Purple_Block"
    },
    {
      "x": -9,
      "y": 10,
      "z": 5,
      "name": "Rock_Crystal_Purple_Block"
    },
    {
      "x": -9,
      "y": 11,
      "z": 5,
      "name": "Rock_Crystal_Purple_Block"
    },
    {
      "x": -9,
      "y": 12,
      "z": 5,
      "name": "Rock_Crystal_Purple_Block"
    },
    {
      "x": -9,
      "y": 13,
      "z": 5,
      "name": "Rock_Crystal_Purple_Block"
    },
    {
      "x": -9,
      "y": 14,
      "z": 5,
      "name": "Rock_Crystal_Purple_Block"
    },
    {
      "x": -9,
      "y": 15,
      "z": 5,
      "name": "Rock_Crystal_Purple_Block"
    },
    {
      "x": -9,
      "y": 16,
      "z": 5,
      "name": "Rock_Crystal_Purple_Block"
    },
    {
      "x": -9,
      "y": 17,
      "z": 5,
      "name": "Rock_Crystal_Purple_Block"
    },
    {
      "x": -9,
      "y": 18,
      "z": 5,
      "name": "Rock_Crystal_Purple_Block"
    },
    {
      "x": -9,
      "y": 19,
      "z": 5,
      "name": "Rock_Crystal_Purple_Block"
    },
    {
      "x": -8,
      "y": 0,
      "z": -3,
      "name": "Rock_Crystal_Purple_Block"
    },
    {
      "x": -8,
      "y": 1,
      "z": -3,
      "name": "Rock_Crystal_Purple_Block"
    },
    {
      "x": -8,
      "y": 2,
      "z": -3,
      "name": "Rock_Crystal_Purple_Block"
    },
    {
      "x": -8,
      "y": 3,
      "z": -3,
      "name": "Rock_Crystal_Purple_Block"
    },
    {
      "x": -8,
      "y": 4,
      "z": -3,
      "name": "Rock_Crystal_Purple_Block"
    },
    {
      "x": -8,
      "y": 5,
      "z": -3,
      "name": "Rock_Crystal_Purple_Block"
    },
    {
      "x": -8,
      "y": 6,
      "z": -3,
      "name": "Rock_Crystal_Purple_Block"
    },
    {
      "x": -8,
      "y": 7,
      "z": -3,
      "name": "Rock_Crystal_Purple_Block"
    },
    {
      "x": -8,
      "y": 8,
      "z": -3,
      "name": "Rock_Crystal_Purple_Block"
    },
    {
      "x": -8,
      "y": 9,
      "z": -3,
      "name": "Rock_Crystal_Purple_Block"
    },
    {
      "x": -8,
      "y": 10,
      "z": -3,
      "name": "Rock_Crystal_Purple_Block"
    },
    {
      "x": -8,
      "y": 11,
      "z": -3,
      "name": "Rock_Crystal_Purple_Block"
    },
    {
      "x": -8,
      "y": 12,
      "z": -3,
      "name": "Rock_Crystal_Purple_Block"
    },
    {
      "x": -8,
      "y": 13,
      "z": -3,
      "name": "Rock_Crystal_Purple_Block"
    },
    {
      "x": -8,
      "y": 14,
      "z": -3,
      "name": "Rock_Crystal_Purple_Block"
    },
    {
      "x": -8,
      "y": 15,
      "z": -3,
      "name": "Rock_Crystal_Purple_Block"
    },
    {
      "x": -8,
      "y": 16,
      "z": -3,
      "name": "Rock_Crystal_Purple_Block"
    },
    {
      "x": -8,
      "y": 17,
      "z": -3,
      "name": "Rock_Crystal_Purple_Block"
    },
    {
      "x": -8,
      "y": 18,
      "z": -3,
      "name": "Rock_Crystal_Purple_Block"
    },
    {
      "x": -8,
      "y": 19,
      "z": -3,
      "name": "Rock_Crystal_Purple_Block"
    },
    {
      "x": -8,
      "y": 0,
      "z": -2,
      "name": "Rock_Crystal_Purple_Block"
    },
    {
      "x": -8,
      "y": 1,
      "z": -2,
      "name": "Rock_Crystal_Purple_Block"
    },
    {
      "x": -8,
      "y": 2,
      "z": -2,
      "name": "Rock_Crystal_Purple_Block"
    },
    {
      "x": -8,
      "y": 3,
      "z": -2,
      "name": "Rock_Crystal_Purple_Block"
    },
    {
      "x": -8,
      "y": 4,
      "z": -2,
      "name": "Rock_Crystal_Purple_Block"
    },
    {
      "x": -8,
      "y": 5,
      "z": -2,
      "name": "Rock_Crystal_Purple_Block"
    },
    {
      "x": -8,
      "y": 6,
      "z": -2,
      "name": "Rock_Crystal_Purple_Block"
    },
    {
      "x": -8,
      "y": 7,
      "z": -2,
      "name": "Rock_Crystal_Purple_Block"
    },
    {
      "x": -8,
      "y": 8,
      "z": -2,
      "name": "Rock_Crystal_Purple_Block"
    },
    {
      "x": -8,
      "y": 9,
      "z": -2,
      "name": "Rock_Crystal_Purple_Block"
    },
    {
      "x": -8,
      "y": 10,
      "z": -2,
      "name": "Rock_Crystal_Purple_Block"
    },
    {
      "x": -8,
      "y": 11,
      "z": -2,
      "name": "Rock_Crystal_Purple_Block"
    },
    {
      "x": -8,
      "y": 12,
      "z": -2,
      "name": "Rock_Crystal_Purple_Block"
    },
    {
      "x": -8,
      "y": 13,
      "z": -2,
      "name": "Rock_Crystal_Purple_Block"
    },
    {
      "x": -8,
      "y": 14,
      "z": -2,
      "name": "Rock_Crystal_Purple_Block"
    },
    {
      "x": -8,
      "y": 15,
      "z": -2,
      "name": "Rock_Crystal_Purple_Block"
    },
    {
      "x": -8,
      "y": 16,
      "z": -2,
      "name": "Rock_Crystal_Purple_Block"
    },
    {
      "x": -8,
      "y": 17,
      "z": -2,
      "name": "Rock_Crystal_Purple_Block"
    },
    {
      "x": -8,
      "y": 18,
      "z": -2,
      "name": "Rock_Crystal_Purple_Block"
    },
    {
      "x": -8,
      "y": 19,
      "z": -2,
      "name": "Rock_Crystal_Purple_Block"
    },
    {
      "x": -8,
      "y": 0,
      "z": 3,
      "name": "Rock_Crystal_Purple_Block"
    },
    {
      "x": -8,
      "y": 1,
      "z": 3,
      "name": "Rock_Crystal_Purple_Block"
    },
    {
      "x": -8,
      "y": 2,
      "z": 3,
      "name": "Rock_Crystal_Purple_Block"
    },
    {
      "x": -8,
      "y": 3,
      "z": 3,
      "name": "Rock_Crystal_Purple_Block"
    },
    {
      "x": -8,
      "y": 4,
      "z": 3,
      "name": "Rock_Crystal_Purple_Block"
    },
    {
      "x": -8,
      "y": 5,
      "z": 3,
      "name": "Rock_Crystal_Purple_Block"
    },
    {
      "x": -8,
      "y": 6,
      "z": 3,
      "name": "Rock_Crystal_Purple_Block"
    },
    {
      "x": -8,
      "y": 7,
      "z": 3,
      "name": "Rock_Crystal_Purple_Block"
    },
    {
      "x": -8,
      "y": 8,
      "z": 3,
      "name": "Rock_Crystal_Purple_Block"
    },
    {
      "x": -8,
      "y": 9,
      "z": 3,
      "name": "Rock_Crystal_Purple_Block"
    },
    {
      "x": -8,
      "y": 10,
      "z": 3,
      "name": "Rock_Crystal_Purple_Block"
    },
    {
      "x": -8,
      "y": 11,
      "z": 3,
      "name": "Rock_Crystal_Purple_Block"
    },
    {
      "x": -8,
      "y": 12,
      "z": 3,
      "name": "Rock_Crystal_Purple_Block"
    },
    {
      "x": -8,
      "y": 13,
      "z": 3,
      "name": "Rock_Crystal_Purple_Block"
    },
    {
      "x": -8,
      "y": 14,
      "z": 3,
      "name": "Rock_Crystal_Purple_Block"
    },
    {
      "x": -8,
      "y": 15,
      "z": 3,
      "name": "Rock_Crystal_Purple_Block"
    },
    {
      "x": -8,
      "y": 16,
      "z": 3,
      "name": "Rock_Crystal_Purple_Block"
    },
    {
      "x": -8,
      "y": 17,
      "z": 3,
      "name": "Rock_Crystal_Purple_Block"
    },
    {
      "x": -8,
      "y": 18,
      "z": 3,
      "name": "Rock_Crystal_Purple_Block"
    },
    {
      "x": -8,
      "y": 19,
      "z": 3,
      "name": "Rock_Crystal_Purple_Block"
    },
    {
      "x": -8,
      "y": 0,
      "z": 4,
      "name": "Rock_Crystal_Purple_Block"
    },
    {
      "x": -8,
      "y": 1,
      "z": 4,
      "name": "Rock_Crystal_Purple_Block"
    },
    {
      "x": -8,
      "y": 2,
      "z": 4,
      "name": "Rock_Crystal_Purple_Block"
    },
    {
      "x": -8,
      "y": 3,
      "z": 4,
      "name": "Rock_Crystal_Purple_Block"
    },
    {
      "x": -8,
      "y": 4,
      "z": 4,
      "name": "Rock_Crystal_Purple_Block"
    },
    {
      "x": -8,
      "y": 5,
      "z": 4,
      "name": "Rock_Crystal_Purple_Block"
    },
    {
      "x": -8,
      "y": 6,
      "z": 4,
      "name": "Rock_Crystal_Purple_Block"
    },
    {
      "x": -8,
      "y": 7,
      "z": 4,
      "name": "Rock_Crystal_Purple_Block"
    },
    {
      "x": -8,
      "y": 8,
      "z": 4,
      "name": "Rock_Crystal_Purple_Block"
    },
    {
      "x": -8,
      "y": 9,
      "z": 4,
      "name": "Rock_Crystal_Purple_Block"
    },
    {
      "x": -8,
      "y": 10,
      "z": 4,
      "name": "Rock_Crystal_Purple_Block"
    },
    {
      "x": -8,
      "y": 11,
      "z": 4,
      "name": "Rock_Crystal_Purple_Block"
    },
    {
      "x": -8,
      "y": 12,
      "z": 4,
      "name": "Rock_Crystal_Purple_Block"
    },
    {
      "x": -8,
      "y": 13,
      "z": 4,
      "name": "Rock_Crystal_Purple_Block"
    },
    {
      "x": -8,
      "y": 14,
      "z": 4,
      "name": "Rock_Crystal_Purple_Block"
    },
    {
      "x": -8,
      "y": 15,
      "z": 4,
      "name": "Rock_Crystal_Purple_Block"
    },
    {
      "x": -8,
      "y": 16,
      "z": 4,
      "name": "Rock_Crystal_Purple_Block"
    },
    {
      "x": -8,
      "y": 17,
      "z": 4,
      "name": "Rock_Crystal_Purple_Block"
    },
    {
      "x": -8,
      "y": 18,
      "z": 4,
      "name": "Rock_Crystal_Purple_Block"
    },
    {
      "x": -8,
      "y": 19,
      "z": 4,
      "name": "Rock_Crystal_Purple_Block"
    },
    {
      "x": -8,
      "y": 0,
      "z": 5,
      "name": "Rock_Crystal_Purple_Block"
    },
    {
      "x": -8,
      "y": 1,
      "z": 5,
      "name": "Rock_Crystal_Purple_Block"
    },
    {
      "x": -8,
      "y": 2,
      "z": 5,
      "name": "Rock_Crystal_Purple_Block"
    },
    {
      "x": -8,
      "y": 3,
      "z": 5,
      "name": "Rock_Crystal_Purple_Block"
    },
    {
      "x": -8,
      "y": 4,
      "z": 5,
      "name": "Rock_Crystal_Purple_Block"
    },
    {
      "x": -8,
      "y": 5,
      "z": 5,
      "name": "Rock_Crystal_Purple_Block"
    },
    {
      "x": -8,
      "y": 6,
      "z": 5,
      "name": "Rock_Crystal_Purple_Block"
    },
    {
      "x": -8,
      "y": 7,
      "z": 5,
      "name": "Rock_Crystal_Purple_Block"
    },
    {
      "x": -8,
      "y": 8,
      "z": 5,
      "name": "Rock_Crystal_Purple_Block"
    },
    {
      "x": -8,
      "y": 9,
      "z": 5,
      "name": "Rock_Crystal_Purple_Block"
    },
    {
      "x": -8,
      "y": 10,
      "z": 5,
      "name": "Rock_Crystal_Purple_Block"
    },
    {
      "x": -8,
      "y": 11,
      "z": 5,
      "name": "Rock_Crystal_Purple_Block"
    },
    {
      "x": -8,
      "y": 12,
      "z": 5,
      "name": "Rock_Crystal_Purple_Block"
    },
    {
      "x": -8,
      "y": 13,
      "z": 5,
      "name": "Rock_Crystal_Purple_Block"
    },
    {
      "x": -8,
      "y": 14,
      "z": 5,
      "name": "Rock_Crystal_Purple_Block"
    },
    {
      "x": -8,
      "y": 15,
      "z": 5,
      "name": "Rock_Crystal_Purple_Block"
    },
    {
      "x": -8,
      "y": 16,
      "z": 5,
      "name": "Rock_Crystal_Purple_Block"
    },
    {
      "x": -8,
      "y": 17,
      "z": 5,
      "name": "Rock_Crystal_Purple_Block"
    },
    {
      "x": -8,
      "y": 18,
      "z": 5,
      "name": "Rock_Crystal_Purple_Block"
    },
    {
      "x": -8,
      "y": 19,
      "z": 5,
      "name": "Rock_Crystal_Purple_Block"
    },
    {
      "x": -7,
      "y": 0,
      "z": -2,
      "name": "Rock_Crystal_Purple_Block"
    },
    {
      "x": -7,
      "y": 1,
      "z": -2,
      "name": "Rock_Crystal_Purple_Block"
    },
    {
      "x": -7,
      "y": 2,
      "z": -2,
      "name": "Rock_Crystal_Purple_Block"
    },
    {
      "x": -7,
      "y": 3,
      "z": -2,
      "name": "Rock_Crystal_Purple_Block"
    },
    {
      "x": -7,
      "y": 4,
      "z": -2,
      "name": "Rock_Crystal_Purple_Block"
    },
    {
      "x": -7,
      "y": 5,
      "z": -2,
      "name": "Rock_Crystal_Purple_Block"
    },
    {
      "x": -7,
      "y": 6,
      "z": -2,
      "name": "Rock_Crystal_Purple_Block"
    },
    {
      "x": -7,
      "y": 7,
      "z": -2,
      "name": "Rock_Crystal_Purple_Block"
    },
    {
      "x": -7,
      "y": 8,
      "z": -2,
      "name": "Rock_Crystal_Purple_Block"
    },
    {
      "x": -7,
      "y": 9,
      "z": -2,
      "name": "Rock_Crystal_Purple_Block"
    },
    {
      "x": -7,
      "y": 10,
      "z": -2,
      "name": "Rock_Crystal_Purple_Block"
    },
    {
      "x": -7,
      "y": 11,
      "z": -2,
      "name": "Rock_Crystal_Purple_Block"
    },
    {
      "x": -7,
      "y": 12,
      "z": -2,
      "name": "Rock_Crystal_Purple_Block"
    },
    {
      "x": -7,
      "y": 13,
      "z": -2,
      "name": "Rock_Crystal_Purple_Block"
    },
    {
      "x": -7,
      "y": 14,
      "z": -2,
      "name": "Rock_Crystal_Purple_Block"
    },
    {
      "x": -7,
      "y": 15,
      "z": -2,
      "name": "Rock_Crystal_Purple_Block"
    },
    {
      "x": -7,
      "y": 16,
      "z": -2,
      "name": "Rock_Crystal_Purple_Block"
    },
    {
      "x": -7,
      "y": 17,
      "z": -2,
      "name": "Rock_Crystal_Purple_Block"
    },
    {
      "x": -7,
      "y": 18,
      "z": -2,
      "name": "Rock_Crystal_Purple_Block"
    },
    {
      "x": -7,
      "y": 19,
      "z": -2,
      "name": "Rock_Crystal_Purple_Block"
    },
    {
      "x": -7,
      "y": 0,
      "z": 3,
      "name": "Rock_Crystal_Purple_Block"
    },
    {
      "x": -7,
      "y": 1,
      "z": 3,
      "name": "Rock_Crystal_Purple_Block"
    },
    {
      "x": -7,
      "y": 2,
      "z": 3,
      "name": "Rock_Crystal_Purple_Block"
    },
    {
      "x": -7,
      "y": 3,
      "z": 3,
      "name": "Rock_Crystal_Purple_Block"
    },
    {
      "x": -7,
      "y": 4,
      "z": 3,
      "name": "Rock_Crystal_Purple_Block"
    },
    {
      "x": -7,
      "y": 5,
      "z": 3,
      "name": "Rock_Crystal_Purple_Block"
    },
    {
      "x": -7,
      "y": 6,
      "z": 3,
      "name": "Rock_Crystal_Purple_Block"
    },
    {
      "x": -7,
      "y": 7,
      "z": 3,
      "name": "Rock_Crystal_Purple_Block"
    },
    {
      "x": -7,
      "y": 8,
      "z": 3,
      "name": "Rock_Crystal_Purple_Block"
    },
    {
      "x": -7,
      "y": 9,
      "z": 3,
      "name": "Rock_Crystal_Purple_Block"
    },
    {
      "x": -7,
      "y": 10,
      "z": 3,
      "name": "Rock_Crystal_Purple_Block"
    },
    {
      "x": -7,
      "y": 11,
      "z": 3,
      "name": "Rock_Crystal_Purple_Block"
    },
    {
      "x": -7,
      "y": 12,
      "z": 3,
      "name": "Rock_Crystal_Purple_Block"
    },
    {
      "x": -7,
      "y": 13,
      "z": 3,
      "name": "Rock_Crystal_Purple_Block"
    },
    {
      "x": -7,
      "y": 14,
      "z": 3,
      "name": "Rock_Crystal_Purple_Block"
    },
    {
      "x": -7,
      "y": 15,
      "z": 3,
      "name": "Rock_Crystal_Purple_Block"
    },
    {
      "x": -7,
      "y": 16,
      "z": 3,
      "name": "Rock_Crystal_Purple_Block"
    },
    {
      "x": -7,
      "y": 17,
      "z": 3,
      "name": "Rock_Crystal_Purple_Block"
    },
    {
      "x": -7,
      "y": 18,
      "z": 3,
      "name": "Rock_Crystal_Purple_Block"
    },
    {
      "x": -7,
      "y": 19,
      "z": 3,
      "name": "Rock_Crystal_Purple_Block"
    },
    {
      "x": -6,
      "y": 0,
      "z": -12,
      "name": "Rock_Crystal_Purple_Block"
    },
    {
      "x": -6,
      "y": 1,
      "z": -12,
      "name": "Rock_Crystal_Purple_Block"
    },
    {
      "x": -6,
      "y": 2,
      "z": -12,
      "name": "Rock_Crystal_Purple_Block"
    },
    {
      "x": -6,
      "y": 3,
      "z": -12,
      "name": "Rock_Crystal_Purple_Block"
    },
    {
      "x": -6,
      "y": 4,
      "z": -12,
      "name": "Rock_Crystal_Purple_Block"
    },
    {
      "x": -6,
      "y": 5,
      "z": -12,
      "name": "Rock_Crystal_Purple_Block"
    },
    {
      "x": -6,
      "y": 6,
      "z": -12,
      "name": "Rock_Crystal_Purple_Block"
    },
    {
      "x": -6,
      "y": 7,
      "z": -12,
      "name": "Rock_Crystal_Purple_Block"
    },
    {
      "x": -6,
      "y": 8,
      "z": -12,
      "name": "Rock_Crystal_Purple_Block"
    },
    {
      "x": -6,
      "y": 9,
      "z": -12,
      "name": "Rock_Crystal_Purple_Block"
    },
    {
      "x": -6,
      "y": 10,
      "z": -12,
      "name": "Rock_Crystal_Purple_Block"
    },
    {
      "x": -6,
      "y": 11,
      "z": -12,
      "name": "Rock_Crystal_Purple_Block"
    },
    {
      "x": -6,
      "y": 12,
      "z": -12,
      "name": "Rock_Crystal_Purple_Block"
    },
    {
      "x": -6,
      "y": 13,
      "z": -12,
      "name": "Rock_Crystal_Purple_Block"
    },
    {
      "x": -6,
      "y": 14,
      "z": -12,
      "name": "Rock_Crystal_Purple_Block"
    },
    {
      "x": -6,
      "y": 15,
      "z": -12,
      "name": "Rock_Crystal_Purple_Block"
    },
    {
      "x": -6,
      "y": 16,
      "z": -12,
      "name": "Rock_Crystal_Purple_Block"
    },
    {
      "x": -6,
      "y": 17,
      "z": -12,
      "name": "Rock_Crystal_Purple_Block"
    },
    {
      "x": -6,
      "y": 18,
      "z": -12,
      "name": "Rock_Crystal_Purple_Block"
    },
    {
      "x": -6,
      "y": 19,
      "z": -12,
      "name": "Rock_Crystal_Purple_Block"
    },
    {
      "x": -6,
      "y": 0,
      "z": -11,
      "name": "Rock_Crystal_Purple_Block"
    },
    {
      "x": -6,
      "y": 1,
      "z": -11,
      "name": "Rock_Crystal_Purple_Block"
    },
    {
      "x": -6,
      "y": 2,
      "z": -11,
      "name": "Rock_Crystal_Purple_Block"
    },
    {
      "x": -6,
      "y": 3,
      "z": -11,
      "name": "Rock_Crystal_Purple_Block"
    },
    {
      "x": -6,
      "y": 4,
      "z": -11,
      "name": "Rock_Crystal_Purple_Block"
    },
    {
      "x": -6,
      "y": 5,
      "z": -11,
      "name": "Rock_Crystal_Purple_Block"
    },
    {
      "x": -6,
      "y": 6,
      "z": -11,
      "name": "Rock_Crystal_Purple_Block"
    },
    {
      "x": -6,
      "y": 7,
      "z": -11,
      "name": "Rock_Crystal_Purple_Block"
    },
    {
      "x": -6,
      "y": 8,
      "z": -11,
      "name": "Rock_Crystal_Purple_Block"
    },
    {
      "x": -6,
      "y": 9,
      "z": -11,
      "name": "Rock_Crystal_Purple_Block"
    },
    {
      "x": -6,
      "y": 10,
      "z": -11,
      "name": "Rock_Crystal_Purple_Block"
    },
    {
      "x": -6,
      "y": 11,
      "z": -11,
      "name": "Rock_Crystal_Purple_Block"
    },
    {
      "x": -6,
      "y": 12,
      "z": -11,
      "name": "Rock_Crystal_Purple_Block"
    },
    {
      "x": -6,
      "y": 13,
      "z": -11,
      "name": "Rock_Crystal_Purple_Block"
    },
    {
      "x": -6,
      "y": 14,
      "z": -11,
      "name": "Rock_Crystal_Purple_Block"
    },
    {
      "x": -6,
      "y": 15,
      "z": -11,
      "name": "Rock_Crystal_Purple_Block"
    },
    {
      "x": -6,
      "y": 16,
      "z": -11,
      "name": "Rock_Crystal_Purple_Block"
    },
    {
      "x": -6,
      "y": 17,
      "z": -11,
      "name": "Rock_Crystal_Purple_Block"
    },
    {
      "x": -6,
      "y": 18,
      "z": -11,
      "name": "Rock_Crystal_Purple_Block"
    },
    {
      "x": -6,
      "y": 19,
      "z": -11,
      "name": "Rock_Crystal_Purple_Block"
    },
    {
      "x": -6,
      "y": 0,
      "z": -10,
      "name": "Rock_Crystal_Purple_Block"
    },
    {
      "x": -6,
      "y": 1,
      "z": -10,
      "name": "Rock_Crystal_Purple_Block"
    },
    {
      "x": -6,
      "y": 2,
      "z": -10,
      "name": "Rock_Crystal_Purple_Block"
    },
    {
      "x": -6,
      "y": 3,
      "z": -10,
      "name": "Rock_Crystal_Purple_Block"
    },
    {
      "x": -6,
      "y": 4,
      "z": -10,
      "name": "Rock_Crystal_Purple_Block"
    },
    {
      "x": -6,
      "y": 5,
      "z": -10,
      "name": "Rock_Crystal_Purple_Block"
    },
    {
      "x": -6,
      "y": 6,
      "z": -10,
      "name": "Rock_Crystal_Purple_Block"
    },
    {
      "x": -6,
      "y": 7,
      "z": -10,
      "name": "Rock_Crystal_Purple_Block"
    },
    {
      "x": -6,
      "y": 8,
      "z": -10,
      "name": "Rock_Crystal_Purple_Block"
    },
    {
      "x": -6,
      "y": 9,
      "z": -10,
      "name": "Rock_Crystal_Purple_Block"
    },
    {
      "x": -6,
      "y": 10,
      "z": -10,
      "name": "Rock_Crystal_Purple_Block"
    },
    {
      "x": -6,
      "y": 11,
      "z": -10,
      "name": "Rock_Crystal_Purple_Block"
    },
    {
      "x": -6,
      "y": 12,
      "z": -10,
      "name": "Rock_Crystal_Purple_Block"
    },
    {
      "x": -6,
      "y": 13,
      "z": -10,
      "name": "Rock_Crystal_Purple_Block"
    },
    {
      "x": -6,
      "y": 14,
      "z": -10,
      "name": "Rock_Crystal_Purple_Block"
    },
    {
      "x": -6,
      "y": 15,
      "z": -10,
      "name": "Rock_Crystal_Purple_Block"
    },
    {
      "x": -6,
      "y": 16,
      "z": -10,
      "name": "Rock_Crystal_Purple_Block"
    },
    {
      "x": -6,
      "y": 17,
      "z": -10,
      "name": "Rock_Crystal_Purple_Block"
    },
    {
      "x": -6,
      "y": 18,
      "z": -10,
      "name": "Rock_Crystal_Purple_Block"
    },
    {
      "x": -6,
      "y": 19,
      "z": -10,
      "name": "Rock_Crystal_Purple_Block"
    },
    {
      "x": -6,
      "y": 0,
      "z": -2,
      "name": "Rock_Crystal_Purple_Block"
    },
    {
      "x": -6,
      "y": 1,
      "z": -2,
      "name": "Rock_Crystal_Purple_Block"
    },
    {
      "x": -6,
      "y": 2,
      "z": -2,
      "name": "Rock_Crystal_Purple_Block"
    },
    {
      "x": -6,
      "y": 3,
      "z": -2,
      "name": "Rock_Crystal_Purple_Block"
    },
    {
      "x": -6,
      "y": 4,
      "z": -2,
      "name": "Rock_Crystal_Purple_Block"
    },
    {
      "x": -6,
      "y": 5,
      "z": -2,
      "name": "Rock_Crystal_Purple_Block"
    },
    {
      "x": -6,
      "y": 6,
      "z": -2,
      "name": "Rock_Crystal_Purple_Block"
    },
    {
      "x": -6,
      "y": 7,
      "z": -2,
      "name": "Rock_Crystal_Purple_Block"
    },
    {
      "x": -6,
      "y": 8,
      "z": -2,
      "name": "Rock_Crystal_Purple_Block"
    },
    {
      "x": -6,
      "y": 9,
      "z": -2,
      "name": "Rock_Crystal_Purple_Block"
    },
    {
      "x": -6,
      "y": 10,
      "z": -2,
      "name": "Rock_Crystal_Purple_Block"
    },
    {
      "x": -6,
      "y": 11,
      "z": -2,
      "name": "Rock_Crystal_Purple_Block"
    },
    {
      "x": -6,
      "y": 12,
      "z": -2,
      "name": "Rock_Crystal_Purple_Block"
    },
    {
      "x": -6,
      "y": 13,
      "z": -2,
      "name": "Rock_Crystal_Purple_Block"
    },
    {
      "x": -6,
      "y": 14,
      "z": -2,
      "name": "Rock_Crystal_Purple_Block"
    },
    {
      "x": -6,
      "y": 15,
      "z": -2,
      "name": "Rock_Crystal_Purple_Block"
    },
    {
      "x": -6,
      "y": 16,
      "z": -2,
      "name": "Rock_Crystal_Purple_Block"
    },
    {
      "x": -6,
      "y": 17,
      "z": -2,
      "name": "Rock_Crystal_Purple_Block"
    },
    {
      "x": -6,
      "y": 18,
      "z": -2,
      "name": "Rock_Crystal_Purple_Block"
    },
    {
      "x": -6,
      "y": 19,
      "z": -2,
      "name": "Rock_Crystal_Purple_Block"
    },
    {
      "x": -6,
      "y": 0,
      "z": 2,
      "name": "Rock_Crystal_Purple_Block"
    },
    {
      "x": -6,
      "y": 1,
      "z": 2,
      "name": "Rock_Crystal_Purple_Block"
    },
    {
      "x": -6,
      "y": 2,
      "z": 2,
      "name": "Rock_Crystal_Purple_Block"
    },
    {
      "x": -6,
      "y": 3,
      "z": 2,
      "name": "Rock_Crystal_Purple_Block"
    },
    {
      "x": -6,
      "y": 4,
      "z": 2,
      "name": "Rock_Crystal_Purple_Block"
    },
    {
      "x": -6,
      "y": 5,
      "z": 2,
      "name": "Rock_Crystal_Purple_Block"
    },
    {
      "x": -6,
      "y": 6,
      "z": 2,
      "name": "Rock_Crystal_Purple_Block"
    },
    {
      "x": -6,
      "y": 7,
      "z": 2,
      "name": "Rock_Crystal_Purple_Block"
    },
    {
      "x": -6,
      "y": 8,
      "z": 2,
      "name": "Rock_Crystal_Purple_Block"
    },
    {
      "x": -6,
      "y": 9,
      "z": 2,
      "name": "Rock_Crystal_Purple_Block"
    },
    {
      "x": -6,
      "y": 10,
      "z": 2,
      "name": "Rock_Crystal_Purple_Block"
    },
    {
      "x": -6,
      "y": 11,
      "z": 2,
      "name": "Rock_Crystal_Purple_Block"
    },
    {
      "x": -6,
      "y": 12,
      "z": 2,
      "name": "Rock_Crystal_Purple_Block"
    },
    {
      "x": -6,
      "y": 13,
      "z": 2,
      "name": "Rock_Crystal_Purple_Block"
    },
    {
      "x": -6,
      "y": 14,
      "z": 2,
      "name": "Rock_Crystal_Purple_Block"
    },
    {
      "x": -6,
      "y": 15,
      "z": 2,
      "name": "Rock_Crystal_Purple_Block"
    },
    {
      "x": -6,
      "y": 16,
      "z": 2,
      "name": "Rock_Crystal_Purple_Block"
    },
    {
      "x": -6,
      "y": 17,
      "z": 2,
      "name": "Rock_Crystal_Purple_Block"
    },
    {
      "x": -6,
      "y": 18,
      "z": 2,
      "name": "Rock_Crystal_Purple_Block"
    },
    {
      "x": -6,
      "y": 19,
      "z": 2,
      "name": "Rock_Crystal_Purple_Block"
    },
    {
      "x": -6,
      "y": 0,
      "z": 3,
      "name": "Rock_Crystal_Purple_Block"
    },
    {
      "x": -6,
      "y": 1,
      "z": 3,
      "name": "Rock_Crystal_Purple_Block"
    },
    {
      "x": -6,
      "y": 2,
      "z": 3,
      "name": "Rock_Crystal_Purple_Block"
    },
    {
      "x": -6,
      "y": 3,
      "z": 3,
      "name": "Rock_Crystal_Purple_Block"
    },
    {
      "x": -6,
      "y": 4,
      "z": 3,
      "name": "Rock_Crystal_Purple_Block"
    },
    {
      "x": -6,
      "y": 5,
      "z": 3,
      "name": "Rock_Crystal_Purple_Block"
    },
    {
      "x": -6,
      "y": 6,
      "z": 3,
      "name": "Rock_Crystal_Purple_Block"
    },
    {
      "x": -6,
      "y": 7,
      "z": 3,
      "name": "Rock_Crystal_Purple_Block"
    },
    {
      "x": -6,
      "y": 8,
      "z": 3,
      "name": "Rock_Crystal_Purple_Block"
    },
    {
      "x": -6,
      "y": 9,
      "z": 3,
      "name": "Rock_Crystal_Purple_Block"
    },
    {
      "x": -6,
      "y": 10,
      "z": 3,
      "name": "Rock_Crystal_Purple_Block"
    },
    {
      "x": -6,
      "y": 11,
      "z": 3,
      "name": "Rock_Crystal_Purple_Block"
    },
    {
      "x": -6,
      "y": 12,
      "z": 3,
      "name": "Rock_Crystal_Purple_Block"
    },
    {
      "x": -6,
      "y": 13,
      "z": 3,
      "name": "Rock_Crystal_Purple_Block"
    },
    {
      "x": -6,
      "y": 14,
      "z": 3,
      "name": "Rock_Crystal_Purple_Block"
    },
    {
      "x": -6,
      "y": 15,
      "z": 3,
      "name": "Rock_Crystal_Purple_Block"
    },
    {
      "x": -6,
      "y": 16,
      "z": 3,
      "name": "Rock_Crystal_Purple_Block"
    },
    {
      "x": -6,
      "y": 17,
      "z": 3,
      "name": "Rock_Crystal_Purple_Block"
    },
    {
      "x": -6,
      "y": 18,
      "z": 3,
      "name": "Rock_Crystal_Purple_Block"
    },
    {
      "x": -6,
      "y": 19,
      "z": 3,
      "name": "Rock_Crystal_Purple_Block"
    },
    {
      "x": -5,
      "y": 0,
      "z": -14,
      "name": "Rock_Crystal_Purple_Block"
    },
    {
      "x": -5,
      "y": 1,
      "z": -14,
      "name": "Rock_Crystal_Purple_Block"
    },
    {
      "x": -5,
      "y": 2,
      "z": -14,
      "name": "Rock_Crystal_Purple_Block"
    },
    {
      "x": -5,
      "y": 3,
      "z": -14,
      "name": "Rock_Crystal_Purple_Block"
    },
    {
      "x": -5,
      "y": 4,
      "z": -14,
      "name": "Rock_Crystal_Purple_Block"
    },
    {
      "x": -5,
      "y": 5,
      "z": -14,
      "name": "Rock_Crystal_Purple_Block"
    },
    {
      "x": -5,
      "y": 6,
      "z": -14,
      "name": "Rock_Crystal_Purple_Block"
    },
    {
      "x": -5,
      "y": 7,
      "z": -14,
      "name": "Rock_Crystal_Purple_Block"
    },
    {
      "x": -5,
      "y": 8,
      "z": -14,
      "name": "Rock_Crystal_Purple_Block"
    },
    {
      "x": -5,
      "y": 9,
      "z": -14,
      "name": "Rock_Crystal_Purple_Block"
    },
    {
      "x": -5,
      "y": 10,
      "z": -14,
      "name": "Rock_Crystal_Purple_Block"
    },
    {
      "x": -5,
      "y": 11,
      "z": -14,
      "name": "Rock_Crystal_Purple_Block"
    },
    {
      "x": -5,
      "y": 12,
      "z": -14,
      "name": "Rock_Crystal_Purple_Block"
    },
    {
      "x": -5,
      "y": 13,
      "z": -14,
      "name": "Rock_Crystal_Purple_Block"
    },
    {
      "x": -5,
      "y": 14,
      "z": -14,
      "name": "Rock_Crystal_Purple_Block"
    },
    {
      "x": -5,
      "y": 15,
      "z": -14,
      "name": "Rock_Crystal_Purple_Block"
    },
    {
      "x": -5,
      "y": 16,
      "z": -14,
      "name": "Rock_Crystal_Purple_Block"
    },
    {
      "x": -5,
      "y": 17,
      "z": -14,
      "name": "Rock_Crystal_Purple_Block"
    },
    {
      "x": -5,
      "y": 18,
      "z": -14,
      "name": "Rock_Crystal_Purple_Block"
    },
    {
      "x": -5,
      "y": 19,
      "z": -14,
      "name": "Rock_Crystal_Purple_Block"
    },
    {
      "x": -5,
      "y": 0,
      "z": -13,
      "name": "Rock_Crystal_Purple_Block"
    },
    {
      "x": -5,
      "y": 1,
      "z": -13,
      "name": "Rock_Crystal_Purple_Block"
    },
    {
      "x": -5,
      "y": 2,
      "z": -13,
      "name": "Rock_Crystal_Purple_Block"
    },
    {
      "x": -5,
      "y": 3,
      "z": -13,
      "name": "Rock_Crystal_Purple_Block"
    },
    {
      "x": -5,
      "y": 4,
      "z": -13,
      "name": "Rock_Crystal_Purple_Block"
    },
    {
      "x": -5,
      "y": 5,
      "z": -13,
      "name": "Rock_Crystal_Purple_Block"
    },
    {
      "x": -5,
      "y": 6,
      "z": -13,
      "name": "Rock_Crystal_Purple_Block"
    },
    {
      "x": -5,
      "y": 7,
      "z": -13,
      "name": "Rock_Crystal_Purple_Block"
    },
    {
      "x": -5,
      "y": 8,
      "z": -13,
      "name": "Rock_Crystal_Purple_Block"
    },
    {
      "x": -5,
      "y": 9,
      "z": -13,
      "name": "Rock_Crystal_Purple_Block"
    },
    {
      "x": -5,
      "y": 10,
      "z": -13,
      "name": "Rock_Crystal_Purple_Block"
    },
    {
      "x": -5,
      "y": 11,
      "z": -13,
      "name": "Rock_Crystal_Purple_Block"
    },
    {
      "x": -5,
      "y": 12,
      "z": -13,
      "name": "Rock_Crystal_Purple_Block"
    },
    {
      "x": -5,
      "y": 13,
      "z": -13,
      "name": "Rock_Crystal_Purple_Block"
    },
    {
      "x": -5,
      "y": 14,
      "z": -13,
      "name": "Rock_Crystal_Purple_Block"
    },
    {
      "x": -5,
      "y": 15,
      "z": -13,
      "name": "Rock_Crystal_Purple_Block"
    },
    {
      "x": -5,
      "y": 16,
      "z": -13,
      "name": "Rock_Crystal_Purple_Block"
    },
    {
      "x": -5,
      "y": 17,
      "z": -13,
      "name": "Rock_Crystal_Purple_Block"
    },
    {
      "x": -5,
      "y": 18,
      "z": -13,
      "name": "Rock_Crystal_Purple_Block"
    },
    {
      "x": -5,
      "y": 19,
      "z": -13,
      "name": "Rock_Crystal_Purple_Block"
    },
    {
      "x": -5,
      "y": 0,
      "z": -12,
      "name": "Rock_Crystal_Purple_Block"
    },
    {
      "x": -5,
      "y": 1,
      "z": -12,
      "name": "Rock_Crystal_Purple_Block"
    },
    {
      "x": -5,
      "y": 2,
      "z": -12,
      "name": "Rock_Crystal_Purple_Block"
    },
    {
      "x": -5,
      "y": 3,
      "z": -12,
      "name": "Rock_Crystal_Purple_Block"
    },
    {
      "x": -5,
      "y": 4,
      "z": -12,
      "name": "Rock_Crystal_Purple_Block"
    },
    {
      "x": -5,
      "y": 5,
      "z": -12,
      "name": "Rock_Crystal_Purple_Block"
    },
    {
      "x": -5,
      "y": 6,
      "z": -12,
      "name": "Rock_Crystal_Purple_Block"
    },
    {
      "x": -5,
      "y": 7,
      "z": -12,
      "name": "Rock_Crystal_Purple_Block"
    },
    {
      "x": -5,
      "y": 8,
      "z": -12,
      "name": "Rock_Crystal_Purple_Block"
    },
    {
      "x": -5,
      "y": 9,
      "z": -12,
      "name": "Rock_Crystal_Purple_Block"
    },
    {
      "x": -5,
      "y": 10,
      "z": -12,
      "name": "Rock_Crystal_Purple_Block"
    },
    {
      "x": -5,
      "y": 11,
      "z": -12,
      "name": "Rock_Crystal_Purple_Block"
    },
    {
      "x": -5,
      "y": 12,
      "z": -12,
      "name": "Rock_Crystal_Purple_Block"
    },
    {
      "x": -5,
      "y": 13,
      "z": -12,
      "name": "Rock_Crystal_Purple_Block"
    },
    {
      "x": -5,
      "y": 14,
      "z": -12,
      "name": "Rock_Crystal_Purple_Block"
    },
    {
      "x": -5,
      "y": 15,
      "z": -12,
      "name": "Rock_Crystal_Purple_Block"
    },
    {
      "x": -5,
      "y": 16,
      "z": -12,
      "name": "Rock_Crystal_Purple_Block"
    },
    {
      "x": -5,
      "y": 17,
      "z": -12,
      "name": "Rock_Crystal_Purple_Block"
    },
    {
      "x": -5,
      "y": 18,
      "z": -12,
      "name": "Rock_Crystal_Purple_Block"
    },
    {
      "x": -5,
      "y": 19,
      "z": -12,
      "name": "Rock_Crystal_Purple_Block"
    },
    {
      "x": -5,
      "y": 0,
      "z": -10,
      "name": "Rock_Crystal_Purple_Block"
    },
    {
      "x": -5,
      "y": 1,
      "z": -10,
      "name": "Rock_Crystal_Purple_Block"
    },
    {
      "x": -5,
      "y": 2,
      "z": -10,
      "name": "Rock_Crystal_Purple_Block"
    },
    {
      "x": -5,
      "y": 3,
      "z": -10,
      "name": "Rock_Crystal_Purple_Block"
    },
    {
      "x": -5,
      "y": 4,
      "z": -10,
      "name": "Rock_Crystal_Purple_Block"
    },
    {
      "x": -5,
      "y": 5,
      "z": -10,
      "name": "Rock_Crystal_Purple_Block"
    },
    {
      "x": -5,
      "y": 6,
      "z": -10,
      "name": "Rock_Crystal_Purple_Block"
    },
    {
      "x": -5,
      "y": 7,
      "z": -10,
      "name": "Rock_Crystal_Purple_Block"
    },
    {
      "x": -5,
      "y": 8,
      "z": -10,
      "name": "Rock_Crystal_Purple_Block"
    },
    {
      "x": -5,
      "y": 9,
      "z": -10,
      "name": "Rock_Crystal_Purple_Block"
    },
    {
      "x": -5,
      "y": 10,
      "z": -10,
      "name": "Rock_Crystal_Purple_Block"
    },
    {
      "x": -5,
      "y": 11,
      "z": -10,
      "name": "Rock_Crystal_Purple_Block"
    },
    {
      "x": -5,
      "y": 12,
      "z": -10,
      "name": "Rock_Crystal_Purple_Block"
    },
    {
      "x": -5,
      "y": 13,
      "z": -10,
      "name": "Rock_Crystal_Purple_Block"
    },
    {
      "x": -5,
      "y": 14,
      "z": -10,
      "name": "Rock_Crystal_Purple_Block"
    },
    {
      "x": -5,
      "y": 15,
      "z": -10,
      "name": "Rock_Crystal_Purple_Block"
    },
    {
      "x": -5,
      "y": 16,
      "z": -10,
      "name": "Rock_Crystal_Purple_Block"
    },
    {
      "x": -5,
      "y": 17,
      "z": -10,
      "name": "Rock_Crystal_Purple_Block"
    },
    {
      "x": -5,
      "y": 18,
      "z": -10,
      "name": "Rock_Crystal_Purple_Block"
    },
    {
      "x": -5,
      "y": 19,
      "z": -10,
      "name": "Rock_Crystal_Purple_Block"
    },
    {
      "x": -5,
      "y": 0,
      "z": -9,
      "name": "Rock_Crystal_Purple_Block"
    },
    {
      "x": -5,
      "y": 1,
      "z": -9,
      "name": "Rock_Crystal_Purple_Block"
    },
    {
      "x": -5,
      "y": 2,
      "z": -9,
      "name": "Rock_Crystal_Purple_Block"
    },
    {
      "x": -5,
      "y": 3,
      "z": -9,
      "name": "Rock_Crystal_Purple_Block"
    },
    {
      "x": -5,
      "y": 4,
      "z": -9,
      "name": "Rock_Crystal_Purple_Block"
    },
    {
      "x": -5,
      "y": 5,
      "z": -9,
      "name": "Rock_Crystal_Purple_Block"
    },
    {
      "x": -5,
      "y": 6,
      "z": -9,
      "name": "Rock_Crystal_Purple_Block"
    },
    {
      "x": -5,
      "y": 7,
      "z": -9,
      "name": "Rock_Crystal_Purple_Block"
    },
    {
      "x": -5,
      "y": 8,
      "z": -9,
      "name": "Rock_Crystal_Purple_Block"
    },
    {
      "x": -5,
      "y": 9,
      "z": -9,
      "name": "Rock_Crystal_Purple_Block"
    },
    {
      "x": -5,
      "y": 10,
      "z": -9,
      "name": "Rock_Crystal_Purple_Block"
    },
    {
      "x": -5,
      "y": 11,
      "z": -9,
      "name": "Rock_Crystal_Purple_Block"
    },
    {
      "x": -5,
      "y": 12,
      "z": -9,
      "name": "Rock_Crystal_Purple_Block"
    },
    {
      "x": -5,
      "y": 13,
      "z": -9,
      "name": "Rock_Crystal_Purple_Block"
    },
    {
      "x": -5,
      "y": 14,
      "z": -9,
      "name": "Rock_Crystal_Purple_Block"
    },
    {
      "x": -5,
      "y": 15,
      "z": -9,
      "name": "Rock_Crystal_Purple_Block"
    },
    {
      "x": -5,
      "y": 16,
      "z": -9,
      "name": "Rock_Crystal_Purple_Block"
    },
    {
      "x": -5,
      "y": 17,
      "z": -9,
      "name": "Rock_Crystal_Purple_Block"
    },
    {
      "x": -5,
      "y": 18,
      "z": -9,
      "name": "Rock_Crystal_Purple_Block"
    },
    {
      "x": -5,
      "y": 19,
      "z": -9,
      "name": "Rock_Crystal_Purple_Block"
    },
    {
      "x": -5,
      "y": 0,
      "z": -8,
      "name": "Rock_Crystal_Purple_Block"
    },
    {
      "x": -5,
      "y": 1,
      "z": -8,
      "name": "Rock_Crystal_Purple_Block"
    },
    {
      "x": -5,
      "y": 2,
      "z": -8,
      "name": "Rock_Crystal_Purple_Block"
    },
    {
      "x": -5,
      "y": 3,
      "z": -8,
      "name": "Rock_Crystal_Purple_Block"
    },
    {
      "x": -5,
      "y": 4,
      "z": -8,
      "name": "Rock_Crystal_Purple_Block"
    },
    {
      "x": -5,
      "y": 5,
      "z": -8,
      "name": "Rock_Crystal_Purple_Block"
    },
    {
      "x": -5,
      "y": 6,
      "z": -8,
      "name": "Rock_Crystal_Purple_Block"
    },
    {
      "x": -5,
      "y": 7,
      "z": -8,
      "name": "Rock_Crystal_Purple_Block"
    },
    {
      "x": -5,
      "y": 8,
      "z": -8,
      "name": "Rock_Crystal_Purple_Block"
    },
    {
      "x": -5,
      "y": 9,
      "z": -8,
      "name": "Rock_Crystal_Purple_Block"
    },
    {
      "x": -5,
      "y": 10,
      "z": -8,
      "name": "Rock_Crystal_Purple_Block"
    },
    {
      "x": -5,
      "y": 11,
      "z": -8,
      "name": "Rock_Crystal_Purple_Block"
    },
    {
      "x": -5,
      "y": 12,
      "z": -8,
      "name": "Rock_Crystal_Purple_Block"
    },
    {
      "x": -5,
      "y": 13,
      "z": -8,
      "name": "Rock_Crystal_Purple_Block"
    },
    {
      "x": -5,
      "y": 14,
      "z": -8,
      "name": "Rock_Crystal_Purple_Block"
    },
    {
      "x": -5,
      "y": 15,
      "z": -8,
      "name": "Rock_Crystal_Purple_Block"
    },
    {
      "x": -5,
      "y": 16,
      "z": -8,
      "name": "Rock_Crystal_Purple_Block"
    },
    {
      "x": -5,
      "y": 17,
      "z": -8,
      "name": "Rock_Crystal_Purple_Block"
    },
    {
      "x": -5,
      "y": 18,
      "z": -8,
      "name": "Rock_Crystal_Purple_Block"
    },
    {
      "x": -5,
      "y": 19,
      "z": -8,
      "name": "Rock_Crystal_Purple_Block"
    },
    {
      "x": -5,
      "y": 0,
      "z": -7,
      "name": "Rock_Crystal_Purple_Block"
    },
    {
      "x": -5,
      "y": 1,
      "z": -7,
      "name": "Rock_Crystal_Purple_Block"
    },
    {
      "x": -5,
      "y": 2,
      "z": -7,
      "name": "Rock_Crystal_Purple_Block"
    },
    {
      "x": -5,
      "y": 3,
      "z": -7,
      "name": "Rock_Crystal_Purple_Block"
    },
    {
      "x": -5,
      "y": 4,
      "z": -7,
      "name": "Rock_Crystal_Purple_Block"
    },
    {
      "x": -5,
      "y": 5,
      "z": -7,
      "name": "Rock_Crystal_Purple_Block"
    },
    {
      "x": -5,
      "y": 6,
      "z": -7,
      "name": "Rock_Crystal_Purple_Block"
    },
    {
      "x": -5,
      "y": 7,
      "z": -7,
      "name": "Rock_Crystal_Purple_Block"
    },
    {
      "x": -5,
      "y": 8,
      "z": -7,
      "name": "Rock_Crystal_Purple_Block"
    },
    {
      "x": -5,
      "y": 9,
      "z": -7,
      "name": "Rock_Crystal_Purple_Block"
    },
    {
      "x": -5,
      "y": 10,
      "z": -7,
      "name": "Rock_Crystal_Purple_Block"
    },
    {
      "x": -5,
      "y": 11,
      "z": -7,
      "name": "Rock_Crystal_Purple_Block"
    },
    {
      "x": -5,
      "y": 12,
      "z": -7,
      "name": "Rock_Crystal_Purple_Block"
    },
    {
      "x": -5,
      "y": 13,
      "z": -7,
      "name": "Rock_Crystal_Purple_Block"
    },
    {
      "x": -5,
      "y": 14,
      "z": -7,
      "name": "Rock_Crystal_Purple_Block"
    },
    {
      "x": -5,
      "y": 15,
      "z": -7,
      "name": "Rock_Crystal_Purple_Block"
    },
    {
      "x": -5,
      "y": 16,
      "z": -7,
      "name": "Rock_Crystal_Purple_Block"
    },
    {
      "x": -5,
      "y": 17,
      "z": -7,
      "name": "Rock_Crystal_Purple_Block"
    },
    {
      "x": -5,
      "y": 18,
      "z": -7,
      "name": "Rock_Crystal_Purple_Block"
    },
    {
      "x": -5,
      "y": 19,
      "z": -7,
      "name": "Rock_Crystal_Purple_Block"
    },
    {
      "x": -5,
      "y": 0,
      "z": -2,
      "name": "Rock_Crystal_Purple_Block"
    },
    {
      "x": -5,
      "y": 1,
      "z": -2,
      "name": "Rock_Crystal_Purple_Block"
    },
    {
      "x": -5,
      "y": 2,
      "z": -2,
      "name": "Rock_Crystal_Purple_Block"
    },
    {
      "x": -5,
      "y": 3,
      "z": -2,
      "name": "Rock_Crystal_Purple_Block"
    },
    {
      "x": -5,
      "y": 4,
      "z": -2,
      "name": "Rock_Crystal_Purple_Block"
    },
    {
      "x": -5,
      "y": 5,
      "z": -2,
      "name": "Rock_Crystal_Purple_Block"
    },
    {
      "x": -5,
      "y": 6,
      "z": -2,
      "name": "Rock_Crystal_Purple_Block"
    },
    {
      "x": -5,
      "y": 7,
      "z": -2,
      "name": "Rock_Crystal_Purple_Block"
    },
    {
      "x": -5,
      "y": 8,
      "z": -2,
      "name": "Rock_Crystal_Purple_Block"
    },
    {
      "x": -5,
      "y": 9,
      "z": -2,
      "name": "Rock_Crystal_Purple_Block"
    },
    {
      "x": -5,
      "y": 10,
      "z": -2,
      "name": "Rock_Crystal_Purple_Block"
    },
    {
      "x": -5,
      "y": 11,
      "z": -2,
      "name": "Rock_Crystal_Purple_Block"
    },
    {
      "x": -5,
      "y": 12,
      "z": -2,
      "name": "Rock_Crystal_Purple_Block"
    },
    {
      "x": -5,
      "y": 13,
      "z": -2,
      "name": "Rock_Crystal_Purple_Block"
    },
    {
      "x": -5,
      "y": 14,
      "z": -2,
      "name": "Rock_Crystal_Purple_Block"
    },
    {
      "x": -5,
      "y": 15,
      "z": -2,
      "name": "Rock_Crystal_Purple_Block"
    },
    {
      "x": -5,
      "y": 16,
      "z": -2,
      "name": "Rock_Crystal_Purple_Block"
    },
    {
      "x": -5,
      "y": 17,
      "z": -2,
      "name": "Rock_Crystal_Purple_Block"
    },
    {
      "x": -5,
      "y": 18,
      "z": -2,
      "name": "Rock_Crystal_Purple_Block"
    },
    {
      "x": -5,
      "y": 19,
      "z": -2,
      "name": "Rock_Crystal_Purple_Block"
    },
    {
      "x": -5,
      "y": 0,
