{
  "version": 8,
  "blockIdVersion": 11,
  "anchorX": 0,
  "anchorY": 0,
  "anchorZ": 0,
  "blocks": [
    {
      "x": -18,
      "y": 112,
      "z": 4,
      "name": "Plant_Leaves_Azure"
    },
    {
      "x": -18,
      "y": 113,
      "z": 4,
      "name": "Plant_Leaves_Azure"
    },
    {
      "x": -18,
      "y": 112,
      "z": 5,
      "name": "Plant_Leaves_Azure"
    },
    {
      "x": -18,
      "y": 113,
      "z": 5,
      "name": "Plant_Leaves_Azure"
    },
    {
      "x": -17,
      "y": 112,
      "z": 3,
      "name": "Plant_Leaves_Azure"
    },
    {
      "x": -17,
      "y": 113,
      "z": 3,
      "name": "Plant_Leaves_Azure"
    },
    {
      "x": -17,
      "y": 111,
      "z": 4,
      "name": "Plant_Leaves_Azure"
    },
    {
      "x": -17,
      "y": 112,
      "z": 4,
      "name": "Plant_Leaves_Azure"
    },
    {
      "x": -17,
      "y": 113,
      "z": 4,
      "name": "Plant_Leaves_Azure"
    },
    {
      "x": -17,
      "y": 114,
      "z": 4,
      "name": "Plant_Leaves_Azure"
    },
    {
      "x": -17,
      "y": 111,
      "z": 5,
      "name": "Plant_Leaves_Azure"
    },
    {
      "x": -17,
      "y": 112,
      "z": 5,
      "name": "Plant_Leaves_Azure"
    },
    {
      "x": -17,
      "y": 113,
      "z": 5,
      "name": "Plant_Leaves_Azure"
    },
    {
      "x": -17,
      "y": 114,
      "z": 5,
      "name": "Plant_Leaves_Azure"
    },
    {
      "x": -17,
      "y": 115,
      "z": 5,
      "name": "Plant_Fruit_Azure"
    },
    {
      "x": -17,
      "y": 111,
      "z": 6,
      "name": "Plant_Leaves_Azure"
    },
    {
      "x": -17,
      "y": 112,
      "z": 6,
      "name": "Plant_Leaves_Azure"
    },
    {
      "x": -17,
      "y": 113,
      "z": 6,
      "name": "Plant_Leaves_Azure"
    },
    {
      "x": -17,
      "y": 114,
      "z": 6,
      "name": "Plant_Leaves_Azure"
    },
    {
      "x": -17,
      "y": 112,
      "z": 7,
      "name": "Plant_Leaves_Azure"
    },
    {
      "x": -17,
      "y": 113,
      "z": 7,
      "name": "Plant_Leaves_Azure"
    },
    {
      "x": -16,
      "y": 115,
      "z": 0,
      "name": "Plant_Leaves_Azure"
    },
    {
      "x": -16,
      "y": 116,
      "z": 0,
      "name": "Plant_Leaves_Azure"
    },
    {
      "x": -16,
      "y": 117,
      "z": 0,
      "name": "Plant_Leaves_Azure"
    },
    {
      "x": -16,
      "y": 115,
      "z": 1,
      "name": "Plant_Leaves_Azure"
    },
    {
      "x": -16,
      "y": 116,
      "z": 1,
      "name": "Plant_Leaves_Azure"
    },
    {
      "x": -16,
      "y": 117,
      "z": 1,
      "name": "Plant_Leaves_Azure"
    },
    {
      "x": -16,
      "y": 118,
      "z": 1,
      "name": "Plant_Leaves_Azure"
    },
    {
      "x": -16,
      "y": 116,
      "z": 2,
      "name": "Plant_Leaves_Azure"
    },
    {
      "x": -16,
      "y": 117,
      "z": 2,
      "name": "Plant_Leaves_Azure"
    },
    {
      "x": -16,
      "y": 118,
      "z": 2,
      "name": "Plant_Leaves_Azure"
    },
    {
      "x": -16,
      "y": 119,
      "z": 2,
      "name": "Plant_Leaves_Azure"
    },
    {
      "x": -16,
      "y": 112,
      "z": 3,
      "name": "Plant_Leaves_Azure"
    },
    {
      "x": -16,
      "y": 113,
      "z": 3,
      "name": "Plant_Leaves_Azure"
    },
    {
      "x": -16,
      "y": 117,
      "z": 3,
      "name": "Plant_Leaves_Azure"
    },
    {
      "x": -16,
      "y": 118,
      "z": 3,
      "name": "Plant_Leaves_Azure"
    },
    {
      "x": -16,
      "y": 119,
      "z": 3,
      "name": "Plant_Leaves_Azure"
    },
    {
      "x": -16,
      "y": 120,
      "z": 3,
      "name": "Plant_Leaves_Azure"
    },
    {
      "x": -16,
      "y": 111,
      "z": 4,
      "name": "Plant_Leaves_Azure"
    },
    {
      "x": -16,
      "y": 112,
      "z": 4,
      "name": "Plant_Leaves_Azure"
    },
    {
      "x": -16,
      "y": 113,
      "z": 4,
      "name": "Plant_Leaves_Azure"
    },
    {
      "x": -16,
      "y": 114,
      "z": 4,
      "name": "Plant_Leaves_Azure"
    },
    {
      "x": -16,
      "y": 118,
      "z": 4,
      "name": "Plant_Leaves_Azure"
    },
    {
      "x": -16,
      "y": 119,
      "z": 4,
      "name": "Plant_Leaves_Azure"
    },
    {
      "x": -16,
      "y": 120,
      "z": 4,
      "name": "Plant_Leaves_Azure"
    },
    {
      "x": -16,
      "y": 111,
      "z": 5,
      "name": "Plant_Leaves_Azure"
    },
    {
      "x": -16,
      "y": 112,
      "z": 5,
      "name": "Plant_Leaves_Azure"
    },
    {
      "x": -16,
      "y": 113,
      "z": 5,
      "name": "Plant_Leaves_Azure"
    },
    {
      "x": -16,
      "y": 114,
      "z": 5,
      "name": "Plant_Leaves_Azure"
    },
    {
      "x": -16,
      "y": 111,
      "z": 6,
      "name": "Plant_Leaves_Azure"
    },
    {
      "x": -16,
      "y": 112,
      "z": 6,
      "name": "Plant_Leaves_Azure"
    },
    {
      "x": -16,
      "y": 113,
      "z": 6,
      "name": "Plant_Leaves_Azure"
    },
    {
      "x": -16,
      "y": 114,
      "z": 6,
      "name": "Plant_Leaves_Azure"
    },
    {
      "x": -16,
      "y": 115,
      "z": 6,
      "name": "Plant_Leaves_Azure"
    },
    {
      "x": -16,
      "y": 111,
      "z": 7,
      "name": "Plant_Leaves_Azure"
    },
    {
      "x": -16,
      "y": 112,
      "z": 7,
      "name": "Plant_Leaves_Azure"
    },
    {
      "x": -16,
      "y": 113,
      "z": 7,
      "name": "Plant_Leaves_Azure"
    },
    {
      "x": -16,
      "y": 114,
      "z": 7,
      "name": "Plant_Leaves_Azure"
    },
    {
      "x": -16,
      "y": 115,
      "z": 7,
      "name": "Plant_Leaves_Azure"
    },
    {
      "x": -15,
      "y": 114,
      "z": -1,
      "name": "Plant_Leaves_Azure"
    },
    {
      "x": -15,
      "y": 115,
      "z": -1,
      "name": "Plant_Leaves_Azure"
    },
    {
      "x": -15,
      "y": 116,
      "z": -1,
      "name": "Plant_Leaves_Azure"
    },
    {
      "x": -15,
      "y": 94,
      "z": 0,
      "name": "Plant_Moss_Wall_Blue",
      "support": 15,
      "rotation": 3
    },
    {
      "x": -15,
      "y": 95,
      "z": 0,
      "name": "Plant_Moss_Wall_Blue",
      "support": 15,
      "rotation": 3
    },
    {
      "x": -15,
      "y": 114,
      "z": 0,
      "name": "Plant_Leaves_Azure"
    },
    {
      "x": -15,
      "y": 115,
      "z": 0,
      "name": "Plant_Leaves_Azure"
    },
    {
      "x": -15,
      "y": 116,
      "z": 0,
      "name": "Plant_Leaves_Azure"
    },
    {
      "x": -15,
      "y": 117,
      "z": 0,
      "name": "Plant_Leaves_Azure"
    },
    {
      "x": -15,
      "y": 118,
      "z": 0,
      "name": "Plant_Leaves_Azure"
    },
    {
      "x": -15,
      "y": 115,
      "z": 1,
      "name": "Plant_Leaves_Azure"
    },
    {
      "x": -15,
      "y": 116,
      "z": 1,
      "name": "Plant_Leaves_Azure"
    },
    {
      "x": -15,
      "y": 117,
      "z": 1,
      "name": "Plant_Leaves_Azure"
    },
    {
      "x": -15,
      "y": 118,
      "z": 1,
      "name": "Plant_Leaves_Azure"
    },
    {
      "x": -15,
      "y": 119,
      "z": 1,
      "name": "Plant_Leaves_Azure"
    },
    {
      "x": -15,
      "y": 115,
      "z": 2,
      "name": "Plant_Leaves_Azure"
    },
    {
      "x": -15,
      "y": 116,
      "z": 2,
      "name": "Wood_Azure_Branch_Long",
      "rotation": 5
    },
    {
      "x": -15,
      "y": 117,
      "z": 2,
      "name": "Plant_Leaves_Azure"
    },
    {
      "x": -15,
      "y": 118,
      "z": 2,
      "name": "Plant_Leaves_Azure"
    },
    {
      "x": -15,
      "y": 119,
      "z": 2,
      "name": "Plant_Leaves_Azure"
    },
    {
      "x": -15,
      "y": 120,
      "z": 2,
      "name": "Plant_Leaves_Azure"
    },
    {
      "x": -15,
      "y": 96,
      "z": 3,
      "name": "Plant_Moss_Wall_Blue",
      "support": 15,
      "rotation": 3
    },
    {
      "x": -15,
      "y": 116,
      "z": 3,
      "name": "Plant_Leaves_Azure"
    },
    {
      "x": -15,
      "y": 117,
      "z": 3,
      "name": "Plant_Leaves_Azure"
    },
    {
      "x": -15,
      "y": 118,
      "z": 3,
      "name": "Plant_Leaves_Azure"
    },
    {
      "x": -15,
      "y": 119,
      "z": 3,
      "name": "Plant_Leaves_Azure"
    },
    {
      "x": -15,
      "y": 120,
      "z": 3,
      "name": "Plant_Leaves_Azure"
    },
    {
      "x": -15,
      "y": 121,
      "z": 3,
      "name": "Plant_Leaves_Azure"
    },
    {
      "x": -15,
      "y": 112,
      "z": 4,
      "name": "Wood_Azure_Branch_Long",
      "rotation": 5
    },
    {
      "x": -15,
      "y": 117,
      "z": 4,
      "name": "Plant_Leaves_Azure"
    },
    {
      "x": -15,
      "y": 118,
      "z": 4,
      "name": "Plant_Leaves_Azure"
    },
    {
      "x": -15,
      "y": 119,
      "z": 4,
      "name": "Plant_Leaves_Azure"
    },
    {
      "x": -15,
      "y": 120,
      "z": 4,
      "name": "Plant_Leaves_Azure"
    },
    {
      "x": -15,
      "y": 121,
      "z": 4,
      "name": "Plant_Leaves_Azure"
    },
    {
      "x": -15,
      "y": 114,
      "z": 5,
      "name": "Plant_Leaves_Azure"
    },
    {
      "x": -15,
      "y": 115,
      "z": 5,
      "name": "Plant_Leaves_Azure"
    },
    {
      "x": -15,
      "y": 119,
      "z": 5,
      "name": "Plant_Leaves_Azure"
    },
    {
      "x": -15,
      "y": 120,
      "z": 5,
      "name": "Plant_Leaves_Azure"
    },
    {
      "x": -15,
      "y": 112,
      "z": 6,
      "name": "Plant_Leaves_Azure"
    },
    {
      "x": -15,
      "y": 113,
      "z": 6,
      "name": "Plant_Leaves_Azure"
    },
    {
      "x": -15,
      "y": 114,
      "z": 6,
      "name": "Plant_Leaves_Azure"
    },
    {
      "x": -15,
      "y": 115,
      "z": 6,
      "name": "Plant_Leaves_Azure"
    },
    {
      "x": -15,
      "y": 112,
      "z": 7,
      "name": "Plant_Leaves_Azure"
    },
    {
      "x": -15,
      "y": 113,
      "z": 7,
      "name": "Plant_Leaves_Azure"
    },
    {
      "x": -15,
      "y": 114,
      "z": 7,
      "name": "Plant_Leaves_Azure"
    },
    {
      "x": -15,
      "y": 115,
      "z": 7,
      "name": "Plant_Leaves_Azure"
    },
    {
      "x": -15,
      "y": 116,
      "z": 7,
      "name": "Plant_Leaves_Azure"
    },
    {
      "x": -15,
      "y": 117,
      "z": 7,
      "name": "Plant_Fruit_Azure"
    },
    {
      "x": -15,
      "y": 113,
      "z": 8,
      "name": "Plant_Leaves_Azure"
    },
    {
      "x": -15,
      "y": 114,
      "z": 8,
      "name": "Plant_Leaves_Azure"
    },
    {
      "x": -15,
      "y": 115,
      "z": 8,
      "name": "Plant_Leaves_Azure"
    },
    {
      "x": -14,
      "y": 113,
      "z": -2,
      "name": "Plant_Leaves_Azure"
    },
    {
      "x": -14,
      "y": 114,
      "z": -2,
      "name": "Plant_Leaves_Azure"
    },
    {
      "x": -14,
      "y": 115,
      "z": -2,
      "name": "Plant_Leaves_Azure"
    },
    {
      "x": -14,
      "y": 116,
      "z": -2,
      "name": "Plant_Leaves_Azure"
    },
    {
      "x": -14,
      "y": 93,
      "z": -1,
      "name": "Plant_Moss_Wall_Blue",
      "support": 15,
      "rotation": 3
    },
    {
      "x": -14,
      "y": 94,
      "z": -1,
      "name": "Plant_Moss_Wall_Blue",
      "support": 15,
      "rotation": 3
    },
    {
      "x": -14,
      "y": 113,
      "z": -1,
      "name": "Plant_Leaves_Azure"
    },
    {
      "x": -14,
      "y": 114,
      "z": -1,
      "name": "Plant_Leaves_Azure"
    },
    {
      "x": -14,
      "y": 115,
      "z": -1,
      "name": "Plant_Leaves_Azure"
    },
    {
      "x": -14,
      "y": 116,
      "z": -1,
      "name": "Plant_Leaves_Azure"
    },
    {
      "x": -14,
      "y": 117,
      "z": -1,
      "name": "Plant_Leaves_Azure"
    },
    {
      "x": -14,
      "y": 93,
      "z": 0,
      "name": "Plant_Moss_Wall_Blue",
      "support": 15,
      "rotation": 3
    },
    {
      "x": -14,
      "y": 94,
      "z": 0,
      "name": "Rock_Marble"
    },
    {
      "x": -14,
      "y": 95,
      "z": 0,
      "name": "Plant_Moss_Block_Blue"
    },
    {
      "x": -14,
      "y": 96,
      "z": 0,
      "name": "Plant_Moss_Block_Blue"
    },
    {
      "x": -14,
      "y": 97,
      "z": 0,
      "name": "Plant_Moss_Short_Green_Dark"
    },
    {
      "x": -14,
      "y": 114,
      "z": 0,
      "name": "Plant_Leaves_Azure"
    },
    {
      "x": -14,
      "y": 115,
      "z": 0,
      "name": "Plant_Leaves_Azure"
    },
    {
      "x": -14,
      "y": 116,
      "z": 0,
      "name": "Plant_Leaves_Azure"
    },
    {
      "x": -14,
      "y": 117,
      "z": 0,
      "name": "Plant_Leaves_Azure"
    },
    {
      "x": -14,
      "y": 118,
      "z": 0,
      "name": "Plant_Leaves_Azure"
    },
    {
      "x": -14,
      "y": 95,
      "z": 1,
      "name": "Plant_Moss_Block_Blue"
    },
    {
      "x": -14,
      "y": 96,
      "z": 1,
      "name": "Plant_Moss_Block_Blue"
    },
    {
      "x": -14,
      "y": 97,
      "z": 1,
      "name": "Plant_Moss_Short_Green_Dark"
    },
    {
      "x": -14,
      "y": 116,
      "z": 1,
      "name": "Plant_Leaves_Azure"
    },
    {
      "x": -14,
      "y": 117,
      "z": 1,
      "name": "Plant_Leaves_Azure"
    },
    {
      "x": -14,
      "y": 118,
      "z": 1,
      "name": "Plant_Leaves_Azure"
    },
    {
      "x": -14,
      "y": 119,
      "z": 1,
      "name": "Plant_Fruit_Azure"
    },
    {
      "x": -14,
      "y": 94,
      "z": 2,
      "name": "Rock_Marble"
    },
    {
      "x": -14,
      "y": 95,
      "z": 2,
      "name": "Plant_Moss_Block_Blue"
    },
    {
      "x": -14,
      "y": 96,
      "z": 2,
      "name": "Plant_Moss_Block_Blue"
    },
    {
      "x": -14,
      "y": 97,
      "z": 2,
      "name": "Plant_Moss_Rug_Blue"
    },
    {
      "x": -14,
      "y": 116,
      "z": 2,
      "name": "Wood_Azure_Branch_Long",
      "rotation": 5
    },
    {
      "x": -14,
      "y": 118,
      "z": 2,
      "name": "Plant_Leaves_Azure"
    },
    {
      "x": -14,
      "y": 119,
      "z": 2,
      "name": "Plant_Leaves_Azure"
    },
    {
      "x": -14,
      "y": 94,
      "z": 3,
      "name": "Rock_Marble"
    },
    {
      "x": -14,
      "y": 95,
      "z": 3,
      "name": "Plant_Moss_Block_Blue"
    },
    {
      "x": -14,
      "y": 96,
      "z": 3,
      "name": "Plant_Moss_Block_Blue"
    },
    {
      "x": -14,
      "y": 97,
      "z": 3,
      "name": "Plant_Moss_Blue"
    },
    {
      "x": -14,
      "y": 112,
      "z": 3,
      "name": "Plant_Moss_Wall_Blue",
      "rotation": 2
    },
    {
      "x": -14,
      "y": 118,
      "z": 3,
      "name": "Plant_Leaves_Azure"
    },
    {
      "x": -14,
      "y": 119,
      "z": 3,
      "name": "Wood_Azure_Branch_Long",
      "rotation": 5
    },
    {
      "x": -14,
      "y": 120,
      "z": 3,
      "name": "Plant_Leaves_Azure"
    },
    {
      "x": -14,
      "y": 121,
      "z": 3,
      "name": "Plant_Fruit_Azure"
    },
    {
      "x": -14,
      "y": 93,
      "z": 4,
      "name": "Rock_Marble"
    },
    {
      "x": -14,
      "y": 94,
      "z": 4,
      "name": "Plant_Moss_Block_Blue"
    },
    {
      "x": -14,
      "y": 95,
      "z": 4,
      "name": "Plant_Moss_Block_Blue"
    },
    {
      "x": -14,
      "y": 96,
      "z": 4,
      "name": "Plant_Moss_Rug_Lime"
    },
    {
      "x": -14,
      "y": 112,
      "z": 4,
      "name": "Wood_Azure_Trunk_Full"
    },
    {
      "x": -14,
      "y": 113,
      "z": 4,
      "name": "Plant_Moss_Rug_Blue"
    },
    {
      "x": -14,
      "y": 117,
      "z": 4,
      "name": "Plant_Leaves_Azure"
    },
    {
      "x": -14,
      "y": 118,
      "z": 4,
      "name": "Plant_Leaves_Azure"
    },
    {
      "x": -14,
      "y": 119,
      "z": 4,
      "name": "Plant_Leaves_Azure"
    },
    {
      "x": -14,
      "y": 120,
      "z": 4,
      "name": "Plant_Leaves_Azure"
    },
    {
      "x": -14,
      "y": 121,
      "z": 4,
      "name": "Plant_Leaves_Azure"
    },
    {
      "x": -14,
      "y": 122,
      "z": 4,
      "name": "Plant_Leaves_Azure"
    },
    {
      "x": -14,
      "y": 93,
      "z": 5,
      "name": "Plant_Moss_Wall_Blue",
      "support": 15
    },
    {
      "x": -14,
      "y": 94,
      "z": 5,
      "name": "Plant_Moss_Wall_Blue",
      "support": 15
    },
    {
      "x": -14,
      "y": 112,
      "z": 5,
      "name": "Plant_Moss_Wall_Blue"
    },
    {
      "x": -14,
      "y": 118,
      "z": 5,
      "name": "Plant_Leaves_Azure"
    },
    {
      "x": -14,
      "y": 119,
      "z": 5,
      "name": "Plant_Leaves_Azure"
    },
    {
      "x": -14,
      "y": 120,
      "z": 5,
      "name": "Plant_Leaves_Azure"
    },
    {
      "x": -14,
      "y": 121,
      "z": 5,
      "name": "Plant_Leaves_Azure"
    },
    {
      "x": -14,
      "y": 122,
      "z": 5,
      "name": "Plant_Leaves_Azure"
    },
    {
      "x": -14,
      "y": 114,
      "z": 6,
      "name": "Plant_Leaves_Azure"
    },
    {
      "x": -14,
      "y": 115,
      "z": 6,
      "name": "Plant_Leaves_Azure"
    },
    {
      "x": -14,
      "y": 116,
      "z": 6,
      "name": "Plant_Leaves_Azure"
    },
    {
      "x": -14,
      "y": 119,
      "z": 6,
      "name": "Plant_Leaves_Azure"
    },
    {
      "x": -14,
      "y": 120,
      "z": 6,
      "name": "Plant_Leaves_Azure"
    },
    {
      "x": -14,
      "y": 121,
      "z": 6,
      "name": "Plant_Leaves_Azure"
    },
    {
      "x": -14,
      "y": 113,
      "z": 7,
      "name": "Plant_Leaves_Azure"
    },
    {
      "x": -14,
      "y": 114,
      "z": 7,
      "name": "Plant_Leaves_Azure"
    },
    {
      "x": -14,
      "y": 115,
      "z": 7,
      "name": "Plant_Leaves_Azure"
    },
    {
      "x": -14,
      "y": 116,
      "z": 7,
      "name": "Plant_Leaves_Azure"
    },
    {
      "x": -14,
      "y": 113,
      "z": 8,
      "name": "Plant_Leaves_Azure"
    },
    {
      "x": -14,
      "y": 114,
      "z": 8,
      "name": "Plant_Leaves_Azure"
    },
    {
      "x": -14,
      "y": 115,
      "z": 8,
      "name": "Plant_Leaves_Azure"
    },
    {
      "x": -14,
      "y": 116,
      "z": 8,
      "name": "Plant_Leaves_Azure"
    },
    {
      "x": -13,
      "y": 96,
      "z": -3,
      "name": "Plant_Moss_Wall_Blue",
      "support": 15,
      "rotation": 3
    },
    {
      "x": -13,
      "y": 113,
      "z": -3,
      "name": "Plant_Leaves_Azure"
    },
    {
      "x": -13,
      "y": 114,
      "z": -3,
      "name": "Plant_Leaves_Azure"
    },
    {
      "x": -13,
      "y": 115,
      "z": -3,
      "name": "Plant_Leaves_Azure"
    },
    {
      "x": -13,
      "y": 94,
      "z": -2,
      "name": "Plant_Moss_Wall_Blue",
      "support": 15,
      "rotation": 3
    },
    {
      "x": -13,
      "y": 95,
      "z": -2,
      "name": "Plant_Moss_Wall_Blue",
      "support": 15,
      "rotation": 3
    },
    {
      "x": -13,
      "y": 96,
      "z": -2,
      "name": "Plant_Moss_Block_Blue"
    },
    {
      "x": -13,
      "y": 97,
      "z": -2,
      "name": "Plant_Moss_Block_Blue"
    },
    {
      "x": -13,
      "y": 98,
      "z": -2,
      "name": "Plant_Moss_Blue"
    },
    {
      "x": -13,
      "y": 112,
      "z": -2,
      "name": "Plant_Leaves_Azure"
    },
    {
      "x": -13,
      "y": 113,
      "z": -2,
      "name": "Plant_Leaves_Azure"
    },
    {
      "x": -13,
      "y": 114,
      "z": -2,
      "name": "Plant_Leaves_Azure"
    },
    {
      "x": -13,
      "y": 115,
      "z": -2,
      "name": "Plant_Leaves_Azure"
    },
    {
      "x": -13,
      "y": 116,
      "z": -2,
      "name": "Plant_Leaves_Azure"
    },
    {
      "x": -13,
      "y": 93,
      "z": -1,
      "name": "Rock_Marble"
    },
    {
      "x": -13,
      "y": 94,
      "z": -1,
      "name": "Rock_Marble"
    },
    {
      "x": -13,
      "y": 95,
      "z": -1,
      "name": "Rock_Marble"
    },
    {
      "x": -13,
      "y": 96,
      "z": -1,
      "name": "Plant_Moss_Block_Blue"
    },
    {
      "x": -13,
      "y": 97,
      "z": -1,
      "name": "Plant_Moss_Block_Blue"
    },
    {
      "x": -13,
      "y": 98,
      "z": -1,
      "name": "Plant_Moss_Rug_Blue"
    },
    {
      "x": -13,
      "y": 113,
      "z": -1,
      "name": "Plant_Leaves_Azure"
    },
    {
      "x": -13,
      "y": 114,
      "z": -1,
      "name": "Plant_Leaves_Azure"
    },
    {
      "x": -13,
      "y": 115,
      "z": -1,
      "name": "Plant_Leaves_Azure"
    },
    {
      "x": -13,
      "y": 116,
      "z": -1,
      "name": "Plant_Leaves_Azure"
    },
    {
      "x": -13,
      "y": 117,
      "z": -1,
      "name": "Plant_Leaves_Azure"
    },
    {
      "x": -13,
      "y": 92,
      "z": 0,
      "name": "Plant_Moss_Wall_Blue",
      "support": 15,
      "rotation": 3
    },
    {
      "x": -13,
      "y": 93,
      "z": 0,
      "name": "Rock_Marble"
    },
    {
      "x": -13,
      "y": 94,
      "z": 0,
      "name": "Rock_Marble"
    },
    {
      "x": -13,
      "y": 95,
      "z": 0,
      "name": "Rock_Marble"
    },
    {
      "x": -13,
      "y": 96,
      "z": 0,
      "name": "Rock_Marble"
    },
    {
      "x": -13,
      "y": 97,
      "z": 0,
      "name": "Plant_Moss_Block_Blue"
    },
    {
      "x": -13,
      "y": 98,
      "z": 0,
      "name": "Plant_Moss_Block_Blue"
    },
    {
      "x": -13,
      "y": 99,
      "z": 0,
      "name": "Plant_Moss_Rug_Blue"
    },
    {
      "x": -13,
      "y": 116,
      "z": 0,
      "name": "Plant_Leaves_Azure"
    },
    {
      "x": -13,
      "y": 117,
      "z": 0,
      "name": "Plant_Leaves_Azure"
    },
    {
      "x": -13,
      "y": 92,
      "z": 1,
      "name": "Plant_Moss_Wall_Blue",
      "support": 15,
      "rotation": 3
    },
    {
      "x": -13,
      "y": 93,
      "z": 1,
      "name": "Rock_Marble"
    },
    {
      "x": -13,
      "y": 94,
      "z": 1,
      "name": "Rock_Marble"
    },
    {
      "x": -13,
      "y": 95,
      "z": 1,
      "name": "Rock_Marble"
    },
    {
      "x": -13,
      "y": 96,
      "z": 1,
      "name": "Rock_Marble"
    },
    {
      "x": -13,
      "y": 97,
      "z": 1,
      "name": "Plant_Moss_Block_Blue"
    },
    {
      "x": -13,
      "y": 98,
      "z": 1,
      "name": "Plant_Moss_Block_Blue"
    },
    {
      "x": -13,
      "y": 99,
      "z": 1,
      "name": "Plant_Moss_Rug_Blue"
    },
    {
      "x": -13,
      "y": 102,
      "z": 1,
      "name": "Wood_Azure_Roots"
    },
    {
      "x": -13,
      "y": 103,
      "z": 1,
      "name": "Wood_Azure_Trunk_Full"
    },
    {
      "x": -13,
      "y": 104,
      "z": 1,
      "name": "Wood_Azure_Trunk_Full"
    },
    {
      "x": -13,
      "y": 92,
      "z": 2,
      "name": "Rock_Marble"
    },
    {
      "x": -13,
      "y": 93,
      "z": 2,
      "name": "Rock_Marble"
    },
    {
      "x": -13,
      "y": 94,
      "z": 2,
      "name": "Rock_Marble"
    },
    {
      "x": -13,
      "y": 95,
      "z": 2,
      "name": "Rock_Marble"
    },
    {
      "x": -13,
      "y": 96,
      "z": 2,
      "name": "Plant_Moss_Block_Blue"
    },
    {
      "x": -13,
      "y": 97,
      "z": 2,
      "name": "Plant_Moss_Block_Blue"
    },
    {
      "x": -13,
      "y": 98,
      "z": 2,
      "name": "Plant_Moss_Blue"
    },
    {
      "x": -13,
      "y": 104,
      "z": 2,
      "name": "Wood_Azure_Trunk_Full"
    },
    {
      "x": -13,
      "y": 105,
      "z": 2,
      "name": "Wood_Azure_Trunk_Full"
    },
    {
      "x": -13,
      "y": 116,
      "z": 2,
      "name": "Wood_Azure_Branch_Long",
      "rotation": 5
    },
    {
      "x": -13,
      "y": 92,
      "z": 3,
      "name": "Rock_Marble"
    },
    {
      "x": -13,
      "y": 93,
      "z": 3,
      "name": "Rock_Marble"
    },
    {
      "x": -13,
      "y": 94,
      "z": 3,
      "name": "Rock_Marble"
    },
    {
      "x": -13,
      "y": 95,
      "z": 3,
      "name": "Rock_Marble"
    },
    {
      "x": -13,
      "y": 96,
      "z": 3,
      "name": "Plant_Moss_Block_Blue"
    },
    {
      "x": -13,
      "y": 97,
      "z": 3,
      "name": "Plant_Moss_Block_Blue"
    },
    {
      "x": -13,
      "y": 98,
      "z": 3,
      "name": "Plant_Moss_Short_Green_Dark"
    },
    {
      "x": -13,
      "y": 105,
      "z": 3,
      "name": "Wood_Azure_Trunk_Full"
    },
    {
      "x": -13,
      "y": 108,
      "z": 3,
      "name": "Plant_Moss_Wall_Blue",
      "rotation": 3
    },
    {
      "x": -13,
      "y": 119,
      "z": 3,
      "name": "Wood_Azure_Branch_Long",
      "rotation": 5
    },
    {
      "x": -13,
      "y": 124,
      "z": 3,
      "name": "Plant_Leaves_Azure"
    },
    {
      "x": -13,
      "y": 92,
      "z": 4,
      "name": "Rock_Marble"
    },
    {
      "x": -13,
      "y": 93,
      "z": 4,
      "name": "Rock_Marble"
    },
    {
      "x": -13,
      "y": 94,
      "z": 4,
      "name": "Rock_Marble"
    },
    {
      "x": -13,
      "y": 95,
      "z": 4,
      "name": "Rock_Marble"
    },
    {
      "x": -13,
      "y": 96,
      "z": 4,
      "name": "Rock_Marble"
    },
    {
      "x": -13,
      "y": 97,
      "z": 4,
      "name": "Rock_Marble"
    },
    {
      "x": -13,
      "y": 98,
      "z": 4,
      "name": "Rock_Marble"
    },
    {
      "x": -13,
      "y": 99,
      "z": 4,
      "name": "Rock_Marble"
    },
    {
      "x": -13,
      "y": 100,
      "z": 4,
      "name": "Plant_Moss_Block_Blue"
    },
    {
      "x": -13,
      "y": 101,
      "z": 4,
      "name": "Plant_Moss_Block_Blue"
    },
    {
      "x": -13,
      "y": 102,
      "z": 4,
      "name": "Plant_Moss_Short_Green_Dark"
    },
    {
      "x": -13,
      "y": 105,
      "z": 4,
      "name": "Wood_Azure_Trunk_Full"
    },
    {
      "x": -13,
      "y": 106,
      "z": 4,
      "name": "Wood_Azure_Trunk_Full"
    },
    {
      "x": -13,
      "y": 112,
      "z": 4,
      "name": "Wood_Azure_Trunk_Full"
    },
    {
      "x": -13,
      "y": 114,
      "z": 4,
      "name": "Wood_Azure_Branch_Corner",
      "rotation": 3
    },
    {
      "x": -13,
      "y": 115,
      "z": 4,
      "name": "Wood_Azure_Branch_Corner",
      "rotation": 8
    },
    {
      "x": -13,
      "y": 119,
      "z": 4,
      "name": "Plant_Leaves_Azure"
    },
    {
      "x": -13,
      "y": 120,
      "z": 4,
      "name": "Plant_Leaves_Azure"
    },
    {
      "x": -13,
      "y": 121,
      "z": 4,
      "name": "Plant_Leaves_Azure"
    },
    {
      "x": -13,
      "y": 93,
      "z": 5,
      "name": "Plant_Moss_Block_Blue"
    },
    {
      "x": -13,
      "y": 94,
      "z": 5,
      "name": "Plant_Moss_Block_Blue"
    },
    {
      "x": -13,
      "y": 95,
      "z": 5,
      "name": "Plant_Moss_Blue"
    },
    {
      "x": -13,
      "y": 98,
      "z": 5,
      "name": "Rock_Marble"
    },
    {
      "x": -13,
      "y": 99,
      "z": 5,
      "name": "Rock_Marble"
    },
    {
      "x": -13,
      "y": 100,
      "z": 5,
      "name": "Rock_Marble"
    },
    {
      "x": -13,
      "y": 101,
      "z": 5,
      "name": "Plant_Moss_Block_Blue"
    },
    {
      "x": -13,
      "y": 102,
      "z": 5,
      "name": "Plant_Moss_Block_Blue"
    },
    {
      "x": -13,
      "y": 103,
      "z": 5,
      "name": "Plant_Moss_Rug_Blue"
    },
    {
      "x": -13,
      "y": 115,
      "z": 5,
      "name": "Wood_Azure_Branch_Long",
      "rotation": 4
    },
    {
      "x": -13,
      "y": 119,
      "z": 5,
      "name": "Plant_Leaves_Azure"
    },
    {
      "x": -13,
      "y": 120,
      "z": 5,
      "name": "Plant_Leaves_Azure"
    },
    {
      "x": -13,
      "y": 121,
      "z": 5,
      "name": "Plant_Leaves_Azure"
    },
    {
      "x": -13,
      "y": 122,
      "z": 5,
      "name": "Plant_Leaves_Azure"
    },
    {
      "x": -13,
      "y": 123,
      "z": 5,
      "name": "Plant_Leaves_Azure"
    },
    {
      "x": -13,
      "y": 124,
      "z": 5,
      "name": "Plant_Fruit_Azure"
    },
    {
      "x": -13,
      "y": 93,
      "z": 6,
      "name": "Plant_Moss_Wall_Blue",
      "support": 15
    },
    {
      "x": -13,
      "y": 98,
      "z": 6,
      "name": "Rock_Marble"
    },
    {
      "x": -13,
      "y": 99,
      "z": 6,
      "name": "Rock_Marble"
    },
    {
      "x": -13,
      "y": 100,
      "z": 6,
      "name": "Rock_Marble"
    },
    {
      "x": -13,
      "y": 101,
      "z": 6,
      "name": "Plant_Moss_Block_Blue"
    },
    {
      "x": -13,
      "y": 102,
      "z": 6,
      "name": "Plant_Moss_Block_Blue"
    },
    {
      "x": -13,
      "y": 103,
      "z": 6,
      "name": "Plant_Moss_Rug_Lime"
    },
    {
      "x": -13,
      "y": 115,
      "z": 6,
      "name": "Wood_Azure_Branch_Long",
      "rotation": 4
    },
    {
      "x": -13,
      "y": 116,
      "z": 6,
      "name": "Plant_Leaves_Azure"
    },
    {
      "x": -13,
      "y": 119,
      "z": 6,
      "name": "Plant_Leaves_Azure"
    },
    {
      "x": -13,
      "y": 120,
      "z": 6,
      "name": "Plant_Leaves_Azure"
    },
    {
      "x": -13,
      "y": 121,
      "z": 6,
      "name": "Plant_Leaves_Azure"
    },
    {
      "x": -13,
      "y": 122,
      "z": 6,
      "name": "Plant_Leaves_Azure"
    },
    {
      "x": -13,
      "y": 98,
      "z": 7,
      "name": "Rock_Marble"
    },
    {
      "x": -13,
      "y": 99,
      "z": 7,
      "name": "Rock_Marble"
    },
    {
      "x": -13,
      "y": 100,
      "z": 7,
      "name": "Rock_Marble"
    },
    {
      "x": -13,
      "y": 101,
      "z": 7,
      "name": "Rock_Marble"
    },
    {
      "x": -13,
      "y": 102,
      "z": 7,
      "name": "Plant_Moss_Short_Green_Dark"
    },
    {
      "x": -13,
      "y": 110,
      "z": 7,
      "name": "Plant_Leaves_Azure"
    },
    {
      "x": -13,
      "y": 114,
      "z": 7,
      "name": "Plant_Leaves_Azure"
    },
    {
      "x": -13,
      "y": 115,
      "z": 7,
      "name": "Plant_Leaves_Azure"
    },
    {
      "x": -13,
      "y": 116,
      "z": 7,
      "name": "Plant_Leaves_Azure"
    },
    {
      "x": -13,
      "y": 117,
      "z": 7,
      "name": "Plant_Leaves_Azure"
    },
    {
      "x": -13,
      "y": 110,
      "z": 8,
      "name": "Plant_Leaves_Azure"
    },
    {
      "x": -13,
      "y": 111,
      "z": 8,
      "name": "Plant_Leaves_Azure"
    },
    {
      "x": -13,
      "y": 114,
      "z": 8,
      "name": "Plant_Leaves_Azure"
    },
    {
      "x": -13,
      "y": 115,
      "z": 8,
      "name": "Plant_Leaves_Azure"
    },
    {
      "x": -13,
      "y": 116,
      "z": 8,
      "name": "Plant_Leaves_Azure"
    },
    {
      "x": -12,
      "y": 96,
      "z": -3,
      "name": "Rock_Marble"
    },
    {
      "x": -12,
      "y": 97,
      "z": -3,
      "name": "Rock_Marble"
    },
    {
      "x": -12,
      "y": 98,
      "z": -3,
      "name": "Plant_Moss_Block_Blue"
    },
    {
      "x": -12,
      "y": 99,
      "z": -3,
      "name": "Plant_Moss_Block_Blue"
    },
    {
      "x": -12,
      "y": 100,
      "z": -3,
      "name": "Plant_Moss_Rug_Blue"
    },
    {
      "x": -12,
      "y": 112,
      "z": -3,
      "name": "Plant_Leaves_Azure"
    },
    {
      "x": -12,
      "y": 113,
      "z": -3,
      "name": "Plant_Leaves_Azure"
    },
    {
      "x": -12,
      "y": 114,
      "z": -3,
      "name": "Plant_Leaves_Azure"
    },
    {
      "x": -12,
      "y": 115,
      "z": -3,
      "name": "Plant_Leaves_Azure"
    },
    {
      "x": -12,
      "y": 94,
      "z": -2,
      "name": "Rock_Marble"
    },
    {
      "x": -12,
      "y": 95,
      "z": -2,
      "name": "Rock_Marble"
    },
    {
      "x": -12,
      "y": 96,
      "z": -2,
      "name": "Rock_Marble"
    },
    {
      "x": -12,
      "y": 97,
      "z": -2,
      "name": "Rock_Marble"
    },
    {
      "x": -12,
      "y": 98,
      "z": -2,
      "name": "Plant_Moss_Block_Blue"
    },
    {
      "x": -12,
      "y": 99,
      "z": -2,
      "name": "Plant_Moss_Block_Blue"
    },
    {
      "x": -12,
      "y": 100,
      "z": -2,
      "name": "Plant_Moss_Rug_Lime"
    },
    {
      "x": -12,
      "y": 111,
      "z": -2,
      "name": "Plant_Leaves_Azure"
    },
    {
      "x": -12,
      "y": 112,
      "z": -2,
      "name": "Plant_Leaves_Azure"
    },
    {
      "x": -12,
      "y": 113,
      "z": -2,
      "name": "Plant_Leaves_Azure"
    },
    {
      "x": -12,
      "y": 114,
      "z": -2,
      "name": "Plant_Leaves_Azure"
    },
    {
      "x": -12,
      "y": 115,
      "z": -2,
      "name": "Plant_Leaves_Azure"
    },
    {
      "x": -12,
      "y": 116,
      "z": -2,
      "name": "Plant_Leaves_Azure"
    },
    {
      "x": -12,
      "y": 92,
      "z": -1,
      "name": "Rock_Marble"
    },
    {
      "x": -12,
      "y": 93,
      "z": -1,
      "name": "Rock_Marble"
    },
    {
      "x": -12,
      "y": 94,
      "z": -1,
      "name": "Rock_Marble"
    },
    {
      "x": -12,
      "y": 95,
      "z": -1,
      "name": "Rock_Marble"
    },
    {
      "x": -12,
      "y": 96,
      "z": -1,
      "name": "Rock_Marble"
    },
    {
      "x": -12,
      "y": 97,
      "z": -1,
      "name": "Rock_Marble"
    },
    {
      "x": -12,
      "y": 98,
      "z": -1,
      "name": "Plant_Moss_Block_Blue"
    },
    {
      "x": -12,
      "y": 99,
      "z": -1,
      "name": "Plant_Moss_Block_Blue"
    },
    {
      "x": -12,
      "y": 100,
      "z": -1,
      "name": "Plant_Moss_Rug_Lime"
    },
    {
      "x": -12,
      "y": 113,
      "z": -1,
      "name": "Plant_Leaves_Azure"
    },
    {
      "x": -12,
      "y": 114,
      "z": -1,
      "name": "Plant_Leaves_Azure"
    },
    {
      "x": -12,
      "y": 115,
      "z": -1,
      "name": "Wood_Azure_Branch_Long",
      "rotation": 4
    },
    {
      "x": -12,
      "y": 116,
      "z": -1,
      "name": "Plant_Leaves_Azure"
    },
    {
      "x": -12,
      "y": 91,
      "z": 0,
      "name": "Rock_Marble"
    },
    {
      "x": -12,
      "y": 92,
      "z": 0,
      "name": "Rock_Marble"
    },
    {
      "x": -12,
      "y": 93,
      "z": 0,
      "name": "Rock_Marble"
    },
    {
      "x": -12,
      "y": 94,
      "z": 0,
      "name": "Rock_Marble"
    },
    {
      "x": -12,
      "y": 95,
      "z": 0,
      "name": "Rock_Marble"
    },
    {
      "x": -12,
      "y": 96,
      "z": 0,
      "name": "Rock_Marble"
    },
    {
      "x": -12,
      "y": 97,
      "z": 0,
      "name": "Rock_Marble"
    },
    {
      "x": -12,
      "y": 98,
      "z": 0,
      "name": "Plant_Moss_Block_Blue"
    },
    {
      "x": -12,
      "y": 99,
      "z": 0,
      "name": "Plant_Moss_Block_Blue"
    },
    {
      "x": -12,
      "y": 100,
      "z": 0,
      "name": "Plant_Moss_Blue"
    },
    {
      "x": -12,
      "y": 115,
      "z": 0,
      "name": "Wood_Azure_Branch_Long",
      "rotation": 4
    },
    {
      "x": -12,
      "y": 120,
      "z": 0,
      "name": "Plant_Leaves_Azure"
    },
    {
      "x": -12,
      "y": 91,
      "z": 1,
      "name": "Plant_Moss_Wall_Blue",
      "support": 15,
      "rotation": 3
    },
    {
      "x": -12,
      "y": 92,
      "z": 1,
      "name": "Rock_Marble"
    },
    {
      "x": -12,
      "y": 93,
      "z": 1,
      "name": "Rock_Marble"
    },
    {
      "x": -12,
      "y": 94,
      "z": 1,
      "name": "Rock_Marble"
    },
    {
      "x": -12,
      "y": 95,
      "z": 1,
      "name": "Rock_Marble"
    },
    {
      "x": -12,
      "y": 96,
      "z": 1,
      "name": "Rock_Marble"
    },
    {
      "x": -12,
      "y": 97,
      "z": 1,
      "name": "Rock_Marble"
    },
    {
      "x": -12,
      "y": 98,
      "z": 1,
      "name": "Plant_Moss_Block_Blue"
    },
    {
      "x": -12,
      "y": 99,
      "z": 1,
      "name": "Plant_Moss_Block_Blue"
    },
    {
      "x": -12,
      "y": 100,
      "z": 1,
      "name": "Plant_Moss_Short_Green_Dark"
    },
    {
      "x": -12,
      "y": 104,
      "z": 1,
      "name": "Wood_Azure_Trunk_Full"
    },
    {
      "x": -12,
      "y": 105,
      "z": 1,
      "name": "Wood_Azure_Trunk_Full"
    },
    {
      "x": -12,
      "y": 115,
      "z": 1,
      "name": "Wood_Azure_Branch_Long",
      "rotation": 4
    },
    {
      "x": -12,
      "y": 120,
      "z": 1,
      "name": "Plant_Leaves_Azure"
    },
    {
      "x": -12,
      "y": 121,
      "z": 1,
      "name": "Plant_Leaves_Azure"
    },
    {
      "x": -12,
      "y": 122,
      "z": 1,
      "name": "Plant_Leaves_Azure"
    },
    {
      "x": -12,
      "y": 90,
      "z": 2,
      "name": "Plant_Moss_Wall_Blue",
      "support": 15,
      "rotation": 3
    },
    {
      "x": -12,
      "y": 91,
      "z": 2,
      "name": "Rock_Marble"
    },
    {
      "x": -12,
      "y": 92,
      "z": 2,
      "name": "Rock_Marble"
    },
    {
      "x": -12,
      "y": 93,
      "z": 2,
      "name": "Rock_Marble"
    },
    {
      "x": -12,
      "y": 94,
      "z": 2,
      "name": "Rock_Marble"
    },
    {
      "x": -12,
      "y": 95,
      "z": 2,
      "name": "Rock_Marble"
    },
    {
      "x": -12,
      "y": 96,
      "z": 2,
      "name": "Rock_Marble"
    },
    {
      "x": -12,
      "y": 97,
      "z": 2,
      "name": "Plant_Moss_Block_Blue"
    },
    {
      "x": -12,
      "y": 98,
      "z": 2,
      "name": "Plant_Moss_Block_Blue"
    },
    {
      "x": -12,
      "y": 99,
      "z": 2,
      "name": "Plant_Moss_Short_Green_Dark"
    },
    {
      "x": -12,
      "y": 103,
      "z": 2,
      "name": "Wood_Azure_Roots"
    },
    {
      "x": -12,
      "y": 104,
      "z": 2,
      "name": "Wood_Azure_Trunk_Full"
    },
    {
      "x": -12,
      "y": 105,
      "z": 2,
      "name": "Wood_Azure_Trunk"
    },
    {
      "x": -12,
      "y": 106,
      "z": 2,
      "name": "Wood_Azure_Trunk_Full"
    },
    {
      "x": -12,
      "y": 108,
      "z": 2,
      "name": "Plant_Moss_Wall_Blue",
      "rotation": 2
    },
    {
      "x": -12,
      "y": 115,
      "z": 2,
      "name": "Wood_Azure_Trunk_Full"
    },
    {
      "x": -12,
      "y": 116,
      "z": 2,
      "name": "Wood_Azure_Trunk"
    },
    {
      "x": -12,
      "y": 117,
      "z": 2,
      "name": "Wood_Azure_Trunk_Full"
    },
    {
      "x": -12,
      "y": 120,
      "z": 2,
      "name": "Wood_Azure_Branch_Long",
      "rotation": 4
    },
    {
      "x": -12,
      "y": 124,
      "z": 2,
      "name": "Plant_Leaves_Azure"
    },
    {
      "x": -12,
      "y": 125,
      "z": 2,
      "name": "Plant_Leaves_Azure"
    },
    {
      "x": -12,
      "y": 126,
      "z": 2,
      "name": "Plant_Leaves_Azure"
    },
    {
      "x": -12,
      "y": 127,
      "z": 2,
      "name": "Plant_Leaves_Azure"
    },
    {
      "x": -12,
      "y": 91,
      "z": 3,
      "name": "Rock_Marble"
    },
    {
      "x": -12,
      "y": 92,
      "z": 3,
      "name": "Rock_Marble"
    },
    {
      "x": -12,
      "y": 93,
      "z": 3,
      "name": "Rock_Marble"
    },
    {
      "x": -12,
      "y": 94,
      "z": 3,
      "name": "Rock_Marble"
    },
    {
      "x": -12,
      "y": 95,
      "z": 3,
      "name": "Rock_Marble"
    },
    {
      "x": -12,
      "y": 96,
      "z": 3,
      "name": "Rock_Marble"
    },
    {
      "x": -12,
      "y": 97,
      "z": 3,
      "name": "Rock_Marble"
    },
    {
      "x": -12,
      "y": 98,
      "z": 3,
      "name": "Rock_Marble"
    },
    {
      "x": -12,
      "y": 99,
      "z": 3,
      "name": "Rock_Marble"
    },
    {
      "x": -12,
      "y": 100,
      "z": 3,
      "name": "Plant_Moss_Block_Blue"
    },
    {
      "x": -12,
      "y": 101,
      "z": 3,
      "name": "Plant_Moss_Block_Blue"
    },
    {
      "x": -12,
      "y": 102,
      "z": 3,
      "name": "Plant_Moss_Rug_Lime"
    },
    {
      "x": -12,
      "y": 105,
      "z": 3,
      "name": "Wood_Azure_Trunk_Full"
    },
    {
      "x": -12,
      "y": 106,
      "z": 3,
      "name": "Wood_Azure_Trunk"
    },
    {
      "x": -12,
      "y": 107,
      "z": 3,
      "name": "Wood_Azure_Trunk"
    },
    {
      "x": -12,
      "y": 108,
      "z": 3,
      "name": "Wood_Azure_Trunk_Full"
    },
    {
      "x": -12,
      "y": 109,
      "z": 3,
      "name": "Plant_Moss_Rug_Blue"
    },
    {
      "x": -12,
      "y": 112,
      "z": 3,
      "name": "Wood_Azure_Trunk_Full"
    },
    {
      "x": -12,
      "y": 113,
      "z": 3,
      "name": "Wood_Azure_Trunk"
    },
    {
      "x": -12,
      "y": 114,
      "z": 3,
      "name": "Wood_Azure_Trunk"
    },
    {
      "x": -12,
      "y": 115,
      "z": 3,
      "name": "Wood_Azure_Trunk"
    },
    {
      "x": -12,
      "y": 116,
      "z": 3,
      "name": "Wood_Azure_Trunk"
    },
    {
      "x": -12,
      "y": 117,
      "z": 3,
      "name": "Wood_Azure_Trunk"
    },
    {
      "x": -12,
      "y": 118,
      "z": 3,
      "name": "Wood_Azure_Trunk"
    },
    {
      "x": -12,
      "y": 119,
      "z": 3,
      "name": "Wood_Azure_Trunk"
    },
    {
      "x": -12,
      "y": 120,
      "z": 3,
      "name": "Wood_Azure_Trunk"
    },
    {
      "x": -12,
      "y": 121,
      "z": 3,
      "name": "Wood_Azure_Trunk_Full"
    },
    {
      "x": -12,
      "y": 122,
      "z": 3,
      "name": "Wood_Azure_Branch_Long"
    },
    {
      "x": -12,
      "y": 123,
      "z": 3,
      "name": "Wood_Azure_Branch_Long"
    },
    {
      "x": -12,
      "y": 124,
      "z": 3,
      "name": "Wood_Azure_Branch_Long"
    },
    {
      "x": -12,
      "y": 125,
      "z": 3,
      "name": "Plant_Leaves_Azure"
    },
    {
      "x": -12,
      "y": 126,
      "z": 3,
      "name": "Plant_Leaves_Azure"
    },
    {
      "x": -12,
      "y": 90,
      "z": 4,
      "name": "Rock_Marble"
    },
    {
      "x": -12,
      "y": 91,
      "z": 4,
      "name": "Rock_Marble"
    },
    {
      "x": -12,
      "y": 92,
      "z": 4,
      "name": "Rock_Marble"
    },
    {
      "x": -12,
      "y": 93,
      "z": 4,
      "name": "Rock_Marble"
    },
    {
      "x": -12,
      "y": 94,
      "z": 4,
      "name": "Rock_Marble"
    },
    {
      "x": -12,
      "y": 95,
      "z": 4,
      "name": "Rock_Marble"
    },
    {
      "x": -12,
      "y": 96,
      "z": 4,
      "name": "Rock_Marble"
    },
    {
      "x": -12,
      "y": 97,
      "z": 4,
      "name": "Rock_Marble"
    },
    {
      "x": -12,
      "y": 98,
      "z": 4,
      "name": "Rock_Marble"
    },
    {
      "x": -12,
      "y": 99,
      "z": 4,
      "name": "Rock_Marble"
    },
    {
      "x": -12,
      "y": 100,
      "z": 4,
      "name": "Rock_Marble"
    },
    {
      "x": -12,
      "y": 101,
      "z": 4,
      "name": "Rock_Marble"
    },
    {
      "x": -12,
      "y": 102,
      "z": 4,
      "name": "Plant_Moss_Block_Blue"
    },
    {
      "x": -12,
      "y": 103,
      "z": 4,
      "name": "Plant_Moss_Block_Blue"
    },
    {
      "x": -12,
      "y": 104,
      "z": 4,
      "name": "Plant_Moss_Rug_Blue"
    },
    {
      "x": -12,
      "y": 106,
      "z": 4,
      "name": "Wood_Azure_Trunk_Full"
    },
    {
      "x": -12,
      "y": 107,
      "z": 4,
      "name": "Wood_Azure_Trunk"
    },
    {
      "x": -12,
      "y": 108,
      "z": 4,
      "name": "Wood_Azure_Trunk"
    },
    {
      "x": -12,
      "y": 109,
      "z": 4,
      "name": "Wood_Azure_Trunk"
    },
    {
      "x": -12,
      "y": 110,
      "z": 4,
      "name": "Wood_Azure_Trunk"
    },
    {
      "x": -12,
      "y": 111,
      "z": 4,
      "name": "Wood_Azure_Trunk"
    },
    {
      "x": -12,
      "y": 112,
      "z": 4,
      "name": "Wood_Azure_Trunk"
    },
    {
      "x": -12,
      "y": 113,
      "z": 4,
      "name": "Wood_Azure_Trunk"
    },
    {
      "x": -12,
      "y": 114,
      "z": 4,
      "name": "Wood_Azure_Trunk_Full"
    },
    {
      "x": -12,
      "y": 116,
      "z": 4,
      "name": "Plant_Moss_Wall_Blue",
      "rotation": 3
    },
    {
      "x": -12,
      "y": 121,
      "z": 4,
      "name": "Wood_Azure_Branch_Long",
      "rotation": 4
    },
    {
      "x": -12,
      "y": 123,
      "z": 4,
      "name": "Plant_Leaves_Azure"
    },
    {
      "x": -12,
      "y": 124,
      "z": 4,
      "name": "Plant_Leaves_Azure"
    },
    {
      "x": -12,
      "y": 92,
      "z": 5,
      "name": "Rock_Marble"
    },
    {
      "x": -12,
      "y": 93,
      "z": 5,
      "name": "Rock_Marble"
    },
    {
      "x": -12,
      "y": 94,
      "z": 5,
      "name": "Rock_Marble"
    },
    {
      "x": -12,
      "y": 95,
      "z": 5,
      "name": "Rock_Marble"
    },
    {
      "x": -12,
      "y": 96,
      "z": 5,
      "name": "Rock_Marble"
    },
    {
      "x": -12,
      "y": 97,
      "z": 5,
      "name": "Rock_Marble"
    },
    {
      "x": -12,
      "y": 98,
      "z": 5,
      "name": "Rock_Marble"
    },
    {
      "x": -12,
      "y": 99,
      "z": 5,
      "name": "Rock_Marble"
    },
    {
      "x": -12,
      "y": 100,
      "z": 5,
      "name": "Rock_Marble"
    },
    {
      "x": -12,
      "y": 101,
      "z": 5,
      "name": "Rock_Marble"
    },
    {
      "x": -12,
      "y": 102,
      "z": 5,
      "name": "Plant_Moss_Block_Blue"
    },
    {
      "x": -12,
      "y": 103,
      "z": 5,
      "name": "Plant_Moss_Block_Blue"
    },
    {
      "x": -12,
      "y": 104,
      "z": 5,
      "name": "Plant_Moss_Blue"
    },
    {
      "x": -12,
      "y": 106,
      "z": 5,
      "name": "Wood_Azure_Trunk_Full"
    },
    {
      "x": -12,
      "y": 107,
      "z": 5,
      "name": "Wood_Azure_Trunk"
    },
    {
      "x": -12,
      "y": 108,
      "z": 5,
      "name": "Wood_Azure_Trunk"
    },
    {
      "x": -12,
      "y": 109,
      "z": 5,
      "name": "Wood_Azure_Trunk"
    },
    {
      "x": -12,
      "y": 110,
      "z": 5,
      "name": "Wood_Azure_Trunk_Full"
    },
    {
      "x": -12,
      "y": 121,
      "z": 5,
      "name": "Plant_Leaves_Azure"
    },
    {
      "x": -12,
      "y": 122,
      "z": 5,
      "name": "Plant_Leaves_Azure"
    },
    {
      "x": -12,
      "y": 123,
      "z": 5,
      "name": "Plant_Leaves_Azure"
    },
    {
      "x": -12,
      "y": 92,
      "z": 6,
      "name": "Plant_Moss_Wall_Blue",
      "support": 15
    },
    {
      "x": -12,
      "y": 94,
      "z": 6,
      "name": "Rock_Marble"
    },
    {
      "x": -12,
      "y": 95,
      "z": 6,
      "name": "Rock_Marble"
    },
    {
      "x": -12,
      "y": 96,
      "z": 6,
      "name": "Rock_Marble"
    },
    {
      "x": -12,
      "y": 97,
      "z": 6,
      "name": "Rock_Marble"
    },
    {
      "x": -12,
      "y": 98,
      "z": 6,
      "name": "Rock_Marble"
    },
    {
      "x": -12,
      "y": 99,
      "z": 6,
      "name": "Rock_Marble"
    },
    {
      "x": -12,
      "y": 100,
      "z": 6,
      "name": "Rock_Marble"
    },
    {
      "x": -12,
      "y": 101,
      "z": 6,
      "name": "Rock_Marble"
    },
    {
      "x": -12,
      "y": 102,
      "z": 6,
      "name": "Rock_Marble"
    },
    {
      "x": -12,
      "y": 103,
      "z": 6,
      "name": "Plant_Moss_Block_Blue"
    },
    {
      "x": -12,
      "y": 104,
      "z": 6,
      "name": "Plant_Moss_Block_Blue"
    },
    {
      "x": -12,
      "y": 105,
      "z": 6,
      "name": "Plant_Moss_Rug_Blue"
    },
    {
      "x": -12,
      "y": 115,
      "z": 6,
      "name": "Plant_Leaves_Azure"
    },
    {
      "x": -12,
      "y": 116,
      "z": 6,
      "name": "Plant_Leaves_Azure"
    },
    {
      "x": -12,
      "y": 117,
      "z": 6,
      "name": "Plant_Leaves_Azure"
    },
    {
      "x": -12,
      "y": 121,
      "z": 6,
      "name": "Plant_Leaves_Azure"
    },
    {
      "x": -12,
      "y": 122,
      "z": 6,
      "name": "Plant_Leaves_Azure"
    },
    {
      "x": -12,
      "y": 96,
      "z": 7,
      "name": "Rock_Marble"
    },
    {
      "x": -12,
      "y": 97,
      "z": 7,
      "name": "Rock_Marble"
    },
    {
      "x": -12,
      "y": 98,
      "z": 7,
      "name": "Rock_Marble"
    },
    {
      "x": -12,
      "y": 99,
      "z": 7,
      "name": "Rock_Marble"
    },
    {
      "x": -12,
      "y": 100,
      "z": 7,
      "name": "Rock_Marble"
    },
    {
      "x": -12,
      "y": 101,
      "z": 7,
      "name": "Rock_Marble"
    },
    {
      "x": -12,
      "y": 102,
      "z": 7,
      "name": "Plant_Moss_Block_Blue"
    },
    {
      "x": -12,
      "y": 103,
      "z": 7,
      "name": "Plant_Moss_Block_Blue"
    },
    {
      "x": -12,
      "y": 104,
      "z": 7,
      "name": "Plant_Moss_Blue"
    },
    {
      "x": -12,
      "y": 109,
      "z": 7,
      "name": "Plant_Leaves_Azure"
    },
    {
      "x": -12,
      "y": 110,
      "z": 7,
      "name": "Plant_Leaves_Azure"
    },
    {
      "x": -12,
      "y": 111,
      "z": 7,
      "name": "Plant_Leaves_Azure"
    },
    {
      "x": -12,
      "y": 115,
      "z": 7,
      "name": "Plant_Leaves_Azure"
    },
    {
      "x": -12,
      "y": 116,
      "z": 7,
      "name": "Plant_Leaves_Azure"
    },
    {
      "x": -12,
      "y": 117,
      "z": 7,
      "name": "Plant_Leaves_Azure"
    },
    {
      "x": -12,
      "y": 118,
      "z": 7,
      "name": "Plant_Fruit_Azure"
    },
    {
      "x": -12,
      "y": 98,
      "z": 8,
      "name": "Rock_Marble"
    },
    {
      "x": -12,
      "y": 99,
      "z": 8,
      "name": "Rock_Marble"
    },
    {
      "x": -12,
      "y": 100,
      "z": 8,
      "name": "Rock_Marble"
    },
    {
      "x": -12,
      "y": 101,
      "z": 8,
      "name": "Rock_Marble"
    },
    {
      "x": -12,
      "y": 102,
      "z": 8,
      "name": "Plant_Moss_Block_Blue"
    },
    {
      "x": -12,
      "y": 103,
      "z": 8,
      "name": "Plant_Moss_Rug_Lime"
    },
    {
      "x": -12,
      "y": 109,
      "z": 8,
      "name": "Plant_Leaves_Azure"
    },
    {
      "x": -12,
      "y": 110,
      "z": 8,
      "name": "Plant_Leaves_Azure"
    },
    {
      "x": -12,
      "y": 111,
      "z": 8,
      "name": "Plant_Leaves_Azure"
    },
    {
      "x": -12,
      "y": 112,
      "z": 8,
      "name": "Plant_Leaves_Azure"
    },
    {
      "x": -12,
      "y": 113,
      "z": 8,
      "name": "Plant_Fruit_Azure"
    },
    {
      "x": -12,
      "y": 116,
      "z": 8,
      "name": "Plant_Leaves_Azure"
    },
    {
      "x": -12,
      "y": 117,
      "z": 8,
      "name": "Plant_Leaves_Azure"
    },
    {
      "x": -12,
      "y": 110,
      "z": 9,
      "name": "Plant_Leaves_Azure"
    },
    {
      "x": -12,
      "y": 111,
      "z": 9,
      "name": "Plant_Leaves_Azure"
    },
    {
      "x": -11,
      "y": 96,
      "z": -4,
      "name": "Rock_Marble"
    },
    {
      "x": -11,
      "y": 97,
      "z": -4,
      "name": "Rock_Marble"
    },
    {
      "x": -11,
      "y": 98,
      "z": -4,
      "name": "Plant_Moss_Block_Blue"
    },
    {
      "x": -11,
      "y": 99,
      "z": -4,
      "name": "Plant_Moss_Block_Blue"
    },
    {
      "x": -11,
      "y": 100,
      "z": -4,
      "name": "Plant_Moss_Rug_Lime"
    },
    {
      "x": -11,
      "y": 95,
      "z": -3,
      "name": "Rock_Marble"
    },
    {
      "x": -11,
      "y": 96,
      "z": -3,
      "name": "Rock_Marble"
    },
    {
      "x": -11,
      "y": 97,
      "z": -3,
      "name": "Rock_Marble"
    },
    {
      "x": -11,
      "y": 98,
      "z": -3,
      "name": "Plant_Moss_Block_Blue"
    },
    {
      "x": -11,
      "y": 99,
      "z": -3,
      "name": "Plant_Moss_Block_Blue"
    },
    {
      "x": -11,
      "y": 100,
      "z": -3,
      "name": "Plant_Moss_Rug_Lime"
    },
    {
      "x": -11,
      "y": 111,
      "z": -3,
      "name": "Plant_Leaves_Azure"
    },
    {
      "x": -11,
      "y": 112,
      "z": -3,
      "name": "Plant_Leaves_Azure"
    },
    {
      "x": -11,
      "y": 113,
      "z": -3,
      "name": "Plant_Leaves_Azure"
    },
    {
      "x": -11,
      "y": 114,
      "z": -3,
      "name": "Plant_Leaves_Azure"
    },
    {
      "x": -11,
      "y": 93,
      "z": -2,
      "name": "Rock_Marble"
    },
    {
      "x": -11,
      "y": 94,
      "z": -2,
      "name": "Rock_Marble"
    },
    {
      "x": -11,
      "y": 95,
      "z": -2,
      "name": "Rock_Marble"
    },
    {
      "x": -11,
      "y": 96,
      "z": -2,
      "name": "Rock_Marble"
    },
    {
      "x": -11,
      "y": 97,
      "z": -2,
      "name": "Rock_Marble"
    },
    {
      "x": -11,
      "y": 98,
      "z": -2,
      "name": "Rock_Marble"
    },
    {
      "x": -11,
      "y": 99,
      "z": -2,
      "name": "Plant_Moss_Block_Blue"
    },
    {
      "x": -11,
      "y": 100,
      "z": -2,
      "name": "Plant_Moss_Block_Blue"
    },
    {
      "x": -11,
      "y": 101,
      "z": -2,
      "name": "Plant_Moss_Rug_Lime"
    },
    {
      "x": -11,
      "y": 111,
      "z": -2,
      "name": "Plant_Leaves_Azure"
    },
    {
      "x": -11,
      "y": 112,
      "z": -2,
      "name": "Plant_Leaves_Azure"
    },
    {
      "x": -11,
      "y": 113,
      "z": -2,
      "name": "Plant_Leaves_Azure"
    },
    {
      "x": -11,
      "y": 114,
      "z": -2,
      "name": "Plant_Leaves_Azure"
    },
    {
      "x": -11,
      "y": 115,
      "z": -2,
      "name": "Plant_Leaves_Azure"
    },
    {
      "x": -11,
      "y": 116,
      "z": -2,
      "name": "Plant_Fruit_Azure"
    },
    {
      "x": -11,
      "y": 90,
      "z": -1,
      "name": "Rock_Marble"
    },
    {
      "x": -11,
      "y": 91,
      "z": -1,
      "name": "Rock_Marble"
    },
    {
      "x": -11,
      "y": 92,
      "z": -1,
      "name": "Rock_Marble"
    },
    {
      "x": -11,
      "y": 93,
      "z": -1,
      "name": "Rock_Marble"
    },
    {
      "x": -11,
      "y": 94,
      "z": -1,
      "name": "Rock_Marble"
    },
    {
      "x": -11,
      "y": 95,
      "z": -1,
      "name": "Rock_Marble"
    },
    {
      "x": -11,
      "y": 96,
      "z": -1,
      "name": "Rock_Marble"
    },
    {
      "x": -11,
      "y": 97,
      "z": -1,
      "name": "Rock_Marble"
    },
    {
      "x": -11,
      "y": 98,
      "z": -1,
      "name": "Rock_Marble"
    },
    {
      "x": -11,
      "y": 99,
      "z": -1,
      "name": "Plant_Moss_Block_Blue"
    },
    {
      "x": -11,
      "y": 100,
      "z": -1,
      "name": "Plant_Moss_Block_Blue"
    },
    {
      "x": -11,
      "y": 101,
      "z": -1,
      "name": "Plant_Moss_Rug_Blue"
    },
    {
      "x": -11,
      "y": 112,
      "z": -1,
      "name": "Plant_Leaves_Azure"
    },
    {
      "x": -11,
      "y": 113,
      "z": -1,
      "name": "Wood_Azure_Branch_Long",
      "rotation": 4
    },
    {
      "x": -11,
      "y": 114,
      "z": -1,
      "name": "Plant_Leaves_Azure"
    },
    {
      "x": -11,
      "y": 115,
      "z": -1,
      "name": "Plant_Leaves_Azure"
    },
    {
      "x": -11,
      "y": 90,
      "z": 0,
      "name": "Rock_Marble"
    },
    {
      "x": -11,
      "y": 91,
      "z": 0,
      "name": "Rock_Marble"
    },
    {
      "x": -11,
      "y": 92,
      "z": 0,
      "name": "Rock_Marble"
    },
    {
      "x": -11,
      "y": 93,
      "z": 0,
      "name": "Rock_Marble"
    },
    {
      "x": -11,
      "y": 94,
      "z": 0,
      "name": "Rock_Marble"
    },
    {
      "x": -11,
      "y": 95,
      "z": 0,
      "name": "Rock_Marble"
    },
    {
      "x": -11,
      "y": 96,
      "z": 0,
      "name": "Rock_Marble"
    },
    {
      "x": -11,
      "y": 97,
      "z": 0,
      "name": "Rock_Marble"
    },
    {
      "x": -11,
      "y": 98,
      "z": 0,
      "name": "Rock_Marble"
    },
    {
      "x": -11,
      "y": 99,
      "z": 0,
      "name": "Plant_Moss_Block_Blue"
    },
    {
      "x": -11,
      "y": 100,
      "z": 0,
      "name": "Plant_Moss_Block_Blue"
    },
    {
      "x": -11,
      "y": 101,
      "z": 0,
      "name": "Plant_Moss_Blue"
    },
    {
      "x": -11,
      "y": 113,
      "z": 0,
      "name": "Wood_Azure_Branch_Long",
      "rotation": 4
    },
    {
      "x": -11,
      "y": 119,
      "z": 0,
      "name": "Plant_Leaves_Azure"
    },
    {
      "x": -11,
      "y": 120,
      "z": 0,
      "name": "Plant_Leaves_Azure"
    },
    {
      "x": -11,
      "y": 121,
      "z": 0,
      "name": "Plant_Leaves_Azure"
    },
    {
      "x": -11,
      "y": 91,
      "z": 1,
      "name": "Rock_Marble"
    },
    {
      "x": -11,
      "y": 92,
      "z": 1,
      "name": "Rock_Marble"
    },
    {
      "x": -11,
      "y": 93,
      "z": 1,
      "name": "Rock_Marble"
    },
    {
      "x": -11,
      "y": 94,
      "z": 1,
      "name": "Rock_Marble"
    },
    {
      "x": -11,
      "y": 95,
      "z": 1,
      "name": "Rock_Marble"
    },
    {
      "x": -11,
      "y": 96,
      "z": 1,
      "name": "Rock_Marble"
    },
    {
      "x": -11,
      "y": 97,
      "z": 1,
      "name": "Rock_Marble"
    },
    {
      "x": -11,
      "y": 98,
      "z": 1,
      "name": "Rock_Marble"
    },
    {
      "x": -11,
      "y": 99,
      "z": 1,
      "name": "Rock_Marble"
    },
    {
      "x": -11,
      "y": 100,
      "z": 1,
      "name": "Rock_Marble"
    },
    {
      "x": -11,
      "y": 101,
      "z": 1,
      "name": "Plant_Moss_Block_Blue"
    },
    {
      "x": -11,
      "y": 102,
      "z": 1,
      "name": "Plant_Moss_Block_Blue"
    },
    {
      "x": -11,
      "y": 103,
      "z": 1,
      "name": "Plant_Moss_Blue"
    },
    {
      "x": -11,
      "y": 113,
      "z": 1,
      "name": "Wood_Azure_Branch_Long",
      "rotation": 4
    },
    {
      "x": -11,
      "y": 118,
      "z": 1,
      "name": "Plant_Leaves_Azure"
    },
    {
      "x": -11,
      "y": 119,
      "z": 1,
      "name": "Plant_Leaves_Azure"
    },
    {
      "x": -11,
      "y": 120,
      "z": 1,
      "name": "Plant_Leaves_Azure"
    },
    {
      "x": -11,
      "y": 121,
      "z": 1,
      "name": "Plant_Leaves_Azure"
    },
    {
      "x": -11,
      "y": 90,
      "z": 2,
      "name": "Rock_Marble"
    },
    {
      "x": -11,
      "y": 91,
      "z": 2,
      "name": "Rock_Marble"
    },
    {
      "x": -11,
      "y": 92,
      "z": 2,
      "name": "Rock_Marble"
    },
    {
      "x": -11,
      "y": 93,
      "z": 2,
      "name": "Rock_Marble"
    },
    {
      "x": -11,
      "y": 94,
      "z": 2,
      "name": "Rock_Marble"
    },
    {
      "x": -11,
      "y": 95,
      "z": 2,
      "name": "Rock_Marble"
    },
    {
      "x": -11,
      "y": 96,
      "z": 2,
      "name": "Rock_Marble"
    },
    {
      "x": -11,
      "y": 97,
      "z": 2,
      "name": "Rock_Marble"
    },
    {
      "x": -11,
      "y": 98,
      "z": 2,
      "name": "Rock_Marble"
    },
    {
      "x": -11,
      "y": 99,
      "z": 2,
      "name": "Rock_Marble"
    },
    {
      "x": -11,
      "y": 100,
      "z": 2,
      "name": "Rock_Marble"
    },
    {
      "x": -11,
      "y": 101,
      "z": 2,
      "name": "Rock_Marble"
    },
    {
      "x": -11,
      "y": 102,
      "z": 2,
      "name": "Plant_Moss_Block_Blue"
    },
    {
      "x": -11,
      "y": 103,
      "z": 2,
      "name": "Plant_Moss_Block_Blue"
    },
    {
      "x": -11,
      "y": 104,
      "z": 2,
      "name": "Plant_Moss_Rug_Lime"
    },
    {
      "x": -11,
      "y": 105,
      "z": 2,
      "name": "Wood_Azure_Trunk_Full"
    },
    {
      "x": -11,
      "y": 106,
      "z": 2,
      "name": "Wood_Azure_Trunk"
    },
    {
      "x": -11,
      "y": 107,
      "z": 2,
      "name": "Wood_Azure_Trunk_Full"
    },
    {
      "x": -11,
      "y": 113,
      "z": 2,
      "name": "Wood_Azure_Trunk_Full"
    },
    {
      "x": -11,
      "y": 114,
      "z": 2,
      "name": "Wood_Azure_Trunk"
    },
    {
      "x": -11,
      "y": 115,
      "z": 2,
      "name": "Wood_Azure_Trunk_Full"
    },
    {
      "x": -11,
      "y": 118,
      "z": 2,
      "name": "Wood_Azure_Branch_Long",
      "rotation": 4
    },
    {
      "x": -11,
      "y": 123,
      "z": 2,
      "name": "Plant_Leaves_Azure"
    },
    {
      "x": -11,
      "y": 124,
      "z": 2,
      "name": "Plant_Leaves_Azure"
    },
    {
      "x": -11,
      "y": 125,
      "z": 2,
      "name": "Plant_Leaves_Azure"
    },
    {
      "x": -11,
      "y": 126,
      "z": 2,
      "name": "Plant_Leaves_Azure"
    },
    {
      "x": -11,
      "y": 90,
      "z": 3,
      "name": "Rock_Marble"
    },
    {
      "x": -11,
      "y": 91,
      "z": 3,
      "name": "Rock_Marble"
    },
    {
      "x": -11,
      "y": 92,
      "z": 3,
      "name": "Rock_Marble"
    },
    {
      "x": -11,
      "y": 93,
      "z": 3,
      "name": "Rock_Marble"
    },
    {
      "x": -11,
      "y": 94,
      "z": 3,
      "name": "Rock_Marble"
    },
    {
      "x": -11,
      "y": 95,
      "z": 3,
      "name": "Rock_Marble"
    },
    {
      "x": -11,
      "y": 96,
      "z": 3,
      "name": "Rock_Marble"
    },
    {
      "x": -11,
      "y": 97,
      "z": 3,
      "name": "Rock_Marble"
    },
    {
      "x": -11,
      "y": 98,
      "z": 3,
      "name": "Rock_Marble"
    },
    {
      "x": -11,
      "y": 99,
      "z": 3,
      "name": "Rock_Marble"
    },
    {
      "x": -11,
      "y": 100,
      "z": 3,
      "name": "Rock_Marble"
    },
    {
      "x": -11,
      "y": 101,
      "z": 3,
      "name": "Rock_Marble"
    },
    {
      "x": -11,
      "y": 102,
      "z": 3,
      "name": "Rock_Marble"
    },
    {
      "x": -11,
      "y": 103,
      "z": 3,
      "name": "Plant_Moss_Block_Blue"
    },
    {
      "x": -11,
      "y": 104,
      "z": 3,
      "name": "Plant_Moss_Block_Blue"
    },
    {
      "x": -11,
      "y": 105,
      "z": 3,
      "name": "Wood_Azure_Trunk_Full"
    },
    {
      "x": -11,
      "y": 106,
      "z": 3,
      "name": "Wood_Azure_Trunk"
    },
    {
      "x": -11,
      "y": 107,
      "z": 3,
      "name": "Wood_Azure_Trunk"
    },
    {
      "x": -11,
      "y": 108,
      "z": 3,
      "name": "Wood_Azure_Trunk"
    },
    {
      "x": -11,
      "y": 109,
      "z": 3,
      "name": "Wood_Azure_Trunk"
    },
    {
      "x": -11,
      "y": 110,
      "z": 3,
      "name": "Wood_Azure_Trunk"
    },
    {
      "x": -11,
      "y": 111,
      "z": 3,
      "name": "Wood_Azure_Trunk"
    },
    {
      "x": -11,
      "y": 112,
      "z": 3,
      "name": "Wood_Azure_Trunk"
    },
    {
      "x": -11,
      "y": 113,
      "z": 3,
      "name": "Wood_Azure_Trunk"
    },
    {
      "x": -11,
      "y": 114,
      "z": 3,
      "name": "Wood_Azure_Trunk"
    },
    {
      "x": -11,
      "y": 115,
      "z": 3,
      "name": "Wood_Azure_Trunk"
    },
    {
      "x": -11,
      "y": 116,
      "z": 3,
      "name": "Wood_Azure_Trunk"
    },
    {
      "x": -11,
      "y": 117,
      "z": 3,
      "name": "Wood_Azure_Trunk"
    },
    {
      "x": -11,
      "y": 118,
      "z": 3,
      "name": "Wood_Azure_Trunk_Full"
    },
    {
      "x": -11,
      "y": 121,
      "z": 3,
      "name": "Plant_Moss_Wall_Blue",
      "rotation": 1
    },
    {
      "x": -11,
      "y": 123,
      "z": 3,
      "name": "Plant_Leaves_Azure"
    },
    {
      "x": -11,
      "y": 124,
      "z": 3,
      "name": "Plant_Leaves_Azure"
    },
    {
      "x": -11,
      "y": 125,
      "z": 3,
      "name": "Plant_Leaves_Azure"
    },
    {
      "x": -11,
      "y": 126,
      "z": 3,
      "name": "Plant_Fruit_Azure"
    },
    {
      "x": -11,
      "y": 90,
      "z": 4,
      "name": "Rock_Marble"
    },
    {
      "x": -11,
      "y": 91,
      "z": 4,
      "name": "Rock_Marble"
    },
    {
      "x": -11,
      "y": 92,
      "z": 4,
      "name": "Rock_Marble"
    },
    {
      "x": -11,
      "y": 93,
      "z": 4,
      "name": "Rock_Marble"
    },
    {
      "x": -11,
      "y": 94,
      "z": 4,
      "name": "Rock_Marble"
    },
    {
      "x": -11,
      "y": 95,
      "z": 4,
      "name": "Rock_Marble"
    },
    {
      "x": -11,
      "y": 96,
      "z": 4,
      "name": "Rock_Marble"
    },
    {
      "x": -11,
      "y": 97,
      "z": 4,
      "name": "Rock_Marble"
    },
    {
      "x": -11,
      "y": 98,
      "z": 4,
      "name": "Rock_Marble"
    },
    {
      "x": -11,
      "y": 99,
      "z": 4,
      "name": "Rock_Marble"
    },
    {
      "x": -11,
      "y": 100,
      "z": 4,
      "name": "Rock_Marble"
    },
    {
      "x": -11,
      "y": 101,
      "z": 4,
      "name": "Rock_Marble"
    },
    {
      "x": -11,
      "y": 102,
      "z": 4,
      "name": "Rock_Marble"
    },
    {
      "x": -11,
      "y": 103,
      "z": 4,
      "name": "Plant_Moss_Block_Blue"
    },
    {
      "x": -11,
      "y": 104,
      "z": 4,
      "name": "Plant_Moss_Block_Blue"
    },
    {
      "x": -11,
      "y": 105,
      "z": 4,
      "name": "Plant_Moss_Blue"
    },
    {
      "x": -11,
      "y": 106,
      "z": 4,
      "name": "Wood_Azure_Trunk"
    },
    {
      "x": -11,
      "y": 107,
      "z": 4,
      "name": "Wood_Azure_Trunk"
    },
    {
      "x": -11,
      "y": 108,
      "z": 4,
      "name": "Wood_Azure_Trunk"
    },
    {
      "x": -11,
      "y": 109,
      "z": 4,
      "name": "Wood_Azure_Trunk"
    },
    {
      "x": -11,
      "y": 110,
      "z": 4,
      "name": "Wood_Azure_Trunk"
    },
    {
      "x": -11,
      "y": 111,
      "z": 4,
      "name": "Wood_Azure_Trunk"
    },
    {
      "x": -11,
      "y": 112,
      "z": 4,
      "name": "Wood_Azure_Trunk"
    },
    {
      "x": -11,
      "y": 113,
      "z": 4,
      "name": "Wood_Azure_Trunk"
    },
    {
      "x": -11,
      "y": 114,
      "z": 4,
      "name": "Wood_Azure_Trunk"
    },
    {
      "x": -11,
      "y": 115,
      "z": 4,
      "name": "Wood_Azure_Trunk"
    },
    {
      "x": -11,
      "y": 116,
      "z": 4,
      "name": "Wood_Azure_Trunk_Full"
    },
    {
      "x": -11,
      "y": 117,
      "z": 4,
      "name": "Plant_Moss_Rug_Blue"
    },
    {
      "x": -11,
      "y": 118,
      "z": 4,
      "name": "Wood_Azure_Branch_Long",
      "rotation": 4
    },
    {
      "x": -11,
      "y": 121,
      "z": 4,
      "name": "Plant_Leaves_Azure"
    },
    {
      "x": -11,
      "y": 122,
      "z": 4,
      "name": "Plant_Leaves_Azure"
    },
    {
      "x": -11,
      "y": 123,
      "z": 4,
      "name": "Plant_Leaves_Azure"
    },
    {
      "x": -11,
      "y": 124,
      "z": 4,
      "name": "Plant_Leaves_Azure"
    },
    {
      "x": -11,
      "y": 91,
      "z": 5,
      "name": "Rock_Marble"
    },
    {
      "x": -11,
      "y": 92,
      "z": 5,
      "name": "Rock_Marble"
    },
    {
      "x": -11,
      "y": 93,
      "z": 5,
      "name": "Rock_Marble"
    },
    {
      "x": -11,
      "y": 94,
      "z": 5,
      "name": "Rock_Marble"
    },
    {
      "x": -11,
      "y": 95,
      "z": 5,
      "name": "Rock_Marble"
    },
    {
      "x": -11,
      "y": 96,
      "z": 5,
      "name": "Rock_Marble"
    },
    {
      "x": -11,
      "y": 97,
      "z": 5,
      "name": "Rock_Marble"
    },
    {
      "x": -11,
      "y": 98,
      "z": 5,
      "name": "Rock_Marble"
    },
    {
      "x": -11,
      "y": 99,
      "z": 5,
      "name": "Rock_Marble"
    },
    {
      "x": -11,
      "y": 100,
      "z": 5,
      "name": "Rock_Marble"
    },
    {
      "x": -11,
      "y": 101,
      "z": 5,
      "name": "Rock_Marble"
    },
    {
      "x": -11,
      "y": 102,
      "z": 5,
      "name": "Rock_Marble"
    },
    {
      "x": -11,
      "y": 103,
      "z": 5,
      "name": "Rock_Marble"
    },
    {
      "x": -11,
      "y": 104,
      "z": 5,
      "name": "Plant_Moss_Block_Blue"
    },
    {
      "x": -11,
      "y": 105,
      "z": 5,
      "name": "Wood_Azure_Trunk_Full"
    },
    {
      "x": -11,
      "y": 106,
      "z": 5,
      "name": "Wood_Azure_Trunk"
    },
    {
      "x": -11,
      "y": 107,
      "z": 5,
      "name": "Wood_Azure_Trunk"
    },
    {
      "x": -11,
      "y": 108,
      "z": 5,
      "name": "Wood_Azure_Trunk"
    },
    {
      "x": -11,
      "y": 109,
      "z": 5,
      "name": "Wood_Azure_Trunk"
    },
    {
      "x": -11,
      "y": 110,
      "z": 5,
      "name": "Wood_Azure_Trunk"
    },
    {
      "x": -11,
      "y": 111,
      "z": 5,
      "name": "Wood_Azure_Trunk"
    },
    {
      "x": -11,
      "y": 112,
      "z": 5,
      "name": "Wood_Azure_Trunk_Full"
    },
    {
      "x": -11,
      "y": 116,
      "z": 5,
      "name": "Plant_Moss_Wall_Blue"
    },
    {
      "x": -11,
      "y": 118,
      "z": 5,
      "name": "Wood_Azure_Branch_Long",
      "rotation": 4
    },
    {
      "x": -11,
      "y": 121,
      "z": 5,
      "name": "Plant_Leaves_Azure"
    },
    {
      "x": -11,
      "y": 122,
      "z": 5,
      "name": "Plant_Leaves_Azure"
    },
    {
      "x": -11,
      "y": 123,
      "z": 5,
      "name": "Plant_Leaves_Azure"
    },
    {
      "x": -11,
      "y": 91,
      "z": 6,
      "name": "Plant_Moss_Wall_Blue",
      "support": 15
    },
    {
      "x": -11,
      "y": 94,
      "z": 6,
      "name": "Rock_Marble"
    },
    {
      "x": -11,
      "y": 95,
      "z": 6,
      "name": "Rock_Marble"
    },
    {
      "x": -11,
      "y": 96,
      "z": 6,
      "name": "Rock_Marble"
    },
    {
      "x": -11,
      "y": 97,
      "z": 6,
      "name": "Rock_Marble"
    },
    {
      "x": -11,
      "y": 98,
      "z": 6,
      "name": "Rock_Marble"
    },
    {
      "x": -11,
      "y": 99,
      "z": 6,
      "name": "Rock_Marble"
    },
    {
      "x": -11,
      "y": 100,
      "z": 6,
      "name": "Rock_Marble"
    },
    {
      "x": -11,
      "y": 101,
      "z": 6,
      "name": "Rock_Marble"
    },
    {
      "x": -11,
      "y": 102,
      "z": 6,
      "name": "Rock_Marble"
    },
    {
      "x": -11,
      "y": 103,
      "z": 6,
      "name": "Plant_Moss_Block_Blue"
    },
    {
      "x": -11,
      "y": 104,
      "z": 6,
      "name": "Plant_Moss_Block_Blue"
    },
    {
      "x": -11,
      "y": 105,
      "z": 6,
      "name": "Wood_Azure_Trunk_Full"
    },
    {
      "x": -11,
      "y": 106,
      "z": 6,
      "name": "Wood_Azure_Trunk"
    },
    {
      "x": -11,
      "y": 107,
      "z": 6,
      "name": "Wood_Azure_Trunk_Full"
    },
    {
      "x": -11,
      "y": 111,
      "z": 6,
      "name": "Wood_Azure_Branch_Long",
      "rotation": 4
    },
    {
      "x": -11,
      "y": 117,
      "z": 6,
      "name": "Plant_Leaves_Azure"
    },
    {
      "x": -11,
      "y": 118,
      "z": 6,
      "name": "Wood_Azure_Branch_Long",
      "rotation": 4
    },
    {
      "x": -11,
      "y": 119,
      "z": 6,
      "name": "Plant_Leaves_Azure"
    },
    {
      "x": -11,
      "y": 94,
      "z": 7,
      "name": "Rock_Marble"
    },
    {
      "x": -11,
      "y": 95,
      "z": 7,
      "name": "Rock_Marble"
    },
    {
      "x": -11,
      "y": 96,
      "z": 7,
      "name": "Rock_Marble"
    },
    {
      "x": -11,
      "y": 97,
      "z": 7,
      "name": "Rock_Marble"
    },
    {
      "x": -11,
      "y": 98,
      "z": 7,
      "name": "Rock_Marble"
    },
    {
      "x": -11,
      "y": 99,
      "z": 7,
      "name": "Rock_Marble"
    },
    {
      "x": -11,
      "y": 100,
      "z": 7,
      "name": "Rock_Marble"
    },
    {
      "x": -11,
      "y": 101,
      "z": 7,
      "name": "Rock_Marble"
    },
    {
      "x": -11,
      "y": 102,
      "z": 7,
      "name": "Rock_Marble"
    },
    {
      "x": -11,
      "y": 103,
      "z": 7,
      "name": "Plant_Moss_Block_Blue"
    },
    {
      "x": -11,
      "y": 104,
      "z": 7,
      "name": "Plant_Moss_Block_Blue"
    },
    {
      "x": -11,
      "y": 105,
      "z": 7,
      "name": "Plant_Moss_Rug_Lime"
    },
    {
      "x": -11,
      "y": 110,
      "z": 7,
      "name": "Plant_Leaves_Azure"
    },
    {
      "x": -11,
      "y": 111,
      "z": 7,
      "name": "Wood_Azure_Branch_Long",
      "rotation": 4
    },
    {
      "x": -11,
      "y": 113,
      "z": 7,
      "name": "Plant_Leaves_Azure"
    },
    {
      "x": -11,
      "y": 116,
      "z": 7,
      "name": "Plant_Leaves_Azure"
    },
    {
      "x": -11,
      "y": 117,
      "z": 7,
      "name": "Plant_Leaves_Azure"
    },
    {
      "x": -11,
      "y": 118,
      "z": 7,
      "name": "Plant_Leaves_Azure"
    },
    {
      "x": -11,
      "y": 95,
      "z": 8,
      "name": "Rock_Marble"
    },
    {
      "x": -11,
      "y": 96,
      "z": 8,
      "name": "Rock_Marble"
    },
    {
      "x": -11,
      "y": 97,
      "z": 8,
      "name": "Rock_Marble"
    },
    {
      "x": -11,
      "y": 98,
      "z": 8,
      "name": "Rock_Marble"
    },
    {
      "x": -11,
      "y": 99,
      "z": 8,
      "name": "Rock_Marble"
    },
    {
      "x": -11,
      "y": 100,
      "z": 8,
      "name": "Rock_Marble"
    },
    {
      "x": -11,
      "y": 101,
      "z": 8,
      "name": "Rock_Marble"
    },
    {
      "x": -11,
      "y": 102,
      "z": 8,
      "name": "Plant_Moss_Block_Blue"
    },
    {
      "x": -11,
      "y": 103,
      "z": 8,
      "name": "Plant_Moss_Block_Blue"
    },
    {
      "x": -11,
      "y": 104,
      "z": 8,
      "name": "Plant_Moss_Rug_Lime"
    },
    {
      "x": -11,
      "y": 110,
      "z": 8,
      "name": "Plant_Leaves_Azure"
    },
    {
      "x": -11,
      "y": 111,
      "z": 8,
      "name": "Plant_Leaves_Azure"
    },
    {
      "x": -11,
      "y": 112,
      "z": 8,
      "name": "Plant_Leaves_Azure"
    },
    {
      "x": -11,
      "y": 113,
      "z": 8,
      "name": "Plant_Leaves_Azure"
    },
    {
      "x": -11,
      "y": 100,
      "z": 9,
      "name": "Rock_Marble"
    },
    {
      "x": -11,
      "y": 101,
      "z": 9,
      "name": "Rock_Marble"
    },
    {
      "x": -11,
      "y": 102,
      "z": 9,
      "name": "Plant_Moss_Block_Blue"
    },
    {
      "x": -11,
      "y": 103,
      "z": 9,
      "name": "Plant_Moss_Block_Blue"
    },
    {
      "x": -11,
      "y": 104,
      "z": 9,
      "name": "Plant_Moss_Short_Green_Dark"
    },
    {
      "x": -11,
      "y": 111,
      "z": 9,
      "name": "Plant_Leaves_Azure"
    },
    {
      "x": -10,
      "y": 95,
      "z": -5,
      "name": "Plant_Moss_Wall_Blue",
      "support": 15,
      "rotation": 2
    },
    {
      "x": -10,
      "y": 97,
      "z": -5,
      "name": "Plant_Moss_Block_Blue"
    },
    {
      "x": -10,
      "y": 98,
      "z": -5,
      "name": "Plant_Moss_Block_Blue"
    },
    {
      "x": -10,
      "y": 99,
      "z": -5,
      "name": "Plant_Moss_Rug_Blue"
    },
    {
      "x": -10,
      "y": 94,
      "z": -4,
      "name": "Plant_Moss_Wall_Blue",
      "support": 15,
      "rotation": 3
    },
    {
      "x": -10,
      "y": 95,
      "z": -4,
      "name": "Rock_Marble"
    },
    {
      "x": -10,
      "y": 96,
      "z": -4,
      "name": "Rock_Marble"
    },
    {
      "x": -10,
      "y": 97,
      "z": -4,
      "name": "Rock_Marble"
    },
    {
      "x": -10,
      "y": 98,
      "z": -4,
      "name": "Plant_Moss_Block_Blue"
    },
    {
      "x": -10,
      "y": 99,
      "z": -4,
      "name": "Plant_Moss_Block_Blue"
    },
    {
      "x": -10,
      "y": 100,
      "z": -4,
      "name": "Plant_Moss_Rug_Lime"
    },
    {
      "x": -10,
      "y": 93,
      "z": -3,
      "name": "Plant_Moss_Wall_Blue",
      "support": 15,
      "rotation": 3
    },
    {
      "x": -10,
      "y": 94,
      "z": -3,
      "name": "Rock_Marble"
    },
    {
      "x": -10,
      "y": 95,
      "z": -3,
      "name": "Rock_Marble"
    },
    {
      "x": -10,
      "y": 96,
      "z": -3,
      "name": "Rock_Marble"
    },
    {
      "x": -10,
      "y": 97,
      "z": -3,
      "name": "Rock_Marble"
    },
    {
      "x": -10,
      "y": 98,
      "z": -3,
      "name": "Rock_Marble"
    },
    {
      "x": -10,
      "y": 99,
      "z": -3,
      "name": "Plant_Moss_Block_Blue"
    },
    {
      "x": -10,
      "y": 100,
      "z": -3,
      "name": "Plant_Moss_Block_Blue"
    },
    {
      "x": -10,
      "y": 101,
      "z": -3,
      "name": "Plant_Moss_Rug_Lime"
    },
    {
      "x": -10,
      "y": 111,
      "z": -3,
      "name": "Plant_Leaves_Azure"
    },
    {
      "x": -10,
      "y": 112,
      "z": -3,
      "name": "Plant_Leaves_Azure"
    },
    {
      "x": -10,
      "y": 113,
      "z": -3,
      "name": "Plant_Leaves_Azure"
    },
    {
      "x": -10,
      "y": 114,
      "z": -3,
      "name": "Plant_Leaves_Azure"
    },
    {
      "x": -10,
      "y": 93,
      "z": -2,
      "name": "Rock_Marble"
    },
    {
      "x": -10,
      "y": 94,
      "z": -2,
      "name": "Rock_Marble"
    },
    {
      "x": -10,
      "y": 95,
      "z": -2,
      "name": "Rock_Marble"
    },
    {
      "x": -10,
      "y": 96,
      "z": -2,
      "name": "Rock_Marble"
    },
    {
      "x": -10,
      "y": 97,
      "z": -2,
      "name": "Rock_Marble"
    },
    {
      "x": -10,
      "y": 98,
      "z": -2,
      "name": "Rock_Marble"
    },
    {
      "x": -10,
      "y": 99,
      "z": -2,
      "name": "Plant_Moss_Block_Blue"
    },
    {
      "x": -10,
      "y": 100,
      "z": -2,
      "name": "Plant_Moss_Block_Blue"
    },
    {
      "x": -10,
      "y": 101,
      "z": -2,
      "name": "Plant_Moss_Blue"
    },
    {
      "x": -10,
      "y": 110,
      "z": -2,
      "name": "Plant_Leaves_Azure"
    },
    {
      "x": -10,
      "y": 111,
      "z": -2,
      "name": "Plant_Leaves_Azure"
    },
    {
      "x": -10,
      "y": 112,
      "z": -2,
      "name": "Plant_Leaves_Azure"
    },
    {
      "x": -10,
      "y": 113,
      "z": -2,
      "name": "Plant_Leaves_Azure"
    },
    {
      "x": -10,
      "y": 114,
      "z": -2,
      "name": "Plant_Leaves_Azure"
    },
    {
      "x": -10,
      "y": 115,
      "z": -2,
      "name": "Plant_Leaves_Azure"
    },
    {
      "x": -10,
      "y": 90,
      "z": -1,
      "name": "Rock_Marble"
    },
    {
      "x": -10,
      "y": 91,
      "z": -1,
      "name": "Rock_Marble"
    },
    {
      "x": -10,
      "y": 92,
      "z": -1,
      "name": "Rock_Marble"
    },
    {
      "x": -10,
      "y": 93,
      "z": -1,
      "name": "Rock_Marble"
    },
    {
      "x": -10,
      "y": 94,
      "z": -1,
      "name": "Rock_Marble"
    },
    {
      "x": -10,
      "y": 95,
      "z": -1,
      "name": "Rock_Marble"
    },
    {
      "x": -10,
      "y": 96,
      "z": -1,
      "name": "Rock_Marble"
    },
    {
      "x": -10,
      "y": 97,
      "z": -1,
      "name": "Rock_Marble"
    },
    {
      "x": -10,
      "y": 98,
      "z": -1,
      "name": "Rock_Marble"
    },
    {
      "x": -10,
      "y": 99,
      "z": -1,
      "name": "Rock_Marble"
    },
    {
      "x": -10,
      "y": 100,
      "z": -1,
      "name": "Plant_Moss_Block_Blue"
    },
    {
      "x": -10,
      "y": 101,
      "z": -1,
      "name": "Plant_Moss_Block_Blue"
    },
    {
      "x": -10,
      "y": 102,
      "z": -1,
      "name": "Plant_Moss_Rug_Lime"
    },
    {
      "x": -10,
      "y": 112,
      "z": -1,
      "name": "Plant_Leaves_Azure"
    },
    {
      "x": -10,
      "y": 113,
      "z": -1,
      "name": "Plant_Leaves_Azure"
    },
    {
      "x": -10,
      "y": 114,
      "z": -1,
      "name": "Plant_Leaves_Azure"
    },
    {
      "x": -10,
      "y": 89,
      "z": 0,
      "name": "Rock_Marble"
    },
    {
      "x": -10,
      "y": 90,
      "z": 0,
      "name": "Rock_Marble"
    },
    {
      "x": -10,
      "y": 91,
      "z": 0,
      "name": "Rock_Marble"
    },
    {
      "x": -10,
      "y": 92,
      "z": 0,
      "name": "Rock_Marble"
    },
    {
      "x": -10,
      "y": 93,
      "z": 0,
      "name": "Rock_Marble"
    },
    {
      "x": -10,
      "y": 94,
      "z": 0,
      "name": "Rock_Marble"
    },
    {
      "x": -10,
      "y": 95,
      "z": 0,
      "name": "Rock_Marble"
    },
    {
      "x": -10,
      "y": 96,
      "z": 0,
      "name": "Rock_Marble"
    },
    {
      "x": -10,
      "y": 97,
      "z": 0,
      "name": "Rock_Marble"
    },
    {
      "x": -10,
      "y": 98,
      "z": 0,
      "name": "Rock_Marble"
    },
    {
      "x": -10,
      "y": 99,
      "z": 0,
      "name": "Rock_Marble"
    },
    {
      "x": -10,
      "y": 100,
      "z": 0,
      "name": "Rock_Marble"
    },
    {
      "x": -10,
      "y": 101,
      "z": 0,
      "name": "Plant_Moss_Block_Blue"
    },
    {
      "x": -10,
      "y": 102,
      "z": 0,
      "name": "Plant_Moss_Block_Blue"
    },
    {
      "x": -10,
      "y": 103,
      "z": 0,
      "name": "Plant_Moss_Blue"
    },
    {
      "x": -10,
      "y": 113,
      "z": 0,
      "name": "Plant_Leaves_Azure"
    },
    {
      "x": -10,
      "y": 114,
      "z": 0,
      "name": "Plant_Leaves_Azure"
    },
    {
      "x": -10,
      "y": 118,
      "z": 0,
      "name": "Plant_Leaves_Azure"
    },
    {
      "x": -10,
      "y": 119,
      "z": 0,
      "name": "Plant_Leaves_Azure"
    },
    {
      "x": -10,
      "y": 120,
      "z": 0,
      "name": "Plant_Leaves_Azure"
    },
    {
      "x": -10,
      "y": 90,
      "z": 1,
      "name": "Rock_Marble"
    },
    {
      "x": -10,
      "y": 91,
      "z": 1,
      "name": "Rock_Marble"
    },
    {
      "x": -10,
      "y": 92,
      "z": 1,
      "name": "Rock_Marble"
    },
    {
      "x": -10,
      "y": 93,
      "z": 1,
      "name": "Rock_Marble"
    },
    {
      "x": -10,
      "y": 94,
      "z": 1,
      "name": "Rock_Marble"
    },
    {
      "x": -10,
      "y": 95,
      "z": 1,
      "name": "Rock_Marble"
    },
    {
      "x": -10,
      "y": 96,
      "z": 1,
      "name": "Rock_Marble"
    },
    {
      "x": -10,
      "y": 97,
      "z": 1,
      "name": "Rock_Marble"
    },
    {
      "x": -10,
      "y": 98,
      "z": 1,
      "name": "Rock_Marble"
    },
    {
      "x": -10,
      "y": 99,
      "z": 1,
      "name": "Rock_Marble"
    },
    {
      "x": -10,
      "y": 100,
      "z": 1,
      "name": "Rock_Marble"
    },
    {
      "x": -10,
      "y": 101,
      "z": 1,
      "name": "Rock_Marble"
    },
    {
      "x": -10,
      "y": 102,
      "z": 1,
      "name": "Plant_Moss_Block_Blue"
    },
    {
      "x": -10,
      "y": 103,
      "z": 1,
      "name": "Plant_Moss_Block_Blue"
    },
    {
      "x": -10,
      "y": 104,
      "z": 1,
      "name": "Plant_Moss_Rug_Lime"
    },
    {
      "x": -10,
      "y": 117,
      "z": 1,
      "name": "Plant_Leaves_Azure"
    },
    {
      "x": -10,
      "y": 118,
      "z": 1,
      "name": "Plant_Leaves_Azure"
    },
    {
      "x": -10,
      "y": 119,
      "z": 1,
      "name": "Plant_Leaves_Azure"
    },
    {
      "x": -10,
      "y": 120,
      "z": 1,
      "name": "Plant_Fruit_Azure"
    },
    {
      "x": -10,
      "y": 89,
      "z": 2,
      "name": "Plant_Moss_Wall_Blue",
      "support": 15,
      "rotation": 3
    },
    {
      "x": -10,
      "y": 90,
      "z": 2,
      "name": "Rock_Marble"
    },
    {
      "x": -10,
      "y": 91,
      "z": 2,
      "name": "Rock_Marble"
    },
    {
      "x": -10,
      "y": 92,
      "z": 2,
      "name": "Rock_Marble"
    },
    {
      "x": -10,
      "y": 93,
      "z": 2,
      "name": "Rock_Marble"
    },
    {
      "x": -10,
      "y": 94,
      "z": 2,
      "name": "Rock_Marble"
    },
    {
      "x": -10,
      "y": 95,
      "z": 2,
      "name": "Rock_Marble"
    },
    {
      "x": -10,
      "y": 96,
      "z": 2,
      "name": "Rock_Marble"
    },
    {
      "x": -10,
      "y": 97,
      "z": 2,
      "name": "Rock_Marble"
    },
    {
      "x": -10,
      "y": 98,
      "z": 2,
      "name": "Rock_Marble"
    },
    {
      "x": -10,
      "y": 99,
      "z": 2,
      "name": "Rock_Marble"
    },
    {
      "x": -10,
      "y": 100,
      "z": 2,
      "name": "Rock_Marble"
    },
    {
      "x": -10,
      "y": 101,
      "z": 2,
      "name": "Rock_Marble"
    },
    {
      "x": -10,
      "y": 102,
      "z": 2,
      "name": "Rock_Marble"
    },
    {
      "x": -10,
      "y": 103,
      "z": 2,
      "name": "Plant_Moss_Block_Blue"
    },
    {
      "x": -10,
      "y": 104,
      "z": 2,
      "name": "Plant_Moss_Block_Blue"
    },
    {
      "x": -10,
      "y": 105,
      "z": 2,
      "name": "Plant_Moss_Blue"
    },
    {
      "x": -10,
      "y": 113,
      "z": 2,
      "name": "Plant_Moss_Wall_Blue",
      "rotation": 2
    },
    {
      "x": -10,
      "y": 118,
      "z": 2,
      "name": "Plant_Leaves_Azure"
    },
    {
      "x": -10,
      "y": 124,
      "z": 2,
      "name": "Plant_Leaves_Azure"
    },
    {
      "x": -10,
      "y": 89,
      "z": 3,
      "name": "Plant_Moss_Wall_Blue",
      "support": 15,
      "rotation": 3
    },
    {
      "x": -10,
      "y": 90,
      "z": 3,
      "name": "Rock_Marble"
    },
    {
      "x": -10,
      "y": 91,
      "z": 3,
      "name": "Rock_Marble"
    },
    {
      "x": -10,
      "y": 92,
      "z": 3,
      "name": "Rock_Marble"
    },
    {
      "x": -10,
      "y": 93,
      "z": 3,
      "name": "Rock_Marble"
    },
    {
      "x": -10,
      "y": 94,
      "z": 3,
      "name": "Rock_Marble"
    },
    {
      "x": -10,
      "y": 95,
      "z": 3,
      "name": "Rock_Marble"
    },
    {
      "x": -10,
      "y": 96,
      "z": 3,
      "name": "Rock_Marble"
    },
    {
      "x": -10,
      "y": 97,
      "z": 3,
      "name": "Rock_Marble"
    },
    {
      "x": -10,
      "y": 98,
      "z": 3,
      "name": "Rock_Marble"
    },
    {
      "x": -10,
      "y": 99,
      "z": 3,
      "name": "Rock_Marble"
    },
    {
      "x": -10,
      "y": 100,
      "z": 3,
      "name": "Rock_Marble"
    },
    {
      "x": -10,
      "y": 101,
      "z": 3,
      "name": "Rock_Marble"
    },
    {
      "x": -10,
      "y": 102,
      "z": 3,
      "name": "Rock_Marble"
    },
    {
      "x": -10,
      "y": 103,
      "z": 3,
      "name": "Plant_Moss_Block_Blue"
    },
    {
      "x": -10,
      "y": 104,
      "z": 3,
      "name": "Plant_Moss_Block_Blue"
    },
    {
      "x": -10,
      "y": 105,
      "z": 3,
      "name": "Plant_Moss_Rug_Lime"
    },
    {
      "x": -10,
      "y": 110,
      "z": 3,
      "name": "Wood_Azure_Trunk_Full"
    },
    {
      "x": -10,
      "y": 111,
      "z": 3,
      "name": "Wood_Azure_Trunk"
    },
    {
      "x": -10,
      "y": 112,
      "z": 3,
      "name": "Wood_Azure_Trunk"
    },
    {
      "x": -10,
      "y": 113,
      "z": 3,
      "name": "Wood_Azure_Trunk_Full"
    },
    {
      "x": -10,
      "y": 114,
      "z": 3,
      "name": "Plant_Moss_Rug_Blue"
    },
    {
      "x": -10,
      "y": 122,
      "z": 3,
      "name": "Plant_Leaves_Azure"
    },
    {
      "x": -10,
      "y": 123,
      "z": 3,
      "name": "Plant_Leaves_Azure"
    },
    {
      "x": -10,
      "y": 124,
      "z": 3,
      "name": "Plant_Leaves_Azure"
    },
    {
      "x": -10,
      "y": 88,
      "z": 4,
      "name": "Plant_Moss_Wall_Blue",
      "support": 15,
      "rotation": 3
    },
    {
      "x": -10,
      "y": 90,
      "z": 4,
      "name": "Rock_Marble"
    },
    {
      "x": -10,
      "y": 91,
      "z": 4,
      "name": "Rock_Marble"
    },
    {
      "x": -10,
      "y": 92,
      "z": 4,
      "name": "Rock_Marble"
    },
    {
      "x": -10,
      "y": 93,
      "z": 4,
      "name": "Rock_Marble"
    },
    {
      "x": -10,
      "y": 94,
      "z": 4,
      "name": "Rock_Marble"
    },
    {
      "x": -10,
      "y": 95,
      "z": 4,
      "name": "Rock_Marble"
    },
    {
      "x": -10,
      "y": 96,
      "z": 4,
      "name": "Rock_Marble"
    },
    {
      "x": -10,
      "y": 97,
      "z": 4,
      "name": "Rock_Marble"
    },
    {
      "x": -10,
      "y": 98,
      "z": 4,
      "name": "Rock_Marble"
    },
    {
      "x": -10,
      "y": 99,
      "z": 4,
      "name": "Rock_Marble"
    },
    {
      "x": -10,
      "y": 100,
      "z": 4,
      "name": "Rock_Marble"
    },
    {
      "x": -10,
      "y": 101,
      "z": 4,
      "name": "Rock_Marble"
    },
    {
      "x": -10,
      "y": 102,
      "z": 4,
      "name": "Rock_Marble"
    },
    {
      "x": -10,
      "y": 103,
      "z": 4,
      "name": "Rock_Marble"
    },
    {
      "x": -10,
      "y": 104,
      "z": 4,
      "name": "Plant_Moss_Block_Blue"
    },
    {
      "x": -10,
      "y": 105,
      "z": 4,
      "name": "Plant_Moss_Block_Blue"
    },
    {
      "x": -10,
      "y": 106,
      "z": 4,
      "name": "Plant_Moss_Blue"
    },
    {
      "x": -10,
      "y": 108,
      "z": 4,
      "name": "Wood_Azure_Trunk_Full"
    },
    {
      "x": -10,
      "y": 109,
      "z": 4,
      "name": "Wood_Azure_Trunk"
    },
    {
      "x": -10,
      "y": 110,
      "z": 4,
      "name": "Wood_Azure_Trunk"
    },
    {
      "x": -10,
      "y": 111,
      "z": 4,
      "name": "Wood_Azure_Trunk_Full"
    },
    {
      "x": -10,
      "y": 113,
      "z": 4,
      "name": "Plant_Moss_Wall_Blue"
    },
    {
      "x": -10,
      "y": 115,
      "z": 4,
      "name": "Wood_Azure_Branch_Long",
      "rotation": 5
    },
    {
      "x": -10,
      "y": 116,
      "z": 4,
      "name": "Plant_Moss_Wall_Blue",
      "rotation": 1
    },
    {
      "x": -10,
      "y": 119,
      "z": 4,
      "name": "Plant_Leaves_Azure"
    },
    {
      "x": -10,
      "y": 122,
      "z": 4,
      "name": "Plant_Leaves_Azure"
    },
    {
      "x": -10,
      "y": 123,
      "z": 4,
      "name": "Plant_Leaves_Azure"
    },
    {
      "x": -10,
      "y": 90,
      "z": 5,
      "name": "Plant_Moss_Wall_Blue",
      "support": 15
    },
    {
      "x": -10,
      "y": 91,
      "z": 5,
      "name": "Rock_Marble"
    },
    {
      "x": -10,
      "y": 92,
      "z": 5,
      "name": "Rock_Marble"
    },
    {
      "x": -10,
      "y": 93,
      "z": 5,
      "name": "Rock_Marble"
    },
    {
      "x": -10,
      "y": 94,
      "z": 5,
      "name": "Rock_Marble"
    },
    {
      "x": -10,
      "y": 95,
      "z": 5,
      "name": "Rock_Marble"
    },
    {
      "x": -10,
      "y": 96,
      "z": 5,
      "name": "Rock_Marble"
    },
    {
      "x": -10,
      "y": 97,
      "z": 5,
      "name": "Rock_Marble"
    },
    {
      "x": -10,
      "y": 98,
      "z": 5,
      "name": "Rock_Marble"
    },
    {
      "x": -10,
      "y": 99,
      "z": 5,
      "name": "Rock_Marble"
    },
    {
      "x": -10,
      "y": 100,
      "z": 5,
      "name": "Rock_Marble"
    },
    {
      "x": -10,
      "y": 101,
      "z": 5,
      "name": "Rock_Marble"
    },
    {
      "x": -10,
      "y": 102,
      "z": 5,
      "name": "Rock_Marble"
    },
    {
      "x": -10,
      "y": 103,
      "z": 5,
      "name": "Rock_Marble"
    },
    {
      "x": -10,
      "y": 104,
      "z": 5,
      "name": "Plant_Moss_Block_Blue"
    },
    {
      "x": -10,
      "y": 105,
      "z": 5,
      "name": "Wood_Azure_Trunk_Full"
    },
    {
      "x": -10,
      "y": 106,
      "z": 5,
      "name": "Wood_Azure_Trunk"
    },
    {
      "x": -10,
      "y": 107,
      "z": 5,
      "name": "Wood_Azure_Trunk"
    },
    {
      "x": -10,
      "y": 108,
      "z": 5,
      "name": "Wood_Azure_Trunk_Full"
    },
    {
      "x": -10,
      "y": 118,
      "z": 5,
      "name": "Plant_Leaves_Azure"
    },
    {
      "x": -10,
      "y": 119,
      "z": 5,
      "name": "Plant_Leaves_Azure"
    },
    {
      "x": -10,
      "y": 120,
      "z": 5,
      "name": "Plant_Fruit_Azure"
    },
    {
      "x": -10,
      "y": 122,
      "z": 5,
      "name": "Plant_Leaves_Azure"
    },
    {
      "x": -10,
      "y": 93,
      "z": 6,
      "name": "Rock_Marble"
    },
    {
      "x": -10,
      "y": 94,
      "z": 6,
      "name": "Rock_Marble"
    },
    {
      "x": -10,
      "y": 95,
      "z": 6,
      "name": "Rock_Marble"
    },
    {
      "x": -10,
      "y": 96,
      "z": 6,
      "name": "Rock_Marble"
    },
    {
      "x": -10,
      "y": 97,
      "z": 6,
      "name": "Rock_Marble"
    },
    {
      "x": -10,
      "y": 98,
      "z": 6,
      "name": "Rock_Marble"
    },
    {
      "x": -10,
      "y": 99,
      "z": 6,
      "name": "Rock_Marble"
    },
    {
      "x": -10,
      "y": 100,
      "z": 6,
      "name": "Rock_Marble"
    },
    {
      "x": -10,
      "y": 101,
      "z": 6,
      "name": "Rock_Marble"
    },
    {
      "x": -10,
      "y": 102,
      "z": 6,
      "name": "Rock_Marble"
    },
    {
      "x": -10,
      "y": 103,
      "z": 6,
      "name": "Wood_Azure_Roots"
    },
    {
      "x": -10,
      "y": 104,
      "z": 6,
      "name": "Wood_Azure_Trunk_Full"
    },
    {
      "x": -10,
      "y": 105,
      "z": 6,
      "name": "Wood_Azure_Trunk"
    },
    {
      "x": -10,
      "y": 106,
      "z": 6,
      "name": "Wood_Azure_Trunk_Full"
    },
    {
      "x": -10,
      "y": 114,
      "z": 6,
      "name": "Plant_Leaves_Azure"
    },
    {
      "x": -10,
      "y": 118,
      "z": 6,
      "name": "Plant_Leaves_Azure"
    },
    {
      "x": -10,
      "y": 119,
      "z": 6,
      "name": "Plant_Leaves_Azure"
    },
    {
      "x": -10,
      "y": 94,
      "z": 7,
      "name": "Rock_Marble"
    },
    {
      "x": -10,
      "y": 95,
      "z": 7,
      "name": "Rock_Marble"
    },
    {
      "x": -10,
      "y": 96,
      "z": 7,
      "name": "Rock_Marble"
    },
    {
      "x": -10,
      "y": 97,
      "z": 7,
      "name": "Rock_Marble"
    },
    {
      "x": -10,
      "y": 98,
      "z": 7,
      "name": "Rock_Marble"
    },
    {
      "x": -10,
      "y": 99,
      "z": 7,
      "name": "Rock_Marble"
    },
    {
      "x": -10,
      "y": 100,
      "z": 7,
      "name": "Rock_Marble"
    },
    {
      "x": -10,
      "y": 101,
      "z": 7,
      "name": "Rock_Marble"
    },
    {
      "x": -10,
      "y": 102,
      "z": 7,
      "name": "Rock_Marble"
    },
    {
      "x": -10,
      "y": 103,
      "z": 7,
      "name": "Plant_Moss_Block_Blue"
    },
    {
      "x": -10,
      "y": 104,
      "z": 7,
      "name": "Wood_Azure_Trunk_Full"
    },
    {
      "x": -10,
      "y": 105,
      "z": 7,
      "name": "Wood_Azure_Trunk_Full"
    },
    {
      "x": -10,
      "y": 112,
      "z": 7,
      "name": "Plant_Leaves_Azure"
    },
    {
      "x": -10,
      "y": 113,
      "z": 7,
      "name": "Plant_Leaves_Azure"
    },
    {
      "x": -10,
      "y": 114,
      "z": 7,
      "name": "Plant_Leaves_Azure"
    },
    {
      "x": -10,
      "y": 94,
      "z": 8,
      "name": "Rock_Marble"
    },
    {
      "x": -10,
      "y": 95,
      "z": 8,
      "name": "Rock_Marble"
    },
    {
      "x": -10,
      "y": 96,
      "z": 8,
      "name": "Rock_Marble"
    },
    {
      "x": -10,
      "y": 97,
      "z": 8,
      "name": "Rock_Marble"
    },
    {
      "x": -10,
      "y": 98,
      "z": 8,
      "name": "Rock_Marble"
    },
    {
      "x": -10,
      "y": 99,
      "z": 8,
      "name": "Rock_Marble"
    },
    {
      "x": -10,
      "y": 100,
      "z": 8,
      "name": "Rock_Marble"
    },
    {
      "x": -10,
      "y": 101,
      "z": 8,
      "name": "Rock_Marble"
    },
    {
      "x": -10,
      "y": 102,
      "z": 8,
      "name": "Rock_Marble"
    },
    {
      "x": -10,
      "y": 103,
      "z": 8,
      "name": "Plant_Moss_Block_Blue"
    },
    {
      "x": -10,
      "y": 104,
      "z": 8,
      "name": "Plant_Moss_Block_Blue"
    },
    {
      "x": -10,
      "y": 105,
      "z": 8,
      "name": "Plant_Moss_Short_Green_Dark"
    },
    {
      "x": -10,
      "y": 111,
      "z": 8,
      "name": "Plant_Leaves_Azure"
    },
    {
      "x": -10,
      "y": 112,
      "z": 8,
      "name": "Plant_Leaves_Azure"
    },
    {
      "x": -10,
      "y": 113,
      "z": 8,
      "name": "Plant_Leaves_Azure"
    },
    {
      "x": -10,
      "y": 114,
      "z": 8,
      "name": "Plant_Leaves_Azure"
    },
    {
      "x": -10,
      "y": 115,
      "z": 8,
      "name": "Plant_Fruit_Azure"
    },
    {
      "x": -10,
      "y": 95,
      "z": 9,
      "name": "Rock_Marble"
    },
    {
      "x": -10,
      "y": 96,
      "z": 9,
      "name": "Rock_Marble"
    },
    {
      "x": -10,
      "y": 97,
      "z": 9,
      "name": "Rock_Marble"
    },
    {
      "x": -10,
      "y": 98,
      "z": 9,
      "name": "Rock_Marble"
    },
    {
      "x": -10,
      "y": 99,
      "z": 9,
      "name": "Rock_Marble"
    },
    {
      "x": -10,
      "y": 100,
      "z": 9,
      "name": "Rock_Marble"
    },
    {
      "x": -10,
      "y": 101,
      "z": 9,
      "name": "Rock_Marble"
    },
    {
      "x": -10,
      "y": 102,
      "z": 9,
      "name": "Plant_Moss_Block_Blue"
    },
    {
      "x": -10,
      "y": 103,
      "z": 9,
      "name": "Plant_Moss_Block_Blue"
    },
    {
      "x": -10,
      "y": 104,
      "z": 9,
      "name": "Plant_Moss_Short_Green_Dark"
    },
    {
      "x": -10,
      "y": 99,
      "z": 10,
      "name": "Rock_Marble"
    },
    {
      "x": -10,
      "y": 100,
      "z": 10,
      "name": "Rock_Marble"
    },
    {
      "x": -10,
      "y": 101,
      "z": 10,
      "name": "Rock_Marble"
    },
    {
      "x": -10,
      "y": 102,
      "z": 10,
      "name": "Plant_Moss_Block_Blue"
    },
    {
      "x": -10,
      "y": 103,
      "z": 10,
      "name": "Plant_Moss_Block_Blue"
    },
    {
      "x": -10,
      "y": 104,
      "z": 10,
      "name": "Plant_Moss_Short_Green_Dark"
    },
    {
      "x": -9,
      "y": 96,
      "z": -6,
      "name": "Plant_Moss_Wall_Blue",
      "support": 15,
      "rotation": 2
    },
    {
      "x": -9,
      "y": 97,
      "z": -6,
      "name": "Plant_Moss_Wall_Blue",
      "support": 15,
      "rotation": 2
    },
    {
      "x": -9,
      "y": 99,
      "z": -6,
      "name": "Plant_Moss_Wall_Blue",
      "support": 15,
      "rotation": 2
    },
    {
      "x": -9,
      "y": 94,
      "z": -5,
      "name": "Plant_Moss_Wall_Blue",
      "support": 15,
      "rotation": 2
    },
    {
      "x": -9,
      "y": 96,
      "z": -5,
      "name": "Rock_Marble"
    },
    {
      "x": -9,
      "y": 97,
      "z": -5,
      "name": "Rock_Marble"
    },
    {
      "x": -9,
      "y": 98,
      "z": -5,
      "name": "Plant_Moss_Block_Blue"
    },
    {
      "x": -9,
      "y": 99,
      "z": -5,
      "name": "Plant_Moss_Block_Blue"
    },
    {
      "x": -9,
      "y": 100,
      "z": -5,
      "name": "Plant_Moss_Wall_Blue",
      "support": 15,
      "rotation": 2
    },
    {
      "x": -9,
      "y": 94,
      "z": -4,
      "name": "Rock_Marble"
    },
    {
      "x": -9,
      "y": 95,
      "z": -4,
      "name": "Rock_Marble"
    },
    {
      "x": -9,
      "y": 96,
      "z": -4,
      "name": "Rock_Marble"
    },
    {
      "x": -9,
      "y": 97,
      "z": -4,
      "name": "Rock_Marble"
    },
    {
      "x": -9,
      "y": 98,
      "z": -4,
      "name": "Rock_Marble"
    },
    {
      "x": -9,
      "y": 99,
      "z": -4,
      "name": "Plant_Moss_Block_Blue"
    },
    {
      "x": -9,
      "y": 100,
      "z": -4,
      "name": "Plant_Moss_Block_Blue"
    },
    {
      "x": -9,
      "y": 101,
      "z": -4,
      "name": "Plant_Moss_Blue"
    },
    {
      "x": -9,
      "y": 93,
      "z": -3,
      "name": "Rock_Marble"
    },
    {
      "x": -9,
      "y": 94,
      "z": -3,
      "name": "Rock_Marble"
    },
    {
      "x": -9,
      "y": 95,
      "z": -3,
      "name": "Rock_Marble"
    },
    {
      "x": -9,
      "y": 96,
      "z": -3,
      "name": "Rock_Marble"
    },
    {
      "x": -9,
      "y": 97,
      "z": -3,
      "name": "Rock_Marble"
    },
    {
      "x": -9,
      "y": 98,
      "z": -3,
