{
  "version": 8,
  "blockIdVersion": 11,
  "anchorX": 0,
  "anchorY": 0,
  "anchorZ": 0,
  "blocks": [
    {
      "x": -3,
      "y": 1,
      "z": -3,
      "name": "Rock_Sandstone_Red"
    },
    {
      "x": -3,
      "y": 2,
      "z": -3,
      "name": "Rock_Sandstone_Red"
    },
    {
      "x": -3,
      "y": 3,
      "z": -3,
      "name": "Rubble_Sandstone_Red_Medium"
    },
    {
      "x": -2,
      "y": 1,
      "z": -4,
      "name": "Rock_Sandstone_Red"
    },
    {
      "x": -2,
      "y": 2,
      "z": -4,
      "name": "Rock_Sandstone_Red"
    },
    {
      "x": -2,
      "y": 3,
      "z": -4,
      "name": "Rubble_Sandstone_Red_Medium"
    },
    {
      "x": -2,
      "y": 0,
      "z": -3,
      "name": "Rock_Sandstone_Red"
    },
    {
      "x": -2,
      "y": 1,
      "z": -3,
      "name": "Rock_Sandstone_Red"
    },
    {
      "x": -2,
      "y": 2,
      "z": -3,
      "name": "Rock_Sandstone_Red"
    },
    {
      "x": -2,
      "y": 3,
      "z": -3,
      "name": "Rock_Sandstone_Red_Stalactite_Small",
      "rotation": 2
    },
    {
      "x": -2,
      "y": 4,
      "z": -3,
      "name": "Rock_Crystal_Red_Medium",
      "rotation": 7
    },
    {
      "x": -2,
      "y": 1,
      "z": -2,
      "name": "Rock_Sandstone_Red"
    },
    {
      "x": -2,
      "y": 2,
      "z": -2,
      "name": "Rock_Sandstone_Red"
    },
    {
      "x": -2,
      "y": 3,
      "z": -2,
      "name": "Rock_Sandstone_Red_Stalactite_Large"
    },
    {
      "x": -2,
      "y": 4,
      "z": -2,
      "name": "Rock_Sandstone_Red_Stalactite_Large",
      "filler": 1024
    },
    {
      "x": -1,
      "y": 1,
      "z": -5,
      "name": "Rock_Sandstone_Red"
    },
    {
      "x": -1,
      "y": 2,
      "z": -5,
      "name": "Rock_Sandstone_Red"
    },
    {
      "x": -1,
      "y": 0,
      "z": -4,
      "name": "Rock_Sandstone_Red"
    },
    {
      "x": -1,
      "y": 1,
      "z": -4,
      "name": "Rock_Sandstone_Red"
    },
    {
      "x": -1,
      "y": 2,
      "z": -4,
      "name": "Rock_Sandstone_Red"
    },
    {
      "x": -1,
      "y": 3,
      "z": -4,
      "name": "Rock_Crystal_Red_Large"
    },
    {
      "x": -1,
      "y": 4,
      "z": -4,
      "name": "Rock_Crystal_Red_Medium",
      "rotation": 7
    },
    {
      "x": -1,
      "y": 0,
      "z": -3,
      "name": "Rock_Sandstone_Red"
    },
    {
      "x": -1,
      "y": 1,
      "z": -3,
      "name": "Rock_Sandstone_Red"
    },
    {
      "x": -1,
      "y": 2,
      "z": -3,
      "name": "Rock_Crystal_Red_Block"
    },
    {
      "x": -1,
      "y": 3,
      "z": -3,
      "name": "Rock_Crystal_Red_Block"
    },
    {
      "x": -1,
      "y": 4,
      "z": -3,
      "name": "Rock_Crystal_Red_Block"
    },
    {
      "x": -1,
      "y": 5,
      "z": -3,
      "name": "Rock_Crystal_Red_Medium"
    },
    {
      "x": -1,
      "y": 6,
      "z": -3,
      "name": "Rock_Crystal_Red_Medium",
      "rotation": 7
    },
    {
      "x": -1,
      "y": 1,
      "z": -2,
      "name": "Rock_Sandstone_Red"
    },
    {
      "x": -1,
      "y": 2,
      "z": -2,
      "name": "Rock_Sandstone_Red"
    },
    {
      "x": -1,
      "y": 3,
      "z": -2,
      "name": "Rock_Crystal_Red_Medium",
      "rotation": 4
    },
    {
      "x": 0,
      "y": 1,
      "z": -5,
      "name": "Rock_Sandstone_Red"
    },
    {
      "x": 0,
      "y": 2,
      "z": -5,
      "name": "Rock_Sandstone_Red"
    },
    {
      "x": 0,
      "y": 3,
      "z": -5,
      "name": "Rock_Crystal_Red_Medium",
      "rotation": 6
    },
    {
      "x": 0,
      "y": 4,
      "z": -5,
      "name": "Rock_Crystal_Red_Medium",
      "rotation": 6
    },
    {
      "x": 0,
      "y": 0,
      "z": -4,
      "name": "Rock_Sandstone_Red"
    },
    {
      "x": 0,
      "y": 1,
      "z": -4,
      "name": "Rock_Sandstone_Red"
    },
    {
      "x": 0,
      "y": 2,
      "z": -4,
      "name": "Rock_Crystal_Red_Block"
    },
    {
      "x": 0,
      "y": 3,
      "z": -4,
      "name": "Rock_Crystal_Red_Block"
    },
    {
      "x": 0,
      "y": 4,
      "z": -4,
      "name": "Rock_Crystal_Red_Block"
    },
    {
      "x": 0,
      "y": 5,
      "z": -4,
      "name": "Rock_Crystal_Red_Medium"
    },
    {
      "x": 0,
      "y": 0,
      "z": -3,
      "name": "Rock_Sandstone_Red"
    },
    {
      "x": 0,
      "y": 1,
      "z": -3,
      "name": "Rock_Sandstone_Red"
    },
    {
      "x": 0,
      "y": 2,
      "z": -3,
      "name": "Rock_Crystal_Red_Block"
    },
    {
      "x": 0,
      "y": 3,
      "z": -3,
      "name": "Rock_Crystal_Red_Block"
    },
    {
      "x": 0,
      "y": 4,
      "z": -3,
      "name": "Rock_Crystal_Red_Block"
    },
    {
      "x": 0,
      "y": 5,
      "z": -3,
      "name": "Rock_Crystal_Red_Block"
    },
    {
      "x": 0,
      "y": 6,
      "z": -3,
      "name": "Rock_Crystal_Red_Block"
    },
    {
      "x": 0,
      "y": 7,
      "z": -3,
      "name": "Rock_Crystal_Red_Large"
    },
    {
      "x": 0,
      "y": 0,
      "z": -2,
      "name": "Rock_Sandstone_Red"
    },
    {
      "x": 0,
      "y": 1,
      "z": -2,
      "name": "Rock_Sandstone_Red"
    },
    {
      "x": 0,
      "y": 2,
      "z": -2,
      "name": "Rock_Crystal_Red_Block"
    },
    {
      "x": 0,
      "y": 3,
      "z": -2,
      "name": "Rock_Crystal_Red_Block"
    },
    {
      "x": 0,
      "y": 4,
      "z": -2,
      "name": "Rock_Crystal_Red_Block"
    },
    {
      "x": 0,
      "y": 5,
      "z": -2,
      "name": "Rock_Crystal_Red_Large"
    },
    {
      "x": 0,
      "y": 1,
      "z": -1,
      "name": "Rock_Sandstone_Red"
    },
    {
      "x": 0,
      "y": 2,
      "z": -1,
      "name": "Rock_Sandstone_Red"
    },
    {
      "x": 0,
      "y": 3,
      "z": -1,
      "name": "Rock_Crystal_Red_Medium",
      "rotation": 4
    },
    {
      "x": 0,
      "y": 2,
      "z": 0,
      "name": "Rock_Sandstone_Red"
    },
    {
      "x": 1,
      "y": 1,
      "z": -4,
      "name": "Rock_Sandstone_Red"
    },
    {
      "x": 1,
      "y": 2,
      "z": -4,
      "name": "Rock_Sandstone_Red"
    },
    {
      "x": 1,
      "y": 3,
      "z": -4,
      "name": "Rock_Crystal_Red_Medium",
      "rotation": 5
    },
    {
      "x": 1,
      "y": 4,
      "z": -4,
      "name": "Rock_Crystal_Red_Medium",
      "rotation": 5
    },
    {
      "x": 1,
      "y": 0,
      "z": -3,
      "name": "Rock_Sandstone_Red"
    },
    {
      "x": 1,
      "y": 1,
      "z": -3,
      "name": "Rock_Sandstone_Red"
    },
    {
      "x": 1,
      "y": 2,
      "z": -3,
      "name": "Rock_Crystal_Red_Block"
    },
    {
      "x": 1,
      "y": 3,
      "z": -3,
      "name": "Rock_Crystal_Red_Block"
    },
    {
      "x": 1,
      "y": 4,
      "z": -3,
      "name": "Rock_Crystal_Red_Medium"
    },
    {
      "x": 1,
      "y": 6,
      "z": -3,
      "name": "Rock_Crystal_Red_Large",
      "rotation": 5
    },
    {
      "x": 1,
      "y": 0,
      "z": -2,
      "name": "Rock_Sandstone_Red"
    },
    {
      "x": 1,
      "y": 1,
      "z": -2,
      "name": "Rock_Sandstone_Red"
    },
    {
      "x": 1,
      "y": 2,
      "z": -2,
      "name": "Rock_Sandstone_Red"
    },
    {
      "x": 1,
      "y": 0,
      "z": -1,
      "name": "Rock_Sandstone_Red"
    },
    {
      "x": 1,
      "y": 1,
      "z": -1,
      "name": "Rock_Sandstone_Red"
    },
    {
      "x": 1,
      "y": 2,
      "z": -1,
      "name": "Rock_Sandstone_Red"
    },
    {
      "x": 1,
      "y": 1,
      "z": 0,
      "name": "Rock_Sandstone_Red"
    },
    {
      "x": 1,
      "y": 2,
      "z": 0,
      "name": "Rock_Sandstone_Red"
    },
    {
      "x": 1,
      "y": 2,
      "z": 1,
      "name": "Rock_Sandstone_Red"
    },
    {
      "x": 2,
      "y": 1,
      "z": -3,
      "name": "Rock_Sandstone_Red"
    },
    {
      "x": 2,
      "y": 2,
      "z": -3,
      "name": "Rock_Sandstone_Red"
    },
    {
      "x": 2,
      "y": 3,
      "z": -3,
      "name": "Rock_Sandstone_Red_Stalactite_Small"
    },
    {
      "x": 2,
      "y": 0,
      "z": -2,
      "name": "Rock_Sandstone_Red"
    },
    {
      "x": 2,
      "y": 1,
      "z": -2,
      "name": "Rock_Sandstone_Red"
    },
    {
      "x": 2,
      "y": 2,
      "z": -2,
      "name": "Rock_Sandstone_Red"
    },
    {
      "x": 2,
      "y": 1,
      "z": -1,
      "name": "Rock_Sandstone_Red"
    },
    {
      "x": 2,
      "y": 2,
      "z": -1,
      "name": "Rock_Sandstone_Red"
    },
    {
      "x": 2,
      "y": 2,
      "z": 0,
      "name": "Rock_Sandstone_Red"
    },
    {
      "x": 3,
      "y": 2,
      "z": -2,
      "name": "Rock_Sandstone_Red"
    },
    {
      "x": 3,
      "y": 2,
      "z": -1,
      "name": "Rock_Sandstone_Red"
    }
  ],
  "fluids": [
    {
      "x": -3,
      "y": 1,
      "z": -3,
      "name": "Empty",
      "level": 0
    },
    {
      "x": -3,
      "y": 2,
      "z": -3,
      "name": "Empty",
      "level": 0
    },
    {
      "x": -3,
      "y": 3,
      "z": -3,
      "name": "Empty",
      "level": 0
    },
    {
      "x": -2,
      "y": 1,
      "z": -4,
      "name": "Empty",
      "level": 0
    },
    {
      "x": -2,
      "y": 2,
      "z": -4,
      "name": "Empty",
      "level": 0
    },
    {
      "x": -2,
      "y": 3,
      "z": -4,
      "name": "Empty",
      "level": 0
    },
    {
      "x": -2,
      "y": 0,
      "z": -3,
      "name": "Empty",
      "level": 0
    },
    {
      "x": -2,
      "y": 1,
      "z": -3,
      "name": "Empty",
      "level": 0
    },
    {
      "x": -2,
      "y": 2,
      "z": -3,
      "name": "Empty",
      "level": 0
    },
    {
      "x": -2,
      "y": 3,
      "z": -3,
      "name": "Empty",
      "level": 0
    },
    {
      "x": -2,
      "y": 4,
      "z": -3,
      "name": "Empty",
      "level": 0
    },
    {
      "x": -2,
      "y": 1,
      "z": -2,
      "name": "Empty",
      "level": 0
    },
    {
      "x": -2,
      "y": 2,
      "z": -2,
      "name": "Empty",
      "level": 0
    },
    {
      "x": -2,
      "y": 3,
      "z": -2,
      "name": "Empty",
      "level": 0
    },
    {
      "x": -2,
      "y": 4,
      "z": -2,
      "name": "Empty",
      "level": 0
    },
    {
      "x": -1,
      "y": 1,
      "z": -5,
      "name": "Empty",
      "level": 0
    },
    {
      "x": -1,
      "y": 2,
      "z": -5,
      "name": "Empty",
      "level": 0
    },
    {
      "x": -1,
      "y": 0,
      "z": -4,
      "name": "Empty",
      "level": 0
    },
    {
      "x": -1,
      "y": 1,
      "z": -4,
      "name": "Empty",
      "level": 0
    },
    {
      "x": -1,
      "y": 2,
      "z": -4,
      "name": "Empty",
      "level": 0
    },
    {
      "x": -1,
      "y": 3,
      "z": -4,
      "name": "Empty",
      "level": 0
    },
    {
      "x": -1,
      "y": 4,
      "z": -4,
      "name": "Empty",
      "level": 0
    },
    {
      "x": -1,
      "y": 0,
      "z": -3,
      "name": "Empty",
      "level": 0
    },
    {
      "x": -1,
      "y": 1,
      "z": -3,
      "name": "Empty",
      "level": 0
    },
    {
      "x": -1,
      "y": 2,
      "z": -3,
      "name": "Empty",
      "level": 0
    },
    {
      "x": -1,
      "y": 3,
      "z": -3,
      "name": "Empty",
      "level": 0
    },
    {
      "x": -1,
      "y": 4,
      "z": -3,
      "name": "Empty",
      "level": 0
    },
    {
      "x": -1,
      "y": 5,
      "z": -3,
      "name": "Empty",
      "level": 0
    },
    {
      "x": -1,
      "y": 6,
      "z": -3,
      "name": "Empty",
      "level": 0
    },
    {
      "x": -1,
      "y": 1,
      "z": -2,
      "name": "Empty",
      "level": 0
    },
    {
      "x": -1,
      "y": 2,
      "z": -2,
      "name": "Empty",
      "level": 0
    },
    {
      "x": -1,
      "y": 3,
      "z": -2,
      "name": "Empty",
      "level": 0
    },
    {
      "x": 0,
      "y": 1,
      "z": -5,
      "name": "Empty",
      "level": 0
    },
    {
      "x": 0,
      "y": 2,
      "z": -5,
      "name": "Empty",
      "level": 0
    },
    {
      "x": 0,
      "y": 3,
      "z": -5,
      "name": "Empty",
      "level": 0
    },
    {
      "x": 0,
      "y": 4,
      "z": -5,
      "name": "Empty",
      "level": 0
    },
    {
      "x": 0,
      "y": 0,
      "z": -4,
      "name": "Empty",
      "level": 0
    },
    {
      "x": 0,
      "y": 1,
      "z": -4,
      "name": "Empty",
      "level": 0
    },
    {
      "x": 0,
      "y": 2,
      "z": -4,
      "name": "Empty",
      "level": 0
    },
    {
      "x": 0,
      "y": 3,
      "z": -4,
      "name": "Empty",
      "level": 0
    },
    {
      "x": 0,
      "y": 4,
      "z": -4,
      "name": "Empty",
      "level": 0
    },
    {
      "x": 0,
      "y": 5,
      "z": -4,
      "name": "Empty",
      "level": 0
    },
    {
      "x": 0,
      "y": 0,
      "z": -3,
      "name": "Empty",
      "level": 0
    },
    {
      "x": 0,
      "y": 1,
      "z": -3,
      "name": "Empty",
      "level": 0
    },
    {
      "x": 0,
      "y": 2,
      "z": -3,
      "name": "Empty",
      "level": 0
    },
    {
      "x": 0,
      "y": 3,
      "z": -3,
      "name": "Empty",
      "level": 0
    },
    {
      "x": 0,
      "y": 4,
      "z": -3,
      "name": "Empty",
      "level": 0
    },
    {
      "x": 0,
      "y": 5,
      "z": -3,
      "name": "Empty",
      "level": 0
    },
    {
      "x": 0,
      "y": 6,
      "z": -3,
      "name": "Empty",
      "level": 0
    },
    {
      "x": 0,
      "y": 7,
      "z": -3,
      "name": "Empty",
      "level": 0
    },
    {
      "x": 0,
      "y": 0,
      "z": -2,
      "name": "Empty",
      "level": 0
    },
    {
      "x": 0,
      "y": 1,
      "z": -2,
      "name": "Empty",
      "level": 0
    },
    {
      "x": 0,
      "y": 2,
      "z": -2,
      "name": "Empty",
      "level": 0
    },
    {
      "x": 0,
      "y": 3,
      "z": -2,
      "name": "Empty",
      "level": 0
    },
    {
      "x": 0,
      "y": 4,
      "z": -2,
      "name": "Empty",
      "level": 0
    },
    {
      "x": 0,
      "y": 5,
      "z": -2,
      "name": "Empty",
      "level": 0
    },
    {
      "x": 0,
      "y": 1,
      "z": -1,
      "name": "Empty",
      "level": 0
    },
    {
      "x": 0,
      "y": 2,
      "z": -1,
      "name": "Empty",
      "level": 0
    },
    {
      "x": 0,
      "y": 3,
      "z": -1,
      "name": "Empty",
      "level": 0
    },
    {
      "x": 0,
      "y": 2,
      "z": 0,
      "name": "Empty",
      "level": 0
    },
    {
      "x": 1,
      "y": 1,
      "z": -4,
      "name": "Empty",
      "level": 0
    },
    {
      "x": 1,
      "y": 2,
      "z": -4,
      "name": "Empty",
      "level": 0
    },
    {
      "x": 1,
      "y": 3,
      "z": -4,
      "name": "Empty",
      "level": 0
    },
    {
      "x": 1,
      "y": 4,
      "z": -4,
      "name": "Empty",
      "level": 0
    },
    {
      "x": 1,
      "y": 0,
      "z": -3,
      "name": "Empty",
      "level": 0
    },
    {
      "x": 1,
      "y": 1,
      "z": -3,
      "name": "Empty",
      "level": 0
    },
    {
      "x": 1,
      "y": 2,
      "z": -3,
      "name": "Empty",
      "level": 0
    },
    {
      "x": 1,
      "y": 3,
      "z": -3,
      "name": "Empty",
      "level": 0
    },
    {
      "x": 1,
      "y": 4,
      "z": -3,
      "name": "Empty",
      "level": 0
    },
    {
      "x": 1,
      "y": 6,
      "z": -3,
      "name": "Empty",
      "level": 0
    },
    {
      "x": 1,
      "y": 0,
      "z": -2,
      "name": "Empty",
      "level": 0
    },
    {
      "x": 1,
      "y": 1,
      "z": -2,
      "name": "Empty",
      "level": 0
    },
    {
      "x": 1,
      "y": 2,
      "z": -2,
      "name": "Empty",
      "level": 0
    },
    {
      "x": 1,
      "y": 0,
      "z": -1,
      "name": "Empty",
      "level": 0
    },
    {
      "x": 1,
      "y": 1,
      "z": -1,
      "name": "Empty",
      "level": 0
    },
    {
      "x": 1,
      "y": 2,
      "z": -1,
      "name": "Empty",
      "level": 0
    },
    {
      "x": 1,
      "y": 1,
      "z": 0,
      "name": "Empty",
      "level": 0
    },
    {
      "x": 1,
      "y": 2,
      "z": 0,
      "name": "Empty",
      "level": 0
    },
    {
      "x": 1,
      "y": 2,
      "z": 1,
      "name": "Empty",
      "level": 0
    },
    {
      "x": 2,
      "y": 1,
      "z": -3,
      "name": "Empty",
      "level": 0
    },
    {
      "x": 2,
      "y": 2,
      "z": -3,
      "name": "Empty",
      "level": 0
    },
    {
      "x": 2,
      "y": 3,
      "z": -3,
      "name": "Empty",
      "level": 0
    },
    {
      "x": 2,
      "y": 0,
      "z": -2,
      "name": "Empty",
      "level": 0
    },
    {
      "x": 2,
      "y": 1,
      "z": -2,
      "name": "Empty",
      "level": 0
    },
    {
      "x": 2,
      "y": 2,
      "z": -2,
      "name": "Empty",
      "level": 0
    },
    {
      "x": 2,
      "y": 1,
      "z": -1,
      "name": "Empty",
      "level": 0
    },
    {
      "x": 2,
      "y": 2,
      "z": -1,
      "name": "Empty",
      "level": 0
    },
    {
      "x": 2,
      "y": 2,
      "z": 0,
      "name": "Empty",
      "level": 0
    },
    {
      "x": 3,
      "y": 2,
      "z": -2,
      "name": "Empty",
      "level": 0
    },
    {
      "x": 3,
      "y": 2,
      "z": -1,
      "name": "Empty",
      "level": 0
    }
  ],
  "entities": [
    {
      "Components": {
        "Nameplate": {
          "Text": "Fullmetal_Crystalwulf_Red"
        },
        "HiddenFromAdventurePlayer": {},
        "RefId": {
          "Count": 2
        },
        "SpawnMarkerComponent": {
          "SpawnMarker": "Fullmetal_Crystalwulf_Red",
          "RespawnTime": 0.0,
          "SpawnCount": 1,
          "GameTimeRespawn": "PT24H",
          "NPCReferences": [
            {
              "UUID": {
                "$binary": "Vw8HUCTmPK+KgRRWQu3f/Q==",
                "$type": "04"
              },
              "RefCount": 0
            }
          ],
          "PersistedFlock": {},
          "SpawnPosition": {
            "X": -672.5,
            "Y": 80.0,
            "Z": 270.5
          }
        },
        "Transform": {
          "Position": {
            "X": -0.0897216796875,
            "Y": 4.229026794433594,
            "Z": 1.278228759765625
          },
          "Rotation": {
            "Pitch": 0.0,
            "Yaw": 1.2079639434814453,
            "Roll": 0.0
          }
        },
        "Intangible": {},
        "PrefabCopyable": {},
        "Model": {
          "Model": {
            "Id": "NPC_Spawn_Marker",
            "Scale": 1.0,
            "Static": false
          }
        },
        "UUID": {
          "UUID": {
            "$binary": "p2f17JXQPHOiXNFmNX5bTg==",
            "$type": "04"
          }
        },
        "WorldGenId": {
          "WorldGenId": 0
        },
        "HeadRotation": {
          "Rotation": {
            "Pitch": 0.0,
            "Yaw": 1.2079639434814453,
            "Roll": 0.0
          }
        }
      }
    },
    {
      "Components": {
        "Nameplate": {
          "Text": "Fullmetal_Crystalwulf_Red"
        },
        "HiddenFromAdventurePlayer": {},
        "RefId": {
          "Count": 2
        },
        "SpawnMarkerComponent": {
          "SpawnMarker": "Fullmetal_Crystalwulf_Red",
          "RespawnTime": 0.0,
          "SpawnCount": 1,
          "GameTimeRespawn": "PT24H",
          "NPCReferences": [
            {
              "UUID": {
                "$binary": "WUvHOiYSOO2w0MDCR6Obug==",
                "$type": "04"
              },
              "RefCount": 0
            }
          ],
          "PersistedFlock": {},
          "SpawnPosition": {
            "X": -666.5,
            "Y": 80.0,
            "Z": 267.5
          }
        },
        "Transform": {
          "Position": {
            "X": 3.323974609375,
            "Y": 4.286933898925781,
            "Z": 0.723968505859375
          },
          "Rotation": {
            "Pitch": 0.0,
            "Yaw": 1.2079639434814453,
            "Roll": 0.0
          }
        },
        "Intangible": {},
        "PrefabCopyable": {},
        "Model": {
          "Model": {
            "Id": "NPC_Spawn_Marker",
            "Scale": 1.0,
            "Static": false
          }
        },
        "UUID": {
          "UUID": {
            "$binary": "udZWeOaoPJWraRO+sXfKzg==",
            "$type": "04"
          }
        },
        "WorldGenId": {
          "WorldGenId": 0
        },
        "HeadRotation": {
          "Rotation": {
            "Pitch": 0.0,
            "Yaw": 1.2079639434814453,
            "Roll": 0.0
          }
        }
      }
    },
    {
      "Components": {
        "UtilityInventory": {
          "Inventory": {
            "Id": "Empty"
          },
          "ActiveSlot": -1
        },
        "EffectController": {},
        "DisplayName": {
          "DisplayName": {
            "MessageId": "server.npcRoles.Emberwulf.name",
            "Bold": null,
            "Italic": null,
            "Monospace": null,
            "Underline": null
          }
        },
        "RefId": {
          "Count": 0
        },
        "UIComponentList": {},
        "HotbarInventory": {
          "Inventory": {
            "Id": "Simple",
            "Capacity": 3,
            "Items": {}
          },
          "ActiveSlot": 0
        },
        "Transform": {
          "Position": {
            "X": 2.92840576171875,
            "Y": 3.9639968872070312,
            "Z": 0.86907958984375
          },
          "Rotation": {
            "Pitch": 0.0,
            "Yaw": 1.2079639434814453,
            "Roll": 0.0
          }
        },
        "StorageInventory": {
          "Inventory": {
            "Id": "Empty"
          }
        },
        "Velocity": {
          "Velocity": {
            "X": 0.0,
            "Y": 0.0,
            "Z": 0.0
          }
        },
        "PrefabCopyable": {},
        "Interactions": {
          "Interactions": {
            "Use": "*UseNPC"
          }
        },
        "Model": {
          "Model": {
            "Id": "Fullmetal_Crystalwulf_Red",
            "Scale": 0.9950916171073914,
            "Static": false
          }
        },
        "UUID": {
          "UUID": {
            "$binary": "WUvHOiYSOO2w0MDCR6Obug==",
            "$type": "04"
          }
        },
        "EntityStats": {
          "Version": 5,
          "Stats": {
            "Oxygen": {
              "Id": "Oxygen",
              "Value": 100.0
            },
            "Mana": {
              "Id": "Mana",
              "Value": 0.0
            },
            "Health": {
              "Id": "Health",
              "Value": 100.0,
              "Modifiers": {
                "NPC_Max": {
                  "Id": "Static",
                  "CalculationType": "Additive",
                  "Amount": 350.0
                }
              }
            },
            "GlidingActive": {
              "Id": "GlidingActive",
              "Value": 0.0
            },
            "Immunity": {
              "Id": "Immunity",
              "Value": 0.0
            },
            "SignatureCharges": {
              "Id": "SignatureCharges",
              "Value": 0.0
            },
            "Stamina": {
              "Id": "Stamina",
              "Value": 10.0
            },
            "Ammo": {
              "Id": "Ammo",
              "Value": 0.0
            },
            "Unknown": {
              "Id": "Unknown",
              "Value": 0.0
            },
            "SignatureEnergy": {
              "Id": "SignatureEnergy",
              "Value": 0.0
            },
            "DeployablePreview": {
              "Id": "DeployablePreview",
              "Value": 0.0
            },
            "StaminaRegenDelay": {
              "Id": "StaminaRegenDelay",
              "Value": 0.0
            },
            "MagicCharges": {
              "Id": "MagicCharges",
              "Value": 0.0
            }
          }
        },
        "SpawnMarkerReference": {
          "SpawnMarker": {
            "UUID": {
              "$binary": "udZWeOaoPJWraRO+sXfKzg==",
              "$type": "04"
            },
            "RefCount": 2
          }
        },
        "WorldGenId": {
          "WorldGenId": 0
        },
        "NPC": {
          "Version": 5,
          "UUID": {
            "$binary": "WUvHOiYSOO2w0MDCR6Obug==",
            "$type": "04"
          },
          "Inventory": {
            "Version": 4,
            "ActiveHotbarSlot": 0,
            "ActiveToolsSlot": -1,
            "ActiveUtilitySlot": -1
          },
          "HvrPhs": 0.0,
          "HvrHght": 0.0,
          "MdlScl": 0.9950916171073914,
          "SpawnInstant": "0001-02-02T12:00:00Z",
          "WorldgenId": 0,
          "PathManager": {},
          "LeashPos": {
            "X": -666.5,
            "Y": 80.0,
            "Z": 267.5
          },
          "LeashHdg": 1.2079639434814453,
          "LeashPtch": 0.0,
          "RoleName": "Fullmetal_Crystalwulf_Red"
        },
        "ArmorInventory": {
          "Inventory": {
            "Id": "Simple",
            "Capacity": 4,
            "Items": {}
          }
        },
        "HeadRotation": {
          "Rotation": {
            "Pitch": 0.0,
            "Yaw": 1.2079639434814453,
            "Roll": 0.0
          }
        }
      }
    },
    {
      "Components": {
        "UtilityInventory": {
          "Inventory": {
            "Id": "Empty"
          },
          "ActiveSlot": -1
        },
        "EffectController": {},
        "DisplayName": {
          "DisplayName": {
            "MessageId": "server.npcRoles.Emberwulf.name",
            "Bold": null,
            "Italic": null,
            "Monospace": null,
            "Underline": null
          }
        },
        "RefId": {
          "Count": 0
        },
        "UIComponentList": {},
        "HotbarInventory": {
          "Inventory": {
            "Id": "Simple",
            "Capacity": 3,
            "Items": {}
          },
          "ActiveSlot": 0
        },
        "Transform": {
          "Position": {
            "X": 1.01226806640625,
            "Y": 3.5530853271484375,
            "Z": 2.340911865234375
          },
          "Rotation": {
            "Pitch": 0.0,
            "Yaw": 1.2079639434814453,
            "Roll": 0.0
          }
        },
        "StorageInventory": {
          "Inventory": {
            "Id": "Empty"
          }
        },
        "Velocity": {
          "Velocity": {
            "X": 0.0,
            "Y": 0.0,
            "Z": 0.0
          }
        },
        "PrefabCopyable": {},
        "Interactions": {
          "Interactions": {
            "Use": "*UseNPC"
          }
        },
        "Model": {
          "Model": {
            "Id": "Fullmetal_Crystalwulf_Red",
            "Scale": 0.9981227517127991,
            "Static": false
          }
        },
        "UUID": {
          "UUID": {
            "$binary": "Vw8HUCTmPK+KgRRWQu3f/Q==",
            "$type": "04"
          }
        },
        "EntityStats": {
          "Version": 5,
          "Stats": {
            "Oxygen": {
              "Id": "Oxygen",
              "Value": 100.0
            },
            "Mana": {
              "Id": "Mana",
              "Value": 0.0
            },
            "Health": {
              "Id": "Health",
              "Value": 100.0,
              "Modifiers": {
                "NPC_Max": {
                  "Id": "Static",
                  "CalculationType": "Additive",
                  "Amount": 350.0
                }
              }
            },
            "GlidingActive": {
              "Id": "GlidingActive",
              "Value": 0.0
            },
            "Immunity": {
              "Id": "Immunity",
              "Value": 0.0
            },
            "SignatureCharges": {
              "Id": "SignatureCharges",
              "Value": 0.0
            },
            "Stamina": {
              "Id": "Stamina",
              "Value": 10.0
            },
            "Ammo": {
              "Id": "Ammo",
              "Value": 0.0
            },
            "Unknown": {
              "Id": "Unknown",
              "Value": 0.0
            },
            "SignatureEnergy": {
              "Id": "SignatureEnergy",
              "Value": 0.0
            },
            "DeployablePreview": {
              "Id": "DeployablePreview",
              "Value": 0.0
            },
            "StaminaRegenDelay": {
              "Id": "StaminaRegenDelay",
              "Value": 0.0
            },
            "MagicCharges": {
              "Id": "MagicCharges",
              "Value": 0.0
            }
          }
        },
        "SpawnMarkerReference": {
          "SpawnMarker": {
            "UUID": {
              "$binary": "p2f17JXQPHOiXNFmNX5bTg==",
              "$type": "04"
            },
            "RefCount": 2
          }
        },
        "WorldGenId": {
          "WorldGenId": 0
        },
        "NPC": {
          "Version": 5,
          "UUID": {
            "$binary": "Vw8HUCTmPK+KgRRWQu3f/Q==",
            "$type": "04"
          },
          "Inventory": {
            "Version": 4,
            "ActiveHotbarSlot": 0,
            "ActiveToolsSlot": -1,
            "ActiveUtilitySlot": -1
          },
          "HvrPhs": 0.0,
          "HvrHght": 0.0,
          "MdlScl": 0.9981227517127991,
          "SpawnInstant": "0001-02-02T12:00:00Z",
          "WorldgenId": 0,
          "PathManager": {},
          "LeashPos": {
            "X": -672.5,
            "Y": 80.0,
            "Z": 270.5
          },
          "LeashHdg": 1.2079639434814453,
          "LeashPtch": 0.0,
          "RoleName": "Fullmetal_Crystalwulf_Red"
        },
        "ArmorInventory": {
          "Inventory": {
            "Id": "Simple",
            "Capacity": 4,
            "Items": {}
          }
        },
        "HeadRotation": {
          "Rotation": {
            "Pitch": 0.0,
            "Yaw": 1.2079639434814453,
            "Roll": 0.0
          }
        }
      }
    }
  ]
}