{
  "version": 8,
  "blockIdVersion": 11,
  "anchorX": 0,
  "anchorY": 0,
  "anchorZ": 0,
  "blocks": [
    {
      "x": -1,
      "y": 1,
      "z": -1,
      "name": "Rock_Sandstone_Red"
    },
    {
      "x": -1,
      "y": 2,
      "z": -1,
      "name": "Rock_Sandstone_Red"
    },
    {
      "x": -1,
      "y": 1,
      "z": 0,
      "name": "Rock_Sandstone_Red"
    },
    {
      "x": -1,
      "y": 2,
      "z": 0,
      "name": "Rock_Sandstone_Red"
    },
    {
      "x": -1,
      "y": 1,
      "z": 1,
      "name": "Rock_Sandstone_Red"
    },
    {
      "x": 0,
      "y": 1,
      "z": -2,
      "name": "Rock_Sandstone_Red_Cobble"
    },
    {
      "x": 0,
      "y": 0,
      "z": -1,
      "name": "Rock_Sandstone_Red"
    },
    {
      "x": 0,
      "y": 1,
      "z": -1,
      "name": "Rock_Sandstone_Red"
    },
    {
      "x": 0,
      "y": 2,
      "z": -1,
      "name": "Rock_Sandstone_Red"
    },
    {
      "x": 0,
      "y": 0,
      "z": 0,
      "name": "Rock_Sandstone_Red"
    },
    {
      "x": 0,
      "y": 1,
      "z": 0,
      "name": "Rock_Sandstone_Red"
    },
    {
      "x": 0,
      "y": 2,
      "z": 0,
      "name": "Rock_Sandstone_Red"
    },
    {
      "x": 0,
      "y": 0,
      "z": 1,
      "name": "Rock_Sandstone_Red"
    },
    {
      "x": 0,
      "y": 1,
      "z": 1,
      "name": "Rock_Sandstone_Red"
    },
    {
      "x": 0,
      "y": 2,
      "z": 1,
      "name": "Rock_Sandstone_Red"
    },
    {
      "x": 0,
      "y": 1,
      "z": 2,
      "name": "Rock_Sandstone_Red"
    },
    {
      "x": 1,
      "y": 1,
      "z": -3,
      "name": "Rock_Sandstone_Red_Cobble"
    },
    {
      "x": 1,
      "y": 2,
      "z": -3,
      "name": "Plant_Crop_Mushroom_Glowing_Violet"
    },
    {
      "x": 1,
      "y": 0,
      "z": -2,
      "name": "Rock_Sandstone_Red"
    },
    {
      "x": 1,
      "y": 1,
      "z": -2,
      "name": "Rock_Sandstone_Red_Cobble"
    },
    {
      "x": 1,
      "y": 0,
      "z": -1,
      "name": "Rock_Sandstone_Red"
    },
    {
      "x": 1,
      "y": 1,
      "z": -1,
      "name": "Rock_Sandstone_Red_Cobble"
    },
    {
      "x": 1,
      "y": 2,
      "z": -1,
      "name": "Rock_Sandstone_Red_Cobble"
    },
    {
      "x": 1,
      "y": 0,
      "z": 0,
      "name": "Rock_Sandstone_Red_Cobble"
    },
    {
      "x": 1,
      "y": 1,
      "z": 0,
      "name": "Rock_Sandstone_Red"
    },
    {
      "x": 1,
      "y": 2,
      "z": 0,
      "name": "Rock_Sandstone_Red_Cobble"
    },
    {
      "x": 1,
      "y": 0,
      "z": 1,
      "name": "Rock_Sandstone_Red"
    },
    {
      "x": 1,
      "y": 1,
      "z": 1,
      "name": "Rock_Sandstone_Red"
    },
    {
      "x": 1,
      "y": 2,
      "z": 1,
      "name": "Rock_Sandstone_Red"
    },
    {
      "x": 1,
      "y": 1,
      "z": 2,
      "name": "Rock_Sandstone_Red"
    },
    {
      "x": 1,
      "y": 2,
      "z": 2,
      "name": "Rock_Sandstone_Red"
    },
    {
      "x": 2,
      "y": 1,
      "z": -2,
      "name": "Rock_Sandstone_Red_Cobble"
    },
    {
      "x": 2,
      "y": 0,
      "z": -1,
      "name": "Rock_Sandstone_Red"
    },
    {
      "x": 2,
      "y": 1,
      "z": -1,
      "name": "Rock_Sandstone_Red_Cobble"
    },
    {
      "x": 2,
      "y": 0,
      "z": 0,
      "name": "Rock_Sandstone_Red"
    },
    {
      "x": 2,
      "y": 1,
      "z": 0,
      "name": "Rock_Sandstone_Red"
    },
    {
      "x": 2,
      "y": 2,
      "z": 0,
      "name": "Rock_Sandstone_Red_Cobble"
    },
    {
      "x": 2,
      "y": 1,
      "z": 1,
      "name": "Rock_Sandstone_Red"
    },
    {
      "x": 2,
      "y": 2,
      "z": 1,
      "name": "Rock_Sandstone_Red"
    },
    {
      "x": 2,
      "y": 1,
      "z": 2,
      "name": "Rock_Sandstone_Red"
    },
    {
      "x": 2,
      "y": 2,
      "z": 2,
      "name": "Rock_Sandstone_Red"
    },
    {
      "x": 2,
      "y": 3,
      "z": 2,
      "name": "Plant_Crop_Mushroom_Glowing_Violet"
    },
    {
      "x": 3,
      "y": 1,
      "z": -1,
      "name": "Rock_Sandstone_Red_Cobble"
    },
    {
      "x": 3,
      "y": 2,
      "z": -1,
      "name": "Plant_Crop_Mushroom_Glowing_Red"
    },
    {
      "x": 3,
      "y": 1,
      "z": 0,
      "name": "Rock_Sandstone_Red_Cobble"
    },
    {
      "x": 3,
      "y": 1,
      "z": 1,
      "name": "Rock_Sandstone_Red_Cobble"
    }
  ],
  "fluids": [
    {
      "x": -1,
      "y": 1,
      "z": -1,
      "name": "Empty",
      "level": 0
    },
    {
      "x": -1,
      "y": 2,
      "z": -1,
      "name": "Empty",
      "level": 0
    },
    {
      "x": -1,
      "y": 1,
      "z": 0,
      "name": "Empty",
      "level": 0
    },
    {
      "x": -1,
      "y": 2,
      "z": 0,
      "name": "Empty",
      "level": 0
    },
    {
      "x": -1,
      "y": 1,
      "z": 1,
      "name": "Empty",
      "level": 0
    },
    {
      "x": 0,
      "y": 1,
      "z": -2,
      "name": "Empty",
      "level": 0
    },
    {
      "x": 0,
      "y": 0,
      "z": -1,
      "name": "Empty",
      "level": 0
    },
    {
      "x": 0,
      "y": 1,
      "z": -1,
      "name": "Empty",
      "level": 0
    },
    {
      "x": 0,
      "y": 2,
      "z": -1,
      "name": "Empty",
      "level": 0
    },
    {
      "x": 0,
      "y": 0,
      "z": 0,
      "name": "Empty",
      "level": 0
    },
    {
      "x": 0,
      "y": 1,
      "z": 0,
      "name": "Empty",
      "level": 0
    },
    {
      "x": 0,
      "y": 2,
      "z": 0,
      "name": "Empty",
      "level": 0
    },
    {
      "x": 0,
      "y": 0,
      "z": 1,
      "name": "Empty",
      "level": 0
    },
    {
      "x": 0,
      "y": 1,
      "z": 1,
      "name": "Empty",
      "level": 0
    },
    {
      "x": 0,
      "y": 2,
      "z": 1,
      "name": "Empty",
      "level": 0
    },
    {
      "x": 0,
      "y": 1,
      "z": 2,
      "name": "Empty",
      "level": 0
    },
    {
      "x": 1,
      "y": 1,
      "z": -3,
      "name": "Empty",
      "level": 0
    },
    {
      "x": 1,
      "y": 2,
      "z": -3,
      "name": "Empty",
      "level": 0
    },
    {
      "x": 1,
      "y": 0,
      "z": -2,
      "name": "Empty",
      "level": 0
    },
    {
      "x": 1,
      "y": 1,
      "z": -2,
      "name": "Empty",
      "level": 0
    },
    {
      "x": 1,
      "y": 0,
      "z": -1,
      "name": "Empty",
      "level": 0
    },
    {
      "x": 1,
      "y": 1,
      "z": -1,
      "name": "Empty",
      "level": 0
    },
    {
      "x": 1,
      "y": 2,
      "z": -1,
      "name": "Empty",
      "level": 0
    },
    {
      "x": 1,
      "y": 0,
      "z": 0,
      "name": "Empty",
      "level": 0
    },
    {
      "x": 1,
      "y": 1,
      "z": 0,
      "name": "Empty",
      "level": 0
    },
    {
      "x": 1,
      "y": 2,
      "z": 0,
      "name": "Empty",
      "level": 0
    },
    {
      "x": 1,
      "y": 0,
      "z": 1,
      "name": "Empty",
      "level": 0
    },
    {
      "x": 1,
      "y": 1,
      "z": 1,
      "name": "Empty",
      "level": 0
    },
    {
      "x": 1,
      "y": 2,
      "z": 1,
      "name": "Empty",
      "level": 0
    },
    {
      "x": 1,
      "y": 1,
      "z": 2,
      "name": "Empty",
      "level": 0
    },
    {
      "x": 1,
      "y": 2,
      "z": 2,
      "name": "Empty",
      "level": 0
    },
    {
      "x": 2,
      "y": 1,
      "z": -2,
      "name": "Empty",
      "level": 0
    },
    {
      "x": 2,
      "y": 0,
      "z": -1,
      "name": "Empty",
      "level": 0
    },
    {
      "x": 2,
      "y": 1,
      "z": -1,
      "name": "Empty",
      "level": 0
    },
    {
      "x": 2,
      "y": 0,
      "z": 0,
      "name": "Empty",
      "level": 0
    },
    {
      "x": 2,
      "y": 1,
      "z": 0,
      "name": "Empty",
      "level": 0
    },
    {
      "x": 2,
      "y": 2,
      "z": 0,
      "name": "Empty",
      "level": 0
    },
    {
      "x": 2,
      "y": 1,
      "z": 1,
      "name": "Empty",
      "level": 0
    },
    {
      "x": 2,
      "y": 2,
      "z": 1,
      "name": "Empty",
      "level": 0
    },
    {
      "x": 2,
      "y": 1,
      "z": 2,
      "name": "Empty",
      "level": 0
    },
    {
      "x": 2,
      "y": 2,
      "z": 2,
      "name": "Empty",
      "level": 0
    },
    {
      "x": 2,
      "y": 3,
      "z": 2,
      "name": "Empty",
      "level": 0
    },
    {
      "x": 3,
      "y": 1,
      "z": -1,
      "name": "Empty",
      "level": 0
    },
    {
      "x": 3,
      "y": 2,
      "z": -1,
      "name": "Empty",
      "level": 0
    },
    {
      "x": 3,
      "y": 1,
      "z": 0,
      "name": "Empty",
      "level": 0
    },
    {
      "x": 3,
      "y": 1,
      "z": 1,
      "name": "Empty",
      "level": 0
    }
  ],
  "entities": [
    {
      "Components": {
        "Nameplate": {
          "Text": "Fullmetal_Raptor_Cave"
        },
        "HiddenFromAdventurePlayer": {},
        "RefId": {
          "Count": 2
        },
        "SpawnMarkerComponent": {
          "SpawnMarker": "Fullmetal_Raptor_Cave",
          "RespawnTime": 0.0,
          "SpawnCount": 1,
          "GameTimeRespawn": "PT24H",
          "NPCReferences": [
            {
              "UUID": {
                "$binary": "jQ0fKQo5OSe/TsAovSGRWw==",
                "$type": "04"
              },
              "RefCount": 0
            }
          ],
          "PersistedFlock": {},
          "SpawnPosition": {
            "X": -297.5,
            "Y": 83.0,
            "Z": 199.5
          }
        },
        "Transform": {
          "Position": {
            "X": 1.378753662109375,
            "Y": 4.028343200683594,
            "Z": 2.02606201171875
          },
          "Rotation": {
            "Pitch": 0.0,
            "Yaw": 1.2079639434814453,
            "Roll": 0.0
          }
        },
        "Intangible": {},
        "PrefabCopyable": {},
        "Model": {
          "Model": {
            "Id": "NPC_Spawn_Marker",
            "Scale": 1.0,
            "Static": false
          }
        },
        "UUID": {
          "UUID": {
            "$binary": "K79er6NePfC/t4Oylku93A==",
            "$type": "04"
          }
        },
        "WorldGenId": {
          "WorldGenId": 0
        },
        "HeadRotation": {
          "Rotation": {
            "Pitch": 0.0,
            "Yaw": 1.2079639434814453,
            "Roll": 0.0
          }
        }
      }
    },
    {
      "Components": {
        "Nameplate": {
          "Text": "Fullmetal_Raptor_Cave"
        },
        "HiddenFromAdventurePlayer": {},
        "RefId": {
          "Count": 2
        },
        "SpawnMarkerComponent": {
          "SpawnMarker": "Fullmetal_Raptor_Cave",
          "RespawnTime": 0.0,
          "SpawnCount": 1,
          "GameTimeRespawn": "PT24H",
          "NPCReferences": [
            {
              "UUID": {
                "$binary": "PRCeyyYxOC6hscM85AUJIw==",
                "$type": "04"
              },
              "RefCount": 0
            }
          ],
          "PersistedFlock": {},
          "SpawnPosition": {
            "X": -298.5,
            "Y": 83.0,
            "Z": 197.5
          }
        },
        "Transform": {
          "Position": {
            "X": 0.378753662109375,
            "Y": 4.028343200683594,
            "Z": 0.02606201171875
          },
          "Rotation": {
            "Pitch": 0.0,
            "Yaw": 1.2079639434814453,
            "Roll": 0.0
          }
        },
        "Intangible": {},
        "PrefabCopyable": {},
        "Model": {
          "Model": {
            "Id": "NPC_Spawn_Marker",
            "Scale": 1.0,
            "Static": false
          }
        },
        "UUID": {
          "UUID": {
            "$binary": "HY1b7NIGObSIPi3wT+LAzw==",
            "$type": "04"
          }
        },
        "WorldGenId": {
          "WorldGenId": 0
        },
        "HeadRotation": {
          "Rotation": {
            "Pitch": 0.0,
            "Yaw": 1.2079639434814453,
            "Roll": 0.0
          }
        }
      }
    },
    {
      "Components": {
        "UtilityInventory": {
          "Inventory": {
            "Id": "Empty"
          },
          "ActiveSlot": -1
        },
        "EffectController": {},
        "DisplayName": {
          "DisplayName": {
            "MessageId": "server.npcRoles.Raptor_Cave.name",
            "Bold": null,
            "Italic": null,
            "Monospace": null,
            "Underline": null
          }
        },
        "RefId": {
          "Count": 0
        },
        "UIComponentList": {},
        "HotbarInventory": {
          "Inventory": {
            "Id": "Simple",
            "Capacity": 3,
            "Items": {}
          },
          "ActiveSlot": 0
        },
        "Transform": {
          "Position": {
            "X": 1.5,
            "Y": 3.0,
            "Z": 2.5
          },
          "Rotation": {
            "Pitch": 0.0,
            "Yaw": 1.2079639434814453,
            "Roll": 0.0
          }
        },
        "StorageInventory": {
          "Inventory": {
            "Id": "Empty"
          }
        },
        "Velocity": {
          "Velocity": {
            "X": 0.0,
            "Y": 0.0,
            "Z": 0.0
          }
        },
        "PrefabCopyable": {},
        "Interactions": {
          "Interactions": {
            "Use": "*UseNPC"
          }
        },
        "Model": {
          "Model": {
            "Id": "Fullmetal_Raptor_Cave",
            "Scale": 0.9084044098854065,
            "Static": false
          }
        },
        "UUID": {
          "UUID": {
            "$binary": "jQ0fKQo5OSe/TsAovSGRWw==",
            "$type": "04"
          }
        },
        "EntityStats": {
          "Version": 5,
          "Stats": {
            "Oxygen": {
              "Id": "Oxygen",
              "Value": 100.0
            },
            "Mana": {
              "Id": "Mana",
              "Value": 0.0
            },
            "Health": {
              "Id": "Health",
              "Value": 100.0,
              "Modifiers": {
                "NPC_Max": {
                  "Id": "Static",
                  "CalculationType": "Additive",
                  "Amount": 3.0
                }
              }
            },
            "GlidingActive": {
              "Id": "GlidingActive",
              "Value": 0.0
            },
            "Immunity": {
              "Id": "Immunity",
              "Value": 0.0
            },
            "SignatureCharges": {
              "Id": "SignatureCharges",
              "Value": 0.0
            },
            "Stamina": {
              "Id": "Stamina",
              "Value": 10.0
            },
            "Ammo": {
              "Id": "Ammo",
              "Value": 0.0
            },
            "Unknown": {
              "Id": "Unknown",
              "Value": 0.0
            },
            "SignatureEnergy": {
              "Id": "SignatureEnergy",
              "Value": 0.0
            },
            "DeployablePreview": {
              "Id": "DeployablePreview",
              "Value": 0.0
            },
            "StaminaRegenDelay": {
              "Id": "StaminaRegenDelay",
              "Value": 0.0
            },
            "MagicCharges": {
              "Id": "MagicCharges",
              "Value": 0.0
            }
          }
        },
        "SpawnMarkerReference": {
          "SpawnMarker": {
            "UUID": {
              "$binary": "K79er6NePfC/t4Oylku93A==",
              "$type": "04"
            },
            "RefCount": 2
          }
        },
        "WorldGenId": {
          "WorldGenId": 0
        },
        "NPC": {
          "Version": 5,
          "UUID": {
            "$binary": "jQ0fKQo5OSe/TsAovSGRWw==",
            "$type": "04"
          },
          "Inventory": {
            "Version": 4,
            "ActiveHotbarSlot": 0,
            "ActiveToolsSlot": -1,
            "ActiveUtilitySlot": -1
          },
          "HvrPhs": 0.0,
          "HvrHght": 0.0,
          "MdlScl": 0.9084044098854065,
          "SpawnInstant": "0001-02-03T12:00:00Z",
          "WorldgenId": 0,
          "PathManager": {},
          "LeashPos": {
            "X": -297.5,
            "Y": 83.0,
            "Z": 199.5
          },
          "LeashHdg": 1.2079639434814453,
          "LeashPtch": 0.0,
          "RoleName": "Fullmetal_Raptor_Cave"
        },
        "ArmorInventory": {
          "Inventory": {
            "Id": "Simple",
            "Capacity": 4,
            "Items": {}
          }
        },
        "HeadRotation": {
          "Rotation": {
            "Pitch": 0.0,
            "Yaw": 1.2079639434814453,
            "Roll": 0.0
          }
        }
      }
    },
    {
      "Components": {
        "UtilityInventory": {
          "Inventory": {
            "Id": "Empty"
          },
          "ActiveSlot": -1
        },
        "EffectController": {},
        "DisplayName": {
          "DisplayName": {
            "MessageId": "server.npcRoles.Raptor_Cave.name",
            "Bold": null,
            "Italic": null,
            "Monospace": null,
            "Underline": null
          }
        },
        "RefId": {
          "Count": 0
        },
        "UIComponentList": {},
        "HotbarInventory": {
          "Inventory": {
            "Id": "Simple",
            "Capacity": 3,
            "Items": {}
          },
          "ActiveSlot": 0
        },
        "Transform": {
          "Position": {
            "X": 0.5,
            "Y": 3.0,
            "Z": 0.5
          },
          "Rotation": {
            "Pitch": 0.0,
            "Yaw": 1.2079639434814453,
            "Roll": 0.0
          }
        },
        "StorageInventory": {
          "Inventory": {
            "Id": "Empty"
          }
        },
        "Velocity": {
          "Velocity": {
            "X": 0.0,
            "Y": 0.0,
            "Z": 0.0
          }
        },
        "PrefabCopyable": {},
        "Interactions": {
          "Interactions": {
            "Use": "*UseNPC"
          }
        },
        "Model": {
          "Model": {
            "Id": "Fullmetal_Raptor_Cave",
            "Scale": 0.9141302108764648,
            "Static": false
          }
        },
        "UUID": {
          "UUID": {
            "$binary": "PRCeyyYxOC6hscM85AUJIw==",
            "$type": "04"
          }
        },
        "EntityStats": {
          "Version": 5,
          "Stats": {
            "Oxygen": {
              "Id": "Oxygen",
              "Value": 100.0
            },
            "Mana": {
              "Id": "Mana",
              "Value": 0.0
            },
            "Health": {
              "Id": "Health",
              "Value": 100.0,
              "Modifiers": {
                "NPC_Max": {
                  "Id": "Static",
                  "CalculationType": "Additive",
                  "Amount": 3.0
                }
              }
            },
            "GlidingActive": {
              "Id": "GlidingActive",
              "Value": 0.0
            },
            "Immunity": {
              "Id": "Immunity",
              "Value": 0.0
            },
            "SignatureCharges": {
              "Id": "SignatureCharges",
              "Value": 0.0
            },
            "Stamina": {
              "Id": "Stamina",
              "Value": 10.0
            },
            "Ammo": {
              "Id": "Ammo",
              "Value": 0.0
            },
            "Unknown": {
              "Id": "Unknown",
              "Value": 0.0
            },
            "SignatureEnergy": {
              "Id": "SignatureEnergy",
              "Value": 0.0
            },
            "DeployablePreview": {
              "Id": "DeployablePreview",
              "Value": 0.0
            },
            "StaminaRegenDelay": {
              "Id": "StaminaRegenDelay",
              "Value": 0.0
            },
            "MagicCharges": {
              "Id": "MagicCharges",
              "Value": 0.0
            }
          }
        },
        "SpawnMarkerReference": {
          "SpawnMarker": {
            "UUID": {
              "$binary": "HY1b7NIGObSIPi3wT+LAzw==",
              "$type": "04"
            },
            "RefCount": 2
          }
        },
        "WorldGenId": {
          "WorldGenId": 0
        },
        "NPC": {
          "Version": 5,
          "UUID": {
            "$binary": "PRCeyyYxOC6hscM85AUJIw==",
            "$type": "04"
          },
          "Inventory": {
            "Version": 4,
            "ActiveHotbarSlot": 0,
            "ActiveToolsSlot": -1,
            "ActiveUtilitySlot": -1
          },
          "HvrPhs": 0.0,
          "HvrHght": 0.0,
          "MdlScl": 0.9141302108764648,
          "SpawnInstant": "0001-02-03T12:00:00Z",
          "WorldgenId": 0,
          "PathManager": {},
          "LeashPos": {
            "X": -298.5,
            "Y": 83.0,
            "Z": 197.5
          },
          "LeashHdg": 1.2079639434814453,
          "LeashPtch": 0.0,
          "RoleName": "Fullmetal_Raptor_Cave"
        },
        "ArmorInventory": {
          "Inventory": {
            "Id": "Simple",
            "Capacity": 4,
            "Items": {}
          }
        },
        "HeadRotation": {
          "Rotation": {
            "Pitch": 0.0,
            "Yaw": 1.2079639434814453,
            "Roll": 0.0
          }
        }
      }
    }
  ]
}