{
  "version": 8,
  "blockIdVersion": 11,
  "anchorX": 0,
  "anchorY": 0,
  "anchorZ": 0,
  "blocks": [
    {
      "x": -34,
      "y": -18,
      "z": -38,
      "name": "Soil_Grass"
    },
    {
      "x": -34,
      "y": -18,
      "z": -37,
      "name": "Soil_Grass"
    },
    {
      "x": -34,
      "y": -18,
      "z": -36,
      "name": "Soil_Grass"
    },
    {
      "x": -34,
      "y": -18,
      "z": -35,
      "name": "Soil_Grass"
    },
    {
      "x": -34,
      "y": -18,
      "z": -34,
      "name": "Soil_Grass"
    },
    {
      "x": -34,
      "y": -18,
      "z": -33,
      "name": "Soil_Grass"
    },
    {
      "x": -34,
      "y": -18,
      "z": -32,
      "name": "Soil_Grass"
    },
    {
      "x": -34,
      "y": -18,
      "z": -31,
      "name": "Soil_Grass"
    },
    {
      "x": -34,
      "y": -18,
      "z": -30,
      "name": "Soil_Grass"
    },
    {
      "x": -34,
      "y": -18,
      "z": -29,
      "name": "Soil_Grass"
    },
    {
      "x": -34,
      "y": -18,
      "z": -28,
      "name": "Soil_Grass"
    },
    {
      "x": -34,
      "y": -18,
      "z": -27,
      "name": "Soil_Grass"
    },
    {
      "x": -34,
      "y": -18,
      "z": -26,
      "name": "Soil_Grass"
    },
    {
      "x": -34,
      "y": -18,
      "z": -25,
      "name": "Soil_Grass"
    },
    {
      "x": -34,
      "y": -18,
      "z": -24,
      "name": "Soil_Grass"
    },
    {
      "x": -34,
      "y": -18,
      "z": -23,
      "name": "Soil_Grass"
    },
    {
      "x": -34,
      "y": -18,
      "z": -22,
      "name": "Soil_Grass"
    },
    {
      "x": -34,
      "y": -18,
      "z": -21,
      "name": "Soil_Grass"
    },
    {
      "x": -34,
      "y": -18,
      "z": -20,
      "name": "Soil_Grass"
    },
    {
      "x": -34,
      "y": -18,
      "z": -19,
      "name": "Soil_Grass"
    },
    {
      "x": -34,
      "y": -18,
      "z": -18,
      "name": "Soil_Grass"
    },
    {
      "x": -34,
      "y": -18,
      "z": -17,
      "name": "Soil_Grass"
    },
    {
      "x": -34,
      "y": -18,
      "z": -16,
      "name": "Soil_Grass"
    },
    {
      "x": -34,
      "y": -18,
      "z": -15,
      "name": "Soil_Grass"
    },
    {
      "x": -34,
      "y": -18,
      "z": -14,
      "name": "Soil_Grass"
    },
    {
      "x": -34,
      "y": -18,
      "z": -13,
      "name": "Soil_Grass"
    },
    {
      "x": -34,
      "y": -18,
      "z": -12,
      "name": "Soil_Grass"
    },
    {
      "x": -34,
      "y": -18,
      "z": -11,
      "name": "Soil_Grass"
    },
    {
      "x": -34,
      "y": -18,
      "z": -10,
      "name": "Soil_Grass"
    },
    {
      "x": -34,
      "y": -18,
      "z": -9,
      "name": "Soil_Grass"
    },
    {
      "x": -34,
      "y": -18,
      "z": -8,
      "name": "Soil_Grass"
    },
    {
      "x": -34,
      "y": -18,
      "z": -7,
      "name": "Soil_Grass"
    },
    {
      "x": -34,
      "y": -18,
      "z": -6,
      "name": "Soil_Grass"
    },
    {
      "x": -34,
      "y": -18,
      "z": -5,
      "name": "Soil_Grass"
    },
    {
      "x": -34,
      "y": -18,
      "z": -4,
      "name": "Soil_Grass"
    },
    {
      "x": -34,
      "y": -18,
      "z": -3,
      "name": "Soil_Grass"
    },
    {
      "x": -34,
      "y": -18,
      "z": -2,
      "name": "Soil_Grass"
    },
    {
      "x": -34,
      "y": -18,
      "z": -1,
      "name": "Soil_Grass"
    },
    {
      "x": -34,
      "y": -18,
      "z": 0,
      "name": "Soil_Grass"
    },
    {
      "x": -34,
      "y": -18,
      "z": 1,
      "name": "Soil_Grass"
    },
    {
      "x": -34,
      "y": -18,
      "z": 2,
      "name": "Soil_Grass"
    },
    {
      "x": -34,
      "y": -18,
      "z": 3,
      "name": "Soil_Grass"
    },
    {
      "x": -34,
      "y": -18,
      "z": 4,
      "name": "Soil_Grass"
    },
    {
      "x": -34,
      "y": -18,
      "z": 5,
      "name": "Soil_Grass"
    },
    {
      "x": -34,
      "y": -18,
      "z": 6,
      "name": "Soil_Grass"
    },
    {
      "x": -34,
      "y": -18,
      "z": 7,
      "name": "Soil_Grass"
    },
    {
      "x": -34,
      "y": -18,
      "z": 8,
      "name": "Soil_Grass"
    },
    {
      "x": -34,
      "y": -18,
      "z": 9,
      "name": "Soil_Grass"
    },
    {
      "x": -34,
      "y": -18,
      "z": 10,
      "name": "Soil_Grass"
    },
    {
      "x": -34,
      "y": -18,
      "z": 11,
      "name": "Soil_Grass"
    },
    {
      "x": -34,
      "y": -18,
      "z": 12,
      "name": "Soil_Grass"
    },
    {
      "x": -34,
      "y": -18,
      "z": 13,
      "name": "Soil_Grass"
    },
    {
      "x": -34,
      "y": -18,
      "z": 14,
      "name": "Soil_Grass"
    },
    {
      "x": -34,
      "y": -18,
      "z": 15,
      "name": "Soil_Grass"
    },
    {
      "x": -34,
      "y": -18,
      "z": 16,
      "name": "Soil_Grass"
    },
    {
      "x": -34,
      "y": -18,
      "z": 17,
      "name": "Soil_Grass"
    },
    {
      "x": -34,
      "y": -18,
      "z": 18,
      "name": "Soil_Grass"
    },
    {
      "x": -34,
      "y": -18,
      "z": 19,
      "name": "Soil_Grass"
    },
    {
      "x": -34,
      "y": -18,
      "z": 20,
      "name": "Soil_Grass"
    },
    {
      "x": -34,
      "y": -18,
      "z": 21,
      "name": "Soil_Grass"
    },
    {
      "x": -34,
      "y": -18,
      "z": 22,
      "name": "Soil_Grass"
    },
    {
      "x": -34,
      "y": -18,
      "z": 23,
      "name": "Soil_Grass"
    },
    {
      "x": -34,
      "y": -18,
      "z": 24,
      "name": "Soil_Grass"
    },
    {
      "x": -34,
      "y": -18,
      "z": 25,
      "name": "Soil_Grass"
    },
    {
      "x": -34,
      "y": -18,
      "z": 26,
      "name": "Soil_Grass"
    },
    {
      "x": -34,
      "y": -18,
      "z": 27,
      "name": "Soil_Grass"
    },
    {
      "x": -34,
      "y": -18,
      "z": 28,
      "name": "Soil_Grass"
    },
    {
      "x": -34,
      "y": -18,
      "z": 29,
      "name": "Soil_Grass"
    },
    {
      "x": -34,
      "y": -18,
      "z": 30,
      "name": "Soil_Grass"
    },
    {
      "x": -34,
      "y": -18,
      "z": 31,
      "name": "Soil_Grass"
    },
    {
      "x": -34,
      "y": -18,
      "z": 32,
      "name": "Soil_Grass"
    },
    {
      "x": -34,
      "y": -18,
      "z": 33,
      "name": "Soil_Grass"
    },
    {
      "x": -34,
      "y": -18,
      "z": 34,
      "name": "Soil_Grass"
    },
    {
      "x": -34,
      "y": -18,
      "z": 35,
      "name": "Soil_Grass"
    },
    {
      "x": -34,
      "y": -18,
      "z": 36,
      "name": "Soil_Grass"
    },
    {
      "x": -34,
      "y": -18,
      "z": 37,
      "name": "Soil_Grass"
    },
    {
      "x": -33,
      "y": -18,
      "z": -38,
      "name": "Soil_Grass"
    },
    {
      "x": -33,
      "y": -18,
      "z": -37,
      "name": "Soil_Grass"
    },
    {
      "x": -33,
      "y": -18,
      "z": -36,
      "name": "Soil_Grass"
    },
    {
      "x": -33,
      "y": -18,
      "z": -35,
      "name": "Soil_Grass"
    },
    {
      "x": -33,
      "y": -18,
      "z": -34,
      "name": "Soil_Grass"
    },
    {
      "x": -33,
      "y": -18,
      "z": -33,
      "name": "Soil_Grass"
    },
    {
      "x": -33,
      "y": -18,
      "z": -32,
      "name": "Soil_Grass"
    },
    {
      "x": -33,
      "y": -18,
      "z": -31,
      "name": "Soil_Grass"
    },
    {
      "x": -33,
      "y": -18,
      "z": -30,
      "name": "Soil_Grass"
    },
    {
      "x": -33,
      "y": -18,
      "z": -29,
      "name": "Soil_Grass"
    },
    {
      "x": -33,
      "y": -18,
      "z": -28,
      "name": "Soil_Grass"
    },
    {
      "x": -33,
      "y": -18,
      "z": -27,
      "name": "Soil_Grass"
    },
    {
      "x": -33,
      "y": -18,
      "z": -26,
      "name": "Soil_Grass"
    },
    {
      "x": -33,
      "y": -18,
      "z": -25,
      "name": "Soil_Grass"
    },
    {
      "x": -33,
      "y": -18,
      "z": -24,
      "name": "Soil_Grass"
    },
    {
      "x": -33,
      "y": -18,
      "z": -23,
      "name": "Soil_Grass"
    },
    {
      "x": -33,
      "y": -18,
      "z": -22,
      "name": "Soil_Grass"
    },
    {
      "x": -33,
      "y": -18,
      "z": -21,
      "name": "Soil_Grass"
    },
    {
      "x": -33,
      "y": -18,
      "z": -20,
      "name": "Soil_Grass"
    },
    {
      "x": -33,
      "y": -18,
      "z": -19,
      "name": "Soil_Grass"
    },
    {
      "x": -33,
      "y": -18,
      "z": -18,
      "name": "Soil_Grass"
    },
    {
      "x": -33,
      "y": -18,
      "z": -17,
      "name": "Soil_Grass"
    },
    {
      "x": -33,
      "y": -18,
      "z": -16,
      "name": "Soil_Grass"
    },
    {
      "x": -33,
      "y": -18,
      "z": -15,
      "name": "Soil_Grass"
    },
    {
      "x": -33,
      "y": -18,
      "z": -14,
      "name": "Soil_Grass"
    },
    {
      "x": -33,
      "y": -18,
      "z": -13,
      "name": "Soil_Grass"
    },
    {
      "x": -33,
      "y": -18,
      "z": -12,
      "name": "Soil_Grass"
    },
    {
      "x": -33,
      "y": -18,
      "z": -11,
      "name": "Soil_Grass"
    },
    {
      "x": -33,
      "y": -18,
      "z": -10,
      "name": "Soil_Grass"
    },
    {
      "x": -33,
      "y": -18,
      "z": -9,
      "name": "Soil_Grass"
    },
    {
      "x": -33,
      "y": -18,
      "z": -8,
      "name": "Soil_Grass"
    },
    {
      "x": -33,
      "y": -18,
      "z": -7,
      "name": "Soil_Grass"
    },
    {
      "x": -33,
      "y": -18,
      "z": -6,
      "name": "Soil_Grass"
    },
    {
      "x": -33,
      "y": -18,
      "z": -5,
      "name": "Soil_Grass"
    },
    {
      "x": -33,
      "y": -18,
      "z": -4,
      "name": "Soil_Grass"
    },
    {
      "x": -33,
      "y": -18,
      "z": -3,
      "name": "Soil_Grass"
    },
    {
      "x": -33,
      "y": -18,
      "z": -2,
      "name": "Soil_Grass"
    },
    {
      "x": -33,
      "y": -18,
      "z": -1,
      "name": "Soil_Grass"
    },
    {
      "x": -33,
      "y": -18,
      "z": 0,
      "name": "Soil_Grass"
    },
    {
      "x": -33,
      "y": -18,
      "z": 1,
      "name": "Soil_Grass"
    },
    {
      "x": -33,
      "y": -18,
      "z": 2,
      "name": "Soil_Grass"
    },
    {
      "x": -33,
      "y": -18,
      "z": 3,
      "name": "Soil_Grass"
    },
    {
      "x": -33,
      "y": -18,
      "z": 4,
      "name": "Soil_Grass"
    },
    {
      "x": -33,
      "y": -18,
      "z": 5,
      "name": "Soil_Grass"
    },
    {
      "x": -33,
      "y": -18,
      "z": 6,
      "name": "Soil_Grass"
    },
    {
      "x": -33,
      "y": -18,
      "z": 7,
      "name": "Soil_Grass"
    },
    {
      "x": -33,
      "y": -18,
      "z": 8,
      "name": "Soil_Grass"
    },
    {
      "x": -33,
      "y": -18,
      "z": 9,
      "name": "Soil_Grass"
    },
    {
      "x": -33,
      "y": -18,
      "z": 10,
      "name": "Soil_Grass"
    },
    {
      "x": -33,
      "y": -18,
      "z": 11,
      "name": "Soil_Grass"
    },
    {
      "x": -33,
      "y": -18,
      "z": 12,
      "name": "Soil_Grass"
    },
    {
      "x": -33,
      "y": -18,
      "z": 13,
      "name": "Soil_Grass"
    },
    {
      "x": -33,
      "y": -18,
      "z": 14,
      "name": "Soil_Grass"
    },
    {
      "x": -33,
      "y": -18,
      "z": 15,
      "name": "Soil_Grass"
    },
    {
      "x": -33,
      "y": -18,
      "z": 16,
      "name": "Soil_Grass"
    },
    {
      "x": -33,
      "y": -18,
      "z": 17,
      "name": "Soil_Grass"
    },
    {
      "x": -33,
      "y": -18,
      "z": 18,
      "name": "Soil_Grass"
    },
    {
      "x": -33,
      "y": -18,
      "z": 19,
      "name": "Soil_Grass"
    },
    {
      "x": -33,
      "y": -18,
      "z": 20,
      "name": "Soil_Grass"
    },
    {
      "x": -33,
      "y": -18,
      "z": 21,
      "name": "Soil_Grass"
    },
    {
      "x": -33,
      "y": -18,
      "z": 22,
      "name": "Soil_Grass"
    },
    {
      "x": -33,
      "y": -18,
      "z": 23,
      "name": "Soil_Grass"
    },
    {
      "x": -33,
      "y": -18,
      "z": 24,
      "name": "Soil_Grass"
    },
    {
      "x": -33,
      "y": -18,
      "z": 25,
      "name": "Soil_Grass"
    },
    {
      "x": -33,
      "y": -18,
      "z": 26,
      "name": "Soil_Grass"
    },
    {
      "x": -33,
      "y": -18,
      "z": 27,
      "name": "Soil_Grass"
    },
    {
      "x": -33,
      "y": -18,
      "z": 28,
      "name": "Soil_Grass"
    },
    {
      "x": -33,
      "y": -18,
      "z": 29,
      "name": "Soil_Grass"
    },
    {
      "x": -33,
      "y": -18,
      "z": 30,
      "name": "Soil_Grass"
    },
    {
      "x": -33,
      "y": -18,
      "z": 31,
      "name": "Soil_Grass"
    },
    {
      "x": -33,
      "y": -18,
      "z": 32,
      "name": "Soil_Grass"
    },
    {
      "x": -33,
      "y": -18,
      "z": 33,
      "name": "Soil_Grass"
    },
    {
      "x": -33,
      "y": -18,
      "z": 34,
      "name": "Soil_Grass"
    },
    {
      "x": -33,
      "y": -18,
      "z": 35,
      "name": "Soil_Grass"
    },
    {
      "x": -33,
      "y": -18,
      "z": 36,
      "name": "Soil_Grass"
    },
    {
      "x": -33,
      "y": -18,
      "z": 37,
      "name": "Soil_Grass"
    },
    {
      "x": -32,
      "y": -18,
      "z": -38,
      "name": "Soil_Grass"
    },
    {
      "x": -32,
      "y": -18,
      "z": -37,
      "name": "Soil_Grass"
    },
    {
      "x": -32,
      "y": -18,
      "z": -36,
      "name": "Soil_Grass"
    },
    {
      "x": -32,
      "y": -18,
      "z": -35,
      "name": "Soil_Grass"
    },
    {
      "x": -32,
      "y": -18,
      "z": -34,
      "name": "Soil_Grass"
    },
    {
      "x": -32,
      "y": -18,
      "z": -33,
      "name": "Soil_Grass"
    },
    {
      "x": -32,
      "y": -18,
      "z": -32,
      "name": "Soil_Grass"
    },
    {
      "x": -32,
      "y": -18,
      "z": -31,
      "name": "Soil_Grass"
    },
    {
      "x": -32,
      "y": -18,
      "z": -30,
      "name": "Soil_Grass"
    },
    {
      "x": -32,
      "y": -18,
      "z": -29,
      "name": "Soil_Grass"
    },
    {
      "x": -32,
      "y": -18,
      "z": -28,
      "name": "Soil_Grass"
    },
    {
      "x": -32,
      "y": -18,
      "z": -27,
      "name": "Soil_Grass"
    },
    {
      "x": -32,
      "y": -18,
      "z": -26,
      "name": "Soil_Grass"
    },
    {
      "x": -32,
      "y": -18,
      "z": -25,
      "name": "Soil_Grass"
    },
    {
      "x": -32,
      "y": -18,
      "z": -24,
      "name": "Soil_Grass"
    },
    {
      "x": -32,
      "y": -18,
      "z": -23,
      "name": "Soil_Grass"
    },
    {
      "x": -32,
      "y": -18,
      "z": -22,
      "name": "Soil_Grass"
    },
    {
      "x": -32,
      "y": -18,
      "z": -21,
      "name": "Soil_Grass"
    },
    {
      "x": -32,
      "y": -18,
      "z": -20,
      "name": "Soil_Grass"
    },
    {
      "x": -32,
      "y": -18,
      "z": -19,
      "name": "Soil_Grass"
    },
    {
      "x": -32,
      "y": -18,
      "z": -18,
      "name": "Soil_Grass"
    },
    {
      "x": -32,
      "y": -18,
      "z": -17,
      "name": "Soil_Grass"
    },
    {
      "x": -32,
      "y": -18,
      "z": -16,
      "name": "Soil_Grass"
    },
    {
      "x": -32,
      "y": -18,
      "z": -15,
      "name": "Soil_Grass"
    },
    {
      "x": -32,
      "y": -18,
      "z": -14,
      "name": "Soil_Grass"
    },
    {
      "x": -32,
      "y": -18,
      "z": -13,
      "name": "Soil_Grass"
    },
    {
      "x": -32,
      "y": -18,
      "z": -12,
      "name": "Soil_Grass"
    },
    {
      "x": -32,
      "y": -18,
      "z": -11,
      "name": "Soil_Grass"
    },
    {
      "x": -32,
      "y": -18,
      "z": -10,
      "name": "Soil_Grass"
    },
    {
      "x": -32,
      "y": -18,
      "z": -9,
      "name": "Soil_Grass"
    },
    {
      "x": -32,
      "y": -18,
      "z": -8,
      "name": "Soil_Grass"
    },
    {
      "x": -32,
      "y": -18,
      "z": -7,
      "name": "Soil_Grass"
    },
    {
      "x": -32,
      "y": -18,
      "z": -6,
      "name": "Soil_Grass"
    },
    {
      "x": -32,
      "y": -18,
      "z": -5,
      "name": "Soil_Grass"
    },
    {
      "x": -32,
      "y": -18,
      "z": -4,
      "name": "Soil_Grass"
    },
    {
      "x": -32,
      "y": -18,
      "z": -3,
      "name": "Soil_Grass"
    },
    {
      "x": -32,
      "y": -18,
      "z": -2,
      "name": "Soil_Grass"
    },
    {
      "x": -32,
      "y": -18,
      "z": -1,
      "name": "Soil_Grass"
    },
    {
      "x": -32,
      "y": -18,
      "z": 0,
      "name": "Soil_Grass"
    },
    {
      "x": -32,
      "y": -18,
      "z": 1,
      "name": "Soil_Grass"
    },
    {
      "x": -32,
      "y": -18,
      "z": 2,
      "name": "Soil_Grass"
    },
    {
      "x": -32,
      "y": -18,
      "z": 3,
      "name": "Soil_Grass"
    },
    {
      "x": -32,
      "y": -18,
      "z": 4,
      "name": "Soil_Grass"
    },
    {
      "x": -32,
      "y": -18,
      "z": 5,
      "name": "Soil_Grass"
    },
    {
      "x": -32,
      "y": -18,
      "z": 6,
      "name": "Soil_Grass"
    },
    {
      "x": -32,
      "y": -18,
      "z": 7,
      "name": "Soil_Grass"
    },
    {
      "x": -32,
      "y": -18,
      "z": 8,
      "name": "Soil_Grass"
    },
    {
      "x": -32,
      "y": -18,
      "z": 9,
      "name": "Soil_Grass"
    },
    {
      "x": -32,
      "y": -18,
      "z": 10,
      "name": "Soil_Grass"
    },
    {
      "x": -32,
      "y": -18,
      "z": 11,
      "name": "Soil_Grass"
    },
    {
      "x": -32,
      "y": -18,
      "z": 12,
      "name": "Soil_Grass"
    },
    {
      "x": -32,
      "y": -18,
      "z": 13,
      "name": "Soil_Grass"
    },
    {
      "x": -32,
      "y": -18,
      "z": 14,
      "name": "Soil_Grass"
    },
    {
      "x": -32,
      "y": -18,
      "z": 15,
      "name": "Soil_Grass"
    },
    {
      "x": -32,
      "y": -18,
      "z": 16,
      "name": "Soil_Grass"
    },
    {
      "x": -32,
      "y": -18,
      "z": 17,
      "name": "Soil_Grass"
    },
    {
      "x": -32,
      "y": -18,
      "z": 18,
      "name": "Soil_Grass"
    },
    {
      "x": -32,
      "y": -18,
      "z": 19,
      "name": "Soil_Grass"
    },
    {
      "x": -32,
      "y": -18,
      "z": 20,
      "name": "Soil_Grass"
    },
    {
      "x": -32,
      "y": -18,
      "z": 21,
      "name": "Soil_Grass"
    },
    {
      "x": -32,
      "y": -18,
      "z": 22,
      "name": "Soil_Grass"
    },
    {
      "x": -32,
      "y": -18,
      "z": 23,
      "name": "Soil_Grass"
    },
    {
      "x": -32,
      "y": -18,
      "z": 24,
      "name": "Soil_Grass"
    },
    {
      "x": -32,
      "y": -18,
      "z": 25,
      "name": "Soil_Grass"
    },
    {
      "x": -32,
      "y": -18,
      "z": 26,
      "name": "Soil_Grass"
    },
    {
      "x": -32,
      "y": -18,
      "z": 27,
      "name": "Soil_Grass"
    },
    {
      "x": -32,
      "y": -18,
      "z": 28,
      "name": "Soil_Grass"
    },
    {
      "x": -32,
      "y": -18,
      "z": 29,
      "name": "Soil_Grass"
    },
    {
      "x": -32,
      "y": -18,
      "z": 30,
      "name": "Soil_Grass"
    },
    {
      "x": -32,
      "y": -18,
      "z": 31,
      "name": "Soil_Grass"
    },
    {
      "x": -32,
      "y": -18,
      "z": 32,
      "name": "Soil_Grass"
    },
    {
      "x": -32,
      "y": -18,
      "z": 33,
      "name": "Soil_Grass"
    },
    {
      "x": -32,
      "y": -18,
      "z": 34,
      "name": "Soil_Grass"
    },
    {
      "x": -32,
      "y": -18,
      "z": 35,
      "name": "Soil_Grass"
    },
    {
      "x": -32,
      "y": -18,
      "z": 36,
      "name": "Soil_Grass"
    },
    {
      "x": -32,
      "y": -18,
      "z": 37,
      "name": "Soil_Grass"
    },
    {
      "x": -31,
      "y": -18,
      "z": -38,
      "name": "Soil_Grass"
    },
    {
      "x": -31,
      "y": -18,
      "z": -37,
      "name": "Soil_Grass"
    },
    {
      "x": -31,
      "y": -18,
      "z": -36,
      "name": "Soil_Grass"
    },
    {
      "x": -31,
      "y": -18,
      "z": -35,
      "name": "Soil_Grass"
    },
    {
      "x": -31,
      "y": -18,
      "z": -34,
      "name": "Soil_Grass"
    },
    {
      "x": -31,
      "y": -18,
      "z": -33,
      "name": "Soil_Grass"
    },
    {
      "x": -31,
      "y": -18,
      "z": -32,
      "name": "Soil_Grass"
    },
    {
      "x": -31,
      "y": -18,
      "z": -31,
      "name": "Soil_Grass"
    },
    {
      "x": -31,
      "y": -18,
      "z": -30,
      "name": "Soil_Grass"
    },
    {
      "x": -31,
      "y": -18,
      "z": -29,
      "name": "Soil_Grass"
    },
    {
      "x": -31,
      "y": -18,
      "z": -28,
      "name": "Soil_Grass"
    },
    {
      "x": -31,
      "y": -18,
      "z": -27,
      "name": "Soil_Grass"
    },
    {
      "x": -31,
      "y": -18,
      "z": -26,
      "name": "Soil_Grass"
    },
    {
      "x": -31,
      "y": -18,
      "z": -25,
      "name": "Soil_Grass"
    },
    {
      "x": -31,
      "y": -18,
      "z": -24,
      "name": "Soil_Grass"
    },
    {
      "x": -31,
      "y": -18,
      "z": -23,
      "name": "Soil_Grass"
    },
    {
      "x": -31,
      "y": -18,
      "z": -22,
      "name": "Soil_Grass"
    },
    {
      "x": -31,
      "y": -18,
      "z": -21,
      "name": "Soil_Grass"
    },
    {
      "x": -31,
      "y": -18,
      "z": -20,
      "name": "Soil_Grass"
    },
    {
      "x": -31,
      "y": -18,
      "z": -19,
      "name": "Soil_Grass"
    },
    {
      "x": -31,
      "y": -18,
      "z": -18,
      "name": "Soil_Grass"
    },
    {
      "x": -31,
      "y": -18,
      "z": -17,
      "name": "Soil_Grass"
    },
    {
      "x": -31,
      "y": -18,
      "z": -16,
      "name": "Soil_Grass"
    },
    {
      "x": -31,
      "y": -18,
      "z": -15,
      "name": "Soil_Grass"
    },
    {
      "x": -31,
      "y": -18,
      "z": -14,
      "name": "Soil_Grass"
    },
    {
      "x": -31,
      "y": -18,
      "z": -13,
      "name": "Soil_Grass"
    },
    {
      "x": -31,
      "y": -18,
      "z": -12,
      "name": "Soil_Grass"
    },
    {
      "x": -31,
      "y": -18,
      "z": -11,
      "name": "Soil_Grass"
    },
    {
      "x": -31,
      "y": -18,
      "z": -10,
      "name": "Soil_Grass"
    },
    {
      "x": -31,
      "y": -18,
      "z": -9,
      "name": "Soil_Grass"
    },
    {
      "x": -31,
      "y": -18,
      "z": -8,
      "name": "Soil_Grass"
    },
    {
      "x": -31,
      "y": -18,
      "z": -7,
      "name": "Soil_Grass"
    },
    {
      "x": -31,
      "y": -18,
      "z": -6,
      "name": "Soil_Grass"
    },
    {
      "x": -31,
      "y": -18,
      "z": -5,
      "name": "Soil_Grass"
    },
    {
      "x": -31,
      "y": -18,
      "z": -4,
      "name": "Soil_Grass"
    },
    {
      "x": -31,
      "y": -18,
      "z": -3,
      "name": "Soil_Grass"
    },
    {
      "x": -31,
      "y": -18,
      "z": -2,
      "name": "Soil_Grass"
    },
    {
      "x": -31,
      "y": -18,
      "z": -1,
      "name": "Soil_Grass"
    },
    {
      "x": -31,
      "y": -18,
      "z": 0,
      "name": "Soil_Grass"
    },
    {
      "x": -31,
      "y": -18,
      "z": 1,
      "name": "Soil_Grass"
    },
    {
      "x": -31,
      "y": -18,
      "z": 2,
      "name": "Soil_Grass"
    },
    {
      "x": -31,
      "y": -18,
      "z": 3,
      "name": "Soil_Grass"
    },
    {
      "x": -31,
      "y": -18,
      "z": 4,
      "name": "Soil_Grass"
    },
    {
      "x": -31,
      "y": -18,
      "z": 5,
      "name": "Soil_Grass"
    },
    {
      "x": -31,
      "y": -18,
      "z": 6,
      "name": "Soil_Grass"
    },
    {
      "x": -31,
      "y": -18,
      "z": 7,
      "name": "Soil_Grass"
    },
    {
      "x": -31,
      "y": -18,
      "z": 8,
      "name": "Soil_Grass"
    },
    {
      "x": -31,
      "y": -18,
      "z": 9,
      "name": "Soil_Grass"
    },
    {
      "x": -31,
      "y": -18,
      "z": 10,
      "name": "Soil_Grass"
    },
    {
      "x": -31,
      "y": -18,
      "z": 11,
      "name": "Soil_Grass"
    },
    {
      "x": -31,
      "y": -18,
      "z": 12,
      "name": "Soil_Grass"
    },
    {
      "x": -31,
      "y": -18,
      "z": 13,
      "name": "Soil_Grass"
    },
    {
      "x": -31,
      "y": -18,
      "z": 14,
      "name": "Soil_Grass"
    },
    {
      "x": -31,
      "y": -18,
      "z": 15,
      "name": "Soil_Grass"
    },
    {
      "x": -31,
      "y": -18,
      "z": 16,
      "name": "Soil_Grass"
    },
    {
      "x": -31,
      "y": -18,
      "z": 17,
      "name": "Soil_Grass"
    },
    {
      "x": -31,
      "y": -18,
      "z": 18,
      "name": "Soil_Grass"
    },
    {
      "x": -31,
      "y": -18,
      "z": 19,
      "name": "Soil_Grass"
    },
    {
      "x": -31,
      "y": -18,
      "z": 20,
      "name": "Soil_Grass"
    },
    {
      "x": -31,
      "y": -18,
      "z": 21,
      "name": "Soil_Grass"
    },
    {
      "x": -31,
      "y": -18,
      "z": 22,
      "name": "Soil_Grass"
    },
    {
      "x": -31,
      "y": -18,
      "z": 23,
      "name": "Soil_Grass"
    },
    {
      "x": -31,
      "y": -18,
      "z": 24,
      "name": "Soil_Grass"
    },
    {
      "x": -31,
      "y": -18,
      "z": 25,
      "name": "Soil_Grass"
    },
    {
      "x": -31,
      "y": -18,
      "z": 26,
      "name": "Soil_Grass"
    },
    {
      "x": -31,
      "y": -18,
      "z": 27,
      "name": "Soil_Grass"
    },
    {
      "x": -31,
      "y": -18,
      "z": 28,
      "name": "Soil_Grass"
    },
    {
      "x": -31,
      "y": -18,
      "z": 29,
      "name": "Soil_Grass"
    },
    {
      "x": -31,
      "y": -18,
      "z": 30,
      "name": "Soil_Grass"
    },
    {
      "x": -31,
      "y": -18,
      "z": 31,
      "name": "Soil_Grass"
    },
    {
      "x": -31,
      "y": -18,
      "z": 32,
      "name": "Soil_Grass"
    },
    {
      "x": -31,
      "y": -18,
      "z": 33,
      "name": "Soil_Grass"
    },
    {
      "x": -31,
      "y": -18,
      "z": 34,
      "name": "Soil_Grass"
    },
    {
      "x": -31,
      "y": -18,
      "z": 35,
      "name": "Soil_Grass"
    },
    {
      "x": -31,
      "y": -18,
      "z": 36,
      "name": "Soil_Grass"
    },
    {
      "x": -31,
      "y": -18,
      "z": 37,
      "name": "Soil_Grass"
    },
    {
      "x": -30,
      "y": -18,
      "z": -38,
      "name": "Soil_Grass"
    },
    {
      "x": -30,
      "y": -18,
      "z": -37,
      "name": "Soil_Grass"
    },
    {
      "x": -30,
      "y": -18,
      "z": -36,
      "name": "Soil_Grass"
    },
    {
      "x": -30,
      "y": -18,
      "z": -35,
      "name": "Soil_Grass"
    },
    {
      "x": -30,
      "y": -18,
      "z": -34,
      "name": "Soil_Grass"
    },
    {
      "x": -30,
      "y": -18,
      "z": -33,
      "name": "Soil_Grass"
    },
    {
      "x": -30,
      "y": -18,
      "z": -32,
      "name": "Soil_Grass"
    },
    {
      "x": -30,
      "y": -18,
      "z": -31,
      "name": "Soil_Grass"
    },
    {
      "x": -30,
      "y": -18,
      "z": -30,
      "name": "Soil_Grass"
    },
    {
      "x": -30,
      "y": -18,
      "z": -29,
      "name": "Soil_Grass"
    },
    {
      "x": -30,
      "y": -18,
      "z": -28,
      "name": "Soil_Grass"
    },
    {
      "x": -30,
      "y": -18,
      "z": -27,
      "name": "Soil_Grass"
    },
    {
      "x": -30,
      "y": -18,
      "z": -26,
      "name": "Soil_Grass"
    },
    {
      "x": -30,
      "y": -18,
      "z": -25,
      "name": "Soil_Grass"
    },
    {
      "x": -30,
      "y": -18,
      "z": -24,
      "name": "Soil_Grass"
    },
    {
      "x": -30,
      "y": -18,
      "z": -23,
      "name": "Soil_Grass"
    },
    {
      "x": -30,
      "y": -18,
      "z": -22,
      "name": "Soil_Grass"
    },
    {
      "x": -30,
      "y": -18,
      "z": -21,
      "name": "Soil_Grass"
    },
    {
      "x": -30,
      "y": -18,
      "z": -20,
      "name": "Soil_Grass"
    },
    {
      "x": -30,
      "y": -18,
      "z": -19,
      "name": "Soil_Grass"
    },
    {
      "x": -30,
      "y": -18,
      "z": -18,
      "name": "Soil_Grass"
    },
    {
      "x": -30,
      "y": -18,
      "z": -17,
      "name": "Soil_Grass"
    },
    {
      "x": -30,
      "y": -18,
      "z": -16,
      "name": "Soil_Grass"
    },
    {
      "x": -30,
      "y": -18,
      "z": -15,
      "name": "Soil_Grass"
    },
    {
      "x": -30,
      "y": -18,
      "z": -14,
      "name": "Soil_Grass"
    },
    {
      "x": -30,
      "y": -18,
      "z": -13,
      "name": "Soil_Grass"
    },
    {
      "x": -30,
      "y": -18,
      "z": -12,
      "name": "Soil_Grass"
    },
    {
      "x": -30,
      "y": -18,
      "z": -11,
      "name": "Soil_Grass"
    },
    {
      "x": -30,
      "y": -18,
      "z": -10,
      "name": "Soil_Grass"
    },
    {
      "x": -30,
      "y": -18,
      "z": -9,
      "name": "Soil_Grass"
    },
    {
      "x": -30,
      "y": -18,
      "z": -8,
      "name": "Soil_Grass"
    },
    {
      "x": -30,
      "y": -18,
      "z": -7,
      "name": "Soil_Grass"
    },
    {
      "x": -30,
      "y": -18,
      "z": -6,
      "name": "Soil_Grass"
    },
    {
      "x": -30,
      "y": -18,
      "z": -5,
      "name": "Soil_Grass"
    },
    {
      "x": -30,
      "y": -18,
      "z": -4,
      "name": "Soil_Grass"
    },
    {
      "x": -30,
      "y": -18,
      "z": -3,
      "name": "Soil_Grass"
    },
    {
      "x": -30,
      "y": -18,
      "z": -2,
      "name": "Soil_Grass"
    },
    {
      "x": -30,
      "y": -18,
      "z": -1,
      "name": "Soil_Grass"
    },
    {
      "x": -30,
      "y": -18,
      "z": 0,
      "name": "Soil_Grass"
    },
    {
      "x": -30,
      "y": -18,
      "z": 1,
      "name": "Soil_Grass"
    },
    {
      "x": -30,
      "y": -18,
      "z": 2,
      "name": "Soil_Grass"
    },
    {
      "x": -30,
      "y": -18,
      "z": 3,
      "name": "Soil_Grass"
    },
    {
      "x": -30,
      "y": -18,
      "z": 4,
      "name": "Soil_Grass"
    },
    {
      "x": -30,
      "y": -18,
      "z": 5,
      "name": "Soil_Grass"
    },
    {
      "x": -30,
      "y": -18,
      "z": 6,
      "name": "Soil_Grass"
    },
    {
      "x": -30,
      "y": -18,
      "z": 7,
      "name": "Soil_Grass"
    },
    {
      "x": -30,
      "y": -18,
      "z": 8,
      "name": "Soil_Grass"
    },
    {
      "x": -30,
      "y": -18,
      "z": 9,
      "name": "Soil_Grass"
    },
    {
      "x": -30,
      "y": -18,
      "z": 10,
      "name": "Soil_Grass"
    },
    {
      "x": -30,
      "y": -18,
      "z": 11,
      "name": "Soil_Grass"
    },
    {
      "x": -30,
      "y": -18,
      "z": 12,
      "name": "Soil_Grass"
    },
    {
      "x": -30,
      "y": -18,
      "z": 13,
      "name": "Soil_Grass"
    },
    {
      "x": -30,
      "y": -18,
      "z": 14,
      "name": "Soil_Grass"
    },
    {
      "x": -30,
      "y": -18,
      "z": 15,
      "name": "Soil_Grass"
    },
    {
      "x": -30,
      "y": -18,
      "z": 16,
      "name": "Soil_Grass"
    },
    {
      "x": -30,
      "y": -18,
      "z": 17,
      "name": "Soil_Grass"
    },
    {
      "x": -30,
      "y": -18,
      "z": 18,
      "name": "Soil_Grass"
    },
    {
      "x": -30,
      "y": -18,
      "z": 19,
      "name": "Soil_Grass"
    },
    {
      "x": -30,
      "y": -18,
      "z": 20,
      "name": "Soil_Grass"
    },
    {
      "x": -30,
      "y": -18,
      "z": 21,
      "name": "Soil_Grass"
    },
    {
      "x": -30,
      "y": -18,
      "z": 22,
      "name": "Soil_Grass"
    },
    {
      "x": -30,
      "y": -18,
      "z": 23,
      "name": "Soil_Grass"
    },
    {
      "x": -30,
      "y": -18,
      "z": 24,
      "name": "Soil_Grass"
    },
    {
      "x": -30,
      "y": -18,
      "z": 25,
      "name": "Soil_Grass"
    },
    {
      "x": -30,
      "y": -18,
      "z": 26,
      "name": "Soil_Grass"
    },
    {
      "x": -30,
      "y": -18,
      "z": 27,
      "name": "Soil_Grass"
    },
    {
      "x": -30,
      "y": -18,
      "z": 28,
      "name": "Soil_Grass"
    },
    {
      "x": -30,
      "y": -18,
      "z": 29,
      "name": "Soil_Grass"
    },
    {
      "x": -30,
      "y": -18,
      "z": 30,
      "name": "Soil_Grass"
    },
    {
      "x": -30,
      "y": -18,
      "z": 31,
      "name": "Soil_Grass"
    },
    {
      "x": -30,
      "y": -18,
      "z": 32,
      "name": "Soil_Grass"
    },
    {
      "x": -30,
      "y": -18,
      "z": 33,
      "name": "Soil_Grass"
    },
    {
      "x": -30,
      "y": -18,
      "z": 34,
      "name": "Soil_Grass"
    },
    {
      "x": -30,
      "y": -18,
      "z": 35,
      "name": "Soil_Grass"
    },
    {
      "x": -30,
      "y": -18,
      "z": 36,
      "name": "Soil_Grass"
    },
    {
      "x": -30,
      "y": -18,
      "z": 37,
      "name": "Soil_Grass"
    },
    {
      "x": -29,
      "y": -18,
      "z": -38,
      "name": "Soil_Grass"
    },
    {
      "x": -29,
      "y": -18,
      "z": -37,
      "name": "Soil_Grass"
    },
    {
      "x": -29,
      "y": -18,
      "z": -36,
      "name": "Soil_Grass"
    },
    {
      "x": -29,
      "y": -18,
      "z": -35,
      "name": "Soil_Grass"
    },
    {
      "x": -29,
      "y": -18,
      "z": -34,
      "name": "Soil_Grass"
    },
    {
      "x": -29,
      "y": -18,
      "z": -33,
      "name": "Soil_Grass"
    },
    {
      "x": -29,
      "y": -18,
      "z": -32,
      "name": "Soil_Grass"
    },
    {
      "x": -29,
      "y": -18,
      "z": -31,
      "name": "Soil_Grass"
    },
    {
      "x": -29,
      "y": -18,
      "z": -30,
      "name": "Soil_Grass"
    },
    {
      "x": -29,
      "y": -18,
      "z": -29,
      "name": "Soil_Grass"
    },
    {
      "x": -29,
      "y": -18,
      "z": -28,
      "name": "Soil_Grass"
    },
    {
      "x": -29,
      "y": -18,
      "z": -27,
      "name": "Soil_Grass"
    },
    {
      "x": -29,
      "y": -18,
      "z": -26,
      "name": "Soil_Grass"
    },
    {
      "x": -29,
      "y": -18,
      "z": -25,
      "name": "Soil_Grass"
    },
    {
      "x": -29,
      "y": -18,
      "z": -24,
      "name": "Soil_Grass"
    },
    {
      "x": -29,
      "y": -18,
      "z": -23,
      "name": "Soil_Grass"
    },
    {
      "x": -29,
      "y": -18,
      "z": -22,
      "name": "Soil_Grass"
    },
    {
      "x": -29,
      "y": -18,
      "z": -21,
      "name": "Soil_Grass"
    },
    {
      "x": -29,
      "y": -18,
      "z": -20,
      "name": "Soil_Grass"
    },
    {
      "x": -29,
      "y": -18,
      "z": -19,
      "name": "Soil_Grass"
    },
    {
      "x": -29,
      "y": -18,
      "z": -18,
      "name": "Soil_Grass"
    },
    {
      "x": -29,
      "y": -18,
      "z": -17,
      "name": "Soil_Grass"
    },
    {
      "x": -29,
      "y": -18,
      "z": -16,
      "name": "Soil_Grass"
    },
    {
      "x": -29,
      "y": -18,
      "z": -15,
      "name": "Soil_Grass"
    },
    {
      "x": -29,
      "y": -18,
      "z": -14,
      "name": "Soil_Grass"
    },
    {
      "x": -29,
      "y": -18,
      "z": -13,
      "name": "Soil_Grass"
    },
    {
      "x": -29,
      "y": -18,
      "z": -12,
      "name": "Soil_Grass"
    },
    {
      "x": -29,
      "y": -18,
      "z": -11,
      "name": "Soil_Grass"
    },
    {
      "x": -29,
      "y": -18,
      "z": -10,
      "name": "Soil_Grass"
    },
    {
      "x": -29,
      "y": -18,
      "z": -9,
      "name": "Soil_Grass"
    },
    {
      "x": -29,
      "y": -18,
      "z": -8,
      "name": "Soil_Grass"
    },
    {
      "x": -29,
      "y": -18,
      "z": -7,
      "name": "Soil_Grass"
    },
    {
      "x": -29,
      "y": -18,
      "z": -6,
      "name": "Soil_Grass"
    },
    {
      "x": -29,
      "y": -18,
      "z": -5,
      "name": "Soil_Grass"
    },
    {
      "x": -29,
      "y": -18,
      "z": -4,
      "name": "Soil_Grass"
    },
    {
      "x": -29,
      "y": -18,
      "z": -3,
      "name": "Soil_Grass"
    },
    {
      "x": -29,
      "y": -18,
      "z": -2,
      "name": "Soil_Grass"
    },
    {
      "x": -29,
      "y": -18,
      "z": -1,
      "name": "Soil_Grass"
    },
    {
      "x": -29,
      "y": -18,
      "z": 0,
      "name": "Soil_Grass"
    },
    {
      "x": -29,
      "y": -18,
      "z": 1,
      "name": "Soil_Grass"
    },
    {
      "x": -29,
      "y": -18,
      "z": 2,
      "name": "Soil_Grass"
    },
    {
      "x": -29,
      "y": -18,
      "z": 3,
      "name": "Soil_Grass"
    },
    {
      "x": -29,
      "y": -18,
      "z": 4,
      "name": "Soil_Grass"
    },
    {
      "x": -29,
      "y": -18,
      "z": 5,
      "name": "Soil_Grass"
    },
    {
      "x": -29,
      "y": -18,
      "z": 6,
      "name": "Soil_Grass"
    },
    {
      "x": -29,
      "y": -18,
      "z": 7,
      "name": "Soil_Grass"
    },
    {
      "x": -29,
      "y": -18,
      "z": 8,
      "name": "Soil_Grass"
    },
    {
      "x": -29,
      "y": -18,
      "z": 9,
      "name": "Soil_Grass"
    },
    {
      "x": -29,
      "y": -18,
      "z": 10,
      "name": "Soil_Grass"
    },
    {
      "x": -29,
      "y": -18,
      "z": 11,
      "name": "Soil_Grass"
    },
    {
      "x": -29,
      "y": -18,
      "z": 12,
      "name": "Soil_Grass"
    },
    {
      "x": -29,
      "y": -18,
      "z": 13,
      "name": "Soil_Grass"
    },
    {
      "x": -29,
      "y": -18,
      "z": 14,
      "name": "Soil_Grass"
    },
    {
      "x": -29,
      "y": -18,
      "z": 15,
      "name": "Soil_Grass"
    },
    {
      "x": -29,
      "y": -18,
      "z": 16,
      "name": "Soil_Grass"
    },
    {
      "x": -29,
      "y": -18,
      "z": 17,
      "name": "Soil_Grass"
    },
    {
      "x": -29,
      "y": -18,
      "z": 18,
      "name": "Soil_Grass"
    },
    {
      "x": -29,
      "y": -18,
      "z": 19,
      "name": "Soil_Grass"
    },
    {
      "x": -29,
      "y": -18,
      "z": 20,
      "name": "Soil_Grass"
    },
    {
      "x": -29,
      "y": -18,
      "z": 21,
      "name": "Soil_Grass"
    },
    {
      "x": -29,
      "y": -18,
      "z": 22,
      "name": "Soil_Grass"
    },
    {
      "x": -29,
      "y": -18,
      "z": 23,
      "name": "Soil_Grass"
    },
    {
      "x": -29,
      "y": -18,
      "z": 24,
      "name": "Soil_Grass"
    },
    {
      "x": -29,
      "y": -18,
      "z": 25,
      "name": "Soil_Grass"
    },
    {
      "x": -29,
      "y": -18,
      "z": 26,
      "name": "Soil_Grass"
    },
    {
      "x": -29,
      "y": -18,
      "z": 27,
      "name": "Soil_Grass"
    },
    {
      "x": -29,
      "y": -18,
      "z": 28,
      "name": "Soil_Grass"
    },
    {
      "x": -29,
      "y": -18,
      "z": 29,
      "name": "Soil_Grass"
    },
    {
      "x": -29,
      "y": -18,
      "z": 30,
      "name": "Soil_Grass"
    },
    {
      "x": -29,
      "y": -18,
      "z": 31,
      "name": "Soil_Grass"
    },
    {
      "x": -29,
      "y": -18,
      "z": 32,
      "name": "Soil_Grass"
    },
    {
      "x": -29,
      "y": -18,
      "z": 33,
      "name": "Soil_Grass"
    },
    {
      "x": -29,
      "y": -18,
      "z": 34,
      "name": "Soil_Grass"
    },
    {
      "x": -29,
      "y": -18,
      "z": 35,
      "name": "Soil_Grass"
    },
    {
      "x": -29,
      "y": -18,
      "z": 36,
      "name": "Soil_Grass"
    },
    {
      "x": -29,
      "y": -18,
      "z": 37,
      "name": "Soil_Grass"
    },
    {
      "x": -28,
      "y": -18,
      "z": -38,
      "name": "Soil_Grass"
    },
    {
      "x": -28,
      "y": -18,
      "z": -37,
      "name": "Soil_Grass"
    },
    {
      "x": -28,
      "y": -18,
      "z": -36,
      "name": "Soil_Grass"
    },
    {
      "x": -28,
      "y": -18,
      "z": -35,
      "name": "Soil_Grass"
    },
    {
      "x": -28,
      "y": -18,
      "z": -34,
      "name": "Soil_Grass"
    },
    {
      "x": -28,
      "y": -18,
      "z": -33,
      "name": "Soil_Grass"
    },
    {
      "x": -28,
      "y": -18,
      "z": -32,
      "name": "Soil_Grass"
    },
    {
      "x": -28,
      "y": -18,
      "z": -31,
      "name": "Soil_Grass"
    },
    {
      "x": -28,
      "y": -18,
      "z": -30,
      "name": "Soil_Grass"
    },
    {
      "x": -28,
      "y": -18,
      "z": -29,
      "name": "Soil_Grass"
    },
    {
      "x": -28,
      "y": -18,
      "z": -28,
      "name": "Soil_Grass"
    },
    {
      "x": -28,
      "y": -18,
      "z": -27,
      "name": "Soil_Grass"
    },
    {
      "x": -28,
      "y": -18,
      "z": -26,
      "name": "Soil_Grass"
    },
    {
      "x": -28,
      "y": -18,
      "z": -25,
      "name": "Soil_Grass"
    },
    {
      "x": -28,
      "y": -18,
      "z": -24,
      "name": "Soil_Grass"
    },
    {
      "x": -28,
      "y": -18,
      "z": -23,
      "name": "Soil_Grass"
    },
    {
      "x": -28,
      "y": -18,
      "z": -22,
      "name": "Soil_Grass"
    },
    {
      "x": -28,
      "y": -18,
      "z": -21,
      "name": "Soil_Grass"
    },
    {
      "x": -28,
      "y": -18,
      "z": -20,
      "name": "Soil_Grass"
    },
    {
      "x": -28,
      "y": -18,
      "z": -19,
      "name": "Soil_Grass"
    },
    {
      "x": -28,
      "y": -18,
      "z": -18,
      "name": "Soil_Grass"
    },
    {
      "x": -28,
      "y": -18,
      "z": -17,
      "name": "Soil_Grass"
    },
    {
      "x": -28,
      "y": -18,
      "z": -16,
      "name": "Soil_Grass"
    },
    {
      "x": -28,
      "y": -18,
      "z": -15,
      "name": "Soil_Grass"
    },
    {
      "x": -28,
      "y": -18,
      "z": -14,
      "name": "Soil_Grass"
    },
    {
      "x": -28,
      "y": -18,
      "z": -13,
      "name": "Soil_Grass"
    },
    {
      "x": -28,
      "y": -18,
      "z": -12,
      "name": "Soil_Grass"
    },
    {
      "x": -28,
      "y": -18,
      "z": -11,
      "name": "Soil_Grass"
    },
    {
      "x": -28,
      "y": -18,
      "z": -10,
      "name": "Soil_Grass"
    },
    {
      "x": -28,
      "y": -18,
      "z": -9,
      "name": "Soil_Grass"
    },
    {
      "x": -28,
      "y": -18,
      "z": -8,
      "name": "Soil_Grass"
    },
    {
      "x": -28,
      "y": -18,
      "z": -7,
      "name": "Soil_Grass"
    },
    {
      "x": -28,
      "y": -18,
      "z": -6,
      "name": "Soil_Grass"
    },
    {
      "x": -28,
      "y": -18,
      "z": -5,
      "name": "Soil_Grass"
    },
    {
      "x": -28,
      "y": -18,
      "z": -4,
      "name": "Soil_Grass"
    },
    {
      "x": -28,
      "y": -18,
      "z": -3,
      "name": "Soil_Grass"
    },
    {
      "x": -28,
      "y": -18,
      "z": -2,
      "name": "Soil_Grass"
    },
    {
      "x": -28,
      "y": -18,
      "z": -1,
      "name": "Soil_Grass"
    },
    {
      "x": -28,
      "y": -18,
      "z": 0,
      "name": "Soil_Grass"
    },
    {
      "x": -28,
      "y": -18,
      "z": 1,
      "name": "Soil_Grass"
    },
    {
      "x": -28,
      "y": -18,
      "z": 2,
      "name": "Soil_Grass"
    },
    {
      "x": -28,
      "y": -18,
      "z": 3,
      "name": "Soil_Grass"
    },
    {
      "x": -28,
      "y": -18,
      "z": 4,
      "name": "Soil_Grass"
    },
    {
      "x": -28,
      "y": -18,
      "z": 5,
      "name": "Soil_Grass"
    },
    {
      "x": -28,
      "y": -18,
      "z": 6,
      "name": "Soil_Grass"
    },
    {
      "x": -28,
      "y": -18,
      "z": 7,
      "name": "Soil_Grass"
    },
    {
      "x": -28,
      "y": -18,
      "z": 8,
      "name": "Soil_Grass"
    },
    {
      "x": -28,
      "y": -18,
      "z": 9,
      "name": "Soil_Grass"
    },
    {
      "x": -28,
      "y": -18,
      "z": 10,
      "name": "Soil_Grass"
    },
    {
      "x": -28,
      "y": -18,
      "z": 11,
      "name": "Soil_Grass"
    },
    {
      "x": -28,
      "y": -18,
      "z": 12,
      "name": "Soil_Grass"
    },
    {
      "x": -28,
      "y": -18,
      "z": 13,
      "name": "Soil_Grass"
    },
    {
      "x": -28,
      "y": -18,
      "z": 14,
      "name": "Soil_Grass"
    },
    {
      "x": -28,
      "y": -18,
      "z": 15,
      "name": "Soil_Grass"
    },
    {
      "x": -28,
      "y": -18,
      "z": 16,
      "name": "Soil_Grass"
    },
    {
      "x": -28,
      "y": -18,
      "z": 17,
      "name": "Soil_Grass"
    },
    {
      "x": -28,
      "y": -18,
      "z": 18,
      "name": "Soil_Grass"
    },
    {
      "x": -28,
      "y": -18,
      "z": 19,
      "name": "Soil_Grass"
    },
    {
      "x": -28,
      "y": -18,
      "z": 20,
      "name": "Soil_Grass"
    },
    {
      "x": -28,
      "y": -18,
      "z": 21,
      "name": "Soil_Grass"
    },
    {
      "x": -28,
      "y": -18,
      "z": 22,
      "name": "Soil_Grass"
    },
    {
      "x": -28,
      "y": -18,
      "z": 23,
      "name": "Soil_Grass"
    },
    {
      "x": -28,
      "y": -18,
      "z": 24,
      "name": "Soil_Grass"
    },
    {
      "x": -28,
      "y": -18,
      "z": 25,
      "name": "Soil_Grass"
    },
    {
      "x": -28,
      "y": -18,
      "z": 26,
      "name": "Soil_Grass"
    },
    {
      "x": -28,
      "y": -18,
      "z": 27,
      "name": "Soil_Grass"
    },
    {
      "x": -28,
      "y": -18,
      "z": 28,
      "name": "Soil_Grass"
    },
    {
      "x": -28,
      "y": -18,
      "z": 29,
      "name": "Soil_Grass"
    },
    {
      "x": -28,
      "y": -18,
      "z": 30,
      "name": "Soil_Grass"
    },
    {
      "x": -28,
      "y": -18,
      "z": 31,
      "name": "Soil_Grass"
    },
    {
      "x": -28,
      "y": -18,
      "z": 32,
      "name": "Soil_Grass"
    },
    {
      "x": -28,
      "y": -18,
      "z": 33,
      "name": "Soil_Grass"
    },
    {
      "x": -28,
      "y": -18,
      "z": 34,
      "name": "Soil_Grass"
    },
    {
      "x": -28,
      "y": -18,
      "z": 35,
      "name": "Soil_Grass"
    },
    {
      "x": -28,
      "y": -18,
      "z": 36,
      "name": "Soil_Grass"
    },
    {
      "x": -28,
      "y": -18,
      "z": 37,
      "name": "Soil_Grass"
    },
    {
      "x": -27,
      "y": -18,
      "z": -38,
      "name": "Soil_Grass"
    },
    {
      "x": -27,
      "y": -18,
      "z": -37,
      "name": "Soil_Grass"
    },
    {
      "x": -27,
      "y": -18,
      "z": -36,
      "name": "Soil_Grass"
    },
    {
      "x": -27,
      "y": -18,
      "z": -35,
      "name": "Soil_Grass"
    },
    {
      "x": -27,
      "y": -18,
      "z": -34,
      "name": "Soil_Grass"
    },
    {
      "x": -27,
      "y": -18,
      "z": -33,
      "name": "Soil_Grass"
    },
    {
      "x": -27,
      "y": -18,
      "z": -32,
      "name": "Soil_Grass"
    },
    {
      "x": -27,
      "y": -18,
      "z": -31,
      "name": "Soil_Grass"
    },
    {
      "x": -27,
      "y": -18,
      "z": -30,
      "name": "Soil_Grass"
    },
    {
      "x": -27,
      "y": -18,
      "z": -29,
      "name": "Soil_Grass"
    },
    {
      "x": -27,
      "y": -18,
      "z": -28,
      "name": "Soil_Grass"
    },
    {
      "x": -27,
      "y": -18,
      "z": -27,
      "name": "Soil_Grass"
    },
    {
      "x": -27,
      "y": -18,
      "z": -26,
      "name": "Soil_Grass"
    },
    {
      "x": -27,
      "y": -18,
      "z": -25,
      "name": "Soil_Grass"
    },
    {
      "x": -27,
      "y": -18,
      "z": -24,
      "name": "Soil_Grass"
    },
    {
      "x": -27,
      "y": -18,
      "z": -23,
      "name": "Soil_Grass"
    },
    {
      "x": -27,
      "y": -18,
      "z": -22,
      "name": "Soil_Grass"
    },
    {
      "x": -27,
      "y": -18,
      "z": -21,
      "name": "Soil_Grass"
    },
    {
      "x": -27,
      "y": -18,
      "z": -20,
      "name": "Soil_Grass"
    },
    {
      "x": -27,
      "y": -18,
      "z": -19,
      "name": "Soil_Grass"
    },
    {
      "x": -27,
      "y": -18,
      "z": -18,
      "name": "Soil_Grass"
    },
    {
      "x": -27,
      "y": -18,
      "z": -17,
      "name": "Soil_Grass"
    },
    {
      "x": -27,
      "y": -18,
      "z": -16,
      "name": "Soil_Grass"
    },
    {
      "x": -27,
      "y": -18,
      "z": -15,
      "name": "Soil_Grass"
    },
    {
      "x": -27,
      "y": -18,
      "z": -14,
      "name": "Soil_Grass"
    },
    {
      "x": -27,
      "y": -18,
      "z": -13,
      "name": "Soil_Grass"
    },
    {
      "x": -27,
      "y": -18,
      "z": -12,
      "name": "Soil_Grass"
    },
    {
      "x": -27,
      "y": -18,
      "z": -11,
      "name": "Soil_Grass"
    },
    {
      "x": -27,
      "y": -18,
      "z": -10,
      "name": "Soil_Grass"
    },
    {
      "x": -27,
      "y": -18,
      "z": -9,
      "name": "Soil_Grass"
    },
    {
      "x": -27,
      "y": -18,
      "z": -8,
      "name": "Soil_Grass"
    },
    {
      "x": -27,
      "y": -18,
      "z": -7,
      "name": "Soil_Grass"
    },
    {
      "x": -27,
      "y": -18,
      "z": -6,
      "name": "Soil_Grass"
    },
    {
      "x": -27,
      "y": -18,
      "z": -5,
      "name": "Soil_Grass"
    },
    {
      "x": -27,
      "y": -18,
      "z": -4,
      "name": "Soil_Grass"
    },
    {
      "x": -27,
      "y": -18,
      "z": -3,
      "name": "Soil_Grass"
    },
    {
      "x": -27,
      "y": -18,
      "z": -2,
      "name": "Soil_Grass"
    },
    {
      "x": -27,
      "y": -18,
      "z": -1,
      "name": "Soil_Grass"
    },
    {
      "x": -27,
      "y": -18,
      "z": 0,
      "name": "Soil_Grass"
    },
    {
      "x": -27,
      "y": -18,
      "z": 1,
      "name": "Soil_Grass"
    },
    {
      "x": -27,
      "y": -18,
      "z": 2,
      "name": "Soil_Grass"
    },
    {
      "x": -27,
      "y": -18,
      "z": 3,
      "name": "Soil_Grass"
    },
    {
      "x": -27,
      "y": -18,
      "z": 4,
      "name": "Soil_Grass"
    },
    {
      "x": -27,
      "y": -18,
      "z": 5,
      "name": "Soil_Grass"
    },
    {
      "x": -27,
      "y": -18,
      "z": 6,
      "name": "Soil_Grass"
    },
    {
      "x": -27,
      "y": -18,
      "z": 7,
      "name": "Soil_Grass"
    },
    {
      "x": -27,
      "y": -18,
      "z": 8,
      "name": "Soil_Grass"
    },
    {
      "x": -27,
      "y": -18,
      "z": 9,
      "name": "Soil_Grass"
    },
    {
      "x": -27,
      "y": -18,
      "z": 10,
      "name": "Soil_Grass"
    },
    {
      "x": -27,
      "y": -18,
      "z": 11,
      "name": "Soil_Grass"
    },
    {
      "x": -27,
      "y": -18,
      "z": 12,
      "name": "Soil_Grass"
    },
    {
      "x": -27,
      "y": -18,
      "z": 13,
      "name": "Soil_Grass"
    },
    {
      "x": -27,
      "y": -18,
      "z": 14,
      "name": "Soil_Grass"
    },
    {
      "x": -27,
      "y": -18,
      "z": 15,
      "name": "Soil_Grass"
    },
    {
      "x": -27,
      "y": -18,
      "z": 16,
      "name": "Soil_Grass"
    },
    {
      "x": -27,
      "y": -18,
      "z": 17,
      "name": "Soil_Grass"
    },
    {
      "x": -27,
      "y": -18,
      "z": 18,
      "name": "Soil_Grass"
    },
    {
      "x": -27,
      "y": -18,
      "z": 19,
      "name": "Soil_Grass"
    },
    {
      "x": -27,
      "y": -18,
      "z": 20,
      "name": "Soil_Grass"
    },
    {
      "x": -27,
      "y": -18,
      "z": 21,
      "name": "Soil_Grass"
    },
    {
      "x": -27,
      "y": -18,
      "z": 22,
      "name": "Soil_Grass"
    },
    {
      "x": -27,
      "y": -18,
      "z": 23,
      "name": "Soil_Grass"
    },
    {
      "x": -27,
      "y": -18,
      "z": 24,
      "name": "Soil_Grass"
    },
    {
      "x": -27,
      "y": -18,
      "z": 25,
      "name": "Soil_Grass"
    },
    {
      "x": -27,
      "y": -18,
      "z": 26,
      "name": "Soil_Grass"
    },
    {
      "x": -27,
      "y": -18,
      "z": 27,
      "name": "Soil_Grass"
    },
    {
      "x": -27,
      "y": -18,
      "z": 28,
      "name": "Soil_Grass"
    },
    {
      "x": -27,
      "y": -18,
      "z": 29,
      "name": "Soil_Grass"
    },
    {
      "x": -27,
      "y": -18,
      "z": 30,
      "name": "Soil_Grass"
    },
    {
      "x": -27,
      "y": -18,
      "z": 31,
      "name": "Soil_Grass"
    },
    {
      "x": -27,
      "y": -18,
      "z": 32,
      "name": "Soil_Grass"
    },
    {
      "x": -27,
      "y": -18,
      "z": 33,
      "name": "Soil_Grass"
    },
    {
      "x": -27,
      "y": -18,
      "z": 34,
      "name": "Soil_Grass"
    },
    {
      "x": -27,
      "y": -18,
      "z": 35,
      "name": "Soil_Grass"
    },
    {
      "x": -27,
      "y": -18,
      "z": 36,
      "name": "Soil_Grass"
    },
    {
      "x": -27,
      "y": -18,
      "z": 37,
      "name": "Soil_Grass"
    },
    {
      "x": -26,
      "y": -18,
      "z": -38,
      "name": "Soil_Grass"
    },
    {
      "x": -26,
      "y": -18,
      "z": -37,
      "name": "Soil_Grass"
    },
    {
      "x": -26,
      "y": -18,
      "z": -36,
      "name": "Soil_Grass"
    },
    {
      "x": -26,
      "y": -18,
      "z": -35,
      "name": "Soil_Grass"
    },
    {
      "x": -26,
      "y": -18,
      "z": -34,
      "name": "Soil_Grass"
    },
    {
      "x": -26,
      "y": -18,
      "z": -33,
      "name": "Soil_Grass"
    },
    {
      "x": -26,
      "y": -18,
      "z": -32,
      "name": "Soil_Grass"
    },
    {
      "x": -26,
      "y": -18,
      "z": -31,
      "name": "Soil_Grass"
    },
    {
      "x": -26,
      "y": -18,
      "z": -30,
      "name": "Soil_Grass"
    },
    {
      "x": -26,
      "y": -18,
      "z": -29,
      "name": "Soil_Grass"
    },
    {
      "x": -26,
      "y": -18,
      "z": -28,
      "name": "Soil_Grass"
    },
    {
      "x": -26,
      "y": -18,
      "z": -27,
      "name": "Soil_Grass"
    },
    {
      "x": -26,
      "y": -18,
      "z": -26,
      "name": "Soil_Grass"
    },
    {
      "x": -26,
      "y": -18,
      "z": -25,
      "name": "Soil_Grass"
    },
    {
      "x": -26,
      "y": -18,
      "z": -24,
      "name": "Soil_Grass"
    },
    {
      "x": -26,
      "y": -18,
      "z": -23,
      "name": "Soil_Grass"
    },
    {
      "x": -26,
      "y": -18,
      "z": -22,
      "name": "Soil_Grass"
    },
    {
      "x": -26,
      "y": -18,
      "z": -21,
      "name": "Soil_Grass"
    },
    {
      "x": -26,
      "y": -18,
      "z": -20,
      "name": "Soil_Grass"
    },
    {
      "x": -26,
      "y": -18,
      "z": -19,
      "name": "Soil_Grass"
    },
    {
      "x": -26,
      "y": -18,
      "z": -18,
      "name": "Soil_Grass"
    },
    {
      "x": -26,
      "y": -18,
      "z": -17,
      "name": "Soil_Grass"
    },
    {
      "x": -26,
      "y": -18,
      "z": -16,
      "name": "Soil_Grass"
    },
    {
      "x": -26,
      "y": -18,
      "z": -15,
      "name": "Soil_Grass"
    },
    {
      "x": -26,
      "y": -18,
      "z": -14,
      "name": "Soil_Grass"
    },
    {
      "x": -26,
      "y": -18,
      "z": -13,
      "name": "Soil_Grass"
    },
    {
      "x": -26,
      "y": -18,
      "z": -12,
      "name": "Soil_Grass"
    },
    {
      "x": -26,
      "y": -18,
      "z": -11,
      "name": "Soil_Grass"
    },
    {
      "x": -26,
      "y": -18,
      "z": -10,
      "name": "Soil_Grass"
    },
    {
      "x": -26,
      "y": -18,
      "z": -9,
      "name": "Soil_Grass"
    },
    {
      "x": -26,
      "y": -18,
      "z": -8,
      "name": "Soil_Grass"
    },
    {
      "x": -26,
      "y": -18,
      "z": -7,
      "name": "Soil_Grass"
    },
    {
      "x": -26,
      "y": -18,
      "z": -6,
      "name": "Soil_Grass"
    },
    {
      "x": -26,
      "y": -18,
      "z": -5,
      "name": "Soil_Grass"
    },
    {
      "x": -26,
      "y": -18,
      "z": -4,
      "name": "Soil_Grass"
    },
    {
      "x": -26,
      "y": -18,
      "z": -3,
      "name": "Soil_Grass"
    },
    {
      "x": -26,
      "y": -18,
      "z": -2,
      "name": "Soil_Grass"
    },
    {
      "x": -26,
      "y": -18,
      "z": -1,
      "name": "Soil_Grass"
    },
    {
      "x": -26,
      "y": -18,
      "z": 0,
      "name": "Soil_Grass"
    },
    {
      "x": -26,
      "y": -18,
      "z": 1,
      "name": "Soil_Grass"
    },
    {
      "x": -26,
      "y": -18,
      "z": 2,
      "name": "Soil_Grass"
    },
    {
      "x": -26,
      "y": -18,
      "z": 3,
      "name": "Soil_Grass"
    },
    {
      "x": -26,
      "y": -18,
      "z": 4,
      "name": "Soil_Grass"
    },
    {
      "x": -26,
      "y": -18,
      "z": 5,
      "name": "Soil_Grass"
    },
    {
      "x": -26,
      "y": -18,
      "z": 6,
      "name": "Soil_Grass"
    },
    {
      "x": -26,
      "y": -18,
      "z": 7,
      "name": "Soil_Grass"
    },
    {
      "x": -26,
      "y": -18,
      "z": 8,
      "name": "Soil_Grass"
    },
    {
      "x": -26,
      "y": -18,
      "z": 9,
      "name": "Soil_Grass"
    },
    {
      "x": -26,
      "y": -18,
      "z": 10,
      "name": "Soil_Grass"
    },
    {
      "x": -26,
      "y": -18,
      "z": 11,
      "name": "Soil_Grass"
    },
    {
      "x": -26,
      "y": -18,
      "z": 12,
      "name": "Soil_Grass"
    },
    {
      "x": -26,
      "y": -18,
      "z": 13,
      "name": "Soil_Grass"
    },
    {
      "x": -26,
      "y": -18,
      "z": 14,
      "name": "Soil_Grass"
    },
    {
      "x": -26,
      "y": -18,
      "z": 15,
      "name": "Soil_Grass"
    },
    {
      "x": -26,
      "y": -18,
      "z": 16,
      "name": "Soil_Grass"
    },
    {
      "x": -26,
      "y": -18,
      "z": 17,
      "name": "Soil_Grass"
    },
    {
      "x": -26,
      "y": -18,
      "z": 18,
      "name": "Soil_Grass"
    },
    {
      "x": -26,
      "y": -18,
      "z": 19,
      "name": "Soil_Grass"
    },
    {
      "x": -26,
      "y": -18,
      "z": 20,
      "name": "Soil_Grass"
    },
    {
      "x": -26,
      "y": -18,
      "z": 21,
      "name": "Soil_Grass"
    },
    {
      "x": -26,
      "y": -18,
      "z": 22,
      "name": "Soil_Grass"
    },
    {
      "x": -26,
      "y": -18,
      "z": 23,
      "name": "Soil_Grass"
    },
    {
      "x": -26,
      "y": -18,
      "z": 24,
      "name": "Soil_Grass"
    },
    {
      "x": -26,
      "y": -18,
      "z": 25,
      "name": "Soil_Grass"
    },
    {
      "x": -26,
      "y": -18,
      "z": 26,
      "name": "Soil_Grass"
    },
    {
      "x": -26,
      "y": -18,
      "z": 27,
      "name": "Soil_Grass"
    },
    {
      "x": -26,
      "y": -18,
      "z": 28,
      "name": "Soil_Grass"
    },
    {
      "x": -26,
      "y": -18,
      "z": 29,
      "name": "Soil_Grass"
    },
    {
      "x": -26,
      "y": -18,
      "z": 30,
      "name": "Soil_Grass"
    },
    {
      "x": -26,
      "y": -18,
      "z": 31,
      "name": "Soil_Grass"
    },
    {
      "x": -26,
      "y": -18,
      "z": 32,
      "name": "Soil_Grass"
    },
    {
      "x": -26,
      "y": -18,
      "z": 33,
      "name": "Soil_Grass"
    },
    {
      "x": -26,
      "y": -18,
      "z": 34,
      "name": "Soil_Grass"
    },
    {
      "x": -26,
      "y": -18,
      "z": 35,
      "name": "Soil_Grass"
    },
    {
      "x": -26,
      "y": -18,
      "z": 36,
      "name": "Soil_Grass"
    },
    {
      "x": -26,
      "y": -18,
      "z": 37,
      "name": "Soil_Grass"
    },
    {
      "x": -25,
      "y": -18,
      "z": -38,
      "name": "Soil_Grass"
    },
    {
      "x": -25,
      "y": -18,
      "z": -37,
      "name": "Soil_Grass"
    },
    {
      "x": -25,
      "y": -18,
      "z": -36,
      "name": "Soil_Grass"
    },
    {
      "x": -25,
      "y": -18,
      "z": -35,
      "name": "Soil_Grass"
    },
    {
      "x": -25,
      "y": -18,
      "z": -34,
      "name": "Soil_Grass"
    },
    {
      "x": -25,
      "y": -18,
      "z": -33,
      "name": "Soil_Grass"
    },
    {
      "x": -25,
      "y": -18,
      "z": -32,
      "name": "Soil_Grass"
    },
    {
      "x": -25,
      "y": -18,
      "z": -31,
      "name": "Soil_Grass"
    },
    {
      "x": -25,
      "y": -18,
      "z": -30,
      "name": "Soil_Grass"
    },
    {
      "x": -25,
      "y": -18,
      "z": -29,
      "name": "Soil_Grass"
    },
    {
      "x": -25,
      "y": -18,
      "z": -28,
      "name": "Soil_Grass"
    },
    {
      "x": -25,
      "y": -18,
      "z": -27,
      "name": "Soil_Grass"
    },
    {
      "x": -25,
      "y": -18,
      "z": -26,
      "name": "Soil_Grass"
    },
    {
      "x": -25,
      "y": -18,
      "z": -25,
      "name": "Soil_Grass"
    },
    {
      "x": -25,
      "y": -18,
      "z": -24,
      "name": "Soil_Grass"
    },
    {
      "x": -25,
      "y": -18,
      "z": -23,
      "name": "Soil_Grass"
    },
    {
      "x": -25,
      "y": -18,
      "z": -22,
      "name": "Soil_Grass"
    },
    {
      "x": -25,
      "y": -18,
      "z": -21,
      "name": "Soil_Grass"
    },
    {
      "x": -25,
      "y": -18,
      "z": -20,
      "name": "Soil_Grass"
    },
    {
      "x": -25,
      "y": -18,
      "z": -19,
      "name": "Soil_Grass"
    },
    {
      "x": -25,
      "y": -18,
      "z": -18,
      "name": "Soil_Grass"
    },
    {
      "x": -25,
      "y": -18,
      "z": -17,
      "name": "Soil_Grass"
    },
    {
      "x": -25,
      "y": -18,
      "z": -16,
      "name": "Soil_Grass"
    },
    {
      "x": -25,
      "y": -18,
      "z": -15,
      "name": "Soil_Grass"
    },
    {
      "x": -25,
      "y": -18,
      "z": -14,
      "name": "Soil_Grass"
    },
    {
      "x": -25,
      "y": -18,
      "z": -13,
      "name": "Soil_Grass"
    },
    {
      "x": -25,
      "y": -18,
      "z": -12,
      "name": "Soil_Grass"
    },
    {
      "x": -25,
      "y": -18,
      "z": -11,
      "name": "Soil_Grass"
    },
    {
      "x": -25,
      "y": -18,
      "z": -10,
      "name": "Soil_Grass"
    },
    {
      "x": -25,
      "y": -18,
      "z": -9,
      "name": "Soil_Grass"
    },
    {
      "x": -25,
      "y": -18,
      "z": -8,
      "name": "Soil_Grass"
    },
    {
      "x": -25,
      "y": -18,
      "z": -7,
      "name": "Soil_Grass"
    },
    {
      "x": -25,
      "y": -18,
      "z": -6,
      "name": "Soil_Grass"
    },
    {
      "x": -25,
      "y": -18,
      "z": -5,
      "name": "Soil_Grass"
    },
    {
      "x": -25,
      "y": -18,
      "z": -4,
      "name": "Soil_Grass"
    },
    {
      "x": -25,
      "y": -18,
      "z": -3,
      "name": "Soil_Grass"
    },
    {
      "x": -25,
      "y": -18,
      "z": -2,
      "name": "Soil_Grass"
    },
    {
      "x": -25,
      "y": -18,
      "z": -1,
      "name": "Soil_Grass"
    },
    {
      "x": -25,
      "y": -18,
      "z": 0,
      "name": "Soil_Grass"
    },
    {
      "x": -25,
      "y": -18,
      "z": 1,
      "name": "Soil_Grass"
    },
    {
      "x": -25,
      "y": -10,
      "z": 1,
      "name": "*Rock_Stone_Half_State_Definitions_Block",
      "rotation": 7
    },
    {
      "x": -25,
      "y": -9,
      "z": 1,
      "name": "Rock_Stone_Half"
    },
    {
      "x": -25,
      "y": -8,
      "z": 1,
      "name": "Rock_Stone"
    },
    {
      "x": -25,
      "y": -7,
      "z": 1,
      "name": "Rock_Stone"
    },
    {
      "x": -25,
      "y": -6,
      "z": 1,
      "name": "Rock_Stone"
    },
    {
      "x": -25,
      "y": -5,
      "z": 1,
      "name": "Rock_Stone"
    },
    {
      "x": -25,
      "y": -4,
      "z": 1,
      "name": "Rock_Stone"
    },
    {
      "x": -25,
      "y": -2,
      "z": 1,
      "name": "Rock_Stone_Half",
      "rotation": 8
    },
    {
      "x": -25,
      "y": -1,
      "z": 1,
      "name": "Rock_Stone"
    },
    {
      "x": -25,
      "y": 0,
      "z": 1,
      "name": "Rock_Stone"
    },
    {
      "x": -25,
      "y": 1,
      "z": 1,
      "name": "Rock_Stone"
    },
    {
      "x": -25,
      "y": 2,
      "z": 1,
      "name": "Rock_Stone_Mossy"
    },
    {
      "x": -25,
      "y": 3,
      "z": 1,
      "name": "Rock_Stone"
    },
    {
      "x": -25,
      "y": 4,
      "z": 1,
      "name": "Rock_Stone_Mossy"
    },
    {
      "x": -25,
      "y": 5,
      "z": 1,
      "name": "Rock_Stone"
    },
    {
      "x": -25,
      "y": 6,
      "z": 1,
      "name": "Rock_Stone_Mossy"
    },
    {
      "x": -25,
      "y": -18,
      "z": 2,
      "name": "Soil_Grass"
    },
    {
      "x": -25,
      "y": -12,
      "z": 2,
      "name": "Rock_Stone_Mossy"
    },
    {
      "x": -25,
      "y": -11,
      "z": 2,
      "name": "Rock_Stone_Mossy"
    },
    {
      "x": -25,
      "y": -10,
      "z": 2,
      "name": "Rock_Stone"
    },
    {
      "x": -25,
      "y": -9,
      "z": 2,
      "name": "Rock_Stone_Half"
    },
    {
      "x": -25,
      "y": -8,
      "z": 2,
      "name": "Rock_Crystal_Purple_Small",
      "rotation": 7
    },
    {
      "x": -25,
      "y": -7,
      "z": 2,
      "name": "Rock_Stone"
    },
    {
      "x": -25,
      "y": -6,
      "z": 2,
      "name": "Rock_Stone"
    },
    {
      "x": -25,
      "y": -5,
      "z": 2,
      "name": "Rock_Stone"
    },
    {
      "x": -25,
      "y": -4,
      "z": 2,
      "name": "Rock_Stone"
    },
    {
      "x": -25,
      "y": -3,
      "z": 2,
      "name": "Rock_Stone"
    },
    {
      "x": -25,
      "y": -2,
      "z": 2,
      "name": "Rock_Crystal_Purple_Small",
      "rotation": 7
    },
    {
      "x": -25,
      "y": 0,
      "z": 2,
      "name": "Rock_Stone"
    },
    {
      "x": -25,
      "y": 1,
      "z": 2,
      "name": "Rock_Stone"
    },
    {
      "x": -25,
      "y": 2,
      "z": 2,
      "name": "Rock_Stone_Mossy"
    },
    {
      "x": -25,
      "y": 3,
      "z": 2,
      "name": "Rock_Stone"
    },
    {
      "x": -25,
      "y": 4,
      "z": 2,
      "name": "Rock_Stone"
    },
    {
      "x": -25,
      "y": 5,
      "z": 2,
      "name": "Rock_Stone"
    },
    {
      "x": -25,
      "y": 6,
      "z": 2,
      "name": "Rock_Stone"
    },
    {
      "x": -25,
      "y": 7,
      "z": 2,
      "name": "Rock_Stone"
    },
    {
      "x": -25,
      "y": -18,
      "z": 3,
      "name": "Soil_Grass"
    },
    {
      "x": -25,
      "y": -12,
      "z": 3,
      "name": "Rock_Stone"
    },
    {
      "x": -25,
      "y": -11,
      "z": 3,
      "name": "Rock_Stone"
    },
    {
      "x": -25,
      "y": -10,
      "z": 3,
      "name": "Rock_Stone"
    },
    {
      "x": -25,
      "y": -9,
      "z": 3,
      "name": "Rock_Stone"
    },
    {
      "x": -25,
      "y": -7,
      "z": 3,
      "name": "Rock_Stone"
    },
    {
      "x": -25,
      "y": -6,
      "z": 3,
      "name": "Rock_Stone"
    },
    {
      "x": -25,
      "y": -5,
      "z": 3,
      "name": "Rock_Stone"
    },
    {
      "x": -25,
      "y": -4,
      "z": 3,
      "name": "Rock_Stone"
    },
    {
      "x": -25,
      "y": -3,
      "z": 3,
      "name": "Rock_Stone"
    },
    {
      "x": -25,
      "y": -2,
      "z": 3,
      "name": "Rock_Stone"
    },
    {
      "x": -25,
      "y": 0,
      "z": 3,
      "name": "Rock_Stone_Half",
      "rotation": 8
    },
    {
      "x": -25,
      "y": 1,
      "z": 3,
      "name": "Rock_Stone"
    },
    {
      "x": -25,
      "y": 2,
      "z": 3,
      "name": "Rock_Stone"
    },
    {
      "x": -25,
      "y": 3,
      "z": 3,
      "name": "Rock_Stone"
    },
    {
      "x": -25,
      "y": 4,
      "z": 3,
      "name": "Rock_Stone"
    },
    {
      "x": -25,
      "y": 5,
      "z": 3,
      "name": "Rock_Stone"
    },
    {
      "x": -25,
      "y": 6,
      "z": 3,
      "name": "Rock_Stone"
    },
    {
      "x": -25,
      "y": 7,
      "z": 3,
      "name": "Rock_Stone"
    },
    {
      "x": -25,
      "y": 8,
      "z": 3,
      "name": "Rock_Stone"
    },
    {
      "x": -25,
      "y": 9,
      "z": 3,
      "name": "Rock_Stone"
    },
    {
      "x": -25,
      "y": 10,
      "z": 3,
      "name": "Plant_Crop_Mushroom_Glowing_Purple"
    },
    {
      "x": -25,
      "y": -18,
      "z": 4,
      "name": "Soil_Grass"
    },
    {
      "x": -25,
      "y": -9,
      "z": 4,
      "name": "Rock_Stone"
    },
    {
      "x": -25,
      "y": -8,
      "z": 4,
      "name": "Rock_Stone_Half"
    },
    {
      "x": -25,
      "y": -7,
      "z": 4,
      "name": "Rock_Stone"
    },
    {
      "x": -25,
      "y": -6,
      "z": 4,
      "name": "Rock_Stone"
    },
    {
      "x": -25,
      "y": -5,
      "z": 4,
      "name": "Rock_Stone"
    },
    {
      "x": -25,
      "y": -4,
      "z": 4,
      "name": "Rock_Stone"
    },
    {
      "x": -25,
      "y": -3,
      "z": 4,
      "name": "Rock_Stone"
    },
    {
      "x": -25,
      "y": -2,
      "z": 4,
      "name": "Rock_Stone"
    },
    {
      "x": -25,
      "y": -1,
      "z": 4,
      "name": "Rock_Stone"
    },
    {
      "x": -25,
      "y": 0,
      "z": 4,
      "name": "Rock_Crystal_Purple_Small",
      "rotation": 7
    },
    {
      "x": -25,
      "y": 1,
      "z": 4,
      "name": "Rock_Stone"
    },
    {
      "x": -25,
      "y": 2,
      "z": 4,
      "name": "Rock_Stone"
    },
    {
      "x": -25,
      "y": 3,
      "z": 4,
      "name": "Rock_Stone"
    },
    {
      "x": -25,
      "y": 4,
      "z": 4,
      "name": "Rock_Stone"
    },
    {
      "x": -25,
      "y": 5,
      "z": 4,
      "name": "Rock_Stone"
    },
    {
      "x": -25,
      "y": 6,
      "z": 4,
      "name": "Rock_Stone"
    },
    {
      "x": -25,
      "y": 7,
      "z": 4,
      "name": "Rock_Stone_Mossy"
    },
    {
      "x": -25,
      "y": 8,
      "z": 4,
      "name": "Rock_Stone"
    },
    {
      "x": -25,
      "y": -18,
      "z": 5,
      "name": "Soil_Grass"
    },
    {
      "x": -25,
      "y": -7,
      "z": 5,
      "name": "Rock_Stone_Half",
      "rotation": 4
    },
    {
      "x": -25,
      "y": -6,
      "z": 5,
      "name": "Rock_Stone_Half",
      "rotation": 4
    },
    {
      "x": -25,
      "y": 1,
      "z": 5,
      "name": "Rock_Stone_Half",
      "rotation": 4
    },
    {
      "x": -25,
      "y": -18,
      "z": 6,
      "name": "Soil_Grass"
    },
    {
      "x": -25,
      "y": -18,
      "z": 7,
      "name": "Soil_Grass"
    },
    {
      "x": -25,
      "y": -18,
      "z": 8,
      "name": "Soil_Grass"
    },
    {
      "x": -25,
      "y": -18,
      "z": 9,
      "name": "Soil_Grass"
    },
    {
      "x": -25,
      "y": -18,
      "z": 10,
      "name": "Soil_Grass"
    },
    {
      "x": -25,
      "y": -18,
      "z": 11,
      "name": "Soil_Grass"
    },
    {
      "x": -25,
      "y": -18,
      "z": 12,
      "name": "Soil_Grass"
    },
    {
      "x": -25,
      "y": -18,
      "z": 13,
      "name": "Soil_Grass"
    },
    {
      "x": -25,
      "y": -18,
      "z": 14,
      "name": "Soil_Grass"
    },
    {
      "x": -25,
      "y": -18,
      "z": 15,
      "name": "Soil_Grass"
    },
    {
      "x": -25,
      "y": -18,
      "z": 16,
      "name": "Soil_Grass"
    },
    {
      "x": -25,
      "y": -18,
      "z": 17,
      "name": "Soil_Grass"
    },
    {
      "x": -25,
      "y": -18,
      "z": 18,
      "name": "Soil_Grass"
    },
    {
      "x": -25,
      "y": -18,
      "z": 19,
      "name": "Soil_Grass"
    },
    {
      "x": -25,
      "y": -18,
      "z": 20,
      "name": "Soil_Grass"
    },
    {
      "x": -25,
      "y": -18,
      "z": 21,
      "name": "Soil_Grass"
    },
    {
      "x": -25,
      "y": -18,
      "z": 22,
      "name": "Soil_Grass"
    },
    {
      "x": -25,
      "y": -18,
      "z": 23,
      "name": "Soil_Grass"
    },
    {
      "x": -25,
      "y": -18,
      "z": 24,
      "name": "Soil_Grass"
    },
    {
      "x": -25,
      "y": -18,
      "z": 25,
      "name": "Soil_Grass"
    },
    {
      "x": -25,
      "y": -18,
      "z": 26,
      "name": "Soil_Grass"
    },
    {
      "x": -25,
      "y": -18,
      "z": 27,
      "name": "Soil_Grass"
    },
    {
      "x": -25,
      "y": -18,
      "z": 28,
      "name": "Soil_Grass"
    },
    {
      "x": -25,
      "y": -18,
      "z": 29,
      "name": "Soil_Grass"
    },
    {
      "x": -25,
      "y": -18,
      "z": 30,
      "name": "Soil_Grass"
    },
    {
      "x": -25,
      "y": -18,
      "z": 31,
      "name": "Soil_Grass"
    },
    {
      "x": -25,
      "y": -18,
      "z": 32,
      "name": "Soil_Grass"
    },
    {
      "x": -25,
      "y": -18,
      "z": 33,
      "name": "Soil_Grass"
    },
    {
      "x": -25,
      "y": -18,
      "z": 34,
      "name": "Soil_Grass"
    },
    {
      "x": -25,
      "y": -18,
      "z": 35,
      "name": "Soil_Grass"
    },
    {
      "x": -25,
      "y": -18,
      "z": 36,
      "name": "Soil_Grass"
    },
    {
      "x": -25,
      "y": -18,
      "z": 37,
      "name": "Soil_Grass"
    },
    {
      "x": -24,
      "y": -18,
      "z": -38,
      "name": "Soil_Grass"
    },
    {
      "x": -24,
      "y": -18,
      "z": -37,
      "name": "Soil_Grass"
    },
    {
      "x": -24,
      "y": -18,
      "z": -36,
      "name": "Soil_Grass"
    },
    {
      "x": -24,
      "y": -18,
      "z": -35,
      "name": "Soil_Grass"
    },
    {
      "x": -24,
      "y": -18,
      "z": -34,
      "name": "Soil_Grass"
    },
    {
      "x": -24,
      "y": -18,
      "z": -33,
      "name": "Soil_Grass"
    },
    {
      "x": -24,
      "y": -18,
      "z": -32,
      "name": "Soil_Grass"
    },
    {
      "x": -24,
      "y": -18,
      "z": -31,
      "name": "Soil_Grass"
    },
    {
      "x": -24,
      "y": -18,
      "z": -30,
      "name": "Soil_Grass"
    },
    {
      "x": -24,
      "y": -18,
      "z": -29,
      "name": "Soil_Grass"
    },
    {
      "x": -24,
      "y": -18,
      "z": -28,
      "name": "Soil_Grass"
    },
    {
      "x": -24,
      "y": -18,
      "z": -27,
      "name": "Soil_Grass"
    },
    {
      "x": -24,
      "y": -18,
      "z": -26,
      "name": "Soil_Grass"
    },
    {
      "x": -24,
      "y": -18,
      "z": -25,
      "name": "Soil_Grass"
    },
    {
      "x": -24,
      "y": -18,
      "z": -24,
      "name": "Soil_Grass"
    },
    {
      "x": -24,
      "y": -18,
      "z": -23,
      "name": "Soil_Grass"
    },
    {
      "x": -24,
      "y": -18,
      "z": -22,
      "name": "Soil_Grass"
    },
    {
      "x": -24,
      "y": -18,
      "z": -21,
      "name": "Soil_Grass"
    },
    {
      "x": -24,
      "y": -18,
      "z": -20,
      "name": "Soil_Grass"
    },
    {
      "x": -24,
      "y": -18,
      "z": -19,
      "name": "Soil_Grass"
    },
    {
      "x": -24,
      "y": -18,
      "z": -18,
      "name": "Soil_Grass"
    },
    {
      "x": -24,
      "y": -18,
      "z": -17,
      "name": "Soil_Grass"
    },
    {
      "x": -24,
      "y": -18,
      "z": -16,
      "name": "Soil_Grass"
    },
    {
      "x": -24,
      "y": -18,
      "z": -15,
      "name": "Soil_Grass"
    },
    {
      "x": -24,
      "y": -18,
      "z": -14,
      "name": "Soil_Grass"
    },
    {
      "x": -24,
      "y": -18,
      "z": -13,
      "name": "Soil_Grass"
    },
    {
      "x": -24,
      "y": -18,
      "z": -12,
      "name": "Soil_Grass"
    },
    {
      "x": -24,
      "y": -18,
      "z": -11,
      "name": "Soil_Grass"
    },
    {
      "x": -24,
      "y": -18,
      "z": -10,
      "name": "Soil_Grass"
    },
    {
      "x": -24,
      "y": -18,
      "z": -9,
      "name": "Soil_Grass"
    },
    {
      "x": -24,
      "y": -18,
      "z": -8,
      "name": "Soil_Grass"
    },
    {
      "x": -24,
      "y": -18,
      "z": -7,
      "name": "Soil_Grass"
    },
    {
      "x": -24,
      "y": -18,
      "z": -6,
      "name": "Soil_Grass"
    },
    {
      "x": -24,
      "y": -18,
      "z": -5,
      "name": "Soil_Grass"
    },
    {
      "x": -24,
      "y": -18,
      "z": -4,
      "name": "Soil_Grass"
    },
    {
      "x": -24,
      "y": -18,
      "z": -3,
      "name": "Soil_Grass"
    },
    {
      "x": -24,
      "y": -18,
      "z": -2,
      "name": "Soil_Grass"
    },
    {
      "x": -24,
      "y": -18,
      "z": -1,
      "name": "Soil_Grass"
    },
    {
      "x": -24,
      "y": -18,
      "z": 0,
      "name": "Soil_Grass"
    },
    {
      "x": -24,
      "y": -10,
      "z": 0,
      "name": "*Rock_Stone_Half_State_Definitions_Block",
      "rotation": 6
    },
    {
      "x": -24,
      "y": -9,
      "z": 0,
      "name": "Rock_Stone_Half"
    },
    {
      "x": -24,
      "y": -8,
      "z": 0,
      "name": "Rock_Stone"
    },
    {
      "x": -24,
      "y": -7,
      "z": 0,
      "name": "Rock_Stone"
    },
    {
      "x": -24,
      "y": -6,
      "z": 0,
      "name": "Rock_Stone"
    },
    {
      "x": -24,
      "y": -5,
      "z": 0,
      "name": "Rock_Stone"
    },
    {
      "x": -24,
      "y": -4,
      "z": 0,
      "name": "Rock_Stone"
    },
    {
      "x": -24,
      "y": -2,
      "z": 0,
      "name": "Rock_Stone"
    },
    {
      "x": -24,
      "y": -1,
      "z": 0,
      "name": "Rock_Stone"
    },
    {
      "x": -24,
      "y": 0,
      "z": 0,
      "name": "Rock_Stone"
    },
    {
      "x": -24,
      "y": 1,
      "z": 0,
      "name": "Rock_Stone"
    },
    {
      "x": -24,
      "y": 2,
      "z": 0,
      "name": "Rock_Stone"
    },
    {
      "x": -24,
      "y": 3,
      "z": 0,
      "name": "Rock_Stone"
    },
    {
      "x": -24,
      "y": 4,
      "z": 0,
      "name": "Rock_Stone"
    },
    {
      "x": -24,
      "y": 5,
      "z": 0,
      "name": "Rock_Stone"
    },
    {
      "x": -24,
      "y": 6,
      "z": 0,
      "name": "Rock_Stone"
    },
    {
      "x": -24,
      "y": 8,
      "z": 0,
      "name": "Rock_Stone"
    },
    {
      "x": -24,
      "y": 9,
      "z": 0,
      "name": "Rock_Stone"
    },
    {
      "x": -24,
      "y": 10,
      "z": 0,
      "name": "Rubble_Stone_Medium",
      "support": 15
    },
    {
      "x": -24,
      "y": -18,
      "z": 1,
      "name": "Soil_Grass"
    },
    {
      "x": -24,
      "y": -14,
      "z": 1,
      "name": "Rock_Stone"
    },
    {
      "x": -24,
      "y": -13,
      "z": 1,
      "name": "Rock_Stone"
    },
    {
      "x": -24,
      "y": -12,
      "z": 1,
      "name": "Rock_Stone"
    },
    {
      "x": -24,
      "y": -11,
      "z": 1,
      "name": "Rock_Stone_Mossy"
    },
    {
      "x": -24,
      "y": -10,
      "z": 1,
      "name": "Rock_Stone_Mossy"
    },
    {
      "x": -24,
      "y": -9,
      "z": 1,
      "name": "Rock_Crystal_Purple_Block",
      "rotation": 4
    },
    {
      "x": -24,
      "y": -8,
      "z": 1,
      "name": "Rock_Stone"
    },
    {
      "x": -24,
      "y": -7,
      "z": 1,
      "name": "Rock_Stone"
    },
    {
      "x": -24,
      "y": -6,
      "z": 1,
      "name": "Rock_Stone"
    },
    {
      "x": -24,
      "y": -5,
      "z": 1,
      "name": "Rock_Stone"
    },
    {
      "x": -24,
      "y": -4,
      "z": 1,
      "name": "Rock_Stone"
    },
    {
      "x": -24,
      "y": -3,
      "z": 1,
      "name": "Rock_Crystal_Purple_Block",
      "rotation": 4
    },
    {
      "x": -24,
      "y": -2,
      "z": 1,
      "name": "Rock_Crystal_Purple_Block",
      "rotation": 5
    },
    {
      "x": -24,
      "y": -1,
      "z": 1,
      "name": "Rock_Stone"
    },
    {
      "x": -24,
      "y": 0,
      "z": 1,
      "name": "Rock_Stone"
    },
    {
      "x": -24,
      "y": 1,
      "z": 1,
      "name": "Rock_Stone"
    },
    {
      "x": -24,
      "y": 2,
      "z": 1,
      "name": "Rock_Stone"
    },
    {
      "x": -24,
      "y": 3,
      "z": 1,
      "name": "Rock_Stone"
    },
    {
      "x": -24,
      "y": 4,
      "z": 1,
      "name": "Rock_Stone"
    },
    {
      "x": -24,
      "y": 5,
      "z": 1,
      "name": "Rock_Stone"
    },
    {
      "x": -24,
      "y": 6,
      "z": 1,
      "name": "Rock_Stone"
    },
    {
      "x": -24,
      "y": 7,
      "z": 1,
      "name": "Rock_Crystal_Purple_Small",
      "rotation": 7
    },
    {
      "x": -24,
      "y": 9,
      "z": 1,
      "name": "Rock_Stone"
    },
    {
      "x": -24,
      "y": 10,
      "z": 1,
      "name": "Rock_Stone"
    },
    {
      "x": -24,
      "y": 11,
      "z": 1,
      "name": "Rock_Stone"
    },
    {
      "x": -24,
      "y": 12,
      "z": 1,
      "name": "Rock_Stone"
    },
    {
      "x": -24,
      "y": 13,
      "z": 1,
      "name": "Rock_Stone"
    },
    {
      "x": -24,
      "y": 14,
      "z": 1,
      "name": "Rubble_Stone",
      "support": 15
    },
    {
      "x": -24,
      "y": -18,
      "z": 2,
      "name": "Soil_Grass"
    },
    {
      "x": -24,
      "y": -15,
      "z": 2,
      "name": "Rock_Stone"
    },
    {
      "x": -24,
      "y": -14,
      "z": 2,
      "name": "Rock_Stone"
    },
    {
      "x": -24,
      "y": -13,
      "z": 2,
      "name": "Rock_Stone"
    },
    {
      "x": -24,
      "y": -12,
      "z": 2,
      "name": "Rock_Stone"
    },
    {
      "x": -24,
      "y": -11,
      "z": 2,
      "name": "Rock_Stone"
    },
    {
      "x": -24,
      "y": -10,
      "z": 2,
      "name": "Rock_Stone"
    },
    {
      "x": -24,
      "y": -9,
      "z": 2,
      "name": "Rock_Crystal_Purple_Block",
      "rotation": 5
    },
    {
      "x": -24,
      "y": -8,
      "z": 2,
      "name": "Rock_Crystal_Purple_Block",
      "rotation": 5
    },
    {
      "x": -24,
      "y": -7,
      "z": 2,
      "name": "Rock_Stone"
    },
    {
      "x": -24,
      "y": -6,
      "z": 2,
      "name": "Rock_Stone"
    },
    {
      "x": -24,
      "y": -5,
      "z": 2,
      "name": "Rock_Stone"
    },
    {
      "x": -24,
      "y": -4,
      "z": 2,
      "name": "Rock_Stone"
    },
    {
      "x": -24,
      "y": -3,
      "z": 2,
      "name": "Rock_Stone_Mossy"
    },
    {
      "x": -24,
      "y": -2,
      "z": 2,
      "name": "Rock_Crystal_Purple_Block",
      "rotation": 5
    },
    {
      "x": -24,
      "y": -1,
      "z": 2,
      "name": "Rock_Crystal_Purple_Block",
      "rotation": 5
    },
    {
      "x": -24,
      "y": 0,
      "z": 2,
      "name": "Rock_Stone_Mossy"
    },
    {
      "x": -24,
      "y": 1,
      "z": 2,
      "name": "Rock_Stone"
    },
    {
      "x": -24,
      "y": 2,
      "z": 2,
      "name": "Rock_Stone"
    },
    {
      "x": -24,
      "y": 3,
      "z": 2,
      "name": "Rock_Stone"
    },
    {
      "x": -24,
      "y": 4,
      "z": 2,
      "name": "Rock_Stone"
    },
    {
      "x": -24,
      "y": 5,
      "z": 2,
      "name": "Rock_Stone"
    },
    {
      "x": -24,
      "y": 6,
      "z": 2,
      "name": "Rock_Stone"
    },
    {
      "x": -24,
      "y": 7,
      "z": 2,
      "name": "Rock_Stone"
    },
    {
      "x": -24,
      "y": 8,
      "z": 2,
      "name": "Rock_Crystal_Purple_Small",
      "rotation": 7
    },
    {
      "x": -24,
      "y": 10,
      "z": 2,
      "name": "Rock_Crystal_Purple_Medium",
      "rotation": 7
    },
    {
      "x": -24,
      "y": 11,
      "z": 2,
      "name": "Rock_Stone"
    },
    {
      "x": -24,
      "y": 12,
      "z": 2,
      "name": "Rock_Stone"
    },
    {
      "x": -24,
      "y": 13,
      "z": 2,
      "name": "Rock_Stone_Mossy"
    },
    {
      "x": -24,
      "y": 14,
      "z": 2,
      "name": "Rock_Stone"
    },
    {
      "x": -24,
      "y": 15,
      "z": 2,
      "name": "Rubble_Stone",
      "support": 15
    },
    {
      "x": -24,
      "y": -18,
      "z": 3,
      "name": "Soil_Grass"
    },
    {
      "x": -24,
      "y": -16,
      "z": 3,
      "name": "Rock_Stone"
    },
    {
      "x": -24,
      "y": -15,
      "z": 3,
      "name": "Rock_Stone"
    },
    {
      "x": -24,
      "y": -14,
      "z": 3,
      "name": "Rock_Stone"
    },
    {
      "x": -24,
      "y": -13,
      "z": 3,
      "name": "Rock_Stone"
    },
    {
      "x": -24,
      "y": -12,
      "z": 3,
      "name": "Rock_Stone"
    },
    {
      "x": -24,
      "y": -11,
      "z": 3,
      "name": "Rock_Stone_Mossy"
    },
    {
      "x": -24,
      "y": -10,
      "z": 3,
      "name": "Rock_Stone"
    },
    {
      "x": -24,
      "y": -9,
      "z": 3,
      "name": "Rock_Stone"
    },
    {
      "x": -24,
      "y": -8,
      "z": 3,
      "name": "Rock_Crystal_Purple_Block",
      "rotation": 5
    },
    {
      "x": -24,
      "y": -7,
      "z": 3,
      "name": "Rock_Stone"
    },
    {
      "x": -24,
      "y": -6,
      "z": 3,
      "name": "Rock_Stone"
    },
    {
      "x": -24,
      "y": -5,
      "z": 3,
      "name": "Rock_Stone"
    },
    {
      "x": -24,
      "y": -4,
      "z": 3,
      "name": "Rock_Stone"
    },
    {
      "x": -24,
      "y": -3,
      "z": 3,
      "name": "Rock_Stone"
    },
    {
      "x": -24,
      "y": -2,
      "z": 3,
      "name": "Rock_Stone"
    },
    {
      "x": -24,
      "y": -1,
      "z": 3,
      "name": "Rock_Crystal_Purple_Block",
      "rotation": 5
    },
    {
      "x": -24,
      "y": 0,
      "z": 3,
      "name": "Rock_Crystal_Purple_Block",
      "rotation": 5
    },
    {
      "x": -24,
      "y": 1,
      "z": 3,
      "name": "Rock_Stone"
    },
    {
      "x": -24,
      "y": 2,
      "z": 3,
      "name": "Rock_Stone_Mossy"
    },
    {
      "x": -24,
      "y": 3,
      "z": 3,
      "name": "Rock_Stone"
    },
    {
      "x": -24,
      "y": 4,
      "z": 3,
      "name": "Rock_Stone"
    },
    {
      "x": -24,
      "y": 5,
      "z": 3,
      "name": "Rock_Stone"
    },
    {
      "x": -24,
      "y": 6,
      "z": 3,
      "name": "Rock_Stone"
    },
    {
      "x": -24,
      "y": 7,
      "z": 3,
      "name": "Rock_Stone"
    },
    {
      "x": -24,
      "y": 8,
      "z": 3,
      "name": "Rock_Stone_Mossy"
    },
    {
      "x": -24,
      "y": 9,
      "z": 3,
      "name": "Rock_Stone"
    },
    {
      "x": -24,
      "y": 11,
      "z": 3,
      "name": "Rock_Crystal_Purple_Small",
      "rotation": 7
    },
    {
      "x": -24,
      "y": 12,
      "z": 3,
      "name": "Rock_Stone"
    },
    {
      "x": -24,
      "y": 13,
      "z": 3,
      "name": "Rock_Stone"
    },
    {
      "x": -24,
      "y": 14,
      "z": 3,
      "name": "Rock_Stone"
    },
    {
      "x": -24,
      "y": 15,
      "z": 3,
      "name": "Rock_Stone"
    },
    {
      "x": -24,
      "y": 16,
      "z": 3,
      "name": "Plant_Crop_Mushroom_Glowing_Purple"
    },
    {
      "x": -24,
      "y": -18,
      "z": 4,
      "name": "Soil_Grass"
    },
    {
      "x": -24,
      "y": -14,
      "z": 4,
      "name": "Rock_Stone"
    },
    {
      "x": -24,
      "y": -13,
      "z": 4,
      "name": "Rock_Stone"
    },
    {
      "x": -24,
      "y": -12,
      "z": 4,
      "name": "Rock_Stone"
    },
    {
      "x": -24,
      "y": -11,
      "z": 4,
      "name": "Rock_Stone"
    },
    {
      "x": -24,
      "y": -10,
      "z": 4,
      "name": "Rock_Stone"
    },
    {
      "x": -24,
      "y": -9,
      "z": 4,
      "name": "Rock_Stone"
    },
    {
      "x": -24,
      "y": -8,
      "z": 4,
      "name": "Rock_Crystal_Purple_Block",
      "rotation": 4
    },
    {
      "x": -24,
      "y": -7,
      "z": 4,
      "name": "Rock_Crystal_Purple_Block",
      "rotation": 4
    },
    {
      "x": -24,
      "y": -6,
      "z": 4,
      "name": "Rock_Stone"
    },
    {
      "x": -24,
      "y": -5,
      "z": 4,
      "name": "Rock_Stone"
    },
    {
      "x": -24,
      "y": -4,
      "z": 4,
      "name": "Rock_Stone"
    },
    {
      "x": -24,
      "y": -3,
      "z": 4,
      "name": "Rock_Stone"
    },
    {
      "x": -24,
      "y": -2,
      "z": 4,
      "name": "Rock_Stone"
    },
    {
      "x": -24,
      "y": -1,
      "z": 4,
      "name": "Rock_Stone"
    },
    {
      "x": -24,
      "y": 0,
      "z": 4,
      "name": "Rock_Crystal_Purple_Block",
      "rotation": 5
    },
    {
      "x": -24,
      "y": 1,
      "z": 4,
      "name": "Rock_Crystal_Purple_Block",
      "rotation": 4
    },
    {
      "x": -24,
      "y": 2,
      "z": 4,
      "name": "Rock_Stone"
    },
    {
      "x": -24,
      "y": 3,
      "z": 4,
      "name": "Rock_Stone"
    },
    {
      "x": -24,
      "y": 4,
      "z": 4,
      "name": "Rock_Stone"
    },
    {
      "x": -24,
      "y": 5,
      "z": 4,
      "name": "Rock_Stone"
    },
    {
      "x": -24,
      "y": 6,
      "z": 4,
      "name": "Rock_Stone"
    },
    {
      "x": -24,
      "y": 7,
      "z": 4,
      "name": "Rock_Stone"
    },
    {
      "x": -24,
      "y": 8,
      "z": 4,
      "name": "Rock_Stone"
    },
    {
      "x": -24,
      "y": 9,
      "z": 4,
      "name": "Rock_Stone_Mossy"
    },
    {
      "x": -24,
      "y": 10,
      "z": 4,
      "name": "Rock_Stone"
    },
    {
      "x": -24,
      "y": 11,
      "z": 4,
      "name": "Rock_Stone"
    },
    {
      "x": -24,
      "y": 12,
      "z": 4,
      "name": "Rock_Stone"
    },
    {
      "x": -24,
      "y": 13,
      "z": 4,
      "name": "Rock_Stone"
    },
    {
      "x": -24,
      "y": -18,
      "z": 5,
      "name": "Soil_Grass"
    },
    {
      "x": -24,
      "y": -9,
      "z": 5,
      "name": "Rock_Stone"
    },
    {
      "x": -24,
      "y": -8,
      "z": 5,
      "name": "Rock_Stone_Half"
    },
    {
      "x": -24,
      "y": -6,
      "z": 5,
      "name": "Rock_Stone"
    },
    {
      "x": -24,
      "y": -5,
      "z": 5,
      "name": "Rock_Stone"
    },
    {
      "x": -24,
      "y": -4,
      "z": 5,
      "name": "Rock_Stone"
    },
    {
      "x": -24,
      "y": -3,
      "z": 5,
      "name": "Rock_Stone"
    },
    {
      "x": -24,
      "y": -2,
      "z": 5,
      "name": "Rock_Stone"
    },
    {
      "x": -24,
      "y": -1,
      "z": 5,
      "name": "Rock_Stone_Mossy"
    },
    {
      "x": -24,
      "y": 0,
      "z": 5,
      "name": "Rock_Stone_Half"
    },
    {
      "x": -24,
      "y": 1,
      "z": 5,
      "name": "Rock_Stone_Half",
      "rotation": 8
    },
    {
      "x": -24,
      "y": 2,
      "z": 5,
      "name": "Rock_Stone"
    },
    {
      "x": -24,
      "y": 3,
      "z": 5,
      "name": "Rock_Stone"
    },
    {
      "x": -24,
      "y": 4,
      "z": 5,
      "name": "Rock_Stone"
    },
    {
      "x": -24,
      "y": 5,
      "z": 5,
      "name": "Rock_Stone"
    },
    {
      "x": -24,
      "y": 6,
      "z": 5,
      "name": "Rock_Stone"
    },
    {
      "x": -24,
      "y": 7,
      "z": 5,
      "name": "Rock_Stone"
    },
    {
      "x": -24,
      "y": 8,
      "z": 5,
      "name": "Rock_Stone"
    },
    {
      "x": -24,
      "y": 9,
      "z": 5,
      "name": "Rubble_Stone_Medium",
      "support": 15
    },
    {
      "x": -24,
      "y": -18,
      "z": 6,
      "name": "Soil_Grass"
    },
    {
      "x": -24,
      "y": -18,
      "z": 7,
      "name": "Soil_Grass"
    },
    {
      "x": -24,
      "y": -18,
      "z": 8,
      "name": "Soil_Grass"
    },
    {
      "x": -24,
      "y": -18,
      "z": 9,
      "name": "Soil_Grass"
    },
    {
      "x": -24,
      "y": -18,
      "z": 10,
      "name": "Soil_Grass"
    },
    {
      "x": -24,
      "y": -18,
      "z": 11,
      "name": "Soil_Grass"
    },
    {
      "x": -24,
      "y": -18,
      "z": 12,
      "name": "Soil_Grass"
    },
    {
      "x": -24,
      "y": -18,
      "z": 13,
      "name": "Soil_Grass"
    },
    {
      "x": -24,
      "y": -18,
      "z": 14,
      "name": "Soil_Grass"
    },
    {
      "x": -24,
      "y": -18,
      "z": 15,
      "name": "Soil_Grass"
    },
    {
      "x": -24,
      "y": -18,
      "z": 16,
      "name": "Soil_Grass"
    },
    {
      "x": -24,
      "y": -18,
      "z": 17,
      "name": "Soil_Grass"
    },
    {
      "x": -24,
      "y": -18,
      "z": 18,
      "name": "Soil_Grass"
    },
    {
      "x": -24,
      "y": -18,
      "z": 19,
      "name": "Soil_Grass"
    },
    {
      "x": -24,
      "y": -18,
      "z": 20,
      "name": "Soil_Grass"
    },
    {
      "x": -24,
      "y": -18,
      "z": 21,
      "name": "Soil_Grass"
    },
    {
      "x": -24,
      "y": -18,
      "z": 22,
      "name": "Soil_Grass"
    },
    {
      "x": -24,
      "y": -18,
      "z": 23,
      "name": "Soil_Grass"
    },
    {
      "x": -24,
      "y": -18,
      "z": 24,
      "name": "Soil_Grass"
    },
    {
      "x": -24,
      "y": -18,
      "z": 25,
      "name": "Soil_Grass"
    },
    {
      "x": -24,
      "y": -18,
      "z": 26,
      "name": "Soil_Grass"
    },
    {
      "x": -24,
      "y": -18,
      "z": 27,
      "name": "Soil_Grass"
    },
    {
      "x": -24,
      "y": -18,
      "z": 28,
      "name": "Soil_Grass"
    },
    {
      "x": -24,
      "y": -18,
      "z": 29,
      "name": "Soil_Grass"
    },
    {
      "x": -24,
      "y": -18,
      "z": 30,
      "name": "Soil_Grass"
    },
    {
      "x": -24,
      "y": -18,
      "z": 31,
      "name": "Soil_Grass"
    },
    {
      "x": -24,
      "y": -18,
      "z": 32,
      "name": "Soil_Grass"
    },
    {
      "x": -24,
      "y": -18,
      "z": 33,
      "name": "Soil_Grass"
    },
    {
      "x": -24,
      "y": -18,
      "z": 34,
      "name": "Soil_Grass"
    },
    {
      "x": -24,
      "y": -18,
      "z": 35,
      "name": "Soil_Grass"
    },
    {
      "x": -24,
      "y": -18,
      "z": 36,
      "name": "Soil_Grass"
    },
    {
      "x": -24,
      "y": -18,
      "z": 37,
      "name": "Soil_Grass"
    },
    {
      "x": -23,
      "y": -18,
      "z": -38,
      "name": "Soil_Grass"
    },
    {
      "x": -23,
      "y": -18,
      "z": -37,
      "name": "Soil_Grass"
    },
    {
      "x": -23,
      "y": -18,
      "z": -36,
      "name": "Soil_Grass"
    },
    {
      "x": -23,
      "y": -18,
      "z": -35,
      "name": "Soil_Grass"
    },
    {
      "x": -23,
      "y": -18,
      "z": -34,
      "name": "Soil_Grass"
    },
    {
      "x": -23,
      "y": -18,
      "z": -33,
      "name": "Soil_Grass"
    },
    {
      "x": -23,
      "y": -18,
      "z": -32,
      "name": "Soil_Grass"
    },
    {
      "x": -23,
      "y": -18,
      "z": -31,
      "name": "Soil_Grass"
    },
    {
      "x": -23,
      "y": -18,
      "z": -30,
      "name": "Soil_Grass"
    },
    {
      "x": -23,
      "y": -18,
      "z": -29,
      "name": "Soil_Grass"
    },
    {
      "x": -23,
      "y": -18,
      "z": -28,
      "name": "Soil_Grass"
    },
    {
      "x": -23,
      "y": -18,
      "z": -27,
      "name": "Soil_Grass"
    },
    {
      "x": -23,
      "y": -18,
      "z": -26,
      "name": "Soil_Grass"
    },
    {
      "x": -23,
      "y": -18,
      "z": -25,
      "name": "Soil_Grass"
    },
    {
      "x": -23,
      "y": -18,
      "z": -24,
      "name": "Soil_Grass"
    },
    {
      "x": -23,
      "y": -18,
      "z": -23,
      "name": "Soil_Grass"
    },
    {
      "x": -23,
      "y": -18,
      "z": -22,
      "name": "Soil_Grass"
    },
    {
      "x": -23,
      "y": -18,
      "z": -21,
      "name": "Soil_Grass"
    },
    {
      "x": -23,
      "y": -18,
      "z": -20,
      "name": "Soil_Grass"
    },
    {
      "x": -23,
      "y": -18,
      "z": -19,
      "name": "Soil_Grass"
    },
    {
      "x": -23,
      "y": -18,
      "z": -18,
      "name": "Soil_Grass"
    },
    {
      "x": -23,
      "y": -18,
      "z": -17,
      "name": "Soil_Grass"
    },
    {
      "x": -23,
      "y": -18,
      "z": -16,
      "name": "Soil_Grass"
    },
    {
      "x": -23,
      "y": -18,
      "z": -15,
      "name": "Soil_Grass"
    },
    {
      "x": -23,
      "y": -18,
      "z": -14,
      "name": "Soil_Grass"
    },
    {
      "x": -23,
      "y": -18,
      "z": -13,
      "name": "Soil_Grass"
    },
    {
      "x": -23,
      "y": -18,
      "z": -12,
      "name": "Soil_Grass"
    },
    {
      "x": -23,
      "y": -18,
      "z": -11,
      "name": "Soil_Grass"
    },
    {
      "x": -23,
      "y": -18,
      "z": -10,
      "name": "Soil_Grass"
    },
    {
      "x": -23,
      "y": -18,
      "z": -9,
      "name": "Soil_Grass"
    },
    {
      "x": -23,
      "y": -18,
      "z": -8,
      "name": "Soil_Grass"
    },
    {
      "x": -23,
      "y": -18,
      "z": -7,
      "name": "Soil_Grass"
    },
    {
      "x": -23,
      "y": -18,
      "z": -6,
      "name": "Soil_Grass"
    },
    {
      "x": -23,
      "y": -18,
      "z": -5,
      "name": "Soil_Grass"
    },
    {
      "x": -23,
      "y": -18,
      "z": -4,
      "name": "Soil_Grass"
    },
    {
      "x": -23,
      "y": -18,
      "z": -3,
      "name": "Soil_Grass"
    },
    {
      "x": -23,
      "y": -18,
      "z": -2,
      "name": "Soil_Grass"
    },
    {
      "x": -23,
      "y": -18,
      "z": -1,
      "name": "Soil_Grass"
    },
    {
      "x": -23,
      "y": -18,
      "z": 0,
      "name": "Soil_Grass"
    },
    {
      "x": -23,
      "y": -12,
      "z": 0,
      "name": "Rock_Stone"
    },
    {
      "x": -23,
      "y": -11,
      "z": 0,
      "name": "Rock_Stone"
    },
    {
      "x": -23,
      "y": -10,
      "z": 0,
      "name": "Rock_Stone"
    },
    {
      "x": -23,
      "y": -9,
      "z": 0,
      "name": "Rock_Crystal_Purple_Small",
      "rotation": 6
    },
    {
      "x": -23,
      "y": -8,
      "z": 0,
      "name": "Rock_Stone"
    },
    {
      "x": -23,
      "y": -7,
      "z": 0,
      "name": "Rock_Stone"
    },
    {
      "x": -23,
      "y": -6,
      "z": 0,
      "name": "Rock_Stone"
    },
    {
      "x": -23,
      "y": -5,
      "z": 0,
      "name": "Rock_Stone"
    },
    {
      "x": -23,
      "y": -4,
      "z": 0,
      "name": "Rock_Stone"
    },
    {
      "x": -23,
      "y": -3,
      "z": 0,
      "name": "Rock_Crystal_Purple_Small",
      "rotation": 6
    },
    {
      "x": -23,
      "y": -2,
      "z": 0,
      "name": "Rock_Stone"
    },
    {
      "x": -23,
      "y": -1,
      "z": 0,
      "name": "Rock_Stone"
    },
    {
      "x": -23,
      "y": 0,
      "z": 0,
      "name": "Rock_Stone"
    },
    {
      "x": -23,
      "y": 1,
      "z": 0,
      "name": "Rock_Stone"
    },
    {
      "x": -23,
      "y": 2,
      "z": 0,
      "name": "Rock_Stone"
    },
    {
      "x": -23,
      "y": 3,
      "z": 0,
      "name": "Rock_Stone"
    },
    {
      "x": -23,
      "y": 4,
      "z": 0,
      "name": "Rock_Stone"
    },
    {
      "x": -23,
      "y": 5,
      "z": 0,
      "name": "Rock_Stone"
    },
    {
      "x": -23,
      "y": 6,
      "z": 0,
      "name": "Rock_Crystal_Purple_Small",
      "rotation": 6
    },
    {
      "x": -23,
      "y": 8,
      "z": 0,
      "name": "Rock_Stone"
    },
    {
      "x": -23,
      "y": 9,
      "z": 0,
      "name": "Rock_Stone"
    },
    {
      "x": -23,
      "y": 10,
      "z": 0,
      "name": "Rock_Stone"
    },
    {
      "x": -23,
      "y": 11,
      "z": 0,
      "name": "Rock_Stone"
    },
    {
      "x": -23,
      "y": 12,
      "z": 0,
      "name": "Plant_Crop_Mushroom_Glowing_Purple"
    },
    {
      "x": -23,
      "y": -18,
      "z": 1,
      "name": "Soil_Grass"
    },
    {
      "x": -23,
      "y": -15,
      "z": 1,
      "name": "Rock_Stone"
    },
    {
      "x": -23,
      "y": -14,
      "z": 1,
      "name": "Rock_Stone"
    },
    {
      "x": -23,
      "y": -13,
      "z": 1,
      "name": "Rock_Stone"
    },
    {
      "x": -23,
      "y": -12,
      "z": 1,
