{
  "version": 8,
  "blockIdVersion": 11,
  "anchorX": 0,
  "anchorY": 0,
  "anchorZ": 0,
  "blocks": [
    {
      "x": -22,
      "y": -5,
      "z": -1,
      "name": "Rock_Stone"
    },
    {
      "x": -22,
      "y": -4,
      "z": -1,
      "name": "Rock_Stone"
    },
    {
      "x": -22,
      "y": -3,
      "z": -1,
      "name": "Rock_Stone"
    },
    {
      "x": -22,
      "y": -2,
      "z": -1,
      "name": "Rock_Stone"
    },
    {
      "x": -22,
      "y": -1,
      "z": -1,
      "name": "Rock_Stone"
    },
    {
      "x": -22,
      "y": 0,
      "z": -1,
      "name": "Rock_Stone_Half"
    },
    {
      "x": -22,
      "y": 2,
      "z": -1,
      "name": "Rock_Stone"
    },
    {
      "x": -22,
      "y": 3,
      "z": -1,
      "name": "Rock_Stone"
    },
    {
      "x": -22,
      "y": 4,
      "z": -1,
      "name": "Rock_Stone"
    },
    {
      "x": -22,
      "y": 5,
      "z": -1,
      "name": "Rock_Stone_Mossy"
    },
    {
      "x": -22,
      "y": 6,
      "z": -1,
      "name": "Rock_Stone"
    },
    {
      "x": -22,
      "y": 7,
      "z": -1,
      "name": "Rock_Stone_Mossy"
    },
    {
      "x": -22,
      "y": 8,
      "z": -1,
      "name": "Rock_Stone"
    },
    {
      "x": -22,
      "y": 9,
      "z": -1,
      "name": "Rock_Stone_Mossy"
    },
    {
      "x": -22,
      "y": -9,
      "z": 0,
      "name": "Rock_Stone_Mossy"
    },
    {
      "x": -22,
      "y": -8,
      "z": 0,
      "name": "Rock_Stone_Mossy"
    },
    {
      "x": -22,
      "y": -7,
      "z": 0,
      "name": "Rock_Stone"
    },
    {
      "x": -22,
      "y": -4,
      "z": 0,
      "name": "Rock_Stone"
    },
    {
      "x": -22,
      "y": -3,
      "z": 0,
      "name": "Rock_Stone"
    },
    {
      "x": -22,
      "y": -2,
      "z": 0,
      "name": "Rock_Stone"
    },
    {
      "x": -22,
      "y": -1,
      "z": 0,
      "name": "Rock_Stone"
    },
    {
      "x": -22,
      "y": 0,
      "z": 0,
      "name": "Rock_Stone"
    },
    {
      "x": -22,
      "y": 1,
      "z": 0,
      "name": "Rock_Crystal_Cyan_Small",
      "rotation": 7
    },
    {
      "x": -22,
      "y": 3,
      "z": 0,
      "name": "Rock_Stone"
    },
    {
      "x": -22,
      "y": 4,
      "z": 0,
      "name": "Rock_Stone"
    },
    {
      "x": -22,
      "y": 5,
      "z": 0,
      "name": "Rock_Stone_Mossy"
    },
    {
      "x": -22,
      "y": 6,
      "z": 0,
      "name": "Rock_Stone"
    },
    {
      "x": -22,
      "y": 7,
      "z": 0,
      "name": "Rock_Stone"
    },
    {
      "x": -22,
      "y": 8,
      "z": 0,
      "name": "Rock_Stone"
    },
    {
      "x": -22,
      "y": 9,
      "z": 0,
      "name": "Rock_Stone"
    },
    {
      "x": -22,
      "y": 10,
      "z": 0,
      "name": "Rock_Stone"
    },
    {
      "x": -22,
      "y": -9,
      "z": 1,
      "name": "Rock_Stone"
    },
    {
      "x": -22,
      "y": -8,
      "z": 1,
      "name": "Rock_Stone"
    },
    {
      "x": -22,
      "y": -7,
      "z": 1,
      "name": "Rock_Stone"
    },
    {
      "x": -22,
      "y": -6,
      "z": 1,
      "name": "Rock_Stone"
    },
    {
      "x": -22,
      "y": -4,
      "z": 1,
      "name": "Rock_Stone"
    },
    {
      "x": -22,
      "y": -3,
      "z": 1,
      "name": "Rock_Stone"
    },
    {
      "x": -22,
      "y": -2,
      "z": 1,
      "name": "Rock_Stone"
    },
    {
      "x": -22,
      "y": -1,
      "z": 1,
      "name": "Rock_Stone"
    },
    {
      "x": -22,
      "y": 0,
      "z": 1,
      "name": "Rock_Stone"
    },
    {
      "x": -22,
      "y": 1,
      "z": 1,
      "name": "Rock_Stone"
    },
    {
      "x": -22,
      "y": 3,
      "z": 1,
      "name": "Rock_Crystal_Cyan_Small",
      "rotation": 7
    },
    {
      "x": -22,
      "y": 4,
      "z": 1,
      "name": "Rock_Stone"
    },
    {
      "x": -22,
      "y": 5,
      "z": 1,
      "name": "Rock_Stone"
    },
    {
      "x": -22,
      "y": 6,
      "z": 1,
      "name": "Rock_Stone"
    },
    {
      "x": -22,
      "y": 7,
      "z": 1,
      "name": "Rock_Stone"
    },
    {
      "x": -22,
      "y": 8,
      "z": 1,
      "name": "Rock_Stone"
    },
    {
      "x": -22,
      "y": 9,
      "z": 1,
      "name": "Rock_Stone"
    },
    {
      "x": -22,
      "y": 10,
      "z": 1,
      "name": "Rock_Stone"
    },
    {
      "x": -22,
      "y": 11,
      "z": 1,
      "name": "Rock_Stone"
    },
    {
      "x": -22,
      "y": 12,
      "z": 1,
      "name": "Rock_Stone"
    },
    {
      "x": -22,
      "y": 13,
      "z": 1,
      "name": "Rubble_Stone_Mossy_Medium",
      "support": 15
    },
    {
      "x": -22,
      "y": -6,
      "z": 2,
      "name": "Rock_Stone"
    },
    {
      "x": -22,
      "y": -4,
      "z": 2,
      "name": "Rock_Stone"
    },
    {
      "x": -22,
      "y": -3,
      "z": 2,
      "name": "Rock_Stone"
    },
    {
      "x": -22,
      "y": -2,
      "z": 2,
      "name": "Rock_Stone"
    },
    {
      "x": -22,
      "y": -1,
      "z": 2,
      "name": "Rock_Stone"
    },
    {
      "x": -22,
      "y": 0,
      "z": 2,
      "name": "Rock_Stone"
    },
    {
      "x": -22,
      "y": 1,
      "z": 2,
      "name": "Rock_Stone"
    },
    {
      "x": -22,
      "y": 2,
      "z": 2,
      "name": "Rock_Stone"
    },
    {
      "x": -22,
      "y": 3,
      "z": 2,
      "name": "Rock_Stone_Half"
    },
    {
      "x": -22,
      "y": 4,
      "z": 2,
      "name": "Rock_Stone"
    },
    {
      "x": -22,
      "y": 5,
      "z": 2,
      "name": "Rock_Stone"
    },
    {
      "x": -22,
      "y": 6,
      "z": 2,
      "name": "Rock_Stone"
    },
    {
      "x": -22,
      "y": 7,
      "z": 2,
      "name": "Rock_Stone"
    },
    {
      "x": -22,
      "y": 8,
      "z": 2,
      "name": "Rock_Stone"
    },
    {
      "x": -22,
      "y": 9,
      "z": 2,
      "name": "Rock_Stone"
    },
    {
      "x": -22,
      "y": 10,
      "z": 2,
      "name": "Rock_Stone_Mossy"
    },
    {
      "x": -22,
      "y": 11,
      "z": 2,
      "name": "Rock_Stone"
    },
    {
      "x": -22,
      "y": 12,
      "z": 2,
      "name": "Rubble_Stone_Mossy_Medium",
      "support": 15
    },
    {
      "x": -21,
      "y": -5,
      "z": -2,
      "name": "Rock_Stone"
    },
    {
      "x": -21,
      "y": -4,
      "z": -2,
      "name": "Rock_Stone"
    },
    {
      "x": -21,
      "y": -3,
      "z": -2,
      "name": "Rock_Stone"
    },
    {
      "x": -21,
      "y": -2,
      "z": -2,
      "name": "Rock_Stone"
    },
    {
      "x": -21,
      "y": -1,
      "z": -2,
      "name": "Rock_Stone"
    },
    {
      "x": -21,
      "y": 0,
      "z": -2,
      "name": "Rock_Stone_Half"
    },
    {
      "x": -21,
      "y": 1,
      "z": -2,
      "name": "Rock_Stone"
    },
    {
      "x": -21,
      "y": 2,
      "z": -2,
      "name": "Rock_Stone"
    },
    {
      "x": -21,
      "y": 3,
      "z": -2,
      "name": "Rock_Stone"
    },
    {
      "x": -21,
      "y": 4,
      "z": -2,
      "name": "Rock_Stone"
    },
    {
      "x": -21,
      "y": 5,
      "z": -2,
      "name": "Rock_Stone"
    },
    {
      "x": -21,
      "y": 6,
      "z": -2,
      "name": "Rock_Stone"
    },
    {
      "x": -21,
      "y": 7,
      "z": -2,
      "name": "Rock_Stone"
    },
    {
      "x": -21,
      "y": 8,
      "z": -2,
      "name": "Rock_Stone"
    },
    {
      "x": -21,
      "y": 9,
      "z": -2,
      "name": "Rock_Stone"
    },
    {
      "x": -21,
      "y": 11,
      "z": -2,
      "name": "Rock_Stone"
    },
    {
      "x": -21,
      "y": 12,
      "z": -2,
      "name": "Rock_Stone"
    },
    {
      "x": -21,
      "y": 13,
      "z": -2,
      "name": "Rubble_Stone_Mossy_Medium",
      "support": 15
    },
    {
      "x": -21,
      "y": -11,
      "z": -1,
      "name": "Rock_Stone"
    },
    {
      "x": -21,
      "y": -10,
      "z": -1,
      "name": "Rock_Stone"
    },
    {
      "x": -21,
      "y": -9,
      "z": -1,
      "name": "Rock_Stone"
    },
    {
      "x": -21,
      "y": -8,
      "z": -1,
      "name": "Rock_Stone_Mossy"
    },
    {
      "x": -21,
      "y": -7,
      "z": -1,
      "name": "Rock_Stone_Mossy"
    },
    {
      "x": -21,
      "y": -6,
      "z": -1,
      "name": "Rock_Crystal_Cyan_Block",
      "rotation": 4
    },
    {
      "x": -21,
      "y": -5,
      "z": -1,
      "name": "Rock_Stone"
    },
    {
      "x": -21,
      "y": -4,
      "z": -1,
      "name": "Rock_Stone"
    },
    {
      "x": -21,
      "y": -3,
      "z": -1,
      "name": "Rock_Stone"
    },
    {
      "x": -21,
      "y": -2,
      "z": -1,
      "name": "Rock_Stone"
    },
    {
      "x": -21,
      "y": -1,
      "z": -1,
      "name": "Rock_Stone"
    },
    {
      "x": -21,
      "y": 0,
      "z": -1,
      "name": "Rock_Crystal_Cyan_Block",
      "rotation": 4
    },
    {
      "x": -21,
      "y": 1,
      "z": -1,
      "name": "Rock_Crystal_Cyan_Block",
      "rotation": 5
    },
    {
      "x": -21,
      "y": 2,
      "z": -1,
      "name": "Rock_Stone"
    },
    {
      "x": -21,
      "y": 3,
      "z": -1,
      "name": "Rock_Stone"
    },
    {
      "x": -21,
      "y": 4,
      "z": -1,
      "name": "Rock_Stone"
    },
    {
      "x": -21,
      "y": 5,
      "z": -1,
      "name": "Rock_Stone"
    },
    {
      "x": -21,
      "y": 6,
      "z": -1,
      "name": "Rock_Stone"
    },
    {
      "x": -21,
      "y": 7,
      "z": -1,
      "name": "Rock_Stone"
    },
    {
      "x": -21,
      "y": 8,
      "z": -1,
      "name": "Rock_Stone"
    },
    {
      "x": -21,
      "y": 9,
      "z": -1,
      "name": "Rock_Stone"
    },
    {
      "x": -21,
      "y": 12,
      "z": -1,
      "name": "Rock_Stone"
    },
    {
      "x": -21,
      "y": 13,
      "z": -1,
      "name": "Rock_Stone"
    },
    {
      "x": -21,
      "y": 14,
      "z": -1,
      "name": "Rock_Stone"
    },
    {
      "x": -21,
      "y": 15,
      "z": -1,
      "name": "Rock_Stone"
    },
    {
      "x": -21,
      "y": 16,
      "z": -1,
      "name": "Rock_Stone"
    },
    {
      "x": -21,
      "y": -12,
      "z": 0,
      "name": "Rock_Stone"
    },
    {
      "x": -21,
      "y": -11,
      "z": 0,
      "name": "Rock_Stone"
    },
    {
      "x": -21,
      "y": -10,
      "z": 0,
      "name": "Rock_Stone"
    },
    {
      "x": -21,
      "y": -9,
      "z": 0,
      "name": "Rock_Stone"
    },
    {
      "x": -21,
      "y": -8,
      "z": 0,
      "name": "Rock_Stone"
    },
    {
      "x": -21,
      "y": -7,
      "z": 0,
      "name": "Rock_Stone"
    },
    {
      "x": -21,
      "y": -6,
      "z": 0,
      "name": "Rock_Crystal_Cyan_Block",
      "rotation": 5
    },
    {
      "x": -21,
      "y": -5,
      "z": 0,
      "name": "Rock_Crystal_Cyan_Block",
      "rotation": 5
    },
    {
      "x": -21,
      "y": -4,
      "z": 0,
      "name": "Rock_Stone"
    },
    {
      "x": -21,
      "y": -3,
      "z": 0,
      "name": "Rock_Stone"
    },
    {
      "x": -21,
      "y": -2,
      "z": 0,
      "name": "Rock_Stone"
    },
    {
      "x": -21,
      "y": -1,
      "z": 0,
      "name": "Rock_Stone"
    },
    {
      "x": -21,
      "y": 0,
      "z": 0,
      "name": "Rock_Stone_Mossy"
    },
    {
      "x": -21,
      "y": 1,
      "z": 0,
      "name": "Rock_Crystal_Cyan_Block",
      "rotation": 5
    },
    {
      "x": -21,
      "y": 2,
      "z": 0,
      "name": "Rock_Crystal_Cyan_Block",
      "rotation": 5
    },
    {
      "x": -21,
      "y": 3,
      "z": 0,
      "name": "Rock_Stone_Mossy"
    },
    {
      "x": -21,
      "y": 4,
      "z": 0,
      "name": "Rock_Stone"
    },
    {
      "x": -21,
      "y": 5,
      "z": 0,
      "name": "Rock_Stone"
    },
    {
      "x": -21,
      "y": 6,
      "z": 0,
      "name": "Rock_Stone"
    },
    {
      "x": -21,
      "y": 7,
      "z": 0,
      "name": "Rock_Stone"
    },
    {
      "x": -21,
      "y": 8,
      "z": 0,
      "name": "Rock_Stone"
    },
    {
      "x": -21,
      "y": 9,
      "z": 0,
      "name": "Rock_Stone"
    },
    {
      "x": -21,
      "y": 10,
      "z": 0,
      "name": "Rock_Stone"
    },
    {
      "x": -21,
      "y": 13,
      "z": 0,
      "name": "Rock_Crystal_Cyan_Small",
      "rotation": 7
    },
    {
      "x": -21,
      "y": 14,
      "z": 0,
      "name": "Rock_Stone"
    },
    {
      "x": -21,
      "y": 15,
      "z": 0,
      "name": "Rock_Stone"
    },
    {
      "x": -21,
      "y": 16,
      "z": 0,
      "name": "Rock_Stone_Mossy"
    },
    {
      "x": -21,
      "y": 17,
      "z": 0,
      "name": "Rock_Stone"
    },
    {
      "x": -21,
      "y": 18,
      "z": 0,
      "name": "Rubble_Stone",
      "support": 15
    },
    {
      "x": -21,
      "y": -13,
      "z": 1,
      "name": "Rock_Stone"
    },
    {
      "x": -21,
      "y": -12,
      "z": 1,
      "name": "Rock_Stone"
    },
    {
      "x": -21,
      "y": -11,
      "z": 1,
      "name": "Rock_Stone"
    },
    {
      "x": -21,
      "y": -10,
      "z": 1,
      "name": "Rock_Stone"
    },
    {
      "x": -21,
      "y": -9,
      "z": 1,
      "name": "Rock_Stone"
    },
    {
      "x": -21,
      "y": -8,
      "z": 1,
      "name": "Rock_Stone_Mossy"
    },
    {
      "x": -21,
      "y": -7,
      "z": 1,
      "name": "Rock_Stone"
    },
    {
      "x": -21,
      "y": -6,
      "z": 1,
      "name": "Rock_Stone"
    },
    {
      "x": -21,
      "y": -5,
      "z": 1,
      "name": "Rock_Crystal_Cyan_Block",
      "rotation": 5
    },
    {
      "x": -21,
      "y": -4,
      "z": 1,
      "name": "Rock_Stone"
    },
    {
      "x": -21,
      "y": -3,
      "z": 1,
      "name": "Rock_Stone"
    },
    {
      "x": -21,
      "y": -2,
      "z": 1,
      "name": "Rock_Stone"
    },
    {
      "x": -21,
      "y": -1,
      "z": 1,
      "name": "Rock_Stone"
    },
    {
      "x": -21,
      "y": 0,
      "z": 1,
      "name": "Rock_Stone"
    },
    {
      "x": -21,
      "y": 1,
      "z": 1,
      "name": "Rock_Stone"
    },
    {
      "x": -21,
      "y": 2,
      "z": 1,
      "name": "Rock_Crystal_Cyan_Block",
      "rotation": 5
    },
    {
      "x": -21,
      "y": 3,
      "z": 1,
      "name": "Rock_Crystal_Cyan_Block",
      "rotation": 5
    },
    {
      "x": -21,
      "y": 4,
      "z": 1,
      "name": "Rock_Stone"
    },
    {
      "x": -21,
      "y": 5,
      "z": 1,
      "name": "Rock_Stone_Mossy"
    },
    {
      "x": -21,
      "y": 6,
      "z": 1,
      "name": "Rock_Stone"
    },
    {
      "x": -21,
      "y": 7,
      "z": 1,
      "name": "Rock_Stone"
    },
    {
      "x": -21,
      "y": 8,
      "z": 1,
      "name": "Rock_Stone"
    },
    {
      "x": -21,
      "y": 9,
      "z": 1,
      "name": "Rock_Stone"
    },
    {
      "x": -21,
      "y": 10,
      "z": 1,
      "name": "Rock_Stone"
    },
    {
      "x": -21,
      "y": 11,
      "z": 1,
      "name": "Rock_Stone_Mossy"
    },
    {
      "x": -21,
      "y": 12,
      "z": 1,
      "name": "Rock_Stone"
    },
    {
      "x": -21,
      "y": 14,
      "z": 1,
      "name": "Rock_Gem_Zephyr",
      "rotation": 7
    },
    {
      "x": -21,
      "y": 15,
      "z": 1,
      "name": "Rock_Stone"
    },
    {
      "x": -21,
      "y": 16,
      "z": 1,
      "name": "Rock_Stone"
    },
    {
      "x": -21,
      "y": 17,
      "z": 1,
      "name": "Rock_Stone"
    },
    {
      "x": -21,
      "y": 18,
      "z": 1,
      "name": "Rock_Stone"
    },
    {
      "x": -21,
      "y": -11,
      "z": 2,
      "name": "Rock_Stone"
    },
    {
      "x": -21,
      "y": -10,
      "z": 2,
      "name": "Rock_Stone"
    },
    {
      "x": -21,
      "y": -9,
      "z": 2,
      "name": "Rock_Stone"
    },
    {
      "x": -21,
      "y": -8,
      "z": 2,
      "name": "Rock_Stone"
    },
    {
      "x": -21,
      "y": -7,
      "z": 2,
      "name": "Rock_Stone"
    },
    {
      "x": -21,
      "y": -6,
      "z": 2,
      "name": "Rock_Stone"
    },
    {
      "x": -21,
      "y": -5,
      "z": 2,
      "name": "Rock_Crystal_Cyan_Block",
      "rotation": 4
    },
    {
      "x": -21,
      "y": -4,
      "z": 2,
      "name": "Rock_Crystal_Cyan_Block",
      "rotation": 4
    },
    {
      "x": -21,
      "y": -3,
      "z": 2,
      "name": "Rock_Stone"
    },
    {
      "x": -21,
      "y": -2,
      "z": 2,
      "name": "Rock_Stone"
    },
    {
      "x": -21,
      "y": -1,
      "z": 2,
      "name": "Rock_Stone"
    },
    {
      "x": -21,
      "y": 0,
      "z": 2,
      "name": "Rock_Stone"
    },
    {
      "x": -21,
      "y": 1,
      "z": 2,
      "name": "Rock_Stone"
    },
    {
      "x": -21,
      "y": 2,
      "z": 2,
      "name": "Rock_Stone"
    },
    {
      "x": -21,
      "y": 3,
      "z": 2,
      "name": "Rock_Crystal_Cyan_Block",
      "rotation": 5
    },
    {
      "x": -21,
      "y": 4,
      "z": 2,
      "name": "Rock_Crystal_Cyan_Block",
      "rotation": 4
    },
    {
      "x": -21,
      "y": 5,
      "z": 2,
      "name": "Rock_Stone"
    },
    {
      "x": -21,
      "y": 6,
      "z": 2,
      "name": "Rock_Stone"
    },
    {
      "x": -21,
      "y": 7,
      "z": 2,
      "name": "Rock_Stone"
    },
    {
      "x": -21,
      "y": 8,
      "z": 2,
      "name": "Rock_Stone"
    },
    {
      "x": -21,
      "y": 9,
      "z": 2,
      "name": "Rock_Stone"
    },
    {
      "x": -21,
      "y": 10,
      "z": 2,
      "name": "Rock_Stone"
    },
    {
      "x": -21,
      "y": 11,
      "z": 2,
      "name": "Rock_Stone"
    },
    {
      "x": -21,
      "y": 12,
      "z": 2,
      "name": "Rock_Stone_Mossy"
    },
    {
      "x": -21,
      "y": 13,
      "z": 2,
      "name": "Rock_Stone"
    },
    {
      "x": -21,
      "y": 14,
      "z": 2,
      "name": "Rock_Stone"
    },
    {
      "x": -21,
      "y": 15,
      "z": 2,
      "name": "Rock_Stone"
    },
    {
      "x": -21,
      "y": 16,
      "z": 2,
      "name": "Rock_Stone"
    },
    {
      "x": -21,
      "y": -6,
      "z": 3,
      "name": "Rock_Stone"
    },
    {
      "x": -21,
      "y": -5,
      "z": 3,
      "name": "Rock_Crystal_Cyan_Small",
      "rotation": 4
    },
    {
      "x": -21,
      "y": -3,
      "z": 3,
      "name": "Rock_Stone"
    },
    {
      "x": -21,
      "y": -2,
      "z": 3,
      "name": "Rock_Stone"
    },
    {
      "x": -21,
      "y": -1,
      "z": 3,
      "name": "Rock_Stone"
    },
    {
      "x": -21,
      "y": 0,
      "z": 3,
      "name": "Rock_Stone"
    },
    {
      "x": -21,
      "y": 1,
      "z": 3,
      "name": "Rock_Stone"
    },
    {
      "x": -21,
      "y": 2,
      "z": 3,
      "name": "Rock_Stone_Mossy"
    },
    {
      "x": -21,
      "y": 3,
      "z": 3,
      "name": "Rock_Stone_Half"
    },
    {
      "x": -21,
      "y": 5,
      "z": 3,
      "name": "Rock_Stone"
    },
    {
      "x": -21,
      "y": 6,
      "z": 3,
      "name": "Rock_Stone"
    },
    {
      "x": -21,
      "y": 7,
      "z": 3,
      "name": "Rock_Stone"
    },
    {
      "x": -21,
      "y": 8,
      "z": 3,
      "name": "Rock_Stone"
    },
    {
      "x": -21,
      "y": 9,
      "z": 3,
      "name": "Rock_Stone"
    },
    {
      "x": -21,
      "y": 10,
      "z": 3,
      "name": "Rock_Stone"
    },
    {
      "x": -21,
      "y": 11,
      "z": 3,
      "name": "Rock_Stone"
    },
    {
      "x": -20,
      "y": -5,
      "z": -2,
      "name": "Rock_Stone"
    },
    {
      "x": -20,
      "y": -4,
      "z": -2,
      "name": "Rock_Stone"
    },
    {
      "x": -20,
      "y": -3,
      "z": -2,
      "name": "Rock_Stone"
    },
    {
      "x": -20,
      "y": -2,
      "z": -2,
      "name": "Rock_Stone"
    },
    {
      "x": -20,
      "y": -1,
      "z": -2,
      "name": "Rock_Stone"
    },
    {
      "x": -20,
      "y": 1,
      "z": -2,
      "name": "Rock_Stone"
    },
    {
      "x": -20,
      "y": 2,
      "z": -2,
      "name": "Rock_Stone"
    },
    {
      "x": -20,
      "y": 3,
      "z": -2,
      "name": "Rock_Stone"
    },
    {
      "x": -20,
      "y": 4,
      "z": -2,
      "name": "Rock_Stone"
    },
    {
      "x": -20,
      "y": 5,
      "z": -2,
      "name": "Rock_Stone"
    },
    {
      "x": -20,
      "y": 6,
      "z": -2,
      "name": "Rock_Stone"
    },
    {
      "x": -20,
      "y": 7,
      "z": -2,
      "name": "Rock_Stone"
    },
    {
      "x": -20,
      "y": 8,
      "z": -2,
      "name": "Rock_Stone"
    },
    {
      "x": -20,
      "y": 10,
      "z": -2,
      "name": "Rock_Crystal_Cyan_Small",
      "rotation": 6
    },
    {
      "x": -20,
      "y": 11,
      "z": -2,
      "name": "Rock_Stone"
    },
    {
      "x": -20,
      "y": 12,
      "z": -2,
      "name": "Rock_Stone"
    },
    {
      "x": -20,
      "y": 13,
      "z": -2,
      "name": "Rock_Stone"
    },
    {
      "x": -20,
      "y": 14,
      "z": -2,
      "name": "Rock_Stone"
    },
    {
      "x": -20,
      "y": 15,
      "z": -2,
      "name": "Rubble_Stone",
      "support": 15
    },
    {
      "x": -20,
      "y": -12,
      "z": -1,
      "name": "Rock_Stone"
    },
    {
      "x": -20,
      "y": -6,
      "z": -1,
      "name": "Rock_Crystal_Cyan_Block",
      "rotation": 4
    },
    {
      "x": -20,
      "y": -5,
      "z": -1,
      "name": "Rock_Stone"
    },
    {
      "x": -20,
      "y": -4,
      "z": -1,
      "name": "Rock_Stone"
    },
    {
      "x": -20,
      "y": -3,
      "z": -1,
      "name": "Rock_Stone"
    },
    {
      "x": -20,
      "y": -2,
      "z": -1,
      "name": "Rock_Stone"
    },
    {
      "x": -20,
      "y": -1,
      "z": -1,
      "name": "Rock_Stone_Mossy"
    },
    {
      "x": -20,
      "y": 0,
      "z": -1,
      "name": "Rock_Crystal_Cyan_Block",
      "rotation": 4
    },
    {
      "x": -20,
      "y": 1,
      "z": -1,
      "name": "Rock_Stone_Mossy"
    },
    {
      "x": -20,
      "y": 2,
      "z": -1,
      "name": "Rock_Stone"
    },
    {
      "x": -20,
      "y": 3,
      "z": -1,
      "name": "Rock_Stone"
    },
    {
      "x": -20,
      "y": 4,
      "z": -1,
      "name": "Rock_Stone"
    },
    {
      "x": -20,
      "y": 5,
      "z": -1,
      "name": "Rock_Stone"
    },
    {
      "x": -20,
      "y": 6,
      "z": -1,
      "name": "Rock_Stone"
    },
    {
      "x": -20,
      "y": 7,
      "z": -1,
      "name": "Rock_Stone"
    },
    {
      "x": -20,
      "y": 8,
      "z": -1,
      "name": "Rock_Stone"
    },
    {
      "x": -20,
      "y": 9,
      "z": -1,
      "name": "Rock_Crystal_Cyan_Block",
      "rotation": 4
    },
    {
      "x": -20,
      "y": 10,
      "z": -1,
      "name": "Rock_Crystal_Cyan_Block",
      "rotation": 4
    },
    {
      "x": -20,
      "y": 11,
      "z": -1,
      "name": "Rock_Crystal_Cyan_Block",
      "rotation": 5
    },
    {
      "x": -20,
      "y": 12,
      "z": -1,
      "name": "Rock_Stone"
    },
    {
      "x": -20,
      "y": 13,
      "z": -1,
      "name": "Rock_Stone"
    },
    {
      "x": -20,
      "y": 14,
      "z": -1,
      "name": "Rock_Stone"
    },
    {
      "x": -20,
      "y": 15,
      "z": -1,
      "name": "Rock_Stone"
    },
    {
      "x": -20,
      "y": 16,
      "z": -1,
      "name": "Rock_Stone_Mossy"
    },
    {
      "x": -20,
      "y": 17,
      "z": -1,
      "name": "Rock_Stone"
    },
    {
      "x": -20,
      "y": 18,
      "z": -1,
      "name": "Rubble_Stone",
      "support": 15
    },
    {
      "x": -20,
      "y": -14,
      "z": 0,
      "name": "Rock_Stone"
    },
    {
      "x": -20,
      "y": -13,
      "z": 0,
      "name": "Rock_Stone"
    },
    {
      "x": -20,
      "y": -12,
      "z": 0,
      "name": "Rock_Stone"
    },
    {
      "x": -20,
      "y": -11,
      "z": 0,
      "name": "Rock_Crystal_Cyan_Block",
      "rotation": 4
    },
    {
      "x": -20,
      "y": -10,
      "z": 0,
      "name": "Rock_Crystal_Cyan_Block",
      "rotation": 4
    },
    {
      "x": -20,
      "y": -9,
      "z": 0,
      "name": "Rock_Crystal_Cyan_Block",
      "rotation": 4
    },
    {
      "x": -20,
      "y": -8,
      "z": 0,
      "name": "Rock_Crystal_Cyan_Block",
      "rotation": 4
    },
    {
      "x": -20,
      "y": -7,
      "z": 0,
      "name": "Rock_Crystal_Cyan_Block",
      "rotation": 4
    },
    {
      "x": -20,
      "y": -6,
      "z": 0,
      "name": "Rock_Stone"
    },
    {
      "x": -20,
      "y": -5,
      "z": 0,
      "name": "Rock_Stone"
    },
    {
      "x": -20,
      "y": -4,
      "z": 0,
      "name": "Rock_Stone"
    },
    {
      "x": -20,
      "y": -3,
      "z": 0,
      "name": "Rock_Stone"
    },
    {
      "x": -20,
      "y": -2,
      "z": 0,
      "name": "Rock_Stone"
    },
    {
      "x": -20,
      "y": -1,
      "z": 0,
      "name": "Rock_Stone"
    },
    {
      "x": -20,
      "y": 0,
      "z": 0,
      "name": "Rock_Stone"
    },
    {
      "x": -20,
      "y": 1,
      "z": 0,
      "name": "Rock_Stone"
    },
    {
      "x": -20,
      "y": 2,
      "z": 0,
      "name": "Rock_Stone"
    },
    {
      "x": -20,
      "y": 3,
      "z": 0,
      "name": "Rock_Stone"
    },
    {
      "x": -20,
      "y": 4,
      "z": 0,
      "name": "Rock_Stone"
    },
    {
      "x": -20,
      "y": 5,
      "z": 0,
      "name": "Rock_Stone"
    },
    {
      "x": -20,
      "y": 6,
      "z": 0,
      "name": "Rock_Stone"
    },
    {
      "x": -20,
      "y": 7,
      "z": 0,
      "name": "Rock_Stone"
    },
    {
      "x": -20,
      "y": 8,
      "z": 0,
      "name": "Rock_Stone"
    },
    {
      "x": -20,
      "y": 9,
      "z": 0,
      "name": "Rock_Stone"
    },
    {
      "x": -20,
      "y": 10,
      "z": 0,
      "name": "Rock_Stone_Mossy"
    },
    {
      "x": -20,
      "y": 11,
      "z": 0,
      "name": "Rock_Crystal_Cyan_Block",
      "rotation": 5
    },
    {
      "x": -20,
      "y": 12,
      "z": 0,
      "name": "Rock_Crystal_Cyan_Block",
      "rotation": 5
    },
    {
      "x": -20,
      "y": 13,
      "z": 0,
      "name": "Rock_Crystal_Cyan_Block",
      "rotation": 5
    },
    {
      "x": -20,
      "y": 14,
      "z": 0,
      "name": "Rock_Stone_Mossy"
    },
    {
      "x": -20,
      "y": 15,
      "z": 0,
      "name": "Rock_Stone"
    },
    {
      "x": -20,
      "y": 16,
      "z": 0,
      "name": "Rock_Stone"
    },
    {
      "x": -20,
      "y": 17,
      "z": 0,
      "name": "Rock_Stone"
    },
    {
      "x": -20,
      "y": 18,
      "z": 0,
      "name": "Rock_Stone"
    },
    {
      "x": -20,
      "y": 19,
      "z": 0,
      "name": "Rock_Stone"
    },
    {
      "x": -20,
      "y": 20,
      "z": 0,
      "name": "Rubble_Stone_Medium",
      "support": 15
    },
    {
      "x": -20,
      "y": -14,
      "z": 1,
      "name": "Rock_Stone"
    },
    {
      "x": -20,
      "y": -13,
      "z": 1,
      "name": "Rock_Stone"
    },
    {
      "x": -20,
      "y": -12,
      "z": 1,
      "name": "Rock_Stone_Mossy"
    },
    {
      "x": -20,
      "y": -11,
      "z": 1,
      "name": "Rock_Stone_Mossy"
    },
    {
      "x": -20,
      "y": -10,
      "z": 1,
      "name": "Rock_Stone"
    },
    {
      "x": -20,
      "y": -9,
      "z": 1,
      "name": "Rock_Stone"
    },
    {
      "x": -20,
      "y": -8,
      "z": 1,
      "name": "Rock_Stone"
    },
    {
      "x": -20,
      "y": -7,
      "z": 1,
      "name": "Rock_Stone"
    },
    {
      "x": -20,
      "y": -6,
      "z": 1,
      "name": "Rock_Stone"
    },
    {
      "x": -20,
      "y": -5,
      "z": 1,
      "name": "Rock_Stone"
    },
    {
      "x": -20,
      "y": -4,
      "z": 1,
      "name": "Rock_Stone"
    },
    {
      "x": -20,
      "y": -3,
      "z": 1,
      "name": "Rock_Stone"
    },
    {
      "x": -20,
      "y": -2,
      "z": 1,
      "name": "Rock_Stone"
    },
    {
      "x": -20,
      "y": -1,
      "z": 1,
      "name": "Rock_Stone_Mossy"
    },
    {
      "x": -20,
      "y": 0,
      "z": 1,
      "name": "Rock_Stone"
    },
    {
      "x": -20,
      "y": 1,
      "z": 1,
      "name": "Rock_Stone"
    },
    {
      "x": -20,
      "y": 2,
      "z": 1,
      "name": "Rock_Stone"
    },
    {
      "x": -20,
      "y": 3,
      "z": 1,
      "name": "Rock_Stone"
    },
    {
      "x": -20,
      "y": 4,
      "z": 1,
      "name": "Rock_Stone"
    },
    {
      "x": -20,
      "y": 5,
      "z": 1,
      "name": "Rock_Stone"
    },
    {
      "x": -20,
      "y": 6,
      "z": 1,
      "name": "Rock_Stone_Mossy"
    },
    {
      "x": -20,
      "y": 7,
      "z": 1,
      "name": "Rock_Stone"
    },
    {
      "x": -20,
      "y": 8,
      "z": 1,
      "name": "Rock_Stone"
    },
    {
      "x": -20,
      "y": 9,
      "z": 1,
      "name": "Rock_Stone"
    },
    {
      "x": -20,
      "y": 10,
      "z": 1,
      "name": "Rock_Stone"
    },
    {
      "x": -20,
      "y": 11,
      "z": 1,
      "name": "Rock_Stone"
    },
    {
      "x": -20,
      "y": 12,
      "z": 1,
      "name": "Rock_Stone"
    },
    {
      "x": -20,
      "y": 13,
      "z": 1,
      "name": "Rock_Crystal_Cyan_Block",
      "rotation": 5
    },
    {
      "x": -20,
      "y": 14,
      "z": 1,
      "name": "Rock_Crystal_Cyan_Block",
      "rotation": 5
    },
    {
      "x": -20,
      "y": 15,
      "z": 1,
      "name": "Rock_Stone"
    },
    {
      "x": -20,
      "y": 16,
      "z": 1,
      "name": "Rock_Stone"
    },
    {
      "x": -20,
      "y": 17,
      "z": 1,
      "name": "Rock_Stone_Mossy"
    },
    {
      "x": -20,
      "y": 18,
      "z": 1,
      "name": "Rock_Stone"
    },
    {
      "x": -20,
      "y": 19,
      "z": 1,
      "name": "Rock_Stone_Mossy"
    },
    {
      "x": -20,
      "y": -12,
      "z": 2,
      "name": "Rock_Stone"
    },
    {
      "x": -20,
      "y": -11,
      "z": 2,
      "name": "Rock_Stone"
    },
    {
      "x": -20,
      "y": -10,
      "z": 2,
      "name": "Rock_Stone"
    },
    {
      "x": -20,
      "y": -9,
      "z": 2,
      "name": "Rock_Stone"
    },
    {
      "x": -20,
      "y": -8,
      "z": 2,
      "name": "Rock_Stone"
    },
    {
      "x": -20,
      "y": -7,
      "z": 2,
      "name": "Rock_Stone"
    },
    {
      "x": -20,
      "y": -6,
      "z": 2,
      "name": "Rock_Stone"
    },
    {
      "x": -20,
      "y": -5,
      "z": 2,
      "name": "Rock_Stone_Mossy"
    },
    {
      "x": -20,
      "y": -4,
      "z": 2,
      "name": "Rock_Crystal_Cyan_Block",
      "rotation": 4
    },
    {
      "x": -20,
      "y": -3,
      "z": 2,
      "name": "Rock_Stone"
    },
    {
      "x": -20,
      "y": -2,
      "z": 2,
      "name": "Rock_Stone"
    },
    {
      "x": -20,
      "y": -1,
      "z": 2,
      "name": "Rock_Stone"
    },
    {
      "x": -20,
      "y": 0,
      "z": 2,
      "name": "Rock_Stone"
    },
    {
      "x": -20,
      "y": 1,
      "z": 2,
      "name": "Rock_Stone"
    },
    {
      "x": -20,
      "y": 2,
      "z": 2,
      "name": "Rock_Stone"
    },
    {
      "x": -20,
      "y": 3,
      "z": 2,
      "name": "Rock_Stone"
    },
    {
      "x": -20,
      "y": 4,
      "z": 2,
      "name": "Rock_Crystal_Cyan_Block",
      "rotation": 4
    },
    {
      "x": -20,
      "y": 5,
      "z": 2,
      "name": "Rock_Crystal_Cyan_Block",
      "rotation": 4
    },
    {
      "x": -20,
      "y": 6,
      "z": 2,
      "name": "Rock_Stone"
    },
    {
      "x": -20,
      "y": 7,
      "z": 2,
      "name": "Rock_Stone"
    },
    {
      "x": -20,
      "y": 8,
      "z": 2,
      "name": "Rock_Stone"
    },
    {
      "x": -20,
      "y": 9,
      "z": 2,
      "name": "Rock_Stone"
    },
    {
      "x": -20,
      "y": 10,
      "z": 2,
      "name": "Rock_Stone"
    },
    {
      "x": -20,
      "y": 11,
      "z": 2,
      "name": "Rock_Stone"
    },
    {
      "x": -20,
      "y": 12,
      "z": 2,
      "name": "Rock_Stone"
    },
    {
      "x": -20,
      "y": 13,
      "z": 2,
      "name": "Rock_Stone"
    },
    {
      "x": -20,
      "y": 14,
      "z": 2,
      "name": "Rock_Stone_Mossy"
    },
    {
      "x": -20,
      "y": 15,
      "z": 2,
      "name": "Rock_Stone"
    },
    {
      "x": -20,
      "y": 16,
      "z": 2,
      "name": "Rock_Stone_Mossy"
    },
    {
      "x": -20,
      "y": 17,
      "z": 2,
      "name": "Rock_Stone"
    },
    {
      "x": -20,
      "y": -9,
      "z": 3,
      "name": "Rock_Stone"
    },
    {
      "x": -20,
      "y": -8,
      "z": 3,
      "name": "Rock_Stone"
    },
    {
      "x": -20,
      "y": -7,
      "z": 3,
      "name": "Rock_Stone"
    },
    {
      "x": -20,
      "y": -6,
      "z": 3,
      "name": "Rock_Stone"
    },
    {
      "x": -20,
      "y": -5,
      "z": 3,
      "name": "Rock_Stone"
    },
    {
      "x": -20,
      "y": -3,
      "z": 3,
      "name": "Rock_Stone"
    },
    {
      "x": -20,
      "y": -2,
      "z": 3,
      "name": "Rock_Stone_Mossy"
    },
    {
      "x": -20,
      "y": -1,
      "z": 3,
      "name": "Rock_Stone_Mossy"
    },
    {
      "x": -20,
      "y": 0,
      "z": 3,
      "name": "Rock_Stone"
    },
    {
      "x": -20,
      "y": 1,
      "z": 3,
      "name": "Rock_Stone"
    },
    {
      "x": -20,
      "y": 2,
      "z": 3,
      "name": "Rock_Stone"
    },
    {
      "x": -20,
      "y": 3,
      "z": 3,
      "name": "Rock_Stone"
    },
    {
      "x": -20,
      "y": 6,
      "z": 3,
      "name": "Rock_Stone"
    },
    {
      "x": -20,
      "y": 7,
      "z": 3,
      "name": "Rock_Stone"
    },
    {
      "x": -20,
      "y": 8,
      "z": 3,
      "name": "Rock_Stone"
    },
    {
      "x": -20,
      "y": 9,
      "z": 3,
      "name": "Rock_Stone"
    },
    {
      "x": -20,
      "y": 10,
      "z": 3,
      "name": "Rock_Stone"
    },
    {
      "x": -20,
      "y": 11,
      "z": 3,
      "name": "Rock_Stone"
    },
    {
      "x": -20,
      "y": 12,
      "z": 3,
      "name": "Rock_Stone"
    },
    {
      "x": -20,
      "y": 13,
      "z": 3,
      "name": "Rock_Stone"
    },
    {
      "x": -20,
      "y": 14,
      "z": 3,
      "name": "Rock_Stone"
    },
    {
      "x": -19,
      "y": -9,
      "z": -2,
      "name": "Rock_Stone"
    },
    {
      "x": -19,
      "y": -8,
      "z": -2,
      "name": "Rock_Stone"
    },
    {
      "x": -19,
      "y": -7,
      "z": -2,
      "name": "Rock_Stone"
    },
    {
      "x": -19,
      "y": -6,
      "z": -2,
      "name": "Rock_Stone"
    },
    {
      "x": -19,
      "y": -5,
      "z": -2,
      "name": "Rock_Stone"
    },
    {
      "x": -19,
      "y": -4,
      "z": -2,
      "name": "Rock_Stone_Mossy"
    },
    {
      "x": -19,
      "y": -3,
      "z": -2,
      "name": "Rock_Stone_Mossy"
    },
    {
      "x": -19,
      "y": -2,
      "z": -2,
      "name": "Rock_Stone"
    },
    {
      "x": -19,
      "y": 0,
      "z": -2,
      "name": "Rock_Crystal_Cyan_Small",
      "rotation": 6
    },
    {
      "x": -19,
      "y": 1,
      "z": -2,
      "name": "Rock_Stone"
    },
    {
      "x": -19,
      "y": 2,
      "z": -2,
      "name": "Rock_Stone"
    },
    {
      "x": -19,
      "y": 3,
      "z": -2,
      "name": "Rock_Stone"
    },
    {
      "x": -19,
      "y": 4,
      "z": -2,
      "name": "Rock_Stone"
    },
    {
      "x": -19,
      "y": 5,
      "z": -2,
      "name": "Rock_Stone"
    },
    {
      "x": -19,
      "y": 6,
      "z": -2,
      "name": "Rock_Stone"
    },
    {
      "x": -19,
      "y": 7,
      "z": -2,
      "name": "Rock_Stone"
    },
    {
      "x": -19,
      "y": 8,
      "z": -2,
      "name": "Rock_Crystal_Cyan_Small",
      "rotation": 6
    },
    {
      "x": -19,
      "y": 10,
      "z": -2,
      "name": "Rock_Stone"
    },
    {
      "x": -19,
      "y": 11,
      "z": -2,
      "name": "Rock_Stone"
    },
    {
      "x": -19,
      "y": 12,
      "z": -2,
      "name": "Rock_Stone"
    },
    {
      "x": -19,
      "y": 13,
      "z": -2,
      "name": "Rock_Stone"
    },
    {
      "x": -19,
      "y": 14,
      "z": -2,
      "name": "Rock_Stone"
    },
    {
      "x": -19,
      "y": -12,
      "z": -1,
      "name": "Rock_Stone"
    },
    {
      "x": -19,
      "y": -11,
      "z": -1,
      "name": "Rock_Stone"
    },
    {
      "x": -19,
      "y": -10,
      "z": -1,
      "name": "Rock_Stone"
    },
    {
      "x": -19,
      "y": -9,
      "z": -1,
      "name": "Rock_Stone"
    },
    {
      "x": -19,
      "y": -8,
      "z": -1,
      "name": "Rock_Stone"
    },
    {
      "x": -19,
      "y": -7,
      "z": -1,
      "name": "Rock_Stone"
    },
    {
      "x": -19,
      "y": -6,
      "z": -1,
      "name": "Rock_Crystal_Cyan_Block",
      "rotation": 4
    },
    {
      "x": -19,
      "y": -5,
      "z": -1,
      "name": "Rock_Stone"
    },
    {
      "x": -19,
      "y": -4,
      "z": -1,
      "name": "Rock_Stone"
    },
    {
      "x": -19,
      "y": -3,
      "z": -1,
      "name": "Rock_Stone"
    },
    {
      "x": -19,
      "y": -2,
      "z": -1,
      "name": "Rock_Stone"
    },
    {
      "x": -19,
      "y": -1,
      "z": -1,
      "name": "Rock_Crystal_Cyan_Block",
      "rotation": 4
    },
    {
      "x": -19,
      "y": 0,
      "z": -1,
      "name": "Rock_Crystal_Cyan_Block",
      "rotation": 4
    },
    {
      "x": -19,
      "y": 1,
      "z": -1,
      "name": "Rock_Stone"
    },
    {
      "x": -19,
      "y": 2,
      "z": -1,
      "name": "Rock_Stone"
    },
    {
      "x": -19,
      "y": 3,
      "z": -1,
      "name": "Rock_Stone"
    },
    {
      "x": -19,
      "y": 4,
      "z": -1,
      "name": "Rock_Stone"
    },
    {
      "x": -19,
      "y": 5,
      "z": -1,
      "name": "Rock_Stone"
    },
    {
      "x": -19,
      "y": 6,
      "z": -1,
      "name": "Rock_Stone"
    },
    {
      "x": -19,
      "y": 7,
      "z": -1,
      "name": "Rock_Stone"
    },
    {
      "x": -19,
      "y": 8,
      "z": -1,
      "name": "Rock_Crystal_Cyan_Block",
      "rotation": 4
    },
    {
      "x": -19,
      "y": 9,
      "z": -1,
      "name": "Rock_Crystal_Cyan_Block",
      "rotation": 4
    },
    {
      "x": -19,
      "y": 10,
      "z": -1,
      "name": "Rock_Stone"
    },
    {
      "x": -19,
      "y": 11,
      "z": -1,
      "name": "Rock_Stone"
    },
    {
      "x": -19,
      "y": 12,
      "z": -1,
      "name": "Rock_Stone"
    },
    {
      "x": -19,
      "y": 13,
      "z": -1,
      "name": "Rock_Stone_Mossy"
    },
    {
      "x": -19,
      "y": 14,
      "z": -1,
      "name": "Rock_Stone"
    },
    {
      "x": -19,
      "y": 15,
      "z": -1,
      "name": "Rock_Stone_Mossy"
    },
    {
      "x": -19,
      "y": 16,
      "z": -1,
      "name": "Rock_Stone"
    },
    {
      "x": -19,
      "y": 17,
      "z": -1,
      "name": "Rock_Stone"
    },
    {
      "x": -19,
      "y": -14,
      "z": 0,
      "name": "Rock_Stone"
    },
    {
      "x": -19,
      "y": -13,
      "z": 0,
      "name": "Rock_Stone"
    },
    {
      "x": -19,
      "y": -12,
      "z": 0,
      "name": "Rock_Stone"
    },
    {
      "x": -19,
      "y": -11,
      "z": 0,
      "name": "Rock_Stone"
    },
    {
      "x": -19,
      "y": -10,
      "z": 0,
      "name": "Rock_Stone"
    },
    {
      "x": -19,
      "y": -9,
      "z": 0,
      "name": "Rock_Stone"
    },
    {
      "x": -19,
      "y": -8,
      "z": 0,
      "name": "Rock_Stone"
    },
    {
      "x": -19,
      "y": -7,
      "z": 0,
      "name": "Rock_Stone"
    },
    {
      "x": -19,
      "y": -6,
      "z": 0,
      "name": "Rock_Stone"
    },
    {
      "x": -19,
      "y": -5,
      "z": 0,
      "name": "Rock_Stone"
    },
    {
      "x": -19,
      "y": -4,
      "z": 0,
      "name": "Rock_Stone_Mossy"
    },
    {
      "x": -19,
      "y": -3,
      "z": 0,
      "name": "Rock_Stone"
    },
    {
      "x": -19,
      "y": -2,
      "z": 0,
      "name": "Rock_Stone"
    },
    {
      "x": -19,
      "y": -1,
      "z": 0,
      "name": "Rock_Stone"
    },
    {
      "x": -19,
      "y": 0,
      "z": 0,
      "name": "Rock_Stone_Mossy"
    },
    {
      "x": -19,
      "y": 1,
      "z": 0,
      "name": "Rock_Stone"
    },
    {
      "x": -19,
      "y": 2,
      "z": 0,
      "name": "Rock_Stone"
    },
    {
      "x": -19,
      "y": 3,
      "z": 0,
      "name": "Rock_Stone_Mossy"
    },
    {
      "x": -19,
      "y": 4,
      "z": 0,
      "name": "Rock_Stone"
    },
    {
      "x": -19,
      "y": 5,
      "z": 0,
      "name": "Rock_Stone"
    },
    {
      "x": -19,
      "y": 6,
      "z": 0,
      "name": "Rock_Stone"
    },
    {
      "x": -19,
      "y": 7,
      "z": 0,
      "name": "Rock_Stone"
    },
    {
      "x": -19,
      "y": 8,
      "z": 0,
      "name": "Rock_Stone_Mossy"
    },
    {
      "x": -19,
      "y": 9,
      "z": 0,
      "name": "Rock_Stone"
    },
    {
      "x": -19,
      "y": 10,
      "z": 0,
      "name": "Rock_Stone"
    },
    {
      "x": -19,
      "y": 11,
      "z": 0,
      "name": "Rock_Stone"
    },
    {
      "x": -19,
      "y": 12,
      "z": 0,
      "name": "Rock_Stone"
    },
    {
      "x": -19,
      "y": 13,
      "z": 0,
      "name": "Rock_Stone_Mossy"
    },
    {
      "x": -19,
      "y": 14,
      "z": 0,
      "name": "Rock_Stone"
    },
    {
      "x": -19,
      "y": 15,
      "z": 0,
      "name": "Rock_Stone"
    },
    {
      "x": -19,
      "y": 16,
      "z": 0,
      "name": "Rock_Stone_Mossy"
    },
    {
      "x": -19,
      "y": 17,
      "z": 0,
      "name": "Rock_Stone"
    },
    {
      "x": -19,
      "y": 18,
      "z": 0,
      "name": "Rock_Stone_Mossy"
    },
    {
      "x": -19,
      "y": 19,
      "z": 0,
      "name": "Rock_Stone"
    },
    {
      "x": -19,
      "y": -14,
      "z": 1,
      "name": "Rock_Stone"
    },
    {
      "x": -19,
      "y": -13,
      "z": 1,
      "name": "Rock_Stone_Mossy"
    },
    {
      "x": -19,
      "y": -12,
      "z": 1,
      "name": "Rock_Stone"
    },
    {
      "x": -19,
      "y": -11,
      "z": 1,
      "name": "Rock_Stone"
    },
    {
      "x": -19,
      "y": -10,
      "z": 1,
      "name": "Rock_Stone"
    },
    {
      "x": -19,
      "y": -9,
      "z": 1,
      "name": "Rock_Stone"
    },
    {
      "x": -19,
      "y": -8,
      "z": 1,
      "name": "Rock_Stone"
    },
    {
      "x": -19,
      "y": -7,
      "z": 1,
      "name": "Rock_Stone"
    },
    {
      "x": -19,
      "y": -6,
      "z": 1,
      "name": "Rock_Stone"
    },
    {
      "x": -19,
      "y": -5,
      "z": 1,
      "name": "Rock_Stone"
    },
    {
      "x": -19,
      "y": -4,
      "z": 1,
      "name": "Rock_Stone"
    },
    {
      "x": -19,
      "y": -3,
      "z": 1,
      "name": "Rock_Stone"
    },
    {
      "x": -19,
      "y": -2,
      "z": 1,
      "name": "Rock_Stone"
    },
    {
      "x": -19,
      "y": -1,
      "z": 1,
      "name": "Rock_Stone"
    },
    {
      "x": -19,
      "y": 0,
      "z": 1,
      "name": "Rock_Stone"
    },
    {
      "x": -19,
      "y": 1,
      "z": 1,
      "name": "Rock_Stone"
    },
    {
      "x": -19,
      "y": 2,
      "z": 1,
      "name": "Rock_Stone_Mossy"
    },
    {
      "x": -19,
      "y": 3,
      "z": 1,
      "name": "Rock_Stone"
    },
    {
      "x": -19,
      "y": 4,
      "z": 1,
      "name": "Rock_Stone"
    },
    {
      "x": -19,
      "y": 5,
      "z": 1,
      "name": "Rock_Stone"
    },
    {
      "x": -19,
      "y": 6,
      "z": 1,
      "name": "Rock_Stone"
    },
    {
      "x": -19,
      "y": 7,
      "z": 1,
      "name": "Rock_Stone"
    },
    {
      "x": -19,
      "y": 8,
      "z": 1,
      "name": "Rock_Stone"
    },
    {
      "x": -19,
      "y": 9,
      "z": 1,
      "name": "Rock_Stone"
    },
    {
      "x": -19,
      "y": 10,
      "z": 1,
      "name": "Rock_Stone_Mossy"
    },
    {
      "x": -19,
      "y": 11,
      "z": 1,
      "name": "Rock_Stone"
    },
    {
      "x": -19,
      "y": 12,
      "z": 1,
      "name": "Rock_Stone_Mossy"
    },
    {
      "x": -19,
      "y": 13,
      "z": 1,
      "name": "Rock_Stone"
    },
    {
      "x": -19,
      "y": 14,
      "z": 1,
      "name": "Rock_Stone"
    },
    {
      "x": -19,
      "y": 15,
      "z": 1,
      "name": "Rock_Stone"
    },
    {
      "x": -19,
      "y": 16,
      "z": 1,
      "name": "Rock_Stone"
    },
    {
      "x": -19,
      "y": 17,
      "z": 1,
      "name": "Rock_Stone_Mossy"
    },
    {
      "x": -19,
      "y": 18,
      "z": 1,
      "name": "Rock_Stone"
    },
    {
      "x": -19,
      "y": 19,
      "z": 1,
      "name": "Rock_Stone_Mossy"
    },
    {
      "x": -19,
      "y": 20,
      "z": 1,
      "name": "Rubble_Stone_Medium",
      "support": 15
    },
    {
      "x": -19,
      "y": -12,
      "z": 2,
      "name": "Rock_Stone_Mossy"
    },
    {
      "x": -19,
      "y": -11,
      "z": 2,
      "name": "Rock_Stone"
    },
    {
      "x": -19,
      "y": -10,
      "z": 2,
      "name": "Rock_Stone"
    },
    {
      "x": -19,
      "y": -9,
      "z": 2,
      "name": "Rock_Stone"
    },
    {
      "x": -19,
      "y": -8,
      "z": 2,
      "name": "Rock_Stone"
    },
    {
      "x": -19,
      "y": -7,
      "z": 2,
      "name": "Rock_Stone"
    },
    {
      "x": -19,
      "y": -6,
      "z": 2,
      "name": "Rock_Stone"
    },
    {
      "x": -19,
      "y": -5,
      "z": 2,
      "name": "Rock_Stone"
    },
    {
      "x": -19,
      "y": -4,
      "z": 2,
      "name": "Rock_Crystal_Cyan_Block",
      "rotation": 4
    },
    {
      "x": -19,
      "y": -3,
      "z": 2,
      "name": "Rock_Crystal_Cyan_Block",
      "rotation": 4
    },
    {
      "x": -19,
      "y": -2,
      "z": 2,
      "name": "Rock_Stone"
    },
    {
      "x": -19,
      "y": -1,
      "z": 2,
      "name": "Rock_Stone_Mossy"
    },
    {
      "x": -19,
      "y": 0,
      "z": 2,
      "name": "Rock_Stone_Mossy"
    },
    {
      "x": -19,
      "y": 1,
      "z": 2,
      "name": "Rock_Stone"
    },
    {
      "x": -19,
      "y": 2,
      "z": 2,
      "name": "Rock_Stone_Mossy"
    },
    {
      "x": -19,
      "y": 3,
      "z": 2,
      "name": "Rock_Stone"
    },
    {
      "x": -19,
      "y": 4,
      "z": 2,
      "name": "Rock_Stone"
    },
    {
      "x": -19,
      "y": 5,
      "z": 2,
      "name": "Rock_Crystal_Cyan_Block",
      "rotation": 4
    },
    {
      "x": -19,
      "y": 6,
      "z": 2,
      "name": "Rock_Stone"
    },
    {
      "x": -19,
      "y": 7,
      "z": 2,
      "name": "Rock_Stone"
    },
    {
      "x": -19,
      "y": 8,
      "z": 2,
      "name": "Rock_Stone"
    },
    {
      "x": -19,
      "y": 9,
      "z": 2,
      "name": "Rock_Stone"
    },
    {
      "x": -19,
      "y": 10,
      "z": 2,
      "name": "Rock_Stone"
    },
    {
      "x": -19,
      "y": 11,
      "z": 2,
      "name": "Rock_Stone"
    },
    {
      "x": -19,
      "y": 12,
      "z": 2,
      "name": "Rock_Stone"
    },
    {
      "x": -19,
      "y": 13,
      "z": 2,
      "name": "Rock_Stone"
    },
    {
      "x": -19,
      "y": 14,
      "z": 2,
      "name": "Rock_Stone"
    },
    {
      "x": -19,
      "y": 15,
      "z": 2,
      "name": "Rock_Stone"
    },
    {
      "x": -19,
      "y": 16,
      "z": 2,
      "name": "Rock_Stone"
    },
    {
      "x": -19,
      "y": 17,
      "z": 2,
      "name": "Rock_Stone"
    },
    {
      "x": -19,
      "y": -9,
      "z": 3,
      "name": "Rock_Stone"
    },
    {
      "x": -19,
      "y": -8,
      "z": 3,
      "name": "Rock_Stone_Mossy"
    },
    {
      "x": -19,
      "y": -7,
      "z": 3,
      "name": "Rock_Stone"
    },
    {
      "x": -19,
      "y": -6,
      "z": 3,
      "name": "Rock_Stone"
    },
    {
      "x": -19,
      "y": -5,
      "z": 3,
      "name": "Rock_Stone_Mossy"
    },
    {
      "x": -19,
      "y": -4,
      "z": 3,
      "name": "Rock_Crystal_Cyan_Small",
      "rotation": 4
    },
    {
      "x": -19,
      "y": -2,
      "z": 3,
      "name": "Rock_Stone"
    },
    {
      "x": -19,
      "y": -1,
      "z": 3,
      "name": "Rock_Stone"
    },
    {
      "x": -19,
      "y": 0,
      "z": 3,
      "name": "Rock_Stone"
    },
    {
      "x": -19,
      "y": 1,
      "z": 3,
      "name": "Rock_Stone"
    },
    {
      "x": -19,
      "y": 2,
      "z": 3,
      "name": "Rock_Stone"
    },
    {
      "x": -19,
      "y": 3,
      "z": 3,
      "name": "Rock_Stone"
    },
    {
      "x": -19,
      "y": 4,
      "z": 3,
      "name": "Rock_Stone"
    },
    {
      "x": -19,
      "y": 5,
      "z": 3,
      "name": "Rock_Crystal_Cyan_Small",
      "rotation": 4
    },
    {
      "x": -19,
      "y": 6,
      "z": 3,
      "name": "Rock_Stone"
    },
    {
      "x": -19,
      "y": 7,
      "z": 3,
      "name": "Rock_Stone"
    },
    {
      "x": -19,
      "y": 8,
      "z": 3,
      "name": "Rock_Stone"
    },
    {
      "x": -19,
      "y": 9,
      "z": 3,
      "name": "Rock_Stone"
    },
    {
      "x": -19,
      "y": 10,
      "z": 3,
      "name": "Rock_Stone"
    },
    {
      "x": -19,
      "y": 11,
      "z": 3,
      "name": "Rock_Stone"
    },
    {
      "x": -19,
      "y": 12,
      "z": 3,
      "name": "Rock_Stone"
    },
    {
      "x": -19,
      "y": 13,
      "z": 3,
      "name": "Rock_Stone"
    },
    {
      "x": -19,
      "y": 14,
      "z": 3,
      "name": "Rock_Stone"
    },
    {
      "x": -18,
      "y": -6,
      "z": -2,
      "name": "Rock_Stone"
    },
    {
      "x": -18,
      "y": -5,
      "z": -2,
      "name": "Rock_Stone"
    },
    {
      "x": -18,
      "y": -4,
      "z": -2,
      "name": "Rock_Stone"
    },
    {
      "x": -18,
      "y": -3,
      "z": -2,
      "name": "Rock_Stone"
    },
    {
      "x": -18,
      "y": -2,
      "z": -2,
      "name": "Rock_Stone_Half"
    },
    {
      "x": -18,
      "y": 0,
      "z": -2,
      "name": "Rock_Stone"
    },
    {
      "x": -18,
      "y": 1,
      "z": -2,
      "name": "Rock_Stone"
    },
    {
      "x": -18,
      "y": 2,
      "z": -2,
      "name": "Rock_Stone_Mossy"
    },
    {
      "x": -18,
      "y": 3,
      "z": -2,
      "name": "Rock_Stone"
    },
    {
      "x": -18,
      "y": 4,
      "z": -2,
      "name": "Rock_Stone"
    },
    {
      "x": -18,
      "y": 5,
      "z": -2,
      "name": "Rock_Stone"
    },
    {
      "x": -18,
      "y": 6,
      "z": -2,
      "name": "Rock_Stone_Mossy"
    },
    {
      "x": -18,
      "y": 9,
      "z": -2,
      "name": "Rock_Stone"
    },
    {
      "x": -18,
      "y": 10,
      "z": -2,
      "name": "Rock_Stone"
    },
    {
      "x": -18,
      "y": 11,
      "z": -2,
      "name": "Rock_Stone"
    },
    {
      "x": -18,
      "y": 12,
      "z": -2,
      "name": "Rock_Stone_Half"
    },
    {
      "x": -18,
      "y": -11,
      "z": -1,
      "name": "Rock_Stone"
    },
    {
      "x": -18,
      "y": -10,
      "z": -1,
      "name": "Rock_Stone"
    },
    {
      "x": -18,
      "y": -9,
      "z": -1,
      "name": "Rock_Stone"
    },
    {
      "x": -18,
      "y": -8,
      "z": -1,
      "name": "Rock_Stone"
    },
    {
      "x": -18,
      "y": -7,
      "z": -1,
      "name": "Rock_Stone"
    },
    {
      "x": -18,
      "y": -6,
      "z": -1,
      "name": "Rock_Stone"
    },
    {
      "x": -18,
      "y": -5,
      "z": -1,
      "name": "Rock_Stone"
    },
    {
      "x": -18,
      "y": -4,
      "z": -1,
      "name": "Rock_Stone"
    },
    {
      "x": -18,
      "y": -3,
      "z": -1,
      "name": "Rock_Stone"
    },
    {
      "x": -18,
      "y": -2,
      "z": -1,
      "name": "Rock_Crystal_Cyan_Block",
      "rotation": 5
    },
    {
      "x": -18,
      "y": -1,
      "z": -1,
      "name": "Rock_Crystal_Cyan_Block",
      "rotation": 4
    },
    {
      "x": -18,
      "y": 0,
      "z": -1,
      "name": "Rock_Stone"
    },
    {
      "x": -18,
      "y": 1,
      "z": -1,
      "name": "Rock_Stone"
    },
    {
      "x": -18,
      "y": 2,
      "z": -1,
      "name": "Rock_Stone"
    },
    {
      "x": -18,
      "y": 3,
      "z": -1,
      "name": "Rock_Stone"
    },
    {
      "x": -18,
      "y": 4,
      "z": -1,
      "name": "Rock_Stone"
    },
    {
      "x": -18,
      "y": 5,
      "z": -1,
      "name": "Rock_Stone_Mossy"
    },
    {
      "x": -18,
      "y": 6,
      "z": -1,
      "name": "Rock_Stone_Mossy"
    },
    {
      "x": -18,
      "y": 7,
      "z": -1,
      "name": "Rock_Crystal_Cyan_Block",
      "rotation": 5
    },
    {
      "x": -18,
      "y": 8,
      "z": -1,
      "name": "Rock_Crystal_Cyan_Block",
      "rotation": 4
    },
    {
      "x": -18,
      "y": 9,
      "z": -1,
      "name": "Rock_Stone"
    },
    {
      "x": -18,
      "y": 10,
      "z": -1,
      "name": "Rock_Stone_Mossy"
    },
    {
      "x": -18,
      "y": 11,
      "z": -1,
      "name": "Rock_Stone_Mossy"
    },
    {
      "x": -18,
      "y": 12,
      "z": -1,
      "name": "Rock_Stone"
    },
    {
      "x": -18,
      "y": 13,
      "z": -1,
      "name": "Rock_Stone"
    },
    {
      "x": -18,
      "y": 14,
      "z": -1,
      "name": "Rock_Stone"
    },
    {
      "x": -18,
      "y": 15,
      "z": -1,
      "name": "Rock_Stone"
    },
    {
      "x": -18,
      "y": 16,
      "z": -1,
      "name": "Rock_Stone"
    },
    {
      "x": -18,
      "y": 17,
      "z": -1,
      "name": "Plant_Moss_Rug_Blue",
      "support": 15
    },
    {
      "x": -18,
      "y": -12,
      "z": 0,
      "name": "Rock_Stone"
    },
    {
      "x": -18,
      "y": -11,
      "z": 0,
      "name": "Rock_Stone"
    },
    {
      "x": -18,
      "y": -10,
      "z": 0,
      "name": "Rock_Stone"
    },
    {
      "x": -18,
      "y": -9,
      "z": 0,
      "name": "Rock_Stone"
    },
    {
      "x": -18,
      "y": -8,
      "z": 0,
      "name": "Rock_Stone"
    },
    {
      "x": -18,
      "y": -7,
      "z": 0,
      "name": "Rock_Stone"
    },
    {
      "x": -18,
      "y": -6,
      "z": 0,
      "name": "Rock_Stone"
    },
    {
      "x": -18,
      "y": -5,
      "z": 0,
      "name": "Rock_Stone"
    },
    {
      "x": -18,
      "y": -4,
      "z": 0,
      "name": "Rock_Stone"
    },
    {
      "x": -18,
      "y": -3,
      "z": 0,
      "name": "Rock_Stone_Mossy"
    },
    {
      "x": -18,
      "y": -2,
      "z": 0,
      "name": "Rock_Crystal_Cyan_Block",
      "rotation": 5
    },
    {
      "x": -18,
      "y": -1,
      "z": 0,
      "name": "Rock_Stone"
    },
    {
      "x": -18,
      "y": 0,
      "z": 0,
      "name": "Rock_Stone"
    },
    {
      "x": -18,
      "y": 1,
      "z": 0,
      "name": "Rock_Stone_Mossy"
    },
    {
      "x": -18,
      "y": 2,
      "z": 0,
      "name": "Rock_Stone"
    },
    {
      "x": -18,
      "y": 3,
      "z": 0,
      "name": "Rock_Stone"
    },
    {
      "x": -18,
      "y": 4,
      "z": 0,
      "name": "Rock_Stone"
    },
    {
      "x": -18,
      "y": 5,
      "z": 0,
      "name": "Rock_Stone"
    },
    {
      "x": -18,
      "y": 6,
      "z": 0,
      "name": "Rock_Crystal_Cyan_Block",
      "rotation": 5
    },
    {
      "x": -18,
      "y": 7,
      "z": 0,
      "name": "Rock_Crystal_Cyan_Block",
      "rotation": 5
    },
    {
      "x": -18,
      "y": 8,
      "z": 0,
      "name": "Rock_Stone_Mossy"
    },
    {
      "x": -18,
      "y": 9,
      "z": 0,
      "name": "Rock_Stone_Mossy"
    },
    {
      "x": -18,
      "y": 10,
      "z": 0,
      "name": "Rock_Stone"
    },
    {
      "x": -18,
      "y": 11,
      "z": 0,
      "name": "Rock_Stone"
    },
    {
      "x": -18,
      "y": 12,
      "z": 0,
      "name": "Rock_Stone"
    },
    {
      "x": -18,
      "y": 13,
      "z": 0,
      "name": "Rock_Stone"
    },
    {
      "x": -18,
      "y": 14,
      "z": 0,
      "name": "Rock_Stone"
    },
    {
      "x": -18,
      "y": 15,
      "z": 0,
      "name": "Rock_Stone"
    },
    {
      "x": -18,
      "y": 16,
      "z": 0,
      "name": "Rock_Stone"
    },
    {
      "x": -18,
      "y": 17,
      "z": 0,
      "name": "Rock_Stone"
    },
    {
      "x": -18,
      "y": 18,
      "z": 0,
      "name": "Plant_Moss_Rug_Blue",
      "support": 15
    },
    {
      "x": -18,
      "y": -13,
      "z": 1,
      "name": "Rock_Stone"
    },
    {
      "x": -18,
      "y": -12,
      "z": 1,
      "name": "Rock_Stone"
    },
    {
      "x": -18,
      "y": -11,
      "z": 1,
      "name": "Rock_Stone"
    },
    {
      "x": -18,
      "y": -10,
      "z": 1,
      "name": "Rock_Stone"
    },
    {
      "x": -18,
      "y": -9,
      "z": 1,
      "name": "Rock_Stone"
    },
    {
      "x": -18,
      "y": -8,
      "z": 1,
      "name": "Rock_Stone"
    },
    {
      "x": -18,
      "y": -7,
      "z": 1,
      "name": "Rock_Stone"
    },
    {
      "x": -18,
      "y": -6,
      "z": 1,
      "name": "Rock_Stone"
    },
    {
      "x": -18,
      "y": -5,
      "z": 1,
      "name": "Rock_Stone"
    },
    {
      "x": -18,
      "y": -4,
      "z": 1,
      "name": "Rock_Stone"
    },
    {
      "x": -18,
      "y": -3,
      "z": 1,
      "name": "Rock_Stone"
    },
    {
      "x": -18,
      "y": -2,
      "z": 1,
      "name": "Rock_Crystal_Cyan_Block",
      "rotation": 5
    },
    {
      "x": -18,
      "y": -1,
      "z": 1,
      "name": "Rock_Stone"
    },
    {
      "x": -18,
      "y": 0,
      "z": 1,
      "name": "Rock_Stone"
    },
    {
      "x": -18,
      "y": 1,
      "z": 1,
      "name": "Rock_Stone_Mossy"
    },
    {
      "x": -18,
      "y": 2,
      "z": 1,
      "name": "Rock_Stone"
    },
    {
      "x": -18,
      "y": 3,
      "z": 1,
      "name": "Rock_Stone_Mossy"
    },
    {
      "x": -18,
      "y": 4,
      "z": 1,
      "name": "Rock_Stone_Mossy"
    },
    {
      "x": -18,
      "y": 5,
      "z": 1,
      "name": "Rock_Stone"
    },
    {
      "x": -18,
      "y": 6,
      "z": 1,
      "name": "Rock_Crystal_Cyan_Block",
      "rotation": 5
    },
    {
      "x": -18,
      "y": 7,
      "z": 1,
      "name": "Rock_Stone"
    },
    {
      "x": -18,
      "y": 8,
      "z": 1,
      "name": "Rock_Stone"
    },
    {
      "x": -18,
      "y": 9,
      "z": 1,
      "name": "Rock_Stone"
    },
    {
      "x": -18,
      "y": 10,
      "z": 1,
      "name": "Rock_Stone"
    },
    {
      "x": -18,
      "y": 11,
      "z": 1,
      "name": "Rock_Stone"
    },
    {
      "x": -18,
      "y": 12,
      "z": 1,
      "name": "Rock_Stone_Mossy"
    },
    {
      "x": -18,
      "y": 13,
      "z": 1,
      "name": "Rock_Stone"
    },
    {
      "x": -18,
      "y": 14,
      "z": 1,
      "name": "Rock_Stone"
    },
    {
      "x": -18,
      "y": 15,
      "z": 1,
      "name": "Rock_Stone"
    },
    {
      "x": -18,
      "y": 16,
      "z": 1,
      "name": "Rock_Stone"
    },
    {
      "x": -18,
      "y": 17,
      "z": 1,
      "name": "Rock_Stone_Mossy"
    },
    {
      "x": -18,
      "y": 18,
      "z": 1,
      "name": "Rock_Stone"
    },
    {
      "x": -18,
      "y": 19,
      "z": 1,
      "name": "Plant_Moss_Rug_Blue",
      "support": 15
    },
    {
      "x": -18,
      "y": -11,
      "z": 2,
      "name": "Rock_Stone"
    },
    {
      "x": -18,
      "y": -10,
      "z": 2,
      "name": "Rock_Stone"
    },
    {
      "x": -18,
      "y": -9,
      "z": 2,
      "name": "Rock_Stone"
    },
    {
      "x": -18,
      "y": -8,
      "z": 2,
      "name": "Rock_Stone"
    },
    {
      "x": -18,
      "y": -7,
      "z": 2,
      "name": "Rock_Stone"
    },
    {
      "x": -18,
      "y": -6,
      "z": 2,
      "name": "Rock_Stone"
    },
    {
      "x": -18,
      "y": -5,
      "z": 2,
      "name": "Rock_Stone"
    },
    {
      "x": -18,
      "y": -4,
      "z": 2,
      "name": "Rock_Stone"
    },
    {
      "x": -18,
      "y": -3,
      "z": 2,
      "name": "Rock_Crystal_Cyan_Block",
      "rotation": 4
    },
    {
      "x": -18,
      "y": -2,
      "z": 2,
      "name": "Rock_Crystal_Cyan_Block",
      "rotation": 5
    },
    {
      "x": -18,
      "y": -1,
      "z": 2,
      "name": "Rock_Stone"
    },
    {
      "x": -18,
      "y": 0,
      "z": 2,
      "name": "Rock_Stone"
    },
    {
      "x": -18,
      "y": 1,
      "z": 2,
      "name": "Rock_Stone"
    },
    {
      "x": -18,
      "y": 2,
      "z": 2,
      "name": "Rock_Stone_Mossy"
    },
    {
      "x": -18,
      "y": 3,
      "z": 2,
      "name": "Rock_Stone"
    },
    {
      "x": -18,
      "y": 4,
      "z": 2,
      "name": "Rock_Stone"
    },
    {
      "x": -18,
      "y": 5,
      "z": 2,
      "name": "Rock_Crystal_Cyan_Block",
      "rotation": 4
    },
    {
      "x": -18,
      "y": 6,
      "z": 2,
      "name": "Rock_Crystal_Cyan_Block",
      "rotation": 5
    },
    {
      "x": -18,
      "y": 7,
      "z": 2,
      "name": "Rock_Stone"
    },
    {
      "x": -18,
      "y": 8,
      "z": 2,
      "name": "Rock_Stone"
    },
    {
      "x": -18,
      "y": 9,
      "z": 2,
      "name": "Rock_Stone"
    },
    {
      "x": -18,
      "y": 10,
      "z": 2,
      "name": "Rock_Stone"
    },
    {
      "x": -18,
      "y": 11,
      "z": 2,
      "name": "Rock_Stone"
    },
    {
      "x": -18,
      "y": 12,
      "z": 2,
      "name": "Rock_Stone"
    },
    {
      "x": -18,
      "y": 13,
      "z": 2,
      "name": "Rock_Stone"
    },
    {
      "x": -18,
      "y": 14,
      "z": 2,
      "name": "Rock_Stone"
    },
    {
      "x": -18,
      "y": 15,
      "z": 2,
      "name": "Rock_Stone"
    },
    {
      "x": -18,
      "y": 16,
      "z": 2,
      "name": "Rock_Stone"
    },
    {
      "x": -18,
      "y": -6,
      "z": 3,
      "name": "Rock_Stone_Mossy"
    },
    {
      "x": -18,
      "y": -5,
      "z": 3,
      "name": "Rock_Stone"
    },
    {
      "x": -18,
      "y": -4,
      "z": 3,
      "name": "Rock_Stone"
    },
    {
      "x": -18,
      "y": -3,
      "z": 3,
      "name": "Rock_Stone_Half"
    },
    {
      "x": -18,
      "y": -2,
      "z": 3,
      "name": "Rock_Stone"
    },
    {
      "x": -18,
      "y": -1,
      "z": 3,
      "name": "Rock_Stone"
    },
    {
      "x": -18,
      "y": 0,
      "z": 3,
      "name": "Rock_Stone"
    },
    {
      "x": -18,
      "y": 1,
      "z": 3,
      "name": "Rock_Stone"
    },
    {
      "x": -18,
      "y": 2,
      "z": 3,
      "name": "Rock_Stone"
    },
    {
      "x": -18,
      "y": 3,
      "z": 3,
      "name": "Rock_Stone_Mossy"
    },
    {
      "x": -18,
      "y": 4,
      "z": 3,
      "name": "Rock_Stone"
    },
    {
      "x": -18,
      "y": 5,
      "z": 3,
      "name": "Rock_Stone_Half"
    },
    {
      "x": -18,
      "y": 6,
      "z": 3,
      "name": "Rock_Stone"
    },
    {
      "x": -18,
      "y": 7,
      "z": 3,
      "name": "Rock_Stone"
    },
    {
      "x": -18,
      "y": 8,
      "z": 3,
      "name": "Rock_Stone"
    },
    {
      "x": -18,
      "y": 9,
      "z": 3,
      "name": "Rock_Stone"
    },
    {
      "x": -18,
      "y": 10,
      "z": 3,
      "name": "Rock_Stone"
    },
    {
      "x": -18,
      "y": 11,
      "z": 3,
      "name": "Rock_Stone"
    },
    {
      "x": -17,
      "y": 1,
      "z": -16,
      "name": "Rock_Stone_Half",
      "rotation": 6
    },
    {
      "x": -17,
      "y": 8,
      "z": -16,
      "name": "Rock_Stone_Half",
      "rotation": 6
    },
    {
      "x": -17,
      "y": -7,
      "z": -15,
      "name": "Rock_Stone"
    },
    {
      "x": -17,
      "y": -6,
      "z": -15,
      "name": "Rock_Stone"
    },
    {
      "x": -17,
      "y": -5,
      "z": -15,
      "name": "Rock_Stone"
    },
    {
      "x": -17,
      "y": -4,
      "z": -15,
      "name": "Rock_Stone"
    },
    {
      "x": -17,
      "y": -3,
      "z": -15,
      "name": "Rock_Crystal_Cyan_Small",
      "rotation": 7
    },
    {
      "x": -17,
      "y": -2,
      "z": -15,
      "name": "Rock_Stone"
    },
    {
      "x": -17,
      "y": -1,
      "z": -15,
      "name": "Rock_Stone"
    },
    {
      "x": -17,
      "y": 0,
      "z": -15,
      "name": "Rock_Stone"
    },
    {
      "x": -17,
      "y": 1,
      "z": -15,
      "name": "Rock_Stone"
    },
    {
      "x": -17,
      "y": 2,
      "z": -15,
      "name": "Rock_Stone_Half"
    },
    {
      "x": -17,
      "y": 3,
      "z": -15,
      "name": "Rock_Stone"
    },
    {
      "x": -17,
      "y": 4,
      "z": -15,
      "name": "Rock_Stone"
    },
    {
      "x": -17,
      "y": 5,
      "z": -15,
      "name": "Rock_Stone_Mossy"
    },
    {
      "x": -17,
      "y": 6,
      "z": -15,
      "name": "Rock_Stone"
    },
    {
      "x": -17,
      "y": 7,
      "z": -15,
      "name": "Rock_Stone"
    },
    {
      "x": -17,
      "y": 8,
      "z": -15,
      "name": "Rock_Stone_Mossy"
    },
    {
      "x": -17,
      "y": 9,
      "z": -15,
      "name": "Rock_Stone_Half"
    },
    {
      "x": -17,
      "y": 10,
      "z": -15,
      "name": "Rock_Stone_Half",
      "rotation": 7
    },
    {
      "x": -17,
      "y": -9,
      "z": -14,
      "name": "Rock_Stone"
    },
    {
      "x": -17,
      "y": -8,
      "z": -14,
      "name": "Rock_Stone"
    },
    {
      "x": -17,
      "y": -7,
      "z": -14,
      "name": "Rock_Stone"
    },
    {
      "x": -17,
      "y": -6,
      "z": -14,
      "name": "Rock_Stone"
    },
    {
      "x": -17,
      "y": -5,
      "z": -14,
      "name": "Rock_Stone"
    },
    {
      "x": -17,
      "y": -4,
      "z": -14,
      "name": "Rock_Stone_Mossy"
    },
    {
      "x": -17,
      "y": -1,
      "z": -14,
      "name": "Rock_Stone"
    },
    {
      "x": -17,
      "y": 0,
      "z": -14,
      "name": "Rock_Stone"
    },
    {
      "x": -17,
      "y": 1,
      "z": -14,
      "name": "Rock_Stone"
    },
    {
      "x": -17,
      "y": 4,
      "z": -14,
      "name": "Rock_Crystal_Cyan_Small",
      "rotation": 7
    },
    {
      "x": -17,
      "y": 5,
      "z": -14,
      "name": "Rock_Stone"
    },
    {
      "x": -17,
      "y": 6,
      "z": -14,
      "name": "Rock_Stone"
    },
    {
      "x": -17,
      "y": 7,
      "z": -14,
      "name": "Rock_Stone_Mossy"
    },
    {
      "x": -17,
      "y": 8,
      "z": -14,
      "name": "Rock_Stone"
    },
    {
      "x": -17,
      "y": 9,
      "z": -14,
      "name": "Rock_Stone_Half"
    },
    {
      "x": -17,
      "y": 11,
      "z": -14,
      "name": "Rock_Stone_Mossy"
    },
    {
      "x": -17,
      "y": -10,
      "z": -13,
      "name": "Rock_Stone"
    },
    {
      "x": -17,
      "y": -9,
      "z": -13,
      "name": "Rock_Stone"
    },
    {
      "x": -17,
      "y": -8,
      "z": -13,
      "name": "Rock_Stone"
    },
    {
      "x": -17,
      "y": -7,
      "z": -13,
      "name": "Rock_Stone"
    },
    {
      "x": -17,
      "y": -6,
      "z": -13,
      "name": "Rock_Stone"
    },
    {
      "x": -17,
      "y": -5,
      "z": -13,
      "name": "Rock_Stone"
    },
    {
      "x": -17,
      "y": -4,
      "z": -13,
      "name": "Rock_Stone"
    },
    {
      "x": -17,
      "y": -3,
      "z": -13,
      "name": "Rock_Stone"
    },
    {
      "x": -17,
      "y": -2,
      "z": -13,
      "name": "Rock_Crystal_Cyan_Small",
      "rotation": 7
    },
    {
      "x": -17,
      "y": -1,
      "z": -13,
      "name": "Rock_Stone"
    },
    {
      "x": -17,
      "y": 0,
      "z": -13,
      "name": "Rock_Stone"
    },
    {
      "x": -17,
      "y": 1,
      "z": -13,
      "name": "Rock_Stone"
    },
    {
      "x": -17,
      "y": 2,
      "z": -13,
      "name": "Rock_Stone"
    },
    {
      "x": -17,
      "y": 3,
      "z": -13,
      "name": "Rock_Stone"
    },
    {
      "x": -17,
      "y": 5,
      "z": -13,
      "name": "Rock_Stone"
    },
    {
      "x": -17,
      "y": 6,
      "z": -13,
      "name": "Rock_Stone_Mossy"
    },
    {
      "x": -17,
      "y": 7,
      "z": -13,
      "name": "Rock_Stone"
    },
    {
      "x": -17,
      "y": 8,
      "z": -13,
      "name": "Rock_Stone"
    },
    {
      "x": -17,
      "y": 9,
      "z": -13,
      "name": "Rock_Stone"
    },
    {
      "x": -17,
      "y": 10,
      "z": -13,
      "name": "Rock_Crystal_Cyan_Small",
      "rotation": 7
    },
    {
      "x": -17,
      "y": 11,
      "z": -13,
      "name": "Rock_Stone_Half",
      "rotation": 8
    },
    {
      "x": -17,
      "y": 12,
      "z": -13,
      "name": "Rock_Stone"
    },
    {
      "x": -17,
      "y": -7,
      "z": -12,
      "name": "Rock_Stone"
    },
    {
      "x": -17,
      "y": -6,
      "z": -12,
      "name": "Rock_Stone"
    },
    {
      "x": -17,
      "y": -5,
      "z": -12,
      "name": "Rock_Stone"
    },
    {
      "x": -17,
      "y": -4,
      "z": -12,
      "name": "Rock_Stone"
    },
    {
      "x": -17,
      "y": -3,
      "z": -12,
      "name": "Rock_Stone"
    },
    {
      "x": -17,
      "y": -1,
      "z": -12,
      "name": "Rock_Stone"
    },
    {
      "x": -17,
      "y": 0,
      "z": -12,
      "name": "Rock_Stone"
    },
    {
      "x": -17,
      "y": 1,
      "z": -12,
      "name": "Rock_Stone"
    },
    {
      "x": -17,
      "y": 2,
      "z": -12,
      "name": "Rock_Stone"
    },
    {
      "x": -17,
      "y": 3,
      "z": -12,
      "name": "Rock_Stone"
    },
    {
      "x": -17,
      "y": 4,
      "z": -12,
      "name": "Rock_Crystal_Cyan_Small",
      "rotation": 7
    },
    {
      "x": -17,
      "y": 5,
      "z": -12,
      "name": "Rock_Stone"
    },
    {
      "x": -17,
      "y": 6,
      "z": -12,
      "name": "Rock_Stone"
    },
    {
      "x": -17,
      "y": 7,
      "z": -12,
      "name": "Rock_Stone"
    },
    {
      "x": -17,
      "y": 8,
      "z": -12,
      "name": "Rock_Stone"
    },
    {
      "x": -17,
      "y": 9,
      "z": -12,
      "name": "Rock_Stone"
    },
    {
      "x": -17,
      "y": -3,
      "z": -11,
      "name": "Rock_Stone_Half",
      "rotation": 7
    },
    {
      "x": -17,
      "y": 3,
      "z": -11,
      "name": "Rock_Stone_Half",
      "rotation": 4
    },
    {
      "x": -17,
      "y": -6,
      "z": -1,
      "name": "Rock_Stone"
    },
    {
      "x": -17,
      "y": -5,
      "z": -1,
      "name": "Rock_Stone"
    },
    {
      "x": -17,
      "y": -4,
      "z": -1,
      "name": "Rock_Stone"
    },
    {
      "x": -17,
      "y": -3,
      "z": -1,
      "name": "Rock_Stone"
    },
    {
      "x": -17,
      "y": -2,
      "z": -1,
      "name": "Rock_Stone_Half"
    },
    {
      "x": -17,
      "y": -1,
      "z": -1,
      "name": "Rock_Stone"
    },
    {
      "x": -17,
      "y": 0,
      "z": -1,
      "name": "Rock_Stone"
    },
    {
      "x": -17,
      "y": 1,
      "z": -1,
      "name": "Rock_Stone"
    },
    {
      "x": -17,
      "y": 2,
      "z": -1,
      "name": "Rock_Stone"
    },
    {
      "x": -17,
      "y": 3,
      "z": -1,
      "name": "Rock_Stone"
    },
    {
      "x": -17,
      "y": 4,
      "z": -1,
      "name": "Rock_Stone_Mossy"
    },
    {
      "x": -17,
      "y": 5,
      "z": -1,
      "name": "Rock_Stone"
    },
    {
      "x": -17,
      "y": 6,
      "z": -1,
      "name": "Rock_Stone_Mossy"
    },
    {
      "x": -17,
      "y": 7,
      "z": -1,
      "name": "Plant_Crop_Mushroom_Common_Blue",
      "components": {
        "Components": {
          "FarmingBlock": {
            "LastTickGameTime": "0001-02-23T03:00:00Z"
          },
          "PlacedByInteraction": {
            "WhoPlacedUuid": {
              "$binary": "3XRzOktQTQGfL/+8x7+CHA==",
              "$type": "04"
            }
          }
        }
      }
    },
    {
      "x": -17,
      "y": 8,
      "z": -1,
      "name": "Rock_Stone"
    },
    {
      "x": -17,
      "y": 9,
      "z": -1,
      "name": "Rock_Stone"
    },
    {
      "x": -17,
      "y": 10,
      "z": -1,
      "name": "Rock_Stone"
    },
    {
      "x": -17,
      "y": 11,
      "z": -1,
      "name": "Rock_Stone"
    },
    {
      "x": -17,
      "y": 15,
      "z": -1,
      "name": "Plant_Moss_Wall_Blue",
      "support": 15,
      "rotation": 1
    },
    {
      "x": -17,
      "y": 16,
      "z": -1,
      "name": "Plant_Moss_Wall_Blue",
      "support": 15,
      "rotation": 1
    },
    {
      "x": -17,
      "y": -9,
      "z": 0,
      "name": "Rock_Stone_Mossy"
    },
    {
      "x": -17,
      "y": -8,
      "z": 0,
      "name": "Rock_Stone"
    },
    {
      "x": -17,
      "y": -7,
      "z": 0,
      "name": "Rock_Stone"
    },
    {
      "x": -17,
      "y": -6,
      "z": 0,
      "name": "Rock_Stone_Mossy"
    },
    {
      "x": -17,
      "y": -5,
      "z": 0,
      "name": "Rock_Stone"
    },
    {
      "x": -17,
      "y": -4,
      "z": 0,
      "name": "Rock_Stone"
    },
    {
      "x": -17,
      "y": -3,
      "z": 0,
      "name": "Rock_Stone"
    },
    {
      "x": -17,
      "y": -1,
      "z": 0,
      "name": "Rock_Stone"
    },
    {
      "x": -17,
      "y": 0,
      "z": 0,
      "name": "Rock_Stone"
    },
    {
      "x": -17,
      "y": 1,
      "z": 0,
      "name": "Rock_Stone"
    },
    {
      "x": -17,
      "y": 2,
      "z": 0,
      "name": "Rock_Stone"
    },
    {
      "x": -17,
      "y": 3,
      "z": 0,
      "name": "Rock_Stone"
    },
    {
      "x": -17,
      "y": 4,
      "z": 0,
      "name": "Rock_Stone"
    },
    {
      "x": -17,
      "y": 5,
      "z": 0,
      "name": "Rock_Stone"
    },
    {
      "x": -17,
      "y": 7,
      "z": 0,
      "name": "Rock_Crystal_Cyan_Small",
      "rotation": 5
    },
    {
      "x": -17,
      "y": 8,
      "z": 0,
      "name": "Rock_Stone"
    },
    {
      "x": -17,
      "y": 9,
      "z": 0,
      "name": "Rock_Stone"
    },
    {
      "x": -17,
      "y": 10,
      "z": 0,
      "name": "Rock_Stone"
    },
    {
      "x": -17,
      "y": 11,
      "z": 0,
      "name": "Rock_Stone"
    },
    {
      "x": -17,
      "y": 12,
      "z": 0,
      "name": "Rock_Stone"
    },
    {
      "x": -17,
      "y": 13,
      "z": 0,
      "name": "Rock_Stone"
    },
    {
      "x": -17,
      "y": 14,
      "z": 0,
      "name": "Rock_Stone"
    },
    {
      "x": -17,
      "y": 16,
      "z": 0,
      "name": "Plant_Moss_Wall_Blue",
      "support": 15,
      "rotation": 1
    },
    {
      "x": -17,
      "y": 17,
      "z": 0,
      "name": "Plant_Moss_Wall_Blue",
      "support": 15,
      "rotation": 1
    },
    {
      "x": -17,
      "y": -9,
      "z": 1,
      "name": "Rock_Stone_Mossy"
    },
    {
      "x": -17,
      "y": -8,
      "z": 1,
      "name": "Rock_Stone"
    },
    {
      "x": -17,
      "y": -7,
      "z": 1,
      "name": "Rock_Stone"
    },
    {
      "x": -17,
      "y": -6,
      "z": 1,
      "name": "Rock_Stone"
    },
    {
      "x": -17,
      "y": -5,
      "z": 1,
      "name": "Rock_Stone_Mossy"
    },
    {
      "x": -17,
      "y": -4,
      "z": 1,
      "name": "Rock_Stone"
    },
    {
      "x": -17,
      "y": -3,
      "z": 1,
      "name": "Rock_Stone"
    },
    {
      "x": -17,
      "y": -2,
      "z": 1,
      "name": "Rock_Crystal_Cyan_Small",
      "rotation": 5
    },
    {
      "x": -17,
      "y": -1,
      "z": 1,
      "name": "Rock_Stone"
    },
    {
      "x": -17,
      "y": 0,
      "z": 1,
      "name": "Rock_Stone_Mossy"
    },
    {
      "x": -17,
      "y": 1,
      "z": 1,
      "name": "Rock_Stone"
    },
    {
      "x": -17,
      "y": 2,
      "z": 1,
      "name": "Rock_Stone"
    },
    {
      "x": -17,
      "y": 3,
      "z": 1,
      "name": "Rock_Stone"
    },
    {
      "x": -17,
      "y": 4,
      "z": 1,
      "name": "Rock_Stone"
    },
    {
      "x": -17,
      "y": 5,
      "z": 1,
      "name": "Rock_Stone"
    },
    {
      "x": -17,
      "y": 6,
      "z": 1,
      "name": "Plant_Crop_Mushroom_Common_Blue",
      "components": {
        "Components": {
          "FarmingBlock": {
            "LastTickGameTime": "0001-02-23T03:00:00Z"
          },
          "PlacedByInteraction": {
            "WhoPlacedUuid": {
              "$binary": "3XRzOktQTQGfL/+8x7+CHA==",
              "$type": "04"
            }
          }
        }
      }
    },
    {
      "x": -17,
      "y": 7,
      "z": 1,
      "name": "Rock_Stone"
    },
    {
      "x": -17,
      "y": 8,
      "z": 1,
      "name": "Rock_Stone"
    },
    {
      "x": -17,
      "y": 9,
      "z": 1,
      "name": "Rock_Stone"
    },
    {
      "x": -17,
      "y": 10,
      "z": 1,
      "name": "Rock_Stone"
    },
    {
      "x": -17,
      "y": 11,
      "z": 1,
      "name": "Rock_Stone"
    },
    {
      "x": -17,
      "y": 12,
      "z": 1,
      "name": "Rock_Stone"
    },
    {
      "x": -17,
      "y": 13,
      "z": 1,
      "name": "Rock_Stone"
    },
    {
      "x": -17,
      "y": 14,
      "z": 1,
      "name": "Rock_Stone"
    },
    {
      "x": -17,
      "y": 17,
      "z": 1,
      "name": "Plant_Moss_Wall_Blue",
      "support": 15,
      "rotation": 1
    },
    {
      "x": -17,
      "y": 18,
      "z": 1,
      "name": "Plant_Moss_Wall_Blue",
      "support": 15,
      "rotation": 1
    },
    {
      "x": -17,
      "y": -6,
      "z": 2,
      "name": "Rock_Stone"
    },
    {
      "x": -17,
      "y": -5,
      "z": 2,
      "name": "Rock_Stone"
    },
    {
      "x": -17,
      "y": -4,
      "z": 2,
      "name": "Rock_Stone"
    },
    {
      "x": -17,
      "y": -3,
      "z": 2,
      "name": "Rock_Stone_Half"
    },
    {
      "x": -17,
      "y": -1,
      "z": 2,
      "name": "Rock_Stone"
    },
    {
      "x": -17,
      "y": 0,
      "z": 2,
      "name": "Rock_Stone"
    },
    {
      "x": -17,
      "y": 1,
      "z": 2,
      "name": "Rock_Stone"
    },
    {
      "x": -17,
      "y": 2,
      "z": 2,
      "name": "Rock_Stone"
    },
    {
      "x": -17,
      "y": 3,
      "z": 2,
      "name": "Rock_Stone"
    },
    {
      "x": -17,
      "y": 4,
      "z": 2,
      "name": "Rock_Stone"
    },
    {
      "x": -17,
      "y": 5,
      "z": 2,
      "name": "Rock_Stone_Half"
    },
    {
      "x": -17,
      "y": 7,
      "z": 2,
      "name": "Rock_Stone"
    },
    {
      "x": -17,
      "y": 8,
      "z": 2,
      "name": "Rock_Stone"
    },
    {
      "x": -17,
      "y": 9,
      "z": 2,
      "name": "Rock_Stone"
    },
    {
      "x": -17,
      "y": 10,
      "z": 2,
      "name": "Rock_Stone"
    },
    {
      "x": -17,
      "y": 11,
      "z": 2,
      "name": "Rock_Stone"
    },
    {
      "x": -16,
      "y": -7,
      "z": -16,
      "name": "Rock_Stone"
    },
    {
      "x": -16,
      "y": -6,
      "z": -16,
      "name": "Rock_Stone"
    },
    {
      "x": -16,
      "y": -5,
      "z": -16,
      "name": "Rock_Stone_Mossy"
    },
    {
      "x": -16,
      "y": -4,
      "z": -16,
      "name": "Rock_Stone"
    },
    {
      "x": -16,
      "y": -2,
      "z": -16,
      "name": "Rock_Stone"
    },
    {
      "x": -16,
      "y": -1,
      "z": -16,
      "name": "Rock_Stone"
    },
    {
      "x": -16,
      "y": 0,
      "z": -16,
      "name": "Rock_Stone"
    },
    {
      "x": -16,
      "y": 1,
      "z": -16,
      "name": "Rock_Stone"
    },
    {
      "x": -16,
      "y": 2,
      "z": -16,
      "name": "Rock_Crystal_Cyan_Small",
      "rotation": 6
    },
    {
      "x": -16,
      "y": 3,
      "z": -16,
      "name": "Rock_Stone"
    },
    {
      "x": -16,
      "y": 4,
      "z": -16,
      "name": "Rock_Stone"
    },
    {
      "x": -16,
      "y": 5,
      "z": -16,
      "name": "Rock_Stone"
    },
    {
      "x": -16,
      "y": 6,
      "z": -16,
      "name": "Rock_Stone"
    },
    {
      "x": -16,
      "y": 7,
      "z": -16,
      "name": "Rock_Stone_Mossy"
    },
    {
      "x": -16,
      "y": 8,
      "z": -16,
      "name": "Rock_Stone_Half"
    },
    {
      "x": -16,
      "y": 9,
      "z": -16,
      "name": "Rock_Crystal_Cyan_Small",
      "rotation": 6
    },
    {
      "x": -16,
      "y": 10,
      "z": -16,
      "name": "Rock_Stone_Half",
      "rotation": 6
    },
    {
      "x": -16,
      "y": -11,
      "z": -15,
      "name": "Rock_Stone"
    },
    {
      "x": -16,
      "y": -10,
      "z": -15,
      "name": "Rock_Stone"
    },
    {
      "x": -16,
      "y": -9,
      "z": -15,
      "name": "Rock_Stone"
    },
    {
      "x": -16,
      "y": -8,
      "z": -15,
      "name": "Rock_Stone"
    },
    {
      "x": -16,
      "y": -7,
      "z": -15,
      "name": "Rock_Stone"
    },
    {
      "x": -16,
      "y": -6,
      "z": -15,
      "name": "Rock_Stone"
    },
    {
      "x": -16,
      "y": -5,
      "z": -15,
      "name": "Rock_Stone"
    },
    {
      "x": -16,
      "y": -4,
      "z": -15,
      "name": "Rock_Stone"
    },
    {
      "x": -16,
      "y": -3,
      "z": -15,
      "name": "Rock_Crystal_Cyan_Block",
      "rotation": 4
    },
    {
      "x": -16,
      "y": -2,
      "z": -15,
      "name": "Rock_Stone"
    },
    {
      "x": -16,
      "y": -1,
      "z": -15,
      "name": "Rock_Stone"
    },
    {
      "x": -16,
      "y": 0,
      "z": -15,
      "name": "Rock_Stone"
    },
    {
      "x": -16,
      "y": 1,
      "z": -15,
      "name": "Rock_Stone"
    },
    {
      "x": -16,
      "y": 2,
      "z": -15,
      "name": "Rock_Crystal_Cyan_Block",
      "rotation": 4
    },
    {
      "x": -16,
      "y": 3,
      "z": -15,
      "name": "Rock_Stone"
    },
    {
      "x": -16,
      "y": 4,
      "z": -15,
      "name": "Rock_Stone"
    },
    {
      "x": -16,
      "y": 5,
      "z": -15,
      "name": "Rock_Stone"
    },
    {
      "x": -16,
      "y": 6,
      "z": -15,
      "name": "Rock_Stone"
    },
    {
      "x": -16,
      "y": 7,
      "z": -15,
      "name": "Rock_Stone"
    },
    {
      "x": -16,
      "y": 8,
      "z": -15,
      "name": "Rock_Crystal_Cyan_Block",
      "rotation": 4
    },
    {
      "x": -16,
      "y": 9,
      "z": -15,
      "name": "Rock_Crystal_Cyan_Block",
      "rotation": 4
    },
    {
      "x": -16,
      "y": 10,
      "z": -15,
      "name": "Rock_Stone_Mossy"
    },
    {
      "x": -16,
      "y": 11,
      "z": -15,
      "name": "Rock_Stone"
    },
    {
      "x": -16,
      "y": 12,
      "z": -15,
      "name": "Rock_Stone"
    },
    {
      "x": -16,
      "y": 13,
      "z": -15,
      "name": "Rock_Stone"
    },
    {
      "x": -16,
      "y": -13,
      "z": -14,
      "name": "Rock_Stone"
    },
    {
      "x": -16,
      "y": -12,
      "z": -14,
      "name": "Rock_Stone"
    },
    {
      "x": -16,
      "y": -11,
      "z": -14,
      "name": "Rock_Stone"
    },
    {
      "x": -16,
      "y": -10,
      "z": -14,
      "name": "Rock_Stone"
    },
    {
      "x": -16,
      "y": -9,
      "z": -14,
      "name": "Rock_Stone"
    },
    {
      "x": -16,
      "y": -8,
      "z": -14,
      "name": "Rock_Stone"
    },
    {
      "x": -16,
      "y": -7,
      "z": -14,
      "name": "Rock_Stone"
    },
    {
      "x": -16,
      "y": -6,
      "z": -14,
      "name": "Rock_Stone"
    },
    {
      "x": -16,
      "y": -5,
      "z": -14,
      "name": "Rock_Stone_Mossy"
    },
    {
      "x": -16,
      "y": -4,
      "z": -14,
      "name": "Rock_Stone"
    },
    {
      "x": -16,
      "y": -3,
      "z": -14,
      "name": "Rock_Crystal_Cyan_Block",
      "rotation": 5
    },
    {
      "x": -16,
      "y": -2,
      "z": -14,
      "name": "Rock_Crystal_Cyan_Block",
      "rotation": 5
    },
    {
      "x": -16,
      "y": -1,
      "z": -14,
      "name": "Rock_Stone"
    },
    {
      "x": -16,
      "y": 0,
      "z": -14,
      "name": "Rock_Stone"
    },
    {
      "x": -16,
      "y": 1,
      "z": -14,
      "name": "Rock_Stone"
    },
    {
      "x": -16,
      "y": 2,
      "z": -14,
      "name": "Rock_Crystal_Cyan_Block",
      "rotation": 5
    },
    {
      "x": -16,
      "y": 3,
      "z": -14,
      "name": "Rock_Crystal_Cyan_Block",
      "rotation": 5
    },
    {
      "x": -16,
      "y": 4,
      "z": -14,
      "name": "Rock_Crystal_Cyan_Block",
      "rotation": 5
    },
    {
      "x": -16,
      "y": 5,
      "z": -14,
      "name": "Rock_Stone"
    },
    {
      "x": -16,
      "y": 6,
      "z": -14,
      "name": "Rock_Stone"
    },
    {
      "x": -16,
      "y": 7,
      "z": -14,
      "name": "Rock_Stone"
    },
    {
      "x": -16,
      "y": 8,
      "z": -14,
      "name": "Rock_Stone"
    },
    {
      "x": -16,
      "y": 9,
      "z": -14,
      "name": "Rock_Crystal_Cyan_Block",
      "rotation": 5
    },
    {
      "x": -16,
      "y": 10,
      "z": -14,
      "name": "Rock_Crystal_Cyan_Block",
      "rotation": 5
    },
    {
      "x": -16,
      "y": 11,
      "z": -14,
      "name": "Rock_Stone"
    },
    {
      "x": -16,
      "y": 12,
      "z": -14,
      "name": "Rock_Stone"
    },
    {
      "x": -16,
      "y": 13,
      "z": -14,
      "name": "Rock_Stone"
    },
    {
      "x": -16,
      "y": 14,
      "z": -14,
      "name": "Rock_Stone"
    },
    {
      "x": -16,
      "y": 15,
      "z": -14,
      "name": "Rock_Stone"
    },
    {
      "x": -16,
      "y": -13,
      "z": -13,
      "name": "Rock_Stone"
    },
    {
      "x": -16,
      "y": -12,
      "z": -13,
      "name": "Rock_Stone"
    },
    {
      "x": -16,
      "y": -11,
      "z": -13,
      "name": "Rock_Stone"
    },
    {
      "x": -16,
      "y": -10,
      "z": -13,
      "name": "Rock_Stone"
    },
    {
      "x": -16,
      "y": -9,
      "z": -13,
      "name": "Rock_Stone"
    },
    {
      "x": -16,
      "y": -8,
      "z": -13,
      "name": "Rock_Stone"
    },
    {
      "x": -16,
      "y": -7,
      "z": -13,
      "name": "Rock_Stone"
    },
    {
      "x": -16,
      "y": -6,
      "z": -13,
      "name": "Rock_Stone"
    },
    {
      "x": -16,
      "y": -5,
      "z": -13,
      "name": "Rock_Stone"
    },
    {
      "x": -16,
      "y": -4,
      "z": -13,
      "name": "Rock_Stone"
    },
    {
      "x": -16,
      "y": -3,
      "z": -13,
      "name": "Rock_Stone"
    },
    {
      "x": -16,
      "y": -2,
      "z": -13,
      "name": "Rock_Crystal_Cyan_Block",
      "rotation": 5
    },
    {
      "x": -16,
      "y": -1,
      "z": -13,
      "name": "Rock_Stone"
    },
    {
      "x": -16,
      "y": 0,
      "z": -13,
      "name": "Rock_Stone"
    },
    {
      "x": -16,
      "y": 1,
      "z": -13,
      "name": "Rock_Stone_Mossy"
    },
    {
      "x": -16,
      "y": 2,
      "z": -13,
      "name": "Rock_Stone"
    },
    {
      "x": -16,
      "y": 3,
      "z": -13,
      "name": "Rock_Stone"
    },
    {
      "x": -16,
      "y": 4,
      "z": -13,
      "name": "Rock_Crystal_Cyan_Block",
      "rotation": 5
    },
    {
      "x": -16,
      "y": 5,
      "z": -13,
      "name": "Rock_Stone_Mossy"
    },
    {
      "x": -16,
      "y": 6,
      "z": -13,
      "name": "Rock_Stone"
    },
    {
      "x": -16,
      "y": 7,
      "z": -13,
      "name": "Rock_Stone_Mossy"
    },
    {
      "x": -16,
      "y": 8,
      "z": -13,
      "name": "Rock_Stone"
    },
    {
      "x": -16,
      "y": 9,
      "z": -13,
      "name": "Rock_Stone"
    },
    {
      "x": -16,
      "y": 10,
      "z": -13,
      "name": "Rock_Crystal_Cyan_Block",
      "rotation": 5
    },
    {
      "x": -16,
      "y": 11,
      "z": -13,
      "name": "Rock_Crystal_Cyan_Block",
      "rotation": 4
    },
    {
      "x": -16,
      "y": 12,
      "z": -13,
      "name": "Rock_Stone"
    },
    {
      "x": -16,
      "y": 13,
      "z": -13,
      "name": "Rock_Stone"
    },
    {
      "x": -16,
      "y": 14,
      "z": -13,
      "name": "Rock_Stone"
    },
    {
      "x": -16,
      "y": 15,
      "z": -13,
      "name": "Rock_Stone"
    },
    {
      "x": -16,
      "y": -11,
      "z": -12,
      "name": "Rock_Stone"
    },
    {
      "x": -16,
      "y": -10,
      "z": -12,
      "name": "Rock_Stone"
    },
    {
      "x": -16,
      "y": -9,
      "z": -12,
      "name": "Rock_Stone"
    },
    {
      "x": -16,
      "y": -8,
      "z": -12,
      "name": "Rock_Stone"
    },
    {
      "x": -16,
      "y": -7,
      "z": -12,
      "name": "Rock_Stone"
    },
    {
      "x": -16,
      "y": -6,
      "z": -12,
      "name": "Rock_Stone"
    },
    {
      "x": -16,
      "y": -5,
      "z": -12,
      "name": "Rock_Stone"
    },
    {
      "x": -16,
      "y": -4,
      "z": -12,
      "name": "Rock_Stone"
    },
    {
      "x": -16,
      "y": -3,
      "z": -12,
      "name": "Rock_Stone"
    },
    {
      "x": -16,
      "y": -2,
      "z": -12,
      "name": "Rock_Crystal_Cyan_Block",
      "rotation": 5
    },
    {
      "x": -16,
      "y": -1,
      "z": -12,
      "name": "Rock_Stone"
    },
    {
      "x": -16,
      "y": 0,
      "z": -12,
      "name": "Rock_Stone"
    },
    {
      "x": -16,
      "y": 1,
      "z": -12,
      "name": "Rock_Stone"
    },
    {
      "x": -16,
      "y": 2,
      "z": -12,
      "name": "Rock_Stone_Mossy"
    },
    {
      "x": -16,
      "y": 3,
      "z": -12,
      "name": "Rock_Stone"
    },
    {
      "x": -16,
      "y": 4,
      "z": -12,
      "name": "Rock_Crystal_Cyan_Block",
      "rotation": 5
    },
    {
      "x": -16,
      "y": 5,
      "z": -12,
      "name": "Rock_Stone_Mossy"
    },
    {
      "x": -16,
      "y": 6,
      "z": -12,
      "name": "Rock_Stone"
    },
    {
      "x": -16,
      "y": 7,
      "z": -12,
      "name": "Rock_Stone"
    },
    {
      "x": -16,
      "y": 8,
      "z": -12,
      "name": "Rock_Stone"
    },
    {
      "x": -16,
      "y": 9,
      "z": -12,
      "name": "Rock_Stone"
    },
    {
      "x": -16,
      "y": 10,
      "z": -12,
      "name": "Rock_Stone_Half"
    },
    {
      "x": -16,
      "y": 12,
      "z": -12,
      "name": "Rock_Stone"
    },
    {
      "x": -16,
      "y": 13,
      "z": -12,
      "name": "Rock_Stone"
    },
    {
      "x": -16,
      "y": 14,
      "z": -12,
      "name": "Rock_Stone_Half",
      "rotation": 4
    },
    {
      "x": -16,
      "y": -7,
      "z": -11,
      "name": "Rock_Stone_Mossy"
    },
    {
      "x": -16,
      "y": -6,
      "z": -11,
      "name": "Rock_Stone"
    },
    {
      "x": -16,
      "y": -5,
      "z": -11,
      "name": "Rock_Stone"
    },
    {
      "x": -16,
      "y": -4,
      "z": -11,
      "name": "Rock_Stone"
    },
    {
      "x": -16,
      "y": -3,
      "z": -11,
      "name": "Rock_Stone"
    },
    {
      "x": -16,
      "y": -2,
      "z": -11,
      "name": "Rock_Stone_Half"
    },
    {
      "x": -16,
      "y": -1,
      "z": -11,
      "name": "Rock_Stone"
    },
    {
      "x": -16,
      "y": 0,
      "z": -11,
      "name": "Rock_Stone_Mossy"
    },
    {
      "x": -16,
      "y": 1,
      "z": -11,
      "name": "Rock_Stone"
    },
    {
      "x": -16,
      "y": 2,
      "z": -11,
      "name": "Rock_Stone"
    },
    {
      "x": -16,
      "y": 3,
      "z": -11,
      "name": "Rock_Stone"
    },
    {
      "x": -16,
      "y": 4,
      "z": -11,
      "name": "Rock_Stone_Half"
    },
    {
      "x": -16,
      "y": 5,
      "z": -11,
      "name": "Rock_Stone"
    },
    {
      "x": -16,
      "y": 6,
      "z": -11,
      "name": "Rock_Stone"
    },
    {
      "x": -16,
      "y": 7,
      "z": -11,
      "name": "Rock_Stone"
    },
    {
      "x": -16,
      "y": 8,
      "z": -11,
      "name": "Rock_Stone"
    },
    {
      "x": -16,
      "y": 9,
      "z": -11,
      "name": "Rock_Stone"
    },
    {
      "x": -15,
      "y": -9,
      "z": -16,
      "name": "Rock_Stone"
    },
    {
      "x": -15,
      "y": -8,
      "z": -16,
      "name": "Rock_Stone"
    },
    {
      "x": -15,
      "y": -7,
      "z": -16,
      "name": "Rock_Stone"
    },
    {
      "x": -15,
      "y": -6,
      "z": -16,
      "name": "Rock_Stone"
    },
    {
      "x": -15,
      "y": -5,
      "z": -16,
      "name": "Rock_Stone"
    },
    {
      "x": -15,
      "y": -4,
      "z": -16,
      "name": "Rock_Stone"
    },
    {
      "x": -15,
      "y": -3,
      "z": -16,
      "name": "Rock_Crystal_Cyan_Small",
      "rotation": 6
    },
    {
      "x": -15,
      "y": -2,
      "z": -16,
      "name": "Rock_Stone"
    },
    {
      "x": -15,
      "y": -1,
      "z": -16,
      "name": "Rock_Stone"
    },
    {
      "x": -15,
      "y": 0,
      "z": -16,
      "name": "Rock_Stone"
    },
    {
      "x": -15,
      "y": 1,
      "z": -16,
      "name": "Rock_Stone"
    },
    {
      "x": -15,
      "y": 3,
      "z": -16,
      "name": "Rock_Stone"
    },
    {
      "x": -15,
      "y": 4,
      "z": -16,
      "name": "Rock_Stone"
    },
    {
      "x": -15,
      "y": 5,
      "z": -16,
      "name": "Rock_Stone"
    },
    {
      "x": -15,
      "y": 6,
      "z": -16,
      "name": "Rock_Stone"
    },
    {
      "x": -15,
      "y": 7,
      "z": -16,
      "name": "Rock_Stone"
    },
    {
      "x": -15,
      "y": 9,
      "z": -16,
      "name": "Rock_Stone"
    },
    {
      "x": -15,
      "y": 10,
      "z": -16,
      "name": "Rock_Stone"
    },
    {
      "x": -15,
      "y": 11,
      "z": -16,
      "name": "Rock_Stone"
    },
    {
      "x": -15,
      "y": -13,
      "z": -15,
      "name": "Rock_Stone"
    },
    {
      "x": -15,
      "y": -12,
      "z": -15,
      "name": "Rock_Stone"
    },
    {
      "x": -15,
      "y": -11,
      "z": -15,
      "name": "Rock_Stone"
    },
    {
      "x": -15,
      "y": -10,
      "z": -15,
      "name": "Rock_Stone"
    },
    {
      "x": -15,
      "y": -9,
      "z": -15,
      "name": "Rock_Stone"
    },
    {
      "x": -15,
      "y": -8,
      "z": -15,
      "name": "Rock_Stone"
    },
    {
      "x": -15,
      "y": -7,
      "z": -15,
      "name": "Rock_Stone"
    },
    {
      "x": -15,
      "y": -6,
      "z": -15,
      "name": "Rock_Stone"
    },
    {
      "x": -15,
      "y": -5,
      "z": -15,
      "name": "Rock_Stone"
    },
    {
      "x": -15,
      "y": -4,
      "z": -15,
      "name": "Rock_Stone_Mossy"
    },
    {
      "x": -15,
      "y": -3,
      "z": -15,
      "name": "Rock_Crystal_Cyan_Block",
      "rotation": 4
    },
    {
      "x": -15,
      "y": -2,
      "z": -15,
      "name": "Rock_Stone"
    },
    {
      "x": -15,
      "y": -1,
      "z": -15,
      "name": "Rock_Stone"
    },
    {
      "x": -15,
      "y": 0,
      "z": -15,
      "name": "Rock_Stone"
    },
    {
      "x": -15,
      "y": 1,
      "z": -15,
      "name": "Rock_Stone"
    },
    {
      "x": -15,
      "y": 2,
      "z": -15,
      "name": "Rock_Crystal_Cyan_Block",
      "rotation": 4
    },
    {
      "x": -15,
      "y": 3,
      "z": -15,
      "name": "Rock_Stone"
    },
    {
      "x": -15,
      "y": 4,
      "z": -15,
      "name": "Rock_Stone"
    },
    {
      "x": -15,
      "y": 5,
      "z": -15,
      "name": "Rock_Stone"
    },
    {
      "x": -15,
      "y": 6,
      "z": -15,
      "name": "Rock_Stone"
    },
    {
      "x": -15,
      "y": 7,
      "z": -15,
      "name": "Rock_Stone"
    },
    {
      "x": -15,
      "y": 8,
      "z": -15,
      "name": "Rock_Crystal_Cyan_Block",
      "rotation": 4
    },
    {
      "x": -15,
      "y": 9,
      "z": -15,
      "name": "Rock_Stone"
    },
    {
      "x": -15,
      "y": 10,
      "z": -15,
      "name": "Rock_Stone"
    },
    {
      "x": -15,
      "y": 11,
      "z": -15,
      "name": "Rock_Stone"
    },
    {
      "x": -15,
      "y": 12,
      "z": -15,
      "name": "Rock_Stone"
    },
    {
      "x": -15,
      "y": 13,
      "z": -15,
      "name": "Rock_Stone"
    },
    {
      "x": -15,
      "y": 14,
      "z": -15,
      "name": "Rock_Stone"
    },
    {
      "x": -15,
      "y": 15,
      "z": -15,
      "name": "Rock_Stone"
    },
    {
      "x": -15,
      "y": -14,
      "z": -14,
      "name": "Rock_Stone"
    },
    {
      "x": -15,
      "y": -13,
      "z": -14,
      "name": "Rock_Stone"
    },
    {
      "x": -15,
      "y": -12,
      "z": -14,
      "name": "Rock_Stone"
    },
    {
      "x": -15,
      "y": -11,
      "z": -14,
      "name": "Rock_Stone"
    },
    {
      "x": -15,
      "y": -10,
      "z": -14,
      "name": "Rock_Stone"
    },
    {
      "x": -15,
      "y": -9,
      "z": -14,
      "name": "Rock_Stone"
    },
    {
      "x": -15,
      "y": -8,
      "z": -14,
      "name": "Rock_Stone_Mossy"
    },
    {
      "x": -15,
      "y": -7,
      "z": -14,
      "name": "Rock_Stone"
    },
    {
      "x": -15,
      "y": -6,
      "z": -14,
      "name": "Rock_Stone"
    },
    {
      "x": -15,
      "y": -5,
      "z": -14,
      "name": "Rock_Stone"
    },
    {
      "x": -15,
      "y": -4,
      "z": -14,
      "name": "Rock_Stone"
    },
    {
      "x": -15,
      "y": -3,
      "z": -14,
      "name": "Rock_Stone"
    },
    {
      "x": -15,
      "y": -2,
      "z": -14,
      "name": "Rock_Stone"
    },
    {
      "x": -15,
      "y": -1,
      "z": -14,
      "name": "Rock_Stone"
    },
    {
      "x": -15,
      "y": 0,
      "z": -14,
      "name": "Rock_Stone_Mossy"
    },
    {
      "x": -15,
      "y": 1,
      "z": -14,
      "name": "Rock_Stone"
    },
    {
      "x": -15,
      "y": 2,
      "z": -14,
      "name": "Rock_Stone_Mossy"
    },
    {
      "x": -15,
      "y": 3,
      "z": -14,
      "name": "Rock_Stone"
    },
    {
      "x": -15,
      "y": 4,
      "z": -14,
      "name": "Rock_Stone_Mossy"
    },
    {
      "x": -15,
      "y": 5,
      "z": -14,
      "name": "Rock_Stone"
    },
    {
      "x": -15,
      "y": 6,
      "z": -14,
      "name": "Rock_Stone"
    },
    {
      "x": -15,
      "y": 7,
      "z": -14,
      "name": "Rock_Stone"
    },
    {
      "x": -15,
      "y": 8,
      "z": -14,
      "name": "Rock_Stone"
    },
    {
      "x": -15,
      "y": 9,
      "z": -14,
      "name": "Rock_Stone_Mossy"
    },
    {
      "x": -15,
      "y": 10,
      "z": -14,
      "name": "Rock_Stone"
    },
    {
      "x": -15,
      "y": 11,
      "z": -14,
      "name": "Rock_Stone_Mossy"
    },
    {
      "x": -15,
      "y": 12,
      "z": -14,
      "name": "Rock_Stone_Mossy"
    },
    {
      "x": -15,
      "y": 13,
      "z": -14,
      "name": "Rock_Stone"
    },
    {
      "x": -15,
      "y": 14,
      "z": -14,
      "name": "Rock_Stone"
    },
    {
      "x": -15,
      "y": 15,
      "z": -14,
      "name": "Rock_Stone_Mossy"
    },
    {
      "x": -15,
      "y": 16,
      "z": -14,
      "name": "Rock_Stone"
    },
    {
      "x": -15,
      "y": -14,
      "z": -13,
      "name": "Rock_Stone_Mossy"
    },
    {
      "x": -15,
      "y": -13,
      "z": -13,
      "name": "Rock_Stone"
    },
    {
      "x": -15,
      "y": -12,
      "z": -13,
      "name": "Rock_Stone"
    },
    {
      "x": -15,
      "y": -11,
      "z": -13,
      "name": "Rock_Stone"
    },
    {
      "x": -15,
      "y": -10,
      "z": -13,
      "name": "Rock_Stone"
    },
    {
      "x": -15,
      "y": -9,
      "z": -13,
      "name": "Rock_Stone"
    },
    {
      "x": -15,
      "y": -8,
      "z": -13,
      "name": "Rock_Stone"
    },
    {
      "x": -15,
      "y": -7,
      "z": -13,
      "name": "Rock_Stone"
    },
    {
      "x": -15,
      "y": -6,
      "z": -13,
      "name": "Rock_Stone"
    },
    {
      "x": -15,
      "y": -5,
      "z": -13,
      "name": "Rock_Stone"
    },
    {
      "x": -15,
      "y": -4,
