{
  "version": 8,
  "blockIdVersion": 11,
  "anchorX": 0,
  "anchorY": 0,
  "anchorZ": 0,
  "blocks": [
    {
      "x": -7,
      "y": -7,
      "z": -8,
      "name": "Rock_Stone",
      "rotation": 12
    },
    {
      "x": -7,
      "y": -8,
      "z": -7,
      "name": "Rock_Stone",
      "rotation": 12
    },
    {
      "x": -7,
      "y": -7,
      "z": -7,
      "name": "Rock_Stone",
      "rotation": 12
    },
    {
      "x": -7,
      "y": -6,
      "z": -7,
      "name": "Rock_Stone_Mossy",
      "rotation": 12
    },
    {
      "x": -7,
      "y": -5,
      "z": -7,
      "name": "Rock_Stone",
      "rotation": 12
    },
    {
      "x": -7,
      "y": -4,
      "z": -7,
      "name": "Rock_Stone",
      "rotation": 12
    },
    {
      "x": -7,
      "y": -8,
      "z": -6,
      "name": "Rock_Stone",
      "rotation": 12
    },
    {
      "x": -7,
      "y": -7,
      "z": -6,
      "name": "Rock_Stone",
      "rotation": 12
    },
    {
      "x": -7,
      "y": -6,
      "z": -6,
      "name": "Rock_Stone",
      "rotation": 12
    },
    {
      "x": -7,
      "y": -5,
      "z": -6,
      "name": "Rock_Stone",
      "rotation": 12
    },
    {
      "x": -7,
      "y": -4,
      "z": -6,
      "name": "Rock_Stone",
      "rotation": 12
    },
    {
      "x": -7,
      "y": -8,
      "z": -5,
      "name": "Rock_Stone",
      "rotation": 12
    },
    {
      "x": -7,
      "y": -7,
      "z": -5,
      "name": "Rock_Stone",
      "rotation": 12
    },
    {
      "x": -7,
      "y": -6,
      "z": -5,
      "name": "Rock_Stone",
      "rotation": 12
    },
    {
      "x": -7,
      "y": -5,
      "z": -5,
      "name": "Rock_Stone_Mossy",
      "rotation": 12
    },
    {
      "x": -7,
      "y": -4,
      "z": -5,
      "name": "Rock_Stone_Mossy",
      "rotation": 12
    },
    {
      "x": -7,
      "y": -8,
      "z": -4,
      "name": "Rock_Stone_Mossy",
      "rotation": 12
    },
    {
      "x": -7,
      "y": -7,
      "z": -4,
      "name": "Rock_Stone",
      "rotation": 12
    },
    {
      "x": -7,
      "y": -6,
      "z": -4,
      "name": "Rock_Stone_Mossy",
      "rotation": 12
    },
    {
      "x": -7,
      "y": -5,
      "z": -4,
      "name": "Rock_Stone",
      "rotation": 12
    },
    {
      "x": -7,
      "y": -4,
      "z": -4,
      "name": "Rock_Stone",
      "rotation": 12
    },
    {
      "x": -7,
      "y": -8,
      "z": -3,
      "name": "Rock_Stone",
      "rotation": 12
    },
    {
      "x": -7,
      "y": -7,
      "z": -3,
      "name": "Rock_Stone",
      "rotation": 12
    },
    {
      "x": -7,
      "y": -6,
      "z": -3,
      "name": "Rock_Stone",
      "rotation": 12
    },
    {
      "x": -7,
      "y": -5,
      "z": -3,
      "name": "Rock_Stone_Mossy",
      "rotation": 12
    },
    {
      "x": -7,
      "y": -4,
      "z": -3,
      "name": "Rock_Stone",
      "rotation": 12
    },
    {
      "x": -7,
      "y": -8,
      "z": -2,
      "name": "Rock_Stone_Mossy",
      "rotation": 12
    },
    {
      "x": -7,
      "y": -7,
      "z": -2,
      "name": "Rock_Stone",
      "rotation": 12
    },
    {
      "x": -7,
      "y": -6,
      "z": -2,
      "name": "Rock_Stone_Mossy",
      "rotation": 12
    },
    {
      "x": -7,
      "y": -5,
      "z": -2,
      "name": "Rock_Stone",
      "rotation": 12
    },
    {
      "x": -7,
      "y": -4,
      "z": -2,
      "name": "Rock_Stone",
      "rotation": 12
    },
    {
      "x": -7,
      "y": -9,
      "z": -1,
      "name": "Rock_Stone",
      "rotation": 12
    },
    {
      "x": -7,
      "y": -8,
      "z": -1,
      "name": "Rock_Stone_Mossy",
      "rotation": 12
    },
    {
      "x": -7,
      "y": -7,
      "z": -1,
      "name": "Rock_Stone_Mossy",
      "rotation": 12
    },
    {
      "x": -7,
      "y": -6,
      "z": -1,
      "name": "Rock_Stone",
      "rotation": 12
    },
    {
      "x": -7,
      "y": -5,
      "z": -1,
      "name": "Rock_Stone",
      "rotation": 12
    },
    {
      "x": -7,
      "y": -9,
      "z": 0,
      "name": "Rock_Stone",
      "rotation": 12
    },
    {
      "x": -7,
      "y": -8,
      "z": 0,
      "name": "Rock_Stone",
      "rotation": 12
    },
    {
      "x": -7,
      "y": -7,
      "z": 0,
      "name": "Rock_Stone_Mossy",
      "rotation": 12
    },
    {
      "x": -7,
      "y": -6,
      "z": 0,
      "name": "Rock_Stone_Mossy",
      "rotation": 12
    },
    {
      "x": -7,
      "y": -5,
      "z": 0,
      "name": "Rock_Stone_Mossy",
      "rotation": 12
    },
    {
      "x": -7,
      "y": -9,
      "z": 1,
      "name": "Rock_Stone_Mossy",
      "rotation": 12
    },
    {
      "x": -7,
      "y": -8,
      "z": 1,
      "name": "Rock_Stone_Mossy",
      "rotation": 12
    },
    {
      "x": -7,
      "y": -7,
      "z": 1,
      "name": "Rock_Stone_Mossy",
      "rotation": 12
    },
    {
      "x": -7,
      "y": -6,
      "z": 1,
      "name": "Rock_Stone",
      "rotation": 12
    },
    {
      "x": -7,
      "y": -5,
      "z": 1,
      "name": "Rock_Stone_Mossy",
      "rotation": 12
    },
    {
      "x": -7,
      "y": -9,
      "z": 2,
      "name": "Rock_Stone",
      "rotation": 12
    },
    {
      "x": -7,
      "y": -8,
      "z": 2,
      "name": "Rock_Stone",
      "rotation": 12
    },
    {
      "x": -7,
      "y": -7,
      "z": 2,
      "name": "Rock_Stone",
      "rotation": 12
    },
    {
      "x": -7,
      "y": -6,
      "z": 2,
      "name": "Rock_Stone",
      "rotation": 12
    },
    {
      "x": -7,
      "y": -5,
      "z": 2,
      "name": "Rock_Stone",
      "rotation": 12
    },
    {
      "x": -7,
      "y": -9,
      "z": 3,
      "name": "Rock_Stone",
      "rotation": 12
    },
    {
      "x": -7,
      "y": -8,
      "z": 3,
      "name": "Rock_Stone",
      "rotation": 12
    },
    {
      "x": -7,
      "y": -7,
      "z": 3,
      "name": "Rock_Stone_Mossy",
      "rotation": 12
    },
    {
      "x": -7,
      "y": -6,
      "z": 3,
      "name": "Rock_Stone",
      "rotation": 12
    },
    {
      "x": -7,
      "y": -5,
      "z": 3,
      "name": "Rock_Stone",
      "rotation": 12
    },
    {
      "x": -7,
      "y": -10,
      "z": 4,
      "name": "Rock_Stone",
      "rotation": 12
    },
    {
      "x": -7,
      "y": -9,
      "z": 4,
      "name": "Rock_Stone",
      "rotation": 12
    },
    {
      "x": -7,
      "y": -8,
      "z": 4,
      "name": "Rock_Stone",
      "rotation": 12
    },
    {
      "x": -7,
      "y": -7,
      "z": 4,
      "name": "Rock_Stone",
      "rotation": 12
    },
    {
      "x": -7,
      "y": -6,
      "z": 4,
      "name": "Rock_Stone",
      "rotation": 12
    },
    {
      "x": -7,
      "y": -5,
      "z": 4,
      "name": "Rock_Stone_Mossy",
      "rotation": 12
    },
    {
      "x": -7,
      "y": -7,
      "z": 5,
      "name": "Rock_Stone",
      "rotation": 12
    },
    {
      "x": -7,
      "y": -6,
      "z": 5,
      "name": "Rock_Stone",
      "rotation": 12
    },
    {
      "x": -6,
      "y": -7,
      "z": -9,
      "name": "Rock_Stone",
      "rotation": 12
    },
    {
      "x": -6,
      "y": -8,
      "z": -8,
      "name": "Rock_Stone",
      "rotation": 12
    },
    {
      "x": -6,
      "y": -7,
      "z": -8,
      "name": "Rock_Stone",
      "rotation": 12
    },
    {
      "x": -6,
      "y": -6,
      "z": -8,
      "name": "Rock_Stone",
      "rotation": 12
    },
    {
      "x": -6,
      "y": -5,
      "z": -8,
      "name": "Rock_Stone",
      "rotation": 12
    },
    {
      "x": -6,
      "y": -4,
      "z": -8,
      "name": "Rock_Stone",
      "rotation": 12
    },
    {
      "x": -6,
      "y": -3,
      "z": -8,
      "name": "Rock_Stone",
      "rotation": 12
    },
    {
      "x": -6,
      "y": -9,
      "z": -7,
      "name": "Rock_Stone",
      "rotation": 12
    },
    {
      "x": -6,
      "y": -8,
      "z": -7,
      "name": "Rock_Stone_Mossy",
      "rotation": 12
    },
    {
      "x": -6,
      "y": -7,
      "z": -7,
      "name": "Rock_Stone",
      "rotation": 12
    },
    {
      "x": -6,
      "y": -6,
      "z": -7,
      "name": "Rock_Stone_Mossy",
      "rotation": 12
    },
    {
      "x": -6,
      "y": -5,
      "z": -7,
      "name": "Rock_Stone_Mossy",
      "rotation": 12
    },
    {
      "x": -6,
      "y": -4,
      "z": -7,
      "name": "Rock_Stone",
      "rotation": 12
    },
    {
      "x": -6,
      "y": -3,
      "z": -7,
      "name": "Rock_Stone",
      "rotation": 12
    },
    {
      "x": -6,
      "y": -2,
      "z": -7,
      "name": "Rock_Stone",
      "rotation": 12
    },
    {
      "x": -6,
      "y": -1,
      "z": -7,
      "name": "Rock_Stone",
      "rotation": 12
    },
    {
      "x": -6,
      "y": -9,
      "z": -6,
      "name": "Rock_Stone_Mossy",
      "rotation": 12
    },
    {
      "x": -6,
      "y": -8,
      "z": -6,
      "name": "Rock_Stone",
      "rotation": 12
    },
    {
      "x": -6,
      "y": -7,
      "z": -6,
      "name": "Rock_Stone",
      "rotation": 12
    },
    {
      "x": -6,
      "y": -6,
      "z": -6,
      "name": "Rock_Stone",
      "rotation": 12
    },
    {
      "x": -6,
      "y": -5,
      "z": -6,
      "name": "Rock_Stone",
      "rotation": 12
    },
    {
      "x": -6,
      "y": -4,
      "z": -6,
      "name": "Rock_Stone",
      "rotation": 12
    },
    {
      "x": -6,
      "y": -3,
      "z": -6,
      "name": "Rock_Stone",
      "rotation": 12
    },
    {
      "x": -6,
      "y": -2,
      "z": -6,
      "name": "Rock_Stone_Mossy",
      "rotation": 12
    },
    {
      "x": -6,
      "y": -1,
      "z": -6,
      "name": "Rock_Stone",
      "rotation": 12
    },
    {
      "x": -6,
      "y": -9,
      "z": -5,
      "name": "Rock_Stone_Mossy",
      "rotation": 12
    },
    {
      "x": -6,
      "y": -8,
      "z": -5,
      "name": "Rock_Stone",
      "rotation": 12
    },
    {
      "x": -6,
      "y": -7,
      "z": -5,
      "name": "Rock_Stone",
      "rotation": 12
    },
    {
      "x": -6,
      "y": -6,
      "z": -5,
      "name": "Rock_Stone_Mossy",
      "rotation": 12
    },
    {
      "x": -6,
      "y": -5,
      "z": -5,
      "name": "Rock_Stone",
      "rotation": 12
    },
    {
      "x": -6,
      "y": -4,
      "z": -5,
      "name": "Rock_Stone",
      "rotation": 12
    },
    {
      "x": -6,
      "y": -3,
      "z": -5,
      "name": "Rock_Stone",
      "rotation": 12
    },
    {
      "x": -6,
      "y": -2,
      "z": -5,
      "name": "Rock_Stone",
      "rotation": 12
    },
    {
      "x": -6,
      "y": -1,
      "z": -5,
      "name": "Rock_Stone",
      "rotation": 12
    },
    {
      "x": -6,
      "y": -9,
      "z": -4,
      "name": "Rock_Stone_Mossy",
      "rotation": 12
    },
    {
      "x": -6,
      "y": -8,
      "z": -4,
      "name": "Rock_Stone",
      "rotation": 12
    },
    {
      "x": -6,
      "y": -7,
      "z": -4,
      "name": "Rock_Stone_Mossy",
      "rotation": 12
    },
    {
      "x": -6,
      "y": -6,
      "z": -4,
      "name": "Rock_Stone",
      "rotation": 12
    },
    {
      "x": -6,
      "y": -5,
      "z": -4,
      "name": "Rock_Stone_Mossy",
      "rotation": 12
    },
    {
      "x": -6,
      "y": -4,
      "z": -4,
      "name": "Rock_Stone",
      "rotation": 12
    },
    {
      "x": -6,
      "y": -3,
      "z": -4,
      "name": "Rock_Stone",
      "rotation": 12
    },
    {
      "x": -6,
      "y": -2,
      "z": -4,
      "name": "Rock_Stone",
      "rotation": 12
    },
    {
      "x": -6,
      "y": -1,
      "z": -4,
      "name": "Rock_Stone",
      "rotation": 12
    },
    {
      "x": -6,
      "y": -9,
      "z": -3,
      "name": "Rock_Stone",
      "rotation": 12
    },
    {
      "x": -6,
      "y": -8,
      "z": -3,
      "name": "Rock_Stone_Mossy",
      "rotation": 12
    },
    {
      "x": -6,
      "y": -7,
      "z": -3,
      "name": "Rock_Stone",
      "rotation": 12
    },
    {
      "x": -6,
      "y": -6,
      "z": -3,
      "name": "Rock_Stone",
      "rotation": 12
    },
    {
      "x": -6,
      "y": -5,
      "z": -3,
      "name": "Rock_Stone_Mossy",
      "rotation": 12
    },
    {
      "x": -6,
      "y": -4,
      "z": -3,
      "name": "Rock_Stone",
      "rotation": 12
    },
    {
      "x": -6,
      "y": -3,
      "z": -3,
      "name": "Rock_Stone",
      "rotation": 12
    },
    {
      "x": -6,
      "y": -2,
      "z": -3,
      "name": "Rock_Stone",
      "rotation": 12
    },
    {
      "x": -6,
      "y": -1,
      "z": -3,
      "name": "Rock_Stone",
      "rotation": 12
    },
    {
      "x": -6,
      "y": -9,
      "z": -2,
      "name": "Rock_Stone",
      "rotation": 12
    },
    {
      "x": -6,
      "y": -8,
      "z": -2,
      "name": "Rock_Stone",
      "rotation": 12
    },
    {
      "x": -6,
      "y": -7,
      "z": -2,
      "name": "Rock_Stone",
      "rotation": 12
    },
    {
      "x": -6,
      "y": -6,
      "z": -2,
      "name": "Rock_Stone",
      "rotation": 12
    },
    {
      "x": -6,
      "y": -5,
      "z": -2,
      "name": "Rock_Stone_Mossy",
      "rotation": 12
    },
    {
      "x": -6,
      "y": -4,
      "z": -2,
      "name": "Rock_Stone",
      "rotation": 12
    },
    {
      "x": -6,
      "y": -3,
      "z": -2,
      "name": "Rock_Stone",
      "rotation": 12
    },
    {
      "x": -6,
      "y": -2,
      "z": -2,
      "name": "Rock_Stone",
      "rotation": 12
    },
    {
      "x": -6,
      "y": -1,
      "z": -2,
      "name": "Rock_Stone_Mossy",
      "rotation": 12
    },
    {
      "x": -6,
      "y": -10,
      "z": -1,
      "name": "Rock_Stone",
      "rotation": 12
    },
    {
      "x": -6,
      "y": -9,
      "z": -1,
      "name": "Rock_Stone",
      "rotation": 12
    },
    {
      "x": -6,
      "y": -8,
      "z": -1,
      "name": "Rock_Stone",
      "rotation": 12
    },
    {
      "x": -6,
      "y": -7,
      "z": -1,
      "name": "Rock_Stone",
      "rotation": 12
    },
    {
      "x": -6,
      "y": -6,
      "z": -1,
      "name": "Rock_Stone",
      "rotation": 12
    },
    {
      "x": -6,
      "y": -5,
      "z": -1,
      "name": "Rock_Stone",
      "rotation": 12
    },
    {
      "x": -6,
      "y": -4,
      "z": -1,
      "name": "Rock_Stone",
      "rotation": 12
    },
    {
      "x": -6,
      "y": -3,
      "z": -1,
      "name": "Rock_Stone",
      "rotation": 12
    },
    {
      "x": -6,
      "y": -2,
      "z": -1,
      "name": "Rock_Stone",
      "rotation": 12
    },
    {
      "x": -6,
      "y": -10,
      "z": 0,
      "name": "Rock_Stone",
      "rotation": 12
    },
    {
      "x": -6,
      "y": -9,
      "z": 0,
      "name": "Rock_Stone",
      "rotation": 12
    },
    {
      "x": -6,
      "y": -8,
      "z": 0,
      "name": "Rock_Stone",
      "rotation": 12
    },
    {
      "x": -6,
      "y": -7,
      "z": 0,
      "name": "Rock_Stone",
      "rotation": 12
    },
    {
      "x": -6,
      "y": -6,
      "z": 0,
      "name": "Rock_Stone_Mossy",
      "rotation": 12
    },
    {
      "x": -6,
      "y": -5,
      "z": 0,
      "name": "Rock_Stone",
      "rotation": 12
    },
    {
      "x": -6,
      "y": -4,
      "z": 0,
      "name": "Rock_Stone",
      "rotation": 12
    },
    {
      "x": -6,
      "y": -3,
      "z": 0,
      "name": "Rock_Stone",
      "rotation": 12
    },
    {
      "x": -6,
      "y": -2,
      "z": 0,
      "name": "Rock_Stone_Mossy",
      "rotation": 12
    },
    {
      "x": -6,
      "y": -10,
      "z": 1,
      "name": "Rock_Stone",
      "rotation": 12
    },
    {
      "x": -6,
      "y": -9,
      "z": 1,
      "name": "Rock_Stone",
      "rotation": 12
    },
    {
      "x": -6,
      "y": -8,
      "z": 1,
      "name": "Rock_Stone",
      "rotation": 12
    },
    {
      "x": -6,
      "y": -7,
      "z": 1,
      "name": "Rock_Stone",
      "rotation": 12
    },
    {
      "x": -6,
      "y": -6,
      "z": 1,
      "name": "Rock_Stone",
      "rotation": 12
    },
    {
      "x": -6,
      "y": -5,
      "z": 1,
      "name": "Rock_Stone",
      "rotation": 12
    },
    {
      "x": -6,
      "y": -4,
      "z": 1,
      "name": "Rock_Stone",
      "rotation": 12
    },
    {
      "x": -6,
      "y": -3,
      "z": 1,
      "name": "Rock_Stone",
      "rotation": 12
    },
    {
      "x": -6,
      "y": -2,
      "z": 1,
      "name": "Rock_Stone",
      "rotation": 12
    },
    {
      "x": -6,
      "y": -10,
      "z": 2,
      "name": "Rock_Stone_Mossy",
      "rotation": 12
    },
    {
      "x": -6,
      "y": -9,
      "z": 2,
      "name": "Rock_Stone",
      "rotation": 12
    },
    {
      "x": -6,
      "y": -8,
      "z": 2,
      "name": "Rock_Stone",
      "rotation": 12
    },
    {
      "x": -6,
      "y": -7,
      "z": 2,
      "name": "Rock_Stone",
      "rotation": 12
    },
    {
      "x": -6,
      "y": -6,
      "z": 2,
      "name": "Rock_Stone",
      "rotation": 12
    },
    {
      "x": -6,
      "y": -5,
      "z": 2,
      "name": "Rock_Stone_Mossy",
      "rotation": 12
    },
    {
      "x": -6,
      "y": -4,
      "z": 2,
      "name": "Rock_Stone",
      "rotation": 12
    },
    {
      "x": -6,
      "y": -3,
      "z": 2,
      "name": "Rock_Stone",
      "rotation": 12
    },
    {
      "x": -6,
      "y": -2,
      "z": 2,
      "name": "Rock_Stone",
      "rotation": 12
    },
    {
      "x": -6,
      "y": -10,
      "z": 3,
      "name": "Rock_Stone",
      "rotation": 12
    },
    {
      "x": -6,
      "y": -9,
      "z": 3,
      "name": "Rock_Stone",
      "rotation": 12
    },
    {
      "x": -6,
      "y": -8,
      "z": 3,
      "name": "Rock_Stone",
      "rotation": 12
    },
    {
      "x": -6,
      "y": -7,
      "z": 3,
      "name": "Rock_Stone_Mossy",
      "rotation": 12
    },
    {
      "x": -6,
      "y": -6,
      "z": 3,
      "name": "Rock_Stone_Mossy",
      "rotation": 12
    },
    {
      "x": -6,
      "y": -5,
      "z": 3,
      "name": "Rock_Stone",
      "rotation": 12
    },
    {
      "x": -6,
      "y": -4,
      "z": 3,
      "name": "Rock_Stone_Mossy",
      "rotation": 12
    },
    {
      "x": -6,
      "y": -3,
      "z": 3,
      "name": "Rock_Stone",
      "rotation": 12
    },
    {
      "x": -6,
      "y": -2,
      "z": 3,
      "name": "Rock_Stone",
      "rotation": 12
    },
    {
      "x": -6,
      "y": -10,
      "z": 4,
      "name": "Rock_Stone_Mossy",
      "rotation": 12
    },
    {
      "x": -6,
      "y": -9,
      "z": 4,
      "name": "Rock_Stone",
      "rotation": 12
    },
    {
      "x": -6,
      "y": -8,
      "z": 4,
      "name": "Rock_Stone",
      "rotation": 12
    },
    {
      "x": -6,
      "y": -7,
      "z": 4,
      "name": "Rock_Stone_Mossy",
      "rotation": 12
    },
    {
      "x": -6,
      "y": -6,
      "z": 4,
      "name": "Rock_Stone_Mossy",
      "rotation": 12
    },
    {
      "x": -6,
      "y": -5,
      "z": 4,
      "name": "Rock_Stone",
      "rotation": 12
    },
    {
      "x": -6,
      "y": -4,
      "z": 4,
      "name": "Rock_Stone",
      "rotation": 12
    },
    {
      "x": -6,
      "y": -3,
      "z": 4,
      "name": "Rock_Stone",
      "rotation": 12
    },
    {
      "x": -6,
      "y": -2,
      "z": 4,
      "name": "Rock_Stone",
      "rotation": 12
    },
    {
      "x": -6,
      "y": -10,
      "z": 5,
      "name": "Rock_Stone",
      "rotation": 12
    },
    {
      "x": -6,
      "y": -9,
      "z": 5,
      "name": "Rock_Stone",
      "rotation": 12
    },
    {
      "x": -6,
      "y": -8,
      "z": 5,
      "name": "Rock_Stone_Mossy",
      "rotation": 12
    },
    {
      "x": -6,
      "y": -7,
      "z": 5,
      "name": "Rock_Stone",
      "rotation": 12
    },
    {
      "x": -6,
      "y": -6,
      "z": 5,
      "name": "Rock_Stone",
      "rotation": 12
    },
    {
      "x": -6,
      "y": -5,
      "z": 5,
      "name": "Rock_Stone_Mossy",
      "rotation": 12
    },
    {
      "x": -6,
      "y": -4,
      "z": 5,
      "name": "Rock_Stone",
      "rotation": 12
    },
    {
      "x": -6,
      "y": -7,
      "z": 6,
      "name": "Rock_Stone_Mossy",
      "rotation": 12
    },
    {
      "x": -6,
      "y": -6,
      "z": 6,
      "name": "Rock_Stone",
      "rotation": 12
    },
    {
      "x": -5,
      "y": -7,
      "z": -9,
      "name": "Rock_Stone",
      "rotation": 12
    },
    {
      "x": -5,
      "y": -8,
      "z": -8,
      "name": "Rock_Stone",
      "rotation": 12
    },
    {
      "x": -5,
      "y": -7,
      "z": -8,
      "name": "Rock_Stone_Mossy",
      "rotation": 12
    },
    {
      "x": -5,
      "y": -6,
      "z": -8,
      "name": "Rock_Stone_Mossy",
      "rotation": 12
    },
    {
      "x": -5,
      "y": -5,
      "z": -8,
      "name": "Rock_Stone",
      "rotation": 12
    },
    {
      "x": -5,
      "y": -4,
      "z": -8,
      "name": "Rock_Stone_Mossy",
      "rotation": 12
    },
    {
      "x": -5,
      "y": -3,
      "z": -8,
      "name": "Rock_Stone",
      "rotation": 12
    },
    {
      "x": -5,
      "y": -9,
      "z": -7,
      "name": "Rock_Stone",
      "rotation": 12
    },
    {
      "x": -5,
      "y": -8,
      "z": -7,
      "name": "Rock_Stone",
      "rotation": 12
    },
    {
      "x": -5,
      "y": -7,
      "z": -7,
      "name": "Rock_Stone_Mossy",
      "rotation": 12
    },
    {
      "x": -5,
      "y": -6,
      "z": -7,
      "name": "Rock_Stone",
      "rotation": 12
    },
    {
      "x": -5,
      "y": -5,
      "z": -7,
      "name": "Rock_Stone",
      "rotation": 12
    },
    {
      "x": -5,
      "y": -4,
      "z": -7,
      "name": "Rock_Stone",
      "rotation": 12
    },
    {
      "x": -5,
      "y": -3,
      "z": -7,
      "name": "Rock_Stone",
      "rotation": 12
    },
    {
      "x": -5,
      "y": -2,
      "z": -7,
      "name": "Rock_Stone",
      "rotation": 12
    },
    {
      "x": -5,
      "y": -1,
      "z": -7,
      "name": "Rock_Stone",
      "rotation": 12
    },
    {
      "x": -5,
      "y": -9,
      "z": -6,
      "name": "Rock_Stone",
      "rotation": 12
    },
    {
      "x": -5,
      "y": -8,
      "z": -6,
      "name": "Rock_Stone",
      "rotation": 12
    },
    {
      "x": -5,
      "y": -7,
      "z": -6,
      "name": "Rock_Stone",
      "rotation": 12
    },
    {
      "x": -5,
      "y": -6,
      "z": -6,
      "name": "Rock_Stone_Mossy",
      "rotation": 12
    },
    {
      "x": -5,
      "y": -5,
      "z": -6,
      "name": "Rock_Stone",
      "rotation": 12
    },
    {
      "x": -5,
      "y": -4,
      "z": -6,
      "name": "Rock_Stone",
      "rotation": 12
    },
    {
      "x": -5,
      "y": -3,
      "z": -6,
      "name": "Rock_Stone",
      "rotation": 12
    },
    {
      "x": -5,
      "y": -2,
      "z": -6,
      "name": "Rock_Stone",
      "rotation": 12
    },
    {
      "x": -5,
      "y": -1,
      "z": -6,
      "name": "Rock_Stone",
      "rotation": 12
    },
    {
      "x": -5,
      "y": -9,
      "z": -5,
      "name": "Rock_Stone",
      "rotation": 12
    },
    {
      "x": -5,
      "y": -8,
      "z": -5,
      "name": "Rock_Stone",
      "rotation": 12
    },
    {
      "x": -5,
      "y": -7,
      "z": -5,
      "name": "Rock_Stone",
      "rotation": 12
    },
    {
      "x": -5,
      "y": -6,
      "z": -5,
      "name": "Rock_Stone",
      "rotation": 12
    },
    {
      "x": -5,
      "y": -5,
      "z": -5,
      "name": "Rock_Stone",
      "rotation": 12
    },
    {
      "x": -5,
      "y": -4,
      "z": -5,
      "name": "Rock_Stone",
      "rotation": 12
    },
    {
      "x": -5,
      "y": -3,
      "z": -5,
      "name": "Rock_Stone",
      "rotation": 12
    },
    {
      "x": -5,
      "y": -2,
      "z": -5,
      "name": "Rock_Stone",
      "rotation": 12
    },
    {
      "x": -5,
      "y": -1,
      "z": -5,
      "name": "Rock_Stone_Mossy",
      "rotation": 12
    },
    {
      "x": -5,
      "y": 0,
      "z": -5,
      "name": "Rock_Stone",
      "rotation": 12
    },
    {
      "x": -5,
      "y": -9,
      "z": -4,
      "name": "Rock_Stone",
      "rotation": 12
    },
    {
      "x": -5,
      "y": -8,
      "z": -4,
      "name": "Rock_Stone",
      "rotation": 12
    },
    {
      "x": -5,
      "y": -7,
      "z": -4,
      "name": "Rock_Stone_Mossy",
      "rotation": 12
    },
    {
      "x": -5,
      "y": -6,
      "z": -4,
      "name": "Rock_Stone_Mossy",
      "rotation": 12
    },
    {
      "x": -5,
      "y": -5,
      "z": -4,
      "name": "Rock_Stone",
      "rotation": 12
    },
    {
      "x": -5,
      "y": -4,
      "z": -4,
      "name": "Rock_Stone",
      "rotation": 12
    },
    {
      "x": -5,
      "y": -3,
      "z": -4,
      "name": "Rock_Stone_Mossy",
      "rotation": 12
    },
    {
      "x": -5,
      "y": -2,
      "z": -4,
      "name": "Rock_Stone",
      "rotation": 12
    },
    {
      "x": -5,
      "y": -1,
      "z": -4,
      "name": "Rock_Stone_Mossy",
      "rotation": 12
    },
    {
      "x": -5,
      "y": 0,
      "z": -4,
      "name": "Rock_Stone_Mossy",
      "rotation": 12
    },
    {
      "x": -5,
      "y": 1,
      "z": -4,
      "name": "Rock_Stone_Mossy",
      "rotation": 12
    },
    {
      "x": -5,
      "y": 2,
      "z": -4,
      "name": "Rock_Stone",
      "rotation": 12
    },
    {
      "x": -5,
      "y": 3,
      "z": -4,
      "name": "Rock_Stone",
      "rotation": 12
    },
    {
      "x": -5,
      "y": -9,
      "z": -3,
      "name": "Rock_Stone",
      "rotation": 12
    },
    {
      "x": -5,
      "y": -8,
      "z": -3,
      "name": "Rock_Stone_Mossy",
      "rotation": 12
    },
    {
      "x": -5,
      "y": -7,
      "z": -3,
      "name": "Rock_Stone",
      "rotation": 12
    },
    {
      "x": -5,
      "y": -6,
      "z": -3,
      "name": "Rock_Stone",
      "rotation": 12
    },
    {
      "x": -5,
      "y": -5,
      "z": -3,
      "name": "Rock_Stone",
      "rotation": 12
    },
    {
      "x": -5,
      "y": -4,
      "z": -3,
      "name": "Rock_Stone",
      "rotation": 12
    },
    {
      "x": -5,
      "y": -3,
      "z": -3,
      "name": "Rock_Stone",
      "rotation": 12
    },
    {
      "x": -5,
      "y": -2,
      "z": -3,
      "name": "Rock_Stone",
      "rotation": 12
    },
    {
      "x": -5,
      "y": -1,
      "z": -3,
      "name": "Rock_Stone_Mossy",
      "rotation": 12
    },
    {
      "x": -5,
      "y": 0,
      "z": -3,
      "name": "Rock_Stone",
      "rotation": 12
    },
    {
      "x": -5,
      "y": 1,
      "z": -3,
      "name": "Rock_Stone",
      "rotation": 12
    },
    {
      "x": -5,
      "y": 2,
      "z": -3,
      "name": "Rock_Stone",
      "rotation": 12
    },
    {
      "x": -5,
      "y": 3,
      "z": -3,
      "name": "Rock_Stone",
      "rotation": 12
    },
    {
      "x": -5,
      "y": -9,
      "z": -2,
      "name": "Rock_Stone",
      "rotation": 12
    },
    {
      "x": -5,
      "y": -8,
      "z": -2,
      "name": "Rock_Stone",
      "rotation": 12
    },
    {
      "x": -5,
      "y": -7,
      "z": -2,
      "name": "Rock_Stone",
      "rotation": 12
    },
    {
      "x": -5,
      "y": -6,
      "z": -2,
      "name": "Rock_Stone",
      "rotation": 12
    },
    {
      "x": -5,
      "y": -5,
      "z": -2,
      "name": "Rock_Stone",
      "rotation": 12
    },
    {
      "x": -5,
      "y": -4,
      "z": -2,
      "name": "Rock_Stone",
      "rotation": 12
    },
    {
      "x": -5,
      "y": -3,
      "z": -2,
      "name": "Rock_Stone",
      "rotation": 12
    },
    {
      "x": -5,
      "y": -2,
      "z": -2,
      "name": "Rock_Stone",
      "rotation": 12
    },
    {
      "x": -5,
      "y": -1,
      "z": -2,
      "name": "Rock_Stone",
      "rotation": 12
    },
    {
      "x": -5,
      "y": 0,
      "z": -2,
      "name": "Rock_Stone_Mossy",
      "rotation": 12
    },
    {
      "x": -5,
      "y": 1,
      "z": -2,
      "name": "Rock_Stone",
      "rotation": 12
    },
    {
      "x": -5,
      "y": 2,
      "z": -2,
      "name": "Rock_Stone",
      "rotation": 12
    },
    {
      "x": -5,
      "y": 3,
      "z": -2,
      "name": "Rock_Stone",
      "rotation": 12
    },
    {
      "x": -5,
      "y": -10,
      "z": -1,
      "name": "Rock_Stone",
      "rotation": 12
    },
    {
      "x": -5,
      "y": -9,
      "z": -1,
      "name": "Rock_Stone",
      "rotation": 12
    },
    {
      "x": -5,
      "y": -8,
      "z": -1,
      "name": "Rock_Stone_Mossy",
      "rotation": 12
    },
    {
      "x": -5,
      "y": -7,
      "z": -1,
      "name": "Rock_Stone",
      "rotation": 12
    },
    {
      "x": -5,
      "y": -6,
      "z": -1,
      "name": "Rock_Stone",
      "rotation": 12
    },
    {
      "x": -5,
      "y": -5,
      "z": -1,
      "name": "Rock_Stone",
      "rotation": 12
    },
    {
      "x": -5,
      "y": -4,
      "z": -1,
      "name": "Rock_Stone",
      "rotation": 12
    },
    {
      "x": -5,
      "y": -3,
      "z": -1,
      "name": "Rock_Stone_Mossy",
      "rotation": 12
    },
    {
      "x": -5,
      "y": -2,
      "z": -1,
      "name": "Rock_Stone",
      "rotation": 12
    },
    {
      "x": -5,
      "y": -1,
      "z": -1,
      "name": "Rock_Stone",
      "rotation": 12
    },
    {
      "x": -5,
      "y": 0,
      "z": -1,
      "name": "Rock_Stone",
      "rotation": 12
    },
    {
      "x": -5,
      "y": 1,
      "z": -1,
      "name": "Rock_Stone",
      "rotation": 12
    },
    {
      "x": -5,
      "y": -10,
      "z": 0,
      "name": "Rock_Stone",
      "rotation": 12
    },
    {
      "x": -5,
      "y": -9,
      "z": 0,
      "name": "Rock_Stone",
      "rotation": 12
    },
    {
      "x": -5,
      "y": -8,
      "z": 0,
      "name": "Rock_Stone_Mossy",
      "rotation": 12
    },
    {
      "x": -5,
      "y": -7,
      "z": 0,
      "name": "Rock_Stone",
      "rotation": 12
    },
    {
      "x": -5,
      "y": -6,
      "z": 0,
      "name": "Rock_Stone",
      "rotation": 12
    },
    {
      "x": -5,
      "y": -5,
      "z": 0,
      "name": "Rock_Stone",
      "rotation": 12
    },
    {
      "x": -5,
      "y": -4,
      "z": 0,
      "name": "Rock_Stone",
      "rotation": 12
    },
    {
      "x": -5,
      "y": -3,
      "z": 0,
      "name": "Rock_Stone",
      "rotation": 12
    },
    {
      "x": -5,
      "y": -2,
      "z": 0,
      "name": "Rock_Stone_Mossy",
      "rotation": 12
    },
    {
      "x": -5,
      "y": -1,
      "z": 0,
      "name": "Rock_Stone",
      "rotation": 12
    },
    {
      "x": -5,
      "y": 0,
      "z": 0,
      "name": "Rock_Stone",
      "rotation": 12
    },
    {
      "x": -5,
      "y": 1,
      "z": 0,
      "name": "Rock_Stone",
      "rotation": 12
    },
    {
      "x": -5,
      "y": -10,
      "z": 1,
      "name": "Rock_Stone",
      "rotation": 12
    },
    {
      "x": -5,
      "y": -9,
      "z": 1,
      "name": "Rock_Stone_Mossy",
      "rotation": 12
    },
    {
      "x": -5,
      "y": -8,
      "z": 1,
      "name": "Rock_Stone",
      "rotation": 12
    },
    {
      "x": -5,
      "y": -7,
      "z": 1,
      "name": "Rock_Stone",
      "rotation": 12
    },
    {
      "x": -5,
      "y": -6,
      "z": 1,
      "name": "Rock_Stone",
      "rotation": 12
    },
    {
      "x": -5,
      "y": -5,
      "z": 1,
      "name": "Rock_Stone",
      "rotation": 12
    },
    {
      "x": -5,
      "y": -4,
      "z": 1,
      "name": "Rock_Stone",
      "rotation": 12
    },
    {
      "x": -5,
      "y": -3,
      "z": 1,
      "name": "Rock_Stone",
      "rotation": 12
    },
    {
      "x": -5,
      "y": -2,
      "z": 1,
      "name": "Rock_Stone",
      "rotation": 12
    },
    {
      "x": -5,
      "y": -1,
      "z": 1,
      "name": "Rock_Stone_Mossy",
      "rotation": 12
    },
    {
      "x": -5,
      "y": 0,
      "z": 1,
      "name": "Rock_Stone",
      "rotation": 12
    },
    {
      "x": -5,
      "y": 1,
      "z": 1,
      "name": "Rock_Stone",
      "rotation": 12
    },
    {
      "x": -5,
      "y": 2,
      "z": 1,
      "name": "Rock_Stone",
      "rotation": 12
    },
    {
      "x": -5,
      "y": -10,
      "z": 2,
      "name": "Rock_Stone",
      "rotation": 12
    },
    {
      "x": -5,
      "y": -9,
      "z": 2,
      "name": "Rock_Stone",
      "rotation": 12
    },
    {
      "x": -5,
      "y": -8,
      "z": 2,
      "name": "Rock_Stone",
      "rotation": 12
    },
    {
      "x": -5,
      "y": -7,
      "z": 2,
      "name": "Rock_Stone",
      "rotation": 12
    },
    {
      "x": -5,
      "y": -6,
      "z": 2,
      "name": "Rock_Stone_Mossy",
      "rotation": 12
    },
    {
      "x": -5,
      "y": -5,
      "z": 2,
      "name": "Rock_Stone",
      "rotation": 12
    },
    {
      "x": -5,
      "y": -4,
      "z": 2,
      "name": "Rock_Stone_Mossy",
      "rotation": 12
    },
    {
      "x": -5,
      "y": -3,
      "z": 2,
      "name": "Rock_Stone_Mossy",
      "rotation": 12
    },
    {
      "x": -5,
      "y": -2,
      "z": 2,
      "name": "Rock_Stone_Mossy",
      "rotation": 12
    },
    {
      "x": -5,
      "y": -1,
      "z": 2,
      "name": "Rock_Stone",
      "rotation": 12
    },
    {
      "x": -5,
      "y": 0,
      "z": 2,
      "name": "Rock_Stone",
      "rotation": 12
    },
    {
      "x": -5,
      "y": 1,
      "z": 2,
      "name": "Rock_Stone_Mossy",
      "rotation": 12
    },
    {
      "x": -5,
      "y": 2,
      "z": 2,
      "name": "Rock_Stone",
      "rotation": 12
    },
    {
      "x": -5,
      "y": -10,
      "z": 3,
      "name": "Rock_Stone",
      "rotation": 12
    },
    {
      "x": -5,
      "y": -9,
      "z": 3,
      "name": "Rock_Stone",
      "rotation": 12
    },
    {
      "x": -5,
      "y": -8,
      "z": 3,
      "name": "Rock_Stone",
      "rotation": 12
    },
    {
      "x": -5,
      "y": -7,
      "z": 3,
      "name": "Rock_Stone",
      "rotation": 12
    },
    {
      "x": -5,
      "y": -6,
      "z": 3,
      "name": "Rock_Stone",
      "rotation": 12
    },
    {
      "x": -5,
      "y": -5,
      "z": 3,
      "name": "Rock_Stone",
      "rotation": 12
    },
    {
      "x": -5,
      "y": -4,
      "z": 3,
      "name": "Rock_Stone",
      "rotation": 12
    },
    {
      "x": -5,
      "y": -3,
      "z": 3,
      "name": "Rock_Stone_Mossy",
      "rotation": 12
    },
    {
      "x": -5,
      "y": -2,
      "z": 3,
      "name": "Rock_Stone",
      "rotation": 12
    },
    {
      "x": -5,
      "y": -1,
      "z": 3,
      "name": "Rock_Stone",
      "rotation": 12
    },
    {
      "x": -5,
      "y": 0,
      "z": 3,
      "name": "Rock_Stone",
      "rotation": 12
    },
    {
      "x": -5,
      "y": 1,
      "z": 3,
      "name": "Rock_Stone",
      "rotation": 12
    },
    {
      "x": -5,
      "y": 2,
      "z": 3,
      "name": "Rock_Stone",
      "rotation": 12
    },
    {
      "x": -5,
      "y": -10,
      "z": 4,
      "name": "Rock_Stone_Mossy",
      "rotation": 12
    },
    {
      "x": -5,
      "y": -9,
      "z": 4,
      "name": "Rock_Stone",
      "rotation": 12
    },
    {
      "x": -5,
      "y": -8,
      "z": 4,
      "name": "Rock_Stone",
      "rotation": 12
    },
    {
      "x": -5,
      "y": -7,
      "z": 4,
      "name": "Rock_Stone",
      "rotation": 12
    },
    {
      "x": -5,
      "y": -6,
      "z": 4,
      "name": "Rock_Stone",
      "rotation": 12
    },
    {
      "x": -5,
      "y": -5,
      "z": 4,
      "name": "Rock_Stone",
      "rotation": 12
    },
    {
      "x": -5,
      "y": -4,
      "z": 4,
      "name": "Rock_Stone_Mossy",
      "rotation": 12
    },
    {
      "x": -5,
      "y": -3,
      "z": 4,
      "name": "Rock_Stone",
      "rotation": 12
    },
    {
      "x": -5,
      "y": -2,
      "z": 4,
      "name": "Rock_Stone",
      "rotation": 12
    },
    {
      "x": -5,
      "y": -1,
      "z": 4,
      "name": "Rock_Stone",
      "rotation": 12
    },
    {
      "x": -5,
      "y": 0,
      "z": 4,
      "name": "Rock_Stone_Mossy",
      "rotation": 12
    },
    {
      "x": -5,
      "y": 1,
      "z": 4,
      "name": "Rock_Stone",
      "rotation": 12
    },
    {
      "x": -5,
      "y": 2,
      "z": 4,
      "name": "Rock_Stone",
      "rotation": 12
    },
    {
      "x": -5,
      "y": -10,
      "z": 5,
      "name": "Rock_Stone_Mossy",
      "rotation": 12
    },
    {
      "x": -5,
      "y": -9,
      "z": 5,
      "name": "Rock_Stone",
      "rotation": 12
    },
    {
      "x": -5,
      "y": -8,
      "z": 5,
      "name": "Rock_Stone",
      "rotation": 12
    },
    {
      "x": -5,
      "y": -7,
      "z": 5,
      "name": "Rock_Stone",
      "rotation": 12
    },
    {
      "x": -5,
      "y": -6,
      "z": 5,
      "name": "Rock_Stone",
      "rotation": 12
    },
    {
      "x": -5,
      "y": -5,
      "z": 5,
      "name": "Rock_Stone",
      "rotation": 12
    },
    {
      "x": -5,
      "y": -4,
      "z": 5,
      "name": "Rock_Stone",
      "rotation": 12
    },
    {
      "x": -5,
      "y": -3,
      "z": 5,
      "name": "Rock_Stone",
      "rotation": 12
    },
    {
      "x": -5,
      "y": -7,
      "z": 6,
      "name": "Rock_Stone_Mossy",
      "rotation": 12
    },
    {
      "x": -5,
      "y": -6,
      "z": 6,
      "name": "Rock_Stone",
      "rotation": 12
    },
    {
      "x": -4,
      "y": -7,
      "z": -9,
      "name": "Rock_Stone",
      "rotation": 12
    },
    {
      "x": -4,
      "y": -8,
      "z": -8,
      "name": "Rock_Stone",
      "rotation": 12
    },
    {
      "x": -4,
      "y": -7,
      "z": -8,
      "name": "Rock_Stone",
      "rotation": 12
    },
    {
      "x": -4,
      "y": -6,
      "z": -8,
      "name": "Rock_Stone",
      "rotation": 12
    },
    {
      "x": -4,
      "y": -5,
      "z": -8,
      "name": "Rock_Stone",
      "rotation": 12
    },
    {
      "x": -4,
      "y": -4,
      "z": -8,
      "name": "Rock_Stone_Mossy",
      "rotation": 12
    },
    {
      "x": -4,
      "y": -3,
      "z": -8,
      "name": "Rock_Stone",
      "rotation": 12
    },
    {
      "x": -4,
      "y": -9,
      "z": -7,
      "name": "Rock_Stone",
      "rotation": 12
    },
    {
      "x": -4,
      "y": -8,
      "z": -7,
      "name": "Rock_Stone",
      "rotation": 12
    },
    {
      "x": -4,
      "y": -7,
      "z": -7,
      "name": "Rock_Stone",
      "rotation": 12
    },
    {
      "x": -4,
      "y": -6,
      "z": -7,
      "name": "Rock_Stone",
      "rotation": 12
    },
    {
      "x": -4,
      "y": -5,
      "z": -7,
      "name": "Rock_Stone",
      "rotation": 12
    },
    {
      "x": -4,
      "y": -4,
      "z": -7,
      "name": "Rock_Stone_Mossy",
      "rotation": 12
    },
    {
      "x": -4,
      "y": -3,
      "z": -7,
      "name": "Rock_Stone",
      "rotation": 12
    },
    {
      "x": -4,
      "y": -2,
      "z": -7,
      "name": "Rock_Stone",
      "rotation": 12
    },
    {
      "x": -4,
      "y": -1,
      "z": -7,
      "name": "Rock_Stone",
      "rotation": 12
    },
    {
      "x": -4,
      "y": -9,
      "z": -6,
      "name": "Rock_Stone",
      "rotation": 12
    },
    {
      "x": -4,
      "y": -8,
      "z": -6,
      "name": "Rock_Stone",
      "rotation": 12
    },
    {
      "x": -4,
      "y": -7,
      "z": -6,
      "name": "Rock_Stone",
      "rotation": 12
    },
    {
      "x": -4,
      "y": -6,
      "z": -6,
      "name": "Rock_Stone",
      "rotation": 12
    },
    {
      "x": -4,
      "y": -5,
      "z": -6,
      "name": "Rock_Stone_Mossy",
      "rotation": 12
    },
    {
      "x": -4,
      "y": -4,
      "z": -6,
      "name": "Rock_Stone",
      "rotation": 12
    },
    {
      "x": -4,
      "y": -3,
      "z": -6,
      "name": "Rock_Stone",
      "rotation": 12
    },
    {
      "x": -4,
      "y": -2,
      "z": -6,
      "name": "Rock_Stone",
      "rotation": 12
    },
    {
      "x": -4,
      "y": -1,
      "z": -6,
      "name": "Rock_Stone",
      "rotation": 12
    },
    {
      "x": -4,
      "y": -9,
      "z": -5,
      "name": "Rock_Stone",
      "rotation": 12
    },
    {
      "x": -4,
      "y": -8,
      "z": -5,
      "name": "Rock_Stone",
      "rotation": 12
    },
    {
      "x": -4,
      "y": -7,
      "z": -5,
      "name": "Rock_Stone_Mossy",
      "rotation": 12
    },
    {
      "x": -4,
      "y": -6,
      "z": -5,
      "name": "Rock_Stone",
      "rotation": 12
    },
    {
      "x": -4,
      "y": -5,
      "z": -5,
      "name": "Rock_Stone",
      "rotation": 12
    },
    {
      "x": -4,
      "y": -4,
      "z": -5,
      "name": "Rock_Stone",
      "rotation": 12
    },
    {
      "x": -4,
      "y": -3,
      "z": -5,
      "name": "Rock_Stone",
      "rotation": 12
    },
    {
      "x": -4,
      "y": -2,
      "z": -5,
      "name": "Rock_Stone",
      "rotation": 12
    },
    {
      "x": -4,
      "y": -1,
      "z": -5,
      "name": "Rock_Stone",
      "rotation": 12
    },
    {
      "x": -4,
      "y": 0,
      "z": -5,
      "name": "Rock_Stone",
      "rotation": 12
    },
    {
      "x": -4,
      "y": 1,
      "z": -5,
      "name": "Rock_Stone",
      "rotation": 12
    },
    {
      "x": -4,
      "y": 2,
      "z": -5,
      "name": "Rock_Stone",
      "rotation": 12
    },
    {
      "x": -4,
      "y": 3,
      "z": -5,
      "name": "Rock_Stone",
      "rotation": 12
    },
    {
      "x": -4,
      "y": -9,
      "z": -4,
      "name": "Rock_Stone",
      "rotation": 12
    },
    {
      "x": -4,
      "y": -8,
      "z": -4,
      "name": "Rock_Stone",
      "rotation": 12
    },
    {
      "x": -4,
      "y": -7,
      "z": -4,
      "name": "Rock_Stone",
      "rotation": 12
    },
    {
      "x": -4,
      "y": -6,
      "z": -4,
      "name": "Rock_Stone",
      "rotation": 12
    },
    {
      "x": -4,
      "y": -5,
      "z": -4,
      "name": "Rock_Stone",
      "rotation": 12
    },
    {
      "x": -4,
      "y": -4,
      "z": -4,
      "name": "Rock_Stone",
      "rotation": 12
    },
    {
      "x": -4,
      "y": -3,
      "z": -4,
      "name": "Rock_Stone_Mossy",
      "rotation": 12
    },
    {
      "x": -4,
      "y": -2,
      "z": -4,
      "name": "Rock_Stone_Mossy",
      "rotation": 12
    },
    {
      "x": -4,
      "y": -1,
      "z": -4,
      "name": "Rock_Stone",
      "rotation": 12
    },
    {
      "x": -4,
      "y": 0,
      "z": -4,
      "name": "Rock_Stone",
      "rotation": 12
    },
    {
      "x": -4,
      "y": 1,
      "z": -4,
      "name": "Rock_Stone_Mossy",
      "rotation": 12
    },
    {
      "x": -4,
      "y": 2,
      "z": -4,
      "name": "Rock_Stone_Mossy",
      "rotation": 12
    },
    {
      "x": -4,
      "y": 3,
      "z": -4,
      "name": "Rock_Stone_Mossy",
      "rotation": 12
    },
    {
      "x": -4,
      "y": 4,
      "z": -4,
      "name": "Rock_Stone",
      "rotation": 12
    },
    {
      "x": -4,
      "y": -9,
      "z": -3,
      "name": "Rock_Stone",
      "rotation": 12
    },
    {
      "x": -4,
      "y": -8,
      "z": -3,
      "name": "Rock_Stone",
      "rotation": 12
    },
    {
      "x": -4,
      "y": -7,
      "z": -3,
      "name": "Rock_Stone_Mossy",
      "rotation": 12
    },
    {
      "x": -4,
      "y": -6,
      "z": -3,
      "name": "Rock_Stone",
      "rotation": 12
    },
    {
      "x": -4,
      "y": -5,
      "z": -3,
      "name": "Rock_Stone",
      "rotation": 12
    },
    {
      "x": -4,
      "y": -4,
      "z": -3,
      "name": "Rock_Stone",
      "rotation": 12
    },
    {
      "x": -4,
      "y": -3,
      "z": -3,
      "name": "Rock_Stone",
      "rotation": 12
    },
    {
      "x": -4,
      "y": -2,
      "z": -3,
      "name": "Rock_Stone_Mossy",
      "rotation": 12
    },
    {
      "x": -4,
      "y": -1,
      "z": -3,
      "name": "Rock_Stone",
      "rotation": 12
    },
    {
      "x": -4,
      "y": 0,
      "z": -3,
      "name": "Rock_Stone",
      "rotation": 12
    },
    {
      "x": -4,
      "y": 1,
      "z": -3,
      "name": "Rock_Stone_Mossy",
      "rotation": 12
    },
    {
      "x": -4,
      "y": 2,
      "z": -3,
      "name": "Rock_Stone",
      "rotation": 12
    },
    {
      "x": -4,
      "y": 3,
      "z": -3,
      "name": "Rock_Stone",
      "rotation": 12
    },
    {
      "x": -4,
      "y": 4,
      "z": -3,
      "name": "Rock_Stone",
      "rotation": 12
    },
    {
      "x": -4,
      "y": 5,
      "z": -3,
      "name": "Rock_Stone",
      "rotation": 12
    },
    {
      "x": -4,
      "y": 6,
      "z": -3,
      "name": "Rock_Stone",
      "rotation": 12
    },
    {
      "x": -4,
      "y": -9,
      "z": -2,
      "name": "Rock_Stone",
      "rotation": 12
    },
    {
      "x": -4,
      "y": -8,
      "z": -2,
      "name": "Rock_Stone",
      "rotation": 12
    },
    {
      "x": -4,
      "y": -7,
      "z": -2,
      "name": "Rock_Stone",
      "rotation": 12
    },
    {
      "x": -4,
      "y": -6,
      "z": -2,
      "name": "Rock_Stone",
      "rotation": 12
    },
    {
      "x": -4,
      "y": -5,
      "z": -2,
      "name": "Rock_Stone",
      "rotation": 12
    },
    {
      "x": -4,
      "y": -4,
      "z": -2,
      "name": "Rock_Stone",
      "rotation": 12
    },
    {
      "x": -4,
      "y": -3,
      "z": -2,
      "name": "Rock_Stone",
      "rotation": 12
    },
    {
      "x": -4,
      "y": -2,
      "z": -2,
      "name": "Rock_Stone",
      "rotation": 12
    },
    {
      "x": -4,
      "y": -1,
      "z": -2,
      "name": "Rock_Stone_Mossy",
      "rotation": 12
    },
    {
      "x": -4,
      "y": 0,
      "z": -2,
      "name": "Rock_Stone",
      "rotation": 12
    },
    {
      "x": -4,
      "y": 1,
      "z": -2,
      "name": "Rock_Stone_Mossy",
      "rotation": 12
    },
    {
      "x": -4,
      "y": 2,
      "z": -2,
      "name": "Rock_Stone",
      "rotation": 12
    },
    {
      "x": -4,
      "y": 3,
      "z": -2,
      "name": "Rock_Stone",
      "rotation": 12
    },
    {
      "x": -4,
      "y": 4,
      "z": -2,
      "name": "Rock_Stone_Mossy",
      "rotation": 12
    },
    {
      "x": -4,
      "y": 5,
      "z": -2,
      "name": "Rock_Stone",
      "rotation": 12
    },
    {
      "x": -4,
      "y": 6,
      "z": -2,
      "name": "Rock_Stone_Mossy",
      "rotation": 12
    },
    {
      "x": -4,
      "y": -10,
      "z": -1,
      "name": "Rock_Stone_Mossy",
      "rotation": 12
    },
    {
      "x": -4,
      "y": -9,
      "z": -1,
      "name": "Rock_Stone",
      "rotation": 12
    },
    {
      "x": -4,
      "y": -8,
      "z": -1,
      "name": "Rock_Stone",
      "rotation": 12
    },
    {
      "x": -4,
      "y": -7,
      "z": -1,
      "name": "Rock_Stone",
      "rotation": 12
    },
    {
      "x": -4,
      "y": -6,
      "z": -1,
      "name": "Rock_Stone",
      "rotation": 12
    },
    {
      "x": -4,
      "y": -5,
      "z": -1,
      "name": "Rock_Stone",
      "rotation": 12
    },
    {
      "x": -4,
      "y": -4,
      "z": -1,
      "name": "Rock_Stone",
      "rotation": 12
    },
    {
      "x": -4,
      "y": -3,
      "z": -1,
      "name": "Rock_Stone",
      "rotation": 12
    },
    {
      "x": -4,
      "y": -2,
      "z": -1,
      "name": "Rock_Stone",
      "rotation": 12
    },
    {
      "x": -4,
      "y": -1,
      "z": -1,
      "name": "Rock_Stone",
      "rotation": 12
    },
    {
      "x": -4,
      "y": 0,
      "z": -1,
      "name": "Rock_Stone",
      "rotation": 12
    },
    {
      "x": -4,
      "y": 1,
      "z": -1,
      "name": "Rock_Stone",
      "rotation": 12
    },
    {
      "x": -4,
      "y": 2,
      "z": -1,
      "name": "Rock_Stone",
      "rotation": 12
    },
    {
      "x": -4,
      "y": 4,
      "z": -1,
      "name": "Rock_Stone",
      "rotation": 12
    },
    {
      "x": -4,
      "y": 5,
      "z": -1,
      "name": "Rock_Stone",
      "rotation": 12
    },
    {
      "x": -4,
      "y": 6,
      "z": -1,
      "name": "Rock_Stone",
      "rotation": 12
    },
    {
      "x": -4,
      "y": 13,
      "z": -1,
      "name": "Rock_Stone",
      "rotation": 12
    },
    {
      "x": -4,
      "y": 14,
      "z": -1,
      "name": "Rock_Stone",
      "rotation": 12
    },
    {
      "x": -4,
      "y": 15,
      "z": -1,
      "name": "Rock_Stone_Mossy",
      "rotation": 12
    },
    {
      "x": -4,
      "y": -10,
      "z": 0,
      "name": "Rock_Stone",
      "rotation": 12
    },
    {
      "x": -4,
      "y": -9,
      "z": 0,
      "name": "Rock_Stone_Mossy",
      "rotation": 12
    },
    {
      "x": -4,
      "y": -8,
      "z": 0,
      "name": "Rock_Stone",
      "rotation": 12
    },
    {
      "x": -4,
      "y": -7,
      "z": 0,
      "name": "Rock_Stone",
      "rotation": 12
    },
    {
      "x": -4,
      "y": -6,
      "z": 0,
      "name": "Rock_Stone",
      "rotation": 12
    },
    {
      "x": -4,
      "y": -5,
      "z": 0,
      "name": "Rock_Stone",
      "rotation": 12
    },
    {
      "x": -4,
      "y": -4,
      "z": 0,
      "name": "Rock_Stone_Mossy",
      "rotation": 12
    },
    {
      "x": -4,
      "y": -3,
      "z": 0,
      "name": "Rock_Stone_Mossy",
      "rotation": 12
    },
    {
      "x": -4,
      "y": -2,
      "z": 0,
      "name": "Rock_Stone_Mossy",
      "rotation": 12
    },
    {
      "x": -4,
      "y": -1,
      "z": 0,
      "name": "Rock_Stone",
      "rotation": 12
    },
    {
      "x": -4,
      "y": 0,
      "z": 0,
      "name": "Rock_Stone",
      "rotation": 12
    },
    {
      "x": -4,
      "y": 1,
      "z": 0,
      "name": "Rock_Stone",
      "rotation": 12
    },
    {
      "x": -4,
      "y": 2,
      "z": 0,
      "name": "Rock_Stone",
      "rotation": 12
    },
    {
      "x": -4,
      "y": 13,
      "z": 0,
      "name": "Rock_Stone",
      "rotation": 12
    },
    {
      "x": -4,
      "y": 14,
      "z": 0,
      "name": "Rock_Stone",
      "rotation": 12
    },
    {
      "x": -4,
      "y": 15,
      "z": 0,
      "name": "Rock_Stone_Mossy",
      "rotation": 12
    },
    {
      "x": -4,
      "y": -10,
      "z": 1,
      "name": "Rock_Stone",
      "rotation": 12
    },
    {
      "x": -4,
      "y": -9,
      "z": 1,
      "name": "Rock_Stone",
      "rotation": 12
    },
    {
      "x": -4,
      "y": -8,
      "z": 1,
      "name": "Rock_Stone_Mossy",
      "rotation": 12
    },
    {
      "x": -4,
      "y": -7,
      "z": 1,
      "name": "Rock_Stone",
      "rotation": 12
    },
    {
      "x": -4,
      "y": -6,
      "z": 1,
      "name": "Rock_Stone",
      "rotation": 12
    },
    {
      "x": -4,
      "y": -5,
      "z": 1,
      "name": "Rock_Stone",
      "rotation": 12
    },
    {
      "x": -4,
      "y": -4,
      "z": 1,
      "name": "Rock_Stone",
      "rotation": 12
    },
    {
      "x": -4,
      "y": -3,
      "z": 1,
      "name": "Rock_Stone",
      "rotation": 12
    },
    {
      "x": -4,
      "y": -2,
      "z": 1,
      "name": "Rock_Stone",
      "rotation": 12
    },
    {
      "x": -4,
      "y": -1,
      "z": 1,
      "name": "Rock_Stone",
      "rotation": 12
    },
    {
      "x": -4,
      "y": 0,
      "z": 1,
      "name": "Rock_Stone",
      "rotation": 12
    },
    {
      "x": -4,
      "y": 1,
      "z": 1,
      "name": "Rock_Stone",
      "rotation": 12
    },
    {
      "x": -4,
      "y": 2,
      "z": 1,
      "name": "Rock_Stone_Mossy",
      "rotation": 12
    },
    {
      "x": -4,
      "y": 12,
      "z": 1,
      "name": "Rock_Stone",
      "rotation": 12
    },
    {
      "x": -4,
      "y": 13,
      "z": 1,
      "name": "Rock_Stone_Mossy",
      "rotation": 12
    },
    {
      "x": -4,
      "y": 14,
      "z": 1,
      "name": "Rock_Stone",
      "rotation": 12
    },
    {
      "x": -4,
      "y": -10,
      "z": 2,
      "name": "Rock_Stone",
      "rotation": 12
    },
    {
      "x": -4,
      "y": -9,
      "z": 2,
      "name": "Rock_Stone_Mossy",
      "rotation": 12
    },
    {
      "x": -4,
      "y": -8,
      "z": 2,
      "name": "Rock_Stone",
      "rotation": 12
    },
    {
      "x": -4,
      "y": -7,
      "z": 2,
      "name": "Rock_Stone",
      "rotation": 12
    },
    {
      "x": -4,
      "y": -6,
      "z": 2,
      "name": "Rock_Stone",
      "rotation": 12
    },
    {
      "x": -4,
      "y": -5,
      "z": 2,
      "name": "Rock_Stone",
      "rotation": 12
    },
    {
      "x": -4,
      "y": -4,
      "z": 2,
      "name": "Rock_Stone",
      "rotation": 12
    },
    {
      "x": -4,
      "y": -3,
      "z": 2,
      "name": "Rock_Stone",
      "rotation": 12
    },
    {
      "x": -4,
      "y": -2,
      "z": 2,
      "name": "Rock_Stone",
      "rotation": 12
    },
    {
      "x": -4,
      "y": -1,
      "z": 2,
      "name": "Rock_Stone",
      "rotation": 12
    },
    {
      "x": -4,
      "y": 0,
      "z": 2,
      "name": "Rock_Stone",
      "rotation": 12
    },
    {
      "x": -4,
      "y": 1,
      "z": 2,
      "name": "Rock_Stone_Mossy",
      "rotation": 12
    },
    {
      "x": -4,
      "y": 2,
      "z": 2,
      "name": "Rock_Stone",
      "rotation": 12
    },
    {
      "x": -4,
      "y": 3,
      "z": 2,
      "name": "Rock_Stone_Mossy",
      "rotation": 12
    },
    {
      "x": -4,
      "y": 4,
      "z": 2,
      "name": "Rock_Stone_Mossy",
      "rotation": 12
    },
    {
      "x": -4,
      "y": 12,
      "z": 2,
      "name": "Rock_Stone",
      "rotation": 12
    },
    {
      "x": -4,
      "y": 13,
      "z": 2,
      "name": "Rock_Stone_Mossy",
      "rotation": 12
    },
    {
      "x": -4,
      "y": 14,
      "z": 2,
      "name": "Rock_Stone",
      "rotation": 12
    },
    {
      "x": -4,
      "y": 15,
      "z": 2,
      "name": "Plant_Crop_Mushroom_Glowing_Violet"
    },
    {
      "x": -4,
      "y": -10,
      "z": 3,
      "name": "Rock_Stone",
      "rotation": 12
    },
    {
      "x": -4,
      "y": -9,
      "z": 3,
      "name": "Rock_Stone_Mossy",
      "rotation": 12
    },
    {
      "x": -4,
      "y": -8,
      "z": 3,
      "name": "Rock_Stone",
      "rotation": 12
    },
    {
      "x": -4,
      "y": -7,
      "z": 3,
      "name": "Rock_Stone",
      "rotation": 12
    },
    {
      "x": -4,
      "y": -6,
      "z": 3,
      "name": "Rock_Stone",
      "rotation": 12
    },
    {
      "x": -4,
      "y": -5,
      "z": 3,
      "name": "Rock_Stone",
      "rotation": 12
    },
    {
      "x": -4,
      "y": -4,
      "z": 3,
      "name": "Rock_Stone_Mossy",
      "rotation": 12
    },
    {
      "x": -4,
      "y": -3,
      "z": 3,
      "name": "Rock_Stone_Mossy",
      "rotation": 12
    },
    {
      "x": -4,
      "y": -2,
      "z": 3,
      "name": "Rock_Stone",
      "rotation": 12
    },
    {
      "x": -4,
      "y": -1,
      "z": 3,
      "name": "Rock_Stone",
      "rotation": 12
    },
    {
      "x": -4,
      "y": 0,
      "z": 3,
      "name": "Rock_Stone",
      "rotation": 12
    },
    {
      "x": -4,
      "y": 1,
      "z": 3,
      "name": "Rock_Stone",
      "rotation": 12
    },
    {
      "x": -4,
      "y": 2,
      "z": 3,
      "name": "Rock_Stone_Mossy",
      "rotation": 12
    },
    {
      "x": -4,
      "y": 3,
      "z": 3,
      "name": "Rock_Stone_Mossy",
      "rotation": 12
    },
    {
      "x": -4,
      "y": 4,
      "z": 3,
      "name": "Rock_Stone_Mossy",
      "rotation": 12
    },
    {
      "x": -4,
      "y": 12,
      "z": 3,
      "name": "Rock_Stone",
      "rotation": 12
    },
    {
      "x": -4,
      "y": 13,
      "z": 3,
      "name": "Rock_Stone",
      "rotation": 12
    },
    {
      "x": -4,
      "y": 14,
      "z": 3,
      "name": "Rock_Stone",
      "rotation": 12
    },
    {
      "x": -4,
      "y": -10,
      "z": 4,
      "name": "Rock_Stone",
      "rotation": 12
    },
    {
      "x": -4,
      "y": -9,
      "z": 4,
      "name": "Rock_Stone",
      "rotation": 12
    },
    {
      "x": -4,
      "y": -8,
      "z": 4,
      "name": "Rock_Stone",
      "rotation": 12
    },
    {
      "x": -4,
      "y": -7,
      "z": 4,
      "name": "Rock_Stone_Mossy",
      "rotation": 12
    },
    {
      "x": -4,
      "y": -6,
      "z": 4,
      "name": "Rock_Stone",
      "rotation": 12
    },
    {
      "x": -4,
      "y": -5,
      "z": 4,
      "name": "Rock_Stone",
      "rotation": 12
    },
    {
      "x": -4,
      "y": -4,
      "z": 4,
      "name": "Rock_Stone",
      "rotation": 12
    },
    {
      "x": -4,
      "y": -3,
      "z": 4,
      "name": "Rock_Stone",
      "rotation": 12
    },
    {
      "x": -4,
      "y": -2,
      "z": 4,
      "name": "Rock_Stone",
      "rotation": 12
    },
    {
      "x": -4,
      "y": -1,
      "z": 4,
      "name": "Rock_Stone",
      "rotation": 12
    },
    {
      "x": -4,
      "y": 0,
      "z": 4,
      "name": "Rock_Stone",
      "rotation": 12
    },
    {
      "x": -4,
      "y": 1,
      "z": 4,
      "name": "Rock_Stone",
      "rotation": 12
    },
    {
      "x": -4,
      "y": 2,
      "z": 4,
      "name": "Rock_Stone",
      "rotation": 12
    },
    {
      "x": -4,
      "y": 3,
      "z": 4,
      "name": "Rock_Stone",
      "rotation": 12
    },
    {
      "x": -4,
      "y": 4,
      "z": 4,
      "name": "Rock_Stone_Mossy",
      "rotation": 12
    },
    {
      "x": -4,
      "y": 5,
      "z": 4,
      "name": "Rock_Stone_Mossy",
      "rotation": 12
    },
    {
      "x": -4,
      "y": 12,
      "z": 4,
      "name": "Rock_Stone",
      "rotation": 12
    },
    {
      "x": -4,
      "y": 13,
      "z": 4,
      "name": "Rock_Stone",
      "rotation": 12
    },
    {
      "x": -4,
      "y": 14,
      "z": 4,
      "name": "Rock_Stone",
      "rotation": 12
    },
    {
      "x": -4,
      "y": -10,
      "z": 5,
      "name": "Rock_Stone",
      "rotation": 12
    },
    {
      "x": -4,
      "y": -9,
      "z": 5,
      "name": "Rock_Stone",
      "rotation": 12
    },
    {
      "x": -4,
      "y": -8,
      "z": 5,
      "name": "Rock_Stone",
      "rotation": 12
    },
    {
      "x": -4,
      "y": -7,
      "z": 5,
      "name": "Rock_Stone",
      "rotation": 12
    },
    {
      "x": -4,
      "y": -6,
      "z": 5,
      "name": "Rock_Stone",
      "rotation": 12
    },
    {
      "x": -4,
      "y": -5,
      "z": 5,
      "name": "Rock_Stone",
      "rotation": 12
    },
    {
      "x": -4,
      "y": -4,
      "z": 5,
      "name": "Rock_Stone_Mossy",
      "rotation": 12
    },
    {
      "x": -4,
      "y": -3,
      "z": 5,
      "name": "Rock_Stone",
      "rotation": 12
    },
    {
      "x": -4,
      "y": -1,
      "z": 5,
      "name": "Rock_Stone",
      "rotation": 12
    },
    {
      "x": -4,
      "y": 0,
      "z": 5,
      "name": "Rock_Stone",
      "rotation": 12
    },
    {
      "x": -4,
      "y": 1,
      "z": 5,
      "name": "Rock_Stone",
      "rotation": 12
    },
    {
      "x": -4,
      "y": 5,
      "z": 5,
      "name": "Rock_Stone_Mossy",
      "rotation": 12
    },
    {
      "x": -4,
      "y": 12,
      "z": 5,
      "name": "Rock_Stone",
      "rotation": 12
    },
    {
      "x": -4,
      "y": 13,
      "z": 5,
      "name": "Rock_Stone",
      "rotation": 12
    },
    {
      "x": -4,
      "y": 14,
      "z": 5,
      "name": "Rock_Stone",
      "rotation": 12
    },
    {
      "x": -4,
      "y": -7,
      "z": 6,
      "name": "Rock_Stone",
      "rotation": 12
    },
    {
      "x": -4,
      "y": -6,
      "z": 6,
      "name": "Rock_Stone_Mossy",
      "rotation": 12
    },
    {
      "x": -3,
      "y": -7,
      "z": -9,
      "name": "Rock_Stone",
      "rotation": 12
    },
    {
      "x": -3,
      "y": -8,
      "z": -8,
      "name": "Rock_Stone_Mossy",
      "rotation": 12
    },
    {
      "x": -3,
      "y": -7,
      "z": -8,
      "name": "Rock_Stone_Mossy",
      "rotation": 12
    },
    {
      "x": -3,
      "y": -6,
      "z": -8,
      "name": "Rock_Stone",
      "rotation": 12
    },
    {
      "x": -3,
      "y": -5,
      "z": -8,
      "name": "Rock_Stone",
      "rotation": 12
    },
    {
      "x": -3,
      "y": -4,
      "z": -8,
      "name": "Rock_Stone_Mossy",
      "rotation": 12
    },
    {
      "x": -3,
      "y": -3,
      "z": -8,
      "name": "Rock_Stone_Mossy",
      "rotation": 12
    },
    {
      "x": -3,
      "y": -9,
      "z": -7,
      "name": "Rock_Stone",
      "rotation": 12
    },
    {
      "x": -3,
      "y": -8,
      "z": -7,
      "name": "Rock_Stone",
      "rotation": 12
    },
    {
      "x": -3,
      "y": -7,
      "z": -7,
      "name": "Rock_Stone_Mossy",
      "rotation": 12
    },
    {
      "x": -3,
      "y": -6,
      "z": -7,
      "name": "Rock_Stone",
      "rotation": 12
    },
    {
      "x": -3,
      "y": -5,
      "z": -7,
      "name": "Rock_Stone",
      "rotation": 12
    },
    {
      "x": -3,
      "y": -4,
      "z": -7,
      "name": "Rock_Stone",
      "rotation": 12
    },
    {
      "x": -3,
      "y": -3,
      "z": -7,
      "name": "Rock_Stone",
      "rotation": 12
    },
    {
      "x": -3,
      "y": -2,
      "z": -7,
      "name": "Rock_Stone",
      "rotation": 12
    },
    {
      "x": -3,
      "y": -1,
      "z": -7,
      "name": "Rock_Stone",
      "rotation": 12
    },
    {
      "x": -3,
      "y": -9,
      "z": -6,
      "name": "Rock_Stone_Mossy",
      "rotation": 12
    },
    {
      "x": -3,
      "y": -8,
      "z": -6,
      "name": "Rock_Stone",
      "rotation": 12
    },
    {
      "x": -3,
      "y": -7,
      "z": -6,
      "name": "Rock_Stone",
      "rotation": 12
    },
    {
      "x": -3,
      "y": -6,
      "z": -6,
      "name": "Rock_Stone",
      "rotation": 12
    },
    {
      "x": -3,
      "y": -5,
      "z": -6,
      "name": "Rock_Stone_Mossy",
      "rotation": 12
    },
    {
      "x": -3,
      "y": -4,
      "z": -6,
      "name": "Rock_Stone",
      "rotation": 12
    },
    {
      "x": -3,
      "y": -3,
      "z": -6,
      "name": "Rock_Stone",
      "rotation": 12
    },
    {
      "x": -3,
      "y": -2,
      "z": -6,
      "name": "Rock_Stone",
      "rotation": 12
    },
    {
      "x": -3,
      "y": -1,
      "z": -6,
      "name": "Rock_Stone",
      "rotation": 12
    },
    {
      "x": -3,
      "y": -9,
      "z": -5,
      "name": "Rock_Stone",
      "rotation": 12
    },
    {
      "x": -3,
      "y": -8,
      "z": -5,
      "name": "Rock_Stone",
      "rotation": 12
    },
    {
      "x": -3,
      "y": -7,
      "z": -5,
      "name": "Rock_Stone",
      "rotation": 12
    },
    {
      "x": -3,
      "y": -6,
      "z": -5,
      "name": "Rock_Stone_Mossy",
      "rotation": 12
    },
    {
      "x": -3,
      "y": -5,
      "z": -5,
      "name": "Rock_Stone",
      "rotation": 12
    },
    {
      "x": -3,
      "y": -4,
      "z": -5,
      "name": "Rock_Stone",
      "rotation": 12
    },
    {
      "x": -3,
      "y": -3,
      "z": -5,
      "name": "Rock_Stone",
      "rotation": 12
    },
    {
      "x": -3,
      "y": -2,
      "z": -5,
      "name": "Rock_Stone",
      "rotation": 12
    },
    {
      "x": -3,
      "y": -1,
      "z": -5,
      "name": "Rock_Stone",
      "rotation": 12
    },
    {
      "x": -3,
      "y": 0,
      "z": -5,
      "name": "Rock_Stone",
      "rotation": 12
    },
    {
      "x": -3,
      "y": 1,
      "z": -5,
      "name": "Rock_Stone_Mossy",
      "rotation": 12
    },
    {
      "x": -3,
      "y": 2,
      "z": -5,
      "name": "Rock_Stone",
      "rotation": 12
    },
    {
      "x": -3,
      "y": 3,
      "z": -5,
      "name": "Rock_Stone",
      "rotation": 12
    },
    {
      "x": -3,
      "y": -9,
      "z": -4,
      "name": "Rock_Stone",
      "rotation": 12
    },
    {
      "x": -3,
      "y": -8,
      "z": -4,
      "name": "Rock_Stone_Mossy",
      "rotation": 12
    },
    {
      "x": -3,
      "y": -7,
      "z": -4,
      "name": "Rock_Stone",
      "rotation": 12
    },
    {
      "x": -3,
      "y": -6,
      "z": -4,
      "name": "Rock_Stone",
      "rotation": 12
    },
    {
      "x": -3,
      "y": -5,
      "z": -4,
      "name": "Rock_Stone",
      "rotation": 12
    },
    {
      "x": -3,
      "y": -4,
      "z": -4,
      "name": "Rock_Stone",
      "rotation": 12
    },
    {
      "x": -3,
      "y": -3,
      "z": -4,
      "name": "Rock_Stone",
      "rotation": 12
    },
    {
      "x": -3,
      "y": -2,
      "z": -4,
      "name": "Rock_Stone",
      "rotation": 12
    },
    {
      "x": -3,
      "y": -1,
      "z": -4,
      "name": "Rock_Stone",
      "rotation": 12
    },
    {
      "x": -3,
      "y": 0,
      "z": -4,
      "name": "Rock_Stone",
      "rotation": 12
    },
    {
      "x": -3,
      "y": 1,
      "z": -4,
      "name": "Rock_Stone",
      "rotation": 12
    },
    {
      "x": -3,
      "y": 2,
      "z": -4,
      "name": "Rock_Stone",
      "rotation": 12
    },
    {
      "x": -3,
      "y": 3,
      "z": -4,
      "name": "Rock_Stone",
      "rotation": 12
    },
    {
      "x": -3,
      "y": 4,
      "z": -4,
      "name": "Rock_Stone",
      "rotation": 12
    },
    {
      "x": -3,
      "y": -9,
      "z": -3,
      "name": "Rock_Stone",
      "rotation": 12
    },
    {
      "x": -3,
      "y": -8,
      "z": -3,
      "name": "Rock_Stone",
      "rotation": 12
    },
    {
      "x": -3,
      "y": -7,
      "z": -3,
      "name": "Rock_Stone",
      "rotation": 12
    },
    {
      "x": -3,
      "y": -6,
      "z": -3,
      "name": "Rock_Stone",
      "rotation": 12
    },
    {
      "x": -3,
      "y": -5,
      "z": -3,
      "name": "Rock_Stone_Mossy",
      "rotation": 12
    },
    {
      "x": -3,
      "y": -4,
      "z": -3,
      "name": "Rock_Stone",
      "rotation": 12
    },
    {
      "x": -3,
      "y": -3,
      "z": -3,
      "name": "Rock_Stone",
      "rotation": 12
    },
    {
      "x": -3,
      "y": -2,
      "z": -3,
      "name": "Rock_Stone",
      "rotation": 12
    },
    {
      "x": -3,
      "y": -1,
      "z": -3,
      "name": "Rock_Stone",
      "rotation": 12
    },
    {
      "x": -3,
      "y": 0,
      "z": -3,
      "name": "Rock_Stone",
      "rotation": 12
    },
    {
      "x": -3,
      "y": 1,
      "z": -3,
      "name": "Rock_Stone",
      "rotation": 12
    },
    {
      "x": -3,
      "y": 2,
      "z": -3,
      "name": "Rock_Stone",
      "rotation": 12
    },
    {
      "x": -3,
      "y": 3,
      "z": -3,
      "name": "Rock_Stone",
      "rotation": 12
    },
    {
      "x": -3,
      "y": 4,
      "z": -3,
      "name": "Rock_Stone",
      "rotation": 12
    },
    {
      "x": -3,
      "y": 5,
      "z": -3,
      "name": "Rock_Stone",
      "rotation": 12
    },
    {
      "x": -3,
      "y": 6,
      "z": -3,
      "name": "Rock_Stone",
      "rotation": 12
    },
    {
      "x": -3,
      "y": -9,
      "z": -2,
      "name": "Rock_Stone",
      "rotation": 12
    },
    {
      "x": -3,
      "y": -8,
      "z": -2,
      "name": "Rock_Stone",
      "rotation": 12
    },
    {
      "x": -3,
      "y": -7,
      "z": -2,
      "name": "Rock_Stone",
      "rotation": 12
    },
    {
      "x": -3,
      "y": -6,
      "z": -2,
      "name": "Rock_Stone",
      "rotation": 12
    },
    {
      "x": -3,
      "y": -5,
      "z": -2,
      "name": "Rock_Stone",
      "rotation": 12
    },
    {
      "x": -3,
      "y": -4,
      "z": -2,
      "name": "Rock_Stone",
      "rotation": 12
    },
    {
      "x": -3,
      "y": -3,
      "z": -2,
      "name": "Rock_Stone",
      "rotation": 12
    },
    {
      "x": -3,
      "y": -2,
      "z": -2,
      "name": "Rock_Stone_Mossy",
      "rotation": 12
    },
    {
      "x": -3,
      "y": -1,
      "z": -2,
      "name": "Rock_Stone",
      "rotation": 12
    },
    {
      "x": -3,
      "y": 0,
      "z": -2,
      "name": "Rock_Stone",
      "rotation": 12
    },
    {
      "x": -3,
      "y": 1,
      "z": -2,
      "name": "Rock_Stone",
      "rotation": 12
    },
    {
      "x": -3,
      "y": 2,
      "z": -2,
      "name": "Rock_Stone",
      "rotation": 12
    },
    {
      "x": -3,
      "y": 3,
      "z": -2,
      "name": "Rock_Stone_Mossy",
      "rotation": 12
    },
    {
      "x": -3,
      "y": 4,
      "z": -2,
      "name": "Rock_Stone",
      "rotation": 12
    },
    {
      "x": -3,
      "y": 5,
      "z": -2,
      "name": "Rock_Stone",
      "rotation": 12
    },
    {
      "x": -3,
      "y": 6,
      "z": -2,
      "name": "Rock_Stone",
      "rotation": 12
    },
    {
      "x": -3,
      "y": 7,
      "z": -2,
      "name": "Rock_Stone_Mossy",
      "rotation": 12
    },
    {
      "x": -3,
      "y": 8,
      "z": -2,
      "name": "Rock_Stone_Mossy",
      "rotation": 12
    },
    {
      "x": -3,
      "y": 9,
      "z": -2,
      "name": "Rock_Stone",
      "rotation": 12
    },
    {
      "x": -3,
      "y": 10,
      "z": -2,
      "name": "Rock_Stone",
      "rotation": 12
    },
    {
      "x": -3,
      "y": 13,
      "z": -2,
      "name": "Rock_Stone_Mossy",
      "rotation": 12
    },
    {
      "x": -3,
      "y": 14,
      "z": -2,
      "name": "Rock_Stone",
      "rotation": 12
    },
    {
      "x": -3,
      "y": 15,
      "z": -2,
      "name": "Rock_Stone_Mossy",
      "rotation": 12
    },
    {
      "x": -3,
      "y": -10,
      "z": -1,
      "name": "Rock_Stone",
      "rotation": 12
    },
    {
      "x": -3,
      "y": -9,
      "z": -1,
      "name": "Rock_Stone_Mossy",
      "rotation": 12
    },
    {
      "x": -3,
      "y": -8,
      "z": -1,
      "name": "Rock_Stone",
      "rotation": 12
    },
    {
      "x": -3,
      "y": -7,
      "z": -1,
      "name": "Rock_Stone",
      "rotation": 12
    },
    {
      "x": -3,
      "y": -6,
      "z": -1,
      "name": "Rock_Stone",
      "rotation": 12
    },
    {
      "x": -3,
      "y": -5,
      "z": -1,
      "name": "Rock_Stone",
      "rotation": 12
    },
    {
      "x": -3,
      "y": -4,
      "z": -1,
      "name": "Rock_Stone",
      "rotation": 12
    },
    {
      "x": -3,
      "y": -3,
      "z": -1,
      "name": "Rock_Stone",
      "rotation": 12
    },
    {
      "x": -3,
      "y": -2,
      "z": -1,
      "name": "Rock_Stone",
      "rotation": 12
    },
    {
      "x": -3,
      "y": -1,
      "z": -1,
      "name": "Rock_Stone",
      "rotation": 12
    },
    {
      "x": -3,
      "y": 0,
      "z": -1,
      "name": "Rock_Stone",
      "rotation": 12
    },
    {
      "x": -3,
      "y": 1,
      "z": -1,
      "name": "Rock_Stone",
      "rotation": 12
    },
    {
      "x": -3,
      "y": 2,
      "z": -1,
      "name": "Rock_Stone",
      "rotation": 12
    },
    {
      "x": -3,
      "y": 3,
      "z": -1,
      "name": "Rock_Stone",
      "rotation": 12
    },
    {
      "x": -3,
      "y": 4,
      "z": -1,
      "name": "Rock_Stone",
      "rotation": 12
    },
    {
      "x": -3,
      "y": 5,
      "z": -1,
      "name": "Rock_Stone",
      "rotation": 12
    },
    {
      "x": -3,
      "y": 6,
      "z": -1,
      "name": "Rock_Stone",
      "rotation": 12
    },
    {
      "x": -3,
      "y": 7,
      "z": -1,
      "name": "Rock_Stone_Mossy",
      "rotation": 12
    },
    {
      "x": -3,
      "y": 8,
      "z": -1,
      "name": "Rock_Stone",
      "rotation": 12
    },
    {
      "x": -3,
      "y": 9,
      "z": -1,
      "name": "Rock_Stone",
      "rotation": 12
    },
    {
      "x": -3,
      "y": 10,
      "z": -1,
      "name": "Rock_Stone",
      "rotation": 12
    },
    {
      "x": -3,
      "y": 11,
      "z": -1,
      "name": "Rock_Stone",
      "rotation": 12
    },
    {
      "x": -3,
      "y": 12,
      "z": -1,
      "name": "Rock_Stone",
      "rotation": 12
    },
    {
      "x": -3,
      "y": 13,
      "z": -1,
      "name": "Rock_Stone",
      "rotation": 12
    },
    {
      "x": -3,
      "y": 14,
      "z": -1,
      "name": "Rock_Stone",
      "rotation": 12
    },
    {
      "x": -3,
      "y": 15,
      "z": -1,
      "name": "Rock_Stone",
      "rotation": 12
    },
    {
      "x": -3,
      "y": 16,
      "z": -1,
      "name": "Rock_Stone",
      "rotation": 12
    },
    {
      "x": -3,
      "y": -10,
      "z": 0,
      "name": "Rock_Stone",
      "rotation": 12
    },
    {
      "x": -3,
      "y": -9,
      "z": 0,
      "name": "Rock_Stone_Mossy",
      "rotation": 12
    },
    {
      "x": -3,
      "y": -8,
      "z": 0,
      "name": "Rock_Stone",
      "rotation": 12
    },
    {
      "x": -3,
      "y": -7,
      "z": 0,
      "name": "Rock_Stone",
      "rotation": 12
    },
    {
      "x": -3,
      "y": -6,
      "z": 0,
      "name": "Rock_Stone",
      "rotation": 12
    },
    {
      "x": -3,
      "y": -5,
      "z": 0,
      "name": "Rock_Stone",
      "rotation": 12
    },
    {
      "x": -3,
      "y": -4,
      "z": 0,
      "name": "Rock_Stone_Mossy",
      "rotation": 12
    },
    {
      "x": -3,
      "y": -3,
      "z": 0,
      "name": "Rock_Stone",
      "rotation": 12
    },
    {
      "x": -3,
      "y": -2,
      "z": 0,
      "name": "Rock_Stone_Mossy",
      "rotation": 12
    },
    {
      "x": -3,
      "y": -1,
      "z": 0,
      "name": "Rock_Stone_Mossy",
      "rotation": 12
    },
    {
      "x": -3,
      "y": 0,
      "z": 0,
      "name": "Rock_Stone",
      "rotation": 12
    },
    {
      "x": -3,
      "y": 1,
      "z": 0,
      "name": "Rock_Stone",
      "rotation": 12
    },
    {
      "x": -3,
      "y": 2,
      "z": 0,
      "name": "Rock_Stone",
      "rotation": 12
    },
    {
      "x": -3,
      "y": 3,
      "z": 0,
      "name": "Rock_Stone_Mossy",
      "rotation": 12
    },
    {
      "x": -3,
      "y": 4,
      "z": 0,
      "name": "Rock_Stone",
      "rotation": 12
    },
    {
      "x": -3,
      "y": 5,
      "z": 0,
      "name": "Rock_Stone",
      "rotation": 12
    },
    {
      "x": -3,
      "y": 6,
      "z": 0,
      "name": "Rock_Stone",
      "rotation": 12
    },
    {
      "x": -3,
      "y": 7,
      "z": 0,
      "name": "Rock_Stone",
      "rotation": 12
    },
    {
      "x": -3,
      "y": 8,
      "z": 0,
      "name": "Rock_Stone",
      "rotation": 12
    },
    {
      "x": -3,
      "y": 9,
      "z": 0,
      "name": "Rock_Stone_Mossy",
      "rotation": 12
    },
    {
      "x": -3,
      "y": 10,
      "z": 0,
      "name": "Rock_Stone_Mossy",
      "rotation": 12
    },
    {
      "x": -3,
      "y": 11,
      "z": 0,
      "name": "Rock_Stone",
      "rotation": 12
    },
    {
      "x": -3,
      "y": 12,
      "z": 0,
      "name": "Rock_Stone",
      "rotation": 12
    },
    {
      "x": -3,
      "y": 13,
      "z": 0,
      "name": "Rock_Stone",
      "rotation": 12
    },
    {
      "x": -3,
      "y": 14,
      "z": 0,
      "name": "Rock_Stone",
      "rotation": 12
    },
    {
      "x": -3,
      "y": 15,
      "z": 0,
      "name": "Rock_Stone",
      "rotation": 12
    },
    {
      "x": -3,
      "y": 16,
      "z": 0,
      "name": "Rock_Stone",
      "rotation": 12
    },
    {
      "x": -3,
      "y": 17,
      "z": 0,
      "name": "Plant_Crop_Mushroom_Glowing_Violet"
    },
    {
      "x": -3,
      "y": -10,
      "z": 1,
      "name": "Rock_Stone_Mossy",
      "rotation": 12
    },
    {
      "x": -3,
      "y": -9,
      "z": 1,
      "name": "Rock_Stone",
      "rotation": 12
    },
    {
      "x": -3,
      "y": -8,
      "z": 1,
      "name": "Rock_Stone",
      "rotation": 12
    },
    {
      "x": -3,
      "y": -7,
      "z": 1,
      "name": "Rock_Stone",
      "rotation": 12
    },
    {
      "x": -3,
      "y": -6,
      "z": 1,
      "name": "Rock_Stone",
      "rotation": 12
    },
    {
      "x": -3,
      "y": -5,
      "z": 1,
      "name": "Rock_Stone",
      "rotation": 12
    },
    {
      "x": -3,
      "y": -4,
      "z": 1,
      "name": "Rock_Stone_Mossy",
      "rotation": 12
    },
    {
      "x": -3,
      "y": -3,
      "z": 1,
      "name": "Rock_Stone",
      "rotation": 12
    },
    {
      "x": -3,
      "y": -2,
      "z": 1,
      "name": "Rock_Stone",
      "rotation": 12
    },
    {
      "x": -3,
      "y": -1,
      "z": 1,
      "name": "Rock_Stone_Mossy",
      "rotation": 12
    },
    {
      "x": -3,
      "y": 0,
      "z": 1,
      "name": "Rock_Stone_Mossy",
      "rotation": 12
    },
    {
      "x": -3,
      "y": 1,
      "z": 1,
      "name": "Rock_Stone_Mossy",
      "rotation": 12
    },
    {
      "x": -3,
      "y": 2,
      "z": 1,
      "name": "Rock_Stone",
      "rotation": 12
    },
    {
      "x": -3,
      "y": 3,
      "z": 1,
      "name": "Rock_Stone",
      "rotation": 12
    },
    {
      "x": -3,
      "y": 4,
      "z": 1,
      "name": "Rock_Stone_Mossy",
      "rotation": 12
    },
    {
      "x": -3,
      "y": 5,
      "z": 1,
      "name": "Rock_Stone_Mossy",
      "rotation": 12
    },
    {
      "x": -3,
      "y": 6,
      "z": 1,
      "name": "Rock_Stone",
      "rotation": 12
    },
    {
      "x": -3,
      "y": 7,
      "z": 1,
      "name": "Rock_Stone",
      "rotation": 12
    },
    {
      "x": -3,
      "y": 8,
      "z": 1,
      "name": "Rock_Stone",
      "rotation": 12
    },
    {
      "x": -3,
      "y": 9,
      "z": 1,
      "name": "Rock_Stone_Mossy",
      "rotation": 12
    },
    {
      "x": -3,
      "y": 10,
      "z": 1,
      "name": "Rock_Stone_Mossy",
      "rotation": 12
    },
    {
      "x": -3,
      "y": 11,
      "z": 1,
      "name": "Rock_Stone",
      "rotation": 12
    },
    {
      "x": -3,
      "y": 12,
      "z": 1,
      "name": "Rock_Stone",
      "rotation": 12
    },
    {
      "x": -3,
      "y": 13,
      "z": 1,
      "name": "Rock_Stone",
      "rotation": 12
    },
    {
      "x": -3,
      "y": 14,
      "z": 1,
      "name": "Rock_Stone",
      "rotation": 12
    },
    {
      "x": -3,
      "y": 15,
      "z": 1,
      "name": "Rock_Stone_Mossy",
      "rotation": 12
    },
    {
      "x": -3,
      "y": 16,
      "z": 1,
      "name": "Rock_Stone",
      "rotation": 12
    },
    {
      "x": -3,
      "y": 17,
      "z": 1,
      "name": "Rock_Stone_Mossy",
      "rotation": 12
    },
    {
      "x": -3,
      "y": 18,
      "z": 1,
      "name": "Rock_Stone",
      "rotation": 12
    },
    {
      "x": -3,
      "y": 19,
      "z": 1,
      "name": "Rock_Stone",
      "rotation": 12
    },
    {
      "x": -3,
      "y": 20,
      "z": 1,
      "name": "Rock_Stone",
      "rotation": 12
    },
    {
      "x": -3,
      "y": 21,
      "z": 1,
      "name": "Rock_Stone",
      "rotation": 12
    },
    {
      "x": -3,
      "y": -10,
      "z": 2,
      "name": "Rock_Stone",
      "rotation": 12
    },
    {
      "x": -3,
      "y": -9,
      "z": 2,
      "name": "Rock_Stone",
      "rotation": 12
    },
    {
      "x": -3,
      "y": -8,
      "z": 2,
      "name": "Rock_Stone",
      "rotation": 12
    },
    {
      "x": -3,
      "y": -7,
      "z": 2,
      "name": "Rock_Stone_Mossy",
      "rotation": 12
    },
    {
      "x": -3,
      "y": -6,
      "z": 2,
      "name": "Rock_Stone_Mossy",
      "rotation": 12
    },
    {
      "x": -3,
      "y": -5,
      "z": 2,
      "name": "Rock_Stone",
      "rotation": 12
    },
    {
      "x": -3,
      "y": -4,
      "z": 2,
      "name": "Rock_Stone",
      "rotation": 12
    },
    {
      "x": -3,
      "y": -3,
      "z": 2,
      "name": "Rock_Stone",
      "rotation": 12
    },
    {
      "x": -3,
      "y": -2,
      "z": 2,
      "name": "Rock_Stone",
      "rotation": 12
    },
    {
      "x": -3,
      "y": -1,
      "z": 2,
      "name": "Rock_Stone_Mossy",
      "rotation": 12
    },
    {
      "x": -3,
      "y": 0,
      "z": 2,
      "name": "Rock_Stone",
      "rotation": 12
    },
    {
      "x": -3,
      "y": 1,
      "z": 2,
      "name": "Rock_Stone",
      "rotation": 12
    },
    {
      "x": -3,
      "y": 2,
      "z": 2,
      "name": "Rock_Stone",
      "rotation": 12
    },
    {
      "x": -3,
      "y": 3,
      "z": 2,
      "name": "Rock_Stone",
      "rotation": 12
    },
    {
      "x": -3,
      "y": 4,
      "z": 2,
      "name": "Rock_Stone",
      "rotation": 12
    },
    {
      "x": -3,
      "y": 5,
      "z": 2,
      "name": "Rock_Stone",
      "rotation": 12
    },
    {
      "x": -3,
      "y": 6,
      "z": 2,
      "name": "Rock_Stone",
      "rotation": 12
    },
    {
      "x": -3,
      "y": 7,
      "z": 2,
      "name": "Rock_Stone",
      "rotation": 12
    },
    {
      "x": -3,
      "y": 8,
      "z": 2,
      "name": "Rock_Stone_Mossy",
      "rotation": 12
    },
    {
      "x": -3,
      "y": 9,
      "z": 2,
      "name": "Rock_Stone",
      "rotation": 12
    },
    {
      "x": -3,
      "y": 10,
      "z": 2,
      "name": "Rock_Stone",
      "rotation": 12
    },
    {
      "x": -3,
      "y": 11,
      "z": 2,
      "name": "Rock_Stone",
      "rotation": 12
    },
    {
      "x": -3,
      "y": 12,
      "z": 2,
      "name": "Rock_Stone",
      "rotation": 12
    },
    {
      "x": -3,
      "y": 13,
      "z": 2,
      "name": "Rock_Stone",
      "rotation": 12
    },
    {
      "x": -3,
      "y": 14,
      "z": 2,
      "name": "Rock_Stone",
      "rotation": 12
    },
    {
      "x": -3,
      "y": 15,
      "z": 2,
      "name": "Rock_Stone",
      "rotation": 12
    },
    {
      "x": -3,
      "y": 16,
      "z": 2,
      "name": "Rock_Stone",
      "rotation": 12
    },
    {
      "x": -3,
      "y": 17,
      "z": 2,
      "name": "Rock_Stone_Mossy",
      "rotation": 12
    },
    {
      "x": -3,
      "y": 18,
      "z": 2,
      "name": "Rock_Stone",
      "rotation": 12
    },
    {
      "x": -3,
      "y": 19,
      "z": 2,
      "name": "Rock_Stone",
      "rotation": 12
    },
    {
      "x": -3,
      "y": 20,
      "z": 2,
      "name": "Rock_Stone_Mossy",
      "rotation": 12
    },
    {
      "x": -3,
      "y": 21,
      "z": 2,
      "name": "Rock_Stone_Mossy",
      "rotation": 12
    },
    {
      "x": -3,
      "y": 22,
      "z": 2,
      "name": "Rock_Stone",
      "rotation": 12
    },
    {
      "x": -3,
      "y": 26,
      "z": 2,
      "name": "Plant_Moss_Wall_Blue",
      "support": 15,
      "rotation": 3
    },
    {
      "x": -3,
      "y": 27,
      "z": 2,
      "name": "Plant_Moss_Wall_Blue",
      "support": 15,
      "rotation": 3
    },
    {
      "x": -3,
      "y": -10,
      "z": 3,
      "name": "Rock_Stone",
      "rotation": 12
    },
    {
      "x": -3,
      "y": -9,
      "z": 3,
      "name": "Rock_Stone",
      "rotation": 12
    },
    {
      "x": -3,
      "y": -8,
      "z": 3,
      "name": "Rock_Stone",
      "rotation": 12
    },
    {
      "x": -3,
      "y": -7,
      "z": 3,
      "name": "Rock_Stone_Mossy",
      "rotation": 12
    },
    {
      "x": -3,
      "y": -6,
      "z": 3,
      "name": "Rock_Stone",
      "rotation": 12
    },
    {
      "x": -3,
      "y": -5,
      "z": 3,
      "name": "Rock_Stone_Mossy",
      "rotation": 12
    },
    {
      "x": -3,
      "y": -4,
      "z": 3,
      "name": "Rock_Stone",
      "rotation": 12
    },
    {
      "x": -3,
      "y": -3,
      "z": 3,
      "name": "Rock_Stone",
      "rotation": 12
    },
    {
      "x": -3,
      "y": -2,
      "z": 3,
      "name": "Rock_Stone",
      "rotation": 12
    },
    {
      "x": -3,
      "y": -1,
      "z": 3,
      "name": "Rock_Stone_Mossy",
      "rotation": 12
    },
    {
      "x": -3,
      "y": 0,
      "z": 3,
      "name": "Rock_Stone",
      "rotation": 12
    },
    {
      "x": -3,
      "y": 1,
      "z": 3,
      "name": "Rock_Stone",
      "rotation": 12
    },
    {
      "x": -3,
      "y": 2,
      "z": 3,
      "name": "Rock_Stone",
      "rotation": 12
    },
    {
      "x": -3,
      "y": 3,
      "z": 3,
      "name": "Rock_Stone",
      "rotation": 12
    },
    {
      "x": -3,
      "y": 4,
      "z": 3,
      "name": "Rock_Stone",
      "rotation": 12
    },
    {
      "x": -3,
      "y": 5,
      "z": 3,
      "name": "Rock_Stone",
      "rotation": 12
    },
    {
      "x": -3,
      "y": 6,
      "z": 3,
      "name": "Rock_Stone",
      "rotation": 12
    },
    {
      "x": -3,
      "y": 7,
      "z": 3,
      "name": "Rock_Stone",
      "rotation": 12
    },
    {
      "x": -3,
      "y": 8,
      "z": 3,
      "name": "Rock_Stone",
      "rotation": 12
    },
    {
      "x": -3,
      "y": 9,
      "z": 3,
      "name": "Rock_Stone",
      "rotation": 12
    },
    {
      "x": -3,
      "y": 10,
      "z": 3,
      "name": "Rock_Stone",
      "rotation": 12
    },
    {
      "x": -3,
      "y": 11,
      "z": 3,
      "name": "Rock_Stone",
      "rotation": 12
    },
    {
      "x": -3,
      "y": 12,
      "z": 3,
      "name": "Rock_Stone_Mossy",
      "rotation": 12
    },
    {
      "x": -3,
      "y": 13,
      "z": 3,
      "name": "Rock_Stone",
      "rotation": 12
    },
    {
      "x": -3,
      "y": 14,
      "z": 3,
      "name": "Rock_Stone",
      "rotation": 12
    },
    {
      "x": -3,
      "y": 15,
      "z": 3,
      "name": "Rock_Stone",
      "rotation": 12
    },
    {
      "x": -3,
      "y": 16,
      "z": 3,
      "name": "Rock_Stone",
      "rotation": 12
    },
    {
      "x": -3,
      "y": 17,
      "z": 3,
      "name": "Rock_Stone",
      "rotation": 12
    },
    {
      "x": -3,
      "y": 18,
      "z": 3,
      "name": "Rock_Stone",
      "rotation": 12
    },
    {
      "x": -3,
      "y": 19,
      "z": 3,
      "name": "Rock_Stone",
      "rotation": 12
    },
    {
      "x": -3,
      "y": 20,
      "z": 3,
      "name": "Rock_Stone",
      "rotation": 12
    },
    {
      "x": -3,
      "y": 21,
      "z": 3,
      "name": "Rock_Stone",
      "rotation": 12
    },
    {
      "x": -3,
      "y": 22,
      "z": 3,
      "name": "Rock_Stone",
      "rotation": 12
    },
    {
      "x": -3,
      "y": 27,
      "z": 3,
      "name": "Plant_Moss_Wall_Blue",
      "support": 15,
      "rotation": 3
    },
    {
      "x": -3,
      "y": -10,
      "z": 4,
      "name": "Rock_Stone",
      "rotation": 12
    },
    {
      "x": -3,
      "y": -9,
      "z": 4,
      "name": "Rock_Stone_Mossy",
      "rotation": 12
    },
    {
      "x": -3,
      "y": -8,
      "z": 4,
      "name": "Rock_Stone_Mossy",
      "rotation": 12
    },
    {
      "x": -3,
      "y": -7,
      "z": 4,
      "name": "Rock_Stone",
      "rotation": 12
    },
    {
      "x": -3,
      "y": -6,
      "z": 4,
      "name": "Rock_Stone_Mossy",
      "rotation": 12
    },
    {
      "x": -3,
      "y": -5,
      "z": 4,
      "name": "Rock_Stone",
      "rotation": 12
    },
    {
      "x": -3,
      "y": -4,
      "z": 4,
      "name": "Rock_Stone",
      "rotation": 12
    },
    {
      "x": -3,
      "y": -3,
      "z": 4,
      "name": "Rock_Stone_Mossy",
      "rotation": 12
    },
    {
      "x": -3,
      "y": -2,
      "z": 4,
      "name": "Rock_Stone_Mossy",
      "rotation": 12
    },
    {
      "x": -3,
      "y": -1,
      "z": 4,
      "name": "Rock_Stone",
      "rotation": 12
    },
    {
      "x": -3,
      "y": 0,
      "z": 4,
      "name": "Rock_Stone",
      "rotation": 12
    },
    {
      "x": -3,
      "y": 1,
      "z": 4,
      "name": "Rock_Stone",
      "rotation": 12
    },
    {
      "x": -3,
      "y": 2,
      "z": 4,
      "name": "Rock_Stone",
      "rotation": 12
    },
    {
      "x": -3,
      "y": 3,
      "z": 4,
      "name": "Rock_Stone",
      "rotation": 12
    },
    {
      "x": -3,
      "y": 4,
      "z": 4,
      "name": "Rock_Stone",
      "rotation": 12
    },
    {
      "x": -3,
      "y": 5,
      "z": 4,
      "name": "Rock_Stone",
      "rotation": 12
    },
    {
      "x": -3,
      "y": 6,
      "z": 4,
      "name": "Rock_Stone_Mossy",
      "rotation": 12
    },
    {
      "x": -3,
      "y": 8,
      "z": 4,
      "name": "Rock_Stone_Mossy",
      "rotation": 12
    },
    {
      "x": -3,
      "y": 9,
      "z": 4,
      "name": "Rock_Stone",
      "rotation": 12
    },
    {
      "x": -3,
      "y": 10,
      "z": 4,
      "name": "Rock_Stone",
      "rotation": 12
    },
    {
      "x": -3,
      "y": 11,
      "z": 4,
      "name": "Rock_Stone",
      "rotation": 12
    },
    {
      "x": -3,
      "y": 12,
      "z": 4,
      "name": "Rock_Stone",
      "rotation": 12
    },
    {
      "x": -3,
      "y": 13,
      "z": 4,
      "name": "Rock_Stone",
      "rotation": 12
    },
    {
      "x": -3,
      "y": 14,
      "z": 4,
      "name": "Rock_Stone",
      "rotation": 12
    },
    {
      "x": -3,
      "y": 15,
      "z": 4,
      "name": "Rock_Stone",
      "rotation": 12
    },
    {
      "x": -3,
      "y": 16,
      "z": 4,
      "name": "Rock_Stone",
      "rotation": 12
    },
    {
      "x": -3,
      "y": 17,
      "z": 4,
      "name": "Rock_Stone",
      "rotation": 12
    },
    {
      "x": -3,
      "y": 18,
      "z": 4,
      "name": "Rock_Stone",
      "rotation": 12
    },
    {
      "x": -3,
      "y": 19,
      "z": 4,
      "name": "Rock_Stone",
      "rotation": 12
    },
    {
      "x": -3,
      "y": 20,
      "z": 4,
      "name": "Rock_Stone",
      "rotation": 12
    },
    {
      "x": -3,
      "y": 21,
      "z": 4,
      "name": "Rock_Stone",
      "rotation": 12
    },
    {
      "x": -3,
      "y": 22,
      "z": 4,
      "name": "Rock_Stone",
      "rotation": 12
    },
    {
      "x": -3,
      "y": 28,
      "z": 4,
      "name": "Plant_Moss_Wall_Blue",
      "support": 15,
      "rotation": 3
    },
    {
      "x": -3,
      "y": -10,
      "z": 5,
      "name": "Rock_Stone",
      "rotation": 12
    },
    {
      "x": -3,
      "y": -9,
      "z": 5,
      "name": "Rock_Stone",
      "rotation": 12
    },
    {
      "x": -3,
      "y": -8,
      "z": 5,
      "name": "Rock_Stone",
      "rotation": 12
    },
    {
      "x": -3,
      "y": -7,
      "z": 5,
      "name": "Rock_Stone",
      "rotation": 12
    },
    {
      "x": -3,
      "y": -6,
      "z": 5,
      "name": "Rock_Stone",
      "rotation": 12
    },
    {
      "x": -3,
      "y": -5,
      "z": 5,
      "name": "Rock_Stone",
      "rotation": 12
    },
    {
      "x": -3,
      "y": -4,
      "z": 5,
      "name": "Rock_Stone",
      "rotation": 12
    },
    {
      "x": -3,
      "y": -3,
      "z": 5,
      "name": "Rock_Stone",
      "rotation": 12
    },
    {
      "x": -3,
      "y": -1,
      "z": 5,
      "name": "Rock_Stone",
      "rotation": 12
    },
    {
      "x": -3,
      "y": 0,
      "z": 5,
      "name": "Rock_Stone",
      "rotation": 12
    },
    {
      "x": -3,
      "y": 1,
      "z": 5,
      "name": "Rock_Stone",
      "rotation": 12
    },
    {
      "x": -3,
      "y": 5,
      "z": 5,
      "name": "Rock_Stone",
      "rotation": 12
    },
    {
      "x": -3,
      "y": 13,
      "z": 5,
      "name": "Rock_Stone",
      "rotation": 12
    },
    {
      "x": -3,
      "y": 14,
      "z": 5,
      "name": "Rock_Stone",
      "rotation": 12
    },
    {
      "x": -3,
      "y": 15,
      "z": 5,
      "name": "Rock_Stone_Mossy",
      "rotation": 12
    },
    {
      "x": -3,
      "y": 16,
      "z": 5,
      "name": "Rock_Stone",
      "rotation": 12
    },
    {
      "x": -3,
      "y": 17,
      "z": 5,
      "name": "Rock_Stone_Mossy",
      "rotation": 12
    },
    {
      "x": -3,
      "y": 18,
      "z": 5,
      "name": "Rock_Stone_Mossy",
      "rotation": 12
    },
    {
      "x": -3,
      "y": 19,
      "z": 5,
      "name": "Rock_Stone_Mossy",
      "rotation": 12
    },
    {
      "x": -3,
      "y": 20,
      "z": 5,
      "name": "Rock_Stone_Mossy",
      "rotation": 12
    },
    {
      "x": -3,
      "y": 21,
      "z": 5,
      "name": "Rock_Stone",
      "rotation": 12
    },
    {
      "x": -3,
      "y": 22,
      "z": 5,
      "name": "Rock_Stone",
      "rotation": 12
    },
    {
      "x": -3,
      "y": 28,
      "z": 5,
      "name": "Plant_Moss_Wall_Blue",
      "support": 15,
      "rotation": 3
    },
    {
      "x": -3,
      "y": 30,
      "z": 5,
      "name": "Plant_Moss_Wall_Blue",
      "support": 15,
      "rotation": 3
    },
    {
      "x": -3,
      "y": 31,
      "z": 5,
      "name": "Plant_Moss_Wall_Blue",
      "support": 15,
      "rotation": 3
    },
    {
      "x": -3,
      "y": 32,
      "z": 5,
      "name": "Plant_Moss_Wall_Blue",
      "support": 15,
      "rotation": 3
    },
    {
      "x": -3,
      "y": -7,
      "z": 6,
      "name": "Rock_Stone",
      "rotation": 12
    },
    {
      "x": -3,
      "y": -6,
      "z": 6,
      "name": "Rock_Stone",
      "rotation": 12
    },
    {
      "x": -3,
      "y": 22,
      "z": 6,
      "name": "Rock_Stone",
      "rotation": 12
    },
    {
      "x": -3,
      "y": 29,
      "z": 6,
      "name": "Plant_Moss_Wall_Blue",
      "support": 15,
      "rotation": 3
    },
    {
      "x": -3,
      "y": 30,
      "z": 6,
      "name": "Plant_Moss_Wall_Blue",
      "support": 15,
      "rotation": 3
    },
    {
      "x": -3,
      "y": 32,
      "z": 6,
      "name": "Plant_Moss_Wall_Blue",
      "support": 15,
      "rotation": 3
    },
    {
      "x": -3,
      "y": 33,
      "z": 6,
      "name": "Plant_Moss_Wall_Blue",
      "support": 15,
      "rotation": 3
    },
    {
      "x": -3,
      "y": 30,
      "z": 7,
      "name": "Plant_Moss_Wall_Blue",
      "support": 15,
      "rotation": 3
    },
    {
      "x": -2,
      "y": -7,
      "z": -9,
      "name": "Rock_Stone",
      "rotation": 12
    },
    {
      "x": -2,
      "y": -8,
      "z": -8,
      "name": "Rock_Stone",
      "rotation": 12
    },
    {
      "x": -2,
      "y": -7,
      "z": -8,
      "name": "Rock_Stone_Mossy",
      "rotation": 12
    },
    {
      "x": -2,
      "y": -6,
      "z": -8,
      "name": "Rock_Stone_Mossy",
      "rotation": 12
    },
    {
      "x": -2,
      "y": -5,
      "z": -8,
      "name": "Rock_Stone",
      "rotation": 12
    },
    {
      "x": -2,
      "y": -4,
      "z": -8,
      "name": "Rock_Stone",
      "rotation": 12
    },
    {
      "x": -2,
      "y": -3,
      "z": -8,
      "name": "Rock_Stone_Mossy",
      "rotation": 12
    },
    {
      "x": -2,
      "y": -9,
      "z": -7,
      "name": "Rock_Stone",
      "rotation": 12
    },
    {
      "x": -2,
      "y": -8,
      "z": -7,
      "name": "Rock_Stone",
      "rotation": 12
    },
    {
      "x": -2,
      "y": -7,
      "z": -7,
      "name": "Rock_Stone_Mossy",
      "rotation": 12
    },
    {
      "x": -2,
      "y": -6,
      "z": -7,
      "name": "Rock_Stone",
      "rotation": 12
    },
    {
      "x": -2,
      "y": -5,
      "z": -7,
      "name": "Rock_Stone",
      "rotation": 12
    },
    {
      "x": -2,
      "y": -4,
      "z": -7,
      "name": "Rock_Stone",
      "rotation": 12
    },
    {
      "x": -2,
      "y": -3,
      "z": -7,
      "name": "Rock_Stone",
      "rotation": 12
    },
    {
      "x": -2,
      "y": -2,
      "z": -7,
      "name": "Rock_Stone",
      "rotation": 12
    },
    {
      "x": -2,
      "y": -1,
      "z": -7,
      "name": "Rock_Stone",
      "rotation": 12
    },
    {
      "x": -2,
      "y": -9,
      "z": -6,
      "name": "Rock_Stone_Mossy",
      "rotation": 12
    },
    {
      "x": -2,
      "y": -8,
      "z": -6,
      "name": "Rock_Stone",
      "rotation": 12
    },
    {
      "x": -2,
      "y": -7,
      "z": -6,
      "name": "Rock_Stone",
      "rotation": 12
    },
    {
      "x": -2,
      "y": -6,
      "z": -6,
      "name": "Rock_Stone",
      "rotation": 12
    },
    {
      "x": -2,
      "y": -5,
      "z": -6,
      "name": "Rock_Stone",
      "rotation": 12
    },
    {
      "x": -2,
      "y": -4,
      "z": -6,
      "name": "Rock_Stone",
      "rotation": 12
    },
    {
      "x": -2,
      "y": -3,
      "z": -6,
      "name": "Rock_Stone",
      "rotation": 12
    },
    {
      "x": -2,
      "y": -2,
      "z": -6,
      "name": "Rock_Stone_Mossy",
      "rotation": 12
    },
    {
      "x": -2,
      "y": -1,
      "z": -6,
      "name": "Rock_Stone",
      "rotation": 12
    },
    {
      "x": -2,
      "y": -9,
      "z": -5,
      "name": "Rock_Stone_Mossy",
      "rotation": 12
    },
    {
      "x": -2,
      "y": -8,
      "z": -5,
      "name": "Rock_Stone",
      "rotation": 12
    },
    {
      "x": -2,
      "y": -7,
      "z": -5,
      "name": "Rock_Stone",
      "rotation": 12
    },
    {
      "x": -2,
      "y": -6,
      "z": -5,
      "name": "Rock_Stone",
      "rotation": 12
    },
    {
      "x": -2,
      "y": -5,
      "z": -5,
      "name": "Rock_Stone",
      "rotation": 12
    },
    {
      "x": -2,
      "y": -4,
      "z": -5,
      "name": "Rock_Stone",
      "rotation": 12
    },
    {
      "x": -2,
      "y": -3,
      "z": -5,
      "name": "Rock_Stone",
      "rotation": 12
    },
    {
      "x": -2,
      "y": -2,
      "z": -5,
      "name": "Rock_Stone",
      "rotation": 12
    },
    {
      "x": -2,
      "y": -1,
      "z": -5,
      "name": "Rock_Stone",
      "rotation": 12
    },
    {
      "x": -2,
      "y": 0,
      "z": -5,
      "name": "Rock_Stone",
      "rotation": 12
    },
    {
      "x": -2,
      "y": 1,
      "z": -5,
      "name": "Rock_Stone",
      "rotation": 12
    },
    {
      "x": -2,
      "y": 2,
      "z": -5,
      "name": "Rock_Stone",
      "rotation": 12
    },
    {
      "x": -2,
      "y": 3,
      "z": -5,
      "name": "Rock_Stone",
      "rotation": 12
    },
    {
      "x": -2,
      "y": -9,
      "z": -4,
      "name": "Rock_Stone",
      "rotation": 12
    },
    {
      "x": -2,
      "y": -8,
      "z": -4,
      "name": "Rock_Stone",
      "rotation": 12
    },
    {
      "x": -2,
      "y": -7,
      "z": -4,
      "name": "Rock_Stone",
      "rotation": 12
    },
    {
      "x": -2,
      "y": -6,
      "z": -4,
      "name": "Rock_Stone",
      "rotation": 12
    },
    {
      "x": -2,
      "y": -5,
      "z": -4,
      "name": "Rock_Stone",
      "rotation": 12
    },
    {
      "x": -2,
      "y": -4,
      "z": -4,
      "name": "Rock_Stone_Mossy",
      "rotation": 12
    },
    {
      "x": -2,
      "y": -3,
      "z": -4,
      "name": "Rock_Stone_Mossy",
      "rotation": 12
    },
    {
      "x": -2,
      "y": -2,
      "z": -4,
      "name": "Rock_Stone",
      "rotation": 12
    },
    {
      "x": -2,
      "y": -1,
      "z": -4,
      "name": "Rock_Stone",
      "rotation": 12
    },
    {
      "x": -2,
      "y": 0,
      "z": -4,
      "name": "Rock_Stone",
      "rotation": 12
    },
    {
      "x": -2,
      "y": 1,
      "z": -4,
      "name": "Rock_Stone",
      "rotation": 12
    },
    {
      "x": -2,
      "y": 2,
      "z": -4,
      "name": "Rock_Stone",
      "rotation": 12
    },
    {
      "x": -2,
      "y": 3,
      "z": -4,
      "name": "Rock_Stone_Mossy",
      "rotation": 12
    },
    {
      "x": -2,
      "y": 4,
      "z": -4,
      "name": "Rock_Stone",
      "rotation": 12
    },
    {
      "x": -2,
      "y": -9,
      "z": -3,
      "name": "Rock_Stone_Mossy",
      "rotation": 12
    },
    {
      "x": -2,
      "y": -8,
      "z": -3,
      "name": "Rock_Stone",
      "rotation": 12
    },
    {
      "x": -2,
      "y": -7,
      "z": -3,
      "name": "Rock_Stone",
