{
  "version": 8,
  "blockIdVersion": 11,
  "anchorX": 0,
  "anchorY": 0,
  "anchorZ": 0,
  "blocks": [
    {
      "x": -15,
      "y": 0,
      "z": -15,
      "name": "Rock_Volcanic"
    },
    {
      "x": -15,
      "y": 1,
      "z": -15,
      "name": "Rock_Volcanic_Cobble"
    },
    {
      "x": -15,
      "y": 2,
      "z": -15,
      "name": "Rock_Volcanic_Cobble"
    },
    {
      "x": -15,
      "y": 12,
      "z": -15,
      "name": "Rock_Volcanic_Brick_Smooth"
    },
    {
      "x": -15,
      "y": 113,
      "z": -15,
      "name": "Rock_Sandstone_Brick_Smooth"
    },
    {
      "x": -15,
      "y": 121,
      "z": -15,
      "name": "Rock_Sandstone_Brick_Smooth"
    },
    {
      "x": -15,
      "y": 129,
      "z": -15,
      "name": "Rock_Sandstone_Brick_Smooth"
    },
    {
      "x": -15,
      "y": 130,
      "z": -15,
      "name": "Rock_Sandstone"
    },
    {
      "x": -15,
      "y": 0,
      "z": -14,
      "name": "Rock_Volcanic"
    },
    {
      "x": -15,
      "y": 1,
      "z": -14,
      "name": "Rock_Volcanic_Cobble"
    },
    {
      "x": -15,
      "y": 2,
      "z": -14,
      "name": "Rock_Volcanic_Cobble"
    },
    {
      "x": -15,
      "y": 12,
      "z": -14,
      "name": "Rock_Volcanic_Brick_Smooth"
    },
    {
      "x": -15,
      "y": 113,
      "z": -14,
      "name": "Rock_Sandstone_Brick_Smooth"
    },
    {
      "x": -15,
      "y": 121,
      "z": -14,
      "name": "Rock_Sandstone_Brick_Smooth"
    },
    {
      "x": -15,
      "y": 129,
      "z": -14,
      "name": "Rock_Sandstone_Brick_Smooth"
    },
    {
      "x": -15,
      "y": 130,
      "z": -14,
      "name": "Rock_Sandstone"
    },
    {
      "x": -15,
      "y": 0,
      "z": -13,
      "name": "Rock_Volcanic"
    },
    {
      "x": -15,
      "y": 1,
      "z": -13,
      "name": "Rock_Volcanic_Cobble"
    },
    {
      "x": -15,
      "y": 2,
      "z": -13,
      "name": "Rock_Volcanic_Cobble"
    },
    {
      "x": -15,
      "y": 12,
      "z": -13,
      "name": "Rock_Volcanic_Brick_Smooth"
    },
    {
      "x": -15,
      "y": 113,
      "z": -13,
      "name": "Rock_Sandstone_Brick_Smooth"
    },
    {
      "x": -15,
      "y": 121,
      "z": -13,
      "name": "Rock_Sandstone_Brick_Smooth"
    },
    {
      "x": -15,
      "y": 129,
      "z": -13,
      "name": "Rock_Sandstone_Brick_Smooth"
    },
    {
      "x": -15,
      "y": 130,
      "z": -13,
      "name": "Rock_Sandstone"
    },
    {
      "x": -15,
      "y": 0,
      "z": -12,
      "name": "Rock_Volcanic"
    },
    {
      "x": -15,
      "y": 1,
      "z": -12,
      "name": "Rock_Volcanic_Cobble"
    },
    {
      "x": -15,
      "y": 2,
      "z": -12,
      "name": "Rock_Volcanic_Cobble"
    },
    {
      "x": -15,
      "y": 12,
      "z": -12,
      "name": "Rock_Volcanic_Brick_Smooth"
    },
    {
      "x": -15,
      "y": 113,
      "z": -12,
      "name": "Rock_Sandstone_Brick_Smooth"
    },
    {
      "x": -15,
      "y": 121,
      "z": -12,
      "name": "Rock_Sandstone_Brick_Smooth"
    },
    {
      "x": -15,
      "y": 129,
      "z": -12,
      "name": "Rock_Sandstone_Brick_Smooth"
    },
    {
      "x": -15,
      "y": 130,
      "z": -12,
      "name": "Rock_Sandstone"
    },
    {
      "x": -15,
      "y": 0,
      "z": -11,
      "name": "Rock_Volcanic"
    },
    {
      "x": -15,
      "y": 1,
      "z": -11,
      "name": "Rock_Volcanic_Cobble"
    },
    {
      "x": -15,
      "y": 2,
      "z": -11,
      "name": "Rock_Volcanic_Cobble"
    },
    {
      "x": -15,
      "y": 12,
      "z": -11,
      "name": "Rock_Volcanic_Brick_Smooth"
    },
    {
      "x": -15,
      "y": 113,
      "z": -11,
      "name": "Rock_Sandstone_Brick_Smooth"
    },
    {
      "x": -15,
      "y": 121,
      "z": -11,
      "name": "Rock_Sandstone_Brick_Smooth"
    },
    {
      "x": -15,
      "y": 129,
      "z": -11,
      "name": "Rock_Sandstone_Brick_Smooth"
    },
    {
      "x": -15,
      "y": 130,
      "z": -11,
      "name": "Rock_Sandstone"
    },
    {
      "x": -15,
      "y": 0,
      "z": -10,
      "name": "Rock_Volcanic_Cracked_Lava"
    },
    {
      "x": -15,
      "y": 1,
      "z": -10,
      "name": "Rock_Volcanic_Cobble"
    },
    {
      "x": -15,
      "y": 2,
      "z": -10,
      "name": "Rock_Volcanic_Cobble"
    },
    {
      "x": -15,
      "y": 12,
      "z": -10,
      "name": "Rock_Volcanic_Brick_Smooth"
    },
    {
      "x": -15,
      "y": 113,
      "z": -10,
      "name": "Rock_Sandstone_Brick_Smooth"
    },
    {
      "x": -15,
      "y": 121,
      "z": -10,
      "name": "Rock_Sandstone_Brick_Smooth"
    },
    {
      "x": -15,
      "y": 129,
      "z": -10,
      "name": "Rock_Sandstone_Brick_Smooth"
    },
    {
      "x": -15,
      "y": 130,
      "z": -10,
      "name": "Rock_Sandstone"
    },
    {
      "x": -15,
      "y": 0,
      "z": -9,
      "name": "Rock_Volcanic"
    },
    {
      "x": -15,
      "y": 1,
      "z": -9,
      "name": "Rock_Volcanic_Cobble"
    },
    {
      "x": -15,
      "y": 2,
      "z": -9,
      "name": "Rock_Volcanic_Cobble"
    },
    {
      "x": -15,
      "y": 12,
      "z": -9,
      "name": "Rock_Volcanic_Brick_Smooth"
    },
    {
      "x": -15,
      "y": 113,
      "z": -9,
      "name": "Rock_Sandstone_Brick_Smooth"
    },
    {
      "x": -15,
      "y": 121,
      "z": -9,
      "name": "Rock_Sandstone_Brick_Smooth"
    },
    {
      "x": -15,
      "y": 129,
      "z": -9,
      "name": "Rock_Sandstone_Brick_Smooth"
    },
    {
      "x": -15,
      "y": 130,
      "z": -9,
      "name": "Rock_Sandstone"
    },
    {
      "x": -15,
      "y": 0,
      "z": -8,
      "name": "Rock_Volcanic"
    },
    {
      "x": -15,
      "y": 1,
      "z": -8,
      "name": "Rock_Volcanic_Cobble"
    },
    {
      "x": -15,
      "y": 2,
      "z": -8,
      "name": "Rock_Volcanic_Cobble"
    },
    {
      "x": -15,
      "y": 12,
      "z": -8,
      "name": "Rock_Volcanic_Brick_Smooth"
    },
    {
      "x": -15,
      "y": 113,
      "z": -8,
      "name": "Rock_Sandstone_Brick_Smooth"
    },
    {
      "x": -15,
      "y": 121,
      "z": -8,
      "name": "Rock_Sandstone_Brick_Smooth"
    },
    {
      "x": -15,
      "y": 129,
      "z": -8,
      "name": "Rock_Sandstone_Brick_Smooth"
    },
    {
      "x": -15,
      "y": 130,
      "z": -8,
      "name": "Rock_Sandstone"
    },
    {
      "x": -15,
      "y": 0,
      "z": -7,
      "name": "Rock_Volcanic_Cracked_Lava"
    },
    {
      "x": -15,
      "y": 1,
      "z": -7,
      "name": "Rock_Volcanic_Cobble"
    },
    {
      "x": -15,
      "y": 2,
      "z": -7,
      "name": "Rock_Volcanic_Cobble"
    },
    {
      "x": -15,
      "y": 12,
      "z": -7,
      "name": "Rock_Volcanic_Brick_Smooth"
    },
    {
      "x": -15,
      "y": 113,
      "z": -7,
      "name": "Rock_Sandstone_Brick_Smooth"
    },
    {
      "x": -15,
      "y": 121,
      "z": -7,
      "name": "Rock_Sandstone_Brick_Smooth"
    },
    {
      "x": -15,
      "y": 129,
      "z": -7,
      "name": "Rock_Sandstone_Brick_Smooth"
    },
    {
      "x": -15,
      "y": 130,
      "z": -7,
      "name": "Rock_Sandstone"
    },
    {
      "x": -15,
      "y": 0,
      "z": -6,
      "name": "Rock_Volcanic"
    },
    {
      "x": -15,
      "y": 1,
      "z": -6,
      "name": "Rock_Volcanic_Cobble"
    },
    {
      "x": -15,
      "y": 2,
      "z": -6,
      "name": "Rock_Volcanic_Cobble"
    },
    {
      "x": -15,
      "y": 12,
      "z": -6,
      "name": "Rock_Volcanic_Brick_Smooth"
    },
    {
      "x": -15,
      "y": 21,
      "z": -6,
      "name": "Survival_Trap_Spike_Iron",
      "rotation": 7
    },
    {
      "x": -15,
      "y": 113,
      "z": -6,
      "name": "Rock_Sandstone_Brick_Smooth"
    },
    {
      "x": -15,
      "y": 121,
      "z": -6,
      "name": "Rock_Sandstone_Brick_Smooth"
    },
    {
      "x": -15,
      "y": 129,
      "z": -6,
      "name": "Rock_Sandstone_Brick_Smooth"
    },
    {
      "x": -15,
      "y": 130,
      "z": -6,
      "name": "Rock_Sandstone"
    },
    {
      "x": -15,
      "y": 0,
      "z": -5,
      "name": "Rock_Volcanic_Cracked_Lava"
    },
    {
      "x": -15,
      "y": 1,
      "z": -5,
      "name": "Rock_Volcanic_Cobble"
    },
    {
      "x": -15,
      "y": 2,
      "z": -5,
      "name": "Rock_Volcanic_Cobble"
    },
    {
      "x": -15,
      "y": 12,
      "z": -5,
      "name": "Rock_Volcanic_Brick_Smooth"
    },
    {
      "x": -15,
      "y": 21,
      "z": -5,
      "name": "Survival_Trap_Spike_Iron",
      "rotation": 7
    },
    {
      "x": -15,
      "y": 113,
      "z": -5,
      "name": "Rock_Sandstone_Brick_Smooth"
    },
    {
      "x": -15,
      "y": 121,
      "z": -5,
      "name": "Rock_Sandstone_Brick_Smooth"
    },
    {
      "x": -15,
      "y": 129,
      "z": -5,
      "name": "Rock_Sandstone_Brick_Smooth"
    },
    {
      "x": -15,
      "y": 130,
      "z": -5,
      "name": "Rock_Sandstone"
    },
    {
      "x": -15,
      "y": 0,
      "z": -4,
      "name": "Rock_Volcanic"
    },
    {
      "x": -15,
      "y": 1,
      "z": -4,
      "name": "Rock_Volcanic_Cobble"
    },
    {
      "x": -15,
      "y": 2,
      "z": -4,
      "name": "Rock_Volcanic_Cobble"
    },
    {
      "x": -15,
      "y": 12,
      "z": -4,
      "name": "Rock_Volcanic_Brick_Smooth"
    },
    {
      "x": -15,
      "y": 21,
      "z": -4,
      "name": "Survival_Trap_Spike_Iron",
      "rotation": 7
    },
    {
      "x": -15,
      "y": 113,
      "z": -4,
      "name": "Rock_Sandstone_Brick_Smooth"
    },
    {
      "x": -15,
      "y": 121,
      "z": -4,
      "name": "Rock_Sandstone_Brick_Smooth"
    },
    {
      "x": -15,
      "y": 129,
      "z": -4,
      "name": "Rock_Sandstone_Brick_Smooth"
    },
    {
      "x": -15,
      "y": 130,
      "z": -4,
      "name": "Rock_Sandstone"
    },
    {
      "x": -15,
      "y": 0,
      "z": -3,
      "name": "Rock_Volcanic"
    },
    {
      "x": -15,
      "y": 1,
      "z": -3,
      "name": "Rock_Volcanic_Cobble"
    },
    {
      "x": -15,
      "y": 2,
      "z": -3,
      "name": "Rock_Volcanic_Cobble"
    },
    {
      "x": -15,
      "y": 12,
      "z": -3,
      "name": "Rock_Volcanic_Brick_Smooth"
    },
    {
      "x": -15,
      "y": 21,
      "z": -3,
      "name": "Survival_Trap_Spike_Iron",
      "rotation": 7
    },
    {
      "x": -15,
      "y": 113,
      "z": -3,
      "name": "Rock_Sandstone_Brick_Smooth"
    },
    {
      "x": -15,
      "y": 121,
      "z": -3,
      "name": "Rock_Sandstone_Brick_Smooth"
    },
    {
      "x": -15,
      "y": 129,
      "z": -3,
      "name": "Rock_Sandstone_Brick_Smooth"
    },
    {
      "x": -15,
      "y": 130,
      "z": -3,
      "name": "Rock_Sandstone"
    },
    {
      "x": -15,
      "y": 0,
      "z": -2,
      "name": "Rock_Volcanic_Cracked_Lava"
    },
    {
      "x": -15,
      "y": 1,
      "z": -2,
      "name": "Rock_Volcanic_Cobble"
    },
    {
      "x": -15,
      "y": 2,
      "z": -2,
      "name": "Rock_Volcanic_Cobble"
    },
    {
      "x": -15,
      "y": 12,
      "z": -2,
      "name": "Rock_Volcanic_Brick_Smooth"
    },
    {
      "x": -15,
      "y": 21,
      "z": -2,
      "name": "Survival_Trap_Spike_Iron",
      "rotation": 7
    },
    {
      "x": -15,
      "y": 113,
      "z": -2,
      "name": "Rock_Sandstone_Brick_Smooth"
    },
    {
      "x": -15,
      "y": 121,
      "z": -2,
      "name": "Rock_Sandstone_Brick_Smooth"
    },
    {
      "x": -15,
      "y": 129,
      "z": -2,
      "name": "Rock_Sandstone_Brick_Smooth"
    },
    {
      "x": -15,
      "y": 130,
      "z": -2,
      "name": "Rock_Sandstone"
    },
    {
      "x": -15,
      "y": 0,
      "z": -1,
      "name": "Rock_Volcanic"
    },
    {
      "x": -15,
      "y": 1,
      "z": -1,
      "name": "Rock_Volcanic_Cobble"
    },
    {
      "x": -15,
      "y": 2,
      "z": -1,
      "name": "Rock_Volcanic_Cobble"
    },
    {
      "x": -15,
      "y": 12,
      "z": -1,
      "name": "Rock_Volcanic_Brick_Smooth"
    },
    {
      "x": -15,
      "y": 21,
      "z": -1,
      "name": "Survival_Trap_Spike_Iron",
      "rotation": 7
    },
    {
      "x": -15,
      "y": 113,
      "z": -1,
      "name": "Rock_Sandstone_Brick_Smooth"
    },
    {
      "x": -15,
      "y": 121,
      "z": -1,
      "name": "Rock_Sandstone_Brick_Smooth"
    },
    {
      "x": -15,
      "y": 129,
      "z": -1,
      "name": "Rock_Sandstone_Brick_Smooth"
    },
    {
      "x": -15,
      "y": 130,
      "z": -1,
      "name": "Rock_Sandstone"
    },
    {
      "x": -15,
      "y": 0,
      "z": 0,
      "name": "Rock_Volcanic"
    },
    {
      "x": -15,
      "y": 1,
      "z": 0,
      "name": "Rock_Volcanic_Cobble"
    },
    {
      "x": -15,
      "y": 2,
      "z": 0,
      "name": "Rock_Volcanic_Cobble"
    },
    {
      "x": -15,
      "y": 12,
      "z": 0,
      "name": "Rock_Volcanic_Brick_Smooth"
    },
    {
      "x": -15,
      "y": 113,
      "z": 0,
      "name": "Rock_Sandstone_Brick_Smooth"
    },
    {
      "x": -15,
      "y": 121,
      "z": 0,
      "name": "Rock_Sandstone_Brick_Smooth"
    },
    {
      "x": -15,
      "y": 129,
      "z": 0,
      "name": "Rock_Sandstone_Brick_Smooth"
    },
    {
      "x": -15,
      "y": 130,
      "z": 0,
      "name": "Rock_Sandstone"
    },
    {
      "x": -15,
      "y": 0,
      "z": 1,
      "name": "Rock_Volcanic"
    },
    {
      "x": -15,
      "y": 1,
      "z": 1,
      "name": "Rock_Volcanic_Cobble"
    },
    {
      "x": -15,
      "y": 2,
      "z": 1,
      "name": "Rock_Volcanic_Cobble"
    },
    {
      "x": -15,
      "y": 12,
      "z": 1,
      "name": "Rock_Volcanic_Brick_Smooth"
    },
    {
      "x": -15,
      "y": 113,
      "z": 1,
      "name": "Rock_Sandstone_Brick_Smooth"
    },
    {
      "x": -15,
      "y": 121,
      "z": 1,
      "name": "Rock_Sandstone_Brick_Smooth"
    },
    {
      "x": -15,
      "y": 129,
      "z": 1,
      "name": "Rock_Sandstone_Brick_Smooth"
    },
    {
      "x": -15,
      "y": 130,
      "z": 1,
      "name": "Rock_Sandstone"
    },
    {
      "x": -15,
      "y": 0,
      "z": 2,
      "name": "Rock_Volcanic_Cracked_Lava"
    },
    {
      "x": -15,
      "y": 1,
      "z": 2,
      "name": "Rock_Volcanic_Cobble"
    },
    {
      "x": -15,
      "y": 2,
      "z": 2,
      "name": "Rock_Volcanic_Cobble"
    },
    {
      "x": -15,
      "y": 12,
      "z": 2,
      "name": "Rock_Volcanic_Brick_Smooth"
    },
    {
      "x": -15,
      "y": 113,
      "z": 2,
      "name": "Rock_Sandstone_Brick_Smooth"
    },
    {
      "x": -15,
      "y": 121,
      "z": 2,
      "name": "Rock_Sandstone_Brick_Smooth"
    },
    {
      "x": -15,
      "y": 129,
      "z": 2,
      "name": "Rock_Sandstone_Brick_Smooth"
    },
    {
      "x": -15,
      "y": 130,
      "z": 2,
      "name": "Rock_Sandstone"
    },
    {
      "x": -15,
      "y": 0,
      "z": 3,
      "name": "Rock_Volcanic_Cracked_Lava"
    },
    {
      "x": -15,
      "y": 1,
      "z": 3,
      "name": "Rock_Volcanic_Cobble"
    },
    {
      "x": -15,
      "y": 2,
      "z": 3,
      "name": "Rock_Volcanic_Cobble"
    },
    {
      "x": -15,
      "y": 12,
      "z": 3,
      "name": "Rock_Volcanic_Brick_Smooth"
    },
    {
      "x": -15,
      "y": 113,
      "z": 3,
      "name": "Rock_Sandstone_Brick_Smooth"
    },
    {
      "x": -15,
      "y": 121,
      "z": 3,
      "name": "Rock_Sandstone_Brick_Smooth"
    },
    {
      "x": -15,
      "y": 129,
      "z": 3,
      "name": "Rock_Sandstone_Brick_Smooth"
    },
    {
      "x": -15,
      "y": 130,
      "z": 3,
      "name": "Rock_Sandstone"
    },
    {
      "x": -15,
      "y": 0,
      "z": 4,
      "name": "Rock_Volcanic"
    },
    {
      "x": -15,
      "y": 1,
      "z": 4,
      "name": "Rock_Volcanic_Cobble"
    },
    {
      "x": -15,
      "y": 2,
      "z": 4,
      "name": "Rock_Volcanic_Cobble"
    },
    {
      "x": -15,
      "y": 12,
      "z": 4,
      "name": "Rock_Volcanic_Brick_Smooth"
    },
    {
      "x": -15,
      "y": 113,
      "z": 4,
      "name": "Rock_Sandstone_Brick_Smooth"
    },
    {
      "x": -15,
      "y": 121,
      "z": 4,
      "name": "Rock_Sandstone_Brick_Smooth"
    },
    {
      "x": -15,
      "y": 129,
      "z": 4,
      "name": "Rock_Sandstone_Brick_Smooth"
    },
    {
      "x": -15,
      "y": 130,
      "z": 4,
      "name": "Rock_Sandstone"
    },
    {
      "x": -15,
      "y": 0,
      "z": 5,
      "name": "Rock_Volcanic"
    },
    {
      "x": -15,
      "y": 1,
      "z": 5,
      "name": "Rock_Volcanic_Cobble"
    },
    {
      "x": -15,
      "y": 2,
      "z": 5,
      "name": "Rock_Volcanic_Cobble"
    },
    {
      "x": -15,
      "y": 12,
      "z": 5,
      "name": "Rock_Volcanic_Brick_Smooth"
    },
    {
      "x": -15,
      "y": 113,
      "z": 5,
      "name": "Rock_Sandstone_Brick_Smooth"
    },
    {
      "x": -15,
      "y": 121,
      "z": 5,
      "name": "Rock_Sandstone_Brick_Smooth"
    },
    {
      "x": -15,
      "y": 129,
      "z": 5,
      "name": "Rock_Sandstone_Brick_Smooth"
    },
    {
      "x": -15,
      "y": 130,
      "z": 5,
      "name": "Rock_Sandstone"
    },
    {
      "x": -15,
      "y": 0,
      "z": 6,
      "name": "Rock_Volcanic"
    },
    {
      "x": -15,
      "y": 1,
      "z": 6,
      "name": "Rock_Volcanic_Cobble"
    },
    {
      "x": -15,
      "y": 2,
      "z": 6,
      "name": "Rock_Volcanic_Cobble"
    },
    {
      "x": -15,
      "y": 12,
      "z": 6,
      "name": "Rock_Volcanic_Brick_Smooth"
    },
    {
      "x": -15,
      "y": 113,
      "z": 6,
      "name": "Rock_Sandstone_Brick_Smooth"
    },
    {
      "x": -15,
      "y": 121,
      "z": 6,
      "name": "Rock_Sandstone_Brick_Smooth"
    },
    {
      "x": -15,
      "y": 129,
      "z": 6,
      "name": "Rock_Sandstone_Brick_Smooth"
    },
    {
      "x": -15,
      "y": 130,
      "z": 6,
      "name": "Rock_Sandstone"
    },
    {
      "x": -15,
      "y": 0,
      "z": 7,
      "name": "Rock_Volcanic"
    },
    {
      "x": -15,
      "y": 1,
      "z": 7,
      "name": "Rock_Volcanic_Cobble"
    },
    {
      "x": -15,
      "y": 2,
      "z": 7,
      "name": "Rock_Volcanic_Cobble"
    },
    {
      "x": -15,
      "y": 12,
      "z": 7,
      "name": "Rock_Volcanic_Brick_Smooth"
    },
    {
      "x": -15,
      "y": 113,
      "z": 7,
      "name": "Rock_Sandstone_Brick_Smooth"
    },
    {
      "x": -15,
      "y": 121,
      "z": 7,
      "name": "Rock_Sandstone_Brick_Smooth"
    },
    {
      "x": -15,
      "y": 129,
      "z": 7,
      "name": "Rock_Sandstone_Brick_Smooth"
    },
    {
      "x": -15,
      "y": 130,
      "z": 7,
      "name": "Rock_Sandstone"
    },
    {
      "x": -15,
      "y": 0,
      "z": 8,
      "name": "Rock_Volcanic"
    },
    {
      "x": -15,
      "y": 1,
      "z": 8,
      "name": "Rock_Volcanic_Cobble"
    },
    {
      "x": -15,
      "y": 2,
      "z": 8,
      "name": "Rock_Volcanic_Cobble"
    },
    {
      "x": -15,
      "y": 12,
      "z": 8,
      "name": "Rock_Volcanic_Brick_Smooth"
    },
    {
      "x": -15,
      "y": 113,
      "z": 8,
      "name": "Rock_Sandstone_Brick_Smooth"
    },
    {
      "x": -15,
      "y": 121,
      "z": 8,
      "name": "Rock_Sandstone_Brick_Smooth"
    },
    {
      "x": -15,
      "y": 129,
      "z": 8,
      "name": "Rock_Sandstone_Brick_Smooth"
    },
    {
      "x": -15,
      "y": 130,
      "z": 8,
      "name": "Rock_Sandstone"
    },
    {
      "x": -15,
      "y": 0,
      "z": 9,
      "name": "Rock_Volcanic_Cracked_Lava"
    },
    {
      "x": -15,
      "y": 1,
      "z": 9,
      "name": "Rock_Volcanic_Cobble"
    },
    {
      "x": -15,
      "y": 2,
      "z": 9,
      "name": "Rock_Volcanic_Cobble"
    },
    {
      "x": -15,
      "y": 12,
      "z": 9,
      "name": "Rock_Volcanic_Brick_Smooth"
    },
    {
      "x": -15,
      "y": 113,
      "z": 9,
      "name": "Rock_Sandstone_Brick_Smooth"
    },
    {
      "x": -15,
      "y": 121,
      "z": 9,
      "name": "Rock_Sandstone_Brick_Smooth"
    },
    {
      "x": -15,
      "y": 129,
      "z": 9,
      "name": "Rock_Sandstone_Brick_Smooth"
    },
    {
      "x": -15,
      "y": 130,
      "z": 9,
      "name": "Rock_Sandstone"
    },
    {
      "x": -15,
      "y": 0,
      "z": 10,
      "name": "Rock_Volcanic"
    },
    {
      "x": -15,
      "y": 1,
      "z": 10,
      "name": "Rock_Volcanic_Cobble"
    },
    {
      "x": -15,
      "y": 2,
      "z": 10,
      "name": "Rock_Volcanic_Cobble"
    },
    {
      "x": -15,
      "y": 12,
      "z": 10,
      "name": "Rock_Volcanic_Brick_Smooth"
    },
    {
      "x": -15,
      "y": 113,
      "z": 10,
      "name": "Rock_Sandstone_Brick_Smooth"
    },
    {
      "x": -15,
      "y": 121,
      "z": 10,
      "name": "Rock_Sandstone_Brick_Smooth"
    },
    {
      "x": -15,
      "y": 129,
      "z": 10,
      "name": "Rock_Sandstone_Brick_Smooth"
    },
    {
      "x": -15,
      "y": 130,
      "z": 10,
      "name": "Rock_Sandstone"
    },
    {
      "x": -15,
      "y": 0,
      "z": 11,
      "name": "Rock_Volcanic"
    },
    {
      "x": -15,
      "y": 1,
      "z": 11,
      "name": "Rock_Volcanic_Cobble"
    },
    {
      "x": -15,
      "y": 2,
      "z": 11,
      "name": "Rock_Volcanic_Cobble"
    },
    {
      "x": -15,
      "y": 12,
      "z": 11,
      "name": "Rock_Volcanic_Brick_Smooth"
    },
    {
      "x": -15,
      "y": 113,
      "z": 11,
      "name": "Rock_Sandstone_Brick_Smooth"
    },
    {
      "x": -15,
      "y": 121,
      "z": 11,
      "name": "Rock_Sandstone_Brick_Smooth"
    },
    {
      "x": -15,
      "y": 129,
      "z": 11,
      "name": "Rock_Sandstone_Brick_Smooth"
    },
    {
      "x": -15,
      "y": 130,
      "z": 11,
      "name": "Rock_Sandstone"
    },
    {
      "x": -15,
      "y": 0,
      "z": 12,
      "name": "Rock_Volcanic_Cracked_Lava"
    },
    {
      "x": -15,
      "y": 1,
      "z": 12,
      "name": "Rock_Volcanic_Cobble"
    },
    {
      "x": -15,
      "y": 2,
      "z": 12,
      "name": "Rock_Volcanic_Cobble"
    },
    {
      "x": -15,
      "y": 12,
      "z": 12,
      "name": "Rock_Volcanic_Brick_Smooth"
    },
    {
      "x": -15,
      "y": 113,
      "z": 12,
      "name": "Rock_Sandstone_Brick_Smooth"
    },
    {
      "x": -15,
      "y": 121,
      "z": 12,
      "name": "Rock_Sandstone_Brick_Smooth"
    },
    {
      "x": -15,
      "y": 129,
      "z": 12,
      "name": "Rock_Sandstone_Brick_Smooth"
    },
    {
      "x": -15,
      "y": 130,
      "z": 12,
      "name": "Rock_Sandstone"
    },
    {
      "x": -15,
      "y": 0,
      "z": 13,
      "name": "Rock_Volcanic"
    },
    {
      "x": -15,
      "y": 1,
      "z": 13,
      "name": "Rock_Volcanic_Cobble"
    },
    {
      "x": -15,
      "y": 2,
      "z": 13,
      "name": "Rock_Volcanic_Cobble"
    },
    {
      "x": -15,
      "y": 12,
      "z": 13,
      "name": "Rock_Volcanic_Brick_Smooth"
    },
    {
      "x": -15,
      "y": 113,
      "z": 13,
      "name": "Rock_Sandstone_Brick_Smooth"
    },
    {
      "x": -15,
      "y": 121,
      "z": 13,
      "name": "Rock_Sandstone_Brick_Smooth"
    },
    {
      "x": -15,
      "y": 129,
      "z": 13,
      "name": "Rock_Sandstone_Brick_Smooth"
    },
    {
      "x": -15,
      "y": 130,
      "z": 13,
      "name": "Rock_Sandstone"
    },
    {
      "x": -15,
      "y": 0,
      "z": 14,
      "name": "Rock_Volcanic"
    },
    {
      "x": -15,
      "y": 1,
      "z": 14,
      "name": "Rock_Volcanic_Cobble"
    },
    {
      "x": -15,
      "y": 2,
      "z": 14,
      "name": "Rock_Volcanic_Cobble"
    },
    {
      "x": -15,
      "y": 12,
      "z": 14,
      "name": "Rock_Volcanic_Brick_Smooth"
    },
    {
      "x": -15,
      "y": 113,
      "z": 14,
      "name": "Rock_Sandstone_Brick_Smooth"
    },
    {
      "x": -15,
      "y": 121,
      "z": 14,
      "name": "Rock_Sandstone_Brick_Smooth"
    },
    {
      "x": -15,
      "y": 129,
      "z": 14,
      "name": "Rock_Sandstone_Brick_Smooth"
    },
    {
      "x": -15,
      "y": 130,
      "z": 14,
      "name": "Rock_Sandstone"
    },
    {
      "x": -15,
      "y": 0,
      "z": 15,
      "name": "Rock_Volcanic"
    },
    {
      "x": -15,
      "y": 1,
      "z": 15,
      "name": "Rock_Volcanic_Cobble"
    },
    {
      "x": -15,
      "y": 2,
      "z": 15,
      "name": "Rock_Volcanic_Cobble"
    },
    {
      "x": -15,
      "y": 12,
      "z": 15,
      "name": "Rock_Volcanic_Brick_Smooth"
    },
    {
      "x": -15,
      "y": 113,
      "z": 15,
      "name": "Rock_Sandstone_Brick_Smooth"
    },
    {
      "x": -15,
      "y": 121,
      "z": 15,
      "name": "Rock_Sandstone_Brick_Smooth"
    },
    {
      "x": -15,
      "y": 129,
      "z": 15,
      "name": "Rock_Sandstone_Brick_Smooth"
    },
    {
      "x": -15,
      "y": 130,
      "z": 15,
      "name": "Rock_Sandstone"
    },
    {
      "x": -14,
      "y": 0,
      "z": -15,
      "name": "Rock_Volcanic"
    },
    {
      "x": -14,
      "y": 1,
      "z": -15,
      "name": "Rock_Volcanic_Cobble"
    },
    {
      "x": -14,
      "y": 2,
      "z": -15,
      "name": "Rock_Volcanic_Cobble"
    },
    {
      "x": -14,
      "y": 12,
      "z": -15,
      "name": "Rock_Volcanic_Brick_Smooth"
    },
    {
      "x": -14,
      "y": 113,
      "z": -15,
      "name": "Rock_Sandstone_Brick_Smooth"
    },
    {
      "x": -14,
      "y": 121,
      "z": -15,
      "name": "Rock_Sandstone_Brick_Smooth"
    },
    {
      "x": -14,
      "y": 129,
      "z": -15,
      "name": "Rock_Sandstone_Brick_Smooth"
    },
    {
      "x": -14,
      "y": 130,
      "z": -15,
      "name": "Rock_Sandstone"
    },
    {
      "x": -14,
      "y": 0,
      "z": -14,
      "name": "Rock_Volcanic"
    },
    {
      "x": -14,
      "y": 1,
      "z": -14,
      "name": "Rock_Volcanic_Cobble"
    },
    {
      "x": -14,
      "y": 2,
      "z": -14,
      "name": "Rock_Volcanic_Cobble"
    },
    {
      "x": -14,
      "y": 12,
      "z": -14,
      "name": "Rock_Volcanic_Brick_Smooth"
    },
    {
      "x": -14,
      "y": 113,
      "z": -14,
      "name": "Rock_Sandstone_Brick_Smooth"
    },
    {
      "x": -14,
      "y": 121,
      "z": -14,
      "name": "Rock_Sandstone_Brick_Smooth"
    },
    {
      "x": -14,
      "y": 128,
      "z": -14,
      "name": "Deco_SpiderWeb",
      "rotation": 8
    },
    {
      "x": -14,
      "y": 129,
      "z": -14,
      "name": "Rock_Sandstone_Brick_Smooth"
    },
    {
      "x": -14,
      "y": 130,
      "z": -14,
      "name": "Rock_Sandstone"
    },
    {
      "x": -14,
      "y": 0,
      "z": -13,
      "name": "Rock_Volcanic"
    },
    {
      "x": -14,
      "y": 1,
      "z": -13,
      "name": "Rock_Volcanic_Cobble"
    },
    {
      "x": -14,
      "y": 2,
      "z": -13,
      "name": "Rock_Volcanic_Cobble"
    },
    {
      "x": -14,
      "y": 12,
      "z": -13,
      "name": "Rock_Volcanic_Brick_Smooth"
    },
    {
      "x": -14,
      "y": 113,
      "z": -13,
      "name": "Rock_Sandstone_Brick_Smooth"
    },
    {
      "x": -14,
      "y": 121,
      "z": -13,
      "name": "Rock_Sandstone_Brick_Smooth"
    },
    {
      "x": -14,
      "y": 129,
      "z": -13,
      "name": "Rock_Sandstone_Brick_Smooth"
    },
    {
      "x": -14,
      "y": 130,
      "z": -13,
      "name": "Rock_Sandstone"
    },
    {
      "x": -14,
      "y": 0,
      "z": -12,
      "name": "Rock_Volcanic"
    },
    {
      "x": -14,
      "y": 1,
      "z": -12,
      "name": "Rock_Volcanic_Cobble"
    },
    {
      "x": -14,
      "y": 2,
      "z": -12,
      "name": "Rock_Volcanic_Cobble"
    },
    {
      "x": -14,
      "y": 12,
      "z": -12,
      "name": "Rock_Volcanic_Brick_Smooth"
    },
    {
      "x": -14,
      "y": 113,
      "z": -12,
      "name": "Rock_Sandstone_Brick_Smooth"
    },
    {
      "x": -14,
      "y": 121,
      "z": -12,
      "name": "Rock_Sandstone_Brick_Smooth"
    },
    {
      "x": -14,
      "y": 129,
      "z": -12,
      "name": "Rock_Sandstone_Brick_Smooth"
    },
    {
      "x": -14,
      "y": 130,
      "z": -12,
      "name": "Rock_Sandstone"
    },
    {
      "x": -14,
      "y": 0,
      "z": -11,
      "name": "Rock_Volcanic"
    },
    {
      "x": -14,
      "y": 1,
      "z": -11,
      "name": "Rock_Volcanic_Cobble"
    },
    {
      "x": -14,
      "y": 2,
      "z": -11,
      "name": "Rock_Volcanic_Cobble"
    },
    {
      "x": -14,
      "y": 3,
      "z": -11,
      "name": "Rock_Volcanic_Brick_Smooth",
      "rotation": 3
    },
    {
      "x": -14,
      "y": 4,
      "z": -11,
      "name": "Rock_Volcanic_Brick_Ornate",
      "rotation": 3
    },
    {
      "x": -14,
      "y": 5,
      "z": -11,
      "name": "Rock_Volcanic_Brick_Decorative",
      "rotation": 3
    },
    {
      "x": -14,
      "y": 6,
      "z": -11,
      "name": "Rock_Volcanic_Brick_Decorative",
      "rotation": 3
    },
    {
      "x": -14,
      "y": 7,
      "z": -11,
      "name": "Rock_Volcanic_Brick_Decorative",
      "rotation": 3
    },
    {
      "x": -14,
      "y": 8,
      "z": -11,
      "name": "Rock_Volcanic_Brick_Ornate",
      "rotation": 3
    },
    {
      "x": -14,
      "y": 9,
      "z": -11,
      "name": "Rock_Volcanic_Brick",
      "rotation": 3
    },
    {
      "x": -14,
      "y": 10,
      "z": -11,
      "name": "Rock_Volcanic_Brick",
      "rotation": 3
    },
    {
      "x": -14,
      "y": 11,
      "z": -11,
      "name": "Rock_Volcanic_Brick",
      "rotation": 3
    },
    {
      "x": -14,
      "y": 12,
      "z": -11,
      "name": "Rock_Volcanic_Brick_Smooth"
    },
    {
      "x": -14,
      "y": 13,
      "z": -11,
      "name": "Rock_Volcanic_Brick",
      "rotation": 3
    },
    {
      "x": -14,
      "y": 14,
      "z": -11,
      "name": "Rock_Volcanic_Brick",
      "rotation": 3
    },
    {
      "x": -14,
      "y": 15,
      "z": -11,
      "name": "Rock_Volcanic_Brick_Ornate",
      "rotation": 3
    },
    {
      "x": -14,
      "y": 16,
      "z": -11,
      "name": "Rock_Volcanic_Brick_Decorative",
      "rotation": 3
    },
    {
      "x": -14,
      "y": 17,
      "z": -11,
      "name": "Rock_Volcanic_Brick_Decorative",
      "rotation": 3
    },
    {
      "x": -14,
      "y": 18,
      "z": -11,
      "name": "Rock_Volcanic_Brick_Decorative",
      "rotation": 3
    },
    {
      "x": -14,
      "y": 19,
      "z": -11,
      "name": "Rock_Volcanic_Brick_Ornate",
      "rotation": 3
    },
    {
      "x": -14,
      "y": 20,
      "z": -11,
      "name": "Rock_Volcanic_Brick",
      "rotation": 3
    },
    {
      "x": -14,
      "y": 21,
      "z": -11,
      "name": "Rock_Volcanic_Brick_Smooth",
      "rotation": 3
    },
    {
      "x": -14,
      "y": 111,
      "z": -11,
      "name": "Rock_Sandstone_Brick_Ornate"
    },
    {
      "x": -14,
      "y": 112,
      "z": -11,
      "name": "Rock_Sandstone_Brick"
    },
    {
      "x": -14,
      "y": 113,
      "z": -11,
      "name": "Rock_Sandstone_Brick_Smooth"
    },
    {
      "x": -14,
      "y": 114,
      "z": -11,
      "name": "Rock_Sandstone_Brick"
    },
    {
      "x": -14,
      "y": 115,
      "z": -11,
      "name": "Rock_Sandstone_Brick_Ornate"
    },
    {
      "x": -14,
      "y": 116,
      "z": -11,
      "name": "Rock_Sandstone_Brick_Decorative"
    },
    {
      "x": -14,
      "y": 117,
      "z": -11,
      "name": "Rock_Sandstone_Brick_Decorative"
    },
    {
      "x": -14,
      "y": 118,
      "z": -11,
      "name": "Rock_Sandstone_Brick_Decorative"
    },
    {
      "x": -14,
      "y": 119,
      "z": -11,
      "name": "Rock_Sandstone_Brick_Ornate"
    },
    {
      "x": -14,
      "y": 120,
      "z": -11,
      "name": "Rock_Sandstone_Brick"
    },
    {
      "x": -14,
      "y": 121,
      "z": -11,
      "name": "Rock_Sandstone_Brick_Smooth"
    },
    {
      "x": -14,
      "y": 122,
      "z": -11,
      "name": "Rock_Sandstone_Brick"
    },
    {
      "x": -14,
      "y": 123,
      "z": -11,
      "name": "Rock_Sandstone_Brick_Ornate"
    },
    {
      "x": -14,
      "y": 124,
      "z": -11,
      "name": "Rock_Sandstone_Brick_Decorative"
    },
    {
      "x": -14,
      "y": 125,
      "z": -11,
      "name": "Rock_Sandstone_Brick_Decorative"
    },
    {
      "x": -14,
      "y": 126,
      "z": -11,
      "name": "Rock_Sandstone_Brick_Decorative"
    },
    {
      "x": -14,
      "y": 127,
      "z": -11,
      "name": "Rock_Sandstone_Brick_Ornate"
    },
    {
      "x": -14,
      "y": 128,
      "z": -11,
      "name": "Rock_Sandstone_Brick"
    },
    {
      "x": -14,
      "y": 129,
      "z": -11,
      "name": "Rock_Sandstone_Brick_Smooth",
      "rotation": 3
    },
    {
      "x": -14,
      "y": 130,
      "z": -11,
      "name": "Rock_Sandstone",
      "rotation": 3
    },
    {
      "x": -14,
      "y": 0,
      "z": -10,
      "name": "Rock_Volcanic_Cracked_Lava"
    },
    {
      "x": -14,
      "y": 1,
      "z": -10,
      "name": "Rock_Volcanic_Cobble"
    },
    {
      "x": -14,
      "y": 2,
      "z": -10,
      "name": "Rock_Volcanic_Cobble"
    },
    {
      "x": -14,
      "y": 3,
      "z": -10,
      "name": "Survival_Trap_Spike_Wood"
    },
    {
      "x": -14,
      "y": 12,
      "z": -10,
      "name": "Rock_Volcanic_Brick_Smooth"
    },
    {
      "x": -14,
      "y": 113,
      "z": -10,
      "name": "Rock_Sandstone_Brick_Smooth"
    },
    {
      "x": -14,
      "y": 121,
      "z": -10,
      "name": "Rock_Sandstone_Brick_Smooth"
    },
    {
      "x": -14,
      "y": 129,
      "z": -10,
      "name": "Rock_Sandstone_Brick_Smooth"
    },
    {
      "x": -14,
      "y": 130,
      "z": -10,
      "name": "Rock_Sandstone"
    },
    {
      "x": -14,
      "y": 0,
      "z": -9,
      "name": "Rock_Volcanic_Cracked_Lava"
    },
    {
      "x": -14,
      "y": 1,
      "z": -9,
      "name": "Rock_Volcanic_Cobble"
    },
    {
      "x": -14,
      "y": 2,
      "z": -9,
      "name": "Rock_Volcanic_Cobble"
    },
    {
      "x": -14,
      "y": 3,
      "z": -9,
      "name": "Survival_Trap_Spike_Wood"
    },
    {
      "x": -14,
      "y": 12,
      "z": -9,
      "name": "Rock_Volcanic_Brick_Smooth"
    },
    {
      "x": -14,
      "y": 113,
      "z": -9,
      "name": "Rock_Sandstone_Brick_Smooth"
    },
    {
      "x": -14,
      "y": 121,
      "z": -9,
      "name": "Rock_Sandstone_Brick_Smooth"
    },
    {
      "x": -14,
      "y": 129,
      "z": -9,
      "name": "Rock_Sandstone_Brick_Smooth"
    },
    {
      "x": -14,
      "y": 130,
      "z": -9,
      "name": "Rock_Sandstone"
    },
    {
      "x": -14,
      "y": 0,
      "z": -8,
      "name": "Rock_Volcanic"
    },
    {
      "x": -14,
      "y": 1,
      "z": -8,
      "name": "Rock_Volcanic_Cobble"
    },
    {
      "x": -14,
      "y": 2,
      "z": -8,
      "name": "Rock_Volcanic_Cobble"
    },
    {
      "x": -14,
      "y": 3,
      "z": -8,
      "name": "Survival_Trap_Spike_Wood"
    },
    {
      "x": -14,
      "y": 12,
      "z": -8,
      "name": "Rock_Volcanic_Brick_Smooth"
    },
    {
      "x": -14,
      "y": 113,
      "z": -8,
      "name": "Rock_Sandstone_Brick_Smooth"
    },
    {
      "x": -14,
      "y": 114,
      "z": -8,
      "name": "Deco_SpiderWeb",
      "rotation": 3
    },
    {
      "x": -14,
      "y": 121,
      "z": -8,
      "name": "Rock_Sandstone_Brick_Smooth"
    },
    {
      "x": -14,
      "y": 129,
      "z": -8,
      "name": "Rock_Sandstone_Brick_Smooth"
    },
    {
      "x": -14,
      "y": 130,
      "z": -8,
      "name": "Rock_Sandstone"
    },
    {
      "x": -14,
      "y": 0,
      "z": -7,
      "name": "Rock_Volcanic_Cracked_Lava"
    },
    {
      "x": -14,
      "y": 1,
      "z": -7,
      "name": "Rock_Volcanic_Cobble"
    },
    {
      "x": -14,
      "y": 2,
      "z": -7,
      "name": "Rock_Volcanic_Cobble"
    },
    {
      "x": -14,
      "y": 3,
      "z": -7,
      "name": "Survival_Trap_Spike_Wood"
    },
    {
      "x": -14,
      "y": 12,
      "z": -7,
      "name": "Rock_Volcanic_Brick_Smooth"
    },
    {
      "x": -14,
      "y": 21,
      "z": -7,
      "name": "Survival_Trap_Spike_Iron",
      "rotation": 6
    },
    {
      "x": -14,
      "y": 113,
      "z": -7,
      "name": "Rock_Sandstone_Brick_Smooth"
    },
    {
      "x": -14,
      "y": 121,
      "z": -7,
      "name": "Rock_Sandstone_Brick_Smooth"
    },
    {
      "x": -14,
      "y": 129,
      "z": -7,
      "name": "Rock_Sandstone_Brick_Smooth"
    },
    {
      "x": -14,
      "y": 130,
      "z": -7,
      "name": "Rock_Sandstone"
    },
    {
      "x": -14,
      "y": 0,
      "z": -6,
      "name": "Rock_Volcanic"
    },
    {
      "x": -14,
      "y": 1,
      "z": -6,
      "name": "Rock_Volcanic_Cobble"
    },
    {
      "x": -14,
      "y": 2,
      "z": -6,
      "name": "Rock_Volcanic_Cobble"
    },
    {
      "x": -14,
      "y": 3,
      "z": -6,
      "name": "Rock_Volcanic_Brick_Smooth",
      "rotation": 1
    },
    {
      "x": -14,
      "y": 4,
      "z": -6,
      "name": "Rock_Volcanic_Brick_Ornate",
      "rotation": 1
    },
    {
      "x": -14,
      "y": 5,
      "z": -6,
      "name": "Rock_Volcanic_Brick_Decorative",
      "rotation": 1
    },
    {
      "x": -14,
      "y": 6,
      "z": -6,
      "name": "Rock_Volcanic_Brick_Decorative",
      "rotation": 1
    },
    {
      "x": -14,
      "y": 7,
      "z": -6,
      "name": "Rock_Volcanic_Brick_Decorative",
      "rotation": 1
    },
    {
      "x": -14,
      "y": 8,
      "z": -6,
      "name": "Rock_Volcanic_Brick_Ornate",
      "rotation": 1
    },
    {
      "x": -14,
      "y": 9,
      "z": -6,
      "name": "Rock_Volcanic_Brick",
      "rotation": 1
    },
    {
      "x": -14,
      "y": 10,
      "z": -6,
      "name": "Rock_Volcanic_Brick",
      "rotation": 1
    },
    {
      "x": -14,
      "y": 11,
      "z": -6,
      "name": "Rock_Volcanic_Brick",
      "rotation": 1
    },
    {
      "x": -14,
      "y": 12,
      "z": -6,
      "name": "Rock_Volcanic_Brick_Smooth"
    },
    {
      "x": -14,
      "y": 13,
      "z": -6,
      "name": "Rock_Volcanic_Brick",
      "rotation": 1
    },
    {
      "x": -14,
      "y": 14,
      "z": -6,
      "name": "Rock_Volcanic_Brick",
      "rotation": 1
    },
    {
      "x": -14,
      "y": 15,
      "z": -6,
      "name": "Rock_Volcanic_Brick_Ornate",
      "rotation": 1
    },
    {
      "x": -14,
      "y": 16,
      "z": -6,
      "name": "Rock_Volcanic_Brick_Decorative",
      "rotation": 1
    },
    {
      "x": -14,
      "y": 17,
      "z": -6,
      "name": "Rock_Volcanic_Brick_Decorative",
      "rotation": 1
    },
    {
      "x": -14,
      "y": 18,
      "z": -6,
      "name": "Rock_Volcanic_Brick_Decorative",
      "rotation": 1
    },
    {
      "x": -14,
      "y": 19,
      "z": -6,
      "name": "Rock_Volcanic_Brick_Ornate",
      "rotation": 1
    },
    {
      "x": -14,
      "y": 20,
      "z": -6,
      "name": "Rock_Volcanic_Brick",
      "rotation": 1
    },
    {
      "x": -14,
      "y": 21,
      "z": -6,
      "name": "Rock_Volcanic_Brick_Smooth",
      "rotation": 1
    },
    {
      "x": -14,
      "y": 22,
      "z": -6,
      "name": "Survival_Trap_Spike_Iron"
    },
    {
      "x": -14,
      "y": 111,
      "z": -6,
      "name": "Rock_Sandstone_Brick_Ornate",
      "rotation": 2
    },
    {
      "x": -14,
      "y": 112,
      "z": -6,
      "name": "Rock_Sandstone_Brick",
      "rotation": 2
    },
    {
      "x": -14,
      "y": 113,
      "z": -6,
      "name": "Rock_Sandstone_Brick_Smooth"
    },
    {
      "x": -14,
      "y": 114,
      "z": -6,
      "name": "Rock_Sandstone_Brick",
      "rotation": 2
    },
    {
      "x": -14,
      "y": 115,
      "z": -6,
      "name": "Rock_Sandstone_Brick_Ornate",
      "rotation": 2
    },
    {
      "x": -14,
      "y": 116,
      "z": -6,
      "name": "Rock_Sandstone_Brick_Decorative",
      "rotation": 2
    },
    {
      "x": -14,
      "y": 117,
      "z": -6,
      "name": "Rock_Sandstone_Brick_Decorative",
      "rotation": 2
    },
    {
      "x": -14,
      "y": 118,
      "z": -6,
      "name": "Rock_Sandstone_Brick_Decorative",
      "rotation": 2
    },
    {
      "x": -14,
      "y": 119,
      "z": -6,
      "name": "Rock_Sandstone_Brick_Ornate",
      "rotation": 2
    },
    {
      "x": -14,
      "y": 120,
      "z": -6,
      "name": "Rock_Sandstone_Brick",
      "rotation": 2
    },
    {
      "x": -14,
      "y": 121,
      "z": -6,
      "name": "Rock_Sandstone_Brick_Smooth"
    },
    {
      "x": -14,
      "y": 122,
      "z": -6,
      "name": "Rock_Sandstone_Brick",
      "rotation": 2
    },
    {
      "x": -14,
      "y": 123,
      "z": -6,
      "name": "Rock_Sandstone_Brick_Ornate",
      "rotation": 2
    },
    {
      "x": -14,
      "y": 124,
      "z": -6,
      "name": "Rock_Sandstone_Brick_Decorative",
      "rotation": 2
    },
    {
      "x": -14,
      "y": 125,
      "z": -6,
      "name": "Rock_Sandstone_Brick_Decorative",
      "rotation": 2
    },
    {
      "x": -14,
      "y": 126,
      "z": -6,
      "name": "Rock_Sandstone_Brick_Decorative",
      "rotation": 2
    },
    {
      "x": -14,
      "y": 127,
      "z": -6,
      "name": "Rock_Sandstone_Brick_Ornate",
      "rotation": 2
    },
    {
      "x": -14,
      "y": 128,
      "z": -6,
      "name": "Rock_Sandstone_Brick",
      "rotation": 2
    },
    {
      "x": -14,
      "y": 129,
      "z": -6,
      "name": "Rock_Sandstone_Brick_Smooth"
    },
    {
      "x": -14,
      "y": 130,
      "z": -6,
      "name": "Rock_Sandstone"
    },
    {
      "x": -14,
      "y": 0,
      "z": -5,
      "name": "Rock_Volcanic"
    },
    {
      "x": -14,
      "y": 1,
      "z": -5,
      "name": "Rock_Volcanic_Cobble"
    },
    {
      "x": -14,
      "y": 2,
      "z": -5,
      "name": "Rock_Volcanic_Cobble"
    },
    {
      "x": -14,
      "y": 3,
      "z": -5,
      "name": "Rock_Volcanic_Brick_Smooth",
      "rotation": 1
    },
    {
      "x": -14,
      "y": 4,
      "z": -5,
      "name": "Rock_Volcanic_Brick_Ornate",
      "rotation": 1
    },
    {
      "x": -14,
      "y": 5,
      "z": -5,
      "name": "Rock_Volcanic_Brick_Decorative",
      "rotation": 1
    },
    {
      "x": -14,
      "y": 6,
      "z": -5,
      "name": "Rock_Volcanic_Brick_Decorative",
      "rotation": 1
    },
    {
      "x": -14,
      "y": 7,
      "z": -5,
      "name": "Rock_Volcanic_Brick_Decorative",
      "rotation": 1
    },
    {
      "x": -14,
      "y": 8,
      "z": -5,
      "name": "Rock_Volcanic_Brick_Ornate",
      "rotation": 1
    },
    {
      "x": -14,
      "y": 9,
      "z": -5,
      "name": "Rock_Volcanic_Brick",
      "rotation": 1
    },
    {
      "x": -14,
      "y": 10,
      "z": -5,
      "name": "Rock_Volcanic_Brick",
      "rotation": 1
    },
    {
      "x": -14,
      "y": 11,
      "z": -5,
      "name": "Rock_Volcanic_Brick",
      "rotation": 1
    },
    {
      "x": -14,
      "y": 12,
      "z": -5,
      "name": "Rock_Volcanic_Brick_Smooth"
    },
    {
      "x": -14,
      "y": 13,
      "z": -5,
      "name": "Rock_Volcanic_Brick",
      "rotation": 1
    },
    {
      "x": -14,
      "y": 14,
      "z": -5,
      "name": "Rock_Volcanic_Brick",
      "rotation": 1
    },
    {
      "x": -14,
      "y": 15,
      "z": -5,
      "name": "Rock_Volcanic_Brick_Ornate",
      "rotation": 1
    },
    {
      "x": -14,
      "y": 16,
      "z": -5,
      "name": "Rock_Volcanic_Brick_Decorative",
      "rotation": 1
    },
    {
      "x": -14,
      "y": 17,
      "z": -5,
      "name": "Rock_Volcanic_Brick_Decorative",
      "rotation": 1
    },
    {
      "x": -14,
      "y": 18,
      "z": -5,
      "name": "Rock_Volcanic_Brick_Decorative",
      "rotation": 1
    },
    {
      "x": -14,
      "y": 19,
      "z": -5,
      "name": "Rock_Volcanic_Brick_Ornate",
      "rotation": 1
    },
    {
      "x": -14,
      "y": 20,
      "z": -5,
      "name": "Rock_Volcanic_Brick",
      "rotation": 1
    },
    {
      "x": -14,
      "y": 21,
      "z": -5,
      "name": "Rock_Volcanic_Brick_Smooth",
      "rotation": 1
    },
    {
      "x": -14,
      "y": 22,
      "z": -5,
      "name": "Survival_Trap_Spike_Iron"
    },
    {
      "x": -14,
      "y": 111,
      "z": -5,
      "name": "Rock_Sandstone_Brick_Ornate",
      "rotation": 2
    },
    {
      "x": -14,
      "y": 112,
      "z": -5,
      "name": "Rock_Sandstone_Brick",
      "rotation": 2
    },
    {
      "x": -14,
      "y": 113,
      "z": -5,
      "name": "Rock_Sandstone_Brick_Smooth"
    },
    {
      "x": -14,
      "y": 114,
      "z": -5,
      "name": "Rock_Sandstone_Brick",
      "rotation": 2
    },
    {
      "x": -14,
      "y": 115,
      "z": -5,
      "name": "Rock_Sandstone_Brick_Ornate",
      "rotation": 2
    },
    {
      "x": -14,
      "y": 116,
      "z": -5,
      "name": "Rock_Sandstone_Brick_Decorative",
      "rotation": 2
    },
    {
      "x": -14,
      "y": 117,
      "z": -5,
      "name": "Rock_Sandstone_Brick_Decorative",
      "rotation": 2
    },
    {
      "x": -14,
      "y": 118,
      "z": -5,
      "name": "Rock_Sandstone_Brick_Decorative",
      "rotation": 2
    },
    {
      "x": -14,
      "y": 119,
      "z": -5,
      "name": "Rock_Sandstone_Brick_Ornate",
      "rotation": 2
    },
    {
      "x": -14,
      "y": 120,
      "z": -5,
      "name": "Rock_Sandstone_Brick",
      "rotation": 2
    },
    {
      "x": -14,
      "y": 121,
      "z": -5,
      "name": "Rock_Sandstone_Brick_Smooth"
    },
    {
      "x": -14,
      "y": 122,
      "z": -5,
      "name": "Rock_Sandstone_Brick",
      "rotation": 2
    },
    {
      "x": -14,
      "y": 123,
      "z": -5,
      "name": "Rock_Sandstone_Brick_Ornate",
      "rotation": 2
    },
    {
      "x": -14,
      "y": 124,
      "z": -5,
      "name": "Rock_Sandstone_Brick_Decorative",
      "rotation": 2
    },
    {
      "x": -14,
      "y": 125,
      "z": -5,
      "name": "Rock_Sandstone_Brick_Decorative",
      "rotation": 2
    },
    {
      "x": -14,
      "y": 126,
      "z": -5,
      "name": "Rock_Sandstone_Brick_Decorative",
      "rotation": 2
    },
    {
      "x": -14,
      "y": 127,
      "z": -5,
      "name": "Rock_Sandstone_Brick_Ornate",
      "rotation": 2
    },
    {
      "x": -14,
      "y": 128,
      "z": -5,
      "name": "Rock_Sandstone_Brick",
      "rotation": 2
    },
    {
      "x": -14,
      "y": 129,
      "z": -5,
      "name": "Rock_Sandstone_Brick_Smooth",
      "rotation": 1
    },
    {
      "x": -14,
      "y": 130,
      "z": -5,
      "name": "Rock_Sandstone",
      "rotation": 1
    },
    {
      "x": -14,
      "y": 0,
      "z": -4,
      "name": "Rock_Volcanic_Cracked_Lava"
    },
    {
      "x": -14,
      "y": 1,
      "z": -4,
      "name": "Rock_Volcanic_Cobble"
    },
    {
      "x": -14,
      "y": 2,
      "z": -4,
      "name": "Rock_Volcanic_Cobble"
    },
    {
      "x": -14,
      "y": 3,
      "z": -4,
      "name": "Rock_Volcanic_Brick_Smooth",
      "rotation": 1
    },
    {
      "x": -14,
      "y": 4,
      "z": -4,
      "name": "Rock_Volcanic_Brick_Ornate",
      "rotation": 1
    },
    {
      "x": -14,
      "y": 5,
      "z": -4,
      "name": "Rock_Volcanic_Brick_Decorative",
      "rotation": 1
    },
    {
      "x": -14,
      "y": 6,
      "z": -4,
      "name": "Rock_Volcanic_Brick_Decorative",
      "rotation": 1
    },
    {
      "x": -14,
      "y": 7,
      "z": -4,
      "name": "Rock_Volcanic_Brick_Decorative",
      "rotation": 1
    },
    {
      "x": -14,
      "y": 8,
      "z": -4,
      "name": "Rock_Volcanic_Brick_Ornate",
      "rotation": 1
    },
    {
      "x": -14,
      "y": 9,
      "z": -4,
      "name": "Rock_Volcanic_Brick",
      "rotation": 1
    },
    {
      "x": -14,
      "y": 10,
      "z": -4,
      "name": "Rock_Volcanic_Brick",
      "rotation": 1
    },
    {
      "x": -14,
      "y": 11,
      "z": -4,
      "name": "Rock_Volcanic_Brick",
      "rotation": 1
    },
    {
      "x": -14,
      "y": 12,
      "z": -4,
      "name": "Rock_Volcanic_Brick_Smooth"
    },
    {
      "x": -14,
      "y": 13,
      "z": -4,
      "name": "Rock_Volcanic_Brick",
      "rotation": 1
    },
    {
      "x": -14,
      "y": 14,
      "z": -4,
      "name": "Rock_Volcanic_Brick",
      "rotation": 1
    },
    {
      "x": -14,
      "y": 15,
      "z": -4,
      "name": "Rock_Volcanic_Brick_Ornate",
      "rotation": 1
    },
    {
      "x": -14,
      "y": 16,
      "z": -4,
      "name": "Rock_Volcanic_Brick_Decorative",
      "rotation": 1
    },
    {
      "x": -14,
      "y": 17,
      "z": -4,
      "name": "Rock_Volcanic_Brick_Decorative",
      "rotation": 1
    },
    {
      "x": -14,
      "y": 18,
      "z": -4,
      "name": "Rock_Volcanic_Brick_Decorative",
      "rotation": 1
    },
    {
      "x": -14,
      "y": 19,
      "z": -4,
      "name": "Rock_Volcanic_Brick_Ornate",
      "rotation": 1
    },
    {
      "x": -14,
      "y": 20,
      "z": -4,
      "name": "Rock_Volcanic_Brick",
      "rotation": 1
    },
    {
      "x": -14,
      "y": 21,
      "z": -4,
      "name": "Rock_Volcanic_Brick_Smooth",
      "rotation": 1
    },
    {
      "x": -14,
      "y": 22,
      "z": -4,
      "name": "Survival_Trap_Spike_Iron"
    },
    {
      "x": -14,
      "y": 111,
      "z": -4,
      "name": "Rock_Sandstone_Brick_Ornate",
      "rotation": 2
    },
    {
      "x": -14,
      "y": 112,
      "z": -4,
      "name": "Rock_Sandstone_Brick",
      "rotation": 2
    },
    {
      "x": -14,
      "y": 113,
      "z": -4,
      "name": "Rock_Sandstone_Brick_Smooth"
    },
    {
      "x": -14,
      "y": 114,
      "z": -4,
      "name": "Rock_Sandstone_Brick",
      "rotation": 2
    },
    {
      "x": -14,
      "y": 115,
      "z": -4,
      "name": "Rock_Sandstone_Brick_Ornate",
      "rotation": 2
    },
    {
      "x": -14,
      "y": 116,
      "z": -4,
      "name": "Rock_Sandstone_Brick_Decorative",
      "rotation": 2
    },
    {
      "x": -14,
      "y": 117,
      "z": -4,
      "name": "Rock_Sandstone_Brick_Decorative",
      "rotation": 2
    },
    {
      "x": -14,
      "y": 118,
      "z": -4,
      "name": "Rock_Sandstone_Brick_Decorative",
      "rotation": 2
    },
    {
      "x": -14,
      "y": 119,
      "z": -4,
      "name": "Rock_Sandstone_Brick_Ornate",
      "rotation": 2
    },
    {
      "x": -14,
      "y": 120,
      "z": -4,
      "name": "Rock_Sandstone_Brick",
      "rotation": 2
    },
    {
      "x": -14,
      "y": 121,
      "z": -4,
      "name": "Rock_Sandstone_Brick_Smooth"
    },
    {
      "x": -14,
      "y": 122,
      "z": -4,
      "name": "Rock_Sandstone_Brick",
      "rotation": 2
    },
    {
      "x": -14,
      "y": 123,
      "z": -4,
      "name": "Rock_Sandstone_Brick_Ornate",
      "rotation": 2
    },
    {
      "x": -14,
      "y": 124,
      "z": -4,
      "name": "Rock_Sandstone_Brick_Decorative",
      "rotation": 2
    },
    {
      "x": -14,
      "y": 125,
      "z": -4,
      "name": "Rock_Sandstone_Brick_Decorative",
      "rotation": 2
    },
    {
      "x": -14,
      "y": 126,
      "z": -4,
      "name": "Rock_Sandstone_Brick_Decorative",
      "rotation": 2
    },
    {
      "x": -14,
      "y": 127,
      "z": -4,
      "name": "Rock_Sandstone_Brick_Ornate",
      "rotation": 2
    },
    {
      "x": -14,
      "y": 128,
      "z": -4,
      "name": "Rock_Sandstone_Brick",
      "rotation": 2
    },
    {
      "x": -14,
      "y": 129,
      "z": -4,
      "name": "Rock_Sandstone_Brick_Smooth",
      "rotation": 1
    },
    {
      "x": -14,
      "y": 130,
      "z": -4,
      "name": "Rock_Sandstone",
      "rotation": 1
    },
    {
      "x": -14,
      "y": 0,
      "z": -3,
      "name": "Rock_Volcanic"
    },
    {
      "x": -14,
      "y": 1,
      "z": -3,
      "name": "Rock_Volcanic_Cobble"
    },
    {
      "x": -14,
      "y": 2,
      "z": -3,
      "name": "Rock_Volcanic_Cobble"
    },
    {
      "x": -14,
      "y": 3,
      "z": -3,
      "name": "Rock_Volcanic_Brick_Smooth",
      "rotation": 1
    },
    {
      "x": -14,
      "y": 4,
      "z": -3,
      "name": "Rock_Volcanic_Brick_Ornate",
      "rotation": 1
    },
    {
      "x": -14,
      "y": 5,
      "z": -3,
      "name": "Rock_Volcanic_Brick_Decorative",
      "rotation": 1
    },
    {
      "x": -14,
      "y": 6,
      "z": -3,
      "name": "Rock_Volcanic_Brick_Decorative",
      "rotation": 1
    },
    {
      "x": -14,
      "y": 7,
      "z": -3,
      "name": "Rock_Volcanic_Brick_Decorative",
      "rotation": 1
    },
    {
      "x": -14,
      "y": 8,
      "z": -3,
      "name": "Rock_Volcanic_Brick_Ornate",
      "rotation": 1
    },
    {
      "x": -14,
      "y": 9,
      "z": -3,
      "name": "Rock_Volcanic_Brick",
      "rotation": 1
    },
    {
      "x": -14,
      "y": 10,
      "z": -3,
      "name": "Rock_Volcanic_Brick",
      "rotation": 1
    },
    {
      "x": -14,
      "y": 11,
      "z": -3,
      "name": "Rock_Volcanic_Brick",
      "rotation": 1
    },
    {
      "x": -14,
      "y": 12,
      "z": -3,
      "name": "Rock_Volcanic_Brick_Smooth"
    },
    {
      "x": -14,
      "y": 13,
      "z": -3,
      "name": "Rock_Volcanic_Brick",
      "rotation": 1
    },
    {
      "x": -14,
      "y": 14,
      "z": -3,
      "name": "Rock_Volcanic_Brick",
      "rotation": 1
    },
    {
      "x": -14,
      "y": 15,
      "z": -3,
      "name": "Rock_Volcanic_Brick_Ornate",
      "rotation": 1
    },
    {
      "x": -14,
      "y": 16,
      "z": -3,
      "name": "Rock_Volcanic_Brick_Decorative",
      "rotation": 1
    },
    {
      "x": -14,
      "y": 17,
      "z": -3,
      "name": "Rock_Volcanic_Brick_Decorative",
      "rotation": 1
    },
    {
      "x": -14,
      "y": 18,
      "z": -3,
      "name": "Rock_Volcanic_Brick_Decorative",
      "rotation": 1
    },
    {
      "x": -14,
      "y": 19,
      "z": -3,
      "name": "Rock_Volcanic_Brick_Ornate",
      "rotation": 1
    },
    {
      "x": -14,
      "y": 20,
      "z": -3,
      "name": "Rock_Volcanic_Brick",
      "rotation": 1
    },
    {
      "x": -14,
      "y": 21,
      "z": -3,
      "name": "Rock_Volcanic_Brick_Smooth",
      "rotation": 1
    },
    {
      "x": -14,
      "y": 22,
      "z": -3,
      "name": "Survival_Trap_Spike_Iron"
    },
    {
      "x": -14,
      "y": 111,
      "z": -3,
      "name": "Rock_Sandstone_Brick_Ornate",
      "rotation": 2
    },
    {
      "x": -14,
      "y": 112,
      "z": -3,
      "name": "Rock_Sandstone_Brick",
      "rotation": 2
    },
    {
      "x": -14,
      "y": 113,
      "z": -3,
      "name": "Rock_Sandstone_Brick_Smooth"
    },
    {
      "x": -14,
      "y": 114,
      "z": -3,
      "name": "Rock_Sandstone_Brick",
      "rotation": 2
    },
    {
      "x": -14,
      "y": 115,
      "z": -3,
      "name": "Rock_Sandstone_Brick_Ornate",
      "rotation": 2
    },
    {
      "x": -14,
      "y": 116,
      "z": -3,
      "name": "Rock_Sandstone_Brick_Decorative",
      "rotation": 2
    },
    {
      "x": -14,
      "y": 117,
      "z": -3,
      "name": "Rock_Sandstone_Brick_Decorative",
      "rotation": 2
    },
    {
      "x": -14,
      "y": 118,
      "z": -3,
      "name": "Rock_Sandstone_Brick_Decorative",
      "rotation": 2
    },
    {
      "x": -14,
      "y": 119,
      "z": -3,
      "name": "Rock_Sandstone_Brick_Ornate",
      "rotation": 2
    },
    {
      "x": -14,
      "y": 120,
      "z": -3,
      "name": "Rock_Sandstone_Brick",
      "rotation": 2
    },
    {
      "x": -14,
      "y": 121,
      "z": -3,
      "name": "Rock_Sandstone_Brick_Smooth"
    },
    {
      "x": -14,
      "y": 122,
      "z": -3,
      "name": "Rock_Sandstone_Brick",
      "rotation": 2
    },
    {
      "x": -14,
      "y": 123,
      "z": -3,
      "name": "Rock_Sandstone_Brick_Ornate",
      "rotation": 2
    },
    {
      "x": -14,
      "y": 124,
      "z": -3,
      "name": "Rock_Sandstone_Brick_Decorative",
      "rotation": 2
    },
    {
      "x": -14,
      "y": 125,
      "z": -3,
      "name": "Rock_Sandstone_Brick_Decorative",
      "rotation": 2
    },
    {
      "x": -14,
      "y": 126,
      "z": -3,
      "name": "Rock_Sandstone_Brick_Decorative",
      "rotation": 2
    },
    {
      "x": -14,
      "y": 127,
      "z": -3,
      "name": "Rock_Sandstone_Brick_Ornate",
      "rotation": 2
    },
    {
      "x": -14,
      "y": 128,
      "z": -3,
      "name": "Rock_Sandstone_Brick",
      "rotation": 2
    },
    {
      "x": -14,
      "y": 129,
      "z": -3,
      "name": "Rock_Sandstone_Brick_Smooth",
      "rotation": 1
    },
    {
      "x": -14,
      "y": 130,
      "z": -3,
      "name": "Rock_Sandstone",
      "rotation": 1
    },
    {
      "x": -14,
      "y": 0,
      "z": -2,
      "name": "Rock_Volcanic"
    },
    {
      "x": -14,
      "y": 1,
      "z": -2,
      "name": "Rock_Volcanic_Cobble"
    },
    {
      "x": -14,
      "y": 2,
      "z": -2,
      "name": "Rock_Volcanic_Cobble"
    },
    {
      "x": -14,
      "y": 3,
      "z": -2,
      "name": "Rock_Volcanic_Brick_Smooth",
      "rotation": 1
    },
    {
      "x": -14,
      "y": 4,
      "z": -2,
      "name": "Rock_Volcanic_Brick_Ornate",
      "rotation": 1
    },
    {
      "x": -14,
      "y": 5,
      "z": -2,
      "name": "Rock_Volcanic_Brick_Decorative",
      "rotation": 1
    },
    {
      "x": -14,
      "y": 6,
      "z": -2,
      "name": "Rock_Volcanic_Brick_Decorative",
      "rotation": 1
    },
    {
      "x": -14,
      "y": 7,
      "z": -2,
      "name": "Rock_Volcanic_Brick_Decorative",
      "rotation": 1
    },
    {
      "x": -14,
      "y": 8,
      "z": -2,
      "name": "Rock_Volcanic_Brick_Ornate",
      "rotation": 1
    },
    {
      "x": -14,
      "y": 9,
      "z": -2,
      "name": "Rock_Volcanic_Brick",
      "rotation": 1
    },
    {
      "x": -14,
      "y": 10,
      "z": -2,
      "name": "Rock_Volcanic_Brick",
      "rotation": 1
    },
    {
      "x": -14,
      "y": 11,
      "z": -2,
      "name": "Rock_Volcanic_Brick",
      "rotation": 1
    },
    {
      "x": -14,
      "y": 12,
      "z": -2,
      "name": "Rock_Volcanic_Brick_Smooth"
    },
    {
      "x": -14,
      "y": 13,
      "z": -2,
      "name": "Rock_Volcanic_Brick",
      "rotation": 1
    },
    {
      "x": -14,
      "y": 14,
      "z": -2,
      "name": "Rock_Volcanic_Brick",
      "rotation": 1
    },
    {
      "x": -14,
      "y": 15,
      "z": -2,
      "name": "Rock_Volcanic_Brick_Ornate",
      "rotation": 1
    },
    {
      "x": -14,
      "y": 16,
      "z": -2,
      "name": "Rock_Volcanic_Brick_Decorative",
      "rotation": 1
    },
    {
      "x": -14,
      "y": 17,
      "z": -2,
      "name": "Rock_Volcanic_Brick_Decorative",
      "rotation": 1
    },
    {
      "x": -14,
      "y": 18,
      "z": -2,
      "name": "Rock_Volcanic_Brick_Decorative",
      "rotation": 1
    },
    {
      "x": -14,
      "y": 19,
      "z": -2,
      "name": "Rock_Volcanic_Brick_Ornate",
      "rotation": 1
    },
    {
      "x": -14,
      "y": 20,
      "z": -2,
      "name": "Rock_Volcanic_Brick",
      "rotation": 1
    },
    {
      "x": -14,
      "y": 21,
      "z": -2,
      "name": "Rock_Volcanic_Brick_Smooth",
      "rotation": 1
    },
    {
      "x": -14,
      "y": 22,
      "z": -2,
      "name": "Survival_Trap_Spike_Iron"
    },
    {
      "x": -14,
      "y": 111,
      "z": -2,
      "name": "Rock_Sandstone_Brick_Ornate",
      "rotation": 2
    },
    {
      "x": -14,
      "y": 112,
      "z": -2,
      "name": "Rock_Sandstone_Brick",
      "rotation": 2
    },
    {
      "x": -14,
      "y": 113,
      "z": -2,
      "name": "Rock_Sandstone_Brick_Smooth"
    },
    {
      "x": -14,
      "y": 114,
      "z": -2,
      "name": "Rock_Sandstone_Brick",
      "rotation": 2
    },
    {
      "x": -14,
      "y": 115,
      "z": -2,
      "name": "Rock_Sandstone_Brick_Ornate",
      "rotation": 2
    },
    {
      "x": -14,
      "y": 116,
      "z": -2,
      "name": "Rock_Sandstone_Brick_Decorative",
      "rotation": 2
    },
    {
      "x": -14,
      "y": 117,
      "z": -2,
      "name": "Rock_Sandstone_Brick_Decorative",
      "rotation": 2
    },
    {
      "x": -14,
      "y": 118,
      "z": -2,
      "name": "Rock_Sandstone_Brick_Decorative",
      "rotation": 2
    },
    {
      "x": -14,
      "y": 119,
      "z": -2,
      "name": "Rock_Sandstone_Brick_Ornate",
      "rotation": 2
    },
    {
      "x": -14,
      "y": 120,
      "z": -2,
      "name": "Rock_Sandstone_Brick",
      "rotation": 2
    },
    {
      "x": -14,
      "y": 121,
      "z": -2,
      "name": "Rock_Sandstone_Brick_Smooth"
    },
    {
      "x": -14,
      "y": 122,
      "z": -2,
      "name": "Rock_Sandstone_Brick",
      "rotation": 2
    },
    {
      "x": -14,
      "y": 123,
      "z": -2,
      "name": "Rock_Sandstone_Brick_Ornate",
      "rotation": 2
    },
    {
      "x": -14,
      "y": 124,
      "z": -2,
      "name": "Rock_Sandstone_Brick_Decorative",
      "rotation": 2
    },
    {
      "x": -14,
      "y": 125,
      "z": -2,
      "name": "Rock_Sandstone_Brick_Decorative",
      "rotation": 2
    },
    {
      "x": -14,
      "y": 126,
      "z": -2,
      "name": "Rock_Sandstone_Brick_Decorative",
      "rotation": 2
    },
    {
      "x": -14,
      "y": 127,
      "z": -2,
      "name": "Rock_Sandstone_Brick_Ornate",
      "rotation": 2
    },
    {
      "x": -14,
      "y": 128,
      "z": -2,
      "name": "Rock_Sandstone_Brick",
      "rotation": 2
    },
    {
      "x": -14,
      "y": 129,
      "z": -2,
      "name": "Rock_Sandstone_Brick_Smooth",
      "rotation": 1
    },
    {
      "x": -14,
      "y": 130,
      "z": -2,
      "name": "Rock_Sandstone",
      "rotation": 1
    },
    {
      "x": -14,
      "y": 0,
      "z": -1,
      "name": "Rock_Volcanic"
    },
    {
      "x": -14,
      "y": 1,
      "z": -1,
      "name": "Rock_Volcanic_Cobble"
    },
    {
      "x": -14,
      "y": 2,
      "z": -1,
      "name": "Rock_Volcanic_Cobble"
    },
    {
      "x": -14,
      "y": 3,
      "z": -1,
      "name": "Rock_Volcanic_Brick_Smooth",
      "rotation": 1
    },
    {
      "x": -14,
      "y": 4,
      "z": -1,
      "name": "Rock_Volcanic_Brick_Ornate",
      "rotation": 1
    },
    {
      "x": -14,
      "y": 5,
      "z": -1,
      "name": "Rock_Volcanic_Brick_Decorative",
      "rotation": 1
    },
    {
      "x": -14,
      "y": 6,
      "z": -1,
      "name": "Rock_Volcanic_Brick_Decorative",
      "rotation": 1
    },
    {
      "x": -14,
      "y": 7,
      "z": -1,
      "name": "Rock_Volcanic_Brick_Decorative",
      "rotation": 1
    },
    {
      "x": -14,
      "y": 8,
      "z": -1,
      "name": "Rock_Volcanic_Brick_Ornate",
      "rotation": 1
    },
    {
      "x": -14,
      "y": 9,
      "z": -1,
      "name": "Rock_Volcanic_Brick",
      "rotation": 1
    },
    {
      "x": -14,
      "y": 10,
      "z": -1,
      "name": "Rock_Volcanic_Brick",
      "rotation": 1
    },
    {
      "x": -14,
      "y": 11,
      "z": -1,
      "name": "Rock_Volcanic_Brick",
      "rotation": 1
    },
    {
      "x": -14,
      "y": 12,
      "z": -1,
      "name": "Rock_Volcanic_Brick_Smooth"
    },
    {
      "x": -14,
      "y": 13,
      "z": -1,
      "name": "Rock_Volcanic_Brick",
      "rotation": 1
    },
    {
      "x": -14,
      "y": 14,
      "z": -1,
      "name": "Rock_Volcanic_Brick",
      "rotation": 1
    },
    {
      "x": -14,
      "y": 15,
      "z": -1,
      "name": "Rock_Volcanic_Brick_Ornate",
      "rotation": 1
    },
    {
      "x": -14,
      "y": 16,
      "z": -1,
      "name": "Rock_Volcanic_Brick_Decorative",
      "rotation": 1
    },
    {
      "x": -14,
      "y": 17,
      "z": -1,
      "name": "Rock_Volcanic_Brick_Decorative",
      "rotation": 1
    },
    {
      "x": -14,
      "y": 18,
      "z": -1,
      "name": "Rock_Volcanic_Brick_Decorative",
      "rotation": 1
    },
    {
      "x": -14,
      "y": 19,
      "z": -1,
      "name": "Rock_Volcanic_Brick_Ornate",
      "rotation": 1
    },
    {
      "x": -14,
      "y": 20,
      "z": -1,
      "name": "Rock_Volcanic_Brick",
      "rotation": 1
    },
    {
      "x": -14,
      "y": 21,
      "z": -1,
      "name": "Rock_Volcanic_Brick_Smooth",
      "rotation": 1
    },
    {
      "x": -14,
      "y": 22,
      "z": -1,
      "name": "Survival_Trap_Spike_Iron"
    },
    {
      "x": -14,
      "y": 111,
      "z": -1,
      "name": "Rock_Sandstone_Brick_Ornate",
      "rotation": 2
    },
    {
      "x": -14,
      "y": 112,
      "z": -1,
      "name": "Rock_Sandstone_Brick",
      "rotation": 2
    },
    {
      "x": -14,
      "y": 113,
      "z": -1,
      "name": "Rock_Sandstone_Brick_Smooth"
    },
    {
      "x": -14,
      "y": 114,
      "z": -1,
      "name": "Rock_Sandstone_Brick",
      "rotation": 2
    },
    {
      "x": -14,
      "y": 115,
      "z": -1,
      "name": "Rock_Sandstone_Brick_Ornate",
      "rotation": 2
    },
    {
      "x": -14,
      "y": 116,
      "z": -1,
      "name": "Rock_Sandstone_Brick_Decorative",
      "rotation": 2
    },
    {
      "x": -14,
      "y": 117,
      "z": -1,
      "name": "Rock_Sandstone_Brick_Decorative",
      "rotation": 2
    },
    {
      "x": -14,
      "y": 118,
      "z": -1,
      "name": "Rock_Sandstone_Brick_Decorative",
      "rotation": 2
    },
    {
      "x": -14,
      "y": 119,
      "z": -1,
      "name": "Rock_Sandstone_Brick_Ornate",
      "rotation": 2
    },
    {
      "x": -14,
      "y": 120,
      "z": -1,
      "name": "Rock_Sandstone_Brick",
      "rotation": 2
    },
    {
      "x": -14,
      "y": 121,
      "z": -1,
      "name": "Rock_Sandstone_Brick_Smooth"
    },
    {
      "x": -14,
      "y": 122,
      "z": -1,
      "name": "Rock_Sandstone_Brick",
      "rotation": 2
    },
    {
      "x": -14,
      "y": 123,
      "z": -1,
      "name": "Rock_Sandstone_Brick_Ornate",
      "rotation": 2
    },
    {
      "x": -14,
      "y": 124,
      "z": -1,
      "name": "Rock_Sandstone_Brick_Decorative",
      "rotation": 2
    },
    {
      "x": -14,
      "y": 125,
      "z": -1,
      "name": "Rock_Sandstone_Brick_Decorative",
      "rotation": 2
    },
    {
      "x": -14,
      "y": 126,
      "z": -1,
      "name": "Rock_Sandstone_Brick_Decorative",
      "rotation": 2
    },
    {
      "x": -14,
      "y": 127,
      "z": -1,
      "name": "Rock_Sandstone_Brick_Ornate",
      "rotation": 2
    },
    {
      "x": -14,
      "y": 128,
      "z": -1,
      "name": "Rock_Sandstone_Brick",
      "rotation": 2
    },
    {
      "x": -14,
      "y": 129,
      "z": -1,
      "name": "Rock_Sandstone_Brick_Smooth",
      "rotation": 1
    },
    {
      "x": -14,
      "y": 130,
      "z": -1,
      "name": "Rock_Sandstone",
      "rotation": 1
    },
    {
      "x": -14,
      "y": 0,
      "z": 0,
      "name": "Rock_Volcanic"
    },
    {
      "x": -14,
      "y": 1,
      "z": 0,
      "name": "Rock_Volcanic_Cobble"
    },
    {
      "x": -14,
      "y": 2,
      "z": 0,
      "name": "Rock_Volcanic_Cobble"
    },
    {
      "x": -14,
      "y": 12,
      "z": 0,
      "name": "Rock_Volcanic_Brick_Smooth"
    },
    {
      "x": -14,
      "y": 21,
      "z": 0,
      "name": "Survival_Trap_Spike_Iron",
      "rotation": 4
    },
    {
      "x": -14,
      "y": 54,
      "z": 0,
      "name": "Plant_Crop_Mushroom_Shelve_Yellow"
    },
    {
      "x": -14,
      "y": 113,
      "z": 0,
      "name": "Rock_Sandstone_Brick_Smooth"
    },
    {
      "x": -14,
      "y": 121,
      "z": 0,
      "name": "Rock_Sandstone_Brick_Smooth"
    },
    {
      "x": -14,
      "y": 129,
      "z": 0,
      "name": "Rock_Sandstone_Brick_Smooth"
    },
    {
      "x": -14,
      "y": 130,
      "z": 0,
      "name": "Rock_Sandstone"
    },
    {
      "x": -14,
      "y": 0,
      "z": 1,
      "name": "Rock_Volcanic_Cracked_Lava"
    },
    {
      "x": -14,
      "y": 1,
      "z": 1,
      "name": "Rock_Volcanic_Cobble"
    },
    {
      "x": -14,
      "y": 2,
      "z": 1,
      "name": "Rock_Volcanic_Cobble"
    },
    {
      "x": -14,
      "y": 12,
      "z": 1,
      "name": "Rock_Volcanic_Brick_Smooth"
    },
    {
      "x": -14,
      "y": 113,
      "z": 1,
      "name": "Rock_Sandstone_Brick_Smooth"
    },
    {
      "x": -14,
      "y": 121,
      "z": 1,
      "name": "Rock_Sandstone_Brick_Smooth"
    },
    {
      "x": -14,
      "y": 129,
      "z": 1,
      "name": "Rock_Sandstone_Brick_Smooth"
    },
    {
      "x": -14,
      "y": 130,
      "z": 1,
      "name": "Rock_Sandstone"
    },
    {
      "x": -14,
      "y": 0,
      "z": 2,
      "name": "Rock_Volcanic"
    },
    {
      "x": -14,
      "y": 1,
      "z": 2,
      "name": "Rock_Volcanic_Cobble"
    },
    {
      "x": -14,
      "y": 2,
      "z": 2,
      "name": "Rock_Volcanic_Cobble"
    },
    {
      "x": -14,
      "y": 12,
      "z": 2,
      "name": "Rock_Volcanic_Brick_Smooth"
    },
    {
      "x": -14,
      "y": 113,
      "z": 2,
      "name": "Rock_Sandstone_Brick_Smooth"
    },
    {
      "x": -14,
      "y": 121,
      "z": 2,
      "name": "Rock_Sandstone_Brick_Smooth"
    },
    {
      "x": -14,
      "y": 129,
      "z": 2,
      "name": "Rock_Sandstone_Brick_Smooth"
    },
    {
      "x": -14,
      "y": 130,
      "z": 2,
      "name": "Rock_Sandstone"
    },
    {
      "x": -14,
      "y": 0,
      "z": 3,
      "name": "Rock_Volcanic"
    },
    {
      "x": -14,
      "y": 1,
      "z": 3,
      "name": "Rock_Volcanic_Cobble"
    },
    {
      "x": -14,
      "y": 2,
      "z": 3,
      "name": "Rock_Volcanic_Cobble"
    },
    {
      "x": -14,
      "y": 12,
      "z": 3,
      "name": "Rock_Volcanic_Brick_Smooth"
    },
    {
      "x": -14,
      "y": 113,
      "z": 3,
      "name": "Rock_Sandstone_Brick_Smooth"
    },
    {
      "x": -14,
      "y": 121,
      "z": 3,
      "name": "Rock_Sandstone_Brick_Smooth"
    },
    {
      "x": -14,
      "y": 129,
      "z": 3,
      "name": "Rock_Sandstone_Brick_Smooth"
    },
    {
      "x": -14,
      "y": 130,
      "z": 3,
      "name": "Rock_Sandstone"
    },
    {
      "x": -14,
      "y": 0,
      "z": 4,
      "name": "Rock_Volcanic"
    },
    {
      "x": -14,
      "y": 1,
      "z": 4,
      "name": "Rock_Volcanic_Cobble"
    },
    {
      "x": -14,
      "y": 2,
      "z": 4,
      "name": "Rock_Volcanic_Cobble"
    },
    {
      "x": -14,
      "y": 3,
      "z": 4,
      "name": "Furniture_Ancient_Crate",
      "rotation": 3
    },
    {
      "x": -14,
      "y": 12,
      "z": 4,
      "name": "Rock_Volcanic_Brick_Smooth"
    },
    {
      "x": -14,
      "y": 54,
      "z": 4,
      "name": "Soil_Gravel_Sand_Red"
    },
    {
      "x": -14,
      "y": 55,
      "z": 4,
      "name": "Soil_Gravel_Sand_Red"
    },
    {
      "x": -14,
      "y": 56,
      "z": 4,
      "name": "Soil_Gravel_Sand_Red"
    },
    {
      "x": -14,
      "y": 57,
      "z": 4,
      "name": "Soil_Sand_Red"
    },
    {
      "x": -14,
      "y": 113,
      "z": 4,
      "name": "Rock_Sandstone_Brick_Smooth"
    },
    {
      "x": -14,
      "y": 121,
      "z": 4,
      "name": "Rock_Sandstone_Brick_Smooth"
    },
    {
      "x": -14,
      "y": 129,
      "z": 4,
      "name": "Rock_Sandstone_Brick_Smooth"
    },
    {
      "x": -14,
      "y": 130,
      "z": 4,
      "name": "Rock_Sandstone"
    },
    {
      "x": -14,
      "y": 0,
      "z": 5,
      "name": "Rock_Volcanic"
    },
    {
      "x": -14,
      "y": 1,
      "z": 5,
      "name": "Rock_Volcanic_Cobble"
    },
    {
      "x": -14,
      "y": 2,
      "z": 5,
      "name": "Rock_Volcanic_Cobble"
    },
    {
      "x": -14,
      "y": 12,
      "z": 5,
      "name": "Rock_Volcanic_Brick_Smooth"
    },
    {
      "x": -14,
      "y": 53,
      "z": 5,
      "name": "Rock_Sandstone_Red"
    },
    {
      "x": -14,
      "y": 54,
      "z": 5,
      "name": "Soil_Gravel_Sand_Red"
    },
    {
      "x": -14,
      "y": 55,
      "z": 5,
      "name": "Soil_Gravel_Sand_Red"
    },
    {
      "x": -14,
      "y": 56,
      "z": 5,
      "name": "Soil_Gravel_Sand_Red"
    },
    {
      "x": -14,
      "y": 57,
      "z": 5,
      "name": "Soil_Sand_Red"
    },
    {
      "x": -14,
      "y": 113,
      "z": 5,
      "name": "Rock_Sandstone_Brick_Smooth"
    },
    {
      "x": -14,
      "y": 121,
      "z": 5,
      "name": "Rock_Sandstone_Brick_Smooth"
    },
    {
      "x": -14,
      "y": 129,
      "z": 5,
      "name": "Rock_Sandstone_Brick_Smooth"
    },
    {
      "x": -14,
      "y": 130,
      "z": 5,
      "name": "Rock_Sandstone"
    },
    {
      "x": -14,
      "y": 0,
      "z": 6,
      "name": "Rock_Volcanic_Cracked_Lava"
    },
    {
      "x": -14,
      "y": 1,
      "z": 6,
      "name": "Rock_Volcanic_Cobble"
    },
    {
      "x": -14,
      "y": 2,
      "z": 6,
      "name": "Rock_Volcanic_Cobble"
    },
    {
      "x": -14,
      "y": 12,
      "z": 6,
      "name": "Rock_Volcanic_Brick_Smooth"
    },
    {
      "x": -14,
      "y": 54,
      "z": 6,
      "name": "Soil_Gravel_Sand_Red"
    },
    {
      "x": -14,
      "y": 55,
      "z": 6,
      "name": "Soil_Gravel_Sand_Red"
    },
    {
      "x": -14,
      "y": 56,
      "z": 6,
      "name": "Soil_Gravel_Sand_Red"
    },
    {
      "x": -14,
      "y": 57,
      "z": 6,
      "name": "Soil_Sand_Red"
    },
    {
      "x": -14,
      "y": 113,
      "z": 6,
      "name": "Rock_Sandstone_Brick_Smooth"
    },
    {
      "x": -14,
      "y": 121,
      "z": 6,
      "name": "Rock_Sandstone_Brick_Smooth"
    },
    {
      "x": -14,
      "y": 129,
      "z": 6,
      "name": "Rock_Sandstone_Brick_Smooth"
    },
    {
      "x": -14,
      "y": 130,
      "z": 6,
      "name": "Rock_Sandstone"
    },
    {
      "x": -14,
      "y": 0,
      "z": 7,
      "name": "Rock_Volcanic"
    },
    {
      "x": -14,
      "y": 1,
      "z": 7,
      "name": "Rock_Volcanic_Cobble"
    },
    {
      "x": -14,
      "y": 2,
      "z": 7,
      "name": "Rock_Volcanic_Cobble"
    },
    {
      "x": -14,
      "y": 12,
      "z": 7,
      "name": "Rock_Volcanic_Brick_Smooth"
    },
    {
      "x": -14,
      "y": 113,
      "z": 7,
      "name": "Rock_Sandstone_Brick_Smooth"
    },
    {
      "x": -14,
      "y": 121,
      "z": 7,
      "name": "Rock_Sandstone_Brick_Smooth"
    },
    {
      "x": -14,
      "y": 129,
      "z": 7,
      "name": "Rock_Sandstone_Brick_Smooth"
    },
    {
      "x": -14,
      "y": 130,
      "z": 7,
      "name": "Rock_Sandstone"
    },
    {
      "x": -14,
      "y": 0,
      "z": 8,
      "name": "Rock_Volcanic_Cracked_Lava"
    },
    {
      "x": -14,
      "y": 1,
      "z": 8,
      "name": "Rock_Volcanic_Cobble"
    },
    {
      "x": -14,
      "y": 2,
      "z": 8,
      "name": "Rock_Volcanic_Cobble"
    },
    {
      "x": -14,
      "y": 12,
      "z": 8,
      "name": "Rock_Volcanic_Brick_Smooth"
    },
    {
      "x": -14,
      "y": 113,
      "z": 8,
      "name": "Rock_Sandstone_Brick_Smooth"
    },
    {
      "x": -14,
      "y": 121,
      "z": 8,
      "name": "Rock_Sandstone_Brick_Smooth"
    },
    {
      "x": -14,
      "y": 129,
      "z": 8,
      "name": "Rock_Sandstone_Brick_Smooth"
    },
    {
      "x": -14,
      "y": 130,
      "z": 8,
      "name": "Rock_Sandstone"
    },
    {
      "x": -14,
      "y": 0,
      "z": 9,
      "name": "Rock_Volcanic_Cracked_Lava"
    },
    {
      "x": -14,
      "y": 1,
      "z": 9,
      "name": "Rock_Volcanic_Cobble"
    },
    {
      "x": -14,
      "y": 2,
      "z": 9,
      "name": "Rock_Volcanic_Cobble"
    },
    {
      "x": -14,
      "y": 12,
      "z": 9,
      "name": "Rock_Volcanic_Brick_Smooth"
    },
    {
      "x": -14,
      "y": 113,
      "z": 9,
      "name": "Rock_Sandstone_Brick_Smooth"
    },
    {
      "x": -14,
      "y": 121,
      "z": 9,
      "name": "Rock_Sandstone_Brick_Smooth"
    },
    {
      "x": -14,
      "y": 129,
      "z": 9,
      "name": "Rock_Sandstone_Brick_Smooth"
    },
    {
      "x": -14,
      "y": 130,
      "z": 9,
      "name": "Rock_Sandstone"
    },
    {
      "x": -14,
      "y": 0,
      "z": 10,
      "name": "Rock_Volcanic_Cracked_Lava"
    },
    {
      "x": -14,
      "y": 1,
      "z": 10,
      "name": "Rock_Volcanic_Cobble"
    },
    {
      "x": -14,
      "y": 2,
      "z": 10,
      "name": "Rock_Volcanic_Cobble"
    },
    {
      "x": -14,
      "y": 12,
      "z": 10,
      "name": "Rock_Volcanic_Brick_Smooth"
    },
    {
      "x": -14,
      "y": 113,
      "z": 10,
      "name": "Rock_Sandstone_Brick_Smooth"
    },
    {
      "x": -14,
      "y": 121,
      "z": 10,
      "name": "Rock_Sandstone_Brick_Smooth"
    },
    {
      "x": -14,
      "y": 129,
      "z": 10,
      "name": "Rock_Sandstone_Brick_Smooth"
    },
    {
      "x": -14,
      "y": 130,
      "z": 10,
      "name": "Rock_Sandstone"
    },
    {
      "x": -14,
      "y": 0,
      "z": 11,
      "name": "Rock_Volcanic"
    },
    {
      "x": -14,
      "y": 1,
      "z": 11,
      "name": "Rock_Volcanic_Cobble"
    },
    {
      "x": -14,
      "y": 2,
      "z": 11,
      "name": "Rock_Volcanic_Cobble"
    },
    {
      "x": -14,
      "y": 3,
      "z": 11,
      "name": "Furniture_Temple_Dark_Candle"
    },
    {
      "x": -14,
      "y": 4,
      "z": 11,
      "name": "Furniture_Temple_Dark_Candle",
      "filler": 1024
    },
    {
      "x": -14,
      "y": 12,
      "z": 11,
      "name": "Rock_Volcanic_Brick_Smooth"
    },
    {
      "x": -14,
      "y": 21,
      "z": 11,
      "name": "Survival_Trap_Spike_Iron",
      "rotation": 7
    },
    {
      "x": -14,
      "y": 113,
      "z": 11,
      "name": "Rock_Sandstone_Brick_Smooth"
    },
    {
      "x": -14,
      "y": 121,
      "z": 11,
      "name": "Rock_Sandstone_Brick_Smooth"
    },
    {
      "x": -14,
      "y": 129,
      "z": 11,
      "name": "Rock_Sandstone_Brick_Smooth"
    },
    {
      "x": -14,
      "y": 130,
      "z": 11,
      "name": "Rock_Sandstone"
    },
    {
      "x": -14,
      "y": 0,
      "z": 12,
      "name": "Rock_Volcanic"
    },
    {
      "x": -14,
      "y": 1,
      "z": 12,
      "name": "Rock_Volcanic_Cobble"
    },
    {
      "x": -14,
      "y": 2,
      "z": 12,
      "name": "Rock_Volcanic_Cobble"
    },
    {
      "x": -14,
      "y": 12,
      "z": 12,
      "name": "Rock_Volcanic_Brick_Smooth"
    },
    {
      "x": -14,
      "y": 113,
      "z": 12,
      "name": "Rock_Sandstone_Brick_Smooth"
    },
    {
      "x": -14,
      "y": 121,
      "z": 12,
      "name": "Rock_Sandstone_Brick_Smooth"
    },
    {
      "x": -14,
      "y": 129,
      "z": 12,
      "name": "Rock_Sandstone_Brick_Smooth"
    },
    {
      "x": -14,
      "y": 130,
      "z": 12,
      "name": "Rock_Sandstone"
    },
    {
      "x": -14,
      "y": 0,
      "z": 13,
      "name": "Rock_Volcanic"
    },
    {
      "x": -14,
      "y": 1,
      "z": 13,
      "name": "Rock_Volcanic_Cobble"
    },
    {
      "x": -14,
      "y": 2,
      "z": 13,
      "name": "Rock_Volcanic_Cobble"
    },
    {
      "x": -14,
      "y": 12,
      "z": 13,
      "name": "Rock_Volcanic_Brick_Smooth"
    },
    {
      "x": -14,
      "y": 113,
      "z": 13,
      "name": "Rock_Sandstone_Brick_Smooth"
    },
    {
      "x": -14,
      "y": 121,
      "z": 13,
      "name": "Rock_Sandstone_Brick_Smooth"
    },
    {
      "x": -14,
      "y": 129,
      "z": 13,
      "name": "Rock_Sandstone_Brick_Smooth"
    },
    {
      "x": -14,
      "y": 130,
      "z": 13,
      "name": "Rock_Sandstone"
    },
    {
      "x": -14,
      "y": 0,
      "z": 14,
      "name": "Rock_Volcanic_Cracked_Lava"
    },
    {
      "x": -14,
      "y": 1,
      "z": 14,
      "name": "Rock_Volcanic_Cobble"
    },
    {
      "x": -14,
      "y": 2,
      "z": 14,
      "name": "Rock_Volcanic_Cobble"
    },
    {
      "x": -14,
      "y": 12,
      "z": 14,
      "name": "Rock_Volcanic_Brick_Smooth"
    },
    {
      "x": -14,
      "y": 113,
      "z": 14,
      "name": "Rock_Sandstone_Brick_Smooth"
    },
    {
      "x": -14,
      "y": 121,
      "z": 14,
      "name": "Rock_Sandstone_Brick_Smooth"
    },
    {
      "x": -14,
      "y": 129,
      "z": 14,
      "name": "Rock_Sandstone_Brick_Smooth"
    },
    {
      "x": -14,
      "y": 130,
      "z": 14,
      "name": "Rock_Sandstone"
    },
    {
      "x": -14,
      "y": 0,
      "z": 15,
      "name": "Rock_Volcanic"
    },
    {
      "x": -14,
      "y": 1,
      "z": 15,
      "name": "Rock_Volcanic_Cobble"
    },
    {
      "x": -14,
      "y": 2,
      "z": 15,
      "name": "Rock_Volcanic_Cobble"
    },
    {
      "x": -14,
      "y": 12,
      "z": 15,
      "name": "Rock_Volcanic_Brick_Smooth"
    },
    {
      "x": -14,
      "y": 113,
      "z": 15,
      "name": "Rock_Sandstone_Brick_Smooth"
    },
    {
      "x": -14,
      "y": 121,
      "z": 15,
      "name": "Rock_Sandstone_Brick_Smooth"
    },
    {
      "x": -14,
      "y": 129,
      "z": 15,
      "name": "Rock_Sandstone_Brick_Smooth"
    },
    {
      "x": -14,
      "y": 130,
      "z": 15,
      "name": "Rock_Sandstone"
    },
    {
      "x": -13,
      "y": 0,
      "z": -15,
      "name": "Rock_Volcanic"
    },
    {
      "x": -13,
      "y": 1,
      "z": -15,
      "name": "Rock_Volcanic_Cobble"
    },
    {
      "x": -13,
      "y": 2,
      "z": -15,
      "name": "Rock_Volcanic_Cobble"
    },
    {
      "x": -13,
      "y": 12,
      "z": -15,
      "name": "Rock_Volcanic_Brick_Smooth"
    },
    {
      "x": -13,
      "y": 113,
      "z": -15,
      "name": "Rock_Sandstone_Brick_Smooth"
    },
    {
      "x": -13,
      "y": 121,
      "z": -15,
      "name": "Rock_Sandstone_Brick_Smooth"
    },
    {
      "x": -13,
      "y": 129,
      "z": -15,
      "name": "Rock_Sandstone_Brick_Smooth"
    },
    {
      "x": -13,
      "y": 130,
      "z": -15,
      "name": "Rock_Sandstone"
    },
    {
      "x": -13,
      "y": 0,
      "z": -14,
      "name": "Rock_Volcanic"
    },
    {
      "x": -13,
      "y": 1,
      "z": -14,
      "name": "Rock_Volcanic_Cobble"
    },
    {
      "x": -13,
      "y": 2,
      "z": -14,
      "name": "Rock_Volcanic_Cobble"
    },
    {
      "x": -13,
      "y": 12,
      "z": -14,
      "name": "Rock_Volcanic_Brick_Smooth"
    },
    {
      "x": -13,
      "y": 113,
      "z": -14,
      "name": "Rock_Sandstone_Brick_Smooth"
    },
    {
      "x": -13,
      "y": 121,
      "z": -14,
      "name": "Rock_Sandstone_Brick_Smooth"
    },
    {
      "x": -13,
      "y": 129,
      "z": -14,
      "name": "Rock_Sandstone_Brick_Smooth"
    },
    {
      "x": -13,
      "y": 130,
      "z": -14,
      "name": "Rock_Sandstone"
    },
    {
      "x": -13,
      "y": 0,
      "z": -13,
      "name": "Rock_Volcanic"
    },
    {
      "x": -13,
      "y": 1,
      "z": -13,
      "name": "Rock_Volcanic_Cobble"
    },
    {
      "x": -13,
      "y": 2,
      "z": -13,
      "name": "Rock_Volcanic_Cobble"
    },
    {
      "x": -13,
      "y": 12,
      "z": -13,
      "name": "Rock_Volcanic_Brick_Smooth"
    },
    {
      "x": -13,
      "y": 13,
      "z": -13,
      "name": "Furniture_Ancient_Barrel"
    },
    {
      "x": -13,
      "y": 113,
      "z": -13,
      "name": "Rock_Sandstone_Brick_Smooth"
    },
    {
      "x": -13,
      "y": 121,
      "z": -13,
      "name": "Rock_Sandstone_Brick_Smooth"
    },
    {
      "x": -13,
      "y": 129,
      "z": -13,
      "name": "Rock_Sandstone_Brick_Smooth"
    },
    {
      "x": -13,
      "y": 130,
      "z": -13,
      "name": "Rock_Sandstone"
    },
    {
      "x": -13,
      "y": 0,
      "z": -12,
      "name": "Rock_Volcanic"
    },
    {
      "x": -13,
      "y": 1,
      "z": -12,
      "name": "Rock_Volcanic_Cobble"
    },
    {
      "x": -13,
      "y": 2,
      "z": -12,
      "name": "Rock_Volcanic_Cobble"
    },
    {
      "x": -13,
      "y": 3,
      "z": -12,
      "name": "Furniture_Ancient_Crate",
      "rotation": 2
    },
    {
      "x": -13,
      "y": 12,
      "z": -12,
      "name": "Rock_Volcanic_Brick_Smooth"
    },
    {
      "x": -13,
      "y": 13,
      "z": -12,
      "name": "Furniture_Ancient_Crate",
      "rotation": 2
    },
    {
      "x": -13,
      "y": 113,
      "z": -12,
      "name": "Rock_Sandstone_Brick_Smooth"
    },
    {
      "x": -13,
      "y": 121,
      "z": -12,
      "name": "Rock_Sandstone_Brick_Smooth"
    },
    {
      "x": -13,
      "y": 122,
      "z": -12,
      "name": "Deco_Bone_Skulls_Feran"
    },
    {
      "x": -13,
      "y": 129,
      "z": -12,
      "name": "Rock_Sandstone_Brick_Smooth"
    },
    {
      "x": -13,
      "y": 130,
      "z": -12,
      "name": "Rock_Sandstone"
    },
    {
      "x": -13,
      "y": 0,
      "z": -11,
      "name": "Rock_Volcanic"
    },
    {
      "x": -13,
      "y": 1,
      "z": -11,
      "name": "Rock_Volcanic_Cobble"
    },
    {
      "x": -13,
      "y": 2,
      "z": -11,
      "name": "Rock_Volcanic_Cobble"
    },
    {
      "x": -13,
      "y": 3,
      "z": -11,
      "name": "Rock_Volcanic_Brick_Smooth",
      "rotation": 3
    },
    {
      "x": -13,
      "y": 4,
      "z": -11,
      "name": "Rock_Volcanic_Brick_Ornate",
      "rotation": 3
    },
    {
      "x": -13,
      "y": 5,
      "z": -11,
      "name": "Rock_Volcanic_Brick_Decorative",
      "rotation": 3
    },
    {
      "x": -13,
      "y": 6,
      "z": -11,
      "name": "Rock_Volcanic_Brick_Decorative",
      "rotation": 3
    },
    {
      "x": -13,
      "y": 7,
      "z": -11,
      "name": "Rock_Volcanic_Brick_Decorative",
      "rotation": 3
    },
    {
      "x": -13,
      "y": 8,
      "z": -11,
      "name": "Rock_Volcanic_Brick_Ornate",
      "rotation": 3
    },
    {
      "x": -13,
      "y": 9,
      "z": -11,
      "name": "Rock_Volcanic_Brick",
      "rotation": 3
    },
    {
      "x": -13,
      "y": 10,
      "z": -11,
      "name": "Rock_Volcanic_Brick",
      "rotation": 3
    },
    {
      "x": -13,
      "y": 11,
      "z": -11,
      "name": "Rock_Volcanic_Brick",
      "rotation": 3
    },
    {
      "x": -13,
      "y": 12,
      "z": -11,
      "name": "Rock_Volcanic_Brick_Smooth"
    },
    {
      "x": -13,
      "y": 13,
      "z": -11,
      "name": "Rock_Volcanic_Brick",
      "rotation": 3
    },
    {
      "x": -13,
      "y": 14,
      "z": -11,
      "name": "Rock_Volcanic_Brick",
      "rotation": 3
    },
    {
      "x": -13,
      "y": 15,
      "z": -11,
      "name": "Rock_Volcanic_Brick_Ornate",
      "rotation": 3
    },
    {
      "x": -13,
      "y": 16,
      "z": -11,
      "name": "Rock_Volcanic_Brick_Decorative",
      "rotation": 3
    },
    {
      "x": -13,
      "y": 17,
      "z": -11,
      "name": "Rock_Volcanic_Brick_Decorative",
      "rotation": 3
    },
    {
      "x": -13,
      "y": 18,
      "z": -11,
      "name": "Rock_Volcanic_Brick_Decorative",
      "rotation": 3
    },
    {
      "x": -13,
      "y": 19,
      "z": -11,
      "name": "Rock_Volcanic_Brick_Ornate",
      "rotation": 3
    },
    {
      "x": -13,
      "y": 20,
      "z": -11,
      "name": "Rock_Volcanic_Brick",
      "rotation": 3
    },
    {
      "x": -13,
      "y": 21,
      "z": -11,
      "name": "Rock_Volcanic_Brick_Smooth",
      "rotation": 3
    },
    {
      "x": -13,
      "y": 111,
      "z": -11,
      "name": "Rock_Sandstone_Brick_Ornate"
    },
    {
      "x": -13,
      "y": 112,
      "z": -11,
      "name": "Rock_Sandstone_Brick"
    },
    {
      "x": -13,
      "y": 113,
      "z": -11,
      "name": "Rock_Sandstone_Brick_Smooth"
    },
    {
      "x": -13,
      "y": 114,
      "z": -11,
      "name": "Rock_Sandstone_Brick"
    },
    {
      "x": -13,
      "y": 115,
      "z": -11,
      "name": "Rock_Sandstone_Brick_Ornate"
    },
    {
      "x": -13,
      "y": 116,
      "z": -11,
      "name": "Rock_Sandstone_Brick_Decorative"
    },
    {
      "x": -13,
      "y": 117,
      "z": -11,
      "name": "Rock_Sandstone_Brick_Decorative"
    },
    {
      "x": -13,
      "y": 118,
      "z": -11,
      "name": "Rock_Sandstone_Brick_Decorative"
    },
    {
      "x": -13,
      "y": 119,
      "z": -11,
      "name": "Rock_Sandstone_Brick_Ornate"
    },
    {
      "x": -13,
      "y": 120,
      "z": -11,
      "name": "Rock_Sandstone_Brick"
    },
    {
      "x": -13,
      "y": 121,
      "z": -11,
      "name": "Rock_Sandstone_Brick_Smooth"
    },
    {
      "x": -13,
      "y": 122,
      "z": -11,
      "name": "Rock_Sandstone_Brick"
    },
    {
      "x": -13,
      "y": 123,
      "z": -11,
      "name": "Rock_Sandstone_Brick_Ornate"
    },
    {
      "x": -13,
      "y": 124,
      "z": -11,
      "name": "Rock_Sandstone_Brick_Decorative"
    },
    {
      "x": -13,
      "y": 125,
      "z": -11,
      "name": "Rock_Sandstone_Brick_Decorative"
    },
    {
      "x": -13,
      "y": 126,
      "z": -11,
      "name": "Rock_Sandstone_Brick_Decorative"
    },
    {
      "x": -13,
      "y": 127,
      "z": -11,
      "name": "Rock_Sandstone_Brick_Ornate"
    },
    {
      "x": -13,
      "y": 128,
      "z": -11,
      "name": "Rock_Sandstone_Brick"
    },
    {
      "x": -13,
      "y": 129,
      "z": -11,
      "name": "Rock_Sandstone_Brick_Smooth",
      "rotation": 3
    },
    {
      "x": -13,
      "y": 130,
      "z": -11,
      "name": "Rock_Sandstone",
      "rotation": 3
    },
    {
      "x": -13,
      "y": 0,
      "z": -10,
      "name": "Rock_Volcanic"
    },
    {
      "x": -13,
      "y": 1,
      "z": -10,
      "name": "Rock_Volcanic_Cobble"
    },
    {
      "x": -13,
      "y": 2,
      "z": -10,
      "name": "Rock_Volcanic_Cobble"
    },
    {
      "x": -13,
      "y": 12,
      "z": -10,
      "name": "Rock_Volcanic_Brick_Smooth"
    },
    {
      "x": -13,
      "y": 113,
      "z": -10,
      "name": "Rock_Sandstone_Brick_Smooth"
    },
    {
      "x": -13,
      "y": 121,
      "z": -10,
      "name": "Rock_Sandstone_Brick_Smooth"
    },
    {
      "x": -13,
      "y": 122,
      "z": -10,
      "name": "Furniture_Village_Pot"
    },
    {
      "x": -13,
      "y": 128,
      "z": -10,
      "name": "Deco_SpiderWeb_Full"
    },
    {
      "x": -13,
      "y": 129,
      "z": -10,
      "name": "Rock_Sandstone_Brick_Smooth"
    },
    {
      "x": -13,
      "y": 130,
      "z": -10,
      "name": "Rock_Sandstone"
    },
    {
      "x": -13,
      "y": 0,
      "z": -9,
      "name": "Rock_Volcanic"
    },
    {
      "x": -13,
      "y": 1,
      "z": -9,
      "name": "Rock_Volcanic_Cobble"
    },
    {
      "x": -13,
      "y": 2,
      "z": -9,
      "name": "Rock_Volcanic_Cobble"
    },
    {
      "x": -13,
      "y": 12,
      "z": -9,
      "name": "Rock_Volcanic_Brick_Smooth"
    },
    {
      "x": -13,
      "y": 113,
      "z": -9,
      "name": "Rock_Sandstone_Brick_Smooth"
    },
    {
      "x": -13,
      "y": 121,
      "z": -9,
      "name": "Rock_Sandstone_Brick_Smooth"
    },
    {
      "x": -13,
      "y": 129,
      "z": -9,
      "name": "Rock_Sandstone_Brick_Smooth"
    },
    {
      "x": -13,
      "y": 130,
      "z": -9,
      "name": "Rock_Sandstone"
    },
    {
      "x": -13,
      "y": 0,
      "z": -8,
      "name": "Rock_Volcanic"
    },
    {
      "x": -13,
      "y": 1,
      "z": -8,
      "name": "Rock_Volcanic_Cobble"
    },
    {
      "x": -13,
      "y": 2,
      "z": -8,
      "name": "Rock_Volcanic_Cobble"
    },
    {
      "x": -13,
      "y": 3,
      "z": -8,
      "name": "Rock_Volcanic_Brick_Smooth",
      "rotation": 3
    },
    {
      "x": -13,
      "y": 4,
      "z": -8,
      "name": "Rock_Volcanic_Brick_Ornate",
      "rotation": 3
    },
    {
      "x": -13,
      "y": 5,
      "z": -8,
      "name": "Rock_Volcanic_Brick_Decorative",
      "rotation": 3
    },
    {
      "x": -13,
      "y": 6,
      "z": -8,
      "name": "Rock_Volcanic_Brick_Decorative",
      "rotation": 3
    },
    {
      "x": -13,
      "y": 7,
      "z": -8,
      "name": "Rock_Volcanic_Brick_Decorative",
      "rotation": 3
    },
    {
      "x": -13,
      "y": 8,
      "z": -8,
      "name": "Rock_Volcanic_Brick_Ornate",
      "rotation": 3
    },
    {
      "x": -13,
      "y": 9,
      "z": -8,
      "name": "Rock_Volcanic_Brick",
      "rotation": 3
    },
    {
      "x": -13,
      "y": 10,
      "z": -8,
      "name": "Rock_Volcanic_Brick",
      "rotation": 3
    },
    {
      "x": -13,
      "y": 11,
      "z": -8,
      "name": "Rock_Volcanic_Brick",
      "rotation": 3
    },
    {
      "x": -13,
      "y": 12,
      "z": -8,
      "name": "Rock_Volcanic_Brick_Smooth"
    },
    {
      "x": -13,
      "y": 13,
      "z": -8,
      "name": "Rock_Volcanic_Brick",
      "rotation": 3
    },
    {
      "x": -13,
      "y": 14,
      "z": -8,
      "name": "Rock_Volcanic_Brick",
      "rotation": 3
    },
    {
      "x": -13,
      "y": 15,
      "z": -8,
      "name": "Rock_Volcanic_Brick_Ornate",
      "rotation": 3
    },
    {
      "x": -13,
      "y": 16,
      "z": -8,
      "name": "Rock_Volcanic_Brick_Decorative",
      "rotation": 3
    },
    {
      "x": -13,
      "y": 17,
      "z": -8,
      "name": "Rock_Volcanic_Brick_Decorative",
      "rotation": 3
    },
    {
      "x": -13,
      "y": 18,
      "z": -8,
      "name": "Rock_Volcanic_Brick_Decorative",
      "rotation": 3
    },
    {
      "x": -13,
      "y": 19,
      "z": -8,
      "name": "Rock_Volcanic_Brick_Ornate",
      "rotation": 3
    },
    {
      "x": -13,
      "y": 20,
      "z": -8,
      "name": "Rock_Volcanic_Brick",
      "rotation": 3
    },
    {
      "x": -13,
      "y": 21,
      "z": -8,
      "name": "Rock_Volcanic_Brick_Smooth",
      "rotation": 3
    },
    {
      "x": -13,
      "y": 111,
      "z": -8,
      "name": "Rock_Sandstone_Brick_Ornate"
    },
    {
      "x": -13,
      "y": 112,
      "z": -8,
      "name": "Rock_Sandstone_Brick"
    },
    {
      "x": -13,
      "y": 113,
      "z": -8,
      "name": "Rock_Sandstone_Brick_Smooth"
    },
    {
      "x": -13,
      "y": 114,
      "z": -8,
      "name": "Rock_Sandstone_Brick"
    },
    {
      "x": -13,
      "y": 115,
      "z": -8,
      "name": "Rock_Sandstone_Brick_Ornate"
    },
    {
      "x": -13,
      "y": 116,
      "z": -8,
      "name": "Rock_Sandstone_Brick_Decorative"
    },
    {
      "x": -13,
      "y": 117,
      "z": -8,
      "name": "Rock_Sandstone_Brick_Decorative"
    },
    {
      "x": -13,
      "y": 118,
      "z": -8,
      "name": "Rock_Sandstone_Brick_Decorative"
    },
    {
      "x": -13,
      "y": 119,
      "z": -8,
      "name": "Rock_Sandstone_Brick_Ornate"
    },
    {
      "x": -13,
      "y": 120,
      "z": -8,
      "name": "Rock_Sandstone_Brick"
    },
    {
      "x": -13,
      "y": 121,
      "z": -8,
      "name": "Rock_Sandstone_Brick_Smooth"
    },
    {
      "x": -13,
      "y": 122,
      "z": -8,
      "name": "Rock_Sandstone_Brick"
    },
    {
      "x": -13,
      "y": 123,
      "z": -8,
      "name": "Rock_Sandstone_Brick_Ornate"
    },
    {
      "x": -13,
      "y": 124,
      "z": -8,
      "name": "Rock_Sandstone_Brick_Decorative"
    },
    {
      "x": -13,
      "y": 125,
      "z": -8,
      "name": "Rock_Sandstone_Brick_Decorative"
    },
    {
      "x": -13,
      "y": 126,
      "z": -8,
      "name": "Rock_Sandstone_Brick_Decorative"
    },
    {
      "x": -13,
      "y": 127,
      "z": -8,
      "name": "Rock_Sandstone_Brick_Ornate"
    },
    {
      "x": -13,
      "y": 128,
      "z": -8,
      "name": "Rock_Sandstone_Brick"
    },
    {
      "x": -13,
      "y": 129,
      "z": -8,
      "name": "Rock_Sandstone_Brick_Smooth",
      "rotation": 3
    },
    {
      "x": -13,
      "y": 130,
      "z": -8,
      "name": "Rock_Sandstone",
      "rotation": 3
    },
    {
      "x": -13,
      "y": 0,
      "z": -7,
      "name": "Rock_Volcanic"
    },
    {
      "x": -13,
      "y": 1,
      "z": -7,
      "name": "Rock_Volcanic_Cobble"
    },
    {
      "x": -13,
      "y": 2,
      "z": -7,
      "name": "Rock_Volcanic_Cobble"
    },
    {
      "x": -13,
      "y": 12,
      "z": -7,
      "name": "Rock_Volcanic_Brick_Smooth"
    },
    {
      "x": -13,
      "y": 113,
      "z": -7,
      "name": "Rock_Sandstone_Brick_Smooth"
    },
    {
      "x": -13,
      "y": 121,
      "z": -7,
      "name": "Rock_Sandstone_Brick_Smooth"
    },
    {
      "x": -13,
      "y": 129,
      "z": -7,
      "name": "Rock_Sandstone_Brick_Smooth"
    },
    {
      "x": -13,
      "y": 130,
      "z": -7,
      "name": "Rock_Sandstone"
    },
    {
      "x": -13,
      "y": 0,
      "z": -6,
      "name": "Rock_Volcanic"
    },
    {
      "x": -13,
      "y": 1,
      "z": -6,
      "name": "Rock_Volcanic_Cobble"
    },
    {
      "x": -13,
      "y": 2,
      "z": -6,
      "name": "Rock_Volcanic_Cobble"
    },
    {
      "x": -13,
      "y": 12,
      "z": -6,
      "name": "Rock_Volcanic_Brick_Smooth"
    },
    {
      "x": -13,
      "y": 21,
      "z": -6,
      "name": "Survival_Trap_Spike_Iron",
      "rotation": 5
    },
    {
      "x": -13,
      "y": 113,
      "z": -6,
      "name": "Rock_Sandstone_Brick_Smooth"
    },
    {
      "x": -13,
      "y": 121,
      "z": -6,
      "name": "Rock_Sandstone_Brick_Smooth"
    },
    {
      "x": -13,
      "y": 129,
      "z": -6,
      "name": "Rock_Sandstone_Brick_Smooth"
    },
    {
      "x": -13,
      "y": 130,
      "z": -6,
      "name": "Rock_Sandstone"
    },
    {
      "x": -13,
      "y": 0,
      "z": -5,
      "name": "Rock_Volcanic"
    },
    {
      "x": -13,
      "y": 1,
      "z": -5,
      "name": "Rock_Volcanic_Cobble"
    },
    {
      "x": -13,
      "y": 2,
      "z": -5,
      "name": "Rock_Volcanic_Cobble"
    },
    {
      "x": -13,
      "y": 12,
      "z": -5,
      "name": "Rock_Volcanic_Brick_Smooth"
    },
    {
      "x": -13,
      "y": 21,
      "z": -5,
      "name": "Survival_Trap_Spike_Iron",
      "rotation": 5
    },
    {
      "x": -13,
      "y": 113,
      "z": -5,
      "name": "Rock_Sandstone_Brick_Smooth"
    },
    {
      "x": -13,
      "y": 121,
      "z": -5,
      "name": "Rock_Sandstone_Brick_Smooth"
    },
    {
      "x": -13,
      "y": 129,
      "z": -5,
      "name": "Rock_Sandstone_Brick_Smooth",
      "rotation": 2
    },
    {
      "x": -13,
      "y": 130,
      "z": -5,
      "name": "Rock_Sandstone",
      "rotation": 2
    },
    {
      "x": -13,
      "y": 0,
      "z": -4,
      "name": "Rock_Volcanic"
    },
    {
      "x": -13,
      "y": 1,
      "z": -4,
      "name": "Rock_Volcanic_Cobble"
    },
    {
      "x": -13,
      "y": 2,
      "z": -4,
      "name": "Rock_Volcanic_Cobble"
    },
    {
      "x": -13,
      "y": 3,
      "z": -4,
      "name": "Rock_Volcanic_Brick_Smooth",
      "rotation": 1
    },
    {
      "x": -13,
      "y": 4,
      "z": -4,
      "name": "Rock_Volcanic_Brick_Ornate",
      "rotation": 1
    },
    {
      "x": -13,
      "y": 5,
      "z": -4,
      "name": "Rock_Volcanic_Brick_Decorative",
