{
  "version": 8,
  "blockIdVersion": 11,
  "anchorX": 0,
  "anchorY": 0,
  "anchorZ": 0,
  "blocks": [
    {
      "x": -14,
      "y": 0,
      "z": -7,
      "name": "Rock_Volcanic"
    },
    {
      "x": -14,
      "y": 0,
      "z": -6,
      "name": "Rock_Volcanic"
    },
    {
      "x": -14,
      "y": 1,
      "z": -6,
      "name": "Rock_Volcanic"
    },
    {
      "x": -14,
      "y": 2,
      "z": -6,
      "name": "Rock_Volcanic"
    },
    {
      "x": -14,
      "y": 3,
      "z": -6,
      "name": "Rock_Volcanic_Cracked_Lava"
    },
    {
      "x": -14,
      "y": 0,
      "z": -5,
      "name": "Rock_Volcanic"
    },
    {
      "x": -14,
      "y": 1,
      "z": -5,
      "name": "Rock_Volcanic"
    },
    {
      "x": -14,
      "y": 3,
      "z": -5,
      "name": "Rock_Volcanic"
    },
    {
      "x": -14,
      "y": 0,
      "z": -4,
      "name": "Rock_Volcanic"
    },
    {
      "x": -14,
      "y": 1,
      "z": -4,
      "name": "Rock_Volcanic"
    },
    {
      "x": -14,
      "y": 2,
      "z": -4,
      "name": "Rock_Volcanic"
    },
    {
      "x": -14,
      "y": 3,
      "z": -4,
      "name": "Rock_Volcanic"
    },
    {
      "x": -14,
      "y": 4,
      "z": -4,
      "name": "Rock_Volcanic"
    },
    {
      "x": -14,
      "y": 0,
      "z": -3,
      "name": "Rock_Volcanic"
    },
    {
      "x": -14,
      "y": 1,
      "z": -3,
      "name": "Rock_Volcanic"
    },
    {
      "x": -14,
      "y": 2,
      "z": -3,
      "name": "Rock_Volcanic"
    },
    {
      "x": -14,
      "y": 3,
      "z": -3,
      "name": "Rock_Volcanic"
    },
    {
      "x": -14,
      "y": 4,
      "z": -3,
      "name": "Rock_Volcanic"
    },
    {
      "x": -14,
      "y": 0,
      "z": -2,
      "name": "Rock_Volcanic"
    },
    {
      "x": -14,
      "y": 1,
      "z": -2,
      "name": "Rock_Volcanic"
    },
    {
      "x": -14,
      "y": 2,
      "z": -2,
      "name": "Rock_Volcanic"
    },
    {
      "x": -14,
      "y": 0,
      "z": -1,
      "name": "Rock_Volcanic"
    },
    {
      "x": -14,
      "y": 1,
      "z": -1,
      "name": "Rock_Volcanic"
    },
    {
      "x": -14,
      "y": 2,
      "z": -1,
      "name": "Rock_Volcanic"
    },
    {
      "x": -14,
      "y": 0,
      "z": 0,
      "name": "Rock_Volcanic"
    },
    {
      "x": -14,
      "y": 1,
      "z": 0,
      "name": "Rock_Volcanic"
    },
    {
      "x": -14,
      "y": 2,
      "z": 0,
      "name": "Rock_Volcanic"
    },
    {
      "x": -14,
      "y": 0,
      "z": 1,
      "name": "Rock_Volcanic"
    },
    {
      "x": -14,
      "y": 1,
      "z": 1,
      "name": "Rock_Volcanic"
    },
    {
      "x": -14,
      "y": 2,
      "z": 1,
      "name": "Rock_Volcanic"
    },
    {
      "x": -14,
      "y": 0,
      "z": 2,
      "name": "Rock_Volcanic"
    },
    {
      "x": -14,
      "y": 1,
      "z": 2,
      "name": "Rock_Volcanic"
    },
    {
      "x": -14,
      "y": 2,
      "z": 2,
      "name": "Rock_Volcanic"
    },
    {
      "x": -14,
      "y": 3,
      "z": 2,
      "name": "Rock_Volcanic"
    },
    {
      "x": -14,
      "y": 0,
      "z": 3,
      "name": "Rock_Volcanic"
    },
    {
      "x": -14,
      "y": 1,
      "z": 3,
      "name": "Rock_Volcanic"
    },
    {
      "x": -14,
      "y": 2,
      "z": 3,
      "name": "Rock_Volcanic"
    },
    {
      "x": -14,
      "y": 3,
      "z": 3,
      "name": "Rock_Volcanic_Cracked_Lava"
    },
    {
      "x": -14,
      "y": 0,
      "z": 4,
      "name": "Rock_Volcanic"
    },
    {
      "x": -14,
      "y": 1,
      "z": 4,
      "name": "Rock_Volcanic"
    },
    {
      "x": -14,
      "y": 2,
      "z": 4,
      "name": "Rock_Volcanic"
    },
    {
      "x": -14,
      "y": 3,
      "z": 4,
      "name": "Rock_Volcanic"
    },
    {
      "x": -14,
      "y": 0,
      "z": 5,
      "name": "Rock_Volcanic"
    },
    {
      "x": -14,
      "y": 1,
      "z": 5,
      "name": "Rock_Volcanic"
    },
    {
      "x": -14,
      "y": 0,
      "z": 6,
      "name": "Rock_Volcanic"
    },
    {
      "x": -14,
      "y": 1,
      "z": 6,
      "name": "Rock_Volcanic"
    },
    {
      "x": -14,
      "y": 0,
      "z": 7,
      "name": "Rock_Volcanic"
    },
    {
      "x": -14,
      "y": 1,
      "z": 7,
      "name": "Rock_Volcanic"
    },
    {
      "x": -14,
      "y": 0,
      "z": 8,
      "name": "Rock_Volcanic"
    },
    {
      "x": -14,
      "y": 1,
      "z": 8,
      "name": "Rock_Volcanic"
    },
    {
      "x": -14,
      "y": 0,
      "z": 9,
      "name": "Rock_Volcanic"
    },
    {
      "x": -14,
      "y": 1,
      "z": 9,
      "name": "Rock_Volcanic"
    },
    {
      "x": -14,
      "y": 0,
      "z": 10,
      "name": "Rock_Volcanic"
    },
    {
      "x": -14,
      "y": 1,
      "z": 10,
      "name": "Rock_Volcanic"
    },
    {
      "x": -14,
      "y": 0,
      "z": 11,
      "name": "Rock_Volcanic"
    },
    {
      "x": -14,
      "y": 1,
      "z": 11,
      "name": "Rock_Volcanic"
    },
    {
      "x": -14,
      "y": 0,
      "z": 12,
      "name": "Rock_Volcanic"
    },
    {
      "x": -13,
      "y": 1,
      "z": -11,
      "name": "Rock_Volcanic"
    },
    {
      "x": -13,
      "y": 0,
      "z": -10,
      "name": "Rock_Volcanic"
    },
    {
      "x": -13,
      "y": 1,
      "z": -10,
      "name": "Rock_Volcanic"
    },
    {
      "x": -13,
      "y": 2,
      "z": -10,
      "name": "Rock_Volcanic"
    },
    {
      "x": -13,
      "y": 0,
      "z": -9,
      "name": "Rock_Volcanic"
    },
    {
      "x": -13,
      "y": 1,
      "z": -9,
      "name": "Rock_Volcanic"
    },
    {
      "x": -13,
      "y": 2,
      "z": -9,
      "name": "Rock_Volcanic"
    },
    {
      "x": -13,
      "y": 0,
      "z": -8,
      "name": "Rock_Volcanic"
    },
    {
      "x": -13,
      "y": 1,
      "z": -8,
      "name": "Rock_Volcanic"
    },
    {
      "x": -13,
      "y": 2,
      "z": -8,
      "name": "Rock_Volcanic"
    },
    {
      "x": -13,
      "y": 3,
      "z": -8,
      "name": "Rock_Volcanic"
    },
    {
      "x": -13,
      "y": 0,
      "z": -7,
      "name": "Rock_Volcanic"
    },
    {
      "x": -13,
      "y": 1,
      "z": -7,
      "name": "Rock_Volcanic"
    },
    {
      "x": -13,
      "y": 2,
      "z": -7,
      "name": "Rock_Volcanic"
    },
    {
      "x": -13,
      "y": 3,
      "z": -7,
      "name": "Rock_Volcanic_Cracked_Lava"
    },
    {
      "x": -13,
      "y": 4,
      "z": -7,
      "name": "Rock_Volcanic"
    },
    {
      "x": -13,
      "y": 0,
      "z": -6,
      "name": "Rock_Volcanic"
    },
    {
      "x": -13,
      "y": 1,
      "z": -6,
      "name": "Rock_Volcanic"
    },
    {
      "x": -13,
      "y": 2,
      "z": -6,
      "name": "Rock_Volcanic"
    },
    {
      "x": -13,
      "y": 3,
      "z": -6,
      "name": "Rock_Volcanic"
    },
    {
      "x": -13,
      "y": 4,
      "z": -6,
      "name": "Rock_Volcanic"
    },
    {
      "x": -13,
      "y": 0,
      "z": -5,
      "name": "Rock_Volcanic"
    },
    {
      "x": -13,
      "y": 1,
      "z": -5,
      "name": "Rock_Volcanic"
    },
    {
      "x": -13,
      "y": 2,
      "z": -5,
      "name": "Rock_Volcanic"
    },
    {
      "x": -13,
      "y": 3,
      "z": -5,
      "name": "Rock_Volcanic_Cracked_Lava"
    },
    {
      "x": -13,
      "y": 4,
      "z": -5,
      "name": "Rock_Volcanic"
    },
    {
      "x": -13,
      "y": 0,
      "z": -4,
      "name": "Rock_Volcanic"
    },
    {
      "x": -13,
      "y": 1,
      "z": -4,
      "name": "Rock_Volcanic"
    },
    {
      "x": -13,
      "y": 2,
      "z": -4,
      "name": "Rock_Volcanic"
    },
    {
      "x": -13,
      "y": 3,
      "z": -4,
      "name": "Rock_Volcanic"
    },
    {
      "x": -13,
      "y": 4,
      "z": -4,
      "name": "Rock_Volcanic"
    },
    {
      "x": -13,
      "y": 0,
      "z": -3,
      "name": "Rock_Volcanic"
    },
    {
      "x": -13,
      "y": 1,
      "z": -3,
      "name": "Rock_Volcanic"
    },
    {
      "x": -13,
      "y": 2,
      "z": -3,
      "name": "Rock_Volcanic"
    },
    {
      "x": -13,
      "y": 3,
      "z": -3,
      "name": "Rock_Volcanic_Cracked_Lava"
    },
    {
      "x": -13,
      "y": 4,
      "z": -3,
      "name": "Rock_Volcanic"
    },
    {
      "x": -13,
      "y": 0,
      "z": -2,
      "name": "Rock_Volcanic"
    },
    {
      "x": -13,
      "y": 1,
      "z": -2,
      "name": "Rock_Volcanic"
    },
    {
      "x": -13,
      "y": 2,
      "z": -2,
      "name": "Rock_Volcanic"
    },
    {
      "x": -13,
      "y": 3,
      "z": -2,
      "name": "Rock_Volcanic_Cracked_Lava"
    },
    {
      "x": -13,
      "y": 4,
      "z": -2,
      "name": "Rock_Volcanic"
    },
    {
      "x": -13,
      "y": 0,
      "z": -1,
      "name": "Rock_Volcanic"
    },
    {
      "x": -13,
      "y": 1,
      "z": -1,
      "name": "Rock_Volcanic"
    },
    {
      "x": -13,
      "y": 2,
      "z": -1,
      "name": "Rock_Volcanic"
    },
    {
      "x": -13,
      "y": 0,
      "z": 0,
      "name": "Rock_Volcanic"
    },
    {
      "x": -13,
      "y": 1,
      "z": 0,
      "name": "Rock_Volcanic"
    },
    {
      "x": -13,
      "y": 2,
      "z": 0,
      "name": "Rock_Volcanic"
    },
    {
      "x": -13,
      "y": 0,
      "z": 1,
      "name": "Rock_Volcanic"
    },
    {
      "x": -13,
      "y": 1,
      "z": 1,
      "name": "Rock_Volcanic"
    },
    {
      "x": -13,
      "y": 2,
      "z": 1,
      "name": "Rock_Volcanic"
    },
    {
      "x": -13,
      "y": 0,
      "z": 2,
      "name": "Rock_Volcanic"
    },
    {
      "x": -13,
      "y": 1,
      "z": 2,
      "name": "Rock_Volcanic"
    },
    {
      "x": -13,
      "y": 2,
      "z": 2,
      "name": "Rock_Volcanic"
    },
    {
      "x": -13,
      "y": 0,
      "z": 3,
      "name": "Rock_Volcanic"
    },
    {
      "x": -13,
      "y": 1,
      "z": 3,
      "name": "Rock_Volcanic"
    },
    {
      "x": -13,
      "y": 2,
      "z": 3,
      "name": "Rock_Volcanic"
    },
    {
      "x": -13,
      "y": 3,
      "z": 3,
      "name": "Rock_Volcanic"
    },
    {
      "x": -13,
      "y": 4,
      "z": 3,
      "name": "Rock_Volcanic"
    },
    {
      "x": -13,
      "y": 0,
      "z": 4,
      "name": "Rock_Volcanic"
    },
    {
      "x": -13,
      "y": 1,
      "z": 4,
      "name": "Rock_Volcanic"
    },
    {
      "x": -13,
      "y": 2,
      "z": 4,
      "name": "Rock_Volcanic"
    },
    {
      "x": -13,
      "y": 3,
      "z": 4,
      "name": "Rock_Volcanic"
    },
    {
      "x": -13,
      "y": 4,
      "z": 4,
      "name": "Rock_Volcanic"
    },
    {
      "x": -13,
      "y": 0,
      "z": 5,
      "name": "Rock_Volcanic"
    },
    {
      "x": -13,
      "y": 1,
      "z": 5,
      "name": "Rock_Volcanic"
    },
    {
      "x": -13,
      "y": 2,
      "z": 5,
      "name": "Rock_Volcanic"
    },
    {
      "x": -13,
      "y": 3,
      "z": 5,
      "name": "Rock_Volcanic_Cracked_Lava"
    },
    {
      "x": -13,
      "y": 4,
      "z": 5,
      "name": "Rock_Volcanic_Cracked_Lava"
    },
    {
      "x": -13,
      "y": 5,
      "z": 5,
      "name": "Rock_Volcanic_Stalactite_Large"
    },
    {
      "x": -13,
      "y": 6,
      "z": 5,
      "name": "Rock_Volcanic_Stalactite_Large",
      "filler": 1024
    },
    {
      "x": -13,
      "y": 0,
      "z": 6,
      "name": "Rock_Volcanic"
    },
    {
      "x": -13,
      "y": 1,
      "z": 6,
      "name": "Rock_Volcanic"
    },
    {
      "x": -13,
      "y": 2,
      "z": 6,
      "name": "Rock_Volcanic"
    },
    {
      "x": -13,
      "y": 3,
      "z": 6,
      "name": "Rock_Volcanic_Cracked_Lava"
    },
    {
      "x": -13,
      "y": 0,
      "z": 7,
      "name": "Rock_Volcanic"
    },
    {
      "x": -13,
      "y": 1,
      "z": 7,
      "name": "Rock_Volcanic"
    },
    {
      "x": -13,
      "y": 3,
      "z": 7,
      "name": "Rock_Volcanic"
    },
    {
      "x": -13,
      "y": 0,
      "z": 8,
      "name": "Rock_Volcanic"
    },
    {
      "x": -13,
      "y": 1,
      "z": 8,
      "name": "Rock_Volcanic"
    },
    {
      "x": -13,
      "y": 3,
      "z": 8,
      "name": "Rock_Volcanic"
    },
    {
      "x": -13,
      "y": 0,
      "z": 9,
      "name": "Rock_Volcanic"
    },
    {
      "x": -13,
      "y": 1,
      "z": 9,
      "name": "Rock_Volcanic"
    },
    {
      "x": -13,
      "y": 0,
      "z": 10,
      "name": "Rock_Volcanic"
    },
    {
      "x": -13,
      "y": 1,
      "z": 10,
      "name": "Rock_Volcanic"
    },
    {
      "x": -13,
      "y": 0,
      "z": 11,
      "name": "Rock_Volcanic"
    },
    {
      "x": -13,
      "y": 1,
      "z": 11,
      "name": "Rock_Volcanic"
    },
    {
      "x": -13,
      "y": 0,
      "z": 12,
      "name": "Rock_Volcanic"
    },
    {
      "x": -12,
      "y": 0,
      "z": -11,
      "name": "Rock_Volcanic"
    },
    {
      "x": -12,
      "y": 1,
      "z": -11,
      "name": "Rock_Volcanic"
    },
    {
      "x": -12,
      "y": 2,
      "z": -11,
      "name": "Rock_Volcanic"
    },
    {
      "x": -12,
      "y": 3,
      "z": -11,
      "name": "Rock_Volcanic"
    },
    {
      "x": -12,
      "y": 0,
      "z": -10,
      "name": "Rock_Volcanic"
    },
    {
      "x": -12,
      "y": 1,
      "z": -10,
      "name": "Rock_Volcanic"
    },
    {
      "x": -12,
      "y": 2,
      "z": -10,
      "name": "Rock_Volcanic"
    },
    {
      "x": -12,
      "y": 0,
      "z": -9,
      "name": "Rock_Volcanic"
    },
    {
      "x": -12,
      "y": 1,
      "z": -9,
      "name": "Rock_Volcanic"
    },
    {
      "x": -12,
      "y": 2,
      "z": -9,
      "name": "Rock_Volcanic"
    },
    {
      "x": -12,
      "y": 0,
      "z": -8,
      "name": "Rock_Volcanic"
    },
    {
      "x": -12,
      "y": 1,
      "z": -8,
      "name": "Rock_Volcanic"
    },
    {
      "x": -12,
      "y": 2,
      "z": -8,
      "name": "Rock_Volcanic"
    },
    {
      "x": -12,
      "y": 3,
      "z": -8,
      "name": "Rock_Volcanic"
    },
    {
      "x": -12,
      "y": 0,
      "z": -7,
      "name": "Rock_Volcanic"
    },
    {
      "x": -12,
      "y": 1,
      "z": -7,
      "name": "Rock_Volcanic"
    },
    {
      "x": -12,
      "y": 2,
      "z": -7,
      "name": "Rock_Volcanic"
    },
    {
      "x": -12,
      "y": 3,
      "z": -7,
      "name": "Rock_Volcanic"
    },
    {
      "x": -12,
      "y": 4,
      "z": -7,
      "name": "Rock_Volcanic"
    },
    {
      "x": -12,
      "y": 0,
      "z": -6,
      "name": "Rock_Volcanic"
    },
    {
      "x": -12,
      "y": 1,
      "z": -6,
      "name": "Rock_Volcanic"
    },
    {
      "x": -12,
      "y": 2,
      "z": -6,
      "name": "Rock_Volcanic"
    },
    {
      "x": -12,
      "y": 3,
      "z": -6,
      "name": "Rock_Volcanic"
    },
    {
      "x": -12,
      "y": 4,
      "z": -6,
      "name": "Rock_Volcanic"
    },
    {
      "x": -12,
      "y": 0,
      "z": -5,
      "name": "Rock_Volcanic"
    },
    {
      "x": -12,
      "y": 1,
      "z": -5,
      "name": "Rock_Volcanic"
    },
    {
      "x": -12,
      "y": 2,
      "z": -5,
      "name": "Rock_Volcanic"
    },
    {
      "x": -12,
      "y": 3,
      "z": -5,
      "name": "Rock_Volcanic"
    },
    {
      "x": -12,
      "y": 4,
      "z": -5,
      "name": "Rock_Volcanic_Cracked_Lava"
    },
    {
      "x": -12,
      "y": 0,
      "z": -4,
      "name": "Rock_Volcanic"
    },
    {
      "x": -12,
      "y": 1,
      "z": -4,
      "name": "Rock_Volcanic"
    },
    {
      "x": -12,
      "y": 2,
      "z": -4,
      "name": "Rock_Volcanic"
    },
    {
      "x": -12,
      "y": 3,
      "z": -4,
      "name": "Rock_Volcanic"
    },
    {
      "x": -12,
      "y": 4,
      "z": -4,
      "name": "Rock_Volcanic"
    },
    {
      "x": -12,
      "y": 5,
      "z": -4,
      "name": "Rock_Volcanic_Stalactite_Small"
    },
    {
      "x": -12,
      "y": 0,
      "z": -3,
      "name": "Rock_Volcanic"
    },
    {
      "x": -12,
      "y": 1,
      "z": -3,
      "name": "Rock_Volcanic"
    },
    {
      "x": -12,
      "y": 2,
      "z": -3,
      "name": "Rock_Volcanic"
    },
    {
      "x": -12,
      "y": 3,
      "z": -3,
      "name": "Rock_Volcanic"
    },
    {
      "x": -12,
      "y": 4,
      "z": -3,
      "name": "Rock_Volcanic"
    },
    {
      "x": -12,
      "y": 0,
      "z": -2,
      "name": "Rock_Volcanic"
    },
    {
      "x": -12,
      "y": 1,
      "z": -2,
      "name": "Rock_Volcanic"
    },
    {
      "x": -12,
      "y": 2,
      "z": -2,
      "name": "Rock_Volcanic"
    },
    {
      "x": -12,
      "y": 3,
      "z": -2,
      "name": "Rock_Volcanic"
    },
    {
      "x": -12,
      "y": 4,
      "z": -2,
      "name": "Rock_Volcanic"
    },
    {
      "x": -12,
      "y": 0,
      "z": -1,
      "name": "Rock_Volcanic"
    },
    {
      "x": -12,
      "y": 1,
      "z": -1,
      "name": "Rock_Volcanic"
    },
    {
      "x": -12,
      "y": 2,
      "z": -1,
      "name": "Rock_Volcanic"
    },
    {
      "x": -12,
      "y": 3,
      "z": -1,
      "name": "Rock_Volcanic_Cracked_Lava"
    },
    {
      "x": -12,
      "y": 4,
      "z": -1,
      "name": "Rock_Volcanic"
    },
    {
      "x": -12,
      "y": 0,
      "z": 0,
      "name": "Rock_Volcanic"
    },
    {
      "x": -12,
      "y": 1,
      "z": 0,
      "name": "Rock_Volcanic"
    },
    {
      "x": -12,
      "y": 2,
      "z": 0,
      "name": "Rock_Volcanic"
    },
    {
      "x": -12,
      "y": 3,
      "z": 0,
      "name": "Rock_Volcanic"
    },
    {
      "x": -12,
      "y": 4,
      "z": 0,
      "name": "Rock_Volcanic_Cracked_Lava"
    },
    {
      "x": -12,
      "y": 0,
      "z": 1,
      "name": "Rock_Volcanic"
    },
    {
      "x": -12,
      "y": 1,
      "z": 1,
      "name": "Rock_Volcanic"
    },
    {
      "x": -12,
      "y": 2,
      "z": 1,
      "name": "Rock_Volcanic"
    },
    {
      "x": -12,
      "y": 0,
      "z": 2,
      "name": "Rock_Volcanic"
    },
    {
      "x": -12,
      "y": 1,
      "z": 2,
      "name": "Rock_Volcanic"
    },
    {
      "x": -12,
      "y": 2,
      "z": 2,
      "name": "Rock_Volcanic"
    },
    {
      "x": -12,
      "y": 0,
      "z": 3,
      "name": "Rock_Volcanic"
    },
    {
      "x": -12,
      "y": 1,
      "z": 3,
      "name": "Rock_Volcanic"
    },
    {
      "x": -12,
      "y": 2,
      "z": 3,
      "name": "Rock_Volcanic"
    },
    {
      "x": -12,
      "y": 0,
      "z": 4,
      "name": "Rock_Volcanic"
    },
    {
      "x": -12,
      "y": 1,
      "z": 4,
      "name": "Rock_Volcanic"
    },
    {
      "x": -12,
      "y": 0,
      "z": 5,
      "name": "Rock_Volcanic"
    },
    {
      "x": -12,
      "y": 1,
      "z": 5,
      "name": "Rock_Volcanic"
    },
    {
      "x": -12,
      "y": 2,
      "z": 5,
      "name": "Rock_Volcanic"
    },
    {
      "x": -12,
      "y": 3,
      "z": 5,
      "name": "Rock_Volcanic"
    },
    {
      "x": -12,
      "y": 4,
      "z": 5,
      "name": "Rock_Volcanic"
    },
    {
      "x": -12,
      "y": 0,
      "z": 6,
      "name": "Rock_Volcanic"
    },
    {
      "x": -12,
      "y": 1,
      "z": 6,
      "name": "Rock_Volcanic"
    },
    {
      "x": -12,
      "y": 2,
      "z": 6,
      "name": "Rock_Volcanic_Cracked_Lava"
    },
    {
      "x": -12,
      "y": 3,
      "z": 6,
      "name": "Rock_Volcanic"
    },
    {
      "x": -12,
      "y": 4,
      "z": 6,
      "name": "Rock_Volcanic"
    },
    {
      "x": -12,
      "y": 0,
      "z": 7,
      "name": "Rock_Volcanic"
    },
    {
      "x": -12,
      "y": 1,
      "z": 7,
      "name": "Rock_Volcanic"
    },
    {
      "x": -12,
      "y": 2,
      "z": 7,
      "name": "Rock_Volcanic"
    },
    {
      "x": -12,
      "y": 3,
      "z": 7,
      "name": "Rock_Volcanic"
    },
    {
      "x": -12,
      "y": 4,
      "z": 7,
      "name": "Rock_Volcanic"
    },
    {
      "x": -12,
      "y": 0,
      "z": 8,
      "name": "Rock_Volcanic"
    },
    {
      "x": -12,
      "y": 1,
      "z": 8,
      "name": "Rock_Volcanic"
    },
    {
      "x": -12,
      "y": 2,
      "z": 8,
      "name": "Rock_Volcanic"
    },
    {
      "x": -12,
      "y": 3,
      "z": 8,
      "name": "Rock_Volcanic"
    },
    {
      "x": -12,
      "y": 4,
      "z": 8,
      "name": "Rock_Volcanic"
    },
    {
      "x": -12,
      "y": 5,
      "z": 8,
      "name": "Rock_Volcanic_Stalactite_Small"
    },
    {
      "x": -12,
      "y": 0,
      "z": 9,
      "name": "Rock_Volcanic"
    },
    {
      "x": -12,
      "y": 1,
      "z": 9,
      "name": "Rock_Volcanic"
    },
    {
      "x": -12,
      "y": 2,
      "z": 9,
      "name": "Rock_Volcanic"
    },
    {
      "x": -12,
      "y": 3,
      "z": 9,
      "name": "Rock_Volcanic"
    },
    {
      "x": -12,
      "y": 0,
      "z": 10,
      "name": "Rock_Volcanic"
    },
    {
      "x": -12,
      "y": 1,
      "z": 10,
      "name": "Rock_Volcanic"
    },
    {
      "x": -12,
      "y": 2,
      "z": 10,
      "name": "Rock_Volcanic"
    },
    {
      "x": -12,
      "y": 3,
      "z": 10,
      "name": "Rock_Volcanic"
    },
    {
      "x": -12,
      "y": 0,
      "z": 11,
      "name": "Rock_Volcanic"
    },
    {
      "x": -12,
      "y": 1,
      "z": 11,
      "name": "Rock_Volcanic"
    },
    {
      "x": -12,
      "y": 0,
      "z": 12,
      "name": "Rock_Volcanic"
    },
    {
      "x": -11,
      "y": 3,
      "z": -13,
      "name": "Rock_Volcanic"
    },
    {
      "x": -11,
      "y": 0,
      "z": -12,
      "name": "Rock_Volcanic"
    },
    {
      "x": -11,
      "y": 2,
      "z": -12,
      "name": "Rock_Volcanic"
    },
    {
      "x": -11,
      "y": 3,
      "z": -12,
      "name": "Rock_Volcanic"
    },
    {
      "x": -11,
      "y": 0,
      "z": -11,
      "name": "Rock_Volcanic"
    },
    {
      "x": -11,
      "y": 1,
      "z": -11,
      "name": "Rock_Volcanic"
    },
    {
      "x": -11,
      "y": 2,
      "z": -11,
      "name": "Rock_Volcanic"
    },
    {
      "x": -11,
      "y": 3,
      "z": -11,
      "name": "Rock_Volcanic"
    },
    {
      "x": -11,
      "y": 4,
      "z": -11,
      "name": "Rock_Volcanic"
    },
    {
      "x": -11,
      "y": 0,
      "z": -10,
      "name": "Rock_Volcanic"
    },
    {
      "x": -11,
      "y": 1,
      "z": -10,
      "name": "Rock_Volcanic"
    },
    {
      "x": -11,
      "y": 2,
      "z": -10,
      "name": "Rock_Volcanic"
    },
    {
      "x": -11,
      "y": 0,
      "z": -9,
      "name": "Rock_Volcanic"
    },
    {
      "x": -11,
      "y": 1,
      "z": -9,
      "name": "Rock_Volcanic"
    },
    {
      "x": -11,
      "y": 2,
      "z": -9,
      "name": "Rock_Volcanic"
    },
    {
      "x": -11,
      "y": 0,
      "z": -8,
      "name": "Rock_Volcanic"
    },
    {
      "x": -11,
      "y": 1,
      "z": -8,
      "name": "Rock_Volcanic"
    },
    {
      "x": -11,
      "y": 2,
      "z": -8,
      "name": "Rock_Volcanic"
    },
    {
      "x": -11,
      "y": 0,
      "z": -7,
      "name": "Rock_Volcanic"
    },
    {
      "x": -11,
      "y": 1,
      "z": -7,
      "name": "Rock_Volcanic"
    },
    {
      "x": -11,
      "y": 2,
      "z": -7,
      "name": "Rock_Volcanic"
    },
    {
      "x": -11,
      "y": 3,
      "z": -7,
      "name": "Rock_Volcanic_Cracked_Lava"
    },
    {
      "x": -11,
      "y": 0,
      "z": -6,
      "name": "Rock_Volcanic"
    },
    {
      "x": -11,
      "y": 1,
      "z": -6,
      "name": "Rock_Volcanic"
    },
    {
      "x": -11,
      "y": 2,
      "z": -6,
      "name": "Rock_Volcanic"
    },
    {
      "x": -11,
      "y": 3,
      "z": -6,
      "name": "Rock_Volcanic_Cracked_Lava"
    },
    {
      "x": -11,
      "y": 4,
      "z": -6,
      "name": "Rock_Volcanic"
    },
    {
      "x": -11,
      "y": 0,
      "z": -5,
      "name": "Rock_Volcanic"
    },
    {
      "x": -11,
      "y": 1,
      "z": -5,
      "name": "Rock_Volcanic"
    },
    {
      "x": -11,
      "y": 2,
      "z": -5,
      "name": "Rock_Volcanic"
    },
    {
      "x": -11,
      "y": 3,
      "z": -5,
      "name": "Rock_Volcanic_Cracked_Lava"
    },
    {
      "x": -11,
      "y": 4,
      "z": -5,
      "name": "Rock_Volcanic"
    },
    {
      "x": -11,
      "y": 0,
      "z": -4,
      "name": "Rock_Volcanic"
    },
    {
      "x": -11,
      "y": 1,
      "z": -4,
      "name": "Rock_Volcanic"
    },
    {
      "x": -11,
      "y": 2,
      "z": -4,
      "name": "Rock_Volcanic"
    },
    {
      "x": -11,
      "y": 3,
      "z": -4,
      "name": "Rock_Volcanic"
    },
    {
      "x": -11,
      "y": 4,
      "z": -4,
      "name": "Rock_Volcanic"
    },
    {
      "x": -11,
      "y": 0,
      "z": -3,
      "name": "Rock_Volcanic"
    },
    {
      "x": -11,
      "y": 1,
      "z": -3,
      "name": "Rock_Volcanic"
    },
    {
      "x": -11,
      "y": 2,
      "z": -3,
      "name": "Rock_Volcanic"
    },
    {
      "x": -11,
      "y": 3,
      "z": -3,
      "name": "Rock_Volcanic"
    },
    {
      "x": -11,
      "y": 4,
      "z": -3,
      "name": "Rock_Volcanic"
    },
    {
      "x": -11,
      "y": 0,
      "z": -2,
      "name": "Rock_Volcanic"
    },
    {
      "x": -11,
      "y": 1,
      "z": -2,
      "name": "Rock_Volcanic"
    },
    {
      "x": -11,
      "y": 2,
      "z": -2,
      "name": "Rock_Volcanic"
    },
    {
      "x": -11,
      "y": 3,
      "z": -2,
      "name": "Rock_Volcanic"
    },
    {
      "x": -11,
      "y": 4,
      "z": -2,
      "name": "Rock_Volcanic"
    },
    {
      "x": -11,
      "y": 5,
      "z": -2,
      "name": "Rock_Volcanic"
    },
    {
      "x": -11,
      "y": 0,
      "z": -1,
      "name": "Rock_Volcanic"
    },
    {
      "x": -11,
      "y": 1,
      "z": -1,
      "name": "Rock_Volcanic"
    },
    {
      "x": -11,
      "y": 2,
      "z": -1,
      "name": "Rock_Volcanic"
    },
    {
      "x": -11,
      "y": 3,
      "z": -1,
      "name": "Rock_Volcanic"
    },
    {
      "x": -11,
      "y": 4,
      "z": -1,
      "name": "Rock_Volcanic"
    },
    {
      "x": -11,
      "y": 5,
      "z": -1,
      "name": "Plant_Bramble_Dead_Lavathorn"
    },
    {
      "x": -11,
      "y": 0,
      "z": 0,
      "name": "Rock_Volcanic"
    },
    {
      "x": -11,
      "y": 1,
      "z": 0,
      "name": "Rock_Volcanic"
    },
    {
      "x": -11,
      "y": 2,
      "z": 0,
      "name": "Rock_Volcanic"
    },
    {
      "x": -11,
      "y": 3,
      "z": 0,
      "name": "Rock_Volcanic_Cracked_Lava"
    },
    {
      "x": -11,
      "y": 4,
      "z": 0,
      "name": "Rock_Volcanic"
    },
    {
      "x": -11,
      "y": 0,
      "z": 1,
      "name": "Rock_Volcanic"
    },
    {
      "x": -11,
      "y": 1,
      "z": 1,
      "name": "Rock_Volcanic"
    },
    {
      "x": -11,
      "y": 2,
      "z": 1,
      "name": "Rock_Volcanic"
    },
    {
      "x": -11,
      "y": 3,
      "z": 1,
      "name": "Rock_Volcanic"
    },
    {
      "x": -11,
      "y": 4,
      "z": 1,
      "name": "Rock_Volcanic"
    },
    {
      "x": -11,
      "y": 5,
      "z": 1,
      "name": "Rock_Volcanic_Stalactite_Small"
    },
    {
      "x": -11,
      "y": 0,
      "z": 2,
      "name": "Rock_Volcanic"
    },
    {
      "x": -11,
      "y": 1,
      "z": 2,
      "name": "Rock_Volcanic"
    },
    {
      "x": -11,
      "y": 2,
      "z": 2,
      "name": "Rock_Volcanic"
    },
    {
      "x": -11,
      "y": 0,
      "z": 3,
      "name": "Rock_Volcanic"
    },
    {
      "x": -11,
      "y": 1,
      "z": 3,
      "name": "Rock_Volcanic"
    },
    {
      "x": -11,
      "y": 2,
      "z": 3,
      "name": "Rock_Volcanic"
    },
    {
      "x": -11,
      "y": 0,
      "z": 4,
      "name": "Rock_Volcanic"
    },
    {
      "x": -11,
      "y": 1,
      "z": 4,
      "name": "Rock_Volcanic"
    },
    {
      "x": -11,
      "y": 0,
      "z": 5,
      "name": "Rock_Volcanic"
    },
    {
      "x": -11,
      "y": 1,
      "z": 5,
      "name": "Rock_Volcanic"
    },
    {
      "x": -11,
      "y": 0,
      "z": 6,
      "name": "Rock_Volcanic"
    },
    {
      "x": -11,
      "y": 1,
      "z": 6,
      "name": "Rock_Volcanic"
    },
    {
      "x": -11,
      "y": 0,
      "z": 7,
      "name": "Rock_Volcanic"
    },
    {
      "x": -11,
      "y": 1,
      "z": 7,
      "name": "Rock_Volcanic"
    },
    {
      "x": -11,
      "y": 2,
      "z": 7,
      "name": "Rock_Volcanic"
    },
    {
      "x": -11,
      "y": 3,
      "z": 7,
      "name": "Rock_Volcanic"
    },
    {
      "x": -11,
      "y": 4,
      "z": 7,
      "name": "Rock_Volcanic"
    },
    {
      "x": -11,
      "y": 0,
      "z": 8,
      "name": "Rock_Volcanic"
    },
    {
      "x": -11,
      "y": 1,
      "z": 8,
      "name": "Rock_Volcanic"
    },
    {
      "x": -11,
      "y": 2,
      "z": 8,
      "name": "Rock_Volcanic_Cracked_Lava"
    },
    {
      "x": -11,
      "y": 3,
      "z": 8,
      "name": "Rock_Volcanic"
    },
    {
      "x": -11,
      "y": 4,
      "z": 8,
      "name": "Rock_Volcanic"
    },
    {
      "x": -11,
      "y": 0,
      "z": 9,
      "name": "Rock_Volcanic"
    },
    {
      "x": -11,
      "y": 1,
      "z": 9,
      "name": "Rock_Volcanic"
    },
    {
      "x": -11,
      "y": 2,
      "z": 9,
      "name": "Rock_Volcanic"
    },
    {
      "x": -11,
      "y": 3,
      "z": 9,
      "name": "Rock_Volcanic"
    },
    {
      "x": -11,
      "y": 4,
      "z": 9,
      "name": "Rock_Volcanic"
    },
    {
      "x": -11,
      "y": 0,
      "z": 10,
      "name": "Rock_Volcanic"
    },
    {
      "x": -11,
      "y": 1,
      "z": 10,
      "name": "Rock_Volcanic"
    },
    {
      "x": -11,
      "y": 2,
      "z": 10,
      "name": "Rock_Volcanic"
    },
    {
      "x": -11,
      "y": 3,
      "z": 10,
      "name": "Rock_Volcanic"
    },
    {
      "x": -11,
      "y": 4,
      "z": 10,
      "name": "Rock_Volcanic_Cracked_Lava"
    },
    {
      "x": -11,
      "y": 0,
      "z": 11,
      "name": "Rock_Volcanic"
    },
    {
      "x": -11,
      "y": 1,
      "z": 11,
      "name": "Rock_Volcanic"
    },
    {
      "x": -11,
      "y": 3,
      "z": 11,
      "name": "Rock_Volcanic"
    },
    {
      "x": -11,
      "y": 0,
      "z": 12,
      "name": "Rock_Volcanic"
    },
    {
      "x": -10,
      "y": 2,
      "z": -13,
      "name": "Rock_Volcanic"
    },
    {
      "x": -10,
      "y": 3,
      "z": -13,
      "name": "Rock_Volcanic"
    },
    {
      "x": -10,
      "y": 0,
      "z": -12,
      "name": "Rock_Volcanic"
    },
    {
      "x": -10,
      "y": 1,
      "z": -12,
      "name": "Rock_Volcanic"
    },
    {
      "x": -10,
      "y": 2,
      "z": -12,
      "name": "Rock_Volcanic"
    },
    {
      "x": -10,
      "y": 3,
      "z": -12,
      "name": "Rock_Volcanic"
    },
    {
      "x": -10,
      "y": 4,
      "z": -12,
      "name": "Rock_Volcanic"
    },
    {
      "x": -10,
      "y": 0,
      "z": -11,
      "name": "Rock_Volcanic"
    },
    {
      "x": -10,
      "y": 1,
      "z": -11,
      "name": "Rock_Volcanic"
    },
    {
      "x": -10,
      "y": 2,
      "z": -11,
      "name": "Rock_Volcanic"
    },
    {
      "x": -10,
      "y": 3,
      "z": -11,
      "name": "Rock_Volcanic"
    },
    {
      "x": -10,
      "y": 4,
      "z": -11,
      "name": "Rock_Volcanic"
    },
    {
      "x": -10,
      "y": 0,
      "z": -10,
      "name": "Rock_Volcanic"
    },
    {
      "x": -10,
      "y": 1,
      "z": -10,
      "name": "Rock_Volcanic"
    },
    {
      "x": -10,
      "y": 2,
      "z": -10,
      "name": "Rock_Volcanic"
    },
    {
      "x": -10,
      "y": 3,
      "z": -10,
      "name": "Rock_Volcanic"
    },
    {
      "x": -10,
      "y": 4,
      "z": -10,
      "name": "Rock_Volcanic_Stalactite_Small"
    },
    {
      "x": -10,
      "y": 0,
      "z": -9,
      "name": "Rock_Volcanic"
    },
    {
      "x": -10,
      "y": 1,
      "z": -9,
      "name": "Rock_Volcanic"
    },
    {
      "x": -10,
      "y": 2,
      "z": -9,
      "name": "Rock_Volcanic"
    },
    {
      "x": -10,
      "y": 0,
      "z": -8,
      "name": "Rock_Volcanic"
    },
    {
      "x": -10,
      "y": 1,
      "z": -8,
      "name": "Rock_Volcanic"
    },
    {
      "x": -10,
      "y": 2,
      "z": -8,
      "name": "Rock_Volcanic"
    },
    {
      "x": -10,
      "y": 0,
      "z": -7,
      "name": "Rock_Volcanic"
    },
    {
      "x": -10,
      "y": 1,
      "z": -7,
      "name": "Rock_Volcanic"
    },
    {
      "x": -10,
      "y": 2,
      "z": -7,
      "name": "Rock_Volcanic"
    },
    {
      "x": -10,
      "y": 3,
      "z": -7,
      "name": "Rock_Volcanic"
    },
    {
      "x": -10,
      "y": 0,
      "z": -6,
      "name": "Rock_Volcanic"
    },
    {
      "x": -10,
      "y": 1,
      "z": -6,
      "name": "Rock_Volcanic"
    },
    {
      "x": -10,
      "y": 2,
      "z": -6,
      "name": "Rock_Volcanic"
    },
    {
      "x": -10,
      "y": 3,
      "z": -6,
      "name": "Rock_Volcanic_Cracked_Lava"
    },
    {
      "x": -10,
      "y": 4,
      "z": -6,
      "name": "Rock_Volcanic"
    },
    {
      "x": -10,
      "y": 0,
      "z": -5,
      "name": "Rock_Volcanic"
    },
    {
      "x": -10,
      "y": 1,
      "z": -5,
      "name": "Rock_Volcanic"
    },
    {
      "x": -10,
      "y": 2,
      "z": -5,
      "name": "Rock_Volcanic"
    },
    {
      "x": -10,
      "y": 3,
      "z": -5,
      "name": "Rock_Volcanic"
    },
    {
      "x": -10,
      "y": 4,
      "z": -5,
      "name": "Rock_Volcanic"
    },
    {
      "x": -10,
      "y": 5,
      "z": -5,
      "name": "Rock_Volcanic"
    },
    {
      "x": -10,
      "y": 6,
      "z": -5,
      "name": "Plant_Bramble_Dead_Lavathorn"
    },
    {
      "x": -10,
      "y": 0,
      "z": -4,
      "name": "Rock_Volcanic"
    },
    {
      "x": -10,
      "y": 1,
      "z": -4,
      "name": "Rock_Volcanic"
    },
    {
      "x": -10,
      "y": 2,
      "z": -4,
      "name": "Rock_Volcanic"
    },
    {
      "x": -10,
      "y": 3,
      "z": -4,
      "name": "Rock_Volcanic"
    },
    {
      "x": -10,
      "y": 4,
      "z": -4,
      "name": "Rock_Volcanic"
    },
    {
      "x": -10,
      "y": 5,
      "z": -4,
      "name": "Rock_Volcanic"
    },
    {
      "x": -10,
      "y": 0,
      "z": -3,
      "name": "Rock_Volcanic"
    },
    {
      "x": -10,
      "y": 1,
      "z": -3,
      "name": "Rock_Volcanic"
    },
    {
      "x": -10,
      "y": 2,
      "z": -3,
      "name": "Rock_Volcanic"
    },
    {
      "x": -10,
      "y": 3,
      "z": -3,
      "name": "Rock_Volcanic"
    },
    {
      "x": -10,
      "y": 4,
      "z": -3,
      "name": "Rock_Volcanic"
    },
    {
      "x": -10,
      "y": 5,
      "z": -3,
      "name": "Rock_Volcanic"
    },
    {
      "x": -10,
      "y": 0,
      "z": -2,
      "name": "Rock_Volcanic"
    },
    {
      "x": -10,
      "y": 1,
      "z": -2,
      "name": "Rock_Volcanic"
    },
    {
      "x": -10,
      "y": 2,
      "z": -2,
      "name": "Rock_Volcanic"
    },
    {
      "x": -10,
      "y": 3,
      "z": -2,
      "name": "Rock_Volcanic"
    },
    {
      "x": -10,
      "y": 4,
      "z": -2,
      "name": "Rock_Volcanic"
    },
    {
      "x": -10,
      "y": 5,
      "z": -2,
      "name": "Rock_Volcanic"
    },
    {
      "x": -10,
      "y": 0,
      "z": -1,
      "name": "Rock_Volcanic"
    },
    {
      "x": -10,
      "y": 1,
      "z": -1,
      "name": "Rock_Volcanic"
    },
    {
      "x": -10,
      "y": 2,
      "z": -1,
      "name": "Rock_Volcanic"
    },
    {
      "x": -10,
      "y": 3,
      "z": -1,
      "name": "Rock_Volcanic_Cracked_Lava"
    },
    {
      "x": -10,
      "y": 4,
      "z": -1,
      "name": "Rock_Volcanic_Cracked_Lava"
    },
    {
      "x": -10,
      "y": 5,
      "z": -1,
      "name": "Rock_Volcanic"
    },
    {
      "x": -10,
      "y": 0,
      "z": 0,
      "name": "Rock_Volcanic"
    },
    {
      "x": -10,
      "y": 1,
      "z": 0,
      "name": "Rock_Volcanic"
    },
    {
      "x": -10,
      "y": 2,
      "z": 0,
      "name": "Rock_Volcanic"
    },
    {
      "x": -10,
      "y": 3,
      "z": 0,
      "name": "Rock_Volcanic"
    },
    {
      "x": -10,
      "y": 4,
      "z": 0,
      "name": "Rock_Volcanic"
    },
    {
      "x": -10,
      "y": 5,
      "z": 0,
      "name": "Rock_Volcanic"
    },
    {
      "x": -10,
      "y": 0,
      "z": 1,
      "name": "Rock_Volcanic"
    },
    {
      "x": -10,
      "y": 1,
      "z": 1,
      "name": "Rock_Volcanic"
    },
    {
      "x": -10,
      "y": 2,
      "z": 1,
      "name": "Rock_Volcanic"
    },
    {
      "x": -10,
      "y": 3,
      "z": 1,
      "name": "Rock_Volcanic"
    },
    {
      "x": -10,
      "y": 4,
      "z": 1,
      "name": "Rock_Volcanic"
    },
    {
      "x": -10,
      "y": 5,
      "z": 1,
      "name": "Rock_Volcanic"
    },
    {
      "x": -10,
      "y": 0,
      "z": 2,
      "name": "Rock_Volcanic"
    },
    {
      "x": -10,
      "y": 1,
      "z": 2,
      "name": "Rock_Volcanic"
    },
    {
      "x": -10,
      "y": 2,
      "z": 2,
      "name": "Rock_Volcanic"
    },
    {
      "x": -10,
      "y": 3,
      "z": 2,
      "name": "Rock_Volcanic"
    },
    {
      "x": -10,
      "y": 4,
      "z": 2,
      "name": "Rock_Volcanic"
    },
    {
      "x": -10,
      "y": 5,
      "z": 2,
      "name": "Rock_Volcanic"
    },
    {
      "x": -10,
      "y": 0,
      "z": 3,
      "name": "Rock_Volcanic"
    },
    {
      "x": -10,
      "y": 1,
      "z": 3,
      "name": "Rock_Volcanic"
    },
    {
      "x": -10,
      "y": 2,
      "z": 3,
      "name": "Rock_Volcanic"
    },
    {
      "x": -10,
      "y": 3,
      "z": 3,
      "name": "Rock_Volcanic"
    },
    {
      "x": -10,
      "y": 4,
      "z": 3,
      "name": "Rock_Volcanic"
    },
    {
      "x": -10,
      "y": 5,
      "z": 3,
      "name": "Rock_Volcanic"
    },
    {
      "x": -10,
      "y": 6,
      "z": 3,
      "name": "Rock_Volcanic_Stalactite_Large"
    },
    {
      "x": -10,
      "y": 7,
      "z": 3,
      "name": "Rock_Volcanic_Stalactite_Large",
      "filler": 1024
    },
    {
      "x": -10,
      "y": 0,
      "z": 4,
      "name": "Rock_Volcanic"
    },
    {
      "x": -10,
      "y": 1,
      "z": 4,
      "name": "Rock_Volcanic"
    },
    {
      "x": -10,
      "y": 5,
      "z": 4,
      "name": "Rock_Volcanic"
    },
    {
      "x": -10,
      "y": 0,
      "z": 5,
      "name": "Rock_Volcanic"
    },
    {
      "x": -10,
      "y": 1,
      "z": 5,
      "name": "Rock_Volcanic"
    },
    {
      "x": -10,
      "y": 0,
      "z": 6,
      "name": "Rock_Volcanic"
    },
    {
      "x": -10,
      "y": 1,
      "z": 6,
      "name": "Rock_Volcanic"
    },
    {
      "x": -10,
      "y": 0,
      "z": 7,
      "name": "Rock_Volcanic"
    },
    {
      "x": -10,
      "y": 1,
      "z": 7,
      "name": "Rock_Volcanic"
    },
    {
      "x": -10,
      "y": 2,
      "z": 7,
      "name": "Rock_Volcanic"
    },
    {
      "x": -10,
      "y": 3,
      "z": 7,
      "name": "Rock_Volcanic"
    },
    {
      "x": -10,
      "y": 4,
      "z": 7,
      "name": "Rock_Volcanic"
    },
    {
      "x": -10,
      "y": 0,
      "z": 8,
      "name": "Rock_Volcanic"
    },
    {
      "x": -10,
      "y": 1,
      "z": 8,
      "name": "Rock_Volcanic"
    },
    {
      "x": -10,
      "y": 2,
      "z": 8,
      "name": "Rock_Volcanic"
    },
    {
      "x": -10,
      "y": 3,
      "z": 8,
      "name": "Rock_Volcanic"
    },
    {
      "x": -10,
      "y": 4,
      "z": 8,
      "name": "Rock_Volcanic"
    },
    {
      "x": -10,
      "y": 0,
      "z": 9,
      "name": "Rock_Volcanic"
    },
    {
      "x": -10,
      "y": 1,
      "z": 9,
      "name": "Rock_Volcanic"
    },
    {
      "x": -10,
      "y": 2,
      "z": 9,
      "name": "Rock_Volcanic"
    },
    {
      "x": -10,
      "y": 3,
      "z": 9,
      "name": "Rock_Volcanic"
    },
    {
      "x": -10,
      "y": 4,
      "z": 9,
      "name": "Rock_Volcanic"
    },
    {
      "x": -10,
      "y": 0,
      "z": 10,
      "name": "Rock_Volcanic"
    },
    {
      "x": -10,
      "y": 1,
      "z": 10,
      "name": "Rock_Volcanic"
    },
    {
      "x": -10,
      "y": 2,
      "z": 10,
      "name": "Rock_Volcanic"
    },
    {
      "x": -10,
      "y": 3,
      "z": 10,
      "name": "Rock_Volcanic"
    },
    {
      "x": -10,
      "y": 4,
      "z": 10,
      "name": "Rock_Volcanic"
    },
    {
      "x": -10,
      "y": 0,
      "z": 11,
      "name": "Rock_Volcanic"
    },
    {
      "x": -10,
      "y": 1,
      "z": 11,
      "name": "Rock_Volcanic"
    },
    {
      "x": -10,
      "y": 2,
      "z": 11,
      "name": "Rock_Volcanic"
    },
    {
      "x": -10,
      "y": 3,
      "z": 11,
      "name": "Rock_Volcanic"
    },
    {
      "x": -10,
      "y": 4,
      "z": 11,
      "name": "Rock_Volcanic"
    },
    {
      "x": -10,
      "y": 0,
      "z": 12,
      "name": "Rock_Volcanic"
    },
    {
      "x": -10,
      "y": 1,
      "z": 12,
      "name": "Rock_Volcanic_Cracked_Lava"
    },
    {
      "x": -10,
      "y": 2,
      "z": 12,
      "name": "Rock_Volcanic"
    },
    {
      "x": -10,
      "y": 3,
      "z": 12,
      "name": "Rock_Volcanic"
    },
    {
      "x": -10,
      "y": 0,
      "z": 13,
      "name": "Rock_Volcanic_Cracked_Lava"
    },
    {
      "x": -10,
      "y": 1,
      "z": 13,
      "name": "Rock_Volcanic"
    },
    {
      "x": -10,
      "y": 2,
      "z": 13,
      "name": "Rock_Volcanic"
    },
    {
      "x": -10,
      "y": 3,
      "z": 13,
      "name": "Rock_Volcanic_Cracked_Lava"
    },
    {
      "x": -9,
      "y": 3,
      "z": -14,
      "name": "Rock_Volcanic"
    },
    {
      "x": -9,
      "y": 0,
      "z": -13,
      "name": "Rock_Volcanic"
    },
    {
      "x": -9,
      "y": 2,
      "z": -13,
      "name": "Rock_Volcanic"
    },
    {
      "x": -9,
      "y": 3,
      "z": -13,
      "name": "Rock_Volcanic"
    },
    {
      "x": -9,
      "y": 4,
      "z": -13,
      "name": "Rock_Volcanic"
    },
    {
      "x": -9,
      "y": 0,
      "z": -12,
      "name": "Rock_Volcanic"
    },
    {
      "x": -9,
      "y": 1,
      "z": -12,
      "name": "Rock_Volcanic"
    },
    {
      "x": -9,
      "y": 2,
      "z": -12,
      "name": "Rock_Volcanic"
    },
    {
      "x": -9,
      "y": 3,
      "z": -12,
      "name": "Rock_Volcanic_Cracked_Lava"
    },
    {
      "x": -9,
      "y": 4,
      "z": -12,
      "name": "Rock_Volcanic"
    },
    {
      "x": -9,
      "y": 0,
      "z": -11,
      "name": "Rock_Volcanic"
    },
    {
      "x": -9,
      "y": 1,
      "z": -11,
      "name": "Rock_Volcanic"
    },
    {
      "x": -9,
      "y": 2,
      "z": -11,
      "name": "Rock_Volcanic"
    },
    {
      "x": -9,
      "y": 3,
      "z": -11,
      "name": "Rock_Volcanic"
    },
    {
      "x": -9,
      "y": 0,
      "z": -10,
      "name": "Rock_Volcanic"
    },
    {
      "x": -9,
      "y": 1,
      "z": -10,
      "name": "Rock_Volcanic"
    },
    {
      "x": -9,
      "y": 2,
      "z": -10,
      "name": "Rock_Volcanic"
    },
    {
      "x": -9,
      "y": 3,
      "z": -10,
      "name": "Rock_Volcanic"
    },
    {
      "x": -9,
      "y": 0,
      "z": -9,
      "name": "Rock_Volcanic"
    },
    {
      "x": -9,
      "y": 1,
      "z": -9,
      "name": "Rock_Volcanic"
    },
    {
      "x": -9,
      "y": 2,
      "z": -9,
      "name": "Rock_Volcanic"
    },
    {
      "x": -9,
      "y": 0,
      "z": -8,
      "name": "Rock_Volcanic"
    },
    {
      "x": -9,
      "y": 1,
      "z": -8,
      "name": "Rock_Volcanic"
    },
    {
      "x": -9,
      "y": 2,
      "z": -8,
      "name": "Rock_Volcanic"
    },
    {
      "x": -9,
      "y": 0,
      "z": -7,
      "name": "Rock_Volcanic"
    },
    {
      "x": -9,
      "y": 1,
      "z": -7,
      "name": "Rock_Volcanic"
    },
    {
      "x": -9,
      "y": 2,
      "z": -7,
      "name": "Rock_Volcanic"
    },
    {
      "x": -9,
      "y": 3,
      "z": -7,
      "name": "Rock_Volcanic"
    },
    {
      "x": -9,
      "y": 4,
      "z": -7,
      "name": "Rock_Volcanic"
    },
    {
      "x": -9,
      "y": 0,
      "z": -6,
      "name": "Rock_Volcanic"
    },
    {
      "x": -9,
      "y": 1,
      "z": -6,
      "name": "Rock_Volcanic"
    },
    {
      "x": -9,
      "y": 2,
      "z": -6,
      "name": "Rock_Volcanic"
    },
    {
      "x": -9,
      "y": 3,
      "z": -6,
      "name": "Rock_Volcanic"
    },
    {
      "x": -9,
      "y": 4,
      "z": -6,
      "name": "Rock_Volcanic"
    },
    {
      "x": -9,
      "y": 5,
      "z": -6,
      "name": "Rock_Volcanic"
    },
    {
      "x": -9,
      "y": 0,
      "z": -5,
      "name": "Rock_Volcanic"
    },
    {
      "x": -9,
      "y": 1,
      "z": -5,
      "name": "Rock_Volcanic"
    },
    {
      "x": -9,
      "y": 2,
      "z": -5,
      "name": "Rock_Volcanic"
    },
    {
      "x": -9,
      "y": 3,
      "z": -5,
      "name": "Rock_Volcanic"
    },
    {
      "x": -9,
      "y": 4,
      "z": -5,
      "name": "Rock_Volcanic"
    },
    {
      "x": -9,
      "y": 5,
      "z": -5,
      "name": "Rock_Volcanic"
    },
    {
      "x": -9,
      "y": 0,
      "z": -4,
      "name": "Rock_Volcanic"
    },
    {
      "x": -9,
      "y": 1,
      "z": -4,
      "name": "Rock_Volcanic"
    },
    {
      "x": -9,
      "y": 2,
      "z": -4,
      "name": "Rock_Volcanic_Cracked_Lava"
    },
    {
      "x": -9,
      "y": 3,
      "z": -4,
      "name": "Rock_Volcanic"
    },
    {
      "x": -9,
      "y": 4,
      "z": -4,
      "name": "Rock_Volcanic"
    },
    {
      "x": -9,
      "y": 5,
      "z": -4,
      "name": "Rock_Volcanic"
    },
    {
      "x": -9,
      "y": 0,
      "z": -3,
      "name": "Rock_Volcanic"
    },
    {
      "x": -9,
      "y": 1,
      "z": -3,
      "name": "Rock_Volcanic"
    },
    {
      "x": -9,
      "y": 2,
      "z": -3,
      "name": "Rock_Volcanic"
    },
    {
      "x": -9,
      "y": 3,
      "z": -3,
      "name": "Rock_Volcanic"
    },
    {
      "x": -9,
      "y": 4,
      "z": -3,
      "name": "Rock_Volcanic"
    },
    {
      "x": -9,
      "y": 5,
      "z": -3,
      "name": "Rock_Volcanic"
    },
    {
      "x": -9,
      "y": 0,
      "z": -2,
      "name": "Rock_Volcanic"
    },
    {
      "x": -9,
      "y": 1,
      "z": -2,
      "name": "Rock_Volcanic"
    },
    {
      "x": -9,
      "y": 2,
      "z": -2,
      "name": "Rock_Volcanic"
    },
    {
      "x": -9,
      "y": 3,
      "z": -2,
      "name": "Rock_Volcanic"
    },
    {
      "x": -9,
      "y": 4,
      "z": -2,
      "name": "Rock_Volcanic_Cracked_Lava"
    },
    {
      "x": -9,
      "y": 5,
      "z": -2,
      "name": "Rock_Volcanic"
    },
    {
      "x": -9,
      "y": 0,
      "z": -1,
      "name": "Rock_Volcanic"
    },
    {
      "x": -9,
      "y": 1,
      "z": -1,
      "name": "Rock_Volcanic"
    },
    {
      "x": -9,
      "y": 2,
      "z": -1,
      "name": "Rock_Volcanic"
    },
    {
      "x": -9,
      "y": 3,
      "z": -1,
      "name": "Rock_Volcanic"
    },
    {
      "x": -9,
      "y": 4,
      "z": -1,
      "name": "Rock_Volcanic"
    },
    {
      "x": -9,
      "y": 5,
      "z": -1,
      "name": "Rock_Volcanic"
    },
    {
      "x": -9,
      "y": 6,
      "z": -1,
      "name": "Rock_Volcanic_Stalactite_Small"
    },
    {
      "x": -9,
      "y": 0,
      "z": 0,
      "name": "Rock_Volcanic"
    },
    {
      "x": -9,
      "y": 1,
      "z": 0,
      "name": "Rock_Volcanic"
    },
    {
      "x": -9,
      "y": 2,
      "z": 0,
      "name": "Rock_Volcanic"
    },
    {
      "x": -9,
      "y": 3,
      "z": 0,
      "name": "Rock_Volcanic"
    },
    {
      "x": -9,
      "y": 4,
      "z": 0,
      "name": "Rock_Volcanic"
    },
    {
      "x": -9,
      "y": 5,
      "z": 0,
      "name": "Rock_Volcanic"
    },
    {
      "x": -9,
      "y": 0,
      "z": 1,
      "name": "Rock_Volcanic"
    },
    {
      "x": -9,
      "y": 1,
      "z": 1,
      "name": "Rock_Volcanic"
    },
    {
      "x": -9,
      "y": 2,
      "z": 1,
      "name": "Rock_Volcanic"
    },
    {
      "x": -9,
      "y": 3,
      "z": 1,
      "name": "Rock_Volcanic"
    },
    {
      "x": -9,
      "y": 4,
      "z": 1,
      "name": "Rock_Volcanic"
    },
    {
      "x": -9,
      "y": 5,
      "z": 1,
      "name": "Rock_Volcanic"
    },
    {
      "x": -9,
      "y": 0,
      "z": 2,
      "name": "Rock_Volcanic"
    },
    {
      "x": -9,
      "y": 1,
      "z": 2,
      "name": "Rock_Volcanic"
    },
    {
      "x": -9,
      "y": 2,
      "z": 2,
      "name": "Rock_Volcanic"
    },
    {
      "x": -9,
      "y": 3,
      "z": 2,
      "name": "Rock_Volcanic"
    },
    {
      "x": -9,
      "y": 4,
      "z": 2,
      "name": "Rock_Volcanic"
    },
    {
      "x": -9,
      "y": 5,
      "z": 2,
      "name": "Rock_Volcanic"
    },
    {
      "x": -9,
      "y": 0,
      "z": 3,
      "name": "Rock_Volcanic"
    },
    {
      "x": -9,
      "y": 1,
      "z": 3,
      "name": "Rock_Volcanic"
    },
    {
      "x": -9,
      "y": 2,
      "z": 3,
      "name": "Rock_Volcanic"
    },
    {
      "x": -9,
      "y": 3,
      "z": 3,
      "name": "Rock_Volcanic"
    },
    {
      "x": -9,
      "y": 4,
      "z": 3,
      "name": "Rock_Volcanic"
    },
    {
      "x": -9,
      "y": 5,
      "z": 3,
      "name": "Rock_Volcanic"
    },
    {
      "x": -9,
      "y": 0,
      "z": 4,
      "name": "Rock_Volcanic"
    },
    {
      "x": -9,
      "y": 1,
      "z": 4,
      "name": "Rock_Volcanic_Cracked_Lava"
    },
    {
      "x": -9,
      "y": 2,
      "z": 4,
      "name": "Rock_Volcanic"
    },
    {
      "x": -9,
      "y": 3,
      "z": 4,
      "name": "Rock_Volcanic"
    },
    {
      "x": -9,
      "y": 4,
      "z": 4,
      "name": "Rock_Volcanic"
    },
    {
      "x": -9,
      "y": 5,
      "z": 4,
      "name": "Rock_Volcanic"
    },
    {
      "x": -9,
      "y": 0,
      "z": 5,
      "name": "Rock_Volcanic"
    },
    {
      "x": -9,
      "y": 1,
      "z": 5,
      "name": "Rock_Volcanic"
    },
    {
      "x": -9,
      "y": 2,
      "z": 5,
      "name": "Rock_Volcanic"
    },
    {
      "x": -9,
      "y": 3,
      "z": 5,
      "name": "Rock_Volcanic"
    },
    {
      "x": -9,
      "y": 4,
      "z": 5,
      "name": "Rock_Volcanic"
    },
    {
      "x": -9,
      "y": 5,
      "z": 5,
      "name": "Rock_Volcanic"
    },
    {
      "x": -9,
      "y": 0,
      "z": 6,
      "name": "Rock_Volcanic"
    },
    {
      "x": -9,
      "y": 1,
      "z": 6,
      "name": "Rock_Volcanic"
    },
    {
      "x": -9,
      "y": 2,
      "z": 6,
      "name": "Rock_Volcanic"
    },
    {
      "x": -9,
      "y": 3,
      "z": 6,
      "name": "Rock_Volcanic"
    },
    {
      "x": -9,
      "y": 4,
      "z": 6,
      "name": "Rock_Volcanic"
    },
    {
      "x": -9,
      "y": 5,
      "z": 6,
      "name": "Rock_Volcanic"
    },
    {
      "x": -9,
      "y": 0,
      "z": 7,
      "name": "Rock_Volcanic"
    },
    {
      "x": -9,
      "y": 1,
      "z": 7,
      "name": "Rock_Volcanic"
    },
    {
      "x": -9,
      "y": 2,
      "z": 7,
      "name": "Rock_Volcanic"
    },
    {
      "x": -9,
      "y": 3,
      "z": 7,
      "name": "Rock_Volcanic"
    },
    {
      "x": -9,
      "y": 4,
      "z": 7,
      "name": "Rock_Volcanic"
    },
    {
      "x": -9,
      "y": 5,
      "z": 7,
      "name": "Rock_Volcanic"
    },
    {
      "x": -9,
      "y": 0,
      "z": 8,
      "name": "Rock_Volcanic"
    },
    {
      "x": -9,
      "y": 1,
      "z": 8,
      "name": "Rock_Volcanic"
    },
    {
      "x": -9,
      "y": 2,
      "z": 8,
      "name": "Rock_Volcanic"
    },
    {
      "x": -9,
      "y": 3,
      "z": 8,
      "name": "Rock_Volcanic"
    },
    {
      "x": -9,
      "y": 4,
      "z": 8,
      "name": "Rock_Volcanic"
    },
    {
      "x": -9,
      "y": 0,
      "z": 9,
      "name": "Rock_Volcanic"
    },
    {
      "x": -9,
      "y": 1,
      "z": 9,
      "name": "Rock_Volcanic"
    },
    {
      "x": -9,
      "y": 2,
      "z": 9,
      "name": "Rock_Volcanic"
    },
    {
      "x": -9,
      "y": 3,
      "z": 9,
      "name": "Rock_Volcanic_Cracked_Lava"
    },
    {
      "x": -9,
      "y": 4,
      "z": 9,
      "name": "Rock_Volcanic"
    },
    {
      "x": -9,
      "y": 0,
      "z": 10,
      "name": "Rock_Volcanic"
    },
    {
      "x": -9,
      "y": 1,
      "z": 10,
      "name": "Rock_Volcanic"
    },
    {
      "x": -9,
      "y": 2,
      "z": 10,
      "name": "Rock_Volcanic"
    },
    {
      "x": -9,
      "y": 3,
      "z": 10,
      "name": "Rock_Volcanic"
    },
    {
      "x": -9,
      "y": 4,
      "z": 10,
      "name": "Rock_Volcanic"
    },
    {
      "x": -9,
      "y": 0,
      "z": 11,
      "name": "Rock_Volcanic"
    },
    {
      "x": -9,
      "y": 1,
      "z": 11,
      "name": "Rock_Volcanic"
    },
    {
      "x": -9,
      "y": 2,
      "z": 11,
      "name": "Rock_Volcanic"
    },
    {
      "x": -9,
      "y": 3,
      "z": 11,
      "name": "Rock_Volcanic_Cracked_Lava"
    },
    {
      "x": -9,
      "y": 4,
      "z": 11,
      "name": "Rock_Volcanic"
    },
    {
      "x": -9,
      "y": 0,
      "z": 12,
      "name": "Rock_Volcanic"
    },
    {
      "x": -9,
      "y": 1,
      "z": 12,
      "name": "Rock_Volcanic_Cracked_Lava"
    },
    {
      "x": -9,
      "y": 2,
      "z": 12,
      "name": "Rock_Volcanic"
    },
    {
      "x": -9,
      "y": 3,
      "z": 12,
      "name": "Rock_Volcanic"
    },
    {
      "x": -9,
      "y": 4,
      "z": 12,
      "name": "Rock_Volcanic"
    },
    {
      "x": -9,
      "y": 0,
      "z": 13,
      "name": "Rock_Volcanic_Cracked_Lava"
    },
    {
      "x": -9,
      "y": 1,
      "z": 13,
      "name": "Rock_Volcanic"
    },
    {
      "x": -9,
      "y": 2,
      "z": 13,
      "name": "Rock_Volcanic"
    },
    {
      "x": -9,
      "y": 3,
      "z": 13,
      "name": "Rock_Volcanic"
    },
    {
      "x": -9,
      "y": 0,
      "z": 14,
      "name": "Rock_Volcanic"
    },
    {
      "x": -8,
      "y": 3,
      "z": -15,
      "name": "Rock_Volcanic"
    },
    {
      "x": -8,
      "y": 0,
      "z": -14,
      "name": "Rock_Volcanic"
    },
    {
      "x": -8,
      "y": 1,
      "z": -14,
      "name": "Rock_Volcanic"
    },
    {
      "x": -8,
      "y": 2,
      "z": -14,
      "name": "Rock_Volcanic"
    },
    {
      "x": -8,
      "y": 3,
      "z": -14,
      "name": "Rock_Volcanic"
    },
    {
      "x": -8,
      "y": 4,
      "z": -14,
      "name": "Rock_Volcanic"
    },
    {
      "x": -8,
      "y": 0,
      "z": -13,
      "name": "Rock_Volcanic"
    },
    {
      "x": -8,
      "y": 1,
      "z": -13,
      "name": "Rock_Volcanic"
    },
    {
      "x": -8,
      "y": 2,
      "z": -13,
      "name": "Rock_Volcanic"
    },
    {
      "x": -8,
      "y": 3,
      "z": -13,
      "name": "Rock_Volcanic"
    },
    {
      "x": -8,
      "y": 4,
      "z": -13,
      "name": "Rock_Volcanic_Cracked_Lava"
    },
    {
      "x": -8,
      "y": 5,
      "z": -13,
      "name": "Rock_Volcanic_Stalactite_Large"
    },
    {
      "x": -8,
      "y": 6,
      "z": -13,
      "name": "Rock_Volcanic_Stalactite_Large",
      "filler": 1024
    },
    {
      "x": -8,
      "y": 0,
      "z": -12,
      "name": "Rock_Volcanic"
    },
    {
      "x": -8,
      "y": 1,
      "z": -12,
      "name": "Rock_Volcanic"
    },
    {
      "x": -8,
      "y": 2,
      "z": -12,
      "name": "Rock_Volcanic"
    },
    {
      "x": -8,
      "y": 3,
      "z": -12,
      "name": "Rock_Volcanic"
    },
    {
      "x": -8,
      "y": 4,
      "z": -12,
      "name": "Rock_Volcanic"
    },
    {
      "x": -8,
      "y": 0,
      "z": -11,
      "name": "Rock_Volcanic"
    },
    {
      "x": -8,
      "y": 1,
      "z": -11,
      "name": "Rock_Volcanic"
    },
    {
      "x": -8,
      "y": 2,
      "z": -11,
      "name": "Rock_Volcanic"
    },
    {
      "x": -8,
      "y": 3,
      "z": -11,
      "name": "Rock_Volcanic"
    },
    {
      "x": -8,
      "y": 0,
      "z": -10,
      "name": "Rock_Volcanic"
    },
    {
      "x": -8,
      "y": 1,
      "z": -10,
      "name": "Rock_Volcanic"
    },
    {
      "x": -8,
      "y": 2,
      "z": -10,
      "name": "Rock_Volcanic"
    },
    {
      "x": -8,
      "y": 0,
      "z": -9,
      "name": "Rock_Volcanic"
    },
    {
      "x": -8,
      "y": 1,
      "z": -9,
      "name": "Rock_Volcanic"
    },
    {
      "x": -8,
      "y": 2,
      "z": -9,
      "name": "Rock_Volcanic"
    },
    {
      "x": -8,
      "y": 0,
      "z": -8,
      "name": "Rock_Volcanic"
    },
    {
      "x": -8,
      "y": 1,
      "z": -8,
      "name": "Rock_Volcanic"
    },
    {
      "x": -8,
      "y": 2,
      "z": -8,
      "name": "Rock_Volcanic_Cracked_Lava"
    },
    {
      "x": -8,
      "y": 0,
      "z": -7,
      "name": "Rock_Volcanic"
    },
    {
      "x": -8,
      "y": 1,
      "z": -7,
      "name": "Rock_Volcanic"
    },
    {
      "x": -8,
      "y": 2,
      "z": -7,
      "name": "Rock_Volcanic"
    },
    {
      "x": -8,
      "y": 3,
      "z": -7,
      "name": "Rock_Volcanic_Cracked_Lava"
    },
    {
      "x": -8,
      "y": 4,
      "z": -7,
      "name": "Rock_Volcanic"
    },
    {
      "x": -8,
      "y": 0,
      "z": -6,
      "name": "Rock_Volcanic"
    },
    {
      "x": -8,
      "y": 1,
      "z": -6,
      "name": "Rock_Volcanic"
    },
    {
      "x": -8,
      "y": 3,
      "z": -6,
      "name": "Rock_Volcanic"
    },
    {
      "x": -8,
      "y": 4,
      "z": -6,
      "name": "Rock_Volcanic"
    },
    {
      "x": -8,
      "y": 5,
      "z": -6,
      "name": "Rock_Volcanic_Cracked_Lava"
    },
    {
      "x": -8,
      "y": 0,
      "z": -5,
      "name": "Rock_Volcanic"
    },
    {
      "x": -8,
      "y": 1,
      "z": -5,
      "name": "Rock_Volcanic"
    },
    {
      "x": -8,
      "y": 2,
      "z": -5,
      "name": "Rock_Volcanic"
    },
    {
      "x": -8,
      "y": 3,
      "z": -5,
      "name": "Rock_Volcanic"
    },
    {
      "x": -8,
      "y": 4,
      "z": -5,
      "name": "Rock_Volcanic"
    },
    {
      "x": -8,
      "y": 5,
      "z": -5,
      "name": "Rock_Volcanic"
    },
    {
      "x": -8,
      "y": 0,
      "z": -4,
      "name": "Rock_Volcanic"
    },
    {
      "x": -8,
      "y": 1,
      "z": -4,
      "name": "Rock_Volcanic"
    },
    {
      "x": -8,
      "y": 2,
      "z": -4,
      "name": "Rock_Volcanic"
    },
    {
      "x": -8,
      "y": 3,
      "z": -4,
      "name": "Rock_Volcanic"
    },
    {
      "x": -8,
      "y": 4,
      "z": -4,
      "name": "Rock_Volcanic"
    },
    {
      "x": -8,
      "y": 5,
      "z": -4,
      "name": "Rock_Volcanic"
    },
    {
      "x": -8,
      "y": 6,
      "z": -4,
      "name": "Rock_Volcanic_Stalactite_Large"
    },
    {
      "x": -8,
      "y": 7,
      "z": -4,
      "name": "Rock_Volcanic_Stalactite_Large",
      "filler": 1024
    },
    {
      "x": -8,
      "y": 0,
      "z": -3,
      "name": "Rock_Volcanic"
    },
    {
      "x": -8,
      "y": 1,
      "z": -3,
      "name": "Rock_Volcanic"
    },
    {
      "x": -8,
      "y": 2,
      "z": -3,
      "name": "Rock_Volcanic"
    },
    {
      "x": -8,
      "y": 3,
      "z": -3,
      "name": "Rock_Volcanic"
    },
    {
      "x": -8,
      "y": 4,
      "z": -3,
      "name": "Rock_Volcanic"
    },
    {
      "x": -8,
      "y": 5,
      "z": -3,
      "name": "Rock_Volcanic"
    },
    {
      "x": -8,
      "y": 0,
      "z": -2,
      "name": "Rock_Volcanic"
    },
    {
      "x": -8,
      "y": 1,
      "z": -2,
      "name": "Rock_Volcanic"
    },
    {
      "x": -8,
      "y": 2,
      "z": -2,
      "name": "Rock_Volcanic"
    },
    {
      "x": -8,
      "y": 3,
      "z": -2,
      "name": "Rock_Volcanic"
    },
    {
      "x": -8,
      "y": 4,
      "z": -2,
      "name": "Rock_Volcanic"
    },
    {
      "x": -8,
      "y": 5,
      "z": -2,
      "name": "Rock_Volcanic"
    },
    {
      "x": -8,
      "y": 6,
      "z": -2,
      "name": "Rock_Volcanic"
    },
    {
      "x": -8,
      "y": 0,
      "z": -1,
      "name": "Rock_Volcanic"
    },
    {
      "x": -8,
      "y": 1,
      "z": -1,
      "name": "Rock_Volcanic"
    },
    {
      "x": -8,
      "y": 2,
      "z": -1,
      "name": "Rock_Volcanic"
    },
    {
      "x": -8,
      "y": 3,
      "z": -1,
      "name": "Rock_Volcanic"
    },
    {
      "x": -8,
      "y": 4,
      "z": -1,
      "name": "Rock_Volcanic"
    },
    {
      "x": -8,
      "y": 5,
      "z": -1,
      "name": "Rock_Volcanic"
    },
    {
      "x": -8,
      "y": 6,
      "z": -1,
      "name": "Rock_Volcanic"
    },
    {
      "x": -8,
      "y": 0,
      "z": 0,
      "name": "Rock_Volcanic"
    },
    {
      "x": -8,
      "y": 1,
      "z": 0,
      "name": "Rock_Volcanic"
    },
    {
      "x": -8,
      "y": 2,
      "z": 0,
      "name": "Rock_Volcanic"
    },
    {
      "x": -8,
      "y": 3,
      "z": 0,
      "name": "Rock_Volcanic_Cracked_Lava"
    },
    {
      "x": -8,
      "y": 4,
      "z": 0,
      "name": "Rock_Volcanic"
    },
    {
      "x": -8,
      "y": 5,
      "z": 0,
      "name": "Rock_Volcanic"
    },
    {
      "x": -8,
      "y": 6,
      "z": 0,
      "name": "Rock_Volcanic_Cracked_Lava"
    },
    {
      "x": -8,
      "y": 0,
      "z": 1,
      "name": "Rock_Volcanic"
    },
    {
      "x": -8,
      "y": 1,
      "z": 1,
      "name": "Rock_Volcanic"
    },
    {
      "x": -8,
      "y": 2,
      "z": 1,
      "name": "Rock_Volcanic"
    },
    {
      "x": -8,
      "y": 3,
      "z": 1,
      "name": "Rock_Volcanic"
    },
    {
      "x": -8,
      "y": 4,
      "z": 1,
      "name": "Rock_Volcanic"
    },
    {
      "x": -8,
      "y": 5,
      "z": 1,
      "name": "Rock_Volcanic"
    },
    {
      "x": -8,
      "y": 6,
      "z": 1,
      "name": "Rock_Volcanic_Cracked_Lava"
    },
    {
      "x": -8,
      "y": 7,
      "z": 1,
      "name": "Rock_Volcanic"
    },
    {
      "x": -8,
      "y": 14,
      "z": 1,
      "name": "Ore_Adamantite_Magma_Cracked"
    },
    {
      "x": -8,
      "y": 0,
      "z": 2,
      "name": "Rock_Volcanic"
    },
    {
      "x": -8,
      "y": 1,
      "z": 2,
      "name": "Rock_Volcanic"
    },
    {
      "x": -8,
      "y": 2,
      "z": 2,
      "name": "Rock_Volcanic"
    },
    {
      "x": -8,
      "y": 3,
      "z": 2,
      "name": "Rock_Volcanic"
    },
    {
      "x": -8,
      "y": 4,
      "z": 2,
      "name": "Rock_Volcanic"
    },
    {
      "x": -8,
      "y": 5,
      "z": 2,
      "name": "Rock_Volcanic"
    },
    {
      "x": -8,
      "y": 6,
      "z": 2,
      "name": "Rock_Volcanic"
    },
    {
      "x": -8,
      "y": 13,
      "z": 2,
      "name": "Rock_Magma_Cooled_Stalactite_Small",
      "rotation": 8
    },
    {
      "x": -8,
      "y": 14,
      "z": 2,
      "name": "Rock_Magma_Cooled"
    },
    {
      "x": -8,
      "y": 15,
      "z": 2,
      "name": "Rock_Magma_Cooled"
    },
    {
      "x": -8,
      "y": 16,
      "z": 2,
      "name": "Ore_Adamantite_Magma_Cracked"
    },
    {
      "x": -8,
      "y": 17,
      "z": 2,
      "name": "Ore_Adamantite_Magma_Cracked"
    },
    {
      "x": -8,
      "y": 0,
      "z": 3,
      "name": "Rock_Volcanic"
    },
    {
      "x": -8,
      "y": 1,
      "z": 3,
      "name": "Rock_Volcanic"
    },
    {
      "x": -8,
      "y": 2,
      "z": 3,
      "name": "Rock_Volcanic"
    },
    {
      "x": -8,
      "y": 3,
      "z": 3,
      "name": "Rock_Volcanic"
    },
    {
      "x": -8,
      "y": 4,
      "z": 3,
      "name": "Rock_Volcanic"
    },
    {
      "x": -8,
      "y": 5,
      "z": 3,
      "name": "Rock_Volcanic"
    },
    {
      "x": -8,
      "y": 6,
      "z": 3,
      "name": "Rock_Volcanic"
    },
    {
      "x": -8,
      "y": 0,
      "z": 4,
      "name": "Rock_Volcanic"
    },
    {
      "x": -8,
      "y": 1,
      "z": 4,
      "name": "Rock_Volcanic"
    },
    {
      "x": -8,
      "y": 2,
      "z": 4,
      "name": "Rock_Volcanic"
    },
    {
      "x": -8,
      "y": 3,
      "z": 4,
      "name": "Rock_Volcanic"
    },
    {
      "x": -8,
      "y": 4,
      "z": 4,
      "name": "Rock_Volcanic"
    },
    {
      "x": -8,
      "y": 5,
      "z": 4,
      "name": "Rock_Volcanic"
    },
    {
      "x": -8,
      "y": 6,
      "z": 4,
      "name": "Rock_Volcanic"
    },
    {
      "x": -8,
      "y": 0,
      "z": 5,
      "name": "Rock_Volcanic"
    },
    {
      "x": -8,
      "y": 1,
      "z": 5,
      "name": "Rock_Volcanic"
    },
    {
      "x": -8,
      "y": 2,
      "z": 5,
      "name": "Rock_Volcanic"
    },
    {
      "x": -8,
      "y": 3,
      "z": 5,
      "name": "Rock_Volcanic_Cracked_Lava"
    },
    {
      "x": -8,
      "y": 4,
      "z": 5,
      "name": "Rock_Volcanic"
    },
    {
      "x": -8,
      "y": 5,
      "z": 5,
      "name": "Rock_Volcanic"
    },
    {
      "x": -8,
      "y": 0,
      "z": 6,
      "name": "Rock_Volcanic"
    },
    {
      "x": -8,
      "y": 1,
      "z": 6,
      "name": "Rock_Volcanic"
    },
    {
      "x": -8,
      "y": 2,
      "z": 6,
      "name": "Rock_Volcanic"
    },
    {
      "x": -8,
      "y": 3,
      "z": 6,
      "name": "Rock_Volcanic"
    },
    {
      "x": -8,
      "y": 4,
      "z": 6,
      "name": "Rock_Volcanic"
    },
    {
      "x": -8,
      "y": 5,
      "z": 6,
      "name": "Rock_Volcanic"
    },
    {
      "x": -8,
      "y": 0,
      "z": 7,
      "name": "Rock_Volcanic"
    },
    {
      "x": -8,
      "y": 1,
      "z": 7,
      "name": "Rock_Volcanic"
    },
    {
      "x": -8,
      "y": 2,
      "z": 7,
      "name": "Rock_Volcanic"
    },
    {
      "x": -8,
      "y": 3,
      "z": 7,
      "name": "Rock_Volcanic"
    },
    {
      "x": -8,
      "y": 4,
      "z": 7,
      "name": "Rock_Volcanic"
    },
    {
      "x": -8,
      "y": 5,
      "z": 7,
      "name": "Rock_Volcanic"
    },
    {
      "x": -8,
      "y": 0,
      "z": 8,
      "name": "Rock_Volcanic"
    },
    {
      "x": -8,
      "y": 1,
      "z": 8,
      "name": "Rock_Volcanic"
    },
    {
      "x": -8,
      "y": 2,
      "z": 8,
      "name": "Rock_Volcanic"
    },
    {
      "x": -8,
      "y": 3,
      "z": 8,
      "name": "Rock_Volcanic"
    },
    {
      "x": -8,
      "y": 4,
      "z": 8,
      "name": "Rock_Volcanic"
    },
    {
      "x": -8,
      "y": 5,
      "z": 8,
      "name": "Rock_Volcanic"
    },
    {
      "x": -8,
      "y": 0,
      "z": 9,
      "name": "Rock_Volcanic"
    },
    {
      "x": -8,
      "y": 1,
      "z": 9,
      "name": "Rock_Volcanic"
    },
    {
      "x": -8,
      "y": 2,
      "z": 9,
      "name": "Rock_Volcanic_Cracked_Lava"
    },
    {
      "x": -8,
      "y": 3,
      "z": 9,
      "name": "Rock_Volcanic"
    },
    {
      "x": -8,
      "y": 4,
      "z": 9,
      "name": "Rock_Volcanic"
    },
    {
      "x": -8,
      "y": 5,
      "z": 9,
      "name": "Rock_Volcanic"
    },
    {
      "x": -8,
      "y": 0,
      "z": 10,
      "name": "Rock_Volcanic"
    },
    {
      "x": -8,
      "y": 1,
      "z": 10,
      "name": "Rock_Volcanic"
    },
    {
      "x": -8,
      "y": 2,
      "z": 10,
      "name": "Rock_Volcanic"
    },
    {
      "x": -8,
      "y": 3,
      "z": 10,
      "name": "Rock_Volcanic"
    },
    {
      "x": -8,
      "y": 4,
      "z": 10,
      "name": "Rock_Volcanic"
    },
    {
      "x": -8,
      "y": 0,
      "z": 11,
      "name": "Rock_Volcanic"
    },
    {
      "x": -8,
      "y": 1,
      "z": 11,
      "name": "Rock_Volcanic"
    },
    {
      "x": -8,
      "y": 2,
      "z": 11,
      "name": "Rock_Volcanic"
    },
    {
      "x": -8,
      "y": 3,
      "z": 11,
      "name": "Rock_Volcanic"
    },
    {
      "x": -8,
      "y": 4,
      "z": 11,
      "name": "Rock_Volcanic"
    },
    {
      "x": -8,
      "y": 0,
      "z": 12,
      "name": "Rock_Volcanic_Cracked_Lava"
    },
    {
      "x": -8,
      "y": 1,
      "z": 12,
      "name": "Rock_Volcanic"
    },
    {
      "x": -8,
      "y": 2,
      "z": 12,
      "name": "Rock_Volcanic"
    },
    {
      "x": -8,
      "y": 3,
      "z": 12,
      "name": "Rock_Volcanic"
    },
    {
      "x": -8,
      "y": 4,
      "z": 12,
      "name": "Rock_Volcanic"
    },
    {
      "x": -8,
      "y": 5,
      "z": 12,
      "name": "Rock_Volcanic_Stalactite_Small"
    },
    {
      "x": -8,
      "y": 0,
      "z": 13,
      "name": "Rock_Volcanic"
    },
    {
      "x": -8,
      "y": 1,
      "z": 13,
      "name": "Rock_Volcanic"
    },
    {
      "x": -8,
      "y": 2,
      "z": 13,
      "name": "Rock_Volcanic"
    },
    {
      "x": -8,
      "y": 3,
      "z": 13,
      "name": "Rock_Volcanic"
    },
    {
      "x": -8,
      "y": 4,
      "z": 13,
      "name": "Rock_Volcanic"
    },
    {
      "x": -8,
      "y": 0,
      "z": 14,
      "name": "Rock_Volcanic"
    },
    {
      "x": -8,
      "y": 1,
      "z": 14,
      "name": "Rock_Volcanic_Cracked_Lava"
    },
    {
      "x": -8,
      "y": 2,
      "z": 14,
      "name": "Rock_Volcanic"
    },
    {
      "x": -8,
      "y": 3,
      "z": 14,
      "name": "Rock_Volcanic"
    },
    {
      "x": -7,
      "y": 0,
      "z": -15,
      "name": "Rock_Volcanic"
    },
    {
      "x": -7,
      "y": 2,
      "z": -15,
      "name": "Rock_Volcanic"
    },
    {
      "x": -7,
      "y": 3,
      "z": -15,
      "name": "Rock_Volcanic"
    },
    {
      "x": -7,
      "y": 0,
      "z": -14,
      "name": "Rock_Volcanic"
    },
    {
      "x": -7,
      "y": 1,
      "z": -14,
      "name": "Rock_Volcanic"
    },
    {
      "x": -7,
      "y": 2,
      "z": -14,
      "name": "Rock_Volcanic"
    },
    {
      "x": -7,
      "y": 3,
      "z": -14,
      "name": "Rock_Volcanic"
    },
    {
      "x": -7,
      "y": 4,
      "z": -14,
      "name": "Rock_Volcanic_Cracked_Lava"
    },
    {
      "x": -7,
      "y": 0,
      "z": -13,
      "name": "Rock_Volcanic"
    },
    {
      "x": -7,
      "y": 1,
      "z": -13,
      "name": "Rock_Volcanic_Cracked_Lava"
    },
    {
      "x": -7,
      "y": 2,
      "z": -13,
      "name": "Rock_Volcanic"
    },
    {
      "x": -7,
      "y": 3,
      "z": -13,
      "name": "Rock_Volcanic"
    },
    {
      "x": -7,
      "y": 4,
      "z": -13,
      "name": "Rock_Volcanic_Cracked_Lava"
    },
    {
      "x": -7,
      "y": 0,
      "z": -12,
      "name": "Rock_Volcanic"
    },
    {
      "x": -7,
      "y": 1,
      "z": -12,
      "name": "Rock_Volcanic"
    },
    {
      "x": -7,
      "y": 2,
      "z": -12,
      "name": "Rock_Volcanic"
    },
    {
      "x": -7,
      "y": 3,
      "z": -12,
      "name": "Rock_Volcanic"
    },
    {
      "x": -7,
      "y": 4,
      "z": -12,
      "name": "Rock_Volcanic"
    },
    {
      "x": -7,
      "y": 0,
      "z": -11,
      "name": "Rock_Volcanic"
    },
    {
      "x": -7,
      "y": 1,
      "z": -11,
      "name": "Rock_Volcanic"
    },
    {
      "x": -7,
      "y": 2,
      "z": -11,
      "name": "Rock_Volcanic"
    },
    {
      "x": -7,
      "y": 3,
      "z": -11,
      "name": "Rock_Volcanic"
    },
    {
      "x": -7,
      "y": 4,
      "z": -11,
      "name": "Rock_Volcanic"
    },
    {
      "x": -7,
      "y": 0,
      "z": -10,
      "name": "Rock_Volcanic"
    },
    {
      "x": -7,
      "y": 1,
      "z": -10,
      "name": "Rock_Volcanic"
    },
    {
      "x": -7,
      "y": 2,
      "z": -10,
      "name": "Rock_Volcanic"
    },
    {
      "x": -7,
      "y": 0,
      "z": -9,
      "name": "Rock_Volcanic"
    },
    {
      "x": -7,
      "y": 1,
      "z": -9,
      "name": "Rock_Volcanic"
    },
    {
      "x": -7,
      "y": 2,
      "z": -9,
      "name": "Rock_Volcanic"
    },
    {
      "x": -7,
      "y": 0,
      "z": -8,
      "name": "Rock_Volcanic"
    },
    {
      "x": -7,
      "y": 1,
      "z": -8,
      "name": "Rock_Volcanic"
    },
    {
      "x": -7,
      "y": 2,
      "z": -8,
      "name": "Rock_Volcanic"
    },
    {
      "x": -7,
      "y": 3,
      "z": -8,
      "name": "Rock_Volcanic"
    },
    {
      "x": -7,
      "y": 4,
      "z": -8,
      "name": "Rock_Volcanic"
    },
    {
      "x": -7,
      "y": 0,
      "z": -7,
      "name": "Rock_Volcanic"
    },
    {
      "x": -7,
      "y": 1,
      "z": -7,
      "name": "Rock_Volcanic"
    },
    {
      "x": -7,
      "y": 2,
      "z": -7,
      "name": "Rock_Volcanic"
    },
    {
      "x": -7,
      "y": 3,
      "z": -7,
      "name": "Rock_Volcanic"
    },
    {
      "x": -7,
      "y": 4,
      "z": -7,
      "name": "Rock_Volcanic"
    },
    {
      "x": -7,
      "y": 5,
      "z": -7,
      "name": "Rock_Volcanic"
    },
    {
      "x": -7,
      "y": 0,
      "z": -6,
      "name": "Rock_Volcanic"
    },
    {
      "x": -7,
      "y": 1,
      "z": -6,
      "name": "Rock_Volcanic"
    },
    {
      "x": -7,
      "y": 2,
      "z": -6,
      "name": "Rock_Volcanic_Cracked_Lava"
    },
    {
      "x": -7,
      "y": 3,
      "z": -6,
      "name": "Rock_Volcanic"
    },
    {
      "x": -7,
      "y": 4,
      "z": -6,
      "name": "Rock_Volcanic_Cracked_Lava"
    },
    {
      "x": -7,
      "y": 5,
      "z": -6,
      "name": "Rock_Volcanic"
    },
    {
      "x": -7,
      "y": 0,
      "z": -5,
      "name": "Rock_Volcanic"
    },
    {
      "x": -7,
      "y": 1,
      "z": -5,
      "name": "Rock_Volcanic"
    },
    {
      "x": -7,
      "y": 2,
      "z": -5,
      "name": "Rock_Volcanic"
    },
    {
      "x": -7,
      "y": 3,
      "z": -5,
      "name": "Rock_Volcanic"
    },
    {
      "x": -7,
      "y": 4,
      "z": -5,
      "name": "Rock_Volcanic"
    },
    {
      "x": -7,
      "y": 5,
      "z": -5,
      "name": "Rock_Volcanic"
    },
    {
      "x": -7,
      "y": 0,
      "z": -4,
      "name": "Rock_Volcanic"
    },
    {
      "x": -7,
      "y": 1,
      "z": -4,
      "name": "Rock_Volcanic"
    },
    {
      "x": -7,
      "y": 2,
      "z": -4,
      "name": "Rock_Volcanic"
    },
    {
      "x": -7,
      "y": 3,
      "z": -4,
      "name": "Rock_Volcanic"
    },
    {
      "x": -7,
      "y": 4,
      "z": -4,
      "name": "Rock_Volcanic"
    },
    {
      "x": -7,
      "y": 5,
      "z": -4,
      "name": "Rock_Volcanic"
    },
    {
      "x": -7,
      "y": 6,
      "z": -4,
      "name": "Rock_Volcanic_Cracked_Lava"
    },
    {
      "x": -7,
      "y": 10,
      "z": -4,
      "name": "Rock_Volcanic"
    },
    {
      "x": -7,
      "y": 11,
      "z": -4,
      "name": "Rock_Volcanic"
    },
    {
      "x": -7,
      "y": 12,
      "z": -4,
      "name": "Rock_Magma_Cooled"
    },
    {
      "x": -7,
      "y": 13,
      "z": -4,
      "name": "Rock_Magma_Cooled"
    },
    {
      "x": -7,
      "y": 14,
      "z": -4,
      "name": "Rock_Magma_Cooled"
    },
    {
      "x": -7,
      "y": 15,
      "z": -4,
      "name": "Rock_Magma_Cooled_Stalactite_Large"
    },
    {
      "x": -7,
      "y": 16,
      "z": -4,
      "name": "Rock_Magma_Cooled_Stalactite_Large",
      "filler": 1024
    },
    {
      "x": -7,
      "y": 0,
      "z": -3,
      "name": "Rock_Volcanic"
    },
    {
      "x": -7,
      "y": 1,
      "z": -3,
      "name": "Rock_Volcanic"
    },
    {
      "x": -7,
      "y": 2,
      "z": -3,
      "name": "Rock_Volcanic"
    },
    {
      "x": -7,
      "y": 3,
      "z": -3,
      "name": "Rock_Volcanic"
    },
    {
      "x": -7,
      "y": 4,
      "z": -3,
      "name": "Rock_Volcanic"
    },
    {
      "x": -7,
      "y": 5,
      "z": -3,
      "name": "Rock_Volcanic_Cracked_Lava"
    },
    {
      "x": -7,
      "y": 6,
      "z": -3,
      "name": "Rock_Volcanic"
    },
    {
      "x": -7,
      "y": 7,
      "z": -3,
      "name": "Rock_Volcanic"
    },
    {
      "x": -7,
      "y": 8,
      "z": -3,
      "name": "Rock_Volcanic"
    },
    {
      "x": -7,
      "y": 9,
      "z": -3,
      "name": "Rock_Volcanic"
    },
    {
      "x": -7,
      "y": 10,
      "z": -3,
      "name": "Rock_Volcanic"
    },
    {
      "x": -7,
      "y": 11,
      "z": -3,
      "name": "Rock_Volcanic"
    },
    {
      "x": -7,
      "y": 12,
      "z": -3,
      "name": "Rock_Magma_Cooled"
    },
    {
      "x": -7,
      "y": 13,
      "z": -3,
      "name": "Rock_Magma_Cooled"
    },
    {
      "x": -7,
      "y": 0,
      "z": -2,
      "name": "Rock_Volcanic_Cracked_Lava"
    },
    {
      "x": -7,
      "y": 1,
      "z": -2,
      "name": "Rock_Volcanic"
    },
    {
      "x": -7,
      "y": 2,
      "z": -2,
      "name": "Rock_Volcanic_Cracked_Lava"
    },
    {
      "x": -7,
      "y": 3,
      "z": -2,
      "name": "Rock_Volcanic"
    },
    {
      "x": -7,
      "y": 4,
      "z": -2,
      "name": "Rock_Volcanic"
    },
    {
      "x": -7,
      "y": 5,
      "z": -2,
      "name": "Rock_Volcanic"
    },
    {
      "x": -7,
      "y": 6,
      "z": -2,
      "name": "Rock_Volcanic"
    },
    {
      "x": -7,
      "y": 7,
      "z": -2,
      "name": "Rock_Volcanic"
    },
    {
      "x": -7,
      "y": 8,
      "z": -2,
      "name": "Rock_Volcanic"
    },
    {
      "x": -7,
      "y": 9,
      "z": -2,
      "name": "Rock_Volcanic"
    },
    {
      "x": -7,
      "y": 10,
      "z": -2,
      "name": "Rock_Volcanic"
    },
    {
      "x": -7,
      "y": 11,
      "z": -2,
      "name": "Rock_Volcanic_Cracked_Lava"
    },
    {
      "x": -7,
      "y": 12,
      "z": -2,
      "name": "Ore_Adamantite_Magma_Cracked"
    },
    {
      "x": -7,
      "y": 0,
      "z": -1,
      "name": "Rock_Volcanic_Cracked_Lava"
    },
    {
      "x": -7,
      "y": 1,
      "z": -1,
      "name": "Rock_Volcanic"
    },
    {
      "x": -7,
      "y": 2,
      "z": -1,
      "name": "Rock_Volcanic"
    },
    {
      "x": -7,
      "y": 3,
      "z": -1,
      "name": "Rock_Volcanic"
    },
    {
      "x": -7,
      "y": 4,
      "z": -1,
      "name": "Rock_Volcanic"
    },
    {
      "x": -7,
      "y": 5,
      "z": -1,
      "name": "Rock_Volcanic"
    },
    {
      "x": -7,
      "y": 6,
      "z": -1,
      "name": "Rock_Volcanic"
    },
    {
      "x": -7,
      "y": 7,
      "z": -1,
      "name": "Rock_Volcanic_Cracked_Lava"
    },
    {
      "x": -7,
      "y": 8,
      "z": -1,
      "name": "Rock_Volcanic"
    },
    {
      "x": -7,
      "y": 9,
      "z": -1,
      "name": "Rock_Volcanic"
    },
    {
      "x": -7,
      "y": 10,
      "z": -1,
      "name": "Rock_Volcanic"
    },
    {
      "x": -7,
      "y": 11,
      "z": -1,
      "name": "Rock_Volcanic"
    },
    {
      "x": -7,
      "y": 12,
      "z": -1,
      "name": "Rock_Magma_Cooled"
    },
    {
      "x": -7,
      "y": 13,
      "z": -1,
      "name": "Rock_Magma_Cooled"
    },
    {
      "x": -7,
      "y": 14,
      "z": -1,
      "name": "Rock_Magma_Cooled"
    },
    {
      "x": -7,
      "y": 0,
      "z": 0,
      "name": "Rock_Volcanic"
    },
    {
      "x": -7,
      "y": 1,
      "z": 0,
      "name": "Rock_Volcanic"
    },
    {
      "x": -7,
      "y": 2,
      "z": 0,
      "name": "Rock_Volcanic"
    },
    {
      "x": -7,
      "y": 3,
      "z": 0,
      "name": "Rock_Volcanic"
    },
    {
      "x": -7,
      "y": 4,
      "z": 0,
      "name": "Rock_Volcanic"
    },
    {
      "x": -7,
      "y": 5,
      "z": 0,
      "name": "Rock_Volcanic"
    },
    {
      "x": -7,
      "y": 6,
      "z": 0,
      "name": "Rock_Volcanic"
    },
    {
      "x": -7,
      "y": 10,
      "z": 0,
      "name": "Rock_Volcanic"
    },
    {
      "x": -7,
      "y": 11,
      "z": 0,
      "name": "Rock_Magma_Cooled"
    },
    {
      "x": -7,
      "y": 12,
      "z": 0,
      "name": "Rock_Magma_Cooled"
    },
    {
      "x": -7,
      "y": 13,
      "z": 0,
      "name": "Rock_Magma_Cooled"
    },
    {
      "x": -7,
      "y": 14,
      "z": 0,
      "name": "Rock_Magma_Cooled"
    },
    {
      "x": -7,
      "y": 15,
      "z": 0,
      "name": "Ore_Adamantite_Magma_Cracked"
    },
    {
      "x": -7,
      "y": 16,
      "z": 0,
      "name": "Ore_Adamantite_Magma_Cracked"
    },
    {
      "x": -7,
      "y": 17,
      "z": 0,
      "name": "Rock_Magma_Cooled"
    },
    {
      "x": -7,
      "y": 18,
      "z": 0,
      "name": "Plant_Bramble_Dead_Lavathorn"
    },
    {
      "x": -7,
      "y": 0,
      "z": 1,
      "name": "Rock_Volcanic"
    },
    {
      "x": -7,
      "y": 1,
      "z": 1,
      "name": "Rock_Volcanic"
    },
    {
      "x": -7,
      "y": 2,
      "z": 1,
      "name": "Rock_Volcanic"
    },
    {
      "x": -7,
      "y": 3,
      "z": 1,
      "name": "Rock_Volcanic_Cracked_Lava"
    },
    {
      "x": -7,
      "y": 4,
      "z": 1,
      "name": "Rock_Volcanic"
    },
    {
      "x": -7,
      "y": 5,
      "z": 1,
      "name": "Rock_Volcanic"
    },
    {
      "x": -7,
      "y": 6,
      "z": 1,
      "name": "Rock_Volcanic_Cracked_Lava"
    },
    {
      "x": -7,
      "y": 7,
      "z": 1,
      "name": "Rock_Volcanic"
    },
    {
      "x": -7,
      "y": 9,
      "z": 1,
      "name": "Rock_Magma_Cooled_Stalactite_Large",
      "filler": 31744,
      "rotation": 8
    },
    {
      "x": -7,
      "y": 10,
      "z": 1,
      "name": "Rock_Magma_Cooled_Stalactite_Large",
      "rotation": 8
    },
    {
      "x": -7,
      "y": 11,
      "z": 1,
      "name": "Rock_Magma_Cooled"
    },
    {
      "x": -7,
      "y": 12,
      "z": 1,
      "name": "Rock_Magma_Cooled"
    },
    {
      "x": -7,
      "y": 13,
      "z": 1,
      "name": "Rock_Magma_Cooled"
    },
    {
      "x": -7,
      "y": 14,
      "z": 1,
      "name": "Rock_Magma_Cooled"
    },
    {
      "x": -7,
      "y": 15,
      "z": 1,
      "name": "Rock_Magma_Cooled"
    },
    {
      "x": -7,
      "y": 16,
      "z": 1,
      "name": "Rock_Magma_Cooled"
    },
    {
      "x": -7,
      "y": 17,
      "z": 1,
      "name": "Rock_Magma_Cooled"
    },
    {
      "x": -7,
      "y": 18,
      "z": 1,
      "name": "Rock_Magma_Cooled"
    },
    {
      "x": -7,
      "y": 19,
      "z": 1,
      "name": "Rock_Magma_Cooled"
    },
    {
      "x": -7,
      "y": 20,
      "z": 1,
      "name": "Rock_Magma_Cooled"
    },
    {
      "x": -7,
      "y": 0,
      "z": 2,
      "name": "Rock_Volcanic"
    },
    {
      "x": -7,
      "y": 1,
      "z": 2,
      "name": "Rock_Volcanic_Cracked_Lava"
    },
    {
      "x": -7,
      "y": 2,
      "z": 2,
      "name": "Rock_Volcanic_Cracked_Lava"
    },
    {
      "x": -7,
      "y": 3,
      "z": 2,
      "name": "Rock_Volcanic"
    },
    {
      "x": -7,
      "y": 4,
      "z": 2,
      "name": "Rock_Volcanic_Cracked_Lava"
    },
    {
      "x": -7,
      "y": 5,
      "z": 2,
      "name": "Rock_Volcanic"
    },
    {
      "x": -7,
      "y": 6,
      "z": 2,
      "name": "Rock_Volcanic"
    },
    {
      "x": -7,
      "y": 7,
      "z": 2,
      "name": "Rock_Volcanic"
    },
    {
      "x": -7,
      "y": 8,
      "z": 2,
      "name": "Rock_Volcanic"
    },
    {
      "x": -7,
      "y": 13,
      "z": 2,
      "name": "Rock_Magma_Cooled"
    },
    {
      "x": -7,
      "y": 14,
      "z": 2,
      "name": "Rock_Magma_Cooled"
    },
    {
      "x": -7,
      "y": 15,
      "z": 2,
      "name": "Rock_Magma_Cooled"
    },
    {
      "x": -7,
      "y": 16,
      "z": 2,
      "name": "Ore_Adamantite_Magma_Cracked"
    },
    {
      "x": -7,
      "y": 17,
      "z": 2,
      "name": "Rock_Magma_Cooled"
    },
    {
      "x": -7,
      "y": 18,
      "z": 2,
      "name": "Rock_Magma_Cooled"
    },
    {
      "x": -7,
      "y": 19,
      "z": 2,
      "name": "Rock_Magma_Cooled"
    },
    {
      "x": -7,
      "y": 20,
      "z": 2,
      "name": "Ore_Adamantite_Magma_Cracked"
    },
    {
      "x": -7,
      "y": 22,
      "z": 2,
      "name": "Ore_Adamantite_Magma_Cracked"
    },
    {
      "x": -7,
      "y": 0,
      "z": 3,
      "name": "Rock_Volcanic"
    },
    {
      "x": -7,
      "y": 1,
      "z": 3,
      "name": "Rock_Volcanic"
    },
    {
      "x": -7,
      "y": 2,
      "z": 3,
      "name": "Rock_Volcanic"
    },
    {
      "x": -7,
      "y": 3,
      "z": 3,
      "name": "Rock_Volcanic_Cracked_Lava"
    },
    {
      "x": -7,
      "y": 4,
      "z": 3,
      "name": "Rock_Volcanic"
    },
    {
      "x": -7,
      "y": 5,
      "z": 3,
      "name": "Rock_Volcanic"
    },
    {
      "x": -7,
      "y": 6,
      "z": 3,
      "name": "Rock_Volcanic"
    },
    {
      "x": -7,
      "y": 7,
      "z": 3,
      "name": "Rock_Volcanic"
    },
    {
      "x": -7,
      "y": 8,
      "z": 3,
      "name": "Rock_Volcanic"
    },
    {
      "x": -7,
      "y": 12,
      "z": 3,
      "name": "Rock_Magma_Cooled_Stalactite_Small",
      "rotation": 8
    },
    {
      "x": -7,
      "y": 13,
      "z": 3,
      "name": "Rock_Magma_Cooled"
    },
    {
      "x": -7,
      "y": 14,
      "z": 3,
      "name": "Rock_Magma_Cooled"
    },
    {
      "x": -7,
      "y": 15,
      "z": 3,
      "name": "Rock_Magma_Cooled"
    },
    {
      "x": -7,
      "y": 16,
      "z": 3,
      "name": "Ore_Adamantite_Magma_Cracked"
    },
    {
      "x": -7,
      "y": 17,
      "z": 3,
      "name": "Rock_Magma_Cooled"
    },
    {
      "x": -7,
      "y": 18,
      "z": 3,
      "name": "Rock_Magma_Cooled"
    },
    {
      "x": -7,
      "y": 19,
      "z": 3,
      "name": "Rock_Magma_Cooled"
    },
    {
      "x": -7,
      "y": 20,
      "z": 3,
      "name": "Rock_Magma_Cooled"
    },
    {
      "x": -7,
      "y": 21,
      "z": 3,
      "name": "Rock_Magma_Cooled"
    },
    {
      "x": -7,
      "y": 22,
      "z": 3,
      "name": "Plant_Bramble_Dead_Lavathorn"
    },
    {
      "x": -7,
      "y": 0,
      "z": 4,
      "name": "Rock_Volcanic"
    },
    {
      "x": -7,
      "y": 1,
      "z": 4,
      "name": "Rock_Volcanic"
    },
    {
      "x": -7,
      "y": 2,
      "z": 4,
      "name": "Rock_Volcanic"
    },
    {
      "x": -7,
      "y": 3,
      "z": 4,
      "name": "Rock_Volcanic"
    },
    {
      "x": -7,
      "y": 4,
      "z": 4,
      "name": "Rock_Volcanic"
    },
    {
      "x": -7,
      "y": 5,
      "z": 4,
      "name": "Rock_Volcanic"
    },
    {
      "x": -7,
      "y": 6,
      "z": 4,
      "name": "Rock_Volcanic"
    },
    {
      "x": -7,
      "y": 7,
      "z": 4,
      "name": "Rock_Volcanic"
    },
    {
      "x": -7,
      "y": 8,
      "z": 4,
      "name": "Rock_Volcanic_Cracked_Lava"
    },
    {
      "x": -7,
      "y": 0,
      "z": 5,
      "name": "Rock_Volcanic"
    },
    {
      "x": -7,
      "y": 1,
      "z": 5,
      "name": "Rock_Volcanic_Cracked_Lava"
    },
    {
      "x": -7,
      "y": 2,
      "z": 5,
      "name": "Rock_Volcanic"
    },
    {
      "x": -7,
      "y": 3,
      "z": 5,
      "name": "Rock_Volcanic_Cracked_Lava"
    },
    {
      "x": -7,
      "y": 4,
      "z": 5,
      "name": "Rock_Volcanic"
    },
    {
      "x": -7,
      "y": 5,
      "z": 5,
      "name": "Rock_Volcanic"
    },
    {
      "x": -7,
      "y": 6,
      "z": 5,
      "name": "Rock_Volcanic"
    },
    {
      "x": -7,
      "y": 7,
      "z": 5,
      "name": "Rock_Volcanic"
    },
    {
      "x": -7,
      "y": 8,
      "z": 5,
      "name": "Rock_Volcanic"
    },
    {
      "x": -7,
      "y": 0,
      "z": 6,
      "name": "Rock_Volcanic"
    },
    {
      "x": -7,
      "y": 1,
      "z": 6,
      "name": "Rock_Volcanic"
    },
    {
      "x": -7,
      "y": 2,
      "z": 6,
      "name": "Rock_Volcanic"
    },
    {
      "x": -7,
      "y": 3,
      "z": 6,
      "name": "Rock_Volcanic_Cracked_Lava"
    },
    {
      "x": -7,
      "y": 4,
      "z": 6,
      "name": "Rock_Volcanic"
    },
    {
      "x": -7,
      "y": 5,
      "z": 6,
      "name": "Rock_Volcanic"
    },
    {
      "x": -7,
      "y": 6,
      "z": 6,
      "name": "Rock_Volcanic"
    },
    {
      "x": -7,
      "y": 0,
      "z": 7,
      "name": "Rock_Volcanic"
    },
    {
      "x": -7,
      "y": 1,
      "z": 7,
      "name": "Rock_Volcanic"
    },
    {
      "x": -7,
      "y": 2,
      "z": 7,
      "name": "Rock_Volcanic"
    },
    {
      "x": -7,
      "y": 3,
      "z": 7,
      "name": "Rock_Volcanic"
    },
    {
      "x": -7,
      "y": 4,
      "z": 7,
      "name": "Rock_Volcanic"
    },
    {
      "x": -7,
      "y": 5,
      "z": 7,
      "name": "Rock_Volcanic"
    },
    {
      "x": -7,
      "y": 6,
      "z": 7,
      "name": "Rock_Volcanic_Cracked_Lava"
    },
    {
      "x": -7,
      "y": 0,
      "z": 8,
      "name": "Rock_Volcanic"
    },
    {
      "x": -7,
      "y": 1,
      "z": 8,
      "name": "Rock_Volcanic_Cracked_Lava"
    },
    {
      "x": -7,
      "y": 2,
      "z": 8,
      "name": "Rock_Volcanic"
    },
    {
      "x": -7,
      "y": 3,
      "z": 8,
      "name": "Rock_Volcanic"
    },
    {
      "x": -7,
      "y": 4,
      "z": 8,
      "name": "Rock_Volcanic"
    },
    {
      "x": -7,
      "y": 5,
      "z": 8,
      "name": "Rock_Volcanic"
    },
    {
      "x": -7,
      "y": 0,
      "z": 9,
      "name": "Rock_Volcanic_Cracked_Lava"
    },
    {
      "x": -7,
      "y": 1,
      "z": 9,
      "name": "Rock_Volcanic"
    },
    {
      "x": -7,
      "y": 2,
      "z": 9,
      "name": "Rock_Volcanic"
    },
    {
      "x": -7,
      "y": 3,
      "z": 9,
      "name": "Rock_Volcanic_Cracked_Lava"
    },
    {
      "x": -7,
      "y": 4,
      "z": 9,
      "name": "Rock_Volcanic_Cracked_Lava"
    },
    {
      "x": -7,
      "y": 5,
      "z": 9,
      "name": "Rock_Volcanic"
    },
    {
      "x": -7,
      "y": 0,
      "z": 10,
      "name": "Rock_Volcanic"
    },
    {
      "x": -7,
      "y": 1,
      "z": 10,
      "name": "Rock_Volcanic"
    },
    {
      "x": -7,
      "y": 2,
      "z": 10,
      "name": "Rock_Volcanic"
    },
    {
      "x": -7,
      "y": 3,
      "z": 10,
      "name": "Rock_Volcanic"
    },
    {
      "x": -7,
      "y": 4,
      "z": 10,
      "name": "Rock_Volcanic"
    },
    {
      "x": -7,
      "y": 5,
      "z": 10,
      "name": "Rock_Volcanic"
    },
    {
      "x": -7,
      "y": 6,
      "z": 10,
      "name": "Rock_Volcanic_Stalactite_Large"
    },
    {
      "x": -7,
      "y": 7,
      "z": 10,
      "name": "Rock_Volcanic_Stalactite_Large",
      "filler": 1024
    },
    {
      "x": -7,
      "y": 0,
      "z": 11,
      "name": "Rock_Volcanic"
    },
    {
      "x": -7,
      "y": 1,
      "z": 11,
      "name": "Rock_Volcanic"
    },
    {
      "x": -7,
      "y": 2,
      "z": 11,
      "name": "Rock_Volcanic"
    },
    {
      "x": -7,
      "y": 3,
      "z": 11,
      "name": "Rock_Volcanic"
    },
    {
      "x": -7,
      "y": 4,
      "z": 11,
      "name": "Rock_Volcanic"
    },
    {
      "x": -7,
      "y": 0,
      "z": 12,
      "name": "Rock_Volcanic"
    },
    {
      "x": -7,
      "y": 1,
      "z": 12,
      "name": "Rock_Volcanic"
    },
    {
      "x": -7,
      "y": 2,
      "z": 12,
      "name": "Rock_Volcanic"
    },
    {
      "x": -7,
      "y": 3,
      "z": 12,
      "name": "Rock_Volcanic"
    },
    {
      "x": -7,
      "y": 4,
      "z": 12,
      "name": "Rock_Volcanic_Cracked_Lava"
    },
    {
      "x": -7,
      "y": 0,
      "z": 13,
      "name": "Rock_Volcanic"
    },
    {
      "x": -7,
      "y": 1,
      "z": 13,
      "name": "Rock_Volcanic"
    },
    {
      "x": -7,
      "y": 2,
      "z": 13,
      "name": "Rock_Volcanic"
    },
    {
      "x": -7,
      "y": 3,
      "z": 13,
      "name": "Rock_Volcanic"
    },
    {
      "x": -7,
      "y": 4,
      "z": 13,
      "name": "Rock_Volcanic"
    },
    {
      "x": -7,
      "y": 0,
      "z": 14,
      "name": "Rock_Volcanic"
    },
    {
      "x": -7,
      "y": 1,
      "z": 14,
      "name": "Rock_Volcanic"
    },
    {
      "x": -7,
      "y": 2,
      "z": 14,
      "name": "Rock_Volcanic"
    },
    {
      "x": -7,
      "y": 3,
      "z": 14,
      "name": "Rock_Volcanic"
    },
    {
      "x": -7,
      "y": 4,
      "z": 14,
      "name": "Rock_Volcanic"
    },
    {
      "x": -7,
      "y": 0,
      "z": 15,
      "name": "Rock_Volcanic"
    },
    {
      "x": -7,
      "y": 1,
      "z": 15,
      "name": "Rock_Volcanic"
    },
    {
      "x": -7,
      "y": 2,
      "z": 15,
      "name": "Rock_Volcanic"
    },
    {
      "x": -7,
      "y": 3,
      "z": 15,
      "name": "Rock_Volcanic"
    },
    {
      "x": -7,
      "y": 0,
      "z": 16,
      "name": "Rock_Volcanic"
    },
    {
      "x": -7,
      "y": 0,
      "z": 17,
      "name": "Rock_Volcanic"
    },
    {
      "x": -6,
      "y": 0,
      "z": -15,
      "name": "Rock_Volcanic"
    },
    {
      "x": -6,
      "y": 1,
      "z": -15,
      "name": "Rock_Volcanic"
    },
    {
      "x": -6,
      "y": 2,
      "z": -15,
      "name": "Rock_Volcanic"
    },
    {
      "x": -6,
      "y": 3,
      "z": -15,
      "name": "Rock_Volcanic"
    },
    {
      "x": -6,
      "y": 0,
      "z": -14,
      "name": "Rock_Volcanic"
    },
    {
      "x": -6,
      "y": 1,
      "z": -14,
      "name": "Rock_Volcanic"
    },
    {
      "x": -6,
      "y": 2,
      "z": -14,
      "name": "Rock_Volcanic"
    },
    {
      "x": -6,
      "y": 3,
      "z": -14,
      "name": "Rock_Volcanic"
    },
    {
      "x": -6,
      "y": 4,
      "z": -14,
      "name": "Rock_Volcanic"
    },
    {
      "x": -6,
      "y": 0,
      "z": -13,
      "name": "Rock_Volcanic_Cracked_Lava"
    },
    {
      "x": -6,
      "y": 1,
      "z": -13,
      "name": "Rock_Volcanic"
    },
    {
      "x": -6,
      "y": 2,
      "z": -13,
      "name": "Rock_Volcanic"
    },
    {
      "x": -6,
      "y": 3,
      "z": -13,
      "name": "Rock_Volcanic_Cracked_Lava"
    },
    {
      "x": -6,
      "y": 4,
      "z": -13,
      "name": "Rock_Volcanic_Cracked_Lava"
    },
    {
      "x": -6,
      "y": 5,
      "z": -13,
      "name": "Rock_Volcanic_Stalactite_Small"
    },
    {
      "x": -6,
      "y": 0,
      "z": -12,
      "name": "Rock_Volcanic"
    },
    {
      "x": -6,
      "y": 1,
      "z": -12,
      "name": "Rock_Volcanic"
    },
    {
      "x": -6,
      "y": 2,
      "z": -12,
      "name": "Rock_Volcanic"
    },
    {
      "x": -6,
      "y": 3,
      "z": -12,
      "name": "Rock_Volcanic_Cracked_Lava"
    },
    {
      "x": -6,
      "y": 4,
      "z": -12,
      "name": "Rock_Volcanic"
    },
    {
      "x": -6,
      "y": 5,
      "z": -12,
      "name": "Plant_Bramble_Dead_Lavathorn"
    },
    {
      "x": -6,
      "y": 0,
      "z": -11,
      "name": "Rock_Volcanic"
    },
    {
      "x": -6,
      "y": 1,
      "z": -11,
      "name": "Rock_Volcanic"
    },
    {
      "x": -6,
      "y": 2,
      "z": -11,
      "name": "Rock_Volcanic"
    },
    {
      "x": -6,
      "y": 3,
      "z": -11,
      "name": "Rock_Volcanic"
    },
    {
      "x": -6,
      "y": 4,
      "z": -11,
      "name": "Rock_Volcanic"
    },
    {
      "x": -6,
      "y": 0,
      "z": -10,
      "name": "Rock_Volcanic"
    },
    {
      "x": -6,
      "y": 1,
      "z": -10,
      "name": "Rock_Volcanic"
    },
    {
      "x": -6,
      "y": 2,
      "z": -10,
      "name": "Rock_Volcanic"
    },
    {
      "x": -6,
      "y": 0,
      "z": -9,
      "name": "Rock_Volcanic"
    },
    {
      "x": -6,
      "y": 1,
      "z": -9,
      "name": "Rock_Volcanic"
    },
    {
      "x": -6,
      "y": 2,
      "z": -9,
      "name": "Rock_Volcanic_Cracked_Lava"
    },
    {
      "x": -6,
      "y": 0,
      "z": -8,
      "name": "Rock_Volcanic"
    },
    {
      "x": -6,
      "y": 1,
      "z": -8,
      "name": "Rock_Volcanic"
    },
    {
      "x": -6,
      "y": 2,
      "z": -8,
      "name": "Rock_Volcanic"
    },
    {
      "x": -6,
      "y": 0,
      "z": -7,
      "name": "Rock_Volcanic"
    },
    {
      "x": -6,
      "y": 1,
      "z": -7,
      "name": "Rock_Volcanic"
    },
    {
      "x": -6,
      "y": 2,
      "z": -7,
      "name": "Rock_Volcanic"
    },
    {
      "x": -6,
      "y": 3,
      "z": -7,
      "name": "Rock_Volcanic"
    },
    {
      "x": -6,
      "y": 4,
      "z": -7,
      "name": "Rock_Volcanic"
    },
    {
      "x": -6,
      "y": 5,
      "z": -7,
      "name": "Rock_Volcanic"
    },
    {
      "x": -6,
      "y": 0,
      "z": -6,
      "name": "Rock_Volcanic"
    },
    {
      "x": -6,
      "y": 1,
      "z": -6,
      "name": "Rock_Volcanic"
    },
    {
      "x": -6,
      "y": 2,
      "z": -6,
      "name": "Rock_Volcanic_Cracked_Lava"
    },
    {
      "x": -6,
      "y": 3,
      "z": -6,
      "name": "Rock_Volcanic"
    },
    {
      "x": -6,
      "y": 4,
      "z": -6,
      "name": "Rock_Volcanic"
    },
    {
      "x": -6,
      "y": 5,
      "z": -6,
      "name": "Rock_Volcanic"
    },
    {
      "x": -6,
      "y": 6,
      "z": -6,
      "name": "Rock_Volcanic"
    },
    {
      "x": -6,
      "y": 0,
      "z": -5,
      "name": "Rock_Volcanic"
    },
    {
      "x": -6,
      "y": 1,
      "z": -5,
      "name": "Rock_Volcanic"
    },
    {
      "x": -6,
      "y": 2,
      "z": -5,
      "name": "Rock_Volcanic"
    },
    {
      "x": -6,
      "y": 3,
      "z": -5,
      "name": "Rock_Volcanic"
    },
    {
      "x": -6,
      "y": 4,
      "z": -5,
      "name": "Rock_Volcanic"
    },
    {
      "x": -6,
      "y": 5,
      "z": -5,
      "name": "Rock_Volcanic"
    },
    {
      "x": -6,
      "y": 6,
      "z": -5,
      "name": "Rock_Volcanic"
    },
    {
      "x": -6,
      "y": 11,
      "z": -5,
      "name": "Rock_Volcanic"
    },
    {
      "x": -6,
      "y": 12,
      "z": -5,
      "name": "Rock_Magma_Cooled"
    },
    {
      "x": -6,
      "y": 13,
      "z": -5,
      "name": "Ore_Adamantite_Magma_Cracked"
    },
    {
      "x": -6,
      "y": 0,
      "z": -4,
      "name": "Rock_Volcanic"
    },
    {
      "x": -6,
      "y": 1,
      "z": -4,
      "name": "Rock_Volcanic"
    },
    {
      "x": -6,
      "y": 2,
      "z": -4,
      "name": "Rock_Volcanic"
    },
    {
      "x": -6,
      "y": 3,
      "z": -4,
      "name": "Rock_Volcanic"
    },
    {
      "x": -6,
      "y": 4,
      "z": -4,
      "name": "Rock_Volcanic"
    },
    {
      "x": -6,
      "y": 5,
      "z": -4,
      "name": "Rock_Volcanic"
    },
    {
      "x": -6,
      "y": 6,
      "z": -4,
      "name": "Rock_Volcanic_Cracked_Lava"
    },
    {
      "x": -6,
      "y": 7,
      "z": -4,
      "name": "Rock_Volcanic"
    },
    {
      "x": -6,
      "y": 8,
      "z": -4,
      "name": "Rock_Volcanic"
    },
    {
      "x": -6,
      "y": 9,
      "z": -4,
      "name": "Rock_Volcanic"
    },
    {
      "x": -6,
      "y": 10,
      "z": -4,
      "name": "Rock_Volcanic"
    },
    {
      "x": -6,
      "y": 11,
      "z": -4,
      "name": "Rock_Volcanic_Cracked_Lava"
    },
    {
      "x": -6,
      "y": 12,
      "z": -4,
      "name": "Ore_Adamantite_Magma_Cracked"
    },
    {
      "x": -6,
      "y": 13,
      "z": -4,
      "name": "Rock_Magma_Cooled"
    },
    {
      "x": -6,
      "y": 14,
      "z": -4,
      "name": "Rock_Magma_Cooled"
    },
    {
