{
  "version": 8,
  "blockIdVersion": 11,
  "anchorX": 0,
  "anchorY": 0,
  "anchorZ": 0,
  "blocks": [
    {
      "x": -23,
      "y": 103,
      "z": 2,
      "name": "Plant_Leaves_Azure",
      "rotation": 2
    },
    {
      "x": -23,
      "y": 102,
      "z": 3,
      "name": "Plant_Leaves_Azure",
      "rotation": 2
    },
    {
      "x": -23,
      "y": 103,
      "z": 3,
      "name": "Plant_Leaves_Azure",
      "rotation": 2
    },
    {
      "x": -23,
      "y": 104,
      "z": 3,
      "name": "Plant_Leaves_Azure",
      "rotation": 2
    },
    {
      "x": -23,
      "y": 102,
      "z": 4,
      "name": "Plant_Leaves_Azure",
      "rotation": 2
    },
    {
      "x": -23,
      "y": 103,
      "z": 4,
      "name": "Plant_Leaves_Azure",
      "rotation": 2
    },
    {
      "x": -23,
      "y": 104,
      "z": 4,
      "name": "Plant_Leaves_Azure",
      "rotation": 2
    },
    {
      "x": -23,
      "y": 105,
      "z": 4,
      "name": "Plant_Leaves_Azure",
      "rotation": 2
    },
    {
      "x": -23,
      "y": 102,
      "z": 5,
      "name": "Plant_Leaves_Azure",
      "rotation": 2
    },
    {
      "x": -23,
      "y": 103,
      "z": 5,
      "name": "Plant_Leaves_Azure",
      "rotation": 2
    },
    {
      "x": -23,
      "y": 104,
      "z": 5,
      "name": "Plant_Leaves_Azure",
      "rotation": 2
    },
    {
      "x": -23,
      "y": 94,
      "z": 9,
      "name": "Plant_Moss_Wall_Blue",
      "support": 15,
      "rotation": 3
    },
    {
      "x": -22,
      "y": 95,
      "z": -6,
      "name": "Plant_Moss_Block_Blue"
    },
    {
      "x": -22,
      "y": 96,
      "z": -6,
      "name": "Plant_Moss_Block_Blue"
    },
    {
      "x": -22,
      "y": 97,
      "z": -6,
      "name": "Plant_Moss_Short_Green_Dark"
    },
    {
      "x": -22,
      "y": 93,
      "z": -5,
      "name": "Plant_Moss_Wall_Blue",
      "support": 15,
      "rotation": 3
    },
    {
      "x": -22,
      "y": 95,
      "z": -5,
      "name": "Rock_Marble"
    },
    {
      "x": -22,
      "y": 96,
      "z": -5,
      "name": "Plant_Moss_Block_Blue"
    },
    {
      "x": -22,
      "y": 97,
      "z": -5,
      "name": "Plant_Moss_Block_Blue"
    },
    {
      "x": -22,
      "y": 98,
      "z": -5,
      "name": "Plant_Moss_Rug_Lime"
    },
    {
      "x": -22,
      "y": 93,
      "z": -4,
      "name": "Plant_Moss_Wall_Blue",
      "support": 15,
      "rotation": 3
    },
    {
      "x": -22,
      "y": 94,
      "z": -4,
      "name": "Rock_Marble"
    },
    {
      "x": -22,
      "y": 95,
      "z": -4,
      "name": "Rock_Marble"
    },
    {
      "x": -22,
      "y": 96,
      "z": -4,
      "name": "Plant_Moss_Block_Blue"
    },
    {
      "x": -22,
      "y": 97,
      "z": -4,
      "name": "Plant_Moss_Block_Blue"
    },
    {
      "x": -22,
      "y": 98,
      "z": -4,
      "name": "Plant_Moss_Blue"
    },
    {
      "x": -22,
      "y": 93,
      "z": -3,
      "name": "Plant_Moss_Wall_Blue",
      "support": 15,
      "rotation": 3
    },
    {
      "x": -22,
      "y": 95,
      "z": -3,
      "name": "Plant_Moss_Block_Blue"
    },
    {
      "x": -22,
      "y": 96,
      "z": -3,
      "name": "Plant_Moss_Block_Blue"
    },
    {
      "x": -22,
      "y": 97,
      "z": -3,
      "name": "Plant_Moss_Rug_Lime"
    },
    {
      "x": -22,
      "y": 93,
      "z": -2,
      "name": "Plant_Moss_Wall_Blue",
      "support": 15,
      "rotation": 3
    },
    {
      "x": -22,
      "y": 95,
      "z": -2,
      "name": "Plant_Moss_Block_Blue"
    },
    {
      "x": -22,
      "y": 96,
      "z": -2,
      "name": "Plant_Moss_Block_Blue"
    },
    {
      "x": -22,
      "y": 97,
      "z": -2,
      "name": "Plant_Moss_Rug_Blue"
    },
    {
      "x": -22,
      "y": 106,
      "z": 1,
      "name": "Plant_Leaves_Azure",
      "rotation": 2
    },
    {
      "x": -22,
      "y": 107,
      "z": 1,
      "name": "Plant_Leaves_Azure",
      "rotation": 2
    },
    {
      "x": -22,
      "y": 108,
      "z": 1,
      "name": "Plant_Leaves_Azure",
      "rotation": 2
    },
    {
      "x": -22,
      "y": 94,
      "z": 2,
      "name": "Plant_Moss_Wall_Blue",
      "support": 15,
      "rotation": 3
    },
    {
      "x": -22,
      "y": 102,
      "z": 2,
      "name": "Plant_Leaves_Azure",
      "rotation": 2
    },
    {
      "x": -22,
      "y": 103,
      "z": 2,
      "name": "Plant_Leaves_Azure",
      "rotation": 2
    },
    {
      "x": -22,
      "y": 104,
      "z": 2,
      "name": "Plant_Leaves_Azure",
      "rotation": 2
    },
    {
      "x": -22,
      "y": 106,
      "z": 2,
      "name": "Plant_Leaves_Azure",
      "rotation": 2
    },
    {
      "x": -22,
      "y": 107,
      "z": 2,
      "name": "Plant_Leaves_Azure",
      "rotation": 2
    },
    {
      "x": -22,
      "y": 108,
      "z": 2,
      "name": "Plant_Leaves_Azure",
      "rotation": 2
    },
    {
      "x": -22,
      "y": 109,
      "z": 2,
      "name": "Plant_Leaves_Azure",
      "rotation": 2
    },
    {
      "x": -22,
      "y": 94,
      "z": 3,
      "name": "Plant_Moss_Wall_Blue",
      "support": 15,
      "rotation": 3
    },
    {
      "x": -22,
      "y": 102,
      "z": 3,
      "name": "Plant_Leaves_Azure",
      "rotation": 2
    },
    {
      "x": -22,
      "y": 103,
      "z": 3,
      "name": "Plant_Leaves_Azure",
      "rotation": 2
    },
    {
      "x": -22,
      "y": 104,
      "z": 3,
      "name": "Wood_Azure_Branch_Long",
      "rotation": 7
    },
    {
      "x": -22,
      "y": 105,
      "z": 3,
      "name": "Plant_Leaves_Azure",
      "rotation": 2
    },
    {
      "x": -22,
      "y": 107,
      "z": 3,
      "name": "Plant_Leaves_Azure",
      "rotation": 2
    },
    {
      "x": -22,
      "y": 108,
      "z": 3,
      "name": "Plant_Leaves_Azure",
      "rotation": 2
    },
    {
      "x": -22,
      "y": 109,
      "z": 3,
      "name": "Plant_Leaves_Azure",
      "rotation": 2
    },
    {
      "x": -22,
      "y": 110,
      "z": 3,
      "name": "Plant_Leaves_Azure",
      "rotation": 2
    },
    {
      "x": -22,
      "y": 94,
      "z": 4,
      "name": "Plant_Moss_Wall_Blue",
      "support": 15,
      "rotation": 3
    },
    {
      "x": -22,
      "y": 102,
      "z": 4,
      "name": "Plant_Leaves_Azure",
      "rotation": 2
    },
    {
      "x": -22,
      "y": 103,
      "z": 4,
      "name": "Plant_Leaves_Azure",
      "rotation": 2
    },
    {
      "x": -22,
      "y": 104,
      "z": 4,
      "name": "Plant_Leaves_Azure",
      "rotation": 2
    },
    {
      "x": -22,
      "y": 105,
      "z": 4,
      "name": "Plant_Leaves_Azure",
      "rotation": 2
    },
    {
      "x": -22,
      "y": 106,
      "z": 4,
      "name": "Plant_Fruit_Azure",
      "rotation": 2
    },
    {
      "x": -22,
      "y": 108,
      "z": 4,
      "name": "Plant_Leaves_Azure",
      "rotation": 2
    },
    {
      "x": -22,
      "y": 109,
      "z": 4,
      "name": "Plant_Leaves_Azure",
      "rotation": 2
    },
    {
      "x": -22,
      "y": 110,
      "z": 4,
      "name": "Plant_Leaves_Azure",
      "rotation": 2
    },
    {
      "x": -22,
      "y": 103,
      "z": 5,
      "name": "Plant_Leaves_Azure",
      "rotation": 2
    },
    {
      "x": -22,
      "y": 104,
      "z": 5,
      "name": "Plant_Leaves_Azure",
      "rotation": 2
    },
    {
      "x": -22,
      "y": 105,
      "z": 5,
      "name": "Plant_Leaves_Azure",
      "rotation": 2
    },
    {
      "x": -22,
      "y": 106,
      "z": 5,
      "name": "Plant_Leaves_Azure",
      "rotation": 2
    },
    {
      "x": -22,
      "y": 103,
      "z": 6,
      "name": "Plant_Leaves_Azure",
      "rotation": 2
    },
    {
      "x": -22,
      "y": 104,
      "z": 6,
      "name": "Plant_Leaves_Azure",
      "rotation": 2
    },
    {
      "x": -22,
      "y": 105,
      "z": 6,
      "name": "Plant_Leaves_Azure",
      "rotation": 2
    },
    {
      "x": -22,
      "y": 106,
      "z": 6,
      "name": "Plant_Leaves_Azure",
      "rotation": 2
    },
    {
      "x": -22,
      "y": 103,
      "z": 7,
      "name": "Plant_Leaves_Azure",
      "rotation": 2
    },
    {
      "x": -22,
      "y": 104,
      "z": 7,
      "name": "Plant_Leaves_Azure",
      "rotation": 2
    },
    {
      "x": -22,
      "y": 105,
      "z": 7,
      "name": "Plant_Leaves_Azure",
      "rotation": 2
    },
    {
      "x": -22,
      "y": 93,
      "z": 9,
      "name": "Plant_Moss_Wall_Blue",
      "support": 15,
      "rotation": 3
    },
    {
      "x": -22,
      "y": 94,
      "z": 9,
      "name": "Plant_Moss_Block_Blue"
    },
    {
      "x": -22,
      "y": 95,
      "z": 9,
      "name": "Plant_Moss_Block_Blue"
    },
    {
      "x": -22,
      "y": 96,
      "z": 9,
      "name": "Plant_Moss_Short_Green_Dark"
    },
    {
      "x": -21,
      "y": 97,
      "z": -8,
      "name": "Plant_Moss_Rug_Lime"
    },
    {
      "x": -21,
      "y": 95,
      "z": -7,
      "name": "Rock_Marble"
    },
    {
      "x": -21,
      "y": 96,
      "z": -7,
      "name": "Rock_Marble"
    },
    {
      "x": -21,
      "y": 97,
      "z": -7,
      "name": "Plant_Moss_Block_Blue"
    },
    {
      "x": -21,
      "y": 98,
      "z": -7,
      "name": "Plant_Moss_Block_Blue"
    },
    {
      "x": -21,
      "y": 99,
      "z": -7,
      "name": "Plant_Moss_Rug_Blue"
    },
    {
      "x": -21,
      "y": 93,
      "z": -6,
      "name": "Rock_Marble"
    },
    {
      "x": -21,
      "y": 94,
      "z": -6,
      "name": "Rock_Marble"
    },
    {
      "x": -21,
      "y": 95,
      "z": -6,
      "name": "Rock_Marble"
    },
    {
      "x": -21,
      "y": 96,
      "z": -6,
      "name": "Plant_Moss_Block_Blue"
    },
    {
      "x": -21,
      "y": 97,
      "z": -6,
      "name": "Plant_Moss_Block_Blue"
    },
    {
      "x": -21,
      "y": 98,
      "z": -6,
      "name": "Plant_Moss_Rug_Lime"
    },
    {
      "x": -21,
      "y": 93,
      "z": -5,
      "name": "Rock_Marble"
    },
    {
      "x": -21,
      "y": 94,
      "z": -5,
      "name": "Rock_Marble"
    },
    {
      "x": -21,
      "y": 95,
      "z": -5,
      "name": "Rock_Marble"
    },
    {
      "x": -21,
      "y": 96,
      "z": -5,
      "name": "Plant_Moss_Block_Blue"
    },
    {
      "x": -21,
      "y": 97,
      "z": -5,
      "name": "Plant_Moss_Block_Blue"
    },
    {
      "x": -21,
      "y": 98,
      "z": -5,
      "name": "Plant_Moss_Short_Green_Dark"
    },
    {
      "x": -21,
      "y": 92,
      "z": -4,
      "name": "Rock_Marble"
    },
    {
      "x": -21,
      "y": 93,
      "z": -4,
      "name": "Rock_Marble"
    },
    {
      "x": -21,
      "y": 94,
      "z": -4,
      "name": "Rock_Marble"
    },
    {
      "x": -21,
      "y": 95,
      "z": -4,
      "name": "Rock_Marble"
    },
    {
      "x": -21,
      "y": 96,
      "z": -4,
      "name": "Plant_Moss_Block_Blue"
    },
    {
      "x": -21,
      "y": 97,
      "z": -4,
      "name": "Plant_Moss_Block_Blue"
    },
    {
      "x": -21,
      "y": 98,
      "z": -4,
      "name": "Plant_Moss_Blue"
    },
    {
      "x": -21,
      "y": 93,
      "z": -3,
      "name": "Rock_Marble"
    },
    {
      "x": -21,
      "y": 94,
      "z": -3,
      "name": "Rock_Marble"
    },
    {
      "x": -21,
      "y": 95,
      "z": -3,
      "name": "Rock_Marble"
    },
    {
      "x": -21,
      "y": 96,
      "z": -3,
      "name": "Plant_Moss_Block_Blue"
    },
    {
      "x": -21,
      "y": 97,
      "z": -3,
      "name": "Plant_Moss_Block_Blue"
    },
    {
      "x": -21,
      "y": 98,
      "z": -3,
      "name": "Plant_Moss_Blue"
    },
    {
      "x": -21,
      "y": 93,
      "z": -2,
      "name": "Rock_Marble"
    },
    {
      "x": -21,
      "y": 94,
      "z": -2,
      "name": "Rock_Marble"
    },
    {
      "x": -21,
      "y": 95,
      "z": -2,
      "name": "Rock_Marble"
    },
    {
      "x": -21,
      "y": 96,
      "z": -2,
      "name": "Plant_Moss_Block_Blue"
    },
    {
      "x": -21,
      "y": 97,
      "z": -2,
      "name": "Plant_Moss_Block_Blue"
    },
    {
      "x": -21,
      "y": 98,
      "z": -2,
      "name": "Plant_Moss_Short_Green_Dark"
    },
    {
      "x": -21,
      "y": 93,
      "z": -1,
      "name": "Rock_Marble"
    },
    {
      "x": -21,
      "y": 94,
      "z": -1,
      "name": "Rock_Marble"
    },
    {
      "x": -21,
      "y": 95,
      "z": -1,
      "name": "Plant_Moss_Block_Blue"
    },
    {
      "x": -21,
      "y": 96,
      "z": -1,
      "name": "Plant_Moss_Block_Blue"
    },
    {
      "x": -21,
      "y": 97,
      "z": -1,
      "name": "Plant_Moss_Short_Green_Dark"
    },
    {
      "x": -21,
      "y": 106,
      "z": -1,
      "name": "Plant_Leaves_Azure",
      "rotation": 2
    },
    {
      "x": -21,
      "y": 107,
      "z": -1,
      "name": "Plant_Leaves_Azure",
      "rotation": 2
    },
    {
      "x": -21,
      "y": 108,
      "z": -1,
      "name": "Plant_Leaves_Azure",
      "rotation": 2
    },
    {
      "x": -21,
      "y": 93,
      "z": 0,
      "name": "Plant_Moss_Wall_Blue",
      "support": 15,
      "rotation": 3
    },
    {
      "x": -21,
      "y": 94,
      "z": 0,
      "name": "Rock_Marble"
    },
    {
      "x": -21,
      "y": 95,
      "z": 0,
      "name": "Rock_Marble"
    },
    {
      "x": -21,
      "y": 96,
      "z": 0,
      "name": "Rock_Marble"
    },
    {
      "x": -21,
      "y": 97,
      "z": 0,
      "name": "Plant_Moss_Block_Blue"
    },
    {
      "x": -21,
      "y": 98,
      "z": 0,
      "name": "Plant_Moss_Block_Blue"
    },
    {
      "x": -21,
      "y": 99,
      "z": 0,
      "name": "Plant_Moss_Rug_Blue"
    },
    {
      "x": -21,
      "y": 105,
      "z": 0,
      "name": "Plant_Leaves_Azure",
      "rotation": 2
    },
    {
      "x": -21,
      "y": 106,
      "z": 0,
      "name": "Plant_Leaves_Azure",
      "rotation": 2
    },
    {
      "x": -21,
      "y": 107,
      "z": 0,
      "name": "Plant_Leaves_Azure",
      "rotation": 2
    },
    {
      "x": -21,
      "y": 108,
      "z": 0,
      "name": "Plant_Leaves_Azure",
      "rotation": 2
    },
    {
      "x": -21,
      "y": 109,
      "z": 0,
      "name": "Plant_Leaves_Azure",
      "rotation": 2
    },
    {
      "x": -21,
      "y": 110,
      "z": 0,
      "name": "Plant_Fruit_Azure",
      "rotation": 2
    },
    {
      "x": -21,
      "y": 93,
      "z": 1,
      "name": "Plant_Moss_Wall_Blue",
      "support": 15,
      "rotation": 3
    },
    {
      "x": -21,
      "y": 94,
      "z": 1,
      "name": "Rock_Marble"
    },
    {
      "x": -21,
      "y": 95,
      "z": 1,
      "name": "Rock_Marble"
    },
    {
      "x": -21,
      "y": 96,
      "z": 1,
      "name": "Plant_Moss_Block_Blue"
    },
    {
      "x": -21,
      "y": 97,
      "z": 1,
      "name": "Plant_Moss_Block_Blue"
    },
    {
      "x": -21,
      "y": 98,
      "z": 1,
      "name": "Plant_Moss_Rug_Lime"
    },
    {
      "x": -21,
      "y": 107,
      "z": 1,
      "name": "Plant_Leaves_Azure",
      "rotation": 2
    },
    {
      "x": -21,
      "y": 108,
      "z": 1,
      "name": "Plant_Leaves_Azure",
      "rotation": 2
    },
    {
      "x": -21,
      "y": 109,
      "z": 1,
      "name": "Plant_Leaves_Azure",
      "rotation": 2
    },
    {
      "x": -21,
      "y": 93,
      "z": 2,
      "name": "Rock_Marble"
    },
    {
      "x": -21,
      "y": 94,
      "z": 2,
      "name": "Rock_Marble"
    },
    {
      "x": -21,
      "y": 95,
      "z": 2,
      "name": "Plant_Moss_Block_Blue"
    },
    {
      "x": -21,
      "y": 96,
      "z": 2,
      "name": "Plant_Moss_Block_Blue"
    },
    {
      "x": -21,
      "y": 97,
      "z": 2,
      "name": "Plant_Moss_Rug_Lime"
    },
    {
      "x": -21,
      "y": 103,
      "z": 2,
      "name": "Plant_Leaves_Azure",
      "rotation": 2
    },
    {
      "x": -21,
      "y": 108,
      "z": 2,
      "name": "Plant_Leaves_Azure",
      "rotation": 2
    },
    {
      "x": -21,
      "y": 109,
      "z": 2,
      "name": "Plant_Leaves_Azure",
      "rotation": 2
    },
    {
      "x": -21,
      "y": 110,
      "z": 2,
      "name": "Plant_Leaves_Azure",
      "rotation": 2
    },
    {
      "x": -21,
      "y": 111,
      "z": 2,
      "name": "Plant_Fruit_Azure",
      "rotation": 2
    },
    {
      "x": -21,
      "y": 93,
      "z": 3,
      "name": "Rock_Marble"
    },
    {
      "x": -21,
      "y": 94,
      "z": 3,
      "name": "Plant_Moss_Block_Blue"
    },
    {
      "x": -21,
      "y": 95,
      "z": 3,
      "name": "Plant_Moss_Block_Blue"
    },
    {
      "x": -21,
      "y": 96,
      "z": 3,
      "name": "Plant_Moss_Rug_Lime"
    },
    {
      "x": -21,
      "y": 102,
      "z": 3,
      "name": "Plant_Leaves_Azure",
      "rotation": 2
    },
    {
      "x": -21,
      "y": 103,
      "z": 3,
      "name": "Plant_Leaves_Azure",
      "rotation": 2
    },
    {
      "x": -21,
      "y": 104,
      "z": 3,
      "name": "Wood_Azure_Branch_Long",
      "rotation": 7
    },
    {
      "x": -21,
      "y": 108,
      "z": 3,
      "name": "Plant_Leaves_Azure",
      "rotation": 2
    },
    {
      "x": -21,
      "y": 109,
      "z": 3,
      "name": "Plant_Leaves_Azure",
      "rotation": 2
    },
    {
      "x": -21,
      "y": 110,
      "z": 3,
      "name": "Plant_Leaves_Azure",
      "rotation": 2
    },
    {
      "x": -21,
      "y": 111,
      "z": 3,
      "name": "Plant_Leaves_Azure",
      "rotation": 2
    },
    {
      "x": -21,
      "y": 94,
      "z": 4,
      "name": "Plant_Moss_Block_Blue"
    },
    {
      "x": -21,
      "y": 95,
      "z": 4,
      "name": "Plant_Moss_Rug_Blue"
    },
    {
      "x": -21,
      "y": 103,
      "z": 4,
      "name": "Plant_Leaves_Azure",
      "rotation": 2
    },
    {
      "x": -21,
      "y": 104,
      "z": 4,
      "name": "Plant_Leaves_Azure",
      "rotation": 2
    },
    {
      "x": -21,
      "y": 108,
      "z": 4,
      "name": "Plant_Leaves_Azure",
      "rotation": 2
    },
    {
      "x": -21,
      "y": 109,
      "z": 4,
      "name": "Plant_Leaves_Azure",
      "rotation": 2
    },
    {
      "x": -21,
      "y": 110,
      "z": 4,
      "name": "Plant_Leaves_Azure",
      "rotation": 2
    },
    {
      "x": -21,
      "y": 111,
      "z": 4,
      "name": "Plant_Leaves_Azure",
      "rotation": 2
    },
    {
      "x": -21,
      "y": 112,
      "z": 4,
      "name": "Plant_Fruit_Azure",
      "rotation": 2
    },
    {
      "x": -21,
      "y": 93,
      "z": 5,
      "name": "Plant_Moss_Block_Blue"
    },
    {
      "x": -21,
      "y": 94,
      "z": 5,
      "name": "Plant_Moss_Blue"
    },
    {
      "x": -21,
      "y": 103,
      "z": 5,
      "name": "Plant_Leaves_Azure",
      "rotation": 2
    },
    {
      "x": -21,
      "y": 104,
      "z": 5,
      "name": "Plant_Leaves_Azure",
      "rotation": 2
    },
    {
      "x": -21,
      "y": 105,
      "z": 5,
      "name": "Plant_Leaves_Azure",
      "rotation": 2
    },
    {
      "x": -21,
      "y": 106,
      "z": 5,
      "name": "Plant_Leaves_Azure",
      "rotation": 2
    },
    {
      "x": -21,
      "y": 109,
      "z": 5,
      "name": "Plant_Leaves_Azure",
      "rotation": 2
    },
    {
      "x": -21,
      "y": 110,
      "z": 5,
      "name": "Plant_Leaves_Azure",
      "rotation": 2
    },
    {
      "x": -21,
      "y": 111,
      "z": 5,
      "name": "Plant_Leaves_Azure",
      "rotation": 2
    },
    {
      "x": -21,
      "y": 95,
      "z": 6,
      "name": "Plant_Moss_Wall_Blue",
      "support": 15,
      "rotation": 3
    },
    {
      "x": -21,
      "y": 103,
      "z": 6,
      "name": "Plant_Leaves_Azure",
      "rotation": 2
    },
    {
      "x": -21,
      "y": 104,
      "z": 6,
      "name": "Plant_Leaves_Azure",
      "rotation": 2
    },
    {
      "x": -21,
      "y": 105,
      "z": 6,
      "name": "Plant_Leaves_Azure",
      "rotation": 2
    },
    {
      "x": -21,
      "y": 106,
      "z": 6,
      "name": "Plant_Leaves_Azure",
      "rotation": 2
    },
    {
      "x": -21,
      "y": 107,
      "z": 6,
      "name": "Plant_Fruit_Azure",
      "rotation": 2
    },
    {
      "x": -21,
      "y": 95,
      "z": 7,
      "name": "Plant_Moss_Wall_Blue",
      "support": 15,
      "rotation": 3
    },
    {
      "x": -21,
      "y": 103,
      "z": 7,
      "name": "Plant_Leaves_Azure",
      "rotation": 2
    },
    {
      "x": -21,
      "y": 104,
      "z": 7,
      "name": "Plant_Leaves_Azure",
      "rotation": 2
    },
    {
      "x": -21,
      "y": 105,
      "z": 7,
      "name": "Plant_Leaves_Azure",
      "rotation": 2
    },
    {
      "x": -21,
      "y": 106,
      "z": 7,
      "name": "Plant_Leaves_Azure",
      "rotation": 2
    },
    {
      "x": -21,
      "y": 107,
      "z": 7,
      "name": "Plant_Leaves_Azure",
      "rotation": 2
    },
    {
      "x": -21,
      "y": 92,
      "z": 8,
      "name": "Plant_Crop_Mushroom_Block_Blue_Mycelium"
    },
    {
      "x": -21,
      "y": 93,
      "z": 8,
      "name": "Rock_Crystal_Blue_Block"
    },
    {
      "x": -21,
      "y": 94,
      "z": 8,
      "name": "Plant_Moss_Block_Blue"
    },
    {
      "x": -21,
      "y": 95,
      "z": 8,
      "name": "Plant_Moss_Short_Green_Dark"
    },
    {
      "x": -21,
      "y": 104,
      "z": 8,
      "name": "Plant_Leaves_Azure",
      "rotation": 2
    },
    {
      "x": -21,
      "y": 105,
      "z": 8,
      "name": "Plant_Leaves_Azure",
      "rotation": 2
    },
    {
      "x": -21,
      "y": 106,
      "z": 8,
      "name": "Plant_Leaves_Azure",
      "rotation": 2
    },
    {
      "x": -21,
      "y": 92,
      "z": 9,
      "name": "Plant_Moss_Wall_Blue",
      "support": 15,
      "rotation": 3
    },
    {
      "x": -21,
      "y": 93,
      "z": 9,
      "name": "Rock_Crystal_Blue_Block"
    },
    {
      "x": -21,
      "y": 94,
      "z": 9,
      "name": "Plant_Moss_Block_Blue"
    },
    {
      "x": -21,
      "y": 95,
      "z": 9,
      "name": "Plant_Moss_Block_Blue"
    },
    {
      "x": -21,
      "y": 96,
      "z": 9,
      "name": "Plant_Moss_Short_Green_Dark"
    },
    {
      "x": -21,
      "y": 94,
      "z": 10,
      "name": "Plant_Moss_Block_Blue"
    },
    {
      "x": -21,
      "y": 95,
      "z": 10,
      "name": "Plant_Moss_Block_Blue"
    },
    {
      "x": -21,
      "y": 96,
      "z": 10,
      "name": "Plant_Moss_Rug_Lime"
    },
    {
      "x": -20,
      "y": 95,
      "z": -9,
      "name": "Plant_Moss_Wall_Blue",
      "support": 15,
      "rotation": 2
    },
    {
      "x": -20,
      "y": 97,
      "z": -9,
      "name": "Plant_Moss_Block_Blue"
    },
    {
      "x": -20,
      "y": 98,
      "z": -9,
      "name": "Plant_Moss_Blue"
    },
    {
      "x": -20,
      "y": 94,
      "z": -8,
      "name": "Plant_Moss_Wall_Blue",
      "support": 15,
      "rotation": 3
    },
    {
      "x": -20,
      "y": 95,
      "z": -8,
      "name": "Rock_Marble"
    },
    {
      "x": -20,
      "y": 96,
      "z": -8,
      "name": "Rock_Marble"
    },
    {
      "x": -20,
      "y": 97,
      "z": -8,
      "name": "Rock_Marble"
    },
    {
      "x": -20,
      "y": 98,
      "z": -8,
      "name": "Plant_Moss_Block_Blue"
    },
    {
      "x": -20,
      "y": 99,
      "z": -8,
      "name": "Plant_Moss_Block_Blue"
    },
    {
      "x": -20,
      "y": 100,
      "z": -8,
      "name": "Plant_Moss_Short_Green_Dark"
    },
    {
      "x": -20,
      "y": 94,
      "z": -7,
      "name": "Rock_Marble"
    },
    {
      "x": -20,
      "y": 95,
      "z": -7,
      "name": "Rock_Marble"
    },
    {
      "x": -20,
      "y": 96,
      "z": -7,
      "name": "Rock_Marble"
    },
    {
      "x": -20,
      "y": 97,
      "z": -7,
      "name": "Rock_Marble"
    },
    {
      "x": -20,
      "y": 98,
      "z": -7,
      "name": "Plant_Moss_Block_Blue"
    },
    {
      "x": -20,
      "y": 99,
      "z": -7,
      "name": "Plant_Moss_Block_Blue"
    },
    {
      "x": -20,
      "y": 100,
      "z": -7,
      "name": "Plant_Moss_Rug_Lime"
    },
    {
      "x": -20,
      "y": 92,
      "z": -6,
      "name": "Plant_Moss_Wall_Blue",
      "support": 15,
      "rotation": 3
    },
    {
      "x": -20,
      "y": 93,
      "z": -6,
      "name": "Rock_Marble"
    },
    {
      "x": -20,
      "y": 94,
      "z": -6,
      "name": "Rock_Marble"
    },
    {
      "x": -20,
      "y": 95,
      "z": -6,
      "name": "Rock_Marble"
    },
    {
      "x": -20,
      "y": 96,
      "z": -6,
      "name": "Rock_Marble"
    },
    {
      "x": -20,
      "y": 97,
      "z": -6,
      "name": "Plant_Moss_Block_Blue"
    },
    {
      "x": -20,
      "y": 98,
      "z": -6,
      "name": "Plant_Moss_Block_Blue"
    },
    {
      "x": -20,
      "y": 99,
      "z": -6,
      "name": "Plant_Moss_Short_Green_Dark"
    },
    {
      "x": -20,
      "y": 90,
      "z": -5,
      "name": "Rock_Marble"
    },
    {
      "x": -20,
      "y": 91,
      "z": -5,
      "name": "Rock_Marble"
    },
    {
      "x": -20,
      "y": 92,
      "z": -5,
      "name": "Rock_Marble"
    },
    {
      "x": -20,
      "y": 93,
      "z": -5,
      "name": "Rock_Marble"
    },
    {
      "x": -20,
      "y": 94,
      "z": -5,
      "name": "Rock_Marble"
    },
    {
      "x": -20,
      "y": 95,
      "z": -5,
      "name": "Rock_Marble"
    },
    {
      "x": -20,
      "y": 96,
      "z": -5,
      "name": "Rock_Marble"
    },
    {
      "x": -20,
      "y": 97,
      "z": -5,
      "name": "Plant_Moss_Block_Blue"
    },
    {
      "x": -20,
      "y": 98,
      "z": -5,
      "name": "Plant_Moss_Block_Blue"
    },
    {
      "x": -20,
      "y": 99,
      "z": -5,
      "name": "Plant_Moss_Short_Green_Dark"
    },
    {
      "x": -20,
      "y": 91,
      "z": -4,
      "name": "Rock_Marble"
    },
    {
      "x": -20,
      "y": 92,
      "z": -4,
      "name": "Rock_Marble"
    },
    {
      "x": -20,
      "y": 93,
      "z": -4,
      "name": "Rock_Marble"
    },
    {
      "x": -20,
      "y": 94,
      "z": -4,
      "name": "Rock_Marble"
    },
    {
      "x": -20,
      "y": 95,
      "z": -4,
      "name": "Rock_Marble"
    },
    {
      "x": -20,
      "y": 96,
      "z": -4,
      "name": "Rock_Marble"
    },
    {
      "x": -20,
      "y": 97,
      "z": -4,
      "name": "Plant_Moss_Block_Blue"
    },
    {
      "x": -20,
      "y": 98,
      "z": -4,
      "name": "Plant_Moss_Block_Blue"
    },
    {
      "x": -20,
      "y": 99,
      "z": -4,
      "name": "Plant_Moss_Rug_Lime"
    },
    {
      "x": -20,
      "y": 91,
      "z": -3,
      "name": "Rock_Marble"
    },
    {
      "x": -20,
      "y": 92,
      "z": -3,
      "name": "Rock_Crystal_Blue_Block"
    },
    {
      "x": -20,
      "y": 93,
      "z": -3,
      "name": "Rock_Marble"
    },
    {
      "x": -20,
      "y": 94,
      "z": -3,
      "name": "Rock_Marble"
    },
    {
      "x": -20,
      "y": 95,
      "z": -3,
      "name": "Rock_Marble"
    },
    {
      "x": -20,
      "y": 96,
      "z": -3,
      "name": "Rock_Marble"
    },
    {
      "x": -20,
      "y": 97,
      "z": -3,
      "name": "Plant_Moss_Block_Blue"
    },
    {
      "x": -20,
      "y": 98,
      "z": -3,
      "name": "Plant_Moss_Block_Blue"
    },
    {
      "x": -20,
      "y": 99,
      "z": -3,
      "name": "Plant_Moss_Blue"
    },
    {
      "x": -20,
      "y": 93,
      "z": -2,
      "name": "Rock_Crystal_Blue_Block"
    },
    {
      "x": -20,
      "y": 94,
      "z": -2,
      "name": "Rock_Marble"
    },
    {
      "x": -20,
      "y": 95,
      "z": -2,
      "name": "Rock_Marble"
    },
    {
      "x": -20,
      "y": 96,
      "z": -2,
      "name": "Rock_Marble"
    },
    {
      "x": -20,
      "y": 97,
      "z": -2,
      "name": "Plant_Moss_Block_Blue"
    },
    {
      "x": -20,
      "y": 98,
      "z": -2,
      "name": "Plant_Moss_Block_Blue"
    },
    {
      "x": -20,
      "y": 99,
      "z": -2,
      "name": "Plant_Moss_Blue"
    },
    {
      "x": -20,
      "y": 105,
      "z": -2,
      "name": "Plant_Leaves_Azure",
      "rotation": 2
    },
    {
      "x": -20,
      "y": 106,
      "z": -2,
      "name": "Plant_Leaves_Azure",
      "rotation": 2
    },
    {
      "x": -20,
      "y": 107,
      "z": -2,
      "name": "Plant_Leaves_Azure",
      "rotation": 2
    },
    {
      "x": -20,
      "y": 93,
      "z": -1,
      "name": "Rock_Crystal_Blue_Block"
    },
    {
      "x": -20,
      "y": 94,
      "z": -1,
      "name": "Rock_Marble"
    },
    {
      "x": -20,
      "y": 95,
      "z": -1,
      "name": "Wood_Azure_Roots",
      "rotation": 2
    },
    {
      "x": -20,
      "y": 96,
      "z": -1,
      "name": "Wood_Azure_Trunk_Full",
      "rotation": 2
    },
    {
      "x": -20,
      "y": 97,
      "z": -1,
      "name": "Wood_Azure_Trunk_Full",
      "rotation": 2
    },
    {
      "x": -20,
      "y": 98,
      "z": -1,
      "name": "Plant_Moss_Block_Blue"
    },
    {
      "x": -20,
      "y": 99,
      "z": -1,
      "name": "Plant_Moss_Rug_Lime"
    },
    {
      "x": -20,
      "y": 104,
      "z": -1,
      "name": "Plant_Leaves_Azure",
      "rotation": 2
    },
    {
      "x": -20,
      "y": 105,
      "z": -1,
      "name": "Plant_Leaves_Azure",
      "rotation": 2
    },
    {
      "x": -20,
      "y": 106,
      "z": -1,
      "name": "Plant_Leaves_Azure",
      "rotation": 2
    },
    {
      "x": -20,
      "y": 107,
      "z": -1,
      "name": "Plant_Leaves_Azure",
      "rotation": 2
    },
    {
      "x": -20,
      "y": 108,
      "z": -1,
      "name": "Plant_Leaves_Azure",
      "rotation": 2
    },
    {
      "x": -20,
      "y": 92,
      "z": 0,
      "name": "Rock_Marble"
    },
    {
      "x": -20,
      "y": 93,
      "z": 0,
      "name": "Rock_Marble"
    },
    {
      "x": -20,
      "y": 94,
      "z": 0,
      "name": "Rock_Marble"
    },
    {
      "x": -20,
      "y": 95,
      "z": 0,
      "name": "Rock_Marble"
    },
    {
      "x": -20,
      "y": 96,
      "z": 0,
      "name": "Rock_Marble"
    },
    {
      "x": -20,
      "y": 97,
      "z": 0,
      "name": "Wood_Azure_Trunk_Full",
      "rotation": 2
    },
    {
      "x": -20,
      "y": 98,
      "z": 0,
      "name": "Wood_Azure_Trunk_Full",
      "rotation": 2
    },
    {
      "x": -20,
      "y": 99,
      "z": 0,
      "name": "Plant_Moss_Rug_Blue"
    },
    {
      "x": -20,
      "y": 106,
      "z": 0,
      "name": "Plant_Leaves_Azure",
      "rotation": 2
    },
    {
      "x": -20,
      "y": 107,
      "z": 0,
      "name": "Plant_Leaves_Azure",
      "rotation": 2
    },
    {
      "x": -20,
      "y": 108,
      "z": 0,
      "name": "Plant_Leaves_Azure",
      "rotation": 2
    },
    {
      "x": -20,
      "y": 92,
      "z": 1,
      "name": "Rock_Marble"
    },
    {
      "x": -20,
      "y": 93,
      "z": 1,
      "name": "Rock_Marble"
    },
    {
      "x": -20,
      "y": 94,
      "z": 1,
      "name": "Rock_Marble"
    },
    {
      "x": -20,
      "y": 95,
      "z": 1,
      "name": "Rock_Marble"
    },
    {
      "x": -20,
      "y": 96,
      "z": 1,
      "name": "Rock_Marble"
    },
    {
      "x": -20,
      "y": 97,
      "z": 1,
      "name": "Plant_Moss_Block_Blue"
    },
    {
      "x": -20,
      "y": 98,
      "z": 1,
      "name": "Plant_Moss_Block_Blue"
    },
    {
      "x": -20,
      "y": 99,
      "z": 1,
      "name": "Plant_Moss_Rug_Lime"
    },
    {
      "x": -20,
      "y": 108,
      "z": 1,
      "name": "Plant_Leaves_Azure",
      "rotation": 2
    },
    {
      "x": -20,
      "y": 109,
      "z": 1,
      "name": "Plant_Leaves_Azure",
      "rotation": 2
    },
    {
      "x": -20,
      "y": 112,
      "z": 1,
      "name": "Plant_Leaves_Azure",
      "rotation": 2
    },
    {
      "x": -20,
      "y": 92,
      "z": 2,
      "name": "Rock_Marble"
    },
    {
      "x": -20,
      "y": 93,
      "z": 2,
      "name": "Rock_Marble"
    },
    {
      "x": -20,
      "y": 94,
      "z": 2,
      "name": "Rock_Marble"
    },
    {
      "x": -20,
      "y": 95,
      "z": 2,
      "name": "Rock_Marble"
    },
    {
      "x": -20,
      "y": 96,
      "z": 2,
      "name": "Plant_Moss_Block_Blue"
    },
    {
      "x": -20,
      "y": 97,
      "z": 2,
      "name": "Plant_Moss_Block_Blue"
    },
    {
      "x": -20,
      "y": 98,
      "z": 2,
      "name": "Plant_Moss_Short_Green_Dark"
    },
    {
      "x": -20,
      "y": 108,
      "z": 2,
      "name": "Plant_Leaves_Azure",
      "rotation": 2
    },
    {
      "x": -20,
      "y": 109,
      "z": 2,
      "name": "Plant_Leaves_Azure",
      "rotation": 2
    },
    {
      "x": -20,
      "y": 92,
      "z": 3,
      "name": "Rock_Marble"
    },
    {
      "x": -20,
      "y": 93,
      "z": 3,
      "name": "Rock_Marble"
    },
    {
      "x": -20,
      "y": 94,
      "z": 3,
      "name": "Rock_Marble"
    },
    {
      "x": -20,
      "y": 95,
      "z": 3,
      "name": "Plant_Moss_Block_Blue"
    },
    {
      "x": -20,
      "y": 96,
      "z": 3,
      "name": "Plant_Moss_Block_Blue"
    },
    {
      "x": -20,
      "y": 97,
      "z": 3,
      "name": "Plant_Moss_Short_Green_Dark"
    },
    {
      "x": -20,
      "y": 104,
      "z": 3,
      "name": "Wood_Azure_Branch_Long",
      "rotation": 7
    },
    {
      "x": -20,
      "y": 106,
      "z": 3,
      "name": "Plant_Moss_Wall_Blue",
      "rotation": 3
    },
    {
      "x": -20,
      "y": 109,
      "z": 3,
      "name": "Plant_Leaves_Azure",
      "rotation": 2
    },
    {
      "x": -20,
      "y": 110,
      "z": 3,
      "name": "Plant_Leaves_Azure",
      "rotation": 2
    },
    {
      "x": -20,
      "y": 92,
      "z": 4,
      "name": "Plant_Moss_Wall_Blue",
      "support": 15,
      "rotation": 3
    },
    {
      "x": -20,
      "y": 93,
      "z": 4,
      "name": "Rock_Marble"
    },
    {
      "x": -20,
      "y": 94,
      "z": 4,
      "name": "Plant_Moss_Block_Blue"
    },
    {
      "x": -20,
      "y": 95,
      "z": 4,
      "name": "Plant_Moss_Block_Blue"
    },
    {
      "x": -20,
      "y": 96,
      "z": 4,
      "name": "Plant_Moss_Short_Green_Dark"
    },
    {
      "x": -20,
      "y": 110,
      "z": 4,
      "name": "Plant_Leaves_Azure",
      "rotation": 2
    },
    {
      "x": -20,
      "y": 111,
      "z": 4,
      "name": "Plant_Leaves_Azure",
      "rotation": 2
    },
    {
      "x": -20,
      "y": 93,
      "z": 5,
      "name": "Rock_Marble"
    },
    {
      "x": -20,
      "y": 94,
      "z": 5,
      "name": "Plant_Moss_Block_Blue"
    },
    {
      "x": -20,
      "y": 95,
      "z": 5,
      "name": "Plant_Moss_Block_Blue"
    },
    {
      "x": -20,
      "y": 96,
      "z": 5,
      "name": "Plant_Moss_Blue"
    },
    {
      "x": -20,
      "y": 109,
      "z": 5,
      "name": "Plant_Leaves_Azure",
      "rotation": 2
    },
    {
      "x": -20,
      "y": 110,
      "z": 5,
      "name": "Plant_Leaves_Azure",
      "rotation": 2
    },
    {
      "x": -20,
      "y": 111,
      "z": 5,
      "name": "Plant_Leaves_Azure",
      "rotation": 2
    },
    {
      "x": -20,
      "y": 112,
      "z": 5,
      "name": "Plant_Leaves_Azure",
      "rotation": 2
    },
    {
      "x": -20,
      "y": 93,
      "z": 6,
      "name": "Plant_Moss_Wall_Blue",
      "support": 15,
      "rotation": 3
    },
    {
      "x": -20,
      "y": 94,
      "z": 6,
      "name": "Plant_Moss_Block_Blue"
    },
    {
      "x": -20,
      "y": 95,
      "z": 6,
      "name": "Plant_Moss_Block_Blue"
    },
    {
      "x": -20,
      "y": 96,
      "z": 6,
      "name": "Plant_Moss_Rug_Lime"
    },
    {
      "x": -20,
      "y": 105,
      "z": 6,
      "name": "Plant_Leaves_Azure",
      "rotation": 2
    },
    {
      "x": -20,
      "y": 106,
      "z": 6,
      "name": "Plant_Leaves_Azure",
      "rotation": 2
    },
    {
      "x": -20,
      "y": 107,
      "z": 6,
      "name": "Plant_Leaves_Azure",
      "rotation": 2
    },
    {
      "x": -20,
      "y": 110,
      "z": 6,
      "name": "Plant_Leaves_Azure",
      "rotation": 2
    },
    {
      "x": -20,
      "y": 111,
      "z": 6,
      "name": "Plant_Leaves_Azure",
      "rotation": 2
    },
    {
      "x": -20,
      "y": 112,
      "z": 6,
      "name": "Plant_Leaves_Azure",
      "rotation": 2
    },
    {
      "x": -20,
      "y": 93,
      "z": 7,
      "name": "Rock_Crystal_Blue_Block"
    },
    {
      "x": -20,
      "y": 94,
      "z": 7,
      "name": "Plant_Moss_Block_Blue"
    },
    {
      "x": -20,
      "y": 95,
      "z": 7,
      "name": "Plant_Moss_Block_Blue"
    },
    {
      "x": -20,
      "y": 96,
      "z": 7,
      "name": "Plant_Moss_Rug_Lime"
    },
    {
      "x": -20,
      "y": 104,
      "z": 7,
      "name": "Plant_Leaves_Azure",
      "rotation": 2
    },
    {
      "x": -20,
      "y": 105,
      "z": 7,
      "name": "Plant_Leaves_Azure",
      "rotation": 2
    },
    {
      "x": -20,
      "y": 106,
      "z": 7,
      "name": "Plant_Leaves_Azure",
      "rotation": 2
    },
    {
      "x": -20,
      "y": 107,
      "z": 7,
      "name": "Plant_Leaves_Azure",
      "rotation": 2
    },
    {
      "x": -20,
      "y": 108,
      "z": 7,
      "name": "Plant_Fruit_Azure",
      "rotation": 2
    },
    {
      "x": -20,
      "y": 92,
      "z": 8,
      "name": "Rock_Crystal_Blue_Block"
    },
    {
      "x": -20,
      "y": 93,
      "z": 8,
      "name": "Rock_Marble"
    },
    {
      "x": -20,
      "y": 94,
      "z": 8,
      "name": "Plant_Moss_Block_Blue"
    },
    {
      "x": -20,
      "y": 95,
      "z": 8,
      "name": "Plant_Moss_Block_Blue"
    },
    {
      "x": -20,
      "y": 96,
      "z": 8,
      "name": "Plant_Moss_Blue"
    },
    {
      "x": -20,
      "y": 103,
      "z": 8,
      "name": "Plant_Leaves_Azure",
      "rotation": 2
    },
    {
      "x": -20,
      "y": 104,
      "z": 8,
      "name": "Plant_Leaves_Azure",
      "rotation": 2
    },
    {
      "x": -20,
      "y": 105,
      "z": 8,
      "name": "Plant_Leaves_Azure",
      "rotation": 2
    },
    {
      "x": -20,
      "y": 106,
      "z": 8,
      "name": "Plant_Leaves_Azure",
      "rotation": 2
    },
    {
      "x": -20,
      "y": 107,
      "z": 8,
      "name": "Plant_Leaves_Azure",
      "rotation": 2
    },
    {
      "x": -20,
      "y": 91,
      "z": 9,
      "name": "Rock_Marble"
    },
    {
      "x": -20,
      "y": 92,
      "z": 9,
      "name": "Rock_Crystal_Blue_Block"
    },
    {
      "x": -20,
      "y": 93,
      "z": 9,
      "name": "Rock_Marble"
    },
    {
      "x": -20,
      "y": 94,
      "z": 9,
      "name": "Rock_Marble"
    },
    {
      "x": -20,
      "y": 95,
      "z": 9,
      "name": "Plant_Moss_Block_Blue"
    },
    {
      "x": -20,
      "y": 96,
      "z": 9,
      "name": "Plant_Moss_Block_Blue"
    },
    {
      "x": -20,
      "y": 97,
      "z": 9,
      "name": "Plant_Moss_Rug_Blue"
    },
    {
      "x": -20,
      "y": 104,
      "z": 9,
      "name": "Plant_Leaves_Azure",
      "rotation": 2
    },
    {
      "x": -20,
      "y": 105,
      "z": 9,
      "name": "Plant_Leaves_Azure",
      "rotation": 2
    },
    {
      "x": -20,
      "y": 106,
      "z": 9,
      "name": "Plant_Leaves_Azure",
      "rotation": 2
    },
    {
      "x": -20,
      "y": 91,
      "z": 10,
      "name": "Plant_Moss_Wall_Blue",
      "support": 15,
      "rotation": 3
    },
    {
      "x": -20,
      "y": 93,
      "z": 10,
      "name": "Rock_Marble"
    },
    {
      "x": -20,
      "y": 94,
      "z": 10,
      "name": "Plant_Moss_Block_Blue"
    },
    {
      "x": -20,
      "y": 95,
      "z": 10,
      "name": "Plant_Moss_Block_Blue"
    },
    {
      "x": -20,
      "y": 96,
      "z": 10,
      "name": "Plant_Moss_Blue"
    },
    {
      "x": -20,
      "y": 92,
      "z": 11,
      "name": "Plant_Moss_Wall_Blue",
      "support": 15,
      "rotation": 3
    },
    {
      "x": -20,
      "y": 93,
      "z": 11,
      "name": "Rock_Marble"
    },
    {
      "x": -20,
      "y": 94,
      "z": 11,
      "name": "Plant_Moss_Block_Blue"
    },
    {
      "x": -20,
      "y": 95,
      "z": 11,
      "name": "Plant_Moss_Block_Blue"
    },
    {
      "x": -20,
      "y": 96,
      "z": 11,
      "name": "Plant_Moss_Short_Green_Dark"
    },
    {
      "x": -19,
      "y": 95,
      "z": -10,
      "name": "Plant_Moss_Wall_Blue",
      "support": 15,
      "rotation": 2
    },
    {
      "x": -19,
      "y": 96,
      "z": -10,
      "name": "Plant_Moss_Block_Blue"
    },
    {
      "x": -19,
      "y": 97,
      "z": -10,
      "name": "Plant_Moss_Block_Blue"
    },
    {
      "x": -19,
      "y": 98,
      "z": -10,
      "name": "Plant_Moss_Short_Green_Dark"
    },
    {
      "x": -19,
      "y": 95,
      "z": -9,
      "name": "Rock_Marble"
    },
    {
      "x": -19,
      "y": 96,
      "z": -9,
      "name": "Rock_Marble"
    },
    {
      "x": -19,
      "y": 97,
      "z": -9,
      "name": "Plant_Moss_Block_Blue"
    },
    {
      "x": -19,
      "y": 98,
      "z": -9,
      "name": "Plant_Moss_Block_Blue"
    },
    {
      "x": -19,
      "y": 99,
      "z": -9,
      "name": "Plant_Moss_Blue"
    },
    {
      "x": -19,
      "y": 94,
      "z": -8,
      "name": "Rock_Marble"
    },
    {
      "x": -19,
      "y": 95,
      "z": -8,
      "name": "Rock_Marble"
    },
    {
      "x": -19,
      "y": 96,
      "z": -8,
      "name": "Rock_Marble"
    },
    {
      "x": -19,
      "y": 97,
      "z": -8,
      "name": "Rock_Marble"
    },
    {
      "x": -19,
      "y": 98,
      "z": -8,
      "name": "Plant_Moss_Block_Blue"
    },
    {
      "x": -19,
      "y": 99,
      "z": -8,
      "name": "Plant_Moss_Block_Blue"
    },
    {
      "x": -19,
      "y": 100,
      "z": -8,
      "name": "Plant_Moss_Blue"
    },
    {
      "x": -19,
      "y": 93,
      "z": -7,
      "name": "Plant_Moss_Wall_Blue",
      "support": 15,
      "rotation": 3
    },
    {
      "x": -19,
      "y": 94,
      "z": -7,
      "name": "Rock_Marble"
    },
    {
      "x": -19,
      "y": 95,
      "z": -7,
      "name": "Rock_Marble"
    },
    {
      "x": -19,
      "y": 96,
      "z": -7,
      "name": "Rock_Marble"
    },
    {
      "x": -19,
      "y": 97,
      "z": -7,
      "name": "Rock_Marble"
    },
    {
      "x": -19,
      "y": 98,
      "z": -7,
      "name": "Plant_Moss_Block_Blue"
    },
    {
      "x": -19,
      "y": 99,
      "z": -7,
      "name": "Plant_Moss_Block_Blue"
    },
    {
      "x": -19,
      "y": 100,
      "z": -7,
      "name": "Plant_Moss_Short_Green_Dark"
    },
    {
      "x": -19,
      "y": 90,
      "z": -6,
      "name": "Rock_Crystal_Blue_Large"
    },
    {
      "x": -19,
      "y": 91,
      "z": -6,
      "name": "Rock_Marble"
    },
    {
      "x": -19,
      "y": 92,
      "z": -6,
      "name": "Rock_Marble"
    },
    {
      "x": -19,
      "y": 93,
      "z": -6,
      "name": "Rock_Marble"
    },
    {
      "x": -19,
      "y": 94,
      "z": -6,
      "name": "Rock_Marble"
    },
    {
      "x": -19,
      "y": 95,
      "z": -6,
      "name": "Rock_Marble"
    },
    {
      "x": -19,
      "y": 96,
      "z": -6,
      "name": "Rock_Marble"
    },
    {
      "x": -19,
      "y": 97,
      "z": -6,
      "name": "Rock_Marble"
    },
    {
      "x": -19,
      "y": 98,
      "z": -6,
      "name": "Plant_Moss_Block_Blue"
    },
    {
      "x": -19,
      "y": 99,
      "z": -6,
      "name": "Plant_Moss_Block_Blue"
    },
    {
      "x": -19,
      "y": 100,
      "z": -6,
      "name": "Plant_Moss_Rug_Lime"
    },
    {
      "x": -19,
      "y": 87,
      "z": -5,
      "name": "Rock_Crystal_Blue_Block"
    },
    {
      "x": -19,
      "y": 88,
      "z": -5,
      "name": "Rock_Crystal_Blue_Block"
    },
    {
      "x": -19,
      "y": 89,
      "z": -5,
      "name": "Rock_Marble"
    },
    {
      "x": -19,
      "y": 90,
      "z": -5,
      "name": "Rock_Marble"
    },
    {
      "x": -19,
      "y": 91,
      "z": -5,
      "name": "Rock_Marble"
    },
    {
      "x": -19,
      "y": 92,
      "z": -5,
      "name": "Rock_Marble"
    },
    {
      "x": -19,
      "y": 93,
      "z": -5,
      "name": "Rock_Marble"
    },
    {
      "x": -19,
      "y": 94,
      "z": -5,
      "name": "Rock_Marble"
    },
    {
      "x": -19,
      "y": 95,
      "z": -5,
      "name": "Rock_Marble"
    },
    {
      "x": -19,
      "y": 96,
      "z": -5,
      "name": "Rock_Marble"
    },
    {
      "x": -19,
      "y": 97,
      "z": -5,
      "name": "Plant_Moss_Block_Blue"
    },
    {
      "x": -19,
      "y": 98,
      "z": -5,
      "name": "Plant_Moss_Block_Blue"
    },
    {
      "x": -19,
      "y": 99,
      "z": -5,
      "name": "Plant_Moss_Blue"
    },
    {
      "x": -19,
      "y": 89,
      "z": -4,
      "name": "Rock_Crystal_Blue_Block"
    },
    {
      "x": -19,
      "y": 90,
      "z": -4,
      "name": "Rock_Crystal_Blue_Block"
    },
    {
      "x": -19,
      "y": 91,
      "z": -4,
      "name": "Rock_Marble"
    },
    {
      "x": -19,
      "y": 92,
      "z": -4,
      "name": "Rock_Marble"
    },
    {
      "x": -19,
      "y": 93,
      "z": -4,
      "name": "Rock_Marble"
    },
    {
      "x": -19,
      "y": 94,
      "z": -4,
      "name": "Rock_Marble"
    },
    {
      "x": -19,
      "y": 95,
      "z": -4,
      "name": "Rock_Marble"
    },
    {
      "x": -19,
      "y": 96,
      "z": -4,
      "name": "Rock_Marble"
    },
    {
      "x": -19,
      "y": 97,
      "z": -4,
      "name": "Plant_Moss_Block_Blue"
    },
    {
      "x": -19,
      "y": 98,
      "z": -4,
      "name": "Plant_Moss_Block_Blue"
    },
    {
      "x": -19,
      "y": 99,
      "z": -4,
      "name": "Plant_Moss_Rug_Blue"
    },
    {
      "x": -19,
      "y": 92,
      "z": -3,
      "name": "Rock_Crystal_Blue_Block"
    },
    {
      "x": -19,
      "y": 93,
      "z": -3,
      "name": "Rock_Marble"
    },
    {
      "x": -19,
      "y": 94,
      "z": -3,
      "name": "Rock_Marble"
    },
    {
      "x": -19,
      "y": 95,
      "z": -3,
      "name": "Rock_Marble"
    },
    {
      "x": -19,
      "y": 96,
      "z": -3,
      "name": "Rock_Marble"
    },
    {
      "x": -19,
      "y": 97,
      "z": -3,
      "name": "Plant_Moss_Block_Blue"
    },
    {
      "x": -19,
      "y": 98,
      "z": -3,
      "name": "Plant_Moss_Block_Blue"
    },
    {
      "x": -19,
      "y": 99,
      "z": -3,
      "name": "Plant_Moss_Rug_Lime"
    },
    {
      "x": -19,
      "y": 92,
      "z": -2,
      "name": "Rock_Crystal_Blue_Block"
    },
    {
      "x": -19,
      "y": 93,
      "z": -2,
      "name": "Rock_Marble"
    },
    {
      "x": -19,
      "y": 94,
      "z": -2,
      "name": "Rock_Marble"
    },
    {
      "x": -19,
      "y": 95,
      "z": -2,
      "name": "Rock_Marble"
    },
    {
      "x": -19,
      "y": 96,
      "z": -2,
      "name": "Rock_Marble"
    },
    {
      "x": -19,
      "y": 97,
      "z": -2,
      "name": "Plant_Moss_Block_Blue"
    },
    {
      "x": -19,
      "y": 98,
      "z": -2,
      "name": "Plant_Moss_Block_Blue"
    },
    {
      "x": -19,
      "y": 99,
      "z": -2,
      "name": "Plant_Moss_Rug_Lime"
    },
    {
      "x": -19,
      "y": 104,
      "z": -2,
      "name": "Plant_Leaves_Azure",
      "rotation": 2
    },
    {
      "x": -19,
      "y": 105,
      "z": -2,
      "name": "Plant_Leaves_Azure",
      "rotation": 2
    },
    {
      "x": -19,
      "y": 106,
      "z": -2,
      "name": "Plant_Leaves_Azure",
      "rotation": 2
    },
    {
      "x": -19,
      "y": 107,
      "z": -2,
      "name": "Plant_Leaves_Azure",
      "rotation": 2
    },
    {
      "x": -19,
      "y": 108,
      "z": -2,
      "name": "Plant_Fruit_Azure",
      "rotation": 2
    },
    {
      "x": -19,
      "y": 91,
      "z": -1,
      "name": "Rock_Crystal_Blue_Block"
    },
    {
      "x": -19,
      "y": 92,
      "z": -1,
      "name": "Rock_Marble"
    },
    {
      "x": -19,
      "y": 93,
      "z": -1,
      "name": "Rock_Marble"
    },
    {
      "x": -19,
      "y": 94,
      "z": -1,
      "name": "Rock_Marble"
    },
    {
      "x": -19,
      "y": 95,
      "z": -1,
      "name": "Rock_Marble"
    },
    {
      "x": -19,
      "y": 96,
      "z": -1,
      "name": "Rock_Marble"
    },
    {
      "x": -19,
      "y": 97,
      "z": -1,
      "name": "Wood_Azure_Trunk_Full",
      "rotation": 2
    },
    {
      "x": -19,
      "y": 98,
      "z": -1,
      "name": "Wood_Azure_Trunk_Full",
      "rotation": 2
    },
    {
      "x": -19,
      "y": 99,
      "z": -1,
      "name": "Plant_Moss_Rug_Blue"
    },
    {
      "x": -19,
      "y": 105,
      "z": -1,
      "name": "Plant_Leaves_Azure",
      "rotation": 2
    },
    {
      "x": -19,
      "y": 106,
      "z": -1,
      "name": "Plant_Leaves_Azure",
      "rotation": 2
    },
    {
      "x": -19,
      "y": 107,
      "z": -1,
      "name": "Plant_Leaves_Azure",
      "rotation": 2
    },
    {
      "x": -19,
      "y": 91,
      "z": 0,
      "name": "Rock_Crystal_Blue_Block"
    },
    {
      "x": -19,
      "y": 92,
      "z": 0,
      "name": "Rock_Marble"
    },
    {
      "x": -19,
      "y": 93,
      "z": 0,
      "name": "Rock_Marble"
    },
    {
      "x": -19,
      "y": 94,
      "z": 0,
      "name": "Rock_Marble"
    },
    {
      "x": -19,
      "y": 95,
      "z": 0,
      "name": "Rock_Marble"
    },
    {
      "x": -19,
      "y": 96,
      "z": 0,
      "name": "Wood_Azure_Roots",
      "rotation": 2
    },
    {
      "x": -19,
      "y": 97,
      "z": 0,
      "name": "Wood_Azure_Trunk_Full",
      "rotation": 2
    },
    {
      "x": -19,
      "y": 98,
      "z": 0,
      "name": "Wood_Azure_Trunk",
      "rotation": 2
    },
    {
      "x": -19,
      "y": 99,
      "z": 0,
      "name": "Wood_Azure_Trunk_Full",
      "rotation": 2
    },
    {
      "x": -19,
      "y": 107,
      "z": 0,
      "name": "Plant_Leaves_Azure",
      "rotation": 2
    },
    {
      "x": -19,
      "y": 111,
      "z": 0,
      "name": "Plant_Leaves_Azure",
      "rotation": 2
    },
    {
      "x": -19,
      "y": 112,
      "z": 0,
      "name": "Plant_Leaves_Azure",
      "rotation": 2
    },
    {
      "x": -19,
      "y": 92,
      "z": 1,
      "name": "Rock_Crystal_Blue_Block"
    },
    {
      "x": -19,
      "y": 93,
      "z": 1,
      "name": "Rock_Marble"
    },
    {
      "x": -19,
      "y": 94,
      "z": 1,
      "name": "Rock_Marble"
    },
    {
      "x": -19,
      "y": 95,
      "z": 1,
      "name": "Rock_Marble"
    },
    {
      "x": -19,
      "y": 96,
      "z": 1,
      "name": "Rock_Marble"
    },
    {
      "x": -19,
      "y": 97,
      "z": 1,
      "name": "Plant_Moss_Block_Blue"
    },
    {
      "x": -19,
      "y": 98,
      "z": 1,
      "name": "Wood_Azure_Trunk_Full",
      "rotation": 2
    },
    {
      "x": -19,
      "y": 99,
      "z": 1,
      "name": "Wood_Azure_Trunk",
      "rotation": 2
    },
    {
      "x": -19,
      "y": 100,
      "z": 1,
      "name": "Wood_Azure_Trunk",
      "rotation": 2
    },
    {
      "x": -19,
      "y": 101,
      "z": 1,
      "name": "Wood_Azure_Trunk_Full",
      "rotation": 2
    },
    {
      "x": -19,
      "y": 111,
      "z": 1,
      "name": "Plant_Leaves_Azure",
      "rotation": 2
    },
    {
      "x": -19,
      "y": 112,
      "z": 1,
      "name": "Plant_Leaves_Azure",
      "rotation": 2
    },
    {
      "x": -19,
      "y": 113,
      "z": 1,
      "name": "Plant_Fruit_Azure",
      "rotation": 2
    },
    {
      "x": -19,
      "y": 115,
      "z": 1,
      "name": "Plant_Leaves_Azure",
      "rotation": 2
    },
    {
      "x": -19,
      "y": 91,
      "z": 2,
      "name": "Plant_Crop_Mushroom_Block_Blue_Mycelium"
    },
    {
      "x": -19,
      "y": 92,
      "z": 2,
      "name": "Rock_Crystal_Blue_Block"
    },
    {
      "x": -19,
      "y": 93,
      "z": 2,
      "name": "Rock_Marble"
    },
    {
      "x": -19,
      "y": 94,
      "z": 2,
      "name": "Rock_Marble"
    },
    {
      "x": -19,
      "y": 95,
      "z": 2,
      "name": "Rock_Marble"
    },
    {
      "x": -19,
      "y": 96,
      "z": 2,
      "name": "Plant_Moss_Block_Blue"
    },
    {
      "x": -19,
      "y": 97,
      "z": 2,
      "name": "Plant_Moss_Block_Blue"
    },
    {
      "x": -19,
      "y": 98,
      "z": 2,
      "name": "Plant_Moss_Rug_Blue"
    },
    {
      "x": -19,
      "y": 101,
      "z": 2,
      "name": "Wood_Azure_Trunk_Full",
      "rotation": 2
    },
    {
      "x": -19,
      "y": 102,
      "z": 2,
      "name": "Wood_Azure_Trunk",
      "rotation": 2
    },
    {
      "x": -19,
      "y": 103,
      "z": 2,
      "name": "Wood_Azure_Trunk",
      "rotation": 2
    },
    {
      "x": -19,
      "y": 104,
      "z": 2,
      "name": "Wood_Azure_Trunk_Full",
      "rotation": 2
    },
    {
      "x": -19,
      "y": 106,
      "z": 2,
      "name": "Plant_Moss_Wall_Blue",
      "rotation": 2
    },
    {
      "x": -19,
      "y": 108,
      "z": 2,
      "name": "Wood_Azure_Branch_Long",
      "rotation": 7
    },
    {
      "x": -19,
      "y": 109,
      "z": 2,
      "name": "Plant_Moss_Wall_Blue",
      "rotation": 3
    },
    {
      "x": -19,
      "y": 112,
      "z": 2,
      "name": "Plant_Leaves_Azure",
      "rotation": 2
    },
    {
      "x": -19,
      "y": 115,
      "z": 2,
      "name": "Plant_Leaves_Azure",
      "rotation": 2
    },
    {
      "x": -19,
      "y": 116,
      "z": 2,
      "name": "Plant_Leaves_Azure",
      "rotation": 2
    },
    {
      "x": -19,
      "y": 90,
      "z": 3,
      "name": "Rock_Crystal_Blue_Block"
    },
    {
      "x": -19,
      "y": 91,
      "z": 3,
      "name": "Rock_Marble"
    },
    {
      "x": -19,
      "y": 92,
      "z": 3,
      "name": "Rock_Marble"
    },
    {
      "x": -19,
      "y": 93,
      "z": 3,
      "name": "Rock_Marble"
    },
    {
      "x": -19,
      "y": 94,
      "z": 3,
      "name": "Rock_Marble"
    },
    {
      "x": -19,
      "y": 95,
      "z": 3,
      "name": "Rock_Marble"
    },
    {
      "x": -19,
      "y": 96,
      "z": 3,
      "name": "Plant_Moss_Block_Blue"
    },
    {
      "x": -19,
      "y": 97,
      "z": 3,
      "name": "Plant_Moss_Block_Blue"
    },
    {
      "x": -19,
      "y": 98,
      "z": 3,
      "name": "Plant_Moss_Short_Green_Dark"
    },
    {
      "x": -19,
      "y": 103,
      "z": 3,
      "name": "Wood_Azure_Trunk_Full",
      "rotation": 2
    },
    {
      "x": -19,
      "y": 104,
      "z": 3,
      "name": "Wood_Azure_Trunk",
      "rotation": 2
    },
    {
      "x": -19,
      "y": 105,
      "z": 3,
      "name": "Wood_Azure_Trunk",
      "rotation": 2
    },
    {
      "x": -19,
      "y": 106,
      "z": 3,
      "name": "Wood_Azure_Trunk_Full",
      "rotation": 2
    },
    {
      "x": -19,
      "y": 107,
      "z": 3,
      "name": "Plant_Moss_Rug_Blue",
      "rotation": 2
    },
    {
      "x": -19,
      "y": 115,
      "z": 3,
      "name": "Plant_Leaves_Azure",
      "rotation": 2
    },
    {
      "x": -19,
      "y": 116,
      "z": 3,
      "name": "Plant_Leaves_Azure",
      "rotation": 2
    },
    {
      "x": -19,
      "y": 117,
      "z": 3,
      "name": "Plant_Leaves_Azure",
      "rotation": 2
    },
    {
      "x": -19,
      "y": 92,
      "z": 4,
      "name": "Rock_Crystal_Blue_Block"
    },
    {
      "x": -19,
      "y": 93,
      "z": 4,
      "name": "Rock_Marble"
    },
    {
      "x": -19,
      "y": 94,
      "z": 4,
      "name": "Rock_Marble"
    },
    {
      "x": -19,
      "y": 95,
      "z": 4,
      "name": "Plant_Moss_Block_Blue"
    },
    {
      "x": -19,
      "y": 96,
      "z": 4,
      "name": "Plant_Moss_Block_Blue"
    },
    {
      "x": -19,
      "y": 97,
      "z": 4,
      "name": "Plant_Moss_Short_Green_Dark"
    },
    {
      "x": -19,
      "y": 106,
      "z": 4,
      "name": "Plant_Moss_Wall_Blue"
    },
    {
      "x": -19,
      "y": 111,
      "z": 4,
      "name": "Plant_Leaves_Azure",
      "rotation": 2
    },
    {
      "x": -19,
      "y": 117,
      "z": 4,
      "name": "Plant_Leaves_Azure",
      "rotation": 2
    },
    {
      "x": -19,
      "y": 92,
      "z": 5,
      "name": "Rock_Crystal_Blue_Block"
    },
    {
      "x": -19,
      "y": 93,
      "z": 5,
      "name": "Rock_Marble"
    },
    {
      "x": -19,
      "y": 94,
      "z": 5,
      "name": "Rock_Marble"
    },
    {
      "x": -19,
      "y": 95,
      "z": 5,
      "name": "Plant_Moss_Block_Blue"
    },
    {
      "x": -19,
      "y": 96,
      "z": 5,
      "name": "Plant_Moss_Block_Blue"
    },
    {
      "x": -19,
      "y": 97,
      "z": 5,
      "name": "Plant_Moss_Rug_Lime"
    },
    {
      "x": -19,
      "y": 110,
      "z": 5,
      "name": "Plant_Leaves_Azure",
      "rotation": 2
    },
    {
      "x": -19,
      "y": 111,
      "z": 5,
      "name": "Plant_Leaves_Azure",
      "rotation": 2
    },
    {
      "x": -19,
      "y": 112,
      "z": 5,
      "name": "Plant_Leaves_Azure",
      "rotation": 2
    },
    {
      "x": -19,
      "y": 113,
      "z": 5,
      "name": "Plant_Fruit_Azure",
      "rotation": 2
    },
    {
      "x": -19,
      "y": 89,
      "z": 6,
      "name": "Plant_Crop_Mushroom_Block_Blue_Mycelium"
    },
    {
      "x": -19,
      "y": 90,
      "z": 6,
      "name": "Rock_Crystal_Blue_Block"
    },
    {
      "x": -19,
      "y": 91,
      "z": 6,
      "name": "Rock_Crystal_Blue_Block"
    },
    {
      "x": -19,
      "y": 92,
      "z": 6,
      "name": "Rock_Marble"
    },
    {
      "x": -19,
      "y": 93,
      "z": 6,
      "name": "Rock_Marble"
    },
    {
      "x": -19,
      "y": 94,
      "z": 6,
      "name": "Rock_Marble"
    },
    {
      "x": -19,
      "y": 95,
      "z": 6,
      "name": "Plant_Moss_Block_Blue"
    },
    {
      "x": -19,
      "y": 96,
      "z": 6,
      "name": "Plant_Moss_Block_Blue"
    },
    {
      "x": -19,
      "y": 97,
      "z": 6,
      "name": "Plant_Moss_Short_Green_Dark"
    },
    {
      "x": -19,
      "y": 106,
      "z": 6,
      "name": "Plant_Leaves_Azure",
      "rotation": 2
    },
    {
      "x": -19,
      "y": 107,
      "z": 6,
      "name": "Plant_Leaves_Azure",
      "rotation": 2
    },
    {
      "x": -19,
      "y": 111,
      "z": 6,
      "name": "Plant_Leaves_Azure",
      "rotation": 2
    },
    {
      "x": -19,
      "y": 112,
      "z": 6,
      "name": "Plant_Leaves_Azure",
      "rotation": 2
    },
    {
      "x": -19,
      "y": 113,
      "z": 6,
      "name": "Plant_Leaves_Azure",
      "rotation": 2
    },
    {
      "x": -19,
      "y": 90,
      "z": 7,
      "name": "Plant_Crop_Mushroom_Block_Blue_Mycelium"
    },
    {
      "x": -19,
      "y": 91,
      "z": 7,
      "name": "Rock_Crystal_Blue_Block"
    },
    {
      "x": -19,
      "y": 92,
      "z": 7,
      "name": "Rock_Marble"
    },
    {
      "x": -19,
      "y": 93,
      "z": 7,
      "name": "Rock_Marble"
    },
    {
      "x": -19,
      "y": 94,
      "z": 7,
      "name": "Rock_Marble"
    },
    {
      "x": -19,
      "y": 95,
      "z": 7,
      "name": "Plant_Moss_Block_Blue"
    },
    {
      "x": -19,
      "y": 96,
      "z": 7,
      "name": "Plant_Moss_Block_Blue"
    },
    {
      "x": -19,
      "y": 97,
      "z": 7,
      "name": "Plant_Moss_Rug_Lime"
    },
    {
      "x": -19,
      "y": 105,
      "z": 7,
      "name": "Plant_Leaves_Azure",
      "rotation": 2
    },
    {
      "x": -19,
      "y": 106,
      "z": 7,
      "name": "Plant_Leaves_Azure",
      "rotation": 2
    },
    {
      "x": -19,
      "y": 107,
      "z": 7,
      "name": "Plant_Leaves_Azure",
      "rotation": 2
    },
    {
      "x": -19,
      "y": 91,
      "z": 8,
      "name": "Rock_Crystal_Blue_Block"
    },
    {
      "x": -19,
      "y": 92,
      "z": 8,
      "name": "Rock_Marble"
    },
    {
      "x": -19,
      "y": 93,
      "z": 8,
      "name": "Rock_Marble"
    },
    {
      "x": -19,
      "y": 94,
      "z": 8,
      "name": "Rock_Marble"
    },
    {
      "x": -19,
      "y": 95,
      "z": 8,
      "name": "Plant_Moss_Block_Blue"
    },
    {
      "x": -19,
      "y": 96,
      "z": 8,
      "name": "Plant_Moss_Block_Blue"
    },
    {
      "x": -19,
      "y": 97,
      "z": 8,
      "name": "Plant_Moss_Short_Green_Dark"
    },
    {
      "x": -19,
      "y": 103,
      "z": 8,
      "name": "Plant_Leaves_Azure",
      "rotation": 2
    },
    {
      "x": -19,
      "y": 104,
      "z": 8,
      "name": "Plant_Leaves_Azure",
      "rotation": 2
    },
    {
      "x": -19,
      "y": 105,
      "z": 8,
      "name": "Plant_Leaves_Azure",
      "rotation": 2
    },
    {
      "x": -19,
      "y": 106,
      "z": 8,
      "name": "Plant_Leaves_Azure",
      "rotation": 2
    },
    {
      "x": -19,
      "y": 107,
      "z": 8,
      "name": "Plant_Leaves_Azure",
      "rotation": 2
    },
    {
      "x": -19,
      "y": 108,
      "z": 8,
      "name": "Plant_Leaves_Azure",
      "rotation": 2
    },
    {
      "x": -19,
      "y": 88,
      "z": 9,
      "name": "Rock_Crystal_Blue_Medium"
    },
    {
      "x": -19,
      "y": 89,
      "z": 9,
      "name": "Rock_Crystal_Blue_Block"
    },
    {
      "x": -19,
      "y": 90,
      "z": 9,
      "name": "Rock_Marble"
    },
    {
      "x": -19,
      "y": 91,
      "z": 9,
      "name": "Rock_Marble"
    },
    {
      "x": -19,
      "y": 92,
      "z": 9,
      "name": "Rock_Marble"
    },
    {
      "x": -19,
      "y": 93,
      "z": 9,
      "name": "Rock_Marble"
    },
    {
      "x": -19,
      "y": 94,
      "z": 9,
      "name": "Plant_Moss_Block_Blue"
    },
    {
      "x": -19,
      "y": 95,
      "z": 9,
      "name": "Plant_Moss_Block_Blue"
    },
    {
      "x": -19,
      "y": 96,
      "z": 9,
      "name": "Plant_Moss_Rug_Blue"
    },
    {
      "x": -19,
      "y": 104,
      "z": 9,
      "name": "Plant_Leaves_Azure",
      "rotation": 2
    },
    {
      "x": -19,
      "y": 105,
      "z": 9,
      "name": "Plant_Leaves_Azure",
      "rotation": 2
    },
    {
      "x": -19,
      "y": 106,
      "z": 9,
      "name": "Plant_Leaves_Azure",
      "rotation": 2
    },
    {
      "x": -19,
      "y": 107,
      "z": 9,
      "name": "Plant_Leaves_Azure",
      "rotation": 2
    },
    {
      "x": -19,
      "y": 90,
      "z": 10,
      "name": "Rock_Marble"
    },
    {
      "x": -19,
      "y": 91,
      "z": 10,
      "name": "Rock_Marble"
    },
    {
      "x": -19,
      "y": 92,
      "z": 10,
      "name": "Rock_Marble"
    },
    {
      "x": -19,
      "y": 93,
      "z": 10,
      "name": "Rock_Marble"
    },
    {
      "x": -19,
      "y": 94,
      "z": 10,
      "name": "Plant_Moss_Block_Blue"
    },
    {
      "x": -19,
      "y": 95,
      "z": 10,
      "name": "Plant_Moss_Block_Blue"
    },
    {
      "x": -19,
      "y": 96,
      "z": 10,
      "name": "Plant_Moss_Short_Green_Dark"
    },
    {
      "x": -19,
      "y": 91,
      "z": 11,
      "name": "Rock_Marble"
    },
    {
      "x": -19,
      "y": 92,
      "z": 11,
      "name": "Rock_Marble"
    },
    {
      "x": -19,
      "y": 93,
      "z": 11,
      "name": "Rock_Marble"
    },
    {
      "x": -19,
      "y": 94,
      "z": 11,
      "name": "Plant_Moss_Block_Blue"
    },
    {
      "x": -19,
      "y": 95,
      "z": 11,
      "name": "Plant_Moss_Block_Blue"
    },
    {
      "x": -19,
      "y": 96,
      "z": 11,
      "name": "Plant_Moss_Rug_Blue"
    },
    {
      "x": -19,
      "y": 91,
      "z": 12,
      "name": "Plant_Moss_Wall_Blue",
      "support": 15
    },
    {
      "x": -19,
      "y": 93,
      "z": 12,
      "name": "Plant_Moss_Block_Blue"
    },
    {
      "x": -19,
      "y": 94,
      "z": 12,
      "name": "Plant_Moss_Block_Blue"
    },
    {
      "x": -19,
      "y": 95,
      "z": 12,
      "name": "Plant_Moss_Rug_Lime"
    },
    {
      "x": -19,
      "y": 93,
      "z": 13,
      "name": "Plant_Moss_Block_Blue"
    },
    {
      "x": -19,
      "y": 94,
      "z": 13,
      "name": "Plant_Moss_Rug_Blue"
    },
    {
      "x": -18,
      "y": 95,
      "z": -11,
      "name": "Plant_Moss_Wall_Blue",
      "support": 15,
      "rotation": 2
    },
    {
      "x": -18,
      "y": 96,
      "z": -11,
      "name": "Plant_Moss_Block_Blue"
    },
    {
      "x": -18,
      "y": 97,
      "z": -11,
      "name": "Plant_Moss_Block_Blue"
    },
    {
      "x": -18,
      "y": 98,
      "z": -11,
      "name": "Plant_Moss_Short_Green_Dark"
    },
    {
      "x": -18,
      "y": 95,
      "z": -10,
      "name": "Rock_Marble"
    },
    {
      "x": -18,
      "y": 96,
      "z": -10,
      "name": "Rock_Marble"
    },
    {
      "x": -18,
      "y": 97,
      "z": -10,
      "name": "Plant_Moss_Block_Blue"
    },
    {
      "x": -18,
      "y": 98,
      "z": -10,
      "name": "Plant_Moss_Block_Blue"
    },
    {
      "x": -18,
      "y": 99,
      "z": -10,
      "name": "Plant_Moss_Blue"
    },
    {
      "x": -18,
      "y": 95,
      "z": -9,
      "name": "Rock_Crystal_Blue_Block"
    },
    {
      "x": -18,
      "y": 96,
      "z": -9,
      "name": "Rock_Marble"
    },
    {
      "x": -18,
      "y": 97,
      "z": -9,
      "name": "Rock_Marble"
    },
    {
      "x": -18,
      "y": 98,
      "z": -9,
      "name": "Plant_Moss_Block_Blue"
    },
    {
      "x": -18,
      "y": 99,
      "z": -9,
      "name": "Plant_Moss_Block_Blue"
    },
    {
      "x": -18,
      "y": 100,
      "z": -9,
      "name": "Plant_Moss_Short_Green_Dark"
    },
    {
      "x": -18,
      "y": 94,
      "z": -8,
      "name": "Plant_Crop_Mushroom_Block_Blue_Mycelium"
    },
    {
      "x": -18,
      "y": 95,
      "z": -8,
      "name": "Rock_Crystal_Blue_Block"
    },
    {
      "x": -18,
      "y": 96,
      "z": -8,
      "name": "Rock_Marble"
    },
    {
      "x": -18,
      "y": 97,
      "z": -8,
      "name": "Rock_Marble"
    },
    {
      "x": -18,
      "y": 98,
      "z": -8,
      "name": "Plant_Moss_Block_Blue"
    },
    {
      "x": -18,
      "y": 99,
      "z": -8,
      "name": "Plant_Moss_Block_Blue"
    },
    {
      "x": -18,
      "y": 100,
      "z": -8,
      "name": "Plant_Moss_Short_Green_Dark"
    },
    {
      "x": -18,
      "y": 91,
      "z": -7,
      "name": "Rock_Crystal_Blue_Small"
    },
    {
      "x": -18,
      "y": 92,
      "z": -7,
      "name": "Rock_Crystal_Blue_Block"
    },
    {
      "x": -18,
      "y": 93,
      "z": -7,
      "name": "Rock_Marble"
    },
    {
      "x": -18,
      "y": 94,
      "z": -7,
      "name": "Rock_Marble"
    },
    {
      "x": -18,
      "y": 95,
      "z": -7,
      "name": "Rock_Marble"
    },
    {
      "x": -18,
      "y": 96,
      "z": -7,
      "name": "Rock_Marble"
    },
    {
      "x": -18,
      "y": 97,
      "z": -7,
      "name": "Rock_Marble"
    },
    {
      "x": -18,
      "y": 98,
      "z": -7,
      "name": "Plant_Moss_Block_Blue"
    },
    {
      "x": -18,
      "y": 99,
      "z": -7,
      "name": "Plant_Moss_Block_Blue"
    },
    {
      "x": -18,
      "y": 100,
      "z": -7,
      "name": "Plant_Moss_Rug_Blue"
    },
    {
      "x": -18,
      "y": 87,
      "z": -6,
      "name": "Rock_Crystal_Blue_Block"
    },
    {
      "x": -18,
      "y": 88,
      "z": -6,
      "name": "Rock_Crystal_Blue_Block"
    },
    {
      "x": -18,
      "y": 89,
      "z": -6,
      "name": "Rock_Marble"
    },
    {
      "x": -18,
      "y": 90,
      "z": -6,
      "name": "Rock_Marble"
    },
    {
      "x": -18,
      "y": 91,
      "z": -6,
      "name": "Rock_Marble"
    },
    {
      "x": -18,
      "y": 92,
      "z": -6,
      "name": "Rock_Marble"
    },
    {
      "x": -18,
      "y": 93,
      "z": -6,
      "name": "Rock_Marble"
    },
    {
      "x": -18,
      "y": 94,
      "z": -6,
      "name": "Rock_Marble"
    },
    {
      "x": -18,
      "y": 95,
      "z": -6,
      "name": "Rock_Marble"
    },
    {
      "x": -18,
      "y": 96,
      "z": -6,
      "name": "Rock_Marble"
    },
    {
      "x": -18,
      "y": 97,
      "z": -6,
      "name": "Rock_Marble"
    },
    {
      "x": -18,
      "y": 98,
      "z": -6,
      "name": "Plant_Moss_Block_Blue"
    },
    {
      "x": -18,
      "y": 99,
      "z": -6,
      "name": "Plant_Moss_Block_Blue"
    },
    {
      "x": -18,
      "y": 100,
      "z": -6,
      "name": "Plant_Moss_Rug_Blue"
    },
    {
      "x": -18,
      "y": 86,
      "z": -5,
      "name": "Rock_Crystal_Blue_Block"
    },
    {
      "x": -18,
      "y": 87,
      "z": -5,
      "name": "Rock_Crystal_Blue_Block"
    },
    {
      "x": -18,
      "y": 88,
      "z": -5,
      "name": "Rock_Marble"
    },
    {
      "x": -18,
      "y": 89,
      "z": -5,
      "name": "Rock_Marble"
    },
    {
      "x": -18,
      "y": 90,
      "z": -5,
      "name": "Rock_Marble"
    },
    {
      "x": -18,
      "y": 91,
      "z": -5,
      "name": "Rock_Marble"
    },
    {
      "x": -18,
      "y": 92,
      "z": -5,
      "name": "Rock_Marble"
    },
    {
      "x": -18,
      "y": 93,
      "z": -5,
      "name": "Rock_Marble"
    },
    {
      "x": -18,
      "y": 94,
      "z": -5,
      "name": "Rock_Marble"
    },
    {
      "x": -18,
      "y": 95,
      "z": -5,
      "name": "Rock_Marble"
    },
    {
      "x": -18,
      "y": 96,
      "z": -5,
      "name": "Rock_Marble"
    },
    {
      "x": -18,
      "y": 97,
      "z": -5,
      "name": "Rock_Marble"
    },
    {
      "x": -18,
      "y": 98,
      "z": -5,
      "name": "Plant_Moss_Block_Blue"
    },
    {
      "x": -18,
      "y": 99,
      "z": -5,
      "name": "Plant_Moss_Block_Blue"
    },
    {
      "x": -18,
      "y": 100,
      "z": -5,
      "name": "Plant_Moss_Blue"
    },
    {
      "x": -18,
      "y": 87,
      "z": -4,
      "name": "Rock_Crystal_Blue_Block"
    },
    {
      "x": -18,
      "y": 88,
      "z": -4,
      "name": "Rock_Crystal_Blue_Block"
    },
    {
      "x": -18,
      "y": 89,
      "z": -4,
      "name": "Rock_Marble"
    },
    {
      "x": -18,
      "y": 90,
      "z": -4,
      "name": "Rock_Marble"
    },
    {
      "x": -18,
      "y": 91,
      "z": -4,
      "name": "Rock_Marble"
    },
    {
      "x": -18,
      "y": 92,
      "z": -4,
      "name": "Rock_Marble"
    },
    {
      "x": -18,
      "y": 93,
      "z": -4,
      "name": "Rock_Marble"
    },
    {
      "x": -18,
      "y": 94,
      "z": -4,
      "name": "Rock_Marble"
    },
    {
      "x": -18,
      "y": 95,
      "z": -4,
      "name": "Rock_Marble"
    },
    {
      "x": -18,
      "y": 96,
      "z": -4,
      "name": "Rock_Marble"
    },
    {
      "x": -18,
      "y": 97,
      "z": -4,
      "name": "Rock_Marble"
    },
    {
      "x": -18,
      "y": 98,
      "z": -4,
      "name": "Plant_Moss_Block_Blue"
    },
    {
      "x": -18,
      "y": 99,
      "z": -4,
      "name": "Plant_Moss_Block_Blue"
    },
    {
      "x": -18,
      "y": 100,
      "z": -4,
      "name": "Plant_Moss_Blue"
    },
    {
      "x": -18,
      "y": 89,
      "z": -3,
      "name": "Rock_Crystal_Blue_Medium"
    },
    {
      "x": -18,
      "y": 90,
      "z": -3,
      "name": "Rock_Crystal_Blue_Block"
    },
    {
      "x": -18,
      "y": 91,
      "z": -3,
      "name": "Rock_Marble"
    },
    {
      "x": -18,
      "y": 92,
      "z": -3,
      "name": "Rock_Marble"
    },
    {
      "x": -18,
      "y": 93,
      "z": -3,
      "name": "Rock_Marble"
    },
    {
      "x": -18,
      "y": 94,
      "z": -3,
      "name": "Rock_Marble"
    },
    {
      "x": -18,
      "y": 95,
      "z": -3,
      "name": "Rock_Marble"
    },
    {
      "x": -18,
      "y": 96,
      "z": -3,
      "name": "Rock_Marble"
    },
    {
      "x": -18,
      "y": 97,
      "z": -3,
      "name": "Rock_Marble"
    },
    {
      "x": -18,
      "y": 98,
      "z": -3,
      "name": "Plant_Moss_Block_Blue"
    },
    {
      "x": -18,
      "y": 99,
      "z": -3,
      "name": "Plant_Moss_Block_Blue"
    },
    {
      "x": -18,
      "y": 100,
      "z": -3,
      "name": "Plant_Moss_Rug_Lime"
    },
    {
      "x": -18,
      "y": 104,
      "z": -3,
      "name": "Plant_Leaves_Azure",
      "rotation": 2
    },
    {
      "x": -18,
      "y": 89,
      "z": -2,
      "name": "Rock_Crystal_Blue_Block"
    },
    {
      "x": -18,
      "y": 90,
      "z": -2,
      "name": "Rock_Crystal_Blue_Block"
    },
    {
      "x": -18,
      "y": 91,
      "z": -2,
      "name": "Rock_Marble"
    },
    {
      "x": -18,
      "y": 92,
      "z": -2,
      "name": "Rock_Marble"
    },
    {
      "x": -18,
      "y": 93,
      "z": -2,
      "name": "Rock_Marble"
    },
    {
      "x": -18,
      "y": 94,
      "z": -2,
      "name": "Rock_Marble"
    },
    {
      "x": -18,
      "y": 95,
      "z": -2,
      "name": "Rock_Marble"
    },
    {
      "x": -18,
      "y": 96,
      "z": -2,
      "name": "Rock_Marble"
    },
    {
      "x": -18,
      "y": 97,
      "z": -2,
      "name": "Rock_Marble"
    },
    {
      "x": -18,
      "y": 98,
      "z": -2,
      "name": "Plant_Moss_Block_Blue"
    },
    {
      "x": -18,
      "y": 99,
      "z": -2,
      "name": "Plant_Moss_Block_Blue"
    },
    {
      "x": -18,
      "y": 100,
      "z": -2,
      "name": "Plant_Moss_Rug_Lime"
    },
    {
      "x": -18,
      "y": 103,
      "z": -2,
      "name": "Plant_Leaves_Azure",
      "rotation": 2
    },
    {
      "x": -18,
      "y": 104,
      "z": -2,
      "name": "Plant_Leaves_Azure",
      "rotation": 2
    },
    {
      "x": -18,
      "y": 105,
      "z": -2,
      "name": "Plant_Leaves_Azure",
      "rotation": 2
    },
    {
      "x": -18,
      "y": 106,
      "z": -2,
      "name": "Plant_Leaves_Azure",
      "rotation": 2
    },
    {
      "x": -18,
      "y": 89,
      "z": -1,
      "name": "Rock_Crystal_Blue_Block"
    },
    {
      "x": -18,
      "y": 90,
      "z": -1,
      "name": "Rock_Crystal_Blue_Block"
    },
    {
      "x": -18,
      "y": 91,
      "z": -1,
      "name": "Rock_Marble"
    },
    {
      "x": -18,
      "y": 92,
      "z": -1,
      "name": "Rock_Marble"
    },
    {
      "x": -18,
      "y": 93,
      "z": -1,
      "name": "Rock_Marble"
    },
    {
      "x": -18,
      "y": 94,
      "z": -1,
      "name": "Rock_Marble"
    },
    {
      "x": -18,
      "y": 95,
      "z": -1,
      "name": "Rock_Marble"
    },
    {
      "x": -18,
      "y": 96,
      "z": -1,
      "name": "Rock_Marble"
    },
    {
      "x": -18,
      "y": 97,
      "z": -1,
      "name": "Rock_Marble"
    },
    {
      "x": -18,
      "y": 98,
      "z": -1,
      "name": "Plant_Moss_Block_Blue"
    },
    {
      "x": -18,
      "y": 99,
      "z": -1,
      "name": "Plant_Moss_Block_Blue"
    },
    {
      "x": -18,
      "y": 100,
      "z": -1,
      "name": "Plant_Moss_Rug_Blue"
    },
    {
      "x": -18,
      "y": 103,
      "z": -1,
      "name": "Plant_Leaves_Azure",
      "rotation": 2
    },
    {
      "x": -18,
      "y": 104,
      "z": -1,
      "name": "Wood_Azure_Branch_Long",
      "rotation": 6
    },
    {
      "x": -18,
      "y": 106,
      "z": -1,
      "name": "Plant_Leaves_Azure",
      "rotation": 2
    },
    {
      "x": -18,
      "y": 109,
      "z": -1,
      "name": "Plant_Leaves_Azure",
      "rotation": 2
    },
    {
      "x": -18,
      "y": 110,
      "z": -1,
      "name": "Plant_Leaves_Azure",
      "rotation": 2
    },
    {
      "x": -18,
      "y": 111,
      "z": -1,
      "name": "Plant_Leaves_Azure",
      "rotation": 2
    },
    {
      "x": -18,
      "y": 90,
      "z": 0,
      "name": "Plant_Crop_Mushroom_Block_Blue_Mycelium"
    },
    {
      "x": -18,
      "y": 91,
      "z": 0,
      "name": "Rock_Crystal_Blue_Block"
    },
    {
      "x": -18,
      "y": 92,
      "z": 0,
      "name": "Rock_Marble"
    },
    {
      "x": -18,
      "y": 93,
      "z": 0,
      "name": "Rock_Marble"
    },
    {
      "x": -18,
      "y": 94,
      "z": 0,
      "name": "Rock_Marble"
    },
    {
      "x": -18,
      "y": 95,
      "z": 0,
      "name": "Rock_Marble"
    },
    {
      "x": -18,
      "y": 96,
      "z": 0,
      "name": "Rock_Marble"
    },
    {
      "x": -18,
      "y": 97,
      "z": 0,
      "name": "Plant_Moss_Block_Blue"
    },
    {
      "x": -18,
      "y": 98,
      "z": 0,
      "name": "Wood_Azure_Trunk_Full",
      "rotation": 2
    },
    {
      "x": -18,
      "y": 99,
      "z": 0,
      "name": "Wood_Azure_Trunk",
      "rotation": 2
    },
    {
      "x": -18,
      "y": 100,
      "z": 0,
      "name": "Wood_Azure_Trunk_Full",
      "rotation": 2
    },
    {
      "x": -18,
      "y": 104,
      "z": 0,
      "name": "Wood_Azure_Branch_Long",
      "rotation": 6
    },
    {
      "x": -18,
      "y": 110,
      "z": 0,
      "name": "Plant_Leaves_Azure",
      "rotation": 2
    },
    {
      "x": -18,
      "y": 111,
      "z": 0,
      "name": "Wood_Azure_Branch_Long",
      "rotation": 6
    },
    {
      "x": -18,
      "y": 112,
      "z": 0,
      "name": "Plant_Leaves_Azure",
      "rotation": 2
    },
    {
      "x": -18,
      "y": 91,
      "z": 1,
      "name": "Rock_Crystal_Blue_Block"
    },
    {
      "x": -18,
      "y": 92,
      "z": 1,
      "name": "Rock_Marble"
    },
    {
      "x": -18,
      "y": 93,
      "z": 1,
      "name": "Rock_Marble"
    },
    {
      "x": -18,
      "y": 94,
      "z": 1,
      "name": "Rock_Marble"
    },
    {
      "x": -18,
      "y": 95,
      "z": 1,
      "name": "Rock_Marble"
    },
    {
      "x": -18,
      "y": 96,
      "z": 1,
      "name": "Rock_Marble"
    },
    {
      "x": -18,
      "y": 97,
      "z": 1,
      "name": "Plant_Moss_Block_Blue"
    },
    {
      "x": -18,
      "y": 98,
      "z": 1,
      "name": "Wood_Azure_Trunk_Full",
      "rotation": 2
    },
    {
      "x": -18,
      "y": 99,
      "z": 1,
      "name": "Wood_Azure_Trunk",
      "rotation": 2
    },
    {
      "x": -18,
      "y": 100,
      "z": 1,
      "name": "Wood_Azure_Trunk",
      "rotation": 2
    },
    {
      "x": -18,
      "y": 101,
      "z": 1,
      "name": "Wood_Azure_Trunk",
      "rotation": 2
    },
    {
      "x": -18,
      "y": 102,
      "z": 1,
      "name": "Wood_Azure_Trunk",
      "rotation": 2
    },
    {
      "x": -18,
      "y": 103,
      "z": 1,
      "name": "Wood_Azure_Trunk",
      "rotation": 2
    },
    {
      "x": -18,
      "y": 104,
      "z": 1,
      "name": "Wood_Azure_Trunk",
      "rotation": 2
    },
    {
      "x": -18,
      "y": 105,
      "z": 1,
      "name": "Wood_Azure_Trunk_Full",
      "rotation": 2
    },
    {
      "x": -18,
      "y": 109,
      "z": 1,
      "name": "Plant_Moss_Wall_Blue",
      "rotation": 2
    },
    {
      "x": -18,
      "y": 111,
      "z": 1,
      "name": "Wood_Azure_Branch_Long",
      "rotation": 6
    },
    {
      "x": -18,
      "y": 114,
      "z": 1,
      "name": "Plant_Leaves_Azure",
      "rotation": 2
    },
    {
      "x": -18,
      "y": 115,
      "z": 1,
      "name": "Plant_Leaves_Azure",
      "rotation": 2
    },
    {
      "x": -18,
      "y": 116,
      "z": 1,
      "name": "Plant_Leaves_Azure",
      "rotation": 2
    },
    {
      "x": -18,
      "y": 90,
      "z": 2,
      "name": "Plant_Crop_Mushroom_Block_Blue_Mycelium"
    },
    {
      "x": -18,
      "y": 91,
      "z": 2,
      "name": "Rock_Crystal_Blue_Block"
    },
    {
      "x": -18,
      "y": 92,
      "z": 2,
      "name": "Rock_Marble"
    },
    {
      "x": -18,
      "y": 93,
      "z": 2,
      "name": "Rock_Marble"
    },
    {
      "x": -18,
      "y": 94,
      "z": 2,
      "name": "Rock_Marble"
    },
    {
      "x": -18,
      "y": 95,
      "z": 2,
      "name": "Rock_Marble"
    },
    {
      "x": -18,
      "y": 96,
      "z": 2,
      "name": "Rock_Marble"
    },
    {
      "x": -18,
      "y": 97,
      "z": 2,
      "name": "Plant_Moss_Block_Blue"
    },
    {
      "x": -18,
      "y": 98,
      "z": 2,
      "name": "Plant_Moss_Block_Blue"
    },
    {
      "x": -18,
      "y": 99,
      "z": 2,
      "name": "Wood_Azure_Trunk",
      "rotation": 2
    },
    {
      "x": -18,
      "y": 100,
      "z": 2,
      "name": "Wood_Azure_Trunk",
      "rotation": 2
    },
    {
      "x": -18,
      "y": 101,
      "z": 2,
      "name": "Wood_Azure_Trunk",
      "rotation": 2
    },
    {
      "x": -18,
      "y": 102,
      "z": 2,
      "name": "Wood_Azure_Trunk",
      "rotation": 2
    },
    {
      "x": -18,
      "y": 103,
      "z": 2,
      "name": "Wood_Azure_Trunk",
      "rotation": 2
    },
    {
      "x": -18,
      "y": 104,
      "z": 2,
      "name": "Wood_Azure_Trunk",
      "rotation": 2
    },
    {
      "x": -18,
      "y": 105,
      "z": 2,
      "name": "Wood_Azure_Trunk",
      "rotation": 2
    },
    {
      "x": -18,
      "y": 106,
      "z": 2,
      "name": "Wood_Azure_Trunk",
      "rotation": 2
    },
    {
      "x": -18,
      "y": 107,
      "z": 2,
      "name": "Wood_Azure_Trunk",
      "rotation": 2
    },
    {
      "x": -18,
      "y": 108,
      "z": 2,
      "name": "Wood_Azure_Trunk",
      "rotation": 2
    },
    {
      "x": -18,
      "y": 109,
      "z": 2,
      "name": "Wood_Azure_Trunk_Full",
      "rotation": 2
    },
    {
      "x": -18,
      "y": 110,
      "z": 2,
      "name": "Plant_Moss_Rug_Blue",
      "rotation": 2
    },
    {
      "x": -18,
      "y": 111,
      "z": 2,
      "name": "Wood_Azure_Branch_Long",
      "rotation": 6
    },
    {
      "x": -18,
      "y": 114,
      "z": 2,
      "name": "Plant_Leaves_Azure",
      "rotation": 2
    },
    {
      "x": -18,
      "y": 115,
      "z": 2,
      "name": "Plant_Leaves_Azure",
      "rotation": 2
    },
    {
      "x": -18,
      "y": 116,
      "z": 2,
      "name": "Plant_Leaves_Azure",
      "rotation": 2
    },
    {
      "x": -18,
      "y": 117,
      "z": 2,
      "name": "Plant_Leaves_Azure",
      "rotation": 2
    },
    {
      "x": -18,
      "y": 90,
      "z": 3,
      "name": "Rock_Crystal_Blue_Block"
    },
    {
      "x": -18,
      "y": 91,
      "z": 3,
      "name": "Rock_Marble"
    },
    {
      "x": -18,
      "y": 92,
      "z": 3,
      "name": "Rock_Marble"
    },
    {
      "x": -18,
      "y": 93,
      "z": 3,
      "name": "Rock_Marble"
    },
    {
      "x": -18,
      "y": 94,
      "z": 3,
      "name": "Rock_Marble"
    },
    {
      "x": -18,
      "y": 95,
      "z": 3,
      "name": "Rock_Marble"
    },
    {
      "x": -18,
      "y": 96,
      "z": 3,
      "name": "Plant_Moss_Block_Blue"
    },
    {
      "x": -18,
      "y": 97,
      "z": 3,
      "name": "Plant_Moss_Block_Blue"
    },
    {
      "x": -18,
      "y": 98,
      "z": 3,
      "name": "Wood_Azure_Trunk_Full",
      "rotation": 2
    },
    {
      "x": -18,
      "y": 99,
      "z": 3,
      "name": "Wood_Azure_Trunk",
      "rotation": 2
    },
    {
      "x": -18,
      "y": 100,
      "z": 3,
      "name": "Wood_Azure_Trunk",
      "rotation": 2
    },
    {
      "x": -18,
      "y": 101,
      "z": 3,
      "name": "Wood_Azure_Trunk",
      "rotation": 2
    },
    {
      "x": -18,
      "y": 102,
      "z": 3,
      "name": "Wood_Azure_Trunk",
      "rotation": 2
    },
    {
      "x": -18,
      "y": 103,
      "z": 3,
      "name": "Wood_Azure_Trunk",
      "rotation": 2
    },
    {
      "x": -18,
      "y": 104,
      "z": 3,
      "name": "Wood_Azure_Trunk",
      "rotation": 2
    },
    {
      "x": -18,
      "y": 105,
      "z": 3,
      "name": "Wood_Azure_Trunk",
      "rotation": 2
    },
    {
      "x": -18,
      "y": 106,
      "z": 3,
      "name": "Wood_Azure_Trunk",
      "rotation": 2
    },
    {
      "x": -18,
      "y": 107,
      "z": 3,
      "name": "Wood_Azure_Trunk",
      "rotation": 2
    },
    {
      "x": -18,
      "y": 108,
      "z": 3,
      "name": "Wood_Azure_Trunk",
      "rotation": 2
    },
    {
      "x": -18,
      "y": 109,
      "z": 3,
      "name": "Wood_Azure_Trunk",
      "rotation": 2
    },
    {
      "x": -18,
      "y": 110,
      "z": 3,
      "name": "Wood_Azure_Trunk",
      "rotation": 2
    },
    {
      "x": -18,
      "y": 111,
      "z": 3,
      "name": "Wood_Azure_Trunk_Full",
      "rotation": 2
    },
    {
      "x": -18,
      "y": 114,
      "z": 3,
      "name": "Plant_Moss_Wall_Blue",
      "rotation": 3
    },
    {
      "x": -18,
      "y": 116,
      "z": 3,
      "name": "Plant_Leaves_Azure",
      "rotation": 2
    },
    {
      "x": -18,
      "y": 117,
      "z": 3,
      "name": "Plant_Leaves_Azure",
      "rotation": 2
    },
    {
      "x": -18,
      "y": 118,
      "z": 3,
      "name": "Plant_Leaves_Azure",
      "rotation": 2
    },
    {
      "x": -18,
      "y": 119,
      "z": 3,
      "name": "Plant_Fruit_Azure",
      "rotation": 2
    },
    {
      "x": -18,
      "y": 88,
      "z": 4,
      "name": "Rock_Crystal_Blue_Block"
    },
    {
      "x": -18,
      "y": 89,
      "z": 4,
      "name": "Rock_Crystal_Blue_Block"
    },
    {
      "x": -18,
      "y": 90,
      "z": 4,
      "name": "Rock_Marble"
    },
    {
      "x": -18,
      "y": 91,
      "z": 4,
      "name": "Rock_Marble"
    },
    {
      "x": -18,
      "y": 92,
      "z": 4,
      "name": "Rock_Marble"
    },
    {
      "x": -18,
      "y": 93,
      "z": 4,
      "name": "Rock_Marble"
    },
    {
      "x": -18,
      "y": 94,
      "z": 4,
      "name": "Rock_Marble"
    },
    {
      "x": -18,
      "y": 95,
      "z": 4,
      "name": "Rock_Marble"
    },
    {
      "x": -18,
      "y": 96,
      "z": 4,
      "name": "Plant_Moss_Block_Blue"
    },
    {
      "x": -18,
      "y": 97,
      "z": 4,
      "name": "Plant_Moss_Block_Blue"
    },
    {
      "x": -18,
      "y": 98,
      "z": 4,
      "name": "Wood_Azure_Trunk_Full",
      "rotation": 2
    },
    {
      "x": -18,
      "y": 99,
      "z": 4,
      "name": "Wood_Azure_Trunk",
      "rotation": 2
    },
    {
      "x": -18,
      "y": 100,
      "z": 4,
      "name": "Wood_Azure_Trunk_Full",
      "rotation": 2
    },
    {
      "x": -18,
      "y": 106,
      "z": 4,
      "name": "Wood_Azure_Trunk_Full",
      "rotation": 2
    },
    {
      "x": -18,
      "y": 107,
      "z": 4,
      "name": "Wood_Azure_Trunk",
      "rotation": 2
    },
    {
      "x": -18,
      "y": 108,
      "z": 4,
      "name": "Wood_Azure_Trunk_Full",
      "rotation": 2
    },
    {
      "x": -18,
      "y": 111,
      "z": 4,
      "name": "Wood_Azure_Branch_Long",
      "rotation": 6
    },
    {
      "x": -18,
      "y": 116,
      "z": 4,
      "name": "Plant_Leaves_Azure",
      "rotation": 2
    },
    {
      "x": -18,
      "y": 117,
      "z": 4,
      "name": "Plant_Leaves_Azure",
      "rotation": 2
    },
    {
      "x": -18,
      "y": 118,
      "z": 4,
      "name": "Plant_Leaves_Azure",
      "rotation": 2
    },
    {
      "x": -18,
      "y": 119,
      "z": 4,
      "name": "Plant_Leaves_Azure",
      "rotation": 2
    },
    {
      "x": -18,
      "y": 88,
      "z": 5,
      "name": "Rock_Crystal_Blue_Block"
    },
    {
      "x": -18,
      "y": 89,
      "z": 5,
      "name": "Rock_Crystal_Blue_Block"
    },
    {
      "x": -18,
      "y": 90,
      "z": 5,
      "name": "Rock_Crystal_Blue_Block"
    },
    {
      "x": -18,
      "y": 91,
      "z": 5,
      "name": "Rock_Marble"
    },
    {
      "x": -18,
      "y": 92,
      "z": 5,
      "name": "Rock_Marble"
    },
    {
      "x": -18,
      "y": 93,
      "z": 5,
      "name": "Rock_Marble"
    },
    {
      "x": -18,
      "y": 94,
      "z": 5,
      "name": "Rock_Marble"
    },
    {
      "x": -18,
      "y": 95,
      "z": 5,
      "name": "Rock_Marble"
    },
    {
      "x": -18,
      "y": 96,
      "z": 5,
      "name": "Plant_Moss_Block_Blue"
    },
    {
      "x": -18,
      "y": 97,
      "z": 5,
      "name": "Plant_Moss_Block_Blue"
    },
    {
      "x": -18,
      "y": 98,
      "z": 5,
      "name": "Plant_Moss_Blue"
    },
    {
      "x": -18,
      "y": 106,
      "z": 5,
      "name": "Wood_Azure_Branch_Long",
      "rotation": 6
    },
    {
      "x": -18,
      "y": 111,
      "z": 5,
      "name": "Plant_Leaves_Azure",
      "rotation": 2
    },
    {
      "x": -18,
      "y": 112,
      "z": 5,
      "name": "Plant_Leaves_Azure",
      "rotation": 2
    },
    {
      "x": -18,
      "y": 113,
      "z": 5,
      "name": "Plant_Leaves_Azure",
      "rotation": 2
    },
    {
      "x": -18,
      "y": 114,
      "z": 5,
      "name": "Plant_Leaves_Azure",
      "rotation": 2
    },
    {
      "x": -18,
      "y": 88,
      "z": 6,
      "name": "Rock_Crystal_Blue_Small"
    },
    {
      "x": -18,
      "y": 89,
      "z": 6,
      "name": "Rock_Crystal_Blue_Block"
    },
    {
      "x": -18,
      "y": 90,
      "z": 6,
      "name": "Rock_Marble"
    },
    {
      "x": -18,
      "y": 91,
      "z": 6,
      "name": "Rock_Marble"
    },
    {
      "x": -18,
      "y": 92,
      "z": 6,
      "name": "Rock_Marble"
    },
    {
      "x": -18,
      "y": 93,
      "z": 6,
      "name": "Rock_Marble"
    },
    {
      "x": -18,
      "y": 94,
      "z": 6,
      "name": "Rock_Marble"
    },
    {
      "x": -18,
      "y": 95,
      "z": 6,
      "name": "Plant_Moss_Block_Blue"
    },
    {
      "x": -18,
      "y": 96,
      "z": 6,
      "name": "Plant_Moss_Block_Blue"
    },
    {
      "x": -18,
      "y": 97,
      "z": 6,
      "name": "Plant_Moss_Rug_Blue"
    },
    {
      "x": -18,
      "y": 106,
      "z": 6,
      "name": "Wood_Azure_Branch_Long",
      "rotation": 6
    },
    {
      "x": -18,
      "y": 112,
      "z": 6,
      "name": "Plant_Leaves_Azure",
      "rotation": 2
    },
    {
      "x": -18,
      "y": 113,
      "z": 6,
      "name": "Plant_Leaves_Azure",
      "rotation": 2
    },
    {
      "x": -18,
      "y": 114,
      "z": 6,
      "name": "Plant_Leaves_Azure",
      "rotation": 2
    },
    {
      "x": -18,
      "y": 87,
      "z": 7,
      "name": "Rock_Crystal_Blue_Block"
    },
    {
      "x": -18,
      "y": 88,
      "z": 7,
      "name": "Rock_Crystal_Blue_Block"
    },
    {
      "x": -18,
      "y": 89,
      "z": 7,
      "name": "Rock_Crystal_Blue_Block"
    },
    {
      "x": -18,
      "y": 90,
      "z": 7,
      "name": "Rock_Marble"
    },
    {
      "x": -18,
      "y": 91,
      "z": 7,
      "name": "Rock_Marble"
    },
    {
      "x": -18,
      "y": 92,
      "z": 7,
      "name": "Rock_Marble"
    },
    {
      "x": -18,
      "y": 93,
      "z": 7,
      "name": "Rock_Marble"
    },
    {
      "x": -18,
      "y": 94,
      "z": 7,
      "name": "Rock_Marble"
    },
    {
      "x": -18,
      "y": 95,
      "z": 7,
      "name": "Plant_Moss_Block_Blue"
    },
    {
      "x": -18,
      "y": 96,
      "z": 7,
      "name": "Plant_Moss_Block_Blue"
    },
    {
      "x": -18,
      "y": 97,
      "z": 7,
      "name": "Plant_Moss_Rug_Lime"
    },
    {
      "x": -18,
      "y": 105,
      "z": 7,
      "name": "Plant_Leaves_Azure",
      "rotation": 2
    },
    {
      "x": -18,
      "y": 106,
      "z": 7,
      "name": "Wood_Azure_Branch_Long",
      "rotation": 6
    },
    {
      "x": -18,
      "y": 107,
      "z": 7,
      "name": "Plant_Leaves_Azure",
      "rotation": 2
    },
    {
      "x": -18,
      "y": 108,
      "z": 7,
      "name": "Plant_Leaves_Azure",
      "rotation": 2
    },
    {
      "x": -18,
      "y": 88,
      "z": 8,
      "name": "Plant_Crop_Mushroom_Block_Blue_Mycelium"
    },
    {
      "x": -18,
      "y": 89,
      "z": 8,
      "name": "Rock_Crystal_Blue_Block"
    },
    {
      "x": -18,
      "y": 90,
      "z": 8,
      "name": "Rock_Marble"
    },
    {
      "x": -18,
      "y": 91,
      "z": 8,
      "name": "Rock_Marble"
    },
    {
      "x": -18,
      "y": 92,
      "z": 8,
      "name": "Rock_Marble"
    },
    {
      "x": -18,
      "y": 93,
      "z": 8,
      "name": "Rock_Marble"
    },
    {
      "x": -18,
      "y": 94,
      "z": 8,
      "name": "Rock_Marble"
    },
    {
      "x": -18,
      "y": 95,
      "z": 8,
      "name": "Plant_Moss_Block_Blue"
    },
    {
      "x": -18,
      "y": 96,
      "z": 8,
      "name": "Plant_Moss_Block_Blue"
    },
    {
      "x": -18,
      "y": 97,
      "z": 8,
      "name": "Plant_Moss_Rug_Blue"
    },
    {
      "x": -18,
      "y": 104,
      "z": 8,
      "name": "Plant_Leaves_Azure",
      "rotation": 2
    },
    {
      "x": -18,
      "y": 105,
      "z": 8,
      "name": "Plant_Leaves_Azure",
      "rotation": 2
    },
    {
      "x": -18,
      "y": 106,
      "z": 8,
      "name": "Plant_Leaves_Azure",
      "rotation": 2
    },
    {
      "x": -18,
      "y": 107,
      "z": 8,
      "name": "Plant_Leaves_Azure",
      "rotation": 2
    },
    {
      "x": -18,
      "y": 108,
      "z": 8,
      "name": "Plant_Leaves_Azure",
      "rotation": 2
    },
    {
      "x": -18,
      "y": 109,
      "z": 8,
      "name": "Plant_Fruit_Azure",
      "rotation": 2
    },
    {
      "x": -18,
      "y": 85,
      "z": 9,
      "name": "Rock_Crystal_Blue_Block"
    },
    {
      "x": -18,
      "y": 86,
      "z": 9,
      "name": "Rock_Crystal_Blue_Block"
    },
    {
      "x": -18,
      "y": 87,
      "z": 9,
      "name": "Rock_Crystal_Blue_Block"
    },
    {
      "x": -18,
      "y": 88,
      "z": 9,
      "name": "Rock_Marble"
    },
    {
      "x": -18,
      "y": 89,
      "z": 9,
      "name": "Rock_Marble"
    },
    {
      "x": -18,
      "y": 90,
      "z": 9,
      "name": "Rock_Marble"
    },
    {
      "x": -18,
      "y": 91,
      "z": 9,
      "name": "Rock_Marble"
    },
    {
      "x": -18,
      "y": 92,
      "z": 9,
      "name": "Rock_Marble"
    },
    {
      "x": -18,
      "y": 93,
      "z": 9,
      "name": "Rock_Marble"
    },
    {
      "x": -18,
      "y": 94,
      "z": 9,
      "name": "Rock_Marble"
    },
    {
      "x": -18,
      "y": 95,
      "z": 9,
      "name": "Plant_Moss_Block_Blue"
    },
    {
      "x": -18,
      "y": 96,
      "z": 9,
      "name": "Plant_Moss_Block_Blue"
    },
    {
      "x": -18,
      "y": 97,
      "z": 9,
      "name": "Plant_Moss_Rug_Blue"
    },
    {
      "x": -18,
      "y": 104,
      "z": 9,
      "name": "Plant_Leaves_Azure",
      "rotation": 2
    },
    {
      "x": -18,
      "y": 105,
      "z": 9,
      "name": "Plant_Leaves_Azure",
      "rotation": 2
    },
    {
      "x": -18,
      "y": 106,
      "z": 9,
      "name": "Plant_Leaves_Azure",
      "rotation": 2
    },
    {
      "x": -18,
      "y": 107,
      "z": 9,
      "name": "Plant_Leaves_Azure",
      "rotation": 2
    },
    {
      "x": -18,
      "y": 87,
      "z": 10,
      "name": "Plant_Crop_Mushroom_Block_Blue_Mycelium"
    },
    {
      "x": -18,
      "y": 88,
      "z": 10,
      "name": "Rock_Crystal_Blue_Block"
    },
    {
      "x": -18,
      "y": 89,
      "z": 10,
      "name": "Rock_Marble"
    },
    {
      "x": -18,
      "y": 90,
      "z": 10,
      "name": "Rock_Marble"
    },
    {
      "x": -18,
      "y": 91,
      "z": 10,
      "name": "Rock_Marble"
    },
    {
      "x": -18,
      "y": 92,
      "z": 10,
      "name": "Rock_Marble"
    },
    {
      "x": -18,
      "y": 93,
      "z": 10,
      "name": "Rock_Marble"
    },
    {
      "x": -18,
      "y": 94,
      "z": 10,
      "name": "Plant_Moss_Block_Blue"
    },
    {
      "x": -18,
      "y": 95,
      "z": 10,
      "name": "Plant_Moss_Block_Blue"
    },
    {
      "x": -18,
      "y": 96,
      "z": 10,
      "name": "Plant_Moss_Short_Green_Dark"
    },
    {
      "x": -18,
      "y": 88,
      "z": 11,
      "name": "Rock_Marble"
    },
    {
      "x": -18,
      "y": 89,
      "z": 11,
      "name": "Rock_Marble"
    },
    {
      "x": -18,
      "y": 90,
      "z": 11,
      "name": "Rock_Marble"
    },
    {
      "x": -18,
      "y": 91,
      "z": 11,
      "name": "Rock_Marble"
    },
    {
      "x": -18,
      "y": 92,
      "z": 11,
      "name": "Rock_Marble"
    },
    {
      "x": -18,
      "y": 93,
      "z": 11,
      "name": "Rock_Marble"
    },
    {
      "x": -18,
      "y": 94,
      "z": 11,
      "name": "Plant_Moss_Block_Blue"
    },
    {
      "x": -18,
      "y": 95,
      "z": 11,
      "name": "Plant_Moss_Block_Blue"
    },
    {
      "x": -18,
      "y": 96,
      "z": 11,
      "name": "Plant_Moss_Rug_Lime"
    },
    {
      "x": -18,
      "y": 90,
      "z": 12,
      "name": "Plant_Moss_Wall_Blue",
      "support": 15
    },
    {
      "x": -18,
      "y": 91,
      "z": 12,
      "name": "Rock_Marble"
    },
    {
      "x": -18,
      "y": 92,
      "z": 12,
      "name": "Rock_Marble"
    },
    {
      "x": -18,
      "y": 93,
      "z": 12,
      "name": "Plant_Moss_Block_Blue"
    },
    {
      "x": -18,
      "y": 94,
      "z": 12,
      "name": "Plant_Moss_Block_Blue"
    },
    {
      "x": -18,
      "y": 95,
      "z": 12,
      "name": "Plant_Moss_Rug_Blue"
    },
    {
      "x": -18,
      "y": 91,
      "z": 13,
      "name": "Rock_Marble"
    },
    {
      "x": -18,
      "y": 92,
      "z": 13,
      "name": "Plant_Moss_Block_Blue"
    },
    {
      "x": -18,
      "y": 93,
      "z": 13,
      "name": "Plant_Moss_Block_Blue"
    },
    {
      "x": -18,
      "y": 94,
      "z": 13,
      "name": "Plant_Moss_Short_Green_Dark"
    },
    {
      "x": -18,
      "y": 93,
      "z": 14,
      "name": "Plant_Moss_Rug_Blue"
    },
    {
      "x": -18,
      "y": 92,
      "z": 15,
      "name": "Plant_Moss_Block_Blue"
    },
    {
      "x": -18,
      "y": 93,
      "z": 15,
      "name": "Plant_Moss_Rug_Blue"
    },
    {
      "x": -17,
      "y": 95,
      "z": -12,
      "name": "Plant_Moss_Wall_Blue",
      "support": 15,
      "rotation": 2
    },
    {
      "x": -17,
      "y": 97,
      "z": -12,
      "name": "Plant_Moss_Block_Blue"
    },
    {
      "x": -17,
      "y": 98,
      "z": -12,
      "name": "Plant_Moss_Rug_Blue"
    },
    {
      "x": -17,
      "y": 95,
      "z": -11,
      "name": "Rock_Marble"
    },
    {
      "x": -17,
      "y": 96,
      "z": -11,
      "name": "Rock_Marble"
    },
    {
      "x": -17,
      "y": 97,
      "z": -11,
      "name": "Plant_Moss_Block_Blue"
    },
    {
      "x": -17,
      "y": 98,
      "z": -11,
      "name": "Plant_Moss_Block_Blue"
    },
    {
      "x": -17,
      "y": 99,
      "z": -11,
      "name": "Plant_Moss_Short_Green_Dark"
    },
    {
      "x": -17,
      "y": 94,
      "z": -10,
      "name": "Rock_Marble"
    },
    {
      "x": -17,
      "y": 95,
      "z": -10,
      "name": "Rock_Marble"
    },
    {
      "x": -17,
      "y": 96,
      "z": -10,
      "name": "Rock_Marble"
    },
    {
      "x": -17,
      "y": 97,
      "z": -10,
      "name": "Rock_Marble"
    },
    {
      "x": -17,
      "y": 98,
      "z": -10,
      "name": "Plant_Moss_Block_Blue"
    },
    {
      "x": -17,
      "y": 99,
      "z": -10,
      "name": "Plant_Moss_Block_Blue"
    },
    {
      "x": -17,
      "y": 100,
      "z": -10,
      "name": "Plant_Moss_Short_Green_Dark"
    },
    {
      "x": -17,
      "y": 95,
      "z": -9,
      "name": "Rock_Crystal_Blue_Block"
    },
    {
      "x": -17,
      "y": 96,
      "z": -9,
