{
  "version": 8,
  "blockIdVersion": 11,
  "anchorX": 0,
  "anchorY": 0,
  "anchorZ": 0,
  "blocks": [
    {
      "x": -23,
      "y": 119,
      "z": -6,
      "name": "Plant_Leaves_Azure",
      "rotation": 1
    },
    {
      "x": -23,
      "y": 120,
      "z": -6,
      "name": "Plant_Leaves_Azure",
      "rotation": 1
    },
    {
      "x": -23,
      "y": 121,
      "z": -6,
      "name": "Plant_Leaves_Azure",
      "rotation": 1
    },
    {
      "x": -23,
      "y": 119,
      "z": -5,
      "name": "Plant_Leaves_Azure",
      "rotation": 1
    },
    {
      "x": -23,
      "y": 120,
      "z": -5,
      "name": "Plant_Leaves_Azure",
      "rotation": 1
    },
    {
      "x": -23,
      "y": 121,
      "z": -5,
      "name": "Plant_Leaves_Azure",
      "rotation": 1
    },
    {
      "x": -23,
      "y": 122,
      "z": -5,
      "name": "Plant_Leaves_Azure",
      "rotation": 1
    },
    {
      "x": -23,
      "y": 119,
      "z": -4,
      "name": "Plant_Leaves_Azure",
      "rotation": 1
    },
    {
      "x": -23,
      "y": 120,
      "z": -4,
      "name": "Plant_Leaves_Azure",
      "rotation": 1
    },
    {
      "x": -23,
      "y": 121,
      "z": -4,
      "name": "Plant_Leaves_Azure",
      "rotation": 1
    },
    {
      "x": -23,
      "y": 122,
      "z": -4,
      "name": "Plant_Leaves_Azure",
      "rotation": 1
    },
    {
      "x": -23,
      "y": 120,
      "z": -3,
      "name": "Plant_Leaves_Azure",
      "rotation": 1
    },
    {
      "x": -23,
      "y": 121,
      "z": -3,
      "name": "Plant_Leaves_Azure",
      "rotation": 1
    },
    {
      "x": -23,
      "y": 122,
      "z": -3,
      "name": "Plant_Leaves_Azure",
      "rotation": 1
    },
    {
      "x": -23,
      "y": 123,
      "z": -3,
      "name": "Plant_Leaves_Azure",
      "rotation": 1
    },
    {
      "x": -23,
      "y": 121,
      "z": -2,
      "name": "Plant_Leaves_Azure",
      "rotation": 1
    },
    {
      "x": -23,
      "y": 122,
      "z": -2,
      "name": "Plant_Leaves_Azure",
      "rotation": 1
    },
    {
      "x": -23,
      "y": 123,
      "z": -2,
      "name": "Plant_Leaves_Azure",
      "rotation": 1
    },
    {
      "x": -22,
      "y": 119,
      "z": -7,
      "name": "Plant_Leaves_Azure",
      "rotation": 1
    },
    {
      "x": -22,
      "y": 120,
      "z": -7,
      "name": "Plant_Leaves_Azure",
      "rotation": 1
    },
    {
      "x": -22,
      "y": 121,
      "z": -7,
      "name": "Plant_Leaves_Azure",
      "rotation": 1
    },
    {
      "x": -22,
      "y": 118,
      "z": -6,
      "name": "Plant_Leaves_Azure",
      "rotation": 1
    },
    {
      "x": -22,
      "y": 119,
      "z": -6,
      "name": "Plant_Leaves_Azure",
      "rotation": 1
    },
    {
      "x": -22,
      "y": 120,
      "z": -6,
      "name": "Plant_Leaves_Azure",
      "rotation": 1
    },
    {
      "x": -22,
      "y": 121,
      "z": -6,
      "name": "Plant_Leaves_Azure",
      "rotation": 1
    },
    {
      "x": -22,
      "y": 122,
      "z": -6,
      "name": "Plant_Leaves_Azure",
      "rotation": 1
    },
    {
      "x": -22,
      "y": 118,
      "z": -5,
      "name": "Plant_Leaves_Azure",
      "rotation": 1
    },
    {
      "x": -22,
      "y": 119,
      "z": -5,
      "name": "Plant_Leaves_Azure",
      "rotation": 1
    },
    {
      "x": -22,
      "y": 120,
      "z": -5,
      "name": "Plant_Leaves_Azure",
      "rotation": 1
    },
    {
      "x": -22,
      "y": 121,
      "z": -5,
      "name": "Plant_Leaves_Azure",
      "rotation": 1
    },
    {
      "x": -22,
      "y": 122,
      "z": -5,
      "name": "Plant_Leaves_Azure",
      "rotation": 1
    },
    {
      "x": -22,
      "y": 123,
      "z": -5,
      "name": "Plant_Leaves_Azure",
      "rotation": 1
    },
    {
      "x": -22,
      "y": 119,
      "z": -4,
      "name": "Plant_Leaves_Azure",
      "rotation": 1
    },
    {
      "x": -22,
      "y": 120,
      "z": -4,
      "name": "Plant_Leaves_Azure",
      "rotation": 1
    },
    {
      "x": -22,
      "y": 121,
      "z": -4,
      "name": "Plant_Leaves_Azure",
      "rotation": 1
    },
    {
      "x": -22,
      "y": 122,
      "z": -4,
      "name": "Plant_Leaves_Azure",
      "rotation": 1
    },
    {
      "x": -22,
      "y": 123,
      "z": -4,
      "name": "Plant_Leaves_Azure",
      "rotation": 1
    },
    {
      "x": -22,
      "y": 124,
      "z": -4,
      "name": "Plant_Fruit_Azure",
      "rotation": 1
    },
    {
      "x": -22,
      "y": 119,
      "z": -3,
      "name": "Plant_Leaves_Azure",
      "rotation": 1
    },
    {
      "x": -22,
      "y": 120,
      "z": -3,
      "name": "Plant_Leaves_Azure",
      "rotation": 1
    },
    {
      "x": -22,
      "y": 121,
      "z": -3,
      "name": "Plant_Leaves_Azure",
      "rotation": 1
    },
    {
      "x": -22,
      "y": 122,
      "z": -3,
      "name": "Plant_Leaves_Azure",
      "rotation": 1
    },
    {
      "x": -22,
      "y": 123,
      "z": -3,
      "name": "Plant_Leaves_Azure",
      "rotation": 1
    },
    {
      "x": -22,
      "y": 124,
      "z": -3,
      "name": "Plant_Leaves_Azure",
      "rotation": 1
    },
    {
      "x": -22,
      "y": 120,
      "z": -2,
      "name": "Plant_Leaves_Azure",
      "rotation": 1
    },
    {
      "x": -22,
      "y": 121,
      "z": -2,
      "name": "Plant_Leaves_Azure",
      "rotation": 1
    },
    {
      "x": -22,
      "y": 122,
      "z": -2,
      "name": "Plant_Leaves_Azure",
      "rotation": 1
    },
    {
      "x": -22,
      "y": 123,
      "z": -2,
      "name": "Plant_Leaves_Azure",
      "rotation": 1
    },
    {
      "x": -22,
      "y": 124,
      "z": -2,
      "name": "Plant_Leaves_Azure",
      "rotation": 1
    },
    {
      "x": -22,
      "y": 121,
      "z": -1,
      "name": "Plant_Leaves_Azure",
      "rotation": 1
    },
    {
      "x": -22,
      "y": 122,
      "z": -1,
      "name": "Plant_Leaves_Azure",
      "rotation": 1
    },
    {
      "x": -22,
      "y": 123,
      "z": -1,
      "name": "Plant_Leaves_Azure",
      "rotation": 1
    },
    {
      "x": -22,
      "y": 124,
      "z": -1,
      "name": "Plant_Leaves_Azure",
      "rotation": 1
    },
    {
      "x": -21,
      "y": 118,
      "z": -8,
      "name": "Plant_Leaves_Azure",
      "rotation": 1
    },
    {
      "x": -21,
      "y": 119,
      "z": -8,
      "name": "Plant_Leaves_Azure",
      "rotation": 1
    },
    {
      "x": -21,
      "y": 120,
      "z": -8,
      "name": "Plant_Leaves_Azure",
      "rotation": 1
    },
    {
      "x": -21,
      "y": 118,
      "z": -7,
      "name": "Plant_Leaves_Azure",
      "rotation": 1
    },
    {
      "x": -21,
      "y": 119,
      "z": -7,
      "name": "Plant_Leaves_Azure",
      "rotation": 1
    },
    {
      "x": -21,
      "y": 120,
      "z": -7,
      "name": "Plant_Leaves_Azure",
      "rotation": 1
    },
    {
      "x": -21,
      "y": 121,
      "z": -7,
      "name": "Plant_Leaves_Azure",
      "rotation": 1
    },
    {
      "x": -21,
      "y": 122,
      "z": -7,
      "name": "Plant_Leaves_Azure",
      "rotation": 1
    },
    {
      "x": -21,
      "y": 119,
      "z": -6,
      "name": "Plant_Leaves_Azure",
      "rotation": 1
    },
    {
      "x": -21,
      "y": 120,
      "z": -6,
      "name": "Plant_Leaves_Azure",
      "rotation": 1
    },
    {
      "x": -21,
      "y": 121,
      "z": -6,
      "name": "Plant_Leaves_Azure",
      "rotation": 1
    },
    {
      "x": -21,
      "y": 122,
      "z": -6,
      "name": "Plant_Leaves_Azure",
      "rotation": 1
    },
    {
      "x": -21,
      "y": 123,
      "z": -6,
      "name": "Plant_Fruit_Azure",
      "rotation": 1
    },
    {
      "x": -21,
      "y": 120,
      "z": -5,
      "name": "Plant_Leaves_Azure",
      "rotation": 1
    },
    {
      "x": -21,
      "y": 121,
      "z": -5,
      "name": "Plant_Leaves_Azure",
      "rotation": 1
    },
    {
      "x": -21,
      "y": 122,
      "z": -5,
      "name": "Plant_Leaves_Azure",
      "rotation": 1
    },
    {
      "x": -21,
      "y": 120,
      "z": -4,
      "name": "Plant_Leaves_Azure",
      "rotation": 1
    },
    {
      "x": -21,
      "y": 121,
      "z": -4,
      "name": "Wood_Azure_Branch_Long",
      "rotation": 5
    },
    {
      "x": -21,
      "y": 122,
      "z": -4,
      "name": "Plant_Leaves_Azure",
      "rotation": 1
    },
    {
      "x": -21,
      "y": 123,
      "z": -4,
      "name": "Plant_Leaves_Azure",
      "rotation": 1
    },
    {
      "x": -21,
      "y": 121,
      "z": -3,
      "name": "Plant_Leaves_Azure",
      "rotation": 1
    },
    {
      "x": -21,
      "y": 122,
      "z": -3,
      "name": "Plant_Leaves_Azure",
      "rotation": 1
    },
    {
      "x": -21,
      "y": 123,
      "z": -3,
      "name": "Wood_Azure_Branch_Long",
      "rotation": 5
    },
    {
      "x": -21,
      "y": 124,
      "z": -3,
      "name": "Plant_Leaves_Azure",
      "rotation": 1
    },
    {
      "x": -21,
      "y": 121,
      "z": -2,
      "name": "Plant_Leaves_Azure",
      "rotation": 1
    },
    {
      "x": -21,
      "y": 122,
      "z": -2,
      "name": "Plant_Leaves_Azure",
      "rotation": 1
    },
    {
      "x": -21,
      "y": 123,
      "z": -2,
      "name": "Plant_Leaves_Azure",
      "rotation": 1
    },
    {
      "x": -21,
      "y": 124,
      "z": -2,
      "name": "Plant_Leaves_Azure",
      "rotation": 1
    },
    {
      "x": -21,
      "y": 125,
      "z": -2,
      "name": "Plant_Leaves_Azure",
      "rotation": 1
    },
    {
      "x": -21,
      "y": 121,
      "z": -1,
      "name": "Plant_Leaves_Azure",
      "rotation": 1
    },
    {
      "x": -21,
      "y": 122,
      "z": -1,
      "name": "Plant_Leaves_Azure",
      "rotation": 1
    },
    {
      "x": -21,
      "y": 123,
      "z": -1,
      "name": "Plant_Leaves_Azure",
      "rotation": 1
    },
    {
      "x": -21,
      "y": 124,
      "z": -1,
      "name": "Plant_Leaves_Azure",
      "rotation": 1
    },
    {
      "x": -21,
      "y": 125,
      "z": -1,
      "name": "Plant_Leaves_Azure",
      "rotation": 1
    },
    {
      "x": -21,
      "y": 122,
      "z": 0,
      "name": "Plant_Leaves_Azure",
      "rotation": 1
    },
    {
      "x": -21,
      "y": 123,
      "z": 0,
      "name": "Plant_Leaves_Azure",
      "rotation": 1
    },
    {
      "x": -21,
      "y": 124,
      "z": 0,
      "name": "Plant_Leaves_Azure",
      "rotation": 1
    },
    {
      "x": -20,
      "y": 118,
      "z": -8,
      "name": "Plant_Leaves_Azure",
      "rotation": 1
    },
    {
      "x": -20,
      "y": 119,
      "z": -8,
      "name": "Plant_Leaves_Azure",
      "rotation": 1
    },
    {
      "x": -20,
      "y": 120,
      "z": -8,
      "name": "Plant_Leaves_Azure",
      "rotation": 1
    },
    {
      "x": -20,
      "y": 121,
      "z": -8,
      "name": "Plant_Leaves_Azure",
      "rotation": 1
    },
    {
      "x": -20,
      "y": 118,
      "z": -7,
      "name": "Plant_Leaves_Azure",
      "rotation": 1
    },
    {
      "x": -20,
      "y": 119,
      "z": -7,
      "name": "Plant_Leaves_Azure",
      "rotation": 1
    },
    {
      "x": -20,
      "y": 120,
      "z": -7,
      "name": "Plant_Leaves_Azure",
      "rotation": 1
    },
    {
      "x": -20,
      "y": 121,
      "z": -7,
      "name": "Plant_Leaves_Azure",
      "rotation": 1
    },
    {
      "x": -20,
      "y": 122,
      "z": -7,
      "name": "Plant_Fruit_Azure",
      "rotation": 1
    },
    {
      "x": -20,
      "y": 120,
      "z": -6,
      "name": "Plant_Leaves_Azure",
      "rotation": 1
    },
    {
      "x": -20,
      "y": 121,
      "z": -6,
      "name": "Plant_Leaves_Azure",
      "rotation": 1
    },
    {
      "x": -20,
      "y": 122,
      "z": -6,
      "name": "Plant_Leaves_Azure",
      "rotation": 1
    },
    {
      "x": -20,
      "y": 125,
      "z": -6,
      "name": "Plant_Leaves_Azure",
      "rotation": 1
    },
    {
      "x": -20,
      "y": 126,
      "z": -6,
      "name": "Plant_Leaves_Azure",
      "rotation": 1
    },
    {
      "x": -20,
      "y": 127,
      "z": -6,
      "name": "Plant_Leaves_Azure",
      "rotation": 1
    },
    {
      "x": -20,
      "y": 121,
      "z": -5,
      "name": "Plant_Leaves_Azure",
      "rotation": 1
    },
    {
      "x": -20,
      "y": 122,
      "z": -5,
      "name": "Plant_Leaves_Azure",
      "rotation": 1
    },
    {
      "x": -20,
      "y": 126,
      "z": -5,
      "name": "Plant_Leaves_Azure",
      "rotation": 1
    },
    {
      "x": -20,
      "y": 127,
      "z": -5,
      "name": "Plant_Leaves_Azure",
      "rotation": 1
    },
    {
      "x": -20,
      "y": 128,
      "z": -5,
      "name": "Plant_Leaves_Azure",
      "rotation": 1
    },
    {
      "x": -20,
      "y": 121,
      "z": -4,
      "name": "Wood_Azure_Branch_Long",
      "rotation": 5
    },
    {
      "x": -20,
      "y": 127,
      "z": -4,
      "name": "Plant_Leaves_Azure",
      "rotation": 1
    },
    {
      "x": -20,
      "y": 128,
      "z": -4,
      "name": "Plant_Leaves_Azure",
      "rotation": 1
    },
    {
      "x": -20,
      "y": 129,
      "z": -4,
      "name": "Plant_Leaves_Azure",
      "rotation": 1
    },
    {
      "x": -20,
      "y": 123,
      "z": -3,
      "name": "Wood_Azure_Branch_Long",
      "rotation": 5
    },
    {
      "x": -20,
      "y": 128,
      "z": -3,
      "name": "Plant_Leaves_Azure",
      "rotation": 1
    },
    {
      "x": -20,
      "y": 124,
      "z": -2,
      "name": "Plant_Leaves_Azure",
      "rotation": 1
    },
    {
      "x": -20,
      "y": 125,
      "z": -2,
      "name": "Plant_Leaves_Azure",
      "rotation": 1
    },
    {
      "x": -20,
      "y": 122,
      "z": -1,
      "name": "Plant_Leaves_Azure",
      "rotation": 1
    },
    {
      "x": -20,
      "y": 123,
      "z": -1,
      "name": "Plant_Leaves_Azure",
      "rotation": 1
    },
    {
      "x": -20,
      "y": 124,
      "z": -1,
      "name": "Plant_Leaves_Azure",
      "rotation": 1
    },
    {
      "x": -20,
      "y": 125,
      "z": -1,
      "name": "Plant_Leaves_Azure",
      "rotation": 1
    },
    {
      "x": -20,
      "y": 126,
      "z": -1,
      "name": "Plant_Leaves_Azure",
      "rotation": 1
    },
    {
      "x": -20,
      "y": 122,
      "z": 0,
      "name": "Plant_Leaves_Azure",
      "rotation": 1
    },
    {
      "x": -20,
      "y": 123,
      "z": 0,
      "name": "Plant_Leaves_Azure",
      "rotation": 1
    },
    {
      "x": -20,
      "y": 124,
      "z": 0,
      "name": "Plant_Leaves_Azure",
      "rotation": 1
    },
    {
      "x": -20,
      "y": 125,
      "z": 0,
      "name": "Plant_Leaves_Azure",
      "rotation": 1
    },
    {
      "x": -20,
      "y": 126,
      "z": 0,
      "name": "Plant_Leaves_Azure",
      "rotation": 1
    },
    {
      "x": -20,
      "y": 123,
      "z": 1,
      "name": "Plant_Leaves_Azure",
      "rotation": 1
    },
    {
      "x": -20,
      "y": 124,
      "z": 1,
      "name": "Plant_Leaves_Azure",
      "rotation": 1
    },
    {
      "x": -20,
      "y": 125,
      "z": 1,
      "name": "Plant_Leaves_Azure",
      "rotation": 1
    },
    {
      "x": -19,
      "y": 117,
      "z": -9,
      "name": "Plant_Leaves_Azure",
      "rotation": 1
    },
    {
      "x": -19,
      "y": 118,
      "z": -9,
      "name": "Plant_Leaves_Azure",
      "rotation": 1
    },
    {
      "x": -19,
      "y": 119,
      "z": -9,
      "name": "Plant_Leaves_Azure",
      "rotation": 1
    },
    {
      "x": -19,
      "y": 118,
      "z": -8,
      "name": "Plant_Leaves_Azure",
      "rotation": 1
    },
    {
      "x": -19,
      "y": 119,
      "z": -8,
      "name": "Plant_Leaves_Azure",
      "rotation": 1
    },
    {
      "x": -19,
      "y": 120,
      "z": -8,
      "name": "Plant_Leaves_Azure",
      "rotation": 1
    },
    {
      "x": -19,
      "y": 121,
      "z": -8,
      "name": "Plant_Leaves_Azure",
      "rotation": 1
    },
    {
      "x": -19,
      "y": 118,
      "z": -7,
      "name": "Plant_Leaves_Azure",
      "rotation": 1
    },
    {
      "x": -19,
      "y": 119,
      "z": -7,
      "name": "Plant_Leaves_Azure",
      "rotation": 1
    },
    {
      "x": -19,
      "y": 120,
      "z": -7,
      "name": "Plant_Leaves_Azure",
      "rotation": 1
    },
    {
      "x": -19,
      "y": 121,
      "z": -7,
      "name": "Plant_Leaves_Azure",
      "rotation": 1
    },
    {
      "x": -19,
      "y": 124,
      "z": -7,
      "name": "Plant_Leaves_Azure",
      "rotation": 1
    },
    {
      "x": -19,
      "y": 125,
      "z": -7,
      "name": "Plant_Leaves_Azure",
      "rotation": 1
    },
    {
      "x": -19,
      "y": 126,
      "z": -7,
      "name": "Plant_Leaves_Azure",
      "rotation": 1
    },
    {
      "x": -19,
      "y": 124,
      "z": -6,
      "name": "Plant_Leaves_Azure",
      "rotation": 1
    },
    {
      "x": -19,
      "y": 125,
      "z": -6,
      "name": "Plant_Leaves_Azure",
      "rotation": 1
    },
    {
      "x": -19,
      "y": 126,
      "z": -6,
      "name": "Plant_Leaves_Azure",
      "rotation": 1
    },
    {
      "x": -19,
      "y": 127,
      "z": -6,
      "name": "Plant_Leaves_Azure",
      "rotation": 1
    },
    {
      "x": -19,
      "y": 125,
      "z": -5,
      "name": "Plant_Leaves_Azure",
      "rotation": 1
    },
    {
      "x": -19,
      "y": 126,
      "z": -5,
      "name": "Plant_Leaves_Azure",
      "rotation": 1
    },
    {
      "x": -19,
      "y": 127,
      "z": -5,
      "name": "Plant_Leaves_Azure",
      "rotation": 1
    },
    {
      "x": -19,
      "y": 128,
      "z": -5,
      "name": "Plant_Fruit_Azure",
      "rotation": 1
    },
    {
      "x": -19,
      "y": 121,
      "z": -4,
      "name": "Wood_Azure_Branch_Long",
      "rotation": 5
    },
    {
      "x": -19,
      "y": 126,
      "z": -4,
      "name": "Plant_Leaves_Azure",
      "rotation": 1
    },
    {
      "x": -19,
      "y": 127,
      "z": -4,
      "name": "Plant_Leaves_Azure",
      "rotation": 1
    },
    {
      "x": -19,
      "y": 128,
      "z": -4,
      "name": "Plant_Leaves_Azure",
      "rotation": 1
    },
    {
      "x": -19,
      "y": 129,
      "z": -4,
      "name": "Plant_Leaves_Azure",
      "rotation": 1
    },
    {
      "x": -19,
      "y": 107,
      "z": -3,
      "name": "Plant_Moss_Wall_Blue",
      "support": 15,
      "rotation": 3
    },
    {
      "x": -19,
      "y": 112,
      "z": -3,
      "name": "Wood_Azure_Trunk_Full",
      "rotation": 1
    },
    {
      "x": -19,
      "y": 113,
      "z": -3,
      "name": "Wood_Azure_Trunk_Full",
      "rotation": 1
    },
    {
      "x": -19,
      "y": 123,
      "z": -3,
      "name": "Wood_Azure_Branch_Long",
      "rotation": 5
    },
    {
      "x": -19,
      "y": 128,
      "z": -3,
      "name": "Plant_Leaves_Azure",
      "rotation": 1
    },
    {
      "x": -19,
      "y": 129,
      "z": -3,
      "name": "Plant_Leaves_Azure",
      "rotation": 1
    },
    {
      "x": -19,
      "y": 130,
      "z": -3,
      "name": "Plant_Leaves_Azure",
      "rotation": 1
    },
    {
      "x": -19,
      "y": 110,
      "z": -2,
      "name": "Wood_Azure_Roots",
      "rotation": 1
    },
    {
      "x": -19,
      "y": 111,
      "z": -2,
      "name": "Wood_Azure_Trunk_Full",
      "rotation": 1
    },
    {
      "x": -19,
      "y": 112,
      "z": -2,
      "name": "Wood_Azure_Trunk_Full",
      "rotation": 1
    },
    {
      "x": -19,
      "y": 124,
      "z": -1,
      "name": "Plant_Leaves_Azure",
      "rotation": 1
    },
    {
      "x": -19,
      "y": 125,
      "z": -1,
      "name": "Plant_Leaves_Azure",
      "rotation": 1
    },
    {
      "x": -19,
      "y": 126,
      "z": -1,
      "name": "Plant_Leaves_Azure",
      "rotation": 1
    },
    {
      "x": -19,
      "y": 127,
      "z": -1,
      "name": "Plant_Fruit_Azure",
      "rotation": 1
    },
    {
      "x": -19,
      "y": 105,
      "z": 0,
      "name": "Plant_Moss_Wall_Blue",
      "support": 15,
      "rotation": 3
    },
    {
      "x": -19,
      "y": 107,
      "z": 0,
      "name": "Plant_Moss_Wall_Blue",
      "support": 15,
      "rotation": 3
    },
    {
      "x": -19,
      "y": 123,
      "z": 0,
      "name": "Plant_Leaves_Azure",
      "rotation": 1
    },
    {
      "x": -19,
      "y": 124,
      "z": 0,
      "name": "Plant_Leaves_Azure",
      "rotation": 1
    },
    {
      "x": -19,
      "y": 125,
      "z": 0,
      "name": "Plant_Leaves_Azure",
      "rotation": 1
    },
    {
      "x": -19,
      "y": 126,
      "z": 0,
      "name": "Plant_Leaves_Azure",
      "rotation": 1
    },
    {
      "x": -19,
      "y": 127,
      "z": 0,
      "name": "Plant_Leaves_Azure",
      "rotation": 1
    },
    {
      "x": -19,
      "y": 105,
      "z": 1,
      "name": "Plant_Moss_Wall_Blue",
      "support": 15,
      "rotation": 3
    },
    {
      "x": -19,
      "y": 123,
      "z": 1,
      "name": "Plant_Leaves_Azure",
      "rotation": 1
    },
    {
      "x": -19,
      "y": 124,
      "z": 1,
      "name": "Plant_Leaves_Azure",
      "rotation": 1
    },
    {
      "x": -19,
      "y": 125,
      "z": 1,
      "name": "Plant_Leaves_Azure",
      "rotation": 1
    },
    {
      "x": -19,
      "y": 126,
      "z": 1,
      "name": "Plant_Leaves_Azure",
      "rotation": 1
    },
    {
      "x": -19,
      "y": 107,
      "z": 2,
      "name": "Plant_Moss_Wall_Blue",
      "support": 15,
      "rotation": 3
    },
    {
      "x": -18,
      "y": 117,
      "z": -9,
      "name": "Plant_Leaves_Azure",
      "rotation": 1
    },
    {
      "x": -18,
      "y": 118,
      "z": -9,
      "name": "Plant_Leaves_Azure",
      "rotation": 1
    },
    {
      "x": -18,
      "y": 119,
      "z": -9,
      "name": "Plant_Leaves_Azure",
      "rotation": 1
    },
    {
      "x": -18,
      "y": 120,
      "z": -9,
      "name": "Plant_Leaves_Azure",
      "rotation": 1
    },
    {
      "x": -18,
      "y": 117,
      "z": -8,
      "name": "Plant_Leaves_Azure",
      "rotation": 1
    },
    {
      "x": -18,
      "y": 118,
      "z": -8,
      "name": "Plant_Leaves_Azure",
      "rotation": 1
    },
    {
      "x": -18,
      "y": 119,
      "z": -8,
      "name": "Plant_Leaves_Azure",
      "rotation": 1
    },
    {
      "x": -18,
      "y": 120,
      "z": -8,
      "name": "Plant_Leaves_Azure",
      "rotation": 1
    },
    {
      "x": -18,
      "y": 121,
      "z": -8,
      "name": "Plant_Fruit_Azure",
      "rotation": 1
    },
    {
      "x": -18,
      "y": 123,
      "z": -8,
      "name": "Plant_Leaves_Azure",
      "rotation": 1
    },
    {
      "x": -18,
      "y": 124,
      "z": -8,
      "name": "Plant_Leaves_Azure",
      "rotation": 1
    },
    {
      "x": -18,
      "y": 125,
      "z": -8,
      "name": "Plant_Leaves_Azure",
      "rotation": 1
    },
    {
      "x": -18,
      "y": 104,
      "z": -7,
      "name": "Plant_Moss_Wall_Blue",
      "support": 15,
      "rotation": 3
    },
    {
      "x": -18,
      "y": 106,
      "z": -7,
      "name": "Plant_Moss_Wall_Blue",
      "support": 15,
      "rotation": 3
    },
    {
      "x": -18,
      "y": 118,
      "z": -7,
      "name": "Plant_Leaves_Azure",
      "rotation": 1
    },
    {
      "x": -18,
      "y": 119,
      "z": -7,
      "name": "Plant_Leaves_Azure",
      "rotation": 1
    },
    {
      "x": -18,
      "y": 123,
      "z": -7,
      "name": "Plant_Leaves_Azure",
      "rotation": 1
    },
    {
      "x": -18,
      "y": 124,
      "z": -7,
      "name": "Plant_Leaves_Azure",
      "rotation": 1
    },
    {
      "x": -18,
      "y": 125,
      "z": -7,
      "name": "Plant_Leaves_Azure",
      "rotation": 1
    },
    {
      "x": -18,
      "y": 126,
      "z": -7,
      "name": "Plant_Leaves_Azure",
      "rotation": 1
    },
    {
      "x": -18,
      "y": 127,
      "z": -7,
      "name": "Plant_Fruit_Azure",
      "rotation": 1
    },
    {
      "x": -18,
      "y": 106,
      "z": -6,
      "name": "Plant_Moss_Wall_Blue",
      "support": 15,
      "rotation": 3
    },
    {
      "x": -18,
      "y": 107,
      "z": -6,
      "name": "Plant_Moss_Wall_Blue",
      "support": 15,
      "rotation": 3
    },
    {
      "x": -18,
      "y": 108,
      "z": -6,
      "name": "Plant_Moss_Wall_Blue",
      "support": 15,
      "rotation": 3
    },
    {
      "x": -18,
      "y": 125,
      "z": -6,
      "name": "Plant_Leaves_Azure",
      "rotation": 1
    },
    {
      "x": -18,
      "y": 126,
      "z": -6,
      "name": "Plant_Leaves_Azure",
      "rotation": 1
    },
    {
      "x": -18,
      "y": 104,
      "z": -5,
      "name": "Plant_Moss_Wall_Blue",
      "support": 15,
      "rotation": 3
    },
    {
      "x": -18,
      "y": 105,
      "z": -5,
      "name": "Plant_Moss_Wall_Blue",
      "support": 15,
      "rotation": 3
    },
    {
      "x": -18,
      "y": 107,
      "z": -5,
      "name": "Plant_Moss_Wall_Blue",
      "support": 15,
      "rotation": 3
    },
    {
      "x": -18,
      "y": 112,
      "z": -5,
      "name": "Plant_Moss_Wall_Blue",
      "support": 15,
      "rotation": 3
    },
    {
      "x": -18,
      "y": 121,
      "z": -5,
      "name": "Plant_Moss_Wall_Blue",
      "rotation": 3
    },
    {
      "x": -18,
      "y": 126,
      "z": -5,
      "name": "Plant_Leaves_Azure",
      "rotation": 1
    },
    {
      "x": -18,
      "y": 132,
      "z": -5,
      "name": "Plant_Leaves_Azure",
      "rotation": 1
    },
    {
      "x": -18,
      "y": 106,
      "z": -4,
      "name": "Rock_Marble"
    },
    {
      "x": -18,
      "y": 107,
      "z": -4,
      "name": "Plant_Moss_Block_Blue"
    },
    {
      "x": -18,
      "y": 108,
      "z": -4,
      "name": "Plant_Moss_Short_Green_Dark"
    },
    {
      "x": -18,
      "y": 111,
      "z": -4,
      "name": "Plant_Moss_Wall_Blue",
      "support": 15,
      "rotation": 3
    },
    {
      "x": -18,
      "y": 112,
      "z": -4,
      "name": "Plant_Moss_Wall_Blue",
      "support": 15,
      "rotation": 3
    },
    {
      "x": -18,
      "y": 113,
      "z": -4,
      "name": "Wood_Azure_Trunk_Full",
      "rotation": 1
    },
    {
      "x": -18,
      "y": 114,
      "z": -4,
      "name": "Wood_Azure_Trunk",
      "rotation": 1
    },
    {
      "x": -18,
      "y": 115,
      "z": -4,
      "name": "Wood_Azure_Trunk_Full",
      "rotation": 1
    },
    {
      "x": -18,
      "y": 121,
      "z": -4,
      "name": "Wood_Azure_Trunk_Full",
      "rotation": 1
    },
    {
      "x": -18,
      "y": 122,
      "z": -4,
      "name": "Wood_Azure_Trunk",
      "rotation": 1
    },
    {
      "x": -18,
      "y": 123,
      "z": -4,
      "name": "Wood_Azure_Trunk_Full",
      "rotation": 1
    },
    {
      "x": -18,
      "y": 126,
      "z": -4,
      "name": "Wood_Azure_Branch_Long",
      "rotation": 5
    },
    {
      "x": -18,
      "y": 131,
      "z": -4,
      "name": "Plant_Leaves_Azure",
      "rotation": 1
    },
    {
      "x": -18,
      "y": 132,
      "z": -4,
      "name": "Plant_Leaves_Azure",
      "rotation": 1
    },
    {
      "x": -18,
      "y": 133,
      "z": -4,
      "name": "Plant_Leaves_Azure",
      "rotation": 1
    },
    {
      "x": -18,
      "y": 134,
      "z": -4,
      "name": "Plant_Leaves_Azure",
      "rotation": 1
    },
    {
      "x": -18,
      "y": 105,
      "z": -3,
      "name": "Plant_Moss_Wall_Blue",
      "support": 15,
      "rotation": 3
    },
    {
      "x": -18,
      "y": 106,
      "z": -3,
      "name": "Rock_Marble"
    },
    {
      "x": -18,
      "y": 107,
      "z": -3,
      "name": "Plant_Moss_Block_Blue"
    },
    {
      "x": -18,
      "y": 108,
      "z": -3,
      "name": "Plant_Moss_Rug_Blue"
    },
    {
      "x": -18,
      "y": 111,
      "z": -3,
      "name": "Wood_Azure_Roots",
      "rotation": 1
    },
    {
      "x": -18,
      "y": 112,
      "z": -3,
      "name": "Wood_Azure_Trunk_Full",
      "rotation": 1
    },
    {
      "x": -18,
      "y": 113,
      "z": -3,
      "name": "Wood_Azure_Trunk",
      "rotation": 1
    },
    {
      "x": -18,
      "y": 114,
      "z": -3,
      "name": "Wood_Azure_Trunk_Full",
      "rotation": 1
    },
    {
      "x": -18,
      "y": 116,
      "z": -3,
      "name": "Plant_Moss_Wall_Blue",
      "rotation": 3
    },
    {
      "x": -18,
      "y": 123,
      "z": -3,
      "name": "Wood_Azure_Trunk_Full",
      "rotation": 1
    },
    {
      "x": -18,
      "y": 124,
      "z": -3,
      "name": "Wood_Azure_Trunk",
      "rotation": 1
    },
    {
      "x": -18,
      "y": 125,
      "z": -3,
      "name": "Wood_Azure_Trunk_Full",
      "rotation": 1
    },
    {
      "x": -18,
      "y": 128,
      "z": -3,
      "name": "Wood_Azure_Branch_Long",
      "rotation": 5
    },
    {
      "x": -18,
      "y": 132,
      "z": -3,
      "name": "Plant_Leaves_Azure",
      "rotation": 1
    },
    {
      "x": -18,
      "y": 133,
      "z": -3,
      "name": "Plant_Leaves_Azure",
      "rotation": 1
    },
    {
      "x": -18,
      "y": 134,
      "z": -3,
      "name": "Plant_Leaves_Azure",
      "rotation": 1
    },
    {
      "x": -18,
      "y": 135,
      "z": -3,
      "name": "Plant_Leaves_Azure",
      "rotation": 1
    },
    {
      "x": -18,
      "y": 104,
      "z": -2,
      "name": "Plant_Moss_Wall_Blue",
      "support": 15,
      "rotation": 3
    },
    {
      "x": -18,
      "y": 105,
      "z": -2,
      "name": "Plant_Moss_Wall_Blue",
      "support": 15,
      "rotation": 3
    },
    {
      "x": -18,
      "y": 106,
      "z": -2,
      "name": "Rock_Marble"
    },
    {
      "x": -18,
      "y": 107,
      "z": -2,
      "name": "Plant_Moss_Block_Blue"
    },
    {
      "x": -18,
      "y": 108,
      "z": -2,
      "name": "Plant_Moss_Short_Green_Dark"
    },
    {
      "x": -18,
      "y": 112,
      "z": -2,
      "name": "Wood_Azure_Trunk_Full",
      "rotation": 1
    },
    {
      "x": -18,
      "y": 113,
      "z": -2,
      "name": "Wood_Azure_Trunk_Full",
      "rotation": 1
    },
    {
      "x": -18,
      "y": 124,
      "z": -2,
      "name": "Wood_Azure_Branch_Long",
      "rotation": 6
    },
    {
      "x": -18,
      "y": 102,
      "z": -1,
      "name": "Plant_Moss_Wall_Blue",
      "support": 15,
      "rotation": 3
    },
    {
      "x": -18,
      "y": 103,
      "z": -1,
      "name": "Plant_Moss_Wall_Blue",
      "support": 15,
      "rotation": 3
    },
    {
      "x": -18,
      "y": 106,
      "z": -1,
      "name": "Plant_Moss_Wall_Blue",
      "support": 15,
      "rotation": 3
    },
    {
      "x": -18,
      "y": 124,
      "z": -1,
      "name": "Wood_Azure_Branch_Long",
      "rotation": 6
    },
    {
      "x": -18,
      "y": 126,
      "z": -1,
      "name": "Plant_Leaves_Azure",
      "rotation": 1
    },
    {
      "x": -18,
      "y": 127,
      "z": -1,
      "name": "Plant_Leaves_Azure",
      "rotation": 1
    },
    {
      "x": -18,
      "y": 104,
      "z": 0,
      "name": "Rock_Marble"
    },
    {
      "x": -18,
      "y": 105,
      "z": 0,
      "name": "Rock_Marble"
    },
    {
      "x": -18,
      "y": 106,
      "z": 0,
      "name": "Rock_Marble"
    },
    {
      "x": -18,
      "y": 107,
      "z": 0,
      "name": "Plant_Moss_Block_Blue"
    },
    {
      "x": -18,
      "y": 108,
      "z": 0,
      "name": "Plant_Moss_Blue"
    },
    {
      "x": -18,
      "y": 123,
      "z": 0,
      "name": "Plant_Leaves_Azure",
      "rotation": 1
    },
    {
      "x": -18,
      "y": 124,
      "z": 0,
      "name": "Wood_Azure_Branch_Long",
      "rotation": 6
    },
    {
      "x": -18,
      "y": 125,
      "z": 0,
      "name": "Plant_Leaves_Azure",
      "rotation": 1
    },
    {
      "x": -18,
      "y": 126,
      "z": 0,
      "name": "Plant_Leaves_Azure",
      "rotation": 1
    },
    {
      "x": -18,
      "y": 127,
      "z": 0,
      "name": "Plant_Leaves_Azure",
      "rotation": 1
    },
    {
      "x": -18,
      "y": 128,
      "z": 0,
      "name": "Plant_Leaves_Azure",
      "rotation": 1
    },
    {
      "x": -18,
      "y": 104,
      "z": 1,
      "name": "Rock_Marble"
    },
    {
      "x": -18,
      "y": 105,
      "z": 1,
      "name": "Rock_Marble"
    },
    {
      "x": -18,
      "y": 106,
      "z": 1,
      "name": "Rock_Marble"
    },
    {
      "x": -18,
      "y": 107,
      "z": 1,
      "name": "Plant_Moss_Block_Blue"
    },
    {
      "x": -18,
      "y": 108,
      "z": 1,
      "name": "Plant_Moss_Rug_Lime"
    },
    {
      "x": -18,
      "y": 124,
      "z": 1,
      "name": "Plant_Leaves_Azure",
      "rotation": 1
    },
    {
      "x": -18,
      "y": 125,
      "z": 1,
      "name": "Plant_Leaves_Azure",
      "rotation": 1
    },
    {
      "x": -18,
      "y": 126,
      "z": 1,
      "name": "Plant_Leaves_Azure",
      "rotation": 1
    },
    {
      "x": -18,
      "y": 127,
      "z": 1,
      "name": "Plant_Leaves_Azure",
      "rotation": 1
    },
    {
      "x": -18,
      "y": 104,
      "z": 2,
      "name": "Rock_Marble"
    },
    {
      "x": -18,
      "y": 105,
      "z": 2,
      "name": "Rock_Marble"
    },
    {
      "x": -18,
      "y": 106,
      "z": 2,
      "name": "Rock_Marble"
    },
    {
      "x": -18,
      "y": 107,
      "z": 2,
      "name": "Plant_Moss_Block_Blue"
    },
    {
      "x": -18,
      "y": 108,
      "z": 2,
      "name": "Plant_Moss_Blue"
    },
    {
      "x": -18,
      "y": 104,
      "z": 3,
      "name": "Plant_Moss_Wall_Blue",
      "support": 15,
      "rotation": 3
    },
    {
      "x": -18,
      "y": 105,
      "z": 3,
      "name": "Plant_Moss_Wall_Blue",
      "support": 15
    },
    {
      "x": -18,
      "y": 107,
      "z": 3,
      "name": "Plant_Moss_Wall_Blue",
      "support": 15,
      "rotation": 3
    },
    {
      "x": -17,
      "y": 117,
      "z": -9,
      "name": "Plant_Leaves_Azure",
      "rotation": 1
    },
    {
      "x": -17,
      "y": 118,
      "z": -9,
      "name": "Plant_Leaves_Azure",
      "rotation": 1
    },
    {
      "x": -17,
      "y": 119,
      "z": -9,
      "name": "Plant_Leaves_Azure",
      "rotation": 1
    },
    {
      "x": -17,
      "y": 104,
      "z": -8,
      "name": "Plant_Moss_Wall_Blue",
      "support": 15,
      "rotation": 3
    },
    {
      "x": -17,
      "y": 107,
      "z": -8,
      "name": "Plant_Moss_Wall_Blue",
      "support": 15,
      "rotation": 3
    },
    {
      "x": -17,
      "y": 108,
      "z": -8,
      "name": "Plant_Moss_Wall_Blue",
      "support": 15,
      "rotation": 3
    },
    {
      "x": -17,
      "y": 117,
      "z": -8,
      "name": "Plant_Leaves_Azure",
      "rotation": 1
    },
    {
      "x": -17,
      "y": 118,
      "z": -8,
      "name": "Plant_Leaves_Azure",
      "rotation": 1
    },
    {
      "x": -17,
      "y": 119,
      "z": -8,
      "name": "Wood_Azure_Branch_Long",
      "rotation": 6
    },
    {
      "x": -17,
      "y": 120,
      "z": -8,
      "name": "Plant_Leaves_Azure",
      "rotation": 1
    },
    {
      "x": -17,
      "y": 122,
      "z": -8,
      "name": "Plant_Leaves_Azure",
      "rotation": 1
    },
    {
      "x": -17,
      "y": 123,
      "z": -8,
      "name": "Plant_Leaves_Azure",
      "rotation": 1
    },
    {
      "x": -17,
      "y": 124,
      "z": -8,
      "name": "Plant_Leaves_Azure",
      "rotation": 1
    },
    {
      "x": -17,
      "y": 125,
      "z": -8,
      "name": "Plant_Leaves_Azure",
      "rotation": 1
    },
    {
      "x": -17,
      "y": 101,
      "z": -7,
      "name": "Rock_Marble"
    },
    {
      "x": -17,
      "y": 102,
      "z": -7,
      "name": "Rock_Marble"
    },
    {
      "x": -17,
      "y": 103,
      "z": -7,
      "name": "Rock_Marble"
    },
    {
      "x": -17,
      "y": 104,
      "z": -7,
      "name": "Rock_Marble"
    },
    {
      "x": -17,
      "y": 105,
      "z": -7,
      "name": "Rock_Marble"
    },
    {
      "x": -17,
      "y": 106,
      "z": -7,
      "name": "Rock_Marble"
    },
    {
      "x": -17,
      "y": 107,
      "z": -7,
      "name": "Rock_Marble"
    },
    {
      "x": -17,
      "y": 108,
      "z": -7,
      "name": "Rock_Marble"
    },
    {
      "x": -17,
      "y": 109,
      "z": -7,
      "name": "Plant_Moss_Blue"
    },
    {
      "x": -17,
      "y": 117,
      "z": -7,
      "name": "Plant_Leaves_Azure",
      "rotation": 1
    },
    {
      "x": -17,
      "y": 118,
      "z": -7,
      "name": "Plant_Leaves_Azure",
      "rotation": 1
    },
    {
      "x": -17,
      "y": 119,
      "z": -7,
      "name": "Wood_Azure_Branch_Long",
      "rotation": 6
    },
    {
      "x": -17,
      "y": 123,
      "z": -7,
      "name": "Plant_Leaves_Azure",
      "rotation": 1
    },
    {
      "x": -17,
      "y": 124,
      "z": -7,
      "name": "Plant_Leaves_Azure",
      "rotation": 1
    },
    {
      "x": -17,
      "y": 125,
      "z": -7,
      "name": "Plant_Leaves_Azure",
      "rotation": 1
    },
    {
      "x": -17,
      "y": 126,
      "z": -7,
      "name": "Plant_Leaves_Azure",
      "rotation": 1
    },
    {
      "x": -17,
      "y": 101,
      "z": -6,
      "name": "Rock_Marble"
    },
    {
      "x": -17,
      "y": 102,
      "z": -6,
      "name": "Rock_Marble"
    },
    {
      "x": -17,
      "y": 103,
      "z": -6,
      "name": "Rock_Marble"
    },
    {
      "x": -17,
      "y": 104,
      "z": -6,
      "name": "Rock_Marble"
    },
    {
      "x": -17,
      "y": 105,
      "z": -6,
      "name": "Rock_Marble"
    },
    {
      "x": -17,
      "y": 106,
      "z": -6,
      "name": "Rock_Marble"
    },
    {
      "x": -17,
      "y": 107,
      "z": -6,
      "name": "Rock_Marble"
    },
    {
      "x": -17,
      "y": 108,
      "z": -6,
      "name": "Plant_Moss_Block_Blue"
    },
    {
      "x": -17,
      "y": 109,
      "z": -6,
      "name": "Plant_Moss_Short_Green_Dark"
    },
    {
      "x": -17,
      "y": 111,
      "z": -6,
      "name": "Plant_Moss_Wall_Blue",
      "support": 15,
      "rotation": 3
    },
    {
      "x": -17,
      "y": 112,
      "z": -6,
      "name": "Plant_Moss_Wall_Blue",
      "support": 15,
      "rotation": 3
    },
    {
      "x": -17,
      "y": 119,
      "z": -6,
      "name": "Wood_Azure_Branch_Long",
      "rotation": 6
    },
    {
      "x": -17,
      "y": 121,
      "z": -6,
      "name": "Plant_Moss_Wall_Blue",
      "rotation": 2
    },
    {
      "x": -17,
      "y": 124,
      "z": -6,
      "name": "Plant_Leaves_Azure",
      "rotation": 1
    },
    {
      "x": -17,
      "y": 125,
      "z": -6,
      "name": "Plant_Leaves_Azure",
      "rotation": 1
    },
    {
      "x": -17,
      "y": 101,
      "z": -5,
      "name": "Rock_Marble"
    },
    {
      "x": -17,
      "y": 102,
      "z": -5,
      "name": "Rock_Marble"
    },
    {
      "x": -17,
      "y": 103,
      "z": -5,
      "name": "Rock_Marble"
    },
    {
      "x": -17,
      "y": 104,
      "z": -5,
      "name": "Rock_Marble"
    },
    {
      "x": -17,
      "y": 105,
      "z": -5,
      "name": "Rock_Marble"
    },
    {
      "x": -17,
      "y": 106,
      "z": -5,
      "name": "Rock_Marble"
    },
    {
      "x": -17,
      "y": 107,
      "z": -5,
      "name": "Rock_Marble"
    },
    {
      "x": -17,
      "y": 108,
      "z": -5,
      "name": "Rock_Marble"
    },
    {
      "x": -17,
      "y": 109,
      "z": -5,
      "name": "Rock_Marble"
    },
    {
      "x": -17,
      "y": 110,
      "z": -5,
      "name": "Rock_Marble"
    },
    {
      "x": -17,
      "y": 111,
      "z": -5,
      "name": "Rock_Marble"
    },
    {
      "x": -17,
      "y": 112,
      "z": -5,
      "name": "Plant_Moss_Block_Blue"
    },
    {
      "x": -17,
      "y": 113,
      "z": -5,
      "name": "Plant_Moss_Blue"
    },
    {
      "x": -17,
      "y": 118,
      "z": -5,
      "name": "Wood_Azure_Trunk_Full",
      "rotation": 1
    },
    {
      "x": -17,
      "y": 119,
      "z": -5,
      "name": "Wood_Azure_Trunk",
      "rotation": 1
    },
    {
      "x": -17,
      "y": 120,
      "z": -5,
      "name": "Wood_Azure_Trunk",
      "rotation": 1
    },
    {
      "x": -17,
      "y": 121,
      "z": -5,
      "name": "Wood_Azure_Trunk_Full",
      "rotation": 1
    },
    {
      "x": -17,
      "y": 122,
      "z": -5,
      "name": "Plant_Moss_Rug_Blue",
      "rotation": 1
    },
    {
      "x": -17,
      "y": 130,
      "z": -5,
      "name": "Plant_Leaves_Azure",
      "rotation": 1
    },
    {
      "x": -17,
      "y": 131,
      "z": -5,
      "name": "Plant_Leaves_Azure",
      "rotation": 1
    },
    {
      "x": -17,
      "y": 132,
      "z": -5,
      "name": "Plant_Leaves_Azure",
      "rotation": 1
    },
    {
      "x": -17,
      "y": 105,
      "z": -4,
      "name": "Rock_Marble"
    },
    {
      "x": -17,
      "y": 106,
      "z": -4,
      "name": "Rock_Marble"
    },
    {
      "x": -17,
      "y": 107,
      "z": -4,
      "name": "Rock_Marble"
    },
    {
      "x": -17,
      "y": 108,
      "z": -4,
      "name": "Rock_Marble"
    },
    {
      "x": -17,
      "y": 109,
      "z": -4,
      "name": "Rock_Marble"
    },
    {
      "x": -17,
      "y": 110,
      "z": -4,
      "name": "Rock_Marble"
    },
    {
      "x": -17,
      "y": 111,
      "z": -4,
      "name": "Rock_Marble"
    },
    {
      "x": -17,
      "y": 112,
      "z": -4,
      "name": "Plant_Moss_Block_Blue"
    },
    {
      "x": -17,
      "y": 113,
      "z": -4,
      "name": "Wood_Azure_Trunk_Full",
      "rotation": 1
    },
    {
      "x": -17,
      "y": 114,
      "z": -4,
      "name": "Wood_Azure_Trunk",
      "rotation": 1
    },
    {
      "x": -17,
      "y": 115,
      "z": -4,
      "name": "Wood_Azure_Trunk",
      "rotation": 1
    },
    {
      "x": -17,
      "y": 116,
      "z": -4,
      "name": "Wood_Azure_Trunk",
      "rotation": 1
    },
    {
      "x": -17,
      "y": 117,
      "z": -4,
      "name": "Wood_Azure_Trunk",
      "rotation": 1
    },
    {
      "x": -17,
      "y": 118,
      "z": -4,
      "name": "Wood_Azure_Trunk",
      "rotation": 1
    },
    {
      "x": -17,
      "y": 119,
      "z": -4,
      "name": "Wood_Azure_Trunk",
      "rotation": 1
    },
    {
      "x": -17,
      "y": 120,
      "z": -4,
      "name": "Wood_Azure_Trunk",
      "rotation": 1
    },
    {
      "x": -17,
      "y": 121,
      "z": -4,
      "name": "Wood_Azure_Trunk",
      "rotation": 1
    },
    {
      "x": -17,
      "y": 122,
      "z": -4,
      "name": "Wood_Azure_Trunk",
      "rotation": 1
    },
    {
      "x": -17,
      "y": 123,
      "z": -4,
      "name": "Wood_Azure_Trunk",
      "rotation": 1
    },
    {
      "x": -17,
      "y": 124,
      "z": -4,
      "name": "Wood_Azure_Trunk",
      "rotation": 1
    },
    {
      "x": -17,
      "y": 125,
      "z": -4,
      "name": "Wood_Azure_Trunk",
      "rotation": 1
    },
    {
      "x": -17,
      "y": 126,
      "z": -4,
      "name": "Wood_Azure_Trunk_Full",
      "rotation": 1
    },
    {
      "x": -17,
      "y": 129,
      "z": -4,
      "name": "Plant_Moss_Wall_Blue",
      "rotation": 2
    },
    {
      "x": -17,
      "y": 131,
      "z": -4,
      "name": "Plant_Leaves_Azure",
      "rotation": 1
    },
    {
      "x": -17,
      "y": 132,
      "z": -4,
      "name": "Plant_Leaves_Azure",
      "rotation": 1
    },
    {
      "x": -17,
      "y": 133,
      "z": -4,
      "name": "Plant_Leaves_Azure",
      "rotation": 1
    },
    {
      "x": -17,
      "y": 134,
      "z": -4,
      "name": "Plant_Fruit_Azure",
      "rotation": 1
    },
    {
      "x": -17,
      "y": 104,
      "z": -3,
      "name": "Rock_Marble"
    },
    {
      "x": -17,
      "y": 105,
      "z": -3,
      "name": "Rock_Marble"
    },
    {
      "x": -17,
      "y": 106,
      "z": -3,
      "name": "Rock_Marble"
    },
    {
      "x": -17,
      "y": 107,
      "z": -3,
      "name": "Rock_Marble"
    },
    {
      "x": -17,
      "y": 108,
      "z": -3,
      "name": "Rock_Marble"
    },
    {
      "x": -17,
      "y": 109,
      "z": -3,
      "name": "Rock_Marble"
    },
    {
      "x": -17,
      "y": 110,
      "z": -3,
      "name": "Rock_Marble"
    },
    {
      "x": -17,
      "y": 111,
      "z": -3,
      "name": "Rock_Marble"
    },
    {
      "x": -17,
      "y": 112,
      "z": -3,
      "name": "Plant_Moss_Block_Blue"
    },
    {
      "x": -17,
      "y": 113,
      "z": -3,
      "name": "Wood_Azure_Trunk_Full",
      "rotation": 1
    },
    {
      "x": -17,
      "y": 114,
      "z": -3,
      "name": "Wood_Azure_Trunk",
      "rotation": 1
    },
    {
      "x": -17,
      "y": 115,
      "z": -3,
      "name": "Wood_Azure_Trunk",
      "rotation": 1
    },
    {
      "x": -17,
      "y": 116,
      "z": -3,
      "name": "Wood_Azure_Trunk_Full",
      "rotation": 1
    },
    {
      "x": -17,
      "y": 117,
      "z": -3,
      "name": "Plant_Moss_Rug_Blue",
      "rotation": 1
    },
    {
      "x": -17,
      "y": 120,
      "z": -3,
      "name": "Wood_Azure_Trunk_Full",
      "rotation": 1
    },
    {
      "x": -17,
      "y": 121,
      "z": -3,
      "name": "Wood_Azure_Trunk",
      "rotation": 1
    },
    {
      "x": -17,
      "y": 122,
      "z": -3,
      "name": "Wood_Azure_Trunk",
      "rotation": 1
    },
    {
      "x": -17,
      "y": 123,
      "z": -3,
      "name": "Wood_Azure_Trunk",
      "rotation": 1
    },
    {
      "x": -17,
      "y": 124,
      "z": -3,
      "name": "Wood_Azure_Trunk",
      "rotation": 1
    },
    {
      "x": -17,
      "y": 125,
      "z": -3,
      "name": "Wood_Azure_Trunk",
      "rotation": 1
    },
    {
      "x": -17,
      "y": 126,
      "z": -3,
      "name": "Wood_Azure_Trunk",
      "rotation": 1
    },
    {
      "x": -17,
      "y": 127,
      "z": -3,
      "name": "Wood_Azure_Trunk",
      "rotation": 1
    },
    {
      "x": -17,
      "y": 128,
      "z": -3,
      "name": "Wood_Azure_Trunk",
      "rotation": 1
    },
    {
      "x": -17,
      "y": 129,
      "z": -3,
      "name": "Wood_Azure_Trunk_Full",
      "rotation": 1
    },
    {
      "x": -17,
      "y": 130,
      "z": -3,
      "name": "Wood_Azure_Branch_Long",
      "rotation": 1
    },
    {
      "x": -17,
      "y": 131,
      "z": -3,
      "name": "Wood_Azure_Branch_Long",
      "rotation": 1
    },
    {
      "x": -17,
      "y": 132,
      "z": -3,
      "name": "Wood_Azure_Branch_Long",
      "rotation": 1
    },
    {
      "x": -17,
      "y": 133,
      "z": -3,
      "name": "Plant_Leaves_Azure",
      "rotation": 1
    },
    {
      "x": -17,
      "y": 134,
      "z": -3,
      "name": "Plant_Leaves_Azure",
      "rotation": 1
    },
    {
      "x": -17,
      "y": 104,
      "z": -2,
      "name": "Rock_Marble"
    },
    {
      "x": -17,
      "y": 105,
      "z": -2,
      "name": "Rock_Marble"
    },
    {
      "x": -17,
      "y": 106,
      "z": -2,
      "name": "Rock_Marble"
    },
    {
      "x": -17,
      "y": 107,
      "z": -2,
      "name": "Plant_Moss_Block_Blue"
    },
    {
      "x": -17,
      "y": 108,
      "z": -2,
      "name": "Plant_Moss_Short_Green_Dark"
    },
    {
      "x": -17,
      "y": 113,
      "z": -2,
      "name": "Wood_Azure_Trunk_Full",
      "rotation": 1
    },
    {
      "x": -17,
      "y": 116,
      "z": -2,
      "name": "Plant_Moss_Wall_Blue"
    },
    {
      "x": -17,
      "y": 127,
      "z": -2,
      "name": "Wood_Azure_Branch_Long",
      "rotation": 6
    },
    {
      "x": -17,
      "y": 132,
      "z": -2,
      "name": "Plant_Leaves_Azure",
      "rotation": 1
    },
    {
      "x": -17,
      "y": 101,
      "z": -1,
      "name": "Rock_Marble"
    },
    {
      "x": -17,
      "y": 102,
      "z": -1,
      "name": "Rock_Marble"
    },
    {
      "x": -17,
      "y": 103,
      "z": -1,
      "name": "Rock_Marble"
    },
    {
      "x": -17,
      "y": 104,
      "z": -1,
      "name": "Rock_Marble"
    },
    {
      "x": -17,
      "y": 105,
      "z": -1,
      "name": "Rock_Marble"
    },
    {
      "x": -17,
      "y": 106,
      "z": -1,
      "name": "Rock_Marble"
    },
    {
      "x": -17,
      "y": 107,
      "z": -1,
      "name": "Plant_Moss_Block_Blue"
    },
    {
      "x": -17,
      "y": 108,
      "z": -1,
      "name": "Plant_Moss_Short_Green_Dark"
    },
    {
      "x": -17,
      "y": 120,
      "z": -1,
      "name": "Plant_Moss_Wall_Blue",
      "rotation": 3
    },
    {
      "x": -17,
      "y": 126,
      "z": -1,
      "name": "Plant_Leaves_Azure",
      "rotation": 1
    },
    {
      "x": -17,
      "y": 127,
      "z": -1,
      "name": "Wood_Azure_Branch_Long",
      "rotation": 6
    },
    {
      "x": -17,
      "y": 128,
      "z": -1,
      "name": "Plant_Leaves_Azure",
      "rotation": 1
    },
    {
      "x": -17,
      "y": 129,
      "z": -1,
      "name": "Plant_Fruit_Azure",
      "rotation": 1
    },
    {
      "x": -17,
      "y": 101,
      "z": 0,
      "name": "Rock_Marble"
    },
    {
      "x": -17,
      "y": 102,
      "z": 0,
      "name": "Rock_Marble"
    },
    {
      "x": -17,
      "y": 103,
      "z": 0,
      "name": "Rock_Marble"
    },
    {
      "x": -17,
      "y": 104,
      "z": 0,
      "name": "Rock_Marble"
    },
    {
      "x": -17,
      "y": 105,
      "z": 0,
      "name": "Rock_Marble"
    },
    {
      "x": -17,
      "y": 106,
      "z": 0,
      "name": "Rock_Marble"
    },
    {
      "x": -17,
      "y": 107,
      "z": 0,
      "name": "Plant_Moss_Block_Blue"
    },
    {
      "x": -17,
      "y": 108,
      "z": 0,
      "name": "Plant_Moss_Rug_Blue"
    },
    {
      "x": -17,
      "y": 124,
      "z": 0,
      "name": "Plant_Leaves_Azure",
      "rotation": 1
    },
    {
      "x": -17,
      "y": 125,
      "z": 0,
      "name": "Plant_Leaves_Azure",
      "rotation": 1
    },
    {
      "x": -17,
      "y": 126,
      "z": 0,
      "name": "Plant_Leaves_Azure",
      "rotation": 1
    },
    {
      "x": -17,
      "y": 127,
      "z": 0,
      "name": "Plant_Leaves_Azure",
      "rotation": 1
    },
    {
      "x": -17,
      "y": 128,
      "z": 0,
      "name": "Plant_Leaves_Azure",
      "rotation": 1
    },
    {
      "x": -17,
      "y": 129,
      "z": 0,
      "name": "Plant_Leaves_Azure",
      "rotation": 1
    },
    {
      "x": -17,
      "y": 101,
      "z": 1,
      "name": "Rock_Marble"
    },
    {
      "x": -17,
      "y": 102,
      "z": 1,
      "name": "Rock_Marble"
    },
    {
      "x": -17,
      "y": 103,
      "z": 1,
      "name": "Rock_Marble"
    },
    {
      "x": -17,
      "y": 104,
      "z": 1,
      "name": "Rock_Marble"
    },
    {
      "x": -17,
      "y": 105,
      "z": 1,
      "name": "Rock_Marble"
    },
    {
      "x": -17,
      "y": 106,
      "z": 1,
      "name": "Rock_Marble"
    },
    {
      "x": -17,
      "y": 107,
      "z": 1,
      "name": "Plant_Moss_Block_Blue"
    },
    {
      "x": -17,
      "y": 108,
      "z": 1,
      "name": "Plant_Moss_Short_Green_Dark"
    },
    {
      "x": -17,
      "y": 111,
      "z": 1,
      "name": "Plant_Moss_Wall_Blue",
      "support": 15,
      "rotation": 3
    },
    {
      "x": -17,
      "y": 120,
      "z": 1,
      "name": "Plant_Leaves_Azure",
      "rotation": 1
    },
    {
      "x": -17,
      "y": 121,
      "z": 1,
      "name": "Plant_Leaves_Azure",
      "rotation": 1
    },
    {
      "x": -17,
      "y": 125,
      "z": 1,
      "name": "Plant_Leaves_Azure",
      "rotation": 1
    },
    {
      "x": -17,
      "y": 126,
      "z": 1,
      "name": "Plant_Leaves_Azure",
      "rotation": 1
    },
    {
      "x": -17,
      "y": 127,
      "z": 1,
      "name": "Plant_Leaves_Azure",
      "rotation": 1
    },
    {
      "x": -17,
      "y": 128,
      "z": 1,
      "name": "Plant_Leaves_Azure",
      "rotation": 1
    },
    {
      "x": -17,
      "y": 102,
      "z": 2,
      "name": "Plant_Moss_Wall_Blue",
      "support": 15
    },
    {
      "x": -17,
      "y": 103,
      "z": 2,
      "name": "Rock_Marble"
    },
    {
      "x": -17,
      "y": 104,
      "z": 2,
      "name": "Rock_Marble"
    },
    {
      "x": -17,
      "y": 105,
      "z": 2,
      "name": "Rock_Marble"
    },
    {
      "x": -17,
      "y": 106,
      "z": 2,
      "name": "Rock_Marble"
    },
    {
      "x": -17,
      "y": 107,
      "z": 2,
      "name": "Plant_Moss_Block_Blue"
    },
    {
      "x": -17,
      "y": 108,
      "z": 2,
      "name": "Plant_Moss_Short_Green_Dark"
    },
    {
      "x": -17,
      "y": 120,
      "z": 2,
      "name": "Plant_Leaves_Azure",
      "rotation": 1
    },
    {
      "x": -17,
      "y": 121,
      "z": 2,
      "name": "Plant_Leaves_Azure",
      "rotation": 1
    },
    {
      "x": -17,
      "y": 103,
      "z": 3,
      "name": "Plant_Moss_Wall_Blue",
      "support": 15
    },
    {
      "x": -17,
      "y": 104,
      "z": 3,
      "name": "Rock_Marble"
    },
    {
      "x": -17,
      "y": 105,
      "z": 3,
      "name": "Rock_Marble"
    },
    {
      "x": -17,
      "y": 106,
      "z": 3,
      "name": "Rock_Marble"
    },
    {
      "x": -17,
      "y": 107,
      "z": 3,
      "name": "Plant_Moss_Block_Blue"
    },
    {
      "x": -17,
      "y": 108,
      "z": 3,
      "name": "Plant_Moss_Short_Green_Dark"
    },
    {
      "x": -16,
      "y": 104,
      "z": -12,
      "name": "Plant_Moss_Wall_Blue",
      "support": 15,
      "rotation": 3
    },
    {
      "x": -16,
      "y": 106,
      "z": -12,
      "name": "Plant_Moss_Wall_Blue",
      "support": 15,
      "rotation": 3
    },
    {
      "x": -16,
      "y": 104,
      "z": -11,
      "name": "Plant_Moss_Wall_Blue",
      "support": 15,
      "rotation": 3
    },
    {
      "x": -16,
      "y": 106,
      "z": -11,
      "name": "Plant_Moss_Wall_Blue",
      "support": 15,
      "rotation": 3
    },
    {
      "x": -16,
      "y": 108,
      "z": -11,
      "name": "Plant_Moss_Wall_Blue",
      "support": 15,
      "rotation": 3
    },
    {
      "x": -16,
      "y": 106,
      "z": -10,
      "name": "Plant_Moss_Wall_Blue",
      "support": 15,
      "rotation": 3
    },
    {
      "x": -16,
      "y": 104,
      "z": -9,
      "name": "Plant_Moss_Wall_Blue",
      "support": 15,
      "rotation": 3
    },
    {
      "x": -16,
      "y": 118,
      "z": -9,
      "name": "Plant_Leaves_Azure",
      "rotation": 1
    },
    {
      "x": -16,
      "y": 101,
      "z": -8,
      "name": "Rock_Marble"
    },
    {
      "x": -16,
      "y": 102,
      "z": -8,
      "name": "Rock_Marble"
    },
    {
      "x": -16,
      "y": 103,
      "z": -8,
      "name": "Rock_Marble"
    },
    {
      "x": -16,
      "y": 104,
      "z": -8,
      "name": "Rock_Marble"
    },
    {
      "x": -16,
      "y": 105,
      "z": -8,
      "name": "Rock_Marble"
    },
    {
      "x": -16,
      "y": 106,
      "z": -8,
      "name": "Rock_Marble"
    },
    {
      "x": -16,
      "y": 107,
      "z": -8,
      "name": "Rock_Marble"
    },
    {
      "x": -16,
      "y": 108,
      "z": -8,
      "name": "Rock_Marble"
    },
    {
      "x": -16,
      "y": 109,
      "z": -8,
      "name": "Plant_Moss_Rug_Lime"
    },
    {
      "x": -16,
      "y": 117,
      "z": -8,
      "name": "Plant_Leaves_Azure",
      "rotation": 1
    },
    {
      "x": -16,
      "y": 118,
      "z": -8,
      "name": "Plant_Leaves_Azure",
      "rotation": 1
    },
    {
      "x": -16,
      "y": 119,
      "z": -8,
      "name": "Plant_Leaves_Azure",
      "rotation": 1
    },
    {
      "x": -16,
      "y": 121,
      "z": -8,
      "name": "Plant_Leaves_Azure",
      "rotation": 1
    },
    {
      "x": -16,
      "y": 122,
      "z": -8,
      "name": "Plant_Leaves_Azure",
      "rotation": 1
    },
    {
      "x": -16,
      "y": 123,
      "z": -8,
      "name": "Plant_Leaves_Azure",
      "rotation": 1
    },
    {
      "x": -16,
      "y": 124,
      "z": -8,
      "name": "Plant_Leaves_Azure",
      "rotation": 1
    },
    {
      "x": -16,
      "y": 101,
      "z": -7,
      "name": "Rock_Marble"
    },
    {
      "x": -16,
      "y": 102,
      "z": -7,
      "name": "Rock_Marble"
    },
    {
      "x": -16,
      "y": 103,
      "z": -7,
      "name": "Rock_Marble"
    },
    {
      "x": -16,
      "y": 104,
      "z": -7,
      "name": "Rock_Marble"
    },
    {
      "x": -16,
      "y": 105,
      "z": -7,
      "name": "Rock_Marble"
    },
    {
      "x": -16,
      "y": 106,
      "z": -7,
      "name": "Rock_Marble"
    },
    {
      "x": -16,
      "y": 107,
      "z": -7,
      "name": "Rock_Marble"
    },
    {
      "x": -16,
      "y": 108,
      "z": -7,
      "name": "Plant_Moss_Block_Blue"
    },
    {
      "x": -16,
      "y": 109,
      "z": -7,
      "name": "Plant_Moss_Rug_Blue"
    },
    {
      "x": -16,
      "y": 118,
      "z": -7,
      "name": "Plant_Leaves_Azure",
      "rotation": 1
    },
    {
      "x": -16,
      "y": 123,
      "z": -7,
      "name": "Plant_Leaves_Azure",
      "rotation": 1
    },
    {
      "x": -16,
      "y": 124,
      "z": -7,
      "name": "Plant_Leaves_Azure",
      "rotation": 1
    },
    {
      "x": -16,
      "y": 125,
      "z": -7,
      "name": "Plant_Leaves_Azure",
      "rotation": 1
    },
    {
      "x": -16,
      "y": 126,
      "z": -7,
      "name": "Plant_Fruit_Azure",
      "rotation": 1
    },
    {
      "x": -16,
      "y": 101,
      "z": -6,
      "name": "Rock_Marble"
    },
    {
      "x": -16,
      "y": 102,
      "z": -6,
      "name": "Rock_Marble"
    },
    {
      "x": -16,
      "y": 103,
      "z": -6,
      "name": "Rock_Marble"
    },
    {
      "x": -16,
      "y": 104,
      "z": -6,
      "name": "Rock_Marble"
    },
    {
      "x": -16,
      "y": 105,
      "z": -6,
      "name": "Rock_Marble"
    },
    {
      "x": -16,
      "y": 106,
      "z": -6,
      "name": "Rock_Marble"
    },
    {
      "x": -16,
      "y": 107,
      "z": -6,
      "name": "Rock_Marble"
    },
    {
      "x": -16,
      "y": 108,
      "z": -6,
      "name": "Rock_Marble"
    },
    {
      "x": -16,
      "y": 109,
      "z": -6,
      "name": "Rock_Marble"
    },
    {
      "x": -16,
      "y": 110,
      "z": -6,
      "name": "Rock_Marble"
    },
    {
      "x": -16,
      "y": 111,
      "z": -6,
      "name": "Rock_Marble"
    },
    {
      "x": -16,
      "y": 112,
      "z": -6,
      "name": "Plant_Moss_Block_Blue"
    },
    {
      "x": -16,
      "y": 113,
      "z": -6,
      "name": "Plant_Moss_Rug_Lime"
    },
    {
      "x": -16,
      "y": 123,
      "z": -6,
      "name": "Plant_Leaves_Azure",
      "rotation": 1
    },
    {
      "x": -16,
      "y": 124,
      "z": -6,
      "name": "Plant_Leaves_Azure",
      "rotation": 1
    },
    {
      "x": -16,
      "y": 101,
      "z": -5,
      "name": "Rock_Marble"
    },
    {
      "x": -16,
      "y": 102,
      "z": -5,
      "name": "Rock_Marble"
    },
    {
      "x": -16,
      "y": 103,
      "z": -5,
      "name": "Rock_Marble"
    },
    {
      "x": -16,
      "y": 104,
      "z": -5,
      "name": "Rock_Marble"
    },
    {
      "x": -16,
      "y": 105,
      "z": -5,
      "name": "Rock_Marble"
    },
    {
      "x": -16,
      "y": 106,
      "z": -5,
      "name": "Rock_Marble"
    },
    {
      "x": -16,
      "y": 107,
      "z": -5,
      "name": "Rock_Marble"
    },
    {
      "x": -16,
      "y": 108,
      "z": -5,
      "name": "Rock_Marble"
    },
    {
      "x": -16,
      "y": 109,
      "z": -5,
      "name": "Rock_Marble"
    },
    {
      "x": -16,
      "y": 110,
      "z": -5,
      "name": "Rock_Marble"
    },
    {
      "x": -16,
      "y": 111,
      "z": -5,
      "name": "Rock_Marble"
    },
    {
      "x": -16,
      "y": 112,
      "z": -5,
      "name": "Plant_Moss_Block_Blue"
    },
    {
      "x": -16,
      "y": 113,
      "z": -5,
      "name": "Plant_Moss_Blue"
    },
    {
      "x": -16,
      "y": 116,
      "z": -5,
      "name": "Wood_Azure_Trunk_Full",
      "rotation": 1
    },
    {
      "x": -16,
      "y": 117,
      "z": -5,
      "name": "Wood_Azure_Trunk",
      "rotation": 1
    },
    {
      "x": -16,
      "y": 118,
      "z": -5,
      "name": "Wood_Azure_Trunk",
      "rotation": 1
    },
    {
      "x": -16,
      "y": 119,
      "z": -5,
      "name": "Wood_Azure_Trunk_Full",
      "rotation": 1
    },
    {
      "x": -16,
      "y": 121,
      "z": -5,
      "name": "Plant_Moss_Wall_Blue",
      "rotation": 1
    },
    {
      "x": -16,
      "y": 123,
      "z": -5,
      "name": "Wood_Azure_Branch_Long",
      "rotation": 6
    },
    {
      "x": -16,
      "y": 124,
      "z": -5,
      "name": "Plant_Moss_Wall_Blue",
      "rotation": 2
    },
    {
      "x": -16,
      "y": 127,
      "z": -5,
      "name": "Plant_Leaves_Azure",
      "rotation": 1
    },
    {
      "x": -16,
      "y": 130,
      "z": -5,
      "name": "Plant_Leaves_Azure",
      "rotation": 1
    },
    {
      "x": -16,
      "y": 131,
      "z": -5,
      "name": "Plant_Leaves_Azure",
      "rotation": 1
    },
    {
      "x": -16,
      "y": 101,
      "z": -4,
      "name": "Rock_Marble"
    },
    {
      "x": -16,
      "y": 102,
      "z": -4,
      "name": "Rock_Marble"
    },
    {
      "x": -16,
      "y": 103,
      "z": -4,
      "name": "Rock_Marble"
    },
    {
      "x": -16,
      "y": 104,
      "z": -4,
      "name": "Rock_Marble"
    },
    {
      "x": -16,
      "y": 105,
      "z": -4,
      "name": "Rock_Marble"
    },
    {
      "x": -16,
      "y": 106,
      "z": -4,
      "name": "Rock_Marble"
    },
    {
      "x": -16,
      "y": 107,
      "z": -4,
      "name": "Rock_Marble"
    },
    {
      "x": -16,
      "y": 108,
      "z": -4,
      "name": "Rock_Marble"
    },
    {
      "x": -16,
      "y": 109,
      "z": -4,
      "name": "Rock_Marble"
    },
    {
      "x": -16,
      "y": 110,
      "z": -4,
      "name": "Rock_Marble"
    },
    {
      "x": -16,
      "y": 111,
      "z": -4,
      "name": "Rock_Marble"
    },
    {
      "x": -16,
      "y": 112,
      "z": -4,
      "name": "Plant_Moss_Block_Blue"
    },
    {
      "x": -16,
      "y": 113,
      "z": -4,
      "name": "Plant_Moss_Short_Green_Dark"
    },
    {
      "x": -16,
      "y": 114,
      "z": -4,
      "name": "Wood_Azure_Trunk",
      "rotation": 1
    },
    {
      "x": -16,
      "y": 115,
      "z": -4,
      "name": "Wood_Azure_Trunk",
      "rotation": 1
    },
    {
      "x": -16,
      "y": 116,
      "z": -4,
      "name": "Wood_Azure_Trunk",
      "rotation": 1
    },
    {
      "x": -16,
      "y": 117,
      "z": -4,
      "name": "Wood_Azure_Trunk",
      "rotation": 1
    },
    {
      "x": -16,
      "y": 118,
      "z": -4,
      "name": "Wood_Azure_Trunk",
      "rotation": 1
    },
    {
      "x": -16,
      "y": 119,
      "z": -4,
      "name": "Wood_Azure_Trunk",
      "rotation": 1
    },
    {
      "x": -16,
      "y": 120,
      "z": -4,
      "name": "Wood_Azure_Trunk",
      "rotation": 1
    },
    {
      "x": -16,
      "y": 121,
      "z": -4,
      "name": "Wood_Azure_Trunk",
      "rotation": 1
    },
    {
      "x": -16,
      "y": 122,
      "z": -4,
      "name": "Wood_Azure_Trunk",
      "rotation": 1
    },
    {
      "x": -16,
      "y": 123,
      "z": -4,
      "name": "Wood_Azure_Trunk",
      "rotation": 1
    },
    {
      "x": -16,
      "y": 124,
      "z": -4,
      "name": "Wood_Azure_Trunk_Full",
      "rotation": 1
    },
    {
      "x": -16,
      "y": 125,
      "z": -4,
      "name": "Plant_Moss_Rug_Blue",
      "rotation": 1
    },
    {
      "x": -16,
      "y": 126,
      "z": -4,
      "name": "Wood_Azure_Branch_Long",
      "rotation": 5
    },
    {
      "x": -16,
      "y": 129,
      "z": -4,
      "name": "Plant_Leaves_Azure",
      "rotation": 1
    },
    {
      "x": -16,
      "y": 130,
      "z": -4,
      "name": "Plant_Leaves_Azure",
      "rotation": 1
    },
    {
      "x": -16,
      "y": 131,
      "z": -4,
      "name": "Plant_Leaves_Azure",
      "rotation": 1
    },
    {
      "x": -16,
      "y": 132,
      "z": -4,
      "name": "Plant_Leaves_Azure",
      "rotation": 1
    },
    {
      "x": -16,
      "y": 102,
      "z": -3,
      "name": "Rock_Marble"
    },
    {
      "x": -16,
      "y": 103,
      "z": -3,
      "name": "Rock_Marble"
    },
    {
      "x": -16,
      "y": 104,
      "z": -3,
      "name": "Rock_Marble"
    },
    {
      "x": -16,
      "y": 105,
      "z": -3,
      "name": "Rock_Marble"
    },
    {
      "x": -16,
      "y": 106,
      "z": -3,
      "name": "Rock_Marble"
    },
    {
      "x": -16,
      "y": 107,
      "z": -3,
      "name": "Rock_Marble"
    },
    {
      "x": -16,
      "y": 108,
      "z": -3,
      "name": "Rock_Marble"
    },
    {
      "x": -16,
      "y": 109,
      "z": -3,
      "name": "Rock_Marble"
    },
    {
      "x": -16,
      "y": 110,
      "z": -3,
      "name": "Rock_Marble"
    },
    {
      "x": -16,
      "y": 111,
      "z": -3,
      "name": "Rock_Marble"
    },
    {
      "x": -16,
      "y": 112,
      "z": -3,
      "name": "Plant_Moss_Block_Blue"
    },
    {
      "x": -16,
      "y": 113,
      "z": -3,
      "name": "Plant_Moss_Short_Green_Dark"
    },
    {
      "x": -16,
      "y": 114,
      "z": -3,
      "name": "Wood_Azure_Trunk_Full",
      "rotation": 1
    },
    {
      "x": -16,
      "y": 115,
      "z": -3,
      "name": "Wood_Azure_Trunk",
      "rotation": 1
    },
    {
      "x": -16,
      "y": 116,
      "z": -3,
      "name": "Wood_Azure_Trunk",
      "rotation": 1
    },
    {
      "x": -16,
      "y": 117,
      "z": -3,
      "name": "Wood_Azure_Trunk",
      "rotation": 1
    },
    {
      "x": -16,
      "y": 118,
      "z": -3,
      "name": "Wood_Azure_Trunk",
      "rotation": 1
    },
    {
      "x": -16,
      "y": 119,
      "z": -3,
      "name": "Wood_Azure_Trunk",
      "rotation": 1
    },
    {
      "x": -16,
      "y": 120,
      "z": -3,
      "name": "Wood_Azure_Trunk",
      "rotation": 1
    },
    {
      "x": -16,
      "y": 121,
      "z": -3,
      "name": "Wood_Azure_Trunk",
      "rotation": 1
    },
    {
      "x": -16,
      "y": 122,
      "z": -3,
      "name": "Wood_Azure_Trunk_Full",
      "rotation": 1
    },
    {
      "x": -16,
      "y": 124,
      "z": -3,
      "name": "Plant_Moss_Wall_Blue"
    },
    {
      "x": -16,
      "y": 129,
      "z": -3,
      "name": "Wood_Azure_Branch_Long",
      "rotation": 5
    },
    {
      "x": -16,
      "y": 131,
      "z": -3,
      "name": "Plant_Leaves_Azure",
      "rotation": 1
    },
    {
      "x": -16,
      "y": 132,
      "z": -3,
      "name": "Plant_Leaves_Azure",
      "rotation": 1
    },
    {
      "x": -16,
      "y": 101,
      "z": -2,
      "name": "Rock_Marble"
    },
    {
      "x": -16,
      "y": 102,
      "z": -2,
      "name": "Rock_Marble"
    },
    {
      "x": -16,
      "y": 103,
      "z": -2,
      "name": "Rock_Marble"
    },
    {
      "x": -16,
      "y": 104,
      "z": -2,
      "name": "Rock_Marble"
    },
    {
      "x": -16,
      "y": 105,
      "z": -2,
      "name": "Rock_Marble"
    },
    {
      "x": -16,
      "y": 106,
      "z": -2,
      "name": "Rock_Marble"
    },
    {
      "x": -16,
      "y": 107,
      "z": -2,
      "name": "Rock_Marble"
    },
    {
      "x": -16,
      "y": 108,
      "z": -2,
      "name": "Rock_Marble"
    },
    {
      "x": -16,
      "y": 109,
      "z": -2,
      "name": "Rock_Marble"
    },
    {
      "x": -16,
      "y": 110,
      "z": -2,
      "name": "Rock_Marble"
    },
    {
      "x": -16,
      "y": 111,
      "z": -2,
      "name": "Rock_Marble"
    },
    {
      "x": -16,
      "y": 112,
      "z": -2,
      "name": "Plant_Moss_Block_Blue"
    },
    {
      "x": -16,
      "y": 113,
      "z": -2,
      "name": "Wood_Azure_Trunk_Full",
      "rotation": 1
    },
    {
      "x": -16,
      "y": 114,
      "z": -2,
      "name": "Wood_Azure_Trunk_Full",
      "rotation": 1
    },
    {
      "x": -16,
      "y": 120,
      "z": -2,
      "name": "Wood_Azure_Trunk_Full",
      "rotation": 1
    },
    {
      "x": -16,
      "y": 122,
      "z": -2,
      "name": "Wood_Azure_Branch_Corner"
    },
    {
      "x": -16,
      "y": 123,
      "z": -2,
      "name": "Wood_Azure_Branch_Corner",
      "rotation": 9
    },
    {
      "x": -16,
      "y": 127,
      "z": -2,
      "name": "Plant_Leaves_Azure",
      "rotation": 1
    },
    {
      "x": -16,
      "y": 128,
      "z": -2,
      "name": "Plant_Leaves_Azure",
      "rotation": 1
    },
    {
      "x": -16,
      "y": 129,
      "z": -2,
      "name": "Plant_Leaves_Azure",
      "rotation": 1
    },
    {
      "x": -16,
      "y": 101,
      "z": -1,
      "name": "Rock_Marble"
    },
    {
      "x": -16,
      "y": 102,
      "z": -1,
      "name": "Rock_Marble"
    },
    {
      "x": -16,
      "y": 103,
      "z": -1,
      "name": "Rock_Marble"
    },
    {
      "x": -16,
      "y": 104,
      "z": -1,
      "name": "Rock_Marble"
    },
    {
      "x": -16,
      "y": 105,
      "z": -1,
      "name": "Rock_Marble"
    },
    {
      "x": -16,
      "y": 106,
      "z": -1,
      "name": "Rock_Marble"
    },
    {
      "x": -16,
      "y": 107,
      "z": -1,
      "name": "Rock_Marble"
    },
    {
      "x": -16,
      "y": 108,
      "z": -1,
      "name": "Rock_Marble"
    },
    {
      "x": -16,
      "y": 109,
      "z": -1,
      "name": "Rock_Marble"
    },
    {
      "x": -16,
      "y": 110,
      "z": -1,
      "name": "Rock_Marble"
    },
    {
      "x": -16,
      "y": 111,
      "z": -1,
      "name": "Plant_Moss_Block_Blue"
    },
    {
      "x": -16,
      "y": 112,
      "z": -1,
      "name": "Plant_Moss_Rug_Lime"
    },
    {
      "x": -16,
      "y": 120,
      "z": -1,
      "name": "Wood_Azure_Trunk_Full",
      "rotation": 1
    },
    {
      "x": -16,
      "y": 121,
      "z": -1,
      "name": "Plant_Moss_Rug_Blue",
      "rotation": 1
    },
    {
      "x": -16,
      "y": 125,
      "z": -1,
      "name": "Plant_Leaves_Azure",
      "rotation": 1
    },
    {
      "x": -16,
      "y": 126,
      "z": -1,
      "name": "Plant_Leaves_Azure",
      "rotation": 1
    },
    {
      "x": -16,
      "y": 127,
      "z": -1,
      "name": "Plant_Leaves_Azure",
      "rotation": 1
    },
    {
      "x": -16,
      "y": 128,
      "z": -1,
      "name": "Plant_Leaves_Azure",
      "rotation": 1
    },
    {
      "x": -16,
      "y": 129,
      "z": -1,
      "name": "Plant_Leaves_Azure",
      "rotation": 1
    },
    {
      "x": -16,
      "y": 130,
      "z": -1,
      "name": "Plant_Leaves_Azure",
      "rotation": 1
    },
    {
      "x": -16,
      "y": 101,
      "z": 0,
      "name": "Rock_Marble"
    },
    {
      "x": -16,
      "y": 102,
      "z": 0,
      "name": "Rock_Marble"
    },
    {
      "x": -16,
      "y": 103,
      "z": 0,
      "name": "Rock_Marble"
    },
    {
      "x": -16,
      "y": 104,
      "z": 0,
      "name": "Rock_Marble"
    },
    {
      "x": -16,
      "y": 105,
      "z": 0,
      "name": "Rock_Marble"
    },
    {
      "x": -16,
      "y": 106,
      "z": 0,
      "name": "Rock_Marble"
    },
    {
      "x": -16,
      "y": 107,
      "z": 0,
      "name": "Rock_Marble"
    },
    {
      "x": -16,
      "y": 108,
      "z": 0,
      "name": "Rock_Marble"
    },
    {
      "x": -16,
      "y": 109,
      "z": 0,
      "name": "Rock_Marble"
    },
    {
      "x": -16,
      "y": 110,
      "z": 0,
      "name": "Rock_Marble"
    },
    {
      "x": -16,
      "y": 111,
      "z": 0,
      "name": "Plant_Moss_Block_Blue"
    },
    {
      "x": -16,
      "y": 112,
      "z": 0,
      "name": "Plant_Moss_Rug_Lime"
    },
    {
      "x": -16,
      "y": 120,
      "z": 0,
      "name": "Wood_Azure_Branch_Long",
      "rotation": 6
    },
    {
      "x": -16,
      "y": 125,
      "z": 0,
      "name": "Plant_Leaves_Azure",
      "rotation": 1
    },
    {
      "x": -16,
      "y": 126,
      "z": 0,
      "name": "Plant_Leaves_Azure",
      "rotation": 1
    },
    {
      "x": -16,
      "y": 127,
      "z": 0,
      "name": "Plant_Leaves_Azure",
      "rotation": 1
    },
    {
      "x": -16,
      "y": 128,
      "z": 0,
      "name": "Plant_Leaves_Azure",
      "rotation": 1
    },
    {
      "x": -16,
      "y": 129,
      "z": 0,
      "name": "Plant_Leaves_Azure",
      "rotation": 1
    },
    {
      "x": -16,
      "y": 99,
      "z": 1,
      "name": "Rock_Marble_Stalactite_Large",
      "filler": 31744,
      "rotation": 8
    },
    {
      "x": -16,
      "y": 100,
      "z": 1,
      "name": "Rock_Marble_Stalactite_Large",
      "rotation": 8
    },
    {
      "x": -16,
      "y": 101,
      "z": 1,
      "name": "Rock_Marble"
    },
    {
      "x": -16,
      "y": 102,
      "z": 1,
      "name": "Rock_Marble"
    },
    {
      "x": -16,
      "y": 103,
      "z": 1,
      "name": "Rock_Marble"
    },
    {
      "x": -16,
      "y": 104,
      "z": 1,
      "name": "Rock_Marble"
    },
    {
      "x": -16,
      "y": 105,
      "z": 1,
      "name": "Rock_Marble"
    },
    {
      "x": -16,
      "y": 106,
      "z": 1,
      "name": "Rock_Marble"
    },
    {
      "x": -16,
      "y": 107,
      "z": 1,
      "name": "Rock_Marble"
    },
    {
      "x": -16,
      "y": 108,
      "z": 1,
      "name": "Rock_Marble"
    },
    {
      "x": -16,
      "y": 109,
      "z": 1,
      "name": "Rock_Marble"
    },
    {
      "x": -16,
      "y": 110,
      "z": 1,
      "name": "Rock_Marble"
    },
    {
      "x": -16,
      "y": 111,
      "z": 1,
      "name": "Plant_Moss_Block_Blue"
    },
    {
      "x": -16,
      "y": 112,
      "z": 1,
      "name": "Plant_Moss_Short_Green_Dark"
    },
    {
      "x": -16,
      "y": 119,
      "z": 1,
      "name": "Plant_Leaves_Azure",
      "rotation": 1
    },
    {
      "x": -16,
      "y": 120,
      "z": 1,
      "name": "Plant_Leaves_Azure",
      "rotation": 1
    },
    {
      "x": -16,
      "y": 121,
      "z": 1,
      "name": "Plant_Leaves_Azure",
      "rotation": 1
    },
    {
      "x": -16,
      "y": 122,
      "z": 1,
      "name": "Plant_Leaves_Azure",
      "rotation": 1
    },
    {
      "x": -16,
      "y": 126,
      "z": 1,
      "name": "Plant_Leaves_Azure",
      "rotation": 1
    },
    {
      "x": -16,
      "y": 127,
      "z": 1,
      "name": "Plant_Leaves_Azure",
      "rotation": 1
    },
    {
      "x": -16,
      "y": 128,
      "z": 1,
      "name": "Plant_Leaves_Azure",
      "rotation": 1
    },
    {
      "x": -16,
      "y": 101,
      "z": 2,
      "name": "Rock_Marble"
    },
    {
      "x": -16,
      "y": 102,
      "z": 2,
      "name": "Rock_Marble"
    },
    {
      "x": -16,
      "y": 103,
      "z": 2,
      "name": "Rock_Marble"
    },
    {
      "x": -16,
      "y": 104,
      "z": 2,
      "name": "Rock_Marble"
    },
    {
      "x": -16,
      "y": 105,
      "z": 2,
      "name": "Rock_Marble"
    },
    {
      "x": -16,
      "y": 106,
      "z": 2,
      "name": "Rock_Marble"
    },
    {
      "x": -16,
      "y": 107,
      "z": 2,
      "name": "Plant_Moss_Block_Blue"
    },
    {
      "x": -16,
      "y": 108,
      "z": 2,
      "name": "Plant_Moss_Short_Green_Dark"
    },
    {
      "x": -16,
      "y": 119,
      "z": 2,
      "name": "Plant_Leaves_Azure",
      "rotation": 1
    },
    {
      "x": -16,
      "y": 120,
      "z": 2,
      "name": "Plant_Leaves_Azure",
      "rotation": 1
    },
    {
      "x": -16,
      "y": 121,
      "z": 2,
      "name": "Plant_Leaves_Azure",
      "rotation": 1
    },
    {
      "x": -16,
      "y": 122,
      "z": 2,
      "name": "Plant_Leaves_Azure",
      "rotation": 1
    },
    {
      "x": -16,
      "y": 103,
      "z": 3,
      "name": "Rock_Marble"
    },
    {
      "x": -16,
      "y": 104,
      "z": 3,
      "name": "Rock_Marble"
    },
    {
      "x": -16,
      "y": 105,
      "z": 3,
      "name": "Rock_Marble"
    },
    {
      "x": -16,
      "y": 106,
      "z": 3,
      "name": "Rock_Marble"
    },
    {
      "x": -16,
      "y": 107,
      "z": 3,
      "name": "Plant_Moss_Block_Blue"
    },
    {
      "x": -16,
      "y": 108,
      "z": 3,
      "name": "Plant_Moss_Rug_Lime"
    },
    {
      "x": -16,
      "y": 120,
      "z": 3,
      "name": "Plant_Leaves_Azure",
      "rotation": 1
    },
    {
      "x": -16,
      "y": 121,
      "z": 3,
      "name": "Plant_Leaves_Azure",
      "rotation": 1
    },
    {
      "x": -15,
      "y": 104,
      "z": -13,
      "name": "Plant_Moss_Wall_Blue",
      "support": 15,
      "rotation": 3
    },
    {
      "x": -15,
      "y": 105,
      "z": -13,
      "name": "Plant_Moss_Wall_Blue",
      "support": 15,
      "rotation": 3
    },
    {
      "x": -15,
      "y": 106,
      "z": -13,
      "name": "Plant_Moss_Wall_Blue",
      "support": 15,
      "rotation": 3
    },
    {
      "x": -15,
      "y": 107,
      "z": -13,
      "name": "Plant_Moss_Wall_Blue",
      "support": 15,
      "rotation": 2
    },
    {
      "x": -15,
      "y": 108,
      "z": -13,
      "name": "Plant_Moss_Wall_Blue",
      "support": 15,
      "rotation": 2
    },
    {
      "x": -15,
      "y": 102,
      "z": -12,
      "name": "Rock_Marble"
    },
    {
      "x": -15,
      "y": 103,
      "z": -12,
      "name": "Rock_Marble"
    },
    {
      "x": -15,
      "y": 104,
      "z": -12,
      "name": "Rock_Marble"
    },
    {
      "x": -15,
      "y": 105,
      "z": -12,
      "name": "Rock_Marble"
    },
    {
      "x": -15,
      "y": 106,
      "z": -12,
      "name": "Rock_Marble"
    },
    {
      "x": -15,
      "y": 107,
      "z": -12,
      "name": "Rock_Marble"
    },
    {
      "x": -15,
      "y": 108,
      "z": -12,
      "name": "Rock_Marble"
    },
    {
      "x": -15,
      "y": 109,
      "z": -12,
      "name": "Plant_Moss_Block_Blue"
    },
    {
      "x": -15,
      "y": 110,
      "z": -12,
      "name": "Plant_Moss_Rug_Lime"
    },
    {
      "x": -15,
      "y": 102,
      "z": -11,
      "name": "Rock_Marble"
    },
    {
      "x": -15,
      "y": 103,
      "z": -11,
      "name": "Rock_Marble"
    },
    {
      "x": -15,
      "y": 104,
      "z": -11,
      "name": "Rock_Marble"
    },
    {
      "x": -15,
      "y": 105,
      "z": -11,
      "name": "Rock_Marble"
    },
    {
      "x": -15,
      "y": 106,
      "z": -11,
      "name": "Rock_Marble"
    },
    {
      "x": -15,
      "y": 107,
      "z": -11,
      "name": "Rock_Marble"
    },
    {
      "x": -15,
      "y": 108,
      "z": -11,
      "name": "Rock_Marble"
    },
    {
      "x": -15,
      "y": 109,
      "z": -11,
      "name": "Plant_Moss_Block_Blue"
    },
    {
      "x": -15,
      "y": 110,
      "z": -11,
      "name": "Plant_Moss_Rug_Lime"
    },
    {
      "x": -15,
      "y": 101,
      "z": -10,
      "name": "Ore_Gold_Calcite"
    },
    {
      "x": -15,
      "y": 102,
      "z": -10,
      "name": "Rock_Marble"
    },
    {
      "x": -15,
      "y": 103,
      "z": -10,
      "name": "Rock_Marble"
    },
    {
      "x": -15,
      "y": 104,
      "z": -10,
      "name": "Rock_Marble"
    },
    {
      "x": -15,
      "y": 105,
      "z": -10,
      "name": "Rock_Marble"
    },
    {
      "x": -15,
      "y": 106,
      "z": -10,
      "name": "Rock_Marble"
    },
    {
      "x": -15,
      "y": 107,
      "z": -10,
      "name": "Rock_Marble"
    },
    {
      "x": -15,
      "y": 108,
      "z": -10,
      "name": "Rock_Marble"
    },
    {
      "x": -15,
      "y": 109,
      "z": -10,
      "name": "Plant_Moss_Block_Blue"
    },
    {
      "x": -15,
      "y": 110,
      "z": -10,
      "name": "Plant_Moss_Rug_Lime"
    },
    {
      "x": -15,
      "y": 101,
      "z": -9,
      "name": "Ore_Gold_Calcite"
    },
    {
      "x": -15,
      "y": 102,
      "z": -9,
      "name": "Ore_Gold_Calcite"
    },
    {
      "x": -15,
      "y": 103,
      "z": -9,
      "name": "Rock_Marble"
    },
    {
      "x": -15,
      "y": 104,
      "z": -9,
      "name": "Rock_Marble"
    },
    {
      "x": -15,
      "y": 105,
      "z": -9,
      "name": "Rock_Marble"
    },
    {
      "x": -15,
      "y": 99,
      "z": -8,
      "name": "Rock_Marble_Stalactite_Large",
      "filler": 31744,
      "rotation": 8
    },
    {
      "x": -15,
      "y": 100,
      "z": -8,
      "name": "Rock_Marble_Stalactite_Large",
      "rotation": 8
    },
    {
      "x": -15,
      "y": 101,
      "z": -8,
      "name": "Rock_Marble"
    },
    {
      "x": -15,
      "y": 102,
      "z": -8,
      "name": "Rock_Marble"
    },
    {
      "x": -15,
      "y": 103,
      "z": -8,
      "name": "Rock_Marble"
    },
    {
      "x": -15,
      "y": 104,
      "z": -8,
      "name": "Rock_Marble"
    },
    {
      "x": -15,
      "y": 105,
      "z": -8,
      "name": "Rock_Marble"
    },
    {
      "x": -15,
      "y": 106,
      "z": -8,
      "name": "Rock_Marble"
    },
    {
      "x": -15,
      "y": 107,
      "z": -8,
      "name": "Rock_Marble"
    },
    {
      "x": -15,
      "y": 108,
      "z": -8,
      "name": "Plant_Moss_Block_Blue"
    },
    {
      "x": -15,
      "y": 109,
      "z": -8,
      "name": "Plant_Moss_Rug_Blue"
    },
    {
      "x": -15,
      "y": 121,
      "z": -8,
      "name": "Plant_Leaves_Azure",
      "rotation": 1
    },
    {
      "x": -15,
      "y": 122,
      "z": -8,
      "name": "Plant_Leaves_Azure",
      "rotation": 1
    },
    {
      "x": -15,
      "y": 123,
      "z": -8,
      "name": "Plant_Leaves_Azure",
      "rotation": 1
    },
    {
      "x": -15,
      "y": 101,
      "z": -7,
      "name": "Rock_Marble"
    },
    {
      "x": -15,
      "y": 102,
      "z": -7,
      "name": "Rock_Marble"
    },
    {
      "x": -15,
      "y": 103,
      "z": -7,
      "name": "Rock_Marble"
    },
    {
      "x": -15,
      "y": 104,
      "z": -7,
      "name": "Rock_Marble"
    },
    {
      "x": -15,
      "y": 105,
      "z": -7,
      "name": "Rock_Marble"
    },
    {
      "x": -15,
      "y": 106,
      "z": -7,
      "name": "Rock_Marble"
    },
    {
      "x": -15,
      "y": 107,
      "z": -7,
      "name": "Rock_Marble"
    },
    {
      "x": -15,
      "y": 108,
      "z": -7,
      "name": "Plant_Moss_Block_Blue"
    },
    {
      "x": -15,
      "y": 109,
      "z": -7,
      "name": "Plant_Moss_Short_Green_Dark"
    },
    {
      "x": -15,
      "y": 122,
      "z": -7,
      "name": "Plant_Leaves_Azure",
      "rotation": 1
    },
    {
      "x": -15,
      "y": 123,
      "z": -7,
      "name": "Plant_Leaves_Azure",
      "rotation": 1
    },
    {
      "x": -15,
      "y": 124,
      "z": -7,
      "name": "Plant_Leaves_Azure",
      "rotation": 1
    },
    {
      "x": -15,
      "y": 99,
      "z": -6,
      "name": "Rock_Marble_Stalactite_Large",
      "filler": 31744,
      "rotation": 8
    },
    {
      "x": -15,
      "y": 100,
      "z": -6,
      "name": "Rock_Marble_Stalactite_Large",
      "rotation": 8
    },
    {
      "x": -15,
      "y": 101,
      "z": -6,
      "name": "Rock_Marble"
    },
    {
      "x": -15,
      "y": 102,
      "z": -6,
      "name": "Rock_Marble"
    },
    {
      "x": -15,
      "y": 103,
      "z": -6,
      "name": "Rock_Marble"
    },
    {
      "x": -15,
      "y": 104,
      "z": -6,
      "name": "Rock_Marble"
    },
    {
      "x": -15,
      "y": 105,
      "z": -6,
      "name": "Rock_Marble"
    },
    {
      "x": -15,
      "y": 106,
      "z": -6,
      "name": "Rock_Marble"
    },
    {
      "x": -15,
      "y": 107,
      "z": -6,
      "name": "Rock_Marble"
    },
    {
      "x": -15,
      "y": 108,
      "z": -6,
      "name": "Rock_Marble"
    },
    {
      "x": -15,
      "y": 109,
      "z": -6,
      "name": "Rock_Marble"
    },
    {
      "x": -15,
      "y": 110,
      "z": -6,
      "name": "Rock_Marble"
    },
    {
      "x": -15,
      "y": 111,
      "z": -6,
      "name": "Rock_Marble"
    },
    {
      "x": -15,
      "y": 112,
      "z": -6,
      "name": "Plant_Moss_Block_Blue"
    },
    {
      "x": -15,
      "y": 113,
      "z": -6,
      "name": "Plant_Moss_Rug_Lime"
    },
    {
      "x": -15,
      "y": 123,
      "z": -6,
      "name": "Plant_Leaves_Azure",
      "rotation": 1
    },
    {
      "x": -15,
      "y": 124,
      "z": -6,
      "name": "Plant_Leaves_Azure",
      "rotation": 1
    },
    {
      "x": -15,
      "y": 127,
      "z": -6,
      "name": "Plant_Leaves_Azure",
      "rotation": 1
    },
    {
      "x": -15,
      "y": 101,
      "z": -5,
      "name": "Rock_Marble"
    },
    {
      "x": -15,
      "y": 102,
      "z": -5,
      "name": "Rock_Marble"
    },
    {
      "x": -15,
      "y": 103,
      "z": -5,
      "name": "Rock_Marble"
    },
    {
      "x": -15,
      "y": 104,
      "z": -5,
      "name": "Rock_Marble"
    },
    {
      "x": -15,
      "y": 105,
      "z": -5,
      "name": "Rock_Marble"
    },
    {
      "x": -15,
      "y": 106,
      "z": -5,
      "name": "Rock_Marble"
    },
    {
      "x": -15,
      "y": 107,
      "z": -5,
      "name": "Rock_Marble"
    },
    {
      "x": -15,
      "y": 108,
      "z": -5,
      "name": "Rock_Marble"
    },
    {
      "x": -15,
      "y": 109,
      "z": -5,
      "name": "Rock_Marble"
    },
    {
      "x": -15,
      "y": 110,
      "z": -5,
      "name": "Rock_Marble"
    },
    {
      "x": -15,
      "y": 111,
      "z": -5,
      "name": "Rock_Marble"
    },
    {
      "x": -15,
      "y": 112,
      "z": -5,
      "name": "Plant_Moss_Block_Blue"
    },
    {
      "x": -15,
      "y": 113,
      "z": -5,
      "name": "Wood_Azure_Trunk_Full",
      "rotation": 1
    },
    {
      "x": -15,
      "y": 114,
      "z": -5,
      "name": "Wood_Azure_Trunk",
      "rotation": 1
    },
    {
      "x": -15,
      "y": 115,
      "z": -5,
      "name": "Wood_Azure_Trunk",
      "rotation": 1
    },
    {
      "x": -15,
      "y": 116,
      "z": -5,
      "name": "Wood_Azure_Trunk_Full",
      "rotation": 1
    },
    {
      "x": -15,
      "y": 126,
      "z": -5,
      "name": "Plant_Leaves_Azure",
      "rotation": 1
    },
    {
      "x": -15,
      "y": 127,
      "z": -5,
      "name": "Plant_Leaves_Azure",
      "rotation": 1
    },
    {
      "x": -15,
      "y": 128,
      "z": -5,
      "name": "Plant_Fruit_Azure",
      "rotation": 1
    },
    {
      "x": -15,
      "y": 130,
      "z": -5,
      "name": "Plant_Leaves_Azure",
      "rotation": 1
    },
    {
      "x": -15,
      "y": 99,
      "z": -4,
      "name": "Rock_Marble_Stalactite_Large",
      "filler": 31744,
      "rotation": 8
    },
    {
      "x": -15,
      "y": 100,
      "z": -4,
      "name": "Rock_Marble_Stalactite_Large",
      "rotation": 8
    },
    {
      "x": -15,
      "y": 101,
      "z": -4,
      "name": "Rock_Marble"
    },
    {
      "x": -15,
      "y": 102,
      "z": -4,
      "name": "Rock_Marble"
    },
    {
      "x": -15,
      "y": 103,
      "z": -4,
      "name": "Rock_Marble"
    },
    {
      "x": -15,
      "y": 104,
      "z": -4,
      "name": "Rock_Marble"
    },
    {
      "x": -15,
      "y": 105,
      "z": -4,
      "name": "Rock_Marble"
    },
    {
      "x": -15,
      "y": 106,
      "z": -4,
      "name": "Rock_Marble"
    },
    {
      "x": -15,
      "y": 107,
      "z": -4,
      "name": "Rock_Marble"
    },
    {
      "x": -15,
      "y": 108,
      "z": -4,
      "name": "Rock_Marble"
    },
    {
      "x": -15,
      "y": 109,
      "z": -4,
      "name": "Rock_Marble"
    },
    {
      "x": -15,
      "y": 110,
      "z": -4,
      "name": "Rock_Marble"
    },
    {
      "x": -15,
      "y": 111,
      "z": -4,
      "name": "Rock_Marble"
    },
    {
      "x": -15,
      "y": 112,
      "z": -4,
      "name": "Plant_Moss_Block_Blue"
    },
    {
      "x": -15,
      "y": 113,
      "z": -4,
      "name": "Wood_Azure_Trunk_Full",
      "rotation": 1
    },
    {
      "x": -15,
      "y": 114,
      "z": -4,
      "name": "Wood_Azure_Trunk",
      "rotation": 1
    },
    {
      "x": -15,
      "y": 115,
      "z": -4,
      "name": "Wood_Azure_Trunk",
      "rotation": 1
    },
    {
      "x": -15,
      "y": 116,
      "z": -4,
      "name": "Wood_Azure_Trunk",
      "rotation": 1
    },
    {
      "x": -15,
      "y": 117,
      "z": -4,
      "name": "Wood_Azure_Trunk",
      "rotation": 1
    },
    {
      "x": -15,
      "y": 118,
      "z": -4,
      "name": "Wood_Azure_Trunk",
      "rotation": 1
    },
    {
      "x": -15,
      "y": 119,
      "z": -4,
      "name": "Wood_Azure_Trunk",
      "rotation": 1
    },
    {
      "x": -15,
      "y": 120,
      "z": -4,
      "name": "Wood_Azure_Trunk_Full",
      "rotation": 1
    },
    {
      "x": -15,
      "y": 124,
      "z": -4,
      "name": "Plant_Moss_Wall_Blue",
      "rotation": 1
    },
    {
      "x": -15,
      "y": 126,
      "z": -4,
      "name": "Wood_Azure_Branch_Long",
      "rotation": 5
    },
    {
      "x": -15,
      "y": 129,
      "z": -4,
      "name": "Plant_Leaves_Azure",
      "rotation": 1
    },
    {
      "x": -15,
      "y": 130,
      "z": -4,
      "name": "Plant_Leaves_Azure",
      "rotation": 1
    },
    {
      "x": -15,
      "y": 131,
      "z": -4,
      "name": "Plant_Leaves_Azure",
      "rotation": 1
    },
    {
      "x": -15,
      "y": 102,
      "z": -3,
      "name": "Rock_Marble"
    },
    {
      "x": -15,
      "y": 103,
      "z": -3,
      "name": "Rock_Marble"
    },
    {
      "x": -15,
      "y": 104,
      "z": -3,
      "name": "Rock_Marble"
    },
    {
      "x": -15,
      "y": 105,
      "z": -3,
      "name": "Rock_Marble"
    },
    {
      "x": -15,
      "y": 106,
      "z": -3,
      "name": "Rock_Marble"
    },
    {
      "x": -15,
      "y": 107,
      "z": -3,
      "name": "Rock_Marble"
    },
    {
      "x": -15,
      "y": 108,
      "z": -3,
      "name": "Rock_Marble"
    },
    {
      "x": -15,
      "y": 109,
      "z": -3,
      "name": "Rock_Marble"
    },
    {
      "x": -15,
      "y": 110,
      "z": -3,
      "name": "Rock_Marble"
    },
    {
      "x": -15,
      "y": 111,
      "z": -3,
      "name": "Rock_Marble"
    },
    {
      "x": -15,
      "y": 112,
      "z": -3,
      "name": "Plant_Moss_Block_Blue"
    },
    {
      "x": -15,
      "y": 113,
      "z": -3,
      "name": "Plant_Moss_Short_Green_Dark"
    },
    {
      "x": -15,
      "y": 114,
      "z": -3,
      "name": "Wood_Azure_Trunk_Full",
      "rotation": 1
    },
    {
      "x": -15,
      "y": 115,
      "z": -3,
      "name": "Wood_Azure_Trunk",
      "rotation": 1
    },
    {
      "x": -15,
      "y": 116,
      "z": -3,
      "name": "Wood_Azure_Trunk",
      "rotation": 1
    },
    {
      "x": -15,
      "y": 117,
      "z": -3,
      "name": "Wood_Azure_Trunk",
      "rotation": 1
    },
    {
      "x": -15,
      "y": 118,
      "z": -3,
      "name": "Wood_Azure_Trunk_Full",
      "rotation": 1
    },
    {
      "x": -15,
      "y": 129,
      "z": -3,
      "name": "Plant_Leaves_Azure",
      "rotation": 1
    },
    {
      "x": -15,
      "y": 130,
      "z": -3,
      "name": "Plant_Leaves_Azure",
      "rotation": 1
    },
    {
      "x": -15,
      "y": 131,
      "z": -3,
      "name": "Plant_Leaves_Azure",
      "rotation": 1
    },
    {
      "x": -15,
      "y": 101,
      "z": -2,
      "name": "Rock_Marble"
    },
    {
      "x": -15,
      "y": 102,
      "z": -2,
      "name": "Rock_Marble"
    },
    {
      "x": -15,
      "y": 103,
      "z": -2,
      "name": "Rock_Marble"
    },
    {
      "x": -15,
      "y": 104,
      "z": -2,
      "name": "Rock_Marble"
    },
    {
      "x": -15,
      "y": 105,
      "z": -2,
      "name": "Rock_Marble"
    },
    {
      "x": -15,
      "y": 106,
      "z": -2,
      "name": "Rock_Marble"
    },
    {
      "x": -15,
      "y": 107,
      "z": -2,
      "name": "Rock_Marble"
    },
    {
      "x": -15,
      "y": 108,
      "z": -2,
      "name": "Rock_Marble"
    },
    {
      "x": -15,
      "y": 109,
      "z": -2,
      "name": "Rock_Marble"
    },
    {
      "x": -15,
      "y": 110,
      "z": -2,
      "name": "Rock_Marble"
    },
    {
      "x": -15,
      "y": 111,
      "z": -2,
      "name": "Rock_Marble"
    },
    {
      "x": -15,
      "y": 112,
      "z": -2,
      "name": "Plant_Moss_Block_Blue"
    },
    {
      "x": -15,
      "y": 113,
      "z": -2,
      "name": "Plant_Moss_Rug_Lime"
    },
    {
      "x": -15,
      "y": 123,
      "z": -2,
      "name": "Wood_Azure_Branch_Long",
      "rotation": 5
    },
    {
      "x": -15,
      "y": 127,
      "z": -2,
      "name": "Plant_Leaves_Azure",
      "rotation": 1
    },
    {
      "x": -15,
      "y": 128,
      "z": -2,
      "name": "Plant_Leaves_Azure",
      "rotation": 1
    },
    {
      "x": -15,
      "y": 129,
      "z": -2,
      "name": "Plant_Leaves_Azure",
      "rotation": 1
    },
    {
      "x": -15,
      "y": 130,
      "z": -2,
      "name": "Plant_Leaves_Azure",
      "rotation": 1
    },
    {
      "x": -15,
      "y": 131,
      "z": -2,
      "name": "Plant_Leaves_Azure",
      "rotation": 1
    },
    {
      "x": -15,
      "y": 132,
      "z": -2,
      "name": "Plant_Fruit_Azure",
      "rotation": 1
    },
    {
      "x": -15,
      "y": 100,
      "z": -1,
      "name": "Rock_Marble"
    },
    {
      "x": -15,
      "y": 101,
      "z": -1,
      "name": "Rock_Marble"
    },
    {
      "x": -15,
      "y": 102,
      "z": -1,
      "name": "Rock_Marble"
    },
    {
      "x": -15,
      "y": 103,
      "z": -1,
      "name": "Rock_Marble"
    },
    {
      "x": -15,
      "y": 104,
      "z": -1,
      "name": "Rock_Marble"
    },
    {
      "x": -15,
      "y": 105,
      "z": -1,
      "name": "Rock_Marble"
    },
    {
      "x": -15,
      "y": 106,
      "z": -1,
      "name": "Rock_Marble"
    },
    {
      "x": -15,
      "y": 107,
      "z": -1,
      "name": "Rock_Marble"
    },
    {
      "x": -15,
      "y": 108,
      "z": -1,
      "name": "Rock_Marble"
    },
    {
      "x": -15,
      "y": 109,
      "z": -1,
      "name": "Rock_Marble"
    },
    {
      "x": -15,
      "y": 110,
      "z": -1,
      "name": "Rock_Marble"
    },
    {
      "x": -15,
      "y": 111,
      "z": -1,
      "name": "Plant_Moss_Block_Blue"
    },
    {
      "x": -15,
      "y": 112,
      "z": -1,
      "name": "Plant_Moss_Short_Green_Dark"
    },
    {
      "x": -15,
      "y": 120,
      "z": -1,
      "name": "Plant_Moss_Wall_Blue",
      "rotation": 1
    },
    {
      "x": -15,
      "y": 126,
      "z": -1,
      "name": "Plant_Leaves_Azure",
      "rotation": 1
    },
    {
      "x": -15,
      "y": 127,
      "z": -1,
      "name": "Plant_Leaves_Azure",
      "rotation": 1
    },
    {
      "x": -15,
      "y": 128,
      "z": -1,
      "name": "Plant_Leaves_Azure",
      "rotation": 1
    },
    {
      "x": -15,
      "y": 129,
      "z": -1,
      "name": "Plant_Leaves_Azure",
      "rotation": 1
    },
    {
      "x": -15,
      "y": 130,
      "z": -1,
      "name": "Plant_Leaves_Azure",
      "rotation": 1
    },
    {
      "x": -15,
      "y": 101,
      "z": 0,
      "name": "Rock_Marble"
    },
    {
      "x": -15,
      "y": 102,
      "z": 0,
      "name": "Rock_Marble"
    },
    {
      "x": -15,
      "y": 103,
      "z": 0,
      "name": "Rock_Marble"
    },
    {
      "x": -15,
      "y": 104,
      "z": 0,
      "name": "Rock_Marble"
    },
    {
      "x": -15,
      "y": 105,
      "z": 0,
      "name": "Rock_Marble"
    },
    {
      "x": -15,
      "y": 106,
      "z": 0,
      "name": "Rock_Marble"
    },
    {
      "x": -15,
      "y": 107,
      "z": 0,
      "name": "Rock_Marble"
    },
    {
      "x": -15,
      "y": 108,
      "z": 0,
      "name": "Rock_Marble"
    },
    {
      "x": -15,
      "y": 109,
      "z": 0,
      "name": "Rock_Marble"
    },
    {
      "x": -15,
      "y": 110,
      "z": 0,
      "name": "Rock_Marble"
    },
    {
      "x": -15,
      "y": 111,
      "z": 0,
      "name": "Plant_Moss_Block_Blue"
    },
    {
      "x": -15,
      "y": 112,
      "z": 0,
      "name": "Plant_Moss_Short_Green_Dark"
    },
    {
      "x": -15,
      "y": 122,
      "z": 0,
      "name": "Plant_Leaves_Azure",
      "rotation": 1
    },
    {
      "x": -15,
      "y": 123,
      "z": 0,
      "name": "Plant_Leaves_Azure",
      "rotation": 1
    },
    {
      "x": -15,
      "y": 127,
      "z": 0,
      "name": "Plant_Leaves_Azure",
      "rotation": 1
    },
    {
      "x": -15,
      "y": 128,
      "z": 0,
      "name": "Plant_Leaves_Azure",
      "rotation": 1
    },
    {
      "x": -15,
      "y": 100,
      "z": 1,
      "name": "Rock_Marble"
    },
    {
      "x": -15,
      "y": 101,
      "z": 1,
      "name": "Rock_Marble"
    },
    {
      "x": -15,
      "y": 102,
      "z": 1,
      "name": "Rock_Marble"
    },
    {
      "x": -15,
      "y": 103,
      "z": 1,
      "name": "Rock_Marble"
    },
    {
      "x": -15,
      "y": 104,
      "z": 1,
      "name": "Rock_Marble"
    },
    {
      "x": -15,
      "y": 105,
      "z": 1,
      "name": "Rock_Marble"
    },
    {
      "x": -15,
      "y": 106,
      "z": 1,
      "name": "Rock_Marble"
    },
    {
      "x": -15,
      "y": 107,
      "z": 1,
      "name": "Rock_Marble"
    },
    {
      "x": -15,
      "y": 108,
      "z": 1,
      "name": "Rock_Marble"
    },
    {
      "x": -15,
      "y": 109,
      "z": 1,
      "name": "Rock_Marble"
    },
    {
      "x": -15,
      "y": 110,
      "z": 1,
      "name": "Rock_Marble"
    },
    {
      "x": -15,
      "y": 111,
      "z": 1,
      "name": "Plant_Moss_Block_Blue"
    },
    {
      "x": -15,
      "y": 112,
      "z": 1,
      "name": "Plant_Moss_Rug_Lime"
    },
    {
      "x": -15,
      "y": 119,
      "z": 1,
      "name": "Plant_Leaves_Azure",
      "rotation": 1
    },
    {
      "x": -15,
      "y": 120,
      "z": 1,
      "name": "Plant_Leaves_Azure",
      "rotation": 1
    },
    {
      "x": -15,
      "y": 121,
      "z": 1,
      "name": "Plant_Leaves_Azure",
      "rotation": 1
    },
    {
      "x": -15,
      "y": 122,
      "z": 1,
      "name": "Plant_Leaves_Azure",
      "rotation": 1
    },
    {
      "x": -15,
      "y": 99,
      "z": 2,
      "name": "Rock_Marble"
    },
    {
      "x": -15,
      "y": 100,
      "z": 2,
      "name": "Rock_Marble"
    },
    {
      "x": -15,
      "y": 101,
      "z": 2,
      "name": "Rock_Marble"
    },
    {
      "x": -15,
      "y": 102,
      "z": 2,
      "name": "Rock_Marble"
    },
    {
      "x": -15,
      "y": 103,
      "z": 2,
      "name": "Rock_Marble"
    },
    {
      "x": -15,
      "y": 104,
      "z": 2,
      "name": "Rock_Marble"
    },
    {
      "x": -15,
      "y": 105,
      "z": 2,
      "name": "Rock_Marble"
    },
    {
      "x": -15,
      "y": 106,
      "z": 2,
      "name": "Rock_Marble"
    },
    {
      "x": -15,
      "y": 107,
      "z": 2,
      "name": "Rock_Marble"
    },
    {
      "x": -15,
      "y": 108,
      "z": 2,
      "name": "Rock_Marble"
    },
    {
      "x": -15,
      "y": 109,
      "z": 2,
      "name": "Rock_Marble"
