{
  "version": 8,
  "blockIdVersion": 11,
  "anchorX": 0,
  "anchorY": 0,
  "anchorZ": 0,
  "blocks": [
    {
      "x": -17,
      "y": 110,
      "z": 0,
      "name": "Plant_Leaves_Azure",
      "rotation": 1
    },
    {
      "x": -17,
      "y": 111,
      "z": 0,
      "name": "Plant_Leaves_Azure",
      "rotation": 1
    },
    {
      "x": -17,
      "y": 112,
      "z": 0,
      "name": "Plant_Leaves_Azure",
      "rotation": 1
    },
    {
      "x": -17,
      "y": 110,
      "z": 1,
      "name": "Plant_Leaves_Azure",
      "rotation": 1
    },
    {
      "x": -17,
      "y": 111,
      "z": 1,
      "name": "Plant_Leaves_Azure",
      "rotation": 1
    },
    {
      "x": -17,
      "y": 112,
      "z": 1,
      "name": "Plant_Leaves_Azure",
      "rotation": 1
    },
    {
      "x": -17,
      "y": 113,
      "z": 1,
      "name": "Plant_Leaves_Azure",
      "rotation": 1
    },
    {
      "x": -17,
      "y": 110,
      "z": 2,
      "name": "Plant_Leaves_Azure",
      "rotation": 1
    },
    {
      "x": -17,
      "y": 111,
      "z": 2,
      "name": "Plant_Leaves_Azure",
      "rotation": 1
    },
    {
      "x": -17,
      "y": 112,
      "z": 2,
      "name": "Plant_Leaves_Azure",
      "rotation": 1
    },
    {
      "x": -17,
      "y": 113,
      "z": 2,
      "name": "Plant_Leaves_Azure",
      "rotation": 1
    },
    {
      "x": -17,
      "y": 111,
      "z": 3,
      "name": "Plant_Leaves_Azure",
      "rotation": 1
    },
    {
      "x": -17,
      "y": 112,
      "z": 3,
      "name": "Plant_Leaves_Azure",
      "rotation": 1
    },
    {
      "x": -17,
      "y": 113,
      "z": 3,
      "name": "Plant_Leaves_Azure",
      "rotation": 1
    },
    {
      "x": -17,
      "y": 114,
      "z": 3,
      "name": "Plant_Leaves_Azure",
      "rotation": 1
    },
    {
      "x": -17,
      "y": 112,
      "z": 4,
      "name": "Plant_Leaves_Azure",
      "rotation": 1
    },
    {
      "x": -17,
      "y": 113,
      "z": 4,
      "name": "Plant_Leaves_Azure",
      "rotation": 1
    },
    {
      "x": -17,
      "y": 114,
      "z": 4,
      "name": "Plant_Leaves_Azure",
      "rotation": 1
    },
    {
      "x": -16,
      "y": 109,
      "z": -1,
      "name": "Plant_Leaves_Azure",
      "rotation": 1
    },
    {
      "x": -16,
      "y": 110,
      "z": -1,
      "name": "Plant_Leaves_Azure",
      "rotation": 1
    },
    {
      "x": -16,
      "y": 111,
      "z": -1,
      "name": "Plant_Leaves_Azure",
      "rotation": 1
    },
    {
      "x": -16,
      "y": 112,
      "z": -1,
      "name": "Plant_Leaves_Azure",
      "rotation": 1
    },
    {
      "x": -16,
      "y": 109,
      "z": 0,
      "name": "Plant_Leaves_Azure",
      "rotation": 1
    },
    {
      "x": -16,
      "y": 110,
      "z": 0,
      "name": "Plant_Leaves_Azure",
      "rotation": 1
    },
    {
      "x": -16,
      "y": 111,
      "z": 0,
      "name": "Plant_Leaves_Azure",
      "rotation": 1
    },
    {
      "x": -16,
      "y": 112,
      "z": 0,
      "name": "Plant_Leaves_Azure",
      "rotation": 1
    },
    {
      "x": -16,
      "y": 113,
      "z": 0,
      "name": "Plant_Leaves_Azure",
      "rotation": 1
    },
    {
      "x": -16,
      "y": 109,
      "z": 1,
      "name": "Plant_Leaves_Azure",
      "rotation": 1
    },
    {
      "x": -16,
      "y": 110,
      "z": 1,
      "name": "Plant_Leaves_Azure",
      "rotation": 1
    },
    {
      "x": -16,
      "y": 111,
      "z": 1,
      "name": "Plant_Leaves_Azure",
      "rotation": 1
    },
    {
      "x": -16,
      "y": 112,
      "z": 1,
      "name": "Plant_Leaves_Azure",
      "rotation": 1
    },
    {
      "x": -16,
      "y": 113,
      "z": 1,
      "name": "Plant_Leaves_Azure",
      "rotation": 1
    },
    {
      "x": -16,
      "y": 114,
      "z": 1,
      "name": "Plant_Leaves_Azure",
      "rotation": 1
    },
    {
      "x": -16,
      "y": 110,
      "z": 2,
      "name": "Plant_Leaves_Azure",
      "rotation": 1
    },
    {
      "x": -16,
      "y": 111,
      "z": 2,
      "name": "Plant_Leaves_Azure",
      "rotation": 1
    },
    {
      "x": -16,
      "y": 112,
      "z": 2,
      "name": "Plant_Leaves_Azure",
      "rotation": 1
    },
    {
      "x": -16,
      "y": 113,
      "z": 2,
      "name": "Plant_Leaves_Azure",
      "rotation": 1
    },
    {
      "x": -16,
      "y": 114,
      "z": 2,
      "name": "Plant_Leaves_Azure",
      "rotation": 1
    },
    {
      "x": -16,
      "y": 115,
      "z": 2,
      "name": "Plant_Fruit_Azure",
      "rotation": 1
    },
    {
      "x": -16,
      "y": 110,
      "z": 3,
      "name": "Plant_Leaves_Azure",
      "rotation": 1
    },
    {
      "x": -16,
      "y": 111,
      "z": 3,
      "name": "Plant_Leaves_Azure",
      "rotation": 1
    },
    {
      "x": -16,
      "y": 112,
      "z": 3,
      "name": "Plant_Leaves_Azure",
      "rotation": 1
    },
    {
      "x": -16,
      "y": 113,
      "z": 3,
      "name": "Plant_Leaves_Azure",
      "rotation": 1
    },
    {
      "x": -16,
      "y": 114,
      "z": 3,
      "name": "Plant_Leaves_Azure",
      "rotation": 1
    },
    {
      "x": -16,
      "y": 115,
      "z": 3,
      "name": "Plant_Leaves_Azure",
      "rotation": 1
    },
    {
      "x": -16,
      "y": 111,
      "z": 4,
      "name": "Plant_Leaves_Azure",
      "rotation": 1
    },
    {
      "x": -16,
      "y": 112,
      "z": 4,
      "name": "Plant_Leaves_Azure",
      "rotation": 1
    },
    {
      "x": -16,
      "y": 113,
      "z": 4,
      "name": "Plant_Leaves_Azure",
      "rotation": 1
    },
    {
      "x": -16,
      "y": 114,
      "z": 4,
      "name": "Plant_Leaves_Azure",
      "rotation": 1
    },
    {
      "x": -16,
      "y": 115,
      "z": 4,
      "name": "Plant_Leaves_Azure",
      "rotation": 1
    },
    {
      "x": -16,
      "y": 112,
      "z": 5,
      "name": "Plant_Leaves_Azure",
      "rotation": 1
    },
    {
      "x": -16,
      "y": 113,
      "z": 5,
      "name": "Plant_Leaves_Azure",
      "rotation": 1
    },
    {
      "x": -16,
      "y": 114,
      "z": 5,
      "name": "Plant_Leaves_Azure",
      "rotation": 1
    },
    {
      "x": -16,
      "y": 115,
      "z": 5,
      "name": "Plant_Leaves_Azure",
      "rotation": 1
    },
    {
      "x": -15,
      "y": 109,
      "z": -2,
      "name": "Plant_Leaves_Azure",
      "rotation": 1
    },
    {
      "x": -15,
      "y": 110,
      "z": -2,
      "name": "Plant_Leaves_Azure",
      "rotation": 1
    },
    {
      "x": -15,
      "y": 111,
      "z": -2,
      "name": "Plant_Leaves_Azure",
      "rotation": 1
    },
    {
      "x": -15,
      "y": 108,
      "z": -1,
      "name": "Plant_Leaves_Azure",
      "rotation": 1
    },
    {
      "x": -15,
      "y": 109,
      "z": -1,
      "name": "Plant_Leaves_Azure",
      "rotation": 1
    },
    {
      "x": -15,
      "y": 110,
      "z": -1,
      "name": "Plant_Leaves_Azure",
      "rotation": 1
    },
    {
      "x": -15,
      "y": 111,
      "z": -1,
      "name": "Plant_Leaves_Azure",
      "rotation": 1
    },
    {
      "x": -15,
      "y": 112,
      "z": -1,
      "name": "Plant_Leaves_Azure",
      "rotation": 1
    },
    {
      "x": -15,
      "y": 113,
      "z": -1,
      "name": "Plant_Leaves_Azure",
      "rotation": 1
    },
    {
      "x": -15,
      "y": 108,
      "z": 0,
      "name": "Plant_Leaves_Azure",
      "rotation": 1
    },
    {
      "x": -15,
      "y": 109,
      "z": 0,
      "name": "Plant_Leaves_Azure",
      "rotation": 1
    },
    {
      "x": -15,
      "y": 110,
      "z": 0,
      "name": "Plant_Leaves_Azure",
      "rotation": 1
    },
    {
      "x": -15,
      "y": 111,
      "z": 0,
      "name": "Plant_Leaves_Azure",
      "rotation": 1
    },
    {
      "x": -15,
      "y": 112,
      "z": 0,
      "name": "Plant_Leaves_Azure",
      "rotation": 1
    },
    {
      "x": -15,
      "y": 113,
      "z": 0,
      "name": "Plant_Leaves_Azure",
      "rotation": 1
    },
    {
      "x": -15,
      "y": 114,
      "z": 0,
      "name": "Plant_Fruit_Azure",
      "rotation": 1
    },
    {
      "x": -15,
      "y": 109,
      "z": 1,
      "name": "Plant_Leaves_Azure",
      "rotation": 1
    },
    {
      "x": -15,
      "y": 110,
      "z": 1,
      "name": "Plant_Leaves_Azure",
      "rotation": 1
    },
    {
      "x": -15,
      "y": 111,
      "z": 1,
      "name": "Plant_Leaves_Azure",
      "rotation": 1
    },
    {
      "x": -15,
      "y": 112,
      "z": 1,
      "name": "Plant_Leaves_Azure",
      "rotation": 1
    },
    {
      "x": -15,
      "y": 113,
      "z": 1,
      "name": "Plant_Leaves_Azure",
      "rotation": 1
    },
    {
      "x": -15,
      "y": 114,
      "z": 1,
      "name": "Plant_Fruit_Azure",
      "rotation": 1
    },
    {
      "x": -15,
      "y": 109,
      "z": 2,
      "name": "Plant_Leaves_Azure",
      "rotation": 1
    },
    {
      "x": -15,
      "y": 110,
      "z": 2,
      "name": "Plant_Leaves_Azure",
      "rotation": 1
    },
    {
      "x": -15,
      "y": 111,
      "z": 2,
      "name": "Plant_Leaves_Azure",
      "rotation": 1
    },
    {
      "x": -15,
      "y": 112,
      "z": 2,
      "name": "Wood_Azure_Branch_Long",
      "rotation": 5
    },
    {
      "x": -15,
      "y": 113,
      "z": 2,
      "name": "Plant_Leaves_Azure",
      "rotation": 1
    },
    {
      "x": -15,
      "y": 114,
      "z": 2,
      "name": "Plant_Leaves_Azure",
      "rotation": 1
    },
    {
      "x": -15,
      "y": 110,
      "z": 3,
      "name": "Plant_Leaves_Azure",
      "rotation": 1
    },
    {
      "x": -15,
      "y": 111,
      "z": 3,
      "name": "Plant_Leaves_Azure",
      "rotation": 1
    },
    {
      "x": -15,
      "y": 112,
      "z": 3,
      "name": "Plant_Leaves_Azure",
      "rotation": 1
    },
    {
      "x": -15,
      "y": 113,
      "z": 3,
      "name": "Plant_Leaves_Azure",
      "rotation": 1
    },
    {
      "x": -15,
      "y": 114,
      "z": 3,
      "name": "Wood_Azure_Branch_Long",
      "rotation": 5
    },
    {
      "x": -15,
      "y": 115,
      "z": 3,
      "name": "Plant_Leaves_Azure",
      "rotation": 1
    },
    {
      "x": -15,
      "y": 111,
      "z": 4,
      "name": "Plant_Leaves_Azure",
      "rotation": 1
    },
    {
      "x": -15,
      "y": 112,
      "z": 4,
      "name": "Plant_Leaves_Azure",
      "rotation": 1
    },
    {
      "x": -15,
      "y": 113,
      "z": 4,
      "name": "Plant_Leaves_Azure",
      "rotation": 1
    },
    {
      "x": -15,
      "y": 114,
      "z": 4,
      "name": "Plant_Leaves_Azure",
      "rotation": 1
    },
    {
      "x": -15,
      "y": 115,
      "z": 4,
      "name": "Plant_Leaves_Azure",
      "rotation": 1
    },
    {
      "x": -15,
      "y": 116,
      "z": 4,
      "name": "Plant_Leaves_Azure",
      "rotation": 1
    },
    {
      "x": -15,
      "y": 112,
      "z": 5,
      "name": "Plant_Leaves_Azure",
      "rotation": 1
    },
    {
      "x": -15,
      "y": 113,
      "z": 5,
      "name": "Plant_Leaves_Azure",
      "rotation": 1
    },
    {
      "x": -15,
      "y": 114,
      "z": 5,
      "name": "Plant_Leaves_Azure",
      "rotation": 1
    },
    {
      "x": -15,
      "y": 115,
      "z": 5,
      "name": "Plant_Leaves_Azure",
      "rotation": 1
    },
    {
      "x": -15,
      "y": 116,
      "z": 5,
      "name": "Plant_Leaves_Azure",
      "rotation": 1
    },
    {
      "x": -15,
      "y": 113,
      "z": 6,
      "name": "Plant_Leaves_Azure",
      "rotation": 1
    },
    {
      "x": -15,
      "y": 114,
      "z": 6,
      "name": "Plant_Leaves_Azure",
      "rotation": 1
    },
    {
      "x": -15,
      "y": 115,
      "z": 6,
      "name": "Plant_Leaves_Azure",
      "rotation": 1
    },
    {
      "x": -14,
      "y": 108,
      "z": -3,
      "name": "Plant_Leaves_Azure",
      "rotation": 1
    },
    {
      "x": -14,
      "y": 109,
      "z": -3,
      "name": "Plant_Leaves_Azure",
      "rotation": 1
    },
    {
      "x": -14,
      "y": 110,
      "z": -3,
      "name": "Plant_Leaves_Azure",
      "rotation": 1
    },
    {
      "x": -14,
      "y": 108,
      "z": -2,
      "name": "Plant_Leaves_Azure",
      "rotation": 1
    },
    {
      "x": -14,
      "y": 109,
      "z": -2,
      "name": "Plant_Leaves_Azure",
      "rotation": 1
    },
    {
      "x": -14,
      "y": 110,
      "z": -2,
      "name": "Plant_Leaves_Azure",
      "rotation": 1
    },
    {
      "x": -14,
      "y": 111,
      "z": -2,
      "name": "Plant_Leaves_Azure",
      "rotation": 1
    },
    {
      "x": -14,
      "y": 112,
      "z": -2,
      "name": "Plant_Leaves_Azure",
      "rotation": 1
    },
    {
      "x": -14,
      "y": 109,
      "z": -1,
      "name": "Plant_Leaves_Azure",
      "rotation": 1
    },
    {
      "x": -14,
      "y": 110,
      "z": -1,
      "name": "Plant_Leaves_Azure",
      "rotation": 1
    },
    {
      "x": -14,
      "y": 111,
      "z": -1,
      "name": "Plant_Leaves_Azure",
      "rotation": 1
    },
    {
      "x": -14,
      "y": 112,
      "z": -1,
      "name": "Plant_Leaves_Azure",
      "rotation": 1
    },
    {
      "x": -14,
      "y": 113,
      "z": -1,
      "name": "Plant_Fruit_Azure",
      "rotation": 1
    },
    {
      "x": -14,
      "y": 110,
      "z": 0,
      "name": "Plant_Leaves_Azure",
      "rotation": 1
    },
    {
      "x": -14,
      "y": 111,
      "z": 0,
      "name": "Plant_Leaves_Azure",
      "rotation": 1
    },
    {
      "x": -14,
      "y": 112,
      "z": 0,
      "name": "Plant_Leaves_Azure",
      "rotation": 1
    },
    {
      "x": -14,
      "y": 113,
      "z": 0,
      "name": "Plant_Leaves_Azure",
      "rotation": 1
    },
    {
      "x": -14,
      "y": 116,
      "z": 0,
      "name": "Plant_Leaves_Azure",
      "rotation": 1
    },
    {
      "x": -14,
      "y": 117,
      "z": 0,
      "name": "Plant_Leaves_Azure",
      "rotation": 1
    },
    {
      "x": -14,
      "y": 118,
      "z": 0,
      "name": "Plant_Leaves_Azure",
      "rotation": 1
    },
    {
      "x": -14,
      "y": 110,
      "z": 1,
      "name": "Plant_Leaves_Azure",
      "rotation": 1
    },
    {
      "x": -14,
      "y": 111,
      "z": 1,
      "name": "Wood_Azure_Branch_Long",
      "rotation": 5
    },
    {
      "x": -14,
      "y": 112,
      "z": 1,
      "name": "Plant_Leaves_Azure",
      "rotation": 1
    },
    {
      "x": -14,
      "y": 113,
      "z": 1,
      "name": "Plant_Leaves_Azure",
      "rotation": 1
    },
    {
      "x": -14,
      "y": 117,
      "z": 1,
      "name": "Plant_Leaves_Azure",
      "rotation": 1
    },
    {
      "x": -14,
      "y": 118,
      "z": 1,
      "name": "Plant_Leaves_Azure",
      "rotation": 1
    },
    {
      "x": -14,
      "y": 119,
      "z": 1,
      "name": "Plant_Leaves_Azure",
      "rotation": 1
    },
    {
      "x": -14,
      "y": 111,
      "z": 2,
      "name": "Plant_Leaves_Azure",
      "rotation": 1
    },
    {
      "x": -14,
      "y": 112,
      "z": 2,
      "name": "Wood_Azure_Branch_Long",
      "rotation": 5
    },
    {
      "x": -14,
      "y": 113,
      "z": 2,
      "name": "Wood_Azure_Branch_Long",
      "rotation": 5
    },
    {
      "x": -14,
      "y": 114,
      "z": 2,
      "name": "Plant_Leaves_Azure",
      "rotation": 1
    },
    {
      "x": -14,
      "y": 118,
      "z": 2,
      "name": "Plant_Leaves_Azure",
      "rotation": 1
    },
    {
      "x": -14,
      "y": 119,
      "z": 2,
      "name": "Plant_Leaves_Azure",
      "rotation": 1
    },
    {
      "x": -14,
      "y": 120,
      "z": 2,
      "name": "Plant_Leaves_Azure",
      "rotation": 1
    },
    {
      "x": -14,
      "y": 111,
      "z": 3,
      "name": "Plant_Leaves_Azure",
      "rotation": 1
    },
    {
      "x": -14,
      "y": 112,
      "z": 3,
      "name": "Plant_Leaves_Azure",
      "rotation": 1
    },
    {
      "x": -14,
      "y": 113,
      "z": 3,
      "name": "Plant_Leaves_Azure",
      "rotation": 1
    },
    {
      "x": -14,
      "y": 114,
      "z": 3,
      "name": "Wood_Azure_Branch_Long",
      "rotation": 5
    },
    {
      "x": -14,
      "y": 115,
      "z": 3,
      "name": "Plant_Leaves_Azure",
      "rotation": 1
    },
    {
      "x": -14,
      "y": 119,
      "z": 3,
      "name": "Plant_Leaves_Azure",
      "rotation": 1
    },
    {
      "x": -14,
      "y": 111,
      "z": 4,
      "name": "Plant_Leaves_Azure",
      "rotation": 1
    },
    {
      "x": -14,
      "y": 112,
      "z": 4,
      "name": "Plant_Leaves_Azure",
      "rotation": 1
    },
    {
      "x": -14,
      "y": 113,
      "z": 4,
      "name": "Plant_Leaves_Azure",
      "rotation": 1
    },
    {
      "x": -14,
      "y": 114,
      "z": 4,
      "name": "Plant_Leaves_Azure",
      "rotation": 1
    },
    {
      "x": -14,
      "y": 115,
      "z": 4,
      "name": "Plant_Leaves_Azure",
      "rotation": 1
    },
    {
      "x": -14,
      "y": 116,
      "z": 4,
      "name": "Plant_Leaves_Azure",
      "rotation": 1
    },
    {
      "x": -14,
      "y": 112,
      "z": 5,
      "name": "Plant_Leaves_Azure",
      "rotation": 1
    },
    {
      "x": -14,
      "y": 113,
      "z": 5,
      "name": "Plant_Leaves_Azure",
      "rotation": 1
    },
    {
      "x": -14,
      "y": 114,
      "z": 5,
      "name": "Plant_Leaves_Azure",
      "rotation": 1
    },
    {
      "x": -14,
      "y": 115,
      "z": 5,
      "name": "Plant_Leaves_Azure",
      "rotation": 1
    },
    {
      "x": -14,
      "y": 116,
      "z": 5,
      "name": "Plant_Leaves_Azure",
      "rotation": 1
    },
    {
      "x": -14,
      "y": 117,
      "z": 5,
      "name": "Plant_Leaves_Azure",
      "rotation": 1
    },
    {
      "x": -14,
      "y": 113,
      "z": 6,
      "name": "Plant_Leaves_Azure",
      "rotation": 1
    },
    {
      "x": -14,
      "y": 114,
      "z": 6,
      "name": "Plant_Leaves_Azure",
      "rotation": 1
    },
    {
      "x": -14,
      "y": 115,
      "z": 6,
      "name": "Plant_Leaves_Azure",
      "rotation": 1
    },
    {
      "x": -14,
      "y": 116,
      "z": 6,
      "name": "Plant_Leaves_Azure",
      "rotation": 1
    },
    {
      "x": -14,
      "y": 117,
      "z": 6,
      "name": "Plant_Leaves_Azure",
      "rotation": 1
    },
    {
      "x": -14,
      "y": 114,
      "z": 7,
      "name": "Plant_Leaves_Azure",
      "rotation": 1
    },
    {
      "x": -14,
      "y": 115,
      "z": 7,
      "name": "Plant_Leaves_Azure",
      "rotation": 1
    },
    {
      "x": -14,
      "y": 116,
      "z": 7,
      "name": "Plant_Leaves_Azure",
      "rotation": 1
    },
    {
      "x": -13,
      "y": 108,
      "z": -3,
      "name": "Plant_Leaves_Azure",
      "rotation": 1
    },
    {
      "x": -13,
      "y": 109,
      "z": -3,
      "name": "Plant_Leaves_Azure",
      "rotation": 1
    },
    {
      "x": -13,
      "y": 110,
      "z": -3,
      "name": "Plant_Leaves_Azure",
      "rotation": 1
    },
    {
      "x": -13,
      "y": 111,
      "z": -3,
      "name": "Plant_Leaves_Azure",
      "rotation": 1
    },
    {
      "x": -13,
      "y": 108,
      "z": -2,
      "name": "Plant_Leaves_Azure",
      "rotation": 1
    },
    {
      "x": -13,
      "y": 109,
      "z": -2,
      "name": "Plant_Leaves_Azure",
      "rotation": 1
    },
    {
      "x": -13,
      "y": 110,
      "z": -2,
      "name": "Plant_Leaves_Azure",
      "rotation": 1
    },
    {
      "x": -13,
      "y": 111,
      "z": -2,
      "name": "Plant_Leaves_Azure",
      "rotation": 1
    },
    {
      "x": -13,
      "y": 112,
      "z": -2,
      "name": "Plant_Leaves_Azure",
      "rotation": 1
    },
    {
      "x": -13,
      "y": 109,
      "z": -1,
      "name": "Plant_Leaves_Azure",
      "rotation": 1
    },
    {
      "x": -13,
      "y": 110,
      "z": -1,
      "name": "Plant_Leaves_Azure",
      "rotation": 1
    },
    {
      "x": -13,
      "y": 111,
      "z": -1,
      "name": "Plant_Leaves_Azure",
      "rotation": 1
    },
    {
      "x": -13,
      "y": 112,
      "z": -1,
      "name": "Plant_Leaves_Azure",
      "rotation": 1
    },
    {
      "x": -13,
      "y": 115,
      "z": -1,
      "name": "Plant_Leaves_Azure",
      "rotation": 1
    },
    {
      "x": -13,
      "y": 116,
      "z": -1,
      "name": "Plant_Leaves_Azure",
      "rotation": 1
    },
    {
      "x": -13,
      "y": 117,
      "z": -1,
      "name": "Plant_Leaves_Azure",
      "rotation": 1
    },
    {
      "x": -13,
      "y": 111,
      "z": 0,
      "name": "Plant_Leaves_Azure",
      "rotation": 1
    },
    {
      "x": -13,
      "y": 112,
      "z": 0,
      "name": "Plant_Leaves_Azure",
      "rotation": 1
    },
    {
      "x": -13,
      "y": 115,
      "z": 0,
      "name": "Plant_Leaves_Azure",
      "rotation": 1
    },
    {
      "x": -13,
      "y": 116,
      "z": 0,
      "name": "Plant_Leaves_Azure",
      "rotation": 1
    },
    {
      "x": -13,
      "y": 117,
      "z": 0,
      "name": "Plant_Leaves_Azure",
      "rotation": 1
    },
    {
      "x": -13,
      "y": 118,
      "z": 0,
      "name": "Plant_Leaves_Azure",
      "rotation": 1
    },
    {
      "x": -13,
      "y": 111,
      "z": 1,
      "name": "Wood_Azure_Branch_Long",
      "rotation": 5
    },
    {
      "x": -13,
      "y": 116,
      "z": 1,
      "name": "Plant_Leaves_Azure",
      "rotation": 1
    },
    {
      "x": -13,
      "y": 117,
      "z": 1,
      "name": "Plant_Leaves_Azure",
      "rotation": 1
    },
    {
      "x": -13,
      "y": 118,
      "z": 1,
      "name": "Plant_Leaves_Azure",
      "rotation": 1
    },
    {
      "x": -13,
      "y": 119,
      "z": 1,
      "name": "Plant_Fruit_Azure",
      "rotation": 1
    },
    {
      "x": -13,
      "y": 112,
      "z": 2,
      "name": "Wood_Azure_Branch_Long",
      "rotation": 5
    },
    {
      "x": -13,
      "y": 113,
      "z": 2,
      "name": "Wood_Azure_Branch_Long",
      "rotation": 5
    },
    {
      "x": -13,
      "y": 117,
      "z": 2,
      "name": "Plant_Leaves_Azure",
      "rotation": 1
    },
    {
      "x": -13,
      "y": 118,
      "z": 2,
      "name": "Plant_Leaves_Azure",
      "rotation": 1
    },
    {
      "x": -13,
      "y": 119,
      "z": 2,
      "name": "Plant_Leaves_Azure",
      "rotation": 1
    },
    {
      "x": -13,
      "y": 120,
      "z": 2,
      "name": "Plant_Leaves_Azure",
      "rotation": 1
    },
    {
      "x": -13,
      "y": 103,
      "z": 3,
      "name": "Wood_Azure_Trunk_Full",
      "rotation": 1
    },
    {
      "x": -13,
      "y": 104,
      "z": 3,
      "name": "Wood_Azure_Trunk_Full",
      "rotation": 1
    },
    {
      "x": -13,
      "y": 114,
      "z": 3,
      "name": "Wood_Azure_Branch_Long",
      "rotation": 5
    },
    {
      "x": -13,
      "y": 115,
      "z": 3,
      "name": "Plant_Leaves_Azure",
      "rotation": 1
    },
    {
      "x": -13,
      "y": 119,
      "z": 3,
      "name": "Plant_Leaves_Azure",
      "rotation": 1
    },
    {
      "x": -13,
      "y": 120,
      "z": 3,
      "name": "Plant_Leaves_Azure",
      "rotation": 1
    },
    {
      "x": -13,
      "y": 121,
      "z": 3,
      "name": "Plant_Leaves_Azure",
      "rotation": 1
    },
    {
      "x": -13,
      "y": 101,
      "z": 4,
      "name": "Wood_Azure_Roots",
      "rotation": 1
    },
    {
      "x": -13,
      "y": 102,
      "z": 4,
      "name": "Wood_Azure_Trunk_Full",
      "rotation": 1
    },
    {
      "x": -13,
      "y": 103,
      "z": 4,
      "name": "Wood_Azure_Trunk_Full",
      "rotation": 1
    },
    {
      "x": -13,
      "y": 112,
      "z": 4,
      "name": "Plant_Leaves_Azure",
      "rotation": 1
    },
    {
      "x": -13,
      "y": 113,
      "z": 4,
      "name": "Plant_Leaves_Azure",
      "rotation": 1
    },
    {
      "x": -13,
      "y": 114,
      "z": 4,
      "name": "Plant_Leaves_Azure",
      "rotation": 1
    },
    {
      "x": -13,
      "y": 115,
      "z": 4,
      "name": "Plant_Leaves_Azure",
      "rotation": 1
    },
    {
      "x": -13,
      "y": 116,
      "z": 4,
      "name": "Plant_Leaves_Azure",
      "rotation": 1
    },
    {
      "x": -13,
      "y": 112,
      "z": 5,
      "name": "Plant_Leaves_Azure",
      "rotation": 1
    },
    {
      "x": -13,
      "y": 113,
      "z": 5,
      "name": "Plant_Leaves_Azure",
      "rotation": 1
    },
    {
      "x": -13,
      "y": 114,
      "z": 5,
      "name": "Plant_Leaves_Azure",
      "rotation": 1
    },
    {
      "x": -13,
      "y": 115,
      "z": 5,
      "name": "Plant_Leaves_Azure",
      "rotation": 1
    },
    {
      "x": -13,
      "y": 116,
      "z": 5,
      "name": "Plant_Leaves_Azure",
      "rotation": 1
    },
    {
      "x": -13,
      "y": 117,
      "z": 5,
      "name": "Plant_Leaves_Azure",
      "rotation": 1
    },
    {
      "x": -13,
      "y": 118,
      "z": 5,
      "name": "Plant_Fruit_Azure",
      "rotation": 1
    },
    {
      "x": -13,
      "y": 113,
      "z": 6,
      "name": "Plant_Leaves_Azure",
      "rotation": 1
    },
    {
      "x": -13,
      "y": 114,
      "z": 6,
      "name": "Plant_Leaves_Azure",
      "rotation": 1
    },
    {
      "x": -13,
      "y": 115,
      "z": 6,
      "name": "Plant_Leaves_Azure",
      "rotation": 1
    },
    {
      "x": -13,
      "y": 116,
      "z": 6,
      "name": "Plant_Leaves_Azure",
      "rotation": 1
    },
    {
      "x": -13,
      "y": 117,
      "z": 6,
      "name": "Plant_Leaves_Azure",
      "rotation": 1
    },
    {
      "x": -13,
      "y": 118,
      "z": 6,
      "name": "Plant_Leaves_Azure",
      "rotation": 1
    },
    {
      "x": -13,
      "y": 114,
      "z": 7,
      "name": "Plant_Leaves_Azure",
      "rotation": 1
    },
    {
      "x": -13,
      "y": 115,
      "z": 7,
      "name": "Plant_Leaves_Azure",
      "rotation": 1
    },
    {
      "x": -13,
      "y": 116,
      "z": 7,
      "name": "Plant_Leaves_Azure",
      "rotation": 1
    },
    {
      "x": -13,
      "y": 117,
      "z": 7,
      "name": "Plant_Leaves_Azure",
      "rotation": 1
    },
    {
      "x": -12,
      "y": 107,
      "z": -4,
      "name": "Plant_Leaves_Azure",
      "rotation": 1
    },
    {
      "x": -12,
      "y": 108,
      "z": -4,
      "name": "Plant_Leaves_Azure",
      "rotation": 1
    },
    {
      "x": -12,
      "y": 109,
      "z": -4,
      "name": "Plant_Leaves_Azure",
      "rotation": 1
    },
    {
      "x": -12,
      "y": 108,
      "z": -3,
      "name": "Plant_Leaves_Azure",
      "rotation": 1
    },
    {
      "x": -12,
      "y": 109,
      "z": -3,
      "name": "Plant_Leaves_Azure",
      "rotation": 1
    },
    {
      "x": -12,
      "y": 110,
      "z": -3,
      "name": "Plant_Leaves_Azure",
      "rotation": 1
    },
    {
      "x": -12,
      "y": 111,
      "z": -3,
      "name": "Plant_Leaves_Azure",
      "rotation": 1
    },
    {
      "x": -12,
      "y": 108,
      "z": -2,
      "name": "Plant_Leaves_Azure",
      "rotation": 1
    },
    {
      "x": -12,
      "y": 109,
      "z": -2,
      "name": "Plant_Leaves_Azure",
      "rotation": 1
    },
    {
      "x": -12,
      "y": 110,
      "z": -2,
      "name": "Plant_Leaves_Azure",
      "rotation": 1
    },
    {
      "x": -12,
      "y": 111,
      "z": -2,
      "name": "Plant_Leaves_Azure",
      "rotation": 1
    },
    {
      "x": -12,
      "y": 112,
      "z": -2,
      "name": "Plant_Fruit_Azure",
      "rotation": 1
    },
    {
      "x": -12,
      "y": 114,
      "z": -2,
      "name": "Plant_Leaves_Azure",
      "rotation": 1
    },
    {
      "x": -12,
      "y": 115,
      "z": -2,
      "name": "Plant_Leaves_Azure",
      "rotation": 1
    },
    {
      "x": -12,
      "y": 116,
      "z": -2,
      "name": "Plant_Leaves_Azure",
      "rotation": 1
    },
    {
      "x": -12,
      "y": 109,
      "z": -1,
      "name": "Plant_Leaves_Azure",
      "rotation": 1
    },
    {
      "x": -12,
      "y": 110,
      "z": -1,
      "name": "Plant_Leaves_Azure",
      "rotation": 1
    },
    {
      "x": -12,
      "y": 114,
      "z": -1,
      "name": "Plant_Leaves_Azure",
      "rotation": 1
    },
    {
      "x": -12,
      "y": 115,
      "z": -1,
      "name": "Plant_Leaves_Azure",
      "rotation": 1
    },
    {
      "x": -12,
      "y": 116,
      "z": -1,
      "name": "Plant_Leaves_Azure",
      "rotation": 1
    },
    {
      "x": -12,
      "y": 117,
      "z": -1,
      "name": "Plant_Leaves_Azure",
      "rotation": 1
    },
    {
      "x": -12,
      "y": 118,
      "z": -1,
      "name": "Plant_Fruit_Azure",
      "rotation": 1
    },
    {
      "x": -12,
      "y": 115,
      "z": 0,
      "name": "Plant_Leaves_Azure",
      "rotation": 1
    },
    {
      "x": -12,
      "y": 116,
      "z": 0,
      "name": "Plant_Leaves_Azure",
      "rotation": 1
    },
    {
      "x": -12,
      "y": 117,
      "z": 0,
      "name": "Plant_Leaves_Azure",
      "rotation": 1
    },
    {
      "x": -12,
      "y": 118,
      "z": 0,
      "name": "Plant_Fruit_Azure",
      "rotation": 1
    },
    {
      "x": -12,
      "y": 111,
      "z": 1,
      "name": "Wood_Azure_Branch_Long",
      "rotation": 5
    },
    {
      "x": -12,
      "y": 112,
      "z": 1,
      "name": "Plant_Moss_Wall_Blue",
      "rotation": 3
    },
    {
      "x": -12,
      "y": 116,
      "z": 1,
      "name": "Plant_Leaves_Azure",
      "rotation": 1
    },
    {
      "x": -12,
      "y": 117,
      "z": 1,
      "name": "Plant_Leaves_Azure",
      "rotation": 1
    },
    {
      "x": -12,
      "y": 118,
      "z": 1,
      "name": "Plant_Leaves_Azure",
      "rotation": 1
    },
    {
      "x": -12,
      "y": 119,
      "z": 1,
      "name": "Plant_Leaves_Azure",
      "rotation": 1
    },
    {
      "x": -12,
      "y": 123,
      "z": 1,
      "name": "Plant_Leaves_Azure",
      "rotation": 1
    },
    {
      "x": -12,
      "y": 102,
      "z": 2,
      "name": "Wood_Azure_Trunk_Full",
      "rotation": 1
    },
    {
      "x": -12,
      "y": 103,
      "z": 2,
      "name": "Wood_Azure_Trunk_Full",
      "rotation": 1
    },
    {
      "x": -12,
      "y": 104,
      "z": 2,
      "name": "Wood_Azure_Trunk_Full",
      "rotation": 1
    },
    {
      "x": -12,
      "y": 105,
      "z": 2,
      "name": "Wood_Azure_Trunk",
      "rotation": 1
    },
    {
      "x": -12,
      "y": 106,
      "z": 2,
      "name": "Wood_Azure_Trunk_Full",
      "rotation": 1
    },
    {
      "x": -12,
      "y": 112,
      "z": 2,
      "name": "Wood_Azure_Trunk_Full",
      "rotation": 1
    },
    {
      "x": -12,
      "y": 113,
      "z": 2,
      "name": "Wood_Azure_Trunk",
      "rotation": 1
    },
    {
      "x": -12,
      "y": 114,
      "z": 2,
      "name": "Wood_Azure_Trunk_Full",
      "rotation": 1
    },
    {
      "x": -12,
      "y": 117,
      "z": 2,
      "name": "Wood_Azure_Branch_Long",
      "rotation": 5
    },
    {
      "x": -12,
      "y": 118,
      "z": 2,
      "name": "Plant_Leaves_Azure",
      "rotation": 1
    },
    {
      "x": -12,
      "y": 119,
      "z": 2,
      "name": "Plant_Leaves_Azure",
      "rotation": 1
    },
    {
      "x": -12,
      "y": 120,
      "z": 2,
      "name": "Plant_Leaves_Azure",
      "rotation": 1
    },
    {
      "x": -12,
      "y": 122,
      "z": 2,
      "name": "Plant_Leaves_Azure",
      "rotation": 1
    },
    {
      "x": -12,
      "y": 123,
      "z": 2,
      "name": "Plant_Leaves_Azure",
      "rotation": 1
    },
    {
      "x": -12,
      "y": 124,
      "z": 2,
      "name": "Plant_Leaves_Azure",
      "rotation": 1
    },
    {
      "x": -12,
      "y": 125,
      "z": 2,
      "name": "Plant_Leaves_Azure",
      "rotation": 1
    },
    {
      "x": -12,
      "y": 100,
      "z": 3,
      "name": "Wood_Azure_Roots",
      "rotation": 1
    },
    {
      "x": -12,
      "y": 101,
      "z": 3,
      "name": "Wood_Azure_Trunk_Full",
      "rotation": 1
    },
    {
      "x": -12,
      "y": 102,
      "z": 3,
      "name": "Wood_Azure_Roots",
      "rotation": 1
    },
    {
      "x": -12,
      "y": 103,
      "z": 3,
      "name": "Wood_Azure_Trunk_Full",
      "rotation": 1
    },
    {
      "x": -12,
      "y": 104,
      "z": 3,
      "name": "Wood_Azure_Trunk",
      "rotation": 1
    },
    {
      "x": -12,
      "y": 105,
      "z": 3,
      "name": "Wood_Azure_Trunk_Full",
      "rotation": 1
    },
    {
      "x": -12,
      "y": 107,
      "z": 3,
      "name": "Plant_Moss_Wall_Blue",
      "rotation": 3
    },
    {
      "x": -12,
      "y": 114,
      "z": 3,
      "name": "Wood_Azure_Trunk_Full",
      "rotation": 1
    },
    {
      "x": -12,
      "y": 115,
      "z": 3,
      "name": "Wood_Azure_Trunk",
      "rotation": 1
    },
    {
      "x": -12,
      "y": 116,
      "z": 3,
      "name": "Wood_Azure_Trunk_Full",
      "rotation": 1
    },
    {
      "x": -12,
      "y": 119,
      "z": 3,
      "name": "Wood_Azure_Branch_Long",
      "rotation": 5
    },
    {
      "x": -12,
      "y": 123,
      "z": 3,
      "name": "Plant_Leaves_Azure",
      "rotation": 1
    },
    {
      "x": -12,
      "y": 124,
      "z": 3,
      "name": "Plant_Leaves_Azure",
      "rotation": 1
    },
    {
      "x": -12,
      "y": 125,
      "z": 3,
      "name": "Plant_Leaves_Azure",
      "rotation": 1
    },
    {
      "x": -12,
      "y": 126,
      "z": 3,
      "name": "Plant_Leaves_Azure",
      "rotation": 1
    },
    {
      "x": -12,
      "y": 103,
      "z": 4,
      "name": "Wood_Azure_Trunk_Full",
      "rotation": 1
    },
    {
      "x": -12,
      "y": 104,
      "z": 4,
      "name": "Wood_Azure_Trunk_Full",
      "rotation": 1
    },
    {
      "x": -12,
      "y": 114,
      "z": 4,
      "name": "Plant_Leaves_Azure",
      "rotation": 1
    },
    {
      "x": -12,
      "y": 115,
      "z": 4,
      "name": "Wood_Azure_Branch_Long",
      "rotation": 6
    },
    {
      "x": -12,
      "y": 116,
      "z": 4,
      "name": "Plant_Leaves_Azure",
      "rotation": 1
    },
    {
      "x": -12,
      "y": 117,
      "z": 4,
      "name": "Plant_Fruit_Azure",
      "rotation": 1
    },
    {
      "x": -12,
      "y": 113,
      "z": 5,
      "name": "Plant_Leaves_Azure",
      "rotation": 1
    },
    {
      "x": -12,
      "y": 114,
      "z": 5,
      "name": "Plant_Leaves_Azure",
      "rotation": 1
    },
    {
      "x": -12,
      "y": 115,
      "z": 5,
      "name": "Wood_Azure_Branch_Long",
      "rotation": 6
    },
    {
      "x": -12,
      "y": 116,
      "z": 5,
      "name": "Plant_Leaves_Azure",
      "rotation": 1
    },
    {
      "x": -12,
      "y": 117,
      "z": 5,
      "name": "Plant_Leaves_Azure",
      "rotation": 1
    },
    {
      "x": -12,
      "y": 118,
      "z": 5,
      "name": "Plant_Leaves_Azure",
      "rotation": 1
    },
    {
      "x": -12,
      "y": 113,
      "z": 6,
      "name": "Plant_Leaves_Azure",
      "rotation": 1
    },
    {
      "x": -12,
      "y": 114,
      "z": 6,
      "name": "Plant_Leaves_Azure",
      "rotation": 1
    },
    {
      "x": -12,
      "y": 115,
      "z": 6,
      "name": "Wood_Azure_Branch_Long",
      "rotation": 6
    },
    {
      "x": -12,
      "y": 116,
      "z": 6,
      "name": "Plant_Leaves_Azure",
      "rotation": 1
    },
    {
      "x": -12,
      "y": 117,
      "z": 6,
      "name": "Plant_Leaves_Azure",
      "rotation": 1
    },
    {
      "x": -12,
      "y": 118,
      "z": 6,
      "name": "Plant_Leaves_Azure",
      "rotation": 1
    },
    {
      "x": -12,
      "y": 119,
      "z": 6,
      "name": "Plant_Leaves_Azure",
      "rotation": 1
    },
    {
      "x": -12,
      "y": 115,
      "z": 7,
      "name": "Plant_Leaves_Azure",
      "rotation": 1
    },
    {
      "x": -12,
      "y": 116,
      "z": 7,
      "name": "Plant_Leaves_Azure",
      "rotation": 1
    },
    {
      "x": -12,
      "y": 117,
      "z": 7,
      "name": "Plant_Leaves_Azure",
      "rotation": 1
    },
    {
      "x": -12,
      "y": 118,
      "z": 7,
      "name": "Plant_Leaves_Azure",
      "rotation": 1
    },
    {
      "x": -11,
      "y": 107,
      "z": -4,
      "name": "Plant_Leaves_Azure",
      "rotation": 1
    },
    {
      "x": -11,
      "y": 108,
      "z": -4,
      "name": "Plant_Leaves_Azure",
      "rotation": 1
    },
    {
      "x": -11,
      "y": 109,
      "z": -4,
      "name": "Plant_Leaves_Azure",
      "rotation": 1
    },
    {
      "x": -11,
      "y": 110,
      "z": -4,
      "name": "Plant_Leaves_Azure",
      "rotation": 1
    },
    {
      "x": -11,
      "y": 107,
      "z": -3,
      "name": "Plant_Leaves_Azure",
      "rotation": 1
    },
    {
      "x": -11,
      "y": 108,
      "z": -3,
      "name": "Plant_Leaves_Azure",
      "rotation": 1
    },
    {
      "x": -11,
      "y": 109,
      "z": -3,
      "name": "Plant_Leaves_Azure",
      "rotation": 1
    },
    {
      "x": -11,
      "y": 110,
      "z": -3,
      "name": "Plant_Leaves_Azure",
      "rotation": 1
    },
    {
      "x": -11,
      "y": 111,
      "z": -3,
      "name": "Plant_Fruit_Azure",
      "rotation": 1
    },
    {
      "x": -11,
      "y": 113,
      "z": -3,
      "name": "Plant_Leaves_Azure",
      "rotation": 1
    },
    {
      "x": -11,
      "y": 114,
      "z": -3,
      "name": "Plant_Leaves_Azure",
      "rotation": 1
    },
    {
      "x": -11,
      "y": 115,
      "z": -3,
      "name": "Plant_Leaves_Azure",
      "rotation": 1
    },
    {
      "x": -11,
      "y": 108,
      "z": -2,
      "name": "Plant_Leaves_Azure",
      "rotation": 1
    },
    {
      "x": -11,
      "y": 109,
      "z": -2,
      "name": "Plant_Leaves_Azure",
      "rotation": 1
    },
    {
      "x": -11,
      "y": 110,
      "z": -2,
      "name": "Wood_Azure_Branch_Long",
      "rotation": 6
    },
    {
      "x": -11,
      "y": 111,
      "z": -2,
      "name": "Plant_Leaves_Azure",
      "rotation": 1
    },
    {
      "x": -11,
      "y": 113,
      "z": -2,
      "name": "Plant_Leaves_Azure",
      "rotation": 1
    },
    {
      "x": -11,
      "y": 114,
      "z": -2,
      "name": "Plant_Leaves_Azure",
      "rotation": 1
    },
    {
      "x": -11,
      "y": 115,
      "z": -2,
      "name": "Plant_Leaves_Azure",
      "rotation": 1
    },
    {
      "x": -11,
      "y": 116,
      "z": -2,
      "name": "Plant_Leaves_Azure",
      "rotation": 1
    },
    {
      "x": -11,
      "y": 117,
      "z": -2,
      "name": "Plant_Fruit_Azure",
      "rotation": 1
    },
    {
      "x": -11,
      "y": 108,
      "z": -1,
      "name": "Plant_Leaves_Azure",
      "rotation": 1
    },
    {
      "x": -11,
      "y": 109,
      "z": -1,
      "name": "Plant_Leaves_Azure",
      "rotation": 1
    },
    {
      "x": -11,
      "y": 110,
      "z": -1,
      "name": "Wood_Azure_Branch_Long",
      "rotation": 6
    },
    {
      "x": -11,
      "y": 114,
      "z": -1,
      "name": "Plant_Leaves_Azure",
      "rotation": 1
    },
    {
      "x": -11,
      "y": 115,
      "z": -1,
      "name": "Plant_Leaves_Azure",
      "rotation": 1
    },
    {
      "x": -11,
      "y": 116,
      "z": -1,
      "name": "Plant_Leaves_Azure",
      "rotation": 1
    },
    {
      "x": -11,
      "y": 117,
      "z": -1,
      "name": "Plant_Leaves_Azure",
      "rotation": 1
    },
    {
      "x": -11,
      "y": 110,
      "z": 0,
      "name": "Wood_Azure_Branch_Long",
      "rotation": 6
    },
    {
      "x": -11,
      "y": 111,
      "z": 0,
      "name": "Plant_Moss_Wall_Blue",
      "rotation": 3
    },
    {
      "x": -11,
      "y": 112,
      "z": 0,
      "name": "Plant_Moss_Wall_Blue",
      "rotation": 2
    },
    {
      "x": -11,
      "y": 115,
      "z": 0,
      "name": "Plant_Leaves_Azure",
      "rotation": 1
    },
    {
      "x": -11,
      "y": 116,
      "z": 0,
      "name": "Plant_Leaves_Azure",
      "rotation": 1
    },
    {
      "x": -11,
      "y": 122,
      "z": 0,
      "name": "Plant_Leaves_Azure",
      "rotation": 1
    },
    {
      "x": -11,
      "y": 103,
      "z": 1,
      "name": "Wood_Azure_Trunk_Full",
      "rotation": 1
    },
    {
      "x": -11,
      "y": 104,
      "z": 1,
      "name": "Wood_Azure_Trunk",
      "rotation": 1
    },
    {
      "x": -11,
      "y": 105,
      "z": 1,
      "name": "Wood_Azure_Trunk_Full",
      "rotation": 1
    },
    {
      "x": -11,
      "y": 109,
      "z": 1,
      "name": "Wood_Azure_Trunk_Full",
      "rotation": 1
    },
    {
      "x": -11,
      "y": 110,
      "z": 1,
      "name": "Wood_Azure_Trunk",
      "rotation": 1
    },
    {
      "x": -11,
      "y": 111,
      "z": 1,
      "name": "Wood_Azure_Trunk",
      "rotation": 1
    },
    {
      "x": -11,
      "y": 112,
      "z": 1,
      "name": "Wood_Azure_Trunk_Full",
      "rotation": 1
    },
    {
      "x": -11,
      "y": 113,
      "z": 1,
      "name": "Plant_Moss_Rug_Blue",
      "rotation": 1
    },
    {
      "x": -11,
      "y": 116,
      "z": 1,
      "name": "Wood_Azure_Branch_Long",
      "rotation": 5
    },
    {
      "x": -11,
      "y": 121,
      "z": 1,
      "name": "Plant_Leaves_Azure",
      "rotation": 1
    },
    {
      "x": -11,
      "y": 122,
      "z": 1,
      "name": "Plant_Leaves_Azure",
      "rotation": 1
    },
    {
      "x": -11,
      "y": 123,
      "z": 1,
      "name": "Plant_Leaves_Azure",
      "rotation": 1
    },
    {
      "x": -11,
      "y": 124,
      "z": 1,
      "name": "Plant_Leaves_Azure",
      "rotation": 1
    },
    {
      "x": -11,
      "y": 101,
      "z": 2,
      "name": "Wood_Azure_Roots",
      "rotation": 1
    },
    {
      "x": -11,
      "y": 102,
      "z": 2,
      "name": "Wood_Azure_Trunk_Full",
      "rotation": 1
    },
    {
      "x": -11,
      "y": 103,
      "z": 2,
      "name": "Wood_Azure_Trunk",
      "rotation": 1
    },
    {
      "x": -11,
      "y": 104,
      "z": 2,
      "name": "Wood_Azure_Trunk_Full",
      "rotation": 1
    },
    {
      "x": -11,
      "y": 105,
      "z": 2,
      "name": "Wood_Azure_Trunk",
      "rotation": 1
    },
    {
      "x": -11,
      "y": 106,
      "z": 2,
      "name": "Wood_Azure_Trunk",
      "rotation": 1
    },
    {
      "x": -11,
      "y": 107,
      "z": 2,
      "name": "Wood_Azure_Trunk",
      "rotation": 1
    },
    {
      "x": -11,
      "y": 108,
      "z": 2,
      "name": "Wood_Azure_Trunk",
      "rotation": 1
    },
    {
      "x": -11,
      "y": 109,
      "z": 2,
      "name": "Wood_Azure_Trunk",
      "rotation": 1
    },
    {
      "x": -11,
      "y": 110,
      "z": 2,
      "name": "Wood_Azure_Trunk",
      "rotation": 1
    },
    {
      "x": -11,
      "y": 111,
      "z": 2,
      "name": "Wood_Azure_Trunk",
      "rotation": 1
    },
    {
      "x": -11,
      "y": 112,
      "z": 2,
      "name": "Wood_Azure_Trunk",
      "rotation": 1
    },
    {
      "x": -11,
      "y": 113,
      "z": 2,
      "name": "Wood_Azure_Trunk",
      "rotation": 1
    },
    {
      "x": -11,
      "y": 114,
      "z": 2,
      "name": "Wood_Azure_Trunk",
      "rotation": 1
    },
    {
      "x": -11,
      "y": 115,
      "z": 2,
      "name": "Wood_Azure_Trunk",
      "rotation": 1
    },
    {
      "x": -11,
      "y": 116,
      "z": 2,
      "name": "Wood_Azure_Trunk",
      "rotation": 1
    },
    {
      "x": -11,
      "y": 117,
      "z": 2,
      "name": "Wood_Azure_Trunk_Full",
      "rotation": 1
    },
    {
      "x": -11,
      "y": 118,
      "z": 2,
      "name": "Wood_Azure_Branch_Long",
      "rotation": 5
    },
    {
      "x": -11,
      "y": 120,
      "z": 2,
      "name": "Plant_Moss_Wall_Blue",
      "rotation": 2
    },
    {
      "x": -11,
      "y": 122,
      "z": 2,
      "name": "Plant_Leaves_Azure",
      "rotation": 1
    },
    {
      "x": -11,
      "y": 123,
      "z": 2,
      "name": "Plant_Leaves_Azure",
      "rotation": 1
    },
    {
      "x": -11,
      "y": 124,
      "z": 2,
      "name": "Plant_Leaves_Azure",
      "rotation": 1
    },
    {
      "x": -11,
      "y": 125,
      "z": 2,
      "name": "Plant_Fruit_Azure",
      "rotation": 1
    },
    {
      "x": -11,
      "y": 102,
      "z": 3,
      "name": "Wood_Azure_Trunk_Full",
      "rotation": 1
    },
    {
      "x": -11,
      "y": 103,
      "z": 3,
      "name": "Wood_Azure_Trunk_Full",
      "rotation": 1
    },
    {
      "x": -11,
      "y": 104,
      "z": 3,
      "name": "Wood_Azure_Trunk_Full",
      "rotation": 1
    },
    {
      "x": -11,
      "y": 105,
      "z": 3,
      "name": "Wood_Azure_Trunk",
      "rotation": 1
    },
    {
      "x": -11,
      "y": 106,
      "z": 3,
      "name": "Wood_Azure_Trunk",
      "rotation": 1
    },
    {
      "x": -11,
      "y": 107,
      "z": 3,
      "name": "Wood_Azure_Trunk_Full",
      "rotation": 1
    },
    {
      "x": -11,
      "y": 108,
      "z": 3,
      "name": "Plant_Moss_Rug_Blue",
      "rotation": 1
    },
    {
      "x": -11,
      "y": 111,
      "z": 3,
      "name": "Wood_Azure_Trunk_Full",
      "rotation": 1
    },
    {
      "x": -11,
      "y": 112,
      "z": 3,
      "name": "Wood_Azure_Trunk",
      "rotation": 1
    },
    {
      "x": -11,
      "y": 113,
      "z": 3,
      "name": "Wood_Azure_Trunk",
      "rotation": 1
    },
    {
      "x": -11,
      "y": 114,
      "z": 3,
      "name": "Wood_Azure_Trunk",
      "rotation": 1
    },
    {
      "x": -11,
      "y": 115,
      "z": 3,
      "name": "Wood_Azure_Trunk",
      "rotation": 1
    },
    {
      "x": -11,
      "y": 116,
      "z": 3,
      "name": "Wood_Azure_Trunk",
      "rotation": 1
    },
    {
      "x": -11,
      "y": 117,
      "z": 3,
      "name": "Wood_Azure_Trunk",
      "rotation": 1
    },
    {
      "x": -11,
      "y": 118,
      "z": 3,
      "name": "Wood_Azure_Trunk",
      "rotation": 1
    },
    {
      "x": -11,
      "y": 119,
      "z": 3,
      "name": "Wood_Azure_Trunk",
      "rotation": 1
    },
    {
      "x": -11,
      "y": 120,
      "z": 3,
      "name": "Wood_Azure_Trunk_Full",
      "rotation": 1
    },
    {
      "x": -11,
      "y": 121,
      "z": 3,
      "name": "Wood_Azure_Branch_Long",
      "rotation": 1
    },
    {
      "x": -11,
      "y": 122,
      "z": 3,
      "name": "Wood_Azure_Branch_Long",
      "rotation": 1
    },
    {
      "x": -11,
      "y": 123,
      "z": 3,
      "name": "Wood_Azure_Branch_Long",
      "rotation": 1
    },
    {
      "x": -11,
      "y": 124,
      "z": 3,
      "name": "Plant_Leaves_Azure",
      "rotation": 1
    },
    {
      "x": -11,
      "y": 125,
      "z": 3,
      "name": "Plant_Leaves_Azure",
      "rotation": 1
    },
    {
      "x": -11,
      "y": 97,
      "z": 4,
      "name": "Plant_Moss_Wall_Blue",
      "support": 15,
      "rotation": 3
    },
    {
      "x": -11,
      "y": 98,
      "z": 4,
      "name": "Plant_Moss_Wall_Blue",
      "support": 15,
      "rotation": 3
    },
    {
      "x": -11,
      "y": 104,
      "z": 4,
      "name": "Wood_Azure_Trunk_Full",
      "rotation": 1
    },
    {
      "x": -11,
      "y": 107,
      "z": 4,
      "name": "Plant_Moss_Wall_Blue"
    },
    {
      "x": -11,
      "y": 114,
      "z": 4,
      "name": "Wood_Azure_Branch_Long",
      "rotation": 6
    },
    {
      "x": -11,
      "y": 116,
      "z": 4,
      "name": "Plant_Leaves_Azure",
      "rotation": 1
    },
    {
      "x": -11,
      "y": 117,
      "z": 4,
      "name": "Plant_Leaves_Azure",
      "rotation": 1
    },
    {
      "x": -11,
      "y": 118,
      "z": 4,
      "name": "Wood_Azure_Branch_Long",
      "rotation": 6
    },
    {
      "x": -11,
      "y": 123,
      "z": 4,
      "name": "Plant_Leaves_Azure",
      "rotation": 1
    },
    {
      "x": -11,
      "y": 97,
      "z": 5,
      "name": "Plant_Moss_Wall_Blue",
      "support": 15,
      "rotation": 3
    },
    {
      "x": -11,
      "y": 98,
      "z": 5,
      "name": "Plant_Moss_Wall_Blue",
      "support": 15,
      "rotation": 3
    },
    {
      "x": -11,
      "y": 99,
      "z": 5,
      "name": "Plant_Moss_Wall_Blue",
      "support": 15,
      "rotation": 3
    },
    {
      "x": -11,
      "y": 111,
      "z": 5,
      "name": "Plant_Moss_Wall_Blue",
      "rotation": 3
    },
    {
      "x": -11,
      "y": 113,
      "z": 5,
      "name": "Plant_Leaves_Azure",
      "rotation": 1
    },
    {
      "x": -11,
      "y": 114,
      "z": 5,
      "name": "Wood_Azure_Branch_Long",
      "rotation": 6
    },
    {
      "x": -11,
      "y": 115,
      "z": 5,
      "name": "Plant_Leaves_Azure",
      "rotation": 1
    },
    {
      "x": -11,
      "y": 116,
      "z": 5,
      "name": "Plant_Leaves_Azure",
      "rotation": 1
    },
    {
      "x": -11,
      "y": 117,
      "z": 5,
      "name": "Plant_Leaves_Azure",
      "rotation": 1
    },
    {
      "x": -11,
      "y": 118,
      "z": 5,
      "name": "Wood_Azure_Branch_Long",
      "rotation": 6
    },
    {
      "x": -11,
      "y": 119,
      "z": 5,
      "name": "Plant_Leaves_Azure",
      "rotation": 1
    },
    {
      "x": -11,
      "y": 120,
      "z": 5,
      "name": "Plant_Fruit_Azure",
      "rotation": 1
    },
    {
      "x": -11,
      "y": 97,
      "z": 6,
      "name": "Plant_Moss_Wall_Blue",
      "support": 15,
      "rotation": 3
    },
    {
      "x": -11,
      "y": 98,
      "z": 6,
      "name": "Plant_Moss_Wall_Blue",
      "support": 15,
      "rotation": 3
    },
    {
      "x": -11,
      "y": 114,
      "z": 6,
      "name": "Plant_Leaves_Azure",
      "rotation": 1
    },
    {
      "x": -11,
      "y": 115,
      "z": 6,
      "name": "Plant_Leaves_Azure",
      "rotation": 1
    },
    {
      "x": -11,
      "y": 116,
      "z": 6,
      "name": "Plant_Leaves_Azure",
      "rotation": 1
    },
    {
      "x": -11,
      "y": 117,
      "z": 6,
      "name": "Plant_Leaves_Azure",
      "rotation": 1
    },
    {
      "x": -11,
      "y": 118,
      "z": 6,
      "name": "Plant_Leaves_Azure",
      "rotation": 1
    },
    {
      "x": -11,
      "y": 119,
      "z": 6,
      "name": "Plant_Leaves_Azure",
      "rotation": 1
    },
    {
      "x": -11,
      "y": 120,
      "z": 6,
      "name": "Plant_Leaves_Azure",
      "rotation": 1
    },
    {
      "x": -11,
      "y": 111,
      "z": 7,
      "name": "Plant_Leaves_Azure",
      "rotation": 1
    },
    {
      "x": -11,
      "y": 112,
      "z": 7,
      "name": "Plant_Leaves_Azure",
      "rotation": 1
    },
    {
      "x": -11,
      "y": 116,
      "z": 7,
      "name": "Plant_Leaves_Azure",
      "rotation": 1
    },
    {
      "x": -11,
      "y": 117,
      "z": 7,
      "name": "Plant_Leaves_Azure",
      "rotation": 1
    },
    {
      "x": -11,
      "y": 118,
      "z": 7,
      "name": "Plant_Leaves_Azure",
      "rotation": 1
    },
    {
      "x": -11,
      "y": 119,
      "z": 7,
      "name": "Plant_Leaves_Azure",
      "rotation": 1
    },
    {
      "x": -11,
      "y": 111,
      "z": 8,
      "name": "Plant_Leaves_Azure",
      "rotation": 1
    },
    {
      "x": -11,
      "y": 112,
      "z": 8,
      "name": "Plant_Leaves_Azure",
      "rotation": 1
    },
    {
      "x": -10,
      "y": 107,
      "z": -4,
      "name": "Plant_Leaves_Azure",
      "rotation": 1
    },
    {
      "x": -10,
      "y": 108,
      "z": -4,
      "name": "Plant_Leaves_Azure",
      "rotation": 1
    },
    {
      "x": -10,
      "y": 109,
      "z": -4,
      "name": "Plant_Leaves_Azure",
      "rotation": 1
    },
    {
      "x": -10,
      "y": 107,
      "z": -3,
      "name": "Plant_Leaves_Azure",
      "rotation": 1
    },
    {
      "x": -10,
      "y": 108,
      "z": -3,
      "name": "Plant_Leaves_Azure",
      "rotation": 1
    },
    {
      "x": -10,
      "y": 109,
      "z": -3,
      "name": "Plant_Leaves_Azure",
      "rotation": 1
    },
    {
      "x": -10,
      "y": 110,
      "z": -3,
      "name": "Plant_Leaves_Azure",
      "rotation": 1
    },
    {
      "x": -10,
      "y": 112,
      "z": -3,
      "name": "Plant_Leaves_Azure",
      "rotation": 1
    },
    {
      "x": -10,
      "y": 113,
      "z": -3,
      "name": "Plant_Leaves_Azure",
      "rotation": 1
    },
    {
      "x": -10,
      "y": 114,
      "z": -3,
      "name": "Plant_Leaves_Azure",
      "rotation": 1
    },
    {
      "x": -10,
      "y": 115,
      "z": -3,
      "name": "Plant_Leaves_Azure",
      "rotation": 1
    },
    {
      "x": -10,
      "y": 107,
      "z": -2,
      "name": "Plant_Leaves_Azure",
      "rotation": 1
    },
    {
      "x": -10,
      "y": 108,
      "z": -2,
      "name": "Plant_Leaves_Azure",
      "rotation": 1
    },
    {
      "x": -10,
      "y": 109,
      "z": -2,
      "name": "Plant_Leaves_Azure",
      "rotation": 1
    },
    {
      "x": -10,
      "y": 110,
      "z": -2,
      "name": "Plant_Leaves_Azure",
      "rotation": 1
    },
    {
      "x": -10,
      "y": 112,
      "z": -2,
      "name": "Plant_Leaves_Azure",
      "rotation": 1
    },
    {
      "x": -10,
      "y": 113,
      "z": -2,
      "name": "Plant_Leaves_Azure",
      "rotation": 1
    },
    {
      "x": -10,
      "y": 114,
      "z": -2,
      "name": "Plant_Leaves_Azure",
      "rotation": 1
    },
    {
      "x": -10,
      "y": 115,
      "z": -2,
      "name": "Plant_Leaves_Azure",
      "rotation": 1
    },
    {
      "x": -10,
      "y": 116,
      "z": -2,
      "name": "Plant_Leaves_Azure",
      "rotation": 1
    },
    {
      "x": -10,
      "y": 104,
      "z": -1,
      "name": "Plant_Moss_Wall_Blue",
      "support": 15,
      "rotation": 3
    },
    {
      "x": -10,
      "y": 109,
      "z": -1,
      "name": "Plant_Leaves_Azure",
      "rotation": 1
    },
    {
      "x": -10,
      "y": 111,
      "z": -1,
      "name": "Plant_Moss_Wall_Blue",
      "rotation": 2
    },
    {
      "x": -10,
      "y": 114,
      "z": -1,
      "name": "Plant_Leaves_Azure",
      "rotation": 1
    },
    {
      "x": -10,
      "y": 115,
      "z": -1,
      "name": "Plant_Leaves_Azure",
      "rotation": 1
    },
    {
      "x": -10,
      "y": 116,
      "z": -1,
      "name": "Plant_Leaves_Azure",
      "rotation": 1
    },
    {
      "x": -10,
      "y": 117,
      "z": -1,
      "name": "Plant_Fruit_Azure",
      "rotation": 1
    },
    {
      "x": -10,
      "y": 108,
      "z": 0,
      "name": "Wood_Azure_Trunk_Full",
      "rotation": 1
    },
    {
      "x": -10,
      "y": 109,
      "z": 0,
      "name": "Wood_Azure_Trunk",
      "rotation": 1
    },
    {
      "x": -10,
      "y": 110,
      "z": 0,
      "name": "Wood_Azure_Trunk",
      "rotation": 1
    },
    {
      "x": -10,
      "y": 111,
      "z": 0,
      "name": "Wood_Azure_Trunk_Full",
      "rotation": 1
    },
    {
      "x": -10,
      "y": 112,
      "z": 0,
      "name": "Plant_Moss_Rug_Blue",
      "rotation": 1
    },
    {
      "x": -10,
      "y": 114,
      "z": 0,
      "name": "Plant_Leaves_Azure",
      "rotation": 1
    },
    {
      "x": -10,
      "y": 115,
      "z": 0,
      "name": "Plant_Leaves_Azure",
      "rotation": 1
    },
    {
      "x": -10,
      "y": 120,
      "z": 0,
      "name": "Plant_Leaves_Azure",
      "rotation": 1
    },
    {
      "x": -10,
      "y": 121,
      "z": 0,
      "name": "Plant_Leaves_Azure",
      "rotation": 1
    },
    {
      "x": -10,
      "y": 122,
      "z": 0,
      "name": "Plant_Leaves_Azure",
      "rotation": 1
    },
    {
      "x": -10,
      "y": 103,
      "z": 1,
      "name": "Wood_Azure_Trunk_Full",
      "rotation": 1
    },
    {
      "x": -10,
      "y": 104,
      "z": 1,
      "name": "Wood_Azure_Trunk",
      "rotation": 1
    },
    {
      "x": -10,
      "y": 105,
      "z": 1,
      "name": "Wood_Azure_Trunk",
      "rotation": 1
    },
    {
      "x": -10,
      "y": 106,
      "z": 1,
      "name": "Wood_Azure_Trunk",
      "rotation": 1
    },
    {
      "x": -10,
      "y": 107,
      "z": 1,
      "name": "Wood_Azure_Trunk_Full",
      "rotation": 1
    },
    {
      "x": -10,
      "y": 108,
      "z": 1,
      "name": "Wood_Azure_Trunk",
      "rotation": 1
    },
    {
      "x": -10,
      "y": 109,
      "z": 1,
      "name": "Wood_Azure_Trunk",
      "rotation": 1
    },
    {
      "x": -10,
      "y": 110,
      "z": 1,
      "name": "Wood_Azure_Trunk_Full",
      "rotation": 1
    },
    {
      "x": -10,
      "y": 111,
      "z": 1,
      "name": "Wood_Azure_Trunk",
      "rotation": 1
    },
    {
      "x": -10,
      "y": 112,
      "z": 1,
      "name": "Plant_Moss_Wall_Blue",
      "rotation": 1
    },
    {
      "x": -10,
      "y": 113,
      "z": 1,
      "name": "Wood_Azure_Trunk",
      "rotation": 1
    },
    {
      "x": -10,
      "y": 114,
      "z": 1,
      "name": "Wood_Azure_Branch_Long",
      "rotation": 6
    },
    {
      "x": -10,
      "y": 115,
      "z": 1,
      "name": "Plant_Moss_Wall_Blue",
      "rotation": 2
    },
    {
      "x": -10,
      "y": 116,
      "z": 1,
      "name": "Wood_Azure_Trunk_Full",
      "rotation": 1
    },
    {
      "x": -10,
      "y": 118,
      "z": 1,
      "name": "Plant_Leaves_Azure",
      "rotation": 1
    },
    {
      "x": -10,
      "y": 119,
      "z": 1,
      "name": "Plant_Moss_Wall_Blue",
      "rotation": 2
    },
    {
      "x": -10,
      "y": 121,
      "z": 1,
      "name": "Plant_Leaves_Azure",
      "rotation": 1
    },
    {
      "x": -10,
      "y": 122,
      "z": 1,
      "name": "Plant_Leaves_Azure",
      "rotation": 1
    },
    {
      "x": -10,
      "y": 123,
      "z": 1,
      "name": "Plant_Leaves_Azure",
      "rotation": 1
    },
    {
      "x": -10,
      "y": 124,
      "z": 1,
      "name": "Plant_Fruit_Azure",
      "rotation": 1
    },
    {
      "x": -10,
      "y": 97,
      "z": 2,
      "name": "Plant_Moss_Wall_Blue",
      "support": 15,
      "rotation": 3
    },
    {
      "x": -10,
      "y": 103,
      "z": 2,
      "name": "Wood_Azure_Trunk_Full",
      "rotation": 1
    },
    {
      "x": -10,
      "y": 104,
      "z": 2,
      "name": "Wood_Azure_Trunk",
      "rotation": 1
    },
    {
      "x": -10,
      "y": 105,
      "z": 2,
      "name": "Wood_Azure_Trunk",
      "rotation": 1
    },
    {
      "x": -10,
      "y": 106,
      "z": 2,
      "name": "Wood_Azure_Trunk",
      "rotation": 1
    },
    {
      "x": -10,
      "y": 107,
      "z": 2,
      "name": "Wood_Azure_Trunk",
      "rotation": 1
    },
    {
      "x": -10,
      "y": 108,
      "z": 2,
      "name": "Wood_Azure_Trunk",
      "rotation": 1
    },
    {
      "x": -10,
      "y": 109,
      "z": 2,
      "name": "Wood_Azure_Trunk",
      "rotation": 1
    },
    {
      "x": -10,
      "y": 110,
      "z": 2,
      "name": "Wood_Azure_Trunk",
      "rotation": 1
    },
    {
      "x": -10,
      "y": 111,
      "z": 2,
      "name": "Wood_Azure_Trunk",
      "rotation": 1
    },
    {
      "x": -10,
      "y": 112,
      "z": 2,
      "name": "Wood_Azure_Trunk",
      "rotation": 1
    },
    {
      "x": -10,
      "y": 113,
      "z": 2,
      "name": "Wood_Azure_Trunk",
      "rotation": 1
    },
    {
      "x": -10,
      "y": 114,
      "z": 2,
      "name": "Wood_Azure_Trunk",
      "rotation": 1
    },
    {
      "x": -10,
      "y": 115,
      "z": 2,
      "name": "Wood_Azure_Trunk_Full",
      "rotation": 1
    },
    {
      "x": -10,
      "y": 116,
      "z": 2,
      "name": "Plant_Moss_Rug_Blue",
      "rotation": 1
    },
    {
      "x": -10,
      "y": 117,
      "z": 2,
      "name": "Wood_Azure_Branch_Long",
      "rotation": 5
    },
    {
      "x": -10,
      "y": 118,
      "z": 2,
      "name": "Wood_Azure_Trunk",
      "rotation": 1
    },
    {
      "x": -10,
      "y": 119,
      "z": 2,
      "name": "Wood_Azure_Trunk_Full",
      "rotation": 1
    },
    {
      "x": -10,
      "y": 120,
      "z": 2,
      "name": "Plant_Leaves_Azure",
      "rotation": 1
    },
    {
      "x": -10,
      "y": 121,
      "z": 2,
      "name": "Plant_Leaves_Azure",
      "rotation": 1
    },
    {
      "x": -10,
      "y": 122,
      "z": 2,
      "name": "Plant_Leaves_Azure",
      "rotation": 1
    },
    {
      "x": -10,
      "y": 123,
      "z": 2,
      "name": "Plant_Leaves_Azure",
      "rotation": 1
    },
    {
      "x": -10,
      "y": 124,
      "z": 2,
      "name": "Plant_Leaves_Azure",
      "rotation": 1
    },
    {
      "x": -10,
      "y": 97,
      "z": 3,
      "name": "Plant_Moss_Wall_Blue",
      "support": 15,
      "rotation": 3
    },
    {
      "x": -10,
      "y": 103,
      "z": 3,
      "name": "Wood_Azure_Trunk_Full",
      "rotation": 1
    },
    {
      "x": -10,
      "y": 105,
      "z": 3,
      "name": "Wood_Azure_Trunk_Full",
      "rotation": 1
    },
    {
      "x": -10,
      "y": 106,
      "z": 3,
      "name": "Wood_Azure_Trunk",
      "rotation": 1
    },
    {
      "x": -10,
      "y": 107,
      "z": 3,
      "name": "Wood_Azure_Trunk",
      "rotation": 1
    },
    {
      "x": -10,
      "y": 108,
      "z": 3,
      "name": "Wood_Azure_Trunk",
      "rotation": 1
    },
    {
      "x": -10,
      "y": 109,
      "z": 3,
      "name": "Wood_Azure_Trunk",
      "rotation": 1
    },
    {
      "x": -10,
      "y": 110,
      "z": 3,
      "name": "Wood_Azure_Trunk",
      "rotation": 1
    },
    {
      "x": -10,
      "y": 111,
      "z": 3,
      "name": "Wood_Azure_Trunk",
      "rotation": 1
    },
    {
      "x": -10,
      "y": 112,
      "z": 3,
      "name": "Wood_Azure_Trunk",
      "rotation": 1
    },
    {
      "x": -10,
      "y": 113,
      "z": 3,
      "name": "Wood_Azure_Trunk_Full",
      "rotation": 1
    },
    {
      "x": -10,
      "y": 115,
      "z": 3,
      "name": "Plant_Moss_Wall_Blue"
    },
    {
      "x": -10,
      "y": 117,
      "z": 3,
      "name": "Wood_Azure_Branch_Long",
      "rotation": 6
    },
    {
      "x": -10,
      "y": 120,
      "z": 3,
      "name": "Wood_Azure_Branch_Long",
      "rotation": 5
    },
    {
      "x": -10,
      "y": 122,
      "z": 3,
      "name": "Plant_Leaves_Azure",
      "rotation": 1
    },
    {
      "x": -10,
      "y": 123,
      "z": 3,
      "name": "Plant_Leaves_Azure",
      "rotation": 1
    },
    {
      "x": -10,
      "y": 97,
      "z": 4,
      "name": "Rock_Marble"
    },
    {
      "x": -10,
      "y": 98,
      "z": 4,
      "name": "Rock_Marble"
    },
    {
      "x": -10,
      "y": 99,
      "z": 4,
      "name": "Rock_Marble"
    },
    {
      "x": -10,
      "y": 100,
      "z": 4,
      "name": "Rock_Marble"
    },
    {
      "x": -10,
      "y": 101,
      "z": 4,
      "name": "Rock_Marble"
    },
    {
      "x": -10,
      "y": 104,
      "z": 4,
      "name": "Wood_Azure_Trunk_Full",
      "rotation": 1
    },
    {
      "x": -10,
      "y": 105,
      "z": 4,
      "name": "Wood_Azure_Trunk_Full",
      "rotation": 1
    },
    {
      "x": -10,
      "y": 110,
      "z": 4,
      "name": "Plant_Moss_Wall_Blue",
      "rotation": 3
    },
    {
      "x": -10,
      "y": 111,
      "z": 4,
      "name": "Wood_Azure_Trunk_Full",
      "rotation": 1
    },
    {
      "x": -10,
      "y": 113,
      "z": 4,
      "name": "Wood_Azure_Branch_Corner"
    },
    {
      "x": -10,
      "y": 114,
      "z": 4,
      "name": "Wood_Azure_Branch_Corner",
      "rotation": 9
    },
    {
      "x": -10,
      "y": 116,
      "z": 4,
      "name": "Plant_Leaves_Azure",
      "rotation": 1
    },
    {
      "x": -10,
      "y": 117,
      "z": 4,
      "name": "Wood_Azure_Branch_Long",
      "rotation": 6
    },
    {
      "x": -10,
      "y": 118,
      "z": 4,
      "name": "Plant_Leaves_Azure",
      "rotation": 1
    },
    {
      "x": -10,
      "y": 119,
      "z": 4,
      "name": "Plant_Leaves_Azure",
      "rotation": 1
    },
    {
      "x": -10,
      "y": 120,
      "z": 4,
      "name": "Plant_Leaves_Azure",
      "rotation": 1
    },
    {
      "x": -10,
      "y": 97,
      "z": 5,
      "name": "Rock_Marble"
    },
    {
      "x": -10,
      "y": 98,
      "z": 5,
      "name": "Rock_Marble"
    },
    {
      "x": -10,
      "y": 99,
      "z": 5,
      "name": "Rock_Marble"
    },
    {
      "x": -10,
      "y": 100,
      "z": 5,
      "name": "Rock_Marble"
    },
    {
      "x": -10,
      "y": 101,
      "z": 5,
      "name": "Rock_Marble_Cobble"
    },
    {
      "x": -10,
      "y": 111,
      "z": 5,
      "name": "Wood_Azure_Trunk_Full",
      "rotation": 1
    },
    {
      "x": -10,
      "y": 112,
      "z": 5,
      "name": "Plant_Moss_Rug_Blue",
      "rotation": 1
    },
    {
      "x": -10,
      "y": 114,
      "z": 5,
      "name": "Plant_Leaves_Azure",
      "rotation": 1
    },
    {
      "x": -10,
      "y": 115,
      "z": 5,
      "name": "Plant_Leaves_Azure",
      "rotation": 1
    },
    {
      "x": -10,
      "y": 116,
      "z": 5,
      "name": "Plant_Leaves_Azure",
      "rotation": 1
    },
    {
      "x": -10,
      "y": 117,
      "z": 5,
      "name": "Plant_Leaves_Azure",
      "rotation": 1
    },
    {
      "x": -10,
      "y": 118,
      "z": 5,
      "name": "Plant_Leaves_Azure",
      "rotation": 1
    },
    {
      "x": -10,
      "y": 119,
      "z": 5,
      "name": "Plant_Leaves_Azure",
      "rotation": 1
    },
    {
      "x": -10,
      "y": 120,
      "z": 5,
      "name": "Plant_Leaves_Azure",
      "rotation": 1
    },
    {
      "x": -10,
      "y": 121,
      "z": 5,
      "name": "Plant_Leaves_Azure",
      "rotation": 1
    },
    {
      "x": -10,
      "y": 97,
      "z": 6,
      "name": "Rock_Marble"
    },
    {
      "x": -10,
      "y": 98,
      "z": 6,
      "name": "Rock_Marble"
    },
    {
      "x": -10,
      "y": 99,
      "z": 6,
      "name": "Rock_Marble"
    },
    {
      "x": -10,
      "y": 100,
      "z": 6,
      "name": "Rock_Marble"
    },
    {
      "x": -10,
      "y": 101,
      "z": 6,
      "name": "Plant_Moss_Rug_Lime"
    },
    {
      "x": -10,
      "y": 110,
      "z": 6,
      "name": "Plant_Leaves_Azure",
      "rotation": 1
    },
    {
      "x": -10,
      "y": 111,
      "z": 6,
      "name": "Wood_Azure_Branch_Long",
      "rotation": 6
    },
    {
      "x": -10,
      "y": 115,
      "z": 6,
      "name": "Plant_Leaves_Azure",
      "rotation": 1
    },
    {
      "x": -10,
      "y": 116,
      "z": 6,
      "name": "Plant_Leaves_Azure",
      "rotation": 1
    },
    {
      "x": -10,
      "y": 117,
      "z": 6,
      "name": "Plant_Leaves_Azure",
      "rotation": 1
    },
    {
      "x": -10,
      "y": 118,
      "z": 6,
      "name": "Plant_Leaves_Azure",
      "rotation": 1
    },
    {
      "x": -10,
      "y": 119,
      "z": 6,
      "name": "Plant_Leaves_Azure",
      "rotation": 1
    },
    {
      "x": -10,
      "y": 120,
      "z": 6,
      "name": "Plant_Leaves_Azure",
      "rotation": 1
    },
    {
      "x": -10,
      "y": 97,
      "z": 7,
      "name": "Plant_Moss_Wall_Blue",
      "support": 15,
      "rotation": 3
    },
    {
      "x": -10,
      "y": 110,
      "z": 7,
      "name": "Plant_Leaves_Azure",
      "rotation": 1
    },
    {
      "x": -10,
      "y": 111,
      "z": 7,
      "name": "Plant_Leaves_Azure",
      "rotation": 1
    },
    {
      "x": -10,
      "y": 112,
      "z": 7,
      "name": "Plant_Leaves_Azure",
      "rotation": 1
    },
    {
      "x": -10,
      "y": 113,
      "z": 7,
      "name": "Plant_Leaves_Azure",
      "rotation": 1
    },
    {
      "x": -10,
      "y": 117,
      "z": 7,
      "name": "Plant_Leaves_Azure",
      "rotation": 1
    },
    {
      "x": -10,
      "y": 118,
      "z": 7,
      "name": "Plant_Leaves_Azure",
      "rotation": 1
    },
    {
      "x": -10,
      "y": 119,
      "z": 7,
      "name": "Plant_Leaves_Azure",
      "rotation": 1
    },
    {
      "x": -10,
      "y": 110,
      "z": 8,
      "name": "Plant_Leaves_Azure",
      "rotation": 1
    },
    {
      "x": -10,
      "y": 111,
      "z": 8,
      "name": "Plant_Leaves_Azure",
      "rotation": 1
    },
    {
      "x": -10,
      "y": 112,
      "z": 8,
      "name": "Plant_Leaves_Azure",
      "rotation": 1
    },
    {
      "x": -10,
      "y": 113,
      "z": 8,
      "name": "Plant_Leaves_Azure",
      "rotation": 1
    },
    {
      "x": -10,
      "y": 111,
      "z": 9,
      "name": "Plant_Leaves_Azure",
      "rotation": 1
    },
    {
      "x": -10,
      "y": 112,
      "z": 9,
      "name": "Plant_Leaves_Azure",
      "rotation": 1
    },
    {
      "x": -9,
      "y": 108,
      "z": -4,
      "name": "Plant_Leaves_Azure",
      "rotation": 1
    },
    {
      "x": -9,
      "y": 96,
      "z": -3,
      "name": "Plant_Moss_Wall_Blue",
      "support": 15,
      "rotation": 3
    },
    {
      "x": -9,
      "y": 107,
      "z": -3,
      "name": "Plant_Leaves_Azure",
      "rotation": 1
    },
    {
      "x": -9,
      "y": 108,
      "z": -3,
      "name": "Plant_Leaves_Azure",
      "rotation": 1
    },
    {
      "x": -9,
      "y": 109,
      "z": -3,
      "name": "Plant_Leaves_Azure",
      "rotation": 1
    },
    {
      "x": -9,
      "y": 111,
      "z": -3,
      "name": "Plant_Leaves_Azure",
      "rotation": 1
    },
    {
      "x": -9,
      "y": 112,
      "z": -3,
      "name": "Plant_Leaves_Azure",
      "rotation": 1
    },
    {
      "x": -9,
      "y": 113,
      "z": -3,
      "name": "Plant_Leaves_Azure",
      "rotation": 1
    },
    {
      "x": -9,
      "y": 114,
      "z": -3,
      "name": "Plant_Leaves_Azure",
      "rotation": 1
    },
    {
      "x": -9,
      "y": 92,
      "z": -2,
      "name": "Plant_Moss_Wall_Blue",
      "support": 15,
      "rotation": 3
    },
    {
      "x": -9,
      "y": 93,
      "z": -2,
      "name": "Plant_Moss_Wall_Blue",
      "support": 15,
      "rotation": 3
    },
    {
      "x": -9,
      "y": 95,
      "z": -2,
      "name": "Plant_Moss_Wall_Blue",
      "support": 15,
      "rotation": 3
    },
    {
      "x": -9,
      "y": 96,
      "z": -2,
      "name": "Plant_Moss_Wall_Blue",
      "support": 15,
      "rotation": 3
    },
    {
      "x": -9,
      "y": 98,
      "z": -2,
      "name": "Plant_Moss_Wall_Blue",
      "support": 15,
      "rotation": 3
    },
    {
      "x": -9,
      "y": 108,
      "z": -2,
      "name": "Plant_Leaves_Azure",
      "rotation": 1
    },
    {
      "x": -9,
      "y": 112,
      "z": -2,
      "name": "Plant_Leaves_Azure",
      "rotation": 1
    },
    {
      "x": -9,
      "y": 113,
      "z": -2,
      "name": "Plant_Leaves_Azure",
      "rotation": 1
    },
    {
      "x": -9,
      "y": 114,
      "z": -2,
      "name": "Plant_Leaves_Azure",
      "rotation": 1
    },
    {
      "x": -9,
      "y": 115,
      "z": -2,
      "name": "Plant_Leaves_Azure",
      "rotation": 1
    },
    {
      "x": -9,
      "y": 116,
      "z": -2,
      "name": "Plant_Fruit_Azure",
      "rotation": 1
    },
    {
      "x": -9,
      "y": 89,
      "z": -1,
      "name": "Plant_Moss_Wall_Blue",
      "support": 15,
      "rotation": 3
    },
    {
      "x": -9,
      "y": 90,
      "z": -1,
      "name": "Plant_Moss_Wall_Blue",
      "support": 15,
      "rotation": 3
    },
    {
      "x": -9,
      "y": 93,
      "z": -1,
      "name": "Plant_Moss_Wall_Blue",
      "support": 15,
      "rotation": 3
    },
    {
      "x": -9,
      "y": 94,
      "z": -1,
      "name": "Plant_Moss_Wall_Blue",
      "support": 15,
      "rotation": 3
    },
    {
      "x": -9,
      "y": 97,
      "z": -1,
      "name": "Plant_Moss_Wall_Blue",
      "support": 15,
      "rotation": 3
    },
    {
      "x": -9,
      "y": 98,
      "z": -1,
      "name": "Plant_Moss_Wall_Blue",
      "support": 15,
      "rotation": 3
    },
    {
      "x": -9,
      "y": 102,
      "z": -1,
      "name": "Rock_Marble"
    },
    {
      "x": -9,
      "y": 103,
      "z": -1,
      "name": "Rock_Marble"
    },
    {
      "x": -9,
      "y": 104,
      "z": -1,
      "name": "Rock_Marble"
    },
    {
      "x": -9,
      "y": 113,
      "z": -1,
      "name": "Plant_Leaves_Azure",
      "rotation": 1
    },
    {
      "x": -9,
      "y": 114,
      "z": -1,
      "name": "Plant_Leaves_Azure",
      "rotation": 1
    },
    {
      "x": -9,
      "y": 115,
      "z": -1,
      "name": "Plant_Leaves_Azure",
      "rotation": 1
    },
    {
      "x": -9,
      "y": 88,
      "z": 0,
      "name": "Plant_Moss_Wall_Blue",
      "support": 15,
      "rotation": 3
    },
    {
      "x": -9,
      "y": 97,
      "z": 0,
      "name": "Plant_Moss_Wall_Blue",
      "support": 15,
      "rotation": 3
    },
    {
      "x": -9,
      "y": 102,
      "z": 0,
      "name": "Rock_Marble"
    },
    {
      "x": -9,
      "y": 103,
      "z": 0,
      "name": "Rock_Marble"
    },
    {
      "x": -9,
      "y": 104,
      "z": 0,
      "name": "Plant_Moss_Rug_Lime"
    },
    {
      "x": -9,
      "y": 106,
      "z": 0,
      "name": "Wood_Azure_Trunk_Full",
      "rotation": 1
    },
    {
      "x": -9,
      "y": 107,
      "z": 0,
      "name": "Wood_Azure_Trunk",
      "rotation": 1
    },
    {
      "x": -9,
      "y": 108,
      "z": 0,
      "name": "Wood_Azure_Trunk",
      "rotation": 1
    },
    {
      "x": -9,
      "y": 109,
      "z": 0,
      "name": "Wood_Azure_Trunk_Full",
      "rotation": 1
    },
    {
      "x": -9,
      "y": 111,
      "z": 0,
      "name": "Plant_Moss_Wall_Blue",
      "rotation": 1
    },
    {
      "x": -9,
      "y": 113,
      "z": 0,
      "name": "Wood_Azure_Branch_Long",
      "rotation": 6
    },
    {
      "x": -9,
      "y": 114,
      "z": 0,
      "name": "Plant_Leaves_Azure",
      "rotation": 1
    },
    {
      "x": -9,
      "y": 115,
      "z": 0,
      "name": "Plant_Leaves_Azure",
      "rotation": 1
    },
    {
      "x": -9,
      "y": 117,
      "z": 0,
      "name": "Plant_Leaves_Azure",
      "rotation": 1
    },
    {
      "x": -9,
      "y": 118,
      "z": 0,
      "name": "Plant_Leaves_Azure",
      "rotation": 1
    },
    {
      "x": -9,
      "y": 120,
      "z": 0,
      "name": "Plant_Leaves_Azure",
      "rotation": 1
    },
    {
      "x": -9,
      "y": 121,
      "z": 0,
      "name": "Plant_Leaves_Azure",
      "rotation": 1
    },
    {
      "x": -9,
      "y": 96,
      "z": 1,
      "name": "Plant_Moss_Wall_Blue",
      "support": 15,
      "rotation": 3
    },
    {
      "x": -9,
      "y": 98,
      "z": 1,
      "name": "Plant_Moss_Wall_Blue",
      "support": 15,
      "rotation": 3
    },
    {
      "x": -9,
      "y": 102,
      "z": 1,
      "name": "Rock_Marble"
    },
    {
      "x": -9,
      "y": 103,
      "z": 1,
      "name": "Plant_Moss_Block_Blue"
    },
    {
      "x": -9,
      "y": 104,
      "z": 1,
      "name": "Wood_Azure_Trunk_Full",
      "rotation": 1
    },
    {
      "x": -9,
      "y": 105,
      "z": 1,
      "name": "Wood_Azure_Trunk",
      "rotation": 1
    },
    {
      "x": -9,
      "y": 106,
      "z": 1,
      "name": "Wood_Azure_Trunk",
      "rotation": 1
    },
    {
      "x": -9,
      "y": 107,
      "z": 1,
      "name": "Wood_Azure_Trunk_Full",
      "rotation": 1
    },
    {
      "x": -9,
      "y": 108,
      "z": 1,
      "name": "Wood_Azure_Trunk",
      "rotation": 1
    },
    {
      "x": -9,
      "y": 109,
      "z": 1,
      "name": "Wood_Azure_Trunk",
      "rotation": 1
    },
    {
      "x": -9,
      "y": 110,
      "z": 1,
      "name": "Wood_Azure_Trunk",
      "rotation": 1
    },
    {
      "x": -9,
      "y": 111,
      "z": 1,
      "name": "Wood_Azure_Trunk",
      "rotation": 1
    },
    {
      "x": -9,
      "y": 112,
      "z": 1,
      "name": "Wood_Azure_Trunk",
      "rotation": 1
    },
    {
      "x": -9,
      "y": 113,
      "z": 1,
      "name": "Wood_Azure_Trunk",
      "rotation": 1
    },
    {
      "x": -9,
      "y": 114,
      "z": 1,
      "name": "Wood_Azure_Trunk_Full",
      "rotation": 1
    },
    {
      "x": -9,
      "y": 115,
      "z": 1,
      "name": "Plant_Moss_Rug_Blue",
      "rotation": 1
    },
    {
      "x": -9,
      "y": 116,
      "z": 1,
      "name": "Wood_Azure_Branch_Long",
      "rotation": 5
    },
    {
      "x": -9,
      "y": 117,
      "z": 1,
      "name": "Plant_Leaves_Azure",
      "rotation": 1
    },
    {
      "x": -9,
      "y": 118,
      "z": 1,
      "name": "Plant_Leaves_Azure",
      "rotation": 1
    },
    {
      "x": -9,
      "y": 119,
      "z": 1,
      "name": "Plant_Fruit_Azure",
      "rotation": 1
    },
    {
      "x": -9,
      "y": 120,
      "z": 1,
      "name": "Plant_Leaves_Azure",
      "rotation": 1
    },
    {
      "x": -9,
      "y": 121,
      "z": 1,
      "name": "Plant_Leaves_Azure",
      "rotation": 1
    },
    {
      "x": -9,
      "y": 122,
      "z": 1,
      "name": "Plant_Leaves_Azure",
      "rotation": 1
    },
    {
      "x": -9,
      "y": 97,
      "z": 2,
      "name": "Rock_Marble"
    },
    {
      "x": -9,
      "y": 98,
      "z": 2,
      "name": "Rock_Marble"
    },
    {
      "x": -9,
      "y": 99,
      "z": 2,
      "name": "Rock_Marble"
    },
    {
      "x": -9,
      "y": 100,
      "z": 2,
      "name": "Rock_Marble"
    },
    {
      "x": -9,
      "y": 101,
      "z": 2,
      "name": "Rock_Marble"
    },
    {
      "x": -9,
      "y": 104,
      "z": 2,
      "name": "Wood_Azure_Trunk_Full",
      "rotation": 1
    },
    {
      "x": -9,
      "y": 105,
      "z": 2,
      "name": "Wood_Azure_Trunk",
      "rotation": 1
    },
    {
      "x": -9,
      "y": 106,
      "z": 2,
      "name": "Wood_Azure_Trunk",
      "rotation": 1
    },
    {
      "x": -9,
      "y": 107,
      "z": 2,
      "name": "Wood_Azure_Trunk",
      "rotation": 1
    },
    {
      "x": -9,
      "y": 108,
      "z": 2,
      "name": "Wood_Azure_Trunk",
      "rotation": 1
    },
    {
      "x": -9,
      "y": 109,
      "z": 2,
      "name": "Wood_Azure_Trunk",
      "rotation": 1
    },
    {
      "x": -9,
      "y": 110,
      "z": 2,
      "name": "Wood_Azure_Trunk",
      "rotation": 1
    },
    {
      "x": -9,
      "y": 111,
      "z": 2,
      "name": "Wood_Azure_Trunk_Full",
      "rotation": 1
    },
    {
      "x": -9,
      "y": 112,
      "z": 2,
      "name": "Wood_Azure_Trunk_Full",
      "rotation": 1
    },
    {
      "x": -9,
      "y": 114,
      "z": 2,
      "name": "Plant_Moss_Wall_Blue"
    },
    {
      "x": -9,
      "y": 115,
      "z": 2,
      "name": "Plant_Moss_Wall_Blue",
      "rotation": 1
    },
    {
      "x": -9,
      "y": 117,
      "z": 2,
      "name": "Wood_Azure_Branch_Long",
      "rotation": 5
    },
    {
      "x": -9,
      "y": 119,
      "z": 2,
      "name": "Wood_Azure_Branch_Long",
      "rotation": 5
    },
    {
      "x": -9,
      "y": 120,
      "z": 2,
      "name": "Plant_Leaves_Azure",
      "rotation": 1
    },
    {
      "x": -9,
      "y": 121,
      "z": 2,
      "name": "Plant_Leaves_Azure",
      "rotation": 1
    },
    {
      "x": -9,
      "y": 122,
      "z": 2,
      "name": "Plant_Leaves_Azure",
      "rotation": 1
    },
    {
      "x": -9,
      "y": 97,
      "z": 3,
      "name": "Rock_Marble"
    },
    {
      "x": -9,
      "y": 98,
      "z": 3,
      "name": "Rock_Marble"
    },
    {
      "x": -9,
      "y": 99,
      "z": 3,
      "name": "Rock_Marble"
    },
    {
      "x": -9,
      "y": 100,
      "z": 3,
      "name": "Rock_Marble"
    },
    {
      "x": -9,
      "y": 101,
      "z": 3,
      "name": "Rock_Marble"
    },
    {
      "x": -9,
      "y": 102,
      "z": 3,
      "name": "Plant_Moss_Block_Blue"
    },
    {
      "x": -9,
      "y": 103,
      "z": 3,
      "name": "Wood_Azure_Trunk_Full",
      "rotation": 1
    },
    {
      "x": -9,
      "y": 104,
      "z": 3,
      "name": "Wood_Azure_Trunk_Full",
      "rotation": 1
    },
    {
      "x": -9,
      "y": 105,
      "z": 3,
      "name": "Wood_Azure_Trunk_Full",
      "rotation": 1
    },
    {
      "x": -9,
      "y": 106,
      "z": 3,
      "name": "Wood_Azure_Trunk",
      "rotation": 1
    },
    {
      "x": -9,
      "y": 107,
      "z": 3,
      "name": "Wood_Azure_Trunk",
      "rotation": 1
    },
    {
      "x": -9,
      "y": 108,
      "z": 3,
      "name": "Wood_Azure_Trunk",
      "rotation": 1
    },
    {
      "x": -9,
      "y": 109,
      "z": 3,
      "name": "Wood_Azure_Trunk_Full",
      "rotation": 1
    },
    {
      "x": -9,
      "y": 110,
      "z": 3,
      "name": "Wood_Azure_Trunk_Full",
      "rotation": 1
    },
    {
      "x": -9,
      "y": 112,
      "z": 3,
      "name": "Wood_Azure_Branch_Corner"
    },
    {
      "x": -9,
      "y": 113,
      "z": 3,
      "name": "Wood_Azure_Branch_Corner",
      "rotation": 9
    },
    {
      "x": -9,
      "y": 117,
      "z": 3,
      "name": "Plant_Leaves_Azure",
      "rotation": 1
    },
    {
      "x": -9,
      "y": 118,
      "z": 3,
      "name": "Plant_Leaves_Azure",
      "rotation": 1
    },
    {
      "x": -9,
      "y": 119,
      "z": 3,
      "name": "Plant_Leaves_Azure",
      "rotation": 1
    },
    {
      "x": -9,
      "y": 120,
      "z": 3,
      "name": "Plant_Leaves_Azure",
      "rotation": 1
    },
    {
      "x": -9,
      "y": 121,
      "z": 3,
      "name": "Plant_Leaves_Azure",
      "rotation": 1
    },
    {
      "x": -9,
      "y": 122,
      "z": 3,
      "name": "Plant_Leaves_Azure",
      "rotation": 1
    },
    {
      "x": -9,
      "y": 95,
      "z": 4,
      "name": "Rock_Marble_Stalactite_Large",
      "filler": 31744,
      "rotation": 8
    },
    {
      "x": -9,
      "y": 96,
      "z": 4,
      "name": "Rock_Marble_Stalactite_Large",
      "rotation": 8
    },
    {
      "x": -9,
      "y": 97,
      "z": 4,
      "name": "Rock_Marble"
    },
    {
      "x": -9,
      "y": 98,
      "z": 4,
      "name": "Rock_Marble"
    },
    {
      "x": -9,
      "y": 99,
      "z": 4,
      "name": "Rock_Marble"
    },
    {
      "x": -9,
      "y": 100,
      "z": 4,
      "name": "Rock_Marble"
    },
    {
      "x": -9,
      "y": 101,
      "z": 4,
      "name": "Rock_Marble"
    },
    {
      "x": -9,
      "y": 102,
      "z": 4,
      "name": "Plant_Moss_Block_Blue"
    },
    {
      "x": -9,
      "y": 103,
      "z": 4,
      "name": "Plant_Moss_Short_Green_Dark"
    },
    {
      "x": -9,
      "y": 110,
      "z": 4,
      "name": "Wood_Azure_Trunk_Full",
      "rotation": 1
    },
    {
      "x": -9,
      "y": 111,
      "z": 4,
      "name": "Plant_Moss_Rug_Blue",
      "rotation": 1
    },
    {
      "x": -9,
      "y": 114,
      "z": 4,
      "name": "Wood_Azure_Branch_Long",
      "rotation": 5
    },
    {
      "x": -9,
      "y": 115,
      "z": 4,
      "name": "Plant_Leaves_Azure",
      "rotation": 1
    },
    {
      "x": -9,
      "y": 116,
      "z": 4,
      "name": "Plant_Leaves_Azure",
      "rotation": 1
    },
    {
      "x": -9,
      "y": 117,
      "z": 4,
      "name": "Plant_Leaves_Azure",
      "rotation": 1
    },
    {
      "x": -9,
      "y": 118,
      "z": 4,
      "name": "Plant_Leaves_Azure",
      "rotation": 1
    },
    {
      "x": -9,
      "y": 119,
      "z": 4,
      "name": "Plant_Leaves_Azure",
      "rotation": 1
    },
    {
      "x": -9,
      "y": 120,
      "z": 4,
      "name": "Plant_Leaves_Azure",
      "rotation": 1
    },
    {
      "x": -9,
      "y": 121,
      "z": 4,
      "name": "Plant_Leaves_Azure",
      "rotation": 1
    },
    {
      "x": -9,
      "y": 122,
      "z": 4,
      "name": "Plant_Leaves_Azure",
      "rotation": 1
    },
    {
      "x": -9,
      "y": 123,
      "z": 4,
      "name": "Plant_Fruit_Azure",
      "rotation": 1
    },
    {
      "x": -9,
      "y": 97,
      "z": 5,
      "name": "Rock_Marble"
    },
    {
      "x": -9,
      "y": 98,
      "z": 5,
      "name": "Rock_Marble_Cobble"
    },
    {
      "x": -9,
      "y": 99,
      "z": 5,
      "name": "Rock_Marble"
    },
    {
      "x": -9,
      "y": 100,
      "z": 5,
      "name": "Rock_Marble"
    },
    {
      "x": -9,
      "y": 101,
      "z": 5,
      "name": "Rock_Marble"
    },
    {
      "x": -9,
      "y": 102,
      "z": 5,
      "name": "Plant_Moss_Block_Blue"
    },
    {
      "x": -9,
      "y": 103,
      "z": 5,
      "name": "Plant_Moss_Rug_Lime"
    },
    {
      "x": -9,
      "y": 110,
      "z": 5,
      "name": "Wood_Azure_Branch_Long",
      "rotation": 6
    },
    {
      "x": -9,
      "y": 111,
      "z": 5,
      "name": "Plant_Moss_Wall_Blue",
      "rotation": 1
    },
    {
      "x": -9,
      "y": 115,
      "z": 5,
      "name": "Plant_Leaves_Azure",
      "rotation": 1
    },
    {
      "x": -9,
      "y": 116,
      "z": 5,
      "name": "Plant_Leaves_Azure",
      "rotation": 1
    },
    {
      "x": -9,
      "y": 117,
      "z": 5,
      "name": "Plant_Leaves_Azure",
      "rotation": 1
    },
    {
      "x": -9,
      "y": 118,
      "z": 5,
      "name": "Plant_Leaves_Azure",
      "rotation": 1
    },
    {
      "x": -9,
      "y": 119,
      "z": 5,
      "name": "Plant_Leaves_Azure",
      "rotation": 1
    },
    {
      "x": -9,
      "y": 120,
      "z": 5,
      "name": "Plant_Leaves_Azure",
      "rotation": 1
    },
    {
      "x": -9,
      "y": 121,
      "z": 5,
      "name": "Plant_Leaves_Azure",
      "rotation": 1
    },
    {
      "x": -9,
      "y": 97,
      "z": 6,
      "name": "Rock_Marble"
    },
    {
      "x": -9,
      "y": 98,
      "z": 6,
      "name": "Rock_Marble"
    },
    {
      "x": -9,
      "y": 99,
      "z": 6,
      "name": "Rock_Marble"
    },
    {
      "x": -9,
      "y": 100,
      "z": 6,
      "name": "Plant_Moss_Block_Blue"
    },
    {
      "x": -9,
      "y": 101,
      "z": 6,
      "name": "Plant_Moss_Rug_Lime"
    },
    {
      "x": -9,
      "y": 109,
      "z": 6,
      "name": "Plant_Leaves_Azure",
      "rotation": 1
    },
    {
      "x": -9,
      "y": 110,
      "z": 6,
      "name": "Plant_Leaves_Azure",
      "rotation": 1
    },
    {
      "x": -9,
      "y": 111,
      "z": 6,
      "name": "Plant_Leaves_Azure",
      "rotation": 1
    },
    {
      "x": -9,
      "y": 112,
      "z": 6,
      "name": "Plant_Leaves_Azure",
      "rotation": 1
    },
    {
      "x": -9,
      "y": 113,
      "z": 6,
      "name": "Plant_Leaves_Azure",
      "rotation": 1
    },
    {
      "x": -9,
      "y": 114,
      "z": 6,
      "name": "Plant_Leaves_Azure",
      "rotation": 1
    },
    {
      "x": -9,
      "y": 116,
      "z": 6,
      "name": "Plant_Leaves_Azure",
      "rotation": 1
    },
    {
      "x": -9,
      "y": 117,
      "z": 6,
      "name": "Plant_Leaves_Azure",
      "rotation": 1
    },
    {
      "x": -9,
      "y": 118,
      "z": 6,
      "name": "Plant_Leaves_Azure",
      "rotation": 1
    },
    {
      "x": -9,
      "y": 119,
      "z": 6,
      "name": "Plant_Leaves_Azure",
      "rotation": 1
    },
    {
      "x": -9,
      "y": 97,
      "z": 7,
      "name": "Rock_Marble"
    },
    {
      "x": -9,
      "y": 98,
      "z": 7,
      "name": "Rock_Marble"
    },
    {
      "x": -9,
      "y": 99,
      "z": 7,
      "name": "Rock_Marble"
    },
    {
      "x": -9,
      "y": 100,
      "z": 7,
      "name": "Rock_Marble"
    },
    {
      "x": -9,
      "y": 101,
      "z": 7,
      "name": "Plant_Moss_Rug_Lime"
    },
    {
      "x": -9,
      "y": 109,
      "z": 7,
      "name": "Plant_Leaves_Azure",
      "rotation": 1
    },
    {
      "x": -9,
      "y": 110,
      "z": 7,
      "name": "Plant_Leaves_Azure",
      "rotation": 1
    },
    {
      "x": -9,
      "y": 111,
      "z": 7,
      "name": "Plant_Leaves_Azure",
      "rotation": 1
    },
    {
      "x": -9,
      "y": 112,
      "z": 7,
      "name": "Plant_Leaves_Azure",
      "rotation": 1
    },
    {
      "x": -9,
      "y": 113,
      "z": 7,
      "name": "Plant_Leaves_Azure",
      "rotation": 1
    },
    {
      "x": -9,
      "y": 110,
      "z": 8,
      "name": "Plant_Leaves_Azure",
      "rotation": 1
    },
    {
      "x": -9,
      "y": 111,
      "z": 8,
      "name": "Plant_Leaves_Azure",
      "rotation": 1
    },
    {
      "x": -9,
      "y": 112,
      "z": 8,
      "name": "Plant_Leaves_Azure",
      "rotation": 1
    },
    {
      "x": -9,
      "y": 113,
      "z": 8,
      "name": "Plant_Leaves_Azure",
      "rotation": 1
    },
    {
      "x": -9,
      "y": 114,
      "z": 8,
      "name": "Plant_Fruit_Azure",
      "rotation": 1
    },
    {
      "x": -9,
      "y": 97,
      "z": 9,
      "name": "Plant_Moss_Wall_Blue",
      "support": 15,
      "rotation": 3
    },
    {
      "x": -9,
      "y": 111,
      "z": 9,
      "name": "Plant_Leaves_Azure",
      "rotation": 1
    },
    {
      "x": -9,
      "y": 112,
      "z": 9,
      "name": "Plant_Leaves_Azure",
      "rotation": 1
    },
    {
      "x": -8,
      "y": 94,
      "z": -4,
      "name": "Plant_Moss_Wall_Blue",
      "support": 15,
      "rotation": 3
    },
    {
      "x": -8,
      "y": 96,
      "z": -3,
      "name": "Rock_Marble"
    },
    {
      "x": -8,
      "y": 97,
      "z": -3,
      "name": "Rock_Marble"
    },
    {
      "x": -8,
      "y": 98,
      "z": -3,
      "name": "Rock_Marble"
    },
    {
      "x": -8,
      "y": 99,
      "z": -3,
      "name": "Rock_Marble_Cobble"
    },
    {
      "x": -8,
      "y": 100,
      "z": -3,
      "name": "Rock_Marble"
    },
    {
      "x": -8,
      "y": 103,
      "z": -3,
      "name": "Plant_Moss_Wall_Blue",
      "support": 15,
      "rotation": 3
    },
    {
      "x": -8,
      "y": 104,
      "z": -3,
      "name": "Plant_Moss_Wall_Blue",
      "support": 15,
      "rotation": 3
    },
    {
      "x": -8,
      "y": 111,
      "z": -3,
      "name": "Plant_Leaves_Azure",
      "rotation": 1
    },
    {
      "x": -8,
      "y": 112,
      "z": -3,
      "name": "Plant_Leaves_Azure",
      "rotation": 1
    },
    {
      "x": -8,
      "y": 113,
      "z": -3,
      "name": "Plant_Leaves_Azure",
      "rotation": 1
    },
    {
      "x": -8,
      "y": 89,
      "z": -2,
      "name": "Rock_Marble"
    },
    {
      "x": -8,
      "y": 90,
      "z": -2,
      "name": "Rock_Marble"
    },
    {
      "x": -8,
      "y": 91,
      "z": -2,
      "name": "Rock_Marble"
    },
    {
      "x": -8,
      "y": 92,
      "z": -2,
      "name": "Rock_Marble"
    },
    {
      "x": -8,
      "y": 93,
      "z": -2,
      "name": "Rock_Marble"
    },
    {
      "x": -8,
      "y": 94,
      "z": -2,
      "name": "Rock_Marble"
    },
    {
      "x": -8,
      "y": 95,
      "z": -2,
      "name": "Rock_Marble"
    },
    {
      "x": -8,
      "y": 96,
      "z": -2,
      "name": "Rock_Marble_Cobble"
    },
    {
      "x": -8,
      "y": 97,
      "z": -2,
      "name": "Rock_Marble"
    },
    {
      "x": -8,
      "y": 98,
      "z": -2,
      "name": "Rock_Marble"
    },
    {
      "x": -8,
      "y": 99,
      "z": -2,
      "name": "Rock_Marble"
    },
    {
      "x": -8,
      "y": 100,
      "z": -2,
      "name": "Rock_Marble"
    },
    {
      "x": -8,
      "y": 102,
      "z": -2,
      "name": "Rock_Marble"
    },
    {
      "x": -8,
      "y": 103,
      "z": -2,
      "name": "Rock_Marble"
    },
    {
      "x": -8,
      "y": 104,
      "z": -2,
      "name": "Rock_Marble"
    },
    {
      "x": -8,
      "y": 112,
      "z": -2,
      "name": "Plant_Leaves_Azure",
      "rotation": 1
    },
    {
      "x": -8,
      "y": 113,
      "z": -2,
      "name": "Plant_Leaves_Azure",
      "rotation": 1
    },
    {
      "x": -8,
      "y": 114,
      "z": -2,
      "name": "Plant_Leaves_Azure",
      "rotation": 1
    },
    {
      "x": -8,
      "y": 86,
      "z": -1,
      "name": "Rock_Marble"
    },
    {
      "x": -8,
      "y": 87,
      "z": -1,
      "name": "Rock_Marble"
    },
    {
      "x": -8,
      "y": 88,
      "z": -1,
      "name": "Rock_Marble_Cobble"
    },
    {
      "x": -8,
      "y": 89,
      "z": -1,
      "name": "Rock_Marble"
    },
    {
      "x": -8,
      "y": 90,
      "z": -1,
      "name": "Rock_Marble"
    },
    {
      "x": -8,
      "y": 91,
      "z": -1,
      "name": "Rock_Marble"
    },
    {
      "x": -8,
      "y": 92,
      "z": -1,
      "name": "Rock_Marble"
    },
    {
      "x": -8,
      "y": 93,
      "z": -1,
      "name": "Rock_Marble"
    },
    {
      "x": -8,
      "y": 94,
      "z": -1,
      "name": "Rock_Marble"
    },
    {
      "x": -8,
      "y": 95,
      "z": -1,
      "name": "Rock_Marble"
    },
    {
      "x": -8,
      "y": 96,
      "z": -1,
      "name": "Rock_Marble"
    },
    {
      "x": -8,
      "y": 97,
      "z": -1,
      "name": "Rock_Marble"
    },
    {
      "x": -8,
      "y": 98,
      "z": -1,
      "name": "Rock_Marble"
    },
    {
      "x": -8,
      "y": 99,
      "z": -1,
      "name": "Rock_Marble"
    },
    {
      "x": -8,
      "y": 100,
      "z": -1,
      "name": "Rock_Marble_Cobble"
    },
    {
      "x": -8,
      "y": 101,
      "z": -1,
      "name": "Rock_Marble"
    },
    {
      "x": -8,
      "y": 102,
      "z": -1,
      "name": "Rock_Marble"
    },
    {
      "x": -8,
      "y": 103,
      "z": -1,
      "name": "Rock_Marble"
    },
    {
      "x": -8,
      "y": 104,
      "z": -1,
      "name": "Plant_Moss_Rug_Lime"
    },
    {
      "x": -8,
      "y": 105,
      "z": -1,
      "name": "Plant_Moss_Wall_Blue",
      "support": 15,
      "rotation": 3
    },
    {
      "x": -8,
      "y": 111,
      "z": -1,
      "name": "Plant_Leaves_Azure",
      "rotation": 1
    },
    {
      "x": -8,
      "y": 112,
      "z": -1,
      "name": "Plant_Leaves_Azure",
      "rotation": 1
    },
    {
      "x": -8,
      "y": 113,
      "z": -1,
      "name": "Plant_Leaves_Azure",
      "rotation": 1
    },
    {
      "x": -8,
      "y": 114,
      "z": -1,
      "name": "Plant_Leaves_Azure",
      "rotation": 1
    },
    {
      "x": -8,
      "y": 115,
      "z": -1,
      "name": "Plant_Leaves_Azure",
      "rotation": 1
    },
    {
      "x": -8,
      "y": 116,
      "z": -1,
      "name": "Plant_Fruit_Azure",
      "rotation": 1
    },
    {
      "x": -8,
      "y": 117,
      "z": -1,
      "name": "Plant_Leaves_Azure",
      "rotation": 1
    },
    {
      "x": -8,
      "y": 86,
      "z": 0,
      "name": "Rock_Marble_Cobble"
    },
    {
      "x": -8,
      "y": 87,
      "z": 0,
      "name": "Rock_Marble_Cobble"
    },
    {
      "x": -8,
      "y": 88,
      "z": 0,
      "name": "Rock_Marble"
    },
    {
      "x": -8,
      "y": 89,
      "z": 0,
      "name": "Rock_Marble"
    },
    {
      "x": -8,
      "y": 90,
      "z": 0,
      "name": "Rock_Marble"
    },
    {
      "x": -8,
      "y": 91,
      "z": 0,
      "name": "Rock_Marble"
    },
    {
      "x": -8,
      "y": 93,
      "z": 0,
      "name": "Rock_Marble_Stalactite_Large",
      "filler": 31744,
      "rotation": 8
    },
    {
      "x": -8,
      "y": 94,
      "z": 0,
      "name": "Rock_Marble_Stalactite_Large",
      "rotation": 8
    },
    {
      "x": -8,
      "y": 95,
      "z": 0,
      "name": "Rock_Marble"
    },
    {
      "x": -8,
      "y": 96,
      "z": 0,
      "name": "Rock_Marble"
    },
    {
      "x": -8,
      "y": 97,
      "z": 0,
      "name": "Rock_Marble"
    },
    {
      "x": -8,
      "y": 98,
      "z": 0,
      "name": "Rock_Marble"
    },
    {
      "x": -8,
      "y": 99,
      "z": 0,
      "name": "Rock_Marble"
    },
    {
      "x": -8,
      "y": 100,
      "z": 0,
      "name": "Rock_Marble_Cobble"
    },
    {
      "x": -8,
      "y": 101,
      "z": 0,
      "name": "Rock_Marble"
    },
    {
      "x": -8,
      "y": 102,
      "z": 0,
      "name": "Rock_Marble"
    },
    {
      "x": -8,
      "y": 103,
      "z": 0,
      "name": "Wood_Azure_Trunk_Full",
      "rotation": 1
    },
    {
      "x": -8,
      "y": 104,
      "z": 0,
      "name": "Wood_Azure_Trunk_Full",
      "rotation": 1
    },
    {
      "x": -8,
      "y": 105,
      "z": 0,
      "name": "Wood_Azure_Trunk",
      "rotation": 1
    },
    {
      "x": -8,
      "y": 106,
      "z": 0,
      "name": "Wood_Azure_Trunk_Full",
      "rotation": 1
    },
    {
      "x": -8,
      "y": 112,
      "z": 0,
      "name": "Plant_Leaves_Azure",
      "rotation": 1
    },
    {
      "x": -8,
      "y": 113,
      "z": 0,
      "name": "Plant_Leaves_Azure",
      "rotation": 1
    },
    {
      "x": -8,
      "y": 114,
      "z": 0,
      "name": "Plant_Leaves_Azure",
      "rotation": 1
    },
    {
      "x": -8,
      "y": 116,
      "z": 0,
      "name": "Plant_Leaves_Azure",
      "rotation": 1
    },
    {
      "x": -8,
      "y": 117,
      "z": 0,
      "name": "Plant_Leaves_Azure",
      "rotation": 1
    },
    {
      "x": -8,
      "y": 118,
      "z": 0,
      "name": "Plant_Fruit_Azure",
      "rotation": 1
    },
    {
      "x": -8,
      "y": 120,
      "z": 0,
      "name": "Plant_Leaves_Azure",
      "rotation": 1
    },
    {
      "x": -8,
      "y": 86,
      "z": 1,
      "name": "Plant_Crop_Mushroom_Block_Blue_Mycelium"
    },
    {
      "x": -8,
      "y": 87,
      "z": 1,
      "name": "Rock_Marble"
    },
    {
      "x": -8,
      "y": 88,
      "z": 1,
      "name": "Rock_Marble"
    },
    {
      "x": -8,
      "y": 89,
      "z": 1,
      "name": "Rock_Marble"
    },
    {
      "x": -8,
      "y": 90,
      "z": 1,
      "name": "Rock_Marble"
    },
    {
      "x": -8,
      "y": 91,
      "z": 1,
      "name": "Rock_Marble_Cobble"
    },
    {
      "x": -8,
      "y": 92,
      "z": 1,
      "name": "Rock_Marble_Cobble"
    },
    {
      "x": -8,
      "y": 96,
      "z": 1,
      "name": "Rock_Marble_Cobble"
    },
    {
      "x": -8,
      "y": 97,
      "z": 1,
      "name": "Rock_Marble"
    },
    {
      "x": -8,
      "y": 98,
      "z": 1,
      "name": "Rock_Marble"
    },
    {
      "x": -8,
      "y": 99,
      "z": 1,
      "name": "Rock_Marble"
    },
    {
      "x": -8,
      "y": 100,
      "z": 1,
      "name": "Rock_Marble"
    },
    {
      "x": -8,
      "y": 101,
      "z": 1,
      "name": "Rock_Marble"
    },
    {
      "x": -8,
      "y": 102,
      "z": 1,
      "name": "Wood_Azure_Roots",
      "rotation": 1
    },
    {
      "x": -8,
      "y": 103,
      "z": 1,
      "name": "Wood_Azure_Trunk_Full",
      "rotation": 1
    },
    {
      "x": -8,
      "y": 104,
      "z": 1,
      "name": "Wood_Azure_Trunk",
      "rotation": 1
    },
    {
      "x": -8,
      "y": 105,
      "z": 1,
      "name": "Wood_Azure_Trunk_Full",
      "rotation": 1
    },
    {
      "x": -8,
      "y": 106,
      "z": 1,
      "name": "Wood_Azure_Trunk",
      "rotation": 1
    },
    {
      "x": -8,
      "y": 107,
      "z": 1,
      "name": "Wood_Azure_Trunk",
      "rotation": 1
    },
    {
      "x": -8,
      "y": 108,
      "z": 1,
      "name": "Wood_Azure_Trunk",
      "rotation": 1
    },
    {
      "x": -8,
      "y": 109,
      "z": 1,
      "name": "Wood_Azure_Trunk",
      "rotation": 1
    },
    {
      "x": -8,
      "y": 110,
      "z": 1,
      "name": "Wood_Azure_Trunk_Full",
      "rotation": 1
    },
    {
      "x": -8,
      "y": 113,
      "z": 1,
      "name": "Plant_Leaves_Azure",
      "rotation": 1
    },
    {
      "x": -8,
      "y": 114,
      "z": 1,
      "name": "Plant_Moss_Wall_Blue",
      "rotation": 1
    },
    {
      "x": -8,
      "y": 116,
