{
  "version": 8,
  "blockIdVersion": 11,
  "anchorX": 0,
  "anchorY": 0,
  "anchorZ": 0,
  "blocks": [
    {
      "x": -12,
      "y": 25,
      "z": -10,
      "name": "Plant_Vine_Wall_Poisoned",
      "support": 15,
      "rotation": 3
    },
    {
      "x": -11,
      "y": 23,
      "z": -11,
      "name": "Plant_Vine_Wall_Poisoned",
      "support": 15,
      "rotation": 2
    },
    {
      "x": -11,
      "y": 24,
      "z": -11,
      "name": "Plant_Vine_Wall_Poisoned",
      "support": 15,
      "rotation": 2
    },
    {
      "x": -11,
      "y": 22,
      "z": -10,
      "name": "Plant_Vine_Wall_Poisoned",
      "support": 15,
      "rotation": 2
    },
    {
      "x": -11,
      "y": 23,
      "z": -10,
      "name": "Rock_Magma_Cooled",
      "rotation": 1
    },
    {
      "x": -11,
      "y": 24,
      "z": -10,
      "name": "Rock_Magma_Cooled",
      "rotation": 1
    },
    {
      "x": -11,
      "y": 25,
      "z": -10,
      "name": "Rock_Magma_Cooled",
      "rotation": 1
    },
    {
      "x": -11,
      "y": 26,
      "z": -10,
      "name": "Ore_Adamantite_Magma_Cracked",
      "rotation": 1
    },
    {
      "x": -11,
      "y": 27,
      "z": -10,
      "name": "Plant_Moss_Rug_Pink",
      "support": 15
    },
    {
      "x": -11,
      "y": 21,
      "z": -9,
      "name": "Rock_Magma_Cooled",
      "rotation": 1
    },
    {
      "x": -11,
      "y": 22,
      "z": -9,
      "name": "Rock_Magma_Cooled",
      "rotation": 1
    },
    {
      "x": -11,
      "y": 23,
      "z": -9,
      "name": "Rock_Magma_Cooled",
      "rotation": 1
    },
    {
      "x": -11,
      "y": 24,
      "z": -9,
      "name": "Rock_Magma_Cooled",
      "rotation": 1
    },
    {
      "x": -11,
      "y": 25,
      "z": -9,
      "name": "Plant_Moss_Rug_Pink",
      "support": 15
    },
    {
      "x": -11,
      "y": 26,
      "z": -9,
      "name": "Plant_Vine_Wall_Poisoned",
      "support": 15
    },
    {
      "x": -11,
      "y": 23,
      "z": -8,
      "name": "Plant_Vine_Wall_Poisoned",
      "support": 15
    },
    {
      "x": -11,
      "y": 24,
      "z": -8,
      "name": "Plant_Vine_Wall_Poisoned",
      "support": 15
    },
    {
      "x": -10,
      "y": 20,
      "z": -10,
      "name": "Plant_Vine_Wall_Poisoned",
      "support": 15,
      "rotation": 2
    },
    {
      "x": -10,
      "y": 21,
      "z": -10,
      "name": "Plant_Vine_Wall_Poisoned",
      "support": 15,
      "rotation": 2
    },
    {
      "x": -10,
      "y": 22,
      "z": -10,
      "name": "Plant_Vine_Wall_Poisoned",
      "support": 15,
      "rotation": 2
    },
    {
      "x": -10,
      "y": 20,
      "z": -9,
      "name": "Rock_Magma_Cooled",
      "rotation": 1
    },
    {
      "x": -10,
      "y": 21,
      "z": -9,
      "name": "Rock_Magma_Cooled",
      "rotation": 1
    },
    {
      "x": -10,
      "y": 22,
      "z": -9,
      "name": "Rock_Magma_Cooled",
      "rotation": 1
    },
    {
      "x": -10,
      "y": 23,
      "z": -9,
      "name": "Rock_Magma_Cooled",
      "rotation": 1
    },
    {
      "x": -10,
      "y": 24,
      "z": -9,
      "name": "Plant_Moss_Rug_Pink",
      "support": 15
    },
    {
      "x": -10,
      "y": 22,
      "z": -8,
      "name": "Plant_Vine_Wall_Poisoned",
      "support": 15
    },
    {
      "x": -9,
      "y": 19,
      "z": -10,
      "name": "Plant_Vine_Wall_Poisoned",
      "support": 15,
      "rotation": 2
    },
    {
      "x": -9,
      "y": 19,
      "z": -9,
      "name": "Ore_Adamantite_Magma_Cracked",
      "rotation": 1
    },
    {
      "x": -9,
      "y": 20,
      "z": -9,
      "name": "Rock_Magma_Cooled",
      "rotation": 1
    },
    {
      "x": -9,
      "y": 21,
      "z": -9,
      "name": "Plant_Moss_Rug_Pink",
      "support": 15
    },
    {
      "x": -9,
      "y": 18,
      "z": -8,
      "name": "Plant_Vine_Wall_Poisoned",
      "support": 15,
      "rotation": 2
    },
    {
      "x": -9,
      "y": 19,
      "z": -8,
      "name": "Rock_Magma_Cooled",
      "rotation": 1
    },
    {
      "x": -9,
      "y": 20,
      "z": -8,
      "name": "Rock_Magma_Cooled",
      "rotation": 1
    },
    {
      "x": -9,
      "y": 21,
      "z": -8,
      "name": "Rock_Magma_Cooled",
      "rotation": 1
    },
    {
      "x": -9,
      "y": 22,
      "z": -8,
      "name": "Rock_Magma_Cooled",
      "rotation": 1
    },
    {
      "x": -9,
      "y": 23,
      "z": -8,
      "name": "Plant_Moss_Rug_Pink",
      "support": 15
    },
    {
      "x": -9,
      "y": 17,
      "z": -7,
      "name": "Rock_Magma_Cooled",
      "rotation": 1
    },
    {
      "x": -9,
      "y": 18,
      "z": -7,
      "name": "Rock_Magma_Cooled",
      "rotation": 1
    },
    {
      "x": -9,
      "y": 19,
      "z": -7,
      "name": "Plant_Moss_Rug_Pink",
      "support": 15
    },
    {
      "x": -9,
      "y": 20,
      "z": -7,
      "name": "Plant_Vine_Wall_Poisoned",
      "support": 15
    },
    {
      "x": -8,
      "y": 16,
      "z": -8,
      "name": "Plant_Vine_Wall_Poisoned",
      "support": 15,
      "rotation": 2
    },
    {
      "x": -8,
      "y": 17,
      "z": -8,
      "name": "Ore_Adamantite_Magma_Cracked",
      "rotation": 1
    },
    {
      "x": -8,
      "y": 18,
      "z": -8,
      "name": "Rock_Magma_Cooled",
      "rotation": 1
    },
    {
      "x": -8,
      "y": 19,
      "z": -8,
      "name": "Rock_Magma_Cooled",
      "rotation": 1
    },
    {
      "x": -8,
      "y": 20,
      "z": -8,
      "name": "Plant_Moss_Rug_Pink",
      "support": 15
    },
    {
      "x": -8,
      "y": 16,
      "z": -7,
      "name": "Rock_Magma_Cooled",
      "rotation": 1
    },
    {
      "x": -8,
      "y": 17,
      "z": -7,
      "name": "Ore_Adamantite_Magma_Cracked",
      "rotation": 1
    },
    {
      "x": -8,
      "y": 18,
      "z": -7,
      "name": "Rock_Magma_Cooled",
      "rotation": 1
    },
    {
      "x": -8,
      "y": 19,
      "z": -7,
      "name": "Rock_Magma_Cooled",
      "rotation": 1
    },
    {
      "x": -8,
      "y": 20,
      "z": -7,
      "name": "Ore_Adamantite_Magma_Cracked",
      "rotation": 1
    },
    {
      "x": -8,
      "y": 21,
      "z": -7,
      "name": "Plant_Moss_Rug_Pink",
      "support": 15
    },
    {
      "x": -8,
      "y": 16,
      "z": -6,
      "name": "Ore_Adamantite_Magma_Cracked",
      "rotation": 1
    },
    {
      "x": -8,
      "y": 17,
      "z": -6,
      "name": "Rock_Magma_Cooled",
      "rotation": 1
    },
    {
      "x": -8,
      "y": 18,
      "z": -6,
      "name": "Ore_Adamantite_Magma_Cracked",
      "rotation": 1
    },
    {
      "x": -8,
      "y": 19,
      "z": -6,
      "name": "Plant_Moss_Rug_Pink",
      "support": 15
    },
    {
      "x": -8,
      "y": 18,
      "z": -5,
      "name": "Plant_Vine_Wall_Poisoned",
      "support": 15
    },
    {
      "x": -8,
      "y": 28,
      "z": 6,
      "name": "Plant_Vine_Wall_Poisoned",
      "support": 15,
      "rotation": 3
    },
    {
      "x": -8,
      "y": 29,
      "z": 6,
      "name": "Plant_Vine_Wall_Poisoned",
      "support": 15,
      "rotation": 3
    },
    {
      "x": -8,
      "y": 30,
      "z": 6,
      "name": "Plant_Vine_Wall_Poisoned",
      "support": 15,
      "rotation": 3
    },
    {
      "x": -7,
      "y": 16,
      "z": -9,
      "name": "Plant_Vine_Wall_Poisoned",
      "support": 15,
      "rotation": 2
    },
    {
      "x": -7,
      "y": 15,
      "z": -8,
      "name": "Plant_Vine_Wall_Poisoned",
      "support": 15,
      "rotation": 2
    },
    {
      "x": -7,
      "y": 16,
      "z": -8,
      "name": "Rock_Magma_Cooled",
      "rotation": 1
    },
    {
      "x": -7,
      "y": 17,
      "z": -8,
      "name": "Rock_Magma_Cooled",
      "rotation": 1
    },
    {
      "x": -7,
      "y": 18,
      "z": -8,
      "name": "Rock_Magma_Cooled",
      "rotation": 1
    },
    {
      "x": -7,
      "y": 19,
      "z": -8,
      "name": "Rock_Magma_Cooled",
      "rotation": 1
    },
    {
      "x": -7,
      "y": 20,
      "z": -8,
      "name": "Plant_Moss_Rug_Pink",
      "support": 15
    },
    {
      "x": -7,
      "y": 15,
      "z": -7,
      "name": "Rock_Magma_Cooled",
      "rotation": 1
    },
    {
      "x": -7,
      "y": 16,
      "z": -7,
      "name": "Rock_Magma_Cooled",
      "rotation": 1
    },
    {
      "x": -7,
      "y": 17,
      "z": -7,
      "name": "Rock_Magma_Cooled",
      "rotation": 1
    },
    {
      "x": -7,
      "y": 18,
      "z": -7,
      "name": "Rock_Magma_Cooled",
      "rotation": 1
    },
    {
      "x": -7,
      "y": 19,
      "z": -7,
      "name": "Rock_Magma_Cooled",
      "rotation": 1
    },
    {
      "x": -7,
      "y": 20,
      "z": -7,
      "name": "Plant_Moss_Rug_Pink",
      "support": 15
    },
    {
      "x": -7,
      "y": 15,
      "z": -6,
      "name": "Ore_Adamantite_Magma_Cracked",
      "rotation": 1
    },
    {
      "x": -7,
      "y": 16,
      "z": -6,
      "name": "Rock_Magma_Cooled",
      "rotation": 1
    },
    {
      "x": -7,
      "y": 17,
      "z": -6,
      "name": "Rock_Magma_Cooled",
      "rotation": 1
    },
    {
      "x": -7,
      "y": 18,
      "z": -6,
      "name": "Rock_Magma_Cooled",
      "rotation": 1
    },
    {
      "x": -7,
      "y": 19,
      "z": -6,
      "name": "Plant_Moss_Rug_Pink",
      "support": 15
    },
    {
      "x": -7,
      "y": 15,
      "z": -5,
      "name": "Ore_Adamantite_Magma_Cracked",
      "rotation": 1
    },
    {
      "x": -7,
      "y": 16,
      "z": -5,
      "name": "Rock_Magma_Cooled",
      "rotation": 1
    },
    {
      "x": -7,
      "y": 17,
      "z": -5,
      "name": "Plant_Vine_Wall_Poisoned",
      "support": 15
    },
    {
      "x": -7,
      "y": 16,
      "z": -4,
      "name": "Plant_Vine_Wall_Poisoned",
      "support": 15
    },
    {
      "x": -7,
      "y": 0,
      "z": -2,
      "name": "Soil_Ash"
    },
    {
      "x": -7,
      "y": 0,
      "z": -1,
      "name": "Soil_Sand_Ashen"
    },
    {
      "x": -7,
      "y": 0,
      "z": 0,
      "name": "Soil_Ash"
    },
    {
      "x": -7,
      "y": 24,
      "z": 4,
      "name": "Plant_Vine_Wall_Poisoned",
      "support": 15,
      "rotation": 3
    },
    {
      "x": -7,
      "y": 25,
      "z": 4,
      "name": "Plant_Vine_Wall_Poisoned",
      "support": 15,
      "rotation": 3
    },
    {
      "x": -7,
      "y": 26,
      "z": 4,
      "name": "Plant_Vine_Wall_Poisoned",
      "support": 15,
      "rotation": 3
    },
    {
      "x": -7,
      "y": 27,
      "z": 5,
      "name": "Plant_Vine_Wall_Poisoned",
      "support": 15,
      "rotation": 3
    },
    {
      "x": -7,
      "y": 28,
      "z": 6,
      "name": "Rock_Magma_Cooled",
      "rotation": 1
    },
    {
      "x": -7,
      "y": 29,
      "z": 6,
      "name": "Rock_Magma_Cooled",
      "rotation": 1
    },
    {
      "x": -7,
      "y": 30,
      "z": 6,
      "name": "Rock_Magma_Cooled",
      "rotation": 1
    },
    {
      "x": -7,
      "y": 31,
      "z": 6,
      "name": "Rock_Magma_Cooled",
      "rotation": 1
    },
    {
      "x": -7,
      "y": 32,
      "z": 6,
      "name": "Plant_Moss_Rug_Pink",
      "support": 15
    },
    {
      "x": -6,
      "y": 15,
      "z": -8,
      "name": "Plant_Vine_Wall_Poisoned",
      "support": 15,
      "rotation": 2
    },
    {
      "x": -6,
      "y": 15,
      "z": -7,
      "name": "Rock_Magma_Cooled",
      "rotation": 1
    },
    {
      "x": -6,
      "y": 16,
      "z": -7,
      "name": "Rock_Magma_Cooled",
      "rotation": 1
    },
    {
      "x": -6,
      "y": 17,
      "z": -7,
      "name": "Rock_Magma_Cooled",
      "rotation": 1
    },
    {
      "x": -6,
      "y": 18,
      "z": -7,
      "name": "Plant_Moss_Rug_Pink",
      "support": 15
    },
    {
      "x": -6,
      "y": 14,
      "z": -6,
      "name": "Ore_Adamantite_Magma_Cracked",
      "rotation": 1
    },
    {
      "x": -6,
      "y": 15,
      "z": -6,
      "name": "Rock_Magma_Cooled",
      "rotation": 1
    },
    {
      "x": -6,
      "y": 16,
      "z": -6,
      "name": "Ore_Adamantite_Magma_Cracked",
      "rotation": 1
    },
    {
      "x": -6,
      "y": 17,
      "z": -6,
      "name": "Plant_Moss_Rug_Pink",
      "support": 15
    },
    {
      "x": -6,
      "y": 13,
      "z": -5,
      "name": "Ore_Adamantite_Magma_Cracked",
      "rotation": 1
    },
    {
      "x": -6,
      "y": 14,
      "z": -5,
      "name": "Rock_Magma_Cooled",
      "rotation": 1
    },
    {
      "x": -6,
      "y": 15,
      "z": -5,
      "name": "Ore_Adamantite_Magma_Cracked",
      "rotation": 1
    },
    {
      "x": -6,
      "y": 16,
      "z": -5,
      "name": "Ore_Adamantite_Magma_Cracked",
      "rotation": 1
    },
    {
      "x": -6,
      "y": 17,
      "z": -5,
      "name": "Plant_Moss_Rug_Pink",
      "support": 15
    },
    {
      "x": -6,
      "y": 14,
      "z": -4,
      "name": "Rock_Magma_Cooled",
      "rotation": 1
    },
    {
      "x": -6,
      "y": 15,
      "z": -4,
      "name": "Rock_Magma_Cooled",
      "rotation": 1
    },
    {
      "x": -6,
      "y": 16,
      "z": -4,
      "name": "Plant_Moss_Rug_Pink",
      "support": 15
    },
    {
      "x": -6,
      "y": 0,
      "z": -3,
      "name": "Soil_Sand_Ashen"
    },
    {
      "x": -6,
      "y": 15,
      "z": -3,
      "name": "Rock_Magma_Cooled"
    },
    {
      "x": -6,
      "y": 0,
      "z": -2,
      "name": "Soil_Sand_Ashen"
    },
    {
      "x": -6,
      "y": 1,
      "z": -2,
      "name": "Soil_Ash"
    },
    {
      "x": -6,
      "y": 15,
      "z": -2,
      "name": "Rock_Magma_Cooled"
    },
    {
      "x": -6,
      "y": 16,
      "z": -2,
      "name": "Ore_Adamantite_Magma_Cracked"
    },
    {
      "x": -6,
      "y": 0,
      "z": -1,
      "name": "Soil_Ash"
    },
    {
      "x": -6,
      "y": 1,
      "z": -1,
      "name": "Soil_Ash"
    },
    {
      "x": -6,
      "y": 0,
      "z": 0,
      "name": "Soil_Ash"
    },
    {
      "x": -6,
      "y": 1,
      "z": 0,
      "name": "Soil_Ash"
    },
    {
      "x": -6,
      "y": 0,
      "z": 1,
      "name": "Soil_Ash"
    },
    {
      "x": -6,
      "y": 19,
      "z": 1,
      "name": "Plant_Vine_Wall_Poisoned",
      "support": 15,
      "rotation": 3
    },
    {
      "x": -6,
      "y": 20,
      "z": 2,
      "name": "Plant_Vine_Wall_Poisoned",
      "support": 15,
      "rotation": 3
    },
    {
      "x": -6,
      "y": 21,
      "z": 3,
      "name": "Rock_Magma_Cooled",
      "rotation": 1
    },
    {
      "x": -6,
      "y": 22,
      "z": 3,
      "name": "Ore_Adamantite_Magma_Cracked",
      "rotation": 1
    },
    {
      "x": -6,
      "y": 23,
      "z": 3,
      "name": "Rock_Magma_Cooled",
      "rotation": 1
    },
    {
      "x": -6,
      "y": 24,
      "z": 3,
      "name": "Rock_Magma_Cooled",
      "rotation": 1
    },
    {
      "x": -6,
      "y": 25,
      "z": 3,
      "name": "Plant_Moss_Rug_Pink",
      "support": 15
    },
    {
      "x": -6,
      "y": 0,
      "z": 4,
      "name": "Soil_Ash"
    },
    {
      "x": -6,
      "y": 23,
      "z": 4,
      "name": "Rock_Magma_Cooled",
      "rotation": 1
    },
    {
      "x": -6,
      "y": 24,
      "z": 4,
      "name": "Rock_Magma_Cooled",
      "rotation": 1
    },
    {
      "x": -6,
      "y": 25,
      "z": 4,
      "name": "Rock_Magma_Cooled",
      "rotation": 1
    },
    {
      "x": -6,
      "y": 26,
      "z": 4,
      "name": "Rock_Magma_Cooled",
      "rotation": 1
    },
    {
      "x": -6,
      "y": 27,
      "z": 4,
      "name": "Plant_Moss_Rug_Pink",
      "support": 15
    },
    {
      "x": -6,
      "y": 0,
      "z": 5,
      "name": "Soil_Ash"
    },
    {
      "x": -6,
      "y": 25,
      "z": 5,
      "name": "Ore_Adamantite_Magma_Cracked",
      "rotation": 1
    },
    {
      "x": -6,
      "y": 26,
      "z": 5,
      "name": "Rock_Magma_Cooled",
      "rotation": 1
    },
    {
      "x": -6,
      "y": 27,
      "z": 5,
      "name": "Rock_Magma_Cooled",
      "rotation": 1
    },
    {
      "x": -6,
      "y": 28,
      "z": 5,
      "name": "Rock_Magma_Cooled",
      "rotation": 1
    },
    {
      "x": -6,
      "y": 29,
      "z": 5,
      "name": "Plant_Moss_Rug_Pink",
      "support": 15
    },
    {
      "x": -6,
      "y": 0,
      "z": 6,
      "name": "Soil_Ash"
    },
    {
      "x": -6,
      "y": 27,
      "z": 6,
      "name": "Rock_Magma_Cooled",
      "rotation": 1
    },
    {
      "x": -6,
      "y": 28,
      "z": 6,
      "name": "Rock_Magma_Cooled",
      "rotation": 1
    },
    {
      "x": -6,
      "y": 29,
      "z": 6,
      "name": "Ore_Adamantite_Magma_Cracked",
      "rotation": 1
    },
    {
      "x": -6,
      "y": 30,
      "z": 6,
      "name": "Plant_Moss_Rug_Pink",
      "support": 15
    },
    {
      "x": -6,
      "y": 28,
      "z": 7,
      "name": "Plant_Vine_Wall_Poisoned",
      "support": 15
    },
    {
      "x": -5,
      "y": 14,
      "z": -7,
      "name": "Plant_Vine_Wall_Poisoned",
      "support": 15,
      "rotation": 2
    },
    {
      "x": -5,
      "y": 13,
      "z": -6,
      "name": "Rock_Magma_Cooled",
      "rotation": 1
    },
    {
      "x": -5,
      "y": 14,
      "z": -6,
      "name": "Rock_Magma_Cooled",
      "rotation": 1
    },
    {
      "x": -5,
      "y": 15,
      "z": -6,
      "name": "Rock_Magma_Cooled",
      "rotation": 1
    },
    {
      "x": -5,
      "y": 16,
      "z": -6,
      "name": "Rock_Magma_Cooled",
      "rotation": 1
    },
    {
      "x": -5,
      "y": 12,
      "z": -5,
      "name": "Ore_Adamantite_Magma_Cracked",
      "rotation": 1
    },
    {
      "x": -5,
      "y": 13,
      "z": -5,
      "name": "Rock_Magma_Cooled",
      "rotation": 1
    },
    {
      "x": -5,
      "y": 14,
      "z": -5,
      "name": "Rock_Magma_Cooled",
      "rotation": 1
    },
    {
      "x": -5,
      "y": 0,
      "z": -4,
      "name": "Soil_Ash"
    },
    {
      "x": -5,
      "y": 11,
      "z": -4,
      "name": "Ore_Adamantite_Magma_Cracked",
      "rotation": 1
    },
    {
      "x": -5,
      "y": 12,
      "z": -4,
      "name": "Rock_Magma_Cooled",
      "rotation": 1
    },
    {
      "x": -5,
      "y": 13,
      "z": -4,
      "name": "Ore_Adamantite_Magma_Cracked",
      "rotation": 1
    },
    {
      "x": -5,
      "y": 14,
      "z": -4,
      "name": "Ore_Adamantite_Magma_Cracked",
      "rotation": 1
    },
    {
      "x": -5,
      "y": 0,
      "z": -3,
      "name": "Soil_Ash"
    },
    {
      "x": -5,
      "y": 1,
      "z": -3,
      "name": "Soil_Ash"
    },
    {
      "x": -5,
      "y": 13,
      "z": -3,
      "name": "Ore_Adamantite_Magma_Cracked",
      "rotation": 1
    },
    {
      "x": -5,
      "y": 14,
      "z": -3,
      "name": "Rock_Magma_Cooled"
    },
    {
      "x": -5,
      "y": 15,
      "z": -3,
      "name": "Rock_Magma_Cooled"
    },
    {
      "x": -5,
      "y": 0,
      "z": -2,
      "name": "Soil_Sand_Ashen"
    },
    {
      "x": -5,
      "y": 1,
      "z": -2,
      "name": "Soil_Ash"
    },
    {
      "x": -5,
      "y": 13,
      "z": -2,
      "name": "Plant_Vine_Wall_Poisoned",
      "support": 15
    },
    {
      "x": -5,
      "y": 0,
      "z": -1,
      "name": "Soil_Ash"
    },
    {
      "x": -5,
      "y": 1,
      "z": -1,
      "name": "Soil_Sand_Ashen"
    },
    {
      "x": -5,
      "y": 2,
      "z": -1,
      "name": "Soil_Ash"
    },
    {
      "x": -5,
      "y": 3,
      "z": -1,
      "name": "Plant_Flower_Poisoned_Orange"
    },
    {
      "x": -5,
      "y": 0,
      "z": 0,
      "name": "Soil_Ash"
    },
    {
      "x": -5,
      "y": 1,
      "z": 0,
      "name": "Soil_Ash"
    },
    {
      "x": -5,
      "y": 15,
      "z": 0,
      "name": "Rock_Magma_Cooled",
      "rotation": 1
    },
    {
      "x": -5,
      "y": 16,
      "z": 0,
      "name": "Ore_Adamantite_Magma_Cracked",
      "rotation": 1
    },
    {
      "x": -5,
      "y": 0,
      "z": 1,
      "name": "Soil_Sand_Ashen"
    },
    {
      "x": -5,
      "y": 1,
      "z": 1,
      "name": "Soil_Ash"
    },
    {
      "x": -5,
      "y": 16,
      "z": 1,
      "name": "Rock_Magma_Cooled",
      "rotation": 1
    },
    {
      "x": -5,
      "y": 17,
      "z": 1,
      "name": "Rock_Magma_Cooled",
      "rotation": 1
    },
    {
      "x": -5,
      "y": 18,
      "z": 1,
      "name": "Rock_Magma_Cooled",
      "rotation": 1
    },
    {
      "x": -5,
      "y": 19,
      "z": 1,
      "name": "Rock_Magma_Cooled",
      "rotation": 1
    },
    {
      "x": -5,
      "y": 0,
      "z": 2,
      "name": "Soil_Ash"
    },
    {
      "x": -5,
      "y": 17,
      "z": 2,
      "name": "Plant_Vine_Wall_Poisoned",
      "support": 15,
      "rotation": 3
    },
    {
      "x": -5,
      "y": 18,
      "z": 2,
      "name": "Rock_Magma_Cooled",
      "rotation": 1
    },
    {
      "x": -5,
      "y": 19,
      "z": 2,
      "name": "Rock_Magma_Cooled",
      "rotation": 1
    },
    {
      "x": -5,
      "y": 20,
      "z": 2,
      "name": "Rock_Magma_Cooled",
      "rotation": 1
    },
    {
      "x": -5,
      "y": 21,
      "z": 2,
      "name": "Rock_Magma_Cooled",
      "rotation": 1
    },
    {
      "x": -5,
      "y": 22,
      "z": 2,
      "name": "Rock_Magma_Cooled",
      "rotation": 1
    },
    {
      "x": -5,
      "y": 23,
      "z": 2,
      "name": "Rock_Magma_Cooled",
      "rotation": 1
    },
    {
      "x": -5,
      "y": 24,
      "z": 2,
      "name": "Ore_Adamantite_Magma_Cracked",
      "rotation": 1
    },
    {
      "x": -5,
      "y": 25,
      "z": 2,
      "name": "Plant_Moss_Rug_Pink",
      "support": 15
    },
    {
      "x": -5,
      "y": 0,
      "z": 3,
      "name": "Soil_Sand_Ashen"
    },
    {
      "x": -5,
      "y": 20,
      "z": 3,
      "name": "Rock_Magma_Cooled",
      "rotation": 1
    },
    {
      "x": -5,
      "y": 21,
      "z": 3,
      "name": "Ore_Adamantite_Magma_Cracked",
      "rotation": 1
    },
    {
      "x": -5,
      "y": 22,
      "z": 3,
      "name": "Rock_Magma_Cooled",
      "rotation": 1
    },
    {
      "x": -5,
      "y": 23,
      "z": 3,
      "name": "Rock_Magma_Cooled",
      "rotation": 1
    },
    {
      "x": -5,
      "y": 24,
      "z": 3,
      "name": "Rock_Magma_Cooled",
      "rotation": 1
    },
    {
      "x": -5,
      "y": 25,
      "z": 3,
      "name": "Ore_Adamantite_Magma_Cracked",
      "rotation": 1
    },
    {
      "x": -5,
      "y": 26,
      "z": 3,
      "name": "Plant_Moss_Rug_Pink",
      "support": 15
    },
    {
      "x": -5,
      "y": 0,
      "z": 4,
      "name": "Soil_Sand_Ashen"
    },
    {
      "x": -5,
      "y": 1,
      "z": 4,
      "name": "Soil_Ash"
    },
    {
      "x": -5,
      "y": 22,
      "z": 4,
      "name": "Rock_Magma_Cooled",
      "rotation": 1
    },
    {
      "x": -5,
      "y": 23,
      "z": 4,
      "name": "Rock_Magma_Cooled",
      "rotation": 1
    },
    {
      "x": -5,
      "y": 24,
      "z": 4,
      "name": "Rock_Magma_Cooled",
      "rotation": 1
    },
    {
      "x": -5,
      "y": 25,
      "z": 4,
      "name": "Ore_Adamantite_Magma_Cracked",
      "rotation": 1
    },
    {
      "x": -5,
      "y": 26,
      "z": 4,
      "name": "Rock_Magma_Cooled",
      "rotation": 1
    },
    {
      "x": -5,
      "y": 27,
      "z": 4,
      "name": "Plant_Moss_Rug_Pink",
      "support": 15
    },
    {
      "x": -5,
      "y": 0,
      "z": 5,
      "name": "Soil_Ash"
    },
    {
      "x": -5,
      "y": 1,
      "z": 5,
      "name": "Soil_Ash"
    },
    {
      "x": -5,
      "y": 24,
      "z": 5,
      "name": "Rock_Magma_Cooled",
      "rotation": 1
    },
    {
      "x": -5,
      "y": 25,
      "z": 5,
      "name": "Rock_Magma_Cooled",
      "rotation": 1
    },
    {
      "x": -5,
      "y": 26,
      "z": 5,
      "name": "Rock_Magma_Cooled",
      "rotation": 1
    },
    {
      "x": -5,
      "y": 27,
      "z": 5,
      "name": "Plant_Moss_Rug_Pink",
      "support": 15
    },
    {
      "x": -5,
      "y": 0,
      "z": 6,
      "name": "Soil_Sand_Ashen"
    },
    {
      "x": -5,
      "y": 1,
      "z": 6,
      "name": "Soil_Ash"
    },
    {
      "x": -5,
      "y": 25,
      "z": 6,
      "name": "Plant_Vine_Wall_Poisoned",
      "support": 15
    },
    {
      "x": -5,
      "y": 0,
      "z": 7,
      "name": "Soil_Sand_Ashen"
    },
    {
      "x": -4,
      "y": 0,
      "z": -7,
      "name": "Soil_Sand_Ashen"
    },
    {
      "x": -4,
      "y": 12,
      "z": -7,
      "name": "Plant_Vine_Wall_Poisoned",
      "support": 15,
      "rotation": 2
    },
    {
      "x": -4,
      "y": 13,
      "z": -7,
      "name": "Plant_Vine_Wall_Poisoned",
      "support": 15,
      "rotation": 2
    },
    {
      "x": -4,
      "y": 0,
      "z": -6,
      "name": "Soil_Ash"
    },
    {
      "x": -4,
      "y": 12,
      "z": -6,
      "name": "Ore_Adamantite_Magma_Cracked",
      "rotation": 1
    },
    {
      "x": -4,
      "y": 13,
      "z": -6,
      "name": "Rock_Magma_Cooled",
      "rotation": 1
    },
    {
      "x": -4,
      "y": 0,
      "z": -5,
      "name": "Soil_Ash"
    },
    {
      "x": -4,
      "y": 10,
      "z": -5,
      "name": "Rock_Magma_Cooled",
      "rotation": 1
    },
    {
      "x": -4,
      "y": 11,
      "z": -5,
      "name": "Rock_Magma_Cooled",
      "rotation": 1
    },
    {
      "x": -4,
      "y": 12,
      "z": -5,
      "name": "Rock_Magma_Cooled",
      "rotation": 1
    },
    {
      "x": -4,
      "y": 13,
      "z": -5,
      "name": "Rock_Magma_Cooled",
      "rotation": 1
    },
    {
      "x": -4,
      "y": 14,
      "z": -5,
      "name": "Rock_Magma_Cooled",
      "rotation": 1
    },
    {
      "x": -4,
      "y": 0,
      "z": -4,
      "name": "Soil_Ash"
    },
    {
      "x": -4,
      "y": 1,
      "z": -4,
      "name": "Soil_Ash"
    },
    {
      "x": -4,
      "y": 10,
      "z": -4,
      "name": "Rock_Magma_Cooled",
      "rotation": 1
    },
    {
      "x": -4,
      "y": 11,
      "z": -4,
      "name": "Rock_Magma_Cooled",
      "rotation": 1
    },
    {
      "x": -4,
      "y": 12,
      "z": -4,
      "name": "Rock_Magma_Cooled",
      "rotation": 1
    },
    {
      "x": -4,
      "y": 13,
      "z": -4,
      "name": "Rock_Magma_Cooled",
      "rotation": 1
    },
    {
      "x": -4,
      "y": 0,
      "z": -3,
      "name": "Soil_Ash"
    },
    {
      "x": -4,
      "y": 1,
      "z": -3,
      "name": "Soil_Sand_Ashen"
    },
    {
      "x": -4,
      "y": 9,
      "z": -3,
      "name": "Rock_Magma_Cooled",
      "rotation": 1
    },
    {
      "x": -4,
      "y": 10,
      "z": -3,
      "name": "Rock_Magma_Cooled",
      "rotation": 1
    },
    {
      "x": -4,
      "y": 11,
      "z": -3,
      "name": "Rock_Magma_Cooled",
      "rotation": 1
    },
    {
      "x": -4,
      "y": 12,
      "z": -3,
      "name": "Ore_Adamantite_Magma",
      "rotation": 1
    },
    {
      "x": -4,
      "y": 13,
      "z": -3,
      "name": "Rock_Magma_Cooled",
      "rotation": 1
    },
    {
      "x": -4,
      "y": 14,
      "z": -3,
      "name": "Ore_Adamantite_Magma_Cracked"
    },
    {
      "x": -4,
      "y": 0,
      "z": -2,
      "name": "Soil_Sand_Ashen"
    },
    {
      "x": -4,
      "y": 1,
      "z": -2,
      "name": "Soil_Ash"
    },
    {
      "x": -4,
      "y": 2,
      "z": -2,
      "name": "Soil_Ash"
    },
    {
      "x": -4,
      "y": 10,
      "z": -2,
      "name": "Rock_Magma_Cooled",
      "rotation": 1
    },
    {
      "x": -4,
      "y": 11,
      "z": -2,
      "name": "Ore_Adamantite_Magma_Cracked",
      "rotation": 1
    },
    {
      "x": -4,
      "y": 12,
      "z": -2,
      "name": "Plant_Vine_Wall_Poisoned",
      "support": 15,
      "rotation": 3
    },
    {
      "x": -4,
      "y": 14,
      "z": -2,
      "name": "Plant_Vine_Wall_Poisoned",
      "support": 15,
      "rotation": 3
    },
    {
      "x": -4,
      "y": 0,
      "z": -1,
      "name": "Soil_Sand_Ashen"
    },
    {
      "x": -4,
      "y": 1,
      "z": -1,
      "name": "Soil_Ash"
    },
    {
      "x": -4,
      "y": 2,
      "z": -1,
      "name": "Soil_Sand_Ashen"
    },
    {
      "x": -4,
      "y": 3,
      "z": -1,
      "name": "Plant_Flower_Poisoned_Orange"
    },
    {
      "x": -4,
      "y": 12,
      "z": -1,
      "name": "Plant_Vine_Wall_Poisoned",
      "support": 15,
      "rotation": 3
    },
    {
      "x": -4,
      "y": 0,
      "z": 0,
      "name": "Soil_Sand_Ashen"
    },
    {
      "x": -4,
      "y": 1,
      "z": 0,
      "name": "Soil_Ash"
    },
    {
      "x": -4,
      "y": 2,
      "z": 0,
      "name": "Soil_Ash"
    },
    {
      "x": -4,
      "y": 13,
      "z": 0,
      "name": "Rock_Magma_Cooled",
      "rotation": 1
    },
    {
      "x": -4,
      "y": 14,
      "z": 0,
      "name": "Rock_Magma_Cooled",
      "rotation": 1
    },
    {
      "x": -4,
      "y": 15,
      "z": 0,
      "name": "Ore_Adamantite_Magma_Cracked",
      "rotation": 1
    },
    {
      "x": -4,
      "y": 16,
      "z": 0,
      "name": "Ore_Adamantite_Magma_Cracked",
      "rotation": 1
    },
    {
      "x": -4,
      "y": 17,
      "z": 0,
      "name": "Rock_Magma_Cooled",
      "rotation": 1
    },
    {
      "x": -4,
      "y": 18,
      "z": 0,
      "name": "Rock_Magma_Cooled",
      "rotation": 1
    },
    {
      "x": -4,
      "y": 0,
      "z": 1,
      "name": "Soil_Ash"
    },
    {
      "x": -4,
      "y": 1,
      "z": 1,
      "name": "Soil_Ash"
    },
    {
      "x": -4,
      "y": 14,
      "z": 1,
      "name": "Rock_Magma_Cooled",
      "rotation": 1
    },
    {
      "x": -4,
      "y": 15,
      "z": 1,
      "name": "Rock_Magma_Cooled",
      "rotation": 1
    },
    {
      "x": -4,
      "y": 16,
      "z": 1,
      "name": "Rock_Magma_Cooled",
      "rotation": 1
    },
    {
      "x": -4,
      "y": 17,
      "z": 1,
      "name": "Rock_Magma_Cooled",
      "rotation": 1
    },
    {
      "x": -4,
      "y": 18,
      "z": 1,
      "name": "Rock_Magma_Cooled",
      "rotation": 1
    },
    {
      "x": -4,
      "y": 19,
      "z": 1,
      "name": "Rock_Magma_Cooled",
      "rotation": 1
    },
    {
      "x": -4,
      "y": 20,
      "z": 1,
      "name": "Rock_Magma_Cooled",
      "rotation": 1
    },
    {
      "x": -4,
      "y": 21,
      "z": 1,
      "name": "Rock_Magma_Cooled",
      "rotation": 1
    },
    {
      "x": -4,
      "y": 22,
      "z": 1,
      "name": "Rock_Magma_Cooled",
      "rotation": 1
    },
    {
      "x": -4,
      "y": 23,
      "z": 1,
      "name": "Plant_Moss_Rug_Pink",
      "support": 15
    },
    {
      "x": -4,
      "y": 0,
      "z": 2,
      "name": "Soil_Ash"
    },
    {
      "x": -4,
      "y": 1,
      "z": 2,
      "name": "Soil_Sand_Ashen"
    },
    {
      "x": -4,
      "y": 17,
      "z": 2,
      "name": "Ore_Adamantite_Magma_Cracked",
      "rotation": 1
    },
    {
      "x": -4,
      "y": 18,
      "z": 2,
      "name": "Rock_Magma_Cooled",
      "rotation": 1
    },
    {
      "x": -4,
      "y": 19,
      "z": 2,
      "name": "Rock_Magma_Cooled",
      "rotation": 1
    },
    {
      "x": -4,
      "y": 20,
      "z": 2,
      "name": "Ore_Adamantite_Magma_Cracked",
      "rotation": 1
    },
    {
      "x": -4,
      "y": 21,
      "z": 2,
      "name": "Rock_Magma_Cooled",
      "rotation": 1
    },
    {
      "x": -4,
      "y": 22,
      "z": 2,
      "name": "Rock_Magma_Cooled",
      "rotation": 1
    },
    {
      "x": -4,
      "y": 23,
      "z": 2,
      "name": "Rock_Magma_Cooled",
      "rotation": 1
    },
    {
      "x": -4,
      "y": 24,
      "z": 2,
      "name": "Plant_Moss_Rug_Pink",
      "support": 15
    },
    {
      "x": -4,
      "y": 0,
      "z": 3,
      "name": "Soil_Ash"
    },
    {
      "x": -4,
      "y": 1,
      "z": 3,
      "name": "Soil_Sand_Ashen"
    },
    {
      "x": -4,
      "y": 19,
      "z": 3,
      "name": "Ore_Adamantite_Magma_Cracked",
      "rotation": 1
    },
    {
      "x": -4,
      "y": 20,
      "z": 3,
      "name": "Rock_Magma_Cooled",
      "rotation": 1
    },
    {
      "x": -4,
      "y": 21,
      "z": 3,
      "name": "Rock_Magma_Cooled",
      "rotation": 1
    },
    {
      "x": -4,
      "y": 22,
      "z": 3,
      "name": "Plant_Vine_Wall_Poisoned",
      "support": 15
    },
    {
      "x": -4,
      "y": 0,
      "z": 4,
      "name": "Soil_Sand_Ashen"
    },
    {
      "x": -4,
      "y": 1,
      "z": 4,
      "name": "Soil_Sand_Ashen"
    },
    {
      "x": -4,
      "y": 0,
      "z": 5,
      "name": "Soil_Ash"
    },
    {
      "x": -4,
      "y": 1,
      "z": 5,
      "name": "Soil_Ash"
    },
    {
      "x": -4,
      "y": 2,
      "z": 5,
      "name": "Soil_Ash"
    },
    {
      "x": -4,
      "y": 0,
      "z": 6,
      "name": "Soil_Ash"
    },
    {
      "x": -4,
      "y": 1,
      "z": 6,
      "name": "Soil_Sand_Ashen"
    },
    {
      "x": -4,
      "y": 0,
      "z": 7,
      "name": "Soil_Sand_Ashen"
    },
    {
      "x": -4,
      "y": 1,
      "z": 7,
      "name": "Soil_Sand_Ashen"
    },
    {
      "x": -4,
      "y": 0,
      "z": 8,
      "name": "Soil_Sand_Ashen"
    },
    {
      "x": -3,
      "y": 0,
      "z": -8,
      "name": "Soil_Sand_Ashen"
    },
    {
      "x": -3,
      "y": 0,
      "z": -7,
      "name": "Soil_Sand_Ashen"
    },
    {
      "x": -3,
      "y": 1,
      "z": -7,
      "name": "Soil_Sand_Ashen"
    },
    {
      "x": -3,
      "y": 0,
      "z": -6,
      "name": "Soil_Ash"
    },
    {
      "x": -3,
      "y": 1,
      "z": -6,
      "name": "Soil_Sand_Ashen"
    },
    {
      "x": -3,
      "y": 11,
      "z": -6,
      "name": "Plant_Vine_Wall_Poisoned",
      "support": 15,
      "rotation": 2
    },
    {
      "x": -3,
      "y": 0,
      "z": -5,
      "name": "Soil_Ash"
    },
    {
      "x": -3,
      "y": 1,
      "z": -5,
      "name": "Soil_Sand_Ashen"
    },
    {
      "x": -3,
      "y": 8,
      "z": -5,
      "name": "Rock_Magma_Cooled",
      "rotation": 1
    },
    {
      "x": -3,
      "y": 9,
      "z": -5,
      "name": "Rock_Magma_Cooled",
      "rotation": 1
    },
    {
      "x": -3,
      "y": 10,
      "z": -5,
      "name": "Rock_Magma_Cooled",
      "rotation": 1
    },
    {
      "x": -3,
      "y": 11,
      "z": -5,
      "name": "Rock_Magma_Cooled",
      "rotation": 1
    },
    {
      "x": -3,
      "y": 12,
      "z": -5,
      "name": "Ore_Adamantite_Magma_Cracked",
      "rotation": 1
    },
    {
      "x": -3,
      "y": 0,
      "z": -4,
      "name": "Soil_Ash"
    },
    {
      "x": -3,
      "y": 1,
      "z": -4,
      "name": "Soil_Sand_Ashen"
    },
    {
      "x": -3,
      "y": 8,
      "z": -4,
      "name": "Rock_Magma_Cooled",
      "rotation": 1
    },
    {
      "x": -3,
      "y": 9,
      "z": -4,
      "name": "Rock_Magma_Cooled",
      "rotation": 1
    },
    {
      "x": -3,
      "y": 10,
      "z": -4,
      "name": "Rock_Magma_Cooled",
      "rotation": 1
    },
    {
      "x": -3,
      "y": 11,
      "z": -4,
      "name": "Rock_Magma_Cooled",
      "rotation": 1
    },
    {
      "x": -3,
      "y": 12,
      "z": -4,
      "name": "Ore_Adamantite_Magma_Cracked",
      "rotation": 1
    },
    {
      "x": -3,
      "y": 13,
      "z": -4,
      "name": "Plant_Crop_Mushroom_Glowing_Purple"
    },
    {
      "x": -3,
      "y": 0,
      "z": -3,
      "name": "Soil_Sand_Ashen"
    },
    {
      "x": -3,
      "y": 1,
      "z": -3,
      "name": "Soil_Ash"
    },
    {
      "x": -3,
      "y": 2,
      "z": -3,
      "name": "Soil_Sand_Ashen"
    },
    {
      "x": -3,
      "y": 3,
      "z": -3,
      "name": "Plant_Flower_Common_Poisoned2"
    },
    {
      "x": -3,
      "y": 9,
      "z": -3,
      "name": "Rock_Magma_Cooled",
      "rotation": 1
    },
    {
      "x": -3,
      "y": 10,
      "z": -3,
      "name": "Rock_Magma_Cooled",
      "rotation": 1
    },
    {
      "x": -3,
      "y": 11,
      "z": -3,
      "name": "Rock_Magma_Cooled",
      "rotation": 1
    },
    {
      "x": -3,
      "y": 12,
      "z": -3,
      "name": "Rock_Magma_Cooled",
      "rotation": 1
    },
    {
      "x": -3,
      "y": 13,
      "z": -3,
      "name": "Rock_Magma_Cooled",
      "rotation": 1
    },
    {
      "x": -3,
      "y": 0,
      "z": -2,
      "name": "Soil_Ash"
    },
    {
      "x": -3,
      "y": 1,
      "z": -2,
      "name": "Soil_Ash"
    },
    {
      "x": -3,
      "y": 2,
      "z": -2,
      "name": "Soil_Sand_Ashen"
    },
    {
      "x": -3,
      "y": 10,
      "z": -2,
      "name": "Rock_Magma_Cooled",
      "rotation": 1
    },
    {
      "x": -3,
      "y": 11,
      "z": -2,
      "name": "Rock_Magma_Cooled",
      "rotation": 1
    },
    {
      "x": -3,
      "y": 12,
      "z": -2,
      "name": "Rock_Magma_Cooled",
      "rotation": 1
    },
    {
      "x": -3,
      "y": 13,
      "z": -2,
      "name": "Ore_Adamantite_Magma_Cracked",
      "rotation": 1
    },
    {
      "x": -3,
      "y": 14,
      "z": -2,
      "name": "Rock_Magma_Cooled",
      "rotation": 1
    },
    {
      "x": -3,
      "y": 0,
      "z": -1,
      "name": "Soil_Sand_Ashen"
    },
    {
      "x": -3,
      "y": 1,
      "z": -1,
      "name": "Soil_Sand_Ashen"
    },
    {
      "x": -3,
      "y": 2,
      "z": -1,
      "name": "Soil_Sand_Ashen"
    },
    {
      "x": -3,
      "y": 3,
      "z": -1,
      "name": "Plant_Flower_Bushy_Poisoned"
    },
    {
      "x": -3,
      "y": 11,
      "z": -1,
      "name": "Ore_Adamantite_Magma_Cracked",
      "rotation": 1
    },
    {
      "x": -3,
      "y": 12,
      "z": -1,
      "name": "Rock_Magma_Cooled",
      "rotation": 1
    },
    {
      "x": -3,
      "y": 13,
      "z": -1,
      "name": "Ore_Adamantite_Magma_Cracked",
      "rotation": 1
    },
    {
      "x": -3,
      "y": 14,
      "z": -1,
      "name": "Rock_Magma_Cooled",
      "rotation": 1
    },
    {
      "x": -3,
      "y": 15,
      "z": -1,
      "name": "Rock_Magma_Cooled",
      "rotation": 1
    },
    {
      "x": -3,
      "y": 16,
      "z": -1,
      "name": "Plant_Vine_Wall_Poisoned",
      "support": 15,
      "rotation": 3
    },
    {
      "x": -3,
      "y": 0,
      "z": 0,
      "name": "Soil_Sand_Ashen"
    },
    {
      "x": -3,
      "y": 1,
      "z": 0,
      "name": "Soil_Sand_Ashen"
    },
    {
      "x": -3,
      "y": 2,
      "z": 0,
      "name": "Soil_Ash"
    },
    {
      "x": -3,
      "y": 12,
      "z": 0,
      "name": "Rock_Magma_Cooled",
      "rotation": 1
    },
    {
      "x": -3,
      "y": 13,
      "z": 0,
      "name": "Rock_Magma_Cooled",
      "rotation": 1
    },
    {
      "x": -3,
      "y": 14,
      "z": 0,
      "name": "Rock_Magma_Cooled",
      "rotation": 1
    },
    {
      "x": -3,
      "y": 15,
      "z": 0,
      "name": "Ore_Adamantite_Magma_Cracked",
      "rotation": 1
    },
    {
      "x": -3,
      "y": 16,
      "z": 0,
      "name": "Rock_Magma_Cooled",
      "rotation": 1
    },
    {
      "x": -3,
      "y": 17,
      "z": 0,
      "name": "Rock_Magma_Cooled",
      "rotation": 1
    },
    {
      "x": -3,
      "y": 18,
      "z": 0,
      "name": "Rock_Magma_Cooled",
      "rotation": 1
    },
    {
      "x": -3,
      "y": 0,
      "z": 1,
      "name": "Soil_Ash"
    },
    {
      "x": -3,
      "y": 1,
      "z": 1,
      "name": "Soil_Sand_Ashen"
    },
    {
      "x": -3,
      "y": 2,
      "z": 1,
      "name": "Soil_Ash"
    },
    {
      "x": -3,
      "y": 3,
      "z": 1,
      "name": "Plant_Flower_Bushy_Poisoned"
    },
    {
      "x": -3,
      "y": 14,
      "z": 1,
      "name": "Rock_Magma_Cooled",
      "rotation": 1
    },
    {
      "x": -3,
      "y": 15,
      "z": 1,
      "name": "Rock_Magma_Cooled",
      "rotation": 1
    },
    {
      "x": -3,
      "y": 16,
      "z": 1,
      "name": "Rock_Magma_Cooled",
      "rotation": 1
    },
    {
      "x": -3,
      "y": 17,
      "z": 1,
      "name": "Rock_Magma_Cooled",
      "rotation": 1
    },
    {
      "x": -3,
      "y": 18,
      "z": 1,
      "name": "Rock_Magma_Cooled",
      "rotation": 1
    },
    {
      "x": -3,
      "y": 19,
      "z": 1,
      "name": "Ore_Adamantite_Magma_Cracked",
      "rotation": 1
    },
    {
      "x": -3,
      "y": 20,
      "z": 1,
      "name": "Rock_Magma_Cooled",
      "rotation": 1
    },
    {
      "x": -3,
      "y": 21,
      "z": 1,
      "name": "Rock_Magma_Cooled",
      "rotation": 1
    },
    {
      "x": -3,
      "y": 0,
      "z": 2,
      "name": "Soil_Sand_Ashen"
    },
    {
      "x": -3,
      "y": 1,
      "z": 2,
      "name": "Soil_Ash"
    },
    {
      "x": -3,
      "y": 2,
      "z": 2,
      "name": "Plant_Flower_Bushy_Poisoned"
    },
    {
      "x": -3,
      "y": 16,
      "z": 2,
      "name": "Ore_Adamantite_Magma_Cracked",
      "rotation": 1
    },
    {
      "x": -3,
      "y": 17,
      "z": 2,
      "name": "Rock_Magma_Cooled",
      "rotation": 1
    },
    {
      "x": -3,
      "y": 18,
      "z": 2,
      "name": "Ore_Adamantite_Magma_Cracked",
      "rotation": 1
    },
    {
      "x": -3,
      "y": 19,
      "z": 2,
      "name": "Rock_Magma_Cooled",
      "rotation": 1
    },
    {
      "x": -3,
      "y": 20,
      "z": 2,
      "name": "Ore_Adamantite_Magma_Cracked",
      "rotation": 1
    },
    {
      "x": -3,
      "y": 21,
      "z": 2,
      "name": "Rock_Magma_Cooled",
      "rotation": 1
    },
    {
      "x": -3,
      "y": 22,
      "z": 2,
      "name": "Rock_Magma_Cooled",
      "rotation": 1
    },
    {
      "x": -3,
      "y": 23,
      "z": 2,
      "name": "Plant_Moss_Rug_Pink",
      "support": 15
    },
    {
      "x": -3,
      "y": 0,
      "z": 3,
      "name": "Soil_Ash"
    },
    {
      "x": -3,
      "y": 1,
      "z": 3,
      "name": "Soil_Ash"
    },
    {
      "x": -3,
      "y": 2,
      "z": 3,
      "name": "Plant_Flower_Poisoned_Orange"
    },
    {
      "x": -3,
      "y": 17,
      "z": 3,
      "name": "Ore_Adamantite_Magma_Cracked",
      "rotation": 1
    },
    {
      "x": -3,
      "y": 18,
      "z": 3,
      "name": "Rock_Magma_Cooled",
      "rotation": 1
    },
    {
      "x": -3,
      "y": 19,
      "z": 3,
      "name": "Rock_Magma_Cooled",
      "rotation": 1
    },
    {
      "x": -3,
      "y": 20,
      "z": 3,
      "name": "Plant_Vine_Wall_Poisoned",
      "support": 15
    },
    {
      "x": -3,
      "y": 21,
      "z": 3,
      "name": "Plant_Vine_Wall_Poisoned",
      "support": 15
    },
    {
      "x": -3,
      "y": 0,
      "z": 4,
      "name": "Soil_Ash"
    },
    {
      "x": -3,
      "y": 1,
      "z": 4,
      "name": "Soil_Sand_Ashen"
    },
    {
      "x": -3,
      "y": 2,
      "z": 4,
      "name": "Soil_Ash"
    },
    {
      "x": -3,
      "y": 0,
      "z": 5,
      "name": "Soil_Ash"
    },
    {
      "x": -3,
      "y": 1,
      "z": 5,
      "name": "Soil_Ash"
    },
    {
      "x": -3,
      "y": 2,
      "z": 5,
      "name": "Soil_Sand_Ashen"
    },
    {
      "x": -3,
      "y": 0,
      "z": 6,
      "name": "Soil_Sand_Ashen"
    },
    {
      "x": -3,
      "y": 1,
      "z": 6,
      "name": "Soil_Ash"
    },
    {
      "x": -3,
      "y": 2,
      "z": 6,
      "name": "Soil_Ash"
    },
    {
      "x": -3,
      "y": 0,
      "z": 7,
      "name": "Soil_Ash"
    },
    {
      "x": -3,
      "y": 1,
      "z": 7,
      "name": "Soil_Sand_Ashen"
    },
    {
      "x": -3,
      "y": 0,
      "z": 8,
      "name": "Soil_Sand_Ashen"
    },
    {
      "x": -3,
      "y": 1,
      "z": 8,
      "name": "Soil_Sand_Ashen"
    },
    {
      "x": -3,
      "y": 0,
      "z": 9,
      "name": "Soil_Ash"
    },
    {
      "x": -2,
      "y": 0,
      "z": -9,
      "name": "Soil_Ash"
    },
    {
      "x": -2,
      "y": 0,
      "z": -8,
      "name": "Soil_Ash"
    },
    {
      "x": -2,
      "y": 1,
      "z": -8,
      "name": "Soil_Ash"
    },
    {
      "x": -2,
      "y": 0,
      "z": -7,
      "name": "Soil_Ash"
    },
    {
      "x": -2,
      "y": 1,
      "z": -7,
      "name": "Soil_Ash"
    },
    {
      "x": -2,
      "y": 0,
      "z": -6,
      "name": "Soil_Ash"
    },
    {
      "x": -2,
      "y": 1,
      "z": -6,
      "name": "Soil_Sand_Ashen"
    },
    {
      "x": -2,
      "y": 2,
      "z": -6,
      "name": "Soil_Ash"
    },
    {
      "x": -2,
      "y": 3,
      "z": -6,
      "name": "Plant_Bramble_Dead_Twisted"
    },
    {
      "x": -2,
      "y": 9,
      "z": -6,
      "name": "Plant_Vine_Wall_Poisoned",
      "support": 15,
      "rotation": 2
    },
    {
      "x": -2,
      "y": 10,
      "z": -6,
      "name": "Plant_Vine_Wall_Poisoned",
      "support": 15,
      "rotation": 2
    },
    {
      "x": -2,
      "y": 0,
      "z": -5,
      "name": "Soil_Sand_Ashen"
    },
    {
      "x": -2,
      "y": 1,
      "z": -5,
      "name": "Soil_Sand_Ashen"
    },
    {
      "x": -2,
      "y": 2,
      "z": -5,
      "name": "Plant_Flower_Poisoned_Orange"
    },
    {
      "x": -2,
      "y": 8,
      "z": -5,
      "name": "Rock_Magma_Cooled",
      "rotation": 1
    },
    {
      "x": -2,
      "y": 9,
      "z": -5,
      "name": "Rock_Magma_Cooled",
      "rotation": 1
    },
    {
      "x": -2,
      "y": 10,
      "z": -5,
      "name": "Rock_Magma_Cooled",
      "rotation": 1
    },
    {
      "x": -2,
      "y": 11,
      "z": -5,
      "name": "Rock_Magma_Cooled",
      "rotation": 1
    },
    {
      "x": -2,
      "y": 0,
      "z": -4,
      "name": "Soil_Sand_Ashen"
    },
    {
      "x": -2,
      "y": 1,
      "z": -4,
      "name": "Soil_Ash"
    },
    {
      "x": -2,
      "y": 2,
      "z": -4,
      "name": "Plant_Crop_Mushroom_Glowing_Purple"
    },
    {
      "x": -2,
      "y": 7,
      "z": -4,
      "name": "Rock_Magma_Cooled",
      "rotation": 1
    },
    {
      "x": -2,
      "y": 8,
      "z": -4,
      "name": "Rock_Magma_Cooled",
      "rotation": 1
    },
    {
      "x": -2,
      "y": 9,
      "z": -4,
      "name": "Ore_Adamantite_Magma_Cracked",
      "rotation": 1
    },
    {
      "x": -2,
      "y": 10,
      "z": -4,
      "name": "Rock_Magma_Cooled",
      "rotation": 1
    },
    {
      "x": -2,
      "y": 11,
      "z": -4,
      "name": "Rock_Magma_Cooled",
      "rotation": 1
    },
    {
      "x": -2,
      "y": 12,
      "z": -4,
      "name": "Plant_Crop_Mushroom_Glowing_Purple"
    },
    {
      "x": -2,
      "y": 0,
      "z": -3,
      "name": "Soil_Ash"
    },
    {
      "x": -2,
      "y": 1,
      "z": -3,
      "name": "Soil_Ash"
    },
    {
      "x": -2,
      "y": 2,
      "z": -3,
      "name": "Plant_Flower_Bushy_Poisoned"
    },
    {
      "x": -2,
      "y": 8,
      "z": -3,
      "name": "Ore_Adamantite_Magma_Cracked",
      "rotation": 1
    },
    {
      "x": -2,
      "y": 9,
      "z": -3,
      "name": "Rock_Magma_Cooled",
      "rotation": 1
    },
    {
      "x": -2,
      "y": 10,
      "z": -3,
      "name": "Rock_Magma_Cooled",
      "rotation": 1
    },
    {
      "x": -2,
      "y": 11,
      "z": -3,
      "name": "Rock_Magma_Cooled",
      "rotation": 1
    },
    {
      "x": -2,
      "y": 12,
      "z": -3,
      "name": "Ore_Adamantite_Magma_Cracked",
      "rotation": 1
    },
    {
      "x": -2,
      "y": 13,
      "z": -3,
      "name": "Ore_Adamantite_Magma_Cracked",
      "rotation": 1
    },
    {
      "x": -2,
      "y": 0,
      "z": -2,
      "name": "Soil_Sand_Ashen"
    },
    {
      "x": -2,
      "y": 1,
      "z": -2,
      "name": "Soil_Ash"
    },
    {
      "x": -2,
      "y": 2,
      "z": -2,
      "name": "Soil_Ash"
    },
    {
      "x": -2,
      "y": 10,
      "z": -2,
      "name": "Rock_Magma_Cooled",
      "rotation": 1
    },
    {
      "x": -2,
      "y": 11,
      "z": -2,
      "name": "Rock_Magma_Cooled",
      "rotation": 1
    },
    {
      "x": -2,
      "y": 12,
      "z": -2,
      "name": "Rock_Magma_Cooled",
      "rotation": 1
    },
    {
      "x": -2,
      "y": 13,
      "z": -2,
      "name": "Rock_Magma_Cooled",
      "rotation": 1
    },
    {
      "x": -2,
      "y": 14,
      "z": -2,
      "name": "Rock_Magma_Cooled",
      "rotation": 1
    },
    {
      "x": -2,
      "y": 0,
      "z": -1,
      "name": "Soil_Ash"
    },
    {
      "x": -2,
      "y": 1,
      "z": -1,
      "name": "Soil_Sand_Ashen"
    },
    {
      "x": -2,
      "y": 2,
      "z": -1,
      "name": "Soil_Ash"
    },
    {
      "x": -2,
      "y": 10,
      "z": -1,
      "name": "Rock_Magma_Cooled",
      "rotation": 1
    },
    {
      "x": -2,
      "y": 11,
      "z": -1,
      "name": "Rock_Magma_Cooled",
      "rotation": 1
    },
    {
      "x": -2,
      "y": 12,
      "z": -1,
      "name": "Rock_Magma_Cooled",
      "rotation": 1
    },
    {
      "x": -2,
      "y": 13,
      "z": -1,
      "name": "Ore_Adamantite_Magma_Cracked",
      "rotation": 1
    },
    {
      "x": -2,
      "y": 14,
      "z": -1,
      "name": "Ore_Adamantite_Magma_Cracked",
      "rotation": 1
    },
    {
      "x": -2,
      "y": 15,
      "z": -1,
      "name": "Rock_Magma_Cooled",
      "rotation": 1
    },
    {
      "x": -2,
      "y": 16,
      "z": -1,
      "name": "Ore_Adamantite_Magma_Cracked",
      "rotation": 1
    },
    {
      "x": -2,
      "y": 0,
      "z": 0,
      "name": "Soil_Ash"
    },
    {
      "x": -2,
      "y": 1,
      "z": 0,
      "name": "Soil_Sand_Ashen"
    },
    {
      "x": -2,
      "y": 2,
      "z": 0,
      "name": "Soil_Ash"
    },
    {
      "x": -2,
      "y": 3,
      "z": 0,
      "name": "Plant_Bramble_Dead_Twisted"
    },
    {
      "x": -2,
      "y": 12,
      "z": 0,
      "name": "Ore_Adamantite_Magma_Cracked",
      "rotation": 1
    },
    {
      "x": -2,
      "y": 13,
      "z": 0,
      "name": "Ore_Adamantite_Magma_Cracked",
      "rotation": 1
    },
    {
      "x": -2,
      "y": 14,
      "z": 0,
      "name": "Rock_Magma_Cooled",
      "rotation": 1
    },
    {
      "x": -2,
      "y": 15,
      "z": 0,
      "name": "Rock_Magma_Cooled",
      "rotation": 1
    },
    {
      "x": -2,
      "y": 16,
      "z": 0,
      "name": "Rock_Magma_Cooled",
      "rotation": 1
    },
    {
      "x": -2,
      "y": 17,
      "z": 0,
      "name": "Ore_Adamantite_Magma_Cracked",
      "rotation": 1
    },
    {
      "x": -2,
      "y": 0,
      "z": 1,
      "name": "Soil_Sand_Ashen"
    },
    {
      "x": -2,
      "y": 1,
      "z": 1,
      "name": "Soil_Ash"
    },
    {
      "x": -2,
      "y": 2,
      "z": 1,
      "name": "Plant_Bramble_Dead_Twisted"
    },
    {
      "x": -2,
      "y": 14,
      "z": 1,
      "name": "Rock_Magma_Cooled"
    },
    {
      "x": -2,
      "y": 15,
      "z": 1,
      "name": "Rock_Magma_Cooled",
      "rotation": 1
    },
    {
      "x": -2,
      "y": 16,
      "z": 1,
      "name": "Rock_Magma_Cooled",
      "rotation": 1
    },
    {
      "x": -2,
      "y": 17,
      "z": 1,
      "name": "Rock_Magma_Cooled",
      "rotation": 1
    },
    {
      "x": -2,
      "y": 18,
      "z": 1,
      "name": "Rock_Magma_Cooled",
      "rotation": 1
    },
    {
      "x": -2,
      "y": 19,
      "z": 1,
      "name": "Rock_Magma_Cooled",
      "rotation": 1
    },
    {
      "x": -2,
      "y": 0,
      "z": 2,
      "name": "Soil_Sand_Ashen"
    },
    {
      "x": -2,
      "y": 1,
      "z": 2,
      "name": "Soil_Ash"
    },
    {
      "x": -2,
      "y": 12,
      "z": 2,
      "name": "Rock_Magma_Cooled"
    },
    {
      "x": -2,
      "y": 13,
      "z": 2,
      "name": "Rock_Magma_Cooled"
    },
    {
      "x": -2,
      "y": 14,
      "z": 2,
      "name": "Rock_Magma_Cooled"
    },
    {
      "x": -2,
      "y": 15,
      "z": 2,
      "name": "Plant_Moss_Rug_Pink",
      "support": 15
    },
    {
      "x": -2,
      "y": 16,
      "z": 2,
      "name": "Plant_Vine_Wall_Poisoned",
      "support": 15
    },
    {
      "x": -2,
      "y": 18,
      "z": 2,
      "name": "Rock_Magma_Cooled",
      "rotation": 1
    },
    {
      "x": -2,
      "y": 19,
      "z": 2,
      "name": "Rock_Magma_Cooled",
      "rotation": 1
    },
    {
      "x": -2,
      "y": 0,
      "z": 3,
      "name": "Soil_Ash"
    },
    {
      "x": -2,
      "y": 1,
      "z": 3,
      "name": "Soil_Ash"
    },
    {
      "x": -2,
      "y": 2,
      "z": 3,
      "name": "Soil_Sand_Ashen"
    },
    {
      "x": -2,
      "y": 12,
      "z": 3,
      "name": "Plant_Vine_Wall_Poisoned",
      "support": 15
    },
    {
      "x": -2,
      "y": 13,
      "z": 3,
      "name": "Plant_Vine_Wall_Poisoned",
      "support": 15
    },
    {
      "x": -2,
      "y": 18,
      "z": 3,
      "name": "Plant_Vine_Wall_Poisoned",
      "support": 15,
      "rotation": 1
    },
    {
      "x": -2,
      "y": 0,
      "z": 4,
      "name": "Soil_Sand_Ashen"
    },
    {
      "x": -2,
      "y": 1,
      "z": 4,
      "name": "Soil_Sand_Ashen"
    },
    {
      "x": -2,
      "y": 2,
      "z": 4,
      "name": "Soil_Sand_Ashen"
    },
    {
      "x": -2,
      "y": 3,
      "z": 4,
      "name": "Plant_Flower_Bushy_Poisoned"
    },
    {
      "x": -2,
      "y": 0,
      "z": 5,
      "name": "Soil_Ash"
    },
    {
      "x": -2,
      "y": 1,
      "z": 5,
      "name": "Soil_Ash"
    },
    {
      "x": -2,
      "y": 2,
      "z": 5,
      "name": "Soil_Sand_Ashen"
    },
    {
      "x": -2,
      "y": 3,
      "z": 5,
      "name": "Plant_Flower_Poisoned_Orange"
    },
    {
      "x": -2,
      "y": 0,
      "z": 6,
      "name": "Soil_Ash"
    },
    {
      "x": -2,
      "y": 1,
      "z": 6,
      "name": "Soil_Sand_Ashen"
    },
    {
      "x": -2,
      "y": 2,
      "z": 6,
      "name": "Soil_Ash"
    },
    {
      "x": -2,
      "y": 3,
      "z": 6,
      "name": "Plant_Flower_Common_Poisoned2",
      "rotation": 4
    },
    {
      "x": -2,
      "y": 0,
      "z": 7,
      "name": "Soil_Ash"
    },
    {
      "x": -2,
      "y": 1,
      "z": 7,
      "name": "Soil_Ash"
    },
    {
      "x": -2,
      "y": 2,
      "z": 7,
      "name": "Soil_Sand_Ashen"
    },
    {
      "x": -2,
      "y": 0,
      "z": 8,
      "name": "Soil_Sand_Ashen"
    },
    {
      "x": -2,
      "y": 1,
      "z": 8,
      "name": "Soil_Sand_Ashen"
    },
    {
      "x": -2,
      "y": 0,
      "z": 9,
      "name": "Soil_Ash"
    },
    {
      "x": -1,
      "y": 0,
      "z": -10,
      "name": "Soil_Sand_Ashen"
    },
    {
      "x": -1,
      "y": 10,
      "z": -10,
      "name": "Plant_Vine_Wall_Poisoned",
      "support": 15,
      "rotation": 3
    },
    {
      "x": -1,
      "y": 0,
      "z": -9,
      "name": "Soil_Sand_Ashen"
    },
    {
      "x": -1,
      "y": 1,
      "z": -9,
      "name": "Soil_Ash"
    },
    {
      "x": -1,
      "y": 10,
      "z": -9,
      "name": "Plant_Vine_Wall_Poisoned",
      "support": 15,
      "rotation": 3
    },
    {
      "x": -1,
      "y": 0,
      "z": -8,
      "name": "Soil_Ash"
    },
    {
      "x": -1,
      "y": 1,
      "z": -8,
      "name": "Soil_Sand_Ashen"
    },
    {
      "x": -1,
      "y": 0,
      "z": -7,
      "name": "Soil_Sand_Ashen"
    },
    {
      "x": -1,
      "y": 1,
      "z": -7,
      "name": "Soil_Ash"
    },
    {
      "x": -1,
      "y": 2,
      "z": -7,
      "name": "Soil_Sand_Ashen"
    },
    {
      "x": -1,
      "y": 3,
      "z": -7,
      "name": "Plant_Flower_Poisoned_Orange"
    },
    {
      "x": -1,
      "y": 7,
      "z": -7,
      "name": "Plant_Vine_Wall_Poisoned",
      "support": 15,
      "rotation": 3
    },
    {
      "x": -1,
      "y": 0,
      "z": -6,
      "name": "Soil_Sand_Ashen"
    },
    {
      "x": -1,
      "y": 1,
      "z": -6,
      "name": "Soil_Ash"
    },
    {
      "x": -1,
      "y": 2,
      "z": -6,
      "name": "Soil_Ash"
    },
    {
      "x": -1,
      "y": 3,
      "z": -6,
      "name": "Plant_Flower_Common_Poisoned2",
      "rotation": 7
    },
    {
      "x": -1,
      "y": 7,
      "z": -6,
      "name": "Rock_Magma_Cooled"
    },
    {
      "x": -1,
      "y": 8,
      "z": -6,
      "name": "Rock_Magma_Cooled"
    },
    {
      "x": -1,
      "y": 0,
      "z": -5,
      "name": "Soil_Ash"
    },
    {
      "x": -1,
      "y": 1,
      "z": -5,
      "name": "Soil_Sand_Ashen"
    },
    {
      "x": -1,
      "y": 2,
      "z": -5,
      "name": "Soil_Ash"
    },
    {
      "x": -1,
      "y": 3,
      "z": -5,
      "name": "Plant_Flower_Bushy_Poisoned"
    },
    {
      "x": -1,
      "y": 4,
      "z": -5,
      "name": "Rock_Magma_Cooled"
    },
    {
      "x": -1,
      "y": 5,
      "z": -5,
      "name": "Rock_Magma_Cooled"
    },
    {
      "x": -1,
      "y": 6,
      "z": -5,
      "name": "Rock_Magma_Cooled"
    },
    {
      "x": -1,
      "y": 7,
      "z": -5,
      "name": "Rock_Magma_Cooled",
      "rotation": 1
    },
    {
      "x": -1,
      "y": 8,
      "z": -5,
      "name": "Rock_Magma_Cooled",
      "rotation": 1
    },
    {
      "x": -1,
      "y": 9,
      "z": -5,
      "name": "Rock_Magma_Cooled",
      "rotation": 1
    },
    {
      "x": -1,
      "y": 10,
      "z": -5,
      "name": "Rock_Magma_Cooled",
      "rotation": 1
    },
    {
      "x": -1,
      "y": 11,
      "z": -5,
      "name": "Plant_Crop_Mushroom_Glowing_Purple"
    },
    {
      "x": -1,
      "y": 0,
      "z": -4,
      "name": "Soil_Ash"
    },
    {
      "x": -1,
      "y": 1,
      "z": -4,
      "name": "Rock_Magma_Cooled"
    },
    {
      "x": -1,
      "y": 2,
      "z": -4,
      "name": "Rock_Magma_Cooled"
    },
    {
      "x": -1,
      "y": 3,
      "z": -4,
      "name": "Rock_Magma_Cooled"
    },
    {
      "x": -1,
      "y": 4,
      "z": -4,
      "name": "Rock_Magma_Cooled"
    },
    {
      "x": -1,
      "y": 5,
      "z": -4,
      "name": "Ore_Adamantite_Magma_Cracked"
    },
    {
      "x": -1,
      "y": 6,
      "z": -4,
      "name": "Rock_Magma_Cooled"
    },
    {
      "x": -1,
      "y": 7,
      "z": -4,
      "name": "Rock_Magma_Cooled",
      "rotation": 1
    },
    {
      "x": -1,
      "y": 8,
      "z": -4,
      "name": "Ore_Adamantite_Magma_Cracked",
      "rotation": 1
    },
    {
      "x": -1,
      "y": 9,
      "z": -4,
      "name": "Ore_Adamantite_Magma_Cracked",
      "rotation": 1
    },
    {
      "x": -1,
      "y": 10,
      "z": -4,
      "name": "Rock_Magma_Cooled",
      "rotation": 1
    },
    {
      "x": -1,
      "y": 11,
      "z": -4,
      "name": "Rock_Magma_Cooled",
      "rotation": 1
    },
    {
      "x": -1,
      "y": 0,
      "z": -3,
      "name": "Rock_Magma_Cooled"
    },
    {
      "x": -1,
      "y": 1,
      "z": -3,
      "name": "Ore_Adamantite_Magma_Cracked"
    },
    {
      "x": -1,
      "y": 2,
      "z": -3,
      "name": "Rock_Magma_Cooled"
    },
    {
      "x": -1,
      "y": 3,
      "z": -3,
      "name": "Rock_Magma_Cooled"
    },
    {
      "x": -1,
      "y": 4,
      "z": -3,
      "name": "Rock_Magma_Cooled"
    },
    {
      "x": -1,
      "y": 5,
      "z": -3,
      "name": "Rock_Magma_Cooled"
    },
    {
      "x": -1,
      "y": 8,
      "z": -3,
      "name": "Rock_Magma_Cooled",
      "rotation": 1
    },
    {
      "x": -1,
      "y": 9,
      "z": -3,
      "name": "Rock_Magma_Cooled",
      "rotation": 1
    },
    {
      "x": -1,
      "y": 10,
      "z": -3,
      "name": "Rock_Magma_Cooled",
      "rotation": 1
    },
    {
      "x": -1,
      "y": 11,
      "z": -3,
      "name": "Rock_Magma_Cooled",
      "rotation": 1
    },
    {
      "x": -1,
      "y": 12,
      "z": -3,
      "name": "Rock_Magma_Cooled",
      "rotation": 1
    },
    {
      "x": -1,
      "y": 0,
      "z": -2,
      "name": "Rock_Magma_Cooled"
    },
    {
      "x": -1,
      "y": 1,
      "z": -2,
      "name": "Rock_Magma_Cooled"
    },
    {
      "x": -1,
      "y": 2,
      "z": -2,
      "name": "Ore_Adamantite_Magma_Cracked"
    },
    {
      "x": -1,
      "y": 9,
      "z": -2,
      "name": "Ore_Adamantite_Magma_Cracked",
      "rotation": 1
    },
    {
      "x": -1,
      "y": 10,
      "z": -2,
      "name": "Rock_Magma_Cooled",
      "rotation": 1
    },
    {
      "x": -1,
      "y": 11,
      "z": -2,
      "name": "Ore_Adamantite_Magma_Cracked",
      "rotation": 1
    },
    {
      "x": -1,
      "y": 12,
      "z": -2,
      "name": "Rock_Magma_Cooled",
      "rotation": 1
    },
    {
      "x": -1,
      "y": 13,
      "z": -2,
      "name": "Rock_Magma_Cooled",
      "rotation": 1
    },
    {
      "x": -1,
      "y": 0,
      "z": -1,
      "name": "Ore_Adamantite_Magma_Cracked"
    },
    {
      "x": -1,
      "y": 1,
      "z": -1,
      "name": "Soil_Ash"
    },
    {
      "x": -1,
      "y": 2,
      "z": -1,
      "name": "Soil_Sand_Ashen"
    },
    {
      "x": -1,
      "y": 10,
      "z": -1,
      "name": "Rock_Magma_Cooled",
      "rotation": 1
    },
    {
      "x": -1,
      "y": 11,
      "z": -1,
      "name": "Ore_Adamantite_Magma_Cracked",
      "rotation": 1
    },
    {
      "x": -1,
      "y": 12,
      "z": -1,
      "name": "Rock_Magma_Cooled",
      "rotation": 1
    },
    {
      "x": -1,
      "y": 13,
      "z": -1,
      "name": "Rock_Magma_Cooled",
      "rotation": 1
    },
    {
      "x": -1,
      "y": 14,
      "z": -1,
      "name": "Rock_Magma_Cooled",
      "rotation": 1
    },
    {
      "x": -1,
      "y": 0,
      "z": 0,
      "name": "Soil_Sand_Ashen"
    },
    {
      "x": -1,
      "y": 1,
      "z": 0,
      "name": "Soil_Sand_Ashen"
    },
    {
      "x": -1,
      "y": 13,
      "z": 0,
      "name": "Plant_Vine_Wall_Poisoned",
      "support": 15,
      "rotation": 1
    },
    {
      "x": -1,
      "y": 14,
      "z": 0,
      "name": "Plant_Vine_Wall_Poisoned",
      "support": 15,
      "rotation": 1
    },
    {
      "x": -1,
      "y": 0,
      "z": 1,
      "name": "Soil_Sand_Ashen"
    },
    {
      "x": -1,
      "y": 1,
      "z": 1,
      "name": "Soil_Ash"
    },
    {
      "x": -1,
      "y": 2,
      "z": 1,
      "name": "Plant_Bramble_Dead_Twisted"
    },
    {
      "x": -1,
      "y": 15,
      "z": 1,
      "name": "Plant_Vine_Wall_Poisoned",
      "support": 15,
      "rotation": 1
    },
    {
      "x": -1,
      "y": 0,
      "z": 2,
      "name": "Soil_Sand_Ashen"
    },
    {
      "x": -1,
      "y": 1,
      "z": 2,
      "name": "Soil_Sand_Ashen"
    },
    {
      "x": -1,
      "y": 2,
      "z": 2,
      "name": "Plant_Bramble_Dead_Twisted"
    },
    {
      "x": -1,
      "y": 9,
      "z": 2,
      "name": "Rock_Magma_Cooled"
    },
    {
      "x": -1,
      "y": 10,
      "z": 2,
      "name": "Rock_Magma_Cooled"
    },
    {
      "x": -1,
      "y": 11,
      "z": 2,
      "name": "Rock_Magma_Cooled"
    },
    {
      "x": -1,
      "y": 12,
      "z": 2,
      "name": "Rock_Magma_Cooled"
    },
    {
      "x": -1,
      "y": 13,
      "z": 2,
      "name": "Plant_Moss_Rug_Pink",
      "support": 15
    },
    {
      "x": -1,
      "y": 0,
      "z": 3,
      "name": "Soil_Sand_Ashen"
    },
    {
      "x": -1,
      "y": 1,
      "z": 3,
      "name": "Soil_Sand_Ashen"
    },
    {
      "x": -1,
      "y": 2,
      "z": 3,
      "name": "Plant_Bramble_Dead_Twisted"
    },
    {
      "x": -1,
      "y": 6,
      "z": 3,
      "name": "Rock_Magma_Cooled"
    },
    {
      "x": -1,
      "y": 7,
      "z": 3,
      "name": "Rock_Magma_Cooled"
    },
    {
      "x": -1,
      "y": 8,
      "z": 3,
      "name": "Rock_Magma_Cooled"
    },
    {
      "x": -1,
      "y": 9,
      "z": 3,
      "name": "Ore_Adamantite_Magma_Cracked"
    },
    {
      "x": -1,
      "y": 10,
      "z": 3,
      "name": "Ore_Adamantite_Magma_Cracked"
    },
    {
      "x": -1,
      "y": 11,
      "z": 3,
      "name": "Plant_Moss_Rug_Pink",
      "support": 15
    },
    {
      "x": -1,
      "y": 0,
      "z": 4,
      "name": "Soil_Ash"
    },
    {
      "x": -1,
      "y": 1,
      "z": 4,
      "name": "Soil_Ash"
    },
    {
      "x": -1,
      "y": 2,
      "z": 4,
      "name": "Soil_Sand_Ashen"
    },
    {
      "x": -1,
      "y": 9,
      "z": 4,
      "name": "Plant_Vine_Wall_Poisoned",
      "support": 15
    },
    {
      "x": -1,
      "y": 0,
      "z": 5,
      "name": "Soil_Ash"
    },
    {
      "x": -1,
      "y": 1,
      "z": 5,
      "name": "Soil_Ash"
    },
    {
      "x": -1,
      "y": 2,
      "z": 5,
      "name": "Soil_Ash"
    },
    {
      "x": -1,
      "y": 0,
      "z": 6,
      "name": "Soil_Sand_Ashen"
    },
    {
      "x": -1,
      "y": 1,
      "z": 6,
      "name": "Soil_Ash"
    },
    {
      "x": -1,
      "y": 2,
      "z": 6,
      "name": "Soil_Sand_Ashen"
    },
    {
      "x": -1,
      "y": 0,
      "z": 7,
      "name": "Soil_Ash"
    },
    {
      "x": -1,
      "y": 1,
      "z": 7,
      "name": "Soil_Sand_Ashen"
    },
    {
      "x": -1,
      "y": 0,
      "z": 8,
      "name": "Soil_Ash"
    },
    {
      "x": -1,
      "y": 1,
      "z": 8,
      "name": "Soil_Ash"
    },
    {
      "x": -1,
      "y": 0,
      "z": 9,
      "name": "Soil_Sand_Ashen"
    },
    {
      "x": 0,
      "y": 0,
      "z": -10,
      "name": "Soil_Sand_Ashen"
    },
    {
      "x": 0,
      "y": 10,
      "z": -10,
      "name": "Rock_Magma_Cooled"
    },
    {
      "x": 0,
      "y": 11,
      "z": -10,
      "name": "Ore_Adamantite_Magma_Cracked"
    },
    {
      "x": 0,
      "y": 0,
      "z": -9,
      "name": "Soil_Sand_Ashen"
    },
    {
      "x": 0,
      "y": 1,
      "z": -9,
      "name": "Soil_Ash"
    },
    {
      "x": 0,
      "y": 9,
      "z": -9,
      "name": "Rock_Magma_Cooled"
    },
    {
      "x": 0,
      "y": 10,
      "z": -9,
      "name": "Rock_Magma_Cooled"
    },
    {
      "x": 0,
      "y": 11,
      "z": -9,
      "name": "Rock_Magma_Cooled"
    },
    {
      "x": 0,
      "y": 0,
      "z": -8,
      "name": "Soil_Ash"
    },
    {
      "x": 0,
      "y": 1,
      "z": -8,
      "name": "Soil_Sand_Ashen"
    },
    {
      "x": 0,
      "y": 2,
      "z": -8,
      "name": "Soil_Sand_Ashen"
    },
    {
      "x": 0,
      "y": 7,
      "z": -8,
      "name": "Plant_Vine_Wall_Poisoned",
      "support": 15,
      "rotation": 2
    },
    {
      "x": 0,
      "y": 0,
      "z": -7,
      "name": "Soil_Ash"
    },
    {
      "x": 0,
      "y": 1,
      "z": -7,
      "name": "Soil_Ash"
    },
    {
      "x": 0,
      "y": 2,
      "z": -7,
      "name": "Soil_Sand_Ashen"
    },
    {
      "x": 0,
      "y": 6,
      "z": -7,
      "name": "Ore_Adamantite_Magma_Cracked"
    },
    {
      "x": 0,
      "y": 7,
      "z": -7,
      "name": "Ore_Adamantite_Magma_Cracked"
    },
    {
      "x": 0,
      "y": 8,
      "z": -7,
      "name": "Ore_Adamantite_Magma_Cracked"
    },
    {
      "x": 0,
      "y": 0,
      "z": -6,
      "name": "Soil_Sand_Ashen"
    },
    {
      "x": 0,
      "y": 1,
      "z": -6,
      "name": "Soil_Sand_Ashen"
    },
    {
      "x": 0,
      "y": 2,
      "z": -6,
      "name": "Soil_Sand_Ashen"
    },
    {
      "x": 0,
      "y": 3,
      "z": -6,
      "name": "Plant_Flower_Bushy_Poisoned"
    },
    {
      "x": 0,
      "y": 4,
      "z": -6,
      "name": "Rock_Magma_Cooled"
    },
    {
      "x": 0,
      "y": 5,
      "z": -6,
      "name": "Rock_Magma_Cooled"
    },
    {
      "x": 0,
      "y": 6,
      "z": -6,
      "name": "Rock_Magma_Cooled"
    },
    {
      "x": 0,
      "y": 7,
      "z": -6,
      "name": "Rock_Magma_Cooled"
    },
    {
      "x": 0,
      "y": 8,
      "z": -6,
      "name": "Rock_Magma_Cooled"
    },
    {
      "x": 0,
      "y": 0,
      "z": -5,
      "name": "Soil_Ash"
    },
    {
      "x": 0,
      "y": 1,
      "z": -5,
      "name": "Soil_Ash"
    },
    {
      "x": 0,
      "y": 2,
      "z": -5,
      "name": "Ore_Adamantite_Magma_Cracked"
    },
    {
      "x": 0,
      "y": 3,
      "z": -5,
      "name": "Rock_Magma_Cooled"
    },
    {
      "x": 0,
      "y": 4,
      "z": -5,
      "name": "Rock_Magma_Cooled"
    },
    {
      "x": 0,
      "y": 5,
      "z": -5,
      "name": "Rock_Magma_Cooled"
    },
    {
      "x": 0,
      "y": 6,
      "z": -5,
      "name": "Rock_Magma_Cooled",
      "rotation": 1
    },
    {
      "x": 0,
      "y": 7,
      "z": -5,
      "name": "Rock_Magma_Cooled",
      "rotation": 1
    },
    {
      "x": 0,
      "y": 8,
      "z": -5,
      "name": "Rock_Magma_Cooled",
      "rotation": 1
    },
    {
      "x": 0,
      "y": 9,
      "z": -5,
      "name": "Plant_Crop_Mushroom_Glowing_Violet"
    },
    {
      "x": 0,
      "y": 0,
      "z": -4,
      "name": "Ore_Adamantite_Magma_Cracked"
    },
    {
      "x": 0,
      "y": 1,
      "z": -4,
      "name": "Rock_Magma_Cooled"
    },
    {
      "x": 0,
      "y": 2,
      "z": -4,
      "name": "Rock_Magma_Cooled"
    },
    {
      "x": 0,
      "y": 3,
      "z": -4,
      "name": "Rock_Magma_Cooled"
    },
    {
      "x": 0,
      "y": 4,
      "z": -4,
      "name": "Rock_Magma_Cooled"
    },
    {
      "x": 0,
      "y": 5,
      "z": -4,
      "name": "Rock_Magma_Cooled"
    },
    {
      "x": 0,
      "y": 6,
      "z": -4,
      "name": "Rock_Magma_Cooled"
    },
    {
      "x": 0,
      "y": 7,
      "z": -4,
      "name": "Rock_Magma_Cooled",
      "rotation": 1
    },
    {
      "x": 0,
      "y": 8,
      "z": -4,
      "name": "Rock_Magma_Cooled",
      "rotation": 1
    },
    {
      "x": 0,
      "y": 9,
      "z": -4,
      "name": "Rock_Magma_Cooled",
      "rotation": 1
    },
    {
      "x": 0,
      "y": 0,
      "z": -3,
      "name": "Rock_Magma_Cooled"
    },
    {
      "x": 0,
      "y": 1,
      "z": -3,
      "name": "Rock_Magma_Cooled"
    },
    {
      "x": 0,
      "y": 2,
      "z": -3,
      "name": "Rock_Magma_Cooled"
    },
    {
      "x": 0,
      "y": 3,
      "z": -3,
      "name": "Rock_Magma_Cooled"
    },
    {
      "x": 0,
      "y": 4,
      "z": -3,
      "name": "Rock_Magma_Cooled"
    },
    {
      "x": 0,
      "y": 5,
      "z": -3,
      "name": "Rock_Magma_Cooled"
    },
    {
      "x": 0,
      "y": 6,
      "z": -3,
      "name": "Rock_Magma_Cooled"
    },
    {
      "x": 0,
      "y": 7,
      "z": -3,
      "name": "Rock_Magma_Cooled",
      "rotation": 1
    },
    {
      "x": 0,
      "y": 8,
      "z": -3,
      "name": "Rock_Magma_Cooled",
      "rotation": 1
    },
    {
      "x": 0,
      "y": 9,
      "z": -3,
      "name": "Rock_Magma_Cooled",
      "rotation": 1
    },
    {
      "x": 0,
      "y": 10,
      "z": -3,
      "name": "Rock_Magma_Cooled",
      "rotation": 1
    },
    {
      "x": 0,
      "y": 0,
      "z": -2,
      "name": "Rock_Magma_Cooled"
    },
    {
      "x": 0,
      "y": 1,
      "z": -2,
      "name": "Rock_Magma_Cooled"
    },
    {
      "x": 0,
      "y": 2,
      "z": -2,
      "name": "Rock_Magma_Cooled"
    },
    {
      "x": 0,
      "y": 3,
      "z": -2,
      "name": "Rock_Magma_Cooled"
    },
    {
      "x": 0,
      "y": 4,
      "z": -2,
      "name": "Ore_Adamantite_Magma_Cracked"
    },
    {
      "x": 0,
      "y": 10,
      "z": -2,
      "name": "Rock_Magma_Cooled",
      "rotation": 1
    },
    {
      "x": 0,
      "y": 11,
      "z": -2,
      "name": "Rock_Magma_Cooled",
      "rotation": 1
    },
    {
      "x": 0,
      "y": 12,
      "z": -2,
      "name": "Rock_Magma_Cooled",
      "rotation": 1
    },
    {
      "x": 0,
      "y": 0,
      "z": -1,
      "name": "Rock_Magma_Cooled"
    },
    {
      "x": 0,
      "y": 1,
      "z": -1,
      "name": "Ore_Adamantite_Magma_Cracked"
    },
    {
      "x": 0,
      "y": 2,
      "z": -1,
      "name": "Rock_Magma_Cooled"
    },
    {
      "x": 0,
      "y": 12,
      "z": -1,
      "name": "Plant_Vine_Wall_Poisoned",
      "support": 15,
      "rotation": 1
    },
    {
      "x": 0,
      "y": 0,
      "z": 0,
      "name": "Soil_Sand_Ashen"
    },
    {
      "x": 0,
      "y": 1,
      "z": 0,
      "name": "Soil_Sand_Ashen"
    },
    {
      "x": 0,
      "y": 0,
      "z": 1,
      "name": "Soil_Ash"
    },
    {
      "x": 0,
      "y": 1,
      "z": 1,
      "name": "Soil_Sand_Ashen"
    },
    {
      "x": 0,
      "y": 2,
      "z": 1,
      "name": "Soil_Sand_Ashen"
    },
    {
      "x": 0,
      "y": 3,
      "z": 1,
      "name": "Plant_Bramble_Dead_Twisted"
    },
    {
      "x": 0,
      "y": 0,
      "z": 2,
      "name": "Soil_Sand_Ashen"
    },
    {
      "x": 0,
      "y": 1,
      "z": 2,
      "name": "Soil_Sand_Ashen"
    },
    {
      "x": 0,
      "y": 6,
      "z": 2,
      "name": "Rock_Magma_Cooled"
    },
    {
      "x": 0,
      "y": 7,
      "z": 2,
      "name": "Rock_Magma_Cooled"
    },
    {
      "x": 0,
      "y": 8,
      "z": 2,
      "name": "Rock_Magma_Cooled"
    },
    {
      "x": 0,
      "y": 9,
      "z": 2,
      "name": "Plant_Moss_Rug_Pink",
      "support": 15
    },
    {
      "x": 0,
      "y": 0,
      "z": 3,
      "name": "Soil_Sand_Ashen"
    },
    {
      "x": 0,
      "y": 1,
      "z": 3,
      "name": "Ore_Adamantite_Magma_Cracked"
    },
    {
      "x": 0,
      "y": 2,
      "z": 3,
      "name": "Ore_Adamantite_Magma_Cracked"
    },
    {
      "x": 0,
      "y": 3,
      "z": 3,
      "name": "Rock_Magma_Cooled"
    },
    {
      "x": 0,
      "y": 4,
      "z": 3,
      "name": "Rock_Magma_Cooled"
    },
    {
      "x": 0,
      "y": 5,
      "z": 3,
      "name": "Rock_Magma_Cooled"
    },
    {
      "x": 0,
      "y": 6,
      "z": 3,
      "name": "Rock_Magma_Cooled"
    },
    {
      "x": 0,
      "y": 7,
      "z": 3,
      "name": "Ore_Adamantite_Magma_Cracked"
    },
    {
      "x": 0,
      "y": 0,
      "z": 4,
      "name": "Rock_Magma_Cooled"
    },
    {
      "x": 0,
      "y": 1,
      "z": 4,
      "name": "Rock_Magma_Cooled"
    },
    {
      "x": 0,
      "y": 0,
      "z": 5,
      "name": "Soil_Sand_Ashen"
    },
    {
      "x": 0,
      "y": 1,
      "z": 5,
      "name": "Soil_Sand_Ashen"
    },
    {
      "x": 0,
      "y": 2,
      "z": 5,
      "name": "Soil_Ash"
    },
    {
      "x": 0,
      "y": 3,
      "z": 5,
      "name": "Plant_Bramble_Dead_Twisted"
    },
    {
      "x": 0,
      "y": 0,
      "z": 6,
      "name": "Soil_Sand_Ashen"
    },
    {
      "x": 0,
      "y": 1,
      "z": 6,
      "name": "Soil_Sand_Ashen"
    },
    {
      "x": 0,
      "y": 2,
      "z": 6,
      "name": "Plant_Flower_Bushy_Poisoned"
    },
    {
      "x": 0,
      "y": 0,
      "z": 7,
      "name": "Soil_Ash"
    },
    {
      "x": 0,
      "y": 1,
      "z": 7,
      "name": "Soil_Sand_Ashen"
    },
    {
      "x": 0,
      "y": 0,
      "z": 8,
      "name": "Soil_Sand_Ashen"
    },
    {
      "x": 1,
      "y": 14,
      "z": -12,
      "name": "Plant_Vine_Wall_Poisoned",
      "support": 15,
      "rotation": 3
    },
    {
      "x": 1,
      "y": 12,
      "z": -11,
      "name": "Plant_Vine_Wall_Poisoned",
      "support": 15,
      "rotation": 3
    },
    {
      "x": 1,
      "y": 0,
      "z": -10,
      "name": "Soil_Ash"
    },
    {
      "x": 1,
      "y": 9,
      "z": -10,
      "name": "Rock_Magma_Cooled"
    },
    {
      "x": 1,
      "y": 10,
      "z": -10,
      "name": "Rock_Magma_Cooled"
    },
    {
      "x": 1,
      "y": 11,
      "z": -10,
      "name": "Rock_Magma_Cooled"
    },
    {
      "x": 1,
      "y": 12,
      "z": -10,
      "name": "Rock_Magma_Cooled"
    },
    {
      "x": 1,
      "y": 0,
      "z": -9,
      "name": "Soil_Ash"
    },
    {
      "x": 1,
      "y": 1,
      "z": -9,
      "name": "Soil_Sand_Ashen"
    },
    {
      "x": 1,
      "y": 8,
      "z": -9,
      "name": "Rock_Magma_Cooled"
    },
    {
      "x": 1,
      "y": 9,
      "z": -9,
      "name": "Rock_Magma_Cooled"
    },
    {
      "x": 1,
      "y": 10,
      "z": -9,
      "name": "Rock_Magma_Cooled"
    },
    {
      "x": 1,
      "y": 11,
      "z": -9,
      "name": "Ore_Adamantite_Magma_Cracked"
    },
    {
      "x": 1,
      "y": 12,
      "z": -9,
      "name": "Plant_Crop_Mushroom_Glowing_Purple"
    },
    {
      "x": 1,
      "y": 0,
      "z": -8,
      "name": "Soil_Ash"
    },
    {
      "x": 1,
      "y": 1,
      "z": -8,
      "name": "Soil_Ash"
    },
    {
      "x": 1,
      "y": 7,
      "z": -8,
      "name": "Rock_Magma_Cooled"
    },
    {
      "x": 1,
      "y": 8,
      "z": -8,
      "name": "Rock_Magma_Cooled"
    },
    {
      "x": 1,
      "y": 9,
      "z": -8,
      "name": "Rock_Magma_Cooled"
    },
    {
      "x": 1,
      "y": 0,
      "z": -7,
      "name": "Soil_Sand_Ashen"
    },
    {
      "x": 1,
      "y": 1,
      "z": -7,
      "name": "Soil_Sand_Ashen"
    },
    {
      "x": 1,
      "y": 2,
      "z": -7,
      "name": "Soil_Sand_Ashen"
    },
    {
      "x": 1,
      "y": 3,
      "z": -7,
      "name": "Plant_Bramble_Dead_Twisted"
    },
    {
      "x": 1,
      "y": 5,
      "z": -7,
      "name": "Rock_Magma_Cooled"
    },
    {
      "x": 1,
      "y": 6,
      "z": -7,
      "name": "Rock_Magma_Cooled"
    },
    {
      "x": 1,
      "y": 7,
      "z": -7,
      "name": "Rock_Magma_Cooled"
    },
    {
      "x": 1,
      "y": 8,
      "z": -7,
      "name": "Rock_Magma_Cooled"
    },
    {
      "x": 1,
      "y": 9,
      "z": -7,
      "name": "Rock_Magma_Cooled"
    },
    {
      "x": 1,
      "y": 0,
      "z": -6,
      "name": "Soil_Ash"
    },
    {
      "x": 1,
      "y": 1,
      "z": -6,
      "name": "Soil_Ash"
    },
    {
      "x": 1,
      "y": 2,
      "z": -6,
      "name": "Soil_Ash"
    },
    {
      "x": 1,
      "y": 4,
      "z": -6,
      "name": "Ore_Adamantite_Magma_Cracked"
    },
    {
      "x": 1,
      "y": 5,
      "z": -6,
      "name": "Ore_Adamantite_Magma_Cracked"
    },
    {
      "x": 1,
      "y": 6,
      "z": -6,
      "name": "Rock_Magma_Cooled"
    },
    {
      "x": 1,
      "y": 7,
      "z": -6,
      "name": "Rock_Magma_Cooled"
    },
    {
      "x": 1,
      "y": 8,
      "z": -6,
      "name": "Rock_Magma_Cooled"
    },
    {
      "x": 1,
      "y": 0,
      "z": -5,
      "name": "Soil_Sand_Ashen"
    },
    {
      "x": 1,
      "y": 1,
      "z": -5,
      "name": "Soil_Sand_Ashen"
    },
    {
      "x": 1,
      "y": 2,
      "z": -5,
      "name": "Soil_Ash"
    },
    {
      "x": 1,
      "y": 3,
      "z": -5,
      "name": "Rock_Magma_Cooled"
    },
    {
      "x": 1,
      "y": 4,
      "z": -5,
      "name": "Rock_Magma_Cooled"
    },
    {
      "x": 1,
      "y": 5,
      "z": -5,
      "name": "Rock_Magma_Cooled",
      "rotation": 1
    },
    {
      "x": 1,
      "y": 6,
      "z": -5,
      "name": "Rock_Magma_Cooled",
      "rotation": 1
    },
    {
      "x": 1,
      "y": 7,
      "z": -5,
      "name": "Rock_Magma_Cooled",
      "rotation": 1
    },
    {
      "x": 1,
      "y": 8,
      "z": -5,
      "name": "Rock_Magma_Cooled",
      "rotation": 1
    },
    {
      "x": 1,
      "y": 9,
      "z": -5,
      "name": "Plant_Crop_Mushroom_Glowing_Purple"
    },
    {
      "x": 1,
      "y": 0,
      "z": -4,
      "name": "Rock_Magma_Cooled"
    },
    {
      "x": 1,
      "y": 1,
      "z": -4,
      "name": "Ore_Adamantite_Magma_Cracked"
    },
    {
      "x": 1,
      "y": 2,
      "z": -4,
      "name": "Rock_Magma_Cooled"
    },
    {
      "x": 1,
      "y": 3,
      "z": -4,
      "name": "Rock_Magma_Cooled"
    },
    {
      "x": 1,
      "y": 4,
      "z": -4,
      "name": "Rock_Magma_Cooled"
    },
    {
      "x": 1,
      "y": 5,
      "z": -4,
      "name": "Rock_Magma_Cooled"
    },
    {
      "x": 1,
      "y": 6,
      "z": -4,
      "name": "Rock_Magma_Cooled",
      "rotation": 1
    },
    {
      "x": 1,
      "y": 7,
      "z": -4,
      "name": "Rock_Magma_Cooled",
      "rotation": 1
    },
    {
      "x": 1,
      "y": 8,
      "z": -4,
      "name": "Rock_Magma_Cooled",
      "rotation": 1
    },
    {
      "x": 1,
      "y": 0,
      "z": -3,
      "name": "Ore_Adamantite_Magma_Cracked"
    },
    {
      "x": 1,
      "y": 1,
      "z": -3,
      "name": "Rock_Magma_Cooled"
    },
    {
      "x": 1,
      "y": 2,
      "z": -3,
      "name": "Rock_Magma_Cooled"
    },
    {
      "x": 1,
      "y": 3,
      "z": -3,
      "name": "Rock_Magma_Cooled"
    },
    {
      "x": 1,
      "y": 7,
      "z": -3,
      "name": "Rock_Magma_Cooled",
      "rotation": 1
    },
    {
      "x": 1,
      "y": 8,
      "z": -3,
      "name": "Plant_Crop_Mushroom_Glowing_Purple"
    },
    {
      "x": 1,
      "y": 10,
      "z": -3,
      "name": "Plant_Vine_Wall_Poisoned",
      "support": 15,
      "rotation": 1
    },
    {
      "x": 1,
      "y": 0,
      "z": -2,
      "name": "Ore_Adamantite_Magma_Cracked"
    },
    {
      "x": 1,
      "y": 1,
      "z": -2,
      "name": "Ore_Adamantite_Magma_Cracked"
    },
    {
      "x": 1,
      "y": 2,
      "z": -2,
      "name": "Rock_Magma_Cooled"
    },
    {
      "x": 1,
      "y": 11,
      "z": -2,
      "name": "Plant_Vine_Wall_Poisoned",
      "support": 15,
      "rotation": 1
    },
    {
      "x": 1,
      "y": 0,
      "z": -1,
      "name": "Rock_Magma_Cooled"
    },
    {
      "x": 1,
      "y": 1,
      "z": -1,
      "name": "Rock_Magma_Cooled"
    },
    {
      "x": 1,
      "y": 2,
      "z": -1,
      "name": "Rock_Magma_Cooled"
    },
    {
      "x": 1,
      "y": 0,
      "z": 0,
      "name": "Soil_Ash"
    },
    {
      "x": 1,
      "y": 1,
      "z": 0,
      "name": "Soil_Ash"
    },
    {
      "x": 1,
      "y": 2,
      "z": 0,
      "name": "Soil_Sand_Ashen"
    },
    {
      "x": 1,
      "y": 3,
      "z": 0,
      "name": "Plant_Crop_Mushroom_Glowing_Purple"
    },
    {
      "x": 1,
      "y": 0,
      "z": 1,
      "name": "Soil_Ash"
    },
    {
      "x": 1,
      "y": 1,
      "z": 1,
      "name": "Soil_Ash"
    },
    {
      "x": 1,
      "y": 2,
      "z": 1,
      "name": "Soil_Sand_Ashen"
    },
    {
      "x": 1,
      "y": 0,
      "z": 2,
      "name": "Ore_Adamantite_Magma_Cracked"
    },
    {
      "x": 1,
      "y": 1,
      "z": 2,
      "name": "Rock_Magma_Cooled"
    },
    {
      "x": 1,
      "y": 2,
      "z": 2,
      "name": "Ore_Adamantite_Magma_Cracked"
    },
    {
      "x": 1,
      "y": 3,
      "z": 2,
      "name": "Rock_Magma_Cooled"
    },
    {
      "x": 1,
      "y": 4,
      "z": 2,
      "name": "Ore_Adamantite_Magma_Cracked"
    },
    {
      "x": 1,
      "y": 5,
      "z": 2,
      "name": "Rock_Magma_Cooled"
    },
    {
      "x": 1,
      "y": 6,
      "z": 2,
      "name": "Ore_Adamantite_Magma_Cracked"
    },
    {
      "x": 1,
      "y": 0,
      "z": 3,
      "name": "Ore_Adamantite_Magma_Cracked"
    },
    {
      "x": 1,
      "y": 1,
      "z": 3,
      "name": "Rock_Magma_Cooled"
    },
    {
      "x": 1,
      "y": 2,
      "z": 3,
      "name": "Rock_Magma_Cooled"
    },
    {
      "x": 1,
      "y": 3,
      "z": 3,
      "name": "Rock_Magma_Cooled"
    },
    {
      "x": 1,
      "y": 4,
      "z": 3,
      "name": "Rock_Magma_Cooled"
    },
    {
      "x": 1,
      "y": 5,
      "z": 3,
      "name": "Rock_Magma_Cooled"
    },
    {
      "x": 1,
      "y": 0,
      "z": 4,
      "name": "Rock_Magma_Cooled"
    },
    {
      "x": 1,
      "y": 1,
      "z": 4,
      "name": "Rock_Magma_Cooled"
    },
    {
      "x": 1,
      "y": 2,
      "z": 4,
      "name": "Rock_Magma_Cooled"
    },
    {
      "x": 1,
      "y": 3,
      "z": 4,
      "name": "Rock_Magma_Cooled"
    },
    {
      "x": 1,
      "y": 4,
      "z": 4,
      "name": "Rock_Magma_Cooled"
    },
    {
      "x": 1,
      "y": 5,
      "z": 4,
      "name": "Ore_Adamantite_Magma_Cracked"
    },
    {
      "x": 1,
      "y": 0,
      "z": 5,
      "name": "Soil_Sand_Ashen"
    },
    {
      "x": 1,
      "y": 1,
      "z": 5,
      "name": "Soil_Sand_Ashen"
    },
    {
      "x": 1,
      "y": 2,
      "z": 5,
      "name": "Plant_Flower_Bushy_Poisoned"
    },
    {
      "x": 1,
      "y": 0,
      "z": 6,
      "name": "Soil_Sand_Ashen"
    },
    {
      "x": 1,
      "y": 1,
      "z": 6,
      "name": "Soil_Sand_Ashen"
    },
    {
      "x": 1,
      "y": 0,
      "z": 7,
      "name": "Soil_Ash"
    },
    {
      "x": 2,
      "y": 16,
      "z": -14,
      "name": "Plant_Vine_Wall_Poisoned",
      "support": 15,
      "rotation": 3
    },
    {
      "x": 2,
      "y": 16,
      "z": -13,
      "name": "Plant_Vine_Wall_Poisoned",
      "support": 15,
      "rotation": 3
    },
    {
      "x": 2,
      "y": 14,
      "z": -12,
      "name": "Rock_Magma_Cooled"
    },
    {
      "x": 2,
      "y": 15,
      "z": -12,
      "name": "Ore_Adamantite_Magma_Cracked"
    },
    {
      "x": 2,
      "y": 11,
      "z": -11,
      "name": "Rock_Magma_Cooled"
    },
    {
      "x": 2,
      "y": 12,
      "z": -11,
      "name": "Ore_Adamantite_Magma_Cracked"
    },
    {
      "x": 2,
      "y": 13,
      "z": -11,
      "name": "Rock_Magma_Cooled"
    },
    {
      "x": 2,
      "y": 14,
      "z": -11,
      "name": "Ore_Adamantite_Magma_Cracked"
    },
    {
      "x": 2,
      "y": 15,
      "z": -11,
      "name": "Ore_Adamantite_Magma_Cracked"
    },
    {
      "x": 2,
      "y": 9,
      "z": -10,
      "name": "Ore_Adamantite_Magma_Cracked"
    },
    {
      "x": 2,
      "y": 10,
      "z": -10,
      "name": "Rock_Magma_Cooled"
    },
    {
      "x": 2,
      "y": 11,
      "z": -10,
      "name": "Rock_Magma_Cooled"
    },
    {
      "x": 2,
      "y": 12,
      "z": -10,
      "name": "Rock_Magma_Cooled"
    },
    {
      "x": 2,
      "y": 0,
      "z": -9,
      "name": "Soil_Sand_Ashen"
    },
    {
      "x": 2,
      "y": 9,
      "z": -9,
      "name": "Rock_Magma_Cooled"
    },
    {
      "x": 2,
      "y": 10,
      "z": -9,
      "name": "Rock_Magma_Cooled"
    },
    {
      "x": 2,
      "y": 11,
      "z": -9,
      "name": "Rock_Magma_Cooled"
    },
    {
      "x": 2,
      "y": 12,
      "z": -9,
      "name": "Ore_Adamantite_Magma_Cracked"
    },
    {
      "x": 2,
      "y": 0,
      "z": -8,
      "name": "Soil_Ash"
    },
    {
      "x": 2,
      "y": 1,
      "z": -8,
      "name": "Soil_Ash"
    },
    {
      "x": 2,
      "y": 7,
      "z": -8,
      "name": "Rock_Magma_Cooled"
    },
    {
      "x": 2,
      "y": 8,
      "z": -8,
      "name": "Rock_Magma_Cooled"
    },
    {
      "x": 2,
      "y": 9,
      "z": -8,
      "name": "Rock_Magma_Cooled"
    },
    {
      "x": 2,
      "y": 10,
      "z": -8,
      "name": "Rock_Magma_Cooled"
    },
    {
      "x": 2,
      "y": 11,
      "z": -8,
      "name": "Rock_Magma_Cooled"
    },
    {
      "x": 2,
      "y": 0,
      "z": -7,
      "name": "Soil_Ash"
    },
    {
      "x": 2,
      "y": 1,
      "z": -7,
      "name": "Soil_Sand_Ashen"
    },
    {
      "x": 2,
      "y": 6,
      "z": -7,
      "name": "Rock_Magma_Cooled"
    },
    {
      "x": 2,
      "y": 7,
      "z": -7,
      "name": "Rock_Magma_Cooled"
    },
    {
      "x": 2,
      "y": 8,
      "z": -7,
      "name": "Rock_Magma_Cooled"
    },
    {
      "x": 2,
      "y": 9,
      "z": -7,
      "name": "Rock_Magma_Cooled"
    },
    {
      "x": 2,
      "y": 10,
      "z": -7,
      "name": "Plant_Vine_Wall_Poisoned",
      "support": 15
    },
    {
      "x": 2,
      "y": 0,
      "z": -6,
      "name": "Soil_Sand_Ashen"
    },
    {
      "x": 2,
      "y": 1,
      "z": -6,
      "name": "Soil_Sand_Ashen"
    },
    {
      "x": 2,
      "y": 2,
      "z": -6,
      "name": "Soil_Ash"
    },
    {
      "x": 2,
      "y": 3,
      "z": -6,
      "name": "Plant_Crop_Mushroom_Glowing_Violet"
    },
    {
      "x": 2,
      "y": 7,
      "z": -6,
      "name": "Ore_Adamantite_Magma_Cracked"
    },
    {
      "x": 2,
      "y": 8,
      "z": -6,
      "name": "Plant_Vine_Wall_Poisoned",
      "support": 15,
      "rotation": 1
    },
    {
      "x": 2,
      "y": 0,
      "z": -5,
      "name": "Soil_Ash"
    },
    {
      "x": 2,
      "y": 1,
      "z": -5,
      "name": "Soil_Sand_Ashen"
    },
    {
      "x": 2,
      "y": 5,
      "z": -5,
      "name": "Rock_Magma_Cooled",
      "rotation": 1
    },
    {
      "x": 2,
      "y": 6,
      "z": -5,
      "name": "Rock_Magma_Cooled",
      "rotation": 1
    },
    {
      "x": 2,
      "y": 7,
      "z": -5,
      "name": "Plant_Vine_Wall_Poisoned",
      "support": 15,
      "rotation": 1
    },
    {
      "x": 2,
      "y": 0,
      "z": -4,
      "name": "Soil_Ash"
    },
    {
      "x": 2,
      "y": 1,
      "z": -4,
      "name": "Soil_Sand_Ashen"
    },
    {
      "x": 2,
      "y": 2,
      "z": -4,
      "name": "Plant_Bramble_Dead_Twisted"
    },
    {
      "x": 2,
      "y": 6,
      "z": -4,
      "name": "Rock_Magma_Cooled",
      "rotation": 1
    },
    {
      "x": 2,
      "y": 7,
      "z": -4,
      "name": "Rock_Magma_Cooled",
      "rotation": 1
    },
    {
      "x": 2,
      "y": 8,
      "z": -4,
      "name": "Plant_Vine_Wall_Poisoned",
      "support": 15,
      "rotation": 1
    },
    {
      "x": 2,
      "y": 0,
      "z": -3,
      "name": "Rock_Magma_Cooled"
    },
    {
      "x": 2,
      "y": 1,
      "z": -3,
      "name": "Rock_Magma_Cooled"
    },
    {
      "x": 2,
      "y": 0,
      "z": -2,
      "name": "Ore_Adamantite_Magma_Cracked"
    },
    {
      "x": 2,
      "y": 1,
      "z": -2,
      "name": "Soil_Sand_Ashen"
    },
    {
      "x": 2,
      "y": 2,
      "z": -2,
      "name": "Plant_Bramble_Dead_Twisted"
    },
    {
      "x": 2,
      "y": 0,
      "z": -1,
      "name": "Soil_Sand_Ashen"
    },
    {
      "x": 2,
      "y": 1,
      "z": -1,
      "name": "Soil_Ash"
    },
    {
      "x": 2,
      "y": 2,
      "z": -1,
      "name": "Soil_Ash"
    },
    {
      "x": 2,
      "y": 0,
      "z": 0,
      "name": "Soil_Sand_Ashen"
    },
    {
      "x": 2,
      "y": 1,
      "z": 0,
      "name": "Soil_Ash"
    },
    {
      "x": 2,
      "y": 2,
      "z": 0,
      "name": "Soil_Ash"
    },
    {
      "x": 2,
      "y": 0,
      "z": 1,
      "name": "Soil_Sand_Ashen"
    },
    {
      "x": 2,
      "y": 1,
      "z": 1,
      "name": "Soil_Ash"
    },
    {
      "x": 2,
      "y": 2,
      "z": 1,
      "name": "Soil_Ash"
    },
    {
      "x": 2,
      "y": 0,
      "z": 2,
      "name": "Rock_Magma_Cooled"
    },
    {
      "x": 2,
      "y": 1,
      "z": 2,
      "name": "Rock_Magma_Cooled"
    },
    {
      "x": 2,
      "y": 2,
      "z": 2,
      "name": "Rock_Magma_Cooled"
    },
    {
      "x": 2,
      "y": 3,
      "z": 2,
      "name": "Rock_Magma_Cooled"
    },
    {
      "x": 2,
      "y": 4,
      "z": 2,
      "name": "Rock_Magma_Cooled"
    },
    {
      "x": 2,
      "y": 0,
      "z": 3,
      "name": "Rock_Magma_Cooled"
    },
    {
      "x": 2,
      "y": 1,
      "z": 3,
      "name": "Rock_Magma_Cooled"
    },
    {
      "x": 2,
      "y": 2,
      "z": 3,
      "name": "Rock_Magma_Cooled"
    },
    {
      "x": 2,
      "y": 3,
      "z": 3,
      "name": "Rock_Magma_Cooled"
    },
    {
      "x": 2,
      "y": 4,
      "z": 3,
      "name": "Rock_Magma_Cooled"
    },
    {
      "x": 2,
      "y": 5,
      "z": 3,
      "name": "Ore_Adamantite_Magma_Cracked"
    },
    {
      "x": 2,
      "y": 0,
      "z": 4,
      "name": "Rock_Magma_Cooled"
    },
    {
      "x": 2,
      "y": 1,
      "z": 4,
      "name": "Rock_Magma_Cooled"
    },
    {
      "x": 2,
      "y": 2,
      "z": 4,
      "name": "Rock_Magma_Cooled"
    },
    {
      "x": 2,
      "y": 3,
      "z": 4,
      "name": "Rock_Magma_Cooled"
    },
    {
      "x": 2,
      "y": 4,
      "z": 4,
      "name": "Rock_Magma_Cooled"
    },
    {
      "x": 2,
      "y": 5,
      "z": 4,
      "name": "Rock_Magma_Cooled"
    },
    {
      "x": 2,
      "y": 6,
      "z": 4,
      "name": "Plant_Crop_Mushroom_Glowing_Purple"
    },
    {
      "x": 2,
      "y": 0,
      "z": 5,
      "name": "Rock_Magma_Cooled"
    },
    {
      "x": 2,
      "y": 1,
      "z": 5,
      "name": "Rock_Magma_Cooled"
    },
    {
      "x": 2,
      "y": 2,
      "z": 5,
      "name": "Rock_Magma_Cooled"
    },
    {
      "x": 2,
      "y": 3,
      "z": 5,
      "name": "Rock_Magma_Cooled"
    },
    {
      "x": 2,
      "y": 4,
      "z": 5,
      "name": "Rock_Magma_Cooled"
    },
    {
      "x": 2,
      "y": 0,
      "z": 6,
      "name": "Soil_Ash"
    },
    {
      "x": 2,
      "y": 1,
      "z": 6,
      "name": "Plant_Bramble_Dead_Twisted"
    },
    {
      "x": 2,
      "y": 3,
      "z": 6,
      "name": "Plant_Flower_Common_Poisoned2",
      "rotation": 4
    },
    {
      "x": 2,
      "y": 0,
      "z": 7,
      "name": "Soil_Sand_Ashen"
    },
    {
      "x": 3,
      "y": 17,
      "z": -15,
      "name": "Plant_Vine_Wall_Poisoned",
      "support": 15,
      "rotation": 3
    },
    {
      "x": 3,
      "y": 14,
      "z": -14,
      "name": "Rock_Magma_Cooled"
    },
    {
      "x": 3,
      "y": 15,
      "z": -14,
      "name": "Rock_Magma_Cooled"
    },
    {
      "x": 3,
      "y": 16,
      "z": -14,
      "name": "Rock_Magma_Cooled"
    },
    {
      "x": 3,
      "y": 17,
      "z": -14,
      "name": "Rock_Magma_Cooled"
    },
    {
      "x": 3,
      "y": 13,
      "z": -13,
      "name": "Ore_Adamantite_Magma_Cracked"
    },
    {
      "x": 3,
      "y": 14,
      "z": -13,
      "name": "Rock_Magma_Cooled"
    },
    {
      "x": 3,
      "y": 15,
      "z": -13,
      "name": "Rock_Magma_Cooled"
    },
    {
      "x": 3,
      "y": 16,
      "z": -13,
      "name": "Rock_Magma_Cooled"
    },
    {
      "x": 3,
      "y": 17,
      "z": -13,
      "name": "Ore_Adamantite_Magma_Cracked"
    },
    {
      "x": 3,
      "y": 12,
      "z": -12,
      "name": "Rock_Magma_Cooled"
    },
    {
      "x": 3,
      "y": 13,
      "z": -12,
      "name": "Rock_Magma_Cooled"
    },
    {
      "x": 3,
      "y": 14,
      "z": -12,
      "name": "Rock_Magma_Cooled"
    },
    {
      "x": 3,
      "y": 15,
      "z": -12,
      "name": "Ore_Adamantite_Magma_Cracked"
    },
    {
      "x": 3,
      "y": 11,
      "z": -11,
      "name": "Rock_Magma_Cooled"
    },
    {
      "x": 3,
      "y": 12,
      "z": -11,
      "name": "Rock_Magma_Cooled"
    },
    {
      "x": 3,
      "y": 13,
      "z": -11,
      "name": "Rock_Magma_Cooled"
    },
    {
      "x": 3,
      "y": 14,
      "z": -11,
      "name": "Rock_Magma_Cooled"
    },
    {
      "x": 3,
      "y": 15,
      "z": -11,
      "name": "Rock_Magma_Cooled"
    },
    {
      "x": 3,
      "y": 10,
      "z": -10,
      "name": "Rock_Magma_Cooled"
    },
    {
      "x": 3,
      "y": 11,
      "z": -10,
      "name": "Ore_Adamantite_Magma_Cracked"
    },
    {
      "x": 3,
      "y": 12,
      "z": -10,
      "name": "Rock_Magma_Cooled"
    },
    {
      "x": 3,
      "y": 13,
      "z": -10,
      "name": "Rock_Magma_Cooled"
    },
    {
      "x": 3,
      "y": 14,
      "z": -10,
      "name": "Rock_Magma_Cooled"
    },
    {
      "x": 3,
      "y": 9,
      "z": -9,
      "name": "Rock_Magma_Cooled"
    },
    {
      "x": 3,
      "y": 10,
      "z": -9,
      "name": "Rock_Magma_Cooled"
    },
    {
      "x": 3,
      "y": 11,
      "z": -9,
      "name": "Rock_Magma_Cooled"
    },
    {
      "x": 3,
      "y": 12,
      "z": -9,
      "name": "Ore_Adamantite_Magma_Cracked"
    },
    {
      "x": 3,
      "y": 13,
      "z": -9,
      "name": "Rock_Magma_Cooled"
    },
    {
      "x": 3,
      "y": 0,
      "z": -8,
      "name": "Soil_Ash"
    },
    {
      "x": 3,
      "y": 8,
      "z": -8,
      "name": "Rock_Magma_Cooled"
    },
    {
      "x": 3,
      "y": 9,
      "z": -8,
      "name": "Rock_Magma_Cooled"
    },
    {
      "x": 3,
      "y": 10,
      "z": -8,
      "name": "Rock_Magma_Cooled"
    },
    {
      "x": 3,
      "y": 11,
      "z": -8,
      "name": "Plant_Vine_Wall_Poisoned",
      "support": 15
    },
    {
      "x": 3,
      "y": 0,
      "z": -7,
      "name": "Soil_Sand_Ashen"
    },
    {
      "x": 3,
      "y": 1,
      "z": -7,
      "name": "Soil_Ash"
    },
    {
      "x": 3,
      "y": 0,
      "z": -6,
      "name": "Soil_Sand_Ashen"
    },
    {
      "x": 3,
      "y": 1,
      "z": -6,
      "name": "Soil_Sand_Ashen"
    },
    {
      "x": 3,
      "y": 0,
      "z": -5,
      "name": "Soil_Ash"
    },
    {
      "x": 3,
      "y": 1,
      "z": -5,
      "name": "Soil_Sand_Ashen"
    },
    {
      "x": 3,
      "y": 0,
      "z": -4,
      "name": "Soil_Ash"
    },
    {
      "x": 3,
      "y": 0,
      "z": -3,
      "name": "Soil_Sand_Ashen"
    },
    {
      "x": 3,
      "y": 0,
      "z": -2,
      "name": "Soil_Ash"
    },
    {
      "x": 3,
      "y": 1,
      "z": -2,
      "name": "Soil_Ash"
    },
    {
      "x": 3,
      "y": 0,
      "z": -1,
      "name": "Soil_Sand_Ashen"
    },
    {
      "x": 3,
      "y": 1,
      "z": -1,
      "name": "Soil_Sand_Ashen"
    },
    {
      "x": 3,
      "y": 2,
      "z": -1,
      "name": "Plant_Bramble_Dead_Twisted"
    },
    {
      "x": 3,
      "y": 0,
      "z": 0,
      "name": "Soil_Ash"
    },
    {
      "x": 3,
      "y": 1,
      "z": 0,
      "name": "Soil_Ash"
    },
    {
      "x": 3,
      "y": 2,
      "z": 0,
      "name": "Soil_Sand_Ashen"
    },
    {
      "x": 3,
      "y": 3,
      "z": 0,
      "name": "Plant_Flower_Poisoned_Orange"
    },
    {
      "x": 3,
      "y": 0,
      "z": 1,
      "name": "Soil_Sand_Ashen"
    },
    {
      "x": 3,
      "y": 1,
      "z": 1,
      "name": "Soil_Sand_Ashen"
    },
    {
      "x": 3,
      "y": 2,
      "z": 1,
      "name": "Soil_Ash"
    },
    {
      "x": 3,
      "y": 3,
      "z": 1,
      "name": "Plant_Crop_Mushroom_Glowing_Purple"
    },
    {
      "x": 3,
      "y": 0,
      "z": 2,
      "name": "Soil_Ash"
    },
    {
      "x": 3,
      "y": 1,
      "z": 2,
      "name": "Rock_Magma_Cooled"
    },
    {
      "x": 3,
      "y": 2,
      "z": 2,
      "name": "Rock_Magma_Cooled"
    },
    {
      "x": 3,
      "y": 0,
      "z": 3,
      "name": "Rock_Magma_Cooled"
    },
    {
      "x": 3,
      "y": 1,
      "z": 3,
      "name": "Rock_Magma_Cooled"
    },
    {
      "x": 3,
      "y": 2,
      "z": 3,
      "name": "Rock_Magma_Cooled"
    },
    {
      "x": 3,
      "y": 3,
      "z": 3,
      "name": "Rock_Magma_Cooled"
    },
    {
      "x": 3,
      "y": 4,
      "z": 3,
      "name": "Rock_Magma_Cooled"
    },
    {
      "x": 3,
      "y": 5,
      "z": 3,
      "name": "Rock_Magma_Cooled"
    },
    {
      "x": 3,
      "y": 0,
      "z": 4,
      "name": "Ore_Adamantite_Magma_Cracked"
    },
    {
      "x": 3,
      "y": 1,
      "z": 4,
      "name": "Rock_Magma_Cooled"
    },
    {
      "x": 3,
      "y": 2,
      "z": 4,
      "name": "Ore_Adamantite_Magma_Cracked"
    },
    {
      "x": 3,
      "y": 3,
      "z": 4,
      "name": "Rock_Magma_Cooled"
    },
    {
      "x": 3,
      "y": 4,
      "z": 4,
      "name": "Rock_Magma_Cooled"
    },
    {
      "x": 3,
      "y": 5,
      "z": 4,
      "name": "Rock_Magma_Cooled"
    },
    {
      "x": 3,
      "y": 6,
      "z": 4,
      "name": "Rock_Magma_Cooled"
    },
    {
      "x": 3,
      "y": 7,
      "z": 4,
      "name": "Plant_Vine_Wall_Poisoned",
      "support": 15,
      "rotation": 3
    },
    {
      "x": 3,
      "y": 0,
      "z": 5,
      "name": "Soil_Sand_Ashen"
    },
    {
      "x": 3,
      "y": 1,
      "z": 5,
      "name": "Soil_Sand_Ashen"
    },
    {
      "x": 3,
      "y": 2,
      "z": 5,
