{
  "version": 8,
  "blockIdVersion": 11,
  "anchorX": 0,
  "anchorY": 0,
  "anchorZ": 0,
  "blocks": [
    {
      "x": -10,
      "y": 21,
      "z": -11,
      "name": "Plant_Vine_Wall_Poisoned",
      "support": 15,
      "rotation": 3
    },
    {
      "x": -10,
      "y": 20,
      "z": -10,
      "name": "Plant_Vine_Wall_Poisoned",
      "support": 15,
      "rotation": 3
    },
    {
      "x": -10,
      "y": 19,
      "z": -9,
      "name": "Plant_Vine_Wall_Poisoned",
      "support": 15,
      "rotation": 3
    },
    {
      "x": -9,
      "y": 20,
      "z": -11,
      "name": "Rock_Magma_Cooled"
    },
    {
      "x": -9,
      "y": 21,
      "z": -11,
      "name": "Rock_Magma_Cooled"
    },
    {
      "x": -9,
      "y": 22,
      "z": -11,
      "name": "Plant_Moss_Rug_Pink",
      "support": 15
    },
    {
      "x": -9,
      "y": 19,
      "z": -10,
      "name": "Rock_Magma_Cooled"
    },
    {
      "x": -9,
      "y": 20,
      "z": -10,
      "name": "Rock_Magma_Cooled"
    },
    {
      "x": -9,
      "y": 21,
      "z": -10,
      "name": "Rock_Magma_Cooled"
    },
    {
      "x": -9,
      "y": 22,
      "z": -10,
      "name": "Plant_Moss_Rug_Pink",
      "support": 15
    },
    {
      "x": -9,
      "y": 17,
      "z": -9,
      "name": "Rock_Magma_Cooled"
    },
    {
      "x": -9,
      "y": 18,
      "z": -9,
      "name": "Ore_Adamantite_Magma_Cracked"
    },
    {
      "x": -9,
      "y": 19,
      "z": -9,
      "name": "Ore_Adamantite_Magma_Cracked"
    },
    {
      "x": -9,
      "y": 20,
      "z": -9,
      "name": "Plant_Moss_Rug_Pink",
      "support": 15
    },
    {
      "x": -9,
      "y": 18,
      "z": -8,
      "name": "Plant_Vine_Wall_Poisoned",
      "support": 15,
      "rotation": 3
    },
    {
      "x": -9,
      "y": 0,
      "z": 0,
      "name": "Soil_Sand_Ashen"
    },
    {
      "x": -9,
      "y": 0,
      "z": 1,
      "name": "Soil_Sand_Ashen"
    },
    {
      "x": -9,
      "y": 0,
      "z": 2,
      "name": "Soil_Sand_Ashen"
    },
    {
      "x": -9,
      "y": 13,
      "z": 11,
      "name": "Plant_Vine_Wall_Poisoned",
      "support": 15,
      "rotation": 3
    },
    {
      "x": -9,
      "y": 14,
      "z": 11,
      "name": "Plant_Vine_Wall_Poisoned",
      "support": 15,
      "rotation": 3
    },
    {
      "x": -8,
      "y": 18,
      "z": -11,
      "name": "Plant_Vine_Wall_Poisoned",
      "support": 15,
      "rotation": 2
    },
    {
      "x": -8,
      "y": 17,
      "z": -10,
      "name": "Plant_Vine_Wall_Poisoned",
      "support": 15,
      "rotation": 2
    },
    {
      "x": -8,
      "y": 18,
      "z": -10,
      "name": "Rock_Magma_Cooled"
    },
    {
      "x": -8,
      "y": 19,
      "z": -10,
      "name": "Rock_Magma_Cooled"
    },
    {
      "x": -8,
      "y": 20,
      "z": -10,
      "name": "Rock_Magma_Cooled"
    },
    {
      "x": -8,
      "y": 21,
      "z": -10,
      "name": "Plant_Moss_Rug_Pink",
      "support": 15
    },
    {
      "x": -8,
      "y": 16,
      "z": -9,
      "name": "Rock_Magma_Cooled"
    },
    {
      "x": -8,
      "y": 17,
      "z": -9,
      "name": "Rock_Magma_Cooled"
    },
    {
      "x": -8,
      "y": 18,
      "z": -9,
      "name": "Rock_Magma_Cooled"
    },
    {
      "x": -8,
      "y": 19,
      "z": -9,
      "name": "Ore_Adamantite_Magma_Cracked"
    },
    {
      "x": -8,
      "y": 20,
      "z": -9,
      "name": "Plant_Moss_Rug_Pink",
      "support": 15
    },
    {
      "x": -8,
      "y": 16,
      "z": -8,
      "name": "Rock_Magma_Cooled"
    },
    {
      "x": -8,
      "y": 17,
      "z": -8,
      "name": "Rock_Magma_Cooled"
    },
    {
      "x": -8,
      "y": 18,
      "z": -8,
      "name": "Rock_Magma_Cooled"
    },
    {
      "x": -8,
      "y": 19,
      "z": -8,
      "name": "Plant_Moss_Rug_Pink",
      "support": 15
    },
    {
      "x": -8,
      "y": 15,
      "z": -7,
      "name": "Rock_Magma_Cooled"
    },
    {
      "x": -8,
      "y": 16,
      "z": -7,
      "name": "Rock_Magma_Cooled"
    },
    {
      "x": -8,
      "y": 16,
      "z": -6,
      "name": "Plant_Vine_Wall_Poisoned",
      "support": 15,
      "rotation": 3
    },
    {
      "x": -8,
      "y": 0,
      "z": -1,
      "name": "Soil_Sand_Ashen"
    },
    {
      "x": -8,
      "y": 0,
      "z": 0,
      "name": "Soil_Sand_Ashen"
    },
    {
      "x": -8,
      "y": 1,
      "z": 0,
      "name": "Soil_Sand_Ashen"
    },
    {
      "x": -8,
      "y": 0,
      "z": 1,
      "name": "Soil_Sand_Ashen"
    },
    {
      "x": -8,
      "y": 1,
      "z": 1,
      "name": "Soil_Ash"
    },
    {
      "x": -8,
      "y": 0,
      "z": 2,
      "name": "Soil_Sand_Ashen"
    },
    {
      "x": -8,
      "y": 1,
      "z": 2,
      "name": "Soil_Ash"
    },
    {
      "x": -8,
      "y": 0,
      "z": 3,
      "name": "Soil_Sand_Ashen"
    },
    {
      "x": -8,
      "y": 11,
      "z": 10,
      "name": "Plant_Vine_Wall_Poisoned",
      "support": 15,
      "rotation": 3
    },
    {
      "x": -8,
      "y": 13,
      "z": 11,
      "name": "Rock_Magma_Cooled"
    },
    {
      "x": -8,
      "y": 14,
      "z": 11,
      "name": "Rock_Magma_Cooled"
    },
    {
      "x": -8,
      "y": 15,
      "z": 11,
      "name": "Plant_Moss_Rug_Pink",
      "support": 15
    },
    {
      "x": -8,
      "y": 13,
      "z": 12,
      "name": "Plant_Vine_Wall_Poisoned",
      "support": 15
    },
    {
      "x": -8,
      "y": 14,
      "z": 12,
      "name": "Plant_Vine_Wall_Poisoned",
      "support": 15
    },
    {
      "x": -7,
      "y": 18,
      "z": -10,
      "name": "Ore_Adamantite_Magma_Cracked"
    },
    {
      "x": -7,
      "y": 19,
      "z": -10,
      "name": "Plant_Moss_Rug_Pink",
      "support": 15
    },
    {
      "x": -7,
      "y": 15,
      "z": -9,
      "name": "Rock_Magma_Cooled"
    },
    {
      "x": -7,
      "y": 16,
      "z": -9,
      "name": "Rock_Magma_Cooled"
    },
    {
      "x": -7,
      "y": 17,
      "z": -9,
      "name": "Rock_Magma_Cooled"
    },
    {
      "x": -7,
      "y": 18,
      "z": -9,
      "name": "Plant_Moss_Rug_Pink",
      "support": 15
    },
    {
      "x": -7,
      "y": 13,
      "z": -8,
      "name": "Plant_Vine_Wall_Poisoned",
      "support": 15,
      "rotation": 3
    },
    {
      "x": -7,
      "y": 14,
      "z": -8,
      "name": "Rock_Magma_Cooled"
    },
    {
      "x": -7,
      "y": 15,
      "z": -8,
      "name": "Rock_Magma_Cooled"
    },
    {
      "x": -7,
      "y": 16,
      "z": -8,
      "name": "Rock_Magma_Cooled"
    },
    {
      "x": -7,
      "y": 17,
      "z": -8,
      "name": "Ore_Adamantite_Magma_Cracked"
    },
    {
      "x": -7,
      "y": 13,
      "z": -7,
      "name": "Rock_Magma_Cooled"
    },
    {
      "x": -7,
      "y": 14,
      "z": -7,
      "name": "Rock_Magma_Cooled"
    },
    {
      "x": -7,
      "y": 15,
      "z": -7,
      "name": "Rock_Magma_Cooled"
    },
    {
      "x": -7,
      "y": 16,
      "z": -7,
      "name": "Rock_Magma_Cooled"
    },
    {
      "x": -7,
      "y": 12,
      "z": -6,
      "name": "Plant_Vine_Wall_Poisoned",
      "support": 15,
      "rotation": 3
    },
    {
      "x": -7,
      "y": 13,
      "z": -6,
      "name": "Rock_Magma_Cooled"
    },
    {
      "x": -7,
      "y": 14,
      "z": -6,
      "name": "Rock_Magma_Cooled"
    },
    {
      "x": -7,
      "y": 15,
      "z": -6,
      "name": "Ore_Adamantite_Magma_Cracked"
    },
    {
      "x": -7,
      "y": 16,
      "z": -6,
      "name": "Rock_Magma_Cooled"
    },
    {
      "x": -7,
      "y": 14,
      "z": -5,
      "name": "Rock_Magma_Cooled"
    },
    {
      "x": -7,
      "y": 0,
      "z": -2,
      "name": "Soil_Sand_Ashen"
    },
    {
      "x": -7,
      "y": 0,
      "z": -1,
      "name": "Soil_Sand_Ashen"
    },
    {
      "x": -7,
      "y": 1,
      "z": -1,
      "name": "Soil_Sand_Ashen"
    },
    {
      "x": -7,
      "y": 0,
      "z": 0,
      "name": "Soil_Ash"
    },
    {
      "x": -7,
      "y": 1,
      "z": 0,
      "name": "Soil_Sand_Ashen"
    },
    {
      "x": -7,
      "y": 0,
      "z": 1,
      "name": "Soil_Ash"
    },
    {
      "x": -7,
      "y": 1,
      "z": 1,
      "name": "Soil_Sand_Ashen"
    },
    {
      "x": -7,
      "y": 2,
      "z": 1,
      "name": "Soil_Sand_Ashen"
    },
    {
      "x": -7,
      "y": 0,
      "z": 2,
      "name": "Soil_Ash"
    },
    {
      "x": -7,
      "y": 1,
      "z": 2,
      "name": "Soil_Sand_Ashen"
    },
    {
      "x": -7,
      "y": 0,
      "z": 3,
      "name": "Soil_Ash"
    },
    {
      "x": -7,
      "y": 1,
      "z": 3,
      "name": "Soil_Ash"
    },
    {
      "x": -7,
      "y": 0,
      "z": 4,
      "name": "Soil_Sand_Ashen"
    },
    {
      "x": -7,
      "y": 8,
      "z": 7,
      "name": "Plant_Vine_Wall_Poisoned",
      "support": 15,
      "rotation": 3
    },
    {
      "x": -7,
      "y": 9,
      "z": 8,
      "name": "Plant_Vine_Wall_Poisoned",
      "support": 15,
      "rotation": 3
    },
    {
      "x": -7,
      "y": 10,
      "z": 9,
      "name": "Rock_Magma_Cooled"
    },
    {
      "x": -7,
      "y": 11,
      "z": 9,
      "name": "Plant_Moss_Rug_Pink",
      "support": 15
    },
    {
      "x": -7,
      "y": 11,
      "z": 10,
      "name": "Ore_Adamantite_Magma_Cracked"
    },
    {
      "x": -7,
      "y": 12,
      "z": 10,
      "name": "Rock_Magma_Cooled"
    },
    {
      "x": -7,
      "y": 13,
      "z": 10,
      "name": "Plant_Moss_Rug_Pink",
      "support": 15
    },
    {
      "x": -7,
      "y": 12,
      "z": 11,
      "name": "Rock_Magma_Cooled"
    },
    {
      "x": -7,
      "y": 13,
      "z": 11,
      "name": "Rock_Magma_Cooled"
    },
    {
      "x": -7,
      "y": 13,
      "z": 12,
      "name": "Plant_Vine_Wall_Poisoned",
      "support": 15
    },
    {
      "x": -6,
      "y": 13,
      "z": -8,
      "name": "Rock_Magma_Cooled"
    },
    {
      "x": -6,
      "y": 14,
      "z": -8,
      "name": "Rock_Magma_Cooled"
    },
    {
      "x": -6,
      "y": 15,
      "z": -8,
      "name": "Rock_Magma_Cooled"
    },
    {
      "x": -6,
      "y": 16,
      "z": -8,
      "name": "Rock_Magma_Cooled"
    },
    {
      "x": -6,
      "y": 17,
      "z": -8,
      "name": "Plant_Moss_Rug_Pink",
      "support": 15
    },
    {
      "x": -6,
      "y": 13,
      "z": -7,
      "name": "Ore_Adamantite_Magma_Cracked"
    },
    {
      "x": -6,
      "y": 14,
      "z": -7,
      "name": "Rock_Magma_Cooled"
    },
    {
      "x": -6,
      "y": 15,
      "z": -7,
      "name": "Rock_Magma_Cooled"
    },
    {
      "x": -6,
      "y": 11,
      "z": -6,
      "name": "Rock_Magma_Cooled"
    },
    {
      "x": -6,
      "y": 12,
      "z": -6,
      "name": "Rock_Magma_Cooled"
    },
    {
      "x": -6,
      "y": 13,
      "z": -6,
      "name": "Rock_Magma_Cooled"
    },
    {
      "x": -6,
      "y": 14,
      "z": -6,
      "name": "Ore_Adamantite_Magma_Cracked"
    },
    {
      "x": -6,
      "y": 15,
      "z": -6,
      "name": "Ore_Adamantite_Magma_Cracked"
    },
    {
      "x": -6,
      "y": 10,
      "z": -5,
      "name": "Plant_Vine_Wall_Poisoned",
      "support": 15,
      "rotation": 3
    },
    {
      "x": -6,
      "y": 11,
      "z": -5,
      "name": "Rock_Magma_Cooled"
    },
    {
      "x": -6,
      "y": 12,
      "z": -5,
      "name": "Ore_Adamantite_Magma_Cracked"
    },
    {
      "x": -6,
      "y": 13,
      "z": -5,
      "name": "Rock_Magma_Cooled"
    },
    {
      "x": -6,
      "y": 14,
      "z": -5,
      "name": "Rock_Magma_Cooled"
    },
    {
      "x": -6,
      "y": 13,
      "z": -4,
      "name": "Rock_Magma_Cooled"
    },
    {
      "x": -6,
      "y": 14,
      "z": -4,
      "name": "Plant_Crop_Mushroom_Glowing_Purple"
    },
    {
      "x": -6,
      "y": 0,
      "z": -3,
      "name": "Soil_Sand_Ashen"
    },
    {
      "x": -6,
      "y": 0,
      "z": -2,
      "name": "Soil_Sand_Ashen"
    },
    {
      "x": -6,
      "y": 1,
      "z": -2,
      "name": "Soil_Ash"
    },
    {
      "x": -6,
      "y": 0,
      "z": -1,
      "name": "Soil_Ash"
    },
    {
      "x": -6,
      "y": 1,
      "z": -1,
      "name": "Soil_Sand_Ashen"
    },
    {
      "x": -6,
      "y": 2,
      "z": -1,
      "name": "Plant_Flower_Bushy_Violet"
    },
    {
      "x": -6,
      "y": 0,
      "z": 0,
      "name": "Soil_Sand_Ashen"
    },
    {
      "x": -6,
      "y": 1,
      "z": 0,
      "name": "Soil_Ash"
    },
    {
      "x": -6,
      "y": 2,
      "z": 0,
      "name": "Soil_Ash"
    },
    {
      "x": -6,
      "y": 0,
      "z": 1,
      "name": "Soil_Sand_Ashen"
    },
    {
      "x": -6,
      "y": 1,
      "z": 1,
      "name": "Soil_Sand_Ashen"
    },
    {
      "x": -6,
      "y": 2,
      "z": 1,
      "name": "Soil_Ash"
    },
    {
      "x": -6,
      "y": 3,
      "z": 1,
      "name": "Plant_Flower_Bushy_Violet"
    },
    {
      "x": -6,
      "y": 0,
      "z": 2,
      "name": "Soil_Ash"
    },
    {
      "x": -6,
      "y": 1,
      "z": 2,
      "name": "Soil_Ash"
    },
    {
      "x": -6,
      "y": 2,
      "z": 2,
      "name": "Soil_Sand_Ashen"
    },
    {
      "x": -6,
      "y": 0,
      "z": 3,
      "name": "Soil_Ash"
    },
    {
      "x": -6,
      "y": 1,
      "z": 3,
      "name": "Soil_Sand_Ashen"
    },
    {
      "x": -6,
      "y": 0,
      "z": 4,
      "name": "Soil_Sand_Ashen"
    },
    {
      "x": -6,
      "y": 1,
      "z": 4,
      "name": "Soil_Ash"
    },
    {
      "x": -6,
      "y": 2,
      "z": 4,
      "name": "Plant_Flower_Bushy_Violet"
    },
    {
      "x": -6,
      "y": 0,
      "z": 5,
      "name": "Soil_Ash"
    },
    {
      "x": -6,
      "y": 7,
      "z": 7,
      "name": "Plant_Vine_Wall_Poisoned",
      "support": 15,
      "rotation": 3
    },
    {
      "x": -6,
      "y": 8,
      "z": 7,
      "name": "Ore_Adamantite_Magma_Cracked"
    },
    {
      "x": -6,
      "y": 9,
      "z": 7,
      "name": "Plant_Moss_Rug_Pink",
      "support": 15
    },
    {
      "x": -6,
      "y": 9,
      "z": 8,
      "name": "Rock_Magma_Cooled"
    },
    {
      "x": -6,
      "y": 10,
      "z": 8,
      "name": "Rock_Magma_Cooled"
    },
    {
      "x": -6,
      "y": 11,
      "z": 8,
      "name": "Plant_Moss_Rug_Pink",
      "support": 15
    },
    {
      "x": -6,
      "y": 9,
      "z": 9,
      "name": "Rock_Magma_Cooled"
    },
    {
      "x": -6,
      "y": 10,
      "z": 9,
      "name": "Rock_Magma_Cooled"
    },
    {
      "x": -6,
      "y": 11,
      "z": 9,
      "name": "Ore_Adamantite_Magma"
    },
    {
      "x": -6,
      "y": 12,
      "z": 9,
      "name": "Plant_Moss_Rug_Pink",
      "support": 15
    },
    {
      "x": -6,
      "y": 10,
      "z": 10,
      "name": "Rock_Magma_Cooled"
    },
    {
      "x": -6,
      "y": 11,
      "z": 10,
      "name": "Ore_Adamantite_Magma_Cracked"
    },
    {
      "x": -6,
      "y": 12,
      "z": 10,
      "name": "Ore_Adamantite_Magma_Cracked"
    },
    {
      "x": -6,
      "y": 13,
      "z": 10,
      "name": "Plant_Moss_Rug_Pink",
      "support": 15
    },
    {
      "x": -6,
      "y": 12,
      "z": 11,
      "name": "Plant_Vine_Wall_Poisoned",
      "support": 15,
      "rotation": 1
    },
    {
      "x": -5,
      "y": 12,
      "z": -8,
      "name": "Rock_Magma_Cooled"
    },
    {
      "x": -5,
      "y": 13,
      "z": -8,
      "name": "Rock_Magma_Cooled"
    },
    {
      "x": -5,
      "y": 12,
      "z": -7,
      "name": "Rock_Magma_Cooled"
    },
    {
      "x": -5,
      "y": 13,
      "z": -7,
      "name": "Rock_Magma_Cooled"
    },
    {
      "x": -5,
      "y": 14,
      "z": -7,
      "name": "Rock_Magma_Cooled"
    },
    {
      "x": -5,
      "y": 11,
      "z": -6,
      "name": "Rock_Magma_Cooled"
    },
    {
      "x": -5,
      "y": 12,
      "z": -6,
      "name": "Rock_Magma_Cooled"
    },
    {
      "x": -5,
      "y": 13,
      "z": -6,
      "name": "Rock_Magma_Cooled"
    },
    {
      "x": -5,
      "y": 10,
      "z": -5,
      "name": "Rock_Magma_Cooled"
    },
    {
      "x": -5,
      "y": 11,
      "z": -5,
      "name": "Rock_Magma_Cooled"
    },
    {
      "x": -5,
      "y": 12,
      "z": -5,
      "name": "Rock_Magma_Cooled"
    },
    {
      "x": -5,
      "y": 13,
      "z": -5,
      "name": "Rock_Magma_Cooled"
    },
    {
      "x": -5,
      "y": 9,
      "z": -4,
      "name": "Plant_Vine_Wall_Poisoned",
      "support": 15,
      "rotation": 3
    },
    {
      "x": -5,
      "y": 10,
      "z": -4,
      "name": "Ore_Adamantite_Magma_Cracked"
    },
    {
      "x": -5,
      "y": 11,
      "z": -4,
      "name": "Ore_Adamantite_Magma_Cracked"
    },
    {
      "x": -5,
      "y": 12,
      "z": -4,
      "name": "Rock_Magma_Cooled"
    },
    {
      "x": -5,
      "y": 13,
      "z": -4,
      "name": "Ore_Adamantite_Magma_Cracked"
    },
    {
      "x": -5,
      "y": 0,
      "z": -3,
      "name": "Soil_Sand_Ashen"
    },
    {
      "x": -5,
      "y": 9,
      "z": -3,
      "name": "Rock_Magma_Cooled"
    },
    {
      "x": -5,
      "y": 0,
      "z": -2,
      "name": "Soil_Ash"
    },
    {
      "x": -5,
      "y": 1,
      "z": -2,
      "name": "Soil_Ash"
    },
    {
      "x": -5,
      "y": 2,
      "z": -2,
      "name": "Plant_Flower_Bushy_Violet"
    },
    {
      "x": -5,
      "y": 8,
      "z": -2,
      "name": "Plant_Vine_Wall_Poisoned",
      "support": 15,
      "rotation": 3
    },
    {
      "x": -5,
      "y": 0,
      "z": -1,
      "name": "Soil_Sand_Ashen"
    },
    {
      "x": -5,
      "y": 1,
      "z": -1,
      "name": "Soil_Sand_Ashen"
    },
    {
      "x": -5,
      "y": 2,
      "z": -1,
      "name": "Soil_Sand_Ashen"
    },
    {
      "x": -5,
      "y": 0,
      "z": 0,
      "name": "Soil_Ash"
    },
    {
      "x": -5,
      "y": 1,
      "z": 0,
      "name": "Soil_Ash"
    },
    {
      "x": -5,
      "y": 2,
      "z": 0,
      "name": "Soil_Sand_Ashen"
    },
    {
      "x": -5,
      "y": 6,
      "z": 0,
      "name": "Plant_Vine_Wall_Poisoned",
      "support": 15,
      "rotation": 3
    },
    {
      "x": -5,
      "y": 0,
      "z": 1,
      "name": "Soil_Ash"
    },
    {
      "x": -5,
      "y": 1,
      "z": 1,
      "name": "Soil_Ash"
    },
    {
      "x": -5,
      "y": 2,
      "z": 1,
      "name": "Soil_Sand_Ashen"
    },
    {
      "x": -5,
      "y": 0,
      "z": 2,
      "name": "Soil_Ash"
    },
    {
      "x": -5,
      "y": 1,
      "z": 2,
      "name": "Soil_Sand_Ashen"
    },
    {
      "x": -5,
      "y": 2,
      "z": 2,
      "name": "Soil_Sand_Ashen"
    },
    {
      "x": -5,
      "y": 3,
      "z": 2,
      "name": "Plant_Flower_Bushy_Violet"
    },
    {
      "x": -5,
      "y": 0,
      "z": 3,
      "name": "Soil_Ash"
    },
    {
      "x": -5,
      "y": 1,
      "z": 3,
      "name": "Soil_Ash"
    },
    {
      "x": -5,
      "y": 2,
      "z": 3,
      "name": "Soil_Ash"
    },
    {
      "x": -5,
      "y": 0,
      "z": 4,
      "name": "Soil_Sand_Ashen"
    },
    {
      "x": -5,
      "y": 1,
      "z": 4,
      "name": "Soil_Sand_Ashen"
    },
    {
      "x": -5,
      "y": 0,
      "z": 5,
      "name": "Soil_Ash"
    },
    {
      "x": -5,
      "y": 6,
      "z": 6,
      "name": "Plant_Vine_Wall_Poisoned",
      "support": 15,
      "rotation": 3
    },
    {
      "x": -5,
      "y": 7,
      "z": 6,
      "name": "Rock_Magma_Cooled"
    },
    {
      "x": -5,
      "y": 8,
      "z": 6,
      "name": "Rock_Magma_Cooled"
    },
    {
      "x": -5,
      "y": 9,
      "z": 6,
      "name": "Plant_Moss_Rug_Pink",
      "support": 15
    },
    {
      "x": -5,
      "y": 7,
      "z": 7,
      "name": "Rock_Magma_Cooled"
    },
    {
      "x": -5,
      "y": 8,
      "z": 7,
      "name": "Rock_Magma_Cooled"
    },
    {
      "x": -5,
      "y": 9,
      "z": 7,
      "name": "Plant_Moss_Rug_Pink",
      "support": 15
    },
    {
      "x": -5,
      "y": 7,
      "z": 8,
      "name": "Ore_Adamantite_Magma_Cracked"
    },
    {
      "x": -5,
      "y": 8,
      "z": 8,
      "name": "Rock_Magma_Cooled"
    },
    {
      "x": -5,
      "y": 9,
      "z": 8,
      "name": "Rock_Magma_Cooled"
    },
    {
      "x": -5,
      "y": 10,
      "z": 8,
      "name": "Plant_Moss_Rug_Pink",
      "support": 15
    },
    {
      "x": -5,
      "y": 9,
      "z": 9,
      "name": "Rock_Magma_Cooled"
    },
    {
      "x": -5,
      "y": 10,
      "z": 9,
      "name": "Rock_Magma_Cooled"
    },
    {
      "x": -5,
      "y": 11,
      "z": 9,
      "name": "Rock_Magma_Cooled"
    },
    {
      "x": -5,
      "y": 12,
      "z": 9,
      "name": "Plant_Moss_Rug_Pink",
      "support": 15
    },
    {
      "x": -5,
      "y": 10,
      "z": 10,
      "name": "Rock_Magma_Cooled"
    },
    {
      "x": -5,
      "y": 11,
      "z": 10,
      "name": "Plant_Moss_Rug_Pink",
      "support": 15
    },
    {
      "x": -4,
      "y": 12,
      "z": -8,
      "name": "Plant_Vine_Wall_Poisoned",
      "support": 15,
      "rotation": 2
    },
    {
      "x": -4,
      "y": 11,
      "z": -7,
      "name": "Ore_Adamantite_Magma_Cracked"
    },
    {
      "x": -4,
      "y": 12,
      "z": -7,
      "name": "Ore_Adamantite_Magma_Cracked"
    },
    {
      "x": -4,
      "y": 11,
      "z": -6,
      "name": "Rock_Magma_Cooled"
    },
    {
      "x": -4,
      "y": 12,
      "z": -6,
      "name": "Rock_Magma_Cooled"
    },
    {
      "x": -4,
      "y": 13,
      "z": -6,
      "name": "Ore_Adamantite_Magma_Cracked"
    },
    {
      "x": -4,
      "y": 9,
      "z": -5,
      "name": "Rock_Magma_Cooled"
    },
    {
      "x": -4,
      "y": 10,
      "z": -5,
      "name": "Rock_Magma_Cooled"
    },
    {
      "x": -4,
      "y": 11,
      "z": -5,
      "name": "Rock_Magma_Cooled"
    },
    {
      "x": -4,
      "y": 12,
      "z": -5,
      "name": "Ore_Adamantite_Magma_Cracked"
    },
    {
      "x": -4,
      "y": 13,
      "z": -5,
      "name": "Rock_Magma_Cooled"
    },
    {
      "x": -4,
      "y": 9,
      "z": -4,
      "name": "Rock_Magma_Cooled"
    },
    {
      "x": -4,
      "y": 10,
      "z": -4,
      "name": "Rock_Magma_Cooled"
    },
    {
      "x": -4,
      "y": 11,
      "z": -4,
      "name": "Rock_Magma_Cooled"
    },
    {
      "x": -4,
      "y": 12,
      "z": -4,
      "name": "Rock_Magma_Cooled"
    },
    {
      "x": -4,
      "y": 0,
      "z": -3,
      "name": "Soil_Ash"
    },
    {
      "x": -4,
      "y": 7,
      "z": -3,
      "name": "Rock_Magma_Cooled"
    },
    {
      "x": -4,
      "y": 8,
      "z": -3,
      "name": "Rock_Magma_Cooled"
    },
    {
      "x": -4,
      "y": 9,
      "z": -3,
      "name": "Rock_Magma_Cooled"
    },
    {
      "x": -4,
      "y": 10,
      "z": -3,
      "name": "Ore_Adamantite_Magma_Cracked"
    },
    {
      "x": -4,
      "y": 0,
      "z": -2,
      "name": "Soil_Sand_Ashen"
    },
    {
      "x": -4,
      "y": 1,
      "z": -2,
      "name": "Soil_Ash"
    },
    {
      "x": -4,
      "y": 6,
      "z": -2,
      "name": "Ore_Adamantite_Magma_Cracked"
    },
    {
      "x": -4,
      "y": 7,
      "z": -2,
      "name": "Rock_Magma_Cooled"
    },
    {
      "x": -4,
      "y": 8,
      "z": -2,
      "name": "Rock_Magma_Cooled"
    },
    {
      "x": -4,
      "y": 9,
      "z": -2,
      "name": "Rock_Magma_Cooled"
    },
    {
      "x": -4,
      "y": 0,
      "z": -1,
      "name": "Soil_Sand_Ashen"
    },
    {
      "x": -4,
      "y": 1,
      "z": -1,
      "name": "Soil_Ash"
    },
    {
      "x": -4,
      "y": 2,
      "z": -1,
      "name": "Plant_Flower_Bushy_Violet"
    },
    {
      "x": -4,
      "y": 5,
      "z": -1,
      "name": "Rock_Magma_Cooled"
    },
    {
      "x": -4,
      "y": 6,
      "z": -1,
      "name": "Rock_Magma_Cooled"
    },
    {
      "x": -4,
      "y": 7,
      "z": -1,
      "name": "Rock_Magma_Cooled"
    },
    {
      "x": -4,
      "y": 0,
      "z": 0,
      "name": "Soil_Ash"
    },
    {
      "x": -4,
      "y": 1,
      "z": 0,
      "name": "Soil_Sand_Ashen"
    },
    {
      "x": -4,
      "y": 2,
      "z": 0,
      "name": "Soil_Sand_Ashen"
    },
    {
      "x": -4,
      "y": 4,
      "z": 0,
      "name": "Ore_Adamantite_Magma_Cracked"
    },
    {
      "x": -4,
      "y": 5,
      "z": 0,
      "name": "Ore_Adamantite_Magma_Cracked"
    },
    {
      "x": -4,
      "y": 6,
      "z": 0,
      "name": "Rock_Magma_Cooled"
    },
    {
      "x": -4,
      "y": 7,
      "z": 0,
      "name": "Rock_Magma_Cooled"
    },
    {
      "x": -4,
      "y": 0,
      "z": 1,
      "name": "Soil_Sand_Ashen"
    },
    {
      "x": -4,
      "y": 1,
      "z": 1,
      "name": "Soil_Ash"
    },
    {
      "x": -4,
      "y": 2,
      "z": 1,
      "name": "Soil_Sand_Ashen"
    },
    {
      "x": -4,
      "y": 3,
      "z": 1,
      "name": "Plant_Bramble_Dead_Twisted"
    },
    {
      "x": -4,
      "y": 0,
      "z": 2,
      "name": "Soil_Ash"
    },
    {
      "x": -4,
      "y": 1,
      "z": 2,
      "name": "Soil_Ash"
    },
    {
      "x": -4,
      "y": 2,
      "z": 2,
      "name": "Soil_Ash"
    },
    {
      "x": -4,
      "y": 0,
      "z": 3,
      "name": "Soil_Ash"
    },
    {
      "x": -4,
      "y": 1,
      "z": 3,
      "name": "Soil_Sand_Ashen"
    },
    {
      "x": -4,
      "y": 0,
      "z": 4,
      "name": "Soil_Sand_Ashen"
    },
    {
      "x": -4,
      "y": 1,
      "z": 4,
      "name": "Soil_Sand_Ashen"
    },
    {
      "x": -4,
      "y": 2,
      "z": 4,
      "name": "Plant_Flower_Bushy_Violet"
    },
    {
      "x": -4,
      "y": 0,
      "z": 5,
      "name": "Soil_Ash"
    },
    {
      "x": -4,
      "y": 6,
      "z": 5,
      "name": "Plant_Vine_Wall_Poisoned",
      "support": 15,
      "rotation": 3
    },
    {
      "x": -4,
      "y": 0,
      "z": 6,
      "name": "Soil_Ash"
    },
    {
      "x": -4,
      "y": 6,
      "z": 6,
      "name": "Rock_Magma_Cooled"
    },
    {
      "x": -4,
      "y": 7,
      "z": 6,
      "name": "Rock_Magma_Cooled"
    },
    {
      "x": -4,
      "y": 8,
      "z": 6,
      "name": "Plant_Moss_Rug_Pink",
      "support": 15
    },
    {
      "x": -4,
      "y": 6,
      "z": 7,
      "name": "Ore_Adamantite_Magma_Cracked"
    },
    {
      "x": -4,
      "y": 7,
      "z": 7,
      "name": "Rock_Magma_Cooled"
    },
    {
      "x": -4,
      "y": 8,
      "z": 7,
      "name": "Rock_Magma_Cooled"
    },
    {
      "x": -4,
      "y": 9,
      "z": 7,
      "name": "Plant_Moss_Rug_Pink",
      "support": 15
    },
    {
      "x": -4,
      "y": 6,
      "z": 8,
      "name": "Rock_Magma_Cooled"
    },
    {
      "x": -4,
      "y": 7,
      "z": 8,
      "name": "Rock_Magma_Cooled"
    },
    {
      "x": -4,
      "y": 8,
      "z": 8,
      "name": "Rock_Magma_Cooled"
    },
    {
      "x": -4,
      "y": 9,
      "z": 8,
      "name": "Rock_Magma_Cooled"
    },
    {
      "x": -4,
      "y": 10,
      "z": 8,
      "name": "Plant_Moss_Rug_Pink",
      "support": 15
    },
    {
      "x": -4,
      "y": 8,
      "z": 9,
      "name": "Rock_Magma_Cooled"
    },
    {
      "x": -4,
      "y": 9,
      "z": 9,
      "name": "Rock_Magma_Cooled"
    },
    {
      "x": -4,
      "y": 10,
      "z": 9,
      "name": "Rock_Magma_Cooled"
    },
    {
      "x": -4,
      "y": 11,
      "z": 9,
      "name": "Plant_Moss_Rug_Pink",
      "support": 15
    },
    {
      "x": -4,
      "y": 10,
      "z": 10,
      "name": "Plant_Vine_Wall_Poisoned",
      "support": 15,
      "rotation": 1
    },
    {
      "x": -3,
      "y": 11,
      "z": -7,
      "name": "Plant_Vine_Wall_Poisoned",
      "support": 15,
      "rotation": 2
    },
    {
      "x": -3,
      "y": 10,
      "z": -6,
      "name": "Ore_Adamantite_Magma_Cracked"
    },
    {
      "x": -3,
      "y": 11,
      "z": -6,
      "name": "Rock_Magma_Cooled"
    },
    {
      "x": -3,
      "y": 12,
      "z": -6,
      "name": "Rock_Magma_Cooled"
    },
    {
      "x": -3,
      "y": 8,
      "z": -5,
      "name": "Rock_Magma_Cooled"
    },
    {
      "x": -3,
      "y": 9,
      "z": -5,
      "name": "Rock_Magma_Cooled"
    },
    {
      "x": -3,
      "y": 10,
      "z": -5,
      "name": "Rock_Magma_Cooled"
    },
    {
      "x": -3,
      "y": 11,
      "z": -5,
      "name": "Rock_Magma_Cooled"
    },
    {
      "x": -3,
      "y": 0,
      "z": -4,
      "name": "Soil_Ash"
    },
    {
      "x": -3,
      "y": 7,
      "z": -4,
      "name": "Rock_Magma_Cooled"
    },
    {
      "x": -3,
      "y": 8,
      "z": -4,
      "name": "Rock_Magma_Cooled"
    },
    {
      "x": -3,
      "y": 9,
      "z": -4,
      "name": "Rock_Magma_Cooled"
    },
    {
      "x": -3,
      "y": 10,
      "z": -4,
      "name": "Rock_Magma_Cooled"
    },
    {
      "x": -3,
      "y": 11,
      "z": -4,
      "name": "Rock_Magma_Cooled"
    },
    {
      "x": -3,
      "y": 0,
      "z": -3,
      "name": "Soil_Sand_Ashen"
    },
    {
      "x": -3,
      "y": 1,
      "z": -3,
      "name": "Soil_Sand_Ashen"
    },
    {
      "x": -3,
      "y": 6,
      "z": -3,
      "name": "Rock_Magma_Cooled"
    },
    {
      "x": -3,
      "y": 7,
      "z": -3,
      "name": "Rock_Magma_Cooled"
    },
    {
      "x": -3,
      "y": 8,
      "z": -3,
      "name": "Ore_Adamantite_Magma_Cracked"
    },
    {
      "x": -3,
      "y": 9,
      "z": -3,
      "name": "Rock_Magma_Cooled"
    },
    {
      "x": -3,
      "y": 10,
      "z": -3,
      "name": "Rock_Magma_Cooled"
    },
    {
      "x": -3,
      "y": 0,
      "z": -2,
      "name": "Soil_Ash"
    },
    {
      "x": -3,
      "y": 1,
      "z": -2,
      "name": "Soil_Sand_Ashen"
    },
    {
      "x": -3,
      "y": 2,
      "z": -2,
      "name": "Plant_Flower_Bushy_Violet"
    },
    {
      "x": -3,
      "y": 4,
      "z": -2,
      "name": "Rock_Magma_Cooled"
    },
    {
      "x": -3,
      "y": 5,
      "z": -2,
      "name": "Ore_Adamantite_Magma_Cracked"
    },
    {
      "x": -3,
      "y": 6,
      "z": -2,
      "name": "Rock_Magma_Cooled"
    },
    {
      "x": -3,
      "y": 7,
      "z": -2,
      "name": "Rock_Magma_Cooled"
    },
    {
      "x": -3,
      "y": 8,
      "z": -2,
      "name": "Rock_Magma_Cooled"
    },
    {
      "x": -3,
      "y": 9,
      "z": -2,
      "name": "Rock_Magma_Cooled"
    },
    {
      "x": -3,
      "y": 0,
      "z": -1,
      "name": "Soil_Ash"
    },
    {
      "x": -3,
      "y": 1,
      "z": -1,
      "name": "Soil_Sand_Ashen"
    },
    {
      "x": -3,
      "y": 3,
      "z": -1,
      "name": "Rock_Magma_Cooled"
    },
    {
      "x": -3,
      "y": 4,
      "z": -1,
      "name": "Rock_Magma_Cooled"
    },
    {
      "x": -3,
      "y": 5,
      "z": -1,
      "name": "Rock_Magma_Cooled"
    },
    {
      "x": -3,
      "y": 6,
      "z": -1,
      "name": "Rock_Magma_Cooled"
    },
    {
      "x": -3,
      "y": 7,
      "z": -1,
      "name": "Rock_Magma_Cooled"
    },
    {
      "x": -3,
      "y": 8,
      "z": -1,
      "name": "Rock_Magma_Cooled"
    },
    {
      "x": -3,
      "y": 0,
      "z": 0,
      "name": "Soil_Sand_Ashen"
    },
    {
      "x": -3,
      "y": 1,
      "z": 0,
      "name": "Soil_Ash"
    },
    {
      "x": -3,
      "y": 2,
      "z": 0,
      "name": "Ore_Adamantite_Magma_Cracked"
    },
    {
      "x": -3,
      "y": 3,
      "z": 0,
      "name": "Rock_Magma_Cooled"
    },
    {
      "x": -3,
      "y": 4,
      "z": 0,
      "name": "Rock_Magma_Cooled"
    },
    {
      "x": -3,
      "y": 5,
      "z": 0,
      "name": "Rock_Magma_Cooled"
    },
    {
      "x": -3,
      "y": 6,
      "z": 0,
      "name": "Rock_Magma_Cooled"
    },
    {
      "x": -3,
      "y": 7,
      "z": 0,
      "name": "Rock_Magma_Cooled"
    },
    {
      "x": -3,
      "y": 0,
      "z": 1,
      "name": "Soil_Sand_Ashen"
    },
    {
      "x": -3,
      "y": 1,
      "z": 1,
      "name": "Soil_Ash"
    },
    {
      "x": -3,
      "y": 2,
      "z": 1,
      "name": "Rock_Magma_Cooled"
    },
    {
      "x": -3,
      "y": 3,
      "z": 1,
      "name": "Ore_Adamantite_Magma_Cracked"
    },
    {
      "x": -3,
      "y": 4,
      "z": 1,
      "name": "Rock_Magma_Cooled"
    },
    {
      "x": -3,
      "y": 5,
      "z": 1,
      "name": "Rock_Magma_Cooled"
    },
    {
      "x": -3,
      "y": 6,
      "z": 1,
      "name": "Rock_Magma_Cooled"
    },
    {
      "x": -3,
      "y": 0,
      "z": 2,
      "name": "Soil_Sand_Ashen"
    },
    {
      "x": -3,
      "y": 1,
      "z": 2,
      "name": "Soil_Ash"
    },
    {
      "x": -3,
      "y": 3,
      "z": 2,
      "name": "Ore_Adamantite_Magma_Cracked"
    },
    {
      "x": -3,
      "y": 4,
      "z": 2,
      "name": "Rock_Magma_Cooled"
    },
    {
      "x": -3,
      "y": 5,
      "z": 2,
      "name": "Ore_Adamantite_Magma_Cracked"
    },
    {
      "x": -3,
      "y": 0,
      "z": 3,
      "name": "Soil_Sand_Ashen"
    },
    {
      "x": -3,
      "y": 1,
      "z": 3,
      "name": "Soil_Ash"
    },
    {
      "x": -3,
      "y": 2,
      "z": 3,
      "name": "Plant_Bramble_Dead_Twisted"
    },
    {
      "x": -3,
      "y": 0,
      "z": 4,
      "name": "Soil_Sand_Ashen"
    },
    {
      "x": -3,
      "y": 1,
      "z": 4,
      "name": "Soil_Ash"
    },
    {
      "x": -3,
      "y": 4,
      "z": 4,
      "name": "Rock_Magma_Cooled"
    },
    {
      "x": -3,
      "y": 0,
      "z": 5,
      "name": "Soil_Sand_Ashen"
    },
    {
      "x": -3,
      "y": 1,
      "z": 5,
      "name": "Soil_Ash"
    },
    {
      "x": -3,
      "y": 4,
      "z": 5,
      "name": "Rock_Magma_Cooled"
    },
    {
      "x": -3,
      "y": 5,
      "z": 5,
      "name": "Rock_Magma_Cooled"
    },
    {
      "x": -3,
      "y": 6,
      "z": 5,
      "name": "Rock_Magma_Cooled"
    },
    {
      "x": -3,
      "y": 7,
      "z": 5,
      "name": "Rock_Magma_Cooled"
    },
    {
      "x": -3,
      "y": 8,
      "z": 5,
      "name": "Plant_Moss_Rug_Pink",
      "support": 15
    },
    {
      "x": -3,
      "y": 0,
      "z": 6,
      "name": "Soil_Sand_Ashen"
    },
    {
      "x": -3,
      "y": 1,
      "z": 6,
      "name": "Soil_Sand_Ashen"
    },
    {
      "x": -3,
      "y": 5,
      "z": 6,
      "name": "Rock_Magma_Cooled"
    },
    {
      "x": -3,
      "y": 6,
      "z": 6,
      "name": "Rock_Magma_Cooled"
    },
    {
      "x": -3,
      "y": 7,
      "z": 6,
      "name": "Rock_Magma_Cooled"
    },
    {
      "x": -3,
      "y": 8,
      "z": 6,
      "name": "Plant_Moss_Rug_Pink",
      "support": 15
    },
    {
      "x": -3,
      "y": 0,
      "z": 7,
      "name": "Soil_Ash"
    },
    {
      "x": -3,
      "y": 5,
      "z": 7,
      "name": "Rock_Magma_Cooled"
    },
    {
      "x": -3,
      "y": 6,
      "z": 7,
      "name": "Rock_Magma_Cooled"
    },
    {
      "x": -3,
      "y": 7,
      "z": 7,
      "name": "Rock_Magma_Cooled"
    },
    {
      "x": -3,
      "y": 8,
      "z": 7,
      "name": "Rock_Magma_Cooled"
    },
    {
      "x": -3,
      "y": 9,
      "z": 7,
      "name": "Plant_Moss_Rug_Pink",
      "support": 15
    },
    {
      "x": -3,
      "y": 6,
      "z": 8,
      "name": "Rock_Magma_Cooled"
    },
    {
      "x": -3,
      "y": 7,
      "z": 8,
      "name": "Rock_Magma_Cooled"
    },
    {
      "x": -3,
      "y": 8,
      "z": 8,
      "name": "Plant_Vine_Wall_Poisoned",
      "support": 15,
      "rotation": 1
    },
    {
      "x": -3,
      "y": 9,
      "z": 9,
      "name": "Plant_Vine_Wall_Poisoned",
      "support": 15,
      "rotation": 1
    },
    {
      "x": -2,
      "y": 0,
      "z": -5,
      "name": "Soil_Ash"
    },
    {
      "x": -2,
      "y": 8,
      "z": -5,
      "name": "Rock_Magma_Cooled"
    },
    {
      "x": -2,
      "y": 9,
      "z": -5,
      "name": "Rock_Magma_Cooled"
    },
    {
      "x": -2,
      "y": 10,
      "z": -5,
      "name": "Rock_Magma_Cooled"
    },
    {
      "x": -2,
      "y": 0,
      "z": -4,
      "name": "Soil_Ash"
    },
    {
      "x": -2,
      "y": 1,
      "z": -4,
      "name": "Soil_Ash"
    },
    {
      "x": -2,
      "y": 5,
      "z": -4,
      "name": "Rock_Magma_Cooled"
    },
    {
      "x": -2,
      "y": 6,
      "z": -4,
      "name": "Rock_Magma_Cooled"
    },
    {
      "x": -2,
      "y": 7,
      "z": -4,
      "name": "Ore_Adamantite_Magma_Cracked"
    },
    {
      "x": -2,
      "y": 8,
      "z": -4,
      "name": "Ore_Adamantite_Magma_Cracked"
    },
    {
      "x": -2,
      "y": 9,
      "z": -4,
      "name": "Rock_Magma_Cooled"
    },
    {
      "x": -2,
      "y": 10,
      "z": -4,
      "name": "Rock_Magma_Cooled"
    },
    {
      "x": -2,
      "y": 11,
      "z": -4,
      "name": "Plant_Crop_Mushroom_Glowing_Purple"
    },
    {
      "x": -2,
      "y": 0,
      "z": -3,
      "name": "Soil_Sand_Ashen"
    },
    {
      "x": -2,
      "y": 1,
      "z": -3,
      "name": "Soil_Ash"
    },
    {
      "x": -2,
      "y": 2,
      "z": -3,
      "name": "Plant_Bramble_Dead_Twisted"
    },
    {
      "x": -2,
      "y": 5,
      "z": -3,
      "name": "Rock_Magma_Cooled"
    },
    {
      "x": -2,
      "y": 6,
      "z": -3,
      "name": "Rock_Magma_Cooled"
    },
    {
      "x": -2,
      "y": 7,
      "z": -3,
      "name": "Ore_Adamantite_Magma_Cracked"
    },
    {
      "x": -2,
      "y": 8,
      "z": -3,
      "name": "Ore_Adamantite_Magma_Cracked"
    },
    {
      "x": -2,
      "y": 9,
      "z": -3,
      "name": "Rock_Magma_Cooled"
    },
    {
      "x": -2,
      "y": 0,
      "z": -2,
      "name": "Soil_Sand_Ashen"
    },
    {
      "x": -2,
      "y": 1,
      "z": -2,
      "name": "Soil_Ash"
    },
    {
      "x": -2,
      "y": 2,
      "z": -2,
      "name": "Soil_Ash"
    },
    {
      "x": -2,
      "y": 3,
      "z": -2,
      "name": "Rock_Magma_Cooled"
    },
    {
      "x": -2,
      "y": 4,
      "z": -2,
      "name": "Rock_Magma_Cooled"
    },
    {
      "x": -2,
      "y": 5,
      "z": -2,
      "name": "Rock_Magma_Cooled"
    },
    {
      "x": -2,
      "y": 6,
      "z": -2,
      "name": "Rock_Magma_Cooled"
    },
    {
      "x": -2,
      "y": 7,
      "z": -2,
      "name": "Rock_Magma_Cooled"
    },
    {
      "x": -2,
      "y": 8,
      "z": -2,
      "name": "Rock_Magma_Cooled"
    },
    {
      "x": -2,
      "y": 9,
      "z": -2,
      "name": "Rock_Magma_Cooled"
    },
    {
      "x": -2,
      "y": 0,
      "z": -1,
      "name": "Soil_Sand_Ashen"
    },
    {
      "x": -2,
      "y": 1,
      "z": -1,
      "name": "Soil_Sand_Ashen"
    },
    {
      "x": -2,
      "y": 2,
      "z": -1,
      "name": "Soil_Ash"
    },
    {
      "x": -2,
      "y": 3,
      "z": -1,
      "name": "Rock_Magma_Cooled"
    },
    {
      "x": -2,
      "y": 4,
      "z": -1,
      "name": "Rock_Magma_Cooled"
    },
    {
      "x": -2,
      "y": 5,
      "z": -1,
      "name": "Rock_Magma_Cooled"
    },
    {
      "x": -2,
      "y": 6,
      "z": -1,
      "name": "Ore_Adamantite_Magma_Cracked"
    },
    {
      "x": -2,
      "y": 7,
      "z": -1,
      "name": "Rock_Magma_Cooled"
    },
    {
      "x": -2,
      "y": 8,
      "z": -1,
      "name": "Rock_Magma_Cooled"
    },
    {
      "x": -2,
      "y": 9,
      "z": -1,
      "name": "Plant_Crop_Mushroom_Glowing_Purple"
    },
    {
      "x": -2,
      "y": 0,
      "z": 0,
      "name": "Rock_Magma_Cooled"
    },
    {
      "x": -2,
      "y": 1,
      "z": 0,
      "name": "Rock_Magma_Cooled"
    },
    {
      "x": -2,
      "y": 2,
      "z": 0,
      "name": "Rock_Magma_Cooled"
    },
    {
      "x": -2,
      "y": 3,
      "z": 0,
      "name": "Rock_Magma_Cooled"
    },
    {
      "x": -2,
      "y": 4,
      "z": 0,
      "name": "Rock_Magma_Cooled"
    },
    {
      "x": -2,
      "y": 5,
      "z": 0,
      "name": "Rock_Magma_Cooled"
    },
    {
      "x": -2,
      "y": 6,
      "z": 0,
      "name": "Rock_Magma_Cooled"
    },
    {
      "x": -2,
      "y": 7,
      "z": 0,
      "name": "Rock_Magma_Cooled"
    },
    {
      "x": -2,
      "y": 0,
      "z": 1,
      "name": "Rock_Magma_Cooled"
    },
    {
      "x": -2,
      "y": 1,
      "z": 1,
      "name": "Rock_Magma_Cooled"
    },
    {
      "x": -2,
      "y": 2,
      "z": 1,
      "name": "Ore_Adamantite_Magma_Cracked"
    },
    {
      "x": -2,
      "y": 3,
      "z": 1,
      "name": "Rock_Magma_Cooled"
    },
    {
      "x": -2,
      "y": 4,
      "z": 1,
      "name": "Ore_Adamantite_Magma_Cracked"
    },
    {
      "x": -2,
      "y": 5,
      "z": 1,
      "name": "Rock_Magma_Cooled"
    },
    {
      "x": -2,
      "y": 6,
      "z": 1,
      "name": "Rock_Magma_Cooled"
    },
    {
      "x": -2,
      "y": 7,
      "z": 1,
      "name": "Rock_Magma_Cooled"
    },
    {
      "x": -2,
      "y": 19,
      "z": 1,
      "name": "Plant_Vine_Wall_Poisoned",
      "support": 15,
      "rotation": 3
    },
    {
      "x": -2,
      "y": 20,
      "z": 1,
      "name": "Plant_Vine_Wall_Poisoned",
      "support": 15,
      "rotation": 3
    },
    {
      "x": -2,
      "y": 0,
      "z": 2,
      "name": "Rock_Magma_Cooled"
    },
    {
      "x": -2,
      "y": 1,
      "z": 2,
      "name": "Rock_Magma_Cooled"
    },
    {
      "x": -2,
      "y": 2,
      "z": 2,
      "name": "Ore_Adamantite_Magma_Cracked"
    },
    {
      "x": -2,
      "y": 3,
      "z": 2,
      "name": "Ore_Adamantite_Magma_Cracked"
    },
    {
      "x": -2,
      "y": 4,
      "z": 2,
      "name": "Rock_Magma_Cooled"
    },
    {
      "x": -2,
      "y": 5,
      "z": 2,
      "name": "Rock_Magma_Cooled"
    },
    {
      "x": -2,
      "y": 6,
      "z": 2,
      "name": "Rock_Magma_Cooled"
    },
    {
      "x": -2,
      "y": 20,
      "z": 2,
      "name": "Plant_Vine_Wall_Poisoned",
      "support": 15,
      "rotation": 3
    },
    {
      "x": -2,
      "y": 21,
      "z": 2,
      "name": "Rock_Magma_Cooled"
    },
    {
      "x": -2,
      "y": 22,
      "z": 2,
      "name": "Plant_Moss_Rug_Pink",
      "support": 15
    },
    {
      "x": -2,
      "y": 0,
      "z": 3,
      "name": "Rock_Magma_Cooled"
    },
    {
      "x": -2,
      "y": 1,
      "z": 3,
      "name": "Ore_Adamantite_Magma_Cracked"
    },
    {
      "x": -2,
      "y": 2,
      "z": 3,
      "name": "Ore_Adamantite_Magma_Cracked"
    },
    {
      "x": -2,
      "y": 3,
      "z": 3,
      "name": "Ore_Adamantite_Magma_Cracked"
    },
    {
      "x": -2,
      "y": 4,
      "z": 3,
      "name": "Rock_Magma_Cooled"
    },
    {
      "x": -2,
      "y": 5,
      "z": 3,
      "name": "Ore_Adamantite_Magma_Cracked"
    },
    {
      "x": -2,
      "y": 21,
      "z": 3,
      "name": "Rock_Magma_Cooled"
    },
    {
      "x": -2,
      "y": 22,
      "z": 3,
      "name": "Rock_Magma_Cooled"
    },
    {
      "x": -2,
      "y": 23,
      "z": 3,
      "name": "Plant_Moss_Rug_Pink",
      "support": 15
    },
    {
      "x": -2,
      "y": 0,
      "z": 4,
      "name": "Soil_Ash"
    },
    {
      "x": -2,
      "y": 1,
      "z": 4,
      "name": "Rock_Magma_Cooled"
    },
    {
      "x": -2,
      "y": 2,
      "z": 4,
      "name": "Rock_Magma_Cooled"
    },
    {
      "x": -2,
      "y": 3,
      "z": 4,
      "name": "Rock_Magma_Cooled"
    },
    {
      "x": -2,
      "y": 4,
      "z": 4,
      "name": "Rock_Magma_Cooled"
    },
    {
      "x": -2,
      "y": 5,
      "z": 4,
      "name": "Rock_Magma_Cooled"
    },
    {
      "x": -2,
      "y": 22,
      "z": 4,
      "name": "Plant_Vine_Wall_Poisoned",
      "support": 15
    },
    {
      "x": -2,
      "y": 0,
      "z": 5,
      "name": "Soil_Sand_Ashen"
    },
    {
      "x": -2,
      "y": 1,
      "z": 5,
      "name": "Soil_Ash"
    },
    {
      "x": -2,
      "y": 2,
      "z": 5,
      "name": "Soil_Ash"
    },
    {
      "x": -2,
      "y": 3,
      "z": 5,
      "name": "Rock_Magma_Cooled"
    },
    {
      "x": -2,
      "y": 4,
      "z": 5,
      "name": "Ore_Adamantite_Magma_Cracked"
    },
    {
      "x": -2,
      "y": 5,
      "z": 5,
      "name": "Rock_Magma_Cooled"
    },
    {
      "x": -2,
      "y": 6,
      "z": 5,
      "name": "Rock_Magma_Cooled"
    },
    {
      "x": -2,
      "y": 7,
      "z": 5,
      "name": "Plant_Moss_Rug_Pink",
      "support": 15
    },
    {
      "x": -2,
      "y": 0,
      "z": 6,
      "name": "Soil_Sand_Ashen"
    },
    {
      "x": -2,
      "y": 1,
      "z": 6,
      "name": "Soil_Sand_Ashen"
    },
    {
      "x": -2,
      "y": 4,
      "z": 6,
      "name": "Rock_Magma_Cooled"
    },
    {
      "x": -2,
      "y": 5,
      "z": 6,
      "name": "Rock_Magma_Cooled"
    },
    {
      "x": -2,
      "y": 6,
      "z": 6,
      "name": "Rock_Magma_Cooled"
    },
    {
      "x": -2,
      "y": 0,
      "z": 7,
      "name": "Soil_Sand_Ashen"
    },
    {
      "x": -2,
      "y": 1,
      "z": 7,
      "name": "Soil_Ash"
    },
    {
      "x": -2,
      "y": 2,
      "z": 7,
      "name": "Plant_Flower_Bushy_Violet"
    },
    {
      "x": -2,
      "y": 5,
      "z": 7,
      "name": "Rock_Magma_Cooled"
    },
    {
      "x": -2,
      "y": 6,
      "z": 7,
      "name": "Rock_Magma_Cooled"
    },
    {
      "x": -2,
      "y": 0,
      "z": 8,
      "name": "Soil_Sand_Ashen"
    },
    {
      "x": -2,
      "y": 6,
      "z": 8,
      "name": "Rock_Magma_Cooled"
    },
    {
      "x": -2,
      "y": 7,
      "z": 8,
      "name": "Rock_Magma_Cooled"
    },
    {
      "x": -1,
      "y": 0,
      "z": -6,
      "name": "Soil_Ash"
    },
    {
      "x": -1,
      "y": 0,
      "z": -5,
      "name": "Soil_Sand_Ashen"
    },
    {
      "x": -1,
      "y": 1,
      "z": -5,
      "name": "Soil_Sand_Ashen"
    },
    {
      "x": -1,
      "y": 7,
      "z": -5,
      "name": "Rock_Magma_Cooled"
    },
    {
      "x": -1,
      "y": 8,
      "z": -5,
      "name": "Ore_Adamantite_Magma_Cracked"
    },
    {
      "x": -1,
      "y": 0,
      "z": -4,
      "name": "Soil_Sand_Ashen"
    },
    {
      "x": -1,
      "y": 1,
      "z": -4,
      "name": "Soil_Ash"
    },
    {
      "x": -1,
      "y": 2,
      "z": -4,
      "name": "Plant_Flower_Bushy_Violet"
    },
    {
      "x": -1,
      "y": 5,
      "z": -4,
      "name": "Ore_Adamantite_Magma_Cracked"
    },
    {
      "x": -1,
      "y": 6,
      "z": -4,
      "name": "Ore_Adamantite_Magma_Cracked"
    },
    {
      "x": -1,
      "y": 7,
      "z": -4,
      "name": "Rock_Magma_Cooled"
    },
    {
      "x": -1,
      "y": 8,
      "z": -4,
      "name": "Rock_Magma_Cooled"
    },
    {
      "x": -1,
      "y": 9,
      "z": -4,
      "name": "Rock_Magma_Cooled"
    },
    {
      "x": -1,
      "y": 10,
      "z": -4,
      "name": "Rock_Magma_Cooled"
    },
    {
      "x": -1,
      "y": 0,
      "z": -3,
      "name": "Soil_Ash"
    },
    {
      "x": -1,
      "y": 1,
      "z": -3,
      "name": "Soil_Sand_Ashen"
    },
    {
      "x": -1,
      "y": 2,
      "z": -3,
      "name": "Soil_Ash"
    },
    {
      "x": -1,
      "y": 3,
      "z": -3,
      "name": "Plant_Flower_Bushy_Poisoned"
    },
    {
      "x": -1,
      "y": 4,
      "z": -3,
      "name": "Rock_Magma_Cooled"
    },
    {
      "x": -1,
      "y": 5,
      "z": -3,
      "name": "Rock_Magma_Cooled"
    },
    {
      "x": -1,
      "y": 6,
      "z": -3,
      "name": "Rock_Magma_Cooled"
    },
    {
      "x": -1,
      "y": 7,
      "z": -3,
      "name": "Ore_Adamantite_Magma_Cracked"
    },
    {
      "x": -1,
      "y": 8,
      "z": -3,
      "name": "Ore_Adamantite_Magma_Cracked"
    },
    {
      "x": -1,
      "y": 9,
      "z": -3,
      "name": "Rock_Magma_Cooled"
    },
    {
      "x": -1,
      "y": 0,
      "z": -2,
      "name": "Soil_Ash"
    },
    {
      "x": -1,
      "y": 1,
      "z": -2,
      "name": "Soil_Ash"
    },
    {
      "x": -1,
      "y": 2,
      "z": -2,
      "name": "Soil_Ash"
    },
    {
      "x": -1,
      "y": 3,
      "z": -2,
      "name": "Rock_Magma_Cooled"
    },
    {
      "x": -1,
      "y": 4,
      "z": -2,
      "name": "Rock_Magma_Cooled"
    },
    {
      "x": -1,
      "y": 5,
      "z": -2,
      "name": "Rock_Magma_Cooled"
    },
    {
      "x": -1,
      "y": 6,
      "z": -2,
      "name": "Rock_Magma_Cooled"
    },
    {
      "x": -1,
      "y": 7,
      "z": -2,
      "name": "Rock_Magma_Cooled"
    },
    {
      "x": -1,
      "y": 8,
      "z": -2,
      "name": "Rock_Magma_Cooled"
    },
    {
      "x": -1,
      "y": 9,
      "z": -2,
      "name": "Rock_Magma_Cooled"
    },
    {
      "x": -1,
      "y": 0,
      "z": -1,
      "name": "Soil_Sand_Ashen"
    },
    {
      "x": -1,
      "y": 1,
      "z": -1,
      "name": "Rock_Magma_Cooled"
    },
    {
      "x": -1,
      "y": 2,
      "z": -1,
      "name": "Rock_Magma_Cooled"
    },
    {
      "x": -1,
      "y": 3,
      "z": -1,
      "name": "Rock_Magma_Cooled"
    },
    {
      "x": -1,
      "y": 4,
      "z": -1,
      "name": "Rock_Magma_Cooled"
    },
    {
      "x": -1,
      "y": 5,
      "z": -1,
      "name": "Rock_Magma_Cooled"
    },
    {
      "x": -1,
      "y": 6,
      "z": -1,
      "name": "Rock_Magma_Cooled"
    },
    {
      "x": -1,
      "y": 7,
      "z": -1,
      "name": "Rock_Magma_Cooled"
    },
    {
      "x": -1,
      "y": 8,
      "z": -1,
      "name": "Rock_Magma_Cooled"
    },
    {
      "x": -1,
      "y": 9,
      "z": -1,
      "name": "Rock_Magma_Cooled"
    },
    {
      "x": -1,
      "y": 0,
      "z": 0,
      "name": "Rock_Magma_Cooled"
    },
    {
      "x": -1,
      "y": 1,
      "z": 0,
      "name": "Rock_Magma_Cooled"
    },
    {
      "x": -1,
      "y": 2,
      "z": 0,
      "name": "Rock_Magma_Cooled"
    },
    {
      "x": -1,
      "y": 3,
      "z": 0,
      "name": "Ore_Adamantite_Magma_Cracked"
    },
    {
      "x": -1,
      "y": 4,
      "z": 0,
      "name": "Rock_Magma_Cooled"
    },
    {
      "x": -1,
      "y": 5,
      "z": 0,
      "name": "Rock_Magma_Cooled"
    },
    {
      "x": -1,
      "y": 6,
      "z": 0,
      "name": "Rock_Magma_Cooled"
    },
    {
      "x": -1,
      "y": 7,
      "z": 0,
      "name": "Rock_Magma_Cooled"
    },
    {
      "x": -1,
      "y": 8,
      "z": 0,
      "name": "Rock_Magma_Cooled"
    },
    {
      "x": -1,
      "y": 19,
      "z": 0,
      "name": "Plant_Vine_Wall_Poisoned",
      "support": 15,
      "rotation": 3
    },
    {
      "x": -1,
      "y": 0,
      "z": 1,
      "name": "Rock_Magma_Cooled"
    },
    {
      "x": -1,
      "y": 1,
      "z": 1,
      "name": "Rock_Magma_Cooled"
    },
    {
      "x": -1,
      "y": 2,
      "z": 1,
      "name": "Rock_Magma_Cooled"
    },
    {
      "x": -1,
      "y": 3,
      "z": 1,
      "name": "Ore_Adamantite_Magma_Cracked"
    },
    {
      "x": -1,
      "y": 4,
      "z": 1,
      "name": "Rock_Magma_Cooled"
    },
    {
      "x": -1,
      "y": 5,
      "z": 1,
      "name": "Rock_Magma_Cooled"
    },
    {
      "x": -1,
      "y": 6,
      "z": 1,
      "name": "Rock_Magma_Cooled"
    },
    {
      "x": -1,
      "y": 7,
      "z": 1,
      "name": "Rock_Magma_Cooled"
    },
    {
      "x": -1,
      "y": 8,
      "z": 1,
      "name": "Plant_Crop_Mushroom_Glowing_Purple"
    },
    {
      "x": -1,
      "y": 19,
      "z": 1,
      "name": "Rock_Magma_Cooled"
    },
    {
      "x": -1,
      "y": 20,
      "z": 1,
      "name": "Rock_Magma_Cooled"
    },
    {
      "x": -1,
      "y": 21,
      "z": 1,
      "name": "Plant_Moss_Rug_Pink",
      "support": 15
    },
    {
      "x": -1,
      "y": 0,
      "z": 2,
      "name": "Ore_Adamantite_Magma_Cracked"
    },
    {
      "x": -1,
      "y": 1,
      "z": 2,
      "name": "Rock_Magma_Cooled"
    },
    {
      "x": -1,
      "y": 2,
      "z": 2,
      "name": "Rock_Magma_Cooled"
    },
    {
      "x": -1,
      "y": 3,
      "z": 2,
      "name": "Rock_Magma_Cooled"
    },
    {
      "x": -1,
      "y": 4,
      "z": 2,
      "name": "Rock_Magma_Cooled"
    },
    {
      "x": -1,
      "y": 5,
      "z": 2,
      "name": "Rock_Magma_Cooled"
    },
    {
      "x": -1,
      "y": 6,
      "z": 2,
      "name": "Rock_Magma_Cooled"
    },
    {
      "x": -1,
      "y": 20,
      "z": 2,
      "name": "Rock_Magma_Cooled"
    },
    {
      "x": -1,
      "y": 21,
      "z": 2,
      "name": "Rock_Magma_Cooled"
    },
    {
      "x": -1,
      "y": 22,
      "z": 2,
      "name": "Plant_Moss_Rug_Pink",
      "support": 15
    },
    {
      "x": -1,
      "y": 0,
      "z": 3,
      "name": "Rock_Magma_Cooled"
    },
    {
      "x": -1,
      "y": 1,
      "z": 3,
      "name": "Ore_Adamantite_Magma_Cracked"
    },
    {
      "x": -1,
      "y": 2,
      "z": 3,
      "name": "Rock_Magma_Cooled"
    },
    {
      "x": -1,
      "y": 3,
      "z": 3,
      "name": "Rock_Magma_Cooled"
    },
    {
      "x": -1,
      "y": 4,
      "z": 3,
      "name": "Rock_Magma_Cooled"
    },
    {
      "x": -1,
      "y": 5,
      "z": 3,
      "name": "Rock_Magma_Cooled"
    },
    {
      "x": -1,
      "y": 20,
      "z": 3,
      "name": "Plant_Vine_Wall_Poisoned",
      "support": 15
    },
    {
      "x": -1,
      "y": 21,
      "z": 3,
      "name": "Rock_Magma_Cooled"
    },
    {
      "x": -1,
      "y": 22,
      "z": 3,
      "name": "Plant_Moss_Rug_Pink",
      "support": 15
    },
    {
      "x": -1,
      "y": 0,
      "z": 4,
      "name": "Rock_Magma_Cooled"
    },
    {
      "x": -1,
      "y": 1,
      "z": 4,
      "name": "Ore_Adamantite_Magma_Cracked"
    },
    {
      "x": -1,
      "y": 2,
      "z": 4,
      "name": "Rock_Magma_Cooled"
    },
    {
      "x": -1,
      "y": 3,
      "z": 4,
      "name": "Ore_Adamantite_Magma_Cracked"
    },
    {
      "x": -1,
      "y": 4,
      "z": 4,
      "name": "Rock_Magma_Cooled"
    },
    {
      "x": -1,
      "y": 5,
      "z": 4,
      "name": "Ore_Adamantite_Magma_Cracked"
    },
    {
      "x": -1,
      "y": 0,
      "z": 5,
      "name": "Soil_Sand_Ashen"
    },
    {
      "x": -1,
      "y": 1,
      "z": 5,
      "name": "Soil_Ash"
    },
    {
      "x": -1,
      "y": 2,
      "z": 5,
      "name": "Rock_Magma_Cooled"
    },
    {
      "x": -1,
      "y": 3,
      "z": 5,
      "name": "Ore_Adamantite_Magma_Cracked"
    },
    {
      "x": -1,
      "y": 4,
      "z": 5,
      "name": "Rock_Magma_Cooled"
    },
    {
      "x": -1,
      "y": 5,
      "z": 5,
      "name": "Rock_Magma_Cooled"
    },
    {
      "x": -1,
      "y": 0,
      "z": 6,
      "name": "Soil_Ash"
    },
    {
      "x": -1,
      "y": 1,
      "z": 6,
      "name": "Soil_Sand_Ashen"
    },
    {
      "x": -1,
      "y": 2,
      "z": 6,
      "name": "Soil_Ash"
    },
    {
      "x": -1,
      "y": 4,
      "z": 6,
      "name": "Rock_Magma_Cooled"
    },
    {
      "x": -1,
      "y": 5,
      "z": 6,
      "name": "Rock_Magma_Cooled"
    },
    {
      "x": -1,
      "y": 6,
      "z": 6,
      "name": "Ore_Adamantite_Magma_Cracked"
    },
    {
      "x": -1,
      "y": 0,
      "z": 7,
      "name": "Soil_Sand_Ashen"
    },
    {
      "x": -1,
      "y": 1,
      "z": 7,
      "name": "Soil_Ash"
    },
    {
      "x": -1,
      "y": 5,
      "z": 7,
      "name": "Rock_Magma_Cooled"
    },
    {
      "x": -1,
      "y": 6,
      "z": 7,
      "name": "Rock_Magma_Cooled"
    },
    {
      "x": -1,
      "y": 0,
      "z": 8,
      "name": "Soil_Ash"
    },
    {
      "x": -1,
      "y": 1,
      "z": 8,
      "name": "Soil_Sand_Ashen"
    },
    {
      "x": -1,
      "y": 2,
      "z": 8,
      "name": "Plant_Flower_Bushy_Violet"
    },
    {
      "x": -1,
      "y": 6,
      "z": 8,
      "name": "Plant_Vine_Wall_Poisoned",
      "support": 15,
      "rotation": 1
    },
    {
      "x": -1,
      "y": 0,
      "z": 9,
      "name": "Soil_Ash"
    },
    {
      "x": 0,
      "y": 0,
      "z": -6,
      "name": "Soil_Ash"
    },
    {
      "x": 0,
      "y": 0,
      "z": -5,
      "name": "Soil_Ash"
    },
    {
      "x": 0,
      "y": 1,
      "z": -5,
      "name": "Soil_Sand_Ashen"
    },
    {
      "x": 0,
      "y": 2,
      "z": -5,
      "name": "Plant_Flower_Bushy_Violet"
    },
    {
      "x": 0,
      "y": 0,
      "z": -4,
      "name": "Soil_Ash"
    },
    {
      "x": 0,
      "y": 1,
      "z": -4,
      "name": "Soil_Sand_Ashen"
    },
    {
      "x": 0,
      "y": 2,
      "z": -4,
      "name": "Soil_Ash"
    },
    {
      "x": 0,
      "y": 3,
      "z": -4,
      "name": "Plant_Flower_Bushy_Violet"
    },
    {
      "x": 0,
      "y": 6,
      "z": -4,
      "name": "Rock_Magma_Cooled"
    },
    {
      "x": 0,
      "y": 7,
      "z": -4,
      "name": "Rock_Magma_Cooled"
    },
    {
      "x": 0,
      "y": 8,
      "z": -4,
      "name": "Rock_Magma_Cooled"
    },
    {
      "x": 0,
      "y": 9,
      "z": -4,
      "name": "Rock_Magma_Cooled"
    },
    {
      "x": 0,
      "y": 0,
      "z": -3,
      "name": "Soil_Sand_Ashen"
    },
    {
      "x": 0,
      "y": 1,
      "z": -3,
      "name": "Soil_Ash"
    },
    {
      "x": 0,
      "y": 2,
      "z": -3,
      "name": "Soil_Ash"
    },
    {
      "x": 0,
      "y": 4,
      "z": -3,
      "name": "Rock_Magma_Cooled"
    },
    {
      "x": 0,
      "y": 5,
      "z": -3,
      "name": "Rock_Magma_Cooled"
    },
    {
      "x": 0,
      "y": 6,
      "z": -3,
      "name": "Rock_Magma_Cooled"
    },
    {
      "x": 0,
      "y": 7,
      "z": -3,
      "name": "Rock_Magma_Cooled"
    },
    {
      "x": 0,
      "y": 8,
      "z": -3,
      "name": "Rock_Magma_Cooled"
    },
    {
      "x": 0,
      "y": 9,
      "z": -3,
      "name": "Rock_Magma_Cooled"
    },
    {
      "x": 0,
      "y": 10,
      "z": -3,
      "name": "Plant_Vine_Wall_Poisoned",
      "support": 15,
      "rotation": 2
    },
    {
      "x": 0,
      "y": 0,
      "z": -2,
      "name": "Soil_Ash"
    },
    {
      "x": 0,
      "y": 1,
      "z": -2,
      "name": "Soil_Sand_Ashen"
    },
    {
      "x": 0,
      "y": 2,
      "z": -2,
      "name": "Ore_Adamantite_Magma_Cracked"
    },
    {
      "x": 0,
      "y": 3,
      "z": -2,
      "name": "Rock_Magma_Cooled"
    },
    {
      "x": 0,
      "y": 4,
      "z": -2,
      "name": "Ore_Adamantite_Magma_Cracked"
    },
    {
      "x": 0,
      "y": 5,
      "z": -2,
      "name": "Rock_Magma_Cooled"
    },
    {
      "x": 0,
      "y": 6,
      "z": -2,
      "name": "Rock_Magma_Cooled"
    },
    {
      "x": 0,
      "y": 7,
      "z": -2,
      "name": "Ore_Adamantite_Magma_Cracked"
    },
    {
      "x": 0,
      "y": 8,
      "z": -2,
      "name": "Rock_Magma_Cooled"
    },
    {
      "x": 0,
      "y": 9,
      "z": -2,
      "name": "Rock_Magma_Cooled"
    },
    {
      "x": 0,
      "y": 10,
      "z": -2,
      "name": "Rock_Magma_Cooled"
    },
    {
      "x": 0,
      "y": 11,
      "z": -2,
      "name": "Rock_Magma_Cooled"
    },
    {
      "x": 0,
      "y": 0,
      "z": -1,
      "name": "Soil_Sand_Ashen"
    },
    {
      "x": 0,
      "y": 1,
      "z": -1,
      "name": "Rock_Magma_Cooled"
    },
    {
      "x": 0,
      "y": 2,
      "z": -1,
      "name": "Rock_Magma_Cooled"
    },
    {
      "x": 0,
      "y": 3,
      "z": -1,
      "name": "Rock_Magma_Cooled"
    },
    {
      "x": 0,
      "y": 4,
      "z": -1,
      "name": "Rock_Magma_Cooled"
    },
    {
      "x": 0,
      "y": 5,
      "z": -1,
      "name": "Ore_Adamantite_Magma_Cracked"
    },
    {
      "x": 0,
      "y": 6,
      "z": -1,
      "name": "Rock_Magma_Cooled"
    },
    {
      "x": 0,
      "y": 7,
      "z": -1,
      "name": "Rock_Magma_Cooled"
    },
    {
      "x": 0,
      "y": 8,
      "z": -1,
      "name": "Rock_Magma_Cooled"
    },
    {
      "x": 0,
      "y": 9,
      "z": -1,
      "name": "Ore_Adamantite_Magma_Cracked"
    },
    {
      "x": 0,
      "y": 10,
      "z": -1,
      "name": "Rock_Magma_Cooled"
    },
    {
      "x": 0,
      "y": 11,
      "z": -1,
      "name": "Rock_Magma_Cooled"
    },
    {
      "x": 0,
      "y": 18,
      "z": -1,
      "name": "Plant_Vine_Wall_Poisoned",
      "support": 15,
      "rotation": 3
    },
    {
      "x": 0,
      "y": 0,
      "z": 0,
      "name": "Ore_Adamantite_Magma_Cracked"
    },
    {
      "x": 0,
      "y": 1,
      "z": 0,
      "name": "Rock_Magma_Cooled"
    },
    {
      "x": 0,
      "y": 2,
      "z": 0,
      "name": "Ore_Adamantite_Magma_Cracked"
    },
    {
      "x": 0,
      "y": 3,
      "z": 0,
      "name": "Rock_Magma_Cooled"
    },
    {
      "x": 0,
      "y": 4,
      "z": 0,
      "name": "Rock_Magma_Cooled"
    },
    {
      "x": 0,
      "y": 5,
      "z": 0,
      "name": "Rock_Magma_Cooled"
    },
    {
      "x": 0,
      "y": 6,
      "z": 0,
      "name": "Rock_Magma_Cooled"
    },
    {
      "x": 0,
      "y": 7,
      "z": 0,
      "name": "Rock_Magma_Cooled"
    },
    {
      "x": 0,
      "y": 8,
      "z": 0,
      "name": "Ore_Adamantite_Magma_Cracked"
    },
    {
      "x": 0,
      "y": 9,
      "z": 0,
      "name": "Ore_Adamantite_Magma_Cracked"
    },
    {
      "x": 0,
      "y": 18,
      "z": 0,
      "name": "Rock_Magma_Cooled"
    },
    {
      "x": 0,
      "y": 19,
      "z": 0,
      "name": "Rock_Magma_Cooled"
    },
    {
      "x": 0,
      "y": 20,
      "z": 0,
      "name": "Plant_Moss_Rug_Pink",
      "support": 15
    },
    {
      "x": 0,
      "y": 0,
      "z": 1,
      "name": "Ore_Adamantite_Magma_Cracked"
    },
    {
      "x": 0,
      "y": 1,
      "z": 1,
      "name": "Rock_Magma_Cooled"
    },
    {
      "x": 0,
      "y": 2,
      "z": 1,
      "name": "Rock_Magma_Cooled"
    },
    {
      "x": 0,
      "y": 3,
      "z": 1,
      "name": "Rock_Magma_Cooled"
    },
    {
      "x": 0,
      "y": 4,
      "z": 1,
      "name": "Rock_Magma_Cooled"
    },
    {
      "x": 0,
      "y": 5,
      "z": 1,
      "name": "Rock_Magma_Cooled"
    },
    {
      "x": 0,
      "y": 6,
      "z": 1,
      "name": "Rock_Magma_Cooled"
    },
    {
      "x": 0,
      "y": 7,
      "z": 1,
      "name": "Plant_Vine_Wall_Poisoned",
      "support": 15,
      "rotation": 1
    },
    {
      "x": 0,
      "y": 18,
      "z": 1,
      "name": "Rock_Magma_Cooled"
    },
    {
      "x": 0,
      "y": 19,
      "z": 1,
      "name": "Rock_Magma_Cooled"
    },
    {
      "x": 0,
      "y": 20,
      "z": 1,
      "name": "Rock_Magma_Cooled"
    },
    {
      "x": 0,
      "y": 21,
      "z": 1,
      "name": "Plant_Moss_Rug_Pink",
      "support": 15
    },
    {
      "x": 0,
      "y": 0,
      "z": 2,
      "name": "Rock_Magma_Cooled"
    },
    {
      "x": 0,
      "y": 1,
      "z": 2,
      "name": "Rock_Magma_Cooled"
    },
    {
      "x": 0,
      "y": 2,
      "z": 2,
      "name": "Rock_Magma_Cooled"
    },
    {
      "x": 0,
      "y": 3,
      "z": 2,
      "name": "Rock_Magma_Cooled"
    },
    {
      "x": 0,
      "y": 4,
      "z": 2,
      "name": "Rock_Magma_Cooled"
    },
    {
      "x": 0,
      "y": 5,
      "z": 2,
      "name": "Ore_Adamantite_Magma_Cracked"
    },
    {
      "x": 0,
      "y": 6,
      "z": 2,
      "name": "Rock_Magma_Cooled"
    },
    {
      "x": 0,
      "y": 19,
      "z": 2,
      "name": "Rock_Magma_Cooled"
    },
    {
      "x": 0,
      "y": 20,
      "z": 2,
      "name": "Rock_Magma_Cooled"
    },
    {
      "x": 0,
      "y": 21,
      "z": 2,
      "name": "Plant_Moss_Rug_Pink",
      "support": 15
    },
    {
      "x": 0,
      "y": 0,
      "z": 3,
      "name": "Rock_Magma_Cooled"
    },
    {
      "x": 0,
      "y": 1,
      "z": 3,
      "name": "Rock_Magma_Cooled"
    },
    {
      "x": 0,
      "y": 2,
      "z": 3,
      "name": "Ore_Adamantite_Magma_Cracked"
    },
    {
      "x": 0,
      "y": 3,
      "z": 3,
      "name": "Ore_Adamantite_Magma_Cracked"
    },
    {
      "x": 0,
      "y": 4,
      "z": 3,
      "name": "Rock_Magma_Cooled"
    },
    {
      "x": 0,
      "y": 5,
      "z": 3,
      "name": "Plant_Crop_Mushroom_Glowing_Purple"
    },
    {
      "x": 0,
      "y": 19,
      "z": 3,
      "name": "Plant_Vine_Wall_Poisoned",
      "support": 15
    },
    {
      "x": 0,
      "y": 0,
      "z": 4,
      "name": "Rock_Magma_Cooled"
    },
    {
      "x": 0,
      "y": 1,
      "z": 4,
      "name": "Rock_Magma_Cooled"
    },
    {
      "x": 0,
      "y": 2,
      "z": 4,
      "name": "Rock_Magma_Cooled"
    },
    {
      "x": 0,
      "y": 3,
      "z": 4,
      "name": "Rock_Magma_Cooled"
    },
    {
      "x": 0,
      "y": 4,
      "z": 4,
      "name": "Rock_Magma_Cooled"
    },
    {
      "x": 0,
      "y": 0,
      "z": 5,
      "name": "Soil_Ash"
    },
    {
      "x": 0,
      "y": 1,
      "z": 5,
      "name": "Rock_Magma_Cooled"
    },
    {
      "x": 0,
      "y": 2,
      "z": 5,
      "name": "Ore_Adamantite_Magma_Cracked"
    },
    {
      "x": 0,
      "y": 3,
      "z": 5,
      "name": "Rock_Magma_Cooled"
    },
    {
      "x": 0,
      "y": 0,
      "z": 6,
      "name": "Soil_Ash"
    },
    {
      "x": 0,
      "y": 1,
      "z": 6,
      "name": "Soil_Ash"
    },
    {
      "x": 0,
      "y": 2,
      "z": 6,
      "name": "Soil_Ash"
    },
    {
      "x": 0,
      "y": 4,
      "z": 6,
      "name": "Rock_Magma_Cooled"
    },
    {
      "x": 0,
      "y": 5,
      "z": 6,
      "name": "Rock_Magma_Cooled"
    },
    {
      "x": 0,
      "y": 0,
      "z": 7,
      "name": "Soil_Sand_Ashen"
    },
    {
      "x": 0,
      "y": 1,
      "z": 7,
      "name": "Soil_Ash"
    },
    {
      "x": 0,
      "y": 2,
      "z": 7,
      "name": "Soil_Ash"
    },
    {
      "x": 0,
      "y": 6,
      "z": 7,
      "name": "Plant_Vine_Wall_Poisoned",
      "support": 15,
      "rotation": 1
    },
    {
      "x": 0,
      "y": 0,
      "z": 8,
      "name": "Soil_Sand_Ashen"
    },
    {
      "x": 0,
      "y": 1,
      "z": 8,
      "name": "Soil_Ash"
    },
    {
      "x": 0,
      "y": 0,
      "z": 9,
      "name": "Soil_Ash"
    },
    {
      "x": 1,
      "y": 0,
      "z": -6,
      "name": "Soil_Ash"
    },
    {
      "x": 1,
      "y": 0,
      "z": -5,
      "name": "Soil_Ash"
    },
    {
      "x": 1,
      "y": 1,
      "z": -5,
      "name": "Soil_Ash"
    },
    {
      "x": 1,
      "y": 0,
      "z": -4,
      "name": "Soil_Sand_Ashen"
    },
    {
      "x": 1,
      "y": 1,
      "z": -4,
      "name": "Soil_Sand_Ashen"
    },
    {
      "x": 1,
      "y": 2,
      "z": -4,
      "name": "Plant_Flower_Bushy_Poisoned"
    },
    {
      "x": 1,
      "y": 8,
      "z": -4,
      "name": "Rock_Magma_Cooled"
    },
    {
      "x": 1,
      "y": 9,
      "z": -4,
      "name": "Ore_Adamantite_Magma_Cracked"
    },
    {
      "x": 1,
      "y": 0,
      "z": -3,
      "name": "Soil_Sand_Ashen"
    },
    {
      "x": 1,
      "y": 1,
      "z": -3,
      "name": "Soil_Ash"
    },
    {
      "x": 1,
      "y": 2,
      "z": -3,
      "name": "Soil_Ash"
    },
    {
      "x": 1,
      "y": 3,
      "z": -3,
      "name": "Plant_Bramble_Dead_Twisted"
    },
    {
      "x": 1,
      "y": 8,
      "z": -3,
      "name": "Rock_Magma_Cooled"
    },
    {
      "x": 1,
      "y": 9,
      "z": -3,
      "name": "Rock_Magma_Cooled"
    },
    {
      "x": 1,
      "y": 10,
      "z": -3,
      "name": "Rock_Magma_Cooled"
    },
    {
      "x": 1,
      "y": 0,
      "z": -2,
      "name": "Soil_Ash"
    },
    {
      "x": 1,
      "y": 1,
      "z": -2,
      "name": "Soil_Ash"
    },
    {
      "x": 1,
      "y": 2,
      "z": -2,
      "name": "Soil_Ash"
    },
    {
      "x": 1,
      "y": 3,
      "z": -2,
      "name": "Rock_Magma_Cooled"
    },
    {
      "x": 1,
      "y": 4,
      "z": -2,
      "name": "Rock_Magma_Cooled"
    },
    {
      "x": 1,
      "y": 5,
      "z": -2,
      "name": "Rock_Magma_Cooled"
    },
    {
      "x": 1,
      "y": 9,
      "z": -2,
      "name": "Rock_Magma_Cooled"
    },
    {
      "x": 1,
      "y": 10,
      "z": -2,
      "name": "Rock_Magma_Cooled"
    },
    {
      "x": 1,
      "y": 11,
      "z": -2,
      "name": "Ore_Adamantite_Magma"
    },
    {
      "x": 1,
      "y": 12,
      "z": -2,
      "name": "Rock_Magma_Cooled"
    },
    {
      "x": 1,
      "y": 17,
      "z": -2,
      "name": "Ore_Adamantite_Magma_Cracked"
    },
    {
      "x": 1,
      "y": 0,
      "z": -1,
      "name": "Soil_Ash"
    },
    {
      "x": 1,
      "y": 1,
      "z": -1,
      "name": "Rock_Magma_Cooled"
    },
    {
      "x": 1,
      "y": 2,
      "z": -1,
      "name": "Rock_Magma_Cooled"
    },
    {
      "x": 1,
      "y": 3,
      "z": -1,
      "name": "Rock_Magma_Cooled"
    },
    {
      "x": 1,
      "y": 4,
      "z": -1,
      "name": "Rock_Magma_Cooled"
    },
    {
      "x": 1,
      "y": 5,
      "z": -1,
      "name": "Rock_Magma_Cooled"
    },
    {
      "x": 1,
      "y": 9,
      "z": -1,
      "name": "Rock_Magma_Cooled"
    },
    {
      "x": 1,
      "y": 10,
      "z": -1,
      "name": "Rock_Magma_Cooled"
    },
    {
      "x": 1,
      "y": 11,
      "z": -1,
      "name": "Ore_Adamantite_Magma_Cracked"
    },
    {
      "x": 1,
      "y": 17,
      "z": -1,
      "name": "Rock_Magma_Cooled"
    },
    {
      "x": 1,
      "y": 18,
      "z": -1,
      "name": "Rock_Magma_Cooled"
    },
    {
      "x": 1,
      "y": 19,
      "z": -1,
      "name": "Plant_Moss_Rug_Pink",
      "support": 15
    },
    {
      "x": 1,
      "y": 0,
      "z": 0,
      "name": "Rock_Magma_Cooled"
    },
    {
      "x": 1,
      "y": 1,
      "z": 0,
      "name": "Rock_Magma_Cooled"
    },
    {
      "x": 1,
      "y": 2,
      "z": 0,
      "name": "Rock_Magma_Cooled"
    },
    {
      "x": 1,
      "y": 3,
      "z": 0,
      "name": "Rock_Magma_Cooled"
    },
    {
      "x": 1,
      "y": 4,
      "z": 0,
      "name": "Rock_Magma_Cooled"
    },
    {
      "x": 1,
      "y": 5,
      "z": 0,
      "name": "Ore_Adamantite_Magma_Cracked"
    },
    {
      "x": 1,
      "y": 6,
      "z": 0,
      "name": "Rock_Magma_Cooled"
    },
    {
      "x": 1,
      "y": 8,
      "z": 0,
      "name": "Plant_Vine_Wall_Poisoned",
      "support": 15,
      "rotation": 1
    },
    {
      "x": 1,
      "y": 9,
      "z": 0,
      "name": "Plant_Vine_Wall_Poisoned",
      "support": 15,
      "rotation": 1
    },
    {
      "x": 1,
      "y": 17,
      "z": 0,
      "name": "Ore_Adamantite_Magma_Cracked"
    },
    {
      "x": 1,
      "y": 18,
      "z": 0,
      "name": "Rock_Magma_Cooled"
    },
    {
      "x": 1,
      "y": 19,
      "z": 0,
      "name": "Rock_Magma_Cooled"
    },
    {
      "x": 1,
      "y": 20,
      "z": 0,
      "name": "Plant_Moss_Rug_Pink",
      "support": 15
    },
    {
      "x": 1,
      "y": 0,
      "z": 1,
      "name": "Rock_Magma_Cooled"
    },
    {
      "x": 1,
      "y": 1,
      "z": 1,
      "name": "Rock_Magma_Cooled"
    },
    {
      "x": 1,
      "y": 2,
      "z": 1,
      "name": "Ore_Adamantite_Magma_Cracked"
    },
    {
      "x": 1,
      "y": 3,
      "z": 1,
      "name": "Rock_Magma_Cooled"
    },
    {
      "x": 1,
      "y": 4,
      "z": 1,
      "name": "Rock_Magma_Cooled"
    },
    {
      "x": 1,
      "y": 5,
      "z": 1,
      "name": "Rock_Magma_Cooled"
    },
    {
      "x": 1,
      "y": 6,
      "z": 1,
      "name": "Ore_Adamantite_Magma_Cracked"
    },
    {
      "x": 1,
      "y": 17,
      "z": 1,
      "name": "Plant_Vine_Wall_Poisoned",
      "support": 15
    },
    {
      "x": 1,
      "y": 18,
      "z": 1,
      "name": "Rock_Magma_Cooled"
    },
    {
      "x": 1,
      "y": 19,
      "z": 1,
      "name": "Rock_Magma_Cooled"
    },
    {
      "x": 1,
      "y": 20,
      "z": 1,
      "name": "Rock_Magma_Cooled"
    },
    {
      "x": 1,
      "y": 21,
      "z": 1,
      "name": "Plant_Moss_Rug_Pink",
      "support": 15
    },
    {
      "x": 1,
      "y": 0,
      "z": 2,
      "name": "Ore_Adamantite_Magma_Cracked"
    },
    {
      "x": 1,
      "y": 1,
      "z": 2,
      "name": "Rock_Magma_Cooled"
    },
    {
      "x": 1,
      "y": 2,
      "z": 2,
      "name": "Rock_Magma_Cooled"
    },
    {
      "x": 1,
      "y": 3,
      "z": 2,
      "name": "Rock_Magma_Cooled"
    },
    {
      "x": 1,
      "y": 4,
      "z": 2,
      "name": "Rock_Magma_Cooled"
    },
    {
      "x": 1,
      "y": 5,
      "z": 2,
      "name": "Ore_Adamantite_Magma_Cracked"
    },
    {
      "x": 1,
      "y": 19,
      "z": 2,
      "name": "Rock_Magma_Cooled"
    },
    {
      "x": 1,
      "y": 20,
      "z": 2,
      "name": "Plant_Moss_Rug_Pink",
      "support": 15
    },
    {
      "x": 1,
      "y": 0,
      "z": 3,
      "name": "Rock_Magma_Cooled"
    },
    {
      "x": 1,
      "y": 1,
      "z": 3,
      "name": "Ore_Adamantite_Magma_Cracked"
    },
    {
      "x": 1,
      "y": 2,
      "z": 3,
      "name": "Rock_Magma_Cooled"
    },
    {
      "x": 1,
      "y": 3,
      "z": 3,
      "name": "Rock_Magma_Cooled"
    },
    {
      "x": 1,
      "y": 4,
      "z": 3,
      "name": "Rock_Magma_Cooled"
    },
    {
      "x": 1,
      "y": 0,
      "z": 4,
      "name": "Ore_Adamantite_Magma_Cracked"
    },
    {
      "x": 1,
      "y": 1,
      "z": 4,
      "name": "Rock_Magma_Cooled"
    },
    {
      "x": 1,
      "y": 2,
      "z": 4,
      "name": "Rock_Magma_Cooled"
    },
    {
      "x": 1,
      "y": 3,
      "z": 4,
      "name": "Rock_Magma_Cooled"
    },
    {
      "x": 1,
      "y": 0,
      "z": 5,
      "name": "Rock_Magma_Cooled"
    },
    {
      "x": 1,
      "y": 1,
      "z": 5,
      "name": "Rock_Magma_Cooled"
    },
    {
      "x": 1,
      "y": 2,
      "z": 5,
      "name": "Rock_Magma_Cooled"
    },
    {
      "x": 1,
      "y": 3,
      "z": 5,
      "name": "Rock_Magma_Cooled"
    },
    {
      "x": 1,
      "y": 0,
      "z": 6,
      "name": "Soil_Sand_Ashen"
    },
    {
      "x": 1,
      "y": 1,
      "z": 6,
      "name": "Soil_Ash"
    },
    {
      "x": 1,
      "y": 2,
      "z": 6,
      "name": "Soil_Ash"
    },
    {
      "x": 1,
      "y": 3,
      "z": 6,
      "name": "Plant_Crop_Mushroom_Glowing_Purple"
    },
    {
      "x": 1,
      "y": 0,
      "z": 7,
      "name": "Soil_Sand_Ashen"
    },
    {
      "x": 1,
      "y": 1,
      "z": 7,
      "name": "Soil_Ash"
    },
    {
      "x": 1,
      "y": 2,
      "z": 7,
      "name": "Plant_Flower_Bushy_Poisoned"
    },
    {
      "x": 1,
      "y": 0,
      "z": 8,
      "name": "Soil_Ash"
    },
    {
      "x": 1,
      "y": 1,
      "z": 8,
      "name": "Soil_Sand_Ashen"
    },
    {
      "x": 1,
      "y": 2,
      "z": 8,
      "name": "Plant_Flower_Bushy_Violet"
    },
    {
      "x": 1,
      "y": 0,
      "z": 9,
      "name": "Soil_Sand_Ashen"
    },
    {
      "x": 2,
      "y": 0,
      "z": -5,
      "name": "Soil_Ash"
    },
    {
      "x": 2,
      "y": 0,
      "z": -4,
      "name": "Soil_Ash"
    },
    {
      "x": 2,
      "y": 1,
      "z": -4,
      "name": "Soil_Sand_Ashen"
    },
    {
      "x": 2,
      "y": 2,
      "z": -4,
      "name": "Plant_Flower_Bushy_Poisoned"
    },
    {
      "x": 2,
      "y": 13,
      "z": -4,
      "name": "Plant_Vine_Wall_Poisoned",
      "support": 15,
      "rotation": 2
    },
    {
      "x": 2,
      "y": 0,
      "z": -3,
      "name": "Soil_Ash"
    },
    {
      "x": 2,
      "y": 1,
      "z": -3,
      "name": "Soil_Ash"
    },
    {
      "x": 2,
      "y": 9,
      "z": -3,
      "name": "Rock_Magma_Cooled"
    },
    {
      "x": 2,
      "y": 10,
      "z": -3,
      "name": "Ore_Adamantite_Magma_Cracked"
    },
    {
      "x": 2,
      "y": 11,
      "z": -3,
      "name": "Ore_Adamantite_Magma_Cracked"
    },
    {
      "x": 2,
      "y": 12,
      "z": -3,
      "name": "Rock_Magma_Cooled"
    },
    {
      "x": 2,
      "y": 13,
      "z": -3,
      "name": "Rock_Magma_Cooled"
    },
    {
      "x": 2,
      "y": 16,
      "z": -3,
      "name": "Rock_Magma_Cooled"
    },
    {
      "x": 2,
      "y": 0,
      "z": -2,
      "name": "Soil_Sand_Ashen"
    },
    {
      "x": 2,
      "y": 1,
      "z": -2,
      "name": "Soil_Sand_Ashen"
    },
    {
      "x": 2,
      "y": 2,
      "z": -2,
      "name": "Soil_Sand_Ashen"
    },
    {
      "x": 2,
      "y": 9,
      "z": -2,
      "name": "Rock_Magma_Cooled"
    },
    {
      "x": 2,
      "y": 10,
      "z": -2,
      "name": "Rock_Magma_Cooled"
    },
    {
      "x": 2,
      "y": 11,
      "z": -2,
      "name": "Ore_Adamantite_Magma_Cracked"
    },
    {
      "x": 2,
      "y": 12,
      "z": -2,
      "name": "Rock_Magma_Cooled"
    },
    {
      "x": 2,
      "y": 16,
      "z": -2,
      "name": "Rock_Magma_Cooled"
    },
    {
      "x": 2,
      "y": 17,
      "z": -2,
      "name": "Rock_Magma_Cooled"
    },
    {
      "x": 2,
      "y": 18,
      "z": -2,
      "name": "Plant_Moss_Rug_Pink",
      "support": 15
    },
    {
      "x": 2,
      "y": 0,
      "z": -1,
      "name": "Soil_Sand_Ashen"
    },
    {
      "x": 2,
      "y": 1,
      "z": -1,
      "name": "Soil_Ash"
    },
    {
      "x": 2,
      "y": 2,
      "z": -1,
      "name": "Rock_Magma_Cooled"
    },
    {
      "x": 2,
      "y": 3,
      "z": -1,
      "name": "Ore_Adamantite_Magma_Cracked"
    },
    {
      "x": 2,
      "y": 9,
      "z": -1,
      "name": "Rock_Magma_Cooled"
    },
    {
      "x": 2,
      "y": 16,
      "z": -1,
      "name": "Ore_Adamantite_Magma_Cracked"
    },
    {
      "x": 2,
      "y": 17,
      "z": -1,
      "name": "Ore_Adamantite_Magma_Cracked"
    },
    {
      "x": 2,
      "y": 18,
      "z": -1,
      "name": "Rock_Magma_Cooled"
    },
    {
      "x": 2,
      "y": 19,
      "z": -1,
      "name": "Plant_Moss_Rug_Pink",
      "support": 15
    },
    {
      "x": 2,
      "y": 0,
      "z": 0,
      "name": "Rock_Magma_Cooled"
    },
    {
      "x": 2,
      "y": 1,
      "z": 0,
      "name": "Rock_Magma_Cooled"
    },
    {
      "x": 2,
      "y": 2,
      "z": 0,
      "name": "Rock_Magma_Cooled"
    },
    {
      "x": 2,
      "y": 3,
      "z": 0,
      "name": "Rock_Magma_Cooled"
    },
    {
      "x": 2,
      "y": 4,
      "z": 0,
      "name": "Ore_Adamantite_Magma_Cracked"
    },
    {
      "x": 2,
      "y": 5,
      "z": 0,
      "name": "Plant_Crop_Mushroom_Glowing_Violet"
    },
    {
      "x": 2,
      "y": 17,
      "z": 0,
      "name": "Ore_Adamantite_Magma_Cracked"
    },
    {
      "x": 2,
      "y": 18,
      "z": 0,
      "name": "Rock_Magma_Cooled"
    },
    {
      "x": 2,
      "y": 19,
      "z": 0,
      "name": "Plant_Moss_Rug_Pink",
      "support": 15
    },
    {
      "x": 2,
      "y": 0,
      "z": 1,
      "name": "Rock_Magma_Cooled"
    },
    {
      "x": 2,
      "y": 1,
      "z": 1,
      "name": "Rock_Magma_Cooled"
    },
    {
      "x": 2,
      "y": 2,
      "z": 1,
      "name": "Rock_Magma_Cooled"
    },
    {
      "x": 2,
      "y": 3,
      "z": 1,
      "name": "Rock_Magma_Cooled"
    },
    {
      "x": 2,
      "y": 4,
      "z": 1,
      "name": "Rock_Magma_Cooled"
    },
    {
      "x": 2,
      "y": 17,
      "z": 1,
      "name": "Plant_Vine_Wall_Poisoned",
      "support": 15
    },
    {
      "x": 2,
      "y": 18,
      "z": 1,
      "name": "Rock_Magma_Cooled"
    },
    {
      "x": 2,
      "y": 19,
      "z": 1,
      "name": "Rock_Magma_Cooled"
    },
    {
      "x": 2,
      "y": 20,
      "z": 1,
      "name": "Plant_Moss_Rug_Pink",
      "support": 15
    },
    {
      "x": 2,
      "y": 0,
      "z": 2,
      "name": "Rock_Magma_Cooled"
    },
    {
      "x": 2,
      "y": 1,
      "z": 2,
      "name": "Rock_Magma_Cooled"
    },
    {
      "x": 2,
      "y": 2,
      "z": 2,
      "name": "Rock_Magma_Cooled"
    },
    {
      "x": 2,
      "y": 3,
      "z": 2,
      "name": "Rock_Magma_Cooled"
    },
    {
      "x": 2,
      "y": 4,
      "z": 2,
      "name": "Rock_Magma_Cooled"
    },
    {
      "x": 2,
      "y": 18,
      "z": 2,
      "name": "Plant_Vine_Wall_Poisoned",
      "support": 15
    },
    {
      "x": 2,
      "y": 19,
      "z": 2,
      "name": "Plant_Vine_Wall_Poisoned",
      "support": 15,
      "rotation": 1
    },
    {
      "x": 2,
      "y": 0,
      "z": 3,
      "name": "Rock_Magma_Cooled"
    },
    {
      "x": 2,
      "y": 1,
      "z": 3,
      "name": "Ore_Adamantite_Magma_Cracked"
    },
    {
      "x": 2,
      "y": 2,
      "z": 3,
      "name": "Rock_Magma_Cooled"
    },
    {
      "x": 2,
      "y": 3,
      "z": 3,
      "name": "Rock_Magma_Cooled"
    },
    {
      "x": 2,
      "y": 4,
      "z": 3,
      "name": "Rock_Magma_Cooled"
    },
    {
      "x": 2,
      "y": 0,
      "z": 4,
      "name": "Rock_Magma_Cooled"
    },
    {
      "x": 2,
      "y": 1,
      "z": 4,
      "name": "Rock_Magma_Cooled"
    },
    {
      "x": 2,
      "y": 0,
      "z": 5,
      "name": "Rock_Magma_Cooled"
    },
    {
      "x": 2,
      "y": 1,
      "z": 5,
      "name": "Soil_Sand_Ashen"
    },
    {
      "x": 2,
      "y": 2,
      "z": 5,
      "name": "Soil_Ash"
    },
    {
      "x": 2,
      "y": 3,
      "z": 5,
      "name": "Plant_Bramble_Dead_Twisted"
    },
    {
      "x": 2,
      "y": 0,
      "z": 6,
      "name": "Soil_Sand_Ashen"
    },
    {
      "x": 2,
      "y": 1,
      "z": 6,
      "name": "Soil_Ash"
    },
    {
      "x": 2,
      "y": 2,
      "z": 6,
      "name": "Plant_Bramble_Dead_Twisted"
    },
    {
      "x": 2,
      "y": 0,
      "z": 7,
      "name": "Soil_Sand_Ashen"
    },
    {
      "x": 2,
      "y": 1,
      "z": 7,
      "name": "Soil_Ash"
    },
    {
      "x": 2,
      "y": 0,
      "z": 8,
      "name": "Soil_Sand_Ashen"
    },
    {
      "x": 3,
      "y": 0,
      "z": -4,
      "name": "Soil_Sand_Ashen"
    },
    {
      "x": 3,
      "y": 11,
      "z": -4,
      "name": "Ore_Adamantite_Magma_Cracked"
    },
    {
      "x": 3,
      "y": 12,
      "z": -4,
      "name": "Ore_Adamantite_Magma_Cracked"
    },
    {
      "x": 3,
      "y": 13,
      "z": -4,
      "name": "Rock_Magma_Cooled"
    },
    {
      "x": 3,
      "y": 14,
      "z": -4,
      "name": "Ore_Adamantite_Magma_Cracked"
    },
    {
      "x": 3,
      "y": 15,
      "z": -4,
      "name": "Rock_Magma_Cooled"
    },
    {
      "x": 3,
      "y": 16,
      "z": -4,
      "name": "Rock_Magma_Cooled"
    },
    {
      "x": 3,
      "y": 0,
      "z": -3,
      "name": "Soil_Ash"
    },
    {
      "x": 3,
      "y": 1,
      "z": -3,
      "name": "Soil_Sand_Ashen"
    },
    {
      "x": 3,
      "y": 10,
      "z": -3,
      "name": "Rock_Magma_Cooled"
    },
    {
      "x": 3,
      "y": 11,
      "z": -3,
      "name": "Rock_Magma_Cooled"
    },
    {
      "x": 3,
      "y": 12,
      "z": -3,
      "name": "Rock_Magma_Cooled"
    },
    {
      "x": 3,
      "y": 13,
      "z": -3,
      "name": "Rock_Magma_Cooled"
    },
    {
      "x": 3,
      "y": 14,
      "z": -3,
      "name": "Rock_Magma_Cooled"
    },
    {
      "x": 3,
      "y": 15,
      "z": -3,
      "name": "Ore_Adamantite_Magma_Cracked"
    },
    {
      "x": 3,
      "y": 16,
      "z": -3,
      "name": "Rock_Magma_Cooled"
    },
    {
      "x": 3,
      "y": 0,
      "z": -2,
      "name": "Soil_Sand_Ashen"
    },
    {
      "x": 3,
      "y": 1,
      "z": -2,
      "name": "Soil_Sand_Ashen"
    },
    {
      "x": 3,
      "y": 10,
      "z": -2,
      "name": "Ore_Adamantite_Magma_Cracked"
    },
    {
      "x": 3,
      "y": 11,
      "z": -2,
      "name": "Rock_Magma_Cooled"
    },
    {
      "x": 3,
      "y": 12,
      "z": -2,
      "name": "Rock_Magma_Cooled"
    },
    {
      "x": 3,
      "y": 15,
      "z": -2,
      "name": "Rock_Magma_Cooled"
    },
    {
      "x": 3,
      "y": 16,
      "z": -2,
      "name": "Rock_Magma_Cooled"
    },
    {
      "x": 3,
      "y": 17,
      "z": -2,
      "name": "Rock_Magma_Cooled"
    },
    {
      "x": 3,
      "y": 18,
      "z": -2,
      "name": "Plant_Moss_Rug_Pink",
      "support": 15
    },
    {
      "x": 3,
      "y": 0,
      "z": -1,
      "name": "Soil_Ash"
    },
    {
      "x": 3,
      "y": 1,
      "z": -1,
      "name": "Soil_Sand_Ashen"
    },
    {
      "x": 3,
      "y": 2,
      "z": -1,
      "name": "Plant_Flower_Bushy_Violet"
    },
    {
      "x": 3,
      "y": 16,
      "z": -1,
      "name": "Rock_Magma_Cooled"
    },
    {
      "x": 3,
      "y": 17,
      "z": -1,
      "name": "Rock_Magma_Cooled"
    },
    {
      "x": 3,
      "y": 0,
      "z": 0,
      "name": "Soil_Sand_Ashen"
    },
    {
      "x": 3,
      "y": 1,
      "z": 0,
      "name": "Rock_Magma_Cooled"
    },
    {
      "x": 3,
      "y": 2,
      "z": 0,
      "name": "Rock_Magma_Cooled"
    },
    {
      "x": 3,
      "y": 17,
      "z": 0,
      "name": "Plant_Vine_Wall_Poisoned",
      "support": 15,
      "rotation": 1
    },
    {
      "x": 3,
      "y": 18,
      "z": 0,
      "name": "Ore_Adamantite_Magma_Cracked"
    },
    {
      "x": 3,
      "y": 0,
      "z": 1,
      "name": "Rock_Magma_Cooled"
    },
    {
      "x": 3,
      "y": 1,
      "z": 1,
      "name": "Rock_Magma_Cooled"
    },
    {
      "x": 3,
      "y": 2,
      "z": 1,
      "name": "Rock_Magma_Cooled"
    },
    {
      "x": 3,
      "y": 3,
      "z": 1,
      "name": "Rock_Magma_Cooled"
    },
    {
      "x": 3,
      "y": 18,
      "z": 1,
      "name": "Plant_Vine_Wall_Poisoned",
      "support": 15,
      "rotation": 1
    },
    {
      "x": 3,
      "y": 0,
      "z": 2,
      "name": "Ore_Adamantite_Magma_Cracked"
    },
    {
      "x": 3,
      "y": 1,
      "z": 2,
      "name": "Rock_Magma_Cooled"
    },
    {
      "x": 3,
      "y": 2,
      "z": 2,
      "name": "Ore_Adamantite_Magma_Cracked"
    },
    {
      "x": 3,
      "y": 3,
      "z": 2,
      "name": "Rock_Magma_Cooled"
    },
    {
      "x": 3,
      "y": 0,
      "z": 3,
      "name": "Ore_Adamantite_Magma_Cracked"
    },
    {
      "x": 3,
      "y": 1,
      "z": 3,
      "name": "Rock_Magma_Cooled"
    },
    {
      "x": 3,
      "y": 2,
      "z": 3,
      "name": "Rock_Magma_Cooled"
    },
    {
      "x": 3,
      "y": 0,
      "z": 4,
      "name": "Soil_Sand_Ashen"
    },
    {
      "x": 3,
      "y": 1,
      "z": 4,
      "name": "Soil_Sand_Ashen"
    },
    {
      "x": 3,
      "y": 2,
      "z": 4,
      "name": "Plant_Bramble_Dead_Twisted"
    },
    {
      "x": 3,
      "y": 0,
      "z": 5,
      "name": "Soil_Ash"
    },
    {
      "x": 3,
      "y": 1,
      "z": 5,
      "name": "Soil_Sand_Ashen"
    },
    {
      "x": 3,
      "y": 2,
      "z": 5,
      "name": "Plant_Bramble_Dead_Twisted"
    },
    {
      "x": 3,
      "y": 0,
      "z": 6,
      "name": "Soil_Sand_Ashen"
    },
    {
      "x": 3,
      "y": 1,
      "z": 6,
      "name": "Soil_Ash"
    },
    {
      "x": 3,
      "y": 0,
      "z": 7,
      "name": "Soil_Sand_Ashen"
    },
    {
      "x": 4,
      "y": 14,
      "z": -6,
      "name": "Plant_Vine_Wall_Poisoned",
      "support": 15,
      "rotation": 2
    },
    {
      "x": 4,
      "y": 13,
      "z": -5,
      "name": "Rock_Magma_Cooled"
    },
    {
      "x": 4,
      "y": 14,
      "z": -5,
      "name": "Rock_Magma_Cooled"
    },
    {
      "x": 4,
      "y": 15,
      "z": -5,
      "name": "Rock_Magma_Cooled"
    },
    {
      "x": 4,
      "y": 12,
      "z": -4,
      "name": "Rock_Magma_Cooled"
    },
    {
      "x": 4,
      "y": 13,
      "z": -4,
      "name": "Rock_Magma_Cooled"
    },
    {
      "x": 4,
      "y": 14,
      "z": -4,
      "name": "Rock_Magma_Cooled"
    },
    {
      "x": 4,
      "y": 15,
      "z": -4,
      "name": "Rock_Magma_Cooled"
    },
    {
      "x": 4,
      "y": 0,
      "z": -3,
      "name": "Soil_Ash"
    },
    {
      "x": 4,
      "y": 11,
      "z": -3,
      "name": "Ore_Adamantite_Magma_Cracked"
    },
    {
      "x": 4,
      "y": 12,
      "z": -3,
      "name": "Rock_Magma_Cooled"
    },
    {
      "x": 4,
      "y": 13,
      "z": -3,
      "name": "Rock_Magma_Cooled"
    },
    {
      "x": 4,
      "y": 14,
      "z": -3,
      "name": "Ore_Adamantite_Magma_Cracked"
    },
    {
      "x": 4,
      "y": 15,
      "z": -3,
      "name": "Rock_Magma_Cooled"
    },
    {
      "x": 4,
      "y": 16,
      "z": -3,
      "name": "Rock_Magma_Cooled"
    },
    {
      "x": 4,
      "y": 0,
      "z": -2,
      "name": "Soil_Sand_Ashen"
    },
    {
      "x": 4,
      "y": 11,
      "z": -2,
      "name": "Rock_Magma_Cooled"
    },
    {
      "x": 4,
      "y": 12,
      "z": -2,
      "name": "Plant_Vine_Wall_Poisoned",
      "support": 15,
      "rotation": 1
    },
    {
      "x": 4,
      "y": 15,
      "z": -2,
      "name": "Ore_Adamantite_Magma_Cracked"
    },
    {
      "x": 4,
      "y": 16,
      "z": -2,
      "name": "Rock_Magma_Cooled"
    },
    {
      "x": 4,
      "y": 0,
      "z": -1,
      "name": "Soil_Sand_Ashen"
    },
    {
      "x": 4,
      "y": 1,
      "z": -1,
      "name": "Soil_Sand_Ashen"
    },
    {
      "x": 4,
      "y": 16,
      "z": -1,
      "name": "Plant_Vine_Wall_Poisoned",
      "support": 15,
      "rotation": 1
    },
    {
      "x": 4,
      "y": 0,
      "z": 0,
      "name": "Soil_Sand_Ashen"
    },
    {
      "x": 4,
      "y": 1,
      "z": 0,
      "name": "Soil_Ash"
    },
    {
      "x": 4,
      "y": 0,
      "z": 1,
      "name": "Soil_Ash"
    },
    {
      "x": 4,
      "y": 1,
      "z": 1,
      "name": "Soil_Ash"
    },
    {
      "x": 4,
      "y": 2,
      "z": 1,
      "name": "Soil_Ash"
    },
    {
      "x": 4,
      "y": 3,
      "z": 1,
      "name": "Plant_Bramble_Dead_Twisted"
    },
    {
      "x": 4,
      "y": 0,
      "z": 2,
      "name": "Soil_Sand_Ashen"
    },
    {
      "x": 4,
      "y": 1,
      "z": 2,
      "name": "Soil_Sand_Ashen"
    },
    {
      "x": 4,
      "y": 2,
      "z": 2,
      "name": "Soil_Ash"
    },
    {
      "x": 4,
      "y": 3,
      "z": 2,
      "name": "Plant_Flower_Bushy_Poisoned"
    },
    {
      "x": 4,
      "y": 0,
      "z": 3,
      "name": "Soil_Ash"
    },
    {
      "x": 4,
      "y": 1,
      "z": 3,
      "name": "Soil_Ash"
    },
    {
      "x": 4,
      "y": 2,
      "z": 3,
      "name": "Soil_Ash"
    },
    {
      "x": 4,
      "y": 3,
      "z": 3,
      "name": "Plant_Crop_Mushroom_Glowing_Violet"
    },
    {
      "x": 4,
      "y": 0,
      "z": 4,
      "name": "Soil_Ash"
    },
    {
      "x": 4,
      "y": 1,
      "z": 4,
      "name": "Soil_Sand_Ashen"
    },
    {
      "x": 4,
      "y": 0,
      "z": 5,
      "name": "Soil_Ash"
    },
    {
      "x": 4,
      "y": 1,
      "z": 5,
      "name": "Soil_Ash"
    },
    {
      "x": 4,
      "y": 0,
      "z": 6,
      "name": "Soil_Ash"
    },
    {
      "x": 5,
      "y": 15,
      "z": -6,
      "name": "Plant_Vine_Wall_Poisoned",
      "support": 15,
      "rotation": 2
    },
    {
      "x": 5,
      "y": 13,
      "z": -5,
      "name": "Rock_Magma_Cooled"
    },
    {
      "x": 5,
      "y": 14,
      "z": -5,
      "name": "Rock_Magma_Cooled"
    },
    {
      "x": 5,
      "y": 15,
      "z": -5,
      "name": "Rock_Magma_Cooled"
    },
    {
      "x": 5,
      "y": 13,
      "z": -4,
      "name": "Rock_Magma_Cooled"
    },
    {
      "x": 5,
      "y": 14,
      "z": -4,
      "name": "Rock_Magma_Cooled"
    },
    {
      "x": 5,
      "y": 15,
      "z": -4,
      "name": "Ore_Adamantite_Magma_Cracked"
    },
    {
      "x": 5,
      "y": 16,
      "z": -4,
      "name": "Plant_Moss_Rug_Pink",
      "support": 15
    },
    {
      "x": 5,
      "y": 12,
      "z": -3,
      "name": "Ore_Adamantite_Magma_Cracked"
    },
    {
      "x": 5,
      "y": 13,
      "z": -3,
      "name": "Rock_Magma_Cooled"
    },
    {
      "x": 5,
      "y": 0,
      "z": -2,
      "name": "Soil_Ash"
    },
    {
      "x": 5,
      "y": 16,
      "z": -2,
      "name": "Plant_Vine_Wall_Poisoned",
      "support": 15,
      "rotation": 1
    },
    {
      "x": 5,
      "y": 0,
      "z": -1,
      "name": "Soil_Sand_Ashen"
    },
    {
      "x": 5,
      "y": 1,
      "z": -1,
      "name": "Soil_Ash"
    },
    {
      "x": 5,
      "y": 0,
      "z": 0,
      "name": "Soil_Ash"
    },
    {
      "x": 5,
      "y": 1,
      "z": 0,
      "name": "Soil_Ash"
    },
    {
      "x": 5,
      "y": 2,
      "z": 0,
      "name": "Soil_Ash"
    },
    {
      "x": 5,
      "y": 3,
      "z": 0,
      "name": "Plant_Flower_Bushy_Poisoned"
    },
    {
      "x": 5,
      "y": 0,
      "z": 1,
      "name": "Soil_Ash"
    },
    {
      "x": 5,
      "y": 1,
      "z": 1,
      "name": "Soil_Ash"
    },
    {
      "x": 5,
      "y": 2,
      "z": 1,
      "name": "Soil_Ash"
    },
    {
      "x": 5,
      "y": 3,
      "z": 1,
      "name": "Plant_Flower_Bushy_Poisoned"
    },
    {
      "x": 5,
      "y": 0,
      "z": 2,
      "name": "Soil_Sand_Ashen"
    },
    {
      "x": 5,
      "y": 1,
      "z": 2,
      "name": "Soil_Sand_Ashen"
    },
    {
      "x": 5,
      "y": 2,
      "z": 2,
      "name": "Soil_Ash"
    },
    {
      "x": 5,
      "y": 3,
      "z": 2,
      "name": "Plant_Bramble_Dead_Twisted"
    },
    {
      "x": 5,
      "y": 0,
      "z": 3,
      "name": "Soil_Sand_Ashen"
    },
    {
      "x": 5,
      "y": 1,
      "z": 3,
      "name": "Soil_Sand_Ashen"
    },
    {
      "x": 5,
      "y": 2,
      "z": 3,
      "name": "Soil_Ash"
    },
    {
      "x": 5,
      "y": 0,
      "z": 4,
      "name": "Soil_Sand_Ashen"
    },
    {
      "x": 5,
      "y": 1,
      "z": 4,
      "name": "Soil_Sand_Ashen"
    },
    {
      "x": 5,
      "y": 2,
      "z": 4,
      "name": "Soil_Ash"
    },
    {
      "x": 5,
      "y": 3,
      "z": 4,
      "name": "Plant_Crop_Mushroom_Glowing_Purple"
    },
    {
      "x": 5,
      "y": 0,
      "z": 5,
      "name": "Soil_Ash"
    },
    {
      "x": 5,
      "y": 1,
      "z": 5,
      "name": "Soil_Sand_Ashen"
    },
    {
      "x": 5,
      "y": 2,
      "z": 5,
      "name": "Plant_Flower_Bushy_Violet"
    },
    {
      "x": 5,
      "y": 0,
      "z": 6,
      "name": "Soil_Sand_Ashen"
    },
    {
      "x": 6,
      "y": 16,
      "z": -7,
      "name": "Plant_Vine_Wall_Poisoned",
      "support": 15,
      "rotation": 2
    },
    {
      "x": 6,
      "y": 15,
      "z": -6,
      "name": "Rock_Magma_Cooled"
    },
    {
      "x": 6,
      "y": 16,
      "z": -6,
      "name": "Rock_Magma_Cooled"
    },
    {
      "x": 6,
      "y": 17,
      "z": -6,
      "name": "Plant_Moss_Rug_Pink",
      "support": 15
    },
    {
      "x": 6,
      "y": 14,
      "z": -5,
      "name": "Rock_Magma_Cooled"
    },
    {
      "x": 6,
      "y": 15,
      "z": -5,
      "name": "Ore_Adamantite_Magma_Cracked"
    },
    {
      "x": 6,
      "y": 16,
      "z": -5,
      "name": "Plant_Moss_Rug_Pink",
      "support": 15
    },
    {
      "x": 6,
      "y": 13,
      "z": -4,
      "name": "Rock_Magma_Cooled"
    },
    {
      "x": 6,
      "y": 14,
      "z": -4,
      "name": "Ore_Adamantite_Magma_Cracked"
    },
    {
      "x": 6,
      "y": 15,
      "z": -4,
      "name": "Rock_Magma_Cooled"
    },
    {
      "x": 6,
      "y": 16,
      "z": -4,
      "name": "Plant_Moss_Rug_Pink",
      "support": 15
    },
    {
      "x": 6,
      "y": 14,
      "z": -3,
      "name": "Plant_Vine_Wall_Poisoned",
      "support": 15
    },
    {
      "x": 6,
      "y": 0,
      "z": -2,
      "name": "Soil_Sand_Ashen"
    },
    {
      "x": 6,
      "y": 0,
      "z": -1,
      "name": "Soil_Sand_Ashen"
    },
    {
      "x": 6,
      "y": 1,
      "z": -1,
      "name": "Soil_Sand_Ashen"
    },
    {
      "x": 6,
      "y": 0,
      "z": 0,
      "name": "Soil_Ash"
    },
    {
      "x": 6,
      "y": 1,
      "z": 0,
      "name": "Soil_Sand_Ashen"
    },
    {
      "x": 6,
      "y": 0,
      "z": 1,
      "name": "Soil_Sand_Ashen"
    },
    {
      "x": 6,
      "y": 1,
      "z": 1,
      "name": "Soil_Sand_Ashen"
    },
    {
      "x": 6,
      "y": 2,
      "z": 1,
      "name": "Soil_Ash"
    },
    {
      "x": 6,
      "y": 3,
      "z": 1,
      "name": "Plant_Flower_Bushy_Poisoned"
    },
    {
      "x": 6,
      "y": 0,
      "z": 2,
      "name": "Soil_Ash"
    },
    {
      "x": 6,
      "y": 1,
      "z": 2,
      "name": "Soil_Ash"
    },
    {
      "x": 6,
      "y": 2,
      "z": 2,
      "name": "Soil_Ash"
    },
    {
      "x": 6,
      "y": 3,
      "z": 2,
      "name": "Plant_Flower_Bushy_Poisoned"
    },
    {
      "x": 6,
      "y": 0,
      "z": 3,
      "name": "Soil_Sand_Ashen"
    },
    {
      "x": 6,
      "y": 1,
      "z": 3,
      "name": "Soil_Ash"
    },
    {
      "x": 6,
      "y": 2,
      "z": 3,
      "name": "Soil_Ash"
    },
    {
      "x": 6,
      "y": 3,
      "z": 3,
      "name": "Plant_Crop_Mushroom_Glowing_Purple"
    },
    {
      "x": 6,
      "y": 0,
      "z": 4,
      "name": "Soil_Ash"
    },
    {
      "x": 6,
      "y": 1,
      "z": 4,
      "name": "Soil_Sand_Ashen"
    },
    {
      "x": 6,
      "y": 2,
      "z": 4,
      "name": "Plant_Flower_Bushy_Violet"
    },
    {
      "x": 6,
      "y": 0,
      "z": 5,
      "name": "Soil_Sand_Ashen"
    },
    {
      "x": 6,
      "y": 1,
      "z": 5,
      "name": "Soil_Sand_Ashen"
    },
    {
      "x": 6,
      "y": 0,
      "z": 6,
      "name": "Soil_Sand_Ashen"
    },
    {
      "x": 7,
      "y": 17,
      "z": -7,
      "name": "Plant_Vine_Wall_Poisoned",
      "support": 15,
      "rotation": 2
    },
    {
      "x": 7,
      "y": 18,
      "z": -7,
      "name": "Rock_Magma_Cooled"
    },
    {
      "x": 7,
      "y": 19,
      "z": -7,
      "name": "Plant_Moss_Rug_Pink",
      "support": 15
    },
    {
      "x": 7,
      "y": 15,
      "z": -6,
      "name": "Rock_Magma_Cooled"
    },
    {
      "x": 7,
      "y": 16,
      "z": -6,
      "name": "Ore_Adamantite_Magma_Cracked"
    },
    {
      "x": 7,
      "y": 17,
      "z": -6,
      "name": "Rock_Magma_Cooled"
    },
    {
      "x": 7,
      "y": 18,
      "z": -6,
      "name": "Ore_Adamantite_Magma_Cracked"
    },
    {
      "x": 7,
      "y": 19,
      "z": -6,
      "name": "Plant_Moss_Rug_Pink",
      "support": 15
    },
    {
      "x": 7,
      "y": 15,
      "z": -5,
      "name": "Rock_Magma_Cooled"
    },
    {
      "x": 7,
      "y": 16,
      "z": -5,
      "name": "Rock_Magma_Cooled"
    },
    {
      "x": 7,
      "y": 17,
      "z": -5,
      "name": "Plant_Moss_Rug_Pink",
      "support": 15
    },
    {
      "x": 7,
      "y": 14,
      "z": -4,
      "name": "Rock_Magma_Cooled"
    },
    {
      "x": 7,
      "y": 15,
      "z": -4,
      "name": "Ore_Adamantite_Magma_Cracked"
    },
    {
      "x": 7,
      "y": 16,
      "z": -4,
      "name": "Rock_Magma_Cooled"
    },
    {
      "x": 7,
      "y": 0,
      "z": -1,
      "name": "Soil_Ash"
    },
    {
      "x": 7,
      "y": 0,
      "z": 0,
      "name": "Soil_Ash"
    },
    {
      "x": 7,
      "y": 1,
      "z": 0,
      "name": "Soil_Sand_Ashen"
    },
    {
      "x": 7,
      "y": 0,
      "z": 1,
      "name": "Soil_Sand_Ashen"
    },
    {
      "x": 7,
      "y": 1,
      "z": 1,
      "name": "Soil_Sand_Ashen"
    },
    {
      "x": 7,
      "y": 0,
      "z": 2,
      "name": "Soil_Sand_Ashen"
    },
    {
      "x": 7,
      "y": 1,
      "z": 2,
      "name": "Soil_Sand_Ashen"
    },
    {
      "x": 7,
      "y": 0,
      "z": 3,
      "name": "Soil_Sand_Ashen"
    },
    {
      "x": 7,
      "y": 1,
      "z": 3,
      "name": "Soil_Ash"
    },
    {
