{
  "version": 8,
  "blockIdVersion": 11,
  "anchorX": 0,
  "anchorY": 0,
  "anchorZ": 0,
  "blocks": [
    {
      "x": -12,
      "y": 39,
      "z": -2,
      "name": "Plant_Vine_Wall_Poisoned",
      "support": 15,
      "rotation": 2
    },
    {
      "x": -12,
      "y": 40,
      "z": -2,
      "name": "Plant_Vine_Wall_Poisoned",
      "support": 15,
      "rotation": 2
    },
    {
      "x": -12,
      "y": 41,
      "z": -2,
      "name": "Plant_Vine_Wall_Poisoned",
      "support": 15,
      "rotation": 2
    },
    {
      "x": -12,
      "y": 39,
      "z": -1,
      "name": "Rock_Magma_Cooled",
      "rotation": 1
    },
    {
      "x": -12,
      "y": 40,
      "z": -1,
      "name": "Rock_Magma_Cooled",
      "rotation": 1
    },
    {
      "x": -12,
      "y": 41,
      "z": -1,
      "name": "Rock_Magma_Cooled",
      "rotation": 1
    },
    {
      "x": -12,
      "y": 42,
      "z": -1,
      "name": "Rock_Magma_Cooled",
      "rotation": 1
    },
    {
      "x": -12,
      "y": 43,
      "z": -1,
      "name": "Plant_Moss_Rug_Pink",
      "support": 15
    },
    {
      "x": -12,
      "y": 37,
      "z": 0,
      "name": "Rock_Magma_Cooled",
      "rotation": 1
    },
    {
      "x": -12,
      "y": 38,
      "z": 0,
      "name": "Rock_Magma_Cooled",
      "rotation": 1
    },
    {
      "x": -12,
      "y": 39,
      "z": 0,
      "name": "Rock_Magma_Cooled",
      "rotation": 1
    },
    {
      "x": -12,
      "y": 40,
      "z": 0,
      "name": "Rock_Magma_Cooled",
      "rotation": 1
    },
    {
      "x": -12,
      "y": 41,
      "z": 0,
      "name": "Plant_Moss_Rug_Pink",
      "support": 15
    },
    {
      "x": -11,
      "y": 36,
      "z": -1,
      "name": "Plant_Vine_Wall_Poisoned",
      "support": 15,
      "rotation": 2
    },
    {
      "x": -11,
      "y": 39,
      "z": -1,
      "name": "Plant_Vine_Wall_Poisoned",
      "support": 15,
      "rotation": 2
    },
    {
      "x": -11,
      "y": 36,
      "z": 0,
      "name": "Rock_Magma_Cooled",
      "rotation": 1
    },
    {
      "x": -11,
      "y": 37,
      "z": 0,
      "name": "Rock_Magma_Cooled",
      "rotation": 1
    },
    {
      "x": -11,
      "y": 38,
      "z": 0,
      "name": "Rock_Magma_Cooled",
      "rotation": 1
    },
    {
      "x": -11,
      "y": 39,
      "z": 0,
      "name": "Rock_Magma_Cooled",
      "rotation": 1
    },
    {
      "x": -11,
      "y": 40,
      "z": 0,
      "name": "Plant_Moss_Rug_Pink",
      "support": 15
    },
    {
      "x": -11,
      "y": 35,
      "z": 1,
      "name": "Rock_Magma_Cooled",
      "rotation": 1
    },
    {
      "x": -11,
      "y": 36,
      "z": 1,
      "name": "Ore_Adamantite_Magma_Cracked",
      "rotation": 1
    },
    {
      "x": -11,
      "y": 37,
      "z": 1,
      "name": "Rock_Magma_Cooled",
      "rotation": 1
    },
    {
      "x": -11,
      "y": 38,
      "z": 1,
      "name": "Plant_Moss_Rug_Pink",
      "support": 15
    },
    {
      "x": -11,
      "y": 33,
      "z": 2,
      "name": "Rock_Magma_Cooled",
      "rotation": 1
    },
    {
      "x": -11,
      "y": 34,
      "z": 2,
      "name": "Ore_Adamantite_Magma_Cracked",
      "rotation": 1
    },
    {
      "x": -11,
      "y": 35,
      "z": 2,
      "name": "Ore_Adamantite_Magma_Cracked",
      "rotation": 1
    },
    {
      "x": -11,
      "y": 36,
      "z": 2,
      "name": "Rock_Magma_Cooled",
      "rotation": 1
    },
    {
      "x": -11,
      "y": 37,
      "z": 2,
      "name": "Plant_Moss_Rug_Pink",
      "support": 15
    },
    {
      "x": -11,
      "y": 34,
      "z": 3,
      "name": "Rock_Magma_Cooled",
      "rotation": 1
    },
    {
      "x": -11,
      "y": 35,
      "z": 3,
      "name": "Rock_Magma_Cooled",
      "rotation": 1
    },
    {
      "x": -10,
      "y": 34,
      "z": 0,
      "name": "Plant_Vine_Wall_Poisoned",
      "support": 15,
      "rotation": 2
    },
    {
      "x": -10,
      "y": 36,
      "z": 0,
      "name": "Plant_Vine_Wall_Poisoned",
      "support": 15,
      "rotation": 2
    },
    {
      "x": -10,
      "y": 31,
      "z": 1,
      "name": "Rock_Magma_Cooled",
      "rotation": 1
    },
    {
      "x": -10,
      "y": 32,
      "z": 1,
      "name": "Rock_Magma_Cooled",
      "rotation": 1
    },
    {
      "x": -10,
      "y": 33,
      "z": 1,
      "name": "Ore_Adamantite_Magma_Cracked",
      "rotation": 1
    },
    {
      "x": -10,
      "y": 34,
      "z": 1,
      "name": "Rock_Magma_Cooled",
      "rotation": 1
    },
    {
      "x": -10,
      "y": 35,
      "z": 1,
      "name": "Rock_Magma_Cooled",
      "rotation": 1
    },
    {
      "x": -10,
      "y": 36,
      "z": 1,
      "name": "Rock_Magma_Cooled",
      "rotation": 1
    },
    {
      "x": -10,
      "y": 30,
      "z": 2,
      "name": "Rock_Magma_Cooled",
      "rotation": 1
    },
    {
      "x": -10,
      "y": 31,
      "z": 2,
      "name": "Rock_Magma_Cooled",
      "rotation": 1
    },
    {
      "x": -10,
      "y": 32,
      "z": 2,
      "name": "Ore_Adamantite_Magma_Cracked",
      "rotation": 1
    },
    {
      "x": -10,
      "y": 33,
      "z": 2,
      "name": "Ore_Adamantite_Magma_Cracked",
      "rotation": 1
    },
    {
      "x": -10,
      "y": 34,
      "z": 2,
      "name": "Rock_Magma_Cooled",
      "rotation": 1
    },
    {
      "x": -10,
      "y": 35,
      "z": 2,
      "name": "Rock_Magma_Cooled",
      "rotation": 1
    },
    {
      "x": -10,
      "y": 29,
      "z": 3,
      "name": "Rock_Magma_Cooled",
      "rotation": 1
    },
    {
      "x": -10,
      "y": 30,
      "z": 3,
      "name": "Rock_Magma_Cooled",
      "rotation": 1
    },
    {
      "x": -10,
      "y": 31,
      "z": 3,
      "name": "Rock_Magma_Cooled",
      "rotation": 1
    },
    {
      "x": -10,
      "y": 32,
      "z": 3,
      "name": "Rock_Magma_Cooled",
      "rotation": 1
    },
    {
      "x": -10,
      "y": 33,
      "z": 3,
      "name": "Rock_Magma_Cooled",
      "rotation": 1
    },
    {
      "x": -10,
      "y": 34,
      "z": 3,
      "name": "Rock_Magma_Cooled",
      "rotation": 1
    },
    {
      "x": -10,
      "y": 26,
      "z": 4,
      "name": "Plant_Vine_Wall_Poisoned",
      "support": 15,
      "rotation": 3
    },
    {
      "x": -10,
      "y": 31,
      "z": 4,
      "name": "Rock_Magma_Cooled",
      "rotation": 1
    },
    {
      "x": -10,
      "y": 32,
      "z": 4,
      "name": "Rock_Magma_Cooled",
      "rotation": 1
    },
    {
      "x": -10,
      "y": 20,
      "z": 6,
      "name": "Plant_Vine_Wall_Poisoned",
      "support": 15,
      "rotation": 3
    },
    {
      "x": -10,
      "y": 21,
      "z": 7,
      "name": "Plant_Vine_Wall_Poisoned",
      "support": 15,
      "rotation": 3
    },
    {
      "x": -9,
      "y": 33,
      "z": 0,
      "name": "Plant_Vine_Wall_Poisoned",
      "support": 15,
      "rotation": 2
    },
    {
      "x": -9,
      "y": 34,
      "z": 0,
      "name": "Plant_Vine_Wall_Poisoned",
      "support": 15,
      "rotation": 2
    },
    {
      "x": -9,
      "y": 32,
      "z": 1,
      "name": "Rock_Magma_Cooled",
      "rotation": 1
    },
    {
      "x": -9,
      "y": 33,
      "z": 1,
      "name": "Rock_Magma_Cooled",
      "rotation": 1
    },
    {
      "x": -9,
      "y": 34,
      "z": 1,
      "name": "Rock_Magma_Cooled",
      "rotation": 1
    },
    {
      "x": -9,
      "y": 30,
      "z": 2,
      "name": "Rock_Magma_Cooled",
      "rotation": 1
    },
    {
      "x": -9,
      "y": 31,
      "z": 2,
      "name": "Rock_Magma_Cooled",
      "rotation": 1
    },
    {
      "x": -9,
      "y": 32,
      "z": 2,
      "name": "Rock_Magma_Cooled",
      "rotation": 1
    },
    {
      "x": -9,
      "y": 33,
      "z": 2,
      "name": "Rock_Magma_Cooled",
      "rotation": 1
    },
    {
      "x": -9,
      "y": 27,
      "z": 3,
      "name": "Rock_Magma_Cooled",
      "rotation": 1
    },
    {
      "x": -9,
      "y": 28,
      "z": 3,
      "name": "Rock_Magma_Cooled",
      "rotation": 1
    },
    {
      "x": -9,
      "y": 29,
      "z": 3,
      "name": "Ore_Adamantite_Magma_Cracked",
      "rotation": 1
    },
    {
      "x": -9,
      "y": 30,
      "z": 3,
      "name": "Rock_Magma_Cooled",
      "rotation": 1
    },
    {
      "x": -9,
      "y": 31,
      "z": 3,
      "name": "Rock_Magma_Cooled",
      "rotation": 1
    },
    {
      "x": -9,
      "y": 32,
      "z": 3,
      "name": "Rock_Magma_Cooled",
      "rotation": 1
    },
    {
      "x": -9,
      "y": 33,
      "z": 3,
      "name": "Rock_Magma_Cooled",
      "rotation": 1
    },
    {
      "x": -9,
      "y": 26,
      "z": 4,
      "name": "Rock_Magma_Cooled",
      "rotation": 1
    },
    {
      "x": -9,
      "y": 27,
      "z": 4,
      "name": "Rock_Magma_Cooled",
      "rotation": 1
    },
    {
      "x": -9,
      "y": 28,
      "z": 4,
      "name": "Rock_Magma_Cooled",
      "rotation": 1
    },
    {
      "x": -9,
      "y": 29,
      "z": 4,
      "name": "Rock_Magma_Cooled",
      "rotation": 1
    },
    {
      "x": -9,
      "y": 30,
      "z": 4,
      "name": "Rock_Magma_Cooled",
      "rotation": 1
    },
    {
      "x": -9,
      "y": 31,
      "z": 4,
      "name": "Rock_Magma_Cooled",
      "rotation": 1
    },
    {
      "x": -9,
      "y": 32,
      "z": 4,
      "name": "Ore_Adamantite_Magma_Cracked",
      "rotation": 1
    },
    {
      "x": -9,
      "y": 26,
      "z": 5,
      "name": "Rock_Magma_Cooled",
      "rotation": 1
    },
    {
      "x": -9,
      "y": 27,
      "z": 5,
      "name": "Rock_Magma_Cooled",
      "rotation": 1
    },
    {
      "x": -9,
      "y": 28,
      "z": 5,
      "name": "Ore_Adamantite_Magma_Cracked",
      "rotation": 1
    },
    {
      "x": -9,
      "y": 29,
      "z": 5,
      "name": "Ore_Adamantite_Magma_Cracked",
      "rotation": 1
    },
    {
      "x": -9,
      "y": 30,
      "z": 5,
      "name": "Rock_Magma_Cooled",
      "rotation": 1
    },
    {
      "x": -9,
      "y": 31,
      "z": 5,
      "name": "Rock_Magma_Cooled",
      "rotation": 1
    },
    {
      "x": -9,
      "y": 19,
      "z": 6,
      "name": "Rock_Magma_Cooled"
    },
    {
      "x": -9,
      "y": 20,
      "z": 6,
      "name": "Rock_Magma_Cooled"
    },
    {
      "x": -9,
      "y": 21,
      "z": 6,
      "name": "Rock_Magma_Cooled",
      "rotation": 1
    },
    {
      "x": -9,
      "y": 22,
      "z": 6,
      "name": "Rock_Magma_Cooled",
      "rotation": 1
    },
    {
      "x": -9,
      "y": 23,
      "z": 6,
      "name": "Rock_Magma_Cooled",
      "rotation": 1
    },
    {
      "x": -9,
      "y": 24,
      "z": 6,
      "name": "Rock_Magma_Cooled",
      "rotation": 1
    },
    {
      "x": -9,
      "y": 25,
      "z": 6,
      "name": "Rock_Magma_Cooled",
      "rotation": 1
    },
    {
      "x": -9,
      "y": 26,
      "z": 6,
      "name": "Rock_Magma_Cooled",
      "rotation": 1
    },
    {
      "x": -9,
      "y": 27,
      "z": 6,
      "name": "Rock_Magma_Cooled",
      "rotation": 1
    },
    {
      "x": -9,
      "y": 21,
      "z": 7,
      "name": "Rock_Magma_Cooled",
      "rotation": 1
    },
    {
      "x": -9,
      "y": 22,
      "z": 7,
      "name": "Rock_Magma_Cooled",
      "rotation": 1
    },
    {
      "x": -9,
      "y": 23,
      "z": 7,
      "name": "Rock_Magma_Cooled",
      "rotation": 1
    },
    {
      "x": -8,
      "y": 0,
      "z": -8,
      "name": "Soil_Ash"
    },
    {
      "x": -8,
      "y": 0,
      "z": -7,
      "name": "Soil_Ash"
    },
    {
      "x": -8,
      "y": 0,
      "z": -6,
      "name": "Soil_Ash"
    },
    {
      "x": -8,
      "y": 32,
      "z": 1,
      "name": "Plant_Vine_Wall_Poisoned",
      "support": 15,
      "rotation": 2
    },
    {
      "x": -8,
      "y": 31,
      "z": 2,
      "name": "Rock_Magma_Cooled",
      "rotation": 1
    },
    {
      "x": -8,
      "y": 32,
      "z": 2,
      "name": "Rock_Magma_Cooled",
      "rotation": 1
    },
    {
      "x": -8,
      "y": 33,
      "z": 2,
      "name": "Rock_Magma_Cooled",
      "rotation": 1
    },
    {
      "x": -8,
      "y": 27,
      "z": 3,
      "name": "Ore_Adamantite_Magma_Cracked",
      "rotation": 1
    },
    {
      "x": -8,
      "y": 28,
      "z": 3,
      "name": "Rock_Magma_Cooled",
      "rotation": 1
    },
    {
      "x": -8,
      "y": 29,
      "z": 3,
      "name": "Rock_Magma_Cooled",
      "rotation": 1
    },
    {
      "x": -8,
      "y": 30,
      "z": 3,
      "name": "Rock_Magma_Cooled",
      "rotation": 1
    },
    {
      "x": -8,
      "y": 31,
      "z": 3,
      "name": "Rock_Magma_Cooled",
      "rotation": 1
    },
    {
      "x": -8,
      "y": 22,
      "z": 4,
      "name": "Plant_Vine_Wall_Poisoned",
      "support": 15,
      "rotation": 2
    },
    {
      "x": -8,
      "y": 23,
      "z": 4,
      "name": "Plant_Vine_Wall_Poisoned",
      "support": 15,
      "rotation": 2
    },
    {
      "x": -8,
      "y": 24,
      "z": 4,
      "name": "Plant_Vine_Wall_Poisoned",
      "support": 15,
      "rotation": 2
    },
    {
      "x": -8,
      "y": 25,
      "z": 4,
      "name": "Rock_Magma_Cooled",
      "rotation": 1
    },
    {
      "x": -8,
      "y": 26,
      "z": 4,
      "name": "Rock_Magma_Cooled",
      "rotation": 1
    },
    {
      "x": -8,
      "y": 27,
      "z": 4,
      "name": "Rock_Magma_Cooled",
      "rotation": 1
    },
    {
      "x": -8,
      "y": 28,
      "z": 4,
      "name": "Ore_Adamantite_Magma_Cracked",
      "rotation": 1
    },
    {
      "x": -8,
      "y": 29,
      "z": 4,
      "name": "Rock_Magma_Cooled",
      "rotation": 1
    },
    {
      "x": -8,
      "y": 30,
      "z": 4,
      "name": "Rock_Magma_Cooled",
      "rotation": 1
    },
    {
      "x": -8,
      "y": 31,
      "z": 4,
      "name": "Rock_Magma_Cooled",
      "rotation": 1
    },
    {
      "x": -8,
      "y": 19,
      "z": 5,
      "name": "Rock_Magma_Cooled"
    },
    {
      "x": -8,
      "y": 20,
      "z": 5,
      "name": "Ore_Adamantite_Magma_Cracked"
    },
    {
      "x": -8,
      "y": 21,
      "z": 5,
      "name": "Ore_Adamantite_Magma_Cracked",
      "rotation": 1
    },
    {
      "x": -8,
      "y": 22,
      "z": 5,
      "name": "Rock_Magma_Cooled",
      "rotation": 1
    },
    {
      "x": -8,
      "y": 23,
      "z": 5,
      "name": "Rock_Magma_Cooled",
      "rotation": 1
    },
    {
      "x": -8,
      "y": 24,
      "z": 5,
      "name": "Ore_Adamantite_Magma_Cracked",
      "rotation": 1
    },
    {
      "x": -8,
      "y": 25,
      "z": 5,
      "name": "Rock_Magma_Cooled",
      "rotation": 1
    },
    {
      "x": -8,
      "y": 26,
      "z": 5,
      "name": "Rock_Magma_Cooled",
      "rotation": 1
    },
    {
      "x": -8,
      "y": 27,
      "z": 5,
      "name": "Ore_Adamantite_Magma_Cracked",
      "rotation": 1
    },
    {
      "x": -8,
      "y": 28,
      "z": 5,
      "name": "Rock_Magma_Cooled",
      "rotation": 1
    },
    {
      "x": -8,
      "y": 29,
      "z": 5,
      "name": "Rock_Magma_Cooled",
      "rotation": 1
    },
    {
      "x": -8,
      "y": 30,
      "z": 5,
      "name": "Rock_Magma_Cooled",
      "rotation": 1
    },
    {
      "x": -8,
      "y": 31,
      "z": 5,
      "name": "Rock_Magma_Cooled",
      "rotation": 1
    },
    {
      "x": -8,
      "y": 17,
      "z": 6,
      "name": "Rock_Magma_Cooled"
    },
    {
      "x": -8,
      "y": 18,
      "z": 6,
      "name": "Rock_Magma_Cooled"
    },
    {
      "x": -8,
      "y": 19,
      "z": 6,
      "name": "Rock_Magma_Cooled"
    },
    {
      "x": -8,
      "y": 20,
      "z": 6,
      "name": "Ore_Adamantite_Magma_Cracked"
    },
    {
      "x": -8,
      "y": 21,
      "z": 6,
      "name": "Ore_Adamantite_Magma_Cracked",
      "rotation": 1
    },
    {
      "x": -8,
      "y": 22,
      "z": 6,
      "name": "Rock_Magma_Cooled",
      "rotation": 1
    },
    {
      "x": -8,
      "y": 23,
      "z": 6,
      "name": "Rock_Magma_Cooled",
      "rotation": 1
    },
    {
      "x": -8,
      "y": 24,
      "z": 6,
      "name": "Rock_Magma_Cooled",
      "rotation": 1
    },
    {
      "x": -8,
      "y": 25,
      "z": 6,
      "name": "Rock_Magma_Cooled",
      "rotation": 1
    },
    {
      "x": -8,
      "y": 26,
      "z": 6,
      "name": "Ore_Adamantite_Magma_Cracked",
      "rotation": 1
    },
    {
      "x": -8,
      "y": 27,
      "z": 6,
      "name": "Rock_Magma_Cooled",
      "rotation": 1
    },
    {
      "x": -8,
      "y": 28,
      "z": 6,
      "name": "Ore_Adamantite_Magma_Cracked",
      "rotation": 1
    },
    {
      "x": -8,
      "y": 29,
      "z": 6,
      "name": "Rock_Magma_Cooled",
      "rotation": 1
    },
    {
      "x": -8,
      "y": 21,
      "z": 7,
      "name": "Rock_Magma_Cooled",
      "rotation": 1
    },
    {
      "x": -8,
      "y": 22,
      "z": 7,
      "name": "Rock_Magma_Cooled",
      "rotation": 1
    },
    {
      "x": -8,
      "y": 23,
      "z": 7,
      "name": "Rock_Magma_Cooled",
      "rotation": 1
    },
    {
      "x": -8,
      "y": 24,
      "z": 7,
      "name": "Rock_Magma_Cooled",
      "rotation": 1
    },
    {
      "x": -8,
      "y": 25,
      "z": 7,
      "name": "Rock_Magma_Cooled",
      "rotation": 1
    },
    {
      "x": -8,
      "y": 26,
      "z": 7,
      "name": "Rock_Magma_Cooled",
      "rotation": 1
    },
    {
      "x": -7,
      "y": 0,
      "z": -10,
      "name": "Soil_Ash"
    },
    {
      "x": -7,
      "y": 0,
      "z": -9,
      "name": "Soil_Ash"
    },
    {
      "x": -7,
      "y": 1,
      "z": -9,
      "name": "Soil_Ash"
    },
    {
      "x": -7,
      "y": 0,
      "z": -8,
      "name": "Soil_Ash"
    },
    {
      "x": -7,
      "y": 1,
      "z": -8,
      "name": "Soil_Sand_Ashen"
    },
    {
      "x": -7,
      "y": 0,
      "z": -7,
      "name": "Soil_Sand_Ashen"
    },
    {
      "x": -7,
      "y": 1,
      "z": -7,
      "name": "Soil_Ash"
    },
    {
      "x": -7,
      "y": 0,
      "z": -6,
      "name": "Soil_Ash"
    },
    {
      "x": -7,
      "y": 1,
      "z": -6,
      "name": "Soil_Ash"
    },
    {
      "x": -7,
      "y": 0,
      "z": -5,
      "name": "Soil_Sand_Ashen"
    },
    {
      "x": -7,
      "y": 0,
      "z": -4,
      "name": "Soil_Ash"
    },
    {
      "x": -7,
      "y": 30,
      "z": 2,
      "name": "Plant_Vine_Wall_Poisoned",
      "support": 15,
      "rotation": 2
    },
    {
      "x": -7,
      "y": 27,
      "z": 3,
      "name": "Plant_Vine_Wall_Poisoned",
      "support": 15,
      "rotation": 2
    },
    {
      "x": -7,
      "y": 28,
      "z": 3,
      "name": "Rock_Magma_Cooled",
      "rotation": 1
    },
    {
      "x": -7,
      "y": 29,
      "z": 3,
      "name": "Rock_Magma_Cooled",
      "rotation": 1
    },
    {
      "x": -7,
      "y": 30,
      "z": 3,
      "name": "Rock_Magma_Cooled",
      "rotation": 1
    },
    {
      "x": -7,
      "y": 31,
      "z": 3,
      "name": "Rock_Magma_Cooled",
      "rotation": 1
    },
    {
      "x": -7,
      "y": 19,
      "z": 4,
      "name": "Plant_Vine_Wall_Poisoned",
      "support": 15,
      "rotation": 2
    },
    {
      "x": -7,
      "y": 21,
      "z": 4,
      "name": "Plant_Vine_Wall_Poisoned",
      "support": 15,
      "rotation": 2
    },
    {
      "x": -7,
      "y": 22,
      "z": 4,
      "name": "Plant_Vine_Wall_Poisoned",
      "support": 15,
      "rotation": 2
    },
    {
      "x": -7,
      "y": 25,
      "z": 4,
      "name": "Rock_Magma_Cooled",
      "rotation": 1
    },
    {
      "x": -7,
      "y": 26,
      "z": 4,
      "name": "Rock_Magma_Cooled",
      "rotation": 1
    },
    {
      "x": -7,
      "y": 27,
      "z": 4,
      "name": "Rock_Magma_Cooled",
      "rotation": 1
    },
    {
      "x": -7,
      "y": 28,
      "z": 4,
      "name": "Rock_Magma_Cooled",
      "rotation": 1
    },
    {
      "x": -7,
      "y": 29,
      "z": 4,
      "name": "Rock_Magma_Cooled",
      "rotation": 1
    },
    {
      "x": -7,
      "y": 30,
      "z": 4,
      "name": "Rock_Magma_Cooled",
      "rotation": 1
    },
    {
      "x": -7,
      "y": 31,
      "z": 4,
      "name": "Rock_Magma_Cooled",
      "rotation": 1
    },
    {
      "x": -7,
      "y": 17,
      "z": 5,
      "name": "Rock_Magma_Cooled"
    },
    {
      "x": -7,
      "y": 18,
      "z": 5,
      "name": "Rock_Magma_Cooled"
    },
    {
      "x": -7,
      "y": 19,
      "z": 5,
      "name": "Rock_Magma_Cooled"
    },
    {
      "x": -7,
      "y": 20,
      "z": 5,
      "name": "Ore_Adamantite_Magma_Cracked"
    },
    {
      "x": -7,
      "y": 21,
      "z": 5,
      "name": "Rock_Magma_Cooled"
    },
    {
      "x": -7,
      "y": 22,
      "z": 5,
      "name": "Ore_Adamantite_Magma_Cracked",
      "rotation": 1
    },
    {
      "x": -7,
      "y": 23,
      "z": 5,
      "name": "Rock_Magma_Cooled",
      "rotation": 1
    },
    {
      "x": -7,
      "y": 24,
      "z": 5,
      "name": "Rock_Magma_Cooled",
      "rotation": 1
    },
    {
      "x": -7,
      "y": 25,
      "z": 5,
      "name": "Rock_Magma_Cooled",
      "rotation": 1
    },
    {
      "x": -7,
      "y": 26,
      "z": 5,
      "name": "Ore_Adamantite_Magma_Cracked",
      "rotation": 1
    },
    {
      "x": -7,
      "y": 27,
      "z": 5,
      "name": "Ore_Adamantite_Magma_Cracked",
      "rotation": 1
    },
    {
      "x": -7,
      "y": 28,
      "z": 5,
      "name": "Rock_Magma_Cooled",
      "rotation": 1
    },
    {
      "x": -7,
      "y": 29,
      "z": 5,
      "name": "Rock_Magma_Cooled",
      "rotation": 1
    },
    {
      "x": -7,
      "y": 30,
      "z": 5,
      "name": "Rock_Magma_Cooled",
      "rotation": 1
    },
    {
      "x": -7,
      "y": 16,
      "z": 6,
      "name": "Rock_Magma_Cooled"
    },
    {
      "x": -7,
      "y": 17,
      "z": 6,
      "name": "Rock_Magma_Cooled"
    },
    {
      "x": -7,
      "y": 18,
      "z": 6,
      "name": "Rock_Magma_Cooled"
    },
    {
      "x": -7,
      "y": 19,
      "z": 6,
      "name": "Rock_Magma_Cooled"
    },
    {
      "x": -7,
      "y": 20,
      "z": 6,
      "name": "Rock_Magma_Cooled",
      "rotation": 1
    },
    {
      "x": -7,
      "y": 21,
      "z": 6,
      "name": "Rock_Magma_Cooled",
      "rotation": 1
    },
    {
      "x": -7,
      "y": 22,
      "z": 6,
      "name": "Rock_Magma_Cooled",
      "rotation": 1
    },
    {
      "x": -7,
      "y": 23,
      "z": 6,
      "name": "Rock_Magma_Cooled",
      "rotation": 1
    },
    {
      "x": -7,
      "y": 24,
      "z": 6,
      "name": "Rock_Magma_Cooled",
      "rotation": 1
    },
    {
      "x": -7,
      "y": 25,
      "z": 6,
      "name": "Rock_Magma_Cooled",
      "rotation": 1
    },
    {
      "x": -7,
      "y": 26,
      "z": 6,
      "name": "Rock_Magma_Cooled",
      "rotation": 1
    },
    {
      "x": -7,
      "y": 27,
      "z": 6,
      "name": "Rock_Magma_Cooled",
      "rotation": 1
    },
    {
      "x": -7,
      "y": 28,
      "z": 6,
      "name": "Rock_Magma_Cooled",
      "rotation": 1
    },
    {
      "x": -7,
      "y": 29,
      "z": 6,
      "name": "Ore_Adamantite_Magma_Cracked",
      "rotation": 1
    },
    {
      "x": -7,
      "y": 18,
      "z": 7,
      "name": "Plant_Vine_Wall_Poisoned",
      "support": 15
    },
    {
      "x": -7,
      "y": 21,
      "z": 7,
      "name": "Plant_Vine_Wall_Poisoned",
      "support": 15
    },
    {
      "x": -7,
      "y": 22,
      "z": 7,
      "name": "Rock_Magma_Cooled",
      "rotation": 1
    },
    {
      "x": -7,
      "y": 23,
      "z": 7,
      "name": "Ore_Adamantite_Magma_Cracked",
      "rotation": 1
    },
    {
      "x": -7,
      "y": 24,
      "z": 7,
      "name": "Rock_Magma_Cooled",
      "rotation": 1
    },
    {
      "x": -7,
      "y": 25,
      "z": 7,
      "name": "Rock_Magma_Cooled",
      "rotation": 1
    },
    {
      "x": -7,
      "y": 26,
      "z": 7,
      "name": "Rock_Magma_Cooled",
      "rotation": 1
    },
    {
      "x": -7,
      "y": 27,
      "z": 7,
      "name": "Rock_Magma_Cooled",
      "rotation": 1
    },
    {
      "x": -7,
      "y": 28,
      "z": 7,
      "name": "Rock_Magma_Cooled",
      "rotation": 1
    },
    {
      "x": -7,
      "y": 29,
      "z": 7,
      "name": "Rock_Magma_Cooled",
      "rotation": 1
    },
    {
      "x": -7,
      "y": 23,
      "z": 8,
      "name": "Rock_Magma_Cooled",
      "rotation": 1
    },
    {
      "x": -7,
      "y": 24,
      "z": 8,
      "name": "Rock_Magma_Cooled",
      "rotation": 1
    },
    {
      "x": -7,
      "y": 25,
      "z": 8,
      "name": "Ore_Adamantite_Magma_Cracked",
      "rotation": 1
    },
    {
      "x": -7,
      "y": 26,
      "z": 8,
      "name": "Plant_Vine_Wall_Poisoned",
      "support": 15
    },
    {
      "x": -7,
      "y": 27,
      "z": 8,
      "name": "Rock_Magma_Cooled",
      "rotation": 1
    },
    {
      "x": -7,
      "y": 28,
      "z": 8,
      "name": "Rock_Magma_Cooled",
      "rotation": 1
    },
    {
      "x": -7,
      "y": 24,
      "z": 9,
      "name": "Plant_Vine_Wall_Poisoned",
      "support": 15
    },
    {
      "x": -6,
      "y": 0,
      "z": -12,
      "name": "Soil_Sand_Ashen"
    },
    {
      "x": -6,
      "y": 0,
      "z": -11,
      "name": "Soil_Ash"
    },
    {
      "x": -6,
      "y": 1,
      "z": -11,
      "name": "Soil_Ash"
    },
    {
      "x": -6,
      "y": 0,
      "z": -10,
      "name": "Soil_Ash"
    },
    {
      "x": -6,
      "y": 1,
      "z": -10,
      "name": "Soil_Ash"
    },
    {
      "x": -6,
      "y": 0,
      "z": -9,
      "name": "Soil_Ash"
    },
    {
      "x": -6,
      "y": 1,
      "z": -9,
      "name": "Soil_Ash"
    },
    {
      "x": -6,
      "y": 2,
      "z": -9,
      "name": "Soil_Ash"
    },
    {
      "x": -6,
      "y": 0,
      "z": -8,
      "name": "Soil_Ash"
    },
    {
      "x": -6,
      "y": 1,
      "z": -8,
      "name": "Soil_Ash"
    },
    {
      "x": -6,
      "y": 2,
      "z": -8,
      "name": "Soil_Ash"
    },
    {
      "x": -6,
      "y": 0,
      "z": -7,
      "name": "Soil_Ash"
    },
    {
      "x": -6,
      "y": 1,
      "z": -7,
      "name": "Soil_Ash"
    },
    {
      "x": -6,
      "y": 2,
      "z": -7,
      "name": "Soil_Ash"
    },
    {
      "x": -6,
      "y": 0,
      "z": -6,
      "name": "Soil_Ash"
    },
    {
      "x": -6,
      "y": 1,
      "z": -6,
      "name": "Soil_Ash"
    },
    {
      "x": -6,
      "y": 0,
      "z": -5,
      "name": "Soil_Ash"
    },
    {
      "x": -6,
      "y": 1,
      "z": -5,
      "name": "Soil_Ash"
    },
    {
      "x": -6,
      "y": 0,
      "z": -4,
      "name": "Soil_Ash"
    },
    {
      "x": -6,
      "y": 15,
      "z": 3,
      "name": "Ore_Adamantite_Magma_Cracked"
    },
    {
      "x": -6,
      "y": 16,
      "z": 3,
      "name": "Ore_Adamantite_Magma_Cracked"
    },
    {
      "x": -6,
      "y": 14,
      "z": 4,
      "name": "Rock_Magma_Cooled"
    },
    {
      "x": -6,
      "y": 15,
      "z": 4,
      "name": "Ore_Adamantite_Magma_Cracked"
    },
    {
      "x": -6,
      "y": 16,
      "z": 4,
      "name": "Rock_Magma_Cooled"
    },
    {
      "x": -6,
      "y": 17,
      "z": 4,
      "name": "Rock_Magma_Cooled"
    },
    {
      "x": -6,
      "y": 18,
      "z": 4,
      "name": "Rock_Magma_Cooled"
    },
    {
      "x": -6,
      "y": 19,
      "z": 4,
      "name": "Rock_Magma_Cooled"
    },
    {
      "x": -6,
      "y": 26,
      "z": 4,
      "name": "Ore_Adamantite_Magma_Cracked",
      "rotation": 1
    },
    {
      "x": -6,
      "y": 27,
      "z": 4,
      "name": "Rock_Magma_Cooled",
      "rotation": 1
    },
    {
      "x": -6,
      "y": 28,
      "z": 4,
      "name": "Ore_Adamantite_Magma_Cracked",
      "rotation": 1
    },
    {
      "x": -6,
      "y": 29,
      "z": 4,
      "name": "Ore_Adamantite_Magma_Cracked",
      "rotation": 1
    },
    {
      "x": -6,
      "y": 13,
      "z": 5,
      "name": "Rock_Magma_Cooled"
    },
    {
      "x": -6,
      "y": 14,
      "z": 5,
      "name": "Rock_Magma_Cooled"
    },
    {
      "x": -6,
      "y": 15,
      "z": 5,
      "name": "Rock_Magma_Cooled"
    },
    {
      "x": -6,
      "y": 16,
      "z": 5,
      "name": "Rock_Magma_Cooled"
    },
    {
      "x": -6,
      "y": 17,
      "z": 5,
      "name": "Rock_Magma_Cooled"
    },
    {
      "x": -6,
      "y": 18,
      "z": 5,
      "name": "Rock_Magma_Cooled"
    },
    {
      "x": -6,
      "y": 19,
      "z": 5,
      "name": "Rock_Magma_Cooled"
    },
    {
      "x": -6,
      "y": 20,
      "z": 5,
      "name": "Rock_Magma_Cooled"
    },
    {
      "x": -6,
      "y": 24,
      "z": 5,
      "name": "Ore_Adamantite_Magma_Cracked",
      "rotation": 1
    },
    {
      "x": -6,
      "y": 25,
      "z": 5,
      "name": "Ore_Adamantite_Magma_Cracked",
      "rotation": 1
    },
    {
      "x": -6,
      "y": 26,
      "z": 5,
      "name": "Ore_Adamantite_Magma",
      "rotation": 1
    },
    {
      "x": -6,
      "y": 27,
      "z": 5,
      "name": "Ore_Adamantite_Magma",
      "rotation": 1
    },
    {
      "x": -6,
      "y": 28,
      "z": 5,
      "name": "Rock_Magma_Cooled",
      "rotation": 1
    },
    {
      "x": -6,
      "y": 29,
      "z": 5,
      "name": "Rock_Magma_Cooled",
      "rotation": 1
    },
    {
      "x": -6,
      "y": 15,
      "z": 6,
      "name": "Plant_Vine_Wall_Poisoned",
      "support": 15
    },
    {
      "x": -6,
      "y": 18,
      "z": 6,
      "name": "Ore_Adamantite_Magma_Cracked"
    },
    {
      "x": -6,
      "y": 19,
      "z": 6,
      "name": "Rock_Magma_Cooled"
    },
    {
      "x": -6,
      "y": 20,
      "z": 6,
      "name": "Rock_Magma_Cooled"
    },
    {
      "x": -6,
      "y": 21,
      "z": 6,
      "name": "Rock_Magma_Cooled"
    },
    {
      "x": -6,
      "y": 23,
      "z": 6,
      "name": "Rock_Magma_Cooled",
      "rotation": 1
    },
    {
      "x": -6,
      "y": 24,
      "z": 6,
      "name": "Rock_Magma_Cooled",
      "rotation": 1
    },
    {
      "x": -6,
      "y": 25,
      "z": 6,
      "name": "Rock_Magma_Cooled",
      "rotation": 1
    },
    {
      "x": -6,
      "y": 26,
      "z": 6,
      "name": "Rock_Magma_Cooled",
      "rotation": 1
    },
    {
      "x": -6,
      "y": 27,
      "z": 6,
      "name": "Rock_Magma_Cooled",
      "rotation": 1
    },
    {
      "x": -6,
      "y": 28,
      "z": 6,
      "name": "Rock_Magma_Cooled",
      "rotation": 1
    },
    {
      "x": -6,
      "y": 22,
      "z": 7,
      "name": "Rock_Magma_Cooled",
      "rotation": 1
    },
    {
      "x": -6,
      "y": 23,
      "z": 7,
      "name": "Rock_Magma_Cooled",
      "rotation": 1
    },
    {
      "x": -6,
      "y": 24,
      "z": 7,
      "name": "Rock_Magma_Cooled",
      "rotation": 1
    },
    {
      "x": -6,
      "y": 25,
      "z": 7,
      "name": "Rock_Magma_Cooled",
      "rotation": 1
    },
    {
      "x": -6,
      "y": 26,
      "z": 7,
      "name": "Ore_Adamantite_Magma_Cracked",
      "rotation": 1
    },
    {
      "x": -6,
      "y": 27,
      "z": 7,
      "name": "Rock_Magma_Cooled",
      "rotation": 1
    },
    {
      "x": -6,
      "y": 28,
      "z": 7,
      "name": "Rock_Magma_Cooled",
      "rotation": 1
    },
    {
      "x": -6,
      "y": 24,
      "z": 8,
      "name": "Rock_Magma_Cooled",
      "rotation": 1
    },
    {
      "x": -6,
      "y": 25,
      "z": 8,
      "name": "Rock_Magma_Cooled",
      "rotation": 1
    },
    {
      "x": -6,
      "y": 26,
      "z": 8,
      "name": "Ore_Adamantite_Magma_Cracked",
      "rotation": 1
    },
    {
      "x": -6,
      "y": 27,
      "z": 8,
      "name": "Rock_Magma_Cooled",
      "rotation": 1
    },
    {
      "x": -6,
      "y": 28,
      "z": 8,
      "name": "Ore_Adamantite_Magma_Cracked",
      "rotation": 1
    },
    {
      "x": -6,
      "y": 27,
      "z": 9,
      "name": "Rock_Magma_Cooled",
      "rotation": 1
    },
    {
      "x": -6,
      "y": 28,
      "z": 9,
      "name": "Rock_Magma_Cooled",
      "rotation": 1
    },
    {
      "x": -6,
      "y": 29,
      "z": 9,
      "name": "Rock_Magma_Cooled",
      "rotation": 1
    },
    {
      "x": -6,
      "y": 30,
      "z": 9,
      "name": "Rock_Magma_Cooled",
      "rotation": 1
    },
    {
      "x": -6,
      "y": 27,
      "z": 10,
      "name": "Plant_Vine_Wall_Poisoned",
      "support": 15
    },
    {
      "x": -6,
      "y": 28,
      "z": 10,
      "name": "Plant_Vine_Wall_Poisoned",
      "support": 15
    },
    {
      "x": -6,
      "y": 29,
      "z": 10,
      "name": "Rock_Magma_Cooled",
      "rotation": 1
    },
    {
      "x": -6,
      "y": 30,
      "z": 10,
      "name": "Ore_Adamantite_Magma_Cracked",
      "rotation": 1
    },
    {
      "x": -6,
      "y": 31,
      "z": 10,
      "name": "Rock_Magma_Cooled",
      "rotation": 1
    },
    {
      "x": -6,
      "y": 32,
      "z": 10,
      "name": "Ore_Adamantite_Magma_Cracked",
      "rotation": 1
    },
    {
      "x": -6,
      "y": 34,
      "z": 10,
      "name": "Plant_Vine_Wall_Poisoned",
      "support": 15,
      "rotation": 3
    },
    {
      "x": -6,
      "y": 29,
      "z": 11,
      "name": "Plant_Vine_Wall_Poisoned",
      "support": 15
    },
    {
      "x": -6,
      "y": 32,
      "z": 11,
      "name": "Rock_Magma_Cooled",
      "rotation": 1
    },
    {
      "x": -6,
      "y": 33,
      "z": 11,
      "name": "Rock_Magma_Cooled",
      "rotation": 1
    },
    {
      "x": -5,
      "y": 0,
      "z": -13,
      "name": "Soil_Ash"
    },
    {
      "x": -5,
      "y": 0,
      "z": -12,
      "name": "Soil_Sand_Ashen"
    },
    {
      "x": -5,
      "y": 1,
      "z": -12,
      "name": "Soil_Sand_Ashen"
    },
    {
      "x": -5,
      "y": 0,
      "z": -11,
      "name": "Soil_Ash"
    },
    {
      "x": -5,
      "y": 1,
      "z": -11,
      "name": "Soil_Ash"
    },
    {
      "x": -5,
      "y": 0,
      "z": -10,
      "name": "Soil_Ash"
    },
    {
      "x": -5,
      "y": 1,
      "z": -10,
      "name": "Soil_Ash"
    },
    {
      "x": -5,
      "y": 2,
      "z": -10,
      "name": "Soil_Ash"
    },
    {
      "x": -5,
      "y": 0,
      "z": -9,
      "name": "Soil_Ash"
    },
    {
      "x": -5,
      "y": 1,
      "z": -9,
      "name": "Soil_Ash"
    },
    {
      "x": -5,
      "y": 2,
      "z": -9,
      "name": "Soil_Ash"
    },
    {
      "x": -5,
      "y": 3,
      "z": -9,
      "name": "Soil_Ash"
    },
    {
      "x": -5,
      "y": 0,
      "z": -8,
      "name": "Soil_Ash"
    },
    {
      "x": -5,
      "y": 1,
      "z": -8,
      "name": "Soil_Ash"
    },
    {
      "x": -5,
      "y": 2,
      "z": -8,
      "name": "Soil_Ash"
    },
    {
      "x": -5,
      "y": 3,
      "z": -8,
      "name": "Soil_Ash"
    },
    {
      "x": -5,
      "y": 0,
      "z": -7,
      "name": "Soil_Ash"
    },
    {
      "x": -5,
      "y": 1,
      "z": -7,
      "name": "Soil_Ash"
    },
    {
      "x": -5,
      "y": 2,
      "z": -7,
      "name": "Soil_Ash"
    },
    {
      "x": -5,
      "y": 3,
      "z": -7,
      "name": "Soil_Ash"
    },
    {
      "x": -5,
      "y": 0,
      "z": -6,
      "name": "Soil_Ash"
    },
    {
      "x": -5,
      "y": 1,
      "z": -6,
      "name": "Soil_Ash"
    },
    {
      "x": -5,
      "y": 2,
      "z": -6,
      "name": "Soil_Ash"
    },
    {
      "x": -5,
      "y": 0,
      "z": -5,
      "name": "Soil_Sand_Ashen"
    },
    {
      "x": -5,
      "y": 1,
      "z": -5,
      "name": "Soil_Ash"
    },
    {
      "x": -5,
      "y": 0,
      "z": -4,
      "name": "Soil_Sand_Ashen"
    },
    {
      "x": -5,
      "y": 1,
      "z": -4,
      "name": "Soil_Ash"
    },
    {
      "x": -5,
      "y": 0,
      "z": -3,
      "name": "Soil_Ash"
    },
    {
      "x": -5,
      "y": 0,
      "z": 3,
      "name": "Soil_Ash"
    },
    {
      "x": -5,
      "y": 12,
      "z": 3,
      "name": "Rock_Magma_Cooled"
    },
    {
      "x": -5,
      "y": 13,
      "z": 3,
      "name": "Rock_Magma_Cooled"
    },
    {
      "x": -5,
      "y": 14,
      "z": 3,
      "name": "Ore_Adamantite_Magma_Cracked"
    },
    {
      "x": -5,
      "y": 15,
      "z": 3,
      "name": "Ore_Adamantite_Magma_Cracked"
    },
    {
      "x": -5,
      "y": 0,
      "z": 4,
      "name": "Soil_Ash"
    },
    {
      "x": -5,
      "y": 12,
      "z": 4,
      "name": "Rock_Magma_Cooled"
    },
    {
      "x": -5,
      "y": 13,
      "z": 4,
      "name": "Rock_Magma_Cooled"
    },
    {
      "x": -5,
      "y": 14,
      "z": 4,
      "name": "Rock_Magma_Cooled"
    },
    {
      "x": -5,
      "y": 15,
      "z": 4,
      "name": "Rock_Magma_Cooled"
    },
    {
      "x": -5,
      "y": 16,
      "z": 4,
      "name": "Rock_Magma_Cooled"
    },
    {
      "x": -5,
      "y": 17,
      "z": 4,
      "name": "Rock_Magma_Cooled"
    },
    {
      "x": -5,
      "y": 18,
      "z": 4,
      "name": "Rock_Magma_Cooled"
    },
    {
      "x": -5,
      "y": 19,
      "z": 4,
      "name": "Plant_Vine_Wall_Poisoned",
      "support": 15,
      "rotation": 2
    },
    {
      "x": -5,
      "y": 28,
      "z": 4,
      "name": "Ore_Adamantite_Magma",
      "rotation": 1
    },
    {
      "x": -5,
      "y": 0,
      "z": 5,
      "name": "Soil_Ash"
    },
    {
      "x": -5,
      "y": 12,
      "z": 5,
      "name": "Rock_Magma_Cooled"
    },
    {
      "x": -5,
      "y": 13,
      "z": 5,
      "name": "Ore_Adamantite_Magma_Cracked"
    },
    {
      "x": -5,
      "y": 14,
      "z": 5,
      "name": "Rock_Magma_Cooled"
    },
    {
      "x": -5,
      "y": 15,
      "z": 5,
      "name": "Ore_Adamantite_Magma_Cracked"
    },
    {
      "x": -5,
      "y": 16,
      "z": 5,
      "name": "Rock_Magma_Cooled"
    },
    {
      "x": -5,
      "y": 17,
      "z": 5,
      "name": "Rock_Magma_Cooled"
    },
    {
      "x": -5,
      "y": 18,
      "z": 5,
      "name": "Rock_Magma_Cooled"
    },
    {
      "x": -5,
      "y": 19,
      "z": 5,
      "name": "Rock_Magma_Cooled"
    },
    {
      "x": -5,
      "y": 27,
      "z": 5,
      "name": "Rock_Magma_Cooled",
      "rotation": 1
    },
    {
      "x": -5,
      "y": 28,
      "z": 5,
      "name": "Rock_Magma_Cooled",
      "rotation": 1
    },
    {
      "x": -5,
      "y": 16,
      "z": 6,
      "name": "Plant_Vine_Wall_Poisoned",
      "support": 15
    },
    {
      "x": -5,
      "y": 17,
      "z": 6,
      "name": "Ore_Adamantite_Magma_Cracked"
    },
    {
      "x": -5,
      "y": 23,
      "z": 6,
      "name": "Rock_Magma_Cooled",
      "rotation": 1
    },
    {
      "x": -5,
      "y": 24,
      "z": 6,
      "name": "Rock_Magma_Cooled",
      "rotation": 1
    },
    {
      "x": -5,
      "y": 25,
      "z": 6,
      "name": "Rock_Magma_Cooled",
      "rotation": 1
    },
    {
      "x": -5,
      "y": 26,
      "z": 6,
      "name": "Rock_Magma_Cooled",
      "rotation": 1
    },
    {
      "x": -5,
      "y": 27,
      "z": 6,
      "name": "Rock_Magma_Cooled",
      "rotation": 1
    },
    {
      "x": -5,
      "y": 28,
      "z": 6,
      "name": "Rock_Magma_Cooled",
      "rotation": 1
    },
    {
      "x": -5,
      "y": 23,
      "z": 7,
      "name": "Rock_Magma_Cooled",
      "rotation": 1
    },
    {
      "x": -5,
      "y": 24,
      "z": 7,
      "name": "Rock_Magma_Cooled",
      "rotation": 1
    },
    {
      "x": -5,
      "y": 25,
      "z": 7,
      "name": "Rock_Magma_Cooled",
      "rotation": 1
    },
    {
      "x": -5,
      "y": 26,
      "z": 7,
      "name": "Ore_Adamantite_Magma_Cracked",
      "rotation": 1
    },
    {
      "x": -5,
      "y": 27,
      "z": 7,
      "name": "Rock_Magma_Cooled",
      "rotation": 1
    },
    {
      "x": -5,
      "y": 28,
      "z": 7,
      "name": "Rock_Magma_Cooled",
      "rotation": 1
    },
    {
      "x": -5,
      "y": 29,
      "z": 7,
      "name": "Ore_Adamantite_Magma_Cracked",
      "rotation": 1
    },
    {
      "x": -5,
      "y": 26,
      "z": 8,
      "name": "Rock_Magma_Cooled",
      "rotation": 1
    },
    {
      "x": -5,
      "y": 27,
      "z": 8,
      "name": "Rock_Magma_Cooled",
      "rotation": 1
    },
    {
      "x": -5,
      "y": 28,
      "z": 8,
      "name": "Rock_Magma_Cooled",
      "rotation": 1
    },
    {
      "x": -5,
      "y": 29,
      "z": 8,
      "name": "Rock_Magma_Cooled",
      "rotation": 1
    },
    {
      "x": -5,
      "y": 28,
      "z": 9,
      "name": "Ore_Adamantite_Magma_Cracked",
      "rotation": 1
    },
    {
      "x": -5,
      "y": 29,
      "z": 9,
      "name": "Rock_Magma_Cooled",
      "rotation": 1
    },
    {
      "x": -5,
      "y": 30,
      "z": 9,
      "name": "Rock_Magma_Cooled",
      "rotation": 1
    },
    {
      "x": -5,
      "y": 31,
      "z": 9,
      "name": "Rock_Magma_Cooled",
      "rotation": 1
    },
    {
      "x": -5,
      "y": 30,
      "z": 10,
      "name": "Rock_Magma_Cooled",
      "rotation": 1
    },
    {
      "x": -5,
      "y": 31,
      "z": 10,
      "name": "Rock_Magma_Cooled",
      "rotation": 1
    },
    {
      "x": -5,
      "y": 32,
      "z": 10,
      "name": "Rock_Magma_Cooled",
      "rotation": 1
    },
    {
      "x": -5,
      "y": 33,
      "z": 10,
      "name": "Rock_Magma_Cooled",
      "rotation": 1
    },
    {
      "x": -5,
      "y": 34,
      "z": 10,
      "name": "Rock_Magma_Cooled",
      "rotation": 1
    },
    {
      "x": -5,
      "y": 31,
      "z": 11,
      "name": "Ore_Adamantite_Magma_Cracked",
      "rotation": 1
    },
    {
      "x": -5,
      "y": 32,
      "z": 11,
      "name": "Rock_Magma_Cooled",
      "rotation": 1
    },
    {
      "x": -5,
      "y": 33,
      "z": 11,
      "name": "Rock_Magma_Cooled",
      "rotation": 1
    },
    {
      "x": -5,
      "y": 34,
      "z": 11,
      "name": "Ore_Adamantite_Magma_Cracked",
      "rotation": 1
    },
    {
      "x": -5,
      "y": 35,
      "z": 11,
      "name": "Rock_Magma_Cooled",
      "rotation": 1
    },
    {
      "x": -5,
      "y": 36,
      "z": 11,
      "name": "Rock_Magma_Cooled",
      "rotation": 1
    },
    {
      "x": -5,
      "y": 37,
      "z": 11,
      "name": "Plant_Moss_Rug_Pink",
      "support": 15
    },
    {
      "x": -4,
      "y": 0,
      "z": -13,
      "name": "Soil_Ash"
    },
    {
      "x": -4,
      "y": 0,
      "z": -12,
      "name": "Soil_Ash"
    },
    {
      "x": -4,
      "y": 1,
      "z": -12,
      "name": "Soil_Ash"
    },
    {
      "x": -4,
      "y": 0,
      "z": -11,
      "name": "Soil_Ash"
    },
    {
      "x": -4,
      "y": 1,
      "z": -11,
      "name": "Soil_Ash"
    },
    {
      "x": -4,
      "y": 2,
      "z": -11,
      "name": "Soil_Ash"
    },
    {
      "x": -4,
      "y": 0,
      "z": -10,
      "name": "Soil_Ash"
    },
    {
      "x": -4,
      "y": 1,
      "z": -10,
      "name": "Soil_Ash"
    },
    {
      "x": -4,
      "y": 2,
      "z": -10,
      "name": "Soil_Ash"
    },
    {
      "x": -4,
      "y": 3,
      "z": -10,
      "name": "Soil_Ash"
    },
    {
      "x": -4,
      "y": 0,
      "z": -9,
      "name": "Soil_Ash"
    },
    {
      "x": -4,
      "y": 1,
      "z": -9,
      "name": "Soil_Ash"
    },
    {
      "x": -4,
      "y": 2,
      "z": -9,
      "name": "Soil_Ash"
    },
    {
      "x": -4,
      "y": 3,
      "z": -9,
      "name": "Soil_Ash"
    },
    {
      "x": -4,
      "y": 0,
      "z": -8,
      "name": "Soil_Ash"
    },
    {
      "x": -4,
      "y": 1,
      "z": -8,
      "name": "Soil_Ash"
    },
    {
      "x": -4,
      "y": 2,
      "z": -8,
      "name": "Soil_Ash"
    },
    {
      "x": -4,
      "y": 3,
      "z": -8,
      "name": "Soil_Ash"
    },
    {
      "x": -4,
      "y": 4,
      "z": -8,
      "name": "Soil_Ash"
    },
    {
      "x": -4,
      "y": 0,
      "z": -7,
      "name": "Soil_Ash"
    },
    {
      "x": -4,
      "y": 1,
      "z": -7,
      "name": "Soil_Ash"
    },
    {
      "x": -4,
      "y": 2,
      "z": -7,
      "name": "Soil_Ash"
    },
    {
      "x": -4,
      "y": 3,
      "z": -7,
      "name": "Soil_Ash"
    },
    {
      "x": -4,
      "y": 0,
      "z": -6,
      "name": "Soil_Ash"
    },
    {
      "x": -4,
      "y": 1,
      "z": -6,
      "name": "Soil_Ash"
    },
    {
      "x": -4,
      "y": 2,
      "z": -6,
      "name": "Soil_Ash"
    },
    {
      "x": -4,
      "y": 3,
      "z": -6,
      "name": "Soil_Ash"
    },
    {
      "x": -4,
      "y": 0,
      "z": -5,
      "name": "Soil_Ash"
    },
    {
      "x": -4,
      "y": 1,
      "z": -5,
      "name": "Soil_Ash"
    },
    {
      "x": -4,
      "y": 2,
      "z": -5,
      "name": "Soil_Ash"
    },
    {
      "x": -4,
      "y": 0,
      "z": -4,
      "name": "Soil_Ash"
    },
    {
      "x": -4,
      "y": 1,
      "z": -4,
      "name": "Soil_Ash"
    },
    {
      "x": -4,
      "y": 0,
      "z": -3,
      "name": "Soil_Sand_Ashen"
    },
    {
      "x": -4,
      "y": 1,
      "z": -3,
      "name": "Soil_Ash"
    },
    {
      "x": -4,
      "y": 0,
      "z": 1,
      "name": "Soil_Ash"
    },
    {
      "x": -4,
      "y": 0,
      "z": 2,
      "name": "Soil_Sand_Ashen"
    },
    {
      "x": -4,
      "y": 1,
      "z": 2,
      "name": "Soil_Ash"
    },
    {
      "x": -4,
      "y": 13,
      "z": 2,
      "name": "Plant_Vine_Wall_Poisoned",
      "support": 15,
      "rotation": 2
    },
    {
      "x": -4,
      "y": 0,
      "z": 3,
      "name": "Soil_Ash"
    },
    {
      "x": -4,
      "y": 1,
      "z": 3,
      "name": "Soil_Ash"
    },
    {
      "x": -4,
      "y": 10,
      "z": 3,
      "name": "Rock_Magma_Cooled"
    },
    {
      "x": -4,
      "y": 11,
      "z": 3,
      "name": "Rock_Magma_Cooled"
    },
    {
      "x": -4,
      "y": 12,
      "z": 3,
      "name": "Rock_Magma_Cooled"
    },
    {
      "x": -4,
      "y": 13,
      "z": 3,
      "name": "Rock_Magma_Cooled"
    },
    {
      "x": -4,
      "y": 14,
      "z": 3,
      "name": "Rock_Magma_Cooled"
    },
    {
      "x": -4,
      "y": 0,
      "z": 4,
      "name": "Soil_Ash"
    },
    {
      "x": -4,
      "y": 1,
      "z": 4,
      "name": "Soil_Ash"
    },
    {
      "x": -4,
      "y": 9,
      "z": 4,
      "name": "Plant_Vine_Wall_Poisoned",
      "support": 15,
      "rotation": 3
    },
    {
      "x": -4,
      "y": 11,
      "z": 4,
      "name": "Rock_Magma_Cooled"
    },
    {
      "x": -4,
      "y": 12,
      "z": 4,
      "name": "Rock_Magma_Cooled"
    },
    {
      "x": -4,
      "y": 13,
      "z": 4,
      "name": "Ore_Adamantite_Magma_Cracked"
    },
    {
      "x": -4,
      "y": 14,
      "z": 4,
      "name": "Rock_Magma_Cooled"
    },
    {
      "x": -4,
      "y": 15,
      "z": 4,
      "name": "Rock_Magma_Cooled"
    },
    {
      "x": -4,
      "y": 16,
      "z": 4,
      "name": "Rock_Magma_Cooled"
    },
    {
      "x": -4,
      "y": 0,
      "z": 5,
      "name": "Soil_Ash"
    },
    {
      "x": -4,
      "y": 1,
      "z": 5,
      "name": "Soil_Ash"
    },
    {
      "x": -4,
      "y": 12,
      "z": 5,
      "name": "Rock_Magma_Cooled"
    },
    {
      "x": -4,
      "y": 13,
      "z": 5,
      "name": "Rock_Magma_Cooled"
    },
    {
      "x": -4,
      "y": 14,
      "z": 5,
      "name": "Rock_Magma_Cooled"
    },
    {
      "x": -4,
      "y": 15,
      "z": 5,
      "name": "Ore_Adamantite_Magma_Cracked"
    },
    {
      "x": -4,
      "y": 16,
      "z": 5,
      "name": "Rock_Magma_Cooled"
    },
    {
      "x": -4,
      "y": 17,
      "z": 5,
      "name": "Rock_Magma_Cooled"
    },
    {
      "x": -4,
      "y": 27,
      "z": 5,
      "name": "Rock_Magma_Cooled",
      "rotation": 1
    },
    {
      "x": -4,
      "y": 28,
      "z": 5,
      "name": "Rock_Magma_Cooled",
      "rotation": 1
    },
    {
      "x": -4,
      "y": 0,
      "z": 6,
      "name": "Soil_Ash"
    },
    {
      "x": -4,
      "y": 1,
      "z": 6,
      "name": "Soil_Sand_Ashen"
    },
    {
      "x": -4,
      "y": 14,
      "z": 6,
      "name": "Plant_Vine_Wall_Poisoned",
      "support": 15
    },
    {
      "x": -4,
      "y": 24,
      "z": 6,
      "name": "Rock_Magma_Cooled",
      "rotation": 1
    },
    {
      "x": -4,
      "y": 25,
      "z": 6,
      "name": "Rock_Magma_Cooled",
      "rotation": 1
    },
    {
      "x": -4,
      "y": 26,
      "z": 6,
      "name": "Ore_Adamantite_Magma_Cracked",
      "rotation": 1
    },
    {
      "x": -4,
      "y": 27,
      "z": 6,
      "name": "Rock_Magma_Cooled",
      "rotation": 1
    },
    {
      "x": -4,
      "y": 0,
      "z": 7,
      "name": "Soil_Sand_Ashen"
    },
    {
      "x": -4,
      "y": 25,
      "z": 7,
      "name": "Rock_Magma_Cooled",
      "rotation": 1
    },
    {
      "x": -4,
      "y": 26,
      "z": 7,
      "name": "Rock_Magma_Cooled",
      "rotation": 1
    },
    {
      "x": -4,
      "y": 27,
      "z": 7,
      "name": "Rock_Magma_Cooled",
      "rotation": 1
    },
    {
      "x": -4,
      "y": 29,
      "z": 8,
      "name": "Rock_Magma_Cooled",
      "rotation": 1
    },
    {
      "x": -4,
      "y": 30,
      "z": 8,
      "name": "Ore_Adamantite_Magma_Cracked",
      "rotation": 1
    },
    {
      "x": -4,
      "y": 30,
      "z": 9,
      "name": "Ore_Adamantite_Magma_Cracked",
      "rotation": 1
    },
    {
      "x": -4,
      "y": 31,
      "z": 9,
      "name": "Rock_Magma_Cooled",
      "rotation": 1
    },
    {
      "x": -4,
      "y": 31,
      "z": 10,
      "name": "Rock_Magma_Cooled",
      "rotation": 1
    },
    {
      "x": -4,
      "y": 32,
      "z": 10,
      "name": "Rock_Magma_Cooled",
      "rotation": 1
    },
    {
      "x": -4,
      "y": 33,
      "z": 10,
      "name": "Rock_Magma_Cooled",
      "rotation": 1
    },
    {
      "x": -4,
      "y": 34,
      "z": 10,
      "name": "Rock_Magma_Cooled",
      "rotation": 1
    },
    {
      "x": -4,
      "y": 35,
      "z": 10,
      "name": "Rock_Magma_Cooled",
      "rotation": 1
    },
    {
      "x": -4,
      "y": 36,
      "z": 10,
      "name": "Plant_Moss_Rug_Pink",
      "support": 15
    },
    {
      "x": -4,
      "y": 33,
      "z": 11,
      "name": "Rock_Magma_Cooled",
      "rotation": 1
    },
    {
      "x": -4,
      "y": 34,
      "z": 11,
      "name": "Rock_Magma_Cooled",
      "rotation": 1
    },
    {
      "x": -4,
      "y": 35,
      "z": 11,
      "name": "Rock_Magma_Cooled",
      "rotation": 1
    },
    {
      "x": -4,
      "y": 36,
      "z": 11,
      "name": "Rock_Magma_Cooled",
      "rotation": 1
    },
    {
      "x": -4,
      "y": 37,
      "z": 11,
      "name": "Rock_Magma_Cooled",
      "rotation": 1
    },
    {
      "x": -4,
      "y": 38,
      "z": 11,
      "name": "Plant_Moss_Rug_Pink",
      "support": 15
    },
    {
      "x": -4,
      "y": 34,
      "z": 12,
      "name": "Rock_Magma_Cooled",
      "rotation": 1
    },
    {
      "x": -4,
      "y": 35,
      "z": 12,
      "name": "Rock_Magma_Cooled",
      "rotation": 1
    },
    {
      "x": -4,
      "y": 36,
      "z": 12,
      "name": "Rock_Magma_Cooled",
      "rotation": 1
    },
    {
      "x": -4,
      "y": 37,
      "z": 12,
      "name": "Ore_Adamantite_Magma_Cracked",
      "rotation": 1
    },
    {
      "x": -4,
      "y": 38,
      "z": 12,
      "name": "Rock_Magma_Cooled",
      "rotation": 1
    },
    {
      "x": -4,
      "y": 39,
      "z": 12,
      "name": "Plant_Moss_Rug_Pink",
      "support": 15
    },
    {
      "x": -4,
      "y": 36,
      "z": 13,
      "name": "Plant_Vine_Wall_Poisoned",
      "support": 15
    },
    {
      "x": -3,
      "y": 0,
      "z": -14,
      "name": "Soil_Sand_Ashen"
    },
    {
      "x": -3,
      "y": 0,
      "z": -13,
      "name": "Soil_Ash"
    },
    {
      "x": -3,
      "y": 1,
      "z": -13,
      "name": "Soil_Ash"
    },
    {
      "x": -3,
      "y": 0,
      "z": -12,
      "name": "Soil_Ash"
    },
    {
      "x": -3,
      "y": 1,
      "z": -12,
      "name": "Soil_Ash"
    },
    {
      "x": -3,
      "y": 2,
      "z": -12,
      "name": "Soil_Ash"
    },
    {
      "x": -3,
      "y": 0,
      "z": -11,
      "name": "Soil_Ash"
    },
    {
      "x": -3,
      "y": 1,
      "z": -11,
      "name": "Soil_Ash"
    },
    {
      "x": -3,
      "y": 2,
      "z": -11,
      "name": "Soil_Ash"
    },
    {
      "x": -3,
      "y": 3,
      "z": -11,
      "name": "Soil_Ash"
    },
    {
      "x": -3,
      "y": 0,
      "z": -10,
      "name": "Soil_Ash"
    },
    {
      "x": -3,
      "y": 1,
      "z": -10,
      "name": "Soil_Ash"
    },
    {
      "x": -3,
      "y": 2,
      "z": -10,
      "name": "Soil_Ash"
    },
    {
      "x": -3,
      "y": 3,
      "z": -10,
      "name": "Soil_Ash"
    },
    {
      "x": -3,
      "y": 4,
      "z": -10,
      "name": "Soil_Ash"
    },
    {
      "x": -3,
      "y": 5,
      "z": -10,
      "name": "Plant_Bramble_Dead_Twisted"
    },
    {
      "x": -3,
      "y": 0,
      "z": -9,
      "name": "Soil_Ash"
    },
    {
      "x": -3,
      "y": 1,
      "z": -9,
      "name": "Soil_Ash"
    },
    {
      "x": -3,
      "y": 2,
      "z": -9,
      "name": "Soil_Ash"
    },
    {
      "x": -3,
      "y": 3,
      "z": -9,
      "name": "Soil_Ash"
    },
    {
      "x": -3,
      "y": 4,
      "z": -9,
      "name": "Soil_Ash"
    },
    {
      "x": -3,
      "y": 5,
      "z": -9,
      "name": "Plant_Bramble_Dead_Twisted"
    },
    {
      "x": -3,
      "y": 0,
      "z": -8,
      "name": "Soil_Ash"
    },
    {
      "x": -3,
      "y": 1,
      "z": -8,
      "name": "Soil_Ash"
    },
    {
      "x": -3,
      "y": 2,
      "z": -8,
      "name": "Soil_Ash"
    },
    {
      "x": -3,
      "y": 3,
      "z": -8,
      "name": "Soil_Ash"
    },
    {
      "x": -3,
      "y": 4,
      "z": -8,
      "name": "Soil_Ash"
    },
    {
      "x": -3,
      "y": 5,
      "z": -8,
      "name": "Plant_Bramble_Dead_Twisted"
    },
    {
      "x": -3,
      "y": 0,
      "z": -7,
      "name": "Soil_Ash"
    },
    {
      "x": -3,
      "y": 1,
      "z": -7,
      "name": "Soil_Ash"
    },
    {
      "x": -3,
      "y": 2,
      "z": -7,
      "name": "Soil_Ash"
    },
    {
      "x": -3,
      "y": 3,
      "z": -7,
      "name": "Soil_Ash"
    },
    {
      "x": -3,
      "y": 4,
      "z": -7,
      "name": "Soil_Ash"
    },
    {
      "x": -3,
      "y": 5,
      "z": -7,
      "name": "Plant_Bramble_Dead_Twisted"
    },
    {
      "x": -3,
      "y": 0,
      "z": -6,
      "name": "Soil_Ash"
    },
    {
      "x": -3,
      "y": 1,
      "z": -6,
      "name": "Soil_Ash"
    },
    {
      "x": -3,
      "y": 2,
      "z": -6,
      "name": "Soil_Ash"
    },
    {
      "x": -3,
      "y": 3,
      "z": -6,
      "name": "Soil_Ash"
    },
    {
      "x": -3,
      "y": 4,
      "z": -6,
      "name": "Soil_Ash"
    },
    {
      "x": -3,
      "y": 0,
      "z": -5,
      "name": "Soil_Ash"
    },
    {
      "x": -3,
      "y": 1,
      "z": -5,
      "name": "Soil_Ash"
    },
    {
      "x": -3,
      "y": 2,
      "z": -5,
      "name": "Soil_Ash"
    },
    {
      "x": -3,
      "y": 3,
      "z": -5,
      "name": "Soil_Ash"
    },
    {
      "x": -3,
      "y": 4,
      "z": -5,
      "name": "Plant_Bramble_Dead_Twisted"
    },
    {
      "x": -3,
      "y": 0,
      "z": -4,
      "name": "Soil_Ash"
    },
    {
      "x": -3,
      "y": 1,
      "z": -4,
      "name": "Soil_Ash"
    },
    {
      "x": -3,
      "y": 2,
      "z": -4,
      "name": "Soil_Sand_Ashen"
    },
    {
      "x": -3,
      "y": 0,
      "z": -3,
      "name": "Soil_Sand_Ashen"
    },
    {
      "x": -3,
      "y": 1,
      "z": -3,
      "name": "Soil_Sand_Ashen"
    },
    {
      "x": -3,
      "y": 0,
      "z": -1,
      "name": "Soil_Sand_Ashen"
    },
    {
      "x": -3,
      "y": 1,
      "z": -1,
      "name": "Soil_Sand_Ashen"
    },
    {
      "x": -3,
      "y": 0,
      "z": 0,
      "name": "Soil_Ash"
    },
    {
      "x": -3,
      "y": 1,
      "z": 0,
      "name": "Soil_Ash"
    },
    {
      "x": -3,
      "y": 0,
      "z": 1,
      "name": "Soil_Ash"
    },
    {
      "x": -3,
      "y": 1,
      "z": 1,
      "name": "Soil_Ash"
    },
    {
      "x": -3,
      "y": 2,
      "z": 1,
      "name": "Soil_Ash"
    },
    {
      "x": -3,
      "y": 7,
      "z": 1,
      "name": "Plant_Vine_Wall_Poisoned",
      "support": 15,
      "rotation": 2
    },
    {
      "x": -3,
      "y": 0,
      "z": 2,
      "name": "Soil_Ash"
    },
    {
      "x": -3,
      "y": 1,
      "z": 2,
      "name": "Soil_Ash"
    },
    {
      "x": -3,
      "y": 2,
      "z": 2,
      "name": "Soil_Ash"
    },
    {
      "x": -3,
      "y": 3,
      "z": 2,
      "name": "Rock_Magma_Cooled"
    },
    {
      "x": -3,
      "y": 4,
      "z": 2,
      "name": "Ore_Adamantite_Magma_Cracked"
    },
    {
      "x": -3,
      "y": 5,
      "z": 2,
      "name": "Rock_Magma_Cooled"
    },
    {
      "x": -3,
      "y": 6,
      "z": 2,
      "name": "Rock_Magma_Cooled"
    },
    {
      "x": -3,
      "y": 7,
      "z": 2,
      "name": "Ore_Adamantite_Magma_Cracked"
    },
    {
      "x": -3,
      "y": 8,
      "z": 2,
      "name": "Rock_Magma_Cooled"
    },
    {
      "x": -3,
      "y": 10,
      "z": 2,
      "name": "Rock_Magma_Cooled"
    },
    {
      "x": -3,
      "y": 11,
      "z": 2,
      "name": "Ore_Adamantite_Magma_Cracked"
    },
    {
      "x": -3,
      "y": 0,
      "z": 3,
      "name": "Soil_Ash"
    },
    {
      "x": -3,
      "y": 1,
      "z": 3,
      "name": "Soil_Ash"
    },
    {
      "x": -3,
      "y": 2,
      "z": 3,
      "name": "Soil_Ash"
    },
    {
      "x": -3,
      "y": 3,
      "z": 3,
      "name": "Soil_Ash"
    },
    {
      "x": -3,
      "y": 4,
      "z": 3,
      "name": "Ore_Adamantite_Magma_Cracked"
    },
    {
      "x": -3,
      "y": 5,
      "z": 3,
      "name": "Ore_Adamantite_Magma_Cracked"
    },
    {
      "x": -3,
      "y": 6,
      "z": 3,
      "name": "Rock_Magma_Cooled"
    },
    {
      "x": -3,
      "y": 7,
      "z": 3,
      "name": "Rock_Magma_Cooled"
    },
    {
      "x": -3,
      "y": 8,
      "z": 3,
      "name": "Ore_Adamantite_Magma_Cracked"
    },
    {
      "x": -3,
      "y": 9,
      "z": 3,
      "name": "Rock_Magma_Cooled"
    },
    {
      "x": -3,
      "y": 10,
      "z": 3,
      "name": "Rock_Magma_Cooled"
    },
    {
      "x": -3,
      "y": 11,
      "z": 3,
      "name": "Rock_Magma_Cooled"
    },
    {
      "x": -3,
      "y": 12,
      "z": 3,
      "name": "Rock_Magma_Cooled"
    },
    {
      "x": -3,
      "y": 0,
      "z": 4,
      "name": "Soil_Ash"
    },
    {
      "x": -3,
      "y": 1,
      "z": 4,
      "name": "Soil_Ash"
    },
    {
      "x": -3,
      "y": 2,
      "z": 4,
      "name": "Soil_Ash"
    },
    {
      "x": -3,
      "y": 3,
      "z": 4,
      "name": "Soil_Ash"
    },
    {
      "x": -3,
      "y": 9,
      "z": 4,
      "name": "Ore_Adamantite_Magma_Cracked"
    },
    {
      "x": -3,
      "y": 10,
      "z": 4,
      "name": "Ore_Adamantite_Magma_Cracked"
    },
    {
      "x": -3,
      "y": 11,
      "z": 4,
      "name": "Rock_Magma_Cooled"
    },
    {
      "x": -3,
      "y": 12,
      "z": 4,
      "name": "Rock_Magma_Cooled"
    },
    {
      "x": -3,
      "y": 13,
      "z": 4,
      "name": "Rock_Magma_Cooled"
    },
    {
      "x": -3,
      "y": 29,
      "z": 4,
      "name": "Rock_Magma_Cooled",
      "rotation": 1
    },
    {
      "x": -3,
      "y": 30,
      "z": 4,
      "name": "Rock_Magma_Cooled",
      "rotation": 1
    },
    {
      "x": -3,
      "y": 31,
      "z": 4,
      "name": "Ore_Adamantite_Magma_Cracked",
      "rotation": 1
    },
    {
      "x": -3,
      "y": 0,
      "z": 5,
      "name": "Soil_Ash"
    },
    {
      "x": -3,
      "y": 1,
      "z": 5,
      "name": "Soil_Ash"
    },
    {
      "x": -3,
      "y": 2,
      "z": 5,
      "name": "Soil_Ash"
    },
    {
      "x": -3,
      "y": 3,
      "z": 5,
      "name": "Plant_Bramble_Dead_Twisted"
    },
    {
      "x": -3,
      "y": 4,
      "z": 5,
      "name": "Plant_Bramble_Dead_Twisted"
    },
    {
      "x": -3,
      "y": 5,
      "z": 5,
      "name": "Plant_Bramble_Dead_Twisted"
    },
    {
      "x": -3,
      "y": 12,
      "z": 5,
      "name": "Rock_Magma_Cooled"
    },
    {
      "x": -3,
      "y": 13,
      "z": 5,
      "name": "Rock_Magma_Cooled"
    },
    {
      "x": -3,
      "y": 28,
      "z": 5,
      "name": "Rock_Magma_Cooled",
      "rotation": 1
    },
    {
      "x": -3,
      "y": 29,
      "z": 5,
      "name": "Rock_Magma_Cooled",
      "rotation": 1
    },
    {
      "x": -3,
      "y": 0,
      "z": 6,
      "name": "Soil_Ash"
    },
    {
      "x": -3,
      "y": 1,
      "z": 6,
      "name": "Soil_Ash"
    },
    {
      "x": -3,
      "y": 2,
      "z": 6,
      "name": "Soil_Ash"
    },
    {
      "x": -3,
      "y": 26,
      "z": 6,
      "name": "Ore_Adamantite_Magma_Cracked",
      "rotation": 1
    },
    {
      "x": -3,
      "y": 27,
      "z": 6,
      "name": "Ore_Adamantite_Magma_Cracked",
      "rotation": 1
    },
    {
      "x": -3,
      "y": 0,
      "z": 7,
      "name": "Soil_Ash"
    },
    {
      "x": -3,
      "y": 1,
      "z": 7,
      "name": "Soil_Ash"
    },
    {
      "x": -3,
      "y": 0,
      "z": 8,
      "name": "Soil_Sand_Ashen"
    },
    {
      "x": -3,
      "y": 1,
      "z": 8,
      "name": "Soil_Sand_Ashen"
    },
    {
      "x": -3,
      "y": 35,
      "z": 11,
      "name": "Ore_Adamantite_Magma_Cracked",
      "rotation": 1
    },
    {
      "x": -3,
      "y": 36,
      "z": 11,
      "name": "Plant_Moss_Rug_Pink",
      "support": 15
    },
    {
      "x": -3,
      "y": 36,
      "z": 12,
      "name": "Rock_Magma_Cooled",
      "rotation": 1
    },
    {
      "x": -3,
      "y": 37,
      "z": 12,
      "name": "Rock_Magma_Cooled",
      "rotation": 1
    },
    {
      "x": -3,
      "y": 38,
      "z": 12,
      "name": "Rock_Magma_Cooled",
      "rotation": 1
    },
    {
      "x": -3,
      "y": 39,
      "z": 12,
      "name": "Rock_Magma_Cooled",
      "rotation": 1
    },
    {
      "x": -3,
      "y": 40,
      "z": 12,
      "name": "Plant_Moss_Rug_Pink",
      "support": 15
    },
    {
      "x": -3,
      "y": 38,
      "z": 13,
      "name": "Rock_Magma_Cooled",
      "rotation": 1
    },
    {
      "x": -3,
      "y": 39,
      "z": 13,
      "name": "Rock_Magma_Cooled",
      "rotation": 1
    },
    {
      "x": -3,
      "y": 40,
      "z": 13,
      "name": "Plant_Moss_Rug_Pink",
      "support": 15
    },
    {
      "x": -2,
      "y": 0,
      "z": -14,
      "name": "Soil_Ash"
    },
    {
      "x": -2,
      "y": 0,
      "z": -13,
      "name": "Soil_Sand_Ashen"
    },
    {
      "x": -2,
      "y": 1,
      "z": -13,
      "name": "Soil_Ash"
    },
    {
      "x": -2,
      "y": 0,
      "z": -12,
      "name": "Soil_Ash"
    },
    {
      "x": -2,
      "y": 1,
      "z": -12,
      "name": "Soil_Ash"
    },
    {
      "x": -2,
      "y": 2,
      "z": -12,
      "name": "Soil_Ash"
    },
    {
      "x": -2,
      "y": 0,
      "z": -11,
      "name": "Soil_Ash"
    },
    {
      "x": -2,
      "y": 1,
      "z": -11,
      "name": "Soil_Ash"
    },
    {
      "x": -2,
      "y": 2,
      "z": -11,
      "name": "Soil_Ash"
    },
    {
      "x": -2,
      "y": 3,
      "z": -11,
      "name": "Soil_Ash"
    },
    {
      "x": -2,
      "y": 0,
      "z": -10,
      "name": "Soil_Ash"
    },
    {
      "x": -2,
      "y": 1,
      "z": -10,
      "name": "Soil_Ash"
    },
    {
      "x": -2,
      "y": 2,
      "z": -10,
      "name": "Soil_Ash"
    },
    {
      "x": -2,
      "y": 3,
      "z": -10,
      "name": "Soil_Ash"
    },
    {
      "x": -2,
      "y": 4,
      "z": -10,
      "name": "Soil_Ash"
    },
    {
      "x": -2,
      "y": 5,
      "z": -10,
      "name": "Plant_Flower_Poisoned_Orange"
    },
    {
      "x": -2,
      "y": 0,
      "z": -9,
      "name": "Soil_Ash"
    },
    {
      "x": -2,
      "y": 1,
      "z": -9,
      "name": "Soil_Ash"
    },
    {
      "x": -2,
      "y": 2,
      "z": -9,
      "name": "Soil_Ash"
    },
    {
      "x": -2,
      "y": 3,
      "z": -9,
      "name": "Soil_Ash"
    },
    {
      "x": -2,
      "y": 4,
      "z": -9,
      "name": "Soil_Ash"
    },
    {
      "x": -2,
      "y": 5,
      "z": -9,
      "name": "Soil_Ash"
    },
    {
      "x": -2,
      "y": 0,
      "z": -8,
      "name": "Soil_Ash"
    },
    {
      "x": -2,
      "y": 1,
      "z": -8,
      "name": "Soil_Ash"
    },
    {
      "x": -2,
      "y": 2,
      "z": -8,
      "name": "Soil_Ash"
    },
    {
      "x": -2,
      "y": 3,
      "z": -8,
      "name": "Soil_Ash"
    },
    {
      "x": -2,
      "y": 4,
      "z": -8,
      "name": "Soil_Ash"
    },
    {
      "x": -2,
      "y": 5,
      "z": -8,
      "name": "Soil_Ash"
    },
    {
      "x": -2,
      "y": 6,
      "z": -8,
      "name": "Plant_Bramble_Dead_Twisted"
    },
    {
      "x": -2,
      "y": 0,
      "z": -7,
      "name": "Soil_Ash"
    },
    {
      "x": -2,
      "y": 1,
      "z": -7,
      "name": "Soil_Ash"
    },
    {
      "x": -2,
      "y": 2,
      "z": -7,
      "name": "Soil_Ash"
    },
    {
      "x": -2,
      "y": 3,
      "z": -7,
      "name": "Soil_Ash"
    },
    {
      "x": -2,
      "y": 4,
      "z": -7,
      "name": "Soil_Ash"
    },
    {
      "x": -2,
      "y": 5,
      "z": -7,
      "name": "Soil_Ash"
    },
    {
      "x": -2,
      "y": 0,
      "z": -6,
      "name": "Soil_Ash"
    },
    {
      "x": -2,
      "y": 1,
      "z": -6,
      "name": "Soil_Ash"
    },
    {
      "x": -2,
      "y": 2,
      "z": -6,
      "name": "Soil_Ash"
    },
    {
      "x": -2,
      "y": 3,
      "z": -6,
      "name": "Soil_Ash"
    },
    {
      "x": -2,
      "y": 4,
      "z": -6,
      "name": "Soil_Ash"
    },
    {
      "x": -2,
      "y": 5,
      "z": -6,
      "name": "Soil_Ash"
    },
    {
      "x": -2,
      "y": 6,
      "z": -6,
      "name": "Plant_Bramble_Dead_Twisted"
    },
    {
      "x": -2,
      "y": 7,
      "z": -6,
      "name": "Plant_Bramble_Dead_Twisted"
    },
    {
      "x": -2,
      "y": 8,
      "z": -6,
      "name": "Plant_Bramble_Dead_Twisted"
    },
    {
      "x": -2,
      "y": 0,
      "z": -5,
      "name": "Soil_Ash"
    },
    {
      "x": -2,
      "y": 1,
      "z": -5,
      "name": "Soil_Ash"
    },
    {
      "x": -2,
      "y": 2,
      "z": -5,
      "name": "Soil_Ash"
    },
    {
      "x": -2,
      "y": 3,
      "z": -5,
      "name": "Soil_Ash"
    },
    {
      "x": -2,
      "y": 4,
      "z": -5,
      "name": "Soil_Sand_Ashen"
    },
    {
      "x": -2,
      "y": 0,
      "z": -4,
      "name": "Soil_Ash"
    },
    {
      "x": -2,
      "y": 1,
      "z": -4,
      "name": "Soil_Ash"
    },
    {
      "x": -2,
      "y": 2,
      "z": -4,
      "name": "Soil_Ash"
    },
    {
      "x": -2,
      "y": 0,
      "z": -3,
      "name": "Soil_Ash"
    },
    {
      "x": -2,
      "y": 0,
      "z": -2,
      "name": "Soil_Ash"
    },
    {
      "x": -2,
      "y": 1,
      "z": -2,
      "name": "Soil_Ash"
    },
    {
      "x": -2,
      "y": 0,
      "z": -1,
      "name": "Soil_Sand_Ashen"
    },
    {
      "x": -2,
      "y": 1,
      "z": -1,
      "name": "Soil_Sand_Ashen"
    },
    {
      "x": -2,
      "y": 2,
      "z": -1,
      "name": "Soil_Sand_Ashen"
    },
    {
      "x": -2,
      "y": 3,
      "z": -1,
      "name": "Soil_Ash"
    },
    {
      "x": -2,
      "y": 4,
      "z": -1,
      "name": "Plant_Flower_Poisoned_Orange"
    },
    {
      "x": -2,
      "y": 0,
      "z": 0,
      "name": "Soil_Ash"
    },
    {
      "x": -2,
      "y": 1,
      "z": 0,
      "name": "Soil_Ash"
    },
    {
      "x": -2,
      "y": 2,
      "z": 0,
      "name": "Soil_Ash"
    },
    {
      "x": -2,
      "y": 3,
      "z": 0,
      "name": "Soil_Sand_Ashen"
    },
    {
      "x": -2,
      "y": 4,
      "z": 0,
      "name": "Soil_Sand_Ashen"
    },
    {
      "x": -2,
      "y": 5,
      "z": 0,
      "name": "Rock_Magma_Cooled"
    },
    {
      "x": -2,
      "y": 6,
      "z": 0,
      "name": "Ore_Adamantite_Magma_Cracked"
    },
    {
      "x": -2,
      "y": 8,
      "z": 0,
      "name": "Plant_Vine_Wall_Poisoned",
      "support": 15,
      "rotation": 3
    },
    {
      "x": -2,
      "y": 0,
      "z": 1,
      "name": "Soil_Ash"
    },
    {
      "x": -2,
      "y": 1,
      "z": 1,
      "name": "Soil_Ash"
    },
    {
      "x": -2,
      "y": 2,
      "z": 1,
      "name": "Rock_Magma_Cooled"
    },
    {
      "x": -2,
      "y": 3,
      "z": 1,
      "name": "Rock_Magma_Cooled"
    },
    {
      "x": -2,
      "y": 4,
      "z": 1,
      "name": "Rock_Magma_Cooled"
    },
    {
      "x": -2,
      "y": 5,
      "z": 1,
      "name": "Rock_Magma_Cooled"
    },
    {
      "x": -2,
      "y": 6,
      "z": 1,
      "name": "Rock_Magma_Cooled"
    },
    {
      "x": -2,
      "y": 7,
      "z": 1,
      "name": "Ore_Adamantite_Magma_Cracked"
    },
    {
      "x": -2,
      "y": 8,
      "z": 1,
      "name": "Ore_Adamantite_Magma_Cracked"
    },
    {
      "x": -2,
      "y": 9,
      "z": 1,
      "name": "Rock_Magma_Cooled"
    },
    {
      "x": -2,
      "y": 0,
      "z": 2,
      "name": "Soil_Ash"
    },
    {
      "x": -2,
      "y": 1,
      "z": 2,
      "name": "Soil_Ash"
    },
    {
      "x": -2,
      "y": 2,
      "z": 2,
      "name": "Rock_Magma_Cooled"
    },
    {
      "x": -2,
      "y": 3,
      "z": 2,
      "name": "Rock_Magma_Cooled"
    },
    {
      "x": -2,
      "y": 4,
      "z": 2,
      "name": "Ore_Adamantite_Magma_Cracked"
    },
    {
      "x": -2,
      "y": 5,
      "z": 2,
      "name": "Ore_Adamantite_Magma_Cracked"
    },
    {
      "x": -2,
      "y": 6,
      "z": 2,
      "name": "Rock_Magma_Cooled"
    },
    {
      "x": -2,
      "y": 7,
      "z": 2,
      "name": "Rock_Magma_Cooled"
    },
    {
      "x": -2,
      "y": 8,
      "z": 2,
      "name": "Rock_Magma_Cooled"
    },
    {
      "x": -2,
      "y": 9,
      "z": 2,
      "name": "Rock_Magma_Cooled"
    },
    {
      "x": -2,
      "y": 10,
      "z": 2,
      "name": "Rock_Magma_Cooled"
    },
    {
      "x": -2,
      "y": 11,
      "z": 2,
      "name": "Rock_Magma_Cooled"
    },
    {
      "x": -2,
      "y": 12,
      "z": 2,
      "name": "Rock_Magma_Cooled"
    },
    {
      "x": -2,
      "y": 32,
      "z": 2,
      "name": "Plant_Vine_Wall_Poisoned",
      "support": 15,
      "rotation": 2
    },
    {
      "x": -2,
      "y": 0,
      "z": 3,
      "name": "Soil_Ash"
    },
    {
      "x": -2,
      "y": 1,
      "z": 3,
      "name": "Soil_Ash"
    },
    {
      "x": -2,
      "y": 2,
      "z": 3,
      "name": "Soil_Ash"
    },
    {
      "x": -2,
      "y": 3,
      "z": 3,
      "name": "Rock_Magma_Cooled"
    },
    {
      "x": -2,
      "y": 4,
      "z": 3,
      "name": "Rock_Magma_Cooled"
    },
    {
      "x": -2,
      "y": 5,
      "z": 3,
      "name": "Rock_Magma_Cooled"
    },
    {
      "x": -2,
      "y": 6,
      "z": 3,
      "name": "Ore_Adamantite_Magma_Cracked"
    },
    {
      "x": -2,
      "y": 7,
      "z": 3,
      "name": "Ore_Adamantite_Magma_Cracked"
    },
    {
      "x": -2,
      "y": 8,
      "z": 3,
      "name": "Rock_Magma_Cooled"
    },
    {
      "x": -2,
      "y": 9,
      "z": 3,
      "name": "Ore_Adamantite_Magma_Cracked"
    },
    {
      "x": -2,
      "y": 10,
      "z": 3,
      "name": "Ore_Adamantite_Magma_Cracked"
    },
    {
      "x": -2,
      "y": 11,
      "z": 3,
      "name": "Rock_Magma_Cooled"
    },
    {
      "x": -2,
      "y": 32,
      "z": 3,
      "name": "Rock_Magma_Cooled",
      "rotation": 1
    },
    {
      "x": -2,
      "y": 33,
      "z": 3,
      "name": "Rock_Magma_Cooled",
      "rotation": 1
    },
    {
      "x": -2,
      "y": 0,
      "z": 4,
      "name": "Soil_Ash"
    },
    {
      "x": -2,
      "y": 1,
      "z": 4,
      "name": "Soil_Ash"
    },
    {
      "x": -2,
      "y": 2,
      "z": 4,
      "name": "Soil_Ash"
    },
    {
      "x": -2,
      "y": 3,
      "z": 4,
      "name": "Soil_Ash"
    },
    {
      "x": -2,
      "y": 4,
      "z": 4,
      "name": "Soil_Ash"
    },
    {
      "x": -2,
      "y": 6,
      "z": 4,
      "name": "Rock_Magma_Cooled"
    },
    {
      "x": -2,
      "y": 7,
      "z": 4,
      "name": "Ore_Adamantite_Magma"
    },
    {
      "x": -2,
      "y": 8,
      "z": 4,
      "name": "Rock_Magma_Cooled"
    },
    {
      "x": -2,
      "y": 9,
      "z": 4,
      "name": "Rock_Magma_Cooled"
    },
    {
      "x": -2,
      "y": 10,
      "z": 4,
      "name": "Rock_Magma_Cooled"
    },
    {
      "x": -2,
      "y": 11,
      "z": 4,
      "name": "Rock_Magma_Cooled"
    },
    {
      "x": -2,
      "y": 12,
      "z": 4,
      "name": "Rock_Magma_Cooled"
    },
    {
      "x": -2,
      "y": 29,
      "z": 4,
      "name": "Rock_Magma_Cooled",
      "rotation": 1
    },
    {
      "x": -2,
      "y": 30,
      "z": 4,
      "name": "Rock_Magma_Cooled",
      "rotation": 1
    },
    {
      "x": -2,
      "y": 31,
      "z": 4,
      "name": "Rock_Magma_Cooled",
      "rotation": 1
    },
    {
      "x": -2,
      "y": 32,
      "z": 4,
      "name": "Rock_Magma_Cooled",
      "rotation": 1
    },
    {
      "x": -2,
      "y": 0,
      "z": 5,
      "name": "Soil_Ash"
    },
    {
      "x": -2,
      "y": 1,
      "z": 5,
      "name": "Soil_Ash"
    },
    {
      "x": -2,
      "y": 2,
      "z": 5,
      "name": "Soil_Ash"
    },
    {
      "x": -2,
      "y": 3,
      "z": 5,
      "name": "Soil_Ash"
    },
    {
      "x": -2,
      "y": 8,
      "z": 5,
      "name": "Rock_Magma_Cooled"
    },
    {
      "x": -2,
      "y": 9,
      "z": 5,
      "name": "Ore_Adamantite_Magma_Cracked"
    },
    {
      "x": -2,
      "y": 10,
      "z": 5,
      "name": "Ore_Adamantite_Magma_Cracked"
    },
    {
      "x": -2,
      "y": 11,
      "z": 5,
      "name": "Rock_Magma_Cooled"
    },
    {
      "x": -2,
      "y": 12,
      "z": 5,
      "name": "Rock_Magma_Cooled"
    },
    {
      "x": -2,
      "y": 28,
      "z": 5,
      "name": "Rock_Magma_Cooled",
      "rotation": 1
    },
    {
      "x": -2,
      "y": 29,
      "z": 5,
      "name": "Rock_Magma_Cooled",
      "rotation": 1
    },
    {
      "x": -2,
      "y": 30,
      "z": 5,
      "name": "Ore_Adamantite_Magma_Cracked",
      "rotation": 1
    },
    {
      "x": -2,
      "y": 0,
      "z": 6,
      "name": "Soil_Ash"
    },
    {
      "x": -2,
      "y": 1,
      "z": 6,
      "name": "Soil_Ash"
    },
    {
      "x": -2,
      "y": 2,
      "z": 6,
      "name": "Soil_Ash"
    },
    {
      "x": -2,
      "y": 3,
      "z": 6,
      "name": "Soil_Ash"
    },
    {
      "x": -2,
      "y": 29,
      "z": 6,
      "name": "Plant_Vine_Wall_Poisoned",
      "support": 15
    },
    {
      "x": -2,
      "y": 30,
      "z": 6,
      "name": "Plant_Vine_Wall_Poisoned",
      "support": 15
    },
    {
      "x": -2,
      "y": 0,
      "z": 7,
      "name": "Soil_Ash"
    },
    {
      "x": -2,
      "y": 1,
      "z": 7,
      "name": "Soil_Ash"
    },
    {
      "x": -2,
      "y": 2,
      "z": 7,
      "name": "Soil_Ash"
    },
    {
      "x": -2,
      "y": 0,
      "z": 8,
      "name": "Soil_Ash"
    },
    {
      "x": -2,
      "y": 1,
      "z": 8,
      "name": "Soil_Sand_Ashen"
    },
    {
      "x": -2,
      "y": 39,
      "z": 13,
      "name": "Rock_Magma_Cooled",
      "rotation": 1
    },
    {
      "x": -2,
      "y": 40,
      "z": 13,
      "name": "Rock_Magma_Cooled",
      "rotation": 1
    },
    {
      "x": -2,
      "y": 41,
      "z": 13,
      "name": "Ore_Adamantite_Magma_Cracked",
      "rotation": 1
    },
    {
      "x": -2,
      "y": 42,
      "z": 13,
      "name": "Plant_Moss_Rug_Pink",
      "support": 15
    },
    {
      "x": -1,
      "y": 0,
      "z": -14,
      "name": "Soil_Sand_Ashen"
    },
    {
      "x": -1,
      "y": 0,
      "z": -13,
      "name": "Soil_Sand_Ashen"
    },
    {
      "x": -1,
      "y": 1,
      "z": -13,
      "name": "Soil_Ash"
    },
    {
      "x": -1,
      "y": 0,
      "z": -12,
      "name": "Soil_Sand_Ashen"
    },
    {
      "x": -1,
      "y": 1,
      "z": -12,
      "name": "Soil_Ash"
    },
    {
      "x": -1,
      "y": 2,
      "z": -12,
      "name": "Soil_Ash"
    },
    {
      "x": -1,
      "y": 0,
      "z": -11,
      "name": "Soil_Ash"
    },
    {
      "x": -1,
      "y": 1,
      "z": -11,
      "name": "Soil_Ash"
    },
    {
      "x": -1,
      "y": 2,
      "z": -11,
      "name": "Soil_Ash"
    },
    {
      "x": -1,
      "y": 3,
      "z": -11,
      "name": "Soil_Ash"
    },
    {
      "x": -1,
      "y": 0,
      "z": -10,
      "name": "Soil_Ash"
    },
    {
      "x": -1,
      "y": 1,
      "z": -10,
      "name": "Soil_Ash"
    },
    {
      "x": -1,
      "y": 2,
      "z": -10,
      "name": "Soil_Ash"
    },
    {
      "x": -1,
      "y": 3,
      "z": -10,
      "name": "Soil_Ash"
    },
    {
      "x": -1,
      "y": 4,
      "z": -10,
      "name": "Soil_Ash"
    },
    {
      "x": -1,
      "y": 0,
      "z": -9,
      "name": "Soil_Ash"
    },
    {
      "x": -1,
      "y": 1,
      "z": -9,
      "name": "Soil_Ash"
    },
    {
      "x": -1,
      "y": 2,
      "z": -9,
      "name": "Soil_Ash"
    },
    {
      "x": -1,
      "y": 3,
      "z": -9,
      "name": "Soil_Ash"
    },
    {
      "x": -1,
      "y": 4,
      "z": -9,
      "name": "Soil_Ash"
    },
    {
      "x": -1,
      "y": 5,
      "z": -9,
      "name": "Soil_Ash"
    },
    {
      "x": -1,
      "y": 0,
      "z": -8,
      "name": "Soil_Ash"
    },
    {
      "x": -1,
      "y": 1,
      "z": -8,
      "name": "Soil_Ash"
    },
    {
      "x": -1,
      "y": 2,
      "z": -8,
      "name": "Soil_Ash"
    },
    {
      "x": -1,
      "y": 3,
      "z": -8,
      "name": "Soil_Ash"
    },
    {
      "x": -1,
      "y": 4,
      "z": -8,
      "name": "Soil_Ash"
    },
    {
      "x": -1,
      "y": 5,
      "z": -8,
      "name": "Soil_Ash"
    },
    {
      "x": -1,
      "y": 6,
      "z": -8,
      "name": "Soil_Sand_Ashen"
    },
    {
      "x": -1,
      "y": 0,
      "z": -7,
      "name": "Soil_Ash"
    },
    {
      "x": -1,
      "y": 1,
      "z": -7,
      "name": "Soil_Ash"
    },
    {
      "x": -1,
      "y": 2,
      "z": -7,
      "name": "Soil_Ash"
    },
    {
      "x": -1,
      "y": 3,
      "z": -7,
      "name": "Soil_Ash"
    },
    {
      "x": -1,
      "y": 4,
      "z": -7,
      "name": "Soil_Ash"
    },
    {
      "x": -1,
      "y": 5,
      "z": -7,
      "name": "Soil_Ash"
    },
    {
      "x": -1,
      "y": 6,
      "z": -7,
      "name": "Soil_Ash"
    },
    {
      "x": -1,
      "y": 0,
      "z": -6,
      "name": "Soil_Ash"
    },
    {
      "x": -1,
      "y": 1,
      "z": -6,
      "name": "Soil_Ash"
    },
    {
      "x": -1,
      "y": 2,
      "z": -6,
      "name": "Soil_Ash"
    },
    {
      "x": -1,
      "y": 3,
      "z": -6,
      "name": "Soil_Ash"
    },
    {
      "x": -1,
      "y": 4,
      "z": -6,
      "name": "Soil_Ash"
    },
    {
      "x": -1,
      "y": 5,
      "z": -6,
      "name": "Soil_Ash"
    },
    {
      "x": -1,
      "y": 0,
      "z": -5,
      "name": "Soil_Ash"
    },
    {
      "x": -1,
      "y": 1,
      "z": -5,
      "name": "Soil_Ash"
    },
    {
      "x": -1,
      "y": 2,
      "z": -5,
      "name": "Soil_Ash"
    },
    {
      "x": -1,
      "y": 3,
      "z": -5,
      "name": "Soil_Ash"
    },
    {
      "x": -1,
      "y": 4,
      "z": -5,
      "name": "Soil_Ash"
    },
    {
      "x": -1,
      "y": 5,
      "z": -5,
      "name": "Soil_Sand_Ashen"
    },
    {
      "x": -1,
      "y": 0,
      "z": -4,
      "name": "Soil_Ash"
    },
    {
      "x": -1,
      "y": 1,
      "z": -4,
      "name": "Soil_Ash"
    },
    {
      "x": -1,
      "y": 2,
      "z": -4,
      "name": "Soil_Ash"
    },
    {
      "x": -1,
      "y": 3,
      "z": -4,
      "name": "Soil_Ash"
    },
    {
      "x": -1,
      "y": 4,
      "z": -4,
      "name": "Soil_Ash"
    },
    {
      "x": -1,
      "y": 0,
      "z": -3,
      "name": "Soil_Sand_Ashen"
    },
    {
      "x": -1,
      "y": 1,
      "z": -3,
      "name": "Soil_Ash"
    },
    {
      "x": -1,
      "y": 0,
      "z": -2,
      "name": "Soil_Ash"
    },
    {
      "x": -1,
      "y": 1,
      "z": -2,
      "name": "Soil_Ash"
    },
    {
      "x": -1,
      "y": 2,
      "z": -2,
      "name": "Soil_Sand_Ashen"
    },
    {
      "x": -1,
      "y": 3,
      "z": -2,
      "name": "Soil_Ash"
    },
    {
      "x": -1,
      "y": 0,
      "z": -1,
      "name": "Soil_Ash"
    },
    {
      "x": -1,
      "y": 1,
      "z": -1,
      "name": "Soil_Ash"
    },
    {
      "x": -1,
      "y": 2,
      "z": -1,
      "name": "Soil_Ash"
    },
    {
      "x": -1,
      "y": 3,
      "z": -1,
      "name": "Soil_Ash"
    },
    {
      "x": -1,
      "y": 4,
      "z": -1,
      "name": "Soil_Ash"
    },
    {
      "x": -1,
      "y": 0,
      "z": 0,
      "name": "Soil_Ash"
    },
    {
      "x": -1,
      "y": 1,
      "z": 0,
      "name": "Soil_Ash"
    },
    {
      "x": -1,
      "y": 2,
      "z": 0,
      "name": "Rock_Magma_Cooled"
    },
    {
      "x": -1,
      "y": 3,
      "z": 0,
      "name": "Ore_Adamantite_Magma_Cracked"
    },
    {
      "x": -1,
      "y": 4,
      "z": 0,
      "name": "Ore_Adamantite_Magma_Cracked"
    },
    {
      "x": -1,
      "y": 5,
      "z": 0,
      "name": "Ore_Adamantite_Magma_Cracked"
    },
    {
      "x": -1,
      "y": 6,
      "z": 0,
      "name": "Rock_Magma_Cooled"
    },
    {
      "x": -1,
      "y": 7,
      "z": 0,
      "name": "Ore_Adamantite_Magma_Cracked"
    },
    {
      "x": -1,
      "y": 8,
      "z": 0,
      "name": "Rock_Magma_Cooled"
    },
    {
      "x": -1,
      "y": 9,
      "z": 0,
      "name": "Rock_Magma_Cooled"
    },
    {
      "x": -1,
      "y": 10,
      "z": 0,
      "name": "Rock_Magma_Cooled"
    },
    {
      "x": -1,
      "y": 39,
      "z": 0,
      "name": "Plant_Vine_Wall_Poisoned",
      "support": 15,
      "rotation": 2
    },
    {
      "x": -1,
      "y": 0,
      "z": 1,
      "name": "Soil_Ash"
    },
    {
      "x": -1,
      "y": 1,
      "z": 1,
      "name": "Soil_Ash"
    },
    {
      "x": -1,
      "y": 2,
      "z": 1,
      "name": "Rock_Magma_Cooled"
    },
    {
      "x": -1,
      "y": 3,
      "z": 1,
      "name": "Rock_Magma_Cooled"
    },
    {
      "x": -1,
      "y": 4,
      "z": 1,
      "name": "Rock_Magma_Cooled"
    },
    {
      "x": -1,
      "y": 5,
      "z": 1,
      "name": "Ore_Adamantite_Magma_Cracked"
    },
    {
      "x": -1,
      "y": 6,
      "z": 1,
      "name": "Rock_Magma_Cooled"
    },
    {
      "x": -1,
      "y": 7,
      "z": 1,
      "name": "Ore_Adamantite_Magma_Cracked"
    },
    {
      "x": -1,
      "y": 8,
      "z": 1,
      "name": "Ore_Adamantite_Magma_Cracked"
    },
    {
      "x": -1,
      "y": 9,
      "z": 1,
      "name": "Rock_Magma_Cooled"
    },
    {
      "x": -1,
      "y": 10,
      "z": 1,
      "name": "Rock_Magma_Cooled"
    },
    {
      "x": -1,
      "y": 11,
      "z": 1,
      "name": "Rock_Magma_Cooled"
    },
    {
      "x": -1,
      "y": 12,
      "z": 1,
      "name": "Ore_Adamantite_Magma_Cracked"
    },
    {
      "x": -1,
      "y": 35,
      "z": 1,
      "name": "Plant_Vine_Wall_Poisoned",
      "support": 15,
      "rotation": 2
    },
    {
      "x": -1,
      "y": 37,
      "z": 1,
      "name": "Rock_Magma_Cooled",
      "rotation": 1
    },
    {
      "x": -1,
      "y": 38,
      "z": 1,
      "name": "Rock_Magma_Cooled",
      "rotation": 1
    },
    {
      "x": -1,
      "y": 39,
      "z": 1,
      "name": "Rock_Magma_Cooled",
      "rotation": 1
    },
    {
      "x": -1,
      "y": 40,
      "z": 1,
      "name": "Plant_Moss_Rug_Pink",
      "support": 15
    },
    {
      "x": -1,
      "y": 0,
      "z": 2,
      "name": "Soil_Ash"
    },
    {
      "x": -1,
      "y": 1,
      "z": 2,
      "name": "Soil_Ash"
    },
    {
      "x": -1,
      "y": 2,
      "z": 2,
      "name": "Rock_Magma_Cooled"
    },
    {
      "x": -1,
      "y": 3,
      "z": 2,
      "name": "Rock_Magma_Cooled"
    },
    {
      "x": -1,
      "y": 4,
      "z": 2,
      "name": "Rock_Magma_Cooled"
    },
    {
      "x": -1,
      "y": 5,
      "z": 2,
      "name": "Rock_Magma_Cooled"
    },
    {
      "x": -1,
      "y": 6,
      "z": 2,
      "name": "Ore_Adamantite_Magma_Cracked"
    },
    {
      "x": -1,
      "y": 7,
      "z": 2,
      "name": "Ore_Adamantite_Magma_Cracked"
    },
    {
      "x": -1,
      "y": 8,
      "z": 2,
      "name": "Rock_Magma_Cooled"
    },
    {
      "x": -1,
      "y": 9,
      "z": 2,
      "name": "Rock_Magma_Cooled"
    },
    {
      "x": -1,
      "y": 10,
      "z": 2,
      "name": "Ore_Adamantite_Magma_Cracked"
    },
    {
      "x": -1,
      "y": 11,
      "z": 2,
      "name": "Rock_Magma_Cooled"
    },
    {
      "x": -1,
      "y": 12,
      "z": 2,
      "name": "Rock_Magma_Cooled"
    },
    {
      "x": -1,
      "y": 31,
      "z": 2,
      "name": "Plant_Vine_Wall_Poisoned",
      "support": 15,
      "rotation": 2
    },
    {
      "x": -1,
      "y": 33,
      "z": 2,
      "name": "Plant_Vine_Wall_Poisoned",
      "support": 15,
      "rotation": 2
    },
    {
      "x": -1,
      "y": 34,
      "z": 2,
      "name": "Ore_Adamantite_Magma_Cracked",
      "rotation": 1
    },
    {
      "x": -1,
      "y": 35,
      "z": 2,
      "name": "Rock_Magma_Cooled",
      "rotation": 1
    },
    {
      "x": -1,
      "y": 36,
      "z": 2,
      "name": "Rock_Magma_Cooled",
      "rotation": 1
    },
    {
      "x": -1,
      "y": 37,
      "z": 2,
      "name": "Rock_Magma_Cooled",
      "rotation": 1
    },
    {
      "x": -1,
      "y": 38,
      "z": 2,
      "name": "Plant_Moss_Rug_Pink",
      "support": 15
    },
    {
      "x": -1,
      "y": 0,
      "z": 3,
      "name": "Soil_Ash"
    },
    {
      "x": -1,
      "y": 1,
      "z": 3,
      "name": "Soil_Ash"
    },
    {
      "x": -1,
      "y": 2,
      "z": 3,
      "name": "Soil_Ash"
    },
    {
      "x": -1,
      "y": 3,
      "z": 3,
      "name": "Rock_Magma_Cooled"
    },
    {
      "x": -1,
      "y": 4,
      "z": 3,
      "name": "Rock_Magma_Cooled"
    },
    {
      "x": -1,
      "y": 5,
      "z": 3,
      "name": "Rock_Magma_Cooled"
    },
    {
      "x": -1,
      "y": 6,
      "z": 3,
      "name": "Rock_Magma_Cooled"
    },
    {
      "x": -1,
      "y": 7,
      "z": 3,
      "name": "Rock_Magma_Cooled"
    },
    {
      "x": -1,
      "y": 8,
      "z": 3,
      "name": "Rock_Magma_Cooled"
    },
    {
      "x": -1,
      "y": 9,
      "z": 3,
      "name": "Rock_Magma_Cooled"
    },
    {
      "x": -1,
      "y": 10,
      "z": 3,
      "name": "Rock_Magma_Cooled"
    },
    {
      "x": -1,
      "y": 11,
      "z": 3,
      "name": "Rock_Magma_Cooled"
    },
    {
      "x": -1,
      "y": 31,
      "z": 3,
      "name": "Rock_Magma_Cooled",
      "rotation": 1
    },
    {
      "x": -1,
      "y": 32,
      "z": 3,
      "name": "Rock_Magma_Cooled",
      "rotation": 1
    },
    {
      "x": -1,
      "y": 33,
      "z": 3,
      "name": "Rock_Magma_Cooled",
      "rotation": 1
    },
    {
      "x": -1,
      "y": 34,
      "z": 3,
      "name": "Rock_Magma_Cooled",
      "rotation": 1
    },
    {
      "x": -1,
      "y": 35,
      "z": 3,
      "name": "Rock_Magma_Cooled",
      "rotation": 1
    },
    {
      "x": -1,
      "y": 0,
      "z": 4,
      "name": "Soil_Ash"
    },
    {
      "x": -1,
      "y": 1,
      "z": 4,
      "name": "Soil_Ash"
    },
    {
      "x": -1,
      "y": 2,
      "z": 4,
      "name": "Soil_Ash"
    },
    {
      "x": -1,
      "y": 3,
      "z": 4,
      "name": "Soil_Ash"
    },
    {
      "x": -1,
      "y": 4,
      "z": 4,
      "name": "Soil_Ash"
    },
    {
      "x": -1,
      "y": 5,
      "z": 4,
      "name": "Rock_Magma_Cooled"
    },
    {
      "x": -1,
      "y": 6,
      "z": 4,
      "name": "Rock_Magma_Cooled"
    },
    {
      "x": -1,
      "y": 7,
      "z": 4,
      "name": "Ore_Adamantite_Magma_Cracked"
    },
    {
      "x": -1,
      "y": 8,
      "z": 4,
      "name": "Rock_Magma_Cooled"
    },
    {
      "x": -1,
      "y": 9,
      "z": 4,
      "name": "Rock_Magma_Cooled"
    },
    {
      "x": -1,
      "y": 10,
      "z": 4,
      "name": "Rock_Magma_Cooled"
    },
    {
      "x": -1,
      "y": 11,
      "z": 4,
      "name": "Rock_Magma_Cooled"
    },
    {
      "x": -1,
      "y": 30,
      "z": 4,
      "name": "Rock_Magma_Cooled",
      "rotation": 1
    },
    {
      "x": -1,
      "y": 31,
      "z": 4,
      "name": "Ore_Adamantite_Magma_Cracked",
      "rotation": 1
    },
    {
      "x": -1,
      "y": 32,
      "z": 4,
      "name": "Ore_Adamantite_Magma_Cracked",
      "rotation": 1
    },
    {
      "x": -1,
      "y": 33,
      "z": 4,
      "name": "Ore_Adamantite_Magma_Cracked",
      "rotation": 1
    },
    {
      "x": -1,
      "y": 34,
      "z": 4,
      "name": "Rock_Magma_Cooled",
      "rotation": 1
    },
    {
      "x": -1,
      "y": 0,
      "z": 5,
      "name": "Soil_Ash"
    },
    {
      "x": -1,
      "y": 1,
      "z": 5,
      "name": "Soil_Ash"
    },
    {
      "x": -1,
      "y": 2,
      "z": 5,
      "name": "Soil_Ash"
    },
    {
      "x": -1,
      "y": 3,
      "z": 5,
      "name": "Soil_Ash"
    },
    {
      "x": -1,
      "y": 4,
      "z": 5,
      "name": "Soil_Ash"
    },
    {
      "x": -1,
      "y": 5,
      "z": 5,
      "name": "Plant_Bramble_Dead_Twisted"
    },
    {
      "x": -1,
      "y": 7,
      "z": 5,
      "name": "Rock_Magma_Cooled"
    },
    {
      "x": -1,
      "y": 8,
      "z": 5,
      "name": "Rock_Magma_Cooled"
    },
    {
      "x": -1,
      "y": 9,
      "z": 5,
      "name": "Rock_Magma_Cooled"
    },
    {
      "x": -1,
      "y": 10,
      "z": 5,
      "name": "Rock_Magma_Cooled"
    },
    {
      "x": -1,
      "y": 32,
      "z": 5,
      "name": "Plant_Vine_Wall_Poisoned",
      "support": 15
    },
    {
      "x": -1,
      "y": 0,
      "z": 6,
      "name": "Soil_Ash"
    },
    {
      "x": -1,
      "y": 1,
      "z": 6,
      "name": "Soil_Ash"
    },
    {
      "x": -1,
      "y": 2,
      "z": 6,
      "name": "Soil_Ash"
    },
    {
      "x": -1,
      "y": 3,
      "z": 6,
      "name": "Soil_Ash"
    },
    {
      "x": -1,
      "y": 9,
      "z": 6,
      "name": "Ore_Adamantite_Magma_Cracked"
    },
    {
      "x": -1,
      "y": 10,
      "z": 6,
      "name": "Rock_Magma_Cooled"
    },
    {
      "x": -1,
      "y": 0,
      "z": 7,
      "name": "Soil_Ash"
    },
    {
      "x": -1,
      "y": 1,
      "z": 7,
      "name": "Soil_Ash"
    },
    {
      "x": -1,
      "y": 2,
      "z": 7,
      "name": "Soil_Ash"
    },
    {
      "x": -1,
      "y": 3,
      "z": 7,
      "name": "Soil_Ash"
    },
    {
      "x": -1,
      "y": 0,
      "z": 8,
      "name": "Soil_Ash"
    },
    {
      "x": -1,
      "y": 1,
      "z": 8,
      "name": "Soil_Ash"
    },
    {
      "x": -1,
      "y": 0,
      "z": 9,
      "name": "Soil_Ash"
    },
    {
      "x": -1,
      "y": 1,
      "z": 9,
      "name": "Soil_Ash"
    },
    {
      "x": 0,
      "y": 0,
      "z": -13,
      "name": "Soil_Sand_Ashen"
    },
    {
      "x": 0,
      "y": 0,
      "z": -12,
      "name": "Soil_Ash"
    },
    {
      "x": 0,
      "y": 1,
      "z": -12,
      "name": "Soil_Ash"
    },
    {
      "x": 0,
      "y": 0,
      "z": -11,
      "name": "Soil_Ash"
    },
    {
      "x": 0,
      "y": 1,
      "z": -11,
      "name": "Soil_Ash"
    },
    {
      "x": 0,
      "y": 2,
      "z": -11,
      "name": "Soil_Ash"
    },
    {
      "x": 0,
      "y": 3,
      "z": -11,
      "name": "Soil_Sand_Ashen"
    },
    {
      "x": 0,
      "y": 0,
      "z": -10,
      "name": "Soil_Ash"
    },
    {
      "x": 0,
      "y": 1,
      "z": -10,
      "name": "Soil_Ash"
    },
    {
      "x": 0,
      "y": 2,
      "z": -10,
      "name": "Soil_Ash"
    },
    {
      "x": 0,
      "y": 3,
      "z": -10,
      "name": "Soil_Ash"
    },
    {
      "x": 0,
      "y": 4,
      "z": -10,
      "name": "Soil_Ash"
    },
    {
      "x": 0,
      "y": 0,
      "z": -9,
      "name": "Soil_Ash"
    },
    {
      "x": 0,
      "y": 1,
      "z": -9,
      "name": "Soil_Ash"
    },
    {
      "x": 0,
      "y": 2,
      "z": -9,
      "name": "Soil_Ash"
    },
    {
      "x": 0,
      "y": 3,
      "z": -9,
      "name": "Soil_Ash"
    },
    {
      "x": 0,
      "y": 4,
      "z": -9,
      "name": "Soil_Ash"
    },
    {
      "x": 0,
      "y": 5,
      "z": -9,
      "name": "Soil_Ash"
    },
    {
      "x": 0,
      "y": 0,
      "z": -8,
      "name": "Soil_Ash"
    },
    {
      "x": 0,
      "y": 1,
      "z": -8,
      "name": "Soil_Ash"
    },
    {
      "x": 0,
      "y": 2,
      "z": -8,
      "name": "Soil_Ash"
    },
    {
      "x": 0,
      "y": 3,
      "z": -8,
      "name": "Soil_Ash"
    },
    {
      "x": 0,
      "y": 4,
      "z": -8,
      "name": "Soil_Ash"
    },
    {
      "x": 0,
      "y": 5,
      "z": -8,
      "name": "Soil_Ash"
    },
    {
      "x": 0,
      "y": 6,
      "z": -8,
      "name": "Soil_Sand_Ashen"
    },
    {
      "x": 0,
      "y": 7,
      "z": -8,
      "name": "Plant_Flower_Bushy_Poisoned"
    },
    {
      "x": 0,
      "y": 0,
      "z": -7,
      "name": "Soil_Ash"
    },
    {
      "x": 0,
      "y": 1,
      "z": -7,
      "name": "Soil_Ash"
    },
    {
      "x": 0,
      "y": 2,
      "z": -7,
      "name": "Soil_Ash"
    },
    {
      "x": 0,
      "y": 3,
      "z": -7,
      "name": "Soil_Ash"
    },
    {
      "x": 0,
      "y": 4,
      "z": -7,
      "name": "Soil_Ash"
    },
    {
      "x": 0,
      "y": 5,
      "z": -7,
      "name": "Soil_Ash"
    },
    {
      "x": 0,
      "y": 6,
      "z": -7,
      "name": "Soil_Sand_Ashen"
    },
    {
      "x": 0,
      "y": 7,
      "z": -7,
      "name": "Plant_Flower_Bushy_Poisoned"
    },
    {
      "x": 0,
      "y": 0,
      "z": -6,
      "name": "Soil_Ash"
    },
    {
      "x": 0,
      "y": 1,
      "z": -6,
      "name": "Soil_Ash"
    },
    {
      "x": 0,
      "y": 2,
      "z": -6,
      "name": "Soil_Ash"
    },
    {
      "x": 0,
      "y": 3,
      "z": -6,
      "name": "Soil_Ash"
    },
    {
      "x": 0,
      "y": 4,
      "z": -6,
      "name": "Soil_Ash"
    },
    {
      "x": 0,
      "y": 5,
      "z": -6,
      "name": "Soil_Ash"
    },
    {
      "x": 0,
      "y": 6,
      "z": -6,
      "name": "Soil_Sand_Ashen"
    },
    {
      "x": 0,
      "y": 7,
      "z": -6,
      "name": "Plant_Flower_Bushy_Poisoned"
    },
    {
      "x": 0,
      "y": 0,
      "z": -5,
      "name": "Soil_Ash"
    },
    {
      "x": 0,
      "y": 1,
      "z": -5,
      "name": "Soil_Ash"
    },
    {
      "x": 0,
      "y": 2,
      "z": -5,
      "name": "Soil_Ash"
    },
    {
      "x": 0,
      "y": 3,
      "z": -5,
      "name": "Soil_Ash"
    },
    {
      "x": 0,
      "y": 4,
      "z": -5,
      "name": "Soil_Ash"
    },
    {
      "x": 0,
      "y": 5,
      "z": -5,
      "name": "Soil_Ash"
    },
    {
      "x": 0,
      "y": 0,
      "z": -4,
      "name": "Soil_Ash"
    },
    {
      "x": 0,
      "y": 1,
      "z": -4,
      "name": "Soil_Ash"
    },
    {
      "x": 0,
      "y": 2,
      "z": -4,
      "name": "Soil_Ash"
    },
    {
      "x": 0,
      "y": 3,
      "z": -4,
      "name": "Soil_Ash"
    },
    {
      "x": 0,
      "y": 4,
      "z": -4,
      "name": "Soil_Ash"
    },
    {
      "x": 0,
      "y": 0,
      "z": -3,
      "name": "Soil_Ash"
    },
    {
      "x": 0,
      "y": 1,
      "z": -3,
      "name": "Soil_Ash"
    },
    {
      "x": 0,
      "y": 2,
      "z": -3,
      "name": "Soil_Ash"
    },
    {
      "x": 0,
      "y": 3,
      "z": -3,
      "name": "Soil_Sand_Ashen"
    },
    {
      "x": 0,
      "y": 0,
      "z": -2,
      "name": "Soil_Ash"
    },
    {
      "x": 0,
      "y": 1,
      "z": -2,
      "name": "Soil_Ash"
    },
    {
      "x": 0,
      "y": 2,
      "z": -2,
      "name": "Soil_Ash"
    },
    {
      "x": 0,
      "y": 3,
      "z": -2,
      "name": "Soil_Ash"
    },
    {
      "x": 0,
      "y": 4,
      "z": -2,
      "name": "Soil_Sand_Ashen"
    },
    {
      "x": 0,
      "y": 0,
      "z": -1,
      "name": "Soil_Ash"
    },
    {
      "x": 0,
      "y": 1,
      "z": -1,
      "name": "Soil_Ash"
    },
    {
      "x": 0,
      "y": 2,
      "z": -1,
      "name": "Soil_Ash"
    },
    {
      "x": 0,
      "y": 3,
      "z": -1,
      "name": "Soil_Ash"
    },
    {
      "x": 0,
      "y": 4,
      "z": -1,
      "name": "Soil_Ash"
    },
    {
      "x": 0,
      "y": 5,
      "z": -1,
      "name": "Soil_Ash"
    },
    {
      "x": 0,
      "y": 11,
      "z": -1,
      "name": "Plant_Vine_Wall_Poisoned",
      "support": 15,
      "rotation": 2
    },
    {
      "x": 0,
      "y": 39,
      "z": -1,
      "name": "Plant_Vine_Wall_Poisoned",
      "support": 15,
      "rotation": 2
    },
    {
      "x": 0,
      "y": 40,
      "z": -1,
      "name": "Plant_Vine_Wall_Poisoned",
      "support": 15,
      "rotation": 2
    },
    {
      "x": 0,
      "y": 0,
      "z": 0,
      "name": "Soil_Ash"
    },
    {
      "x": 0,
      "y": 1,
      "z": 0,
      "name": "Soil_Ash"
    },
    {
      "x": 0,
      "y": 2,
      "z": 0,
      "name": "Rock_Magma_Cooled"
    },
    {
      "x": 0,
      "y": 3,
      "z": 0,
      "name": "Rock_Magma_Cooled"
    },
    {
      "x": 0,
      "y": 4,
      "z": 0,
      "name": "Ore_Adamantite_Magma_Cracked"
    },
    {
      "x": 0,
      "y": 5,
      "z": 0,
      "name": "Rock_Magma_Cooled"
    },
    {
      "x": 0,
      "y": 6,
      "z": 0,
      "name": "Ore_Adamantite_Magma_Cracked"
    },
    {
      "x": 0,
      "y": 7,
      "z": 0,
      "name": "Rock_Magma_Cooled"
    },
    {
      "x": 0,
      "y": 8,
      "z": 0,
      "name": "Rock_Magma_Cooled"
    },
    {
      "x": 0,
      "y": 9,
      "z": 0,
      "name": "Rock_Magma_Cooled"
    },
    {
      "x": 0,
      "y": 10,
      "z": 0,
      "name": "Rock_Magma_Cooled"
    },
    {
      "x": 0,
      "y": 11,
      "z": 0,
      "name": "Rock_Magma_Cooled"
    },
    {
      "x": 0,
      "y": 12,
      "z": 0,
      "name": "Rock_Magma_Cooled"
    },
    {
      "x": 0,
      "y": 13,
      "z": 0,
      "name": "Rock_Magma_Cooled"
    },
    {
      "x": 0,
      "y": 14,
      "z": 0,
      "name": "Rock_Magma_Cooled"
    },
    {
      "x": 0,
      "y": 38,
      "z": 0,
      "name": "Rock_Magma_Cooled",
      "rotation": 1
    },
    {
      "x": 0,
      "y": 39,
      "z": 0,
      "name": "Rock_Magma_Cooled",
      "rotation": 1
    },
    {
      "x": 0,
      "y": 40,
      "z": 0,
      "name": "Rock_Magma_Cooled",
      "rotation": 1
    },
    {
      "x": 0,
      "y": 42,
      "z": 0,
      "name": "Plant_Vine_Wall_Poisoned",
      "support": 15,
