{
  "version": 8,
  "blockIdVersion": 11,
  "anchorX": 0,
  "anchorY": 0,
  "anchorZ": 0,
  "blocks": [
    {
      "x": -10,
      "y": 0,
      "z": -4,
      "name": "Soil_Sand_Ashen"
    },
    {
      "x": -10,
      "y": 0,
      "z": -3,
      "name": "Soil_Sand_Ashen"
    },
    {
      "x": -10,
      "y": 0,
      "z": -2,
      "name": "Soil_Sand_Ashen"
    },
    {
      "x": -9,
      "y": 0,
      "z": -6,
      "name": "Soil_Ash"
    },
    {
      "x": -9,
      "y": 0,
      "z": -5,
      "name": "Soil_Ash"
    },
    {
      "x": -9,
      "y": 1,
      "z": -5,
      "name": "Soil_Ash"
    },
    {
      "x": -9,
      "y": 0,
      "z": -4,
      "name": "Soil_Ash"
    },
    {
      "x": -9,
      "y": 1,
      "z": -4,
      "name": "Soil_Ash"
    },
    {
      "x": -9,
      "y": 0,
      "z": -3,
      "name": "Soil_Ash"
    },
    {
      "x": -9,
      "y": 1,
      "z": -3,
      "name": "Soil_Ash"
    },
    {
      "x": -9,
      "y": 0,
      "z": -2,
      "name": "Soil_Ash"
    },
    {
      "x": -9,
      "y": 1,
      "z": -2,
      "name": "Soil_Ash"
    },
    {
      "x": -9,
      "y": 0,
      "z": -1,
      "name": "Soil_Ash"
    },
    {
      "x": -9,
      "y": 1,
      "z": -1,
      "name": "Soil_Sand_Ashen"
    },
    {
      "x": -9,
      "y": 0,
      "z": 0,
      "name": "Soil_Sand_Ashen"
    },
    {
      "x": -9,
      "y": 0,
      "z": 5,
      "name": "Soil_Sand_Ashen"
    },
    {
      "x": -9,
      "y": 0,
      "z": 6,
      "name": "Soil_Ash"
    },
    {
      "x": -9,
      "y": 0,
      "z": 7,
      "name": "Soil_Ash"
    },
    {
      "x": -8,
      "y": 0,
      "z": -6,
      "name": "Soil_Sand_Ashen"
    },
    {
      "x": -8,
      "y": 1,
      "z": -6,
      "name": "Soil_Ash"
    },
    {
      "x": -8,
      "y": 17,
      "z": -6,
      "name": "Plant_Vine_Wall_Poisoned",
      "support": 15,
      "rotation": 3
    },
    {
      "x": -8,
      "y": 0,
      "z": -5,
      "name": "Soil_Ash"
    },
    {
      "x": -8,
      "y": 1,
      "z": -5,
      "name": "Soil_Ash"
    },
    {
      "x": -8,
      "y": 2,
      "z": -5,
      "name": "Soil_Ash"
    },
    {
      "x": -8,
      "y": 16,
      "z": -5,
      "name": "Plant_Vine_Wall_Poisoned",
      "support": 15,
      "rotation": 3
    },
    {
      "x": -8,
      "y": 0,
      "z": -4,
      "name": "Soil_Ash"
    },
    {
      "x": -8,
      "y": 1,
      "z": -4,
      "name": "Soil_Ash"
    },
    {
      "x": -8,
      "y": 2,
      "z": -4,
      "name": "Soil_Ash"
    },
    {
      "x": -8,
      "y": 0,
      "z": -3,
      "name": "Soil_Ash"
    },
    {
      "x": -8,
      "y": 1,
      "z": -3,
      "name": "Soil_Ash"
    },
    {
      "x": -8,
      "y": 2,
      "z": -3,
      "name": "Soil_Ash"
    },
    {
      "x": -8,
      "y": 3,
      "z": -3,
      "name": "Soil_Ash"
    },
    {
      "x": -8,
      "y": 4,
      "z": -3,
      "name": "Plant_Flower_Bushy_Violet"
    },
    {
      "x": -8,
      "y": 0,
      "z": -2,
      "name": "Soil_Ash"
    },
    {
      "x": -8,
      "y": 1,
      "z": -2,
      "name": "Soil_Ash"
    },
    {
      "x": -8,
      "y": 2,
      "z": -2,
      "name": "Soil_Ash"
    },
    {
      "x": -8,
      "y": 0,
      "z": -1,
      "name": "Soil_Ash"
    },
    {
      "x": -8,
      "y": 1,
      "z": -1,
      "name": "Soil_Ash"
    },
    {
      "x": -8,
      "y": 2,
      "z": -1,
      "name": "Soil_Ash"
    },
    {
      "x": -8,
      "y": 0,
      "z": 0,
      "name": "Soil_Sand_Ashen"
    },
    {
      "x": -8,
      "y": 1,
      "z": 0,
      "name": "Soil_Ash"
    },
    {
      "x": -8,
      "y": 0,
      "z": 3,
      "name": "Soil_Ash"
    },
    {
      "x": -8,
      "y": 0,
      "z": 4,
      "name": "Soil_Ash"
    },
    {
      "x": -8,
      "y": 1,
      "z": 4,
      "name": "Soil_Ash"
    },
    {
      "x": -8,
      "y": 0,
      "z": 5,
      "name": "Soil_Sand_Ashen"
    },
    {
      "x": -8,
      "y": 1,
      "z": 5,
      "name": "Soil_Sand_Ashen"
    },
    {
      "x": -8,
      "y": 0,
      "z": 6,
      "name": "Soil_Ash"
    },
    {
      "x": -8,
      "y": 1,
      "z": 6,
      "name": "Soil_Ash"
    },
    {
      "x": -8,
      "y": 0,
      "z": 7,
      "name": "Soil_Sand_Ashen"
    },
    {
      "x": -8,
      "y": 1,
      "z": 7,
      "name": "Soil_Ash"
    },
    {
      "x": -8,
      "y": 0,
      "z": 8,
      "name": "Soil_Ash"
    },
    {
      "x": -8,
      "y": 1,
      "z": 8,
      "name": "Soil_Ash"
    },
    {
      "x": -8,
      "y": 0,
      "z": 9,
      "name": "Soil_Ash"
    },
    {
      "x": -7,
      "y": 0,
      "z": -7,
      "name": "Soil_Sand_Ashen"
    },
    {
      "x": -7,
      "y": 1,
      "z": -7,
      "name": "Soil_Ash"
    },
    {
      "x": -7,
      "y": 0,
      "z": -6,
      "name": "Soil_Ash"
    },
    {
      "x": -7,
      "y": 1,
      "z": -6,
      "name": "Soil_Ash"
    },
    {
      "x": -7,
      "y": 2,
      "z": -6,
      "name": "Soil_Ash"
    },
    {
      "x": -7,
      "y": 16,
      "z": -6,
      "name": "Rock_Magma_Cooled",
      "rotation": 1
    },
    {
      "x": -7,
      "y": 17,
      "z": -6,
      "name": "Rock_Magma_Cooled",
      "rotation": 1
    },
    {
      "x": -7,
      "y": 18,
      "z": -6,
      "name": "Rock_Magma_Cooled",
      "rotation": 1
    },
    {
      "x": -7,
      "y": 19,
      "z": -6,
      "name": "Rock_Magma_Cooled",
      "rotation": 1
    },
    {
      "x": -7,
      "y": 20,
      "z": -6,
      "name": "Plant_Moss_Rug_Pink",
      "support": 15
    },
    {
      "x": -7,
      "y": 0,
      "z": -5,
      "name": "Soil_Ash"
    },
    {
      "x": -7,
      "y": 1,
      "z": -5,
      "name": "Soil_Ash"
    },
    {
      "x": -7,
      "y": 2,
      "z": -5,
      "name": "Soil_Ash"
    },
    {
      "x": -7,
      "y": 3,
      "z": -5,
      "name": "Soil_Ash"
    },
    {
      "x": -7,
      "y": 14,
      "z": -5,
      "name": "Rock_Magma_Cooled",
      "rotation": 1
    },
    {
      "x": -7,
      "y": 15,
      "z": -5,
      "name": "Rock_Magma_Cooled",
      "rotation": 1
    },
    {
      "x": -7,
      "y": 16,
      "z": -5,
      "name": "Rock_Magma_Cooled",
      "rotation": 1
    },
    {
      "x": -7,
      "y": 17,
      "z": -5,
      "name": "Rock_Magma_Cooled",
      "rotation": 1
    },
    {
      "x": -7,
      "y": 18,
      "z": -5,
      "name": "Plant_Moss_Rug_Pink",
      "support": 15
    },
    {
      "x": -7,
      "y": 0,
      "z": -4,
      "name": "Soil_Ash"
    },
    {
      "x": -7,
      "y": 1,
      "z": -4,
      "name": "Soil_Ash"
    },
    {
      "x": -7,
      "y": 2,
      "z": -4,
      "name": "Soil_Ash"
    },
    {
      "x": -7,
      "y": 3,
      "z": -4,
      "name": "Soil_Ash"
    },
    {
      "x": -7,
      "y": 4,
      "z": -4,
      "name": "Soil_Ash"
    },
    {
      "x": -7,
      "y": 0,
      "z": -3,
      "name": "Soil_Ash"
    },
    {
      "x": -7,
      "y": 1,
      "z": -3,
      "name": "Soil_Ash"
    },
    {
      "x": -7,
      "y": 2,
      "z": -3,
      "name": "Soil_Ash"
    },
    {
      "x": -7,
      "y": 3,
      "z": -3,
      "name": "Soil_Ash"
    },
    {
      "x": -7,
      "y": 4,
      "z": -3,
      "name": "Soil_Ash"
    },
    {
      "x": -7,
      "y": 5,
      "z": -3,
      "name": "Plant_Flower_Bushy_Poisoned"
    },
    {
      "x": -7,
      "y": 0,
      "z": -2,
      "name": "Soil_Ash"
    },
    {
      "x": -7,
      "y": 1,
      "z": -2,
      "name": "Soil_Ash"
    },
    {
      "x": -7,
      "y": 2,
      "z": -2,
      "name": "Soil_Ash"
    },
    {
      "x": -7,
      "y": 3,
      "z": -2,
      "name": "Soil_Ash"
    },
    {
      "x": -7,
      "y": 4,
      "z": -2,
      "name": "Soil_Ash"
    },
    {
      "x": -7,
      "y": 0,
      "z": -1,
      "name": "Soil_Ash"
    },
    {
      "x": -7,
      "y": 1,
      "z": -1,
      "name": "Soil_Ash"
    },
    {
      "x": -7,
      "y": 2,
      "z": -1,
      "name": "Soil_Ash"
    },
    {
      "x": -7,
      "y": 3,
      "z": -1,
      "name": "Soil_Ash"
    },
    {
      "x": -7,
      "y": 0,
      "z": 0,
      "name": "Soil_Ash"
    },
    {
      "x": -7,
      "y": 1,
      "z": 0,
      "name": "Soil_Ash"
    },
    {
      "x": -7,
      "y": 2,
      "z": 0,
      "name": "Soil_Ash"
    },
    {
      "x": -7,
      "y": 3,
      "z": 0,
      "name": "Soil_Ash"
    },
    {
      "x": -7,
      "y": 0,
      "z": 1,
      "name": "Soil_Sand_Ashen"
    },
    {
      "x": -7,
      "y": 1,
      "z": 1,
      "name": "Soil_Ash"
    },
    {
      "x": -7,
      "y": 2,
      "z": 1,
      "name": "Soil_Ash"
    },
    {
      "x": -7,
      "y": 3,
      "z": 1,
      "name": "Plant_Flower_Bushy_Violet"
    },
    {
      "x": -7,
      "y": 0,
      "z": 2,
      "name": "Soil_Sand_Ashen"
    },
    {
      "x": -7,
      "y": 0,
      "z": 3,
      "name": "Soil_Ash"
    },
    {
      "x": -7,
      "y": 1,
      "z": 3,
      "name": "Soil_Ash"
    },
    {
      "x": -7,
      "y": 0,
      "z": 4,
      "name": "Soil_Ash"
    },
    {
      "x": -7,
      "y": 1,
      "z": 4,
      "name": "Soil_Ash"
    },
    {
      "x": -7,
      "y": 2,
      "z": 4,
      "name": "Soil_Ash"
    },
    {
      "x": -7,
      "y": 0,
      "z": 5,
      "name": "Soil_Ash"
    },
    {
      "x": -7,
      "y": 1,
      "z": 5,
      "name": "Soil_Ash"
    },
    {
      "x": -7,
      "y": 2,
      "z": 5,
      "name": "Soil_Ash"
    },
    {
      "x": -7,
      "y": 3,
      "z": 5,
      "name": "Plant_Flower_Bushy_Violet"
    },
    {
      "x": -7,
      "y": 0,
      "z": 6,
      "name": "Soil_Ash"
    },
    {
      "x": -7,
      "y": 1,
      "z": 6,
      "name": "Soil_Ash"
    },
    {
      "x": -7,
      "y": 2,
      "z": 6,
      "name": "Soil_Ash"
    },
    {
      "x": -7,
      "y": 0,
      "z": 7,
      "name": "Soil_Sand_Ashen"
    },
    {
      "x": -7,
      "y": 1,
      "z": 7,
      "name": "Soil_Ash"
    },
    {
      "x": -7,
      "y": 2,
      "z": 7,
      "name": "Soil_Ash"
    },
    {
      "x": -7,
      "y": 0,
      "z": 8,
      "name": "Soil_Ash"
    },
    {
      "x": -7,
      "y": 1,
      "z": 8,
      "name": "Soil_Ash"
    },
    {
      "x": -7,
      "y": 2,
      "z": 8,
      "name": "Soil_Ash"
    },
    {
      "x": -7,
      "y": 0,
      "z": 9,
      "name": "Soil_Sand_Ashen"
    },
    {
      "x": -7,
      "y": 1,
      "z": 9,
      "name": "Soil_Ash"
    },
    {
      "x": -7,
      "y": 0,
      "z": 10,
      "name": "Soil_Ash"
    },
    {
      "x": -7,
      "y": 1,
      "z": 10,
      "name": "Soil_Ash"
    },
    {
      "x": -7,
      "y": 0,
      "z": 11,
      "name": "Soil_Ash"
    },
    {
      "x": -6,
      "y": 0,
      "z": -9,
      "name": "Soil_Ash"
    },
    {
      "x": -6,
      "y": 0,
      "z": -8,
      "name": "Soil_Sand_Ashen"
    },
    {
      "x": -6,
      "y": 1,
      "z": -8,
      "name": "Soil_Ash"
    },
    {
      "x": -6,
      "y": 0,
      "z": -7,
      "name": "Soil_Ash"
    },
    {
      "x": -6,
      "y": 1,
      "z": -7,
      "name": "Soil_Ash"
    },
    {
      "x": -6,
      "y": 2,
      "z": -7,
      "name": "Soil_Ash"
    },
    {
      "x": -6,
      "y": 0,
      "z": -6,
      "name": "Soil_Ash"
    },
    {
      "x": -6,
      "y": 1,
      "z": -6,
      "name": "Soil_Ash"
    },
    {
      "x": -6,
      "y": 2,
      "z": -6,
      "name": "Soil_Ash"
    },
    {
      "x": -6,
      "y": 3,
      "z": -6,
      "name": "Soil_Ash"
    },
    {
      "x": -6,
      "y": 0,
      "z": -5,
      "name": "Soil_Ash"
    },
    {
      "x": -6,
      "y": 1,
      "z": -5,
      "name": "Soil_Ash"
    },
    {
      "x": -6,
      "y": 2,
      "z": -5,
      "name": "Soil_Ash"
    },
    {
      "x": -6,
      "y": 3,
      "z": -5,
      "name": "Soil_Ash"
    },
    {
      "x": -6,
      "y": 4,
      "z": -5,
      "name": "Soil_Ash"
    },
    {
      "x": -6,
      "y": 13,
      "z": -5,
      "name": "Rock_Magma_Cooled",
      "rotation": 1
    },
    {
      "x": -6,
      "y": 14,
      "z": -5,
      "name": "Rock_Magma_Cooled",
      "rotation": 1
    },
    {
      "x": -6,
      "y": 15,
      "z": -5,
      "name": "Rock_Magma_Cooled",
      "rotation": 1
    },
    {
      "x": -6,
      "y": 16,
      "z": -5,
      "name": "Rock_Magma_Cooled",
      "rotation": 1
    },
    {
      "x": -6,
      "y": 17,
      "z": -5,
      "name": "Plant_Moss_Rug_Pink",
      "support": 15
    },
    {
      "x": -6,
      "y": 0,
      "z": -4,
      "name": "Soil_Ash"
    },
    {
      "x": -6,
      "y": 1,
      "z": -4,
      "name": "Soil_Ash"
    },
    {
      "x": -6,
      "y": 2,
      "z": -4,
      "name": "Soil_Ash"
    },
    {
      "x": -6,
      "y": 3,
      "z": -4,
      "name": "Soil_Ash"
    },
    {
      "x": -6,
      "y": 4,
      "z": -4,
      "name": "Soil_Ash"
    },
    {
      "x": -6,
      "y": 5,
      "z": -4,
      "name": "Soil_Ash"
    },
    {
      "x": -6,
      "y": 13,
      "z": -4,
      "name": "Plant_Vine_Wall_Poisoned",
      "support": 15
    },
    {
      "x": -6,
      "y": 15,
      "z": -4,
      "name": "Plant_Vine_Wall_Poisoned",
      "support": 15,
      "rotation": 3
    },
    {
      "x": -6,
      "y": 0,
      "z": -3,
      "name": "Soil_Ash"
    },
    {
      "x": -6,
      "y": 1,
      "z": -3,
      "name": "Soil_Ash"
    },
    {
      "x": -6,
      "y": 2,
      "z": -3,
      "name": "Soil_Ash"
    },
    {
      "x": -6,
      "y": 3,
      "z": -3,
      "name": "Soil_Ash"
    },
    {
      "x": -6,
      "y": 4,
      "z": -3,
      "name": "Soil_Ash"
    },
    {
      "x": -6,
      "y": 5,
      "z": -3,
      "name": "Soil_Ash"
    },
    {
      "x": -6,
      "y": 6,
      "z": -3,
      "name": "Plant_Flower_Poisoned_Orange"
    },
    {
      "x": -6,
      "y": 11,
      "z": -3,
      "name": "Plant_Vine_Wall_Poisoned",
      "support": 15,
      "rotation": 3
    },
    {
      "x": -6,
      "y": 0,
      "z": -2,
      "name": "Soil_Ash"
    },
    {
      "x": -6,
      "y": 1,
      "z": -2,
      "name": "Soil_Ash"
    },
    {
      "x": -6,
      "y": 2,
      "z": -2,
      "name": "Soil_Ash"
    },
    {
      "x": -6,
      "y": 3,
      "z": -2,
      "name": "Soil_Ash"
    },
    {
      "x": -6,
      "y": 4,
      "z": -2,
      "name": "Soil_Ash"
    },
    {
      "x": -6,
      "y": 5,
      "z": -2,
      "name": "Soil_Ash"
    },
    {
      "x": -6,
      "y": 6,
      "z": -2,
      "name": "Plant_Flower_Poisoned_Orange"
    },
    {
      "x": -6,
      "y": 0,
      "z": -1,
      "name": "Soil_Ash"
    },
    {
      "x": -6,
      "y": 1,
      "z": -1,
      "name": "Soil_Ash"
    },
    {
      "x": -6,
      "y": 2,
      "z": -1,
      "name": "Soil_Ash"
    },
    {
      "x": -6,
      "y": 3,
      "z": -1,
      "name": "Soil_Ash"
    },
    {
      "x": -6,
      "y": 4,
      "z": -1,
      "name": "Soil_Ash"
    },
    {
      "x": -6,
      "y": 5,
      "z": -1,
      "name": "Soil_Ash"
    },
    {
      "x": -6,
      "y": 6,
      "z": -1,
      "name": "Plant_Flower_Bushy_Poisoned"
    },
    {
      "x": -6,
      "y": 0,
      "z": 0,
      "name": "Soil_Ash"
    },
    {
      "x": -6,
      "y": 1,
      "z": 0,
      "name": "Soil_Ash"
    },
    {
      "x": -6,
      "y": 2,
      "z": 0,
      "name": "Soil_Ash"
    },
    {
      "x": -6,
      "y": 3,
      "z": 0,
      "name": "Soil_Ash"
    },
    {
      "x": -6,
      "y": 4,
      "z": 0,
      "name": "Soil_Ash"
    },
    {
      "x": -6,
      "y": 0,
      "z": 1,
      "name": "Soil_Ash"
    },
    {
      "x": -6,
      "y": 1,
      "z": 1,
      "name": "Soil_Ash"
    },
    {
      "x": -6,
      "y": 2,
      "z": 1,
      "name": "Soil_Ash"
    },
    {
      "x": -6,
      "y": 3,
      "z": 1,
      "name": "Soil_Ash"
    },
    {
      "x": -6,
      "y": 0,
      "z": 2,
      "name": "Soil_Ash"
    },
    {
      "x": -6,
      "y": 1,
      "z": 2,
      "name": "Soil_Ash"
    },
    {
      "x": -6,
      "y": 2,
      "z": 2,
      "name": "Soil_Ash"
    },
    {
      "x": -6,
      "y": 3,
      "z": 2,
      "name": "Soil_Ash"
    },
    {
      "x": -6,
      "y": 0,
      "z": 3,
      "name": "Soil_Ash"
    },
    {
      "x": -6,
      "y": 1,
      "z": 3,
      "name": "Soil_Ash"
    },
    {
      "x": -6,
      "y": 2,
      "z": 3,
      "name": "Soil_Ash"
    },
    {
      "x": -6,
      "y": 0,
      "z": 4,
      "name": "Soil_Ash"
    },
    {
      "x": -6,
      "y": 1,
      "z": 4,
      "name": "Soil_Ash"
    },
    {
      "x": -6,
      "y": 2,
      "z": 4,
      "name": "Soil_Ash"
    },
    {
      "x": -6,
      "y": 3,
      "z": 4,
      "name": "Soil_Ash"
    },
    {
      "x": -6,
      "y": 0,
      "z": 5,
      "name": "Soil_Ash"
    },
    {
      "x": -6,
      "y": 1,
      "z": 5,
      "name": "Soil_Ash"
    },
    {
      "x": -6,
      "y": 2,
      "z": 5,
      "name": "Soil_Ash"
    },
    {
      "x": -6,
      "y": 3,
      "z": 5,
      "name": "Soil_Ash"
    },
    {
      "x": -6,
      "y": 0,
      "z": 6,
      "name": "Soil_Ash"
    },
    {
      "x": -6,
      "y": 1,
      "z": 6,
      "name": "Soil_Ash"
    },
    {
      "x": -6,
      "y": 2,
      "z": 6,
      "name": "Soil_Ash"
    },
    {
      "x": -6,
      "y": 3,
      "z": 6,
      "name": "Soil_Ash"
    },
    {
      "x": -6,
      "y": 4,
      "z": 6,
      "name": "Plant_Flower_Bushy_Violet"
    },
    {
      "x": -6,
      "y": 0,
      "z": 7,
      "name": "Soil_Ash"
    },
    {
      "x": -6,
      "y": 1,
      "z": 7,
      "name": "Soil_Ash"
    },
    {
      "x": -6,
      "y": 2,
      "z": 7,
      "name": "Soil_Ash"
    },
    {
      "x": -6,
      "y": 3,
      "z": 7,
      "name": "Soil_Ash"
    },
    {
      "x": -6,
      "y": 4,
      "z": 7,
      "name": "Plant_Flower_Bushy_Violet"
    },
    {
      "x": -6,
      "y": 0,
      "z": 8,
      "name": "Soil_Ash"
    },
    {
      "x": -6,
      "y": 1,
      "z": 8,
      "name": "Soil_Ash"
    },
    {
      "x": -6,
      "y": 2,
      "z": 8,
      "name": "Soil_Ash"
    },
    {
      "x": -6,
      "y": 3,
      "z": 8,
      "name": "Soil_Ash"
    },
    {
      "x": -6,
      "y": 4,
      "z": 8,
      "name": "Plant_Flower_Bushy_Violet"
    },
    {
      "x": -6,
      "y": 0,
      "z": 9,
      "name": "Soil_Ash"
    },
    {
      "x": -6,
      "y": 1,
      "z": 9,
      "name": "Soil_Ash"
    },
    {
      "x": -6,
      "y": 2,
      "z": 9,
      "name": "Soil_Ash"
    },
    {
      "x": -6,
      "y": 0,
      "z": 10,
      "name": "Soil_Ash"
    },
    {
      "x": -6,
      "y": 1,
      "z": 10,
      "name": "Soil_Ash"
    },
    {
      "x": -6,
      "y": 0,
      "z": 11,
      "name": "Soil_Ash"
    },
    {
      "x": -6,
      "y": 1,
      "z": 11,
      "name": "Soil_Ash"
    },
    {
      "x": -5,
      "y": 0,
      "z": -9,
      "name": "Soil_Ash"
    },
    {
      "x": -5,
      "y": 0,
      "z": -8,
      "name": "Soil_Sand_Ashen"
    },
    {
      "x": -5,
      "y": 1,
      "z": -8,
      "name": "Soil_Ash"
    },
    {
      "x": -5,
      "y": 0,
      "z": -7,
      "name": "Soil_Ash"
    },
    {
      "x": -5,
      "y": 1,
      "z": -7,
      "name": "Soil_Ash"
    },
    {
      "x": -5,
      "y": 2,
      "z": -7,
      "name": "Soil_Ash"
    },
    {
      "x": -5,
      "y": 0,
      "z": -6,
      "name": "Soil_Ash"
    },
    {
      "x": -5,
      "y": 1,
      "z": -6,
      "name": "Soil_Ash"
    },
    {
      "x": -5,
      "y": 2,
      "z": -6,
      "name": "Soil_Ash"
    },
    {
      "x": -5,
      "y": 3,
      "z": -6,
      "name": "Soil_Ash"
    },
    {
      "x": -5,
      "y": 4,
      "z": -6,
      "name": "Soil_Sand_Ashen"
    },
    {
      "x": -5,
      "y": 0,
      "z": -5,
      "name": "Soil_Ash"
    },
    {
      "x": -5,
      "y": 1,
      "z": -5,
      "name": "Soil_Ash"
    },
    {
      "x": -5,
      "y": 2,
      "z": -5,
      "name": "Soil_Ash"
    },
    {
      "x": -5,
      "y": 3,
      "z": -5,
      "name": "Soil_Ash"
    },
    {
      "x": -5,
      "y": 4,
      "z": -5,
      "name": "Soil_Ash"
    },
    {
      "x": -5,
      "y": 5,
      "z": -5,
      "name": "Soil_Ash"
    },
    {
      "x": -5,
      "y": 12,
      "z": -5,
      "name": "Rock_Magma_Cooled",
      "rotation": 1
    },
    {
      "x": -5,
      "y": 13,
      "z": -5,
      "name": "Rock_Magma_Cooled",
      "rotation": 1
    },
    {
      "x": -5,
      "y": 0,
      "z": -4,
      "name": "Soil_Ash"
    },
    {
      "x": -5,
      "y": 1,
      "z": -4,
      "name": "Soil_Ash"
    },
    {
      "x": -5,
      "y": 2,
      "z": -4,
      "name": "Soil_Ash"
    },
    {
      "x": -5,
      "y": 3,
      "z": -4,
      "name": "Soil_Ash"
    },
    {
      "x": -5,
      "y": 4,
      "z": -4,
      "name": "Soil_Ash"
    },
    {
      "x": -5,
      "y": 5,
      "z": -4,
      "name": "Soil_Ash"
    },
    {
      "x": -5,
      "y": 6,
      "z": -4,
      "name": "Plant_Flower_Poisoned_Orange"
    },
    {
      "x": -5,
      "y": 12,
      "z": -4,
      "name": "Ore_Adamantite_Magma_Cracked",
      "rotation": 1
    },
    {
      "x": -5,
      "y": 13,
      "z": -4,
      "name": "Rock_Magma_Cooled",
      "rotation": 1
    },
    {
      "x": -5,
      "y": 14,
      "z": -4,
      "name": "Ore_Adamantite_Magma_Cracked",
      "rotation": 1
    },
    {
      "x": -5,
      "y": 15,
      "z": -4,
      "name": "Rock_Magma_Cooled",
      "rotation": 1
    },
    {
      "x": -5,
      "y": 16,
      "z": -4,
      "name": "Plant_Moss_Rug_Pink",
      "support": 15
    },
    {
      "x": -5,
      "y": 0,
      "z": -3,
      "name": "Soil_Ash"
    },
    {
      "x": -5,
      "y": 1,
      "z": -3,
      "name": "Soil_Ash"
    },
    {
      "x": -5,
      "y": 2,
      "z": -3,
      "name": "Soil_Ash"
    },
    {
      "x": -5,
      "y": 3,
      "z": -3,
      "name": "Soil_Ash"
    },
    {
      "x": -5,
      "y": 4,
      "z": -3,
      "name": "Soil_Ash"
    },
    {
      "x": -5,
      "y": 5,
      "z": -3,
      "name": "Soil_Ash"
    },
    {
      "x": -5,
      "y": 6,
      "z": -3,
      "name": "Soil_Ash"
    },
    {
      "x": -5,
      "y": 10,
      "z": -3,
      "name": "Rock_Magma_Cooled",
      "rotation": 1
    },
    {
      "x": -5,
      "y": 11,
      "z": -3,
      "name": "Rock_Magma_Cooled",
      "rotation": 1
    },
    {
      "x": -5,
      "y": 12,
      "z": -3,
      "name": "Plant_Vine_Wall_Poisoned",
      "support": 15,
      "rotation": 3
    },
    {
      "x": -5,
      "y": 0,
      "z": -2,
      "name": "Soil_Ash"
    },
    {
      "x": -5,
      "y": 1,
      "z": -2,
      "name": "Soil_Ash"
    },
    {
      "x": -5,
      "y": 2,
      "z": -2,
      "name": "Soil_Ash"
    },
    {
      "x": -5,
      "y": 3,
      "z": -2,
      "name": "Soil_Ash"
    },
    {
      "x": -5,
      "y": 4,
      "z": -2,
      "name": "Soil_Ash"
    },
    {
      "x": -5,
      "y": 5,
      "z": -2,
      "name": "Soil_Ash"
    },
    {
      "x": -5,
      "y": 6,
      "z": -2,
      "name": "Soil_Ash"
    },
    {
      "x": -5,
      "y": 0,
      "z": -1,
      "name": "Soil_Ash"
    },
    {
      "x": -5,
      "y": 1,
      "z": -1,
      "name": "Soil_Ash"
    },
    {
      "x": -5,
      "y": 2,
      "z": -1,
      "name": "Soil_Ash"
    },
    {
      "x": -5,
      "y": 3,
      "z": -1,
      "name": "Soil_Ash"
    },
    {
      "x": -5,
      "y": 4,
      "z": -1,
      "name": "Soil_Ash"
    },
    {
      "x": -5,
      "y": 5,
      "z": -1,
      "name": "Soil_Ash"
    },
    {
      "x": -5,
      "y": 0,
      "z": 0,
      "name": "Soil_Ash"
    },
    {
      "x": -5,
      "y": 1,
      "z": 0,
      "name": "Soil_Ash"
    },
    {
      "x": -5,
      "y": 2,
      "z": 0,
      "name": "Soil_Ash"
    },
    {
      "x": -5,
      "y": 3,
      "z": 0,
      "name": "Soil_Ash"
    },
    {
      "x": -5,
      "y": 4,
      "z": 0,
      "name": "Soil_Ash"
    },
    {
      "x": -5,
      "y": 5,
      "z": 0,
      "name": "Soil_Ash"
    },
    {
      "x": -5,
      "y": 6,
      "z": 0,
      "name": "Plant_Flower_Poisoned_Orange"
    },
    {
      "x": -5,
      "y": 0,
      "z": 1,
      "name": "Soil_Ash"
    },
    {
      "x": -5,
      "y": 1,
      "z": 1,
      "name": "Soil_Ash"
    },
    {
      "x": -5,
      "y": 2,
      "z": 1,
      "name": "Soil_Ash"
    },
    {
      "x": -5,
      "y": 3,
      "z": 1,
      "name": "Soil_Ash"
    },
    {
      "x": -5,
      "y": 4,
      "z": 1,
      "name": "Soil_Ash"
    },
    {
      "x": -5,
      "y": 0,
      "z": 2,
      "name": "Soil_Ash"
    },
    {
      "x": -5,
      "y": 1,
      "z": 2,
      "name": "Soil_Ash"
    },
    {
      "x": -5,
      "y": 2,
      "z": 2,
      "name": "Soil_Ash"
    },
    {
      "x": -5,
      "y": 3,
      "z": 2,
      "name": "Soil_Ash"
    },
    {
      "x": -5,
      "y": 4,
      "z": 2,
      "name": "Soil_Ash"
    },
    {
      "x": -5,
      "y": 5,
      "z": 2,
      "name": "Plant_Flower_Poisoned_Orange"
    },
    {
      "x": -5,
      "y": 0,
      "z": 3,
      "name": "Soil_Ash"
    },
    {
      "x": -5,
      "y": 1,
      "z": 3,
      "name": "Soil_Ash"
    },
    {
      "x": -5,
      "y": 2,
      "z": 3,
      "name": "Soil_Ash"
    },
    {
      "x": -5,
      "y": 3,
      "z": 3,
      "name": "Soil_Ash"
    },
    {
      "x": -5,
      "y": 4,
      "z": 3,
      "name": "Soil_Ash"
    },
    {
      "x": -5,
      "y": 0,
      "z": 4,
      "name": "Soil_Ash"
    },
    {
      "x": -5,
      "y": 1,
      "z": 4,
      "name": "Soil_Ash"
    },
    {
      "x": -5,
      "y": 2,
      "z": 4,
      "name": "Soil_Ash"
    },
    {
      "x": -5,
      "y": 3,
      "z": 4,
      "name": "Soil_Ash"
    },
    {
      "x": -5,
      "y": 4,
      "z": 4,
      "name": "Soil_Ash"
    },
    {
      "x": -5,
      "y": 0,
      "z": 5,
      "name": "Soil_Ash"
    },
    {
      "x": -5,
      "y": 1,
      "z": 5,
      "name": "Soil_Ash"
    },
    {
      "x": -5,
      "y": 2,
      "z": 5,
      "name": "Soil_Ash"
    },
    {
      "x": -5,
      "y": 3,
      "z": 5,
      "name": "Soil_Ash"
    },
    {
      "x": -5,
      "y": 4,
      "z": 5,
      "name": "Soil_Ash"
    },
    {
      "x": -5,
      "y": 0,
      "z": 6,
      "name": "Soil_Ash"
    },
    {
      "x": -5,
      "y": 1,
      "z": 6,
      "name": "Soil_Ash"
    },
    {
      "x": -5,
      "y": 2,
      "z": 6,
      "name": "Soil_Ash"
    },
    {
      "x": -5,
      "y": 3,
      "z": 6,
      "name": "Soil_Ash"
    },
    {
      "x": -5,
      "y": 4,
      "z": 6,
      "name": "Soil_Ash"
    },
    {
      "x": -5,
      "y": 0,
      "z": 7,
      "name": "Soil_Ash"
    },
    {
      "x": -5,
      "y": 1,
      "z": 7,
      "name": "Soil_Ash"
    },
    {
      "x": -5,
      "y": 2,
      "z": 7,
      "name": "Soil_Ash"
    },
    {
      "x": -5,
      "y": 3,
      "z": 7,
      "name": "Soil_Ash"
    },
    {
      "x": -5,
      "y": 4,
      "z": 7,
      "name": "Soil_Ash"
    },
    {
      "x": -5,
      "y": 5,
      "z": 7,
      "name": "Soil_Sand_Ashen"
    },
    {
      "x": -5,
      "y": 0,
      "z": 8,
      "name": "Soil_Ash"
    },
    {
      "x": -5,
      "y": 1,
      "z": 8,
      "name": "Soil_Ash"
    },
    {
      "x": -5,
      "y": 2,
      "z": 8,
      "name": "Soil_Ash"
    },
    {
      "x": -5,
      "y": 3,
      "z": 8,
      "name": "Soil_Ash"
    },
    {
      "x": -5,
      "y": 4,
      "z": 8,
      "name": "Soil_Ash"
    },
    {
      "x": -5,
      "y": 5,
      "z": 8,
      "name": "Plant_Flower_Bushy_Violet"
    },
    {
      "x": -5,
      "y": 0,
      "z": 9,
      "name": "Soil_Ash"
    },
    {
      "x": -5,
      "y": 1,
      "z": 9,
      "name": "Soil_Ash"
    },
    {
      "x": -5,
      "y": 2,
      "z": 9,
      "name": "Soil_Ash"
    },
    {
      "x": -5,
      "y": 3,
      "z": 9,
      "name": "Soil_Ash"
    },
    {
      "x": -5,
      "y": 4,
      "z": 9,
      "name": "Soil_Ash"
    },
    {
      "x": -5,
      "y": 0,
      "z": 10,
      "name": "Soil_Ash"
    },
    {
      "x": -5,
      "y": 1,
      "z": 10,
      "name": "Soil_Ash"
    },
    {
      "x": -5,
      "y": 2,
      "z": 10,
      "name": "Soil_Ash"
    },
    {
      "x": -5,
      "y": 3,
      "z": 10,
      "name": "Soil_Sand_Ashen"
    },
    {
      "x": -5,
      "y": 0,
      "z": 11,
      "name": "Soil_Sand_Ashen"
    },
    {
      "x": -5,
      "y": 1,
      "z": 11,
      "name": "Soil_Ash"
    },
    {
      "x": -5,
      "y": 0,
      "z": 12,
      "name": "Soil_Sand_Ashen"
    },
    {
      "x": -4,
      "y": 0,
      "z": -10,
      "name": "Soil_Sand_Ashen"
    },
    {
      "x": -4,
      "y": 0,
      "z": -9,
      "name": "Soil_Sand_Ashen"
    },
    {
      "x": -4,
      "y": 1,
      "z": -9,
      "name": "Soil_Ash"
    },
    {
      "x": -4,
      "y": 0,
      "z": -8,
      "name": "Soil_Ash"
    },
    {
      "x": -4,
      "y": 1,
      "z": -8,
      "name": "Soil_Ash"
    },
    {
      "x": -4,
      "y": 2,
      "z": -8,
      "name": "Soil_Ash"
    },
    {
      "x": -4,
      "y": 0,
      "z": -7,
      "name": "Soil_Ash"
    },
    {
      "x": -4,
      "y": 1,
      "z": -7,
      "name": "Soil_Ash"
    },
    {
      "x": -4,
      "y": 2,
      "z": -7,
      "name": "Soil_Ash"
    },
    {
      "x": -4,
      "y": 3,
      "z": -7,
      "name": "Soil_Ash"
    },
    {
      "x": -4,
      "y": 0,
      "z": -6,
      "name": "Soil_Ash"
    },
    {
      "x": -4,
      "y": 1,
      "z": -6,
      "name": "Soil_Ash"
    },
    {
      "x": -4,
      "y": 2,
      "z": -6,
      "name": "Soil_Ash"
    },
    {
      "x": -4,
      "y": 3,
      "z": -6,
      "name": "Soil_Ash"
    },
    {
      "x": -4,
      "y": 4,
      "z": -6,
      "name": "Soil_Ash"
    },
    {
      "x": -4,
      "y": 0,
      "z": -5,
      "name": "Soil_Ash"
    },
    {
      "x": -4,
      "y": 1,
      "z": -5,
      "name": "Soil_Ash"
    },
    {
      "x": -4,
      "y": 2,
      "z": -5,
      "name": "Soil_Ash"
    },
    {
      "x": -4,
      "y": 3,
      "z": -5,
      "name": "Soil_Ash"
    },
    {
      "x": -4,
      "y": 4,
      "z": -5,
      "name": "Soil_Ash"
    },
    {
      "x": -4,
      "y": 5,
      "z": -5,
      "name": "Soil_Sand_Ashen"
    },
    {
      "x": -4,
      "y": 0,
      "z": -4,
      "name": "Soil_Ash"
    },
    {
      "x": -4,
      "y": 1,
      "z": -4,
      "name": "Soil_Ash"
    },
    {
      "x": -4,
      "y": 2,
      "z": -4,
      "name": "Soil_Ash"
    },
    {
      "x": -4,
      "y": 3,
      "z": -4,
      "name": "Soil_Ash"
    },
    {
      "x": -4,
      "y": 4,
      "z": -4,
      "name": "Soil_Ash"
    },
    {
      "x": -4,
      "y": 5,
      "z": -4,
      "name": "Soil_Ash"
    },
    {
      "x": -4,
      "y": 6,
      "z": -4,
      "name": "Soil_Ash"
    },
    {
      "x": -4,
      "y": 10,
      "z": -4,
      "name": "Rock_Magma_Cooled",
      "rotation": 1
    },
    {
      "x": -4,
      "y": 11,
      "z": -4,
      "name": "Rock_Magma_Cooled",
      "rotation": 1
    },
    {
      "x": -4,
      "y": 12,
      "z": -4,
      "name": "Ore_Adamantite_Magma_Cracked",
      "rotation": 1
    },
    {
      "x": -4,
      "y": 0,
      "z": -3,
      "name": "Soil_Ash"
    },
    {
      "x": -4,
      "y": 1,
      "z": -3,
      "name": "Soil_Ash"
    },
    {
      "x": -4,
      "y": 2,
      "z": -3,
      "name": "Soil_Ash"
    },
    {
      "x": -4,
      "y": 3,
      "z": -3,
      "name": "Soil_Ash"
    },
    {
      "x": -4,
      "y": 4,
      "z": -3,
      "name": "Soil_Ash"
    },
    {
      "x": -4,
      "y": 5,
      "z": -3,
      "name": "Soil_Ash"
    },
    {
      "x": -4,
      "y": 6,
      "z": -3,
      "name": "Soil_Ash"
    },
    {
      "x": -4,
      "y": 9,
      "z": -3,
      "name": "Ore_Adamantite_Magma_Cracked",
      "rotation": 1
    },
    {
      "x": -4,
      "y": 10,
      "z": -3,
      "name": "Rock_Magma_Cooled",
      "rotation": 1
    },
    {
      "x": -4,
      "y": 11,
      "z": -3,
      "name": "Rock_Magma_Cooled",
      "rotation": 1
    },
    {
      "x": -4,
      "y": 12,
      "z": -3,
      "name": "Rock_Magma_Cooled",
      "rotation": 1
    },
    {
      "x": -4,
      "y": 13,
      "z": -3,
      "name": "Rock_Magma_Cooled",
      "rotation": 1
    },
    {
      "x": -4,
      "y": 0,
      "z": -2,
      "name": "Soil_Ash"
    },
    {
      "x": -4,
      "y": 1,
      "z": -2,
      "name": "Soil_Ash"
    },
    {
      "x": -4,
      "y": 2,
      "z": -2,
      "name": "Soil_Ash"
    },
    {
      "x": -4,
      "y": 3,
      "z": -2,
      "name": "Soil_Ash"
    },
    {
      "x": -4,
      "y": 4,
      "z": -2,
      "name": "Soil_Ash"
    },
    {
      "x": -4,
      "y": 5,
      "z": -2,
      "name": "Soil_Ash"
    },
    {
      "x": -4,
      "y": 6,
      "z": -2,
      "name": "Soil_Ash"
    },
    {
      "x": -4,
      "y": 9,
      "z": -2,
      "name": "Rock_Magma_Cooled",
      "rotation": 1
    },
    {
      "x": -4,
      "y": 10,
      "z": -2,
      "name": "Rock_Magma_Cooled",
      "rotation": 1
    },
    {
      "x": -4,
      "y": 11,
      "z": -2,
      "name": "Rock_Magma_Cooled",
      "rotation": 1
    },
    {
      "x": -4,
      "y": 0,
      "z": -1,
      "name": "Soil_Ash"
    },
    {
      "x": -4,
      "y": 1,
      "z": -1,
      "name": "Soil_Ash"
    },
    {
      "x": -4,
      "y": 2,
      "z": -1,
      "name": "Soil_Ash"
    },
    {
      "x": -4,
      "y": 3,
      "z": -1,
      "name": "Soil_Ash"
    },
    {
      "x": -4,
      "y": 4,
      "z": -1,
      "name": "Soil_Ash"
    },
    {
      "x": -4,
      "y": 5,
      "z": -1,
      "name": "Soil_Ash"
    },
    {
      "x": -4,
      "y": 6,
      "z": -1,
      "name": "Soil_Ash"
    },
    {
      "x": -4,
      "y": 0,
      "z": 0,
      "name": "Soil_Ash"
    },
    {
      "x": -4,
      "y": 1,
      "z": 0,
      "name": "Soil_Ash"
    },
    {
      "x": -4,
      "y": 2,
      "z": 0,
      "name": "Soil_Ash"
    },
    {
      "x": -4,
      "y": 3,
      "z": 0,
      "name": "Soil_Ash"
    },
    {
      "x": -4,
      "y": 4,
      "z": 0,
      "name": "Soil_Ash"
    },
    {
      "x": -4,
      "y": 5,
      "z": 0,
      "name": "Soil_Ash"
    },
    {
      "x": -4,
      "y": 0,
      "z": 1,
      "name": "Soil_Ash"
    },
    {
      "x": -4,
      "y": 1,
      "z": 1,
      "name": "Soil_Ash"
    },
    {
      "x": -4,
      "y": 2,
      "z": 1,
      "name": "Soil_Ash"
    },
    {
      "x": -4,
      "y": 3,
      "z": 1,
      "name": "Soil_Ash"
    },
    {
      "x": -4,
      "y": 4,
      "z": 1,
      "name": "Soil_Ash"
    },
    {
      "x": -4,
      "y": 5,
      "z": 1,
      "name": "Soil_Ash"
    },
    {
      "x": -4,
      "y": 6,
      "z": 1,
      "name": "Plant_Bramble_Dead_Twisted"
    },
    {
      "x": -4,
      "y": 0,
      "z": 2,
      "name": "Soil_Ash"
    },
    {
      "x": -4,
      "y": 1,
      "z": 2,
      "name": "Soil_Ash"
    },
    {
      "x": -4,
      "y": 2,
      "z": 2,
      "name": "Soil_Ash"
    },
    {
      "x": -4,
      "y": 3,
      "z": 2,
      "name": "Soil_Ash"
    },
    {
      "x": -4,
      "y": 4,
      "z": 2,
      "name": "Soil_Ash"
    },
    {
      "x": -4,
      "y": 5,
      "z": 2,
      "name": "Plant_Bramble_Dead_Twisted"
    },
    {
      "x": -4,
      "y": 0,
      "z": 3,
      "name": "Soil_Ash"
    },
    {
      "x": -4,
      "y": 1,
      "z": 3,
      "name": "Soil_Ash"
    },
    {
      "x": -4,
      "y": 2,
      "z": 3,
      "name": "Soil_Ash"
    },
    {
      "x": -4,
      "y": 3,
      "z": 3,
      "name": "Soil_Ash"
    },
    {
      "x": -4,
      "y": 4,
      "z": 3,
      "name": "Soil_Ash"
    },
    {
      "x": -4,
      "y": 0,
      "z": 4,
      "name": "Soil_Ash"
    },
    {
      "x": -4,
      "y": 1,
      "z": 4,
      "name": "Soil_Ash"
    },
    {
      "x": -4,
      "y": 2,
      "z": 4,
      "name": "Soil_Ash"
    },
    {
      "x": -4,
      "y": 3,
      "z": 4,
      "name": "Soil_Ash"
    },
    {
      "x": -4,
      "y": 4,
      "z": 4,
      "name": "Soil_Ash"
    },
    {
      "x": -4,
      "y": 0,
      "z": 5,
      "name": "Soil_Ash"
    },
    {
      "x": -4,
      "y": 1,
      "z": 5,
      "name": "Soil_Ash"
    },
    {
      "x": -4,
      "y": 2,
      "z": 5,
      "name": "Soil_Ash"
    },
    {
      "x": -4,
      "y": 3,
      "z": 5,
      "name": "Soil_Ash"
    },
    {
      "x": -4,
      "y": 4,
      "z": 5,
      "name": "Soil_Ash"
    },
    {
      "x": -4,
      "y": 5,
      "z": 5,
      "name": "Soil_Ash"
    },
    {
      "x": -4,
      "y": 0,
      "z": 6,
      "name": "Soil_Ash"
    },
    {
      "x": -4,
      "y": 1,
      "z": 6,
      "name": "Soil_Ash"
    },
    {
      "x": -4,
      "y": 2,
      "z": 6,
      "name": "Soil_Ash"
    },
    {
      "x": -4,
      "y": 3,
      "z": 6,
      "name": "Soil_Ash"
    },
    {
      "x": -4,
      "y": 4,
      "z": 6,
      "name": "Soil_Ash"
    },
    {
      "x": -4,
      "y": 5,
      "z": 6,
      "name": "Soil_Ash"
    },
    {
      "x": -4,
      "y": 0,
      "z": 7,
      "name": "Soil_Ash"
    },
    {
      "x": -4,
      "y": 1,
      "z": 7,
      "name": "Soil_Ash"
    },
    {
      "x": -4,
      "y": 2,
      "z": 7,
      "name": "Soil_Ash"
    },
    {
      "x": -4,
      "y": 3,
      "z": 7,
      "name": "Soil_Ash"
    },
    {
      "x": -4,
      "y": 4,
      "z": 7,
      "name": "Soil_Ash"
    },
    {
      "x": -4,
      "y": 5,
      "z": 7,
      "name": "Soil_Ash"
    },
    {
      "x": -4,
      "y": 6,
      "z": 7,
      "name": "Plant_Flower_Bushy_Violet"
    },
    {
      "x": -4,
      "y": 0,
      "z": 8,
      "name": "Soil_Ash"
    },
    {
      "x": -4,
      "y": 1,
      "z": 8,
      "name": "Soil_Ash"
    },
    {
      "x": -4,
      "y": 2,
      "z": 8,
      "name": "Soil_Ash"
    },
    {
      "x": -4,
      "y": 3,
      "z": 8,
      "name": "Soil_Ash"
    },
    {
      "x": -4,
      "y": 4,
      "z": 8,
      "name": "Soil_Ash"
    },
    {
      "x": -4,
      "y": 5,
      "z": 8,
      "name": "Soil_Ash"
    },
    {
      "x": -4,
      "y": 6,
      "z": 8,
      "name": "Plant_Flower_Bushy_Poisoned"
    },
    {
      "x": -4,
      "y": 0,
      "z": 9,
      "name": "Soil_Ash"
    },
    {
      "x": -4,
      "y": 1,
      "z": 9,
      "name": "Soil_Ash"
    },
    {
      "x": -4,
      "y": 2,
      "z": 9,
      "name": "Soil_Ash"
    },
    {
      "x": -4,
      "y": 3,
      "z": 9,
      "name": "Soil_Ash"
    },
    {
      "x": -4,
      "y": 4,
      "z": 9,
      "name": "Soil_Ash"
    },
    {
      "x": -4,
      "y": 5,
      "z": 9,
      "name": "Soil_Ash"
    },
    {
      "x": -4,
      "y": 0,
      "z": 10,
      "name": "Soil_Ash"
    },
    {
      "x": -4,
      "y": 1,
      "z": 10,
      "name": "Soil_Ash"
    },
    {
      "x": -4,
      "y": 2,
      "z": 10,
      "name": "Soil_Ash"
    },
    {
      "x": -4,
      "y": 3,
      "z": 10,
      "name": "Soil_Ash"
    },
    {
      "x": -4,
      "y": 4,
      "z": 10,
      "name": "Soil_Sand_Ashen"
    },
    {
      "x": -4,
      "y": 0,
      "z": 11,
      "name": "Soil_Ash"
    },
    {
      "x": -4,
      "y": 1,
      "z": 11,
      "name": "Soil_Sand_Ashen"
    },
    {
      "x": -4,
      "y": 2,
      "z": 11,
      "name": "Soil_Sand_Ashen"
    },
    {
      "x": -4,
      "y": 0,
      "z": 12,
      "name": "Soil_Ash"
    },
    {
      "x": -3,
      "y": 0,
      "z": -10,
      "name": "Soil_Ash"
    },
    {
      "x": -3,
      "y": 0,
      "z": -9,
      "name": "Soil_Ash"
    },
    {
      "x": -3,
      "y": 1,
      "z": -9,
      "name": "Soil_Ash"
    },
    {
      "x": -3,
      "y": 0,
      "z": -8,
      "name": "Soil_Ash"
    },
    {
      "x": -3,
      "y": 1,
      "z": -8,
      "name": "Soil_Ash"
    },
    {
      "x": -3,
      "y": 2,
      "z": -8,
      "name": "Soil_Ash"
    },
    {
      "x": -3,
      "y": 0,
      "z": -7,
      "name": "Soil_Ash"
    },
    {
      "x": -3,
      "y": 1,
      "z": -7,
      "name": "Soil_Ash"
    },
    {
      "x": -3,
      "y": 2,
      "z": -7,
      "name": "Soil_Ash"
    },
    {
      "x": -3,
      "y": 3,
      "z": -7,
      "name": "Soil_Ash"
    },
    {
      "x": -3,
      "y": 0,
      "z": -6,
      "name": "Soil_Ash"
    },
    {
      "x": -3,
      "y": 1,
      "z": -6,
      "name": "Soil_Ash"
    },
    {
      "x": -3,
      "y": 2,
      "z": -6,
      "name": "Soil_Ash"
    },
    {
      "x": -3,
      "y": 3,
      "z": -6,
      "name": "Soil_Ash"
    },
    {
      "x": -3,
      "y": 4,
      "z": -6,
      "name": "Soil_Sand_Ashen"
    },
    {
      "x": -3,
      "y": 0,
      "z": -5,
      "name": "Soil_Ash"
    },
    {
      "x": -3,
      "y": 1,
      "z": -5,
      "name": "Soil_Ash"
    },
    {
      "x": -3,
      "y": 2,
      "z": -5,
      "name": "Soil_Ash"
    },
    {
      "x": -3,
      "y": 3,
      "z": -5,
      "name": "Soil_Ash"
    },
    {
      "x": -3,
      "y": 4,
      "z": -5,
      "name": "Soil_Ash"
    },
    {
      "x": -3,
      "y": 5,
      "z": -5,
      "name": "Soil_Ash"
    },
    {
      "x": -3,
      "y": 0,
      "z": -4,
      "name": "Soil_Ash"
    },
    {
      "x": -3,
      "y": 1,
      "z": -4,
      "name": "Soil_Ash"
    },
    {
      "x": -3,
      "y": 2,
      "z": -4,
      "name": "Soil_Ash"
    },
    {
      "x": -3,
      "y": 3,
      "z": -4,
      "name": "Soil_Ash"
    },
    {
      "x": -3,
      "y": 4,
      "z": -4,
      "name": "Soil_Ash"
    },
    {
      "x": -3,
      "y": 5,
      "z": -4,
      "name": "Soil_Ash"
    },
    {
      "x": -3,
      "y": 6,
      "z": -4,
      "name": "Plant_Flower_Poisoned_Orange"
    },
    {
      "x": -3,
      "y": 9,
      "z": -4,
      "name": "Ore_Adamantite_Magma_Cracked",
      "rotation": 1
    },
    {
      "x": -3,
      "y": 10,
      "z": -4,
      "name": "Ore_Adamantite_Magma_Cracked",
      "rotation": 1
    },
    {
      "x": -3,
      "y": 11,
      "z": -4,
      "name": "Rock_Magma_Cooled",
      "rotation": 1
    },
    {
      "x": -3,
      "y": 12,
      "z": -4,
      "name": "Rock_Magma_Cooled",
      "rotation": 1
    },
    {
      "x": -3,
      "y": 0,
      "z": -3,
      "name": "Soil_Ash"
    },
    {
      "x": -3,
      "y": 1,
      "z": -3,
      "name": "Soil_Ash"
    },
    {
      "x": -3,
      "y": 2,
      "z": -3,
      "name": "Soil_Ash"
    },
    {
      "x": -3,
      "y": 3,
      "z": -3,
      "name": "Soil_Ash"
    },
    {
      "x": -3,
      "y": 4,
      "z": -3,
      "name": "Soil_Ash"
    },
    {
      "x": -3,
      "y": 5,
      "z": -3,
      "name": "Soil_Ash"
    },
    {
      "x": -3,
      "y": 6,
      "z": -3,
      "name": "Soil_Ash"
    },
    {
      "x": -3,
      "y": 8,
      "z": -3,
      "name": "Rock_Magma_Cooled",
      "rotation": 1
    },
    {
      "x": -3,
      "y": 9,
      "z": -3,
      "name": "Rock_Magma_Cooled",
      "rotation": 1
    },
    {
      "x": -3,
      "y": 10,
      "z": -3,
      "name": "Ore_Adamantite_Magma_Cracked",
      "rotation": 1
    },
    {
      "x": -3,
      "y": 11,
      "z": -3,
      "name": "Rock_Magma_Cooled",
      "rotation": 1
    },
    {
      "x": -3,
      "y": 12,
      "z": -3,
      "name": "Rock_Magma_Cooled",
      "rotation": 1
    },
    {
      "x": -3,
      "y": 0,
      "z": -2,
      "name": "Soil_Ash"
    },
    {
      "x": -3,
      "y": 1,
      "z": -2,
      "name": "Soil_Ash"
    },
    {
      "x": -3,
      "y": 2,
      "z": -2,
      "name": "Soil_Ash"
    },
    {
      "x": -3,
      "y": 3,
      "z": -2,
      "name": "Soil_Ash"
    },
    {
      "x": -3,
      "y": 4,
      "z": -2,
      "name": "Soil_Ash"
    },
    {
      "x": -3,
      "y": 5,
      "z": -2,
      "name": "Soil_Ash"
    },
    {
      "x": -3,
      "y": 6,
      "z": -2,
      "name": "Soil_Ash"
    },
    {
      "x": -3,
      "y": 8,
      "z": -2,
      "name": "Ore_Adamantite_Magma",
      "rotation": 1
    },
    {
      "x": -3,
      "y": 9,
      "z": -2,
      "name": "Rock_Magma_Cooled",
      "rotation": 1
    },
    {
      "x": -3,
      "y": 10,
      "z": -2,
      "name": "Rock_Magma_Cooled",
      "rotation": 1
    },
    {
      "x": -3,
      "y": 11,
      "z": -2,
      "name": "Rock_Magma_Cooled",
      "rotation": 1
    },
    {
      "x": -3,
      "y": 0,
      "z": -1,
      "name": "Soil_Ash"
    },
    {
      "x": -3,
      "y": 1,
      "z": -1,
      "name": "Soil_Ash"
    },
    {
      "x": -3,
      "y": 2,
      "z": -1,
      "name": "Soil_Ash"
    },
    {
      "x": -3,
      "y": 3,
      "z": -1,
      "name": "Soil_Ash"
    },
    {
      "x": -3,
      "y": 4,
      "z": -1,
      "name": "Soil_Ash"
    },
    {
      "x": -3,
      "y": 5,
      "z": -1,
      "name": "Soil_Ash"
    },
    {
      "x": -3,
      "y": 6,
      "z": -1,
      "name": "Soil_Sand_Ashen"
    },
    {
      "x": -3,
      "y": 7,
      "z": -1,
      "name": "Plant_Bramble_Dead_Twisted"
    },
    {
      "x": -3,
      "y": 8,
      "z": -1,
      "name": "Ore_Adamantite_Magma_Cracked",
      "rotation": 1
    },
    {
      "x": -3,
      "y": 9,
      "z": -1,
      "name": "Rock_Magma_Cooled",
      "rotation": 1
    },
    {
      "x": -3,
      "y": 0,
      "z": 0,
      "name": "Soil_Ash"
    },
    {
      "x": -3,
      "y": 1,
      "z": 0,
      "name": "Soil_Ash"
    },
    {
      "x": -3,
      "y": 2,
      "z": 0,
      "name": "Soil_Ash"
    },
    {
      "x": -3,
      "y": 3,
      "z": 0,
      "name": "Soil_Ash"
    },
    {
      "x": -3,
      "y": 4,
      "z": 0,
      "name": "Soil_Ash"
    },
    {
      "x": -3,
      "y": 5,
      "z": 0,
      "name": "Soil_Ash"
    },
    {
      "x": -3,
      "y": 6,
      "z": 0,
      "name": "Plant_Bramble_Dead_Twisted"
    },
    {
      "x": -3,
      "y": 0,
      "z": 1,
      "name": "Soil_Ash"
    },
    {
      "x": -3,
      "y": 1,
      "z": 1,
      "name": "Soil_Ash"
    },
    {
      "x": -3,
      "y": 2,
      "z": 1,
      "name": "Soil_Ash"
    },
    {
      "x": -3,
      "y": 3,
      "z": 1,
      "name": "Soil_Ash"
    },
    {
      "x": -3,
      "y": 4,
      "z": 1,
      "name": "Soil_Ash"
    },
    {
      "x": -3,
      "y": 5,
      "z": 1,
      "name": "Soil_Ash"
    },
    {
      "x": -3,
      "y": 6,
      "z": 1,
      "name": "Plant_Bramble_Dead_Twisted"
    },
    {
      "x": -3,
      "y": 0,
      "z": 2,
      "name": "Soil_Ash"
    },
    {
      "x": -3,
      "y": 1,
      "z": 2,
      "name": "Soil_Ash"
    },
    {
      "x": -3,
      "y": 2,
      "z": 2,
      "name": "Soil_Ash"
    },
    {
      "x": -3,
      "y": 3,
      "z": 2,
      "name": "Soil_Ash"
    },
    {
      "x": -3,
      "y": 4,
      "z": 2,
      "name": "Soil_Ash"
    },
    {
      "x": -3,
      "y": 5,
      "z": 2,
      "name": "Soil_Ash"
    },
    {
      "x": -3,
      "y": 0,
      "z": 3,
      "name": "Soil_Ash"
    },
    {
      "x": -3,
      "y": 1,
      "z": 3,
      "name": "Soil_Ash"
    },
    {
      "x": -3,
      "y": 2,
      "z": 3,
      "name": "Soil_Ash"
    },
    {
      "x": -3,
      "y": 3,
      "z": 3,
      "name": "Soil_Ash"
    },
    {
      "x": -3,
      "y": 4,
      "z": 3,
      "name": "Soil_Ash"
    },
    {
      "x": -3,
      "y": 5,
      "z": 3,
      "name": "Plant_Flower_Bushy_Poisoned"
    },
    {
      "x": -3,
      "y": 0,
      "z": 4,
      "name": "Soil_Ash"
    },
    {
      "x": -3,
      "y": 1,
      "z": 4,
      "name": "Soil_Ash"
    },
    {
      "x": -3,
      "y": 2,
      "z": 4,
      "name": "Soil_Ash"
    },
    {
      "x": -3,
      "y": 3,
      "z": 4,
      "name": "Soil_Ash"
    },
    {
      "x": -3,
      "y": 4,
      "z": 4,
      "name": "Soil_Ash"
    },
    {
      "x": -3,
      "y": 0,
      "z": 5,
      "name": "Soil_Ash"
    },
    {
      "x": -3,
      "y": 1,
      "z": 5,
      "name": "Soil_Ash"
    },
    {
      "x": -3,
      "y": 2,
      "z": 5,
      "name": "Soil_Ash"
    },
    {
      "x": -3,
      "y": 3,
      "z": 5,
      "name": "Soil_Ash"
    },
    {
      "x": -3,
      "y": 4,
      "z": 5,
      "name": "Soil_Ash"
    },
    {
      "x": -3,
      "y": 5,
      "z": 5,
      "name": "Soil_Ash"
    },
    {
      "x": -3,
      "y": 0,
      "z": 6,
      "name": "Soil_Ash"
    },
    {
      "x": -3,
      "y": 1,
      "z": 6,
      "name": "Soil_Ash"
    },
    {
      "x": -3,
      "y": 2,
      "z": 6,
      "name": "Soil_Ash"
    },
    {
      "x": -3,
      "y": 3,
      "z": 6,
      "name": "Soil_Ash"
    },
    {
      "x": -3,
      "y": 4,
      "z": 6,
      "name": "Soil_Ash"
    },
    {
      "x": -3,
      "y": 5,
      "z": 6,
      "name": "Soil_Ash"
    },
    {
      "x": -3,
      "y": 6,
      "z": 6,
      "name": "Soil_Ash"
    },
    {
      "x": -3,
      "y": 0,
      "z": 7,
      "name": "Soil_Ash"
    },
    {
      "x": -3,
      "y": 1,
      "z": 7,
      "name": "Soil_Ash"
    },
    {
      "x": -3,
      "y": 2,
      "z": 7,
      "name": "Soil_Ash"
    },
    {
      "x": -3,
      "y": 3,
      "z": 7,
      "name": "Soil_Ash"
    },
    {
      "x": -3,
      "y": 4,
      "z": 7,
      "name": "Soil_Ash"
    },
    {
      "x": -3,
      "y": 5,
      "z": 7,
      "name": "Soil_Ash"
    },
    {
      "x": -3,
      "y": 6,
      "z": 7,
      "name": "Soil_Ash"
    },
    {
      "x": -3,
      "y": 7,
      "z": 7,
      "name": "Plant_Flower_Bushy_Violet"
    },
    {
      "x": -3,
      "y": 0,
      "z": 8,
      "name": "Soil_Ash"
    },
    {
      "x": -3,
      "y": 1,
      "z": 8,
      "name": "Soil_Ash"
    },
    {
      "x": -3,
      "y": 2,
      "z": 8,
      "name": "Soil_Ash"
    },
    {
      "x": -3,
      "y": 3,
      "z": 8,
      "name": "Soil_Ash"
    },
    {
      "x": -3,
      "y": 4,
      "z": 8,
      "name": "Soil_Ash"
    },
    {
      "x": -3,
      "y": 5,
      "z": 8,
      "name": "Soil_Ash"
    },
    {
      "x": -3,
      "y": 6,
      "z": 8,
      "name": "Soil_Ash"
    },
    {
      "x": -3,
      "y": 16,
      "z": 8,
      "name": "Plant_Vine_Wall_Poisoned",
      "support": 15,
      "rotation": 3
    },
    {
      "x": -3,
      "y": 19,
      "z": 8,
      "name": "Plant_Vine_Wall_Poisoned",
      "support": 15,
      "rotation": 3
    },
    {
      "x": -3,
      "y": 0,
      "z": 9,
      "name": "Soil_Ash"
    },
    {
      "x": -3,
      "y": 1,
      "z": 9,
      "name": "Soil_Ash"
    },
    {
      "x": -3,
      "y": 2,
      "z": 9,
      "name": "Soil_Ash"
    },
    {
      "x": -3,
      "y": 3,
      "z": 9,
      "name": "Soil_Ash"
    },
    {
      "x": -3,
      "y": 4,
      "z": 9,
      "name": "Soil_Ash"
    },
    {
      "x": -3,
      "y": 5,
      "z": 9,
      "name": "Soil_Ash"
    },
    {
      "x": -3,
      "y": 6,
      "z": 9,
      "name": "Plant_Flower_Bushy_Violet"
    },
    {
      "x": -3,
      "y": 19,
      "z": 9,
      "name": "Plant_Vine_Wall_Poisoned",
      "support": 15,
      "rotation": 3
    },
    {
      "x": -3,
      "y": 0,
      "z": 10,
      "name": "Soil_Ash"
    },
    {
      "x": -3,
      "y": 1,
      "z": 10,
      "name": "Soil_Ash"
    },
    {
      "x": -3,
      "y": 2,
      "z": 10,
      "name": "Soil_Ash"
    },
    {
      "x": -3,
      "y": 3,
      "z": 10,
      "name": "Soil_Ash"
    },
    {
      "x": -3,
      "y": 4,
      "z": 10,
      "name": "Soil_Ash"
    },
    {
      "x": -3,
      "y": 5,
      "z": 10,
      "name": "Soil_Ash"
    },
    {
      "x": -3,
      "y": 20,
      "z": 10,
      "name": "Plant_Vine_Wall_Poisoned",
      "support": 15,
      "rotation": 3
    },
    {
      "x": -3,
      "y": 21,
      "z": 10,
      "name": "Rock_Magma_Cooled",
      "rotation": 1
    },
    {
      "x": -3,
      "y": 22,
      "z": 10,
      "name": "Rock_Magma_Cooled",
      "rotation": 1
    },
    {
      "x": -3,
      "y": 23,
      "z": 10,
      "name": "Rock_Magma_Cooled",
      "rotation": 1
    },
    {
      "x": -3,
      "y": 24,
      "z": 10,
      "name": "Ore_Adamantite_Magma_Cracked",
      "rotation": 1
    },
    {
      "x": -3,
      "y": 25,
      "z": 10,
      "name": "Plant_Moss_Rug_Pink",
      "support": 15
    },
    {
      "x": -3,
      "y": 0,
      "z": 11,
      "name": "Soil_Sand_Ashen"
    },
    {
      "x": -3,
      "y": 1,
      "z": 11,
      "name": "Soil_Ash"
    },
    {
      "x": -3,
      "y": 2,
      "z": 11,
      "name": "Soil_Ash"
    },
    {
      "x": -3,
      "y": 3,
      "z": 11,
      "name": "Soil_Ash"
    },
    {
      "x": -3,
      "y": 0,
      "z": 12,
      "name": "Soil_Sand_Ashen"
    },
    {
      "x": -3,
      "y": 1,
      "z": 12,
      "name": "Soil_Sand_Ashen"
    },
    {
      "x": -2,
      "y": 0,
      "z": -10,
      "name": "Soil_Sand_Ashen"
    },
    {
      "x": -2,
      "y": 0,
      "z": -9,
      "name": "Soil_Ash"
    },
    {
      "x": -2,
      "y": 1,
      "z": -9,
      "name": "Soil_Ash"
    },
    {
      "x": -2,
      "y": 0,
      "z": -8,
      "name": "Soil_Ash"
    },
    {
      "x": -2,
      "y": 1,
      "z": -8,
      "name": "Soil_Ash"
    },
    {
      "x": -2,
      "y": 0,
      "z": -7,
      "name": "Soil_Ash"
    },
    {
      "x": -2,
      "y": 1,
      "z": -7,
      "name": "Soil_Ash"
    },
    {
      "x": -2,
      "y": 2,
      "z": -7,
      "name": "Soil_Ash"
    },
    {
      "x": -2,
      "y": 21,
      "z": -7,
      "name": "Rock_Magma_Cooled",
      "rotation": 1
    },
    {
      "x": -2,
      "y": 22,
      "z": -7,
      "name": "Rock_Magma_Cooled",
      "rotation": 1
    },
    {
      "x": -2,
      "y": 23,
      "z": -7,
      "name": "Rock_Magma_Cooled",
      "rotation": 1
    },
    {
      "x": -2,
      "y": 24,
      "z": -7,
      "name": "Rock_Magma_Cooled",
      "rotation": 1
    },
    {
      "x": -2,
      "y": 25,
      "z": -7,
      "name": "Plant_Moss_Rug_Pink",
      "support": 15
    },
    {
      "x": -2,
      "y": 0,
      "z": -6,
      "name": "Soil_Ash"
    },
    {
      "x": -2,
      "y": 1,
      "z": -6,
      "name": "Soil_Ash"
    },
    {
      "x": -2,
      "y": 2,
      "z": -6,
      "name": "Soil_Ash"
    },
    {
      "x": -2,
      "y": 3,
      "z": -6,
      "name": "Soil_Ash"
    },
    {
      "x": -2,
      "y": 19,
      "z": -6,
      "name": "Rock_Magma_Cooled",
      "rotation": 1
    },
    {
      "x": -2,
      "y": 20,
      "z": -6,
      "name": "Rock_Magma_Cooled",
      "rotation": 1
    },
    {
      "x": -2,
      "y": 21,
      "z": -6,
      "name": "Rock_Magma_Cooled",
      "rotation": 1
    },
    {
      "x": -2,
      "y": 22,
      "z": -6,
      "name": "Rock_Magma_Cooled",
      "rotation": 1
    },
    {
      "x": -2,
      "y": 23,
      "z": -6,
      "name": "Plant_Moss_Rug_Pink",
      "support": 15
    },
    {
      "x": -2,
      "y": 0,
      "z": -5,
      "name": "Soil_Ash"
    },
    {
      "x": -2,
      "y": 1,
      "z": -5,
      "name": "Soil_Ash"
    },
    {
      "x": -2,
      "y": 2,
      "z": -5,
      "name": "Soil_Ash"
    },
    {
      "x": -2,
      "y": 3,
      "z": -5,
      "name": "Soil_Ash"
    },
    {
      "x": -2,
      "y": 4,
      "z": -5,
      "name": "Soil_Sand_Ashen"
    },
    {
      "x": -2,
      "y": 5,
      "z": -5,
      "name": "Plant_Flower_Bushy_Violet"
    },
    {
      "x": -2,
      "y": 0,
      "z": -4,
      "name": "Soil_Ash"
    },
    {
      "x": -2,
      "y": 1,
      "z": -4,
      "name": "Soil_Ash"
    },
    {
      "x": -2,
      "y": 2,
      "z": -4,
      "name": "Soil_Ash"
    },
    {
      "x": -2,
      "y": 3,
      "z": -4,
      "name": "Soil_Ash"
    },
    {
      "x": -2,
      "y": 4,
      "z": -4,
      "name": "Soil_Ash"
    },
    {
      "x": -2,
      "y": 5,
      "z": -4,
      "name": "Soil_Sand_Ashen"
    },
    {
      "x": -2,
      "y": 15,
      "z": -4,
      "name": "Plant_Vine_Wall_Poisoned",
      "support": 15,
      "rotation": 3
    },
    {
      "x": -2,
      "y": 16,
      "z": -4,
      "name": "Plant_Vine_Wall_Poisoned",
      "support": 15,
      "rotation": 3
    },
    {
      "x": -2,
      "y": 0,
      "z": -3,
      "name": "Soil_Ash"
    },
    {
      "x": -2,
      "y": 1,
      "z": -3,
      "name": "Soil_Ash"
    },
    {
      "x": -2,
      "y": 2,
      "z": -3,
      "name": "Soil_Ash"
    },
    {
      "x": -2,
      "y": 3,
      "z": -3,
      "name": "Soil_Ash"
    },
    {
      "x": -2,
      "y": 4,
      "z": -3,
      "name": "Soil_Ash"
    },
    {
      "x": -2,
      "y": 5,
      "z": -3,
      "name": "Soil_Sand_Ashen"
    },
    {
      "x": -2,
      "y": 8,
      "z": -3,
      "name": "Rock_Magma_Cooled",
      "rotation": 1
    },
    {
      "x": -2,
      "y": 9,
      "z": -3,
      "name": "Rock_Magma_Cooled",
      "rotation": 1
    },
    {
      "x": -2,
      "y": 10,
      "z": -3,
      "name": "Rock_Magma_Cooled",
      "rotation": 1
    },
    {
      "x": -2,
      "y": 16,
      "z": -3,
      "name": "Plant_Vine_Wall_Poisoned",
      "support": 15,
      "rotation": 3
    },
    {
      "x": -2,
      "y": 0,
      "z": -2,
      "name": "Soil_Ash"
    },
    {
      "x": -2,
      "y": 1,
      "z": -2,
      "name": "Soil_Ash"
    },
    {
      "x": -2,
      "y": 2,
      "z": -2,
      "name": "Soil_Ash"
    },
    {
      "x": -2,
      "y": 3,
      "z": -2,
      "name": "Soil_Ash"
    },
    {
      "x": -2,
      "y": 4,
      "z": -2,
      "name": "Soil_Ash"
    },
    {
      "x": -2,
      "y": 5,
      "z": -2,
      "name": "Soil_Ash"
    },
    {
      "x": -2,
      "y": 7,
      "z": -2,
      "name": "Rock_Magma_Cooled",
      "rotation": 1
    },
    {
      "x": -2,
      "y": 8,
      "z": -2,
      "name": "Rock_Magma_Cooled",
      "rotation": 1
    },
    {
      "x": -2,
      "y": 9,
      "z": -2,
      "name": "Rock_Magma_Cooled",
      "rotation": 1
    },
    {
      "x": -2,
      "y": 0,
      "z": -1,
      "name": "Soil_Ash"
    },
    {
      "x": -2,
      "y": 1,
      "z": -1,
      "name": "Soil_Ash"
    },
    {
      "x": -2,
      "y": 2,
      "z": -1,
      "name": "Soil_Ash"
    },
    {
      "x": -2,
      "y": 3,
      "z": -1,
      "name": "Soil_Ash"
    },
    {
      "x": -2,
      "y": 4,
      "z": -1,
      "name": "Soil_Ash"
    },
    {
      "x": -2,
      "y": 5,
      "z": -1,
      "name": "Soil_Ash"
    },
    {
      "x": -2,
      "y": 6,
      "z": -1,
      "name": "Rock_Magma_Cooled",
      "rotation": 1
    },
    {
      "x": -2,
      "y": 7,
      "z": -1,
      "name": "Rock_Magma_Cooled",
      "rotation": 1
    },
    {
      "x": -2,
      "y": 8,
      "z": -1,
      "name": "Ore_Adamantite_Magma_Cracked",
      "rotation": 1
    },
    {
      "x": -2,
      "y": 9,
      "z": -1,
      "name": "Rock_Magma_Cooled",
      "rotation": 1
    },
    {
      "x": -2,
      "y": 0,
      "z": 0,
      "name": "Soil_Ash"
    },
    {
      "x": -2,
      "y": 1,
      "z": 0,
      "name": "Soil_Ash"
    },
    {
      "x": -2,
      "y": 2,
      "z": 0,
      "name": "Soil_Ash"
    },
    {
      "x": -2,
      "y": 3,
      "z": 0,
      "name": "Soil_Ash"
    },
    {
      "x": -2,
      "y": 4,
      "z": 0,
      "name": "Soil_Ash"
    },
    {
      "x": -2,
      "y": 5,
      "z": 0,
      "name": "Soil_Ash"
    },
    {
      "x": -2,
      "y": 7,
      "z": 0,
      "name": "Ore_Adamantite_Magma_Cracked",
      "rotation": 1
    },
    {
      "x": -2,
      "y": 8,
      "z": 0,
      "name": "Rock_Magma_Cooled",
      "rotation": 1
    },
    {
      "x": -2,
      "y": 0,
      "z": 1,
      "name": "Soil_Ash"
    },
    {
      "x": -2,
      "y": 1,
      "z": 1,
      "name": "Soil_Ash"
    },
    {
      "x": -2,
      "y": 2,
      "z": 1,
      "name": "Soil_Ash"
    },
    {
      "x": -2,
      "y": 3,
      "z": 1,
      "name": "Soil_Ash"
    },
    {
      "x": -2,
      "y": 4,
      "z": 1,
      "name": "Soil_Ash"
    },
    {
      "x": -2,
      "y": 5,
      "z": 1,
      "name": "Soil_Ash"
    },
    {
      "x": -2,
      "y": 0,
      "z": 2,
      "name": "Soil_Ash"
    },
    {
      "x": -2,
      "y": 1,
      "z": 2,
      "name": "Soil_Ash"
    },
    {
      "x": -2,
      "y": 2,
      "z": 2,
      "name": "Soil_Ash"
    },
    {
      "x": -2,
      "y": 3,
      "z": 2,
      "name": "Soil_Ash"
    },
    {
      "x": -2,
      "y": 4,
      "z": 2,
      "name": "Soil_Ash"
    },
    {
      "x": -2,
      "y": 5,
      "z": 2,
      "name": "Soil_Ash"
    },
    {
      "x": -2,
      "y": 0,
      "z": 3,
      "name": "Soil_Ash"
    },
    {
      "x": -2,
      "y": 1,
      "z": 3,
      "name": "Soil_Ash"
    },
    {
      "x": -2,
      "y": 2,
      "z": 3,
      "name": "Soil_Ash"
    },
    {
      "x": -2,
      "y": 3,
      "z": 3,
      "name": "Soil_Ash"
    },
    {
      "x": -2,
      "y": 4,
      "z": 3,
      "name": "Soil_Ash"
    },
    {
      "x": -2,
      "y": 0,
      "z": 4,
      "name": "Soil_Ash"
    },
    {
      "x": -2,
      "y": 1,
      "z": 4,
      "name": "Soil_Ash"
    },
    {
      "x": -2,
      "y": 2,
      "z": 4,
      "name": "Soil_Ash"
    },
    {
      "x": -2,
      "y": 3,
      "z": 4,
      "name": "Soil_Ash"
    },
    {
      "x": -2,
      "y": 4,
      "z": 4,
      "name": "Soil_Ash"
    },
    {
      "x": -2,
      "y": 0,
      "z": 5,
      "name": "Soil_Ash"
    },
    {
      "x": -2,
      "y": 1,
      "z": 5,
      "name": "Soil_Ash"
    },
    {
      "x": -2,
      "y": 2,
      "z": 5,
      "name": "Soil_Ash"
    },
    {
      "x": -2,
      "y": 3,
      "z": 5,
      "name": "Soil_Ash"
    },
    {
      "x": -2,
      "y": 4,
      "z": 5,
      "name": "Soil_Ash"
    },
    {
      "x": -2,
      "y": 5,
      "z": 5,
      "name": "Soil_Ash"
    },
    {
      "x": -2,
      "y": 0,
      "z": 6,
      "name": "Soil_Ash"
    },
    {
      "x": -2,
      "y": 1,
      "z": 6,
      "name": "Soil_Ash"
    },
    {
      "x": -2,
      "y": 2,
      "z": 6,
      "name": "Soil_Ash"
    },
    {
      "x": -2,
      "y": 3,
      "z": 6,
      "name": "Soil_Ash"
    },
    {
      "x": -2,
      "y": 4,
      "z": 6,
      "name": "Soil_Ash"
    },
    {
      "x": -2,
      "y": 5,
      "z": 6,
      "name": "Soil_Ash"
    },
    {
      "x": -2,
      "y": 6,
      "z": 6,
      "name": "Soil_Ash"
    },
    {
      "x": -2,
      "y": 7,
      "z": 6,
      "name": "Plant_Flower_Bushy_Poisoned"
    },
    {
      "x": -2,
      "y": 0,
      "z": 7,
      "name": "Soil_Ash"
    },
    {
      "x": -2,
      "y": 1,
      "z": 7,
      "name": "Soil_Ash"
    },
    {
      "x": -2,
      "y": 2,
      "z": 7,
      "name": "Soil_Ash"
    },
    {
      "x": -2,
      "y": 3,
      "z": 7,
      "name": "Soil_Ash"
    },
    {
      "x": -2,
      "y": 4,
      "z": 7,
      "name": "Soil_Ash"
    },
    {
      "x": -2,
      "y": 5,
      "z": 7,
      "name": "Soil_Ash"
    },
    {
      "x": -2,
      "y": 6,
      "z": 7,
      "name": "Soil_Ash"
    },
    {
      "x": -2,
      "y": 7,
      "z": 7,
      "name": "Plant_Flower_Bushy_Poisoned"
    },
    {
      "x": -2,
      "y": 14,
      "z": 7,
      "name": "Rock_Magma_Cooled",
      "rotation": 1
    },
    {
      "x": -2,
      "y": 15,
      "z": 7,
      "name": "Rock_Magma_Cooled",
      "rotation": 1
    },
    {
      "x": -2,
      "y": 16,
      "z": 7,
      "name": "Rock_Magma_Cooled",
      "rotation": 1
    },
    {
      "x": -2,
      "y": 17,
      "z": 7,
      "name": "Rock_Magma_Cooled",
      "rotation": 1
    },
    {
      "x": -2,
      "y": 18,
      "z": 7,
      "name": "Plant_Moss_Rug_Pink",
      "support": 15
    },
    {
      "x": -2,
      "y": 0,
      "z": 8,
      "name": "Soil_Ash"
    },
    {
      "x": -2,
      "y": 1,
      "z": 8,
      "name": "Soil_Ash"
    },
    {
      "x": -2,
      "y": 2,
      "z": 8,
      "name": "Soil_Ash"
    },
    {
      "x": -2,
      "y": 3,
      "z": 8,
      "name": "Soil_Ash"
    },
    {
      "x": -2,
      "y": 4,
      "z": 8,
      "name": "Soil_Ash"
    },
    {
      "x": -2,
      "y": 5,
      "z": 8,
      "name": "Soil_Ash"
    },
    {
      "x": -2,
      "y": 6,
      "z": 8,
      "name": "Soil_Ash"
    },
    {
      "x": -2,
      "y": 15,
      "z": 8,
      "name": "Plant_Vine_Wall_Poisoned",
      "support": 15
    },
    {
      "x": -2,
      "y": 16,
      "z": 8,
      "name": "Rock_Magma_Cooled",
      "rotation": 1
    },
    {
      "x": -2,
      "y": 17,
      "z": 8,
      "name": "Rock_Magma_Cooled",
      "rotation": 1
    },
    {
      "x": -2,
      "y": 18,
      "z": 8,
      "name": "Rock_Magma_Cooled",
      "rotation": 1
    },
    {
      "x": -2,
      "y": 19,
      "z": 8,
      "name": "Rock_Magma_Cooled",
      "rotation": 1
    },
    {
      "x": -2,
      "y": 20,
      "z": 8,
      "name": "Plant_Moss_Rug_Pink",
      "support": 15
    },
    {
      "x": -2,
      "y": 0,
      "z": 9,
      "name": "Soil_Ash"
    },
    {
      "x": -2,
      "y": 1,
      "z": 9,
      "name": "Soil_Ash"
    },
    {
      "x": -2,
      "y": 2,
      "z": 9,
      "name": "Soil_Ash"
    },
    {
      "x": -2,
      "y": 3,
      "z": 9,
      "name": "Soil_Ash"
    },
    {
      "x": -2,
      "y": 4,
      "z": 9,
      "name": "Soil_Ash"
    },
    {
      "x": -2,
      "y": 5,
      "z": 9,
      "name": "Soil_Ash"
    },
    {
      "x": -2,
      "y": 6,
      "z": 9,
      "name": "Soil_Ash"
    },
    {
      "x": -2,
      "y": 17,
      "z": 9,
      "name": "Plant_Vine_Wall_Poisoned",
      "support": 15
    },
    {
      "x": -2,
      "y": 18,
      "z": 9,
      "name": "Rock_Magma_Cooled",
      "rotation": 1
    },
    {
      "x": -2,
      "y": 19,
      "z": 9,
      "name": "Rock_Magma_Cooled",
      "rotation": 1
    },
    {
      "x": -2,
      "y": 20,
      "z": 9,
      "name": "Rock_Magma_Cooled",
      "rotation": 1
    },
    {
      "x": -2,
      "y": 21,
      "z": 9,
      "name": "Rock_Magma_Cooled",
      "rotation": 1
    },
    {
      "x": -2,
      "y": 22,
      "z": 9,
      "name": "Plant_Moss_Rug_Pink",
      "support": 15
    },
    {
      "x": -2,
      "y": 0,
      "z": 10,
      "name": "Soil_Ash"
    },
    {
      "x": -2,
      "y": 1,
      "z": 10,
      "name": "Soil_Ash"
    },
    {
      "x": -2,
      "y": 2,
      "z": 10,
      "name": "Soil_Ash"
    },
    {
      "x": -2,
      "y": 3,
      "z": 10,
      "name": "Soil_Ash"
    },
    {
      "x": -2,
      "y": 4,
      "z": 10,
      "name": "Soil_Ash"
    },
    {
      "x": -2,
      "y": 5,
      "z": 10,
      "name": "Soil_Ash"
    },
    {
      "x": -2,
      "y": 20,
      "z": 10,
      "name": "Rock_Magma_Cooled",
      "rotation": 1
    },
    {
      "x": -2,
      "y": 21,
      "z": 10,
      "name": "Rock_Magma_Cooled",
      "rotation": 1
    },
    {
      "x": -2,
      "y": 22,
      "z": 10,
      "name": "Rock_Magma_Cooled",
      "rotation": 1
    },
    {
      "x": -2,
      "y": 23,
      "z": 10,
      "name": "Plant_Moss_Rug_Pink",
      "support": 15
    },
    {
      "x": -2,
      "y": 0,
      "z": 11,
      "name": "Soil_Ash"
    },
    {
      "x": -2,
      "y": 1,
      "z": 11,
      "name": "Soil_Sand_Ashen"
    },
    {
      "x": -2,
      "y": 2,
      "z": 11,
      "name": "Soil_Ash"
    },
    {
      "x": -2,
      "y": 3,
      "z": 11,
      "name": "Soil_Ash"
    },
    {
      "x": -2,
      "y": 0,
      "z": 12,
      "name": "Soil_Ash"
    },
    {
      "x": -2,
      "y": 1,
      "z": 12,
      "name": "Soil_Sand_Ashen"
    },
    {
      "x": -1,
      "y": 0,
      "z": -9,
      "name": "Soil_Sand_Ashen"
    },
    {
      "x": -1,
      "y": 0,
      "z": -8,
      "name": "Soil_Sand_Ashen"
    },
    {
      "x": -1,
      "y": 1,
      "z": -8,
      "name": "Soil_Ash"
    },
    {
      "x": -1,
      "y": 0,
      "z": -7,
      "name": "Soil_Ash"
    },
    {
      "x": -1,
      "y": 1,
      "z": -7,
      "name": "Soil_Ash"
    },
    {
      "x": -1,
      "y": 0,
      "z": -6,
      "name": "Soil_Ash"
    },
    {
      "x": -1,
      "y": 1,
      "z": -6,
      "name": "Soil_Ash"
    },
    {
      "x": -1,
      "y": 2,
      "z": -6,
      "name": "Soil_Ash"
    },
    {
      "x": -1,
      "y": 18,
      "z": -6,
      "name": "Rock_Magma_Cooled",
      "rotation": 1
    },
    {
      "x": -1,
      "y": 19,
      "z": -6,
      "name": "Rock_Magma_Cooled",
      "rotation": 1
    },
    {
      "x": -1,
      "y": 20,
      "z": -6,
      "name": "Ore_Adamantite_Magma_Cracked",
      "rotation": 1
    },
    {
      "x": -1,
      "y": 21,
      "z": -6,
      "name": "Rock_Magma_Cooled",
      "rotation": 1
    },
    {
      "x": -1,
      "y": 22,
      "z": -6,
      "name": "Plant_Moss_Rug_Pink",
      "support": 15
    },
    {
      "x": -1,
      "y": 0,
      "z": -5,
      "name": "Soil_Ash"
    },
    {
      "x": -1,
      "y": 1,
      "z": -5,
      "name": "Soil_Ash"
    },
    {
      "x": -1,
      "y": 2,
      "z": -5,
      "name": "Soil_Ash"
    },
    {
      "x": -1,
      "y": 3,
      "z": -5,
      "name": "Soil_Sand_Ashen"
    },
    {
      "x": -1,
      "y": 16,
      "z": -5,
      "name": "Plant_Vine_Wall_Poisoned",
      "support": 15,
      "rotation": 3
    },
    {
      "x": -1,
      "y": 17,
      "z": -5,
      "name": "Rock_Magma_Cooled",
      "rotation": 1
    },
    {
      "x": -1,
      "y": 18,
      "z": -5,
      "name": "Ore_Adamantite_Magma_Cracked",
      "rotation": 1
    },
    {
      "x": -1,
      "y": 19,
      "z": -5,
      "name": "Ore_Adamantite_Magma_Cracked",
      "rotation": 1
    },
    {
      "x": -1,
      "y": 20,
      "z": -5,
      "name": "Plant_Moss_Rug_Pink",
      "support": 15
    },
    {
      "x": -1,
      "y": 0,
      "z": -4,
      "name": "Soil_Ash"
    },
    {
      "x": -1,
      "y": 1,
      "z": -4,
      "name": "Soil_Ash"
    },
    {
      "x": -1,
      "y": 2,
      "z": -4,
      "name": "Soil_Ash"
    },
    {
      "x": -1,
      "y": 3,
      "z": -4,
      "name": "Soil_Ash"
    },
    {
      "x": -1,
      "y": 4,
      "z": -4,
      "name": "Plant_Flower_Bushy_Violet"
    },
    {
      "x": -1,
      "y": 15,
      "z": -4,
      "name": "Rock_Magma_Cooled",
      "rotation": 1
    },
    {
      "x": -1,
      "y": 16,
      "z": -4,
      "name": "Rock_Magma_Cooled",
      "rotation": 1
    },
    {
      "x": -1,
      "y": 17,
      "z": -4,
      "name": "Rock_Magma_Cooled",
      "rotation": 1
    },
    {
      "x": -1,
      "y": 18,
      "z": -4,
      "name": "Rock_Magma_Cooled",
      "rotation": 1
    },
    {
      "x": -1,
      "y": 19,
      "z": -4,
      "name": "Plant_Moss_Rug_Pink",
      "support": 15
    },
    {
      "x": -1,
      "y": 0,
      "z": -3,
      "name": "Soil_Ash"
    },
    {
      "x": -1,
      "y": 1,
      "z": -3,
      "name": "Soil_Ash"
    },
    {
      "x": -1,
      "y": 2,
      "z": -3,
      "name": "Soil_Ash"
    },
    {
      "x": -1,
      "y": 3,
      "z": -3,
      "name": "Soil_Ash"
    },
    {
      "x": -1,
      "y": 4,
      "z": -3,
      "name": "Soil_Ash"
    },
    {
      "x": -1,
      "y": 16,
      "z": -3,
      "name": "Rock_Magma_Cooled",
      "rotation": 1
    },
    {
      "x": -1,
      "y": 17,
      "z": -3,
      "name": "Ore_Adamantite_Magma_Cracked",
      "rotation": 1
    },
    {
      "x": -1,
      "y": 0,
      "z": -2,
      "name": "Soil_Ash"
    },
    {
      "x": -1,
      "y": 1,
      "z": -2,
      "name": "Soil_Ash"
    },
    {
      "x": -1,
      "y": 2,
      "z": -2,
      "name": "Soil_Ash"
    },
    {
      "x": -1,
      "y": 3,
      "z": -2,
      "name": "Soil_Ash"
    },
    {
      "x": -1,
      "y": 4,
      "z": -2,
      "name": "Soil_Ash"
    },
    {
      "x": -1,
      "y": 5,
      "z": -2,
      "name": "Plant_Flower_Poisoned_Orange"
    },
    {
      "x": -1,
      "y": 6,
      "z": -2,
      "name": "Rock_Magma_Cooled",
      "rotation": 1
    },
    {
      "x": -1,
      "y": 7,
      "z": -2,
      "name": "Rock_Magma_Cooled",
      "rotation": 1
    },
    {
      "x": -1,
      "y": 8,
      "z": -2,
      "name": "Rock_Magma_Cooled",
      "rotation": 1
    },
    {
      "x": -1,
      "y": 9,
      "z": -2,
      "name": "Rock_Magma_Cooled",
      "rotation": 1
    },
    {
      "x": -1,
      "y": 0,
      "z": -1,
      "name": "Soil_Ash"
    },
    {
      "x": -1,
      "y": 1,
      "z": -1,
      "name": "Soil_Ash"
    },
    {
      "x": -1,
      "y": 2,
      "z": -1,
      "name": "Soil_Ash"
    },
    {
      "x": -1,
      "y": 3,
      "z": -1,
      "name": "Soil_Ash"
    },
    {
      "x": -1,
      "y": 4,
      "z": -1,
      "name": "Soil_Ash"
    },
    {
      "x": -1,
      "y": 5,
      "z": -1,
      "name": "Rock_Magma_Cooled",
      "rotation": 1
    },
    {
      "x": -1,
      "y": 6,
      "z": -1,
      "name": "Rock_Magma_Cooled",
      "rotation": 1
    },
    {
      "x": -1,
      "y": 7,
      "z": -1,
      "name": "Rock_Magma_Cooled",
      "rotation": 1
    },
    {
      "x": -1,
      "y": 0,
      "z": 0,
      "name": "Soil_Ash"
    },
    {
      "x": -1,
      "y": 1,
      "z": 0,
      "name": "Soil_Ash"
    },
    {
      "x": -1,
      "y": 2,
      "z": 0,
      "name": "Soil_Ash"
    },
    {
      "x": -1,
      "y": 3,
      "z": 0,
      "name": "Soil_Ash"
    },
    {
      "x": -1,
      "y": 4,
      "z": 0,
      "name": "Rock_Magma_Cooled",
      "rotation": 1
    },
    {
      "x": -1,
      "y": 5,
      "z": 0,
      "name": "Rock_Magma_Cooled",
      "rotation": 1
    },
    {
      "x": -1,
      "y": 6,
      "z": 0,
      "name": "Ore_Adamantite_Magma_Cracked",
      "rotation": 1
    },
    {
      "x": -1,
      "y": 7,
      "z": 0,
      "name": "Rock_Magma_Cooled",
      "rotation": 1
    },
    {
      "x": -1,
      "y": 0,
      "z": 1,
      "name": "Soil_Ash"
    },
    {
      "x": -1,
      "y": 1,
      "z": 1,
      "name": "Soil_Ash"
    },
    {
      "x": -1,
      "y": 2,
      "z": 1,
      "name": "Soil_Ash"
    },
    {
      "x": -1,
      "y": 3,
      "z": 1,
      "name": "Soil_Ash"
    },
    {
      "x": -1,
      "y": 4,
      "z": 1,
      "name": "Soil_Ash"
    },
    {
      "x": -1,
      "y": 5,
      "z": 1,
      "name": "Soil_Ash"
    },
    {
      "x": -1,
      "y": 6,
      "z": 1,
      "name": "Rock_Magma_Cooled",
      "rotation": 1
    },
    {
      "x": -1,
      "y": 0,
      "z": 2,
      "name": "Soil_Ash"
    },
    {
      "x": -1,
      "y": 1,
      "z": 2,
      "name": "Soil_Ash"
    },
    {
      "x": -1,
      "y": 2,
      "z": 2,
      "name": "Soil_Ash"
    },
    {
      "x": -1,
      "y": 3,
      "z": 2,
      "name": "Soil_Ash"
    },
    {
      "x": -1,
      "y": 4,
      "z": 2,
      "name": "Soil_Ash"
    },
    {
      "x": -1,
      "y": 5,
      "z": 2,
      "name": "Soil_Ash"
    },
    {
      "x": -1,
      "y": 0,
      "z": 3,
      "name": "Soil_Ash"
    },
    {
      "x": -1,
      "y": 1,
      "z": 3,
      "name": "Soil_Ash"
    },
    {
      "x": -1,
      "y": 2,
      "z": 3,
      "name": "Soil_Ash"
    },
    {
      "x": -1,
      "y": 3,
      "z": 3,
      "name": "Soil_Ash"
    },
    {
      "x": -1,
      "y": 4,
      "z": 3,
      "name": "Soil_Ash"
    },
    {
      "x": -1,
      "y": 5,
      "z": 3,
      "name": "Soil_Ash"
    },
    {
      "x": -1,
      "y": 0,
      "z": 4,
      "name": "Soil_Ash"
    },
    {
      "x": -1,
      "y": 1,
      "z": 4,
      "name": "Soil_Ash"
    },
    {
      "x": -1,
      "y": 2,
      "z": 4,
      "name": "Soil_Ash"
    },
    {
      "x": -1,
      "y": 3,
      "z": 4,
      "name": "Soil_Ash"
    },
    {
      "x": -1,
      "y": 4,
      "z": 4,
      "name": "Soil_Ash"
    },
    {
      "x": -1,
      "y": 5,
      "z": 4,
      "name": "Plant_Bramble_Dead_Twisted"
    },
    {
      "x": -1,
      "y": 8,
      "z": 4,
      "name": "Rock_Magma_Cooled",
      "rotation": 1
    },
    {
      "x": -1,
      "y": 9,
      "z": 4,
      "name": "Rock_Magma_Cooled",
      "rotation": 1
    },
    {
      "x": -1,
      "y": 10,
      "z": 4,
      "name": "Plant_Vine_Wall_Poisoned",
      "support": 15,
      "rotation": 3
    },
    {
      "x": -1,
      "y": 0,
      "z": 5,
      "name": "Soil_Ash"
    },
    {
      "x": -1,
      "y": 1,
      "z": 5,
      "name": "Soil_Ash"
    },
    {
      "x": -1,
      "y": 2,
      "z": 5,
      "name": "Soil_Ash"
    },
    {
      "x": -1,
      "y": 3,
      "z": 5,
      "name": "Soil_Ash"
    },
    {
      "x": -1,
      "y": 4,
      "z": 5,
      "name": "Soil_Ash"
    },
    {
      "x": -1,
      "y": 5,
      "z": 5,
      "name": "Soil_Ash"
    },
    {
      "x": -1,
      "y": 9,
      "z": 5,
      "name": "Rock_Magma_Cooled",
      "rotation": 1
    },
    {
      "x": -1,
      "y": 10,
      "z": 5,
      "name": "Rock_Magma_Cooled",
      "rotation": 1
    },
    {
      "x": -1,
      "y": 11,
      "z": 5,
      "name": "Rock_Magma_Cooled",
      "rotation": 1
    },
    {
      "x": -1,
      "y": 12,
      "z": 5,
      "name": "Rock_Magma_Cooled",
      "rotation": 1
    },
    {
      "x": -1,
      "y": 13,
      "z": 5,
      "name": "Plant_Vine_Wall_Poisoned",
      "support": 15,
      "rotation": 3
    },
    {
      "x": -1,
      "y": 0,
      "z": 6,
      "name": "Soil_Ash"
    },
    {
      "x": -1,
      "y": 1,
      "z": 6,
      "name": "Soil_Ash"
    },
    {
      "x": -1,
      "y": 2,
      "z": 6,
      "name": "Soil_Ash"
    },
    {
      "x": -1,
      "y": 3,
      "z": 6,
      "name": "Soil_Ash"
    },
    {
      "x": -1,
      "y": 4,
      "z": 6,
      "name": "Soil_Ash"
    },
    {
      "x": -1,
      "y": 5,
      "z": 6,
      "name": "Soil_Ash"
    },
    {
      "x": -1,
      "y": 11,
      "z": 6,
      "name": "Rock_Magma_Cooled",
      "rotation": 1
    },
    {
      "x": -1,
      "y": 12,
      "z": 6,
      "name": "Rock_Magma_Cooled",
      "rotation": 1
    },
    {
      "x": -1,
      "y": 13,
      "z": 6,
      "name": "Ore_Adamantite_Magma_Cracked",
      "rotation": 1
    },
    {
      "x": -1,
      "y": 14,
      "z": 6,
      "name": "Rock_Magma_Cooled",
      "rotation": 1
    },
    {
      "x": -1,
      "y": 15,
      "z": 6,
      "name": "Rock_Magma_Cooled",
      "rotation": 1
    },
    {
      "x": -1,
      "y": 16,
      "z": 6,
      "name": "Rock_Magma_Cooled",
      "rotation": 1
    },
    {
      "x": -1,
      "y": 17,
      "z": 6,
      "name": "Rock_Magma_Cooled",
      "rotation": 1
    },
    {
      "x": -1,
      "y": 18,
      "z": 6,
      "name": "Plant_Moss_Rug_Pink",
      "support": 15
    },
    {
      "x": -1,
      "y": 0,
      "z": 7,
      "name": "Soil_Ash"
    },
    {
      "x": -1,
      "y": 1,
      "z": 7,
      "name": "Soil_Ash"
    },
    {
      "x": -1,
      "y": 2,
      "z": 7,
      "name": "Soil_Ash"
    },
    {
      "x": -1,
      "y": 3,
      "z": 7,
      "name": "Soil_Ash"
    },
    {
      "x": -1,
      "y": 4,
      "z": 7,
      "name": "Soil_Ash"
    },
    {
      "x": -1,
      "y": 5,
      "z": 7,
      "name": "Soil_Ash"
    },
    {
      "x": -1,
      "y": 6,
      "z": 7,
      "name": "Soil_Ash"
    },
    {
      "x": -1,
      "y": 13,
      "z": 7,
      "name": "Rock_Magma_Cooled",
      "rotation": 1
    },
    {
      "x": -1,
      "y": 14,
      "z": 7,
      "name": "Rock_Magma_Cooled",
      "rotation": 1
    },
    {
      "x": -1,
      "y": 15,
      "z": 7,
      "name": "Rock_Magma_Cooled",
      "rotation": 1
    },
    {
      "x": -1,
      "y": 16,
      "z": 7,
      "name": "Rock_Magma_Cooled",
      "rotation": 1
    },
    {
      "x": -1,
      "y": 17,
      "z": 7,
      "name": "Rock_Magma_Cooled",
      "rotation": 1
    },
    {
      "x": -1,
      "y": 18,
      "z": 7,
      "name": "Rock_Magma_Cooled",
      "rotation": 1
    },
    {
      "x": -1,
      "y": 19,
      "z": 7,
      "name": "Plant_Moss_Rug_Pink",
      "support": 15
    },
    {
      "x": -1,
      "y": 0,
      "z": 8,
      "name": "Soil_Ash"
    },
    {
      "x": -1,
      "y": 1,
      "z": 8,
      "name": "Soil_Ash"
    },
    {
      "x": -1,
      "y": 2,
      "z": 8,
      "name": "Soil_Ash"
    },
    {
      "x": -1,
      "y": 3,
      "z": 8,
      "name": "Soil_Ash"
    },
    {
      "x": -1,
      "y": 4,
      "z": 8,
      "name": "Soil_Ash"
    },
    {
      "x": -1,
      "y": 5,
      "z": 8,
      "name": "Soil_Ash"
    },
    {
      "x": -1,
      "y": 6,
      "z": 8,
      "name": "Soil_Ash"
    },
    {
      "x": -1,
      "y": 15,
      "z": 8,
      "name": "Rock_Magma_Cooled",
      "rotation": 1
    },
    {
      "x": -1,
      "y": 16,
      "z": 8,
      "name": "Rock_Magma_Cooled",
      "rotation": 1
    },
    {
      "x": -1,
      "y": 17,
      "z": 8,
      "name": "Ore_Adamantite_Magma_Cracked",
      "rotation": 1
    },
    {
      "x": -1,
      "y": 18,
      "z": 8,
      "name": "Ore_Adamantite_Magma_Cracked",
      "rotation": 1
    },
    {
      "x": -1,
      "y": 19,
      "z": 8,
      "name": "Rock_Magma_Cooled",
      "rotation": 1
    },
    {
      "x": -1,
      "y": 20,
      "z": 8,
      "name": "Plant_Moss_Rug_Pink",
      "support": 15
    },
    {
      "x": -1,
      "y": 0,
      "z": 9,
      "name": "Soil_Ash"
    },
    {
      "x": -1,
      "y": 1,
      "z": 9,
      "name": "Soil_Ash"
    },
    {
      "x": -1,
      "y": 2,
      "z": 9,
      "name": "Soil_Ash"
    },
    {
      "x": -1,
      "y": 3,
      "z": 9,
      "name": "Soil_Ash"
    },
    {
      "x": -1,
      "y": 4,
      "z": 9,
      "name": "Soil_Ash"
    },
    {
      "x": -1,
      "y": 5,
      "z": 9,
      "name": "Soil_Ash"
    },
    {
      "x": -1,
      "y": 17,
      "z": 9,
      "name": "Rock_Magma_Cooled",
      "rotation": 1
    },
    {
      "x": -1,
      "y": 18,
      "z": 9,
      "name": "Rock_Magma_Cooled",
      "rotation": 1
    },
    {
      "x": -1,
      "y": 19,
      "z": 9,
      "name": "Rock_Magma_Cooled",
      "rotation": 1
    },
    {
      "x": -1,
      "y": 20,
      "z": 9,
      "name": "Plant_Moss_Rug_Pink",
      "support": 15
    },
    {
      "x": -1,
      "y": 0,
      "z": 10,
      "name": "Soil_Ash"
    },
    {
      "x": -1,
      "y": 1,
      "z": 10,
      "name": "Soil_Ash"
    },
    {
      "x": -1,
      "y": 2,
      "z": 10,
      "name": "Soil_Ash"
    },
    {
      "x": -1,
      "y": 3,
      "z": 10,
      "name": "Soil_Ash"
    },
    {
      "x": -1,
      "y": 4,
      "z": 10,
      "name": "Soil_Ash"
    },
    {
      "x": -1,
      "y": 0,
      "z": 11,
      "name": "Soil_Ash"
    },
    {
      "x": -1,
      "y": 1,
      "z": 11,
      "name": "Soil_Sand_Ashen"
    },
    {
      "x": -1,
      "y": 2,
      "z": 11,
      "name": "Soil_Sand_Ashen"
    },
    {
      "x": -1,
      "y": 3,
      "z": 11,
      "name": "Soil_Sand_Ashen"
    },
    {
      "x": -1,
      "y": 0,
      "z": 12,
      "name": "Soil_Ash"
    },
    {
      "x": -1,
      "y": 1,
      "z": 12,
      "name": "Soil_Ash"
    },
    {
      "x": 0,
      "y": 0,
      "z": -9,
      "name": "Soil_Ash"
    },
    {
      "x": 0,
      "y": 0,
      "z": -8,
      "name": "Soil_Ash"
    },
    {
      "x": 0,
      "y": 0,
      "z": -7,
      "name": "Soil_Ash"
    },
    {
      "x": 0,
      "y": 1,
      "z": -7,
      "name": "Soil_Sand_Ashen"
    },
    {
      "x": 0,
      "y": 0,
      "z": -6,
      "name": "Soil_Ash"
    },
    {
      "x": 0,
      "y": 1,
      "z": -6,
      "name": "Soil_Ash"
    },
    {
      "x": 0,
      "y": 0,
      "z": -5,
      "name": "Soil_Ash"
    },
    {
      "x": 0,
      "y": 1,
      "z": -5,
      "name": "Soil_Ash"
    },
    {
      "x": 0,
      "y": 13,
      "z": -5,
      "name": "Ore_Adamantite_Magma_Cracked",
      "rotation": 1
    },
    {
      "x": 0,
      "y": 14,
      "z": -5,
      "name": "Ore_Adamantite_Magma_Cracked",
      "rotation": 1
    },
    {
      "x": 0,
      "y": 15,
      "z": -5,
      "name": "Rock_Magma_Cooled",
      "rotation": 1
    },
    {
      "x": 0,
      "y": 16,
      "z": -5,
      "name": "Rock_Magma_Cooled",
      "rotation": 1
    },
    {
      "x": 0,
      "y": 17,
      "z": -5,
      "name": "Rock_Magma_Cooled",
      "rotation": 1
    },
    {
      "x": 0,
      "y": 18,
      "z": -5,
      "name": "Rock_Magma_Cooled",
      "rotation": 1
    },
    {
      "x": 0,
      "y": 19,
      "z": -5,
      "name": "Plant_Moss_Rug_Pink",
      "support": 15
    },
    {
      "x": 0,
      "y": 0,
      "z": -4,
      "name": "Soil_Sand_Ashen"
    },
    {
      "x": 0,
      "y": 1,
      "z": -4,
      "name": "Soil_Ash"
    },
    {
      "x": 0,
      "y": 2,
      "z": -4,
      "name": "Soil_Sand_Ashen"
    },
    {
      "x": 0,
      "y": 12,
      "z": -4,
      "name": "Rock_Magma_Cooled",
      "rotation": 1
    },
    {
      "x": 0,
      "y": 13,
      "z": -4,
      "name": "Rock_Magma_Cooled",
      "rotation": 1
    },
    {
      "x": 0,
      "y": 14,
      "z": -4,
      "name": "Rock_Magma_Cooled",
      "rotation": 1
    },
    {
      "x": 0,
      "y": 15,
      "z": -4,
      "name": "Rock_Magma_Cooled",
      "rotation": 1
    },
    {
      "x": 0,
      "y": 16,
      "z": -4,
      "name": "Ore_Adamantite_Magma_Cracked",
      "rotation": 1
    },
    {
      "x": 0,
      "y": 17,
      "z": -4,
      "name": "Rock_Magma_Cooled",
      "rotation": 1
    },
    {
      "x": 0,
      "y": 18,
      "z": -4,
      "name": "Plant_Moss_Rug_Pink",
      "support": 15
    },
    {
      "x": 0,
      "y": 0,
      "z": -3,
      "name": "Soil_Ash"
    },
    {
      "x": 0,
      "y": 1,
      "z": -3,
      "name": "Soil_Ash"
    },
    {
      "x": 0,
      "y": 2,
      "z": -3,
      "name": "Soil_Ash"
    },
    {
      "x": 0,
      "y": 11,
      "z": -3,
      "name": "Rock_Magma_Cooled",
      "rotation": 1
    },
    {
      "x": 0,
      "y": 12,
      "z": -3,
      "name": "Rock_Magma_Cooled",
      "rotation": 1
    },
    {
      "x": 0,
      "y": 13,
      "z": -3,
      "name": "Rock_Magma_Cooled",
      "rotation": 1
    },
    {
      "x": 0,
      "y": 14,
      "z": -3,
      "name": "Rock_Magma_Cooled",
      "rotation": 1
    },
    {
      "x": 0,
      "y": 15,
      "z": -3,
      "name": "Rock_Magma_Cooled",
      "rotation": 1
    },
    {
      "x": 0,
      "y": 16,
      "z": -3,
      "name": "Rock_Magma_Cooled",
      "rotation": 1
    },
    {
      "x": 0,
      "y": 0,
      "z": -2,
      "name": "Soil_Ash"
    },
    {
      "x": 0,
      "y": 1,
      "z": -2,
      "name": "Soil_Ash"
    },
    {
      "x": 0,
      "y": 2,
      "z": -2,
      "name": "Soil_Ash"
    },
    {
      "x": 0,
      "y": 3,
      "z": -2,
      "name": "Soil_Ash"
    },
    {
      "x": 0,
      "y": 4,
      "z": -2,
      "name": "Soil_Ash"
    },
    {
      "x": 0,
      "y": 5,
      "z": -2,
      "name": "Ore_Adamantite_Magma_Cracked",
      "rotation": 1
    },
    {
      "x": 0,
      "y": 6,
      "z": -2,
      "name": "Rock_Magma_Cooled",
      "rotation": 1
    },
    {
      "x": 0,
      "y": 13,
      "z": -2,
      "name": "Ore_Adamantite_Magma_Cracked",
      "rotation": 1
    },
    {
      "x": 0,
      "y": 14,
      "z": -2,
      "name": "Rock_Magma_Cooled",
      "rotation": 1
    },
    {
      "x": 0,
      "y": 0,
      "z": -1,
      "name": "Soil_Ash"
    },
    {
      "x": 0,
      "y": 1,
      "z": -1,
      "name": "Soil_Ash"
    },
    {
      "x": 0,
      "y": 2,
      "z": -1,
      "name": "Soil_Ash"
    },
    {
      "x": 0,
      "y": 3,
      "z": -1,
      "name": "Ore_Adamantite_Magma_Cracked",
      "rotation": 1
    },
    {
      "x": 0,
      "y": 4,
      "z": -1,
      "name": "Rock_Magma_Cooled",
      "rotation": 1
    },
    {
      "x": 0,
      "y": 5,
      "z": -1,
      "name": "Ore_Adamantite_Magma_Cracked",
      "rotation": 1
    },
    {
      "x": 0,
      "y": 6,
      "z": -1,
      "name": "Rock_Magma_Cooled",
      "rotation": 1
    },
    {
      "x": 0,
      "y": 7,
      "z": -1,
      "name": "Rock_Magma_Cooled",
      "rotation": 1
    },
    {
      "x": 0,
      "y": 12,
      "z": -1,
      "name": "Plant_Vine_Wall_Poisoned",
      "support": 15,
      "rotation": 3
    },
    {
      "x": 0,
      "y": 0,
      "z": 0,
      "name": "Soil_Ash"
    },
    {
      "x": 0,
      "y": 1,
      "z": 0,
      "name": "Soil_Ash"
    },
    {
      "x": 0,
      "y": 2,
      "z": 0,
      "name": "Soil_Ash"
    },
    {
      "x": 0,
      "y": 3,
      "z": 0,
      "name": "Rock_Magma_Cooled",
      "rotation": 1
    },
    {
      "x": 0,
      "y": 4,
      "z": 0,
      "name": "Rock_Magma_Cooled",
      "rotation": 1
    },
    {
      "x": 0,
      "y": 5,
      "z": 0,
      "name": "Rock_Magma_Cooled",
      "rotation": 1
    },
    {
      "x": 0,
      "y": 6,
      "z": 0,
      "name": "Rock_Magma_Cooled",
      "rotation": 1
    },
    {
      "x": 0,
      "y": 0,
      "z": 1,
      "name": "Soil_Ash"
    },
    {
      "x": 0,
      "y": 1,
      "z": 1,
      "name": "Soil_Ash"
    },
    {
      "x": 0,
      "y": 2,
      "z": 1,
      "name": "Rock_Magma_Cooled",
      "rotation": 1
    },
    {
      "x": 0,
      "y": 3,
      "z": 1,
      "name": "Rock_Magma_Cooled",
      "rotation": 1
    },
    {
      "x": 0,
      "y": 4,
      "z": 1,
      "name": "Ore_Adamantite_Magma_Cracked",
      "rotation": 1
    },
    {
      "x": 0,
      "y": 5,
      "z": 1,
      "name": "Rock_Magma_Cooled",
      "rotation": 1
    },
    {
      "x": 0,
      "y": 6,
      "z": 1,
      "name": "Ore_Adamantite_Magma_Cracked",
      "rotation": 1
    },
    {
      "x": 0,
      "y": 0,
      "z": 2,
      "name": "Soil_Ash"
    },
    {
      "x": 0,
      "y": 1,
      "z": 2,
      "name": "Soil_Ash"
    },
    {
      "x": 0,
      "y": 2,
      "z": 2,
      "name": "Soil_Ash"
    },
    {
      "x": 0,
      "y": 3,
      "z": 2,
      "name": "Ore_Adamantite_Magma_Cracked",
      "rotation": 1
    },
    {
      "x": 0,
      "y": 4,
      "z": 2,
      "name": "Rock_Magma_Cooled",
      "rotation": 1
    },
    {
      "x": 0,
      "y": 5,
      "z": 2,
      "name": "Soil_Ash"
    },
    {
      "x": 0,
      "y": 0,
      "z": 3,
      "name": "Soil_Ash"
    },
    {
      "x": 0,
      "y": 1,
      "z": 3,
      "name": "Soil_Ash"
    },
    {
      "x": 0,
      "y": 2,
      "z": 3,
      "name": "Soil_Ash"
    },
    {
      "x": 0,
      "y": 3,
      "z": 3,
      "name": "Soil_Ash"
    },
    {
      "x": 0,
      "y": 4,
      "z": 3,
      "name": "Soil_Ash"
    },
    {
      "x": 0,
      "y": 5,
      "z": 3,
      "name": "Soil_Ash"
    },
    {
      "x": 0,
      "y": 0,
      "z": 4,
      "name": "Soil_Ash"
    },
    {
      "x": 0,
      "y": 1,
      "z": 4,
      "name": "Soil_Ash"
    },
    {
      "x": 0,
      "y": 2,
      "z": 4,
      "name": "Soil_Ash"
    },
    {
      "x": 0,
      "y": 3,
      "z": 4,
      "name": "Soil_Ash"
    },
    {
      "x": 0,
      "y": 4,
      "z": 4,
      "name": "Soil_Ash"
    },
    {
      "x": 0,
      "y": 5,
      "z": 4,
      "name": "Soil_Ash"
    },
    {
      "x": 0,
      "y": 6,
      "z": 4,
      "name": "Rock_Magma_Cooled",
      "rotation": 1
    },
    {
      "x": 0,
      "y": 7,
      "z": 4,
      "name": "Rock_Magma_Cooled",
      "rotation": 1
    },
    {
      "x": 0,
      "y": 8,
      "z": 4,
      "name": "Rock_Magma_Cooled",
      "rotation": 1
    },
    {
      "x": 0,
      "y": 9,
      "z": 4,
      "name": "Rock_Magma_Cooled",
      "rotation": 1
    },
    {
      "x": 0,
      "y": 10,
      "z": 4,
      "name": "Ore_Adamantite_Magma_Cracked",
      "rotation": 1
    },
    {
      "x": 0,
      "y": 11,
      "z": 4,
      "name": "Rock_Magma_Cooled",
      "rotation": 1
    },
    {
      "x": 0,
      "y": 0,
      "z": 5,
      "name": "Soil_Ash"
    },
    {
      "x": 0,
      "y": 1,
      "z": 5,
      "name": "Soil_Ash"
    },
    {
      "x": 0,
      "y": 2,
      "z": 5,
      "name": "Soil_Ash"
    },
    {
      "x": 0,
      "y": 3,
      "z": 5,
      "name": "Soil_Ash"
    },
    {
      "x": 0,
      "y": 4,
      "z": 5,
      "name": "Soil_Ash"
    },
    {
      "x": 0,
      "y": 5,
      "z": 5,
      "name": "Soil_Ash"
    },
    {
      "x": 0,
      "y": 6,
      "z": 5,
      "name": "Plant_Bramble_Dead_Twisted"
    },
    {
      "x": 0,
      "y": 7,
      "z": 5,
      "name": "Rock_Magma_Cooled",
      "rotation": 1
    },
    {
      "x": 0,
      "y": 8,
      "z": 5,
      "name": "Rock_Magma_Cooled",
      "rotation": 1
    },
    {
      "x": 0,
      "y": 9,
      "z": 5,
      "name": "Ore_Adamantite_Magma_Cracked",
      "rotation": 1
    },
    {
      "x": 0,
      "y": 10,
      "z": 5,
      "name": "Rock_Magma_Cooled",
      "rotation": 1
    },
    {
      "x": 0,
      "y": 11,
      "z": 5,
      "name": "Ore_Adamantite_Magma_Cracked",
      "rotation": 1
    },
    {
      "x": 0,
      "y": 12,
      "z": 5,
      "name": "Rock_Magma_Cooled",
      "rotation": 1
    },
    {
      "x": 0,
      "y": 13,
      "z": 5,
      "name": "Rock_Magma_Cooled",
      "rotation": 1
    },
    {
      "x": 0,
      "y": 14,
      "z": 5,
      "name": "Rock_Magma_Cooled",
      "rotation": 1
    },
    {
      "x": 0,
      "y": 15,
      "z": 5,
      "name": "Rock_Magma_Cooled",
      "rotation": 1
    },
    {
      "x": 0,
      "y": 0,
      "z": 6,
      "name": "Soil_Ash"
    },
    {
      "x": 0,
      "y": 1,
      "z": 6,
      "name": "Soil_Ash"
    },
    {
      "x": 0,
      "y": 2,
      "z": 6,
      "name": "Soil_Ash"
    },
    {
      "x": 0,
      "y": 3,
      "z": 6,
      "name": "Soil_Ash"
    },
    {
      "x": 0,
      "y": 4,
      "z": 6,
      "name": "Soil_Ash"
    },
    {
      "x": 0,
      "y": 10,
      "z": 6,
      "name": "Rock_Magma_Cooled",
      "rotation": 1
    },
    {
      "x": 0,
      "y": 11,
      "z": 6,
      "name": "Ore_Adamantite_Magma_Cracked",
      "rotation": 1
    },
    {
      "x": 0,
      "y": 12,
      "z": 6,
      "name": "Rock_Magma_Cooled",
      "rotation": 1
    },
    {
      "x": 0,
      "y": 13,
      "z": 6,
      "name": "Rock_Magma_Cooled",
      "rotation": 1
    },
    {
      "x": 0,
      "y": 14,
      "z": 6,
      "name": "Rock_Magma_Cooled",
      "rotation": 1
    },
    {
      "x": 0,
      "y": 15,
      "z": 6,
      "name": "Rock_Magma_Cooled",
      "rotation": 1
    },
    {
      "x": 0,
      "y": 16,
      "z": 6,
      "name": "Rock_Magma_Cooled",
      "rotation": 1
    },
    {
      "x": 0,
      "y": 0,
      "z": 7,
      "name": "Soil_Ash"
    },
    {
      "x": 0,
      "y": 1,
      "z": 7,
      "name": "Soil_Ash"
    },
    {
      "x": 0,
      "y": 2,
      "z": 7,
      "name": "Soil_Ash"
    },
    {
      "x": 0,
      "y": 3,
      "z": 7,
      "name": "Soil_Ash"
    },
    {
      "x": 0,
      "y": 4,
      "z": 7,
      "name": "Soil_Ash"
    },
    {
      "x": 0,
      "y": 5,
      "z": 7,
      "name": "Soil_Ash"
    },
    {
      "x": 0,
      "y": 12,
      "z": 7,
      "name": "Rock_Magma_Cooled",
      "rotation": 1
    },
    {
      "x": 0,
      "y": 13,
      "z": 7,
      "name": "Rock_Magma_Cooled",
      "rotation": 1
    },
    {
      "x": 0,
      "y": 14,
      "z": 7,
      "name": "Rock_Magma_Cooled",
      "rotation": 1
    },
    {
      "x": 0,
      "y": 0,
      "z": 8,
      "name": "Soil_Ash"
    },
    {
      "x": 0,
      "y": 1,
      "z": 8,
      "name": "Soil_Ash"
    },
    {
      "x": 0,
      "y": 2,
      "z": 8,
      "name": "Soil_Ash"
    },
    {
      "x": 0,
      "y": 3,
      "z": 8,
      "name": "Soil_Ash"
    },
    {
      "x": 0,
      "y": 4,
      "z": 8,
      "name": "Soil_Ash"
    },
    {
      "x": 0,
      "y": 5,
      "z": 8,
      "name": "Soil_Ash"
    },
    {
      "x": 0,
      "y": 13,
      "z": 8,
      "name": "Plant_Vine_Wall_Poisoned",
      "support": 15
    },
    {
      "x": 0,
      "y": 0,
      "z": 9,
      "name": "Soil_Ash"
    },
    {
      "x": 0,
      "y": 1,
      "z": 9,
      "name": "Soil_Ash"
    },
    {
      "x": 0,
      "y": 2,
      "z": 9,
      "name": "Soil_Ash"
    },
    {
      "x": 0,
      "y": 3,
      "z": 9,
      "name": "Soil_Ash"
    },
    {
      "x": 0,
      "y": 4,
      "z": 9,
      "name": "Soil_Ash"
    },
    {
      "x": 0,
      "y": 0,
      "z": 10,
      "name": "Soil_Ash"
    },
    {
      "x": 0,
      "y": 1,
      "z": 10,
      "name": "Soil_Ash"
    },
    {
      "x": 0,
      "y": 2,
      "z": 10,
      "name": "Soil_Ash"
    },
    {
      "x": 0,
      "y": 3,
      "z": 10,
      "name": "Soil_Sand_Ashen"
    },
    {
      "x": 0,
      "y": 0,
      "z": 11,
      "name": "Soil_Sand_Ashen"
    },
    {
      "x": 0,
      "y": 1,
      "z": 11,
      "name": "Soil_Ash"
    },
    {
      "x": 1,
      "y": 0,
      "z": -7,
      "name": "Soil_Ash"
    },
    {
      "x": 1,
      "y": 0,
      "z": -6,
      "name": "Soil_Sand_Ashen"
    },
    {
      "x": 1,
      "y": 0,
      "z": -5,
      "name": "Soil_Ash"
    },
    {
      "x": 1,
      "y": 13,
      "z": -5,
      "name": "Plant_Vine_Wall_Poisoned",
      "support": 15,
      "rotation": 1
    },
    {
      "x": 1,
      "y": 14,
      "z": -5,
      "name": "Rock_Magma_Cooled",
      "rotation": 1
    },
    {
      "x": 1,
      "y": 15,
      "z": -5,
      "name": "Rock_Magma_Cooled",
      "rotation": 1
    },
    {
      "x": 1,
      "y": 16,
      "z": -5,
      "name": "Rock_Magma_Cooled",
      "rotation": 1
    },
    {
      "x": 1,
      "y": 12,
      "z": -4,
      "name": "Rock_Magma_Cooled",
      "rotation": 1
    },
    {
      "x": 1,
      "y": 13,
      "z": -4,
      "name": "Rock_Magma_Cooled",
      "rotation": 1
    },
    {
      "x": 1,
      "y": 14,
      "z": -4,
      "name": "Ore_Adamantite_Magma_Cracked",
      "rotation": 1
    },
    {
      "x": 1,
      "y": 15,
      "z": -4,
      "name": "Rock_Magma_Cooled",
      "rotation": 1
    },
    {
      "x": 1,
      "y": 0,
      "z": -3,
      "name": "Soil_Ash"
    },
    {
      "x": 1,
      "y": 1,
      "z": -3,
      "name": "Soil_Ash"
    },
    {
      "x": 1,
      "y": 2,
      "z": -3,
      "name": "Soil_Ash"
    },
    {
      "x": 1,
      "y": 3,
      "z": -3,
      "name": "Plant_Bramble_Dead_Twisted"
    },
    {
      "x": 1,
      "y": 9,
      "z": -3,
      "name": "Rock_Magma_Cooled",
      "rotation": 1
    },
    {
      "x": 1,
      "y": 10,
      "z": -3,
      "name": "Ore_Adamantite_Magma_Cracked",
