{
  "version": 8,
  "blockIdVersion": 11,
  "anchorX": 0,
  "anchorY": 0,
  "anchorZ": 0,
  "blocks": [
    {
      "x": -7,
      "y": 0,
      "z": 2,
      "name": "Soil_Ash"
    },
    {
      "x": -7,
      "y": 0,
      "z": 3,
      "name": "Soil_Ash"
    },
    {
      "x": -7,
      "y": 0,
      "z": 4,
      "name": "Soil_Ash"
    },
    {
      "x": -6,
      "y": 0,
      "z": -3,
      "name": "Soil_Ash"
    },
    {
      "x": -6,
      "y": 0,
      "z": -2,
      "name": "Soil_Ash"
    },
    {
      "x": -6,
      "y": 0,
      "z": -1,
      "name": "Soil_Ash"
    },
    {
      "x": -6,
      "y": 0,
      "z": 1,
      "name": "Soil_Sand_Ashen"
    },
    {
      "x": -6,
      "y": 0,
      "z": 2,
      "name": "Soil_Sand_Ashen"
    },
    {
      "x": -6,
      "y": 1,
      "z": 2,
      "name": "Soil_Sand_Ashen"
    },
    {
      "x": -6,
      "y": 0,
      "z": 3,
      "name": "Soil_Ash"
    },
    {
      "x": -6,
      "y": 1,
      "z": 3,
      "name": "Soil_Sand_Ashen"
    },
    {
      "x": -6,
      "y": 0,
      "z": 4,
      "name": "Soil_Ash"
    },
    {
      "x": -6,
      "y": 1,
      "z": 4,
      "name": "Soil_Sand_Ashen"
    },
    {
      "x": -6,
      "y": 0,
      "z": 5,
      "name": "Soil_Ash"
    },
    {
      "x": -5,
      "y": 0,
      "z": -4,
      "name": "Soil_Ash"
    },
    {
      "x": -5,
      "y": 0,
      "z": -3,
      "name": "Soil_Ash"
    },
    {
      "x": -5,
      "y": 1,
      "z": -3,
      "name": "Soil_Sand_Ashen"
    },
    {
      "x": -5,
      "y": 0,
      "z": -2,
      "name": "Soil_Ash"
    },
    {
      "x": -5,
      "y": 1,
      "z": -2,
      "name": "Soil_Sand_Ashen"
    },
    {
      "x": -5,
      "y": 2,
      "z": -2,
      "name": "Plant_Bramble_Dead_Twisted"
    },
    {
      "x": -5,
      "y": 0,
      "z": -1,
      "name": "Soil_Ash"
    },
    {
      "x": -5,
      "y": 1,
      "z": -1,
      "name": "Soil_Ash"
    },
    {
      "x": -5,
      "y": 2,
      "z": -1,
      "name": "Plant_Bush_Dead_Tall",
      "support": 15
    },
    {
      "x": -5,
      "y": 0,
      "z": 0,
      "name": "Soil_Ash"
    },
    {
      "x": -5,
      "y": 0,
      "z": 1,
      "name": "Soil_Sand_Ashen"
    },
    {
      "x": -5,
      "y": 1,
      "z": 1,
      "name": "Soil_Ash"
    },
    {
      "x": -5,
      "y": 0,
      "z": 2,
      "name": "Soil_Sand_Ashen"
    },
    {
      "x": -5,
      "y": 1,
      "z": 2,
      "name": "Soil_Ash"
    },
    {
      "x": -5,
      "y": 0,
      "z": 3,
      "name": "Soil_Ash"
    },
    {
      "x": -5,
      "y": 1,
      "z": 3,
      "name": "Soil_Sand_Ashen"
    },
    {
      "x": -5,
      "y": 2,
      "z": 3,
      "name": "Soil_Ash"
    },
    {
      "x": -5,
      "y": 0,
      "z": 4,
      "name": "Soil_Ash"
    },
    {
      "x": -5,
      "y": 1,
      "z": 4,
      "name": "Soil_Sand_Ashen"
    },
    {
      "x": -5,
      "y": 0,
      "z": 5,
      "name": "Soil_Ash"
    },
    {
      "x": -5,
      "y": 1,
      "z": 5,
      "name": "Soil_Sand_Ashen"
    },
    {
      "x": -5,
      "y": 0,
      "z": 6,
      "name": "Soil_Sand_Ashen"
    },
    {
      "x": -4,
      "y": 0,
      "z": -5,
      "name": "Soil_Sand_Ashen"
    },
    {
      "x": -4,
      "y": 0,
      "z": -4,
      "name": "Soil_Sand_Ashen"
    },
    {
      "x": -4,
      "y": 1,
      "z": -4,
      "name": "Soil_Sand_Ashen"
    },
    {
      "x": -4,
      "y": 0,
      "z": -3,
      "name": "Soil_Sand_Ashen"
    },
    {
      "x": -4,
      "y": 1,
      "z": -3,
      "name": "Soil_Ash"
    },
    {
      "x": -4,
      "y": 0,
      "z": -2,
      "name": "Soil_Sand_Ashen"
    },
    {
      "x": -4,
      "y": 1,
      "z": -2,
      "name": "Soil_Sand_Ashen"
    },
    {
      "x": -4,
      "y": 2,
      "z": -2,
      "name": "Soil_Ash"
    },
    {
      "x": -4,
      "y": 3,
      "z": -2,
      "name": "Plant_Bramble_Dead_Twisted"
    },
    {
      "x": -4,
      "y": 0,
      "z": -1,
      "name": "Soil_Sand_Ashen"
    },
    {
      "x": -4,
      "y": 1,
      "z": -1,
      "name": "Soil_Ash"
    },
    {
      "x": -4,
      "y": 2,
      "z": -1,
      "name": "Plant_Flower_Bushy_Poisoned"
    },
    {
      "x": -4,
      "y": 0,
      "z": 0,
      "name": "Soil_Sand_Ashen"
    },
    {
      "x": -4,
      "y": 1,
      "z": 0,
      "name": "Soil_Ash"
    },
    {
      "x": -4,
      "y": 2,
      "z": 0,
      "name": "Plant_Bramble_Dead_Twisted"
    },
    {
      "x": -4,
      "y": 0,
      "z": 1,
      "name": "Soil_Ash"
    },
    {
      "x": -4,
      "y": 1,
      "z": 1,
      "name": "Soil_Ash"
    },
    {
      "x": -4,
      "y": 2,
      "z": 1,
      "name": "Plant_Bush_Dead_Tall",
      "support": 15
    },
    {
      "x": -4,
      "y": 0,
      "z": 2,
      "name": "Soil_Ash"
    },
    {
      "x": -4,
      "y": 1,
      "z": 2,
      "name": "Soil_Sand_Ashen"
    },
    {
      "x": -4,
      "y": 2,
      "z": 2,
      "name": "Soil_Ash"
    },
    {
      "x": -4,
      "y": 3,
      "z": 2,
      "name": "Plant_Bush_Dead_Tall",
      "support": 15
    },
    {
      "x": -4,
      "y": 0,
      "z": 3,
      "name": "Soil_Ash"
    },
    {
      "x": -4,
      "y": 1,
      "z": 3,
      "name": "Soil_Ash"
    },
    {
      "x": -4,
      "y": 2,
      "z": 3,
      "name": "Soil_Ash"
    },
    {
      "x": -4,
      "y": 3,
      "z": 3,
      "name": "Plant_Bramble_Dead_Twisted"
    },
    {
      "x": -4,
      "y": 0,
      "z": 4,
      "name": "Soil_Sand_Ashen"
    },
    {
      "x": -4,
      "y": 1,
      "z": 4,
      "name": "Soil_Sand_Ashen"
    },
    {
      "x": -4,
      "y": 2,
      "z": 4,
      "name": "Soil_Ash"
    },
    {
      "x": -4,
      "y": 3,
      "z": 4,
      "name": "Plant_Flower_Bushy_Poisoned"
    },
    {
      "x": -4,
      "y": 0,
      "z": 5,
      "name": "Soil_Sand_Ashen"
    },
    {
      "x": -4,
      "y": 1,
      "z": 5,
      "name": "Soil_Sand_Ashen"
    },
    {
      "x": -4,
      "y": 0,
      "z": 6,
      "name": "Soil_Ash"
    },
    {
      "x": -4,
      "y": 1,
      "z": 6,
      "name": "Soil_Ash"
    },
    {
      "x": -4,
      "y": 0,
      "z": 7,
      "name": "Soil_Sand_Ashen"
    },
    {
      "x": -3,
      "y": 0,
      "z": -6,
      "name": "Soil_Sand_Ashen"
    },
    {
      "x": -3,
      "y": 0,
      "z": -5,
      "name": "Soil_Ash"
    },
    {
      "x": -3,
      "y": 1,
      "z": -5,
      "name": "Soil_Ash"
    },
    {
      "x": -3,
      "y": 0,
      "z": -4,
      "name": "Soil_Ash"
    },
    {
      "x": -3,
      "y": 1,
      "z": -4,
      "name": "Soil_Ash"
    },
    {
      "x": -3,
      "y": 2,
      "z": -4,
      "name": "Plant_Bramble_Dead_Twisted"
    },
    {
      "x": -3,
      "y": 0,
      "z": -3,
      "name": "Soil_Ash"
    },
    {
      "x": -3,
      "y": 1,
      "z": -3,
      "name": "Soil_Sand_Ashen"
    },
    {
      "x": -3,
      "y": 2,
      "z": -3,
      "name": "Soil_Ash"
    },
    {
      "x": -3,
      "y": 3,
      "z": -3,
      "name": "Plant_Bush_Dead_Tall",
      "support": 15
    },
    {
      "x": -3,
      "y": 0,
      "z": -2,
      "name": "Soil_Ash"
    },
    {
      "x": -3,
      "y": 1,
      "z": -2,
      "name": "Soil_Sand_Ashen"
    },
    {
      "x": -3,
      "y": 2,
      "z": -2,
      "name": "Soil_Ash"
    },
    {
      "x": -3,
      "y": 3,
      "z": -2,
      "name": "Plant_Flower_Bushy_Violet"
    },
    {
      "x": -3,
      "y": 0,
      "z": -1,
      "name": "Soil_Sand_Ashen"
    },
    {
      "x": -3,
      "y": 1,
      "z": -1,
      "name": "Soil_Sand_Ashen"
    },
    {
      "x": -3,
      "y": 2,
      "z": -1,
      "name": "Soil_Ash"
    },
    {
      "x": -3,
      "y": 3,
      "z": -1,
      "name": "Plant_Bramble_Dead_Twisted"
    },
    {
      "x": -3,
      "y": 0,
      "z": 0,
      "name": "Soil_Ash"
    },
    {
      "x": -3,
      "y": 1,
      "z": 0,
      "name": "Soil_Sand_Ashen"
    },
    {
      "x": -3,
      "y": 2,
      "z": 0,
      "name": "Soil_Ash"
    },
    {
      "x": -3,
      "y": 3,
      "z": 0,
      "name": "Plant_Flower_Bushy_Violet"
    },
    {
      "x": -3,
      "y": 0,
      "z": 1,
      "name": "Soil_Ash"
    },
    {
      "x": -3,
      "y": 1,
      "z": 1,
      "name": "Soil_Sand_Ashen"
    },
    {
      "x": -3,
      "y": 2,
      "z": 1,
      "name": "Soil_Ash"
    },
    {
      "x": -3,
      "y": 3,
      "z": 1,
      "name": "Plant_Flower_Common_Poisoned2"
    },
    {
      "x": -3,
      "y": 0,
      "z": 2,
      "name": "Soil_Sand_Ashen"
    },
    {
      "x": -3,
      "y": 1,
      "z": 2,
      "name": "Soil_Ash"
    },
    {
      "x": -3,
      "y": 2,
      "z": 2,
      "name": "Soil_Ash"
    },
    {
      "x": -3,
      "y": 3,
      "z": 2,
      "name": "Plant_Flower_Bushy_Poisoned"
    },
    {
      "x": -3,
      "y": 0,
      "z": 3,
      "name": "Soil_Ash"
    },
    {
      "x": -3,
      "y": 1,
      "z": 3,
      "name": "Soil_Sand_Ashen"
    },
    {
      "x": -3,
      "y": 2,
      "z": 3,
      "name": "Soil_Ash"
    },
    {
      "x": -3,
      "y": 0,
      "z": 4,
      "name": "Soil_Ash"
    },
    {
      "x": -3,
      "y": 1,
      "z": 4,
      "name": "Soil_Sand_Ashen"
    },
    {
      "x": -3,
      "y": 2,
      "z": 4,
      "name": "Soil_Ash"
    },
    {
      "x": -3,
      "y": 3,
      "z": 4,
      "name": "Plant_Flower_Bushy_Poisoned"
    },
    {
      "x": -3,
      "y": 0,
      "z": 5,
      "name": "Soil_Sand_Ashen"
    },
    {
      "x": -3,
      "y": 1,
      "z": 5,
      "name": "Soil_Sand_Ashen"
    },
    {
      "x": -3,
      "y": 2,
      "z": 5,
      "name": "Soil_Ash"
    },
    {
      "x": -3,
      "y": 0,
      "z": 6,
      "name": "Soil_Ash"
    },
    {
      "x": -3,
      "y": 1,
      "z": 6,
      "name": "Soil_Ash"
    },
    {
      "x": -3,
      "y": 0,
      "z": 7,
      "name": "Soil_Ash"
    },
    {
      "x": -2,
      "y": 0,
      "z": -6,
      "name": "Soil_Ash"
    },
    {
      "x": -2,
      "y": 0,
      "z": -5,
      "name": "Soil_Ash"
    },
    {
      "x": -2,
      "y": 1,
      "z": -5,
      "name": "Soil_Ash"
    },
    {
      "x": -2,
      "y": 0,
      "z": -4,
      "name": "Soil_Ash"
    },
    {
      "x": -2,
      "y": 1,
      "z": -4,
      "name": "Soil_Sand_Ashen"
    },
    {
      "x": -2,
      "y": 2,
      "z": -4,
      "name": "Soil_Ash"
    },
    {
      "x": -2,
      "y": 3,
      "z": -4,
      "name": "Plant_Bramble_Dead_Twisted"
    },
    {
      "x": -2,
      "y": 0,
      "z": -3,
      "name": "Soil_Ash"
    },
    {
      "x": -2,
      "y": 1,
      "z": -3,
      "name": "Soil_Sand_Ashen"
    },
    {
      "x": -2,
      "y": 2,
      "z": -3,
      "name": "Soil_Ash"
    },
    {
      "x": -2,
      "y": 3,
      "z": -3,
      "name": "Plant_Flower_Bushy_Poisoned"
    },
    {
      "x": -2,
      "y": 0,
      "z": -2,
      "name": "Soil_Sand_Ashen"
    },
    {
      "x": -2,
      "y": 1,
      "z": -2,
      "name": "Soil_Sand_Ashen"
    },
    {
      "x": -2,
      "y": 2,
      "z": -2,
      "name": "Soil_Ash"
    },
    {
      "x": -2,
      "y": 3,
      "z": -2,
      "name": "Plant_Flower_Common_Poisoned2"
    },
    {
      "x": -2,
      "y": 0,
      "z": -1,
      "name": "Soil_Sand_Ashen"
    },
    {
      "x": -2,
      "y": 1,
      "z": -1,
      "name": "Soil_Ash"
    },
    {
      "x": -2,
      "y": 2,
      "z": -1,
      "name": "Rock_Crystal_Purple_Block"
    },
    {
      "x": -2,
      "y": 3,
      "z": -1,
      "name": "Rock_Crystal_Purple_Medium"
    },
    {
      "x": -2,
      "y": 4,
      "z": -1,
      "name": "Rock_Crystal_Purple_Medium",
      "rotation": 7
    },
    {
      "x": -2,
      "y": 0,
      "z": 0,
      "name": "Soil_Sand_Ashen"
    },
    {
      "x": -2,
      "y": 1,
      "z": 0,
      "name": "Soil_Sand_Ashen"
    },
    {
      "x": -2,
      "y": 2,
      "z": 0,
      "name": "Rock_Crystal_Purple_Block"
    },
    {
      "x": -2,
      "y": 3,
      "z": 0,
      "name": "Rock_Crystal_Purple_Medium"
    },
    {
      "x": -2,
      "y": 4,
      "z": 0,
      "name": "Rock_Crystal_Purple_Medium",
      "rotation": 7
    },
    {
      "x": -2,
      "y": 5,
      "z": 0,
      "name": "Rock_Crystal_Purple_Medium",
      "rotation": 7
    },
    {
      "x": -2,
      "y": 0,
      "z": 1,
      "name": "Soil_Ash"
    },
    {
      "x": -2,
      "y": 1,
      "z": 1,
      "name": "Soil_Ash"
    },
    {
      "x": -2,
      "y": 2,
      "z": 1,
      "name": "Rock_Crystal_Purple_Block"
    },
    {
      "x": -2,
      "y": 3,
      "z": 1,
      "name": "Rock_Crystal_Purple_Medium",
      "rotation": 7
    },
    {
      "x": -2,
      "y": 4,
      "z": 1,
      "name": "Rock_Crystal_Purple_Medium",
      "rotation": 7
    },
    {
      "x": -2,
      "y": 0,
      "z": 2,
      "name": "Soil_Ash"
    },
    {
      "x": -2,
      "y": 1,
      "z": 2,
      "name": "Soil_Sand_Ashen"
    },
    {
      "x": -2,
      "y": 2,
      "z": 2,
      "name": "Soil_Ash"
    },
    {
      "x": -2,
      "y": 0,
      "z": 3,
      "name": "Soil_Sand_Ashen"
    },
    {
      "x": -2,
      "y": 1,
      "z": 3,
      "name": "Soil_Ash"
    },
    {
      "x": -2,
      "y": 2,
      "z": 3,
      "name": "Soil_Ash"
    },
    {
      "x": -2,
      "y": 3,
      "z": 3,
      "name": "Plant_Flower_Bushy_Violet"
    },
    {
      "x": -2,
      "y": 0,
      "z": 4,
      "name": "Soil_Ash"
    },
    {
      "x": -2,
      "y": 1,
      "z": 4,
      "name": "Soil_Ash"
    },
    {
      "x": -2,
      "y": 2,
      "z": 4,
      "name": "Soil_Ash"
    },
    {
      "x": -2,
      "y": 0,
      "z": 5,
      "name": "Soil_Ash"
    },
    {
      "x": -2,
      "y": 1,
      "z": 5,
      "name": "Soil_Ash"
    },
    {
      "x": -2,
      "y": 2,
      "z": 5,
      "name": "Plant_Flower_Bushy_Poisoned"
    },
    {
      "x": -2,
      "y": 0,
      "z": 6,
      "name": "Soil_Sand_Ashen"
    },
    {
      "x": -2,
      "y": 1,
      "z": 6,
      "name": "Soil_Ash"
    },
    {
      "x": -2,
      "y": 2,
      "z": 6,
      "name": "Plant_Flower_Common_Poisoned2"
    },
    {
      "x": -2,
      "y": 0,
      "z": 7,
      "name": "Soil_Ash"
    },
    {
      "x": -1,
      "y": 0,
      "z": -6,
      "name": "Soil_Ash"
    },
    {
      "x": -1,
      "y": 0,
      "z": -5,
      "name": "Soil_Sand_Ashen"
    },
    {
      "x": -1,
      "y": 1,
      "z": -5,
      "name": "Soil_Ash"
    },
    {
      "x": -1,
      "y": 0,
      "z": -4,
      "name": "Soil_Ash"
    },
    {
      "x": -1,
      "y": 1,
      "z": -4,
      "name": "Soil_Ash"
    },
    {
      "x": -1,
      "y": 2,
      "z": -4,
      "name": "Plant_Bush_Dead_Tall",
      "support": 15
    },
    {
      "x": -1,
      "y": 0,
      "z": -3,
      "name": "Soil_Sand_Ashen"
    },
    {
      "x": -1,
      "y": 1,
      "z": -3,
      "name": "Soil_Sand_Ashen"
    },
    {
      "x": -1,
      "y": 2,
      "z": -3,
      "name": "Soil_Ash"
    },
    {
      "x": -1,
      "y": 3,
      "z": -3,
      "name": "Plant_Bramble_Dead_Twisted"
    },
    {
      "x": -1,
      "y": 0,
      "z": -2,
      "name": "Soil_Ash"
    },
    {
      "x": -1,
      "y": 1,
      "z": -2,
      "name": "Soil_Ash"
    },
    {
      "x": -1,
      "y": 2,
      "z": -2,
      "name": "Soil_Ash"
    },
    {
      "x": -1,
      "y": 3,
      "z": -2,
      "name": "Rock_Crystal_Purple_Medium",
      "rotation": 6
    },
    {
      "x": -1,
      "y": 4,
      "z": -2,
      "name": "Rock_Crystal_Purple_Medium",
      "rotation": 6
    },
    {
      "x": -1,
      "y": 0,
      "z": -1,
      "name": "Soil_Ash"
    },
    {
      "x": -1,
      "y": 1,
      "z": -1,
      "name": "Soil_Sand_Ashen"
    },
    {
      "x": -1,
      "y": 2,
      "z": -1,
      "name": "Rock_Crystal_Purple_Block"
    },
    {
      "x": -1,
      "y": 3,
      "z": -1,
      "name": "Rock_Crystal_Purple_Block"
    },
    {
      "x": -1,
      "y": 4,
      "z": -1,
      "name": "Rock_Crystal_Purple_Block"
    },
    {
      "x": -1,
      "y": 5,
      "z": -1,
      "name": "Rock_Crystal_Purple_Large",
      "rotation": 7
    },
    {
      "x": -1,
      "y": 0,
      "z": 0,
      "name": "Soil_Sand_Ashen"
    },
    {
      "x": -1,
      "y": 1,
      "z": 0,
      "name": "Rock_Crystal_Purple_Block"
    },
    {
      "x": -1,
      "y": 2,
      "z": 0,
      "name": "Rock_Crystal_Purple_Block"
    },
    {
      "x": -1,
      "y": 3,
      "z": 0,
      "name": "Rock_Crystal_Purple_Block"
    },
    {
      "x": -1,
      "y": 4,
      "z": 0,
      "name": "Rock_Crystal_Purple_Block"
    },
    {
      "x": -1,
      "y": 5,
      "z": 0,
      "name": "Rock_Crystal_Purple_Block"
    },
    {
      "x": -1,
      "y": 6,
      "z": 0,
      "name": "Rock_Crystal_Purple_Large",
      "rotation": 7
    },
    {
      "x": -1,
      "y": 7,
      "z": 0,
      "name": "Rock_Crystal_Purple_Small",
      "rotation": 7
    },
    {
      "x": -1,
      "y": 0,
      "z": 1,
      "name": "Soil_Ash"
    },
    {
      "x": -1,
      "y": 1,
      "z": 1,
      "name": "Rock_Crystal_Purple_Block"
    },
    {
      "x": -1,
      "y": 2,
      "z": 1,
      "name": "Rock_Crystal_Purple_Block"
    },
    {
      "x": -1,
      "y": 3,
      "z": 1,
      "name": "Rock_Crystal_Purple_Block"
    },
    {
      "x": -1,
      "y": 4,
      "z": 1,
      "name": "Rock_Crystal_Purple_Block"
    },
    {
      "x": -1,
      "y": 5,
      "z": 1,
      "name": "Rock_Crystal_Purple_Large",
      "rotation": 7
    },
    {
      "x": -1,
      "y": 6,
      "z": 1,
      "name": "Rock_Crystal_Purple_Small",
      "rotation": 7
    },
    {
      "x": -1,
      "y": 0,
      "z": 2,
      "name": "Soil_Sand_Ashen"
    },
    {
      "x": -1,
      "y": 1,
      "z": 2,
      "name": "Rock_Crystal_Purple_Block"
    },
    {
      "x": -1,
      "y": 2,
      "z": 2,
      "name": "Rock_Crystal_Purple_Block"
    },
    {
      "x": -1,
      "y": 3,
      "z": 2,
      "name": "Rock_Crystal_Purple_Medium",
      "rotation": 4
    },
    {
      "x": -1,
      "y": 4,
      "z": 2,
      "name": "Rock_Crystal_Purple_Small",
      "rotation": 4
    },
    {
      "x": -1,
      "y": 0,
      "z": 3,
      "name": "Soil_Ash"
    },
    {
      "x": -1,
      "y": 1,
      "z": 3,
      "name": "Soil_Sand_Ashen"
    },
    {
      "x": -1,
      "y": 2,
      "z": 3,
      "name": "Soil_Ash"
    },
    {
      "x": -1,
      "y": 0,
      "z": 4,
      "name": "Soil_Sand_Ashen"
    },
    {
      "x": -1,
      "y": 1,
      "z": 4,
      "name": "Soil_Ash"
    },
    {
      "x": -1,
      "y": 2,
      "z": 4,
      "name": "Plant_Flower_Bushy_Poisoned"
    },
    {
      "x": -1,
      "y": 0,
      "z": 5,
      "name": "Soil_Ash"
    },
    {
      "x": -1,
      "y": 1,
      "z": 5,
      "name": "Soil_Ash"
    },
    {
      "x": -1,
      "y": 0,
      "z": 6,
      "name": "Soil_Ash"
    },
    {
      "x": 0,
      "y": 0,
      "z": -5,
      "name": "Soil_Ash"
    },
    {
      "x": 0,
      "y": 0,
      "z": -4,
      "name": "Soil_Sand_Ashen"
    },
    {
      "x": 0,
      "y": 1,
      "z": -4,
      "name": "Soil_Ash"
    },
    {
      "x": 0,
      "y": 0,
      "z": -3,
      "name": "Soil_Sand_Ashen"
    },
    {
      "x": 0,
      "y": 1,
      "z": -3,
      "name": "Soil_Sand_Ashen"
    },
    {
      "x": 0,
      "y": 2,
      "z": -3,
      "name": "Plant_Bramble_Dead_Twisted"
    },
    {
      "x": 0,
      "y": 0,
      "z": -2,
      "name": "Soil_Sand_Ashen"
    },
    {
      "x": 0,
      "y": 1,
      "z": -2,
      "name": "Soil_Sand_Ashen"
    },
    {
      "x": 0,
      "y": 2,
      "z": -2,
      "name": "Soil_Ash"
    },
    {
      "x": 0,
      "y": 3,
      "z": -2,
      "name": "Rock_Crystal_Purple_Medium",
      "rotation": 6
    },
    {
      "x": 0,
      "y": 5,
      "z": -2,
      "name": "Rock_Crystal_Purple_Medium",
      "rotation": 6
    },
    {
      "x": 0,
      "y": 0,
      "z": -1,
      "name": "Soil_Ash"
    },
    {
      "x": 0,
      "y": 1,
      "z": -1,
      "name": "Rock_Crystal_Purple_Block"
    },
    {
      "x": 0,
      "y": 2,
      "z": -1,
      "name": "Rock_Crystal_Purple_Block"
    },
    {
      "x": 0,
      "y": 3,
      "z": -1,
      "name": "Rock_Crystal_Purple_Block"
    },
    {
      "x": 0,
      "y": 4,
      "z": -1,
      "name": "Rock_Crystal_Purple_Block"
    },
    {
      "x": 0,
      "y": 5,
      "z": -1,
      "name": "Rock_Crystal_Purple_Block"
    },
    {
      "x": 0,
      "y": 6,
      "z": -1,
      "name": "Rock_Crystal_Purple_Medium"
    },
    {
      "x": 0,
      "y": 7,
      "z": -1,
      "name": "Rock_Crystal_Purple_Small",
      "rotation": 6
    },
    {
      "x": 0,
      "y": 0,
      "z": 0,
      "name": "Soil_Ash"
    },
    {
      "x": 0,
      "y": 1,
      "z": 0,
      "name": "Rock_Crystal_Purple_Block"
    },
    {
      "x": 0,
      "y": 2,
      "z": 0,
      "name": "Rock_Crystal_Purple_Block"
    },
    {
      "x": 0,
      "y": 3,
      "z": 0,
      "name": "Rock_Crystal_Purple_Block"
    },
    {
      "x": 0,
      "y": 4,
      "z": 0,
      "name": "Rock_Crystal_Purple_Block"
    },
    {
      "x": 0,
      "y": 5,
      "z": 0,
      "name": "Rock_Crystal_Purple_Block"
    },
    {
      "x": 0,
      "y": 6,
      "z": 0,
      "name": "Rock_Crystal_Purple_Block"
    },
    {
      "x": 0,
      "y": 7,
      "z": 0,
      "name": "Rock_Crystal_Purple_Block"
    },
    {
      "x": 0,
      "y": 8,
      "z": 0,
      "name": "Rock_Crystal_Purple_Large"
    },
    {
      "x": 0,
      "y": 0,
      "z": 1,
      "name": "Rock_Crystal_Purple_Block"
    },
    {
      "x": 0,
      "y": 1,
      "z": 1,
      "name": "Rock_Crystal_Purple_Block"
    },
    {
      "x": 0,
      "y": 2,
      "z": 1,
      "name": "Rock_Crystal_Purple_Block"
    },
    {
      "x": 0,
      "y": 3,
      "z": 1,
      "name": "Rock_Crystal_Purple_Block"
    },
    {
      "x": 0,
      "y": 4,
      "z": 1,
      "name": "Rock_Crystal_Purple_Block"
    },
    {
      "x": 0,
      "y": 5,
      "z": 1,
      "name": "Rock_Crystal_Purple_Block"
    },
    {
      "x": 0,
      "y": 6,
      "z": 1,
      "name": "Rock_Crystal_Purple_Block"
    },
    {
      "x": 0,
      "y": 7,
      "z": 1,
      "name": "Rock_Crystal_Purple_Large",
      "rotation": 4
    },
    {
      "x": 0,
      "y": 0,
      "z": 2,
      "name": "Soil_Ash"
    },
    {
      "x": 0,
      "y": 1,
      "z": 2,
      "name": "Rock_Crystal_Purple_Block"
    },
    {
      "x": 0,
      "y": 2,
      "z": 2,
      "name": "Rock_Crystal_Purple_Block"
    },
    {
      "x": 0,
      "y": 3,
      "z": 2,
      "name": "Rock_Crystal_Purple_Medium"
    },
    {
      "x": 0,
      "y": 4,
      "z": 2,
      "name": "Rock_Crystal_Purple_Medium",
      "rotation": 4
    },
    {
      "x": 0,
      "y": 5,
      "z": 2,
      "name": "Rock_Crystal_Purple_Small",
      "rotation": 4
    },
    {
      "x": 0,
      "y": 6,
      "z": 2,
      "name": "Rock_Crystal_Purple_Small",
      "rotation": 4
    },
    {
      "x": 0,
      "y": 0,
      "z": 3,
      "name": "Soil_Sand_Ashen"
    },
    {
      "x": 0,
      "y": 1,
      "z": 3,
      "name": "Soil_Sand_Ashen"
    },
    {
      "x": 0,
      "y": 2,
      "z": 3,
      "name": "Rock_Crystal_Purple_Medium",
      "rotation": 4
    },
    {
      "x": 0,
      "y": 0,
      "z": 4,
      "name": "Soil_Sand_Ashen"
    },
    {
      "x": 0,
      "y": 1,
      "z": 4,
      "name": "Soil_Sand_Ashen"
    },
    {
      "x": 0,
      "y": 0,
      "z": 5,
      "name": "Soil_Sand_Ashen"
    },
    {
      "x": 1,
      "y": 0,
      "z": -4,
      "name": "Soil_Sand_Ashen"
    },
    {
      "x": 1,
      "y": 0,
      "z": -3,
      "name": "Soil_Sand_Ashen"
    },
    {
      "x": 1,
      "y": 1,
      "z": -3,
      "name": "Soil_Sand_Ashen"
    },
    {
      "x": 1,
      "y": 0,
      "z": -2,
      "name": "Soil_Sand_Ashen"
    },
    {
      "x": 1,
      "y": 1,
      "z": -2,
      "name": "Soil_Ash"
    },
    {
      "x": 1,
      "y": 2,
      "z": -2,
      "name": "Plant_Bramble_Dead_Twisted"
    },
    {
      "x": 1,
      "y": 0,
      "z": -1,
      "name": "Soil_Ash"
    },
    {
      "x": 1,
      "y": 1,
      "z": -1,
      "name": "Soil_Ash"
    },
    {
      "x": 1,
      "y": 3,
      "z": -1,
      "name": "Rock_Crystal_Purple_Large",
      "rotation": 6
    },
    {
      "x": 1,
      "y": 4,
      "z": -1,
      "name": "Rock_Crystal_Purple_Medium",
      "rotation": 6
    },
    {
      "x": 1,
      "y": 5,
      "z": -1,
      "name": "Rock_Crystal_Purple_Medium",
      "rotation": 5
    },
    {
      "x": 1,
      "y": 0,
      "z": 0,
      "name": "Soil_Ash"
    },
    {
      "x": 1,
      "y": 1,
      "z": 0,
      "name": "Rock_Crystal_Purple_Block"
    },
    {
      "x": 1,
      "y": 2,
      "z": 0,
      "name": "Rock_Crystal_Purple_Block"
    },
    {
      "x": 1,
      "y": 3,
      "z": 0,
      "name": "Rock_Crystal_Purple_Block"
    },
    {
      "x": 1,
      "y": 4,
      "z": 0,
      "name": "Rock_Crystal_Purple_Block"
    },
    {
      "x": 1,
      "y": 5,
      "z": 0,
      "name": "Rock_Crystal_Purple_Small"
    },
    {
      "x": 1,
      "y": 6,
      "z": 0,
      "name": "Rock_Crystal_Purple_Medium",
      "rotation": 5
    },
    {
      "x": 1,
      "y": 7,
      "z": 0,
      "name": "Rock_Crystal_Purple_Medium",
      "rotation": 5
    },
    {
      "x": 1,
      "y": 0,
      "z": 1,
      "name": "Soil_Sand_Ashen"
    },
    {
      "x": 1,
      "y": 1,
      "z": 1,
      "name": "Rock_Crystal_Purple_Block"
    },
    {
      "x": 1,
      "y": 2,
      "z": 1,
      "name": "Rock_Crystal_Purple_Block"
    },
    {
      "x": 1,
      "y": 3,
      "z": 1,
      "name": "Rock_Crystal_Purple_Block"
    },
    {
      "x": 1,
      "y": 4,
      "z": 1,
      "name": "Rock_Crystal_Purple_Block"
    },
    {
      "x": 1,
      "y": 5,
      "z": 1,
      "name": "Rock_Crystal_Purple_Medium",
      "rotation": 5
    },
    {
      "x": 1,
      "y": 6,
      "z": 1,
      "name": "Rock_Crystal_Purple_Medium",
      "rotation": 5
    },
    {
      "x": 1,
      "y": 0,
      "z": 2,
      "name": "Soil_Sand_Ashen"
    },
    {
      "x": 1,
      "y": 1,
      "z": 2,
      "name": "Rock_Crystal_Purple_Block"
    },
    {
      "x": 1,
      "y": 2,
      "z": 2,
      "name": "Rock_Crystal_Purple_Block"
    },
    {
      "x": 1,
      "y": 3,
      "z": 2,
      "name": "Rock_Crystal_Purple_Block"
    },
    {
      "x": 1,
      "y": 4,
      "z": 2,
      "name": "Rock_Crystal_Purple_Medium"
    },
    {
      "x": 1,
      "y": 0,
      "z": 3,
      "name": "Rock_Crystal_Purple_Block"
    },
    {
      "x": 1,
      "y": 3,
      "z": 3,
      "name": "Rock_Crystal_Purple_Medium",
      "rotation": 4
    },
    {
      "x": 1,
      "y": 0,
      "z": 4,
      "name": "Soil_Ash"
    },
    {
      "x": 2,
      "y": 0,
      "z": -3,
      "name": "Soil_Ash"
    },
    {
      "x": 2,
      "y": 0,
      "z": -2,
      "name": "Soil_Ash"
    },
    {
      "x": 2,
      "y": 1,
      "z": -2,
      "name": "Plant_Bramble_Dead_Twisted"
    },
    {
      "x": 2,
      "y": 0,
      "z": -1,
      "name": "Soil_Ash"
    },
    {
      "x": 2,
      "y": 1,
      "z": -1,
      "name": "Soil_Ash"
    },
    {
      "x": 2,
      "y": 2,
      "z": -1,
      "name": "Plant_Flower_Bushy_Poisoned"
    },
    {
      "x": 2,
      "y": 0,
      "z": 0,
      "name": "Soil_Sand_Ashen"
    },
    {
      "x": 2,
      "y": 1,
      "z": 0,
      "name": "Rock_Crystal_Purple_Block"
    },
    {
      "x": 2,
      "y": 2,
      "z": 0,
      "name": "Rock_Crystal_Purple_Block"
    },
    {
      "x": 2,
      "y": 3,
      "z": 0,
      "name": "Rock_Crystal_Purple_Medium"
    },
    {
      "x": 2,
      "y": 4,
      "z": 0,
      "name": "Rock_Crystal_Purple_Medium",
      "rotation": 5
    },
    {
      "x": 2,
      "y": 0,
      "z": 1,
      "name": "Soil_Sand_Ashen"
    },
    {
      "x": 2,
      "y": 1,
      "z": 1,
      "name": "Soil_Ash"
    },
    {
      "x": 2,
      "y": 2,
      "z": 1,
      "name": "Rock_Crystal_Purple_Block"
    },
    {
      "x": 2,
      "y": 3,
      "z": 1,
      "name": "Rock_Crystal_Purple_Medium",
      "rotation": 5
    },
    {
      "x": 2,
      "y": 4,
      "z": 1,
      "name": "Rock_Crystal_Purple_Medium",
      "rotation": 5
    },
    {
      "x": 2,
      "y": 0,
      "z": 2,
      "name": "Soil_Sand_Ashen"
    },
    {
      "x": 2,
      "y": 1,
      "z": 2,
      "name": "Rock_Crystal_Purple_Block"
    },
    {
      "x": 2,
      "y": 3,
      "z": 2,
      "name": "Rock_Crystal_Purple_Medium",
      "rotation": 5
    },
    {
      "x": 2,
      "y": 0,
      "z": 3,
      "name": "Soil_Ash"
    },
    {
      "x": 2,
      "y": 1,
      "z": 3,
      "name": "Soil_Sand_Ashen"
    },
    {
      "x": 2,
      "y": 0,
      "z": 4,
      "name": "Soil_Sand_Ashen"
    },
    {
      "x": 3,
      "y": 0,
      "z": -3,
      "name": "Soil_Ash"
    },
    {
      "x": 3,
      "y": 0,
      "z": -2,
      "name": "Soil_Ash"
    },
    {
      "x": 3,
      "y": 1,
      "z": -2,
      "name": "Soil_Ash"
    },
    {
      "x": 3,
      "y": 0,
      "z": -1,
      "name": "Soil_Sand_Ashen"
    },
    {
      "x": 3,
      "y": 1,
      "z": -1,
      "name": "Soil_Ash"
    },
    {
      "x": 3,
      "y": 2,
      "z": -1,
      "name": "Plant_Flower_Common_Poisoned2"
    },
    {
      "x": 3,
      "y": 0,
      "z": 0,
      "name": "Soil_Ash"
    },
    {
      "x": 3,
      "y": 1,
      "z": 0,
      "name": "Soil_Sand_Ashen"
    },
    {
      "x": 3,
      "y": 2,
      "z": 0,
      "name": "Soil_Ash"
    },
    {
      "x": 3,
      "y": 0,
      "z": 1,
      "name": "Soil_Sand_Ashen"
    },
    {
      "x": 3,
      "y": 1,
      "z": 1,
      "name": "Soil_Sand_Ashen"
    },
    {
      "x": 3,
      "y": 2,
      "z": 1,
      "name": "Soil_Ash"
    },
    {
      "x": 3,
      "y": 3,
      "z": 1,
      "name": "Plant_Flower_Common_Poisoned2"
    },
    {
      "x": 3,
      "y": 0,
      "z": 2,
      "name": "Soil_Ash"
    },
    {
      "x": 3,
      "y": 1,
      "z": 2,
      "name": "Soil_Sand_Ashen"
    },
    {
      "x": 3,
      "y": 2,
      "z": 2,
      "name": "Soil_Ash"
    },
    {
      "x": 3,
      "y": 3,
      "z": 2,
      "name": "Plant_Flower_Bushy_Violet"
    },
    {
      "x": 3,
      "y": 0,
      "z": 3,
      "name": "Soil_Sand_Ashen"
    },
    {
      "x": 3,
      "y": 1,
      "z": 3,
      "name": "Soil_Sand_Ashen"
    },
    {
      "x": 3,
      "y": 0,
      "z": 4,
      "name": "Soil_Sand_Ashen"
    },
    {
      "x": 3,
      "y": 1,
      "z": 4,
      "name": "Soil_Ash"
    },
    {
      "x": 3,
      "y": 2,
      "z": 4,
      "name": "Plant_Bush_Dead_Tall",
      "support": 15
    },
    {
      "x": 3,
      "y": 0,
      "z": 5,
      "name": "Soil_Ash"
    },
    {
      "x": 4,
      "y": 0,
      "z": -3,
      "name": "Soil_Ash"
    },
    {
      "x": 4,
      "y": 0,
      "z": -2,
      "name": "Soil_Sand_Ashen"
    },
    {
      "x": 4,
      "y": 1,
      "z": -2,
      "name": "Soil_Ash"
    },
    {
      "x": 4,
      "y": 0,
      "z": -1,
      "name": "Soil_Ash"
    },
    {
      "x": 4,
      "y": 1,
      "z": -1,
      "name": "Soil_Sand_Ashen"
    },
    {
      "x": 4,
      "y": 2,
      "z": -1,
      "name": "Soil_Ash"
    },
    {
      "x": 4,
      "y": 3,
      "z": -1,
      "name": "Plant_Flower_Bushy_Poisoned"
    },
    {
      "x": 4,
      "y": 0,
      "z": 0,
      "name": "Soil_Sand_Ashen"
    },
    {
      "x": 4,
      "y": 1,
      "z": 0,
      "name": "Soil_Ash"
    },
    {
      "x": 4,
      "y": 2,
      "z": 0,
      "name": "Soil_Ash"
    },
    {
      "x": 4,
      "y": 0,
      "z": 1,
      "name": "Soil_Sand_Ashen"
    },
    {
      "x": 4,
      "y": 1,
      "z": 1,
      "name": "Soil_Ash"
    },
    {
      "x": 4,
      "y": 2,
      "z": 1,
      "name": "Soil_Ash"
    },
    {
      "x": 4,
      "y": 0,
      "z": 2,
      "name": "Soil_Ash"
    },
    {
      "x": 4,
      "y": 1,
      "z": 2,
      "name": "Soil_Ash"
    },
    {
      "x": 4,
      "y": 2,
      "z": 2,
      "name": "Soil_Ash"
    },
    {
      "x": 4,
      "y": 0,
      "z": 3,
      "name": "Soil_Ash"
    },
    {
      "x": 4,
      "y": 1,
      "z": 3,
      "name": "Soil_Sand_Ashen"
    },
    {
      "x": 4,
      "y": 2,
      "z": 3,
      "name": "Soil_Ash"
    },
    {
      "x": 4,
      "y": 3,
      "z": 3,
      "name": "Plant_Flower_Bushy_Poisoned"
    },
    {
      "x": 4,
      "y": 0,
      "z": 4,
      "name": "Soil_Sand_Ashen"
    },
    {
      "x": 4,
      "y": 1,
      "z": 4,
      "name": "Soil_Ash"
    },
    {
      "x": 4,
      "y": 0,
      "z": 5,
      "name": "Soil_Sand_Ashen"
    },
    {
      "x": 5,
      "y": 0,
      "z": -3,
      "name": "Soil_Sand_Ashen"
    },
    {
      "x": 5,
      "y": 0,
      "z": -2,
      "name": "Soil_Sand_Ashen"
    },
    {
      "x": 5,
      "y": 1,
      "z": -2,
      "name": "Soil_Sand_Ashen"
    },
    {
      "x": 5,
      "y": 0,
      "z": -1,
      "name": "Soil_Ash"
    },
    {
      "x": 5,
      "y": 1,
      "z": -1,
      "name": "Soil_Ash"
    },
    {
      "x": 5,
      "y": 0,
      "z": 0,
      "name": "Soil_Sand_Ashen"
    },
    {
      "x": 5,
      "y": 1,
      "z": 0,
      "name": "Soil_Sand_Ashen"
    },
    {
      "x": 5,
      "y": 2,
      "z": 0,
      "name": "Soil_Ash"
    },
    {
      "x": 5,
      "y": 3,
      "z": 0,
      "name": "Plant_Flower_Bushy_Poisoned"
    },
    {
      "x": 5,
      "y": 0,
      "z": 1,
      "name": "Soil_Sand_Ashen"
    },
    {
      "x": 5,
      "y": 1,
      "z": 1,
      "name": "Soil_Ash"
    },
    {
      "x": 5,
      "y": 2,
      "z": 1,
      "name": "Soil_Ash"
    },
    {
      "x": 5,
      "y": 3,
      "z": 1,
      "name": "Plant_Bush_Dead_Tall",
      "support": 15
    },
    {
      "x": 5,
      "y": 0,
      "z": 2,
      "name": "Soil_Sand_Ashen"
    },
    {
      "x": 5,
      "y": 1,
      "z": 2,
      "name": "Soil_Ash"
    },
    {
      "x": 5,
      "y": 2,
      "z": 2,
      "name": "Soil_Ash"
    },
    {
      "x": 5,
      "y": 3,
      "z": 2,
      "name": "Plant_Bush_Dead_Tall",
      "support": 15
    },
    {
      "x": 5,
      "y": 0,
      "z": 3,
      "name": "Soil_Ash"
    },
    {
      "x": 5,
      "y": 1,
      "z": 3,
      "name": "Soil_Ash"
    },
    {
      "x": 5,
      "y": 0,
      "z": 4,
      "name": "Soil_Sand_Ashen"
    },
    {
      "x": 5,
      "y": 1,
      "z": 4,
      "name": "Soil_Ash"
    },
    {
      "x": 5,
      "y": 0,
      "z": 5,
      "name": "Soil_Sand_Ashen"
    },
    {
      "x": 6,
      "y": 0,
      "z": -2,
      "name": "Soil_Sand_Ashen"
    },
    {
      "x": 6,
      "y": 0,
      "z": -1,
      "name": "Soil_Sand_Ashen"
    },
    {
      "x": 6,
      "y": 1,
      "z": -1,
      "name": "Soil_Sand_Ashen"
    },
    {
      "x": 6,
      "y": 0,
      "z": 0,
      "name": "Soil_Sand_Ashen"
    },
    {
      "x": 6,
      "y": 1,
      "z": 0,
      "name": "Soil_Ash"
    },
    {
      "x": 6,
      "y": 0,
      "z": 1,
      "name": "Soil_Ash"
    },
    {
      "x": 6,
      "y": 1,
      "z": 1,
      "name": "Soil_Sand_Ashen"
    },
    {
      "x": 6,
      "y": 2,
      "z": 1,
      "name": "Soil_Ash"
    },
    {
      "x": 6,
      "y": 0,
      "z": 2,
      "name": "Soil_Sand_Ashen"
    },
    {
      "x": 6,
      "y": 1,
      "z": 2,
      "name": "Soil_Sand_Ashen"
    },
    {
      "x": 6,
      "y": 0,
      "z": 3,
      "name": "Soil_Sand_Ashen"
    },
    {
      "x": 6,
      "y": 1,
      "z": 3,
      "name": "Soil_Sand_Ashen"
    },
    {
      "x": 6,
      "y": 0,
      "z": 4,
      "name": "Soil_Ash"
    },
    {
      "x": 7,
      "y": 0,
      "z": -1,
      "name": "Soil_Sand_Ashen"
    },
    {
      "x": 7,
      "y": 0,
      "z": 0,
      "name": "Soil_Sand_Ashen"
    },
    {
      "x": 7,
      "y": 1,
      "z": 0,
      "name": "Soil_Sand_Ashen"
    },
    {
      "x": 7,
      "y": 0,
      "z": 1,
      "name": "Soil_Sand_Ashen"
    },
    {
      "x": 7,
      "y": 1,
      "z": 1,
      "name": "Soil_Ash"
    },
    {
      "x": 7,
      "y": 0,
      "z": 2,
      "name": "Soil_Ash"
    },
    {
      "x": 7,
      "y": 1,
      "z": 2,
      "name": "Soil_Sand_Ashen"
    },
    {
      "x": 7,
      "y": 0,
      "z": 3,
      "name": "Soil_Ash"
    },
    {
      "x": 8,
      "y": 0,
      "z": 0,
      "name": "Soil_Ash"
    },
    {
      "x": 8,
      "y": 0,
      "z": 1,
      "name": "Soil_Ash"
    },
    {
      "x": 8,
      "y": 0,
      "z": 2,
      "name": "Soil_Ash"
    }
  ]
}