{
  "version": 8,
  "blockIdVersion": 11,
  "anchorX": 0,
  "anchorY": 0,
  "anchorZ": 0,
  "blocks": [
    {
      "x": -7,
      "y": 0,
      "z": -4,
      "name": "Soil_Sand_Ashen"
    },
    {
      "x": -7,
      "y": 0,
      "z": -3,
      "name": "Soil_Sand_Ashen"
    },
    {
      "x": -7,
      "y": 0,
      "z": -2,
      "name": "Soil_Ash"
    },
    {
      "x": -6,
      "y": 0,
      "z": -5,
      "name": "Soil_Ash"
    },
    {
      "x": -6,
      "y": 0,
      "z": -4,
      "name": "Soil_Sand_Ashen"
    },
    {
      "x": -6,
      "y": 1,
      "z": -4,
      "name": "Soil_Ash"
    },
    {
      "x": -6,
      "y": 2,
      "z": -4,
      "name": "Plant_Flower_Bushy_Poisoned"
    },
    {
      "x": -6,
      "y": 0,
      "z": -3,
      "name": "Soil_Sand_Ashen"
    },
    {
      "x": -6,
      "y": 1,
      "z": -3,
      "name": "Soil_Ash"
    },
    {
      "x": -6,
      "y": 0,
      "z": -2,
      "name": "Soil_Sand_Ashen"
    },
    {
      "x": -6,
      "y": 1,
      "z": -2,
      "name": "Soil_Ash"
    },
    {
      "x": -6,
      "y": 0,
      "z": -1,
      "name": "Soil_Ash"
    },
    {
      "x": -6,
      "y": 0,
      "z": 1,
      "name": "Soil_Ash"
    },
    {
      "x": -6,
      "y": 0,
      "z": 2,
      "name": "Soil_Sand_Ashen"
    },
    {
      "x": -6,
      "y": 0,
      "z": 3,
      "name": "Soil_Sand_Ashen"
    },
    {
      "x": -5,
      "y": 0,
      "z": -6,
      "name": "Soil_Sand_Ashen"
    },
    {
      "x": -5,
      "y": 0,
      "z": -5,
      "name": "Soil_Sand_Ashen"
    },
    {
      "x": -5,
      "y": 1,
      "z": -5,
      "name": "Soil_Ash"
    },
    {
      "x": -5,
      "y": 0,
      "z": -4,
      "name": "Soil_Sand_Ashen"
    },
    {
      "x": -5,
      "y": 1,
      "z": -4,
      "name": "Soil_Sand_Ashen"
    },
    {
      "x": -5,
      "y": 0,
      "z": -3,
      "name": "Soil_Ash"
    },
    {
      "x": -5,
      "y": 1,
      "z": -3,
      "name": "Soil_Sand_Ashen"
    },
    {
      "x": -5,
      "y": 2,
      "z": -3,
      "name": "Soil_Sand_Ashen"
    },
    {
      "x": -5,
      "y": 3,
      "z": -3,
      "name": "Plant_Moss_Rug_Pink",
      "support": 15
    },
    {
      "x": -5,
      "y": 0,
      "z": -2,
      "name": "Soil_Ash"
    },
    {
      "x": -5,
      "y": 1,
      "z": -2,
      "name": "Soil_Ash"
    },
    {
      "x": -5,
      "y": 0,
      "z": -1,
      "name": "Soil_Sand_Ashen"
    },
    {
      "x": -5,
      "y": 1,
      "z": -1,
      "name": "Soil_Sand_Ashen"
    },
    {
      "x": -5,
      "y": 0,
      "z": 0,
      "name": "Soil_Ash"
    },
    {
      "x": -5,
      "y": 0,
      "z": 1,
      "name": "Soil_Sand_Ashen"
    },
    {
      "x": -5,
      "y": 1,
      "z": 1,
      "name": "Soil_Sand_Ashen"
    },
    {
      "x": -5,
      "y": 0,
      "z": 2,
      "name": "Soil_Sand_Ashen"
    },
    {
      "x": -5,
      "y": 1,
      "z": 2,
      "name": "Soil_Sand_Ashen"
    },
    {
      "x": -5,
      "y": 0,
      "z": 3,
      "name": "Soil_Ash"
    },
    {
      "x": -5,
      "y": 1,
      "z": 3,
      "name": "Soil_Sand_Ashen"
    },
    {
      "x": -5,
      "y": 0,
      "z": 4,
      "name": "Soil_Ash"
    },
    {
      "x": -4,
      "y": 0,
      "z": -7,
      "name": "Soil_Ash"
    },
    {
      "x": -4,
      "y": 0,
      "z": -6,
      "name": "Soil_Sand_Ashen"
    },
    {
      "x": -4,
      "y": 1,
      "z": -6,
      "name": "Soil_Sand_Ashen"
    },
    {
      "x": -4,
      "y": 0,
      "z": -5,
      "name": "Soil_Ash"
    },
    {
      "x": -4,
      "y": 1,
      "z": -5,
      "name": "Soil_Sand_Ashen"
    },
    {
      "x": -4,
      "y": 2,
      "z": -5,
      "name": "Plant_Flower_Bushy_Poisoned"
    },
    {
      "x": -4,
      "y": 0,
      "z": -4,
      "name": "Soil_Ash"
    },
    {
      "x": -4,
      "y": 1,
      "z": -4,
      "name": "Soil_Ash"
    },
    {
      "x": -4,
      "y": 2,
      "z": -4,
      "name": "Plant_Moss_Rug_Pink",
      "support": 15
    },
    {
      "x": -4,
      "y": 0,
      "z": -3,
      "name": "Soil_Sand_Ashen"
    },
    {
      "x": -4,
      "y": 1,
      "z": -3,
      "name": "Soil_Sand_Ashen"
    },
    {
      "x": -4,
      "y": 2,
      "z": -3,
      "name": "Soil_Ash"
    },
    {
      "x": -4,
      "y": 3,
      "z": -3,
      "name": "Plant_Moss_Rug_Pink",
      "support": 15
    },
    {
      "x": -4,
      "y": 0,
      "z": -2,
      "name": "Soil_Ash"
    },
    {
      "x": -4,
      "y": 1,
      "z": -2,
      "name": "Soil_Sand_Ashen"
    },
    {
      "x": -4,
      "y": 2,
      "z": -2,
      "name": "Soil_Ash"
    },
    {
      "x": -4,
      "y": 3,
      "z": -2,
      "name": "Plant_Moss_Rug_Pink",
      "support": 15
    },
    {
      "x": -4,
      "y": 0,
      "z": -1,
      "name": "Soil_Ash"
    },
    {
      "x": -4,
      "y": 1,
      "z": -1,
      "name": "Soil_Ash"
    },
    {
      "x": -4,
      "y": 2,
      "z": -1,
      "name": "Plant_Flower_Bushy_Poisoned"
    },
    {
      "x": -4,
      "y": 0,
      "z": 0,
      "name": "Soil_Sand_Ashen"
    },
    {
      "x": -4,
      "y": 1,
      "z": 0,
      "name": "Soil_Ash"
    },
    {
      "x": -4,
      "y": 0,
      "z": 1,
      "name": "Soil_Sand_Ashen"
    },
    {
      "x": -4,
      "y": 1,
      "z": 1,
      "name": "Soil_Sand_Ashen"
    },
    {
      "x": -4,
      "y": 2,
      "z": 1,
      "name": "Plant_Flower_Bushy_Poisoned"
    },
    {
      "x": -4,
      "y": 0,
      "z": 2,
      "name": "Soil_Sand_Ashen"
    },
    {
      "x": -4,
      "y": 1,
      "z": 2,
      "name": "Soil_Ash"
    },
    {
      "x": -4,
      "y": 2,
      "z": 2,
      "name": "Soil_Ash"
    },
    {
      "x": -4,
      "y": 3,
      "z": 2,
      "name": "Plant_Moss_Rug_Pink",
      "support": 15
    },
    {
      "x": -4,
      "y": 0,
      "z": 3,
      "name": "Soil_Sand_Ashen"
    },
    {
      "x": -4,
      "y": 1,
      "z": 3,
      "name": "Soil_Ash"
    },
    {
      "x": -4,
      "y": 0,
      "z": 4,
      "name": "Soil_Sand_Ashen"
    },
    {
      "x": -4,
      "y": 1,
      "z": 4,
      "name": "Soil_Sand_Ashen"
    },
    {
      "x": -4,
      "y": 0,
      "z": 5,
      "name": "Soil_Ash"
    },
    {
      "x": -3,
      "y": 0,
      "z": -7,
      "name": "Soil_Ash"
    },
    {
      "x": -3,
      "y": 0,
      "z": -6,
      "name": "Soil_Ash"
    },
    {
      "x": -3,
      "y": 1,
      "z": -6,
      "name": "Soil_Sand_Ashen"
    },
    {
      "x": -3,
      "y": 0,
      "z": -5,
      "name": "Soil_Ash"
    },
    {
      "x": -3,
      "y": 1,
      "z": -5,
      "name": "Soil_Sand_Ashen"
    },
    {
      "x": -3,
      "y": 2,
      "z": -5,
      "name": "Soil_Ash"
    },
    {
      "x": -3,
      "y": 3,
      "z": -5,
      "name": "Plant_Moss_Rug_Pink",
      "support": 15
    },
    {
      "x": -3,
      "y": 0,
      "z": -4,
      "name": "Soil_Sand_Ashen"
    },
    {
      "x": -3,
      "y": 1,
      "z": -4,
      "name": "Soil_Ash"
    },
    {
      "x": -3,
      "y": 2,
      "z": -4,
      "name": "Soil_Ash"
    },
    {
      "x": -3,
      "y": 3,
      "z": -4,
      "name": "Plant_Moss_Rug_Pink",
      "support": 15
    },
    {
      "x": -3,
      "y": 0,
      "z": -3,
      "name": "Soil_Sand_Ashen"
    },
    {
      "x": -3,
      "y": 1,
      "z": -3,
      "name": "Soil_Ash"
    },
    {
      "x": -3,
      "y": 2,
      "z": -3,
      "name": "Soil_Ash"
    },
    {
      "x": -3,
      "y": 3,
      "z": -3,
      "name": "Plant_Moss_Rug_Pink",
      "support": 15
    },
    {
      "x": -3,
      "y": 0,
      "z": -2,
      "name": "Soil_Ash"
    },
    {
      "x": -3,
      "y": 1,
      "z": -2,
      "name": "Soil_Sand_Ashen"
    },
    {
      "x": -3,
      "y": 2,
      "z": -2,
      "name": "Soil_Ash"
    },
    {
      "x": -3,
      "y": 3,
      "z": -2,
      "name": "Plant_Moss_Rug_Pink",
      "support": 15
    },
    {
      "x": -3,
      "y": 0,
      "z": -1,
      "name": "Soil_Ash"
    },
    {
      "x": -3,
      "y": 1,
      "z": -1,
      "name": "Soil_Sand_Ashen"
    },
    {
      "x": -3,
      "y": 2,
      "z": -1,
      "name": "Soil_Ash"
    },
    {
      "x": -3,
      "y": 3,
      "z": -1,
      "name": "Plant_Moss_Rug_Pink",
      "support": 15
    },
    {
      "x": -3,
      "y": 0,
      "z": 0,
      "name": "Soil_Ash"
    },
    {
      "x": -3,
      "y": 1,
      "z": 0,
      "name": "Soil_Ash"
    },
    {
      "x": -3,
      "y": 2,
      "z": 0,
      "name": "Plant_Moss_Rug_Pink",
      "support": 15
    },
    {
      "x": -3,
      "y": 0,
      "z": 1,
      "name": "Soil_Sand_Ashen"
    },
    {
      "x": -3,
      "y": 1,
      "z": 1,
      "name": "Soil_Sand_Ashen"
    },
    {
      "x": -3,
      "y": 2,
      "z": 1,
      "name": "Soil_Ash"
    },
    {
      "x": -3,
      "y": 3,
      "z": 1,
      "name": "Plant_Moss_Rug_Pink",
      "support": 15
    },
    {
      "x": -3,
      "y": 0,
      "z": 2,
      "name": "Soil_Ash"
    },
    {
      "x": -3,
      "y": 1,
      "z": 2,
      "name": "Soil_Sand_Ashen"
    },
    {
      "x": -3,
      "y": 2,
      "z": 2,
      "name": "Soil_Ash"
    },
    {
      "x": -3,
      "y": 3,
      "z": 2,
      "name": "Plant_Moss_Rug_Pink",
      "support": 15
    },
    {
      "x": -3,
      "y": 0,
      "z": 3,
      "name": "Soil_Sand_Ashen"
    },
    {
      "x": -3,
      "y": 1,
      "z": 3,
      "name": "Soil_Sand_Ashen"
    },
    {
      "x": -3,
      "y": 2,
      "z": 3,
      "name": "Soil_Ash"
    },
    {
      "x": -3,
      "y": 3,
      "z": 3,
      "name": "Plant_Moss_Rug_Pink",
      "support": 15
    },
    {
      "x": -3,
      "y": 0,
      "z": 4,
      "name": "Soil_Ash"
    },
    {
      "x": -3,
      "y": 1,
      "z": 4,
      "name": "Soil_Ash"
    },
    {
      "x": -3,
      "y": 0,
      "z": 5,
      "name": "Soil_Sand_Ashen"
    },
    {
      "x": -3,
      "y": 1,
      "z": 5,
      "name": "Soil_Ash"
    },
    {
      "x": -3,
      "y": 0,
      "z": 6,
      "name": "Soil_Sand_Ashen"
    },
    {
      "x": -2,
      "y": 0,
      "z": -7,
      "name": "Soil_Sand_Ashen"
    },
    {
      "x": -2,
      "y": 0,
      "z": -6,
      "name": "Soil_Ash"
    },
    {
      "x": -2,
      "y": 1,
      "z": -6,
      "name": "Soil_Sand_Ashen"
    },
    {
      "x": -2,
      "y": 0,
      "z": -5,
      "name": "Soil_Sand_Ashen"
    },
    {
      "x": -2,
      "y": 1,
      "z": -5,
      "name": "Soil_Ash"
    },
    {
      "x": -2,
      "y": 0,
      "z": -4,
      "name": "Soil_Ash"
    },
    {
      "x": -2,
      "y": 1,
      "z": -4,
      "name": "Soil_Sand_Ashen"
    },
    {
      "x": -2,
      "y": 2,
      "z": -4,
      "name": "Soil_Ash"
    },
    {
      "x": -2,
      "y": 3,
      "z": -4,
      "name": "Plant_Moss_Rug_Pink",
      "support": 15
    },
    {
      "x": -2,
      "y": 0,
      "z": -3,
      "name": "Soil_Ash"
    },
    {
      "x": -2,
      "y": 1,
      "z": -3,
      "name": "Soil_Ash"
    },
    {
      "x": -2,
      "y": 2,
      "z": -3,
      "name": "Soil_Ash"
    },
    {
      "x": -2,
      "y": 3,
      "z": -3,
      "name": "Plant_Moss_Rug_Pink",
      "support": 15
    },
    {
      "x": -2,
      "y": 0,
      "z": -2,
      "name": "Soil_Sand_Ashen"
    },
    {
      "x": -2,
      "y": 1,
      "z": -2,
      "name": "Soil_Sand_Ashen"
    },
    {
      "x": -2,
      "y": 2,
      "z": -2,
      "name": "Soil_Ash"
    },
    {
      "x": -2,
      "y": 3,
      "z": -2,
      "name": "Plant_Moss_Rug_Pink",
      "support": 15
    },
    {
      "x": -2,
      "y": 0,
      "z": -1,
      "name": "Soil_Sand_Ashen"
    },
    {
      "x": -2,
      "y": 1,
      "z": -1,
      "name": "Soil_Ash"
    },
    {
      "x": -2,
      "y": 2,
      "z": -1,
      "name": "Plant_Moss_Rug_Pink",
      "support": 15
    },
    {
      "x": -2,
      "y": 0,
      "z": 0,
      "name": "Soil_Ash"
    },
    {
      "x": -2,
      "y": 1,
      "z": 0,
      "name": "Soil_Sand_Ashen"
    },
    {
      "x": -2,
      "y": 2,
      "z": 0,
      "name": "Soil_Ash"
    },
    {
      "x": -2,
      "y": 3,
      "z": 0,
      "name": "Plant_Moss_Rug_Pink",
      "support": 15
    },
    {
      "x": -2,
      "y": 0,
      "z": 1,
      "name": "Soil_Sand_Ashen"
    },
    {
      "x": -2,
      "y": 1,
      "z": 1,
      "name": "Soil_Ash"
    },
    {
      "x": -2,
      "y": 2,
      "z": 1,
      "name": "Soil_Ash"
    },
    {
      "x": -2,
      "y": 3,
      "z": 1,
      "name": "Plant_Crop_Mushroom_Glowing_Purple"
    },
    {
      "x": -2,
      "y": 0,
      "z": 2,
      "name": "Soil_Ash"
    },
    {
      "x": -2,
      "y": 1,
      "z": 2,
      "name": "Soil_Ash"
    },
    {
      "x": -2,
      "y": 2,
      "z": 2,
      "name": "Soil_Ash"
    },
    {
      "x": -2,
      "y": 3,
      "z": 2,
      "name": "Plant_Moss_Rug_Pink",
      "support": 15
    },
    {
      "x": -2,
      "y": 0,
      "z": 3,
      "name": "Soil_Ash"
    },
    {
      "x": -2,
      "y": 1,
      "z": 3,
      "name": "Soil_Ash"
    },
    {
      "x": -2,
      "y": 2,
      "z": 3,
      "name": "Soil_Ash"
    },
    {
      "x": -2,
      "y": 3,
      "z": 3,
      "name": "Plant_Moss_Rug_Pink",
      "support": 15
    },
    {
      "x": -2,
      "y": 0,
      "z": 4,
      "name": "Soil_Sand_Ashen"
    },
    {
      "x": -2,
      "y": 1,
      "z": 4,
      "name": "Soil_Ash"
    },
    {
      "x": -2,
      "y": 2,
      "z": 4,
      "name": "Plant_Flower_Bushy_Poisoned"
    },
    {
      "x": -2,
      "y": 0,
      "z": 5,
      "name": "Soil_Ash"
    },
    {
      "x": -2,
      "y": 1,
      "z": 5,
      "name": "Soil_Ash"
    },
    {
      "x": -2,
      "y": 0,
      "z": 6,
      "name": "Soil_Ash"
    },
    {
      "x": -1,
      "y": 0,
      "z": -6,
      "name": "Soil_Sand_Ashen"
    },
    {
      "x": -1,
      "y": 0,
      "z": -5,
      "name": "Soil_Sand_Ashen"
    },
    {
      "x": -1,
      "y": 1,
      "z": -5,
      "name": "Soil_Sand_Ashen"
    },
    {
      "x": -1,
      "y": 2,
      "z": -5,
      "name": "Plant_Flower_Bushy_Poisoned"
    },
    {
      "x": -1,
      "y": 0,
      "z": -4,
      "name": "Soil_Sand_Ashen"
    },
    {
      "x": -1,
      "y": 1,
      "z": -4,
      "name": "Soil_Ash"
    },
    {
      "x": -1,
      "y": 2,
      "z": -4,
      "name": "Plant_Flower_Bushy_Violet"
    },
    {
      "x": -1,
      "y": 0,
      "z": -3,
      "name": "Soil_Ash"
    },
    {
      "x": -1,
      "y": 1,
      "z": -3,
      "name": "Soil_Sand_Ashen"
    },
    {
      "x": -1,
      "y": 2,
      "z": -3,
      "name": "Soil_Ash"
    },
    {
      "x": -1,
      "y": 3,
      "z": -3,
      "name": "Plant_Moss_Rug_Pink",
      "support": 15
    },
    {
      "x": -1,
      "y": 0,
      "z": -2,
      "name": "Soil_Ash"
    },
    {
      "x": -1,
      "y": 1,
      "z": -2,
      "name": "Soil_Sand_Ashen"
    },
    {
      "x": -1,
      "y": 2,
      "z": -2,
      "name": "Plant_Crop_Mushroom_Glowing_Violet"
    },
    {
      "x": -1,
      "y": 0,
      "z": -1,
      "name": "Soil_Sand_Ashen"
    },
    {
      "x": -1,
      "y": 1,
      "z": -1,
      "name": "Soil_Sand_Ashen"
    },
    {
      "x": -1,
      "y": 2,
      "z": -1,
      "name": "Plant_Moss_Rug_Pink",
      "support": 15
    },
    {
      "x": -1,
      "y": 0,
      "z": 0,
      "name": "Soil_Ash"
    },
    {
      "x": -1,
      "y": 1,
      "z": 0,
      "name": "Soil_Ash"
    },
    {
      "x": -1,
      "y": 2,
      "z": 0,
      "name": "Plant_Crop_Mushroom_Glowing_Purple"
    },
    {
      "x": -1,
      "y": 0,
      "z": 1,
      "name": "Soil_Ash"
    },
    {
      "x": -1,
      "y": 1,
      "z": 1,
      "name": "Soil_Ash"
    },
    {
      "x": -1,
      "y": 2,
      "z": 1,
      "name": "Soil_Ash"
    },
    {
      "x": -1,
      "y": 3,
      "z": 1,
      "name": "Plant_Crop_Mushroom_Glowing_Purple"
    },
    {
      "x": -1,
      "y": 0,
      "z": 2,
      "name": "Soil_Ash"
    },
    {
      "x": -1,
      "y": 1,
      "z": 2,
      "name": "Soil_Ash"
    },
    {
      "x": -1,
      "y": 2,
      "z": 2,
      "name": "Soil_Ash"
    },
    {
      "x": -1,
      "y": 3,
      "z": 2,
      "name": "Plant_Moss_Rug_Pink",
      "support": 15
    },
    {
      "x": -1,
      "y": 0,
      "z": 3,
      "name": "Soil_Sand_Ashen"
    },
    {
      "x": -1,
      "y": 1,
      "z": 3,
      "name": "Soil_Sand_Ashen"
    },
    {
      "x": -1,
      "y": 0,
      "z": 4,
      "name": "Soil_Ash"
    },
    {
      "x": -1,
      "y": 1,
      "z": 4,
      "name": "Soil_Ash"
    },
    {
      "x": -1,
      "y": 0,
      "z": 5,
      "name": "Soil_Ash"
    },
    {
      "x": -1,
      "y": 1,
      "z": 5,
      "name": "Soil_Ash"
    },
    {
      "x": -1,
      "y": 0,
      "z": 6,
      "name": "Soil_Ash"
    },
    {
      "x": 0,
      "y": 0,
      "z": -7,
      "name": "Soil_Ash"
    },
    {
      "x": 0,
      "y": 0,
      "z": -6,
      "name": "Soil_Ash"
    },
    {
      "x": 0,
      "y": 1,
      "z": -6,
      "name": "Soil_Sand_Ashen"
    },
    {
      "x": 0,
      "y": 0,
      "z": -5,
      "name": "Soil_Sand_Ashen"
    },
    {
      "x": 0,
      "y": 1,
      "z": -5,
      "name": "Soil_Sand_Ashen"
    },
    {
      "x": 0,
      "y": 2,
      "z": -5,
      "name": "Plant_Flower_Bushy_Poisoned"
    },
    {
      "x": 0,
      "y": 0,
      "z": -4,
      "name": "Soil_Sand_Ashen"
    },
    {
      "x": 0,
      "y": 1,
      "z": -4,
      "name": "Soil_Ash"
    },
    {
      "x": 0,
      "y": 2,
      "z": -4,
      "name": "Plant_Moss_Rug_Pink",
      "support": 15
    },
    {
      "x": 0,
      "y": 0,
      "z": -3,
      "name": "Soil_Ash"
    },
    {
      "x": 0,
      "y": 1,
      "z": -3,
      "name": "Soil_Ash"
    },
    {
      "x": 0,
      "y": 2,
      "z": -3,
      "name": "Plant_Crop_Mushroom_Glowing_Violet"
    },
    {
      "x": 0,
      "y": 0,
      "z": -2,
      "name": "Soil_Sand_Ashen"
    },
    {
      "x": 0,
      "y": 1,
      "z": -2,
      "name": "Soil_Sand_Ashen"
    },
    {
      "x": 0,
      "y": 2,
      "z": -2,
      "name": "Plant_Moss_Rug_Pink",
      "support": 15
    },
    {
      "x": 0,
      "y": 0,
      "z": -1,
      "name": "Soil_Sand_Ashen"
    },
    {
      "x": 0,
      "y": 1,
      "z": -1,
      "name": "Plant_Moss_Rug_Pink",
      "support": 15
    },
    {
      "x": 0,
      "y": 0,
      "z": 0,
      "name": "Soil_Ash"
    },
    {
      "x": 0,
      "y": 1,
      "z": 0,
      "name": "Soil_Ash"
    },
    {
      "x": 0,
      "y": 2,
      "z": 0,
      "name": "Plant_Moss_Rug_Pink",
      "support": 15
    },
    {
      "x": 0,
      "y": 0,
      "z": 1,
      "name": "Soil_Ash"
    },
    {
      "x": 0,
      "y": 1,
      "z": 1,
      "name": "Soil_Ash"
    },
    {
      "x": 0,
      "y": 2,
      "z": 1,
      "name": "Plant_Crop_Mushroom_Glowing_Purple"
    },
    {
      "x": 0,
      "y": 0,
      "z": 2,
      "name": "Soil_Sand_Ashen"
    },
    {
      "x": 0,
      "y": 1,
      "z": 2,
      "name": "Soil_Sand_Ashen"
    },
    {
      "x": 0,
      "y": 2,
      "z": 2,
      "name": "Soil_Ash"
    },
    {
      "x": 0,
      "y": 3,
      "z": 2,
      "name": "Plant_Moss_Rug_Pink",
      "support": 15
    },
    {
      "x": 0,
      "y": 0,
      "z": 3,
      "name": "Soil_Sand_Ashen"
    },
    {
      "x": 0,
      "y": 1,
      "z": 3,
      "name": "Soil_Ash"
    },
    {
      "x": 0,
      "y": 0,
      "z": 4,
      "name": "Soil_Ash"
    },
    {
      "x": 0,
      "y": 1,
      "z": 4,
      "name": "Soil_Ash"
    },
    {
      "x": 0,
      "y": 0,
      "z": 5,
      "name": "Soil_Ash"
    },
    {
      "x": 1,
      "y": 0,
      "z": -8,
      "name": "Soil_Sand_Ashen"
    },
    {
      "x": 1,
      "y": 0,
      "z": -7,
      "name": "Soil_Ash"
    },
    {
      "x": 1,
      "y": 1,
      "z": -7,
      "name": "Soil_Sand_Ashen"
    },
    {
      "x": 1,
      "y": 2,
      "z": -7,
      "name": "Plant_Crop_Mushroom_Glowing_Purple"
    },
    {
      "x": 1,
      "y": 0,
      "z": -6,
      "name": "Soil_Ash"
    },
    {
      "x": 1,
      "y": 1,
      "z": -6,
      "name": "Soil_Ash"
    },
    {
      "x": 1,
      "y": 0,
      "z": -5,
      "name": "Soil_Sand_Ashen"
    },
    {
      "x": 1,
      "y": 1,
      "z": -5,
      "name": "Soil_Sand_Ashen"
    },
    {
      "x": 1,
      "y": 2,
      "z": -5,
      "name": "Soil_Ash"
    },
    {
      "x": 1,
      "y": 3,
      "z": -5,
      "name": "Plant_Moss_Rug_Pink",
      "support": 15
    },
    {
      "x": 1,
      "y": 0,
      "z": -4,
      "name": "Soil_Ash"
    },
    {
      "x": 1,
      "y": 1,
      "z": -4,
      "name": "Soil_Ash"
    },
    {
      "x": 1,
      "y": 2,
      "z": -4,
      "name": "Plant_Moss_Rug_Pink",
      "support": 15
    },
    {
      "x": 1,
      "y": 0,
      "z": -3,
      "name": "Soil_Ash"
    },
    {
      "x": 1,
      "y": 1,
      "z": -3,
      "name": "Soil_Ash"
    },
    {
      "x": 1,
      "y": 2,
      "z": -3,
      "name": "Plant_Moss_Rug_Pink",
      "support": 15
    },
    {
      "x": 1,
      "y": 0,
      "z": -2,
      "name": "Soil_Ash"
    },
    {
      "x": 1,
      "y": 1,
      "z": -2,
      "name": "Plant_Moss_Rug_Pink",
      "support": 15
    },
    {
      "x": 1,
      "y": 0,
      "z": -1,
      "name": "Soil_Sand_Ashen"
    },
    {
      "x": 1,
      "y": 1,
      "z": -1,
      "name": "Soil_Sand_Ashen"
    },
    {
      "x": 1,
      "y": 2,
      "z": -1,
      "name": "Plant_Moss_Rug_Pink",
      "support": 15
    },
    {
      "x": 1,
      "y": 0,
      "z": 0,
      "name": "Soil_Ash"
    },
    {
      "x": 1,
      "y": 1,
      "z": 0,
      "name": "Soil_Ash"
    },
    {
      "x": 1,
      "y": 2,
      "z": 0,
      "name": "Plant_Moss_Rug_Pink",
      "support": 15
    },
    {
      "x": 1,
      "y": 0,
      "z": 1,
      "name": "Soil_Ash"
    },
    {
      "x": 1,
      "y": 1,
      "z": 1,
      "name": "Soil_Ash"
    },
    {
      "x": 1,
      "y": 2,
      "z": 1,
      "name": "Plant_Moss_Rug_Pink",
      "support": 15
    },
    {
      "x": 1,
      "y": 0,
      "z": 2,
      "name": "Soil_Ash"
    },
    {
      "x": 1,
      "y": 1,
      "z": 2,
      "name": "Soil_Ash"
    },
    {
      "x": 1,
      "y": 2,
      "z": 2,
      "name": "Plant_Moss_Rug_Pink",
      "support": 15
    },
    {
      "x": 1,
      "y": 0,
      "z": 3,
      "name": "Soil_Ash"
    },
    {
      "x": 1,
      "y": 1,
      "z": 3,
      "name": "Soil_Sand_Ashen"
    },
    {
      "x": 1,
      "y": 0,
      "z": 4,
      "name": "Soil_Sand_Ashen"
    },
    {
      "x": 2,
      "y": 0,
      "z": -9,
      "name": "Soil_Sand_Ashen"
    },
    {
      "x": 2,
      "y": 0,
      "z": -8,
      "name": "Soil_Sand_Ashen"
    },
    {
      "x": 2,
      "y": 1,
      "z": -8,
      "name": "Soil_Sand_Ashen"
    },
    {
      "x": 2,
      "y": 0,
      "z": -7,
      "name": "Soil_Ash"
    },
    {
      "x": 2,
      "y": 1,
      "z": -7,
      "name": "Soil_Ash"
    },
    {
      "x": 2,
      "y": 0,
      "z": -6,
      "name": "Soil_Sand_Ashen"
    },
    {
      "x": 2,
      "y": 1,
      "z": -6,
      "name": "Soil_Sand_Ashen"
    },
    {
      "x": 2,
      "y": 2,
      "z": -6,
      "name": "Soil_Ash"
    },
    {
      "x": 2,
      "y": 3,
      "z": -6,
      "name": "Plant_Moss_Rug_Pink",
      "support": 15
    },
    {
      "x": 2,
      "y": 0,
      "z": -5,
      "name": "Soil_Sand_Ashen"
    },
    {
      "x": 2,
      "y": 1,
      "z": -5,
      "name": "Soil_Sand_Ashen"
    },
    {
      "x": 2,
      "y": 2,
      "z": -5,
      "name": "Soil_Ash"
    },
    {
      "x": 2,
      "y": 3,
      "z": -5,
      "name": "Plant_Moss_Rug_Pink",
      "support": 15
    },
    {
      "x": 2,
      "y": 0,
      "z": -4,
      "name": "Soil_Ash"
    },
    {
      "x": 2,
      "y": 1,
      "z": -4,
      "name": "Soil_Ash"
    },
    {
      "x": 2,
      "y": 2,
      "z": -4,
      "name": "Soil_Ash"
    },
    {
      "x": 2,
      "y": 3,
      "z": -4,
      "name": "Plant_Crop_Mushroom_Glowing_Purple"
    },
    {
      "x": 2,
      "y": 0,
      "z": -3,
      "name": "Soil_Ash"
    },
    {
      "x": 2,
      "y": 1,
      "z": -3,
      "name": "Soil_Ash"
    },
    {
      "x": 2,
      "y": 2,
      "z": -3,
      "name": "Plant_Moss_Rug_Pink",
      "support": 15
    },
    {
      "x": 2,
      "y": 0,
      "z": -2,
      "name": "Soil_Sand_Ashen"
    },
    {
      "x": 2,
      "y": 1,
      "z": -2,
      "name": "Soil_Sand_Ashen"
    },
    {
      "x": 2,
      "y": 2,
      "z": -2,
      "name": "Plant_Crop_Mushroom_Glowing_Violet"
    },
    {
      "x": 2,
      "y": 0,
      "z": -1,
      "name": "Soil_Sand_Ashen"
    },
    {
      "x": 2,
      "y": 1,
      "z": -1,
      "name": "Soil_Ash"
    },
    {
      "x": 2,
      "y": 2,
      "z": -1,
      "name": "Plant_Moss_Rug_Pink",
      "support": 15
    },
    {
      "x": 2,
      "y": 0,
      "z": 0,
      "name": "Soil_Ash"
    },
    {
      "x": 2,
      "y": 1,
      "z": 0,
      "name": "Soil_Sand_Ashen"
    },
    {
      "x": 2,
      "y": 2,
      "z": 0,
      "name": "Soil_Ash"
    },
    {
      "x": 2,
      "y": 3,
      "z": 0,
      "name": "Plant_Crop_Mushroom_Glowing_Purple"
    },
    {
      "x": 2,
      "y": 0,
      "z": 1,
      "name": "Soil_Sand_Ashen"
    },
    {
      "x": 2,
      "y": 1,
      "z": 1,
      "name": "Soil_Ash"
    },
    {
      "x": 2,
      "y": 2,
      "z": 1,
      "name": "Plant_Moss_Rug_Pink",
      "support": 15
    },
    {
      "x": 2,
      "y": 0,
      "z": 2,
      "name": "Soil_Sand_Ashen"
    },
    {
      "x": 2,
      "y": 1,
      "z": 2,
      "name": "Soil_Sand_Ashen"
    },
    {
      "x": 2,
      "y": 0,
      "z": 3,
      "name": "Soil_Ash"
    },
    {
      "x": 3,
      "y": 0,
      "z": -9,
      "name": "Soil_Sand_Ashen"
    },
    {
      "x": 3,
      "y": 0,
      "z": -8,
      "name": "Soil_Sand_Ashen"
    },
    {
      "x": 3,
      "y": 1,
      "z": -8,
      "name": "Soil_Sand_Ashen"
    },
    {
      "x": 3,
      "y": 0,
      "z": -7,
      "name": "Soil_Sand_Ashen"
    },
    {
      "x": 3,
      "y": 1,
      "z": -7,
      "name": "Soil_Sand_Ashen"
    },
    {
      "x": 3,
      "y": 2,
      "z": -7,
      "name": "Soil_Sand_Ashen"
    },
    {
      "x": 3,
      "y": 3,
      "z": -7,
      "name": "Plant_Moss_Rug_Pink",
      "support": 15
    },
    {
      "x": 3,
      "y": 0,
      "z": -6,
      "name": "Soil_Sand_Ashen"
    },
    {
      "x": 3,
      "y": 1,
      "z": -6,
      "name": "Soil_Ash"
    },
    {
      "x": 3,
      "y": 2,
      "z": -6,
      "name": "Soil_Ash"
    },
    {
      "x": 3,
      "y": 3,
      "z": -6,
      "name": "Plant_Moss_Rug_Pink",
      "support": 15
    },
    {
      "x": 3,
      "y": 0,
      "z": -5,
      "name": "Soil_Ash"
    },
    {
      "x": 3,
      "y": 1,
      "z": -5,
      "name": "Soil_Sand_Ashen"
    },
    {
      "x": 3,
      "y": 2,
      "z": -5,
      "name": "Soil_Ash"
    },
    {
      "x": 3,
      "y": 3,
      "z": -5,
      "name": "Plant_Moss_Rug_Pink",
      "support": 15
    },
    {
      "x": 3,
      "y": 0,
      "z": -4,
      "name": "Soil_Sand_Ashen"
    },
    {
      "x": 3,
      "y": 1,
      "z": -4,
      "name": "Soil_Sand_Ashen"
    },
    {
      "x": 3,
      "y": 2,
      "z": -4,
      "name": "Soil_Ash"
    },
    {
      "x": 3,
      "y": 3,
      "z": -4,
      "name": "Plant_Crop_Mushroom_Glowing_Purple"
    },
    {
      "x": 3,
      "y": 0,
      "z": -3,
      "name": "Soil_Sand_Ashen"
    },
    {
      "x": 3,
      "y": 1,
      "z": -3,
      "name": "Soil_Ash"
    },
    {
      "x": 3,
      "y": 2,
      "z": -3,
      "name": "Soil_Ash"
    },
    {
      "x": 3,
      "y": 3,
      "z": -3,
      "name": "Plant_Moss_Rug_Pink",
      "support": 15
    },
    {
      "x": 3,
      "y": 0,
      "z": -2,
      "name": "Soil_Ash"
    },
    {
      "x": 3,
      "y": 1,
      "z": -2,
      "name": "Soil_Ash"
    },
    {
      "x": 3,
      "y": 2,
      "z": -2,
      "name": "Plant_Moss_Rug_Pink",
      "support": 15
    },
    {
      "x": 3,
      "y": 0,
      "z": -1,
      "name": "Soil_Ash"
    },
    {
      "x": 3,
      "y": 1,
      "z": -1,
      "name": "Soil_Ash"
    },
    {
      "x": 3,
      "y": 2,
      "z": -1,
      "name": "Soil_Ash"
    },
    {
      "x": 3,
      "y": 3,
      "z": -1,
      "name": "Plant_Crop_Mushroom_Glowing_Purple"
    },
    {
      "x": 3,
      "y": 0,
      "z": 0,
      "name": "Soil_Sand_Ashen"
    },
    {
      "x": 3,
      "y": 1,
      "z": 0,
      "name": "Soil_Sand_Ashen"
    },
    {
      "x": 3,
      "y": 2,
      "z": 0,
      "name": "Soil_Ash"
    },
    {
      "x": 3,
      "y": 3,
      "z": 0,
      "name": "Plant_Crop_Mushroom_Glowing_Purple"
    },
    {
      "x": 3,
      "y": 0,
      "z": 1,
      "name": "Soil_Ash"
    },
    {
      "x": 3,
      "y": 1,
      "z": 1,
      "name": "Soil_Sand_Ashen"
    },
    {
      "x": 3,
      "y": 2,
      "z": 1,
      "name": "Soil_Ash"
    },
    {
      "x": 3,
      "y": 3,
      "z": 1,
      "name": "Plant_Moss_Rug_Pink",
      "support": 15
    },
    {
      "x": 3,
      "y": 0,
      "z": 2,
      "name": "Soil_Ash"
    },
    {
      "x": 3,
      "y": 1,
      "z": 2,
      "name": "Soil_Ash"
    },
    {
      "x": 3,
      "y": 0,
      "z": 3,
      "name": "Soil_Sand_Ashen"
    },
    {
      "x": 3,
      "y": 1,
      "z": 3,
      "name": "Soil_Ash"
    },
    {
      "x": 3,
      "y": 0,
      "z": 4,
      "name": "Soil_Sand_Ashen"
    },
    {
      "x": 4,
      "y": 0,
      "z": -9,
      "name": "Soil_Sand_Ashen"
    },
    {
      "x": 4,
      "y": 0,
      "z": -8,
      "name": "Soil_Ash"
    },
    {
      "x": 4,
      "y": 1,
      "z": -8,
      "name": "Soil_Ash"
    },
    {
      "x": 4,
      "y": 2,
      "z": -8,
      "name": "Plant_Crop_Mushroom_Glowing_Purple"
    },
    {
      "x": 4,
      "y": 0,
      "z": -7,
      "name": "Soil_Ash"
    },
    {
      "x": 4,
      "y": 1,
      "z": -7,
      "name": "Soil_Ash"
    },
    {
      "x": 4,
      "y": 0,
      "z": -6,
      "name": "Soil_Ash"
    },
    {
      "x": 4,
      "y": 1,
      "z": -6,
      "name": "Soil_Ash"
    },
    {
      "x": 4,
      "y": 2,
      "z": -6,
      "name": "Soil_Ash"
    },
    {
      "x": 4,
      "y": 3,
      "z": -6,
      "name": "Plant_Moss_Rug_Pink",
      "support": 15
    },
    {
      "x": 4,
      "y": 0,
      "z": -5,
      "name": "Soil_Sand_Ashen"
    },
    {
      "x": 4,
      "y": 1,
      "z": -5,
      "name": "Soil_Ash"
    },
    {
      "x": 4,
      "y": 2,
      "z": -5,
      "name": "Soil_Ash"
    },
    {
      "x": 4,
      "y": 3,
      "z": -5,
      "name": "Plant_Crop_Mushroom_Glowing_Purple"
    },
    {
      "x": 4,
      "y": 0,
      "z": -4,
      "name": "Soil_Sand_Ashen"
    },
    {
      "x": 4,
      "y": 1,
      "z": -4,
      "name": "Soil_Ash"
    },
    {
      "x": 4,
      "y": 2,
      "z": -4,
      "name": "Soil_Ash"
    },
    {
      "x": 4,
      "y": 3,
      "z": -4,
      "name": "Plant_Moss_Rug_Pink",
      "support": 15
    },
    {
      "x": 4,
      "y": 0,
      "z": -3,
      "name": "Soil_Ash"
    },
    {
      "x": 4,
      "y": 1,
      "z": -3,
      "name": "Soil_Ash"
    },
    {
      "x": 4,
      "y": 0,
      "z": -2,
      "name": "Soil_Sand_Ashen"
    },
    {
      "x": 4,
      "y": 1,
      "z": -2,
      "name": "Soil_Ash"
    },
    {
      "x": 4,
      "y": 2,
      "z": -2,
      "name": "Soil_Ash"
    },
    {
      "x": 4,
      "y": 3,
      "z": -2,
      "name": "Plant_Moss_Rug_Pink",
      "support": 15
    },
    {
      "x": 4,
      "y": 0,
      "z": -1,
      "name": "Soil_Ash"
    },
    {
      "x": 4,
      "y": 1,
      "z": -1,
      "name": "Soil_Sand_Ashen"
    },
    {
      "x": 4,
      "y": 2,
      "z": -1,
      "name": "Soil_Ash"
    },
    {
      "x": 4,
      "y": 3,
      "z": -1,
      "name": "Plant_Crop_Mushroom_Glowing_Purple"
    },
    {
      "x": 4,
      "y": 0,
      "z": 0,
      "name": "Soil_Sand_Ashen"
    },
    {
      "x": 4,
      "y": 1,
      "z": 0,
      "name": "Soil_Ash"
    },
    {
      "x": 4,
      "y": 2,
      "z": 0,
      "name": "Soil_Ash"
    },
    {
      "x": 4,
      "y": 3,
      "z": 0,
      "name": "Plant_Moss_Rug_Pink",
      "support": 15
    },
    {
      "x": 4,
      "y": 0,
      "z": 1,
      "name": "Soil_Ash"
    },
    {
      "x": 4,
      "y": 1,
      "z": 1,
      "name": "Soil_Sand_Ashen"
    },
    {
      "x": 4,
      "y": 2,
      "z": 1,
      "name": "Soil_Ash"
    },
    {
      "x": 4,
      "y": 3,
      "z": 1,
      "name": "Plant_Moss_Rug_Pink",
      "support": 15
    },
    {
      "x": 4,
      "y": 0,
      "z": 2,
      "name": "Soil_Sand_Ashen"
    },
    {
      "x": 4,
      "y": 1,
      "z": 2,
      "name": "Soil_Ash"
    },
    {
      "x": 4,
      "y": 0,
      "z": 3,
      "name": "Soil_Ash"
    },
    {
      "x": 4,
      "y": 1,
      "z": 3,
      "name": "Soil_Sand_Ashen"
    },
    {
      "x": 4,
      "y": 2,
      "z": 3,
      "name": "Plant_Crop_Mushroom_Glowing_Purple"
    },
    {
      "x": 4,
      "y": 0,
      "z": 4,
      "name": "Soil_Ash"
    },
    {
      "x": 5,
      "y": 0,
      "z": -8,
      "name": "Soil_Sand_Ashen"
    },
    {
      "x": 5,
      "y": 0,
      "z": -7,
      "name": "Soil_Sand_Ashen"
    },
    {
      "x": 5,
      "y": 1,
      "z": -7,
      "name": "Soil_Ash"
    },
    {
      "x": 5,
      "y": 0,
      "z": -6,
      "name": "Soil_Ash"
    },
    {
      "x": 5,
      "y": 1,
      "z": -6,
      "name": "Soil_Ash"
    },
    {
      "x": 5,
      "y": 0,
      "z": -5,
      "name": "Soil_Sand_Ashen"
    },
    {
      "x": 5,
      "y": 1,
      "z": -5,
      "name": "Soil_Sand_Ashen"
    },
    {
      "x": 5,
      "y": 2,
      "z": -5,
      "name": "Soil_Ash"
    },
    {
      "x": 5,
      "y": 3,
      "z": -5,
      "name": "Plant_Moss_Rug_Pink",
      "support": 15
    },
    {
      "x": 5,
      "y": 0,
      "z": -4,
      "name": "Soil_Sand_Ashen"
    },
    {
      "x": 5,
      "y": 1,
      "z": -4,
      "name": "Soil_Ash"
    },
    {
      "x": 5,
      "y": 0,
      "z": -3,
      "name": "Soil_Sand_Ashen"
    },
    {
      "x": 5,
      "y": 1,
      "z": -3,
      "name": "Soil_Sand_Ashen"
    },
    {
      "x": 5,
      "y": 0,
      "z": -2,
      "name": "Soil_Sand_Ashen"
    },
    {
      "x": 5,
      "y": 1,
      "z": -2,
      "name": "Soil_Sand_Ashen"
    },
    {
      "x": 5,
      "y": 2,
      "z": -2,
      "name": "Plant_Flower_Bushy_Violet"
    },
    {
      "x": 5,
      "y": 0,
      "z": -1,
      "name": "Soil_Sand_Ashen"
    },
    {
      "x": 5,
      "y": 1,
      "z": -1,
      "name": "Soil_Sand_Ashen"
    },
    {
      "x": 5,
      "y": 2,
      "z": -1,
      "name": "Soil_Ash"
    },
    {
      "x": 5,
      "y": 3,
      "z": -1,
      "name": "Plant_Moss_Rug_Pink",
      "support": 15
    },
    {
      "x": 5,
      "y": 0,
      "z": 0,
      "name": "Soil_Sand_Ashen"
    },
    {
      "x": 5,
      "y": 1,
      "z": 0,
      "name": "Soil_Ash"
    },
    {
      "x": 5,
      "y": 2,
      "z": 0,
      "name": "Soil_Ash"
    },
    {
      "x": 5,
      "y": 3,
      "z": 0,
      "name": "Plant_Crop_Mushroom_Glowing_Purple"
    },
    {
      "x": 5,
      "y": 0,
      "z": 1,
      "name": "Soil_Sand_Ashen"
    },
    {
      "x": 5,
      "y": 1,
      "z": 1,
      "name": "Soil_Sand_Ashen"
    },
    {
      "x": 5,
      "y": 2,
      "z": 1,
      "name": "Soil_Ash"
    },
    {
      "x": 5,
      "y": 3,
      "z": 1,
      "name": "Plant_Moss_Rug_Pink",
      "support": 15
    },
    {
      "x": 5,
      "y": 0,
      "z": 2,
      "name": "Soil_Ash"
    },
    {
      "x": 5,
      "y": 1,
      "z": 2,
      "name": "Soil_Sand_Ashen"
    },
    {
      "x": 5,
      "y": 0,
      "z": 3,
      "name": "Soil_Ash"
    },
    {
      "x": 5,
      "y": 1,
      "z": 3,
      "name": "Soil_Ash"
    },
    {
      "x": 5,
      "y": 0,
      "z": 4,
      "name": "Soil_Ash"
    },
    {
      "x": 6,
      "y": 0,
      "z": -7,
      "name": "Soil_Ash"
    },
    {
      "x": 6,
      "y": 0,
      "z": -6,
      "name": "Soil_Ash"
    },
    {
      "x": 6,
      "y": 1,
      "z": -6,
      "name": "Soil_Ash"
    },
    {
      "x": 6,
      "y": 2,
      "z": -6,
      "name": "Plant_Crop_Mushroom_Glowing_Purple"
    },
    {
      "x": 6,
      "y": 0,
      "z": -5,
      "name": "Soil_Sand_Ashen"
    },
    {
      "x": 6,
      "y": 1,
      "z": -5,
      "name": "Soil_Ash"
    },
    {
      "x": 6,
      "y": 0,
      "z": -4,
      "name": "Soil_Ash"
    },
    {
      "x": 6,
      "y": 1,
      "z": -4,
      "name": "Soil_Sand_Ashen"
    },
    {
      "x": 6,
      "y": 0,
      "z": -3,
      "name": "Soil_Ash"
    },
    {
      "x": 6,
      "y": 0,
      "z": -2,
      "name": "Soil_Sand_Ashen"
    },
    {
      "x": 6,
      "y": 1,
      "z": -2,
      "name": "Soil_Sand_Ashen"
    },
    {
      "x": 6,
      "y": 0,
      "z": -1,
      "name": "Soil_Ash"
    },
    {
      "x": 6,
      "y": 1,
      "z": -1,
      "name": "Soil_Sand_Ashen"
    },
    {
      "x": 6,
      "y": 2,
      "z": -1,
      "name": "Plant_Crop_Mushroom_Glowing_Purple"
    },
    {
      "x": 6,
      "y": 0,
      "z": 0,
      "name": "Soil_Ash"
    },
    {
      "x": 6,
      "y": 1,
      "z": 0,
      "name": "Soil_Sand_Ashen"
    },
    {
      "x": 6,
      "y": 2,
      "z": 0,
      "name": "Soil_Sand_Ashen"
    },
    {
      "x": 6,
      "y": 3,
      "z": 0,
      "name": "Plant_Moss_Rug_Pink",
      "support": 15
    },
    {
      "x": 6,
      "y": 0,
      "z": 1,
      "name": "Soil_Ash"
    },
    {
      "x": 6,
      "y": 1,
      "z": 1,
      "name": "Soil_Sand_Ashen"
    },
    {
      "x": 6,
      "y": 0,
      "z": 2,
      "name": "Soil_Sand_Ashen"
    },
    {
      "x": 6,
      "y": 1,
      "z": 2,
      "name": "Soil_Sand_Ashen"
    },
    {
      "x": 6,
      "y": 0,
      "z": 3,
      "name": "Soil_Sand_Ashen"
    },
    {
      "x": 7,
      "y": 0,
      "z": -6,
      "name": "Soil_Ash"
    },
    {
      "x": 7,
      "y": 0,
      "z": -5,
      "name": "Soil_Sand_Ashen"
    },
    {
      "x": 7,
      "y": 0,
      "z": -4,
      "name": "Soil_Sand_Ashen"
    },
    {
      "x": 7,
      "y": 0,
      "z": -2,
      "name": "Soil_Ash"
    },
    {
      "x": 7,
      "y": 0,
      "z": -1,
      "name": "Soil_Ash"
    },
    {
      "x": 7,
      "y": 1,
      "z": -1,
      "name": "Soil_Ash"
    },
    {
      "x": 7,
      "y": 0,
      "z": 0,
      "name": "Soil_Ash"
    },
    {
      "x": 7,
      "y": 1,
      "z": 0,
      "name": "Soil_Ash"
    },
    {
      "x": 7,
      "y": 0,
      "z": 1,
      "name": "Soil_Sand_Ashen"
    },
    {
      "x": 7,
      "y": 1,
      "z": 1,
      "name": "Soil_Sand_Ashen"
    },
    {
      "x": 7,
      "y": 2,
      "z": 1,
      "name": "Plant_Crop_Mushroom_Glowing_Purple"
    },
    {
      "x": 7,
      "y": 0,
      "z": 2,
      "name": "Soil_Ash"
    },
    {
      "x": 8,
      "y": 0,
      "z": -1,
      "name": "Soil_Sand_Ashen"
    },
    {
      "x": 8,
      "y": 0,
      "z": 0,
      "name": "Soil_Ash"
    },
    {
      "x": 8,
      "y": 0,
      "z": 1,
      "name": "Soil_Ash"
    }
  ]
}