{
  "version": 8,
  "blockIdVersion": 11,
  "anchorX": 0,
  "anchorY": 0,
  "anchorZ": 0,
  "blocks": [
    {
      "x": -18,
      "y": 6,
      "z": 1,
      "name": "Wood_Hardwood_Planks_Half",
      "rotation": 8
    },
    {
      "x": -18,
      "y": 7,
      "z": 1,
      "name": "Cloth_Block_Wool_Orange_Light"
    },
    {
      "x": -18,
      "y": 13,
      "z": 1,
      "name": "Cloth_Block_Wool_Orange_Light"
    },
    {
      "x": -18,
      "y": 14,
      "z": 1,
      "name": "Wood_Hardwood_Planks_Half"
    },
    {
      "x": -17,
      "y": 6,
      "z": 1,
      "name": "Wood_Hardwood_Planks_Half",
      "rotation": 8
    },
    {
      "x": -17,
      "y": 7,
      "z": 1,
      "name": "Cloth_Block_Wool_Orange_Light"
    },
    {
      "x": -17,
      "y": 8,
      "z": 1,
      "name": "Cloth_Block_Wool_Orange_Light"
    },
    {
      "x": -17,
      "y": 12,
      "z": 1,
      "name": "Cloth_Block_Wool_Orange_Light"
    },
    {
      "x": -17,
      "y": 13,
      "z": 1,
      "name": "Cloth_Block_Wool_Orange_Light"
    },
    {
      "x": -17,
      "y": 14,
      "z": 1,
      "name": "Wood_Hardwood_Planks_Half"
    },
    {
      "x": -16,
      "y": 10,
      "z": -4,
      "name": "Wood_Hardwood_Planks_Half",
      "rotation": 6
    },
    {
      "x": -16,
      "y": 10,
      "z": -3,
      "name": "Cloth_Block_Wool_Orange_Light"
    },
    {
      "x": -16,
      "y": 6,
      "z": 1,
      "name": "Wood_Hardwood_Planks_Half",
      "rotation": 8
    },
    {
      "x": -16,
      "y": 7,
      "z": 1,
      "name": "Cloth_Block_Wool_Orange_Light"
    },
    {
      "x": -16,
      "y": 8,
      "z": 1,
      "name": "Cloth_Block_Wool_Orange_Light"
    },
    {
      "x": -16,
      "y": 9,
      "z": 1,
      "name": "Cloth_Block_Wool_Orange_Light"
    },
    {
      "x": -16,
      "y": 11,
      "z": 1,
      "name": "Cloth_Block_Wool_Orange_Light"
    },
    {
      "x": -16,
      "y": 12,
      "z": 1,
      "name": "Cloth_Block_Wool_Orange_Light"
    },
    {
      "x": -16,
      "y": 13,
      "z": 1,
      "name": "Cloth_Block_Wool_Orange_Light"
    },
    {
      "x": -16,
      "y": 14,
      "z": 1,
      "name": "Wood_Hardwood_Planks_Half"
    },
    {
      "x": -16,
      "y": 10,
      "z": 5,
      "name": "Cloth_Block_Wool_Orange_Light"
    },
    {
      "x": -16,
      "y": 10,
      "z": 6,
      "name": "Wood_Hardwood_Planks_Half",
      "rotation": 4
    },
    {
      "x": -15,
      "y": 10,
      "z": -4,
      "name": "Wood_Hardwood_Planks_Half",
      "rotation": 6
    },
    {
      "x": -15,
      "y": 10,
      "z": -3,
      "name": "Cloth_Block_Wool_Orange_Light"
    },
    {
      "x": -15,
      "y": 10,
      "z": -2,
      "name": "Cloth_Block_Wool_Orange_Light"
    },
    {
      "x": -15,
      "y": 25,
      "z": -1,
      "name": "Cloth_Block_Wool_Orange_Light"
    },
    {
      "x": -15,
      "y": 26,
      "z": -1,
      "name": "Cloth_Block_Wool_Orange_Light"
    },
    {
      "x": -15,
      "y": 27,
      "z": -1,
      "name": "Cloth_Block_Wool_Orange_Light"
    },
    {
      "x": -15,
      "y": 24,
      "z": 0,
      "name": "Cloth_Block_Wool_Orange_Light"
    },
    {
      "x": -15,
      "y": 25,
      "z": 0,
      "name": "Cloth_Block_Wool_Orange_Light"
    },
    {
      "x": -15,
      "y": 26,
      "z": 0,
      "name": "Cloth_Block_Wool_Orange_Light"
    },
    {
      "x": -15,
      "y": 27,
      "z": 0,
      "name": "Cloth_Block_Wool_Orange_Light"
    },
    {
      "x": -15,
      "y": 28,
      "z": 0,
      "name": "Cloth_Block_Wool_Orange_Light"
    },
    {
      "x": -15,
      "y": 6,
      "z": 1,
      "name": "Wood_Hardwood_Planks_Half",
      "rotation": 8
    },
    {
      "x": -15,
      "y": 7,
      "z": 1,
      "name": "Cloth_Block_Wool_Orange_Light"
    },
    {
      "x": -15,
      "y": 8,
      "z": 1,
      "name": "Cloth_Block_Wool_Orange_Light"
    },
    {
      "x": -15,
      "y": 9,
      "z": 1,
      "name": "Cloth_Block_Wool_Orange_Light"
    },
    {
      "x": -15,
      "y": 10,
      "z": 1,
      "name": "Cloth_Block_Wool_Orange_Light"
    },
    {
      "x": -15,
      "y": 11,
      "z": 1,
      "name": "Cloth_Block_Wool_Orange_Light"
    },
    {
      "x": -15,
      "y": 12,
      "z": 1,
      "name": "Cloth_Block_Wool_Orange_Light"
    },
    {
      "x": -15,
      "y": 13,
      "z": 1,
      "name": "Cloth_Block_Wool_Orange_Light"
    },
    {
      "x": -15,
      "y": 14,
      "z": 1,
      "name": "Wood_Hardwood_Planks_Half"
    },
    {
      "x": -15,
      "y": 24,
      "z": 1,
      "name": "Cloth_Block_Wool_Orange_Light"
    },
    {
      "x": -15,
      "y": 25,
      "z": 1,
      "name": "Cloth_Block_Wool_Orange_Light"
    },
    {
      "x": -15,
      "y": 26,
      "z": 1,
      "name": "Cloth_Block_Wool_Orange_Light"
    },
    {
      "x": -15,
      "y": 27,
      "z": 1,
      "name": "Cloth_Block_Wool_Orange_Light"
    },
    {
      "x": -15,
      "y": 28,
      "z": 1,
      "name": "Cloth_Block_Wool_Orange_Light"
    },
    {
      "x": -15,
      "y": 24,
      "z": 2,
      "name": "Cloth_Block_Wool_Orange_Light"
    },
    {
      "x": -15,
      "y": 25,
      "z": 2,
      "name": "Cloth_Block_Wool_Orange_Light"
    },
    {
      "x": -15,
      "y": 26,
      "z": 2,
      "name": "Cloth_Block_Wool_Orange_Light"
    },
    {
      "x": -15,
      "y": 27,
      "z": 2,
      "name": "Cloth_Block_Wool_Orange_Light"
    },
    {
      "x": -15,
      "y": 28,
      "z": 2,
      "name": "Cloth_Block_Wool_Orange_Light"
    },
    {
      "x": -15,
      "y": 25,
      "z": 3,
      "name": "Cloth_Block_Wool_Orange_Light"
    },
    {
      "x": -15,
      "y": 26,
      "z": 3,
      "name": "Cloth_Block_Wool_Orange_Light"
    },
    {
      "x": -15,
      "y": 27,
      "z": 3,
      "name": "Cloth_Block_Wool_Orange_Light"
    },
    {
      "x": -15,
      "y": 10,
      "z": 4,
      "name": "Cloth_Block_Wool_Orange_Light"
    },
    {
      "x": -15,
      "y": 10,
      "z": 5,
      "name": "Cloth_Block_Wool_Orange_Light"
    },
    {
      "x": -15,
      "y": 10,
      "z": 6,
      "name": "Wood_Hardwood_Planks_Half",
      "rotation": 4
    },
    {
      "x": -14,
      "y": 10,
      "z": -4,
      "name": "Wood_Hardwood_Planks_Half",
      "rotation": 6
    },
    {
      "x": -14,
      "y": 10,
      "z": -3,
      "name": "Cloth_Block_Wool_Orange_Light"
    },
    {
      "x": -14,
      "y": 26,
      "z": -3,
      "name": "Cloth_Block_Wool_Orange_Light"
    },
    {
      "x": -14,
      "y": 10,
      "z": -2,
      "name": "Cloth_Block_Wool_Orange_Light"
    },
    {
      "x": -14,
      "y": 24,
      "z": -2,
      "name": "Cloth_Block_Wool_Orange_Light"
    },
    {
      "x": -14,
      "y": 25,
      "z": -2,
      "name": "Cloth_Block_Wool_Orange_Light"
    },
    {
      "x": -14,
      "y": 26,
      "z": -2,
      "name": "Cloth_Block_Wool_Orange_Light"
    },
    {
      "x": -14,
      "y": 27,
      "z": -2,
      "name": "Cloth_Block_Wool_Orange_Light"
    },
    {
      "x": -14,
      "y": 28,
      "z": -2,
      "name": "Cloth_Block_Wool_Orange_Light"
    },
    {
      "x": -14,
      "y": 10,
      "z": -1,
      "name": "Cloth_Block_Wool_Orange_Light"
    },
    {
      "x": -14,
      "y": 23,
      "z": -1,
      "name": "Cloth_Block_Wool_Orange_Light"
    },
    {
      "x": -14,
      "y": 24,
      "z": -1,
      "name": "Cloth_Block_Wool_Orange_Light"
    },
    {
      "x": -14,
      "y": 25,
      "z": -1,
      "name": "Cloth_Block_Wool_Orange_Light"
    },
    {
      "x": -14,
      "y": 26,
      "z": -1,
      "name": "Cloth_Block_Wool_Orange_Light"
    },
    {
      "x": -14,
      "y": 27,
      "z": -1,
      "name": "Cloth_Block_Wool_Orange_Light"
    },
    {
      "x": -14,
      "y": 28,
      "z": -1,
      "name": "Cloth_Block_Wool_Orange_Light"
    },
    {
      "x": -14,
      "y": 29,
      "z": -1,
      "name": "Cloth_Block_Wool_Orange_Light"
    },
    {
      "x": -14,
      "y": 23,
      "z": 0,
      "name": "Cloth_Block_Wool_Orange_Light"
    },
    {
      "x": -14,
      "y": 24,
      "z": 0,
      "name": "Cloth_Block_Wool_Orange_Light"
    },
    {
      "x": -14,
      "y": 25,
      "z": 0,
      "name": "Cloth_Block_Wool_Orange_Light"
    },
    {
      "x": -14,
      "y": 27,
      "z": 0,
      "name": "Cloth_Block_Wool_Orange_Light"
    },
    {
      "x": -14,
      "y": 28,
      "z": 0,
      "name": "Cloth_Block_Wool_Orange_Light"
    },
    {
      "x": -14,
      "y": 29,
      "z": 0,
      "name": "Cloth_Block_Wool_Orange_Light"
    },
    {
      "x": -14,
      "y": 7,
      "z": 1,
      "name": "Wood_Hardwood_Stairs",
      "rotation": 11
    },
    {
      "x": -14,
      "y": 8,
      "z": 1,
      "name": "Cloth_Block_Wool_Orange_Light"
    },
    {
      "x": -14,
      "y": 9,
      "z": 1,
      "name": "Cloth_Block_Wool_Orange_Light"
    },
    {
      "x": -14,
      "y": 10,
      "z": 1,
      "name": "Cloth_Block_Wool_Orange_Light"
    },
    {
      "x": -14,
      "y": 11,
      "z": 1,
      "name": "Cloth_Block_Wool_Orange_Light"
    },
    {
      "x": -14,
      "y": 12,
      "z": 1,
      "name": "Cloth_Block_Wool_Orange_Light"
    },
    {
      "x": -14,
      "y": 13,
      "z": 1,
      "name": "Wood_Hardwood_Stairs",
      "rotation": 1
    },
    {
      "x": -14,
      "y": 22,
      "z": 1,
      "name": "Cloth_Block_Wool_Orange_Light"
    },
    {
      "x": -14,
      "y": 23,
      "z": 1,
      "name": "Cloth_Block_Wool_Orange_Light"
    },
    {
      "x": -14,
      "y": 24,
      "z": 1,
      "name": "Cloth_Block_Wool_Orange_Light"
    },
    {
      "x": -14,
      "y": 28,
      "z": 1,
      "name": "Cloth_Block_Wool_Orange_Light"
    },
    {
      "x": -14,
      "y": 29,
      "z": 1,
      "name": "Cloth_Block_Wool_Orange_Light"
    },
    {
      "x": -14,
      "y": 30,
      "z": 1,
      "name": "Cloth_Block_Wool_Orange_Light"
    },
    {
      "x": -14,
      "y": 23,
      "z": 2,
      "name": "Cloth_Block_Wool_Orange_Light"
    },
    {
      "x": -14,
      "y": 24,
      "z": 2,
      "name": "Cloth_Block_Wool_Orange_Light"
    },
    {
      "x": -14,
      "y": 25,
      "z": 2,
      "name": "Cloth_Block_Wool_Orange_Light"
    },
    {
      "x": -14,
      "y": 27,
      "z": 2,
      "name": "Cloth_Block_Wool_Orange_Light"
    },
    {
      "x": -14,
      "y": 28,
      "z": 2,
      "name": "Cloth_Block_Wool_Orange_Light"
    },
    {
      "x": -14,
      "y": 29,
      "z": 2,
      "name": "Cloth_Block_Wool_Orange_Light"
    },
    {
      "x": -14,
      "y": 10,
      "z": 3,
      "name": "Cloth_Block_Wool_Orange_Light"
    },
    {
      "x": -14,
      "y": 23,
      "z": 3,
      "name": "Cloth_Block_Wool_Orange_Light"
    },
    {
      "x": -14,
      "y": 24,
      "z": 3,
      "name": "Cloth_Block_Wool_Orange_Light"
    },
    {
      "x": -14,
      "y": 25,
      "z": 3,
      "name": "Cloth_Block_Wool_Orange_Light"
    },
    {
      "x": -14,
      "y": 26,
      "z": 3,
      "name": "Cloth_Block_Wool_Orange_Light"
    },
    {
      "x": -14,
      "y": 27,
      "z": 3,
      "name": "Cloth_Block_Wool_Orange_Light"
    },
    {
      "x": -14,
      "y": 28,
      "z": 3,
      "name": "Cloth_Block_Wool_Orange_Light"
    },
    {
      "x": -14,
      "y": 29,
      "z": 3,
      "name": "Cloth_Block_Wool_Orange_Light"
    },
    {
      "x": -14,
      "y": 10,
      "z": 4,
      "name": "Cloth_Block_Wool_Orange_Light"
    },
    {
      "x": -14,
      "y": 24,
      "z": 4,
      "name": "Cloth_Block_Wool_Orange_Light"
    },
    {
      "x": -14,
      "y": 25,
      "z": 4,
      "name": "Cloth_Block_Wool_Orange_Light"
    },
    {
      "x": -14,
      "y": 26,
      "z": 4,
      "name": "Cloth_Block_Wool_Orange_Light"
    },
    {
      "x": -14,
      "y": 27,
      "z": 4,
      "name": "Cloth_Block_Wool_Orange_Light"
    },
    {
      "x": -14,
      "y": 28,
      "z": 4,
      "name": "Cloth_Block_Wool_Orange_Light"
    },
    {
      "x": -14,
      "y": 10,
      "z": 5,
      "name": "Cloth_Block_Wool_Orange_Light"
    },
    {
      "x": -14,
      "y": 26,
      "z": 5,
      "name": "Cloth_Block_Wool_Orange_Light"
    },
    {
      "x": -14,
      "y": 10,
      "z": 6,
      "name": "Wood_Hardwood_Planks_Half",
      "rotation": 4
    },
    {
      "x": -13,
      "y": 10,
      "z": -4,
      "name": "Wood_Hardwood_Planks_Half",
      "rotation": 6
    },
    {
      "x": -13,
      "y": 26,
      "z": -4,
      "name": "Cloth_Block_Wool_Orange_Light"
    },
    {
      "x": -13,
      "y": 10,
      "z": -3,
      "name": "Cloth_Block_Wool_Orange_Light"
    },
    {
      "x": -13,
      "y": 23,
      "z": -3,
      "name": "Cloth_Block_Wool_Orange_Light"
    },
    {
      "x": -13,
      "y": 24,
      "z": -3,
      "name": "Cloth_Block_Wool_Orange_Light"
    },
    {
      "x": -13,
      "y": 25,
      "z": -3,
      "name": "Cloth_Block_Wool_Orange_Light"
    },
    {
      "x": -13,
      "y": 26,
      "z": -3,
      "name": "Cloth_Block_Wool_Orange_Light"
    },
    {
      "x": -13,
      "y": 27,
      "z": -3,
      "name": "Cloth_Block_Wool_Orange_Light"
    },
    {
      "x": -13,
      "y": 28,
      "z": -3,
      "name": "Cloth_Block_Wool_Orange_Light"
    },
    {
      "x": -13,
      "y": 29,
      "z": -3,
      "name": "Cloth_Block_Wool_Orange_Light"
    },
    {
      "x": -13,
      "y": 10,
      "z": -2,
      "name": "Cloth_Block_Wool_Orange_Light"
    },
    {
      "x": -13,
      "y": 22,
      "z": -2,
      "name": "Cloth_Block_Wool_Orange_Light"
    },
    {
      "x": -13,
      "y": 23,
      "z": -2,
      "name": "Cloth_Block_Wool_Orange_Light"
    },
    {
      "x": -13,
      "y": 24,
      "z": -2,
      "name": "Cloth_Block_Wool_Orange_Light"
    },
    {
      "x": -13,
      "y": 25,
      "z": -2,
      "name": "Cloth_Block_Wool_Orange_Light"
    },
    {
      "x": -13,
      "y": 26,
      "z": -2,
      "name": "Cloth_Block_Wool_Orange_Light"
    },
    {
      "x": -13,
      "y": 27,
      "z": -2,
      "name": "Cloth_Block_Wool_Orange_Light"
    },
    {
      "x": -13,
      "y": 28,
      "z": -2,
      "name": "Cloth_Block_Wool_Orange_Light"
    },
    {
      "x": -13,
      "y": 29,
      "z": -2,
      "name": "Cloth_Block_Wool_Orange_Light"
    },
    {
      "x": -13,
      "y": 30,
      "z": -2,
      "name": "Cloth_Block_Wool_Orange_Light"
    },
    {
      "x": -13,
      "y": 10,
      "z": -1,
      "name": "Cloth_Block_Wool_Orange_Light"
    },
    {
      "x": -13,
      "y": 22,
      "z": -1,
      "name": "Cloth_Block_Wool_Orange_Light"
    },
    {
      "x": -13,
      "y": 23,
      "z": -1,
      "name": "Cloth_Block_Wool_Orange_Light"
    },
    {
      "x": -13,
      "y": 24,
      "z": -1,
      "name": "Cloth_Block_Wool_Orange_Light"
    },
    {
      "x": -13,
      "y": 28,
      "z": -1,
      "name": "Cloth_Block_Wool_Orange_Light"
    },
    {
      "x": -13,
      "y": 29,
      "z": -1,
      "name": "Cloth_Block_Wool_Orange_Light"
    },
    {
      "x": -13,
      "y": 30,
      "z": -1,
      "name": "Cloth_Block_Wool_Orange_Light"
    },
    {
      "x": -13,
      "y": 22,
      "z": 0,
      "name": "Cloth_Block_Wool_Orange_Light"
    },
    {
      "x": -13,
      "y": 23,
      "z": 0,
      "name": "Cloth_Block_Wool_Orange_Light"
    },
    {
      "x": -13,
      "y": 29,
      "z": 0,
      "name": "Cloth_Block_Wool_Orange_Light"
    },
    {
      "x": -13,
      "y": 30,
      "z": 0,
      "name": "Cloth_Block_Wool_Orange_Light"
    },
    {
      "x": -13,
      "y": 8,
      "z": 1,
      "name": "Wood_Hardwood_Stairs",
      "rotation": 11
    },
    {
      "x": -13,
      "y": 9,
      "z": 1,
      "name": "Cloth_Block_Wool_Orange_Light"
    },
    {
      "x": -13,
      "y": 10,
      "z": 1,
      "name": "Cloth_Block_Wool_Orange_Light"
    },
    {
      "x": -13,
      "y": 11,
      "z": 1,
      "name": "Cloth_Block_Wool_Orange_Light"
    },
    {
      "x": -13,
      "y": 12,
      "z": 1,
      "name": "Wood_Hardwood_Planks"
    },
    {
      "x": -13,
      "y": 13,
      "z": 1,
      "name": "Wood_Hardwood_Planks_Half"
    },
    {
      "x": -13,
      "y": 21,
      "z": 1,
      "name": "Cloth_Block_Wool_Orange_Light"
    },
    {
      "x": -13,
      "y": 22,
      "z": 1,
      "name": "Cloth_Block_Wool_Orange_Light"
    },
    {
      "x": -13,
      "y": 23,
      "z": 1,
      "name": "Cloth_Block_Wool_Orange_Light"
    },
    {
      "x": -13,
      "y": 29,
      "z": 1,
      "name": "Cloth_Block_Wool_Orange_Light"
    },
    {
      "x": -13,
      "y": 30,
      "z": 1,
      "name": "Cloth_Block_Wool_Orange_Light"
    },
    {
      "x": -13,
      "y": 31,
      "z": 1,
      "name": "Cloth_Block_Wool_Orange_Light"
    },
    {
      "x": -13,
      "y": 22,
      "z": 2,
      "name": "Cloth_Block_Wool_Orange_Light"
    },
    {
      "x": -13,
      "y": 23,
      "z": 2,
      "name": "Cloth_Block_Wool_Orange_Light"
    },
    {
      "x": -13,
      "y": 29,
      "z": 2,
      "name": "Cloth_Block_Wool_Orange_Light"
    },
    {
      "x": -13,
      "y": 30,
      "z": 2,
      "name": "Cloth_Block_Wool_Orange_Light"
    },
    {
      "x": -13,
      "y": 10,
      "z": 3,
      "name": "Cloth_Block_Wool_Orange_Light"
    },
    {
      "x": -13,
      "y": 22,
      "z": 3,
      "name": "Cloth_Block_Wool_Orange_Light"
    },
    {
      "x": -13,
      "y": 23,
      "z": 3,
      "name": "Cloth_Block_Wool_Orange_Light"
    },
    {
      "x": -13,
      "y": 24,
      "z": 3,
      "name": "Cloth_Block_Wool_Orange_Light"
    },
    {
      "x": -13,
      "y": 28,
      "z": 3,
      "name": "Cloth_Block_Wool_Orange_Light"
    },
    {
      "x": -13,
      "y": 29,
      "z": 3,
      "name": "Cloth_Block_Wool_Orange_Light"
    },
    {
      "x": -13,
      "y": 30,
      "z": 3,
      "name": "Cloth_Block_Wool_Orange_Light"
    },
    {
      "x": -13,
      "y": 10,
      "z": 4,
      "name": "Cloth_Block_Wool_Orange_Light"
    },
    {
      "x": -13,
      "y": 22,
      "z": 4,
      "name": "Cloth_Block_Wool_Orange_Light"
    },
    {
      "x": -13,
      "y": 23,
      "z": 4,
      "name": "Cloth_Block_Wool_Orange_Light"
    },
    {
      "x": -13,
      "y": 24,
      "z": 4,
      "name": "Cloth_Block_Wool_Orange_Light"
    },
    {
      "x": -13,
      "y": 25,
      "z": 4,
      "name": "Cloth_Block_Wool_Orange_Light"
    },
    {
      "x": -13,
      "y": 26,
      "z": 4,
      "name": "Cloth_Block_Wool_Orange_Light"
    },
    {
      "x": -13,
      "y": 27,
      "z": 4,
      "name": "Cloth_Block_Wool_Orange_Light"
    },
    {
      "x": -13,
      "y": 28,
      "z": 4,
      "name": "Cloth_Block_Wool_Orange_Light"
    },
    {
      "x": -13,
      "y": 29,
      "z": 4,
      "name": "Cloth_Block_Wool_Orange_Light"
    },
    {
      "x": -13,
      "y": 30,
      "z": 4,
      "name": "Cloth_Block_Wool_Orange_Light"
    },
    {
      "x": -13,
      "y": 10,
      "z": 5,
      "name": "Cloth_Block_Wool_Orange_Light"
    },
    {
      "x": -13,
      "y": 23,
      "z": 5,
      "name": "Cloth_Block_Wool_Orange_Light"
    },
    {
      "x": -13,
      "y": 24,
      "z": 5,
      "name": "Cloth_Block_Wool_Orange_Light"
    },
    {
      "x": -13,
      "y": 25,
      "z": 5,
      "name": "Cloth_Block_Wool_Orange_Light"
    },
    {
      "x": -13,
      "y": 26,
      "z": 5,
      "name": "Cloth_Block_Wool_Orange_Light"
    },
    {
      "x": -13,
      "y": 27,
      "z": 5,
      "name": "Cloth_Block_Wool_Orange_Light"
    },
    {
      "x": -13,
      "y": 28,
      "z": 5,
      "name": "Cloth_Block_Wool_Orange_Light"
    },
    {
      "x": -13,
      "y": 29,
      "z": 5,
      "name": "Cloth_Block_Wool_Orange_Light"
    },
    {
      "x": -13,
      "y": 10,
      "z": 6,
      "name": "Wood_Hardwood_Planks_Half",
      "rotation": 4
    },
    {
      "x": -13,
      "y": 26,
      "z": 6,
      "name": "Cloth_Block_Wool_Orange_Light"
    },
    {
      "x": -12,
      "y": 24,
      "z": -4,
      "name": "Cloth_Block_Wool_Orange_Light"
    },
    {
      "x": -12,
      "y": 25,
      "z": -4,
      "name": "Cloth_Block_Wool_Orange_Light"
    },
    {
      "x": -12,
      "y": 26,
      "z": -4,
      "name": "Cloth_Block_Wool_Orange_Light"
    },
    {
      "x": -12,
      "y": 27,
      "z": -4,
      "name": "Cloth_Block_Wool_Orange_Light"
    },
    {
      "x": -12,
      "y": 28,
      "z": -4,
      "name": "Cloth_Block_Wool_Orange_Light"
    },
    {
      "x": -12,
      "y": 10,
      "z": -3,
      "name": "*Wood_Hardwood_Planks_Half_State_Definitions_Block",
      "rotation": 6
    },
    {
      "x": -12,
      "y": 22,
      "z": -3,
      "name": "Cloth_Block_Wool_Orange_Light"
    },
    {
      "x": -12,
      "y": 23,
      "z": -3,
      "name": "Cloth_Block_Wool_Orange_Light"
    },
    {
      "x": -12,
      "y": 24,
      "z": -3,
      "name": "Cloth_Block_Wool_Orange_Light"
    },
    {
      "x": -12,
      "y": 25,
      "z": -3,
      "name": "Cloth_Block_Wool_Orange_Light"
    },
    {
      "x": -12,
      "y": 26,
      "z": -3,
      "name": "Cloth_Block_Wool_Orange_Light"
    },
    {
      "x": -12,
      "y": 27,
      "z": -3,
      "name": "Cloth_Block_Wool_Orange_Light"
    },
    {
      "x": -12,
      "y": 28,
      "z": -3,
      "name": "Cloth_Block_Wool_Orange_Light"
    },
    {
      "x": -12,
      "y": 29,
      "z": -3,
      "name": "Cloth_Block_Wool_Orange_Light"
    },
    {
      "x": -12,
      "y": 30,
      "z": -3,
      "name": "Cloth_Block_Wool_Orange_Light"
    },
    {
      "x": -12,
      "y": 10,
      "z": -2,
      "name": "Cloth_Block_Wool_Orange_Light"
    },
    {
      "x": -12,
      "y": 22,
      "z": -2,
      "name": "Cloth_Block_Wool_Orange_Light"
    },
    {
      "x": -12,
      "y": 23,
      "z": -2,
      "name": "Cloth_Block_Wool_Orange_Light"
    },
    {
      "x": -12,
      "y": 29,
      "z": -2,
      "name": "Cloth_Block_Wool_Orange_Light"
    },
    {
      "x": -12,
      "y": 30,
      "z": -2,
      "name": "Cloth_Block_Wool_Orange_Light"
    },
    {
      "x": -12,
      "y": 10,
      "z": -1,
      "name": "Cloth_Block_Wool_Orange_Light"
    },
    {
      "x": -12,
      "y": 21,
      "z": -1,
      "name": "Cloth_Block_Wool_Orange_Light"
    },
    {
      "x": -12,
      "y": 22,
      "z": -1,
      "name": "Cloth_Block_Wool_Orange_Light"
    },
    {
      "x": -12,
      "y": 30,
      "z": -1,
      "name": "Cloth_Block_Wool_Orange_Light"
    },
    {
      "x": -12,
      "y": 31,
      "z": -1,
      "name": "Cloth_Block_Wool_Orange_Light"
    },
    {
      "x": -12,
      "y": 4,
      "z": 0,
      "name": "*Wood_Hardwood_Stairs_State_Definitions_Corner_Left",
      "rotation": 9
    },
    {
      "x": -12,
      "y": 8,
      "z": 0,
      "name": "Wood_Hardwood_Stairs",
      "rotation": 9
    },
    {
      "x": -12,
      "y": 9,
      "z": 0,
      "name": "Wood_Hardwood_Planks"
    },
    {
      "x": -12,
      "y": 10,
      "z": 0,
      "name": "Wood_Hardwood_Planks"
    },
    {
      "x": -12,
      "y": 11,
      "z": 0,
      "name": "Wood_Hardwood_Planks"
    },
    {
      "x": -12,
      "y": 12,
      "z": 0,
      "name": "Wood_Hardwood_Stairs",
      "rotation": 3
    },
    {
      "x": -12,
      "y": 21,
      "z": 0,
      "name": "Cloth_Block_Wool_Orange_Light"
    },
    {
      "x": -12,
      "y": 22,
      "z": 0,
      "name": "Cloth_Block_Wool_Orange_Light"
    },
    {
      "x": -12,
      "y": 30,
      "z": 0,
      "name": "Cloth_Block_Wool_Orange_Light"
    },
    {
      "x": -12,
      "y": 31,
      "z": 0,
      "name": "Cloth_Block_Wool_Orange_Light"
    },
    {
      "x": -12,
      "y": 0,
      "z": 1,
      "name": "Deco_Iron_Chain_Small"
    },
    {
      "x": -12,
      "y": 1,
      "z": 1,
      "name": "Deco_Iron_Chain_Small"
    },
    {
      "x": -12,
      "y": 2,
      "z": 1,
      "name": "Deco_Iron_Chain_Small"
    },
    {
      "x": -12,
      "y": 3,
      "z": 1,
      "name": "Deco_Iron_Chain_Small"
    },
    {
      "x": -12,
      "y": 4,
      "z": 1,
      "name": "Deco_Iron_Chain_Small"
    },
    {
      "x": -12,
      "y": 5,
      "z": 1,
      "name": "Deco_Iron_Chain_Small"
    },
    {
      "x": -12,
      "y": 6,
      "z": 1,
      "name": "Deco_Iron_Chain_Small"
    },
    {
      "x": -12,
      "y": 7,
      "z": 1,
      "name": "Wood_Hardwood_Ornate"
    },
    {
      "x": -12,
      "y": 8,
      "z": 1,
      "name": "Wood_Hardwood_Planks"
    },
    {
      "x": -12,
      "y": 9,
      "z": 1,
      "name": "Cloth_Block_Wool_Orange_Light"
    },
    {
      "x": -12,
      "y": 10,
      "z": 1,
      "name": "Cloth_Block_Wool_Orange_Light"
    },
    {
      "x": -12,
      "y": 11,
      "z": 1,
      "name": "Cloth_Block_Wool_Orange_Light"
    },
    {
      "x": -12,
      "y": 12,
      "z": 1,
      "name": "Wood_Hardwood_Planks"
    },
    {
      "x": -12,
      "y": 13,
      "z": 1,
      "name": "Wood_Hardwood_Planks"
    },
    {
      "x": -12,
      "y": 14,
      "z": 1,
      "name": "Wood_Hardwood_Planks"
    },
    {
      "x": -12,
      "y": 15,
      "z": 1,
      "name": "Wood_Hardwood_Planks"
    },
    {
      "x": -12,
      "y": 16,
      "z": 1,
      "name": "Wood_Hardwood_Stairs",
      "rotation": 3
    },
    {
      "x": -12,
      "y": 21,
      "z": 1,
      "name": "Cloth_Block_Wool_Orange_Light"
    },
    {
      "x": -12,
      "y": 22,
      "z": 1,
      "name": "Cloth_Block_Wool_Orange_Light"
    },
    {
      "x": -12,
      "y": 30,
      "z": 1,
      "name": "Cloth_Block_Wool_Orange_Light"
    },
    {
      "x": -12,
      "y": 31,
      "z": 1,
      "name": "Cloth_Block_Wool_Orange_Light"
    },
    {
      "x": -12,
      "y": 4,
      "z": 2,
      "name": "*Wood_Hardwood_Stairs_State_Definitions_Corner_Right",
      "rotation": 9
    },
    {
      "x": -12,
      "y": 8,
      "z": 2,
      "name": "Wood_Hardwood_Stairs",
      "rotation": 9
    },
    {
      "x": -12,
      "y": 9,
      "z": 2,
      "name": "Wood_Hardwood_Planks"
    },
    {
      "x": -12,
      "y": 10,
      "z": 2,
      "name": "Wood_Hardwood_Planks"
    },
    {
      "x": -12,
      "y": 11,
      "z": 2,
      "name": "Wood_Hardwood_Planks"
    },
    {
      "x": -12,
      "y": 12,
      "z": 2,
      "name": "Wood_Hardwood_Stairs",
      "rotation": 3
    },
    {
      "x": -12,
      "y": 21,
      "z": 2,
      "name": "Cloth_Block_Wool_Orange_Light"
    },
    {
      "x": -12,
      "y": 22,
      "z": 2,
      "name": "Cloth_Block_Wool_Orange_Light"
    },
    {
      "x": -12,
      "y": 30,
      "z": 2,
      "name": "Cloth_Block_Wool_Orange_Light"
    },
    {
      "x": -12,
      "y": 31,
      "z": 2,
      "name": "Cloth_Block_Wool_Orange_Light"
    },
    {
      "x": -12,
      "y": 10,
      "z": 3,
      "name": "Cloth_Block_Wool_Orange_Light"
    },
    {
      "x": -12,
      "y": 21,
      "z": 3,
      "name": "Cloth_Block_Wool_Orange_Light"
    },
    {
      "x": -12,
      "y": 22,
      "z": 3,
      "name": "Cloth_Block_Wool_Orange_Light"
    },
    {
      "x": -12,
      "y": 30,
      "z": 3,
      "name": "Cloth_Block_Wool_Orange_Light"
    },
    {
      "x": -12,
      "y": 31,
      "z": 3,
      "name": "Cloth_Block_Wool_Orange_Light"
    },
    {
      "x": -12,
      "y": 10,
      "z": 4,
      "name": "Cloth_Block_Wool_Orange_Light"
    },
    {
      "x": -12,
      "y": 22,
      "z": 4,
      "name": "Cloth_Block_Wool_Orange_Light"
    },
    {
      "x": -12,
      "y": 23,
      "z": 4,
      "name": "Cloth_Block_Wool_Orange_Light"
    },
    {
      "x": -12,
      "y": 29,
      "z": 4,
      "name": "Cloth_Block_Wool_Orange_Light"
    },
    {
      "x": -12,
      "y": 30,
      "z": 4,
      "name": "Cloth_Block_Wool_Orange_Light"
    },
    {
      "x": -12,
      "y": 10,
      "z": 5,
      "name": "*Wood_Hardwood_Planks_Half_State_Definitions_Block",
      "rotation": 4
    },
    {
      "x": -12,
      "y": 22,
      "z": 5,
      "name": "Cloth_Block_Wool_Orange_Light"
    },
    {
      "x": -12,
      "y": 23,
      "z": 5,
      "name": "Cloth_Block_Wool_Orange_Light"
    },
    {
      "x": -12,
      "y": 24,
      "z": 5,
      "name": "Cloth_Block_Wool_Orange_Light"
    },
    {
      "x": -12,
      "y": 25,
      "z": 5,
      "name": "Cloth_Block_Wool_Orange_Light"
    },
    {
      "x": -12,
      "y": 26,
      "z": 5,
      "name": "Cloth_Block_Wool_Orange_Light"
    },
    {
      "x": -12,
      "y": 27,
      "z": 5,
      "name": "Cloth_Block_Wool_Orange_Light"
    },
    {
      "x": -12,
      "y": 28,
      "z": 5,
      "name": "Cloth_Block_Wool_Orange_Light"
    },
    {
      "x": -12,
      "y": 29,
      "z": 5,
      "name": "Cloth_Block_Wool_Orange_Light"
    },
    {
      "x": -12,
      "y": 30,
      "z": 5,
      "name": "Cloth_Block_Wool_Orange_Light"
    },
    {
      "x": -12,
      "y": 24,
      "z": 6,
      "name": "Cloth_Block_Wool_Orange_Light"
    },
    {
      "x": -12,
      "y": 25,
      "z": 6,
      "name": "Cloth_Block_Wool_Orange_Light"
    },
    {
      "x": -12,
      "y": 26,
      "z": 6,
      "name": "Cloth_Block_Wool_Orange_Light"
    },
    {
      "x": -12,
      "y": 27,
      "z": 6,
      "name": "Cloth_Block_Wool_Orange_Light"
    },
    {
      "x": -12,
      "y": 28,
      "z": 6,
      "name": "Cloth_Block_Wool_Orange_Light"
    },
    {
      "x": -11,
      "y": 25,
      "z": -5,
      "name": "Cloth_Block_Wool_Orange_Light"
    },
    {
      "x": -11,
      "y": 26,
      "z": -5,
      "name": "Cloth_Block_Wool_Orange_Light"
    },
    {
      "x": -11,
      "y": 27,
      "z": -5,
      "name": "Cloth_Block_Wool_Orange_Light"
    },
    {
      "x": -11,
      "y": 23,
      "z": -4,
      "name": "Cloth_Block_Wool_Orange_Light"
    },
    {
      "x": -11,
      "y": 24,
      "z": -4,
      "name": "Cloth_Block_Wool_Orange_Light"
    },
    {
      "x": -11,
      "y": 25,
      "z": -4,
      "name": "Cloth_Block_Wool_Orange_Light"
    },
    {
      "x": -11,
      "y": 26,
      "z": -4,
      "name": "Cloth_Block_Wool_Orange_Light"
    },
    {
      "x": -11,
      "y": 27,
      "z": -4,
      "name": "Cloth_Block_Wool_Orange_Light"
    },
    {
      "x": -11,
      "y": 28,
      "z": -4,
      "name": "Cloth_Block_Wool_Orange_Light"
    },
    {
      "x": -11,
      "y": 29,
      "z": -4,
      "name": "Cloth_Block_Wool_Orange_Light"
    },
    {
      "x": -11,
      "y": 10,
      "z": -3,
      "name": "Wood_Hardwood_Planks"
    },
    {
      "x": -11,
      "y": 11,
      "z": -3,
      "name": "Wood_Hardwood_Planks"
    },
    {
      "x": -11,
      "y": 12,
      "z": -3,
      "name": "Wood_Hardwood_Planks"
    },
    {
      "x": -11,
      "y": 13,
      "z": -3,
      "name": "Wood_Hardwood_Planks"
    },
    {
      "x": -11,
      "y": 14,
      "z": -3,
      "name": "Wood_Hardwood_Planks"
    },
    {
      "x": -11,
      "y": 15,
      "z": -3,
      "name": "Wood_Hardwood_Planks"
    },
    {
      "x": -11,
      "y": 16,
      "z": -3,
      "name": "Wood_Hardwood_Planks"
    },
    {
      "x": -11,
      "y": 22,
      "z": -3,
      "name": "Cloth_Block_Wool_Orange_Light"
    },
    {
      "x": -11,
      "y": 23,
      "z": -3,
      "name": "Cloth_Block_Wool_Orange_Light"
    },
    {
      "x": -11,
      "y": 24,
      "z": -3,
      "name": "Cloth_Block_Wool_Orange_Light"
    },
    {
      "x": -11,
      "y": 28,
      "z": -3,
      "name": "Cloth_Block_Wool_Orange_Light"
    },
    {
      "x": -11,
      "y": 29,
      "z": -3,
      "name": "Cloth_Block_Wool_Orange_Light"
    },
    {
      "x": -11,
      "y": 30,
      "z": -3,
      "name": "Cloth_Block_Wool_Orange_Light"
    },
    {
      "x": -11,
      "y": 9,
      "z": -2,
      "name": "Wood_Hardwood_Planks"
    },
    {
      "x": -11,
      "y": 10,
      "z": -2,
      "name": "Wood_Hardwood_Planks"
    },
    {
      "x": -11,
      "y": 11,
      "z": -2,
      "name": "Wood_Hardwood_Planks"
    },
    {
      "x": -11,
      "y": 12,
      "z": -2,
      "name": "Wood_Hardwood_Planks"
    },
    {
      "x": -11,
      "y": 13,
      "z": -2,
      "name": "Wood_Hardwood_Planks"
    },
    {
      "x": -11,
      "y": 14,
      "z": -2,
      "name": "Furniture_Village_Window",
      "rotation": 1
    },
    {
      "x": -11,
      "y": 15,
      "z": -2,
      "name": "Wood_Hardwood_Planks"
    },
    {
      "x": -11,
      "y": 16,
      "z": -2,
      "name": "Wood_Hardwood_Planks"
    },
    {
      "x": -11,
      "y": 21,
      "z": -2,
      "name": "Cloth_Block_Wool_Orange_Light"
    },
    {
      "x": -11,
      "y": 22,
      "z": -2,
      "name": "Cloth_Block_Wool_Orange_Light"
    },
    {
      "x": -11,
      "y": 30,
      "z": -2,
      "name": "Cloth_Block_Wool_Orange_Light"
    },
    {
      "x": -11,
      "y": 31,
      "z": -2,
      "name": "Cloth_Block_Wool_Orange_Light"
    },
    {
      "x": -11,
      "y": 7,
      "z": -1,
      "name": "Deco_Lantern_Ceiling"
    },
    {
      "x": -11,
      "y": 8,
      "z": -1,
      "name": "Wood_Hardwood_Planks"
    },
    {
      "x": -11,
      "y": 9,
      "z": -1,
      "name": "Wood_Hardwood_Planks"
    },
    {
      "x": -11,
      "y": 10,
      "z": -1,
      "name": "Wood_Hardwood_Planks"
    },
    {
      "x": -11,
      "y": 11,
      "z": -1,
      "name": "Wood_Hardwood_Planks"
    },
    {
      "x": -11,
      "y": 12,
      "z": -1,
      "name": "Wood_Hardwood_Planks"
    },
    {
      "x": -11,
      "y": 13,
      "z": -1,
      "name": "Wood_Hardwood_Planks"
    },
    {
      "x": -11,
      "y": 14,
      "z": -1,
      "name": "Wood_Hardwood_Planks"
    },
    {
      "x": -11,
      "y": 15,
      "z": -1,
      "name": "Wood_Hardwood_Planks"
    },
    {
      "x": -11,
      "y": 16,
      "z": -1,
      "name": "Wood_Hardwood_Planks"
    },
    {
      "x": -11,
      "y": 21,
      "z": -1,
      "name": "Cloth_Block_Wool_Orange_Light"
    },
    {
      "x": -11,
      "y": 22,
      "z": -1,
      "name": "Cloth_Block_Wool_Orange_Light"
    },
    {
      "x": -11,
      "y": 30,
      "z": -1,
      "name": "Cloth_Block_Wool_Orange_Light"
    },
    {
      "x": -11,
      "y": 31,
      "z": -1,
      "name": "Cloth_Block_Wool_Orange_Light"
    },
    {
      "x": -11,
      "y": 4,
      "z": 0,
      "name": "Wood_Hardwood_Stairs",
      "rotation": 8
    },
    {
      "x": -11,
      "y": 8,
      "z": 0,
      "name": "Wood_Hardwood_Planks"
    },
    {
      "x": -11,
      "y": 9,
      "z": 0,
      "name": "Wood_Hardwood_Planks"
    },
    {
      "x": -11,
      "y": 10,
      "z": 0,
      "name": "Wood_Hardwood_Planks"
    },
    {
      "x": -11,
      "y": 11,
      "z": 0,
      "name": "Wood_Hardwood_Planks"
    },
    {
      "x": -11,
      "y": 12,
      "z": 0,
      "name": "Wood_Hardwood_Planks"
    },
    {
      "x": -11,
      "y": 13,
      "z": 0,
      "name": "Wood_Hardwood_Planks"
    },
    {
      "x": -11,
      "y": 14,
      "z": 0,
      "name": "Furniture_Village_Window",
      "rotation": 1
    },
    {
      "x": -11,
      "y": 15,
      "z": 0,
      "name": "Wood_Hardwood_Planks"
    },
    {
      "x": -11,
      "y": 16,
      "z": 0,
      "name": "Wood_Hardwood_Planks"
    },
    {
      "x": -11,
      "y": 20,
      "z": 0,
      "name": "Cloth_Block_Wool_Orange_Light"
    },
    {
      "x": -11,
      "y": 21,
      "z": 0,
      "name": "Cloth_Block_Wool_Orange_Light"
    },
    {
      "x": -11,
      "y": 31,
      "z": 0,
      "name": "Cloth_Block_Wool_Orange_Light"
    },
    {
      "x": -11,
      "y": 32,
      "z": 0,
      "name": "Cloth_Block_Wool_Orange_Light"
    },
    {
      "x": -11,
      "y": 4,
      "z": 1,
      "name": "Wood_Hardwood_Planks"
    },
    {
      "x": -11,
      "y": 5,
      "z": 1,
      "name": "Wood_Hardwood_Planks"
    },
    {
      "x": -11,
      "y": 6,
      "z": 1,
      "name": "Wood_Hardwood_Planks"
    },
    {
      "x": -11,
      "y": 7,
      "z": 1,
      "name": "Wood_Hardwood_Planks"
    },
    {
      "x": -11,
      "y": 8,
      "z": 1,
      "name": "Wood_Hardwood_Planks"
    },
    {
      "x": -11,
      "y": 9,
      "z": 1,
      "name": "Wood_Hardwood_Planks"
    },
    {
      "x": -11,
      "y": 10,
      "z": 1,
      "name": "Wood_Hardwood_Planks"
    },
    {
      "x": -11,
      "y": 11,
      "z": 1,
      "name": "Wood_Hardwood_Planks"
    },
    {
      "x": -11,
      "y": 12,
      "z": 1,
      "name": "Wood_Hardwood_Planks"
    },
    {
      "x": -11,
      "y": 13,
      "z": 1,
      "name": "Wood_Hardwood_Planks"
    },
    {
      "x": -11,
      "y": 14,
      "z": 1,
      "name": "Wood_Hardwood_Planks"
    },
    {
      "x": -11,
      "y": 15,
      "z": 1,
      "name": "Wood_Hardwood_Planks"
    },
    {
      "x": -11,
      "y": 16,
      "z": 1,
      "name": "Wood_Hardwood_Planks"
    },
    {
      "x": -11,
      "y": 20,
      "z": 1,
      "name": "Cloth_Block_Wool_Orange_Light"
    },
    {
      "x": -11,
      "y": 21,
      "z": 1,
      "name": "Cloth_Block_Wool_Orange_Light"
    },
    {
      "x": -11,
      "y": 22,
      "z": 1,
      "name": "Rock_Gem_Topaz"
    },
    {
      "x": -11,
      "y": 31,
      "z": 1,
      "name": "Cloth_Block_Wool_Orange_Light"
    },
    {
      "x": -11,
      "y": 32,
      "z": 1,
      "name": "Cloth_Block_Wool_Orange_Light"
    },
    {
      "x": -11,
      "y": 4,
      "z": 2,
      "name": "Wood_Hardwood_Stairs",
      "rotation": 10
    },
    {
      "x": -11,
      "y": 8,
      "z": 2,
      "name": "Wood_Hardwood_Planks"
    },
    {
      "x": -11,
      "y": 9,
      "z": 2,
      "name": "Wood_Hardwood_Planks"
    },
    {
      "x": -11,
      "y": 10,
      "z": 2,
      "name": "Wood_Hardwood_Planks"
    },
    {
      "x": -11,
      "y": 11,
      "z": 2,
      "name": "Wood_Hardwood_Planks"
    },
    {
      "x": -11,
      "y": 12,
      "z": 2,
      "name": "Wood_Hardwood_Planks"
    },
    {
      "x": -11,
      "y": 13,
      "z": 2,
      "name": "Wood_Hardwood_Planks"
    },
    {
      "x": -11,
      "y": 14,
      "z": 2,
      "name": "Furniture_Village_Window",
      "rotation": 1
    },
    {
      "x": -11,
      "y": 15,
      "z": 2,
      "name": "Wood_Hardwood_Planks"
    },
    {
      "x": -11,
      "y": 16,
      "z": 2,
      "name": "Wood_Hardwood_Planks"
    },
    {
      "x": -11,
      "y": 20,
      "z": 2,
      "name": "Cloth_Block_Wool_Orange_Light"
    },
    {
      "x": -11,
      "y": 21,
      "z": 2,
      "name": "Cloth_Block_Wool_Orange_Light"
    },
    {
      "x": -11,
      "y": 31,
      "z": 2,
      "name": "Cloth_Block_Wool_Orange_Light"
    },
    {
      "x": -11,
      "y": 32,
      "z": 2,
      "name": "Cloth_Block_Wool_Orange_Light"
    },
    {
      "x": -11,
      "y": 7,
      "z": 3,
      "name": "Deco_Lantern_Ceiling"
    },
    {
      "x": -11,
      "y": 8,
      "z": 3,
      "name": "Wood_Hardwood_Planks"
    },
    {
      "x": -11,
      "y": 9,
      "z": 3,
      "name": "Wood_Hardwood_Planks"
    },
    {
      "x": -11,
      "y": 10,
      "z": 3,
      "name": "Wood_Hardwood_Planks"
    },
    {
      "x": -11,
      "y": 11,
      "z": 3,
      "name": "Wood_Hardwood_Planks"
    },
    {
      "x": -11,
      "y": 12,
      "z": 3,
      "name": "Wood_Hardwood_Planks"
    },
    {
      "x": -11,
      "y": 13,
      "z": 3,
      "name": "Wood_Hardwood_Planks"
    },
    {
      "x": -11,
      "y": 14,
      "z": 3,
      "name": "Wood_Hardwood_Planks"
    },
    {
      "x": -11,
      "y": 15,
      "z": 3,
      "name": "Wood_Hardwood_Planks"
    },
    {
      "x": -11,
      "y": 16,
      "z": 3,
      "name": "Wood_Hardwood_Planks"
    },
    {
      "x": -11,
      "y": 21,
      "z": 3,
      "name": "Cloth_Block_Wool_Orange_Light"
    },
    {
      "x": -11,
      "y": 22,
      "z": 3,
      "name": "Cloth_Block_Wool_Orange_Light"
    },
    {
      "x": -11,
      "y": 30,
      "z": 3,
      "name": "Cloth_Block_Wool_Orange_Light"
    },
    {
      "x": -11,
      "y": 31,
      "z": 3,
      "name": "Cloth_Block_Wool_Orange_Light"
    },
    {
      "x": -11,
      "y": 9,
      "z": 4,
      "name": "Wood_Hardwood_Planks"
    },
    {
      "x": -11,
      "y": 10,
      "z": 4,
      "name": "Wood_Hardwood_Planks"
    },
    {
      "x": -11,
      "y": 11,
      "z": 4,
      "name": "Wood_Hardwood_Planks"
    },
    {
      "x": -11,
      "y": 12,
      "z": 4,
      "name": "Wood_Hardwood_Planks"
    },
    {
      "x": -11,
      "y": 13,
      "z": 4,
      "name": "Wood_Hardwood_Planks"
    },
    {
      "x": -11,
      "y": 14,
      "z": 4,
      "name": "Furniture_Village_Window",
      "rotation": 1
    },
    {
      "x": -11,
      "y": 15,
      "z": 4,
      "name": "Wood_Hardwood_Planks"
    },
    {
      "x": -11,
      "y": 16,
      "z": 4,
      "name": "Wood_Hardwood_Planks"
    },
    {
      "x": -11,
      "y": 21,
      "z": 4,
      "name": "Cloth_Block_Wool_Orange_Light"
    },
    {
      "x": -11,
      "y": 22,
      "z": 4,
      "name": "Cloth_Block_Wool_Orange_Light"
    },
    {
      "x": -11,
      "y": 30,
      "z": 4,
      "name": "Cloth_Block_Wool_Orange_Light"
    },
    {
      "x": -11,
      "y": 31,
      "z": 4,
      "name": "Cloth_Block_Wool_Orange_Light"
    },
    {
      "x": -11,
      "y": 10,
      "z": 5,
      "name": "Wood_Hardwood_Planks"
    },
    {
      "x": -11,
      "y": 11,
      "z": 5,
      "name": "Wood_Hardwood_Planks"
    },
    {
      "x": -11,
      "y": 12,
      "z": 5,
      "name": "Wood_Hardwood_Planks"
    },
    {
      "x": -11,
      "y": 13,
      "z": 5,
      "name": "Wood_Hardwood_Planks"
    },
    {
      "x": -11,
      "y": 14,
      "z": 5,
      "name": "Wood_Hardwood_Planks"
    },
    {
      "x": -11,
      "y": 15,
      "z": 5,
      "name": "Wood_Hardwood_Planks"
    },
    {
      "x": -11,
      "y": 16,
      "z": 5,
      "name": "Wood_Hardwood_Planks"
    },
    {
      "x": -11,
      "y": 22,
      "z": 5,
      "name": "Cloth_Block_Wool_Orange_Light"
    },
    {
      "x": -11,
      "y": 23,
      "z": 5,
      "name": "Cloth_Block_Wool_Orange_Light"
    },
    {
      "x": -11,
      "y": 24,
      "z": 5,
      "name": "Cloth_Block_Wool_Orange_Light"
    },
    {
      "x": -11,
      "y": 28,
      "z": 5,
      "name": "Cloth_Block_Wool_Orange_Light"
    },
    {
      "x": -11,
      "y": 29,
      "z": 5,
      "name": "Cloth_Block_Wool_Orange_Light"
    },
    {
      "x": -11,
      "y": 30,
      "z": 5,
      "name": "Cloth_Block_Wool_Orange_Light"
    },
    {
      "x": -11,
      "y": 23,
      "z": 6,
      "name": "Cloth_Block_Wool_Orange_Light"
    },
    {
      "x": -11,
      "y": 24,
      "z": 6,
      "name": "Cloth_Block_Wool_Orange_Light"
    },
    {
      "x": -11,
      "y": 25,
      "z": 6,
      "name": "Cloth_Block_Wool_Orange_Light"
    },
    {
      "x": -11,
      "y": 26,
      "z": 6,
      "name": "Cloth_Block_Wool_Orange_Light"
    },
    {
      "x": -11,
      "y": 27,
      "z": 6,
      "name": "Cloth_Block_Wool_Orange_Light"
    },
    {
      "x": -11,
      "y": 28,
      "z": 6,
      "name": "Cloth_Block_Wool_Orange_Light"
    },
    {
      "x": -11,
      "y": 29,
      "z": 6,
      "name": "Cloth_Block_Wool_Orange_Light"
    },
    {
      "x": -11,
      "y": 25,
      "z": 7,
      "name": "Cloth_Block_Wool_Orange_Light"
    },
    {
      "x": -11,
      "y": 26,
      "z": 7,
      "name": "Cloth_Block_Wool_Orange_Light"
    },
    {
      "x": -11,
      "y": 27,
      "z": 7,
      "name": "Cloth_Block_Wool_Orange_Light"
    },
    {
      "x": -10,
      "y": 24,
      "z": -5,
      "name": "Cloth_Block_Wool_Orange_Light"
    },
    {
      "x": -10,
      "y": 25,
      "z": -5,
      "name": "Cloth_Block_Wool_Orange_Light"
    },
    {
      "x": -10,
      "y": 26,
      "z": -5,
      "name": "Cloth_Block_Wool_Orange_Light"
    },
    {
      "x": -10,
      "y": 27,
      "z": -5,
      "name": "Cloth_Block_Wool_Orange_Light"
    },
    {
      "x": -10,
      "y": 28,
      "z": -5,
      "name": "Cloth_Block_Wool_Orange_Light"
    },
    {
      "x": -10,
      "y": 10,
      "z": -4,
      "name": "Wood_Hardwood_Planks"
    },
    {
      "x": -10,
      "y": 11,
      "z": -4,
      "name": "Wood_Hardwood_Planks"
    },
    {
      "x": -10,
      "y": 12,
      "z": -4,
      "name": "Wood_Hardwood_Planks"
    },
    {
      "x": -10,
      "y": 13,
      "z": -4,
      "name": "Wood_Hardwood_Planks"
    },
    {
      "x": -10,
      "y": 14,
      "z": -4,
      "name": "Wood_Hardwood_Planks"
    },
    {
      "x": -10,
      "y": 15,
      "z": -4,
      "name": "Wood_Hardwood_Planks"
    },
    {
      "x": -10,
      "y": 16,
      "z": -4,
      "name": "Wood_Hardwood_Planks"
    },
    {
      "x": -10,
      "y": 23,
      "z": -4,
      "name": "Cloth_Block_Wool_Orange_Light"
    },
    {
      "x": -10,
      "y": 24,
      "z": -4,
      "name": "Cloth_Block_Wool_Orange_Light"
    },
    {
      "x": -10,
      "y": 25,
      "z": -4,
      "name": "Cloth_Block_Wool_Orange_Light"
    },
    {
      "x": -10,
      "y": 27,
      "z": -4,
      "name": "Cloth_Block_Wool_Orange_Light"
    },
    {
      "x": -10,
      "y": 28,
      "z": -4,
      "name": "Cloth_Block_Wool_Orange_Light"
    },
    {
      "x": -10,
      "y": 29,
      "z": -4,
      "name": "Cloth_Block_Wool_Orange_Light"
    },
    {
      "x": -10,
      "y": 9,
      "z": -3,
      "name": "Wood_Hardwood_Planks"
    },
    {
      "x": -10,
      "y": 10,
      "z": -3,
      "name": "Wood_Hardwood_Planks"
    },
    {
      "x": -10,
      "y": 11,
      "z": -3,
      "name": "Wood_Hardwood_Planks"
    },
    {
      "x": -10,
      "y": 12,
      "z": -3,
      "name": "Wood_Hardwood_Planks"
    },
    {
      "x": -10,
      "y": 13,
      "z": -3,
      "name": "Wood_Hardwood_Planks"
    },
    {
      "x": -10,
      "y": 14,
      "z": -3,
      "name": "Wood_Hardwood_Planks"
    },
    {
      "x": -10,
      "y": 15,
      "z": -3,
      "name": "Wood_Hardwood_Planks"
    },
    {
      "x": -10,
      "y": 16,
      "z": -3,
      "name": "Furniture_Village_Crate"
    },
    {
      "x": -10,
      "y": 22,
      "z": -3,
      "name": "Cloth_Block_Wool_Orange_Light"
    },
    {
      "x": -10,
      "y": 23,
      "z": -3,
      "name": "Cloth_Block_Wool_Orange_Light"
    },
    {
      "x": -10,
      "y": 29,
      "z": -3,
      "name": "Cloth_Block_Wool_Orange_Light"
    },
    {
      "x": -10,
      "y": 30,
      "z": -3,
      "name": "Cloth_Block_Wool_Orange_Light"
    },
    {
      "x": -10,
      "y": 8,
      "z": -2,
      "name": "Wood_Hardwood_Planks"
    },
    {
      "x": -10,
      "y": 9,
      "z": -2,
      "name": "Wood_Hardwood_Planks"
    },
    {
      "x": -10,
      "y": 10,
      "z": -2,
      "name": "Wood_Hardwood_Planks"
    },
    {
      "x": -10,
      "y": 11,
      "z": -2,
      "name": "Wood_Hardwood_Planks"
    },
    {
      "x": -10,
      "y": 12,
      "z": -2,
      "name": "Furniture_Village_Crate"
    },
    {
      "x": -10,
      "y": 13,
      "z": -2,
      "name": "Furniture_Village_Crate"
    },
    {
      "x": -10,
      "y": 15,
      "z": -2,
      "name": "Wood_Hardwood_Planks"
    },
    {
      "x": -10,
      "y": 16,
      "z": -2,
      "name": "Deco_Lantern"
    },
    {
      "x": -10,
      "y": 21,
      "z": -2,
      "name": "Cloth_Block_Wool_Orange_Light"
    },
    {
      "x": -10,
      "y": 22,
      "z": -2,
      "name": "Cloth_Block_Wool_Orange_Light"
    },
    {
      "x": -10,
      "y": 30,
      "z": -2,
      "name": "Cloth_Block_Wool_Orange_Light"
    },
    {
      "x": -10,
      "y": 31,
      "z": -2,
      "name": "Cloth_Block_Wool_Orange_Light"
    },
    {
      "x": -10,
      "y": 8,
      "z": -1,
      "name": "Wood_Hardwood_Planks"
    },
    {
      "x": -10,
      "y": 9,
      "z": -1,
      "name": "Wood_Hardwood_Planks"
    },
    {
      "x": -10,
      "y": 10,
      "z": -1,
      "name": "Wood_Hardwood_Planks"
    },
    {
      "x": -10,
      "y": 11,
      "z": -1,
      "name": "Wood_Hardwood_Planks"
    },
    {
      "x": -10,
      "y": 12,
      "z": -1,
      "name": "Deco_Lantern"
    },
    {
      "x": -10,
      "y": 15,
      "z": -1,
      "name": "Wood_Hardwood_Planks"
    },
    {
      "x": -10,
      "y": 20,
      "z": -1,
      "name": "Cloth_Block_Wool_Orange_Light"
    },
    {
      "x": -10,
      "y": 21,
      "z": -1,
      "name": "Cloth_Block_Wool_Orange_Light"
    },
    {
      "x": -10,
      "y": 31,
      "z": -1,
      "name": "Cloth_Block_Wool_Orange_Light"
    },
    {
      "x": -10,
      "y": 32,
      "z": -1,
      "name": "Cloth_Block_Wool_Orange_Light"
    },
    {
      "x": -10,
      "y": 4,
      "z": 0,
      "name": "Wood_Hardwood_Stairs",
      "rotation": 8
    },
    {
      "x": -10,
      "y": 8,
      "z": 0,
      "name": "Wood_Hardwood_Planks"
    },
    {
      "x": -10,
      "y": 9,
      "z": 0,
      "name": "Wood_Hardwood_Planks"
    },
    {
      "x": -10,
      "y": 10,
      "z": 0,
      "name": "Wood_Hardwood_Planks"
    },
    {
      "x": -10,
      "y": 11,
      "z": 0,
      "name": "Wood_Hardwood_Planks"
    },
    {
      "x": -10,
      "y": 15,
      "z": 0,
      "name": "Wood_Hardwood_Planks"
    },
    {
      "x": -10,
      "y": 20,
      "z": 0,
      "name": "Cloth_Block_Wool_Orange_Light"
    },
    {
      "x": -10,
      "y": 21,
      "z": 0,
      "name": "Cloth_Block_Wool_Orange_Light"
    },
    {
      "x": -10,
      "y": 31,
      "z": 0,
      "name": "Cloth_Block_Wool_Orange_Light"
    },
    {
      "x": -10,
      "y": 32,
      "z": 0,
      "name": "Cloth_Block_Wool_Orange_Light"
    },
    {
      "x": -10,
      "y": 4,
      "z": 1,
      "name": "Wood_Hardwood_Planks"
    },
    {
      "x": -10,
      "y": 5,
      "z": 1,
      "name": "Furniture_Village_Ladder",
      "rotation": 1
    },
    {
      "x": -10,
      "y": 6,
      "z": 1,
      "name": "Furniture_Village_Ladder",
      "rotation": 1
    },
    {
      "x": -10,
      "y": 7,
      "z": 1,
      "name": "Furniture_Village_Ladder",
      "rotation": 1
    },
    {
      "x": -10,
      "y": 8,
      "z": 1,
      "name": "Furniture_Village_Ladder",
      "rotation": 1
    },
    {
      "x": -10,
      "y": 9,
      "z": 1,
      "name": "Furniture_Village_Ladder",
      "rotation": 1
    },
    {
      "x": -10,
      "y": 10,
      "z": 1,
      "name": "Furniture_Village_Ladder",
      "rotation": 1
    },
    {
      "x": -10,
      "y": 11,
      "z": 1,
      "name": "Furniture_Village_Ladder",
      "rotation": 1
    },
    {
      "x": -10,
      "y": 12,
      "z": 1,
      "name": "Furniture_Village_Ladder",
      "rotation": 1
    },
    {
      "x": -10,
      "y": 15,
      "z": 1,
      "name": "Wood_Hardwood_Planks"
    },
    {
      "x": -10,
      "y": 20,
      "z": 1,
      "name": "Cloth_Block_Wool_Orange_Light"
    },
    {
      "x": -10,
      "y": 32,
      "z": 1,
      "name": "Cloth_Block_Wool_Orange_Light"
    },
    {
      "x": -10,
      "y": 4,
      "z": 2,
      "name": "Wood_Hardwood_Stairs",
      "rotation": 10
    },
    {
      "x": -10,
      "y": 8,
      "z": 2,
      "name": "Wood_Hardwood_Planks"
    },
    {
      "x": -10,
      "y": 9,
      "z": 2,
      "name": "Wood_Hardwood_Planks"
    },
    {
      "x": -10,
      "y": 10,
      "z": 2,
      "name": "Wood_Hardwood_Planks"
    },
    {
      "x": -10,
      "y": 11,
      "z": 2,
      "name": "Wood_Hardwood_Planks"
    },
    {
      "x": -10,
      "y": 15,
      "z": 2,
      "name": "Wood_Hardwood_Planks"
    },
    {
      "x": -10,
      "y": 20,
      "z": 2,
      "name": "Cloth_Block_Wool_Orange_Light"
    },
    {
      "x": -10,
      "y": 21,
      "z": 2,
      "name": "Cloth_Block_Wool_Orange_Light"
    },
    {
      "x": -10,
      "y": 31,
      "z": 2,
      "name": "Cloth_Block_Wool_Orange_Light"
    },
    {
      "x": -10,
      "y": 32,
      "z": 2,
      "name": "Cloth_Block_Wool_Orange_Light"
    },
    {
      "x": -10,
      "y": 8,
      "z": 3,
      "name": "Wood_Hardwood_Planks"
    },
    {
      "x": -10,
      "y": 9,
      "z": 3,
      "name": "Wood_Hardwood_Planks"
    },
    {
      "x": -10,
      "y": 10,
      "z": 3,
      "name": "Wood_Hardwood_Planks"
    },
    {
      "x": -10,
      "y": 11,
      "z": 3,
      "name": "Wood_Hardwood_Planks"
    },
    {
      "x": -10,
      "y": 15,
      "z": 3,
      "name": "Wood_Hardwood_Planks"
    },
    {
      "x": -10,
      "y": 20,
      "z": 3,
      "name": "Cloth_Block_Wool_Orange_Light"
    },
    {
      "x": -10,
      "y": 21,
      "z": 3,
      "name": "Cloth_Block_Wool_Orange_Light"
    },
    {
      "x": -10,
      "y": 31,
      "z": 3,
      "name": "Cloth_Block_Wool_Orange_Light"
    },
    {
      "x": -10,
      "y": 32,
      "z": 3,
      "name": "Cloth_Block_Wool_Orange_Light"
    },
    {
      "x": -10,
      "y": 8,
      "z": 4,
      "name": "Wood_Hardwood_Planks"
    },
    {
      "x": -10,
      "y": 9,
      "z": 4,
      "name": "Wood_Hardwood_Planks"
    },
    {
      "x": -10,
      "y": 10,
      "z": 4,
      "name": "Wood_Hardwood_Planks"
    },
    {
      "x": -10,
      "y": 11,
      "z": 4,
      "name": "Wood_Hardwood_Planks"
    },
    {
      "x": -10,
      "y": 12,
      "z": 4,
      "name": "Furniture_Village_Crate"
    },
    {
      "x": -10,
      "y": 15,
      "z": 4,
      "name": "Wood_Hardwood_Planks"
    },
    {
      "x": -10,
      "y": 21,
      "z": 4,
      "name": "Cloth_Block_Wool_Orange_Light"
    },
    {
      "x": -10,
      "y": 22,
      "z": 4,
      "name": "Cloth_Block_Wool_Orange_Light"
    },
    {
      "x": -10,
      "y": 30,
      "z": 4,
      "name": "Cloth_Block_Wool_Orange_Light"
    },
    {
      "x": -10,
      "y": 31,
      "z": 4,
      "name": "Cloth_Block_Wool_Orange_Light"
    },
    {
      "x": -10,
      "y": 9,
      "z": 5,
      "name": "Wood_Hardwood_Planks"
    },
    {
      "x": -10,
      "y": 10,
      "z": 5,
      "name": "Wood_Hardwood_Planks"
    },
    {
      "x": -10,
      "y": 11,
      "z": 5,
      "name": "Wood_Hardwood_Planks"
    },
    {
      "x": -10,
      "y": 12,
      "z": 5,
      "name": "Wood_Hardwood_Planks"
    },
    {
      "x": -10,
      "y": 13,
      "z": 5,
      "name": "Wood_Hardwood_Planks"
    },
    {
      "x": -10,
      "y": 14,
      "z": 5,
      "name": "Wood_Hardwood_Planks"
    },
    {
      "x": -10,
      "y": 15,
      "z": 5,
      "name": "Wood_Hardwood_Planks"
    },
    {
      "x": -10,
      "y": 22,
      "z": 5,
      "name": "Cloth_Block_Wool_Orange_Light"
    },
    {
      "x": -10,
      "y": 23,
      "z": 5,
      "name": "Cloth_Block_Wool_Orange_Light"
    },
    {
      "x": -10,
      "y": 29,
      "z": 5,
      "name": "Cloth_Block_Wool_Orange_Light"
    },
    {
      "x": -10,
      "y": 30,
      "z": 5,
      "name": "Cloth_Block_Wool_Orange_Light"
    },
    {
      "x": -10,
      "y": 10,
      "z": 6,
      "name": "Wood_Hardwood_Planks"
    },
    {
      "x": -10,
      "y": 11,
      "z": 6,
      "name": "Wood_Hardwood_Planks"
    },
    {
      "x": -10,
      "y": 12,
      "z": 6,
      "name": "Wood_Hardwood_Planks"
    },
    {
      "x": -10,
      "y": 13,
      "z": 6,
      "name": "Wood_Hardwood_Planks"
    },
    {
      "x": -10,
      "y": 14,
      "z": 6,
      "name": "Wood_Hardwood_Planks"
    },
    {
      "x": -10,
      "y": 15,
      "z": 6,
      "name": "Wood_Hardwood_Planks"
    },
    {
      "x": -10,
      "y": 16,
      "z": 6,
      "name": "Wood_Hardwood_Planks"
    },
    {
      "x": -10,
      "y": 23,
      "z": 6,
      "name": "Cloth_Block_Wool_Orange_Light"
    },
    {
      "x": -10,
      "y": 24,
      "z": 6,
      "name": "Cloth_Block_Wool_Orange_Light"
    },
    {
      "x": -10,
      "y": 25,
      "z": 6,
      "name": "Cloth_Block_Wool_Orange_Light"
    },
    {
      "x": -10,
      "y": 27,
      "z": 6,
      "name": "Cloth_Block_Wool_Orange_Light"
    },
    {
      "x": -10,
      "y": 28,
      "z": 6,
      "name": "Cloth_Block_Wool_Orange_Light"
    },
    {
      "x": -10,
      "y": 29,
      "z": 6,
      "name": "Cloth_Block_Wool_Orange_Light"
    },
    {
      "x": -10,
      "y": 24,
      "z": 7,
      "name": "Cloth_Block_Wool_Orange_Light"
    },
    {
      "x": -10,
      "y": 25,
      "z": 7,
      "name": "Cloth_Block_Wool_Orange_Light"
    },
    {
      "x": -10,
      "y": 26,
      "z": 7,
      "name": "Cloth_Block_Wool_Orange_Light"
    },
    {
      "x": -10,
      "y": 27,
      "z": 7,
      "name": "Cloth_Block_Wool_Orange_Light"
    },
    {
      "x": -10,
      "y": 28,
      "z": 7,
      "name": "Cloth_Block_Wool_Orange_Light"
    },
    {
      "x": -9,
      "y": 24,
      "z": -5,
      "name": "Cloth_Block_Wool_Orange_Light"
    },
    {
      "x": -9,
      "y": 25,
      "z": -5,
      "name": "Cloth_Block_Wool_Orange_Light"
    },
    {
      "x": -9,
      "y": 26,
      "z": -5,
      "name": "Cloth_Block_Wool_Orange_Light"
    },
    {
      "x": -9,
      "y": 27,
      "z": -5,
      "name": "Cloth_Block_Wool_Orange_Light"
    },
    {
      "x": -9,
      "y": 28,
      "z": -5,
      "name": "Cloth_Block_Wool_Orange_Light"
    },
    {
      "x": -9,
      "y": 10,
      "z": -4,
      "name": "Wood_Hardwood_Planks"
    },
    {
      "x": -9,
      "y": 11,
      "z": -4,
      "name": "Wood_Hardwood_Planks"
    },
    {
      "x": -9,
      "y": 12,
      "z": -4,
      "name": "Wood_Hardwood_Planks"
    },
    {
      "x": -9,
      "y": 13,
      "z": -4,
      "name": "Wood_Hardwood_Planks"
    },
    {
      "x": -9,
      "y": 14,
      "z": -4,
      "name": "Wood_Hardwood_Planks"
    },
    {
      "x": -9,
      "y": 15,
      "z": -4,
      "name": "Wood_Hardwood_Planks"
    },
    {
      "x": -9,
      "y": 16,
      "z": -4,
      "name": "Wood_Hardwood_Planks"
    },
    {
      "x": -9,
      "y": 22,
      "z": -4,
      "name": "Cloth_Block_Wool_Orange_Light"
    },
    {
      "x": -9,
      "y": 23,
      "z": -4,
      "name": "Cloth_Block_Wool_Orange_Light"
    },
    {
      "x": -9,
      "y": 24,
      "z": -4,
      "name": "Cloth_Block_Wool_Orange_Light"
    },
    {
      "x": -9,
      "y": 28,
      "z": -4,
      "name": "Cloth_Block_Wool_Orange_Light"
    },
    {
      "x": -9,
      "y": 29,
      "z": -4,
      "name": "Cloth_Block_Wool_Orange_Light"
    },
    {
      "x": -9,
      "y": 30,
      "z": -4,
      "name": "Cloth_Block_Wool_Orange_Light"
    },
    {
      "x": -9,
      "y": 8,
      "z": -3,
      "name": "Wood_Hardwood_Planks"
    },
    {
      "x": -9,
      "y": 9,
      "z": -3,
      "name": "Wood_Hardwood_Planks"
    },
    {
      "x": -9,
      "y": 10,
      "z": -3,
      "name": "Wood_Hardwood_Planks"
    },
    {
      "x": -9,
      "y": 11,
      "z": -3,
      "name": "Wood_Hardwood_Planks"
    },
    {
      "x": -9,
      "y": 12,
      "z": -3,
      "name": "Furniture_Village_Crate"
    },
    {
      "x": -9,
      "y": 15,
      "z": -3,
      "name": "Wood_Hardwood_Planks"
    },
    {
      "x": -9,
      "y": 21,
      "z": -3,
      "name": "Cloth_Block_Wool_Orange_Light"
    },
    {
      "x": -9,
      "y": 22,
      "z": -3,
      "name": "Cloth_Block_Wool_Orange_Light"
    },
    {
      "x": -9,
      "y": 23,
      "z": -3,
      "name": "Cloth_Block_Wool_Orange_Light"
    },
    {
      "x": -9,
      "y": 29,
      "z": -3,
      "name": "Cloth_Block_Wool_Orange_Light"
    },
    {
      "x": -9,
      "y": 30,
      "z": -3,
      "name": "Cloth_Block_Wool_Orange_Light"
    },
    {
      "x": -9,
      "y": 31,
      "z": -3,
      "name": "Cloth_Block_Wool_Orange_Light"
    },
    {
      "x": -9,
      "y": 7,
      "z": -2,
      "name": "Wood_Hardwood_Planks"
    },
    {
      "x": -9,
      "y": 8,
      "z": -2,
      "name": "Furniture_Village_Crate"
    },
    {
      "x": -9,
      "y": 11,
      "z": -2,
      "name": "Wood_Hardwood_Planks"
    },
    {
      "x": -9,
      "y": 15,
      "z": -2,
      "name": "Wood_Hardwood_Planks"
    },
    {
      "x": -9,
      "y": 21,
      "z": -2,
      "name": "Cloth_Block_Wool_Orange_Light"
    },
    {
      "x": -9,
      "y": 22,
      "z": -2,
      "name": "Cloth_Block_Wool_Orange_Light"
    },
    {
      "x": -9,
      "y": 30,
      "z": -2,
      "name": "Cloth_Block_Wool_Orange_Light"
    },
    {
      "x": -9,
      "y": 31,
      "z": -2,
      "name": "Cloth_Block_Wool_Orange_Light"
    },
    {
      "x": -9,
      "y": 7,
      "z": -1,
      "name": "Wood_Hardwood_Planks"
    },
    {
      "x": -9,
      "y": 8,
      "z": -1,
      "name": "Furniture_Tavern_Barrel"
    },
    {
      "x": -9,
      "y": 11,
      "z": -1,
      "name": "Wood_Hardwood_Planks"
    },
    {
      "x": -9,
      "y": 15,
      "z": -1,
      "name": "Wood_Hardwood_Planks"
    },
    {
      "x": -9,
      "y": 20,
      "z": -1,
      "name": "Cloth_Block_Wool_Orange_Light"
    },
    {
      "x": -9,
      "y": 21,
      "z": -1,
      "name": "Cloth_Block_Wool_Orange_Light"
    },
    {
      "x": -9,
      "y": 31,
      "z": -1,
      "name": "Cloth_Block_Wool_Orange_Light"
    },
    {
      "x": -9,
      "y": 32,
      "z": -1,
      "name": "Cloth_Block_Wool_Orange_Light"
    },
    {
      "x": -9,
      "y": 4,
      "z": 0,
      "name": "*Wood_Hardwood_Stairs_State_Definitions_Corner_Right",
      "rotation": 11
    },
    {
      "x": -9,
      "y": 6,
      "z": 0,
      "name": "Wood_Hardwood_Planks"
    },
    {
      "x": -9,
      "y": 7,
      "z": 0,
      "name": "Wood_Hardwood_Planks"
    },
    {
      "x": -9,
      "y": 11,
      "z": 0,
      "name": "Wood_Hardwood_Planks"
    },
    {
      "x": -9,
      "y": 15,
      "z": 0,
      "name": "Wood_Hardwood_Planks"
    },
    {
      "x": -9,
      "y": 20,
      "z": 0,
      "name": "Cloth_Block_Wool_Orange_Light"
    },
    {
      "x": -9,
      "y": 32,
      "z": 0,
      "name": "Cloth_Block_Wool_Orange_Light"
    },
    {
      "x": -9,
      "y": 4,
      "z": 1,
      "name": "Wood_Hardwood_Stairs",
      "rotation": 11
    },
    {
      "x": -9,
      "y": 5,
      "z": 1,
      "name": "Wood_Hardwood_Planks"
    },
    {
      "x": -9,
      "y": 6,
      "z": 1,
      "name": "Wood_Hardwood_Planks"
    },
    {
      "x": -9,
      "y": 7,
      "z": 1,
      "name": "Wood_Hardwood_Planks"
    },
    {
      "x": -9,
      "y": 11,
      "z": 1,
      "name": "Wood_Hardwood_Planks"
    },
    {
      "x": -9,
      "y": 15,
      "z": 1,
      "name": "Wood_Hardwood_Planks"
    },
    {
      "x": -9,
      "y": 20,
      "z": 1,
      "name": "Cloth_Block_Wool_Orange_Light"
    },
    {
      "x": -9,
      "y": 32,
      "z": 1,
      "name": "Cloth_Block_Wool_Orange_Light"
    },
    {
      "x": -9,
      "y": 4,
      "z": 2,
      "name": "*Wood_Hardwood_Stairs_State_Definitions_Corner_Left",
      "rotation": 11
    },
    {
      "x": -9,
      "y": 6,
      "z": 2,
      "name": "Wood_Hardwood_Planks"
    },
    {
      "x": -9,
      "y": 7,
      "z": 2,
      "name": "Wood_Hardwood_Planks"
    },
    {
      "x": -9,
      "y": 11,
      "z": 2,
      "name": "Wood_Hardwood_Planks"
    },
    {
      "x": -9,
      "y": 15,
      "z": 2,
      "name": "Wood_Hardwood_Planks"
    },
    {
      "x": -9,
      "y": 20,
      "z": 2,
      "name": "Cloth_Block_Wool_Orange_Light"
    },
    {
      "x": -9,
      "y": 32,
      "z": 2,
      "name": "Cloth_Block_Wool_Orange_Light"
    },
    {
      "x": -9,
      "y": 7,
      "z": 3,
      "name": "Wood_Hardwood_Planks"
    },
    {
      "x": -9,
      "y": 8,
      "z": 3,
      "name": "Furniture_Village_Crate"
    },
    {
      "x": -9,
      "y": 11,
      "z": 3,
      "name": "Wood_Hardwood_Planks"
    },
    {
      "x": -9,
      "y": 15,
      "z": 3,
      "name": "Wood_Hardwood_Planks"
    },
    {
      "x": -9,
      "y": 20,
      "z": 3,
      "name": "Cloth_Block_Wool_Orange_Light"
    },
    {
      "x": -9,
      "y": 21,
      "z": 3,
      "name": "Cloth_Block_Wool_Orange_Light"
    },
    {
      "x": -9,
      "y": 31,
      "z": 3,
      "name": "Cloth_Block_Wool_Orange_Light"
    },
    {
      "x": -9,
      "y": 32,
      "z": 3,
      "name": "Cloth_Block_Wool_Orange_Light"
    },
    {
      "x": -9,
      "y": 7,
      "z": 4,
      "name": "Wood_Hardwood_Planks"
    },
    {
      "x": -9,
      "y": 8,
      "z": 4,
      "name": "Furniture_Village_Crate"
    },
    {
      "x": -9,
      "y": 9,
      "z": 4,
      "name": "Furniture_Village_Crate"
    },
    {
      "x": -9,
      "y": 11,
      "z": 4,
      "name": "Wood_Hardwood_Planks"
    },
    {
      "x": -9,
      "y": 15,
      "z": 4,
      "name": "Wood_Hardwood_Planks"
    },
    {
      "x": -9,
      "y": 21,
      "z": 4,
      "name": "Cloth_Block_Wool_Orange_Light"
    },
    {
      "x": -9,
      "y": 22,
      "z": 4,
      "name": "Cloth_Block_Wool_Orange_Light"
    },
    {
      "x": -9,
      "y": 30,
      "z": 4,
      "name": "Cloth_Block_Wool_Orange_Light"
    },
    {
      "x": -9,
      "y": 31,
      "z": 4,
      "name": "Cloth_Block_Wool_Orange_Light"
    },
    {
      "x": -9,
      "y": 8,
      "z": 5,
      "name": "Wood_Hardwood_Planks"
    },
    {
      "x": -9,
      "y": 9,
      "z": 5,
      "name": "Wood_Hardwood_Planks"
    },
    {
      "x": -9,
      "y": 10,
      "z": 5,
      "name": "Wood_Hardwood_Planks"
    },
    {
      "x": -9,
      "y": 11,
      "z": 5,
      "name": "Wood_Hardwood_Planks"
    },
    {
      "x": -9,
      "y": 15,
      "z": 5,
      "name": "Wood_Hardwood_Planks"
    },
    {
      "x": -9,
      "y": 21,
      "z": 5,
      "name": "Cloth_Block_Wool_Orange_Light"
    },
    {
      "x": -9,
      "y": 22,
      "z": 5,
      "name": "Cloth_Block_Wool_Orange_Light"
    },
    {
      "x": -9,
      "y": 23,
      "z": 5,
      "name": "Cloth_Block_Wool_Orange_Light"
    },
    {
      "x": -9,
      "y": 29,
      "z": 5,
      "name": "Cloth_Block_Wool_Orange_Light"
    },
    {
      "x": -9,
      "y": 30,
      "z": 5,
      "name": "Cloth_Block_Wool_Orange_Light"
    },
    {
      "x": -9,
      "y": 31,
      "z": 5,
      "name": "Cloth_Block_Wool_Orange_Light"
    },
    {
      "x": -9,
      "y": 10,
      "z": 6,
      "name": "Wood_Hardwood_Planks"
    },
    {
      "x": -9,
      "y": 11,
      "z": 6,
      "name": "Wood_Hardwood_Planks"
    },
    {
      "x": -9,
      "y": 12,
      "z": 6,
      "name": "Wood_Hardwood_Planks"
    },
    {
      "x": -9,
      "y": 13,
      "z": 6,
      "name": "Wood_Hardwood_Planks"
    },
    {
      "x": -9,
      "y": 14,
      "z": 6,
      "name": "Wood_Hardwood_Planks"
    },
    {
      "x": -9,
      "y": 15,
      "z": 6,
      "name": "Wood_Hardwood_Planks"
    },
    {
      "x": -9,
      "y": 16,
      "z": 6,
      "name": "Wood_Hardwood_Planks"
    },
    {
      "x": -9,
      "y": 22,
      "z": 6,
      "name": "Cloth_Block_Wool_Orange_Light"
    },
    {
      "x": -9,
      "y": 23,
      "z": 6,
      "name": "Cloth_Block_Wool_Orange_Light"
    },
    {
      "x": -9,
      "y": 24,
      "z": 6,
      "name": "Cloth_Block_Wool_Orange_Light"
    },
    {
      "x": -9,
      "y": 28,
      "z": 6,
      "name": "Cloth_Block_Wool_Orange_Light"
    },
    {
      "x": -9,
      "y": 29,
      "z": 6,
      "name": "Cloth_Block_Wool_Orange_Light"
    },
    {
      "x": -9,
      "y": 30,
      "z": 6,
      "name": "Cloth_Block_Wool_Orange_Light"
    },
    {
      "x": -9,
      "y": 24,
      "z": 7,
      "name": "Cloth_Block_Wool_Orange_Light"
    },
    {
      "x": -9,
      "y": 25,
      "z": 7,
      "name": "Cloth_Block_Wool_Orange_Light"
    },
    {
      "x": -9,
      "y": 26,
      "z": 7,
      "name": "Cloth_Block_Wool_Orange_Light"
    },
    {
      "x": -9,
      "y": 27,
      "z": 7,
      "name": "Cloth_Block_Wool_Orange_Light"
    },
    {
      "x": -9,
      "y": 28,
      "z": 7,
      "name": "Cloth_Block_Wool_Orange_Light"
    },
    {
      "x": -8,
      "y": 24,
      "z": -6,
      "name": "Wood_Hardwood_Planks_Half",
      "rotation": 6
    },
    {
      "x": -8,
      "y": 25,
      "z": -6,
      "name": "Wood_Hardwood_Planks_Half",
      "rotation": 6
    },
    {
      "x": -8,
      "y": 26,
      "z": -6,
      "name": "Wood_Hardwood_Planks_Half",
      "rotation": 6
    },
    {
      "x": -8,
      "y": 27,
      "z": -6,
      "name": "Wood_Hardwood_Planks_Half",
      "rotation": 6
    },
    {
      "x": -8,
      "y": 28,
      "z": -6,
      "name": "Wood_Hardwood_Planks_Half",
      "rotation": 6
    },
    {
      "x": -8,
      "y": 22,
      "z": -5,
      "name": "Wood_Hardwood_Planks_Half",
      "rotation": 6
    },
    {
      "x": -8,
      "y": 23,
      "z": -5,
      "name": "Wood_Hardwood_Stairs",
      "rotation": 8
    },
    {
      "x": -8,
      "y": 24,
      "z": -5,
      "name": "Wood_Hardwood_Planks"
    },
    {
      "x": -8,
      "y": 25,
      "z": -5,
      "name": "Wood_Hardwood_Planks"
    },
    {
      "x": -8,
      "y": 26,
      "z": -5,
      "name": "Wood_Hardwood_Planks"
    },
    {
      "x": -8,
      "y": 27,
      "z": -5,
      "name": "Wood_Hardwood_Planks"
    },
    {
      "x": -8,
      "y": 28,
      "z": -5,
      "name": "Wood_Hardwood_Planks"
    },
    {
      "x": -8,
      "y": 29,
      "z": -5,
      "name": "Wood_Hardwood_Stairs",
      "rotation": 2
    },
    {
      "x": -8,
      "y": 30,
      "z": -5,
      "name": "Wood_Hardwood_Planks_Half",
      "rotation": 6
    },
    {
      "x": -8,
      "y": 10,
      "z": -4,
      "name": "Wood_Hardwood_Planks"
    },
    {
      "x": -8,
      "y": 11,
      "z": -4,
      "name": "Wood_Hardwood_Planks"
    },
    {
      "x": -8,
      "y": 12,
      "z": -4,
      "name": "Wood_Hardwood_Planks"
    },
    {
      "x": -8,
      "y": 13,
      "z": -4,
      "name": "Wood_Hardwood_Planks"
    },
    {
      "x": -8,
      "y": 14,
      "z": -4,
      "name": "Furniture_Village_Window"
    },
    {
      "x": -8,
      "y": 15,
      "z": -4,
      "name": "Wood_Hardwood_Planks"
    },
    {
      "x": -8,
      "y": 16,
      "z": -4,
      "name": "Wood_Hardwood_Ornate"
    },
    {
      "x": -8,
      "y": 17,
      "z": -4,
      "name": "Deco_Iron_Chain_Small"
    },
    {
      "x": -8,
      "y": 18,
      "z": -4,
      "name": "Deco_Iron_Chain_Small"
    },
    {
      "x": -8,
      "y": 19,
      "z": -4,
      "name": "Deco_Iron_Chain_Small"
    },
    {
      "x": -8,
      "y": 20,
      "z": -4,
      "name": "Wood_Hardwood_Ornate"
    },
    {
      "x": -8,
      "y": 21,
      "z": -4,
      "name": "Wood_Hardwood_Planks"
    },
    {
      "x": -8,
      "y": 22,
      "z": -4,
      "name": "Wood_Hardwood_Planks"
    },
    {
      "x": -8,
      "y": 23,
      "z": -4,
      "name": "Wood_Hardwood_Planks"
    },
    {
      "x": -8,
      "y": 29,
      "z": -4,
      "name": "Wood_Hardwood_Planks"
    },
    {
      "x": -8,
      "y": 30,
      "z": -4,
      "name": "Wood_Hardwood_Planks"
    },
    {
      "x": -8,
      "y": 31,
      "z": -4,
      "name": "Wood_Hardwood_Stairs",
      "rotation": 2
    },
    {
      "x": -8,
      "y": 8,
      "z": -3,
      "name": "Wood_Hardwood_Planks"
    },
    {
      "x": -8,
      "y": 9,
      "z": -3,
      "name": "Wood_Hardwood_Planks"
    },
    {
      "x": -8,
      "y": 10,
      "z": -3,
      "name": "Wood_Hardwood_Planks"
    },
    {
      "x": -8,
      "y": 11,
      "z": -3,
      "name": "Wood_Hardwood_Planks"
    },
    {
      "x": -8,
      "y": 12,
      "z": -3,
      "name": "Block_Spawner_Block",
      "components": {
        "Components": {
          "PlacedByInteraction": {
            "WhoPlacedUuid": {
              "$binary": "3XRzOktQTQGfL/+8x7+CHA==",
              "$type": "04"
            }
          },
          "BlockSpawner": {
            "BlockSpawnerId": "Zone2_Undead_Tier2"
          }
        }
      }
    },
    {
      "x": -8,
      "y": 15,
      "z": -3,
      "name": "Wood_Hardwood_Planks"
    },
    {
      "x": -8,
      "y": 20,
      "z": -3,
      "name": "Wood_Hardwood_Planks_Half",
      "rotation": 8
    },
    {
      "x": -8,
      "y": 21,
      "z": -3,
      "name": "Wood_Hardwood_Planks"
    },
    {
      "x": -8,
      "y": 31,
      "z": -3,
      "name": "Wood_Hardwood_Planks"
    },
    {
      "x": -8,
      "y": 32,
      "z": -3,
      "name": "Wood_Hardwood_Planks_Half"
    },
    {
      "x": -8,
      "y": 7,
      "z": -2,
      "name": "Wood_Hardwood_Planks"
    },
    {
      "x": -8,
      "y": 11,
      "z": -2,
      "name": "Wood_Hardwood_Planks"
    },
    {
      "x": -8,
      "y": 15,
      "z": -2,
      "name": "Wood_Hardwood_Planks"
    },
    {
      "x": -8,
      "y": 20,
      "z": -2,
      "name": "Wood_Hardwood_Stairs",
      "rotation": 8
    },
    {
      "x": -8,
      "y": 21,
      "z": -2,
      "name": "Wood_Hardwood_Planks"
    },
    {
      "x": -8,
      "y": 31,
      "z": -2,
      "name": "Wood_Hardwood_Planks"
    },
    {
      "x": -8,
      "y": 32,
      "z": -2,
      "name": "Wood_Hardwood_Stairs",
      "rotation": 2
    },
    {
      "x": -8,
      "y": 7,
      "z": -1,
      "name": "Wood_Hardwood_Planks"
    },
    {
      "x": -8,
      "y": 11,
      "z": -1,
      "name": "Wood_Hardwood_Planks"
    },
    {
      "x": -8,
      "y": 15,
      "z": -1,
      "name": "Wood_Hardwood_Planks"
    },
    {
      "x": -8,
      "y": 19,
      "z": -1,
      "name": "Wood_Hardwood_Planks_Half",
      "rotation": 8
    },
    {
      "x": -8,
      "y": 20,
      "z": -1,
      "name": "Wood_Hardwood_Planks"
    },
    {
      "x": -8,
      "y": 32,
      "z": -1,
      "name": "Wood_Hardwood_Planks"
    },
    {
      "x": -8,
      "y": 33,
      "z": -1,
      "name": "Wood_Hardwood_Planks_Half"
    },
    {
      "x": -8,
      "y": 6,
      "z": 0,
      "name": "Wood_Hardwood_Planks"
    },
    {
      "x": -8,
      "y": 7,
      "z": 0,
      "name": "Wood_Hardwood_Planks"
    },
    {
      "x": -8,
      "y": 11,
      "z": 0,
      "name": "Wood_Hardwood_Planks"
    },
    {
      "x": -8,
      "y": 15,
      "z": 0,
      "name": "Wood_Hardwood_Planks"
    },
    {
      "x": -8,
      "y": 19,
      "z": 0,
      "name": "Wood_Hardwood_Planks_Half",
      "rotation": 8
    },
    {
      "x": -8,
      "y": 20,
      "z": 0,
      "name": "Wood_Hardwood_Planks"
    },
    {
      "x": -8,
      "y": 32,
      "z": 0,
      "name": "Wood_Hardwood_Planks"
    },
    {
      "x": -8,
      "y": 33,
      "z": 0,
      "name": "Wood_Hardwood_Planks_Half"
    },
    {
      "x": -8,
      "y": 5,
      "z": 1,
      "name": "Wood_Hardwood_Planks"
    },
    {
      "x": -8,
      "y": 6,
      "z": 1,
      "name": "Wood_Hardwood_Planks"
    },
    {
      "x": -8,
      "y": 7,
      "z": 1,
      "name": "Wood_Hardwood_Planks"
    },
    {
      "x": -8,
      "y": 11,
      "z": 1,
      "name": "Wood_Hardwood_Planks"
    },
    {
      "x": -8,
      "y": 15,
      "z": 1,
      "name": "Wood_Hardwood_Planks"
    },
    {
      "x": -8,
      "y": 19,
      "z": 1,
      "name": "Wood_Hardwood_Planks_Half",
      "rotation": 8
    },
    {
      "x": -8,
      "y": 20,
      "z": 1,
      "name": "Wood_Hardwood_Planks"
    },
    {
      "x": -8,
      "y": 32,
      "z": 1,
      "name": "Wood_Hardwood_Planks"
    },
    {
      "x": -8,
      "y": 33,
      "z": 1,
      "name": "Wood_Hardwood_Planks_Half"
    },
    {
      "x": -8,
      "y": 6,
      "z": 2,
      "name": "Wood_Hardwood_Planks"
    },
    {
      "x": -8,
      "y": 7,
      "z": 2,
      "name": "Wood_Hardwood_Planks"
    },
    {
      "x": -8,
      "y": 11,
      "z": 2,
      "name": "Wood_Hardwood_Planks"
    },
    {
      "x": -8,
      "y": 15,
      "z": 2,
      "name": "Wood_Hardwood_Planks"
    },
    {
      "x": -8,
      "y": 19,
      "z": 2,
      "name": "Wood_Hardwood_Planks_Half",
      "rotation": 8
    },
    {
      "x": -8,
      "y": 20,
      "z": 2,
      "name": "Wood_Hardwood_Planks"
    },
    {
      "x": -8,
      "y": 32,
      "z": 2,
      "name": "Wood_Hardwood_Planks"
    },
    {
      "x": -8,
      "y": 33,
      "z": 2,
      "name": "Wood_Hardwood_Planks_Half"
    },
    {
      "x": -8,
      "y": 7,
      "z": 3,
      "name": "Wood_Hardwood_Planks"
    },
    {
      "x": -8,
      "y": 11,
      "z": 3,
      "name": "Wood_Hardwood_Planks"
    },
    {
      "x": -8,
      "y": 15,
      "z": 3,
      "name": "Wood_Hardwood_Planks"
    },
    {
      "x": -8,
      "y": 19,
      "z": 3,
      "name": "Wood_Hardwood_Planks_Half",
      "rotation": 8
    },
    {
      "x": -8,
      "y": 20,
      "z": 3,
      "name": "Wood_Hardwood_Planks"
    },
    {
      "x": -8,
      "y": 32,
      "z": 3,
      "name": "Wood_Hardwood_Planks"
    },
    {
      "x": -8,
      "y": 33,
      "z": 3,
      "name": "Wood_Hardwood_Planks_Half"
    },
    {
      "x": -8,
      "y": 7,
      "z": 4,
      "name": "Wood_Hardwood_Planks"
    },
    {
      "x": -8,
      "y": 8,
      "z": 4,
      "name": "Furniture_Village_Crate"
    },
    {
      "x": -8,
      "y": 11,
      "z": 4,
      "name": "Wood_Hardwood_Planks"
    },
    {
      "x": -8,
      "y": 15,
      "z": 4,
      "name": "Wood_Hardwood_Planks"
    },
    {
      "x": -8,
      "y": 20,
      "z": 4,
      "name": "Wood_Hardwood_Stairs",
      "rotation": 10
    },
    {
      "x": -8,
      "y": 21,
      "z": 4,
      "name": "Wood_Hardwood_Planks"
    },
    {
      "x": -8,
      "y": 31,
      "z": 4,
      "name": "Wood_Hardwood_Planks"
    },
    {
      "x": -8,
      "y": 32,
      "z": 4,
      "name": "Wood_Hardwood_Stairs"
    },
    {
      "x": -8,
      "y": 8,
      "z": 5,
      "name": "Wood_Hardwood_Planks"
    },
    {
      "x": -8,
      "y": 9,
      "z": 5,
      "name": "Wood_Hardwood_Planks"
    },
    {
      "x": -8,
      "y": 10,
      "z": 5,
      "name": "Wood_Hardwood_Planks"
    },
    {
      "x": -8,
      "y": 11,
      "z": 5,
      "name": "Wood_Hardwood_Planks"
    },
    {
      "x": -8,
      "y": 15,
      "z": 5,
      "name": "Wood_Hardwood_Planks"
    },
    {
      "x": -8,
      "y": 20,
      "z": 5,
      "name": "Wood_Hardwood_Planks_Half",
      "rotation": 8
    },
    {
      "x": -8,
      "y": 21,
      "z": 5,
      "name": "Wood_Hardwood_Planks"
    },
    {
      "x": -8,
      "y": 31,
      "z": 5,
      "name": "Wood_Hardwood_Planks"
    },
    {
      "x": -8,
      "y": 32,
      "z": 5,
      "name": "Wood_Hardwood_Planks_Half"
    },
    {
      "x": -8,
      "y": 10,
      "z": 6,
      "name": "Wood_Hardwood_Planks"
    },
    {
      "x": -8,
      "y": 11,
      "z": 6,
      "name": "Wood_Hardwood_Planks"
    },
    {
      "x": -8,
      "y": 12,
      "z": 6,
      "name": "Wood_Hardwood_Planks"
    },
    {
      "x": -8,
      "y": 13,
      "z": 6,
      "name": "Wood_Hardwood_Planks"
    },
    {
      "x": -8,
      "y": 14,
      "z": 6,
      "name": "Furniture_Village_Window"
    },
    {
      "x": -8,
      "y": 15,
      "z": 6,
      "name": "Wood_Hardwood_Planks"
    },
    {
      "x": -8,
      "y": 16,
      "z": 6,
      "name": "Wood_Hardwood_Ornate"
    },
    {
      "x": -8,
      "y": 17,
      "z": 6,
      "name": "Deco_Iron_Chain_Small"
    },
    {
      "x": -8,
      "y": 18,
      "z": 6,
      "name": "Deco_Iron_Chain_Small"
    },
    {
      "x": -8,
      "y": 19,
      "z": 6,
      "name": "Deco_Iron_Chain_Small"
    },
    {
      "x": -8,
      "y": 20,
      "z": 6,
      "name": "Wood_Hardwood_Ornate"
    },
    {
      "x": -8,
      "y": 21,
      "z": 6,
      "name": "Wood_Hardwood_Planks"
    },
    {
      "x": -8,
      "y": 22,
      "z": 6,
      "name": "Wood_Hardwood_Planks"
    },
    {
      "x": -8,
      "y": 23,
      "z": 6,
      "name": "Wood_Hardwood_Planks"
    },
    {
      "x": -8,
      "y": 29,
      "z": 6,
      "name": "Wood_Hardwood_Planks"
    },
    {
      "x": -8,
      "y": 30,
      "z": 6,
      "name": "Wood_Hardwood_Planks"
    },
    {
      "x": -8,
      "y": 31,
      "z": 6,
      "name": "Wood_Hardwood_Stairs"
    },
    {
      "x": -8,
      "y": 22,
      "z": 7,
      "name": "Wood_Hardwood_Planks_Half",
      "rotation": 4
    },
    {
      "x": -8,
      "y": 23,
      "z": 7,
      "name": "Wood_Hardwood_Stairs",
      "rotation": 10
    },
    {
      "x": -8,
      "y": 24,
      "z": 7,
      "name": "Wood_Hardwood_Planks"
    },
    {
      "x": -8,
      "y": 25,
      "z": 7,
      "name": "Wood_Hardwood_Planks"
    },
    {
      "x": -8,
      "y": 26,
      "z": 7,
      "name": "Wood_Hardwood_Planks"
    },
    {
      "x": -8,
      "y": 27,
      "z": 7,
      "name": "Wood_Hardwood_Planks"
    },
    {
      "x": -8,
      "y": 28,
      "z": 7,
      "name": "Wood_Hardwood_Planks"
    },
    {
      "x": -8,
      "y": 29,
      "z": 7,
      "name": "Wood_Hardwood_Stairs"
    },
    {
      "x": -8,
      "y": 30,
      "z": 7,
      "name": "Wood_Hardwood_Planks_Half",
      "rotation": 4
    },
    {
      "x": -8,
      "y": 24,
      "z": 8,
      "name": "Wood_Hardwood_Planks_Half",
      "rotation": 4
    },
    {
      "x": -8,
      "y": 25,
      "z": 8,
      "name": "Wood_Hardwood_Planks_Half",
      "rotation": 4
    },
    {
      "x": -8,
      "y": 26,
      "z": 8,
      "name": "Wood_Hardwood_Planks_Half",
      "rotation": 4
    },
    {
      "x": -8,
      "y": 27,
      "z": 8,
      "name": "Wood_Hardwood_Planks_Half",
      "rotation": 4
    },
    {
      "x": -8,
      "y": 28,
      "z": 8,
      "name": "Wood_Hardwood_Planks_Half",
      "rotation": 4
    },
    {
      "x": -7,
      "y": 24,
      "z": -5,
      "name": "Cloth_Block_Wool_Orange_Light"
    },
    {
      "x": -7,
      "y": 25,
      "z": -5,
      "name": "Cloth_Block_Wool_Orange_Light"
    },
    {
      "x": -7,
      "y": 26,
      "z": -5,
      "name": "Cloth_Block_Wool_Orange_Light"
    },
    {
      "x": -7,
      "y": 27,
      "z": -5,
      "name": "Cloth_Block_Wool_Orange_Light"
    },
    {
      "x": -7,
      "y": 28,
      "z": -5,
      "name": "Cloth_Block_Wool_Orange_Light"
    },
    {
      "x": -7,
      "y": 10,
      "z": -4,
      "name": "Wood_Hardwood_Stairs",
      "rotation": 8
    },
    {
      "x": -7,
      "y": 11,
      "z": -4,
      "name": "Wood_Hardwood_Planks"
    },
    {
      "x": -7,
      "y": 12,
      "z": -4,
      "name": "Wood_Hardwood_Planks"
    },
    {
      "x": -7,
      "y": 13,
      "z": -4,
      "name": "Wood_Hardwood_Planks"
    },
    {
      "x": -7,
      "y": 14,
      "z": -4,
      "name": "Wood_Hardwood_Planks"
    },
    {
      "x": -7,
      "y": 15,
      "z": -4,
      "name": "Wood_Hardwood_Planks"
    },
    {
      "x": -7,
      "y": 16,
      "z": -4,
      "name": "Wood_Hardwood_Planks"
    },
    {
      "x": -7,
      "y": 22,
      "z": -4,
      "name": "Cloth_Block_Wool_Orange_Light"
    },
    {
      "x": -7,
      "y": 23,
      "z": -4,
      "name": "Cloth_Block_Wool_Orange_Light"
    },
    {
      "x": -7,
      "y": 29,
      "z": -4,
      "name": "Cloth_Block_Wool_Orange_Light"
    },
    {
      "x": -7,
      "y": 30,
      "z": -4,
      "name": "Cloth_Block_Wool_Orange_Light"
    },
    {
      "x": -7,
      "y": 8,
      "z": -3,
      "name": "Wood_Hardwood_Planks"
    },
    {
      "x": -7,
      "y": 9,
      "z": -3,
      "name": "Wood_Hardwood_Planks"
    },
    {
      "x": -7,
      "y": 10,
      "z": -3,
      "name": "Wood_Hardwood_Planks"
    },
    {
      "x": -7,
      "y": 11,
      "z": -3,
      "name": "Wood_Hardwood_Planks"
    },
    {
      "x": -7,
      "y": 15,
      "z": -3,
      "name": "Wood_Hardwood_Planks"
    },
    {
      "x": -7,
      "y": 21,
      "z": -3,
      "name": "Cloth_Block_Wool_Orange_Light"
    },
    {
      "x": -7,
      "y": 31,
      "z": -3,
      "name": "Cloth_Block_Wool_Orange_Light"
    },
    {
      "x": -7,
      "y": 7,
      "z": -2,
      "name": "Wood_Hardwood_Planks"
    },
    {
      "x": -7,
      "y": 8,
      "z": -2,
      "name": "Block_Spawner_Block",
      "components": {
        "Components": {
          "PlacedByInteraction": {
            "WhoPlacedUuid": {
              "$binary": "3XRzOktQTQGfL/+8x7+CHA==",
              "$type": "04"
            }
          },
          "BlockSpawner": {
            "BlockSpawnerId": "Zone2_Undead_Tier2"
          }
        }
      }
    },
    {
      "x": -7,
      "y": 11,
      "z": -2,
      "name": "Wood_Hardwood_Planks"
    },
    {
      "x": -7,
      "y": 15,
      "z": -2,
      "name": "Wood_Hardwood_Planks"
    },
    {
      "x": -7,
      "y": 21,
      "z": -2,
      "name": "Cloth_Block_Wool_Orange_Light"
    },
    {
      "x": -7,
      "y": 31,
      "z": -2,
      "name": "Cloth_Block_Wool_Orange_Light"
    },
    {
      "x": -7,
      "y": 7,
      "z": -1,
      "name": "Wood_Hardwood_Planks"
    },
    {
      "x": -7,
      "y": 11,
      "z": -1,
      "name": "Wood_Hardwood_Planks"
    },
    {
      "x": -7,
      "y": 15,
      "z": -1,
      "name": "Wood_Hardwood_Planks"
    },
    {
      "x": -7,
      "y": 20,
      "z": -1,
      "name": "Cloth_Block_Wool_Orange_Light"
    },
    {
      "x": -7,
      "y": 32,
      "z": -1,
      "name": "Cloth_Block_Wool_Orange_Light"
    },
    {
      "x": -7,
      "y": 6,
      "z": 0,
      "name": "Wood_Hardwood_Planks"
    },
    {
      "x": -7,
      "y": 7,
      "z": 0,
      "name": "Wood_Hardwood_Planks"
    },
    {
      "x": -7,
      "y": 11,
      "z": 0,
      "name": "Wood_Hardwood_Planks"
    },
    {
      "x": -7,
      "y": 15,
      "z": 0,
      "name": "Wood_Hardwood_Planks"
    },
    {
      "x": -7,
      "y": 20,
      "z": 0,
      "name": "Cloth_Block_Wool_Orange_Light"
    },
    {
      "x": -7,
      "y": 32,
      "z": 0,
      "name": "Cloth_Block_Wool_Orange_Light"
    },
    {
      "x": -7,
      "y": 5,
      "z": 1,
      "name": "Wood_Hardwood_Planks"
    },
    {
      "x": -7,
      "y": 6,
      "z": 1,
      "name": "Wood_Hardwood_Planks"
    },
    {
      "x": -7,
      "y": 7,
      "z": 1,
      "name": "Wood_Hardwood_Planks"
    },
    {
      "x": -7,
      "y": 11,
      "z": 1,
      "name": "Wood_Hardwood_Planks"
    },
    {
      "x": -7,
      "y": 15,
      "z": 1,
      "name": "Wood_Hardwood_Planks"
    },
    {
      "x": -7,
      "y": 17,
      "z": 1,
      "name": "Metal_Copper_Pipe_Corner",
      "rotation": 3
    },
    {
      "x": -7,
      "y": 20,
      "z": 1,
      "name": "Cloth_Block_Wool_Orange_Light"
    },
    {
      "x": -7,
      "y": 32,
      "z": 1,
      "name": "Cloth_Block_Wool_Orange_Light"
    },
    {
      "x": -7,
      "y": 6,
      "z": 2,
      "name": "Wood_Hardwood_Planks"
    },
    {
      "x": -7,
      "y": 7,
      "z": 2,
      "name": "Wood_Hardwood_Planks"
    },
    {
      "x": -7,
      "y": 11,
      "z": 2,
      "name": "Wood_Hardwood_Planks"
    },
    {
      "x": -7,
      "y": 15,
      "z": 2,
      "name": "Wood_Hardwood_Planks"
    },
    {
      "x": -7,
      "y": 20,
      "z": 2,
      "name": "Cloth_Block_Wool_Orange_Light"
    },
    {
      "x": -7,
      "y": 32,
      "z": 2,
      "name": "Cloth_Block_Wool_Orange_Light"
    },
    {
      "x": -7,
      "y": 7,
      "z": 3,
      "name": "Wood_Hardwood_Planks"
    },
    {
      "x": -7,
      "y": 11,
      "z": 3,
      "name": "Wood_Hardwood_Planks"
    },
    {
      "x": -7,
      "y": 15,
      "z": 3,
      "name": "Wood_Hardwood_Planks"
    },
    {
      "x": -7,
      "y": 20,
      "z": 3,
      "name": "Cloth_Block_Wool_Orange_Light"
    },
    {
      "x": -7,
      "y": 32,
      "z": 3,
      "name": "Cloth_Block_Wool_Orange_Light"
    },
    {
      "x": -7,
      "y": 7,
      "z": 4,
      "name": "Wood_Hardwood_Planks"
    },
    {
      "x": -7,
      "y": 8,
      "z": 4,
      "name": "Deco_Lantern"
    },
    {
      "x": -7,
      "y": 11,
      "z": 4,
      "name": "Wood_Hardwood_Planks"
    },
    {
      "x": -7,
      "y": 15,
      "z": 4,
      "name": "Wood_Hardwood_Planks"
    },
    {
      "x": -7,
      "y": 21,
      "z": 4,
      "name": "Cloth_Block_Wool_Orange_Light"
    },
    {
      "x": -7,
      "y": 31,
      "z": 4,
      "name": "Cloth_Block_Wool_Orange_Light"
    },
    {
      "x": -7,
      "y": 8,
      "z": 5,
      "name": "Wood_Hardwood_Planks"
    },
    {
      "x": -7,
      "y": 9,
      "z": 5,
      "name": "Wood_Hardwood_Planks"
    },
    {
      "x": -7,
      "y": 10,
      "z": 5,
      "name": "Wood_Hardwood_Planks"
    },
    {
      "x": -7,
      "y": 11,
      "z": 5,
      "name": "Wood_Hardwood_Planks"
    },
    {
      "x": -7,
      "y": 15,
      "z": 5,
      "name": "Wood_Hardwood_Planks"
    },
    {
      "x": -7,
      "y": 21,
      "z": 5,
      "name": "Cloth_Block_Wool_Orange_Light"
    },
    {
      "x": -7,
      "y": 31,
      "z": 5,
      "name": "Cloth_Block_Wool_Orange_Light"
    },
    {
      "x": -7,
      "y": 10,
      "z": 6,
      "name": "Wood_Hardwood_Stairs",
      "rotation": 10
    },
    {
      "x": -7,
      "y": 11,
      "z": 6,
      "name": "Wood_Hardwood_Planks"
    },
    {
      "x": -7,
      "y": 12,
      "z": 6,
      "name": "Wood_Hardwood_Planks"
    },
    {
      "x": -7,
      "y": 13,
      "z": 6,
      "name": "Wood_Hardwood_Planks"
    },
    {
      "x": -7,
      "y": 14,
      "z": 6,
      "name": "Wood_Hardwood_Planks"
    },
    {
      "x": -7,
      "y": 15,
      "z": 6,
      "name": "Wood_Hardwood_Planks"
    },
    {
      "x": -7,
      "y": 16,
      "z": 6,
      "name": "Wood_Hardwood_Planks"
    },
    {
      "x": -7,
      "y": 22,
      "z": 6,
      "name": "Cloth_Block_Wool_Orange_Light"
    },
    {
      "x": -7,
      "y": 23,
      "z": 6,
      "name": "Cloth_Block_Wool_Orange_Light"
    },
    {
      "x": -7,
      "y": 29,
      "z": 6,
      "name": "Cloth_Block_Wool_Orange_Light"
    },
    {
      "x": -7,
      "y": 30,
      "z": 6,
      "name": "Cloth_Block_Wool_Orange_Light"
    },
    {
      "x": -7,
      "y": 24,
      "z": 7,
      "name": "Cloth_Block_Wool_Orange_Light"
    },
    {
      "x": -7,
      "y": 25,
      "z": 7,
      "name": "Cloth_Block_Wool_Orange_Light"
    },
    {
      "x": -7,
      "y": 26,
      "z": 7,
      "name": "Cloth_Block_Wool_Orange_Light"
    },
    {
      "x": -7,
      "y": 27,
      "z": 7,
      "name": "Cloth_Block_Wool_Orange_Light"
    },
    {
      "x": -7,
      "y": 28,
      "z": 7,
      "name": "Cloth_Block_Wool_Orange_Light"
    },
    {
      "x": -6,
      "y": 24,
      "z": -5,
      "name": "Cloth_Block_Wool_Orange_Light"
    },
    {
      "x": -6,
      "y": 25,
      "z": -5,
      "name": "Cloth_Block_Wool_Orange_Light"
    },
    {
      "x": -6,
      "y": 26,
      "z": -5,
      "name": "Cloth_Block_Wool_Orange_Light"
    },
    {
      "x": -6,
      "y": 27,
      "z": -5,
      "name": "Cloth_Block_Wool_Orange_Light"
    },
    {
      "x": -6,
      "y": 28,
      "z": -5,
      "name": "Cloth_Block_Wool_Orange_Light"
    },
    {
      "x": -6,
      "y": 10,
      "z": -4,
      "name": "Wood_Hardwood_Stairs",
      "rotation": 8
    },
    {
      "x": -6,
      "y": 11,
      "z": -4,
      "name": "Wood_Hardwood_Planks"
    },
    {
      "x": -6,
      "y": 12,
      "z": -4,
      "name": "Wood_Hardwood_Planks"
    },
    {
      "x": -6,
      "y": 13,
      "z": -4,
      "name": "Wood_Hardwood_Planks"
    },
    {
      "x": -6,
      "y": 14,
      "z": -4,
      "name": "Wood_Hardwood_Planks"
    },
    {
      "x": -6,
      "y": 15,
      "z": -4,
      "name": "Wood_Hardwood_Planks"
    },
    {
      "x": -6,
      "y": 16,
      "z": -4,
      "name": "Wood_Hardwood_Planks"
    },
    {
      "x": -6,
      "y": 22,
      "z": -4,
      "name": "Cloth_Block_Wool_Orange_Light"
    },
    {
      "x": -6,
      "y": 23,
      "z": -4,
      "name": "Cloth_Block_Wool_Orange_Light"
    },
    {
      "x": -6,
      "y": 29,
      "z": -4,
      "name": "Cloth_Block_Wool_Orange_Light"
    },
    {
      "x": -6,
      "y": 30,
      "z": -4,
      "name": "Cloth_Block_Wool_Orange_Light"
    },
    {
      "x": -6,
      "y": 8,
      "z": -3,
      "name": "Wood_Hardwood_Planks"
    },
    {
      "x": -6,
      "y": 9,
      "z": -3,
      "name": "Furniture_Village_Window"
    },
    {
      "x": -6,
      "y": 10,
      "z": -3,
      "name": "Wood_Hardwood_Planks"
    },
    {
      "x": -6,
      "y": 11,
      "z": -3,
      "name": "Wood_Hardwood_Planks"
    },
    {
      "x": -6,
      "y": 12,
      "z": -3,
      "name": "Wood_Hardwood_Planks"
    },
    {
      "x": -6,
      "y": 13,
      "z": -3,
      "name": "Wood_Hardwood_Planks"
    },
    {
      "x": -6,
      "y": 14,
      "z": -3,
      "name": "Wood_Hardwood_Planks"
    },
    {
      "x": -6,
      "y": 15,
      "z": -3,
      "name": "Wood_Hardwood_Planks"
    },
    {
      "x": -6,
      "y": 21,
      "z": -3,
      "name": "Cloth_Block_Wool_Orange_Light"
    },
    {
      "x": -6,
      "y": 31,
      "z": -3,
      "name": "Cloth_Block_Wool_Orange_Light"
    },
    {
      "x": -6,
      "y": 7,
      "z": -2,
      "name": "Wood_Hardwood_Planks"
    },
    {
      "x": -6,
      "y": 11,
      "z": -2,
      "name": "Wood_Hardwood_Planks"
    },
    {
      "x": -6,
      "y": 12,
      "z": -2,
      "name": "Wood_Hardwood_Planks"
    },
    {
      "x": -6,
      "y": 13,
      "z": -2,
      "name": "Wood_Hardwood_Planks"
    },
    {
      "x": -6,
      "y": 14,
      "z": -2,
      "name": "Wood_Hardwood_Planks"
    },
    {
      "x": -6,
      "y": 15,
      "z": -2,
      "name": "Wood_Hardwood_Planks"
    },
    {
      "x": -6,
      "y": 16,
      "z": -2,
      "name": "Wood_Hardwood_Planks"
    },
    {
      "x": -6,
      "y": 21,
      "z": -2,
      "name": "Cloth_Block_Wool_Orange_Light"
    },
    {
      "x": -6,
      "y": 31,
      "z": -2,
      "name": "Cloth_Block_Wool_Orange_Light"
    },
    {
      "x": -6,
      "y": 7,
      "z": -1,
      "name": "Wood_Hardwood_Planks"
    },
    {
      "x": -6,
      "y": 11,
      "z": -1,
      "name": "Wood_Hardwood_Planks"
    },
    {
      "x": -6,
      "y": 12,
      "z": -1,
      "name": "Wood_Hardwood_Planks"
    },
    {
      "x": -6,
      "y": 13,
      "z": -1,
      "name": "Furniture_Village_Window",
      "rotation": 1
    },
    {
      "x": -6,
      "y": 14,
      "z": -1,
      "name": "Furniture_Village_Window",
      "rotation": 1
    },
    {
      "x": -6,
      "y": 15,
      "z": -1,
      "name": "Wood_Hardwood_Planks"
    },
    {
      "x": -6,
      "y": 16,
      "z": -1,
      "name": "Wood_Hardwood_Planks"
    },
    {
      "x": -6,
      "y": 20,
      "z": -1,
      "name": "Cloth_Block_Wool_Orange_Light"
    },
    {
      "x": -6,
      "y": 32,
      "z": -1,
      "name": "Cloth_Block_Wool_Orange_Light"
    },
    {
      "x": -6,
      "y": 6,
      "z": 0,
      "name": "Wood_Hardwood_Planks"
    },
    {
      "x": -6,
      "y": 7,
      "z": 0,
      "name": "Wood_Hardwood_Planks"
    },
    {
      "x": -6,
      "y": 11,
      "z": 0,
      "name": "Wood_Hardwood_Planks"
    },
    {
      "x": -6,
      "y": 12,
      "z": 0,
      "name": "Wood_Hardwood_Planks"
    },
    {
      "x": -6,
      "y": 13,
      "z": 0,
      "name": "Wood_Hardwood_Planks"
    },
    {
      "x": -6,
      "y": 14,
      "z": 0,
      "name": "Wood_Hardwood_Planks"
    },
    {
      "x": -6,
      "y": 15,
      "z": 0,
      "name": "Wood_Hardwood_Planks"
    },
    {
      "x": -6,
      "y": 16,
      "z": 0,
      "name": "Wood_Hardwood_Planks"
    },
    {
      "x": -6,
      "y": 20,
      "z": 0,
      "name": "Cloth_Block_Wool_Orange_Light"
    },
    {
      "x": -6,
      "y": 32,
      "z": 0,
      "name": "Cloth_Block_Wool_Orange_Light"
    },
    {
      "x": -6,
      "y": 5,
      "z": 1,
      "name": "Wood_Hardwood_Planks"
    },
    {
      "x": -6,
      "y": 6,
      "z": 1,
      "name": "Wood_Hardwood_Planks"
    },
    {
      "x": -6,
      "y": 7,
      "z": 1,
      "name": "Wood_Hardwood_Planks"
    },
    {
      "x": -6,
      "y": 11,
      "z": 1,
      "name": "Wood_Hardwood_Planks"
    },
    {
      "x": -6,
      "y": 14,
      "z": 1,
      "name": "Wood_Hardwood_Planks"
    },
    {
      "x": -6,
      "y": 15,
      "z": 1,
      "name": "Metal_Copper"
    },
    {
      "x": -6,
      "y": 16,
      "z": 1,
      "name": "Metal_Copper_Decorative"
    },
    {
      "x": -6,
      "y": 17,
      "z": 1,
      "name": "Metal_Copper_Pipe_Corner",
      "rotation": 11
    },
    {
      "x": -6,
      "y": 20,
      "z": 1,
      "name": "Cloth_Block_Wool_Orange_Light"
    },
    {
      "x": -6,
      "y": 32,
      "z": 1,
      "name": "Cloth_Block_Wool_Orange_Light"
    },
    {
      "x": -6,
      "y": 6,
      "z": 2,
      "name": "Wood_Hardwood_Planks"
    },
    {
      "x": -6,
      "y": 7,
      "z": 2,
      "name": "Wood_Hardwood_Planks"
    },
    {
      "x": -6,
      "y": 11,
      "z": 2,
      "name": "Wood_Hardwood_Planks"
    },
    {
      "x": -6,
      "y": 12,
      "z": 2,
      "name": "Wood_Hardwood_Planks"
    },
    {
      "x": -6,
      "y": 13,
      "z": 2,
      "name": "Wood_Hardwood_Planks"
    },
    {
      "x": -6,
      "y": 14,
      "z": 2,
      "name": "Wood_Hardwood_Planks"
    },
    {
      "x": -6,
      "y": 15,
      "z": 2,
      "name": "Wood_Hardwood_Planks"
    },
    {
      "x": -6,
      "y": 16,
      "z": 2,
      "name": "Wood_Hardwood_Planks"
    },
    {
      "x": -6,
      "y": 20,
      "z": 2,
      "name": "Cloth_Block_Wool_Orange_Light"
    },
    {
      "x": -6,
      "y": 32,
      "z": 2,
      "name": "Cloth_Block_Wool_Orange_Light"
    },
    {
      "x": -6,
      "y": 7,
      "z": 3,
      "name": "Wood_Hardwood_Planks"
    },
    {
      "x": -6,
      "y": 11,
      "z": 3,
      "name": "Wood_Hardwood_Planks"
    },
    {
      "x": -6,
      "y": 12,
      "z": 3,
      "name": "Wood_Hardwood_Planks"
    },
    {
      "x": -6,
      "y": 13,
      "z": 3,
      "name": "Furniture_Village_Window",
      "rotation": 1
    },
    {
      "x": -6,
      "y": 14,
      "z": 3,
      "name": "Furniture_Village_Window",
      "rotation": 1
    },
    {
      "x": -6,
      "y": 15,
      "z": 3,
      "name": "Wood_Hardwood_Planks"
    },
    {
      "x": -6,
      "y": 16,
      "z": 3,
      "name": "Wood_Hardwood_Planks"
    },
    {
      "x": -6,
      "y": 20,
      "z": 3,
      "name": "Cloth_Block_Wool_Orange_Light"
    },
    {
      "x": -6,
      "y": 32,
      "z": 3,
      "name": "Cloth_Block_Wool_Orange_Light"
    },
    {
      "x": -6,
      "y": 7,
      "z": 4,
      "name": "Wood_Hardwood_Planks"
    },
    {
      "x": -6,
      "y": 11,
      "z": 4,
