{
  "version": 8,
  "blockIdVersion": 11,
  "anchorX": 0,
  "anchorY": 0,
  "anchorZ": 0,
  "blocks": [
    {
      "x": -15,
      "y": 11,
      "z": 7,
      "name": "Rock_Basalt"
    },
    {
      "x": -15,
      "y": 12,
      "z": 7,
      "name": "Rock_Basalt"
    },
    {
      "x": -15,
      "y": 13,
      "z": 7,
      "name": "Ore_Iron_Basalt_Cracked"
    },
    {
      "x": -15,
      "y": 14,
      "z": 7,
      "name": "Soil_Ash"
    },
    {
      "x": -15,
      "y": 8,
      "z": 8,
      "name": "Rock_Basalt_Stalactite_Large",
      "filler": 31744,
      "rotation": 8
    },
    {
      "x": -15,
      "y": 9,
      "z": 8,
      "name": "Rock_Basalt_Stalactite_Large",
      "rotation": 8
    },
    {
      "x": -15,
      "y": 10,
      "z": 8,
      "name": "Rock_Basalt"
    },
    {
      "x": -15,
      "y": 11,
      "z": 8,
      "name": "Rock_Basalt"
    },
    {
      "x": -15,
      "y": 12,
      "z": 8,
      "name": "Rock_Basalt"
    },
    {
      "x": -15,
      "y": 13,
      "z": 8,
      "name": "Rock_Basalt"
    },
    {
      "x": -15,
      "y": 14,
      "z": 8,
      "name": "Soil_Ash"
    },
    {
      "x": -15,
      "y": 11,
      "z": 9,
      "name": "Ore_Iron_Basalt_Cracked"
    },
    {
      "x": -15,
      "y": 12,
      "z": 9,
      "name": "Ore_Iron_Basalt_Cracked"
    },
    {
      "x": -15,
      "y": 13,
      "z": 9,
      "name": "Ore_Iron_Basalt_Cracked"
    },
    {
      "x": -15,
      "y": 14,
      "z": 9,
      "name": "Soil_Ash"
    },
    {
      "x": -15,
      "y": 15,
      "z": 9,
      "name": "Plant_Flower_Bushy_Poisoned"
    },
    {
      "x": -14,
      "y": 9,
      "z": 6,
      "name": "Ore_Iron_Basalt_Cracked"
    },
    {
      "x": -14,
      "y": 10,
      "z": 6,
      "name": "Rock_Basalt"
    },
    {
      "x": -14,
      "y": 11,
      "z": 6,
      "name": "Rock_Basalt"
    },
    {
      "x": -14,
      "y": 12,
      "z": 6,
      "name": "Rock_Basalt"
    },
    {
      "x": -14,
      "y": 13,
      "z": 6,
      "name": "Soil_Ash"
    },
    {
      "x": -14,
      "y": 14,
      "z": 6,
      "name": "Soil_Ash"
    },
    {
      "x": -14,
      "y": 15,
      "z": 6,
      "name": "Plant_Flower_Bushy_Poisoned"
    },
    {
      "x": -14,
      "y": 7,
      "z": 7,
      "name": "Rock_Basalt"
    },
    {
      "x": -14,
      "y": 8,
      "z": 7,
      "name": "Rock_Basalt"
    },
    {
      "x": -14,
      "y": 9,
      "z": 7,
      "name": "Rock_Basalt"
    },
    {
      "x": -14,
      "y": 10,
      "z": 7,
      "name": "Ore_Iron_Basalt_Cracked"
    },
    {
      "x": -14,
      "y": 11,
      "z": 7,
      "name": "Rock_Basalt"
    },
    {
      "x": -14,
      "y": 12,
      "z": 7,
      "name": "Rock_Basalt"
    },
    {
      "x": -14,
      "y": 13,
      "z": 7,
      "name": "Rock_Basalt"
    },
    {
      "x": -14,
      "y": 14,
      "z": 7,
      "name": "Rock_Basalt_Brick"
    },
    {
      "x": -14,
      "y": 15,
      "z": 7,
      "name": "Rock_Basalt_Brick_Pillar_Base"
    },
    {
      "x": -14,
      "y": 16,
      "z": 7,
      "name": "Rock_Basalt_Brick_Pillar_Middle"
    },
    {
      "x": -14,
      "y": 4,
      "z": 8,
      "name": "Rock_Crystal_Yellow_Medium",
      "rotation": 7
    },
    {
      "x": -14,
      "y": 6,
      "z": 8,
      "name": "Ore_Iron_Basalt_Cracked"
    },
    {
      "x": -14,
      "y": 7,
      "z": 8,
      "name": "Ore_Iron_Basalt_Cracked"
    },
    {
      "x": -14,
      "y": 8,
      "z": 8,
      "name": "Ore_Iron_Basalt_Cracked"
    },
    {
      "x": -14,
      "y": 9,
      "z": 8,
      "name": "Ore_Iron_Basalt_Cracked"
    },
    {
      "x": -14,
      "y": 10,
      "z": 8,
      "name": "Ore_Iron_Basalt_Cracked"
    },
    {
      "x": -14,
      "y": 11,
      "z": 8,
      "name": "Rock_Basalt"
    },
    {
      "x": -14,
      "y": 12,
      "z": 8,
      "name": "Rock_Basalt"
    },
    {
      "x": -14,
      "y": 13,
      "z": 8,
      "name": "Ore_Iron_Basalt_Cracked"
    },
    {
      "x": -14,
      "y": 14,
      "z": 8,
      "name": "Rock_Basalt_Brick"
    },
    {
      "x": -14,
      "y": 15,
      "z": 8,
      "name": "Block_Spawner_Block",
      "components": {
        "Components": {
          "PlacedByInteraction": {
            "WhoPlacedUuid": {
              "$binary": "3XRzOktQTQGfL/+8x7+CHA==",
              "$type": "04"
            }
          },
          "BlockSpawner": {
            "BlockSpawnerId": "Zone4_Encounters_Tier4"
          }
        }
      },
      "rotation": 1
    },
    {
      "x": -14,
      "y": 7,
      "z": 9,
      "name": "Rock_Basalt"
    },
    {
      "x": -14,
      "y": 8,
      "z": 9,
      "name": "Rock_Basalt"
    },
    {
      "x": -14,
      "y": 9,
      "z": 9,
      "name": "Ore_Iron_Basalt_Cracked"
    },
    {
      "x": -14,
      "y": 10,
      "z": 9,
      "name": "Rock_Basalt"
    },
    {
      "x": -14,
      "y": 11,
      "z": 9,
      "name": "Ore_Iron_Basalt_Cracked"
    },
    {
      "x": -14,
      "y": 12,
      "z": 9,
      "name": "Rock_Basalt"
    },
    {
      "x": -14,
      "y": 13,
      "z": 9,
      "name": "Ore_Iron_Basalt_Cracked"
    },
    {
      "x": -14,
      "y": 14,
      "z": 9,
      "name": "Rock_Basalt_Brick"
    },
    {
      "x": -14,
      "y": 7,
      "z": 10,
      "name": "Rock_Basalt_Stalactite_Large",
      "filler": 31744,
      "rotation": 8
    },
    {
      "x": -14,
      "y": 8,
      "z": 10,
      "name": "Rock_Basalt_Stalactite_Large",
      "rotation": 8
    },
    {
      "x": -14,
      "y": 9,
      "z": 10,
      "name": "Rock_Basalt"
    },
    {
      "x": -14,
      "y": 10,
      "z": 10,
      "name": "Rock_Basalt"
    },
    {
      "x": -14,
      "y": 11,
      "z": 10,
      "name": "Ore_Iron_Basalt_Cracked"
    },
    {
      "x": -14,
      "y": 12,
      "z": 10,
      "name": "Ore_Iron_Basalt_Cracked"
    },
    {
      "x": -14,
      "y": 13,
      "z": 10,
      "name": "Rock_Basalt"
    },
    {
      "x": -14,
      "y": 14,
      "z": 10,
      "name": "Soil_Ash"
    },
    {
      "x": -14,
      "y": 15,
      "z": 10,
      "name": "Plant_Flower_Bushy_Poisoned"
    },
    {
      "x": -13,
      "y": 7,
      "z": 6,
      "name": "Rock_Basalt"
    },
    {
      "x": -13,
      "y": 8,
      "z": 6,
      "name": "Rock_Basalt"
    },
    {
      "x": -13,
      "y": 9,
      "z": 6,
      "name": "Rock_Basalt"
    },
    {
      "x": -13,
      "y": 10,
      "z": 6,
      "name": "Ore_Iron_Basalt_Cracked"
    },
    {
      "x": -13,
      "y": 11,
      "z": 6,
      "name": "Rock_Basalt"
    },
    {
      "x": -13,
      "y": 12,
      "z": 6,
      "name": "Soil_Ash"
    },
    {
      "x": -13,
      "y": 13,
      "z": 6,
      "name": "Soil_Ash"
    },
    {
      "x": -13,
      "y": 14,
      "z": 6,
      "name": "Soil_Ash"
    },
    {
      "x": -13,
      "y": 3,
      "z": 7,
      "name": "Rock_Crystal_Yellow_Medium",
      "rotation": 7
    },
    {
      "x": -13,
      "y": 4,
      "z": 7,
      "name": "Rock_Crystal_Yellow_Medium",
      "rotation": 7
    },
    {
      "x": -13,
      "y": 5,
      "z": 7,
      "name": "Rock_Basalt"
    },
    {
      "x": -13,
      "y": 6,
      "z": 7,
      "name": "Ore_Iron_Basalt_Cracked"
    },
    {
      "x": -13,
      "y": 7,
      "z": 7,
      "name": "Ore_Iron_Basalt_Cracked"
    },
    {
      "x": -13,
      "y": 8,
      "z": 7,
      "name": "Ore_Iron_Basalt_Cracked"
    },
    {
      "x": -13,
      "y": 9,
      "z": 7,
      "name": "Ore_Iron_Basalt_Cracked"
    },
    {
      "x": -13,
      "y": 10,
      "z": 7,
      "name": "Rock_Basalt"
    },
    {
      "x": -13,
      "y": 11,
      "z": 7,
      "name": "Rock_Basalt"
    },
    {
      "x": -13,
      "y": 12,
      "z": 7,
      "name": "Rock_Basalt"
    },
    {
      "x": -13,
      "y": 13,
      "z": 7,
      "name": "Rock_Basalt_Brick"
    },
    {
      "x": -13,
      "y": 14,
      "z": 7,
      "name": "Rock_Basalt_Brick"
    },
    {
      "x": -13,
      "y": 2,
      "z": 8,
      "name": "Rock_Crystal_Yellow_Medium",
      "rotation": 7
    },
    {
      "x": -13,
      "y": 3,
      "z": 8,
      "name": "Rock_Crystal_Yellow_Medium",
      "rotation": 7
    },
    {
      "x": -13,
      "y": 4,
      "z": 8,
      "name": "Rock_Crystal_Yellow_Block"
    },
    {
      "x": -13,
      "y": 5,
      "z": 8,
      "name": "Rock_Crystal_Yellow_Block"
    },
    {
      "x": -13,
      "y": 6,
      "z": 8,
      "name": "Rock_Crystal_Yellow_Block"
    },
    {
      "x": -13,
      "y": 7,
      "z": 8,
      "name": "Rock_Crystal_Yellow_Block"
    },
    {
      "x": -13,
      "y": 8,
      "z": 8,
      "name": "Rock_Crystal_Yellow_Block"
    },
    {
      "x": -13,
      "y": 9,
      "z": 8,
      "name": "Rock_Crystal_Yellow_Block"
    },
    {
      "x": -13,
      "y": 10,
      "z": 8,
      "name": "Rock_Basalt"
    },
    {
      "x": -13,
      "y": 11,
      "z": 8,
      "name": "Rock_Basalt"
    },
    {
      "x": -13,
      "y": 12,
      "z": 8,
      "name": "Rock_Basalt"
    },
    {
      "x": -13,
      "y": 13,
      "z": 8,
      "name": "Ore_Iron_Basalt_Cracked"
    },
    {
      "x": -13,
      "y": 14,
      "z": 8,
      "name": "Rock_Basalt_Brick"
    },
    {
      "x": -13,
      "y": 3,
      "z": 9,
      "name": "Rock_Crystal_Yellow_Medium",
      "rotation": 7
    },
    {
      "x": -13,
      "y": 4,
      "z": 9,
      "name": "Rock_Crystal_Yellow_Medium",
      "rotation": 4
    },
    {
      "x": -13,
      "y": 5,
      "z": 9,
      "name": "Rock_Basalt"
    },
    {
      "x": -13,
      "y": 6,
      "z": 9,
      "name": "Rock_Basalt"
    },
    {
      "x": -13,
      "y": 7,
      "z": 9,
      "name": "Rock_Basalt"
    },
    {
      "x": -13,
      "y": 8,
      "z": 9,
      "name": "Rock_Basalt"
    },
    {
      "x": -13,
      "y": 9,
      "z": 9,
      "name": "Ore_Iron_Basalt_Cracked"
    },
    {
      "x": -13,
      "y": 10,
      "z": 9,
      "name": "Rock_Basalt"
    },
    {
      "x": -13,
      "y": 11,
      "z": 9,
      "name": "Rock_Basalt"
    },
    {
      "x": -13,
      "y": 12,
      "z": 9,
      "name": "Ore_Iron_Basalt_Cracked"
    },
    {
      "x": -13,
      "y": 13,
      "z": 9,
      "name": "Ore_Iron_Basalt_Cracked"
    },
    {
      "x": -13,
      "y": 14,
      "z": 9,
      "name": "Rock_Basalt_Brick"
    },
    {
      "x": -13,
      "y": 7,
      "z": 10,
      "name": "Rock_Basalt"
    },
    {
      "x": -13,
      "y": 8,
      "z": 10,
      "name": "Ore_Iron_Basalt_Cracked"
    },
    {
      "x": -13,
      "y": 9,
      "z": 10,
      "name": "Rock_Basalt"
    },
    {
      "x": -13,
      "y": 10,
      "z": 10,
      "name": "Rock_Basalt"
    },
    {
      "x": -13,
      "y": 11,
      "z": 10,
      "name": "Rock_Basalt"
    },
    {
      "x": -13,
      "y": 12,
      "z": 10,
      "name": "Rock_Basalt"
    },
    {
      "x": -13,
      "y": 13,
      "z": 10,
      "name": "Ore_Iron_Basalt_Cracked"
    },
    {
      "x": -13,
      "y": 14,
      "z": 10,
      "name": "Rock_Basalt_Brick"
    },
    {
      "x": -13,
      "y": 11,
      "z": 11,
      "name": "Rock_Basalt"
    },
    {
      "x": -13,
      "y": 12,
      "z": 11,
      "name": "Rock_Basalt"
    },
    {
      "x": -13,
      "y": 13,
      "z": 11,
      "name": "Rock_Basalt"
    },
    {
      "x": -13,
      "y": 14,
      "z": 11,
      "name": "Soil_Ash"
    },
    {
      "x": -12,
      "y": 14,
      "z": 5,
      "name": "Plant_Vine_Wall_Dead",
      "rotation": 2
    },
    {
      "x": -12,
      "y": 3,
      "z": 6,
      "name": "Rock_Crystal_Yellow_Medium",
      "rotation": 6
    },
    {
      "x": -12,
      "y": 4,
      "z": 6,
      "name": "Ore_Iron_Basalt_Cracked"
    },
    {
      "x": -12,
      "y": 5,
      "z": 6,
      "name": "Ore_Iron_Basalt_Cracked"
    },
    {
      "x": -12,
      "y": 6,
      "z": 6,
      "name": "Rock_Basalt"
    },
    {
      "x": -12,
      "y": 7,
      "z": 6,
      "name": "Rock_Basalt"
    },
    {
      "x": -12,
      "y": 8,
      "z": 6,
      "name": "Rock_Basalt"
    },
    {
      "x": -12,
      "y": 9,
      "z": 6,
      "name": "Ore_Iron_Basalt_Cracked"
    },
    {
      "x": -12,
      "y": 10,
      "z": 6,
      "name": "Rock_Basalt"
    },
    {
      "x": -12,
      "y": 11,
      "z": 6,
      "name": "Rock_Basalt"
    },
    {
      "x": -12,
      "y": 12,
      "z": 6,
      "name": "Rock_Basalt"
    },
    {
      "x": -12,
      "y": 13,
      "z": 6,
      "name": "Soil_Ash"
    },
    {
      "x": -12,
      "y": 14,
      "z": 6,
      "name": "Soil_Ash"
    },
    {
      "x": -12,
      "y": 2,
      "z": 7,
      "name": "Rock_Crystal_Yellow_Large",
      "rotation": 8
    },
    {
      "x": -12,
      "y": 3,
      "z": 7,
      "name": "Rock_Crystal_Yellow_Block"
    },
    {
      "x": -12,
      "y": 4,
      "z": 7,
      "name": "Rock_Crystal_Yellow_Block"
    },
    {
      "x": -12,
      "y": 5,
      "z": 7,
      "name": "Rock_Crystal_Yellow_Block"
    },
    {
      "x": -12,
      "y": 6,
      "z": 7,
      "name": "Rock_Crystal_Yellow_Block"
    },
    {
      "x": -12,
      "y": 7,
      "z": 7,
      "name": "Rock_Basalt"
    },
    {
      "x": -12,
      "y": 8,
      "z": 7,
      "name": "Rock_Crystal_Yellow_Block"
    },
    {
      "x": -12,
      "y": 9,
      "z": 7,
      "name": "Rock_Crystal_Yellow_Block"
    },
    {
      "x": -12,
      "y": 10,
      "z": 7,
      "name": "Ore_Iron_Basalt"
    },
    {
      "x": -12,
      "y": 11,
      "z": 7,
      "name": "Ore_Iron_Basalt_Cracked"
    },
    {
      "x": -12,
      "y": 12,
      "z": 7,
      "name": "Rock_Basalt"
    },
    {
      "x": -12,
      "y": 13,
      "z": 7,
      "name": "Rock_Basalt_Brick"
    },
    {
      "x": -12,
      "y": 14,
      "z": 7,
      "name": "Rock_Basalt_Brick"
    },
    {
      "x": -12,
      "y": 1,
      "z": 8,
      "name": "Rock_Crystal_Yellow_Large",
      "rotation": 8
    },
    {
      "x": -12,
      "y": 2,
      "z": 8,
      "name": "Rock_Crystal_Yellow_Block"
    },
    {
      "x": -12,
      "y": 3,
      "z": 8,
      "name": "Rock_Crystal_Yellow_Block"
    },
    {
      "x": -12,
      "y": 4,
      "z": 8,
      "name": "Rock_Crystal_Yellow_Block"
    },
    {
      "x": -12,
      "y": 5,
      "z": 8,
      "name": "Rock_Crystal_Yellow_Block"
    },
    {
      "x": -12,
      "y": 6,
      "z": 8,
      "name": "Rock_Crystal_Yellow_Block"
    },
    {
      "x": -12,
      "y": 7,
      "z": 8,
      "name": "Rock_Crystal_Yellow_Block"
    },
    {
      "x": -12,
      "y": 8,
      "z": 8,
      "name": "Soil_Dirt"
    },
    {
      "x": -12,
      "y": 9,
      "z": 8,
      "name": "Spawn_Labyrinth_Yellow_Circle"
    },
    {
      "x": -12,
      "y": 10,
      "z": 8,
      "name": "Rock_Basalt"
    },
    {
      "x": -12,
      "y": 11,
      "z": 8,
      "name": "Rock_Basalt"
    },
    {
      "x": -12,
      "y": 12,
      "z": 8,
      "name": "Rock_Basalt"
    },
    {
      "x": -12,
      "y": 13,
      "z": 8,
      "name": "Rock_Basalt"
    },
    {
      "x": -12,
      "y": 14,
      "z": 8,
      "name": "Rock_Basalt_Brick"
    },
    {
      "x": -12,
      "y": 2,
      "z": 9,
      "name": "Rock_Crystal_Yellow_Medium",
      "rotation": 8
    },
    {
      "x": -12,
      "y": 3,
      "z": 9,
      "name": "Rock_Crystal_Yellow_Block"
    },
    {
      "x": -12,
      "y": 4,
      "z": 9,
      "name": "Rock_Crystal_Yellow_Block"
    },
    {
      "x": -12,
      "y": 5,
      "z": 9,
      "name": "Rock_Crystal_Yellow_Block"
    },
    {
      "x": -12,
      "y": 6,
      "z": 9,
      "name": "Rock_Crystal_Yellow_Block"
    },
    {
      "x": -12,
      "y": 7,
      "z": 9,
      "name": "Rock_Crystal_Yellow_Block"
    },
    {
      "x": -12,
      "y": 8,
      "z": 9,
      "name": "Rock_Crystal_Yellow_Block"
    },
    {
      "x": -12,
      "y": 9,
      "z": 9,
      "name": "Rock_Crystal_Yellow_Block"
    },
    {
      "x": -12,
      "y": 10,
      "z": 9,
      "name": "Rock_Basalt"
    },
    {
      "x": -12,
      "y": 11,
      "z": 9,
      "name": "Rock_Basalt"
    },
    {
      "x": -12,
      "y": 12,
      "z": 9,
      "name": "Ore_Iron_Basalt"
    },
    {
      "x": -12,
      "y": 13,
      "z": 9,
      "name": "Rock_Basalt"
    },
    {
      "x": -12,
      "y": 14,
      "z": 9,
      "name": "Rock_Basalt_Brick"
    },
    {
      "x": -12,
      "y": 3,
      "z": 10,
      "name": "Rock_Crystal_Yellow_Medium",
      "rotation": 4
    },
    {
      "x": -12,
      "y": 5,
      "z": 10,
      "name": "Rock_Crystal_Yellow_Medium",
      "rotation": 4
    },
    {
      "x": -12,
      "y": 6,
      "z": 10,
      "name": "Rock_Basalt"
    },
    {
      "x": -12,
      "y": 7,
      "z": 10,
      "name": "Ore_Iron_Basalt_Cracked"
    },
    {
      "x": -12,
      "y": 8,
      "z": 10,
      "name": "Rock_Basalt"
    },
    {
      "x": -12,
      "y": 9,
      "z": 10,
      "name": "Rock_Basalt"
    },
    {
      "x": -12,
      "y": 10,
      "z": 10,
      "name": "Rock_Basalt"
    },
    {
      "x": -12,
      "y": 11,
      "z": 10,
      "name": "Rock_Basalt"
    },
    {
      "x": -12,
      "y": 12,
      "z": 10,
      "name": "Ore_Iron_Basalt_Cracked"
    },
    {
      "x": -12,
      "y": 13,
      "z": 10,
      "name": "Ore_Iron_Basalt_Cracked"
    },
    {
      "x": -12,
      "y": 14,
      "z": 10,
      "name": "Rock_Basalt_Brick"
    },
    {
      "x": -12,
      "y": 15,
      "z": 10,
      "name": "Rock_Basalt_Brick_Pillar_Middle",
      "rotation": 7
    },
    {
      "x": -12,
      "y": 10,
      "z": 11,
      "name": "Ore_Iron_Basalt_Cracked"
    },
    {
      "x": -12,
      "y": 11,
      "z": 11,
      "name": "Rock_Basalt"
    },
    {
      "x": -12,
      "y": 12,
      "z": 11,
      "name": "Rock_Basalt"
    },
    {
      "x": -12,
      "y": 13,
      "z": 11,
      "name": "Ore_Iron_Basalt_Cracked"
    },
    {
      "x": -12,
      "y": 14,
      "z": 11,
      "name": "Soil_Ash"
    },
    {
      "x": -12,
      "y": 15,
      "z": 11,
      "name": "Deco_SpiderWeb_Flat"
    },
    {
      "x": -11,
      "y": 7,
      "z": 6,
      "name": "Rock_Basalt"
    },
    {
      "x": -11,
      "y": 8,
      "z": 6,
      "name": "Rock_Basalt"
    },
    {
      "x": -11,
      "y": 9,
      "z": 6,
      "name": "Rock_Basalt"
    },
    {
      "x": -11,
      "y": 10,
      "z": 6,
      "name": "Rock_Basalt"
    },
    {
      "x": -11,
      "y": 11,
      "z": 6,
      "name": "Rock_Basalt"
    },
    {
      "x": -11,
      "y": 12,
      "z": 6,
      "name": "Rock_Basalt"
    },
    {
      "x": -11,
      "y": 13,
      "z": 6,
      "name": "Soil_Ash"
    },
    {
      "x": -11,
      "y": 14,
      "z": 6,
      "name": "Soil_Ash"
    },
    {
      "x": -11,
      "y": 5,
      "z": 7,
      "name": "Rock_Basalt"
    },
    {
      "x": -11,
      "y": 6,
      "z": 7,
      "name": "Ore_Iron_Basalt_Cracked"
    },
    {
      "x": -11,
      "y": 7,
      "z": 7,
      "name": "Ore_Iron_Basalt_Cracked"
    },
    {
      "x": -11,
      "y": 8,
      "z": 7,
      "name": "Ore_Iron_Basalt_Cracked"
    },
    {
      "x": -11,
      "y": 9,
      "z": 7,
      "name": "Ore_Iron_Basalt_Cracked"
    },
    {
      "x": -11,
      "y": 10,
      "z": 7,
      "name": "Ore_Iron_Basalt_Cracked"
    },
    {
      "x": -11,
      "y": 11,
      "z": 7,
      "name": "Ore_Iron_Basalt_Cracked"
    },
    {
      "x": -11,
      "y": 12,
      "z": 7,
      "name": "Rock_Basalt"
    },
    {
      "x": -11,
      "y": 13,
      "z": 7,
      "name": "Rock_Basalt_Brick"
    },
    {
      "x": -11,
      "y": 14,
      "z": 7,
      "name": "Rock_Basalt_Brick"
    },
    {
      "x": -11,
      "y": 15,
      "z": 7,
      "name": "Rock_Basalt_Brick_Pillar_Base"
    },
    {
      "x": -11,
      "y": 16,
      "z": 7,
      "name": "Rock_Basalt_Brick_Pillar_Middle"
    },
    {
      "x": -11,
      "y": 17,
      "z": 7,
      "name": "Rock_Basalt_Brick_Pillar_Middle"
    },
    {
      "x": -11,
      "y": 2,
      "z": 8,
      "name": "Rock_Crystal_Yellow_Large",
      "rotation": 8
    },
    {
      "x": -11,
      "y": 3,
      "z": 8,
      "name": "Rock_Crystal_Yellow_Block"
    },
    {
      "x": -11,
      "y": 4,
      "z": 8,
      "name": "Rock_Crystal_Yellow_Block"
    },
    {
      "x": -11,
      "y": 5,
      "z": 8,
      "name": "Rock_Crystal_Yellow_Block"
    },
    {
      "x": -11,
      "y": 6,
      "z": 8,
      "name": "Rock_Crystal_Yellow_Block"
    },
    {
      "x": -11,
      "y": 7,
      "z": 8,
      "name": "Rock_Crystal_Yellow_Block"
    },
    {
      "x": -11,
      "y": 8,
      "z": 8,
      "name": "Rock_Crystal_Yellow_Block"
    },
    {
      "x": -11,
      "y": 9,
      "z": 8,
      "name": "Rock_Crystal_Yellow_Block"
    },
    {
      "x": -11,
      "y": 10,
      "z": 8,
      "name": "Rock_Basalt"
    },
    {
      "x": -11,
      "y": 11,
      "z": 8,
      "name": "Ore_Iron_Basalt_Cracked"
    },
    {
      "x": -11,
      "y": 12,
      "z": 8,
      "name": "Ore_Iron_Basalt_Cracked"
    },
    {
      "x": -11,
      "y": 13,
      "z": 8,
      "name": "Rock_Basalt_Brick"
    },
    {
      "x": -11,
      "y": 14,
      "z": 8,
      "name": "Rock_Basalt_Brick"
    },
    {
      "x": -11,
      "y": 4,
      "z": 9,
      "name": "Rock_Crystal_Yellow_Medium",
      "rotation": 5
    },
    {
      "x": -11,
      "y": 5,
      "z": 9,
      "name": "Rock_Basalt"
    },
    {
      "x": -11,
      "y": 6,
      "z": 9,
      "name": "Rock_Basalt"
    },
    {
      "x": -11,
      "y": 7,
      "z": 9,
      "name": "Rock_Basalt"
    },
    {
      "x": -11,
      "y": 8,
      "z": 9,
      "name": "Ore_Iron_Basalt_Cracked"
    },
    {
      "x": -11,
      "y": 9,
      "z": 9,
      "name": "Ore_Iron_Basalt_Cracked"
    },
    {
      "x": -11,
      "y": 10,
      "z": 9,
      "name": "Rock_Basalt"
    },
    {
      "x": -11,
      "y": 11,
      "z": 9,
      "name": "Rock_Basalt"
    },
    {
      "x": -11,
      "y": 12,
      "z": 9,
      "name": "Ore_Iron_Basalt_Cracked"
    },
    {
      "x": -11,
      "y": 13,
      "z": 9,
      "name": "Rock_Basalt"
    },
    {
      "x": -11,
      "y": 14,
      "z": 9,
      "name": "Rock_Basalt_Brick"
    },
    {
      "x": -11,
      "y": 5,
      "z": 10,
      "name": "Rock_Basalt_Stalactite_Large",
      "filler": 31744,
      "rotation": 8
    },
    {
      "x": -11,
      "y": 6,
      "z": 10,
      "name": "Rock_Basalt_Stalactite_Large",
      "rotation": 8
    },
    {
      "x": -11,
      "y": 7,
      "z": 10,
      "name": "Rock_Basalt"
    },
    {
      "x": -11,
      "y": 8,
      "z": 10,
      "name": "Rock_Basalt"
    },
    {
      "x": -11,
      "y": 9,
      "z": 10,
      "name": "Rock_Basalt"
    },
    {
      "x": -11,
      "y": 10,
      "z": 10,
      "name": "Rock_Basalt"
    },
    {
      "x": -11,
      "y": 11,
      "z": 10,
      "name": "Rock_Basalt"
    },
    {
      "x": -11,
      "y": 12,
      "z": 10,
      "name": "Ore_Iron_Basalt_Cracked"
    },
    {
      "x": -11,
      "y": 13,
      "z": 10,
      "name": "Ore_Iron_Basalt_Cracked"
    },
    {
      "x": -11,
      "y": 14,
      "z": 10,
      "name": "Rock_Basalt_Brick"
    },
    {
      "x": -11,
      "y": 15,
      "z": 10,
      "name": "Rock_Basalt_Brick_Pillar_Base"
    },
    {
      "x": -11,
      "y": 11,
      "z": 11,
      "name": "Rock_Basalt"
    },
    {
      "x": -11,
      "y": 12,
      "z": 11,
      "name": "Rock_Basalt"
    },
    {
      "x": -11,
      "y": 13,
      "z": 11,
      "name": "Rock_Basalt"
    },
    {
      "x": -11,
      "y": 14,
      "z": 11,
      "name": "Soil_Ash"
    },
    {
      "x": -11,
      "y": 15,
      "z": 11,
      "name": "Deco_SpiderWeb_Flat"
    },
    {
      "x": -11,
      "y": 14,
      "z": 12,
      "name": "Deco_SpiderWeb_Flat",
      "rotation": 4
    },
    {
      "x": -10,
      "y": 6,
      "z": 7,
      "name": "Rock_Basalt_Stalactite_Small",
      "rotation": 8
    },
    {
      "x": -10,
      "y": 7,
      "z": 7,
      "name": "Rock_Basalt"
    },
    {
      "x": -10,
      "y": 8,
      "z": 7,
      "name": "Rock_Basalt"
    },
    {
      "x": -10,
      "y": 9,
      "z": 7,
      "name": "Rock_Basalt"
    },
    {
      "x": -10,
      "y": 10,
      "z": 7,
      "name": "Ore_Iron_Basalt_Cracked"
    },
    {
      "x": -10,
      "y": 11,
      "z": 7,
      "name": "Rock_Basalt"
    },
    {
      "x": -10,
      "y": 12,
      "z": 7,
      "name": "Rock_Basalt"
    },
    {
      "x": -10,
      "y": 13,
      "z": 7,
      "name": "Soil_Ash"
    },
    {
      "x": -10,
      "y": 14,
      "z": 7,
      "name": "Soil_Ash"
    },
    {
      "x": -10,
      "y": 15,
      "z": 7,
      "name": "Plant_Bush_Dead_Twisted"
    },
    {
      "x": -10,
      "y": 3,
      "z": 8,
      "name": "Rock_Crystal_Yellow_Medium",
      "rotation": 5
    },
    {
      "x": -10,
      "y": 4,
      "z": 8,
      "name": "Ore_Iron_Basalt_Cracked"
    },
    {
      "x": -10,
      "y": 5,
      "z": 8,
      "name": "Ore_Iron_Basalt_Cracked"
    },
    {
      "x": -10,
      "y": 6,
      "z": 8,
      "name": "Rock_Basalt"
    },
    {
      "x": -10,
      "y": 7,
      "z": 8,
      "name": "Ore_Iron_Basalt_Cracked"
    },
    {
      "x": -10,
      "y": 8,
      "z": 8,
      "name": "Ore_Iron_Basalt_Cracked"
    },
    {
      "x": -10,
      "y": 9,
      "z": 8,
      "name": "Rock_Basalt"
    },
    {
      "x": -10,
      "y": 10,
      "z": 8,
      "name": "Rock_Basalt"
    },
    {
      "x": -10,
      "y": 11,
      "z": 8,
      "name": "Rock_Basalt"
    },
    {
      "x": -10,
      "y": 12,
      "z": 8,
      "name": "Ore_Iron_Basalt_Cracked"
    },
    {
      "x": -10,
      "y": 13,
      "z": 8,
      "name": "Soil_Sand_Ashen"
    },
    {
      "x": -10,
      "y": 14,
      "z": 8,
      "name": "Soil_Ash"
    },
    {
      "x": -10,
      "y": 15,
      "z": 8,
      "name": "Plant_Bush_Dead_Twisted"
    },
    {
      "x": -10,
      "y": 5,
      "z": 9,
      "name": "Rock_Basalt_Stalactite_Large",
      "filler": 31744,
      "rotation": 8
    },
    {
      "x": -10,
      "y": 6,
      "z": 9,
      "name": "Rock_Basalt_Stalactite_Large",
      "rotation": 8
    },
    {
      "x": -10,
      "y": 7,
      "z": 9,
      "name": "Ore_Iron_Basalt_Cracked"
    },
    {
      "x": -10,
      "y": 8,
      "z": 9,
      "name": "Rock_Basalt"
    },
    {
      "x": -10,
      "y": 9,
      "z": 9,
      "name": "Ore_Iron_Basalt_Cracked"
    },
    {
      "x": -10,
      "y": 10,
      "z": 9,
      "name": "Ore_Iron_Basalt_Cracked"
    },
    {
      "x": -10,
      "y": 11,
      "z": 9,
      "name": "Ore_Iron_Basalt"
    },
    {
      "x": -10,
      "y": 12,
      "z": 9,
      "name": "Rock_Basalt"
    },
    {
      "x": -10,
      "y": 13,
      "z": 9,
      "name": "Soil_Sand_Ashen"
    },
    {
      "x": -10,
      "y": 14,
      "z": 9,
      "name": "Soil_Ash"
    },
    {
      "x": -10,
      "y": 15,
      "z": 9,
      "name": "Plant_Bush_Dead_Twisted"
    },
    {
      "x": -10,
      "y": 8,
      "z": 10,
      "name": "Rock_Basalt_Stalactite_Small",
      "rotation": 8
    },
    {
      "x": -10,
      "y": 9,
      "z": 10,
      "name": "Rock_Basalt"
    },
    {
      "x": -10,
      "y": 10,
      "z": 10,
      "name": "Rock_Basalt"
    },
    {
      "x": -10,
      "y": 11,
      "z": 10,
      "name": "Ore_Iron_Basalt_Cracked"
    },
    {
      "x": -10,
      "y": 12,
      "z": 10,
      "name": "Rock_Basalt"
    },
    {
      "x": -10,
      "y": 13,
      "z": 10,
      "name": "Ore_Iron_Basalt_Cracked"
    },
    {
      "x": -10,
      "y": 14,
      "z": 10,
      "name": "Soil_Ash"
    },
    {
      "x": -9,
      "y": 14,
      "z": 7,
      "name": "Plant_Vine_Wall_Dead",
      "rotation": 1
    },
    {
      "x": -9,
      "y": 8,
      "z": 8,
      "name": "Rock_Basalt_Stalactite_Large",
      "filler": 31744,
      "rotation": 8
    },
    {
      "x": -9,
      "y": 9,
      "z": 8,
      "name": "Rock_Basalt_Stalactite_Large",
      "rotation": 8
    },
    {
      "x": -9,
      "y": 10,
      "z": 8,
      "name": "Rock_Basalt"
    },
    {
      "x": -9,
      "y": 11,
      "z": 8,
      "name": "Ore_Iron_Basalt_Cracked"
    },
    {
      "x": -9,
      "y": 12,
      "z": 8,
      "name": "Ore_Iron_Basalt_Cracked"
    },
    {
      "x": -9,
      "y": 13,
      "z": 8,
      "name": "Soil_Ash"
    },
    {
      "x": -9,
      "y": 14,
      "z": 8,
      "name": "Soil_Ash"
    },
    {
      "x": -9,
      "y": 10,
      "z": 9,
      "name": "Rock_Basalt_Stalactite_Small",
      "rotation": 8
    },
    {
      "x": -9,
      "y": 11,
      "z": 9,
      "name": "Ore_Iron_Basalt_Cracked"
    },
    {
      "x": -9,
      "y": 12,
      "z": 9,
      "name": "Ore_Iron_Basalt_Cracked"
    },
    {
      "x": -9,
      "y": 13,
      "z": 9,
      "name": "Rock_Basalt"
    },
    {
      "x": -9,
      "y": 14,
      "z": 9,
      "name": "Soil_Ash"
    },
    {
      "x": -9,
      "y": 15,
      "z": 9,
      "name": "Plant_Bush_Dead_Twisted"
    },
    {
      "x": -9,
      "y": 14,
      "z": 10,
      "name": "Plant_Vine_Wall_Dead",
      "rotation": 1
    },
    {
      "x": -8,
      "y": 13,
      "z": 8,
      "name": "Plant_Vine_Wall_Dead",
      "rotation": 1
    },
    {
      "x": -8,
      "y": 14,
      "z": 8,
      "name": "Plant_Vine_Wall_Dead",
      "rotation": 1
    },
    {
      "x": -8,
      "y": 14,
      "z": 9,
      "name": "Plant_Vine_Wall_Dead",
      "rotation": 1
    },
    {
      "x": -4,
      "y": 18,
      "z": -10,
      "name": "Plant_Vine_Wall_Dead",
      "rotation": 3
    },
    {
      "x": -4,
      "y": 18,
      "z": -9,
      "name": "Plant_Vine_Wall_Dead",
      "rotation": 3
    },
    {
      "x": -4,
      "y": 18,
      "z": -8,
      "name": "Plant_Vine_Wall_Dead",
      "rotation": 3
    },
    {
      "x": -4,
      "y": 19,
      "z": -6,
      "name": "Plant_Vine_Wall_Dead",
      "rotation": 3
    },
    {
      "x": -4,
      "y": 17,
      "z": 0,
      "name": "Plant_Vine_Wall_Dead",
      "rotation": 3
    },
    {
      "x": -4,
      "y": 18,
      "z": 0,
      "name": "Plant_Vine_Wall_Dead",
      "rotation": 3
    },
    {
      "x": -4,
      "y": 19,
      "z": 0,
      "name": "Plant_Vine_Wall_Dead",
      "rotation": 3
    },
    {
      "x": -4,
      "y": 19,
      "z": 1,
      "name": "Plant_Vine_Wall_Dead",
      "rotation": 3
    },
    {
      "x": -4,
      "y": 18,
      "z": 2,
      "name": "Plant_Vine_Wall_Dead",
      "rotation": 3
    },
    {
      "x": -4,
      "y": 19,
      "z": 2,
      "name": "Plant_Vine_Wall_Dead",
      "rotation": 3
    },
    {
      "x": -4,
      "y": 14,
      "z": 3,
      "name": "Wood_Ash_Roots"
    },
    {
      "x": -4,
      "y": 15,
      "z": 3,
      "name": "Wood_Ash_Trunk_Full"
    },
    {
      "x": -4,
      "y": 16,
      "z": 3,
      "name": "Wood_Ash_Trunk_Full"
    },
    {
      "x": -4,
      "y": 16,
      "z": 4,
      "name": "Wood_Ash_Trunk_Full"
    },
    {
      "x": -4,
      "y": 17,
      "z": 4,
      "name": "Wood_Ash_Trunk"
    },
    {
      "x": -4,
      "y": 18,
      "z": 4,
      "name": "Wood_Ash_Trunk_Full"
    },
    {
      "x": -3,
      "y": 15,
      "z": -10,
      "name": "Ore_Iron_Basalt_Cracked"
    },
    {
      "x": -3,
      "y": 16,
      "z": -10,
      "name": "Rock_Basalt"
    },
    {
      "x": -3,
      "y": 17,
      "z": -10,
      "name": "Ore_Iron_Basalt_Cracked"
    },
    {
      "x": -3,
      "y": 18,
      "z": -10,
      "name": "Soil_Ash"
    },
    {
      "x": -3,
      "y": 12,
      "z": -9,
      "name": "Rock_Basalt_Stalactite_Large",
      "filler": 31744,
      "rotation": 8
    },
    {
      "x": -3,
      "y": 13,
      "z": -9,
      "name": "Rock_Basalt_Stalactite_Large",
      "rotation": 8
    },
    {
      "x": -3,
      "y": 14,
      "z": -9,
      "name": "Ore_Iron_Basalt_Cracked"
    },
    {
      "x": -3,
      "y": 15,
      "z": -9,
      "name": "Ore_Iron_Basalt_Cracked"
    },
    {
      "x": -3,
      "y": 16,
      "z": -9,
      "name": "Ore_Iron_Basalt_Cracked"
    },
    {
      "x": -3,
      "y": 17,
      "z": -9,
      "name": "Rock_Basalt"
    },
    {
      "x": -3,
      "y": 18,
      "z": -9,
      "name": "Soil_Ash"
    },
    {
      "x": -3,
      "y": 19,
      "z": -9,
      "name": "Plant_Bush_Dead_Twisted"
    },
    {
      "x": -3,
      "y": 13,
      "z": -8,
      "name": "Rock_Basalt_Stalactite_Large",
      "filler": 31744,
      "rotation": 8
    },
    {
      "x": -3,
      "y": 14,
      "z": -8,
      "name": "Rock_Basalt_Stalactite_Large",
      "rotation": 8
    },
    {
      "x": -3,
      "y": 15,
      "z": -8,
      "name": "Ore_Iron_Basalt_Cracked"
    },
    {
      "x": -3,
      "y": 16,
      "z": -8,
      "name": "Rock_Basalt"
    },
    {
      "x": -3,
      "y": 17,
      "z": -8,
      "name": "Rock_Basalt"
    },
    {
      "x": -3,
      "y": 18,
      "z": -8,
      "name": "Soil_Ash"
    },
    {
      "x": -3,
      "y": 10,
      "z": -7,
      "name": "Rock_Crystal_Yellow_Medium",
      "rotation": 7
    },
    {
      "x": -3,
      "y": 11,
      "z": -7,
      "name": "Rock_Crystal_Yellow_Medium",
      "rotation": 7
    },
    {
      "x": -3,
      "y": 12,
      "z": -7,
      "name": "Rock_Basalt"
    },
    {
      "x": -3,
      "y": 13,
      "z": -7,
      "name": "Ore_Iron_Basalt_Cracked"
    },
    {
      "x": -3,
      "y": 14,
      "z": -7,
      "name": "Ore_Iron_Basalt_Cracked"
    },
    {
      "x": -3,
      "y": 15,
      "z": -7,
      "name": "Ore_Iron_Basalt_Cracked"
    },
    {
      "x": -3,
      "y": 16,
      "z": -7,
      "name": "Rock_Basalt"
    },
    {
      "x": -3,
      "y": 17,
      "z": -7,
      "name": "Rock_Basalt"
    },
    {
      "x": -3,
      "y": 18,
      "z": -7,
      "name": "Rock_Basalt"
    },
    {
      "x": -3,
      "y": 19,
      "z": -7,
      "name": "Soil_Ash"
    },
    {
      "x": -3,
      "y": 20,
      "z": -7,
      "name": "Plant_Flower_Bushy_Poisoned"
    },
    {
      "x": -3,
      "y": 15,
      "z": -6,
      "name": "Rock_Basalt"
    },
    {
      "x": -3,
      "y": 16,
      "z": -6,
      "name": "Rock_Basalt"
    },
    {
      "x": -3,
      "y": 17,
      "z": -6,
      "name": "Ore_Iron_Basalt"
    },
    {
      "x": -3,
      "y": 18,
      "z": -6,
      "name": "Rock_Basalt"
    },
    {
      "x": -3,
      "y": 19,
      "z": -6,
      "name": "Soil_Ash"
    },
    {
      "x": -3,
      "y": 16,
      "z": -5,
      "name": "Ore_Iron_Basalt_Cracked"
    },
    {
      "x": -3,
      "y": 17,
      "z": -5,
      "name": "Ore_Iron_Basalt"
    },
    {
      "x": -3,
      "y": 18,
      "z": -5,
      "name": "Wood_Ash_Trunk_Full"
    },
    {
      "x": -3,
      "y": 19,
      "z": -5,
      "name": "Wood_Ash_Trunk"
    },
    {
      "x": -3,
      "y": 20,
      "z": -5,
      "name": "Wood_Ash_Trunk_Full"
    },
    {
      "x": -3,
      "y": 34,
      "z": -5,
      "name": "Wood_Ash_Branch_Short",
      "rotation": 3
    },
    {
      "x": -3,
      "y": 15,
      "z": -4,
      "name": "Wood_Ash_Roots"
    },
    {
      "x": -3,
      "y": 16,
      "z": -4,
      "name": "Wood_Ash_Trunk_Full"
    },
    {
      "x": -3,
      "y": 17,
      "z": -4,
      "name": "Wood_Ash_Trunk"
    },
    {
      "x": -3,
      "y": 18,
      "z": -4,
      "name": "Wood_Ash_Trunk_Full"
    },
    {
      "x": -3,
      "y": 15,
      "z": -2,
      "name": "Wood_Ash_Roots"
    },
    {
      "x": -3,
      "y": 16,
      "z": -2,
      "name": "Wood_Ash_Trunk_Full"
    },
    {
      "x": -3,
      "y": 17,
      "z": -2,
      "name": "Wood_Ash_Trunk"
    },
    {
      "x": -3,
      "y": 18,
      "z": -2,
      "name": "Wood_Ash_Trunk_Full"
    },
    {
      "x": -3,
      "y": 18,
      "z": -1,
      "name": "Wood_Ash_Trunk_Full"
    },
    {
      "x": -3,
      "y": 36,
      "z": -1,
      "name": "Wood_Ash_Trunk_Full"
    },
    {
      "x": -3,
      "y": 37,
      "z": -1,
      "name": "Wood_Ash_Trunk"
    },
    {
      "x": -3,
      "y": 38,
      "z": -1,
      "name": "Wood_Ash_Trunk"
    },
    {
      "x": -3,
      "y": 39,
      "z": -1,
      "name": "Wood_Ash_Trunk_Full"
    },
    {
      "x": -3,
      "y": 16,
      "z": 0,
      "name": "Rock_Basalt"
    },
    {
      "x": -3,
      "y": 17,
      "z": 0,
      "name": "Ore_Iron_Basalt"
    },
    {
      "x": -3,
      "y": 18,
      "z": 0,
      "name": "Ore_Iron_Basalt_Cracked"
    },
    {
      "x": -3,
      "y": 19,
      "z": 0,
      "name": "Soil_Sand_Ashen"
    },
    {
      "x": -3,
      "y": 15,
      "z": 1,
      "name": "Ore_Iron_Basalt_Cracked"
    },
    {
      "x": -3,
      "y": 16,
      "z": 1,
      "name": "Rock_Basalt"
    },
    {
      "x": -3,
      "y": 17,
      "z": 1,
      "name": "Ore_Iron_Basalt"
    },
    {
      "x": -3,
      "y": 18,
      "z": 1,
      "name": "Ore_Iron_Basalt_Cracked"
    },
    {
      "x": -3,
      "y": 19,
      "z": 1,
      "name": "Soil_Sand_Ashen"
    },
    {
      "x": -3,
      "y": 16,
      "z": 2,
      "name": "Rock_Basalt"
    },
    {
      "x": -3,
      "y": 17,
      "z": 2,
      "name": "Rock_Basalt"
    },
    {
      "x": -3,
      "y": 18,
      "z": 2,
      "name": "Rock_Basalt"
    },
    {
      "x": -3,
      "y": 19,
      "z": 2,
      "name": "Wood_Ash_Trunk_Full"
    },
    {
      "x": -3,
      "y": 20,
      "z": 2,
      "name": "Wood_Ash_Trunk_Full"
    },
    {
      "x": -3,
      "y": 19,
      "z": 3,
      "name": "Wood_Ash_Trunk_Full"
    },
    {
      "x": -3,
      "y": 17,
      "z": 4,
      "name": "Wood_Ash_Roots"
    },
    {
      "x": -3,
      "y": 18,
      "z": 4,
      "name": "Wood_Ash_Trunk_Full"
    },
    {
      "x": -3,
      "y": 19,
      "z": 4,
      "name": "Wood_Ash_Trunk_Full"
    },
    {
      "x": -2,
      "y": 18,
      "z": -12,
      "name": "Plant_Vine_Wall_Dead",
      "rotation": 2
    },
    {
      "x": -2,
      "y": 13,
      "z": -11,
      "name": "Rock_Basalt"
    },
    {
      "x": -2,
      "y": 14,
      "z": -11,
      "name": "Rock_Basalt"
    },
    {
      "x": -2,
      "y": 15,
      "z": -11,
      "name": "Ore_Iron_Basalt_Cracked"
    },
    {
      "x": -2,
      "y": 16,
      "z": -11,
      "name": "Ore_Iron_Basalt_Cracked"
    },
    {
      "x": -2,
      "y": 17,
      "z": -11,
      "name": "Ore_Iron_Basalt_Cracked"
    },
    {
      "x": -2,
      "y": 18,
      "z": -11,
      "name": "Soil_Ash"
    },
    {
      "x": -2,
      "y": 19,
      "z": -11,
      "name": "Plant_Flower_Bushy_Poisoned"
    },
    {
      "x": -2,
      "y": 10,
      "z": -10,
      "name": "Rock_Basalt_Stalactite_Small",
      "rotation": 8
    },
    {
      "x": -2,
      "y": 11,
      "z": -10,
      "name": "Rock_Basalt"
    },
    {
      "x": -2,
      "y": 12,
      "z": -10,
      "name": "Rock_Basalt"
    },
    {
      "x": -2,
      "y": 13,
      "z": -10,
      "name": "Rock_Basalt"
    },
    {
      "x": -2,
      "y": 14,
      "z": -10,
      "name": "Rock_Basalt"
    },
    {
      "x": -2,
      "y": 15,
      "z": -10,
      "name": "Rock_Basalt"
    },
    {
      "x": -2,
      "y": 16,
      "z": -10,
      "name": "Rock_Basalt"
    },
    {
      "x": -2,
      "y": 17,
      "z": -10,
      "name": "Ore_Iron_Basalt_Cracked"
    },
    {
      "x": -2,
      "y": 18,
      "z": -10,
      "name": "Soil_Ash"
    },
    {
      "x": -2,
      "y": 10,
      "z": -9,
      "name": "Ore_Iron_Basalt_Cracked"
    },
    {
      "x": -2,
      "y": 11,
      "z": -9,
      "name": "Rock_Basalt"
    },
    {
      "x": -2,
      "y": 12,
      "z": -9,
      "name": "Rock_Basalt"
    },
    {
      "x": -2,
      "y": 13,
      "z": -9,
      "name": "Rock_Basalt"
    },
    {
      "x": -2,
      "y": 14,
      "z": -9,
      "name": "Rock_Basalt"
    },
    {
      "x": -2,
      "y": 15,
      "z": -9,
      "name": "Ore_Iron_Basalt_Cracked"
    },
    {
      "x": -2,
      "y": 16,
      "z": -9,
      "name": "Ore_Iron_Basalt"
    },
    {
      "x": -2,
      "y": 17,
      "z": -9,
      "name": "Rock_Basalt"
    },
    {
      "x": -2,
      "y": 18,
      "z": -9,
      "name": "Soil_Ash"
    },
    {
      "x": -2,
      "y": 19,
      "z": -9,
      "name": "Plant_Flower_Bushy_Poisoned"
    },
    {
      "x": -2,
      "y": 9,
      "z": -8,
      "name": "Rock_Crystal_Yellow_Medium",
      "rotation": 7
    },
    {
      "x": -2,
      "y": 10,
      "z": -8,
      "name": "Rock_Crystal_Yellow_Medium",
      "rotation": 6
    },
    {
      "x": -2,
      "y": 11,
      "z": -8,
      "name": "Ore_Iron_Basalt_Cracked"
    },
    {
      "x": -2,
      "y": 12,
      "z": -8,
      "name": "Ore_Iron_Basalt_Cracked"
    },
    {
      "x": -2,
      "y": 13,
      "z": -8,
      "name": "Rock_Basalt"
    },
    {
      "x": -2,
      "y": 14,
      "z": -8,
      "name": "Rock_Basalt"
    },
    {
      "x": -2,
      "y": 15,
      "z": -8,
      "name": "Ore_Iron_Basalt_Cracked"
    },
    {
      "x": -2,
      "y": 16,
      "z": -8,
      "name": "Ore_Iron_Basalt_Cracked"
    },
    {
      "x": -2,
      "y": 17,
      "z": -8,
      "name": "Ore_Iron_Basalt"
    },
    {
      "x": -2,
      "y": 18,
      "z": -8,
      "name": "Rock_Basalt"
    },
    {
      "x": -2,
      "y": 19,
      "z": -8,
      "name": "Soil_Ash"
    },
    {
      "x": -2,
      "y": 9,
      "z": -7,
      "name": "Rock_Crystal_Yellow_Large",
      "rotation": 8
    },
    {
      "x": -2,
      "y": 10,
      "z": -7,
      "name": "Rock_Crystal_Yellow_Block"
    },
    {
      "x": -2,
      "y": 11,
      "z": -7,
      "name": "Rock_Crystal_Yellow_Block"
    },
    {
      "x": -2,
      "y": 12,
      "z": -7,
      "name": "Rock_Crystal_Yellow_Block"
    },
    {
      "x": -2,
      "y": 13,
      "z": -7,
      "name": "Rock_Crystal_Yellow_Block"
    },
    {
      "x": -2,
      "y": 14,
      "z": -7,
      "name": "Rock_Crystal_Yellow_Block"
    },
    {
      "x": -2,
      "y": 15,
      "z": -7,
      "name": "Rock_Crystal_Yellow_Block"
    },
    {
      "x": -2,
      "y": 16,
      "z": -7,
      "name": "Rock_Basalt"
    },
    {
      "x": -2,
      "y": 17,
      "z": -7,
      "name": "Ore_Iron_Basalt_Cracked"
    },
    {
      "x": -2,
      "y": 18,
      "z": -7,
      "name": "Rock_Basalt"
    },
    {
      "x": -2,
      "y": 19,
      "z": -7,
      "name": "Soil_Ash"
    },
    {
      "x": -2,
      "y": 10,
      "z": -6,
      "name": "Rock_Crystal_Yellow_Medium",
      "rotation": 7
    },
    {
      "x": -2,
      "y": 11,
      "z": -6,
      "name": "Rock_Basalt"
    },
    {
      "x": -2,
      "y": 12,
      "z": -6,
      "name": "Rock_Basalt"
    },
    {
      "x": -2,
      "y": 13,
      "z": -6,
      "name": "Rock_Basalt"
    },
    {
      "x": -2,
      "y": 14,
      "z": -6,
      "name": "Ore_Iron_Basalt_Cracked"
    },
    {
      "x": -2,
      "y": 15,
      "z": -6,
      "name": "Rock_Basalt"
    },
    {
      "x": -2,
      "y": 16,
      "z": -6,
      "name": "Ore_Iron_Basalt_Cracked"
    },
    {
      "x": -2,
      "y": 17,
      "z": -6,
      "name": "Rock_Basalt"
    },
    {
      "x": -2,
      "y": 18,
      "z": -6,
      "name": "Ore_Iron_Basalt_Cracked"
    },
    {
      "x": -2,
      "y": 19,
      "z": -6,
      "name": "Wood_Ash_Trunk_Full"
    },
    {
      "x": -2,
      "y": 20,
      "z": -6,
      "name": "Wood_Ash_Trunk_Full"
    },
    {
      "x": -2,
      "y": 34,
      "z": -6,
      "name": "Wood_Ash_Trunk_Full"
    },
    {
      "x": -2,
      "y": 35,
      "z": -6,
      "name": "Wood_Ash_Trunk"
    },
    {
      "x": -2,
      "y": 36,
      "z": -6,
      "name": "Wood_Ash_Trunk"
    },
    {
      "x": -2,
      "y": 37,
      "z": -6,
      "name": "Wood_Ash_Trunk_Full"
    },
    {
      "x": -2,
      "y": 12,
      "z": -5,
      "name": "Ore_Iron_Basalt_Cracked"
    },
    {
      "x": -2,
      "y": 13,
      "z": -5,
      "name": "Rock_Basalt"
    },
    {
      "x": -2,
      "y": 14,
      "z": -5,
      "name": "Ore_Iron_Basalt_Cracked"
    },
    {
      "x": -2,
      "y": 15,
      "z": -5,
      "name": "Rock_Basalt"
    },
    {
      "x": -2,
      "y": 16,
      "z": -5,
      "name": "Rock_Basalt"
    },
    {
      "x": -2,
      "y": 17,
      "z": -5,
      "name": "Rock_Basalt"
    },
    {
      "x": -2,
      "y": 18,
      "z": -5,
      "name": "Wood_Ash_Roots"
    },
    {
      "x": -2,
      "y": 19,
      "z": -5,
      "name": "Wood_Ash_Trunk_Full"
    },
    {
      "x": -2,
      "y": 20,
      "z": -5,
      "name": "Wood_Ash_Trunk_Full"
    },
    {
      "x": -2,
      "y": 33,
      "z": -5,
      "name": "Wood_Ash_Trunk_Full"
    },
    {
      "x": -2,
      "y": 34,
      "z": -5,
      "name": "Wood_Ash_Trunk"
    },
    {
      "x": -2,
      "y": 35,
      "z": -5,
      "name": "Wood_Ash_Trunk"
    },
    {
      "x": -2,
      "y": 36,
      "z": -5,
      "name": "Wood_Ash_Trunk_Full"
    },
    {
      "x": -2,
      "y": 14,
      "z": -4,
      "name": "Rock_Basalt"
    },
    {
      "x": -2,
      "y": 15,
      "z": -4,
      "name": "Rock_Basalt"
    },
    {
      "x": -2,
      "y": 16,
      "z": -4,
      "name": "Rock_Basalt"
    },
    {
      "x": -2,
      "y": 17,
      "z": -4,
      "name": "Ore_Iron_Basalt_Cracked"
    },
    {
      "x": -2,
      "y": 18,
      "z": -4,
      "name": "Rock_Basalt"
    },
    {
      "x": -2,
      "y": 19,
      "z": -4,
      "name": "Soil_Ash"
    },
    {
      "x": -2,
      "y": 20,
      "z": -4,
      "name": "Wood_Ash_Trunk_Full"
    },
    {
      "x": -2,
      "y": 21,
      "z": -4,
      "name": "Wood_Ash_Trunk_Full"
    },
    {
      "x": -2,
      "y": 32,
      "z": -4,
      "name": "Wood_Ash_Trunk_Full"
    },
    {
      "x": -2,
      "y": 33,
      "z": -4,
      "name": "Wood_Ash_Trunk_Full"
    },
    {
      "x": -2,
      "y": 30,
      "z": -2,
      "name": "Wood_Ash_Branch_Corner",
      "rotation": 3
    },
    {
      "x": -2,
      "y": 14,
      "z": -1,
      "name": "Rock_Basalt"
    },
    {
      "x": -2,
      "y": 15,
      "z": -1,
      "name": "Rock_Basalt"
    },
    {
      "x": -2,
      "y": 16,
      "z": -1,
      "name": "Rock_Basalt"
    },
    {
      "x": -2,
      "y": 17,
      "z": -1,
      "name": "Wood_Ash_Roots"
    },
    {
      "x": -2,
      "y": 18,
      "z": -1,
      "name": "Wood_Ash_Trunk_Full"
    },
    {
      "x": -2,
      "y": 19,
      "z": -1,
      "name": "Wood_Ash_Trunk"
    },
    {
      "x": -2,
      "y": 20,
      "z": -1,
      "name": "Wood_Ash_Trunk_Full"
    },
    {
      "x": -2,
      "y": 34,
      "z": -1,
      "name": "Wood_Ash_Trunk_Full"
    },
    {
      "x": -2,
      "y": 35,
      "z": -1,
      "name": "Wood_Ash_Trunk"
    },
    {
      "x": -2,
      "y": 36,
      "z": -1,
      "name": "Wood_Ash_Trunk_Full"
    },
    {
      "x": -2,
      "y": 12,
      "z": 0,
      "name": "Rock_Basalt"
    },
    {
      "x": -2,
      "y": 13,
      "z": 0,
      "name": "Ore_Iron_Basalt_Cracked"
    },
    {
      "x": -2,
      "y": 14,
      "z": 0,
      "name": "Rock_Basalt"
    },
    {
      "x": -2,
      "y": 15,
      "z": 0,
      "name": "Ore_Iron_Basalt_Cracked"
    },
    {
      "x": -2,
      "y": 16,
      "z": 0,
      "name": "Rock_Basalt"
    },
    {
      "x": -2,
      "y": 17,
      "z": 0,
      "name": "Rock_Basalt"
    },
    {
      "x": -2,
      "y": 18,
      "z": 0,
      "name": "Rock_Basalt"
    },
    {
      "x": -2,
      "y": 19,
      "z": 0,
      "name": "Soil_Sand_Ashen"
    },
    {
      "x": -2,
      "y": 20,
      "z": 0,
      "name": "Wood_Ash_Trunk_Full"
    },
    {
      "x": -2,
      "y": 35,
      "z": 0,
      "name": "Wood_Ash_Trunk_Full"
    },
    {
      "x": -2,
      "y": 36,
      "z": 0,
      "name": "Wood_Ash_Trunk_Full"
    },
    {
      "x": -2,
      "y": 11,
      "z": 1,
      "name": "Rock_Basalt"
    },
    {
      "x": -2,
      "y": 12,
      "z": 1,
      "name": "Rock_Basalt"
    },
    {
      "x": -2,
      "y": 13,
      "z": 1,
      "name": "Rock_Basalt"
    },
    {
      "x": -2,
      "y": 14,
      "z": 1,
      "name": "Ore_Iron_Basalt_Cracked"
    },
    {
      "x": -2,
      "y": 15,
      "z": 1,
      "name": "Rock_Basalt"
    },
    {
      "x": -2,
      "y": 16,
      "z": 1,
      "name": "Ore_Iron_Basalt_Cracked"
    },
    {
      "x": -2,
      "y": 17,
      "z": 1,
      "name": "Ore_Iron_Basalt_Cracked"
    },
    {
      "x": -2,
      "y": 18,
      "z": 1,
      "name": "Rock_Basalt"
    },
    {
      "x": -2,
      "y": 19,
      "z": 1,
      "name": "Soil_Sand_Ashen"
    },
    {
      "x": -2,
      "y": 20,
      "z": 1,
      "name": "Wood_Ash_Trunk_Full"
    },
    {
      "x": -2,
      "y": 21,
      "z": 1,
      "name": "Wood_Ash_Trunk_Full"
    },
    {
      "x": -2,
      "y": 33,
      "z": 1,
      "name": "Wood_Ash_Branch_Long",
      "rotation": 5
    },
    {
      "x": -2,
      "y": 12,
      "z": 2,
      "name": "Ore_Iron_Basalt_Cracked"
    },
    {
      "x": -2,
      "y": 13,
      "z": 2,
      "name": "Ore_Iron_Basalt_Cracked"
    },
    {
      "x": -2,
      "y": 14,
      "z": 2,
      "name": "Ore_Iron_Basalt_Cracked"
    },
    {
      "x": -2,
      "y": 15,
      "z": 2,
      "name": "Rock_Basalt"
    },
    {
      "x": -2,
      "y": 16,
      "z": 2,
      "name": "Rock_Basalt"
    },
    {
      "x": -2,
      "y": 17,
      "z": 2,
      "name": "Rock_Basalt"
    },
    {
      "x": -2,
      "y": 18,
      "z": 2,
      "name": "Ore_Iron_Basalt_Cracked"
    },
    {
      "x": -2,
      "y": 19,
      "z": 2,
      "name": "Soil_Sand_Ashen"
    },
    {
      "x": -2,
      "y": 20,
      "z": 2,
      "name": "Wood_Ash_Trunk_Full"
    },
    {
      "x": -2,
      "y": 37,
      "z": 2,
      "name": "Wood_Ash_Branch_Long",
      "rotation": 5
    },
    {
      "x": -2,
      "y": 14,
      "z": 3,
      "name": "Rock_Basalt"
    },
    {
      "x": -2,
      "y": 15,
      "z": 3,
      "name": "Rock_Basalt"
    },
    {
      "x": -2,
      "y": 16,
      "z": 3,
      "name": "Rock_Basalt"
    },
    {
      "x": -2,
      "y": 17,
      "z": 3,
      "name": "Rock_Basalt"
    },
    {
      "x": -2,
      "y": 18,
      "z": 3,
      "name": "Ore_Iron_Basalt_Cracked"
    },
    {
      "x": -2,
      "y": 19,
      "z": 3,
      "name": "Soil_Sand_Ashen"
    },
    {
      "x": -1,
      "y": 15,
      "z": -12,
      "name": "Ore_Iron_Basalt_Cracked"
    },
    {
      "x": -1,
      "y": 16,
      "z": -12,
      "name": "Rock_Basalt"
    },
    {
      "x": -1,
      "y": 17,
      "z": -12,
      "name": "Ore_Iron_Basalt_Cracked"
    },
    {
      "x": -1,
      "y": 18,
      "z": -12,
      "name": "Soil_Ash"
    },
    {
      "x": -1,
      "y": 11,
      "z": -11,
      "name": "Rock_Basalt"
    },
    {
      "x": -1,
      "y": 12,
      "z": -11,
      "name": "Rock_Basalt"
    },
    {
      "x": -1,
      "y": 13,
      "z": -11,
      "name": "Rock_Basalt"
    },
    {
      "x": -1,
      "y": 14,
      "z": -11,
      "name": "Rock_Basalt"
    },
    {
      "x": -1,
      "y": 15,
      "z": -11,
      "name": "Rock_Basalt"
    },
    {
      "x": -1,
      "y": 16,
      "z": -11,
      "name": "Rock_Basalt"
    },
    {
      "x": -1,
      "y": 17,
      "z": -11,
      "name": "Ore_Iron_Basalt_Cracked"
    },
    {
      "x": -1,
      "y": 18,
      "z": -11,
      "name": "Soil_Ash"
    },
    {
      "x": -1,
      "y": 8,
      "z": -10,
      "name": "Rock_Basalt_Stalactite_Small",
      "rotation": 8
    },
    {
      "x": -1,
      "y": 9,
      "z": -10,
      "name": "Ore_Iron_Basalt_Cracked"
    },
    {
      "x": -1,
      "y": 10,
      "z": -10,
      "name": "Ore_Iron_Basalt_Cracked"
    },
    {
      "x": -1,
      "y": 11,
      "z": -10,
      "name": "Rock_Basalt"
    },
    {
      "x": -1,
      "y": 12,
      "z": -10,
      "name": "Rock_Basalt"
    },
    {
      "x": -1,
      "y": 13,
      "z": -10,
      "name": "Rock_Basalt"
    },
    {
      "x": -1,
      "y": 14,
      "z": -10,
      "name": "Ore_Iron_Basalt_Cracked"
    },
    {
      "x": -1,
      "y": 15,
      "z": -10,
      "name": "Ore_Iron_Basalt_Cracked"
    },
    {
      "x": -1,
      "y": 16,
      "z": -10,
      "name": "Ore_Iron_Basalt_Cracked"
    },
    {
      "x": -1,
      "y": 17,
      "z": -10,
      "name": "Ore_Iron_Basalt_Cracked"
    },
    {
      "x": -1,
      "y": 18,
      "z": -10,
      "name": "Soil_Ash"
    },
    {
      "x": -1,
      "y": 9,
      "z": -9,
      "name": "Rock_Basalt"
    },
    {
      "x": -1,
      "y": 10,
      "z": -9,
      "name": "Rock_Basalt"
    },
    {
      "x": -1,
      "y": 11,
      "z": -9,
      "name": "Ore_Iron_Basalt_Cracked"
    },
    {
      "x": -1,
      "y": 12,
      "z": -9,
      "name": "Rock_Basalt"
    },
    {
      "x": -1,
      "y": 13,
      "z": -9,
      "name": "Rock_Basalt"
    },
    {
      "x": -1,
      "y": 14,
      "z": -9,
      "name": "Rock_Basalt"
    },
    {
      "x": -1,
      "y": 15,
      "z": -9,
      "name": "Rock_Basalt"
    },
    {
      "x": -1,
      "y": 16,
      "z": -9,
      "name": "Ore_Iron_Basalt_Cracked"
    },
    {
      "x": -1,
      "y": 17,
      "z": -9,
      "name": "Rock_Basalt"
    },
    {
      "x": -1,
      "y": 18,
      "z": -9,
      "name": "Ore_Iron_Basalt_Cracked"
    },
    {
      "x": -1,
      "y": 19,
      "z": -9,
      "name": "Soil_Ash"
    },
    {
      "x": -1,
      "y": 20,
      "z": -9,
      "name": "Deco_SpiderWeb_Flat"
    },
    {
      "x": -1,
      "y": 8,
      "z": -8,
      "name": "Rock_Crystal_Yellow_Medium",
      "rotation": 8
    },
    {
      "x": -1,
      "y": 9,
      "z": -8,
      "name": "Rock_Crystal_Yellow_Block"
    },
    {
      "x": -1,
      "y": 10,
      "z": -8,
      "name": "Rock_Crystal_Yellow_Block"
    },
    {
      "x": -1,
      "y": 11,
      "z": -8,
      "name": "Rock_Crystal_Yellow_Block"
    },
    {
      "x": -1,
      "y": 12,
      "z": -8,
      "name": "Rock_Crystal_Yellow_Block"
    },
    {
      "x": -1,
      "y": 13,
      "z": -8,
      "name": "Rock_Crystal_Yellow_Block"
    },
    {
      "x": -1,
      "y": 14,
      "z": -8,
      "name": "Rock_Crystal_Yellow_Block"
    },
    {
      "x": -1,
      "y": 15,
      "z": -8,
      "name": "Rock_Crystal_Yellow_Block"
    },
    {
      "x": -1,
      "y": 16,
      "z": -8,
      "name": "Rock_Basalt"
    },
    {
      "x": -1,
      "y": 17,
      "z": -8,
      "name": "Ore_Iron_Basalt_Cracked"
    },
    {
      "x": -1,
      "y": 18,
      "z": -8,
      "name": "Rock_Basalt"
    },
    {
      "x": -1,
      "y": 19,
      "z": -8,
      "name": "Soil_Ash"
    },
    {
      "x": -1,
      "y": 20,
      "z": -8,
      "name": "Plant_Flower_Bushy_Poisoned"
    },
    {
      "x": -1,
      "y": 7,
      "z": -7,
      "name": "Rock_Crystal_Yellow_Large",
      "rotation": 8
    },
    {
      "x": -1,
      "y": 8,
      "z": -7,
      "name": "Rock_Crystal_Yellow_Block"
    },
    {
      "x": -1,
      "y": 9,
      "z": -7,
      "name": "Rock_Crystal_Yellow_Block"
    },
    {
      "x": -1,
      "y": 10,
      "z": -7,
      "name": "Rock_Crystal_Yellow_Block"
    },
    {
      "x": -1,
      "y": 11,
      "z": -7,
      "name": "Rock_Crystal_Yellow_Block"
    },
    {
      "x": -1,
      "y": 12,
      "z": -7,
      "name": "Rock_Crystal_Yellow_Block"
    },
    {
      "x": -1,
      "y": 13,
      "z": -7,
      "name": "Rock_Crystal_Yellow_Block"
    },
    {
      "x": -1,
      "y": 14,
      "z": -7,
      "name": "Rock_Crystal_Yellow_Block"
    },
    {
      "x": -1,
      "y": 15,
      "z": -7,
      "name": "Rock_Crystal_Yellow_Block"
    },
    {
      "x": -1,
      "y": 16,
      "z": -7,
      "name": "Wood_Ash_Trunk"
    },
    {
      "x": -1,
      "y": 17,
      "z": -7,
      "name": "Wood_Ash_Trunk"
    },
    {
      "x": -1,
      "y": 18,
      "z": -7,
      "name": "Wood_Ash_Trunk_Full"
    },
    {
      "x": -1,
      "y": 19,
      "z": -7,
      "name": "Soil_Ash"
    },
    {
      "x": -1,
      "y": 35,
      "z": -7,
      "name": "Wood_Ash_Branch_Long",
      "rotation": 4
    },
    {
      "x": -1,
      "y": 8,
      "z": -6,
      "name": "Rock_Crystal_Yellow_Large",
      "rotation": 8
    },
    {
      "x": -1,
      "y": 9,
      "z": -6,
      "name": "Rock_Crystal_Yellow_Block"
    },
    {
      "x": -1,
      "y": 10,
      "z": -6,
      "name": "Rock_Crystal_Yellow_Block"
    },
    {
      "x": -1,
      "y": 11,
      "z": -6,
      "name": "Rock_Crystal_Yellow_Block"
    },
    {
      "x": -1,
      "y": 12,
      "z": -6,
      "name": "Rock_Crystal_Yellow_Block"
    },
    {
      "x": -1,
      "y": 13,
      "z": -6,
      "name": "Rock_Crystal_Yellow_Block"
    },
    {
      "x": -1,
      "y": 14,
      "z": -6,
      "name": "Rock_Crystal_Yellow_Block"
    },
    {
      "x": -1,
      "y": 15,
      "z": -6,
      "name": "Rock_Crystal_Yellow_Block"
    },
    {
      "x": -1,
      "y": 16,
      "z": -6,
      "name": "Rock_Basalt"
    },
    {
      "x": -1,
      "y": 17,
      "z": -6,
      "name": "Rock_Basalt"
    },
    {
      "x": -1,
      "y": 18,
      "z": -6,
      "name": "Wood_Ash_Trunk_Full"
    },
    {
      "x": -1,
      "y": 19,
      "z": -6,
      "name": "Wood_Ash_Trunk_Full"
    },
    {
      "x": -1,
      "y": 33,
      "z": -6,
      "name": "Wood_Ash_Trunk_Full"
    },
    {
      "x": -1,
      "y": 34,
      "z": -6,
      "name": "Wood_Ash_Trunk"
    },
    {
      "x": -1,
      "y": 35,
      "z": -6,
      "name": "Wood_Ash_Trunk"
    },
    {
      "x": -1,
      "y": 36,
      "z": -6,
      "name": "Wood_Ash_Trunk"
    },
    {
      "x": -1,
      "y": 37,
      "z": -6,
      "name": "Wood_Ash_Trunk"
    },
    {
      "x": -1,
      "y": 38,
      "z": -6,
      "name": "Wood_Ash_Trunk_Full"
    },
    {
      "x": -1,
      "y": 9,
      "z": -5,
      "name": "Rock_Crystal_Yellow_Medium",
      "rotation": 4
    },
    {
      "x": -1,
      "y": 10,
      "z": -5,
      "name": "Rock_Basalt"
    },
    {
      "x": -1,
      "y": 11,
      "z": -5,
      "name": "Ore_Iron_Basalt_Cracked"
    },
    {
      "x": -1,
      "y": 12,
      "z": -5,
      "name": "Rock_Basalt"
    },
    {
      "x": -1,
      "y": 13,
      "z": -5,
      "name": "Rock_Basalt"
    },
    {
      "x": -1,
      "y": 14,
      "z": -5,
      "name": "Ore_Iron_Basalt_Cracked"
    },
    {
      "x": -1,
      "y": 15,
      "z": -5,
      "name": "Rock_Basalt"
    },
    {
      "x": -1,
      "y": 16,
      "z": -5,
      "name": "Ore_Iron_Basalt_Cracked"
    },
    {
      "x": -1,
      "y": 17,
      "z": -5,
      "name": "Ore_Iron_Basalt_Cracked"
    },
    {
      "x": -1,
      "y": 18,
      "z": -5,
      "name": "Ore_Iron_Basalt_Cracked"
    },
    {
      "x": -1,
      "y": 19,
      "z": -5,
      "name": "Soil_Ash"
    },
    {
      "x": -1,
      "y": 32,
      "z": -5,
      "name": "Wood_Ash_Trunk_Full"
    },
    {
      "x": -1,
      "y": 33,
      "z": -5,
      "name": "Wood_Ash_Trunk"
    },
    {
      "x": -1,
      "y": 34,
      "z": -5,
      "name": "Wood_Ash_Trunk_Full"
    },
    {
      "x": -1,
      "y": 37,
      "z": -5,
      "name": "Wood_Ash_Trunk_Full"
    },
    {
      "x": -1,
      "y": 38,
      "z": -5,
      "name": "Wood_Ash_Trunk"
    },
    {
      "x": -1,
      "y": 39,
      "z": -5,
      "name": "Wood_Ash_Trunk_Full"
    },
    {
      "x": -1,
      "y": 12,
      "z": -4,
      "name": "Ore_Iron_Basalt_Cracked"
    },
    {
      "x": -1,
      "y": 13,
      "z": -4,
      "name": "Ore_Iron_Basalt_Cracked"
    },
    {
      "x": -1,
      "y": 14,
      "z": -4,
      "name": "Rock_Basalt"
    },
    {
      "x": -1,
      "y": 15,
      "z": -4,
      "name": "Rock_Basalt"
    },
    {
      "x": -1,
      "y": 16,
      "z": -4,
      "name": "Ore_Iron_Basalt_Cracked"
    },
    {
      "x": -1,
      "y": 17,
      "z": -4,
      "name": "Ore_Iron_Basalt_Cracked"
    },
    {
      "x": -1,
      "y": 18,
      "z": -4,
      "name": "Rock_Basalt"
    },
    {
      "x": -1,
      "y": 19,
      "z": -4,
      "name": "Soil_Ash"
    },
    {
      "x": -1,
      "y": 21,
      "z": -4,
      "name": "Wood_Ash_Trunk_Full"
    },
    {
      "x": -1,
      "y": 30,
      "z": -4,
      "name": "Wood_Ash_Roots"
    },
    {
      "x": -1,
      "y": 31,
      "z": -4,
      "name": "Wood_Ash_Trunk_Full"
    },
    {
      "x": -1,
      "y": 32,
      "z": -4,
      "name": "Wood_Ash_Trunk"
    },
    {
      "x": -1,
      "y": 33,
      "z": -4,
      "name": "Wood_Ash_Trunk_Full"
    },
    {
      "x": -1,
      "y": 39,
      "z": -4,
      "name": "Wood_Ash_Trunk_Full"
    },
    {
      "x": -1,
      "y": 40,
      "z": -4,
      "name": "Wood_Ash_Trunk"
    },
    {
      "x": -1,
      "y": 41,
      "z": -4,
      "name": "Wood_Ash_Trunk_Full"
    },
    {
      "x": -1,
      "y": 16,
      "z": -3,
      "name": "Ore_Iron_Basalt_Cracked"
    },
    {
      "x": -1,
      "y": 17,
      "z": -3,
      "name": "Rock_Basalt"
    },
    {
      "x": -1,
      "y": 18,
      "z": -3,
      "name": "Rock_Basalt"
    },
    {
      "x": -1,
      "y": 19,
      "z": -3,
      "name": "Soil_Ash"
    },
    {
      "x": -1,
      "y": 23,
      "z": -3,
      "name": "Deco_SpiderWeb_Flat",
      "rotation": 7
    },
    {
      "x": -1,
      "y": 31,
      "z": -3,
      "name": "Wood_Ash_Trunk_Full"
    },
    {
      "x": -1,
      "y": 32,
      "z": -3,
      "name": "Wood_Ash_Trunk_Full"
    },
    {
      "x": -1,
      "y": 16,
      "z": -2,
      "name": "Rock_Basalt"
    },
    {
      "x": -1,
      "y": 17,
      "z": -2,
      "name": "Ore_Iron_Basalt"
    },
    {
      "x": -1,
      "y": 18,
      "z": -2,
      "name": "Rock_Basalt"
    },
    {
      "x": -1,
      "y": 19,
      "z": -2,
      "name": "Soil_Sand_Ashen"
    },
    {
      "x": -1,
      "y": 30,
      "z": -2,
      "name": "Wood_Ash_Branch_Long",
      "rotation": 5
    },
    {
      "x": -1,
      "y": 11,
      "z": -1,
      "name": "Rock_Basalt_Stalactite_Small",
      "rotation": 8
    },
    {
      "x": -1,
      "y": 12,
      "z": -1,
      "name": "Rock_Basalt"
    },
    {
      "x": -1,
      "y": 13,
      "z": -1,
      "name": "Rock_Basalt"
    },
    {
      "x": -1,
      "y": 14,
      "z": -1,
      "name": "Rock_Basalt"
    },
    {
      "x": -1,
      "y": 15,
      "z": -1,
      "name": "Ore_Iron_Basalt_Cracked"
    },
    {
      "x": -1,
      "y": 16,
      "z": -1,
      "name": "Rock_Basalt"
    },
    {
      "x": -1,
      "y": 17,
      "z": -1,
      "name": "Rock_Basalt"
    },
    {
      "x": -1,
      "y": 18,
      "z": -1,
      "name": "Rock_Basalt"
    },
    {
      "x": -1,
      "y": 19,
      "z": -1,
      "name": "Soil_Sand_Ashen"
    },
    {
      "x": -1,
      "y": 34,
      "z": -1,
      "name": "Wood_Ash_Trunk_Full"
    },
    {
      "x": -1,
      "y": 8,
      "z": 0,
      "name": "Rock_Basalt_Stalactite_Large",
      "filler": 31744,
      "rotation": 8
    },
    {
      "x": -1,
      "y": 9,
      "z": 0,
      "name": "Rock_Basalt_Stalactite_Large",
      "rotation": 8
    },
    {
      "x": -1,
      "y": 10,
      "z": 0,
      "name": "Rock_Basalt"
    },
    {
      "x": -1,
      "y": 11,
      "z": 0,
      "name": "Rock_Basalt"
    },
    {
      "x": -1,
      "y": 12,
      "z": 0,
      "name": "Rock_Basalt"
    },
    {
      "x": -1,
      "y": 13,
      "z": 0,
      "name": "Ore_Iron_Basalt_Cracked"
    },
    {
      "x": -1,
      "y": 14,
      "z": 0,
      "name": "Rock_Basalt"
    },
    {
      "x": -1,
      "y": 15,
      "z": 0,
      "name": "Ore_Iron_Basalt_Cracked"
    },
    {
      "x": -1,
      "y": 16,
      "z": 0,
      "name": "Rock_Basalt"
    },
    {
      "x": -1,
      "y": 17,
      "z": 0,
      "name": "Ore_Iron_Basalt"
    },
    {
      "x": -1,
      "y": 18,
      "z": 0,
      "name": "Ore_Iron_Basalt_Cracked"
    },
    {
      "x": -1,
      "y": 19,
      "z": 0,
      "name": "Soil_Sand_Ashen"
    },
    {
      "x": -1,
      "y": 20,
      "z": 0,
      "name": "Wood_Ash_Trunk_Full"
    },
    {
      "x": -1,
      "y": 21,
      "z": 0,
      "name": "Wood_Ash_Trunk_Full"
    },
    {
      "x": -1,
      "y": 32,
      "z": 0,
      "name": "Wood_Ash_Roots"
    },
    {
      "x": -1,
      "y": 33,
      "z": 0,
      "name": "Wood_Ash_Trunk_Full"
    },
    {
      "x": -1,
      "y": 34,
      "z": 0,
      "name": "Wood_Ash_Trunk"
    },
    {
      "x": -1,
      "y": 35,
      "z": 0,
      "name": "Wood_Ash_Trunk_Full"
    },
    {
      "x": -1,
      "y": 10,
      "z": 1,
      "name": "Rock_Basalt"
    },
    {
      "x": -1,
      "y": 11,
      "z": 1,
      "name": "Ore_Iron_Basalt_Cracked"
    },
    {
      "x": -1,
      "y": 12,
      "z": 1,
      "name": "Rock_Basalt"
    },
    {
      "x": -1,
      "y": 13,
      "z": 1,
      "name": "Rock_Basalt"
    },
    {
      "x": -1,
      "y": 14,
      "z": 1,
      "name": "Rock_Basalt"
    },
    {
      "x": -1,
      "y": 15,
      "z": 1,
      "name": "Ore_Iron_Basalt_Cracked"
    },
    {
      "x": -1,
      "y": 16,
      "z": 1,
      "name": "Ore_Iron_Basalt_Cracked"
    },
    {
      "x": -1,
      "y": 17,
      "z": 1,
      "name": "Rock_Basalt"
    },
    {
      "x": -1,
      "y": 18,
      "z": 1,
      "name": "Rock_Basalt"
    },
    {
      "x": -1,
      "y": 19,
      "z": 1,
      "name": "Soil_Sand_Ashen"
    },
    {
      "x": -1,
      "y": 20,
      "z": 1,
      "name": "Wood_Ash_Roots"
    },
    {
      "x": -1,
      "y": 21,
      "z": 1,
      "name": "Wood_Ash_Trunk_Full"
    },
    {
      "x": -1,
      "y": 22,
      "z": 1,
      "name": "Wood_Ash_Trunk_Full"
    },
    {
      "x": -1,
      "y": 32,
      "z": 1,
      "name": "Deco_SpiderWeb_Flat",
      "rotation": 7
    },
    {
      "x": -1,
      "y": 33,
      "z": 1,
      "name": "Wood_Ash_Branch_Long",
      "rotation": 5
    },
    {
      "x": -1,
      "y": 10,
      "z": 2,
      "name": "Rock_Basalt"
    },
    {
      "x": -1,
      "y": 11,
      "z": 2,
      "name": "Rock_Basalt"
    },
    {
      "x": -1,
      "y": 12,
      "z": 2,
      "name": "Rock_Basalt"
    },
    {
      "x": -1,
      "y": 13,
      "z": 2,
      "name": "Ore_Iron_Basalt_Cracked"
    },
    {
      "x": -1,
      "y": 14,
      "z": 2,
      "name": "Ore_Iron_Basalt_Cracked"
    },
    {
      "x": -1,
      "y": 15,
      "z": 2,
      "name": "Rock_Basalt"
    },
    {
      "x": -1,
      "y": 16,
      "z": 2,
      "name": "Rock_Basalt"
    },
    {
      "x": -1,
      "y": 17,
      "z": 2,
      "name": "Ore_Iron_Basalt_Cracked"
    },
    {
      "x": -1,
      "y": 18,
      "z": 2,
      "name": "Ore_Iron_Basalt_Cracked"
    },
    {
      "x": -1,
      "y": 19,
      "z": 2,
      "name": "Soil_Sand_Ashen"
    },
    {
      "x": -1,
      "y": 33,
      "z": 2,
      "name": "Deco_SpiderWeb_Flat",
      "rotation": 7
    },
    {
      "x": -1,
      "y": 36,
      "z": 2,
      "name": "Wood_Ash_Trunk_Full"
    },
    {
      "x": -1,
      "y": 37,
      "z": 2,
      "name": "Wood_Ash_Trunk"
    },
    {
      "x": -1,
      "y": 38,
      "z": 2,
      "name": "Wood_Ash_Trunk"
    },
    {
      "x": -1,
      "y": 39,
      "z": 2,
      "name": "Wood_Ash_Trunk_Full"
    },
    {
      "x": -1,
      "y": 12,
      "z": 3,
      "name": "Rock_Basalt"
    },
    {
      "x": -1,
      "y": 13,
      "z": 3,
      "name": "Rock_Basalt"
    },
    {
      "x": -1,
      "y": 14,
      "z": 3,
      "name": "Rock_Basalt"
    },
    {
      "x": -1,
      "y": 15,
      "z": 3,
      "name": "Rock_Basalt"
    },
    {
      "x": -1,
      "y": 16,
      "z": 3,
      "name": "Rock_Basalt"
    },
    {
      "x": -1,
      "y": 17,
      "z": 3,
      "name": "Ore_Iron_Basalt_Cracked"
    },
    {
      "x": -1,
      "y": 18,
      "z": 3,
      "name": "Rock_Basalt"
    },
    {
      "x": -1,
      "y": 19,
      "z": 3,
      "name": "Soil_Sand_Ashen"
    },
    {
      "x": -1,
      "y": 35,
      "z": 3,
      "name": "Wood_Ash_Trunk_Full"
    },
    {
      "x": -1,
      "y": 36,
      "z": 3,
      "name": "Wood_Ash_Trunk"
    },
    {
      "x": -1,
      "y": 37,
      "z": 3,
      "name": "Wood_Ash_Trunk"
    },
    {
      "x": -1,
      "y": 38,
      "z": 3,
      "name": "Wood_Ash_Trunk_Full"
    },
    {
      "x": -1,
      "y": 16,
      "z": 4,
      "name": "Rock_Basalt"
    },
    {
      "x": -1,
      "y": 17,
      "z": 4,
      "name": "Rock_Basalt"
    },
    {
      "x": -1,
      "y": 18,
      "z": 4,
      "name": "Ore_Iron_Basalt_Cracked"
    },
    {
      "x": -1,
      "y": 19,
      "z": 4,
      "name": "Soil_Sand_Ashen"
    },
    {
      "x": -1,
      "y": 36,
      "z": 4,
      "name": "Deco_SpiderWeb_Flat",
      "rotation": 4
    },
    {
      "x": 0,
      "y": 14,
      "z": -12,
      "name": "Ore_Iron_Basalt_Cracked"
    },
    {
      "x": 0,
      "y": 15,
      "z": -12,
      "name": "Rock_Basalt"
    },
    {
      "x": 0,
      "y": 16,
      "z": -12,
      "name": "Ore_Iron_Basalt_Cracked"
    },
    {
      "x": 0,
      "y": 17,
      "z": -12,
      "name": "Rock_Basalt"
    },
    {
      "x": 0,
      "y": 18,
      "z": -12,
      "name": "Soil_Ash"
    },
    {
      "x": 0,
      "y": 10,
      "z": -11,
      "name": "Rock_Basalt"
    },
    {
      "x": 0,
      "y": 11,
      "z": -11,
      "name": "Ore_Iron_Basalt_Cracked"
    },
    {
      "x": 0,
      "y": 12,
      "z": -11,
      "name": "Ore_Iron_Basalt_Cracked"
    },
    {
      "x": 0,
      "y": 13,
      "z": -11,
      "name": "Rock_Basalt"
    },
    {
      "x": 0,
      "y": 14,
      "z": -11,
      "name": "Ore_Iron_Basalt_Cracked"
    },
    {
      "x": 0,
      "y": 15,
      "z": -11,
      "name": "Rock_Basalt"
    },
    {
      "x": 0,
      "y": 16,
      "z": -11,
      "name": "Rock_Basalt"
    },
    {
      "x": 0,
      "y": 17,
      "z": -11,
      "name": "Rock_Basalt"
    },
    {
      "x": 0,
      "y": 18,
      "z": -11,
      "name": "Soil_Ash"
    },
    {
      "x": 0,
      "y": 19,
      "z": -11,
      "name": "Plant_Flower_Bushy_Poisoned"
    },
    {
      "x": 0,
      "y": 8,
      "z": -10,
      "name": "Rock_Basalt_Stalactite_Small",
      "rotation": 8
    },
    {
      "x": 0,
      "y": 9,
      "z": -10,
      "name": "Rock_Basalt"
    },
    {
      "x": 0,
      "y": 10,
      "z": -10,
      "name": "Rock_Basalt"
    },
    {
      "x": 0,
      "y": 11,
      "z": -10,
      "name": "Rock_Basalt"
    },
    {
      "x": 0,
      "y": 12,
      "z": -10,
      "name": "Ore_Iron_Basalt_Cracked"
    },
    {
      "x": 0,
      "y": 13,
      "z": -10,
      "name": "Rock_Basalt"
    },
    {
      "x": 0,
      "y": 14,
      "z": -10,
      "name": "Rock_Basalt"
    },
    {
      "x": 0,
      "y": 15,
      "z": -10,
      "name": "Rock_Basalt"
    },
    {
      "x": 0,
      "y": 16,
      "z": -10,
      "name": "Ore_Iron_Basalt_Cracked"
    },
    {
      "x": 0,
      "y": 17,
      "z": -10,
      "name": "Rock_Basalt"
    },
    {
      "x": 0,
      "y": 18,
      "z": -10,
      "name": "Soil_Sand_Ashen"
    },
    {
      "x": 0,
      "y": 8,
      "z": -9,
      "name": "Rock_Basalt"
    },
    {
      "x": 0,
      "y": 9,
      "z": -9,
      "name": "Rock_Basalt"
    },
    {
      "x": 0,
      "y": 10,
      "z": -9,
      "name": "Ore_Iron_Basalt_Cracked"
    },
    {
      "x": 0,
      "y": 11,
      "z": -9,
      "name": "Rock_Basalt"
    },
    {
      "x": 0,
      "y": 12,
      "z": -9,
      "name": "Ore_Iron_Basalt_Cracked"
    },
    {
      "x": 0,
      "y": 13,
      "z": -9,
      "name": "Rock_Basalt"
    },
    {
      "x": 0,
      "y": 14,
      "z": -9,
      "name": "Rock_Basalt"
    },
    {
      "x": 0,
      "y": 15,
      "z": -9,
      "name": "Ore_Iron_Basalt_Cracked"
    },
    {
      "x": 0,
      "y": 16,
      "z": -9,
      "name": "Ore_Iron_Basalt_Cracked"
    },
    {
      "x": 0,
      "y": 17,
      "z": -9,
      "name": "Rock_Basalt"
    },
    {
      "x": 0,
      "y": 18,
      "z": -9,
      "name": "Soil_Sand_Ashen"
    },
    {
      "x": 0,
      "y": 19,
      "z": -9,
      "name": "Deco_Spider_Cocoon"
    },
    {
      "x": 0,
      "y": 20,
      "z": -9,
      "name": "Deco_Spider_Cocoon",
      "filler": 1024
    },
    {
      "x": 0,
      "y": 9,
      "z": -8,
      "name": "Rock_Basalt"
    },
    {
      "x": 0,
      "y": 10,
      "z": -8,
      "name": "Rock_Basalt"
    },
    {
      "x": 0,
      "y": 11,
      "z": -8,
      "name": "Rock_Basalt"
    },
    {
      "x": 0,
      "y": 12,
      "z": -8,
      "name": "Ore_Iron_Basalt_Cracked"
    },
    {
      "x": 0,
      "y": 13,
      "z": -8,
      "name": "Ore_Iron_Basalt_Cracked"
    },
    {
      "x": 0,
      "y": 14,
      "z": -8,
      "name": "Ore_Iron_Basalt_Cracked"
    },
    {
      "x": 0,
      "y": 15,
      "z": -8,
      "name": "Ore_Iron_Basalt_Cracked"
    },
    {
      "x": 0,
      "y": 16,
      "z": -8,
      "name": "Rock_Basalt"
    },
    {
      "x": 0,
      "y": 17,
      "z": -8,
      "name": "Ore_Iron_Basalt_Cracked"
    },
    {
      "x": 0,
      "y": 18,
      "z": -8,
      "name": "Rock_Basalt"
    },
    {
      "x": 0,
      "y": 19,
      "z": -8,
      "name": "Soil_Ash"
    },
    {
      "x": 0,
      "y": 20,
      "z": -8,
      "name": "Deco_SpiderWeb_Flat"
    },
    {
      "x": 0,
      "y": 8,
      "z": -7,
      "name": "Rock_Crystal_Yellow_Medium",
      "rotation": 8
    },
    {
      "x": 0,
      "y": 9,
      "z": -7,
      "name": "Rock_Crystal_Yellow_Block"
    },
    {
      "x": 0,
      "y": 10,
      "z": -7,
      "name": "Rock_Crystal_Yellow_Block"
    },
    {
      "x": 0,
      "y": 11,
      "z": -7,
      "name": "Rock_Crystal_Yellow_Block"
    },
    {
      "x": 0,
      "y": 12,
      "z": -7,
      "name": "Rock_Crystal_Yellow_Block"
    },
    {
      "x": 0,
      "y": 13,
      "z": -7,
      "name": "Rock_Crystal_Yellow_Block"
    },
    {
      "x": 0,
      "y": 14,
      "z": -7,
      "name": "Rock_Crystal_Yellow_Block"
    },
    {
      "x": 0,
      "y": 15,
      "z": -7,
      "name": "Rock_Crystal_Yellow_Block"
    },
    {
      "x": 0,
      "y": 16,
      "z": -7,
      "name": "Rock_Basalt"
    },
    {
      "x": 0,
      "y": 17,
      "z": -7,
      "name": "Rock_Basalt"
    },
    {
      "x": 0,
      "y": 18,
      "z": -7,
      "name": "Ore_Iron_Basalt_Cracked"
    },
    {
      "x": 0,
      "y": 19,
      "z": -7,
      "name": "Soil_Ash"
    },
    {
      "x": 0,
      "y": 9,
      "z": -6,
      "name": "Rock_Basalt"
    },
    {
      "x": 0,
      "y": 10,
      "z": -6,
      "name": "Rock_Basalt"
    },
    {
      "x": 0,
      "y": 11,
      "z": -6,
      "name": "Ore_Iron_Basalt_Cracked"
    },
    {
      "x": 0,
      "y": 12,
      "z": -6,
      "name": "Rock_Basalt"
    },
    {
      "x": 0,
      "y": 13,
      "z": -6,
      "name": "Rock_Basalt"
    },
    {
      "x": 0,
      "y": 14,
      "z": -6,
      "name": "Rock_Basalt"
    },
    {
      "x": 0,
      "y": 15,
      "z": -6,
      "name": "Ore_Iron_Basalt_Cracked"
    },
    {
      "x": 0,
      "y": 16,
      "z": -6,
      "name": "Rock_Basalt"
    },
    {
      "x": 0,
      "y": 17,
      "z": -6,
      "name": "Ore_Iron_Basalt_Cracked"
    },
    {
      "x": 0,
      "y": 18,
      "z": -6,
      "name": "Rock_Basalt"
    },
    {
      "x": 0,
      "y": 19,
      "z": -6,
      "name": "Soil_Ash"
    },
    {
      "x": 0,
      "y": 33,
      "z": -6,
      "name": "Deco_SpiderWeb_Flat",
      "rotation": 6
    },
    {
      "x": 0,
      "y": 10,
      "z": -5,
      "name": "Rock_Basalt"
    },
    {
      "x": 0,
      "y": 11,
      "z": -5,
      "name": "Ore_Iron_Basalt_Cracked"
    },
    {
      "x": 0,
      "y": 12,
      "z": -5,
      "name": "Ore_Iron_Basalt_Cracked"
    },
    {
      "x": 0,
      "y": 13,
      "z": -5,
      "name": "Ore_Iron_Basalt_Cracked"
    },
    {
      "x": 0,
      "y": 14,
      "z": -5,
      "name": "Rock_Basalt"
    },
    {
      "x": 0,
      "y": 15,
      "z": -5,
      "name": "Rock_Basalt"
    },
    {
      "x": 0,
      "y": 16,
      "z": -5,
      "name": "Ore_Iron_Basalt_Cracked"
    },
    {
      "x": 0,
      "y": 17,
      "z": -5,
      "name": "Rock_Basalt"
    },
    {
      "x": 0,
      "y": 18,
      "z": -5,
      "name": "Ore_Iron_Basalt_Cracked"
    },
    {
      "x": 0,
      "y": 19,
      "z": -5,
      "name": "Soil_Ash"
    },
    {
      "x": 0,
      "y": 21,
      "z": -5,
      "name": "Deco_SpiderWeb_Flat",
      "rotation": 6
    },
    {
      "x": 0,
      "y": 32,
      "z": -5,
      "name": "Wood_Ash_Trunk_Full"
    },
    {
      "x": 0,
      "y": 33,
      "z": -5,
      "name": "Wood_Ash_Trunk_Full"
    },
    {
      "x": 0,
      "y": 10,
      "z": -4,
      "name": "Rock_Basalt"
    },
    {
      "x": 0,
      "y": 11,
      "z": -4,
      "name": "Rock_Basalt"
    },
    {
      "x": 0,
      "y": 12,
      "z": -4,
      "name": "Ore_Iron_Basalt_Cracked"
    },
    {
      "x": 0,
      "y": 13,
      "z": -4,
      "name": "Ore_Iron_Basalt_Cracked"
    },
    {
      "x": 0,
      "y": 14,
      "z": -4,
      "name": "Rock_Basalt"
    },
    {
      "x": 0,
      "y": 15,
      "z": -4,
      "name": "Rock_Basalt"
    },
    {
      "x": 0,
      "y": 16,
      "z": -4,
      "name": "Rock_Basalt"
    },
    {
      "x": 0,
      "y": 17,
      "z": -4,
      "name": "Rock_Basalt"
    },
    {
      "x": 0,
      "y": 18,
      "z": -4,
      "name": "Ore_Iron_Basalt_Cracked"
    },
    {
      "x": 0,
      "y": 19,
      "z": -4,
      "name": "Soil_Ash"
    },
    {
      "x": 0,
      "y": 21,
      "z": -4,
      "name": "Wood_Ash_Trunk_Full"
    },
    {
      "x": 0,
      "y": 22,
      "z": -4,
      "name": "Wood_Ash_Trunk_Full"
    },
    {
      "x": 0,
      "y": 30,
      "z": -4,
      "name": "Wood_Ash_Trunk_Full"
    },
    {
      "x": 0,
      "y": 31,
      "z": -4,
      "name": "Wood_Ash_Trunk"
    },
    {
      "x": 0,
      "y": 32,
      "z": -4,
      "name": "Wood_Ash_Trunk_Full"
    },
    {
      "x": 0,
      "y": 11,
      "z": -3,
      "name": "Rock_Basalt"
    },
    {
      "x": 0,
      "y": 12,
      "z": -3,
      "name": "Ore_Iron_Basalt_Cracked"
    },
    {
      "x": 0,
      "y": 13,
      "z": -3,
      "name": "Rock_Basalt"
    },
    {
      "x": 0,
      "y": 14,
      "z": -3,
      "name": "Rock_Basalt"
    },
    {
      "x": 0,
      "y": 15,
      "z": -3,
      "name": "Rock_Basalt"
    },
    {
      "x": 0,
      "y": 16,
      "z": -3,
      "name": "Rock_Basalt"
    },
    {
      "x": 0,
      "y": 17,
      "z": -3,
      "name": "Rock_Basalt"
    },
    {
      "x": 0,
      "y": 18,
      "z": -3,
      "name": "Rock_Basalt"
    },
    {
      "x": 0,
      "y": 19,
      "z": -3,
      "name": "Soil_Sand_Ashen"
    },
    {
      "x": 0,
      "y": 22,
      "z": -3,
      "name": "Wood_Ash_Trunk_Full"
    },
    {
      "x": 0,
      "y": 23,
      "z": -3,
      "name": "Wood_Ash_Trunk_Full"
    },
    {
      "x": 0,
      "y": 29,
      "z": -3,
      "name": "Wood_Ash_Trunk_Full"
    },
    {
      "x": 0,
      "y": 30,
      "z": -3,
      "name": "Wood_Ash_Trunk"
    },
    {
      "x": 0,
      "y": 31,
      "z": -3,
      "name": "Wood_Ash_Trunk"
    },
    {
      "x": 0,
      "y": 32,
      "z": -3,
      "name": "Wood_Ash_Trunk_Full"
    },
    {
      "x": 0,
      "y": 14,
      "z": -2,
      "name": "Rock_Basalt"
    },
    {
      "x": 0,
      "y": 15,
      "z": -2,
      "name": "Rock_Basalt"
    },
    {
      "x": 0,
      "y": 16,
      "z": -2,
      "name": "Rock_Basalt"
    },
    {
      "x": 0,
      "y": 17,
      "z": -2,
      "name": "Rock_Basalt"
    },
    {
      "x": 0,
      "y": 18,
      "z": -2,
      "name": "Rock_Basalt"
    },
    {
      "x": 0,
      "y": 19,
      "z": -2,
      "name": "Soil_Sand_Ashen"
    },
    {
      "x": 0,
      "y": 30,
      "z": -2,
      "name": "Wood_Ash_Trunk_Full"
    },
    {
      "x": 0,
      "y": 31,
      "z": -2,
      "name": "Wood_Ash_Trunk_Full"
    },
    {
      "x": 0,
      "y": 10,
      "z": -1,
      "name": "Rock_Basalt_Stalactite_Small",
      "rotation": 8
    },
    {
      "x": 0,
      "y": 11,
      "z": -1,
      "name": "Rock_Basalt"
    },
    {
      "x": 0,
      "y": 12,
      "z": -1,
      "name": "Rock_Basalt"
    },
    {
      "x": 0,
      "y": 13,
      "z": -1,
      "name": "Ore_Iron_Basalt_Cracked"
    },
    {
      "x": 0,
      "y": 14,
      "z": -1,
      "name": "Rock_Basalt"
    },
    {
      "x": 0,
      "y": 15,
      "z": -1,
      "name": "Rock_Basalt"
    },
    {
      "x": 0,
      "y": 16,
      "z": -1,
      "name": "Rock_Basalt"
    },
    {
      "x": 0,
      "y": 17,
      "z": -1,
      "name": "Rock_Basalt"
    },
    {
      "x": 0,
      "y": 18,
      "z": -1,
      "name": "Rock_Basalt"
    },
    {
      "x": 0,
      "y": 19,
      "z": -1,
      "name": "Soil_Sand_Ashen"
    },
    {
      "x": 0,
      "y": 28,
      "z": -1,
      "name": "Wood_Ash_Branch_Long",
      "rotation": 5
    },
    {
      "x": 0,
      "y": 8,
      "z": 0,
      "name": "Rock_Basalt_Stalactite_Large",
      "filler": 31744,
      "rotation": 8
    },
    {
      "x": 0,
      "y": 9,
      "z": 0,
      "name": "Rock_Basalt_Stalactite_Large",
      "rotation": 8
    },
    {
      "x": 0,
      "y": 10,
      "z": 0,
      "name": "Rock_Basalt"
    },
    {
      "x": 0,
      "y": 11,
      "z": 0,
      "name": "Ore_Iron_Basalt_Cracked"
    },
    {
      "x": 0,
      "y": 12,
      "z": 0,
      "name": "Rock_Basalt"
    },
    {
      "x": 0,
      "y": 13,
      "z": 0,
      "name": "Rock_Basalt"
    },
    {
      "x": 0,
      "y": 14,
      "z": 0,
      "name": "Ore_Iron_Basalt_Cracked"
    },
    {
      "x": 0,
      "y": 15,
      "z": 0,
      "name": "Rock_Basalt"
    },
    {
      "x": 0,
      "y": 16,
      "z": 0,
      "name": "Ore_Iron_Basalt_Cracked"
    },
    {
      "x": 0,
      "y": 17,
      "z": 0,
      "name": "Rock_Basalt"
    },
    {
      "x": 0,
      "y": 18,
      "z": 0,
      "name": "Ore_Iron_Basalt_Cracked"
    },
    {
      "x": 0,
      "y": 19,
      "z": 0,
      "name": "Soil_Sand_Ashen"
    },
    {
      "x": 0,
      "y": 23,
      "z": 0,
      "name": "Wood_Ash_Trunk_Full"
    },
    {
      "x": 0,
      "y": 24,
      "z": 0,
      "name": "Wood_Ash_Trunk"
    },
    {
      "x": 0,
      "y": 25,
      "z": 0,
      "name": "Wood_Ash_Trunk_Full"
    },
    {
      "x": 0,
      "y": 33,
      "z": 0,
      "name": "Wood_Ash_Trunk_Full"
    },
    {
      "x": 0,
      "y": 34,
      "z": 0,
      "name": "Wood_Ash_Trunk_Full"
    },
    {
      "x": 0,
      "y": 9,
      "z": 1,
      "name": "Rock_Basalt"
    },
    {
      "x": 0,
      "y": 10,
      "z": 1,
      "name": "Rock_Basalt"
    },
    {
      "x": 0,
      "y": 11,
      "z": 1,
      "name": "Ore_Iron_Basalt_Cracked"
    },
    {
      "x": 0,
      "y": 12,
      "z": 1,
      "name": "Ore_Iron_Basalt_Cracked"
    },
    {
      "x": 0,
      "y": 13,
      "z": 1,
      "name": "Ore_Iron_Basalt_Cracked"
    },
    {
      "x": 0,
      "y": 14,
      "z": 1,
      "name": "Rock_Basalt"
    },
    {
      "x": 0,
      "y": 15,
      "z": 1,
      "name": "Rock_Basalt"
    },
    {
      "x": 0,
      "y": 16,
      "z": 1,
      "name": "Rock_Basalt"
    },
    {
      "x": 0,
      "y": 17,
      "z": 1,
      "name": "Rock_Basalt"
    },
    {
      "x": 0,
      "y": 18,
      "z": 1,
      "name": "Ore_Iron_Basalt_Cracked"
    },
    {
      "x": 0,
      "y": 19,
      "z": 1,
      "name": "Rock_Basalt"
    },
    {
      "x": 0,
      "y": 20,
      "z": 1,
      "name": "Rock_Basalt"
    },
    {
      "x": 0,
      "y": 21,
      "z": 1,
      "name": "Soil_Sand_Ashen"
    },
    {
      "x": 0,
      "y": 22,
      "z": 1,
      "name": "Wood_Ash_Trunk_Full"
    },
    {
      "x": 0,
      "y": 23,
      "z": 1,
      "name": "Wood_Ash_Trunk_Full"
    },
    {
      "x": 0,
      "y": 31,
      "z": 1,
      "name": "Wood_Ash_Trunk_Full"
    },
    {
      "x": 0,
      "y": 32,
      "z": 1,
      "name": "Wood_Ash_Trunk"
    },
    {
      "x": 0,
      "y": 33,
      "z": 1,
      "name": "Wood_Ash_Trunk"
    },
    {
      "x": 0,
      "y": 34,
      "z": 1,
      "name": "Wood_Ash_Trunk"
    },
    {
      "x": 0,
      "y": 35,
      "z": 1,
      "name": "Wood_Ash_Trunk"
    },
    {
      "x": 0,
      "y": 36,
      "z": 1,
      "name": "Wood_Ash_Trunk_Full"
    },
    {
      "x": 0,
      "y": 39,
      "z": 1,
      "name": "Wood_Ash_Trunk_Full"
    },
    {
      "x": 0,
      "y": 40,
      "z": 1,
      "name": "Wood_Ash_Trunk"
    },
    {
      "x": 0,
      "y": 41,
      "z": 1,
      "name": "Wood_Ash_Trunk_Full"
    },
    {
      "x": 0,
      "y": 10,
      "z": 2,
      "name": "Rock_Basalt"
    },
    {
      "x": 0,
      "y": 11,
      "z": 2,
      "name": "Rock_Basalt"
    },
    {
      "x": 0,
      "y": 12,
      "z": 2,
      "name": "Rock_Basalt"
    },
    {
      "x": 0,
      "y": 13,
      "z": 2,
      "name": "Rock_Basalt"
    },
    {
      "x": 0,
      "y": 14,
      "z": 2,
      "name": "Rock_Basalt"
    },
    {
      "x": 0,
      "y": 15,
      "z": 2,
      "name": "Ore_Iron_Basalt_Cracked"
    },
    {
      "x": 0,
      "y": 16,
      "z": 2,
      "name": "Rock_Basalt"
    },
    {
      "x": 0,
      "y": 17,
      "z": 2,
      "name": "Rock_Basalt"
    },
    {
      "x": 0,
      "y": 18,
      "z": 2,
      "name": "Ore_Iron_Basalt_Cracked"
    },
    {
      "x": 0,
      "y": 19,
      "z": 2,
      "name": "Ore_Iron_Basalt_Cracked"
    },
    {
      "x": 0,
      "y": 20,
      "z": 2,
      "name": "Rock_Basalt"
    },
    {
      "x": 0,
      "y": 21,
      "z": 2,
      "name": "Soil_Sand_Ashen"
    },
    {
      "x": 0,
      "y": 33,
      "z": 2,
      "name": "Wood_Ash_Trunk_Full"
    },
    {
      "x": 0,
      "y": 34,
      "z": 2,
      "name": "Wood_Ash_Trunk"
    },
    {
      "x": 0,
      "y": 35,
      "z": 2,
      "name": "Wood_Ash_Trunk"
    },
    {
      "x": 0,
      "y": 36,
      "z": 2,
      "name": "Wood_Ash_Trunk"
    },
    {
      "x": 0,
      "y": 37,
      "z": 2,
      "name": "Wood_Ash_Trunk"
    },
    {
      "x": 0,
      "y": 38,
      "z": 2,
      "name": "Wood_Ash_Trunk"
    },
    {
      "x": 0,
      "y": 39,
      "z": 2,
      "name": "Wood_Ash_Trunk"
    },
    {
      "x": 0,
      "y": 40,
      "z": 2,
      "name": "Wood_Ash_Trunk_Full"
    },
    {
      "x": 0,
      "y": 11,
      "z": 3,
      "name": "Rock_Basalt"
    },
    {
      "x": 0,
      "y": 12,
      "z": 3,
      "name": "Rock_Basalt"
    },
    {
      "x": 0,
      "y": 13,
      "z": 3,
      "name": "Rock_Basalt"
    },
    {
      "x": 0,
      "y": 14,
      "z": 3,
      "name": "Ore_Iron_Basalt_Cracked"
    },
    {
      "x": 0,
      "y": 15,
      "z": 3,
      "name": "Rock_Basalt"
    },
    {
      "x": 0,
      "y": 16,
      "z": 3,
      "name": "Rock_Basalt"
    },
    {
      "x": 0,
      "y": 17,
      "z": 3,
      "name": "Rock_Basalt"
    },
    {
      "x": 0,
      "y": 18,
      "z": 3,
      "name": "Rock_Basalt"
    },
    {
      "x": 0,
      "y": 19,
      "z": 3,
      "name": "Ore_Iron_Basalt_Cracked"
    },
    {
      "x": 0,
      "y": 20,
      "z": 3,
      "name": "Rock_Basalt"
    },
    {
      "x": 0,
      "y": 21,
      "z": 3,
      "name": "Soil_Sand_Ashen"
    },
    {
      "x": 0,
      "y": 30,
      "z": 3,
      "name": "Wood_Ash_Branch_Corner",
      "rotation": 3
    },
    {
      "x": 0,
      "y": 33,
      "z": 3,
      "name": "Deco_SpiderWeb_Flat",
      "rotation": 7
    },
    {
      "x": 0,
      "y": 34,
      "z": 3,
      "name": "Wood_Ash_Trunk_Full"
    },
    {
      "x": 0,
      "y": 35,
      "z": 3,
      "name": "Wood_Ash_Trunk"
    },
    {
      "x": 0,
      "y": 36,
      "z": 3,
      "name": "Wood_Ash_Trunk"
    },
    {
      "x": 0,
      "y": 37,
      "z": 3,
      "name": "Wood_Ash_Trunk"
    },
    {
      "x": 0,
      "y": 38,
      "z": 3,
      "name": "Wood_Ash_Trunk"
    },
    {
      "x": 0,
      "y": 39,
      "z": 3,
      "name": "Wood_Ash_Trunk_Full"
    },
    {
      "x": 0,
      "y": 15,
      "z": 4,
      "name": "Ore_Iron_Basalt_Cracked"
    },
    {
      "x": 0,
      "y": 16,
      "z": 4,
      "name": "Rock_Basalt"
    },
    {
      "x": 0,
      "y": 17,
      "z": 4,
      "name": "Rock_Basalt"
    },
    {
      "x": 0,
      "y": 18,
      "z": 4,
      "name": "Ore_Iron_Basalt_Cracked"
    },
    {
      "x": 0,
      "y": 19,
      "z": 4,
      "name": "Ore_Iron_Basalt_Cracked"
    },
    {
      "x": 0,
      "y": 36,
      "z": 4,
      "name": "Wood_Ash_Branch_Short"
    },
    {
      "x": 0,
      "y": 32,
      "z": 5,
      "name": "Wood_Ash_Branch_Corner",
      "rotation": 3
    },
    {
      "x": 1,
      "y": 15,
      "z": -12,
      "name": "Rock_Basalt"
    },
    {
      "x": 1,
      "y": 16,
      "z": -12,
      "name": "Ore_Iron_Basalt_Cracked"
    },
    {
      "x": 1,
      "y": 17,
      "z": -12,
      "name": "Ore_Iron_Basalt_Cracked"
    },
    {
      "x": 1,
      "y": 18,
      "z": -12,
      "name": "Soil_Ash"
    },
    {
      "x": 1,
      "y": 11,
      "z": -11,
      "name": "Rock_Basalt"
    },
    {
      "x": 1,
      "y": 12,
      "z": -11,
      "name": "Ore_Iron_Basalt_Cracked"
    },
    {
      "x": 1,
      "y": 13,
      "z": -11,
      "name": "Ore_Iron_Basalt_Cracked"
    },
    {
      "x": 1,
      "y": 14,
      "z": -11,
      "name": "Rock_Basalt"
    },
    {
      "x": 1,
      "y": 15,
      "z": -11,
      "name": "Rock_Basalt"
    },
    {
      "x": 1,
      "y": 16,
      "z": -11,
      "name": "Rock_Basalt"
    },
    {
      "x": 1,
      "y": 17,
      "z": -11,
      "name": "Soil_Sand_Ashen"
    },
    {
      "x": 1,
      "y": 9,
      "z": -10,
      "name": "Rock_Basalt"
    },
    {
      "x": 1,
      "y": 10,
      "z": -10,
      "name": "Rock_Basalt"
    },
    {
      "x": 1,
      "y": 11,
      "z": -10,
      "name": "Ore_Iron_Basalt_Cracked"
    },
    {
      "x": 1,
      "y": 12,
      "z": -10,
      "name": "Ore_Iron_Basalt_Cracked"
    },
    {
      "x": 1,
      "y": 13,
      "z": -10,
      "name": "Ore_Iron_Basalt_Cracked"
    },
    {
      "x": 1,
      "y": 14,
      "z": -10,
      "name": "Ore_Iron_Basalt_Cracked"
    },
    {
      "x": 1,
      "y": 15,
      "z": -10,
      "name": "Rock_Basalt"
    },
    {
      "x": 1,
      "y": 16,
      "z": -10,
      "name": "Rock_Basalt"
    },
    {
      "x": 1,
      "y": 17,
      "z": -10,
      "name": "Rock_Basalt"
    },
    {
      "x": 1,
      "y": 18,
      "z": -10,
      "name": "Soil_Sand_Ashen"
    },
    {
      "x": 1,
      "y": 9,
      "z": -9,
      "name": "Rock_Basalt"
    },
    {
      "x": 1,
      "y": 10,
      "z": -9,
      "name": "Rock_Basalt"
    },
    {
      "x": 1,
      "y": 11,
      "z": -9,
      "name": "Rock_Basalt"
    },
    {
      "x": 1,
      "y": 12,
      "z": -9,
      "name": "Rock_Basalt"
    },
    {
      "x": 1,
      "y": 13,
      "z": -9,
      "name": "Rock_Basalt"
    },
    {
      "x": 1,
      "y": 14,
      "z": -9,
      "name": "Ore_Iron_Basalt_Cracked"
    },
    {
      "x": 1,
      "y": 15,
      "z": -9,
      "name": "Rock_Basalt"
    },
    {
      "x": 1,
      "y": 16,
      "z": -9,
      "name": "Ore_Iron_Basalt_Cracked"
    },
    {
      "x": 1,
      "y": 17,
      "z": -9,
      "name": "Rock_Basalt"
    },
    {
      "x": 1,
      "y": 18,
      "z": -9,
      "name": "Soil_Sand_Ashen"
    },
    {
      "x": 1,
      "y": 9,
      "z": -8,
      "name": "Ore_Iron_Basalt_Cracked"
    },
    {
      "x": 1,
      "y": 10,
      "z": -8,
      "name": "Rock_Basalt"
    },
    {
      "x": 1,
      "y": 11,
      "z": -8,
      "name": "Rock_Basalt"
    },
    {
      "x": 1,
      "y": 12,
      "z": -8,
      "name": "Rock_Basalt"
    },
    {
      "x": 1,
      "y": 13,
      "z": -8,
      "name": "Rock_Basalt"
    },
    {
      "x": 1,
      "y": 14,
      "z": -8,
      "name": "Rock_Basalt"
    },
    {
      "x": 1,
      "y": 15,
      "z": -8,
      "name": "Rock_Basalt"
    },
    {
      "x": 1,
      "y": 16,
      "z": -8,
      "name": "Ore_Iron_Basalt_Cracked"
    },
    {
      "x": 1,
      "y": 17,
      "z": -8,
      "name": "Ore_Iron_Basalt"
    },
    {
      "x": 1,
      "y": 18,
      "z": -8,
      "name": "Ore_Iron_Basalt_Cracked"
    },
    {
      "x": 1,
      "y": 19,
      "z": -8,
      "name": "Soil_Sand_Ashen"
    },
    {
      "x": 1,
      "y": 9,
      "z": -7,
      "name": "Rock_Basalt"
    },
    {
      "x": 1,
      "y": 10,
      "z": -7,
      "name": "Ore_Iron_Basalt_Cracked"
    },
    {
      "x": 1,
      "y": 11,
      "z": -7,
      "name": "Rock_Basalt"
    },
    {
      "x": 1,
      "y": 12,
      "z": -7,
      "name": "Rock_Basalt"
    },
    {
      "x": 1,
      "y": 13,
      "z": -7,
      "name": "Ore_Iron_Basalt_Cracked"
    },
    {
      "x": 1,
      "y": 14,
      "z": -7,
      "name": "Rock_Basalt"
    },
    {
      "x": 1,
      "y": 15,
      "z": -7,
      "name": "Rock_Basalt"
    },
    {
      "x": 1,
      "y": 16,
      "z": -7,
      "name": "Rock_Basalt"
    },
    {
      "x": 1,
      "y": 17,
      "z": -7,
      "name": "Rock_Basalt"
    },
    {
      "x": 1,
      "y": 18,
      "z": -7,
      "name": "Rock_Basalt"
    },
    {
      "x": 1,
      "y": 19,
      "z": -7,
      "name": "Soil_Ash"
    },
    {
      "x": 1,
      "y": 20,
      "z": -7,
      "name": "Deco_SpiderWeb_Flat"
    },
    {
      "x": 1,
      "y": 7,
      "z": -6,
      "name": "Rock_Basalt_Stalactite_Large",
      "filler": 31744,
      "rotation": 8
    },
    {
      "x": 1,
      "y": 8,
      "z": -6,
      "name": "Rock_Basalt_Stalactite_Large",
      "rotation": 8
    },
    {
      "x": 1,
      "y": 9,
      "z": -6,
      "name": "Ore_Iron_Basalt_Cracked"
    },
    {
      "x": 1,
      "y": 10,
      "z": -6,
      "name": "Rock_Basalt"
    },
    {
      "x": 1,
      "y": 11,
      "z": -6,
      "name": "Ore_Iron_Basalt_Cracked"
    },
    {
      "x": 1,
      "y": 12,
      "z": -6,
      "name": "Rock_Basalt"
    },
    {
      "x": 1,
      "y": 13,
      "z": -6,
      "name": "Rock_Basalt"
    },
    {
      "x": 1,
      "y": 14,
      "z": -6,
      "name": "Ore_Iron_Basalt_Cracked"
    },
    {
      "x": 1,
      "y": 15,
      "z": -6,
      "name": "Ore_Iron_Basalt_Cracked"
    },
    {
      "x": 1,
      "y": 16,
      "z": -6,
      "name": "Rock_Basalt"
    },
    {
      "x": 1,
      "y": 17,
      "z": -6,
      "name": "Ore_Iron_Basalt_Cracked"
    },
    {
      "x": 1,
      "y": 18,
      "z": -6,
      "name": "Rock_Basalt"
    },
    {
      "x": 1,
      "y": 19,
      "z": -6,
      "name": "Soil_Ash"
    },
    {
      "x": 1,
      "y": 7,
      "z": -5,
      "name": "Rock_Basalt"
    },
    {
      "x": 1,
      "y": 8,
      "z": -5,
      "name": "Ore_Iron_Basalt_Cracked"
    },
    {
      "x": 1,
      "y": 9,
      "z": -5,
      "name": "Rock_Basalt"
    },
    {
      "x": 1,
      "y": 10,
      "z": -5,
      "name": "Rock_Basalt"
    },
    {
      "x": 1,
      "y": 11,
      "z": -5,
      "name": "Rock_Basalt"
    },
    {
      "x": 1,
      "y": 12,
      "z": -5,
      "name": "Rock_Basalt"
    },
    {
      "x": 1,
      "y": 13,
      "z": -5,
      "name": "Rock_Basalt"
    },
    {
      "x": 1,
      "y": 14,
      "z": -5,
      "name": "Rock_Basalt"
    },
    {
      "x": 1,
      "y": 15,
      "z": -5,
      "name": "Ore_Iron_Basalt_Cracked"
    },
    {
      "x": 1,
      "y": 16,
      "z": -5,
      "name": "Rock_Basalt"
    },
    {
      "x": 1,
      "y": 17,
      "z": -5,
      "name": "Ore_Iron_Basalt"
    },
    {
      "x": 1,
      "y": 18,
      "z": -5,
      "name": "Ore_Iron_Basalt_Cracked"
    },
    {
      "x": 1,
      "y": 19,
      "z": -5,
      "name": "Soil_Sand_Ashen"
    },
    {
      "x": 1,
      "y": 6,
      "z": -4,
      "name": "Rock_Basalt"
    },
    {
      "x": 1,
      "y": 7,
      "z": -4,
      "name": "Rock_Basalt"
    },
    {
      "x": 1,
      "y": 8,
      "z": -4,
      "name": "Rock_Basalt"
    },
    {
      "x": 1,
      "y": 9,
      "z": -4,
      "name": "Rock_Basalt"
    },
    {
      "x": 1,
      "y": 10,
      "z": -4,
      "name": "Rock_Basalt"
    },
    {
      "x": 1,
      "y": 11,
      "z": -4,
      "name": "Rock_Basalt"
    },
    {
      "x": 1,
      "y": 12,
      "z": -4,
      "name": "Rock_Basalt"
    },
    {
      "x": 1,
      "y": 13,
      "z": -4,
      "name": "Rock_Basalt"
    },
    {
      "x": 1,
      "y": 14,
      "z": -4,
      "name": "Rock_Basalt"
    },
    {
      "x": 1,
      "y": 15,
      "z": -4,
      "name": "Ore_Iron_Basalt_Cracked"
    },
    {
      "x": 1,
      "y": 16,
      "z": -4,
      "name": "Rock_Basalt"
    },
    {
      "x": 1,
      "y": 17,
      "z": -4,
      "name": "Rock_Basalt"
    },
    {
      "x": 1,
      "y": 18,
      "z": -4,
      "name": "Rock_Basalt"
    },
    {
      "x": 1,
      "y": 19,
      "z": -4,
      "name": "Wood_Ash_Roots"
    },
    {
      "x": 1,
      "y": 20,
      "z": -4,
      "name": "Wood_Ash_Trunk_Full"
    },
    {
      "x": 1,
      "y": 21,
      "z": -4,
      "name": "Wood_Ash_Trunk_Full"
    },
    {
      "x": 1,
      "y": 28,
      "z": -4,
      "name": "Deco_SpiderWeb_Flat",
      "rotation": 6
    },
    {
      "x": 1,
      "y": 30,
      "z": -4,
      "name": "Wood_Ash_Trunk_Full"
    },
    {
      "x": 1,
      "y": 31,
      "z": -4,
      "name": "Wood_Ash_Trunk"
    },
    {
      "x": 1,
      "y": 32,
      "z": -4,
      "name": "Wood_Ash_Trunk_Full"
    },
    {
      "x": 1,
      "y": 7,
      "z": -3,
      "name": "Rock_Basalt"
    },
    {
      "x": 1,
      "y": 8,
      "z": -3,
      "name": "Rock_Basalt"
    },
    {
      "x": 1,
      "y": 9,
      "z": -3,
      "name": "Rock_Basalt"
    },
    {
      "x": 1,
      "y": 10,
      "z": -3,
      "name": "Rock_Basalt"
    },
    {
      "x": 1,
      "y": 11,
      "z": -3,
      "name": "Ore_Iron_Basalt_Cracked"
    },
    {
      "x": 1,
      "y": 12,
      "z": -3,
      "name": "Ore_Iron_Basalt_Cracked"
    },
    {
      "x": 1,
      "y": 13,
      "z": -3,
      "name": "Ore_Iron_Basalt_Cracked"
    },
    {
      "x": 1,
      "y": 14,
      "z": -3,
      "name": "Ore_Iron_Basalt_Cracked"
    },
    {
      "x": 1,
      "y": 15,
      "z": -3,
