{
  "version": 8,
  "blockIdVersion": 11,
  "anchorX": 0,
  "anchorY": 0,
  "anchorZ": 0,
  "blocks": [
    {
      "x": -19,
      "y": 15,
      "z": 13,
      "name": "Rock_Basalt"
    },
    {
      "x": -19,
      "y": 16,
      "z": 13,
      "name": "Ore_Iron_Basalt"
    },
    {
      "x": -19,
      "y": 17,
      "z": 13,
      "name": "Ore_Iron_Basalt_Cracked"
    },
    {
      "x": -19,
      "y": 18,
      "z": 13,
      "name": "Soil_Ash"
    },
    {
      "x": -19,
      "y": 14,
      "z": 14,
      "name": "Rock_Basalt"
    },
    {
      "x": -19,
      "y": 15,
      "z": 14,
      "name": "Rock_Basalt"
    },
    {
      "x": -19,
      "y": 16,
      "z": 14,
      "name": "Ore_Iron_Basalt_Cracked"
    },
    {
      "x": -19,
      "y": 17,
      "z": 14,
      "name": "Ore_Iron_Basalt_Cracked"
    },
    {
      "x": -19,
      "y": 18,
      "z": 14,
      "name": "Soil_Ash"
    },
    {
      "x": -19,
      "y": 15,
      "z": 15,
      "name": "Ore_Iron_Basalt_Cracked"
    },
    {
      "x": -19,
      "y": 16,
      "z": 15,
      "name": "Ore_Iron_Basalt_Cracked"
    },
    {
      "x": -19,
      "y": 17,
      "z": 15,
      "name": "Ore_Iron_Basalt_Cracked"
    },
    {
      "x": -19,
      "y": 18,
      "z": 15,
      "name": "Soil_Ash"
    },
    {
      "x": -18,
      "y": 13,
      "z": 12,
      "name": "Ore_Iron_Basalt_Cracked"
    },
    {
      "x": -18,
      "y": 14,
      "z": 12,
      "name": "Rock_Basalt"
    },
    {
      "x": -18,
      "y": 15,
      "z": 12,
      "name": "Rock_Basalt"
    },
    {
      "x": -18,
      "y": 16,
      "z": 12,
      "name": "Rock_Basalt"
    },
    {
      "x": -18,
      "y": 17,
      "z": 12,
      "name": "Soil_Ash"
    },
    {
      "x": -18,
      "y": 11,
      "z": 13,
      "name": "Ore_Iron_Basalt_Cracked"
    },
    {
      "x": -18,
      "y": 12,
      "z": 13,
      "name": "Rock_Basalt"
    },
    {
      "x": -18,
      "y": 13,
      "z": 13,
      "name": "Rock_Basalt"
    },
    {
      "x": -18,
      "y": 14,
      "z": 13,
      "name": "Rock_Basalt"
    },
    {
      "x": -18,
      "y": 15,
      "z": 13,
      "name": "Ore_Iron_Basalt_Cracked"
    },
    {
      "x": -18,
      "y": 16,
      "z": 13,
      "name": "Ore_Iron_Basalt_Cracked"
    },
    {
      "x": -18,
      "y": 17,
      "z": 13,
      "name": "Soil_Ash"
    },
    {
      "x": -18,
      "y": 10,
      "z": 14,
      "name": "Rock_Basalt"
    },
    {
      "x": -18,
      "y": 11,
      "z": 14,
      "name": "Rock_Basalt"
    },
    {
      "x": -18,
      "y": 12,
      "z": 14,
      "name": "Ore_Iron_Basalt_Cracked"
    },
    {
      "x": -18,
      "y": 13,
      "z": 14,
      "name": "Rock_Basalt"
    },
    {
      "x": -18,
      "y": 14,
      "z": 14,
      "name": "Rock_Basalt"
    },
    {
      "x": -18,
      "y": 15,
      "z": 14,
      "name": "Rock_Basalt"
    },
    {
      "x": -18,
      "y": 16,
      "z": 14,
      "name": "Rock_Basalt"
    },
    {
      "x": -18,
      "y": 17,
      "z": 14,
      "name": "Soil_Ash"
    },
    {
      "x": -18,
      "y": 18,
      "z": 14,
      "name": "Plant_Bush_Dead_Twisted"
    },
    {
      "x": -18,
      "y": 11,
      "z": 15,
      "name": "Rock_Basalt"
    },
    {
      "x": -18,
      "y": 12,
      "z": 15,
      "name": "Ore_Iron_Basalt_Cracked"
    },
    {
      "x": -18,
      "y": 13,
      "z": 15,
      "name": "Ore_Iron_Basalt_Cracked"
    },
    {
      "x": -18,
      "y": 14,
      "z": 15,
      "name": "Rock_Basalt"
    },
    {
      "x": -18,
      "y": 15,
      "z": 15,
      "name": "Rock_Basalt"
    },
    {
      "x": -18,
      "y": 16,
      "z": 15,
      "name": "Ore_Iron_Basalt_Cracked"
    },
    {
      "x": -18,
      "y": 17,
      "z": 15,
      "name": "Ore_Iron_Basalt_Cracked"
    },
    {
      "x": -18,
      "y": 18,
      "z": 15,
      "name": "Soil_Ash"
    },
    {
      "x": -18,
      "y": 13,
      "z": 16,
      "name": "Ore_Iron_Basalt_Cracked"
    },
    {
      "x": -18,
      "y": 14,
      "z": 16,
      "name": "Rock_Basalt"
    },
    {
      "x": -18,
      "y": 15,
      "z": 16,
      "name": "Rock_Basalt"
    },
    {
      "x": -18,
      "y": 16,
      "z": 16,
      "name": "Ore_Iron_Basalt_Cracked"
    },
    {
      "x": -18,
      "y": 17,
      "z": 16,
      "name": "Rock_Basalt"
    },
    {
      "x": -18,
      "y": 18,
      "z": 16,
      "name": "Soil_Ash"
    },
    {
      "x": -17,
      "y": 27,
      "z": 10,
      "name": "Wood_Ash_Branch_Short",
      "rotation": 3
    },
    {
      "x": -17,
      "y": 14,
      "z": 11,
      "name": "Rock_Basalt"
    },
    {
      "x": -17,
      "y": 15,
      "z": 11,
      "name": "Rock_Basalt"
    },
    {
      "x": -17,
      "y": 16,
      "z": 11,
      "name": "Soil_Ash"
    },
    {
      "x": -17,
      "y": 11,
      "z": 12,
      "name": "Ore_Iron_Basalt_Cracked"
    },
    {
      "x": -17,
      "y": 12,
      "z": 12,
      "name": "Ore_Iron_Basalt_Cracked"
    },
    {
      "x": -17,
      "y": 13,
      "z": 12,
      "name": "Rock_Basalt"
    },
    {
      "x": -17,
      "y": 14,
      "z": 12,
      "name": "Ore_Iron_Basalt_Cracked"
    },
    {
      "x": -17,
      "y": 15,
      "z": 12,
      "name": "Ore_Iron_Basalt_Cracked"
    },
    {
      "x": -17,
      "y": 16,
      "z": 12,
      "name": "Rock_Basalt"
    },
    {
      "x": -17,
      "y": 17,
      "z": 12,
      "name": "Soil_Ash"
    },
    {
      "x": -17,
      "y": 9,
      "z": 13,
      "name": "Rock_Basalt"
    },
    {
      "x": -17,
      "y": 10,
      "z": 13,
      "name": "Ore_Iron_Basalt_Cracked"
    },
    {
      "x": -17,
      "y": 11,
      "z": 13,
      "name": "Ore_Iron_Basalt_Cracked"
    },
    {
      "x": -17,
      "y": 12,
      "z": 13,
      "name": "Rock_Basalt"
    },
    {
      "x": -17,
      "y": 13,
      "z": 13,
      "name": "Rock_Basalt"
    },
    {
      "x": -17,
      "y": 14,
      "z": 13,
      "name": "Rock_Basalt"
    },
    {
      "x": -17,
      "y": 15,
      "z": 13,
      "name": "Rock_Basalt"
    },
    {
      "x": -17,
      "y": 16,
      "z": 13,
      "name": "Ore_Iron_Basalt_Cracked"
    },
    {
      "x": -17,
      "y": 17,
      "z": 13,
      "name": "Ore_Iron_Basalt_Cracked"
    },
    {
      "x": -17,
      "y": 18,
      "z": 13,
      "name": "Soil_Ash"
    },
    {
      "x": -17,
      "y": 9,
      "z": 14,
      "name": "Rock_Basalt"
    },
    {
      "x": -17,
      "y": 10,
      "z": 14,
      "name": "Rock_Basalt"
    },
    {
      "x": -17,
      "y": 11,
      "z": 14,
      "name": "Rock_Basalt"
    },
    {
      "x": -17,
      "y": 12,
      "z": 14,
      "name": "Rock_Basalt"
    },
    {
      "x": -17,
      "y": 13,
      "z": 14,
      "name": "Rock_Basalt"
    },
    {
      "x": -17,
      "y": 14,
      "z": 14,
      "name": "Rock_Basalt"
    },
    {
      "x": -17,
      "y": 15,
      "z": 14,
      "name": "Rock_Basalt"
    },
    {
      "x": -17,
      "y": 16,
      "z": 14,
      "name": "Rock_Basalt"
    },
    {
      "x": -17,
      "y": 17,
      "z": 14,
      "name": "Rock_Basalt"
    },
    {
      "x": -17,
      "y": 18,
      "z": 14,
      "name": "Soil_Ash"
    },
    {
      "x": -17,
      "y": 9,
      "z": 15,
      "name": "Rock_Basalt"
    },
    {
      "x": -17,
      "y": 10,
      "z": 15,
      "name": "Rock_Basalt"
    },
    {
      "x": -17,
      "y": 11,
      "z": 15,
      "name": "Rock_Basalt"
    },
    {
      "x": -17,
      "y": 12,
      "z": 15,
      "name": "Rock_Basalt"
    },
    {
      "x": -17,
      "y": 13,
      "z": 15,
      "name": "Ore_Iron_Basalt_Cracked"
    },
    {
      "x": -17,
      "y": 14,
      "z": 15,
      "name": "Rock_Basalt"
    },
    {
      "x": -17,
      "y": 15,
      "z": 15,
      "name": "Ore_Iron_Basalt_Cracked"
    },
    {
      "x": -17,
      "y": 16,
      "z": 15,
      "name": "Rock_Basalt"
    },
    {
      "x": -17,
      "y": 17,
      "z": 15,
      "name": "Rock_Basalt"
    },
    {
      "x": -17,
      "y": 18,
      "z": 15,
      "name": "Soil_Ash"
    },
    {
      "x": -17,
      "y": 11,
      "z": 16,
      "name": "Ore_Iron_Basalt_Cracked"
    },
    {
      "x": -17,
      "y": 12,
      "z": 16,
      "name": "Rock_Basalt"
    },
    {
      "x": -17,
      "y": 13,
      "z": 16,
      "name": "Rock_Basalt"
    },
    {
      "x": -17,
      "y": 14,
      "z": 16,
      "name": "Rock_Basalt"
    },
    {
      "x": -17,
      "y": 15,
      "z": 16,
      "name": "Rock_Basalt"
    },
    {
      "x": -17,
      "y": 16,
      "z": 16,
      "name": "Ore_Iron_Basalt_Cracked"
    },
    {
      "x": -17,
      "y": 17,
      "z": 16,
      "name": "Rock_Basalt"
    },
    {
      "x": -17,
      "y": 18,
      "z": 16,
      "name": "Soil_Ash"
    },
    {
      "x": -17,
      "y": 19,
      "z": 16,
      "name": "Plant_Bush_Dead_Twisted"
    },
    {
      "x": -17,
      "y": 15,
      "z": 17,
      "name": "Ore_Iron_Basalt_Cracked"
    },
    {
      "x": -17,
      "y": 16,
      "z": 17,
      "name": "Rock_Basalt"
    },
    {
      "x": -17,
      "y": 17,
      "z": 17,
      "name": "Rock_Basalt"
    },
    {
      "x": -17,
      "y": 18,
      "z": 17,
      "name": "Soil_Ash"
    },
    {
      "x": -17,
      "y": 18,
      "z": 18,
      "name": "Plant_Vine_Wall_Dead"
    },
    {
      "x": -16,
      "y": 28,
      "z": 5,
      "name": "Wood_Ash_Branch_Corner",
      "rotation": 3
    },
    {
      "x": -16,
      "y": 23,
      "z": 7,
      "name": "Wood_Ash_Branch_Corner",
      "rotation": 3
    },
    {
      "x": -16,
      "y": 9,
      "z": 8,
      "name": "Rock_Basalt"
    },
    {
      "x": -16,
      "y": 10,
      "z": 8,
      "name": "Ore_Iron_Basalt_Cracked"
    },
    {
      "x": -16,
      "y": 11,
      "z": 8,
      "name": "Rock_Basalt"
    },
    {
      "x": -16,
      "y": 12,
      "z": 8,
      "name": "Rock_Basalt"
    },
    {
      "x": -16,
      "y": 13,
      "z": 8,
      "name": "Soil_Ash"
    },
    {
      "x": -16,
      "y": 14,
      "z": 8,
      "name": "Soil_Ash"
    },
    {
      "x": -16,
      "y": 8,
      "z": 9,
      "name": "Rock_Basalt"
    },
    {
      "x": -16,
      "y": 9,
      "z": 9,
      "name": "Ore_Iron_Basalt_Cracked"
    },
    {
      "x": -16,
      "y": 10,
      "z": 9,
      "name": "Rock_Basalt"
    },
    {
      "x": -16,
      "y": 11,
      "z": 9,
      "name": "Rock_Basalt"
    },
    {
      "x": -16,
      "y": 12,
      "z": 9,
      "name": "Rock_Basalt"
    },
    {
      "x": -16,
      "y": 13,
      "z": 9,
      "name": "Rock_Basalt"
    },
    {
      "x": -16,
      "y": 14,
      "z": 9,
      "name": "Soil_Ash"
    },
    {
      "x": -16,
      "y": 15,
      "z": 9,
      "name": "Soil_Ash"
    },
    {
      "x": -16,
      "y": 25,
      "z": 9,
      "name": "Wood_Ash_Trunk_Full"
    },
    {
      "x": -16,
      "y": 26,
      "z": 9,
      "name": "Wood_Ash_Trunk_Full"
    },
    {
      "x": -16,
      "y": 9,
      "z": 10,
      "name": "Ore_Iron_Basalt_Cracked"
    },
    {
      "x": -16,
      "y": 10,
      "z": 10,
      "name": "Rock_Basalt"
    },
    {
      "x": -16,
      "y": 11,
      "z": 10,
      "name": "Rock_Basalt"
    },
    {
      "x": -16,
      "y": 12,
      "z": 10,
      "name": "Rock_Basalt"
    },
    {
      "x": -16,
      "y": 13,
      "z": 10,
      "name": "Rock_Basalt"
    },
    {
      "x": -16,
      "y": 14,
      "z": 10,
      "name": "Rock_Basalt"
    },
    {
      "x": -16,
      "y": 15,
      "z": 10,
      "name": "Rock_Basalt"
    },
    {
      "x": -16,
      "y": 16,
      "z": 10,
      "name": "Soil_Ash"
    },
    {
      "x": -16,
      "y": 26,
      "z": 10,
      "name": "Wood_Ash_Trunk_Full"
    },
    {
      "x": -16,
      "y": 27,
      "z": 10,
      "name": "Wood_Ash_Trunk"
    },
    {
      "x": -16,
      "y": 28,
      "z": 10,
      "name": "Wood_Ash_Trunk"
    },
    {
      "x": -16,
      "y": 29,
      "z": 10,
      "name": "Wood_Ash_Trunk"
    },
    {
      "x": -16,
      "y": 30,
      "z": 10,
      "name": "Wood_Ash_Trunk_Full"
    },
    {
      "x": -16,
      "y": 10,
      "z": 11,
      "name": "Ore_Iron_Basalt_Cracked"
    },
    {
      "x": -16,
      "y": 11,
      "z": 11,
      "name": "Rock_Basalt"
    },
    {
      "x": -16,
      "y": 12,
      "z": 11,
      "name": "Rock_Basalt"
    },
    {
      "x": -16,
      "y": 13,
      "z": 11,
      "name": "Rock_Basalt"
    },
    {
      "x": -16,
      "y": 14,
      "z": 11,
      "name": "Ore_Iron_Basalt_Cracked"
    },
    {
      "x": -16,
      "y": 15,
      "z": 11,
      "name": "Rock_Basalt"
    },
    {
      "x": -16,
      "y": 16,
      "z": 11,
      "name": "Soil_Ash"
    },
    {
      "x": -16,
      "y": 28,
      "z": 11,
      "name": "Wood_Ash_Trunk_Full"
    },
    {
      "x": -16,
      "y": 29,
      "z": 11,
      "name": "Wood_Ash_Trunk_Full"
    },
    {
      "x": -16,
      "y": 30,
      "z": 11,
      "name": "Wood_Ash_Trunk"
    },
    {
      "x": -16,
      "y": 31,
      "z": 11,
      "name": "Wood_Ash_Trunk"
    },
    {
      "x": -16,
      "y": 32,
      "z": 11,
      "name": "Wood_Ash_Trunk_Full"
    },
    {
      "x": -16,
      "y": 9,
      "z": 12,
      "name": "Rock_Basalt"
    },
    {
      "x": -16,
      "y": 10,
      "z": 12,
      "name": "Rock_Basalt"
    },
    {
      "x": -16,
      "y": 11,
      "z": 12,
      "name": "Ore_Iron_Basalt_Cracked"
    },
    {
      "x": -16,
      "y": 12,
      "z": 12,
      "name": "Rock_Basalt"
    },
    {
      "x": -16,
      "y": 13,
      "z": 12,
      "name": "Rock_Basalt"
    },
    {
      "x": -16,
      "y": 14,
      "z": 12,
      "name": "Ore_Iron_Basalt_Cracked"
    },
    {
      "x": -16,
      "y": 15,
      "z": 12,
      "name": "Rock_Basalt"
    },
    {
      "x": -16,
      "y": 16,
      "z": 12,
      "name": "Ore_Iron_Basalt_Cracked"
    },
    {
      "x": -16,
      "y": 17,
      "z": 12,
      "name": "Soil_Ash"
    },
    {
      "x": -16,
      "y": 9,
      "z": 13,
      "name": "Ore_Iron_Basalt_Cracked"
    },
    {
      "x": -16,
      "y": 10,
      "z": 13,
      "name": "Ore_Iron_Basalt_Cracked"
    },
    {
      "x": -16,
      "y": 11,
      "z": 13,
      "name": "Ore_Iron_Basalt_Cracked"
    },
    {
      "x": -16,
      "y": 12,
      "z": 13,
      "name": "Rock_Basalt"
    },
    {
      "x": -16,
      "y": 13,
      "z": 13,
      "name": "Rock_Basalt"
    },
    {
      "x": -16,
      "y": 14,
      "z": 13,
      "name": "Rock_Basalt"
    },
    {
      "x": -16,
      "y": 15,
      "z": 13,
      "name": "Ore_Iron_Basalt_Cracked"
    },
    {
      "x": -16,
      "y": 16,
      "z": 13,
      "name": "Ore_Iron_Basalt_Cracked"
    },
    {
      "x": -16,
      "y": 17,
      "z": 13,
      "name": "Rock_Basalt"
    },
    {
      "x": -16,
      "y": 18,
      "z": 13,
      "name": "Soil_Ash"
    },
    {
      "x": -16,
      "y": 8,
      "z": 14,
      "name": "Rock_Crystal_Purple_Medium",
      "rotation": 7
    },
    {
      "x": -16,
      "y": 9,
      "z": 14,
      "name": "Rock_Basalt"
    },
    {
      "x": -16,
      "y": 10,
      "z": 14,
      "name": "Rock_Basalt"
    },
    {
      "x": -16,
      "y": 11,
      "z": 14,
      "name": "Rock_Basalt"
    },
    {
      "x": -16,
      "y": 12,
      "z": 14,
      "name": "Ore_Iron_Basalt_Cracked"
    },
    {
      "x": -16,
      "y": 13,
      "z": 14,
      "name": "Ore_Iron_Basalt_Cracked"
    },
    {
      "x": -16,
      "y": 14,
      "z": 14,
      "name": "Ore_Iron_Basalt_Cracked"
    },
    {
      "x": -16,
      "y": 15,
      "z": 14,
      "name": "Rock_Basalt"
    },
    {
      "x": -16,
      "y": 16,
      "z": 14,
      "name": "Ore_Iron_Basalt_Cracked"
    },
    {
      "x": -16,
      "y": 17,
      "z": 14,
      "name": "Ore_Iron_Basalt_Cracked"
    },
    {
      "x": -16,
      "y": 18,
      "z": 14,
      "name": "Soil_Ash"
    },
    {
      "x": -16,
      "y": 9,
      "z": 15,
      "name": "Rock_Basalt"
    },
    {
      "x": -16,
      "y": 10,
      "z": 15,
      "name": "Rock_Basalt"
    },
    {
      "x": -16,
      "y": 11,
      "z": 15,
      "name": "Rock_Basalt"
    },
    {
      "x": -16,
      "y": 12,
      "z": 15,
      "name": "Rock_Basalt"
    },
    {
      "x": -16,
      "y": 13,
      "z": 15,
      "name": "Ore_Iron_Basalt_Cracked"
    },
    {
      "x": -16,
      "y": 14,
      "z": 15,
      "name": "Rock_Basalt"
    },
    {
      "x": -16,
      "y": 15,
      "z": 15,
      "name": "Rock_Basalt"
    },
    {
      "x": -16,
      "y": 16,
      "z": 15,
      "name": "Ore_Iron_Basalt_Cracked"
    },
    {
      "x": -16,
      "y": 17,
      "z": 15,
      "name": "Ore_Iron_Basalt_Cracked"
    },
    {
      "x": -16,
      "y": 18,
      "z": 15,
      "name": "Soil_Ash"
    },
    {
      "x": -16,
      "y": 10,
      "z": 16,
      "name": "Rock_Basalt"
    },
    {
      "x": -16,
      "y": 11,
      "z": 16,
      "name": "Ore_Iron_Basalt_Cracked"
    },
    {
      "x": -16,
      "y": 12,
      "z": 16,
      "name": "Ore_Iron_Basalt_Cracked"
    },
    {
      "x": -16,
      "y": 13,
      "z": 16,
      "name": "Ore_Iron_Basalt_Cracked"
    },
    {
      "x": -16,
      "y": 14,
      "z": 16,
      "name": "Ore_Iron_Basalt_Cracked"
    },
    {
      "x": -16,
      "y": 15,
      "z": 16,
      "name": "Rock_Basalt"
    },
    {
      "x": -16,
      "y": 16,
      "z": 16,
      "name": "Rock_Basalt"
    },
    {
      "x": -16,
      "y": 17,
      "z": 16,
      "name": "Rock_Basalt"
    },
    {
      "x": -16,
      "y": 18,
      "z": 16,
      "name": "Soil_Ash"
    },
    {
      "x": -16,
      "y": 19,
      "z": 16,
      "name": "Plant_Bush_Dead_Twisted"
    },
    {
      "x": -16,
      "y": 14,
      "z": 17,
      "name": "Rock_Basalt"
    },
    {
      "x": -16,
      "y": 15,
      "z": 17,
      "name": "Ore_Iron_Basalt_Cracked"
    },
    {
      "x": -16,
      "y": 16,
      "z": 17,
      "name": "Ore_Iron_Basalt_Cracked"
    },
    {
      "x": -16,
      "y": 17,
      "z": 17,
      "name": "Rock_Basalt"
    },
    {
      "x": -16,
      "y": 18,
      "z": 17,
      "name": "Soil_Ash"
    },
    {
      "x": -16,
      "y": 19,
      "z": 17,
      "name": "Plant_Bush_Dead_Twisted"
    },
    {
      "x": -16,
      "y": 18,
      "z": 18,
      "name": "Plant_Vine_Wall_Dead"
    },
    {
      "x": -15,
      "y": 27,
      "z": 4,
      "name": "Wood_Ash_Trunk_Full"
    },
    {
      "x": -15,
      "y": 28,
      "z": 4,
      "name": "Wood_Ash_Trunk"
    },
    {
      "x": -15,
      "y": 29,
      "z": 4,
      "name": "Wood_Ash_Trunk"
    },
    {
      "x": -15,
      "y": 30,
      "z": 4,
      "name": "Wood_Ash_Trunk_Full"
    },
    {
      "x": -15,
      "y": 25,
      "z": 5,
      "name": "Wood_Ash_Roots"
    },
    {
      "x": -15,
      "y": 26,
      "z": 5,
      "name": "Wood_Ash_Trunk_Full"
    },
    {
      "x": -15,
      "y": 27,
      "z": 5,
      "name": "Wood_Ash_Trunk"
    },
    {
      "x": -15,
      "y": 28,
      "z": 5,
      "name": "Wood_Ash_Trunk_Full"
    },
    {
      "x": -15,
      "y": 7,
      "z": 7,
      "name": "Rock_Basalt"
    },
    {
      "x": -15,
      "y": 8,
      "z": 7,
      "name": "Rock_Basalt"
    },
    {
      "x": -15,
      "y": 9,
      "z": 7,
      "name": "Rock_Basalt"
    },
    {
      "x": -15,
      "y": 10,
      "z": 7,
      "name": "Ore_Iron_Basalt_Cracked"
    },
    {
      "x": -15,
      "y": 11,
      "z": 7,
      "name": "Rock_Basalt"
    },
    {
      "x": -15,
      "y": 12,
      "z": 7,
      "name": "Rock_Basalt"
    },
    {
      "x": -15,
      "y": 13,
      "z": 7,
      "name": "Rock_Basalt"
    },
    {
      "x": -15,
      "y": 14,
      "z": 7,
      "name": "Rock_Basalt"
    },
    {
      "x": -15,
      "y": 15,
      "z": 7,
      "name": "Ore_Iron_Basalt_Cracked"
    },
    {
      "x": -15,
      "y": 16,
      "z": 7,
      "name": "Rock_Basalt"
    },
    {
      "x": -15,
      "y": 17,
      "z": 7,
      "name": "Soil_Ash"
    },
    {
      "x": -15,
      "y": 23,
      "z": 7,
      "name": "Wood_Ash_Trunk_Full"
    },
    {
      "x": -15,
      "y": 5,
      "z": 8,
      "name": "Ore_Iron_Basalt_Cracked"
    },
    {
      "x": -15,
      "y": 6,
      "z": 8,
      "name": "Rock_Basalt"
    },
    {
      "x": -15,
      "y": 7,
      "z": 8,
      "name": "Ore_Iron_Basalt_Cracked"
    },
    {
      "x": -15,
      "y": 8,
      "z": 8,
      "name": "Ore_Iron_Basalt_Cracked"
    },
    {
      "x": -15,
      "y": 9,
      "z": 8,
      "name": "Rock_Basalt"
    },
    {
      "x": -15,
      "y": 10,
      "z": 8,
      "name": "Ore_Iron_Basalt_Cracked"
    },
    {
      "x": -15,
      "y": 11,
      "z": 8,
      "name": "Rock_Basalt"
    },
    {
      "x": -15,
      "y": 12,
      "z": 8,
      "name": "Rock_Basalt"
    },
    {
      "x": -15,
      "y": 13,
      "z": 8,
      "name": "Rock_Basalt"
    },
    {
      "x": -15,
      "y": 14,
      "z": 8,
      "name": "Ore_Iron_Basalt"
    },
    {
      "x": -15,
      "y": 15,
      "z": 8,
      "name": "Ore_Iron_Basalt_Cracked"
    },
    {
      "x": -15,
      "y": 16,
      "z": 8,
      "name": "Soil_Ash"
    },
    {
      "x": -15,
      "y": 23,
      "z": 8,
      "name": "Wood_Ash_Trunk_Full"
    },
    {
      "x": -15,
      "y": 24,
      "z": 8,
      "name": "Wood_Ash_Trunk"
    },
    {
      "x": -15,
      "y": 25,
      "z": 8,
      "name": "Wood_Ash_Trunk_Full"
    },
    {
      "x": -15,
      "y": 4,
      "z": 9,
      "name": "Rock_Basalt"
    },
    {
      "x": -15,
      "y": 5,
      "z": 9,
      "name": "Ore_Iron_Basalt_Cracked"
    },
    {
      "x": -15,
      "y": 6,
      "z": 9,
      "name": "Rock_Basalt"
    },
    {
      "x": -15,
      "y": 7,
      "z": 9,
      "name": "Rock_Basalt"
    },
    {
      "x": -15,
      "y": 8,
      "z": 9,
      "name": "Rock_Basalt"
    },
    {
      "x": -15,
      "y": 9,
      "z": 9,
      "name": "Rock_Basalt"
    },
    {
      "x": -15,
      "y": 10,
      "z": 9,
      "name": "Rock_Basalt"
    },
    {
      "x": -15,
      "y": 11,
      "z": 9,
      "name": "Rock_Basalt"
    },
    {
      "x": -15,
      "y": 12,
      "z": 9,
      "name": "Rock_Basalt"
    },
    {
      "x": -15,
      "y": 13,
      "z": 9,
      "name": "Rock_Basalt"
    },
    {
      "x": -15,
      "y": 14,
      "z": 9,
      "name": "Ore_Iron_Basalt_Cracked"
    },
    {
      "x": -15,
      "y": 15,
      "z": 9,
      "name": "Rock_Basalt"
    },
    {
      "x": -15,
      "y": 16,
      "z": 9,
      "name": "Soil_Ash"
    },
    {
      "x": -15,
      "y": 23,
      "z": 9,
      "name": "Wood_Ash_Roots"
    },
    {
      "x": -15,
      "y": 24,
      "z": 9,
      "name": "Wood_Ash_Trunk_Full"
    },
    {
      "x": -15,
      "y": 25,
      "z": 9,
      "name": "Wood_Ash_Trunk"
    },
    {
      "x": -15,
      "y": 26,
      "z": 9,
      "name": "Wood_Ash_Trunk"
    },
    {
      "x": -15,
      "y": 27,
      "z": 9,
      "name": "Wood_Ash_Trunk_Full"
    },
    {
      "x": -15,
      "y": 5,
      "z": 10,
      "name": "Rock_Basalt"
    },
    {
      "x": -15,
      "y": 6,
      "z": 10,
      "name": "Rock_Basalt"
    },
    {
      "x": -15,
      "y": 7,
      "z": 10,
      "name": "Rock_Basalt"
    },
    {
      "x": -15,
      "y": 8,
      "z": 10,
      "name": "Rock_Basalt"
    },
    {
      "x": -15,
      "y": 9,
      "z": 10,
      "name": "Ore_Iron_Basalt_Cracked"
    },
    {
      "x": -15,
      "y": 10,
      "z": 10,
      "name": "Ore_Iron_Basalt_Cracked"
    },
    {
      "x": -15,
      "y": 11,
      "z": 10,
      "name": "Rock_Basalt"
    },
    {
      "x": -15,
      "y": 12,
      "z": 10,
      "name": "Ore_Iron_Basalt_Cracked"
    },
    {
      "x": -15,
      "y": 13,
      "z": 10,
      "name": "Rock_Basalt"
    },
    {
      "x": -15,
      "y": 14,
      "z": 10,
      "name": "Ore_Iron_Basalt_Cracked"
    },
    {
      "x": -15,
      "y": 15,
      "z": 10,
      "name": "Ore_Iron_Basalt_Cracked"
    },
    {
      "x": -15,
      "y": 16,
      "z": 10,
      "name": "Soil_Ash"
    },
    {
      "x": -15,
      "y": 25,
      "z": 10,
      "name": "Wood_Ash_Trunk_Full"
    },
    {
      "x": -15,
      "y": 26,
      "z": 10,
      "name": "Wood_Ash_Trunk"
    },
    {
      "x": -15,
      "y": 27,
      "z": 10,
      "name": "Wood_Ash_Trunk"
    },
    {
      "x": -15,
      "y": 28,
      "z": 10,
      "name": "Wood_Ash_Trunk"
    },
    {
      "x": -15,
      "y": 29,
      "z": 10,
      "name": "Wood_Ash_Trunk_Full"
    },
    {
      "x": -15,
      "y": 7,
      "z": 11,
      "name": "Rock_Basalt"
    },
    {
      "x": -15,
      "y": 8,
      "z": 11,
      "name": "Ore_Iron_Basalt_Cracked"
    },
    {
      "x": -15,
      "y": 9,
      "z": 11,
      "name": "Ore_Iron_Basalt_Cracked"
    },
    {
      "x": -15,
      "y": 10,
      "z": 11,
      "name": "Ore_Iron_Basalt_Cracked"
    },
    {
      "x": -15,
      "y": 11,
      "z": 11,
      "name": "Rock_Basalt"
    },
    {
      "x": -15,
      "y": 12,
      "z": 11,
      "name": "Rock_Basalt"
    },
    {
      "x": -15,
      "y": 13,
      "z": 11,
      "name": "Rock_Basalt"
    },
    {
      "x": -15,
      "y": 14,
      "z": 11,
      "name": "Ore_Iron_Basalt_Cracked"
    },
    {
      "x": -15,
      "y": 15,
      "z": 11,
      "name": "Rock_Basalt"
    },
    {
      "x": -15,
      "y": 16,
      "z": 11,
      "name": "Ore_Iron_Basalt_Cracked"
    },
    {
      "x": -15,
      "y": 17,
      "z": 11,
      "name": "Soil_Ash"
    },
    {
      "x": -15,
      "y": 25,
      "z": 11,
      "name": "Wood_Ash_Branch_Long",
      "rotation": 4
    },
    {
      "x": -15,
      "y": 8,
      "z": 12,
      "name": "Rock_Basalt"
    },
    {
      "x": -15,
      "y": 9,
      "z": 12,
      "name": "Rock_Basalt"
    },
    {
      "x": -15,
      "y": 10,
      "z": 12,
      "name": "Rock_Basalt"
    },
    {
      "x": -15,
      "y": 11,
      "z": 12,
      "name": "Rock_Basalt"
    },
    {
      "x": -15,
      "y": 12,
      "z": 12,
      "name": "Ore_Iron_Basalt_Cracked"
    },
    {
      "x": -15,
      "y": 13,
      "z": 12,
      "name": "Rock_Basalt"
    },
    {
      "x": -15,
      "y": 14,
      "z": 12,
      "name": "Ore_Iron_Basalt_Cracked"
    },
    {
      "x": -15,
      "y": 15,
      "z": 12,
      "name": "Rock_Basalt"
    },
    {
      "x": -15,
      "y": 16,
      "z": 12,
      "name": "Rock_Basalt"
    },
    {
      "x": -15,
      "y": 17,
      "z": 12,
      "name": "Soil_Ash"
    },
    {
      "x": -15,
      "y": 18,
      "z": 12,
      "name": "Plant_Bush_Dead_Twisted"
    },
    {
      "x": -15,
      "y": 7,
      "z": 13,
      "name": "Rock_Crystal_Purple_Medium",
      "rotation": 7
    },
    {
      "x": -15,
      "y": 8,
      "z": 13,
      "name": "Rock_Basalt"
    },
    {
      "x": -15,
      "y": 9,
      "z": 13,
      "name": "Rock_Basalt"
    },
    {
      "x": -15,
      "y": 10,
      "z": 13,
      "name": "Ore_Iron_Basalt_Cracked"
    },
    {
      "x": -15,
      "y": 11,
      "z": 13,
      "name": "Rock_Basalt"
    },
    {
      "x": -15,
      "y": 12,
      "z": 13,
      "name": "Rock_Basalt"
    },
    {
      "x": -15,
      "y": 13,
      "z": 13,
      "name": "Ore_Iron_Basalt_Cracked"
    },
    {
      "x": -15,
      "y": 14,
      "z": 13,
      "name": "Ore_Iron_Basalt_Cracked"
    },
    {
      "x": -15,
      "y": 15,
      "z": 13,
      "name": "Ore_Iron_Basalt_Cracked"
    },
    {
      "x": -15,
      "y": 16,
      "z": 13,
      "name": "Rock_Basalt"
    },
    {
      "x": -15,
      "y": 17,
      "z": 13,
      "name": "Soil_Ash"
    },
    {
      "x": -15,
      "y": 18,
      "z": 13,
      "name": "Plant_Bush_Dead_Twisted"
    },
    {
      "x": -15,
      "y": 6,
      "z": 14,
      "name": "Rock_Crystal_Purple_Medium",
      "rotation": 7
    },
    {
      "x": -15,
      "y": 7,
      "z": 14,
      "name": "Rock_Crystal_Purple_Medium",
      "rotation": 7
    },
    {
      "x": -15,
      "y": 8,
      "z": 14,
      "name": "Rock_Crystal_Purple_Block"
    },
    {
      "x": -15,
      "y": 9,
      "z": 14,
      "name": "Rock_Crystal_Purple_Block"
    },
    {
      "x": -15,
      "y": 10,
      "z": 14,
      "name": "Rock_Crystal_Purple_Block"
    },
    {
      "x": -15,
      "y": 11,
      "z": 14,
      "name": "Rock_Crystal_Purple_Block"
    },
    {
      "x": -15,
      "y": 12,
      "z": 14,
      "name": "Rock_Crystal_Purple_Block"
    },
    {
      "x": -15,
      "y": 13,
      "z": 14,
      "name": "Rock_Crystal_Purple_Block"
    },
    {
      "x": -15,
      "y": 14,
      "z": 14,
      "name": "Rock_Crystal_Purple_Block"
    },
    {
      "x": -15,
      "y": 15,
      "z": 14,
      "name": "Rock_Basalt"
    },
    {
      "x": -15,
      "y": 16,
      "z": 14,
      "name": "Ore_Iron_Basalt"
    },
    {
      "x": -15,
      "y": 17,
      "z": 14,
      "name": "Rock_Basalt"
    },
    {
      "x": -15,
      "y": 18,
      "z": 14,
      "name": "Soil_Ash"
    },
    {
      "x": -15,
      "y": 19,
      "z": 14,
      "name": "Plant_Bush_Dead_Twisted"
    },
    {
      "x": -15,
      "y": 8,
      "z": 15,
      "name": "Rock_Crystal_Purple_Medium",
      "rotation": 4
    },
    {
      "x": -15,
      "y": 9,
      "z": 15,
      "name": "Rock_Crystal_Purple_Medium",
      "rotation": 4
    },
    {
      "x": -15,
      "y": 10,
      "z": 15,
      "name": "Rock_Basalt"
    },
    {
      "x": -15,
      "y": 11,
      "z": 15,
      "name": "Ore_Iron_Basalt_Cracked"
    },
    {
      "x": -15,
      "y": 12,
      "z": 15,
      "name": "Rock_Basalt"
    },
    {
      "x": -15,
      "y": 13,
      "z": 15,
      "name": "Rock_Basalt"
    },
    {
      "x": -15,
      "y": 14,
      "z": 15,
      "name": "Rock_Basalt"
    },
    {
      "x": -15,
      "y": 15,
      "z": 15,
      "name": "Ore_Iron_Basalt_Cracked"
    },
    {
      "x": -15,
      "y": 16,
      "z": 15,
      "name": "Ore_Iron_Basalt_Cracked"
    },
    {
      "x": -15,
      "y": 17,
      "z": 15,
      "name": "Ore_Iron_Basalt_Cracked"
    },
    {
      "x": -15,
      "y": 18,
      "z": 15,
      "name": "Soil_Ash"
    },
    {
      "x": -15,
      "y": 11,
      "z": 16,
      "name": "Rock_Basalt"
    },
    {
      "x": -15,
      "y": 12,
      "z": 16,
      "name": "Rock_Basalt"
    },
    {
      "x": -15,
      "y": 13,
      "z": 16,
      "name": "Rock_Basalt"
    },
    {
      "x": -15,
      "y": 14,
      "z": 16,
      "name": "Ore_Iron_Basalt_Cracked"
    },
    {
      "x": -15,
      "y": 15,
      "z": 16,
      "name": "Rock_Basalt"
    },
    {
      "x": -15,
      "y": 16,
      "z": 16,
      "name": "Rock_Basalt"
    },
    {
      "x": -15,
      "y": 17,
      "z": 16,
      "name": "Ore_Iron_Basalt_Cracked"
    },
    {
      "x": -15,
      "y": 18,
      "z": 16,
      "name": "Soil_Ash"
    },
    {
      "x": -15,
      "y": 19,
      "z": 16,
      "name": "Plant_Bush_Dead_Twisted"
    },
    {
      "x": -15,
      "y": 15,
      "z": 17,
      "name": "Ore_Iron_Basalt_Cracked"
    },
    {
      "x": -15,
      "y": 16,
      "z": 17,
      "name": "Rock_Basalt"
    },
    {
      "x": -15,
      "y": 17,
      "z": 17,
      "name": "Rock_Basalt"
    },
    {
      "x": -15,
      "y": 18,
      "z": 17,
      "name": "Soil_Ash"
    },
    {
      "x": -15,
      "y": 17,
      "z": 18,
      "name": "Plant_Vine_Wall_Dead"
    },
    {
      "x": -15,
      "y": 18,
      "z": 18,
      "name": "Plant_Vine_Wall_Dead"
    },
    {
      "x": -14,
      "y": 26,
      "z": 4,
      "name": "Wood_Ash_Trunk_Full"
    },
    {
      "x": -14,
      "y": 27,
      "z": 4,
      "name": "Wood_Ash_Trunk_Full"
    },
    {
      "x": -14,
      "y": 12,
      "z": 5,
      "name": "Wood_Ash_Trunk_Full"
    },
    {
      "x": -14,
      "y": 13,
      "z": 5,
      "name": "Wood_Ash_Trunk"
    },
    {
      "x": -14,
      "y": 14,
      "z": 5,
      "name": "Wood_Ash_Trunk"
    },
    {
      "x": -14,
      "y": 15,
      "z": 5,
      "name": "Wood_Ash_Trunk_Full"
    },
    {
      "x": -14,
      "y": 24,
      "z": 5,
      "name": "Wood_Ash_Trunk_Full"
    },
    {
      "x": -14,
      "y": 25,
      "z": 5,
      "name": "Wood_Ash_Trunk"
    },
    {
      "x": -14,
      "y": 26,
      "z": 5,
      "name": "Wood_Ash_Trunk"
    },
    {
      "x": -14,
      "y": 27,
      "z": 5,
      "name": "Wood_Ash_Trunk_Full"
    },
    {
      "x": -14,
      "y": 9,
      "z": 6,
      "name": "Ore_Iron_Basalt_Cracked"
    },
    {
      "x": -14,
      "y": 10,
      "z": 6,
      "name": "Ore_Iron_Basalt_Cracked"
    },
    {
      "x": -14,
      "y": 11,
      "z": 6,
      "name": "Wood_Ash_Trunk_Full"
    },
    {
      "x": -14,
      "y": 12,
      "z": 6,
      "name": "Wood_Ash_Trunk_Full"
    },
    {
      "x": -14,
      "y": 13,
      "z": 6,
      "name": "Rock_Basalt"
    },
    {
      "x": -14,
      "y": 14,
      "z": 6,
      "name": "Rock_Basalt"
    },
    {
      "x": -14,
      "y": 15,
      "z": 6,
      "name": "Ore_Iron_Basalt_Cracked"
    },
    {
      "x": -14,
      "y": 16,
      "z": 6,
      "name": "Rock_Basalt"
    },
    {
      "x": -14,
      "y": 17,
      "z": 6,
      "name": "Soil_Ash"
    },
    {
      "x": -14,
      "y": 21,
      "z": 6,
      "name": "Wood_Ash_Trunk_Full"
    },
    {
      "x": -14,
      "y": 22,
      "z": 6,
      "name": "Wood_Ash_Trunk"
    },
    {
      "x": -14,
      "y": 23,
      "z": 6,
      "name": "Wood_Ash_Trunk"
    },
    {
      "x": -14,
      "y": 24,
      "z": 6,
      "name": "Wood_Ash_Trunk"
    },
    {
      "x": -14,
      "y": 25,
      "z": 6,
      "name": "Wood_Ash_Trunk"
    },
    {
      "x": -14,
      "y": 26,
      "z": 6,
      "name": "Wood_Ash_Trunk_Full"
    },
    {
      "x": -14,
      "y": 4,
      "z": 7,
      "name": "Rock_Basalt_Stalactite_Small",
      "rotation": 8
    },
    {
      "x": -14,
      "y": 5,
      "z": 7,
      "name": "Rock_Basalt"
    },
    {
      "x": -14,
      "y": 6,
      "z": 7,
      "name": "Ore_Iron_Basalt_Cracked"
    },
    {
      "x": -14,
      "y": 7,
      "z": 7,
      "name": "Ore_Iron_Basalt_Cracked"
    },
    {
      "x": -14,
      "y": 8,
      "z": 7,
      "name": "Rock_Basalt"
    },
    {
      "x": -14,
      "y": 9,
      "z": 7,
      "name": "Ore_Iron_Basalt_Cracked"
    },
    {
      "x": -14,
      "y": 10,
      "z": 7,
      "name": "Rock_Basalt"
    },
    {
      "x": -14,
      "y": 11,
      "z": 7,
      "name": "Rock_Basalt"
    },
    {
      "x": -14,
      "y": 12,
      "z": 7,
      "name": "Rock_Basalt"
    },
    {
      "x": -14,
      "y": 13,
      "z": 7,
      "name": "Rock_Basalt"
    },
    {
      "x": -14,
      "y": 14,
      "z": 7,
      "name": "Ore_Iron_Basalt"
    },
    {
      "x": -14,
      "y": 15,
      "z": 7,
      "name": "Ore_Iron_Basalt_Cracked"
    },
    {
      "x": -14,
      "y": 16,
      "z": 7,
      "name": "Soil_Ash"
    },
    {
      "x": -14,
      "y": 19,
      "z": 7,
      "name": "Wood_Ash_Trunk_Full"
    },
    {
      "x": -14,
      "y": 20,
      "z": 7,
      "name": "Wood_Ash_Trunk"
    },
    {
      "x": -14,
      "y": 21,
      "z": 7,
      "name": "Wood_Ash_Trunk"
    },
    {
      "x": -14,
      "y": 22,
      "z": 7,
      "name": "Wood_Ash_Trunk"
    },
    {
      "x": -14,
      "y": 23,
      "z": 7,
      "name": "Wood_Ash_Trunk"
    },
    {
      "x": -14,
      "y": 24,
      "z": 7,
      "name": "Wood_Ash_Trunk_Full"
    },
    {
      "x": -14,
      "y": 3,
      "z": 8,
      "name": "Rock_Basalt"
    },
    {
      "x": -14,
      "y": 4,
      "z": 8,
      "name": "Ore_Iron_Basalt_Cracked"
    },
    {
      "x": -14,
      "y": 5,
      "z": 8,
      "name": "Rock_Basalt"
    },
    {
      "x": -14,
      "y": 6,
      "z": 8,
      "name": "Rock_Basalt"
    },
    {
      "x": -14,
      "y": 7,
      "z": 8,
      "name": "Rock_Basalt"
    },
    {
      "x": -14,
      "y": 8,
      "z": 8,
      "name": "Rock_Basalt"
    },
    {
      "x": -14,
      "y": 9,
      "z": 8,
      "name": "Rock_Basalt"
    },
    {
      "x": -14,
      "y": 10,
      "z": 8,
      "name": "Rock_Basalt"
    },
    {
      "x": -14,
      "y": 11,
      "z": 8,
      "name": "Rock_Basalt"
    },
    {
      "x": -14,
      "y": 12,
      "z": 8,
      "name": "Rock_Basalt"
    },
    {
      "x": -14,
      "y": 13,
      "z": 8,
      "name": "Ore_Iron_Basalt_Cracked"
    },
    {
      "x": -14,
      "y": 14,
      "z": 8,
      "name": "Ore_Iron_Basalt_Cracked"
    },
    {
      "x": -14,
      "y": 15,
      "z": 8,
      "name": "Ore_Iron_Basalt_Cracked"
    },
    {
      "x": -14,
      "y": 16,
      "z": 8,
      "name": "Soil_Ash"
    },
    {
      "x": -14,
      "y": 19,
      "z": 8,
      "name": "Deco_SpiderWeb_Flat",
      "rotation": 4
    },
    {
      "x": -14,
      "y": 20,
      "z": 8,
      "name": "Deco_SpiderWeb_Flat",
      "rotation": 4
    },
    {
      "x": -14,
      "y": 22,
      "z": 8,
      "name": "Wood_Ash_Trunk_Full"
    },
    {
      "x": -14,
      "y": 23,
      "z": 8,
      "name": "Wood_Ash_Trunk"
    },
    {
      "x": -14,
      "y": 24,
      "z": 8,
      "name": "Wood_Ash_Trunk"
    },
    {
      "x": -14,
      "y": 25,
      "z": 8,
      "name": "Wood_Ash_Trunk_Full"
    },
    {
      "x": -14,
      "y": 3,
      "z": 9,
      "name": "Rock_Basalt"
    },
    {
      "x": -14,
      "y": 4,
      "z": 9,
      "name": "Ore_Iron_Basalt_Cracked"
    },
    {
      "x": -14,
      "y": 5,
      "z": 9,
      "name": "Rock_Basalt"
    },
    {
      "x": -14,
      "y": 6,
      "z": 9,
      "name": "Rock_Basalt"
    },
    {
      "x": -14,
      "y": 7,
      "z": 9,
      "name": "Rock_Basalt"
    },
    {
      "x": -14,
      "y": 8,
      "z": 9,
      "name": "Rock_Basalt"
    },
    {
      "x": -14,
      "y": 9,
      "z": 9,
      "name": "Rock_Basalt"
    },
    {
      "x": -14,
      "y": 10,
      "z": 9,
      "name": "Rock_Basalt"
    },
    {
      "x": -14,
      "y": 11,
      "z": 9,
      "name": "Rock_Basalt"
    },
    {
      "x": -14,
      "y": 12,
      "z": 9,
      "name": "Rock_Basalt"
    },
    {
      "x": -14,
      "y": 13,
      "z": 9,
      "name": "Rock_Basalt"
    },
    {
      "x": -14,
      "y": 14,
      "z": 9,
      "name": "Rock_Basalt"
    },
    {
      "x": -14,
      "y": 15,
      "z": 9,
      "name": "Ore_Iron_Basalt_Cracked"
    },
    {
      "x": -14,
      "y": 16,
      "z": 9,
      "name": "Soil_Ash"
    },
    {
      "x": -14,
      "y": 24,
      "z": 9,
      "name": "Wood_Ash_Trunk_Full"
    },
    {
      "x": -14,
      "y": 25,
      "z": 9,
      "name": "Wood_Ash_Trunk"
    },
    {
      "x": -14,
      "y": 26,
      "z": 9,
      "name": "Wood_Ash_Trunk_Full"
    },
    {
      "x": -14,
      "y": 2,
      "z": 10,
      "name": "Rock_Basalt_Stalactite_Small",
      "rotation": 8
    },
    {
      "x": -14,
      "y": 3,
      "z": 10,
      "name": "Rock_Basalt"
    },
    {
      "x": -14,
      "y": 4,
      "z": 10,
      "name": "Rock_Basalt"
    },
    {
      "x": -14,
      "y": 5,
      "z": 10,
      "name": "Rock_Basalt"
    },
    {
      "x": -14,
      "y": 6,
      "z": 10,
      "name": "Ore_Iron_Basalt_Cracked"
    },
    {
      "x": -14,
      "y": 7,
      "z": 10,
      "name": "Rock_Basalt"
    },
    {
      "x": -14,
      "y": 8,
      "z": 10,
      "name": "Ore_Iron_Basalt_Cracked"
    },
    {
      "x": -14,
      "y": 9,
      "z": 10,
      "name": "Ore_Iron_Basalt_Cracked"
    },
    {
      "x": -14,
      "y": 10,
      "z": 10,
      "name": "Rock_Basalt"
    },
    {
      "x": -14,
      "y": 11,
      "z": 10,
      "name": "Rock_Basalt"
    },
    {
      "x": -14,
      "y": 12,
      "z": 10,
      "name": "Ore_Iron_Basalt_Cracked"
    },
    {
      "x": -14,
      "y": 13,
      "z": 10,
      "name": "Ore_Iron_Basalt_Cracked"
    },
    {
      "x": -14,
      "y": 14,
      "z": 10,
      "name": "Rock_Basalt"
    },
    {
      "x": -14,
      "y": 15,
      "z": 10,
      "name": "Ore_Iron_Basalt_Cracked"
    },
    {
      "x": -14,
      "y": 16,
      "z": 10,
      "name": "Ore_Iron_Basalt_Cracked"
    },
    {
      "x": -14,
      "y": 17,
      "z": 10,
      "name": "Soil_Ash"
    },
    {
      "x": -14,
      "y": 27,
      "z": 10,
      "name": "Wood_Ash_Trunk_Full"
    },
    {
      "x": -14,
      "y": 5,
      "z": 11,
      "name": "Rock_Basalt"
    },
    {
      "x": -14,
      "y": 6,
      "z": 11,
      "name": "Rock_Basalt"
    },
    {
      "x": -14,
      "y": 7,
      "z": 11,
      "name": "Ore_Iron_Basalt_Cracked"
    },
    {
      "x": -14,
      "y": 8,
      "z": 11,
      "name": "Rock_Basalt"
    },
    {
      "x": -14,
      "y": 9,
      "z": 11,
      "name": "Rock_Basalt"
    },
    {
      "x": -14,
      "y": 10,
      "z": 11,
      "name": "Ore_Iron_Basalt_Cracked"
    },
    {
      "x": -14,
      "y": 11,
      "z": 11,
      "name": "Rock_Basalt"
    },
    {
      "x": -14,
      "y": 12,
      "z": 11,
      "name": "Rock_Basalt"
    },
    {
      "x": -14,
      "y": 13,
      "z": 11,
      "name": "Rock_Basalt"
    },
    {
      "x": -14,
      "y": 14,
      "z": 11,
      "name": "Rock_Basalt"
    },
    {
      "x": -14,
      "y": 15,
      "z": 11,
      "name": "Ore_Iron_Basalt_Cracked"
    },
    {
      "x": -14,
      "y": 16,
      "z": 11,
      "name": "Ore_Iron_Basalt_Cracked"
    },
    {
      "x": -14,
      "y": 17,
      "z": 11,
      "name": "Soil_Ash"
    },
    {
      "x": -14,
      "y": 18,
      "z": 11,
      "name": "Plant_Bush_Dead_Twisted"
    },
    {
      "x": -14,
      "y": 7,
      "z": 12,
      "name": "Rock_Basalt"
    },
    {
      "x": -14,
      "y": 8,
      "z": 12,
      "name": "Rock_Basalt"
    },
    {
      "x": -14,
      "y": 9,
      "z": 12,
      "name": "Ore_Iron_Basalt_Cracked"
    },
    {
      "x": -14,
      "y": 10,
      "z": 12,
      "name": "Rock_Basalt"
    },
    {
      "x": -14,
      "y": 11,
      "z": 12,
      "name": "Rock_Basalt"
    },
    {
      "x": -14,
      "y": 12,
      "z": 12,
      "name": "Ore_Iron_Basalt_Cracked"
    },
    {
      "x": -14,
      "y": 13,
      "z": 12,
      "name": "Rock_Basalt"
    },
    {
      "x": -14,
      "y": 14,
      "z": 12,
      "name": "Rock_Basalt"
    },
    {
      "x": -14,
      "y": 15,
      "z": 12,
      "name": "Rock_Basalt"
    },
    {
      "x": -14,
      "y": 16,
      "z": 12,
      "name": "Ore_Iron_Basalt_Cracked"
    },
    {
      "x": -14,
      "y": 17,
      "z": 12,
      "name": "Soil_Ash"
    },
    {
      "x": -14,
      "y": 6,
      "z": 13,
      "name": "Rock_Crystal_Purple_Medium",
      "rotation": 8
    },
    {
      "x": -14,
      "y": 7,
      "z": 13,
      "name": "Rock_Crystal_Purple_Block"
    },
    {
      "x": -14,
      "y": 8,
      "z": 13,
      "name": "Rock_Crystal_Purple_Block"
    },
    {
      "x": -14,
      "y": 9,
      "z": 13,
      "name": "Rock_Crystal_Purple_Block"
    },
    {
      "x": -14,
      "y": 10,
      "z": 13,
      "name": "Rock_Crystal_Purple_Block"
    },
    {
      "x": -14,
      "y": 11,
      "z": 13,
      "name": "Rock_Crystal_Purple_Block"
    },
    {
      "x": -14,
      "y": 12,
      "z": 13,
      "name": "Rock_Crystal_Purple_Block"
    },
    {
      "x": -14,
      "y": 13,
      "z": 13,
      "name": "Rock_Crystal_Purple_Block"
    },
    {
      "x": -14,
      "y": 14,
      "z": 13,
      "name": "Rock_Crystal_Purple_Block"
    },
    {
      "x": -14,
      "y": 15,
      "z": 13,
      "name": "Ore_Iron_Basalt_Cracked"
    },
    {
      "x": -14,
      "y": 16,
      "z": 13,
      "name": "Rock_Basalt"
    },
    {
      "x": -14,
      "y": 17,
      "z": 13,
      "name": "Soil_Ash"
    },
    {
      "x": -14,
      "y": 5,
      "z": 14,
      "name": "Rock_Crystal_Purple_Large",
      "rotation": 8
    },
    {
      "x": -14,
      "y": 6,
      "z": 14,
      "name": "Rock_Crystal_Purple_Block"
    },
    {
      "x": -14,
      "y": 7,
      "z": 14,
      "name": "Rock_Crystal_Purple_Block"
    },
    {
      "x": -14,
      "y": 8,
      "z": 14,
      "name": "Rock_Crystal_Purple_Block"
    },
    {
      "x": -14,
      "y": 9,
      "z": 14,
      "name": "Rock_Crystal_Purple_Block"
    },
    {
      "x": -14,
      "y": 10,
      "z": 14,
      "name": "Rock_Crystal_Purple_Block"
    },
    {
      "x": -14,
      "y": 11,
      "z": 14,
      "name": "Rock_Crystal_Purple_Block"
    },
    {
      "x": -14,
      "y": 12,
      "z": 14,
      "name": "Rock_Crystal_Purple_Block"
    },
    {
      "x": -14,
      "y": 13,
      "z": 14,
      "name": "Rock_Crystal_Purple_Block"
    },
    {
      "x": -14,
      "y": 14,
      "z": 14,
      "name": "Rock_Crystal_Purple_Block"
    },
    {
      "x": -14,
      "y": 15,
      "z": 14,
      "name": "Rock_Basalt"
    },
    {
      "x": -14,
      "y": 16,
      "z": 14,
      "name": "Ore_Iron_Basalt_Cracked"
    },
    {
      "x": -14,
      "y": 17,
      "z": 14,
      "name": "Soil_Ash"
    },
    {
      "x": -14,
      "y": 6,
      "z": 15,
      "name": "Rock_Crystal_Purple_Medium",
      "rotation": 4
    },
    {
      "x": -14,
      "y": 7,
      "z": 15,
      "name": "Rock_Crystal_Purple_Large",
      "rotation": 8
    },
    {
      "x": -14,
      "y": 8,
      "z": 15,
      "name": "Rock_Crystal_Purple_Block"
    },
    {
      "x": -14,
      "y": 9,
      "z": 15,
      "name": "Rock_Crystal_Purple_Block"
    },
    {
      "x": -14,
      "y": 10,
      "z": 15,
      "name": "Rock_Crystal_Purple_Block"
    },
    {
      "x": -14,
      "y": 11,
      "z": 15,
      "name": "Rock_Crystal_Purple_Block"
    },
    {
      "x": -14,
      "y": 12,
      "z": 15,
      "name": "Rock_Crystal_Purple_Block"
    },
    {
      "x": -14,
      "y": 13,
      "z": 15,
      "name": "Rock_Crystal_Purple_Block"
    },
    {
      "x": -14,
      "y": 14,
      "z": 15,
      "name": "Rock_Crystal_Purple_Block"
    },
    {
      "x": -14,
      "y": 15,
      "z": 15,
      "name": "Ore_Iron_Basalt_Cracked"
    },
    {
      "x": -14,
      "y": 16,
      "z": 15,
      "name": "Ore_Iron_Basalt"
    },
    {
      "x": -14,
      "y": 17,
      "z": 15,
      "name": "Rock_Basalt"
    },
    {
      "x": -14,
      "y": 18,
      "z": 15,
      "name": "Soil_Ash"
    },
    {
      "x": -14,
      "y": 19,
      "z": 15,
      "name": "Plant_Flower_Bushy_Poisoned"
    },
    {
      "x": -14,
      "y": 9,
      "z": 16,
      "name": "Rock_Crystal_Purple_Medium",
      "rotation": 4
    },
    {
      "x": -14,
      "y": 10,
      "z": 16,
      "name": "Rock_Crystal_Purple_Medium",
      "rotation": 4
    },
    {
      "x": -14,
      "y": 11,
      "z": 16,
      "name": "Rock_Crystal_Purple_Medium",
      "rotation": 4
    },
    {
      "x": -14,
      "y": 12,
      "z": 16,
      "name": "Ore_Iron_Basalt_Cracked"
    },
    {
      "x": -14,
      "y": 13,
      "z": 16,
      "name": "Rock_Basalt"
    },
    {
      "x": -14,
      "y": 14,
      "z": 16,
      "name": "Ore_Iron_Basalt_Cracked"
    },
    {
      "x": -14,
      "y": 15,
      "z": 16,
      "name": "Rock_Basalt"
    },
    {
      "x": -14,
      "y": 16,
      "z": 16,
      "name": "Rock_Basalt"
    },
    {
      "x": -14,
      "y": 17,
      "z": 16,
      "name": "Rock_Basalt"
    },
    {
      "x": -14,
      "y": 18,
      "z": 16,
      "name": "Soil_Ash"
    },
    {
      "x": -14,
      "y": 17,
      "z": 17,
      "name": "Plant_Vine_Wall_Dead"
    },
    {
      "x": -14,
      "y": 18,
      "z": 17,
      "name": "Plant_Vine_Wall_Dead"
    },
    {
      "x": -13,
      "y": 27,
      "z": 4,
      "name": "Deco_SpiderWeb_Flat",
      "rotation": 6
    },
    {
      "x": -13,
      "y": 11,
      "z": 5,
      "name": "Ore_Iron_Basalt_Cracked"
    },
    {
      "x": -13,
      "y": 12,
      "z": 5,
      "name": "Ore_Iron_Basalt_Cracked"
    },
    {
      "x": -13,
      "y": 13,
      "z": 5,
      "name": "Rock_Basalt"
    },
    {
      "x": -13,
      "y": 14,
      "z": 5,
      "name": "Wood_Ash_Roots"
    },
    {
      "x": -13,
      "y": 15,
      "z": 5,
      "name": "Wood_Ash_Trunk_Full"
    },
    {
      "x": -13,
      "y": 16,
      "z": 5,
      "name": "Wood_Ash_Trunk_Full"
    },
    {
      "x": -13,
      "y": 17,
      "z": 5,
      "name": "Soil_Ash"
    },
    {
      "x": -13,
      "y": 22,
      "z": 5,
      "name": "Wood_Ash_Roots"
    },
    {
      "x": -13,
      "y": 23,
      "z": 5,
      "name": "Wood_Ash_Trunk_Full"
    },
    {
      "x": -13,
      "y": 24,
      "z": 5,
      "name": "Wood_Ash_Trunk"
    },
    {
      "x": -13,
      "y": 25,
      "z": 5,
      "name": "Wood_Ash_Trunk"
    },
    {
      "x": -13,
      "y": 26,
      "z": 5,
      "name": "Wood_Ash_Trunk"
    },
    {
      "x": -13,
      "y": 27,
      "z": 5,
      "name": "Wood_Ash_Trunk_Full"
    },
    {
      "x": -13,
      "y": 8,
      "z": 6,
      "name": "Ore_Iron_Basalt_Cracked"
    },
    {
      "x": -13,
      "y": 9,
      "z": 6,
      "name": "Rock_Basalt"
    },
    {
      "x": -13,
      "y": 10,
      "z": 6,
      "name": "Ore_Iron_Basalt_Cracked"
    },
    {
      "x": -13,
      "y": 11,
      "z": 6,
      "name": "Ore_Iron_Basalt_Cracked"
    },
    {
      "x": -13,
      "y": 12,
      "z": 6,
      "name": "Ore_Iron_Basalt_Cracked"
    },
    {
      "x": -13,
      "y": 13,
      "z": 6,
      "name": "Rock_Basalt"
    },
    {
      "x": -13,
      "y": 14,
      "z": 6,
      "name": "Rock_Basalt"
    },
    {
      "x": -13,
      "y": 15,
      "z": 6,
      "name": "Rock_Basalt"
    },
    {
      "x": -13,
      "y": 16,
      "z": 6,
      "name": "Wood_Ash_Trunk_Full"
    },
    {
      "x": -13,
      "y": 17,
      "z": 6,
      "name": "Wood_Ash_Trunk"
    },
    {
      "x": -13,
      "y": 18,
      "z": 6,
      "name": "Wood_Ash_Trunk"
    },
    {
      "x": -13,
      "y": 19,
      "z": 6,
      "name": "Wood_Ash_Trunk"
    },
    {
      "x": -13,
      "y": 20,
      "z": 6,
      "name": "Wood_Ash_Trunk"
    },
    {
      "x": -13,
      "y": 21,
      "z": 6,
      "name": "Wood_Ash_Trunk"
    },
    {
      "x": -13,
      "y": 22,
      "z": 6,
      "name": "Wood_Ash_Trunk"
    },
    {
      "x": -13,
      "y": 23,
      "z": 6,
      "name": "Wood_Ash_Trunk"
    },
    {
      "x": -13,
      "y": 24,
      "z": 6,
      "name": "Wood_Ash_Trunk"
    },
    {
      "x": -13,
      "y": 25,
      "z": 6,
      "name": "Wood_Ash_Trunk"
    },
    {
      "x": -13,
      "y": 26,
      "z": 6,
      "name": "Wood_Ash_Trunk"
    },
    {
      "x": -13,
      "y": 27,
      "z": 6,
      "name": "Wood_Ash_Trunk_Full"
    },
    {
      "x": -13,
      "y": 3,
      "z": 7,
      "name": "Rock_Basalt_Stalactite_Small",
      "rotation": 8
    },
    {
      "x": -13,
      "y": 4,
      "z": 7,
      "name": "Rock_Basalt"
    },
    {
      "x": -13,
      "y": 5,
      "z": 7,
      "name": "Ore_Iron_Basalt_Cracked"
    },
    {
      "x": -13,
      "y": 6,
      "z": 7,
      "name": "Rock_Basalt"
    },
    {
      "x": -13,
      "y": 7,
      "z": 7,
      "name": "Rock_Basalt"
    },
    {
      "x": -13,
      "y": 8,
      "z": 7,
      "name": "Rock_Basalt"
    },
    {
      "x": -13,
      "y": 9,
      "z": 7,
      "name": "Rock_Basalt"
    },
    {
      "x": -13,
      "y": 10,
      "z": 7,
      "name": "Rock_Basalt"
    },
    {
      "x": -13,
      "y": 11,
      "z": 7,
      "name": "Rock_Basalt"
    },
    {
      "x": -13,
      "y": 12,
      "z": 7,
      "name": "Ore_Iron_Basalt_Cracked"
    },
    {
      "x": -13,
      "y": 13,
      "z": 7,
      "name": "Rock_Basalt"
    },
    {
      "x": -13,
      "y": 14,
      "z": 7,
      "name": "Ore_Iron_Basalt_Cracked"
    },
    {
      "x": -13,
      "y": 15,
      "z": 7,
      "name": "Rock_Basalt"
    },
    {
      "x": -13,
      "y": 16,
      "z": 7,
      "name": "Rock_Basalt"
    },
    {
      "x": -13,
      "y": 17,
      "z": 7,
      "name": "Wood_Ash_Trunk_Full"
    },
    {
      "x": -13,
      "y": 18,
      "z": 7,
      "name": "Wood_Ash_Trunk"
    },
    {
      "x": -13,
      "y": 19,
      "z": 7,
      "name": "Wood_Ash_Trunk"
    },
    {
      "x": -13,
      "y": 20,
      "z": 7,
      "name": "Wood_Ash_Trunk"
    },
    {
      "x": -13,
      "y": 21,
      "z": 7,
      "name": "Wood_Ash_Trunk"
    },
    {
      "x": -13,
      "y": 22,
      "z": 7,
      "name": "Wood_Ash_Trunk_Full"
    },
    {
      "x": -13,
      "y": 3,
      "z": 8,
      "name": "Rock_Basalt"
    },
    {
      "x": -13,
      "y": 4,
      "z": 8,
      "name": "Rock_Basalt"
    },
    {
      "x": -13,
      "y": 5,
      "z": 8,
      "name": "Rock_Basalt"
    },
    {
      "x": -13,
      "y": 6,
      "z": 8,
      "name": "Rock_Basalt"
    },
    {
      "x": -13,
      "y": 7,
      "z": 8,
      "name": "Ore_Iron_Basalt_Cracked"
    },
    {
      "x": -13,
      "y": 8,
      "z": 8,
      "name": "Rock_Basalt"
    },
    {
      "x": -13,
      "y": 9,
      "z": 8,
      "name": "Rock_Basalt"
    },
    {
      "x": -13,
      "y": 10,
      "z": 8,
      "name": "Ore_Iron_Basalt_Cracked"
    },
    {
      "x": -13,
      "y": 11,
      "z": 8,
      "name": "Ore_Iron_Basalt_Cracked"
    },
    {
      "x": -13,
      "y": 12,
      "z": 8,
      "name": "Rock_Basalt"
    },
    {
      "x": -13,
      "y": 13,
      "z": 8,
      "name": "Rock_Basalt"
    },
    {
      "x": -13,
      "y": 14,
      "z": 8,
      "name": "Rock_Basalt"
    },
    {
      "x": -13,
      "y": 15,
      "z": 8,
      "name": "Ore_Iron_Basalt_Cracked"
    },
    {
      "x": -13,
      "y": 16,
      "z": 8,
      "name": "Rock_Basalt"
    },
    {
      "x": -13,
      "y": 17,
      "z": 8,
      "name": "Soil_Ash"
    },
    {
      "x": -13,
      "y": 20,
      "z": 8,
      "name": "Wood_Ash_Roots"
    },
    {
      "x": -13,
      "y": 21,
      "z": 8,
      "name": "Wood_Ash_Trunk_Full"
    },
    {
      "x": -13,
      "y": 22,
      "z": 8,
      "name": "Wood_Ash_Trunk"
    },
    {
      "x": -13,
      "y": 23,
      "z": 8,
      "name": "Wood_Ash_Trunk"
    },
    {
      "x": -13,
      "y": 24,
      "z": 8,
      "name": "Wood_Ash_Trunk_Full"
    },
    {
      "x": -13,
      "y": 1,
      "z": 9,
      "name": "Rock_Basalt_Stalactite_Small",
      "rotation": 8
    },
    {
      "x": -13,
      "y": 2,
      "z": 9,
      "name": "Ore_Iron_Basalt_Cracked"
    },
    {
      "x": -13,
      "y": 3,
      "z": 9,
      "name": "Ore_Iron_Basalt_Cracked"
    },
    {
      "x": -13,
      "y": 4,
      "z": 9,
      "name": "Rock_Basalt"
    },
    {
      "x": -13,
      "y": 5,
      "z": 9,
      "name": "Ore_Iron_Basalt_Cracked"
    },
    {
      "x": -13,
      "y": 6,
      "z": 9,
      "name": "Rock_Basalt"
    },
    {
      "x": -13,
      "y": 7,
      "z": 9,
      "name": "Rock_Basalt"
    },
    {
      "x": -13,
      "y": 8,
      "z": 9,
      "name": "Ore_Iron_Basalt_Cracked"
    },
    {
      "x": -13,
      "y": 9,
      "z": 9,
      "name": "Rock_Basalt"
    },
    {
      "x": -13,
      "y": 10,
      "z": 9,
      "name": "Ore_Iron_Basalt_Cracked"
    },
    {
      "x": -13,
      "y": 11,
      "z": 9,
      "name": "Rock_Basalt"
    },
    {
      "x": -13,
      "y": 12,
      "z": 9,
      "name": "Rock_Basalt"
    },
    {
      "x": -13,
      "y": 13,
      "z": 9,
      "name": "Ore_Iron_Basalt_Cracked"
    },
    {
      "x": -13,
      "y": 14,
      "z": 9,
      "name": "Rock_Basalt"
    },
    {
      "x": -13,
      "y": 15,
      "z": 9,
      "name": "Ore_Iron_Basalt_Cracked"
    },
    {
      "x": -13,
      "y": 16,
      "z": 9,
      "name": "Ore_Iron_Basalt_Cracked"
    },
    {
      "x": -13,
      "y": 17,
      "z": 9,
      "name": "Soil_Ash"
    },
    {
      "x": -13,
      "y": 22,
      "z": 9,
      "name": "Deco_SpiderWeb_Flat",
      "rotation": 4
    },
    {
      "x": -13,
      "y": 23,
      "z": 9,
      "name": "Wood_Ash_Trunk_Full"
    },
    {
      "x": -13,
      "y": 24,
      "z": 9,
      "name": "Wood_Ash_Trunk"
    },
    {
      "x": -13,
      "y": 25,
      "z": 9,
      "name": "Wood_Ash_Trunk_Full"
    },
    {
      "x": -13,
      "y": 2,
      "z": 10,
      "name": "Rock_Basalt_Stalactite_Small",
      "rotation": 8
    },
    {
      "x": -13,
      "y": 3,
      "z": 10,
      "name": "Ore_Iron_Basalt_Cracked"
    },
    {
      "x": -13,
      "y": 4,
      "z": 10,
      "name": "Rock_Basalt"
    },
    {
      "x": -13,
      "y": 5,
      "z": 10,
      "name": "Rock_Basalt"
    },
    {
      "x": -13,
      "y": 6,
      "z": 10,
      "name": "Rock_Basalt"
    },
    {
      "x": -13,
      "y": 7,
      "z": 10,
      "name": "Rock_Basalt"
    },
    {
      "x": -13,
      "y": 8,
      "z": 10,
      "name": "Rock_Basalt"
    },
    {
      "x": -13,
      "y": 9,
      "z": 10,
      "name": "Ore_Iron_Basalt_Cracked"
    },
    {
      "x": -13,
      "y": 10,
      "z": 10,
      "name": "Rock_Basalt"
    },
    {
      "x": -13,
      "y": 11,
      "z": 10,
      "name": "Ore_Iron_Basalt_Cracked"
    },
    {
      "x": -13,
      "y": 12,
      "z": 10,
      "name": "Ore_Iron_Basalt_Cracked"
    },
    {
      "x": -13,
      "y": 13,
      "z": 10,
      "name": "Rock_Basalt"
    },
    {
      "x": -13,
      "y": 14,
      "z": 10,
      "name": "Rock_Basalt"
    },
    {
      "x": -13,
      "y": 15,
      "z": 10,
      "name": "Rock_Basalt"
    },
    {
      "x": -13,
      "y": 16,
      "z": 10,
      "name": "Rock_Basalt"
    },
    {
      "x": -13,
      "y": 17,
      "z": 10,
      "name": "Soil_Ash"
    },
    {
      "x": -13,
      "y": 23,
      "z": 10,
      "name": "Deco_SpiderWeb_Flat",
      "rotation": 4
    },
    {
      "x": -13,
      "y": 4,
      "z": 11,
      "name": "Ore_Iron_Basalt_Cracked"
    },
    {
      "x": -13,
      "y": 5,
      "z": 11,
      "name": "Rock_Basalt"
    },
    {
      "x": -13,
      "y": 6,
      "z": 11,
      "name": "Rock_Basalt"
    },
    {
      "x": -13,
      "y": 7,
      "z": 11,
      "name": "Rock_Basalt"
    },
    {
      "x": -13,
      "y": 8,
      "z": 11,
      "name": "Rock_Basalt"
    },
    {
      "x": -13,
      "y": 9,
      "z": 11,
      "name": "Rock_Basalt"
    },
    {
      "x": -13,
      "y": 10,
      "z": 11,
      "name": "Ore_Iron_Basalt_Cracked"
    },
    {
      "x": -13,
      "y": 11,
      "z": 11,
      "name": "Rock_Basalt"
    },
    {
      "x": -13,
      "y": 12,
      "z": 11,
      "name": "Rock_Basalt"
    },
    {
      "x": -13,
      "y": 13,
      "z": 11,
      "name": "Rock_Basalt"
    },
    {
      "x": -13,
      "y": 14,
      "z": 11,
      "name": "Ore_Iron_Basalt_Cracked"
    },
    {
      "x": -13,
      "y": 15,
      "z": 11,
      "name": "Ore_Iron_Basalt_Cracked"
    },
    {
      "x": -13,
      "y": 16,
      "z": 11,
      "name": "Rock_Basalt"
    },
    {
      "x": -13,
      "y": 17,
      "z": 11,
      "name": "Soil_Ash"
    },
    {
      "x": -13,
      "y": 8,
      "z": 12,
      "name": "Rock_Basalt"
    },
    {
      "x": -13,
      "y": 9,
      "z": 12,
      "name": "Rock_Basalt"
    },
    {
      "x": -13,
      "y": 10,
      "z": 12,
      "name": "Rock_Basalt"
    },
    {
      "x": -13,
      "y": 11,
      "z": 12,
      "name": "Rock_Basalt"
    },
    {
      "x": -13,
      "y": 12,
      "z": 12,
      "name": "Rock_Basalt"
    },
    {
      "x": -13,
      "y": 13,
      "z": 12,
      "name": "Rock_Basalt"
    },
    {
      "x": -13,
      "y": 14,
      "z": 12,
      "name": "Rock_Basalt"
    },
    {
      "x": -13,
      "y": 15,
      "z": 12,
      "name": "Ore_Iron_Basalt"
    },
    {
      "x": -13,
      "y": 16,
      "z": 12,
      "name": "Rock_Basalt"
    },
    {
      "x": -13,
      "y": 17,
      "z": 12,
      "name": "Soil_Ash"
    },
    {
      "x": -13,
      "y": 7,
      "z": 13,
      "name": "Rock_Crystal_Purple_Medium",
      "rotation": 5
    },
    {
      "x": -13,
      "y": 8,
      "z": 13,
      "name": "Rock_Basalt"
    },
    {
      "x": -13,
      "y": 9,
      "z": 13,
      "name": "Rock_Basalt"
    },
    {
      "x": -13,
      "y": 10,
      "z": 13,
      "name": "Rock_Basalt"
    },
    {
      "x": -13,
      "y": 11,
      "z": 13,
      "name": "Rock_Basalt"
    },
    {
      "x": -13,
      "y": 12,
      "z": 13,
      "name": "Rock_Basalt"
    },
    {
      "x": -13,
      "y": 13,
      "z": 13,
      "name": "Rock_Basalt"
    },
    {
      "x": -13,
      "y": 14,
      "z": 13,
      "name": "Rock_Basalt"
    },
    {
      "x": -13,
      "y": 15,
      "z": 13,
      "name": "Ore_Iron_Basalt"
    },
    {
      "x": -13,
      "y": 16,
      "z": 13,
      "name": "Rock_Basalt"
    },
    {
      "x": -13,
      "y": 17,
      "z": 13,
      "name": "Soil_Ash"
    },
    {
      "x": -13,
      "y": 6,
      "z": 14,
      "name": "Rock_Crystal_Purple_Medium",
      "rotation": 5
    },
    {
      "x": -13,
      "y": 7,
      "z": 14,
      "name": "Rock_Crystal_Purple_Large",
      "rotation": 8
    },
    {
      "x": -13,
      "y": 8,
      "z": 14,
      "name": "Rock_Crystal_Purple_Block"
    },
    {
      "x": -13,
      "y": 9,
      "z": 14,
      "name": "Rock_Crystal_Purple_Block"
    },
    {
      "x": -13,
      "y": 10,
      "z": 14,
      "name": "Rock_Crystal_Purple_Block"
    },
    {
      "x": -13,
      "y": 11,
      "z": 14,
      "name": "Rock_Crystal_Purple_Block"
    },
    {
      "x": -13,
      "y": 12,
      "z": 14,
      "name": "Rock_Crystal_Purple_Block"
    },
    {
      "x": -13,
      "y": 13,
      "z": 14,
      "name": "Rock_Crystal_Purple_Block"
    },
    {
      "x": -13,
      "y": 14,
      "z": 14,
      "name": "Rock_Crystal_Purple_Block"
    },
    {
      "x": -13,
      "y": 15,
      "z": 14,
      "name": "Rock_Basalt"
    },
    {
      "x": -13,
      "y": 16,
      "z": 14,
      "name": "Ore_Iron_Basalt_Cracked"
    },
    {
      "x": -13,
      "y": 17,
      "z": 14,
      "name": "Soil_Ash"
    },
    {
      "x": -13,
      "y": 8,
      "z": 15,
      "name": "Rock_Crystal_Purple_Medium",
      "rotation": 5
    },
    {
      "x": -13,
      "y": 9,
      "z": 15,
      "name": "Rock_Crystal_Purple_Medium",
      "rotation": 4
    },
    {
      "x": -13,
      "y": 10,
      "z": 15,
      "name": "Rock_Crystal_Purple_Medium",
      "rotation": 4
    },
    {
      "x": -13,
      "y": 11,
      "z": 15,
      "name": "Ore_Iron_Basalt_Cracked"
    },
    {
      "x": -13,
      "y": 12,
      "z": 15,
      "name": "Ore_Iron_Basalt_Cracked"
    },
    {
      "x": -13,
      "y": 13,
      "z": 15,
      "name": "Ore_Iron_Basalt_Cracked"
    },
    {
      "x": -13,
      "y": 14,
      "z": 15,
      "name": "Rock_Basalt"
    },
    {
      "x": -13,
      "y": 15,
      "z": 15,
      "name": "Rock_Basalt"
    },
    {
      "x": -13,
      "y": 16,
      "z": 15,
      "name": "Ore_Iron_Basalt_Cracked"
    },
    {
      "x": -13,
      "y": 17,
      "z": 15,
      "name": "Ore_Iron_Basalt_Cracked"
    },
    {
      "x": -13,
      "y": 18,
      "z": 15,
      "name": "Soil_Ash"
    },
    {
      "x": -13,
      "y": 16,
      "z": 16,
      "name": "Plant_Vine_Wall_Dead"
    },
    {
      "x": -13,
      "y": 18,
      "z": 16,
      "name": "Plant_Vine_Wall_Dead"
    },
    {
      "x": -12,
      "y": 16,
      "z": -12,
      "name": "Plant_Vine_Wall_Dead",
      "rotation": 3
    },
    {
      "x": -12,
      "y": 15,
      "z": -11,
      "name": "Plant_Vine_Wall_Dead",
      "rotation": 3
    },
    {
      "x": -12,
      "y": 16,
      "z": -11,
      "name": "Plant_Vine_Wall_Dead",
      "rotation": 3
    },
    {
      "x": -12,
      "y": 16,
      "z": -10,
      "name": "Plant_Vine_Wall_Dead",
      "rotation": 3
    },
    {
      "x": -12,
      "y": 28,
      "z": 3,
      "name": "Wood_Ash_Branch_Long",
      "rotation": 4
    },
    {
      "x": -12,
      "y": 7,
      "z": 4,
      "name": "Rock_Basalt_Stalactite_Large",
      "filler": 31744,
      "rotation": 8
    },
    {
      "x": -12,
      "y": 8,
      "z": 4,
      "name": "Rock_Basalt_Stalactite_Large",
      "rotation": 8
    },
    {
      "x": -12,
      "y": 9,
      "z": 4,
      "name": "Rock_Basalt"
    },
    {
      "x": -12,
      "y": 10,
      "z": 4,
      "name": "Ore_Iron_Basalt_Cracked"
    },
    {
      "x": -12,
      "y": 11,
      "z": 4,
      "name": "Ore_Iron_Basalt_Cracked"
    },
    {
      "x": -12,
      "y": 12,
      "z": 4,
      "name": "Ore_Iron_Basalt_Cracked"
    },
    {
      "x": -12,
      "y": 13,
      "z": 4,
      "name": "Rock_Basalt"
    },
    {
      "x": -12,
      "y": 14,
      "z": 4,
      "name": "Soil_Sand_Ashen"
    },
    {
      "x": -12,
      "y": 27,
      "z": 4,
      "name": "Wood_Ash_Trunk_Full"
    },
    {
      "x": -12,
      "y": 28,
      "z": 4,
      "name": "Wood_Ash_Trunk_Full"
    },
    {
      "x": -12,
      "y": 30,
      "z": 4,
      "name": "Wood_Ash_Trunk_Full"
    },
    {
      "x": -12,
      "y": 31,
      "z": 4,
      "name": "Wood_Ash_Trunk"
    },
    {
      "x": -12,
      "y": 32,
      "z": 4,
      "name": "Wood_Ash_Trunk"
    },
    {
      "x": -12,
      "y": 33,
      "z": 4,
      "name": "Wood_Ash_Trunk_Full"
    },
    {
      "x": -12,
      "y": 7,
      "z": 5,
      "name": "Rock_Basalt"
    },
    {
      "x": -12,
      "y": 8,
      "z": 5,
      "name": "Ore_Iron_Basalt_Cracked"
    },
    {
      "x": -12,
      "y": 9,
      "z": 5,
      "name": "Rock_Basalt"
    },
    {
      "x": -12,
      "y": 10,
      "z": 5,
      "name": "Rock_Basalt"
    },
    {
      "x": -12,
      "y": 11,
      "z": 5,
      "name": "Ore_Iron_Basalt_Cracked"
    },
    {
      "x": -12,
      "y": 12,
      "z": 5,
      "name": "Rock_Basalt"
    },
    {
      "x": -12,
      "y": 13,
      "z": 5,
      "name": "Rock_Basalt"
    },
    {
      "x": -12,
      "y": 14,
      "z": 5,
      "name": "Rock_Basalt"
    },
    {
      "x": -12,
      "y": 15,
      "z": 5,
      "name": "Soil_Sand_Ashen"
    },
    {
      "x": -12,
      "y": 17,
      "z": 5,
      "name": "Wood_Ash_Trunk_Full"
    },
    {
      "x": -12,
      "y": 18,
      "z": 5,
      "name": "Wood_Ash_Trunk_Full"
    },
    {
      "x": -12,
      "y": 25,
      "z": 5,
      "name": "Wood_Ash_Trunk_Full"
    },
    {
      "x": -12,
      "y": 26,
      "z": 5,
      "name": "Wood_Ash_Trunk"
    },
    {
      "x": -12,
      "y": 27,
      "z": 5,
      "name": "Wood_Ash_Trunk"
    },
    {
      "x": -12,
      "y": 28,
      "z": 5,
      "name": "Wood_Ash_Trunk_Full"
    },
    {
      "x": -12,
      "y": 33,
      "z": 5,
      "name": "Wood_Ash_Trunk_Full"
    },
    {
      "x": -12,
      "y": 34,
      "z": 5,
      "name": "Wood_Ash_Trunk"
    },
    {
      "x": -12,
      "y": 35,
      "z": 5,
      "name": "Wood_Ash_Trunk_Full"
    },
    {
      "x": -12,
      "y": 6,
      "z": 6,
      "name": "Rock_Basalt"
    },
    {
      "x": -12,
      "y": 7,
      "z": 6,
      "name": "Ore_Iron_Basalt_Cracked"
    },
    {
      "x": -12,
      "y": 8,
      "z": 6,
      "name": "Rock_Basalt"
    },
    {
      "x": -12,
      "y": 9,
      "z": 6,
      "name": "Rock_Basalt"
    },
    {
      "x": -12,
      "y": 10,
      "z": 6,
      "name": "Ore_Iron_Basalt_Cracked"
    },
    {
      "x": -12,
      "y": 11,
      "z": 6,
      "name": "Rock_Basalt"
    },
    {
      "x": -12,
      "y": 12,
      "z": 6,
      "name": "Rock_Basalt"
    },
    {
      "x": -12,
      "y": 13,
      "z": 6,
      "name": "Rock_Basalt"
    },
    {
      "x": -12,
      "y": 14,
      "z": 6,
      "name": "Rock_Basalt"
    },
    {
      "x": -12,
      "y": 15,
      "z": 6,
      "name": "Ore_Iron_Basalt_Cracked"
    },
    {
      "x": -12,
      "y": 16,
      "z": 6,
      "name": "Soil_Ash"
    },
    {
      "x": -12,
      "y": 17,
      "z": 6,
      "name": "Wood_Ash_Trunk"
    },
    {
      "x": -12,
      "y": 18,
      "z": 6,
      "name": "Wood_Ash_Trunk"
    },
    {
      "x": -12,
      "y": 19,
      "z": 6,
      "name": "Wood_Ash_Trunk_Full"
    },
    {
      "x": -12,
      "y": 23,
      "z": 6,
      "name": "Deco_SpiderWeb_Flat",
      "rotation": 5
    },
    {
      "x": -12,
      "y": 26,
      "z": 6,
      "name": "Wood_Ash_Trunk_Full"
    },
    {
      "x": -12,
      "y": 5,
      "z": 7,
      "name": "Rock_Basalt"
    },
    {
      "x": -12,
      "y": 6,
      "z": 7,
      "name": "Rock_Basalt"
    },
    {
      "x": -12,
      "y": 7,
      "z": 7,
      "name": "Ore_Iron_Basalt_Cracked"
    },
    {
      "x": -12,
      "y": 8,
      "z": 7,
      "name": "Rock_Basalt"
    },
    {
      "x": -12,
      "y": 9,
      "z": 7,
      "name": "Ore_Iron_Basalt_Cracked"
    },
    {
      "x": -12,
      "y": 10,
      "z": 7,
      "name": "Rock_Basalt"
    },
    {
      "x": -12,
      "y": 11,
      "z": 7,
      "name": "Rock_Basalt"
    },
    {
      "x": -12,
      "y": 12,
      "z": 7,
      "name": "Rock_Basalt"
    },
    {
      "x": -12,
      "y": 13,
      "z": 7,
      "name": "Rock_Basalt"
    },
    {
      "x": -12,
      "y": 14,
      "z": 7,
      "name": "Rock_Basalt"
    },
    {
      "x": -12,
      "y": 15,
      "z": 7,
      "name": "Rock_Basalt"
    },
    {
      "x": -12,
      "y": 16,
      "z": 7,
      "name": "Wood_Ash_Trunk_Full"
    },
    {
      "x": -12,
      "y": 17,
      "z": 7,
      "name": "Wood_Ash_Trunk"
    },
    {
      "x": -12,
      "y": 18,
      "z": 7,
      "name": "Wood_Ash_Trunk"
    },
    {
      "x": -12,
      "y": 19,
      "z": 7,
      "name": "Wood_Ash_Trunk"
    },
    {
      "x": -12,
      "y": 20,
      "z": 7,
      "name": "Wood_Ash_Trunk"
    },
    {
      "x": -12,
      "y": 21,
      "z": 7,
      "name": "Wood_Ash_Trunk"
    },
    {
      "x": -12,
      "y": 22,
      "z": 7,
      "name": "Wood_Ash_Trunk"
    },
    {
      "x": -12,
      "y": 23,
      "z": 7,
      "name": "Wood_Ash_Trunk_Full"
    },
    {
      "x": -12,
      "y": 3,
      "z": 8,
      "name": "Rock_Basalt"
    },
    {
      "x": -12,
      "y": 4,
      "z": 8,
      "name": "Ore_Iron_Basalt_Cracked"
    },
    {
      "x": -12,
      "y": 5,
      "z": 8,
      "name": "Rock_Basalt"
    },
    {
      "x": -12,
      "y": 6,
      "z": 8,
      "name": "Rock_Basalt"
    },
    {
      "x": -12,
      "y": 7,
      "z": 8,
      "name": "Rock_Basalt"
    },
    {
      "x": -12,
      "y": 8,
      "z": 8,
      "name": "Ore_Iron_Basalt_Cracked"
    },
    {
      "x": -12,
      "y": 9,
      "z": 8,
      "name": "Ore_Iron_Basalt_Cracked"
    },
    {
      "x": -12,
      "y": 10,
      "z": 8,
      "name": "Rock_Basalt"
    },
    {
      "x": -12,
      "y": 11,
      "z": 8,
      "name": "Rock_Basalt"
    },
    {
      "x": -12,
      "y": 12,
      "z": 8,
      "name": "Ore_Iron_Basalt_Cracked"
    },
    {
      "x": -12,
      "y": 13,
      "z": 8,
      "name": "Ore_Iron_Basalt_Cracked"
    },
    {
      "x": -12,
      "y": 14,
      "z": 8,
      "name": "Rock_Basalt"
    },
    {
      "x": -12,
      "y": 15,
      "z": 8,
      "name": "Wood_Ash_Trunk_Full"
    },
    {
      "x": -12,
      "y": 16,
      "z": 8,
      "name": "Wood_Ash_Trunk"
    },
    {
      "x": -12,
      "y": 17,
      "z": 8,
      "name": "Wood_Ash_Trunk_Full"
    },
    {
      "x": -12,
      "y": 20,
      "z": 8,
      "name": "Wood_Ash_Trunk_Full"
    },
    {
      "x": -12,
      "y": 21,
      "z": 8,
      "name": "Wood_Ash_Trunk"
    },
    {
      "x": -12,
      "y": 22,
      "z": 8,
      "name": "Wood_Ash_Trunk"
    },
    {
      "x": -12,
      "y": 23,
      "z": 8,
      "name": "Wood_Ash_Trunk_Full"
    },
    {
      "x": -12,
      "y": 3,
      "z": 9,
      "name": "Rock_Basalt"
    },
    {
      "x": -12,
      "y": 4,
      "z": 9,
      "name": "Rock_Basalt"
    },
    {
      "x": -12,
      "y": 5,
      "z": 9,
      "name": "Ore_Iron_Basalt_Cracked"
    },
    {
      "x": -12,
      "y": 6,
      "z": 9,
      "name": "Rock_Basalt"
    },
    {
      "x": -12,
      "y": 7,
      "z": 9,
      "name": "Rock_Basalt"
    },
    {
      "x": -12,
      "y": 8,
      "z": 9,
      "name": "Rock_Basalt"
    },
    {
      "x": -12,
      "y": 9,
      "z": 9,
      "name": "Ore_Iron_Basalt_Cracked"
    },
    {
      "x": -12,
      "y": 10,
      "z": 9,
      "name": "Rock_Basalt"
    },
    {
      "x": -12,
      "y": 11,
      "z": 9,
      "name": "Rock_Basalt"
    },
    {
      "x": -12,
      "y": 12,
      "z": 9,
      "name": "Wood_Ash_Trunk_Full"
    },
    {
      "x": -12,
      "y": 13,
      "z": 9,
      "name": "Wood_Ash_Trunk_Full"
    },
    {
      "x": -12,
      "y": 14,
      "z": 9,
      "name": "Rock_Basalt"
    },
    {
      "x": -12,
      "y": 15,
      "z": 9,
      "name": "Rock_Basalt"
    },
    {
      "x": -12,
      "y": 16,
      "z": 9,
      "name": "Ore_Iron_Basalt_Cracked"
    },
    {
      "x": -12,
      "y": 17,
      "z": 9,
      "name": "Soil_Ash"
    },
    {
      "x": -12,
      "y": 23,
      "z": 9,
      "name": "Deco_SpiderWeb_Flat",
      "rotation": 4
    },
    {
      "x": -12,
      "y": 3,
      "z": 10,
      "name": "Rock_Basalt"
    },
    {
      "x": -12,
      "y": 4,
      "z": 10,
      "name": "Ore_Iron_Basalt_Cracked"
    },
    {
      "x": -12,
      "y": 5,
      "z": 10,
      "name": "Rock_Basalt"
    },
    {
      "x": -12,
      "y": 6,
      "z": 10,
      "name": "Rock_Basalt"
    },
    {
      "x": -12,
      "y": 7,
      "z": 10,
      "name": "Rock_Basalt"
    },
    {
      "x": -12,
      "y": 8,
      "z": 10,
      "name": "Rock_Basalt"
    },
    {
      "x": -12,
      "y": 9,
      "z": 10,
      "name": "Ore_Iron_Basalt_Cracked"
    },
    {
      "x": -12,
      "y": 10,
      "z": 10,
      "name": "Rock_Basalt"
    },
    {
      "x": -12,
      "y": 11,
      "z": 10,
      "name": "Rock_Basalt"
    },
    {
      "x": -12,
      "y": 12,
      "z": 10,
      "name": "Rock_Basalt"
    },
    {
      "x": -12,
      "y": 13,
      "z": 10,
      "name": "Rock_Basalt"
    },
    {
      "x": -12,
      "y": 14,
      "z": 10,
      "name": "Ore_Iron_Basalt_Cracked"
    },
    {
      "x": -12,
      "y": 15,
      "z": 10,
      "name": "Ore_Iron_Basalt_Cracked"
    },
    {
      "x": -12,
      "y": 16,
      "z": 10,
      "name": "Ore_Iron_Basalt_Cracked"
    },
    {
      "x": -12,
      "y": 17,
      "z": 10,
      "name": "Soil_Ash"
    },
    {
      "x": -12,
      "y": 5,
      "z": 11,
      "name": "Rock_Basalt"
    },
    {
      "x": -12,
      "y": 6,
      "z": 11,
      "name": "Rock_Basalt"
    },
    {
      "x": -12,
      "y": 7,
      "z": 11,
      "name": "Rock_Basalt"
    },
    {
      "x": -12,
      "y": 8,
      "z": 11,
      "name": "Rock_Basalt"
    },
    {
      "x": -12,
      "y": 9,
      "z": 11,
      "name": "Rock_Basalt"
    },
    {
      "x": -12,
      "y": 10,
      "z": 11,
      "name": "Ore_Iron_Basalt_Cracked"
    },
    {
      "x": -12,
      "y": 11,
      "z": 11,
      "name": "Rock_Basalt"
    },
    {
      "x": -12,
      "y": 12,
      "z": 11,
      "name": "Ore_Iron_Basalt_Cracked"
    },
    {
      "x": -12,
      "y": 13,
      "z": 11,
      "name": "Ore_Iron_Basalt_Cracked"
    },
    {
      "x": -12,
      "y": 14,
      "z": 11,
      "name": "Rock_Basalt"
    },
    {
      "x": -12,
      "y": 15,
      "z": 11,
      "name": "Ore_Iron_Basalt"
    },
    {
      "x": -12,
      "y": 16,
      "z": 11,
      "name": "Rock_Basalt"
    },
    {
      "x": -12,
      "y": 17,
      "z": 11,
      "name": "Soil_Ash"
    },
    {
      "x": -12,
      "y": 31,
      "z": 11,
      "name": "Wood_Ash_Trunk_Full"
    },
    {
      "x": -12,
      "y": 32,
      "z": 11,
      "name": "Wood_Ash_Trunk"
    },
    {
      "x": -12,
      "y": 33,
      "z": 11,
      "name": "Wood_Ash_Trunk"
    },
    {
      "x": -12,
      "y": 34,
      "z": 11,
      "name": "Wood_Ash_Trunk"
    },
    {
      "x": -12,
      "y": 35,
      "z": 11,
      "name": "Wood_Ash_Trunk_Full"
    },
    {
      "x": -12,
      "y": 8,
      "z": 12,
      "name": "Rock_Basalt"
    },
    {
      "x": -12,
      "y": 9,
      "z": 12,
      "name": "Rock_Basalt"
    },
    {
      "x": -12,
      "y": 10,
      "z": 12,
      "name": "Ore_Iron_Basalt_Cracked"
    },
    {
      "x": -12,
      "y": 11,
      "z": 12,
      "name": "Ore_Iron_Basalt_Cracked"
    },
    {
      "x": -12,
      "y": 12,
      "z": 12,
      "name": "Rock_Basalt"
    },
    {
      "x": -12,
      "y": 13,
      "z": 12,
      "name": "Rock_Basalt"
    },
    {
      "x": -12,
      "y": 14,
      "z": 12,
      "name": "Rock_Basalt"
    },
    {
      "x": -12,
      "y": 15,
      "z": 12,
      "name": "Ore_Iron_Basalt_Cracked"
    },
    {
      "x": -12,
      "y": 16,
      "z": 12,
      "name": "Ore_Iron_Basalt_Cracked"
    },
    {
      "x": -12,
      "y": 17,
      "z": 12,
      "name": "Soil_Ash"
    },
    {
      "x": -12,
      "y": 18,
      "z": 12,
      "name": "Deco_SpiderWeb_Flat"
    },
    {
      "x": -12,
      "y": 32,
      "z": 12,
      "name": "Wood_Ash_Branch_Long",
      "rotation": 4
    },
    {
      "x": -12,
      "y": 10,
      "z": 13,
      "name": "Rock_Basalt"
    },
    {
      "x": -12,
      "y": 11,
      "z": 13,
      "name": "Rock_Basalt"
    },
    {
      "x": -12,
      "y": 12,
      "z": 13,
      "name": "Ore_Iron_Basalt_Cracked"
    },
    {
      "x": -12,
      "y": 13,
      "z": 13,
      "name": "Rock_Basalt"
    },
    {
      "x": -12,
      "y": 14,
      "z": 13,
      "name": "Rock_Basalt"
    },
    {
      "x": -12,
      "y": 15,
      "z": 13,
      "name": "Ore_Iron_Basalt_Cracked"
    },
    {
      "x": -12,
      "y": 16,
      "z": 13,
      "name": "Rock_Basalt"
    },
    {
      "x": -12,
      "y": 17,
      "z": 13,
      "name": "Soil_Ash"
    },
    {
      "x": -12,
      "y": 18,
      "z": 13,
      "name": "Deco_SpiderWeb_Flat"
    },
    {
      "x": -12,
      "y": 8,
      "z": 14,
      "name": "Rock_Crystal_Purple_Medium",
      "rotation": 5
    },
    {
      "x": -12,
      "y": 9,
      "z": 14,
      "name": "Rock_Crystal_Purple_Medium",
      "rotation": 5
    },
    {
      "x": -12,
      "y": 12,
      "z": 14,
      "name": "Rock_Basalt"
    },
    {
      "x": -12,
      "y": 13,
      "z": 14,
      "name": "Rock_Basalt"
    },
    {
      "x": -12,
      "y": 14,
      "z": 14,
      "name": "Rock_Basalt"
    },
    {
      "x": -12,
      "y": 15,
      "z": 14,
      "name": "Rock_Basalt"
    },
    {
      "x": -12,
      "y": 16,
      "z": 14,
      "name": "Ore_Iron_Basalt_Cracked"
    },
    {
      "x": -12,
      "y": 17,
      "z": 14,
      "name": "Soil_Ash"
    },
    {
      "x": -11,
      "y": 13,
      "z": -12,
      "name": "Rock_Basalt"
    },
    {
      "x": -11,
      "y": 14,
      "z": -12,
      "name": "Rock_Basalt"
    },
    {
      "x": -11,
      "y": 15,
      "z": -12,
      "name": "Ore_Iron_Basalt_Cracked"
    },
    {
      "x": -11,
      "y": 16,
      "z": -12,
      "name": "Soil_Sand_Ashen"
    },
    {
      "x": -11,
      "y": 10,
      "z": -11,
      "name": "Rock_Basalt_Stalactite_Large",
      "filler": 31744,
      "rotation": 8
    },
    {
      "x": -11,
      "y": 11,
      "z": -11,
      "name": "Rock_Basalt_Stalactite_Large",
      "rotation": 8
    },
    {
      "x": -11,
      "y": 12,
      "z": -11,
      "name": "Rock_Basalt"
    },
    {
      "x": -11,
      "y": 13,
      "z": -11,
      "name": "Rock_Basalt"
    },
    {
      "x": -11,
      "y": 14,
      "z": -11,
      "name": "Ore_Iron_Basalt_Cracked"
    },
    {
      "x": -11,
      "y": 15,
      "z": -11,
      "name": "Ore_Iron_Basalt_Cracked"
    },
    {
      "x": -11,
      "y": 16,
      "z": -11,
      "name": "Soil_Sand_Ashen"
    },
    {
      "x": -11,
      "y": 11,
      "z": -10,
      "name": "Rock_Basalt_Stalactite_Large",
      "filler": 31744,
      "rotation": 8
    },
    {
      "x": -11,
      "y": 12,
      "z": -10,
      "name": "Rock_Basalt_Stalactite_Large",
      "rotation": 8
    },
    {
      "x": -11,
      "y": 13,
      "z": -10,
      "name": "Rock_Basalt"
    },
    {
      "x": -11,
      "y": 14,
      "z": -10,
      "name": "Ore_Iron_Basalt_Cracked"
    },
    {
      "x": -11,
      "y": 15,
      "z": -10,
      "name": "Rock_Basalt"
    },
    {
      "x": -11,
      "y": 16,
      "z": -10,
      "name": "Soil_Sand_Ashen"
    },
    {
      "x": -11,
      "y": 16,
      "z": -9,
      "name": "Plant_Vine_Wall_Dead"
    },
    {
      "x": -11,
      "y": 9,
      "z": 3,
      "name": "Rock_Basalt_Stalactite_Large",
      "filler": 31744,
      "rotation": 8
    },
    {
      "x": -11,
      "y": 10,
      "z": 3,
      "name": "Rock_Basalt_Stalactite_Large",
      "rotation": 8
    },
    {
      "x": -11,
      "y": 11,
      "z": 3,
      "name": "Ore_Iron_Basalt_Cracked"
    },
    {
      "x": -11,
      "y": 12,
      "z": 3,
      "name": "Ore_Iron_Basalt"
    },
    {
      "x": -11,
      "y": 13,
      "z": 3,
      "name": "Rock_Basalt"
    },
    {
      "x": -11,
      "y": 14,
      "z": 3,
      "name": "Soil_Sand_Ashen"
    },
    {
      "x": -11,
      "y": 29,
      "z": 3,
      "name": "Deco_SpiderWeb_Flat",
      "rotation": 6
    },
    {
      "x": -11,
      "y": 7,
      "z": 4,
      "name": "Rock_Basalt"
    },
    {
      "x": -11,
      "y": 8,
      "z": 4,
      "name": "Ore_Iron_Basalt_Cracked"
    },
    {
      "x": -11,
      "y": 9,
      "z": 4,
      "name": "Rock_Basalt"
    },
    {
      "x": -11,
      "y": 10,
      "z": 4,
      "name": "Rock_Basalt"
    },
    {
      "x": -11,
      "y": 11,
      "z": 4,
      "name": "Rock_Basalt"
    },
    {
      "x": -11,
      "y": 12,
      "z": 4,
      "name": "Rock_Basalt"
    },
    {
      "x": -11,
      "y": 13,
      "z": 4,
      "name": "Rock_Basalt"
    },
    {
      "x": -11,
      "y": 14,
      "z": 4,
      "name": "Wood_Ash_Trunk_Full"
    },
    {
      "x": -11,
      "y": 15,
      "z": 4,
      "name": "Wood_Ash_Trunk"
    },
    {
      "x": -11,
      "y": 16,
      "z": 4,
      "name": "Wood_Ash_Trunk_Full"
    },
    {
      "x": -11,
      "y": 27,
      "z": 4,
      "name": "Wood_Ash_Roots"
    },
    {
      "x": -11,
      "y": 28,
      "z": 4,
      "name": "Wood_Ash_Trunk_Full"
    },
    {
      "x": -11,
      "y": 29,
      "z": 4,
      "name": "Wood_Ash_Trunk"
    },
    {
      "x": -11,
      "y": 30,
      "z": 4,
      "name": "Wood_Ash_Trunk"
    },
    {
      "x": -11,
      "y": 31,
      "z": 4,
      "name": "Wood_Ash_Trunk"
    },
    {
      "x": -11,
      "y": 32,
      "z": 4,
      "name": "Wood_Ash_Trunk_Full"
    },
    {
      "x": -11,
      "y": 3,
      "z": 5,
      "name": "Rock_Basalt_Stalactite_Large",
      "filler": 31744,
      "rotation": 8
    },
    {
      "x": -11,
      "y": 4,
      "z": 5,
      "name": "Rock_Basalt_Stalactite_Large",
      "rotation": 8
    },
    {
      "x": -11,
      "y": 5,
      "z": 5,
      "name": "Rock_Basalt"
    },
    {
      "x": -11,
      "y": 6,
      "z": 5,
      "name": "Rock_Basalt"
    },
    {
      "x": -11,
      "y": 7,
      "z": 5,
      "name": "Rock_Basalt"
    },
    {
      "x": -11,
      "y": 8,
      "z": 5,
      "name": "Rock_Basalt"
    },
    {
      "x": -11,
      "y": 9,
      "z": 5,
      "name": "Rock_Basalt"
    },
    {
      "x": -11,
      "y": 10,
      "z": 5,
      "name": "Rock_Basalt"
    },
    {
      "x": -11,
      "y": 11,
      "z": 5,
      "name": "Rock_Basalt"
    },
    {
      "x": -11,
      "y": 12,
      "z": 5,
      "name": "Ore_Iron_Basalt_Cracked"
    },
    {
      "x": -11,
      "y": 13,
      "z": 5,
      "name": "Ore_Iron_Basalt_Cracked"
    },
    {
      "x": -11,
      "y": 14,
      "z": 5,
      "name": "Rock_Basalt"
    },
    {
      "x": -11,
      "y": 15,
      "z": 5,
      "name": "Soil_Sand_Ashen"
    },
    {
      "x": -11,
      "y": 16,
      "z": 5,
      "name": "Wood_Ash_Trunk_Full"
    },
    {
      "x": -11,
      "y": 17,
      "z": 5,
      "name": "Wood_Ash_Trunk_Full"
    },
    {
      "x": -11,
      "y": 28,
      "z": 5,
      "name": "Wood_Ash_Trunk_Full"
    },
    {
      "x": -11,
      "y": 29,
      "z": 5,
      "name": "Wood_Ash_Trunk"
    },
    {
      "x": -11,
      "y": 30,
      "z": 5,
      "name": "Wood_Ash_Trunk_Full"
    },
    {
      "x": -11,
      "y": 5,
      "z": 6,
      "name": "Rock_Basalt"
    },
    {
      "x": -11,
      "y": 6,
      "z": 6,
      "name": "Rock_Basalt"
    },
    {
      "x": -11,
      "y": 7,
      "z": 6,
      "name": "Ore_Iron_Basalt_Cracked"
    },
    {
      "x": -11,
      "y": 8,
      "z": 6,
      "name": "Rock_Basalt"
    },
    {
      "x": -11,
      "y": 9,
      "z": 6,
      "name": "Rock_Basalt"
    },
    {
      "x": -11,
      "y": 10,
      "z": 6,
      "name": "Ore_Iron_Basalt_Cracked"
    },
    {
      "x": -11,
      "y": 11,
      "z": 6,
      "name": "Rock_Basalt"
    },
    {
      "x": -11,
      "y": 12,
      "z": 6,
      "name": "Rock_Basalt"
    },
    {
      "x": -11,
      "y": 13,
      "z": 6,
      "name": "Rock_Basalt"
    },
    {
      "x": -11,
      "y": 14,
      "z": 6,
      "name": "Rock_Basalt"
    },
    {
      "x": -11,
      "y": 15,
      "z": 6,
      "name": "Ore_Iron_Basalt_Cracked"
    },
    {
      "x": -11,
      "y": 16,
      "z": 6,
      "name": "Soil_Ash"
    },
    {
      "x": -11,
      "y": 17,
      "z": 6,
      "name": "Wood_Ash_Trunk_Full"
    },
    {
      "x": -11,
      "y": 23,
      "z": 6,
      "name": "Deco_SpiderWeb_Flat",
      "rotation": 6
    },
    {
      "x": -11,
      "y": 24,
      "z": 6,
      "name": "Deco_SpiderWeb_Flat",
      "rotation": 6
    },
    {
      "x": -11,
      "y": 5,
      "z": 7,
      "name": "Ore_Iron_Basalt_Cracked"
    },
    {
      "x": -11,
      "y": 6,
      "z": 7,
      "name": "Ore_Iron_Basalt_Cracked"
    },
    {
      "x": -11,
      "y": 7,
      "z": 7,
      "name": "Rock_Basalt"
    },
    {
      "x": -11,
      "y": 8,
      "z": 7,
      "name": "Rock_Basalt"
    },
    {
      "x": -11,
      "y": 9,
      "z": 7,
      "name": "Rock_Basalt"
    },
    {
      "x": -11,
      "y": 10,
      "z": 7,
      "name": "Rock_Basalt"
    },
    {
      "x": -11,
      "y": 11,
      "z": 7,
      "name": "Rock_Basalt"
    },
    {
      "x": -11,
      "y": 12,
      "z": 7,
      "name": "Rock_Basalt"
    },
    {
      "x": -11,
      "y": 13,
      "z": 7,
      "name": "Rock_Basalt"
    },
    {
      "x": -11,
      "y": 14,
      "z": 7,
      "name": "Ore_Iron_Basalt_Cracked"
    },
    {
      "x": -11,
      "y": 15,
      "z": 7,
      "name": "Ore_Iron_Basalt_Cracked"
    },
    {
      "x": -11,
      "y": 16,
      "z": 7,
      "name": "Rock_Basalt"
    },
    {
      "x": -11,
      "y": 17,
      "z": 7,
      "name": "Soil_Ash"
    },
    {
      "x": -11,
      "y": 22,
      "z": 7,
      "name": "Wood_Ash_Trunk_Full"
    },
    {
      "x": -11,
      "y": 23,
      "z": 7,
      "name": "Wood_Ash_Trunk"
    },
    {
      "x": -11,
      "y": 24,
      "z": 7,
      "name": "Wood_Ash_Trunk_Full"
    },
    {
      "x": -11,
      "y": 4,
      "z": 8,
      "name": "Rock_Basalt_Stalactite_Small",
      "rotation": 8
    },
    {
      "x": -11,
      "y": 5,
      "z": 8,
      "name": "Rock_Basalt"
    },
    {
      "x": -11,
      "y": 6,
      "z": 8,
      "name": "Ore_Iron_Basalt_Cracked"
    },
    {
      "x": -11,
      "y": 7,
      "z": 8,
      "name": "Rock_Basalt"
    },
    {
      "x": -11,
      "y": 8,
      "z": 8,
      "name": "Ore_Iron_Basalt_Cracked"
    },
    {
      "x": -11,
      "y": 9,
      "z": 8,
      "name": "Rock_Basalt"
    },
    {
      "x": -11,
      "y": 10,
      "z": 8,
      "name": "Ore_Iron_Basalt_Cracked"
    },
    {
      "x": -11,
      "y": 11,
      "z": 8,
      "name": "Rock_Basalt"
    },
    {
      "x": -11,
      "y": 12,
      "z": 8,
      "name": "Ore_Iron_Basalt_Cracked"
    },
    {
      "x": -11,
      "y": 13,
      "z": 8,
      "name": "Wood_Ash_Roots"
    },
    {
      "x": -11,
      "y": 14,
      "z": 8,
      "name": "Wood_Ash_Trunk_Full"
    },
    {
      "x": -11,
      "y": 15,
      "z": 8,
      "name": "Wood_Ash_Trunk"
    },
    {
      "x": -11,
      "y": 16,
      "z": 8,
      "name": "Wood_Ash_Trunk_Full"
    },
    {
      "x": -11,
      "y": 17,
      "z": 8,
      "name": "Soil_Ash"
    },
    {
      "x": -11,
      "y": 21,
      "z": 8,
      "name": "Wood_Ash_Trunk_Full"
    },
    {
      "x": -11,
      "y": 22,
      "z": 8,
      "name": "Wood_Ash_Trunk"
    },
    {
      "x": -11,
      "y": 23,
      "z": 8,
      "name": "Wood_Ash_Trunk"
    },
    {
      "x": -11,
      "y": 24,
      "z": 8,
      "name": "Wood_Ash_Trunk"
    },
    {
      "x": -11,
      "y": 25,
      "z": 8,
      "name": "Wood_Ash_Trunk_Full"
    },
    {
      "x": -11,
      "y": 2,
      "z": 9,
      "name": "Rock_Basalt_Stalactite_Large",
      "filler": 31744,
      "rotation": 8
    },
    {
      "x": -11,
      "y": 3,
      "z": 9,
      "name": "Rock_Basalt_Stalactite_Large",
      "rotation": 8
    },
    {
      "x": -11,
      "y": 4,
      "z": 9,
      "name": "Rock_Basalt"
    },
    {
      "x": -11,
      "y": 5,
      "z": 9,
      "name": "Ore_Iron_Basalt_Cracked"
    },
    {
      "x": -11,
      "y": 6,
      "z": 9,
      "name": "Rock_Basalt"
    },
    {
      "x": -11,
      "y": 7,
      "z": 9,
      "name": "Ore_Iron_Basalt_Cracked"
    },
    {
      "x": -11,
      "y": 8,
      "z": 9,
      "name": "Rock_Basalt"
    },
    {
      "x": -11,
      "y": 9,
      "z": 9,
      "name": "Ore_Iron_Basalt_Cracked"
    },
    {
      "x": -11,
      "y": 10,
      "z": 9,
      "name": "Ore_Iron_Basalt_Cracked"
    },
    {
      "x": -11,
      "y": 11,
      "z": 9,
      "name": "Ore_Iron_Basalt_Cracked"
    },
    {
      "x": -11,
      "y": 12,
      "z": 9,
      "name": "Ore_Iron_Basalt_Cracked"
    },
    {
      "x": -11,
      "y": 13,
      "z": 9,
      "name": "Wood_Ash_Trunk_Full"
    },
    {
      "x": -11,
      "y": 14,
      "z": 9,
      "name": "Wood_Ash_Trunk_Full"
    },
    {
      "x": -11,
      "y": 15,
      "z": 9,
      "name": "Ore_Iron_Basalt"
    },
    {
      "x": -11,
      "y": 16,
      "z": 9,
      "name": "Ore_Iron_Basalt_Cracked"
    },
    {
      "x": -11,
      "y": 17,
      "z": 9,
      "name": "Soil_Ash"
    },
    {
      "x": -11,
      "y": 22,
      "z": 9,
      "name": "Wood_Ash_Trunk_Full"
    },
    {
      "x": -11,
      "y": 23,
      "z": 9,
      "name": "Wood_Ash_Trunk"
    },
    {
      "x": -11,
      "y": 24,
      "z": 9,
      "name": "Wood_Ash_Trunk"
    },
    {
      "x": -11,
      "y": 25,
      "z": 9,
      "name": "Wood_Ash_Trunk"
    },
    {
      "x": -11,
      "y": 26,
      "z": 9,
      "name": "Wood_Ash_Trunk"
    },
    {
      "x": -11,
      "y": 27,
      "z": 9,
      "name": "Wood_Ash_Trunk"
    },
    {
      "x": -11,
      "y": 28,
      "z": 9,
      "name": "Wood_Ash_Trunk_Full"
    },
    {
      "x": -11,
      "y": 5,
      "z": 10,
      "name": "Ore_Iron_Basalt_Cracked"
    },
    {
      "x": -11,
      "y": 6,
      "z": 10,
      "name": "Rock_Basalt"
    },
    {
      "x": -11,
      "y": 7,
      "z": 10,
      "name": "Rock_Basalt"
    },
    {
      "x": -11,
      "y": 8,
      "z": 10,
      "name": "Ore_Iron_Basalt_Cracked"
    },
    {
      "x": -11,
      "y": 9,
      "z": 10,
      "name": "Rock_Basalt"
    },
    {
      "x": -11,
      "y": 10,
      "z": 10,
      "name": "Rock_Basalt"
    },
    {
      "x": -11,
      "y": 11,
      "z": 10,
      "name": "Rock_Basalt"
    },
    {
      "x": -11,
      "y": 12,
      "z": 10,
      "name": "Rock_Basalt"
    },
    {
      "x": -11,
      "y": 13,
      "z": 10,
      "name": "Rock_Basalt"
    },
    {
      "x": -11,
      "y": 14,
      "z": 10,
      "name": "Rock_Basalt"
    },
    {
      "x": -11,
      "y": 15,
      "z": 10,
      "name": "Ore_Iron_Basalt_Cracked"
    },
    {
      "x": -11,
      "y": 16,
      "z": 10,
      "name": "Ore_Iron_Basalt_Cracked"
    },
    {
      "x": -11,
      "y": 17,
      "z": 10,
      "name": "Soil_Ash"
    },
    {
      "x": -11,
      "y": 18,
      "z": 10,
      "name": "Plant_Bush_Dead_Twisted"
    },
    {
      "x": -11,
      "y": 26,
      "z": 10,
      "name": "Wood_Ash_Trunk_Full"
    },
    {
      "x": -11,
      "y": 27,
      "z": 10,
      "name": "Wood_Ash_Trunk"
    },
    {
      "x": -11,
      "y": 28,
      "z": 10,
      "name": "Wood_Ash_Trunk"
    },
    {
      "x": -11,
      "y": 29,
      "z": 10,
      "name": "Wood_Ash_Trunk"
    },
    {
      "x": -11,
      "y": 30,
      "z": 10,
      "name": "Wood_Ash_Trunk"
    },
    {
      "x": -11,
      "y": 31,
      "z": 10,
      "name": "Wood_Ash_Trunk_Full"
    },
    {
      "x": -11,
      "y": 7,
      "z": 11,
      "name": "Rock_Basalt"
    },
    {
      "x": -11,
      "y": 8,
      "z": 11,
      "name": "Rock_Basalt"
    },
    {
      "x": -11,
      "y": 9,
      "z": 11,
      "name": "Ore_Iron_Basalt_Cracked"
    },
    {
      "x": -11,
      "y": 10,
      "z": 11,
      "name": "Rock_Basalt"
    },
    {
      "x": -11,
      "y": 11,
      "z": 11,
      "name": "Ore_Iron_Basalt_Cracked"
    },
    {
      "x": -11,
      "y": 12,
      "z": 11,
      "name": "Ore_Iron_Basalt_Cracked"
    },
    {
      "x": -11,
      "y": 13,
      "z": 11,
      "name": "Rock_Basalt"
    },
    {
      "x": -11,
      "y": 14,
      "z": 11,
      "name": "Rock_Basalt"
    },
    {
      "x": -11,
      "y": 15,
      "z": 11,
      "name": "Ore_Iron_Basalt"
    },
    {
      "x": -11,
      "y": 16,
      "z": 11,
      "name": "Rock_Basalt"
    },
    {
      "x": -11,
      "y": 17,
      "z": 11,
      "name": "Soil_Ash"
    },
    {
      "x": -11,
      "y": 26,
      "z": 11,
      "name": "Deco_SpiderWeb_Flat",
      "rotation": 4
    },
    {
      "x": -11,
      "y": 27,
      "z": 11,
      "name": "Deco_SpiderWeb_Flat",
      "rotation": 4
    },
    {
      "x": -11,
      "y": 30,
      "z": 11,
      "name": "Wood_Ash_Trunk_Full"
    },
    {
      "x": -11,
      "y": 31,
      "z": 11,
      "name": "Wood_Ash_Trunk"
    },
    {
      "x": -11,
      "y": 32,
      "z": 11,
      "name": "Wood_Ash_Trunk_Full"
    },
    {
      "x": -11,
      "y": 9,
      "z": 12,
      "name": "Rock_Basalt"
    },
    {
      "x": -11,
      "y": 10,
      "z": 12,
      "name": "Rock_Basalt"
    },
    {
      "x": -11,
      "y": 11,
      "z": 12,
      "name": "Rock_Basalt"
    },
    {
      "x": -11,
      "y": 12,
      "z": 12,
      "name": "Rock_Basalt"
    },
    {
      "x": -11,
      "y": 13,
      "z": 12,
      "name": "Ore_Iron_Basalt_Cracked"
    },
    {
      "x": -11,
      "y": 14,
      "z": 12,
      "name": "Rock_Basalt"
    },
    {
      "x": -11,
      "y": 15,
      "z": 12,
      "name": "Ore_Iron_Basalt_Cracked"
    },
    {
      "x": -11,
      "y": 16,
      "z": 12,
      "name": "Soil_Ash"
    },
    {
      "x": -11,
      "y": 17,
      "z": 12,
      "name": "Deco_Spider_Cocoon"
    },
    {
      "x": -11,
      "y": 18,
      "z": 12,
      "name": "Deco_Spider_Cocoon",
      "filler": 1024
    },
    {
      "x": -11,
      "y": 13,
      "z": 13,
      "name": "Rock_Basalt"
    },
    {
      "x": -11,
      "y": 14,
      "z": 13,
      "name": "Ore_Iron_Basalt_Cracked"
    },
    {
      "x": -11,
      "y": 15,
      "z": 13,
      "name": "Rock_Basalt"
    },
    {
      "x": -11,
      "y": 16,
      "z": 13,
      "name": "Rock_Basalt"
    },
    {
      "x": -11,
      "y": 17,
      "z": 13,
      "name": "Soil_Ash"
    },
    {
      "x": -11,
      "y": 18,
      "z": 13,
      "name": "Deco_SpiderWeb_Flat"
    },
    {
      "x": -11,
      "y": 16,
      "z": 14,
      "name": "Plant_Vine_Wall_Dead"
    },
    {
      "x": -10,
      "y": 11,
      "z": -13,
      "name": "Rock_Basalt"
    },
    {
      "x": -10,
      "y": 12,
      "z": -13,
      "name": "Rock_Basalt"
    },
    {
      "x": -10,
      "y": 13,
      "z": -13,
      "name": "Rock_Basalt"
    },
    {
      "x": -10,
      "y": 14,
      "z": -13,
      "name": "Rock_Basalt"
    },
    {
      "x": -10,
      "y": 15,
      "z": -13,
      "name": "Rock_Basalt"
    },
    {
      "x": -10,
      "y": 16,
      "z": -13,
      "name": "Rock_Basalt_Brick"
    },
    {
      "x": -10,
      "y": 17,
      "z": -13,
      "name": "Rock_Basalt_Brick_Pillar_Base"
    },
    {
      "x": -10,
      "y": 18,
      "z": -13,
      "name": "Rock_Basalt_Brick_Pillar_Middle"
    },
    {
      "x": -10,
      "y": 19,
      "z": -13,
      "name": "Rock_Basalt_Brick_Pillar_Middle"
    },
    {
      "x": -10,
      "y": 9,
      "z": -12,
      "name": "Rock_Basalt"
    },
    {
      "x": -10,
      "y": 10,
      "z": -12,
      "name": "Rock_Basalt"
    },
    {
      "x": -10,
      "y": 11,
      "z": -12,
      "name": "Rock_Basalt"
    },
    {
      "x": -10,
      "y": 12,
      "z": -12,
      "name": "Rock_Basalt"
    },
    {
      "x": -10,
      "y": 13,
      "z": -12,
      "name": "Ore_Iron_Basalt_Cracked"
    },
    {
      "x": -10,
      "y": 14,
      "z": -12,
      "name": "Ore_Iron_Basalt_Cracked"
    },
    {
      "x": -10,
      "y": 15,
      "z": -12,
      "name": "Ore_Iron_Basalt_Cracked"
    },
    {
      "x": -10,
      "y": 16,
      "z": -12,
      "name": "Rock_Basalt_Brick"
    },
    {
      "x": -10,
      "y": 6,
      "z": -11,
      "name": "Rock_Crystal_Yellow_Medium",
      "rotation": 7
    },
    {
      "x": -10,
      "y": 7,
      "z": -11,
      "name": "Rock_Crystal_Yellow_Medium",
      "rotation": 7
    },
    {
      "x": -10,
      "y": 8,
      "z": -11,
      "name": "Rock_Basalt"
    },
    {
      "x": -10,
      "y": 9,
      "z": -11,
      "name": "Ore_Iron_Basalt_Cracked"
    },
    {
      "x": -10,
      "y": 10,
      "z": -11,
      "name": "Ore_Iron_Basalt_Cracked"
    },
    {
      "x": -10,
      "y": 11,
      "z": -11,
      "name": "Ore_Iron_Basalt_Cracked"
    },
    {
      "x": -10,
      "y": 12,
      "z": -11,
      "name": "Rock_Basalt"
    },
    {
      "x": -10,
      "y": 13,
      "z": -11,
      "name": "Ore_Iron_Basalt_Cracked"
    },
    {
      "x": -10,
      "y": 14,
      "z": -11,
      "name": "Ore_Iron_Basalt_Cracked"
    },
    {
      "x": -10,
      "y": 15,
      "z": -11,
      "name": "Rock_Basalt"
    },
    {
      "x": -10,
      "y": 16,
      "z": -11,
      "name": "Rock_Basalt_Brick"
    },
    {
      "x": -10,
      "y": 17,
      "z": -11,
