{
  "version": 8,
  "blockIdVersion": 11,
  "anchorX": 0,
  "anchorY": 0,
  "anchorZ": 0,
  "blocks": [
    {
      "x": -16,
      "y": 16,
      "z": 5,
      "name": "Plant_Moss_Wall_Yellow",
      "rotation": 3
    },
    {
      "x": -16,
      "y": 17,
      "z": 5,
      "name": "Plant_Moss_Wall_Yellow",
      "rotation": 3
    },
    {
      "x": -16,
      "y": 15,
      "z": 6,
      "name": "Plant_Moss_Wall_Yellow",
      "rotation": 3
    },
    {
      "x": -16,
      "y": 16,
      "z": 6,
      "name": "Plant_Moss_Wall_Yellow",
      "rotation": 3
    },
    {
      "x": -16,
      "y": 17,
      "z": 6,
      "name": "Plant_Moss_Wall_Yellow",
      "rotation": 3
    },
    {
      "x": -16,
      "y": 18,
      "z": 6,
      "name": "Plant_Moss_Wall_Yellow",
      "rotation": 3
    },
    {
      "x": -16,
      "y": 15,
      "z": 7,
      "name": "Plant_Moss_Wall_Yellow",
      "rotation": 3
    },
    {
      "x": -16,
      "y": 16,
      "z": 7,
      "name": "Plant_Moss_Wall_Yellow",
      "rotation": 3
    },
    {
      "x": -16,
      "y": 17,
      "z": 7,
      "name": "Plant_Moss_Wall_Yellow",
      "rotation": 3
    },
    {
      "x": -16,
      "y": 15,
      "z": 8,
      "name": "Plant_Moss_Wall_Yellow",
      "rotation": 3
    },
    {
      "x": -15,
      "y": 19,
      "z": 0,
      "name": "Plant_Moss_Wall_Yellow",
      "rotation": 3
    },
    {
      "x": -15,
      "y": 20,
      "z": 0,
      "name": "Plant_Moss_Wall_Yellow",
      "rotation": 3
    },
    {
      "x": -15,
      "y": 17,
      "z": 4,
      "name": "Plant_Moss_Wall_Yellow",
      "rotation": 3
    },
    {
      "x": -15,
      "y": 18,
      "z": 4,
      "name": "Plant_Moss_Wall_Yellow",
      "rotation": 3
    },
    {
      "x": -15,
      "y": 19,
      "z": 4,
      "name": "Plant_Moss_Wall_Yellow",
      "rotation": 3
    },
    {
      "x": -15,
      "y": 16,
      "z": 5,
      "name": "Rock_Basalt"
    },
    {
      "x": -15,
      "y": 17,
      "z": 5,
      "name": "Soil_Sand_Ashen"
    },
    {
      "x": -15,
      "y": 18,
      "z": 5,
      "name": "Plant_Moss_Rug_Yellow"
    },
    {
      "x": -15,
      "y": 19,
      "z": 5,
      "name": "Plant_Moss_Wall_Yellow",
      "rotation": 3
    },
    {
      "x": -15,
      "y": 15,
      "z": 6,
      "name": "Rock_Basalt"
    },
    {
      "x": -15,
      "y": 16,
      "z": 6,
      "name": "Ore_Iron_Basalt_Cracked"
    },
    {
      "x": -15,
      "y": 17,
      "z": 6,
      "name": "Soil_Basalt_Gravel"
    },
    {
      "x": -15,
      "y": 18,
      "z": 6,
      "name": "Soil_Sand_Ashen"
    },
    {
      "x": -15,
      "y": 19,
      "z": 6,
      "name": "Plant_Moss_Rug_Yellow"
    },
    {
      "x": -15,
      "y": 15,
      "z": 7,
      "name": "Ore_Iron_Basalt_Cracked"
    },
    {
      "x": -15,
      "y": 16,
      "z": 7,
      "name": "Soil_Basalt_Gravel"
    },
    {
      "x": -15,
      "y": 17,
      "z": 7,
      "name": "Soil_Sand_Ashen"
    },
    {
      "x": -15,
      "y": 18,
      "z": 7,
      "name": "Plant_Moss_Rug_Yellow"
    },
    {
      "x": -15,
      "y": 19,
      "z": 7,
      "name": "Plant_Moss_Wall_Yellow",
      "rotation": 3
    },
    {
      "x": -15,
      "y": 15,
      "z": 8,
      "name": "Ore_Iron_Basalt_Cracked"
    },
    {
      "x": -15,
      "y": 16,
      "z": 8,
      "name": "Plant_Moss_Rug_Yellow"
    },
    {
      "x": -15,
      "y": 18,
      "z": 8,
      "name": "Plant_Moss_Wall_Yellow",
      "rotation": 3
    },
    {
      "x": -15,
      "y": 17,
      "z": 9,
      "name": "Plant_Moss_Wall_Yellow",
      "rotation": 3
    },
    {
      "x": -14,
      "y": 19,
      "z": -2,
      "name": "Plant_Moss_Wall_Yellow",
      "rotation": 3
    },
    {
      "x": -14,
      "y": 20,
      "z": -2,
      "name": "Plant_Moss_Wall_Yellow",
      "rotation": 3
    },
    {
      "x": -14,
      "y": 18,
      "z": -1,
      "name": "Ore_Iron_Basalt_Cracked"
    },
    {
      "x": -14,
      "y": 19,
      "z": -1,
      "name": "Plant_Moss_Rug_Yellow"
    },
    {
      "x": -14,
      "y": 20,
      "z": -1,
      "name": "Plant_Moss_Wall_Yellow",
      "rotation": 3
    },
    {
      "x": -14,
      "y": 18,
      "z": 0,
      "name": "Rock_Basalt"
    },
    {
      "x": -14,
      "y": 19,
      "z": 0,
      "name": "Rock_Basalt"
    },
    {
      "x": -14,
      "y": 20,
      "z": 0,
      "name": "Soil_Ash"
    },
    {
      "x": -14,
      "y": 21,
      "z": 0,
      "name": "Plant_Moss_Rug_Yellow"
    },
    {
      "x": -14,
      "y": 16,
      "z": 1,
      "name": "Deco_SpiderWeb_Flat",
      "rotation": 7
    },
    {
      "x": -14,
      "y": 19,
      "z": 1,
      "name": "Plant_Moss_Wall_Yellow"
    },
    {
      "x": -14,
      "y": 20,
      "z": 1,
      "name": "Plant_Moss_Wall_Yellow"
    },
    {
      "x": -14,
      "y": 17,
      "z": 2,
      "name": "Deco_SpiderWeb_Flat",
      "rotation": 7
    },
    {
      "x": -14,
      "y": 17,
      "z": 3,
      "name": "Plant_Moss_Wall_Yellow",
      "rotation": 2
    },
    {
      "x": -14,
      "y": 18,
      "z": 3,
      "name": "Plant_Moss_Wall_Yellow",
      "rotation": 2
    },
    {
      "x": -14,
      "y": 19,
      "z": 3,
      "name": "Plant_Moss_Wall_Yellow",
      "rotation": 2
    },
    {
      "x": -14,
      "y": 17,
      "z": 4,
      "name": "Ore_Iron_Basalt"
    },
    {
      "x": -14,
      "y": 18,
      "z": 4,
      "name": "Soil_Basalt_Gravel"
    },
    {
      "x": -14,
      "y": 19,
      "z": 4,
      "name": "Soil_Sand_Ashen"
    },
    {
      "x": -14,
      "y": 20,
      "z": 4,
      "name": "Plant_Moss_Rug_Yellow"
    },
    {
      "x": -14,
      "y": 13,
      "z": 5,
      "name": "Rock_Basalt_Stalactite_Large",
      "filler": 31744,
      "rotation": 8
    },
    {
      "x": -14,
      "y": 14,
      "z": 5,
      "name": "Rock_Basalt_Stalactite_Large",
      "rotation": 8
    },
    {
      "x": -14,
      "y": 15,
      "z": 5,
      "name": "Ore_Iron_Basalt_Cracked"
    },
    {
      "x": -14,
      "y": 16,
      "z": 5,
      "name": "Ore_Iron_Basalt_Cracked"
    },
    {
      "x": -14,
      "y": 17,
      "z": 5,
      "name": "Ore_Iron_Basalt_Cracked"
    },
    {
      "x": -14,
      "y": 18,
      "z": 5,
      "name": "Rock_Basalt"
    },
    {
      "x": -14,
      "y": 19,
      "z": 5,
      "name": "Soil_Sand_Ashen"
    },
    {
      "x": -14,
      "y": 20,
      "z": 5,
      "name": "Plant_Moss_Rug_Yellow"
    },
    {
      "x": -14,
      "y": 15,
      "z": 6,
      "name": "Rock_Basalt"
    },
    {
      "x": -14,
      "y": 16,
      "z": 6,
      "name": "Rock_Basalt"
    },
    {
      "x": -14,
      "y": 17,
      "z": 6,
      "name": "Ore_Iron_Basalt_Cracked"
    },
    {
      "x": -14,
      "y": 18,
      "z": 6,
      "name": "Ore_Iron_Basalt_Cracked"
    },
    {
      "x": -14,
      "y": 19,
      "z": 6,
      "name": "Soil_Sand_Ashen"
    },
    {
      "x": -14,
      "y": 20,
      "z": 6,
      "name": "Plant_Moss_Rug_Yellow"
    },
    {
      "x": -14,
      "y": 14,
      "z": 7,
      "name": "Rock_Basalt"
    },
    {
      "x": -14,
      "y": 15,
      "z": 7,
      "name": "Rock_Basalt"
    },
    {
      "x": -14,
      "y": 16,
      "z": 7,
      "name": "Rock_Basalt"
    },
    {
      "x": -14,
      "y": 17,
      "z": 7,
      "name": "Ore_Iron_Basalt_Cracked"
    },
    {
      "x": -14,
      "y": 18,
      "z": 7,
      "name": "Soil_Basalt_Gravel"
    },
    {
      "x": -14,
      "y": 19,
      "z": 7,
      "name": "Soil_Sand_Ashen"
    },
    {
      "x": -14,
      "y": 20,
      "z": 7,
      "name": "Plant_Moss_Rug_Yellow"
    },
    {
      "x": -14,
      "y": 15,
      "z": 8,
      "name": "Ore_Iron_Basalt_Cracked"
    },
    {
      "x": -14,
      "y": 16,
      "z": 8,
      "name": "Rock_Basalt"
    },
    {
      "x": -14,
      "y": 17,
      "z": 8,
      "name": "Rock_Basalt"
    },
    {
      "x": -14,
      "y": 18,
      "z": 8,
      "name": "Rock_Basalt"
    },
    {
      "x": -14,
      "y": 19,
      "z": 8,
      "name": "Plant_Moss_Rug_Yellow"
    },
    {
      "x": -14,
      "y": 17,
      "z": 9,
      "name": "Rock_Basalt"
    },
    {
      "x": -14,
      "y": 18,
      "z": 9,
      "name": "Plant_Moss_Rug_Yellow"
    },
    {
      "x": -14,
      "y": 19,
      "z": 9,
      "name": "Plant_Moss_Wall_Yellow",
      "rotation": 3
    },
    {
      "x": -14,
      "y": 17,
      "z": 10,
      "name": "Plant_Moss_Wall_Yellow",
      "rotation": 3
    },
    {
      "x": -13,
      "y": 19,
      "z": -3,
      "name": "Plant_Moss_Wall_Yellow",
      "rotation": 3
    },
    {
      "x": -13,
      "y": 20,
      "z": -3,
      "name": "Plant_Moss_Wall_Yellow",
      "rotation": 3
    },
    {
      "x": -13,
      "y": 18,
      "z": -2,
      "name": "Ore_Iron_Basalt_Cracked"
    },
    {
      "x": -13,
      "y": 19,
      "z": -2,
      "name": "Rock_Basalt"
    },
    {
      "x": -13,
      "y": 20,
      "z": -2,
      "name": "Soil_Ash"
    },
    {
      "x": -13,
      "y": 21,
      "z": -2,
      "name": "Plant_Moss_Rug_Yellow"
    },
    {
      "x": -13,
      "y": 17,
      "z": -1,
      "name": "Ore_Iron_Basalt_Cracked"
    },
    {
      "x": -13,
      "y": 18,
      "z": -1,
      "name": "Rock_Basalt"
    },
    {
      "x": -13,
      "y": 19,
      "z": -1,
      "name": "Rock_Basalt"
    },
    {
      "x": -13,
      "y": 20,
      "z": -1,
      "name": "Soil_Ash"
    },
    {
      "x": -13,
      "y": 21,
      "z": -1,
      "name": "Plant_Moss_Rug_Yellow"
    },
    {
      "x": -13,
      "y": 16,
      "z": 0,
      "name": "Rock_Basalt"
    },
    {
      "x": -13,
      "y": 17,
      "z": 0,
      "name": "Rock_Basalt"
    },
    {
      "x": -13,
      "y": 18,
      "z": 0,
      "name": "Rock_Basalt"
    },
    {
      "x": -13,
      "y": 19,
      "z": 0,
      "name": "Rock_Basalt"
    },
    {
      "x": -13,
      "y": 20,
      "z": 0,
      "name": "Soil_Ash"
    },
    {
      "x": -13,
      "y": 16,
      "z": 1,
      "name": "Rock_Basalt"
    },
    {
      "x": -13,
      "y": 17,
      "z": 1,
      "name": "Ore_Iron_Basalt_Cracked"
    },
    {
      "x": -13,
      "y": 18,
      "z": 1,
      "name": "Rock_Basalt"
    },
    {
      "x": -13,
      "y": 19,
      "z": 1,
      "name": "Rock_Basalt"
    },
    {
      "x": -13,
      "y": 20,
      "z": 1,
      "name": "Soil_Ash"
    },
    {
      "x": -13,
      "y": 16,
      "z": 2,
      "name": "Rock_Basalt"
    },
    {
      "x": -13,
      "y": 17,
      "z": 2,
      "name": "Rock_Basalt"
    },
    {
      "x": -13,
      "y": 18,
      "z": 2,
      "name": "Ore_Iron_Basalt_Cracked"
    },
    {
      "x": -13,
      "y": 19,
      "z": 2,
      "name": "Rock_Basalt"
    },
    {
      "x": -13,
      "y": 20,
      "z": 2,
      "name": "Soil_Ash"
    },
    {
      "x": -13,
      "y": 21,
      "z": 2,
      "name": "Plant_Bush_Arid"
    },
    {
      "x": -13,
      "y": 16,
      "z": 3,
      "name": "Rock_Basalt"
    },
    {
      "x": -13,
      "y": 17,
      "z": 3,
      "name": "Rock_Basalt"
    },
    {
      "x": -13,
      "y": 18,
      "z": 3,
      "name": "Ore_Iron_Basalt_Cracked"
    },
    {
      "x": -13,
      "y": 19,
      "z": 3,
      "name": "Rock_Basalt"
    },
    {
      "x": -13,
      "y": 20,
      "z": 3,
      "name": "Soil_Sand_Ashen"
    },
    {
      "x": -13,
      "y": 21,
      "z": 3,
      "name": "Plant_Crop_Mushroom_Glowing_Orange"
    },
    {
      "x": -13,
      "y": 17,
      "z": 4,
      "name": "Ore_Iron_Basalt_Cracked"
    },
    {
      "x": -13,
      "y": 18,
      "z": 4,
      "name": "Ore_Iron_Basalt_Cracked"
    },
    {
      "x": -13,
      "y": 19,
      "z": 4,
      "name": "Ore_Iron_Basalt_Cracked"
    },
    {
      "x": -13,
      "y": 20,
      "z": 4,
      "name": "Soil_Sand_Ashen"
    },
    {
      "x": -13,
      "y": 21,
      "z": 4,
      "name": "Plant_Bush_Arid"
    },
    {
      "x": -13,
      "y": 15,
      "z": 5,
      "name": "Rock_Basalt"
    },
    {
      "x": -13,
      "y": 16,
      "z": 5,
      "name": "Ore_Iron_Basalt_Cracked"
    },
    {
      "x": -13,
      "y": 17,
      "z": 5,
      "name": "Rock_Basalt"
    },
    {
      "x": -13,
      "y": 18,
      "z": 5,
      "name": "Ore_Iron_Basalt_Cracked"
    },
    {
      "x": -13,
      "y": 19,
      "z": 5,
      "name": "Rock_Basalt"
    },
    {
      "x": -13,
      "y": 20,
      "z": 5,
      "name": "Soil_Sand_Ashen"
    },
    {
      "x": -13,
      "y": 21,
      "z": 5,
      "name": "Plant_Moss_Yellow"
    },
    {
      "x": -13,
      "y": 14,
      "z": 6,
      "name": "Rock_Basalt"
    },
    {
      "x": -13,
      "y": 15,
      "z": 6,
      "name": "Rock_Basalt"
    },
    {
      "x": -13,
      "y": 16,
      "z": 6,
      "name": "Ore_Iron_Basalt_Cracked"
    },
    {
      "x": -13,
      "y": 17,
      "z": 6,
      "name": "Rock_Basalt"
    },
    {
      "x": -13,
      "y": 18,
      "z": 6,
      "name": "Ore_Iron_Basalt_Cracked"
    },
    {
      "x": -13,
      "y": 19,
      "z": 6,
      "name": "Ore_Iron_Basalt_Cracked"
    },
    {
      "x": -13,
      "y": 20,
      "z": 6,
      "name": "Soil_Sand_Ashen"
    },
    {
      "x": -13,
      "y": 12,
      "z": 7,
      "name": "Rock_Basalt_Stalactite_Large",
      "filler": 31744,
      "rotation": 8
    },
    {
      "x": -13,
      "y": 13,
      "z": 7,
      "name": "Rock_Basalt_Stalactite_Large",
      "rotation": 8
    },
    {
      "x": -13,
      "y": 14,
      "z": 7,
      "name": "Ore_Iron_Basalt_Cracked"
    },
    {
      "x": -13,
      "y": 15,
      "z": 7,
      "name": "Rock_Basalt"
    },
    {
      "x": -13,
      "y": 16,
      "z": 7,
      "name": "Rock_Basalt"
    },
    {
      "x": -13,
      "y": 17,
      "z": 7,
      "name": "Rock_Basalt"
    },
    {
      "x": -13,
      "y": 18,
      "z": 7,
      "name": "Ore_Iron_Basalt_Cracked"
    },
    {
      "x": -13,
      "y": 19,
      "z": 7,
      "name": "Rock_Basalt"
    },
    {
      "x": -13,
      "y": 20,
      "z": 7,
      "name": "Soil_Sand_Ashen"
    },
    {
      "x": -13,
      "y": 21,
      "z": 7,
      "name": "Plant_Moss_Yellow"
    },
    {
      "x": -13,
      "y": 14,
      "z": 8,
      "name": "Rock_Basalt"
    },
    {
      "x": -13,
      "y": 15,
      "z": 8,
      "name": "Rock_Basalt"
    },
    {
      "x": -13,
      "y": 16,
      "z": 8,
      "name": "Ore_Iron_Basalt_Cracked"
    },
    {
      "x": -13,
      "y": 17,
      "z": 8,
      "name": "Rock_Basalt"
    },
    {
      "x": -13,
      "y": 18,
      "z": 8,
      "name": "Rock_Basalt"
    },
    {
      "x": -13,
      "y": 19,
      "z": 8,
      "name": "Soil_Ash"
    },
    {
      "x": -13,
      "y": 20,
      "z": 8,
      "name": "Plant_Moss_Rug_Yellow"
    },
    {
      "x": -13,
      "y": 15,
      "z": 9,
      "name": "Ore_Iron_Basalt_Cracked"
    },
    {
      "x": -13,
      "y": 16,
      "z": 9,
      "name": "Rock_Basalt"
    },
    {
      "x": -13,
      "y": 17,
      "z": 9,
      "name": "Ore_Iron_Basalt_Cracked"
    },
    {
      "x": -13,
      "y": 18,
      "z": 9,
      "name": "Rock_Basalt"
    },
    {
      "x": -13,
      "y": 19,
      "z": 9,
      "name": "Soil_Ash"
    },
    {
      "x": -13,
      "y": 20,
      "z": 9,
      "name": "Plant_Moss_Rug_Yellow"
    },
    {
      "x": -13,
      "y": 16,
      "z": 10,
      "name": "Deco_SpiderWeb_Flat",
      "rotation": 7
    },
    {
      "x": -13,
      "y": 17,
      "z": 10,
      "name": "Rock_Basalt"
    },
    {
      "x": -13,
      "y": 18,
      "z": 10,
      "name": "Plant_Moss_Rug_Yellow"
    },
    {
      "x": -12,
      "y": 18,
      "z": -4,
      "name": "Plant_Moss_Wall_Yellow",
      "rotation": 2
    },
    {
      "x": -12,
      "y": 19,
      "z": -4,
      "name": "Plant_Moss_Wall_Yellow",
      "rotation": 2
    },
    {
      "x": -12,
      "y": 20,
      "z": -4,
      "name": "Plant_Moss_Wall_Yellow",
      "rotation": 2
    },
    {
      "x": -12,
      "y": 16,
      "z": -3,
      "name": "Rock_Basalt_Stalactite_Large",
      "filler": 31744,
      "rotation": 8
    },
    {
      "x": -12,
      "y": 17,
      "z": -3,
      "name": "Rock_Basalt_Stalactite_Large",
      "rotation": 8
    },
    {
      "x": -12,
      "y": 18,
      "z": -3,
      "name": "Ore_Iron_Basalt_Cracked"
    },
    {
      "x": -12,
      "y": 19,
      "z": -3,
      "name": "Rock_Basalt"
    },
    {
      "x": -12,
      "y": 20,
      "z": -3,
      "name": "Soil_Ash"
    },
    {
      "x": -12,
      "y": 21,
      "z": -3,
      "name": "Plant_Moss_Rug_Yellow"
    },
    {
      "x": -12,
      "y": 17,
      "z": -2,
      "name": "Ore_Iron_Basalt_Cracked"
    },
    {
      "x": -12,
      "y": 18,
      "z": -2,
      "name": "Rock_Basalt"
    },
    {
      "x": -12,
      "y": 19,
      "z": -2,
      "name": "Rock_Basalt"
    },
    {
      "x": -12,
      "y": 20,
      "z": -2,
      "name": "Soil_Ash"
    },
    {
      "x": -12,
      "y": 21,
      "z": -2,
      "name": "Plant_Moss_Rug_Yellow"
    },
    {
      "x": -12,
      "y": 15,
      "z": -1,
      "name": "Rock_Basalt"
    },
    {
      "x": -12,
      "y": 16,
      "z": -1,
      "name": "Ore_Iron_Basalt_Cracked"
    },
    {
      "x": -12,
      "y": 17,
      "z": -1,
      "name": "Rock_Basalt"
    },
    {
      "x": -12,
      "y": 18,
      "z": -1,
      "name": "Ore_Iron_Basalt_Cracked"
    },
    {
      "x": -12,
      "y": 19,
      "z": -1,
      "name": "Ore_Iron_Basalt_Cracked"
    },
    {
      "x": -12,
      "y": 20,
      "z": -1,
      "name": "Ore_Iron_Basalt_Cracked"
    },
    {
      "x": -12,
      "y": 21,
      "z": -1,
      "name": "Soil_Ash"
    },
    {
      "x": -12,
      "y": 22,
      "z": -1,
      "name": "Plant_Bush_Arid"
    },
    {
      "x": -12,
      "y": 15,
      "z": 0,
      "name": "Ore_Iron_Basalt_Cracked"
    },
    {
      "x": -12,
      "y": 16,
      "z": 0,
      "name": "Ore_Iron_Basalt_Cracked"
    },
    {
      "x": -12,
      "y": 17,
      "z": 0,
      "name": "Ore_Iron_Basalt_Cracked"
    },
    {
      "x": -12,
      "y": 18,
      "z": 0,
      "name": "Rock_Basalt"
    },
    {
      "x": -12,
      "y": 19,
      "z": 0,
      "name": "Ore_Iron_Basalt"
    },
    {
      "x": -12,
      "y": 20,
      "z": 0,
      "name": "Soil_Basalt_Gravel"
    },
    {
      "x": -12,
      "y": 21,
      "z": 0,
      "name": "Soil_Ash"
    },
    {
      "x": -12,
      "y": 22,
      "z": 0,
      "name": "Plant_Bush_Arid"
    },
    {
      "x": -12,
      "y": 14,
      "z": 1,
      "name": "Ore_Iron_Basalt_Cracked"
    },
    {
      "x": -12,
      "y": 15,
      "z": 1,
      "name": "Ore_Iron_Basalt_Cracked"
    },
    {
      "x": -12,
      "y": 16,
      "z": 1,
      "name": "Rock_Basalt"
    },
    {
      "x": -12,
      "y": 17,
      "z": 1,
      "name": "Ore_Iron_Basalt_Cracked"
    },
    {
      "x": -12,
      "y": 18,
      "z": 1,
      "name": "Ore_Iron_Basalt_Cracked"
    },
    {
      "x": -12,
      "y": 19,
      "z": 1,
      "name": "Ore_Iron_Basalt_Cracked"
    },
    {
      "x": -12,
      "y": 20,
      "z": 1,
      "name": "Soil_Basalt_Gravel"
    },
    {
      "x": -12,
      "y": 21,
      "z": 1,
      "name": "Soil_Ash"
    },
    {
      "x": -12,
      "y": 14,
      "z": 2,
      "name": "Rock_Basalt"
    },
    {
      "x": -12,
      "y": 15,
      "z": 2,
      "name": "Rock_Basalt"
    },
    {
      "x": -12,
      "y": 16,
      "z": 2,
      "name": "Rock_Basalt"
    },
    {
      "x": -12,
      "y": 17,
      "z": 2,
      "name": "Rock_Basalt"
    },
    {
      "x": -12,
      "y": 18,
      "z": 2,
      "name": "Rock_Basalt"
    },
    {
      "x": -12,
      "y": 19,
      "z": 2,
      "name": "Ore_Iron_Basalt_Cracked"
    },
    {
      "x": -12,
      "y": 20,
      "z": 2,
      "name": "Ore_Iron_Basalt_Cracked"
    },
    {
      "x": -12,
      "y": 21,
      "z": 2,
      "name": "Soil_Ash"
    },
    {
      "x": -12,
      "y": 22,
      "z": 2,
      "name": "Plant_Bush_Arid"
    },
    {
      "x": -12,
      "y": 14,
      "z": 3,
      "name": "Rock_Basalt"
    },
    {
      "x": -12,
      "y": 15,
      "z": 3,
      "name": "Rock_Basalt"
    },
    {
      "x": -12,
      "y": 16,
      "z": 3,
      "name": "Rock_Basalt"
    },
    {
      "x": -12,
      "y": 17,
      "z": 3,
      "name": "Ore_Iron_Basalt_Cracked"
    },
    {
      "x": -12,
      "y": 18,
      "z": 3,
      "name": "Rock_Basalt"
    },
    {
      "x": -12,
      "y": 19,
      "z": 3,
      "name": "Ore_Iron_Basalt_Cracked"
    },
    {
      "x": -12,
      "y": 20,
      "z": 3,
      "name": "Rock_Basalt"
    },
    {
      "x": -12,
      "y": 21,
      "z": 3,
      "name": "Soil_Sand_Ashen"
    },
    {
      "x": -12,
      "y": 22,
      "z": 3,
      "name": "Plant_Bush_Arid"
    },
    {
      "x": -12,
      "y": 14,
      "z": 4,
      "name": "Rock_Basalt"
    },
    {
      "x": -12,
      "y": 15,
      "z": 4,
      "name": "Ore_Iron_Basalt_Cracked"
    },
    {
      "x": -12,
      "y": 16,
      "z": 4,
      "name": "Rock_Basalt"
    },
    {
      "x": -12,
      "y": 17,
      "z": 4,
      "name": "Rock_Basalt"
    },
    {
      "x": -12,
      "y": 18,
      "z": 4,
      "name": "Rock_Basalt"
    },
    {
      "x": -12,
      "y": 19,
      "z": 4,
      "name": "Ore_Iron_Basalt_Cracked"
    },
    {
      "x": -12,
      "y": 20,
      "z": 4,
      "name": "Ore_Iron_Basalt_Cracked"
    },
    {
      "x": -12,
      "y": 21,
      "z": 4,
      "name": "Soil_Sand_Ashen"
    },
    {
      "x": -12,
      "y": 22,
      "z": 4,
      "name": "Plant_Bush_Arid"
    },
    {
      "x": -12,
      "y": 14,
      "z": 5,
      "name": "Ore_Iron_Basalt_Cracked"
    },
    {
      "x": -12,
      "y": 15,
      "z": 5,
      "name": "Ore_Iron_Basalt_Cracked"
    },
    {
      "x": -12,
      "y": 16,
      "z": 5,
      "name": "Rock_Basalt"
    },
    {
      "x": -12,
      "y": 17,
      "z": 5,
      "name": "Rock_Basalt"
    },
    {
      "x": -12,
      "y": 18,
      "z": 5,
      "name": "Ore_Iron_Basalt_Cracked"
    },
    {
      "x": -12,
      "y": 19,
      "z": 5,
      "name": "Soil_Basalt_Gravel"
    },
    {
      "x": -12,
      "y": 20,
      "z": 5,
      "name": "Soil_Sand_Ashen"
    },
    {
      "x": -12,
      "y": 14,
      "z": 6,
      "name": "Rock_Basalt"
    },
    {
      "x": -12,
      "y": 15,
      "z": 6,
      "name": "Rock_Basalt"
    },
    {
      "x": -12,
      "y": 16,
      "z": 6,
      "name": "Ore_Iron_Basalt_Cracked"
    },
    {
      "x": -12,
      "y": 17,
      "z": 6,
      "name": "Rock_Basalt"
    },
    {
      "x": -12,
      "y": 18,
      "z": 6,
      "name": "Rock_Basalt"
    },
    {
      "x": -12,
      "y": 19,
      "z": 6,
      "name": "Ore_Iron_Basalt_Cracked"
    },
    {
      "x": -12,
      "y": 20,
      "z": 6,
      "name": "Ore_Iron_Basalt_Cracked"
    },
    {
      "x": -12,
      "y": 21,
      "z": 6,
      "name": "Soil_Sand_Ashen"
    },
    {
      "x": -12,
      "y": 22,
      "z": 6,
      "name": "Plant_Moss_Yellow"
    },
    {
      "x": -12,
      "y": 11,
      "z": 7,
      "name": "Rock_Basalt_Stalactite_Large",
      "filler": 31744,
      "rotation": 8
    },
    {
      "x": -12,
      "y": 12,
      "z": 7,
      "name": "Rock_Basalt_Stalactite_Large",
      "rotation": 8
    },
    {
      "x": -12,
      "y": 13,
      "z": 7,
      "name": "Rock_Basalt"
    },
    {
      "x": -12,
      "y": 14,
      "z": 7,
      "name": "Rock_Basalt"
    },
    {
      "x": -12,
      "y": 15,
      "z": 7,
      "name": "Ore_Iron_Basalt_Cracked"
    },
    {
      "x": -12,
      "y": 16,
      "z": 7,
      "name": "Ore_Iron_Basalt_Cracked"
    },
    {
      "x": -12,
      "y": 17,
      "z": 7,
      "name": "Ore_Iron_Basalt_Cracked"
    },
    {
      "x": -12,
      "y": 18,
      "z": 7,
      "name": "Ore_Iron_Basalt"
    },
    {
      "x": -12,
      "y": 19,
      "z": 7,
      "name": "Soil_Basalt_Gravel"
    },
    {
      "x": -12,
      "y": 20,
      "z": 7,
      "name": "Soil_Sand_Ashen"
    },
    {
      "x": -12,
      "y": 21,
      "z": 7,
      "name": "Plant_Moss_Yellow"
    },
    {
      "x": -12,
      "y": 11,
      "z": 8,
      "name": "Rock_Basalt_Stalactite_Large",
      "filler": 31744,
      "rotation": 8
    },
    {
      "x": -12,
      "y": 12,
      "z": 8,
      "name": "Rock_Basalt_Stalactite_Large",
      "rotation": 8
    },
    {
      "x": -12,
      "y": 13,
      "z": 8,
      "name": "Ore_Iron_Basalt_Cracked"
    },
    {
      "x": -12,
      "y": 14,
      "z": 8,
      "name": "Ore_Iron_Basalt_Cracked"
    },
    {
      "x": -12,
      "y": 15,
      "z": 8,
      "name": "Ore_Iron_Basalt_Cracked"
    },
    {
      "x": -12,
      "y": 16,
      "z": 8,
      "name": "Rock_Basalt"
    },
    {
      "x": -12,
      "y": 17,
      "z": 8,
      "name": "Rock_Basalt"
    },
    {
      "x": -12,
      "y": 18,
      "z": 8,
      "name": "Ore_Iron_Basalt_Cracked"
    },
    {
      "x": -12,
      "y": 19,
      "z": 8,
      "name": "Ore_Iron_Basalt_Cracked"
    },
    {
      "x": -12,
      "y": 20,
      "z": 8,
      "name": "Soil_Ash"
    },
    {
      "x": -12,
      "y": 13,
      "z": 9,
      "name": "Ore_Iron_Basalt_Cracked"
    },
    {
      "x": -12,
      "y": 14,
      "z": 9,
      "name": "Rock_Basalt"
    },
    {
      "x": -12,
      "y": 15,
      "z": 9,
      "name": "Ore_Iron_Basalt_Cracked"
    },
    {
      "x": -12,
      "y": 16,
      "z": 9,
      "name": "Rock_Basalt"
    },
    {
      "x": -12,
      "y": 17,
      "z": 9,
      "name": "Ore_Iron_Basalt_Cracked"
    },
    {
      "x": -12,
      "y": 18,
      "z": 9,
      "name": "Ore_Iron_Basalt_Cracked"
    },
    {
      "x": -12,
      "y": 19,
      "z": 9,
      "name": "Soil_Ash"
    },
    {
      "x": -12,
      "y": 20,
      "z": 9,
      "name": "Plant_Moss_Rug_Yellow"
    },
    {
      "x": -12,
      "y": 14,
      "z": 10,
      "name": "Rock_Basalt"
    },
    {
      "x": -12,
      "y": 15,
      "z": 10,
      "name": "Rock_Basalt"
    },
    {
      "x": -12,
      "y": 16,
      "z": 10,
      "name": "Rock_Basalt"
    },
    {
      "x": -12,
      "y": 17,
      "z": 10,
      "name": "Ore_Iron_Basalt_Cracked"
    },
    {
      "x": -12,
      "y": 18,
      "z": 10,
      "name": "Soil_Ash"
    },
    {
      "x": -12,
      "y": 19,
      "z": 10,
      "name": "Plant_Moss_Rug_Yellow"
    },
    {
      "x": -12,
      "y": 15,
      "z": 11,
      "name": "Deco_SpiderWeb_Flat",
      "rotation": 7
    },
    {
      "x": -12,
      "y": 18,
      "z": 11,
      "name": "Plant_Moss_Wall_Yellow",
      "rotation": 3
    },
    {
      "x": -12,
      "y": 19,
      "z": 11,
      "name": "Plant_Moss_Wall_Yellow",
      "rotation": 3
    },
    {
      "x": -11,
      "y": 20,
      "z": -5,
      "name": "Plant_Moss_Wall_Yellow",
      "rotation": 2
    },
    {
      "x": -11,
      "y": 17,
      "z": -4,
      "name": "Deco_SpiderWeb_Flat",
      "rotation": 8
    },
    {
      "x": -11,
      "y": 18,
      "z": -4,
      "name": "Rock_Basalt"
    },
    {
      "x": -11,
      "y": 19,
      "z": -4,
      "name": "Ore_Iron_Basalt_Cracked"
    },
    {
      "x": -11,
      "y": 20,
      "z": -4,
      "name": "Soil_Ash"
    },
    {
      "x": -11,
      "y": 21,
      "z": -4,
      "name": "Plant_Moss_Rug_Yellow"
    },
    {
      "x": -11,
      "y": 16,
      "z": -3,
      "name": "Deco_SpiderWeb_Flat",
      "rotation": 7
    },
    {
      "x": -11,
      "y": 17,
      "z": -3,
      "name": "Rock_Basalt"
    },
    {
      "x": -11,
      "y": 18,
      "z": -3,
      "name": "Rock_Basalt"
    },
    {
      "x": -11,
      "y": 19,
      "z": -3,
      "name": "Rock_Basalt"
    },
    {
      "x": -11,
      "y": 20,
      "z": -3,
      "name": "Rock_Basalt"
    },
    {
      "x": -11,
      "y": 21,
      "z": -3,
      "name": "Soil_Ash"
    },
    {
      "x": -11,
      "y": 22,
      "z": -3,
      "name": "Plant_Moss_Rug_Yellow"
    },
    {
      "x": -11,
      "y": 14,
      "z": -2,
      "name": "Deco_SpiderWeb_Flat",
      "rotation": 8
    },
    {
      "x": -11,
      "y": 15,
      "z": -2,
      "name": "Rock_Basalt"
    },
    {
      "x": -11,
      "y": 16,
      "z": -2,
      "name": "Rock_Basalt"
    },
    {
      "x": -11,
      "y": 17,
      "z": -2,
      "name": "Rock_Basalt"
    },
    {
      "x": -11,
      "y": 18,
      "z": -2,
      "name": "Ore_Iron_Basalt_Cracked"
    },
    {
      "x": -11,
      "y": 19,
      "z": -2,
      "name": "Rock_Basalt"
    },
    {
      "x": -11,
      "y": 20,
      "z": -2,
      "name": "Ore_Iron_Basalt_Cracked"
    },
    {
      "x": -11,
      "y": 21,
      "z": -2,
      "name": "Soil_Ash"
    },
    {
      "x": -11,
      "y": 22,
      "z": -2,
      "name": "Plant_Moss_Rug_Yellow"
    },
    {
      "x": -11,
      "y": 15,
      "z": -1,
      "name": "Ore_Iron_Basalt_Cracked"
    },
    {
      "x": -11,
      "y": 16,
      "z": -1,
      "name": "Rock_Basalt"
    },
    {
      "x": -11,
      "y": 17,
      "z": -1,
      "name": "Ore_Iron_Basalt_Cracked"
    },
    {
      "x": -11,
      "y": 18,
      "z": -1,
      "name": "Rock_Basalt"
    },
    {
      "x": -11,
      "y": 19,
      "z": -1,
      "name": "Rock_Basalt"
    },
    {
      "x": -11,
      "y": 20,
      "z": -1,
      "name": "Ore_Iron_Basalt_Cracked"
    },
    {
      "x": -11,
      "y": 21,
      "z": -1,
      "name": "Soil_Basalt_Gravel"
    },
    {
      "x": -11,
      "y": 22,
      "z": -1,
      "name": "Soil_Ash"
    },
    {
      "x": -11,
      "y": 23,
      "z": -1,
      "name": "Rock_Crystal_Yellow_Small"
    },
    {
      "x": -11,
      "y": 14,
      "z": 0,
      "name": "Rock_Basalt"
    },
    {
      "x": -11,
      "y": 15,
      "z": 0,
      "name": "Ore_Iron_Basalt_Cracked"
    },
    {
      "x": -11,
      "y": 16,
      "z": 0,
      "name": "Ore_Iron_Basalt_Cracked"
    },
    {
      "x": -11,
      "y": 17,
      "z": 0,
      "name": "Ore_Iron_Basalt_Cracked"
    },
    {
      "x": -11,
      "y": 18,
      "z": 0,
      "name": "Rock_Basalt"
    },
    {
      "x": -11,
      "y": 19,
      "z": 0,
      "name": "Rock_Basalt"
    },
    {
      "x": -11,
      "y": 20,
      "z": 0,
      "name": "Ore_Iron_Basalt_Cracked"
    },
    {
      "x": -11,
      "y": 21,
      "z": 0,
      "name": "Rock_Basalt"
    },
    {
      "x": -11,
      "y": 22,
      "z": 0,
      "name": "Soil_Ash"
    },
    {
      "x": -11,
      "y": 23,
      "z": 0,
      "name": "Plant_Bush_Arid"
    },
    {
      "x": -11,
      "y": 14,
      "z": 1,
      "name": "Rock_Basalt"
    },
    {
      "x": -11,
      "y": 15,
      "z": 1,
      "name": "Ore_Iron_Basalt_Cracked"
    },
    {
      "x": -11,
      "y": 16,
      "z": 1,
      "name": "Rock_Basalt"
    },
    {
      "x": -11,
      "y": 17,
      "z": 1,
      "name": "Rock_Basalt"
    },
    {
      "x": -11,
      "y": 18,
      "z": 1,
      "name": "Rock_Basalt"
    },
    {
      "x": -11,
      "y": 19,
      "z": 1,
      "name": "Ore_Iron_Basalt_Cracked"
    },
    {
      "x": -11,
      "y": 20,
      "z": 1,
      "name": "Ore_Iron_Basalt_Cracked"
    },
    {
      "x": -11,
      "y": 21,
      "z": 1,
      "name": "Soil_Basalt_Gravel"
    },
    {
      "x": -11,
      "y": 22,
      "z": 1,
      "name": "Soil_Ash"
    },
    {
      "x": -11,
      "y": 13,
      "z": 2,
      "name": "Ore_Iron_Basalt"
    },
    {
      "x": -11,
      "y": 14,
      "z": 2,
      "name": "Rock_Basalt"
    },
    {
      "x": -11,
      "y": 15,
      "z": 2,
      "name": "Rock_Basalt"
    },
    {
      "x": -11,
      "y": 16,
      "z": 2,
      "name": "Rock_Basalt"
    },
    {
      "x": -11,
      "y": 17,
      "z": 2,
      "name": "Ore_Iron_Basalt_Cracked"
    },
    {
      "x": -11,
      "y": 18,
      "z": 2,
      "name": "Ore_Iron_Basalt_Cracked"
    },
    {
      "x": -11,
      "y": 19,
      "z": 2,
      "name": "Ore_Iron_Basalt"
    },
    {
      "x": -11,
      "y": 20,
      "z": 2,
      "name": "Rock_Basalt"
    },
    {
      "x": -11,
      "y": 21,
      "z": 2,
      "name": "Soil_Ash"
    },
    {
      "x": -11,
      "y": 13,
      "z": 3,
      "name": "Ore_Iron_Basalt_Cracked"
    },
    {
      "x": -11,
      "y": 14,
      "z": 3,
      "name": "Rock_Basalt"
    },
    {
      "x": -11,
      "y": 15,
      "z": 3,
      "name": "Ore_Iron_Basalt_Cracked"
    },
    {
      "x": -11,
      "y": 16,
      "z": 3,
      "name": "Rock_Basalt"
    },
    {
      "x": -11,
      "y": 17,
      "z": 3,
      "name": "Rock_Basalt"
    },
    {
      "x": -11,
      "y": 18,
      "z": 3,
      "name": "Rock_Basalt"
    },
    {
      "x": -11,
      "y": 19,
      "z": 3,
      "name": "Ore_Iron_Basalt_Cracked"
    },
    {
      "x": -11,
      "y": 20,
      "z": 3,
      "name": "Ore_Iron_Basalt_Cracked"
    },
    {
      "x": -11,
      "y": 21,
      "z": 3,
      "name": "Soil_Sand_Ashen"
    },
    {
      "x": -11,
      "y": 12,
      "z": 4,
      "name": "Ore_Iron_Basalt"
    },
    {
      "x": -11,
      "y": 13,
      "z": 4,
      "name": "Ore_Iron_Basalt_Cracked"
    },
    {
      "x": -11,
      "y": 14,
      "z": 4,
      "name": "Ore_Iron_Basalt_Cracked"
    },
    {
      "x": -11,
      "y": 15,
      "z": 4,
      "name": "Rock_Basalt"
    },
    {
      "x": -11,
      "y": 16,
      "z": 4,
      "name": "Rock_Basalt"
    },
    {
      "x": -11,
      "y": 17,
      "z": 4,
      "name": "Rock_Basalt"
    },
    {
      "x": -11,
      "y": 18,
      "z": 4,
      "name": "Rock_Basalt"
    },
    {
      "x": -11,
      "y": 19,
      "z": 4,
      "name": "Ore_Iron_Basalt_Cracked"
    },
    {
      "x": -11,
      "y": 20,
      "z": 4,
      "name": "Rock_Basalt"
    },
    {
      "x": -11,
      "y": 21,
      "z": 4,
      "name": "Soil_Sand_Ashen"
    },
    {
      "x": -11,
      "y": 12,
      "z": 5,
      "name": "Rock_Basalt"
    },
    {
      "x": -11,
      "y": 13,
      "z": 5,
      "name": "Ore_Iron_Basalt_Cracked"
    },
    {
      "x": -11,
      "y": 14,
      "z": 5,
      "name": "Rock_Basalt"
    },
    {
      "x": -11,
      "y": 15,
      "z": 5,
      "name": "Ore_Iron_Basalt_Cracked"
    },
    {
      "x": -11,
      "y": 16,
      "z": 5,
      "name": "Rock_Basalt"
    },
    {
      "x": -11,
      "y": 17,
      "z": 5,
      "name": "Ore_Iron_Basalt_Cracked"
    },
    {
      "x": -11,
      "y": 18,
      "z": 5,
      "name": "Ore_Iron_Basalt_Cracked"
    },
    {
      "x": -11,
      "y": 19,
      "z": 5,
      "name": "Ore_Iron_Basalt_Cracked"
    },
    {
      "x": -11,
      "y": 20,
      "z": 5,
      "name": "Rock_Basalt"
    },
    {
      "x": -11,
      "y": 21,
      "z": 5,
      "name": "Soil_Sand_Ashen"
    },
    {
      "x": -11,
      "y": 10,
      "z": 6,
      "name": "Rock_Crystal_Yellow_Medium",
      "rotation": 7
    },
    {
      "x": -11,
      "y": 11,
      "z": 6,
      "name": "Rock_Crystal_Yellow_Medium",
      "rotation": 7
    },
    {
      "x": -11,
      "y": 12,
      "z": 6,
      "name": "Rock_Basalt"
    },
    {
      "x": -11,
      "y": 13,
      "z": 6,
      "name": "Rock_Basalt"
    },
    {
      "x": -11,
      "y": 14,
      "z": 6,
      "name": "Rock_Basalt"
    },
    {
      "x": -11,
      "y": 15,
      "z": 6,
      "name": "Rock_Basalt"
    },
    {
      "x": -11,
      "y": 16,
      "z": 6,
      "name": "Ore_Iron_Basalt_Cracked"
    },
    {
      "x": -11,
      "y": 17,
      "z": 6,
      "name": "Rock_Basalt"
    },
    {
      "x": -11,
      "y": 18,
      "z": 6,
      "name": "Rock_Basalt"
    },
    {
      "x": -11,
      "y": 19,
      "z": 6,
      "name": "Ore_Iron_Basalt"
    },
    {
      "x": -11,
      "y": 20,
      "z": 6,
      "name": "Rock_Basalt"
    },
    {
      "x": -11,
      "y": 21,
      "z": 6,
      "name": "Soil_Sand_Ashen"
    },
    {
      "x": -11,
      "y": 8,
      "z": 7,
      "name": "Rock_Crystal_Yellow_Medium",
      "rotation": 7
    },
    {
      "x": -11,
      "y": 9,
      "z": 7,
      "name": "Rock_Crystal_Yellow_Medium",
      "rotation": 7
    },
    {
      "x": -11,
      "y": 10,
      "z": 7,
      "name": "Rock_Crystal_Yellow_Medium",
      "rotation": 7
    },
    {
      "x": -11,
      "y": 11,
      "z": 7,
      "name": "Rock_Crystal_Yellow_Block"
    },
    {
      "x": -11,
      "y": 12,
      "z": 7,
      "name": "Rock_Crystal_Yellow_Block"
    },
    {
      "x": -11,
      "y": 13,
      "z": 7,
      "name": "Rock_Crystal_Yellow_Block"
    },
    {
      "x": -11,
      "y": 14,
      "z": 7,
      "name": "Rock_Crystal_Yellow_Block"
    },
    {
      "x": -11,
      "y": 15,
      "z": 7,
      "name": "Ore_Iron_Basalt_Cracked"
    },
    {
      "x": -11,
      "y": 16,
      "z": 7,
      "name": "Rock_Basalt"
    },
    {
      "x": -11,
      "y": 17,
      "z": 7,
      "name": "Rock_Basalt"
    },
    {
      "x": -11,
      "y": 18,
      "z": 7,
      "name": "Rock_Basalt"
    },
    {
      "x": -11,
      "y": 19,
      "z": 7,
      "name": "Ore_Iron_Basalt_Cracked"
    },
    {
      "x": -11,
      "y": 20,
      "z": 7,
      "name": "Rock_Basalt"
    },
    {
      "x": -11,
      "y": 21,
      "z": 7,
      "name": "Soil_Sand_Ashen"
    },
    {
      "x": -11,
      "y": 10,
      "z": 8,
      "name": "Rock_Crystal_Yellow_Medium",
      "rotation": 7
    },
    {
      "x": -11,
      "y": 12,
      "z": 8,
      "name": "Ore_Iron_Basalt_Cracked"
    },
    {
      "x": -11,
      "y": 13,
      "z": 8,
      "name": "Rock_Basalt"
    },
    {
      "x": -11,
      "y": 14,
      "z": 8,
      "name": "Rock_Basalt"
    },
    {
      "x": -11,
      "y": 15,
      "z": 8,
      "name": "Ore_Iron_Basalt_Cracked"
    },
    {
      "x": -11,
      "y": 16,
      "z": 8,
      "name": "Rock_Basalt"
    },
    {
      "x": -11,
      "y": 17,
      "z": 8,
      "name": "Ore_Iron_Basalt_Cracked"
    },
    {
      "x": -11,
      "y": 18,
      "z": 8,
      "name": "Ore_Iron_Basalt_Cracked"
    },
    {
      "x": -11,
      "y": 19,
      "z": 8,
      "name": "Ore_Iron_Basalt_Cracked"
    },
    {
      "x": -11,
      "y": 20,
      "z": 8,
      "name": "Soil_Ash"
    },
    {
      "x": -11,
      "y": 13,
      "z": 9,
      "name": "Ore_Iron_Basalt_Cracked"
    },
    {
      "x": -11,
      "y": 14,
      "z": 9,
      "name": "Rock_Basalt"
    },
    {
      "x": -11,
      "y": 15,
      "z": 9,
      "name": "Rock_Basalt"
    },
    {
      "x": -11,
      "y": 16,
      "z": 9,
      "name": "Rock_Basalt"
    },
    {
      "x": -11,
      "y": 17,
      "z": 9,
      "name": "Ore_Iron_Basalt_Cracked"
    },
    {
      "x": -11,
      "y": 18,
      "z": 9,
      "name": "Ore_Iron_Basalt_Cracked"
    },
    {
      "x": -11,
      "y": 19,
      "z": 9,
      "name": "Soil_Basalt_Gravel"
    },
    {
      "x": -11,
      "y": 20,
      "z": 9,
      "name": "Soil_Ash"
    },
    {
      "x": -11,
      "y": 21,
      "z": 9,
      "name": "Plant_Moss_Yellow"
    },
    {
      "x": -11,
      "y": 13,
      "z": 10,
      "name": "Rock_Basalt"
    },
    {
      "x": -11,
      "y": 14,
      "z": 10,
      "name": "Rock_Basalt"
    },
    {
      "x": -11,
      "y": 15,
      "z": 10,
      "name": "Rock_Basalt"
    },
    {
      "x": -11,
      "y": 16,
      "z": 10,
      "name": "Rock_Basalt"
    },
    {
      "x": -11,
      "y": 17,
      "z": 10,
      "name": "Rock_Basalt"
    },
    {
      "x": -11,
      "y": 18,
      "z": 10,
      "name": "Ore_Iron_Basalt_Cracked"
    },
    {
      "x": -11,
      "y": 19,
      "z": 10,
      "name": "Soil_Basalt_Gravel"
    },
    {
      "x": -11,
      "y": 20,
      "z": 10,
      "name": "Soil_Ash"
    },
    {
      "x": -11,
      "y": 21,
      "z": 10,
      "name": "Plant_Moss_Yellow"
    },
    {
      "x": -11,
      "y": 15,
      "z": 11,
      "name": "Rock_Basalt"
    },
    {
      "x": -11,
      "y": 16,
      "z": 11,
      "name": "Ore_Iron_Basalt_Cracked"
    },
    {
      "x": -11,
      "y": 17,
      "z": 11,
      "name": "Rock_Basalt"
    },
    {
      "x": -11,
      "y": 18,
      "z": 11,
      "name": "Soil_Basalt_Gravel"
    },
    {
      "x": -11,
      "y": 19,
      "z": 11,
      "name": "Soil_Ash"
    },
    {
      "x": -11,
      "y": 20,
      "z": 11,
      "name": "Plant_Moss_Rug_Yellow"
    },
    {
      "x": -11,
      "y": 18,
      "z": 12,
      "name": "Plant_Moss_Wall_Yellow"
    },
    {
      "x": -11,
      "y": 19,
      "z": 12,
      "name": "Plant_Moss_Wall_Yellow"
    },
    {
      "x": -11,
      "y": 14,
      "z": 13,
      "name": "Rock_Basalt"
    },
    {
      "x": -11,
      "y": 15,
      "z": 13,
      "name": "Ore_Iron_Basalt_Cracked"
    },
    {
      "x": -11,
      "y": 16,
      "z": 13,
      "name": "Rock_Basalt"
    },
    {
      "x": -11,
      "y": 17,
      "z": 13,
      "name": "Soil_Ash"
    },
    {
      "x": -11,
      "y": 14,
      "z": 14,
      "name": "Rock_Basalt"
    },
    {
      "x": -11,
      "y": 15,
      "z": 14,
      "name": "Rock_Basalt"
    },
    {
      "x": -11,
      "y": 16,
      "z": 14,
      "name": "Ore_Iron_Basalt_Cracked"
    },
    {
      "x": -11,
      "y": 17,
      "z": 14,
      "name": "Rock_Basalt"
    },
    {
      "x": -11,
      "y": 18,
      "z": 14,
      "name": "Soil_Ash"
    },
    {
      "x": -11,
      "y": 14,
      "z": 15,
      "name": "Ore_Iron_Basalt_Cracked"
    },
    {
      "x": -11,
      "y": 15,
      "z": 15,
      "name": "Rock_Basalt"
    },
    {
      "x": -11,
      "y": 16,
      "z": 15,
      "name": "Ore_Iron_Basalt_Cracked"
    },
    {
      "x": -11,
      "y": 17,
      "z": 15,
      "name": "Ore_Iron_Basalt_Cracked"
    },
    {
      "x": -11,
      "y": 18,
      "z": 15,
      "name": "Soil_Ash"
    },
    {
      "x": -10,
      "y": 21,
      "z": -7,
      "name": "Deco_SpiderWeb_Flat",
      "rotation": 7
    },
    {
      "x": -10,
      "y": 19,
      "z": -6,
      "name": "Deco_SpiderWeb_Flat",
      "rotation": 7
    },
    {
      "x": -10,
      "y": 20,
      "z": -6,
      "name": "Deco_SpiderWeb_Flat",
      "rotation": 7
    },
    {
      "x": -10,
      "y": 18,
      "z": -4,
      "name": "Rock_Basalt"
    },
    {
      "x": -10,
      "y": 19,
      "z": -4,
      "name": "Rock_Basalt"
    },
    {
      "x": -10,
      "y": 20,
      "z": -4,
      "name": "Ore_Iron_Basalt_Cracked"
    },
    {
      "x": -10,
      "y": 21,
      "z": -4,
      "name": "Soil_Basalt_Gravel"
    },
    {
      "x": -10,
      "y": 22,
      "z": -4,
      "name": "Soil_Ash"
    },
    {
      "x": -10,
      "y": 16,
      "z": -3,
      "name": "Rock_Basalt"
    },
    {
      "x": -10,
      "y": 17,
      "z": -3,
      "name": "Rock_Basalt"
    },
    {
      "x": -10,
      "y": 18,
      "z": -3,
      "name": "Rock_Basalt"
    },
    {
      "x": -10,
      "y": 19,
      "z": -3,
      "name": "Ore_Iron_Basalt_Cracked"
    },
    {
      "x": -10,
      "y": 20,
      "z": -3,
      "name": "Rock_Basalt"
    },
    {
      "x": -10,
      "y": 21,
      "z": -3,
      "name": "Ore_Iron_Basalt_Cracked"
    },
    {
      "x": -10,
      "y": 22,
      "z": -3,
      "name": "Ore_Iron_Basalt_Cracked"
    },
    {
      "x": -10,
      "y": 23,
      "z": -3,
      "name": "Soil_Ash"
    },
    {
      "x": -10,
      "y": 24,
      "z": -3,
      "name": "Plant_Moss_Yellow"
    },
    {
      "x": -10,
      "y": 16,
      "z": -2,
      "name": "Rock_Basalt"
    },
    {
      "x": -10,
      "y": 17,
      "z": -2,
      "name": "Rock_Basalt"
    },
    {
      "x": -10,
      "y": 18,
      "z": -2,
      "name": "Rock_Basalt"
    },
    {
      "x": -10,
      "y": 19,
      "z": -2,
      "name": "Rock_Basalt"
    },
    {
      "x": -10,
      "y": 20,
      "z": -2,
      "name": "Rock_Basalt"
    },
    {
      "x": -10,
      "y": 21,
      "z": -2,
      "name": "Ore_Iron_Basalt_Cracked"
    },
    {
      "x": -10,
      "y": 22,
      "z": -2,
      "name": "Ore_Iron_Basalt_Cracked"
    },
    {
      "x": -10,
      "y": 23,
      "z": -2,
      "name": "Soil_Ash"
    },
    {
      "x": -10,
      "y": 13,
      "z": -1,
      "name": "Rock_Basalt_Stalactite_Large",
      "filler": 31744,
      "rotation": 8
    },
    {
      "x": -10,
      "y": 14,
      "z": -1,
      "name": "Rock_Basalt_Stalactite_Large",
      "rotation": 8
    },
    {
      "x": -10,
      "y": 15,
      "z": -1,
      "name": "Rock_Basalt"
    },
    {
      "x": -10,
      "y": 16,
      "z": -1,
      "name": "Ore_Iron_Basalt_Cracked"
    },
    {
      "x": -10,
      "y": 17,
      "z": -1,
      "name": "Rock_Basalt"
    },
    {
      "x": -10,
      "y": 18,
      "z": -1,
      "name": "Rock_Basalt"
    },
    {
      "x": -10,
      "y": 19,
      "z": -1,
      "name": "Rock_Basalt"
    },
    {
      "x": -10,
      "y": 20,
      "z": -1,
      "name": "Ore_Iron_Basalt_Cracked"
    },
    {
      "x": -10,
      "y": 21,
      "z": -1,
      "name": "Ore_Iron_Basalt_Cracked"
    },
    {
      "x": -10,
      "y": 22,
      "z": -1,
      "name": "Rock_Basalt"
    },
    {
      "x": -10,
      "y": 23,
      "z": -1,
      "name": "Soil_Ash"
    },
    {
      "x": -10,
      "y": 24,
      "z": -1,
      "name": "Plant_Bush_Arid"
    },
    {
      "x": -10,
      "y": 14,
      "z": 0,
      "name": "Rock_Basalt"
    },
    {
      "x": -10,
      "y": 15,
      "z": 0,
      "name": "Rock_Basalt"
    },
    {
      "x": -10,
      "y": 16,
      "z": 0,
      "name": "Ore_Iron_Basalt_Cracked"
    },
    {
      "x": -10,
      "y": 17,
      "z": 0,
      "name": "Rock_Basalt"
    },
    {
      "x": -10,
      "y": 18,
      "z": 0,
      "name": "Rock_Basalt"
    },
    {
      "x": -10,
      "y": 19,
      "z": 0,
      "name": "Rock_Basalt"
    },
    {
      "x": -10,
      "y": 20,
      "z": 0,
      "name": "Ore_Iron_Basalt_Cracked"
    },
    {
      "x": -10,
      "y": 21,
      "z": 0,
      "name": "Ore_Iron_Basalt_Cracked"
    },
    {
      "x": -10,
      "y": 22,
      "z": 0,
      "name": "Soil_Ash"
    },
    {
      "x": -10,
      "y": 12,
      "z": 1,
      "name": "Rock_Basalt_Stalactite_Small",
      "rotation": 8
    },
    {
      "x": -10,
      "y": 13,
      "z": 1,
      "name": "Rock_Basalt"
    },
    {
      "x": -10,
      "y": 14,
      "z": 1,
      "name": "Ore_Iron_Basalt_Cracked"
    },
    {
      "x": -10,
      "y": 15,
      "z": 1,
      "name": "Rock_Basalt"
    },
    {
      "x": -10,
      "y": 16,
      "z": 1,
      "name": "Ore_Iron_Basalt_Cracked"
    },
    {
      "x": -10,
      "y": 17,
      "z": 1,
      "name": "Rock_Basalt"
    },
    {
      "x": -10,
      "y": 18,
      "z": 1,
      "name": "Rock_Basalt"
    },
    {
      "x": -10,
      "y": 19,
      "z": 1,
      "name": "Ore_Iron_Basalt_Cracked"
    },
    {
      "x": -10,
      "y": 20,
      "z": 1,
      "name": "Ore_Iron_Basalt"
    },
    {
      "x": -10,
      "y": 21,
      "z": 1,
      "name": "Rock_Basalt"
    },
    {
      "x": -10,
      "y": 22,
      "z": 1,
      "name": "Soil_Ash"
    },
    {
      "x": -10,
      "y": 13,
      "z": 2,
      "name": "Ore_Iron_Basalt_Cracked"
    },
    {
      "x": -10,
      "y": 14,
      "z": 2,
      "name": "Rock_Basalt"
    },
    {
      "x": -10,
      "y": 15,
      "z": 2,
      "name": "Rock_Basalt"
    },
    {
      "x": -10,
      "y": 16,
      "z": 2,
      "name": "Rock_Basalt"
    },
    {
      "x": -10,
      "y": 17,
      "z": 2,
      "name": "Rock_Basalt"
    },
    {
      "x": -10,
      "y": 18,
      "z": 2,
      "name": "Rock_Basalt"
    },
    {
      "x": -10,
      "y": 19,
      "z": 2,
      "name": "Rock_Basalt"
    },
    {
      "x": -10,
      "y": 20,
      "z": 2,
      "name": "Ore_Iron_Basalt_Cracked"
    },
    {
      "x": -10,
      "y": 21,
      "z": 2,
      "name": "Rock_Basalt"
    },
    {
      "x": -10,
      "y": 22,
      "z": 2,
      "name": "Soil_Ash"
    },
    {
      "x": -10,
      "y": 12,
      "z": 3,
      "name": "Rock_Basalt"
    },
    {
      "x": -10,
      "y": 13,
      "z": 3,
      "name": "Ore_Iron_Basalt_Cracked"
    },
    {
      "x": -10,
      "y": 14,
      "z": 3,
      "name": "Rock_Basalt"
    },
    {
      "x": -10,
      "y": 15,
      "z": 3,
      "name": "Rock_Basalt"
    },
    {
      "x": -10,
      "y": 16,
      "z": 3,
      "name": "Rock_Basalt"
    },
    {
      "x": -10,
      "y": 17,
      "z": 3,
      "name": "Ore_Iron_Basalt_Cracked"
    },
    {
      "x": -10,
      "y": 18,
      "z": 3,
      "name": "Rock_Basalt"
    },
    {
      "x": -10,
      "y": 19,
      "z": 3,
      "name": "Ore_Iron_Basalt_Cracked"
    },
    {
      "x": -10,
      "y": 20,
      "z": 3,
      "name": "Soil_Basalt_Gravel"
    },
    {
      "x": -10,
      "y": 21,
      "z": 3,
      "name": "Soil_Sand_Ashen"
    },
    {
      "x": -10,
      "y": 12,
      "z": 4,
      "name": "Ore_Iron_Basalt"
    },
    {
      "x": -10,
      "y": 13,
      "z": 4,
      "name": "Ore_Iron_Basalt_Cracked"
    },
    {
      "x": -10,
      "y": 14,
      "z": 4,
      "name": "Rock_Basalt"
    },
    {
      "x": -10,
      "y": 15,
      "z": 4,
      "name": "Rock_Basalt"
    },
    {
      "x": -10,
      "y": 16,
      "z": 4,
      "name": "Rock_Basalt"
    },
    {
      "x": -10,
      "y": 17,
      "z": 4,
      "name": "Rock_Basalt"
    },
    {
      "x": -10,
      "y": 18,
      "z": 4,
      "name": "Ore_Iron_Basalt_Cracked"
    },
    {
      "x": -10,
      "y": 19,
      "z": 4,
      "name": "Ore_Iron_Basalt_Cracked"
    },
    {
      "x": -10,
      "y": 20,
      "z": 4,
      "name": "Ore_Iron_Basalt_Cracked"
    },
    {
      "x": -10,
      "y": 21,
      "z": 4,
      "name": "Soil_Sand_Ashen"
    },
    {
      "x": -10,
      "y": 10,
      "z": 5,
      "name": "Rock_Crystal_Yellow_Medium",
      "rotation": 6
    },
    {
      "x": -10,
      "y": 11,
      "z": 5,
      "name": "Ore_Iron_Basalt_Cracked"
    },
    {
      "x": -10,
      "y": 12,
      "z": 5,
      "name": "Rock_Basalt"
    },
    {
      "x": -10,
      "y": 13,
      "z": 5,
      "name": "Rock_Basalt"
    },
    {
      "x": -10,
      "y": 14,
      "z": 5,
      "name": "Ore_Iron_Basalt_Cracked"
    },
    {
      "x": -10,
      "y": 15,
      "z": 5,
      "name": "Ore_Iron_Basalt_Cracked"
    },
    {
      "x": -10,
      "y": 16,
      "z": 5,
      "name": "Ore_Iron_Basalt_Cracked"
    },
    {
      "x": -10,
      "y": 17,
      "z": 5,
      "name": "Rock_Basalt"
    },
    {
      "x": -10,
      "y": 18,
      "z": 5,
      "name": "Rock_Basalt"
    },
    {
      "x": -10,
      "y": 19,
      "z": 5,
      "name": "Ore_Iron_Basalt_Cracked"
    },
    {
      "x": -10,
      "y": 20,
      "z": 5,
      "name": "Rock_Basalt"
    },
    {
      "x": -10,
      "y": 21,
      "z": 5,
      "name": "Soil_Sand_Ashen"
    },
    {
      "x": -10,
      "y": 8,
      "z": 6,
      "name": "Rock_Crystal_Yellow_Medium",
      "rotation": 6
    },
    {
      "x": -10,
      "y": 9,
      "z": 6,
      "name": "Rock_Crystal_Yellow_Medium",
      "rotation": 6
    },
    {
      "x": -10,
      "y": 10,
      "z": 6,
      "name": "Rock_Crystal_Yellow_Block"
    },
    {
      "x": -10,
      "y": 11,
      "z": 6,
      "name": "Rock_Crystal_Yellow_Block"
    },
    {
      "x": -10,
      "y": 12,
      "z": 6,
      "name": "Rock_Crystal_Yellow_Block"
    },
    {
      "x": -10,
      "y": 13,
      "z": 6,
      "name": "Rock_Crystal_Yellow_Block"
    },
    {
      "x": -10,
      "y": 14,
      "z": 6,
      "name": "Rock_Crystal_Yellow_Block"
    },
    {
      "x": -10,
      "y": 15,
      "z": 6,
      "name": "Rock_Basalt"
    },
    {
      "x": -10,
      "y": 16,
      "z": 6,
      "name": "Rock_Basalt"
    },
    {
      "x": -10,
      "y": 17,
      "z": 6,
      "name": "Ore_Iron_Basalt_Cracked"
    },
    {
      "x": -10,
      "y": 18,
      "z": 6,
      "name": "Rock_Basalt"
    },
    {
      "x": -10,
      "y": 19,
      "z": 6,
      "name": "Ore_Iron_Basalt_Cracked"
    },
    {
      "x": -10,
      "y": 20,
      "z": 6,
      "name": "Soil_Basalt_Gravel"
    },
    {
      "x": -10,
      "y": 21,
      "z": 6,
      "name": "Soil_Sand_Ashen"
    },
    {
      "x": -10,
      "y": 7,
      "z": 7,
      "name": "Rock_Crystal_Yellow_Large",
      "rotation": 8
    },
    {
      "x": -10,
      "y": 8,
      "z": 7,
      "name": "Rock_Crystal_Yellow_Block"
    },
    {
      "x": -10,
      "y": 9,
      "z": 7,
      "name": "Rock_Crystal_Yellow_Block"
    },
    {
      "x": -10,
      "y": 10,
      "z": 7,
      "name": "Rock_Crystal_Yellow_Block"
    },
    {
      "x": -10,
      "y": 11,
      "z": 7,
      "name": "Rock_Crystal_Yellow_Block"
    },
    {
      "x": -10,
      "y": 12,
      "z": 7,
      "name": "Rock_Crystal_Yellow_Block"
    },
    {
      "x": -10,
      "y": 13,
      "z": 7,
      "name": "Rock_Crystal_Yellow_Block"
    },
    {
      "x": -10,
      "y": 14,
      "z": 7,
      "name": "Rock_Crystal_Yellow_Block"
    },
    {
      "x": -10,
      "y": 15,
      "z": 7,
      "name": "Rock_Crystal_Yellow_Block"
    },
    {
      "x": -10,
      "y": 16,
      "z": 7,
      "name": "Rock_Crystal_Yellow_Block"
    },
    {
      "x": -10,
      "y": 17,
      "z": 7,
      "name": "Rock_Basalt"
    },
    {
      "x": -10,
      "y": 18,
      "z": 7,
      "name": "Ore_Iron_Basalt_Cracked"
    },
    {
      "x": -10,
      "y": 19,
      "z": 7,
      "name": "Ore_Iron_Basalt_Cracked"
    },
    {
      "x": -10,
      "y": 20,
      "z": 7,
      "name": "Ore_Iron_Basalt_Cracked"
    },
    {
      "x": -10,
      "y": 21,
      "z": 7,
      "name": "Soil_Sand_Ashen"
    },
    {
      "x": -10,
      "y": 8,
      "z": 8,
      "name": "Rock_Crystal_Yellow_Medium",
      "rotation": 4
    },
    {
      "x": -10,
      "y": 9,
      "z": 8,
      "name": "Rock_Crystal_Yellow_Large",
      "rotation": 4
    },
    {
      "x": -10,
      "y": 10,
      "z": 8,
      "name": "Rock_Crystal_Yellow_Block"
    },
    {
      "x": -10,
      "y": 11,
      "z": 8,
      "name": "Rock_Crystal_Yellow_Block"
    },
    {
      "x": -10,
      "y": 12,
      "z": 8,
      "name": "Rock_Crystal_Yellow_Block"
    },
    {
      "x": -10,
      "y": 13,
      "z": 8,
      "name": "Rock_Crystal_Yellow_Block"
    },
    {
      "x": -10,
      "y": 14,
      "z": 8,
      "name": "Rock_Crystal_Yellow_Block"
    },
    {
      "x": -10,
      "y": 15,
      "z": 8,
      "name": "Ore_Iron_Basalt_Cracked"
    },
    {
      "x": -10,
      "y": 16,
      "z": 8,
      "name": "Rock_Basalt"
    },
    {
      "x": -10,
      "y": 17,
      "z": 8,
      "name": "Rock_Basalt"
    },
    {
      "x": -10,
      "y": 18,
      "z": 8,
      "name": "Rock_Basalt"
    },
    {
      "x": -10,
      "y": 19,
      "z": 8,
      "name": "Ore_Iron_Basalt_Cracked"
    },
    {
      "x": -10,
      "y": 20,
      "z": 8,
      "name": "Rock_Basalt"
    },
    {
      "x": -10,
      "y": 21,
      "z": 8,
      "name": "Rock_Basalt"
    },
    {
      "x": -10,
      "y": 10,
      "z": 9,
      "name": "Rock_Crystal_Yellow_Large",
      "rotation": 4
    },
    {
      "x": -10,
      "y": 12,
      "z": 9,
      "name": "Rock_Basalt"
    },
    {
      "x": -10,
      "y": 13,
      "z": 9,
      "name": "Ore_Iron_Basalt_Cracked"
    },
    {
      "x": -10,
      "y": 14,
      "z": 9,
      "name": "Ore_Iron_Basalt_Cracked"
    },
    {
      "x": -10,
      "y": 15,
      "z": 9,
      "name": "Rock_Basalt"
    },
    {
      "x": -10,
      "y": 16,
      "z": 9,
      "name": "Rock_Basalt"
    },
    {
      "x": -10,
      "y": 17,
      "z": 9,
      "name": "Ore_Iron_Basalt_Cracked"
    },
    {
      "x": -10,
      "y": 18,
      "z": 9,
      "name": "Ore_Iron_Basalt_Cracked"
    },
    {
      "x": -10,
      "y": 19,
      "z": 9,
      "name": "Ore_Iron_Basalt_Cracked"
    },
    {
      "x": -10,
      "y": 20,
      "z": 9,
      "name": "Soil_Basalt_Gravel"
    },
    {
      "x": -10,
      "y": 21,
      "z": 9,
      "name": "Soil_Ash"
    },
    {
      "x": -10,
      "y": 38,
      "z": 9,
      "name": "Wood_Ash_Branch_Corner",
      "rotation": 3
    },
    {
      "x": -10,
      "y": 13,
      "z": 10,
      "name": "Rock_Basalt"
    },
    {
      "x": -10,
      "y": 14,
      "z": 10,
      "name": "Rock_Basalt"
    },
    {
      "x": -10,
      "y": 15,
      "z": 10,
      "name": "Rock_Basalt"
    },
    {
      "x": -10,
      "y": 16,
      "z": 10,
      "name": "Rock_Basalt"
    },
    {
      "x": -10,
      "y": 17,
      "z": 10,
      "name": "Ore_Iron_Basalt_Cracked"
    },
    {
      "x": -10,
      "y": 18,
      "z": 10,
      "name": "Ore_Iron_Basalt_Cracked"
    },
    {
      "x": -10,
      "y": 19,
      "z": 10,
      "name": "Soil_Basalt_Gravel"
    },
    {
      "x": -10,
      "y": 20,
      "z": 10,
      "name": "Soil_Ash"
    },
    {
      "x": -10,
      "y": 15,
      "z": 11,
      "name": "Ore_Iron_Basalt_Cracked"
    },
    {
      "x": -10,
      "y": 16,
      "z": 11,
      "name": "Rock_Basalt"
    },
    {
      "x": -10,
      "y": 17,
      "z": 11,
      "name": "Ore_Iron_Basalt_Cracked"
    },
    {
      "x": -10,
      "y": 18,
      "z": 11,
      "name": "Rock_Basalt"
    },
    {
      "x": -10,
      "y": 19,
      "z": 11,
      "name": "Soil_Ash"
    },
    {
      "x": -10,
      "y": 20,
      "z": 11,
      "name": "Plant_Moss_Yellow"
    },
    {
      "x": -10,
      "y": 12,
      "z": 12,
      "name": "Deco_SpiderWeb",
      "rotation": 8
    },
    {
      "x": -10,
      "y": 13,
      "z": 12,
      "name": "Ore_Iron_Basalt_Cracked"
    },
    {
      "x": -10,
      "y": 14,
      "z": 12,
      "name": "Ore_Iron_Basalt_Cracked"
    },
    {
      "x": -10,
      "y": 15,
      "z": 12,
      "name": "Rock_Basalt"
    },
    {
      "x": -10,
      "y": 16,
      "z": 12,
      "name": "Ore_Iron_Basalt_Cracked"
    },
    {
      "x": -10,
      "y": 17,
      "z": 12,
      "name": "Ore_Iron_Basalt_Cracked"
    },
    {
      "x": -10,
      "y": 18,
      "z": 12,
      "name": "Rock_Basalt"
    },
    {
      "x": -10,
      "y": 19,
      "z": 12,
      "name": "Soil_Ash"
    },
    {
      "x": -10,
      "y": 12,
      "z": 13,
      "name": "Rock_Basalt"
    },
    {
      "x": -10,
      "y": 13,
      "z": 13,
      "name": "Rock_Basalt"
    },
    {
      "x": -10,
      "y": 14,
      "z": 13,
      "name": "Rock_Basalt"
    },
    {
      "x": -10,
      "y": 15,
      "z": 13,
      "name": "Rock_Basalt"
    },
    {
      "x": -10,
      "y": 16,
      "z": 13,
      "name": "Ore_Iron_Basalt_Cracked"
    },
    {
      "x": -10,
      "y": 17,
      "z": 13,
      "name": "Rock_Basalt"
    },
    {
      "x": -10,
      "y": 18,
      "z": 13,
      "name": "Soil_Ash"
    },
    {
      "x": -10,
      "y": 10,
      "z": 14,
      "name": "Rock_Basalt_Stalactite_Large",
      "filler": 31744,
      "rotation": 8
    },
    {
      "x": -10,
      "y": 11,
      "z": 14,
      "name": "Rock_Basalt_Stalactite_Large",
      "rotation": 8
    },
    {
      "x": -10,
      "y": 12,
      "z": 14,
      "name": "Rock_Basalt"
    },
    {
      "x": -10,
      "y": 13,
      "z": 14,
      "name": "Rock_Basalt"
    },
    {
      "x": -10,
      "y": 14,
      "z": 14,
      "name": "Ore_Iron_Basalt_Cracked"
    },
    {
      "x": -10,
      "y": 15,
      "z": 14,
      "name": "Rock_Basalt"
    },
    {
      "x": -10,
      "y": 16,
      "z": 14,
      "name": "Ore_Iron_Basalt_Cracked"
    },
    {
      "x": -10,
      "y": 17,
      "z": 14,
      "name": "Rock_Basalt"
    },
    {
      "x": -10,
      "y": 18,
      "z": 14,
      "name": "Soil_Ash"
    },
    {
      "x": -10,
      "y": 12,
      "z": 15,
      "name": "Rock_Basalt"
    },
    {
      "x": -10,
      "y": 13,
      "z": 15,
      "name": "Rock_Basalt"
    },
    {
      "x": -10,
      "y": 14,
      "z": 15,
      "name": "Rock_Basalt"
    },
    {
      "x": -10,
      "y": 15,
      "z": 15,
      "name": "Rock_Basalt"
    },
    {
      "x": -10,
      "y": 16,
      "z": 15,
      "name": "Rock_Basalt"
    },
    {
      "x": -10,
      "y": 17,
      "z": 15,
      "name": "Ore_Iron_Basalt_Cracked"
    },
    {
      "x": -10,
      "y": 18,
      "z": 15,
      "name": "Rock_Basalt"
    },
    {
      "x": -10,
      "y": 19,
      "z": 15,
      "name": "Soil_Ash"
    },
    {
      "x": -10,
      "y": 13,
      "z": 16,
      "name": "Rock_Basalt"
    },
    {
      "x": -10,
      "y": 14,
      "z": 16,
      "name": "Rock_Basalt"
    },
    {
      "x": -10,
      "y": 15,
      "z": 16,
      "name": "Rock_Basalt"
    },
    {
      "x": -10,
      "y": 16,
      "z": 16,
      "name": "Rock_Basalt"
    },
    {
      "x": -10,
      "y": 17,
      "z": 16,
      "name": "Ore_Iron_Basalt_Cracked"
    },
    {
      "x": -10,
      "y": 18,
      "z": 16,
      "name": "Rock_Basalt"
    },
    {
      "x": -10,
      "y": 19,
      "z": 16,
      "name": "Soil_Ash"
    },
    {
      "x": -9,
      "y": 22,
      "z": -8,
      "name": "Deco_SpiderWeb_Flat",
      "rotation": 7
    },
    {
      "x": -9,
      "y": 18,
      "z": -7,
      "name": "Ore_Iron_Basalt_Cracked"
    },
    {
      "x": -9,
      "y": 19,
      "z": -7,
      "name": "Ore_Iron_Basalt_Cracked"
    },
    {
      "x": -9,
      "y": 20,
      "z": -7,
      "name": "Ore_Iron_Basalt_Cracked"
    },
    {
      "x": -9,
      "y": 21,
      "z": -7,
      "name": "Rock_Basalt"
    },
    {
      "x": -9,
      "y": 22,
      "z": -7,
      "name": "Soil_Ash"
    },
    {
      "x": -9,
      "y": 23,
      "z": -7,
      "name": "Plant_Flower_Bushy_Yellow"
    },
    {
      "x": -9,
      "y": 18,
      "z": -6,
      "name": "Rock_Basalt"
    },
    {
      "x": -9,
      "y": 19,
      "z": -6,
      "name": "Ore_Iron_Basalt_Cracked"
    },
    {
      "x": -9,
      "y": 20,
      "z": -6,
      "name": "Rock_Basalt"
    },
    {
      "x": -9,
      "y": 21,
      "z": -6,
      "name": "Rock_Basalt"
    },
    {
      "x": -9,
      "y": 22,
      "z": -6,
      "name": "Soil_Ash"
    },
    {
      "x": -9,
      "y": 23,
      "z": -6,
      "name": "Plant_Flower_Bushy_Yellow"
    },
    {
      "x": -9,
      "y": 14,
      "z": -5,
      "name": "Rock_Basalt_Stalactite_Large",
      "filler": 31744,
      "rotation": 8
    },
    {
      "x": -9,
      "y": 15,
      "z": -5,
      "name": "Rock_Basalt_Stalactite_Large",
      "rotation": 8
    },
    {
      "x": -9,
      "y": 16,
      "z": -5,
      "name": "Ore_Iron_Basalt_Cracked"
    },
    {
      "x": -9,
      "y": 17,
      "z": -5,
      "name": "Ore_Iron_Basalt_Cracked"
    },
    {
      "x": -9,
      "y": 18,
      "z": -5,
      "name": "Rock_Basalt"
    },
    {
      "x": -9,
      "y": 19,
      "z": -5,
      "name": "Ore_Iron_Basalt_Cracked"
    },
    {
      "x": -9,
      "y": 20,
      "z": -5,
      "name": "Rock_Basalt"
    },
    {
      "x": -9,
      "y": 16,
      "z": -4,
      "name": "Rock_Basalt"
    },
    {
      "x": -9,
      "y": 17,
      "z": -4,
      "name": "Ore_Iron_Basalt_Cracked"
    },
    {
      "x": -9,
      "y": 18,
      "z": -4,
      "name": "Rock_Basalt"
    },
    {
      "x": -9,
      "y": 19,
      "z": -4,
      "name": "Rock_Basalt"
    },
    {
      "x": -9,
      "y": 20,
      "z": -4,
      "name": "Soil_Ash"
    },
    {
      "x": -9,
      "y": 16,
      "z": -3,
      "name": "Rock_Basalt"
    },
    {
      "x": -9,
      "y": 17,
      "z": -3,
      "name": "Rock_Basalt"
    },
    {
      "x": -9,
      "y": 18,
      "z": -3,
      "name": "Rock_Basalt"
    },
    {
      "x": -9,
      "y": 19,
      "z": -3,
      "name": "Ore_Iron_Basalt_Cracked"
    },
    {
      "x": -9,
      "y": 20,
      "z": -3,
      "name": "Rock_Basalt"
    },
    {
      "x": -9,
      "y": 21,
      "z": -3,
      "name": "Ore_Iron_Basalt_Cracked"
    },
    {
      "x": -9,
      "y": 22,
      "z": -3,
      "name": "Soil_Basalt_Gravel"
    },
    {
      "x": -9,
      "y": 23,
      "z": -3,
      "name": "Soil_Ash"
    },
    {
      "x": -9,
      "y": 24,
      "z": -3,
      "name": "Deco_SpiderWeb_Flat"
    },
    {
      "x": -9,
      "y": 14,
      "z": -2,
      "name": "Rock_Basalt"
    },
    {
      "x": -9,
      "y": 15,
      "z": -2,
      "name": "Rock_Basalt"
    },
    {
      "x": -9,
      "y": 16,
      "z": -2,
      "name": "Rock_Basalt"
    },
    {
      "x": -9,
      "y": 17,
      "z": -2,
      "name": "Rock_Basalt"
    },
    {
      "x": -9,
      "y": 18,
      "z": -2,
      "name": "Rock_Basalt"
    },
    {
      "x": -9,
      "y": 19,
      "z": -2,
      "name": "Ore_Iron_Basalt_Cracked"
    },
    {
      "x": -9,
      "y": 20,
      "z": -2,
      "name": "Rock_Basalt"
    },
    {
      "x": -9,
      "y": 21,
      "z": -2,
      "name": "Ore_Iron_Basalt_Cracked"
    },
    {
      "x": -9,
      "y": 22,
      "z": -2,
      "name": "Rock_Basalt"
    },
    {
      "x": -9,
      "y": 23,
      "z": -2,
      "name": "Soil_Ash"
    },
    {
      "x": -9,
      "y": 14,
      "z": -1,
      "name": "Rock_Basalt"
    },
    {
      "x": -9,
      "y": 15,
      "z": -1,
      "name": "Rock_Basalt"
    },
    {
      "x": -9,
      "y": 16,
      "z": -1,
      "name": "Rock_Basalt"
    },
    {
      "x": -9,
      "y": 17,
      "z": -1,
      "name": "Rock_Basalt"
    },
    {
      "x": -9,
      "y": 18,
      "z": -1,
      "name": "Rock_Basalt"
    },
    {
      "x": -9,
      "y": 19,
      "z": -1,
      "name": "Rock_Basalt"
    },
    {
      "x": -9,
      "y": 20,
      "z": -1,
      "name": "Rock_Basalt"
    },
    {
      "x": -9,
      "y": 21,
      "z": -1,
      "name": "Soil_Basalt_Gravel"
    },
    {
      "x": -9,
      "y": 22,
      "z": -1,
      "name": "Soil_Ash"
    },
    {
      "x": -9,
      "y": 12,
      "z": 0,
      "name": "Deco_SpiderWeb",
      "rotation": 9
    },
    {
      "x": -9,
      "y": 14,
      "z": 0,
      "name": "Rock_Basalt"
    },
    {
      "x": -9,
      "y": 15,
      "z": 0,
      "name": "Rock_Basalt"
    },
    {
      "x": -9,
      "y": 16,
      "z": 0,
      "name": "Rock_Basalt"
    },
    {
      "x": -9,
      "y": 17,
      "z": 0,
      "name": "Rock_Basalt"
    },
    {
      "x": -9,
      "y": 18,
      "z": 0,
      "name": "Rock_Basalt"
    },
    {
      "x": -9,
      "y": 19,
      "z": 0,
      "name": "Rock_Basalt"
    },
    {
      "x": -9,
      "y": 20,
      "z": 0,
      "name": "Ore_Iron_Basalt_Cracked"
    },
    {
      "x": -9,
      "y": 21,
      "z": 0,
      "name": "Rock_Basalt"
    },
    {
      "x": -9,
      "y": 22,
      "z": 0,
      "name": "Soil_Ash"
    },
    {
      "x": -9,
      "y": 11,
      "z": 1,
      "name": "Rock_Basalt_Stalactite_Large",
      "filler": 31744,
      "rotation": 8
    },
    {
      "x": -9,
      "y": 12,
      "z": 1,
      "name": "Rock_Basalt_Stalactite_Large",
      "rotation": 8
    },
    {
      "x": -9,
      "y": 13,
      "z": 1,
      "name": "Rock_Basalt"
    },
    {
      "x": -9,
      "y": 14,
      "z": 1,
      "name": "Rock_Basalt"
    },
    {
      "x": -9,
      "y": 15,
      "z": 1,
      "name": "Rock_Basalt"
    },
    {
      "x": -9,
      "y": 16,
      "z": 1,
      "name": "Ore_Iron_Basalt_Cracked"
    },
    {
      "x": -9,
      "y": 17,
      "z": 1,
      "name": "Rock_Basalt"
    },
    {
      "x": -9,
      "y": 18,
      "z": 1,
      "name": "Ore_Iron_Basalt_Cracked"
    },
    {
      "x": -9,
      "y": 19,
      "z": 1,
      "name": "Rock_Basalt"
    },
    {
      "x": -9,
      "y": 20,
      "z": 1,
      "name": "Ore_Iron_Basalt_Cracked"
    },
    {
      "x": -9,
      "y": 21,
      "z": 1,
      "name": "Ore_Iron_Basalt_Cracked"
    },
    {
      "x": -9,
      "y": 22,
      "z": 1,
      "name": "Soil_Ash"
    },
    {
      "x": -9,
      "y": 12,
      "z": 2,
      "name": "Rock_Basalt_Stalactite_Small",
      "rotation": 8
    },
    {
      "x": -9,
      "y": 13,
      "z": 2,
      "name": "Ore_Gold_Basalt"
    },
    {
      "x": -9,
      "y": 14,
      "z": 2,
      "name": "Rock_Basalt"
    },
    {
      "x": -9,
      "y": 15,
      "z": 2,
      "name": "Rock_Basalt"
    },
    {
      "x": -9,
      "y": 16,
      "z": 2,
      "name": "Rock_Basalt"
    },
    {
      "x": -9,
      "y": 17,
      "z": 2,
      "name": "Ore_Iron_Basalt_Cracked"
    },
    {
      "x": -9,
      "y": 18,
      "z": 2,
      "name": "Rock_Basalt"
    },
    {
      "x": -9,
      "y": 19,
      "z": 2,
      "name": "Rock_Basalt"
    },
    {
      "x": -9,
      "y": 20,
      "z": 2,
      "name": "Ore_Iron_Basalt_Cracked"
    },
    {
      "x": -9,
      "y": 21,
      "z": 2,
      "name": "Soil_Ash"
    },
    {
      "x": -9,
      "y": 12,
      "z": 3,
      "name": "Rock_Basalt"
    },
    {
      "x": -9,
      "y": 13,
      "z": 3,
      "name": "Rock_Basalt"
    },
    {
      "x": -9,
      "y": 14,
      "z": 3,
      "name": "Rock_Basalt"
    },
    {
      "x": -9,
      "y": 15,
      "z": 3,
      "name": "Rock_Basalt"
    },
    {
      "x": -9,
      "y": 16,
      "z": 3,
      "name": "Rock_Basalt"
    },
    {
      "x": -9,
      "y": 17,
      "z": 3,
      "name": "Rock_Basalt"
    },
    {
      "x": -9,
      "y": 18,
      "z": 3,
      "name": "Rock_Basalt"
    },
    {
      "x": -9,
      "y": 19,
      "z": 3,
      "name": "Ore_Iron_Basalt_Cracked"
    },
    {
      "x": -9,
      "y": 20,
      "z": 3,
      "name": "Ore_Iron_Basalt_Cracked"
    },
    {
      "x": -9,
      "y": 21,
      "z": 3,
      "name": "Soil_Sand_Ashen"
    },
    {
      "x": -9,
      "y": 22,
      "z": 3,
      "name": "Plant_Bramble_Dry_Twisted"
    },
    {
      "x": -9,
      "y": 11,
      "z": 4,
      "name": "Ore_Gold_Basalt"
    },
    {
      "x": -9,
      "y": 12,
      "z": 4,
      "name": "Ore_Gold_Basalt"
    },
    {
      "x": -9,
      "y": 13,
      "z": 4,
      "name": "Ore_Iron_Basalt_Cracked"
    },
    {
      "x": -9,
      "y": 14,
      "z": 4,
      "name": "Rock_Basalt"
    },
    {
      "x": -9,
      "y": 15,
      "z": 4,
      "name": "Ore_Iron_Basalt_Cracked"
    },
    {
      "x": -9,
      "y": 16,
      "z": 4,
      "name": "Rock_Basalt"
    },
    {
      "x": -9,
      "y": 17,
      "z": 4,
      "name": "Rock_Basalt"
    },
    {
      "x": -9,
      "y": 18,
      "z": 4,
      "name": "Rock_Basalt"
    },
    {
      "x": -9,
      "y": 19,
      "z": 4,
      "name": "Ore_Iron_Basalt_Cracked"
    },
    {
      "x": -9,
      "y": 20,
      "z": 4,
      "name": "Ore_Iron_Basalt_Cracked"
    },
    {
      "x": -9,
      "y": 21,
      "z": 4,
      "name": "Soil_Sand_Ashen"
    },
    {
      "x": -9,
      "y": 22,
      "z": 4,
      "name": "Plant_Bramble_Dry_Twisted"
    },
    {
      "x": -9,
      "y": 23,
      "z": 4,
      "name": "Plant_Bramble_Dry_Twisted"
    },
    {
      "x": -9,
      "y": 11,
      "z": 5,
      "name": "Rock_Basalt"
    },
    {
      "x": -9,
      "y": 12,
      "z": 5,
      "name": "Rock_Basalt"
    },
    {
      "x": -9,
      "y": 13,
      "z": 5,
      "name": "Rock_Basalt"
    },
    {
      "x": -9,
      "y": 14,
      "z": 5,
      "name": "Rock_Basalt"
    },
    {
      "x": -9,
      "y": 15,
      "z": 5,
      "name": "Ore_Iron_Basalt_Cracked"
    },
    {
      "x": -9,
      "y": 16,
      "z": 5,
      "name": "Rock_Basalt"
    },
    {
      "x": -9,
      "y": 17,
      "z": 5,
      "name": "Rock_Basalt"
    },
    {
      "x": -9,
      "y": 18,
      "z": 5,
      "name": "Rock_Basalt"
    },
    {
      "x": -9,
      "y": 19,
      "z": 5,
      "name": "Ore_Iron_Basalt"
    },
    {
      "x": -9,
      "y": 20,
      "z": 5,
      "name": "Rock_Basalt"
    },
    {
      "x": -9,
      "y": 21,
      "z": 5,
      "name": "Soil_Sand_Ashen"
    },
    {
      "x": -9,
      "y": 22,
      "z": 5,
      "name": "Plant_Bramble_Dry_Twisted"
    },
    {
      "x": -9,
      "y": 9,
      "z": 6,
      "name": "Rock_Crystal_Yellow_Medium",
      "rotation": 6
    },
    {
      "x": -9,
      "y": 10,
      "z": 6,
      "name": "Rock_Crystal_Yellow_Medium",
      "rotation": 6
    },
    {
      "x": -9,
      "y": 11,
      "z": 6,
      "name": "Ore_Iron_Basalt_Cracked"
    },
    {
      "x": -9,
      "y": 12,
      "z": 6,
      "name": "Ore_Iron_Basalt_Cracked"
    },
    {
      "x": -9,
      "y": 13,
      "z": 6,
      "name": "Ore_Iron_Basalt_Cracked"
    },
    {
      "x": -9,
      "y": 14,
      "z": 6,
      "name": "Ore_Iron_Basalt_Cracked"
    },
    {
      "x": -9,
      "y": 15,
      "z": 6,
      "name": "Rock_Basalt"
    },
    {
      "x": -9,
      "y": 16,
      "z": 6,
      "name": "Rock_Basalt"
    },
    {
      "x": -9,
      "y": 17,
      "z": 6,
      "name": "Rock_Basalt"
    },
    {
      "x": -9,
      "y": 18,
      "z": 6,
      "name": "Rock_Basalt"
    },
    {
      "x": -9,
      "y": 19,
      "z": 6,
      "name": "Ore_Iron_Basalt_Cracked"
    },
    {
      "x": -9,
      "y": 20,
      "z": 6,
      "name": "Soil_Basalt_Gravel"
    },
    {
      "x": -9,
      "y": 21,
      "z": 6,
      "name": "Soil_Sand_Ashen"
    },
    {
      "x": -9,
      "y": 8,
      "z": 7,
      "name": "Rock_Crystal_Yellow_Large",
      "rotation": 8
    },
    {
      "x": -9,
      "y": 9,
      "z": 7,
      "name": "Rock_Crystal_Yellow_Block"
    },
    {
      "x": -9,
      "y": 10,
      "z": 7,
      "name": "Rock_Crystal_Yellow_Block"
    },
    {
      "x": -9,
      "y": 11,
      "z": 7,
      "name": "Rock_Crystal_Yellow_Block"
    },
    {
      "x": -9,
      "y": 12,
      "z": 7,
      "name": "Rock_Crystal_Yellow_Block"
    },
    {
      "x": -9,
      "y": 13,
      "z": 7,
      "name": "Rock_Crystal_Yellow_Block"
    },
    {
      "x": -9,
      "y": 14,
      "z": 7,
      "name": "Rock_Crystal_Yellow_Block"
    },
    {
      "x": -9,
      "y": 15,
      "z": 7,
      "name": "Rock_Basalt"
    },
    {
      "x": -9,
      "y": 16,
      "z": 7,
      "name": "Ore_Iron_Basalt_Cracked"
    },
    {
      "x": -9,
      "y": 17,
      "z": 7,
      "name": "Rock_Basalt"
    },
    {
      "x": -9,
      "y": 18,
      "z": 7,
      "name": "Rock_Basalt"
    },
    {
      "x": -9,
      "y": 19,
      "z": 7,
      "name": "Ore_Iron_Basalt_Cracked"
    },
    {
      "x": -9,
      "y": 20,
      "z": 7,
      "name": "Rock_Basalt"
    },
    {
      "x": -9,
      "y": 21,
      "z": 7,
      "name": "Soil_Sand_Ashen"
    },
    {
      "x": -9,
      "y": 9,
      "z": 8,
      "name": "Rock_Crystal_Yellow_Medium",
      "rotation": 4
    },
    {
      "x": -9,
      "y": 11,
      "z": 8,
      "name": "Rock_Basalt"
    },
    {
      "x": -9,
      "y": 12,
      "z": 8,
      "name": "Ore_Iron_Basalt_Cracked"
    },
    {
      "x": -9,
      "y": 13,
      "z": 8,
      "name": "Ore_Iron_Basalt_Cracked"
    },
    {
      "x": -9,
      "y": 14,
      "z": 8,
      "name": "Rock_Basalt"
    },
    {
      "x": -9,
      "y": 15,
      "z": 8,
      "name": "Rock_Basalt"
    },
    {
      "x": -9,
      "y": 16,
      "z": 8,
      "name": "Rock_Basalt"
    },
    {
      "x": -9,
      "y": 17,
      "z": 8,
      "name": "Rock_Basalt"
    },
    {
      "x": -9,
      "y": 18,
      "z": 8,
      "name": "Ore_Iron_Basalt_Cracked"
    },
    {
      "x": -9,
      "y": 19,
      "z": 8,
      "name": "Rock_Basalt"
    },
    {
      "x": -9,
      "y": 20,
      "z": 8,
      "name": "Rock_Basalt"
    },
    {
      "x": -9,
      "y": 21,
      "z": 8,
      "name": "Rock_Basalt"
    },
    {
      "x": -9,
      "y": 11,
      "z": 9,
      "name": "Rock_Basalt"
    },
    {
      "x": -9,
      "y": 12,
      "z": 9,
      "name": "Rock_Basalt"
    },
    {
      "x": -9,
      "y": 13,
      "z": 9,
      "name": "Rock_Basalt"
    },
    {
      "x": -9,
      "y": 14,
      "z": 9,
      "name": "Ore_Iron_Basalt_Cracked"
    },
    {
      "x": -9,
      "y": 15,
      "z": 9,
      "name": "Rock_Basalt"
    },
    {
      "x": -9,
      "y": 16,
      "z": 9,
      "name": "Rock_Basalt"
    },
    {
      "x": -9,
      "y": 17,
      "z": 9,
      "name": "Rock_Basalt"
    },
    {
      "x": -9,
      "y": 18,
      "z": 9,
      "name": "Rock_Basalt"
    },
    {
      "x": -9,
      "y": 19,
      "z": 9,
      "name": "Rock_Basalt"
    },
    {
      "x": -9,
      "y": 20,
      "z": 9,
      "name": "Soil_Ash"
    },
    {
      "x": -9,
      "y": 37,
      "z": 9,
      "name": "Wood_Ash_Branch_Corner",
      "rotation": 3
    },
    {
      "x": -9,
      "y": 38,
      "z": 9,
      "name": "Wood_Ash_Branch_Corner",
      "rotation": 11
    },
    {
      "x": -9,
      "y": 11,
      "z": 10,
      "name": "Rock_Basalt"
    },
    {
      "x": -9,
      "y": 12,
      "z": 10,
      "name": "Rock_Basalt"
    },
    {
      "x": -9,
      "y": 13,
      "z": 10,
      "name": "Rock_Basalt"
    },
    {
      "x": -9,
      "y": 14,
      "z": 10,
      "name": "Ore_Iron_Basalt_Cracked"
    },
    {
      "x": -9,
      "y": 15,
      "z": 10,
      "name": "Rock_Basalt"
    },
    {
      "x": -9,
      "y": 16,
      "z": 10,
      "name": "Ore_Iron_Basalt_Cracked"
    },
    {
      "x": -9,
      "y": 17,
      "z": 10,
      "name": "Rock_Basalt"
    },
    {
      "x": -9,
      "y": 18,
      "z": 10,
      "name": "Rock_Basalt"
    },
    {
      "x": -9,
      "y": 19,
      "z": 10,
      "name": "Ore_Iron_Basalt_Cracked"
    },
    {
      "x": -9,
      "y": 20,
      "z": 10,
      "name": "Soil_Ash"
    },
    {
      "x": -9,
      "y": 12,
      "z": 11,
      "name": "Rock_Basalt"
    },
    {
      "x": -9,
      "y": 13,
      "z": 11,
      "name": "Ore_Iron_Basalt_Cracked"
    },
    {
      "x": -9,
      "y": 14,
      "z": 11,
      "name": "Ore_Iron_Basalt_Cracked"
    },
    {
      "x": -9,
      "y": 15,
      "z": 11,
      "name": "Rock_Basalt"
    },
    {
      "x": -9,
      "y": 16,
      "z": 11,
      "name": "Rock_Basalt"
    },
    {
      "x": -9,
      "y": 17,
      "z": 11,
      "name": "Ore_Iron_Basalt_Cracked"
    },
    {
      "x": -9,
      "y": 18,
      "z": 11,
      "name": "Rock_Basalt"
    },
    {
      "x": -9,
      "y": 19,
      "z": 11,
      "name": "Soil_Ash"
    },
    {
      "x": -9,
      "y": 20,
      "z": 11,
      "name": "Plant_Moss_Yellow"
    },
    {
      "x": -9,
      "y": 12,
      "z": 12,
      "name": "Ore_Iron_Basalt_Cracked"
    },
    {
      "x": -9,
      "y": 13,
      "z": 12,
      "name": "Ore_Iron_Basalt_Cracked"
    },
    {
      "x": -9,
      "y": 14,
      "z": 12,
      "name": "Rock_Basalt"
    },
    {
      "x": -9,
      "y": 15,
      "z": 12,
      "name": "Rock_Basalt"
    },
    {
      "x": -9,
      "y": 16,
      "z": 12,
      "name": "Rock_Basalt"
    },
    {
      "x": -9,
      "y": 17,
      "z": 12,
      "name": "Ore_Iron_Basalt_Cracked"
    },
    {
      "x": -9,
      "y": 18,
      "z": 12,
      "name": "Rock_Basalt"
    },
    {
      "x": -9,
      "y": 19,
      "z": 12,
      "name": "Soil_Ash"
    },
    {
      "x": -9,
      "y": 12,
      "z": 13,
      "name": "Rock_Basalt"
    },
    {
      "x": -9,
      "y": 13,
      "z": 13,
      "name": "Ore_Iron_Basalt_Cracked"
    },
    {
      "x": -9,
      "y": 14,
      "z": 13,
      "name": "Rock_Basalt"
    },
    {
      "x": -9,
      "y": 15,
      "z": 13,
      "name": "Rock_Basalt"
    },
    {
      "x": -9,
      "y": 16,
      "z": 13,
      "name": "Rock_Basalt"
    },
    {
      "x": -9,
      "y": 17,
      "z": 13,
      "name": "Ore_Iron_Basalt_Cracked"
    },
    {
      "x": -9,
      "y": 18,
      "z": 13,
      "name": "Soil_Basalt_Gravel"
    },
    {
      "x": -9,
      "y": 19,
      "z": 13,
      "name": "Soil_Ash"
    },
    {
      "x": -9,
      "y": 20,
      "z": 13,
      "name": "Plant_Flower_Bushy_Yellow"
    },
    {
      "x": -9,
      "y": 11,
      "z": 14,
      "name": "Rock_Basalt"
    },
    {
      "x": -9,
      "y": 12,
      "z": 14,
      "name": "Rock_Basalt"
    },
    {
      "x": -9,
      "y": 13,
      "z": 14,
      "name": "Rock_Basalt"
    },
    {
      "x": -9,
      "y": 14,
      "z": 14,
      "name": "Ore_Iron_Basalt_Cracked"
    },
    {
      "x": -9,
      "y": 15,
      "z": 14,
      "name": "Rock_Basalt"
    },
    {
      "x": -9,
      "y": 16,
      "z": 14,
      "name": "Ore_Iron_Basalt_Cracked"
    },
    {
      "x": -9,
      "y": 17,
      "z": 14,
      "name": "Soil_Basalt_Gravel"
    },
    {
      "x": -9,
      "y": 18,
      "z": 14,
      "name": "Soil_Ash"
    },
    {
      "x": -9,
      "y": 19,
      "z": 14,
      "name": "Plant_Flower_Bushy_Yellow"
    },
    {
      "x": -9,
      "y": 12,
      "z": 15,
      "name": "Rock_Basalt"
    },
    {
      "x": -9,
      "y": 13,
      "z": 15,
      "name": "Ore_Iron_Basalt_Cracked"
    },
    {
      "x": -9,
      "y": 14,
      "z": 15,
      "name": "Ore_Iron_Basalt_Cracked"
    },
    {
      "x": -9,
      "y": 15,
      "z": 15,
      "name": "Rock_Basalt"
    },
    {
      "x": -9,
      "y": 16,
      "z": 15,
      "name": "Ore_Iron_Basalt_Cracked"
    },
    {
      "x": -9,
      "y": 17,
      "z": 15,
      "name": "Ore_Iron_Basalt_Cracked"
    },
    {
      "x": -9,
      "y": 18,
      "z": 15,
      "name": "Soil_Ash"
    },
    {
      "x": -9,
      "y": 12,
      "z": 16,
      "name": "Rock_Basalt"
    },
    {
      "x": -9,
      "y": 13,
      "z": 16,
      "name": "Rock_Basalt"
    },
    {
      "x": -9,
      "y": 14,
      "z": 16,
      "name": "Rock_Basalt"
    },
    {
      "x": -9,
      "y": 15,
      "z": 16,
      "name": "Rock_Basalt"
    },
    {
      "x": -9,
      "y": 16,
      "z": 16,
      "name": "Rock_Basalt"
    },
    {
      "x": -9,
      "y": 17,
      "z": 16,
      "name": "Ore_Iron_Basalt"
    },
    {
      "x": -9,
      "y": 18,
      "z": 16,
      "name": "Rock_Basalt"
    },
    {
      "x": -9,
      "y": 19,
      "z": 16,
      "name": "Soil_Ash"
    },
    {
      "x": -9,
      "y": 14,
      "z": 17,
      "name": "Ore_Iron_Basalt_Cracked"
    },
    {
      "x": -9,
      "y": 15,
      "z": 17,
      "name": "Rock_Basalt"
    },
    {
      "x": -9,
      "y": 16,
      "z": 17,
      "name": "Rock_Basalt"
    },
    {
      "x": -9,
      "y": 17,
      "z": 17,
      "name": "Soil_Basalt_Gravel"
    },
    {
      "x": -9,
      "y": 18,
      "z": 17,
      "name": "Soil_Ash"
    },
    {
      "x": -9,
      "y": 16,
      "z": 18,
      "name": "Deco_SpiderWeb_Flat",
      "rotation": 4
    },
    {
      "x": -8,
      "y": 20,
      "z": -9,
      "name": "Ore_Iron_Basalt_Cracked"
    },
    {
      "x": -8,
      "y": 23,
      "z": -9,
      "name": "Deco_SpiderWeb_Flat",
      "rotation": 7
    },
    {
      "x": -8,
      "y": 17,
      "z": -8,
      "name": "Ore_Iron_Basalt_Cracked"
    },
    {
      "x": -8,
      "y": 18,
      "z": -8,
      "name": "Ore_Iron_Basalt_Cracked"
    },
    {
      "x": -8,
      "y": 19,
      "z": -8,
      "name": "Rock_Basalt"
    },
    {
      "x": -8,
      "y": 20,
      "z": -8,
      "name": "Rock_Basalt"
    },
    {
      "x": -8,
      "y": 21,
      "z": -8,
      "name": "Ore_Iron_Basalt_Cracked"
    },
    {
      "x": -8,
      "y": 22,
      "z": -8,
      "name": "Soil_Ash"
    },
    {
      "x": -8,
      "y": 23,
      "z": -8,
      "name": "Plant_Flower_Bushy_Yellow"
    },
    {
      "x": -8,
      "y": 16,
      "z": -7,
      "name": "Rock_Basalt"
    },
    {
      "x": -8,
      "y": 17,
      "z": -7,
      "name": "Rock_Basalt"
    },
    {
      "x": -8,
      "y": 18,
      "z": -7,
      "name": "Ore_Iron_Basalt_Cracked"
    },
    {
      "x": -8,
      "y": 19,
      "z": -7,
      "name": "Rock_Basalt"
    },
    {
      "x": -8,
      "y": 20,
      "z": -7,
      "name": "Rock_Basalt"
    },
    {
      "x": -8,
      "y": 21,
      "z": -7,
      "name": "Rock_Basalt"
    },
    {
      "x": -8,
      "y": 22,
      "z": -7,
      "name": "Ore_Iron_Basalt_Cracked"
    },
    {
      "x": -8,
      "y": 23,
      "z": -7,
      "name": "Ore_Iron_Basalt_Cracked"
    },
    {
      "x": -8,
      "y": 24,
      "z": -7,
      "name": "Soil_Ash"
    },
    {
      "x": -8,
      "y": 25,
      "z": -7,
      "name": "Rock_Crystal_Yellow_Small"
    },
    {
      "x": -8,
      "y": 15,
      "z": -6,
      "name": "Ore_Iron_Basalt_Cracked"
    },
    {
      "x": -8,
      "y": 16,
      "z": -6,
      "name": "Ore_Iron_Basalt_Cracked"
    },
    {
      "x": -8,
      "y": 17,
      "z": -6,
      "name": "Rock_Basalt"
    },
    {
      "x": -8,
      "y": 18,
      "z": -6,
      "name": "Ore_Iron_Basalt_Cracked"
    },
    {
      "x": -8,
      "y": 19,
      "z": -6,
      "name": "Rock_Basalt"
    },
    {
      "x": -8,
      "y": 20,
      "z": -6,
      "name": "Rock_Basalt"
    },
    {
      "x": -8,
      "y": 21,
      "z": -6,
      "name": "Rock_Basalt"
    },
    {
      "x": -8,
      "y": 22,
      "z": -6,
      "name": "Ore_Iron_Basalt"
    },
    {
      "x": -8,
      "y": 23,
      "z": -6,
      "name": "Rock_Basalt"
    },
    {
      "x": -8,
      "y": 24,
      "z": -6,
      "name": "Soil_Ash"
    },
    {
      "x": -8,
      "y": 25,
      "z": -6,
      "name": "Plant_Flower_Bushy_Yellow"
    },
    {
      "x": -8,
      "y": 10,
      "z": -5,
      "name": "Rock_Crystal_Yellow_Medium",
      "rotation": 7
    },
    {
      "x": -8,
      "y": 11,
      "z": -5,
      "name": "Rock_Crystal_Yellow_Medium",
      "rotation": 7
    },
    {
      "x": -8,
      "y": 12,
      "z": -5,
      "name": "Rock_Crystal_Yellow_Large",
      "rotation": 7
    },
    {
      "x": -8,
      "y": 14,
      "z": -5,
      "name": "Ore_Iron_Basalt_Cracked"
    },
    {
      "x": -8,
      "y": 15,
      "z": -5,
      "name": "Rock_Basalt"
    },
    {
      "x": -8,
      "y": 16,
      "z": -5,
      "name": "Rock_Basalt"
    },
    {
      "x": -8,
      "y": 17,
      "z": -5,
      "name": "Rock_Basalt"
    },
    {
      "x": -8,
      "y": 18,
      "z": -5,
      "name": "Rock_Basalt"
    },
    {
      "x": -8,
      "y": 19,
      "z": -5,
      "name": "Rock_Basalt"
    },
    {
      "x": -8,
      "y": 20,
      "z": -5,
      "name": "Rock_Basalt"
    },
    {
      "x": -8,
      "y": 21,
      "z": -5,
      "name": "Ore_Iron_Basalt_Cracked"
    },
    {
      "x": -8,
      "y": 22,
      "z": -5,
      "name": "Soil_Basalt_Gravel"
    },
    {
      "x": -8,
      "y": 23,
      "z": -5,
      "name": "Soil_Ash"
    },
    {
      "x": -8,
      "y": 14,
      "z": -4,
      "name": "Ore_Iron_Basalt_Cracked"
    },
    {
      "x": -8,
      "y": 15,
      "z": -4,
      "name": "Rock_Basalt"
    },
    {
      "x": -8,
      "y": 16,
      "z": -4,
      "name": "Rock_Basalt"
    },
    {
      "x": -8,
      "y": 17,
      "z": -4,
      "name": "Rock_Basalt"
    },
    {
      "x": -8,
      "y": 18,
      "z": -4,
      "name": "Ore_Iron_Basalt_Cracked"
    },
    {
      "x": -8,
      "y": 19,
      "z": -4,
      "name": "Ore_Iron_Basalt_Cracked"
    },
    {
      "x": -8,
      "y": 20,
      "z": -4,
      "name": "Ore_Iron_Basalt_Cracked"
    },
    {
      "x": -8,
      "y": 21,
      "z": -4,
      "name": "Rock_Basalt"
    },
    {
      "x": -8,
      "y": 22,
      "z": -4,
      "name": "Soil_Ash"
    },
    {
      "x": -8,
      "y": 13,
      "z": -3,
      "name": "Rock_Basalt"
    },
    {
      "x": -8,
      "y": 14,
      "z": -3,
      "name": "Rock_Basalt"
    },
    {
      "x": -8,
      "y": 15,
      "z": -3,
      "name": "Rock_Basalt"
    },
    {
      "x": -8,
      "y": 16,
      "z": -3,
      "name": "Rock_Basalt"
    },
    {
      "x": -8,
      "y": 17,
      "z": -3,
      "name": "Rock_Basalt"
    },
    {
      "x": -8,
      "y": 18,
      "z": -3,
      "name": "Rock_Basalt"
    },
    {
      "x": -8,
      "y": 19,
      "z": -3,
      "name": "Ore_Iron_Basalt_Cracked"
    },
    {
      "x": -8,
      "y": 20,
      "z": -3,
      "name": "Rock_Basalt"
    },
    {
      "x": -8,
      "y": 21,
      "z": -3,
      "name": "Rock_Basalt"
    },
    {
      "x": -8,
      "y": 22,
      "z": -3,
      "name": "Soil_Ash"
    },
    {
      "x": -8,
      "y": 12,
      "z": -2,
      "name": "Rock_Basalt"
    },
    {
      "x": -8,
      "y": 13,
      "z": -2,
      "name": "Rock_Basalt"
    },
    {
      "x": -8,
      "y": 14,
      "z": -2,
      "name": "Rock_Basalt"
    },
    {
      "x": -8,
      "y": 15,
      "z": -2,
      "name": "Ore_Iron_Basalt_Cracked"
    },
    {
      "x": -8,
      "y": 16,
      "z": -2,
      "name": "Rock_Basalt"
    },
    {
      "x": -8,
      "y": 17,
      "z": -2,
      "name": "Rock_Basalt"
    },
    {
      "x": -8,
      "y": 18,
      "z": -2,
      "name": "Ore_Iron_Basalt_Cracked"
    },
    {
      "x": -8,
      "y": 19,
      "z": -2,
      "name": "Ore_Iron_Basalt_Cracked"
    },
    {
      "x": -8,
      "y": 20,
      "z": -2,
      "name": "Rock_Basalt"
    },
    {
      "x": -8,
      "y": 21,
      "z": -2,
      "name": "Soil_Basalt_Gravel"
    },
    {
      "x": -8,
      "y": 22,
      "z": -2,
      "name": "Soil_Ash"
    },
    {
      "x": -8,
      "y": 12,
      "z": -1,
      "name": "Rock_Basalt"
    },
    {
      "x": -8,
      "y": 13,
      "z": -1,
      "name": "Rock_Basalt"
    },
    {
      "x": -8,
      "y": 14,
      "z": -1,
      "name": "Rock_Basalt"
    },
    {
      "x": -8,
      "y": 15,
      "z": -1,
      "name": "Rock_Basalt"
    },
    {
      "x": -8,
      "y": 16,
      "z": -1,
      "name": "Rock_Basalt"
    },
    {
      "x": -8,
      "y": 17,
      "z": -1,
      "name": "Rock_Basalt"
    },
    {
      "x": -8,
      "y": 18,
      "z": -1,
      "name": "Rock_Basalt"
    },
    {
      "x": -8,
      "y": 19,
      "z": -1,
      "name": "Rock_Basalt"
    },
    {
      "x": -8,
      "y": 20,
      "z": -1,
      "name": "Ore_Iron_Basalt_Cracked"
    },
    {
      "x": -8,
      "y": 21,
      "z": -1,
      "name": "Rock_Basalt"
    },
    {
      "x": -8,
      "y": 22,
      "z": -1,
      "name": "Soil_Ash"
    },
    {
      "x": -8,
      "y": 12,
      "z": 0,
      "name": "Rock_Basalt"
    },
    {
      "x": -8,
      "y": 13,
      "z": 0,
      "name": "Rock_Basalt"
    },
    {
      "x": -8,
      "y": 14,
      "z": 0,
      "name": "Rock_Basalt"
    },
    {
      "x": -8,
      "y": 15,
      "z": 0,
      "name": "Rock_Basalt"
    },
    {
      "x": -8,
      "y": 16,
      "z": 0,
      "name": "Rock_Basalt"
    },
    {
      "x": -8,
      "y": 17,
      "z": 0,
      "name": "Rock_Basalt"
    },
    {
      "x": -8,
      "y": 18,
      "z": 0,
      "name": "Ore_Iron_Basalt_Cracked"
    },
    {
      "x": -8,
      "y": 19,
      "z": 0,
      "name": "Rock_Basalt"
    },
    {
      "x": -8,
      "y": 20,
      "z": 0,
      "name": "Ore_Iron_Basalt_Cracked"
    },
    {
      "x": -8,
      "y": 21,
      "z": 0,
      "name": "Rock_Basalt"
    },
    {
      "x": -8,
      "y": 22,
      "z": 0,
      "name": "Soil_Ash"
    },
    {
      "x": -8,
      "y": 11,
      "z": 1,
      "name": "Rock_Basalt"
    },
    {
      "x": -8,
      "y": 12,
      "z": 1,
      "name": "Rock_Basalt"
    },
    {
      "x": -8,
      "y": 13,
      "z": 1,
      "name": "Rock_Basalt"
    },
    {
      "x": -8,
      "y": 14,
      "z": 1,
      "name": "Ore_Iron_Basalt_Cracked"
    },
    {
      "x": -8,
      "y": 15,
      "z": 1,
      "name": "Rock_Basalt"
    },
    {
      "x": -8,
      "y": 16,
      "z": 1,
      "name": "Rock_Basalt"
    },
    {
      "x": -8,
      "y": 17,
      "z": 1,
      "name": "Ore_Iron_Basalt_Cracked"
    },
    {
      "x": -8,
      "y": 18,
      "z": 1,
      "name": "Ore_Iron_Basalt_Cracked"
    },
    {
      "x": -8,
      "y": 19,
      "z": 1,
      "name": "Rock_Basalt"
    },
    {
      "x": -8,
      "y": 20,
      "z": 1,
      "name": "Rock_Basalt"
    },
    {
      "x": -8,
      "y": 21,
      "z": 1,
      "name": "Soil_Ash"
    },
    {
      "x": -8,
      "y": 11,
      "z": 2,
      "name": "Ore_Iron_Basalt_Cracked"
    },
    {
      "x": -8,
      "y": 12,
      "z": 2,
      "name": "Ore_Iron_Basalt_Cracked"
    },
    {
      "x": -8,
      "y": 13,
      "z": 2,
      "name": "Ore_Iron_Basalt"
    },
    {
      "x": -8,
      "y": 14,
      "z": 2,
      "name": "Ore_Iron_Basalt_Cracked"
    },
    {
      "x": -8,
      "y": 15,
      "z": 2,
      "name": "Ore_Iron_Basalt_Cracked"
    },
    {
      "x": -8,
      "y": 16,
      "z": 2,
      "name": "Rock_Basalt"
    },
    {
      "x": -8,
      "y": 17,
      "z": 2,
      "name": "Rock_Basalt"
    },
    {
      "x": -8,
      "y": 18,
      "z": 2,
      "name": "Rock_Basalt"
    },
    {
      "x": -8,
      "y": 19,
      "z": 2,
      "name": "Ore_Iron_Basalt_Cracked"
    },
    {
      "x": -8,
      "y": 20,
      "z": 2,
      "name": "Ore_Iron_Basalt_Cracked"
    },
    {
      "x": -8,
      "y": 21,
      "z": 2,
      "name": "Soil_Sand_Ashen"
    },
    {
      "x": -8,
      "y": 22,
      "z": 2,
      "name": "Plant_Bramble_Dry_Twisted"
    },
    {
      "x": -8,
      "y": 11,
      "z": 3,
      "name": "Rock_Basalt"
    },
    {
      "x": -8,
      "y": 12,
      "z": 3,
      "name": "Ore_Iron_Basalt_Cracked"
    },
    {
      "x": -8,
      "y": 13,
      "z": 3,
      "name": "Rock_Basalt"
    },
    {
      "x": -8,
      "y": 14,
      "z": 3,
      "name": "Rock_Basalt"
    },
    {
      "x": -8,
      "y": 15,
      "z": 3,
      "name": "Rock_Basalt"
    },
    {
      "x": -8,
      "y": 16,
      "z": 3,
      "name": "Rock_Basalt"
    },
    {
      "x": -8,
      "y": 17,
      "z": 3,
      "name": "Ore_Iron_Basalt_Cracked"
    },
    {
      "x": -8,
      "y": 18,
      "z": 3,
      "name": "Rock_Basalt"
    },
    {
      "x": -8,
      "y": 19,
      "z": 3,
      "name": "Ore_Iron_Basalt"
    },
    {
      "x": -8,
      "y": 20,
      "z": 3,
      "name": "Rock_Basalt"
    },
    {
      "x": -8,
      "y": 21,
      "z": 3,
      "name": "Soil_Sand_Ashen"
    },
    {
      "x": -8,
      "y": 22,
      "z": 3,
      "name": "Plant_Bramble_Dry_Twisted"
    },
    {
      "x": -8,
      "y": 11,
      "z": 4,
      "name": "Ore_Iron_Basalt"
    },
    {
      "x": -8,
      "y": 12,
      "z": 4,
      "name": "Ore_Silver_Basalt"
    },
    {
      "x": -8,
      "y": 13,
      "z": 4,
      "name": "Ore_Iron_Basalt_Cracked"
    },
    {
      "x": -8,
      "y": 14,
      "z": 4,
      "name": "Rock_Basalt"
    },
    {
      "x": -8,
      "y": 15,
      "z": 4,
      "name": "Rock_Basalt"
    },
    {
      "x": -8,
      "y": 16,
      "z": 4,
      "name": "Rock_Basalt"
    },
    {
      "x": -8,
      "y": 17,
      "z": 4,
      "name": "Rock_Basalt"
    },
    {
      "x": -8,
      "y": 18,
      "z": 4,
      "name": "Ore_Iron_Basalt_Cracked"
    },
    {
      "x": -8,
      "y": 19,
      "z": 4,
      "name": "Ore_Iron_Basalt_Cracked"
    },
    {
      "x": -8,
      "y": 20,
      "z": 4,
      "name": "Ore_Iron_Basalt_Cracked"
    },
    {
      "x": -8,
      "y": 21,
      "z": 4,
      "name": "Soil_Sand_Ashen"
    },
    {
      "x": -8,
      "y": 22,
      "z": 4,
      "name": "Plant_Bramble_Dry_Twisted"
    },
    {
      "x": -8,
      "y": 10,
      "z": 5,
      "name": "Ore_Iron_Basalt_Cracked"
    },
    {
      "x": -8,
      "y": 11,
      "z": 5,
      "name": "Rock_Basalt"
    },
    {
      "x": -8,
      "y": 12,
      "z": 5,
      "name": "Rock_Basalt"
    },
    {
      "x": -8,
      "y": 13,
      "z": 5,
      "name": "Rock_Basalt"
    },
    {
      "x": -8,
      "y": 14,
      "z": 5,
      "name": "Ore_Iron_Basalt_Cracked"
    },
    {
      "x": -8,
      "y": 15,
      "z": 5,
      "name": "Rock_Basalt"
    },
    {
      "x": -8,
      "y": 16,
      "z": 5,
      "name": "Ore_Iron_Basalt_Cracked"
    },
    {
      "x": -8,
      "y": 17,
      "z": 5,
      "name": "Rock_Basalt"
    },
    {
      "x": -8,
      "y": 18,
      "z": 5,
      "name": "Rock_Basalt"
    },
    {
      "x": -8,
      "y": 19,
      "z": 5,
      "name": "Ore_Iron_Basalt_Cracked"
    },
    {
      "x": -8,
      "y": 20,
      "z": 5,
      "name": "Rock_Basalt"
    },
    {
      "x": -8,
      "y": 21,
      "z": 5,
      "name": "Soil_Sand_Ashen"
    },
    {
      "x": -8,
      "y": 8,
      "z": 6,
      "name": "Rock_Basalt_Stalactite_Large",
      "filler": 31744,
      "rotation": 8
    },
    {
      "x": -8,
      "y": 9,
      "z": 6,
      "name": "Rock_Basalt_Stalactite_Large",
      "rotation": 8
    },
    {
      "x": -8,
      "y": 10,
      "z": 6,
      "name": "Rock_Basalt"
    },
    {
      "x": -8,
      "y": 11,
      "z": 6,
      "name": "Rock_Basalt"
    },
    {
      "x": -8,
      "y": 12,
      "z": 6,
      "name": "Rock_Basalt"
    },
    {
      "x": -8,
      "y": 13,
      "z": 6,
      "name": "Ore_Iron_Basalt_Cracked"
    },
    {
      "x": -8,
      "y": 14,
      "z": 6,
      "name": "Rock_Basalt"
    },
    {
      "x": -8,
      "y": 15,
      "z": 6,
      "name": "Rock_Basalt"
    },
    {
      "x": -8,
      "y": 16,
      "z": 6,
      "name": "Rock_Basalt"
    },
    {
      "x": -8,
      "y": 17,
      "z": 6,
      "name": "Ore_Iron_Basalt_Cracked"
    },
    {
      "x": -8,
      "y": 18,
      "z": 6,
      "name": "Rock_Basalt"
    },
    {
      "x": -8,
      "y": 19,
      "z": 6,
      "name": "Soil_Basalt_Gravel"
    },
    {
      "x": -8,
      "y": 20,
      "z": 6,
      "name": "Soil_Sand_Ashen"
    },
    {
      "x": -8,
      "y": 10,
      "z": 7,
      "name": "Ore_Iron_Basalt_Cracked"
    },
    {
      "x": -8,
      "y": 11,
      "z": 7,
      "name": "Rock_Basalt"
    },
    {
      "x": -8,
      "y": 12,
      "z": 7,
      "name": "Rock_Basalt"
    },
    {
      "x": -8,
      "y": 13,
      "z": 7,
      "name": "Ore_Iron_Basalt_Cracked"
    },
    {
      "x": -8,
      "y": 14,
      "z": 7,
      "name": "Rock_Basalt"
    },
    {
      "x": -8,
      "y": 15,
      "z": 7,
      "name": "Rock_Basalt"
    },
    {
      "x": -8,
      "y": 16,
      "z": 7,
      "name": "Rock_Basalt"
    },
    {
      "x": -8,
      "y": 17,
      "z": 7,
      "name": "Rock_Basalt"
    },
    {
      "x": -8,
      "y": 18,
      "z": 7,
      "name": "Rock_Basalt"
    },
    {
      "x": -8,
      "y": 19,
      "z": 7,
      "name": "Ore_Iron_Basalt_Cracked"
    },
    {
      "x": -8,
      "y": 20,
      "z": 7,
      "name": "Soil_Ash"
    },
    {
      "x": -8,
      "y": 11,
      "z": 8,
      "name": "Ore_Iron_Basalt_Cracked"
    },
    {
      "x": -8,
      "y": 12,
      "z": 8,
      "name": "Rock_Basalt"
    },
    {
      "x": -8,
      "y": 13,
      "z": 8,
      "name": "Rock_Basalt"
    },
    {
