{
  "version": 8,
  "blockIdVersion": 11,
  "anchorX": 0,
  "anchorY": 0,
  "anchorZ": 0,
  "blocks": [
    {
      "x": -12,
      "y": 13,
      "z": 2,
      "name": "Deco_SpiderWeb_Flat",
      "rotation": 7
    },
    {
      "x": -12,
      "y": 12,
      "z": 3,
      "name": "Deco_SpiderWeb_Flat",
      "rotation": 7
    },
    {
      "x": -12,
      "y": 14,
      "z": 6,
      "name": "Deco_SpiderWeb_Flat",
      "rotation": 7
    },
    {
      "x": -12,
      "y": 14,
      "z": 7,
      "name": "Deco_SpiderWeb_Flat",
      "rotation": 7
    },
    {
      "x": -11,
      "y": 13,
      "z": 0,
      "name": "Deco_SpiderWeb_Flat",
      "rotation": 7
    },
    {
      "x": -11,
      "y": 14,
      "z": 0,
      "name": "Deco_SpiderWeb_Flat",
      "rotation": 6
    },
    {
      "x": -11,
      "y": 10,
      "z": 1,
      "name": "Rock_Basalt"
    },
    {
      "x": -11,
      "y": 11,
      "z": 1,
      "name": "Ore_Iron_Basalt_Cracked"
    },
    {
      "x": -11,
      "y": 12,
      "z": 1,
      "name": "Ore_Iron_Basalt_Cracked"
    },
    {
      "x": -11,
      "y": 13,
      "z": 1,
      "name": "Rock_Basalt"
    },
    {
      "x": -11,
      "y": 14,
      "z": 1,
      "name": "Soil_Sand_Ashen"
    },
    {
      "x": -11,
      "y": 15,
      "z": 1,
      "name": "Soil_Sand_Ashen"
    },
    {
      "x": -11,
      "y": 10,
      "z": 2,
      "name": "Rock_Basalt"
    },
    {
      "x": -11,
      "y": 11,
      "z": 2,
      "name": "Rock_Basalt"
    },
    {
      "x": -11,
      "y": 12,
      "z": 2,
      "name": "Ore_Iron_Basalt_Cracked"
    },
    {
      "x": -11,
      "y": 13,
      "z": 2,
      "name": "Ore_Iron_Basalt_Cracked"
    },
    {
      "x": -11,
      "y": 14,
      "z": 2,
      "name": "Soil_Sand_Ashen"
    },
    {
      "x": -11,
      "y": 15,
      "z": 2,
      "name": "Soil_Sand_Ashen"
    },
    {
      "x": -11,
      "y": 10,
      "z": 3,
      "name": "Rock_Basalt"
    },
    {
      "x": -11,
      "y": 11,
      "z": 3,
      "name": "Rock_Basalt"
    },
    {
      "x": -11,
      "y": 12,
      "z": 3,
      "name": "Ore_Iron_Basalt"
    },
    {
      "x": -11,
      "y": 13,
      "z": 3,
      "name": "Rock_Basalt"
    },
    {
      "x": -11,
      "y": 14,
      "z": 3,
      "name": "Soil_Sand_Ashen"
    },
    {
      "x": -11,
      "y": 13,
      "z": 5,
      "name": "Ore_Iron_Basalt_Cracked"
    },
    {
      "x": -11,
      "y": 14,
      "z": 5,
      "name": "Rock_Basalt"
    },
    {
      "x": -11,
      "y": 15,
      "z": 5,
      "name": "Soil_Ash"
    },
    {
      "x": -11,
      "y": 13,
      "z": 6,
      "name": "Rock_Basalt"
    },
    {
      "x": -11,
      "y": 14,
      "z": 6,
      "name": "Soil_Ash"
    },
    {
      "x": -11,
      "y": 13,
      "z": 7,
      "name": "Rock_Basalt"
    },
    {
      "x": -11,
      "y": 14,
      "z": 7,
      "name": "Rock_Basalt"
    },
    {
      "x": -11,
      "y": 15,
      "z": 7,
      "name": "Soil_Ash"
    },
    {
      "x": -10,
      "y": 8,
      "z": -5,
      "name": "Ore_Iron_Basalt_Cracked"
    },
    {
      "x": -10,
      "y": 9,
      "z": -5,
      "name": "Soil_Ash"
    },
    {
      "x": -10,
      "y": 10,
      "z": -5,
      "name": "Deco_SpiderWeb_Flat"
    },
    {
      "x": -10,
      "y": 8,
      "z": -4,
      "name": "Ore_Iron_Basalt_Cracked"
    },
    {
      "x": -10,
      "y": 9,
      "z": -4,
      "name": "Rock_Basalt"
    },
    {
      "x": -10,
      "y": 10,
      "z": -4,
      "name": "Soil_Ash"
    },
    {
      "x": -10,
      "y": 37,
      "z": -4,
      "name": "Wood_Ash_Branch_Corner",
      "rotation": 3
    },
    {
      "x": -10,
      "y": 8,
      "z": -3,
      "name": "Ore_Iron_Basalt_Cracked"
    },
    {
      "x": -10,
      "y": 9,
      "z": -3,
      "name": "Ore_Iron_Basalt_Cracked"
    },
    {
      "x": -10,
      "y": 10,
      "z": -3,
      "name": "Ore_Iron_Basalt_Cracked"
    },
    {
      "x": -10,
      "y": 11,
      "z": -3,
      "name": "Soil_Ash"
    },
    {
      "x": -10,
      "y": 12,
      "z": -1,
      "name": "Deco_SpiderWeb_Flat",
      "rotation": 7
    },
    {
      "x": -10,
      "y": 13,
      "z": -1,
      "name": "Deco_SpiderWeb_Flat",
      "rotation": 7
    },
    {
      "x": -10,
      "y": 9,
      "z": 0,
      "name": "Rock_Basalt"
    },
    {
      "x": -10,
      "y": 10,
      "z": 0,
      "name": "Rock_Basalt"
    },
    {
      "x": -10,
      "y": 11,
      "z": 0,
      "name": "Rock_Basalt"
    },
    {
      "x": -10,
      "y": 12,
      "z": 0,
      "name": "Ore_Iron_Basalt_Cracked"
    },
    {
      "x": -10,
      "y": 13,
      "z": 0,
      "name": "Ore_Iron_Basalt_Cracked"
    },
    {
      "x": -10,
      "y": 14,
      "z": 0,
      "name": "Rock_Basalt"
    },
    {
      "x": -10,
      "y": 15,
      "z": 0,
      "name": "Soil_Sand_Ashen"
    },
    {
      "x": -10,
      "y": 8,
      "z": 1,
      "name": "Ore_Iron_Basalt_Cracked"
    },
    {
      "x": -10,
      "y": 9,
      "z": 1,
      "name": "Ore_Iron_Basalt_Cracked"
    },
    {
      "x": -10,
      "y": 10,
      "z": 1,
      "name": "Ore_Iron_Basalt_Cracked"
    },
    {
      "x": -10,
      "y": 11,
      "z": 1,
      "name": "Rock_Basalt"
    },
    {
      "x": -10,
      "y": 12,
      "z": 1,
      "name": "Rock_Basalt"
    },
    {
      "x": -10,
      "y": 13,
      "z": 1,
      "name": "Rock_Basalt"
    },
    {
      "x": -10,
      "y": 14,
      "z": 1,
      "name": "Ore_Iron_Basalt_Cracked"
    },
    {
      "x": -10,
      "y": 15,
      "z": 1,
      "name": "Rock_Basalt"
    },
    {
      "x": -10,
      "y": 16,
      "z": 1,
      "name": "Soil_Sand_Ashen"
    },
    {
      "x": -10,
      "y": 8,
      "z": 2,
      "name": "Ore_Iron_Basalt_Cracked"
    },
    {
      "x": -10,
      "y": 9,
      "z": 2,
      "name": "Rock_Basalt"
    },
    {
      "x": -10,
      "y": 10,
      "z": 2,
      "name": "Rock_Basalt"
    },
    {
      "x": -10,
      "y": 11,
      "z": 2,
      "name": "Rock_Basalt"
    },
    {
      "x": -10,
      "y": 12,
      "z": 2,
      "name": "Ore_Iron_Basalt_Cracked"
    },
    {
      "x": -10,
      "y": 13,
      "z": 2,
      "name": "Ore_Iron_Basalt_Cracked"
    },
    {
      "x": -10,
      "y": 14,
      "z": 2,
      "name": "Ore_Iron_Basalt_Cracked"
    },
    {
      "x": -10,
      "y": 15,
      "z": 2,
      "name": "Soil_Basalt_Gravel"
    },
    {
      "x": -10,
      "y": 16,
      "z": 2,
      "name": "Soil_Sand_Ashen"
    },
    {
      "x": -10,
      "y": 7,
      "z": 3,
      "name": "Deco_SpiderWeb",
      "rotation": 9
    },
    {
      "x": -10,
      "y": 8,
      "z": 3,
      "name": "Rock_Basalt"
    },
    {
      "x": -10,
      "y": 9,
      "z": 3,
      "name": "Ore_Iron_Basalt_Cracked"
    },
    {
      "x": -10,
      "y": 10,
      "z": 3,
      "name": "Rock_Basalt"
    },
    {
      "x": -10,
      "y": 11,
      "z": 3,
      "name": "Rock_Basalt"
    },
    {
      "x": -10,
      "y": 12,
      "z": 3,
      "name": "Ore_Iron_Basalt_Cracked"
    },
    {
      "x": -10,
      "y": 13,
      "z": 3,
      "name": "Ore_Iron_Basalt_Cracked"
    },
    {
      "x": -10,
      "y": 14,
      "z": 3,
      "name": "Ore_Iron_Basalt_Cracked"
    },
    {
      "x": -10,
      "y": 15,
      "z": 3,
      "name": "Soil_Sand_Ashen"
    },
    {
      "x": -10,
      "y": 16,
      "z": 3,
      "name": "Soil_Sand_Ashen"
    },
    {
      "x": -10,
      "y": 9,
      "z": 4,
      "name": "Rock_Basalt"
    },
    {
      "x": -10,
      "y": 10,
      "z": 4,
      "name": "Rock_Basalt"
    },
    {
      "x": -10,
      "y": 11,
      "z": 4,
      "name": "Ore_Iron_Basalt_Cracked"
    },
    {
      "x": -10,
      "y": 12,
      "z": 4,
      "name": "Ore_Iron_Basalt_Cracked"
    },
    {
      "x": -10,
      "y": 13,
      "z": 4,
      "name": "Ore_Iron_Basalt_Cracked"
    },
    {
      "x": -10,
      "y": 14,
      "z": 4,
      "name": "Ore_Iron_Basalt_Cracked"
    },
    {
      "x": -10,
      "y": 15,
      "z": 4,
      "name": "Rock_Basalt"
    },
    {
      "x": -10,
      "y": 16,
      "z": 4,
      "name": "Soil_Sand_Ashen"
    },
    {
      "x": -10,
      "y": 10,
      "z": 5,
      "name": "Deco_SpiderWeb",
      "rotation": 9
    },
    {
      "x": -10,
      "y": 11,
      "z": 5,
      "name": "Rock_Basalt"
    },
    {
      "x": -10,
      "y": 12,
      "z": 5,
      "name": "Rock_Basalt"
    },
    {
      "x": -10,
      "y": 13,
      "z": 5,
      "name": "Ore_Iron_Basalt_Cracked"
    },
    {
      "x": -10,
      "y": 14,
      "z": 5,
      "name": "Ore_Iron_Basalt_Cracked"
    },
    {
      "x": -10,
      "y": 15,
      "z": 5,
      "name": "Rock_Basalt"
    },
    {
      "x": -10,
      "y": 16,
      "z": 5,
      "name": "Soil_Ash"
    },
    {
      "x": -10,
      "y": 11,
      "z": 6,
      "name": "Ore_Iron_Basalt_Cracked"
    },
    {
      "x": -10,
      "y": 12,
      "z": 6,
      "name": "Ore_Iron_Basalt_Cracked"
    },
    {
      "x": -10,
      "y": 13,
      "z": 6,
      "name": "Rock_Basalt"
    },
    {
      "x": -10,
      "y": 14,
      "z": 6,
      "name": "Ore_Iron_Basalt_Cracked"
    },
    {
      "x": -10,
      "y": 15,
      "z": 6,
      "name": "Soil_Basalt_Gravel"
    },
    {
      "x": -10,
      "y": 16,
      "z": 6,
      "name": "Soil_Ash"
    },
    {
      "x": -10,
      "y": 11,
      "z": 7,
      "name": "Rock_Basalt"
    },
    {
      "x": -10,
      "y": 12,
      "z": 7,
      "name": "Rock_Basalt"
    },
    {
      "x": -10,
      "y": 13,
      "z": 7,
      "name": "Rock_Basalt"
    },
    {
      "x": -10,
      "y": 14,
      "z": 7,
      "name": "Ore_Iron_Basalt_Cracked"
    },
    {
      "x": -10,
      "y": 15,
      "z": 7,
      "name": "Ore_Iron_Basalt_Cracked"
    },
    {
      "x": -10,
      "y": 16,
      "z": 7,
      "name": "Soil_Ash"
    },
    {
      "x": -10,
      "y": 12,
      "z": 8,
      "name": "Rock_Basalt"
    },
    {
      "x": -10,
      "y": 13,
      "z": 8,
      "name": "Rock_Basalt"
    },
    {
      "x": -10,
      "y": 14,
      "z": 8,
      "name": "Rock_Basalt"
    },
    {
      "x": -10,
      "y": 15,
      "z": 8,
      "name": "Soil_Ash"
    },
    {
      "x": -9,
      "y": 7,
      "z": -6,
      "name": "Ore_Iron_Basalt_Cracked"
    },
    {
      "x": -9,
      "y": 8,
      "z": -6,
      "name": "Ore_Iron_Basalt_Cracked"
    },
    {
      "x": -9,
      "y": 9,
      "z": -6,
      "name": "Soil_Ash"
    },
    {
      "x": -9,
      "y": 10,
      "z": -6,
      "name": "Deco_SpiderWeb_Flat"
    },
    {
      "x": -9,
      "y": 6,
      "z": -5,
      "name": "Ore_Iron_Basalt_Cracked"
    },
    {
      "x": -9,
      "y": 7,
      "z": -5,
      "name": "Rock_Basalt"
    },
    {
      "x": -9,
      "y": 8,
      "z": -5,
      "name": "Ore_Iron_Basalt_Cracked"
    },
    {
      "x": -9,
      "y": 9,
      "z": -5,
      "name": "Ore_Iron_Basalt_Cracked"
    },
    {
      "x": -9,
      "y": 10,
      "z": -5,
      "name": "Rock_Basalt"
    },
    {
      "x": -9,
      "y": 11,
      "z": -5,
      "name": "Soil_Ash"
    },
    {
      "x": -9,
      "y": 6,
      "z": -4,
      "name": "Rock_Basalt"
    },
    {
      "x": -9,
      "y": 7,
      "z": -4,
      "name": "Ore_Iron_Basalt_Cracked"
    },
    {
      "x": -9,
      "y": 8,
      "z": -4,
      "name": "Ore_Iron_Basalt_Cracked"
    },
    {
      "x": -9,
      "y": 9,
      "z": -4,
      "name": "Ore_Iron_Basalt_Cracked"
    },
    {
      "x": -9,
      "y": 10,
      "z": -4,
      "name": "Soil_Basalt_Gravel"
    },
    {
      "x": -9,
      "y": 11,
      "z": -4,
      "name": "Soil_Ash"
    },
    {
      "x": -9,
      "y": 37,
      "z": -4,
      "name": "Wood_Ash_Branch_Long",
      "rotation": 5
    },
    {
      "x": -9,
      "y": 6,
      "z": -3,
      "name": "Ore_Iron_Basalt_Cracked"
    },
    {
      "x": -9,
      "y": 7,
      "z": -3,
      "name": "Ore_Iron_Basalt_Cracked"
    },
    {
      "x": -9,
      "y": 8,
      "z": -3,
      "name": "Ore_Iron_Basalt_Cracked"
    },
    {
      "x": -9,
      "y": 9,
      "z": -3,
      "name": "Rock_Basalt"
    },
    {
      "x": -9,
      "y": 10,
      "z": -3,
      "name": "Ore_Iron_Basalt_Cracked"
    },
    {
      "x": -9,
      "y": 11,
      "z": -3,
      "name": "Soil_Basalt_Gravel"
    },
    {
      "x": -9,
      "y": 12,
      "z": -3,
      "name": "Soil_Ash"
    },
    {
      "x": -9,
      "y": 7,
      "z": -2,
      "name": "Rock_Basalt"
    },
    {
      "x": -9,
      "y": 8,
      "z": -2,
      "name": "Rock_Basalt"
    },
    {
      "x": -9,
      "y": 9,
      "z": -2,
      "name": "Rock_Basalt"
    },
    {
      "x": -9,
      "y": 10,
      "z": -2,
      "name": "Ore_Iron_Basalt"
    },
    {
      "x": -9,
      "y": 11,
      "z": -2,
      "name": "Rock_Basalt"
    },
    {
      "x": -9,
      "y": 12,
      "z": -2,
      "name": "Soil_Ash"
    },
    {
      "x": -9,
      "y": 13,
      "z": -2,
      "name": "Deco_SpiderWeb_Flat",
      "rotation": 6
    },
    {
      "x": -9,
      "y": 8,
      "z": -1,
      "name": "Rock_Basalt"
    },
    {
      "x": -9,
      "y": 9,
      "z": -1,
      "name": "Rock_Basalt"
    },
    {
      "x": -9,
      "y": 10,
      "z": -1,
      "name": "Ore_Iron_Basalt_Cracked"
    },
    {
      "x": -9,
      "y": 11,
      "z": -1,
      "name": "Rock_Basalt"
    },
    {
      "x": -9,
      "y": 12,
      "z": -1,
      "name": "Ore_Iron_Basalt_Cracked"
    },
    {
      "x": -9,
      "y": 13,
      "z": -1,
      "name": "Soil_Basalt_Gravel"
    },
    {
      "x": -9,
      "y": 14,
      "z": -1,
      "name": "Soil_Ash"
    },
    {
      "x": -9,
      "y": 8,
      "z": 0,
      "name": "Ore_Iron_Basalt_Cracked"
    },
    {
      "x": -9,
      "y": 9,
      "z": 0,
      "name": "Rock_Basalt"
    },
    {
      "x": -9,
      "y": 10,
      "z": 0,
      "name": "Ore_Iron_Basalt_Cracked"
    },
    {
      "x": -9,
      "y": 11,
      "z": 0,
      "name": "Ore_Iron_Basalt_Cracked"
    },
    {
      "x": -9,
      "y": 12,
      "z": 0,
      "name": "Ore_Iron_Basalt_Cracked"
    },
    {
      "x": -9,
      "y": 13,
      "z": 0,
      "name": "Rock_Basalt"
    },
    {
      "x": -9,
      "y": 14,
      "z": 0,
      "name": "Ore_Iron_Basalt_Cracked"
    },
    {
      "x": -9,
      "y": 15,
      "z": 0,
      "name": "Rock_Basalt"
    },
    {
      "x": -9,
      "y": 16,
      "z": 0,
      "name": "Soil_Sand_Ashen"
    },
    {
      "x": -9,
      "y": 8,
      "z": 1,
      "name": "Rock_Basalt"
    },
    {
      "x": -9,
      "y": 9,
      "z": 1,
      "name": "Rock_Basalt"
    },
    {
      "x": -9,
      "y": 10,
      "z": 1,
      "name": "Rock_Basalt"
    },
    {
      "x": -9,
      "y": 11,
      "z": 1,
      "name": "Rock_Basalt"
    },
    {
      "x": -9,
      "y": 12,
      "z": 1,
      "name": "Ore_Iron_Basalt_Cracked"
    },
    {
      "x": -9,
      "y": 13,
      "z": 1,
      "name": "Rock_Basalt"
    },
    {
      "x": -9,
      "y": 14,
      "z": 1,
      "name": "Ore_Iron_Basalt_Cracked"
    },
    {
      "x": -9,
      "y": 15,
      "z": 1,
      "name": "Rock_Basalt"
    },
    {
      "x": -9,
      "y": 16,
      "z": 1,
      "name": "Soil_Sand_Ashen"
    },
    {
      "x": -9,
      "y": 6,
      "z": 2,
      "name": "Deco_SpiderWeb",
      "rotation": 9
    },
    {
      "x": -9,
      "y": 7,
      "z": 2,
      "name": "Ore_Iron_Basalt_Cracked"
    },
    {
      "x": -9,
      "y": 8,
      "z": 2,
      "name": "Rock_Basalt"
    },
    {
      "x": -9,
      "y": 9,
      "z": 2,
      "name": "Ore_Iron_Basalt_Cracked"
    },
    {
      "x": -9,
      "y": 10,
      "z": 2,
      "name": "Rock_Basalt"
    },
    {
      "x": -9,
      "y": 11,
      "z": 2,
      "name": "Rock_Basalt"
    },
    {
      "x": -9,
      "y": 12,
      "z": 2,
      "name": "Rock_Basalt"
    },
    {
      "x": -9,
      "y": 13,
      "z": 2,
      "name": "Ore_Iron_Basalt"
    },
    {
      "x": -9,
      "y": 14,
      "z": 2,
      "name": "Rock_Basalt"
    },
    {
      "x": -9,
      "y": 15,
      "z": 2,
      "name": "Soil_Sand_Ashen"
    },
    {
      "x": -9,
      "y": 16,
      "z": 2,
      "name": "Soil_Sand_Ashen"
    },
    {
      "x": -9,
      "y": 8,
      "z": 3,
      "name": "Rock_Basalt"
    },
    {
      "x": -9,
      "y": 9,
      "z": 3,
      "name": "Rock_Basalt"
    },
    {
      "x": -9,
      "y": 10,
      "z": 3,
      "name": "Ore_Iron_Basalt_Cracked"
    },
    {
      "x": -9,
      "y": 11,
      "z": 3,
      "name": "Rock_Basalt"
    },
    {
      "x": -9,
      "y": 12,
      "z": 3,
      "name": "Rock_Basalt"
    },
    {
      "x": -9,
      "y": 13,
      "z": 3,
      "name": "Ore_Gold_Basalt"
    },
    {
      "x": -9,
      "y": 14,
      "z": 3,
      "name": "Ore_Iron_Basalt_Cracked"
    },
    {
      "x": -9,
      "y": 15,
      "z": 3,
      "name": "Soil_Basalt_Gravel"
    },
    {
      "x": -9,
      "y": 16,
      "z": 3,
      "name": "Soil_Sand_Ashen"
    },
    {
      "x": -9,
      "y": 8,
      "z": 4,
      "name": "Rock_Basalt"
    },
    {
      "x": -9,
      "y": 9,
      "z": 4,
      "name": "Rock_Basalt"
    },
    {
      "x": -9,
      "y": 10,
      "z": 4,
      "name": "Rock_Basalt"
    },
    {
      "x": -9,
      "y": 11,
      "z": 4,
      "name": "Rock_Basalt"
    },
    {
      "x": -9,
      "y": 12,
      "z": 4,
      "name": "Rock_Basalt"
    },
    {
      "x": -9,
      "y": 13,
      "z": 4,
      "name": "Ore_Iron_Basalt_Cracked"
    },
    {
      "x": -9,
      "y": 14,
      "z": 4,
      "name": "Rock_Basalt"
    },
    {
      "x": -9,
      "y": 15,
      "z": 4,
      "name": "Ore_Iron_Basalt_Cracked"
    },
    {
      "x": -9,
      "y": 16,
      "z": 4,
      "name": "Ore_Iron_Basalt_Cracked"
    },
    {
      "x": -9,
      "y": 17,
      "z": 4,
      "name": "Soil_Ash"
    },
    {
      "x": -9,
      "y": 9,
      "z": 5,
      "name": "Rock_Basalt"
    },
    {
      "x": -9,
      "y": 10,
      "z": 5,
      "name": "Rock_Basalt"
    },
    {
      "x": -9,
      "y": 11,
      "z": 5,
      "name": "Ore_Iron_Basalt_Cracked"
    },
    {
      "x": -9,
      "y": 12,
      "z": 5,
      "name": "Rock_Basalt"
    },
    {
      "x": -9,
      "y": 13,
      "z": 5,
      "name": "Ore_Iron_Basalt"
    },
    {
      "x": -9,
      "y": 14,
      "z": 5,
      "name": "Ore_Iron_Basalt"
    },
    {
      "x": -9,
      "y": 15,
      "z": 5,
      "name": "Soil_Basalt_Gravel"
    },
    {
      "x": -9,
      "y": 16,
      "z": 5,
      "name": "Soil_Ash"
    },
    {
      "x": -9,
      "y": 9,
      "z": 6,
      "name": "Ore_Iron_Basalt_Cracked"
    },
    {
      "x": -9,
      "y": 10,
      "z": 6,
      "name": "Rock_Basalt"
    },
    {
      "x": -9,
      "y": 11,
      "z": 6,
      "name": "Rock_Basalt"
    },
    {
      "x": -9,
      "y": 12,
      "z": 6,
      "name": "Rock_Basalt"
    },
    {
      "x": -9,
      "y": 13,
      "z": 6,
      "name": "Rock_Basalt"
    },
    {
      "x": -9,
      "y": 14,
      "z": 6,
      "name": "Rock_Basalt"
    },
    {
      "x": -9,
      "y": 15,
      "z": 6,
      "name": "Ore_Iron_Basalt_Cracked"
    },
    {
      "x": -9,
      "y": 16,
      "z": 6,
      "name": "Soil_Basalt_Gravel"
    },
    {
      "x": -9,
      "y": 17,
      "z": 6,
      "name": "Soil_Ash"
    },
    {
      "x": -9,
      "y": 11,
      "z": 7,
      "name": "Rock_Basalt"
    },
    {
      "x": -9,
      "y": 12,
      "z": 7,
      "name": "Rock_Basalt"
    },
    {
      "x": -9,
      "y": 13,
      "z": 7,
      "name": "Ore_Iron_Basalt_Cracked"
    },
    {
      "x": -9,
      "y": 14,
      "z": 7,
      "name": "Rock_Basalt"
    },
    {
      "x": -9,
      "y": 15,
      "z": 7,
      "name": "Rock_Basalt"
    },
    {
      "x": -9,
      "y": 16,
      "z": 7,
      "name": "Soil_Ash"
    },
    {
      "x": -9,
      "y": 11,
      "z": 8,
      "name": "Rock_Basalt"
    },
    {
      "x": -9,
      "y": 12,
      "z": 8,
      "name": "Rock_Basalt"
    },
    {
      "x": -9,
      "y": 13,
      "z": 8,
      "name": "Rock_Basalt"
    },
    {
      "x": -9,
      "y": 14,
      "z": 8,
      "name": "Ore_Iron_Basalt_Cracked"
    },
    {
      "x": -9,
      "y": 15,
      "z": 8,
      "name": "Ore_Iron_Basalt_Cracked"
    },
    {
      "x": -9,
      "y": 16,
      "z": 8,
      "name": "Soil_Ash"
    },
    {
      "x": -9,
      "y": 13,
      "z": 9,
      "name": "Rock_Basalt"
    },
    {
      "x": -9,
      "y": 14,
      "z": 9,
      "name": "Rock_Basalt"
    },
    {
      "x": -9,
      "y": 15,
      "z": 9,
      "name": "Soil_Ash"
    },
    {
      "x": -9,
      "y": 16,
      "z": 9,
      "name": "Plant_Flower_Bushy_Yellow"
    },
    {
      "x": -9,
      "y": 14,
      "z": 10,
      "name": "Deco_SpiderWeb_Flat",
      "rotation": 4
    },
    {
      "x": -8,
      "y": 8,
      "z": -7,
      "name": "Rock_Basalt"
    },
    {
      "x": -8,
      "y": 9,
      "z": -7,
      "name": "Rock_Basalt"
    },
    {
      "x": -8,
      "y": 10,
      "z": -7,
      "name": "Soil_Ash"
    },
    {
      "x": -8,
      "y": 11,
      "z": -7,
      "name": "Deco_SpiderWeb_Flat",
      "rotation": 6
    },
    {
      "x": -8,
      "y": 6,
      "z": -6,
      "name": "Rock_Basalt"
    },
    {
      "x": -8,
      "y": 7,
      "z": -6,
      "name": "Ore_Iron_Basalt_Cracked"
    },
    {
      "x": -8,
      "y": 8,
      "z": -6,
      "name": "Rock_Basalt"
    },
    {
      "x": -8,
      "y": 9,
      "z": -6,
      "name": "Ore_Iron_Basalt_Cracked"
    },
    {
      "x": -8,
      "y": 10,
      "z": -6,
      "name": "Ore_Iron_Basalt_Cracked"
    },
    {
      "x": -8,
      "y": 11,
      "z": -6,
      "name": "Soil_Ash"
    },
    {
      "x": -8,
      "y": 6,
      "z": -5,
      "name": "Ore_Iron_Basalt_Cracked"
    },
    {
      "x": -8,
      "y": 7,
      "z": -5,
      "name": "Rock_Basalt"
    },
    {
      "x": -8,
      "y": 8,
      "z": -5,
      "name": "Ore_Iron_Basalt_Cracked"
    },
    {
      "x": -8,
      "y": 9,
      "z": -5,
      "name": "Rock_Basalt"
    },
    {
      "x": -8,
      "y": 10,
      "z": -5,
      "name": "Ore_Iron_Basalt_Cracked"
    },
    {
      "x": -8,
      "y": 11,
      "z": -5,
      "name": "Soil_Basalt_Gravel"
    },
    {
      "x": -8,
      "y": 12,
      "z": -5,
      "name": "Soil_Ash"
    },
    {
      "x": -8,
      "y": 3,
      "z": -4,
      "name": "Rock_Crystal_Yellow_Medium",
      "rotation": 7
    },
    {
      "x": -8,
      "y": 4,
      "z": -4,
      "name": "Rock_Crystal_Yellow_Medium",
      "rotation": 7
    },
    {
      "x": -8,
      "y": 5,
      "z": -4,
      "name": "Rock_Basalt"
    },
    {
      "x": -8,
      "y": 6,
      "z": -4,
      "name": "Rock_Basalt"
    },
    {
      "x": -8,
      "y": 7,
      "z": -4,
      "name": "Rock_Basalt"
    },
    {
      "x": -8,
      "y": 8,
      "z": -4,
      "name": "Rock_Basalt"
    },
    {
      "x": -8,
      "y": 9,
      "z": -4,
      "name": "Rock_Basalt"
    },
    {
      "x": -8,
      "y": 10,
      "z": -4,
      "name": "Rock_Basalt"
    },
    {
      "x": -8,
      "y": 11,
      "z": -4,
      "name": "Ore_Iron_Basalt_Cracked"
    },
    {
      "x": -8,
      "y": 12,
      "z": -4,
      "name": "Soil_Basalt_Gravel"
    },
    {
      "x": -8,
      "y": 13,
      "z": -4,
      "name": "Soil_Ash"
    },
    {
      "x": -8,
      "y": 36,
      "z": -4,
      "name": "Wood_Ash_Branch_Corner",
      "rotation": 3
    },
    {
      "x": -8,
      "y": 37,
      "z": -4,
      "name": "Wood_Ash_Branch_Corner",
      "rotation": 11
    },
    {
      "x": -8,
      "y": 6,
      "z": -3,
      "name": "Rock_Basalt"
    },
    {
      "x": -8,
      "y": 7,
      "z": -3,
      "name": "Rock_Basalt"
    },
    {
      "x": -8,
      "y": 8,
      "z": -3,
      "name": "Rock_Basalt"
    },
    {
      "x": -8,
      "y": 9,
      "z": -3,
      "name": "Rock_Basalt"
    },
    {
      "x": -8,
      "y": 10,
      "z": -3,
      "name": "Rock_Basalt"
    },
    {
      "x": -8,
      "y": 11,
      "z": -3,
      "name": "Ore_Iron_Basalt"
    },
    {
      "x": -8,
      "y": 12,
      "z": -3,
      "name": "Soil_Basalt_Gravel"
    },
    {
      "x": -8,
      "y": 13,
      "z": -3,
      "name": "Soil_Ash"
    },
    {
      "x": -8,
      "y": 6,
      "z": -2,
      "name": "Rock_Basalt"
    },
    {
      "x": -8,
      "y": 7,
      "z": -2,
      "name": "Rock_Basalt"
    },
    {
      "x": -8,
      "y": 8,
      "z": -2,
      "name": "Ore_Iron_Basalt_Cracked"
    },
    {
      "x": -8,
      "y": 9,
      "z": -2,
      "name": "Ore_Iron_Basalt_Cracked"
    },
    {
      "x": -8,
      "y": 10,
      "z": -2,
      "name": "Ore_Iron_Basalt_Cracked"
    },
    {
      "x": -8,
      "y": 11,
      "z": -2,
      "name": "Ore_Iron_Basalt_Cracked"
    },
    {
      "x": -8,
      "y": 12,
      "z": -2,
      "name": "Rock_Basalt"
    },
    {
      "x": -8,
      "y": 13,
      "z": -2,
      "name": "Soil_Ash"
    },
    {
      "x": -8,
      "y": 6,
      "z": -1,
      "name": "Rock_Basalt"
    },
    {
      "x": -8,
      "y": 7,
      "z": -1,
      "name": "Rock_Basalt"
    },
    {
      "x": -8,
      "y": 8,
      "z": -1,
      "name": "Ore_Iron_Basalt_Cracked"
    },
    {
      "x": -8,
      "y": 9,
      "z": -1,
      "name": "Ore_Iron_Basalt_Cracked"
    },
    {
      "x": -8,
      "y": 10,
      "z": -1,
      "name": "Ore_Iron_Basalt_Cracked"
    },
    {
      "x": -8,
      "y": 11,
      "z": -1,
      "name": "Rock_Basalt"
    },
    {
      "x": -8,
      "y": 12,
      "z": -1,
      "name": "Ore_Iron_Basalt_Cracked"
    },
    {
      "x": -8,
      "y": 13,
      "z": -1,
      "name": "Rock_Basalt"
    },
    {
      "x": -8,
      "y": 14,
      "z": -1,
      "name": "Soil_Ash"
    },
    {
      "x": -8,
      "y": 6,
      "z": 0,
      "name": "Rock_Basalt"
    },
    {
      "x": -8,
      "y": 7,
      "z": 0,
      "name": "Rock_Basalt"
    },
    {
      "x": -8,
      "y": 8,
      "z": 0,
      "name": "Rock_Basalt"
    },
    {
      "x": -8,
      "y": 9,
      "z": 0,
      "name": "Rock_Basalt"
    },
    {
      "x": -8,
      "y": 10,
      "z": 0,
      "name": "Rock_Basalt"
    },
    {
      "x": -8,
      "y": 11,
      "z": 0,
      "name": "Rock_Basalt"
    },
    {
      "x": -8,
      "y": 12,
      "z": 0,
      "name": "Ore_Iron_Basalt_Cracked"
    },
    {
      "x": -8,
      "y": 13,
      "z": 0,
      "name": "Ore_Iron_Basalt_Cracked"
    },
    {
      "x": -8,
      "y": 14,
      "z": 0,
      "name": "Ore_Iron_Basalt_Cracked"
    },
    {
      "x": -8,
      "y": 15,
      "z": 0,
      "name": "Soil_Sand_Ashen"
    },
    {
      "x": -8,
      "y": 6,
      "z": 1,
      "name": "Deco_SpiderWeb",
      "rotation": 9
    },
    {
      "x": -8,
      "y": 7,
      "z": 1,
      "name": "Rock_Basalt"
    },
    {
      "x": -8,
      "y": 8,
      "z": 1,
      "name": "Rock_Basalt"
    },
    {
      "x": -8,
      "y": 9,
      "z": 1,
      "name": "Rock_Basalt"
    },
    {
      "x": -8,
      "y": 10,
      "z": 1,
      "name": "Ore_Iron_Basalt_Cracked"
    },
    {
      "x": -8,
      "y": 11,
      "z": 1,
      "name": "Rock_Basalt"
    },
    {
      "x": -8,
      "y": 12,
      "z": 1,
      "name": "Ore_Iron_Basalt_Cracked"
    },
    {
      "x": -8,
      "y": 13,
      "z": 1,
      "name": "Ore_Iron_Basalt_Cracked"
    },
    {
      "x": -8,
      "y": 14,
      "z": 1,
      "name": "Soil_Basalt_Gravel"
    },
    {
      "x": -8,
      "y": 15,
      "z": 1,
      "name": "Soil_Sand_Ashen"
    },
    {
      "x": -8,
      "y": 16,
      "z": 1,
      "name": "Deco_SpiderWeb_Flat"
    },
    {
      "x": -8,
      "y": 6,
      "z": 2,
      "name": "Deco_SpiderWeb",
      "rotation": 9
    },
    {
      "x": -8,
      "y": 7,
      "z": 2,
      "name": "Rock_Basalt"
    },
    {
      "x": -8,
      "y": 8,
      "z": 2,
      "name": "Rock_Basalt"
    },
    {
      "x": -8,
      "y": 9,
      "z": 2,
      "name": "Ore_Iron_Basalt_Cracked"
    },
    {
      "x": -8,
      "y": 10,
      "z": 2,
      "name": "Rock_Basalt"
    },
    {
      "x": -8,
      "y": 11,
      "z": 2,
      "name": "Ore_Iron_Basalt_Cracked"
    },
    {
      "x": -8,
      "y": 12,
      "z": 2,
      "name": "Rock_Basalt"
    },
    {
      "x": -8,
      "y": 13,
      "z": 2,
      "name": "Rock_Basalt"
    },
    {
      "x": -8,
      "y": 14,
      "z": 2,
      "name": "Ore_Iron_Basalt_Cracked"
    },
    {
      "x": -8,
      "y": 15,
      "z": 2,
      "name": "Soil_Basalt_Gravel"
    },
    {
      "x": -8,
      "y": 16,
      "z": 2,
      "name": "Soil_Sand_Ashen"
    },
    {
      "x": -8,
      "y": 7,
      "z": 3,
      "name": "Rock_Basalt"
    },
    {
      "x": -8,
      "y": 8,
      "z": 3,
      "name": "Ore_Iron_Basalt_Cracked"
    },
    {
      "x": -8,
      "y": 9,
      "z": 3,
      "name": "Rock_Basalt"
    },
    {
      "x": -8,
      "y": 10,
      "z": 3,
      "name": "Rock_Basalt"
    },
    {
      "x": -8,
      "y": 11,
      "z": 3,
      "name": "Rock_Basalt"
    },
    {
      "x": -8,
      "y": 12,
      "z": 3,
      "name": "Rock_Basalt"
    },
    {
      "x": -8,
      "y": 13,
      "z": 3,
      "name": "Ore_Iron_Basalt"
    },
    {
      "x": -8,
      "y": 14,
      "z": 3,
      "name": "Ore_Iron_Basalt_Cracked"
    },
    {
      "x": -8,
      "y": 15,
      "z": 3,
      "name": "Ore_Iron_Basalt_Cracked"
    },
    {
      "x": -8,
      "y": 16,
      "z": 3,
      "name": "Soil_Sand_Ashen"
    },
    {
      "x": -8,
      "y": 17,
      "z": 3,
      "name": "Deco_SpiderWeb_Flat"
    },
    {
      "x": -8,
      "y": 7,
      "z": 4,
      "name": "Ore_Iron_Basalt_Cracked"
    },
    {
      "x": -8,
      "y": 8,
      "z": 4,
      "name": "Ore_Iron_Basalt_Cracked"
    },
    {
      "x": -8,
      "y": 9,
      "z": 4,
      "name": "Ore_Iron_Basalt_Cracked"
    },
    {
      "x": -8,
      "y": 10,
      "z": 4,
      "name": "Rock_Basalt"
    },
    {
      "x": -8,
      "y": 11,
      "z": 4,
      "name": "Rock_Basalt"
    },
    {
      "x": -8,
      "y": 12,
      "z": 4,
      "name": "Ore_Iron_Basalt_Cracked"
    },
    {
      "x": -8,
      "y": 13,
      "z": 4,
      "name": "Rock_Basalt"
    },
    {
      "x": -8,
      "y": 14,
      "z": 4,
      "name": "Ore_Iron_Basalt_Cracked"
    },
    {
      "x": -8,
      "y": 15,
      "z": 4,
      "name": "Soil_Basalt_Gravel"
    },
    {
      "x": -8,
      "y": 16,
      "z": 4,
      "name": "Soil_Sand_Ashen"
    },
    {
      "x": -8,
      "y": 17,
      "z": 4,
      "name": "Deco_SpiderWeb_Flat"
    },
    {
      "x": -8,
      "y": 7,
      "z": 5,
      "name": "Rock_Basalt"
    },
    {
      "x": -8,
      "y": 8,
      "z": 5,
      "name": "Rock_Basalt"
    },
    {
      "x": -8,
      "y": 9,
      "z": 5,
      "name": "Rock_Basalt"
    },
    {
      "x": -8,
      "y": 10,
      "z": 5,
      "name": "Ore_Iron_Basalt_Cracked"
    },
    {
      "x": -8,
      "y": 11,
      "z": 5,
      "name": "Rock_Basalt"
    },
    {
      "x": -8,
      "y": 12,
      "z": 5,
      "name": "Ore_Iron_Basalt_Cracked"
    },
    {
      "x": -8,
      "y": 13,
      "z": 5,
      "name": "Ore_Silver_Basalt"
    },
    {
      "x": -8,
      "y": 14,
      "z": 5,
      "name": "Ore_Silver_Basalt"
    },
    {
      "x": -8,
      "y": 15,
      "z": 5,
      "name": "Ore_Iron_Basalt"
    },
    {
      "x": -8,
      "y": 16,
      "z": 5,
      "name": "Soil_Basalt_Gravel"
    },
    {
      "x": -8,
      "y": 17,
      "z": 5,
      "name": "Soil_Ash"
    },
    {
      "x": -8,
      "y": 7,
      "z": 6,
      "name": "Ore_Iron_Basalt_Cracked"
    },
    {
      "x": -8,
      "y": 8,
      "z": 6,
      "name": "Rock_Basalt"
    },
    {
      "x": -8,
      "y": 9,
      "z": 6,
      "name": "Rock_Basalt"
    },
    {
      "x": -8,
      "y": 10,
      "z": 6,
      "name": "Ore_Iron_Basalt_Cracked"
    },
    {
      "x": -8,
      "y": 11,
      "z": 6,
      "name": "Ore_Iron_Basalt_Cracked"
    },
    {
      "x": -8,
      "y": 12,
      "z": 6,
      "name": "Rock_Basalt"
    },
    {
      "x": -8,
      "y": 13,
      "z": 6,
      "name": "Rock_Basalt"
    },
    {
      "x": -8,
      "y": 14,
      "z": 6,
      "name": "Rock_Basalt"
    },
    {
      "x": -8,
      "y": 15,
      "z": 6,
      "name": "Ore_Iron_Basalt_Cracked"
    },
    {
      "x": -8,
      "y": 16,
      "z": 6,
      "name": "Soil_Basalt_Gravel"
    },
    {
      "x": -8,
      "y": 17,
      "z": 6,
      "name": "Soil_Ash"
    },
    {
      "x": -8,
      "y": 8,
      "z": 7,
      "name": "Rock_Basalt"
    },
    {
      "x": -8,
      "y": 9,
      "z": 7,
      "name": "Rock_Basalt"
    },
    {
      "x": -8,
      "y": 10,
      "z": 7,
      "name": "Rock_Basalt"
    },
    {
      "x": -8,
      "y": 11,
      "z": 7,
      "name": "Ore_Iron_Basalt_Cracked"
    },
    {
      "x": -8,
      "y": 12,
      "z": 7,
      "name": "Ore_Iron_Basalt_Cracked"
    },
    {
      "x": -8,
      "y": 13,
      "z": 7,
      "name": "Rock_Basalt"
    },
    {
      "x": -8,
      "y": 14,
      "z": 7,
      "name": "Ore_Iron_Basalt_Cracked"
    },
    {
      "x": -8,
      "y": 15,
      "z": 7,
      "name": "Soil_Basalt_Gravel"
    },
    {
      "x": -8,
      "y": 16,
      "z": 7,
      "name": "Soil_Ash"
    },
    {
      "x": -8,
      "y": 11,
      "z": 8,
      "name": "Rock_Basalt"
    },
    {
      "x": -8,
      "y": 12,
      "z": 8,
      "name": "Rock_Basalt"
    },
    {
      "x": -8,
      "y": 13,
      "z": 8,
      "name": "Ore_Iron_Basalt_Cracked"
    },
    {
      "x": -8,
      "y": 14,
      "z": 8,
      "name": "Ore_Iron_Basalt_Cracked"
    },
    {
      "x": -8,
      "y": 15,
      "z": 8,
      "name": "Rock_Basalt"
    },
    {
      "x": -8,
      "y": 16,
      "z": 8,
      "name": "Soil_Ash"
    },
    {
      "x": -8,
      "y": 17,
      "z": 8,
      "name": "Plant_Flower_Bushy_Yellow"
    },
    {
      "x": -8,
      "y": 13,
      "z": 9,
      "name": "Rock_Basalt"
    },
    {
      "x": -8,
      "y": 14,
      "z": 9,
      "name": "Ore_Iron_Basalt_Cracked"
    },
    {
      "x": -8,
      "y": 15,
      "z": 9,
      "name": "Rock_Basalt"
    },
    {
      "x": -8,
      "y": 16,
      "z": 9,
      "name": "Soil_Ash"
    },
    {
      "x": -8,
      "y": 17,
      "z": 9,
      "name": "Rock_Crystal_Yellow_Small"
    },
    {
      "x": -8,
      "y": 14,
      "z": 10,
      "name": "Deco_SpiderWeb_Flat",
      "rotation": 4
    },
    {
      "x": -7,
      "y": 8,
      "z": -7,
      "name": "Rock_Basalt"
    },
    {
      "x": -7,
      "y": 9,
      "z": -7,
      "name": "Rock_Basalt"
    },
    {
      "x": -7,
      "y": 10,
      "z": -7,
      "name": "Rock_Basalt"
    },
    {
      "x": -7,
      "y": 11,
      "z": -7,
      "name": "Soil_Ash"
    },
    {
      "x": -7,
      "y": 12,
      "z": -7,
      "name": "Deco_SpiderWeb_Flat",
      "rotation": 6
    },
    {
      "x": -7,
      "y": 5,
      "z": -6,
      "name": "Rock_Crystal_Yellow_Medium",
      "rotation": 6
    },
    {
      "x": -7,
      "y": 6,
      "z": -6,
      "name": "Ore_Iron_Basalt_Cracked"
    },
    {
      "x": -7,
      "y": 7,
      "z": -6,
      "name": "Ore_Iron_Basalt_Cracked"
    },
    {
      "x": -7,
      "y": 8,
      "z": -6,
      "name": "Rock_Basalt"
    },
    {
      "x": -7,
      "y": 9,
      "z": -6,
      "name": "Rock_Basalt"
    },
    {
      "x": -7,
      "y": 10,
      "z": -6,
      "name": "Ore_Iron_Basalt_Cracked"
    },
    {
      "x": -7,
      "y": 11,
      "z": -6,
      "name": "Ore_Iron_Basalt_Cracked"
    },
    {
      "x": -7,
      "y": 12,
      "z": -6,
      "name": "Rock_Basalt"
    },
    {
      "x": -7,
      "y": 13,
      "z": -6,
      "name": "Soil_Ash"
    },
    {
      "x": -7,
      "y": 3,
      "z": -5,
      "name": "Rock_Crystal_Yellow_Medium",
      "rotation": 6
    },
    {
      "x": -7,
      "y": 4,
      "z": -5,
      "name": "Rock_Crystal_Yellow_Medium",
      "rotation": 7
    },
    {
      "x": -7,
      "y": 5,
      "z": -5,
      "name": "Rock_Basalt"
    },
    {
      "x": -7,
      "y": 6,
      "z": -5,
      "name": "Rock_Basalt"
    },
    {
      "x": -7,
      "y": 7,
      "z": -5,
      "name": "Rock_Basalt"
    },
    {
      "x": -7,
      "y": 8,
      "z": -5,
      "name": "Ore_Iron_Basalt_Cracked"
    },
    {
      "x": -7,
      "y": 9,
      "z": -5,
      "name": "Rock_Basalt"
    },
    {
      "x": -7,
      "y": 10,
      "z": -5,
      "name": "Rock_Basalt"
    },
    {
      "x": -7,
      "y": 11,
      "z": -5,
      "name": "Rock_Basalt"
    },
    {
      "x": -7,
      "y": 12,
      "z": -5,
      "name": "Ore_Iron_Basalt_Cracked"
    },
    {
      "x": -7,
      "y": 13,
      "z": -5,
      "name": "Rock_Basalt"
    },
    {
      "x": -7,
      "y": 14,
      "z": -5,
      "name": "Soil_Ash"
    },
    {
      "x": -7,
      "y": 1,
      "z": -4,
      "name": "Rock_Crystal_Yellow_Medium",
      "rotation": 7
    },
    {
      "x": -7,
      "y": 2,
      "z": -4,
      "name": "Rock_Crystal_Yellow_Medium",
      "rotation": 7
    },
    {
      "x": -7,
      "y": 3,
      "z": -4,
      "name": "Rock_Crystal_Yellow_Block"
    },
    {
      "x": -7,
      "y": 4,
      "z": -4,
      "name": "Rock_Crystal_Yellow_Block"
    },
    {
      "x": -7,
      "y": 5,
      "z": -4,
      "name": "Rock_Crystal_Yellow_Block"
    },
    {
      "x": -7,
      "y": 6,
      "z": -4,
      "name": "Rock_Crystal_Yellow_Block"
    },
    {
      "x": -7,
      "y": 7,
      "z": -4,
      "name": "Rock_Crystal_Yellow_Block"
    },
    {
      "x": -7,
      "y": 8,
      "z": -4,
      "name": "Ore_Iron_Basalt_Cracked"
    },
    {
      "x": -7,
      "y": 9,
      "z": -4,
      "name": "Rock_Basalt"
    },
    {
      "x": -7,
      "y": 10,
      "z": -4,
      "name": "Ore_Iron_Basalt_Cracked"
    },
    {
      "x": -7,
      "y": 11,
      "z": -4,
      "name": "Rock_Basalt"
    },
    {
      "x": -7,
      "y": 12,
      "z": -4,
      "name": "Ore_Iron_Basalt"
    },
    {
      "x": -7,
      "y": 13,
      "z": -4,
      "name": "Soil_Basalt_Gravel"
    },
    {
      "x": -7,
      "y": 14,
      "z": -4,
      "name": "Soil_Ash"
    },
    {
      "x": -7,
      "y": 36,
      "z": -4,
      "name": "Wood_Ash_Trunk_Full",
      "rotation": 5
    },
    {
      "x": -7,
      "y": 2,
      "z": -3,
      "name": "Rock_Crystal_Yellow_Medium",
      "rotation": 7
    },
    {
      "x": -7,
      "y": 3,
      "z": -3,
      "name": "Rock_Crystal_Yellow_Medium",
      "rotation": 4
    },
    {
      "x": -7,
      "y": 4,
      "z": -3,
      "name": "Rock_Crystal_Yellow_Medium",
      "rotation": 7
    },
    {
      "x": -7,
      "y": 5,
      "z": -3,
      "name": "Rock_Basalt"
    },
    {
      "x": -7,
      "y": 6,
      "z": -3,
      "name": "Ore_Iron_Basalt_Cracked"
    },
    {
      "x": -7,
      "y": 7,
      "z": -3,
      "name": "Ore_Iron_Basalt_Cracked"
    },
    {
      "x": -7,
      "y": 8,
      "z": -3,
      "name": "Rock_Basalt"
    },
    {
      "x": -7,
      "y": 9,
      "z": -3,
      "name": "Rock_Basalt"
    },
    {
      "x": -7,
      "y": 10,
      "z": -3,
      "name": "Rock_Basalt"
    },
    {
      "x": -7,
      "y": 11,
      "z": -3,
      "name": "Rock_Basalt"
    },
    {
      "x": -7,
      "y": 12,
      "z": -3,
      "name": "Ore_Iron_Basalt_Cracked"
    },
    {
      "x": -7,
      "y": 13,
      "z": -3,
      "name": "Soil_Basalt_Gravel"
    },
    {
      "x": -7,
      "y": 14,
      "z": -3,
      "name": "Soil_Ash"
    },
    {
      "x": -7,
      "y": 6,
      "z": -2,
      "name": "Ore_Iron_Basalt_Cracked"
    },
    {
      "x": -7,
      "y": 7,
      "z": -2,
      "name": "Rock_Basalt"
    },
    {
      "x": -7,
      "y": 8,
      "z": -2,
      "name": "Ore_Iron_Basalt_Cracked"
    },
    {
      "x": -7,
      "y": 9,
      "z": -2,
      "name": "Rock_Basalt"
    },
    {
      "x": -7,
      "y": 10,
      "z": -2,
      "name": "Rock_Basalt"
    },
    {
      "x": -7,
      "y": 11,
      "z": -2,
      "name": "Ore_Iron_Basalt_Cracked"
    },
    {
      "x": -7,
      "y": 12,
      "z": -2,
      "name": "Ore_Iron_Basalt_Cracked"
    },
    {
      "x": -7,
      "y": 13,
      "z": -2,
      "name": "Soil_Basalt_Gravel"
    },
    {
      "x": -7,
      "y": 14,
      "z": -2,
      "name": "Soil_Ash"
    },
    {
      "x": -7,
      "y": 5,
      "z": -1,
      "name": "Ore_Iron_Basalt_Cracked"
    },
    {
      "x": -7,
      "y": 6,
      "z": -1,
      "name": "Rock_Basalt"
    },
    {
      "x": -7,
      "y": 7,
      "z": -1,
      "name": "Ore_Iron_Basalt_Cracked"
    },
    {
      "x": -7,
      "y": 8,
      "z": -1,
      "name": "Rock_Basalt"
    },
    {
      "x": -7,
      "y": 9,
      "z": -1,
      "name": "Rock_Basalt"
    },
    {
      "x": -7,
      "y": 10,
      "z": -1,
      "name": "Ore_Iron_Basalt_Cracked"
    },
    {
      "x": -7,
      "y": 11,
      "z": -1,
      "name": "Rock_Basalt"
    },
    {
      "x": -7,
      "y": 12,
      "z": -1,
      "name": "Rock_Basalt"
    },
    {
      "x": -7,
      "y": 13,
      "z": -1,
      "name": "Rock_Basalt"
    },
    {
      "x": -7,
      "y": 14,
      "z": -1,
      "name": "Soil_Sand_Ashen"
    },
    {
      "x": -7,
      "y": 6,
      "z": 0,
      "name": "Ore_Iron_Basalt_Cracked"
    },
    {
      "x": -7,
      "y": 7,
      "z": 0,
      "name": "Ore_Iron_Basalt_Cracked"
    },
    {
      "x": -7,
      "y": 8,
      "z": 0,
      "name": "Rock_Basalt"
    },
    {
      "x": -7,
      "y": 9,
      "z": 0,
      "name": "Rock_Basalt"
    },
    {
      "x": -7,
      "y": 10,
      "z": 0,
      "name": "Rock_Basalt"
    },
    {
      "x": -7,
      "y": 11,
      "z": 0,
      "name": "Rock_Basalt"
    },
    {
      "x": -7,
      "y": 12,
      "z": 0,
      "name": "Rock_Basalt"
    },
    {
      "x": -7,
      "y": 13,
      "z": 0,
      "name": "Ore_Iron_Basalt_Cracked"
    },
    {
      "x": -7,
      "y": 14,
      "z": 0,
      "name": "Soil_Basalt_Gravel"
    },
    {
      "x": -7,
      "y": 15,
      "z": 0,
      "name": "Soil_Sand_Ashen"
    },
    {
      "x": -7,
      "y": 6,
      "z": 1,
      "name": "Rock_Basalt"
    },
    {
      "x": -7,
      "y": 7,
      "z": 1,
      "name": "Ore_Iron_Basalt_Cracked"
    },
    {
      "x": -7,
      "y": 8,
      "z": 1,
      "name": "Rock_Basalt"
    },
    {
      "x": -7,
      "y": 9,
      "z": 1,
      "name": "Rock_Basalt"
    },
    {
      "x": -7,
      "y": 10,
      "z": 1,
      "name": "Ore_Iron_Basalt_Cracked"
    },
    {
      "x": -7,
      "y": 11,
      "z": 1,
      "name": "Rock_Basalt"
    },
    {
      "x": -7,
      "y": 12,
      "z": 1,
      "name": "Ore_Iron_Basalt_Cracked"
    },
    {
      "x": -7,
      "y": 13,
      "z": 1,
      "name": "Ore_Iron_Basalt_Cracked"
    },
    {
      "x": -7,
      "y": 14,
      "z": 1,
      "name": "Ore_Iron_Basalt_Cracked"
    },
    {
      "x": -7,
      "y": 15,
      "z": 1,
      "name": "Soil_Sand_Ashen"
    },
    {
      "x": -7,
      "y": 16,
      "z": 1,
      "name": "Deco_SpiderWeb_Flat"
    },
    {
      "x": -7,
      "y": 6,
      "z": 2,
      "name": "Rock_Basalt"
    },
    {
      "x": -7,
      "y": 7,
      "z": 2,
      "name": "Rock_Basalt"
    },
    {
      "x": -7,
      "y": 8,
      "z": 2,
      "name": "Rock_Basalt"
    },
    {
      "x": -7,
      "y": 9,
      "z": 2,
      "name": "Rock_Basalt"
    },
    {
      "x": -7,
      "y": 10,
      "z": 2,
      "name": "Ore_Iron_Basalt_Cracked"
    },
    {
      "x": -7,
      "y": 11,
      "z": 2,
      "name": "Rock_Basalt"
    },
    {
      "x": -7,
      "y": 12,
      "z": 2,
      "name": "Rock_Basalt"
    },
    {
      "x": -7,
      "y": 13,
      "z": 2,
      "name": "Ore_Iron_Basalt_Cracked"
    },
    {
      "x": -7,
      "y": 14,
      "z": 2,
      "name": "Soil_Basalt_Gravel"
    },
    {
      "x": -7,
      "y": 15,
      "z": 2,
      "name": "Soil_Sand_Ashen"
    },
    {
      "x": -7,
      "y": 6,
      "z": 3,
      "name": "Ore_Iron_Basalt_Cracked"
    },
    {
      "x": -7,
      "y": 7,
      "z": 3,
      "name": "Ore_Iron_Basalt_Cracked"
    },
    {
      "x": -7,
      "y": 8,
      "z": 3,
      "name": "Rock_Basalt"
    },
    {
      "x": -7,
      "y": 9,
      "z": 3,
      "name": "Rock_Basalt"
    },
    {
      "x": -7,
      "y": 10,
      "z": 3,
      "name": "Ore_Iron_Basalt_Cracked"
    },
    {
      "x": -7,
      "y": 11,
      "z": 3,
      "name": "Rock_Basalt"
    },
    {
      "x": -7,
      "y": 12,
      "z": 3,
      "name": "Rock_Basalt"
    },
    {
      "x": -7,
      "y": 13,
      "z": 3,
      "name": "Ore_Silver_Basalt"
    },
    {
      "x": -7,
      "y": 14,
      "z": 3,
      "name": "Ore_Iron_Basalt_Cracked"
    },
    {
      "x": -7,
      "y": 15,
      "z": 3,
      "name": "Soil_Basalt_Gravel"
    },
    {
      "x": -7,
      "y": 16,
      "z": 3,
      "name": "Soil_Sand_Ashen"
    },
    {
      "x": -7,
      "y": 7,
      "z": 4,
      "name": "Rock_Basalt"
    },
    {
      "x": -7,
      "y": 8,
      "z": 4,
      "name": "Ore_Iron_Basalt_Cracked"
    },
    {
      "x": -7,
      "y": 9,
      "z": 4,
      "name": "Rock_Basalt"
    },
    {
      "x": -7,
      "y": 10,
      "z": 4,
      "name": "Ore_Iron_Basalt_Cracked"
    },
    {
      "x": -7,
      "y": 11,
      "z": 4,
      "name": "Rock_Basalt"
    },
    {
      "x": -7,
      "y": 12,
      "z": 4,
      "name": "Rock_Basalt"
    },
    {
      "x": -7,
      "y": 13,
      "z": 4,
      "name": "Rock_Basalt"
    },
    {
      "x": -7,
      "y": 14,
      "z": 4,
      "name": "Ore_Iron_Basalt"
    },
    {
      "x": -7,
      "y": 15,
      "z": 4,
      "name": "Soil_Basalt_Gravel"
    },
    {
      "x": -7,
      "y": 16,
      "z": 4,
      "name": "Soil_Sand_Ashen"
    },
    {
      "x": -7,
      "y": 6,
      "z": 5,
      "name": "Rock_Basalt"
    },
    {
      "x": -7,
      "y": 7,
      "z": 5,
      "name": "Rock_Basalt"
    },
    {
      "x": -7,
      "y": 8,
      "z": 5,
      "name": "Ore_Iron_Basalt_Cracked"
    },
    {
      "x": -7,
      "y": 9,
      "z": 5,
      "name": "Rock_Basalt"
    },
    {
      "x": -7,
      "y": 10,
      "z": 5,
      "name": "Rock_Basalt"
    },
    {
      "x": -7,
      "y": 11,
      "z": 5,
      "name": "Ore_Iron_Basalt_Cracked"
    },
    {
      "x": -7,
      "y": 12,
      "z": 5,
      "name": "Rock_Basalt"
    },
    {
      "x": -7,
      "y": 13,
      "z": 5,
      "name": "Ore_Silver_Basalt"
    },
    {
      "x": -7,
      "y": 14,
      "z": 5,
      "name": "Ore_Iron_Basalt_Cracked"
    },
    {
      "x": -7,
      "y": 15,
      "z": 5,
      "name": "Rock_Basalt"
    },
    {
      "x": -7,
      "y": 16,
      "z": 5,
      "name": "Soil_Ash"
    },
    {
      "x": -7,
      "y": 17,
      "z": 5,
      "name": "Deco_Spider_Cocoon"
    },
    {
      "x": -7,
      "y": 18,
      "z": 5,
      "name": "Deco_Spider_Cocoon",
      "filler": 1024
    },
    {
      "x": -7,
      "y": 7,
      "z": 6,
      "name": "Ore_Iron_Basalt_Cracked"
    },
    {
      "x": -7,
      "y": 8,
      "z": 6,
      "name": "Rock_Basalt"
    },
    {
      "x": -7,
      "y": 9,
      "z": 6,
      "name": "Rock_Basalt"
    },
    {
      "x": -7,
      "y": 10,
      "z": 6,
      "name": "Ore_Iron_Basalt_Cracked"
    },
    {
      "x": -7,
      "y": 11,
      "z": 6,
      "name": "Rock_Basalt"
    },
    {
      "x": -7,
      "y": 12,
      "z": 6,
      "name": "Rock_Basalt"
    },
    {
      "x": -7,
      "y": 13,
      "z": 6,
      "name": "Rock_Basalt"
    },
    {
      "x": -7,
      "y": 14,
      "z": 6,
      "name": "Rock_Basalt"
    },
    {
      "x": -7,
      "y": 15,
      "z": 6,
      "name": "Ore_Iron_Basalt_Cracked"
    },
    {
      "x": -7,
      "y": 16,
      "z": 6,
      "name": "Soil_Basalt_Gravel"
    },
    {
      "x": -7,
      "y": 17,
      "z": 6,
      "name": "Soil_Ash"
    },
    {
      "x": -7,
      "y": 7,
      "z": 7,
      "name": "Rock_Basalt"
    },
    {
      "x": -7,
      "y": 8,
      "z": 7,
      "name": "Rock_Basalt"
    },
    {
      "x": -7,
      "y": 9,
      "z": 7,
      "name": "Rock_Basalt"
    },
    {
      "x": -7,
      "y": 10,
      "z": 7,
      "name": "Rock_Basalt"
    },
    {
      "x": -7,
      "y": 11,
      "z": 7,
      "name": "Rock_Basalt"
    },
    {
      "x": -7,
      "y": 12,
      "z": 7,
      "name": "Ore_Iron_Basalt_Cracked"
    },
    {
      "x": -7,
      "y": 13,
      "z": 7,
      "name": "Rock_Basalt"
    },
    {
      "x": -7,
      "y": 14,
      "z": 7,
      "name": "Ore_Iron_Basalt_Cracked"
    },
    {
      "x": -7,
      "y": 15,
      "z": 7,
      "name": "Ore_Iron_Basalt_Cracked"
    },
    {
      "x": -7,
      "y": 16,
      "z": 7,
      "name": "Soil_Ash"
    },
    {
      "x": -7,
      "y": 9,
      "z": 8,
      "name": "Rock_Basalt"
    },
    {
      "x": -7,
      "y": 10,
      "z": 8,
      "name": "Ore_Iron_Basalt_Cracked"
    },
    {
      "x": -7,
      "y": 11,
      "z": 8,
      "name": "Rock_Basalt"
    },
    {
      "x": -7,
      "y": 12,
      "z": 8,
      "name": "Ore_Iron_Basalt_Cracked"
    },
    {
      "x": -7,
      "y": 13,
      "z": 8,
      "name": "Rock_Basalt"
    },
    {
      "x": -7,
      "y": 14,
      "z": 8,
      "name": "Ore_Iron_Basalt_Cracked"
    },
    {
      "x": -7,
      "y": 15,
      "z": 8,
      "name": "Ore_Iron_Basalt_Cracked"
    },
    {
      "x": -7,
      "y": 16,
      "z": 8,
      "name": "Soil_Ash"
    },
    {
      "x": -7,
      "y": 13,
      "z": 9,
      "name": "Rock_Basalt"
    },
    {
      "x": -7,
      "y": 14,
      "z": 9,
      "name": "Ore_Iron_Basalt_Cracked"
    },
    {
      "x": -7,
      "y": 15,
      "z": 9,
      "name": "Ore_Iron_Basalt_Cracked"
    },
    {
      "x": -7,
      "y": 16,
      "z": 9,
      "name": "Soil_Ash"
    },
    {
      "x": -7,
      "y": 17,
      "z": 9,
      "name": "Plant_Flower_Bushy_Yellow"
    },
    {
      "x": -6,
      "y": 40,
      "z": -12,
      "name": "Wood_Ash_Branch_Long",
      "rotation": 5
    },
    {
      "x": -6,
      "y": 8,
      "z": -7,
      "name": "Rock_Basalt"
    },
    {
      "x": -6,
      "y": 9,
      "z": -7,
      "name": "Ore_Iron_Basalt_Cracked"
    },
    {
      "x": -6,
      "y": 10,
      "z": -7,
      "name": "Rock_Basalt"
    },
    {
      "x": -6,
      "y": 11,
      "z": -7,
      "name": "Ore_Iron_Basalt_Cracked"
    },
    {
      "x": -6,
      "y": 12,
      "z": -7,
      "name": "Soil_Ash"
    },
    {
      "x": -6,
      "y": 13,
      "z": -7,
      "name": "Deco_SpiderWeb_Flat",
      "rotation": 7
    },
    {
      "x": -6,
      "y": 14,
      "z": -7,
      "name": "Deco_SpiderWeb_Flat",
      "rotation": 7
    },
    {
      "x": -6,
      "y": 3,
      "z": -6,
      "name": "Rock_Crystal_Yellow_Medium",
      "rotation": 6
    },
    {
      "x": -6,
      "y": 4,
      "z": -6,
      "name": "Rock_Crystal_Yellow_Medium",
      "rotation": 6
    },
    {
      "x": -6,
      "y": 5,
      "z": -6,
      "name": "Rock_Crystal_Yellow_Medium",
      "rotation": 6
    },
    {
      "x": -6,
      "y": 6,
      "z": -6,
      "name": "Rock_Basalt"
    },
    {
      "x": -6,
      "y": 7,
      "z": -6,
      "name": "Rock_Basalt"
    },
    {
      "x": -6,
      "y": 8,
      "z": -6,
      "name": "Rock_Basalt"
    },
    {
      "x": -6,
      "y": 9,
      "z": -6,
      "name": "Rock_Basalt"
    },
    {
      "x": -6,
      "y": 10,
      "z": -6,
      "name": "Ore_Iron_Basalt_Cracked"
    },
    {
      "x": -6,
      "y": 11,
      "z": -6,
      "name": "Rock_Basalt"
    },
    {
      "x": -6,
      "y": 12,
      "z": -6,
      "name": "Ore_Iron_Basalt_Cracked"
    },
    {
      "x": -6,
      "y": 13,
      "z": -6,
      "name": "Ore_Iron_Basalt_Cracked"
    },
    {
      "x": -6,
      "y": 14,
      "z": -6,
      "name": "Rock_Basalt"
    },
    {
      "x": -6,
      "y": 15,
      "z": -6,
      "name": "Soil_Ash"
    },
    {
      "x": -6,
      "y": 2,
      "z": -5,
      "name": "Rock_Crystal_Yellow_Medium",
      "rotation": 6
    },
    {
      "x": -6,
      "y": 3,
      "z": -5,
      "name": "Rock_Crystal_Yellow_Block"
    },
    {
      "x": -6,
      "y": 4,
      "z": -5,
      "name": "Rock_Crystal_Yellow_Block"
    },
    {
      "x": -6,
      "y": 5,
      "z": -5,
      "name": "Rock_Crystal_Yellow_Block"
    },
    {
      "x": -6,
      "y": 6,
      "z": -5,
      "name": "Rock_Crystal_Yellow_Block"
    },
    {
      "x": -6,
      "y": 7,
      "z": -5,
      "name": "Rock_Crystal_Yellow_Block"
    },
    {
      "x": -6,
      "y": 8,
      "z": -5,
      "name": "Rock_Basalt"
    },
    {
      "x": -6,
      "y": 9,
      "z": -5,
      "name": "Rock_Basalt"
    },
    {
      "x": -6,
      "y": 10,
      "z": -5,
      "name": "Ore_Iron_Basalt_Cracked"
    },
    {
      "x": -6,
      "y": 11,
      "z": -5,
      "name": "Rock_Basalt"
    },
    {
      "x": -6,
      "y": 12,
      "z": -5,
      "name": "Rock_Basalt"
    },
    {
      "x": -6,
      "y": 13,
      "z": -5,
      "name": "Ore_Iron_Basalt_Cracked"
    },
    {
      "x": -6,
      "y": 14,
      "z": -5,
      "name": "Rock_Basalt"
    },
    {
      "x": -6,
      "y": 15,
      "z": -5,
      "name": "Soil_Ash"
    },
    {
      "x": -6,
      "y": 29,
      "z": -5,
      "name": "Wood_Ash_Branch_Corner",
      "rotation": 9
    },
    {
      "x": -6,
      "y": 0,
      "z": -4,
      "name": "Rock_Crystal_Yellow_Large",
      "rotation": 8
    },
    {
      "x": -6,
      "y": 1,
      "z": -4,
      "name": "Rock_Crystal_Yellow_Block"
    },
    {
      "x": -6,
      "y": 2,
      "z": -4,
      "name": "Rock_Crystal_Yellow_Block"
    },
    {
      "x": -6,
      "y": 3,
      "z": -4,
      "name": "Rock_Crystal_Yellow_Block"
    },
    {
      "x": -6,
      "y": 4,
      "z": -4,
      "name": "Rock_Crystal_Yellow_Block"
    },
    {
      "x": -6,
      "y": 5,
      "z": -4,
      "name": "Rock_Crystal_Yellow_Block"
    },
    {
      "x": -6,
      "y": 6,
      "z": -4,
      "name": "Rock_Crystal_Yellow_Block"
    },
    {
      "x": -6,
      "y": 7,
      "z": -4,
      "name": "Rock_Crystal_Yellow_Block"
    },
    {
      "x": -6,
      "y": 8,
      "z": -4,
      "name": "Rock_Crystal_Yellow_Block"
    },
    {
      "x": -6,
      "y": 9,
      "z": -4,
      "name": "Rock_Crystal_Yellow_Block"
    },
    {
      "x": -6,
      "y": 10,
      "z": -4,
      "name": "Ore_Iron_Basalt_Cracked"
    },
    {
      "x": -6,
      "y": 11,
      "z": -4,
      "name": "Rock_Basalt"
    },
    {
      "x": -6,
      "y": 12,
      "z": -4,
      "name": "Rock_Basalt"
    },
    {
      "x": -6,
      "y": 13,
      "z": -4,
      "name": "Ore_Iron_Basalt_Cracked"
    },
    {
      "x": -6,
      "y": 14,
      "z": -4,
      "name": "Rock_Basalt"
    },
    {
      "x": -6,
      "y": 15,
      "z": -4,
      "name": "Soil_Ash"
    },
    {
      "x": -6,
      "y": 16,
      "z": -4,
      "name": "Deco_SpiderWeb_Flat"
    },
    {
      "x": -6,
      "y": 36,
      "z": -4,
      "name": "Wood_Ash_Trunk_Full",
      "rotation": 5
    },
    {
      "x": -6,
      "y": 1,
      "z": -3,
      "name": "Rock_Crystal_Yellow_Medium",
      "rotation": 4
    },
    {
      "x": -6,
      "y": 2,
      "z": -3,
      "name": "Rock_Crystal_Yellow_Block"
    },
    {
      "x": -6,
      "y": 3,
      "z": -3,
      "name": "Rock_Crystal_Yellow_Block"
    },
    {
      "x": -6,
      "y": 4,
      "z": -3,
      "name": "Rock_Crystal_Yellow_Block"
    },
    {
      "x": -6,
      "y": 5,
      "z": -3,
      "name": "Rock_Crystal_Yellow_Block"
    },
    {
      "x": -6,
      "y": 6,
      "z": -3,
      "name": "Rock_Crystal_Yellow_Block"
    },
    {
      "x": -6,
      "y": 7,
      "z": -3,
      "name": "Rock_Crystal_Yellow_Block"
    },
    {
      "x": -6,
      "y": 8,
      "z": -3,
      "name": "Ore_Iron_Basalt_Cracked"
    },
    {
      "x": -6,
      "y": 9,
      "z": -3,
      "name": "Rock_Basalt"
    },
    {
      "x": -6,
      "y": 10,
      "z": -3,
      "name": "Rock_Basalt"
    },
    {
      "x": -6,
      "y": 11,
      "z": -3,
      "name": "Rock_Basalt"
    },
    {
      "x": -6,
      "y": 12,
      "z": -3,
      "name": "Ore_Iron_Basalt"
    },
    {
      "x": -6,
      "y": 13,
      "z": -3,
      "name": "Soil_Basalt_Gravel"
    },
    {
      "x": -6,
      "y": 14,
      "z": -3,
      "name": "Soil_Ash"
    },
    {
      "x": -6,
      "y": 36,
      "z": -3,
      "name": "Wood_Ash_Trunk_Full",
      "rotation": 5
    },
    {
      "x": -6,
      "y": 2,
      "z": -2,
      "name": "Rock_Crystal_Yellow_Medium",
      "rotation": 4
    },
    {
      "x": -6,
      "y": 3,
      "z": -2,
      "name": "Rock_Crystal_Yellow_Medium",
      "rotation": 4
    },
    {
      "x": -6,
      "y": 4,
      "z": -2,
      "name": "Rock_Crystal_Yellow_Medium",
      "rotation": 4
    },
    {
      "x": -6,
      "y": 5,
      "z": -2,
      "name": "Rock_Basalt"
    },
    {
      "x": -6,
      "y": 6,
      "z": -2,
      "name": "Rock_Basalt"
    },
    {
      "x": -6,
      "y": 7,
      "z": -2,
      "name": "Ore_Iron_Basalt_Cracked"
    },
    {
      "x": -6,
      "y": 8,
      "z": -2,
      "name": "Rock_Basalt"
    },
    {
      "x": -6,
      "y": 9,
      "z": -2,
      "name": "Rock_Basalt"
    },
    {
      "x": -6,
      "y": 10,
      "z": -2,
      "name": "Ore_Iron_Basalt_Cracked"
    },
    {
      "x": -6,
      "y": 11,
      "z": -2,
      "name": "Rock_Basalt"
    },
    {
      "x": -6,
      "y": 12,
      "z": -2,
      "name": "Ore_Iron_Basalt_Cracked"
    },
    {
      "x": -6,
      "y": 13,
      "z": -2,
      "name": "Ore_Iron_Basalt_Cracked"
    },
    {
      "x": -6,
      "y": 14,
      "z": -2,
      "name": "Soil_Sand_Ashen"
    },
    {
      "x": -6,
      "y": 36,
      "z": -2,
      "name": "Wood_Ash_Branch_Corner"
    },
    {
      "x": -6,
      "y": 37,
      "z": -2,
      "name": "Wood_Ash_Branch_Corner",
      "rotation": 8
    },
    {
      "x": -6,
      "y": 5,
      "z": -1,
      "name": "Rock_Basalt"
    },
    {
      "x": -6,
      "y": 6,
      "z": -1,
      "name": "Rock_Basalt"
    },
    {
      "x": -6,
      "y": 7,
      "z": -1,
      "name": "Rock_Basalt"
    },
    {
      "x": -6,
      "y": 8,
      "z": -1,
      "name": "Rock_Basalt"
    },
    {
      "x": -6,
      "y": 9,
      "z": -1,
      "name": "Rock_Basalt"
    },
    {
      "x": -6,
      "y": 10,
      "z": -1,
      "name": "Rock_Basalt"
    },
    {
      "x": -6,
      "y": 11,
      "z": -1,
      "name": "Rock_Basalt"
    },
    {
      "x": -6,
      "y": 12,
      "z": -1,
      "name": "Rock_Basalt"
    },
    {
      "x": -6,
      "y": 13,
      "z": -1,
      "name": "Ore_Iron_Basalt_Cracked"
    },
    {
      "x": -6,
      "y": 14,
      "z": -1,
      "name": "Ore_Iron_Basalt_Cracked"
    },
    {
      "x": -6,
      "y": 15,
      "z": -1,
      "name": "Soil_Sand_Ashen"
    },
    {
      "x": -6,
      "y": 37,
      "z": -1,
      "name": "Wood_Ash_Branch_Corner"
    },
    {
      "x": -6,
      "y": 5,
      "z": 0,
      "name": "Rock_Basalt"
    },
    {
      "x": -6,
      "y": 6,
      "z": 0,
      "name": "Rock_Basalt"
    },
    {
      "x": -6,
      "y": 7,
      "z": 0,
      "name": "Ore_Iron_Basalt_Cracked"
    },
    {
      "x": -6,
      "y": 8,
      "z": 0,
      "name": "Rock_Basalt"
    },
    {
      "x": -6,
      "y": 9,
      "z": 0,
      "name": "Ore_Iron_Basalt_Cracked"
    },
    {
      "x": -6,
      "y": 10,
      "z": 0,
      "name": "Rock_Basalt"
    },
    {
      "x": -6,
      "y": 11,
      "z": 0,
      "name": "Ore_Iron_Basalt_Cracked"
    },
    {
      "x": -6,
      "y": 12,
      "z": 0,
      "name": "Rock_Basalt"
    },
    {
      "x": -6,
      "y": 13,
      "z": 0,
      "name": "Ore_Iron_Basalt_Cracked"
    },
    {
      "x": -6,
      "y": 14,
      "z": 0,
      "name": "Rock_Basalt"
    },
    {
      "x": -6,
      "y": 15,
      "z": 0,
      "name": "Soil_Sand_Ashen"
    },
    {
      "x": -6,
      "y": 6,
      "z": 1,
      "name": "Ore_Iron_Basalt_Cracked"
    },
    {
      "x": -6,
      "y": 7,
      "z": 1,
      "name": "Ore_Iron_Basalt_Cracked"
    },
    {
      "x": -6,
      "y": 8,
      "z": 1,
      "name": "Ore_Iron_Basalt_Cracked"
    },
    {
      "x": -6,
      "y": 9,
      "z": 1,
      "name": "Rock_Basalt"
    },
    {
      "x": -6,
      "y": 10,
      "z": 1,
      "name": "Ore_Iron_Basalt_Cracked"
    },
    {
      "x": -6,
      "y": 11,
      "z": 1,
      "name": "Ore_Iron_Basalt_Cracked"
    },
    {
      "x": -6,
      "y": 12,
      "z": 1,
      "name": "Rock_Basalt"
    },
    {
      "x": -6,
      "y": 13,
      "z": 1,
      "name": "Ore_Iron_Basalt_Cracked"
    },
    {
      "x": -6,
      "y": 14,
      "z": 1,
      "name": "Ore_Iron_Basalt_Cracked"
    },
    {
      "x": -6,
      "y": 15,
      "z": 1,
      "name": "Soil_Sand_Ashen"
    },
    {
      "x": -6,
      "y": 5,
      "z": 2,
      "name": "Rock_Basalt"
    },
    {
      "x": -6,
      "y": 6,
      "z": 2,
      "name": "Rock_Basalt"
    },
    {
      "x": -6,
      "y": 7,
      "z": 2,
      "name": "Ore_Iron_Basalt_Cracked"
    },
    {
      "x": -6,
      "y": 8,
      "z": 2,
      "name": "Rock_Basalt"
    },
    {
      "x": -6,
      "y": 9,
      "z": 2,
      "name": "Rock_Basalt"
    },
    {
      "x": -6,
      "y": 10,
      "z": 2,
      "name": "Rock_Basalt"
    },
    {
      "x": -6,
      "y": 11,
      "z": 2,
      "name": "Rock_Basalt"
    },
    {
      "x": -6,
      "y": 12,
      "z": 2,
      "name": "Rock_Basalt"
    },
    {
      "x": -6,
      "y": 13,
      "z": 2,
      "name": "Rock_Basalt"
    },
    {
      "x": -6,
      "y": 14,
      "z": 2,
      "name": "Soil_Basalt_Gravel"
    },
    {
      "x": -6,
      "y": 15,
      "z": 2,
      "name": "Soil_Sand_Ashen"
    },
    {
      "x": -6,
      "y": 6,
      "z": 3,
      "name": "Rock_Basalt"
    },
    {
      "x": -6,
      "y": 7,
      "z": 3,
      "name": "Ore_Iron_Basalt_Cracked"
    },
    {
      "x": -6,
      "y": 8,
      "z": 3,
      "name": "Ore_Iron_Basalt_Cracked"
    },
    {
      "x": -6,
      "y": 9,
      "z": 3,
      "name": "Ore_Iron_Basalt_Cracked"
    },
    {
      "x": -6,
      "y": 10,
      "z": 3,
      "name": "Rock_Basalt"
    },
    {
      "x": -6,
      "y": 11,
      "z": 3,
      "name": "Rock_Basalt"
    },
    {
      "x": -6,
      "y": 12,
      "z": 3,
      "name": "Ore_Iron_Basalt_Cracked"
    },
    {
      "x": -6,
      "y": 13,
      "z": 3,
      "name": "Ore_Silver_Basalt"
    },
    {
      "x": -6,
      "y": 14,
      "z": 3,
      "name": "Ore_Iron_Basalt_Cracked"
    },
    {
      "x": -6,
      "y": 15,
      "z": 3,
      "name": "Soil_Sand_Ashen"
    },
    {
      "x": -6,
      "y": 16,
      "z": 3,
      "name": "Deco_Spider_Cocoon"
    },
    {
      "x": -6,
      "y": 17,
      "z": 3,
      "name": "Deco_Spider_Cocoon",
      "filler": 1024
    },
    {
      "x": -6,
      "y": 6,
      "z": 4,
      "name": "Ore_Iron_Basalt_Cracked"
    },
    {
      "x": -6,
      "y": 7,
      "z": 4,
      "name": "Rock_Basalt"
    },
    {
      "x": -6,
      "y": 8,
      "z": 4,
      "name": "Ore_Iron_Basalt_Cracked"
    },
    {
      "x": -6,
      "y": 9,
      "z": 4,
      "name": "Ore_Iron_Basalt_Cracked"
    },
    {
      "x": -6,
      "y": 10,
      "z": 4,
      "name": "Rock_Basalt"
    },
    {
      "x": -6,
      "y": 11,
      "z": 4,
      "name": "Rock_Basalt"
    },
    {
      "x": -6,
      "y": 12,
      "z": 4,
      "name": "Rock_Basalt"
    },
    {
      "x": -6,
      "y": 13,
      "z": 4,
      "name": "Rock_Basalt"
    },
    {
      "x": -6,
      "y": 14,
      "z": 4,
      "name": "Ore_Iron_Basalt_Cracked"
    },
    {
      "x": -6,
      "y": 15,
      "z": 4,
      "name": "Rock_Basalt"
    },
    {
      "x": -6,
      "y": 16,
      "z": 4,
      "name": "Soil_Ash"
    },
    {
      "x": -6,
      "y": 4,
      "z": 5,
      "name": "Rock_Basalt_Stalactite_Large",
      "filler": 31744,
      "rotation": 8
    },
    {
      "x": -6,
      "y": 5,
      "z": 5,
      "name": "Rock_Basalt_Stalactite_Large",
      "rotation": 8
    },
    {
      "x": -6,
      "y": 6,
      "z": 5,
      "name": "Rock_Basalt"
    },
    {
      "x": -6,
      "y": 7,
      "z": 5,
      "name": "Rock_Basalt"
    },
    {
      "x": -6,
      "y": 8,
      "z": 5,
      "name": "Rock_Basalt"
    },
    {
      "x": -6,
      "y": 9,
      "z": 5,
      "name": "Ore_Iron_Basalt_Cracked"
    },
    {
      "x": -6,
      "y": 10,
      "z": 5,
      "name": "Rock_Basalt"
    },
    {
      "x": -6,
      "y": 11,
      "z": 5,
      "name": "Rock_Basalt"
    },
    {
      "x": -6,
      "y": 12,
      "z": 5,
      "name": "Rock_Basalt"
    },
    {
      "x": -6,
      "y": 13,
      "z": 5,
      "name": "Ore_Silver_Basalt"
    },
    {
      "x": -6,
      "y": 14,
      "z": 5,
      "name": "Ore_Iron_Basalt_Cracked"
    },
    {
      "x": -6,
      "y": 15,
      "z": 5,
      "name": "Rock_Basalt"
    },
    {
      "x": -6,
      "y": 16,
      "z": 5,
      "name": "Soil_Ash"
    },
    {
      "x": -6,
      "y": 17,
      "z": 5,
      "name": "Deco_SpiderWeb_Flat"
    },
    {
      "x": -6,
      "y": 6,
      "z": 6,
      "name": "Rock_Basalt"
    },
    {
      "x": -6,
      "y": 7,
      "z": 6,
      "name": "Ore_Iron_Basalt_Cracked"
    },
    {
      "x": -6,
      "y": 8,
      "z": 6,
      "name": "Rock_Basalt"
    },
    {
      "x": -6,
      "y": 9,
      "z": 6,
      "name": "Rock_Basalt"
    },
    {
      "x": -6,
      "y": 10,
      "z": 6,
      "name": "Rock_Basalt"
    },
    {
      "x": -6,
      "y": 11,
      "z": 6,
      "name": "Ore_Iron_Basalt_Cracked"
    },
    {
      "x": -6,
      "y": 12,
      "z": 6,
      "name": "Rock_Basalt"
    },
    {
      "x": -6,
      "y": 13,
      "z": 6,
      "name": "Rock_Basalt"
    },
    {
      "x": -6,
      "y": 14,
      "z": 6,
      "name": "Ore_Iron_Basalt_Cracked"
    },
    {
      "x": -6,
      "y": 15,
      "z": 6,
      "name": "Ore_Iron_Basalt_Cracked"
    },
    {
      "x": -6,
      "y": 16,
      "z": 6,
      "name": "Soil_Ash"
    },
    {
      "x": -6,
      "y": 7,
      "z": 7,
      "name": "Ore_Iron_Basalt_Cracked"
    },
    {
      "x": -6,
      "y": 8,
      "z": 7,
      "name": "Rock_Basalt"
    },
    {
      "x": -6,
      "y": 9,
      "z": 7,
      "name": "Rock_Basalt"
    },
    {
      "x": -6,
      "y": 10,
      "z": 7,
      "name": "Ore_Iron_Basalt_Cracked"
    },
    {
      "x": -6,
      "y": 11,
      "z": 7,
      "name": "Ore_Iron_Basalt_Cracked"
    },
    {
      "x": -6,
      "y": 12,
      "z": 7,
      "name": "Rock_Basalt"
    },
    {
      "x": -6,
      "y": 13,
      "z": 7,
      "name": "Ore_Iron_Basalt_Cracked"
    },
    {
      "x": -6,
      "y": 14,
      "z": 7,
      "name": "Ore_Iron_Basalt_Cracked"
    },
    {
      "x": -6,
      "y": 15,
      "z": 7,
      "name": "Rock_Basalt"
    },
    {
      "x": -6,
      "y": 16,
      "z": 7,
      "name": "Soil_Ash"
    },
    {
      "x": -6,
      "y": 9,
      "z": 8,
      "name": "Ore_Iron_Basalt_Cracked"
    },
    {
      "x": -6,
      "y": 10,
      "z": 8,
      "name": "Rock_Basalt"
    },
    {
      "x": -6,
      "y": 11,
      "z": 8,
      "name": "Rock_Basalt"
    },
    {
      "x": -6,
      "y": 12,
      "z": 8,
      "name": "Rock_Basalt"
    },
    {
      "x": -6,
      "y": 13,
      "z": 8,
      "name": "Ore_Iron_Basalt_Cracked"
    },
    {
      "x": -6,
      "y": 14,
      "z": 8,
      "name": "Ore_Iron_Basalt_Cracked"
    },
    {
      "x": -6,
      "y": 15,
      "z": 8,
      "name": "Rock_Basalt"
    },
    {
      "x": -6,
      "y": 16,
      "z": 8,
      "name": "Soil_Ash"
    },
    {
      "x": -6,
      "y": 14,
      "z": 9,
      "name": "Deco_SpiderWeb_Flat",
      "rotation": 7
    },
    {
      "x": -5,
      "y": 39,
      "z": -12,
      "name": "Wood_Ash_Branch_Corner",
      "rotation": 3
    },
    {
      "x": -5,
      "y": 40,
      "z": -12,
      "name": "Wood_Ash_Branch_Corner",
      "rotation": 11
    },
    {
      "x": -5,
      "y": 14,
      "z": -9,
      "name": "Ore_Iron_Basalt_Cracked"
    },
    {
      "x": -5,
      "y": 15,
      "z": -9,
      "name": "Rock_Basalt"
    },
    {
      "x": -5,
      "y": 16,
      "z": -9,
      "name": "Soil_Ash"
    },
    {
      "x": -5,
      "y": 11,
      "z": -7,
      "name": "Rock_Basalt"
    },
    {
      "x": -5,
      "y": 12,
      "z": -7,
      "name": "Ore_Iron_Basalt_Cracked"
    },
    {
      "x": -5,
      "y": 13,
      "z": -7,
      "name": "Ore_Iron_Basalt_Cracked"
    },
    {
      "x": -5,
      "y": 14,
      "z": -7,
      "name": "Ore_Iron_Basalt_Cracked"
    },
    {
      "x": -5,
      "y": 15,
      "z": -7,
      "name": "Soil_Basalt_Gravel"
    },
    {
      "x": -5,
      "y": 16,
      "z": -7,
      "name": "Soil_Ash"
    },
    {
      "x": -5,
      "y": 17,
      "z": -7,
      "name": "Deco_SpiderWeb_Flat"
    },
    {
      "x": -5,
      "y": 7,
      "z": -6,
      "name": "Ore_Iron_Basalt_Cracked"
    },
    {
      "x": -5,
      "y": 8,
      "z": -6,
      "name": "Rock_Basalt"
    },
    {
      "x": -5,
      "y": 9,
      "z": -6,
      "name": "Rock_Basalt"
    },
    {
      "x": -5,
      "y": 10,
      "z": -6,
      "name": "Rock_Basalt"
    },
    {
      "x": -5,
      "y": 11,
      "z": -6,
      "name": "Ore_Iron_Basalt_Cracked"
    },
    {
      "x": -5,
      "y": 12,
      "z": -6,
      "name": "Rock_Basalt"
    },
    {
      "x": -5,
      "y": 13,
      "z": -6,
      "name": "Rock_Basalt"
    },
    {
      "x": -5,
      "y": 14,
      "z": -6,
      "name": "Ore_Iron_Basalt_Cracked"
    },
    {
      "x": -5,
      "y": 15,
      "z": -6,
      "name": "Soil_Basalt_Gravel"
    },
    {
      "x": -5,
      "y": 16,
      "z": -6,
      "name": "Soil_Ash"
    },
    {
      "x": -5,
      "y": 17,
      "z": -6,
      "name": "Deco_SpiderWeb_Flat"
    },
    {
      "x": -5,
      "y": 4,
      "z": -5,
      "name": "Rock_Crystal_Yellow_Large",
      "rotation": 5
    },
    {
      "x": -5,
      "y": 5,
      "z": -5,
      "name": "Rock_Crystal_Yellow_Medium",
      "rotation": 6
    },
    {
      "x": -5,
      "y": 6,
      "z": -5,
      "name": "Rock_Basalt"
    },
    {
      "x": -5,
      "y": 7,
      "z": -5,
      "name": "Rock_Basalt"
    },
    {
      "x": -5,
      "y": 8,
      "z": -5,
      "name": "Rock_Basalt"
    },
    {
      "x": -5,
      "y": 9,
      "z": -5,
      "name": "Ore_Iron_Basalt_Cracked"
    },
    {
      "x": -5,
      "y": 10,
      "z": -5,
      "name": "Rock_Basalt"
    },
    {
      "x": -5,
      "y": 11,
      "z": -5,
      "name": "Rock_Basalt"
    },
    {
      "x": -5,
      "y": 12,
      "z": -5,
      "name": "Ore_Iron_Basalt_Cracked"
    },
    {
      "x": -5,
      "y": 13,
      "z": -5,
      "name": "Ore_Iron_Basalt_Cracked"
    },
    {
      "x": -5,
      "y": 14,
      "z": -5,
      "name": "Ore_Iron_Basalt_Cracked"
    },
    {
      "x": -5,
      "y": 15,
      "z": -5,
      "name": "Soil_Ash"
    },
    {
      "x": -5,
      "y": 28,
      "z": -5,
      "name": "Wood_Ash_Branch_Corner",
      "rotation": 3
    },
    {
      "x": -5,
      "y": 29,
      "z": -5,
      "name": "Wood_Ash_Branch_Corner",
      "rotation": 11
    },
    {
      "x": -5,
      "y": 2,
      "z": -4,
      "name": "Rock_Crystal_Yellow_Large",
      "rotation": 5
    },
    {
      "x": -5,
      "y": 3,
      "z": -4,
      "name": "Rock_Crystal_Yellow_Large",
      "rotation": 8
    },
    {
      "x": -5,
      "y": 4,
      "z": -4,
      "name": "Rock_Crystal_Yellow_Block"
    },
    {
      "x": -5,
      "y": 5,
      "z": -4,
      "name": "Rock_Crystal_Yellow_Block"
    },
    {
      "x": -5,
      "y": 6,
      "z": -4,
      "name": "Rock_Crystal_Yellow_Block"
    },
    {
      "x": -5,
      "y": 7,
      "z": -4,
      "name": "Rock_Crystal_Yellow_Block"
    },
    {
      "x": -5,
      "y": 8,
      "z": -4,
      "name": "Rock_Basalt"
    },
    {
      "x": -5,
      "y": 9,
      "z": -4,
      "name": "Rock_Basalt"
    },
    {
      "x": -5,
      "y": 10,
      "z": -4,
      "name": "Ore_Iron_Basalt_Cracked"
    },
    {
      "x": -5,
      "y": 11,
      "z": -4,
      "name": "Rock_Basalt"
    },
    {
      "x": -5,
      "y": 12,
      "z": -4,
      "name": "Ore_Iron_Basalt_Cracked"
    },
    {
      "x": -5,
      "y": 13,
      "z": -4,
      "name": "Ore_Iron_Basalt_Cracked"
    },
    {
      "x": -5,
      "y": 14,
      "z": -4,
      "name": "Ore_Iron_Basalt_Cracked"
    },
    {
      "x": -5,
      "y": 15,
      "z": -4,
      "name": "Ore_Iron_Basalt_Cracked"
    },
    {
      "x": -5,
      "y": 16,
      "z": -4,
      "name": "Soil_Ash"
    },
    {
      "x": -5,
      "y": 31,
      "z": -4,
      "name": "Wood_Ash_Branch_Corner",
      "rotation": 3
    },
    {
      "x": -5,
      "y": 2,
      "z": -3,
      "name": "Rock_Crystal_Yellow_Medium",
      "rotation": 5
    },
    {
      "x": -5,
      "y": 3,
      "z": -3,
      "name": "Rock_Crystal_Yellow_Medium",
      "rotation": 5
    },
    {
      "x": -5,
      "y": 4,
      "z": -3,
      "name": "Rock_Crystal_Yellow_Medium",
      "rotation": 5
    },
    {
      "x": -5,
      "y": 5,
      "z": -3,
      "name": "Rock_Crystal_Yellow_Large",
      "rotation": 4
    },
    {
      "x": -5,
      "y": 6,
      "z": -3,
      "name": "Ore_Iron_Basalt_Cracked"
    },
    {
      "x": -5,
      "y": 7,
      "z": -3,
      "name": "Ore_Iron_Basalt_Cracked"
    },
    {
      "x": -5,
      "y": 8,
      "z": -3,
      "name": "Ore_Iron_Basalt_Cracked"
    },
    {
      "x": -5,
      "y": 9,
      "z": -3,
      "name": "Rock_Basalt"
    },
    {
      "x": -5,
      "y": 10,
      "z": -3,
      "name": "Rock_Basalt"
    },
    {
      "x": -5,
      "y": 11,
      "z": -3,
      "name": "Rock_Basalt"
    },
    {
      "x": -5,
      "y": 12,
      "z": -3,
      "name": "Ore_Iron_Basalt_Cracked"
    },
    {
      "x": -5,
      "y": 13,
      "z": -3,
      "name": "Ore_Iron_Basalt_Cracked"
    },
    {
      "x": -5,
      "y": 14,
      "z": -3,
      "name": "Ore_Iron_Basalt_Cracked"
    },
    {
      "x": -5,
      "y": 15,
      "z": -3,
      "name": "Soil_Sand_Ashen"
    },
    {
      "x": -5,
      "y": 35,
      "z": -3,
      "name": "Wood_Ash_Trunk_Full",
      "rotation": 5
    },
    {
      "x": -5,
      "y": 36,
      "z": -3,
      "name": "Wood_Ash_Trunk_Full",
      "rotation": 5
    },
    {
      "x": -5,
      "y": 6,
      "z": -2,
      "name": "Rock_Basalt"
    },
    {
      "x": -5,
      "y": 7,
      "z": -2,
      "name": "Rock_Basalt"
    },
    {
      "x": -5,
      "y": 8,
      "z": -2,
      "name": "Rock_Basalt"
    },
    {
      "x": -5,
      "y": 9,
      "z": -2,
      "name": "Rock_Basalt"
    },
    {
      "x": -5,
      "y": 10,
      "z": -2,
      "name": "Rock_Basalt"
    },
    {
      "x": -5,
      "y": 11,
      "z": -2,
      "name": "Ore_Iron_Basalt_Cracked"
    },
    {
      "x": -5,
      "y": 12,
      "z": -2,
      "name": "Ore_Iron_Basalt_Cracked"
    },
    {
      "x": -5,
      "y": 13,
      "z": -2,
      "name": "Ore_Iron_Basalt_Cracked"
    },
    {
      "x": -5,
      "y": 14,
      "z": -2,
      "name": "Soil_Basalt_Gravel"
    },
    {
      "x": -5,
      "y": 15,
      "z": -2,
      "name": "Soil_Sand_Ashen"
    },
    {
      "x": -5,
      "y": 3,
      "z": -1,
      "name": "Rock_Basalt_Stalactite_Large",
      "filler": 31744,
      "rotation": 8
    },
    {
      "x": -5,
      "y": 4,
      "z": -1,
      "name": "Rock_Basalt_Stalactite_Large",
      "rotation": 8
    },
    {
      "x": -5,
      "y": 5,
      "z": -1,
      "name": "Rock_Basalt"
    },
    {
      "x": -5,
      "y": 6,
      "z": -1,
      "name": "Rock_Basalt"
    },
    {
      "x": -5,
      "y": 7,
      "z": -1,
      "name": "Rock_Basalt"
    },
    {
      "x": -5,
      "y": 8,
      "z": -1,
      "name": "Rock_Basalt"
    },
    {
      "x": -5,
      "y": 9,
      "z": -1,
      "name": "Ore_Iron_Basalt_Cracked"
    },
    {
      "x": -5,
      "y": 10,
      "z": -1,
      "name": "Rock_Basalt"
    },
    {
      "x": -5,
      "y": 11,
      "z": -1,
      "name": "Rock_Basalt"
    },
    {
      "x": -5,
      "y": 12,
      "z": -1,
      "name": "Ore_Iron_Basalt_Cracked"
    },
    {
      "x": -5,
      "y": 13,
      "z": -1,
      "name": "Ore_Iron_Basalt_Cracked"
    },
    {
      "x": -5,
      "y": 14,
      "z": -1,
      "name": "Ore_Iron_Basalt_Cracked"
    },
    {
      "x": -5,
      "y": 15,
      "z": -1,
      "name": "Soil_Sand_Ashen"
    },
    {
      "x": -5,
      "y": 6,
      "z": 0,
      "name": "Ore_Iron_Basalt_Cracked"
    },
    {
      "x": -5,
      "y": 7,
      "z": 0,
      "name": "Rock_Basalt"
    },
    {
      "x": -5,
      "y": 8,
      "z": 0,
      "name": "Rock_Basalt"
    },
    {
      "x": -5,
      "y": 9,
      "z": 0,
      "name": "Rock_Basalt"
    },
    {
      "x": -5,
      "y": 10,
      "z": 0,
      "name": "Rock_Basalt"
    },
    {
      "x": -5,
      "y": 11,
      "z": 0,
      "name": "Rock_Basalt"
    },
    {
      "x": -5,
      "y": 12,
      "z": 0,
      "name": "Rock_Basalt"
    },
    {
      "x": -5,
      "y": 13,
      "z": 0,
      "name": "Ore_Iron_Basalt_Cracked"
    },
    {
      "x": -5,
      "y": 14,
      "z": 0,
      "name": "Soil_Basalt_Gravel"
    },
    {
      "x": -5,
      "y": 15,
      "z": 0,
      "name": "Soil_Sand_Ashen"
    },
    {
      "x": -5,
      "y": 4,
      "z": 1,
      "name": "Rock_Basalt_Stalactite_Small",
      "rotation": 8
    },
    {
      "x": -5,
      "y": 5,
      "z": 1,
      "name": "Rock_Basalt"
    },
    {
      "x": -5,
      "y": 6,
      "z": 1,
      "name": "Rock_Basalt"
    },
    {
      "x": -5,
      "y": 7,
      "z": 1,
      "name": "Ore_Iron_Basalt_Cracked"
    },
    {
      "x": -5,
      "y": 8,
      "z": 1,
      "name": "Rock_Basalt"
    },
    {
      "x": -5,
      "y": 9,
      "z": 1,
      "name": "Rock_Basalt"
    },
    {
      "x": -5,
      "y": 10,
      "z": 1,
      "name": "Rock_Basalt"
    },
    {
      "x": -5,
      "y": 11,
      "z": 1,
      "name": "Rock_Basalt"
    },
    {
      "x": -5,
      "y": 12,
      "z": 1,
      "name": "Rock_Basalt"
    },
    {
      "x": -5,
      "y": 13,
      "z": 1,
      "name": "Ore_Iron_Basalt_Cracked"
    },
    {
      "x": -5,
      "y": 14,
      "z": 1,
      "name": "Rock_Basalt"
    },
    {
      "x": -5,
      "y": 15,
      "z": 1,
      "name": "Soil_Sand_Ashen"
    },
    {
      "x": -5,
      "y": 5,
      "z": 2,
      "name": "Rock_Basalt"
    },
    {
      "x": -5,
      "y": 6,
      "z": 2,
      "name": "Ore_Iron_Basalt_Cracked"
    },
    {
      "x": -5,
      "y": 7,
      "z": 2,
      "name": "Ore_Iron_Basalt_Cracked"
    },
    {
      "x": -5,
      "y": 8,
      "z": 2,
      "name": "Rock_Basalt"
    },
    {
      "x": -5,
      "y": 9,
      "z": 2,
      "name": "Rock_Basalt"
    },
    {
      "x": -5,
      "y": 10,
      "z": 2,
      "name": "Rock_Basalt"
    },
    {
      "x": -5,
      "y": 11,
      "z": 2,
      "name": "Ore_Iron_Basalt_Cracked"
    },
    {
      "x": -5,
      "y": 12,
      "z": 2,
      "name": "Ore_Iron_Basalt_Cracked"
    },
    {
      "x": -5,
      "y": 13,
      "z": 2,
      "name": "Ore_Iron_Basalt_Cracked"
    },
    {
      "x": -5,
      "y": 14,
      "z": 2,
      "name": "Soil_Basalt_Gravel"
    },
    {
      "x": -5,
      "y": 15,
      "z": 2,
      "name": "Soil_Sand_Ashen"
    },
    {
      "x": -5,
      "y": 5,
      "z": 3,
      "name": "Rock_Basalt"
    },
    {
      "x": -5,
      "y": 6,
      "z": 3,
      "name": "Rock_Basalt"
    },
    {
      "x": -5,
      "y": 7,
      "z": 3,
      "name": "Ore_Iron_Basalt_Cracked"
    },
    {
      "x": -5,
      "y": 8,
      "z": 3,
      "name": "Rock_Basalt"
    },
    {
      "x": -5,
      "y": 9,
      "z": 3,
      "name": "Rock_Basalt"
    },
    {
      "x": -5,
      "y": 10,
      "z": 3,
      "name": "Ore_Iron_Basalt_Cracked"
    },
    {
      "x": -5,
      "y": 11,
      "z": 3,
      "name": "Rock_Basalt"
    },
    {
      "x": -5,
      "y": 12,
      "z": 3,
      "name": "Rock_Basalt"
    },
    {
      "x": -5,
      "y": 13,
      "z": 3,
      "name": "Ore_Iron_Basalt"
    },
    {
      "x": -5,
      "y": 14,
      "z": 3,
      "name": "Rock_Basalt"
    },
    {
      "x": -5,
      "y": 15,
      "z": 3,
      "name": "Soil_Ash"
    },
    {
      "x": -5,
      "y": 6,
      "z": 4,
      "name": "Rock_Basalt"
    },
    {
      "x": -5,
      "y": 7,
      "z": 4,
      "name": "Rock_Basalt"
    },
    {
      "x": -5,
      "y": 8,
      "z": 4,
      "name": "Ore_Iron_Basalt_Cracked"
    },
    {
      "x": -5,
      "y": 9,
      "z": 4,
      "name": "Rock_Basalt"
    },
    {
      "x": -5,
      "y": 10,
      "z": 4,
      "name": "Ore_Iron_Basalt_Cracked"
    },
    {
      "x": -5,
      "y": 11,
      "z": 4,
      "name": "Ore_Iron_Basalt_Cracked"
    },
    {
      "x": -5,
      "y": 12,
      "z": 4,
      "name": "Rock_Basalt"
    },
    {
      "x": -5,
      "y": 13,
      "z": 4,
      "name": "Ore_Iron_Basalt_Cracked"
    },
    {
      "x": -5,
      "y": 14,
      "z": 4,
      "name": "Ore_Iron_Basalt_Cracked"
    },
    {
      "x": -5,
      "y": 15,
      "z": 4,
      "name": "Soil_Ash"
    },
    {
      "x": -5,
      "y": 6,
      "z": 5,
      "name": "Rock_Basalt"
    },
    {
      "x": -5,
      "y": 7,
      "z": 5,
      "name": "Ore_Iron_Basalt_Cracked"
    },
    {
      "x": -5,
      "y": 8,
      "z": 5,
      "name": "Rock_Basalt"
    },
    {
      "x": -5,
      "y": 9,
      "z": 5,
      "name": "Rock_Basalt"
    },
    {
      "x": -5,
      "y": 10,
      "z": 5,
      "name": "Rock_Basalt"
    },
    {
      "x": -5,
      "y": 11,
      "z": 5,
      "name": "Rock_Basalt"
    },
    {
      "x": -5,
      "y": 12,
      "z": 5,
      "name": "Rock_Basalt"
    },
    {
      "x": -5,
      "y": 13,
      "z": 5,
      "name": "Ore_Silver_Basalt"
    },
    {
      "x": -5,
      "y": 14,
      "z": 5,
      "name": "Ore_Iron_Basalt_Cracked"
    },
    {
      "x": -5,
      "y": 15,
      "z": 5,
      "name": "Ore_Iron_Basalt_Cracked"
    },
    {
      "x": -5,
      "y": 16,
      "z": 5,
      "name": "Soil_Ash"
    },
    {
      "x": -5,
      "y": 7,
      "z": 6,
      "name": "Rock_Basalt"
    },
    {
      "x": -5,
      "y": 8,
      "z": 6,
      "name": "Ore_Iron_Basalt_Cracked"
    },
    {
      "x": -5,
      "y": 9,
      "z": 6,
      "name": "Rock_Basalt"
    },
    {
      "x": -5,
      "y": 10,
      "z": 6,
      "name": "Ore_Iron_Basalt_Cracked"
    },
    {
      "x": -5,
      "y": 11,
      "z": 6,
      "name": "Rock_Basalt"
    },
    {
      "x": -5,
      "y": 12,
      "z": 6,
      "name": "Rock_Basalt"
    },
    {
      "x": -5,
      "y": 13,
      "z": 6,
      "name": "Ore_Iron_Basalt_Cracked"
    },
    {
      "x": -5,
      "y": 14,
      "z": 6,
      "name": "Ore_Iron_Basalt_Cracked"
    },
    {
      "x": -5,
      "y": 15,
      "z": 6,
      "name": "Ore_Iron_Basalt_Cracked"
    },
    {
      "x": -5,
      "y": 16,
      "z": 6,
      "name": "Soil_Ash"
    },
    {
      "x": -5,
      "y": 7,
      "z": 7,
      "name": "Rock_Basalt"
    },
    {
      "x": -5,
      "y": 8,
      "z": 7,
      "name": "Rock_Basalt"
    },
    {
      "x": -5,
      "y": 9,
      "z": 7,
      "name": "Rock_Basalt"
    },
    {
      "x": -5,
      "y": 10,
      "z": 7,
      "name": "Rock_Basalt"
    },
    {
      "x": -5,
      "y": 11,
      "z": 7,
      "name": "Ore_Iron_Basalt_Cracked"
    },
    {
      "x": -5,
      "y": 12,
      "z": 7,
      "name": "Rock_Basalt"
    },
    {
      "x": -5,
      "y": 13,
      "z": 7,
      "name": "Rock_Basalt"
    },
    {
      "x": -5,
      "y": 14,
      "z": 7,
      "name": "Ore_Iron_Basalt_Cracked"
    },
    {
      "x": -5,
      "y": 15,
      "z": 7,
      "name": "Ore_Iron_Basalt_Cracked"
    },
    {
      "x": -5,
      "y": 16,
      "z": 7,
      "name": "Soil_Basalt_Gravel"
    },
    {
      "x": -5,
      "y": 17,
      "z": 7,
      "name": "Soil_Ash"
    },
    {
      "x": -5,
      "y": 9,
      "z": 8,
      "name": "Ore_Iron_Basalt_Cracked"
    },
    {
      "x": -5,
      "y": 10,
      "z": 8,
      "name": "Ore_Iron_Basalt_Cracked"
    },
    {
      "x": -5,
      "y": 11,
      "z": 8,
      "name": "Rock_Basalt"
    },
    {
      "x": -5,
      "y": 12,
      "z": 8,
      "name": "Rock_Basalt"
    },
    {
      "x": -5,
      "y": 13,
      "z": 8,
      "name": "Rock_Basalt"
    },
    {
      "x": -5,
      "y": 14,
      "z": 8,
      "name": "Ore_Iron_Basalt_Cracked"
    },
    {
      "x": -5,
      "y": 15,
      "z": 8,
      "name": "Rock_Basalt"
    },
    {
      "x": -5,
      "y": 16,
      "z": 8,
      "name": "Soil_Ash"
    },
    {
      "x": -5,
      "y": 17,
      "z": 8,
      "name": "Plant_Moss_Yellow"
    },
    {
      "x": -5,
      "y": 13,
      "z": 9,
      "name": "Rock_Basalt"
    },
    {
      "x": -5,
      "y": 14,
      "z": 9,
      "name": "Ore_Iron_Basalt_Cracked"
    },
    {
      "x": -5,
      "y": 15,
      "z": 9,
      "name": "Ore_Iron_Basalt_Cracked"
    },
    {
      "x": -5,
      "y": 16,
      "z": 9,
      "name": "Soil_Ash"
    },
    {
      "x": -5,
      "y": 13,
      "z": 10,
      "name": "Deco_SpiderWeb_Flat",
      "rotation": 4
    },
    {
      "x": -4,
      "y": 39,
      "z": -12,
      "name": "Wood_Ash_Branch_Long",
      "rotation": 5
    },
    {
      "x": -4,
      "y": 12,
      "z": -10,
      "name": "Rock_Basalt"
    },
    {
      "x": -4,
      "y": 14,
      "z": -10,
      "name": "Rock_Basalt"
    },
    {
      "x": -4,
      "y": 15,
      "z": -10,
      "name": "Soil_Ash"
    },
    {
      "x": -4,
      "y": 12,
      "z": -9,
      "name": "Ore_Iron_Basalt_Cracked"
    },
    {
      "x": -4,
      "y": 13,
      "z": -9,
      "name": "Rock_Basalt"
    },
    {
      "x": -4,
      "y": 14,
      "z": -9,
      "name": "Ore_Iron_Basalt_Cracked"
    },
    {
      "x": -4,
      "y": 15,
      "z": -9,
      "name": "Rock_Basalt"
    },
    {
      "x": -4,
      "y": 16,
      "z": -9,
      "name": "Soil_Ash"
    },
    {
      "x": -4,
      "y": 12,
      "z": -8,
      "name": "Rock_Basalt"
    },
    {
      "x": -4,
      "y": 13,
      "z": -8,
      "name": "Rock_Basalt"
    },
    {
      "x": -4,
      "y": 14,
      "z": -8,
      "name": "Ore_Iron_Basalt"
    },
    {
      "x": -4,
      "y": 15,
      "z": -8,
      "name": "Rock_Basalt"
    },
    {
      "x": -4,
      "y": 16,
      "z": -8,
      "name": "Soil_Ash"
    },
    {
      "x": -4,
      "y": 10,
      "z": -7,
      "name": "Ore_Iron_Basalt_Cracked"
    },
    {
      "x": -4,
      "y": 11,
      "z": -7,
      "name": "Rock_Basalt"
    },
    {
      "x": -4,
      "y": 12,
      "z": -7,
      "name": "Rock_Basalt"
    },
    {
      "x": -4,
      "y": 13,
      "z": -7,
      "name": "Rock_Basalt"
    },
    {
      "x": -4,
      "y": 14,
      "z": -7,
      "name": "Ore_Iron_Basalt"
    },
    {
      "x": -4,
      "y": 15,
      "z": -7,
      "name": "Rock_Basalt"
    },
    {
      "x": -4,
      "y": 16,
      "z": -7,
      "name": "Soil_Ash"
    },
    {
      "x": -4,
      "y": 17,
      "z": -7,
      "name": "Deco_SpiderWeb_Flat"
    },
    {
      "x": -4,
      "y": 10,
      "z": -6,
      "name": "Rock_Basalt"
    },
    {
      "x": -4,
      "y": 11,
      "z": -6,
      "name": "Rock_Basalt"
    },
    {
      "x": -4,
      "y": 12,
      "z": -6,
      "name": "Rock_Basalt"
    },
    {
      "x": -4,
      "y": 13,
      "z": -6,
      "name": "Rock_Basalt"
    },
    {
      "x": -4,
      "y": 14,
      "z": -6,
      "name": "Ore_Iron_Basalt_Cracked"
    },
    {
      "x": -4,
      "y": 15,
      "z": -6,
      "name": "Soil_Basalt_Gravel"
    },
    {
      "x": -4,
      "y": 16,
      "z": -6,
      "name": "Soil_Ash"
    },
    {
      "x": -4,
      "y": 6,
      "z": -5,
      "name": "Rock_Crystal_Yellow_Medium",
      "rotation": 5
    },
    {
      "x": -4,
      "y": 7,
      "z": -5,
      "name": "Rock_Crystal_Yellow_Medium",
      "rotation": 5
    },
    {
      "x": -4,
      "y": 8,
      "z": -5,
      "name": "Rock_Basalt"
    },
    {
      "x": -4,
      "y": 9,
      "z": -5,
      "name": "Ore_Iron_Basalt_Cracked"
    },
    {
      "x": -4,
      "y": 10,
      "z": -5,
      "name": "Rock_Basalt"
    },
    {
      "x": -4,
      "y": 11,
      "z": -5,
      "name": "Rock_Basalt"
    },
    {
      "x": -4,
      "y": 12,
      "z": -5,
      "name": "Ore_Iron_Basalt_Cracked"
    },
    {
      "x": -4,
      "y": 13,
      "z": -5,
      "name": "Ore_Iron_Basalt_Cracked"
    },
    {
      "x": -4,
      "y": 14,
      "z": -5,
      "name": "Ore_Iron_Basalt_Cracked"
    },
    {
      "x": -4,
      "y": 15,
      "z": -5,
      "name": "Rock_Basalt"
    },
    {
      "x": -4,
      "y": 16,
      "z": -5,
      "name": "Soil_Ash"
    },
    {
      "x": -4,
      "y": 28,
      "z": -5,
      "name": "Wood_Ash_Branch_Long",
      "rotation": 5
    },
    {
      "x": -4,
      "y": 4,
      "z": -4,
      "name": "Rock_Crystal_Yellow_Large",
      "rotation": 5
    },
    {
      "x": -4,
      "y": 5,
      "z": -4,
      "name": "Rock_Crystal_Yellow_Medium",
      "rotation": 5
    },
    {
      "x": -4,
      "y": 6,
      "z": -4,
      "name": "Rock_Crystal_Yellow_Large",
      "rotation": 5
    },
    {
      "x": -4,
      "y": 7,
      "z": -4,
      "name": "Rock_Crystal_Yellow_Medium",
      "rotation": 5
    },
    {
      "x": -4,
      "y": 8,
      "z": -4,
      "name": "Ore_Iron_Basalt_Cracked"
    },
    {
      "x": -4,
      "y": 9,
      "z": -4,
      "name": "Rock_Basalt"
    },
    {
      "x": -4,
      "y": 10,
      "z": -4,
      "name": "Rock_Basalt"
    },
    {
      "x": -4,
      "y": 11,
      "z": -4,
      "name": "Rock_Basalt"
    },
    {
      "x": -4,
      "y": 12,
      "z": -4,
      "name": "Rock_Basalt"
    },
    {
      "x": -4,
      "y": 13,
      "z": -4,
      "name": "Rock_Basalt"
    },
    {
      "x": -4,
      "y": 14,
      "z": -4,
      "name": "Ore_Iron_Basalt_Cracked"
    },
    {
      "x": -4,
      "y": 15,
      "z": -4,
      "name": "Rock_Basalt"
    },
    {
      "x": -4,
      "y": 16,
      "z": -4,
      "name": "Soil_Ash"
    },
    {
      "x": -4,
      "y": 17,
      "z": -4,
      "name": "Plant_Bush_Arid"
    },
    {
      "x": -4,
      "y": 31,
      "z": -4,
      "name": "Wood_Ash_Branch_Corner",
      "rotation": 1
    },
    {
      "x": -4,
      "y": 32,
      "z": -4,
      "name": "Wood_Ash_Branch_Corner",
      "rotation": 9
    },
    {
      "x": -4,
      "y": 6,
      "z": -3,
      "name": "Rock_Crystal_Yellow_Large",
      "rotation": 5
    },
    {
      "x": -4,
      "y": 7,
      "z": -3,
      "name": "Rock_Basalt"
    },
    {
      "x": -4,
      "y": 8,
      "z": -3,
      "name": "Rock_Basalt"
    },
    {
      "x": -4,
      "y": 9,
      "z": -3,
      "name": "Rock_Basalt"
    },
    {
      "x": -4,
      "y": 10,
      "z": -3,
      "name": "Rock_Basalt"
    },
    {
      "x": -4,
      "y": 11,
      "z": -3,
      "name": "Rock_Basalt"
    },
    {
      "x": -4,
      "y": 12,
      "z": -3,
      "name": "Rock_Basalt"
    },
    {
      "x": -4,
      "y": 13,
      "z": -3,
      "name": "Rock_Basalt"
    },
    {
      "x": -4,
      "y": 14,
      "z": -3,
      "name": "Ore_Iron_Basalt_Cracked"
    },
    {
      "x": -4,
      "y": 15,
      "z": -3,
      "name": "Rock_Basalt"
    },
    {
      "x": -4,
      "y": 16,
      "z": -3,
      "name": "Soil_Sand_Ashen"
    },
    {
      "x": -4,
      "y": 35,
      "z": -3,
      "name": "Wood_Ash_Trunk",
      "rotation": 5
    },
    {
      "x": -4,
      "y": 6,
      "z": -2,
      "name": "Rock_Basalt"
    },
    {
      "x": -4,
      "y": 7,
      "z": -2,
      "name": "Rock_Basalt"
    },
    {
      "x": -4,
      "y": 8,
      "z": -2,
      "name": "Ore_Iron_Basalt_Cracked"
    },
    {
      "x": -4,
      "y": 9,
      "z": -2,
      "name": "Ore_Iron_Basalt_Cracked"
    },
    {
      "x": -4,
      "y": 10,
      "z": -2,
      "name": "Ore_Iron_Basalt_Cracked"
    },
    {
      "x": -4,
      "y": 11,
      "z": -2,
      "name": "Rock_Basalt"
    },
    {
      "x": -4,
      "y": 12,
      "z": -2,
      "name": "Ore_Iron_Basalt_Cracked"
    },
    {
      "x": -4,
      "y": 13,
      "z": -2,
      "name": "Rock_Basalt"
    },
    {
      "x": -4,
      "y": 14,
      "z": -2,
      "name": "Ore_Iron_Basalt_Cracked"
    },
    {
      "x": -4,
      "y": 15,
      "z": -2,
      "name": "Soil_Basalt_Gravel"
    },
    {
      "x": -4,
      "y": 16,
      "z": -2,
      "name": "Soil_Sand_Ashen"
    },
    {
      "x": -4,
      "y": 35,
      "z": -2,
      "name": "Wood_Ash_Trunk_Full",
      "rotation": 5
    },
    {
      "x": -4,
      "y": 6,
      "z": -1,
      "name": "Rock_Basalt"
    },
    {
      "x": -4,
      "y": 7,
      "z": -1,
      "name": "Rock_Basalt"
    },
    {
      "x": -4,
      "y": 8,
      "z": -1,
      "name": "Rock_Basalt"
    },
    {
      "x": -4,
      "y": 9,
      "z": -1,
      "name": "Rock_Basalt"
    },
    {
      "x": -4,
      "y": 10,
      "z": -1,
      "name": "Ore_Iron_Basalt_Cracked"
    },
    {
      "x": -4,
      "y": 11,
      "z": -1,
      "name": "Ore_Iron_Basalt_Cracked"
    },
    {
      "x": -4,
      "y": 12,
      "z": -1,
      "name": "Rock_Basalt"
    },
    {
      "x": -4,
      "y": 13,
      "z": -1,
      "name": "Ore_Iron_Basalt_Cracked"
    },
    {
      "x": -4,
      "y": 14,
      "z": -1,
      "name": "Ore_Iron_Basalt_Cracked"
    },
    {
      "x": -4,
      "y": 15,
      "z": -1,
      "name": "Soil_Sand_Ashen"
    },
    {
      "x": -4,
      "y": 6,
      "z": 0,
      "name": "Rock_Basalt"
    },
    {
      "x": -4,
      "y": 7,
      "z": 0,
      "name": "Rock_Basalt"
    },
    {
      "x": -4,
      "y": 8,
      "z": 0,
      "name": "Rock_Basalt"
    },
    {
      "x": -4,
      "y": 9,
      "z": 0,
      "name": "Ore_Iron_Basalt_Cracked"
    },
    {
      "x": -4,
      "y": 10,
      "z": 0,
      "name": "Ore_Iron_Basalt_Cracked"
    },
    {
      "x": -4,
      "y": 11,
      "z": 0,
      "name": "Rock_Basalt"
    },
    {
      "x": -4,
      "y": 12,
      "z": 0,
      "name": "Ore_Iron_Basalt_Cracked"
    },
    {
      "x": -4,
      "y": 13,
      "z": 0,
      "name": "Ore_Iron_Basalt_Cracked"
    },
    {
      "x": -4,
      "y": 14,
      "z": 0,
      "name": "Ore_Iron_Basalt_Cracked"
    },
    {
      "x": -4,
      "y": 15,
      "z": 0,
      "name": "Soil_Sand_Ashen"
    },
    {
      "x": -4,
      "y": 6,
      "z": 1,
      "name": "Rock_Basalt"
    },
    {
      "x": -4,
      "y": 7,
      "z": 1,
      "name": "Ore_Iron_Basalt_Cracked"
    },
    {
      "x": -4,
      "y": 8,
      "z": 1,
      "name": "Rock_Basalt"
    },
    {
      "x": -4,
      "y": 9,
      "z": 1,
      "name": "Rock_Basalt"
    },
    {
      "x": -4,
      "y": 10,
      "z": 1,
      "name": "Rock_Basalt"
    },
    {
      "x": -4,
      "y": 11,
      "z": 1,
      "name": "Rock_Basalt"
    },
    {
      "x": -4,
      "y": 12,
      "z": 1,
      "name": "Rock_Basalt"
    },
    {
      "x": -4,
      "y": 13,
      "z": 1,
      "name": "Ore_Iron_Basalt_Cracked"
    },
    {
      "x": -4,
      "y": 14,
      "z": 1,
      "name": "Ore_Iron_Basalt_Cracked"
    },
    {
      "x": -4,
      "y": 15,
      "z": 1,
      "name": "Soil_Sand_Ashen"
    },
    {
      "x": -4,
      "y": 5,
      "z": 2,
      "name": "Ore_Iron_Basalt_Cracked"
    },
    {
      "x": -4,
      "y": 6,
      "z": 2,
      "name": "Ore_Iron_Basalt_Cracked"
    },
    {
      "x": -4,
      "y": 7,
      "z": 2,
      "name": "Rock_Basalt"
    },
    {
      "x": -4,
      "y": 8,
      "z": 2,
      "name": "Rock_Basalt"
    },
    {
      "x": -4,
      "y": 9,
      "z": 2,
      "name": "Ore_Iron_Basalt_Cracked"
    },
    {
      "x": -4,
      "y": 10,
      "z": 2,
      "name": "Ore_Iron_Basalt_Cracked"
    },
    {
      "x": -4,
      "y": 11,
      "z": 2,
      "name": "Ore_Iron_Basalt_Cracked"
    },
    {
      "x": -4,
      "y": 12,
      "z": 2,
      "name": "Rock_Basalt"
    },
    {
      "x": -4,
      "y": 13,
      "z": 2,
      "name": "Rock_Basalt"
    },
    {
      "x": -4,
      "y": 14,
      "z": 2,
      "name": "Soil_Ash"
    },
    {
      "x": -4,
      "y": 6,
      "z": 3,
      "name": "Rock_Basalt"
    },
    {
      "x": -4,
      "y": 7,
      "z": 3,
      "name": "Rock_Basalt"
    },
    {
      "x": -4,
      "y": 8,
      "z": 3,
      "name": "Rock_Basalt"
    },
    {
      "x": -4,
      "y": 9,
      "z": 3,
      "name": "Rock_Basalt"
    },
    {
      "x": -4,
      "y": 10,
      "z": 3,
      "name": "Rock_Basalt"
    },
    {
      "x": -4,
      "y": 11,
      "z": 3,
      "name": "Ore_Iron_Basalt_Cracked"
    },
    {
      "x": -4,
      "y": 12,
      "z": 3,
      "name": "Ore_Iron_Basalt_Cracked"
    },
    {
      "x": -4,
      "y": 13,
      "z": 3,
      "name": "Rock_Basalt"
    },
    {
      "x": -4,
      "y": 14,
      "z": 3,
      "name": "Soil_Ash"
    },
    {
      "x": -4,
      "y": 5,
      "z": 4,
      "name": "Rock_Basalt"
    },
    {
      "x": -4,
      "y": 6,
      "z": 4,
      "name": "Rock_Basalt"
    },
    {
      "x": -4,
      "y": 7,
      "z": 4,
      "name": "Ore_Iron_Basalt_Cracked"
    },
    {
      "x": -4,
      "y": 8,
      "z": 4,
      "name": "Rock_Basalt"
    },
    {
      "x": -4,
      "y": 9,
      "z": 4,
      "name": "Rock_Basalt"
    },
    {
      "x": -4,
      "y": 10,
      "z": 4,
      "name": "Ore_Iron_Basalt_Cracked"
    },
    {
      "x": -4,
      "y": 11,
      "z": 4,
      "name": "Rock_Basalt"
    },
    {
      "x": -4,
      "y": 12,
      "z": 4,
      "name": "Ore_Iron_Basalt_Cracked"
    },
    {
      "x": -4,
      "y": 13,
      "z": 4,
      "name": "Ore_Iron_Basalt_Cracked"
    },
    {
      "x": -4,
      "y": 14,
      "z": 4,
      "name": "Ore_Iron_Basalt_Cracked"
    },
    {
      "x": -4,
      "y": 15,
      "z": 4,
      "name": "Soil_Ash"
    },
    {
      "x": -4,
      "y": 6,
      "z": 5,
      "name": "Rock_Basalt"
    },
    {
      "x": -4,
      "y": 7,
      "z": 5,
