{
  "version": 8,
  "blockIdVersion": 11,
  "anchorX": 0,
  "anchorY": 0,
  "anchorZ": 0,
  "blocks": [
    {
      "x": -21,
      "y": 25,
      "z": -3,
      "name": "Rock_Stone"
    },
    {
      "x": -21,
      "y": 26,
      "z": -3,
      "name": "Rock_Stone"
    },
    {
      "x": -21,
      "y": 27,
      "z": -3,
      "name": "Plant_Crop_Mushroom_Block_Brown"
    },
    {
      "x": -21,
      "y": 28,
      "z": -3,
      "name": "Plant_Crop_Mushroom_Block_Brown"
    },
    {
      "x": -21,
      "y": 29,
      "z": -3,
      "name": "Plant_Crop_Mushroom_Common_Lime",
      "components": {
        "Components": {
          "FarmingBlock": {
            "LastTickGameTime": "0001-01-03T12:00:00Z"
          }
        }
      }
    },
    {
      "x": -21,
      "y": 24,
      "z": -2,
      "name": "Rock_Stone"
    },
    {
      "x": -21,
      "y": 25,
      "z": -2,
      "name": "Plant_Crop_Mushroom_Block_Brown"
    },
    {
      "x": -21,
      "y": 26,
      "z": -2,
      "name": "Plant_Crop_Mushroom_Block_Brown"
    },
    {
      "x": -21,
      "y": 27,
      "z": -2,
      "name": "Plant_Crop_Mushroom_Common_Brown",
      "components": {
        "Components": {
          "FarmingBlock": {
            "LastTickGameTime": "0001-01-03T12:00:00Z"
          }
        }
      }
    },
    {
      "x": -21,
      "y": 23,
      "z": -1,
      "name": "Rock_Stone"
    },
    {
      "x": -21,
      "y": 24,
      "z": -1,
      "name": "Ore_Copper_Stone"
    },
    {
      "x": -21,
      "y": 25,
      "z": -1,
      "name": "Plant_Crop_Mushroom_Block_Brown"
    },
    {
      "x": -21,
      "y": 26,
      "z": -1,
      "name": "Plant_Crop_Mushroom_Block_Brown"
    },
    {
      "x": -21,
      "y": 27,
      "z": -1,
      "name": "Plant_Crop_Mushroom_Block_Brown"
    },
    {
      "x": -21,
      "y": 19,
      "z": 0,
      "name": "Rock_Stone_Stalactite_Large",
      "filler": 31744,
      "rotation": 8
    },
    {
      "x": -21,
      "y": 20,
      "z": 0,
      "name": "Rock_Stone_Stalactite_Large",
      "rotation": 8
    },
    {
      "x": -21,
      "y": 21,
      "z": 0,
      "name": "Rock_Stone_Mossy"
    },
    {
      "x": -21,
      "y": 22,
      "z": 0,
      "name": "Plant_Crop_Mushroom_Block_Brown"
    },
    {
      "x": -21,
      "y": 23,
      "z": 0,
      "name": "Plant_Crop_Mushroom_Block_Brown"
    },
    {
      "x": -21,
      "y": 24,
      "z": 0,
      "name": "Plant_Crop_Mushroom_Block_Brown"
    },
    {
      "x": -21,
      "y": 22,
      "z": 1,
      "name": "Plant_Crop_Mushroom_Block_Brown"
    },
    {
      "x": -21,
      "y": 23,
      "z": 1,
      "name": "Plant_Crop_Mushroom_Block_Brown"
    },
    {
      "x": -21,
      "y": 24,
      "z": 1,
      "name": "Plant_Crop_Mushroom_Block_Brown"
    },
    {
      "x": -21,
      "y": 23,
      "z": 4,
      "name": "Plant_Moss_Rug_Yellow"
    },
    {
      "x": -21,
      "y": 23,
      "z": 5,
      "name": "Plant_Crop_Mushroom_Block_Brown"
    },
    {
      "x": -21,
      "y": 24,
      "z": 5,
      "name": "Plant_Moss_Rug_Yellow"
    },
    {
      "x": -21,
      "y": 23,
      "z": 6,
      "name": "Plant_Crop_Mushroom_Block_Brown"
    },
    {
      "x": -21,
      "y": 24,
      "z": 6,
      "name": "Plant_Crop_Mushroom_Block_Brown"
    },
    {
      "x": -21,
      "y": 25,
      "z": 6,
      "name": "Plant_Moss_Rug_Yellow"
    },
    {
      "x": -21,
      "y": 23,
      "z": 7,
      "name": "Rock_Stone_Mossy"
    },
    {
      "x": -21,
      "y": 24,
      "z": 7,
      "name": "Plant_Crop_Mushroom_Block_Brown"
    },
    {
      "x": -21,
      "y": 25,
      "z": 7,
      "name": "Plant_Crop_Mushroom_Block_Brown"
    },
    {
      "x": -21,
      "y": 26,
      "z": 7,
      "name": "Plant_Crop_Mushroom_Glowing_Orange"
    },
    {
      "x": -21,
      "y": 25,
      "z": 8,
      "name": "Rock_Stone"
    },
    {
      "x": -21,
      "y": 26,
      "z": 8,
      "name": "Plant_Crop_Mushroom_Block_Brown"
    },
    {
      "x": -21,
      "y": 27,
      "z": 8,
      "name": "Plant_Crop_Mushroom_Block_Brown"
    },
    {
      "x": -21,
      "y": 28,
      "z": 8,
      "name": "Plant_Moss_Rug_Yellow"
    },
    {
      "x": -20,
      "y": 24,
      "z": -4,
      "name": "Rock_Stone"
    },
    {
      "x": -20,
      "y": 25,
      "z": -4,
      "name": "Rock_Stone"
    },
    {
      "x": -20,
      "y": 26,
      "z": -4,
      "name": "Rock_Stone"
    },
    {
      "x": -20,
      "y": 27,
      "z": -4,
      "name": "Rock_Stone"
    },
    {
      "x": -20,
      "y": 28,
      "z": -4,
      "name": "Plant_Crop_Mushroom_Block_Brown"
    },
    {
      "x": -20,
      "y": 29,
      "z": -4,
      "name": "Plant_Crop_Mushroom_Block_Brown"
    },
    {
      "x": -20,
      "y": 30,
      "z": -4,
      "name": "Plant_Crop_Mushroom_Cap_Brown",
      "components": {
        "Components": {
          "FarmingBlock": {
            "LastTickGameTime": "0001-01-03T12:00:00Z"
          }
        }
      }
    },
    {
      "x": -20,
      "y": 24,
      "z": -3,
      "name": "Rock_Stone"
    },
    {
      "x": -20,
      "y": 25,
      "z": -3,
      "name": "Rock_Stone"
    },
    {
      "x": -20,
      "y": 26,
      "z": -3,
      "name": "Rock_Stone"
    },
    {
      "x": -20,
      "y": 27,
      "z": -3,
      "name": "Plant_Crop_Mushroom_Block_Brown"
    },
    {
      "x": -20,
      "y": 28,
      "z": -3,
      "name": "Plant_Crop_Mushroom_Block_Brown"
    },
    {
      "x": -20,
      "y": 29,
      "z": -3,
      "name": "Plant_Moss_Rug_Yellow"
    },
    {
      "x": -20,
      "y": 23,
      "z": -2,
      "name": "Rock_Stone"
    },
    {
      "x": -20,
      "y": 24,
      "z": -2,
      "name": "Rock_Stone"
    },
    {
      "x": -20,
      "y": 25,
      "z": -2,
      "name": "Rock_Stone"
    },
    {
      "x": -20,
      "y": 26,
      "z": -2,
      "name": "Plant_Crop_Mushroom_Block_Brown"
    },
    {
      "x": -20,
      "y": 27,
      "z": -2,
      "name": "Plant_Crop_Mushroom_Block_Brown"
    },
    {
      "x": -20,
      "y": 28,
      "z": -2,
      "name": "Plant_Moss_Rug_Yellow"
    },
    {
      "x": -20,
      "y": 22,
      "z": -1,
      "name": "Rock_Stone"
    },
    {
      "x": -20,
      "y": 23,
      "z": -1,
      "name": "Rock_Stone"
    },
    {
      "x": -20,
      "y": 24,
      "z": -1,
      "name": "Rock_Stone"
    },
    {
      "x": -20,
      "y": 25,
      "z": -1,
      "name": "Rock_Stone"
    },
    {
      "x": -20,
      "y": 26,
      "z": -1,
      "name": "Rock_Stone_Mossy"
    },
    {
      "x": -20,
      "y": 27,
      "z": -1,
      "name": "Plant_Crop_Mushroom_Block_Brown"
    },
    {
      "x": -20,
      "y": 28,
      "z": -1,
      "name": "Plant_Crop_Mushroom_Block_Brown"
    },
    {
      "x": -20,
      "y": 29,
      "z": -1,
      "name": "Plant_Crop_Mushroom_Block_Brown"
    },
    {
      "x": -20,
      "y": 22,
      "z": 0,
      "name": "Rock_Stone"
    },
    {
      "x": -20,
      "y": 23,
      "z": 0,
      "name": "Rock_Stone"
    },
    {
      "x": -20,
      "y": 24,
      "z": 0,
      "name": "Rock_Stone"
    },
    {
      "x": -20,
      "y": 25,
      "z": 0,
      "name": "Rock_Stone"
    },
    {
      "x": -20,
      "y": 26,
      "z": 0,
      "name": "Rock_Stone"
    },
    {
      "x": -20,
      "y": 27,
      "z": 0,
      "name": "Rock_Stone"
    },
    {
      "x": -20,
      "y": 28,
      "z": 0,
      "name": "Plant_Crop_Mushroom_Block_Brown"
    },
    {
      "x": -20,
      "y": 29,
      "z": 0,
      "name": "Plant_Crop_Mushroom_Block_Brown"
    },
    {
      "x": -20,
      "y": 30,
      "z": 0,
      "name": "Plant_Crop_Mushroom_Block_Brown"
    },
    {
      "x": -20,
      "y": 31,
      "z": 0,
      "name": "Plant_Moss_Rug_Yellow"
    },
    {
      "x": -20,
      "y": 22,
      "z": 1,
      "name": "Rock_Stone"
    },
    {
      "x": -20,
      "y": 23,
      "z": 1,
      "name": "Rock_Stone"
    },
    {
      "x": -20,
      "y": 24,
      "z": 1,
      "name": "Rock_Stone"
    },
    {
      "x": -20,
      "y": 25,
      "z": 1,
      "name": "Rock_Stone"
    },
    {
      "x": -20,
      "y": 26,
      "z": 1,
      "name": "Rock_Stone"
    },
    {
      "x": -20,
      "y": 27,
      "z": 1,
      "name": "Rock_Stone"
    },
    {
      "x": -20,
      "y": 28,
      "z": 1,
      "name": "Plant_Crop_Mushroom_Block_Brown"
    },
    {
      "x": -20,
      "y": 29,
      "z": 1,
      "name": "Plant_Crop_Mushroom_Block_Brown"
    },
    {
      "x": -20,
      "y": 30,
      "z": 1,
      "name": "Plant_Crop_Mushroom_Block_Brown"
    },
    {
      "x": -20,
      "y": 31,
      "z": 1,
      "name": "Plant_Moss_Rug_Yellow"
    },
    {
      "x": -20,
      "y": 23,
      "z": 2,
      "name": "Rock_Stone"
    },
    {
      "x": -20,
      "y": 24,
      "z": 2,
      "name": "Rock_Stone"
    },
    {
      "x": -20,
      "y": 25,
      "z": 2,
      "name": "Rock_Stone"
    },
    {
      "x": -20,
      "y": 26,
      "z": 2,
      "name": "Rock_Stone"
    },
    {
      "x": -20,
      "y": 27,
      "z": 2,
      "name": "Rock_Stone"
    },
    {
      "x": -20,
      "y": 28,
      "z": 2,
      "name": "Plant_Crop_Mushroom_Block_Brown"
    },
    {
      "x": -20,
      "y": 29,
      "z": 2,
      "name": "Plant_Crop_Mushroom_Block_Brown"
    },
    {
      "x": -20,
      "y": 30,
      "z": 2,
      "name": "Plant_Crop_Mushroom_Block_Brown"
    },
    {
      "x": -20,
      "y": 22,
      "z": 3,
      "name": "Rock_Stone"
    },
    {
      "x": -20,
      "y": 23,
      "z": 3,
      "name": "Rock_Stone"
    },
    {
      "x": -20,
      "y": 24,
      "z": 3,
      "name": "Ore_Gold_Stone"
    },
    {
      "x": -20,
      "y": 25,
      "z": 3,
      "name": "Ore_Gold_Stone"
    },
    {
      "x": -20,
      "y": 26,
      "z": 3,
      "name": "Ore_Copper_Stone"
    },
    {
      "x": -20,
      "y": 27,
      "z": 3,
      "name": "Plant_Crop_Mushroom_Block_Brown"
    },
    {
      "x": -20,
      "y": 28,
      "z": 3,
      "name": "Plant_Crop_Mushroom_Block_Brown"
    },
    {
      "x": -20,
      "y": 29,
      "z": 3,
      "name": "Plant_Crop_Mushroom_Block_Brown"
    },
    {
      "x": -20,
      "y": 21,
      "z": 4,
      "name": "Rock_Stone"
    },
    {
      "x": -20,
      "y": 22,
      "z": 4,
      "name": "Rock_Stone"
    },
    {
      "x": -20,
      "y": 23,
      "z": 4,
      "name": "Rock_Stone"
    },
    {
      "x": -20,
      "y": 24,
      "z": 4,
      "name": "Ore_Gold_Stone"
    },
    {
      "x": -20,
      "y": 25,
      "z": 4,
      "name": "Rock_Stone"
    },
    {
      "x": -20,
      "y": 26,
      "z": 4,
      "name": "Plant_Crop_Mushroom_Block_Brown"
    },
    {
      "x": -20,
      "y": 27,
      "z": 4,
      "name": "Plant_Crop_Mushroom_Block_Brown"
    },
    {
      "x": -20,
      "y": 28,
      "z": 4,
      "name": "Plant_Crop_Mushroom_Cap_Brown",
      "components": {
        "Components": {
          "FarmingBlock": {
            "LastTickGameTime": "0001-01-03T12:00:00Z"
          }
        }
      }
    },
    {
      "x": -20,
      "y": 16,
      "z": 5,
      "name": "Rock_Stone_Stalactite_Large",
      "filler": 31744,
      "rotation": 8
    },
    {
      "x": -20,
      "y": 17,
      "z": 5,
      "name": "Rock_Stone_Stalactite_Large",
      "rotation": 8
    },
    {
      "x": -20,
      "y": 18,
      "z": 5,
      "name": "Rock_Stone"
    },
    {
      "x": -20,
      "y": 19,
      "z": 5,
      "name": "Rock_Stone"
    },
    {
      "x": -20,
      "y": 20,
      "z": 5,
      "name": "Rock_Stone"
    },
    {
      "x": -20,
      "y": 21,
      "z": 5,
      "name": "Rock_Stone"
    },
    {
      "x": -20,
      "y": 22,
      "z": 5,
      "name": "Rock_Stone"
    },
    {
      "x": -20,
      "y": 23,
      "z": 5,
      "name": "Rock_Stone"
    },
    {
      "x": -20,
      "y": 24,
      "z": 5,
      "name": "Rock_Stone"
    },
    {
      "x": -20,
      "y": 25,
      "z": 5,
      "name": "Rock_Stone_Mossy"
    },
    {
      "x": -20,
      "y": 26,
      "z": 5,
      "name": "Plant_Crop_Mushroom_Block_Brown"
    },
    {
      "x": -20,
      "y": 27,
      "z": 5,
      "name": "Plant_Crop_Mushroom_Block_Brown"
    },
    {
      "x": -20,
      "y": 28,
      "z": 5,
      "name": "Plant_Crop_Mushroom_Glowing_Orange"
    },
    {
      "x": -20,
      "y": 20,
      "z": 6,
      "name": "Rock_Stone"
    },
    {
      "x": -20,
      "y": 21,
      "z": 6,
      "name": "Rock_Stone"
    },
    {
      "x": -20,
      "y": 22,
      "z": 6,
      "name": "Rock_Stone"
    },
    {
      "x": -20,
      "y": 23,
      "z": 6,
      "name": "Rock_Stone"
    },
    {
      "x": -20,
      "y": 24,
      "z": 6,
      "name": "Rock_Stone"
    },
    {
      "x": -20,
      "y": 25,
      "z": 6,
      "name": "Rock_Stone"
    },
    {
      "x": -20,
      "y": 26,
      "z": 6,
      "name": "Plant_Crop_Mushroom_Block_Brown"
    },
    {
      "x": -20,
      "y": 27,
      "z": 6,
      "name": "Plant_Crop_Mushroom_Block_Brown"
    },
    {
      "x": -20,
      "y": 28,
      "z": 6,
      "name": "Plant_Moss_Rug_Yellow"
    },
    {
      "x": -20,
      "y": 21,
      "z": 7,
      "name": "Rock_Stone"
    },
    {
      "x": -20,
      "y": 22,
      "z": 7,
      "name": "Rock_Stone"
    },
    {
      "x": -20,
      "y": 23,
      "z": 7,
      "name": "Rock_Stone"
    },
    {
      "x": -20,
      "y": 24,
      "z": 7,
      "name": "Rock_Stone"
    },
    {
      "x": -20,
      "y": 25,
      "z": 7,
      "name": "Plant_Crop_Mushroom_Block_Brown"
    },
    {
      "x": -20,
      "y": 26,
      "z": 7,
      "name": "Plant_Crop_Mushroom_Block_Brown"
    },
    {
      "x": -20,
      "y": 27,
      "z": 7,
      "name": "Plant_Moss_Rug_Yellow"
    },
    {
      "x": -20,
      "y": 22,
      "z": 8,
      "name": "Rock_Stone"
    },
    {
      "x": -20,
      "y": 23,
      "z": 8,
      "name": "Rock_Stone"
    },
    {
      "x": -20,
      "y": 24,
      "z": 8,
      "name": "Rock_Stone"
    },
    {
      "x": -20,
      "y": 25,
      "z": 8,
      "name": "Rock_Stone_Mossy"
    },
    {
      "x": -20,
      "y": 26,
      "z": 8,
      "name": "Plant_Crop_Mushroom_Block_Brown"
    },
    {
      "x": -20,
      "y": 27,
      "z": 8,
      "name": "Plant_Crop_Mushroom_Block_Brown"
    },
    {
      "x": -20,
      "y": 28,
      "z": 8,
      "name": "Plant_Crop_Mushroom_Common_Brown",
      "components": {
        "Components": {
          "FarmingBlock": {
            "LastTickGameTime": "0001-01-03T12:00:00Z"
          }
        }
      }
    },
    {
      "x": -20,
      "y": 23,
      "z": 9,
      "name": "Rock_Stone"
    },
    {
      "x": -20,
      "y": 24,
      "z": 9,
      "name": "Rock_Stone"
    },
    {
      "x": -20,
      "y": 25,
      "z": 9,
      "name": "Rock_Stone"
    },
    {
      "x": -20,
      "y": 26,
      "z": 9,
      "name": "Plant_Crop_Mushroom_Block_Brown"
    },
    {
      "x": -20,
      "y": 27,
      "z": 9,
      "name": "Plant_Crop_Mushroom_Block_Brown"
    },
    {
      "x": -20,
      "y": 28,
      "z": 9,
      "name": "Plant_Crop_Mushroom_Common_Brown",
      "components": {
        "Components": {
          "FarmingBlock": {
            "LastTickGameTime": "0001-01-03T12:00:00Z"
          }
        }
      }
    },
    {
      "x": -20,
      "y": 28,
      "z": 10,
      "name": "Plant_Moss_Rug_Yellow"
    },
    {
      "x": -19,
      "y": 25,
      "z": -5,
      "name": "Rock_Stone"
    },
    {
      "x": -19,
      "y": 26,
      "z": -5,
      "name": "Ore_Gold_Stone"
    },
    {
      "x": -19,
      "y": 27,
      "z": -5,
      "name": "Rock_Stone"
    },
    {
      "x": -19,
      "y": 28,
      "z": -5,
      "name": "Plant_Crop_Mushroom_Block_Brown"
    },
    {
      "x": -19,
      "y": 29,
      "z": -5,
      "name": "Plant_Crop_Mushroom_Block_Brown"
    },
    {
      "x": -19,
      "y": 30,
      "z": -5,
      "name": "Plant_Moss_Rug_Yellow"
    },
    {
      "x": -19,
      "y": 21,
      "z": -4,
      "name": "Rock_Stone_Stalactite_Large",
      "filler": 31744,
      "rotation": 8
    },
    {
      "x": -19,
      "y": 22,
      "z": -4,
      "name": "Rock_Stone_Stalactite_Large",
      "rotation": 8
    },
    {
      "x": -19,
      "y": 23,
      "z": -4,
      "name": "Rock_Stone"
    },
    {
      "x": -19,
      "y": 24,
      "z": -4,
      "name": "Rock_Stone"
    },
    {
      "x": -19,
      "y": 25,
      "z": -4,
      "name": "Rock_Stone"
    },
    {
      "x": -19,
      "y": 26,
      "z": -4,
      "name": "Ore_Gold_Stone"
    },
    {
      "x": -19,
      "y": 27,
      "z": -4,
      "name": "Rock_Stone"
    },
    {
      "x": -19,
      "y": 28,
      "z": -4,
      "name": "Plant_Crop_Mushroom_Block_Brown"
    },
    {
      "x": -19,
      "y": 29,
      "z": -4,
      "name": "Plant_Crop_Mushroom_Block_Brown"
    },
    {
      "x": -19,
      "y": 30,
      "z": -4,
      "name": "Plant_Crop_Mushroom_Glowing_Orange"
    },
    {
      "x": -19,
      "y": 24,
      "z": -3,
      "name": "Rock_Stone"
    },
    {
      "x": -19,
      "y": 25,
      "z": -3,
      "name": "Rock_Stone"
    },
    {
      "x": -19,
      "y": 26,
      "z": -3,
      "name": "Ore_Gold_Stone"
    },
    {
      "x": -19,
      "y": 27,
      "z": -3,
      "name": "Ore_Copper_Stone"
    },
    {
      "x": -19,
      "y": 28,
      "z": -3,
      "name": "Plant_Crop_Mushroom_Block_Brown"
    },
    {
      "x": -19,
      "y": 29,
      "z": -3,
      "name": "Plant_Crop_Mushroom_Block_Brown"
    },
    {
      "x": -19,
      "y": 30,
      "z": -3,
      "name": "Plant_Moss_Rug_Yellow"
    },
    {
      "x": -19,
      "y": 23,
      "z": -2,
      "name": "Rock_Stone"
    },
    {
      "x": -19,
      "y": 24,
      "z": -2,
      "name": "Rock_Stone"
    },
    {
      "x": -19,
      "y": 25,
      "z": -2,
      "name": "Rock_Stone"
    },
    {
      "x": -19,
      "y": 26,
      "z": -2,
      "name": "Ore_Copper_Stone"
    },
    {
      "x": -19,
      "y": 27,
      "z": -2,
      "name": "Plant_Crop_Mushroom_Block_Brown"
    },
    {
      "x": -19,
      "y": 28,
      "z": -2,
      "name": "Plant_Crop_Mushroom_Block_Brown"
    },
    {
      "x": -19,
      "y": 29,
      "z": -2,
      "name": "Plant_Crop_Mushroom_Cap_Brown",
      "components": {
        "Components": {
          "FarmingBlock": {
            "LastTickGameTime": "0001-01-03T12:00:00Z"
          }
        }
      }
    },
    {
      "x": -19,
      "y": 22,
      "z": -1,
      "name": "Plant_Crop_Mushroom_Block_Brown"
    },
    {
      "x": -19,
      "y": 23,
      "z": -1,
      "name": "Plant_Crop_Mushroom_Block_Brown"
    },
    {
      "x": -19,
      "y": 24,
      "z": -1,
      "name": "Plant_Crop_Mushroom_Block_Brown"
    },
    {
      "x": -19,
      "y": 26,
      "z": -1,
      "name": "Ore_Gold_Stone"
    },
    {
      "x": -19,
      "y": 27,
      "z": -1,
      "name": "Ore_Copper_Stone"
    },
    {
      "x": -19,
      "y": 28,
      "z": -1,
      "name": "Plant_Crop_Mushroom_Block_Brown"
    },
    {
      "x": -19,
      "y": 29,
      "z": -1,
      "name": "Plant_Crop_Mushroom_Block_Brown"
    },
    {
      "x": -19,
      "y": 30,
      "z": -1,
      "name": "Rock_Stone"
    },
    {
      "x": -19,
      "y": 31,
      "z": -1,
      "name": "Plant_Moss_Rug_Yellow"
    },
    {
      "x": -19,
      "y": 21,
      "z": 0,
      "name": "Rock_Stone"
    },
    {
      "x": -19,
      "y": 22,
      "z": 0,
      "name": "Rock_Stone"
    },
    {
      "x": -19,
      "y": 23,
      "z": 0,
      "name": "Rock_Stone"
    },
    {
      "x": -19,
      "y": 24,
      "z": 0,
      "name": "Rock_Stone"
    },
    {
      "x": -19,
      "y": 25,
      "z": 0,
      "name": "Rock_Stone"
    },
    {
      "x": -19,
      "y": 26,
      "z": 0,
      "name": "Rock_Stone"
    },
    {
      "x": -19,
      "y": 27,
      "z": 0,
      "name": "Rock_Stone"
    },
    {
      "x": -19,
      "y": 28,
      "z": 0,
      "name": "Plant_Crop_Mushroom_Block_Brown"
    },
    {
      "x": -19,
      "y": 29,
      "z": 0,
      "name": "Plant_Crop_Mushroom_Block_Brown"
    },
    {
      "x": -19,
      "y": 30,
      "z": 0,
      "name": "Plant_Crop_Mushroom_Block_Brown"
    },
    {
      "x": -19,
      "y": 31,
      "z": 0,
      "name": "Plant_Moss_Rug_Yellow"
    },
    {
      "x": -19,
      "y": 21,
      "z": 1,
      "name": "Rock_Stone"
    },
    {
      "x": -19,
      "y": 22,
      "z": 1,
      "name": "Rock_Stone"
    },
    {
      "x": -19,
      "y": 23,
      "z": 1,
      "name": "Rock_Stone"
    },
    {
      "x": -19,
      "y": 24,
      "z": 1,
      "name": "Rock_Stone"
    },
    {
      "x": -19,
      "y": 25,
      "z": 1,
      "name": "Rock_Stone"
    },
    {
      "x": -19,
      "y": 26,
      "z": 1,
      "name": "Rock_Stone"
    },
    {
      "x": -19,
      "y": 27,
      "z": 1,
      "name": "Rock_Stone"
    },
    {
      "x": -19,
      "y": 28,
      "z": 1,
      "name": "Plant_Crop_Mushroom_Block_Brown"
    },
    {
      "x": -19,
      "y": 29,
      "z": 1,
      "name": "Plant_Crop_Mushroom_Block_Brown"
    },
    {
      "x": -19,
      "y": 30,
      "z": 1,
      "name": "Plant_Crop_Mushroom_Block_Brown"
    },
    {
      "x": -19,
      "y": 21,
      "z": 2,
      "name": "Rock_Stone"
    },
    {
      "x": -19,
      "y": 22,
      "z": 2,
      "name": "Rock_Stone"
    },
    {
      "x": -19,
      "y": 23,
      "z": 2,
      "name": "Rock_Stone"
    },
    {
      "x": -19,
      "y": 24,
      "z": 2,
      "name": "Rock_Stone"
    },
    {
      "x": -19,
      "y": 25,
      "z": 2,
      "name": "Rock_Stone"
    },
    {
      "x": -19,
      "y": 26,
      "z": 2,
      "name": "Rock_Stone"
    },
    {
      "x": -19,
      "y": 27,
      "z": 2,
      "name": "Rock_Stone"
    },
    {
      "x": -19,
      "y": 28,
      "z": 2,
      "name": "Plant_Crop_Mushroom_Block_Brown"
    },
    {
      "x": -19,
      "y": 29,
      "z": 2,
      "name": "Plant_Crop_Mushroom_Block_Brown"
    },
    {
      "x": -19,
      "y": 30,
      "z": 2,
      "name": "Plant_Crop_Mushroom_Block_Brown"
    },
    {
      "x": -19,
      "y": 20,
      "z": 3,
      "name": "Rock_Stone"
    },
    {
      "x": -19,
      "y": 21,
      "z": 3,
      "name": "Rock_Stone"
    },
    {
      "x": -19,
      "y": 22,
      "z": 3,
      "name": "Rock_Stone"
    },
    {
      "x": -19,
      "y": 23,
      "z": 3,
      "name": "Rock_Stone"
    },
    {
      "x": -19,
      "y": 24,
      "z": 3,
      "name": "Ore_Gold_Stone"
    },
    {
      "x": -19,
      "y": 25,
      "z": 3,
      "name": "Ore_Gold_Stone"
    },
    {
      "x": -19,
      "y": 26,
      "z": 3,
      "name": "Rock_Stone"
    },
    {
      "x": -19,
      "y": 27,
      "z": 3,
      "name": "Ore_Copper_Stone"
    },
    {
      "x": -19,
      "y": 28,
      "z": 3,
      "name": "Plant_Crop_Mushroom_Block_Brown"
    },
    {
      "x": -19,
      "y": 29,
      "z": 3,
      "name": "Plant_Crop_Mushroom_Block_Brown"
    },
    {
      "x": -19,
      "y": 30,
      "z": 3,
      "name": "Plant_Crop_Mushroom_Block_Brown"
    },
    {
      "x": -19,
      "y": 19,
      "z": 4,
      "name": "Rock_Stone"
    },
    {
      "x": -19,
      "y": 20,
      "z": 4,
      "name": "Rock_Stone"
    },
    {
      "x": -19,
      "y": 21,
      "z": 4,
      "name": "Rock_Stone"
    },
    {
      "x": -19,
      "y": 22,
      "z": 4,
      "name": "Rock_Stone"
    },
    {
      "x": -19,
      "y": 23,
      "z": 4,
      "name": "Rock_Stone"
    },
    {
      "x": -19,
      "y": 24,
      "z": 4,
      "name": "Rock_Stone"
    },
    {
      "x": -19,
      "y": 25,
      "z": 4,
      "name": "Rock_Stone"
    },
    {
      "x": -19,
      "y": 26,
      "z": 4,
      "name": "Rock_Stone"
    },
    {
      "x": -19,
      "y": 27,
      "z": 4,
      "name": "Plant_Crop_Mushroom_Block_Brown"
    },
    {
      "x": -19,
      "y": 28,
      "z": 4,
      "name": "Plant_Crop_Mushroom_Block_Brown"
    },
    {
      "x": -19,
      "y": 29,
      "z": 4,
      "name": "Plant_Crop_Mushroom_Block_Brown"
    },
    {
      "x": -19,
      "y": 15,
      "z": 5,
      "name": "Rock_Stone"
    },
    {
      "x": -19,
      "y": 16,
      "z": 5,
      "name": "Rock_Stone"
    },
    {
      "x": -19,
      "y": 17,
      "z": 5,
      "name": "Rock_Stone"
    },
    {
      "x": -19,
      "y": 18,
      "z": 5,
      "name": "Rock_Stone"
    },
    {
      "x": -19,
      "y": 19,
      "z": 5,
      "name": "Rock_Stone"
    },
    {
      "x": -19,
      "y": 20,
      "z": 5,
      "name": "Rock_Stone"
    },
    {
      "x": -19,
      "y": 21,
      "z": 5,
      "name": "Rock_Stone"
    },
    {
      "x": -19,
      "y": 22,
      "z": 5,
      "name": "Rock_Stone"
    },
    {
      "x": -19,
      "y": 23,
      "z": 5,
      "name": "Rock_Stone"
    },
    {
      "x": -19,
      "y": 24,
      "z": 5,
      "name": "Rock_Stone"
    },
    {
      "x": -19,
      "y": 25,
      "z": 5,
      "name": "Rock_Stone"
    },
    {
      "x": -19,
      "y": 26,
      "z": 5,
      "name": "Plant_Crop_Mushroom_Block_Brown"
    },
    {
      "x": -19,
      "y": 27,
      "z": 5,
      "name": "Plant_Crop_Mushroom_Block_Brown"
    },
    {
      "x": -19,
      "y": 28,
      "z": 5,
      "name": "Plant_Crop_Mushroom_Cap_Brown",
      "components": {
        "Components": {
          "FarmingBlock": {
            "LastTickGameTime": "0001-01-03T12:00:00Z"
          }
        }
      }
    },
    {
      "x": -19,
      "y": 36,
      "z": 5,
      "name": "Plant_Crop_Mushroom_Block_Brown"
    },
    {
      "x": -19,
      "y": 16,
      "z": 6,
      "name": "Rock_Stone"
    },
    {
      "x": -19,
      "y": 17,
      "z": 6,
      "name": "Rock_Stone"
    },
    {
      "x": -19,
      "y": 18,
      "z": 6,
      "name": "Rock_Stone"
    },
    {
      "x": -19,
      "y": 19,
      "z": 6,
      "name": "Rock_Stone"
    },
    {
      "x": -19,
      "y": 20,
      "z": 6,
      "name": "Rock_Stone"
    },
    {
      "x": -19,
      "y": 21,
      "z": 6,
      "name": "Rock_Stone"
    },
    {
      "x": -19,
      "y": 22,
      "z": 6,
      "name": "Rock_Stone"
    },
    {
      "x": -19,
      "y": 23,
      "z": 6,
      "name": "Rock_Stone"
    },
    {
      "x": -19,
      "y": 24,
      "z": 6,
      "name": "Rock_Stone"
    },
    {
      "x": -19,
      "y": 25,
      "z": 6,
      "name": "Ore_Copper_Stone"
    },
    {
      "x": -19,
      "y": 26,
      "z": 6,
      "name": "Plant_Crop_Mushroom_Block_Brown"
    },
    {
      "x": -19,
      "y": 27,
      "z": 6,
      "name": "Plant_Crop_Mushroom_Block_Brown"
    },
    {
      "x": -19,
      "y": 28,
      "z": 6,
      "name": "Plant_Crop_Mushroom_Common_Brown",
      "components": {
        "Components": {
          "FarmingBlock": {
            "LastTickGameTime": "0001-01-03T12:00:00Z"
          }
        }
      }
    },
    {
      "x": -19,
      "y": 36,
      "z": 6,
      "name": "Plant_Crop_Mushroom_Block_Brown"
    },
    {
      "x": -19,
      "y": 19,
      "z": 7,
      "name": "Rock_Stone"
    },
    {
      "x": -19,
      "y": 20,
      "z": 7,
      "name": "Rock_Stone"
    },
    {
      "x": -19,
      "y": 21,
      "z": 7,
      "name": "Rock_Stone"
    },
    {
      "x": -19,
      "y": 22,
      "z": 7,
      "name": "Rock_Stone"
    },
    {
      "x": -19,
      "y": 23,
      "z": 7,
      "name": "Rock_Stone"
    },
    {
      "x": -19,
      "y": 24,
      "z": 7,
      "name": "Rock_Stone_Mossy"
    },
    {
      "x": -19,
      "y": 25,
      "z": 7,
      "name": "Plant_Crop_Mushroom_Block_Brown"
    },
    {
      "x": -19,
      "y": 26,
      "z": 7,
      "name": "Plant_Crop_Mushroom_Block_Brown"
    },
    {
      "x": -19,
      "y": 27,
      "z": 7,
      "name": "Plant_Crop_Mushroom_Common_Brown",
      "components": {
        "Components": {
          "FarmingBlock": {
            "LastTickGameTime": "0001-01-03T12:00:00Z"
          }
        }
      }
    },
    {
      "x": -19,
      "y": 36,
      "z": 7,
      "name": "Plant_Crop_Mushroom_Block_Brown"
    },
    {
      "x": -19,
      "y": 18,
      "z": 8,
      "name": "Rock_Stone_Stalactite_Large",
      "filler": 31744,
      "rotation": 8
    },
    {
      "x": -19,
      "y": 19,
      "z": 8,
      "name": "Rock_Stone_Stalactite_Large",
      "rotation": 8
    },
    {
      "x": -19,
      "y": 20,
      "z": 8,
      "name": "Rock_Stone"
    },
    {
      "x": -19,
      "y": 21,
      "z": 8,
      "name": "Rock_Stone"
    },
    {
      "x": -19,
      "y": 22,
      "z": 8,
      "name": "Rock_Stone"
    },
    {
      "x": -19,
      "y": 23,
      "z": 8,
      "name": "Rock_Stone"
    },
    {
      "x": -19,
      "y": 24,
      "z": 8,
      "name": "Rock_Stone"
    },
    {
      "x": -19,
      "y": 25,
      "z": 8,
      "name": "Rock_Stone"
    },
    {
      "x": -19,
      "y": 26,
      "z": 8,
      "name": "Plant_Crop_Mushroom_Block_Brown"
    },
    {
      "x": -19,
      "y": 27,
      "z": 8,
      "name": "Plant_Crop_Mushroom_Block_Brown"
    },
    {
      "x": -19,
      "y": 28,
      "z": 8,
      "name": "Plant_Crop_Mushroom_Glowing_Orange"
    },
    {
      "x": -19,
      "y": 21,
      "z": 9,
      "name": "Rock_Stone"
    },
    {
      "x": -19,
      "y": 22,
      "z": 9,
      "name": "Rock_Stone"
    },
    {
      "x": -19,
      "y": 23,
      "z": 9,
      "name": "Rock_Stone"
    },
    {
      "x": -19,
      "y": 24,
      "z": 9,
      "name": "Rock_Stone"
    },
    {
      "x": -19,
      "y": 25,
      "z": 9,
      "name": "Ore_Copper_Stone"
    },
    {
      "x": -19,
      "y": 26,
      "z": 9,
      "name": "Plant_Crop_Mushroom_Block_Brown"
    },
    {
      "x": -19,
      "y": 27,
      "z": 9,
      "name": "Plant_Crop_Mushroom_Block_Brown"
    },
    {
      "x": -19,
      "y": 28,
      "z": 9,
      "name": "Plant_Crop_Mushroom_Common_Brown",
      "components": {
        "Components": {
          "FarmingBlock": {
            "LastTickGameTime": "0001-01-03T12:00:00Z"
          }
        }
      }
    },
    {
      "x": -19,
      "y": 23,
      "z": 10,
      "name": "Rock_Stone"
    },
    {
      "x": -19,
      "y": 24,
      "z": 10,
      "name": "Rock_Stone"
    },
    {
      "x": -19,
      "y": 25,
      "z": 10,
      "name": "Rock_Stone"
    },
    {
      "x": -19,
      "y": 26,
      "z": 10,
      "name": "Plant_Crop_Mushroom_Block_Brown"
    },
    {
      "x": -19,
      "y": 27,
      "z": 10,
      "name": "Plant_Crop_Mushroom_Block_Brown"
    },
    {
      "x": -19,
      "y": 28,
      "z": 10,
      "name": "Plant_Crop_Mushroom_Cap_Brown",
      "components": {
        "Components": {
          "FarmingBlock": {
            "LastTickGameTime": "0001-01-03T12:00:00Z"
          }
        }
      }
    },
    {
      "x": -18,
      "y": 24,
      "z": -5,
      "name": "Rock_Stone"
    },
    {
      "x": -18,
      "y": 25,
      "z": -5,
      "name": "Rock_Stone"
    },
    {
      "x": -18,
      "y": 26,
      "z": -5,
      "name": "Ore_Gold_Stone"
    },
    {
      "x": -18,
      "y": 27,
      "z": -5,
      "name": "Rock_Stone"
    },
    {
      "x": -18,
      "y": 28,
      "z": -5,
      "name": "Plant_Crop_Mushroom_Block_Brown"
    },
    {
      "x": -18,
      "y": 29,
      "z": -5,
      "name": "Plant_Crop_Mushroom_Block_Brown"
    },
    {
      "x": -18,
      "y": 30,
      "z": -5,
      "name": "Plant_Crop_Mushroom_Cap_Brown",
      "components": {
        "Components": {
          "FarmingBlock": {
            "LastTickGameTime": "0001-01-03T12:00:00Z"
          }
        }
      }
    },
    {
      "x": -18,
      "y": 22,
      "z": -4,
      "name": "Rock_Stone"
    },
    {
      "x": -18,
      "y": 23,
      "z": -4,
      "name": "Rock_Stone"
    },
    {
      "x": -18,
      "y": 24,
      "z": -4,
      "name": "Rock_Stone"
    },
    {
      "x": -18,
      "y": 25,
      "z": -4,
      "name": "Rock_Stone"
    },
    {
      "x": -18,
      "y": 26,
      "z": -4,
      "name": "Ore_Gold_Stone"
    },
    {
      "x": -18,
      "y": 27,
      "z": -4,
      "name": "Rock_Stone"
    },
    {
      "x": -18,
      "y": 28,
      "z": -4,
      "name": "Plant_Crop_Mushroom_Block_Brown"
    },
    {
      "x": -18,
      "y": 29,
      "z": -4,
      "name": "Plant_Crop_Mushroom_Block_Brown"
    },
    {
      "x": -18,
      "y": 30,
      "z": -4,
      "name": "Plant_Crop_Mushroom_Glowing_Orange"
    },
    {
      "x": -18,
      "y": 21,
      "z": -3,
      "name": "Rock_Stone"
    },
    {
      "x": -18,
      "y": 22,
      "z": -3,
      "name": "Rock_Stone"
    },
    {
      "x": -18,
      "y": 23,
      "z": -3,
      "name": "Rock_Stone"
    },
    {
      "x": -18,
      "y": 24,
      "z": -3,
      "name": "Rock_Stone"
    },
    {
      "x": -18,
      "y": 25,
      "z": -3,
      "name": "Rock_Stone"
    },
    {
      "x": -18,
      "y": 26,
      "z": -3,
      "name": "Ore_Gold_Stone"
    },
    {
      "x": -18,
      "y": 27,
      "z": -3,
      "name": "Ore_Copper_Stone"
    },
    {
      "x": -18,
      "y": 28,
      "z": -3,
      "name": "Plant_Crop_Mushroom_Block_Brown"
    },
    {
      "x": -18,
      "y": 29,
      "z": -3,
      "name": "Plant_Crop_Mushroom_Block_Brown"
    },
    {
      "x": -18,
      "y": 30,
      "z": -3,
      "name": "Plant_Moss_Rug_Yellow"
    },
    {
      "x": -18,
      "y": 22,
      "z": -2,
      "name": "Rock_Stone"
    },
    {
      "x": -18,
      "y": 23,
      "z": -2,
      "name": "Rock_Stone"
    },
    {
      "x": -18,
      "y": 24,
      "z": -2,
      "name": "Rock_Stone"
    },
    {
      "x": -18,
      "y": 25,
      "z": -2,
      "name": "Rock_Stone"
    },
    {
      "x": -18,
      "y": 26,
      "z": -2,
      "name": "Rock_Stone"
    },
    {
      "x": -18,
      "y": 27,
      "z": -2,
      "name": "Rock_Stone"
    },
    {
      "x": -18,
      "y": 28,
      "z": -2,
      "name": "Rock_Stone"
    },
    {
      "x": -18,
      "y": 29,
      "z": -2,
      "name": "Plant_Crop_Mushroom_Block_Brown"
    },
    {
      "x": -18,
      "y": 30,
      "z": -2,
      "name": "Plant_Crop_Mushroom_Glowing_Orange"
    },
    {
      "x": -18,
      "y": 22,
      "z": -1,
      "name": "Rock_Stone"
    },
    {
      "x": -18,
      "y": 23,
      "z": -1,
      "name": "Rock_Stone"
    },
    {
      "x": -18,
      "y": 24,
      "z": -1,
      "name": "Rock_Stone"
    },
    {
      "x": -18,
      "y": 25,
      "z": -1,
      "name": "Rock_Stone"
    },
    {
      "x": -18,
      "y": 26,
      "z": -1,
      "name": "Rock_Stone"
    },
    {
      "x": -18,
      "y": 27,
      "z": -1,
      "name": "Rock_Stone"
    },
    {
      "x": -18,
      "y": 28,
      "z": -1,
      "name": "Plant_Crop_Mushroom_Block_Brown"
    },
    {
      "x": -18,
      "y": 29,
      "z": -1,
      "name": "Plant_Crop_Mushroom_Block_Brown"
    },
    {
      "x": -18,
      "y": 30,
      "z": -1,
      "name": "Plant_Crop_Mushroom_Cap_Brown",
      "components": {
        "Components": {
          "FarmingBlock": {
            "LastTickGameTime": "0001-01-03T12:00:00Z"
          }
        }
      }
    },
    {
      "x": -18,
      "y": 19,
      "z": 0,
      "name": "Rock_Stone"
    },
    {
      "x": -18,
      "y": 20,
      "z": 0,
      "name": "Rock_Stone"
    },
    {
      "x": -18,
      "y": 21,
      "z": 0,
      "name": "Rock_Stone"
    },
    {
      "x": -18,
      "y": 22,
      "z": 0,
      "name": "Rock_Stone"
    },
    {
      "x": -18,
      "y": 23,
      "z": 0,
      "name": "Rock_Stone"
    },
    {
      "x": -18,
      "y": 24,
      "z": 0,
      "name": "Rock_Stone"
    },
    {
      "x": -18,
      "y": 25,
      "z": 0,
      "name": "Rock_Stone"
    },
    {
      "x": -18,
      "y": 26,
      "z": 0,
      "name": "Rock_Stone"
    },
    {
      "x": -18,
      "y": 27,
      "z": 0,
      "name": "Rock_Stone"
    },
    {
      "x": -18,
      "y": 28,
      "z": 0,
      "name": "Plant_Crop_Mushroom_Block_Brown"
    },
    {
      "x": -18,
      "y": 29,
      "z": 0,
      "name": "Plant_Crop_Mushroom_Block_Brown"
    },
    {
      "x": -18,
      "y": 30,
      "z": 0,
      "name": "Plant_Crop_Mushroom_Block_Brown"
    },
    {
      "x": -18,
      "y": 20,
      "z": 1,
      "name": "Rock_Stone"
    },
    {
      "x": -18,
      "y": 21,
      "z": 1,
      "name": "Rock_Stone"
    },
    {
      "x": -18,
      "y": 22,
      "z": 1,
      "name": "Rock_Stone"
    },
    {
      "x": -18,
      "y": 23,
      "z": 1,
      "name": "Rock_Stone"
    },
    {
      "x": -18,
      "y": 24,
      "z": 1,
      "name": "Rock_Stone"
    },
    {
      "x": -18,
      "y": 25,
      "z": 1,
      "name": "Rock_Stone"
    },
    {
      "x": -18,
      "y": 26,
      "z": 1,
      "name": "Rock_Stone"
    },
    {
      "x": -18,
      "y": 27,
      "z": 1,
      "name": "Rock_Stone_Mossy"
    },
    {
      "x": -18,
      "y": 28,
      "z": 1,
      "name": "Plant_Crop_Mushroom_Block_Brown"
    },
    {
      "x": -18,
      "y": 29,
      "z": 1,
      "name": "Plant_Crop_Mushroom_Block_Brown"
    },
    {
      "x": -18,
      "y": 30,
      "z": 1,
      "name": "Plant_Crop_Mushroom_Block_Brown"
    },
    {
      "x": -18,
      "y": 20,
      "z": 2,
      "name": "Rock_Stone"
    },
    {
      "x": -18,
      "y": 21,
      "z": 2,
      "name": "Rock_Stone"
    },
    {
      "x": -18,
      "y": 22,
      "z": 2,
      "name": "Rock_Stone"
    },
    {
      "x": -18,
      "y": 23,
      "z": 2,
      "name": "Rock_Stone"
    },
    {
      "x": -18,
      "y": 24,
      "z": 2,
      "name": "Rock_Stone"
    },
    {
      "x": -18,
      "y": 25,
      "z": 2,
      "name": "Rock_Stone"
    },
    {
      "x": -18,
      "y": 26,
      "z": 2,
      "name": "Rock_Stone"
    },
    {
      "x": -18,
      "y": 27,
      "z": 2,
      "name": "Rock_Stone"
    },
    {
      "x": -18,
      "y": 28,
      "z": 2,
      "name": "Plant_Crop_Mushroom_Block_Brown"
    },
    {
      "x": -18,
      "y": 29,
      "z": 2,
      "name": "Plant_Crop_Mushroom_Block_Brown"
    },
    {
      "x": -18,
      "y": 30,
      "z": 2,
      "name": "Plant_Crop_Mushroom_Block_Brown"
    },
    {
      "x": -18,
      "y": 19,
      "z": 3,
      "name": "Rock_Stone"
    },
    {
      "x": -18,
      "y": 20,
      "z": 3,
      "name": "Rock_Stone"
    },
    {
      "x": -18,
      "y": 21,
      "z": 3,
      "name": "Rock_Stone"
    },
    {
      "x": -18,
      "y": 22,
      "z": 3,
      "name": "Rock_Stone"
    },
    {
      "x": -18,
      "y": 23,
      "z": 3,
      "name": "Rock_Stone"
    },
    {
      "x": -18,
      "y": 24,
      "z": 3,
      "name": "Rock_Stone"
    },
    {
      "x": -18,
      "y": 25,
      "z": 3,
      "name": "Ore_Gold_Stone"
    },
    {
      "x": -18,
      "y": 26,
      "z": 3,
      "name": "Rock_Stone"
    },
    {
      "x": -18,
      "y": 27,
      "z": 3,
      "name": "Ore_Copper_Stone"
    },
    {
      "x": -18,
      "y": 28,
      "z": 3,
      "name": "Plant_Crop_Mushroom_Block_Brown"
    },
    {
      "x": -18,
      "y": 29,
      "z": 3,
      "name": "Plant_Crop_Mushroom_Block_Brown"
    },
    {
      "x": -18,
      "y": 30,
      "z": 3,
      "name": "Plant_Crop_Mushroom_Block_Brown"
    },
    {
      "x": -18,
      "y": 16,
      "z": 4,
      "name": "Rock_Crystal_Yellow_Medium",
      "rotation": 7
    },
    {
      "x": -18,
      "y": 17,
      "z": 4,
      "name": "Rock_Crystal_Yellow_Medium",
      "rotation": 7
    },
    {
      "x": -18,
      "y": 19,
      "z": 4,
      "name": "Rock_Stone"
    },
    {
      "x": -18,
      "y": 20,
      "z": 4,
      "name": "Rock_Stone"
    },
    {
      "x": -18,
      "y": 21,
      "z": 4,
      "name": "Rock_Stone"
    },
    {
      "x": -18,
      "y": 22,
      "z": 4,
      "name": "Rock_Stone"
    },
    {
      "x": -18,
      "y": 23,
      "z": 4,
      "name": "Rock_Stone"
    },
    {
      "x": -18,
      "y": 24,
      "z": 4,
      "name": "Rock_Stone"
    },
    {
      "x": -18,
      "y": 25,
      "z": 4,
      "name": "Rock_Stone"
    },
    {
      "x": -18,
      "y": 26,
      "z": 4,
      "name": "Rock_Stone"
    },
    {
      "x": -18,
      "y": 27,
      "z": 4,
      "name": "Ore_Copper_Stone"
    },
    {
      "x": -18,
      "y": 28,
      "z": 4,
      "name": "Plant_Crop_Mushroom_Block_Brown"
    },
    {
      "x": -18,
      "y": 29,
      "z": 4,
      "name": "Plant_Crop_Mushroom_Block_Brown"
    },
    {
      "x": -18,
      "y": 30,
      "z": 4,
      "name": "Plant_Crop_Mushroom_Block_Brown"
    },
    {
      "x": -18,
      "y": 36,
      "z": 4,
      "name": "Plant_Crop_Mushroom_Block_Brown"
    },
    {
      "x": -18,
      "y": 18,
      "z": 5,
      "name": "Rock_Stone"
    },
    {
      "x": -18,
      "y": 19,
      "z": 5,
      "name": "Rock_Stone"
    },
    {
      "x": -18,
      "y": 20,
      "z": 5,
      "name": "Rock_Stone"
    },
    {
      "x": -18,
      "y": 21,
      "z": 5,
      "name": "Rock_Stone"
    },
    {
      "x": -18,
      "y": 22,
      "z": 5,
      "name": "Rock_Stone"
    },
    {
      "x": -18,
      "y": 23,
      "z": 5,
      "name": "Rock_Stone"
    },
    {
      "x": -18,
      "y": 24,
      "z": 5,
      "name": "Rock_Stone"
    },
    {
      "x": -18,
      "y": 25,
      "z": 5,
      "name": "Rock_Stone"
    },
    {
      "x": -18,
      "y": 26,
      "z": 5,
      "name": "Rock_Stone"
    },
    {
      "x": -18,
      "y": 27,
      "z": 5,
      "name": "Plant_Crop_Mushroom_Block_Brown"
    },
    {
      "x": -18,
      "y": 28,
      "z": 5,
      "name": "Plant_Crop_Mushroom_Block_Brown"
    },
    {
      "x": -18,
      "y": 29,
      "z": 5,
      "name": "Plant_Crop_Mushroom_Block_Brown"
    },
    {
      "x": -18,
      "y": 36,
      "z": 5,
      "name": "Plant_Crop_Mushroom_Block_Brown"
    },
    {
      "x": -18,
      "y": 37,
      "z": 5,
      "name": "Plant_Crop_Mushroom_Block_Brown"
    },
    {
      "x": -18,
      "y": 18,
      "z": 6,
      "name": "Rock_Stone"
    },
    {
      "x": -18,
      "y": 19,
      "z": 6,
      "name": "Rock_Stone"
    },
    {
      "x": -18,
      "y": 20,
      "z": 6,
      "name": "Rock_Stone"
    },
    {
      "x": -18,
      "y": 21,
      "z": 6,
      "name": "Rock_Stone"
    },
    {
      "x": -18,
      "y": 22,
      "z": 6,
      "name": "Rock_Stone"
    },
    {
      "x": -18,
      "y": 23,
      "z": 6,
      "name": "Rock_Stone"
    },
    {
      "x": -18,
      "y": 24,
      "z": 6,
      "name": "Rock_Stone"
    },
    {
      "x": -18,
      "y": 25,
      "z": 6,
      "name": "Ore_Copper_Stone"
    },
    {
      "x": -18,
      "y": 26,
      "z": 6,
      "name": "Plant_Crop_Mushroom_Block_Brown"
    },
    {
      "x": -18,
      "y": 27,
      "z": 6,
      "name": "Plant_Crop_Mushroom_Block_Brown"
    },
    {
      "x": -18,
      "y": 28,
      "z": 6,
      "name": "Plant_Crop_Mushroom_Block_Brown"
    },
    {
      "x": -18,
      "y": 37,
      "z": 6,
      "name": "Plant_Crop_Mushroom_Block_Brown"
    },
    {
      "x": -18,
      "y": 18,
      "z": 7,
      "name": "Rock_Stone"
    },
    {
      "x": -18,
      "y": 19,
      "z": 7,
      "name": "Rock_Stone"
    },
    {
      "x": -18,
      "y": 20,
      "z": 7,
      "name": "Rock_Stone"
    },
    {
      "x": -18,
      "y": 21,
      "z": 7,
      "name": "Rock_Stone"
    },
    {
      "x": -18,
      "y": 22,
      "z": 7,
      "name": "Rock_Stone"
    },
    {
      "x": -18,
      "y": 23,
      "z": 7,
      "name": "Rock_Stone"
    },
    {
      "x": -18,
      "y": 24,
      "z": 7,
      "name": "Rock_Stone"
    },
    {
      "x": -18,
      "y": 25,
      "z": 7,
      "name": "Rock_Stone"
    },
    {
      "x": -18,
      "y": 26,
      "z": 7,
      "name": "Plant_Crop_Mushroom_Block_Brown"
    },
    {
      "x": -18,
      "y": 27,
      "z": 7,
      "name": "Plant_Crop_Mushroom_Block_Brown"
    },
    {
      "x": -18,
      "y": 28,
      "z": 7,
      "name": "Plant_Crop_Mushroom_Block_Brown"
    },
    {
      "x": -18,
      "y": 29,
      "z": 7,
      "name": "Plant_Crop_Mushroom_Glowing_Orange"
    },
    {
      "x": -18,
      "y": 36,
      "z": 7,
      "name": "Plant_Crop_Mushroom_Block_Brown"
    },
    {
      "x": -18,
      "y": 37,
      "z": 7,
      "name": "Plant_Crop_Mushroom_Block_Brown"
    },
    {
      "x": -18,
      "y": 19,
      "z": 8,
      "name": "Rock_Stone"
    },
    {
      "x": -18,
      "y": 20,
      "z": 8,
      "name": "Rock_Stone"
    },
    {
      "x": -18,
      "y": 21,
      "z": 8,
      "name": "Rock_Stone"
    },
    {
      "x": -18,
      "y": 22,
      "z": 8,
      "name": "Rock_Stone"
    },
    {
      "x": -18,
      "y": 23,
      "z": 8,
      "name": "Rock_Stone"
    },
    {
      "x": -18,
      "y": 24,
      "z": 8,
      "name": "Rock_Stone"
    },
    {
      "x": -18,
      "y": 25,
      "z": 8,
      "name": "Rock_Stone"
    },
    {
      "x": -18,
      "y": 26,
      "z": 8,
      "name": "Plant_Crop_Mushroom_Block_Brown"
    },
    {
      "x": -18,
      "y": 27,
      "z": 8,
      "name": "Plant_Crop_Mushroom_Block_Brown"
    },
    {
      "x": -18,
      "y": 28,
      "z": 8,
      "name": "Plant_Crop_Mushroom_Block_Brown"
    },
    {
      "x": -18,
      "y": 36,
      "z": 8,
      "name": "Plant_Crop_Mushroom_Block_Brown"
    },
    {
      "x": -18,
      "y": 20,
      "z": 9,
      "name": "Rock_Stone"
    },
    {
      "x": -18,
      "y": 21,
      "z": 9,
      "name": "Rock_Stone"
    },
    {
      "x": -18,
      "y": 22,
      "z": 9,
      "name": "Rock_Stone"
    },
    {
      "x": -18,
      "y": 23,
      "z": 9,
      "name": "Rock_Stone"
    },
    {
      "x": -18,
      "y": 24,
      "z": 9,
      "name": "Rock_Stone"
    },
    {
      "x": -18,
      "y": 25,
      "z": 9,
      "name": "Rock_Stone"
    },
    {
      "x": -18,
      "y": 26,
      "z": 9,
      "name": "Plant_Crop_Mushroom_Block_Brown"
    },
    {
      "x": -18,
      "y": 27,
      "z": 9,
      "name": "Plant_Crop_Mushroom_Block_Brown"
    },
    {
      "x": -18,
      "y": 28,
      "z": 9,
      "name": "Plant_Crop_Mushroom_Common_Brown",
      "components": {
        "Components": {
          "FarmingBlock": {
            "LastTickGameTime": "0001-01-03T12:00:00Z"
          }
        }
      }
    },
    {
      "x": -18,
      "y": 22,
      "z": 10,
      "name": "Rock_Stone"
    },
    {
      "x": -18,
      "y": 23,
      "z": 10,
      "name": "Rock_Stone"
    },
    {
      "x": -18,
      "y": 24,
      "z": 10,
      "name": "Rock_Stone"
    },
    {
      "x": -18,
      "y": 25,
      "z": 10,
      "name": "Rock_Stone"
    },
    {
      "x": -18,
      "y": 26,
      "z": 10,
      "name": "Plant_Crop_Mushroom_Block_Brown"
    },
    {
      "x": -18,
      "y": 27,
      "z": 10,
      "name": "Plant_Crop_Mushroom_Block_Brown"
    },
    {
      "x": -18,
      "y": 28,
      "z": 10,
      "name": "Plant_Crop_Mushroom_Common_Brown",
      "components": {
        "Components": {
          "FarmingBlock": {
            "LastTickGameTime": "0001-01-03T12:00:00Z"
          }
        }
      }
    },
    {
      "x": -18,
      "y": 25,
      "z": 11,
      "name": "Rock_Stone"
    },
    {
      "x": -18,
      "y": 26,
      "z": 11,
      "name": "Plant_Crop_Mushroom_Block_Brown"
    },
    {
      "x": -18,
      "y": 27,
      "z": 11,
      "name": "Plant_Crop_Mushroom_Block_Brown"
    },
    {
      "x": -18,
      "y": 28,
      "z": 11,
      "name": "Plant_Moss_Rug_Yellow"
    },
    {
      "x": -17,
      "y": 26,
      "z": -6,
      "name": "Plant_Crop_Mushroom_Block_Brown"
    },
    {
      "x": -17,
      "y": 23,
      "z": -5,
      "name": "Rock_Stone"
    },
    {
      "x": -17,
      "y": 24,
      "z": -5,
      "name": "Rock_Stone"
    },
    {
      "x": -17,
      "y": 25,
      "z": -5,
      "name": "Rock_Stone"
    },
    {
      "x": -17,
      "y": 26,
      "z": -5,
      "name": "Rock_Stone"
    },
    {
      "x": -17,
      "y": 27,
      "z": -5,
      "name": "Rock_Stone"
    },
    {
      "x": -17,
      "y": 28,
      "z": -5,
      "name": "Plant_Crop_Mushroom_Block_Brown"
    },
    {
      "x": -17,
      "y": 29,
      "z": -5,
      "name": "Plant_Crop_Mushroom_Block_Brown"
    },
    {
      "x": -17,
      "y": 30,
      "z": -5,
      "name": "Plant_Crop_Mushroom_Cap_Brown",
      "components": {
        "Components": {
          "FarmingBlock": {
            "LastTickGameTime": "0001-01-03T12:00:00Z"
          }
        }
      }
    },
    {
      "x": -17,
      "y": 22,
      "z": -4,
      "name": "Rock_Stone"
    },
    {
      "x": -17,
      "y": 23,
      "z": -4,
      "name": "Rock_Stone"
    },
    {
      "x": -17,
      "y": 24,
      "z": -4,
      "name": "Rock_Stone"
    },
    {
      "x": -17,
      "y": 25,
      "z": -4,
      "name": "Rock_Stone"
    },
    {
      "x": -17,
      "y": 26,
      "z": -4,
      "name": "Rock_Stone"
    },
    {
      "x": -17,
      "y": 27,
      "z": -4,
      "name": "Rock_Stone"
    },
    {
      "x": -17,
      "y": 28,
      "z": -4,
      "name": "Plant_Crop_Mushroom_Block_Brown"
    },
    {
      "x": -17,
      "y": 29,
      "z": -4,
      "name": "Plant_Crop_Mushroom_Block_Brown"
    },
    {
      "x": -17,
      "y": 30,
      "z": -4,
      "name": "Plant_Crop_Mushroom_Common_Lime",
      "components": {
        "Components": {
          "FarmingBlock": {
            "LastTickGameTime": "0001-01-03T12:00:00Z"
          }
        }
      }
    },
    {
      "x": -17,
      "y": 21,
      "z": -3,
      "name": "Rock_Stone"
    },
    {
      "x": -17,
      "y": 22,
      "z": -3,
      "name": "Rock_Stone"
    },
    {
      "x": -17,
      "y": 23,
      "z": -3,
      "name": "Rock_Stone"
    },
    {
      "x": -17,
      "y": 24,
      "z": -3,
      "name": "Rock_Stone"
    },
    {
      "x": -17,
      "y": 25,
      "z": -3,
      "name": "Rock_Stone"
    },
    {
      "x": -17,
      "y": 26,
      "z": -3,
      "name": "Rock_Stone"
    },
    {
      "x": -17,
      "y": 27,
      "z": -3,
      "name": "Rock_Stone_Mossy"
    },
    {
      "x": -17,
      "y": 28,
      "z": -3,
      "name": "Plant_Crop_Mushroom_Block_Brown"
    },
    {
      "x": -17,
      "y": 29,
      "z": -3,
      "name": "Plant_Crop_Mushroom_Block_Brown"
    },
    {
      "x": -17,
      "y": 30,
      "z": -3,
      "name": "Plant_Crop_Mushroom_Common_Lime",
      "components": {
        "Components": {
          "FarmingBlock": {
            "LastTickGameTime": "0001-01-03T12:00:00Z"
          }
        }
      }
    },
    {
      "x": -17,
      "y": 21,
      "z": -2,
      "name": "Rock_Stone"
    },
    {
      "x": -17,
      "y": 22,
      "z": -2,
      "name": "Rock_Stone"
    },
    {
      "x": -17,
      "y": 23,
      "z": -2,
      "name": "Rock_Stone"
    },
    {
      "x": -17,
      "y": 24,
      "z": -2,
      "name": "Rock_Stone"
    },
    {
      "x": -17,
      "y": 25,
      "z": -2,
      "name": "Rock_Stone"
    },
    {
      "x": -17,
      "y": 26,
      "z": -2,
      "name": "Rock_Stone"
    },
    {
      "x": -17,
      "y": 27,
      "z": -2,
      "name": "Rock_Stone"
    },
    {
      "x": -17,
      "y": 28,
      "z": -2,
      "name": "Plant_Crop_Mushroom_Block_Brown"
    },
    {
      "x": -17,
      "y": 29,
      "z": -2,
      "name": "Plant_Crop_Mushroom_Block_Brown"
    },
    {
      "x": -17,
      "y": 30,
      "z": -2,
      "name": "Plant_Moss_Rug_Yellow"
    },
    {
      "x": -17,
      "y": 20,
      "z": -1,
      "name": "Rock_Stone"
    },
    {
      "x": -17,
      "y": 21,
      "z": -1,
      "name": "Rock_Stone"
    },
    {
      "x": -17,
      "y": 22,
      "z": -1,
      "name": "Rock_Stone"
    },
    {
      "x": -17,
      "y": 23,
      "z": -1,
      "name": "Rock_Stone"
    },
    {
      "x": -17,
      "y": 24,
      "z": -1,
      "name": "Rock_Stone"
    },
    {
      "x": -17,
      "y": 25,
      "z": -1,
      "name": "Rock_Stone"
    },
    {
      "x": -17,
      "y": 26,
      "z": -1,
      "name": "Rock_Stone"
    },
    {
      "x": -17,
      "y": 27,
      "z": -1,
      "name": "Rock_Stone"
    },
    {
      "x": -17,
      "y": 28,
      "z": -1,
      "name": "Rock_Stone"
    },
    {
      "x": -17,
      "y": 29,
      "z": -1,
      "name": "Plant_Crop_Mushroom_Block_Brown"
    },
    {
      "x": -17,
      "y": 30,
      "z": -1,
      "name": "Plant_Crop_Mushroom_Block_Brown"
    },
    {
      "x": -17,
      "y": 31,
      "z": -1,
      "name": "Plant_Crop_Mushroom_Glowing_Orange"
    },
    {
      "x": -17,
      "y": 18,
      "z": 0,
      "name": "Rock_Stone"
    },
    {
      "x": -17,
      "y": 19,
      "z": 0,
      "name": "Rock_Stone"
    },
    {
      "x": -17,
      "y": 20,
      "z": 0,
      "name": "Rock_Stone"
    },
    {
      "x": -17,
      "y": 21,
      "z": 0,
      "name": "Rock_Stone"
    },
    {
      "x": -17,
      "y": 22,
      "z": 0,
      "name": "Rock_Stone"
    },
    {
      "x": -17,
      "y": 23,
      "z": 0,
      "name": "Rock_Stone"
    },
    {
      "x": -17,
      "y": 24,
      "z": 0,
      "name": "Rock_Stone"
    },
    {
      "x": -17,
      "y": 25,
      "z": 0,
      "name": "Rock_Stone"
    },
    {
      "x": -17,
      "y": 26,
      "z": 0,
      "name": "Rock_Stone"
    },
    {
      "x": -17,
      "y": 27,
      "z": 0,
      "name": "Rock_Stone"
    },
    {
      "x": -17,
      "y": 28,
      "z": 0,
      "name": "Plant_Crop_Mushroom_Block_Brown"
    },
    {
      "x": -17,
      "y": 29,
      "z": 0,
      "name": "Plant_Crop_Mushroom_Block_Brown"
    },
    {
      "x": -17,
      "y": 30,
      "z": 0,
      "name": "Plant_Crop_Mushroom_Block_Brown"
    },
    {
      "x": -17,
      "y": 20,
      "z": 1,
      "name": "Rock_Stone"
    },
    {
      "x": -17,
      "y": 21,
      "z": 1,
      "name": "Rock_Stone"
    },
    {
      "x": -17,
      "y": 22,
      "z": 1,
      "name": "Rock_Stone"
    },
    {
      "x": -17,
      "y": 23,
      "z": 1,
      "name": "Rock_Stone"
    },
    {
      "x": -17,
      "y": 24,
      "z": 1,
      "name": "Rock_Stone"
    },
    {
      "x": -17,
      "y": 25,
      "z": 1,
      "name": "Rock_Stone"
    },
    {
      "x": -17,
      "y": 26,
      "z": 1,
      "name": "Rock_Stone"
    },
    {
      "x": -17,
      "y": 27,
      "z": 1,
      "name": "Rock_Stone"
    },
    {
      "x": -17,
      "y": 28,
      "z": 1,
      "name": "Plant_Crop_Mushroom_Block_Brown"
    },
    {
      "x": -17,
      "y": 29,
      "z": 1,
      "name": "Plant_Crop_Mushroom_Block_Brown"
    },
    {
      "x": -17,
      "y": 30,
      "z": 1,
      "name": "Plant_Crop_Mushroom_Block_Brown"
    },
    {
      "x": -17,
      "y": 19,
      "z": 2,
      "name": "Rock_Stone"
    },
    {
      "x": -17,
      "y": 20,
      "z": 2,
      "name": "Rock_Stone"
    },
    {
      "x": -17,
      "y": 21,
      "z": 2,
      "name": "Rock_Stone"
    },
    {
      "x": -17,
      "y": 22,
      "z": 2,
      "name": "Rock_Stone"
    },
    {
      "x": -17,
      "y": 23,
      "z": 2,
      "name": "Rock_Stone"
    },
    {
      "x": -17,
      "y": 24,
      "z": 2,
      "name": "Rock_Stone"
    },
    {
      "x": -17,
      "y": 25,
      "z": 2,
      "name": "Rock_Stone"
    },
    {
      "x": -17,
      "y": 26,
      "z": 2,
      "name": "Rock_Stone"
    },
    {
      "x": -17,
      "y": 27,
      "z": 2,
      "name": "Rock_Stone"
    },
    {
      "x": -17,
      "y": 28,
      "z": 2,
      "name": "Plant_Crop_Mushroom_Block_Brown"
    },
    {
      "x": -17,
      "y": 29,
      "z": 2,
      "name": "Plant_Crop_Mushroom_Block_Brown"
    },
    {
      "x": -17,
      "y": 30,
      "z": 2,
      "name": "Plant_Crop_Mushroom_Block_Brown"
    },
    {
      "x": -17,
      "y": 14,
      "z": 3,
      "name": "Rock_Crystal_Yellow_Medium",
      "rotation": 7
    },
    {
      "x": -17,
      "y": 15,
      "z": 3,
      "name": "Rock_Crystal_Yellow_Large",
      "rotation": 7
    },
    {
      "x": -17,
      "y": 16,
      "z": 3,
      "name": "Rock_Crystal_Yellow_Medium",
      "rotation": 7
    },
    {
      "x": -17,
      "y": 17,
      "z": 3,
      "name": "Rock_Crystal_Yellow_Medium",
      "rotation": 6
    },
    {
      "x": -17,
      "y": 19,
      "z": 3,
      "name": "Rock_Stone"
    },
    {
      "x": -17,
      "y": 20,
      "z": 3,
      "name": "Rock_Stone"
    },
    {
      "x": -17,
      "y": 21,
      "z": 3,
      "name": "Rock_Stone"
    },
    {
      "x": -17,
      "y": 22,
      "z": 3,
      "name": "Rock_Stone"
    },
    {
      "x": -17,
      "y": 23,
      "z": 3,
      "name": "Rock_Stone"
    },
    {
      "x": -17,
      "y": 24,
      "z": 3,
      "name": "Rock_Stone"
    },
    {
      "x": -17,
      "y": 25,
      "z": 3,
      "name": "Rock_Stone"
    },
    {
      "x": -17,
      "y": 26,
      "z": 3,
      "name": "Rock_Stone"
    },
    {
      "x": -17,
      "y": 27,
      "z": 3,
      "name": "Rock_Stone"
    },
    {
      "x": -17,
      "y": 28,
      "z": 3,
      "name": "Plant_Crop_Mushroom_Block_Brown"
    },
    {
      "x": -17,
      "y": 29,
      "z": 3,
      "name": "Plant_Crop_Mushroom_Block_Brown"
    },
    {
      "x": -17,
      "y": 30,
      "z": 3,
      "name": "Plant_Crop_Mushroom_Block_Brown"
    },
    {
      "x": -17,
      "y": 35,
      "z": 3,
      "name": "Plant_Crop_Mushroom_Block_Brown_Mycelium"
    },
    {
      "x": -17,
      "y": 36,
      "z": 3,
      "name": "Plant_Crop_Mushroom_Block_Brown"
    },
    {
      "x": -17,
      "y": 12,
      "z": 4,
      "name": "Rock_Crystal_Yellow_Large",
      "rotation": 7
    },
    {
      "x": -17,
      "y": 14,
      "z": 4,
      "name": "Rock_Crystal_Yellow_Medium",
      "rotation": 7
    },
    {
      "x": -17,
      "y": 15,
      "z": 4,
      "name": "Rock_Crystal_Yellow_Large",
      "rotation": 8
    },
    {
      "x": -17,
      "y": 16,
      "z": 4,
      "name": "Rock_Crystal_Yellow_Block"
    },
    {
      "x": -17,
      "y": 17,
      "z": 4,
      "name": "Rock_Crystal_Yellow_Block"
    },
    {
      "x": -17,
      "y": 18,
      "z": 4,
      "name": "Rock_Crystal_Yellow_Block"
    },
    {
      "x": -17,
      "y": 19,
      "z": 4,
      "name": "Rock_Crystal_Yellow_Block"
    },
    {
      "x": -17,
      "y": 20,
      "z": 4,
      "name": "Rock_Crystal_Yellow_Block"
    },
    {
      "x": -17,
      "y": 21,
      "z": 4,
      "name": "Rock_Crystal_Yellow_Block"
    },
    {
      "x": -17,
      "y": 22,
      "z": 4,
      "name": "Rock_Stone"
    },
    {
      "x": -17,
      "y": 23,
      "z": 4,
      "name": "Rock_Stone"
    },
    {
      "x": -17,
      "y": 24,
      "z": 4,
      "name": "Rock_Stone"
    },
    {
      "x": -17,
      "y": 25,
      "z": 4,
      "name": "Rock_Stone"
    },
    {
      "x": -17,
      "y": 26,
      "z": 4,
      "name": "Rock_Stone"
    },
    {
      "x": -17,
      "y": 27,
      "z": 4,
      "name": "Rock_Stone"
    },
    {
      "x": -17,
      "y": 28,
      "z": 4,
      "name": "Plant_Crop_Mushroom_Block_Brown"
    },
    {
      "x": -17,
      "y": 29,
      "z": 4,
      "name": "Plant_Crop_Mushroom_Block_Brown"
    },
    {
      "x": -17,
      "y": 30,
      "z": 4,
      "name": "Plant_Crop_Mushroom_Block_Brown"
    },
    {
      "x": -17,
      "y": 35,
      "z": 4,
      "name": "Plant_Crop_Mushroom_Block_Brown_Mycelium"
    },
    {
      "x": -17,
      "y": 36,
      "z": 4,
      "name": "Plant_Crop_Mushroom_Block_Brown"
    },
    {
      "x": -17,
      "y": 37,
      "z": 4,
      "name": "Plant_Crop_Mushroom_Block_Brown"
    },
    {
      "x": -17,
      "y": 15,
      "z": 5,
      "name": "Rock_Crystal_Yellow_Large",
      "rotation": 7
    },
    {
      "x": -17,
      "y": 17,
      "z": 5,
      "name": "Rock_Stone"
    },
    {
      "x": -17,
      "y": 18,
      "z": 5,
      "name": "Rock_Stone"
    },
    {
      "x": -17,
      "y": 19,
      "z": 5,
      "name": "Rock_Stone"
    },
    {
      "x": -17,
      "y": 20,
      "z": 5,
      "name": "Rock_Stone"
    },
    {
      "x": -17,
      "y": 21,
      "z": 5,
      "name": "Rock_Stone"
    },
    {
      "x": -17,
      "y": 22,
      "z": 5,
      "name": "Rock_Stone"
    },
    {
      "x": -17,
      "y": 23,
      "z": 5,
      "name": "Rock_Stone"
    },
    {
      "x": -17,
      "y": 24,
      "z": 5,
      "name": "Rock_Stone"
    },
    {
      "x": -17,
      "y": 25,
      "z": 5,
      "name": "Rock_Stone"
    },
    {
      "x": -17,
      "y": 26,
      "z": 5,
      "name": "Rock_Stone"
    },
    {
      "x": -17,
      "y": 27,
      "z": 5,
      "name": "Plant_Crop_Mushroom_Block_Brown"
    },
    {
      "x": -17,
      "y": 28,
      "z": 5,
      "name": "Plant_Crop_Mushroom_Block_Brown"
    },
    {
      "x": -17,
      "y": 29,
      "z": 5,
      "name": "Plant_Crop_Mushroom_Block_Brown"
    },
    {
      "x": -17,
      "y": 37,
      "z": 5,
      "name": "Plant_Crop_Mushroom_Block_Brown"
    },
    {
      "x": -17,
      "y": 17,
      "z": 6,
      "name": "Rock_Stone"
    },
    {
      "x": -17,
      "y": 18,
      "z": 6,
      "name": "Rock_Stone"
    },
    {
      "x": -17,
      "y": 19,
      "z": 6,
      "name": "Rock_Stone"
    },
    {
      "x": -17,
      "y": 20,
      "z": 6,
      "name": "Rock_Stone"
    },
    {
      "x": -17,
      "y": 21,
      "z": 6,
      "name": "Rock_Stone"
    },
    {
      "x": -17,
      "y": 22,
      "z": 6,
      "name": "Rock_Stone"
    },
    {
      "x": -17,
      "y": 23,
      "z": 6,
      "name": "Rock_Stone"
    },
    {
      "x": -17,
      "y": 24,
      "z": 6,
      "name": "Rock_Stone"
    },
    {
      "x": -17,
      "y": 25,
      "z": 6,
      "name": "Ore_Copper_Stone"
    },
    {
      "x": -17,
      "y": 26,
      "z": 6,
      "name": "Plant_Crop_Mushroom_Block_Brown"
    },
    {
      "x": -17,
      "y": 27,
      "z": 6,
      "name": "Plant_Crop_Mushroom_Block_Brown"
    },
    {
      "x": -17,
      "y": 28,
      "z": 6,
      "name": "Plant_Crop_Mushroom_Block_Brown"
    },
    {
      "x": -17,
      "y": 32,
      "z": 6,
      "name": "Plant_Crop_Mushroom_Block_Brown"
    },
    {
      "x": -17,
      "y": 37,
      "z": 6,
      "name": "Plant_Crop_Mushroom_Block_Brown"
    },
    {
      "x": -17,
      "y": 17,
      "z": 7,
      "name": "Rock_Stone"
    },
    {
      "x": -17,
      "y": 18,
      "z": 7,
      "name": "Rock_Stone"
    },
    {
      "x": -17,
      "y": 19,
      "z": 7,
      "name": "Rock_Stone"
    },
    {
      "x": -17,
      "y": 20,
      "z": 7,
      "name": "Rock_Stone"
    },
    {
      "x": -17,
      "y": 21,
      "z": 7,
      "name": "Rock_Stone"
    },
    {
      "x": -17,
      "y": 22,
      "z": 7,
      "name": "Rock_Stone"
    },
    {
      "x": -17,
      "y": 23,
      "z": 7,
      "name": "Rock_Stone"
    },
    {
      "x": -17,
      "y": 24,
      "z": 7,
      "name": "Rock_Stone"
    },
    {
      "x": -17,
      "y": 25,
      "z": 7,
      "name": "Rock_Stone"
    },
    {
      "x": -17,
      "y": 26,
      "z": 7,
      "name": "Plant_Crop_Mushroom_Block_Brown"
    },
    {
      "x": -17,
      "y": 27,
      "z": 7,
      "name": "Plant_Crop_Mushroom_Block_Brown"
    },
    {
      "x": -17,
      "y": 28,
      "z": 7,
      "name": "Plant_Crop_Mushroom_Block_Brown"
    },
    {
      "x": -17,
      "y": 32,
      "z": 7,
      "name": "Plant_Crop_Mushroom_Block_Brown"
    },
    {
      "x": -17,
      "y": 37,
      "z": 7,
      "name": "Plant_Crop_Mushroom_Block_Brown"
    },
    {
      "x": -17,
      "y": 18,
      "z": 8,
      "name": "Rock_Stone"
    },
    {
      "x": -17,
      "y": 19,
      "z": 8,
      "name": "Rock_Stone"
    },
    {
      "x": -17,
      "y": 20,
      "z": 8,
      "name": "Rock_Stone"
    },
    {
      "x": -17,
      "y": 21,
      "z": 8,
      "name": "Rock_Stone"
    },
    {
      "x": -17,
      "y": 22,
      "z": 8,
      "name": "Rock_Stone"
    },
    {
      "x": -17,
      "y": 23,
      "z": 8,
      "name": "Rock_Stone"
    },
    {
      "x": -17,
      "y": 24,
      "z": 8,
      "name": "Rock_Stone"
    },
    {
      "x": -17,
      "y": 25,
      "z": 8,
      "name": "Rock_Stone_Mossy"
    },
    {
      "x": -17,
      "y": 26,
      "z": 8,
      "name": "Plant_Crop_Mushroom_Block_Brown"
    },
    {
      "x": -17,
      "y": 27,
      "z": 8,
      "name": "Plant_Crop_Mushroom_Block_Brown"
    },
    {
      "x": -17,
      "y": 28,
      "z": 8,
      "name": "Plant_Crop_Mushroom_Block_Brown"
    },
    {
      "x": -17,
      "y": 36,
      "z": 8,
      "name": "Plant_Crop_Mushroom_Block_Brown"
    },
    {
      "x": -17,
      "y": 37,
      "z": 8,
      "name": "Plant_Crop_Mushroom_Block_Brown"
    },
    {
      "x": -17,
      "y": 19,
      "z": 9,
      "name": "Rock_Stone"
    },
    {
      "x": -17,
      "y": 20,
      "z": 9,
      "name": "Rock_Stone"
    },
    {
      "x": -17,
      "y": 21,
      "z": 9,
      "name": "Rock_Stone"
    },
    {
      "x": -17,
      "y": 22,
      "z": 9,
      "name": "Rock_Stone"
    },
    {
      "x": -17,
      "y": 23,
      "z": 9,
      "name": "Rock_Stone"
    },
    {
      "x": -17,
      "y": 24,
      "z": 9,
      "name": "Rock_Stone"
    },
    {
      "x": -17,
      "y": 25,
      "z": 9,
      "name": "Rock_Stone"
    },
    {
      "x": -17,
      "y": 26,
      "z": 9,
      "name": "Plant_Crop_Mushroom_Block_Brown"
    },
    {
      "x": -17,
      "y": 27,
      "z": 9,
      "name": "Plant_Crop_Mushroom_Block_Brown"
    },
    {
      "x": -17,
      "y": 28,
      "z": 9,
      "name": "Plant_Crop_Mushroom_Block_Brown"
    },
    {
      "x": -17,
      "y": 36,
      "z": 9,
      "name": "Plant_Crop_Mushroom_Block_Brown"
    },
    {
      "x": -17,
      "y": 21,
      "z": 10,
      "name": "Rock_Stone"
    },
    {
      "x": -17,
      "y": 22,
      "z": 10,
      "name": "Rock_Stone"
    },
    {
      "x": -17,
      "y": 23,
      "z": 10,
      "name": "Rock_Stone"
    },
    {
      "x": -17,
      "y": 24,
      "z": 10,
      "name": "Rock_Stone"
    },
    {
      "x": -17,
      "y": 25,
      "z": 10,
      "name": "Rock_Stone"
    },
    {
      "x": -17,
      "y": 26,
      "z": 10,
      "name": "Plant_Crop_Mushroom_Block_Brown"
    },
    {
      "x": -17,
      "y": 27,
      "z": 10,
      "name": "Plant_Crop_Mushroom_Block_Brown"
    },
    {
      "x": -17,
      "y": 28,
      "z": 10,
      "name": "Plant_Moss_Rug_Yellow"
    },
    {
      "x": -17,
      "y": 23,
      "z": 11,
      "name": "Rock_Stone"
    },
    {
      "x": -17,
      "y": 24,
      "z": 11,
      "name": "Rock_Stone"
    },
    {
      "x": -17,
      "y": 25,
      "z": 11,
      "name": "Rock_Stone_Mossy"
    },
    {
      "x": -17,
      "y": 26,
      "z": 11,
      "name": "Plant_Crop_Mushroom_Block_Brown"
    },
    {
      "x": -17,
      "y": 27,
      "z": 11,
      "name": "Plant_Crop_Mushroom_Block_Brown"
    },
    {
      "x": -17,
      "y": 28,
      "z": 11,
      "name": "Plant_Crop_Mushroom_Cap_Brown",
      "components": {
        "Components": {
          "FarmingBlock": {
            "LastTickGameTime": "0001-01-03T12:00:00Z"
          }
        }
      }
    },
    {
      "x": -16,
      "y": 26,
      "z": -6,
      "name": "Plant_Crop_Mushroom_Block_Brown"
    },
    {
      "x": -16,
      "y": 27,
      "z": -6,
      "name": "Plant_Crop_Mushroom_Block_Brown"
    },
    {
      "x": -16,
      "y": 21,
      "z": -5,
      "name": "Rock_Stone_Stalactite_Large",
      "filler": 31744,
      "rotation": 8
    },
    {
      "x": -16,
      "y": 22,
      "z": -5,
      "name": "Rock_Stone_Stalactite_Large",
      "rotation": 8
    },
    {
      "x": -16,
      "y": 23,
      "z": -5,
      "name": "Rock_Stone"
    },
    {
      "x": -16,
      "y": 24,
      "z": -5,
      "name": "Rock_Stone"
    },
    {
      "x": -16,
      "y": 25,
      "z": -5,
      "name": "Rock_Stone"
    },
    {
      "x": -16,
      "y": 26,
      "z": -5,
      "name": "Rock_Stone"
    },
    {
      "x": -16,
      "y": 27,
      "z": -5,
      "name": "Rock_Stone"
    },
    {
      "x": -16,
      "y": 28,
      "z": -5,
      "name": "Plant_Crop_Mushroom_Block_Brown"
    },
    {
      "x": -16,
      "y": 29,
      "z": -5,
      "name": "Plant_Crop_Mushroom_Block_Brown"
    },
    {
      "x": -16,
      "y": 30,
      "z": -5,
      "name": "Plant_Crop_Mushroom_Block_Brown"
    },
    {
      "x": -16,
      "y": 20,
      "z": -4,
      "name": "Rock_Stone_Stalactite_Large",
      "filler": 31744,
      "rotation": 8
    },
    {
      "x": -16,
      "y": 21,
      "z": -4,
      "name": "Rock_Stone_Stalactite_Large",
      "rotation": 8
    },
    {
      "x": -16,
      "y": 22,
      "z": -4,
      "name": "Rock_Stone"
    },
    {
      "x": -16,
      "y": 23,
      "z": -4,
      "name": "Rock_Stone"
    },
    {
      "x": -16,
      "y": 24,
      "z": -4,
      "name": "Rock_Stone"
    },
    {
      "x": -16,
      "y": 25,
      "z": -4,
      "name": "Rock_Stone"
    },
    {
      "x": -16,
      "y": 26,
      "z": -4,
      "name": "Rock_Stone"
    },
    {
      "x": -16,
      "y": 27,
      "z": -4,
      "name": "Rock_Stone"
    },
    {
      "x": -16,
      "y": 28,
      "z": -4,
      "name": "Plant_Crop_Mushroom_Block_Brown"
    },
    {
      "x": -16,
      "y": 29,
      "z": -4,
      "name": "Plant_Crop_Mushroom_Block_Brown"
    },
    {
      "x": -16,
      "y": 30,
      "z": -4,
      "name": "Plant_Moss_Rug_Yellow"
    },
    {
      "x": -16,
      "y": 21,
      "z": -3,
      "name": "Rock_Stone"
    },
    {
      "x": -16,
      "y": 22,
      "z": -3,
      "name": "Rock_Stone"
    },
    {
      "x": -16,
      "y": 23,
      "z": -3,
      "name": "Rock_Stone"
    },
    {
      "x": -16,
      "y": 24,
      "z": -3,
      "name": "Rock_Stone"
    },
    {
      "x": -16,
      "y": 25,
      "z": -3,
      "name": "Rock_Stone"
    },
    {
      "x": -16,
      "y": 26,
      "z": -3,
      "name": "Rock_Stone"
    },
    {
      "x": -16,
      "y": 27,
      "z": -3,
      "name": "Ore_Copper_Stone"
    },
    {
      "x": -16,
      "y": 28,
      "z": -3,
      "name": "Plant_Crop_Mushroom_Block_Brown"
    },
    {
      "x": -16,
      "y": 29,
      "z": -3,
      "name": "Plant_Crop_Mushroom_Block_Brown"
    },
    {
      "x": -16,
      "y": 30,
      "z": -3,
      "name": "Plant_Crop_Mushroom_Block_Brown"
    },
    {
      "x": -16,
      "y": 20,
      "z": -2,
      "name": "Rock_Stone"
    },
    {
      "x": -16,
      "y": 21,
      "z": -2,
      "name": "Rock_Stone"
    },
    {
      "x": -16,
      "y": 22,
      "z": -2,
      "name": "Rock_Stone"
    },
    {
      "x": -16,
      "y": 23,
      "z": -2,
      "name": "Rock_Stone"
    },
    {
      "x": -16,
      "y": 24,
      "z": -2,
      "name": "Rock_Stone"
    },
    {
      "x": -16,
      "y": 25,
      "z": -2,
      "name": "Rock_Stone"
    },
    {
      "x": -16,
      "y": 26,
      "z": -2,
      "name": "Rock_Stone"
    },
    {
      "x": -16,
      "y": 27,
      "z": -2,
      "name": "Rock_Stone"
    },
    {
      "x": -16,
      "y": 28,
      "z": -2,
      "name": "Rock_Stone"
    },
    {
      "x": -16,
      "y": 29,
      "z": -2,
      "name": "Plant_Crop_Mushroom_Block_Brown"
    },
    {
      "x": -16,
      "y": 30,
      "z": -2,
      "name": "Plant_Crop_Mushroom_Block_Brown"
    },
    {
      "x": -16,
      "y": 31,
      "z": -2,
      "name": "Plant_Crop_Mushroom_Block_Brown"
    },
    {
      "x": -16,
      "y": 20,
      "z": -1,
      "name": "Rock_Stone"
    },
    {
      "x": -16,
      "y": 21,
      "z": -1,
      "name": "Rock_Stone"
    },
    {
      "x": -16,
      "y": 22,
      "z": -1,
      "name": "Rock_Stone"
    },
    {
      "x": -16,
      "y": 23,
      "z": -1,
      "name": "Rock_Stone"
    },
    {
      "x": -16,
      "y": 24,
      "z": -1,
      "name": "Rock_Stone"
    },
    {
      "x": -16,
      "y": 25,
      "z": -1,
      "name": "Rock_Stone"
    },
    {
      "x": -16,
      "y": 26,
      "z": -1,
      "name": "Rock_Stone"
    },
    {
      "x": -16,
      "y": 27,
      "z": -1,
      "name": "Rock_Stone"
    },
    {
      "x": -16,
      "y": 28,
      "z": -1,
      "name": "Rock_Stone_Mossy"
    },
    {
      "x": -16,
      "y": 29,
      "z": -1,
      "name": "Plant_Crop_Mushroom_Block_Brown"
    },
    {
      "x": -16,
      "y": 30,
      "z": -1,
      "name": "Plant_Crop_Mushroom_Block_Brown"
    },
    {
      "x": -16,
      "y": 31,
      "z": -1,
      "name": "Plant_Crop_Mushroom_Block_Brown"
    },
    {
      "x": -16,
      "y": 20,
      "z": 0,
      "name": "Rock_Stone"
    },
    {
      "x": -16,
      "y": 21,
      "z": 0,
      "name": "Rock_Stone"
    },
    {
      "x": -16,
      "y": 22,
      "z": 0,
      "name": "Rock_Stone"
    },
    {
      "x": -16,
      "y": 23,
      "z": 0,
      "name": "Rock_Stone"
    },
    {
      "x": -16,
      "y": 24,
      "z": 0,
      "name": "Rock_Stone"
    },
    {
      "x": -16,
      "y": 25,
      "z": 0,
      "name": "Rock_Stone"
    },
    {
      "x": -16,
      "y": 26,
      "z": 0,
      "name": "Rock_Stone"
    },
    {
      "x": -16,
      "y": 27,
      "z": 0,
      "name": "Rock_Stone"
    },
    {
      "x": -16,
      "y": 28,
      "z": 0,
      "name": "Ore_Copper_Stone"
    },
    {
      "x": -16,
      "y": 29,
      "z": 0,
      "name": "Plant_Crop_Mushroom_Block_Brown"
    },
    {
      "x": -16,
      "y": 30,
      "z": 0,
      "name": "Plant_Crop_Mushroom_Block_Brown"
    },
    {
      "x": -16,
      "y": 31,
      "z": 0,
      "name": "Plant_Crop_Mushroom_Block_Brown"
    },
    {
      "x": -16,
      "y": 20,
      "z": 1,
      "name": "Rock_Stone"
    },
    {
      "x": -16,
      "y": 21,
      "z": 1,
      "name": "Rock_Stone"
    },
    {
      "x": -16,
      "y": 22,
      "z": 1,
      "name": "Rock_Stone"
    },
    {
      "x": -16,
      "y": 23,
      "z": 1,
      "name": "Rock_Stone"
    },
    {
      "x": -16,
      "y": 24,
      "z": 1,
      "name": "Rock_Stone"
    },
    {
      "x": -16,
      "y": 25,
      "z": 1,
      "name": "Rock_Stone"
    },
    {
      "x": -16,
      "y": 26,
      "z": 1,
      "name": "Rock_Stone"
    },
    {
      "x": -16,
      "y": 27,
      "z": 1,
      "name": "Rock_Stone"
    },
    {
      "x": -16,
      "y": 28,
      "z": 1,
      "name": "Rock_Stone"
    },
    {
      "x": -16,
      "y": 29,
      "z": 1,
      "name": "Plant_Crop_Mushroom_Block_Brown"
    },
    {
      "x": -16,
      "y": 30,
      "z": 1,
      "name": "Plant_Crop_Mushroom_Block_Brown"
    },
    {
      "x": -16,
      "y": 31,
      "z": 1,
      "name": "Plant_Crop_Mushroom_Block_Brown"
    },
    {
      "x": -16,
      "y": 14,
      "z": 2,
      "name": "Rock_Crystal_Yellow_Large",
      "rotation": 6
    },
    {
      "x": -16,
      "y": 15,
      "z": 2,
      "name": "Rock_Crystal_Yellow_Large",
      "rotation": 6
    },
    {
      "x": -16,
      "y": 17,
      "z": 2,
      "name": "Rock_Crystal_Yellow_Medium",
      "rotation": 6
    },
    {
      "x": -16,
      "y": 19,
      "z": 2,
      "name": "Rock_Stone"
    },
    {
      "x": -16,
      "y": 20,
      "z": 2,
      "name": "Rock_Stone"
    },
    {
      "x": -16,
      "y": 21,
      "z": 2,
      "name": "Rock_Stone"
    },
    {
      "x": -16,
      "y": 22,
      "z": 2,
      "name": "Rock_Stone"
    },
    {
      "x": -16,
      "y": 23,
      "z": 2,
      "name": "Rock_Stone"
    },
    {
      "x": -16,
      "y": 24,
      "z": 2,
      "name": "Rock_Stone"
    },
    {
      "x": -16,
      "y": 25,
      "z": 2,
      "name": "Rock_Stone"
    },
    {
      "x": -16,
      "y": 26,
      "z": 2,
      "name": "Rock_Stone"
    },
    {
      "x": -16,
      "y": 27,
      "z": 2,
      "name": "Rock_Stone"
    },
    {
      "x": -16,
      "y": 28,
      "z": 2,
      "name": "Rock_Stone"
    },
    {
      "x": -16,
      "y": 29,
      "z": 2,
      "name": "Plant_Crop_Mushroom_Block_Brown"
    },
    {
      "x": -16,
      "y": 30,
      "z": 2,
      "name": "Plant_Crop_Mushroom_Block_Brown"
    },
    {
      "x": -16,
      "y": 31,
      "z": 2,
      "name": "Plant_Crop_Mushroom_Block_Brown"
    },
    {
      "x": -16,
      "y": 13,
      "z": 3,
      "name": "Rock_Crystal_Yellow_Large",
      "rotation": 8
    },
    {
      "x": -16,
      "y": 14,
      "z": 3,
      "name": "Rock_Crystal_Yellow_Block"
    },
    {
      "x": -16,
      "y": 15,
      "z": 3,
      "name": "Rock_Crystal_Yellow_Block"
    },
    {
      "x": -16,
      "y": 16,
      "z": 3,
      "name": "Rock_Crystal_Yellow_Block"
    },
    {
      "x": -16,
      "y": 17,
      "z": 3,
      "name": "Rock_Crystal_Yellow_Block"
    },
    {
      "x": -16,
      "y": 18,
      "z": 3,
      "name": "Rock_Crystal_Yellow_Block"
    },
    {
      "x": -16,
      "y": 19,
      "z": 3,
      "name": "Rock_Crystal_Yellow_Block"
    },
    {
      "x": -16,
      "y": 20,
      "z": 3,
      "name": "Rock_Crystal_Yellow_Block"
    },
    {
      "x": -16,
      "y": 21,
      "z": 3,
      "name": "Rock_Crystal_Yellow_Block"
    },
    {
      "x": -16,
      "y": 22,
      "z": 3,
      "name": "Rock_Stone"
    },
    {
      "x": -16,
      "y": 23,
      "z": 3,
      "name": "Rock_Stone"
    },
    {
      "x": -16,
      "y": 24,
      "z": 3,
      "name": "Rock_Stone"
    },
    {
      "x": -16,
      "y": 25,
      "z": 3,
      "name": "Rock_Stone"
    },
    {
      "x": -16,
      "y": 26,
      "z": 3,
      "name": "Rock_Stone"
    },
    {
      "x": -16,
      "y": 27,
      "z": 3,
      "name": "Rock_Stone"
    },
    {
      "x": -16,
      "y": 28,
      "z": 3,
      "name": "Rock_Stone"
    },
    {
      "x": -16,
      "y": 29,
      "z": 3,
      "name": "Plant_Crop_Mushroom_Block_Brown"
    },
    {
      "x": -16,
      "y": 30,
      "z": 3,
      "name": "Plant_Crop_Mushroom_Block_Brown"
    },
    {
      "x": -16,
      "y": 31,
      "z": 3,
      "name": "Plant_Crop_Mushroom_Block_Brown"
    },
    {
      "x": -16,
      "y": 34,
      "z": 3,
      "name": "Plant_Crop_Mushroom_Block_Brown_Mycelium"
    },
    {
      "x": -16,
      "y": 35,
      "z": 3,
      "name": "Plant_Crop_Mushroom_Block_Brown_Mycelium"
    },
    {
      "x": -16,
      "y": 36,
      "z": 3,
      "name": "Plant_Crop_Mushroom_Block_Brown"
    },
    {
      "x": -16,
      "y": 11,
      "z": 4,
      "name": "Rock_Crystal_Yellow_Large",
      "rotation": 8
    },
    {
      "x": -16,
      "y": 12,
      "z": 4,
      "name": "Rock_Crystal_Yellow_Block"
    },
    {
      "x": -16,
      "y": 13,
      "z": 4,
      "name": "Rock_Crystal_Yellow_Block"
    },
    {
      "x": -16,
      "y": 14,
      "z": 4,
      "name": "Rock_Crystal_Yellow_Block"
    },
    {
      "x": -16,
      "y": 15,
      "z": 4,
      "name": "Rock_Crystal_Yellow_Block"
    },
    {
      "x": -16,
      "y": 16,
      "z": 4,
      "name": "Rock_Crystal_Yellow_Block"
    },
    {
      "x": -16,
      "y": 17,
      "z": 4,
      "name": "Rock_Crystal_Yellow_Block"
    },
    {
      "x": -16,
      "y": 18,
      "z": 4,
      "name": "Rock_Crystal_Yellow_Block"
    },
    {
      "x": -16,
      "y": 19,
      "z": 4,
      "name": "Rock_Crystal_Yellow_Block"
    },
    {
      "x": -16,
      "y": 20,
      "z": 4,
      "name": "Rock_Crystal_Yellow_Block"
    },
    {
      "x": -16,
      "y": 21,
      "z": 4,
      "name": "Rock_Crystal_Yellow_Block"
    },
    {
      "x": -16,
      "y": 22,
      "z": 4,
      "name": "Rock_Stone"
    },
    {
      "x": -16,
      "y": 23,
      "z": 4,
      "name": "Rock_Stone"
    },
    {
      "x": -16,
      "y": 24,
      "z": 4,
      "name": "Rock_Stone"
    },
    {
      "x": -16,
      "y": 25,
      "z": 4,
      "name": "Rock_Stone"
    },
    {
      "x": -16,
      "y": 26,
      "z": 4,
      "name": "Rock_Stone"
    },
    {
      "x": -16,
      "y": 27,
      "z": 4,
      "name": "Rock_Stone"
    },
    {
      "x": -16,
      "y": 28,
      "z": 4,
      "name": "Plant_Crop_Mushroom_Block_Brown"
    },
    {
      "x": -16,
      "y": 29,
      "z": 4,
      "name": "Plant_Crop_Mushroom_Block_Brown"
    },
    {
      "x": -16,
      "y": 30,
      "z": 4,
      "name": "Plant_Crop_Mushroom_Block_Brown"
    },
    {
      "x": -16,
      "y": 37,
      "z": 4,
      "name": "Plant_Crop_Mushroom_Block_Brown"
    },
    {
      "x": -16,
      "y": 12,
      "z": 5,
      "name": "Rock_Crystal_Yellow_Medium",
      "rotation": 4
    },
    {
      "x": -16,
      "y": 13,
      "z": 5,
      "name": "Rock_Crystal_Yellow_Medium",
      "rotation": 4
    },
    {
      "x": -16,
      "y": 14,
      "z": 5,
      "name": "Rock_Crystal_Yellow_Medium",
      "rotation": 4
    },
    {
      "x": -16,
      "y": 15,
      "z": 5,
      "name": "Rock_Crystal_Yellow_Block"
    },
    {
      "x": -16,
      "y": 16,
      "z": 5,
      "name": "Rock_Crystal_Yellow_Block"
    },
    {
      "x": -16,
      "y": 17,
      "z": 5,
      "name": "Rock_Crystal_Yellow_Block"
    },
    {
      "x": -16,
      "y": 18,
      "z": 5,
      "name": "Rock_Crystal_Yellow_Block"
    },
    {
      "x": -16,
      "y": 19,
      "z": 5,
      "name": "Rock_Crystal_Yellow_Block"
    },
    {
      "x": -16,
      "y": 20,
      "z": 5,
      "name": "Rock_Crystal_Yellow_Block"
    },
    {
      "x": -16,
      "y": 21,
      "z": 5,
      "name": "Rock_Crystal_Yellow_Block"
    },
    {
      "x": -16,
      "y": 22,
      "z": 5,
      "name": "Rock_Stone"
    },
    {
      "x": -16,
      "y": 23,
      "z": 5,
      "name": "Rock_Stone"
    },
    {
      "x": -16,
      "y": 24,
      "z": 5,
      "name": "Rock_Stone"
    },
    {
      "x": -16,
      "y": 25,
      "z": 5,
      "name": "Rock_Stone"
    },
    {
      "x": -16,
      "y": 26,
      "z": 5,
      "name": "Rock_Stone"
    },
    {
      "x": -16,
      "y": 27,
      "z": 5,
      "name": "Plant_Crop_Mushroom_Block_Brown"
    },
    {
      "x": -16,
      "y": 28,
      "z": 5,
      "name": "Plant_Crop_Mushroom_Block_Brown"
    },
    {
      "x": -16,
      "y": 29,
      "z": 5,
      "name": "Plant_Crop_Mushroom_Block_Brown"
    },
    {
      "x": -16,
      "y": 32,
      "z": 5,
      "name": "Plant_Crop_Mushroom_Block_Brown"
    },
    {
      "x": -16,
      "y": 37,
      "z": 5,
      "name": "Plant_Crop_Mushroom_Block_Brown"
    },
    {
      "x": -16,
      "y": 38,
      "z": 5,
      "name": "Plant_Crop_Mushroom_Common_Brown",
      "components": {
        "Components": {
          "FarmingBlock": {
            "LastTickGameTime": "0001-01-03T12:00:00Z"
          }
        }
      }
    },
    {
      "x": -16,
      "y": 15,
      "z": 6,
      "name": "Rock_Crystal_Yellow_Medium",
      "rotation": 4
    },
    {
      "x": -16,
      "y": 16,
      "z": 6,
      "name": "Rock_Crystal_Yellow_Medium",
      "rotation": 4
    },
    {
      "x": -16,
      "y": 17,
      "z": 6,
      "name": "Rock_Stone"
    },
    {
      "x": -16,
      "y": 18,
      "z": 6,
      "name": "Rock_Stone"
    },
    {
      "x": -16,
      "y": 19,
      "z": 6,
      "name": "Rock_Stone"
    },
    {
      "x": -16,
      "y": 20,
      "z": 6,
      "name": "Rock_Stone"
    },
    {
      "x": -16,
      "y": 21,
      "z": 6,
      "name": "Rock_Stone"
    },
    {
      "x": -16,
      "y": 22,
      "z": 6,
      "name": "Rock_Stone"
    },
    {
      "x": -16,
      "y": 23,
      "z": 6,
      "name": "Rock_Stone"
    },
    {
      "x": -16,
      "y": 24,
      "z": 6,
      "name": "Rock_Stone"
    },
    {
      "x": -16,
      "y": 25,
      "z": 6,
      "name": "Ore_Copper_Stone"
    },
    {
      "x": -16,
      "y": 26,
      "z": 6,
      "name": "Plant_Crop_Mushroom_Block_Brown"
    },
    {
      "x": -16,
      "y": 27,
      "z": 6,
      "name": "Plant_Crop_Mushroom_Block_Brown"
    },
    {
      "x": -16,
      "y": 28,
      "z": 6,
      "name": "Plant_Crop_Mushroom_Block_Brown_Trunk"
    },
    {
      "x": -16,
      "y": 29,
      "z": 6,
      "name": "Plant_Crop_Mushroom_Block_Brown_Trunk"
    },
    {
      "x": -16,
      "y": 30,
      "z": 6,
      "name": "Plant_Crop_Mushroom_Block_Brown_Trunk"
    },
    {
      "x": -16,
      "y": 31,
      "z": 6,
      "name": "Plant_Crop_Mushroom_Block_Brown_Trunk"
    },
    {
      "x": -16,
      "y": 32,
      "z": 6,
      "name": "Plant_Crop_Mushroom_Block_Brown_Trunk"
    },
    {
      "x": -16,
      "y": 33,
      "z": 6,
      "name": "Plant_Crop_Mushroom_Block_Brown_Trunk"
    },
    {
      "x": -16,
      "y": 34,
      "z": 6,
      "name": "Plant_Crop_Mushroom_Block_Brown_Trunk"
    },
    {
      "x": -16,
      "y": 35,
      "z": 6,
      "name": "Plant_Crop_Mushroom_Block_Brown_Trunk"
    },
    {
      "x": -16,
      "y": 36,
      "z": 6,
      "name": "Plant_Crop_Mushroom_Block_Brown_Trunk"
    },
    {
      "x": -16,
      "y": 37,
      "z": 6,
      "name": "Plant_Crop_Mushroom_Block_Brown"
    },
    {
      "x": -16,
      "y": 17,
      "z": 7,
      "name": "Rock_Stone"
    },
    {
      "x": -16,
      "y": 18,
      "z": 7,
      "name": "Rock_Stone"
    },
    {
      "x": -16,
      "y": 19,
      "z": 7,
      "name": "Rock_Stone"
    },
    {
      "x": -16,
      "y": 20,
      "z": 7,
      "name": "Rock_Stone"
    },
    {
      "x": -16,
      "y": 21,
      "z": 7,
      "name": "Rock_Stone"
    },
    {
      "x": -16,
      "y": 22,
      "z": 7,
      "name": "Rock_Stone"
    },
    {
      "x": -16,
      "y": 23,
      "z": 7,
      "name": "Rock_Stone"
    },
    {
      "x": -16,
      "y": 24,
      "z": 7,
      "name": "Rock_Stone"
    },
    {
      "x": -16,
      "y": 25,
      "z": 7,
      "name": "Rock_Stone"
    },
    {
      "x": -16,
      "y": 26,
      "z": 7,
      "name": "Plant_Crop_Mushroom_Block_Brown"
    },
    {
      "x": -16,
      "y": 27,
      "z": 7,
      "name": "Plant_Crop_Mushroom_Block_Brown"
    },
    {
      "x": -16,
      "y": 28,
      "z": 7,
      "name": "Plant_Crop_Mushroom_Block_Brown"
    },
    {
      "x": -16,
      "y": 31,
      "z": 7,
      "name": "Plant_Crop_Mushroom_Block_Brown_Mycelium"
    },
    {
      "x": -16,
      "y": 32,
      "z": 7,
      "name": "Plant_Crop_Mushroom_Block_Brown"
    },
    {
      "x": -16,
      "y": 33,
      "z": 7,
      "name": "Plant_Crop_Mushroom_Shelve_Brown"
    },
    {
      "x": -16,
      "y": 37,
      "z": 7,
      "name": "Plant_Crop_Mushroom_Block_Brown"
    },
    {
      "x": -16,
      "y": 17,
      "z": 8,
      "name": "Rock_Stone"
    },
    {
      "x": -16,
      "y": 18,
      "z": 8,
      "name": "Rock_Stone"
    },
    {
      "x": -16,
      "y": 19,
      "z": 8,
      "name": "Rock_Stone"
    },
    {
      "x": -16,
      "y": 20,
      "z": 8,
      "name": "Rock_Stone"
    },
    {
      "x": -16,
      "y": 21,
      "z": 8,
      "name": "Rock_Stone"
    },
    {
      "x": -16,
      "y": 22,
      "z": 8,
      "name": "Rock_Stone"
    },
    {
      "x": -16,
      "y": 23,
      "z": 8,
      "name": "Rock_Stone"
    },
    {
      "x": -16,
      "y": 24,
      "z": 8,
      "name": "Rock_Stone"
    },
    {
      "x": -16,
      "y": 25,
      "z": 8,
      "name": "Rock_Stone"
    },
    {
      "x": -16,
      "y": 26,
      "z": 8,
      "name": "Plant_Crop_Mushroom_Block_Brown"
    },
    {
      "x": -16,
      "y": 27,
      "z": 8,
      "name": "Plant_Crop_Mushroom_Block_Brown"
    },
    {
      "x": -16,
      "y": 28,
      "z": 8,
      "name": "Plant_Crop_Mushroom_Block_Brown"
    },
    {
      "x": -16,
      "y": 32,
      "z": 8,
      "name": "Plant_Crop_Mushroom_Block_Brown"
    },
    {
      "x": -16,
      "y": 35,
      "z": 8,
      "name": "Plant_Crop_Mushroom_Block_Brown_Mycelium"
    },
    {
      "x": -16,
      "y": 36,
      "z": 8,
      "name": "Plant_Crop_Mushroom_Block_Brown_Mycelium"
    },
    {
      "x": -16,
      "y": 37,
      "z": 8,
      "name": "Plant_Crop_Mushroom_Block_Brown"
    },
    {
      "x": -16,
      "y": 19,
      "z": 9,
      "name": "Rock_Stone"
    },
    {
      "x": -16,
      "y": 20,
      "z": 9,
      "name": "Rock_Stone"
    },
    {
      "x": -16,
      "y": 21,
      "z": 9,
      "name": "Rock_Stone"
    },
    {
      "x": -16,
      "y": 22,
      "z": 9,
      "name": "Rock_Stone"
    },
    {
      "x": -16,
      "y": 23,
      "z": 9,
      "name": "Ore_Gold_Stone"
    },
    {
      "x": -16,
      "y": 24,
      "z": 9,
      "name": "Rock_Stone"
    },
    {
      "x": -16,
      "y": 25,
      "z": 9,
      "name": "Rock_Stone"
    },
    {
      "x": -16,
      "y": 26,
      "z": 9,
      "name": "Plant_Crop_Mushroom_Block_Brown"
    },
    {
      "x": -16,
      "y": 27,
      "z": 9,
      "name": "Plant_Crop_Mushroom_Block_Brown"
    },
    {
      "x": -16,
      "y": 28,
      "z": 9,
      "name": "Plant_Crop_Mushroom_Block_Brown"
    },
    {
      "x": -16,
      "y": 35,
      "z": 9,
      "name": "Plant_Crop_Mushroom_Block_Brown_Mycelium"
    },
    {
      "x": -16,
      "y": 36,
      "z": 9,
      "name": "Plant_Crop_Mushroom_Block_Brown"
    },
    {
      "x": -16,
      "y": 37,
      "z": 9,
      "name": "Plant_Crop_Mushroom_Shelve_Brown"
    },
    {
      "x": -16,
      "y": 20,
      "z": 10,
      "name": "Rock_Stone"
    },
    {
      "x": -16,
      "y": 21,
      "z": 10,
      "name": "Rock_Stone"
    },
    {
      "x": -16,
      "y": 22,
      "z": 10,
      "name": "Rock_Stone"
    },
    {
      "x": -16,
      "y": 23,
      "z": 10,
      "name": "Ore_Gold_Stone"
    },
    {
      "x": -16,
      "y": 24,
      "z": 10,
      "name": "Rock_Stone"
    },
    {
      "x": -16,
      "y": 25,
      "z": 10,
      "name": "Rock_Stone"
    },
    {
      "x": -16,
      "y": 26,
      "z": 10,
      "name": "Plant_Crop_Mushroom_Block_Brown"
    },
    {
      "x": -16,
      "y": 27,
      "z": 10,
      "name": "Plant_Crop_Mushroom_Block_Brown"
    },
    {
      "x": -16,
      "y": 28,
      "z": 10,
      "name": "Plant_Crop_Mushroom_Block_Brown"
    },
    {
      "x": -16,
      "y": 23,
      "z": 11,
      "name": "Ore_Gold_Stone"
    },
    {
      "x": -16,
      "y": 24,
      "z": 11,
      "name": "Rock_Stone"
    },
    {
      "x": -16,
      "y": 25,
      "z": 11,
      "name": "Rock_Stone"
    },
    {
      "x": -16,
      "y": 26,
      "z": 11,
      "name": "Plant_Crop_Mushroom_Block_Brown"
    },
    {
      "x": -16,
      "y": 27,
      "z": 11,
      "name": "Plant_Crop_Mushroom_Block_Brown"
    },
    {
      "x": -16,
      "y": 28,
      "z": 11,
      "name": "Plant_Crop_Mushroom_Block_Brown"
    },
    {
      "x": -15,
      "y": 26,
      "z": -6,
      "name": "Rock_Stone"
    },
    {
      "x": -15,
      "y": 27,
      "z": -6,
      "name": "Rock_Stone"
    },
    {
      "x": -15,
      "y": 28,
      "z": -6,
      "name": "Ore_Copper_Stone"
    },
    {
      "x": -15,
      "y": 29,
      "z": -6,
      "name": "Plant_Crop_Mushroom_Block_Brown"
    },
    {
      "x": -15,
      "y": 30,
      "z": -6,
      "name": "Plant_Crop_Mushroom_Block_Brown"
    },
    {
      "x": -15,
      "y": 31,
      "z": -6,
      "name": "Plant_Crop_Mushroom_Block_Brown"
    },
    {
      "x": -15,
      "y": 24,
      "z": -5,
      "name": "Rock_Stone"
    },
    {
      "x": -15,
      "y": 25,
      "z": -5,
      "name": "Rock_Stone"
    },
    {
      "x": -15,
      "y": 26,
      "z": -5,
      "name": "Rock_Stone"
    },
    {
      "x": -15,
      "y": 27,
      "z": -5,
      "name": "Rock_Stone"
    },
    {
      "x": -15,
      "y": 28,
      "z": -5,
      "name": "Rock_Stone"
    },
    {
      "x": -15,
      "y": 29,
      "z": -5,
      "name": "Plant_Crop_Mushroom_Block_Brown"
    },
    {
      "x": -15,
      "y": 30,
      "z": -5,
      "name": "Plant_Crop_Mushroom_Block_Brown"
    },
    {
      "x": -15,
      "y": 31,
      "z": -5,
      "name": "Plant_Crop_Mushroom_Block_Brown"
    },
    {
      "x": -15,
      "y": 22,
      "z": -4,
      "name": "Rock_Stone"
    },
    {
      "x": -15,
      "y": 23,
      "z": -4,
      "name": "Rock_Stone"
    },
    {
      "x": -15,
      "y": 24,
      "z": -4,
      "name": "Rock_Stone"
    },
    {
      "x": -15,
      "y": 25,
      "z": -4,
      "name": "Rock_Stone"
    },
    {
      "x": -15,
      "y": 26,
      "z": -4,
      "name": "Rock_Stone"
    },
    {
      "x": -15,
      "y": 27,
      "z": -4,
      "name": "Rock_Stone"
    },
    {
      "x": -15,
      "y": 28,
      "z": -4,
      "name": "Rock_Stone"
    },
    {
      "x": -15,
      "y": 29,
      "z": -4,
      "name": "Plant_Crop_Mushroom_Block_Brown"
    },
    {
      "x": -15,
      "y": 30,
      "z": -4,
      "name": "Plant_Crop_Mushroom_Block_Brown"
    },
    {
      "x": -15,
      "y": 31,
      "z": -4,
      "name": "Plant_Crop_Mushroom_Block_Brown"
    },
    {
      "x": -15,
      "y": 21,
      "z": -3,
      "name": "Rock_Stone"
    },
    {
      "x": -15,
      "y": 22,
      "z": -3,
      "name": "Rock_Stone"
    },
    {
      "x": -15,
      "y": 23,
      "z": -3,
      "name": "Rock_Stone"
    },
    {
      "x": -15,
      "y": 24,
      "z": -3,
      "name": "Rock_Stone"
    },
    {
      "x": -15,
      "y": 25,
      "z": -3,
      "name": "Rock_Stone"
    },
    {
      "x": -15,
      "y": 26,
      "z": -3,
      "name": "Rock_Stone"
    },
    {
      "x": -15,
      "y": 27,
      "z": -3,
      "name": "Rock_Stone"
    },
    {
      "x": -15,
      "y": 28,
      "z": -3,
      "name": "Rock_Stone"
    },
    {
      "x": -15,
      "y": 29,
      "z": -3,
      "name": "Plant_Crop_Mushroom_Block_Brown"
    },
    {
      "x": -15,
      "y": 30,
      "z": -3,
      "name": "Plant_Crop_Mushroom_Block_Brown"
    },
    {
      "x": -15,
      "y": 31,
      "z": -3,
      "name": "Plant_Crop_Mushroom_Block_Brown"
    },
    {
      "x": -15,
      "y": 20,
      "z": -2,
      "name": "Rock_Stone"
    },
    {
      "x": -15,
      "y": 21,
      "z": -2,
      "name": "Rock_Stone"
    },
    {
      "x": -15,
      "y": 22,
      "z": -2,
      "name": "Rock_Stone"
    },
    {
      "x": -15,
      "y": 23,
      "z": -2,
      "name": "Rock_Stone"
    },
    {
      "x": -15,
      "y": 24,
      "z": -2,
      "name": "Rock_Stone"
    },
    {
      "x": -15,
      "y": 25,
      "z": -2,
      "name": "Rock_Stone"
    },
    {
      "x": -15,
      "y": 26,
      "z": -2,
      "name": "Rock_Stone"
    },
    {
      "x": -15,
      "y": 27,
      "z": -2,
      "name": "Rock_Stone"
    },
    {
      "x": -15,
      "y": 28,
      "z": -2,
      "name": "Rock_Stone"
    },
    {
      "x": -15,
      "y": 29,
      "z": -2,
      "name": "Plant_Crop_Mushroom_Block_Brown"
    },
    {
      "x": -15,
      "y": 30,
      "z": -2,
      "name": "Plant_Crop_Mushroom_Block_Brown"
    },
    {
      "x": -15,
      "y": 31,
      "z": -2,
      "name": "Plant_Crop_Mushroom_Block_Brown"
    },
    {
      "x": -15,
      "y": 20,
      "z": -1,
      "name": "Rock_Stone"
    },
    {
      "x": -15,
      "y": 21,
      "z": -1,
      "name": "Rock_Stone"
    },
    {
      "x": -15,
      "y": 22,
      "z": -1,
      "name": "Rock_Stone"
    },
    {
      "x": -15,
      "y": 23,
      "z": -1,
      "name": "Rock_Stone"
    },
    {
      "x": -15,
      "y": 24,
      "z": -1,
      "name": "Rock_Stone"
    },
    {
      "x": -15,
      "y": 25,
      "z": -1,
      "name": "Rock_Stone"
    },
    {
      "x": -15,
      "y": 26,
      "z": -1,
      "name": "Rock_Stone"
    },
    {
      "x": -15,
      "y": 27,
      "z": -1,
      "name": "Rock_Stone"
    },
    {
      "x": -15,
      "y": 28,
      "z": -1,
      "name": "Rock_Stone"
    },
    {
      "x": -15,
      "y": 29,
      "z": -1,
      "name": "Plant_Crop_Mushroom_Block_Brown"
    },
    {
      "x": -15,
      "y": 30,
      "z": -1,
      "name": "Plant_Crop_Mushroom_Block_Brown"
    },
    {
      "x": -15,
      "y": 31,
      "z": -1,
      "name": "Plant_Crop_Mushroom_Block_Brown"
    },
    {
      "x": -15,
      "y": 20,
      "z": 0,
      "name": "Rock_Stone"
    },
    {
      "x": -15,
      "y": 21,
      "z": 0,
      "name": "Rock_Stone"
    },
    {
      "x": -15,
      "y": 22,
      "z": 0,
      "name": "Rock_Stone"
    },
    {
      "x": -15,
      "y": 23,
      "z": 0,
      "name": "Rock_Stone"
    },
    {
      "x": -15,
      "y": 24,
      "z": 0,
      "name": "Rock_Stone"
    },
    {
      "x": -15,
      "y": 25,
      "z": 0,
      "name": "Rock_Stone"
    },
    {
      "x": -15,
      "y": 26,
      "z": 0,
      "name": "Rock_Stone"
    },
    {
      "x": -15,
      "y": 27,
      "z": 0,
      "name": "Rock_Stone"
    },
    {
      "x": -15,
      "y": 28,
      "z": 0,
      "name": "Ore_Copper_Stone"
    },
    {
      "x": -15,
      "y": 29,
      "z": 0,
      "name": "Plant_Crop_Mushroom_Block_Brown"
    },
    {
      "x": -15,
      "y": 30,
      "z": 0,
      "name": "Plant_Crop_Mushroom_Block_Brown"
    },
    {
      "x": -15,
      "y": 31,
      "z": 0,
      "name": "Plant_Crop_Mushroom_Block_Brown"
    },
    {
      "x": -15,
      "y": 20,
      "z": 1,
      "name": "Rock_Stone"
    },
    {
      "x": -15,
      "y": 21,
      "z": 1,
      "name": "Rock_Stone"
    },
    {
      "x": -15,
      "y": 22,
      "z": 1,
      "name": "Rock_Stone"
    },
    {
      "x": -15,
      "y": 23,
      "z": 1,
      "name": "Rock_Stone"
    },
    {
      "x": -15,
      "y": 24,
      "z": 1,
      "name": "Rock_Stone"
    },
    {
      "x": -15,
      "y": 25,
      "z": 1,
      "name": "Rock_Stone"
    },
    {
      "x": -15,
      "y": 26,
      "z": 1,
      "name": "Rock_Stone"
    },
    {
      "x": -15,
      "y": 27,
      "z": 1,
      "name": "Rock_Stone"
    },
    {
      "x": -15,
      "y": 28,
      "z": 1,
      "name": "Rock_Stone"
    },
    {
      "x": -15,
      "y": 29,
      "z": 1,
      "name": "Plant_Crop_Mushroom_Block_Brown"
    },
    {
      "x": -15,
      "y": 30,
      "z": 1,
      "name": "Plant_Crop_Mushroom_Block_Brown"
    },
    {
      "x": -15,
      "y": 31,
      "z": 1,
      "name": "Plant_Crop_Mushroom_Block_Brown"
    },
    {
      "x": -15,
      "y": 19,
      "z": 2,
      "name": "Rock_Stone"
    },
    {
      "x": -15,
      "y": 20,
      "z": 2,
      "name": "Rock_Stone"
    },
    {
      "x": -15,
      "y": 21,
      "z": 2,
      "name": "Rock_Stone"
    },
    {
      "x": -15,
      "y": 22,
      "z": 2,
      "name": "Rock_Stone"
    },
    {
      "x": -15,
      "y": 23,
      "z": 2,
      "name": "Rock_Stone"
    },
    {
