{
  "version": 8,
  "blockIdVersion": 11,
  "anchorX": 0,
  "anchorY": 0,
  "anchorZ": 0,
  "blocks": [
    {
      "x": -21,
      "y": 36,
      "z": 0,
      "name": "Plant_Leaves_Azure"
    },
    {
      "x": -21,
      "y": 37,
      "z": 0,
      "name": "Plant_Leaves_Azure"
    },
    {
      "x": -21,
      "y": 35,
      "z": 1,
      "name": "Plant_Leaves_Azure"
    },
    {
      "x": -21,
      "y": 36,
      "z": 1,
      "name": "Plant_Leaves_Azure"
    },
    {
      "x": -21,
      "y": 37,
      "z": 1,
      "name": "Plant_Leaves_Azure"
    },
    {
      "x": -21,
      "y": 38,
      "z": 1,
      "name": "Plant_Leaves_Azure"
    },
    {
      "x": -21,
      "y": 35,
      "z": 2,
      "name": "Plant_Leaves_Azure"
    },
    {
      "x": -21,
      "y": 36,
      "z": 2,
      "name": "Plant_Leaves_Azure"
    },
    {
      "x": -21,
      "y": 37,
      "z": 2,
      "name": "Plant_Leaves_Azure"
    },
    {
      "x": -21,
      "y": 38,
      "z": 2,
      "name": "Plant_Leaves_Azure"
    },
    {
      "x": -21,
      "y": 39,
      "z": 2,
      "name": "Plant_Fruit_Azure"
    },
    {
      "x": -21,
      "y": 35,
      "z": 3,
      "name": "Plant_Leaves_Azure"
    },
    {
      "x": -21,
      "y": 36,
      "z": 3,
      "name": "Plant_Leaves_Azure"
    },
    {
      "x": -21,
      "y": 37,
      "z": 3,
      "name": "Plant_Leaves_Azure"
    },
    {
      "x": -21,
      "y": 38,
      "z": 3,
      "name": "Plant_Leaves_Azure"
    },
    {
      "x": -21,
      "y": 36,
      "z": 4,
      "name": "Plant_Leaves_Azure"
    },
    {
      "x": -21,
      "y": 37,
      "z": 4,
      "name": "Plant_Leaves_Azure"
    },
    {
      "x": -20,
      "y": 39,
      "z": -3,
      "name": "Plant_Leaves_Azure"
    },
    {
      "x": -20,
      "y": 40,
      "z": -3,
      "name": "Plant_Leaves_Azure"
    },
    {
      "x": -20,
      "y": 41,
      "z": -3,
      "name": "Plant_Leaves_Azure"
    },
    {
      "x": -20,
      "y": 39,
      "z": -2,
      "name": "Plant_Leaves_Azure"
    },
    {
      "x": -20,
      "y": 40,
      "z": -2,
      "name": "Plant_Leaves_Azure"
    },
    {
      "x": -20,
      "y": 41,
      "z": -2,
      "name": "Plant_Leaves_Azure"
    },
    {
      "x": -20,
      "y": 42,
      "z": -2,
      "name": "Plant_Leaves_Azure"
    },
    {
      "x": -20,
      "y": 40,
      "z": -1,
      "name": "Plant_Leaves_Azure"
    },
    {
      "x": -20,
      "y": 41,
      "z": -1,
      "name": "Plant_Leaves_Azure"
    },
    {
      "x": -20,
      "y": 42,
      "z": -1,
      "name": "Plant_Leaves_Azure"
    },
    {
      "x": -20,
      "y": 43,
      "z": -1,
      "name": "Plant_Leaves_Azure"
    },
    {
      "x": -20,
      "y": 36,
      "z": 0,
      "name": "Plant_Leaves_Azure"
    },
    {
      "x": -20,
      "y": 37,
      "z": 0,
      "name": "Plant_Leaves_Azure"
    },
    {
      "x": -20,
      "y": 41,
      "z": 0,
      "name": "Plant_Leaves_Azure"
    },
    {
      "x": -20,
      "y": 42,
      "z": 0,
      "name": "Plant_Leaves_Azure"
    },
    {
      "x": -20,
      "y": 43,
      "z": 0,
      "name": "Plant_Leaves_Azure"
    },
    {
      "x": -20,
      "y": 44,
      "z": 0,
      "name": "Plant_Leaves_Azure"
    },
    {
      "x": -20,
      "y": 35,
      "z": 1,
      "name": "Plant_Leaves_Azure"
    },
    {
      "x": -20,
      "y": 36,
      "z": 1,
      "name": "Plant_Leaves_Azure"
    },
    {
      "x": -20,
      "y": 37,
      "z": 1,
      "name": "Plant_Leaves_Azure"
    },
    {
      "x": -20,
      "y": 38,
      "z": 1,
      "name": "Plant_Leaves_Azure"
    },
    {
      "x": -20,
      "y": 42,
      "z": 1,
      "name": "Plant_Leaves_Azure"
    },
    {
      "x": -20,
      "y": 43,
      "z": 1,
      "name": "Plant_Leaves_Azure"
    },
    {
      "x": -20,
      "y": 44,
      "z": 1,
      "name": "Plant_Leaves_Azure"
    },
    {
      "x": -20,
      "y": 35,
      "z": 2,
      "name": "Plant_Leaves_Azure"
    },
    {
      "x": -20,
      "y": 36,
      "z": 2,
      "name": "Plant_Leaves_Azure"
    },
    {
      "x": -20,
      "y": 37,
      "z": 2,
      "name": "Plant_Leaves_Azure"
    },
    {
      "x": -20,
      "y": 38,
      "z": 2,
      "name": "Plant_Leaves_Azure"
    },
    {
      "x": -20,
      "y": 35,
      "z": 3,
      "name": "Plant_Leaves_Azure"
    },
    {
      "x": -20,
      "y": 36,
      "z": 3,
      "name": "Plant_Leaves_Azure"
    },
    {
      "x": -20,
      "y": 37,
      "z": 3,
      "name": "Plant_Leaves_Azure"
    },
    {
      "x": -20,
      "y": 38,
      "z": 3,
      "name": "Plant_Leaves_Azure"
    },
    {
      "x": -20,
      "y": 39,
      "z": 3,
      "name": "Plant_Leaves_Azure"
    },
    {
      "x": -20,
      "y": 35,
      "z": 4,
      "name": "Plant_Leaves_Azure"
    },
    {
      "x": -20,
      "y": 36,
      "z": 4,
      "name": "Plant_Leaves_Azure"
    },
    {
      "x": -20,
      "y": 37,
      "z": 4,
      "name": "Plant_Leaves_Azure"
    },
    {
      "x": -20,
      "y": 38,
      "z": 4,
      "name": "Plant_Leaves_Azure"
    },
    {
      "x": -20,
      "y": 39,
      "z": 4,
      "name": "Plant_Leaves_Azure"
    },
    {
      "x": -19,
      "y": 38,
      "z": -4,
      "name": "Plant_Leaves_Azure"
    },
    {
      "x": -19,
      "y": 39,
      "z": -4,
      "name": "Plant_Leaves_Azure"
    },
    {
      "x": -19,
      "y": 40,
      "z": -4,
      "name": "Plant_Leaves_Azure"
    },
    {
      "x": -19,
      "y": 18,
      "z": -3,
      "name": "Plant_Moss_Wall_Blue",
      "rotation": 3
    },
    {
      "x": -19,
      "y": 19,
      "z": -3,
      "name": "Plant_Moss_Wall_Blue",
      "rotation": 3
    },
    {
      "x": -19,
      "y": 38,
      "z": -3,
      "name": "Plant_Leaves_Azure"
    },
    {
      "x": -19,
      "y": 39,
      "z": -3,
      "name": "Plant_Leaves_Azure"
    },
    {
      "x": -19,
      "y": 40,
      "z": -3,
      "name": "Plant_Leaves_Azure"
    },
    {
      "x": -19,
      "y": 41,
      "z": -3,
      "name": "Plant_Leaves_Azure"
    },
    {
      "x": -19,
      "y": 42,
      "z": -3,
      "name": "Plant_Leaves_Azure"
    },
    {
      "x": -19,
      "y": 39,
      "z": -2,
      "name": "Plant_Leaves_Azure"
    },
    {
      "x": -19,
      "y": 40,
      "z": -2,
      "name": "Plant_Leaves_Azure"
    },
    {
      "x": -19,
      "y": 41,
      "z": -2,
      "name": "Plant_Leaves_Azure"
    },
    {
      "x": -19,
      "y": 42,
      "z": -2,
      "name": "Plant_Leaves_Azure"
    },
    {
      "x": -19,
      "y": 43,
      "z": -2,
      "name": "Plant_Leaves_Azure"
    },
    {
      "x": -19,
      "y": 39,
      "z": -1,
      "name": "Plant_Leaves_Azure"
    },
    {
      "x": -19,
      "y": 40,
      "z": -1,
      "name": "Wood_Azure_Branch_Long",
      "rotation": 5
    },
    {
      "x": -19,
      "y": 41,
      "z": -1,
      "name": "Plant_Leaves_Azure"
    },
    {
      "x": -19,
      "y": 42,
      "z": -1,
      "name": "Plant_Leaves_Azure"
    },
    {
      "x": -19,
      "y": 43,
      "z": -1,
      "name": "Plant_Leaves_Azure"
    },
    {
      "x": -19,
      "y": 44,
      "z": -1,
      "name": "Plant_Leaves_Azure"
    },
    {
      "x": -19,
      "y": 20,
      "z": 0,
      "name": "Plant_Moss_Wall_Blue",
      "rotation": 3
    },
    {
      "x": -19,
      "y": 40,
      "z": 0,
      "name": "Plant_Leaves_Azure"
    },
    {
      "x": -19,
      "y": 41,
      "z": 0,
      "name": "Plant_Leaves_Azure"
    },
    {
      "x": -19,
      "y": 42,
      "z": 0,
      "name": "Plant_Leaves_Azure"
    },
    {
      "x": -19,
      "y": 43,
      "z": 0,
      "name": "Plant_Leaves_Azure"
    },
    {
      "x": -19,
      "y": 44,
      "z": 0,
      "name": "Plant_Leaves_Azure"
    },
    {
      "x": -19,
      "y": 45,
      "z": 0,
      "name": "Plant_Leaves_Azure"
    },
    {
      "x": -19,
      "y": 36,
      "z": 1,
      "name": "Wood_Azure_Branch_Long",
      "rotation": 5
    },
    {
      "x": -19,
      "y": 41,
      "z": 1,
      "name": "Plant_Leaves_Azure"
    },
    {
      "x": -19,
      "y": 42,
      "z": 1,
      "name": "Plant_Leaves_Azure"
    },
    {
      "x": -19,
      "y": 43,
      "z": 1,
      "name": "Plant_Leaves_Azure"
    },
    {
      "x": -19,
      "y": 44,
      "z": 1,
      "name": "Plant_Leaves_Azure"
    },
    {
      "x": -19,
      "y": 45,
      "z": 1,
      "name": "Plant_Leaves_Azure"
    },
    {
      "x": -19,
      "y": 38,
      "z": 2,
      "name": "Plant_Leaves_Azure"
    },
    {
      "x": -19,
      "y": 39,
      "z": 2,
      "name": "Plant_Leaves_Azure"
    },
    {
      "x": -19,
      "y": 43,
      "z": 2,
      "name": "Plant_Leaves_Azure"
    },
    {
      "x": -19,
      "y": 44,
      "z": 2,
      "name": "Plant_Leaves_Azure"
    },
    {
      "x": -19,
      "y": 36,
      "z": 3,
      "name": "Plant_Leaves_Azure"
    },
    {
      "x": -19,
      "y": 37,
      "z": 3,
      "name": "Plant_Leaves_Azure"
    },
    {
      "x": -19,
      "y": 38,
      "z": 3,
      "name": "Plant_Leaves_Azure"
    },
    {
      "x": -19,
      "y": 39,
      "z": 3,
      "name": "Plant_Leaves_Azure"
    },
    {
      "x": -19,
      "y": 36,
      "z": 4,
      "name": "Plant_Leaves_Azure"
    },
    {
      "x": -19,
      "y": 37,
      "z": 4,
      "name": "Plant_Leaves_Azure"
    },
    {
      "x": -19,
      "y": 38,
      "z": 4,
      "name": "Plant_Leaves_Azure"
    },
    {
      "x": -19,
      "y": 39,
      "z": 4,
      "name": "Plant_Leaves_Azure"
    },
    {
      "x": -19,
      "y": 40,
      "z": 4,
      "name": "Plant_Leaves_Azure"
    },
    {
      "x": -19,
      "y": 41,
      "z": 4,
      "name": "Plant_Fruit_Azure"
    },
    {
      "x": -19,
      "y": 37,
      "z": 5,
      "name": "Plant_Leaves_Azure"
    },
    {
      "x": -19,
      "y": 38,
      "z": 5,
      "name": "Plant_Leaves_Azure"
    },
    {
      "x": -19,
      "y": 39,
      "z": 5,
      "name": "Plant_Leaves_Azure"
    },
    {
      "x": -18,
      "y": 37,
      "z": -5,
      "name": "Plant_Leaves_Azure"
    },
    {
      "x": -18,
      "y": 38,
      "z": -5,
      "name": "Plant_Leaves_Azure"
    },
    {
      "x": -18,
      "y": 39,
      "z": -5,
      "name": "Plant_Leaves_Azure"
    },
    {
      "x": -18,
      "y": 40,
      "z": -5,
      "name": "Plant_Leaves_Azure"
    },
    {
      "x": -18,
      "y": 17,
      "z": -4,
      "name": "Plant_Moss_Wall_Blue",
      "rotation": 3
    },
    {
      "x": -18,
      "y": 18,
      "z": -4,
      "name": "Plant_Moss_Wall_Blue",
      "rotation": 3
    },
    {
      "x": -18,
      "y": 37,
      "z": -4,
      "name": "Plant_Leaves_Azure"
    },
    {
      "x": -18,
      "y": 38,
      "z": -4,
      "name": "Plant_Leaves_Azure"
    },
    {
      "x": -18,
      "y": 39,
      "z": -4,
      "name": "Plant_Leaves_Azure"
    },
    {
      "x": -18,
      "y": 40,
      "z": -4,
      "name": "Plant_Leaves_Azure"
    },
    {
      "x": -18,
      "y": 41,
      "z": -4,
      "name": "Plant_Leaves_Azure"
    },
    {
      "x": -18,
      "y": 17,
      "z": -3,
      "name": "Plant_Moss_Wall_Blue",
      "rotation": 3
    },
    {
      "x": -18,
      "y": 18,
      "z": -3,
      "name": "Rock_Marble"
    },
    {
      "x": -18,
      "y": 19,
      "z": -3,
      "name": "Plant_Moss_Block_Blue"
    },
    {
      "x": -18,
      "y": 20,
      "z": -3,
      "name": "Plant_Moss_Block_Blue"
    },
    {
      "x": -18,
      "y": 21,
      "z": -3,
      "name": "Plant_Moss_Short_Green_Dark"
    },
    {
      "x": -18,
      "y": 38,
      "z": -3,
      "name": "Plant_Leaves_Azure"
    },
    {
      "x": -18,
      "y": 39,
      "z": -3,
      "name": "Plant_Leaves_Azure"
    },
    {
      "x": -18,
      "y": 40,
      "z": -3,
      "name": "Plant_Leaves_Azure"
    },
    {
      "x": -18,
      "y": 41,
      "z": -3,
      "name": "Plant_Leaves_Azure"
    },
    {
      "x": -18,
      "y": 42,
      "z": -3,
      "name": "Plant_Leaves_Azure"
    },
    {
      "x": -18,
      "y": 19,
      "z": -2,
      "name": "Plant_Moss_Block_Blue"
    },
    {
      "x": -18,
      "y": 20,
      "z": -2,
      "name": "Plant_Moss_Block_Blue"
    },
    {
      "x": -18,
      "y": 21,
      "z": -2,
      "name": "Plant_Moss_Short_Green_Dark"
    },
    {
      "x": -18,
      "y": 40,
      "z": -2,
      "name": "Plant_Leaves_Azure"
    },
    {
      "x": -18,
      "y": 41,
      "z": -2,
      "name": "Plant_Leaves_Azure"
    },
    {
      "x": -18,
      "y": 42,
      "z": -2,
      "name": "Plant_Leaves_Azure"
    },
    {
      "x": -18,
      "y": 43,
      "z": -2,
      "name": "Plant_Fruit_Azure"
    },
    {
      "x": -18,
      "y": 18,
      "z": -1,
      "name": "Rock_Marble"
    },
    {
      "x": -18,
      "y": 19,
      "z": -1,
      "name": "Plant_Moss_Block_Blue"
    },
    {
      "x": -18,
      "y": 20,
      "z": -1,
      "name": "Plant_Moss_Block_Blue"
    },
    {
      "x": -18,
      "y": 21,
      "z": -1,
      "name": "Plant_Moss_Rug_Blue"
    },
    {
      "x": -18,
      "y": 40,
      "z": -1,
      "name": "Wood_Azure_Branch_Long",
      "rotation": 5
    },
    {
      "x": -18,
      "y": 42,
      "z": -1,
      "name": "Plant_Leaves_Azure"
    },
    {
      "x": -18,
      "y": 43,
      "z": -1,
      "name": "Plant_Leaves_Azure"
    },
    {
      "x": -18,
      "y": 18,
      "z": 0,
      "name": "Rock_Marble"
    },
    {
      "x": -18,
      "y": 19,
      "z": 0,
      "name": "Plant_Moss_Block_Blue"
    },
    {
      "x": -18,
      "y": 20,
      "z": 0,
      "name": "Plant_Moss_Block_Blue"
    },
    {
      "x": -18,
      "y": 21,
      "z": 0,
      "name": "Plant_Moss_Blue"
    },
    {
      "x": -18,
      "y": 36,
      "z": 0,
      "name": "Plant_Moss_Wall_Blue",
      "rotation": 2
    },
    {
      "x": -18,
      "y": 42,
      "z": 0,
      "name": "Plant_Leaves_Azure"
    },
    {
      "x": -18,
      "y": 43,
      "z": 0,
      "name": "Wood_Azure_Branch_Long",
      "rotation": 5
    },
    {
      "x": -18,
      "y": 44,
      "z": 0,
      "name": "Plant_Leaves_Azure"
    },
    {
      "x": -18,
      "y": 45,
      "z": 0,
      "name": "Plant_Fruit_Azure"
    },
    {
      "x": -18,
      "y": 17,
      "z": 1,
      "name": "Rock_Marble"
    },
    {
      "x": -18,
      "y": 18,
      "z": 1,
      "name": "Plant_Moss_Block_Blue"
    },
    {
      "x": -18,
      "y": 19,
      "z": 1,
      "name": "Plant_Moss_Block_Blue"
    },
    {
      "x": -18,
      "y": 20,
      "z": 1,
      "name": "Plant_Moss_Rug_Lime"
    },
    {
      "x": -18,
      "y": 36,
      "z": 1,
      "name": "Wood_Azure_Trunk_Full"
    },
    {
      "x": -18,
      "y": 37,
      "z": 1,
      "name": "Plant_Moss_Rug_Blue"
    },
    {
      "x": -18,
      "y": 41,
      "z": 1,
      "name": "Plant_Leaves_Azure"
    },
    {
      "x": -18,
      "y": 42,
      "z": 1,
      "name": "Plant_Leaves_Azure"
    },
    {
      "x": -18,
      "y": 43,
      "z": 1,
      "name": "Plant_Leaves_Azure"
    },
    {
      "x": -18,
      "y": 44,
      "z": 1,
      "name": "Plant_Leaves_Azure"
    },
    {
      "x": -18,
      "y": 45,
      "z": 1,
      "name": "Plant_Leaves_Azure"
    },
    {
      "x": -18,
      "y": 46,
      "z": 1,
      "name": "Plant_Leaves_Azure"
    },
    {
      "x": -18,
      "y": 17,
      "z": 2,
      "name": "Plant_Moss_Wall_Blue"
    },
    {
      "x": -18,
      "y": 18,
      "z": 2,
      "name": "Plant_Moss_Wall_Blue"
    },
    {
      "x": -18,
      "y": 36,
      "z": 2,
      "name": "Plant_Moss_Wall_Blue"
    },
    {
      "x": -18,
      "y": 42,
      "z": 2,
      "name": "Plant_Leaves_Azure"
    },
    {
      "x": -18,
      "y": 43,
      "z": 2,
      "name": "Plant_Leaves_Azure"
    },
    {
      "x": -18,
      "y": 44,
      "z": 2,
      "name": "Plant_Leaves_Azure"
    },
    {
      "x": -18,
      "y": 45,
      "z": 2,
      "name": "Plant_Leaves_Azure"
    },
    {
      "x": -18,
      "y": 46,
      "z": 2,
      "name": "Plant_Leaves_Azure"
    },
    {
      "x": -18,
      "y": 38,
      "z": 3,
      "name": "Plant_Leaves_Azure"
    },
    {
      "x": -18,
      "y": 39,
      "z": 3,
      "name": "Plant_Leaves_Azure"
    },
    {
      "x": -18,
      "y": 40,
      "z": 3,
      "name": "Plant_Leaves_Azure"
    },
    {
      "x": -18,
      "y": 43,
      "z": 3,
      "name": "Plant_Leaves_Azure"
    },
    {
      "x": -18,
      "y": 44,
      "z": 3,
      "name": "Plant_Leaves_Azure"
    },
    {
      "x": -18,
      "y": 45,
      "z": 3,
      "name": "Plant_Leaves_Azure"
    },
    {
      "x": -18,
      "y": 37,
      "z": 4,
      "name": "Plant_Leaves_Azure"
    },
    {
      "x": -18,
      "y": 38,
      "z": 4,
      "name": "Plant_Leaves_Azure"
    },
    {
      "x": -18,
      "y": 39,
      "z": 4,
      "name": "Plant_Leaves_Azure"
    },
    {
      "x": -18,
      "y": 40,
      "z": 4,
      "name": "Plant_Leaves_Azure"
    },
    {
      "x": -18,
      "y": 37,
      "z": 5,
      "name": "Plant_Leaves_Azure"
    },
    {
      "x": -18,
      "y": 38,
      "z": 5,
      "name": "Plant_Leaves_Azure"
    },
    {
      "x": -18,
      "y": 39,
      "z": 5,
      "name": "Plant_Leaves_Azure"
    },
    {
      "x": -18,
      "y": 40,
      "z": 5,
      "name": "Plant_Leaves_Azure"
    },
    {
      "x": -17,
      "y": 20,
      "z": -6,
      "name": "Plant_Moss_Wall_Blue",
      "rotation": 3
    },
    {
      "x": -17,
      "y": 37,
      "z": -6,
      "name": "Plant_Leaves_Azure"
    },
    {
      "x": -17,
      "y": 38,
      "z": -6,
      "name": "Plant_Leaves_Azure"
    },
    {
      "x": -17,
      "y": 39,
      "z": -6,
      "name": "Plant_Leaves_Azure"
    },
    {
      "x": -17,
      "y": 18,
      "z": -5,
      "name": "Plant_Moss_Wall_Blue",
      "rotation": 3
    },
    {
      "x": -17,
      "y": 19,
      "z": -5,
      "name": "Plant_Moss_Wall_Blue",
      "rotation": 3
    },
    {
      "x": -17,
      "y": 20,
      "z": -5,
      "name": "Plant_Moss_Block_Blue"
    },
    {
      "x": -17,
      "y": 21,
      "z": -5,
      "name": "Plant_Moss_Block_Blue"
    },
    {
      "x": -17,
      "y": 22,
      "z": -5,
      "name": "Plant_Moss_Blue"
    },
    {
      "x": -17,
      "y": 36,
      "z": -5,
      "name": "Plant_Leaves_Azure"
    },
    {
      "x": -17,
      "y": 37,
      "z": -5,
      "name": "Plant_Leaves_Azure"
    },
    {
      "x": -17,
      "y": 38,
      "z": -5,
      "name": "Plant_Leaves_Azure"
    },
    {
      "x": -17,
      "y": 39,
      "z": -5,
      "name": "Plant_Leaves_Azure"
    },
    {
      "x": -17,
      "y": 40,
      "z": -5,
      "name": "Plant_Leaves_Azure"
    },
    {
      "x": -17,
      "y": 17,
      "z": -4,
      "name": "Rock_Marble"
    },
    {
      "x": -17,
      "y": 18,
      "z": -4,
      "name": "Rock_Marble"
    },
    {
      "x": -17,
      "y": 19,
      "z": -4,
      "name": "Rock_Marble"
    },
    {
      "x": -17,
      "y": 20,
      "z": -4,
      "name": "Plant_Moss_Block_Blue"
    },
    {
      "x": -17,
      "y": 21,
      "z": -4,
      "name": "Plant_Moss_Block_Blue"
    },
    {
      "x": -17,
      "y": 22,
      "z": -4,
      "name": "Plant_Moss_Rug_Blue"
    },
    {
      "x": -17,
      "y": 37,
      "z": -4,
      "name": "Plant_Leaves_Azure"
    },
    {
      "x": -17,
      "y": 38,
      "z": -4,
      "name": "Plant_Leaves_Azure"
    },
    {
      "x": -17,
      "y": 39,
      "z": -4,
      "name": "Plant_Leaves_Azure"
    },
    {
      "x": -17,
      "y": 40,
      "z": -4,
      "name": "Plant_Leaves_Azure"
    },
    {
      "x": -17,
      "y": 41,
      "z": -4,
      "name": "Plant_Leaves_Azure"
    },
    {
      "x": -17,
      "y": 16,
      "z": -3,
      "name": "Plant_Moss_Wall_Blue",
      "rotation": 3
    },
    {
      "x": -17,
      "y": 17,
      "z": -3,
      "name": "Rock_Marble"
    },
    {
      "x": -17,
      "y": 18,
      "z": -3,
      "name": "Rock_Marble"
    },
    {
      "x": -17,
      "y": 19,
      "z": -3,
      "name": "Rock_Marble"
    },
    {
      "x": -17,
      "y": 20,
      "z": -3,
      "name": "Rock_Marble"
    },
    {
      "x": -17,
      "y": 21,
      "z": -3,
      "name": "Plant_Moss_Block_Blue"
    },
    {
      "x": -17,
      "y": 22,
      "z": -3,
      "name": "Plant_Moss_Block_Blue"
    },
    {
      "x": -17,
      "y": 23,
      "z": -3,
      "name": "Plant_Moss_Rug_Blue"
    },
    {
      "x": -17,
      "y": 40,
      "z": -3,
      "name": "Plant_Leaves_Azure"
    },
    {
      "x": -17,
      "y": 41,
      "z": -3,
      "name": "Plant_Leaves_Azure"
    },
    {
      "x": -17,
      "y": 16,
      "z": -2,
      "name": "Plant_Moss_Wall_Blue",
      "rotation": 3
    },
    {
      "x": -17,
      "y": 17,
      "z": -2,
      "name": "Rock_Marble"
    },
    {
      "x": -17,
      "y": 18,
      "z": -2,
      "name": "Rock_Marble"
    },
    {
      "x": -17,
      "y": 19,
      "z": -2,
      "name": "Rock_Marble"
    },
    {
      "x": -17,
      "y": 20,
      "z": -2,
      "name": "Rock_Marble"
    },
    {
      "x": -17,
      "y": 21,
      "z": -2,
      "name": "Plant_Moss_Block_Blue"
    },
    {
      "x": -17,
      "y": 22,
      "z": -2,
      "name": "Plant_Moss_Block_Blue"
    },
    {
      "x": -17,
      "y": 23,
      "z": -2,
      "name": "Plant_Moss_Rug_Blue"
    },
    {
      "x": -17,
      "y": 26,
      "z": -2,
      "name": "Wood_Azure_Roots"
    },
    {
      "x": -17,
      "y": 27,
      "z": -2,
      "name": "Wood_Azure_Trunk_Full"
    },
    {
      "x": -17,
      "y": 28,
      "z": -2,
      "name": "Wood_Azure_Trunk_Full"
    },
    {
      "x": -17,
      "y": 16,
      "z": -1,
      "name": "Rock_Marble"
    },
    {
      "x": -17,
      "y": 17,
      "z": -1,
      "name": "Rock_Marble"
    },
    {
      "x": -17,
      "y": 18,
      "z": -1,
      "name": "Rock_Marble"
    },
    {
      "x": -17,
      "y": 19,
      "z": -1,
      "name": "Rock_Marble"
    },
    {
      "x": -17,
      "y": 20,
      "z": -1,
      "name": "Plant_Moss_Block_Blue"
    },
    {
      "x": -17,
      "y": 21,
      "z": -1,
      "name": "Plant_Moss_Block_Blue"
    },
    {
      "x": -17,
      "y": 22,
      "z": -1,
      "name": "Plant_Moss_Blue"
    },
    {
      "x": -17,
      "y": 28,
      "z": -1,
      "name": "Wood_Azure_Trunk_Full"
    },
    {
      "x": -17,
      "y": 29,
      "z": -1,
      "name": "Wood_Azure_Trunk_Full"
    },
    {
      "x": -17,
      "y": 40,
      "z": -1,
      "name": "Wood_Azure_Branch_Long",
      "rotation": 5
    },
    {
      "x": -17,
      "y": 16,
      "z": 0,
      "name": "Rock_Marble"
    },
    {
      "x": -17,
      "y": 17,
      "z": 0,
      "name": "Rock_Marble"
    },
    {
      "x": -17,
      "y": 18,
      "z": 0,
      "name": "Rock_Marble"
    },
    {
      "x": -17,
      "y": 19,
      "z": 0,
      "name": "Rock_Marble"
    },
    {
      "x": -17,
      "y": 20,
      "z": 0,
      "name": "Plant_Moss_Block_Blue"
    },
    {
      "x": -17,
      "y": 21,
      "z": 0,
      "name": "Plant_Moss_Block_Blue"
    },
    {
      "x": -17,
      "y": 22,
      "z": 0,
      "name": "Plant_Moss_Short_Green_Dark"
    },
    {
      "x": -17,
      "y": 29,
      "z": 0,
      "name": "Wood_Azure_Trunk_Full"
    },
    {
      "x": -17,
      "y": 32,
      "z": 0,
      "name": "Plant_Moss_Wall_Blue",
      "rotation": 3
    },
    {
      "x": -17,
      "y": 43,
      "z": 0,
      "name": "Wood_Azure_Branch_Long",
      "rotation": 5
    },
    {
      "x": -17,
      "y": 48,
      "z": 0,
      "name": "Plant_Leaves_Azure"
    },
    {
      "x": -17,
      "y": 16,
      "z": 1,
      "name": "Rock_Marble"
    },
    {
      "x": -17,
      "y": 17,
      "z": 1,
      "name": "Rock_Marble"
    },
    {
      "x": -17,
      "y": 18,
      "z": 1,
      "name": "Rock_Marble"
    },
    {
      "x": -17,
      "y": 19,
      "z": 1,
      "name": "Rock_Marble"
    },
    {
      "x": -17,
      "y": 20,
      "z": 1,
      "name": "Rock_Marble"
    },
    {
      "x": -17,
      "y": 21,
      "z": 1,
      "name": "Rock_Marble"
    },
    {
      "x": -17,
      "y": 22,
      "z": 1,
      "name": "Rock_Marble"
    },
    {
      "x": -17,
      "y": 23,
      "z": 1,
      "name": "Rock_Marble"
    },
    {
      "x": -17,
      "y": 24,
      "z": 1,
      "name": "Plant_Moss_Block_Blue"
    },
    {
      "x": -17,
      "y": 25,
      "z": 1,
      "name": "Plant_Moss_Block_Blue"
    },
    {
      "x": -17,
      "y": 26,
      "z": 1,
      "name": "Plant_Moss_Short_Green_Dark"
    },
    {
      "x": -17,
      "y": 29,
      "z": 1,
      "name": "Wood_Azure_Trunk_Full"
    },
    {
      "x": -17,
      "y": 30,
      "z": 1,
      "name": "Wood_Azure_Trunk_Full"
    },
    {
      "x": -17,
      "y": 36,
      "z": 1,
      "name": "Wood_Azure_Trunk_Full"
    },
    {
      "x": -17,
      "y": 38,
      "z": 1,
      "name": "Wood_Azure_Branch_Corner",
      "rotation": 3
    },
    {
      "x": -17,
      "y": 39,
      "z": 1,
      "name": "Wood_Azure_Branch_Corner",
      "rotation": 8
    },
    {
      "x": -17,
      "y": 43,
      "z": 1,
      "name": "Plant_Leaves_Azure"
    },
    {
      "x": -17,
      "y": 44,
      "z": 1,
      "name": "Plant_Leaves_Azure"
    },
    {
      "x": -17,
      "y": 45,
      "z": 1,
      "name": "Plant_Leaves_Azure"
    },
    {
      "x": -17,
      "y": 17,
      "z": 2,
      "name": "Plant_Moss_Block_Blue"
    },
    {
      "x": -17,
      "y": 18,
      "z": 2,
      "name": "Plant_Moss_Block_Blue"
    },
    {
      "x": -17,
      "y": 19,
      "z": 2,
      "name": "Plant_Moss_Blue"
    },
    {
      "x": -17,
      "y": 22,
      "z": 2,
      "name": "Rock_Marble"
    },
    {
      "x": -17,
      "y": 23,
      "z": 2,
      "name": "Rock_Marble"
    },
    {
      "x": -17,
      "y": 24,
      "z": 2,
      "name": "Rock_Marble"
    },
    {
      "x": -17,
      "y": 25,
      "z": 2,
      "name": "Plant_Moss_Block_Blue"
    },
    {
      "x": -17,
      "y": 26,
      "z": 2,
      "name": "Plant_Moss_Block_Blue"
    },
    {
      "x": -17,
      "y": 27,
      "z": 2,
      "name": "Plant_Moss_Rug_Blue"
    },
    {
      "x": -17,
      "y": 39,
      "z": 2,
      "name": "Wood_Azure_Branch_Long",
      "rotation": 4
    },
    {
      "x": -17,
      "y": 43,
      "z": 2,
      "name": "Plant_Leaves_Azure"
    },
    {
      "x": -17,
      "y": 44,
      "z": 2,
      "name": "Plant_Leaves_Azure"
    },
    {
      "x": -17,
      "y": 45,
      "z": 2,
      "name": "Plant_Leaves_Azure"
    },
    {
      "x": -17,
      "y": 46,
      "z": 2,
      "name": "Plant_Leaves_Azure"
    },
    {
      "x": -17,
      "y": 47,
      "z": 2,
      "name": "Plant_Leaves_Azure"
    },
    {
      "x": -17,
      "y": 48,
      "z": 2,
      "name": "Plant_Fruit_Azure"
    },
    {
      "x": -17,
      "y": 17,
      "z": 3,
      "name": "Plant_Moss_Wall_Blue"
    },
    {
      "x": -17,
      "y": 22,
      "z": 3,
      "name": "Rock_Marble"
    },
    {
      "x": -17,
      "y": 23,
      "z": 3,
      "name": "Rock_Marble"
    },
    {
      "x": -17,
      "y": 24,
      "z": 3,
      "name": "Rock_Marble"
    },
    {
      "x": -17,
      "y": 25,
      "z": 3,
      "name": "Plant_Moss_Block_Blue"
    },
    {
      "x": -17,
      "y": 26,
      "z": 3,
      "name": "Plant_Moss_Block_Blue"
    },
    {
      "x": -17,
      "y": 27,
      "z": 3,
      "name": "Plant_Moss_Rug_Lime"
    },
    {
      "x": -17,
      "y": 39,
      "z": 3,
      "name": "Wood_Azure_Branch_Long",
      "rotation": 4
    },
    {
      "x": -17,
      "y": 40,
      "z": 3,
      "name": "Plant_Leaves_Azure"
    },
    {
      "x": -17,
      "y": 43,
      "z": 3,
      "name": "Plant_Leaves_Azure"
    },
    {
      "x": -17,
      "y": 44,
      "z": 3,
      "name": "Plant_Leaves_Azure"
    },
    {
      "x": -17,
      "y": 45,
      "z": 3,
      "name": "Plant_Leaves_Azure"
    },
    {
      "x": -17,
      "y": 46,
      "z": 3,
      "name": "Plant_Leaves_Azure"
    },
    {
      "x": -17,
      "y": 22,
      "z": 4,
      "name": "Rock_Marble"
    },
    {
      "x": -17,
      "y": 23,
      "z": 4,
      "name": "Rock_Marble"
    },
    {
      "x": -17,
      "y": 24,
      "z": 4,
      "name": "Rock_Marble"
    },
    {
      "x": -17,
      "y": 25,
      "z": 4,
      "name": "Rock_Marble"
    },
    {
      "x": -17,
      "y": 26,
      "z": 4,
      "name": "Plant_Moss_Short_Green_Dark"
    },
    {
      "x": -17,
      "y": 34,
      "z": 4,
      "name": "Plant_Leaves_Azure"
    },
    {
      "x": -17,
      "y": 38,
      "z": 4,
      "name": "Plant_Leaves_Azure"
    },
    {
      "x": -17,
      "y": 39,
      "z": 4,
      "name": "Plant_Leaves_Azure"
    },
    {
      "x": -17,
      "y": 40,
      "z": 4,
      "name": "Plant_Leaves_Azure"
    },
    {
      "x": -17,
      "y": 41,
      "z": 4,
      "name": "Plant_Leaves_Azure"
    },
    {
      "x": -17,
      "y": 34,
      "z": 5,
      "name": "Plant_Leaves_Azure"
    },
    {
      "x": -17,
      "y": 35,
      "z": 5,
      "name": "Plant_Leaves_Azure"
    },
    {
      "x": -17,
      "y": 38,
      "z": 5,
      "name": "Plant_Leaves_Azure"
    },
    {
      "x": -17,
      "y": 39,
      "z": 5,
      "name": "Plant_Leaves_Azure"
    },
    {
      "x": -17,
      "y": 40,
      "z": 5,
      "name": "Plant_Leaves_Azure"
    },
    {
      "x": -16,
      "y": 20,
      "z": -6,
      "name": "Rock_Marble"
    },
    {
      "x": -16,
      "y": 21,
      "z": -6,
      "name": "Rock_Marble"
    },
    {
      "x": -16,
      "y": 22,
      "z": -6,
      "name": "Plant_Moss_Block_Blue"
    },
    {
      "x": -16,
      "y": 23,
      "z": -6,
      "name": "Plant_Moss_Block_Blue"
    },
    {
      "x": -16,
      "y": 24,
      "z": -6,
      "name": "Plant_Moss_Rug_Blue"
    },
    {
      "x": -16,
      "y": 36,
      "z": -6,
      "name": "Plant_Leaves_Azure"
    },
    {
      "x": -16,
      "y": 37,
      "z": -6,
      "name": "Plant_Leaves_Azure"
    },
    {
      "x": -16,
      "y": 38,
      "z": -6,
      "name": "Plant_Leaves_Azure"
    },
    {
      "x": -16,
      "y": 39,
      "z": -6,
      "name": "Plant_Leaves_Azure"
    },
    {
      "x": -16,
      "y": 18,
      "z": -5,
      "name": "Rock_Marble"
    },
    {
      "x": -16,
      "y": 19,
      "z": -5,
      "name": "Rock_Marble"
    },
    {
      "x": -16,
      "y": 20,
      "z": -5,
      "name": "Rock_Marble"
    },
    {
      "x": -16,
      "y": 21,
      "z": -5,
      "name": "Rock_Marble"
    },
    {
      "x": -16,
      "y": 22,
      "z": -5,
      "name": "Plant_Moss_Block_Blue"
    },
    {
      "x": -16,
      "y": 23,
      "z": -5,
      "name": "Plant_Moss_Block_Blue"
    },
    {
      "x": -16,
      "y": 24,
      "z": -5,
      "name": "Plant_Moss_Rug_Lime"
    },
    {
      "x": -16,
      "y": 35,
      "z": -5,
      "name": "Plant_Leaves_Azure"
    },
    {
      "x": -16,
      "y": 36,
      "z": -5,
      "name": "Plant_Leaves_Azure"
    },
    {
      "x": -16,
      "y": 37,
      "z": -5,
      "name": "Plant_Leaves_Azure"
    },
    {
      "x": -16,
      "y": 38,
      "z": -5,
      "name": "Plant_Leaves_Azure"
    },
    {
      "x": -16,
      "y": 39,
      "z": -5,
      "name": "Plant_Leaves_Azure"
    },
    {
      "x": -16,
      "y": 40,
      "z": -5,
      "name": "Plant_Leaves_Azure"
    },
    {
      "x": -16,
      "y": 16,
      "z": -4,
      "name": "Rock_Marble"
    },
    {
      "x": -16,
      "y": 17,
      "z": -4,
      "name": "Rock_Marble"
    },
    {
      "x": -16,
      "y": 18,
      "z": -4,
      "name": "Rock_Marble"
    },
    {
      "x": -16,
      "y": 19,
      "z": -4,
      "name": "Rock_Marble"
    },
    {
      "x": -16,
      "y": 20,
      "z": -4,
      "name": "Rock_Marble"
    },
    {
      "x": -16,
      "y": 21,
      "z": -4,
      "name": "Rock_Marble"
    },
    {
      "x": -16,
      "y": 22,
      "z": -4,
      "name": "Plant_Moss_Block_Blue"
    },
    {
      "x": -16,
      "y": 23,
      "z": -4,
      "name": "Plant_Moss_Block_Blue"
    },
    {
      "x": -16,
      "y": 24,
      "z": -4,
      "name": "Plant_Moss_Rug_Lime"
    },
    {
      "x": -16,
      "y": 37,
      "z": -4,
      "name": "Plant_Leaves_Azure"
    },
    {
      "x": -16,
      "y": 38,
      "z": -4,
      "name": "Plant_Leaves_Azure"
    },
    {
      "x": -16,
      "y": 39,
      "z": -4,
      "name": "Wood_Azure_Branch_Long",
      "rotation": 4
    },
    {
      "x": -16,
      "y": 40,
      "z": -4,
      "name": "Plant_Leaves_Azure"
    },
    {
      "x": -16,
      "y": 15,
      "z": -3,
      "name": "Rock_Marble"
    },
    {
      "x": -16,
      "y": 16,
      "z": -3,
      "name": "Rock_Marble"
    },
    {
      "x": -16,
      "y": 17,
      "z": -3,
      "name": "Rock_Marble"
    },
    {
      "x": -16,
      "y": 18,
      "z": -3,
      "name": "Rock_Marble"
    },
    {
      "x": -16,
      "y": 19,
      "z": -3,
      "name": "Rock_Marble"
    },
    {
      "x": -16,
      "y": 20,
      "z": -3,
      "name": "Rock_Marble"
    },
    {
      "x": -16,
      "y": 21,
      "z": -3,
      "name": "Rock_Marble"
    },
    {
      "x": -16,
      "y": 22,
      "z": -3,
      "name": "Plant_Moss_Block_Blue"
    },
    {
      "x": -16,
      "y": 23,
      "z": -3,
      "name": "Plant_Moss_Block_Blue"
    },
    {
      "x": -16,
      "y": 24,
      "z": -3,
      "name": "Plant_Moss_Blue"
    },
    {
      "x": -16,
      "y": 39,
      "z": -3,
      "name": "Wood_Azure_Branch_Long",
      "rotation": 4
    },
    {
      "x": -16,
      "y": 44,
      "z": -3,
      "name": "Plant_Leaves_Azure"
    },
    {
      "x": -16,
      "y": 15,
      "z": -2,
      "name": "Plant_Moss_Wall_Blue",
      "rotation": 3
    },
    {
      "x": -16,
      "y": 16,
      "z": -2,
      "name": "Rock_Marble"
    },
    {
      "x": -16,
      "y": 17,
      "z": -2,
      "name": "Rock_Marble"
    },
    {
      "x": -16,
      "y": 18,
      "z": -2,
      "name": "Rock_Marble"
    },
    {
      "x": -16,
      "y": 19,
      "z": -2,
      "name": "Rock_Marble"
    },
    {
      "x": -16,
      "y": 20,
      "z": -2,
      "name": "Rock_Marble"
    },
    {
      "x": -16,
      "y": 21,
      "z": -2,
      "name": "Rock_Marble"
    },
    {
      "x": -16,
      "y": 22,
      "z": -2,
      "name": "Plant_Moss_Block_Blue"
    },
    {
      "x": -16,
      "y": 23,
      "z": -2,
      "name": "Plant_Moss_Block_Blue"
    },
    {
      "x": -16,
      "y": 24,
      "z": -2,
      "name": "Plant_Moss_Short_Green_Dark"
    },
    {
      "x": -16,
      "y": 28,
      "z": -2,
      "name": "Wood_Azure_Trunk_Full"
    },
    {
      "x": -16,
      "y": 29,
      "z": -2,
      "name": "Wood_Azure_Trunk_Full"
    },
    {
      "x": -16,
      "y": 39,
      "z": -2,
      "name": "Wood_Azure_Branch_Long",
      "rotation": 4
    },
    {
      "x": -16,
      "y": 44,
      "z": -2,
      "name": "Plant_Leaves_Azure"
    },
    {
      "x": -16,
      "y": 45,
      "z": -2,
      "name": "Plant_Leaves_Azure"
    },
    {
      "x": -16,
      "y": 46,
      "z": -2,
      "name": "Plant_Leaves_Azure"
    },
    {
      "x": -16,
      "y": 14,
      "z": -1,
      "name": "Plant_Moss_Wall_Blue",
      "rotation": 3
    },
    {
      "x": -16,
      "y": 15,
      "z": -1,
      "name": "Rock_Marble"
    },
    {
      "x": -16,
      "y": 16,
      "z": -1,
      "name": "Rock_Marble"
    },
    {
      "x": -16,
      "y": 17,
      "z": -1,
      "name": "Rock_Marble"
    },
    {
      "x": -16,
      "y": 18,
      "z": -1,
      "name": "Rock_Marble"
    },
    {
      "x": -16,
      "y": 19,
      "z": -1,
      "name": "Rock_Marble"
    },
    {
      "x": -16,
      "y": 20,
      "z": -1,
      "name": "Rock_Marble"
    },
    {
      "x": -16,
      "y": 21,
      "z": -1,
      "name": "Plant_Moss_Block_Blue"
    },
    {
      "x": -16,
      "y": 22,
      "z": -1,
      "name": "Plant_Moss_Block_Blue"
    },
    {
      "x": -16,
      "y": 23,
      "z": -1,
      "name": "Plant_Moss_Short_Green_Dark"
    },
    {
      "x": -16,
      "y": 27,
      "z": -1,
      "name": "Wood_Azure_Roots"
    },
    {
      "x": -16,
      "y": 28,
      "z": -1,
      "name": "Wood_Azure_Trunk_Full"
    },
    {
      "x": -16,
      "y": 29,
      "z": -1,
      "name": "Wood_Azure_Trunk"
    },
    {
      "x": -16,
      "y": 30,
      "z": -1,
      "name": "Wood_Azure_Trunk_Full"
    },
    {
      "x": -16,
      "y": 32,
      "z": -1,
      "name": "Plant_Moss_Wall_Blue",
      "rotation": 2
    },
    {
      "x": -16,
      "y": 39,
      "z": -1,
      "name": "Wood_Azure_Trunk_Full"
    },
    {
      "x": -16,
      "y": 40,
      "z": -1,
      "name": "Wood_Azure_Trunk"
    },
    {
      "x": -16,
      "y": 41,
      "z": -1,
      "name": "Wood_Azure_Trunk_Full"
    },
    {
      "x": -16,
      "y": 44,
      "z": -1,
      "name": "Wood_Azure_Branch_Long",
      "rotation": 4
    },
    {
      "x": -16,
      "y": 48,
      "z": -1,
      "name": "Plant_Leaves_Azure"
    },
    {
      "x": -16,
      "y": 49,
      "z": -1,
      "name": "Plant_Leaves_Azure"
    },
    {
      "x": -16,
      "y": 50,
      "z": -1,
      "name": "Plant_Leaves_Azure"
    },
    {
      "x": -16,
      "y": 51,
      "z": -1,
      "name": "Plant_Leaves_Azure"
    },
    {
      "x": -16,
      "y": 15,
      "z": 0,
      "name": "Rock_Marble"
    },
    {
      "x": -16,
      "y": 16,
      "z": 0,
      "name": "Rock_Marble"
    },
    {
      "x": -16,
      "y": 17,
      "z": 0,
      "name": "Rock_Marble"
    },
    {
      "x": -16,
      "y": 18,
      "z": 0,
      "name": "Rock_Marble"
    },
    {
      "x": -16,
      "y": 19,
      "z": 0,
      "name": "Rock_Marble"
    },
    {
      "x": -16,
      "y": 20,
      "z": 0,
      "name": "Rock_Marble"
    },
    {
      "x": -16,
      "y": 21,
      "z": 0,
      "name": "Rock_Marble"
    },
    {
      "x": -16,
      "y": 22,
      "z": 0,
      "name": "Rock_Marble"
    },
    {
      "x": -16,
      "y": 23,
      "z": 0,
      "name": "Rock_Marble"
    },
    {
      "x": -16,
      "y": 24,
      "z": 0,
      "name": "Plant_Moss_Block_Blue"
    },
    {
      "x": -16,
      "y": 25,
      "z": 0,
      "name": "Plant_Moss_Block_Blue"
    },
    {
      "x": -16,
      "y": 26,
      "z": 0,
      "name": "Plant_Moss_Rug_Lime"
    },
    {
      "x": -16,
      "y": 29,
      "z": 0,
      "name": "Wood_Azure_Trunk_Full"
    },
    {
      "x": -16,
      "y": 30,
      "z": 0,
      "name": "Wood_Azure_Trunk"
    },
    {
      "x": -16,
      "y": 31,
      "z": 0,
      "name": "Wood_Azure_Trunk"
    },
    {
      "x": -16,
      "y": 32,
      "z": 0,
      "name": "Wood_Azure_Trunk_Full"
    },
    {
      "x": -16,
      "y": 33,
      "z": 0,
      "name": "Plant_Moss_Rug_Blue"
    },
    {
      "x": -16,
      "y": 36,
      "z": 0,
      "name": "Wood_Azure_Trunk_Full"
    },
    {
      "x": -16,
      "y": 37,
      "z": 0,
      "name": "Wood_Azure_Trunk"
    },
    {
      "x": -16,
      "y": 38,
      "z": 0,
      "name": "Wood_Azure_Trunk"
    },
    {
      "x": -16,
      "y": 39,
      "z": 0,
      "name": "Wood_Azure_Trunk"
    },
    {
      "x": -16,
      "y": 40,
      "z": 0,
      "name": "Wood_Azure_Trunk"
    },
    {
      "x": -16,
      "y": 41,
      "z": 0,
      "name": "Wood_Azure_Trunk"
    },
    {
      "x": -16,
      "y": 42,
      "z": 0,
      "name": "Wood_Azure_Trunk"
    },
    {
      "x": -16,
      "y": 43,
      "z": 0,
      "name": "Wood_Azure_Trunk"
    },
    {
      "x": -16,
      "y": 44,
      "z": 0,
      "name": "Wood_Azure_Trunk"
    },
    {
      "x": -16,
      "y": 45,
      "z": 0,
      "name": "Wood_Azure_Trunk_Full"
    },
    {
      "x": -16,
      "y": 46,
      "z": 0,
      "name": "Wood_Azure_Branch_Long"
    },
    {
      "x": -16,
      "y": 47,
      "z": 0,
      "name": "Wood_Azure_Branch_Long"
    },
    {
      "x": -16,
      "y": 48,
      "z": 0,
      "name": "Wood_Azure_Branch_Long"
    },
    {
      "x": -16,
      "y": 49,
      "z": 0,
      "name": "Plant_Leaves_Azure"
    },
    {
      "x": -16,
      "y": 50,
      "z": 0,
      "name": "Plant_Leaves_Azure"
    },
    {
      "x": -16,
      "y": 14,
      "z": 1,
      "name": "Rock_Marble"
    },
    {
      "x": -16,
      "y": 15,
      "z": 1,
      "name": "Rock_Marble"
    },
    {
      "x": -16,
      "y": 16,
      "z": 1,
      "name": "Rock_Marble"
    },
    {
      "x": -16,
      "y": 17,
      "z": 1,
      "name": "Rock_Marble"
    },
    {
      "x": -16,
      "y": 18,
      "z": 1,
      "name": "Rock_Marble"
    },
    {
      "x": -16,
      "y": 19,
      "z": 1,
      "name": "Rock_Marble"
    },
    {
      "x": -16,
      "y": 20,
      "z": 1,
      "name": "Rock_Marble"
    },
    {
      "x": -16,
      "y": 21,
      "z": 1,
      "name": "Rock_Marble"
    },
    {
      "x": -16,
      "y": 22,
      "z": 1,
      "name": "Rock_Marble"
    },
    {
      "x": -16,
      "y": 23,
      "z": 1,
      "name": "Rock_Marble"
    },
    {
      "x": -16,
      "y": 24,
      "z": 1,
      "name": "Rock_Marble"
    },
    {
      "x": -16,
      "y": 25,
      "z": 1,
      "name": "Rock_Marble"
    },
    {
      "x": -16,
      "y": 26,
      "z": 1,
      "name": "Plant_Moss_Block_Blue"
    },
    {
      "x": -16,
      "y": 27,
      "z": 1,
      "name": "Plant_Moss_Block_Blue"
    },
    {
      "x": -16,
      "y": 28,
      "z": 1,
      "name": "Plant_Moss_Rug_Blue"
    },
    {
      "x": -16,
      "y": 30,
      "z": 1,
      "name": "Wood_Azure_Trunk_Full"
    },
    {
      "x": -16,
      "y": 31,
      "z": 1,
      "name": "Wood_Azure_Trunk"
    },
    {
      "x": -16,
      "y": 32,
      "z": 1,
      "name": "Wood_Azure_Trunk"
    },
    {
      "x": -16,
      "y": 33,
      "z": 1,
      "name": "Wood_Azure_Trunk"
    },
    {
      "x": -16,
      "y": 34,
      "z": 1,
      "name": "Wood_Azure_Trunk"
    },
    {
      "x": -16,
      "y": 35,
      "z": 1,
      "name": "Wood_Azure_Trunk"
    },
    {
      "x": -16,
      "y": 36,
      "z": 1,
      "name": "Wood_Azure_Trunk"
    },
    {
      "x": -16,
      "y": 37,
      "z": 1,
      "name": "Wood_Azure_Trunk"
    },
    {
      "x": -16,
      "y": 38,
      "z": 1,
      "name": "Wood_Azure_Trunk_Full"
    },
    {
      "x": -16,
      "y": 40,
      "z": 1,
      "name": "Plant_Moss_Wall_Blue",
      "rotation": 3
    },
    {
      "x": -16,
      "y": 45,
      "z": 1,
      "name": "Wood_Azure_Branch_Long",
      "rotation": 4
    },
    {
      "x": -16,
      "y": 47,
      "z": 1,
      "name": "Plant_Leaves_Azure"
    },
    {
      "x": -16,
      "y": 48,
      "z": 1,
      "name": "Plant_Leaves_Azure"
    },
    {
      "x": -16,
      "y": 16,
      "z": 2,
      "name": "Rock_Marble"
    },
    {
      "x": -16,
      "y": 17,
      "z": 2,
      "name": "Rock_Marble"
    },
    {
      "x": -16,
      "y": 18,
      "z": 2,
      "name": "Rock_Marble"
    },
    {
      "x": -16,
      "y": 19,
      "z": 2,
      "name": "Rock_Marble"
    },
    {
      "x": -16,
      "y": 20,
      "z": 2,
      "name": "Rock_Marble"
    },
    {
      "x": -16,
      "y": 21,
      "z": 2,
      "name": "Rock_Marble"
    },
    {
      "x": -16,
      "y": 22,
      "z": 2,
      "name": "Rock_Marble"
    },
    {
      "x": -16,
      "y": 23,
      "z": 2,
      "name": "Rock_Marble"
    },
    {
      "x": -16,
      "y": 24,
      "z": 2,
      "name": "Rock_Marble"
    },
    {
      "x": -16,
      "y": 25,
      "z": 2,
      "name": "Rock_Marble"
    },
    {
      "x": -16,
      "y": 26,
      "z": 2,
      "name": "Plant_Moss_Block_Blue"
    },
    {
      "x": -16,
      "y": 27,
      "z": 2,
      "name": "Plant_Moss_Block_Blue"
    },
    {
      "x": -16,
      "y": 28,
      "z": 2,
      "name": "Plant_Moss_Blue"
    },
    {
      "x": -16,
      "y": 30,
      "z": 2,
      "name": "Wood_Azure_Trunk_Full"
    },
    {
      "x": -16,
      "y": 31,
      "z": 2,
      "name": "Wood_Azure_Trunk"
    },
    {
      "x": -16,
      "y": 32,
      "z": 2,
      "name": "Wood_Azure_Trunk"
    },
    {
      "x": -16,
      "y": 33,
      "z": 2,
      "name": "Wood_Azure_Trunk"
    },
    {
      "x": -16,
      "y": 34,
      "z": 2,
      "name": "Wood_Azure_Trunk_Full"
    },
    {
      "x": -16,
      "y": 45,
      "z": 2,
      "name": "Plant_Leaves_Azure"
    },
    {
      "x": -16,
      "y": 46,
      "z": 2,
      "name": "Plant_Leaves_Azure"
    },
    {
      "x": -16,
      "y": 47,
      "z": 2,
      "name": "Plant_Leaves_Azure"
    },
    {
      "x": -16,
      "y": 16,
      "z": 3,
      "name": "Plant_Moss_Wall_Blue"
    },
    {
      "x": -16,
      "y": 18,
      "z": 3,
      "name": "Rock_Marble"
    },
    {
      "x": -16,
      "y": 19,
      "z": 3,
      "name": "Rock_Marble"
    },
    {
      "x": -16,
      "y": 20,
      "z": 3,
      "name": "Rock_Marble"
    },
    {
      "x": -16,
      "y": 21,
      "z": 3,
      "name": "Rock_Marble"
    },
    {
      "x": -16,
      "y": 22,
      "z": 3,
      "name": "Rock_Marble"
    },
    {
      "x": -16,
      "y": 23,
      "z": 3,
      "name": "Rock_Marble"
    },
    {
      "x": -16,
      "y": 24,
      "z": 3,
      "name": "Rock_Marble"
    },
    {
      "x": -16,
      "y": 25,
      "z": 3,
      "name": "Rock_Marble"
    },
    {
      "x": -16,
      "y": 26,
      "z": 3,
      "name": "Rock_Marble"
    },
    {
      "x": -16,
      "y": 27,
      "z": 3,
      "name": "Plant_Moss_Block_Blue"
    },
    {
      "x": -16,
      "y": 28,
      "z": 3,
      "name": "Plant_Moss_Block_Blue"
    },
    {
      "x": -16,
      "y": 29,
      "z": 3,
      "name": "Plant_Moss_Rug_Blue"
    },
    {
      "x": -16,
      "y": 39,
      "z": 3,
      "name": "Plant_Leaves_Azure"
    },
    {
      "x": -16,
      "y": 40,
      "z": 3,
      "name": "Plant_Leaves_Azure"
    },
    {
      "x": -16,
      "y": 41,
      "z": 3,
      "name": "Plant_Leaves_Azure"
    },
    {
      "x": -16,
      "y": 45,
      "z": 3,
      "name": "Plant_Leaves_Azure"
    },
    {
      "x": -16,
      "y": 46,
      "z": 3,
      "name": "Plant_Leaves_Azure"
    },
    {
      "x": -16,
      "y": 20,
      "z": 4,
      "name": "Rock_Marble"
    },
    {
      "x": -16,
      "y": 21,
      "z": 4,
      "name": "Rock_Marble"
    },
    {
      "x": -16,
      "y": 22,
      "z": 4,
      "name": "Rock_Marble"
    },
    {
      "x": -16,
      "y": 23,
      "z": 4,
      "name": "Rock_Marble"
    },
    {
      "x": -16,
      "y": 24,
      "z": 4,
      "name": "Rock_Marble"
    },
    {
      "x": -16,
      "y": 25,
      "z": 4,
      "name": "Rock_Marble"
    },
    {
      "x": -16,
      "y": 26,
      "z": 4,
      "name": "Plant_Moss_Block_Blue"
    },
    {
      "x": -16,
      "y": 27,
      "z": 4,
      "name": "Plant_Moss_Block_Blue"
    },
    {
      "x": -16,
      "y": 28,
      "z": 4,
      "name": "Plant_Moss_Blue"
    },
    {
      "x": -16,
      "y": 33,
      "z": 4,
      "name": "Plant_Leaves_Azure"
    },
    {
      "x": -16,
      "y": 34,
      "z": 4,
      "name": "Plant_Leaves_Azure"
    },
    {
      "x": -16,
      "y": 35,
      "z": 4,
      "name": "Plant_Leaves_Azure"
    },
    {
      "x": -16,
      "y": 39,
      "z": 4,
      "name": "Plant_Leaves_Azure"
    },
    {
      "x": -16,
      "y": 40,
      "z": 4,
      "name": "Plant_Leaves_Azure"
    },
    {
      "x": -16,
      "y": 41,
      "z": 4,
      "name": "Plant_Leaves_Azure"
    },
    {
      "x": -16,
      "y": 42,
      "z": 4,
      "name": "Plant_Fruit_Azure"
    },
    {
      "x": -16,
      "y": 22,
      "z": 5,
      "name": "Rock_Marble"
    },
    {
      "x": -16,
      "y": 23,
      "z": 5,
      "name": "Rock_Marble"
    },
    {
      "x": -16,
      "y": 24,
      "z": 5,
      "name": "Rock_Marble"
    },
    {
      "x": -16,
      "y": 25,
      "z": 5,
      "name": "Rock_Marble"
    },
    {
      "x": -16,
      "y": 26,
      "z": 5,
      "name": "Plant_Moss_Block_Blue"
    },
    {
      "x": -16,
      "y": 27,
      "z": 5,
      "name": "Plant_Moss_Rug_Lime"
    },
    {
      "x": -16,
      "y": 33,
      "z": 5,
      "name": "Plant_Leaves_Azure"
    },
    {
      "x": -16,
      "y": 34,
      "z": 5,
      "name": "Plant_Leaves_Azure"
    },
    {
      "x": -16,
      "y": 35,
      "z": 5,
      "name": "Plant_Leaves_Azure"
    },
    {
      "x": -16,
      "y": 36,
      "z": 5,
      "name": "Plant_Leaves_Azure"
    },
    {
      "x": -16,
      "y": 37,
      "z": 5,
      "name": "Plant_Fruit_Azure"
    },
    {
      "x": -16,
      "y": 40,
      "z": 5,
      "name": "Plant_Leaves_Azure"
    },
    {
      "x": -16,
      "y": 41,
      "z": 5,
      "name": "Plant_Leaves_Azure"
    },
    {
      "x": -16,
      "y": 34,
      "z": 6,
      "name": "Plant_Leaves_Azure"
    },
    {
      "x": -16,
      "y": 35,
      "z": 6,
      "name": "Plant_Leaves_Azure"
    },
    {
      "x": -15,
      "y": 20,
      "z": -7,
      "name": "Rock_Marble"
    },
    {
      "x": -15,
      "y": 21,
      "z": -7,
      "name": "Rock_Marble"
    },
    {
      "x": -15,
      "y": 22,
      "z": -7,
      "name": "Plant_Moss_Block_Blue"
    },
    {
      "x": -15,
      "y": 23,
      "z": -7,
      "name": "Plant_Moss_Block_Blue"
    },
    {
      "x": -15,
      "y": 24,
      "z": -7,
      "name": "Plant_Moss_Rug_Lime"
    },
    {
      "x": -15,
      "y": 19,
      "z": -6,
      "name": "Rock_Marble"
    },
    {
      "x": -15,
      "y": 20,
      "z": -6,
      "name": "Rock_Marble"
    },
    {
      "x": -15,
      "y": 21,
      "z": -6,
      "name": "Rock_Marble"
    },
    {
      "x": -15,
      "y": 22,
      "z": -6,
      "name": "Plant_Moss_Block_Blue"
    },
    {
      "x": -15,
      "y": 23,
      "z": -6,
      "name": "Plant_Moss_Block_Blue"
    },
    {
      "x": -15,
      "y": 24,
      "z": -6,
      "name": "Plant_Moss_Rug_Lime"
    },
    {
      "x": -15,
      "y": 35,
      "z": -6,
      "name": "Plant_Leaves_Azure"
    },
    {
      "x": -15,
      "y": 36,
      "z": -6,
      "name": "Plant_Leaves_Azure"
    },
    {
      "x": -15,
      "y": 37,
      "z": -6,
      "name": "Plant_Leaves_Azure"
    },
    {
      "x": -15,
      "y": 38,
      "z": -6,
      "name": "Plant_Leaves_Azure"
    },
    {
      "x": -15,
      "y": 17,
      "z": -5,
      "name": "Rock_Marble"
    },
    {
      "x": -15,
      "y": 18,
      "z": -5,
      "name": "Rock_Marble"
    },
    {
      "x": -15,
      "y": 19,
      "z": -5,
      "name": "Rock_Marble"
    },
    {
      "x": -15,
      "y": 20,
      "z": -5,
      "name": "Rock_Marble"
    },
    {
      "x": -15,
      "y": 21,
      "z": -5,
      "name": "Rock_Marble"
    },
    {
      "x": -15,
      "y": 22,
      "z": -5,
      "name": "Rock_Marble"
    },
    {
      "x": -15,
      "y": 23,
      "z": -5,
      "name": "Plant_Moss_Block_Blue"
    },
    {
      "x": -15,
      "y": 24,
      "z": -5,
      "name": "Plant_Moss_Block_Blue"
    },
    {
      "x": -15,
      "y": 25,
      "z": -5,
      "name": "Plant_Moss_Rug_Lime"
    },
    {
      "x": -15,
      "y": 35,
      "z": -5,
      "name": "Plant_Leaves_Azure"
    },
    {
      "x": -15,
      "y": 36,
      "z": -5,
      "name": "Plant_Leaves_Azure"
    },
    {
      "x": -15,
      "y": 37,
      "z": -5,
      "name": "Plant_Leaves_Azure"
    },
    {
      "x": -15,
      "y": 38,
      "z": -5,
      "name": "Plant_Leaves_Azure"
    },
    {
      "x": -15,
      "y": 39,
      "z": -5,
      "name": "Plant_Leaves_Azure"
    },
    {
      "x": -15,
      "y": 40,
      "z": -5,
      "name": "Plant_Fruit_Azure"
    },
    {
      "x": -15,
      "y": 14,
      "z": -4,
      "name": "Rock_Marble"
    },
    {
      "x": -15,
      "y": 15,
      "z": -4,
      "name": "Rock_Marble"
    },
    {
      "x": -15,
      "y": 16,
      "z": -4,
      "name": "Rock_Marble"
    },
    {
      "x": -15,
      "y": 17,
      "z": -4,
      "name": "Rock_Marble"
    },
    {
      "x": -15,
      "y": 18,
      "z": -4,
      "name": "Rock_Marble"
    },
    {
      "x": -15,
      "y": 19,
      "z": -4,
      "name": "Rock_Marble"
    },
    {
      "x": -15,
      "y": 20,
      "z": -4,
      "name": "Rock_Marble"
    },
    {
      "x": -15,
      "y": 21,
      "z": -4,
      "name": "Rock_Marble"
    },
    {
      "x": -15,
      "y": 22,
      "z": -4,
      "name": "Rock_Marble"
    },
    {
      "x": -15,
      "y": 23,
      "z": -4,
      "name": "Plant_Moss_Block_Blue"
    },
    {
      "x": -15,
      "y": 24,
      "z": -4,
      "name": "Plant_Moss_Block_Blue"
    },
    {
      "x": -15,
      "y": 25,
      "z": -4,
      "name": "Plant_Moss_Rug_Blue"
    },
    {
      "x": -15,
      "y": 36,
      "z": -4,
      "name": "Plant_Leaves_Azure"
    },
    {
      "x": -15,
      "y": 37,
      "z": -4,
      "name": "Wood_Azure_Branch_Long",
      "rotation": 4
    },
    {
      "x": -15,
      "y": 38,
      "z": -4,
      "name": "Plant_Leaves_Azure"
    },
    {
      "x": -15,
      "y": 39,
      "z": -4,
      "name": "Plant_Leaves_Azure"
    },
    {
      "x": -15,
      "y": 14,
      "z": -3,
      "name": "Rock_Marble"
    },
    {
      "x": -15,
      "y": 15,
      "z": -3,
      "name": "Rock_Marble"
    },
    {
      "x": -15,
      "y": 16,
      "z": -3,
      "name": "Rock_Marble"
    },
    {
      "x": -15,
      "y": 17,
      "z": -3,
      "name": "Rock_Marble"
    },
    {
      "x": -15,
      "y": 18,
      "z": -3,
      "name": "Rock_Marble"
    },
    {
      "x": -15,
      "y": 19,
      "z": -3,
      "name": "Rock_Marble"
    },
    {
      "x": -15,
      "y": 20,
      "z": -3,
      "name": "Rock_Marble"
    },
    {
      "x": -15,
      "y": 21,
      "z": -3,
      "name": "Rock_Marble"
    },
    {
      "x": -15,
      "y": 22,
      "z": -3,
      "name": "Rock_Marble"
    },
    {
      "x": -15,
      "y": 23,
      "z": -3,
      "name": "Plant_Moss_Block_Blue"
    },
    {
      "x": -15,
      "y": 24,
      "z": -3,
      "name": "Plant_Moss_Block_Blue"
    },
    {
      "x": -15,
      "y": 25,
      "z": -3,
      "name": "Plant_Moss_Blue"
    },
    {
      "x": -15,
      "y": 37,
      "z": -3,
      "name": "Wood_Azure_Branch_Long",
      "rotation": 4
    },
    {
      "x": -15,
      "y": 43,
      "z": -3,
      "name": "Plant_Leaves_Azure"
    },
    {
      "x": -15,
      "y": 44,
      "z": -3,
      "name": "Plant_Leaves_Azure"
    },
    {
      "x": -15,
      "y": 45,
      "z": -3,
      "name": "Plant_Leaves_Azure"
    },
    {
      "x": -15,
      "y": 15,
      "z": -2,
      "name": "Rock_Marble"
    },
    {
      "x": -15,
      "y": 16,
      "z": -2,
      "name": "Rock_Marble"
    },
    {
      "x": -15,
      "y": 17,
      "z": -2,
      "name": "Rock_Marble"
    },
    {
      "x": -15,
      "y": 18,
      "z": -2,
      "name": "Rock_Marble"
    },
    {
      "x": -15,
      "y": 19,
      "z": -2,
      "name": "Rock_Marble"
    },
    {
      "x": -15,
      "y": 20,
      "z": -2,
      "name": "Rock_Marble"
    },
    {
      "x": -15,
      "y": 21,
      "z": -2,
      "name": "Rock_Marble"
    },
    {
      "x": -15,
      "y": 22,
      "z": -2,
      "name": "Rock_Marble"
    },
    {
      "x": -15,
      "y": 23,
      "z": -2,
      "name": "Rock_Marble"
    },
    {
      "x": -15,
      "y": 24,
      "z": -2,
      "name": "Rock_Marble"
    },
    {
      "x": -15,
      "y": 25,
      "z": -2,
      "name": "Plant_Moss_Block_Blue"
    },
    {
      "x": -15,
      "y": 26,
      "z": -2,
      "name": "Plant_Moss_Block_Blue"
    },
    {
      "x": -15,
      "y": 27,
      "z": -2,
      "name": "Plant_Moss_Blue"
    },
    {
      "x": -15,
      "y": 37,
      "z": -2,
      "name": "Wood_Azure_Branch_Long",
      "rotation": 4
    },
    {
      "x": -15,
      "y": 42,
      "z": -2,
      "name": "Plant_Leaves_Azure"
    },
    {
      "x": -15,
      "y": 43,
      "z": -2,
      "name": "Plant_Leaves_Azure"
    },
    {
      "x": -15,
      "y": 44,
      "z": -2,
      "name": "Plant_Leaves_Azure"
    },
    {
      "x": -15,
      "y": 45,
      "z": -2,
      "name": "Plant_Leaves_Azure"
    },
    {
      "x": -15,
      "y": 14,
      "z": -1,
      "name": "Rock_Marble"
    },
    {
      "x": -15,
      "y": 15,
      "z": -1,
      "name": "Rock_Marble"
    },
    {
      "x": -15,
      "y": 16,
      "z": -1,
      "name": "Rock_Marble"
    },
    {
      "x": -15,
      "y": 17,
      "z": -1,
      "name": "Rock_Marble"
    },
    {
      "x": -15,
      "y": 18,
      "z": -1,
      "name": "Rock_Marble"
    },
    {
      "x": -15,
      "y": 19,
      "z": -1,
      "name": "Rock_Marble"
    },
    {
      "x": -15,
      "y": 20,
      "z": -1,
      "name": "Rock_Marble"
    },
    {
      "x": -15,
      "y": 21,
      "z": -1,
      "name": "Rock_Marble"
    },
    {
      "x": -15,
      "y": 22,
      "z": -1,
      "name": "Rock_Marble"
    },
    {
      "x": -15,
      "y": 23,
      "z": -1,
      "name": "Rock_Marble"
    },
    {
      "x": -15,
      "y": 24,
      "z": -1,
      "name": "Rock_Marble"
    },
    {
      "x": -15,
      "y": 25,
      "z": -1,
      "name": "Rock_Marble"
    },
    {
      "x": -15,
      "y": 26,
      "z": -1,
      "name": "Plant_Moss_Block_Blue"
    },
    {
      "x": -15,
      "y": 27,
      "z": -1,
      "name": "Plant_Moss_Block_Blue"
    },
    {
      "x": -15,
      "y": 28,
      "z": -1,
      "name": "Plant_Moss_Rug_Lime"
    },
    {
      "x": -15,
      "y": 29,
      "z": -1,
      "name": "Wood_Azure_Trunk_Full"
    },
    {
      "x": -15,
      "y": 30,
      "z": -1,
      "name": "Wood_Azure_Trunk"
    },
    {
      "x": -15,
      "y": 31,
      "z": -1,
      "name": "Wood_Azure_Trunk_Full"
    },
    {
      "x": -15,
      "y": 37,
      "z": -1,
      "name": "Wood_Azure_Trunk_Full"
    },
    {
      "x": -15,
      "y": 38,
      "z": -1,
      "name": "Wood_Azure_Trunk"
    },
    {
      "x": -15,
      "y": 39,
      "z": -1,
      "name": "Wood_Azure_Trunk_Full"
    },
    {
      "x": -15,
      "y": 42,
      "z": -1,
      "name": "Wood_Azure_Branch_Long",
      "rotation": 4
    },
    {
      "x": -15,
      "y": 47,
      "z": -1,
      "name": "Plant_Leaves_Azure"
    },
    {
      "x": -15,
      "y": 48,
      "z": -1,
      "name": "Plant_Leaves_Azure"
    },
    {
      "x": -15,
      "y": 49,
      "z": -1,
      "name": "Plant_Leaves_Azure"
    },
    {
      "x": -15,
      "y": 50,
      "z": -1,
      "name": "Plant_Leaves_Azure"
    },
    {
      "x": -15,
      "y": 14,
      "z": 0,
      "name": "Rock_Marble"
    },
    {
      "x": -15,
      "y": 15,
      "z": 0,
      "name": "Rock_Marble"
    },
    {
      "x": -15,
      "y": 16,
      "z": 0,
      "name": "Rock_Marble"
    },
    {
      "x": -15,
      "y": 17,
      "z": 0,
      "name": "Rock_Marble"
    },
    {
      "x": -15,
      "y": 18,
      "z": 0,
      "name": "Rock_Marble"
    },
    {
      "x": -15,
      "y": 19,
      "z": 0,
      "name": "Rock_Marble"
    },
    {
      "x": -15,
      "y": 20,
      "z": 0,
      "name": "Rock_Marble"
    },
    {
      "x": -15,
      "y": 21,
      "z": 0,
      "name": "Rock_Marble"
    },
    {
      "x": -15,
      "y": 22,
      "z": 0,
      "name": "Rock_Marble"
    },
    {
      "x": -15,
      "y": 23,
      "z": 0,
      "name": "Rock_Marble"
    },
    {
      "x": -15,
      "y": 24,
      "z": 0,
      "name": "Rock_Marble"
    },
    {
      "x": -15,
      "y": 25,
      "z": 0,
      "name": "Rock_Marble"
    },
    {
      "x": -15,
      "y": 26,
      "z": 0,
      "name": "Rock_Marble"
    },
    {
      "x": -15,
      "y": 27,
      "z": 0,
      "name": "Plant_Moss_Block_Blue"
    },
    {
      "x": -15,
      "y": 28,
      "z": 0,
      "name": "Plant_Moss_Block_Blue"
    },
    {
      "x": -15,
      "y": 29,
      "z": 0,
      "name": "Wood_Azure_Trunk_Full"
    },
    {
      "x": -15,
      "y": 30,
      "z": 0,
      "name": "Wood_Azure_Trunk"
    },
    {
      "x": -15,
      "y": 31,
      "z": 0,
      "name": "Wood_Azure_Trunk"
    },
    {
      "x": -15,
      "y": 32,
      "z": 0,
      "name": "Wood_Azure_Trunk"
    },
    {
      "x": -15,
      "y": 33,
      "z": 0,
      "name": "Wood_Azure_Trunk"
    },
    {
      "x": -15,
      "y": 34,
      "z": 0,
      "name": "Wood_Azure_Trunk"
    },
    {
      "x": -15,
      "y": 35,
      "z": 0,
      "name": "Wood_Azure_Trunk"
    },
    {
      "x": -15,
      "y": 36,
      "z": 0,
      "name": "Wood_Azure_Trunk"
    },
    {
      "x": -15,
      "y": 37,
      "z": 0,
      "name": "Wood_Azure_Trunk"
    },
    {
      "x": -15,
      "y": 38,
      "z": 0,
      "name": "Wood_Azure_Trunk"
    },
    {
      "x": -15,
      "y": 39,
      "z": 0,
      "name": "Wood_Azure_Trunk"
    },
    {
      "x": -15,
      "y": 40,
      "z": 0,
      "name": "Wood_Azure_Trunk"
    },
    {
      "x": -15,
      "y": 41,
      "z": 0,
      "name": "Wood_Azure_Trunk"
    },
    {
      "x": -15,
      "y": 42,
      "z": 0,
      "name": "Wood_Azure_Trunk_Full"
    },
    {
      "x": -15,
      "y": 45,
      "z": 0,
      "name": "Plant_Moss_Wall_Blue",
      "rotation": 1
    },
    {
      "x": -15,
      "y": 47,
      "z": 0,
      "name": "Plant_Leaves_Azure"
    },
    {
      "x": -15,
      "y": 48,
      "z": 0,
      "name": "Plant_Leaves_Azure"
    },
    {
      "x": -15,
      "y": 49,
      "z": 0,
      "name": "Plant_Leaves_Azure"
    },
    {
      "x": -15,
      "y": 50,
      "z": 0,
      "name": "Plant_Fruit_Azure"
    },
    {
      "x": -15,
      "y": 14,
      "z": 1,
      "name": "Rock_Marble"
    },
    {
      "x": -15,
      "y": 15,
      "z": 1,
      "name": "Rock_Marble"
    },
    {
      "x": -15,
      "y": 16,
      "z": 1,
      "name": "Rock_Marble"
    },
    {
      "x": -15,
      "y": 17,
      "z": 1,
      "name": "Rock_Marble"
    },
    {
      "x": -15,
      "y": 18,
      "z": 1,
      "name": "Rock_Marble"
    },
    {
      "x": -15,
      "y": 19,
      "z": 1,
      "name": "Rock_Marble"
    },
    {
      "x": -15,
      "y": 20,
      "z": 1,
      "name": "Rock_Marble"
    },
    {
      "x": -15,
      "y": 21,
      "z": 1,
      "name": "Rock_Marble"
    },
    {
      "x": -15,
      "y": 22,
      "z": 1,
      "name": "Rock_Marble"
    },
    {
      "x": -15,
      "y": 23,
      "z": 1,
      "name": "Rock_Marble"
    },
    {
      "x": -15,
      "y": 24,
      "z": 1,
      "name": "Rock_Marble"
    },
    {
      "x": -15,
      "y": 25,
      "z": 1,
      "name": "Rock_Marble"
    },
    {
      "x": -15,
      "y": 26,
      "z": 1,
      "name": "Rock_Marble"
    },
    {
      "x": -15,
      "y": 27,
      "z": 1,
      "name": "Plant_Moss_Block_Blue"
    },
    {
      "x": -15,
      "y": 28,
      "z": 1,
      "name": "Plant_Moss_Block_Blue"
    },
    {
      "x": -15,
      "y": 29,
      "z": 1,
      "name": "Plant_Moss_Blue"
    },
    {
      "x": -15,
      "y": 30,
      "z": 1,
      "name": "Wood_Azure_Trunk"
    },
    {
      "x": -15,
      "y": 31,
      "z": 1,
      "name": "Wood_Azure_Trunk"
    },
    {
      "x": -15,
      "y": 32,
      "z": 1,
      "name": "Wood_Azure_Trunk"
    },
    {
      "x": -15,
      "y": 33,
      "z": 1,
      "name": "Wood_Azure_Trunk"
    },
    {
      "x": -15,
      "y": 34,
      "z": 1,
      "name": "Wood_Azure_Trunk"
    },
    {
      "x": -15,
      "y": 35,
      "z": 1,
      "name": "Wood_Azure_Trunk"
    },
    {
      "x": -15,
      "y": 36,
      "z": 1,
      "name": "Wood_Azure_Trunk"
    },
    {
      "x": -15,
      "y": 37,
      "z": 1,
      "name": "Wood_Azure_Trunk"
    },
    {
      "x": -15,
      "y": 38,
      "z": 1,
      "name": "Wood_Azure_Trunk"
    },
    {
      "x": -15,
      "y": 39,
      "z": 1,
      "name": "Wood_Azure_Trunk"
    },
    {
      "x": -15,
      "y": 40,
      "z": 1,
      "name": "Wood_Azure_Trunk_Full"
    },
    {
      "x": -15,
      "y": 41,
      "z": 1,
      "name": "Plant_Moss_Rug_Blue"
    },
    {
      "x": -15,
      "y": 42,
      "z": 1,
      "name": "Wood_Azure_Branch_Long",
      "rotation": 4
    },
    {
      "x": -15,
      "y": 45,
      "z": 1,
      "name": "Plant_Leaves_Azure"
    },
    {
      "x": -15,
      "y": 46,
      "z": 1,
      "name": "Plant_Leaves_Azure"
    },
    {
      "x": -15,
      "y": 47,
      "z": 1,
      "name": "Plant_Leaves_Azure"
    },
    {
      "x": -15,
      "y": 48,
      "z": 1,
      "name": "Plant_Leaves_Azure"
    },
    {
      "x": -15,
      "y": 15,
      "z": 2,
      "name": "Rock_Marble"
    },
    {
      "x": -15,
      "y": 16,
      "z": 2,
      "name": "Rock_Marble"
    },
    {
      "x": -15,
      "y": 17,
      "z": 2,
      "name": "Rock_Marble"
    },
    {
      "x": -15,
      "y": 18,
      "z": 2,
      "name": "Rock_Marble"
    },
    {
      "x": -15,
      "y": 19,
      "z": 2,
      "name": "Rock_Marble"
    },
    {
      "x": -15,
      "y": 20,
      "z": 2,
      "name": "Rock_Marble"
    },
    {
      "x": -15,
      "y": 21,
      "z": 2,
      "name": "Rock_Marble"
    },
    {
      "x": -15,
      "y": 22,
      "z": 2,
      "name": "Rock_Marble"
    },
    {
      "x": -15,
      "y": 23,
      "z": 2,
      "name": "Rock_Marble"
    },
    {
      "x": -15,
      "y": 24,
      "z": 2,
      "name": "Rock_Marble"
    },
    {
      "x": -15,
      "y": 25,
      "z": 2,
      "name": "Rock_Marble"
    },
    {
      "x": -15,
      "y": 26,
      "z": 2,
      "name": "Rock_Marble"
    },
    {
      "x": -15,
      "y": 27,
      "z": 2,
      "name": "Rock_Marble"
    },
    {
      "x": -15,
      "y": 28,
      "z": 2,
      "name": "Plant_Moss_Block_Blue"
    },
    {
      "x": -15,
      "y": 29,
      "z": 2,
      "name": "Wood_Azure_Trunk_Full"
    },
    {
      "x": -15,
      "y": 30,
      "z": 2,
      "name": "Wood_Azure_Trunk"
    },
    {
      "x": -15,
      "y": 31,
      "z": 2,
      "name": "Wood_Azure_Trunk"
    },
    {
      "x": -15,
      "y": 32,
      "z": 2,
      "name": "Wood_Azure_Trunk"
    },
    {
      "x": -15,
      "y": 33,
      "z": 2,
      "name": "Wood_Azure_Trunk"
    },
    {
      "x": -15,
      "y": 34,
      "z": 2,
      "name": "Wood_Azure_Trunk"
    },
    {
      "x": -15,
      "y": 35,
      "z": 2,
      "name": "Wood_Azure_Trunk"
    },
    {
      "x": -15,
      "y": 36,
      "z": 2,
      "name": "Wood_Azure_Trunk_Full"
    },
    {
      "x": -15,
      "y": 40,
      "z": 2,
      "name": "Plant_Moss_Wall_Blue"
    },
    {
      "x": -15,
      "y": 42,
      "z": 2,
      "name": "Wood_Azure_Branch_Long",
      "rotation": 4
    },
    {
      "x": -15,
      "y": 45,
      "z": 2,
      "name": "Plant_Leaves_Azure"
    },
    {
      "x": -15,
      "y": 46,
      "z": 2,
      "name": "Plant_Leaves_Azure"
    },
    {
      "x": -15,
      "y": 47,
      "z": 2,
      "name": "Plant_Leaves_Azure"
    },
    {
      "x": -15,
      "y": 15,
      "z": 3,
      "name": "Plant_Moss_Wall_Blue"
    },
    {
      "x": -15,
      "y": 18,
      "z": 3,
      "name": "Rock_Marble"
    },
    {
      "x": -15,
      "y": 19,
      "z": 3,
      "name": "Rock_Marble"
    },
    {
      "x": -15,
      "y": 20,
      "z": 3,
      "name": "Rock_Marble"
    },
    {
      "x": -15,
      "y": 21,
      "z": 3,
      "name": "Rock_Marble"
    },
    {
      "x": -15,
      "y": 22,
      "z": 3,
      "name": "Rock_Marble"
    },
    {
      "x": -15,
      "y": 23,
      "z": 3,
      "name": "Rock_Marble"
    },
    {
      "x": -15,
      "y": 24,
      "z": 3,
      "name": "Rock_Marble"
    },
    {
      "x": -15,
      "y": 25,
      "z": 3,
      "name": "Rock_Marble"
    },
    {
      "x": -15,
      "y": 26,
      "z": 3,
      "name": "Rock_Marble"
    },
    {
      "x": -15,
      "y": 27,
      "z": 3,
      "name": "Plant_Moss_Block_Blue"
    },
    {
      "x": -15,
      "y": 28,
      "z": 3,
      "name": "Plant_Moss_Block_Blue"
    },
    {
      "x": -15,
      "y": 29,
      "z": 3,
      "name": "Wood_Azure_Trunk_Full"
    },
    {
      "x": -15,
      "y": 30,
      "z": 3,
      "name": "Wood_Azure_Trunk"
    },
    {
      "x": -15,
      "y": 31,
      "z": 3,
      "name": "Wood_Azure_Trunk_Full"
    },
    {
      "x": -15,
      "y": 35,
      "z": 3,
      "name": "Wood_Azure_Branch_Long",
      "rotation": 4
    },
    {
      "x": -15,
      "y": 41,
      "z": 3,
      "name": "Plant_Leaves_Azure"
    },
    {
      "x": -15,
      "y": 42,
      "z": 3,
      "name": "Wood_Azure_Branch_Long",
      "rotation": 4
    },
    {
      "x": -15,
      "y": 43,
      "z": 3,
      "name": "Plant_Leaves_Azure"
    },
    {
      "x": -15,
      "y": 18,
      "z": 4,
      "name": "Rock_Marble"
    },
    {
      "x": -15,
      "y": 19,
      "z": 4,
      "name": "Rock_Marble"
    },
    {
      "x": -15,
      "y": 20,
      "z": 4,
      "name": "Rock_Marble"
    },
    {
      "x": -15,
      "y": 21,
      "z": 4,
      "name": "Rock_Marble"
    },
    {
      "x": -15,
      "y": 22,
      "z": 4,
      "name": "Rock_Marble"
    },
    {
      "x": -15,
      "y": 23,
      "z": 4,
      "name": "Rock_Marble"
    },
    {
      "x": -15,
      "y": 24,
      "z": 4,
      "name": "Rock_Marble"
    },
    {
      "x": -15,
      "y": 25,
      "z": 4,
      "name": "Rock_Marble"
    },
    {
      "x": -15,
      "y": 26,
      "z": 4,
      "name": "Rock_Marble"
    },
    {
      "x": -15,
      "y": 27,
      "z": 4,
      "name": "Plant_Moss_Block_Blue"
    },
    {
      "x": -15,
      "y": 28,
      "z": 4,
      "name": "Plant_Moss_Block_Blue"
    },
    {
      "x": -15,
      "y": 29,
      "z": 4,
      "name": "Plant_Moss_Rug_Lime"
    },
    {
      "x": -15,
      "y": 34,
      "z": 4,
      "name": "Plant_Leaves_Azure"
    },
    {
      "x": -15,
      "y": 35,
      "z": 4,
      "name": "Wood_Azure_Branch_Long",
      "rotation": 4
    },
    {
      "x": -15,
      "y": 37,
      "z": 4,
      "name": "Plant_Leaves_Azure"
    },
    {
      "x": -15,
      "y": 40,
      "z": 4,
      "name": "Plant_Leaves_Azure"
    },
    {
      "x": -15,
      "y": 41,
      "z": 4,
      "name": "Plant_Leaves_Azure"
    },
    {
      "x": -15,
      "y": 42,
      "z": 4,
      "name": "Plant_Leaves_Azure"
    },
    {
      "x": -15,
      "y": 19,
      "z": 5,
      "name": "Rock_Marble"
    },
    {
      "x": -15,
      "y": 20,
      "z": 5,
      "name": "Rock_Marble"
    },
    {
      "x": -15,
      "y": 21,
      "z": 5,
      "name": "Rock_Marble"
    },
    {
      "x": -15,
      "y": 22,
      "z": 5,
      "name": "Rock_Marble"
    },
    {
      "x": -15,
      "y": 23,
      "z": 5,
      "name": "Rock_Marble"
    },
    {
      "x": -15,
      "y": 24,
      "z": 5,
      "name": "Rock_Marble"
    },
    {
      "x": -15,
      "y": 25,
      "z": 5,
      "name": "Rock_Marble"
    },
    {
      "x": -15,
      "y": 26,
      "z": 5,
      "name": "Plant_Moss_Block_Blue"
    },
    {
      "x": -15,
      "y": 27,
      "z": 5,
      "name": "Plant_Moss_Block_Blue"
    },
    {
      "x": -15,
      "y": 28,
      "z": 5,
      "name": "Plant_Moss_Rug_Lime"
    },
    {
      "x": -15,
      "y": 34,
      "z": 5,
      "name": "Plant_Leaves_Azure"
    },
    {
      "x": -15,
      "y": 35,
      "z": 5,
      "name": "Plant_Leaves_Azure"
    },
    {
      "x": -15,
      "y": 36,
      "z": 5,
      "name": "Plant_Leaves_Azure"
    },
    {
      "x": -15,
      "y": 37,
      "z": 5,
      "name": "Plant_Leaves_Azure"
    },
    {
      "x": -15,
      "y": 24,
      "z": 6,
      "name": "Rock_Marble"
    },
    {
      "x": -15,
      "y": 25,
      "z": 6,
      "name": "Rock_Marble"
    },
    {
      "x": -15,
      "y": 26,
      "z": 6,
      "name": "Plant_Moss_Block_Blue"
    },
    {
      "x": -15,
      "y": 27,
      "z": 6,
      "name": "Plant_Moss_Block_Blue"
    },
    {
      "x": -15,
      "y": 28,
      "z": 6,
      "name": "Plant_Moss_Short_Green_Dark"
    },
    {
      "x": -15,
      "y": 35,
      "z": 6,
      "name": "Plant_Leaves_Azure"
    },
    {
      "x": -14,
      "y": 19,
      "z": -8,
      "name": "Plant_Moss_Wall_Blue",
      "rotation": 2
    },
    {
      "x": -14,
      "y": 21,
      "z": -8,
      "name": "Plant_Moss_Block_Blue"
    },
    {
      "x": -14,
      "y": 22,
      "z": -8,
      "name": "Plant_Moss_Block_Blue"
    },
    {
      "x": -14,
      "y": 23,
      "z": -8,
      "name": "Plant_Moss_Rug_Blue"
    },
    {
      "x": -14,
      "y": 18,
      "z": -7,
      "name": "Plant_Moss_Wall_Blue",
      "rotation": 3
    },
    {
      "x": -14,
      "y": 19,
      "z": -7,
      "name": "Rock_Marble"
    },
    {
      "x": -14,
      "y": 20,
      "z": -7,
      "name": "Rock_Marble"
    },
    {
      "x": -14,
      "y": 21,
      "z": -7,
      "name": "Rock_Marble"
    },
    {
      "x": -14,
      "y": 22,
      "z": -7,
      "name": "Plant_Moss_Block_Blue"
    },
    {
      "x": -14,
      "y": 23,
      "z": -7,
      "name": "Plant_Moss_Block_Blue"
    },
    {
      "x": -14,
      "y": 24,
      "z": -7,
      "name": "Plant_Moss_Rug_Lime"
    },
    {
      "x": -14,
      "y": 17,
      "z": -6,
      "name": "Plant_Moss_Wall_Blue",
      "rotation": 3
    },
    {
      "x": -14,
      "y": 18,
      "z": -6,
      "name": "Rock_Marble"
    },
    {
      "x": -14,
      "y": 19,
      "z": -6,
      "name": "Rock_Marble"
    },
    {
      "x": -14,
      "y": 20,
      "z": -6,
      "name": "Rock_Marble"
    },
    {
      "x": -14,
      "y": 21,
      "z": -6,
      "name": "Rock_Marble"
    },
    {
      "x": -14,
      "y": 22,
      "z": -6,
      "name": "Rock_Marble"
    },
    {
      "x": -14,
      "y": 23,
      "z": -6,
      "name": "Plant_Moss_Block_Blue"
    },
    {
      "x": -14,
      "y": 24,
      "z": -6,
      "name": "Plant_Moss_Block_Blue"
    },
    {
      "x": -14,
      "y": 25,
      "z": -6,
      "name": "Plant_Moss_Rug_Lime"
    },
    {
      "x": -14,
      "y": 35,
      "z": -6,
      "name": "Plant_Leaves_Azure"
    },
    {
      "x": -14,
      "y": 36,
      "z": -6,
      "name": "Plant_Leaves_Azure"
    },
    {
      "x": -14,
      "y": 37,
      "z": -6,
      "name": "Plant_Leaves_Azure"
    },
    {
      "x": -14,
      "y": 38,
      "z": -6,
      "name": "Plant_Leaves_Azure"
    },
    {
      "x": -14,
      "y": 17,
      "z": -5,
      "name": "Rock_Marble"
    },
    {
      "x": -14,
      "y": 18,
      "z": -5,
      "name": "Rock_Marble"
    },
    {
      "x": -14,
      "y": 19,
      "z": -5,
      "name": "Rock_Marble"
    },
    {
      "x": -14,
      "y": 20,
      "z": -5,
      "name": "Rock_Marble"
    },
    {
      "x": -14,
      "y": 21,
      "z": -5,
      "name": "Rock_Marble"
    },
    {
      "x": -14,
      "y": 22,
      "z": -5,
      "name": "Rock_Marble"
    },
    {
      "x": -14,
      "y": 23,
      "z": -5,
      "name": "Plant_Moss_Block_Blue"
    },
    {
      "x": -14,
      "y": 24,
      "z": -5,
      "name": "Plant_Moss_Block_Blue"
    },
    {
      "x": -14,
      "y": 25,
      "z": -5,
      "name": "Plant_Moss_Blue"
    },
    {
      "x": -14,
      "y": 34,
      "z": -5,
      "name": "Plant_Leaves_Azure"
    },
    {
      "x": -14,
      "y": 35,
      "z": -5,
      "name": "Plant_Leaves_Azure"
    },
    {
      "x": -14,
      "y": 36,
      "z": -5,
      "name": "Plant_Leaves_Azure"
    },
    {
      "x": -14,
      "y": 37,
      "z": -5,
      "name": "Plant_Leaves_Azure"
    },
    {
      "x": -14,
      "y": 38,
      "z": -5,
      "name": "Plant_Leaves_Azure"
    },
    {
      "x": -14,
      "y": 39,
      "z": -5,
      "name": "Plant_Leaves_Azure"
    },
    {
      "x": -14,
      "y": 14,
      "z": -4,
      "name": "Rock_Marble"
    },
    {
      "x": -14,
      "y": 15,
      "z": -4,
      "name": "Rock_Marble"
    },
    {
      "x": -14,
      "y": 16,
      "z": -4,
      "name": "Rock_Marble"
    },
    {
      "x": -14,
      "y": 17,
      "z": -4,
      "name": "Rock_Marble"
    },
    {
      "x": -14,
      "y": 18,
      "z": -4,
      "name": "Rock_Marble"
    },
    {
      "x": -14,
      "y": 19,
      "z": -4,
      "name": "Rock_Marble"
    },
    {
      "x": -14,
      "y": 20,
      "z": -4,
      "name": "Rock_Marble"
    },
    {
      "x": -14,
      "y": 21,
      "z": -4,
      "name": "Rock_Marble"
    },
    {
      "x": -14,
      "y": 22,
      "z": -4,
      "name": "Rock_Marble"
    },
    {
      "x": -14,
      "y": 23,
      "z": -4,
      "name": "Rock_Marble"
    },
    {
      "x": -14,
      "y": 24,
      "z": -4,
      "name": "Plant_Moss_Block_Blue"
    },
    {
      "x": -14,
      "y": 25,
      "z": -4,
      "name": "Plant_Moss_Block_Blue"
    },
    {
      "x": -14,
      "y": 26,
      "z": -4,
      "name": "Plant_Moss_Rug_Lime"
    },
    {
      "x": -14,
      "y": 36,
      "z": -4,
      "name": "Plant_Leaves_Azure"
    },
    {
      "x": -14,
      "y": 37,
      "z": -4,
      "name": "Plant_Leaves_Azure"
    },
    {
      "x": -14,
      "y": 38,
      "z": -4,
      "name": "Plant_Leaves_Azure"
    },
    {
      "x": -14,
      "y": 13,
      "z": -3,
      "name": "Rock_Marble"
    },
    {
      "x": -14,
      "y": 14,
      "z": -3,
      "name": "Rock_Marble"
    },
    {
      "x": -14,
      "y": 15,
      "z": -3,
      "name": "Rock_Marble"
    },
    {
      "x": -14,
      "y": 16,
      "z": -3,
      "name": "Rock_Marble"
    },
    {
      "x": -14,
      "y": 17,
      "z": -3,
      "name": "Rock_Marble"
    },
    {
      "x": -14,
      "y": 18,
      "z": -3,
      "name": "Rock_Marble"
    },
    {
      "x": -14,
      "y": 19,
      "z": -3,
      "name": "Rock_Marble"
    },
    {
      "x": -14,
      "y": 20,
      "z": -3,
      "name": "Rock_Marble"
    },
    {
      "x": -14,
      "y": 21,
      "z": -3,
      "name": "Rock_Marble"
    },
    {
      "x": -14,
      "y": 22,
      "z": -3,
      "name": "Rock_Marble"
    },
    {
      "x": -14,
      "y": 23,
      "z": -3,
      "name": "Rock_Marble"
    },
    {
      "x": -14,
      "y": 24,
      "z": -3,
      "name": "Rock_Marble"
    },
    {
      "x": -14,
      "y": 25,
      "z": -3,
      "name": "Plant_Moss_Block_Blue"
    },
    {
      "x": -14,
      "y": 26,
      "z": -3,
      "name": "Plant_Moss_Block_Blue"
    },
    {
      "x": -14,
      "y": 27,
      "z": -3,
      "name": "Plant_Moss_Blue"
    },
    {
      "x": -14,
      "y": 37,
      "z": -3,
      "name": "Plant_Leaves_Azure"
    },
    {
      "x": -14,
      "y": 38,
      "z": -3,
      "name": "Plant_Leaves_Azure"
    },
    {
      "x": -14,
      "y": 42,
      "z": -3,
      "name": "Plant_Leaves_Azure"
    },
    {
      "x": -14,
      "y": 43,
      "z": -3,
      "name": "Plant_Leaves_Azure"
    },
    {
      "x": -14,
      "y": 44,
      "z": -3,
      "name": "Plant_Leaves_Azure"
    },
    {
      "x": -14,
      "y": 14,
      "z": -2,
      "name": "Rock_Marble"
    },
    {
      "x": -14,
      "y": 15,
      "z": -2,
      "name": "Rock_Marble"
    },
    {
      "x": -14,
      "y": 16,
      "z": -2,
      "name": "Rock_Marble"
    },
    {
      "x": -14,
      "y": 17,
      "z": -2,
      "name": "Rock_Marble"
    },
    {
      "x": -14,
      "y": 18,
      "z": -2,
      "name": "Rock_Marble"
    },
    {
      "x": -14,
      "y": 19,
      "z": -2,
      "name": "Rock_Marble"
    },
    {
      "x": -14,
      "y": 20,
      "z": -2,
      "name": "Rock_Marble"
    },
    {
      "x": -14,
      "y": 21,
      "z": -2,
      "name": "Rock_Marble"
    },
    {
      "x": -14,
      "y": 22,
      "z": -2,
      "name": "Rock_Marble"
    },
    {
      "x": -14,
      "y": 23,
      "z": -2,
      "name": "Rock_Marble"
    },
    {
      "x": -14,
      "y": 24,
      "z": -2,
      "name": "Rock_Marble"
    },
    {
      "x": -14,
      "y": 25,
      "z": -2,
      "name": "Rock_Marble"
    },
    {
      "x": -14,
      "y": 26,
      "z": -2,
      "name": "Plant_Moss_Block_Blue"
    },
    {
      "x": -14,
      "y": 27,
      "z": -2,
      "name": "Plant_Moss_Block_Blue"
    },
    {
      "x": -14,
      "y": 28,
      "z": -2,
      "name": "Plant_Moss_Rug_Lime"
    },
    {
      "x": -14,
      "y": 41,
      "z": -2,
      "name": "Plant_Leaves_Azure"
    },
    {
      "x": -14,
      "y": 42,
      "z": -2,
      "name": "Plant_Leaves_Azure"
    },
    {
      "x": -14,
      "y": 43,
      "z": -2,
      "name": "Plant_Leaves_Azure"
    },
    {
      "x": -14,
      "y": 44,
      "z": -2,
      "name": "Plant_Fruit_Azure"
    },
    {
      "x": -14,
      "y": 13,
      "z": -1,
      "name": "Plant_Moss_Wall_Blue",
      "rotation": 3
    },
    {
      "x": -14,
      "y": 14,
      "z": -1,
      "name": "Rock_Marble"
    },
    {
      "x": -14,
      "y": 15,
      "z": -1,
      "name": "Rock_Marble"
    },
    {
      "x": -14,
      "y": 16,
      "z": -1,
      "name": "Rock_Marble"
    },
    {
      "x": -14,
      "y": 17,
      "z": -1,
      "name": "Rock_Marble"
    },
    {
      "x": -14,
      "y": 18,
      "z": -1,
      "name": "Rock_Marble"
    },
    {
      "x": -14,
      "y": 19,
      "z": -1,
      "name": "Rock_Marble"
    },
    {
      "x": -14,
      "y": 20,
      "z": -1,
      "name": "Rock_Marble"
    },
    {
      "x": -14,
      "y": 21,
      "z": -1,
      "name": "Rock_Marble"
    },
    {
      "x": -14,
      "y": 22,
      "z": -1,
      "name": "Rock_Marble"
    },
    {
      "x": -14,
      "y": 23,
      "z": -1,
      "name": "Rock_Marble"
    },
    {
      "x": -14,
      "y": 24,
      "z": -1,
      "name": "Rock_Marble"
    },
    {
      "x": -14,
      "y": 25,
      "z": -1,
      "name": "Rock_Marble"
    },
    {
      "x": -14,
      "y": 26,
      "z": -1,
      "name": "Rock_Marble"
    },
    {
      "x": -14,
      "y": 27,
      "z": -1,
      "name": "Plant_Moss_Block_Blue"
    },
    {
      "x": -14,
      "y": 28,
      "z": -1,
      "name": "Plant_Moss_Block_Blue"
    },
    {
      "x": -14,
      "y": 29,
      "z": -1,
      "name": "Plant_Moss_Blue"
    },
    {
      "x": -14,
      "y": 37,
      "z": -1,
      "name": "Plant_Moss_Wall_Blue",
      "rotation": 2
    },
    {
      "x": -14,
      "y": 42,
      "z": -1,
      "name": "Plant_Leaves_Azure"
    },
    {
      "x": -14,
      "y": 48,
      "z": -1,
      "name": "Plant_Leaves_Azure"
    },
    {
      "x": -14,
      "y": 13,
      "z": 0,
      "name": "Plant_Moss_Wall_Blue",
      "rotation": 3
    },
    {
      "x": -14,
      "y": 14,
      "z": 0,
      "name": "Rock_Marble"
    },
    {
      "x": -14,
      "y": 15,
      "z": 0,
      "name": "Rock_Marble"
    },
    {
      "x": -14,
      "y": 16,
      "z": 0,
      "name": "Rock_Marble"
    },
    {
      "x": -14,
      "y": 17,
      "z": 0,
      "name": "Rock_Marble"
    },
    {
      "x": -14,
      "y": 18,
      "z": 0,
      "name": "Rock_Marble"
    },
    {
      "x": -14,
      "y": 19,
      "z": 0,
      "name": "Rock_Marble"
    },
    {
      "x": -14,
      "y": 20,
      "z": 0,
      "name": "Rock_Marble"
    },
    {
      "x": -14,
      "y": 21,
      "z": 0,
      "name": "Rock_Marble"
    },
    {
      "x": -14,
      "y": 22,
      "z": 0,
      "name": "Rock_Marble"
    },
    {
      "x": -14,
      "y": 23,
      "z": 0,
      "name": "Rock_Marble"
    },
    {
      "x": -14,
      "y": 24,
      "z": 0,
      "name": "Rock_Marble"
    },
    {
      "x": -14,
      "y": 25,
      "z": 0,
      "name": "Rock_Marble"
    },
    {
      "x": -14,
      "y": 26,
      "z": 0,
      "name": "Rock_Marble"
    },
    {
      "x": -14,
      "y": 27,
      "z": 0,
      "name": "Plant_Moss_Block_Blue"
    },
    {
      "x": -14,
      "y": 28,
      "z": 0,
      "name": "Plant_Moss_Block_Blue"
    },
    {
      "x": -14,
      "y": 29,
      "z": 0,
      "name": "Plant_Moss_Rug_Lime"
    },
    {
      "x": -14,
      "y": 34,
      "z": 0,
      "name": "Wood_Azure_Trunk_Full"
    },
    {
      "x": -14,
      "y": 35,
      "z": 0,
      "name": "Wood_Azure_Trunk"
    },
    {
      "x": -14,
      "y": 36,
      "z": 0,
      "name": "Wood_Azure_Trunk"
    },
    {
      "x": -14,
      "y": 37,
      "z": 0,
      "name": "Wood_Azure_Trunk_Full"
    },
    {
      "x": -14,
      "y": 38,
      "z": 0,
      "name": "Plant_Moss_Rug_Blue"
    },
    {
      "x": -14,
      "y": 46,
      "z": 0,
      "name": "Plant_Leaves_Azure"
    },
    {
      "x": -14,
      "y": 47,
      "z": 0,
      "name": "Plant_Leaves_Azure"
    },
    {
      "x": -14,
      "y": 48,
      "z": 0,
      "name": "Plant_Leaves_Azure"
    },
    {
      "x": -14,
      "y": 12,
      "z": 1,
      "name": "Plant_Moss_Wall_Blue",
      "rotation": 3
    },
    {
      "x": -14,
      "y": 14,
      "z": 1,
      "name": "Rock_Marble"
    },
    {
      "x": -14,
      "y": 15,
      "z": 1,
      "name": "Rock_Marble"
    },
    {
      "x": -14,
      "y": 16,
      "z": 1,
      "name": "Rock_Marble"
    },
    {
      "x": -14,
      "y": 17,
      "z": 1,
      "name": "Rock_Marble"
    },
    {
      "x": -14,
      "y": 18,
      "z": 1,
      "name": "Rock_Marble"
    },
    {
      "x": -14,
      "y": 19,
      "z": 1,
      "name": "Rock_Marble"
    },
    {
      "x": -14,
      "y": 20,
      "z": 1,
      "name": "Rock_Marble"
    },
    {
      "x": -14,
      "y": 21,
      "z": 1,
      "name": "Rock_Marble"
    },
    {
      "x": -14,
      "y": 22,
      "z": 1,
      "name": "Rock_Marble"
    },
    {
      "x": -14,
      "y": 23,
      "z": 1,
      "name": "Rock_Marble"
    },
    {
      "x": -14,
      "y": 24,
      "z": 1,
      "name": "Rock_Marble"
    },
    {
      "x": -14,
      "y": 25,
      "z": 1,
      "name": "Rock_Marble"
    },
    {
      "x": -14,
      "y": 26,
      "z": 1,
      "name": "Rock_Marble"
    },
    {
      "x": -14,
      "y": 27,
      "z": 1,
      "name": "Rock_Marble"
    },
    {
      "x": -14,
      "y": 28,
      "z": 1,
      "name": "Plant_Moss_Block_Blue"
    },
    {
      "x": -14,
      "y": 29,
      "z": 1,
      "name": "Plant_Moss_Block_Blue"
    },
    {
      "x": -14,
      "y": 30,
      "z": 1,
      "name": "Plant_Moss_Blue"
    },
    {
      "x": -14,
      "y": 32,
      "z": 1,
      "name": "Wood_Azure_Trunk_Full"
    },
    {
      "x": -14,
      "y": 33,
      "z": 1,
      "name": "Wood_Azure_Trunk"
    },
    {
      "x": -14,
      "y": 34,
      "z": 1,
      "name": "Wood_Azure_Trunk"
    },
    {
      "x": -14,
      "y": 35,
      "z": 1,
      "name": "Wood_Azure_Trunk_Full"
    },
    {
      "x": -14,
      "y": 37,
      "z": 1,
      "name": "Plant_Moss_Wall_Blue"
    },
    {
      "x": -14,
      "y": 39,
      "z": 1,
      "name": "Wood_Azure_Branch_Long",
      "rotation": 5
    },
    {
      "x": -14,
      "y": 40,
      "z": 1,
      "name": "Plant_Moss_Wall_Blue",
      "rotation": 1
    },
    {
      "x": -14,
      "y": 43,
      "z": 1,
      "name": "Plant_Leaves_Azure"
    },
    {
      "x": -14,
      "y": 46,
      "z": 1,
      "name": "Plant_Leaves_Azure"
    },
    {
      "x": -14,
      "y": 47,
      "z": 1,
      "name": "Plant_Leaves_Azure"
    },
    {
      "x": -14,
      "y": 14,
      "z": 2,
      "name": "Plant_Moss_Wall_Blue"
    },
    {
      "x": -14,
      "y": 15,
      "z": 2,
      "name": "Rock_Marble"
    },
    {
      "x": -14,
      "y": 16,
      "z": 2,
      "name": "Rock_Marble"
    },
    {
      "x": -14,
      "y": 17,
      "z": 2,
      "name": "Rock_Marble"
    },
    {
      "x": -14,
      "y": 18,
      "z": 2,
      "name": "Rock_Marble"
    },
    {
      "x": -14,
      "y": 19,
      "z": 2,
      "name": "Rock_Marble"
    },
    {
      "x": -14,
      "y": 20,
      "z": 2,
      "name": "Rock_Marble"
    },
    {
      "x": -14,
      "y": 21,
      "z": 2,
      "name": "Rock_Marble"
    },
    {
      "x": -14,
      "y": 22,
      "z": 2,
      "name": "Rock_Marble"
    },
    {
      "x": -14,
      "y": 23,
      "z": 2,
      "name": "Rock_Marble"
    },
    {
      "x": -14,
      "y": 24,
      "z": 2,
      "name": "Rock_Marble"
    },
    {
      "x": -14,
      "y": 25,
      "z": 2,
      "name": "Rock_Marble"
    },
    {
      "x": -14,
      "y": 26,
      "z": 2,
      "name": "Rock_Marble"
    },
    {
      "x": -14,
      "y": 27,
      "z": 2,
      "name": "Rock_Marble"
    },
    {
      "x": -14,
      "y": 28,
      "z": 2,
      "name": "Plant_Moss_Block_Blue"
    },
    {
      "x": -14,
      "y": 29,
      "z": 2,
      "name": "Wood_Azure_Trunk_Full"
    },
    {
      "x": -14,
      "y": 30,
      "z": 2,
      "name": "Wood_Azure_Trunk"
    },
    {
      "x": -14,
      "y": 31,
      "z": 2,
      "name": "Wood_Azure_Trunk"
    },
    {
      "x": -14,
      "y": 32,
      "z": 2,
      "name": "Wood_Azure_Trunk_Full"
    },
    {
      "x": -14,
      "y": 42,
      "z": 2,
      "name": "Plant_Leaves_Azure"
    },
    {
      "x": -14,
      "y": 43,
      "z": 2,
      "name": "Plant_Leaves_Azure"
    },
    {
      "x": -14,
      "y": 44,
      "z": 2,
      "name": "Plant_Fruit_Azure"
    },
    {
      "x": -14,
      "y": 46,
      "z": 2,
      "name": "Plant_Leaves_Azure"
    },
    {
      "x": -14,
      "y": 17,
      "z": 3,
      "name": "Rock_Marble"
    },
    {
      "x": -14,
      "y": 18,
      "z": 3,
      "name": "Rock_Marble"
    },
    {
      "x": -14,
      "y": 19,
      "z": 3,
      "name": "Rock_Marble"
    },
    {
      "x": -14,
      "y": 20,
      "z": 3,
      "name": "Rock_Marble"
    },
    {
      "x": -14,
      "y": 21,
      "z": 3,
      "name": "Rock_Marble"
    },
    {
      "x": -14,
      "y": 22,
      "z": 3,
      "name": "Rock_Marble"
    },
    {
      "x": -14,
      "y": 23,
      "z": 3,
      "name": "Rock_Marble"
    },
    {
      "x": -14,
      "y": 24,
      "z": 3,
      "name": "Rock_Marble"
    },
    {
      "x": -14,
      "y": 25,
      "z": 3,
      "name": "Rock_Marble"
    },
    {
      "x": -14,
      "y": 26,
      "z": 3,
      "name": "Rock_Marble"
    },
    {
      "x": -14,
      "y": 27,
      "z": 3,
      "name": "Wood_Azure_Roots"
    },
    {
      "x": -14,
      "y": 28,
      "z": 3,
      "name": "Wood_Azure_Trunk_Full"
    },
    {
      "x": -14,
      "y": 29,
      "z": 3,
      "name": "Wood_Azure_Trunk"
    },
    {
      "x": -14,
      "y": 30,
      "z": 3,
      "name": "Wood_Azure_Trunk_Full"
    },
    {
      "x": -14,
      "y": 38,
      "z": 3,
      "name": "Plant_Leaves_Azure"
    },
    {
      "x": -14,
      "y": 42,
      "z": 3,
      "name": "Plant_Leaves_Azure"
    },
    {
      "x": -14,
      "y": 43,
      "z": 3,
      "name": "Plant_Leaves_Azure"
    },
    {
      "x": -14,
      "y": 18,
      "z": 4,
      "name": "Rock_Marble"
    },
    {
      "x": -14,
      "y": 19,
      "z": 4,
      "name": "Rock_Marble"
    },
    {
      "x": -14,
      "y": 20,
      "z": 4,
      "name": "Rock_Marble"
    },
    {
      "x": -14,
      "y": 21,
      "z": 4,
      "name": "Rock_Marble"
    },
    {
      "x": -14,
      "y": 22,
      "z": 4,
      "name": "Rock_Marble"
    },
    {
      "x": -14,
      "y": 23,
      "z": 4,
      "name": "Rock_Marble"
    },
    {
      "x": -14,
      "y": 24,
      "z": 4,
      "name": "Rock_Marble"
    },
    {
      "x": -14,
      "y": 25,
      "z": 4,
      "name": "Rock_Marble"
    },
    {
      "x": -14,
      "y": 26,
      "z": 4,
      "name": "Rock_Marble"
    },
    {
      "x": -14,
      "y": 27,
      "z": 4,
      "name": "Plant_Moss_Block_Blue"
    },
    {
      "x": -14,
      "y": 28,
      "z": 4,
      "name": "Wood_Azure_Trunk_Full"
    },
    {
      "x": -14,
      "y": 29,
      "z": 4,
      "name": "Wood_Azure_Trunk_Full"
    },
    {
      "x": -14,
      "y": 36,
      "z": 4,
      "name": "Plant_Leaves_Azure"
    },
    {
      "x": -14,
      "y": 37,
      "z": 4,
      "name": "Plant_Leaves_Azure"
    },
    {
      "x": -14,
      "y": 38,
      "z": 4,
      "name": "Plant_Leaves_Azure"
    },
    {
      "x": -14,
      "y": 18,
      "z": 5,
      "name": "Rock_Marble"
    },
    {
      "x": -14,
      "y": 19,
      "z": 5,
      "name": "Rock_Marble"
    },
    {
      "x": -14,
      "y": 20,
      "z": 5,
      "name": "Rock_Marble"
    },
    {
      "x": -14,
      "y": 21,
      "z": 5,
      "name": "Rock_Marble"
    },
    {
      "x": -14,
      "y": 22,
      "z": 5,
      "name": "Rock_Marble"
    },
    {
      "x": -14,
      "y": 23,
      "z": 5,
      "name": "Rock_Marble"
    },
    {
      "x": -14,
      "y": 24,
      "z": 5,
      "name": "Rock_Marble"
    },
    {
      "x": -14,
      "y": 25,
      "z": 5,
      "name": "Rock_Marble"
    },
    {
      "x": -14,
      "y": 26,
      "z": 5,
      "name": "Rock_Marble"
    },
    {
      "x": -14,
      "y": 27,
      "z": 5,
      "name": "Plant_Moss_Block_Blue"
    },
    {
      "x": -14,
      "y": 28,
      "z": 5,
      "name": "Plant_Moss_Block_Blue"
    },
    {
      "x": -14,
      "y": 29,
      "z": 5,
      "name": "Plant_Moss_Short_Green_Dark"
    },
    {
      "x": -14,
      "y": 35,
      "z": 5,
      "name": "Plant_Leaves_Azure"
    },
    {
      "x": -14,
      "y": 36,
      "z": 5,
      "name": "Plant_Leaves_Azure"
    },
    {
      "x": -14,
      "y": 37,
      "z": 5,
      "name": "Plant_Leaves_Azure"
    },
    {
      "x": -14,
      "y": 38,
      "z": 5,
      "name": "Plant_Leaves_Azure"
    },
    {
      "x": -14,
      "y": 39,
      "z": 5,
      "name": "Plant_Fruit_Azure"
    },
    {
      "x": -14,
      "y": 19,
      "z": 6,
      "name": "Rock_Marble"
    },
    {
      "x": -14,
      "y": 20,
      "z": 6,
      "name": "Rock_Marble"
    },
    {
      "x": -14,
      "y": 21,
      "z": 6,
      "name": "Rock_Marble"
    },
    {
      "x": -14,
      "y": 22,
      "z": 6,
      "name": "Rock_Marble"
    },
    {
      "x": -14,
      "y": 23,
      "z": 6,
      "name": "Rock_Marble"
    },
    {
      "x": -14,
      "y": 24,
      "z": 6,
      "name": "Rock_Marble"
    },
    {
      "x": -14,
      "y": 25,
      "z": 6,
      "name": "Rock_Marble"
    },
    {
      "x": -14,
      "y": 26,
      "z": 6,
      "name": "Plant_Moss_Block_Blue"
    },
    {
      "x": -14,
      "y": 27,
      "z": 6,
      "name": "Plant_Moss_Block_Blue"
    },
    {
      "x": -14,
      "y": 28,
      "z": 6,
      "name": "Plant_Moss_Short_Green_Dark"
    },
    {
      "x": -14,
      "y": 23,
      "z": 7,
      "name": "Rock_Marble"
    },
    {
      "x": -14,
      "y": 24,
      "z": 7,
      "name": "Rock_Marble"
    },
    {
      "x": -14,
      "y": 25,
      "z": 7,
      "name": "Rock_Marble"
    },
    {
      "x": -14,
      "y": 26,
      "z": 7,
      "name": "Plant_Moss_Block_Blue"
    },
    {
      "x": -14,
      "y": 27,
      "z": 7,
      "name": "Plant_Moss_Block_Blue"
    },
    {
      "x": -14,
      "y": 28,
      "z": 7,
      "name": "Plant_Moss_Short_Green_Dark"
    },
    {
      "x": -13,
      "y": 20,
      "z": -9,
      "name": "Plant_Moss_Wall_Blue",
      "rotation": 2
    },
    {
      "x": -13,
      "y": 21,
      "z": -9,
      "name": "Plant_Moss_Wall_Blue",
      "rotation": 2
    },
    {
      "x": -13,
      "y": 23,
      "z": -9,
      "name": "Plant_Moss_Wall_Blue",
      "rotation": 2
    },
    {
      "x": -13,
      "y": 18,
      "z": -8,
      "name": "Plant_Moss_Wall_Blue",
      "rotation": 2
    },
    {
      "x": -13,
      "y": 20,
      "z": -8,
      "name": "Rock_Marble"
    },
    {
      "x": -13,
      "y": 21,
      "z": -8,
      "name": "Rock_Marble"
    },
    {
      "x": -13,
      "y": 22,
      "z": -8,
      "name": "Plant_Moss_Block_Blue"
    },
    {
      "x": -13,
      "y": 23,
      "z": -8,
      "name": "Plant_Moss_Block_Blue"
    },
    {
      "x": -13,
      "y": 24,
      "z": -8,
      "name": "Plant_Moss_Wall_Blue",
      "rotation": 2
    },
    {
      "x": -13,
      "y": 18,
      "z": -7,
      "name": "Rock_Marble"
    },
    {
      "x": -13,
      "y": 19,
      "z": -7,
      "name": "Rock_Marble"
    },
    {
      "x": -13,
      "y": 20,
      "z": -7,
      "name": "Rock_Marble"
    },
    {
      "x": -13,
      "y": 21,
      "z": -7,
      "name": "Rock_Marble"
    },
    {
      "x": -13,
      "y": 22,
      "z": -7,
      "name": "Rock_Marble"
    },
    {
      "x": -13,
      "y": 23,
      "z": -7,
      "name": "Plant_Moss_Block_Blue"
    },
    {
      "x": -13,
      "y": 24,
      "z": -7,
      "name": "Plant_Moss_Block_Blue"
    },
    {
      "x": -13,
      "y": 25,
      "z": -7,
      "name": "Plant_Moss_Blue"
    },
    {
      "x": -13,
      "y": 17,
      "z": -6,
      "name": "Rock_Marble"
    },
    {
      "x": -13,
      "y": 18,
      "z": -6,
      "name": "Rock_Marble"
    },
    {
      "x": -13,
      "y": 19,
      "z": -6,
      "name": "Rock_Marble"
    },
    {
      "x": -13,
      "y": 20,
      "z": -6,
      "name": "Rock_Marble"
    },
    {
      "x": -13,
      "y": 21,
      "z": -6,
      "name": "Rock_Marble"
    },
    {
      "x": -13,
      "y": 22,
      "z": -6,
      "name": "Rock_Marble"
    },
    {
      "x": -13,
      "y": 23,
      "z": -6,
      "name": "Plant_Moss_Block_Blue"
    },
    {
      "x": -13,
      "y": 24,
      "z": -6,
      "name": "Plant_Moss_Block_Blue"
    },
    {
      "x": -13,
      "y": 25,
      "z": -6,
      "name": "Plant_Moss_Rug_Lime"
    },
    {
      "x": -13,
      "y": 35,
      "z": -6,
      "name": "Plant_Leaves_Azure"
    },
    {
      "x": -13,
      "y": 36,
      "z": -6,
      "name": "Plant_Leaves_Azure"
    },
    {
      "x": -13,
      "y": 37,
      "z": -6,
      "name": "Plant_Leaves_Azure"
    },
    {
      "x": -13,
      "y": 16,
      "z": -5,
      "name": "Rock_Marble"
    },
    {
      "x": -13,
      "y": 17,
      "z": -5,
      "name": "Rock_Marble"
    },
    {
      "x": -13,
      "y": 18,
      "z": -5,
      "name": "Rock_Marble"
    },
    {
      "x": -13,
      "y": 19,
      "z": -5,
      "name": "Rock_Marble"
    },
    {
      "x": -13,
      "y": 20,
      "z": -5,
      "name": "Rock_Marble"
    },
    {
      "x": -13,
      "y": 21,
      "z": -5,
      "name": "Rock_Marble"
    },
    {
      "x": -13,
      "y": 22,
      "z": -5,
      "name": "Rock_Marble"
    },
    {
      "x": -13,
      "y": 23,
      "z": -5,
      "name": "Rock_Marble"
    },
    {
      "x": -13,
      "y": 24,
      "z": -5,
      "name": "Rock_Marble"
