{
  "version": 8,
  "blockIdVersion": 11,
  "anchorX": 0,
  "anchorY": 0,
  "anchorZ": 0,
  "blocks": [
    {
      "x": -22,
      "y": 35,
      "z": 1,
      "name": "Plant_Leaves_Azure",
      "rotation": 2
    },
    {
      "x": -22,
      "y": 34,
      "z": 2,
      "name": "Plant_Leaves_Azure",
      "rotation": 2
    },
    {
      "x": -22,
      "y": 35,
      "z": 2,
      "name": "Plant_Leaves_Azure",
      "rotation": 2
    },
    {
      "x": -22,
      "y": 36,
      "z": 2,
      "name": "Plant_Leaves_Azure",
      "rotation": 2
    },
    {
      "x": -22,
      "y": 34,
      "z": 3,
      "name": "Plant_Leaves_Azure",
      "rotation": 2
    },
    {
      "x": -22,
      "y": 35,
      "z": 3,
      "name": "Plant_Leaves_Azure",
      "rotation": 2
    },
    {
      "x": -22,
      "y": 36,
      "z": 3,
      "name": "Plant_Leaves_Azure",
      "rotation": 2
    },
    {
      "x": -22,
      "y": 37,
      "z": 3,
      "name": "Plant_Leaves_Azure",
      "rotation": 2
    },
    {
      "x": -22,
      "y": 34,
      "z": 4,
      "name": "Plant_Leaves_Azure",
      "rotation": 2
    },
    {
      "x": -22,
      "y": 35,
      "z": 4,
      "name": "Plant_Leaves_Azure",
      "rotation": 2
    },
    {
      "x": -22,
      "y": 36,
      "z": 4,
      "name": "Plant_Leaves_Azure",
      "rotation": 2
    },
    {
      "x": -22,
      "y": 26,
      "z": 8,
      "name": "Plant_Moss_Wall_Blue",
      "rotation": 3
    },
    {
      "x": -21,
      "y": 27,
      "z": -7,
      "name": "Plant_Moss_Block_Blue"
    },
    {
      "x": -21,
      "y": 28,
      "z": -7,
      "name": "Plant_Moss_Block_Blue"
    },
    {
      "x": -21,
      "y": 29,
      "z": -7,
      "name": "Plant_Moss_Short_Green_Dark"
    },
    {
      "x": -21,
      "y": 25,
      "z": -6,
      "name": "Plant_Moss_Wall_Blue",
      "rotation": 3
    },
    {
      "x": -21,
      "y": 27,
      "z": -6,
      "name": "Rock_Marble"
    },
    {
      "x": -21,
      "y": 28,
      "z": -6,
      "name": "Plant_Moss_Block_Blue"
    },
    {
      "x": -21,
      "y": 29,
      "z": -6,
      "name": "Plant_Moss_Block_Blue"
    },
    {
      "x": -21,
      "y": 30,
      "z": -6,
      "name": "Plant_Moss_Rug_Lime"
    },
    {
      "x": -21,
      "y": 25,
      "z": -5,
      "name": "Plant_Moss_Wall_Blue",
      "rotation": 3
    },
    {
      "x": -21,
      "y": 26,
      "z": -5,
      "name": "Rock_Marble"
    },
    {
      "x": -21,
      "y": 27,
      "z": -5,
      "name": "Rock_Marble"
    },
    {
      "x": -21,
      "y": 28,
      "z": -5,
      "name": "Plant_Moss_Block_Blue"
    },
    {
      "x": -21,
      "y": 29,
      "z": -5,
      "name": "Plant_Moss_Block_Blue"
    },
    {
      "x": -21,
      "y": 30,
      "z": -5,
      "name": "Plant_Moss_Blue"
    },
    {
      "x": -21,
      "y": 25,
      "z": -4,
      "name": "Plant_Moss_Wall_Blue",
      "rotation": 3
    },
    {
      "x": -21,
      "y": 27,
      "z": -4,
      "name": "Plant_Moss_Block_Blue"
    },
    {
      "x": -21,
      "y": 28,
      "z": -4,
      "name": "Plant_Moss_Block_Blue"
    },
    {
      "x": -21,
      "y": 29,
      "z": -4,
      "name": "Plant_Moss_Rug_Lime"
    },
    {
      "x": -21,
      "y": 25,
      "z": -3,
      "name": "Plant_Moss_Wall_Blue",
      "rotation": 3
    },
    {
      "x": -21,
      "y": 27,
      "z": -3,
      "name": "Plant_Moss_Block_Blue"
    },
    {
      "x": -21,
      "y": 28,
      "z": -3,
      "name": "Plant_Moss_Block_Blue"
    },
    {
      "x": -21,
      "y": 29,
      "z": -3,
      "name": "Plant_Moss_Rug_Blue"
    },
    {
      "x": -21,
      "y": 38,
      "z": 0,
      "name": "Plant_Leaves_Azure",
      "rotation": 2
    },
    {
      "x": -21,
      "y": 39,
      "z": 0,
      "name": "Plant_Leaves_Azure",
      "rotation": 2
    },
    {
      "x": -21,
      "y": 40,
      "z": 0,
      "name": "Plant_Leaves_Azure",
      "rotation": 2
    },
    {
      "x": -21,
      "y": 26,
      "z": 1,
      "name": "Plant_Moss_Wall_Blue",
      "rotation": 3
    },
    {
      "x": -21,
      "y": 34,
      "z": 1,
      "name": "Plant_Leaves_Azure",
      "rotation": 2
    },
    {
      "x": -21,
      "y": 35,
      "z": 1,
      "name": "Plant_Leaves_Azure",
      "rotation": 2
    },
    {
      "x": -21,
      "y": 36,
      "z": 1,
      "name": "Plant_Leaves_Azure",
      "rotation": 2
    },
    {
      "x": -21,
      "y": 38,
      "z": 1,
      "name": "Plant_Leaves_Azure",
      "rotation": 2
    },
    {
      "x": -21,
      "y": 39,
      "z": 1,
      "name": "Plant_Leaves_Azure",
      "rotation": 2
    },
    {
      "x": -21,
      "y": 40,
      "z": 1,
      "name": "Plant_Leaves_Azure",
      "rotation": 2
    },
    {
      "x": -21,
      "y": 41,
      "z": 1,
      "name": "Plant_Leaves_Azure",
      "rotation": 2
    },
    {
      "x": -21,
      "y": 26,
      "z": 2,
      "name": "Plant_Moss_Wall_Blue",
      "rotation": 3
    },
    {
      "x": -21,
      "y": 34,
      "z": 2,
      "name": "Plant_Leaves_Azure",
      "rotation": 2
    },
    {
      "x": -21,
      "y": 35,
      "z": 2,
      "name": "Plant_Leaves_Azure",
      "rotation": 2
    },
    {
      "x": -21,
      "y": 36,
      "z": 2,
      "name": "Wood_Azure_Branch_Long",
      "rotation": 7
    },
    {
      "x": -21,
      "y": 37,
      "z": 2,
      "name": "Plant_Leaves_Azure",
      "rotation": 2
    },
    {
      "x": -21,
      "y": 39,
      "z": 2,
      "name": "Plant_Leaves_Azure",
      "rotation": 2
    },
    {
      "x": -21,
      "y": 40,
      "z": 2,
      "name": "Plant_Leaves_Azure",
      "rotation": 2
    },
    {
      "x": -21,
      "y": 41,
      "z": 2,
      "name": "Plant_Leaves_Azure",
      "rotation": 2
    },
    {
      "x": -21,
      "y": 42,
      "z": 2,
      "name": "Plant_Leaves_Azure",
      "rotation": 2
    },
    {
      "x": -21,
      "y": 26,
      "z": 3,
      "name": "Plant_Moss_Wall_Blue",
      "rotation": 3
    },
    {
      "x": -21,
      "y": 34,
      "z": 3,
      "name": "Plant_Leaves_Azure",
      "rotation": 2
    },
    {
      "x": -21,
      "y": 35,
      "z": 3,
      "name": "Plant_Leaves_Azure",
      "rotation": 2
    },
    {
      "x": -21,
      "y": 36,
      "z": 3,
      "name": "Plant_Leaves_Azure",
      "rotation": 2
    },
    {
      "x": -21,
      "y": 37,
      "z": 3,
      "name": "Plant_Leaves_Azure",
      "rotation": 2
    },
    {
      "x": -21,
      "y": 38,
      "z": 3,
      "name": "Plant_Fruit_Azure",
      "rotation": 2
    },
    {
      "x": -21,
      "y": 40,
      "z": 3,
      "name": "Plant_Leaves_Azure",
      "rotation": 2
    },
    {
      "x": -21,
      "y": 41,
      "z": 3,
      "name": "Plant_Leaves_Azure",
      "rotation": 2
    },
    {
      "x": -21,
      "y": 42,
      "z": 3,
      "name": "Plant_Leaves_Azure",
      "rotation": 2
    },
    {
      "x": -21,
      "y": 35,
      "z": 4,
      "name": "Plant_Leaves_Azure",
      "rotation": 2
    },
    {
      "x": -21,
      "y": 36,
      "z": 4,
      "name": "Plant_Leaves_Azure",
      "rotation": 2
    },
    {
      "x": -21,
      "y": 37,
      "z": 4,
      "name": "Plant_Leaves_Azure",
      "rotation": 2
    },
    {
      "x": -21,
      "y": 38,
      "z": 4,
      "name": "Plant_Leaves_Azure",
      "rotation": 2
    },
    {
      "x": -21,
      "y": 35,
      "z": 5,
      "name": "Plant_Leaves_Azure",
      "rotation": 2
    },
    {
      "x": -21,
      "y": 36,
      "z": 5,
      "name": "Plant_Leaves_Azure",
      "rotation": 2
    },
    {
      "x": -21,
      "y": 37,
      "z": 5,
      "name": "Plant_Leaves_Azure",
      "rotation": 2
    },
    {
      "x": -21,
      "y": 38,
      "z": 5,
      "name": "Plant_Leaves_Azure",
      "rotation": 2
    },
    {
      "x": -21,
      "y": 35,
      "z": 6,
      "name": "Plant_Leaves_Azure",
      "rotation": 2
    },
    {
      "x": -21,
      "y": 36,
      "z": 6,
      "name": "Plant_Leaves_Azure",
      "rotation": 2
    },
    {
      "x": -21,
      "y": 37,
      "z": 6,
      "name": "Plant_Leaves_Azure",
      "rotation": 2
    },
    {
      "x": -21,
      "y": 25,
      "z": 8,
      "name": "Plant_Moss_Wall_Blue",
      "rotation": 3
    },
    {
      "x": -21,
      "y": 26,
      "z": 8,
      "name": "Plant_Moss_Block_Blue"
    },
    {
      "x": -21,
      "y": 27,
      "z": 8,
      "name": "Plant_Moss_Block_Blue"
    },
    {
      "x": -21,
      "y": 28,
      "z": 8,
      "name": "Plant_Moss_Short_Green_Dark"
    },
    {
      "x": -20,
      "y": 29,
      "z": -9,
      "name": "Plant_Moss_Rug_Lime"
    },
    {
      "x": -20,
      "y": 27,
      "z": -8,
      "name": "Rock_Marble"
    },
    {
      "x": -20,
      "y": 28,
      "z": -8,
      "name": "Rock_Marble"
    },
    {
      "x": -20,
      "y": 29,
      "z": -8,
      "name": "Plant_Moss_Block_Blue"
    },
    {
      "x": -20,
      "y": 30,
      "z": -8,
      "name": "Plant_Moss_Block_Blue"
    },
    {
      "x": -20,
      "y": 31,
      "z": -8,
      "name": "Plant_Moss_Rug_Blue"
    },
    {
      "x": -20,
      "y": 25,
      "z": -7,
      "name": "Rock_Marble"
    },
    {
      "x": -20,
      "y": 26,
      "z": -7,
      "name": "Rock_Marble"
    },
    {
      "x": -20,
      "y": 27,
      "z": -7,
      "name": "Rock_Marble"
    },
    {
      "x": -20,
      "y": 28,
      "z": -7,
      "name": "Plant_Moss_Block_Blue"
    },
    {
      "x": -20,
      "y": 29,
      "z": -7,
      "name": "Plant_Moss_Block_Blue"
    },
    {
      "x": -20,
      "y": 30,
      "z": -7,
      "name": "Plant_Moss_Rug_Lime"
    },
    {
      "x": -20,
      "y": 25,
      "z": -6,
      "name": "Rock_Marble"
    },
    {
      "x": -20,
      "y": 26,
      "z": -6,
      "name": "Rock_Marble"
    },
    {
      "x": -20,
      "y": 27,
      "z": -6,
      "name": "Rock_Marble"
    },
    {
      "x": -20,
      "y": 28,
      "z": -6,
      "name": "Plant_Moss_Block_Blue"
    },
    {
      "x": -20,
      "y": 29,
      "z": -6,
      "name": "Plant_Moss_Block_Blue"
    },
    {
      "x": -20,
      "y": 30,
      "z": -6,
      "name": "Plant_Moss_Short_Green_Dark"
    },
    {
      "x": -20,
      "y": 24,
      "z": -5,
      "name": "Rock_Marble"
    },
    {
      "x": -20,
      "y": 25,
      "z": -5,
      "name": "Rock_Marble"
    },
    {
      "x": -20,
      "y": 26,
      "z": -5,
      "name": "Rock_Marble"
    },
    {
      "x": -20,
      "y": 27,
      "z": -5,
      "name": "Rock_Marble"
    },
    {
      "x": -20,
      "y": 28,
      "z": -5,
      "name": "Plant_Moss_Block_Blue"
    },
    {
      "x": -20,
      "y": 29,
      "z": -5,
      "name": "Plant_Moss_Block_Blue"
    },
    {
      "x": -20,
      "y": 30,
      "z": -5,
      "name": "Plant_Moss_Blue"
    },
    {
      "x": -20,
      "y": 25,
      "z": -4,
      "name": "Rock_Marble"
    },
    {
      "x": -20,
      "y": 26,
      "z": -4,
      "name": "Rock_Marble"
    },
    {
      "x": -20,
      "y": 27,
      "z": -4,
      "name": "Rock_Marble"
    },
    {
      "x": -20,
      "y": 28,
      "z": -4,
      "name": "Plant_Moss_Block_Blue"
    },
    {
      "x": -20,
      "y": 29,
      "z": -4,
      "name": "Plant_Moss_Block_Blue"
    },
    {
      "x": -20,
      "y": 30,
      "z": -4,
      "name": "Plant_Moss_Blue"
    },
    {
      "x": -20,
      "y": 25,
      "z": -3,
      "name": "Rock_Marble"
    },
    {
      "x": -20,
      "y": 26,
      "z": -3,
      "name": "Rock_Marble"
    },
    {
      "x": -20,
      "y": 27,
      "z": -3,
      "name": "Rock_Marble"
    },
    {
      "x": -20,
      "y": 28,
      "z": -3,
      "name": "Plant_Moss_Block_Blue"
    },
    {
      "x": -20,
      "y": 29,
      "z": -3,
      "name": "Plant_Moss_Block_Blue"
    },
    {
      "x": -20,
      "y": 30,
      "z": -3,
      "name": "Plant_Moss_Short_Green_Dark"
    },
    {
      "x": -20,
      "y": 25,
      "z": -2,
      "name": "Rock_Marble"
    },
    {
      "x": -20,
      "y": 26,
      "z": -2,
      "name": "Rock_Marble"
    },
    {
      "x": -20,
      "y": 27,
      "z": -2,
      "name": "Plant_Moss_Block_Blue"
    },
    {
      "x": -20,
      "y": 28,
      "z": -2,
      "name": "Plant_Moss_Block_Blue"
    },
    {
      "x": -20,
      "y": 29,
      "z": -2,
      "name": "Plant_Moss_Short_Green_Dark"
    },
    {
      "x": -20,
      "y": 38,
      "z": -2,
      "name": "Plant_Leaves_Azure",
      "rotation": 2
    },
    {
      "x": -20,
      "y": 39,
      "z": -2,
      "name": "Plant_Leaves_Azure",
      "rotation": 2
    },
    {
      "x": -20,
      "y": 40,
      "z": -2,
      "name": "Plant_Leaves_Azure",
      "rotation": 2
    },
    {
      "x": -20,
      "y": 25,
      "z": -1,
      "name": "Plant_Moss_Wall_Blue",
      "rotation": 3
    },
    {
      "x": -20,
      "y": 26,
      "z": -1,
      "name": "Rock_Marble"
    },
    {
      "x": -20,
      "y": 27,
      "z": -1,
      "name": "Rock_Marble"
    },
    {
      "x": -20,
      "y": 28,
      "z": -1,
      "name": "Rock_Marble"
    },
    {
      "x": -20,
      "y": 29,
      "z": -1,
      "name": "Plant_Moss_Block_Blue"
    },
    {
      "x": -20,
      "y": 30,
      "z": -1,
      "name": "Plant_Moss_Block_Blue"
    },
    {
      "x": -20,
      "y": 31,
      "z": -1,
      "name": "Plant_Moss_Rug_Blue"
    },
    {
      "x": -20,
      "y": 37,
      "z": -1,
      "name": "Plant_Leaves_Azure",
      "rotation": 2
    },
    {
      "x": -20,
      "y": 38,
      "z": -1,
      "name": "Plant_Leaves_Azure",
      "rotation": 2
    },
    {
      "x": -20,
      "y": 39,
      "z": -1,
      "name": "Plant_Leaves_Azure",
      "rotation": 2
    },
    {
      "x": -20,
      "y": 40,
      "z": -1,
      "name": "Plant_Leaves_Azure",
      "rotation": 2
    },
    {
      "x": -20,
      "y": 41,
      "z": -1,
      "name": "Plant_Leaves_Azure",
      "rotation": 2
    },
    {
      "x": -20,
      "y": 42,
      "z": -1,
      "name": "Plant_Fruit_Azure",
      "rotation": 2
    },
    {
      "x": -20,
      "y": 25,
      "z": 0,
      "name": "Plant_Moss_Wall_Blue",
      "rotation": 3
    },
    {
      "x": -20,
      "y": 26,
      "z": 0,
      "name": "Rock_Marble"
    },
    {
      "x": -20,
      "y": 27,
      "z": 0,
      "name": "Rock_Marble"
    },
    {
      "x": -20,
      "y": 28,
      "z": 0,
      "name": "Plant_Moss_Block_Blue"
    },
    {
      "x": -20,
      "y": 29,
      "z": 0,
      "name": "Plant_Moss_Block_Blue"
    },
    {
      "x": -20,
      "y": 30,
      "z": 0,
      "name": "Plant_Moss_Rug_Lime"
    },
    {
      "x": -20,
      "y": 39,
      "z": 0,
      "name": "Plant_Leaves_Azure",
      "rotation": 2
    },
    {
      "x": -20,
      "y": 40,
      "z": 0,
      "name": "Plant_Leaves_Azure",
      "rotation": 2
    },
    {
      "x": -20,
      "y": 41,
      "z": 0,
      "name": "Plant_Leaves_Azure",
      "rotation": 2
    },
    {
      "x": -20,
      "y": 25,
      "z": 1,
      "name": "Rock_Marble"
    },
    {
      "x": -20,
      "y": 26,
      "z": 1,
      "name": "Rock_Marble"
    },
    {
      "x": -20,
      "y": 27,
      "z": 1,
      "name": "Plant_Moss_Block_Blue"
    },
    {
      "x": -20,
      "y": 28,
      "z": 1,
      "name": "Plant_Moss_Block_Blue"
    },
    {
      "x": -20,
      "y": 29,
      "z": 1,
      "name": "Plant_Moss_Rug_Lime"
    },
    {
      "x": -20,
      "y": 35,
      "z": 1,
      "name": "Plant_Leaves_Azure",
      "rotation": 2
    },
    {
      "x": -20,
      "y": 40,
      "z": 1,
      "name": "Plant_Leaves_Azure",
      "rotation": 2
    },
    {
      "x": -20,
      "y": 41,
      "z": 1,
      "name": "Plant_Leaves_Azure",
      "rotation": 2
    },
    {
      "x": -20,
      "y": 42,
      "z": 1,
      "name": "Plant_Leaves_Azure",
      "rotation": 2
    },
    {
      "x": -20,
      "y": 43,
      "z": 1,
      "name": "Plant_Fruit_Azure",
      "rotation": 2
    },
    {
      "x": -20,
      "y": 25,
      "z": 2,
      "name": "Rock_Marble"
    },
    {
      "x": -20,
      "y": 26,
      "z": 2,
      "name": "Plant_Moss_Block_Blue"
    },
    {
      "x": -20,
      "y": 27,
      "z": 2,
      "name": "Plant_Moss_Block_Blue"
    },
    {
      "x": -20,
      "y": 28,
      "z": 2,
      "name": "Plant_Moss_Rug_Lime"
    },
    {
      "x": -20,
      "y": 34,
      "z": 2,
      "name": "Plant_Leaves_Azure",
      "rotation": 2
    },
    {
      "x": -20,
      "y": 35,
      "z": 2,
      "name": "Plant_Leaves_Azure",
      "rotation": 2
    },
    {
      "x": -20,
      "y": 36,
      "z": 2,
      "name": "Wood_Azure_Branch_Long",
      "rotation": 7
    },
    {
      "x": -20,
      "y": 40,
      "z": 2,
      "name": "Plant_Leaves_Azure",
      "rotation": 2
    },
    {
      "x": -20,
      "y": 41,
      "z": 2,
      "name": "Plant_Leaves_Azure",
      "rotation": 2
    },
    {
      "x": -20,
      "y": 42,
      "z": 2,
      "name": "Plant_Leaves_Azure",
      "rotation": 2
    },
    {
      "x": -20,
      "y": 43,
      "z": 2,
      "name": "Plant_Leaves_Azure",
      "rotation": 2
    },
    {
      "x": -20,
      "y": 26,
      "z": 3,
      "name": "Plant_Moss_Block_Blue"
    },
    {
      "x": -20,
      "y": 27,
      "z": 3,
      "name": "Plant_Moss_Rug_Blue"
    },
    {
      "x": -20,
      "y": 35,
      "z": 3,
      "name": "Plant_Leaves_Azure",
      "rotation": 2
    },
    {
      "x": -20,
      "y": 36,
      "z": 3,
      "name": "Plant_Leaves_Azure",
      "rotation": 2
    },
    {
      "x": -20,
      "y": 40,
      "z": 3,
      "name": "Plant_Leaves_Azure",
      "rotation": 2
    },
    {
      "x": -20,
      "y": 41,
      "z": 3,
      "name": "Plant_Leaves_Azure",
      "rotation": 2
    },
    {
      "x": -20,
      "y": 42,
      "z": 3,
      "name": "Plant_Leaves_Azure",
      "rotation": 2
    },
    {
      "x": -20,
      "y": 43,
      "z": 3,
      "name": "Plant_Leaves_Azure",
      "rotation": 2
    },
    {
      "x": -20,
      "y": 44,
      "z": 3,
      "name": "Plant_Fruit_Azure",
      "rotation": 2
    },
    {
      "x": -20,
      "y": 25,
      "z": 4,
      "name": "Plant_Moss_Block_Blue"
    },
    {
      "x": -20,
      "y": 26,
      "z": 4,
      "name": "Plant_Moss_Blue"
    },
    {
      "x": -20,
      "y": 35,
      "z": 4,
      "name": "Plant_Leaves_Azure",
      "rotation": 2
    },
    {
      "x": -20,
      "y": 36,
      "z": 4,
      "name": "Plant_Leaves_Azure",
      "rotation": 2
    },
    {
      "x": -20,
      "y": 37,
      "z": 4,
      "name": "Plant_Leaves_Azure",
      "rotation": 2
    },
    {
      "x": -20,
      "y": 38,
      "z": 4,
      "name": "Plant_Leaves_Azure",
      "rotation": 2
    },
    {
      "x": -20,
      "y": 41,
      "z": 4,
      "name": "Plant_Leaves_Azure",
      "rotation": 2
    },
    {
      "x": -20,
      "y": 42,
      "z": 4,
      "name": "Plant_Leaves_Azure",
      "rotation": 2
    },
    {
      "x": -20,
      "y": 43,
      "z": 4,
      "name": "Plant_Leaves_Azure",
      "rotation": 2
    },
    {
      "x": -20,
      "y": 27,
      "z": 5,
      "name": "Plant_Moss_Wall_Blue",
      "rotation": 3
    },
    {
      "x": -20,
      "y": 35,
      "z": 5,
      "name": "Plant_Leaves_Azure",
      "rotation": 2
    },
    {
      "x": -20,
      "y": 36,
      "z": 5,
      "name": "Plant_Leaves_Azure",
      "rotation": 2
    },
    {
      "x": -20,
      "y": 37,
      "z": 5,
      "name": "Plant_Leaves_Azure",
      "rotation": 2
    },
    {
      "x": -20,
      "y": 38,
      "z": 5,
      "name": "Plant_Leaves_Azure",
      "rotation": 2
    },
    {
      "x": -20,
      "y": 39,
      "z": 5,
      "name": "Plant_Fruit_Azure",
      "rotation": 2
    },
    {
      "x": -20,
      "y": 27,
      "z": 6,
      "name": "Plant_Moss_Wall_Blue",
      "rotation": 3
    },
    {
      "x": -20,
      "y": 35,
      "z": 6,
      "name": "Plant_Leaves_Azure",
      "rotation": 2
    },
    {
      "x": -20,
      "y": 36,
      "z": 6,
      "name": "Plant_Leaves_Azure",
      "rotation": 2
    },
    {
      "x": -20,
      "y": 37,
      "z": 6,
      "name": "Plant_Leaves_Azure",
      "rotation": 2
    },
    {
      "x": -20,
      "y": 38,
      "z": 6,
      "name": "Plant_Leaves_Azure",
      "rotation": 2
    },
    {
      "x": -20,
      "y": 39,
      "z": 6,
      "name": "Plant_Leaves_Azure",
      "rotation": 2
    },
    {
      "x": -20,
      "y": 24,
      "z": 7,
      "name": "Plant_Crop_Mushroom_Block_Blue_Mycelium"
    },
    {
      "x": -20,
      "y": 25,
      "z": 7,
      "name": "Rock_Crystal_Blue_Block"
    },
    {
      "x": -20,
      "y": 26,
      "z": 7,
      "name": "Plant_Moss_Block_Blue"
    },
    {
      "x": -20,
      "y": 27,
      "z": 7,
      "name": "Plant_Moss_Short_Green_Dark"
    },
    {
      "x": -20,
      "y": 36,
      "z": 7,
      "name": "Plant_Leaves_Azure",
      "rotation": 2
    },
    {
      "x": -20,
      "y": 37,
      "z": 7,
      "name": "Plant_Leaves_Azure",
      "rotation": 2
    },
    {
      "x": -20,
      "y": 38,
      "z": 7,
      "name": "Plant_Leaves_Azure",
      "rotation": 2
    },
    {
      "x": -20,
      "y": 24,
      "z": 8,
      "name": "Plant_Moss_Wall_Blue",
      "rotation": 3
    },
    {
      "x": -20,
      "y": 25,
      "z": 8,
      "name": "Rock_Crystal_Blue_Block"
    },
    {
      "x": -20,
      "y": 26,
      "z": 8,
      "name": "Plant_Moss_Block_Blue"
    },
    {
      "x": -20,
      "y": 27,
      "z": 8,
      "name": "Plant_Moss_Block_Blue"
    },
    {
      "x": -20,
      "y": 28,
      "z": 8,
      "name": "Plant_Moss_Short_Green_Dark"
    },
    {
      "x": -20,
      "y": 26,
      "z": 9,
      "name": "Plant_Moss_Block_Blue"
    },
    {
      "x": -20,
      "y": 27,
      "z": 9,
      "name": "Plant_Moss_Block_Blue"
    },
    {
      "x": -20,
      "y": 28,
      "z": 9,
      "name": "Plant_Moss_Rug_Lime"
    },
    {
      "x": -19,
      "y": 27,
      "z": -10,
      "name": "Plant_Moss_Wall_Blue",
      "rotation": 2
    },
    {
      "x": -19,
      "y": 29,
      "z": -10,
      "name": "Plant_Moss_Block_Blue"
    },
    {
      "x": -19,
      "y": 30,
      "z": -10,
      "name": "Plant_Moss_Blue"
    },
    {
      "x": -19,
      "y": 26,
      "z": -9,
      "name": "Plant_Moss_Wall_Blue",
      "rotation": 3
    },
    {
      "x": -19,
      "y": 27,
      "z": -9,
      "name": "Rock_Marble"
    },
    {
      "x": -19,
      "y": 28,
      "z": -9,
      "name": "Rock_Marble"
    },
    {
      "x": -19,
      "y": 29,
      "z": -9,
      "name": "Rock_Marble"
    },
    {
      "x": -19,
      "y": 30,
      "z": -9,
      "name": "Plant_Moss_Block_Blue"
    },
    {
      "x": -19,
      "y": 31,
      "z": -9,
      "name": "Plant_Moss_Block_Blue"
    },
    {
      "x": -19,
      "y": 32,
      "z": -9,
      "name": "Plant_Moss_Short_Green_Dark"
    },
    {
      "x": -19,
      "y": 26,
      "z": -8,
      "name": "Rock_Marble"
    },
    {
      "x": -19,
      "y": 27,
      "z": -8,
      "name": "Rock_Marble"
    },
    {
      "x": -19,
      "y": 28,
      "z": -8,
      "name": "Rock_Marble"
    },
    {
      "x": -19,
      "y": 29,
      "z": -8,
      "name": "Rock_Marble"
    },
    {
      "x": -19,
      "y": 30,
      "z": -8,
      "name": "Plant_Moss_Block_Blue"
    },
    {
      "x": -19,
      "y": 31,
      "z": -8,
      "name": "Plant_Moss_Block_Blue"
    },
    {
      "x": -19,
      "y": 32,
      "z": -8,
      "name": "Plant_Moss_Rug_Lime"
    },
    {
      "x": -19,
      "y": 24,
      "z": -7,
      "name": "Plant_Moss_Wall_Blue",
      "rotation": 3
    },
    {
      "x": -19,
      "y": 25,
      "z": -7,
      "name": "Rock_Marble"
    },
    {
      "x": -19,
      "y": 26,
      "z": -7,
      "name": "Rock_Marble"
    },
    {
      "x": -19,
      "y": 27,
      "z": -7,
      "name": "Rock_Marble"
    },
    {
      "x": -19,
      "y": 28,
      "z": -7,
      "name": "Rock_Marble"
    },
    {
      "x": -19,
      "y": 29,
      "z": -7,
      "name": "Plant_Moss_Block_Blue"
    },
    {
      "x": -19,
      "y": 30,
      "z": -7,
      "name": "Plant_Moss_Block_Blue"
    },
    {
      "x": -19,
      "y": 31,
      "z": -7,
      "name": "Plant_Moss_Short_Green_Dark"
    },
    {
      "x": -19,
      "y": 22,
      "z": -6,
      "name": "Rock_Marble"
    },
    {
      "x": -19,
      "y": 23,
      "z": -6,
      "name": "Rock_Marble"
    },
    {
      "x": -19,
      "y": 24,
      "z": -6,
      "name": "Rock_Marble"
    },
    {
      "x": -19,
      "y": 25,
      "z": -6,
      "name": "Rock_Marble"
    },
    {
      "x": -19,
      "y": 26,
      "z": -6,
      "name": "Rock_Marble"
    },
    {
      "x": -19,
      "y": 27,
      "z": -6,
      "name": "Rock_Marble"
    },
    {
      "x": -19,
      "y": 28,
      "z": -6,
      "name": "Rock_Marble"
    },
    {
      "x": -19,
      "y": 29,
      "z": -6,
      "name": "Plant_Moss_Block_Blue"
    },
    {
      "x": -19,
      "y": 30,
      "z": -6,
      "name": "Plant_Moss_Block_Blue"
    },
    {
      "x": -19,
      "y": 31,
      "z": -6,
      "name": "Plant_Moss_Short_Green_Dark"
    },
    {
      "x": -19,
      "y": 23,
      "z": -5,
      "name": "Rock_Marble"
    },
    {
      "x": -19,
      "y": 24,
      "z": -5,
      "name": "Rock_Marble"
    },
    {
      "x": -19,
      "y": 25,
      "z": -5,
      "name": "Rock_Marble"
    },
    {
      "x": -19,
      "y": 26,
      "z": -5,
      "name": "Rock_Marble"
    },
    {
      "x": -19,
      "y": 27,
      "z": -5,
      "name": "Rock_Marble"
    },
    {
      "x": -19,
      "y": 28,
      "z": -5,
      "name": "Rock_Marble"
    },
    {
      "x": -19,
      "y": 29,
      "z": -5,
      "name": "Plant_Moss_Block_Blue"
    },
    {
      "x": -19,
      "y": 30,
      "z": -5,
      "name": "Plant_Moss_Block_Blue"
    },
    {
      "x": -19,
      "y": 31,
      "z": -5,
      "name": "Plant_Moss_Rug_Lime"
    },
    {
      "x": -19,
      "y": 23,
      "z": -4,
      "name": "Rock_Marble"
    },
    {
      "x": -19,
      "y": 24,
      "z": -4,
      "name": "Rock_Crystal_Blue_Block"
    },
    {
      "x": -19,
      "y": 25,
      "z": -4,
      "name": "Rock_Marble"
    },
    {
      "x": -19,
      "y": 26,
      "z": -4,
      "name": "Rock_Marble"
    },
    {
      "x": -19,
      "y": 27,
      "z": -4,
      "name": "Rock_Marble"
    },
    {
      "x": -19,
      "y": 28,
      "z": -4,
      "name": "Rock_Marble"
    },
    {
      "x": -19,
      "y": 29,
      "z": -4,
      "name": "Plant_Moss_Block_Blue"
    },
    {
      "x": -19,
      "y": 30,
      "z": -4,
      "name": "Plant_Moss_Block_Blue"
    },
    {
      "x": -19,
      "y": 31,
      "z": -4,
      "name": "Plant_Moss_Blue"
    },
    {
      "x": -19,
      "y": 25,
      "z": -3,
      "name": "Rock_Crystal_Blue_Block"
    },
    {
      "x": -19,
      "y": 26,
      "z": -3,
      "name": "Rock_Marble"
    },
    {
      "x": -19,
      "y": 27,
      "z": -3,
      "name": "Rock_Marble"
    },
    {
      "x": -19,
      "y": 28,
      "z": -3,
      "name": "Rock_Marble"
    },
    {
      "x": -19,
      "y": 29,
      "z": -3,
      "name": "Plant_Moss_Block_Blue"
    },
    {
      "x": -19,
      "y": 30,
      "z": -3,
      "name": "Plant_Moss_Block_Blue"
    },
    {
      "x": -19,
      "y": 31,
      "z": -3,
      "name": "Plant_Moss_Blue"
    },
    {
      "x": -19,
      "y": 37,
      "z": -3,
      "name": "Plant_Leaves_Azure",
      "rotation": 2
    },
    {
      "x": -19,
      "y": 38,
      "z": -3,
      "name": "Plant_Leaves_Azure",
      "rotation": 2
    },
    {
      "x": -19,
      "y": 39,
      "z": -3,
      "name": "Plant_Leaves_Azure",
      "rotation": 2
    },
    {
      "x": -19,
      "y": 25,
      "z": -2,
      "name": "Rock_Crystal_Blue_Block"
    },
    {
      "x": -19,
      "y": 26,
      "z": -2,
      "name": "Rock_Marble"
    },
    {
      "x": -19,
      "y": 27,
      "z": -2,
      "name": "Wood_Azure_Roots",
      "rotation": 2
    },
    {
      "x": -19,
      "y": 28,
      "z": -2,
      "name": "Wood_Azure_Trunk_Full",
      "rotation": 2
    },
    {
      "x": -19,
      "y": 29,
      "z": -2,
      "name": "Wood_Azure_Trunk_Full",
      "rotation": 2
    },
    {
      "x": -19,
      "y": 30,
      "z": -2,
      "name": "Plant_Moss_Block_Blue"
    },
    {
      "x": -19,
      "y": 31,
      "z": -2,
      "name": "Plant_Moss_Rug_Lime"
    },
    {
      "x": -19,
      "y": 36,
      "z": -2,
      "name": "Plant_Leaves_Azure",
      "rotation": 2
    },
    {
      "x": -19,
      "y": 37,
      "z": -2,
      "name": "Plant_Leaves_Azure",
      "rotation": 2
    },
    {
      "x": -19,
      "y": 38,
      "z": -2,
      "name": "Plant_Leaves_Azure",
      "rotation": 2
    },
    {
      "x": -19,
      "y": 39,
      "z": -2,
      "name": "Plant_Leaves_Azure",
      "rotation": 2
    },
    {
      "x": -19,
      "y": 40,
      "z": -2,
      "name": "Plant_Leaves_Azure",
      "rotation": 2
    },
    {
      "x": -19,
      "y": 24,
      "z": -1,
      "name": "Rock_Marble"
    },
    {
      "x": -19,
      "y": 25,
      "z": -1,
      "name": "Rock_Marble"
    },
    {
      "x": -19,
      "y": 26,
      "z": -1,
      "name": "Rock_Marble"
    },
    {
      "x": -19,
      "y": 27,
      "z": -1,
      "name": "Rock_Marble"
    },
    {
      "x": -19,
      "y": 28,
      "z": -1,
      "name": "Rock_Marble"
    },
    {
      "x": -19,
      "y": 29,
      "z": -1,
      "name": "Wood_Azure_Trunk_Full",
      "rotation": 2
    },
    {
      "x": -19,
      "y": 30,
      "z": -1,
      "name": "Wood_Azure_Trunk_Full",
      "rotation": 2
    },
    {
      "x": -19,
      "y": 31,
      "z": -1,
      "name": "Plant_Moss_Rug_Blue"
    },
    {
      "x": -19,
      "y": 38,
      "z": -1,
      "name": "Plant_Leaves_Azure",
      "rotation": 2
    },
    {
      "x": -19,
      "y": 39,
      "z": -1,
      "name": "Plant_Leaves_Azure",
      "rotation": 2
    },
    {
      "x": -19,
      "y": 40,
      "z": -1,
      "name": "Plant_Leaves_Azure",
      "rotation": 2
    },
    {
      "x": -19,
      "y": 24,
      "z": 0,
      "name": "Rock_Marble"
    },
    {
      "x": -19,
      "y": 25,
      "z": 0,
      "name": "Rock_Marble"
    },
    {
      "x": -19,
      "y": 26,
      "z": 0,
      "name": "Rock_Marble"
    },
    {
      "x": -19,
      "y": 27,
      "z": 0,
      "name": "Rock_Marble"
    },
    {
      "x": -19,
      "y": 28,
      "z": 0,
      "name": "Rock_Marble"
    },
    {
      "x": -19,
      "y": 29,
      "z": 0,
      "name": "Plant_Moss_Block_Blue"
    },
    {
      "x": -19,
      "y": 30,
      "z": 0,
      "name": "Plant_Moss_Block_Blue"
    },
    {
      "x": -19,
      "y": 31,
      "z": 0,
      "name": "Plant_Moss_Rug_Lime"
    },
    {
      "x": -19,
      "y": 40,
      "z": 0,
      "name": "Plant_Leaves_Azure",
      "rotation": 2
    },
    {
      "x": -19,
      "y": 41,
      "z": 0,
      "name": "Plant_Leaves_Azure",
      "rotation": 2
    },
    {
      "x": -19,
      "y": 44,
      "z": 0,
      "name": "Plant_Leaves_Azure",
      "rotation": 2
    },
    {
      "x": -19,
      "y": 24,
      "z": 1,
      "name": "Rock_Marble"
    },
    {
      "x": -19,
      "y": 25,
      "z": 1,
      "name": "Rock_Marble"
    },
    {
      "x": -19,
      "y": 26,
      "z": 1,
      "name": "Rock_Marble"
    },
    {
      "x": -19,
      "y": 27,
      "z": 1,
      "name": "Rock_Marble"
    },
    {
      "x": -19,
      "y": 28,
      "z": 1,
      "name": "Plant_Moss_Block_Blue"
    },
    {
      "x": -19,
      "y": 29,
      "z": 1,
      "name": "Plant_Moss_Block_Blue"
    },
    {
      "x": -19,
      "y": 30,
      "z": 1,
      "name": "Plant_Moss_Short_Green_Dark"
    },
    {
      "x": -19,
      "y": 40,
      "z": 1,
      "name": "Plant_Leaves_Azure",
      "rotation": 2
    },
    {
      "x": -19,
      "y": 41,
      "z": 1,
      "name": "Plant_Leaves_Azure",
      "rotation": 2
    },
    {
      "x": -19,
      "y": 24,
      "z": 2,
      "name": "Rock_Marble"
    },
    {
      "x": -19,
      "y": 25,
      "z": 2,
      "name": "Rock_Marble"
    },
    {
      "x": -19,
      "y": 26,
      "z": 2,
      "name": "Rock_Marble"
    },
    {
      "x": -19,
      "y": 27,
      "z": 2,
      "name": "Plant_Moss_Block_Blue"
    },
    {
      "x": -19,
      "y": 28,
      "z": 2,
      "name": "Plant_Moss_Block_Blue"
    },
    {
      "x": -19,
      "y": 29,
      "z": 2,
      "name": "Plant_Moss_Short_Green_Dark"
    },
    {
      "x": -19,
      "y": 36,
      "z": 2,
      "name": "Wood_Azure_Branch_Long",
      "rotation": 7
    },
    {
      "x": -19,
      "y": 38,
      "z": 2,
      "name": "Plant_Moss_Wall_Blue",
      "rotation": 3
    },
    {
      "x": -19,
      "y": 41,
      "z": 2,
      "name": "Plant_Leaves_Azure",
      "rotation": 2
    },
    {
      "x": -19,
      "y": 42,
      "z": 2,
      "name": "Plant_Leaves_Azure",
      "rotation": 2
    },
    {
      "x": -19,
      "y": 24,
      "z": 3,
      "name": "Plant_Moss_Wall_Blue",
      "rotation": 3
    },
    {
      "x": -19,
      "y": 25,
      "z": 3,
      "name": "Rock_Marble"
    },
    {
      "x": -19,
      "y": 26,
      "z": 3,
      "name": "Plant_Moss_Block_Blue"
    },
    {
      "x": -19,
      "y": 27,
      "z": 3,
      "name": "Plant_Moss_Block_Blue"
    },
    {
      "x": -19,
      "y": 28,
      "z": 3,
      "name": "Plant_Moss_Short_Green_Dark"
    },
    {
      "x": -19,
      "y": 42,
      "z": 3,
      "name": "Plant_Leaves_Azure",
      "rotation": 2
    },
    {
      "x": -19,
      "y": 43,
      "z": 3,
      "name": "Plant_Leaves_Azure",
      "rotation": 2
    },
    {
      "x": -19,
      "y": 25,
      "z": 4,
      "name": "Rock_Marble"
    },
    {
      "x": -19,
      "y": 26,
      "z": 4,
      "name": "Plant_Moss_Block_Blue"
    },
    {
      "x": -19,
      "y": 27,
      "z": 4,
      "name": "Plant_Moss_Block_Blue"
    },
    {
      "x": -19,
      "y": 28,
      "z": 4,
      "name": "Plant_Moss_Blue"
    },
    {
      "x": -19,
      "y": 41,
      "z": 4,
      "name": "Plant_Leaves_Azure",
      "rotation": 2
    },
    {
      "x": -19,
      "y": 42,
      "z": 4,
      "name": "Plant_Leaves_Azure",
      "rotation": 2
    },
    {
      "x": -19,
      "y": 43,
      "z": 4,
      "name": "Plant_Leaves_Azure",
      "rotation": 2
    },
    {
      "x": -19,
      "y": 44,
      "z": 4,
      "name": "Plant_Leaves_Azure",
      "rotation": 2
    },
    {
      "x": -19,
      "y": 25,
      "z": 5,
      "name": "Plant_Moss_Wall_Blue",
      "rotation": 3
    },
    {
      "x": -19,
      "y": 26,
      "z": 5,
      "name": "Plant_Moss_Block_Blue"
    },
    {
      "x": -19,
      "y": 27,
      "z": 5,
      "name": "Plant_Moss_Block_Blue"
    },
    {
      "x": -19,
      "y": 28,
      "z": 5,
      "name": "Plant_Moss_Rug_Lime"
    },
    {
      "x": -19,
      "y": 37,
      "z": 5,
      "name": "Plant_Leaves_Azure",
      "rotation": 2
    },
    {
      "x": -19,
      "y": 38,
      "z": 5,
      "name": "Plant_Leaves_Azure",
      "rotation": 2
    },
    {
      "x": -19,
      "y": 39,
      "z": 5,
      "name": "Plant_Leaves_Azure",
      "rotation": 2
    },
    {
      "x": -19,
      "y": 42,
      "z": 5,
      "name": "Plant_Leaves_Azure",
      "rotation": 2
    },
    {
      "x": -19,
      "y": 43,
      "z": 5,
      "name": "Plant_Leaves_Azure",
      "rotation": 2
    },
    {
      "x": -19,
      "y": 44,
      "z": 5,
      "name": "Plant_Leaves_Azure",
      "rotation": 2
    },
    {
      "x": -19,
      "y": 25,
      "z": 6,
      "name": "Rock_Crystal_Blue_Block"
    },
    {
      "x": -19,
      "y": 26,
      "z": 6,
      "name": "Plant_Moss_Block_Blue"
    },
    {
      "x": -19,
      "y": 27,
      "z": 6,
      "name": "Plant_Moss_Block_Blue"
    },
    {
      "x": -19,
      "y": 28,
      "z": 6,
      "name": "Plant_Moss_Rug_Lime"
    },
    {
      "x": -19,
      "y": 36,
      "z": 6,
      "name": "Plant_Leaves_Azure",
      "rotation": 2
    },
    {
      "x": -19,
      "y": 37,
      "z": 6,
      "name": "Plant_Leaves_Azure",
      "rotation": 2
    },
    {
      "x": -19,
      "y": 38,
      "z": 6,
      "name": "Plant_Leaves_Azure",
      "rotation": 2
    },
    {
      "x": -19,
      "y": 39,
      "z": 6,
      "name": "Plant_Leaves_Azure",
      "rotation": 2
    },
    {
      "x": -19,
      "y": 40,
      "z": 6,
      "name": "Plant_Fruit_Azure",
      "rotation": 2
    },
    {
      "x": -19,
      "y": 24,
      "z": 7,
      "name": "Rock_Crystal_Blue_Block"
    },
    {
      "x": -19,
      "y": 25,
      "z": 7,
      "name": "Rock_Marble"
    },
    {
      "x": -19,
      "y": 26,
      "z": 7,
      "name": "Plant_Moss_Block_Blue"
    },
    {
      "x": -19,
      "y": 27,
      "z": 7,
      "name": "Plant_Moss_Block_Blue"
    },
    {
      "x": -19,
      "y": 28,
      "z": 7,
      "name": "Plant_Moss_Blue"
    },
    {
      "x": -19,
      "y": 35,
      "z": 7,
      "name": "Plant_Leaves_Azure",
      "rotation": 2
    },
    {
      "x": -19,
      "y": 36,
      "z": 7,
      "name": "Plant_Leaves_Azure",
      "rotation": 2
    },
    {
      "x": -19,
      "y": 37,
      "z": 7,
      "name": "Plant_Leaves_Azure",
      "rotation": 2
    },
    {
      "x": -19,
      "y": 38,
      "z": 7,
      "name": "Plant_Leaves_Azure",
      "rotation": 2
    },
    {
      "x": -19,
      "y": 39,
      "z": 7,
      "name": "Plant_Leaves_Azure",
      "rotation": 2
    },
    {
      "x": -19,
      "y": 23,
      "z": 8,
      "name": "Rock_Marble"
    },
    {
      "x": -19,
      "y": 24,
      "z": 8,
      "name": "Rock_Crystal_Blue_Block"
    },
    {
      "x": -19,
      "y": 25,
      "z": 8,
      "name": "Rock_Marble"
    },
    {
      "x": -19,
      "y": 26,
      "z": 8,
      "name": "Rock_Marble"
    },
    {
      "x": -19,
      "y": 27,
      "z": 8,
      "name": "Plant_Moss_Block_Blue"
    },
    {
      "x": -19,
      "y": 28,
      "z": 8,
      "name": "Plant_Moss_Block_Blue"
    },
    {
      "x": -19,
      "y": 29,
      "z": 8,
      "name": "Plant_Moss_Rug_Blue"
    },
    {
      "x": -19,
      "y": 36,
      "z": 8,
      "name": "Plant_Leaves_Azure",
      "rotation": 2
    },
    {
      "x": -19,
      "y": 37,
      "z": 8,
      "name": "Plant_Leaves_Azure",
      "rotation": 2
    },
    {
      "x": -19,
      "y": 38,
      "z": 8,
      "name": "Plant_Leaves_Azure",
      "rotation": 2
    },
    {
      "x": -19,
      "y": 23,
      "z": 9,
      "name": "Plant_Moss_Wall_Blue",
      "rotation": 3
    },
    {
      "x": -19,
      "y": 25,
      "z": 9,
      "name": "Rock_Marble"
    },
    {
      "x": -19,
      "y": 26,
      "z": 9,
      "name": "Plant_Moss_Block_Blue"
    },
    {
      "x": -19,
      "y": 27,
      "z": 9,
      "name": "Plant_Moss_Block_Blue"
    },
    {
      "x": -19,
      "y": 28,
      "z": 9,
      "name": "Plant_Moss_Blue"
    },
    {
      "x": -19,
      "y": 24,
      "z": 10,
      "name": "Plant_Moss_Wall_Blue",
      "rotation": 3
    },
    {
      "x": -19,
      "y": 25,
      "z": 10,
      "name": "Rock_Marble"
    },
    {
      "x": -19,
      "y": 26,
      "z": 10,
      "name": "Plant_Moss_Block_Blue"
    },
    {
      "x": -19,
      "y": 27,
      "z": 10,
      "name": "Plant_Moss_Block_Blue"
    },
    {
      "x": -19,
      "y": 28,
      "z": 10,
      "name": "Plant_Moss_Short_Green_Dark"
    },
    {
      "x": -18,
      "y": 27,
      "z": -11,
      "name": "Plant_Moss_Wall_Blue",
      "rotation": 2
    },
    {
      "x": -18,
      "y": 28,
      "z": -11,
      "name": "Plant_Moss_Block_Blue"
    },
    {
      "x": -18,
      "y": 29,
      "z": -11,
      "name": "Plant_Moss_Block_Blue"
    },
    {
      "x": -18,
      "y": 30,
      "z": -11,
      "name": "Plant_Moss_Short_Green_Dark"
    },
    {
      "x": -18,
      "y": 27,
      "z": -10,
      "name": "Rock_Marble"
    },
    {
      "x": -18,
      "y": 28,
      "z": -10,
      "name": "Rock_Marble"
    },
    {
      "x": -18,
      "y": 29,
      "z": -10,
      "name": "Plant_Moss_Block_Blue"
    },
    {
      "x": -18,
      "y": 30,
      "z": -10,
      "name": "Plant_Moss_Block_Blue"
    },
    {
      "x": -18,
      "y": 31,
      "z": -10,
      "name": "Plant_Moss_Blue"
    },
    {
      "x": -18,
      "y": 26,
      "z": -9,
      "name": "Rock_Marble"
    },
    {
      "x": -18,
      "y": 27,
      "z": -9,
      "name": "Rock_Marble"
    },
    {
      "x": -18,
      "y": 28,
      "z": -9,
      "name": "Rock_Marble"
    },
    {
      "x": -18,
      "y": 29,
      "z": -9,
      "name": "Rock_Marble"
    },
    {
      "x": -18,
      "y": 30,
      "z": -9,
      "name": "Plant_Moss_Block_Blue"
    },
    {
      "x": -18,
      "y": 31,
      "z": -9,
      "name": "Plant_Moss_Block_Blue"
    },
    {
      "x": -18,
      "y": 32,
      "z": -9,
      "name": "Plant_Moss_Blue"
    },
    {
      "x": -18,
      "y": 25,
      "z": -8,
      "name": "Plant_Moss_Wall_Blue",
      "rotation": 3
    },
    {
      "x": -18,
      "y": 26,
      "z": -8,
      "name": "Rock_Marble"
    },
    {
      "x": -18,
      "y": 27,
      "z": -8,
      "name": "Rock_Marble"
    },
    {
      "x": -18,
      "y": 28,
      "z": -8,
      "name": "Rock_Marble"
    },
    {
      "x": -18,
      "y": 29,
      "z": -8,
      "name": "Rock_Marble"
    },
    {
      "x": -18,
      "y": 30,
      "z": -8,
      "name": "Plant_Moss_Block_Blue"
    },
    {
      "x": -18,
      "y": 31,
      "z": -8,
      "name": "Plant_Moss_Block_Blue"
    },
    {
      "x": -18,
      "y": 32,
      "z": -8,
      "name": "Plant_Moss_Short_Green_Dark"
    },
    {
      "x": -18,
      "y": 22,
      "z": -7,
      "name": "Rock_Crystal_Blue_Large"
    },
    {
      "x": -18,
      "y": 23,
      "z": -7,
      "name": "Rock_Marble"
    },
    {
      "x": -18,
      "y": 24,
      "z": -7,
      "name": "Rock_Marble"
    },
    {
      "x": -18,
      "y": 25,
      "z": -7,
      "name": "Rock_Marble"
    },
    {
      "x": -18,
      "y": 26,
      "z": -7,
      "name": "Rock_Marble"
    },
    {
      "x": -18,
      "y": 27,
      "z": -7,
      "name": "Rock_Marble"
    },
    {
      "x": -18,
      "y": 28,
      "z": -7,
      "name": "Rock_Marble"
    },
    {
      "x": -18,
      "y": 29,
      "z": -7,
      "name": "Rock_Marble"
    },
    {
      "x": -18,
      "y": 30,
      "z": -7,
      "name": "Plant_Moss_Block_Blue"
    },
    {
      "x": -18,
      "y": 31,
      "z": -7,
      "name": "Plant_Moss_Block_Blue"
    },
    {
      "x": -18,
      "y": 32,
      "z": -7,
      "name": "Plant_Moss_Rug_Lime"
    },
    {
      "x": -18,
      "y": 19,
      "z": -6,
      "name": "Rock_Crystal_Blue_Block"
    },
    {
      "x": -18,
      "y": 20,
      "z": -6,
      "name": "Rock_Crystal_Blue_Block"
    },
    {
      "x": -18,
      "y": 21,
      "z": -6,
      "name": "Rock_Marble"
    },
    {
      "x": -18,
      "y": 22,
      "z": -6,
      "name": "Rock_Marble"
    },
    {
      "x": -18,
      "y": 23,
      "z": -6,
      "name": "Rock_Marble"
    },
    {
      "x": -18,
      "y": 24,
      "z": -6,
      "name": "Rock_Marble"
    },
    {
      "x": -18,
      "y": 25,
      "z": -6,
      "name": "Rock_Marble"
    },
    {
      "x": -18,
      "y": 26,
      "z": -6,
      "name": "Rock_Marble"
    },
    {
      "x": -18,
      "y": 27,
      "z": -6,
      "name": "Rock_Marble"
    },
    {
      "x": -18,
      "y": 28,
      "z": -6,
      "name": "Rock_Marble"
    },
    {
      "x": -18,
      "y": 29,
      "z": -6,
      "name": "Plant_Moss_Block_Blue"
    },
    {
      "x": -18,
      "y": 30,
      "z": -6,
      "name": "Plant_Moss_Block_Blue"
    },
    {
      "x": -18,
      "y": 31,
      "z": -6,
      "name": "Plant_Moss_Blue"
    },
    {
      "x": -18,
      "y": 21,
      "z": -5,
      "name": "Rock_Crystal_Blue_Block"
    },
    {
      "x": -18,
      "y": 22,
      "z": -5,
      "name": "Rock_Crystal_Blue_Block"
    },
    {
      "x": -18,
      "y": 23,
      "z": -5,
      "name": "Rock_Marble"
    },
    {
      "x": -18,
      "y": 24,
      "z": -5,
      "name": "Rock_Marble"
    },
    {
      "x": -18,
      "y": 25,
      "z": -5,
      "name": "Rock_Marble"
    },
    {
      "x": -18,
      "y": 26,
      "z": -5,
      "name": "Rock_Marble"
    },
    {
      "x": -18,
      "y": 27,
      "z": -5,
      "name": "Rock_Marble"
    },
    {
      "x": -18,
      "y": 28,
      "z": -5,
      "name": "Rock_Marble"
    },
    {
      "x": -18,
      "y": 29,
      "z": -5,
      "name": "Plant_Moss_Block_Blue"
    },
    {
      "x": -18,
      "y": 30,
      "z": -5,
      "name": "Plant_Moss_Block_Blue"
    },
    {
      "x": -18,
      "y": 31,
      "z": -5,
      "name": "Plant_Moss_Rug_Blue"
    },
    {
      "x": -18,
      "y": 24,
      "z": -4,
      "name": "Rock_Crystal_Blue_Block"
    },
    {
      "x": -18,
      "y": 25,
      "z": -4,
      "name": "Rock_Marble"
    },
    {
      "x": -18,
      "y": 26,
      "z": -4,
      "name": "Rock_Marble"
    },
    {
      "x": -18,
      "y": 27,
      "z": -4,
      "name": "Rock_Marble"
    },
    {
      "x": -18,
      "y": 28,
      "z": -4,
      "name": "Rock_Marble"
    },
    {
      "x": -18,
      "y": 29,
      "z": -4,
      "name": "Plant_Moss_Block_Blue"
    },
    {
      "x": -18,
      "y": 30,
      "z": -4,
      "name": "Plant_Moss_Block_Blue"
    },
    {
      "x": -18,
      "y": 31,
      "z": -4,
      "name": "Plant_Moss_Rug_Lime"
    },
    {
      "x": -18,
      "y": 24,
      "z": -3,
      "name": "Rock_Crystal_Blue_Block"
    },
    {
      "x": -18,
      "y": 25,
      "z": -3,
      "name": "Rock_Marble"
    },
    {
      "x": -18,
      "y": 26,
      "z": -3,
      "name": "Rock_Marble"
    },
    {
      "x": -18,
      "y": 27,
      "z": -3,
      "name": "Rock_Marble"
    },
    {
      "x": -18,
      "y": 28,
      "z": -3,
      "name": "Rock_Marble"
    },
    {
      "x": -18,
      "y": 29,
      "z": -3,
      "name": "Plant_Moss_Block_Blue"
    },
    {
      "x": -18,
      "y": 30,
      "z": -3,
      "name": "Plant_Moss_Block_Blue"
    },
    {
      "x": -18,
      "y": 31,
      "z": -3,
      "name": "Plant_Moss_Rug_Lime"
    },
    {
      "x": -18,
      "y": 36,
      "z": -3,
      "name": "Plant_Leaves_Azure",
      "rotation": 2
    },
    {
      "x": -18,
      "y": 37,
      "z": -3,
      "name": "Plant_Leaves_Azure",
      "rotation": 2
    },
    {
      "x": -18,
      "y": 38,
      "z": -3,
      "name": "Plant_Leaves_Azure",
      "rotation": 2
    },
    {
      "x": -18,
      "y": 39,
      "z": -3,
      "name": "Plant_Leaves_Azure",
      "rotation": 2
    },
    {
      "x": -18,
      "y": 40,
      "z": -3,
      "name": "Plant_Fruit_Azure",
      "rotation": 2
    },
    {
      "x": -18,
      "y": 23,
      "z": -2,
      "name": "Rock_Crystal_Blue_Block"
    },
    {
      "x": -18,
      "y": 24,
      "z": -2,
      "name": "Rock_Marble"
    },
    {
      "x": -18,
      "y": 25,
      "z": -2,
      "name": "Rock_Marble"
    },
    {
      "x": -18,
      "y": 26,
      "z": -2,
      "name": "Rock_Marble"
    },
    {
      "x": -18,
      "y": 27,
      "z": -2,
      "name": "Rock_Marble"
    },
    {
      "x": -18,
      "y": 28,
      "z": -2,
      "name": "Rock_Marble"
    },
    {
      "x": -18,
      "y": 29,
      "z": -2,
      "name": "Wood_Azure_Trunk_Full",
      "rotation": 2
    },
    {
      "x": -18,
      "y": 30,
      "z": -2,
      "name": "Wood_Azure_Trunk_Full",
      "rotation": 2
    },
    {
      "x": -18,
      "y": 31,
      "z": -2,
      "name": "Plant_Moss_Rug_Blue"
    },
    {
      "x": -18,
      "y": 37,
      "z": -2,
      "name": "Plant_Leaves_Azure",
      "rotation": 2
    },
    {
      "x": -18,
      "y": 38,
      "z": -2,
      "name": "Plant_Leaves_Azure",
      "rotation": 2
    },
    {
      "x": -18,
      "y": 39,
      "z": -2,
      "name": "Plant_Leaves_Azure",
      "rotation": 2
    },
    {
      "x": -18,
      "y": 23,
      "z": -1,
      "name": "Rock_Crystal_Blue_Block"
    },
    {
      "x": -18,
      "y": 24,
      "z": -1,
      "name": "Rock_Marble"
    },
    {
      "x": -18,
      "y": 25,
      "z": -1,
      "name": "Rock_Marble"
    },
    {
      "x": -18,
      "y": 26,
      "z": -1,
      "name": "Rock_Marble"
    },
    {
      "x": -18,
      "y": 27,
      "z": -1,
      "name": "Rock_Marble"
    },
    {
      "x": -18,
      "y": 28,
      "z": -1,
      "name": "Wood_Azure_Roots",
      "rotation": 2
    },
    {
      "x": -18,
      "y": 29,
      "z": -1,
      "name": "Wood_Azure_Trunk_Full",
      "rotation": 2
    },
    {
      "x": -18,
      "y": 30,
      "z": -1,
      "name": "Wood_Azure_Trunk",
      "rotation": 2
    },
    {
      "x": -18,
      "y": 31,
      "z": -1,
      "name": "Wood_Azure_Trunk_Full",
      "rotation": 2
    },
    {
      "x": -18,
      "y": 39,
      "z": -1,
      "name": "Plant_Leaves_Azure",
      "rotation": 2
    },
    {
      "x": -18,
      "y": 43,
      "z": -1,
      "name": "Plant_Leaves_Azure",
      "rotation": 2
    },
    {
      "x": -18,
      "y": 44,
      "z": -1,
      "name": "Plant_Leaves_Azure",
      "rotation": 2
    },
    {
      "x": -18,
      "y": 24,
      "z": 0,
      "name": "Rock_Crystal_Blue_Block"
    },
    {
      "x": -18,
      "y": 25,
      "z": 0,
      "name": "Rock_Marble"
    },
    {
      "x": -18,
      "y": 26,
      "z": 0,
      "name": "Rock_Marble"
    },
    {
      "x": -18,
      "y": 27,
      "z": 0,
      "name": "Rock_Marble"
    },
    {
      "x": -18,
      "y": 28,
      "z": 0,
      "name": "Rock_Marble"
    },
    {
      "x": -18,
      "y": 29,
      "z": 0,
      "name": "Plant_Moss_Block_Blue"
    },
    {
      "x": -18,
      "y": 30,
      "z": 0,
      "name": "Wood_Azure_Trunk_Full",
      "rotation": 2
    },
    {
      "x": -18,
      "y": 31,
      "z": 0,
      "name": "Wood_Azure_Trunk",
      "rotation": 2
    },
    {
      "x": -18,
      "y": 32,
      "z": 0,
      "name": "Wood_Azure_Trunk",
      "rotation": 2
    },
    {
      "x": -18,
      "y": 33,
      "z": 0,
      "name": "Wood_Azure_Trunk_Full",
      "rotation": 2
    },
    {
      "x": -18,
      "y": 43,
      "z": 0,
      "name": "Plant_Leaves_Azure",
      "rotation": 2
    },
    {
      "x": -18,
      "y": 44,
      "z": 0,
      "name": "Plant_Leaves_Azure",
      "rotation": 2
    },
    {
      "x": -18,
      "y": 45,
      "z": 0,
      "name": "Plant_Fruit_Azure",
      "rotation": 2
    },
    {
      "x": -18,
      "y": 47,
      "z": 0,
      "name": "Plant_Leaves_Azure",
      "rotation": 2
    },
    {
      "x": -18,
      "y": 23,
      "z": 1,
      "name": "Plant_Crop_Mushroom_Block_Blue_Mycelium"
    },
    {
      "x": -18,
      "y": 24,
      "z": 1,
      "name": "Rock_Crystal_Blue_Block"
    },
    {
      "x": -18,
      "y": 25,
      "z": 1,
      "name": "Rock_Marble"
    },
    {
      "x": -18,
      "y": 26,
      "z": 1,
      "name": "Rock_Marble"
    },
    {
      "x": -18,
      "y": 27,
      "z": 1,
      "name": "Rock_Marble"
    },
    {
      "x": -18,
      "y": 28,
      "z": 1,
      "name": "Plant_Moss_Block_Blue"
    },
    {
      "x": -18,
      "y": 29,
      "z": 1,
      "name": "Plant_Moss_Block_Blue"
    },
    {
      "x": -18,
      "y": 30,
      "z": 1,
      "name": "Plant_Moss_Rug_Blue"
    },
    {
      "x": -18,
      "y": 33,
      "z": 1,
      "name": "Wood_Azure_Trunk_Full",
      "rotation": 2
    },
    {
      "x": -18,
      "y": 34,
      "z": 1,
      "name": "Wood_Azure_Trunk",
      "rotation": 2
    },
    {
      "x": -18,
      "y": 35,
      "z": 1,
      "name": "Wood_Azure_Trunk",
      "rotation": 2
    },
    {
      "x": -18,
      "y": 36,
      "z": 1,
      "name": "Wood_Azure_Trunk_Full",
      "rotation": 2
    },
    {
      "x": -18,
      "y": 38,
      "z": 1,
      "name": "Plant_Moss_Wall_Blue",
      "rotation": 2
    },
    {
      "x": -18,
      "y": 40,
      "z": 1,
      "name": "Wood_Azure_Branch_Long",
      "rotation": 7
    },
    {
      "x": -18,
      "y": 41,
      "z": 1,
      "name": "Plant_Moss_Wall_Blue",
      "rotation": 3
    },
    {
      "x": -18,
      "y": 44,
      "z": 1,
      "name": "Plant_Leaves_Azure",
      "rotation": 2
    },
    {
      "x": -18,
      "y": 47,
      "z": 1,
      "name": "Plant_Leaves_Azure",
      "rotation": 2
    },
    {
      "x": -18,
      "y": 48,
      "z": 1,
      "name": "Plant_Leaves_Azure",
      "rotation": 2
    },
    {
      "x": -18,
      "y": 22,
      "z": 2,
      "name": "Rock_Crystal_Blue_Block"
    },
    {
      "x": -18,
      "y": 23,
      "z": 2,
      "name": "Rock_Marble"
    },
    {
      "x": -18,
      "y": 24,
      "z": 2,
      "name": "Rock_Marble"
    },
    {
      "x": -18,
      "y": 25,
      "z": 2,
      "name": "Rock_Marble"
    },
    {
      "x": -18,
      "y": 26,
      "z": 2,
      "name": "Rock_Marble"
    },
    {
      "x": -18,
      "y": 27,
      "z": 2,
      "name": "Rock_Marble"
    },
    {
      "x": -18,
      "y": 28,
      "z": 2,
      "name": "Plant_Moss_Block_Blue"
    },
    {
      "x": -18,
      "y": 29,
      "z": 2,
      "name": "Plant_Moss_Block_Blue"
    },
    {
      "x": -18,
      "y": 30,
      "z": 2,
      "name": "Plant_Moss_Short_Green_Dark"
    },
    {
      "x": -18,
      "y": 35,
      "z": 2,
      "name": "Wood_Azure_Trunk_Full",
      "rotation": 2
    },
    {
      "x": -18,
      "y": 36,
      "z": 2,
      "name": "Wood_Azure_Trunk",
      "rotation": 2
    },
    {
      "x": -18,
      "y": 37,
      "z": 2,
      "name": "Wood_Azure_Trunk",
      "rotation": 2
    },
    {
      "x": -18,
      "y": 38,
      "z": 2,
      "name": "Wood_Azure_Trunk_Full",
      "rotation": 2
    },
    {
      "x": -18,
      "y": 39,
      "z": 2,
      "name": "Plant_Moss_Rug_Blue",
      "rotation": 2
    },
    {
      "x": -18,
      "y": 47,
      "z": 2,
      "name": "Plant_Leaves_Azure",
      "rotation": 2
    },
    {
      "x": -18,
      "y": 48,
      "z": 2,
      "name": "Plant_Leaves_Azure",
      "rotation": 2
    },
    {
      "x": -18,
      "y": 49,
      "z": 2,
      "name": "Plant_Leaves_Azure",
      "rotation": 2
    },
    {
      "x": -18,
      "y": 24,
      "z": 3,
      "name": "Rock_Crystal_Blue_Block"
    },
    {
      "x": -18,
      "y": 25,
      "z": 3,
      "name": "Rock_Marble"
    },
    {
      "x": -18,
      "y": 26,
      "z": 3,
      "name": "Rock_Marble"
    },
    {
      "x": -18,
      "y": 27,
      "z": 3,
      "name": "Plant_Moss_Block_Blue"
    },
    {
      "x": -18,
      "y": 28,
      "z": 3,
      "name": "Plant_Moss_Block_Blue"
    },
    {
      "x": -18,
      "y": 29,
      "z": 3,
      "name": "Plant_Moss_Short_Green_Dark"
    },
    {
      "x": -18,
      "y": 38,
      "z": 3,
      "name": "Plant_Moss_Wall_Blue"
    },
    {
      "x": -18,
      "y": 43,
      "z": 3,
      "name": "Plant_Leaves_Azure",
      "rotation": 2
    },
    {
      "x": -18,
      "y": 49,
      "z": 3,
      "name": "Plant_Leaves_Azure",
      "rotation": 2
    },
    {
      "x": -18,
      "y": 24,
      "z": 4,
      "name": "Rock_Crystal_Blue_Block"
    },
    {
      "x": -18,
      "y": 25,
      "z": 4,
      "name": "Rock_Marble"
    },
    {
      "x": -18,
      "y": 26,
      "z": 4,
      "name": "Rock_Marble"
    },
    {
      "x": -18,
      "y": 27,
      "z": 4,
      "name": "Plant_Moss_Block_Blue"
    },
    {
      "x": -18,
      "y": 28,
      "z": 4,
      "name": "Plant_Moss_Block_Blue"
    },
    {
      "x": -18,
      "y": 29,
      "z": 4,
      "name": "Plant_Moss_Rug_Lime"
    },
    {
      "x": -18,
      "y": 42,
      "z": 4,
      "name": "Plant_Leaves_Azure",
      "rotation": 2
    },
    {
      "x": -18,
      "y": 43,
      "z": 4,
      "name": "Plant_Leaves_Azure",
      "rotation": 2
    },
    {
      "x": -18,
      "y": 44,
      "z": 4,
      "name": "Plant_Leaves_Azure",
      "rotation": 2
    },
    {
      "x": -18,
      "y": 45,
      "z": 4,
      "name": "Plant_Fruit_Azure",
      "rotation": 2
    },
    {
      "x": -18,
      "y": 21,
      "z": 5,
      "name": "Plant_Crop_Mushroom_Block_Blue_Mycelium"
    },
    {
      "x": -18,
      "y": 22,
      "z": 5,
      "name": "Rock_Crystal_Blue_Block"
    },
    {
      "x": -18,
      "y": 23,
      "z": 5,
      "name": "Rock_Crystal_Blue_Block"
    },
    {
      "x": -18,
      "y": 24,
      "z": 5,
      "name": "Rock_Marble"
    },
    {
      "x": -18,
      "y": 25,
      "z": 5,
      "name": "Rock_Marble"
    },
    {
      "x": -18,
      "y": 26,
      "z": 5,
      "name": "Rock_Marble"
    },
    {
      "x": -18,
      "y": 27,
      "z": 5,
      "name": "Plant_Moss_Block_Blue"
    },
    {
      "x": -18,
      "y": 28,
      "z": 5,
      "name": "Plant_Moss_Block_Blue"
    },
    {
      "x": -18,
      "y": 29,
      "z": 5,
      "name": "Plant_Moss_Short_Green_Dark"
    },
    {
      "x": -18,
      "y": 38,
      "z": 5,
      "name": "Plant_Leaves_Azure",
      "rotation": 2
    },
    {
      "x": -18,
      "y": 39,
      "z": 5,
      "name": "Plant_Leaves_Azure",
      "rotation": 2
    },
    {
      "x": -18,
      "y": 43,
      "z": 5,
      "name": "Plant_Leaves_Azure",
      "rotation": 2
    },
    {
      "x": -18,
      "y": 44,
      "z": 5,
      "name": "Plant_Leaves_Azure",
      "rotation": 2
    },
    {
      "x": -18,
      "y": 45,
      "z": 5,
      "name": "Plant_Leaves_Azure",
      "rotation": 2
    },
    {
      "x": -18,
      "y": 22,
      "z": 6,
      "name": "Plant_Crop_Mushroom_Block_Blue_Mycelium"
    },
    {
      "x": -18,
      "y": 23,
      "z": 6,
      "name": "Rock_Crystal_Blue_Block"
    },
    {
      "x": -18,
      "y": 24,
      "z": 6,
      "name": "Rock_Marble"
    },
    {
      "x": -18,
      "y": 25,
      "z": 6,
      "name": "Rock_Marble"
    },
    {
      "x": -18,
      "y": 26,
      "z": 6,
      "name": "Rock_Marble"
    },
    {
      "x": -18,
      "y": 27,
      "z": 6,
      "name": "Plant_Moss_Block_Blue"
    },
    {
      "x": -18,
      "y": 28,
      "z": 6,
      "name": "Plant_Moss_Block_Blue"
    },
    {
      "x": -18,
      "y": 29,
      "z": 6,
      "name": "Plant_Moss_Rug_Lime"
    },
    {
      "x": -18,
      "y": 37,
      "z": 6,
      "name": "Plant_Leaves_Azure",
      "rotation": 2
    },
    {
      "x": -18,
      "y": 38,
      "z": 6,
      "name": "Plant_Leaves_Azure",
      "rotation": 2
    },
    {
      "x": -18,
      "y": 39,
      "z": 6,
      "name": "Plant_Leaves_Azure",
      "rotation": 2
    },
    {
      "x": -18,
      "y": 23,
      "z": 7,
      "name": "Rock_Crystal_Blue_Block"
    },
    {
      "x": -18,
      "y": 24,
      "z": 7,
      "name": "Rock_Marble"
    },
    {
      "x": -18,
      "y": 25,
      "z": 7,
      "name": "Rock_Marble"
    },
    {
      "x": -18,
      "y": 26,
      "z": 7,
      "name": "Rock_Marble"
    },
    {
      "x": -18,
      "y": 27,
      "z": 7,
      "name": "Plant_Moss_Block_Blue"
    },
    {
      "x": -18,
      "y": 28,
      "z": 7,
      "name": "Plant_Moss_Block_Blue"
    },
    {
      "x": -18,
      "y": 29,
      "z": 7,
      "name": "Plant_Moss_Short_Green_Dark"
    },
    {
      "x": -18,
      "y": 35,
      "z": 7,
      "name": "Plant_Leaves_Azure",
      "rotation": 2
    },
    {
      "x": -18,
      "y": 36,
      "z": 7,
      "name": "Plant_Leaves_Azure",
      "rotation": 2
    },
    {
      "x": -18,
      "y": 37,
      "z": 7,
      "name": "Plant_Leaves_Azure",
      "rotation": 2
    },
    {
      "x": -18,
      "y": 38,
      "z": 7,
      "name": "Plant_Leaves_Azure",
      "rotation": 2
    },
    {
      "x": -18,
      "y": 39,
      "z": 7,
      "name": "Plant_Leaves_Azure",
      "rotation": 2
    },
    {
      "x": -18,
      "y": 40,
      "z": 7,
      "name": "Plant_Leaves_Azure",
      "rotation": 2
    },
    {
      "x": -18,
      "y": 20,
      "z": 8,
      "name": "Rock_Crystal_Blue_Medium"
    },
    {
      "x": -18,
      "y": 21,
      "z": 8,
      "name": "Rock_Crystal_Blue_Block"
    },
    {
      "x": -18,
      "y": 22,
      "z": 8,
      "name": "Rock_Marble"
    },
    {
      "x": -18,
      "y": 23,
      "z": 8,
      "name": "Rock_Marble"
    },
    {
      "x": -18,
      "y": 24,
      "z": 8,
      "name": "Rock_Marble"
    },
    {
      "x": -18,
      "y": 25,
      "z": 8,
      "name": "Rock_Marble"
    },
    {
      "x": -18,
      "y": 26,
      "z": 8,
      "name": "Plant_Moss_Block_Blue"
    },
    {
      "x": -18,
      "y": 27,
      "z": 8,
      "name": "Plant_Moss_Block_Blue"
    },
    {
      "x": -18,
      "y": 28,
      "z": 8,
      "name": "Plant_Moss_Rug_Blue"
    },
    {
      "x": -18,
      "y": 36,
      "z": 8,
      "name": "Plant_Leaves_Azure",
      "rotation": 2
    },
    {
      "x": -18,
      "y": 37,
      "z": 8,
      "name": "Plant_Leaves_Azure",
      "rotation": 2
    },
    {
      "x": -18,
      "y": 38,
      "z": 8,
      "name": "Plant_Leaves_Azure",
      "rotation": 2
    },
    {
      "x": -18,
      "y": 39,
      "z": 8,
      "name": "Plant_Leaves_Azure",
      "rotation": 2
    },
    {
      "x": -18,
      "y": 22,
      "z": 9,
      "name": "Rock_Marble"
    },
    {
      "x": -18,
      "y": 23,
      "z": 9,
      "name": "Rock_Marble"
    },
    {
      "x": -18,
      "y": 24,
      "z": 9,
      "name": "Rock_Marble"
    },
    {
      "x": -18,
      "y": 25,
      "z": 9,
      "name": "Rock_Marble"
    },
    {
      "x": -18,
      "y": 26,
      "z": 9,
      "name": "Plant_Moss_Block_Blue"
    },
    {
      "x": -18,
      "y": 27,
      "z": 9,
      "name": "Plant_Moss_Block_Blue"
    },
    {
      "x": -18,
      "y": 28,
      "z": 9,
      "name": "Plant_Moss_Short_Green_Dark"
    },
    {
      "x": -18,
      "y": 23,
      "z": 10,
      "name": "Rock_Marble"
    },
    {
      "x": -18,
      "y": 24,
      "z": 10,
      "name": "Rock_Marble"
    },
    {
      "x": -18,
      "y": 25,
      "z": 10,
      "name": "Rock_Marble"
    },
    {
      "x": -18,
      "y": 26,
      "z": 10,
      "name": "Plant_Moss_Block_Blue"
    },
    {
      "x": -18,
      "y": 27,
      "z": 10,
      "name": "Plant_Moss_Block_Blue"
    },
    {
      "x": -18,
      "y": 28,
      "z": 10,
      "name": "Plant_Moss_Rug_Blue"
    },
    {
      "x": -18,
      "y": 23,
      "z": 11,
      "name": "Plant_Moss_Wall_Blue"
    },
    {
      "x": -18,
      "y": 25,
      "z": 11,
      "name": "Plant_Moss_Block_Blue"
    },
    {
      "x": -18,
      "y": 26,
      "z": 11,
      "name": "Plant_Moss_Block_Blue"
    },
    {
      "x": -18,
      "y": 27,
      "z": 11,
      "name": "Plant_Moss_Rug_Lime"
    },
    {
      "x": -18,
      "y": 25,
      "z": 12,
      "name": "Plant_Moss_Block_Blue"
    },
    {
      "x": -18,
      "y": 26,
      "z": 12,
      "name": "Plant_Moss_Rug_Blue"
    },
    {
      "x": -17,
      "y": 27,
      "z": -12,
      "name": "Plant_Moss_Wall_Blue",
      "rotation": 2
    },
    {
      "x": -17,
      "y": 28,
      "z": -12,
      "name": "Plant_Moss_Block_Blue"
    },
    {
      "x": -17,
      "y": 29,
      "z": -12,
      "name": "Plant_Moss_Block_Blue"
    },
    {
      "x": -17,
      "y": 30,
      "z": -12,
      "name": "Plant_Moss_Short_Green_Dark"
    },
    {
      "x": -17,
      "y": 27,
      "z": -11,
      "name": "Rock_Marble"
    },
    {
      "x": -17,
      "y": 28,
      "z": -11,
      "name": "Rock_Marble"
    },
    {
      "x": -17,
      "y": 29,
      "z": -11,
      "name": "Plant_Moss_Block_Blue"
    },
    {
      "x": -17,
      "y": 30,
      "z": -11,
      "name": "Plant_Moss_Block_Blue"
    },
    {
      "x": -17,
      "y": 31,
      "z": -11,
      "name": "Plant_Moss_Blue"
    },
    {
      "x": -17,
      "y": 27,
      "z": -10,
      "name": "Rock_Crystal_Blue_Block"
    },
    {
      "x": -17,
      "y": 28,
      "z": -10,
      "name": "Rock_Marble"
    },
    {
      "x": -17,
      "y": 29,
      "z": -10,
      "name": "Rock_Marble"
    },
    {
      "x": -17,
      "y": 30,
      "z": -10,
      "name": "Plant_Moss_Block_Blue"
    },
    {
      "x": -17,
      "y": 31,
      "z": -10,
      "name": "Plant_Moss_Block_Blue"
    },
    {
      "x": -17,
      "y": 32,
      "z": -10,
      "name": "Plant_Moss_Short_Green_Dark"
    },
    {
      "x": -17,
      "y": 26,
      "z": -9,
      "name": "Plant_Crop_Mushroom_Block_Blue_Mycelium"
    },
    {
      "x": -17,
      "y": 27,
      "z": -9,
      "name": "Rock_Crystal_Blue_Block"
    },
    {
      "x": -17,
      "y": 28,
      "z": -9,
      "name": "Rock_Marble"
    },
    {
      "x": -17,
      "y": 29,
      "z": -9,
      "name": "Rock_Marble"
    },
    {
      "x": -17,
      "y": 30,
      "z": -9,
      "name": "Plant_Moss_Block_Blue"
    },
    {
      "x": -17,
      "y": 31,
      "z": -9,
      "name": "Plant_Moss_Block_Blue"
    },
    {
      "x": -17,
      "y": 32,
      "z": -9,
      "name": "Plant_Moss_Short_Green_Dark"
    },
    {
      "x": -17,
      "y": 23,
      "z": -8,
      "name": "Rock_Crystal_Blue_Small"
    },
    {
      "x": -17,
      "y": 24,
      "z": -8,
      "name": "Rock_Crystal_Blue_Block"
    },
    {
      "x": -17,
      "y": 25,
      "z": -8,
      "name": "Rock_Marble"
    },
    {
      "x": -17,
      "y": 26,
      "z": -8,
      "name": "Rock_Marble"
    },
    {
      "x": -17,
      "y": 27,
      "z": -8,
      "name": "Rock_Marble"
    },
    {
      "x": -17,
      "y": 28,
      "z": -8,
      "name": "Rock_Marble"
    },
    {
      "x": -17,
      "y": 29,
      "z": -8,
      "name": "Rock_Marble"
    },
    {
      "x": -17,
      "y": 30,
      "z": -8,
      "name": "Plant_Moss_Block_Blue"
    },
    {
      "x": -17,
      "y": 31,
      "z": -8,
      "name": "Plant_Moss_Block_Blue"
    },
    {
      "x": -17,
      "y": 32,
      "z": -8,
      "name": "Plant_Moss_Rug_Blue"
    },
    {
      "x": -17,
      "y": 19,
      "z": -7,
      "name": "Rock_Crystal_Blue_Block"
    },
    {
      "x": -17,
      "y": 20,
      "z": -7,
      "name": "Rock_Crystal_Blue_Block"
    },
    {
      "x": -17,
      "y": 21,
      "z": -7,
      "name": "Rock_Marble"
    },
    {
      "x": -17,
      "y": 22,
      "z": -7,
      "name": "Rock_Marble"
    },
    {
      "x": -17,
      "y": 23,
      "z": -7,
      "name": "Rock_Marble"
    },
    {
      "x": -17,
      "y": 24,
      "z": -7,
      "name": "Rock_Marble"
    },
    {
      "x": -17,
      "y": 25,
      "z": -7,
      "name": "Rock_Marble"
    },
    {
      "x": -17,
      "y": 26,
      "z": -7,
      "name": "Rock_Marble"
    },
    {
      "x": -17,
      "y": 27,
      "z": -7,
      "name": "Rock_Marble"
    },
    {
      "x": -17,
      "y": 28,
      "z": -7,
      "name": "Rock_Marble"
    },
    {
      "x": -17,
      "y": 29,
      "z": -7,
      "name": "Rock_Marble"
    },
    {
      "x": -17,
      "y": 30,
      "z": -7,
      "name": "Plant_Moss_Block_Blue"
    },
    {
      "x": -17,
      "y": 31,
      "z": -7,
      "name": "Plant_Moss_Block_Blue"
    },
    {
      "x": -17,
      "y": 32,
      "z": -7,
      "name": "Plant_Moss_Rug_Blue"
    },
    {
      "x": -17,
      "y": 18,
      "z": -6,
      "name": "Rock_Crystal_Blue_Block"
    },
    {
      "x": -17,
      "y": 19,
      "z": -6,
      "name": "Rock_Crystal_Blue_Block"
    },
    {
      "x": -17,
      "y": 20,
      "z": -6,
      "name": "Rock_Marble"
    },
    {
      "x": -17,
      "y": 21,
      "z": -6,
      "name": "Rock_Marble"
    },
    {
      "x": -17,
      "y": 22,
      "z": -6,
      "name": "Rock_Marble"
    },
    {
      "x": -17,
      "y": 23,
      "z": -6,
      "name": "Rock_Marble"
    },
    {
      "x": -17,
      "y": 24,
      "z": -6,
      "name": "Rock_Marble"
    },
    {
      "x": -17,
      "y": 25,
      "z": -6,
      "name": "Rock_Marble"
    },
    {
      "x": -17,
      "y": 26,
      "z": -6,
      "name": "Rock_Marble"
    },
    {
      "x": -17,
      "y": 27,
      "z": -6,
      "name": "Rock_Marble"
    },
    {
      "x": -17,
      "y": 28,
      "z": -6,
      "name": "Rock_Marble"
    },
    {
      "x": -17,
      "y": 29,
      "z": -6,
      "name": "Rock_Marble"
    },
    {
      "x": -17,
      "y": 30,
      "z": -6,
      "name": "Plant_Moss_Block_Blue"
    },
    {
      "x": -17,
      "y": 31,
      "z": -6,
      "name": "Plant_Moss_Block_Blue"
    },
    {
      "x": -17,
      "y": 32,
      "z": -6,
      "name": "Plant_Moss_Blue"
    },
    {
      "x": -17,
      "y": 19,
      "z": -5,
      "name": "Rock_Crystal_Blue_Block"
    },
    {
      "x": -17,
      "y": 20,
      "z": -5,
      "name": "Rock_Crystal_Blue_Block"
    },
    {
      "x": -17,
      "y": 21,
      "z": -5,
      "name": "Rock_Marble"
    },
    {
      "x": -17,
      "y": 22,
      "z": -5,
      "name": "Rock_Marble"
    },
    {
      "x": -17,
      "y": 23,
      "z": -5,
      "name": "Rock_Marble"
    },
    {
      "x": -17,
      "y": 24,
      "z": -5,
      "name": "Rock_Marble"
    },
    {
      "x": -17,
      "y": 25,
      "z": -5,
      "name": "Rock_Marble"
    },
    {
      "x": -17,
      "y": 26,
      "z": -5,
      "name": "Rock_Marble"
    },
    {
      "x": -17,
      "y": 27,
      "z": -5,
      "name": "Rock_Marble"
    },
    {
      "x": -17,
      "y": 28,
      "z": -5,
      "name": "Rock_Marble"
    },
    {
      "x": -17,
      "y": 29,
      "z": -5,
      "name": "Rock_Marble"
    },
    {
      "x": -17,
      "y": 30,
      "z": -5,
      "name": "Plant_Moss_Block_Blue"
    },
    {
      "x": -17,
      "y": 31,
      "z": -5,
      "name": "Plant_Moss_Block_Blue"
    },
    {
      "x": -17,
      "y": 32,
      "z": -5,
      "name": "Plant_Moss_Blue"
    },
    {
      "x": -17,
      "y": 21,
      "z": -4,
      "name": "Rock_Crystal_Blue_Medium"
    },
    {
      "x": -17,
      "y": 22,
      "z": -4,
      "name": "Rock_Crystal_Blue_Block"
    },
    {
      "x": -17,
      "y": 23,
      "z": -4,
      "name": "Rock_Marble"
    },
    {
      "x": -17,
      "y": 24,
      "z": -4,
      "name": "Rock_Marble"
    },
    {
      "x": -17,
      "y": 25,
      "z": -4,
      "name": "Rock_Marble"
    },
    {
      "x": -17,
      "y": 26,
      "z": -4,
      "name": "Rock_Marble"
    },
    {
      "x": -17,
      "y": 27,
      "z": -4,
      "name": "Rock_Marble"
    },
    {
      "x": -17,
      "y": 28,
      "z": -4,
      "name": "Rock_Marble"
    },
    {
      "x": -17,
      "y": 29,
      "z": -4,
      "name": "Rock_Marble"
    },
    {
      "x": -17,
      "y": 30,
      "z": -4,
      "name": "Plant_Moss_Block_Blue"
    },
    {
      "x": -17,
      "y": 31,
      "z": -4,
      "name": "Plant_Moss_Block_Blue"
    },
    {
      "x": -17,
      "y": 32,
      "z": -4,
      "name": "Plant_Moss_Rug_Lime"
    },
    {
      "x": -17,
      "y": 36,
      "z": -4,
      "name": "Plant_Leaves_Azure",
      "rotation": 2
    },
    {
      "x": -17,
      "y": 21,
      "z": -3,
      "name": "Rock_Crystal_Blue_Block"
    },
    {
      "x": -17,
      "y": 22,
      "z": -3,
      "name": "Rock_Crystal_Blue_Block"
    },
    {
      "x": -17,
      "y": 23,
      "z": -3,
      "name": "Rock_Marble"
    },
    {
      "x": -17,
      "y": 24,
      "z": -3,
      "name": "Rock_Marble"
    },
    {
      "x": -17,
      "y": 25,
      "z": -3,
      "name": "Rock_Marble"
    },
    {
      "x": -17,
      "y": 26,
      "z": -3,
      "name": "Rock_Marble"
    },
    {
      "x": -17,
      "y": 27,
      "z": -3,
      "name": "Rock_Marble"
    },
    {
      "x": -17,
      "y": 28,
      "z": -3,
      "name": "Rock_Marble"
    },
    {
      "x": -17,
      "y": 29,
      "z": -3,
      "name": "Rock_Marble"
    },
    {
      "x": -17,
      "y": 30,
      "z": -3,
      "name": "Plant_Moss_Block_Blue"
    },
    {
      "x": -17,
      "y": 31,
      "z": -3,
      "name": "Plant_Moss_Block_Blue"
    },
    {
      "x": -17,
      "y": 32,
      "z": -3,
      "name": "Plant_Moss_Rug_Lime"
    },
    {
      "x": -17,
      "y": 35,
      "z": -3,
      "name": "Plant_Leaves_Azure",
      "rotation": 2
    },
    {
      "x": -17,
      "y": 36,
      "z": -3,
      "name": "Plant_Leaves_Azure",
      "rotation": 2
    },
    {
      "x": -17,
      "y": 37,
      "z": -3,
      "name": "Plant_Leaves_Azure",
      "rotation": 2
    },
    {
      "x": -17,
      "y": 38,
      "z": -3,
      "name": "Plant_Leaves_Azure",
      "rotation": 2
    },
    {
      "x": -17,
      "y": 21,
      "z": -2,
      "name": "Rock_Crystal_Blue_Block"
    },
    {
      "x": -17,
      "y": 22,
      "z": -2,
      "name": "Rock_Crystal_Blue_Block"
    },
    {
      "x": -17,
      "y": 23,
      "z": -2,
      "name": "Rock_Marble"
    },
    {
      "x": -17,
      "y": 24,
      "z": -2,
      "name": "Rock_Marble"
    },
    {
      "x": -17,
      "y": 25,
      "z": -2,
      "name": "Rock_Marble"
    },
    {
      "x": -17,
      "y": 26,
      "z": -2,
      "name": "Rock_Marble"
    },
    {
      "x": -17,
      "y": 27,
      "z": -2,
      "name": "Rock_Marble"
    },
    {
      "x": -17,
      "y": 28,
      "z": -2,
      "name": "Rock_Marble"
    },
    {
      "x": -17,
      "y": 29,
      "z": -2,
      "name": "Rock_Marble"
    },
    {
      "x": -17,
      "y": 30,
      "z": -2,
      "name": "Plant_Moss_Block_Blue"
    },
    {
      "x": -17,
      "y": 31,
      "z": -2,
      "name": "Plant_Moss_Block_Blue"
    },
    {
      "x": -17,
      "y": 32,
      "z": -2,
      "name": "Plant_Moss_Rug_Blue"
    },
    {
      "x": -17,
      "y": 35,
      "z": -2,
      "name": "Plant_Leaves_Azure",
      "rotation": 2
    },
    {
      "x": -17,
      "y": 36,
      "z": -2,
      "name": "Wood_Azure_Branch_Long",
      "rotation": 6
    },
    {
      "x": -17,
      "y": 38,
      "z": -2,
      "name": "Plant_Leaves_Azure",
      "rotation": 2
    },
    {
      "x": -17,
      "y": 41,
      "z": -2,
      "name": "Plant_Leaves_Azure",
      "rotation": 2
    },
    {
      "x": -17,
      "y": 42,
      "z": -2,
      "name": "Plant_Leaves_Azure",
      "rotation": 2
    },
    {
      "x": -17,
      "y": 43,
      "z": -2,
      "name": "Plant_Leaves_Azure",
      "rotation": 2
    },
    {
      "x": -17,
      "y": 22,
      "z": -1,
      "name": "Plant_Crop_Mushroom_Block_Blue_Mycelium"
    },
    {
      "x": -17,
      "y": 23,
      "z": -1,
      "name": "Rock_Crystal_Blue_Block"
    },
    {
      "x": -17,
      "y": 24,
      "z": -1,
      "name": "Rock_Marble"
    },
    {
      "x": -17,
      "y": 25,
      "z": -1,
      "name": "Rock_Marble"
    },
    {
      "x": -17,
      "y": 26,
      "z": -1,
      "name": "Rock_Marble"
    },
    {
      "x": -17,
      "y": 27,
      "z": -1,
      "name": "Rock_Marble"
    },
    {
      "x": -17,
      "y": 28,
      "z": -1,
      "name": "Rock_Marble"
    },
    {
      "x": -17,
      "y": 29,
      "z": -1,
      "name": "Plant_Moss_Block_Blue"
    },
    {
      "x": -17,
      "y": 30,
      "z": -1,
      "name": "Wood_Azure_Trunk_Full",
      "rotation": 2
    },
    {
      "x": -17,
      "y": 31,
      "z": -1,
      "name": "Wood_Azure_Trunk",
      "rotation": 2
    },
    {
      "x": -17,
      "y": 32,
      "z": -1,
      "name": "Wood_Azure_Trunk_Full",
      "rotation": 2
    },
    {
      "x": -17,
      "y": 36,
      "z": -1,
      "name": "Wood_Azure_Branch_Long",
      "rotation": 6
    },
    {
      "x": -17,
      "y": 42,
      "z": -1,
      "name": "Plant_Leaves_Azure",
      "rotation": 2
    },
    {
      "x": -17,
      "y": 43,
      "z": -1,
      "name": "Wood_Azure_Branch_Long",
      "rotation": 6
    },
    {
      "x": -17,
      "y": 44,
      "z": -1,
      "name": "Plant_Leaves_Azure",
      "rotation": 2
    },
    {
      "x": -17,
      "y": 23,
      "z": 0,
      "name": "Rock_Crystal_Blue_Block"
    },
    {
      "x": -17,
      "y": 24,
      "z": 0,
      "name": "Rock_Marble"
    },
    {
      "x": -17,
      "y": 25,
      "z": 0,
      "name": "Rock_Marble"
    },
    {
      "x": -17,
      "y": 26,
      "z": 0,
      "name": "Rock_Marble"
    },
    {
      "x": -17,
      "y": 27,
      "z": 0,
      "name": "Rock_Marble"
    },
    {
      "x": -17,
      "y": 28,
      "z": 0,
      "name": "Rock_Marble"
    },
    {
      "x": -17,
      "y": 29,
      "z": 0,
      "name": "Plant_Moss_Block_Blue"
    },
    {
      "x": -17,
      "y": 30,
      "z": 0,
      "name": "Wood_Azure_Trunk_Full",
      "rotation": 2
    },
    {
      "x": -17,
      "y": 31,
      "z": 0,
      "name": "Wood_Azure_Trunk",
      "rotation": 2
    },
    {
      "x": -17,
      "y": 32,
      "z": 0,
      "name": "Wood_Azure_Trunk",
      "rotation": 2
    },
    {
      "x": -17,
      "y": 33,
      "z": 0,
      "name": "Wood_Azure_Trunk",
      "rotation": 2
    },
    {
      "x": -17,
      "y": 34,
      "z": 0,
      "name": "Wood_Azure_Trunk",
      "rotation": 2
    },
    {
      "x": -17,
      "y": 35,
      "z": 0,
      "name": "Wood_Azure_Trunk",
      "rotation": 2
    },
    {
      "x": -17,
      "y": 36,
      "z": 0,
      "name": "Wood_Azure_Trunk",
      "rotation": 2
    },
    {
      "x": -17,
      "y": 37,
      "z": 0,
      "name": "Wood_Azure_Trunk_Full",
      "rotation": 2
    },
    {
      "x": -17,
      "y": 41,
      "z": 0,
      "name": "Plant_Moss_Wall_Blue",
      "rotation": 2
    },
    {
      "x": -17,
      "y": 43,
      "z": 0,
      "name": "Wood_Azure_Branch_Long",
      "rotation": 6
    },
    {
      "x": -17,
      "y": 46,
      "z": 0,
      "name": "Plant_Leaves_Azure",
      "rotation": 2
    },
    {
      "x": -17,
      "y": 47,
      "z": 0,
      "name": "Plant_Leaves_Azure",
      "rotation": 2
    },
    {
      "x": -17,
      "y": 48,
      "z": 0,
      "name": "Plant_Leaves_Azure",
      "rotation": 2
    },
    {
      "x": -17,
      "y": 22,
      "z": 1,
      "name": "Plant_Crop_Mushroom_Block_Blue_Mycelium"
    },
    {
      "x": -17,
      "y": 23,
      "z": 1,
      "name": "Rock_Crystal_Blue_Block"
    },
    {
      "x": -17,
      "y": 24,
      "z": 1,
      "name": "Rock_Marble"
    },
    {
      "x": -17,
      "y": 25,
      "z": 1,
      "name": "Rock_Marble"
    },
    {
      "x": -17,
      "y": 26,
      "z": 1,
      "name": "Rock_Marble"
    },
    {
      "x": -17,
      "y": 27,
      "z": 1,
      "name": "Rock_Marble"
    },
    {
      "x": -17,
      "y": 28,
      "z": 1,
      "name": "Rock_Marble"
    },
    {
      "x": -17,
      "y": 29,
      "z": 1,
      "name": "Plant_Moss_Block_Blue"
    },
    {
      "x": -17,
      "y": 30,
      "z": 1,
      "name": "Plant_Moss_Block_Blue"
    },
    {
      "x": -17,
      "y": 31,
      "z": 1,
      "name": "Wood_Azure_Trunk",
      "rotation": 2
    },
    {
      "x": -17,
      "y": 32,
      "z": 1,
      "name": "Wood_Azure_Trunk",
      "rotation": 2
    },
    {
      "x": -17,
      "y": 33,
      "z": 1,
      "name": "Wood_Azure_Trunk",
      "rotation": 2
    },
    {
      "x": -17,
      "y": 34,
      "z": 1,
      "name": "Wood_Azure_Trunk",
      "rotation": 2
    },
    {
      "x": -17,
      "y": 35,
      "z": 1,
      "name": "Wood_Azure_Trunk",
      "rotation": 2
    },
    {
      "x": -17,
      "y": 36,
      "z": 1,
      "name": "Wood_Azure_Trunk",
      "rotation": 2
    },
    {
      "x": -17,
      "y": 37,
      "z": 1,
      "name": "Wood_Azure_Trunk",
      "rotation": 2
    },
    {
      "x": -17,
      "y": 38,
      "z": 1,
      "name": "Wood_Azure_Trunk",
      "rotation": 2
    },
    {
      "x": -17,
      "y": 39,
      "z": 1,
      "name": "Wood_Azure_Trunk",
      "rotation": 2
    },
    {
      "x": -17,
      "y": 40,
      "z": 1,
      "name": "Wood_Azure_Trunk",
      "rotation": 2
    },
    {
      "x": -17,
      "y": 41,
      "z": 1,
      "name": "Wood_Azure_Trunk_Full",
      "rotation": 2
    },
    {
      "x": -17,
      "y": 42,
      "z": 1,
      "name": "Plant_Moss_Rug_Blue",
      "rotation": 2
    },
    {
      "x": -17,
      "y": 43,
      "z": 1,
      "name": "Wood_Azure_Branch_Long",
      "rotation": 6
    },
    {
      "x": -17,
      "y": 46,
      "z": 1,
      "name": "Plant_Leaves_Azure",
      "rotation": 2
    },
    {
      "x": -17,
      "y": 47,
      "z": 1,
      "name": "Plant_Leaves_Azure",
      "rotation": 2
    },
    {
      "x": -17,
      "y": 48,
      "z": 1,
      "name": "Plant_Leaves_Azure",
      "rotation": 2
    },
    {
      "x": -17,
      "y": 49,
      "z": 1,
      "name": "Plant_Leaves_Azure",
      "rotation": 2
    },
    {
      "x": -17,
      "y": 22,
      "z": 2,
      "name": "Rock_Crystal_Blue_Block"
    },
    {
      "x": -17,
      "y": 23,
      "z": 2,
      "name": "Rock_Marble"
    },
    {
      "x": -17,
      "y": 24,
      "z": 2,
      "name": "Rock_Marble"
    },
    {
      "x": -17,
      "y": 25,
      "z": 2,
      "name": "Rock_Marble"
    },
    {
      "x": -17,
      "y": 26,
      "z": 2,
      "name": "Rock_Marble"
    },
    {
      "x": -17,
      "y": 27,
      "z": 2,
      "name": "Rock_Marble"
    },
    {
      "x": -17,
      "y": 28,
      "z": 2,
      "name": "Plant_Moss_Block_Blue"
    },
    {
      "x": -17,
      "y": 29,
      "z": 2,
      "name": "Plant_Moss_Block_Blue"
    },
    {
      "x": -17,
      "y": 30,
      "z": 2,
      "name": "Wood_Azure_Trunk_Full",
      "rotation": 2
    },
    {
      "x": -17,
      "y": 31,
      "z": 2,
      "name": "Wood_Azure_Trunk",
      "rotation": 2
    },
    {
      "x": -17,
      "y": 32,
      "z": 2,
      "name": "Wood_Azure_Trunk",
      "rotation": 2
    },
    {
      "x": -17,
      "y": 33,
      "z": 2,
      "name": "Wood_Azure_Trunk",
      "rotation": 2
    },
    {
      "x": -17,
      "y": 34,
      "z": 2,
      "name": "Wood_Azure_Trunk",
      "rotation": 2
    },
    {
      "x": -17,
      "y": 35,
      "z": 2,
      "name": "Wood_Azure_Trunk",
      "rotation": 2
    },
    {
      "x": -17,
      "y": 36,
      "z": 2,
      "name": "Wood_Azure_Trunk",
      "rotation": 2
    },
    {
      "x": -17,
      "y": 37,
      "z": 2,
      "name": "Wood_Azure_Trunk",
      "rotation": 2
    },
    {
      "x": -17,
      "y": 38,
      "z": 2,
      "name": "Wood_Azure_Trunk",
      "rotation": 2
    },
    {
      "x": -17,
      "y": 39,
      "z": 2,
      "name": "Wood_Azure_Trunk",
      "rotation": 2
    },
    {
      "x": -17,
      "y": 40,
      "z": 2,
      "name": "Wood_Azure_Trunk",
      "rotation": 2
    },
    {
      "x": -17,
      "y": 41,
      "z": 2,
      "name": "Wood_Azure_Trunk",
      "rotation": 2
    },
    {
      "x": -17,
      "y": 42,
      "z": 2,
      "name": "Wood_Azure_Trunk",
      "rotation": 2
    },
    {
      "x": -17,
      "y": 43,
      "z": 2,
      "name": "Wood_Azure_Trunk_Full",
      "rotation": 2
    },
    {
      "x": -17,
      "y": 46,
      "z": 2,
      "name": "Plant_Moss_Wall_Blue",
      "rotation": 3
    },
    {
      "x": -17,
      "y": 48,
      "z": 2,
      "name": "Plant_Leaves_Azure",
      "rotation": 2
    },
    {
      "x": -17,
      "y": 49,
      "z": 2,
      "name": "Plant_Leaves_Azure",
      "rotation": 2
    },
    {
      "x": -17,
      "y": 50,
      "z": 2,
      "name": "Plant_Leaves_Azure",
      "rotation": 2
    },
    {
      "x": -17,
      "y": 51,
      "z": 2,
      "name": "Plant_Fruit_Azure",
      "rotation": 2
    },
    {
      "x": -17,
      "y": 20,
      "z": 3,
      "name": "Rock_Crystal_Blue_Block"
    },
    {
      "x": -17,
      "y": 21,
      "z": 3,
      "name": "Rock_Crystal_Blue_Block"
    },
    {
      "x": -17,
      "y": 22,
      "z": 3,
      "name": "Rock_Marble"
    },
    {
      "x": -17,
      "y": 23,
      "z": 3,
      "name": "Rock_Marble"
    },
    {
      "x": -17,
      "y": 24,
      "z": 3,
      "name": "Rock_Marble"
    },
    {
      "x": -17,
      "y": 25,
      "z": 3,
      "name": "Rock_Marble"
    },
    {
      "x": -17,
      "y": 26,
      "z": 3,
      "name": "Rock_Marble"
    },
    {
      "x": -17,
      "y": 27,
      "z": 3,
      "name": "Rock_Marble"
    },
    {
      "x": -17,
      "y": 28,
      "z": 3,
      "name": "Plant_Moss_Block_Blue"
    },
    {
      "x": -17,
      "y": 29,
      "z": 3,
      "name": "Plant_Moss_Block_Blue"
    },
    {
      "x": -17,
      "y": 30,
      "z": 3,
      "name": "Wood_Azure_Trunk_Full",
      "rotation": 2
    },
    {
      "x": -17,
      "y": 31,
      "z": 3,
      "name": "Wood_Azure_Trunk",
      "rotation": 2
    },
    {
      "x": -17,
      "y": 32,
      "z": 3,
      "name": "Wood_Azure_Trunk_Full",
      "rotation": 2
    },
    {
      "x": -17,
      "y": 38,
      "z": 3,
      "name": "Wood_Azure_Trunk_Full",
      "rotation": 2
    },
    {
      "x": -17,
      "y": 39,
      "z": 3,
      "name": "Wood_Azure_Trunk",
      "rotation": 2
    },
    {
      "x": -17,
      "y": 40,
      "z": 3,
      "name": "Wood_Azure_Trunk_Full",
      "rotation": 2
    },
    {
      "x": -17,
      "y": 43,
      "z": 3,
      "name": "Wood_Azure_Branch_Long",
      "rotation": 6
    },
    {
      "x": -17,
      "y": 48,
      "z": 3,
      "name": "Plant_Leaves_Azure",
      "rotation": 2
    },
    {
      "x": -17,
      "y": 49,
      "z": 3,
      "name": "Plant_Leaves_Azure",
      "rotation": 2
    },
    {
      "x": -17,
      "y": 50,
      "z": 3,
      "name": "Plant_Leaves_Azure",
      "rotation": 2
    },
    {
      "x": -17,
      "y": 51,
      "z": 3,
      "name": "Plant_Leaves_Azure",
      "rotation": 2
    },
    {
      "x": -17,
      "y": 20,
      "z": 4,
      "name": "Rock_Crystal_Blue_Block"
    },
    {
      "x": -17,
      "y": 21,
      "z": 4,
      "name": "Rock_Crystal_Blue_Block"
    },
    {
      "x": -17,
      "y": 22,
      "z": 4,
      "name": "Rock_Crystal_Blue_Block"
    },
    {
      "x": -17,
      "y": 23,
      "z": 4,
      "name": "Rock_Marble"
    },
    {
      "x": -17,
      "y": 24,
      "z": 4,
      "name": "Rock_Marble"
    },
    {
      "x": -17,
      "y": 25,
      "z": 4,
      "name": "Rock_Marble"
    },
    {
      "x": -17,
      "y": 26,
      "z": 4,
      "name": "Rock_Marble"
    },
    {
      "x": -17,
      "y": 27,
      "z": 4,
      "name": "Rock_Marble"
    },
    {
      "x": -17,
      "y": 28,
      "z": 4,
      "name": "Plant_Moss_Block_Blue"
    },
    {
      "x": -17,
      "y": 29,
      "z": 4,
      "name": "Plant_Moss_Block_Blue"
    },
    {
      "x": -17,
      "y": 30,
      "z": 4,
      "name": "Plant_Moss_Blue"
    },
    {
      "x": -17,
      "y": 38,
      "z": 4,
      "name": "Wood_Azure_Branch_Long",
      "rotation": 6
    },
    {
      "x": -17,
      "y": 43,
      "z": 4,
      "name": "Plant_Leaves_Azure",
      "rotation": 2
    },
    {
      "x": -17,
      "y": 44,
      "z": 4,
      "name": "Plant_Leaves_Azure",
      "rotation": 2
    },
    {
      "x": -17,
      "y": 45,
      "z": 4,
      "name": "Plant_Leaves_Azure",
      "rotation": 2
    },
    {
      "x": -17,
      "y": 46,
      "z": 4,
      "name": "Plant_Leaves_Azure",
      "rotation": 2
    },
    {
      "x": -17,
      "y": 20,
      "z": 5,
      "name": "Rock_Crystal_Blue_Small"
    },
    {
      "x": -17,
      "y": 21,
      "z": 5,
      "name": "Rock_Crystal_Blue_Block"
    },
    {
      "x": -17,
      "y": 22,
      "z": 5,
      "name": "Rock_Marble"
    },
    {
      "x": -17,
      "y": 23,
      "z": 5,
      "name": "Rock_Marble"
    },
    {
      "x": -17,
      "y": 24,
      "z": 5,
      "name": "Rock_Marble"
    },
    {
      "x": -17,
      "y": 25,
      "z": 5,
      "name": "Rock_Marble"
    },
    {
      "x": -17,
      "y": 26,
      "z": 5,
      "name": "Rock_Marble"
    },
    {
      "x": -17,
      "y": 27,
      "z": 5,
      "name": "Plant_Moss_Block_Blue"
    },
    {
      "x": -17,
      "y": 28,
      "z": 5,
      "name": "Plant_Moss_Block_Blue"
    },
    {
      "x": -17,
      "y": 29,
      "z": 5,
      "name": "Plant_Moss_Rug_Blue"
    },
    {
      "x": -17,
      "y": 38,
      "z": 5,
      "name": "Wood_Azure_Branch_Long",
      "rotation": 6
    },
    {
      "x": -17,
      "y": 44,
      "z": 5,
      "name": "Plant_Leaves_Azure",
      "rotation": 2
    },
    {
      "x": -17,
      "y": 45,
      "z": 5,
      "name": "Plant_Leaves_Azure",
      "rotation": 2
    },
    {
      "x": -17,
      "y": 46,
      "z": 5,
      "name": "Plant_Leaves_Azure",
      "rotation": 2
    },
    {
      "x": -17,
      "y": 19,
      "z": 6,
      "name": "Rock_Crystal_Blue_Block"
    },
    {
      "x": -17,
      "y": 20,
      "z": 6,
      "name": "Rock_Crystal_Blue_Block"
    },
    {
      "x": -17,
      "y": 21,
      "z": 6,
      "name": "Rock_Crystal_Blue_Block"
    },
    {
      "x": -17,
      "y": 22,
      "z": 6,
      "name": "Rock_Marble"
    },
    {
      "x": -17,
      "y": 23,
      "z": 6,
      "name": "Rock_Marble"
    },
    {
      "x": -17,
      "y": 24,
      "z": 6,
      "name": "Rock_Marble"
    },
    {
      "x": -17,
      "y": 25,
      "z": 6,
      "name": "Rock_Marble"
    },
    {
      "x": -17,
      "y": 26,
      "z": 6,
      "name": "Rock_Marble"
    },
    {
      "x": -17,
      "y": 27,
      "z": 6,
      "name": "Plant_Moss_Block_Blue"
    },
    {
      "x": -17,
      "y": 28,
      "z": 6,
      "name": "Plant_Moss_Block_Blue"
    },
    {
      "x": -17,
      "y": 29,
      "z": 6,
      "name": "Plant_Moss_Rug_Lime"
    },
    {
      "x": -17,
      "y": 37,
      "z": 6,
      "name": "Plant_Leaves_Azure",
      "rotation": 2
    },
    {
      "x": -17,
      "y": 38,
      "z": 6,
      "name": "Wood_Azure_Branch_Long",
      "rotation": 6
    },
    {
      "x": -17,
      "y": 39,
      "z": 6,
      "name": "Plant_Leaves_Azure",
      "rotation": 2
    },
    {
      "x": -17,
      "y": 40,
      "z": 6,
      "name": "Plant_Leaves_Azure",
      "rotation": 2
    },
    {
      "x": -17,
      "y": 20,
      "z": 7,
      "name": "Plant_Crop_Mushroom_Block_Blue_Mycelium"
    },
    {
      "x": -17,
      "y": 21,
      "z": 7,
      "name": "Rock_Crystal_Blue_Block"
    },
    {
      "x": -17,
      "y": 22,
      "z": 7,
      "name": "Rock_Marble"
    },
    {
      "x": -17,
      "y": 23,
      "z": 7,
      "name": "Rock_Marble"
    },
    {
      "x": -17,
      "y": 24,
      "z": 7,
      "name": "Rock_Marble"
    },
    {
      "x": -17,
      "y": 25,
      "z": 7,
      "name": "Rock_Marble"
    },
    {
      "x": -17,
      "y": 26,
      "z": 7,
      "name": "Rock_Marble"
    },
    {
      "x": -17,
      "y": 27,
      "z": 7,
      "name": "Plant_Moss_Block_Blue"
    },
    {
      "x": -17,
      "y": 28,
      "z": 7,
      "name": "Plant_Moss_Block_Blue"
    },
    {
      "x": -17,
      "y": 29,
      "z": 7,
      "name": "Plant_Moss_Rug_Blue"
    },
    {
      "x": -17,
      "y": 36,
      "z": 7,
      "name": "Plant_Leaves_Azure",
      "rotation": 2
    },
    {
      "x": -17,
      "y": 37,
      "z": 7,
      "name": "Plant_Leaves_Azure",
      "rotation": 2
    },
    {
      "x": -17,
      "y": 38,
      "z": 7,
      "name": "Plant_Leaves_Azure",
      "rotation": 2
    },
    {
      "x": -17,
      "y": 39,
      "z": 7,
      "name": "Plant_Leaves_Azure",
      "rotation": 2
    },
    {
      "x": -17,
      "y": 40,
      "z": 7,
      "name": "Plant_Leaves_Azure",
      "rotation": 2
    },
    {
      "x": -17,
      "y": 41,
      "z": 7,
      "name": "Plant_Fruit_Azure",
      "rotation": 2
    },
    {
      "x": -17,
      "y": 17,
      "z": 8,
      "name": "Rock_Crystal_Blue_Block"
    },
    {
      "x": -17,
      "y": 18,
      "z": 8,
      "name": "Rock_Crystal_Blue_Block"
    },
    {
      "x": -17,
      "y": 19,
      "z": 8,
      "name": "Rock_Crystal_Blue_Block"
    },
    {
      "x": -17,
      "y": 20,
      "z": 8,
      "name": "Rock_Marble"
    },
    {
      "x": -17,
      "y": 21,
      "z": 8,
      "name": "Rock_Marble"
    },
    {
      "x": -17,
      "y": 22,
      "z": 8,
      "name": "Rock_Marble"
    },
    {
      "x": -17,
      "y": 23,
      "z": 8,
      "name": "Rock_Marble"
    },
    {
      "x": -17,
      "y": 24,
      "z": 8,
      "name": "Rock_Marble"
    },
    {
      "x": -17,
      "y": 25,
      "z": 8,
      "name": "Rock_Marble"
    },
    {
      "x": -17,
      "y": 26,
      "z": 8,
      "name": "Rock_Marble"
    },
    {
      "x": -17,
      "y": 27,
      "z": 8,
      "name": "Plant_Moss_Block_Blue"
    },
    {
      "x": -17,
      "y": 28,
      "z": 8,
      "name": "Plant_Moss_Block_Blue"
    },
    {
      "x": -17,
      "y": 29,
      "z": 8,
      "name": "Plant_Moss_Rug_Blue"
    },
    {
      "x": -17,
      "y": 36,
      "z": 8,
      "name": "Plant_Leaves_Azure",
      "rotation": 2
    },
    {
      "x": -17,
      "y": 37,
      "z": 8,
      "name": "Plant_Leaves_Azure",
      "rotation": 2
    },
    {
      "x": -17,
      "y": 38,
      "z": 8,
      "name": "Plant_Leaves_Azure",
      "rotation": 2
    },
    {
      "x": -17,
      "y": 39,
      "z": 8,
      "name": "Plant_Leaves_Azure",
      "rotation": 2
    },
    {
      "x": -17,
      "y": 19,
      "z": 9,
      "name": "Plant_Crop_Mushroom_Block_Blue_Mycelium"
    },
    {
      "x": -17,
      "y": 20,
      "z": 9,
      "name": "Rock_Crystal_Blue_Block"
    },
    {
      "x": -17,
      "y": 21,
      "z": 9,
      "name": "Rock_Marble"
    },
    {
      "x": -17,
      "y": 22,
      "z": 9,
      "name": "Rock_Marble"
    },
    {
      "x": -17,
      "y": 23,
      "z": 9,
      "name": "Rock_Marble"
    },
    {
      "x": -17,
      "y": 24,
      "z": 9,
      "name": "Rock_Marble"
    },
    {
      "x": -17,
      "y": 25,
      "z": 9,
      "name": "Rock_Marble"
    },
    {
      "x": -17,
      "y": 26,
      "z": 9,
      "name": "Plant_Moss_Block_Blue"
    },
    {
      "x": -17,
      "y": 27,
      "z": 9,
      "name": "Plant_Moss_Block_Blue"
    },
    {
      "x": -17,
      "y": 28,
      "z": 9,
      "name": "Plant_Moss_Short_Green_Dark"
    },
    {
      "x": -17,
      "y": 20,
      "z": 10,
      "name": "Rock_Marble"
    },
    {
      "x": -17,
      "y": 21,
      "z": 10,
      "name": "Rock_Marble"
    },
    {
      "x": -17,
      "y": 22,
      "z": 10,
      "name": "Rock_Marble"
    },
    {
      "x": -17,
      "y": 23,
      "z": 10,
      "name": "Rock_Marble"
    },
    {
      "x": -17,
      "y": 24,
      "z": 10,
      "name": "Rock_Marble"
    },
    {
      "x": -17,
      "y": 25,
      "z": 10,
      "name": "Rock_Marble"
    },
    {
      "x": -17,
      "y": 26,
      "z": 10,
      "name": "Plant_Moss_Block_Blue"
    },
    {
      "x": -17,
      "y": 27,
      "z": 10,
      "name": "Plant_Moss_Block_Blue"
    },
    {
      "x": -17,
      "y": 28,
      "z": 10,
      "name": "Plant_Moss_Rug_Lime"
    },
    {
      "x": -17,
      "y": 22,
      "z": 11,
      "name": "Plant_Moss_Wall_Blue"
    },
    {
      "x": -17,
      "y": 23,
      "z": 11,
      "name": "Rock_Marble"
    },
    {
      "x": -17,
      "y": 24,
      "z": 11,
      "name": "Rock_Marble"
    },
    {
      "x": -17,
      "y": 25,
      "z": 11,
      "name": "Plant_Moss_Block_Blue"
    },
    {
      "x": -17,
      "y": 26,
      "z": 11,
      "name": "Plant_Moss_Block_Blue"
    },
    {
      "x": -17,
      "y": 27,
      "z": 11,
      "name": "Plant_Moss_Rug_Blue"
    },
    {
      "x": -17,
      "y": 23,
      "z": 12,
      "name": "Rock_Marble"
    },
    {
      "x": -17,
      "y": 24,
      "z": 12,
      "name": "Plant_Moss_Block_Blue"
    },
    {
      "x": -17,
      "y": 25,
      "z": 12,
      "name": "Plant_Moss_Block_Blue"
    },
    {
      "x": -17,
      "y": 26,
      "z": 12,
      "name": "Plant_Moss_Short_Green_Dark"
    },
    {
      "x": -17,
      "y": 25,
      "z": 13,
      "name": "Plant_Moss_Rug_Blue"
    },
    {
      "x": -17,
      "y": 24,
      "z": 14,
      "name": "Plant_Moss_Block_Blue"
    },
    {
      "x": -17,
      "y": 25,
      "z": 14,
      "name": "Plant_Moss_Rug_Blue"
    },
    {
      "x": -16,
      "y": 27,
      "z": -13,
      "name": "Plant_Moss_Wall_Blue",
      "rotation": 2
    },
    {
      "x": -16,
      "y": 29,
      "z": -13,
      "name": "Plant_Moss_Block_Blue"
    },
    {
      "x": -16,
      "y": 30,
      "z": -13,
      "name": "Plant_Moss_Rug_Blue"
    },
    {
      "x": -16,
      "y": 27,
      "z": -12,
      "name": "Rock_Marble"
    },
    {
      "x": -16,
      "y": 28,
      "z": -12,
      "name": "Rock_Marble"
    },
    {
      "x": -16,
      "y": 29,
      "z": -12,
      "name": "Plant_Moss_Block_Blue"
    },
    {
      "x": -16,
      "y": 30,
      "z": -12,
      "name": "Plant_Moss_Block_Blue"
    },
    {
      "x": -16,
      "y": 31,
      "z": -12,
      "name": "Plant_Moss_Short_Green_Dark"
    },
    {
      "x": -16,
      "y": 26,
      "z": -11,
      "name": "Rock_Marble"
    },
    {
      "x": -16,
      "y": 27,
      "z": -11,
      "name": "Rock_Marble"
    },
    {
      "x": -16,
      "y": 28,
      "z": -11,
      "name": "Rock_Marble"
    },
    {
      "x": -16,
      "y": 29,
      "z": -11,
      "name": "Rock_Marble"
    },
    {
      "x": -16,
      "y": 30,
      "z": -11,
      "name": "Plant_Moss_Block_Blue"
    },
    {
      "x": -16,
      "y": 31,
      "z": -11,
      "name": "Plant_Moss_Block_Blue"
    },
    {
      "x": -16,
      "y": 32,
      "z": -11,
      "name": "Plant_Moss_Short_Green_Dark"
    },
    {
      "x": -16,
      "y": 27,
      "z": -10,
      "name": "Rock_Crystal_Blue_Block"
    },
    {
      "x": -16,
      "y": 28,
      "z": -10,
      "name": "Rock_Marble"
    },
    {
      "x": -16,
      "y": 29,
      "z": -10,
      "name": "Rock_Marble"
    },
    {
      "x": -16,
      "y": 30,
      "z": -10,
      "name": "Plant_Moss_Block_Blue"
    },
    {
      "x": -16,
      "y": 31,
      "z": -10,
      "name": "Plant_Moss_Block_Blue"
    },
    {
      "x": -16,
      "y": 32,
      "z": -10,
      "name": "Plant_Moss_Blue"
    },
    {
      "x": -16,
      "y": 26,
      "z": -9,
      "name": "Rock_Crystal_Blue_Block"
    },
    {
      "x": -16,
      "y": 27,
      "z": -9,
      "name": "Rock_Marble"
    },
    {
      "x": -16,
      "y": 28,
      "z": -9,
      "name": "Rock_Marble"
    },
    {
      "x": -16,
      "y": 29,
      "z": -9,
      "name": "Rock_Marble"
    },
    {
      "x": -16,
      "y": 30,
      "z": -9,
