{
  "version": 8,
  "blockIdVersion": 11,
  "anchorX": 0,
  "anchorY": 0,
  "anchorZ": 0,
  "blocks": [
    {
      "x": -12,
      "y": 29,
      "z": -3,
      "name": "Plant_Leaves_Azure",
      "rotation": 1
    },
    {
      "x": -12,
      "y": 30,
      "z": -3,
      "name": "Plant_Leaves_Azure",
      "rotation": 1
    },
    {
      "x": -12,
      "y": 31,
      "z": -3,
      "name": "Plant_Leaves_Azure",
      "rotation": 1
    },
    {
      "x": -12,
      "y": 29,
      "z": -2,
      "name": "Plant_Leaves_Azure",
      "rotation": 1
    },
    {
      "x": -12,
      "y": 30,
      "z": -2,
      "name": "Plant_Leaves_Azure",
      "rotation": 1
    },
    {
      "x": -12,
      "y": 31,
      "z": -2,
      "name": "Plant_Leaves_Azure",
      "rotation": 1
    },
    {
      "x": -12,
      "y": 32,
      "z": -2,
      "name": "Plant_Leaves_Azure",
      "rotation": 1
    },
    {
      "x": -12,
      "y": 29,
      "z": -1,
      "name": "Plant_Leaves_Azure",
      "rotation": 1
    },
    {
      "x": -12,
      "y": 30,
      "z": -1,
      "name": "Plant_Leaves_Azure",
      "rotation": 1
    },
    {
      "x": -12,
      "y": 31,
      "z": -1,
      "name": "Plant_Leaves_Azure",
      "rotation": 1
    },
    {
      "x": -12,
      "y": 32,
      "z": -1,
      "name": "Plant_Leaves_Azure",
      "rotation": 1
    },
    {
      "x": -12,
      "y": 30,
      "z": 0,
      "name": "Plant_Leaves_Azure",
      "rotation": 1
    },
    {
      "x": -12,
      "y": 31,
      "z": 0,
      "name": "Plant_Leaves_Azure",
      "rotation": 1
    },
    {
      "x": -12,
      "y": 32,
      "z": 0,
      "name": "Plant_Leaves_Azure",
      "rotation": 1
    },
    {
      "x": -12,
      "y": 33,
      "z": 0,
      "name": "Plant_Leaves_Azure",
      "rotation": 1
    },
    {
      "x": -12,
      "y": 31,
      "z": 1,
      "name": "Plant_Leaves_Azure",
      "rotation": 1
    },
    {
      "x": -12,
      "y": 32,
      "z": 1,
      "name": "Plant_Leaves_Azure",
      "rotation": 1
    },
    {
      "x": -12,
      "y": 33,
      "z": 1,
      "name": "Plant_Leaves_Azure",
      "rotation": 1
    },
    {
      "x": -11,
      "y": 28,
      "z": -4,
      "name": "Plant_Leaves_Azure",
      "rotation": 1
    },
    {
      "x": -11,
      "y": 29,
      "z": -4,
      "name": "Plant_Leaves_Azure",
      "rotation": 1
    },
    {
      "x": -11,
      "y": 30,
      "z": -4,
      "name": "Plant_Leaves_Azure",
      "rotation": 1
    },
    {
      "x": -11,
      "y": 31,
      "z": -4,
      "name": "Plant_Leaves_Azure",
      "rotation": 1
    },
    {
      "x": -11,
      "y": 28,
      "z": -3,
      "name": "Plant_Leaves_Azure",
      "rotation": 1
    },
    {
      "x": -11,
      "y": 29,
      "z": -3,
      "name": "Plant_Leaves_Azure",
      "rotation": 1
    },
    {
      "x": -11,
      "y": 30,
      "z": -3,
      "name": "Plant_Leaves_Azure",
      "rotation": 1
    },
    {
      "x": -11,
      "y": 31,
      "z": -3,
      "name": "Plant_Leaves_Azure",
      "rotation": 1
    },
    {
      "x": -11,
      "y": 32,
      "z": -3,
      "name": "Plant_Leaves_Azure",
      "rotation": 1
    },
    {
      "x": -11,
      "y": 28,
      "z": -2,
      "name": "Plant_Leaves_Azure",
      "rotation": 1
    },
    {
      "x": -11,
      "y": 29,
      "z": -2,
      "name": "Plant_Leaves_Azure",
      "rotation": 1
    },
    {
      "x": -11,
      "y": 30,
      "z": -2,
      "name": "Plant_Leaves_Azure",
      "rotation": 1
    },
    {
      "x": -11,
      "y": 31,
      "z": -2,
      "name": "Plant_Leaves_Azure",
      "rotation": 1
    },
    {
      "x": -11,
      "y": 32,
      "z": -2,
      "name": "Plant_Leaves_Azure",
      "rotation": 1
    },
    {
      "x": -11,
      "y": 33,
      "z": -2,
      "name": "Plant_Leaves_Azure",
      "rotation": 1
    },
    {
      "x": -11,
      "y": 29,
      "z": -1,
      "name": "Plant_Leaves_Azure",
      "rotation": 1
    },
    {
      "x": -11,
      "y": 30,
      "z": -1,
      "name": "Plant_Leaves_Azure",
      "rotation": 1
    },
    {
      "x": -11,
      "y": 31,
      "z": -1,
      "name": "Plant_Leaves_Azure",
      "rotation": 1
    },
    {
      "x": -11,
      "y": 32,
      "z": -1,
      "name": "Plant_Leaves_Azure",
      "rotation": 1
    },
    {
      "x": -11,
      "y": 33,
      "z": -1,
      "name": "Plant_Leaves_Azure",
      "rotation": 1
    },
    {
      "x": -11,
      "y": 34,
      "z": -1,
      "name": "Plant_Fruit_Azure",
      "rotation": 1
    },
    {
      "x": -11,
      "y": 29,
      "z": 0,
      "name": "Plant_Leaves_Azure",
      "rotation": 1
    },
    {
      "x": -11,
      "y": 30,
      "z": 0,
      "name": "Plant_Leaves_Azure",
      "rotation": 1
    },
    {
      "x": -11,
      "y": 31,
      "z": 0,
      "name": "Plant_Leaves_Azure",
      "rotation": 1
    },
    {
      "x": -11,
      "y": 32,
      "z": 0,
      "name": "Plant_Leaves_Azure",
      "rotation": 1
    },
    {
      "x": -11,
      "y": 33,
      "z": 0,
      "name": "Plant_Leaves_Azure",
      "rotation": 1
    },
    {
      "x": -11,
      "y": 34,
      "z": 0,
      "name": "Plant_Leaves_Azure",
      "rotation": 1
    },
    {
      "x": -11,
      "y": 30,
      "z": 1,
      "name": "Plant_Leaves_Azure",
      "rotation": 1
    },
    {
      "x": -11,
      "y": 31,
      "z": 1,
      "name": "Plant_Leaves_Azure",
      "rotation": 1
    },
    {
      "x": -11,
      "y": 32,
      "z": 1,
      "name": "Plant_Leaves_Azure",
      "rotation": 1
    },
    {
      "x": -11,
      "y": 33,
      "z": 1,
      "name": "Plant_Leaves_Azure",
      "rotation": 1
    },
    {
      "x": -11,
      "y": 34,
      "z": 1,
      "name": "Plant_Leaves_Azure",
      "rotation": 1
    },
    {
      "x": -11,
      "y": 31,
      "z": 2,
      "name": "Plant_Leaves_Azure",
      "rotation": 1
    },
    {
      "x": -11,
      "y": 32,
      "z": 2,
      "name": "Plant_Leaves_Azure",
      "rotation": 1
    },
    {
      "x": -11,
      "y": 33,
      "z": 2,
      "name": "Plant_Leaves_Azure",
      "rotation": 1
    },
    {
      "x": -11,
      "y": 34,
      "z": 2,
      "name": "Plant_Leaves_Azure",
      "rotation": 1
    },
    {
      "x": -10,
      "y": 28,
      "z": -5,
      "name": "Plant_Leaves_Azure",
      "rotation": 1
    },
    {
      "x": -10,
      "y": 29,
      "z": -5,
      "name": "Plant_Leaves_Azure",
      "rotation": 1
    },
    {
      "x": -10,
      "y": 30,
      "z": -5,
      "name": "Plant_Leaves_Azure",
      "rotation": 1
    },
    {
      "x": -10,
      "y": 27,
      "z": -4,
      "name": "Plant_Leaves_Azure",
      "rotation": 1
    },
    {
      "x": -10,
      "y": 28,
      "z": -4,
      "name": "Plant_Leaves_Azure",
      "rotation": 1
    },
    {
      "x": -10,
      "y": 29,
      "z": -4,
      "name": "Plant_Leaves_Azure",
      "rotation": 1
    },
    {
      "x": -10,
      "y": 30,
      "z": -4,
      "name": "Plant_Leaves_Azure",
      "rotation": 1
    },
    {
      "x": -10,
      "y": 31,
      "z": -4,
      "name": "Plant_Leaves_Azure",
      "rotation": 1
    },
    {
      "x": -10,
      "y": 32,
      "z": -4,
      "name": "Plant_Leaves_Azure",
      "rotation": 1
    },
    {
      "x": -10,
      "y": 27,
      "z": -3,
      "name": "Plant_Leaves_Azure",
      "rotation": 1
    },
    {
      "x": -10,
      "y": 28,
      "z": -3,
      "name": "Plant_Leaves_Azure",
      "rotation": 1
    },
    {
      "x": -10,
      "y": 29,
      "z": -3,
      "name": "Plant_Leaves_Azure",
      "rotation": 1
    },
    {
      "x": -10,
      "y": 30,
      "z": -3,
      "name": "Plant_Leaves_Azure",
      "rotation": 1
    },
    {
      "x": -10,
      "y": 31,
      "z": -3,
      "name": "Plant_Leaves_Azure",
      "rotation": 1
    },
    {
      "x": -10,
      "y": 32,
      "z": -3,
      "name": "Plant_Leaves_Azure",
      "rotation": 1
    },
    {
      "x": -10,
      "y": 33,
      "z": -3,
      "name": "Plant_Fruit_Azure",
      "rotation": 1
    },
    {
      "x": -10,
      "y": 28,
      "z": -2,
      "name": "Plant_Leaves_Azure",
      "rotation": 1
    },
    {
      "x": -10,
      "y": 29,
      "z": -2,
      "name": "Plant_Leaves_Azure",
      "rotation": 1
    },
    {
      "x": -10,
      "y": 30,
      "z": -2,
      "name": "Plant_Leaves_Azure",
      "rotation": 1
    },
    {
      "x": -10,
      "y": 31,
      "z": -2,
      "name": "Plant_Leaves_Azure",
      "rotation": 1
    },
    {
      "x": -10,
      "y": 32,
      "z": -2,
      "name": "Plant_Leaves_Azure",
      "rotation": 1
    },
    {
      "x": -10,
      "y": 33,
      "z": -2,
      "name": "Plant_Fruit_Azure",
      "rotation": 1
    },
    {
      "x": -10,
      "y": 28,
      "z": -1,
      "name": "Plant_Leaves_Azure",
      "rotation": 1
    },
    {
      "x": -10,
      "y": 29,
      "z": -1,
      "name": "Plant_Leaves_Azure",
      "rotation": 1
    },
    {
      "x": -10,
      "y": 30,
      "z": -1,
      "name": "Plant_Leaves_Azure",
      "rotation": 1
    },
    {
      "x": -10,
      "y": 31,
      "z": -1,
      "name": "Wood_Azure_Branch_Long",
      "rotation": 5
    },
    {
      "x": -10,
      "y": 32,
      "z": -1,
      "name": "Plant_Leaves_Azure",
      "rotation": 1
    },
    {
      "x": -10,
      "y": 33,
      "z": -1,
      "name": "Plant_Leaves_Azure",
      "rotation": 1
    },
    {
      "x": -10,
      "y": 29,
      "z": 0,
      "name": "Plant_Leaves_Azure",
      "rotation": 1
    },
    {
      "x": -10,
      "y": 30,
      "z": 0,
      "name": "Plant_Leaves_Azure",
      "rotation": 1
    },
    {
      "x": -10,
      "y": 31,
      "z": 0,
      "name": "Plant_Leaves_Azure",
      "rotation": 1
    },
    {
      "x": -10,
      "y": 32,
      "z": 0,
      "name": "Plant_Leaves_Azure",
      "rotation": 1
    },
    {
      "x": -10,
      "y": 33,
      "z": 0,
      "name": "Wood_Azure_Branch_Long",
      "rotation": 5
    },
    {
      "x": -10,
      "y": 34,
      "z": 0,
      "name": "Plant_Leaves_Azure",
      "rotation": 1
    },
    {
      "x": -10,
      "y": 30,
      "z": 1,
      "name": "Plant_Leaves_Azure",
      "rotation": 1
    },
    {
      "x": -10,
      "y": 31,
      "z": 1,
      "name": "Plant_Leaves_Azure",
      "rotation": 1
    },
    {
      "x": -10,
      "y": 32,
      "z": 1,
      "name": "Plant_Leaves_Azure",
      "rotation": 1
    },
    {
      "x": -10,
      "y": 33,
      "z": 1,
      "name": "Plant_Leaves_Azure",
      "rotation": 1
    },
    {
      "x": -10,
      "y": 34,
      "z": 1,
      "name": "Plant_Leaves_Azure",
      "rotation": 1
    },
    {
      "x": -10,
      "y": 35,
      "z": 1,
      "name": "Plant_Leaves_Azure",
      "rotation": 1
    },
    {
      "x": -10,
      "y": 31,
      "z": 2,
      "name": "Plant_Leaves_Azure",
      "rotation": 1
    },
    {
      "x": -10,
      "y": 32,
      "z": 2,
      "name": "Plant_Leaves_Azure",
      "rotation": 1
    },
    {
      "x": -10,
      "y": 33,
      "z": 2,
      "name": "Plant_Leaves_Azure",
      "rotation": 1
    },
    {
      "x": -10,
      "y": 34,
      "z": 2,
      "name": "Plant_Leaves_Azure",
      "rotation": 1
    },
    {
      "x": -10,
      "y": 35,
      "z": 2,
      "name": "Plant_Leaves_Azure",
      "rotation": 1
    },
    {
      "x": -10,
      "y": 32,
      "z": 3,
      "name": "Plant_Leaves_Azure",
      "rotation": 1
    },
    {
      "x": -10,
      "y": 33,
      "z": 3,
      "name": "Plant_Leaves_Azure",
      "rotation": 1
    },
    {
      "x": -10,
      "y": 34,
      "z": 3,
      "name": "Plant_Leaves_Azure",
      "rotation": 1
    },
    {
      "x": -9,
      "y": 27,
      "z": -6,
      "name": "Plant_Leaves_Azure",
      "rotation": 1
    },
    {
      "x": -9,
      "y": 28,
      "z": -6,
      "name": "Plant_Leaves_Azure",
      "rotation": 1
    },
    {
      "x": -9,
      "y": 29,
      "z": -6,
      "name": "Plant_Leaves_Azure",
      "rotation": 1
    },
    {
      "x": -9,
      "y": 27,
      "z": -5,
      "name": "Plant_Leaves_Azure",
      "rotation": 1
    },
    {
      "x": -9,
      "y": 28,
      "z": -5,
      "name": "Plant_Leaves_Azure",
      "rotation": 1
    },
    {
      "x": -9,
      "y": 29,
      "z": -5,
      "name": "Plant_Leaves_Azure",
      "rotation": 1
    },
    {
      "x": -9,
      "y": 30,
      "z": -5,
      "name": "Plant_Leaves_Azure",
      "rotation": 1
    },
    {
      "x": -9,
      "y": 31,
      "z": -5,
      "name": "Plant_Leaves_Azure",
      "rotation": 1
    },
    {
      "x": -9,
      "y": 28,
      "z": -4,
      "name": "Plant_Leaves_Azure",
      "rotation": 1
    },
    {
      "x": -9,
      "y": 29,
      "z": -4,
      "name": "Plant_Leaves_Azure",
      "rotation": 1
    },
    {
      "x": -9,
      "y": 30,
      "z": -4,
      "name": "Plant_Leaves_Azure",
      "rotation": 1
    },
    {
      "x": -9,
      "y": 31,
      "z": -4,
      "name": "Plant_Leaves_Azure",
      "rotation": 1
    },
    {
      "x": -9,
      "y": 32,
      "z": -4,
      "name": "Plant_Fruit_Azure",
      "rotation": 1
    },
    {
      "x": -9,
      "y": 29,
      "z": -3,
      "name": "Plant_Leaves_Azure",
      "rotation": 1
    },
    {
      "x": -9,
      "y": 30,
      "z": -3,
      "name": "Plant_Leaves_Azure",
      "rotation": 1
    },
    {
      "x": -9,
      "y": 31,
      "z": -3,
      "name": "Plant_Leaves_Azure",
      "rotation": 1
    },
    {
      "x": -9,
      "y": 32,
      "z": -3,
      "name": "Plant_Leaves_Azure",
      "rotation": 1
    },
    {
      "x": -9,
      "y": 35,
      "z": -3,
      "name": "Plant_Leaves_Azure",
      "rotation": 1
    },
    {
      "x": -9,
      "y": 36,
      "z": -3,
      "name": "Plant_Leaves_Azure",
      "rotation": 1
    },
    {
      "x": -9,
      "y": 37,
      "z": -3,
      "name": "Plant_Leaves_Azure",
      "rotation": 1
    },
    {
      "x": -9,
      "y": 29,
      "z": -2,
      "name": "Plant_Leaves_Azure",
      "rotation": 1
    },
    {
      "x": -9,
      "y": 30,
      "z": -2,
      "name": "Wood_Azure_Branch_Long",
      "rotation": 5
    },
    {
      "x": -9,
      "y": 31,
      "z": -2,
      "name": "Plant_Leaves_Azure",
      "rotation": 1
    },
    {
      "x": -9,
      "y": 32,
      "z": -2,
      "name": "Plant_Leaves_Azure",
      "rotation": 1
    },
    {
      "x": -9,
      "y": 36,
      "z": -2,
      "name": "Plant_Leaves_Azure",
      "rotation": 1
    },
    {
      "x": -9,
      "y": 37,
      "z": -2,
      "name": "Plant_Leaves_Azure",
      "rotation": 1
    },
    {
      "x": -9,
      "y": 38,
      "z": -2,
      "name": "Plant_Leaves_Azure",
      "rotation": 1
    },
    {
      "x": -9,
      "y": 30,
      "z": -1,
      "name": "Plant_Leaves_Azure",
      "rotation": 1
    },
    {
      "x": -9,
      "y": 31,
      "z": -1,
      "name": "Wood_Azure_Branch_Long",
      "rotation": 5
    },
    {
      "x": -9,
      "y": 32,
      "z": -1,
      "name": "Wood_Azure_Branch_Long",
      "rotation": 5
    },
    {
      "x": -9,
      "y": 33,
      "z": -1,
      "name": "Plant_Leaves_Azure",
      "rotation": 1
    },
    {
      "x": -9,
      "y": 37,
      "z": -1,
      "name": "Plant_Leaves_Azure",
      "rotation": 1
    },
    {
      "x": -9,
      "y": 38,
      "z": -1,
      "name": "Plant_Leaves_Azure",
      "rotation": 1
    },
    {
      "x": -9,
      "y": 39,
      "z": -1,
      "name": "Plant_Leaves_Azure",
      "rotation": 1
    },
    {
      "x": -9,
      "y": 30,
      "z": 0,
      "name": "Plant_Leaves_Azure",
      "rotation": 1
    },
    {
      "x": -9,
      "y": 31,
      "z": 0,
      "name": "Plant_Leaves_Azure",
      "rotation": 1
    },
    {
      "x": -9,
      "y": 32,
      "z": 0,
      "name": "Plant_Leaves_Azure",
      "rotation": 1
    },
    {
      "x": -9,
      "y": 33,
      "z": 0,
      "name": "Wood_Azure_Branch_Long",
      "rotation": 5
    },
    {
      "x": -9,
      "y": 34,
      "z": 0,
      "name": "Plant_Leaves_Azure",
      "rotation": 1
    },
    {
      "x": -9,
      "y": 38,
      "z": 0,
      "name": "Plant_Leaves_Azure",
      "rotation": 1
    },
    {
      "x": -9,
      "y": 30,
      "z": 1,
      "name": "Plant_Leaves_Azure",
      "rotation": 1
    },
    {
      "x": -9,
      "y": 31,
      "z": 1,
      "name": "Plant_Leaves_Azure",
      "rotation": 1
    },
    {
      "x": -9,
      "y": 32,
      "z": 1,
      "name": "Plant_Leaves_Azure",
      "rotation": 1
    },
    {
      "x": -9,
      "y": 33,
      "z": 1,
      "name": "Plant_Leaves_Azure",
      "rotation": 1
    },
    {
      "x": -9,
      "y": 34,
      "z": 1,
      "name": "Plant_Leaves_Azure",
      "rotation": 1
    },
    {
      "x": -9,
      "y": 35,
      "z": 1,
      "name": "Plant_Leaves_Azure",
      "rotation": 1
    },
    {
      "x": -9,
      "y": 31,
      "z": 2,
      "name": "Plant_Leaves_Azure",
      "rotation": 1
    },
    {
      "x": -9,
      "y": 32,
      "z": 2,
      "name": "Plant_Leaves_Azure",
      "rotation": 1
    },
    {
      "x": -9,
      "y": 33,
      "z": 2,
      "name": "Plant_Leaves_Azure",
      "rotation": 1
    },
    {
      "x": -9,
      "y": 34,
      "z": 2,
      "name": "Plant_Leaves_Azure",
      "rotation": 1
    },
    {
      "x": -9,
      "y": 35,
      "z": 2,
      "name": "Plant_Leaves_Azure",
      "rotation": 1
    },
    {
      "x": -9,
      "y": 36,
      "z": 2,
      "name": "Plant_Leaves_Azure",
      "rotation": 1
    },
    {
      "x": -9,
      "y": 32,
      "z": 3,
      "name": "Plant_Leaves_Azure",
      "rotation": 1
    },
    {
      "x": -9,
      "y": 33,
      "z": 3,
      "name": "Plant_Leaves_Azure",
      "rotation": 1
    },
    {
      "x": -9,
      "y": 34,
      "z": 3,
      "name": "Plant_Leaves_Azure",
      "rotation": 1
    },
    {
      "x": -9,
      "y": 35,
      "z": 3,
      "name": "Plant_Leaves_Azure",
      "rotation": 1
    },
    {
      "x": -9,
      "y": 36,
      "z": 3,
      "name": "Plant_Leaves_Azure",
      "rotation": 1
    },
    {
      "x": -9,
      "y": 33,
      "z": 4,
      "name": "Plant_Leaves_Azure",
      "rotation": 1
    },
    {
      "x": -9,
      "y": 34,
      "z": 4,
      "name": "Plant_Leaves_Azure",
      "rotation": 1
    },
    {
      "x": -9,
      "y": 35,
      "z": 4,
      "name": "Plant_Leaves_Azure",
      "rotation": 1
    },
    {
      "x": -8,
      "y": 27,
      "z": -6,
      "name": "Plant_Leaves_Azure",
      "rotation": 1
    },
    {
      "x": -8,
      "y": 28,
      "z": -6,
      "name": "Plant_Leaves_Azure",
      "rotation": 1
    },
    {
      "x": -8,
      "y": 29,
      "z": -6,
      "name": "Plant_Leaves_Azure",
      "rotation": 1
    },
    {
      "x": -8,
      "y": 30,
      "z": -6,
      "name": "Plant_Leaves_Azure",
      "rotation": 1
    },
    {
      "x": -8,
      "y": 27,
      "z": -5,
      "name": "Plant_Leaves_Azure",
      "rotation": 1
    },
    {
      "x": -8,
      "y": 28,
      "z": -5,
      "name": "Plant_Leaves_Azure",
      "rotation": 1
    },
    {
      "x": -8,
      "y": 29,
      "z": -5,
      "name": "Plant_Leaves_Azure",
      "rotation": 1
    },
    {
      "x": -8,
      "y": 30,
      "z": -5,
      "name": "Plant_Leaves_Azure",
      "rotation": 1
    },
    {
      "x": -8,
      "y": 31,
      "z": -5,
      "name": "Plant_Leaves_Azure",
      "rotation": 1
    },
    {
      "x": -8,
      "y": 28,
      "z": -4,
      "name": "Plant_Leaves_Azure",
      "rotation": 1
    },
    {
      "x": -8,
      "y": 29,
      "z": -4,
      "name": "Plant_Leaves_Azure",
      "rotation": 1
    },
    {
      "x": -8,
      "y": 30,
      "z": -4,
      "name": "Plant_Leaves_Azure",
      "rotation": 1
    },
    {
      "x": -8,
      "y": 31,
      "z": -4,
      "name": "Plant_Leaves_Azure",
      "rotation": 1
    },
    {
      "x": -8,
      "y": 34,
      "z": -4,
      "name": "Plant_Leaves_Azure",
      "rotation": 1
    },
    {
      "x": -8,
      "y": 35,
      "z": -4,
      "name": "Plant_Leaves_Azure",
      "rotation": 1
    },
    {
      "x": -8,
      "y": 36,
      "z": -4,
      "name": "Plant_Leaves_Azure",
      "rotation": 1
    },
    {
      "x": -8,
      "y": 30,
      "z": -3,
      "name": "Plant_Leaves_Azure",
      "rotation": 1
    },
    {
      "x": -8,
      "y": 31,
      "z": -3,
      "name": "Plant_Leaves_Azure",
      "rotation": 1
    },
    {
      "x": -8,
      "y": 34,
      "z": -3,
      "name": "Plant_Leaves_Azure",
      "rotation": 1
    },
    {
      "x": -8,
      "y": 35,
      "z": -3,
      "name": "Plant_Leaves_Azure",
      "rotation": 1
    },
    {
      "x": -8,
      "y": 36,
      "z": -3,
      "name": "Plant_Leaves_Azure",
      "rotation": 1
    },
    {
      "x": -8,
      "y": 37,
      "z": -3,
      "name": "Plant_Leaves_Azure",
      "rotation": 1
    },
    {
      "x": -8,
      "y": 30,
      "z": -2,
      "name": "Wood_Azure_Branch_Long",
      "rotation": 5
    },
    {
      "x": -8,
      "y": 35,
      "z": -2,
      "name": "Plant_Leaves_Azure",
      "rotation": 1
    },
    {
      "x": -8,
      "y": 36,
      "z": -2,
      "name": "Plant_Leaves_Azure",
      "rotation": 1
    },
    {
      "x": -8,
      "y": 37,
      "z": -2,
      "name": "Plant_Leaves_Azure",
      "rotation": 1
    },
    {
      "x": -8,
      "y": 38,
      "z": -2,
      "name": "Plant_Fruit_Azure",
      "rotation": 1
    },
    {
      "x": -8,
      "y": 31,
      "z": -1,
      "name": "Wood_Azure_Branch_Long",
      "rotation": 5
    },
    {
      "x": -8,
      "y": 32,
      "z": -1,
      "name": "Wood_Azure_Branch_Long",
      "rotation": 5
    },
    {
      "x": -8,
      "y": 36,
      "z": -1,
      "name": "Plant_Leaves_Azure",
      "rotation": 1
    },
    {
      "x": -8,
      "y": 37,
      "z": -1,
      "name": "Plant_Leaves_Azure",
      "rotation": 1
    },
    {
      "x": -8,
      "y": 38,
      "z": -1,
      "name": "Plant_Leaves_Azure",
      "rotation": 1
    },
    {
      "x": -8,
      "y": 39,
      "z": -1,
      "name": "Plant_Leaves_Azure",
      "rotation": 1
    },
    {
      "x": -8,
      "y": 22,
      "z": 0,
      "name": "Wood_Azure_Trunk_Full",
      "rotation": 1
    },
    {
      "x": -8,
      "y": 23,
      "z": 0,
      "name": "Wood_Azure_Trunk_Full",
      "rotation": 1
    },
    {
      "x": -8,
      "y": 33,
      "z": 0,
      "name": "Wood_Azure_Branch_Long",
      "rotation": 5
    },
    {
      "x": -8,
      "y": 34,
      "z": 0,
      "name": "Plant_Leaves_Azure",
      "rotation": 1
    },
    {
      "x": -8,
      "y": 38,
      "z": 0,
      "name": "Plant_Leaves_Azure",
      "rotation": 1
    },
    {
      "x": -8,
      "y": 39,
      "z": 0,
      "name": "Plant_Leaves_Azure",
      "rotation": 1
    },
    {
      "x": -8,
      "y": 40,
      "z": 0,
      "name": "Plant_Leaves_Azure",
      "rotation": 1
    },
    {
      "x": -8,
      "y": 20,
      "z": 1,
      "name": "Wood_Azure_Roots",
      "rotation": 1
    },
    {
      "x": -8,
      "y": 21,
      "z": 1,
      "name": "Wood_Azure_Trunk_Full",
      "rotation": 1
    },
    {
      "x": -8,
      "y": 22,
      "z": 1,
      "name": "Wood_Azure_Trunk_Full",
      "rotation": 1
    },
    {
      "x": -8,
      "y": 31,
      "z": 1,
      "name": "Plant_Leaves_Azure",
      "rotation": 1
    },
    {
      "x": -8,
      "y": 32,
      "z": 1,
      "name": "Plant_Leaves_Azure",
      "rotation": 1
    },
    {
      "x": -8,
      "y": 33,
      "z": 1,
      "name": "Plant_Leaves_Azure",
      "rotation": 1
    },
    {
      "x": -8,
      "y": 34,
      "z": 1,
      "name": "Plant_Leaves_Azure",
      "rotation": 1
    },
    {
      "x": -8,
      "y": 35,
      "z": 1,
      "name": "Plant_Leaves_Azure",
      "rotation": 1
    },
    {
      "x": -8,
      "y": 31,
      "z": 2,
      "name": "Plant_Leaves_Azure",
      "rotation": 1
    },
    {
      "x": -8,
      "y": 32,
      "z": 2,
      "name": "Plant_Leaves_Azure",
      "rotation": 1
    },
    {
      "x": -8,
      "y": 33,
      "z": 2,
      "name": "Plant_Leaves_Azure",
      "rotation": 1
    },
    {
      "x": -8,
      "y": 34,
      "z": 2,
      "name": "Plant_Leaves_Azure",
      "rotation": 1
    },
    {
      "x": -8,
      "y": 35,
      "z": 2,
      "name": "Plant_Leaves_Azure",
      "rotation": 1
    },
    {
      "x": -8,
      "y": 36,
      "z": 2,
      "name": "Plant_Leaves_Azure",
      "rotation": 1
    },
    {
      "x": -8,
      "y": 37,
      "z": 2,
      "name": "Plant_Fruit_Azure",
      "rotation": 1
    },
    {
      "x": -8,
      "y": 32,
      "z": 3,
      "name": "Plant_Leaves_Azure",
      "rotation": 1
    },
    {
      "x": -8,
      "y": 33,
      "z": 3,
      "name": "Plant_Leaves_Azure",
      "rotation": 1
    },
    {
      "x": -8,
      "y": 34,
      "z": 3,
      "name": "Plant_Leaves_Azure",
      "rotation": 1
    },
    {
      "x": -8,
      "y": 35,
      "z": 3,
      "name": "Plant_Leaves_Azure",
      "rotation": 1
    },
    {
      "x": -8,
      "y": 36,
      "z": 3,
      "name": "Plant_Leaves_Azure",
      "rotation": 1
    },
    {
      "x": -8,
      "y": 37,
      "z": 3,
      "name": "Plant_Leaves_Azure",
      "rotation": 1
    },
    {
      "x": -8,
      "y": 33,
      "z": 4,
      "name": "Plant_Leaves_Azure",
      "rotation": 1
    },
    {
      "x": -8,
      "y": 34,
      "z": 4,
      "name": "Plant_Leaves_Azure",
      "rotation": 1
    },
    {
      "x": -8,
      "y": 35,
      "z": 4,
      "name": "Plant_Leaves_Azure",
      "rotation": 1
    },
    {
      "x": -8,
      "y": 36,
      "z": 4,
      "name": "Plant_Leaves_Azure",
      "rotation": 1
    },
    {
      "x": -7,
      "y": 26,
      "z": -7,
      "name": "Plant_Leaves_Azure",
      "rotation": 1
    },
    {
      "x": -7,
      "y": 27,
      "z": -7,
      "name": "Plant_Leaves_Azure",
      "rotation": 1
    },
    {
      "x": -7,
      "y": 28,
      "z": -7,
      "name": "Plant_Leaves_Azure",
      "rotation": 1
    },
    {
      "x": -7,
      "y": 27,
      "z": -6,
      "name": "Plant_Leaves_Azure",
      "rotation": 1
    },
    {
      "x": -7,
      "y": 28,
      "z": -6,
      "name": "Plant_Leaves_Azure",
      "rotation": 1
    },
    {
      "x": -7,
      "y": 29,
      "z": -6,
      "name": "Plant_Leaves_Azure",
      "rotation": 1
    },
    {
      "x": -7,
      "y": 30,
      "z": -6,
      "name": "Plant_Leaves_Azure",
      "rotation": 1
    },
    {
      "x": -7,
      "y": 27,
      "z": -5,
      "name": "Plant_Leaves_Azure",
      "rotation": 1
    },
    {
      "x": -7,
      "y": 28,
      "z": -5,
      "name": "Plant_Leaves_Azure",
      "rotation": 1
    },
    {
      "x": -7,
      "y": 29,
      "z": -5,
      "name": "Plant_Leaves_Azure",
      "rotation": 1
    },
    {
      "x": -7,
      "y": 30,
      "z": -5,
      "name": "Plant_Leaves_Azure",
      "rotation": 1
    },
    {
      "x": -7,
      "y": 31,
      "z": -5,
      "name": "Plant_Fruit_Azure",
      "rotation": 1
    },
    {
      "x": -7,
      "y": 33,
      "z": -5,
      "name": "Plant_Leaves_Azure",
      "rotation": 1
    },
    {
      "x": -7,
      "y": 34,
      "z": -5,
      "name": "Plant_Leaves_Azure",
      "rotation": 1
    },
    {
      "x": -7,
      "y": 35,
      "z": -5,
      "name": "Plant_Leaves_Azure",
      "rotation": 1
    },
    {
      "x": -7,
      "y": 28,
      "z": -4,
      "name": "Plant_Leaves_Azure",
      "rotation": 1
    },
    {
      "x": -7,
      "y": 29,
      "z": -4,
      "name": "Plant_Leaves_Azure",
      "rotation": 1
    },
    {
      "x": -7,
      "y": 33,
      "z": -4,
      "name": "Plant_Leaves_Azure",
      "rotation": 1
    },
    {
      "x": -7,
      "y": 34,
      "z": -4,
      "name": "Plant_Leaves_Azure",
      "rotation": 1
    },
    {
      "x": -7,
      "y": 35,
      "z": -4,
      "name": "Plant_Leaves_Azure",
      "rotation": 1
    },
    {
      "x": -7,
      "y": 36,
      "z": -4,
      "name": "Plant_Leaves_Azure",
      "rotation": 1
    },
    {
      "x": -7,
      "y": 37,
      "z": -4,
      "name": "Plant_Fruit_Azure",
      "rotation": 1
    },
    {
      "x": -7,
      "y": 34,
      "z": -3,
      "name": "Plant_Leaves_Azure",
      "rotation": 1
    },
    {
      "x": -7,
      "y": 35,
      "z": -3,
      "name": "Plant_Leaves_Azure",
      "rotation": 1
    },
    {
      "x": -7,
      "y": 36,
      "z": -3,
      "name": "Plant_Leaves_Azure",
      "rotation": 1
    },
    {
      "x": -7,
      "y": 37,
      "z": -3,
      "name": "Plant_Fruit_Azure",
      "rotation": 1
    },
    {
      "x": -7,
      "y": 30,
      "z": -2,
      "name": "Wood_Azure_Branch_Long",
      "rotation": 5
    },
    {
      "x": -7,
      "y": 31,
      "z": -2,
      "name": "Plant_Moss_Wall_Blue",
      "rotation": 3
    },
    {
      "x": -7,
      "y": 35,
      "z": -2,
      "name": "Plant_Leaves_Azure",
      "rotation": 1
    },
    {
      "x": -7,
      "y": 36,
      "z": -2,
      "name": "Plant_Leaves_Azure",
      "rotation": 1
    },
    {
      "x": -7,
      "y": 37,
      "z": -2,
      "name": "Plant_Leaves_Azure",
      "rotation": 1
    },
    {
      "x": -7,
      "y": 38,
      "z": -2,
      "name": "Plant_Leaves_Azure",
      "rotation": 1
    },
    {
      "x": -7,
      "y": 42,
      "z": -2,
      "name": "Plant_Leaves_Azure",
      "rotation": 1
    },
    {
      "x": -7,
      "y": 21,
      "z": -1,
      "name": "Wood_Azure_Trunk_Full",
      "rotation": 1
    },
    {
      "x": -7,
      "y": 22,
      "z": -1,
      "name": "Wood_Azure_Trunk_Full",
      "rotation": 1
    },
    {
      "x": -7,
      "y": 23,
      "z": -1,
      "name": "Wood_Azure_Trunk_Full",
      "rotation": 1
    },
    {
      "x": -7,
      "y": 24,
      "z": -1,
      "name": "Wood_Azure_Trunk",
      "rotation": 1
    },
    {
      "x": -7,
      "y": 25,
      "z": -1,
      "name": "Wood_Azure_Trunk_Full",
      "rotation": 1
    },
    {
      "x": -7,
      "y": 31,
      "z": -1,
      "name": "Wood_Azure_Trunk_Full",
      "rotation": 1
    },
    {
      "x": -7,
      "y": 32,
      "z": -1,
      "name": "Wood_Azure_Trunk",
      "rotation": 1
    },
    {
      "x": -7,
      "y": 33,
      "z": -1,
      "name": "Wood_Azure_Trunk_Full",
      "rotation": 1
    },
    {
      "x": -7,
      "y": 36,
      "z": -1,
      "name": "Wood_Azure_Branch_Long",
      "rotation": 5
    },
    {
      "x": -7,
      "y": 37,
      "z": -1,
      "name": "Plant_Leaves_Azure",
      "rotation": 1
    },
    {
      "x": -7,
      "y": 38,
      "z": -1,
      "name": "Plant_Leaves_Azure",
      "rotation": 1
    },
    {
      "x": -7,
      "y": 39,
      "z": -1,
      "name": "Plant_Leaves_Azure",
      "rotation": 1
    },
    {
      "x": -7,
      "y": 41,
      "z": -1,
      "name": "Plant_Leaves_Azure",
      "rotation": 1
    },
    {
      "x": -7,
      "y": 42,
      "z": -1,
      "name": "Plant_Leaves_Azure",
      "rotation": 1
    },
    {
      "x": -7,
      "y": 43,
      "z": -1,
      "name": "Plant_Leaves_Azure",
      "rotation": 1
    },
    {
      "x": -7,
      "y": 44,
      "z": -1,
      "name": "Plant_Leaves_Azure",
      "rotation": 1
    },
    {
      "x": -7,
      "y": 19,
      "z": 0,
      "name": "Wood_Azure_Roots",
      "rotation": 1
    },
    {
      "x": -7,
      "y": 20,
      "z": 0,
      "name": "Wood_Azure_Trunk_Full",
      "rotation": 1
    },
    {
      "x": -7,
      "y": 21,
      "z": 0,
      "name": "Wood_Azure_Roots",
      "rotation": 1
    },
    {
      "x": -7,
      "y": 22,
      "z": 0,
      "name": "Wood_Azure_Trunk_Full",
      "rotation": 1
    },
    {
      "x": -7,
      "y": 23,
      "z": 0,
      "name": "Wood_Azure_Trunk",
      "rotation": 1
    },
    {
      "x": -7,
      "y": 24,
      "z": 0,
      "name": "Wood_Azure_Trunk_Full",
      "rotation": 1
    },
    {
      "x": -7,
      "y": 26,
      "z": 0,
      "name": "Plant_Moss_Wall_Blue",
      "rotation": 3
    },
    {
      "x": -7,
      "y": 33,
      "z": 0,
      "name": "Wood_Azure_Trunk_Full",
      "rotation": 1
    },
    {
      "x": -7,
      "y": 34,
      "z": 0,
      "name": "Wood_Azure_Trunk",
      "rotation": 1
    },
    {
      "x": -7,
      "y": 35,
      "z": 0,
      "name": "Wood_Azure_Trunk_Full",
      "rotation": 1
    },
    {
      "x": -7,
      "y": 38,
      "z": 0,
      "name": "Wood_Azure_Branch_Long",
      "rotation": 5
    },
    {
      "x": -7,
      "y": 42,
      "z": 0,
      "name": "Plant_Leaves_Azure",
      "rotation": 1
    },
    {
      "x": -7,
      "y": 43,
      "z": 0,
      "name": "Plant_Leaves_Azure",
      "rotation": 1
    },
    {
      "x": -7,
      "y": 44,
      "z": 0,
      "name": "Plant_Leaves_Azure",
      "rotation": 1
    },
    {
      "x": -7,
      "y": 45,
      "z": 0,
      "name": "Plant_Leaves_Azure",
      "rotation": 1
    },
    {
      "x": -7,
      "y": 22,
      "z": 1,
      "name": "Wood_Azure_Trunk_Full",
      "rotation": 1
    },
    {
      "x": -7,
      "y": 23,
      "z": 1,
      "name": "Wood_Azure_Trunk_Full",
      "rotation": 1
    },
    {
      "x": -7,
      "y": 33,
      "z": 1,
      "name": "Plant_Leaves_Azure",
      "rotation": 1
    },
    {
      "x": -7,
      "y": 34,
      "z": 1,
      "name": "Wood_Azure_Branch_Long",
      "rotation": 6
    },
    {
      "x": -7,
      "y": 35,
      "z": 1,
      "name": "Plant_Leaves_Azure",
      "rotation": 1
    },
    {
      "x": -7,
      "y": 36,
      "z": 1,
      "name": "Plant_Fruit_Azure",
      "rotation": 1
    },
    {
      "x": -7,
      "y": 32,
      "z": 2,
      "name": "Plant_Leaves_Azure",
      "rotation": 1
    },
    {
      "x": -7,
      "y": 33,
      "z": 2,
      "name": "Plant_Leaves_Azure",
      "rotation": 1
    },
    {
      "x": -7,
      "y": 34,
      "z": 2,
      "name": "Wood_Azure_Branch_Long",
      "rotation": 6
    },
    {
      "x": -7,
      "y": 35,
      "z": 2,
      "name": "Plant_Leaves_Azure",
      "rotation": 1
    },
    {
      "x": -7,
      "y": 36,
      "z": 2,
      "name": "Plant_Leaves_Azure",
      "rotation": 1
    },
    {
      "x": -7,
      "y": 37,
      "z": 2,
      "name": "Plant_Leaves_Azure",
      "rotation": 1
    },
    {
      "x": -7,
      "y": 32,
      "z": 3,
      "name": "Plant_Leaves_Azure",
      "rotation": 1
    },
    {
      "x": -7,
      "y": 33,
      "z": 3,
      "name": "Plant_Leaves_Azure",
      "rotation": 1
    },
    {
      "x": -7,
      "y": 34,
      "z": 3,
      "name": "Wood_Azure_Branch_Long",
      "rotation": 6
    },
    {
      "x": -7,
      "y": 35,
      "z": 3,
      "name": "Plant_Leaves_Azure",
      "rotation": 1
    },
    {
      "x": -7,
      "y": 36,
      "z": 3,
      "name": "Plant_Leaves_Azure",
      "rotation": 1
    },
    {
      "x": -7,
      "y": 37,
      "z": 3,
      "name": "Plant_Leaves_Azure",
      "rotation": 1
    },
    {
      "x": -7,
      "y": 38,
      "z": 3,
      "name": "Plant_Leaves_Azure",
      "rotation": 1
    },
    {
      "x": -7,
      "y": 34,
      "z": 4,
      "name": "Plant_Leaves_Azure",
      "rotation": 1
    },
    {
      "x": -7,
      "y": 35,
      "z": 4,
      "name": "Plant_Leaves_Azure",
      "rotation": 1
    },
    {
      "x": -7,
      "y": 36,
      "z": 4,
      "name": "Plant_Leaves_Azure",
      "rotation": 1
    },
    {
      "x": -7,
      "y": 37,
      "z": 4,
      "name": "Plant_Leaves_Azure",
      "rotation": 1
    },
    {
      "x": -6,
      "y": 26,
      "z": -7,
      "name": "Plant_Leaves_Azure",
      "rotation": 1
    },
    {
      "x": -6,
      "y": 27,
      "z": -7,
      "name": "Plant_Leaves_Azure",
      "rotation": 1
    },
    {
      "x": -6,
      "y": 28,
      "z": -7,
      "name": "Plant_Leaves_Azure",
      "rotation": 1
    },
    {
      "x": -6,
      "y": 29,
      "z": -7,
      "name": "Plant_Leaves_Azure",
      "rotation": 1
    },
    {
      "x": -6,
      "y": 26,
      "z": -6,
      "name": "Plant_Leaves_Azure",
      "rotation": 1
    },
    {
      "x": -6,
      "y": 27,
      "z": -6,
      "name": "Plant_Leaves_Azure",
      "rotation": 1
    },
    {
      "x": -6,
      "y": 28,
      "z": -6,
      "name": "Plant_Leaves_Azure",
      "rotation": 1
    },
    {
      "x": -6,
      "y": 29,
      "z": -6,
      "name": "Plant_Leaves_Azure",
      "rotation": 1
    },
    {
      "x": -6,
      "y": 30,
      "z": -6,
      "name": "Plant_Fruit_Azure",
      "rotation": 1
    },
    {
      "x": -6,
      "y": 32,
      "z": -6,
      "name": "Plant_Leaves_Azure",
      "rotation": 1
    },
    {
      "x": -6,
      "y": 33,
      "z": -6,
      "name": "Plant_Leaves_Azure",
      "rotation": 1
    },
    {
      "x": -6,
      "y": 34,
      "z": -6,
      "name": "Plant_Leaves_Azure",
      "rotation": 1
    },
    {
      "x": -6,
      "y": 27,
      "z": -5,
      "name": "Plant_Leaves_Azure",
      "rotation": 1
    },
    {
      "x": -6,
      "y": 28,
      "z": -5,
      "name": "Plant_Leaves_Azure",
      "rotation": 1
    },
    {
      "x": -6,
      "y": 29,
      "z": -5,
      "name": "Wood_Azure_Branch_Long",
      "rotation": 6
    },
    {
      "x": -6,
      "y": 30,
      "z": -5,
      "name": "Plant_Leaves_Azure",
      "rotation": 1
    },
    {
      "x": -6,
      "y": 32,
      "z": -5,
      "name": "Plant_Leaves_Azure",
      "rotation": 1
    },
    {
      "x": -6,
      "y": 33,
      "z": -5,
      "name": "Plant_Leaves_Azure",
      "rotation": 1
    },
    {
      "x": -6,
      "y": 34,
      "z": -5,
      "name": "Plant_Leaves_Azure",
      "rotation": 1
    },
    {
      "x": -6,
      "y": 35,
      "z": -5,
      "name": "Plant_Leaves_Azure",
      "rotation": 1
    },
    {
      "x": -6,
      "y": 36,
      "z": -5,
      "name": "Plant_Fruit_Azure",
      "rotation": 1
    },
    {
      "x": -6,
      "y": 27,
      "z": -4,
      "name": "Plant_Leaves_Azure",
      "rotation": 1
    },
    {
      "x": -6,
      "y": 28,
      "z": -4,
      "name": "Plant_Leaves_Azure",
      "rotation": 1
    },
    {
      "x": -6,
      "y": 29,
      "z": -4,
      "name": "Wood_Azure_Branch_Long",
      "rotation": 6
    },
    {
      "x": -6,
      "y": 33,
      "z": -4,
      "name": "Plant_Leaves_Azure",
      "rotation": 1
    },
    {
      "x": -6,
      "y": 34,
      "z": -4,
      "name": "Plant_Leaves_Azure",
      "rotation": 1
    },
    {
      "x": -6,
      "y": 35,
      "z": -4,
      "name": "Plant_Leaves_Azure",
      "rotation": 1
    },
    {
      "x": -6,
      "y": 36,
      "z": -4,
      "name": "Plant_Leaves_Azure",
      "rotation": 1
    },
    {
      "x": -6,
      "y": 29,
      "z": -3,
      "name": "Wood_Azure_Branch_Long",
      "rotation": 6
    },
    {
      "x": -6,
      "y": 30,
      "z": -3,
      "name": "Plant_Moss_Wall_Blue",
      "rotation": 3
    },
    {
      "x": -6,
      "y": 31,
      "z": -3,
      "name": "Plant_Moss_Wall_Blue",
      "rotation": 2
    },
    {
      "x": -6,
      "y": 34,
      "z": -3,
      "name": "Plant_Leaves_Azure",
      "rotation": 1
    },
    {
      "x": -6,
      "y": 35,
      "z": -3,
      "name": "Plant_Leaves_Azure",
      "rotation": 1
    },
    {
      "x": -6,
      "y": 41,
      "z": -3,
      "name": "Plant_Leaves_Azure",
      "rotation": 1
    },
    {
      "x": -6,
      "y": 22,
      "z": -2,
      "name": "Wood_Azure_Trunk_Full",
      "rotation": 1
    },
    {
      "x": -6,
      "y": 23,
      "z": -2,
      "name": "Wood_Azure_Trunk",
      "rotation": 1
    },
    {
      "x": -6,
      "y": 24,
      "z": -2,
      "name": "Wood_Azure_Trunk_Full",
      "rotation": 1
    },
    {
      "x": -6,
      "y": 28,
      "z": -2,
      "name": "Wood_Azure_Trunk_Full",
      "rotation": 1
    },
    {
      "x": -6,
      "y": 29,
      "z": -2,
      "name": "Wood_Azure_Trunk",
      "rotation": 1
    },
    {
      "x": -6,
      "y": 30,
      "z": -2,
      "name": "Wood_Azure_Trunk",
      "rotation": 1
    },
    {
      "x": -6,
      "y": 31,
      "z": -2,
      "name": "Wood_Azure_Trunk_Full",
      "rotation": 1
    },
    {
      "x": -6,
      "y": 32,
      "z": -2,
      "name": "Plant_Moss_Rug_Blue",
      "rotation": 1
    },
    {
      "x": -6,
      "y": 35,
      "z": -2,
      "name": "Wood_Azure_Branch_Long",
      "rotation": 5
    },
    {
      "x": -6,
      "y": 40,
      "z": -2,
      "name": "Plant_Leaves_Azure",
      "rotation": 1
    },
    {
      "x": -6,
      "y": 41,
      "z": -2,
      "name": "Plant_Leaves_Azure",
      "rotation": 1
    },
    {
      "x": -6,
      "y": 42,
      "z": -2,
      "name": "Plant_Leaves_Azure",
      "rotation": 1
    },
    {
      "x": -6,
      "y": 43,
      "z": -2,
      "name": "Plant_Leaves_Azure",
      "rotation": 1
    },
    {
      "x": -6,
      "y": 20,
      "z": -1,
      "name": "Wood_Azure_Roots",
      "rotation": 1
    },
    {
      "x": -6,
      "y": 21,
      "z": -1,
      "name": "Wood_Azure_Trunk_Full",
      "rotation": 1
    },
    {
      "x": -6,
      "y": 22,
      "z": -1,
      "name": "Wood_Azure_Trunk",
      "rotation": 1
    },
    {
      "x": -6,
      "y": 23,
      "z": -1,
      "name": "Wood_Azure_Trunk_Full",
      "rotation": 1
    },
    {
      "x": -6,
      "y": 24,
      "z": -1,
      "name": "Wood_Azure_Trunk",
      "rotation": 1
    },
    {
      "x": -6,
      "y": 25,
      "z": -1,
      "name": "Wood_Azure_Trunk",
      "rotation": 1
    },
    {
      "x": -6,
      "y": 26,
      "z": -1,
      "name": "Wood_Azure_Trunk",
      "rotation": 1
    },
    {
      "x": -6,
      "y": 27,
      "z": -1,
      "name": "Wood_Azure_Trunk",
      "rotation": 1
    },
    {
      "x": -6,
      "y": 28,
      "z": -1,
      "name": "Wood_Azure_Trunk",
      "rotation": 1
    },
    {
      "x": -6,
      "y": 29,
      "z": -1,
      "name": "Wood_Azure_Trunk",
      "rotation": 1
    },
    {
      "x": -6,
      "y": 30,
      "z": -1,
      "name": "Wood_Azure_Trunk",
      "rotation": 1
    },
    {
      "x": -6,
      "y": 31,
      "z": -1,
      "name": "Wood_Azure_Trunk",
      "rotation": 1
    },
    {
      "x": -6,
      "y": 32,
      "z": -1,
      "name": "Wood_Azure_Trunk",
      "rotation": 1
    },
    {
      "x": -6,
      "y": 33,
      "z": -1,
      "name": "Wood_Azure_Trunk",
      "rotation": 1
    },
    {
      "x": -6,
      "y": 34,
      "z": -1,
      "name": "Wood_Azure_Trunk",
      "rotation": 1
    },
    {
      "x": -6,
      "y": 35,
      "z": -1,
      "name": "Wood_Azure_Trunk",
      "rotation": 1
    },
    {
      "x": -6,
      "y": 36,
      "z": -1,
      "name": "Wood_Azure_Trunk_Full",
      "rotation": 1
    },
    {
      "x": -6,
      "y": 37,
      "z": -1,
      "name": "Wood_Azure_Branch_Long",
      "rotation": 5
    },
    {
      "x": -6,
      "y": 39,
      "z": -1,
      "name": "Plant_Moss_Wall_Blue",
      "rotation": 2
    },
    {
      "x": -6,
      "y": 41,
      "z": -1,
      "name": "Plant_Leaves_Azure",
      "rotation": 1
    },
    {
      "x": -6,
      "y": 42,
      "z": -1,
      "name": "Plant_Leaves_Azure",
      "rotation": 1
    },
    {
      "x": -6,
      "y": 43,
      "z": -1,
      "name": "Plant_Leaves_Azure",
      "rotation": 1
    },
    {
      "x": -6,
      "y": 44,
      "z": -1,
      "name": "Plant_Fruit_Azure",
      "rotation": 1
    },
    {
      "x": -6,
      "y": 21,
      "z": 0,
      "name": "Wood_Azure_Trunk_Full",
      "rotation": 1
    },
    {
      "x": -6,
      "y": 22,
      "z": 0,
      "name": "Wood_Azure_Trunk_Full",
      "rotation": 1
    },
    {
      "x": -6,
      "y": 23,
      "z": 0,
      "name": "Wood_Azure_Trunk_Full",
      "rotation": 1
    },
    {
      "x": -6,
      "y": 24,
      "z": 0,
      "name": "Wood_Azure_Trunk",
      "rotation": 1
    },
    {
      "x": -6,
      "y": 25,
      "z": 0,
      "name": "Wood_Azure_Trunk",
      "rotation": 1
    },
    {
      "x": -6,
      "y": 26,
      "z": 0,
      "name": "Wood_Azure_Trunk_Full",
      "rotation": 1
    },
    {
      "x": -6,
      "y": 27,
      "z": 0,
      "name": "Plant_Moss_Rug_Blue",
      "rotation": 1
    },
    {
      "x": -6,
      "y": 30,
      "z": 0,
      "name": "Wood_Azure_Trunk_Full",
      "rotation": 1
    },
    {
      "x": -6,
      "y": 31,
      "z": 0,
      "name": "Wood_Azure_Trunk",
      "rotation": 1
    },
    {
      "x": -6,
      "y": 32,
      "z": 0,
      "name": "Wood_Azure_Trunk",
      "rotation": 1
    },
    {
      "x": -6,
      "y": 33,
      "z": 0,
      "name": "Wood_Azure_Trunk",
      "rotation": 1
    },
    {
      "x": -6,
      "y": 34,
      "z": 0,
      "name": "Wood_Azure_Trunk",
      "rotation": 1
    },
    {
      "x": -6,
      "y": 35,
      "z": 0,
      "name": "Wood_Azure_Trunk",
      "rotation": 1
    },
    {
      "x": -6,
      "y": 36,
      "z": 0,
      "name": "Wood_Azure_Trunk",
      "rotation": 1
    },
    {
      "x": -6,
      "y": 37,
      "z": 0,
      "name": "Wood_Azure_Trunk",
      "rotation": 1
    },
    {
      "x": -6,
      "y": 38,
      "z": 0,
      "name": "Wood_Azure_Trunk",
      "rotation": 1
    },
    {
      "x": -6,
      "y": 39,
      "z": 0,
      "name": "Wood_Azure_Trunk_Full",
      "rotation": 1
    },
    {
      "x": -6,
      "y": 40,
      "z": 0,
      "name": "Wood_Azure_Branch_Long",
      "rotation": 1
    },
    {
      "x": -6,
      "y": 41,
      "z": 0,
      "name": "Wood_Azure_Branch_Long",
      "rotation": 1
    },
    {
      "x": -6,
      "y": 42,
      "z": 0,
      "name": "Wood_Azure_Branch_Long",
      "rotation": 1
    },
    {
      "x": -6,
      "y": 43,
      "z": 0,
      "name": "Plant_Leaves_Azure",
      "rotation": 1
    },
    {
      "x": -6,
      "y": 44,
      "z": 0,
      "name": "Plant_Leaves_Azure",
      "rotation": 1
    },
    {
      "x": -6,
      "y": 16,
      "z": 1,
      "name": "Plant_Moss_Wall_Blue",
      "rotation": 3
    },
    {
      "x": -6,
      "y": 17,
      "z": 1,
      "name": "Plant_Moss_Wall_Blue",
      "rotation": 3
    },
    {
      "x": -6,
      "y": 23,
      "z": 1,
      "name": "Wood_Azure_Trunk_Full",
      "rotation": 1
    },
    {
      "x": -6,
      "y": 26,
      "z": 1,
      "name": "Plant_Moss_Wall_Blue"
    },
    {
      "x": -6,
      "y": 33,
      "z": 1,
      "name": "Wood_Azure_Branch_Long",
      "rotation": 6
    },
    {
      "x": -6,
      "y": 35,
      "z": 1,
      "name": "Plant_Leaves_Azure",
      "rotation": 1
    },
    {
      "x": -6,
      "y": 36,
      "z": 1,
      "name": "Plant_Leaves_Azure",
      "rotation": 1
    },
    {
      "x": -6,
      "y": 37,
      "z": 1,
      "name": "Wood_Azure_Branch_Long",
      "rotation": 6
    },
    {
      "x": -6,
      "y": 42,
      "z": 1,
      "name": "Plant_Leaves_Azure",
      "rotation": 1
    },
    {
      "x": -6,
      "y": 16,
      "z": 2,
      "name": "Plant_Moss_Wall_Blue",
      "rotation": 3
    },
    {
      "x": -6,
      "y": 17,
      "z": 2,
      "name": "Plant_Moss_Wall_Blue",
      "rotation": 3
    },
    {
      "x": -6,
      "y": 18,
      "z": 2,
      "name": "Plant_Moss_Wall_Blue",
      "rotation": 3
    },
    {
      "x": -6,
      "y": 30,
      "z": 2,
      "name": "Plant_Moss_Wall_Blue",
      "rotation": 3
    },
    {
      "x": -6,
      "y": 32,
      "z": 2,
      "name": "Plant_Leaves_Azure",
      "rotation": 1
    },
    {
      "x": -6,
      "y": 33,
      "z": 2,
      "name": "Wood_Azure_Branch_Long",
      "rotation": 6
    },
    {
      "x": -6,
      "y": 34,
      "z": 2,
      "name": "Plant_Leaves_Azure",
      "rotation": 1
    },
    {
      "x": -6,
      "y": 35,
      "z": 2,
      "name": "Plant_Leaves_Azure",
      "rotation": 1
    },
    {
      "x": -6,
      "y": 36,
      "z": 2,
      "name": "Plant_Leaves_Azure",
      "rotation": 1
    },
    {
      "x": -6,
      "y": 37,
      "z": 2,
      "name": "Wood_Azure_Branch_Long",
      "rotation": 6
    },
    {
      "x": -6,
      "y": 38,
      "z": 2,
      "name": "Plant_Leaves_Azure",
      "rotation": 1
    },
    {
      "x": -6,
      "y": 39,
      "z": 2,
      "name": "Plant_Fruit_Azure",
      "rotation": 1
    },
    {
      "x": -6,
      "y": 16,
      "z": 3,
      "name": "Plant_Moss_Wall_Blue",
      "rotation": 3
    },
    {
      "x": -6,
      "y": 17,
      "z": 3,
      "name": "Plant_Moss_Wall_Blue",
      "rotation": 3
    },
    {
      "x": -6,
      "y": 33,
      "z": 3,
      "name": "Plant_Leaves_Azure",
      "rotation": 1
    },
    {
      "x": -6,
      "y": 34,
      "z": 3,
      "name": "Plant_Leaves_Azure",
      "rotation": 1
    },
    {
      "x": -6,
      "y": 35,
      "z": 3,
      "name": "Plant_Leaves_Azure",
      "rotation": 1
    },
    {
      "x": -6,
      "y": 36,
      "z": 3,
      "name": "Plant_Leaves_Azure",
      "rotation": 1
    },
    {
      "x": -6,
      "y": 37,
      "z": 3,
      "name": "Plant_Leaves_Azure",
      "rotation": 1
    },
    {
      "x": -6,
      "y": 38,
      "z": 3,
      "name": "Plant_Leaves_Azure",
      "rotation": 1
    },
    {
      "x": -6,
      "y": 39,
      "z": 3,
      "name": "Plant_Leaves_Azure",
      "rotation": 1
    },
    {
      "x": -6,
      "y": 30,
      "z": 4,
      "name": "Plant_Leaves_Azure",
      "rotation": 1
    },
    {
      "x": -6,
      "y": 31,
      "z": 4,
      "name": "Plant_Leaves_Azure",
      "rotation": 1
    },
    {
      "x": -6,
      "y": 35,
      "z": 4,
      "name": "Plant_Leaves_Azure",
      "rotation": 1
    },
    {
      "x": -6,
      "y": 36,
      "z": 4,
      "name": "Plant_Leaves_Azure",
      "rotation": 1
    },
    {
      "x": -6,
      "y": 37,
      "z": 4,
      "name": "Plant_Leaves_Azure",
      "rotation": 1
    },
    {
      "x": -6,
      "y": 38,
      "z": 4,
      "name": "Plant_Leaves_Azure",
      "rotation": 1
    },
    {
      "x": -6,
      "y": 30,
      "z": 5,
      "name": "Plant_Leaves_Azure",
      "rotation": 1
    },
    {
      "x": -6,
      "y": 31,
      "z": 5,
      "name": "Plant_Leaves_Azure",
      "rotation": 1
    },
    {
      "x": -5,
      "y": 26,
      "z": -7,
      "name": "Plant_Leaves_Azure",
      "rotation": 1
    },
    {
      "x": -5,
      "y": 27,
      "z": -7,
      "name": "Plant_Leaves_Azure",
      "rotation": 1
    },
    {
      "x": -5,
      "y": 28,
      "z": -7,
      "name": "Plant_Leaves_Azure",
      "rotation": 1
    },
    {
      "x": -5,
      "y": 26,
      "z": -6,
      "name": "Plant_Leaves_Azure",
      "rotation": 1
    },
    {
      "x": -5,
      "y": 27,
      "z": -6,
      "name": "Plant_Leaves_Azure",
      "rotation": 1
    },
    {
      "x": -5,
      "y": 28,
      "z": -6,
      "name": "Plant_Leaves_Azure",
      "rotation": 1
    },
    {
      "x": -5,
      "y": 29,
      "z": -6,
      "name": "Plant_Leaves_Azure",
      "rotation": 1
    },
    {
      "x": -5,
      "y": 31,
      "z": -6,
      "name": "Plant_Leaves_Azure",
      "rotation": 1
    },
    {
      "x": -5,
      "y": 32,
      "z": -6,
      "name": "Plant_Leaves_Azure",
      "rotation": 1
    },
    {
      "x": -5,
      "y": 33,
      "z": -6,
      "name": "Plant_Leaves_Azure",
      "rotation": 1
    },
    {
      "x": -5,
      "y": 34,
      "z": -6,
      "name": "Plant_Leaves_Azure",
      "rotation": 1
    },
    {
      "x": -5,
      "y": 26,
      "z": -5,
      "name": "Plant_Leaves_Azure",
      "rotation": 1
    },
    {
      "x": -5,
      "y": 27,
      "z": -5,
      "name": "Plant_Leaves_Azure",
      "rotation": 1
    },
    {
      "x": -5,
      "y": 28,
      "z": -5,
      "name": "Plant_Leaves_Azure",
      "rotation": 1
    },
    {
      "x": -5,
      "y": 29,
      "z": -5,
      "name": "Plant_Leaves_Azure",
      "rotation": 1
    },
    {
      "x": -5,
      "y": 31,
      "z": -5,
      "name": "Plant_Leaves_Azure",
      "rotation": 1
    },
    {
      "x": -5,
      "y": 32,
      "z": -5,
      "name": "Plant_Leaves_Azure",
      "rotation": 1
    },
    {
      "x": -5,
      "y": 33,
      "z": -5,
      "name": "Plant_Leaves_Azure",
      "rotation": 1
    },
    {
      "x": -5,
      "y": 34,
      "z": -5,
      "name": "Plant_Leaves_Azure",
      "rotation": 1
    },
    {
      "x": -5,
      "y": 35,
      "z": -5,
      "name": "Plant_Leaves_Azure",
      "rotation": 1
    },
    {
      "x": -5,
      "y": 23,
      "z": -4,
      "name": "Plant_Moss_Wall_Blue",
      "rotation": 3
    },
    {
      "x": -5,
      "y": 28,
      "z": -4,
      "name": "Plant_Leaves_Azure",
      "rotation": 1
    },
    {
      "x": -5,
      "y": 30,
      "z": -4,
      "name": "Plant_Moss_Wall_Blue",
      "rotation": 2
    },
    {
      "x": -5,
      "y": 33,
      "z": -4,
      "name": "Plant_Leaves_Azure",
      "rotation": 1
    },
    {
      "x": -5,
      "y": 34,
      "z": -4,
      "name": "Plant_Leaves_Azure",
      "rotation": 1
    },
    {
      "x": -5,
      "y": 35,
      "z": -4,
      "name": "Plant_Leaves_Azure",
      "rotation": 1
    },
    {
      "x": -5,
      "y": 36,
      "z": -4,
      "name": "Plant_Fruit_Azure",
      "rotation": 1
    },
    {
      "x": -5,
      "y": 27,
      "z": -3,
      "name": "Wood_Azure_Trunk_Full",
      "rotation": 1
    },
    {
      "x": -5,
      "y": 28,
      "z": -3,
      "name": "Wood_Azure_Trunk",
      "rotation": 1
    },
    {
      "x": -5,
      "y": 29,
      "z": -3,
      "name": "Wood_Azure_Trunk",
      "rotation": 1
    },
    {
      "x": -5,
      "y": 30,
      "z": -3,
      "name": "Wood_Azure_Trunk_Full",
      "rotation": 1
    },
    {
      "x": -5,
      "y": 31,
      "z": -3,
      "name": "Plant_Moss_Rug_Blue",
      "rotation": 1
    },
    {
      "x": -5,
      "y": 33,
      "z": -3,
      "name": "Plant_Leaves_Azure",
      "rotation": 1
    },
    {
      "x": -5,
      "y": 34,
      "z": -3,
      "name": "Plant_Leaves_Azure",
      "rotation": 1
    },
    {
      "x": -5,
      "y": 39,
      "z": -3,
      "name": "Plant_Leaves_Azure",
      "rotation": 1
    },
    {
      "x": -5,
      "y": 40,
      "z": -3,
      "name": "Plant_Leaves_Azure",
      "rotation": 1
    },
    {
      "x": -5,
      "y": 41,
      "z": -3,
      "name": "Plant_Leaves_Azure",
      "rotation": 1
    },
    {
      "x": -5,
      "y": 22,
      "z": -2,
      "name": "Wood_Azure_Trunk_Full",
      "rotation": 1
    },
    {
      "x": -5,
      "y": 23,
      "z": -2,
      "name": "Wood_Azure_Trunk",
      "rotation": 1
    },
    {
      "x": -5,
      "y": 24,
      "z": -2,
      "name": "Wood_Azure_Trunk",
      "rotation": 1
    },
    {
      "x": -5,
      "y": 25,
      "z": -2,
      "name": "Wood_Azure_Trunk",
      "rotation": 1
    },
    {
      "x": -5,
      "y": 26,
      "z": -2,
      "name": "Wood_Azure_Trunk_Full",
      "rotation": 1
    },
    {
      "x": -5,
      "y": 27,
      "z": -2,
      "name": "Wood_Azure_Trunk",
      "rotation": 1
    },
    {
      "x": -5,
      "y": 28,
      "z": -2,
      "name": "Wood_Azure_Trunk",
      "rotation": 1
    },
    {
      "x": -5,
      "y": 29,
      "z": -2,
      "name": "Wood_Azure_Trunk_Full",
      "rotation": 1
    },
    {
      "x": -5,
      "y": 30,
      "z": -2,
      "name": "Wood_Azure_Trunk",
      "rotation": 1
    },
    {
      "x": -5,
      "y": 31,
      "z": -2,
      "name": "Plant_Moss_Wall_Blue",
      "rotation": 1
    },
    {
      "x": -5,
      "y": 32,
      "z": -2,
      "name": "Wood_Azure_Trunk",
      "rotation": 1
    },
    {
      "x": -5,
      "y": 33,
      "z": -2,
      "name": "Wood_Azure_Branch_Long",
      "rotation": 6
    },
    {
      "x": -5,
      "y": 34,
      "z": -2,
      "name": "Plant_Moss_Wall_Blue",
      "rotation": 2
    },
    {
      "x": -5,
      "y": 35,
      "z": -2,
      "name": "Wood_Azure_Trunk_Full",
      "rotation": 1
    },
    {
      "x": -5,
      "y": 37,
      "z": -2,
      "name": "Plant_Leaves_Azure",
      "rotation": 1
    },
    {
      "x": -5,
      "y": 38,
      "z": -2,
      "name": "Plant_Moss_Wall_Blue",
      "rotation": 2
    },
    {
      "x": -5,
      "y": 40,
      "z": -2,
      "name": "Plant_Leaves_Azure",
      "rotation": 1
    },
    {
      "x": -5,
      "y": 41,
      "z": -2,
      "name": "Plant_Leaves_Azure",
      "rotation": 1
    },
    {
      "x": -5,
      "y": 42,
      "z": -2,
      "name": "Plant_Leaves_Azure",
      "rotation": 1
    },
    {
      "x": -5,
      "y": 43,
      "z": -2,
      "name": "Plant_Fruit_Azure",
      "rotation": 1
    },
    {
      "x": -5,
      "y": 16,
      "z": -1,
      "name": "Plant_Moss_Wall_Blue",
      "rotation": 3
    },
    {
      "x": -5,
      "y": 22,
      "z": -1,
      "name": "Wood_Azure_Trunk_Full",
      "rotation": 1
    },
    {
      "x": -5,
      "y": 23,
      "z": -1,
      "name": "Wood_Azure_Trunk",
      "rotation": 1
    },
    {
      "x": -5,
      "y": 24,
      "z": -1,
      "name": "Wood_Azure_Trunk",
      "rotation": 1
    },
    {
      "x": -5,
      "y": 25,
      "z": -1,
      "name": "Wood_Azure_Trunk",
      "rotation": 1
    },
    {
      "x": -5,
      "y": 26,
      "z": -1,
      "name": "Wood_Azure_Trunk",
      "rotation": 1
    },
    {
      "x": -5,
      "y": 27,
      "z": -1,
      "name": "Wood_Azure_Trunk",
      "rotation": 1
    },
    {
      "x": -5,
      "y": 28,
      "z": -1,
      "name": "Wood_Azure_Trunk",
      "rotation": 1
    },
    {
      "x": -5,
      "y": 29,
      "z": -1,
      "name": "Wood_Azure_Trunk",
      "rotation": 1
    },
    {
      "x": -5,
      "y": 30,
      "z": -1,
      "name": "Wood_Azure_Trunk",
      "rotation": 1
    },
    {
      "x": -5,
      "y": 31,
      "z": -1,
      "name": "Wood_Azure_Trunk",
      "rotation": 1
    },
    {
      "x": -5,
      "y": 32,
      "z": -1,
      "name": "Wood_Azure_Trunk",
      "rotation": 1
    },
    {
      "x": -5,
      "y": 33,
      "z": -1,
      "name": "Wood_Azure_Trunk",
      "rotation": 1
    },
    {
      "x": -5,
      "y": 34,
      "z": -1,
      "name": "Wood_Azure_Trunk_Full",
      "rotation": 1
    },
    {
      "x": -5,
      "y": 35,
      "z": -1,
      "name": "Plant_Moss_Rug_Blue",
      "rotation": 1
    },
    {
      "x": -5,
      "y": 36,
      "z": -1,
      "name": "Wood_Azure_Branch_Long",
      "rotation": 5
    },
    {
      "x": -5,
      "y": 37,
      "z": -1,
      "name": "Wood_Azure_Trunk",
      "rotation": 1
    },
    {
      "x": -5,
      "y": 38,
      "z": -1,
      "name": "Wood_Azure_Trunk_Full",
      "rotation": 1
    },
    {
      "x": -5,
      "y": 39,
      "z": -1,
      "name": "Plant_Leaves_Azure",
      "rotation": 1
    },
    {
      "x": -5,
      "y": 40,
      "z": -1,
      "name": "Plant_Leaves_Azure",
      "rotation": 1
    },
    {
      "x": -5,
      "y": 41,
      "z": -1,
      "name": "Plant_Leaves_Azure",
      "rotation": 1
    },
    {
      "x": -5,
      "y": 42,
      "z": -1,
      "name": "Plant_Leaves_Azure",
      "rotation": 1
    },
    {
      "x": -5,
      "y": 43,
      "z": -1,
      "name": "Plant_Leaves_Azure",
      "rotation": 1
    },
    {
      "x": -5,
      "y": 16,
      "z": 0,
      "name": "Plant_Moss_Wall_Blue",
      "rotation": 3
    },
    {
      "x": -5,
      "y": 22,
      "z": 0,
      "name": "Wood_Azure_Trunk_Full",
      "rotation": 1
    },
    {
      "x": -5,
      "y": 24,
      "z": 0,
      "name": "Wood_Azure_Trunk_Full",
      "rotation": 1
    },
    {
      "x": -5,
      "y": 25,
      "z": 0,
      "name": "Wood_Azure_Trunk",
      "rotation": 1
    },
    {
      "x": -5,
      "y": 26,
      "z": 0,
      "name": "Wood_Azure_Trunk",
      "rotation": 1
    },
    {
      "x": -5,
      "y": 27,
      "z": 0,
      "name": "Wood_Azure_Trunk",
      "rotation": 1
    },
    {
      "x": -5,
      "y": 28,
      "z": 0,
      "name": "Wood_Azure_Trunk",
      "rotation": 1
    },
    {
      "x": -5,
      "y": 29,
      "z": 0,
      "name": "Wood_Azure_Trunk",
      "rotation": 1
    },
    {
      "x": -5,
      "y": 30,
      "z": 0,
      "name": "Wood_Azure_Trunk",
      "rotation": 1
    },
    {
      "x": -5,
      "y": 31,
      "z": 0,
      "name": "Wood_Azure_Trunk",
      "rotation": 1
    },
    {
      "x": -5,
      "y": 32,
      "z": 0,
      "name": "Wood_Azure_Trunk_Full",
      "rotation": 1
    },
    {
      "x": -5,
      "y": 34,
      "z": 0,
      "name": "Plant_Moss_Wall_Blue"
    },
    {
      "x": -5,
      "y": 36,
      "z": 0,
      "name": "Wood_Azure_Branch_Long",
      "rotation": 6
    },
    {
      "x": -5,
      "y": 39,
      "z": 0,
      "name": "Wood_Azure_Branch_Long",
      "rotation": 5
    },
    {
      "x": -5,
      "y": 41,
      "z": 0,
      "name": "Plant_Leaves_Azure",
      "rotation": 1
    },
    {
      "x": -5,
      "y": 42,
      "z": 0,
      "name": "Plant_Leaves_Azure",
      "rotation": 1
    },
    {
      "x": -5,
      "y": 16,
      "z": 1,
      "name": "Rock_Marble"
    },
    {
      "x": -5,
      "y": 17,
      "z": 1,
      "name": "Rock_Marble"
    },
    {
      "x": -5,
      "y": 18,
      "z": 1,
      "name": "Rock_Marble"
    },
    {
      "x": -5,
      "y": 19,
      "z": 1,
      "name": "Rock_Marble"
    },
    {
      "x": -5,
      "y": 20,
      "z": 1,
      "name": "Rock_Marble"
    },
    {
      "x": -5,
      "y": 23,
      "z": 1,
      "name": "Wood_Azure_Trunk_Full",
      "rotation": 1
    },
    {
      "x": -5,
      "y": 24,
      "z": 1,
      "name": "Wood_Azure_Trunk_Full",
      "rotation": 1
    },
    {
      "x": -5,
      "y": 29,
      "z": 1,
      "name": "Plant_Moss_Wall_Blue",
      "rotation": 3
    },
    {
      "x": -5,
      "y": 30,
      "z": 1,
      "name": "Wood_Azure_Trunk_Full",
      "rotation": 1
    },
    {
      "x": -5,
      "y": 32,
      "z": 1,
      "name": "Wood_Azure_Branch_Corner"
    },
    {
      "x": -5,
      "y": 33,
      "z": 1,
      "name": "Wood_Azure_Branch_Corner",
      "rotation": 9
    },
    {
      "x": -5,
      "y": 35,
      "z": 1,
      "name": "Plant_Leaves_Azure",
      "rotation": 1
    },
    {
      "x": -5,
      "y": 36,
      "z": 1,
      "name": "Wood_Azure_Branch_Long",
      "rotation": 6
    },
    {
      "x": -5,
      "y": 37,
      "z": 1,
      "name": "Plant_Leaves_Azure",
      "rotation": 1
    },
    {
      "x": -5,
      "y": 38,
      "z": 1,
      "name": "Plant_Leaves_Azure",
      "rotation": 1
    },
    {
      "x": -5,
      "y": 39,
      "z": 1,
      "name": "Plant_Leaves_Azure",
      "rotation": 1
    },
    {
      "x": -5,
      "y": 16,
      "z": 2,
      "name": "Rock_Marble"
    },
    {
      "x": -5,
      "y": 17,
      "z": 2,
      "name": "Rock_Marble"
    },
    {
      "x": -5,
      "y": 18,
      "z": 2,
      "name": "Rock_Marble"
    },
    {
      "x": -5,
      "y": 19,
      "z": 2,
      "name": "Rock_Marble"
    },
    {
      "x": -5,
      "y": 20,
      "z": 2,
      "name": "Rock_Marble_Cobble"
    },
    {
      "x": -5,
      "y": 30,
      "z": 2,
      "name": "Wood_Azure_Trunk_Full",
      "rotation": 1
    },
    {
      "x": -5,
      "y": 31,
      "z": 2,
      "name": "Plant_Moss_Rug_Blue",
      "rotation": 1
    },
    {
      "x": -5,
      "y": 33,
      "z": 2,
      "name": "Plant_Leaves_Azure",
      "rotation": 1
    },
    {
      "x": -5,
      "y": 34,
      "z": 2,
      "name": "Plant_Leaves_Azure",
      "rotation": 1
    },
    {
      "x": -5,
      "y": 35,
      "z": 2,
      "name": "Plant_Leaves_Azure",
      "rotation": 1
    },
    {
      "x": -5,
      "y": 36,
      "z": 2,
      "name": "Plant_Leaves_Azure",
      "rotation": 1
    },
    {
      "x": -5,
      "y": 37,
      "z": 2,
      "name": "Plant_Leaves_Azure",
      "rotation": 1
    },
    {
      "x": -5,
      "y": 38,
      "z": 2,
      "name": "Plant_Leaves_Azure",
      "rotation": 1
    },
    {
      "x": -5,
      "y": 39,
      "z": 2,
      "name": "Plant_Leaves_Azure",
      "rotation": 1
    },
    {
      "x": -5,
      "y": 40,
      "z": 2,
      "name": "Plant_Leaves_Azure",
      "rotation": 1
    },
    {
      "x": -5,
      "y": 16,
      "z": 3,
      "name": "Rock_Marble"
    },
    {
      "x": -5,
      "y": 17,
      "z": 3,
      "name": "Rock_Marble"
    },
    {
      "x": -5,
      "y": 18,
      "z": 3,
      "name": "Rock_Marble"
    },
    {
      "x": -5,
      "y": 19,
      "z": 3,
      "name": "Rock_Marble"
    },
    {
      "x": -5,
      "y": 20,
      "z": 3,
      "name": "Plant_Moss_Rug_Lime"
    },
    {
      "x": -5,
      "y": 29,
      "z": 3,
      "name": "Plant_Leaves_Azure",
      "rotation": 1
    },
    {
      "x": -5,
      "y": 30,
      "z": 3,
      "name": "Wood_Azure_Branch_Long",
      "rotation": 6
    },
    {
      "x": -5,
      "y": 34,
      "z": 3,
      "name": "Plant_Leaves_Azure",
      "rotation": 1
    },
    {
      "x": -5,
      "y": 35,
      "z": 3,
      "name": "Plant_Leaves_Azure",
      "rotation": 1
    },
    {
      "x": -5,
      "y": 36,
      "z": 3,
      "name": "Plant_Leaves_Azure",
      "rotation": 1
    },
    {
      "x": -5,
      "y": 37,
      "z": 3,
      "name": "Plant_Leaves_Azure",
      "rotation": 1
    },
    {
      "x": -5,
      "y": 38,
      "z": 3,
      "name": "Plant_Leaves_Azure",
      "rotation": 1
    },
    {
      "x": -5,
      "y": 39,
      "z": 3,
      "name": "Plant_Leaves_Azure",
      "rotation": 1
    },
    {
      "x": -5,
      "y": 16,
      "z": 4,
      "name": "Plant_Moss_Wall_Blue",
      "rotation": 3
    },
    {
      "x": -5,
      "y": 29,
      "z": 4,
      "name": "Plant_Leaves_Azure",
      "rotation": 1
    },
    {
      "x": -5,
      "y": 30,
      "z": 4,
      "name": "Plant_Leaves_Azure",
      "rotation": 1
    },
    {
      "x": -5,
      "y": 31,
      "z": 4,
      "name": "Plant_Leaves_Azure",
      "rotation": 1
    },
    {
      "x": -5,
      "y": 32,
      "z": 4,
      "name": "Plant_Leaves_Azure",
      "rotation": 1
    },
    {
      "x": -5,
      "y": 36,
      "z": 4,
      "name": "Plant_Leaves_Azure",
      "rotation": 1
    },
    {
      "x": -5,
      "y": 37,
      "z": 4,
      "name": "Plant_Leaves_Azure",
      "rotation": 1
    },
    {
      "x": -5,
      "y": 38,
      "z": 4,
      "name": "Plant_Leaves_Azure",
      "rotation": 1
    },
    {
      "x": -5,
      "y": 29,
      "z": 5,
      "name": "Plant_Leaves_Azure",
      "rotation": 1
    },
    {
      "x": -5,
      "y": 30,
      "z": 5,
      "name": "Plant_Leaves_Azure",
      "rotation": 1
    },
    {
      "x": -5,
      "y": 31,
      "z": 5,
      "name": "Plant_Leaves_Azure",
      "rotation": 1
    },
    {
      "x": -5,
      "y": 32,
      "z": 5,
      "name": "Plant_Leaves_Azure",
      "rotation": 1
    },
    {
      "x": -5,
      "y": 30,
      "z": 6,
      "name": "Plant_Leaves_Azure",
      "rotation": 1
    },
    {
      "x": -5,
      "y": 31,
      "z": 6,
      "name": "Plant_Leaves_Azure",
      "rotation": 1
    },
    {
      "x": -4,
      "y": 27,
      "z": -7,
      "name": "Plant_Leaves_Azure",
      "rotation": 1
    },
    {
      "x": -4,
      "y": 15,
      "z": -6,
      "name": "Plant_Moss_Wall_Blue",
      "rotation": 3
    },
    {
      "x": -4,
      "y": 26,
      "z": -6,
      "name": "Plant_Leaves_Azure",
      "rotation": 1
    },
    {
      "x": -4,
      "y": 27,
      "z": -6,
      "name": "Plant_Leaves_Azure",
      "rotation": 1
    },
    {
      "x": -4,
      "y": 28,
      "z": -6,
      "name": "Plant_Leaves_Azure",
      "rotation": 1
    },
    {
      "x": -4,
      "y": 30,
      "z": -6,
      "name": "Plant_Leaves_Azure",
      "rotation": 1
    },
    {
      "x": -4,
      "y": 31,
      "z": -6,
      "name": "Plant_Leaves_Azure",
      "rotation": 1
    },
    {
      "x": -4,
      "y": 32,
      "z": -6,
      "name": "Plant_Leaves_Azure",
      "rotation": 1
    },
    {
      "x": -4,
      "y": 33,
      "z": -6,
      "name": "Plant_Leaves_Azure",
      "rotation": 1
    },
    {
      "x": -4,
      "y": 11,
      "z": -5,
      "name": "Plant_Moss_Wall_Blue",
      "rotation": 3
    },
    {
      "x": -4,
      "y": 12,
      "z": -5,
      "name": "Plant_Moss_Wall_Blue",
      "rotation": 3
    },
    {
      "x": -4,
      "y": 14,
      "z": -5,
      "name": "Plant_Moss_Wall_Blue",
      "rotation": 3
    },
    {
      "x": -4,
      "y": 15,
      "z": -5,
      "name": "Plant_Moss_Wall_Blue",
      "rotation": 3
    },
    {
      "x": -4,
      "y": 17,
      "z": -5,
      "name": "Plant_Moss_Wall_Blue",
      "rotation": 3
    },
    {
      "x": -4,
      "y": 27,
      "z": -5,
      "name": "Plant_Leaves_Azure",
      "rotation": 1
    },
    {
      "x": -4,
      "y": 31,
      "z": -5,
      "name": "Plant_Leaves_Azure",
      "rotation": 1
    },
    {
      "x": -4,
      "y": 32,
      "z": -5,
      "name": "Plant_Leaves_Azure",
      "rotation": 1
    },
    {
      "x": -4,
      "y": 33,
      "z": -5,
      "name": "Plant_Leaves_Azure",
      "rotation": 1
    },
    {
      "x": -4,
      "y": 34,
      "z": -5,
      "name": "Plant_Leaves_Azure",
      "rotation": 1
    },
    {
      "x": -4,
      "y": 35,
      "z": -5,
      "name": "Plant_Fruit_Azure",
      "rotation": 1
    },
    {
      "x": -4,
      "y": 8,
      "z": -4,
      "name": "Plant_Moss_Wall_Blue",
      "rotation": 3
    },
    {
      "x": -4,
      "y": 9,
      "z": -4,
      "name": "Plant_Moss_Wall_Blue",
      "rotation": 3
    },
    {
      "x": -4,
      "y": 12,
      "z": -4,
      "name": "Plant_Moss_Wall_Blue",
      "rotation": 3
    },
    {
      "x": -4,
      "y": 13,
      "z": -4,
      "name": "Plant_Moss_Wall_Blue",
      "rotation": 3
    },
    {
      "x": -4,
      "y": 16,
      "z": -4,
      "name": "Plant_Moss_Wall_Blue",
      "rotation": 3
    },
    {
      "x": -4,
      "y": 17,
      "z": -4,
      "name": "Plant_Moss_Wall_Blue",
      "rotation": 3
    },
    {
      "x": -4,
      "y": 21,
      "z": -4,
      "name": "Rock_Marble"
    },
    {
      "x": -4,
      "y": 22,
      "z": -4,
      "name": "Rock_Marble"
    },
    {
      "x": -4,
      "y": 23,
      "z": -4,
      "name": "Rock_Marble"
    },
    {
      "x": -4,
      "y": 32,
      "z": -4,
      "name": "Plant_Leaves_Azure",
      "rotation": 1
    },
    {
      "x": -4,
      "y": 33,
      "z": -4,
      "name": "Plant_Leaves_Azure",
      "rotation": 1
    },
    {
      "x": -4,
      "y": 34,
      "z": -4,
      "name": "Plant_Leaves_Azure",
      "rotation": 1
    },
    {
      "x": -4,
      "y": 7,
      "z": -3,
      "name": "Plant_Moss_Wall_Blue",
      "rotation": 3
    },
    {
      "x": -4,
      "y": 16,
      "z": -3,
      "name": "Plant_Moss_Wall_Blue",
      "rotation": 3
    },
    {
      "x": -4,
      "y": 21,
      "z": -3,
      "name": "Rock_Marble"
    },
    {
      "x": -4,
      "y": 22,
      "z": -3,
      "name": "Rock_Marble"
    },
    {
      "x": -4,
      "y": 23,
      "z": -3,
      "name": "Plant_Moss_Rug_Lime"
    },
    {
      "x": -4,
      "y": 25,
      "z": -3,
      "name": "Wood_Azure_Trunk_Full",
      "rotation": 1
    },
    {
      "x": -4,
      "y": 26,
      "z": -3,
      "name": "Wood_Azure_Trunk",
      "rotation": 1
    },
    {
      "x": -4,
      "y": 27,
      "z": -3,
      "name": "Wood_Azure_Trunk",
      "rotation": 1
    },
    {
      "x": -4,
      "y": 28,
      "z": -3,
      "name": "Wood_Azure_Trunk_Full",
      "rotation": 1
    },
    {
      "x": -4,
      "y": 30,
      "z": -3,
      "name": "Plant_Moss_Wall_Blue",
      "rotation": 1
    },
    {
      "x": -4,
      "y": 32,
      "z": -3,
      "name": "Wood_Azure_Branch_Long",
      "rotation": 6
    },
    {
      "x": -4,
      "y": 33,
      "z": -3,
      "name": "Plant_Leaves_Azure",
      "rotation": 1
    },
    {
      "x": -4,
      "y": 34,
      "z": -3,
      "name": "Plant_Leaves_Azure",
      "rotation": 1
    },
    {
      "x": -4,
      "y": 36,
      "z": -3,
      "name": "Plant_Leaves_Azure",
      "rotation": 1
    },
    {
      "x": -4,
      "y": 37,
      "z": -3,
      "name": "Plant_Leaves_Azure",
      "rotation": 1
    },
    {
      "x": -4,
      "y": 39,
      "z": -3,
      "name": "Plant_Leaves_Azure",
      "rotation": 1
    },
    {
      "x": -4,
      "y": 40,
      "z": -3,
      "name": "Plant_Leaves_Azure",
      "rotation": 1
    },
    {
      "x": -4,
      "y": 15,
      "z": -2,
      "name": "Plant_Moss_Wall_Blue",
      "rotation": 3
    },
    {
      "x": -4,
      "y": 17,
      "z": -2,
      "name": "Plant_Moss_Wall_Blue",
      "rotation": 3
    },
    {
      "x": -4,
      "y": 21,
      "z": -2,
      "name": "Rock_Marble"
    },
    {
      "x": -4,
      "y": 22,
      "z": -2,
      "name": "Plant_Moss_Block_Blue"
    },
    {
      "x": -4,
      "y": 23,
      "z": -2,
      "name": "Wood_Azure_Trunk_Full",
      "rotation": 1
    },
    {
      "x": -4,
      "y": 24,
      "z": -2,
      "name": "Wood_Azure_Trunk",
      "rotation": 1
    },
    {
      "x": -4,
      "y": 25,
      "z": -2,
      "name": "Wood_Azure_Trunk",
      "rotation": 1
    },
    {
      "x": -4,
      "y": 26,
      "z": -2,
      "name": "Wood_Azure_Trunk_Full",
      "rotation": 1
    },
    {
      "x": -4,
      "y": 27,
      "z": -2,
      "name": "Wood_Azure_Trunk",
      "rotation": 1
    },
    {
      "x": -4,
      "y": 28,
      "z": -2,
      "name": "Wood_Azure_Trunk",
      "rotation": 1
    },
    {
      "x": -4,
      "y": 29,
      "z": -2,
      "name": "Wood_Azure_Trunk",
      "rotation": 1
    },
    {
      "x": -4,
      "y": 30,
      "z": -2,
      "name": "Wood_Azure_Trunk",
      "rotation": 1
    },
    {
      "x": -4,
      "y": 31,
      "z": -2,
      "name": "Wood_Azure_Trunk",
      "rotation": 1
    },
    {
      "x": -4,
      "y": 32,
      "z": -2,
      "name": "Wood_Azure_Trunk",
      "rotation": 1
    },
    {
      "x": -4,
      "y": 33,
      "z": -2,
      "name": "Wood_Azure_Trunk_Full",
      "rotation": 1
    },
    {
      "x": -4,
      "y": 34,
      "z": -2,
      "name": "Plant_Moss_Rug_Blue",
      "rotation": 1
    },
    {
      "x": -4,
      "y": 35,
      "z": -2,
      "name": "Wood_Azure_Branch_Long",
      "rotation": 5
    },
    {
      "x": -4,
      "y": 36,
      "z": -2,
      "name": "Plant_Leaves_Azure",
      "rotation": 1
    },
    {
      "x": -4,
      "y": 37,
      "z": -2,
      "name": "Plant_Leaves_Azure",
      "rotation": 1
    },
    {
      "x": -4,
      "y": 38,
      "z": -2,
      "name": "Plant_Fruit_Azure",
      "rotation": 1
    },
    {
      "x": -4,
      "y": 39,
      "z": -2,
      "name": "Plant_Leaves_Azure",
      "rotation": 1
    },
    {
      "x": -4,
      "y": 40,
      "z": -2,
      "name": "Plant_Leaves_Azure",
      "rotation": 1
    },
    {
      "x": -4,
      "y": 41,
      "z": -2,
      "name": "Plant_Leaves_Azure",
      "rotation": 1
    },
    {
      "x": -4,
      "y": 16,
      "z": -1,
      "name": "Rock_Marble"
    },
    {
      "x": -4,
      "y": 17,
      "z": -1,
      "name": "Rock_Marble"
    },
    {
      "x": -4,
      "y": 18,
      "z": -1,
      "name": "Rock_Marble"
    },
    {
      "x": -4,
      "y": 19,
      "z": -1,
      "name": "Rock_Marble"
    },
    {
      "x": -4,
      "y": 20,
      "z": -1,
      "name": "Rock_Marble"
    },
    {
      "x": -4,
      "y": 23,
      "z": -1,
      "name": "Wood_Azure_Trunk_Full",
      "rotation": 1
    },
    {
      "x": -4,
      "y": 24,
      "z": -1,
      "name": "Wood_Azure_Trunk",
      "rotation": 1
    },
    {
      "x": -4,
      "y": 25,
      "z": -1,
      "name": "Wood_Azure_Trunk",
      "rotation": 1
    },
    {
      "x": -4,
      "y": 26,
      "z": -1,
      "name": "Wood_Azure_Trunk",
      "rotation": 1
    },
    {
      "x": -4,
      "y": 27,
      "z": -1,
      "name": "Wood_Azure_Trunk",
      "rotation": 1
    },
    {
      "x": -4,
      "y": 28,
      "z": -1,
      "name": "Wood_Azure_Trunk",
      "rotation": 1
    },
    {
      "x": -4,
      "y": 29,
      "z": -1,
      "name": "Wood_Azure_Trunk",
      "rotation": 1
    },
    {
      "x": -4,
      "y": 30,
      "z": -1,
      "name": "Wood_Azure_Trunk_Full",
      "rotation": 1
    },
    {
      "x": -4,
      "y": 31,
      "z": -1,
      "name": "Wood_Azure_Trunk_Full",
      "rotation": 1
    },
    {
      "x": -4,
      "y": 33,
      "z": -1,
      "name": "Plant_Moss_Wall_Blue"
    },
    {
      "x": -4,
      "y": 34,
      "z": -1,
      "name": "Plant_Moss_Wall_Blue",
      "rotation": 1
    },
    {
      "x": -4,
      "y": 36,
      "z": -1,
      "name": "Wood_Azure_Branch_Long",
      "rotation": 5
    },
    {
      "x": -4,
      "y": 38,
      "z": -1,
      "name": "Wood_Azure_Branch_Long",
      "rotation": 5
    },
    {
      "x": -4,
      "y": 39,
      "z": -1,
      "name": "Plant_Leaves_Azure",
      "rotation": 1
    },
    {
      "x": -4,
      "y": 40,
      "z": -1,
      "name": "Plant_Leaves_Azure",
      "rotation": 1
    },
    {
      "x": -4,
      "y": 41,
      "z": -1,
      "name": "Plant_Leaves_Azure",
      "rotation": 1
    },
    {
      "x": -4,
      "y": 16,
      "z": 0,
      "name": "Rock_Marble"
    },
    {
      "x": -4,
      "y": 17,
      "z": 0,
      "name": "Rock_Marble"
    },
    {
      "x": -4,
      "y": 18,
      "z": 0,
      "name": "Rock_Marble"
    },
    {
      "x": -4,
      "y": 19,
      "z": 0,
      "name": "Rock_Marble"
    },
    {
      "x": -4,
      "y": 20,
      "z": 0,
      "name": "Rock_Marble"
    },
    {
      "x": -4,
      "y": 21,
      "z": 0,
      "name": "Plant_Moss_Block_Blue"
    },
    {
      "x": -4,
      "y": 22,
      "z": 0,
      "name": "Wood_Azure_Trunk_Full",
      "rotation": 1
    },
    {
      "x": -4,
      "y": 23,
      "z": 0,
      "name": "Wood_Azure_Trunk_Full",
      "rotation": 1
    },
    {
      "x": -4,
      "y": 24,
      "z": 0,
      "name": "Wood_Azure_Trunk_Full",
      "rotation": 1
    },
    {
      "x": -4,
      "y": 25,
      "z": 0,
      "name": "Wood_Azure_Trunk",
      "rotation": 1
    },
    {
      "x": -4,
      "y": 26,
      "z": 0,
      "name": "Wood_Azure_Trunk",
      "rotation": 1
    },
    {
      "x": -4,
      "y": 27,
      "z": 0,
      "name": "Wood_Azure_Trunk",
      "rotation": 1
    },
    {
      "x": -4,
      "y": 28,
      "z": 0,
      "name": "Wood_Azure_Trunk_Full",
      "rotation": 1
    },
    {
      "x": -4,
      "y": 29,
      "z": 0,
      "name": "Wood_Azure_Trunk_Full",
      "rotation": 1
    },
    {
      "x": -4,
      "y": 31,
      "z": 0,
      "name": "Wood_Azure_Branch_Corner"
    },
    {
      "x": -4,
      "y": 32,
      "z": 0,
      "name": "Wood_Azure_Branch_Corner",
      "rotation": 9
    },
    {
      "x": -4,
      "y": 36,
      "z": 0,
      "name": "Plant_Leaves_Azure",
      "rotation": 1
    },
    {
      "x": -4,
      "y": 37,
      "z": 0,
      "name": "Plant_Leaves_Azure",
      "rotation": 1
    },
    {
      "x": -4,
      "y": 38,
      "z": 0,
      "name": "Plant_Leaves_Azure",
      "rotation": 1
    },
    {
      "x": -4,
      "y": 39,
      "z": 0,
      "name": "Plant_Leaves_Azure",
      "rotation": 1
    },
    {
      "x": -4,
      "y": 40,
      "z": 0,
      "name": "Plant_Leaves_Azure",
      "rotation": 1
    },
    {
      "x": -4,
      "y": 41,
      "z": 0,
      "name": "Plant_Leaves_Azure",
      "rotation": 1
    },
    {
      "x": -4,
      "y": 14,
      "z": 1,
      "name": "Rock_Marble_Stalactite_Large",
      "filler": 31744,
      "rotation": 8
    },
    {
      "x": -4,
      "y": 15,
      "z": 1,
      "name": "Rock_Marble_Stalactite_Large",
      "rotation": 8
    },
    {
      "x": -4,
      "y": 16,
      "z": 1,
      "name": "Rock_Marble"
    },
    {
      "x": -4,
      "y": 17,
      "z": 1,
      "name": "Rock_Marble"
    },
    {
      "x": -4,
      "y": 18,
      "z": 1,
      "name": "Rock_Marble"
    },
    {
      "x": -4,
      "y": 19,
      "z": 1,
      "name": "Rock_Marble"
    },
    {
      "x": -4,
      "y": 20,
      "z": 1,
      "name": "Rock_Marble"
    },
    {
      "x": -4,
      "y": 21,
      "z": 1,
      "name": "Plant_Moss_Block_Blue"
    },
    {
      "x": -4,
      "y": 22,
      "z": 1,
      "name": "Plant_Moss_Short_Green_Dark"
    },
    {
      "x": -4,
      "y": 29,
      "z": 1,
      "name": "Wood_Azure_Trunk_Full",
      "rotation": 1
    },
    {
      "x": -4,
      "y": 30,
      "z": 1,
      "name": "Plant_Moss_Rug_Blue",
      "rotation": 1
    },
    {
      "x": -4,
      "y": 33,
      "z": 1,
      "name": "Wood_Azure_Branch_Long",
      "rotation": 5
    },
    {
      "x": -4,
      "y": 34,
      "z": 1,
      "name": "Plant_Leaves_Azure",
      "rotation": 1
    },
    {
      "x": -4,
      "y": 35,
      "z": 1,
      "name": "Plant_Leaves_Azure",
      "rotation": 1
    },
    {
      "x": -4,
      "y": 36,
      "z": 1,
      "name": "Plant_Leaves_Azure",
      "rotation": 1
    },
    {
      "x": -4,
      "y": 37,
      "z": 1,
      "name": "Plant_Leaves_Azure",
      "rotation": 1
    },
    {
      "x": -4,
      "y": 38,
      "z": 1,
      "name": "Plant_Leaves_Azure",
      "rotation": 1
    },
    {
      "x": -4,
      "y": 39,
      "z": 1,
      "name": "Plant_Leaves_Azure",
      "rotation": 1
    },
    {
      "x": -4,
      "y": 40,
      "z": 1,
      "name": "Plant_Leaves_Azure",
      "rotation": 1
    },
    {
      "x": -4,
      "y": 41,
      "z": 1,
      "name": "Plant_Leaves_Azure",
      "rotation": 1
    },
    {
      "x": -4,
      "y": 42,
      "z": 1,
      "name": "Plant_Fruit_Azure",
      "rotation": 1
    },
    {
      "x": -4,
      "y": 16,
      "z": 2,
      "name": "Rock_Marble"
    },
    {
      "x": -4,
      "y": 17,
      "z": 2,
      "name": "Rock_Marble_Cobble"
    },
    {
      "x": -4,
      "y": 18,
      "z": 2,
      "name": "Rock_Marble"
    },
    {
      "x": -4,
      "y": 19,
      "z": 2,
      "name": "Rock_Marble"
    },
    {
      "x": -4,
      "y": 20,
      "z": 2,
      "name": "Rock_Marble"
    },
    {
      "x": -4,
      "y": 21,
      "z": 2,
      "name": "Plant_Moss_Block_Blue"
    },
    {
      "x": -4,
      "y": 22,
      "z": 2,
      "name": "Plant_Moss_Rug_Lime"
    },
    {
      "x": -4,
      "y": 29,
      "z": 2,
      "name": "Wood_Azure_Branch_Long",
      "rotation": 6
    },
    {
      "x": -4,
      "y": 30,
      "z": 2,
      "name": "Plant_Moss_Wall_Blue",
      "rotation": 1
    },
    {
      "x": -4,
      "y": 34,
      "z": 2,
      "name": "Plant_Leaves_Azure",
      "rotation": 1
    },
    {
      "x": -4,
      "y": 35,
      "z": 2,
      "name": "Plant_Leaves_Azure",
      "rotation": 1
    },
    {
      "x": -4,
      "y": 36,
      "z": 2,
      "name": "Plant_Leaves_Azure",
      "rotation": 1
    },
    {
      "x": -4,
      "y": 37,
      "z": 2,
      "name": "Plant_Leaves_Azure",
      "rotation": 1
    },
    {
      "x": -4,
      "y": 38,
      "z": 2,
      "name": "Plant_Leaves_Azure",
      "rotation": 1
    },
    {
      "x": -4,
      "y": 39,
      "z": 2,
      "name": "Plant_Leaves_Azure",
      "rotation": 1
    },
    {
      "x": -4,
      "y": 40,
      "z": 2,
      "name": "Plant_Leaves_Azure",
      "rotation": 1
    },
    {
      "x": -4,
      "y": 16,
      "z": 3,
      "name": "Rock_Marble"
    },
    {
      "x": -4,
      "y": 17,
      "z": 3,
      "name": "Rock_Marble"
    },
    {
      "x": -4,
      "y": 18,
      "z": 3,
      "name": "Rock_Marble"
    },
    {
      "x": -4,
      "y": 19,
      "z": 3,
      "name": "Plant_Moss_Block_Blue"
    },
    {
      "x": -4,
      "y": 20,
      "z": 3,
      "name": "Plant_Moss_Rug_Lime"
    },
    {
      "x": -4,
      "y": 28,
      "z": 3,
      "name": "Plant_Leaves_Azure",
      "rotation": 1
    },
    {
      "x": -4,
      "y": 29,
      "z": 3,
      "name": "Plant_Leaves_Azure",
      "rotation": 1
    },
    {
      "x": -4,
      "y": 30,
      "z": 3,
      "name": "Plant_Leaves_Azure",
      "rotation": 1
    },
    {
      "x": -4,
      "y": 31,
      "z": 3,
      "name": "Plant_Leaves_Azure",
      "rotation": 1
    },
    {
      "x": -4,
      "y": 32,
      "z": 3,
      "name": "Plant_Leaves_Azure",
      "rotation": 1
    },
    {
      "x": -4,
      "y": 33,
      "z": 3,
      "name": "Plant_Leaves_Azure",
      "rotation": 1
    },
    {
      "x": -4,
      "y": 35,
      "z": 3,
      "name": "Plant_Leaves_Azure",
      "rotation": 1
    },
    {
      "x": -4,
      "y": 36,
      "z": 3,
      "name": "Plant_Leaves_Azure",
      "rotation": 1
    },
    {
      "x": -4,
      "y": 37,
      "z": 3,
      "name": "Plant_Leaves_Azure",
      "rotation": 1
    },
    {
      "x": -4,
      "y": 38,
      "z": 3,
      "name": "Plant_Leaves_Azure",
      "rotation": 1
    },
    {
      "x": -4,
      "y": 16,
      "z": 4,
      "name": "Rock_Marble"
    },
    {
      "x": -4,
      "y": 17,
      "z": 4,
      "name": "Rock_Marble"
    },
    {
      "x": -4,
      "y": 18,
      "z": 4,
      "name": "Rock_Marble"
    },
    {
      "x": -4,
      "y": 19,
      "z": 4,
      "name": "Rock_Marble"
    },
    {
      "x": -4,
      "y": 20,
      "z": 4,
      "name": "Plant_Moss_Rug_Lime"
    },
    {
      "x": -4,
      "y": 28,
      "z": 4,
      "name": "Plant_Leaves_Azure",
      "rotation": 1
    },
    {
      "x": -4,
      "y": 29,
      "z": 4,
      "name": "Plant_Leaves_Azure",
      "rotation": 1
    },
    {
      "x": -4,
      "y": 30,
      "z": 4,
      "name": "Plant_Leaves_Azure",
      "rotation": 1
    },
    {
      "x": -4,
      "y": 31,
      "z": 4,
      "name": "Plant_Leaves_Azure",
      "rotation": 1
    },
    {
      "x": -4,
      "y": 32,
      "z": 4,
      "name": "Plant_Leaves_Azure",
      "rotation": 1
    },
    {
      "x": -4,
      "y": 29,
      "z": 5,
      "name": "Plant_Leaves_Azure",
      "rotation": 1
    },
    {
      "x": -4,
      "y": 30,
      "z": 5,
      "name": "Plant_Leaves_Azure",
      "rotation": 1
    },
    {
      "x": -4,
      "y": 31,
      "z": 5,
      "name": "Plant_Leaves_Azure",
      "rotation": 1
    },
    {
      "x": -4,
      "y": 32,
      "z": 5,
      "name": "Plant_Leaves_Azure",
      "rotation": 1
    },
    {
      "x": -4,
      "y": 33,
      "z": 5,
      "name": "Plant_Fruit_Azure",
      "rotation": 1
    },
    {
      "x": -4,
      "y": 16,
      "z": 6,
      "name": "Plant_Moss_Wall_Blue",
      "rotation": 3
    },
    {
      "x": -4,
      "y": 30,
      "z": 6,
      "name": "Plant_Leaves_Azure",
      "rotation": 1
    },
    {
      "x": -4,
      "y": 31,
      "z": 6,
      "name": "Plant_Leaves_Azure",
      "rotation": 1
    },
    {
      "x": -3,
      "y": 13,
      "z": -7,
      "name": "Plant_Moss_Wall_Blue",
      "rotation": 3
    },
    {
      "x": -3,
      "y": 15,
      "z": -6,
      "name": "Rock_Marble"
    },
    {
      "x": -3,
      "y": 16,
      "z": -6,
      "name": "Rock_Marble"
    },
    {
      "x": -3,
      "y": 17,
      "z": -6,
      "name": "Rock_Marble"
    },
    {
      "x": -3,
      "y": 18,
      "z": -6,
      "name": "Rock_Marble_Cobble"
    },
    {
      "x": -3,
      "y": 19,
      "z": -6,
      "name": "Rock_Marble"
    },
    {
      "x": -3,
      "y": 22,
      "z": -6,
      "name": "Plant_Moss_Wall_Blue",
      "rotation": 3
    },
    {
      "x": -3,
      "y": 23,
      "z": -6,
      "name": "Plant_Moss_Wall_Blue",
      "rotation": 3
    },
    {
      "x": -3,
      "y": 30,
      "z": -6,
      "name": "Plant_Leaves_Azure",
      "rotation": 1
    },
    {
      "x": -3,
      "y": 31,
      "z": -6,
      "name": "Plant_Leaves_Azure",
      "rotation": 1
    },
    {
      "x": -3,
      "y": 32,
      "z": -6,
      "name": "Plant_Leaves_Azure",
      "rotation": 1
    },
    {
      "x": -3,
      "y": 8,
      "z": -5,
      "name": "Rock_Marble"
    },
    {
      "x": -3,
      "y": 9,
      "z": -5,
      "name": "Rock_Marble"
    },
    {
      "x": -3,
      "y": 10,
      "z": -5,
      "name": "Rock_Marble"
    },
    {
      "x": -3,
      "y": 11,
      "z": -5,
      "name": "Rock_Marble"
    },
    {
      "x": -3,
      "y": 12,
      "z": -5,
      "name": "Rock_Marble"
    },
    {
      "x": -3,
      "y": 13,
      "z": -5,
      "name": "Rock_Marble"
    },
    {
      "x": -3,
      "y": 14,
      "z": -5,
      "name": "Rock_Marble"
    },
    {
      "x": -3,
      "y": 15,
      "z": -5,
      "name": "Rock_Marble_Cobble"
    },
    {
      "x": -3,
      "y": 16,
      "z": -5,
      "name": "Rock_Marble"
    },
    {
      "x": -3,
      "y": 17,
      "z": -5,
      "name": "Rock_Marble"
    },
    {
      "x": -3,
      "y": 18,
      "z": -5,
      "name": "Rock_Marble"
    },
    {
      "x": -3,
      "y": 19,
      "z": -5,
      "name": "Rock_Marble"
    },
    {
      "x": -3,
      "y": 21,
      "z": -5,
      "name": "Rock_Marble"
    },
    {
      "x": -3,
      "y": 22,
      "z": -5,
      "name": "Rock_Marble"
    },
    {
      "x": -3,
      "y": 23,
      "z": -5,
      "name": "Rock_Marble"
    },
    {
      "x": -3,
      "y": 31,
      "z": -5,
      "name": "Plant_Leaves_Azure",
      "rotation": 1
    },
    {
      "x": -3,
      "y": 32,
      "z": -5,
      "name": "Plant_Leaves_Azure",
      "rotation": 1
    },
    {
      "x": -3,
      "y": 33,
      "z": -5,
      "name": "Plant_Leaves_Azure",
      "rotation": 1
    },
    {
      "x": -3,
      "y": 5,
      "z": -4,
      "name": "Rock_Marble"
    },
    {
      "x": -3,
      "y": 6,
      "z": -4,
      "name": "Rock_Marble"
    },
    {
      "x": -3,
      "y": 7,
      "z": -4,
      "name": "Rock_Marble_Cobble"
    },
    {
      "x": -3,
      "y": 8,
      "z": -4,
      "name": "Rock_Marble"
    },
    {
      "x": -3,
      "y": 9,
      "z": -4,
      "name": "Rock_Marble"
    },
    {
      "x": -3,
      "y": 10,
      "z": -4,
      "name": "Rock_Marble"
    },
    {
      "x": -3,
      "y": 11,
      "z": -4,
      "name": "Rock_Marble"
    },
    {
      "x": -3,
      "y": 12,
      "z": -4,
      "name": "Rock_Marble"
    },
    {
      "x": -3,
      "y": 13,
      "z": -4,
      "name": "Rock_Marble"
    },
    {
      "x": -3,
      "y": 14,
      "z": -4,
      "name": "Rock_Marble"
    },
    {
      "x": -3,
      "y": 15,
      "z": -4,
      "name": "Rock_Marble"
    },
    {
      "x": -3,
      "y": 16,
      "z": -4,
      "name": "Rock_Marble"
    },
    {
      "x": -3,
      "y": 17,
      "z": -4,
      "name": "Rock_Marble"
    },
    {
      "x": -3,
      "y": 18,
      "z": -4,
      "name": "Rock_Marble"
    },
    {
      "x": -3,
      "y": 19,
      "z": -4,
      "name": "Rock_Marble_Cobble"
    },
    {
      "x": -3,
      "y": 20,
      "z": -4,
      "name": "Rock_Marble"
    },
    {
      "x": -3,
      "y": 21,
      "z": -4,
      "name": "Rock_Marble"
    },
    {
      "x": -3,
      "y": 22,
      "z": -4,
      "name": "Rock_Marble"
    },
    {
      "x": -3,
      "y": 23,
      "z": -4,
      "name": "Plant_Moss_Rug_Lime"
    },
    {
      "x": -3,
      "y": 24,
      "z": -4,
      "name": "Plant_Moss_Wall_Blue",
      "rotation": 3
    },
    {
      "x": -3,
      "y": 30,
      "z": -4,
      "name": "Plant_Leaves_Azure",
      "rotation": 1
    },
    {
      "x": -3,
      "y": 31,
      "z": -4,
      "name": "Plant_Leaves_Azure",
      "rotation": 1
    },
    {
      "x": -3,
      "y": 32,
      "z": -4,
      "name": "Plant_Leaves_Azure",
      "rotation": 1
    },
    {
      "x": -3,
      "y": 33,
      "z": -4,
      "name": "Plant_Leaves_Azure",
      "rotation": 1
    },
    {
      "x": -3,
      "y": 34,
      "z": -4,
      "name": "Plant_Leaves_Azure",
      "rotation": 1
    },
    {
      "x": -3,
      "y": 35,
      "z": -4,
      "name": "Plant_Fruit_Azure",
      "rotation": 1
    },
    {
      "x": -3,
      "y": 36,
      "z": -4,
      "name": "Plant_Leaves_Azure",
      "rotation": 1
    },
    {
      "x": -3,
      "y": 5,
      "z": -3,
      "name": "Rock_Marble_Cobble"
    },
    {
      "x": -3,
      "y": 6,
      "z": -3,
      "name": "Rock_Marble_Cobble"
    },
    {
      "x": -3,
      "y": 7,
      "z": -3,
      "name": "Rock_Marble"
    },
    {
      "x": -3,
      "y": 8,
      "z": -3,
      "name": "Rock_Marble"
    },
    {
      "x": -3,
      "y": 9,
      "z": -3,
      "name": "Rock_Marble"
    },
    {
      "x": -3,
      "y": 10,
      "z": -3,
      "name": "Rock_Marble"
    },
    {
      "x": -3,
      "y": 12,
      "z": -3,
      "name": "Rock_Marble_Stalactite_Large",
      "filler": 31744,
      "rotation": 8
    },
    {
      "x": -3,
      "y": 13,
      "z": -3,
      "name": "Rock_Marble_Stalactite_Large",
      "rotation": 8
    },
    {
      "x": -3,
      "y": 14,
      "z": -3,
      "name": "Rock_Marble"
    },
    {
      "x": -3,
      "y": 15,
      "z": -3,
      "name": "Rock_Marble"
    },
    {
      "x": -3,
      "y": 16,
      "z": -3,
      "name": "Rock_Marble"
    },
    {
      "x": -3,
      "y": 17,
      "z": -3,
      "name": "Rock_Marble"
    },
    {
      "x": -3,
      "y": 18,
      "z": -3,
      "name": "Rock_Marble"
    },
    {
      "x": -3,
      "y": 19,
      "z": -3,
      "name": "Rock_Marble_Cobble"
    },
    {
      "x": -3,
      "y": 20,
      "z": -3,
      "name": "Rock_Marble"
    },
    {
      "x": -3,
      "y": 21,
      "z": -3,
      "name": "Rock_Marble"
    },
    {
      "x": -3,
      "y": 22,
      "z": -3,
      "name": "Wood_Azure_Trunk_Full",
      "rotation": 1
    },
    {
      "x": -3,
      "y": 23,
      "z": -3,
      "name": "Wood_Azure_Trunk_Full",
      "rotation": 1
    },
    {
      "x": -3,
      "y": 24,
      "z": -3,
      "name": "Wood_Azure_Trunk",
      "rotation": 1
    },
    {
      "x": -3,
      "y": 25,
      "z": -3,
      "name": "Wood_Azure_Trunk_Full",
      "rotation": 1
    },
    {
      "x": -3,
      "y": 31,
      "z": -3,
      "name": "Plant_Leaves_Azure",
      "rotation": 1
    },
    {
      "x": -3,
      "y": 32,
      "z": -3,
      "name": "Plant_Leaves_Azure",
      "rotation": 1
    },
    {
      "x": -3,
      "y": 33,
      "z": -3,
      "name": "Plant_Leaves_Azure",
      "rotation": 1
    },
    {
      "x": -3,
      "y": 35,
      "z": -3,
      "name": "Plant_Leaves_Azure",
      "rotation": 1
    },
    {
      "x": -3,
      "y": 36,
      "z": -3,
      "name": "Plant_Leaves_Azure",
      "rotation": 1
    },
    {
      "x": -3,
      "y": 37,
      "z": -3,
      "name": "Plant_Fruit_Azure",
      "rotation": 1
    },
    {
      "x": -3,
      "y": 39,
      "z": -3,
      "name": "Plant_Leaves_Azure",
      "rotation": 1
    },
    {
      "x": -3,
      "y": 5,
      "z": -2,
      "name": "Plant_Crop_Mushroom_Block_Blue_Mycelium"
    },
    {
      "x": -3,
      "y": 6,
      "z": -2,
      "name": "Rock_Marble"
    },
    {
      "x": -3,
      "y": 7,
      "z": -2,
      "name": "Rock_Marble"
    },
    {
      "x": -3,
      "y": 8,
      "z": -2,
      "name": "Rock_Marble"
    },
    {
      "x": -3,
      "y": 9,
      "z": -2,
      "name": "Rock_Marble"
    },
    {
      "x": -3,
      "y": 10,
      "z": -2,
      "name": "Rock_Marble_Cobble"
    },
    {
      "x": -3,
      "y": 11,
      "z": -2,
      "name": "Rock_Marble_Cobble"
    },
    {
      "x": -3,
      "y": 15,
      "z": -2,
      "name": "Rock_Marble_Cobble"
    },
    {
      "x": -3,
      "y": 16,
      "z": -2,
      "name": "Rock_Marble"
    },
    {
      "x": -3,
      "y": 17,
      "z": -2,
      "name": "Rock_Marble"
    },
    {
      "x": -3,
      "y": 18,
      "z": -2,
      "name": "Rock_Marble"
    },
    {
      "x": -3,
      "y": 19,
      "z": -2,
      "name": "Rock_Marble"
    },
    {
      "x": -3,
      "y": 20,
      "z": -2,
      "name": "Rock_Marble"
    },
    {
      "x": -3,
      "y": 21,
      "z": -2,
      "name": "Wood_Azure_Roots",
      "rotation": 1
    },
    {
      "x": -3,
      "y": 22,
      "z": -2,
      "name": "Wood_Azure_Trunk_Full",
      "rotation": 1
    },
    {
      "x": -3,
      "y": 23,
      "z": -2,
      "name": "Wood_Azure_Trunk",
      "rotation": 1
    },
    {
      "x": -3,
      "y": 24,
      "z": -2,
      "name": "Wood_Azure_Trunk_Full",
      "rotation": 1
    },
    {
      "x": -3,
      "y": 25,
      "z": -2,
      "name": "Wood_Azure_Trunk",
      "rotation": 1
    },
    {
      "x": -3,
      "y": 26,
      "z": -2,
      "name": "Wood_Azure_Trunk",
      "rotation": 1
    },
    {
      "x": -3,
      "y": 27,
      "z": -2,
      "name": "Wood_Azure_Trunk",
      "rotation": 1
    },
    {
      "x": -3,
      "y": 28,
      "z": -2,
      "name": "Wood_Azure_Trunk",
      "rotation": 1
    },
    {
      "x": -3,
      "y": 29,
      "z": -2,
      "name": "Wood_Azure_Trunk_Full",
      "rotation": 1
    },
    {
      "x": -3,
      "y": 32,
      "z": -2,
      "name": "Plant_Leaves_Azure",
      "rotation": 1
    },
    {
      "x": -3,
      "y": 33,
      "z": -2,
      "name": "Plant_Moss_Wall_Blue",
      "rotation": 1
    },
    {
      "x": -3,
      "y": 35,
      "z": -2,
      "name": "Wood_Azure_Branch_Long",
      "rotation": 5
    },
    {
      "x": -3,
      "y": 36,
      "z": -2,
      "name": "Plant_Leaves_Azure",
      "rotation": 1
    },
    {
      "x": -3,
      "y": 37,
      "z": -2,
      "name": "Plant_Leaves_Azure",
      "rotation": 1
    },
    {
      "x": -3,
      "y": 38,
      "z": -2,
      "name": "Plant_Leaves_Azure",
      "rotation": 1
    },
    {
      "x": -3,
      "y": 39,
      "z": -2,
      "name": "Plant_Leaves_Azure",
      "rotation": 1
    },
    {
      "x": -3,
      "y": 40,
      "z": -2,
      "name": "Plant_Leaves_Azure",
      "rotation": 1
    },
    {
      "x": -3,
      "y": 8,
      "z": -1,
      "name": "Rock_Marble_Stalactite_Small",
      "rotation": 8
    },
    {
      "x": -3,
      "y": 9,
      "z": -1,
      "name": "Rock_Marble"
    },
    {
      "x": -3,
      "y": 10,
      "z": -1,
      "name": "Rock_Marble"
    },
    {
      "x": -3,
      "y": 11,
      "z": -1,
      "name": "Rock_Marble"
    },
    {
      "x": -3,
      "y": 12,
      "z": -1,
      "name": "Rock_Marble"
    },
    {
      "x": -3,
      "y": 13,
      "z": -1,
      "name": "Plant_Moss_Wall_Blue",
      "rotation": 3
    },
    {
      "x": -3,
      "y": 17,
      "z": -1,
      "name": "Rock_Marble"
    },
    {
      "x": -3,
      "y": 18,
      "z": -1,
      "name": "Rock_Marble"
    },
    {
      "x": -3,
      "y": 19,
      "z": -1,
      "name": "Rock_Marble"
    },
    {
      "x": -3,
      "y": 20,
      "z": -1,
      "name": "Rock_Marble"
    },
    {
      "x": -3,
      "y": 21,
      "z": -1,
