{
  "version": 8,
  "blockIdVersion": 11,
  "anchorX": 0,
  "anchorY": 0,
  "anchorZ": 0,
  "blocks": [
    {
      "x": -23,
      "y": 33,
      "z": -9,
      "name": "Plant_Leaves_Azure",
      "rotation": 1
    },
    {
      "x": -23,
      "y": 34,
      "z": -9,
      "name": "Plant_Leaves_Azure",
      "rotation": 1
    },
    {
      "x": -23,
      "y": 35,
      "z": -9,
      "name": "Plant_Leaves_Azure",
      "rotation": 1
    },
    {
      "x": -23,
      "y": 33,
      "z": -8,
      "name": "Plant_Leaves_Azure",
      "rotation": 1
    },
    {
      "x": -23,
      "y": 34,
      "z": -8,
      "name": "Plant_Leaves_Azure",
      "rotation": 1
    },
    {
      "x": -23,
      "y": 35,
      "z": -8,
      "name": "Plant_Leaves_Azure",
      "rotation": 1
    },
    {
      "x": -23,
      "y": 36,
      "z": -8,
      "name": "Plant_Leaves_Azure",
      "rotation": 1
    },
    {
      "x": -23,
      "y": 33,
      "z": -7,
      "name": "Plant_Leaves_Azure",
      "rotation": 1
    },
    {
      "x": -23,
      "y": 34,
      "z": -7,
      "name": "Plant_Leaves_Azure",
      "rotation": 1
    },
    {
      "x": -23,
      "y": 35,
      "z": -7,
      "name": "Plant_Leaves_Azure",
      "rotation": 1
    },
    {
      "x": -23,
      "y": 36,
      "z": -7,
      "name": "Plant_Leaves_Azure",
      "rotation": 1
    },
    {
      "x": -23,
      "y": 34,
      "z": -6,
      "name": "Plant_Leaves_Azure",
      "rotation": 1
    },
    {
      "x": -23,
      "y": 35,
      "z": -6,
      "name": "Plant_Leaves_Azure",
      "rotation": 1
    },
    {
      "x": -23,
      "y": 36,
      "z": -6,
      "name": "Plant_Leaves_Azure",
      "rotation": 1
    },
    {
      "x": -23,
      "y": 37,
      "z": -6,
      "name": "Plant_Leaves_Azure",
      "rotation": 1
    },
    {
      "x": -23,
      "y": 35,
      "z": -5,
      "name": "Plant_Leaves_Azure",
      "rotation": 1
    },
    {
      "x": -23,
      "y": 36,
      "z": -5,
      "name": "Plant_Leaves_Azure",
      "rotation": 1
    },
    {
      "x": -23,
      "y": 37,
      "z": -5,
      "name": "Plant_Leaves_Azure",
      "rotation": 1
    },
    {
      "x": -22,
      "y": 33,
      "z": -10,
      "name": "Plant_Leaves_Azure",
      "rotation": 1
    },
    {
      "x": -22,
      "y": 34,
      "z": -10,
      "name": "Plant_Leaves_Azure",
      "rotation": 1
    },
    {
      "x": -22,
      "y": 35,
      "z": -10,
      "name": "Plant_Leaves_Azure",
      "rotation": 1
    },
    {
      "x": -22,
      "y": 32,
      "z": -9,
      "name": "Plant_Leaves_Azure",
      "rotation": 1
    },
    {
      "x": -22,
      "y": 33,
      "z": -9,
      "name": "Plant_Leaves_Azure",
      "rotation": 1
    },
    {
      "x": -22,
      "y": 34,
      "z": -9,
      "name": "Plant_Leaves_Azure",
      "rotation": 1
    },
    {
      "x": -22,
      "y": 35,
      "z": -9,
      "name": "Plant_Leaves_Azure",
      "rotation": 1
    },
    {
      "x": -22,
      "y": 36,
      "z": -9,
      "name": "Plant_Leaves_Azure",
      "rotation": 1
    },
    {
      "x": -22,
      "y": 32,
      "z": -8,
      "name": "Plant_Leaves_Azure",
      "rotation": 1
    },
    {
      "x": -22,
      "y": 33,
      "z": -8,
      "name": "Plant_Leaves_Azure",
      "rotation": 1
    },
    {
      "x": -22,
      "y": 34,
      "z": -8,
      "name": "Plant_Leaves_Azure",
      "rotation": 1
    },
    {
      "x": -22,
      "y": 35,
      "z": -8,
      "name": "Plant_Leaves_Azure",
      "rotation": 1
    },
    {
      "x": -22,
      "y": 36,
      "z": -8,
      "name": "Plant_Leaves_Azure",
      "rotation": 1
    },
    {
      "x": -22,
      "y": 37,
      "z": -8,
      "name": "Plant_Leaves_Azure",
      "rotation": 1
    },
    {
      "x": -22,
      "y": 33,
      "z": -7,
      "name": "Plant_Leaves_Azure",
      "rotation": 1
    },
    {
      "x": -22,
      "y": 34,
      "z": -7,
      "name": "Plant_Leaves_Azure",
      "rotation": 1
    },
    {
      "x": -22,
      "y": 35,
      "z": -7,
      "name": "Plant_Leaves_Azure",
      "rotation": 1
    },
    {
      "x": -22,
      "y": 36,
      "z": -7,
      "name": "Plant_Leaves_Azure",
      "rotation": 1
    },
    {
      "x": -22,
      "y": 37,
      "z": -7,
      "name": "Plant_Leaves_Azure",
      "rotation": 1
    },
    {
      "x": -22,
      "y": 38,
      "z": -7,
      "name": "Plant_Fruit_Azure",
      "rotation": 1
    },
    {
      "x": -22,
      "y": 33,
      "z": -6,
      "name": "Plant_Leaves_Azure",
      "rotation": 1
    },
    {
      "x": -22,
      "y": 34,
      "z": -6,
      "name": "Plant_Leaves_Azure",
      "rotation": 1
    },
    {
      "x": -22,
      "y": 35,
      "z": -6,
      "name": "Plant_Leaves_Azure",
      "rotation": 1
    },
    {
      "x": -22,
      "y": 36,
      "z": -6,
      "name": "Plant_Leaves_Azure",
      "rotation": 1
    },
    {
      "x": -22,
      "y": 37,
      "z": -6,
      "name": "Plant_Leaves_Azure",
      "rotation": 1
    },
    {
      "x": -22,
      "y": 38,
      "z": -6,
      "name": "Plant_Leaves_Azure",
      "rotation": 1
    },
    {
      "x": -22,
      "y": 34,
      "z": -5,
      "name": "Plant_Leaves_Azure",
      "rotation": 1
    },
    {
      "x": -22,
      "y": 35,
      "z": -5,
      "name": "Plant_Leaves_Azure",
      "rotation": 1
    },
    {
      "x": -22,
      "y": 36,
      "z": -5,
      "name": "Plant_Leaves_Azure",
      "rotation": 1
    },
    {
      "x": -22,
      "y": 37,
      "z": -5,
      "name": "Plant_Leaves_Azure",
      "rotation": 1
    },
    {
      "x": -22,
      "y": 38,
      "z": -5,
      "name": "Plant_Leaves_Azure",
      "rotation": 1
    },
    {
      "x": -22,
      "y": 35,
      "z": -4,
      "name": "Plant_Leaves_Azure",
      "rotation": 1
    },
    {
      "x": -22,
      "y": 36,
      "z": -4,
      "name": "Plant_Leaves_Azure",
      "rotation": 1
    },
    {
      "x": -22,
      "y": 37,
      "z": -4,
      "name": "Plant_Leaves_Azure",
      "rotation": 1
    },
    {
      "x": -22,
      "y": 38,
      "z": -4,
      "name": "Plant_Leaves_Azure",
      "rotation": 1
    },
    {
      "x": -21,
      "y": 32,
      "z": -11,
      "name": "Plant_Leaves_Azure",
      "rotation": 1
    },
    {
      "x": -21,
      "y": 33,
      "z": -11,
      "name": "Plant_Leaves_Azure",
      "rotation": 1
    },
    {
      "x": -21,
      "y": 34,
      "z": -11,
      "name": "Plant_Leaves_Azure",
      "rotation": 1
    },
    {
      "x": -21,
      "y": 32,
      "z": -10,
      "name": "Plant_Leaves_Azure",
      "rotation": 1
    },
    {
      "x": -21,
      "y": 33,
      "z": -10,
      "name": "Plant_Leaves_Azure",
      "rotation": 1
    },
    {
      "x": -21,
      "y": 34,
      "z": -10,
      "name": "Plant_Leaves_Azure",
      "rotation": 1
    },
    {
      "x": -21,
      "y": 35,
      "z": -10,
      "name": "Plant_Leaves_Azure",
      "rotation": 1
    },
    {
      "x": -21,
      "y": 36,
      "z": -10,
      "name": "Plant_Leaves_Azure",
      "rotation": 1
    },
    {
      "x": -21,
      "y": 33,
      "z": -9,
      "name": "Plant_Leaves_Azure",
      "rotation": 1
    },
    {
      "x": -21,
      "y": 34,
      "z": -9,
      "name": "Plant_Leaves_Azure",
      "rotation": 1
    },
    {
      "x": -21,
      "y": 35,
      "z": -9,
      "name": "Plant_Leaves_Azure",
      "rotation": 1
    },
    {
      "x": -21,
      "y": 36,
      "z": -9,
      "name": "Plant_Leaves_Azure",
      "rotation": 1
    },
    {
      "x": -21,
      "y": 37,
      "z": -9,
      "name": "Plant_Fruit_Azure",
      "rotation": 1
    },
    {
      "x": -21,
      "y": 34,
      "z": -8,
      "name": "Plant_Leaves_Azure",
      "rotation": 1
    },
    {
      "x": -21,
      "y": 35,
      "z": -8,
      "name": "Plant_Leaves_Azure",
      "rotation": 1
    },
    {
      "x": -21,
      "y": 36,
      "z": -8,
      "name": "Plant_Leaves_Azure",
      "rotation": 1
    },
    {
      "x": -21,
      "y": 34,
      "z": -7,
      "name": "Plant_Leaves_Azure",
      "rotation": 1
    },
    {
      "x": -21,
      "y": 35,
      "z": -7,
      "name": "Wood_Azure_Branch_Long",
      "rotation": 5
    },
    {
      "x": -21,
      "y": 36,
      "z": -7,
      "name": "Plant_Leaves_Azure",
      "rotation": 1
    },
    {
      "x": -21,
      "y": 37,
      "z": -7,
      "name": "Plant_Leaves_Azure",
      "rotation": 1
    },
    {
      "x": -21,
      "y": 35,
      "z": -6,
      "name": "Plant_Leaves_Azure",
      "rotation": 1
    },
    {
      "x": -21,
      "y": 36,
      "z": -6,
      "name": "Plant_Leaves_Azure",
      "rotation": 1
    },
    {
      "x": -21,
      "y": 37,
      "z": -6,
      "name": "Wood_Azure_Branch_Long",
      "rotation": 5
    },
    {
      "x": -21,
      "y": 38,
      "z": -6,
      "name": "Plant_Leaves_Azure",
      "rotation": 1
    },
    {
      "x": -21,
      "y": 35,
      "z": -5,
      "name": "Plant_Leaves_Azure",
      "rotation": 1
    },
    {
      "x": -21,
      "y": 36,
      "z": -5,
      "name": "Plant_Leaves_Azure",
      "rotation": 1
    },
    {
      "x": -21,
      "y": 37,
      "z": -5,
      "name": "Plant_Leaves_Azure",
      "rotation": 1
    },
    {
      "x": -21,
      "y": 38,
      "z": -5,
      "name": "Plant_Leaves_Azure",
      "rotation": 1
    },
    {
      "x": -21,
      "y": 39,
      "z": -5,
      "name": "Plant_Leaves_Azure",
      "rotation": 1
    },
    {
      "x": -21,
      "y": 35,
      "z": -4,
      "name": "Plant_Leaves_Azure",
      "rotation": 1
    },
    {
      "x": -21,
      "y": 36,
      "z": -4,
      "name": "Plant_Leaves_Azure",
      "rotation": 1
    },
    {
      "x": -21,
      "y": 37,
      "z": -4,
      "name": "Plant_Leaves_Azure",
      "rotation": 1
    },
    {
      "x": -21,
      "y": 38,
      "z": -4,
      "name": "Plant_Leaves_Azure",
      "rotation": 1
    },
    {
      "x": -21,
      "y": 39,
      "z": -4,
      "name": "Plant_Leaves_Azure",
      "rotation": 1
    },
    {
      "x": -21,
      "y": 36,
      "z": -3,
      "name": "Plant_Leaves_Azure",
      "rotation": 1
    },
    {
      "x": -21,
      "y": 37,
      "z": -3,
      "name": "Plant_Leaves_Azure",
      "rotation": 1
    },
    {
      "x": -21,
      "y": 38,
      "z": -3,
      "name": "Plant_Leaves_Azure",
      "rotation": 1
    },
    {
      "x": -20,
      "y": 32,
      "z": -11,
      "name": "Plant_Leaves_Azure",
      "rotation": 1
    },
    {
      "x": -20,
      "y": 33,
      "z": -11,
      "name": "Plant_Leaves_Azure",
      "rotation": 1
    },
    {
      "x": -20,
      "y": 34,
      "z": -11,
      "name": "Plant_Leaves_Azure",
      "rotation": 1
    },
    {
      "x": -20,
      "y": 35,
      "z": -11,
      "name": "Plant_Leaves_Azure",
      "rotation": 1
    },
    {
      "x": -20,
      "y": 32,
      "z": -10,
      "name": "Plant_Leaves_Azure",
      "rotation": 1
    },
    {
      "x": -20,
      "y": 33,
      "z": -10,
      "name": "Plant_Leaves_Azure",
      "rotation": 1
    },
    {
      "x": -20,
      "y": 34,
      "z": -10,
      "name": "Plant_Leaves_Azure",
      "rotation": 1
    },
    {
      "x": -20,
      "y": 35,
      "z": -10,
      "name": "Plant_Leaves_Azure",
      "rotation": 1
    },
    {
      "x": -20,
      "y": 36,
      "z": -10,
      "name": "Plant_Fruit_Azure",
      "rotation": 1
    },
    {
      "x": -20,
      "y": 34,
      "z": -9,
      "name": "Plant_Leaves_Azure",
      "rotation": 1
    },
    {
      "x": -20,
      "y": 35,
      "z": -9,
      "name": "Plant_Leaves_Azure",
      "rotation": 1
    },
    {
      "x": -20,
      "y": 36,
      "z": -9,
      "name": "Plant_Leaves_Azure",
      "rotation": 1
    },
    {
      "x": -20,
      "y": 39,
      "z": -9,
      "name": "Plant_Leaves_Azure",
      "rotation": 1
    },
    {
      "x": -20,
      "y": 40,
      "z": -9,
      "name": "Plant_Leaves_Azure",
      "rotation": 1
    },
    {
      "x": -20,
      "y": 41,
      "z": -9,
      "name": "Plant_Leaves_Azure",
      "rotation": 1
    },
    {
      "x": -20,
      "y": 35,
      "z": -8,
      "name": "Plant_Leaves_Azure",
      "rotation": 1
    },
    {
      "x": -20,
      "y": 36,
      "z": -8,
      "name": "Plant_Leaves_Azure",
      "rotation": 1
    },
    {
      "x": -20,
      "y": 40,
      "z": -8,
      "name": "Plant_Leaves_Azure",
      "rotation": 1
    },
    {
      "x": -20,
      "y": 41,
      "z": -8,
      "name": "Plant_Leaves_Azure",
      "rotation": 1
    },
    {
      "x": -20,
      "y": 42,
      "z": -8,
      "name": "Plant_Leaves_Azure",
      "rotation": 1
    },
    {
      "x": -20,
      "y": 35,
      "z": -7,
      "name": "Wood_Azure_Branch_Long",
      "rotation": 5
    },
    {
      "x": -20,
      "y": 41,
      "z": -7,
      "name": "Plant_Leaves_Azure",
      "rotation": 1
    },
    {
      "x": -20,
      "y": 42,
      "z": -7,
      "name": "Plant_Leaves_Azure",
      "rotation": 1
    },
    {
      "x": -20,
      "y": 43,
      "z": -7,
      "name": "Plant_Leaves_Azure",
      "rotation": 1
    },
    {
      "x": -20,
      "y": 37,
      "z": -6,
      "name": "Wood_Azure_Branch_Long",
      "rotation": 5
    },
    {
      "x": -20,
      "y": 42,
      "z": -6,
      "name": "Plant_Leaves_Azure",
      "rotation": 1
    },
    {
      "x": -20,
      "y": 38,
      "z": -5,
      "name": "Plant_Leaves_Azure",
      "rotation": 1
    },
    {
      "x": -20,
      "y": 39,
      "z": -5,
      "name": "Plant_Leaves_Azure",
      "rotation": 1
    },
    {
      "x": -20,
      "y": 36,
      "z": -4,
      "name": "Plant_Leaves_Azure",
      "rotation": 1
    },
    {
      "x": -20,
      "y": 37,
      "z": -4,
      "name": "Plant_Leaves_Azure",
      "rotation": 1
    },
    {
      "x": -20,
      "y": 38,
      "z": -4,
      "name": "Plant_Leaves_Azure",
      "rotation": 1
    },
    {
      "x": -20,
      "y": 39,
      "z": -4,
      "name": "Plant_Leaves_Azure",
      "rotation": 1
    },
    {
      "x": -20,
      "y": 40,
      "z": -4,
      "name": "Plant_Leaves_Azure",
      "rotation": 1
    },
    {
      "x": -20,
      "y": 36,
      "z": -3,
      "name": "Plant_Leaves_Azure",
      "rotation": 1
    },
    {
      "x": -20,
      "y": 37,
      "z": -3,
      "name": "Plant_Leaves_Azure",
      "rotation": 1
    },
    {
      "x": -20,
      "y": 38,
      "z": -3,
      "name": "Plant_Leaves_Azure",
      "rotation": 1
    },
    {
      "x": -20,
      "y": 39,
      "z": -3,
      "name": "Plant_Leaves_Azure",
      "rotation": 1
    },
    {
      "x": -20,
      "y": 40,
      "z": -3,
      "name": "Plant_Leaves_Azure",
      "rotation": 1
    },
    {
      "x": -20,
      "y": 37,
      "z": -2,
      "name": "Plant_Leaves_Azure",
      "rotation": 1
    },
    {
      "x": -20,
      "y": 38,
      "z": -2,
      "name": "Plant_Leaves_Azure",
      "rotation": 1
    },
    {
      "x": -20,
      "y": 39,
      "z": -2,
      "name": "Plant_Leaves_Azure",
      "rotation": 1
    },
    {
      "x": -19,
      "y": 31,
      "z": -12,
      "name": "Plant_Leaves_Azure",
      "rotation": 1
    },
    {
      "x": -19,
      "y": 32,
      "z": -12,
      "name": "Plant_Leaves_Azure",
      "rotation": 1
    },
    {
      "x": -19,
      "y": 33,
      "z": -12,
      "name": "Plant_Leaves_Azure",
      "rotation": 1
    },
    {
      "x": -19,
      "y": 32,
      "z": -11,
      "name": "Plant_Leaves_Azure",
      "rotation": 1
    },
    {
      "x": -19,
      "y": 33,
      "z": -11,
      "name": "Plant_Leaves_Azure",
      "rotation": 1
    },
    {
      "x": -19,
      "y": 34,
      "z": -11,
      "name": "Plant_Leaves_Azure",
      "rotation": 1
    },
    {
      "x": -19,
      "y": 35,
      "z": -11,
      "name": "Plant_Leaves_Azure",
      "rotation": 1
    },
    {
      "x": -19,
      "y": 32,
      "z": -10,
      "name": "Plant_Leaves_Azure",
      "rotation": 1
    },
    {
      "x": -19,
      "y": 33,
      "z": -10,
      "name": "Plant_Leaves_Azure",
      "rotation": 1
    },
    {
      "x": -19,
      "y": 34,
      "z": -10,
      "name": "Plant_Leaves_Azure",
      "rotation": 1
    },
    {
      "x": -19,
      "y": 35,
      "z": -10,
      "name": "Plant_Leaves_Azure",
      "rotation": 1
    },
    {
      "x": -19,
      "y": 38,
      "z": -10,
      "name": "Plant_Leaves_Azure",
      "rotation": 1
    },
    {
      "x": -19,
      "y": 39,
      "z": -10,
      "name": "Plant_Leaves_Azure",
      "rotation": 1
    },
    {
      "x": -19,
      "y": 40,
      "z": -10,
      "name": "Plant_Leaves_Azure",
      "rotation": 1
    },
    {
      "x": -19,
      "y": 38,
      "z": -9,
      "name": "Plant_Leaves_Azure",
      "rotation": 1
    },
    {
      "x": -19,
      "y": 39,
      "z": -9,
      "name": "Plant_Leaves_Azure",
      "rotation": 1
    },
    {
      "x": -19,
      "y": 40,
      "z": -9,
      "name": "Plant_Leaves_Azure",
      "rotation": 1
    },
    {
      "x": -19,
      "y": 41,
      "z": -9,
      "name": "Plant_Leaves_Azure",
      "rotation": 1
    },
    {
      "x": -19,
      "y": 39,
      "z": -8,
      "name": "Plant_Leaves_Azure",
      "rotation": 1
    },
    {
      "x": -19,
      "y": 40,
      "z": -8,
      "name": "Plant_Leaves_Azure",
      "rotation": 1
    },
    {
      "x": -19,
      "y": 41,
      "z": -8,
      "name": "Plant_Leaves_Azure",
      "rotation": 1
    },
    {
      "x": -19,
      "y": 42,
      "z": -8,
      "name": "Plant_Fruit_Azure",
      "rotation": 1
    },
    {
      "x": -19,
      "y": 35,
      "z": -7,
      "name": "Wood_Azure_Branch_Long",
      "rotation": 5
    },
    {
      "x": -19,
      "y": 40,
      "z": -7,
      "name": "Plant_Leaves_Azure",
      "rotation": 1
    },
    {
      "x": -19,
      "y": 41,
      "z": -7,
      "name": "Plant_Leaves_Azure",
      "rotation": 1
    },
    {
      "x": -19,
      "y": 42,
      "z": -7,
      "name": "Plant_Leaves_Azure",
      "rotation": 1
    },
    {
      "x": -19,
      "y": 43,
      "z": -7,
      "name": "Plant_Leaves_Azure",
      "rotation": 1
    },
    {
      "x": -19,
      "y": 21,
      "z": -6,
      "name": "Plant_Moss_Wall_Blue",
      "rotation": 3
    },
    {
      "x": -19,
      "y": 26,
      "z": -6,
      "name": "Wood_Azure_Trunk_Full",
      "rotation": 1
    },
    {
      "x": -19,
      "y": 27,
      "z": -6,
      "name": "Wood_Azure_Trunk_Full",
      "rotation": 1
    },
    {
      "x": -19,
      "y": 37,
      "z": -6,
      "name": "Wood_Azure_Branch_Long",
      "rotation": 5
    },
    {
      "x": -19,
      "y": 42,
      "z": -6,
      "name": "Plant_Leaves_Azure",
      "rotation": 1
    },
    {
      "x": -19,
      "y": 43,
      "z": -6,
      "name": "Plant_Leaves_Azure",
      "rotation": 1
    },
    {
      "x": -19,
      "y": 44,
      "z": -6,
      "name": "Plant_Leaves_Azure",
      "rotation": 1
    },
    {
      "x": -19,
      "y": 24,
      "z": -5,
      "name": "Wood_Azure_Roots",
      "rotation": 1
    },
    {
      "x": -19,
      "y": 25,
      "z": -5,
      "name": "Wood_Azure_Trunk_Full",
      "rotation": 1
    },
    {
      "x": -19,
      "y": 26,
      "z": -5,
      "name": "Wood_Azure_Trunk_Full",
      "rotation": 1
    },
    {
      "x": -19,
      "y": 38,
      "z": -4,
      "name": "Plant_Leaves_Azure",
      "rotation": 1
    },
    {
      "x": -19,
      "y": 39,
      "z": -4,
      "name": "Plant_Leaves_Azure",
      "rotation": 1
    },
    {
      "x": -19,
      "y": 40,
      "z": -4,
      "name": "Plant_Leaves_Azure",
      "rotation": 1
    },
    {
      "x": -19,
      "y": 41,
      "z": -4,
      "name": "Plant_Fruit_Azure",
      "rotation": 1
    },
    {
      "x": -19,
      "y": 19,
      "z": -3,
      "name": "Plant_Moss_Wall_Blue",
      "rotation": 3
    },
    {
      "x": -19,
      "y": 21,
      "z": -3,
      "name": "Plant_Moss_Wall_Blue",
      "rotation": 3
    },
    {
      "x": -19,
      "y": 37,
      "z": -3,
      "name": "Plant_Leaves_Azure",
      "rotation": 1
    },
    {
      "x": -19,
      "y": 38,
      "z": -3,
      "name": "Plant_Leaves_Azure",
      "rotation": 1
    },
    {
      "x": -19,
      "y": 39,
      "z": -3,
      "name": "Plant_Leaves_Azure",
      "rotation": 1
    },
    {
      "x": -19,
      "y": 40,
      "z": -3,
      "name": "Plant_Leaves_Azure",
      "rotation": 1
    },
    {
      "x": -19,
      "y": 41,
      "z": -3,
      "name": "Plant_Leaves_Azure",
      "rotation": 1
    },
    {
      "x": -19,
      "y": 19,
      "z": -2,
      "name": "Plant_Moss_Wall_Blue",
      "rotation": 3
    },
    {
      "x": -19,
      "y": 37,
      "z": -2,
      "name": "Plant_Leaves_Azure",
      "rotation": 1
    },
    {
      "x": -19,
      "y": 38,
      "z": -2,
      "name": "Plant_Leaves_Azure",
      "rotation": 1
    },
    {
      "x": -19,
      "y": 39,
      "z": -2,
      "name": "Plant_Leaves_Azure",
      "rotation": 1
    },
    {
      "x": -19,
      "y": 40,
      "z": -2,
      "name": "Plant_Leaves_Azure",
      "rotation": 1
    },
    {
      "x": -19,
      "y": 21,
      "z": -1,
      "name": "Plant_Moss_Wall_Blue",
      "rotation": 3
    },
    {
      "x": -18,
      "y": 31,
      "z": -12,
      "name": "Plant_Leaves_Azure",
      "rotation": 1
    },
    {
      "x": -18,
      "y": 32,
      "z": -12,
      "name": "Plant_Leaves_Azure",
      "rotation": 1
    },
    {
      "x": -18,
      "y": 33,
      "z": -12,
      "name": "Plant_Leaves_Azure",
      "rotation": 1
    },
    {
      "x": -18,
      "y": 34,
      "z": -12,
      "name": "Plant_Leaves_Azure",
      "rotation": 1
    },
    {
      "x": -18,
      "y": 31,
      "z": -11,
      "name": "Plant_Leaves_Azure",
      "rotation": 1
    },
    {
      "x": -18,
      "y": 32,
      "z": -11,
      "name": "Plant_Leaves_Azure",
      "rotation": 1
    },
    {
      "x": -18,
      "y": 33,
      "z": -11,
      "name": "Plant_Leaves_Azure",
      "rotation": 1
    },
    {
      "x": -18,
      "y": 34,
      "z": -11,
      "name": "Plant_Leaves_Azure",
      "rotation": 1
    },
    {
      "x": -18,
      "y": 35,
      "z": -11,
      "name": "Plant_Fruit_Azure",
      "rotation": 1
    },
    {
      "x": -18,
      "y": 37,
      "z": -11,
      "name": "Plant_Leaves_Azure",
      "rotation": 1
    },
    {
      "x": -18,
      "y": 38,
      "z": -11,
      "name": "Plant_Leaves_Azure",
      "rotation": 1
    },
    {
      "x": -18,
      "y": 39,
      "z": -11,
      "name": "Plant_Leaves_Azure",
      "rotation": 1
    },
    {
      "x": -18,
      "y": 18,
      "z": -10,
      "name": "Plant_Moss_Wall_Blue",
      "rotation": 3
    },
    {
      "x": -18,
      "y": 20,
      "z": -10,
      "name": "Plant_Moss_Wall_Blue",
      "rotation": 3
    },
    {
      "x": -18,
      "y": 32,
      "z": -10,
      "name": "Plant_Leaves_Azure",
      "rotation": 1
    },
    {
      "x": -18,
      "y": 33,
      "z": -10,
      "name": "Plant_Leaves_Azure",
      "rotation": 1
    },
    {
      "x": -18,
      "y": 37,
      "z": -10,
      "name": "Plant_Leaves_Azure",
      "rotation": 1
    },
    {
      "x": -18,
      "y": 38,
      "z": -10,
      "name": "Plant_Leaves_Azure",
      "rotation": 1
    },
    {
      "x": -18,
      "y": 39,
      "z": -10,
      "name": "Plant_Leaves_Azure",
      "rotation": 1
    },
    {
      "x": -18,
      "y": 40,
      "z": -10,
      "name": "Plant_Leaves_Azure",
      "rotation": 1
    },
    {
      "x": -18,
      "y": 41,
      "z": -10,
      "name": "Plant_Fruit_Azure",
      "rotation": 1
    },
    {
      "x": -18,
      "y": 20,
      "z": -9,
      "name": "Plant_Moss_Wall_Blue",
      "rotation": 3
    },
    {
      "x": -18,
      "y": 21,
      "z": -9,
      "name": "Plant_Moss_Wall_Blue",
      "rotation": 3
    },
    {
      "x": -18,
      "y": 22,
      "z": -9,
      "name": "Plant_Moss_Wall_Blue",
      "rotation": 3
    },
    {
      "x": -18,
      "y": 39,
      "z": -9,
      "name": "Plant_Leaves_Azure",
      "rotation": 1
    },
    {
      "x": -18,
      "y": 40,
      "z": -9,
      "name": "Plant_Leaves_Azure",
      "rotation": 1
    },
    {
      "x": -18,
      "y": 18,
      "z": -8,
      "name": "Plant_Moss_Wall_Blue",
      "rotation": 3
    },
    {
      "x": -18,
      "y": 19,
      "z": -8,
      "name": "Plant_Moss_Wall_Blue",
      "rotation": 3
    },
    {
      "x": -18,
      "y": 21,
      "z": -8,
      "name": "Plant_Moss_Wall_Blue",
      "rotation": 3
    },
    {
      "x": -18,
      "y": 26,
      "z": -8,
      "name": "Plant_Moss_Wall_Blue",
      "rotation": 3
    },
    {
      "x": -18,
      "y": 35,
      "z": -8,
      "name": "Plant_Moss_Wall_Blue",
      "rotation": 3
    },
    {
      "x": -18,
      "y": 40,
      "z": -8,
      "name": "Plant_Leaves_Azure",
      "rotation": 1
    },
    {
      "x": -18,
      "y": 46,
      "z": -8,
      "name": "Plant_Leaves_Azure",
      "rotation": 1
    },
    {
      "x": -18,
      "y": 20,
      "z": -7,
      "name": "Rock_Marble"
    },
    {
      "x": -18,
      "y": 21,
      "z": -7,
      "name": "Plant_Moss_Block_Blue"
    },
    {
      "x": -18,
      "y": 22,
      "z": -7,
      "name": "Plant_Moss_Short_Green_Dark"
    },
    {
      "x": -18,
      "y": 25,
      "z": -7,
      "name": "Plant_Moss_Wall_Blue",
      "rotation": 3
    },
    {
      "x": -18,
      "y": 26,
      "z": -7,
      "name": "Plant_Moss_Wall_Blue",
      "rotation": 3
    },
    {
      "x": -18,
      "y": 27,
      "z": -7,
      "name": "Wood_Azure_Trunk_Full",
      "rotation": 1
    },
    {
      "x": -18,
      "y": 28,
      "z": -7,
      "name": "Wood_Azure_Trunk",
      "rotation": 1
    },
    {
      "x": -18,
      "y": 29,
      "z": -7,
      "name": "Wood_Azure_Trunk_Full",
      "rotation": 1
    },
    {
      "x": -18,
      "y": 35,
      "z": -7,
      "name": "Wood_Azure_Trunk_Full",
      "rotation": 1
    },
    {
      "x": -18,
      "y": 36,
      "z": -7,
      "name": "Wood_Azure_Trunk",
      "rotation": 1
    },
    {
      "x": -18,
      "y": 37,
      "z": -7,
      "name": "Wood_Azure_Trunk_Full",
      "rotation": 1
    },
    {
      "x": -18,
      "y": 40,
      "z": -7,
      "name": "Wood_Azure_Branch_Long",
      "rotation": 5
    },
    {
      "x": -18,
      "y": 45,
      "z": -7,
      "name": "Plant_Leaves_Azure",
      "rotation": 1
    },
    {
      "x": -18,
      "y": 46,
      "z": -7,
      "name": "Plant_Leaves_Azure",
      "rotation": 1
    },
    {
      "x": -18,
      "y": 47,
      "z": -7,
      "name": "Plant_Leaves_Azure",
      "rotation": 1
    },
    {
      "x": -18,
      "y": 48,
      "z": -7,
      "name": "Plant_Leaves_Azure",
      "rotation": 1
    },
    {
      "x": -18,
      "y": 19,
      "z": -6,
      "name": "Plant_Moss_Wall_Blue",
      "rotation": 3
    },
    {
      "x": -18,
      "y": 20,
      "z": -6,
      "name": "Rock_Marble"
    },
    {
      "x": -18,
      "y": 21,
      "z": -6,
      "name": "Plant_Moss_Block_Blue"
    },
    {
      "x": -18,
      "y": 22,
      "z": -6,
      "name": "Plant_Moss_Rug_Blue"
    },
    {
      "x": -18,
      "y": 25,
      "z": -6,
      "name": "Wood_Azure_Roots",
      "rotation": 1
    },
    {
      "x": -18,
      "y": 26,
      "z": -6,
      "name": "Wood_Azure_Trunk_Full",
      "rotation": 1
    },
    {
      "x": -18,
      "y": 27,
      "z": -6,
      "name": "Wood_Azure_Trunk",
      "rotation": 1
    },
    {
      "x": -18,
      "y": 28,
      "z": -6,
      "name": "Wood_Azure_Trunk_Full",
      "rotation": 1
    },
    {
      "x": -18,
      "y": 30,
      "z": -6,
      "name": "Plant_Moss_Wall_Blue",
      "rotation": 3
    },
    {
      "x": -18,
      "y": 37,
      "z": -6,
      "name": "Wood_Azure_Trunk_Full",
      "rotation": 1
    },
    {
      "x": -18,
      "y": 38,
      "z": -6,
      "name": "Wood_Azure_Trunk",
      "rotation": 1
    },
    {
      "x": -18,
      "y": 39,
      "z": -6,
      "name": "Wood_Azure_Trunk_Full",
      "rotation": 1
    },
    {
      "x": -18,
      "y": 42,
      "z": -6,
      "name": "Wood_Azure_Branch_Long",
      "rotation": 5
    },
    {
      "x": -18,
      "y": 46,
      "z": -6,
      "name": "Plant_Leaves_Azure",
      "rotation": 1
    },
    {
      "x": -18,
      "y": 47,
      "z": -6,
      "name": "Plant_Leaves_Azure",
      "rotation": 1
    },
    {
      "x": -18,
      "y": 48,
      "z": -6,
      "name": "Plant_Leaves_Azure",
      "rotation": 1
    },
    {
      "x": -18,
      "y": 49,
      "z": -6,
      "name": "Plant_Leaves_Azure",
      "rotation": 1
    },
    {
      "x": -18,
      "y": 18,
      "z": -5,
      "name": "Plant_Moss_Wall_Blue",
      "rotation": 3
    },
    {
      "x": -18,
      "y": 19,
      "z": -5,
      "name": "Plant_Moss_Wall_Blue",
      "rotation": 3
    },
    {
      "x": -18,
      "y": 20,
      "z": -5,
      "name": "Rock_Marble"
    },
    {
      "x": -18,
      "y": 21,
      "z": -5,
      "name": "Plant_Moss_Block_Blue"
    },
    {
      "x": -18,
      "y": 22,
      "z": -5,
      "name": "Plant_Moss_Short_Green_Dark"
    },
    {
      "x": -18,
      "y": 26,
      "z": -5,
      "name": "Wood_Azure_Trunk_Full",
      "rotation": 1
    },
    {
      "x": -18,
      "y": 27,
      "z": -5,
      "name": "Wood_Azure_Trunk_Full",
      "rotation": 1
    },
    {
      "x": -18,
      "y": 38,
      "z": -5,
      "name": "Wood_Azure_Branch_Long",
      "rotation": 6
    },
    {
      "x": -18,
      "y": 16,
      "z": -4,
      "name": "Plant_Moss_Wall_Blue",
      "rotation": 3
    },
    {
      "x": -18,
      "y": 17,
      "z": -4,
      "name": "Plant_Moss_Wall_Blue",
      "rotation": 3
    },
    {
      "x": -18,
      "y": 20,
      "z": -4,
      "name": "Plant_Moss_Wall_Blue",
      "rotation": 3
    },
    {
      "x": -18,
      "y": 38,
      "z": -4,
      "name": "Wood_Azure_Branch_Long",
      "rotation": 6
    },
    {
      "x": -18,
      "y": 40,
      "z": -4,
      "name": "Plant_Leaves_Azure",
      "rotation": 1
    },
    {
      "x": -18,
      "y": 41,
      "z": -4,
      "name": "Plant_Leaves_Azure",
      "rotation": 1
    },
    {
      "x": -18,
      "y": 18,
      "z": -3,
      "name": "Rock_Marble"
    },
    {
      "x": -18,
      "y": 19,
      "z": -3,
      "name": "Rock_Marble"
    },
    {
      "x": -18,
      "y": 20,
      "z": -3,
      "name": "Rock_Marble"
    },
    {
      "x": -18,
      "y": 21,
      "z": -3,
      "name": "Plant_Moss_Block_Blue"
    },
    {
      "x": -18,
      "y": 22,
      "z": -3,
      "name": "Plant_Moss_Blue"
    },
    {
      "x": -18,
      "y": 37,
      "z": -3,
      "name": "Plant_Leaves_Azure",
      "rotation": 1
    },
    {
      "x": -18,
      "y": 38,
      "z": -3,
      "name": "Wood_Azure_Branch_Long",
      "rotation": 6
    },
    {
      "x": -18,
      "y": 39,
      "z": -3,
      "name": "Plant_Leaves_Azure",
      "rotation": 1
    },
    {
      "x": -18,
      "y": 40,
      "z": -3,
      "name": "Plant_Leaves_Azure",
      "rotation": 1
    },
    {
      "x": -18,
      "y": 41,
      "z": -3,
      "name": "Plant_Leaves_Azure",
      "rotation": 1
    },
    {
      "x": -18,
      "y": 42,
      "z": -3,
      "name": "Plant_Leaves_Azure",
      "rotation": 1
    },
    {
      "x": -18,
      "y": 18,
      "z": -2,
      "name": "Rock_Marble"
    },
    {
      "x": -18,
      "y": 19,
      "z": -2,
      "name": "Rock_Marble"
    },
    {
      "x": -18,
      "y": 20,
      "z": -2,
      "name": "Rock_Marble"
    },
    {
      "x": -18,
      "y": 21,
      "z": -2,
      "name": "Plant_Moss_Block_Blue"
    },
    {
      "x": -18,
      "y": 22,
      "z": -2,
      "name": "Plant_Moss_Rug_Lime"
    },
    {
      "x": -18,
      "y": 38,
      "z": -2,
      "name": "Plant_Leaves_Azure",
      "rotation": 1
    },
    {
      "x": -18,
      "y": 39,
      "z": -2,
      "name": "Plant_Leaves_Azure",
      "rotation": 1
    },
    {
      "x": -18,
      "y": 40,
      "z": -2,
      "name": "Plant_Leaves_Azure",
      "rotation": 1
    },
    {
      "x": -18,
      "y": 41,
      "z": -2,
      "name": "Plant_Leaves_Azure",
      "rotation": 1
    },
    {
      "x": -18,
      "y": 18,
      "z": -1,
      "name": "Rock_Marble"
    },
    {
      "x": -18,
      "y": 19,
      "z": -1,
      "name": "Rock_Marble"
    },
    {
      "x": -18,
      "y": 20,
      "z": -1,
      "name": "Rock_Marble"
    },
    {
      "x": -18,
      "y": 21,
      "z": -1,
      "name": "Plant_Moss_Block_Blue"
    },
    {
      "x": -18,
      "y": 22,
      "z": -1,
      "name": "Plant_Moss_Blue"
    },
    {
      "x": -18,
      "y": 18,
      "z": 0,
      "name": "Plant_Moss_Wall_Blue",
      "rotation": 3
    },
    {
      "x": -18,
      "y": 19,
      "z": 0,
      "name": "Plant_Moss_Wall_Blue"
    },
    {
      "x": -18,
      "y": 21,
      "z": 0,
      "name": "Plant_Moss_Wall_Blue",
      "rotation": 3
    },
    {
      "x": -17,
      "y": 31,
      "z": -12,
      "name": "Plant_Leaves_Azure",
      "rotation": 1
    },
    {
      "x": -17,
      "y": 32,
      "z": -12,
      "name": "Plant_Leaves_Azure",
      "rotation": 1
    },
    {
      "x": -17,
      "y": 33,
      "z": -12,
      "name": "Plant_Leaves_Azure",
      "rotation": 1
    },
    {
      "x": -17,
      "y": 18,
      "z": -11,
      "name": "Plant_Moss_Wall_Blue",
      "rotation": 3
    },
    {
      "x": -17,
      "y": 21,
      "z": -11,
      "name": "Plant_Moss_Wall_Blue",
      "rotation": 3
    },
    {
      "x": -17,
      "y": 22,
      "z": -11,
      "name": "Plant_Moss_Wall_Blue",
      "rotation": 3
    },
    {
      "x": -17,
      "y": 31,
      "z": -11,
      "name": "Plant_Leaves_Azure",
      "rotation": 1
    },
    {
      "x": -17,
      "y": 32,
      "z": -11,
      "name": "Plant_Leaves_Azure",
      "rotation": 1
    },
    {
      "x": -17,
      "y": 33,
      "z": -11,
      "name": "Wood_Azure_Branch_Long",
      "rotation": 6
    },
    {
      "x": -17,
      "y": 34,
      "z": -11,
      "name": "Plant_Leaves_Azure",
      "rotation": 1
    },
    {
      "x": -17,
      "y": 36,
      "z": -11,
      "name": "Plant_Leaves_Azure",
      "rotation": 1
    },
    {
      "x": -17,
      "y": 37,
      "z": -11,
      "name": "Plant_Leaves_Azure",
      "rotation": 1
    },
    {
      "x": -17,
      "y": 38,
      "z": -11,
      "name": "Plant_Leaves_Azure",
      "rotation": 1
    },
    {
      "x": -17,
      "y": 39,
      "z": -11,
      "name": "Plant_Leaves_Azure",
      "rotation": 1
    },
    {
      "x": -17,
      "y": 15,
      "z": -10,
      "name": "Rock_Marble"
    },
    {
      "x": -17,
      "y": 16,
      "z": -10,
      "name": "Rock_Marble"
    },
    {
      "x": -17,
      "y": 17,
      "z": -10,
      "name": "Rock_Marble"
    },
    {
      "x": -17,
      "y": 18,
      "z": -10,
      "name": "Rock_Marble"
    },
    {
      "x": -17,
      "y": 19,
      "z": -10,
      "name": "Rock_Marble"
    },
    {
      "x": -17,
      "y": 20,
      "z": -10,
      "name": "Rock_Marble"
    },
    {
      "x": -17,
      "y": 21,
      "z": -10,
      "name": "Rock_Marble"
    },
    {
      "x": -17,
      "y": 22,
      "z": -10,
      "name": "Rock_Marble"
    },
    {
      "x": -17,
      "y": 23,
      "z": -10,
      "name": "Plant_Moss_Blue"
    },
    {
      "x": -17,
      "y": 31,
      "z": -10,
      "name": "Plant_Leaves_Azure",
      "rotation": 1
    },
    {
      "x": -17,
      "y": 32,
      "z": -10,
      "name": "Plant_Leaves_Azure",
      "rotation": 1
    },
    {
      "x": -17,
      "y": 33,
      "z": -10,
      "name": "Wood_Azure_Branch_Long",
      "rotation": 6
    },
    {
      "x": -17,
      "y": 37,
      "z": -10,
      "name": "Plant_Leaves_Azure",
      "rotation": 1
    },
    {
      "x": -17,
      "y": 38,
      "z": -10,
      "name": "Plant_Leaves_Azure",
      "rotation": 1
    },
    {
      "x": -17,
      "y": 39,
      "z": -10,
      "name": "Plant_Leaves_Azure",
      "rotation": 1
    },
    {
      "x": -17,
      "y": 40,
      "z": -10,
      "name": "Plant_Leaves_Azure",
      "rotation": 1
    },
    {
      "x": -17,
      "y": 15,
      "z": -9,
      "name": "Rock_Marble"
    },
    {
      "x": -17,
      "y": 16,
      "z": -9,
      "name": "Rock_Marble"
    },
    {
      "x": -17,
      "y": 17,
      "z": -9,
      "name": "Rock_Marble"
    },
    {
      "x": -17,
      "y": 18,
      "z": -9,
      "name": "Rock_Marble"
    },
    {
      "x": -17,
      "y": 19,
      "z": -9,
      "name": "Rock_Marble"
    },
    {
      "x": -17,
      "y": 20,
      "z": -9,
      "name": "Rock_Marble"
    },
    {
      "x": -17,
      "y": 21,
      "z": -9,
      "name": "Rock_Marble"
    },
    {
      "x": -17,
      "y": 22,
      "z": -9,
      "name": "Plant_Moss_Block_Blue"
    },
    {
      "x": -17,
      "y": 23,
      "z": -9,
      "name": "Plant_Moss_Short_Green_Dark"
    },
    {
      "x": -17,
      "y": 25,
      "z": -9,
      "name": "Plant_Moss_Wall_Blue",
      "rotation": 3
    },
    {
      "x": -17,
      "y": 26,
      "z": -9,
      "name": "Plant_Moss_Wall_Blue",
      "rotation": 3
    },
    {
      "x": -17,
      "y": 33,
      "z": -9,
      "name": "Wood_Azure_Branch_Long",
      "rotation": 6
    },
    {
      "x": -17,
      "y": 35,
      "z": -9,
      "name": "Plant_Moss_Wall_Blue",
      "rotation": 2
    },
    {
      "x": -17,
      "y": 38,
      "z": -9,
      "name": "Plant_Leaves_Azure",
      "rotation": 1
    },
    {
      "x": -17,
      "y": 39,
      "z": -9,
      "name": "Plant_Leaves_Azure",
      "rotation": 1
    },
    {
      "x": -17,
      "y": 15,
      "z": -8,
      "name": "Rock_Marble"
    },
    {
      "x": -17,
      "y": 16,
      "z": -8,
      "name": "Rock_Marble"
    },
    {
      "x": -17,
      "y": 17,
      "z": -8,
      "name": "Rock_Marble"
    },
    {
      "x": -17,
      "y": 18,
      "z": -8,
      "name": "Rock_Marble"
    },
    {
      "x": -17,
      "y": 19,
      "z": -8,
      "name": "Rock_Marble"
    },
    {
      "x": -17,
      "y": 20,
      "z": -8,
      "name": "Rock_Marble"
    },
    {
      "x": -17,
      "y": 21,
      "z": -8,
      "name": "Rock_Marble"
    },
    {
      "x": -17,
      "y": 22,
      "z": -8,
      "name": "Rock_Marble"
    },
    {
      "x": -17,
      "y": 23,
      "z": -8,
      "name": "Rock_Marble"
    },
    {
      "x": -17,
      "y": 24,
      "z": -8,
      "name": "Rock_Marble"
    },
    {
      "x": -17,
      "y": 25,
      "z": -8,
      "name": "Rock_Marble"
    },
    {
      "x": -17,
      "y": 26,
      "z": -8,
      "name": "Plant_Moss_Block_Blue"
    },
    {
      "x": -17,
      "y": 27,
      "z": -8,
      "name": "Plant_Moss_Blue"
    },
    {
      "x": -17,
      "y": 32,
      "z": -8,
      "name": "Wood_Azure_Trunk_Full",
      "rotation": 1
    },
    {
      "x": -17,
      "y": 33,
      "z": -8,
      "name": "Wood_Azure_Trunk",
      "rotation": 1
    },
    {
      "x": -17,
      "y": 34,
      "z": -8,
      "name": "Wood_Azure_Trunk",
      "rotation": 1
    },
    {
      "x": -17,
      "y": 35,
      "z": -8,
      "name": "Wood_Azure_Trunk_Full",
      "rotation": 1
    },
    {
      "x": -17,
      "y": 36,
      "z": -8,
      "name": "Plant_Moss_Rug_Blue",
      "rotation": 1
    },
    {
      "x": -17,
      "y": 44,
      "z": -8,
      "name": "Plant_Leaves_Azure",
      "rotation": 1
    },
    {
      "x": -17,
      "y": 45,
      "z": -8,
      "name": "Plant_Leaves_Azure",
      "rotation": 1
    },
    {
      "x": -17,
      "y": 46,
      "z": -8,
      "name": "Plant_Leaves_Azure",
      "rotation": 1
    },
    {
      "x": -17,
      "y": 19,
      "z": -7,
      "name": "Rock_Marble"
    },
    {
      "x": -17,
      "y": 20,
      "z": -7,
      "name": "Rock_Marble"
    },
    {
      "x": -17,
      "y": 21,
      "z": -7,
      "name": "Rock_Marble"
    },
    {
      "x": -17,
      "y": 22,
      "z": -7,
      "name": "Rock_Marble"
    },
    {
      "x": -17,
      "y": 23,
      "z": -7,
      "name": "Rock_Marble"
    },
    {
      "x": -17,
      "y": 24,
      "z": -7,
      "name": "Rock_Marble"
    },
    {
      "x": -17,
      "y": 25,
      "z": -7,
      "name": "Rock_Marble"
    },
    {
      "x": -17,
      "y": 26,
      "z": -7,
      "name": "Plant_Moss_Block_Blue"
    },
    {
      "x": -17,
      "y": 27,
      "z": -7,
      "name": "Wood_Azure_Trunk_Full",
      "rotation": 1
    },
    {
      "x": -17,
      "y": 28,
      "z": -7,
      "name": "Wood_Azure_Trunk",
      "rotation": 1
    },
    {
      "x": -17,
      "y": 29,
      "z": -7,
      "name": "Wood_Azure_Trunk",
      "rotation": 1
    },
    {
      "x": -17,
      "y": 30,
      "z": -7,
      "name": "Wood_Azure_Trunk",
      "rotation": 1
    },
    {
      "x": -17,
      "y": 31,
      "z": -7,
      "name": "Wood_Azure_Trunk",
      "rotation": 1
    },
    {
      "x": -17,
      "y": 32,
      "z": -7,
      "name": "Wood_Azure_Trunk",
      "rotation": 1
    },
    {
      "x": -17,
      "y": 33,
      "z": -7,
      "name": "Wood_Azure_Trunk",
      "rotation": 1
    },
    {
      "x": -17,
      "y": 34,
      "z": -7,
      "name": "Wood_Azure_Trunk",
      "rotation": 1
    },
    {
      "x": -17,
      "y": 35,
      "z": -7,
      "name": "Wood_Azure_Trunk",
      "rotation": 1
    },
    {
      "x": -17,
      "y": 36,
      "z": -7,
      "name": "Wood_Azure_Trunk",
      "rotation": 1
    },
    {
      "x": -17,
      "y": 37,
      "z": -7,
      "name": "Wood_Azure_Trunk",
      "rotation": 1
    },
    {
      "x": -17,
      "y": 38,
      "z": -7,
      "name": "Wood_Azure_Trunk",
      "rotation": 1
    },
    {
      "x": -17,
      "y": 39,
      "z": -7,
      "name": "Wood_Azure_Trunk",
      "rotation": 1
    },
    {
      "x": -17,
      "y": 40,
      "z": -7,
      "name": "Wood_Azure_Trunk_Full",
      "rotation": 1
    },
    {
      "x": -17,
      "y": 43,
      "z": -7,
      "name": "Plant_Moss_Wall_Blue",
      "rotation": 2
    },
    {
      "x": -17,
      "y": 45,
      "z": -7,
      "name": "Plant_Leaves_Azure",
      "rotation": 1
    },
    {
      "x": -17,
      "y": 46,
      "z": -7,
      "name": "Plant_Leaves_Azure",
      "rotation": 1
    },
    {
      "x": -17,
      "y": 47,
      "z": -7,
      "name": "Plant_Leaves_Azure",
      "rotation": 1
    },
    {
      "x": -17,
      "y": 48,
      "z": -7,
      "name": "Plant_Fruit_Azure",
      "rotation": 1
    },
    {
      "x": -17,
      "y": 18,
      "z": -6,
      "name": "Rock_Marble"
    },
    {
      "x": -17,
      "y": 19,
      "z": -6,
      "name": "Rock_Marble"
    },
    {
      "x": -17,
      "y": 20,
      "z": -6,
      "name": "Rock_Marble"
    },
    {
      "x": -17,
      "y": 21,
      "z": -6,
      "name": "Rock_Marble"
    },
    {
      "x": -17,
      "y": 22,
      "z": -6,
      "name": "Rock_Marble"
    },
    {
      "x": -17,
      "y": 23,
      "z": -6,
      "name": "Rock_Marble"
    },
    {
      "x": -17,
      "y": 24,
      "z": -6,
      "name": "Rock_Marble"
    },
    {
      "x": -17,
      "y": 25,
      "z": -6,
      "name": "Rock_Marble"
    },
    {
      "x": -17,
      "y": 26,
      "z": -6,
      "name": "Plant_Moss_Block_Blue"
    },
    {
      "x": -17,
      "y": 27,
      "z": -6,
      "name": "Wood_Azure_Trunk_Full",
      "rotation": 1
    },
    {
      "x": -17,
      "y": 28,
      "z": -6,
      "name": "Wood_Azure_Trunk",
      "rotation": 1
    },
    {
      "x": -17,
      "y": 29,
      "z": -6,
      "name": "Wood_Azure_Trunk",
      "rotation": 1
    },
    {
      "x": -17,
      "y": 30,
      "z": -6,
      "name": "Wood_Azure_Trunk_Full",
      "rotation": 1
    },
    {
      "x": -17,
      "y": 31,
      "z": -6,
      "name": "Plant_Moss_Rug_Blue",
      "rotation": 1
    },
    {
      "x": -17,
      "y": 34,
      "z": -6,
      "name": "Wood_Azure_Trunk_Full",
      "rotation": 1
    },
    {
      "x": -17,
      "y": 35,
      "z": -6,
      "name": "Wood_Azure_Trunk",
      "rotation": 1
    },
    {
      "x": -17,
      "y": 36,
      "z": -6,
      "name": "Wood_Azure_Trunk",
      "rotation": 1
    },
    {
      "x": -17,
      "y": 37,
      "z": -6,
      "name": "Wood_Azure_Trunk",
      "rotation": 1
    },
    {
      "x": -17,
      "y": 38,
      "z": -6,
      "name": "Wood_Azure_Trunk",
      "rotation": 1
    },
    {
      "x": -17,
      "y": 39,
      "z": -6,
      "name": "Wood_Azure_Trunk",
      "rotation": 1
    },
    {
      "x": -17,
      "y": 40,
      "z": -6,
      "name": "Wood_Azure_Trunk",
      "rotation": 1
    },
    {
      "x": -17,
      "y": 41,
      "z": -6,
      "name": "Wood_Azure_Trunk",
      "rotation": 1
    },
    {
      "x": -17,
      "y": 42,
      "z": -6,
      "name": "Wood_Azure_Trunk",
      "rotation": 1
    },
    {
      "x": -17,
      "y": 43,
      "z": -6,
      "name": "Wood_Azure_Trunk_Full",
      "rotation": 1
    },
    {
      "x": -17,
      "y": 44,
      "z": -6,
      "name": "Wood_Azure_Branch_Long",
      "rotation": 1
    },
    {
      "x": -17,
      "y": 45,
      "z": -6,
      "name": "Wood_Azure_Branch_Long",
      "rotation": 1
    },
    {
      "x": -17,
      "y": 46,
      "z": -6,
      "name": "Wood_Azure_Branch_Long",
      "rotation": 1
    },
    {
      "x": -17,
      "y": 47,
      "z": -6,
      "name": "Plant_Leaves_Azure",
      "rotation": 1
    },
    {
      "x": -17,
      "y": 48,
      "z": -6,
      "name": "Plant_Leaves_Azure",
      "rotation": 1
    },
    {
      "x": -17,
      "y": 18,
      "z": -5,
      "name": "Rock_Marble"
    },
    {
      "x": -17,
      "y": 19,
      "z": -5,
      "name": "Rock_Marble"
    },
    {
      "x": -17,
      "y": 20,
      "z": -5,
      "name": "Rock_Marble"
    },
    {
      "x": -17,
      "y": 21,
      "z": -5,
      "name": "Plant_Moss_Block_Blue"
    },
    {
      "x": -17,
      "y": 22,
      "z": -5,
      "name": "Plant_Moss_Short_Green_Dark"
    },
    {
      "x": -17,
      "y": 27,
      "z": -5,
      "name": "Wood_Azure_Trunk_Full",
      "rotation": 1
    },
    {
      "x": -17,
      "y": 30,
      "z": -5,
      "name": "Plant_Moss_Wall_Blue"
    },
    {
      "x": -17,
      "y": 41,
      "z": -5,
      "name": "Wood_Azure_Branch_Long",
      "rotation": 6
    },
    {
      "x": -17,
      "y": 46,
      "z": -5,
      "name": "Plant_Leaves_Azure",
      "rotation": 1
    },
    {
      "x": -17,
      "y": 15,
      "z": -4,
      "name": "Rock_Marble"
    },
    {
      "x": -17,
      "y": 16,
      "z": -4,
      "name": "Rock_Marble"
    },
    {
      "x": -17,
      "y": 17,
      "z": -4,
      "name": "Rock_Marble"
    },
    {
      "x": -17,
      "y": 18,
      "z": -4,
      "name": "Rock_Marble"
    },
    {
      "x": -17,
      "y": 19,
      "z": -4,
      "name": "Rock_Marble"
    },
    {
      "x": -17,
      "y": 20,
      "z": -4,
      "name": "Rock_Marble"
    },
    {
      "x": -17,
      "y": 21,
      "z": -4,
      "name": "Plant_Moss_Block_Blue"
    },
    {
      "x": -17,
      "y": 22,
      "z": -4,
      "name": "Plant_Moss_Short_Green_Dark"
    },
    {
      "x": -17,
      "y": 34,
      "z": -4,
      "name": "Plant_Moss_Wall_Blue",
      "rotation": 3
    },
    {
      "x": -17,
      "y": 40,
      "z": -4,
      "name": "Plant_Leaves_Azure",
      "rotation": 1
    },
    {
      "x": -17,
      "y": 41,
      "z": -4,
      "name": "Wood_Azure_Branch_Long",
      "rotation": 6
    },
    {
      "x": -17,
      "y": 42,
      "z": -4,
      "name": "Plant_Leaves_Azure",
      "rotation": 1
    },
    {
      "x": -17,
      "y": 43,
      "z": -4,
      "name": "Plant_Fruit_Azure",
      "rotation": 1
    },
    {
      "x": -17,
      "y": 15,
      "z": -3,
      "name": "Rock_Marble"
    },
    {
      "x": -17,
      "y": 16,
      "z": -3,
      "name": "Rock_Marble"
    },
    {
      "x": -17,
      "y": 17,
      "z": -3,
      "name": "Rock_Marble"
    },
    {
      "x": -17,
      "y": 18,
      "z": -3,
      "name": "Rock_Marble"
    },
    {
      "x": -17,
      "y": 19,
      "z": -3,
      "name": "Rock_Marble"
    },
    {
      "x": -17,
      "y": 20,
      "z": -3,
      "name": "Rock_Marble"
    },
    {
      "x": -17,
      "y": 21,
      "z": -3,
      "name": "Plant_Moss_Block_Blue"
    },
    {
      "x": -17,
      "y": 22,
      "z": -3,
      "name": "Plant_Moss_Rug_Blue"
    },
    {
      "x": -17,
      "y": 38,
      "z": -3,
      "name": "Plant_Leaves_Azure",
      "rotation": 1
    },
    {
      "x": -17,
      "y": 39,
      "z": -3,
      "name": "Plant_Leaves_Azure",
      "rotation": 1
    },
    {
      "x": -17,
      "y": 40,
      "z": -3,
      "name": "Plant_Leaves_Azure",
      "rotation": 1
    },
    {
      "x": -17,
      "y": 41,
      "z": -3,
      "name": "Plant_Leaves_Azure",
      "rotation": 1
    },
    {
      "x": -17,
      "y": 42,
      "z": -3,
      "name": "Plant_Leaves_Azure",
      "rotation": 1
    },
    {
      "x": -17,
      "y": 43,
      "z": -3,
      "name": "Plant_Leaves_Azure",
      "rotation": 1
    },
    {
      "x": -17,
      "y": 15,
      "z": -2,
      "name": "Rock_Marble"
    },
    {
      "x": -17,
      "y": 16,
      "z": -2,
      "name": "Rock_Marble"
    },
    {
      "x": -17,
      "y": 17,
      "z": -2,
      "name": "Rock_Marble"
    },
    {
      "x": -17,
      "y": 18,
      "z": -2,
      "name": "Rock_Marble"
    },
    {
      "x": -17,
      "y": 19,
      "z": -2,
      "name": "Rock_Marble"
    },
    {
      "x": -17,
      "y": 20,
      "z": -2,
      "name": "Rock_Marble"
    },
    {
      "x": -17,
      "y": 21,
      "z": -2,
      "name": "Plant_Moss_Block_Blue"
    },
    {
      "x": -17,
      "y": 22,
      "z": -2,
      "name": "Plant_Moss_Short_Green_Dark"
    },
    {
      "x": -17,
      "y": 25,
      "z": -2,
      "name": "Plant_Moss_Wall_Blue",
      "rotation": 3
    },
    {
      "x": -17,
      "y": 34,
      "z": -2,
      "name": "Plant_Leaves_Azure",
      "rotation": 1
    },
    {
      "x": -17,
      "y": 35,
      "z": -2,
      "name": "Plant_Leaves_Azure",
      "rotation": 1
    },
    {
      "x": -17,
      "y": 39,
      "z": -2,
      "name": "Plant_Leaves_Azure",
      "rotation": 1
    },
    {
      "x": -17,
      "y": 40,
      "z": -2,
      "name": "Plant_Leaves_Azure",
      "rotation": 1
    },
    {
      "x": -17,
      "y": 41,
      "z": -2,
      "name": "Plant_Leaves_Azure",
      "rotation": 1
    },
    {
      "x": -17,
      "y": 42,
      "z": -2,
      "name": "Plant_Leaves_Azure",
      "rotation": 1
    },
    {
      "x": -17,
      "y": 16,
      "z": -1,
      "name": "Plant_Moss_Wall_Blue"
    },
    {
      "x": -17,
      "y": 17,
      "z": -1,
      "name": "Rock_Marble"
    },
    {
      "x": -17,
      "y": 18,
      "z": -1,
      "name": "Rock_Marble"
    },
    {
      "x": -17,
      "y": 19,
      "z": -1,
      "name": "Rock_Marble"
    },
    {
      "x": -17,
      "y": 20,
      "z": -1,
      "name": "Rock_Marble"
    },
    {
      "x": -17,
      "y": 21,
      "z": -1,
      "name": "Plant_Moss_Block_Blue"
    },
    {
      "x": -17,
      "y": 22,
      "z": -1,
      "name": "Plant_Moss_Short_Green_Dark"
    },
    {
      "x": -17,
      "y": 34,
      "z": -1,
      "name": "Plant_Leaves_Azure",
      "rotation": 1
    },
    {
      "x": -17,
      "y": 35,
      "z": -1,
      "name": "Plant_Leaves_Azure",
      "rotation": 1
    },
    {
      "x": -17,
      "y": 17,
      "z": 0,
      "name": "Plant_Moss_Wall_Blue"
    },
    {
      "x": -17,
      "y": 18,
      "z": 0,
      "name": "Rock_Marble"
    },
    {
      "x": -17,
      "y": 19,
      "z": 0,
      "name": "Rock_Marble"
    },
    {
      "x": -17,
      "y": 20,
      "z": 0,
      "name": "Rock_Marble"
    },
    {
      "x": -17,
      "y": 21,
      "z": 0,
      "name": "Plant_Moss_Block_Blue"
    },
    {
      "x": -17,
      "y": 22,
      "z": 0,
      "name": "Plant_Moss_Short_Green_Dark"
    },
    {
      "x": -16,
      "y": 18,
      "z": -15,
      "name": "Plant_Moss_Wall_Blue",
      "rotation": 3
    },
    {
      "x": -16,
      "y": 20,
      "z": -15,
      "name": "Plant_Moss_Wall_Blue",
      "rotation": 3
    },
    {
      "x": -16,
      "y": 18,
      "z": -14,
      "name": "Plant_Moss_Wall_Blue",
      "rotation": 3
    },
    {
      "x": -16,
      "y": 20,
      "z": -14,
      "name": "Plant_Moss_Wall_Blue",
      "rotation": 3
    },
    {
      "x": -16,
      "y": 22,
      "z": -14,
      "name": "Plant_Moss_Wall_Blue",
      "rotation": 3
    },
    {
      "x": -16,
      "y": 20,
      "z": -13,
      "name": "Plant_Moss_Wall_Blue",
      "rotation": 3
    },
    {
      "x": -16,
      "y": 18,
      "z": -12,
      "name": "Plant_Moss_Wall_Blue",
      "rotation": 3
    },
    {
      "x": -16,
      "y": 32,
      "z": -12,
      "name": "Plant_Leaves_Azure",
      "rotation": 1
    },
    {
      "x": -16,
      "y": 15,
      "z": -11,
      "name": "Rock_Marble"
    },
    {
      "x": -16,
      "y": 16,
      "z": -11,
      "name": "Rock_Marble"
    },
    {
      "x": -16,
      "y": 17,
      "z": -11,
      "name": "Rock_Marble"
    },
    {
      "x": -16,
      "y": 18,
      "z": -11,
      "name": "Rock_Marble"
    },
    {
      "x": -16,
      "y": 19,
      "z": -11,
      "name": "Rock_Marble"
    },
    {
      "x": -16,
      "y": 20,
      "z": -11,
      "name": "Rock_Marble"
    },
    {
      "x": -16,
      "y": 21,
      "z": -11,
      "name": "Rock_Marble"
    },
    {
      "x": -16,
      "y": 22,
      "z": -11,
      "name": "Rock_Marble"
    },
    {
      "x": -16,
      "y": 23,
      "z": -11,
      "name": "Plant_Moss_Rug_Lime"
    },
    {
      "x": -16,
      "y": 31,
      "z": -11,
      "name": "Plant_Leaves_Azure",
      "rotation": 1
    },
    {
      "x": -16,
      "y": 32,
      "z": -11,
      "name": "Plant_Leaves_Azure",
      "rotation": 1
    },
    {
      "x": -16,
      "y": 33,
      "z": -11,
      "name": "Plant_Leaves_Azure",
      "rotation": 1
    },
    {
      "x": -16,
      "y": 35,
      "z": -11,
      "name": "Plant_Leaves_Azure",
      "rotation": 1
    },
    {
      "x": -16,
      "y": 36,
      "z": -11,
      "name": "Plant_Leaves_Azure",
      "rotation": 1
    },
    {
      "x": -16,
      "y": 37,
      "z": -11,
      "name": "Plant_Leaves_Azure",
      "rotation": 1
    },
    {
      "x": -16,
      "y": 38,
      "z": -11,
      "name": "Plant_Leaves_Azure",
      "rotation": 1
    },
    {
      "x": -16,
      "y": 15,
      "z": -10,
      "name": "Rock_Marble"
    },
    {
      "x": -16,
      "y": 16,
      "z": -10,
      "name": "Rock_Marble"
    },
    {
      "x": -16,
      "y": 17,
      "z": -10,
      "name": "Rock_Marble"
    },
    {
      "x": -16,
      "y": 18,
      "z": -10,
      "name": "Rock_Marble"
    },
    {
      "x": -16,
      "y": 19,
      "z": -10,
      "name": "Rock_Marble"
    },
    {
      "x": -16,
      "y": 20,
      "z": -10,
      "name": "Rock_Marble"
    },
    {
      "x": -16,
      "y": 21,
      "z": -10,
      "name": "Rock_Marble"
    },
    {
      "x": -16,
      "y": 22,
      "z": -10,
      "name": "Plant_Moss_Block_Blue"
    },
    {
      "x": -16,
      "y": 23,
      "z": -10,
      "name": "Plant_Moss_Rug_Blue"
    },
    {
      "x": -16,
      "y": 32,
      "z": -10,
      "name": "Plant_Leaves_Azure",
      "rotation": 1
    },
    {
      "x": -16,
      "y": 37,
      "z": -10,
      "name": "Plant_Leaves_Azure",
      "rotation": 1
    },
    {
      "x": -16,
      "y": 38,
      "z": -10,
      "name": "Plant_Leaves_Azure",
      "rotation": 1
    },
    {
      "x": -16,
      "y": 39,
      "z": -10,
      "name": "Plant_Leaves_Azure",
      "rotation": 1
    },
    {
      "x": -16,
      "y": 40,
      "z": -10,
      "name": "Plant_Fruit_Azure",
      "rotation": 1
    },
    {
      "x": -16,
      "y": 15,
      "z": -9,
      "name": "Rock_Marble"
    },
    {
      "x": -16,
      "y": 16,
      "z": -9,
      "name": "Rock_Marble"
    },
    {
      "x": -16,
      "y": 17,
      "z": -9,
      "name": "Rock_Marble"
    },
    {
      "x": -16,
      "y": 18,
      "z": -9,
      "name": "Rock_Marble"
    },
    {
      "x": -16,
      "y": 19,
      "z": -9,
      "name": "Rock_Marble"
    },
    {
      "x": -16,
      "y": 20,
      "z": -9,
      "name": "Rock_Marble"
    },
    {
      "x": -16,
      "y": 21,
      "z": -9,
      "name": "Rock_Marble"
    },
    {
      "x": -16,
      "y": 22,
      "z": -9,
      "name": "Rock_Marble"
    },
    {
      "x": -16,
      "y": 23,
      "z": -9,
      "name": "Rock_Marble"
    },
    {
      "x": -16,
      "y": 24,
      "z": -9,
      "name": "Rock_Marble"
    },
    {
      "x": -16,
      "y": 25,
      "z": -9,
      "name": "Rock_Marble"
    },
    {
      "x": -16,
      "y": 26,
      "z": -9,
      "name": "Plant_Moss_Block_Blue"
    },
    {
      "x": -16,
      "y": 27,
      "z": -9,
      "name": "Plant_Moss_Rug_Lime"
    },
    {
      "x": -16,
      "y": 37,
      "z": -9,
      "name": "Plant_Leaves_Azure",
      "rotation": 1
    },
    {
      "x": -16,
      "y": 38,
      "z": -9,
      "name": "Plant_Leaves_Azure",
      "rotation": 1
    },
    {
      "x": -16,
      "y": 15,
      "z": -8,
      "name": "Rock_Marble"
    },
    {
      "x": -16,
      "y": 16,
      "z": -8,
      "name": "Rock_Marble"
    },
    {
      "x": -16,
      "y": 17,
      "z": -8,
      "name": "Rock_Marble"
    },
    {
      "x": -16,
      "y": 18,
      "z": -8,
      "name": "Rock_Marble"
    },
    {
      "x": -16,
      "y": 19,
      "z": -8,
      "name": "Rock_Marble"
    },
    {
      "x": -16,
      "y": 20,
      "z": -8,
      "name": "Rock_Marble"
    },
    {
      "x": -16,
      "y": 21,
      "z": -8,
      "name": "Rock_Marble"
    },
    {
      "x": -16,
      "y": 22,
      "z": -8,
      "name": "Rock_Marble"
    },
    {
      "x": -16,
      "y": 23,
      "z": -8,
      "name": "Rock_Marble"
    },
    {
      "x": -16,
      "y": 24,
      "z": -8,
      "name": "Rock_Marble"
    },
    {
      "x": -16,
      "y": 25,
      "z": -8,
      "name": "Rock_Marble"
    },
    {
      "x": -16,
      "y": 26,
      "z": -8,
      "name": "Plant_Moss_Block_Blue"
    },
    {
      "x": -16,
      "y": 27,
      "z": -8,
      "name": "Plant_Moss_Blue"
    },
    {
      "x": -16,
      "y": 30,
      "z": -8,
      "name": "Wood_Azure_Trunk_Full",
      "rotation": 1
    },
    {
      "x": -16,
      "y": 31,
      "z": -8,
      "name": "Wood_Azure_Trunk",
      "rotation": 1
    },
    {
      "x": -16,
      "y": 32,
      "z": -8,
      "name": "Wood_Azure_Trunk",
      "rotation": 1
    },
    {
      "x": -16,
      "y": 33,
      "z": -8,
      "name": "Wood_Azure_Trunk_Full",
      "rotation": 1
    },
    {
      "x": -16,
      "y": 35,
      "z": -8,
      "name": "Plant_Moss_Wall_Blue",
      "rotation": 1
    },
    {
      "x": -16,
      "y": 37,
      "z": -8,
      "name": "Wood_Azure_Branch_Long",
      "rotation": 6
    },
    {
      "x": -16,
      "y": 38,
      "z": -8,
      "name": "Plant_Moss_Wall_Blue",
      "rotation": 2
    },
    {
      "x": -16,
      "y": 41,
      "z": -8,
      "name": "Plant_Leaves_Azure",
      "rotation": 1
    },
    {
      "x": -16,
      "y": 44,
      "z": -8,
      "name": "Plant_Leaves_Azure",
      "rotation": 1
    },
    {
      "x": -16,
      "y": 45,
      "z": -8,
      "name": "Plant_Leaves_Azure",
      "rotation": 1
    },
    {
      "x": -16,
      "y": 15,
      "z": -7,
      "name": "Rock_Marble"
    },
    {
      "x": -16,
      "y": 16,
      "z": -7,
      "name": "Rock_Marble"
    },
    {
      "x": -16,
      "y": 17,
      "z": -7,
      "name": "Rock_Marble"
    },
    {
      "x": -16,
      "y": 18,
      "z": -7,
      "name": "Rock_Marble"
    },
    {
      "x": -16,
      "y": 19,
      "z": -7,
      "name": "Rock_Marble"
    },
    {
      "x": -16,
      "y": 20,
      "z": -7,
      "name": "Rock_Marble"
    },
    {
      "x": -16,
      "y": 21,
      "z": -7,
      "name": "Rock_Marble"
    },
    {
      "x": -16,
      "y": 22,
      "z": -7,
      "name": "Rock_Marble"
    },
    {
      "x": -16,
      "y": 23,
      "z": -7,
      "name": "Rock_Marble"
    },
    {
      "x": -16,
      "y": 24,
      "z": -7,
      "name": "Rock_Marble"
    },
    {
      "x": -16,
      "y": 25,
      "z": -7,
      "name": "Rock_Marble"
    },
    {
      "x": -16,
      "y": 26,
      "z": -7,
      "name": "Plant_Moss_Block_Blue"
    },
    {
      "x": -16,
      "y": 27,
      "z": -7,
      "name": "Plant_Moss_Short_Green_Dark"
    },
    {
      "x": -16,
      "y": 28,
      "z": -7,
      "name": "Wood_Azure_Trunk",
      "rotation": 1
    },
    {
      "x": -16,
      "y": 29,
      "z": -7,
      "name": "Wood_Azure_Trunk",
      "rotation": 1
    },
    {
      "x": -16,
      "y": 30,
      "z": -7,
      "name": "Wood_Azure_Trunk",
      "rotation": 1
    },
    {
      "x": -16,
      "y": 31,
      "z": -7,
      "name": "Wood_Azure_Trunk",
      "rotation": 1
    },
    {
      "x": -16,
      "y": 32,
      "z": -7,
      "name": "Wood_Azure_Trunk",
      "rotation": 1
    },
    {
      "x": -16,
      "y": 33,
      "z": -7,
      "name": "Wood_Azure_Trunk",
      "rotation": 1
    },
    {
      "x": -16,
      "y": 34,
      "z": -7,
      "name": "Wood_Azure_Trunk",
      "rotation": 1
    },
    {
      "x": -16,
      "y": 35,
      "z": -7,
      "name": "Wood_Azure_Trunk",
      "rotation": 1
    },
    {
      "x": -16,
      "y": 36,
      "z": -7,
      "name": "Wood_Azure_Trunk",
      "rotation": 1
    },
    {
      "x": -16,
      "y": 37,
      "z": -7,
      "name": "Wood_Azure_Trunk",
      "rotation": 1
    },
    {
      "x": -16,
      "y": 38,
      "z": -7,
      "name": "Wood_Azure_Trunk_Full",
      "rotation": 1
    },
    {
      "x": -16,
      "y": 39,
      "z": -7,
      "name": "Plant_Moss_Rug_Blue",
      "rotation": 1
    },
    {
      "x": -16,
      "y": 40,
      "z": -7,
      "name": "Wood_Azure_Branch_Long",
      "rotation": 5
    },
    {
      "x": -16,
      "y": 43,
      "z": -7,
      "name": "Plant_Leaves_Azure",
      "rotation": 1
    },
    {
      "x": -16,
      "y": 44,
      "z": -7,
      "name": "Plant_Leaves_Azure",
      "rotation": 1
    },
    {
      "x": -16,
      "y": 45,
      "z": -7,
      "name": "Plant_Leaves_Azure",
      "rotation": 1
    },
    {
      "x": -16,
      "y": 46,
      "z": -7,
      "name": "Plant_Leaves_Azure",
      "rotation": 1
    },
    {
      "x": -16,
      "y": 16,
      "z": -6,
      "name": "Rock_Marble"
    },
    {
      "x": -16,
      "y": 17,
      "z": -6,
      "name": "Rock_Marble"
    },
    {
      "x": -16,
      "y": 18,
      "z": -6,
      "name": "Rock_Marble"
    },
    {
      "x": -16,
      "y": 19,
      "z": -6,
      "name": "Rock_Marble"
    },
    {
      "x": -16,
      "y": 20,
      "z": -6,
      "name": "Rock_Marble"
    },
    {
      "x": -16,
      "y": 21,
      "z": -6,
      "name": "Rock_Marble"
    },
    {
      "x": -16,
      "y": 22,
      "z": -6,
      "name": "Rock_Marble"
    },
    {
      "x": -16,
      "y": 23,
      "z": -6,
      "name": "Rock_Marble"
    },
    {
      "x": -16,
      "y": 24,
      "z": -6,
      "name": "Rock_Marble"
    },
    {
      "x": -16,
      "y": 25,
      "z": -6,
      "name": "Rock_Marble"
    },
    {
      "x": -16,
      "y": 26,
      "z": -6,
      "name": "Plant_Moss_Block_Blue"
    },
    {
      "x": -16,
      "y": 27,
      "z": -6,
      "name": "Plant_Moss_Short_Green_Dark"
    },
    {
      "x": -16,
      "y": 28,
      "z": -6,
      "name": "Wood_Azure_Trunk_Full",
      "rotation": 1
    },
    {
      "x": -16,
      "y": 29,
      "z": -6,
      "name": "Wood_Azure_Trunk",
      "rotation": 1
    },
    {
      "x": -16,
      "y": 30,
      "z": -6,
      "name": "Wood_Azure_Trunk",
      "rotation": 1
    },
    {
      "x": -16,
      "y": 31,
      "z": -6,
      "name": "Wood_Azure_Trunk",
      "rotation": 1
    },
    {
      "x": -16,
      "y": 32,
      "z": -6,
      "name": "Wood_Azure_Trunk",
      "rotation": 1
    },
    {
      "x": -16,
      "y": 33,
      "z": -6,
      "name": "Wood_Azure_Trunk",
      "rotation": 1
    },
    {
      "x": -16,
      "y": 34,
      "z": -6,
      "name": "Wood_Azure_Trunk",
      "rotation": 1
    },
    {
      "x": -16,
      "y": 35,
      "z": -6,
      "name": "Wood_Azure_Trunk",
      "rotation": 1
    },
    {
      "x": -16,
      "y": 36,
      "z": -6,
      "name": "Wood_Azure_Trunk_Full",
      "rotation": 1
    },
    {
      "x": -16,
      "y": 38,
      "z": -6,
      "name": "Plant_Moss_Wall_Blue"
    },
    {
      "x": -16,
      "y": 43,
      "z": -6,
      "name": "Wood_Azure_Branch_Long",
      "rotation": 5
    },
    {
      "x": -16,
      "y": 45,
      "z": -6,
      "name": "Plant_Leaves_Azure",
      "rotation": 1
    },
    {
      "x": -16,
      "y": 46,
      "z": -6,
      "name": "Plant_Leaves_Azure",
      "rotation": 1
    },
    {
      "x": -16,
      "y": 15,
      "z": -5,
      "name": "Rock_Marble"
    },
    {
      "x": -16,
      "y": 16,
      "z": -5,
      "name": "Rock_Marble"
    },
    {
      "x": -16,
      "y": 17,
      "z": -5,
      "name": "Rock_Marble"
    },
    {
      "x": -16,
      "y": 18,
      "z": -5,
      "name": "Rock_Marble"
    },
    {
      "x": -16,
      "y": 19,
      "z": -5,
      "name": "Rock_Marble"
    },
    {
      "x": -16,
      "y": 20,
      "z": -5,
      "name": "Rock_Marble"
    },
    {
      "x": -16,
      "y": 21,
      "z": -5,
      "name": "Rock_Marble"
    },
    {
      "x": -16,
      "y": 22,
      "z": -5,
      "name": "Rock_Marble"
    },
    {
      "x": -16,
      "y": 23,
      "z": -5,
      "name": "Rock_Marble"
    },
    {
      "x": -16,
      "y": 24,
      "z": -5,
      "name": "Rock_Marble"
    },
    {
      "x": -16,
      "y": 25,
      "z": -5,
      "name": "Rock_Marble"
    },
    {
      "x": -16,
      "y": 26,
      "z": -5,
      "name": "Plant_Moss_Block_Blue"
    },
    {
      "x": -16,
      "y": 27,
      "z": -5,
      "name": "Wood_Azure_Trunk_Full",
      "rotation": 1
    },
    {
      "x": -16,
      "y": 28,
      "z": -5,
      "name": "Wood_Azure_Trunk_Full",
      "rotation": 1
    },
    {
      "x": -16,
      "y": 34,
      "z": -5,
      "name": "Wood_Azure_Trunk_Full",
      "rotation": 1
    },
    {
      "x": -16,
      "y": 36,
      "z": -5,
      "name": "Wood_Azure_Branch_Corner"
    },
    {
      "x": -16,
      "y": 37,
      "z": -5,
      "name": "Wood_Azure_Branch_Corner",
      "rotation": 9
    },
    {
      "x": -16,
      "y": 41,
      "z": -5,
      "name": "Plant_Leaves_Azure",
      "rotation": 1
    },
    {
      "x": -16,
      "y": 42,
      "z": -5,
      "name": "Plant_Leaves_Azure",
      "rotation": 1
    },
    {
      "x": -16,
      "y": 43,
      "z": -5,
      "name": "Plant_Leaves_Azure",
      "rotation": 1
    },
    {
      "x": -16,
      "y": 15,
      "z": -4,
      "name": "Rock_Marble"
    },
    {
      "x": -16,
      "y": 16,
      "z": -4,
      "name": "Rock_Marble"
    },
    {
      "x": -16,
      "y": 17,
      "z": -4,
      "name": "Rock_Marble"
    },
    {
      "x": -16,
      "y": 18,
      "z": -4,
      "name": "Rock_Marble"
    },
    {
      "x": -16,
      "y": 19,
      "z": -4,
      "name": "Rock_Marble"
    },
    {
      "x": -16,
      "y": 20,
      "z": -4,
      "name": "Rock_Marble"
    },
    {
      "x": -16,
      "y": 21,
      "z": -4,
      "name": "Rock_Marble"
    },
    {
      "x": -16,
      "y": 22,
      "z": -4,
      "name": "Rock_Marble"
    },
    {
      "x": -16,
      "y": 23,
      "z": -4,
      "name": "Rock_Marble"
    },
    {
      "x": -16,
      "y": 24,
      "z": -4,
      "name": "Rock_Marble"
    },
    {
      "x": -16,
      "y": 25,
      "z": -4,
      "name": "Plant_Moss_Block_Blue"
    },
    {
      "x": -16,
      "y": 26,
      "z": -4,
      "name": "Plant_Moss_Rug_Lime"
    },
    {
      "x": -16,
      "y": 34,
      "z": -4,
      "name": "Wood_Azure_Trunk_Full",
      "rotation": 1
    },
    {
      "x": -16,
      "y": 35,
      "z": -4,
      "name": "Plant_Moss_Rug_Blue",
      "rotation": 1
    },
    {
      "x": -16,
      "y": 39,
      "z": -4,
      "name": "Plant_Leaves_Azure",
      "rotation": 1
    },
    {
      "x": -16,
      "y": 40,
      "z": -4,
      "name": "Plant_Leaves_Azure",
      "rotation": 1
    },
    {
      "x": -16,
      "y": 41,
      "z": -4,
      "name": "Plant_Leaves_Azure",
      "rotation": 1
    },
    {
      "x": -16,
      "y": 42,
      "z": -4,
      "name": "Plant_Leaves_Azure",
      "rotation": 1
    },
    {
      "x": -16,
      "y": 43,
      "z": -4,
      "name": "Plant_Leaves_Azure",
      "rotation": 1
    },
    {
      "x": -16,
      "y": 44,
      "z": -4,
      "name": "Plant_Leaves_Azure",
      "rotation": 1
    },
    {
      "x": -16,
      "y": 15,
      "z": -3,
      "name": "Rock_Marble"
    },
    {
      "x": -16,
      "y": 16,
      "z": -3,
      "name": "Rock_Marble"
    },
    {
      "x": -16,
      "y": 17,
      "z": -3,
      "name": "Rock_Marble"
    },
    {
      "x": -16,
      "y": 18,
      "z": -3,
      "name": "Rock_Marble"
    },
    {
      "x": -16,
      "y": 19,
      "z": -3,
      "name": "Rock_Marble"
    },
    {
      "x": -16,
      "y": 20,
      "z": -3,
      "name": "Rock_Marble"
    },
    {
      "x": -16,
      "y": 21,
      "z": -3,
      "name": "Rock_Marble"
    },
    {
      "x": -16,
      "y": 22,
      "z": -3,
      "name": "Rock_Marble"
    },
    {
      "x": -16,
      "y": 23,
      "z": -3,
      "name": "Rock_Marble"
    },
    {
      "x": -16,
      "y": 24,
      "z": -3,
      "name": "Rock_Marble"
    },
    {
      "x": -16,
      "y": 25,
      "z": -3,
      "name": "Plant_Moss_Block_Blue"
    },
    {
      "x": -16,
      "y": 26,
      "z": -3,
      "name": "Plant_Moss_Rug_Lime"
    },
    {
      "x": -16,
      "y": 34,
      "z": -3,
      "name": "Wood_Azure_Branch_Long",
      "rotation": 6
    },
    {
      "x": -16,
      "y": 39,
      "z": -3,
      "name": "Plant_Leaves_Azure",
      "rotation": 1
    },
    {
      "x": -16,
      "y": 40,
      "z": -3,
      "name": "Plant_Leaves_Azure",
      "rotation": 1
    },
    {
      "x": -16,
      "y": 41,
      "z": -3,
      "name": "Plant_Leaves_Azure",
      "rotation": 1
    },
    {
      "x": -16,
      "y": 42,
      "z": -3,
      "name": "Plant_Leaves_Azure",
      "rotation": 1
    },
    {
      "x": -16,
      "y": 43,
      "z": -3,
      "name": "Plant_Leaves_Azure",
      "rotation": 1
    },
    {
      "x": -16,
      "y": 13,
      "z": -2,
      "name": "Rock_Marble_Stalactite_Large",
      "filler": 31744,
      "rotation": 8
    },
    {
      "x": -16,
      "y": 14,
      "z": -2,
      "name": "Rock_Marble_Stalactite_Large",
      "rotation": 8
    },
    {
      "x": -16,
      "y": 15,
      "z": -2,
      "name": "Rock_Marble"
    },
    {
      "x": -16,
      "y": 16,
      "z": -2,
      "name": "Rock_Marble"
    },
    {
      "x": -16,
      "y": 17,
      "z": -2,
      "name": "Rock_Marble"
    },
    {
      "x": -16,
      "y": 18,
      "z": -2,
      "name": "Rock_Marble"
    },
    {
      "x": -16,
      "y": 19,
      "z": -2,
      "name": "Rock_Marble"
    },
    {
      "x": -16,
      "y": 20,
      "z": -2,
      "name": "Rock_Marble"
    },
    {
      "x": -16,
      "y": 21,
      "z": -2,
      "name": "Rock_Marble"
    },
    {
      "x": -16,
      "y": 22,
      "z": -2,
      "name": "Rock_Marble"
    },
    {
      "x": -16,
      "y": 23,
      "z": -2,
      "name": "Rock_Marble"
    },
    {
      "x": -16,
      "y": 24,
      "z": -2,
      "name": "Rock_Marble"
    },
    {
      "x": -16,
      "y": 25,
      "z": -2,
      "name": "Plant_Moss_Block_Blue"
    },
    {
      "x": -16,
      "y": 26,
      "z": -2,
      "name": "Plant_Moss_Short_Green_Dark"
    },
    {
      "x": -16,
      "y": 33,
      "z": -2,
      "name": "Plant_Leaves_Azure",
      "rotation": 1
    },
    {
      "x": -16,
      "y": 34,
      "z": -2,
      "name": "Plant_Leaves_Azure",
      "rotation": 1
    },
    {
      "x": -16,
      "y": 35,
      "z": -2,
      "name": "Plant_Leaves_Azure",
      "rotation": 1
    },
    {
      "x": -16,
      "y": 36,
      "z": -2,
      "name": "Plant_Leaves_Azure",
      "rotation": 1
    },
    {
      "x": -16,
      "y": 40,
      "z": -2,
      "name": "Plant_Leaves_Azure",
      "rotation": 1
    },
    {
      "x": -16,
      "y": 41,
      "z": -2,
      "name": "Plant_Leaves_Azure",
      "rotation": 1
    },
    {
      "x": -16,
      "y": 42,
      "z": -2,
      "name": "Plant_Leaves_Azure",
      "rotation": 1
    },
    {
      "x": -16,
      "y": 15,
      "z": -1,
      "name": "Rock_Marble"
    },
    {
      "x": -16,
      "y": 16,
      "z": -1,
      "name": "Rock_Marble"
    },
    {
      "x": -16,
      "y": 17,
      "z": -1,
      "name": "Rock_Marble"
    },
    {
      "x": -16,
      "y": 18,
      "z": -1,
      "name": "Rock_Marble"
    },
    {
      "x": -16,
      "y": 19,
      "z": -1,
      "name": "Rock_Marble"
    },
    {
      "x": -16,
      "y": 20,
      "z": -1,
      "name": "Rock_Marble"
    },
    {
      "x": -16,
      "y": 21,
      "z": -1,
      "name": "Plant_Moss_Block_Blue"
    },
    {
      "x": -16,
      "y": 22,
      "z": -1,
      "name": "Plant_Moss_Short_Green_Dark"
    },
    {
      "x": -16,
      "y": 33,
      "z": -1,
      "name": "Plant_Leaves_Azure",
      "rotation": 1
    },
    {
      "x": -16,
      "y": 34,
      "z": -1,
      "name": "Plant_Leaves_Azure",
      "rotation": 1
    },
    {
      "x": -16,
      "y": 35,
      "z": -1,
      "name": "Plant_Leaves_Azure",
      "rotation": 1
    },
    {
      "x": -16,
      "y": 36,
      "z": -1,
      "name": "Plant_Leaves_Azure",
      "rotation": 1
    },
    {
      "x": -16,
      "y": 17,
      "z": 0,
      "name": "Rock_Marble"
    },
    {
      "x": -16,
      "y": 18,
      "z": 0,
      "name": "Rock_Marble"
    },
    {
      "x": -16,
      "y": 19,
      "z": 0,
      "name": "Rock_Marble"
    },
    {
      "x": -16,
      "y": 20,
      "z": 0,
      "name": "Rock_Marble"
    },
    {
      "x": -16,
      "y": 21,
      "z": 0,
      "name": "Plant_Moss_Block_Blue"
    },
    {
      "x": -16,
      "y": 22,
      "z": 0,
      "name": "Plant_Moss_Rug_Lime"
    },
    {
      "x": -16,
      "y": 34,
      "z": 0,
      "name": "Plant_Leaves_Azure",
      "rotation": 1
    },
    {
      "x": -16,
      "y": 35,
      "z": 0,
      "name": "Plant_Leaves_Azure",
      "rotation": 1
    },
    {
      "x": -15,
      "y": 18,
      "z": -16,
      "name": "Plant_Moss_Wall_Blue",
      "rotation": 3
    },
    {
      "x": -15,
      "y": 19,
      "z": -16,
      "name": "Plant_Moss_Wall_Blue",
      "rotation": 3
    },
    {
      "x": -15,
      "y": 20,
      "z": -16,
      "name": "Plant_Moss_Wall_Blue",
      "rotation": 3
    },
    {
      "x": -15,
      "y": 21,
      "z": -16,
      "name": "Plant_Moss_Wall_Blue",
      "rotation": 2
    },
    {
      "x": -15,
      "y": 22,
      "z": -16,
      "name": "Plant_Moss_Wall_Blue",
      "rotation": 2
    },
    {
      "x": -15,
      "y": 16,
      "z": -15,
      "name": "Rock_Marble"
    },
    {
      "x": -15,
      "y": 17,
      "z": -15,
      "name": "Rock_Marble"
    },
    {
      "x": -15,
      "y": 18,
      "z": -15,
      "name": "Rock_Marble"
    },
    {
      "x": -15,
      "y": 19,
      "z": -15,
      "name": "Rock_Marble"
    },
    {
      "x": -15,
      "y": 20,
      "z": -15,
      "name": "Rock_Marble"
    },
    {
      "x": -15,
      "y": 21,
      "z": -15,
      "name": "Rock_Marble"
    },
    {
      "x": -15,
      "y": 22,
      "z": -15,
      "name": "Rock_Marble"
    },
    {
      "x": -15,
      "y": 23,
      "z": -15,
      "name": "Plant_Moss_Block_Blue"
    },
    {
      "x": -15,
      "y": 24,
      "z": -15,
      "name": "Plant_Moss_Rug_Lime"
    },
    {
      "x": -15,
      "y": 16,
      "z": -14,
      "name": "Rock_Marble"
    },
    {
      "x": -15,
      "y": 17,
      "z": -14,
      "name": "Rock_Marble"
    },
    {
      "x": -15,
      "y": 18,
      "z": -14,
      "name": "Rock_Marble"
    },
    {
      "x": -15,
      "y": 19,
      "z": -14,
      "name": "Rock_Marble"
    },
    {
      "x": -15,
      "y": 20,
      "z": -14,
      "name": "Rock_Marble"
    },
    {
      "x": -15,
      "y": 21,
      "z": -14,
      "name": "Rock_Marble"
    },
    {
      "x": -15,
      "y": 22,
      "z": -14,
      "name": "Rock_Marble"
    },
    {
      "x": -15,
      "y": 23,
      "z": -14,
      "name": "Plant_Moss_Block_Blue"
    },
    {
      "x": -15,
      "y": 24,
      "z": -14,
      "name": "Plant_Moss_Rug_Lime"
    },
    {
      "x": -15,
      "y": 15,
      "z": -13,
      "name": "Ore_Gold_Calcite"
    },
    {
      "x": -15,
      "y": 16,
      "z": -13,
      "name": "Rock_Marble"
    },
    {
      "x": -15,
      "y": 17,
      "z": -13,
      "name": "Rock_Marble"
    },
    {
      "x": -15,
      "y": 18,
      "z": -13,
      "name": "Rock_Marble"
    },
    {
      "x": -15,
      "y": 19,
      "z": -13,
      "name": "Rock_Marble"
    },
    {
      "x": -15,
      "y": 20,
      "z": -13,
      "name": "Rock_Marble"
    },
    {
      "x": -15,
      "y": 21,
      "z": -13,
      "name": "Rock_Marble"
    },
    {
      "x": -15,
      "y": 22,
      "z": -13,
      "name": "Rock_Marble"
    },
    {
      "x": -15,
      "y": 23,
      "z": -13,
      "name": "Plant_Moss_Block_Blue"
    },
    {
      "x": -15,
      "y": 24,
      "z": -13,
      "name": "Plant_Moss_Rug_Lime"
    },
    {
      "x": -15,
      "y": 15,
      "z": -12,
      "name": "Ore_Gold_Calcite"
    },
    {
      "x": -15,
      "y": 16,
      "z": -12,
      "name": "Ore_Gold_Calcite"
    },
    {
      "x": -15,
      "y": 17,
      "z": -12,
      "name": "Rock_Marble"
    },
    {
      "x": -15,
      "y": 18,
      "z": -12,
      "name": "Rock_Marble"
    },
    {
      "x": -15,
      "y": 19,
      "z": -12,
      "name": "Rock_Marble"
    },
    {
      "x": -15,
      "y": 13,
      "z": -11,
      "name": "Rock_Marble_Stalactite_Large",
      "filler": 31744,
      "rotation": 8
    },
    {
      "x": -15,
      "y": 14,
      "z": -11,
      "name": "Rock_Marble_Stalactite_Large",
      "rotation": 8
    },
    {
      "x": -15,
      "y": 15,
      "z": -11,
      "name": "Rock_Marble"
    },
    {
      "x": -15,
      "y": 16,
      "z": -11,
      "name": "Rock_Marble"
    },
    {
      "x": -15,
      "y": 17,
      "z": -11,
      "name": "Rock_Marble"
    },
    {
      "x": -15,
      "y": 18,
      "z": -11,
      "name": "Rock_Marble"
    },
    {
      "x": -15,
      "y": 19,
      "z": -11,
      "name": "Rock_Marble"
    },
    {
      "x": -15,
      "y": 20,
      "z": -11,
      "name": "Rock_Marble"
    },
    {
      "x": -15,
      "y": 21,
      "z": -11,
      "name": "Rock_Marble"
    },
    {
      "x": -15,
      "y": 22,
      "z": -11,
      "name": "Plant_Moss_Block_Blue"
    },
    {
      "x": -15,
      "y": 23,
      "z": -11,
      "name": "Plant_Moss_Rug_Blue"
    },
    {
      "x": -15,
      "y": 35,
      "z": -11,
      "name": "Plant_Leaves_Azure",
      "rotation": 1
    },
    {
      "x": -15,
      "y": 36,
      "z": -11,
      "name": "Plant_Leaves_Azure",
      "rotation": 1
    },
    {
      "x": -15,
      "y": 37,
      "z": -11,
      "name": "Plant_Leaves_Azure",
      "rotation": 1
    },
    {
      "x": -15,
      "y": 15,
      "z": -10,
      "name": "Rock_Marble"
    },
    {
      "x": -15,
      "y": 16,
      "z": -10,
      "name": "Rock_Marble"
    },
    {
      "x": -15,
      "y": 17,
      "z": -10,
      "name": "Rock_Marble"
    },
    {
      "x": -15,
      "y": 18,
      "z": -10,
      "name": "Rock_Marble"
    },
    {
      "x": -15,
      "y": 19,
      "z": -10,
      "name": "Rock_Marble"
    },
    {
      "x": -15,
      "y": 20,
      "z": -10,
      "name": "Rock_Marble"
    },
    {
      "x": -15,
      "y": 21,
      "z": -10,
      "name": "Rock_Marble"
    },
    {
      "x": -15,
      "y": 22,
      "z": -10,
      "name": "Plant_Moss_Block_Blue"
    },
    {
      "x": -15,
      "y": 23,
      "z": -10,
      "name": "Plant_Moss_Short_Green_Dark"
    },
    {
      "x": -15,
      "y": 36,
      "z": -10,
      "name": "Plant_Leaves_Azure",
      "rotation": 1
    },
    {
      "x": -15,
      "y": 37,
      "z": -10,
      "name": "Plant_Leaves_Azure",
      "rotation": 1
    },
    {
      "x": -15,
      "y": 38,
      "z": -10,
      "name": "Plant_Leaves_Azure",
      "rotation": 1
    },
    {
      "x": -15,
      "y": 13,
      "z": -9,
      "name": "Rock_Marble_Stalactite_Large",
      "filler": 31744,
      "rotation": 8
    },
    {
      "x": -15,
      "y": 14,
      "z": -9,
      "name": "Rock_Marble_Stalactite_Large",
      "rotation": 8
    },
    {
      "x": -15,
      "y": 15,
      "z": -9,
      "name": "Rock_Marble"
    },
    {
      "x": -15,
      "y": 16,
      "z": -9,
      "name": "Rock_Marble"
    },
    {
      "x": -15,
      "y": 17,
      "z": -9,
      "name": "Rock_Marble"
    },
    {
      "x": -15,
      "y": 18,
      "z": -9,
      "name": "Rock_Marble"
    },
    {
      "x": -15,
      "y": 19,
      "z": -9,
      "name": "Rock_Marble"
    },
    {
      "x": -15,
      "y": 20,
      "z": -9,
      "name": "Rock_Marble"
    },
    {
      "x": -15,
      "y": 21,
      "z": -9,
      "name": "Rock_Marble"
    },
    {
      "x": -15,
      "y": 22,
      "z": -9,
      "name": "Rock_Marble"
    },
    {
      "x": -15,
      "y": 23,
      "z": -9,
      "name": "Rock_Marble"
    },
    {
      "x": -15,
      "y": 24,
      "z": -9,
      "name": "Rock_Marble"
    },
    {
      "x": -15,
      "y": 25,
      "z": -9,
      "name": "Rock_Marble"
    },
    {
      "x": -15,
      "y": 26,
      "z": -9,
      "name": "Plant_Moss_Block_Blue"
    },
    {
      "x": -15,
      "y": 27,
      "z": -9,
      "name": "Plant_Moss_Rug_Lime"
    },
    {
      "x": -15,
      "y": 37,
      "z": -9,
      "name": "Plant_Leaves_Azure",
      "rotation": 1
    },
    {
      "x": -15,
      "y": 38,
      "z": -9,
      "name": "Plant_Leaves_Azure",
      "rotation": 1
    },
    {
      "x": -15,
      "y": 41,
      "z": -9,
      "name": "Plant_Leaves_Azure",
      "rotation": 1
    },
    {
      "x": -15,
      "y": 15,
      "z": -8,
      "name": "Rock_Marble"
    },
    {
      "x": -15,
      "y": 16,
      "z": -8,
      "name": "Rock_Marble"
    },
    {
      "x": -15,
      "y": 17,
      "z": -8,
      "name": "Rock_Marble"
    },
    {
      "x": -15,
      "y": 18,
      "z": -8,
      "name": "Rock_Marble"
    },
    {
      "x": -15,
      "y": 19,
      "z": -8,
      "name": "Rock_Marble"
    },
    {
      "x": -15,
      "y": 20,
      "z": -8,
      "name": "Rock_Marble"
    },
    {
      "x": -15,
      "y": 21,
      "z": -8,
      "name": "Rock_Marble"
    },
    {
      "x": -15,
      "y": 22,
      "z": -8,
      "name": "Rock_Marble"
    },
    {
      "x": -15,
      "y": 23,
      "z": -8,
      "name": "Rock_Marble"
    },
    {
      "x": -15,
      "y": 24,
      "z": -8,
      "name": "Rock_Marble"
    },
    {
      "x": -15,
      "y": 25,
      "z": -8,
      "name": "Rock_Marble"
    },
    {
      "x": -15,
      "y": 26,
      "z": -8,
      "name": "Plant_Moss_Block_Blue"
    },
    {
      "x": -15,
      "y": 27,
      "z": -8,
      "name": "Wood_Azure_Trunk_Full",
      "rotation": 1
    },
    {
      "x": -15,
      "y": 28,
      "z": -8,
      "name": "Wood_Azure_Trunk",
      "rotation": 1
    },
    {
      "x": -15,
      "y": 29,
      "z": -8,
      "name": "Wood_Azure_Trunk",
      "rotation": 1
    },
    {
      "x": -15,
      "y": 30,
      "z": -8,
      "name": "Wood_Azure_Trunk_Full",
      "rotation": 1
    },
    {
      "x": -15,
      "y": 40,
      "z": -8,
      "name": "Plant_Leaves_Azure",
      "rotation": 1
    },
    {
      "x": -15,
      "y": 41,
      "z": -8,
      "name": "Plant_Leaves_Azure",
      "rotation": 1
    },
    {
      "x": -15,
      "y": 42,
      "z": -8,
      "name": "Plant_Fruit_Azure",
      "rotation": 1
    },
    {
      "x": -15,
      "y": 44,
      "z": -8,
      "name": "Plant_Leaves_Azure",
      "rotation": 1
    },
    {
      "x": -15,
      "y": 13,
      "z": -7,
      "name": "Rock_Marble_Stalactite_Large",
      "filler": 31744,
      "rotation": 8
    },
    {
      "x": -15,
      "y": 14,
      "z": -7,
      "name": "Rock_Marble_Stalactite_Large",
      "rotation": 8
    },
    {
      "x": -15,
      "y": 15,
      "z": -7,
      "name": "Rock_Marble"
    },
    {
      "x": -15,
      "y": 16,
      "z": -7,
      "name": "Rock_Marble"
    },
    {
      "x": -15,
      "y": 17,
      "z": -7,
      "name": "Rock_Marble"
    },
    {
      "x": -15,
      "y": 18,
      "z": -7,
      "name": "Rock_Marble"
    },
    {
      "x": -15,
      "y": 19,
      "z": -7,
      "name": "Rock_Marble"
    },
    {
      "x": -15,
      "y": 20,
      "z": -7,
      "name": "Rock_Marble"
    },
    {
      "x": -15,
      "y": 21,
      "z": -7,
      "name": "Rock_Marble"
    },
    {
      "x": -15,
      "y": 22,
      "z": -7,
      "name": "Rock_Marble"
    },
    {
      "x": -15,
      "y": 23,
      "z": -7,
      "name": "Rock_Marble"
    },
    {
      "x": -15,
      "y": 24,
      "z": -7,
      "name": "Rock_Marble"
    },
    {
      "x": -15,
      "y": 25,
      "z": -7,
      "name": "Rock_Marble"
    },
    {
      "x": -15,
      "y": 26,
      "z": -7,
      "name": "Plant_Moss_Block_Blue"
    },
    {
      "x": -15,
      "y": 27,
      "z": -7,
      "name": "Wood_Azure_Trunk_Full",
      "rotation": 1
    },
    {
      "x": -15,
      "y": 28,
      "z": -7,
      "name": "Wood_Azure_Trunk",
      "rotation": 1
    },
    {
      "x": -15,
      "y": 29,
      "z": -7,
      "name": "Wood_Azure_Trunk",
      "rotation": 1
    },
    {
      "x": -15,
      "y": 30,
      "z": -7,
      "name": "Wood_Azure_Trunk",
      "rotation": 1
    },
    {
      "x": -15,
      "y": 31,
      "z": -7,
      "name": "Wood_Azure_Trunk",
      "rotation": 1
    },
    {
      "x": -15,
      "y": 32,
      "z": -7,
      "name": "Wood_Azure_Trunk",
      "rotation": 1
    },
    {
      "x": -15,
      "y": 33,
      "z": -7,
      "name": "Wood_Azure_Trunk",
      "rotation": 1
    },
    {
      "x": -15,
      "y": 34,
      "z": -7,
      "name": "Wood_Azure_Trunk_Full",
      "rotation": 1
    },
    {
      "x": -15,
      "y": 38,
      "z": -7,
      "name": "Plant_Moss_Wall_Blue",
      "rotation": 1
    },
    {
      "x": -15,
      "y": 40,
      "z": -7,
      "name": "Wood_Azure_Branch_Long",
      "rotation": 5
    },
    {
      "x": -15,
      "y": 43,
      "z": -7,
      "name": "Plant_Leaves_Azure",
      "rotation": 1
    },
    {
      "x": -15,
      "y": 44,
      "z": -7,
      "name": "Plant_Leaves_Azure",
      "rotation": 1
    },
    {
      "x": -15,
      "y": 45,
      "z": -7,
      "name": "Plant_Leaves_Azure",
      "rotation": 1
    },
    {
      "x": -15,
      "y": 16,
      "z": -6,
      "name": "Rock_Marble"
    },
    {
      "x": -15,
      "y": 17,
      "z": -6,
      "name": "Rock_Marble"
    },
    {
      "x": -15,
      "y": 18,
      "z": -6,
      "name": "Rock_Marble"
    },
    {
      "x": -15,
      "y": 19,
      "z": -6,
      "name": "Rock_Marble"
    },
    {
      "x": -15,
      "y": 20,
      "z": -6,
      "name": "Rock_Marble"
    },
    {
      "x": -15,
      "y": 21,
      "z": -6,
      "name": "Rock_Marble"
    },
    {
      "x": -15,
      "y": 22,
      "z": -6,
      "name": "Rock_Marble"
    },
    {
      "x": -15,
      "y": 23,
      "z": -6,
      "name": "Rock_Marble"
    },
    {
      "x": -15,
      "y": 24,
      "z": -6,
      "name": "Rock_Marble"
    },
    {
      "x": -15,
      "y": 25,
      "z": -6,
      "name": "Rock_Marble"
    },
    {
      "x": -15,
      "y": 26,
      "z": -6,
      "name": "Plant_Moss_Block_Blue"
    },
    {
      "x": -15,
      "y": 27,
      "z": -6,
      "name": "Plant_Moss_Short_Green_Dark"
    },
    {
      "x": -15,
      "y": 28,
      "z": -6,
      "name": "Wood_Azure_Trunk_Full",
      "rotation": 1
    },
    {
      "x": -15,
      "y": 29,
      "z": -6,
      "name": "Wood_Azure_Trunk",
      "rotation": 1
    },
    {
      "x": -15,
      "y": 30,
      "z": -6,
      "name": "Wood_Azure_Trunk",
      "rotation": 1
    },
    {
      "x": -15,
      "y": 31,
      "z": -6,
      "name": "Wood_Azure_Trunk",
      "rotation": 1
    },
    {
      "x": -15,
      "y": 32,
      "z": -6,
      "name": "Wood_Azure_Trunk_Full",
      "rotation": 1
    },
    {
      "x": -15,
      "y": 43,
      "z": -6,
      "name": "Plant_Leaves_Azure",
      "rotation": 1
    },
    {
      "x": -15,
      "y": 44,
      "z": -6,
      "name": "Plant_Leaves_Azure",
      "rotation": 1
    },
    {
      "x": -15,
      "y": 45,
      "z": -6,
      "name": "Plant_Leaves_Azure",
      "rotation": 1
    },
    {
      "x": -15,
      "y": 15,
      "z": -5,
      "name": "Rock_Marble"
    },
    {
      "x": -15,
      "y": 16,
      "z": -5,
      "name": "Rock_Marble"
    },
    {
      "x": -15,
      "y": 17,
      "z": -5,
      "name": "Rock_Marble"
    },
    {
      "x": -15,
      "y": 18,
      "z": -5,
      "name": "Rock_Marble"
    },
    {
      "x": -15,
      "y": 19,
      "z": -5,
      "name": "Rock_Marble"
    },
    {
      "x": -15,
      "y": 20,
      "z": -5,
      "name": "Rock_Marble"
    },
    {
      "x": -15,
      "y": 21,
      "z": -5,
      "name": "Rock_Marble"
    },
    {
      "x": -15,
      "y": 22,
      "z": -5,
      "name": "Rock_Marble"
    },
    {
      "x": -15,
      "y": 23,
      "z": -5,
      "name": "Rock_Marble"
    },
    {
      "x": -15,
      "y": 24,
      "z": -5,
      "name": "Rock_Marble"
    },
    {
      "x": -15,
      "y": 25,
      "z": -5,
      "name": "Rock_Marble"
    },
    {
      "x": -15,
      "y": 26,
      "z": -5,
      "name": "Plant_Moss_Block_Blue"
    },
    {
      "x": -15,
      "y": 27,
      "z": -5,
      "name": "Plant_Moss_Rug_Lime"
    },
    {
      "x": -15,
      "y": 37,
      "z": -5,
      "name": "Wood_Azure_Branch_Long",
      "rotation": 5
    },
    {
      "x": -15,
      "y": 41,
      "z": -5,
      "name": "Plant_Leaves_Azure",
      "rotation": 1
    },
    {
      "x": -15,
      "y": 42,
      "z": -5,
      "name": "Plant_Leaves_Azure",
      "rotation": 1
    },
    {
      "x": -15,
      "y": 43,
      "z": -5,
      "name": "Plant_Leaves_Azure",
      "rotation": 1
    },
    {
      "x": -15,
      "y": 44,
      "z": -5,
      "name": "Plant_Leaves_Azure",
      "rotation": 1
    },
    {
      "x": -15,
      "y": 45,
      "z": -5,
      "name": "Plant_Leaves_Azure",
      "rotation": 1
    },
    {
      "x": -15,
      "y": 46,
      "z": -5,
      "name": "Plant_Fruit_Azure",
      "rotation": 1
    },
    {
      "x": -15,
      "y": 14,
      "z": -4,
      "name": "Rock_Marble"
    },
    {
      "x": -15,
      "y": 15,
      "z": -4,
      "name": "Rock_Marble"
    },
    {
      "x": -15,
      "y": 16,
      "z": -4,
      "name": "Rock_Marble"
    },
    {
      "x": -15,
      "y": 17,
      "z": -4,
      "name": "Rock_Marble"
    },
    {
      "x": -15,
      "y": 18,
      "z": -4,
      "name": "Rock_Marble"
    },
    {
      "x": -15,
      "y": 19,
      "z": -4,
      "name": "Rock_Marble"
    },
    {
      "x": -15,
      "y": 20,
      "z": -4,
      "name": "Rock_Marble"
    },
    {
      "x": -15,
      "y": 21,
      "z": -4,
      "name": "Rock_Marble"
    },
    {
      "x": -15,
      "y": 22,
      "z": -4,
      "name": "Rock_Marble"
    },
    {
      "x": -15,
      "y": 23,
      "z": -4,
      "name": "Rock_Marble"
    },
    {
      "x": -15,
      "y": 24,
      "z": -4,
      "name": "Rock_Marble"
    },
    {
      "x": -15,
      "y": 25,
      "z": -4,
      "name": "Plant_Moss_Block_Blue"
    },
    {
      "x": -15,
      "y": 26,
      "z": -4,
      "name": "Plant_Moss_Short_Green_Dark"
    },
    {
      "x": -15,
      "y": 34,
      "z": -4,
      "name": "Plant_Moss_Wall_Blue",
      "rotation": 1
    },
    {
      "x": -15,
      "y": 40,
      "z": -4,
      "name": "Plant_Leaves_Azure",
      "rotation": 1
    },
    {
      "x": -15,
      "y": 41,
      "z": -4,
      "name": "Plant_Leaves_Azure",
      "rotation": 1
    },
    {
      "x": -15,
      "y": 42,
      "z": -4,
      "name": "Plant_Leaves_Azure",
      "rotation": 1
    },
    {
      "x": -15,
      "y": 43,
      "z": -4,
      "name": "Plant_Leaves_Azure",
      "rotation": 1
    },
    {
      "x": -15,
      "y": 44,
      "z": -4,
      "name": "Plant_Leaves_Azure",
      "rotation": 1
    },
    {
      "x": -15,
      "y": 15,
      "z": -3,
      "name": "Rock_Marble"
    },
    {
      "x": -15,
      "y": 16,
      "z": -3,
      "name": "Rock_Marble"
    },
    {
      "x": -15,
      "y": 17,
      "z": -3,
      "name": "Rock_Marble"
    },
    {
      "x": -15,
      "y": 18,
      "z": -3,
      "name": "Rock_Marble"
    },
    {
      "x": -15,
      "y": 19,
      "z": -3,
      "name": "Rock_Marble"
    },
    {
      "x": -15,
      "y": 20,
      "z": -3,
      "name": "Rock_Marble"
    },
    {
      "x": -15,
      "y": 21,
      "z": -3,
      "name": "Rock_Marble"
    },
    {
      "x": -15,
      "y": 22,
      "z": -3,
      "name": "Rock_Marble"
    },
    {
      "x": -15,
      "y": 23,
      "z": -3,
      "name": "Rock_Marble"
    },
    {
      "x": -15,
      "y": 24,
      "z": -3,
      "name": "Rock_Marble"
    },
    {
      "x": -15,
      "y": 25,
      "z": -3,
      "name": "Plant_Moss_Block_Blue"
    },
    {
      "x": -15,
      "y": 26,
      "z": -3,
      "name": "Plant_Moss_Short_Green_Dark"
    },
    {
      "x": -15,
      "y": 36,
      "z": -3,
      "name": "Plant_Leaves_Azure",
      "rotation": 1
    },
    {
      "x": -15,
      "y": 37,
      "z": -3,
      "name": "Plant_Leaves_Azure",
      "rotation": 1
    },
    {
      "x": -15,
      "y": 41,
      "z": -3,
      "name": "Plant_Leaves_Azure",
      "rotation": 1
    },
    {
      "x": -15,
      "y": 42,
      "z": -3,
      "name": "Plant_Leaves_Azure",
      "rotation": 1
    },
    {
      "x": -15,
      "y": 14,
      "z": -2,
      "name": "Rock_Marble"
    },
    {
      "x": -15,
      "y": 15,
      "z": -2,
      "name": "Rock_Marble"
    },
    {
      "x": -15,
      "y": 16,
      "z": -2,
      "name": "Rock_Marble"
    },
    {
      "x": -15,
      "y": 17,
      "z": -2,
      "name": "Rock_Marble"
    },
    {
      "x": -15,
      "y": 18,
      "z": -2,
      "name": "Rock_Marble"
    },
    {
      "x": -15,
      "y": 19,
      "z": -2,
      "name": "Rock_Marble"
    },
    {
      "x": -15,
      "y": 20,
      "z": -2,
      "name": "Rock_Marble"
    },
    {
      "x": -15,
      "y": 21,
      "z": -2,
      "name": "Rock_Marble"
    },
    {
      "x": -15,
      "y": 22,
      "z": -2,
      "name": "Rock_Marble"
    },
    {
      "x": -15,
      "y": 23,
      "z": -2,
      "name": "Rock_Marble"
    },
    {
      "x": -15,
      "y": 24,
      "z": -2,
      "name": "Rock_Marble"
    },
    {
      "x": -15,
      "y": 25,
      "z": -2,
      "name": "Plant_Moss_Block_Blue"
    },
    {
      "x": -15,
      "y": 26,
      "z": -2,
      "name": "Plant_Moss_Rug_Lime"
    },
    {
      "x": -15,
      "y": 33,
      "z": -2,
      "name": "Plant_Leaves_Azure",
      "rotation": 1
    },
    {
      "x": -15,
      "y": 34,
      "z": -2,
      "name": "Plant_Leaves_Azure",
      "rotation": 1
    },
    {
      "x": -15,
      "y": 35,
      "z": -2,
      "name": "Plant_Leaves_Azure",
      "rotation": 1
    },
    {
      "x": -15,
      "y": 36,
      "z": -2,
      "name": "Plant_Leaves_Azure",
      "rotation": 1
    },
    {
      "x": -15,
      "y": 13,
      "z": -1,
      "name": "Rock_Marble"
    },
    {
      "x": -15,
      "y": 14,
      "z": -1,
      "name": "Rock_Marble"
    },
    {
      "x": -15,
      "y": 15,
      "z": -1,
      "name": "Rock_Marble"
    },
    {
      "x": -15,
      "y": 16,
      "z": -1,
      "name": "Rock_Marble"
    },
    {
      "x": -15,
      "y": 17,
      "z": -1,
      "name": "Rock_Marble"
    },
    {
      "x": -15,
      "y": 18,
      "z": -1,
      "name": "Rock_Marble"
    },
    {
      "x": -15,
      "y": 19,
      "z": -1,
      "name": "Rock_Marble"
    },
    {
      "x": -15,
      "y": 20,
      "z": -1,
      "name": "Rock_Marble"
    },
    {
      "x": -15,
      "y": 21,
      "z": -1,
      "name": "Rock_Marble"
    },
    {
      "x": -15,
      "y": 22,
      "z": -1,
      "name": "Rock_Marble"
    },
    {
      "x": -15,
      "y": 23,
      "z": -1,
      "name": "Rock_Marble"
    },
    {
      "x": -15,
      "y": 24,
      "z": -1,
      "name": "Rock_Marble"
    },
    {
      "x": -15,
      "y": 25,
      "z": -1,
      "name": "Plant_Moss_Block_Blue"
    },
    {
      "x": -15,
      "y": 26,
      "z": -1,
      "name": "Plant_Moss_Rug_Blue"
    },
    {
      "x": -15,
      "y": 33,
      "z": -1,
      "name": "Plant_Leaves_Azure",
      "rotation": 1
    },
    {
      "x": -15,
      "y": 34,
      "z": -1,
      "name": "Plant_Leaves_Azure",
      "rotation": 1
    },
    {
      "x": -15,
      "y": 35,
      "z": -1,
      "name": "Plant_Leaves_Azure",
      "rotation": 1
    },
    {
      "x": -15,
      "y": 36,
      "z": -1,
      "name": "Plant_Leaves_Azure",
      "rotation": 1
    },
    {
      "x": -15,
      "y": 37,
      "z": -1,
      "name": "Plant_Fruit_Azure",
      "rotation": 1
    },
    {
      "x": -15,
      "y": 14,
      "z": 0,
      "name": "Rock_Marble"
    },
    {
      "x": -15,
      "y": 17,
      "z": 0,
      "name": "Rock_Marble"
    },
    {
      "x": -15,
      "y": 18,
      "z": 0,
      "name": "Rock_Marble"
    },
    {
      "x": -15,
      "y": 19,
      "z": 0,
      "name": "Rock_Marble"
    },
    {
      "x": -15,
      "y": 20,
      "z": 0,
      "name": "Rock_Marble"
    },
    {
      "x": -15,
      "y": 21,
      "z": 0,
      "name": "Plant_Moss_Block_Blue"
    },
    {
      "x": -15,
      "y": 22,
      "z": 0,
      "name": "Plant_Moss_Rug_Blue"
    },
    {
      "x": -15,
      "y": 34,
      "z": 0,
