{
  "version": 8,
  "blockIdVersion": 11,
  "anchorX": 0,
  "anchorY": 0,
  "anchorZ": 0,
  "blocks": [
    {
      "x": -14,
      "y": 15,
      "z": -13,
      "name": "Plant_Moss_Wall_Yellow",
      "rotation": 3
    },
    {
      "x": -13,
      "y": 15,
      "z": -15,
      "name": "Plant_Moss_Wall_Yellow",
      "rotation": 3
    },
    {
      "x": -13,
      "y": 13,
      "z": -14,
      "name": "Plant_Moss_Wall_Yellow",
      "rotation": 3
    },
    {
      "x": -13,
      "y": 14,
      "z": -14,
      "name": "Plant_Moss_Wall_Yellow",
      "rotation": 3
    },
    {
      "x": -13,
      "y": 12,
      "z": -13,
      "name": "Rock_Stone_Stalactite_Large",
      "filler": 31744,
      "rotation": 8
    },
    {
      "x": -13,
      "y": 13,
      "z": -13,
      "name": "Rock_Stone_Stalactite_Large",
      "rotation": 8
    },
    {
      "x": -13,
      "y": 14,
      "z": -13,
      "name": "Rock_Stone"
    },
    {
      "x": -13,
      "y": 15,
      "z": -13,
      "name": "Soil_Grass_Dry_Full"
    },
    {
      "x": -13,
      "y": 16,
      "z": -13,
      "name": "Plant_Moss_Rug_Yellow"
    },
    {
      "x": -13,
      "y": 16,
      "z": -12,
      "name": "Plant_Moss_Wall_Yellow",
      "rotation": 3
    },
    {
      "x": -12,
      "y": 15,
      "z": -17,
      "name": "Plant_Moss_Wall_Yellow",
      "rotation": 3
    },
    {
      "x": -12,
      "y": 15,
      "z": -16,
      "name": "Plant_Moss_Wall_Yellow",
      "rotation": 3
    },
    {
      "x": -12,
      "y": 14,
      "z": -15,
      "name": "Rock_Stone"
    },
    {
      "x": -12,
      "y": 15,
      "z": -15,
      "name": "Soil_Grass_Dry_Full"
    },
    {
      "x": -12,
      "y": 16,
      "z": -15,
      "name": "Plant_Moss_Wall_Yellow",
      "rotation": 3
    },
    {
      "x": -12,
      "y": 13,
      "z": -14,
      "name": "Rock_Stone"
    },
    {
      "x": -12,
      "y": 14,
      "z": -14,
      "name": "Rock_Stone"
    },
    {
      "x": -12,
      "y": 15,
      "z": -14,
      "name": "Rock_Stone_Mossy"
    },
    {
      "x": -12,
      "y": 16,
      "z": -14,
      "name": "Soil_Grass_Dry_Full"
    },
    {
      "x": -12,
      "y": 17,
      "z": -14,
      "name": "Plant_Moss_Rug_Yellow"
    },
    {
      "x": -12,
      "y": 12,
      "z": -13,
      "name": "Rock_Stone"
    },
    {
      "x": -12,
      "y": 13,
      "z": -13,
      "name": "Rock_Stone_Mossy"
    },
    {
      "x": -12,
      "y": 14,
      "z": -13,
      "name": "Rock_Stone"
    },
    {
      "x": -12,
      "y": 15,
      "z": -13,
      "name": "Soil_Grass_Dry_Full"
    },
    {
      "x": -12,
      "y": 16,
      "z": -13,
      "name": "Plant_Moss_Wall_Yellow",
      "rotation": 3
    },
    {
      "x": -12,
      "y": 11,
      "z": -12,
      "name": "Rock_Stone_Stalactite_Large",
      "filler": 31744,
      "rotation": 8
    },
    {
      "x": -12,
      "y": 12,
      "z": -12,
      "name": "Rock_Stone_Stalactite_Large",
      "rotation": 8
    },
    {
      "x": -12,
      "y": 13,
      "z": -12,
      "name": "Rock_Stone"
    },
    {
      "x": -12,
      "y": 14,
      "z": -12,
      "name": "Rock_Stone"
    },
    {
      "x": -12,
      "y": 15,
      "z": -12,
      "name": "Rock_Stone"
    },
    {
      "x": -12,
      "y": 16,
      "z": -12,
      "name": "Soil_Grass_Dry_Full"
    },
    {
      "x": -12,
      "y": 17,
      "z": -12,
      "name": "Plant_Moss_Rug_Yellow"
    },
    {
      "x": -12,
      "y": 14,
      "z": -11,
      "name": "Plant_Moss_Wall_Yellow",
      "rotation": 3
    },
    {
      "x": -12,
      "y": 15,
      "z": -11,
      "name": "Plant_Moss_Wall_Yellow",
      "rotation": 3
    },
    {
      "x": -12,
      "y": 22,
      "z": -8,
      "name": "Plant_Leaves_Dry"
    },
    {
      "x": -12,
      "y": 22,
      "z": -7,
      "name": "Plant_Leaves_Dry"
    },
    {
      "x": -11,
      "y": 14,
      "z": -17,
      "name": "Rock_Stone"
    },
    {
      "x": -11,
      "y": 15,
      "z": -17,
      "name": "Soil_Grass_Dry_Full"
    },
    {
      "x": -11,
      "y": 16,
      "z": -17,
      "name": "Plant_Moss_Wall_Yellow",
      "rotation": 3
    },
    {
      "x": -11,
      "y": 14,
      "z": -16,
      "name": "Rock_Stone"
    },
    {
      "x": -11,
      "y": 15,
      "z": -16,
      "name": "Soil_Grass_Dry_Full"
    },
    {
      "x": -11,
      "y": 16,
      "z": -16,
      "name": "Plant_Moss_Rug_Yellow"
    },
    {
      "x": -11,
      "y": 13,
      "z": -15,
      "name": "Rock_Stone"
    },
    {
      "x": -11,
      "y": 14,
      "z": -15,
      "name": "Rock_Stone"
    },
    {
      "x": -11,
      "y": 15,
      "z": -15,
      "name": "Rock_Stone"
    },
    {
      "x": -11,
      "y": 16,
      "z": -15,
      "name": "Soil_Grass_Dry_Full"
    },
    {
      "x": -11,
      "y": 17,
      "z": -15,
      "name": "Plant_Moss_Rug_Yellow"
    },
    {
      "x": -11,
      "y": 11,
      "z": -14,
      "name": "Plant_Moss_Cave_Yellow",
      "rotation": 8
    },
    {
      "x": -11,
      "y": 12,
      "z": -14,
      "name": "Rock_Stone"
    },
    {
      "x": -11,
      "y": 13,
      "z": -14,
      "name": "Rock_Stone"
    },
    {
      "x": -11,
      "y": 14,
      "z": -14,
      "name": "Rock_Stone"
    },
    {
      "x": -11,
      "y": 15,
      "z": -14,
      "name": "Rock_Stone"
    },
    {
      "x": -11,
      "y": 16,
      "z": -14,
      "name": "Soil_Grass_Dry_Full"
    },
    {
      "x": -11,
      "y": 17,
      "z": -14,
      "name": "Plant_Moss_Rug_Yellow"
    },
    {
      "x": -11,
      "y": 12,
      "z": -13,
      "name": "Rock_Stone"
    },
    {
      "x": -11,
      "y": 13,
      "z": -13,
      "name": "Rock_Stone"
    },
    {
      "x": -11,
      "y": 14,
      "z": -13,
      "name": "Rock_Stone"
    },
    {
      "x": -11,
      "y": 15,
      "z": -13,
      "name": "Rock_Stone"
    },
    {
      "x": -11,
      "y": 16,
      "z": -13,
      "name": "Soil_Grass_Dry_Full"
    },
    {
      "x": -11,
      "y": 11,
      "z": -12,
      "name": "Plant_Moss_Cave_Yellow",
      "rotation": 8
    },
    {
      "x": -11,
      "y": 12,
      "z": -12,
      "name": "Rock_Stone"
    },
    {
      "x": -11,
      "y": 13,
      "z": -12,
      "name": "Rock_Stone"
    },
    {
      "x": -11,
      "y": 14,
      "z": -12,
      "name": "Rock_Stone"
    },
    {
      "x": -11,
      "y": 15,
      "z": -12,
      "name": "Rock_Stone_Mossy"
    },
    {
      "x": -11,
      "y": 16,
      "z": -12,
      "name": "Soil_Grass_Dry_Full"
    },
    {
      "x": -11,
      "y": 17,
      "z": -12,
      "name": "Plant_Moss_Rug_Yellow"
    },
    {
      "x": -11,
      "y": 12,
      "z": -11,
      "name": "Ore_Copper_Stone"
    },
    {
      "x": -11,
      "y": 13,
      "z": -11,
      "name": "Rock_Stone"
    },
    {
      "x": -11,
      "y": 14,
      "z": -11,
      "name": "Rock_Stone"
    },
    {
      "x": -11,
      "y": 15,
      "z": -11,
      "name": "Soil_Grass_Dry_Full"
    },
    {
      "x": -11,
      "y": 16,
      "z": -11,
      "name": "Plant_Moss_Wall_Yellow",
      "rotation": 3
    },
    {
      "x": -11,
      "y": 15,
      "z": -10,
      "name": "Plant_Moss_Wall_Yellow",
      "rotation": 3
    },
    {
      "x": -11,
      "y": 16,
      "z": -10,
      "name": "Plant_Moss_Wall_Yellow",
      "rotation": 3
    },
    {
      "x": -11,
      "y": 22,
      "z": -10,
      "name": "Plant_Leaves_Dry"
    },
    {
      "x": -11,
      "y": 16,
      "z": -9,
      "name": "Plant_Moss_Wall_Yellow",
      "rotation": 3
    },
    {
      "x": -11,
      "y": 22,
      "z": -9,
      "name": "Plant_Leaves_Dry"
    },
    {
      "x": -11,
      "y": 16,
      "z": -8,
      "name": "Plant_Moss_Wall_Yellow",
      "rotation": 3
    },
    {
      "x": -11,
      "y": 22,
      "z": -8,
      "name": "Plant_Leaves_Dry"
    },
    {
      "x": -11,
      "y": 16,
      "z": -7,
      "name": "Plant_Moss_Wall_Yellow",
      "rotation": 3
    },
    {
      "x": -11,
      "y": 22,
      "z": -7,
      "name": "Plant_Leaves_Dry"
    },
    {
      "x": -11,
      "y": 22,
      "z": -6,
      "name": "Plant_Leaves_Dry"
    },
    {
      "x": -11,
      "y": 22,
      "z": -5,
      "name": "Plant_Leaves_Dry"
    },
    {
      "x": -10,
      "y": 16,
      "z": -18,
      "name": "Plant_Moss_Wall_Yellow",
      "rotation": 2
    },
    {
      "x": -10,
      "y": 13,
      "z": -17,
      "name": "Plant_Moss_Cave_Yellow",
      "rotation": 8
    },
    {
      "x": -10,
      "y": 14,
      "z": -17,
      "name": "Ore_Copper_Stone"
    },
    {
      "x": -10,
      "y": 15,
      "z": -17,
      "name": "Rock_Stone"
    },
    {
      "x": -10,
      "y": 16,
      "z": -17,
      "name": "Rock_Stone"
    },
    {
      "x": -10,
      "y": 17,
      "z": -17,
      "name": "Soil_Grass_Dry_Full"
    },
    {
      "x": -10,
      "y": 18,
      "z": -17,
      "name": "Plant_Moss_Rug_Yellow"
    },
    {
      "x": -10,
      "y": 13,
      "z": -16,
      "name": "Rock_Stone"
    },
    {
      "x": -10,
      "y": 14,
      "z": -16,
      "name": "Ore_Copper_Stone"
    },
    {
      "x": -10,
      "y": 15,
      "z": -16,
      "name": "Rock_Stone_Mossy"
    },
    {
      "x": -10,
      "y": 16,
      "z": -16,
      "name": "Rock_Stone"
    },
    {
      "x": -10,
      "y": 17,
      "z": -16,
      "name": "Soil_Grass_Dry_Full"
    },
    {
      "x": -10,
      "y": 18,
      "z": -16,
      "name": "Plant_Moss_Rug_Yellow"
    },
    {
      "x": -10,
      "y": 12,
      "z": -15,
      "name": "Rock_Stone"
    },
    {
      "x": -10,
      "y": 13,
      "z": -15,
      "name": "Rock_Stone"
    },
    {
      "x": -10,
      "y": 14,
      "z": -15,
      "name": "Rock_Stone"
    },
    {
      "x": -10,
      "y": 15,
      "z": -15,
      "name": "Rock_Stone"
    },
    {
      "x": -10,
      "y": 16,
      "z": -15,
      "name": "Rock_Stone"
    },
    {
      "x": -10,
      "y": 17,
      "z": -15,
      "name": "Soil_Grass_Dry_Full"
    },
    {
      "x": -10,
      "y": 11,
      "z": -14,
      "name": "Rock_Stone"
    },
    {
      "x": -10,
      "y": 12,
      "z": -14,
      "name": "Rock_Stone"
    },
    {
      "x": -10,
      "y": 13,
      "z": -14,
      "name": "Rock_Stone"
    },
    {
      "x": -10,
      "y": 14,
      "z": -14,
      "name": "Rock_Stone"
    },
    {
      "x": -10,
      "y": 15,
      "z": -14,
      "name": "Rock_Stone"
    },
    {
      "x": -10,
      "y": 16,
      "z": -14,
      "name": "Rock_Stone"
    },
    {
      "x": -10,
      "y": 17,
      "z": -14,
      "name": "Rock_Stone"
    },
    {
      "x": -10,
      "y": 18,
      "z": -14,
      "name": "Soil_Grass_Dry_Full"
    },
    {
      "x": -10,
      "y": 11,
      "z": -13,
      "name": "Rock_Stone"
    },
    {
      "x": -10,
      "y": 12,
      "z": -13,
      "name": "Rock_Stone"
    },
    {
      "x": -10,
      "y": 13,
      "z": -13,
      "name": "Rock_Stone"
    },
    {
      "x": -10,
      "y": 14,
      "z": -13,
      "name": "Rock_Stone"
    },
    {
      "x": -10,
      "y": 15,
      "z": -13,
      "name": "Ore_Copper_Stone"
    },
    {
      "x": -10,
      "y": 16,
      "z": -13,
      "name": "Rock_Stone"
    },
    {
      "x": -10,
      "y": 17,
      "z": -13,
      "name": "Rock_Stone"
    },
    {
      "x": -10,
      "y": 18,
      "z": -13,
      "name": "Soil_Grass_Dry_Full"
    },
    {
      "x": -10,
      "y": 10,
      "z": -12,
      "name": "Plant_Moss_Cave_Yellow",
      "rotation": 8
    },
    {
      "x": -10,
      "y": 11,
      "z": -12,
      "name": "Rock_Stone"
    },
    {
      "x": -10,
      "y": 12,
      "z": -12,
      "name": "Rock_Stone"
    },
    {
      "x": -10,
      "y": 13,
      "z": -12,
      "name": "Rock_Stone"
    },
    {
      "x": -10,
      "y": 14,
      "z": -12,
      "name": "Rock_Stone"
    },
    {
      "x": -10,
      "y": 15,
      "z": -12,
      "name": "Ore_Copper_Stone"
    },
    {
      "x": -10,
      "y": 16,
      "z": -12,
      "name": "Rock_Stone"
    },
    {
      "x": -10,
      "y": 17,
      "z": -12,
      "name": "Rock_Stone"
    },
    {
      "x": -10,
      "y": 18,
      "z": -12,
      "name": "Soil_Grass_Dry_Full"
    },
    {
      "x": -10,
      "y": 11,
      "z": -11,
      "name": "Rock_Stone"
    },
    {
      "x": -10,
      "y": 12,
      "z": -11,
      "name": "Rock_Stone"
    },
    {
      "x": -10,
      "y": 13,
      "z": -11,
      "name": "Rock_Stone"
    },
    {
      "x": -10,
      "y": 14,
      "z": -11,
      "name": "Ore_Copper_Stone"
    },
    {
      "x": -10,
      "y": 15,
      "z": -11,
      "name": "Rock_Stone"
    },
    {
      "x": -10,
      "y": 16,
      "z": -11,
      "name": "Rock_Stone"
    },
    {
      "x": -10,
      "y": 17,
      "z": -11,
      "name": "Soil_Grass_Dry_Full"
    },
    {
      "x": -10,
      "y": 22,
      "z": -11,
      "name": "Plant_Leaves_Dry"
    },
    {
      "x": -10,
      "y": 11,
      "z": -10,
      "name": "Plant_Moss_Cave_Yellow",
      "rotation": 8
    },
    {
      "x": -10,
      "y": 12,
      "z": -10,
      "name": "Rock_Stone"
    },
    {
      "x": -10,
      "y": 13,
      "z": -10,
      "name": "Ore_Copper_Stone"
    },
    {
      "x": -10,
      "y": 14,
      "z": -10,
      "name": "Rock_Stone_Mossy"
    },
    {
      "x": -10,
      "y": 15,
      "z": -10,
      "name": "Rock_Stone_Mossy"
    },
    {
      "x": -10,
      "y": 16,
      "z": -10,
      "name": "Soil_Grass_Dry_Full"
    },
    {
      "x": -10,
      "y": 22,
      "z": -10,
      "name": "Plant_Leaves_Dry"
    },
    {
      "x": -10,
      "y": 10,
      "z": -9,
      "name": "Plant_Moss_Cave_Yellow",
      "rotation": 8
    },
    {
      "x": -10,
      "y": 11,
      "z": -9,
      "name": "Rock_Stone"
    },
    {
      "x": -10,
      "y": 12,
      "z": -9,
      "name": "Rock_Stone"
    },
    {
      "x": -10,
      "y": 13,
      "z": -9,
      "name": "Rock_Stone"
    },
    {
      "x": -10,
      "y": 14,
      "z": -9,
      "name": "Rock_Stone"
    },
    {
      "x": -10,
      "y": 15,
      "z": -9,
      "name": "Rock_Stone"
    },
    {
      "x": -10,
      "y": 16,
      "z": -9,
      "name": "Soil_Grass_Dry_Full"
    },
    {
      "x": -10,
      "y": 17,
      "z": -9,
      "name": "Plant_Moss_Yellow"
    },
    {
      "x": -10,
      "y": 22,
      "z": -9,
      "name": "Plant_Leaves_Dry"
    },
    {
      "x": -10,
      "y": 12,
      "z": -8,
      "name": "Rock_Stone"
    },
    {
      "x": -10,
      "y": 13,
      "z": -8,
      "name": "Rock_Stone"
    },
    {
      "x": -10,
      "y": 14,
      "z": -8,
      "name": "Rock_Stone"
    },
    {
      "x": -10,
      "y": 15,
      "z": -8,
      "name": "Rock_Stone"
    },
    {
      "x": -10,
      "y": 16,
      "z": -8,
      "name": "Rock_Stone"
    },
    {
      "x": -10,
      "y": 17,
      "z": -8,
      "name": "Soil_Grass_Dry_Full"
    },
    {
      "x": -10,
      "y": 22,
      "z": -8,
      "name": "Plant_Leaves_Dry"
    },
    {
      "x": -10,
      "y": 14,
      "z": -7,
      "name": "Rock_Stone_Mossy"
    },
    {
      "x": -10,
      "y": 15,
      "z": -7,
      "name": "Rock_Stone_Mossy"
    },
    {
      "x": -10,
      "y": 16,
      "z": -7,
      "name": "Soil_Grass_Dry_Full"
    },
    {
      "x": -10,
      "y": 17,
      "z": -7,
      "name": "Plant_Moss_Rug_Yellow"
    },
    {
      "x": -10,
      "y": 22,
      "z": -7,
      "name": "Plant_Leaves_Dry"
    },
    {
      "x": -10,
      "y": 16,
      "z": -6,
      "name": "Plant_Moss_Wall_Yellow",
      "rotation": 3
    },
    {
      "x": -10,
      "y": 22,
      "z": -6,
      "name": "Plant_Leaves_Dry"
    },
    {
      "x": -10,
      "y": 22,
      "z": -5,
      "name": "Plant_Leaves_Dry"
    },
    {
      "x": -10,
      "y": 22,
      "z": -4,
      "name": "Plant_Leaves_Dry"
    },
    {
      "x": -9,
      "y": 15,
      "z": -18,
      "name": "Plant_Moss_Wall_Yellow",
      "rotation": 2
    },
    {
      "x": -9,
      "y": 16,
      "z": -18,
      "name": "Plant_Moss_Wall_Yellow",
      "rotation": 2
    },
    {
      "x": -9,
      "y": 17,
      "z": -18,
      "name": "Plant_Moss_Wall_Yellow",
      "rotation": 2
    },
    {
      "x": -9,
      "y": 14,
      "z": -17,
      "name": "Rock_Stone"
    },
    {
      "x": -9,
      "y": 15,
      "z": -17,
      "name": "Rock_Stone"
    },
    {
      "x": -9,
      "y": 16,
      "z": -17,
      "name": "Rock_Stone_Mossy"
    },
    {
      "x": -9,
      "y": 17,
      "z": -17,
      "name": "Soil_Grass_Dry_Full"
    },
    {
      "x": -9,
      "y": 18,
      "z": -17,
      "name": "Plant_Moss_Rug_Yellow"
    },
    {
      "x": -9,
      "y": 13,
      "z": -16,
      "name": "Rock_Stone"
    },
    {
      "x": -9,
      "y": 14,
      "z": -16,
      "name": "Rock_Stone"
    },
    {
      "x": -9,
      "y": 15,
      "z": -16,
      "name": "Rock_Stone"
    },
    {
      "x": -9,
      "y": 16,
      "z": -16,
      "name": "Rock_Stone"
    },
    {
      "x": -9,
      "y": 17,
      "z": -16,
      "name": "Rock_Stone"
    },
    {
      "x": -9,
      "y": 18,
      "z": -16,
      "name": "Soil_Grass_Dry_Full"
    },
    {
      "x": -9,
      "y": 19,
      "z": -16,
      "name": "Plant_Moss_Rug_Yellow"
    },
    {
      "x": -9,
      "y": 10,
      "z": -15,
      "name": "Plant_Moss_Cave_Yellow",
      "rotation": 8
    },
    {
      "x": -9,
      "y": 11,
      "z": -15,
      "name": "Rock_Stone"
    },
    {
      "x": -9,
      "y": 12,
      "z": -15,
      "name": "Rock_Stone"
    },
    {
      "x": -9,
      "y": 13,
      "z": -15,
      "name": "Rock_Stone"
    },
    {
      "x": -9,
      "y": 14,
      "z": -15,
      "name": "Rock_Stone"
    },
    {
      "x": -9,
      "y": 15,
      "z": -15,
      "name": "Rock_Stone"
    },
    {
      "x": -9,
      "y": 16,
      "z": -15,
      "name": "Rock_Stone"
    },
    {
      "x": -9,
      "y": 17,
      "z": -15,
      "name": "Rock_Stone"
    },
    {
      "x": -9,
      "y": 18,
      "z": -15,
      "name": "Rock_Stone"
    },
    {
      "x": -9,
      "y": 19,
      "z": -15,
      "name": "Soil_Grass_Dry_Full"
    },
    {
      "x": -9,
      "y": 20,
      "z": -15,
      "name": "Plant_Bush_Arid"
    },
    {
      "x": -9,
      "y": 10,
      "z": -14,
      "name": "Rock_Stone"
    },
    {
      "x": -9,
      "y": 11,
      "z": -14,
      "name": "Rock_Stone"
    },
    {
      "x": -9,
      "y": 12,
      "z": -14,
      "name": "Rock_Stone"
    },
    {
      "x": -9,
      "y": 13,
      "z": -14,
      "name": "Rock_Stone"
    },
    {
      "x": -9,
      "y": 14,
      "z": -14,
      "name": "Rock_Stone"
    },
    {
      "x": -9,
      "y": 15,
      "z": -14,
      "name": "Rock_Stone"
    },
    {
      "x": -9,
      "y": 16,
      "z": -14,
      "name": "Rock_Stone"
    },
    {
      "x": -9,
      "y": 17,
      "z": -14,
      "name": "Rock_Stone"
    },
    {
      "x": -9,
      "y": 18,
      "z": -14,
      "name": "Rock_Stone"
    },
    {
      "x": -9,
      "y": 19,
      "z": -14,
      "name": "Rock_Stone"
    },
    {
      "x": -9,
      "y": 20,
      "z": -14,
      "name": "Soil_Grass_Dry_Full"
    },
    {
      "x": -9,
      "y": 21,
      "z": -14,
      "name": "Plant_Moss_Yellow"
    },
    {
      "x": -9,
      "y": 7,
      "z": -13,
      "name": "Rock_Stone_Stalactite_Large",
      "filler": 31744,
      "rotation": 8
    },
    {
      "x": -9,
      "y": 8,
      "z": -13,
      "name": "Rock_Stone_Stalactite_Large",
      "rotation": 8
    },
    {
      "x": -9,
      "y": 9,
      "z": -13,
      "name": "Rock_Stone"
    },
    {
      "x": -9,
      "y": 10,
      "z": -13,
      "name": "Rock_Stone"
    },
    {
      "x": -9,
      "y": 11,
      "z": -13,
      "name": "Rock_Stone"
    },
    {
      "x": -9,
      "y": 12,
      "z": -13,
      "name": "Rock_Stone"
    },
    {
      "x": -9,
      "y": 13,
      "z": -13,
      "name": "Rock_Stone"
    },
    {
      "x": -9,
      "y": 14,
      "z": -13,
      "name": "Rock_Stone"
    },
    {
      "x": -9,
      "y": 15,
      "z": -13,
      "name": "Rock_Stone"
    },
    {
      "x": -9,
      "y": 16,
      "z": -13,
      "name": "Rock_Stone"
    },
    {
      "x": -9,
      "y": 17,
      "z": -13,
      "name": "Ore_Copper_Stone"
    },
    {
      "x": -9,
      "y": 18,
      "z": -13,
      "name": "Rock_Stone"
    },
    {
      "x": -9,
      "y": 19,
      "z": -13,
      "name": "Rock_Stone"
    },
    {
      "x": -9,
      "y": 20,
      "z": -13,
      "name": "Soil_Grass_Dry_Full"
    },
    {
      "x": -9,
      "y": 21,
      "z": -13,
      "name": "Plant_Moss_Yellow"
    },
    {
      "x": -9,
      "y": 9,
      "z": -12,
      "name": "Rock_Stone"
    },
    {
      "x": -9,
      "y": 10,
      "z": -12,
      "name": "Rock_Stone"
    },
    {
      "x": -9,
      "y": 11,
      "z": -12,
      "name": "Rock_Stone"
    },
    {
      "x": -9,
      "y": 12,
      "z": -12,
      "name": "Rock_Stone"
    },
    {
      "x": -9,
      "y": 13,
      "z": -12,
      "name": "Rock_Stone"
    },
    {
      "x": -9,
      "y": 14,
      "z": -12,
      "name": "Rock_Stone"
    },
    {
      "x": -9,
      "y": 15,
      "z": -12,
      "name": "Rock_Stone"
    },
    {
      "x": -9,
      "y": 16,
      "z": -12,
      "name": "Rock_Stone"
    },
    {
      "x": -9,
      "y": 17,
      "z": -12,
      "name": "Rock_Stone"
    },
    {
      "x": -9,
      "y": 18,
      "z": -12,
      "name": "Rock_Stone"
    },
    {
      "x": -9,
      "y": 19,
      "z": -12,
      "name": "Soil_Grass_Dry_Full"
    },
    {
      "x": -9,
      "y": 22,
      "z": -12,
      "name": "Plant_Leaves_Dry"
    },
    {
      "x": -9,
      "y": 8,
      "z": -11,
      "name": "Rock_Stone_Stalactite_Large",
      "filler": 31744,
      "rotation": 8
    },
    {
      "x": -9,
      "y": 9,
      "z": -11,
      "name": "Rock_Stone_Stalactite_Large",
      "rotation": 8
    },
    {
      "x": -9,
      "y": 10,
      "z": -11,
      "name": "Rock_Stone"
    },
    {
      "x": -9,
      "y": 11,
      "z": -11,
      "name": "Rock_Stone"
    },
    {
      "x": -9,
      "y": 12,
      "z": -11,
      "name": "Rock_Stone"
    },
    {
      "x": -9,
      "y": 13,
      "z": -11,
      "name": "Rock_Stone"
    },
    {
      "x": -9,
      "y": 14,
      "z": -11,
      "name": "Rock_Stone"
    },
    {
      "x": -9,
      "y": 15,
      "z": -11,
      "name": "Rock_Stone"
    },
    {
      "x": -9,
      "y": 16,
      "z": -11,
      "name": "Rock_Stone_Mossy"
    },
    {
      "x": -9,
      "y": 17,
      "z": -11,
      "name": "Rock_Stone"
    },
    {
      "x": -9,
      "y": 18,
      "z": -11,
      "name": "Soil_Grass_Dry_Full"
    },
    {
      "x": -9,
      "y": 19,
      "z": -11,
      "name": "Plant_Moss_Yellow"
    },
    {
      "x": -9,
      "y": 22,
      "z": -11,
      "name": "Plant_Leaves_Dry"
    },
    {
      "x": -9,
      "y": 10,
      "z": -10,
      "name": "Rock_Stone"
    },
    {
      "x": -9,
      "y": 11,
      "z": -10,
      "name": "Rock_Stone"
    },
    {
      "x": -9,
      "y": 12,
      "z": -10,
      "name": "Rock_Stone"
    },
    {
      "x": -9,
      "y": 13,
      "z": -10,
      "name": "Rock_Stone"
    },
    {
      "x": -9,
      "y": 14,
      "z": -10,
      "name": "Rock_Stone"
    },
    {
      "x": -9,
      "y": 15,
      "z": -10,
      "name": "Ore_Copper_Stone"
    },
    {
      "x": -9,
      "y": 16,
      "z": -10,
      "name": "Rock_Stone"
    },
    {
      "x": -9,
      "y": 17,
      "z": -10,
      "name": "Rock_Stone"
    },
    {
      "x": -9,
      "y": 18,
      "z": -10,
      "name": "Soil_Grass_Dry_Full"
    },
    {
      "x": -9,
      "y": 19,
      "z": -10,
      "name": "Plant_Moss_Yellow"
    },
    {
      "x": -9,
      "y": 22,
      "z": -10,
      "name": "Plant_Leaves_Dry"
    },
    {
      "x": -9,
      "y": 10,
      "z": -9,
      "name": "Rock_Stone"
    },
    {
      "x": -9,
      "y": 11,
      "z": -9,
      "name": "Rock_Stone"
    },
    {
      "x": -9,
      "y": 12,
      "z": -9,
      "name": "Rock_Stone"
    },
    {
      "x": -9,
      "y": 13,
      "z": -9,
      "name": "Rock_Stone"
    },
    {
      "x": -9,
      "y": 14,
      "z": -9,
      "name": "Rock_Stone"
    },
    {
      "x": -9,
      "y": 15,
      "z": -9,
      "name": "Rock_Stone_Mossy"
    },
    {
      "x": -9,
      "y": 16,
      "z": -9,
      "name": "Rock_Stone_Mossy"
    },
    {
      "x": -9,
      "y": 17,
      "z": -9,
      "name": "Soil_Grass_Dry_Full"
    },
    {
      "x": -9,
      "y": 22,
      "z": -9,
      "name": "Plant_Leaves_Dry"
    },
    {
      "x": -9,
      "y": 23,
      "z": -9,
      "name": "Plant_Leaves_Dry"
    },
    {
      "x": -9,
      "y": 9,
      "z": -8,
      "name": "Plant_Moss_Cave_Yellow",
      "rotation": 8
    },
    {
      "x": -9,
      "y": 10,
      "z": -8,
      "name": "Rock_Stone"
    },
    {
      "x": -9,
      "y": 11,
      "z": -8,
      "name": "Rock_Stone"
    },
    {
      "x": -9,
      "y": 12,
      "z": -8,
      "name": "Rock_Stone"
    },
    {
      "x": -9,
      "y": 13,
      "z": -8,
      "name": "Rock_Stone"
    },
    {
      "x": -9,
      "y": 14,
      "z": -8,
      "name": "Rock_Stone"
    },
    {
      "x": -9,
      "y": 15,
      "z": -8,
      "name": "Rock_Stone_Mossy"
    },
    {
      "x": -9,
      "y": 16,
      "z": -8,
      "name": "Rock_Stone"
    },
    {
      "x": -9,
      "y": 17,
      "z": -8,
      "name": "Soil_Grass_Dry_Full"
    },
    {
      "x": -9,
      "y": 22,
      "z": -8,
      "name": "Wood_Dry_Branch_Long",
      "rotation": 5
    },
    {
      "x": -9,
      "y": 23,
      "z": -8,
      "name": "Plant_Leaves_Dry"
    },
    {
      "x": -9,
      "y": 11,
      "z": -7,
      "name": "Plant_Moss_Cave_Yellow",
      "rotation": 8
    },
    {
      "x": -9,
      "y": 12,
      "z": -7,
      "name": "Rock_Stone"
    },
    {
      "x": -9,
      "y": 13,
      "z": -7,
      "name": "Rock_Stone"
    },
    {
      "x": -9,
      "y": 14,
      "z": -7,
      "name": "Ore_Copper_Stone"
    },
    {
      "x": -9,
      "y": 15,
      "z": -7,
      "name": "Rock_Stone"
    },
    {
      "x": -9,
      "y": 16,
      "z": -7,
      "name": "Rock_Stone_Mossy"
    },
    {
      "x": -9,
      "y": 17,
      "z": -7,
      "name": "Soil_Grass_Dry_Full"
    },
    {
      "x": -9,
      "y": 18,
      "z": -7,
      "name": "Plant_Moss_Yellow"
    },
    {
      "x": -9,
      "y": 23,
      "z": -7,
      "name": "Plant_Leaves_Dry"
    },
    {
      "x": -9,
      "y": 14,
      "z": -6,
      "name": "Rock_Stone"
    },
    {
      "x": -9,
      "y": 15,
      "z": -6,
      "name": "Rock_Stone"
    },
    {
      "x": -9,
      "y": 16,
      "z": -6,
      "name": "Soil_Grass_Dry_Full"
    },
    {
      "x": -9,
      "y": 17,
      "z": -6,
      "name": "Plant_Moss_Wall_Yellow",
      "rotation": 3
    },
    {
      "x": -9,
      "y": 22,
      "z": -6,
      "name": "Plant_Leaves_Dry"
    },
    {
      "x": -9,
      "y": 16,
      "z": -5,
      "name": "Plant_Moss_Wall_Yellow"
    },
    {
      "x": -9,
      "y": 22,
      "z": -5,
      "name": "Plant_Leaves_Dry"
    },
    {
      "x": -9,
      "y": 22,
      "z": -4,
      "name": "Plant_Leaves_Dry"
    },
    {
      "x": -8,
      "y": 16,
      "z": -17,
      "name": "Plant_Moss_Wall_Yellow",
      "rotation": 2
    },
    {
      "x": -8,
      "y": 13,
      "z": -16,
      "name": "Rock_Stone"
    },
    {
      "x": -8,
      "y": 14,
      "z": -16,
      "name": "Rock_Stone"
    },
    {
      "x": -8,
      "y": 15,
      "z": -16,
      "name": "Rock_Stone"
    },
    {
      "x": -8,
      "y": 16,
      "z": -16,
      "name": "Soil_Grass_Dry_Full"
    },
    {
      "x": -8,
      "y": 17,
      "z": -16,
      "name": "Plant_Moss_Wall_Yellow",
      "rotation": 2
    },
    {
      "x": -8,
      "y": 10,
      "z": -15,
      "name": "Rock_Stone"
    },
    {
      "x": -8,
      "y": 11,
      "z": -15,
      "name": "Rock_Stone"
    },
    {
      "x": -8,
      "y": 12,
      "z": -15,
      "name": "Rock_Stone"
    },
    {
      "x": -8,
      "y": 13,
      "z": -15,
      "name": "Rock_Stone"
    },
    {
      "x": -8,
      "y": 14,
      "z": -15,
      "name": "Rock_Stone"
    },
    {
      "x": -8,
      "y": 15,
      "z": -15,
      "name": "Rock_Stone"
    },
    {
      "x": -8,
      "y": 16,
      "z": -15,
      "name": "Rock_Stone"
    },
    {
      "x": -8,
      "y": 17,
      "z": -15,
      "name": "Rock_Stone"
    },
    {
      "x": -8,
      "y": 18,
      "z": -15,
      "name": "Rock_Stone_Mossy"
    },
    {
      "x": -8,
      "y": 19,
      "z": -15,
      "name": "Soil_Grass_Dry_Full"
    },
    {
      "x": -8,
      "y": 7,
      "z": -14,
      "name": "Plant_Moss_Cave_Yellow",
      "rotation": 8
    },
    {
      "x": -8,
      "y": 8,
      "z": -14,
      "name": "Rock_Stone"
    },
    {
      "x": -8,
      "y": 9,
      "z": -14,
      "name": "Rock_Stone"
    },
    {
      "x": -8,
      "y": 10,
      "z": -14,
      "name": "Rock_Stone"
    },
    {
      "x": -8,
      "y": 11,
      "z": -14,
      "name": "Rock_Stone"
    },
    {
      "x": -8,
      "y": 12,
      "z": -14,
      "name": "Rock_Stone"
    },
    {
      "x": -8,
      "y": 13,
      "z": -14,
      "name": "Rock_Stone"
    },
    {
      "x": -8,
      "y": 14,
      "z": -14,
      "name": "Rock_Stone"
    },
    {
      "x": -8,
      "y": 15,
      "z": -14,
      "name": "Rock_Stone"
    },
    {
      "x": -8,
      "y": 16,
      "z": -14,
      "name": "Rock_Stone"
    },
    {
      "x": -8,
      "y": 17,
      "z": -14,
      "name": "Rock_Stone"
    },
    {
      "x": -8,
      "y": 18,
      "z": -14,
      "name": "Rock_Stone"
    },
    {
      "x": -8,
      "y": 19,
      "z": -14,
      "name": "Soil_Grass_Dry_Full"
    },
    {
      "x": -8,
      "y": 20,
      "z": -14,
      "name": "Plant_Moss_Yellow"
    },
    {
      "x": -8,
      "y": 8,
      "z": -13,
      "name": "Rock_Stone"
    },
    {
      "x": -8,
      "y": 9,
      "z": -13,
      "name": "Rock_Stone"
    },
    {
      "x": -8,
      "y": 10,
      "z": -13,
      "name": "Rock_Stone"
    },
    {
      "x": -8,
      "y": 11,
      "z": -13,
      "name": "Rock_Stone"
    },
    {
      "x": -8,
      "y": 12,
      "z": -13,
      "name": "Rock_Stone"
    },
    {
      "x": -8,
      "y": 13,
      "z": -13,
      "name": "Rock_Stone"
    },
    {
      "x": -8,
      "y": 14,
      "z": -13,
      "name": "Rock_Stone"
    },
    {
      "x": -8,
      "y": 15,
      "z": -13,
      "name": "Rock_Stone"
    },
    {
      "x": -8,
      "y": 16,
      "z": -13,
      "name": "Ore_Copper_Stone"
    },
    {
      "x": -8,
      "y": 17,
      "z": -13,
      "name": "Rock_Stone"
    },
    {
      "x": -8,
      "y": 18,
      "z": -13,
      "name": "Rock_Stone"
    },
    {
      "x": -8,
      "y": 19,
      "z": -13,
      "name": "Soil_Grass_Dry_Full"
    },
    {
      "x": -8,
      "y": 20,
      "z": -13,
      "name": "Plant_Bush_Arid"
    },
    {
      "x": -8,
      "y": 9,
      "z": -12,
      "name": "Rock_Stone"
    },
    {
      "x": -8,
      "y": 10,
      "z": -12,
      "name": "Rock_Stone"
    },
    {
      "x": -8,
      "y": 11,
      "z": -12,
      "name": "Rock_Stone"
    },
    {
      "x": -8,
      "y": 12,
      "z": -12,
      "name": "Rock_Stone"
    },
    {
      "x": -8,
      "y": 13,
      "z": -12,
      "name": "Rock_Stone"
    },
    {
      "x": -8,
      "y": 14,
      "z": -12,
      "name": "Rock_Stone"
    },
    {
      "x": -8,
      "y": 15,
      "z": -12,
      "name": "Rock_Stone"
    },
    {
      "x": -8,
      "y": 16,
      "z": -12,
      "name": "Rock_Stone"
    },
    {
      "x": -8,
      "y": 17,
      "z": -12,
      "name": "Rock_Stone"
    },
    {
      "x": -8,
      "y": 18,
      "z": -12,
      "name": "Rock_Stone"
    },
    {
      "x": -8,
      "y": 19,
      "z": -12,
      "name": "Soil_Grass_Dry_Full"
    },
    {
      "x": -8,
      "y": 20,
      "z": -12,
      "name": "Plant_Bush_Arid"
    },
    {
      "x": -8,
      "y": 22,
      "z": -12,
      "name": "Plant_Leaves_Dry"
    },
    {
      "x": -8,
      "y": 10,
      "z": -11,
      "name": "Rock_Stone"
    },
    {
      "x": -8,
      "y": 11,
      "z": -11,
      "name": "Rock_Stone"
    },
    {
      "x": -8,
      "y": 12,
      "z": -11,
      "name": "Rock_Stone"
    },
    {
      "x": -8,
      "y": 13,
      "z": -11,
      "name": "Rock_Stone"
    },
    {
      "x": -8,
      "y": 14,
      "z": -11,
      "name": "Rock_Stone"
    },
    {
      "x": -8,
      "y": 15,
      "z": -11,
      "name": "Rock_Stone"
    },
    {
      "x": -8,
      "y": 16,
      "z": -11,
      "name": "Rock_Stone"
    },
    {
      "x": -8,
      "y": 17,
      "z": -11,
      "name": "Rock_Stone"
    },
    {
      "x": -8,
      "y": 18,
      "z": -11,
      "name": "Rock_Stone"
    },
    {
      "x": -8,
      "y": 19,
      "z": -11,
      "name": "Soil_Grass_Dry_Full"
    },
    {
      "x": -8,
      "y": 22,
      "z": -11,
      "name": "Plant_Leaves_Dry"
    },
    {
      "x": -8,
      "y": 6,
      "z": -10,
      "name": "Rock_Stone_Stalactite_Large",
      "filler": 31744,
      "rotation": 8
    },
    {
      "x": -8,
      "y": 7,
      "z": -10,
      "name": "Rock_Stone_Stalactite_Large",
      "rotation": 8
    },
    {
      "x": -8,
      "y": 8,
      "z": -10,
      "name": "Rock_Stone"
    },
    {
      "x": -8,
      "y": 9,
      "z": -10,
      "name": "Rock_Stone"
    },
    {
      "x": -8,
      "y": 10,
      "z": -10,
      "name": "Rock_Stone"
    },
    {
      "x": -8,
      "y": 11,
      "z": -10,
      "name": "Rock_Stone"
    },
    {
      "x": -8,
      "y": 12,
      "z": -10,
      "name": "Rock_Stone"
    },
    {
      "x": -8,
      "y": 13,
      "z": -10,
      "name": "Rock_Stone"
    },
    {
      "x": -8,
      "y": 14,
      "z": -10,
      "name": "Rock_Stone"
    },
    {
      "x": -8,
      "y": 15,
      "z": -10,
      "name": "Rock_Stone"
    },
    {
      "x": -8,
      "y": 16,
      "z": -10,
      "name": "Rock_Stone"
    },
    {
      "x": -8,
      "y": 17,
      "z": -10,
      "name": "Rock_Stone"
    },
    {
      "x": -8,
      "y": 18,
      "z": -10,
      "name": "Soil_Grass_Dry_Full"
    },
    {
      "x": -8,
      "y": 22,
      "z": -10,
      "name": "Plant_Leaves_Dry"
    },
    {
      "x": -8,
      "y": 23,
      "z": -10,
      "name": "Plant_Leaves_Dry"
    },
    {
      "x": -8,
      "y": 9,
      "z": -9,
      "name": "Rock_Stone"
    },
    {
      "x": -8,
      "y": 10,
      "z": -9,
      "name": "Rock_Stone"
    },
    {
      "x": -8,
      "y": 11,
      "z": -9,
      "name": "Rock_Stone"
    },
    {
      "x": -8,
      "y": 12,
      "z": -9,
      "name": "Rock_Stone"
    },
    {
      "x": -8,
      "y": 13,
      "z": -9,
      "name": "Rock_Stone"
    },
    {
      "x": -8,
      "y": 14,
      "z": -9,
      "name": "Rock_Stone"
    },
    {
      "x": -8,
      "y": 15,
      "z": -9,
      "name": "Rock_Stone"
    },
    {
      "x": -8,
      "y": 16,
      "z": -9,
      "name": "Rock_Stone"
    },
    {
      "x": -8,
      "y": 17,
      "z": -9,
      "name": "Rock_Stone"
    },
    {
      "x": -8,
      "y": 18,
      "z": -9,
      "name": "Soil_Grass_Dry_Full"
    },
    {
      "x": -8,
      "y": 23,
      "z": -9,
      "name": "Plant_Leaves_Dry"
    },
    {
      "x": -8,
      "y": 9,
      "z": -8,
      "name": "Rock_Stone"
    },
    {
      "x": -8,
      "y": 10,
      "z": -8,
      "name": "Rock_Stone"
    },
    {
      "x": -8,
      "y": 11,
      "z": -8,
      "name": "Rock_Stone"
    },
    {
      "x": -8,
      "y": 12,
      "z": -8,
      "name": "Rock_Stone"
    },
    {
      "x": -8,
      "y": 13,
      "z": -8,
      "name": "Rock_Stone"
    },
    {
      "x": -8,
      "y": 14,
      "z": -8,
      "name": "Rock_Stone"
    },
    {
      "x": -8,
      "y": 15,
      "z": -8,
      "name": "Ore_Copper_Stone"
    },
    {
      "x": -8,
      "y": 16,
      "z": -8,
      "name": "Rock_Stone"
    },
    {
      "x": -8,
      "y": 17,
      "z": -8,
      "name": "Rock_Stone"
    },
    {
      "x": -8,
      "y": 18,
      "z": -8,
      "name": "Soil_Grass_Dry_Full"
    },
    {
      "x": -8,
      "y": 22,
      "z": -8,
      "name": "Wood_Dry_Trunk_Full"
    },
    {
      "x": -8,
      "y": 12,
      "z": -7,
      "name": "Rock_Stone"
    },
    {
      "x": -8,
      "y": 13,
      "z": -7,
      "name": "Rock_Stone"
    },
    {
      "x": -8,
      "y": 14,
      "z": -7,
      "name": "Rock_Stone"
    },
    {
      "x": -8,
      "y": 15,
      "z": -7,
      "name": "Rock_Stone"
    },
    {
      "x": -8,
      "y": 16,
      "z": -7,
      "name": "Rock_Stone_Mossy"
    },
    {
      "x": -8,
      "y": 17,
      "z": -7,
      "name": "Rock_Stone"
    },
    {
      "x": -8,
      "y": 18,
      "z": -7,
      "name": "Soil_Grass_Dry_Full"
    },
    {
      "x": -8,
      "y": 22,
      "z": -7,
      "name": "Wood_Dry_Branch_Long",
      "rotation": 4
    },
    {
      "x": -8,
      "y": 23,
      "z": -7,
      "name": "Plant_Leaves_Dry"
    },
    {
      "x": -8,
      "y": 13,
      "z": -6,
      "name": "Rock_Stone"
    },
    {
      "x": -8,
      "y": 14,
      "z": -6,
      "name": "Rock_Stone"
    },
    {
      "x": -8,
      "y": 15,
      "z": -6,
      "name": "Rock_Stone"
    },
    {
      "x": -8,
      "y": 16,
      "z": -6,
      "name": "Rock_Stone"
    },
    {
      "x": -8,
      "y": 17,
      "z": -6,
      "name": "Soil_Grass_Dry_Full"
    },
    {
      "x": -8,
      "y": 18,
      "z": -6,
      "name": "Plant_Moss_Rug_Yellow"
    },
    {
      "x": -8,
      "y": 22,
      "z": -6,
      "name": "Wood_Dry_Branch_Long",
      "rotation": 4
    },
    {
      "x": -8,
      "y": 23,
      "z": -6,
      "name": "Plant_Leaves_Dry"
    },
    {
      "x": -8,
      "y": 15,
      "z": -5,
      "name": "Plant_Moss_Wall_Yellow"
    },
    {
      "x": -8,
      "y": 16,
      "z": -5,
      "name": "Plant_Moss_Wall_Yellow"
    },
    {
      "x": -8,
      "y": 22,
      "z": -5,
      "name": "Plant_Leaves_Dry"
    },
    {
      "x": -8,
      "y": 22,
      "z": -4,
      "name": "Plant_Leaves_Dry"
    },
    {
      "x": -7,
      "y": 15,
      "z": -17,
      "name": "Plant_Moss_Wall_Yellow",
      "rotation": 2
    },
    {
      "x": -7,
      "y": 16,
      "z": -17,
      "name": "Plant_Moss_Wall_Yellow",
      "rotation": 2
    },
    {
      "x": -7,
      "y": 14,
      "z": -16,
      "name": "Rock_Stone"
    },
    {
      "x": -7,
      "y": 15,
      "z": -16,
      "name": "Rock_Stone"
    },
    {
      "x": -7,
      "y": 16,
      "z": -16,
      "name": "Soil_Grass_Dry_Full"
    },
    {
      "x": -7,
      "y": 17,
      "z": -16,
      "name": "Plant_Moss_Rug_Yellow"
    },
    {
      "x": -7,
      "y": 9,
      "z": -15,
      "name": "Plant_Moss_Cave_Yellow",
      "rotation": 8
    },
    {
      "x": -7,
      "y": 10,
      "z": -15,
      "name": "Rock_Stone"
    },
    {
      "x": -7,
      "y": 11,
      "z": -15,
      "name": "Rock_Stone"
    },
    {
      "x": -7,
      "y": 12,
      "z": -15,
      "name": "Rock_Stone"
    },
    {
      "x": -7,
      "y": 13,
      "z": -15,
      "name": "Rock_Stone"
    },
    {
      "x": -7,
      "y": 14,
      "z": -15,
      "name": "Rock_Stone"
    },
    {
      "x": -7,
      "y": 15,
      "z": -15,
      "name": "Rock_Stone"
    },
    {
      "x": -7,
      "y": 16,
      "z": -15,
      "name": "Rock_Stone"
    },
    {
      "x": -7,
      "y": 17,
      "z": -15,
      "name": "Soil_Grass_Dry_Full"
    },
    {
      "x": -7,
      "y": 18,
      "z": -15,
      "name": "Plant_Moss_Rug_Yellow"
    },
    {
      "x": -7,
      "y": 8,
      "z": -14,
      "name": "Plant_Moss_Cave_Yellow",
      "rotation": 8
    },
    {
      "x": -7,
      "y": 9,
      "z": -14,
      "name": "Rock_Stone"
    },
    {
      "x": -7,
      "y": 10,
      "z": -14,
      "name": "Rock_Stone"
    },
    {
      "x": -7,
      "y": 11,
      "z": -14,
      "name": "Rock_Stone"
    },
    {
      "x": -7,
      "y": 12,
      "z": -14,
      "name": "Rock_Stone"
    },
    {
      "x": -7,
      "y": 13,
      "z": -14,
      "name": "Rock_Stone"
    },
    {
      "x": -7,
      "y": 14,
      "z": -14,
      "name": "Rock_Stone"
    },
    {
      "x": -7,
      "y": 15,
      "z": -14,
      "name": "Rock_Stone"
    },
    {
      "x": -7,
      "y": 16,
      "z": -14,
      "name": "Rock_Stone"
    },
    {
      "x": -7,
      "y": 17,
      "z": -14,
      "name": "Rock_Stone"
    },
    {
      "x": -7,
      "y": 18,
      "z": -14,
      "name": "Soil_Grass_Dry_Full"
    },
    {
      "x": -7,
      "y": 19,
      "z": -14,
      "name": "Plant_Bush_Arid"
    },
    {
      "x": -7,
      "y": 25,
      "z": -14,
      "name": "Plant_Leaves_Dry"
    },
    {
      "x": -7,
      "y": 5,
      "z": -13,
      "name": "Rock_Stone_Stalactite_Large",
      "filler": 31744,
      "rotation": 8
    },
    {
      "x": -7,
      "y": 6,
      "z": -13,
      "name": "Rock_Stone_Stalactite_Large",
      "rotation": 8
    },
    {
      "x": -7,
      "y": 7,
      "z": -13,
      "name": "Rock_Stone"
    },
    {
      "x": -7,
      "y": 8,
      "z": -13,
      "name": "Rock_Stone"
    },
    {
      "x": -7,
      "y": 9,
      "z": -13,
      "name": "Rock_Stone"
    },
    {
      "x": -7,
      "y": 10,
      "z": -13,
      "name": "Rock_Stone"
    },
    {
      "x": -7,
      "y": 11,
      "z": -13,
      "name": "Rock_Stone"
    },
    {
      "x": -7,
      "y": 12,
      "z": -13,
      "name": "Rock_Stone"
    },
    {
      "x": -7,
      "y": 13,
      "z": -13,
      "name": "Rock_Stone"
    },
    {
      "x": -7,
      "y": 14,
      "z": -13,
      "name": "Rock_Stone"
    },
    {
      "x": -7,
      "y": 15,
      "z": -13,
      "name": "Rock_Stone"
    },
    {
      "x": -7,
      "y": 16,
      "z": -13,
      "name": "Rock_Stone"
    },
    {
      "x": -7,
      "y": 17,
      "z": -13,
      "name": "Rock_Stone"
    },
    {
      "x": -7,
      "y": 18,
      "z": -13,
      "name": "Soil_Grass_Dry_Full"
    },
    {
      "x": -7,
      "y": 19,
      "z": -13,
      "name": "Plant_Moss_Yellow"
    },
    {
      "x": -7,
      "y": 25,
      "z": -13,
      "name": "Plant_Leaves_Dry"
    },
    {
      "x": -7,
      "y": 9,
      "z": -12,
      "name": "Rock_Stone"
    },
    {
      "x": -7,
      "y": 10,
      "z": -12,
      "name": "Rock_Stone"
    },
    {
      "x": -7,
      "y": 11,
      "z": -12,
      "name": "Rock_Stone"
    },
    {
      "x": -7,
      "y": 12,
      "z": -12,
      "name": "Rock_Stone"
    },
    {
      "x": -7,
      "y": 13,
      "z": -12,
      "name": "Rock_Stone"
    },
    {
      "x": -7,
      "y": 14,
      "z": -12,
      "name": "Rock_Stone"
    },
    {
      "x": -7,
      "y": 15,
      "z": -12,
      "name": "Rock_Stone"
    },
    {
      "x": -7,
      "y": 16,
      "z": -12,
      "name": "Rock_Stone"
    },
    {
      "x": -7,
      "y": 17,
      "z": -12,
      "name": "Rock_Stone"
    },
    {
      "x": -7,
      "y": 18,
      "z": -12,
      "name": "Rock_Stone"
    },
    {
      "x": -7,
      "y": 19,
      "z": -12,
      "name": "Soil_Grass_Dry_Full"
    },
    {
      "x": -7,
      "y": 20,
      "z": -12,
      "name": "Plant_Bush_Arid"
    },
    {
      "x": -7,
      "y": 22,
      "z": -12,
      "name": "Plant_Leaves_Dry"
    },
    {
      "x": -7,
      "y": 25,
      "z": -12,
      "name": "Plant_Leaves_Dry"
    },
    {
      "x": -7,
      "y": 9,
      "z": -11,
      "name": "Rock_Gem_Topaz",
      "rotation": 8
    },
    {
      "x": -7,
      "y": 10,
      "z": -11,
      "name": "Rock_Stone"
    },
    {
      "x": -7,
      "y": 11,
      "z": -11,
      "name": "Rock_Stone"
    },
    {
      "x": -7,
      "y": 12,
      "z": -11,
      "name": "Rock_Stone"
    },
    {
      "x": -7,
      "y": 13,
      "z": -11,
      "name": "Rock_Stone"
    },
    {
      "x": -7,
      "y": 14,
      "z": -11,
      "name": "Rock_Stone"
    },
    {
      "x": -7,
      "y": 15,
      "z": -11,
      "name": "Rock_Stone"
    },
    {
      "x": -7,
      "y": 16,
      "z": -11,
      "name": "Ore_Copper_Stone"
    },
    {
      "x": -7,
      "y": 17,
      "z": -11,
      "name": "Rock_Stone"
    },
    {
      "x": -7,
      "y": 18,
      "z": -11,
      "name": "Rock_Stone"
    },
    {
      "x": -7,
      "y": 19,
      "z": -11,
      "name": "Soil_Grass_Dry_Full"
    },
    {
      "x": -7,
      "y": 20,
      "z": -11,
      "name": "Plant_Crop_Stamina2"
    },
    {
      "x": -7,
      "y": 22,
      "z": -11,
      "name": "Plant_Leaves_Dry"
    },
    {
      "x": -7,
      "y": 25,
      "z": -11,
      "name": "Plant_Leaves_Dry"
    },
    {
      "x": -7,
      "y": 9,
      "z": -10,
      "name": "Rock_Stone"
    },
    {
      "x": -7,
      "y": 10,
      "z": -10,
      "name": "Rock_Stone"
    },
    {
      "x": -7,
      "y": 11,
      "z": -10,
      "name": "Rock_Stone"
    },
    {
      "x": -7,
      "y": 12,
      "z": -10,
      "name": "Rock_Stone"
    },
    {
      "x": -7,
      "y": 13,
      "z": -10,
      "name": "Rock_Stone"
    },
    {
      "x": -7,
      "y": 14,
      "z": -10,
      "name": "Rock_Stone"
    },
    {
      "x": -7,
      "y": 15,
      "z": -10,
      "name": "Rock_Stone"
    },
    {
      "x": -7,
      "y": 16,
      "z": -10,
      "name": "Rock_Stone"
    },
    {
      "x": -7,
      "y": 17,
      "z": -10,
      "name": "Rock_Stone"
    },
    {
      "x": -7,
      "y": 18,
      "z": -10,
      "name": "Rock_Stone"
    },
    {
      "x": -7,
      "y": 19,
      "z": -10,
      "name": "Soil_Grass_Dry_Full"
    },
    {
      "x": -7,
      "y": 22,
      "z": -10,
      "name": "Wood_Dry_Branch_Long",
      "rotation": 4
    },
    {
      "x": -7,
      "y": 23,
      "z": -10,
      "name": "Plant_Leaves_Dry"
    },
    {
      "x": -7,
      "y": 25,
      "z": -10,
      "name": "Plant_Leaves_Dry"
    },
    {
      "x": -7,
      "y": 9,
      "z": -9,
      "name": "Rock_Stone"
    },
    {
      "x": -7,
      "y": 10,
      "z": -9,
      "name": "Rock_Stone"
    },
    {
      "x": -7,
      "y": 11,
      "z": -9,
      "name": "Rock_Stone"
    },
    {
      "x": -7,
      "y": 12,
      "z": -9,
      "name": "Rock_Stone"
    },
    {
      "x": -7,
      "y": 13,
      "z": -9,
      "name": "Rock_Stone"
    },
    {
      "x": -7,
      "y": 14,
      "z": -9,
      "name": "Rock_Stone"
    },
    {
      "x": -7,
      "y": 15,
      "z": -9,
      "name": "Rock_Stone"
    },
    {
      "x": -7,
      "y": 16,
      "z": -9,
      "name": "Rock_Stone"
    },
    {
      "x": -7,
      "y": 17,
      "z": -9,
      "name": "Rock_Stone"
    },
    {
      "x": -7,
      "y": 18,
      "z": -9,
      "name": "Soil_Grass_Dry_Full"
    },
    {
      "x": -7,
      "y": 22,
      "z": -9,
      "name": "Wood_Dry_Branch_Long",
      "rotation": 4
    },
    {
      "x": -7,
      "y": 6,
      "z": -8,
      "name": "Rock_Stone_Stalactite_Large",
      "filler": 31744,
      "rotation": 8
    },
    {
      "x": -7,
      "y": 7,
      "z": -8,
      "name": "Rock_Stone_Stalactite_Large",
      "rotation": 8
    },
    {
      "x": -7,
      "y": 8,
      "z": -8,
      "name": "Rock_Stone"
    },
    {
      "x": -7,
      "y": 9,
      "z": -8,
      "name": "Rock_Stone"
    },
    {
      "x": -7,
      "y": 10,
      "z": -8,
      "name": "Rock_Stone"
    },
    {
      "x": -7,
      "y": 11,
      "z": -8,
      "name": "Rock_Stone"
    },
    {
      "x": -7,
      "y": 12,
      "z": -8,
      "name": "Rock_Stone"
    },
    {
      "x": -7,
      "y": 13,
      "z": -8,
      "name": "Rock_Stone"
    },
    {
      "x": -7,
      "y": 14,
      "z": -8,
      "name": "Rock_Stone"
    },
    {
      "x": -7,
      "y": 15,
      "z": -8,
      "name": "Rock_Stone"
    },
    {
      "x": -7,
      "y": 16,
      "z": -8,
      "name": "Rock_Stone"
    },
    {
      "x": -7,
      "y": 17,
      "z": -8,
      "name": "Rock_Stone"
    },
    {
      "x": -7,
      "y": 18,
      "z": -8,
      "name": "Soil_Grass_Dry_Full"
    },
    {
      "x": -7,
      "y": 22,
      "z": -8,
      "name": "Wood_Dry_Trunk_Full"
    },
    {
      "x": -7,
      "y": 9,
      "z": -7,
      "name": "Rock_Stone_Stalactite_Large",
      "filler": 31744,
      "rotation": 8
    },
    {
      "x": -7,
      "y": 10,
      "z": -7,
      "name": "Rock_Stone_Stalactite_Large",
      "rotation": 8
    },
    {
      "x": -7,
      "y": 11,
      "z": -7,
      "name": "Rock_Stone"
    },
    {
      "x": -7,
      "y": 12,
      "z": -7,
      "name": "Rock_Stone"
    },
    {
      "x": -7,
      "y": 13,
      "z": -7,
      "name": "Rock_Stone"
    },
    {
      "x": -7,
      "y": 14,
      "z": -7,
      "name": "Rock_Stone"
    },
    {
      "x": -7,
      "y": 15,
      "z": -7,
      "name": "Rock_Stone"
    },
    {
      "x": -7,
      "y": 16,
      "z": -7,
      "name": "Rock_Stone"
    },
    {
      "x": -7,
      "y": 17,
      "z": -7,
      "name": "Rock_Stone"
    },
    {
      "x": -7,
      "y": 18,
      "z": -7,
      "name": "Soil_Grass_Dry_Full"
    },
    {
      "x": -7,
      "y": 19,
      "z": -7,
      "name": "Plant_Bramble_Moss_Twisted"
    },
    {
      "x": -7,
      "y": 23,
      "z": -7,
      "name": "Plant_Leaves_Dry"
    },
    {
      "x": -7,
      "y": 12,
      "z": -6,
      "name": "Rock_Stone"
    },
    {
      "x": -7,
      "y": 13,
      "z": -6,
      "name": "Rock_Stone"
    },
    {
      "x": -7,
      "y": 14,
      "z": -6,
      "name": "Rock_Stone"
    },
    {
      "x": -7,
      "y": 15,
      "z": -6,
      "name": "Rock_Stone"
    },
    {
      "x": -7,
      "y": 16,
      "z": -6,
      "name": "Soil_Grass_Dry_Full"
    },
    {
      "x": -7,
      "y": 17,
      "z": -6,
      "name": "Plant_Moss_Rug_Yellow"
    },
    {
      "x": -7,
      "y": 23,
      "z": -6,
      "name": "Plant_Leaves_Dry"
    },
    {
      "x": -7,
      "y": 15,
      "z": -5,
      "name": "Plant_Moss_Wall_Yellow"
    },
    {
      "x": -7,
      "y": 16,
      "z": -5,
      "name": "Plant_Moss_Wall_Yellow"
    },
    {
      "x": -7,
      "y": 22,
      "z": -5,
      "name": "Plant_Leaves_Dry"
    },
    {
      "x": -7,
      "y": 22,
      "z": -4,
      "name": "Plant_Leaves_Dry"
    },
    {
      "x": -6,
      "y": 14,
      "z": -17,
      "name": "Plant_Moss_Wall_Yellow",
      "rotation": 2
    },
    {
      "x": -6,
      "y": 13,
      "z": -16,
      "name": "Plant_Moss_Cave_Yellow",
      "rotation": 8
    },
    {
      "x": -6,
      "y": 14,
      "z": -16,
      "name": "Rock_Stone"
    },
    {
      "x": -6,
      "y": 15,
      "z": -16,
      "name": "Rock_Stone"
    },
    {
      "x": -6,
      "y": 16,
      "z": -16,
      "name": "Soil_Grass_Dry_Full"
    },
    {
      "x": -6,
      "y": 17,
      "z": -16,
      "name": "Plant_Moss_Rug_Yellow"
    },
    {
      "x": -6,
      "y": 10,
      "z": -15,
      "name": "Rock_Stone"
    },
    {
      "x": -6,
      "y": 11,
      "z": -15,
      "name": "Rock_Stone"
    },
    {
      "x": -6,
      "y": 12,
      "z": -15,
      "name": "Rock_Stone"
    },
    {
      "x": -6,
      "y": 13,
      "z": -15,
      "name": "Ore_Copper_Stone"
    },
    {
      "x": -6,
      "y": 14,
      "z": -15,
      "name": "Rock_Stone"
    },
    {
      "x": -6,
      "y": 15,
      "z": -15,
      "name": "Rock_Stone_Mossy"
    },
    {
      "x": -6,
      "y": 16,
      "z": -15,
      "name": "Soil_Grass_Dry_Full"
    },
    {
      "x": -6,
      "y": 25,
      "z": -15,
      "name": "Plant_Leaves_Dry"
    },
    {
      "x": -6,
      "y": 8,
      "z": -14,
      "name": "Plant_Moss_Cave_Yellow",
      "rotation": 8
    },
    {
      "x": -6,
      "y": 9,
      "z": -14,
      "name": "Rock_Stone"
    },
    {
      "x": -6,
      "y": 10,
      "z": -14,
      "name": "Rock_Stone"
    },
    {
      "x": -6,
      "y": 11,
      "z": -14,
      "name": "Rock_Stone"
    },
    {
      "x": -6,
      "y": 12,
      "z": -14,
      "name": "Rock_Stone"
    },
    {
      "x": -6,
      "y": 13,
      "z": -14,
      "name": "Rock_Stone"
    },
    {
      "x": -6,
      "y": 14,
      "z": -14,
      "name": "Rock_Stone"
    },
    {
      "x": -6,
      "y": 15,
      "z": -14,
      "name": "Rock_Stone"
    },
    {
      "x": -6,
      "y": 16,
      "z": -14,
      "name": "Rock_Stone"
    },
    {
      "x": -6,
      "y": 17,
      "z": -14,
      "name": "Soil_Grass_Dry_Full"
    },
    {
      "x": -6,
      "y": 18,
      "z": -14,
      "name": "Plant_Moss_Yellow"
    },
    {
      "x": -6,
      "y": 25,
      "z": -14,
      "name": "Plant_Leaves_Dry"
    },
    {
      "x": -6,
      "y": 9,
      "z": -13,
      "name": "Rock_Stone"
    },
    {
      "x": -6,
      "y": 10,
      "z": -13,
      "name": "Rock_Stone"
    },
    {
      "x": -6,
      "y": 11,
      "z": -13,
      "name": "Rock_Stone"
    },
    {
      "x": -6,
      "y": 12,
      "z": -13,
      "name": "Rock_Stone"
    },
    {
      "x": -6,
      "y": 13,
      "z": -13,
      "name": "Rock_Stone"
    },
    {
      "x": -6,
      "y": 14,
      "z": -13,
      "name": "Rock_Stone"
    },
    {
      "x": -6,
      "y": 15,
      "z": -13,
      "name": "Ore_Copper_Stone"
    },
    {
      "x": -6,
      "y": 16,
      "z": -13,
      "name": "Rock_Stone"
    },
    {
      "x": -6,
      "y": 17,
      "z": -13,
      "name": "Rock_Stone"
    },
    {
      "x": -6,
      "y": 18,
      "z": -13,
      "name": "Soil_Grass_Dry_Full"
    },
    {
      "x": -6,
      "y": 19,
      "z": -13,
      "name": "Plant_Bush_Arid"
    },
    {
      "x": -6,
      "y": 25,
      "z": -13,
      "name": "Plant_Leaves_Dry"
    },
    {
      "x": -6,
      "y": 7,
      "z": -12,
      "name": "Rock_Stone_Stalactite_Large",
      "filler": 31744,
      "rotation": 8
    },
    {
      "x": -6,
      "y": 8,
      "z": -12,
      "name": "Rock_Stone_Stalactite_Large",
      "rotation": 8
    },
    {
      "x": -6,
      "y": 9,
      "z": -12,
      "name": "Rock_Stone"
    },
    {
      "x": -6,
      "y": 10,
      "z": -12,
      "name": "Rock_Stone"
    },
    {
      "x": -6,
      "y": 11,
      "z": -12,
      "name": "Rock_Stone"
    },
    {
      "x": -6,
      "y": 12,
      "z": -12,
      "name": "Rock_Stone"
    },
    {
      "x": -6,
      "y": 13,
      "z": -12,
      "name": "Rock_Stone"
    },
    {
      "x": -6,
      "y": 14,
      "z": -12,
      "name": "Rock_Stone"
    },
    {
      "x": -6,
      "y": 15,
      "z": -12,
      "name": "Rock_Stone"
    },
    {
      "x": -6,
      "y": 16,
      "z": -12,
      "name": "Rock_Stone"
    },
    {
      "x": -6,
      "y": 17,
      "z": -12,
      "name": "Rock_Stone"
    },
    {
      "x": -6,
      "y": 18,
      "z": -12,
      "name": "Soil_Grass_Dry_Full"
    },
    {
      "x": -6,
      "y": 19,
      "z": -12,
      "name": "Plant_Bush_Arid"
    },
    {
      "x": -6,
      "y": 22,
      "z": -12,
      "name": "Plant_Leaves_Dry"
    },
    {
      "x": -6,
      "y": 25,
      "z": -12,
      "name": "Plant_Leaves_Dry"
    },
    {
      "x": -6,
      "y": 9,
      "z": -11,
      "name": "Rock_Stone"
    },
    {
      "x": -6,
      "y": 10,
      "z": -11,
      "name": "Rock_Stone"
    },
    {
      "x": -6,
      "y": 11,
      "z": -11,
      "name": "Rock_Stone"
    },
    {
      "x": -6,
      "y": 12,
      "z": -11,
      "name": "Rock_Stone"
    },
    {
      "x": -6,
      "y": 13,
      "z": -11,
      "name": "Rock_Stone"
    },
    {
      "x": -6,
      "y": 14,
      "z": -11,
      "name": "Rock_Stone"
    },
    {
      "x": -6,
      "y": 15,
      "z": -11,
      "name": "Rock_Stone"
    },
    {
      "x": -6,
      "y": 16,
      "z": -11,
      "name": "Rock_Stone"
    },
    {
      "x": -6,
      "y": 17,
      "z": -11,
      "name": "Rock_Stone"
    },
    {
      "x": -6,
      "y": 18,
      "z": -11,
      "name": "Soil_Grass_Dry_Full"
    },
    {
      "x": -6,
      "y": 22,
      "z": -11,
      "name": "Plant_Leaves_Dry"
    },
    {
      "x": -6,
      "y": 25,
      "z": -11,
      "name": "Plant_Leaves_Dry"
    },
    {
      "x": -6,
      "y": 9,
      "z": -10,
      "name": "Rock_Stone"
    },
    {
      "x": -6,
      "y": 10,
      "z": -10,
      "name": "Rock_Stone"
    },
    {
      "x": -6,
      "y": 11,
      "z": -10,
      "name": "Rock_Stone"
    },
    {
      "x": -6,
      "y": 12,
      "z": -10,
      "name": "Rock_Stone"
    },
    {
      "x": -6,
      "y": 13,
      "z": -10,
      "name": "Rock_Stone"
    },
    {
      "x": -6,
      "y": 14,
      "z": -10,
      "name": "Rock_Stone"
    },
    {
      "x": -6,
      "y": 15,
      "z": -10,
      "name": "Ore_Copper_Stone"
    },
    {
      "x": -6,
      "y": 16,
      "z": -10,
      "name": "Rock_Stone"
    },
    {
      "x": -6,
      "y": 17,
      "z": -10,
      "name": "Rock_Stone_Mossy"
    },
    {
      "x": -6,
      "y": 18,
      "z": -10,
      "name": "Soil_Grass_Dry_Full"
    },
    {
      "x": -6,
      "y": 25,
      "z": -10,
      "name": "Plant_Leaves_Dry"
    },
    {
      "x": -6,
      "y": 9,
      "z": -9,
      "name": "Rock_Stone"
    },
    {
      "x": -6,
      "y": 10,
      "z": -9,
      "name": "Rock_Stone"
    },
    {
      "x": -6,
      "y": 11,
      "z": -9,
      "name": "Rock_Stone"
    },
    {
      "x": -6,
      "y": 12,
      "z": -9,
      "name": "Rock_Stone"
    },
    {
      "x": -6,
      "y": 13,
      "z": -9,
      "name": "Rock_Stone"
    },
    {
      "x": -6,
      "y": 14,
      "z": -9,
      "name": "Rock_Stone"
    },
    {
      "x": -6,
      "y": 15,
      "z": -9,
      "name": "Ore_Copper_Stone"
    },
    {
      "x": -6,
      "y": 16,
      "z": -9,
      "name": "Rock_Stone"
    },
    {
      "x": -6,
      "y": 17,
      "z": -9,
      "name": "Rock_Stone"
    },
    {
      "x": -6,
      "y": 18,
      "z": -9,
      "name": "Soil_Grass_Dry_Full"
    },
    {
      "x": -6,
      "y": 19,
      "z": -9,
      "name": "Plant_Bramble_Moss_Twisted"
    },
    {
      "x": -6,
      "y": 25,
      "z": -9,
      "name": "Plant_Leaves_Dry"
    },
    {
      "x": -6,
      "y": 7,
      "z": -8,
      "name": "Plant_Moss_Cave_Yellow",
      "rotation": 8
    },
    {
      "x": -6,
      "y": 8,
      "z": -8,
      "name": "Rock_Stone"
    },
    {
      "x": -6,
      "y": 9,
      "z": -8,
      "name": "Rock_Stone"
    },
    {
      "x": -6,
      "y": 10,
      "z": -8,
      "name": "Rock_Stone"
    },
    {
      "x": -6,
      "y": 11,
      "z": -8,
      "name": "Rock_Stone"
    },
    {
      "x": -6,
      "y": 12,
      "z": -8,
      "name": "Rock_Stone"
    },
    {
      "x": -6,
      "y": 13,
      "z": -8,
      "name": "Rock_Stone"
    },
    {
      "x": -6,
      "y": 14,
      "z": -8,
      "name": "Rock_Stone"
    },
    {
      "x": -6,
      "y": 15,
      "z": -8,
      "name": "Ore_Copper_Stone"
    },
    {
      "x": -6,
      "y": 16,
      "z": -8,
      "name": "Rock_Stone"
    },
    {
      "x": -6,
      "y": 17,
      "z": -8,
      "name": "Rock_Stone_Mossy"
    },
    {
      "x": -6,
      "y": 18,
      "z": -8,
      "name": "Soil_Grass_Dry_Full"
    },
    {
      "x": -6,
      "y": 19,
      "z": -8,
      "name": "Plant_Bramble_Moss_Twisted"
    },
    {
      "x": -6,
      "y": 22,
      "z": -8,
      "name": "Wood_Dry_Trunk_Full"
    },
    {
      "x": -6,
      "y": 29,
      "z": -8,
      "name": "Plant_Leaves_Dry"
    },
    {
      "x": -6,
      "y": 9,
      "z": -7,
      "name": "Plant_Moss_Cave_Yellow",
      "rotation": 8
    },
    {
      "x": -6,
      "y": 10,
      "z": -7,
      "name": "Rock_Stone"
    },
    {
      "x": -6,
      "y": 11,
      "z": -7,
      "name": "Rock_Stone"
    },
    {
      "x": -6,
      "y": 12,
      "z": -7,
      "name": "Rock_Stone"
    },
    {
      "x": -6,
      "y": 13,
      "z": -7,
      "name": "Rock_Stone"
    },
    {
      "x": -6,
      "y": 14,
      "z": -7,
      "name": "Rock_Stone"
    },
    {
      "x": -6,
      "y": 15,
      "z": -7,
      "name": "Rock_Stone"
    },
    {
      "x": -6,
      "y": 16,
      "z": -7,
      "name": "Rock_Stone"
    },
    {
      "x": -6,
      "y": 17,
      "z": -7,
      "name": "Rock_Stone"
    },
    {
      "x": -6,
      "y": 18,
      "z": -7,
      "name": "Soil_Grass_Dry_Full"
    },
    {
      "x": -6,
      "y": 19,
      "z": -7,
      "name": "Plant_Bramble_Moss_Twisted"
    },
    {
      "x": -6,
      "y": 23,
      "z": -7,
      "name": "Plant_Leaves_Dry"
    },
    {
      "x": -6,
      "y": 29,
      "z": -7,
      "name": "Plant_Leaves_Dry"
    },
    {
      "x": -6,
      "y": 10,
      "z": -6,
      "name": "Rock_Stone"
    },
    {
      "x": -6,
      "y": 11,
      "z": -6,
      "name": "Rock_Stone"
    },
    {
      "x": -6,
      "y": 12,
      "z": -6,
      "name": "Rock_Stone"
    },
    {
      "x": -6,
      "y": 13,
      "z": -6,
      "name": "Rock_Stone"
    },
    {
      "x": -6,
      "y": 14,
      "z": -6,
      "name": "Rock_Stone"
    },
    {
      "x": -6,
      "y": 15,
      "z": -6,
      "name": "Rock_Stone"
    },
    {
      "x": -6,
      "y": 16,
      "z": -6,
      "name": "Soil_Grass_Dry_Full"
    },
    {
      "x": -6,
      "y": 11,
      "z": -5,
      "name": "Rock_Stone"
    },
    {
      "x": -6,
      "y": 12,
      "z": -5,
      "name": "Rock_Stone"
    },
    {
      "x": -6,
      "y": 13,
      "z": -5,
      "name": "Ore_Copper_Stone"
    },
    {
      "x": -6,
      "y": 14,
      "z": -5,
      "name": "Rock_Stone"
    },
    {
      "x": -6,
      "y": 15,
      "z": -5,
      "name": "Rock_Stone"
    },
    {
      "x": -6,
      "y": 16,
      "z": -5,
      "name": "Soil_Grass_Dry_Full"
    },
    {
      "x": -6,
      "y": 17,
      "z": -5,
      "name": "Plant_Moss_Rug_Yellow"
    },
    {
      "x": -6,
      "y": 22,
      "z": -5,
      "name": "Plant_Leaves_Dry"
    },
    {
      "x": -6,
      "y": 13,
      "z": -4,
      "name": "Rock_Stone"
    },
    {
      "x": -6,
      "y": 14,
      "z": -4,
      "name": "Rock_Stone"
    },
    {
      "x": -6,
      "y": 15,
      "z": -4,
      "name": "Rock_Stone_Mossy"
    },
    {
      "x": -6,
      "y": 16,
      "z": -4,
      "name": "Soil_Grass_Dry_Full"
    },
    {
      "x": -6,
      "y": 17,
      "z": -4,
      "name": "Plant_Moss_Rug_Yellow"
    },
    {
      "x": -6,
      "y": 22,
      "z": -4,
      "name": "Plant_Leaves_Dry"
    },
    {
      "x": -6,
      "y": 15,
      "z": -3,
      "name": "Plant_Moss_Wall_Yellow"
    },
    {
      "x": -5,
      "y": 14,
      "z": -17,
      "name": "Plant_Moss_Wall_Yellow",
      "rotation": 2
    },
    {
      "x": -5,
      "y": 13,
      "z": -16,
      "name": "Rock_Stone_Mossy"
    },
    {
      "x": -5,
      "y": 14,
      "z": -16,
      "name": "Rock_Stone"
    },
    {
      "x": -5,
      "y": 15,
      "z": -16,
      "name": "Soil_Grass_Dry_Full"
    },
    {
      "x": -5,
      "y": 16,
      "z": -16,
      "name": "Plant_Moss_Rug_Yellow"
    },
    {
      "x": -5,
      "y": 9,
      "z": -15,
      "name": "Plant_Moss_Cave_Yellow",
      "rotation": 8
    },
    {
      "x": -5,
      "y": 10,
      "z": -15,
      "name": "Rock_Stone"
    },
    {
      "x": -5,
      "y": 11,
      "z": -15,
      "name": "Rock_Stone"
    },
    {
      "x": -5,
      "y": 12,
      "z": -15,
      "name": "Rock_Stone"
    },
    {
      "x": -5,
      "y": 13,
      "z": -15,
      "name": "Rock_Stone"
    },
    {
      "x": -5,
      "y": 14,
      "z": -15,
      "name": "Ore_Copper_Stone"
    },
    {
      "x": -5,
      "y": 15,
      "z": -15,
      "name": "Rock_Stone"
    },
    {
      "x": -5,
      "y": 16,
      "z": -15,
      "name": "Rock_Stone"
    },
    {
      "x": -5,
      "y": 17,
      "z": -15,
      "name": "Soil_Grass_Dry_Full"
    },
    {
      "x": -5,
      "y": 25,
      "z": -15,
      "name": "Plant_Leaves_Dry"
    },
    {
      "x": -5,
      "y": 9,
      "z": -14,
      "name": "Rock_Stone"
    },
    {
      "x": -5,
      "y": 10,
      "z": -14,
      "name": "Rock_Stone"
    },
    {
      "x": -5,
      "y": 11,
      "z": -14,
      "name": "Rock_Stone"
    },
    {
      "x": -5,
      "y": 12,
      "z": -14,
      "name": "Rock_Stone"
    },
    {
      "x": -5,
      "y": 13,
      "z": -14,
      "name": "Rock_Stone"
    },
    {
      "x": -5,
      "y": 14,
      "z": -14,
      "name": "Ore_Copper_Stone"
    },
    {
      "x": -5,
      "y": 15,
      "z": -14,
      "name": "Rock_Stone"
    },
    {
      "x": -5,
      "y": 16,
      "z": -14,
      "name": "Rock_Stone"
    },
    {
      "x": -5,
      "y": 17,
      "z": -14,
      "name": "Soil_Grass_Dry_Full"
    },
    {
      "x": -5,
      "y": 25,
      "z": -14,
      "name": "Plant_Leaves_Dry"
    },
    {
      "x": -5,
      "y": 8,
      "z": -13,
      "name": "Plant_Moss_Cave_Yellow",
      "rotation": 8
    },
    {
      "x": -5,
      "y": 9,
      "z": -13,
      "name": "Rock_Stone"
    },
    {
      "x": -5,
      "y": 10,
      "z": -13,
      "name": "Rock_Stone"
    },
    {
      "x": -5,
      "y": 11,
      "z": -13,
      "name": "Rock_Stone"
    },
    {
      "x": -5,
      "y": 12,
      "z": -13,
      "name": "Rock_Stone"
    },
    {
      "x": -5,
      "y": 13,
      "z": -13,
      "name": "Rock_Stone"
    },
    {
      "x": -5,
      "y": 14,
      "z": -13,
      "name": "Rock_Stone"
    },
    {
      "x": -5,
      "y": 15,
      "z": -13,
      "name": "Rock_Stone"
    },
    {
      "x": -5,
      "y": 16,
      "z": -13,
      "name": "Rock_Stone_Mossy"
    },
    {
      "x": -5,
      "y": 17,
      "z": -13,
      "name": "Soil_Grass_Dry_Full"
    },
    {
      "x": -5,
      "y": 18,
      "z": -13,
      "name": "Plant_Moss_Yellow"
    },
    {
      "x": -5,
      "y": 25,
      "z": -13,
      "name": "Plant_Leaves_Dry"
    },
    {
      "x": -5,
      "y": 9,
      "z": -12,
      "name": "Rock_Stone"
    },
    {
      "x": -5,
      "y": 10,
      "z": -12,
      "name": "Rock_Stone"
    },
    {
      "x": -5,
      "y": 11,
      "z": -12,
      "name": "Rock_Stone"
    },
    {
      "x": -5,
      "y": 12,
      "z": -12,
      "name": "Rock_Stone"
    },
    {
      "x": -5,
      "y": 13,
      "z": -12,
      "name": "Rock_Stone"
    },
    {
      "x": -5,
      "y": 14,
      "z": -12,
      "name": "Rock_Stone"
    },
    {
      "x": -5,
      "y": 15,
      "z": -12,
      "name": "Rock_Stone"
    },
    {
      "x": -5,
      "y": 16,
      "z": -12,
      "name": "Rock_Stone"
    },
    {
      "x": -5,
      "y": 17,
      "z": -12,
      "name": "Soil_Grass_Dry_Full"
    },
    {
      "x": -5,
      "y": 25,
      "z": -12,
      "name": "Wood_Dry_Branch_Long",
      "rotation": 5
    },
    {
      "x": -5,
      "y": 26,
      "z": -12,
      "name": "Plant_Leaves_Dry"
    },
    {
      "x": -5,
      "y": 8,
      "z": -11,
      "name": "Rock_Stone"
    },
    {
      "x": -5,
      "y": 9,
      "z": -11,
      "name": "Rock_Stone"
    },
    {
      "x": -5,
      "y": 10,
      "z": -11,
      "name": "Rock_Stone"
    },
    {
      "x": -5,
      "y": 11,
      "z": -11,
      "name": "Rock_Stone"
    },
    {
      "x": -5,
      "y": 12,
      "z": -11,
      "name": "Rock_Stone"
    },
    {
      "x": -5,
      "y": 13,
      "z": -11,
      "name": "Rock_Stone"
    },
    {
      "x": -5,
      "y": 14,
      "z": -11,
      "name": "Rock_Stone"
    },
    {
      "x": -5,
      "y": 15,
      "z": -11,
      "name": "Rock_Stone"
    },
    {
      "x": -5,
      "y": 16,
      "z": -11,
      "name": "Rock_Stone"
    },
    {
      "x": -5,
      "y": 17,
      "z": -11,
      "name": "Rock_Stone"
    },
    {
      "x": -5,
      "y": 18,
      "z": -11,
      "name": "Soil_Grass_Dry_Full"
    },
    {
      "x": -5,
      "y": 22,
      "z": -11,
      "name": "Plant_Leaves_Dry"
    },
    {
      "x": -5,
      "y": 26,
      "z": -11,
      "name": "Plant_Leaves_Dry"
    },
    {
      "x": -5,
      "y": 8,
      "z": -10,
      "name": "Plant_Moss_Cave_Yellow",
      "rotation": 8
    },
    {
      "x": -5,
      "y": 9,
      "z": -10,
      "name": "Rock_Stone"
    },
    {
      "x": -5,
      "y": 10,
      "z": -10,
      "name": "Rock_Stone"
    },
    {
      "x": -5,
      "y": 11,
      "z": -10,
      "name": "Rock_Stone"
    },
    {
      "x": -5,
      "y": 12,
      "z": -10,
      "name": "Rock_Stone"
    },
    {
      "x": -5,
      "y": 13,
      "z": -10,
      "name": "Rock_Stone"
    },
    {
      "x": -5,
      "y": 14,
      "z": -10,
      "name": "Rock_Stone"
    },
    {
      "x": -5,
      "y": 15,
      "z": -10,
      "name": "Rock_Stone"
    },
    {
      "x": -5,
      "y": 16,
      "z": -10,
      "name": "Rock_Stone"
    },
    {
      "x": -5,
      "y": 17,
      "z": -10,
      "name": "Rock_Stone"
    },
    {
      "x": -5,
      "y": 18,
      "z": -10,
      "name": "Soil_Grass_Dry_Full"
    },
    {
      "x": -5,
      "y": 9,
      "z": -9,
      "name": "Rock_Stone"
    },
    {
      "x": -5,
      "y": 10,
      "z": -9,
      "name": "Rock_Stone"
    },
    {
      "x": -5,
      "y": 11,
      "z": -9,
      "name": "Rock_Stone"
    },
    {
      "x": -5,
      "y": 12,
      "z": -9,
      "name": "Rock_Stone"
    },
    {
      "x": -5,
      "y": 13,
      "z": -9,
      "name": "Rock_Stone"
    },
    {
      "x": -5,
      "y": 14,
      "z": -9,
      "name": "Rock_Stone"
    },
    {
      "x": -5,
      "y": 15,
      "z": -9,
      "name": "Rock_Stone"
    },
    {
      "x": -5,
      "y": 16,
      "z": -9,
      "name": "Rock_Stone"
    },
    {
      "x": -5,
      "y": 17,
      "z": -9,
      "name": "Rock_Stone"
    },
    {
      "x": -5,
      "y": 18,
      "z": -9,
      "name": "Soil_Grass_Dry_Full"
    },
    {
      "x": -5,
      "y": 19,
      "z": -9,
      "name": "Plant_Bramble_Moss_Twisted"
    },
    {
      "x": -5,
      "y": 29,
      "z": -9,
      "name": "Plant_Leaves_Dry"
    },
    {
      "x": -5,
      "y": 8,
      "z": -8,
      "name": "Rock_Stone"
    },
    {
      "x": -5,
      "y": 9,
      "z": -8,
      "name": "Rock_Stone"
    },
    {
      "x": -5,
      "y": 10,
      "z": -8,
      "name": "Rock_Stone"
    },
    {
      "x": -5,
      "y": 11,
      "z": -8,
      "name": "Rock_Stone"
    },
    {
      "x": -5,
      "y": 12,
      "z": -8,
      "name": "Rock_Stone"
    },
    {
      "x": -5,
      "y": 13,
      "z": -8,
      "name": "Rock_Stone"
    },
    {
      "x": -5,
      "y": 14,
      "z": -8,
      "name": "Rock_Stone"
    },
    {
      "x": -5,
      "y": 15,
      "z": -8,
      "name": "Ore_Copper_Stone"
    },
    {
      "x": -5,
      "y": 16,
      "z": -8,
      "name": "Rock_Stone_Mossy"
    },
    {
      "x": -5,
      "y": 17,
      "z": -8,
      "name": "Rock_Stone"
    },
    {
      "x": -5,
      "y": 18,
      "z": -8,
      "name": "Soil_Dirt"
    },
    {
      "x": -5,
      "y": 19,
      "z": -8,
      "name": "Wood_Dry_Trunk"
    },
    {
      "x": -5,
      "y": 20,
      "z": -8,
      "name": "Wood_Dry_Trunk"
    },
    {
      "x": -5,
      "y": 21,
      "z": -8,
      "name": "Wood_Dry_Trunk"
    },
    {
      "x": -5,
      "y": 22,
      "z": -8,
      "name": "Wood_Dry_Trunk_Full"
    },
    {
      "x": -5,
      "y": 23,
      "z": -8,
      "name": "Wood_Dry_Trunk_Full"
    },
    {
      "x": -5,
      "y": 29,
      "z": -8,
      "name": "Plant_Leaves_Dry"
    },
    {
      "x": -5,
      "y": 9,
      "z": -7,
      "name": "Rock_Stone"
    },
    {
      "x": -5,
      "y": 10,
      "z": -7,
      "name": "Rock_Stone"
    },
    {
      "x": -5,
      "y": 11,
      "z": -7,
      "name": "Rock_Stone"
    },
    {
      "x": -5,
      "y": 12,
      "z": -7,
      "name": "Rock_Stone"
    },
    {
      "x": -5,
      "y": 13,
      "z": -7,
      "name": "Rock_Stone"
    },
    {
      "x": -5,
      "y": 14,
      "z": -7,
      "name": "Rock_Stone"
    },
    {
      "x": -5,
      "y": 15,
      "z": -7,
      "name": "Rock_Stone"
    },
    {
      "x": -5,
      "y": 16,
      "z": -7,
      "name": "Rock_Stone_Mossy"
    },
    {
      "x": -5,
      "y": 17,
      "z": -7,
      "name": "Soil_Grass_Dry_Full"
    },
    {
      "x": -5,
      "y": 18,
      "z": -7,
      "name": "Wood_Dry_Trunk"
    },
    {
      "x": -5,
      "y": 19,
      "z": -7,
      "name": "Wood_Dry_Trunk"
    },
    {
      "x": -5,
      "y": 20,
      "z": -7,
      "name": "Wood_Dry_Trunk"
    },
    {
      "x": -5,
      "y": 21,
      "z": -7,
      "name": "Wood_Dry_Trunk_Full"
    },
    {
      "x": -5,
      "y": 29,
      "z": -7,
      "name": "Plant_Leaves_Dry"
    },
    {
      "x": -5,
      "y": 9,
      "z": -6,
      "name": "Plant_Moss_Cave_Yellow",
      "rotation": 8
    },
    {
      "x": -5,
      "y": 10,
      "z": -6,
      "name": "Rock_Stone"
    },
    {
      "x": -5,
      "y": 11,
      "z": -6,
      "name": "Rock_Stone"
    },
    {
      "x": -5,
      "y": 12,
      "z": -6,
      "name": "Rock_Stone"
    },
    {
      "x": -5,
      "y": 13,
      "z": -6,
      "name": "Rock_Stone"
    },
    {
      "x": -5,
      "y": 14,
      "z": -6,
      "name": "Rock_Stone"
    },
    {
      "x": -5,
      "y": 15,
      "z": -6,
      "name": "Rock_Stone"
    },
    {
      "x": -5,
      "y": 16,
      "z": -6,
      "name": "Rock_Stone"
    },
    {
      "x": -5,
      "y": 17,
      "z": -6,
      "name": "Soil_Grass_Dry_Full"
    },
    {
      "x": -5,
      "y": 18,
      "z": -6,
      "name": "Plant_Moss_Yellow"
    },
    {
      "x": -5,
      "y": 29,
      "z": -6,
      "name": "Plant_Leaves_Dry"
    },
    {
      "x": -5,
      "y": 9,
      "z": -5,
      "name": "Plant_Moss_Cave_Yellow",
      "rotation": 8
    },
    {
      "x": -5,
      "y": 10,
      "z": -5,
      "name": "Rock_Stone"
    },
    {
      "x": -5,
      "y": 11,
      "z": -5,
      "name": "Rock_Stone"
    },
    {
      "x": -5,
      "y": 12,
      "z": -5,
      "name": "Rock_Stone"
    },
    {
      "x": -5,
      "y": 13,
      "z": -5,
      "name": "Rock_Stone"
    },
    {
      "x": -5,
      "y": 14,
      "z": -5,
      "name": "Rock_Stone"
    },
    {
      "x": -5,
      "y": 15,
      "z": -5,
      "name": "Rock_Stone"
    },
    {
      "x": -5,
      "y": 16,
      "z": -5,
      "name": "Rock_Stone"
    },
    {
      "x": -5,
      "y": 17,
      "z": -5,
      "name": "Soil_Grass_Dry_Full"
    },
    {
      "x": -5,
      "y": 22,
      "z": -5,
      "name": "Plant_Leaves_Dry"
    },
    {
      "x": -5,
      "y": 29,
      "z": -5,
      "name": "Plant_Leaves_Dry"
    },
    {
      "x": -5,
      "y": 10,
      "z": -4,
      "name": "Rock_Stone"
    },
    {
      "x": -5,
      "y": 11,
      "z": -4,
      "name": "Rock_Stone"
    },
    {
      "x": -5,
      "y": 12,
      "z": -4,
      "name": "Rock_Stone"
    },
    {
      "x": -5,
      "y": 13,
      "z": -4,
      "name": "Rock_Stone"
    },
    {
      "x": -5,
      "y": 14,
      "z": -4,
      "name": "Rock_Stone"
    },
    {
      "x": -5,
      "y": 15,
      "z": -4,
      "name": "Rock_Stone"
    },
    {
      "x": -5,
      "y": 16,
      "z": -4,
      "name": "Soil_Grass_Dry_Full"
    },
    {
      "x": -5,
      "y": 17,
      "z": -4,
      "name": "Plant_Moss_Rug_Yellow"
    },
    {
      "x": -5,
      "y": 10,
      "z": -3,
      "name": "Rock_Stone_Stalactite_Large",
      "filler": 31744,
      "rotation": 8
    },
    {
      "x": -5,
      "y": 11,
      "z": -3,
      "name": "Rock_Stone_Stalactite_Large",
      "rotation": 8
    },
    {
      "x": -5,
      "y": 12,
      "z": -3,
      "name": "Rock_Stone"
    },
    {
      "x": -5,
      "y": 13,
      "z": -3,
      "name": "Rock_Stone"
    },
    {
      "x": -5,
      "y": 14,
      "z": -3,
      "name": "Rock_Stone"
    },
    {
      "x": -5,
      "y": 15,
      "z": -3,
      "name": "Rock_Stone"
    },
    {
      "x": -5,
      "y": 16,
      "z": -3,
      "name": "Soil_Grass_Dry_Full"
    },
    {
      "x": -5,
      "y": 17,
      "z": -3,
      "name": "Plant_Moss_Rug_Yellow"
    },
    {
      "x": -5,
      "y": 15,
      "z": -2,
      "name": "Soil_Grass_Dry_Full"
    },
    {
      "x": -5,
      "y": 16,
      "z": -2,
      "name": "Plant_Moss_Rug_Yellow"
    },
    {
      "x": -5,
      "y": 15,
      "z": -1,
      "name": "Plant_Moss_Wall_Yellow"
    },
    {
      "x": -4,
      "y": 12,
      "z": -16,
      "name": "Rock_Stone"
    },
    {
      "x": -4,
      "y": 13,
      "z": -16,
      "name": "Rock_Stone"
    },
    {
      "x": -4,
      "y": 14,
      "z": -16,
      "name": "Soil_Grass_Dry_Full"
    },
    {
      "x": -4,
      "y": 15,
      "z": -16,
      "name": "Plant_Moss_Wall_Yellow",
      "rotation": 2
    },
    {
      "x": -4,
      "y": 25,
      "z": -16,
      "name": "Plant_Leaves_Dry"
    },
    {
      "x": -4,
      "y": 12,
      "z": -15,
      "name": "Rock_Stone"
    },
    {
      "x": -4,
      "y": 13,
      "z": -15,
      "name": "Rock_Stone"
    },
    {
      "x": -4,
      "y": 14,
      "z": -15,
      "name": "Rock_Stone"
    },
    {
      "x": -4,
      "y": 15,
      "z": -15,
      "name": "Rock_Stone"
    },
    {
      "x": -4,
      "y": 16,
      "z": -15,
      "name": "Soil_Grass_Dry_Full"
    },
    {
      "x": -4,
      "y": 17,
      "z": -15,
      "name": "Plant_Moss_Rug_Yellow"
    },
    {
      "x": -4,
      "y": 25,
      "z": -15,
      "name": "Plant_Leaves_Dry"
    },
    {
      "x": -4,
      "y": 10,
      "z": -14,
      "name": "Rock_Stone"
    },
    {
      "x": -4,
      "y": 11,
      "z": -14,
      "name": "Rock_Stone"
    },
    {
      "x": -4,
      "y": 12,
      "z": -14,
      "name": "Rock_Stone"
    },
    {
      "x": -4,
      "y": 13,
      "z": -14,
      "name": "Rock_Stone"
    },
    {
      "x": -4,
      "y": 14,
      "z": -14,
      "name": "Ore_Copper_Stone"
    },
    {
      "x": -4,
      "y": 15,
      "z": -14,
      "name": "Rock_Stone_Mossy"
    },
    {
      "x": -4,
      "y": 16,
      "z": -14,
      "name": "Rock_Stone"
    },
    {
      "x": -4,
      "y": 17,
      "z": -14,
      "name": "Soil_Grass_Dry_Full"
    },
    {
      "x": -4,
      "y": 25,
      "z": -14,
      "name": "Plant_Leaves_Dry"
    },
    {
      "x": -4,
      "y": 10,
      "z": -13,
      "name": "Rock_Stone"
    },
    {
      "x": -4,
      "y": 11,
      "z": -13,
      "name": "Rock_Stone"
    },
    {
      "x": -4,
      "y": 12,
      "z": -13,
      "name": "Rock_Stone"
    },
    {
      "x": -4,
      "y": 13,
      "z": -13,
      "name": "Rock_Stone"
    },
    {
      "x": -4,
      "y": 14,
      "z": -13,
      "name": "Ore_Copper_Stone"
    },
    {
      "x": -4,
      "y": 15,
      "z": -13,
      "name": "Rock_Stone_Mossy"
    },
    {
      "x": -4,
      "y": 16,
      "z": -13,
      "name": "Rock_Stone"
    },
    {
      "x": -4,
      "y": 17,
      "z": -13,
      "name": "Soil_Grass_Dry_Full"
    },
    {
      "x": -4,
      "y": 26,
      "z": -13,
      "name": "Plant_Leaves_Dry"
    },
    {
      "x": -4,
      "y": 10,
      "z": -12,
      "name": "Rock_Stone"
    },
    {
      "x": -4,
      "y": 11,
      "z": -12,
      "name": "Rock_Stone"
    },
    {
      "x": -4,
      "y": 12,
      "z": -12,
      "name": "Rock_Stone"
    },
    {
      "x": -4,
      "y": 13,
      "z": -12,
      "name": "Rock_Stone"
    },
    {
      "x": -4,
      "y": 14,
      "z": -12,
      "name": "Rock_Stone"
    },
    {
      "x": -4,
      "y": 15,
      "z": -12,
      "name": "Rock_Stone"
    },
    {
      "x": -4,
      "y": 16,
      "z": -12,
      "name": "Rock_Stone"
    },
    {
      "x": -4,
      "y": 17,
      "z": -12,
      "name": "Soil_Grass_Dry_Full"
    },
    {
      "x": -4,
      "y": 18,
      "z": -12,
      "name": "Plant_Moss_Yellow"
    },
    {
      "x": -4,
      "y": 25,
      "z": -12,
      "name": "Wood_Dry_Branch_Long",
      "rotation": 5
    },
    {
      "x": -4,
      "y": 26,
      "z": -12,
      "name": "Plant_Leaves_Dry"
    },
    {
      "x": -4,
      "y": 9,
      "z": -11,
      "name": "Rock_Stone"
    },
    {
      "x": -4,
      "y": 10,
      "z": -11,
      "name": "Rock_Stone"
    },
    {
      "x": -4,
      "y": 11,
      "z": -11,
      "name": "Rock_Stone"
    },
    {
      "x": -4,
      "y": 12,
      "z": -11,
      "name": "Rock_Stone"
    },
    {
      "x": -4,
      "y": 13,
      "z": -11,
      "name": "Rock_Stone"
    },
    {
      "x": -4,
      "y": 14,
      "z": -11,
      "name": "Rock_Stone"
    },
    {
      "x": -4,
      "y": 15,
      "z": -11,
      "name": "Rock_Stone"
    },
    {
      "x": -4,
      "y": 16,
      "z": -11,
      "name": "Rock_Stone"
    },
    {
      "x": -4,
      "y": 17,
      "z": -11,
      "name": "Soil_Grass_Dry_Full"
    },
    {
      "x": -4,
      "y": 18,
      "z": -11,
      "name": "Plant_Crop_Stamina2"
    },
    {
      "x": -4,
      "y": 26,
      "z": -11,
      "name": "Plant_Leaves_Dry"
    },
    {
      "x": -4,
      "y": 29,
      "z": -11,
      "name": "Plant_Leaves_Dry"
    },
    {
      "x": -4,
      "y": 8,
      "z": -10,
      "name": "Rock_Gem_Topaz",
      "rotation": 8
    },
    {
      "x": -4,
      "y": 9,
      "z": -10,
      "name": "Rock_Stone"
    },
    {
      "x": -4,
      "y": 10,
      "z": -10,
      "name": "Rock_Stone"
    },
    {
      "x": -4,
      "y": 11,
      "z": -10,
      "name": "Rock_Stone"
    },
    {
      "x": -4,
      "y": 12,
      "z": -10,
      "name": "Rock_Stone"
    },
    {
      "x": -4,
      "y": 13,
      "z": -10,
      "name": "Rock_Stone"
    },
    {
      "x": -4,
      "y": 14,
      "z": -10,
      "name": "Rock_Stone"
    },
    {
      "x": -4,
      "y": 15,
      "z": -10,
      "name": "Rock_Stone"
    },
    {
      "x": -4,
      "y": 16,
      "z": -10,
      "name": "Rock_Stone"
    },
    {
      "x": -4,
      "y": 17,
      "z": -10,
      "name": "Rock_Stone"
    },
    {
      "x": -4,
      "y": 18,
      "z": -10,
      "name": "Soil_Grass_Dry_Full"
    },
    {
      "x": -4,
      "y": 26,
      "z": -10,
      "name": "Plant_Leaves_Dry"
    },
    {
      "x": -4,
      "y": 7,
      "z": -9,
      "name": "Plant_Moss_Cave_Yellow",
      "rotation": 8
    },
    {
      "x": -4,
      "y": 8,
      "z": -9,
      "name": "Rock_Stone"
    },
    {
      "x": -4,
      "y": 9,
      "z": -9,
      "name": "Rock_Stone"
    },
    {
      "x": -4,
      "y": 10,
      "z": -9,
      "name": "Rock_Stone"
    },
    {
      "x": -4,
      "y": 11,
      "z": -9,
      "name": "Rock_Stone"
    },
    {
      "x": -4,
      "y": 12,
      "z": -9,
      "name": "Rock_Stone"
    },
    {
      "x": -4,
      "y": 13,
      "z": -9,
      "name": "Rock_Stone"
    },
    {
      "x": -4,
      "y": 14,
      "z": -9,
      "name": "Rock_Stone"
    },
    {
      "x": -4,
      "y": 15,
      "z": -9,
      "name": "Rock_Stone"
    },
    {
      "x": -4,
      "y": 16,
      "z": -9,
      "name": "Rock_Stone"
    },
    {
      "x": -4,
      "y": 17,
      "z": -9,
      "name": "Rock_Stone_Mossy"
    },
    {
      "x": -4,
      "y": 18,
      "z": -9,
      "name": "Soil_Grass_Dry_Full"
    },
    {
      "x": -4,
      "y": 24,
      "z": -9,
      "name": "Wood_Dry_Trunk"
    },
    {
      "x": -4,
      "y": 25,
      "z": -9,
      "name": "Wood_Dry_Trunk_Full"
    },
    {
      "x": -4,
      "y": 8,
      "z": -8,
      "name": "Rock_Stone"
    },
    {
      "x": -4,
      "y": 9,
      "z": -8,
      "name": "Rock_Stone"
    },
    {
      "x": -4,
      "y": 10,
      "z": -8,
      "name": "Rock_Stone"
    },
    {
      "x": -4,
      "y": 11,
      "z": -8,
      "name": "Rock_Stone"
    },
    {
      "x": -4,
      "y": 12,
      "z": -8,
      "name": "Rock_Stone"
    },
    {
      "x": -4,
      "y": 13,
      "z": -8,
      "name": "Rock_Stone"
    },
    {
      "x": -4,
      "y": 14,
      "z": -8,
      "name": "Rock_Stone"
    },
    {
      "x": -4,
      "y": 15,
      "z": -8,
      "name": "Rock_Stone"
    },
    {
      "x": -4,
      "y": 16,
      "z": -8,
      "name": "Rock_Stone"
    },
    {
      "x": -4,
      "y": 17,
      "z": -8,
      "name": "Rock_Stone"
    },
    {
      "x": -4,
      "y": 18,
      "z": -8,
      "name": "Soil_Dirt"
    },
    {
      "x": -4,
      "y": 19,
      "z": -8,
      "name": "Wood_Dry_Trunk"
    },
    {
      "x": -4,
      "y": 20,
      "z": -8,
      "name": "Wood_Dry_Trunk_Full"
    },
    {
      "x": -4,
      "y": 23,
      "z": -8,
      "name": "Wood_Dry_Trunk"
    },
    {
      "x": -4,
      "y": 24,
      "z": -8,
      "name": "Wood_Dry_Trunk_Full"
    },
    {
      "x": -4,
      "y": 29,
      "z": -8,
      "name": "Wood_Dry_Branch_Long",
      "rotation": 5
    },
    {
      "x": -4,
      "y": 8,
      "z": -7,
      "name": "Plant_Moss_Cave_Yellow",
      "rotation": 8
    },
    {
      "x": -4,
      "y": 9,
      "z": -7,
      "name": "Rock_Stone"
    },
    {
      "x": -4,
      "y": 10,
      "z": -7,
      "name": "Rock_Stone"
    },
    {
      "x": -4,
      "y": 11,
      "z": -7,
      "name": "Rock_Stone"
    },
    {
      "x": -4,
      "y": 12,
      "z": -7,
      "name": "Rock_Stone"
    },
    {
      "x": -4,
      "y": 13,
      "z": -7,
      "name": "Rock_Stone"
    },
    {
      "x": -4,
      "y": 14,
      "z": -7,
      "name": "Rock_Stone"
    },
    {
      "x": -4,
      "y": 15,
      "z": -7,
      "name": "Rock_Stone"
    },
    {
      "x": -4,
      "y": 16,
      "z": -7,
      "name": "Rock_Stone"
    },
    {
      "x": -4,
      "y": 17,
      "z": -7,
      "name": "Soil_Grass_Dry_Full"
    },
    {
      "x": -4,
      "y": 18,
      "z": -7,
      "name": "Plant_Bramble_Moss_Twisted"
    },
    {
      "x": -4,
      "y": 19,
      "z": -7,
      "name": "Plant_Bramble_Moss_Twisted"
    },
    {
      "x": -4,
      "y": 29,
      "z": -7,
      "name": "Plant_Leaves_Dry"
    },
    {
      "x": -4,
      "y": 9,
      "z": -6,
      "name": "Plant_Moss_Cave_Yellow",
      "rotation": 8
    },
    {
      "x": -4,
      "y": 10,
      "z": -6,
      "name": "Rock_Stone"
    },
    {
      "x": -4,
      "y": 11,
      "z": -6,
      "name": "Rock_Stone"
    },
    {
      "x": -4,
      "y": 12,
      "z": -6,
      "name": "Rock_Stone"
    },
    {
      "x": -4,
      "y": 13,
      "z": -6,
      "name": "Rock_Stone"
    },
    {
      "x": -4,
      "y": 14,
      "z": -6,
      "name": "Rock_Stone"
    },
    {
      "x": -4,
      "y": 15,
      "z": -6,
      "name": "Rock_Stone"
    },
    {
      "x": -4,
      "y": 16,
      "z": -6,
      "name": "Rock_Stone"
    },
    {
      "x": -4,
      "y": 17,
      "z": -6,
      "name": "Soil_Grass_Dry_Full"
    },
    {
      "x": -4,
      "y": 29,
      "z": -6,
      "name": "Plant_Leaves_Dry"
    },
    {
      "x": -4,
      "y": 10,
      "z": -5,
      "name": "Rock_Stone"
    },
    {
      "x": -4,
      "y": 11,
      "z": -5,
      "name": "Rock_Stone"
    },
    {
      "x": -4,
      "y": 12,
      "z": -5,
      "name": "Rock_Stone"
    },
    {
      "x": -4,
      "y": 13,
      "z": -5,
      "name": "Rock_Stone"
    },
    {
      "x": -4,
      "y": 14,
      "z": -5,
      "name": "Ore_Copper_Stone"
    },
    {
      "x": -4,
      "y": 15,
      "z": -5,
      "name": "Rock_Stone"
    },
    {
      "x": -4,
      "y": 16,
      "z": -5,
      "name": "Rock_Stone"
    },
    {
      "x": -4,
      "y": 17,
      "z": -5,
      "name": "Soil_Grass_Dry_Full"
    },
    {
      "x": -4,
      "y": 18,
      "z": -5,
      "name": "Plant_Moss_Rug_Yellow"
    },
    {
      "x": -4,
      "y": 29,
      "z": -5,
      "name": "Plant_Leaves_Dry"
    },
    {
      "x": -4,
      "y": 9,
      "z": -4,
      "name": "Plant_Moss_Cave_Yellow",
      "rotation": 8
    },
    {
      "x": -4,
      "y": 10,
      "z": -4,
      "name": "Rock_Stone"
    },
    {
      "x": -4,
      "y": 11,
      "z": -4,
      "name": "Rock_Stone"
    },
    {
      "x": -4,
      "y": 12,
      "z": -4,
      "name": "Rock_Stone"
    },
    {
      "x": -4,
      "y": 13,
      "z": -4,
      "name": "Rock_Stone"
    },
    {
      "x": -4,
      "y": 14,
      "z": -4,
      "name": "Rock_Stone"
    },
    {
      "x": -4,
      "y": 15,
      "z": -4,
      "name": "Rock_Stone"
    },
    {
      "x": -4,
      "y": 16,
      "z": -4,
      "name": "Soil_Grass_Dry_Full"
    },
    {
      "x": -4,
      "y": 17,
      "z": -4,
      "name": "Plant_Moss_Yellow"
    },
    {
      "x": -4,
      "y": 9,
      "z": -3,
      "name": "Plant_Moss_Cave_Yellow",
      "rotation": 8
    },
    {
      "x": -4,
      "y": 10,
      "z": -3,
      "name": "Rock_Stone"
    },
    {
      "x": -4,
      "y": 11,
      "z": -3,
      "name": "Rock_Stone"
    },
    {
      "x": -4,
      "y": 12,
      "z": -3,
      "name": "Rock_Stone"
    },
    {
      "x": -4,
      "y": 13,
      "z": -3,
      "name": "Rock_Stone"
    },
    {
      "x": -4,
      "y": 14,
      "z": -3,
      "name": "Rock_Stone"
    },
    {
      "x": -4,
      "y": 15,
      "z": -3,
      "name": "Rock_Stone"
    },
    {
      "x": -4,
      "y": 16,
      "z": -3,
      "name": "Soil_Grass_Dry_Full"
    },
    {
      "x": -4,
      "y": 17,
      "z": -3,
      "name": "Plant_Moss_Rug_Yellow"
    },
    {
      "x": -4,
      "y": 11,
      "z": -2,
      "name": "Rock_Stone_Stalactite_Large",
      "filler": 31744,
      "rotation": 8
    },
    {
      "x": -4,
      "y": 12,
      "z": -2,
      "name": "Rock_Stone_Stalactite_Large",
      "rotation": 8
    },
    {
      "x": -4,
      "y": 13,
      "z": -2,
      "name": "Rock_Stone"
    },
    {
      "x": -4,
      "y": 14,
      "z": -2,
      "name": "Rock_Stone"
    },
    {
      "x": -4,
      "y": 15,
      "z": -2,
      "name": "Rock_Stone"
    },
    {
      "x": -4,
      "y": 16,
      "z": -2,
      "name": "Soil_Grass_Dry_Full"
    },
    {
      "x": -4,
      "y": 17,
      "z": -2,
      "name": "Plant_Moss_Rug_Yellow"
    },
    {
      "x": -4,
      "y": 15,
      "z": -1,
      "name": "Plant_Moss_Wall_Yellow"
    },
    {
      "x": -4,
      "y": 16,
      "z": -1,
      "name": "Plant_Moss_Wall_Yellow"
    },
    {
      "x": -3,
      "y": 14,
      "z": -16,
      "name": "Plant_Moss_Wall_Yellow",
      "rotation": 1
    },
    {
      "x": -3,
      "y": 25,
      "z": -16,
      "name": "Plant_Leaves_Dry"
    },
    {
      "x": -3,
      "y": 12,
      "z": -15,
      "name": "Rock_Stone"
    },
    {
      "x": -3,
      "y": 13,
      "z": -15,
      "name": "Rock_Stone"
    },
    {
      "x": -3,
      "y": 14,
      "z": -15,
      "name": "Soil_Grass_Dry_Full"
    },
    {
      "x": -3,
      "y": 15,
      "z": -15,
      "name": "Plant_Moss_Wall_Yellow",
      "rotation": 2
    },
    {
      "x": -3,
      "y": 25,
      "z": -15,
      "name": "Plant_Leaves_Dry"
    },
    {
      "x": -3,
      "y": 12,
      "z": -14,
      "name": "Ore_Copper_Stone"
    },
    {
      "x": -3,
      "y": 13,
      "z": -14,
      "name": "Rock_Stone_Mossy"
    },
    {
      "x": -3,
      "y": 14,
      "z": -14,
      "name": "Rock_Stone_Mossy"
    },
    {
      "x": -3,
      "y": 15,
      "z": -14,
      "name": "Soil_Grass_Dry_Full"
    },
    {
      "x": -3,
      "y": 25,
      "z": -14,
      "name": "Plant_Leaves_Dry"
    },
    {
      "x": -3,
      "y": 12,
      "z": -13,
      "name": "Rock_Stone"
    },
    {
      "x": -3,
      "y": 13,
      "z": -13,
      "name": "Ore_Copper_Stone"
    },
    {
      "x": -3,
      "y": 14,
      "z": -13,
      "name": "Rock_Stone"
    },
    {
      "x": -3,
      "y": 15,
      "z": -13,
      "name": "Rock_Stone"
    },
    {
      "x": -3,
      "y": 16,
      "z": -13,
      "name": "Soil_Grass_Dry_Full"
    },
    {
      "x": -3,
      "y": 25,
      "z": -13,
      "name": "Wood_Dry_Branch_Long",
      "rotation": 4
    },
    {
      "x": -3,
      "y": 26,
      "z": -13,
      "name": "Plant_Leaves_Dry"
    },
    {
      "x": -3,
      "y": 11,
      "z": -12,
      "name": "Rock_Stone"
    },
    {
      "x": -3,
      "y": 12,
      "z": -12,
      "name": "Rock_Stone"
    },
    {
      "x": -3,
      "y": 13,
      "z": -12,
      "name": "Rock_Stone"
    },
    {
      "x": -3,
      "y": 14,
      "z": -12,
      "name": "Rock_Stone"
    },
    {
      "x": -3,
      "y": 15,
      "z": -12,
      "name": "Rock_Stone"
    },
    {
      "x": -3,
      "y": 16,
      "z": -12,
      "name": "Soil_Grass_Dry_Full"
    },
    {
      "x": -3,
      "y": 17,
      "z": -12,
      "name": "Plant_Moss_Yellow"
    },
    {
      "x": -3,
      "y": 25,
      "z": -12,
      "name": "Wood_Dry_Trunk_Full"
    },
    {
      "x": -3,
      "y": 29,
      "z": -12,
      "name": "Plant_Leaves_Dry"
    },
    {
      "x": -3,
      "y": 10,
      "z": -11,
      "name": "Rock_Stone"
    },
    {
      "x": -3,
      "y": 11,
      "z": -11,
      "name": "Rock_Stone"
    },
    {
      "x": -3,
      "y": 12,
      "z": -11,
      "name": "Rock_Stone"
    },
    {
      "x": -3,
      "y": 13,
      "z": -11,
      "name": "Rock_Stone"
    },
    {
      "x": -3,
      "y": 14,
      "z": -11,
      "name": "Rock_Stone"
    },
    {
      "x": -3,
      "y": 15,
      "z": -11,
      "name": "Rock_Stone"
    },
    {
      "x": -3,
      "y": 16,
      "z": -11,
      "name": "Rock_Stone"
    },
    {
      "x": -3,
      "y": 17,
      "z": -11,
      "name": "Soil_Grass_Dry_Full"
    },
    {
      "x": -3,
      "y": 25,
      "z": -11,
      "name": "Wood_Dry_Trunk_Full"
    },
    {
      "x": -3,
      "y": 29,
      "z": -11,
      "name": "Plant_Leaves_Dry"
    },
    {
      "x": -3,
      "y": 6,
      "z": -10,
      "name": "Rock_Stone_Stalactite_Large",
      "filler": 31744,
      "rotation": 8
    },
    {
      "x": -3,
      "y": 7,
      "z": -10,
      "name": "Rock_Stone_Stalactite_Large",
      "rotation": 8
    },
    {
      "x": -3,
      "y": 8,
      "z": -10,
      "name": "Rock_Stone"
    },
    {
      "x": -3,
      "y": 9,
      "z": -10,
      "name": "Rock_Stone"
    },
    {
      "x": -3,
      "y": 10,
      "z": -10,
      "name": "Rock_Stone"
    },
    {
      "x": -3,
      "y": 11,
      "z": -10,
      "name": "Rock_Stone"
    },
    {
      "x": -3,
      "y": 12,
      "z": -10,
      "name": "Rock_Stone"
    },
    {
      "x": -3,
      "y": 13,
      "z": -10,
      "name": "Rock_Stone"
    },
    {
      "x": -3,
      "y": 14,
      "z": -10,
      "name": "Rock_Stone"
    },
    {
      "x": -3,
      "y": 15,
      "z": -10,
      "name": "Ore_Copper_Stone"
    },
    {
      "x": -3,
      "y": 16,
      "z": -10,
      "name": "Rock_Stone"
    },
    {
      "x": -3,
      "y": 17,
      "z": -10,
      "name": "Rock_Stone"
    },
    {
      "x": -3,
      "y": 18,
      "z": -10,
      "name": "Soil_Grass_Dry_Full"
    },
    {
      "x": -3,
      "y": 25,
      "z": -10,
      "name": "Wood_Dry_Trunk_Full"
    },
    {
      "x": -3,
      "y": 7,
      "z": -9,
      "name": "Plant_Moss_Cave_Yellow",
      "rotation": 8
    },
    {
      "x": -3,
      "y": 8,
      "z": -9,
      "name": "Rock_Stone"
    },
    {
      "x": -3,
      "y": 9,
      "z": -9,
      "name": "Rock_Stone"
    },
    {
      "x": -3,
      "y": 10,
      "z": -9,
      "name": "Rock_Stone"
    },
    {
      "x": -3,
      "y": 11,
      "z": -9,
      "name": "Rock_Stone"
    },
    {
      "x": -3,
      "y": 12,
      "z": -9,
      "name": "Rock_Stone"
    },
    {
      "x": -3,
      "y": 13,
      "z": -9,
      "name": "Rock_Stone"
    },
    {
      "x": -3,
      "y": 14,
      "z": -9,
      "name": "Rock_Stone"
    },
    {
      "x": -3,
      "y": 15,
      "z": -9,
      "name": "Ore_Copper_Stone"
    },
    {
      "x": -3,
      "y": 16,
      "z": -9,
      "name": "Rock_Stone"
    },
    {
      "x": -3,
      "y": 17,
      "z": -9,
      "name": "Rock_Stone"
    },
    {
      "x": -3,
      "y": 18,
      "z": -9,
      "name": "Soil_Grass_Dry_Full"
    },
    {
      "x": -3,
      "y": 25,
      "z": -9,
      "name": "Wood_Dry_Trunk_Full"
    },
    {
      "x": -3,
      "y": 26,
      "z": -9,
      "name": "Wood_Dry_Trunk"
    },
    {
      "x": -3,
      "y": 27,
      "z": -9,
      "name": "Wood_Dry_Trunk_Full"
    },
    {
      "x": -3,
      "y": 30,
      "z": -9,
      "name": "Plant_Leaves_Dry"
    },
    {
      "x": -3,
      "y": 7,
      "z": -8,
      "name": "Plant_Moss_Cave_Yellow",
      "rotation": 8
    },
    {
      "x": -3,
      "y": 8,
      "z": -8,
      "name": "Rock_Stone"
    },
    {
      "x": -3,
      "y": 9,
      "z": -8,
      "name": "Rock_Stone"
    },
    {
      "x": -3,
      "y": 10,
      "z": -8,
      "name": "Rock_Stone"
    },
    {
      "x": -3,
      "y": 11,
      "z": -8,
      "name": "Rock_Stone"
    },
    {
      "x": -3,
      "y": 12,
      "z": -8,
      "name": "Rock_Stone"
    },
    {
      "x": -3,
      "y": 13,
      "z": -8,
      "name": "Rock_Stone"
    },
    {
      "x": -3,
      "y": 14,
      "z": -8,
      "name": "Rock_Stone"
    },
    {
      "x": -3,
      "y": 15,
      "z": -8,
      "name": "Rock_Stone"
    },
    {
      "x": -3,
      "y": 16,
      "z": -8,
      "name": "Rock_Stone"
    },
    {
      "x": -3,
      "y": 17,
      "z": -8,
      "name": "Rock_Stone"
    },
    {
      "x": -3,
      "y": 18,
      "z": -8,
      "name": "Soil_Grass_Dry_Full"
    },
    {
      "x": -3,
      "y": 19,
      "z": -8,
      "name": "Plant_Bramble_Moss_Twisted"
    },
    {
      "x": -3,
      "y": 27,
      "z": -8,
      "name": "Wood_Dry_Trunk_Full"
    },
    {
      "x": -3,
      "y": 29,
      "z": -8,
      "name": "Wood_Dry_Branch_Long",
      "rotation": 5
    },
    {
      "x": -3,
      "y": 10,
      "z": -7,
      "name": "Rock_Stone"
    },
    {
      "x": -3,
      "y": 11,
      "z": -7,
      "name": "Rock_Stone"
    },
    {
      "x": -3,
      "y": 12,
      "z": -7,
      "name": "Rock_Stone"
    },
    {
      "x": -3,
      "y": 13,
      "z": -7,
      "name": "Rock_Stone"
    },
    {
      "x": -3,
      "y": 14,
      "z": -7,
      "name": "Rock_Stone"
    },
    {
      "x": -3,
      "y": 15,
      "z": -7,
      "name": "Rock_Stone"
    },
    {
      "x": -3,
      "y": 16,
      "z": -7,
      "name": "Rock_Stone"
    },
    {
      "x": -3,
      "y": 17,
      "z": -7,
