{
  "version": 8,
  "blockIdVersion": 11,
  "anchorX": 0,
  "anchorY": 0,
  "anchorZ": 0,
  "blocks": [
    {
      "x": -11,
      "y": 19,
      "z": -2,
      "name": "Plant_Vine_Wall_Poisoned",
      "rotation": 3
    },
    {
      "x": -11,
      "y": 20,
      "z": -2,
      "name": "Plant_Vine_Wall_Poisoned",
      "rotation": 3
    },
    {
      "x": -11,
      "y": 20,
      "z": -1,
      "name": "Plant_Vine_Wall_Poisoned",
      "rotation": 3
    },
    {
      "x": -11,
      "y": 21,
      "z": -1,
      "name": "Plant_Vine_Wall_Poisoned",
      "rotation": 3
    },
    {
      "x": -11,
      "y": 21,
      "z": 0,
      "name": "Plant_Vine_Wall_Poisoned",
      "rotation": 3
    },
    {
      "x": -11,
      "y": 22,
      "z": 0,
      "name": "Plant_Vine_Wall_Poisoned",
      "rotation": 3
    },
    {
      "x": -10,
      "y": 20,
      "z": -3,
      "name": "Rock_Sandstone"
    },
    {
      "x": -10,
      "y": 21,
      "z": -3,
      "name": "Ore_Silver_Sandstone"
    },
    {
      "x": -10,
      "y": 22,
      "z": -3,
      "name": "Soil_Sand_Red"
    },
    {
      "x": -10,
      "y": 23,
      "z": -3,
      "name": "Soil_Sand_Red"
    },
    {
      "x": -10,
      "y": 24,
      "z": -3,
      "name": "Plant_Bramble_Dry_Magic"
    },
    {
      "x": -10,
      "y": 25,
      "z": -3,
      "name": "Plant_Bramble_Dry_Magic"
    },
    {
      "x": -10,
      "y": 18,
      "z": -2,
      "name": "Rock_Sandstone_Red"
    },
    {
      "x": -10,
      "y": 19,
      "z": -2,
      "name": "Rock_Sandstone_Red"
    },
    {
      "x": -10,
      "y": 20,
      "z": -2,
      "name": "Rock_Sandstone"
    },
    {
      "x": -10,
      "y": 21,
      "z": -2,
      "name": "Rock_Sandstone"
    },
    {
      "x": -10,
      "y": 22,
      "z": -2,
      "name": "Soil_Gravel_Sand_Red"
    },
    {
      "x": -10,
      "y": 23,
      "z": -2,
      "name": "Soil_Sand_Red"
    },
    {
      "x": -10,
      "y": 24,
      "z": -2,
      "name": "Plant_Bramble_Dry_Magic"
    },
    {
      "x": -10,
      "y": 14,
      "z": -1,
      "name": "Rock_Sandstone_Red"
    },
    {
      "x": -10,
      "y": 15,
      "z": -1,
      "name": "Rock_Sandstone_Red"
    },
    {
      "x": -10,
      "y": 16,
      "z": -1,
      "name": "Rock_Sandstone_Red"
    },
    {
      "x": -10,
      "y": 17,
      "z": -1,
      "name": "Rock_Sandstone_Red"
    },
    {
      "x": -10,
      "y": 18,
      "z": -1,
      "name": "Rock_Sandstone_Red_Cobble"
    },
    {
      "x": -10,
      "y": 19,
      "z": -1,
      "name": "Rock_Sandstone_Red"
    },
    {
      "x": -10,
      "y": 20,
      "z": -1,
      "name": "Rock_Sandstone_Red"
    },
    {
      "x": -10,
      "y": 21,
      "z": -1,
      "name": "Rock_Sandstone"
    },
    {
      "x": -10,
      "y": 22,
      "z": -1,
      "name": "Soil_Gravel_Sand_Red"
    },
    {
      "x": -10,
      "y": 23,
      "z": -1,
      "name": "Soil_Sand_Red"
    },
    {
      "x": -10,
      "y": 14,
      "z": 0,
      "name": "Rock_Sandstone_Red_Cobble"
    },
    {
      "x": -10,
      "y": 15,
      "z": 0,
      "name": "Rock_Sandstone_Red"
    },
    {
      "x": -10,
      "y": 16,
      "z": 0,
      "name": "Rock_Sandstone_Red"
    },
    {
      "x": -10,
      "y": 17,
      "z": 0,
      "name": "Rock_Sandstone"
    },
    {
      "x": -10,
      "y": 18,
      "z": 0,
      "name": "Rock_Sandstone"
    },
    {
      "x": -10,
      "y": 19,
      "z": 0,
      "name": "Rock_Sandstone"
    },
    {
      "x": -10,
      "y": 20,
      "z": 0,
      "name": "Rock_Sandstone"
    },
    {
      "x": -10,
      "y": 21,
      "z": 0,
      "name": "Rock_Sandstone"
    },
    {
      "x": -10,
      "y": 22,
      "z": 0,
      "name": "Soil_Sand_Red"
    },
    {
      "x": -10,
      "y": 23,
      "z": 0,
      "name": "Soil_Gravel_Sand_Red"
    },
    {
      "x": -10,
      "y": 15,
      "z": 1,
      "name": "Rock_Crystal_Red_Medium",
      "rotation": 7
    },
    {
      "x": -10,
      "y": 16,
      "z": 1,
      "name": "Rock_Sandstone_Red"
    },
    {
      "x": -10,
      "y": 17,
      "z": 1,
      "name": "Rock_Sandstone_Red"
    },
    {
      "x": -10,
      "y": 18,
      "z": 1,
      "name": "Rock_Sandstone"
    },
    {
      "x": -10,
      "y": 19,
      "z": 1,
      "name": "Rock_Sandstone"
    },
    {
      "x": -10,
      "y": 20,
      "z": 1,
      "name": "Rock_Sandstone"
    },
    {
      "x": -10,
      "y": 21,
      "z": 1,
      "name": "Rock_Sandstone"
    },
    {
      "x": -10,
      "y": 22,
      "z": 1,
      "name": "Soil_Sand_Red"
    },
    {
      "x": -10,
      "y": 23,
      "z": 1,
      "name": "Soil_Gravel_Sand_Red"
    },
    {
      "x": -10,
      "y": 20,
      "z": 2,
      "name": "Rock_Sandstone"
    },
    {
      "x": -10,
      "y": 21,
      "z": 2,
      "name": "Rock_Sandstone"
    },
    {
      "x": -10,
      "y": 22,
      "z": 2,
      "name": "Soil_Sand_Red"
    },
    {
      "x": -10,
      "y": 17,
      "z": 3,
      "name": "Plant_Vine_Wall_Poisoned",
      "rotation": 3
    },
    {
      "x": -10,
      "y": 18,
      "z": 3,
      "name": "Plant_Vine_Wall_Poisoned",
      "rotation": 3
    },
    {
      "x": -10,
      "y": 19,
      "z": 3,
      "name": "Plant_Vine_Wall_Poisoned",
      "rotation": 3
    },
    {
      "x": -10,
      "y": 20,
      "z": 3,
      "name": "Plant_Vine_Wall_Poisoned",
      "rotation": 3
    },
    {
      "x": -10,
      "y": 18,
      "z": 4,
      "name": "Plant_Vine_Wall_Poisoned",
      "rotation": 3
    },
    {
      "x": -10,
      "y": 19,
      "z": 4,
      "name": "Plant_Vine_Wall_Poisoned",
      "rotation": 3
    },
    {
      "x": -10,
      "y": 17,
      "z": 5,
      "name": "Plant_Vine_Wall_Poisoned",
      "rotation": 3
    },
    {
      "x": -10,
      "y": 18,
      "z": 5,
      "name": "Plant_Vine_Wall_Poisoned",
      "rotation": 3
    },
    {
      "x": -10,
      "y": 19,
      "z": 5,
      "name": "Rock_Sandstone"
    },
    {
      "x": -10,
      "y": 20,
      "z": 5,
      "name": "Rock_Sandstone"
    },
    {
      "x": -10,
      "y": 21,
      "z": 5,
      "name": "Rubble_Sandstone_Medium"
    },
    {
      "x": -10,
      "y": 14,
      "z": 6,
      "name": "Rock_Crystal_Red_Medium",
      "rotation": 7
    },
    {
      "x": -10,
      "y": 15,
      "z": 6,
      "name": "Rock_Sandstone_Red_Cobble"
    },
    {
      "x": -10,
      "y": 16,
      "z": 6,
      "name": "Rock_Sandstone_Red"
    },
    {
      "x": -10,
      "y": 17,
      "z": 6,
      "name": "Rock_Sandstone_Red"
    },
    {
      "x": -10,
      "y": 18,
      "z": 6,
      "name": "Rock_Sandstone"
    },
    {
      "x": -10,
      "y": 19,
      "z": 6,
      "name": "Rock_Sandstone"
    },
    {
      "x": -10,
      "y": 20,
      "z": 6,
      "name": "Rock_Sandstone"
    },
    {
      "x": -10,
      "y": 21,
      "z": 6,
      "name": "Rock_Sandstone_Stalactite_Large"
    },
    {
      "x": -10,
      "y": 22,
      "z": 6,
      "name": "Rock_Sandstone_Stalactite_Large",
      "filler": 1024
    },
    {
      "x": -10,
      "y": 13,
      "z": 7,
      "name": "Rock_Sandstone_Red"
    },
    {
      "x": -10,
      "y": 14,
      "z": 7,
      "name": "Rock_Sandstone_Red"
    },
    {
      "x": -10,
      "y": 15,
      "z": 7,
      "name": "Rock_Sandstone_Red_Cobble"
    },
    {
      "x": -10,
      "y": 16,
      "z": 7,
      "name": "Rock_Sandstone_Red"
    },
    {
      "x": -10,
      "y": 17,
      "z": 7,
      "name": "Rock_Sandstone_Red"
    },
    {
      "x": -10,
      "y": 18,
      "z": 7,
      "name": "Rock_Sandstone"
    },
    {
      "x": -10,
      "y": 19,
      "z": 7,
      "name": "Rock_Sandstone"
    },
    {
      "x": -10,
      "y": 20,
      "z": 7,
      "name": "Rock_Sandstone"
    },
    {
      "x": -10,
      "y": 21,
      "z": 7,
      "name": "Soil_Sand_Red"
    },
    {
      "x": -10,
      "y": 13,
      "z": 8,
      "name": "Rock_Sandstone_Red"
    },
    {
      "x": -10,
      "y": 14,
      "z": 8,
      "name": "Rock_Sandstone_Red"
    },
    {
      "x": -10,
      "y": 15,
      "z": 8,
      "name": "Rock_Sandstone_Red"
    },
    {
      "x": -10,
      "y": 16,
      "z": 8,
      "name": "Rock_Sandstone"
    },
    {
      "x": -10,
      "y": 17,
      "z": 8,
      "name": "Rock_Sandstone"
    },
    {
      "x": -10,
      "y": 18,
      "z": 8,
      "name": "Rock_Sandstone"
    },
    {
      "x": -10,
      "y": 19,
      "z": 8,
      "name": "Rock_Sandstone"
    },
    {
      "x": -10,
      "y": 20,
      "z": 8,
      "name": "Rock_Sandstone"
    },
    {
      "x": -10,
      "y": 21,
      "z": 8,
      "name": "Soil_Sand_Red"
    },
    {
      "x": -10,
      "y": 22,
      "z": 8,
      "name": "Soil_Sand_Red"
    },
    {
      "x": -10,
      "y": 15,
      "z": 9,
      "name": "Rock_Sandstone"
    },
    {
      "x": -10,
      "y": 16,
      "z": 9,
      "name": "Rock_Sandstone"
    },
    {
      "x": -10,
      "y": 17,
      "z": 9,
      "name": "Rock_Sandstone"
    },
    {
      "x": -10,
      "y": 18,
      "z": 9,
      "name": "Rock_Sandstone"
    },
    {
      "x": -10,
      "y": 19,
      "z": 9,
      "name": "Rock_Sandstone"
    },
    {
      "x": -10,
      "y": 20,
      "z": 9,
      "name": "Rock_Sandstone"
    },
    {
      "x": -10,
      "y": 21,
      "z": 9,
      "name": "Soil_Sand_Red"
    },
    {
      "x": -10,
      "y": 22,
      "z": 9,
      "name": "Soil_Gravel_Sand_Red"
    },
    {
      "x": -10,
      "y": 19,
      "z": 10,
      "name": "Rock_Sandstone"
    },
    {
      "x": -10,
      "y": 20,
      "z": 10,
      "name": "Rock_Sandstone"
    },
    {
      "x": -10,
      "y": 21,
      "z": 10,
      "name": "Soil_Sand_Red"
    },
    {
      "x": -10,
      "y": 22,
      "z": 10,
      "name": "Soil_Sand_Red"
    },
    {
      "x": -9,
      "y": 17,
      "z": -7,
      "name": "Rock_Crystal_Red_Medium",
      "rotation": 7
    },
    {
      "x": -9,
      "y": 21,
      "z": -7,
      "name": "Rock_Sandstone"
    },
    {
      "x": -9,
      "y": 22,
      "z": -7,
      "name": "Rock_Sandstone"
    },
    {
      "x": -9,
      "y": 23,
      "z": -7,
      "name": "Soil_Sand_Red"
    },
    {
      "x": -9,
      "y": 24,
      "z": -7,
      "name": "Soil_Gravel_Sand_Red"
    },
    {
      "x": -9,
      "y": 17,
      "z": -6,
      "name": "Rock_Sandstone_Red_Cobble"
    },
    {
      "x": -9,
      "y": 18,
      "z": -6,
      "name": "Rock_Sandstone_Red"
    },
    {
      "x": -9,
      "y": 19,
      "z": -6,
      "name": "Rock_Sandstone"
    },
    {
      "x": -9,
      "y": 20,
      "z": -6,
      "name": "Rock_Sandstone"
    },
    {
      "x": -9,
      "y": 21,
      "z": -6,
      "name": "Rock_Sandstone"
    },
    {
      "x": -9,
      "y": 22,
      "z": -6,
      "name": "Rock_Sandstone"
    },
    {
      "x": -9,
      "y": 23,
      "z": -6,
      "name": "Soil_Sand_Red"
    },
    {
      "x": -9,
      "y": 24,
      "z": -6,
      "name": "Soil_Sand_Red"
    },
    {
      "x": -9,
      "y": 25,
      "z": -6,
      "name": "Plant_Bramble_Dry_Magic"
    },
    {
      "x": -9,
      "y": 15,
      "z": -5,
      "name": "Rock_Sandstone_Red"
    },
    {
      "x": -9,
      "y": 16,
      "z": -5,
      "name": "Rock_Sandstone_Red"
    },
    {
      "x": -9,
      "y": 17,
      "z": -5,
      "name": "Rock_Sandstone_Red"
    },
    {
      "x": -9,
      "y": 18,
      "z": -5,
      "name": "Rock_Sandstone_Red"
    },
    {
      "x": -9,
      "y": 19,
      "z": -5,
      "name": "Rock_Sandstone_Red"
    },
    {
      "x": -9,
      "y": 20,
      "z": -5,
      "name": "Rock_Sandstone"
    },
    {
      "x": -9,
      "y": 21,
      "z": -5,
      "name": "Rock_Sandstone"
    },
    {
      "x": -9,
      "y": 22,
      "z": -5,
      "name": "Rock_Sandstone"
    },
    {
      "x": -9,
      "y": 23,
      "z": -5,
      "name": "Soil_Sand_Red"
    },
    {
      "x": -9,
      "y": 24,
      "z": -5,
      "name": "Soil_Sand_Red"
    },
    {
      "x": -9,
      "y": 25,
      "z": -5,
      "name": "Plant_Bramble_Dry_Magic"
    },
    {
      "x": -9,
      "y": 26,
      "z": -5,
      "name": "Plant_Bramble_Dry_Magic"
    },
    {
      "x": -9,
      "y": 15,
      "z": -4,
      "name": "Rock_Sandstone_Red_Cobble"
    },
    {
      "x": -9,
      "y": 16,
      "z": -4,
      "name": "Rock_Sandstone_Red"
    },
    {
      "x": -9,
      "y": 17,
      "z": -4,
      "name": "Rock_Sandstone_Red_Stalactite_Small",
      "rotation": 3
    },
    {
      "x": -9,
      "y": 18,
      "z": -4,
      "name": "Rock_Sandstone_Red_Stalactite_Small",
      "rotation": 10
    },
    {
      "x": -9,
      "y": 19,
      "z": -4,
      "name": "Rock_Sandstone_Red"
    },
    {
      "x": -9,
      "y": 20,
      "z": -4,
      "name": "Rock_Sandstone"
    },
    {
      "x": -9,
      "y": 21,
      "z": -4,
      "name": "Rock_Sandstone"
    },
    {
      "x": -9,
      "y": 22,
      "z": -4,
      "name": "Rock_Sandstone"
    },
    {
      "x": -9,
      "y": 23,
      "z": -4,
      "name": "Soil_Sand_Red"
    },
    {
      "x": -9,
      "y": 24,
      "z": -4,
      "name": "Soil_Sand_Red"
    },
    {
      "x": -9,
      "y": 25,
      "z": -4,
      "name": "Plant_Bramble_Dry_Magic"
    },
    {
      "x": -9,
      "y": 14,
      "z": -3,
      "name": "Rock_Sandstone_Red"
    },
    {
      "x": -9,
      "y": 15,
      "z": -3,
      "name": "Rock_Sandstone_Red"
    },
    {
      "x": -9,
      "y": 20,
      "z": -3,
      "name": "Rock_Sandstone"
    },
    {
      "x": -9,
      "y": 21,
      "z": -3,
      "name": "Rock_Sandstone"
    },
    {
      "x": -9,
      "y": 22,
      "z": -3,
      "name": "Rock_Sandstone"
    },
    {
      "x": -9,
      "y": 23,
      "z": -3,
      "name": "Soil_Sand_Red"
    },
    {
      "x": -9,
      "y": 24,
      "z": -3,
      "name": "Soil_Sand_Red"
    },
    {
      "x": -9,
      "y": 12,
      "z": -2,
      "name": "Rock_Sandstone_Red"
    },
    {
      "x": -9,
      "y": 13,
      "z": -2,
      "name": "Rock_Sandstone_Red"
    },
    {
      "x": -9,
      "y": 14,
      "z": -2,
      "name": "Rock_Sandstone_Red"
    },
    {
      "x": -9,
      "y": 19,
      "z": -2,
      "name": "Plant_Vine_Wall_Poisoned",
      "rotation": 2
    },
    {
      "x": -9,
      "y": 20,
      "z": -2,
      "name": "Rock_Sandstone"
    },
    {
      "x": -9,
      "y": 21,
      "z": -2,
      "name": "Rock_Sandstone"
    },
    {
      "x": -9,
      "y": 22,
      "z": -2,
      "name": "Rock_Sandstone"
    },
    {
      "x": -9,
      "y": 23,
      "z": -2,
      "name": "Soil_Sand_Red"
    },
    {
      "x": -9,
      "y": 24,
      "z": -2,
      "name": "Soil_Gravel_Sand_Red"
    },
    {
      "x": -9,
      "y": 9,
      "z": -1,
      "name": "Rock_Sandstone_Red_Stalactite_Large",
      "filler": 31744,
      "rotation": 8
    },
    {
      "x": -9,
      "y": 10,
      "z": -1,
      "name": "Rock_Sandstone_Red_Stalactite_Large",
      "rotation": 8
    },
    {
      "x": -9,
      "y": 11,
      "z": -1,
      "name": "Rock_Sandstone_Red_Cobble"
    },
    {
      "x": -9,
      "y": 12,
      "z": -1,
      "name": "Rock_Sandstone_Red"
    },
    {
      "x": -9,
      "y": 13,
      "z": -1,
      "name": "Rock_Sandstone_Red"
    },
    {
      "x": -9,
      "y": 14,
      "z": -1,
      "name": "Rock_Sandstone_Red"
    },
    {
      "x": -9,
      "y": 15,
      "z": -1,
      "name": "Rock_Sandstone_Red"
    },
    {
      "x": -9,
      "y": 16,
      "z": -1,
      "name": "Rock_Sandstone_Red"
    },
    {
      "x": -9,
      "y": 17,
      "z": -1,
      "name": "Rock_Sandstone_Red_Cobble"
    },
    {
      "x": -9,
      "y": 18,
      "z": -1,
      "name": "Rock_Crystal_Red_Medium",
      "rotation": 6
    },
    {
      "x": -9,
      "y": 19,
      "z": -1,
      "name": "Ore_Gold_Sandstone"
    },
    {
      "x": -9,
      "y": 20,
      "z": -1,
      "name": "Rock_Sandstone_Red"
    },
    {
      "x": -9,
      "y": 21,
      "z": -1,
      "name": "Rock_Sandstone"
    },
    {
      "x": -9,
      "y": 22,
      "z": -1,
      "name": "Soil_Sand_Red"
    },
    {
      "x": -9,
      "y": 23,
      "z": -1,
      "name": "Soil_Gravel_Sand_Red"
    },
    {
      "x": -9,
      "y": 11,
      "z": 0,
      "name": "Rock_Sandstone_Red_Cobble"
    },
    {
      "x": -9,
      "y": 12,
      "z": 0,
      "name": "Rock_Sandstone_Red"
    },
    {
      "x": -9,
      "y": 13,
      "z": 0,
      "name": "Rock_Sandstone_Red"
    },
    {
      "x": -9,
      "y": 14,
      "z": 0,
      "name": "Rock_Sandstone_Red"
    },
    {
      "x": -9,
      "y": 15,
      "z": 0,
      "name": "Rock_Sandstone_Red"
    },
    {
      "x": -9,
      "y": 16,
      "z": 0,
      "name": "Rock_Sandstone_Red"
    },
    {
      "x": -9,
      "y": 17,
      "z": 0,
      "name": "Rock_Sandstone_Red_Cobble"
    },
    {
      "x": -9,
      "y": 18,
      "z": 0,
      "name": "Rock_Sandstone_Red"
    },
    {
      "x": -9,
      "y": 19,
      "z": 0,
      "name": "Ore_Gold_Sandstone"
    },
    {
      "x": -9,
      "y": 20,
      "z": 0,
      "name": "Rock_Sandstone_Red"
    },
    {
      "x": -9,
      "y": 21,
      "z": 0,
      "name": "Rock_Sandstone"
    },
    {
      "x": -9,
      "y": 22,
      "z": 0,
      "name": "Soil_Sand_Red"
    },
    {
      "x": -9,
      "y": 23,
      "z": 0,
      "name": "Soil_Gravel_Sand_Red"
    },
    {
      "x": -9,
      "y": 12,
      "z": 1,
      "name": "Rock_Sandstone_Red"
    },
    {
      "x": -9,
      "y": 13,
      "z": 1,
      "name": "Rock_Sandstone_Red"
    },
    {
      "x": -9,
      "y": 14,
      "z": 1,
      "name": "Rock_Sandstone_Red"
    },
    {
      "x": -9,
      "y": 15,
      "z": 1,
      "name": "Rock_Sandstone_Red"
    },
    {
      "x": -9,
      "y": 16,
      "z": 1,
      "name": "Rock_Sandstone_Red"
    },
    {
      "x": -9,
      "y": 17,
      "z": 1,
      "name": "Rock_Sandstone_Red"
    },
    {
      "x": -9,
      "y": 18,
      "z": 1,
      "name": "Rock_Sandstone_Red"
    },
    {
      "x": -9,
      "y": 19,
      "z": 1,
      "name": "Rock_Sandstone"
    },
    {
      "x": -9,
      "y": 20,
      "z": 1,
      "name": "Rock_Sandstone"
    },
    {
      "x": -9,
      "y": 21,
      "z": 1,
      "name": "Ore_Silver_Sandstone"
    },
    {
      "x": -9,
      "y": 22,
      "z": 1,
      "name": "Soil_Sand_Red"
    },
    {
      "x": -9,
      "y": 23,
      "z": 1,
      "name": "Soil_Sand_Red"
    },
    {
      "x": -9,
      "y": 13,
      "z": 2,
      "name": "Rock_Sandstone_Red_Stalactite_Small",
      "rotation": 9
    },
    {
      "x": -9,
      "y": 14,
      "z": 2,
      "name": "Rock_Sandstone_Red_Cobble"
    },
    {
      "x": -9,
      "y": 15,
      "z": 2,
      "name": "Rock_Sandstone_Red"
    },
    {
      "x": -9,
      "y": 16,
      "z": 2,
      "name": "Rock_Sandstone_Red"
    },
    {
      "x": -9,
      "y": 17,
      "z": 2,
      "name": "Rock_Sandstone_Red"
    },
    {
      "x": -9,
      "y": 18,
      "z": 2,
      "name": "Rock_Sandstone_Red"
    },
    {
      "x": -9,
      "y": 19,
      "z": 2,
      "name": "Ore_Gold_Sandstone"
    },
    {
      "x": -9,
      "y": 20,
      "z": 2,
      "name": "Rock_Sandstone"
    },
    {
      "x": -9,
      "y": 21,
      "z": 2,
      "name": "Rock_Sandstone"
    },
    {
      "x": -9,
      "y": 22,
      "z": 2,
      "name": "Soil_Sand_Red"
    },
    {
      "x": -9,
      "y": 23,
      "z": 2,
      "name": "Soil_Sand_Red"
    },
    {
      "x": -9,
      "y": 24,
      "z": 2,
      "name": "Plant_Bramble_Dry_Sandthorn"
    },
    {
      "x": -9,
      "y": 11,
      "z": 3,
      "name": "Rock_Sandstone_Red_Stalactite_Small",
      "rotation": 9
    },
    {
      "x": -9,
      "y": 12,
      "z": 3,
      "name": "Rock_Sandstone_Red"
    },
    {
      "x": -9,
      "y": 13,
      "z": 3,
      "name": "Rock_Sandstone_Red_Cobble"
    },
    {
      "x": -9,
      "y": 14,
      "z": 3,
      "name": "Rock_Sandstone_Red"
    },
    {
      "x": -9,
      "y": 15,
      "z": 3,
      "name": "Rock_Sandstone_Red"
    },
    {
      "x": -9,
      "y": 16,
      "z": 3,
      "name": "Rock_Sandstone_Red"
    },
    {
      "x": -9,
      "y": 17,
      "z": 3,
      "name": "Rock_Sandstone_Red"
    },
    {
      "x": -9,
      "y": 18,
      "z": 3,
      "name": "Rock_Sandstone_Red"
    },
    {
      "x": -9,
      "y": 19,
      "z": 3,
      "name": "Rock_Sandstone"
    },
    {
      "x": -9,
      "y": 20,
      "z": 3,
      "name": "Rock_Sandstone"
    },
    {
      "x": -9,
      "y": 21,
      "z": 3,
      "name": "Rock_Sandstone"
    },
    {
      "x": -9,
      "y": 22,
      "z": 3,
      "name": "Soil_Sand_Red"
    },
    {
      "x": -9,
      "y": 14,
      "z": 4,
      "name": "Rock_Sandstone_Red"
    },
    {
      "x": -9,
      "y": 15,
      "z": 4,
      "name": "Rock_Sandstone_Red_Cobble"
    },
    {
      "x": -9,
      "y": 16,
      "z": 4,
      "name": "Rock_Sandstone_Red"
    },
    {
      "x": -9,
      "y": 17,
      "z": 4,
      "name": "Rock_Sandstone_Red"
    },
    {
      "x": -9,
      "y": 18,
      "z": 4,
      "name": "Rock_Sandstone"
    },
    {
      "x": -9,
      "y": 19,
      "z": 4,
      "name": "Rock_Sandstone"
    },
    {
      "x": -9,
      "y": 20,
      "z": 4,
      "name": "Rock_Sandstone"
    },
    {
      "x": -9,
      "y": 21,
      "z": 4,
      "name": "Rock_Sandstone_Stalactite_Large"
    },
    {
      "x": -9,
      "y": 22,
      "z": 4,
      "name": "Rock_Sandstone_Stalactite_Large",
      "filler": 1024
    },
    {
      "x": -9,
      "y": 13,
      "z": 5,
      "name": "Rock_Sandstone_Red"
    },
    {
      "x": -9,
      "y": 14,
      "z": 5,
      "name": "Rock_Sandstone_Red"
    },
    {
      "x": -9,
      "y": 15,
      "z": 5,
      "name": "Rock_Sandstone_Red"
    },
    {
      "x": -9,
      "y": 16,
      "z": 5,
      "name": "Rock_Sandstone_Red"
    },
    {
      "x": -9,
      "y": 17,
      "z": 5,
      "name": "Rock_Sandstone_Red"
    },
    {
      "x": -9,
      "y": 18,
      "z": 5,
      "name": "Rock_Sandstone"
    },
    {
      "x": -9,
      "y": 19,
      "z": 5,
      "name": "Rock_Sandstone"
    },
    {
      "x": -9,
      "y": 20,
      "z": 5,
      "name": "Rock_Sandstone"
    },
    {
      "x": -9,
      "y": 11,
      "z": 6,
      "name": "Rock_Sandstone_Red"
    },
    {
      "x": -9,
      "y": 12,
      "z": 6,
      "name": "Rock_Sandstone_Red"
    },
    {
      "x": -9,
      "y": 13,
      "z": 6,
      "name": "Rock_Sandstone_Red"
    },
    {
      "x": -9,
      "y": 14,
      "z": 6,
      "name": "Rock_Sandstone_Red"
    },
    {
      "x": -9,
      "y": 15,
      "z": 6,
      "name": "Rock_Sandstone_Red_Cobble"
    },
    {
      "x": -9,
      "y": 16,
      "z": 6,
      "name": "Rock_Sandstone_Red"
    },
    {
      "x": -9,
      "y": 17,
      "z": 6,
      "name": "Rock_Sandstone_Red"
    },
    {
      "x": -9,
      "y": 18,
      "z": 6,
      "name": "Rock_Sandstone"
    },
    {
      "x": -9,
      "y": 19,
      "z": 6,
      "name": "Rock_Sandstone"
    },
    {
      "x": -9,
      "y": 20,
      "z": 6,
      "name": "Rock_Sandstone"
    },
    {
      "x": -9,
      "y": 21,
      "z": 6,
      "name": "Soil_Sand_Red"
    },
    {
      "x": -9,
      "y": 10,
      "z": 7,
      "name": "Rock_Sandstone_Red_Cobble"
    },
    {
      "x": -9,
      "y": 11,
      "z": 7,
      "name": "Rock_Sandstone_Red"
    },
    {
      "x": -9,
      "y": 12,
      "z": 7,
      "name": "Rock_Sandstone_Red"
    },
    {
      "x": -9,
      "y": 13,
      "z": 7,
      "name": "Rock_Sandstone_Red_Cobble"
    },
    {
      "x": -9,
      "y": 14,
      "z": 7,
      "name": "Rock_Sandstone_Red_Cobble"
    },
    {
      "x": -9,
      "y": 15,
      "z": 7,
      "name": "Rock_Sandstone_Red"
    },
    {
      "x": -9,
      "y": 16,
      "z": 7,
      "name": "Rock_Sandstone_Red"
    },
    {
      "x": -9,
      "y": 17,
      "z": 7,
      "name": "Rock_Sandstone_Red_Cobble"
    },
    {
      "x": -9,
      "y": 18,
      "z": 7,
      "name": "Rock_Sandstone"
    },
    {
      "x": -9,
      "y": 19,
      "z": 7,
      "name": "Ore_Gold_Sandstone"
    },
    {
      "x": -9,
      "y": 20,
      "z": 7,
      "name": "Rock_Sandstone"
    },
    {
      "x": -9,
      "y": 21,
      "z": 7,
      "name": "Soil_Sand_Red"
    },
    {
      "x": -9,
      "y": 22,
      "z": 7,
      "name": "Soil_Gravel_Sand_Red"
    },
    {
      "x": -9,
      "y": 8,
      "z": 8,
      "name": "Rock_Sandstone_Red_Stalactite_Large",
      "filler": 31744,
      "rotation": 8
    },
    {
      "x": -9,
      "y": 9,
      "z": 8,
      "name": "Rock_Sandstone_Red_Stalactite_Large",
      "rotation": 8
    },
    {
      "x": -9,
      "y": 10,
      "z": 8,
      "name": "Rock_Sandstone_Red"
    },
    {
      "x": -9,
      "y": 11,
      "z": 8,
      "name": "Rock_Sandstone_Red"
    },
    {
      "x": -9,
      "y": 12,
      "z": 8,
      "name": "Rock_Sandstone_Red_Cobble"
    },
    {
      "x": -9,
      "y": 13,
      "z": 8,
      "name": "Rock_Sandstone_Red"
    },
    {
      "x": -9,
      "y": 14,
      "z": 8,
      "name": "Rock_Sandstone_Red"
    },
    {
      "x": -9,
      "y": 15,
      "z": 8,
      "name": "Rock_Sandstone_Red"
    },
    {
      "x": -9,
      "y": 16,
      "z": 8,
      "name": "Rock_Sandstone_Red"
    },
    {
      "x": -9,
      "y": 17,
      "z": 8,
      "name": "Rock_Sandstone_Red"
    },
    {
      "x": -9,
      "y": 18,
      "z": 8,
      "name": "Ore_Gold_Sandstone"
    },
    {
      "x": -9,
      "y": 19,
      "z": 8,
      "name": "Rock_Sandstone"
    },
    {
      "x": -9,
      "y": 20,
      "z": 8,
      "name": "Rock_Sandstone"
    },
    {
      "x": -9,
      "y": 21,
      "z": 8,
      "name": "Soil_Gravel_Sand_Red"
    },
    {
      "x": -9,
      "y": 22,
      "z": 8,
      "name": "Soil_Gravel_Sand_Red"
    },
    {
      "x": -9,
      "y": 11,
      "z": 9,
      "name": "Rock_Sandstone_Red_Cobble"
    },
    {
      "x": -9,
      "y": 12,
      "z": 9,
      "name": "Rock_Sandstone_Red"
    },
    {
      "x": -9,
      "y": 13,
      "z": 9,
      "name": "Rock_Sandstone_Red"
    },
    {
      "x": -9,
      "y": 14,
      "z": 9,
      "name": "Rock_Sandstone_Red"
    },
    {
      "x": -9,
      "y": 15,
      "z": 9,
      "name": "Rock_Sandstone_Red"
    },
    {
      "x": -9,
      "y": 16,
      "z": 9,
      "name": "Rock_Sandstone_Red"
    },
    {
      "x": -9,
      "y": 17,
      "z": 9,
      "name": "Rock_Sandstone_Red"
    },
    {
      "x": -9,
      "y": 18,
      "z": 9,
      "name": "Rock_Sandstone"
    },
    {
      "x": -9,
      "y": 19,
      "z": 9,
      "name": "Rock_Sandstone"
    },
    {
      "x": -9,
      "y": 20,
      "z": 9,
      "name": "Ore_Silver_Sandstone"
    },
    {
      "x": -9,
      "y": 21,
      "z": 9,
      "name": "Soil_Sand_Red"
    },
    {
      "x": -9,
      "y": 22,
      "z": 9,
      "name": "Soil_Gravel_Sand_Red"
    },
    {
      "x": -9,
      "y": 13,
      "z": 10,
      "name": "Rock_Sandstone_Red"
    },
    {
      "x": -9,
      "y": 14,
      "z": 10,
      "name": "Rock_Sandstone_Red"
    },
    {
      "x": -9,
      "y": 15,
      "z": 10,
      "name": "Rock_Sandstone_Red"
    },
    {
      "x": -9,
      "y": 16,
      "z": 10,
      "name": "Rock_Sandstone_Red"
    },
    {
      "x": -9,
      "y": 17,
      "z": 10,
      "name": "Rock_Sandstone_Red"
    },
    {
      "x": -9,
      "y": 18,
      "z": 10,
      "name": "Rock_Sandstone"
    },
    {
      "x": -9,
      "y": 19,
      "z": 10,
      "name": "Rock_Sandstone"
    },
    {
      "x": -9,
      "y": 20,
      "z": 10,
      "name": "Rock_Sandstone"
    },
    {
      "x": -9,
      "y": 21,
      "z": 10,
      "name": "Soil_Sand_Red"
    },
    {
      "x": -9,
      "y": 22,
      "z": 10,
      "name": "Soil_Sand_Red"
    },
    {
      "x": -9,
      "y": 19,
      "z": 11,
      "name": "Rock_Sandstone"
    },
    {
      "x": -9,
      "y": 20,
      "z": 11,
      "name": "Rock_Sandstone"
    },
    {
      "x": -9,
      "y": 21,
      "z": 11,
      "name": "Soil_Sand_Red"
    },
    {
      "x": -9,
      "y": 22,
      "z": 11,
      "name": "Soil_Sand_Red"
    },
    {
      "x": -8,
      "y": 21,
      "z": -8,
      "name": "Rock_Sandstone"
    },
    {
      "x": -8,
      "y": 22,
      "z": -8,
      "name": "Rock_Sandstone"
    },
    {
      "x": -8,
      "y": 23,
      "z": -8,
      "name": "Soil_Gravel_Sand_Red"
    },
    {
      "x": -8,
      "y": 24,
      "z": -8,
      "name": "Soil_Sand_Red"
    },
    {
      "x": -8,
      "y": 15,
      "z": -7,
      "name": "Rock_Sandstone_Red"
    },
    {
      "x": -8,
      "y": 16,
      "z": -7,
      "name": "Rock_Sandstone_Red"
    },
    {
      "x": -8,
      "y": 17,
      "z": -7,
      "name": "Rock_Sandstone_Red"
    },
    {
      "x": -8,
      "y": 18,
      "z": -7,
      "name": "Rock_Sandstone"
    },
    {
      "x": -8,
      "y": 19,
      "z": -7,
      "name": "Rock_Sandstone"
    },
    {
      "x": -8,
      "y": 20,
      "z": -7,
      "name": "Ore_Gold_Sandstone"
    },
    {
      "x": -8,
      "y": 21,
      "z": -7,
      "name": "Rock_Sandstone"
    },
    {
      "x": -8,
      "y": 22,
      "z": -7,
      "name": "Rock_Sandstone"
    },
    {
      "x": -8,
      "y": 23,
      "z": -7,
      "name": "Soil_Sand_Red"
    },
    {
      "x": -8,
      "y": 24,
      "z": -7,
      "name": "Soil_Gravel_Sand_Red"
    },
    {
      "x": -8,
      "y": 13,
      "z": -6,
      "name": "Rock_Sandstone_Red"
    },
    {
      "x": -8,
      "y": 14,
      "z": -6,
      "name": "Rock_Sandstone_Red"
    },
    {
      "x": -8,
      "y": 15,
      "z": -6,
      "name": "Rock_Sandstone_Red"
    },
    {
      "x": -8,
      "y": 16,
      "z": -6,
      "name": "Rock_Sandstone_Red"
    },
    {
      "x": -8,
      "y": 17,
      "z": -6,
      "name": "Rock_Sandstone_Red"
    },
    {
      "x": -8,
      "y": 18,
      "z": -6,
      "name": "Rock_Sandstone_Red"
    },
    {
      "x": -8,
      "y": 19,
      "z": -6,
      "name": "Rock_Sandstone_Red"
    },
    {
      "x": -8,
      "y": 20,
      "z": -6,
      "name": "Ore_Gold_Sandstone"
    },
    {
      "x": -8,
      "y": 21,
      "z": -6,
      "name": "Rock_Sandstone"
    },
    {
      "x": -8,
      "y": 22,
      "z": -6,
      "name": "Rock_Sandstone"
    },
    {
      "x": -8,
      "y": 23,
      "z": -6,
      "name": "Soil_Sand_Red"
    },
    {
      "x": -8,
      "y": 24,
      "z": -6,
      "name": "Soil_Gravel_Sand_Red"
    },
    {
      "x": -8,
      "y": 25,
      "z": -6,
      "name": "Plant_Bramble_Dry_Magic"
    },
    {
      "x": -8,
      "y": 12,
      "z": -5,
      "name": "Rock_Sandstone_Red"
    },
    {
      "x": -8,
      "y": 13,
      "z": -5,
      "name": "Rock_Sandstone_Red"
    },
    {
      "x": -8,
      "y": 14,
      "z": -5,
      "name": "Rock_Sandstone_Red"
    },
    {
      "x": -8,
      "y": 15,
      "z": -5,
      "name": "Rock_Sandstone_Red"
    },
    {
      "x": -8,
      "y": 16,
      "z": -5,
      "name": "Rock_Sandstone_Red"
    },
    {
      "x": -8,
      "y": 17,
      "z": -5,
      "name": "Rock_Sandstone_Red"
    },
    {
      "x": -8,
      "y": 18,
      "z": -5,
      "name": "Rock_Sandstone_Red_Cobble"
    },
    {
      "x": -8,
      "y": 19,
      "z": -5,
      "name": "Rock_Sandstone_Red"
    },
    {
      "x": -8,
      "y": 20,
      "z": -5,
      "name": "Rock_Sandstone"
    },
    {
      "x": -8,
      "y": 21,
      "z": -5,
      "name": "Rock_Sandstone"
    },
    {
      "x": -8,
      "y": 22,
      "z": -5,
      "name": "Rock_Sandstone"
    },
    {
      "x": -8,
      "y": 23,
      "z": -5,
      "name": "Soil_Sand_Red"
    },
    {
      "x": -8,
      "y": 24,
      "z": -5,
      "name": "Soil_Gravel_Sand_Red"
    },
    {
      "x": -8,
      "y": 12,
      "z": -4,
      "name": "Rock_Sandstone_Red"
    },
    {
      "x": -8,
      "y": 13,
      "z": -4,
      "name": "Rock_Sandstone_Red"
    },
    {
      "x": -8,
      "y": 14,
      "z": -4,
      "name": "Rock_Sandstone_Red"
    },
    {
      "x": -8,
      "y": 15,
      "z": -4,
      "name": "Rock_Sandstone_Red"
    },
    {
      "x": -8,
      "y": 16,
      "z": -4,
      "name": "Rock_Sandstone_Red"
    },
    {
      "x": -8,
      "y": 19,
      "z": -4,
      "name": "Rock_Sandstone_Red"
    },
    {
      "x": -8,
      "y": 20,
      "z": -4,
      "name": "Rock_Sandstone"
    },
    {
      "x": -8,
      "y": 21,
      "z": -4,
      "name": "Rock_Sandstone"
    },
    {
      "x": -8,
      "y": 22,
      "z": -4,
      "name": "Ore_Silver_Sandstone"
    },
    {
      "x": -8,
      "y": 23,
      "z": -4,
      "name": "Soil_Sand_Red"
    },
    {
      "x": -8,
      "y": 24,
      "z": -4,
      "name": "Soil_Gravel_Sand_Red"
    },
    {
      "x": -8,
      "y": 12,
      "z": -3,
      "name": "Rock_Sandstone_Red"
    },
    {
      "x": -8,
      "y": 13,
      "z": -3,
      "name": "Rock_Sandstone_Red"
    },
    {
      "x": -8,
      "y": 14,
      "z": -3,
      "name": "Rock_Sandstone_Red"
    },
    {
      "x": -8,
      "y": 15,
      "z": -3,
      "name": "Rock_Sandstone_Red"
    },
    {
      "x": -8,
      "y": 20,
      "z": -3,
      "name": "Rock_Sandstone"
    },
    {
      "x": -8,
      "y": 21,
      "z": -3,
      "name": "Rock_Sandstone_Red"
    },
    {
      "x": -8,
      "y": 22,
      "z": -3,
      "name": "Rock_Sandstone"
    },
    {
      "x": -8,
      "y": 23,
      "z": -3,
      "name": "Soil_Sand_Red"
    },
    {
      "x": -8,
      "y": 24,
      "z": -3,
      "name": "Soil_Gravel_Sand_Red"
    },
    {
      "x": -8,
      "y": 10,
      "z": -2,
      "name": "Rock_Sandstone_Red"
    },
    {
      "x": -8,
      "y": 11,
      "z": -2,
      "name": "Rock_Sandstone_Red"
    },
    {
      "x": -8,
      "y": 12,
      "z": -2,
      "name": "Rock_Sandstone_Red"
    },
    {
      "x": -8,
      "y": 13,
      "z": -2,
      "name": "Rock_Sandstone_Red"
    },
    {
      "x": -8,
      "y": 14,
      "z": -2,
      "name": "Rock_Sandstone_Red"
    },
    {
      "x": -8,
      "y": 15,
      "z": -2,
      "name": "Rock_Sandstone_Red"
    },
    {
      "x": -8,
      "y": 20,
      "z": -2,
      "name": "Rock_Sandstone_Red"
    },
    {
      "x": -8,
      "y": 21,
      "z": -2,
      "name": "Rock_Sandstone_Red"
    },
    {
      "x": -8,
      "y": 22,
      "z": -2,
      "name": "Rock_Sandstone"
    },
    {
      "x": -8,
      "y": 23,
      "z": -2,
      "name": "Soil_Sand_Red"
    },
    {
      "x": -8,
      "y": 24,
      "z": -2,
      "name": "Soil_Gravel_Sand_Red"
    },
    {
      "x": -8,
      "y": 9,
      "z": -1,
      "name": "Rock_Sandstone_Red"
    },
    {
      "x": -8,
      "y": 10,
      "z": -1,
      "name": "Rock_Sandstone_Red"
    },
    {
      "x": -8,
      "y": 11,
      "z": -1,
      "name": "Rock_Sandstone_Red"
    },
    {
      "x": -8,
      "y": 12,
      "z": -1,
      "name": "Rock_Sandstone_Red"
    },
    {
      "x": -8,
      "y": 13,
      "z": -1,
      "name": "Rock_Sandstone_Red"
    },
    {
      "x": -8,
      "y": 14,
      "z": -1,
      "name": "Rock_Sandstone_Red"
    },
    {
      "x": -8,
      "y": 15,
      "z": -1,
      "name": "Rock_Sandstone_Red"
    },
    {
      "x": -8,
      "y": 16,
      "z": -1,
      "name": "Rock_Sandstone_Red"
    },
    {
      "x": -8,
      "y": 19,
      "z": -1,
      "name": "Rock_Sandstone_Red"
    },
    {
      "x": -8,
      "y": 20,
      "z": -1,
      "name": "Rock_Sandstone"
    },
    {
      "x": -8,
      "y": 21,
      "z": -1,
      "name": "Rock_Sandstone"
    },
    {
      "x": -8,
      "y": 22,
      "z": -1,
      "name": "Rock_Sandstone"
    },
    {
      "x": -8,
      "y": 23,
      "z": -1,
      "name": "Soil_Sand_Red"
    },
    {
      "x": -8,
      "y": 24,
      "z": -1,
      "name": "Soil_Gravel_Sand_Red"
    },
    {
      "x": -8,
      "y": 11,
      "z": 0,
      "name": "Rock_Sandstone_Red"
    },
    {
      "x": -8,
      "y": 12,
      "z": 0,
      "name": "Rock_Sandstone_Red"
    },
    {
      "x": -8,
      "y": 13,
      "z": 0,
      "name": "Rock_Sandstone_Red"
    },
    {
      "x": -8,
      "y": 14,
      "z": 0,
      "name": "Rock_Sandstone_Red"
    },
    {
      "x": -8,
      "y": 15,
      "z": 0,
      "name": "Rock_Sandstone_Red_Cobble"
    },
    {
      "x": -8,
      "y": 16,
      "z": 0,
      "name": "Rock_Sandstone_Red"
    },
    {
      "x": -8,
      "y": 17,
      "z": 0,
      "name": "Rock_Sandstone_Red"
    },
    {
      "x": -8,
      "y": 18,
      "z": 0,
      "name": "Rock_Sandstone_Red"
    },
    {
      "x": -8,
      "y": 19,
      "z": 0,
      "name": "Rock_Sandstone"
    },
    {
      "x": -8,
      "y": 20,
      "z": 0,
      "name": "Rock_Sandstone"
    },
    {
      "x": -8,
      "y": 21,
      "z": 0,
      "name": "Ore_Silver_Sandstone"
    },
    {
      "x": -8,
      "y": 22,
      "z": 0,
      "name": "Soil_Gravel_Sand_Red"
    },
    {
      "x": -8,
      "y": 23,
      "z": 0,
      "name": "Soil_Gravel_Sand_Red"
    },
    {
      "x": -8,
      "y": 10,
      "z": 1,
      "name": "Rock_Sandstone_Red"
    },
    {
      "x": -8,
      "y": 11,
      "z": 1,
      "name": "Rock_Sandstone_Red"
    },
    {
      "x": -8,
      "y": 12,
      "z": 1,
      "name": "Rock_Sandstone_Red"
    },
    {
      "x": -8,
      "y": 13,
      "z": 1,
      "name": "Rock_Sandstone_Red"
    },
    {
      "x": -8,
      "y": 14,
      "z": 1,
      "name": "Rock_Sandstone_Red"
    },
    {
      "x": -8,
      "y": 15,
      "z": 1,
      "name": "Rock_Sandstone_Red_Cobble"
    },
    {
      "x": -8,
      "y": 16,
      "z": 1,
      "name": "Rock_Sandstone_Red"
    },
    {
      "x": -8,
      "y": 17,
      "z": 1,
      "name": "Rock_Sandstone_Red_Cobble"
    },
    {
      "x": -8,
      "y": 18,
      "z": 1,
      "name": "Rock_Sandstone_Red"
    },
    {
      "x": -8,
      "y": 19,
      "z": 1,
      "name": "Rock_Sandstone_Red"
    },
    {
      "x": -8,
      "y": 20,
      "z": 1,
      "name": "Rock_Sandstone"
    },
    {
      "x": -8,
      "y": 21,
      "z": 1,
      "name": "Rock_Sandstone"
    },
    {
      "x": -8,
      "y": 22,
      "z": 1,
      "name": "Soil_Gravel_Sand_Red"
    },
    {
      "x": -8,
      "y": 23,
      "z": 1,
      "name": "Soil_Gravel_Sand_Red"
    },
    {
      "x": -8,
      "y": 8,
      "z": 2,
      "name": "Rock_Sandstone_Red_Stalactite_Large",
      "filler": 31744,
      "rotation": 8
    },
    {
      "x": -8,
      "y": 9,
      "z": 2,
      "name": "Rock_Sandstone_Red_Stalactite_Large",
      "rotation": 8
    },
    {
      "x": -8,
      "y": 10,
      "z": 2,
      "name": "Rock_Sandstone_Red"
    },
    {
      "x": -8,
      "y": 11,
      "z": 2,
      "name": "Rock_Sandstone_Red_Cobble"
    },
    {
      "x": -8,
      "y": 12,
      "z": 2,
      "name": "Rock_Sandstone_Red"
    },
    {
      "x": -8,
      "y": 13,
      "z": 2,
      "name": "Rock_Sandstone_Red"
    },
    {
      "x": -8,
      "y": 14,
      "z": 2,
      "name": "Rock_Sandstone_Red"
    },
    {
      "x": -8,
      "y": 15,
      "z": 2,
      "name": "Rock_Sandstone_Red"
    },
    {
      "x": -8,
      "y": 16,
      "z": 2,
      "name": "Rock_Sandstone_Red"
    },
    {
      "x": -8,
      "y": 17,
      "z": 2,
      "name": "Rock_Sandstone_Red_Cobble"
    },
    {
      "x": -8,
      "y": 18,
      "z": 2,
      "name": "Rock_Sandstone_Red"
    },
    {
      "x": -8,
      "y": 19,
      "z": 2,
      "name": "Rock_Sandstone"
    },
    {
      "x": -8,
      "y": 20,
      "z": 2,
      "name": "Ore_Gold_Sandstone"
    },
    {
      "x": -8,
      "y": 21,
      "z": 2,
      "name": "Ore_Silver_Sandstone"
    },
    {
      "x": -8,
      "y": 22,
      "z": 2,
      "name": "Soil_Sand_Red"
    },
    {
      "x": -8,
      "y": 23,
      "z": 2,
      "name": "Soil_Sand_Red"
    },
    {
      "x": -8,
      "y": 6,
      "z": 3,
      "name": "Rock_Crystal_Red_Medium",
      "rotation": 7
    },
    {
      "x": -8,
      "y": 7,
      "z": 3,
      "name": "Rock_Crystal_Red_Medium",
      "rotation": 7
    },
    {
      "x": -8,
      "y": 8,
      "z": 3,
      "name": "Rock_Crystal_Red_Medium",
      "rotation": 7
    },
    {
      "x": -8,
      "y": 9,
      "z": 3,
      "name": "Rock_Sandstone_Red"
    },
    {
      "x": -8,
      "y": 10,
      "z": 3,
      "name": "Rock_Sandstone_Red"
    },
    {
      "x": -8,
      "y": 11,
      "z": 3,
      "name": "Rock_Sandstone_Red"
    },
    {
      "x": -8,
      "y": 12,
      "z": 3,
      "name": "Rock_Sandstone_Red_Cobble"
    },
    {
      "x": -8,
      "y": 13,
      "z": 3,
      "name": "Rock_Sandstone_Red"
    },
    {
      "x": -8,
      "y": 14,
      "z": 3,
      "name": "Rock_Sandstone_Red"
    },
    {
      "x": -8,
      "y": 15,
      "z": 3,
      "name": "Rock_Sandstone_Red"
    },
    {
      "x": -8,
      "y": 16,
      "z": 3,
      "name": "Rock_Sandstone_Red"
    },
    {
      "x": -8,
      "y": 17,
      "z": 3,
      "name": "Rock_Sandstone_Red_Cobble"
    },
    {
      "x": -8,
      "y": 18,
      "z": 3,
      "name": "Rock_Sandstone_Red"
    },
    {
      "x": -8,
      "y": 19,
      "z": 3,
      "name": "Rock_Sandstone"
    },
    {
      "x": -8,
      "y": 20,
      "z": 3,
      "name": "Rock_Sandstone"
    },
    {
      "x": -8,
      "y": 21,
      "z": 3,
      "name": "Rock_Sandstone"
    },
    {
      "x": -8,
      "y": 22,
      "z": 3,
      "name": "Soil_Sand_Red"
    },
    {
      "x": -8,
      "y": 9,
      "z": 4,
      "name": "Rock_Sandstone_Red"
    },
    {
      "x": -8,
      "y": 10,
      "z": 4,
      "name": "Rock_Sandstone_Red_Cobble"
    },
    {
      "x": -8,
      "y": 11,
      "z": 4,
      "name": "Rock_Sandstone_Red"
    },
    {
      "x": -8,
      "y": 12,
      "z": 4,
      "name": "Rock_Sandstone_Red"
    },
    {
      "x": -8,
      "y": 13,
      "z": 4,
      "name": "Rock_Sandstone_Red"
    },
    {
      "x": -8,
      "y": 14,
      "z": 4,
      "name": "Rock_Sandstone_Red"
    },
    {
      "x": -8,
      "y": 15,
      "z": 4,
      "name": "Rock_Sandstone_Red"
    },
    {
      "x": -8,
      "y": 16,
      "z": 4,
      "name": "Rock_Sandstone_Red"
    },
    {
      "x": -8,
      "y": 17,
      "z": 4,
      "name": "Rock_Sandstone_Red_Cobble"
    },
    {
      "x": -8,
      "y": 18,
      "z": 4,
      "name": "Rock_Sandstone"
    },
    {
      "x": -8,
      "y": 19,
      "z": 4,
      "name": "Rock_Sandstone"
    },
    {
      "x": -8,
      "y": 20,
      "z": 4,
      "name": "Rock_Sandstone"
    },
    {
      "x": -8,
      "y": 10,
      "z": 5,
      "name": "Rock_Sandstone_Red"
    },
    {
      "x": -8,
      "y": 11,
      "z": 5,
      "name": "Rock_Sandstone_Red"
    },
    {
      "x": -8,
      "y": 12,
      "z": 5,
      "name": "Rock_Sandstone_Red"
    },
    {
      "x": -8,
      "y": 13,
      "z": 5,
      "name": "Rock_Sandstone_Red"
    },
    {
      "x": -8,
      "y": 14,
      "z": 5,
      "name": "Rock_Sandstone_Red"
    },
    {
      "x": -8,
      "y": 15,
      "z": 5,
      "name": "Rock_Sandstone_Red"
    },
    {
      "x": -8,
      "y": 16,
      "z": 5,
      "name": "Rock_Sandstone_Red"
    },
    {
      "x": -8,
      "y": 17,
      "z": 5,
      "name": "Rock_Sandstone_Red"
    },
    {
      "x": -8,
      "y": 18,
      "z": 5,
      "name": "Rock_Sandstone_Red"
    },
    {
      "x": -8,
      "y": 19,
      "z": 5,
      "name": "Ore_Silver_Sandstone"
    },
    {
      "x": -8,
      "y": 20,
      "z": 5,
      "name": "Ore_Silver_Sandstone"
    },
    {
      "x": -8,
      "y": 9,
      "z": 6,
      "name": "Rock_Sandstone_Red"
    },
    {
      "x": -8,
      "y": 10,
      "z": 6,
      "name": "Rock_Sandstone_Red"
    },
    {
      "x": -8,
      "y": 11,
      "z": 6,
      "name": "Rock_Sandstone_Red"
    },
    {
      "x": -8,
      "y": 12,
      "z": 6,
      "name": "Rock_Sandstone_Red"
    },
    {
      "x": -8,
      "y": 13,
      "z": 6,
      "name": "Rock_Sandstone_Red"
    },
    {
      "x": -8,
      "y": 14,
      "z": 6,
      "name": "Rock_Sandstone_Red_Cobble"
    },
    {
      "x": -8,
      "y": 15,
      "z": 6,
      "name": "Rock_Sandstone_Red"
    },
    {
      "x": -8,
      "y": 16,
      "z": 6,
      "name": "Rock_Sandstone_Red"
    },
    {
      "x": -8,
      "y": 17,
      "z": 6,
      "name": "Rock_Sandstone_Red"
    },
    {
      "x": -8,
      "y": 18,
      "z": 6,
      "name": "Rock_Sandstone_Red"
    },
    {
      "x": -8,
      "y": 19,
      "z": 6,
      "name": "Rock_Sandstone_Red"
    },
    {
      "x": -8,
      "y": 20,
      "z": 6,
      "name": "Rock_Sandstone"
    },
    {
      "x": -8,
      "y": 21,
      "z": 6,
      "name": "Soil_Sand_Red"
    },
    {
      "x": -8,
      "y": 6,
      "z": 7,
      "name": "Rock_Sandstone_Red_Stalactite_Large",
      "filler": 31744,
      "rotation": 8
    },
    {
      "x": -8,
      "y": 7,
      "z": 7,
      "name": "Rock_Sandstone_Red_Stalactite_Large",
      "rotation": 8
    },
    {
      "x": -8,
      "y": 8,
      "z": 7,
      "name": "Rock_Sandstone_Red"
    },
    {
      "x": -8,
      "y": 9,
      "z": 7,
      "name": "Rock_Sandstone_Red"
    },
    {
      "x": -8,
      "y": 10,
      "z": 7,
      "name": "Rock_Sandstone_Red"
    },
    {
      "x": -8,
      "y": 11,
      "z": 7,
      "name": "Rock_Sandstone_Red"
    },
    {
      "x": -8,
      "y": 12,
      "z": 7,
      "name": "Rock_Sandstone_Red"
    },
    {
      "x": -8,
      "y": 13,
      "z": 7,
      "name": "Rock_Sandstone_Red"
    },
    {
      "x": -8,
      "y": 14,
      "z": 7,
      "name": "Rock_Sandstone_Red"
    },
    {
      "x": -8,
      "y": 15,
      "z": 7,
      "name": "Rock_Sandstone_Red_Cobble"
    },
    {
      "x": -8,
      "y": 16,
      "z": 7,
      "name": "Rock_Sandstone_Red_Cobble"
    },
    {
      "x": -8,
      "y": 17,
      "z": 7,
      "name": "Rock_Sandstone_Red"
    },
    {
      "x": -8,
      "y": 18,
      "z": 7,
      "name": "Rock_Sandstone"
    },
    {
      "x": -8,
      "y": 19,
      "z": 7,
      "name": "Ore_Gold_Sandstone"
    },
    {
      "x": -8,
      "y": 20,
      "z": 7,
      "name": "Rock_Sandstone"
    },
    {
      "x": -8,
      "y": 21,
      "z": 7,
      "name": "Soil_Sand_Red"
    },
    {
      "x": -8,
      "y": 22,
      "z": 7,
      "name": "Soil_Sand_Red"
    },
    {
      "x": -8,
      "y": 4,
      "z": 8,
      "name": "Rock_Sandstone_Red_Stalactite_Large",
      "filler": 31744,
      "rotation": 8
    },
    {
      "x": -8,
      "y": 5,
      "z": 8,
      "name": "Rock_Sandstone_Red_Stalactite_Large",
      "rotation": 8
    },
    {
      "x": -8,
      "y": 6,
      "z": 8,
      "name": "Rock_Sandstone_Red"
    },
    {
      "x": -8,
      "y": 7,
      "z": 8,
      "name": "Rock_Sandstone_Red"
    },
    {
      "x": -8,
      "y": 8,
      "z": 8,
      "name": "Rock_Sandstone_Red"
    },
    {
      "x": -8,
      "y": 9,
      "z": 8,
      "name": "Rock_Sandstone_Red"
    },
    {
      "x": -8,
      "y": 10,
      "z": 8,
      "name": "Rock_Sandstone_Red"
    },
    {
      "x": -8,
      "y": 11,
      "z": 8,
      "name": "Rock_Sandstone_Red"
    },
    {
      "x": -8,
      "y": 12,
      "z": 8,
      "name": "Rock_Sandstone_Red"
    },
    {
      "x": -8,
      "y": 13,
      "z": 8,
      "name": "Rock_Sandstone_Red"
    },
    {
      "x": -8,
      "y": 14,
      "z": 8,
      "name": "Rock_Sandstone_Red"
    },
    {
      "x": -8,
      "y": 15,
      "z": 8,
      "name": "Rock_Sandstone_Red"
    },
    {
      "x": -8,
      "y": 16,
      "z": 8,
      "name": "Rock_Sandstone_Red"
    },
    {
      "x": -8,
      "y": 17,
      "z": 8,
      "name": "Rock_Sandstone_Red_Cobble"
    },
    {
      "x": -8,
      "y": 18,
      "z": 8,
      "name": "Rock_Sandstone"
    },
    {
      "x": -8,
      "y": 19,
      "z": 8,
      "name": "Ore_Gold_Sandstone"
    },
    {
      "x": -8,
      "y": 20,
      "z": 8,
      "name": "Rock_Sandstone"
    },
    {
      "x": -8,
      "y": 21,
      "z": 8,
      "name": "Soil_Sand_Red"
    },
    {
      "x": -8,
      "y": 22,
      "z": 8,
      "name": "Soil_Gravel_Sand_Red"
    },
    {
      "x": -8,
      "y": 9,
      "z": 9,
      "name": "Rock_Sandstone_Red"
    },
    {
      "x": -8,
      "y": 10,
      "z": 9,
      "name": "Rock_Sandstone_Red"
    },
    {
      "x": -8,
      "y": 11,
      "z": 9,
      "name": "Rock_Sandstone_Red"
    },
    {
      "x": -8,
      "y": 12,
      "z": 9,
      "name": "Rock_Sandstone_Red"
    },
    {
      "x": -8,
      "y": 13,
      "z": 9,
      "name": "Rock_Sandstone_Red"
    },
    {
      "x": -8,
      "y": 14,
      "z": 9,
      "name": "Rock_Sandstone_Red"
    },
    {
      "x": -8,
      "y": 15,
      "z": 9,
      "name": "Rock_Sandstone_Red"
    },
    {
      "x": -8,
      "y": 16,
      "z": 9,
      "name": "Rock_Sandstone_Red"
    },
    {
      "x": -8,
      "y": 17,
      "z": 9,
      "name": "Rock_Sandstone_Red"
    },
    {
      "x": -8,
      "y": 18,
      "z": 9,
      "name": "Rock_Sandstone_Red"
    },
    {
      "x": -8,
      "y": 19,
      "z": 9,
      "name": "Ore_Gold_Sandstone"
    },
    {
      "x": -8,
      "y": 20,
      "z": 9,
      "name": "Rock_Sandstone"
    },
    {
      "x": -8,
      "y": 21,
      "z": 9,
      "name": "Soil_Sand_Red"
    },
    {
      "x": -8,
      "y": 22,
      "z": 9,
      "name": "Soil_Gravel_Sand_Red"
    },
    {
      "x": -8,
      "y": 23,
      "z": 9,
      "name": "Plant_Cactus_1",
      "components": {
        "Components": {
          "FarmingBlock": {
            "LastTickGameTime": "0001-01-04T12:00:00Z"
          },
          "PlacedByInteraction": {
            "WhoPlacedUuid": {
              "$binary": "3XRzOktQTQGfL/+8x7+CHA==",
              "$type": "04"
            }
          }
        }
      }
    },
    {
      "x": -8,
      "y": 24,
      "z": 9,
      "name": "Plant_Cactus_Flower"
    },
    {
      "x": -8,
      "y": 11,
      "z": 10,
      "name": "Rock_Sandstone_Red"
    },
    {
      "x": -8,
      "y": 12,
      "z": 10,
      "name": "Rock_Sandstone_Red"
    },
    {
      "x": -8,
      "y": 13,
      "z": 10,
      "name": "Rock_Sandstone_Red"
    },
    {
      "x": -8,
      "y": 14,
      "z": 10,
      "name": "Rock_Sandstone_Red"
    },
    {
      "x": -8,
      "y": 15,
      "z": 10,
      "name": "Rock_Sandstone_Red"
    },
    {
      "x": -8,
      "y": 16,
      "z": 10,
      "name": "Rock_Sandstone_Red"
    },
    {
      "x": -8,
      "y": 17,
      "z": 10,
      "name": "Rock_Sandstone_Red"
    },
    {
      "x": -8,
      "y": 18,
      "z": 10,
      "name": "Rock_Sandstone_Red"
    },
    {
      "x": -8,
      "y": 19,
      "z": 10,
      "name": "Rock_Sandstone"
    },
    {
      "x": -8,
      "y": 20,
      "z": 10,
      "name": "Rock_Sandstone"
    },
    {
      "x": -8,
      "y": 21,
      "z": 10,
      "name": "Soil_Sand_Red"
    },
    {
      "x": -8,
      "y": 22,
      "z": 10,
      "name": "Soil_Gravel_Sand_Red"
    },
    {
      "x": -8,
      "y": 15,
      "z": 11,
      "name": "Rock_Sandstone_Red"
    },
    {
      "x": -8,
      "y": 16,
      "z": 11,
      "name": "Rock_Sandstone_Red"
    },
    {
      "x": -8,
      "y": 17,
      "z": 11,
      "name": "Rock_Sandstone_Red"
    },
    {
      "x": -8,
      "y": 18,
      "z": 11,
      "name": "Rock_Sandstone"
    },
    {
      "x": -8,
      "y": 19,
      "z": 11,
      "name": "Rock_Sandstone"
    },
    {
      "x": -8,
      "y": 20,
      "z": 11,
      "name": "Rock_Sandstone"
    },
    {
      "x": -8,
      "y": 21,
      "z": 11,
      "name": "Soil_Sand_Red"
    },
    {
      "x": -8,
      "y": 22,
      "z": 11,
      "name": "Soil_Gravel_Sand_Red"
    },
    {
      "x": -8,
      "y": 18,
      "z": 12,
      "name": "Plant_Vine_Wall_Poisoned"
    },
    {
      "x": -7,
      "y": 22,
      "z": -9,
      "name": "Plant_Vine_Wall_Poisoned",
      "rotation": 2
    },
    {
      "x": -7,
      "y": 23,
      "z": -9,
      "name": "Plant_Vine_Wall_Poisoned",
      "rotation": 2
    },
    {
      "x": -7,
      "y": 17,
      "z": -8,
      "name": "Rock_Sandstone"
    },
    {
      "x": -7,
      "y": 18,
      "z": -8,
      "name": "Rock_Sandstone"
    },
    {
      "x": -7,
      "y": 19,
      "z": -8,
      "name": "Rock_Sandstone"
    },
    {
      "x": -7,
      "y": 20,
      "z": -8,
      "name": "Rock_Sandstone"
    },
    {
      "x": -7,
      "y": 21,
      "z": -8,
      "name": "Rock_Sandstone"
    },
    {
      "x": -7,
      "y": 22,
      "z": -8,
      "name": "Rock_Sandstone"
    },
    {
      "x": -7,
      "y": 23,
      "z": -8,
      "name": "Soil_Sand_Red"
    },
    {
      "x": -7,
      "y": 24,
      "z": -8,
      "name": "Soil_Sand_Red"
    },
    {
      "x": -7,
      "y": 13,
      "z": -7,
      "name": "Rock_Sandstone_Red"
    },
    {
      "x": -7,
      "y": 14,
      "z": -7,
      "name": "Rock_Sandstone_Red"
    },
    {
      "x": -7,
      "y": 15,
      "z": -7,
      "name": "Rock_Sandstone_Red"
    },
    {
      "x": -7,
      "y": 16,
      "z": -7,
      "name": "Rock_Sandstone_Red"
    },
    {
      "x": -7,
      "y": 17,
      "z": -7,
      "name": "Rock_Sandstone_Red"
    },
    {
      "x": -7,
      "y": 18,
      "z": -7,
      "name": "Rock_Sandstone_Red_Cobble"
    },
    {
      "x": -7,
      "y": 19,
      "z": -7,
      "name": "Rock_Sandstone_Red"
    },
    {
      "x": -7,
      "y": 20,
      "z": -7,
      "name": "Rock_Sandstone"
    },
    {
      "x": -7,
      "y": 21,
      "z": -7,
      "name": "Rock_Sandstone"
    },
    {
      "x": -7,
      "y": 22,
      "z": -7,
      "name": "Rock_Sandstone"
    },
    {
      "x": -7,
      "y": 23,
      "z": -7,
      "name": "Soil_Sand_Red"
    },
    {
      "x": -7,
      "y": 24,
      "z": -7,
      "name": "Soil_Gravel_Sand_Red"
    },
    {
      "x": -7,
      "y": 7,
      "z": -6,
      "name": "Rock_Sandstone_Red_Stalactite_Large",
      "filler": 31744,
      "rotation": 8
    },
    {
      "x": -7,
      "y": 8,
      "z": -6,
      "name": "Rock_Sandstone_Red_Stalactite_Large",
      "rotation": 8
    },
    {
      "x": -7,
      "y": 9,
      "z": -6,
      "name": "Rock_Sandstone_Red"
    },
    {
      "x": -7,
      "y": 10,
      "z": -6,
      "name": "Rock_Sandstone_Red"
    },
    {
      "x": -7,
      "y": 11,
      "z": -6,
      "name": "Rock_Sandstone_Red"
    },
    {
      "x": -7,
      "y": 12,
      "z": -6,
      "name": "Rock_Sandstone_Red"
    },
    {
      "x": -7,
      "y": 13,
      "z": -6,
      "name": "Rock_Sandstone_Red"
    },
    {
      "x": -7,
      "y": 14,
      "z": -6,
      "name": "Rock_Sandstone_Red"
    },
    {
      "x": -7,
      "y": 15,
      "z": -6,
      "name": "Rock_Sandstone_Red_Cobble"
    },
    {
      "x": -7,
      "y": 16,
      "z": -6,
      "name": "Rock_Sandstone_Red"
    },
    {
      "x": -7,
      "y": 17,
      "z": -6,
      "name": "Rock_Sandstone_Red"
    },
    {
      "x": -7,
      "y": 18,
      "z": -6,
      "name": "Rock_Sandstone_Red_Cobble"
    },
    {
      "x": -7,
      "y": 19,
      "z": -6,
      "name": "Rock_Sandstone_Red"
    },
    {
      "x": -7,
      "y": 20,
      "z": -6,
      "name": "Rock_Sandstone"
    },
    {
      "x": -7,
      "y": 21,
      "z": -6,
      "name": "Rock_Sandstone_Red"
    },
    {
      "x": -7,
      "y": 22,
      "z": -6,
      "name": "Rock_Sandstone"
    },
    {
      "x": -7,
      "y": 23,
      "z": -6,
      "name": "Soil_Sand_Red"
    },
    {
      "x": -7,
      "y": 24,
      "z": -6,
      "name": "Soil_Gravel_Sand_Red"
    },
    {
      "x": -7,
      "y": 8,
      "z": -5,
      "name": "Rock_Sandstone_Red_Stalactite_Large",
      "filler": 31744,
      "rotation": 8
    },
    {
      "x": -7,
      "y": 9,
      "z": -5,
      "name": "Rock_Sandstone_Red_Stalactite_Large",
      "rotation": 8
    },
    {
      "x": -7,
      "y": 10,
      "z": -5,
      "name": "Rock_Sandstone_Red"
    },
    {
      "x": -7,
      "y": 11,
      "z": -5,
      "name": "Rock_Sandstone_Red"
    },
    {
      "x": -7,
      "y": 12,
      "z": -5,
      "name": "Rock_Sandstone_Red"
    },
    {
      "x": -7,
      "y": 13,
      "z": -5,
      "name": "Rock_Sandstone_Red_Cobble"
    },
    {
      "x": -7,
      "y": 14,
      "z": -5,
      "name": "Rock_Sandstone_Red"
    },
    {
      "x": -7,
      "y": 15,
      "z": -5,
      "name": "Rock_Sandstone_Red"
    },
    {
      "x": -7,
      "y": 16,
      "z": -5,
      "name": "Rock_Sandstone_Red"
    },
    {
      "x": -7,
      "y": 17,
      "z": -5,
      "name": "Rock_Sandstone_Red"
    },
    {
      "x": -7,
      "y": 18,
      "z": -5,
      "name": "Rock_Sandstone_Red"
    },
    {
      "x": -7,
      "y": 19,
      "z": -5,
      "name": "Rock_Sandstone_Red_Cobble"
    },
    {
      "x": -7,
      "y": 20,
      "z": -5,
      "name": "Rock_Sandstone"
    },
    {
      "x": -7,
      "y": 21,
      "z": -5,
      "name": "Ore_Gold_Sandstone"
    },
    {
      "x": -7,
      "y": 22,
      "z": -5,
      "name": "Ore_Silver_Sandstone"
    },
    {
      "x": -7,
      "y": 23,
      "z": -5,
      "name": "Soil_Sand_Red"
    },
    {
      "x": -7,
      "y": 24,
      "z": -5,
      "name": "Soil_Gravel_Sand_Red"
    },
    {
      "x": -7,
      "y": 10,
      "z": -4,
      "name": "Rock_Sandstone_Red"
    },
    {
      "x": -7,
      "y": 11,
      "z": -4,
      "name": "Rock_Sandstone_Red"
    },
    {
      "x": -7,
      "y": 12,
      "z": -4,
      "name": "Rock_Sandstone_Red"
    },
    {
      "x": -7,
      "y": 13,
      "z": -4,
      "name": "Rock_Sandstone_Red"
    },
    {
      "x": -7,
      "y": 14,
      "z": -4,
      "name": "Rock_Sandstone_Red"
    },
    {
      "x": -7,
      "y": 15,
      "z": -4,
      "name": "Rock_Sandstone_Red"
    },
    {
      "x": -7,
      "y": 19,
      "z": -4,
      "name": "Rock_Sandstone_Red_Cobble"
    },
    {
      "x": -7,
      "y": 20,
      "z": -4,
      "name": "Rock_Sandstone_Red"
    },
    {
      "x": -7,
      "y": 21,
      "z": -4,
      "name": "Rock_Sandstone"
    },
    {
      "x": -7,
      "y": 22,
      "z": -4,
      "name": "Rock_Sandstone"
    },
    {
      "x": -7,
      "y": 23,
      "z": -4,
      "name": "Soil_Sand_Red"
    },
    {
      "x": -7,
      "y": 24,
      "z": -4,
      "name": "Soil_Gravel_Sand_Red"
    },
    {
      "x": -7,
      "y": 11,
      "z": -3,
      "name": "Rock_Sandstone_Red_Cobble"
    },
    {
      "x": -7,
      "y": 12,
      "z": -3,
      "name": "Rock_Sandstone_Red"
    },
    {
      "x": -7,
      "y": 13,
      "z": -3,
      "name": "Rock_Sandstone_Red"
    },
    {
      "x": -7,
      "y": 14,
      "z": -3,
      "name": "Rock_Sandstone_Red"
    },
    {
      "x": -7,
      "y": 15,
      "z": -3,
      "name": "Rock_Sandstone_Red"
    },
    {
      "x": -7,
      "y": 20,
      "z": -3,
      "name": "Rock_Sandstone_Red"
    },
    {
      "x": -7,
      "y": 21,
      "z": -3,
      "name": "Rock_Sandstone"
    },
    {
      "x": -7,
      "y": 22,
      "z": -3,
      "name": "Rock_Sandstone"
    },
    {
      "x": -7,
      "y": 23,
      "z": -3,
      "name": "Soil_Sand_Red"
    },
    {
      "x": -7,
      "y": 24,
      "z": -3,
      "name": "Soil_Gravel_Sand_Red"
    },
    {
      "x": -7,
      "y": 8,
      "z": -2,
      "name": "Rock_Sandstone_Red_Stalactite_Small",
      "rotation": 11
    },
    {
      "x": -7,
      "y": 9,
      "z": -2,
      "name": "Rock_Sandstone_Red"
    },
    {
      "x": -7,
      "y": 10,
      "z": -2,
      "name": "Rock_Sandstone_Red"
    },
    {
      "x": -7,
      "y": 11,
      "z": -2,
      "name": "Rock_Sandstone_Red"
    },
    {
      "x": -7,
      "y": 12,
      "z": -2,
      "name": "Rock_Sandstone_Red"
    },
    {
      "x": -7,
      "y": 13,
      "z": -2,
      "name": "Rock_Sandstone_Red_Cobble"
    },
    {
      "x": -7,
      "y": 14,
      "z": -2,
      "name": "Rock_Sandstone_Red"
    },
    {
      "x": -7,
      "y": 15,
      "z": -2,
      "name": "Rock_Sandstone_Red"
    },
    {
      "x": -7,
      "y": 16,
      "z": -2,
      "name": "Rock_Sandstone_Red"
    },
    {
      "x": -7,
      "y": 17,
      "z": -2,
      "name": "Rock_Sandstone_Red_Stalactite_Small",
      "rotation": 1
    },
    {
      "x": -7,
      "y": 20,
      "z": -2,
      "name": "Rock_Sandstone_Red"
    },
    {
      "x": -7,
      "y": 21,
      "z": -2,
      "name": "Ore_Gold_Sandstone"
    },
    {
      "x": -7,
      "y": 22,
      "z": -2,
      "name": "Rock_Sandstone"
    },
    {
      "x": -7,
      "y": 23,
      "z": -2,
      "name": "Soil_Gravel_Sand_Red"
    },
    {
      "x": -7,
      "y": 24,
      "z": -2,
      "name": "Soil_Gravel_Sand_Red"
    },
    {
      "x": -7,
      "y": 9,
      "z": -1,
      "name": "Rock_Sandstone_Red_Cobble"
    },
    {
      "x": -7,
      "y": 10,
      "z": -1,
      "name": "Rock_Sandstone_Red"
    },
    {
      "x": -7,
      "y": 11,
      "z": -1,
      "name": "Rock_Sandstone_Red"
    },
    {
      "x": -7,
      "y": 12,
      "z": -1,
      "name": "Rock_Sandstone_Red"
    },
    {
      "x": -7,
      "y": 13,
      "z": -1,
      "name": "Rock_Sandstone_Red"
    },
    {
      "x": -7,
      "y": 14,
      "z": -1,
      "name": "Rock_Sandstone_Red"
    },
    {
      "x": -7,
      "y": 15,
      "z": -1,
      "name": "Rock_Sandstone_Red"
    },
    {
      "x": -7,
      "y": 16,
      "z": -1,
      "name": "Rock_Sandstone_Red"
    },
    {
      "x": -7,
      "y": 17,
      "z": -1,
      "name": "Rock_Sandstone_Red"
    },
    {
      "x": -7,
      "y": 18,
      "z": -1,
      "name": "Rock_Sandstone_Red"
    },
    {
      "x": -7,
      "y": 19,
      "z": -1,
      "name": "Rock_Sandstone_Red"
    },
    {
      "x": -7,
      "y": 20,
      "z": -1,
      "name": "Rock_Sandstone"
    },
    {
      "x": -7,
      "y": 21,
      "z": -1,
      "name": "Rock_Sandstone"
    },
    {
      "x": -7,
      "y": 22,
      "z": -1,
      "name": "Rock_Sandstone"
    },
    {
      "x": -7,
      "y": 23,
      "z": -1,
      "name": "Soil_Sand_Red"
    },
    {
      "x": -7,
      "y": 24,
      "z": -1,
      "name": "Soil_Gravel_Sand_Red"
    },
    {
      "x": -7,
      "y": 9,
      "z": 0,
      "name": "Rock_Sandstone_Red_Stalactite_Small",
      "rotation": 9
    },
    {
      "x": -7,
      "y": 10,
      "z": 0,
      "name": "Rock_Sandstone_Red"
    },
    {
      "x": -7,
      "y": 11,
      "z": 0,
      "name": "Rock_Sandstone_Red"
    },
    {
      "x": -7,
      "y": 12,
      "z": 0,
      "name": "Rock_Sandstone_Red"
    },
    {
      "x": -7,
      "y": 13,
      "z": 0,
      "name": "Rock_Sandstone_Red"
    },
    {
      "x": -7,
      "y": 14,
      "z": 0,
      "name": "Rock_Sandstone_Red"
    },
    {
      "x": -7,
      "y": 15,
      "z": 0,
      "name": "Rock_Sandstone_Red"
    },
    {
      "x": -7,
      "y": 16,
      "z": 0,
      "name": "Rock_Sandstone_Red_Cobble"
    },
    {
      "x": -7,
      "y": 17,
      "z": 0,
      "name": "Rock_Sandstone_Red"
    },
    {
      "x": -7,
      "y": 18,
      "z": 0,
      "name": "Rock_Sandstone_Red_Cobble"
    },
    {
      "x": -7,
      "y": 19,
      "z": 0,
      "name": "Ore_Gold_Sandstone"
    },
    {
      "x": -7,
      "y": 20,
      "z": 0,
      "name": "Rock_Sandstone_Red"
    },
    {
      "x": -7,
      "y": 21,
      "z": 0,
      "name": "Ore_Silver_Sandstone"
    },
    {
      "x": -7,
      "y": 22,
      "z": 0,
      "name": "Soil_Sand_Red"
    },
    {
      "x": -7,
      "y": 23,
      "z": 0,
      "name": "Soil_Sand_Red"
    },
    {
      "x": -7,
      "y": 9,
      "z": 1,
      "name": "Rock_Sandstone_Red_Cobble"
    },
    {
      "x": -7,
      "y": 10,
      "z": 1,
      "name": "Rock_Sandstone_Red"
    },
    {
      "x": -7,
      "y": 11,
      "z": 1,
      "name": "Rock_Sandstone_Red"
    },
    {
      "x": -7,
      "y": 12,
      "z": 1,
      "name": "Rock_Sandstone_Red_Cobble"
    },
    {
      "x": -7,
      "y": 13,
      "z": 1,
      "name": "Rock_Sandstone_Red"
    },
    {
      "x": -7,
      "y": 14,
      "z": 1,
      "name": "Rock_Sandstone_Red"
    },
    {
      "x": -7,
      "y": 15,
      "z": 1,
      "name": "Rock_Sandstone_Red"
    },
    {
      "x": -7,
      "y": 16,
      "z": 1,
      "name": "Rock_Sandstone_Red"
    },
    {
      "x": -7,
      "y": 17,
      "z": 1,
      "name": "Rock_Sandstone_Red"
    },
    {
      "x": -7,
      "y": 18,
      "z": 1,
      "name": "Rock_Sandstone_Red"
    },
    {
      "x": -7,
      "y": 19,
      "z": 1,
      "name": "Ore_Gold_Sandstone"
    },
    {
      "x": -7,
      "y": 20,
      "z": 1,
      "name": "Rock_Sandstone"
    },
    {
      "x": -7,
      "y": 21,
      "z": 1,
      "name": "Rock_Sandstone"
    },
    {
      "x": -7,
      "y": 22,
      "z": 1,
      "name": "Soil_Sand_Red"
    },
    {
      "x": -7,
      "y": 23,
      "z": 1,
      "name": "Soil_Sand_Red"
    },
    {
      "x": -7,
      "y": 6,
      "z": 2,
      "name": "Rock_Crystal_Red_Medium",
      "rotation": 6
    },
    {
      "x": -7,
      "y": 7,
      "z": 2,
      "name": "Rock_Crystal_Red_Medium",
      "rotation": 6
    },
    {
      "x": -7,
      "y": 8,
      "z": 2,
      "name": "Rock_Sandstone_Red"
    },
    {
      "x": -7,
      "y": 9,
      "z": 2,
      "name": "Rock_Sandstone_Red"
    },
    {
      "x": -7,
      "y": 10,
      "z": 2,
      "name": "Rock_Sandstone_Red"
    },
    {
      "x": -7,
      "y": 11,
      "z": 2,
      "name": "Rock_Sandstone_Red"
    },
    {
      "x": -7,
      "y": 12,
      "z": 2,
      "name": "Rock_Sandstone_Red"
    },
    {
      "x": -7,
      "y": 13,
      "z": 2,
      "name": "Rock_Sandstone_Red"
    },
    {
      "x": -7,
      "y": 14,
      "z": 2,
      "name": "Rock_Sandstone_Red"
    },
    {
      "x": -7,
      "y": 15,
      "z": 2,
      "name": "Rock_Sandstone_Red"
    },
    {
      "x": -7,
      "y": 16,
      "z": 2,
      "name": "Rock_Sandstone_Red"
    },
    {
      "x": -7,
      "y": 17,
      "z": 2,
      "name": "Rock_Sandstone_Red"
    },
    {
      "x": -7,
      "y": 18,
      "z": 2,
      "name": "Rock_Sandstone_Red"
    },
    {
      "x": -7,
      "y": 19,
      "z": 2,
      "name": "Rock_Sandstone_Red"
    },
    {
      "x": -7,
      "y": 20,
      "z": 2,
      "name": "Rock_Sandstone"
    },
    {
      "x": -7,
      "y": 21,
      "z": 2,
      "name": "Rock_Sandstone"
    },
    {
      "x": -7,
      "y": 22,
      "z": 2,
      "name": "Soil_Sand_Red"
    },
    {
      "x": -7,
      "y": 23,
      "z": 2,
      "name": "Soil_Sand_Red"
    },
    {
      "x": -7,
      "y": 4,
      "z": 3,
      "name": "Rock_Crystal_Red_Medium",
      "rotation": 7
    },
    {
      "x": -7,
      "y": 5,
      "z": 3,
      "name": "Rock_Crystal_Red_Large",
      "rotation": 8
    },
    {
      "x": -7,
      "y": 6,
      "z": 3,
      "name": "Rock_Crystal_Red_Block"
    },
    {
      "x": -7,
      "y": 7,
      "z": 3,
      "name": "Rock_Crystal_Red_Block"
    },
    {
      "x": -7,
      "y": 8,
      "z": 3,
      "name": "Rock_Crystal_Red_Block"
    },
    {
      "x": -7,
      "y": 9,
      "z": 3,
      "name": "Rock_Crystal_Red_Block"
    },
    {
      "x": -7,
      "y": 10,
      "z": 3,
      "name": "Rock_Crystal_Red_Block"
    },
    {
      "x": -7,
      "y": 11,
      "z": 3,
      "name": "Rock_Sandstone_Red_Cobble"
    },
    {
      "x": -7,
      "y": 12,
      "z": 3,
      "name": "Rock_Sandstone_Red"
    },
    {
      "x": -7,
      "y": 13,
      "z": 3,
      "name": "Rock_Sandstone_Red_Cobble"
    },
    {
      "x": -7,
      "y": 14,
      "z": 3,
      "name": "Rock_Sandstone_Red"
    },
    {
      "x": -7,
      "y": 15,
      "z": 3,
      "name": "Rock_Sandstone_Red"
    },
    {
      "x": -7,
      "y": 16,
      "z": 3,
      "name": "Rock_Sandstone_Red"
    },
    {
      "x": -7,
      "y": 17,
      "z": 3,
      "name": "Rock_Sandstone_Red"
    },
    {
      "x": -7,
      "y": 18,
      "z": 3,
      "name": "Rock_Sandstone_Red"
    },
    {
      "x": -7,
      "y": 19,
      "z": 3,
      "name": "Rock_Sandstone_Red"
    },
    {
      "x": -7,
      "y": 20,
      "z": 3,
      "name": "Rock_Sandstone"
    },
    {
      "x": -7,
      "y": 21,
      "z": 3,
      "name": "Rock_Sandstone"
    },
    {
      "x": -7,
      "y": 22,
      "z": 3,
      "name": "Soil_Sand_Red"
    },
    {
      "x": -7,
      "y": 23,
      "z": 3,
      "name": "Soil_Sand_Red"
    },
    {
      "x": -7,
      "y": 5,
      "z": 4,
      "name": "Rock_Crystal_Red_Medium",
      "rotation": 7
    },
    {
      "x": -7,
      "y": 6,
      "z": 4,
      "name": "Rock_Crystal_Red_Medium",
      "rotation": 4
    },
    {
      "x": -7,
      "y": 7,
      "z": 4,
      "name": "Rock_Sandstone_Red"
    },
    {
      "x": -7,
      "y": 8,
      "z": 4,
      "name": "Rock_Sandstone_Red"
    },
    {
      "x": -7,
      "y": 9,
      "z": 4,
      "name": "Rock_Sandstone_Red"
    },
    {
      "x": -7,
      "y": 10,
      "z": 4,
      "name": "Rock_Sandstone_Red"
    },
    {
      "x": -7,
      "y": 11,
      "z": 4,
      "name": "Rock_Sandstone_Red"
    },
    {
      "x": -7,
      "y": 12,
      "z": 4,
      "name": "Rock_Sandstone_Red"
    },
    {
      "x": -7,
      "y": 13,
      "z": 4,
      "name": "Rock_Sandstone_Red"
    },
    {
      "x": -7,
      "y": 14,
      "z": 4,
      "name": "Rock_Sandstone_Red"
    },
    {
      "x": -7,
      "y": 15,
      "z": 4,
      "name": "Rock_Sandstone_Red"
    },
    {
      "x": -7,
      "y": 16,
      "z": 4,
      "name": "Rock_Sandstone_Red"
    },
    {
      "x": -7,
      "y": 17,
      "z": 4,
      "name": "Rock_Sandstone_Red"
    },
    {
      "x": -7,
      "y": 18,
      "z": 4,
      "name": "Rock_Sandstone_Red"
    },
    {
      "x": -7,
      "y": 19,
      "z": 4,
      "name": "Rock_Sandstone"
    },
    {
      "x": -7,
      "y": 20,
      "z": 4,
      "name": "Rock_Sandstone"
    },
    {
      "x": -7,
      "y": 21,
      "z": 4,
      "name": "Rubble_Sandstone_Medium"
    },
    {
      "x": -7,
      "y": 8,
      "z": 5,
      "name": "Rock_Sandstone_Red"
    },
    {
      "x": -7,
      "y": 9,
      "z": 5,
      "name": "Rock_Sandstone_Red"
    },
    {
      "x": -7,
      "y": 10,
      "z": 5,
      "name": "Rock_Sandstone_Red"
    },
    {
      "x": -7,
      "y": 11,
      "z": 5,
      "name": "Rock_Sandstone_Red_Cobble"
    },
    {
      "x": -7,
      "y": 12,
      "z": 5,
      "name": "Rock_Sandstone_Red_Cobble"
    },
    {
      "x": -7,
      "y": 13,
      "z": 5,
      "name": "Rock_Sandstone_Red"
    },
    {
      "x": -7,
      "y": 14,
      "z": 5,
      "name": "Rock_Sandstone_Red"
    },
    {
      "x": -7,
      "y": 15,
      "z": 5,
      "name": "Rock_Sandstone_Red"
    },
    {
      "x": -7,
      "y": 16,
      "z": 5,
      "name": "Rock_Sandstone_Red"
    },
    {
      "x": -7,
      "y": 17,
      "z": 5,
      "name": "Rock_Sandstone_Red"
    },
    {
      "x": -7,
      "y": 18,
      "z": 5,
      "name": "Rock_Sandstone_Red"
    },
    {
      "x": -7,
      "y": 19,
      "z": 5,
      "name": "Rock_Sandstone_Red"
    },
    {
      "x": -7,
      "y": 20,
      "z": 5,
      "name": "Rock_Sandstone"
    },
    {
      "x": -7,
      "y": 21,
      "z": 5,
      "name": "Rock_Sandstone"
    },
    {
      "x": -7,
      "y": 22,
      "z": 5,
      "name": "Rock_Sandstone_Stalactite_Large"
    },
    {
      "x": -7,
      "y": 23,
      "z": 5,
      "name": "Rock_Sandstone_Stalactite_Large",
      "filler": 1024
    },
    {
      "x": -7,
      "y": 8,
      "z": 6,
      "name": "Rock_Sandstone_Red"
    },
    {
      "x": -7,
      "y": 9,
      "z": 6,
      "name": "Rock_Sandstone_Red"
    },
    {
      "x": -7,
      "y": 10,
      "z": 6,
      "name": "Rock_Sandstone_Red"
    },
    {
      "x": -7,
      "y": 11,
      "z": 6,
      "name": "Rock_Sandstone_Red"
    },
    {
      "x": -7,
      "y": 12,
      "z": 6,
      "name": "Rock_Sandstone_Red"
    },
    {
      "x": -7,
      "y": 13,
      "z": 6,
      "name": "Rock_Sandstone_Red"
    },
    {
      "x": -7,
      "y": 14,
      "z": 6,
      "name": "Rock_Sandstone_Red"
    },
    {
      "x": -7,
      "y": 15,
      "z": 6,
      "name": "Rock_Sandstone_Red_Cobble"
    },
    {
      "x": -7,
      "y": 16,
      "z": 6,
      "name": "Rock_Sandstone_Red"
    },
    {
      "x": -7,
      "y": 17,
      "z": 6,
      "name": "Rock_Sandstone_Red"
    },
    {
      "x": -7,
      "y": 18,
      "z": 6,
      "name": "Rock_Sandstone_Red"
    },
    {
      "x": -7,
      "y": 19,
      "z": 6,
      "name": "Rock_Sandstone"
    },
    {
      "x": -7,
      "y": 20,
      "z": 6,
      "name": "Rock_Sandstone"
    },
    {
      "x": -7,
      "y": 21,
      "z": 6,
      "name": "Rock_Sandstone"
    },
    {
      "x": -7,
      "y": 7,
      "z": 7,
      "name": "Rock_Sandstone_Red"
    },
    {
      "x": -7,
      "y": 8,
      "z": 7,
      "name": "Rock_Sandstone_Red_Cobble"
    },
    {
      "x": -7,
      "y": 9,
      "z": 7,
      "name": "Rock_Sandstone_Red"
    },
    {
      "x": -7,
      "y": 10,
      "z": 7,
      "name": "Rock_Sandstone_Red"
    },
    {
      "x": -7,
      "y": 11,
      "z": 7,
      "name": "Rock_Sandstone_Red"
    },
    {
      "x": -7,
      "y": 12,
      "z": 7,
      "name": "Rock_Sandstone_Red"
    },
    {
      "x": -7,
      "y": 13,
      "z": 7,
      "name": "Rock_Sandstone_Red"
    },
    {
      "x": -7,
      "y": 14,
      "z": 7,
      "name": "Rock_Sandstone_Red_Cobble"
    },
    {
      "x": -7,
      "y": 15,
      "z": 7,
      "name": "Rock_Sandstone_Red"
    },
    {
      "x": -7,
      "y": 16,
      "z": 7,
      "name": "Rock_Sandstone_Red"
    },
    {
      "x": -7,
      "y": 17,
      "z": 7,
      "name": "Rock_Sandstone_Red"
    },
    {
      "x": -7,
      "y": 18,
      "z": 7,
      "name": "Rock_Sandstone_Red"
    },
    {
      "x": -7,
      "y": 19,
      "z": 7,
      "name": "Rock_Sandstone"
    },
    {
      "x": -7,
      "y": 20,
      "z": 7,
      "name": "Rock_Sandstone"
    },
    {
      "x": -7,
      "y": 21,
      "z": 7,
      "name": "Soil_Sand_Red"
    },
    {
      "x": -7,
      "y": 22,
      "z": 7,
      "name": "Soil_Sand_Red"
    },
    {
      "x": -7,
      "y": 8,
      "z": 8,
      "name": "Rock_Sandstone_Red"
    },
    {
      "x": -7,
      "y": 9,
      "z": 8,
      "name": "Rock_Sandstone_Red"
    },
    {
      "x": -7,
      "y": 10,
      "z": 8,
      "name": "Rock_Sandstone_Red"
    },
    {
      "x": -7,
      "y": 11,
      "z": 8,
      "name": "Rock_Sandstone_Red"
    },
    {
      "x": -7,
      "y": 12,
      "z": 8,
      "name": "Rock_Sandstone_Red"
    },
    {
      "x": -7,
      "y": 13,
      "z": 8,
      "name": "Rock_Sandstone_Red"
    },
    {
      "x": -7,
      "y": 14,
      "z": 8,
      "name": "Rock_Sandstone_Red"
    },
    {
      "x": -7,
      "y": 15,
      "z": 8,
      "name": "Rock_Sandstone_Red"
    },
    {
      "x": -7,
      "y": 16,
      "z": 8,
      "name": "Rock_Sandstone_Red"
    },
    {
      "x": -7,
      "y": 17,
      "z": 8,
      "name": "Rock_Sandstone_Red"
    },
    {
      "x": -7,
      "y": 18,
      "z": 8,
      "name": "Rock_Sandstone"
    },
    {
      "x": -7,
      "y": 19,
      "z": 8,
      "name": "Rock_Sandstone"
    },
    {
      "x": -7,
      "y": 20,
      "z": 8,
      "name": "Rock_Sandstone"
    },
    {
      "x": -7,
      "y": 21,
      "z": 8,
      "name": "Soil_Sand_Red"
    },
    {
      "x": -7,
      "y": 22,
      "z": 8,
      "name": "Soil_Sand_Red"
    },
    {
      "x": -7,
      "y": 7,
      "z": 9,
      "name": "Rock_Sandstone_Red_Stalactite_Small",
      "rotation": 10
    },
    {
      "x": -7,
      "y": 8,
      "z": 9,
      "name": "Rock_Sandstone_Red"
    },
    {
      "x": -7,
      "y": 9,
      "z": 9,
      "name": "Rock_Sandstone_Red_Cobble"
    },
    {
      "x": -7,
      "y": 10,
      "z": 9,
      "name": "Rock_Sandstone_Red"
    },
    {
      "x": -7,
      "y": 11,
      "z": 9,
      "name": "Rock_Sandstone_Red_Cobble"
    },
    {
      "x": -7,
      "y": 12,
      "z": 9,
      "name": "Rock_Sandstone_Red"
    },
    {
      "x": -7,
      "y": 13,
      "z": 9,
      "name": "Rock_Sandstone_Red"
    },
    {
      "x": -7,
      "y": 14,
      "z": 9,
      "name": "Rock_Sandstone_Red"
    },
    {
      "x": -7,
      "y": 15,
      "z": 9,
      "name": "Rock_Sandstone_Red"
    },
    {
      "x": -7,
      "y": 16,
      "z": 9,
      "name": "Rock_Sandstone_Red"
    },
    {
      "x": -7,
      "y": 17,
      "z": 9,
      "name": "Rock_Sandstone_Red"
    },
    {
      "x": -7,
      "y": 18,
      "z": 9,
      "name": "Rock_Sandstone"
    },
    {
      "x": -7,
      "y": 19,
      "z": 9,
      "name": "Rock_Sandstone"
    },
    {
      "x": -7,
      "y": 20,
      "z": 9,
      "name": "Rock_Sandstone"
    },
    {
      "x": -7,
      "y": 21,
      "z": 9,
      "name": "Soil_Sand_Red"
    },
    {
      "x": -7,
      "y": 22,
      "z": 9,
      "name": "Soil_Gravel_Sand_Red"
    },
    {
      "x": -7,
      "y": 9,
      "z": 10,
      "name": "Rock_Sandstone_Red_Stalactite_Small",
      "rotation": 10
    },
    {
      "x": -7,
      "y": 10,
      "z": 10,
      "name": "Rock_Sandstone_Red"
    },
    {
      "x": -7,
      "y": 11,
      "z": 10,
      "name": "Rock_Sandstone_Red_Cobble"
    },
    {
      "x": -7,
      "y": 12,
      "z": 10,
      "name": "Rock_Sandstone_Red"
    },
    {
      "x": -7,
      "y": 13,
      "z": 10,
      "name": "Rock_Sandstone_Red"
    },
    {
      "x": -7,
      "y": 14,
      "z": 10,
      "name": "Rock_Sandstone_Red"
    },
    {
      "x": -7,
      "y": 15,
      "z": 10,
      "name": "Rock_Sandstone_Red_Cobble"
    },
    {
      "x": -7,
      "y": 16,
      "z": 10,
      "name": "Rock_Sandstone_Red"
    },
    {
      "x": -7,
      "y": 17,
      "z": 10,
      "name": "Rock_Sandstone_Red"
    },
    {
      "x": -7,
      "y": 18,
      "z": 10,
      "name": "Rock_Sandstone"
    },
    {
      "x": -7,
      "y": 19,
      "z": 10,
      "name": "Rock_Sandstone_Red"
    },
    {
      "x": -7,
      "y": 20,
      "z": 10,
      "name": "Rock_Sandstone"
    },
    {
      "x": -7,
      "y": 21,
      "z": 10,
      "name": "Soil_Sand_Red"
    },
    {
      "x": -7,
      "y": 22,
      "z": 10,
      "name": "Soil_Gravel_Sand_Red"
    },
    {
      "x": -7,
      "y": 13,
      "z": 11,
      "name": "Rock_Sandstone_Red"
    },
    {
      "x": -7,
      "y": 14,
      "z": 11,
      "name": "Rock_Sandstone_Red_Cobble"
    },
    {
      "x": -7,
      "y": 15,
      "z": 11,
      "name": "Rock_Sandstone_Red_Cobble"
    },
    {
      "x": -7,
      "y": 16,
      "z": 11,
      "name": "Rock_Sandstone_Red"
    },
    {
      "x": -7,
      "y": 17,
      "z": 11,
      "name": "Rock_Sandstone"
    },
    {
      "x": -7,
      "y": 18,
      "z": 11,
      "name": "Rock_Sandstone"
    },
    {
      "x": -7,
      "y": 19,
      "z": 11,
      "name": "Rock_Sandstone"
    },
    {
      "x": -7,
      "y": 20,
      "z": 11,
      "name": "Rock_Sandstone"
    },
    {
      "x": -7,
      "y": 21,
      "z": 11,
      "name": "Soil_Sand_Red"
    },
    {
      "x": -7,
      "y": 22,
      "z": 11,
      "name": "Soil_Sand_Red"
    },
    {
      "x": -7,
      "y": 17,
      "z": 12,
      "name": "Plant_Vine_Wall_Poisoned"
    },
    {
      "x": -7,
      "y": 18,
      "z": 12,
      "name": "Plant_Vine_Wall_Poisoned"
    },
    {
      "x": -7,
      "y": 19,
      "z": 12,
      "name": "Plant_Vine_Wall_Poisoned"
    },
    {
      "x": -7,
      "y": 20,
      "z": 12,
      "name": "Plant_Vine_Wall_Poisoned"
    },
    {
      "x": -6,
      "y": 21,
      "z": -9,
      "name": "Plant_Vine_Wall_Poisoned",
      "rotation": 2
    },
    {
      "x": -6,
      "y": 22,
      "z": -9,
      "name": "Plant_Vine_Wall_Poisoned",
      "rotation": 2
    },
    {
      "x": -6,
      "y": 23,
      "z": -9,
      "name": "Rock_Sandstone"
    },
    {
      "x": -6,
      "y": 24,
      "z": -9,
      "name": "Rock_Sandstone"
    },
    {
      "x": -6,
      "y": 25,
      "z": -9,
      "name": "Soil_Sand_Red"
    },
    {
      "x": -6,
      "y": 26,
      "z": -9,
      "name": "Soil_Sand_Red"
    },
    {
      "x": -6,
      "y": 27,
      "z": -9,
      "name": "Plant_Bramble_Dry_Sandthorn"
    },
    {
      "x": -6,
      "y": 15,
      "z": -8,
      "name": "Rock_Sandstone_Red"
    },
    {
      "x": -6,
      "y": 16,
      "z": -8,
      "name": "Rock_Sandstone_Red"
    },
    {
      "x": -6,
      "y": 17,
      "z": -8,
      "name": "Rock_Sandstone_Red"
    },
    {
      "x": -6,
      "y": 18,
      "z": -8,
      "name": "Rock_Sandstone_Red"
    },
    {
      "x": -6,
      "y": 19,
      "z": -8,
      "name": "Rock_Sandstone_Red"
    },
    {
      "x": -6,
      "y": 20,
      "z": -8,
      "name": "Rock_Sandstone_Red_Cobble"
    },
    {
      "x": -6,
      "y": 21,
      "z": -8,
      "name": "Rock_Sandstone_Red"
    },
    {
      "x": -6,
      "y": 22,
      "z": -8,
      "name": "Rock_Sandstone"
    },
    {
      "x": -6,
      "y": 23,
      "z": -8,
      "name": "Rock_Sandstone"
    },
    {
      "x": -6,
      "y": 24,
      "z": -8,
      "name": "Rock_Sandstone"
    },
    {
      "x": -6,
      "y": 25,
      "z": -8,
      "name": "Soil_Sand_Red"
    },
    {
      "x": -6,
      "y": 26,
      "z": -8,
      "name": "Soil_Sand_Red"
    },
    {
      "x": -6,
      "y": 12,
      "z": -7,
      "name": "Rock_Sandstone_Red"
    },
    {
      "x": -6,
      "y": 13,
      "z": -7,
      "name": "Rock_Sandstone_Red_Cobble"
    },
    {
      "x": -6,
      "y": 14,
      "z": -7,
      "name": "Rock_Sandstone_Red"
    },
    {
      "x": -6,
      "y": 15,
      "z": -7,
      "name": "Rock_Sandstone_Red_Cobble"
    },
    {
      "x": -6,
      "y": 16,
      "z": -7,
      "name": "Rock_Sandstone_Red_Cobble"
    },
    {
      "x": -6,
      "y": 17,
      "z": -7,
      "name": "Rock_Sandstone_Red_Cobble"
    },
    {
      "x": -6,
      "y": 18,
      "z": -7,
      "name": "Rock_Sandstone_Red"
    },
    {
      "x": -6,
      "y": 19,
      "z": -7,
      "name": "Rock_Sandstone_Red"
    },
    {
      "x": -6,
      "y": 20,
      "z": -7,
      "name": "Rock_Sandstone_Red"
    },
    {
      "x": -6,
      "y": 21,
      "z": -7,
      "name": "Rock_Sandstone_Red"
    },
    {
      "x": -6,
      "y": 22,
      "z": -7,
      "name": "Rock_Sandstone"
    },
    {
      "x": -6,
      "y": 23,
      "z": -7,
      "name": "Ore_Gold_Sandstone"
    },
    {
      "x": -6,
      "y": 24,
      "z": -7,
      "name": "Rock_Sandstone"
    },
    {
      "x": -6,
      "y": 25,
      "z": -7,
      "name": "Soil_Sand_Red"
    },
    {
      "x": -6,
      "y": 26,
      "z": -7,
      "name": "Soil_Sand_Red"
    },
    {
      "x": -6,
      "y": 6,
      "z": -6,
      "name": "Rock_Sandstone_Red_Stalactite_Large",
      "filler": 31744,
      "rotation": 8
    },
    {
      "x": -6,
      "y": 7,
      "z": -6,
      "name": "Rock_Sandstone_Red_Stalactite_Large",
      "rotation": 8
    },
    {
      "x": -6,
      "y": 8,
      "z": -6,
      "name": "Rock_Sandstone_Red"
    },
    {
      "x": -6,
      "y": 9,
      "z": -6,
      "name": "Rock_Sandstone_Red"
    },
    {
      "x": -6,
      "y": 10,
      "z": -6,
      "name": "Rock_Sandstone_Red"
    },
    {
      "x": -6,
      "y": 11,
      "z": -6,
      "name": "Rock_Sandstone_Red"
    },
    {
      "x": -6,
      "y": 12,
      "z": -6,
      "name": "Rock_Sandstone_Red"
    },
    {
      "x": -6,
      "y": 13,
      "z": -6,
      "name": "Rock_Sandstone_Red_Cobble"
    },
    {
      "x": -6,
      "y": 14,
      "z": -6,
      "name": "Rock_Sandstone_Red"
    },
    {
      "x": -6,
      "y": 15,
      "z": -6,
      "name": "Rock_Sandstone_Red"
    },
    {
      "x": -6,
      "y": 16,
      "z": -6,
      "name": "Rock_Sandstone_Red"
    },
    {
      "x": -6,
      "y": 17,
      "z": -6,
      "name": "Rock_Sandstone_Red"
    },
    {
      "x": -6,
      "y": 18,
      "z": -6,
      "name": "Rock_Sandstone_Red"
    },
    {
      "x": -6,
      "y": 19,
      "z": -6,
      "name": "Rock_Sandstone_Red"
    },
    {
      "x": -6,
      "y": 20,
      "z": -6,
      "name": "Rock_Sandstone_Red"
    },
    {
      "x": -6,
      "y": 21,
      "z": -6,
      "name": "Rock_Sandstone_Red"
    },
    {
      "x": -6,
      "y": 22,
      "z": -6,
      "name": "Rock_Sandstone"
    },
    {
      "x": -6,
      "y": 23,
      "z": -6,
      "name": "Rock_Sandstone"
    },
    {
      "x": -6,
      "y": 24,
      "z": -6,
      "name": "Rock_Sandstone"
    },
    {
      "x": -6,
      "y": 25,
      "z": -6,
      "name": "Soil_Sand_Red"
    },
    {
      "x": -6,
      "y": 26,
      "z": -6,
      "name": "Soil_Gravel_Sand_Red"
    },
    {
      "x": -6,
      "y": 10,
      "z": -5,
      "name": "Rock_Sandstone_Red"
    },
    {
      "x": -6,
      "y": 11,
      "z": -5,
      "name": "Rock_Sandstone_Red"
    },
    {
      "x": -6,
      "y": 12,
      "z": -5,
      "name": "Rock_Sandstone_Red_Cobble"
    },
    {
      "x": -6,
      "y": 13,
      "z": -5,
      "name": "Rock_Sandstone_Red"
    },
    {
      "x": -6,
      "y": 14,
      "z": -5,
      "name": "Rock_Sandstone_Red_Cobble"
    },
    {
      "x": -6,
      "y": 15,
      "z": -5,
      "name": "Rock_Sandstone_Red"
    },
    {
      "x": -6,
      "y": 16,
      "z": -5,
      "name": "Rock_Sandstone_Red"
    },
    {
      "x": -6,
      "y": 17,
      "z": -5,
      "name": "Rock_Sandstone_Red_Cobble"
    },
    {
      "x": -6,
      "y": 18,
      "z": -5,
      "name": "Rock_Sandstone_Red_Cobble"
    },
    {
      "x": -6,
      "y": 19,
      "z": -5,
      "name": "Rock_Sandstone_Red"
    },
    {
      "x": -6,
      "y": 20,
      "z": -5,
      "name": "Rock_Sandstone_Red"
    },
    {
      "x": -6,
      "y": 21,
      "z": -5,
      "name": "Rock_Sandstone_Red"
    },
    {
      "x": -6,
      "y": 22,
      "z": -5,
      "name": "Rock_Sandstone"
    },
    {
      "x": -6,
      "y": 23,
      "z": -5,
      "name": "Rock_Sandstone"
    },
    {
      "x": -6,
      "y": 24,
      "z": -5,
      "name": "Rock_Sandstone"
    },
    {
      "x": -6,
      "y": 25,
      "z": -5,
      "name": "Soil_Gravel_Sand_Red"
    },
    {
      "x": -6,
      "y": 8,
      "z": -4,
      "name": "Rock_Sandstone_Red_Stalactite_Large",
      "filler": 31744,
      "rotation": 8
    },
    {
      "x": -6,
      "y": 9,
      "z": -4,
      "name": "Rock_Sandstone_Red_Stalactite_Large",
      "rotation": 8
    },
    {
      "x": -6,
      "y": 10,
      "z": -4,
      "name": "Rock_Sandstone_Red"
    },
    {
      "x": -6,
      "y": 11,
      "z": -4,
      "name": "Rock_Sandstone_Red"
    },
    {
      "x": -6,
      "y": 12,
      "z": -4,
      "name": "Rock_Sandstone_Red"
    },
    {
      "x": -6,
      "y": 13,
      "z": -4,
      "name": "Rock_Sandstone_Red"
    },
    {
      "x": -6,
      "y": 14,
      "z": -4,
      "name": "Rock_Sandstone_Red"
    },
    {
      "x": -6,
      "y": 15,
      "z": -4,
      "name": "Rock_Sandstone_Red"
    },
    {
      "x": -6,
      "y": 16,
      "z": -4,
      "name": "Rock_Sandstone_Red_Cobble"
    },
    {
      "x": -6,
      "y": 20,
      "z": -4,
      "name": "Rock_Sandstone_Red"
    },
    {
      "x": -6,
      "y": 21,
      "z": -4,
      "name": "Rock_Sandstone_Red"
    },
    {
      "x": -6,
      "y": 22,
      "z": -4,
      "name": "Rock_Sandstone"
    },
    {
      "x": -6,
      "y": 23,
      "z": -4,
      "name": "Rock_Sandstone"
    },
    {
      "x": -6,
      "y": 24,
      "z": -4,
      "name": "Rock_Sandstone"
    },
    {
      "x": -6,
      "y": 25,
      "z": -4,
      "name": "Soil_Sand_Red"
    },
    {
      "x": -6,
      "y": 10,
      "z": -3,
      "name": "Rock_Sandstone_Red"
    },
    {
      "x": -6,
      "y": 11,
      "z": -3,
      "name": "Rock_Sandstone_Red"
    },
    {
      "x": -6,
      "y": 12,
      "z": -3,
      "name": "Rock_Sandstone_Red"
    },
    {
      "x": -6,
      "y": 13,
      "z": -3,
      "name": "Rock_Sandstone_Red"
    },
    {
      "x": -6,
      "y": 14,
      "z": -3,
      "name": "Rock_Sandstone_Red"
    },
    {
      "x": -6,
      "y": 15,
      "z": -3,
      "name": "Rock_Sandstone_Red_Cobble"
    },
    {
      "x": -6,
      "y": 16,
      "z": -3,
      "name": "Rock_Sandstone_Red"
    },
    {
      "x": -6,
      "y": 19,
      "z": -3,
      "name": "Rock_Sandstone_Red_Stalactite_Small",
      "rotation": 9
    },
    {
      "x": -6,
      "y": 20,
      "z": -3,
      "name": "Rock_Sandstone_Red_Cobble"
    },
    {
      "x": -6,
      "y": 21,
      "z": -3,
      "name": "Rock_Sandstone_Red"
    },
    {
      "x": -6,
      "y": 22,
      "z": -3,
      "name": "Rock_Sandstone"
    },
    {
      "x": -6,
      "y": 23,
      "z": -3,
      "name": "Soil_Sand_Red"
    },
    {
      "x": -6,
      "y": 24,
      "z": -3,
      "name": "Soil_Sand_Red"
    },
    {
      "x": -6,
      "y": 10,
      "z": -2,
      "name": "Rock_Sandstone_Red_Cobble"
    },
    {
      "x": -6,
      "y": 11,
      "z": -2,
      "name": "Rock_Sandstone_Red"
    },
    {
      "x": -6,
      "y": 12,
      "z": -2,
      "name": "Rock_Sandstone_Red"
    },
    {
      "x": -6,
      "y": 13,
      "z": -2,
      "name": "Rock_Sandstone_Red"
    },
    {
      "x": -6,
      "y": 14,
      "z": -2,
      "name": "Rock_Sandstone_Red"
    },
    {
      "x": -6,
      "y": 15,
      "z": -2,
      "name": "Rock_Sandstone_Red_Cobble"
    },
    {
      "x": -6,
      "y": 16,
      "z": -2,
      "name": "Rock_Sandstone_Red"
    },
    {
      "x": -6,
      "y": 20,
      "z": -2,
      "name": "Rock_Sandstone_Red"
    },
    {
      "x": -6,
      "y": 21,
      "z": -2,
      "name": "Rock_Sandstone_Red"
    },
    {
      "x": -6,
      "y": 22,
      "z": -2,
      "name": "Rock_Sandstone"
    },
    {
      "x": -6,
      "y": 23,
      "z": -2,
      "name": "Soil_Sand_Red"
    },
    {
      "x": -6,
      "y": 24,
      "z": -2,
      "name": "Soil_Sand_Red"
    },
    {
      "x": -6,
      "y": 9,
      "z": -1,
      "name": "Rock_Sandstone_Red"
    },
    {
      "x": -6,
      "y": 10,
      "z": -1,
      "name": "Rock_Sandstone_Red"
    },
    {
      "x": -6,
      "y": 11,
      "z": -1,
      "name": "Rock_Sandstone_Red"
    },
    {
      "x": -6,
      "y": 12,
      "z": -1,
      "name": "Rock_Sandstone_Red_Cobble"
    },
    {
      "x": -6,
      "y": 13,
      "z": -1,
      "name": "Rock_Sandstone_Red"
    },
    {
      "x": -6,
      "y": 14,
      "z": -1,
      "name": "Rock_Sandstone_Red"
    },
    {
      "x": -6,
      "y": 15,
      "z": -1,
      "name": "Rock_Sandstone_Red"
    },
    {
      "x": -6,
      "y": 16,
      "z": -1,
      "name": "Rock_Sandstone_Red"
    },
    {
      "x": -6,
      "y": 17,
      "z": -1,
      "name": "Rock_Sandstone_Red"
    },
    {
      "x": -6,
      "y": 18,
      "z": -1,
      "name": "Rock_Sandstone_Red"
    },
    {
      "x": -6,
      "y": 19,
      "z": -1,
      "name": "Rock_Sandstone_Red"
    },
    {
      "x": -6,
      "y": 20,
      "z": -1,
      "name": "Rock_Sandstone"
    },
    {
      "x": -6,
      "y": 21,
      "z": -1,
      "name": "Rock_Sandstone_Red"
    },
    {
      "x": -6,
      "y": 22,
      "z": -1,
      "name": "Rock_Sandstone"
    },
    {
      "x": -6,
      "y": 23,
      "z": -1,
      "name": "Soil_Sand_Red"
    },
    {
      "x": -6,
      "y": 24,
      "z": -1,
      "name": "Soil_Sand_Red"
    },
    {
      "x": -6,
      "y": 8,
      "z": 0,
      "name": "Rock_Sandstone_Red_Stalactite_Small",
      "rotation": 11
    },
    {
      "x": -6,
      "y": 9,
      "z": 0,
      "name": "Rock_Sandstone_Red"
    },
    {
      "x": -6,
      "y": 10,
      "z": 0,
      "name": "Rock_Sandstone_Red"
    },
    {
      "x": -6,
      "y": 11,
      "z": 0,
      "name": "Rock_Sandstone_Red"
    },
    {
      "x": -6,
      "y": 12,
      "z": 0,
      "name": "Rock_Sandstone_Red"
    },
    {
      "x": -6,
      "y": 13,
      "z": 0,
      "name": "Rock_Sandstone_Red"
    },
    {
      "x": -6,
      "y": 14,
      "z": 0,
      "name": "Rock_Sandstone_Red"
    },
    {
      "x": -6,
      "y": 15,
      "z": 0,
      "name": "Rock_Sandstone_Red"
    },
    {
      "x": -6,
      "y": 16,
      "z": 0,
      "name": "Rock_Sandstone_Red"
    },
    {
      "x": -6,
      "y": 17,
      "z": 0,
      "name": "Rock_Sandstone_Red"
    },
    {
      "x": -6,
      "y": 18,
      "z": 0,
      "name": "Rock_Sandstone_Red"
    },
    {
      "x": -6,
      "y": 19,
      "z": 0,
      "name": "Rock_Sandstone"
    },
    {
      "x": -6,
      "y": 20,
      "z": 0,
      "name": "Rock_Sandstone"
    },
    {
      "x": -6,
      "y": 21,
      "z": 0,
      "name": "Rock_Sandstone"
    },
    {
      "x": -6,
      "y": 22,
      "z": 0,
      "name": "Soil_Sand_Red"
    },
    {
      "x": -6,
      "y": 23,
      "z": 0,
      "name": "Soil_Sand_Red"
    },
    {
      "x": -6,
      "y": 7,
      "z": 1,
      "name": "Rock_Crystal_Red_Medium",
      "rotation": 6
    },
    {
      "x": -6,
      "y": 8,
      "z": 1,
      "name": "Rock_Crystal_Red_Medium",
      "rotation": 6
    },
    {
      "x": -6,
      "y": 9,
      "z": 1,
      "name": "Rock_Sandstone_Red"
    },
    {
      "x": -6,
      "y": 10,
      "z": 1,
      "name": "Rock_Sandstone_Red"
    },
    {
      "x": -6,
      "y": 11,
      "z": 1,
      "name": "Rock_Sandstone_Red"
    },
    {
      "x": -6,
      "y": 12,
      "z": 1,
      "name": "Rock_Sandstone_Red"
    },
    {
      "x": -6,
      "y": 13,
      "z": 1,
      "name": "Rock_Sandstone_Red"
    },
    {
      "x": -6,
      "y": 14,
      "z": 1,
      "name": "Rock_Sandstone_Red"
    },
    {
      "x": -6,
      "y": 15,
      "z": 1,
      "name": "Rock_Sandstone_Red"
    },
    {
      "x": -6,
      "y": 16,
      "z": 1,
      "name": "Rock_Sandstone_Red"
    },
    {
      "x": -6,
      "y": 17,
      "z": 1,
      "name": "Rock_Sandstone_Red"
    },
    {
      "x": -6,
      "y": 18,
      "z": 1,
      "name": "Rock_Sandstone_Red"
    },
    {
      "x": -6,
      "y": 19,
      "z": 1,
      "name": "Rock_Sandstone"
    },
    {
      "x": -6,
      "y": 20,
      "z": 1,
      "name": "Rock_Sandstone_Red"
    },
    {
      "x": -6,
      "y": 21,
      "z": 1,
      "name": "Rock_Sandstone"
    },
    {
      "x": -6,
      "y": 22,
      "z": 1,
      "name": "Soil_Sand_Red"
    },
    {
      "x": -6,
      "y": 23,
      "z": 1,
      "name": "Soil_Sand_Red"
    },
    {
      "x": -6,
      "y": 4,
      "z": 2,
      "name": "Rock_Crystal_Red_Medium",
      "rotation": 6
    },
    {
      "x": -6,
      "y": 5,
      "z": 2,
      "name": "Rock_Crystal_Red_Medium",
      "rotation": 6
    },
    {
      "x": -6,
      "y": 6,
      "z": 2,
      "name": "Rock_Crystal_Red_Medium",
      "rotation": 6
    },
    {
      "x": -6,
      "y": 7,
      "z": 2,
      "name": "Rock_Crystal_Red_Block"
    },
    {
      "x": -6,
      "y": 8,
      "z": 2,
      "name": "Rock_Crystal_Red_Block"
    },
    {
      "x": -6,
      "y": 9,
      "z": 2,
      "name": "Rock_Crystal_Red_Block"
    },
    {
      "x": -6,
      "y": 10,
      "z": 2,
      "name": "Rock_Crystal_Red_Block"
    },
    {
      "x": -6,
      "y": 11,
      "z": 2,
      "name": "Rock_Sandstone_Red"
    },
    {
      "x": -6,
      "y": 12,
      "z": 2,
      "name": "Rock_Sandstone_Red"
    },
    {
      "x": -6,
      "y": 13,
      "z": 2,
      "name": "Rock_Sandstone_Red"
    },
    {
      "x": -6,
      "y": 14,
      "z": 2,
      "name": "Rock_Sandstone_Red"
    },
    {
      "x": -6,
      "y": 15,
      "z": 2,
      "name": "Rock_Sandstone_Red"
    },
    {
      "x": -6,
      "y": 16,
      "z": 2,
      "name": "Rock_Sandstone_Red_Cobble"
    },
    {
      "x": -6,
      "y": 17,
      "z": 2,
      "name": "Rock_Sandstone_Red_Cobble"
    },
    {
      "x": -6,
      "y": 18,
      "z": 2,
      "name": "Rock_Sandstone_Red"
    },
    {
      "x": -6,
      "y": 19,
      "z": 2,
      "name": "Rock_Sandstone"
    },
    {
      "x": -6,
      "y": 20,
      "z": 2,
      "name": "Rock_Sandstone_Red"
    },
    {
      "x": -6,
      "y": 21,
      "z": 2,
      "name": "Rock_Sandstone"
    },
    {
      "x": -6,
      "y": 22,
      "z": 2,
      "name": "Soil_Sand_Red"
    },
    {
      "x": -6,
      "y": 23,
      "z": 2,
      "name": "Soil_Sand_Red"
    },
    {
      "x": -6,
      "y": 3,
      "z": 3,
      "name": "Rock_Crystal_Red_Large",
      "rotation": 8
    },
    {
      "x": -6,
      "y": 4,
      "z": 3,
      "name": "Rock_Crystal_Red_Block"
    },
    {
      "x": -6,
      "y": 5,
      "z": 3,
      "name": "Rock_Crystal_Red_Block"
    },
    {
      "x": -6,
      "y": 6,
      "z": 3,
      "name": "Rock_Crystal_Red_Block"
    },
    {
      "x": -6,
      "y": 7,
      "z": 3,
      "name": "Rock_Crystal_Red_Block"
    },
    {
      "x": -6,
      "y": 8,
      "z": 3,
      "name": "Rock_Crystal_Red_Block"
    },
    {
      "x": -6,
      "y": 9,
      "z": 3,
      "name": "Rock_Crystal_Red_Block"
    },
    {
      "x": -6,
      "y": 10,
      "z": 3,
      "name": "Rock_Crystal_Red_Block"
    },
    {
      "x": -6,
      "y": 11,
      "z": 3,
      "name": "Rock_Sandstone_Red"
    },
    {
      "x": -6,
      "y": 12,
      "z": 3,
      "name": "Rock_Sandstone_Red"
    },
    {
      "x": -6,
      "y": 13,
      "z": 3,
      "name": "Rock_Sandstone_Red"
    },
    {
      "x": -6,
      "y": 14,
      "z": 3,
      "name": "Rock_Sandstone_Red"
    },
    {
      "x": -6,
      "y": 15,
      "z": 3,
      "name": "Rock_Sandstone_Red"
    },
    {
      "x": -6,
      "y": 16,
      "z": 3,
      "name": "Rock_Sandstone_Red"
    },
    {
      "x": -6,
      "y": 17,
      "z": 3,
      "name": "Rock_Sandstone_Red"
    },
    {
      "x": -6,
      "y": 18,
      "z": 3,
      "name": "Rock_Sandstone_Red"
    },
    {
      "x": -6,
      "y": 19,
      "z": 3,
      "name": "Rock_Sandstone_Red"
    },
    {
      "x": -6,
      "y": 20,
      "z": 3,
      "name": "Rock_Sandstone"
    },
    {
      "x": -6,
      "y": 21,
      "z": 3,
      "name": "Rock_Sandstone"
    },
    {
      "x": -6,
      "y": 22,
      "z": 3,
      "name": "Rubble_Sandstone_Medium"
    },
    {
      "x": -6,
