{
  "version": 8,
  "blockIdVersion": 11,
  "anchorX": 0,
  "anchorY": 0,
  "anchorZ": 0,
  "blocks": [
    {
      "x": -20,
      "y": 21,
      "z": 17,
      "name": "Soil_Mud"
    },
    {
      "x": -20,
      "y": 23,
      "z": 19,
      "name": "Soil_Mud"
    },
    {
      "x": -19,
      "y": 21,
      "z": 11,
      "name": "Soil_Mud_Dry"
    },
    {
      "x": -19,
      "y": 21,
      "z": 12,
      "name": "Soil_Mud_Dry"
    },
    {
      "x": -19,
      "y": 22,
      "z": 12,
      "name": "Soil_Mud_Dry"
    },
    {
      "x": -19,
      "y": 23,
      "z": 12,
      "name": "Soil_Mud"
    },
    {
      "x": -19,
      "y": 20,
      "z": 13,
      "name": "Ore_Thorium_Mud"
    },
    {
      "x": -19,
      "y": 21,
      "z": 13,
      "name": "Soil_Mud"
    },
    {
      "x": -19,
      "y": 22,
      "z": 13,
      "name": "Soil_Mud"
    },
    {
      "x": -19,
      "y": 23,
      "z": 13,
      "name": "Soil_Mud"
    },
    {
      "x": -19,
      "y": 24,
      "z": 13,
      "name": "Soil_Mud"
    },
    {
      "x": -19,
      "y": 19,
      "z": 14,
      "name": "Soil_Mud_Dry"
    },
    {
      "x": -19,
      "y": 20,
      "z": 14,
      "name": "Soil_Mud"
    },
    {
      "x": -19,
      "y": 21,
      "z": 14,
      "name": "Soil_Mud_Dry"
    },
    {
      "x": -19,
      "y": 22,
      "z": 14,
      "name": "Soil_Mud_Dry"
    },
    {
      "x": -19,
      "y": 23,
      "z": 14,
      "name": "Soil_Mud_Dry"
    },
    {
      "x": -19,
      "y": 24,
      "z": 14,
      "name": "Soil_Mud_Dry"
    },
    {
      "x": -19,
      "y": 18,
      "z": 15,
      "name": "Soil_Mud_Dry"
    },
    {
      "x": -19,
      "y": 19,
      "z": 15,
      "name": "Soil_Mud"
    },
    {
      "x": -19,
      "y": 20,
      "z": 15,
      "name": "Soil_Mud_Dry"
    },
    {
      "x": -19,
      "y": 21,
      "z": 15,
      "name": "Soil_Mud"
    },
    {
      "x": -19,
      "y": 22,
      "z": 15,
      "name": "Soil_Mud"
    },
    {
      "x": -19,
      "y": 23,
      "z": 15,
      "name": "Soil_Mud_Dry"
    },
    {
      "x": -19,
      "y": 24,
      "z": 15,
      "name": "Soil_Mud"
    },
    {
      "x": -19,
      "y": 17,
      "z": 16,
      "name": "Soil_Mud"
    },
    {
      "x": -19,
      "y": 18,
      "z": 16,
      "name": "Soil_Mud_Dry"
    },
    {
      "x": -19,
      "y": 19,
      "z": 16,
      "name": "Soil_Mud_Dry"
    },
    {
      "x": -19,
      "y": 20,
      "z": 16,
      "name": "Soil_Mud_Dry"
    },
    {
      "x": -19,
      "y": 21,
      "z": 16,
      "name": "Soil_Mud"
    },
    {
      "x": -19,
      "y": 22,
      "z": 16,
      "name": "Soil_Mud"
    },
    {
      "x": -19,
      "y": 23,
      "z": 16,
      "name": "Soil_Mud_Dry"
    },
    {
      "x": -19,
      "y": 24,
      "z": 16,
      "name": "Soil_Mud"
    },
    {
      "x": -19,
      "y": 16,
      "z": 17,
      "name": "Soil_Mud"
    },
    {
      "x": -19,
      "y": 17,
      "z": 17,
      "name": "Soil_Mud_Dry"
    },
    {
      "x": -19,
      "y": 18,
      "z": 17,
      "name": "Soil_Mud"
    },
    {
      "x": -19,
      "y": 19,
      "z": 17,
      "name": "Soil_Mud"
    },
    {
      "x": -19,
      "y": 20,
      "z": 17,
      "name": "Soil_Mud"
    },
    {
      "x": -19,
      "y": 21,
      "z": 17,
      "name": "Soil_Mud"
    },
    {
      "x": -19,
      "y": 22,
      "z": 17,
      "name": "Soil_Mud"
    },
    {
      "x": -19,
      "y": 23,
      "z": 17,
      "name": "Soil_Mud"
    },
    {
      "x": -19,
      "y": 17,
      "z": 18,
      "name": "Soil_Mud"
    },
    {
      "x": -19,
      "y": 18,
      "z": 18,
      "name": "Soil_Mud_Dry"
    },
    {
      "x": -19,
      "y": 19,
      "z": 18,
      "name": "Soil_Mud_Dry"
    },
    {
      "x": -19,
      "y": 20,
      "z": 18,
      "name": "Soil_Mud"
    },
    {
      "x": -19,
      "y": 21,
      "z": 18,
      "name": "Soil_Mud"
    },
    {
      "x": -19,
      "y": 22,
      "z": 18,
      "name": "Soil_Mud"
    },
    {
      "x": -19,
      "y": 23,
      "z": 18,
      "name": "Soil_Mud_Dry"
    },
    {
      "x": -19,
      "y": 18,
      "z": 19,
      "name": "Soil_Mud_Dry"
    },
    {
      "x": -19,
      "y": 19,
      "z": 19,
      "name": "Soil_Mud"
    },
    {
      "x": -19,
      "y": 20,
      "z": 19,
      "name": "Soil_Mud"
    },
    {
      "x": -19,
      "y": 21,
      "z": 19,
      "name": "Soil_Mud"
    },
    {
      "x": -19,
      "y": 22,
      "z": 19,
      "name": "Soil_Mud"
    },
    {
      "x": -19,
      "y": 23,
      "z": 19,
      "name": "Soil_Mud"
    },
    {
      "x": -19,
      "y": 20,
      "z": 20,
      "name": "Soil_Mud"
    },
    {
      "x": -19,
      "y": 21,
      "z": 20,
      "name": "Soil_Mud"
    },
    {
      "x": -19,
      "y": 22,
      "z": 20,
      "name": "Soil_Mud"
    },
    {
      "x": -19,
      "y": 23,
      "z": 20,
      "name": "Soil_Mud"
    },
    {
      "x": -18,
      "y": 24,
      "z": -9,
      "name": "Plant_Crop_Mushroom_Shelve_Brown"
    },
    {
      "x": -18,
      "y": 25,
      "z": -9,
      "name": "Plant_Crop_Mushroom_Shelve_Brown"
    },
    {
      "x": -18,
      "y": 26,
      "z": -9,
      "name": "Plant_Crop_Mushroom_Shelve_Brown"
    },
    {
      "x": -18,
      "y": 29,
      "z": -9,
      "name": "Soil_Mud_Dry"
    },
    {
      "x": -18,
      "y": 29,
      "z": -8,
      "name": "Plant_Crop_Mushroom_Shelve_Brown"
    },
    {
      "x": -18,
      "y": 28,
      "z": 5,
      "name": "Soil_Mud_Dry"
    },
    {
      "x": -18,
      "y": 25,
      "z": 6,
      "name": "Soil_Mud_Dry"
    },
    {
      "x": -18,
      "y": 26,
      "z": 6,
      "name": "Soil_Mud"
    },
    {
      "x": -18,
      "y": 27,
      "z": 6,
      "name": "Soil_Mud_Dry"
    },
    {
      "x": -18,
      "y": 28,
      "z": 6,
      "name": "Soil_Mud"
    },
    {
      "x": -18,
      "y": 25,
      "z": 7,
      "name": "Soil_Mud_Dry"
    },
    {
      "x": -18,
      "y": 26,
      "z": 7,
      "name": "Soil_Mud"
    },
    {
      "x": -18,
      "y": 27,
      "z": 7,
      "name": "Soil_Mud"
    },
    {
      "x": -18,
      "y": 28,
      "z": 7,
      "name": "Soil_Mud"
    },
    {
      "x": -18,
      "y": 25,
      "z": 8,
      "name": "Soil_Mud"
    },
    {
      "x": -18,
      "y": 26,
      "z": 8,
      "name": "Soil_Mud"
    },
    {
      "x": -18,
      "y": 27,
      "z": 8,
      "name": "Soil_Mud"
    },
    {
      "x": -18,
      "y": 28,
      "z": 8,
      "name": "Soil_Mud_Dry"
    },
    {
      "x": -18,
      "y": 21,
      "z": 9,
      "name": "Soil_Mud"
    },
    {
      "x": -18,
      "y": 22,
      "z": 9,
      "name": "Soil_Mud"
    },
    {
      "x": -18,
      "y": 23,
      "z": 9,
      "name": "Soil_Mud"
    },
    {
      "x": -18,
      "y": 24,
      "z": 9,
      "name": "Soil_Mud"
    },
    {
      "x": -18,
      "y": 18,
      "z": 10,
      "name": "Plant_Moss_Cave_Red"
    },
    {
      "x": -18,
      "y": 19,
      "z": 10,
      "name": "Soil_Mud"
    },
    {
      "x": -18,
      "y": 20,
      "z": 10,
      "name": "Soil_Mud"
    },
    {
      "x": -18,
      "y": 21,
      "z": 10,
      "name": "Soil_Mud"
    },
    {
      "x": -18,
      "y": 22,
      "z": 10,
      "name": "Soil_Mud_Dry"
    },
    {
      "x": -18,
      "y": 23,
      "z": 10,
      "name": "Soil_Mud"
    },
    {
      "x": -18,
      "y": 24,
      "z": 10,
      "name": "Soil_Mud_Dry"
    },
    {
      "x": -18,
      "y": 18,
      "z": 11,
      "name": "Soil_Mud"
    },
    {
      "x": -18,
      "y": 19,
      "z": 11,
      "name": "Soil_Mud"
    },
    {
      "x": -18,
      "y": 20,
      "z": 11,
      "name": "Soil_Mud"
    },
    {
      "x": -18,
      "y": 21,
      "z": 11,
      "name": "Soil_Mud"
    },
    {
      "x": -18,
      "y": 22,
      "z": 11,
      "name": "Soil_Mud"
    },
    {
      "x": -18,
      "y": 23,
      "z": 11,
      "name": "Soil_Mud_Dry"
    },
    {
      "x": -18,
      "y": 24,
      "z": 11,
      "name": "Soil_Mud"
    },
    {
      "x": -18,
      "y": 25,
      "z": 11,
      "name": "Soil_Mud"
    },
    {
      "x": -18,
      "y": 26,
      "z": 11,
      "name": "Soil_Mud"
    },
    {
      "x": -18,
      "y": 16,
      "z": 12,
      "name": "Soil_Mud_Dry"
    },
    {
      "x": -18,
      "y": 17,
      "z": 12,
      "name": "Soil_Mud_Dry"
    },
    {
      "x": -18,
      "y": 18,
      "z": 12,
      "name": "Soil_Mud"
    },
    {
      "x": -18,
      "y": 19,
      "z": 12,
      "name": "Ore_Thorium_Mud_Cracked"
    },
    {
      "x": -18,
      "y": 20,
      "z": 12,
      "name": "Ore_Thorium_Mud_Cracked"
    },
    {
      "x": -18,
      "y": 21,
      "z": 12,
      "name": "Soil_Mud"
    },
    {
      "x": -18,
      "y": 22,
      "z": 12,
      "name": "Soil_Mud"
    },
    {
      "x": -18,
      "y": 23,
      "z": 12,
      "name": "Soil_Mud_Dry"
    },
    {
      "x": -18,
      "y": 24,
      "z": 12,
      "name": "Soil_Mud"
    },
    {
      "x": -18,
      "y": 25,
      "z": 12,
      "name": "Soil_Mud"
    },
    {
      "x": -18,
      "y": 26,
      "z": 12,
      "name": "Soil_Mud"
    },
    {
      "x": -18,
      "y": 18,
      "z": 13,
      "name": "Soil_Mud"
    },
    {
      "x": -18,
      "y": 19,
      "z": 13,
      "name": "Ore_Thorium_Mud_Cracked"
    },
    {
      "x": -18,
      "y": 20,
      "z": 13,
      "name": "Ore_Thorium_Mud_Cracked"
    },
    {
      "x": -18,
      "y": 21,
      "z": 13,
      "name": "Soil_Mud"
    },
    {
      "x": -18,
      "y": 22,
      "z": 13,
      "name": "Soil_Mud"
    },
    {
      "x": -18,
      "y": 23,
      "z": 13,
      "name": "Soil_Mud"
    },
    {
      "x": -18,
      "y": 24,
      "z": 13,
      "name": "Soil_Mud"
    },
    {
      "x": -18,
      "y": 25,
      "z": 13,
      "name": "Soil_Mud"
    },
    {
      "x": -18,
      "y": 26,
      "z": 13,
      "name": "Soil_Mud_Dry"
    },
    {
      "x": -18,
      "y": 27,
      "z": 13,
      "name": "Soil_Mud"
    },
    {
      "x": -18,
      "y": 17,
      "z": 14,
      "name": "Soil_Mud"
    },
    {
      "x": -18,
      "y": 18,
      "z": 14,
      "name": "Soil_Mud"
    },
    {
      "x": -18,
      "y": 19,
      "z": 14,
      "name": "Soil_Mud"
    },
    {
      "x": -18,
      "y": 20,
      "z": 14,
      "name": "Soil_Mud"
    },
    {
      "x": -18,
      "y": 21,
      "z": 14,
      "name": "Soil_Mud"
    },
    {
      "x": -18,
      "y": 22,
      "z": 14,
      "name": "Soil_Mud"
    },
    {
      "x": -18,
      "y": 23,
      "z": 14,
      "name": "Soil_Mud"
    },
    {
      "x": -18,
      "y": 24,
      "z": 14,
      "name": "Soil_Mud"
    },
    {
      "x": -18,
      "y": 25,
      "z": 14,
      "name": "Soil_Mud_Dry"
    },
    {
      "x": -18,
      "y": 26,
      "z": 14,
      "name": "Soil_Mud"
    },
    {
      "x": -18,
      "y": 27,
      "z": 14,
      "name": "Soil_Mud_Dry"
    },
    {
      "x": -18,
      "y": 16,
      "z": 15,
      "name": "Soil_Mud"
    },
    {
      "x": -18,
      "y": 17,
      "z": 15,
      "name": "Soil_Mud"
    },
    {
      "x": -18,
      "y": 18,
      "z": 15,
      "name": "Soil_Mud"
    },
    {
      "x": -18,
      "y": 19,
      "z": 15,
      "name": "Soil_Mud"
    },
    {
      "x": -18,
      "y": 20,
      "z": 15,
      "name": "Soil_Mud"
    },
    {
      "x": -18,
      "y": 21,
      "z": 15,
      "name": "Soil_Mud"
    },
    {
      "x": -18,
      "y": 22,
      "z": 15,
      "name": "Soil_Mud"
    },
    {
      "x": -18,
      "y": 23,
      "z": 15,
      "name": "Soil_Mud"
    },
    {
      "x": -18,
      "y": 24,
      "z": 15,
      "name": "Soil_Mud_Dry"
    },
    {
      "x": -18,
      "y": 25,
      "z": 15,
      "name": "Soil_Mud_Dry"
    },
    {
      "x": -18,
      "y": 26,
      "z": 15,
      "name": "Soil_Mud"
    },
    {
      "x": -18,
      "y": 27,
      "z": 15,
      "name": "Soil_Mud_Dry"
    },
    {
      "x": -18,
      "y": 28,
      "z": 15,
      "name": "Soil_Mud"
    },
    {
      "x": -18,
      "y": 15,
      "z": 16,
      "name": "Soil_Mud"
    },
    {
      "x": -18,
      "y": 16,
      "z": 16,
      "name": "Soil_Mud"
    },
    {
      "x": -18,
      "y": 17,
      "z": 16,
      "name": "Soil_Mud"
    },
    {
      "x": -18,
      "y": 18,
      "z": 16,
      "name": "Soil_Mud"
    },
    {
      "x": -18,
      "y": 19,
      "z": 16,
      "name": "Soil_Mud"
    },
    {
      "x": -18,
      "y": 20,
      "z": 16,
      "name": "Soil_Mud_Dry"
    },
    {
      "x": -18,
      "y": 21,
      "z": 16,
      "name": "Soil_Mud"
    },
    {
      "x": -18,
      "y": 22,
      "z": 16,
      "name": "Soil_Mud"
    },
    {
      "x": -18,
      "y": 23,
      "z": 16,
      "name": "Soil_Mud_Dry"
    },
    {
      "x": -18,
      "y": 24,
      "z": 16,
      "name": "Soil_Mud"
    },
    {
      "x": -18,
      "y": 25,
      "z": 16,
      "name": "Soil_Mud"
    },
    {
      "x": -18,
      "y": 26,
      "z": 16,
      "name": "Soil_Mud"
    },
    {
      "x": -18,
      "y": 27,
      "z": 16,
      "name": "Soil_Mud"
    },
    {
      "x": -18,
      "y": 28,
      "z": 16,
      "name": "Soil_Mud_Dry"
    },
    {
      "x": -18,
      "y": 15,
      "z": 17,
      "name": "Soil_Mud"
    },
    {
      "x": -18,
      "y": 16,
      "z": 17,
      "name": "Soil_Mud_Dry"
    },
    {
      "x": -18,
      "y": 17,
      "z": 17,
      "name": "Soil_Mud_Dry"
    },
    {
      "x": -18,
      "y": 18,
      "z": 17,
      "name": "Soil_Mud"
    },
    {
      "x": -18,
      "y": 19,
      "z": 17,
      "name": "Soil_Mud"
    },
    {
      "x": -18,
      "y": 20,
      "z": 17,
      "name": "Soil_Mud"
    },
    {
      "x": -18,
      "y": 21,
      "z": 17,
      "name": "Soil_Mud"
    },
    {
      "x": -18,
      "y": 22,
      "z": 17,
      "name": "Soil_Mud"
    },
    {
      "x": -18,
      "y": 23,
      "z": 17,
      "name": "Soil_Mud_Dry"
    },
    {
      "x": -18,
      "y": 24,
      "z": 17,
      "name": "Soil_Mud"
    },
    {
      "x": -18,
      "y": 25,
      "z": 17,
      "name": "Soil_Mud"
    },
    {
      "x": -18,
      "y": 27,
      "z": 17,
      "name": "Soil_Mud_Dry"
    },
    {
      "x": -18,
      "y": 28,
      "z": 17,
      "name": "Soil_Mud"
    },
    {
      "x": -18,
      "y": 29,
      "z": 17,
      "name": "Soil_Mud_Dry"
    },
    {
      "x": -18,
      "y": 15,
      "z": 18,
      "name": "Soil_Mud_Dry"
    },
    {
      "x": -18,
      "y": 16,
      "z": 18,
      "name": "Soil_Mud_Dry"
    },
    {
      "x": -18,
      "y": 17,
      "z": 18,
      "name": "Soil_Mud"
    },
    {
      "x": -18,
      "y": 18,
      "z": 18,
      "name": "Soil_Mud"
    },
    {
      "x": -18,
      "y": 19,
      "z": 18,
      "name": "Soil_Mud_Dry"
    },
    {
      "x": -18,
      "y": 20,
      "z": 18,
      "name": "Soil_Mud"
    },
    {
      "x": -18,
      "y": 21,
      "z": 18,
      "name": "Soil_Mud"
    },
    {
      "x": -18,
      "y": 22,
      "z": 18,
      "name": "Soil_Mud"
    },
    {
      "x": -18,
      "y": 23,
      "z": 18,
      "name": "Soil_Mud"
    },
    {
      "x": -18,
      "y": 27,
      "z": 18,
      "name": "Soil_Mud"
    },
    {
      "x": -18,
      "y": 28,
      "z": 18,
      "name": "Soil_Mud"
    },
    {
      "x": -18,
      "y": 29,
      "z": 18,
      "name": "Soil_Mud"
    },
    {
      "x": -18,
      "y": 30,
      "z": 18,
      "name": "Soil_Mud_Dry"
    },
    {
      "x": -18,
      "y": 16,
      "z": 19,
      "name": "Soil_Mud_Dry"
    },
    {
      "x": -18,
      "y": 17,
      "z": 19,
      "name": "Soil_Mud"
    },
    {
      "x": -18,
      "y": 18,
      "z": 19,
      "name": "Soil_Mud"
    },
    {
      "x": -18,
      "y": 19,
      "z": 19,
      "name": "Soil_Mud"
    },
    {
      "x": -18,
      "y": 20,
      "z": 19,
      "name": "Soil_Mud"
    },
    {
      "x": -18,
      "y": 21,
      "z": 19,
      "name": "Soil_Mud"
    },
    {
      "x": -18,
      "y": 22,
      "z": 19,
      "name": "Soil_Mud"
    },
    {
      "x": -18,
      "y": 23,
      "z": 19,
      "name": "Soil_Mud"
    },
    {
      "x": -18,
      "y": 17,
      "z": 20,
      "name": "Soil_Mud"
    },
    {
      "x": -18,
      "y": 18,
      "z": 20,
      "name": "Soil_Mud"
    },
    {
      "x": -18,
      "y": 19,
      "z": 20,
      "name": "Soil_Mud"
    },
    {
      "x": -18,
      "y": 20,
      "z": 20,
      "name": "Soil_Mud"
    },
    {
      "x": -18,
      "y": 21,
      "z": 20,
      "name": "Soil_Mud"
    },
    {
      "x": -18,
      "y": 22,
      "z": 20,
      "name": "Soil_Mud"
    },
    {
      "x": -18,
      "y": 23,
      "z": 20,
      "name": "Soil_Mud"
    },
    {
      "x": -18,
      "y": 20,
      "z": 21,
      "name": "Soil_Mud"
    },
    {
      "x": -18,
      "y": 21,
      "z": 21,
      "name": "Soil_Mud"
    },
    {
      "x": -18,
      "y": 22,
      "z": 21,
      "name": "Soil_Mud"
    },
    {
      "x": -18,
      "y": 23,
      "z": 21,
      "name": "Soil_Mud"
    },
    {
      "x": -17,
      "y": 28,
      "z": -16,
      "name": "Soil_Mud_Dry"
    },
    {
      "x": -17,
      "y": 25,
      "z": -15,
      "name": "Soil_Mud"
    },
    {
      "x": -17,
      "y": 26,
      "z": -15,
      "name": "Soil_Mud"
    },
    {
      "x": -17,
      "y": 27,
      "z": -15,
      "name": "Soil_Mud"
    },
    {
      "x": -17,
      "y": 28,
      "z": -15,
      "name": "Soil_Mud"
    },
    {
      "x": -17,
      "y": 25,
      "z": -14,
      "name": "Soil_Mud_Dry"
    },
    {
      "x": -17,
      "y": 26,
      "z": -14,
      "name": "Soil_Mud"
    },
    {
      "x": -17,
      "y": 27,
      "z": -14,
      "name": "Soil_Mud_Dry"
    },
    {
      "x": -17,
      "y": 28,
      "z": -14,
      "name": "Soil_Mud"
    },
    {
      "x": -17,
      "y": 29,
      "z": -14,
      "name": "Plant_Crop_Mushroom_Glowing_Violet"
    },
    {
      "x": -17,
      "y": 25,
      "z": -13,
      "name": "Soil_Mud"
    },
    {
      "x": -17,
      "y": 26,
      "z": -13,
      "name": "Soil_Mud"
    },
    {
      "x": -17,
      "y": 27,
      "z": -13,
      "name": "Soil_Mud_Dry"
    },
    {
      "x": -17,
      "y": 27,
      "z": -12,
      "name": "Soil_Mud"
    },
    {
      "x": -17,
      "y": 28,
      "z": -12,
      "name": "Soil_Mud_Dry"
    },
    {
      "x": -17,
      "y": 29,
      "z": -12,
      "name": "Soil_Mud_Dry"
    },
    {
      "x": -17,
      "y": 26,
      "z": -11,
      "name": "Soil_Mud"
    },
    {
      "x": -17,
      "y": 27,
      "z": -11,
      "name": "Soil_Mud"
    },
    {
      "x": -17,
      "y": 28,
      "z": -11,
      "name": "Soil_Mud_Dry"
    },
    {
      "x": -17,
      "y": 29,
      "z": -11,
      "name": "Soil_Mud"
    },
    {
      "x": -17,
      "y": 25,
      "z": -10,
      "name": "Soil_Mud_Dry"
    },
    {
      "x": -17,
      "y": 26,
      "z": -10,
      "name": "Soil_Mud"
    },
    {
      "x": -17,
      "y": 27,
      "z": -10,
      "name": "Soil_Mud"
    },
    {
      "x": -17,
      "y": 28,
      "z": -10,
      "name": "Soil_Mud"
    },
    {
      "x": -17,
      "y": 29,
      "z": -10,
      "name": "Soil_Mud_Dry"
    },
    {
      "x": -17,
      "y": 30,
      "z": -10,
      "name": "Soil_Mud"
    },
    {
      "x": -17,
      "y": 24,
      "z": -9,
      "name": "Soil_Mud_Dry"
    },
    {
      "x": -17,
      "y": 25,
      "z": -9,
      "name": "Soil_Mud"
    },
    {
      "x": -17,
      "y": 26,
      "z": -9,
      "name": "Soil_Mud"
    },
    {
      "x": -17,
      "y": 27,
      "z": -9,
      "name": "Soil_Mud_Dry"
    },
    {
      "x": -17,
      "y": 28,
      "z": -9,
      "name": "Soil_Mud_Dry"
    },
    {
      "x": -17,
      "y": 29,
      "z": -9,
      "name": "Soil_Mud"
    },
    {
      "x": -17,
      "y": 30,
      "z": -9,
      "name": "Soil_Mud_Dry"
    },
    {
      "x": -17,
      "y": 31,
      "z": -9,
      "name": "Plant_Flower_Bushy_Purple"
    },
    {
      "x": -17,
      "y": 25,
      "z": -8,
      "name": "Soil_Mud_Dry"
    },
    {
      "x": -17,
      "y": 26,
      "z": -8,
      "name": "Soil_Mud"
    },
    {
      "x": -17,
      "y": 27,
      "z": -8,
      "name": "Soil_Mud_Dry"
    },
    {
      "x": -17,
      "y": 28,
      "z": -8,
      "name": "Soil_Mud"
    },
    {
      "x": -17,
      "y": 29,
      "z": -8,
      "name": "Soil_Mud"
    },
    {
      "x": -17,
      "y": 30,
      "z": -8,
      "name": "Soil_Mud"
    },
    {
      "x": -17,
      "y": 31,
      "z": -8,
      "name": "Plant_Crop_Mushroom_Glowing_Purple"
    },
    {
      "x": -17,
      "y": 26,
      "z": -7,
      "name": "Soil_Mud"
    },
    {
      "x": -17,
      "y": 27,
      "z": -7,
      "name": "Soil_Mud"
    },
    {
      "x": -17,
      "y": 28,
      "z": -7,
      "name": "Soil_Mud"
    },
    {
      "x": -17,
      "y": 29,
      "z": -7,
      "name": "Soil_Mud"
    },
    {
      "x": -17,
      "y": 30,
      "z": -7,
      "name": "Soil_Mud"
    },
    {
      "x": -17,
      "y": 31,
      "z": -7,
      "name": "Plant_Moss_Rug_Pink"
    },
    {
      "x": -17,
      "y": 28,
      "z": -6,
      "name": "Soil_Mud_Dry"
    },
    {
      "x": -17,
      "y": 29,
      "z": -6,
      "name": "Soil_Mud_Dry"
    },
    {
      "x": -17,
      "y": 28,
      "z": -5,
      "name": "Plant_Crop_Mushroom_Shelve_Brown"
    },
    {
      "x": -17,
      "y": 25,
      "z": 4,
      "name": "Soil_Mud"
    },
    {
      "x": -17,
      "y": 26,
      "z": 4,
      "name": "Soil_Mud"
    },
    {
      "x": -17,
      "y": 27,
      "z": 4,
      "name": "Soil_Mud_Dry"
    },
    {
      "x": -17,
      "y": 28,
      "z": 4,
      "name": "Soil_Mud"
    },
    {
      "x": -17,
      "y": 23,
      "z": 5,
      "name": "Soil_Mud_Dry"
    },
    {
      "x": -17,
      "y": 24,
      "z": 5,
      "name": "Soil_Mud_Dry"
    },
    {
      "x": -17,
      "y": 25,
      "z": 5,
      "name": "Soil_Mud"
    },
    {
      "x": -17,
      "y": 26,
      "z": 5,
      "name": "Soil_Mud_Dry"
    },
    {
      "x": -17,
      "y": 27,
      "z": 5,
      "name": "Soil_Mud"
    },
    {
      "x": -17,
      "y": 28,
      "z": 5,
      "name": "Soil_Mud"
    },
    {
      "x": -17,
      "y": 29,
      "z": 5,
      "name": "Plant_Flower_Bushy_Purple"
    },
    {
      "x": -17,
      "y": 22,
      "z": 6,
      "name": "Soil_Mud"
    },
    {
      "x": -17,
      "y": 23,
      "z": 6,
      "name": "Soil_Mud_Dry"
    },
    {
      "x": -17,
      "y": 24,
      "z": 6,
      "name": "Soil_Mud_Dry"
    },
    {
      "x": -17,
      "y": 25,
      "z": 6,
      "name": "Soil_Mud_Dry"
    },
    {
      "x": -17,
      "y": 26,
      "z": 6,
      "name": "Soil_Mud"
    },
    {
      "x": -17,
      "y": 27,
      "z": 6,
      "name": "Soil_Mud_Dry"
    },
    {
      "x": -17,
      "y": 28,
      "z": 6,
      "name": "Soil_Mud"
    },
    {
      "x": -17,
      "y": 29,
      "z": 6,
      "name": "Plant_Flower_Bushy_Violet"
    },
    {
      "x": -17,
      "y": 20,
      "z": 7,
      "name": "Plant_Moss_Cave_Red"
    },
    {
      "x": -17,
      "y": 21,
      "z": 7,
      "name": "Soil_Mud"
    },
    {
      "x": -17,
      "y": 22,
      "z": 7,
      "name": "Soil_Mud"
    },
    {
      "x": -17,
      "y": 23,
      "z": 7,
      "name": "Soil_Mud"
    },
    {
      "x": -17,
      "y": 24,
      "z": 7,
      "name": "Soil_Mud"
    },
    {
      "x": -17,
      "y": 25,
      "z": 7,
      "name": "Soil_Mud"
    },
    {
      "x": -17,
      "y": 26,
      "z": 7,
      "name": "Soil_Mud"
    },
    {
      "x": -17,
      "y": 27,
      "z": 7,
      "name": "Soil_Mud_Dry"
    },
    {
      "x": -17,
      "y": 28,
      "z": 7,
      "name": "Soil_Mud"
    },
    {
      "x": -17,
      "y": 21,
      "z": 8,
      "name": "Soil_Mud_Dry"
    },
    {
      "x": -17,
      "y": 22,
      "z": 8,
      "name": "Soil_Mud"
    },
    {
      "x": -17,
      "y": 23,
      "z": 8,
      "name": "Soil_Mud"
    },
    {
      "x": -17,
      "y": 24,
      "z": 8,
      "name": "Soil_Mud"
    },
    {
      "x": -17,
      "y": 25,
      "z": 8,
      "name": "Soil_Mud"
    },
    {
      "x": -17,
      "y": 26,
      "z": 8,
      "name": "Soil_Mud"
    },
    {
      "x": -17,
      "y": 27,
      "z": 8,
      "name": "Soil_Mud"
    },
    {
      "x": -17,
      "y": 28,
      "z": 8,
      "name": "Soil_Mud"
    },
    {
      "x": -17,
      "y": 17,
      "z": 9,
      "name": "Soil_Mud"
    },
    {
      "x": -17,
      "y": 18,
      "z": 9,
      "name": "Soil_Mud"
    },
    {
      "x": -17,
      "y": 19,
      "z": 9,
      "name": "Soil_Mud"
    },
    {
      "x": -17,
      "y": 20,
      "z": 9,
      "name": "Soil_Mud_Dry"
    },
    {
      "x": -17,
      "y": 21,
      "z": 9,
      "name": "Soil_Mud"
    },
    {
      "x": -17,
      "y": 22,
      "z": 9,
      "name": "Soil_Mud"
    },
    {
      "x": -17,
      "y": 23,
      "z": 9,
      "name": "Soil_Mud_Dry"
    },
    {
      "x": -17,
      "y": 24,
      "z": 9,
      "name": "Soil_Mud"
    },
    {
      "x": -17,
      "y": 25,
      "z": 9,
      "name": "Soil_Mud"
    },
    {
      "x": -17,
      "y": 26,
      "z": 9,
      "name": "Soil_Mud"
    },
    {
      "x": -17,
      "y": 27,
      "z": 9,
      "name": "Soil_Mud_Dry"
    },
    {
      "x": -17,
      "y": 17,
      "z": 10,
      "name": "Soil_Mud"
    },
    {
      "x": -17,
      "y": 18,
      "z": 10,
      "name": "Soil_Mud"
    },
    {
      "x": -17,
      "y": 19,
      "z": 10,
      "name": "Soil_Mud"
    },
    {
      "x": -17,
      "y": 20,
      "z": 10,
      "name": "Soil_Mud"
    },
    {
      "x": -17,
      "y": 21,
      "z": 10,
      "name": "Soil_Mud"
    },
    {
      "x": -17,
      "y": 22,
      "z": 10,
      "name": "Soil_Mud"
    },
    {
      "x": -17,
      "y": 23,
      "z": 10,
      "name": "Soil_Mud_Dry"
    },
    {
      "x": -17,
      "y": 24,
      "z": 10,
      "name": "Soil_Mud"
    },
    {
      "x": -17,
      "y": 25,
      "z": 10,
      "name": "Soil_Mud_Dry"
    },
    {
      "x": -17,
      "y": 26,
      "z": 10,
      "name": "Soil_Mud"
    },
    {
      "x": -17,
      "y": 27,
      "z": 10,
      "name": "Soil_Mud_Dry"
    },
    {
      "x": -17,
      "y": 15,
      "z": 11,
      "name": "Soil_Mud_Dry"
    },
    {
      "x": -17,
      "y": 16,
      "z": 11,
      "name": "Soil_Mud"
    },
    {
      "x": -17,
      "y": 17,
      "z": 11,
      "name": "Soil_Mud_Dry"
    },
    {
      "x": -17,
      "y": 18,
      "z": 11,
      "name": "Soil_Mud_Dry"
    },
    {
      "x": -17,
      "y": 19,
      "z": 11,
      "name": "Soil_Mud"
    },
    {
      "x": -17,
      "y": 20,
      "z": 11,
      "name": "Soil_Mud"
    },
    {
      "x": -17,
      "y": 21,
      "z": 11,
      "name": "Soil_Mud_Dry"
    },
    {
      "x": -17,
      "y": 22,
      "z": 11,
      "name": "Soil_Mud"
    },
    {
      "x": -17,
      "y": 23,
      "z": 11,
      "name": "Soil_Mud"
    },
    {
      "x": -17,
      "y": 24,
      "z": 11,
      "name": "Soil_Mud_Dry"
    },
    {
      "x": -17,
      "y": 25,
      "z": 11,
      "name": "Soil_Mud"
    },
    {
      "x": -17,
      "y": 26,
      "z": 11,
      "name": "Soil_Mud"
    },
    {
      "x": -17,
      "y": 27,
      "z": 11,
      "name": "Soil_Mud_Dry"
    },
    {
      "x": -17,
      "y": 28,
      "z": 11,
      "name": "Soil_Mud"
    },
    {
      "x": -17,
      "y": 16,
      "z": 12,
      "name": "Soil_Mud_Dry"
    },
    {
      "x": -17,
      "y": 17,
      "z": 12,
      "name": "Soil_Mud"
    },
    {
      "x": -17,
      "y": 18,
      "z": 12,
      "name": "Soil_Mud"
    },
    {
      "x": -17,
      "y": 19,
      "z": 12,
      "name": "Ore_Thorium_Mud"
    },
    {
      "x": -17,
      "y": 20,
      "z": 12,
      "name": "Soil_Mud_Dry"
    },
    {
      "x": -17,
      "y": 21,
      "z": 12,
      "name": "Soil_Mud"
    },
    {
      "x": -17,
      "y": 22,
      "z": 12,
      "name": "Soil_Mud"
    },
    {
      "x": -17,
      "y": 23,
      "z": 12,
      "name": "Soil_Mud"
    },
    {
      "x": -17,
      "y": 24,
      "z": 12,
      "name": "Soil_Mud"
    },
    {
      "x": -17,
      "y": 25,
      "z": 12,
      "name": "Soil_Mud"
    },
    {
      "x": -17,
      "y": 26,
      "z": 12,
      "name": "Soil_Mud"
    },
    {
      "x": -17,
      "y": 27,
      "z": 12,
      "name": "Soil_Mud"
    },
    {
      "x": -17,
      "y": 28,
      "z": 12,
      "name": "Soil_Mud"
    },
    {
      "x": -17,
      "y": 29,
      "z": 12,
      "name": "Soil_Mud_Dry"
    },
    {
      "x": -17,
      "y": 16,
      "z": 13,
      "name": "Soil_Mud"
    },
    {
      "x": -17,
      "y": 17,
      "z": 13,
      "name": "Soil_Mud"
    },
    {
      "x": -17,
      "y": 18,
      "z": 13,
      "name": "Soil_Mud"
    },
    {
      "x": -17,
      "y": 19,
      "z": 13,
      "name": "Ore_Thorium_Mud_Cracked"
    },
    {
      "x": -17,
      "y": 20,
      "z": 13,
      "name": "Ore_Thorium_Mud_Cracked"
    },
    {
      "x": -17,
      "y": 21,
      "z": 13,
      "name": "Soil_Mud"
    },
    {
      "x": -17,
      "y": 22,
      "z": 13,
      "name": "Soil_Mud"
    },
    {
      "x": -17,
      "y": 23,
      "z": 13,
      "name": "Soil_Mud"
    },
    {
      "x": -17,
      "y": 24,
      "z": 13,
      "name": "Soil_Mud_Dry"
    },
    {
      "x": -17,
      "y": 25,
      "z": 13,
      "name": "Soil_Mud_Dry"
    },
    {
      "x": -17,
      "y": 26,
      "z": 13,
      "name": "Soil_Mud"
    },
    {
      "x": -17,
      "y": 27,
      "z": 13,
      "name": "Soil_Mud"
    },
    {
      "x": -17,
      "y": 28,
      "z": 13,
      "name": "Soil_Mud"
    },
    {
      "x": -17,
      "y": 29,
      "z": 13,
      "name": "Soil_Mud"
    },
    {
      "x": -17,
      "y": 16,
      "z": 14,
      "name": "Soil_Mud"
    },
    {
      "x": -17,
      "y": 17,
      "z": 14,
      "name": "Soil_Mud"
    },
    {
      "x": -17,
      "y": 18,
      "z": 14,
      "name": "Soil_Mud_Dry"
    },
    {
      "x": -17,
      "y": 19,
      "z": 14,
      "name": "Soil_Mud"
    },
    {
      "x": -17,
      "y": 20,
      "z": 14,
      "name": "Soil_Mud"
    },
    {
      "x": -17,
      "y": 21,
      "z": 14,
      "name": "Soil_Mud_Dry"
    },
    {
      "x": -17,
      "y": 22,
      "z": 14,
      "name": "Soil_Mud_Dry"
    },
    {
      "x": -17,
      "y": 23,
      "z": 14,
      "name": "Soil_Mud_Dry"
    },
    {
      "x": -17,
      "y": 24,
      "z": 14,
      "name": "Soil_Mud"
    },
    {
      "x": -17,
      "y": 25,
      "z": 14,
      "name": "Soil_Mud_Dry"
    },
    {
      "x": -17,
      "y": 26,
      "z": 14,
      "name": "Soil_Mud"
    },
    {
      "x": -17,
      "y": 27,
      "z": 14,
      "name": "Soil_Mud"
    },
    {
      "x": -17,
      "y": 28,
      "z": 14,
      "name": "Soil_Mud"
    },
    {
      "x": -17,
      "y": 29,
      "z": 14,
      "name": "Soil_Mud_Dry"
    },
    {
      "x": -17,
      "y": 30,
      "z": 14,
      "name": "Soil_Mud"
    },
    {
      "x": -17,
      "y": 14,
      "z": 15,
      "name": "Soil_Mud_Dry"
    },
    {
      "x": -17,
      "y": 15,
      "z": 15,
      "name": "Soil_Mud"
    },
    {
      "x": -17,
      "y": 16,
      "z": 15,
      "name": "Soil_Mud"
    },
    {
      "x": -17,
      "y": 17,
      "z": 15,
      "name": "Soil_Mud"
    },
    {
      "x": -17,
      "y": 18,
      "z": 15,
      "name": "Soil_Mud"
    },
    {
      "x": -17,
      "y": 19,
      "z": 15,
      "name": "Soil_Mud"
    },
    {
      "x": -17,
      "y": 20,
      "z": 15,
      "name": "Soil_Mud"
    },
    {
      "x": -17,
      "y": 21,
      "z": 15,
      "name": "Soil_Mud_Dry"
    },
    {
      "x": -17,
      "y": 22,
      "z": 15,
      "name": "Soil_Mud"
    },
    {
      "x": -17,
      "y": 23,
      "z": 15,
      "name": "Soil_Mud_Dry"
    },
    {
      "x": -17,
      "y": 24,
      "z": 15,
      "name": "Soil_Mud_Dry"
    },
    {
      "x": -17,
      "y": 25,
      "z": 15,
      "name": "Soil_Mud_Dry"
    },
    {
      "x": -17,
      "y": 26,
      "z": 15,
      "name": "Soil_Mud"
    },
    {
      "x": -17,
      "y": 27,
      "z": 15,
      "name": "Soil_Mud"
    },
    {
      "x": -17,
      "y": 28,
      "z": 15,
      "name": "Soil_Mud_Dry"
    },
    {
      "x": -17,
      "y": 29,
      "z": 15,
      "name": "Soil_Mud_Dry"
    },
    {
      "x": -17,
      "y": 30,
      "z": 15,
      "name": "Soil_Mud"
    },
    {
      "x": -17,
      "y": 14,
      "z": 16,
      "name": "Soil_Mud_Dry"
    },
    {
      "x": -17,
      "y": 15,
      "z": 16,
      "name": "Soil_Mud"
    },
    {
      "x": -17,
      "y": 16,
      "z": 16,
      "name": "Soil_Mud"
    },
    {
      "x": -17,
      "y": 17,
      "z": 16,
      "name": "Soil_Mud"
    },
    {
      "x": -17,
      "y": 18,
      "z": 16,
      "name": "Soil_Mud"
    },
    {
      "x": -17,
      "y": 19,
      "z": 16,
      "name": "Soil_Mud"
    },
    {
      "x": -17,
      "y": 20,
      "z": 16,
      "name": "Soil_Mud"
    },
    {
      "x": -17,
      "y": 21,
      "z": 16,
      "name": "Soil_Mud"
    },
    {
      "x": -17,
      "y": 22,
      "z": 16,
      "name": "Soil_Mud"
    },
    {
      "x": -17,
      "y": 23,
      "z": 16,
      "name": "Soil_Mud"
    },
    {
      "x": -17,
      "y": 24,
      "z": 16,
      "name": "Soil_Mud"
    },
    {
      "x": -17,
      "y": 25,
      "z": 16,
      "name": "Soil_Mud"
    },
    {
      "x": -17,
      "y": 26,
      "z": 16,
      "name": "Soil_Mud"
    },
    {
      "x": -17,
      "y": 27,
      "z": 16,
      "name": "Soil_Mud"
    },
    {
      "x": -17,
      "y": 28,
      "z": 16,
      "name": "Soil_Mud"
    },
    {
      "x": -17,
      "y": 29,
      "z": 16,
      "name": "Soil_Mud"
    },
    {
      "x": -17,
      "y": 30,
      "z": 16,
      "name": "Soil_Mud"
    },
    {
      "x": -17,
      "y": 14,
      "z": 17,
      "name": "Soil_Mud_Dry"
    },
    {
      "x": -17,
      "y": 15,
      "z": 17,
      "name": "Soil_Mud"
    },
    {
      "x": -17,
      "y": 16,
      "z": 17,
      "name": "Soil_Mud_Dry"
    },
    {
      "x": -17,
      "y": 17,
      "z": 17,
      "name": "Soil_Mud"
    },
    {
      "x": -17,
      "y": 18,
      "z": 17,
      "name": "Soil_Mud_Dry"
    },
    {
      "x": -17,
      "y": 19,
      "z": 17,
      "name": "Soil_Mud"
    },
    {
      "x": -17,
      "y": 20,
      "z": 17,
      "name": "Soil_Mud_Dry"
    },
    {
      "x": -17,
      "y": 21,
      "z": 17,
      "name": "Soil_Mud_Dry"
    },
    {
      "x": -17,
      "y": 22,
      "z": 17,
      "name": "Soil_Mud"
    },
    {
      "x": -17,
      "y": 23,
      "z": 17,
      "name": "Soil_Mud"
    },
    {
      "x": -17,
      "y": 24,
      "z": 17,
      "name": "Soil_Mud"
    },
    {
      "x": -17,
      "y": 25,
      "z": 17,
      "name": "Soil_Mud"
    },
    {
      "x": -17,
      "y": 26,
      "z": 17,
      "name": "Soil_Mud"
    },
    {
      "x": -17,
      "y": 27,
      "z": 17,
      "name": "Soil_Mud_Dry"
    },
    {
      "x": -17,
      "y": 28,
      "z": 17,
      "name": "Soil_Mud_Dry"
    },
    {
      "x": -17,
      "y": 29,
      "z": 17,
      "name": "Soil_Mud"
    },
    {
      "x": -17,
      "y": 30,
      "z": 17,
      "name": "Soil_Mud"
    },
    {
      "x": -17,
      "y": 14,
      "z": 18,
      "name": "Soil_Mud_Dry"
    },
    {
      "x": -17,
      "y": 15,
      "z": 18,
      "name": "Soil_Mud"
    },
    {
      "x": -17,
      "y": 16,
      "z": 18,
      "name": "Soil_Mud"
    },
    {
      "x": -17,
      "y": 17,
      "z": 18,
      "name": "Soil_Mud"
    },
    {
      "x": -17,
      "y": 18,
      "z": 18,
      "name": "Soil_Mud_Dry"
    },
    {
      "x": -17,
      "y": 19,
      "z": 18,
      "name": "Soil_Mud_Dry"
    },
    {
      "x": -17,
      "y": 20,
      "z": 18,
      "name": "Soil_Mud_Dry"
    },
    {
      "x": -17,
      "y": 21,
      "z": 18,
      "name": "Soil_Mud"
    },
    {
      "x": -17,
      "y": 22,
      "z": 18,
      "name": "Soil_Mud"
    },
    {
      "x": -17,
      "y": 23,
      "z": 18,
      "name": "Soil_Mud"
    },
    {
      "x": -17,
      "y": 24,
      "z": 18,
      "name": "Soil_Mud"
    },
    {
      "x": -17,
      "y": 25,
      "z": 18,
      "name": "Soil_Mud_Dry"
    },
    {
      "x": -17,
      "y": 26,
      "z": 18,
      "name": "Soil_Mud"
    },
    {
      "x": -17,
      "y": 27,
      "z": 18,
      "name": "Soil_Mud"
    },
    {
      "x": -17,
      "y": 28,
      "z": 18,
      "name": "Soil_Mud_Dry"
    },
    {
      "x": -17,
      "y": 29,
      "z": 18,
      "name": "Soil_Mud"
    },
    {
      "x": -17,
      "y": 30,
      "z": 18,
      "name": "Soil_Mud"
    },
    {
      "x": -17,
      "y": 15,
      "z": 19,
      "name": "Soil_Mud_Dry"
    },
    {
      "x": -17,
      "y": 16,
      "z": 19,
      "name": "Soil_Mud"
    },
    {
      "x": -17,
      "y": 17,
      "z": 19,
      "name": "Soil_Mud"
    },
    {
      "x": -17,
      "y": 18,
      "z": 19,
      "name": "Soil_Mud"
    },
    {
      "x": -17,
      "y": 19,
      "z": 19,
      "name": "Soil_Mud_Dry"
    },
    {
      "x": -17,
      "y": 20,
      "z": 19,
      "name": "Soil_Mud"
    },
    {
      "x": -17,
      "y": 21,
      "z": 19,
      "name": "Soil_Mud_Dry"
    },
    {
      "x": -17,
      "y": 22,
      "z": 19,
      "name": "Soil_Mud"
    },
    {
      "x": -17,
      "y": 23,
      "z": 19,
      "name": "Soil_Mud"
    },
    {
      "x": -17,
      "y": 27,
      "z": 19,
      "name": "Soil_Mud"
    },
    {
      "x": -17,
      "y": 28,
      "z": 19,
      "name": "Soil_Mud_Dry"
    },
    {
      "x": -17,
      "y": 29,
      "z": 19,
      "name": "Soil_Mud_Dry"
    },
    {
      "x": -17,
      "y": 30,
      "z": 19,
      "name": "Soil_Mud_Dry"
    },
    {
      "x": -17,
      "y": 31,
      "z": 19,
      "name": "Plant_Flower_Bushy_Violet"
    },
    {
      "x": -17,
      "y": 16,
      "z": 20,
      "name": "Soil_Mud"
    },
    {
      "x": -17,
      "y": 17,
      "z": 20,
      "name": "Soil_Mud"
    },
    {
      "x": -17,
      "y": 18,
      "z": 20,
      "name": "Soil_Mud"
    },
    {
      "x": -17,
      "y": 19,
      "z": 20,
      "name": "Soil_Mud"
    },
    {
      "x": -17,
      "y": 20,
      "z": 20,
      "name": "Soil_Mud"
    },
    {
      "x": -17,
      "y": 21,
      "z": 20,
      "name": "Soil_Mud_Dry"
    },
    {
      "x": -17,
      "y": 22,
      "z": 20,
      "name": "Soil_Mud"
    },
    {
      "x": -17,
      "y": 23,
      "z": 20,
      "name": "Soil_Mud"
    },
    {
      "x": -17,
      "y": 18,
      "z": 21,
      "name": "Soil_Mud"
    },
    {
      "x": -17,
      "y": 19,
      "z": 21,
      "name": "Soil_Mud"
    },
    {
      "x": -17,
      "y": 20,
      "z": 21,
      "name": "Soil_Mud"
    },
    {
      "x": -17,
      "y": 21,
      "z": 21,
      "name": "Soil_Mud"
    },
    {
      "x": -17,
      "y": 22,
      "z": 21,
      "name": "Soil_Mud"
    },
    {
      "x": -17,
      "y": 23,
      "z": 21,
      "name": "Soil_Mud"
    },
    {
      "x": -17,
      "y": 23,
      "z": 22,
      "name": "Soil_Mud"
    },
    {
      "x": -16,
      "y": 25,
      "z": -17,
      "name": "Soil_Mud"
    },
    {
      "x": -16,
      "y": 26,
      "z": -17,
      "name": "Soil_Mud"
    },
    {
      "x": -16,
      "y": 27,
      "z": -17,
      "name": "Soil_Mud"
    },
    {
      "x": -16,
      "y": 28,
      "z": -17,
      "name": "Soil_Mud"
    },
    {
      "x": -16,
      "y": 23,
      "z": -16,
      "name": "Soil_Mud"
    },
    {
      "x": -16,
      "y": 24,
      "z": -16,
      "name": "Soil_Mud"
    },
    {
      "x": -16,
      "y": 25,
      "z": -16,
      "name": "Soil_Mud_Dry"
    },
    {
      "x": -16,
      "y": 26,
      "z": -16,
      "name": "Soil_Mud_Dry"
    },
    {
      "x": -16,
      "y": 27,
      "z": -16,
      "name": "Soil_Mud"
    },
    {
      "x": -16,
      "y": 28,
      "z": -16,
      "name": "Soil_Mud"
    },
    {
      "x": -16,
      "y": 22,
      "z": -15,
      "name": "Soil_Mud"
    },
    {
      "x": -16,
      "y": 23,
      "z": -15,
      "name": "Soil_Mud"
    },
    {
      "x": -16,
      "y": 24,
      "z": -15,
      "name": "Soil_Mud"
    },
    {
      "x": -16,
      "y": 25,
      "z": -15,
      "name": "Soil_Mud"
    },
    {
      "x": -16,
      "y": 26,
      "z": -15,
      "name": "Soil_Mud_Dry"
    },
    {
      "x": -16,
      "y": 27,
      "z": -15,
      "name": "Soil_Mud"
    },
    {
      "x": -16,
      "y": 28,
      "z": -15,
      "name": "Soil_Mud_Dry"
    },
    {
      "x": -16,
      "y": 21,
      "z": -14,
      "name": "Soil_Mud"
    },
    {
      "x": -16,
      "y": 22,
      "z": -14,
      "name": "Soil_Mud"
    },
    {
      "x": -16,
      "y": 23,
      "z": -14,
      "name": "Soil_Mud_Dry"
    },
    {
      "x": -16,
      "y": 24,
      "z": -14,
      "name": "Soil_Mud"
    },
    {
      "x": -16,
      "y": 25,
      "z": -14,
      "name": "Soil_Mud"
    },
    {
      "x": -16,
      "y": 26,
      "z": -14,
      "name": "Soil_Mud_Dry"
    },
    {
      "x": -16,
      "y": 27,
      "z": -14,
      "name": "Soil_Mud"
    },
    {
      "x": -16,
      "y": 28,
      "z": -14,
      "name": "Soil_Mud"
    },
    {
      "x": -16,
      "y": 22,
      "z": -13,
      "name": "Soil_Mud"
    },
    {
      "x": -16,
      "y": 23,
      "z": -13,
      "name": "Soil_Mud_Dry"
    },
    {
      "x": -16,
      "y": 24,
      "z": -13,
      "name": "Soil_Mud"
    },
    {
      "x": -16,
      "y": 25,
      "z": -13,
      "name": "Soil_Mud"
    },
    {
      "x": -16,
      "y": 26,
      "z": -13,
      "name": "Soil_Mud"
    },
    {
      "x": -16,
      "y": 27,
      "z": -13,
      "name": "Soil_Mud_Dry"
    },
    {
      "x": -16,
      "y": 28,
      "z": -13,
      "name": "Soil_Mud_Dry"
    },
    {
      "x": -16,
      "y": 29,
      "z": -13,
      "name": "Soil_Mud"
    },
    {
      "x": -16,
      "y": 23,
      "z": -12,
      "name": "Soil_Mud"
    },
    {
      "x": -16,
      "y": 24,
      "z": -12,
      "name": "Soil_Mud"
    },
    {
      "x": -16,
      "y": 25,
      "z": -12,
      "name": "Soil_Mud"
    },
    {
      "x": -16,
      "y": 26,
      "z": -12,
      "name": "Soil_Mud"
    },
    {
      "x": -16,
      "y": 27,
      "z": -12,
      "name": "Soil_Mud"
    },
    {
      "x": -16,
      "y": 28,
      "z": -12,
      "name": "Soil_Mud"
    },
    {
      "x": -16,
      "y": 29,
      "z": -12,
      "name": "Soil_Mud_Dry"
    },
    {
      "x": -16,
      "y": 30,
      "z": -12,
      "name": "Soil_Mud"
    },
    {
      "x": -16,
      "y": 24,
      "z": -11,
      "name": "Soil_Mud"
    },
    {
      "x": -16,
      "y": 25,
      "z": -11,
      "name": "Soil_Mud_Dry"
    },
    {
      "x": -16,
      "y": 26,
      "z": -11,
      "name": "Soil_Mud_Dry"
    },
    {
      "x": -16,
      "y": 27,
      "z": -11,
      "name": "Soil_Mud"
    },
    {
      "x": -16,
      "y": 28,
      "z": -11,
      "name": "Soil_Mud"
    },
    {
      "x": -16,
      "y": 29,
      "z": -11,
      "name": "Soil_Mud"
    },
    {
      "x": -16,
      "y": 30,
      "z": -11,
      "name": "Soil_Mud"
    },
    {
      "x": -16,
      "y": 23,
      "z": -10,
      "name": "Soil_Mud_Dry"
    },
    {
      "x": -16,
      "y": 24,
      "z": -10,
      "name": "Soil_Mud"
    },
    {
      "x": -16,
      "y": 25,
      "z": -10,
      "name": "Soil_Mud"
    },
    {
      "x": -16,
      "y": 26,
      "z": -10,
      "name": "Soil_Mud"
    },
    {
      "x": -16,
      "y": 27,
      "z": -10,
      "name": "Soil_Mud_Dry"
    },
    {
      "x": -16,
      "y": 28,
      "z": -10,
      "name": "Soil_Mud_Dry"
    },
    {
      "x": -16,
      "y": 29,
      "z": -10,
      "name": "Soil_Mud"
    },
    {
      "x": -16,
      "y": 30,
      "z": -10,
      "name": "Soil_Mud"
    },
    {
      "x": -16,
      "y": 31,
      "z": -10,
      "name": "Soil_Mud"
    },
    {
      "x": -16,
      "y": 23,
      "z": -9,
      "name": "Soil_Mud"
    },
    {
      "x": -16,
      "y": 24,
      "z": -9,
      "name": "Soil_Mud"
    },
    {
      "x": -16,
      "y": 25,
      "z": -9,
      "name": "Soil_Mud_Dry"
    },
    {
      "x": -16,
      "y": 26,
      "z": -9,
      "name": "Soil_Mud_Dry"
    },
    {
      "x": -16,
      "y": 27,
      "z": -9,
      "name": "Soil_Mud"
    },
    {
      "x": -16,
      "y": 28,
      "z": -9,
      "name": "Soil_Mud"
    },
    {
      "x": -16,
      "y": 29,
      "z": -9,
      "name": "Soil_Mud"
    },
    {
      "x": -16,
      "y": 30,
      "z": -9,
      "name": "Soil_Mud"
    },
    {
      "x": -16,
      "y": 31,
      "z": -9,
      "name": "Soil_Mud"
    },
    {
      "x": -16,
      "y": 23,
      "z": -8,
      "name": "Soil_Mud"
    },
    {
      "x": -16,
      "y": 24,
      "z": -8,
      "name": "Soil_Mud"
    },
    {
      "x": -16,
      "y": 25,
      "z": -8,
      "name": "Soil_Mud"
    },
    {
      "x": -16,
      "y": 26,
      "z": -8,
      "name": "Soil_Mud"
    },
    {
      "x": -16,
      "y": 27,
      "z": -8,
      "name": "Soil_Mud"
    },
    {
      "x": -16,
      "y": 28,
      "z": -8,
      "name": "Soil_Mud_Dry"
    },
    {
      "x": -16,
      "y": 29,
      "z": -8,
      "name": "Soil_Mud"
    },
    {
      "x": -16,
      "y": 30,
      "z": -8,
      "name": "Soil_Mud"
    },
    {
      "x": -16,
      "y": 31,
      "z": -8,
      "name": "Soil_Mud"
    },
    {
      "x": -16,
      "y": 24,
      "z": -7,
      "name": "Soil_Mud"
    },
    {
      "x": -16,
      "y": 25,
      "z": -7,
      "name": "Soil_Mud"
    },
    {
      "x": -16,
      "y": 26,
      "z": -7,
      "name": "Soil_Mud"
    },
    {
      "x": -16,
      "y": 27,
      "z": -7,
      "name": "Soil_Mud"
    },
    {
      "x": -16,
      "y": 28,
      "z": -7,
      "name": "Soil_Mud"
    },
    {
      "x": -16,
      "y": 29,
      "z": -7,
      "name": "Soil_Mud_Dry"
    },
    {
      "x": -16,
      "y": 30,
      "z": -7,
      "name": "Soil_Mud"
    },
    {
      "x": -16,
      "y": 31,
      "z": -7,
      "name": "Soil_Mud"
    },
    {
      "x": -16,
      "y": 25,
      "z": -6,
      "name": "Soil_Mud"
    },
    {
      "x": -16,
      "y": 26,
      "z": -6,
      "name": "Soil_Mud"
    },
    {
      "x": -16,
      "y": 27,
      "z": -6,
      "name": "Soil_Mud_Dry"
    },
    {
      "x": -16,
      "y": 28,
      "z": -6,
      "name": "Ore_Thorium_Mud_Cracked"
    },
    {
      "x": -16,
      "y": 29,
      "z": -6,
      "name": "Ore_Thorium_Mud"
    },
    {
      "x": -16,
      "y": 30,
      "z": -6,
      "name": "Soil_Mud"
    },
    {
      "x": -16,
      "y": 27,
      "z": -5,
      "name": "Plant_Crop_Mushroom_Shelve_Brown"
    },
    {
      "x": -16,
      "y": 28,
      "z": -5,
      "name": "Ore_Thorium_Mud_Cracked"
    },
    {
      "x": -16,
      "y": 29,
      "z": -5,
      "name": "Ore_Thorium_Mud_Cracked"
    },
    {
      "x": -16,
      "y": 30,
      "z": -5,
      "name": "Soil_Mud"
    },
    {
      "x": -16,
      "y": 31,
      "z": -5,
      "name": "Soil_Mud"
    },
    {
      "x": -16,
      "y": 25,
      "z": 3,
      "name": "Soil_Mud"
    },
    {
      "x": -16,
      "y": 26,
      "z": 3,
      "name": "Soil_Mud"
    },
    {
      "x": -16,
      "y": 27,
      "z": 3,
      "name": "Soil_Mud"
    },
    {
      "x": -16,
      "y": 28,
      "z": 3,
      "name": "Soil_Mud_Dry"
    },
    {
      "x": -16,
      "y": 21,
      "z": 4,
      "name": "Soil_Mud"
    },
    {
      "x": -16,
      "y": 22,
      "z": 4,
      "name": "Soil_Mud"
    },
    {
      "x": -16,
      "y": 23,
      "z": 4,
      "name": "Soil_Mud"
    },
    {
      "x": -16,
      "y": 24,
      "z": 4,
      "name": "Soil_Mud_Dry"
    },
    {
      "x": -16,
      "y": 25,
      "z": 4,
      "name": "Soil_Mud"
    },
    {
      "x": -16,
      "y": 26,
      "z": 4,
      "name": "Soil_Mud"
    },
    {
      "x": -16,
      "y": 27,
      "z": 4,
      "name": "Soil_Mud"
    },
    {
      "x": -16,
      "y": 28,
      "z": 4,
      "name": "Soil_Mud_Dry"
    },
    {
      "x": -16,
      "y": 20,
      "z": 5,
      "name": "Soil_Mud"
    },
    {
      "x": -16,
      "y": 21,
      "z": 5,
      "name": "Soil_Mud_Dry"
    },
    {
      "x": -16,
      "y": 22,
      "z": 5,
      "name": "Soil_Mud_Dry"
    },
    {
      "x": -16,
      "y": 23,
      "z": 5,
      "name": "Soil_Mud_Dry"
    },
    {
      "x": -16,
      "y": 24,
      "z": 5,
      "name": "Soil_Mud"
    },
    {
      "x": -16,
      "y": 25,
      "z": 5,
      "name": "Soil_Mud"
    },
    {
      "x": -16,
      "y": 26,
      "z": 5,
      "name": "Soil_Mud_Dry"
    },
    {
      "x": -16,
      "y": 27,
      "z": 5,
      "name": "Soil_Mud"
    },
    {
      "x": -16,
      "y": 28,
      "z": 5,
      "name": "Soil_Mud"
    },
    {
      "x": -16,
      "y": 48,
      "z": 5,
      "name": "Plant_Crop_Mushroom_Block_Purple"
    },
    {
      "x": -16,
      "y": 20,
      "z": 6,
      "name": "Soil_Mud_Dry"
    },
    {
      "x": -16,
      "y": 21,
      "z": 6,
      "name": "Soil_Mud_Dry"
    },
    {
      "x": -16,
      "y": 22,
      "z": 6,
      "name": "Soil_Mud"
    },
    {
      "x": -16,
      "y": 23,
      "z": 6,
      "name": "Soil_Mud"
    },
    {
      "x": -16,
      "y": 24,
      "z": 6,
      "name": "Soil_Mud"
    },
    {
      "x": -16,
      "y": 25,
      "z": 6,
      "name": "Soil_Mud"
    },
    {
      "x": -16,
      "y": 26,
      "z": 6,
      "name": "Soil_Mud"
    },
    {
      "x": -16,
      "y": 27,
      "z": 6,
      "name": "Soil_Mud_Dry"
    },
    {
      "x": -16,
      "y": 28,
      "z": 6,
      "name": "Soil_Mud"
    },
    {
      "x": -16,
      "y": 48,
      "z": 6,
      "name": "Plant_Crop_Mushroom_Block_Purple"
    },
    {
      "x": -16,
      "y": 20,
      "z": 7,
      "name": "Soil_Mud"
    },
    {
      "x": -16,
      "y": 21,
      "z": 7,
      "name": "Soil_Mud"
    },
    {
      "x": -16,
      "y": 22,
      "z": 7,
      "name": "Soil_Mud"
    },
    {
      "x": -16,
      "y": 23,
      "z": 7,
      "name": "Soil_Mud_Dry"
    },
    {
      "x": -16,
      "y": 24,
      "z": 7,
      "name": "Soil_Mud"
    },
    {
      "x": -16,
      "y": 25,
      "z": 7,
      "name": "Soil_Mud"
    },
    {
      "x": -16,
      "y": 26,
      "z": 7,
      "name": "Soil_Mud"
    },
    {
      "x": -16,
      "y": 27,
      "z": 7,
      "name": "Soil_Mud_Dry"
    },
    {
      "x": -16,
      "y": 28,
      "z": 7,
      "name": "Soil_Mud"
    },
    {
      "x": -16,
      "y": 48,
      "z": 7,
      "name": "Plant_Crop_Mushroom_Block_Purple"
    },
    {
      "x": -16,
      "y": 19,
      "z": 8,
      "name": "Soil_Mud_Dry"
    },
    {
      "x": -16,
      "y": 20,
      "z": 8,
      "name": "Soil_Mud_Dry"
    },
    {
      "x": -16,
      "y": 21,
      "z": 8,
      "name": "Soil_Mud"
    },
    {
      "x": -16,
      "y": 22,
      "z": 8,
      "name": "Soil_Mud"
    },
    {
      "x": -16,
      "y": 23,
      "z": 8,
      "name": "Soil_Mud_Dry"
    },
    {
      "x": -16,
      "y": 24,
      "z": 8,
      "name": "Soil_Mud_Dry"
    },
    {
      "x": -16,
      "y": 25,
      "z": 8,
      "name": "Soil_Mud"
    },
    {
      "x": -16,
      "y": 26,
      "z": 8,
      "name": "Soil_Mud"
    },
    {
      "x": -16,
      "y": 27,
      "z": 8,
      "name": "Soil_Mud"
    },
    {
      "x": -16,
      "y": 28,
      "z": 8,
      "name": "Soil_Mud"
    },
    {
      "x": -16,
      "y": 48,
      "z": 8,
      "name": "Plant_Crop_Mushroom_Block_Purple"
    },
    {
      "x": -16,
      "y": 17,
      "z": 9,
      "name": "Soil_Mud_Dry"
    },
    {
      "x": -16,
      "y": 18,
      "z": 9,
      "name": "Soil_Mud"
    },
    {
      "x": -16,
      "y": 19,
      "z": 9,
      "name": "Soil_Mud_Dry"
    },
    {
      "x": -16,
      "y": 20,
      "z": 9,
      "name": "Soil_Mud_Dry"
    },
    {
      "x": -16,
      "y": 21,
      "z": 9,
      "name": "Soil_Mud_Dry"
    },
    {
      "x": -16,
      "y": 22,
      "z": 9,
      "name": "Soil_Mud_Dry"
    },
    {
      "x": -16,
      "y": 23,
      "z": 9,
      "name": "Soil_Mud_Dry"
    },
    {
      "x": -16,
      "y": 24,
      "z": 9,
      "name": "Soil_Mud_Dry"
    },
    {
      "x": -16,
      "y": 25,
      "z": 9,
      "name": "Soil_Mud"
    },
    {
      "x": -16,
      "y": 26,
      "z": 9,
      "name": "Soil_Mud"
    },
    {
      "x": -16,
      "y": 27,
      "z": 9,
      "name": "Soil_Mud_Dry"
    },
    {
      "x": -16,
      "y": 28,
      "z": 9,
      "name": "Soil_Mud_Dry"
    },
    {
      "x": -16,
      "y": 48,
      "z": 9,
      "name": "Plant_Crop_Mushroom_Block_Purple"
    },
    {
      "x": -16,
      "y": 16,
      "z": 10,
      "name": "Soil_Mud_Dry"
    },
    {
      "x": -16,
      "y": 17,
      "z": 10,
      "name": "Soil_Mud"
    },
    {
      "x": -16,
      "y": 18,
      "z": 10,
      "name": "Soil_Mud"
    },
    {
      "x": -16,
      "y": 19,
      "z": 10,
      "name": "Soil_Mud_Dry"
    },
    {
      "x": -16,
      "y": 20,
      "z": 10,
      "name": "Soil_Mud"
    },
    {
      "x": -16,
      "y": 21,
      "z": 10,
      "name": "Soil_Mud_Dry"
    },
    {
      "x": -16,
      "y": 22,
      "z": 10,
      "name": "Soil_Mud"
    },
    {
      "x": -16,
      "y": 23,
      "z": 10,
      "name": "Soil_Mud"
    },
    {
      "x": -16,
      "y": 24,
      "z": 10,
      "name": "Soil_Mud"
    },
    {
      "x": -16,
      "y": 25,
      "z": 10,
      "name": "Soil_Mud"
    },
    {
      "x": -16,
      "y": 26,
      "z": 10,
      "name": "Soil_Mud"
    },
    {
      "x": -16,
      "y": 27,
      "z": 10,
      "name": "Soil_Mud_Dry"
    },
    {
      "x": -16,
      "y": 28,
      "z": 10,
      "name": "Soil_Mud"
    },
    {
      "x": -16,
      "y": 29,
      "z": 10,
      "name": "Plant_Moss_Rug_Pink"
    },
    {
      "x": -16,
      "y": 48,
      "z": 10,
      "name": "Plant_Crop_Mushroom_Block_Purple"
    },
    {
      "x": -16,
      "y": 16,
      "z": 11,
      "name": "Soil_Mud"
    },
    {
      "x": -16,
      "y": 17,
      "z": 11,
      "name": "Soil_Mud"
    },
    {
      "x": -16,
      "y": 18,
      "z": 11,
      "name": "Soil_Mud_Dry"
    },
    {
      "x": -16,
      "y": 19,
      "z": 11,
      "name": "Soil_Mud_Dry"
    },
    {
      "x": -16,
      "y": 20,
      "z": 11,
      "name": "Soil_Mud"
    },
    {
      "x": -16,
      "y": 21,
      "z": 11,
      "name": "Soil_Mud_Dry"
    },
    {
      "x": -16,
      "y": 22,
      "z": 11,
      "name": "Soil_Mud_Dry"
    },
    {
      "x": -16,
      "y": 23,
      "z": 11,
      "name": "Soil_Mud"
    },
    {
      "x": -16,
      "y": 24,
      "z": 11,
      "name": "Soil_Mud_Dry"
    },
    {
      "x": -16,
      "y": 25,
      "z": 11,
      "name": "Soil_Mud_Dry"
    },
    {
      "x": -16,
      "y": 26,
      "z": 11,
      "name": "Soil_Mud_Dry"
    },
    {
      "x": -16,
      "y": 27,
      "z": 11,
      "name": "Soil_Mud"
    },
    {
      "x": -16,
      "y": 28,
      "z": 11,
      "name": "Soil_Mud"
    },
    {
      "x": -16,
      "y": 29,
      "z": 11,
      "name": "Soil_Mud_Dry"
    },
    {
      "x": -16,
      "y": 48,
      "z": 11,
      "name": "Plant_Crop_Mushroom_Block_Purple"
    },
    {
      "x": -16,
      "y": 16,
      "z": 12,
      "name": "Soil_Mud"
    },
    {
      "x": -16,
      "y": 17,
      "z": 12,
      "name": "Soil_Mud"
    },
    {
      "x": -16,
      "y": 18,
      "z": 12,
      "name": "Soil_Mud"
    },
    {
      "x": -16,
      "y": 19,
      "z": 12,
      "name": "Ore_Thorium_Mud"
    },
    {
      "x": -16,
      "y": 20,
      "z": 12,
      "name": "Ore_Thorium_Mud_Cracked"
    },
    {
      "x": -16,
      "y": 21,
      "z": 12,
      "name": "Soil_Mud"
    },
    {
      "x": -16,
      "y": 22,
      "z": 12,
      "name": "Soil_Mud_Dry"
    },
    {
      "x": -16,
      "y": 23,
      "z": 12,
      "name": "Soil_Mud_Dry"
    },
    {
      "x": -16,
      "y": 24,
      "z": 12,
      "name": "Soil_Mud_Dry"
    },
    {
      "x": -16,
      "y": 25,
      "z": 12,
      "name": "Soil_Mud"
    },
    {
      "x": -16,
      "y": 26,
      "z": 12,
      "name": "Soil_Mud"
    },
    {
      "x": -16,
      "y": 27,
      "z": 12,
      "name": "Soil_Mud"
    },
    {
      "x": -16,
      "y": 28,
      "z": 12,
      "name": "Soil_Mud"
    },
    {
      "x": -16,
      "y": 29,
      "z": 12,
      "name": "Soil_Mud"
    },
    {
      "x": -16,
      "y": 14,
      "z": 13,
      "name": "Plant_Moss_Cave_Red"
    },
    {
      "x": -16,
      "y": 15,
      "z": 13,
      "name": "Soil_Mud"
    },
    {
      "x": -16,
      "y": 16,
      "z": 13,
      "name": "Soil_Mud_Dry"
    },
    {
      "x": -16,
      "y": 17,
      "z": 13,
      "name": "Soil_Mud"
    },
    {
      "x": -16,
      "y": 18,
      "z": 13,
      "name": "Soil_Mud"
    },
    {
      "x": -16,
      "y": 19,
      "z": 13,
      "name": "Ore_Thorium_Mud"
    },
    {
      "x": -16,
      "y": 20,
      "z": 13,
      "name": "Ore_Thorium_Mud_Cracked"
    },
    {
      "x": -16,
      "y": 21,
      "z": 13,
      "name": "Soil_Mud"
    },
    {
      "x": -16,
      "y": 22,
      "z": 13,
      "name": "Soil_Mud"
    },
    {
      "x": -16,
      "y": 23,
      "z": 13,
      "name": "Soil_Mud_Dry"
    },
    {
      "x": -16,
      "y": 24,
      "z": 13,
      "name": "Soil_Mud"
    },
    {
      "x": -16,
      "y": 25,
      "z": 13,
      "name": "Soil_Mud_Dry"
    },
    {
      "x": -16,
      "y": 26,
      "z": 13,
      "name": "Soil_Mud"
    },
    {
      "x": -16,
      "y": 27,
      "z": 13,
      "name": "Soil_Mud"
    },
    {
      "x": -16,
      "y": 28,
      "z": 13,
      "name": "Soil_Mud"
    },
    {
      "x": -16,
      "y": 29,
      "z": 13,
      "name": "Soil_Mud"
    },
    {
      "x": -16,
      "y": 13,
      "z": 14,
      "name": "Soil_Mud"
    },
    {
      "x": -16,
      "y": 14,
      "z": 14,
      "name": "Soil_Mud_Dry"
    },
    {
      "x": -16,
      "y": 15,
      "z": 14,
      "name": "Soil_Mud_Dry"
    },
    {
      "x": -16,
      "y": 16,
      "z": 14,
      "name": "Soil_Mud"
    },
    {
      "x": -16,
      "y": 17,
      "z": 14,
      "name": "Soil_Mud"
    },
    {
      "x": -16,
      "y": 18,
      "z": 14,
      "name": "Soil_Mud_Dry"
    },
    {
      "x": -16,
      "y": 19,
      "z": 14,
      "name": "Soil_Mud"
    },
    {
      "x": -16,
      "y": 20,
      "z": 14,
      "name": "Soil_Mud_Dry"
    },
    {
      "x": -16,
      "y": 21,
      "z": 14,
      "name": "Soil_Mud"
    },
    {
      "x": -16,
      "y": 22,
      "z": 14,
      "name": "Soil_Mud_Dry"
    },
    {
      "x": -16,
      "y": 23,
      "z": 14,
      "name": "Soil_Mud"
    },
    {
      "x": -16,
      "y": 24,
      "z": 14,
      "name": "Soil_Mud_Dry"
    },
    {
      "x": -16,
      "y": 25,
      "z": 14,
      "name": "Soil_Mud"
    },
    {
      "x": -16,
      "y": 26,
      "z": 14,
      "name": "Soil_Mud"
    },
    {
      "x": -16,
      "y": 27,
      "z": 14,
      "name": "Soil_Mud"
    },
    {
      "x": -16,
      "y": 28,
      "z": 14,
      "name": "Soil_Mud"
    },
    {
      "x": -16,
      "y": 29,
      "z": 14,
      "name": "Soil_Mud_Dry"
    },
    {
      "x": -16,
      "y": 30,
      "z": 14,
      "name": "Soil_Mud_Dry"
    },
    {
      "x": -16,
      "y": 15,
      "z": 15,
      "name": "Soil_Mud"
    },
    {
      "x": -16,
      "y": 16,
      "z": 15,
      "name": "Soil_Mud_Dry"
    },
    {
      "x": -16,
      "y": 17,
      "z": 15,
      "name": "Soil_Mud"
    },
    {
      "x": -16,
      "y": 18,
      "z": 15,
      "name": "Soil_Mud"
    },
    {
      "x": -16,
      "y": 19,
      "z": 15,
      "name": "Soil_Mud_Dry"
    },
    {
      "x": -16,
      "y": 20,
      "z": 15,
      "name": "Soil_Mud"
    },
    {
      "x": -16,
      "y": 21,
      "z": 15,
      "name": "Soil_Mud_Dry"
    },
    {
      "x": -16,
      "y": 22,
      "z": 15,
      "name": "Soil_Mud"
    },
    {
      "x": -16,
      "y": 23,
      "z": 15,
      "name": "Soil_Mud_Dry"
    },
    {
      "x": -16,
      "y": 24,
      "z": 15,
      "name": "Soil_Mud_Dry"
    },
    {
      "x": -16,
      "y": 25,
      "z": 15,
      "name": "Soil_Mud"
    },
    {
      "x": -16,
      "y": 26,
      "z": 15,
      "name": "Soil_Mud"
    },
    {
      "x": -16,
      "y": 27,
      "z": 15,
      "name": "Soil_Mud"
    },
    {
      "x": -16,
      "y": 28,
      "z": 15,
      "name": "Soil_Mud"
    },
    {
      "x": -16,
      "y": 29,
      "z": 15,
      "name": "Soil_Mud"
    },
    {
      "x": -16,
      "y": 30,
      "z": 15,
      "name": "Soil_Mud_Dry"
    },
    {
      "x": -16,
      "y": 14,
      "z": 16,
      "name": "Soil_Mud"
    },
    {
      "x": -16,
      "y": 15,
      "z": 16,
      "name": "Soil_Mud"
    },
    {
      "x": -16,
      "y": 16,
      "z": 16,
      "name": "Soil_Mud"
    },
    {
      "x": -16,
      "y": 17,
      "z": 16,
      "name": "Soil_Mud_Dry"
    },
    {
      "x": -16,
      "y": 18,
      "z": 16,
      "name": "Soil_Mud"
    },
    {
      "x": -16,
      "y": 19,
      "z": 16,
      "name": "Soil_Mud"
    },
    {
      "x": -16,
      "y": 20,
      "z": 16,
      "name": "Soil_Mud_Dry"
    },
    {
      "x": -16,
      "y": 21,
      "z": 16,
      "name": "Soil_Mud"
    },
    {
      "x": -16,
      "y": 22,
      "z": 16,
      "name": "Soil_Mud"
    },
    {
      "x": -16,
      "y": 23,
      "z": 16,
      "name": "Soil_Mud_Dry"
    },
    {
      "x": -16,
      "y": 24,
      "z": 16,
      "name": "Soil_Mud"
    },
    {
      "x": -16,
      "y": 25,
      "z": 16,
      "name": "Soil_Mud"
    },
    {
      "x": -16,
      "y": 26,
      "z": 16,
      "name": "Soil_Mud"
    },
    {
      "x": -16,
      "y": 27,
      "z": 16,
      "name": "Soil_Mud"
    },
    {
      "x": -16,
      "y": 28,
      "z": 16,
      "name": "Soil_Mud"
    },
    {
      "x": -16,
      "y": 29,
      "z": 16,
      "name": "Soil_Mud_Dry"
    },
    {
      "x": -16,
      "y": 30,
      "z": 16,
      "name": "Soil_Mud"
    },
    {
      "x": -16,
      "y": 13,
      "z": 17,
      "name": "Soil_Mud"
    },
    {
      "x": -16,
      "y": 14,
      "z": 17,
      "name": "Soil_Mud_Dry"
    },
    {
      "x": -16,
      "y": 15,
      "z": 17,
      "name": "Soil_Mud"
    },
    {
      "x": -16,
      "y": 16,
      "z": 17,
      "name": "Soil_Mud"
    },
    {
      "x": -16,
      "y": 17,
      "z": 17,
      "name": "Soil_Mud_Dry"
    },
    {
      "x": -16,
      "y": 18,
      "z": 17,
      "name": "Soil_Mud"
    },
    {
      "x": -16,
      "y": 19,
      "z": 17,
      "name": "Soil_Mud"
    },
    {
      "x": -16,
      "y": 20,
      "z": 17,
      "name": "Soil_Mud"
    },
    {
      "x": -16,
      "y": 21,
      "z": 17,
      "name": "Soil_Mud_Dry"
    },
    {
      "x": -16,
      "y": 22,
      "z": 17,
      "name": "Soil_Mud"
    },
    {
      "x": -16,
      "y": 23,
      "z": 17,
      "name": "Soil_Mud"
    },
    {
      "x": -16,
      "y": 24,
      "z": 17,
      "name": "Soil_Mud"
    },
    {
      "x": -16,
      "y": 25,
      "z": 17,
      "name": "Soil_Mud"
    },
    {
      "x": -16,
      "y": 26,
      "z": 17,
      "name": "Soil_Mud_Dry"
    },
    {
      "x": -16,
      "y": 27,
      "z": 17,
      "name": "Soil_Mud_Dry"
    },
    {
      "x": -16,
      "y": 28,
      "z": 17,
      "name": "Soil_Mud_Dry"
    },
    {
      "x": -16,
      "y": 29,
      "z": 17,
      "name": "Soil_Mud"
    },
    {
      "x": -16,
      "y": 30,
      "z": 17,
      "name": "Soil_Mud_Dry"
    },
    {
      "x": -16,
      "y": 13,
      "z": 18,
      "name": "Soil_Mud_Dry"
    },
    {
      "x": -16,
      "y": 14,
      "z": 18,
      "name": "Soil_Mud_Dry"
    },
    {
      "x": -16,
      "y": 15,
      "z": 18,
      "name": "Soil_Mud"
    },
    {
      "x": -16,
      "y": 16,
      "z": 18,
      "name": "Soil_Mud"
    },
    {
      "x": -16,
      "y": 17,
      "z": 18,
      "name": "Soil_Mud"
    },
    {
      "x": -16,
      "y": 18,
      "z": 18,
      "name": "Soil_Mud"
    },
    {
      "x": -16,
      "y": 19,
      "z": 18,
      "name": "Soil_Mud_Dry"
    },
    {
      "x": -16,
      "y": 20,
      "z": 18,
      "name": "Soil_Mud"
    },
    {
      "x": -16,
      "y": 21,
      "z": 18,
      "name": "Soil_Mud_Dry"
    },
    {
      "x": -16,
      "y": 22,
      "z": 18,
      "name": "Soil_Mud"
    },
    {
      "x": -16,
      "y": 23,
      "z": 18,
      "name": "Soil_Mud"
    },
    {
      "x": -16,
      "y": 24,
      "z": 18,
      "name": "Soil_Mud_Dry"
    },
    {
      "x": -16,
      "y": 25,
      "z": 18,
      "name": "Soil_Mud"
    },
    {
      "x": -16,
      "y": 26,
      "z": 18,
      "name": "Soil_Mud"
    },
    {
      "x": -16,
      "y": 27,
      "z": 18,
      "name": "Soil_Mud_Dry"
    },
    {
      "x": -16,
      "y": 28,
      "z": 18,
      "name": "Soil_Mud"
    },
    {
      "x": -16,
      "y": 29,
      "z": 18,
      "name": "Soil_Mud_Dry"
    },
    {
      "x": -16,
      "y": 30,
      "z": 18,
      "name": "Soil_Mud_Dry"
    },
    {
      "x": -16,
      "y": 14,
      "z": 19,
      "name": "Soil_Mud"
    },
    {
      "x": -16,
      "y": 15,
      "z": 19,
      "name": "Soil_Mud"
    },
    {
      "x": -16,
      "y": 16,
      "z": 19,
      "name": "Soil_Mud"
    },
    {
      "x": -16,
      "y": 17,
      "z": 19,
      "name": "Soil_Mud"
    },
    {
      "x": -16,
      "y": 18,
      "z": 19,
      "name": "Soil_Mud_Dry"
    },
    {
      "x": -16,
      "y": 19,
      "z": 19,
      "name": "Soil_Mud_Dry"
    },
    {
      "x": -16,
      "y": 20,
      "z": 19,
      "name": "Soil_Mud_Dry"
    },
    {
      "x": -16,
      "y": 21,
      "z": 19,
      "name": "Soil_Mud"
    },
    {
      "x": -16,
      "y": 22,
      "z": 19,
      "name": "Soil_Mud"
    },
    {
      "x": -16,
      "y": 23,
      "z": 19,
      "name": "Soil_Mud"
    },
    {
      "x": -16,
      "y": 25,
      "z": 19,
      "name": "Soil_Mud_Dry"
    },
    {
      "x": -16,
      "y": 26,
      "z": 19,
      "name": "Soil_Mud_Dry"
    },
    {
      "x": -16,
      "y": 27,
      "z": 19,
      "name": "Soil_Mud"
    },
    {
      "x": -16,
      "y": 28,
      "z": 19,
      "name": "Soil_Mud"
    },
    {
      "x": -16,
      "y": 29,
      "z": 19,
      "name": "Soil_Mud"
    },
    {
      "x": -16,
      "y": 30,
      "z": 19,
      "name": "Soil_Mud_Dry"
    },
    {
      "x": -16,
      "y": 15,
      "z": 20,
      "name": "Soil_Mud"
    },
    {
      "x": -16,
      "y": 16,
      "z": 20,
      "name": "Soil_Mud"
    },
    {
      "x": -16,
      "y": 17,
      "z": 20,
      "name": "Soil_Mud_Dry"
    },
    {
      "x": -16,
      "y": 18,
      "z": 20,
      "name": "Soil_Mud_Dry"
    },
    {
      "x": -16,
      "y": 19,
      "z": 20,
      "name": "Soil_Mud"
    },
    {
      "x": -16,
      "y": 20,
      "z": 20,
      "name": "Soil_Mud"
    },
    {
      "x": -16,
      "y": 21,
      "z": 20,
      "name": "Soil_Mud"
    },
    {
      "x": -16,
      "y": 22,
      "z": 20,
      "name": "Soil_Mud_Dry"
    },
    {
      "x": -16,
      "y": 23,
      "z": 20,
      "name": "Soil_Mud"
    },
    {
      "x": -16,
      "y": 30,
      "z": 20,
      "name": "Soil_Mud"
    },
    {
      "x": -16,
      "y": 17,
      "z": 21,
      "name": "Soil_Mud"
    },
    {
      "x": -16,
      "y": 18,
      "z": 21,
      "name": "Soil_Mud"
    },
    {
      "x": -16,
      "y": 19,
      "z": 21,
      "name": "Soil_Mud"
    },
    {
      "x": -16,
      "y": 20,
      "z": 21,
      "name": "Soil_Mud"
    },
    {
      "x": -16,
      "y": 21,
      "z": 21,
      "name": "Soil_Mud"
    },
    {
      "x": -16,
      "y": 22,
      "z": 21,
      "name": "Soil_Mud"
    },
    {
      "x": -16,
      "y": 23,
      "z": 21,
      "name": "Soil_Mud"
    },
    {
      "x": -16,
      "y": 20,
      "z": 22,
      "name": "Soil_Mud"
    },
    {
      "x": -16,
      "y": 21,
      "z": 22,
      "name": "Soil_Mud"
    },
    {
      "x": -16,
      "y": 22,
      "z": 22,
      "name": "Soil_Mud"
    },
    {
      "x": -16,
      "y": 23,
      "z": 22,
      "name": "Soil_Mud"
    },
    {
      "x": -15,
      "y": 25,
      "z": -18,
      "name": "Soil_Mud"
    },
    {
      "x": -15,
      "y": 26,
      "z": -18,
      "name": "Soil_Mud"
    },
    {
      "x": -15,
      "y": 27,
      "z": -18,
      "name": "Soil_Mud_Dry"
    },
    {
      "x": -15,
      "y": 28,
      "z": -18,
      "name": "Soil_Mud"
    },
    {
      "x": -15,
      "y": 22,
      "z": -17,
      "name": "Soil_Mud"
    },
    {
      "x": -15,
      "y": 23,
      "z": -17,
      "name": "Soil_Mud"
    },
    {
      "x": -15,
      "y": 24,
      "z": -17,
      "name": "Soil_Mud"
    },
    {
      "x": -15,
      "y": 25,
      "z": -17,
      "name": "Soil_Mud"
    },
    {
      "x": -15,
      "y": 26,
      "z": -17,
      "name": "Soil_Mud"
    },
    {
      "x": -15,
      "y": 27,
      "z": -17,
      "name": "Soil_Mud"
    },
    {
      "x": -15,
      "y": 28,
      "z": -17,
      "name": "Soil_Mud"
    },
    {
      "x": -15,
      "y": 21,
      "z": -16,
      "name": "Soil_Mud"
    },
    {
      "x": -15,
      "y": 22,
      "z": -16,
      "name": "Soil_Mud_Dry"
    },
    {
      "x": -15,
      "y": 23,
      "z": -16,
      "name": "Soil_Mud"
    },
    {
      "x": -15,
      "y": 24,
      "z": -16,
      "name": "Soil_Mud"
    },
    {
      "x": -15,
      "y": 25,
      "z": -16,
      "name": "Soil_Mud"
    },
    {
      "x": -15,
      "y": 26,
      "z": -16,
      "name": "Soil_Mud_Dry"
    },
    {
      "x": -15,
      "y": 27,
      "z": -16,
      "name": "Soil_Mud"
    },
    {
      "x": -15,
      "y": 28,
      "z": -16,
      "name": "Soil_Mud_Dry"
    },
    {
      "x": -15,
      "y": 29,
      "z": -16,
      "name": "Plant_Crop_Mushroom_Glowing_Violet"
    },
    {
      "x": -15,
      "y": 19,
      "z": -15,
      "name": "Plant_Crop_Mushroom_Shelve_Brown"
    },
    {
      "x": -15,
      "y": 20,
      "z": -15,
      "name": "Soil_Mud_Dry"
    },
    {
      "x": -15,
      "y": 21,
      "z": -15,
      "name": "Soil_Mud"
    },
    {
      "x": -15,
      "y": 22,
      "z": -15,
      "name": "Soil_Mud"
    },
    {
      "x": -15,
      "y": 23,
      "z": -15,
      "name": "Soil_Mud"
    },
    {
      "x": -15,
      "y": 24,
      "z": -15,
      "name": "Soil_Mud"
    },
    {
      "x": -15,
      "y": 25,
      "z": -15,
      "name": "Soil_Mud"
    },
    {
      "x": -15,
      "y": 26,
      "z": -15,
      "name": "Soil_Mud_Dry"
    },
    {
      "x": -15,
      "y": 27,
      "z": -15,
      "name": "Soil_Mud"
    },
    {
      "x": -15,
      "y": 28,
      "z": -15,
      "name": "Soil_Mud"
    },
    {
      "x": -15,
      "y": 29,
      "z": -15,
      "name": "Soil_Mud_Dry"
    },
    {
      "x": -15,
      "y": 19,
      "z": -14,
      "name": "Plant_Crop_Mushroom_Shelve_Brown"
    },
    {
      "x": -15,
      "y": 20,
      "z": -14,
      "name": "Soil_Mud_Dry"
    },
    {
      "x": -15,
      "y": 21,
      "z": -14,
      "name": "Soil_Mud_Dry"
    },
    {
      "x": -15,
      "y": 22,
      "z": -14,
      "name": "Soil_Mud"
    },
    {
      "x": -15,
      "y": 23,
      "z": -14,
      "name": "Soil_Mud_Dry"
    },
    {
      "x": -15,
      "y": 24,
      "z": -14,
      "name": "Soil_Mud_Dry"
    },
    {
      "x": -15,
      "y": 25,
      "z": -14,
      "name": "Soil_Mud"
    },
    {
      "x": -15,
      "y": 26,
      "z": -14,
      "name": "Soil_Mud"
    },
    {
      "x": -15,
      "y": 27,
      "z": -14,
      "name": "Soil_Mud_Dry"
    },
    {
      "x": -15,
      "y": 28,
      "z": -14,
      "name": "Soil_Mud_Dry"
    },
    {
      "x": -15,
      "y": 29,
      "z": -14,
      "name": "Soil_Mud_Dry"
    },
    {
      "x": -15,
      "y": 30,
      "z": -14,
      "name": "Plant_Grass_Cave_Short"
    },
    {
      "x": -15,
      "y": 19,
      "z": -13,
      "name": "Plant_Crop_Mushroom_Shelve_Brown"
    },
    {
      "x": -15,
      "y": 20,
      "z": -13,
      "name": "Soil_Mud"
    },
    {
      "x": -15,
      "y": 21,
      "z": -13,
      "name": "Soil_Mud"
    },
    {
      "x": -15,
      "y": 22,
      "z": -13,
      "name": "Soil_Mud"
    },
    {
      "x": -15,
      "y": 23,
      "z": -13,
      "name": "Soil_Mud"
    },
    {
      "x": -15,
      "y": 24,
      "z": -13,
      "name": "Soil_Mud"
    },
    {
      "x": -15,
      "y": 25,
      "z": -13,
      "name": "Soil_Mud"
    },
    {
      "x": -15,
      "y": 26,
      "z": -13,
      "name": "Soil_Mud"
    },
    {
      "x": -15,
      "y": 27,
      "z": -13,
      "name": "Soil_Mud"
    },
    {
      "x": -15,
      "y": 28,
      "z": -13,
      "name": "Soil_Mud"
    },
    {
      "x": -15,
      "y": 29,
      "z": -13,
      "name": "Soil_Mud_Dry"
    },
    {
      "x": -15,
      "y": 30,
      "z": -13,
      "name": "Soil_Mud_Dry"
    },
    {
      "x": -15,
      "y": 20,
      "z": -12,
      "name": "Plant_Crop_Mushroom_Shelve_Brown"
    },
    {
      "x": -15,
      "y": 21,
      "z": -12,
      "name": "Soil_Mud"
    },
    {
      "x": -15,
      "y": 22,
      "z": -12,
      "name": "Soil_Mud_Dry"
    },
    {
      "x": -15,
      "y": 23,
      "z": -12,
      "name": "Soil_Mud"
    },
    {
      "x": -15,
      "y": 24,
      "z": -12,
      "name": "Soil_Mud_Dry"
    },
    {
      "x": -15,
      "y": 25,
      "z": -12,
      "name": "Soil_Mud_Dry"
    },
    {
      "x": -15,
      "y": 26,
      "z": -12,
      "name": "Soil_Mud"
    },
    {
      "x": -15,
      "y": 27,
      "z": -12,
      "name": "Soil_Mud"
    },
    {
      "x": -15,
      "y": 28,
      "z": -12,
      "name": "Soil_Mud"
    },
    {
      "x": -15,
      "y": 29,
      "z": -12,
      "name": "Soil_Mud_Dry"
    },
    {
      "x": -15,
      "y": 30,
      "z": -12,
      "name": "Soil_Mud_Dry"
    },
    {
      "x": -15,
      "y": 22,
      "z": -11,
      "name": "Soil_Mud_Dry"
    },
    {
      "x": -15,
      "y": 23,
      "z": -11,
      "name": "Soil_Mud"
    },
    {
      "x": -15,
      "y": 24,
      "z": -11,
      "name": "Soil_Mud"
    },
    {
      "x": -15,
      "y": 25,
      "z": -11,
      "name": "Soil_Mud_Dry"
    },
    {
      "x": -15,
      "y": 26,
      "z": -11,
      "name": "Soil_Mud"
    },
    {
      "x": -15,
      "y": 27,
      "z": -11,
      "name": "Soil_Mud"
    },
    {
      "x": -15,
      "y": 28,
      "z": -11,
      "name": "Soil_Mud"
    },
    {
      "x": -15,
      "y": 29,
      "z": -11,
      "name": "Soil_Mud"
    },
    {
      "x": -15,
      "y": 30,
      "z": -11,
      "name": "Soil_Mud"
    },
    {
      "x": -15,
      "y": 31,
      "z": -11,
      "name": "Soil_Mud"
    },
    {
      "x": -15,
      "y": 22,
      "z": -10,
      "name": "Soil_Mud_Dry"
    },
    {
      "x": -15,
      "y": 23,
      "z": -10,
      "name": "Soil_Mud"
    },
    {
      "x": -15,
      "y": 24,
      "z": -10,
      "name": "Soil_Mud"
    },
    {
      "x": -15,
      "y": 25,
      "z": -10,
      "name": "Soil_Mud_Dry"
    },
    {
      "x": -15,
      "y": 26,
      "z": -10,
      "name": "Soil_Mud"
    },
    {
      "x": -15,
      "y": 27,
      "z": -10,
      "name": "Soil_Mud"
    },
    {
      "x": -15,
      "y": 28,
      "z": -10,
      "name": "Soil_Mud"
    },
    {
      "x": -15,
      "y": 29,
      "z": -10,
      "name": "Soil_Mud"
    },
    {
      "x": -15,
      "y": 30,
      "z": -10,
      "name": "Soil_Mud_Dry"
    },
    {
      "x": -15,
      "y": 31,
      "z": -10,
      "name": "Soil_Mud_Dry"
    },
    {
      "x": -15,
      "y": 32,
      "z": -10,
      "name": "Plant_Moss_Rug_Pink"
    },
    {
      "x": -15,
      "y": 22,
      "z": -9,
      "name": "Soil_Mud"
    },
    {
      "x": -15,
      "y": 23,
      "z": -9,
      "name": "Soil_Mud_Dry"
    },
    {
      "x": -15,
      "y": 24,
      "z": -9,
      "name": "Soil_Mud"
    },
    {
      "x": -15,
      "y": 25,
      "z": -9,
      "name": "Soil_Mud_Dry"
    },
    {
      "x": -15,
      "y": 26,
      "z": -9,
      "name": "Soil_Mud"
    },
    {
      "x": -15,
      "y": 27,
      "z": -9,
      "name": "Soil_Mud"
    },
    {
      "x": -15,
      "y": 28,
      "z": -9,
      "name": "Soil_Mud"
    },
    {
      "x": -15,
      "y": 29,
      "z": -9,
      "name": "Soil_Mud"
    },
    {
      "x": -15,
      "y": 30,
      "z": -9,
      "name": "Soil_Mud_Dry"
    },
    {
      "x": -15,
      "y": 31,
      "z": -9,
      "name": "Soil_Mud_Dry"
    },
    {
      "x": -15,
      "y": 22,
      "z": -8,
      "name": "Soil_Mud"
    },
    {
      "x": -15,
      "y": 23,
      "z": -8,
      "name": "Soil_Mud"
    },
    {
      "x": -15,
      "y": 24,
      "z": -8,
      "name": "Soil_Mud_Dry"
    },
    {
      "x": -15,
      "y": 25,
      "z": -8,
      "name": "Soil_Mud"
    },
    {
      "x": -15,
      "y": 26,
      "z": -8,
      "name": "Soil_Mud"
    },
    {
      "x": -15,
      "y": 27,
      "z": -8,
      "name": "Soil_Mud"
    },
    {
      "x": -15,
      "y": 28,
      "z": -8,
      "name": "Soil_Mud"
    },
    {
      "x": -15,
      "y": 29,
      "z": -8,
      "name": "Soil_Mud"
    },
    {
      "x": -15,
      "y": 30,
      "z": -8,
      "name": "Soil_Mud"
    },
    {
      "x": -15,
      "y": 31,
      "z": -8,
      "name": "Soil_Mud"
    },
    {
      "x": -15,
      "y": 32,
      "z": -8,
      "name": "Plant_Flower_Bushy_Purple"
    },
    {
      "x": -15,
      "y": 23,
      "z": -7,
      "name": "Soil_Mud_Dry"
    },
    {
      "x": -15,
      "y": 24,
      "z": -7,
      "name": "Soil_Mud"
    },
    {
      "x": -15,
      "y": 25,
      "z": -7,
      "name": "Soil_Mud"
    },
    {
      "x": -15,
      "y": 26,
      "z": -7,
      "name": "Soil_Mud_Dry"
    },
    {
      "x": -15,
      "y": 27,
      "z": -7,
      "name": "Soil_Mud"
    },
    {
      "x": -15,
      "y": 28,
      "z": -7,
      "name": "Soil_Mud_Dry"
    },
    {
      "x": -15,
      "y": 29,
      "z": -7,
      "name": "Soil_Mud"
    },
    {
      "x": -15,
      "y": 30,
      "z": -7,
      "name": "Soil_Mud"
    },
    {
      "x": -15,
      "y": 31,
      "z": -7,
      "name": "Soil_Mud_Dry"
    },
    {
      "x": -15,
      "y": 24,
      "z": -6,
      "name": "Soil_Mud"
    },
    {
      "x": -15,
      "y": 25,
      "z": -6,
      "name": "Soil_Mud"
    },
    {
      "x": -15,
      "y": 26,
      "z": -6,
      "name": "Soil_Mud"
    },
    {
      "x": -15,
      "y": 27,
      "z": -6,
      "name": "Soil_Mud"
    },
    {
      "x": -15,
      "y": 28,
      "z": -6,
      "name": "Ore_Thorium_Mud"
    },
    {
      "x": -15,
      "y": 29,
      "z": -6,
      "name": "Ore_Thorium_Mud_Cracked"
    },
    {
      "x": -15,
      "y": 30,
      "z": -6,
      "name": "Soil_Mud"
    },
    {
      "x": -15,
      "y": 31,
      "z": -6,
      "name": "Soil_Mud_Dry"
    },
    {
      "x": -15,
      "y": 26,
      "z": -5,
      "name": "Soil_Mud"
    },
    {
      "x": -15,
      "y": 27,
      "z": -5,
      "name": "Soil_Mud"
    },
    {
      "x": -15,
      "y": 28,
      "z": -5,
      "name": "Soil_Mud_Dry"
    },
    {
      "x": -15,
      "y": 29,
      "z": -5,
      "name": "Soil_Mud_Dry"
    },
    {
      "x": -15,
      "y": 30,
      "z": -5,
      "name": "Soil_Mud"
    },
    {
      "x": -15,
      "y": 31,
      "z": -5,
      "name": "Soil_Mud"
    },
    {
      "x": -15,
      "y": 26,
      "z": -4,
      "name": "Plant_Crop_Mushroom_Shelve_Brown"
    },
    {
      "x": -15,
      "y": 31,
      "z": -4,
      "name": "Soil_Mud"
    },
    {
      "x": -15,
      "y": 27,
      "z": 2,
      "name": "Soil_Mud"
    },
    {
      "x": -15,
      "y": 28,
      "z": 2,
      "name": "Soil_Mud"
    },
    {
      "x": -15,
      "y": 21,
      "z": 3,
      "name": "Soil_Mud"
    },
    {
      "x": -15,
      "y": 22,
      "z": 3,
      "name": "Soil_Mud"
    },
    {
      "x": -15,
      "y": 23,
      "z": 3,
      "name": "Soil_Mud"
    },
    {
      "x": -15,
      "y": 24,
      "z": 3,
      "name": "Soil_Mud"
    },
    {
      "x": -15,
      "y": 25,
      "z": 3,
      "name": "Soil_Mud_Dry"
    },
    {
      "x": -15,
      "y": 26,
      "z": 3,
      "name": "Soil_Mud"
    },
    {
      "x": -15,
      "y": 27,
      "z": 3,
      "name": "Soil_Mud"
    },
    {
      "x": -15,
      "y": 28,
      "z": 3,
      "name": "Soil_Mud_Dry"
    },
    {
      "x": -15,
      "y": 48,
      "z": 3,
      "name": "Plant_Crop_Mushroom_Block_Purple"
    },
    {
      "x": -15,
      "y": 20,
      "z": 4,
      "name": "Soil_Mud_Dry"
    },
    {
      "x": -15,
      "y": 21,
      "z": 4,
      "name": "Soil_Mud_Dry"
    },
    {
      "x": -15,
      "y": 22,
      "z": 4,
      "name": "Soil_Mud_Dry"
    },
    {
      "x": -15,
      "y": 23,
      "z": 4,
      "name": "Soil_Mud"
    },
    {
      "x": -15,
      "y": 24,
      "z": 4,
      "name": "Soil_Mud_Dry"
    },
    {
      "x": -15,
      "y": 25,
      "z": 4,
      "name": "Soil_Mud_Dry"
    },
    {
      "x": -15,
      "y": 26,
      "z": 4,
      "name": "Soil_Mud"
    },
    {
      "x": -15,
      "y": 27,
      "z": 4,
      "name": "Soil_Mud"
    },
    {
      "x": -15,
      "y": 28,
      "z": 4,
      "name": "Soil_Mud"
    },
    {
      "x": -15,
      "y": 48,
      "z": 4,
      "name": "Plant_Crop_Mushroom_Block_Purple"
    },
    {
      "x": -15,
      "y": 20,
      "z": 5,
      "name": "Soil_Mud_Dry"
    },
    {
      "x": -15,
      "y": 21,
      "z": 5,
      "name": "Soil_Mud"
    },
    {
      "x": -15,
      "y": 22,
      "z": 5,
      "name": "Soil_Mud"
    },
    {
      "x": -15,
      "y": 23,
      "z": 5,
      "name": "Soil_Mud"
    },
    {
      "x": -15,
      "y": 24,
      "z": 5,
      "name": "Soil_Mud"
    },
    {
      "x": -15,
      "y": 25,
      "z": 5,
      "name": "Soil_Mud"
    },
    {
      "x": -15,
      "y": 26,
      "z": 5,
      "name": "Soil_Mud_Dry"
    },
    {
      "x": -15,
      "y": 27,
      "z": 5,
      "name": "Soil_Mud_Dry"
    },
    {
      "x": -15,
      "y": 28,
      "z": 5,
      "name": "Soil_Mud_Dry"
    },
    {
      "x": -15,
      "y": 48,
      "z": 5,
      "name": "Plant_Crop_Mushroom_Block_Purple"
    },
    {
      "x": -15,
      "y": 19,
      "z": 6,
      "name": "Soil_Mud"
    },
    {
      "x": -15,
      "y": 20,
      "z": 6,
      "name": "Soil_Mud"
    },
    {
      "x": -15,
      "y": 21,
      "z": 6,
      "name": "Soil_Mud_Dry"
    },
    {
      "x": -15,
      "y": 22,
      "z": 6,
      "name": "Soil_Mud"
    },
    {
      "x": -15,
      "y": 23,
      "z": 6,
      "name": "Soil_Mud"
    },
    {
      "x": -15,
      "y": 24,
      "z": 6,
      "name": "Soil_Mud_Dry"
    },
    {
      "x": -15,
      "y": 25,
      "z": 6,
      "name": "Soil_Mud_Dry"
    },
    {
      "x": -15,
      "y": 26,
      "z": 6,
      "name": "Soil_Mud"
    },
    {
      "x": -15,
      "y": 27,
      "z": 6,
      "name": "Soil_Mud_Dry"
    },
    {
      "x": -15,
      "y": 28,
      "z": 6,
      "name": "Soil_Mud"
    },
    {
      "x": -15,
      "y": 48,
      "z": 6,
      "name": "Plant_Crop_Mushroom_Block_Purple"
    },
    {
      "x": -15,
      "y": 19,
      "z": 7,
      "name": "Soil_Mud"
    },
    {
      "x": -15,
      "y": 20,
      "z": 7,
      "name": "Soil_Mud"
    },
    {
      "x": -15,
      "y": 21,
      "z": 7,
      "name": "Soil_Mud_Dry"
    },
    {
      "x": -15,
      "y": 22,
      "z": 7,
      "name": "Soil_Mud"
    },
    {
      "x": -15,
      "y": 23,
      "z": 7,
      "name": "Soil_Mud_Dry"
    },
    {
      "x": -15,
      "y": 24,
      "z": 7,
      "name": "Soil_Mud_Dry"
    },
    {
      "x": -15,
      "y": 25,
      "z": 7,
      "name": "Soil_Mud_Dry"
    },
    {
      "x": -15,
      "y": 26,
      "z": 7,
      "name": "Soil_Mud"
    },
    {
      "x": -15,
      "y": 27,
      "z": 7,
      "name": "Soil_Mud_Dry"
    },
    {
      "x": -15,
      "y": 28,
      "z": 7,
      "name": "Soil_Mud_Dry"
    },
    {
      "x": -15,
      "y": 48,
      "z": 7,
      "name": "Plant_Crop_Mushroom_Block_Purple"
    },
    {
      "x": -15,
      "y": 18,
      "z": 8,
      "name": "Soil_Mud_Dry"
    },
    {
      "x": -15,
      "y": 19,
      "z": 8,
      "name": "Soil_Mud"
    },
    {
      "x": -15,
      "y": 20,
      "z": 8,
      "name": "Soil_Mud"
    },
    {
      "x": -15,
      "y": 21,
      "z": 8,
      "name": "Soil_Mud"
    },
    {
      "x": -15,
      "y": 22,
      "z": 8,
      "name": "Soil_Mud"
    },
    {
      "x": -15,
      "y": 23,
      "z": 8,
      "name": "Soil_Mud"
    },
    {
      "x": -15,
      "y": 24,
      "z": 8,
      "name": "Soil_Mud"
    },
    {
      "x": -15,
      "y": 25,
      "z": 8,
      "name": "Soil_Mud_Dry"
    },
    {
      "x": -15,
      "y": 26,
      "z": 8,
      "name": "Soil_Mud"
    },
    {
      "x": -15,
      "y": 27,
      "z": 8,
      "name": "Soil_Mud"
    },
    {
      "x": -15,
      "y": 28,
      "z": 8,
      "name": "Soil_Mud_Dry"
    },
    {
      "x": -15,
      "y": 48,
      "z": 8,
      "name": "Plant_Crop_Mushroom_Block_Purple"
    },
    {
      "x": -15,
      "y": 16,
      "z": 9,
      "name": "Soil_Mud_Dry"
    },
    {
      "x": -15,
      "y": 17,
      "z": 9,
      "name": "Soil_Mud"
    },
    {
      "x": -15,
      "y": 18,
      "z": 9,
      "name": "Soil_Mud"
    },
    {
      "x": -15,
      "y": 19,
      "z": 9,
      "name": "Soil_Mud"
    },
    {
      "x": -15,
      "y": 20,
      "z": 9,
      "name": "Soil_Mud"
    },
    {
      "x": -15,
      "y": 21,
      "z": 9,
      "name": "Soil_Mud"
    },
    {
      "x": -15,
      "y": 22,
      "z": 9,
      "name": "Soil_Mud"
    },
    {
      "x": -15,
      "y": 23,
      "z": 9,
      "name": "Soil_Mud"
    },
    {
      "x": -15,
      "y": 24,
      "z": 9,
      "name": "Soil_Mud_Dry"
    },
    {
      "x": -15,
      "y": 25,
      "z": 9,
      "name": "Soil_Mud"
    },
    {
      "x": -15,
      "y": 26,
      "z": 9,
      "name": "Soil_Mud"
    },
    {
      "x": -15,
      "y": 27,
      "z": 9,
      "name": "Soil_Mud"
    },
    {
      "x": -15,
      "y": 28,
      "z": 9,
      "name": "Soil_Mud"
    },
    {
      "x": -15,
      "y": 48,
      "z": 9,
      "name": "Plant_Crop_Mushroom_Block_Purple"
    },
    {
      "x": -15,
      "y": 15,
      "z": 10,
      "name": "Soil_Mud"
    },
    {
      "x": -15,
      "y": 16,
      "z": 10,
      "name": "Soil_Mud"
    },
    {
      "x": -15,
      "y": 17,
      "z": 10,
      "name": "Soil_Mud_Dry"
    },
    {
      "x": -15,
      "y": 18,
      "z": 10,
      "name": "Soil_Mud"
    },
    {
      "x": -15,
      "y": 19,
      "z": 10,
      "name": "Soil_Mud"
    },
    {
      "x": -15,
      "y": 20,
      "z": 10,
      "name": "Soil_Mud"
    },
    {
      "x": -15,
      "y": 21,
      "z": 10,
      "name": "Soil_Mud_Dry"
    },
    {
      "x": -15,
      "y": 22,
      "z": 10,
      "name": "Soil_Mud"
    },
    {
      "x": -15,
      "y": 23,
      "z": 10,
      "name": "Soil_Mud_Dry"
    },
    {
      "x": -15,
      "y": 24,
      "z": 10,
      "name": "Soil_Mud"
    },
    {
      "x": -15,
      "y": 25,
      "z": 10,
      "name": "Soil_Mud_Dry"
    },
    {
      "x": -15,
      "y": 26,
      "z": 10,
      "name": "Soil_Mud"
    },
    {
      "x": -15,
      "y": 27,
      "z": 10,
      "name": "Soil_Mud"
    },
    {
      "x": -15,
      "y": 28,
      "z": 10,
      "name": "Soil_Mud"
    },
    {
      "x": -15,
      "y": 29,
      "z": 10,
      "name": "Soil_Mud"
    },
    {
      "x": -15,
      "y": 48,
      "z": 10,
      "name": "Plant_Crop_Mushroom_Block_Purple"
    },
    {
      "x": -15,
      "y": 15,
      "z": 11,
      "name": "Soil_Mud"
    },
    {
      "x": -15,
      "y": 16,
      "z": 11,
      "name": "Soil_Mud"
    },
    {
      "x": -15,
      "y": 17,
      "z": 11,
      "name": "Soil_Mud"
    },
    {
      "x": -15,
      "y": 18,
      "z": 11,
      "name": "Soil_Mud"
    },
    {
      "x": -15,
      "y": 19,
      "z": 11,
      "name": "Soil_Mud_Dry"
    },
    {
      "x": -15,
      "y": 20,
      "z": 11,
      "name": "Soil_Mud_Dry"
    },
    {
      "x": -15,
      "y": 21,
      "z": 11,
      "name": "Soil_Mud"
    },
    {
      "x": -15,
      "y": 22,
      "z": 11,
      "name": "Soil_Mud"
    },
    {
      "x": -15,
      "y": 23,
      "z": 11,
      "name": "Soil_Mud"
    },
    {
      "x": -15,
      "y": 24,
      "z": 11,
      "name": "Soil_Mud"
    },
    {
      "x": -15,
      "y": 25,
      "z": 11,
      "name": "Soil_Mud_Dry"
    },
    {
      "x": -15,
      "y": 26,
      "z": 11,
      "name": "Soil_Mud"
    },
    {
      "x": -15,
      "y": 27,
      "z": 11,
      "name": "Soil_Mud"
    },
    {
      "x": -15,
      "y": 28,
      "z": 11,
      "name": "Soil_Mud"
    },
    {
      "x": -15,
      "y": 29,
      "z": 11,
      "name": "Soil_Mud"
    },
    {
      "x": -15,
      "y": 48,
      "z": 11,
      "name": "Plant_Crop_Mushroom_Block_Purple"
    },
    {
      "x": -15,
      "y": 14,
      "z": 12,
      "name": "Soil_Mud_Dry"
    },
    {
      "x": -15,
      "y": 15,
      "z": 12,
      "name": "Soil_Mud_Dry"
    },
    {
      "x": -15,
      "y": 16,
      "z": 12,
      "name": "Soil_Mud"
    },
    {
      "x": -15,
      "y": 17,
      "z": 12,
      "name": "Soil_Mud_Dry"
    },
    {
      "x": -15,
      "y": 18,
      "z": 12,
      "name": "Soil_Mud"
    },
    {
      "x": -15,
      "y": 19,
      "z": 12,
      "name": "Soil_Mud_Dry"
    },
    {
      "x": -15,
      "y": 20,
      "z": 12,
      "name": "Ore_Thorium_Mud_Cracked"
    },
    {
      "x": -15,
      "y": 21,
      "z": 12,
      "name": "Soil_Mud"
    },
    {
      "x": -15,
      "y": 22,
      "z": 12,
      "name": "Soil_Mud"
    },
    {
      "x": -15,
      "y": 23,
      "z": 12,
      "name": "Soil_Mud"
    },
    {
      "x": -15,
      "y": 24,
      "z": 12,
      "name": "Soil_Mud"
    },
    {
      "x": -15,
      "y": 25,
      "z": 12,
      "name": "Soil_Mud_Dry"
    },
    {
      "x": -15,
      "y": 26,
      "z": 12,
      "name": "Soil_Mud"
    },
    {
      "x": -15,
      "y": 27,
      "z": 12,
      "name": "Soil_Mud_Dry"
    },
    {
      "x": -15,
      "y": 28,
      "z": 12,
      "name": "Soil_Mud_Dry"
    },
    {
      "x": -15,
      "y": 29,
      "z": 12,
      "name": "Soil_Mud"
    },
    {
      "x": -15,
      "y": 48,
      "z": 12,
      "name": "Plant_Crop_Mushroom_Block_Purple"
    },
    {
      "x": -15,
      "y": 14,
      "z": 13,
      "name": "Soil_Mud"
    },
    {
      "x": -15,
      "y": 15,
      "z": 13,
      "name": "Soil_Mud"
    },
    {
      "x": -15,
      "y": 16,
      "z": 13,
      "name": "Soil_Mud_Dry"
    },
    {
      "x": -15,
      "y": 17,
      "z": 13,
      "name": "Soil_Mud"
    },
    {
      "x": -15,
      "y": 18,
      "z": 13,
      "name": "Soil_Mud_Dry"
    },
    {
      "x": -15,
      "y": 19,
      "z": 13,
      "name": "Ore_Thorium_Mud"
    },
    {
      "x": -15,
      "y": 20,
      "z": 13,
      "name": "Ore_Thorium_Mud_Cracked"
    },
    {
      "x": -15,
      "y": 21,
      "z": 13,
      "name": "Soil_Mud"
    },
    {
      "x": -15,
      "y": 22,
      "z": 13,
      "name": "Soil_Mud"
    },
    {
      "x": -15,
      "y": 23,
      "z": 13,
      "name": "Soil_Mud_Dry"
    },
    {
      "x": -15,
      "y": 24,
      "z": 13,
      "name": "Soil_Mud"
    },
    {
      "x": -15,
      "y": 25,
      "z": 13,
      "name": "Soil_Mud"
    },
    {
      "x": -15,
      "y": 26,
      "z": 13,
      "name": "Soil_Mud_Dry"
    },
    {
      "x": -15,
      "y": 27,
      "z": 13,
      "name": "Soil_Mud_Dry"
    },
    {
      "x": -15,
      "y": 28,
      "z": 13,
      "name": "Soil_Mud"
    },
    {
      "x": -15,
      "y": 29,
      "z": 13,
      "name": "Soil_Mud_Dry"
    },
    {
      "x": -15,
      "y": 30,
      "z": 13,
      "name": "Soil_Mud"
    },
    {
      "x": -15,
      "y": 48,
      "z": 13,
      "name": "Plant_Crop_Mushroom_Block_Purple"
    },
    {
      "x": -15,
      "y": 14,
      "z": 14,
      "name": "Soil_Mud"
    },
    {
      "x": -15,
      "y": 15,
      "z": 14,
      "name": "Soil_Mud"
    },
    {
      "x": -15,
      "y": 16,
      "z": 14,
      "name": "Soil_Mud_Dry"
    },
    {
      "x": -15,
      "y": 17,
      "z": 14,
      "name": "Soil_Mud"
    },
    {
      "x": -15,
      "y": 18,
      "z": 14,
      "name": "Soil_Mud_Dry"
    },
    {
      "x": -15,
      "y": 19,
      "z": 14,
      "name": "Soil_Mud_Dry"
    },
    {
      "x": -15,
      "y": 20,
      "z": 14,
      "name": "Soil_Mud"
    },
    {
      "x": -15,
      "y": 21,
      "z": 14,
      "name": "Soil_Mud_Dry"
    },
    {
      "x": -15,
      "y": 22,
      "z": 14,
      "name": "Soil_Mud_Dry"
    },
    {
      "x": -15,
      "y": 23,
      "z": 14,
      "name": "Soil_Mud"
    },
    {
      "x": -15,
      "y": 24,
      "z": 14,
      "name": "Soil_Mud"
    },
    {
      "x": -15,
      "y": 25,
      "z": 14,
      "name": "Soil_Mud_Dry"
    },
    {
      "x": -15,
      "y": 26,
      "z": 14,
      "name": "Soil_Mud"
    },
    {
      "x": -15,
      "y": 27,
      "z": 14,
      "name": "Soil_Mud"
    },
    {
      "x": -15,
      "y": 28,
      "z": 14,
      "name": "Soil_Mud"
    },
    {
      "x": -15,
      "y": 29,
      "z": 14,
      "name": "Soil_Mud_Dry"
    },
    {
      "x": -15,
      "y": 30,
      "z": 14,
      "name": "Soil_Mud_Dry"
    },
    {
      "x": -15,
      "y": 12,
      "z": 15,
      "name": "Soil_Mud"
    },
    {
      "x": -15,
      "y": 13,
      "z": 15,
      "name": "Soil_Mud"
    },
    {
      "x": -15,
      "y": 14,
      "z": 15,
      "name": "Soil_Mud"
    },
    {
      "x": -15,
      "y": 15,
      "z": 15,
      "name": "Soil_Mud_Dry"
    },
    {
      "x": -15,
      "y": 16,
      "z": 15,
      "name": "Soil_Mud"
    },
    {
      "x": -15,
      "y": 17,
      "z": 15,
      "name": "Soil_Mud"
    },
    {
      "x": -15,
      "y": 18,
      "z": 15,
      "name": "Soil_Mud"
    },
    {
      "x": -15,
      "y": 19,
      "z": 15,
      "name": "Soil_Mud_Dry"
    },
    {
      "x": -15,
      "y": 20,
      "z": 15,
      "name": "Soil_Mud"
    },
    {
      "x": -15,
      "y": 21,
      "z": 15,
      "name": "Soil_Mud_Dry"
    },
    {
      "x": -15,
      "y": 22,
      "z": 15,
      "name": "Soil_Mud_Dry"
    },
    {
      "x": -15,
      "y": 23,
      "z": 15,
      "name": "Soil_Mud"
    },
    {
      "x": -15,
      "y": 24,
      "z": 15,
      "name": "Soil_Mud_Dry"
    },
    {
      "x": -15,
      "y": 25,
      "z": 15,
      "name": "Soil_Mud"
    },
    {
      "x": -15,
      "y": 26,
      "z": 15,
      "name": "Soil_Mud"
    },
    {
      "x": -15,
      "y": 27,
      "z": 15,
      "name": "Soil_Mud"
    },
    {
      "x": -15,
      "y": 28,
      "z": 15,
      "name": "Soil_Mud"
    },
    {
      "x": -15,
      "y": 29,
      "z": 15,
      "name": "Soil_Mud_Dry"
    },
    {
      "x": -15,
      "y": 30,
      "z": 15,
      "name": "Soil_Mud"
    },
    {
      "x": -15,
      "y": 14,
      "z": 16,
      "name": "Soil_Mud"
    },
    {
      "x": -15,
      "y": 15,
      "z": 16,
      "name": "Soil_Mud_Dry"
    },
    {
      "x": -15,
      "y": 16,
      "z": 16,
      "name": "Soil_Mud"
    },
    {
      "x": -15,
      "y": 17,
      "z": 16,
      "name": "Soil_Mud"
    },
    {
      "x": -15,
      "y": 18,
      "z": 16,
      "name": "Soil_Mud"
    },
    {
      "x": -15,
      "y": 19,
      "z": 16,
      "name": "Soil_Mud_Dry"
    },
    {
      "x": -15,
      "y": 20,
      "z": 16,
      "name": "Soil_Mud_Dry"
    },
    {
      "x": -15,
      "y": 21,
      "z": 16,
      "name": "Soil_Mud"
    },
    {
      "x": -15,
      "y": 22,
      "z": 16,
      "name": "Soil_Mud"
    },
    {
      "x": -15,
      "y": 23,
      "z": 16,
      "name": "Soil_Mud"
    },
    {
      "x": -15,
      "y": 24,
      "z": 16,
      "name": "Soil_Mud"
    },
    {
      "x": -15,
      "y": 25,
      "z": 16,
      "name": "Soil_Mud"
    },
    {
      "x": -15,
      "y": 26,
      "z": 16,
      "name": "Soil_Mud_Dry"
    },
    {
      "x": -15,
      "y": 27,
      "z": 16,
      "name": "Soil_Mud"
    },
    {
      "x": -15,
      "y": 28,
      "z": 16,
      "name": "Soil_Mud"
    },
    {
      "x": -15,
      "y": 29,
      "z": 16,
      "name": "Soil_Mud_Dry"
    },
    {
      "x": -15,
      "y": 30,
      "z": 16,
      "name": "Soil_Mud_Dry"
    },
    {
      "x": -15,
      "y": 13,
      "z": 17,
      "name": "Soil_Mud_Dry"
    },
    {
      "x": -15,
      "y": 14,
      "z": 17,
      "name": "Soil_Mud"
    },
    {
      "x": -15,
      "y": 15,
      "z": 17,
      "name": "Soil_Mud_Dry"
    },
    {
      "x": -15,
      "y": 16,
      "z": 17,
      "name": "Soil_Mud_Dry"
    },
    {
      "x": -15,
      "y": 17,
      "z": 17,
      "name": "Soil_Mud_Dry"
    },
    {
      "x": -15,
      "y": 18,
      "z": 17,
      "name": "Soil_Mud"
    },
    {
      "x": -15,
      "y": 19,
      "z": 17,
      "name": "Soil_Mud"
    },
    {
      "x": -15,
      "y": 20,
      "z": 17,
      "name": "Soil_Mud"
    },
    {
      "x": -15,
      "y": 21,
      "z": 17,
      "name": "Soil_Mud_Dry"
    },
    {
      "x": -15,
      "y": 22,
      "z": 17,
      "name": "Soil_Mud"
    },
    {
      "x": -15,
      "y": 23,
      "z": 17,
      "name": "Soil_Mud"
    },
    {
      "x": -15,
      "y": 24,
      "z": 17,
      "name": "Soil_Mud_Dry"
    },
    {
      "x": -15,
      "y": 25,
      "z": 17,
      "name": "Soil_Mud"
    },
    {
      "x": -15,
      "y": 26,
      "z": 17,
      "name": "Soil_Mud_Dry"
    },
    {
      "x": -15,
      "y": 27,
      "z": 17,
      "name": "Soil_Mud"
    },
    {
      "x": -15,
      "y": 28,
      "z": 17,
      "name": "Soil_Mud"
    },
    {
      "x": -15,
      "y": 29,
      "z": 17,
      "name": "Soil_Mud"
    },
    {
      "x": -15,
      "y": 30,
      "z": 17,
      "name": "Soil_Mud"
    },
    {
      "x": -15,
      "y": 13,
      "z": 18,
      "name": "Soil_Mud"
    },
    {
      "x": -15,
      "y": 14,
      "z": 18,
      "name": "Soil_Mud"
    },
    {
      "x": -15,
      "y": 15,
      "z": 18,
      "name": "Soil_Mud_Dry"
