{
  "version": 8,
  "blockIdVersion": 11,
  "anchorX": 0,
  "anchorY": 0,
  "anchorZ": 0,
  "blocks": [
    {
      "x": -18,
      "y": 32,
      "z": 0,
      "name": "Soil_Mud"
    },
    {
      "x": -18,
      "y": 31,
      "z": 1,
      "name": "Soil_Mud_Dry"
    },
    {
      "x": -18,
      "y": 32,
      "z": 1,
      "name": "Soil_Mud"
    },
    {
      "x": -17,
      "y": 30,
      "z": -2,
      "name": "Soil_Mud"
    },
    {
      "x": -17,
      "y": 27,
      "z": -1,
      "name": "Soil_Mud"
    },
    {
      "x": -17,
      "y": 28,
      "z": -1,
      "name": "Soil_Mud"
    },
    {
      "x": -17,
      "y": 29,
      "z": -1,
      "name": "Soil_Mud_Dry"
    },
    {
      "x": -17,
      "y": 30,
      "z": -1,
      "name": "Soil_Mud"
    },
    {
      "x": -17,
      "y": 31,
      "z": -1,
      "name": "Soil_Mud"
    },
    {
      "x": -17,
      "y": 32,
      "z": -1,
      "name": "Soil_Mud"
    },
    {
      "x": -17,
      "y": 33,
      "z": -1,
      "name": "Soil_Mud"
    },
    {
      "x": -17,
      "y": 25,
      "z": 0,
      "name": "Soil_Mud"
    },
    {
      "x": -17,
      "y": 26,
      "z": 0,
      "name": "Soil_Mud_Dry"
    },
    {
      "x": -17,
      "y": 27,
      "z": 0,
      "name": "Soil_Mud"
    },
    {
      "x": -17,
      "y": 28,
      "z": 0,
      "name": "Soil_Mud_Dry"
    },
    {
      "x": -17,
      "y": 29,
      "z": 0,
      "name": "Soil_Mud"
    },
    {
      "x": -17,
      "y": 30,
      "z": 0,
      "name": "Soil_Mud"
    },
    {
      "x": -17,
      "y": 31,
      "z": 0,
      "name": "Soil_Mud"
    },
    {
      "x": -17,
      "y": 32,
      "z": 0,
      "name": "Soil_Mud"
    },
    {
      "x": -17,
      "y": 33,
      "z": 0,
      "name": "Soil_Mud_Dry"
    },
    {
      "x": -17,
      "y": 27,
      "z": 1,
      "name": "Soil_Mud_Dry"
    },
    {
      "x": -17,
      "y": 28,
      "z": 1,
      "name": "Soil_Mud_Dry"
    },
    {
      "x": -17,
      "y": 29,
      "z": 1,
      "name": "Soil_Mud"
    },
    {
      "x": -17,
      "y": 30,
      "z": 1,
      "name": "Soil_Mud_Dry"
    },
    {
      "x": -17,
      "y": 31,
      "z": 1,
      "name": "Soil_Mud"
    },
    {
      "x": -17,
      "y": 32,
      "z": 1,
      "name": "Soil_Mud_Dry"
    },
    {
      "x": -17,
      "y": 33,
      "z": 1,
      "name": "Soil_Mud_Dry"
    },
    {
      "x": -17,
      "y": 34,
      "z": 1,
      "name": "Soil_Mud"
    },
    {
      "x": -17,
      "y": 28,
      "z": 2,
      "name": "Soil_Mud"
    },
    {
      "x": -17,
      "y": 29,
      "z": 2,
      "name": "Soil_Mud_Dry"
    },
    {
      "x": -17,
      "y": 30,
      "z": 2,
      "name": "Soil_Mud"
    },
    {
      "x": -17,
      "y": 31,
      "z": 2,
      "name": "Soil_Mud"
    },
    {
      "x": -17,
      "y": 32,
      "z": 2,
      "name": "Soil_Mud"
    },
    {
      "x": -17,
      "y": 33,
      "z": 2,
      "name": "Soil_Mud"
    },
    {
      "x": -17,
      "y": 34,
      "z": 2,
      "name": "Soil_Mud"
    },
    {
      "x": -17,
      "y": 31,
      "z": 3,
      "name": "Soil_Mud"
    },
    {
      "x": -17,
      "y": 32,
      "z": 3,
      "name": "Soil_Mud"
    },
    {
      "x": -17,
      "y": 33,
      "z": 3,
      "name": "Soil_Mud"
    },
    {
      "x": -17,
      "y": 34,
      "z": 3,
      "name": "Soil_Mud"
    },
    {
      "x": -17,
      "y": 35,
      "z": 3,
      "name": "Soil_Mud"
    },
    {
      "x": -17,
      "y": 32,
      "z": 4,
      "name": "Soil_Mud_Dry"
    },
    {
      "x": -17,
      "y": 33,
      "z": 4,
      "name": "Soil_Mud"
    },
    {
      "x": -17,
      "y": 34,
      "z": 4,
      "name": "Soil_Mud_Dry"
    },
    {
      "x": -17,
      "y": 35,
      "z": 4,
      "name": "Soil_Mud"
    },
    {
      "x": -17,
      "y": 36,
      "z": 4,
      "name": "Soil_Mud"
    },
    {
      "x": -17,
      "y": 31,
      "z": 5,
      "name": "Soil_Mud_Dry"
    },
    {
      "x": -17,
      "y": 32,
      "z": 5,
      "name": "Soil_Mud"
    },
    {
      "x": -17,
      "y": 33,
      "z": 5,
      "name": "Soil_Mud"
    },
    {
      "x": -17,
      "y": 34,
      "z": 5,
      "name": "Soil_Mud"
    },
    {
      "x": -17,
      "y": 35,
      "z": 5,
      "name": "Soil_Mud"
    },
    {
      "x": -17,
      "y": 36,
      "z": 5,
      "name": "Soil_Mud"
    },
    {
      "x": -17,
      "y": 37,
      "z": 5,
      "name": "Soil_Mud"
    },
    {
      "x": -17,
      "y": 32,
      "z": 6,
      "name": "Soil_Mud"
    },
    {
      "x": -17,
      "y": 33,
      "z": 6,
      "name": "Soil_Mud_Dry"
    },
    {
      "x": -17,
      "y": 34,
      "z": 6,
      "name": "Soil_Mud"
    },
    {
      "x": -17,
      "y": 35,
      "z": 6,
      "name": "Soil_Mud"
    },
    {
      "x": -17,
      "y": 36,
      "z": 6,
      "name": "Soil_Mud"
    },
    {
      "x": -17,
      "y": 37,
      "z": 6,
      "name": "Soil_Mud_Dry"
    },
    {
      "x": -17,
      "y": 33,
      "z": 7,
      "name": "Soil_Mud_Dry"
    },
    {
      "x": -17,
      "y": 34,
      "z": 7,
      "name": "Soil_Mud"
    },
    {
      "x": -17,
      "y": 35,
      "z": 7,
      "name": "Soil_Mud"
    },
    {
      "x": -17,
      "y": 36,
      "z": 7,
      "name": "Soil_Mud"
    },
    {
      "x": -16,
      "y": 28,
      "z": -3,
      "name": "Soil_Mud"
    },
    {
      "x": -16,
      "y": 26,
      "z": -2,
      "name": "Plant_Moss_Cave_Red"
    },
    {
      "x": -16,
      "y": 27,
      "z": -2,
      "name": "Soil_Mud_Dry"
    },
    {
      "x": -16,
      "y": 28,
      "z": -2,
      "name": "Soil_Mud"
    },
    {
      "x": -16,
      "y": 29,
      "z": -2,
      "name": "Soil_Mud"
    },
    {
      "x": -16,
      "y": 30,
      "z": -2,
      "name": "Soil_Mud"
    },
    {
      "x": -16,
      "y": 31,
      "z": -2,
      "name": "Soil_Mud"
    },
    {
      "x": -16,
      "y": 32,
      "z": -2,
      "name": "Soil_Mud_Dry"
    },
    {
      "x": -16,
      "y": 33,
      "z": -2,
      "name": "Soil_Mud"
    },
    {
      "x": -16,
      "y": 26,
      "z": -1,
      "name": "Soil_Mud"
    },
    {
      "x": -16,
      "y": 27,
      "z": -1,
      "name": "Soil_Mud_Dry"
    },
    {
      "x": -16,
      "y": 28,
      "z": -1,
      "name": "Soil_Mud_Dry"
    },
    {
      "x": -16,
      "y": 29,
      "z": -1,
      "name": "Soil_Mud"
    },
    {
      "x": -16,
      "y": 30,
      "z": -1,
      "name": "Soil_Mud_Dry"
    },
    {
      "x": -16,
      "y": 31,
      "z": -1,
      "name": "Soil_Mud"
    },
    {
      "x": -16,
      "y": 32,
      "z": -1,
      "name": "Soil_Mud_Dry"
    },
    {
      "x": -16,
      "y": 33,
      "z": -1,
      "name": "Soil_Mud_Dry"
    },
    {
      "x": -16,
      "y": 34,
      "z": -1,
      "name": "Soil_Mud"
    },
    {
      "x": -16,
      "y": 25,
      "z": 0,
      "name": "Plant_Moss_Cave_Red"
    },
    {
      "x": -16,
      "y": 26,
      "z": 0,
      "name": "Soil_Mud"
    },
    {
      "x": -16,
      "y": 27,
      "z": 0,
      "name": "Soil_Mud"
    },
    {
      "x": -16,
      "y": 28,
      "z": 0,
      "name": "Soil_Mud"
    },
    {
      "x": -16,
      "y": 29,
      "z": 0,
      "name": "Soil_Mud"
    },
    {
      "x": -16,
      "y": 30,
      "z": 0,
      "name": "Soil_Mud"
    },
    {
      "x": -16,
      "y": 31,
      "z": 0,
      "name": "Soil_Mud"
    },
    {
      "x": -16,
      "y": 32,
      "z": 0,
      "name": "Soil_Mud"
    },
    {
      "x": -16,
      "y": 33,
      "z": 0,
      "name": "Soil_Mud_Dry"
    },
    {
      "x": -16,
      "y": 34,
      "z": 0,
      "name": "Soil_Mud_Dry"
    },
    {
      "x": -16,
      "y": 26,
      "z": 1,
      "name": "Soil_Mud"
    },
    {
      "x": -16,
      "y": 27,
      "z": 1,
      "name": "Soil_Mud"
    },
    {
      "x": -16,
      "y": 28,
      "z": 1,
      "name": "Soil_Mud"
    },
    {
      "x": -16,
      "y": 29,
      "z": 1,
      "name": "Soil_Mud_Dry"
    },
    {
      "x": -16,
      "y": 30,
      "z": 1,
      "name": "Soil_Mud_Dry"
    },
    {
      "x": -16,
      "y": 31,
      "z": 1,
      "name": "Soil_Mud"
    },
    {
      "x": -16,
      "y": 32,
      "z": 1,
      "name": "Soil_Mud"
    },
    {
      "x": -16,
      "y": 33,
      "z": 1,
      "name": "Soil_Mud"
    },
    {
      "x": -16,
      "y": 34,
      "z": 1,
      "name": "Soil_Mud"
    },
    {
      "x": -16,
      "y": 35,
      "z": 1,
      "name": "Soil_Mud"
    },
    {
      "x": -16,
      "y": 27,
      "z": 2,
      "name": "Soil_Mud_Dry"
    },
    {
      "x": -16,
      "y": 28,
      "z": 2,
      "name": "Soil_Mud"
    },
    {
      "x": -16,
      "y": 29,
      "z": 2,
      "name": "Soil_Mud"
    },
    {
      "x": -16,
      "y": 30,
      "z": 2,
      "name": "Soil_Mud"
    },
    {
      "x": -16,
      "y": 31,
      "z": 2,
      "name": "Soil_Mud"
    },
    {
      "x": -16,
      "y": 32,
      "z": 2,
      "name": "Soil_Mud"
    },
    {
      "x": -16,
      "y": 33,
      "z": 2,
      "name": "Soil_Mud_Dry"
    },
    {
      "x": -16,
      "y": 34,
      "z": 2,
      "name": "Soil_Mud"
    },
    {
      "x": -16,
      "y": 35,
      "z": 2,
      "name": "Soil_Mud"
    },
    {
      "x": -16,
      "y": 36,
      "z": 2,
      "name": "Soil_Mud_Dry"
    },
    {
      "x": -16,
      "y": 37,
      "z": 2,
      "name": "Plant_Grass_Cave_Short"
    },
    {
      "x": -16,
      "y": 28,
      "z": 3,
      "name": "Soil_Mud"
    },
    {
      "x": -16,
      "y": 29,
      "z": 3,
      "name": "Soil_Mud"
    },
    {
      "x": -16,
      "y": 30,
      "z": 3,
      "name": "Soil_Mud"
    },
    {
      "x": -16,
      "y": 31,
      "z": 3,
      "name": "Soil_Mud"
    },
    {
      "x": -16,
      "y": 32,
      "z": 3,
      "name": "Soil_Mud"
    },
    {
      "x": -16,
      "y": 33,
      "z": 3,
      "name": "Soil_Mud"
    },
    {
      "x": -16,
      "y": 34,
      "z": 3,
      "name": "Soil_Mud"
    },
    {
      "x": -16,
      "y": 35,
      "z": 3,
      "name": "Soil_Mud"
    },
    {
      "x": -16,
      "y": 36,
      "z": 3,
      "name": "Soil_Mud"
    },
    {
      "x": -16,
      "y": 30,
      "z": 4,
      "name": "Soil_Mud"
    },
    {
      "x": -16,
      "y": 31,
      "z": 4,
      "name": "Soil_Mud"
    },
    {
      "x": -16,
      "y": 32,
      "z": 4,
      "name": "Soil_Mud"
    },
    {
      "x": -16,
      "y": 33,
      "z": 4,
      "name": "Soil_Mud"
    },
    {
      "x": -16,
      "y": 34,
      "z": 4,
      "name": "Soil_Mud"
    },
    {
      "x": -16,
      "y": 35,
      "z": 4,
      "name": "Soil_Mud_Dry"
    },
    {
      "x": -16,
      "y": 36,
      "z": 4,
      "name": "Soil_Mud_Dry"
    },
    {
      "x": -16,
      "y": 37,
      "z": 4,
      "name": "Soil_Mud_Dry"
    },
    {
      "x": -16,
      "y": 38,
      "z": 4,
      "name": "Plant_Crop_Mushroom_Glowing_Violet"
    },
    {
      "x": -16,
      "y": 29,
      "z": 5,
      "name": "Soil_Mud"
    },
    {
      "x": -16,
      "y": 30,
      "z": 5,
      "name": "Soil_Mud"
    },
    {
      "x": -16,
      "y": 31,
      "z": 5,
      "name": "Soil_Mud_Dry"
    },
    {
      "x": -16,
      "y": 32,
      "z": 5,
      "name": "Soil_Mud"
    },
    {
      "x": -16,
      "y": 33,
      "z": 5,
      "name": "Soil_Mud"
    },
    {
      "x": -16,
      "y": 34,
      "z": 5,
      "name": "Soil_Mud"
    },
    {
      "x": -16,
      "y": 35,
      "z": 5,
      "name": "Soil_Mud_Dry"
    },
    {
      "x": -16,
      "y": 36,
      "z": 5,
      "name": "Soil_Mud"
    },
    {
      "x": -16,
      "y": 37,
      "z": 5,
      "name": "Soil_Mud"
    },
    {
      "x": -16,
      "y": 38,
      "z": 5,
      "name": "Soil_Mud_Dry"
    },
    {
      "x": -16,
      "y": 30,
      "z": 6,
      "name": "Soil_Mud"
    },
    {
      "x": -16,
      "y": 31,
      "z": 6,
      "name": "Soil_Mud"
    },
    {
      "x": -16,
      "y": 32,
      "z": 6,
      "name": "Soil_Mud"
    },
    {
      "x": -16,
      "y": 33,
      "z": 6,
      "name": "Soil_Mud_Dry"
    },
    {
      "x": -16,
      "y": 34,
      "z": 6,
      "name": "Soil_Mud"
    },
    {
      "x": -16,
      "y": 35,
      "z": 6,
      "name": "Soil_Mud"
    },
    {
      "x": -16,
      "y": 36,
      "z": 6,
      "name": "Soil_Mud"
    },
    {
      "x": -16,
      "y": 37,
      "z": 6,
      "name": "Soil_Mud"
    },
    {
      "x": -16,
      "y": 38,
      "z": 6,
      "name": "Soil_Mud"
    },
    {
      "x": -16,
      "y": 30,
      "z": 7,
      "name": "Soil_Mud_Dry"
    },
    {
      "x": -16,
      "y": 31,
      "z": 7,
      "name": "Soil_Mud"
    },
    {
      "x": -16,
      "y": 32,
      "z": 7,
      "name": "Soil_Mud"
    },
    {
      "x": -16,
      "y": 33,
      "z": 7,
      "name": "Soil_Mud"
    },
    {
      "x": -16,
      "y": 34,
      "z": 7,
      "name": "Soil_Mud"
    },
    {
      "x": -16,
      "y": 35,
      "z": 7,
      "name": "Soil_Mud"
    },
    {
      "x": -16,
      "y": 36,
      "z": 7,
      "name": "Soil_Mud_Dry"
    },
    {
      "x": -16,
      "y": 37,
      "z": 7,
      "name": "Soil_Mud"
    },
    {
      "x": -16,
      "y": 32,
      "z": 8,
      "name": "Soil_Mud"
    },
    {
      "x": -16,
      "y": 33,
      "z": 8,
      "name": "Soil_Mud_Dry"
    },
    {
      "x": -16,
      "y": 34,
      "z": 8,
      "name": "Soil_Mud"
    },
    {
      "x": -16,
      "y": 35,
      "z": 8,
      "name": "Soil_Mud_Dry"
    },
    {
      "x": -16,
      "y": 36,
      "z": 8,
      "name": "Soil_Mud"
    },
    {
      "x": -15,
      "y": 29,
      "z": -3,
      "name": "Soil_Mud"
    },
    {
      "x": -15,
      "y": 30,
      "z": -3,
      "name": "Soil_Mud_Dry"
    },
    {
      "x": -15,
      "y": 31,
      "z": -3,
      "name": "Soil_Mud"
    },
    {
      "x": -15,
      "y": 32,
      "z": -3,
      "name": "Soil_Mud"
    },
    {
      "x": -15,
      "y": 33,
      "z": -3,
      "name": "Plant_Crop_Mushroom_Glowing_Purple"
    },
    {
      "x": -15,
      "y": 27,
      "z": -2,
      "name": "Soil_Mud"
    },
    {
      "x": -15,
      "y": 28,
      "z": -2,
      "name": "Soil_Mud"
    },
    {
      "x": -15,
      "y": 29,
      "z": -2,
      "name": "Soil_Mud"
    },
    {
      "x": -15,
      "y": 30,
      "z": -2,
      "name": "Soil_Mud"
    },
    {
      "x": -15,
      "y": 31,
      "z": -2,
      "name": "Soil_Mud"
    },
    {
      "x": -15,
      "y": 32,
      "z": -2,
      "name": "Soil_Mud_Dry"
    },
    {
      "x": -15,
      "y": 33,
      "z": -2,
      "name": "Soil_Mud"
    },
    {
      "x": -15,
      "y": 34,
      "z": -2,
      "name": "Soil_Mud_Dry"
    },
    {
      "x": -15,
      "y": 25,
      "z": -1,
      "name": "Soil_Mud"
    },
    {
      "x": -15,
      "y": 26,
      "z": -1,
      "name": "Soil_Mud"
    },
    {
      "x": -15,
      "y": 27,
      "z": -1,
      "name": "Soil_Mud_Dry"
    },
    {
      "x": -15,
      "y": 28,
      "z": -1,
      "name": "Soil_Mud"
    },
    {
      "x": -15,
      "y": 29,
      "z": -1,
      "name": "Soil_Mud_Dry"
    },
    {
      "x": -15,
      "y": 30,
      "z": -1,
      "name": "Soil_Mud"
    },
    {
      "x": -15,
      "y": 31,
      "z": -1,
      "name": "Soil_Mud"
    },
    {
      "x": -15,
      "y": 32,
      "z": -1,
      "name": "Soil_Mud_Dry"
    },
    {
      "x": -15,
      "y": 33,
      "z": -1,
      "name": "Soil_Mud"
    },
    {
      "x": -15,
      "y": 34,
      "z": -1,
      "name": "Soil_Mud"
    },
    {
      "x": -15,
      "y": 25,
      "z": 0,
      "name": "Soil_Mud"
    },
    {
      "x": -15,
      "y": 26,
      "z": 0,
      "name": "Soil_Mud"
    },
    {
      "x": -15,
      "y": 27,
      "z": 0,
      "name": "Soil_Mud"
    },
    {
      "x": -15,
      "y": 28,
      "z": 0,
      "name": "Soil_Mud"
    },
    {
      "x": -15,
      "y": 29,
      "z": 0,
      "name": "Soil_Mud"
    },
    {
      "x": -15,
      "y": 30,
      "z": 0,
      "name": "Soil_Mud"
    },
    {
      "x": -15,
      "y": 31,
      "z": 0,
      "name": "Soil_Mud"
    },
    {
      "x": -15,
      "y": 32,
      "z": 0,
      "name": "Soil_Mud"
    },
    {
      "x": -15,
      "y": 33,
      "z": 0,
      "name": "Soil_Mud"
    },
    {
      "x": -15,
      "y": 34,
      "z": 0,
      "name": "Soil_Mud"
    },
    {
      "x": -15,
      "y": 35,
      "z": 0,
      "name": "Soil_Mud_Dry"
    },
    {
      "x": -15,
      "y": 25,
      "z": 1,
      "name": "Soil_Mud"
    },
    {
      "x": -15,
      "y": 26,
      "z": 1,
      "name": "Soil_Mud"
    },
    {
      "x": -15,
      "y": 27,
      "z": 1,
      "name": "Soil_Mud"
    },
    {
      "x": -15,
      "y": 28,
      "z": 1,
      "name": "Soil_Mud"
    },
    {
      "x": -15,
      "y": 29,
      "z": 1,
      "name": "Soil_Mud"
    },
    {
      "x": -15,
      "y": 30,
      "z": 1,
      "name": "Soil_Mud"
    },
    {
      "x": -15,
      "y": 31,
      "z": 1,
      "name": "Soil_Mud"
    },
    {
      "x": -15,
      "y": 32,
      "z": 1,
      "name": "Soil_Mud"
    },
    {
      "x": -15,
      "y": 33,
      "z": 1,
      "name": "Soil_Mud_Dry"
    },
    {
      "x": -15,
      "y": 34,
      "z": 1,
      "name": "Soil_Mud"
    },
    {
      "x": -15,
      "y": 35,
      "z": 1,
      "name": "Soil_Mud_Dry"
    },
    {
      "x": -15,
      "y": 36,
      "z": 1,
      "name": "Soil_Mud"
    },
    {
      "x": -15,
      "y": 23,
      "z": 2,
      "name": "Rock_Crystal_Purple_Medium",
      "rotation": 7
    },
    {
      "x": -15,
      "y": 25,
      "z": 2,
      "name": "Rock_Crystal_Purple_Medium",
      "rotation": 7
    },
    {
      "x": -15,
      "y": 26,
      "z": 2,
      "name": "Soil_Mud_Dry"
    },
    {
      "x": -15,
      "y": 27,
      "z": 2,
      "name": "Soil_Mud_Dry"
    },
    {
      "x": -15,
      "y": 28,
      "z": 2,
      "name": "Soil_Mud_Dry"
    },
    {
      "x": -15,
      "y": 29,
      "z": 2,
      "name": "Soil_Mud"
    },
    {
      "x": -15,
      "y": 30,
      "z": 2,
      "name": "Soil_Mud"
    },
    {
      "x": -15,
      "y": 31,
      "z": 2,
      "name": "Soil_Mud_Dry"
    },
    {
      "x": -15,
      "y": 32,
      "z": 2,
      "name": "Soil_Mud"
    },
    {
      "x": -15,
      "y": 33,
      "z": 2,
      "name": "Soil_Mud_Dry"
    },
    {
      "x": -15,
      "y": 34,
      "z": 2,
      "name": "Soil_Mud"
    },
    {
      "x": -15,
      "y": 35,
      "z": 2,
      "name": "Soil_Mud_Dry"
    },
    {
      "x": -15,
      "y": 36,
      "z": 2,
      "name": "Soil_Mud"
    },
    {
      "x": -15,
      "y": 27,
      "z": 3,
      "name": "Soil_Mud_Dry"
    },
    {
      "x": -15,
      "y": 28,
      "z": 3,
      "name": "Soil_Mud_Dry"
    },
    {
      "x": -15,
      "y": 29,
      "z": 3,
      "name": "Soil_Mud"
    },
    {
      "x": -15,
      "y": 30,
      "z": 3,
      "name": "Soil_Mud"
    },
    {
      "x": -15,
      "y": 31,
      "z": 3,
      "name": "Soil_Mud"
    },
    {
      "x": -15,
      "y": 32,
      "z": 3,
      "name": "Soil_Mud_Dry"
    },
    {
      "x": -15,
      "y": 33,
      "z": 3,
      "name": "Soil_Mud_Dry"
    },
    {
      "x": -15,
      "y": 34,
      "z": 3,
      "name": "Soil_Mud"
    },
    {
      "x": -15,
      "y": 35,
      "z": 3,
      "name": "Soil_Mud"
    },
    {
      "x": -15,
      "y": 36,
      "z": 3,
      "name": "Soil_Mud"
    },
    {
      "x": -15,
      "y": 37,
      "z": 3,
      "name": "Soil_Mud"
    },
    {
      "x": -15,
      "y": 29,
      "z": 4,
      "name": "Soil_Mud_Dry"
    },
    {
      "x": -15,
      "y": 30,
      "z": 4,
      "name": "Soil_Mud"
    },
    {
      "x": -15,
      "y": 31,
      "z": 4,
      "name": "Soil_Mud"
    },
    {
      "x": -15,
      "y": 32,
      "z": 4,
      "name": "Soil_Mud"
    },
    {
      "x": -15,
      "y": 33,
      "z": 4,
      "name": "Soil_Mud"
    },
    {
      "x": -15,
      "y": 34,
      "z": 4,
      "name": "Soil_Mud"
    },
    {
      "x": -15,
      "y": 35,
      "z": 4,
      "name": "Soil_Mud"
    },
    {
      "x": -15,
      "y": 36,
      "z": 4,
      "name": "Soil_Mud_Dry"
    },
    {
      "x": -15,
      "y": 37,
      "z": 4,
      "name": "Soil_Mud"
    },
    {
      "x": -15,
      "y": 29,
      "z": 5,
      "name": "Soil_Mud"
    },
    {
      "x": -15,
      "y": 30,
      "z": 5,
      "name": "Soil_Mud"
    },
    {
      "x": -15,
      "y": 31,
      "z": 5,
      "name": "Soil_Mud_Dry"
    },
    {
      "x": -15,
      "y": 32,
      "z": 5,
      "name": "Soil_Mud_Dry"
    },
    {
      "x": -15,
      "y": 33,
      "z": 5,
      "name": "Soil_Mud"
    },
    {
      "x": -15,
      "y": 34,
      "z": 5,
      "name": "Soil_Mud_Dry"
    },
    {
      "x": -15,
      "y": 35,
      "z": 5,
      "name": "Soil_Mud"
    },
    {
      "x": -15,
      "y": 36,
      "z": 5,
      "name": "Soil_Mud"
    },
    {
      "x": -15,
      "y": 37,
      "z": 5,
      "name": "Soil_Mud_Dry"
    },
    {
      "x": -15,
      "y": 38,
      "z": 5,
      "name": "Soil_Mud_Dry"
    },
    {
      "x": -15,
      "y": 39,
      "z": 5,
      "name": "Plant_Crop_Mushroom_Glowing_Violet"
    },
    {
      "x": -15,
      "y": 27,
      "z": 6,
      "name": "Plant_Moss_Cave_Red"
    },
    {
      "x": -15,
      "y": 28,
      "z": 6,
      "name": "Soil_Mud"
    },
    {
      "x": -15,
      "y": 29,
      "z": 6,
      "name": "Soil_Mud"
    },
    {
      "x": -15,
      "y": 30,
      "z": 6,
      "name": "Soil_Mud_Dry"
    },
    {
      "x": -15,
      "y": 31,
      "z": 6,
      "name": "Soil_Mud_Dry"
    },
    {
      "x": -15,
      "y": 32,
      "z": 6,
      "name": "Soil_Mud"
    },
    {
      "x": -15,
      "y": 33,
      "z": 6,
      "name": "Soil_Mud"
    },
    {
      "x": -15,
      "y": 34,
      "z": 6,
      "name": "Soil_Mud"
    },
    {
      "x": -15,
      "y": 35,
      "z": 6,
      "name": "Soil_Mud_Dry"
    },
    {
      "x": -15,
      "y": 36,
      "z": 6,
      "name": "Soil_Mud"
    },
    {
      "x": -15,
      "y": 37,
      "z": 6,
      "name": "Soil_Mud"
    },
    {
      "x": -15,
      "y": 38,
      "z": 6,
      "name": "Soil_Mud"
    },
    {
      "x": -15,
      "y": 30,
      "z": 7,
      "name": "Soil_Mud"
    },
    {
      "x": -15,
      "y": 31,
      "z": 7,
      "name": "Soil_Mud"
    },
    {
      "x": -15,
      "y": 32,
      "z": 7,
      "name": "Soil_Mud"
    },
    {
      "x": -15,
      "y": 33,
      "z": 7,
      "name": "Soil_Mud"
    },
    {
      "x": -15,
      "y": 34,
      "z": 7,
      "name": "Soil_Mud"
    },
    {
      "x": -15,
      "y": 35,
      "z": 7,
      "name": "Soil_Mud"
    },
    {
      "x": -15,
      "y": 36,
      "z": 7,
      "name": "Soil_Mud_Dry"
    },
    {
      "x": -15,
      "y": 37,
      "z": 7,
      "name": "Soil_Mud_Dry"
    },
    {
      "x": -15,
      "y": 38,
      "z": 7,
      "name": "Soil_Mud"
    },
    {
      "x": -15,
      "y": 30,
      "z": 8,
      "name": "Plant_Moss_Cave_Red"
    },
    {
      "x": -15,
      "y": 31,
      "z": 8,
      "name": "Soil_Mud"
    },
    {
      "x": -15,
      "y": 32,
      "z": 8,
      "name": "Soil_Mud"
    },
    {
      "x": -15,
      "y": 33,
      "z": 8,
      "name": "Soil_Mud"
    },
    {
      "x": -15,
      "y": 34,
      "z": 8,
      "name": "Soil_Mud"
    },
    {
      "x": -15,
      "y": 35,
      "z": 8,
      "name": "Soil_Mud"
    },
    {
      "x": -15,
      "y": 36,
      "z": 8,
      "name": "Soil_Mud"
    },
    {
      "x": -15,
      "y": 37,
      "z": 8,
      "name": "Soil_Mud_Dry"
    },
    {
      "x": -15,
      "y": 33,
      "z": 9,
      "name": "Soil_Mud"
    },
    {
      "x": -15,
      "y": 34,
      "z": 9,
      "name": "Soil_Mud"
    },
    {
      "x": -15,
      "y": 35,
      "z": 9,
      "name": "Soil_Mud"
    },
    {
      "x": -15,
      "y": 36,
      "z": 9,
      "name": "Soil_Mud_Dry"
    },
    {
      "x": -14,
      "y": 28,
      "z": -3,
      "name": "Soil_Mud"
    },
    {
      "x": -14,
      "y": 29,
      "z": -3,
      "name": "Soil_Mud"
    },
    {
      "x": -14,
      "y": 30,
      "z": -3,
      "name": "Soil_Mud"
    },
    {
      "x": -14,
      "y": 31,
      "z": -3,
      "name": "Soil_Mud"
    },
    {
      "x": -14,
      "y": 32,
      "z": -3,
      "name": "Soil_Mud"
    },
    {
      "x": -14,
      "y": 26,
      "z": -2,
      "name": "Soil_Mud_Dry"
    },
    {
      "x": -14,
      "y": 27,
      "z": -2,
      "name": "Soil_Mud"
    },
    {
      "x": -14,
      "y": 28,
      "z": -2,
      "name": "Soil_Mud"
    },
    {
      "x": -14,
      "y": 29,
      "z": -2,
      "name": "Soil_Mud"
    },
    {
      "x": -14,
      "y": 30,
      "z": -2,
      "name": "Soil_Mud"
    },
    {
      "x": -14,
      "y": 31,
      "z": -2,
      "name": "Soil_Mud"
    },
    {
      "x": -14,
      "y": 32,
      "z": -2,
      "name": "Soil_Mud"
    },
    {
      "x": -14,
      "y": 33,
      "z": -2,
      "name": "Soil_Mud"
    },
    {
      "x": -14,
      "y": 34,
      "z": -2,
      "name": "Soil_Mud_Dry"
    },
    {
      "x": -14,
      "y": 25,
      "z": -1,
      "name": "Plant_Moss_Cave_Red"
    },
    {
      "x": -14,
      "y": 26,
      "z": -1,
      "name": "Soil_Mud_Dry"
    },
    {
      "x": -14,
      "y": 27,
      "z": -1,
      "name": "Soil_Mud"
    },
    {
      "x": -14,
      "y": 28,
      "z": -1,
      "name": "Soil_Mud"
    },
    {
      "x": -14,
      "y": 29,
      "z": -1,
      "name": "Soil_Mud"
    },
    {
      "x": -14,
      "y": 30,
      "z": -1,
      "name": "Soil_Mud"
    },
    {
      "x": -14,
      "y": 31,
      "z": -1,
      "name": "Soil_Mud_Dry"
    },
    {
      "x": -14,
      "y": 32,
      "z": -1,
      "name": "Soil_Mud"
    },
    {
      "x": -14,
      "y": 33,
      "z": -1,
      "name": "Soil_Mud"
    },
    {
      "x": -14,
      "y": 34,
      "z": -1,
      "name": "Soil_Mud"
    },
    {
      "x": -14,
      "y": 35,
      "z": -1,
      "name": "Soil_Mud"
    },
    {
      "x": -14,
      "y": 25,
      "z": 0,
      "name": "Soil_Mud"
    },
    {
      "x": -14,
      "y": 26,
      "z": 0,
      "name": "Soil_Mud_Dry"
    },
    {
      "x": -14,
      "y": 27,
      "z": 0,
      "name": "Soil_Mud"
    },
    {
      "x": -14,
      "y": 28,
      "z": 0,
      "name": "Soil_Mud"
    },
    {
      "x": -14,
      "y": 29,
      "z": 0,
      "name": "Soil_Mud_Dry"
    },
    {
      "x": -14,
      "y": 30,
      "z": 0,
      "name": "Soil_Mud"
    },
    {
      "x": -14,
      "y": 31,
      "z": 0,
      "name": "Soil_Mud"
    },
    {
      "x": -14,
      "y": 32,
      "z": 0,
      "name": "Soil_Mud_Dry"
    },
    {
      "x": -14,
      "y": 33,
      "z": 0,
      "name": "Soil_Mud_Dry"
    },
    {
      "x": -14,
      "y": 34,
      "z": 0,
      "name": "Soil_Mud"
    },
    {
      "x": -14,
      "y": 35,
      "z": 0,
      "name": "Soil_Mud"
    },
    {
      "x": -14,
      "y": 23,
      "z": 1,
      "name": "Rock_Crystal_Purple_Medium",
      "rotation": 7
    },
    {
      "x": -14,
      "y": 24,
      "z": 1,
      "name": "Soil_Mud"
    },
    {
      "x": -14,
      "y": 25,
      "z": 1,
      "name": "Soil_Mud"
    },
    {
      "x": -14,
      "y": 26,
      "z": 1,
      "name": "Soil_Mud"
    },
    {
      "x": -14,
      "y": 27,
      "z": 1,
      "name": "Soil_Mud"
    },
    {
      "x": -14,
      "y": 28,
      "z": 1,
      "name": "Soil_Mud"
    },
    {
      "x": -14,
      "y": 29,
      "z": 1,
      "name": "Soil_Mud"
    },
    {
      "x": -14,
      "y": 30,
      "z": 1,
      "name": "Soil_Mud"
    },
    {
      "x": -14,
      "y": 31,
      "z": 1,
      "name": "Soil_Mud"
    },
    {
      "x": -14,
      "y": 32,
      "z": 1,
      "name": "Soil_Mud"
    },
    {
      "x": -14,
      "y": 33,
      "z": 1,
      "name": "Soil_Mud"
    },
    {
      "x": -14,
      "y": 34,
      "z": 1,
      "name": "Soil_Mud_Dry"
    },
    {
      "x": -14,
      "y": 35,
      "z": 1,
      "name": "Soil_Mud"
    },
    {
      "x": -14,
      "y": 36,
      "z": 1,
      "name": "Soil_Mud"
    },
    {
      "x": -14,
      "y": 21,
      "z": 2,
      "name": "Rock_Crystal_Purple_Medium",
      "rotation": 7
    },
    {
      "x": -14,
      "y": 22,
      "z": 2,
      "name": "Rock_Crystal_Purple_Medium",
      "rotation": 7
    },
    {
      "x": -14,
      "y": 23,
      "z": 2,
      "name": "Rock_Crystal_Purple_Block"
    },
    {
      "x": -14,
      "y": 24,
      "z": 2,
      "name": "Rock_Crystal_Purple_Block"
    },
    {
      "x": -14,
      "y": 25,
      "z": 2,
      "name": "Rock_Crystal_Purple_Block"
    },
    {
      "x": -14,
      "y": 26,
      "z": 2,
      "name": "Rock_Crystal_Purple_Block"
    },
    {
      "x": -14,
      "y": 27,
      "z": 2,
      "name": "Rock_Crystal_Purple_Block"
    },
    {
      "x": -14,
      "y": 28,
      "z": 2,
      "name": "Rock_Crystal_Purple_Block"
    },
    {
      "x": -14,
      "y": 29,
      "z": 2,
      "name": "Soil_Mud_Dry"
    },
    {
      "x": -14,
      "y": 30,
      "z": 2,
      "name": "Soil_Mud"
    },
    {
      "x": -14,
      "y": 31,
      "z": 2,
      "name": "Soil_Mud"
    },
    {
      "x": -14,
      "y": 32,
      "z": 2,
      "name": "Soil_Mud"
    },
    {
      "x": -14,
      "y": 33,
      "z": 2,
      "name": "Soil_Mud"
    },
    {
      "x": -14,
      "y": 34,
      "z": 2,
      "name": "Soil_Mud_Dry"
    },
    {
      "x": -14,
      "y": 35,
      "z": 2,
      "name": "Soil_Mud_Dry"
    },
    {
      "x": -14,
      "y": 36,
      "z": 2,
      "name": "Soil_Mud_Dry"
    },
    {
      "x": -14,
      "y": 37,
      "z": 2,
      "name": "Soil_Mud"
    },
    {
      "x": -14,
      "y": 22,
      "z": 3,
      "name": "Rock_Crystal_Purple_Large",
      "rotation": 7
    },
    {
      "x": -14,
      "y": 23,
      "z": 3,
      "name": "Rock_Crystal_Purple_Medium",
      "rotation": 7
    },
    {
      "x": -14,
      "y": 24,
      "z": 3,
      "name": "Rock_Crystal_Purple_Medium",
      "rotation": 7
    },
    {
      "x": -14,
      "y": 25,
      "z": 3,
      "name": "Rock_Crystal_Purple_Medium",
      "rotation": 4
    },
    {
      "x": -14,
      "y": 26,
      "z": 3,
      "name": "Soil_Mud"
    },
    {
      "x": -14,
      "y": 27,
      "z": 3,
      "name": "Soil_Mud"
    },
    {
      "x": -14,
      "y": 28,
      "z": 3,
      "name": "Soil_Mud"
    },
    {
      "x": -14,
      "y": 29,
      "z": 3,
      "name": "Soil_Mud"
    },
    {
      "x": -14,
      "y": 30,
      "z": 3,
      "name": "Soil_Mud"
    },
    {
      "x": -14,
      "y": 31,
      "z": 3,
      "name": "Soil_Mud"
    },
    {
      "x": -14,
      "y": 32,
      "z": 3,
      "name": "Soil_Mud"
    },
    {
      "x": -14,
      "y": 33,
      "z": 3,
      "name": "Soil_Mud_Dry"
    },
    {
      "x": -14,
      "y": 34,
      "z": 3,
      "name": "Soil_Mud"
    },
    {
      "x": -14,
      "y": 35,
      "z": 3,
      "name": "Soil_Mud"
    },
    {
      "x": -14,
      "y": 36,
      "z": 3,
      "name": "Soil_Mud_Dry"
    },
    {
      "x": -14,
      "y": 37,
      "z": 3,
      "name": "Soil_Mud_Dry"
    },
    {
      "x": -14,
      "y": 38,
      "z": 3,
      "name": "Plant_Moss_Rug_Pink"
    },
    {
      "x": -14,
      "y": 28,
      "z": 4,
      "name": "Soil_Mud_Dry"
    },
    {
      "x": -14,
      "y": 29,
      "z": 4,
      "name": "Soil_Mud_Dry"
    },
    {
      "x": -14,
      "y": 30,
      "z": 4,
      "name": "Soil_Mud_Dry"
    },
    {
      "x": -14,
      "y": 31,
      "z": 4,
      "name": "Soil_Mud"
    },
    {
      "x": -14,
      "y": 32,
      "z": 4,
      "name": "Soil_Mud"
    },
    {
      "x": -14,
      "y": 33,
      "z": 4,
      "name": "Soil_Mud_Dry"
    },
    {
      "x": -14,
      "y": 34,
      "z": 4,
      "name": "Soil_Mud"
    },
    {
      "x": -14,
      "y": 35,
      "z": 4,
      "name": "Soil_Mud"
    },
    {
      "x": -14,
      "y": 36,
      "z": 4,
      "name": "Soil_Mud_Dry"
    },
    {
      "x": -14,
      "y": 37,
      "z": 4,
      "name": "Soil_Mud"
    },
    {
      "x": -14,
      "y": 38,
      "z": 4,
      "name": "Soil_Mud"
    },
    {
      "x": -14,
      "y": 28,
      "z": 5,
      "name": "Soil_Mud"
    },
    {
      "x": -14,
      "y": 29,
      "z": 5,
      "name": "Soil_Mud"
    },
    {
      "x": -14,
      "y": 30,
      "z": 5,
      "name": "Soil_Mud_Dry"
    },
    {
      "x": -14,
      "y": 31,
      "z": 5,
      "name": "Soil_Mud"
    },
    {
      "x": -14,
      "y": 32,
      "z": 5,
      "name": "Soil_Mud"
    },
    {
      "x": -14,
      "y": 33,
      "z": 5,
      "name": "Soil_Mud_Dry"
    },
    {
      "x": -14,
      "y": 34,
      "z": 5,
      "name": "Soil_Mud"
    },
    {
      "x": -14,
      "y": 35,
      "z": 5,
      "name": "Soil_Mud"
    },
    {
      "x": -14,
      "y": 36,
      "z": 5,
      "name": "Soil_Mud_Dry"
    },
    {
      "x": -14,
      "y": 37,
      "z": 5,
      "name": "Soil_Mud_Dry"
    },
    {
      "x": -14,
      "y": 38,
      "z": 5,
      "name": "Soil_Mud"
    },
    {
      "x": -14,
      "y": 28,
      "z": 6,
      "name": "Soil_Mud"
    },
    {
      "x": -14,
      "y": 29,
      "z": 6,
      "name": "Soil_Mud"
    },
    {
      "x": -14,
      "y": 30,
      "z": 6,
      "name": "Soil_Mud_Dry"
    },
    {
      "x": -14,
      "y": 31,
      "z": 6,
      "name": "Soil_Mud"
    },
    {
      "x": -14,
      "y": 32,
      "z": 6,
      "name": "Soil_Mud"
    },
    {
      "x": -14,
      "y": 33,
      "z": 6,
      "name": "Soil_Mud"
    },
    {
      "x": -14,
      "y": 34,
      "z": 6,
      "name": "Soil_Mud"
    },
    {
      "x": -14,
      "y": 35,
      "z": 6,
      "name": "Soil_Mud"
    },
    {
      "x": -14,
      "y": 36,
      "z": 6,
      "name": "Soil_Mud_Dry"
    },
    {
      "x": -14,
      "y": 37,
      "z": 6,
      "name": "Soil_Mud"
    },
    {
      "x": -14,
      "y": 38,
      "z": 6,
      "name": "Soil_Mud"
    },
    {
      "x": -14,
      "y": 39,
      "z": 6,
      "name": "Plant_Crop_Mushroom_Cap_Brown"
    },
    {
      "x": -14,
      "y": 27,
      "z": 7,
      "name": "Soil_Mud"
    },
    {
      "x": -14,
      "y": 28,
      "z": 7,
      "name": "Soil_Mud"
    },
    {
      "x": -14,
      "y": 29,
      "z": 7,
      "name": "Soil_Mud"
    },
    {
      "x": -14,
      "y": 30,
      "z": 7,
      "name": "Soil_Mud_Dry"
    },
    {
      "x": -14,
      "y": 31,
      "z": 7,
      "name": "Soil_Mud_Dry"
    },
    {
      "x": -14,
      "y": 32,
      "z": 7,
      "name": "Soil_Mud"
    },
    {
      "x": -14,
      "y": 33,
      "z": 7,
      "name": "Soil_Mud"
    },
    {
      "x": -14,
      "y": 34,
      "z": 7,
      "name": "Soil_Mud_Dry"
    },
    {
      "x": -14,
      "y": 35,
      "z": 7,
      "name": "Soil_Mud_Dry"
    },
    {
      "x": -14,
      "y": 36,
      "z": 7,
      "name": "Soil_Mud"
    },
    {
      "x": -14,
      "y": 37,
      "z": 7,
      "name": "Soil_Mud"
    },
    {
      "x": -14,
      "y": 38,
      "z": 7,
      "name": "Soil_Mud_Dry"
    },
    {
      "x": -14,
      "y": 30,
      "z": 8,
      "name": "Soil_Mud"
    },
    {
      "x": -14,
      "y": 31,
      "z": 8,
      "name": "Soil_Mud"
    },
    {
      "x": -14,
      "y": 32,
      "z": 8,
      "name": "Soil_Mud_Dry"
    },
    {
      "x": -14,
      "y": 33,
      "z": 8,
      "name": "Soil_Mud"
    },
    {
      "x": -14,
      "y": 34,
      "z": 8,
      "name": "Soil_Mud"
    },
    {
      "x": -14,
      "y": 35,
      "z": 8,
      "name": "Soil_Mud_Dry"
    },
    {
      "x": -14,
      "y": 36,
      "z": 8,
      "name": "Soil_Mud"
    },
    {
      "x": -14,
      "y": 37,
      "z": 8,
      "name": "Soil_Mud"
    },
    {
      "x": -14,
      "y": 38,
      "z": 8,
      "name": "Soil_Mud"
    },
    {
      "x": -14,
      "y": 32,
      "z": 9,
      "name": "Soil_Mud"
    },
    {
      "x": -14,
      "y": 33,
      "z": 9,
      "name": "Soil_Mud"
    },
    {
      "x": -14,
      "y": 34,
      "z": 9,
      "name": "Soil_Mud"
    },
    {
      "x": -14,
      "y": 35,
      "z": 9,
      "name": "Soil_Mud"
    },
    {
      "x": -14,
      "y": 36,
      "z": 9,
      "name": "Soil_Mud_Dry"
    },
    {
      "x": -14,
      "y": 37,
      "z": 9,
      "name": "Soil_Mud"
    },
    {
      "x": -14,
      "y": 38,
      "z": 9,
      "name": "Soil_Mud"
    },
    {
      "x": -14,
      "y": 34,
      "z": 10,
      "name": "Soil_Mud"
    },
    {
      "x": -14,
      "y": 35,
      "z": 10,
      "name": "Soil_Mud"
    },
    {
      "x": -14,
      "y": 36,
      "z": 10,
      "name": "Soil_Mud"
    },
    {
      "x": -14,
      "y": 37,
      "z": 10,
      "name": "Soil_Mud"
    },
    {
      "x": -13,
      "y": 27,
      "z": -3,
      "name": "Soil_Mud_Dry"
    },
    {
      "x": -13,
      "y": 28,
      "z": -3,
      "name": "Soil_Mud"
    },
    {
      "x": -13,
      "y": 29,
      "z": -3,
      "name": "Soil_Mud"
    },
    {
      "x": -13,
      "y": 30,
      "z": -3,
      "name": "Soil_Mud"
    },
    {
      "x": -13,
      "y": 31,
      "z": -3,
      "name": "Soil_Mud_Dry"
    },
    {
      "x": -13,
      "y": 32,
      "z": -3,
      "name": "Soil_Mud_Dry"
    },
    {
      "x": -13,
      "y": 33,
      "z": -3,
      "name": "Soil_Mud_Dry"
    },
    {
      "x": -13,
      "y": 34,
      "z": -3,
      "name": "Soil_Mud_Dry"
    },
    {
      "x": -13,
      "y": 26,
      "z": -2,
      "name": "Soil_Mud"
    },
    {
      "x": -13,
      "y": 27,
      "z": -2,
      "name": "Soil_Mud"
    },
    {
      "x": -13,
      "y": 28,
      "z": -2,
      "name": "Soil_Mud"
    },
    {
      "x": -13,
      "y": 29,
      "z": -2,
      "name": "Soil_Mud"
    },
    {
      "x": -13,
      "y": 30,
      "z": -2,
      "name": "Soil_Mud"
    },
    {
      "x": -13,
      "y": 31,
      "z": -2,
      "name": "Soil_Mud_Dry"
    },
    {
      "x": -13,
      "y": 32,
      "z": -2,
      "name": "Soil_Mud"
    },
    {
      "x": -13,
      "y": 33,
      "z": -2,
      "name": "Soil_Mud"
    },
    {
      "x": -13,
      "y": 34,
      "z": -2,
      "name": "Soil_Mud"
    },
    {
      "x": -13,
      "y": 25,
      "z": -1,
      "name": "Plant_Moss_Cave_Red"
    },
    {
      "x": -13,
      "y": 26,
      "z": -1,
      "name": "Soil_Mud"
    },
    {
      "x": -13,
      "y": 27,
      "z": -1,
      "name": "Soil_Mud_Dry"
    },
    {
      "x": -13,
      "y": 28,
      "z": -1,
      "name": "Soil_Mud"
    },
    {
      "x": -13,
      "y": 29,
      "z": -1,
      "name": "Soil_Mud_Dry"
    },
    {
      "x": -13,
      "y": 30,
      "z": -1,
      "name": "Soil_Mud"
    },
    {
      "x": -13,
      "y": 31,
      "z": -1,
      "name": "Soil_Mud"
    },
    {
      "x": -13,
      "y": 32,
      "z": -1,
      "name": "Soil_Mud"
    },
    {
      "x": -13,
      "y": 33,
      "z": -1,
      "name": "Soil_Mud"
    },
    {
      "x": -13,
      "y": 34,
      "z": -1,
      "name": "Soil_Mud"
    },
    {
      "x": -13,
      "y": 35,
      "z": -1,
      "name": "Soil_Mud"
    },
    {
      "x": -13,
      "y": 24,
      "z": 0,
      "name": "Rock_Crystal_Purple_Medium",
      "rotation": 6
    },
    {
      "x": -13,
      "y": 25,
      "z": 0,
      "name": "Soil_Mud"
    },
    {
      "x": -13,
      "y": 26,
      "z": 0,
      "name": "Soil_Mud_Dry"
    },
    {
      "x": -13,
      "y": 27,
      "z": 0,
      "name": "Soil_Mud"
    },
    {
      "x": -13,
      "y": 28,
      "z": 0,
      "name": "Soil_Mud"
    },
    {
      "x": -13,
      "y": 29,
      "z": 0,
      "name": "Soil_Mud_Dry"
    },
    {
      "x": -13,
      "y": 30,
      "z": 0,
      "name": "Soil_Mud"
    },
    {
      "x": -13,
      "y": 31,
      "z": 0,
      "name": "Soil_Mud_Dry"
    },
    {
      "x": -13,
      "y": 32,
      "z": 0,
      "name": "Soil_Mud"
    },
    {
      "x": -13,
      "y": 33,
      "z": 0,
      "name": "Soil_Mud"
    },
    {
      "x": -13,
      "y": 34,
      "z": 0,
      "name": "Soil_Mud_Dry"
    },
    {
      "x": -13,
      "y": 35,
      "z": 0,
      "name": "Soil_Mud"
    },
    {
      "x": -13,
      "y": 36,
      "z": 0,
      "name": "Soil_Mud"
    },
    {
      "x": -13,
      "y": 20,
      "z": 1,
      "name": "Rock_Crystal_Purple_Medium",
      "rotation": 6
    },
    {
      "x": -13,
      "y": 21,
      "z": 1,
      "name": "Rock_Crystal_Purple_Medium",
      "rotation": 6
    },
    {
      "x": -13,
      "y": 22,
      "z": 1,
      "name": "Rock_Crystal_Purple_Medium",
      "rotation": 6
    },
    {
      "x": -13,
      "y": 23,
      "z": 1,
      "name": "Rock_Crystal_Purple_Block"
    },
    {
      "x": -13,
      "y": 24,
      "z": 1,
      "name": "Rock_Crystal_Purple_Block"
    },
    {
      "x": -13,
      "y": 25,
      "z": 1,
      "name": "Rock_Crystal_Purple_Block"
    },
    {
      "x": -13,
      "y": 26,
      "z": 1,
      "name": "Rock_Crystal_Purple_Block"
    },
    {
      "x": -13,
      "y": 27,
      "z": 1,
      "name": "Rock_Crystal_Purple_Block"
    },
    {
      "x": -13,
      "y": 28,
      "z": 1,
      "name": "Rock_Crystal_Purple_Block"
    },
    {
      "x": -13,
      "y": 29,
      "z": 1,
      "name": "Soil_Mud"
    },
    {
      "x": -13,
      "y": 30,
      "z": 1,
      "name": "Soil_Mud"
    },
    {
      "x": -13,
      "y": 31,
      "z": 1,
      "name": "Soil_Mud_Dry"
    },
    {
      "x": -13,
      "y": 32,
      "z": 1,
      "name": "Soil_Mud_Dry"
    },
    {
      "x": -13,
      "y": 33,
      "z": 1,
      "name": "Soil_Mud_Dry"
    },
    {
      "x": -13,
      "y": 34,
      "z": 1,
      "name": "Soil_Mud"
    },
    {
      "x": -13,
      "y": 35,
      "z": 1,
      "name": "Soil_Mud_Dry"
    },
    {
      "x": -13,
      "y": 36,
      "z": 1,
      "name": "Soil_Mud"
    },
    {
      "x": -13,
      "y": 19,
      "z": 2,
      "name": "Rock_Crystal_Purple_Large",
      "rotation": 8
    },
    {
      "x": -13,
      "y": 20,
      "z": 2,
      "name": "Rock_Crystal_Purple_Block"
    },
    {
      "x": -13,
      "y": 21,
      "z": 2,
      "name": "Rock_Crystal_Purple_Block"
    },
    {
      "x": -13,
      "y": 22,
      "z": 2,
      "name": "Rock_Crystal_Purple_Block"
    },
    {
      "x": -13,
      "y": 23,
      "z": 2,
      "name": "Rock_Crystal_Purple_Block"
    },
    {
      "x": -13,
      "y": 24,
      "z": 2,
      "name": "Rock_Crystal_Purple_Block"
    },
    {
      "x": -13,
      "y": 25,
      "z": 2,
      "name": "Rock_Crystal_Purple_Block"
    },
    {
      "x": -13,
      "y": 26,
      "z": 2,
      "name": "Rock_Crystal_Purple_Block"
    },
    {
      "x": -13,
      "y": 27,
      "z": 2,
      "name": "Rock_Crystal_Purple_Block"
    },
    {
      "x": -13,
      "y": 28,
      "z": 2,
      "name": "Rock_Crystal_Purple_Block"
    },
    {
      "x": -13,
      "y": 29,
      "z": 2,
      "name": "Soil_Mud"
    },
    {
      "x": -13,
      "y": 30,
      "z": 2,
      "name": "Soil_Mud"
    },
    {
      "x": -13,
      "y": 31,
      "z": 2,
      "name": "Soil_Mud"
    },
    {
      "x": -13,
      "y": 32,
      "z": 2,
      "name": "Soil_Mud"
    },
    {
      "x": -13,
      "y": 33,
      "z": 2,
      "name": "Soil_Mud"
    },
    {
      "x": -13,
      "y": 34,
      "z": 2,
      "name": "Soil_Mud"
    },
    {
      "x": -13,
      "y": 35,
      "z": 2,
      "name": "Soil_Mud_Dry"
    },
    {
      "x": -13,
      "y": 36,
      "z": 2,
      "name": "Soil_Mud"
    },
    {
      "x": -13,
      "y": 37,
      "z": 2,
      "name": "Soil_Mud"
    },
    {
      "x": -13,
      "y": 21,
      "z": 3,
      "name": "Rock_Crystal_Purple_Large",
      "rotation": 4
    },
    {
      "x": -13,
      "y": 22,
      "z": 3,
      "name": "Rock_Crystal_Purple_Block"
    },
    {
      "x": -13,
      "y": 23,
      "z": 3,
      "name": "Rock_Crystal_Purple_Block"
    },
    {
      "x": -13,
      "y": 24,
      "z": 3,
      "name": "Rock_Crystal_Purple_Block"
    },
    {
      "x": -13,
      "y": 25,
      "z": 3,
      "name": "Rock_Crystal_Purple_Block"
    },
    {
      "x": -13,
      "y": 26,
      "z": 3,
      "name": "Rock_Crystal_Purple_Block"
    },
    {
      "x": -13,
      "y": 27,
      "z": 3,
      "name": "Rock_Crystal_Purple_Block"
    },
    {
      "x": -13,
      "y": 28,
      "z": 3,
      "name": "Rock_Crystal_Purple_Block"
    },
    {
      "x": -13,
      "y": 29,
      "z": 3,
      "name": "Soil_Mud"
    },
    {
      "x": -13,
      "y": 30,
      "z": 3,
      "name": "Soil_Mud"
    },
    {
      "x": -13,
      "y": 31,
      "z": 3,
      "name": "Soil_Mud"
    },
    {
      "x": -13,
      "y": 32,
      "z": 3,
      "name": "Soil_Mud_Dry"
    },
    {
      "x": -13,
      "y": 33,
      "z": 3,
      "name": "Soil_Mud"
    },
    {
      "x": -13,
      "y": 34,
      "z": 3,
      "name": "Soil_Mud"
    },
    {
      "x": -13,
      "y": 35,
      "z": 3,
      "name": "Soil_Mud"
    },
    {
      "x": -13,
      "y": 36,
      "z": 3,
      "name": "Soil_Mud_Dry"
    },
    {
      "x": -13,
      "y": 37,
      "z": 3,
      "name": "Soil_Mud"
    },
    {
      "x": -13,
      "y": 22,
      "z": 4,
      "name": "Rock_Crystal_Purple_Medium",
      "rotation": 4
    },
    {
      "x": -13,
      "y": 23,
      "z": 4,
      "name": "Rock_Crystal_Purple_Medium",
      "rotation": 4
    },
    {
      "x": -13,
      "y": 24,
      "z": 4,
      "name": "Rock_Crystal_Purple_Medium",
      "rotation": 4
    },
    {
      "x": -13,
      "y": 25,
      "z": 4,
      "name": "Rock_Crystal_Purple_Medium",
      "rotation": 4
    },
    {
      "x": -13,
      "y": 26,
      "z": 4,
      "name": "Rock_Crystal_Purple_Medium",
      "rotation": 4
    },
    {
      "x": -13,
      "y": 27,
      "z": 4,
      "name": "Soil_Mud"
    },
    {
      "x": -13,
      "y": 28,
      "z": 4,
      "name": "Soil_Mud"
    },
    {
      "x": -13,
      "y": 29,
      "z": 4,
      "name": "Soil_Mud_Dry"
    },
    {
      "x": -13,
      "y": 30,
      "z": 4,
      "name": "Soil_Mud_Dry"
    },
    {
      "x": -13,
      "y": 31,
      "z": 4,
      "name": "Soil_Mud"
    },
    {
      "x": -13,
      "y": 32,
      "z": 4,
      "name": "Soil_Mud"
    },
    {
      "x": -13,
      "y": 33,
      "z": 4,
      "name": "Soil_Mud"
    },
    {
      "x": -13,
      "y": 34,
      "z": 4,
      "name": "Soil_Mud"
    },
    {
      "x": -13,
      "y": 35,
      "z": 4,
      "name": "Soil_Mud"
    },
    {
      "x": -13,
      "y": 36,
      "z": 4,
      "name": "Soil_Mud_Dry"
    },
    {
      "x": -13,
      "y": 37,
      "z": 4,
      "name": "Soil_Mud_Dry"
    },
    {
      "x": -13,
      "y": 38,
      "z": 4,
      "name": "Soil_Mud_Dry"
    },
    {
      "x": -13,
      "y": 28,
      "z": 5,
      "name": "Soil_Mud"
    },
    {
      "x": -13,
      "y": 29,
      "z": 5,
      "name": "Soil_Mud"
    },
    {
      "x": -13,
      "y": 30,
      "z": 5,
      "name": "Soil_Mud"
    },
    {
      "x": -13,
      "y": 31,
      "z": 5,
      "name": "Soil_Mud"
    },
    {
      "x": -13,
      "y": 32,
      "z": 5,
      "name": "Soil_Mud_Dry"
    },
    {
      "x": -13,
      "y": 33,
      "z": 5,
      "name": "Soil_Mud"
    },
    {
      "x": -13,
      "y": 34,
      "z": 5,
      "name": "Soil_Mud_Dry"
    },
    {
      "x": -13,
      "y": 35,
      "z": 5,
      "name": "Soil_Mud_Dry"
    },
    {
      "x": -13,
      "y": 36,
      "z": 5,
      "name": "Soil_Mud"
    },
    {
      "x": -13,
      "y": 37,
      "z": 5,
      "name": "Soil_Mud"
    },
    {
      "x": -13,
      "y": 38,
      "z": 5,
      "name": "Soil_Mud_Dry"
    },
    {
      "x": -13,
      "y": 28,
      "z": 6,
      "name": "Soil_Mud"
    },
    {
      "x": -13,
      "y": 29,
      "z": 6,
      "name": "Soil_Mud"
    },
    {
      "x": -13,
      "y": 30,
      "z": 6,
      "name": "Soil_Mud_Dry"
    },
    {
      "x": -13,
      "y": 31,
      "z": 6,
      "name": "Soil_Mud"
    },
    {
      "x": -13,
      "y": 32,
      "z": 6,
      "name": "Soil_Mud"
    },
    {
      "x": -13,
      "y": 33,
      "z": 6,
      "name": "Soil_Mud"
    },
    {
      "x": -13,
      "y": 34,
      "z": 6,
      "name": "Soil_Mud_Dry"
    },
    {
      "x": -13,
      "y": 35,
      "z": 6,
      "name": "Soil_Mud"
    },
    {
      "x": -13,
      "y": 36,
      "z": 6,
      "name": "Soil_Mud"
    },
    {
      "x": -13,
      "y": 37,
      "z": 6,
      "name": "Soil_Mud"
    },
    {
      "x": -13,
      "y": 38,
      "z": 6,
      "name": "Soil_Mud"
    },
    {
      "x": -13,
      "y": 29,
      "z": 7,
      "name": "Soil_Mud"
    },
    {
      "x": -13,
      "y": 30,
      "z": 7,
      "name": "Soil_Mud"
    },
    {
      "x": -13,
      "y": 31,
      "z": 7,
      "name": "Soil_Mud_Dry"
    },
    {
      "x": -13,
      "y": 32,
      "z": 7,
      "name": "Soil_Mud"
    },
    {
      "x": -13,
      "y": 33,
      "z": 7,
      "name": "Soil_Mud"
    },
    {
      "x": -13,
      "y": 34,
      "z": 7,
      "name": "Soil_Mud"
    },
    {
      "x": -13,
      "y": 35,
      "z": 7,
      "name": "Soil_Mud"
    },
    {
      "x": -13,
      "y": 36,
      "z": 7,
      "name": "Soil_Mud"
    },
    {
      "x": -13,
      "y": 37,
      "z": 7,
      "name": "Soil_Mud_Dry"
    },
    {
      "x": -13,
      "y": 38,
      "z": 7,
      "name": "Soil_Mud_Dry"
    },
    {
      "x": -13,
      "y": 29,
      "z": 8,
      "name": "Soil_Mud"
    },
    {
      "x": -13,
      "y": 30,
      "z": 8,
      "name": "Soil_Mud_Dry"
    },
    {
      "x": -13,
      "y": 31,
      "z": 8,
      "name": "Soil_Mud"
    },
    {
      "x": -13,
      "y": 32,
      "z": 8,
      "name": "Soil_Mud"
    },
    {
      "x": -13,
      "y": 33,
      "z": 8,
      "name": "Soil_Mud"
    },
    {
      "x": -13,
      "y": 34,
      "z": 8,
      "name": "Soil_Mud"
    },
    {
      "x": -13,
      "y": 35,
      "z": 8,
      "name": "Soil_Mud"
    },
    {
      "x": -13,
      "y": 36,
      "z": 8,
      "name": "Soil_Mud"
    },
    {
      "x": -13,
      "y": 37,
      "z": 8,
      "name": "Soil_Mud"
    },
    {
      "x": -13,
      "y": 38,
      "z": 8,
      "name": "Soil_Mud"
    },
    {
      "x": -13,
      "y": 39,
      "z": 8,
      "name": "Plant_Bush_Dead_Tall"
    },
    {
      "x": -13,
      "y": 30,
      "z": 9,
      "name": "Plant_Moss_Cave_Red"
    },
    {
      "x": -13,
      "y": 31,
      "z": 9,
      "name": "Soil_Mud_Dry"
    },
    {
      "x": -13,
      "y": 32,
      "z": 9,
      "name": "Soil_Mud"
    },
    {
      "x": -13,
      "y": 33,
      "z": 9,
      "name": "Soil_Mud"
    },
    {
      "x": -13,
      "y": 34,
      "z": 9,
      "name": "Soil_Mud_Dry"
    },
    {
      "x": -13,
      "y": 35,
      "z": 9,
      "name": "Soil_Mud"
    },
    {
      "x": -13,
      "y": 36,
      "z": 9,
      "name": "Soil_Mud_Dry"
    },
    {
      "x": -13,
      "y": 37,
      "z": 9,
      "name": "Soil_Mud"
    },
    {
      "x": -13,
      "y": 38,
      "z": 9,
      "name": "Soil_Mud"
    },
    {
      "x": -13,
      "y": 34,
      "z": 10,
      "name": "Soil_Mud_Dry"
    },
    {
      "x": -13,
      "y": 35,
      "z": 10,
      "name": "Soil_Mud"
    },
    {
      "x": -13,
      "y": 36,
      "z": 10,
      "name": "Soil_Mud"
    },
    {
      "x": -13,
      "y": 37,
      "z": 10,
      "name": "Soil_Mud_Dry"
    },
    {
      "x": -13,
      "y": 38,
      "z": 10,
      "name": "Soil_Mud_Dry"
    },
    {
      "x": -13,
      "y": 35,
      "z": 11,
      "name": "Soil_Mud_Dry"
    },
    {
      "x": -13,
      "y": 36,
      "z": 11,
      "name": "Soil_Mud"
    },
    {
      "x": -13,
      "y": 37,
      "z": 11,
      "name": "Soil_Mud"
    },
    {
      "x": -12,
      "y": 27,
      "z": -3,
      "name": "Soil_Mud"
    },
    {
      "x": -12,
      "y": 28,
      "z": -3,
      "name": "Soil_Mud_Dry"
    },
    {
      "x": -12,
      "y": 29,
      "z": -3,
      "name": "Soil_Mud_Dry"
    },
    {
      "x": -12,
      "y": 30,
      "z": -3,
      "name": "Soil_Mud_Dry"
    },
    {
      "x": -12,
      "y": 31,
      "z": -3,
      "name": "Soil_Mud"
    },
    {
      "x": -12,
      "y": 32,
      "z": -3,
      "name": "Soil_Mud_Dry"
    },
    {
      "x": -12,
      "y": 33,
      "z": -3,
      "name": "Soil_Mud_Dry"
    },
    {
      "x": -12,
      "y": 34,
      "z": -3,
      "name": "Soil_Mud"
    },
    {
      "x": -12,
      "y": 27,
      "z": -2,
      "name": "Soil_Mud_Dry"
    },
    {
      "x": -12,
      "y": 28,
      "z": -2,
      "name": "Soil_Mud"
    },
    {
      "x": -12,
      "y": 29,
      "z": -2,
      "name": "Soil_Mud"
    },
    {
      "x": -12,
      "y": 30,
      "z": -2,
      "name": "Soil_Mud_Dry"
    },
    {
      "x": -12,
      "y": 31,
      "z": -2,
      "name": "Soil_Mud"
    },
    {
      "x": -12,
      "y": 32,
      "z": -2,
      "name": "Soil_Mud"
    },
    {
      "x": -12,
      "y": 33,
      "z": -2,
      "name": "Soil_Mud"
    },
    {
      "x": -12,
      "y": 34,
      "z": -2,
      "name": "Soil_Mud"
    },
    {
      "x": -12,
      "y": 26,
      "z": -1,
      "name": "Soil_Mud_Dry"
    },
    {
      "x": -12,
      "y": 27,
      "z": -1,
      "name": "Soil_Mud"
    },
    {
      "x": -12,
      "y": 28,
      "z": -1,
      "name": "Soil_Mud"
    },
    {
      "x": -12,
      "y": 29,
      "z": -1,
      "name": "Soil_Mud"
    },
    {
      "x": -12,
      "y": 30,
      "z": -1,
      "name": "Soil_Mud_Dry"
    },
    {
      "x": -12,
      "y": 31,
      "z": -1,
      "name": "Soil_Mud"
    },
    {
      "x": -12,
      "y": 32,
      "z": -1,
      "name": "Soil_Mud"
    },
    {
      "x": -12,
      "y": 33,
      "z": -1,
      "name": "Soil_Mud"
    },
    {
      "x": -12,
      "y": 34,
      "z": -1,
      "name": "Soil_Mud"
    },
    {
      "x": -12,
      "y": 35,
      "z": -1,
      "name": "Soil_Mud"
    },
    {
      "x": -12,
      "y": 36,
      "z": -1,
      "name": "Plant_Crop_Mushroom_Glowing_Purple"
    },
    {
      "x": -12,
      "y": 26,
      "z": 0,
      "name": "Soil_Mud"
    },
    {
      "x": -12,
      "y": 27,
      "z": 0,
      "name": "Soil_Mud_Dry"
    },
    {
      "x": -12,
      "y": 28,
      "z": 0,
      "name": "Soil_Mud"
    },
    {
      "x": -12,
      "y": 29,
      "z": 0,
      "name": "Soil_Mud_Dry"
    },
    {
      "x": -12,
      "y": 30,
      "z": 0,
      "name": "Soil_Mud_Dry"
    },
    {
      "x": -12,
      "y": 31,
      "z": 0,
      "name": "Soil_Mud"
    },
    {
      "x": -12,
      "y": 32,
      "z": 0,
      "name": "Soil_Mud_Dry"
    },
    {
      "x": -12,
      "y": 33,
      "z": 0,
      "name": "Soil_Mud"
    },
    {
      "x": -12,
      "y": 34,
      "z": 0,
      "name": "Soil_Mud"
    },
    {
      "x": -12,
      "y": 35,
      "z": 0,
      "name": "Soil_Mud"
    },
    {
      "x": -12,
      "y": 36,
      "z": 0,
      "name": "Soil_Mud_Dry"
    },
    {
      "x": -12,
      "y": 37,
      "z": 0,
      "name": "Plant_Crop_Mushroom_Glowing_Violet"
    },
    {
      "x": -12,
      "y": 22,
      "z": 1,
      "name": "Rock_Crystal_Purple_Medium",
      "rotation": 6
    },
    {
      "x": -12,
      "y": 23,
      "z": 1,
      "name": "Rock_Crystal_Purple_Medium",
      "rotation": 6
    },
    {
      "x": -12,
      "y": 25,
      "z": 1,
      "name": "Rock_Crystal_Purple_Large",
      "rotation": 5
    },
    {
      "x": -12,
      "y": 26,
      "z": 1,
      "name": "Soil_Mud"
    },
    {
      "x": -12,
      "y": 27,
      "z": 1,
      "name": "Soil_Mud_Dry"
    },
    {
      "x": -12,
      "y": 28,
      "z": 1,
      "name": "Soil_Mud"
    },
    {
      "x": -12,
      "y": 29,
      "z": 1,
      "name": "Soil_Mud"
    },
    {
      "x": -12,
      "y": 30,
      "z": 1,
      "name": "Soil_Mud"
    },
    {
      "x": -12,
      "y": 31,
      "z": 1,
      "name": "Soil_Mud_Dry"
    },
    {
      "x": -12,
      "y": 32,
      "z": 1,
      "name": "Soil_Mud"
    },
    {
      "x": -12,
      "y": 33,
      "z": 1,
      "name": "Soil_Mud"
    },
    {
      "x": -12,
      "y": 34,
      "z": 1,
      "name": "Soil_Mud_Dry"
    },
    {
      "x": -12,
      "y": 35,
      "z": 1,
      "name": "Soil_Mud_Dry"
    },
    {
      "x": -12,
      "y": 36,
      "z": 1,
      "name": "Soil_Mud_Dry"
    },
    {
      "x": -12,
      "y": 20,
      "z": 2,
      "name": "Rock_Crystal_Purple_Large",
      "rotation": 8
    },
    {
      "x": -12,
      "y": 21,
      "z": 2,
      "name": "Rock_Crystal_Purple_Block"
    },
    {
      "x": -12,
      "y": 22,
      "z": 2,
      "name": "Rock_Crystal_Purple_Block"
    },
    {
      "x": -12,
      "y": 23,
      "z": 2,
      "name": "Rock_Crystal_Purple_Block"
    },
    {
      "x": -12,
      "y": 24,
      "z": 2,
      "name": "Rock_Crystal_Purple_Block"
    },
    {
      "x": -12,
      "y": 25,
      "z": 2,
      "name": "Rock_Crystal_Purple_Block"
    },
    {
      "x": -12,
      "y": 26,
      "z": 2,
      "name": "Rock_Crystal_Purple_Block"
    },
    {
      "x": -12,
      "y": 27,
      "z": 2,
      "name": "Rock_Crystal_Purple_Block"
    },
    {
      "x": -12,
      "y": 28,
      "z": 2,
      "name": "Rock_Crystal_Purple_Block"
    },
    {
      "x": -12,
      "y": 29,
      "z": 2,
      "name": "Soil_Mud"
    },
    {
      "x": -12,
      "y": 30,
      "z": 2,
      "name": "Soil_Mud"
    },
    {
      "x": -12,
      "y": 31,
      "z": 2,
      "name": "Soil_Mud"
    },
    {
      "x": -12,
      "y": 32,
      "z": 2,
      "name": "Soil_Mud"
    },
    {
      "x": -12,
      "y": 33,
      "z": 2,
      "name": "Soil_Mud"
    },
    {
      "x": -12,
      "y": 34,
      "z": 2,
      "name": "Soil_Mud"
    },
    {
      "x": -12,
      "y": 35,
      "z": 2,
      "name": "Soil_Mud_Dry"
    },
    {
      "x": -12,
      "y": 36,
      "z": 2,
      "name": "Soil_Mud_Dry"
    },
    {
      "x": -12,
      "y": 37,
      "z": 2,
      "name": "Soil_Mud"
    },
    {
      "x": -12,
      "y": 22,
      "z": 3,
      "name": "Rock_Crystal_Purple_Medium",
      "rotation": 4
    },
    {
      "x": -12,
      "y": 23,
      "z": 3,
      "name": "Rock_Crystal_Purple_Medium",
      "rotation": 4
    },
    {
      "x": -12,
      "y": 24,
      "z": 3,
      "name": "Rock_Crystal_Purple_Medium",
      "rotation": 5
    },
    {
      "x": -12,
      "y": 25,
      "z": 3,
      "name": "Rock_Crystal_Purple_Medium",
      "rotation": 4
    },
    {
      "x": -12,
      "y": 26,
      "z": 3,
      "name": "Soil_Mud"
    },
    {
      "x": -12,
      "y": 27,
      "z": 3,
      "name": "Soil_Mud_Dry"
    },
    {
      "x": -12,
      "y": 28,
      "z": 3,
      "name": "Soil_Mud_Dry"
    },
    {
      "x": -12,
      "y": 29,
      "z": 3,
      "name": "Soil_Mud"
    },
    {
      "x": -12,
      "y": 30,
      "z": 3,
      "name": "Soil_Mud"
    },
    {
      "x": -12,
      "y": 31,
      "z": 3,
      "name": "Soil_Mud"
    },
    {
      "x": -12,
      "y": 32,
      "z": 3,
      "name": "Soil_Mud"
    },
    {
      "x": -12,
      "y": 33,
      "z": 3,
      "name": "Soil_Mud"
    },
    {
      "x": -12,
      "y": 34,
      "z": 3,
      "name": "Soil_Mud_Dry"
    },
    {
      "x": -12,
      "y": 35,
      "z": 3,
      "name": "Soil_Mud"
    },
    {
      "x": -12,
      "y": 36,
      "z": 3,
      "name": "Soil_Mud"
    },
    {
      "x": -12,
      "y": 37,
      "z": 3,
      "name": "Soil_Mud_Dry"
    },
    {
      "x": -12,
      "y": 28,
      "z": 4,
      "name": "Soil_Mud"
    },
    {
      "x": -12,
      "y": 29,
      "z": 4,
      "name": "Soil_Mud"
    },
    {
      "x": -12,
      "y": 30,
      "z": 4,
      "name": "Soil_Mud"
    },
    {
      "x": -12,
      "y": 31,
      "z": 4,
      "name": "Soil_Mud_Dry"
    },
    {
      "x": -12,
      "y": 32,
      "z": 4,
      "name": "Soil_Mud"
    },
    {
      "x": -12,
      "y": 33,
      "z": 4,
      "name": "Soil_Mud"
    },
    {
      "x": -12,
      "y": 34,
      "z": 4,
      "name": "Soil_Mud"
    },
    {
      "x": -12,
      "y": 35,
      "z": 4,
      "name": "Soil_Mud"
    },
    {
      "x": -12,
      "y": 36,
      "z": 4,
      "name": "Soil_Mud"
    },
    {
      "x": -12,
      "y": 37,
      "z": 4,
      "name": "Soil_Mud_Dry"
    },
    {
      "x": -12,
      "y": 38,
      "z": 4,
      "name": "Soil_Mud"
    },
    {
      "x": -12,
      "y": 27,
      "z": 5,
      "name": "Soil_Mud"
    },
    {
      "x": -12,
      "y": 28,
      "z": 5,
      "name": "Soil_Mud_Dry"
    },
    {
      "x": -12,
      "y": 29,
      "z": 5,
      "name": "Soil_Mud_Dry"
    },
    {
      "x": -12,
      "y": 30,
      "z": 5,
      "name": "Soil_Mud"
    },
    {
      "x": -12,
      "y": 31,
      "z": 5,
      "name": "Soil_Mud"
    },
    {
      "x": -12,
      "y": 32,
      "z": 5,
      "name": "Soil_Mud"
    },
    {
      "x": -12,
      "y": 33,
      "z": 5,
      "name": "Soil_Mud"
    },
    {
      "x": -12,
      "y": 34,
      "z": 5,
      "name": "Soil_Mud"
    },
    {
      "x": -12,
      "y": 35,
      "z": 5,
      "name": "Soil_Mud"
    },
    {
      "x": -12,
      "y": 36,
      "z": 5,
      "name": "Soil_Mud_Dry"
    },
    {
      "x": -12,
      "y": 37,
      "z": 5,
      "name": "Soil_Mud"
    },
    {
      "x": -12,
      "y": 38,
      "z": 5,
      "name": "Soil_Mud"
    },
    {
      "x": -12,
      "y": 28,
      "z": 6,
      "name": "Soil_Mud_Dry"
    },
    {
      "x": -12,
      "y": 29,
      "z": 6,
      "name": "Soil_Mud_Dry"
    },
    {
      "x": -12,
      "y": 30,
      "z": 6,
      "name": "Soil_Mud"
    },
    {
      "x": -12,
      "y": 31,
      "z": 6,
      "name": "Soil_Mud"
    },
    {
      "x": -12,
      "y": 32,
      "z": 6,
      "name": "Soil_Mud"
    },
    {
      "x": -12,
      "y": 33,
      "z": 6,
      "name": "Soil_Mud_Dry"
    },
    {
      "x": -12,
      "y": 34,
      "z": 6,
      "name": "Soil_Mud"
    },
    {
      "x": -12,
      "y": 35,
      "z": 6,
      "name": "Soil_Mud_Dry"
    },
    {
      "x": -12,
      "y": 36,
      "z": 6,
      "name": "Soil_Mud"
    },
    {
      "x": -12,
      "y": 37,
      "z": 6,
      "name": "Soil_Mud_Dry"
    },
    {
      "x": -12,
      "y": 38,
      "z": 6,
      "name": "Soil_Mud"
    },
    {
      "x": -12,
      "y": 39,
      "z": 6,
      "name": "Plant_Flower_Bushy_Purple"
    },
    {
      "x": -12,
      "y": 29,
      "z": 7,
      "name": "Soil_Mud"
    },
    {
      "x": -12,
      "y": 30,
      "z": 7,
      "name": "Soil_Mud"
    },
    {
      "x": -12,
      "y": 31,
      "z": 7,
      "name": "Soil_Mud_Dry"
    },
    {
      "x": -12,
      "y": 32,
      "z": 7,
      "name": "Soil_Mud"
    },
    {
      "x": -12,
      "y": 33,
      "z": 7,
      "name": "Soil_Mud"
    },
    {
      "x": -12,
      "y": 34,
      "z": 7,
      "name": "Soil_Mud"
    },
    {
      "x": -12,
      "y": 35,
      "z": 7,
      "name": "Soil_Mud"
    },
    {
      "x": -12,
      "y": 36,
      "z": 7,
      "name": "Soil_Mud"
    },
    {
      "x": -12,
      "y": 37,
      "z": 7,
      "name": "Soil_Mud"
    },
    {
      "x": -12,
      "y": 38,
      "z": 7,
      "name": "Soil_Mud"
    },
    {
      "x": -12,
      "y": 39,
      "z": 7,
      "name": "Plant_Crop_Mushroom_Glowing_Violet"
    },
    {
      "x": -12,
      "y": 30,
      "z": 8,
      "name": "Soil_Mud"
    },
    {
      "x": -12,
      "y": 31,
      "z": 8,
      "name": "Soil_Mud_Dry"
    },
    {
      "x": -12,
      "y": 32,
      "z": 8,
      "name": "Soil_Mud_Dry"
    },
    {
      "x": -12,
      "y": 33,
      "z": 8,
      "name": "Soil_Mud"
    },
    {
      "x": -12,
      "y": 34,
      "z": 8,
      "name": "Soil_Mud"
    },
    {
      "x": -12,
      "y": 35,
      "z": 8,
      "name": "Soil_Mud"
    },
    {
      "x": -12,
      "y": 36,
      "z": 8,
      "name": "Soil_Mud"
    },
    {
      "x": -12,
      "y": 37,
      "z": 8,
      "name": "Soil_Mud_Dry"
    },
    {
      "x": -12,
      "y": 38,
      "z": 8,
      "name": "Soil_Mud"
    },
    {
      "x": -12,
      "y": 32,
      "z": 9,
      "name": "Soil_Mud"
    },
    {
      "x": -12,
      "y": 33,
      "z": 9,
      "name": "Soil_Mud"
    },
    {
      "x": -12,
      "y": 34,
      "z": 9,
      "name": "Soil_Mud"
    },
    {
      "x": -12,
      "y": 35,
      "z": 9,
      "name": "Soil_Mud"
    },
    {
      "x": -12,
      "y": 36,
      "z": 9,
      "name": "Soil_Mud"
    },
    {
      "x": -12,
      "y": 37,
      "z": 9,
      "name": "Soil_Mud"
    },
    {
      "x": -12,
      "y": 38,
      "z": 9,
      "name": "Soil_Mud_Dry"
    },
    {
      "x": -12,
      "y": 39,
      "z": 9,
      "name": "Plant_Bush_Dead_Tall"
    },
    {
      "x": -12,
      "y": 32,
      "z": 10,
      "name": "Soil_Mud"
    },
    {
      "x": -12,
      "y": 33,
      "z": 10,
      "name": "Soil_Mud"
    },
    {
      "x": -12,
      "y": 34,
      "z": 10,
      "name": "Soil_Mud_Dry"
    },
    {
      "x": -12,
      "y": 35,
      "z": 10,
      "name": "Soil_Mud_Dry"
    },
    {
      "x": -12,
      "y": 36,
      "z": 10,
      "name": "Soil_Mud_Dry"
    },
    {
      "x": -12,
      "y": 37,
      "z": 10,
      "name": "Soil_Mud_Dry"
    },
    {
      "x": -12,
      "y": 38,
      "z": 10,
      "name": "Soil_Mud"
    },
    {
      "x": -12,
      "y": 39,
      "z": 10,
      "name": "Plant_Bush_Dead_Tall"
    },
    {
      "x": -12,
      "y": 33,
      "z": 11,
      "name": "Soil_Mud"
    },
    {
      "x": -12,
      "y": 34,
      "z": 11,
      "name": "Soil_Mud"
    },
    {
      "x": -12,
      "y": 35,
      "z": 11,
      "name": "Soil_Mud"
    },
    {
      "x": -12,
      "y": 36,
      "z": 11,
      "name": "Soil_Mud"
    },
    {
      "x": -12,
      "y": 37,
      "z": 11,
      "name": "Soil_Mud"
    },
    {
      "x": -12,
      "y": 38,
      "z": 11,
      "name": "Soil_Mud"
    },
    {
      "x": -12,
      "y": 34,
      "z": 12,
      "name": "Soil_Mud_Dry"
    },
    {
      "x": -12,
      "y": 35,
      "z": 12,
      "name": "Soil_Mud"
    },
    {
      "x": -12,
      "y": 36,
      "z": 12,
      "name": "Soil_Mud"
    },
    {
      "x": -12,
      "y": 37,
      "z": 12,
      "name": "Soil_Mud"
    },
    {
      "x": -12,
      "y": 38,
      "z": 12,
      "name": "Soil_Mud_Dry"
    },
    {
      "x": -12,
      "y": 36,
      "z": 13,
      "name": "Soil_Mud"
    },
    {
      "x": -12,
      "y": 37,
      "z": 13,
      "name": "Soil_Mud_Dry"
    },
    {
      "x": -12,
      "y": 38,
      "z": 13,
      "name": "Soil_Mud"
    },
    {
      "x": -12,
      "y": 39,
      "z": 13,
      "name": "Soil_Mud"
    },
    {
      "x": -11,
      "y": 28,
      "z": -3,
      "name": "Plant_Moss_Cave_Red"
    },
    {
      "x": -11,
      "y": 29,
      "z": -3,
      "name": "Soil_Mud"
    },
    {
      "x": -11,
      "y": 30,
      "z": -3,
      "name": "Soil_Mud"
    },
    {
      "x": -11,
      "y": 31,
      "z": -3,
      "name": "Soil_Mud_Dry"
    },
    {
      "x": -11,
      "y": 32,
      "z": -3,
      "name": "Soil_Mud"
    },
    {
      "x": -11,
      "y": 33,
      "z": -3,
      "name": "Soil_Mud_Dry"
    },
    {
      "x": -11,
      "y": 34,
      "z": -3,
      "name": "Plant_Crop_Mushroom_Cap_Brown"
    },
    {
      "x": -11,
      "y": 28,
      "z": -2,
      "name": "Soil_Mud"
    },
    {
      "x": -11,
      "y": 29,
      "z": -2,
      "name": "Soil_Mud_Dry"
    },
    {
      "x": -11,
      "y": 30,
      "z": -2,
      "name": "Soil_Mud_Dry"
    },
    {
      "x": -11,
      "y": 31,
      "z": -2,
      "name": "Soil_Mud"
    },
    {
      "x": -11,
      "y": 32,
      "z": -2,
      "name": "Soil_Mud"
    },
    {
      "x": -11,
      "y": 33,
      "z": -2,
      "name": "Soil_Mud"
    },
    {
      "x": -11,
      "y": 34,
      "z": -2,
      "name": "Soil_Mud"
    },
    {
      "x": -11,
      "y": 27,
      "z": -1,
      "name": "Soil_Mud"
    },
    {
      "x": -11,
      "y": 28,
      "z": -1,
      "name": "Soil_Mud"
    },
    {
      "x": -11,
      "y": 29,
      "z": -1,
      "name": "Soil_Mud"
    },
    {
      "x": -11,
      "y": 30,
      "z": -1,
      "name": "Soil_Mud"
    },
    {
      "x": -11,
      "y": 31,
      "z": -1,
      "name": "Soil_Mud"
    },
    {
      "x": -11,
      "y": 32,
      "z": -1,
      "name": "Soil_Mud"
    },
    {
      "x": -11,
      "y": 33,
      "z": -1,
      "name": "Soil_Mud"
    },
    {
      "x": -11,
      "y": 34,
      "z": -1,
      "name": "Soil_Mud_Dry"
    },
    {
      "x": -11,
      "y": 35,
      "z": -1,
      "name": "Soil_Mud_Dry"
    },
    {
      "x": -11,
      "y": 26,
      "z": 0,
      "name": "Soil_Mud"
    },
    {
      "x": -11,
      "y": 27,
      "z": 0,
      "name": "Soil_Mud"
    },
    {
      "x": -11,
      "y": 28,
      "z": 0,
      "name": "Soil_Mud"
    },
    {
      "x": -11,
      "y": 29,
      "z": 0,
      "name": "Soil_Mud"
    },
    {
      "x": -11,
      "y": 30,
      "z": 0,
      "name": "Soil_Mud"
    },
    {
      "x": -11,
      "y": 31,
      "z": 0,
      "name": "Soil_Mud_Dry"
    },
    {
      "x": -11,
      "y": 32,
      "z": 0,
      "name": "Soil_Mud_Dry"
    },
    {
      "x": -11,
      "y": 33,
      "z": 0,
      "name": "Soil_Mud"
    },
    {
      "x": -11,
      "y": 34,
      "z": 0,
      "name": "Soil_Mud"
    },
    {
      "x": -11,
      "y": 35,
      "z": 0,
      "name": "Soil_Mud_Dry"
    },
    {
      "x": -11,
      "y": 36,
      "z": 0,
      "name": "Soil_Mud_Dry"
    },
    {
      "x": -11,
      "y": 26,
      "z": 1,
      "name": "Soil_Mud"
    },
    {
      "x": -11,
      "y": 27,
      "z": 1,
      "name": "Soil_Mud"
    },
    {
      "x": -11,
      "y": 28,
      "z": 1,
      "name": "Soil_Mud"
    },
    {
      "x": -11,
      "y": 29,
      "z": 1,
      "name": "Soil_Mud"
    },
    {
      "x": -11,
      "y": 30,
      "z": 1,
      "name": "Soil_Mud_Dry"
    },
    {
      "x": -11,
      "y": 31,
      "z": 1,
      "name": "Soil_Mud"
    },
    {
      "x": -11,
      "y": 32,
      "z": 1,
      "name": "Soil_Mud"
    },
    {
      "x": -11,
      "y": 33,
      "z": 1,
      "name": "Soil_Mud"
    },
    {
      "x": -11,
      "y": 34,
      "z": 1,
      "name": "Soil_Mud"
    },
    {
      "x": -11,
      "y": 35,
      "z": 1,
      "name": "Soil_Mud"
    },
    {
      "x": -11,
      "y": 36,
      "z": 1,
      "name": "Soil_Mud"
    },
    {
      "x": -11,
      "y": 21,
      "z": 2,
      "name": "Rock_Crystal_Purple_Medium",
      "rotation": 5
    },
    {
      "x": -11,
      "y": 22,
      "z": 2,
      "name": "Rock_Crystal_Purple_Medium",
      "rotation": 5
    },
    {
      "x": -11,
      "y": 25,
      "z": 2,
      "name": "Rock_Crystal_Purple_Large",
      "rotation": 8
    },
    {
      "x": -11,
      "y": 26,
      "z": 2,
      "name": "Soil_Mud"
    },
    {
      "x": -11,
      "y": 27,
      "z": 2,
      "name": "Soil_Mud"
    },
    {
      "x": -11,
      "y": 28,
      "z": 2,
      "name": "Soil_Mud"
    },
    {
      "x": -11,
      "y": 29,
      "z": 2,
      "name": "Soil_Mud_Dry"
    },
    {
      "x": -11,
      "y": 30,
      "z": 2,
      "name": "Soil_Mud_Dry"
    },
    {
      "x": -11,
      "y": 31,
      "z": 2,
      "name": "Soil_Mud"
    },
    {
      "x": -11,
      "y": 32,
      "z": 2,
      "name": "Soil_Mud"
    },
    {
      "x": -11,
      "y": 33,
      "z": 2,
      "name": "Soil_Mud"
    },
    {
      "x": -11,
      "y": 34,
      "z": 2,
      "name": "Soil_Mud"
    },
    {
      "x": -11,
      "y": 35,
      "z": 2,
      "name": "Soil_Mud"
    },
    {
      "x": -11,
      "y": 36,
      "z": 2,
      "name": "Soil_Mud"
    },
    {
      "x": -11,
      "y": 37,
      "z": 2,
      "name": "Soil_Mud"
    },
    {
      "x": -11,
      "y": 26,
      "z": 3,
      "name": "Soil_Mud"
    },
    {
      "x": -11,
      "y": 27,
      "z": 3,
      "name": "Soil_Mud"
    },
    {
      "x": -11,
      "y": 28,
      "z": 3,
      "name": "Soil_Mud"
    },
    {
      "x": -11,
      "y": 29,
      "z": 3,
      "name": "Soil_Mud_Dry"
    },
    {
      "x": -11,
      "y": 30,
      "z": 3,
      "name": "Soil_Mud"
    },
    {
      "x": -11,
      "y": 31,
      "z": 3,
      "name": "Soil_Mud"
    },
    {
      "x": -11,
      "y": 32,
      "z": 3,
      "name": "Soil_Mud_Dry"
    },
    {
      "x": -11,
      "y": 33,
      "z": 3,
      "name": "Soil_Mud"
    },
    {
      "x": -11,
      "y": 34,
      "z": 3,
      "name": "Soil_Mud"
    },
    {
      "x": -11,
      "y": 35,
      "z": 3,
      "name": "Soil_Mud"
    },
    {
      "x": -11,
      "y": 36,
      "z": 3,
      "name": "Soil_Mud_Dry"
    },
    {
      "x": -11,
      "y": 37,
      "z": 3,
      "name": "Soil_Mud"
    },
    {
      "x": -11,
      "y": 38,
      "z": 3,
      "name": "Soil_Mud"
    },
    {
      "x": -11,
      "y": 25,
      "z": 4,
      "name": "Plant_Moss_Cave_Red"
    },
    {
      "x": -11,
      "y": 26,
      "z": 4,
      "name": "Soil_Mud"
    },
    {
      "x": -11,
      "y": 27,
      "z": 4,
      "name": "Soil_Mud"
    },
    {
      "x": -11,
      "y": 28,
      "z": 4,
      "name": "Soil_Mud"
    },
    {
      "x": -11,
      "y": 29,
      "z": 4,
      "name": "Soil_Mud"
    },
    {
      "x": -11,
      "y": 30,
      "z": 4,
      "name": "Soil_Mud"
    },
    {
      "x": -11,
      "y": 31,
      "z": 4,
      "name": "Soil_Mud"
    },
    {
      "x": -11,
      "y": 32,
      "z": 4,
      "name": "Soil_Mud"
    },
    {
      "x": -11,
      "y": 33,
      "z": 4,
      "name": "Soil_Mud"
    },
    {
      "x": -11,
      "y": 34,
      "z": 4,
      "name": "Soil_Mud_Dry"
    },
    {
      "x": -11,
      "y": 35,
      "z": 4,
      "name": "Soil_Mud"
    },
    {
      "x": -11,
      "y": 36,
      "z": 4,
      "name": "Soil_Mud"
    },
    {
      "x": -11,
      "y": 37,
      "z": 4,
      "name": "Soil_Mud_Dry"
    },
    {
      "x": -11,
      "y": 38,
      "z": 4,
      "name": "Soil_Mud"
    },
    {
      "x": -11,
      "y": 27,
      "z": 5,
      "name": "Soil_Mud"
    },
    {
      "x": -11,
      "y": 28,
      "z": 5,
      "name": "Soil_Mud_Dry"
    },
    {
      "x": -11,
      "y": 29,
      "z": 5,
      "name": "Soil_Mud"
    },
    {
      "x": -11,
      "y": 30,
      "z": 5,
      "name": "Soil_Mud"
    },
    {
      "x": -11,
      "y": 31,
      "z": 5,
      "name": "Soil_Mud_Dry"
    },
    {
      "x": -11,
      "y": 32,
      "z": 5,
      "name": "Soil_Mud"
    },
    {
      "x": -11,
      "y": 33,
      "z": 5,
      "name": "Soil_Mud_Dry"
    },
    {
      "x": -11,
      "y": 34,
      "z": 5,
      "name": "Soil_Mud_Dry"
    },
    {
      "x": -11,
      "y": 35,
      "z": 5,
      "name": "Soil_Mud"
    },
    {
      "x": -11,
      "y": 36,
      "z": 5,
      "name": "Soil_Mud_Dry"
    },
    {
      "x": -11,
      "y": 37,
      "z": 5,
      "name": "Soil_Mud_Dry"
    },
    {
      "x": -11,
      "y": 38,
      "z": 5,
      "name": "Soil_Mud_Dry"
    },
    {
      "x": -11,
      "y": 26,
      "z": 6,
      "name": "Soil_Mud"
    },
    {
      "x": -11,
      "y": 27,
      "z": 6,
      "name": "Soil_Mud"
    },
    {
      "x": -11,
      "y": 28,
      "z": 6,
      "name": "Soil_Mud_Dry"
    },
    {
      "x": -11,
      "y": 29,
      "z": 6,
      "name": "Soil_Mud"
    },
    {
      "x": -11,
      "y": 30,
      "z": 6,
      "name": "Soil_Mud"
    },
    {
      "x": -11,
      "y": 31,
      "z": 6,
      "name": "Soil_Mud"
    },
    {
      "x": -11,
      "y": 32,
      "z": 6,
      "name": "Soil_Mud"
    },
    {
      "x": -11,
      "y": 33,
      "z": 6,
      "name": "Soil_Mud"
    },
    {
      "x": -11,
      "y": 34,
      "z": 6,
      "name": "Soil_Mud"
    },
    {
      "x": -11,
      "y": 35,
      "z": 6,
      "name": "Soil_Mud_Dry"
    },
    {
      "x": -11,
      "y": 36,
      "z": 6,
      "name": "Soil_Mud"
    },
    {
      "x": -11,
      "y": 37,
      "z": 6,
      "name": "Soil_Mud_Dry"
    },
    {
      "x": -11,
      "y": 38,
      "z": 6,
      "name": "Soil_Mud"
    },
    {
      "x": -11,
      "y": 28,
      "z": 7,
      "name": "Soil_Mud"
    },
    {
      "x": -11,
      "y": 29,
      "z": 7,
      "name": "Soil_Mud_Dry"
    },
    {
      "x": -11,
      "y": 30,
      "z": 7,
      "name": "Soil_Mud"
    },
    {
      "x": -11,
      "y": 31,
      "z": 7,
      "name": "Soil_Mud"
    },
    {
      "x": -11,
      "y": 32,
      "z": 7,
      "name": "Soil_Mud"
    },
    {
      "x": -11,
      "y": 33,
      "z": 7,
      "name": "Soil_Mud"
    },
    {
      "x": -11,
      "y": 34,
      "z": 7,
      "name": "Soil_Mud"
    },
    {
      "x": -11,
      "y": 35,
      "z": 7,
      "name": "Soil_Mud"
    },
    {
      "x": -11,
      "y": 36,
      "z": 7,
      "name": "Soil_Mud_Dry"
    },
    {
      "x": -11,
      "y": 37,
      "z": 7,
      "name": "Soil_Mud"
    },
    {
      "x": -11,
      "y": 38,
      "z": 7,
      "name": "Soil_Mud_Dry"
    },
    {
      "x": -11,
      "y": 29,
      "z": 8,
      "name": "Soil_Mud_Dry"
    },
    {
      "x": -11,
      "y": 30,
      "z": 8,
      "name": "Soil_Mud"
    },
    {
      "x": -11,
      "y": 31,
      "z": 8,
      "name": "Soil_Mud_Dry"
    },
    {
      "x": -11,
      "y": 32,
      "z": 8,
      "name": "Soil_Mud"
    },
    {
      "x": -11,
      "y": 33,
      "z": 8,
      "name": "Soil_Mud"
    },
    {
      "x": -11,
      "y": 34,
      "z": 8,
      "name": "Soil_Mud"
    },
    {
      "x": -11,
      "y": 35,
      "z": 8,
      "name": "Soil_Mud"
    },
    {
      "x": -11,
      "y": 36,
      "z": 8,
      "name": "Soil_Mud_Dry"
    },
    {
      "x": -11,
      "y": 37,
      "z": 8,
      "name": "Soil_Mud"
    },
    {
      "x": -11,
      "y": 38,
      "z": 8,
      "name": "Soil_Mud"
    },
    {
      "x": -11,
      "y": 31,
      "z": 9,
      "name": "Soil_Mud"
    },
    {
      "x": -11,
      "y": 32,
      "z": 9,
      "name": "Soil_Mud"
    },
    {
      "x": -11,
      "y": 33,
      "z": 9,
      "name": "Soil_Mud"
    },
    {
      "x": -11,
      "y": 34,
      "z": 9,
      "name": "Soil_Mud_Dry"
    },
    {
      "x": -11,
      "y": 35,
      "z": 9,
      "name": "Soil_Mud_Dry"
    },
    {
      "x": -11,
      "y": 36,
      "z": 9,
      "name": "Soil_Mud"
    },
    {
      "x": -11,
      "y": 37,
      "z": 9,
      "name": "Soil_Mud"
    },
    {
      "x": -11,
      "y": 38,
      "z": 9,
      "name": "Soil_Mud_Dry"
    },
    {
      "x": -11,
      "y": 39,
      "z": 9,
      "name": "Soil_Mud"
    },
    {
      "x": -11,
      "y": 40,
      "z": 9,
      "name": "Plant_Bush_Dead_Tall"
    },
    {
      "x": -11,
      "y": 31,
      "z": 10,
      "name": "Soil_Mud"
    },
    {
      "x": -11,
      "y": 32,
      "z": 10,
      "name": "Soil_Mud"
    },
    {
      "x": -11,
      "y": 33,
      "z": 10,
      "name": "Soil_Mud_Dry"
    },
    {
      "x": -11,
      "y": 34,
      "z": 10,
      "name": "Soil_Mud"
    },
    {
      "x": -11,
      "y": 35,
      "z": 10,
      "name": "Soil_Mud"
    },
    {
      "x": -11,
      "y": 36,
      "z": 10,
      "name": "Soil_Mud"
    },
    {
      "x": -11,
      "y": 37,
      "z": 10,
      "name": "Soil_Mud_Dry"
    },
    {
      "x": -11,
      "y": 38,
      "z": 10,
      "name": "Soil_Mud"
    },
    {
      "x": -11,
      "y": 39,
      "z": 10,
      "name": "Soil_Mud_Dry"
    },
    {
      "x": -11,
      "y": 31,
      "z": 11,
      "name": "Soil_Mud_Dry"
    },
    {
      "x": -11,
      "y": 32,
      "z": 11,
      "name": "Soil_Mud"
    },
    {
      "x": -11,
      "y": 33,
      "z": 11,
      "name": "Soil_Mud_Dry"
    },
    {
      "x": -11,
      "y": 34,
      "z": 11,
      "name": "Soil_Mud_Dry"
    },
    {
      "x": -11,
      "y": 35,
      "z": 11,
      "name": "Soil_Mud"
    },
    {
      "x": -11,
      "y": 36,
      "z": 11,
      "name": "Soil_Mud"
    },
    {
      "x": -11,
      "y": 37,
      "z": 11,
      "name": "Soil_Mud_Dry"
    },
    {
      "x": -11,
      "y": 38,
      "z": 11,
      "name": "Soil_Mud"
    },
    {
      "x": -11,
      "y": 39,
      "z": 11,
      "name": "Soil_Mud_Dry"
    },
    {
      "x": -11,
      "y": 40,
      "z": 11,
      "name": "Plant_Crop_Mushroom_Cap_Brown"
    },
    {
      "x": -11,
      "y": 32,
      "z": 12,
      "name": "Soil_Mud_Dry"
    },
    {
      "x": -11,
      "y": 33,
      "z": 12,
      "name": "Soil_Mud"
    },
    {
      "x": -11,
      "y": 34,
      "z": 12,
      "name": "Soil_Mud"
    },
    {
      "x": -11,
      "y": 35,
      "z": 12,
      "name": "Soil_Mud"
    },
    {
      "x": -11,
      "y": 36,
      "z": 12,
      "name": "Soil_Mud"
    },
    {
      "x": -11,
      "y": 37,
      "z": 12,
      "name": "Soil_Mud_Dry"
    },
    {
      "x": -11,
      "y": 38,
      "z": 12,
      "name": "Soil_Mud"
    },
    {
      "x": -11,
      "y": 39,
      "z": 12,
      "name": "Soil_Mud"
    },
    {
      "x": -11,
      "y": 33,
      "z": 13,
      "name": "Soil_Mud_Dry"
    },
    {
      "x": -11,
      "y": 34,
      "z": 13,
      "name": "Soil_Mud"
    },
    {
      "x": -11,
      "y": 35,
      "z": 13,
      "name": "Soil_Mud"
    },
    {
      "x": -11,
      "y": 36,
      "z": 13,
      "name": "Soil_Mud"
    },
    {
      "x": -11,
      "y": 37,
      "z": 13,
      "name": "Soil_Mud"
    },
    {
      "x": -11,
      "y": 38,
      "z": 13,
      "name": "Soil_Mud_Dry"
    },
    {
      "x": -11,
      "y": 39,
      "z": 13,
      "name": "Soil_Mud"
    },
    {
      "x": -11,
      "y": 36,
      "z": 14,
      "name": "Soil_Mud"
    },
    {
      "x": -11,
      "y": 37,
      "z": 14,
      "name": "Soil_Mud"
    },
    {
      "x": -11,
      "y": 38,
      "z": 14,
      "name": "Soil_Mud"
    },
    {
      "x": -11,
      "y": 39,
      "z": 14,
      "name": "Soil_Mud_Dry"
    },
    {
      "x": -10,
      "y": 33,
      "z": -3,
      "name": "Soil_Mud"
    },
    {
      "x": -10,
      "y": 34,
      "z": -3,
      "name": "Plant_Moss_Rug_Pink"
    },
    {
      "x": -10,
      "y": 12,
      "z": -2,
      "name": "Plant_Crop_Mushroom_Shelve_Brown"
    },
    {
      "x": -10,
      "y": 29,
      "z": -2,
      "name": "Soil_Mud"
    },
    {
      "x": -10,
      "y": 30,
      "z": -2,
      "name": "Soil_Mud"
    },
    {
      "x": -10,
      "y": 31,
      "z": -2,
      "name": "Soil_Mud"
    },
    {
      "x": -10,
      "y": 32,
      "z": -2,
      "name": "Soil_Mud_Dry"
    },
    {
      "x": -10,
      "y": 33,
      "z": -2,
      "name": "Soil_Mud"
    },
    {
      "x": -10,
      "y": 34,
      "z": -2,
      "name": "Soil_Mud"
    },
    {
      "x": -10,
      "y": 35,
      "z": -2,
      "name": "Plant_Moss_Rug_Pink"
    },
    {
      "x": -10,
      "y": 11,
      "z": -1,
      "name": "Plant_Crop_Mushroom_Shelve_Brown"
    },
    {
      "x": -10,
      "y": 28,
      "z": -1,
      "name": "Soil_Mud"
    },
    {
      "x": -10,
      "y": 29,
      "z": -1,
      "name": "Soil_Mud"
    },
    {
      "x": -10,
      "y": 30,
      "z": -1,
      "name": "Soil_Mud"
    },
    {
      "x": -10,
      "y": 31,
      "z": -1,
      "name": "Soil_Mud"
    },
    {
      "x": -10,
      "y": 32,
      "z": -1,
      "name": "Soil_Mud"
    },
    {
      "x": -10,
      "y": 33,
      "z": -1,
      "name": "Soil_Mud"
    },
    {
      "x": -10,
      "y": 34,
      "z": -1,
      "name": "Soil_Mud"
    },
    {
      "x": -10,
      "y": 35,
      "z": -1,
      "name": "Soil_Mud"
    },
    {
      "x": -10,
      "y": 36,
      "z": -1,
      "name": "Plant_Moss_Rug_Pink"
    },
    {
      "x": -10,
      "y": 27,
      "z": 0,
      "name": "Soil_Mud_Dry"
    },
    {
      "x": -10,
      "y": 28,
      "z": 0,
      "name": "Soil_Mud"
    },
    {
      "x": -10,
      "y": 29,
      "z": 0,
      "name": "Soil_Mud_Dry"
    },
    {
      "x": -10,
      "y": 30,
      "z": 0,
      "name": "Soil_Mud"
    },
    {
      "x": -10,
      "y": 31,
      "z": 0,
      "name": "Soil_Mud"
    },
    {
      "x": -10,
      "y": 32,
      "z": 0,
      "name": "Soil_Mud_Dry"
    },
    {
      "x": -10,
      "y": 33,
      "z": 0,
      "name": "Soil_Mud"
    },
    {
      "x": -10,
      "y": 34,
      "z": 0,
      "name": "Soil_Mud"
    },
    {
      "x": -10,
      "y": 35,
      "z": 0,
      "name": "Soil_Mud"
    },
    {
      "x": -10,
      "y": 36,
      "z": 0,
      "name": "Plant_Crop_Mushroom_Glowing_Purple"
    },
    {
      "x": -10,
      "y": 27,
      "z": 1,
      "name": "Soil_Mud"
    },
    {
      "x": -10,
      "y": 28,
      "z": 1,
      "name": "Soil_Mud"
    },
    {
      "x": -10,
      "y": 29,
      "z": 1,
      "name": "Soil_Mud"
    },
    {
      "x": -10,
      "y": 30,
      "z": 1,
      "name": "Soil_Mud"
    },
    {
      "x": -10,
      "y": 31,
      "z": 1,
      "name": "Soil_Mud"
    },
    {
      "x": -10,
      "y": 32,
      "z": 1,
      "name": "Soil_Mud_Dry"
    },
    {
      "x": -10,
      "y": 33,
      "z": 1,
      "name": "Soil_Mud_Dry"
    },
    {
      "x": -10,
      "y": 34,
      "z": 1,
      "name": "Soil_Mud"
    },
    {
      "x": -10,
      "y": 35,
      "z": 1,
      "name": "Soil_Mud_Dry"
    },
    {
      "x": -10,
      "y": 36,
      "z": 1,
      "name": "Soil_Mud"
    },
    {
      "x": -10,
      "y": 27,
      "z": 2,
      "name": "Soil_Mud"
    },
    {
      "x": -10,
      "y": 28,
      "z": 2,
      "name": "Soil_Mud"
    },
    {
      "x": -10,
      "y": 29,
      "z": 2,
      "name": "Soil_Mud"
    },
    {
      "x": -10,
      "y": 30,
      "z": 2,
      "name": "Soil_Mud_Dry"
    },
    {
      "x": -10,
      "y": 31,
      "z": 2,
      "name": "Soil_Mud"
    },
    {
      "x": -10,
      "y": 32,
      "z": 2,
      "name": "Soil_Mud_Dry"
    },
    {
      "x": -10,
      "y": 33,
      "z": 2,
      "name": "Soil_Mud"
    },
    {
      "x": -10,
      "y": 34,
      "z": 2,
      "name": "Soil_Mud"
    },
    {
      "x": -10,
      "y": 35,
      "z": 2,
      "name": "Soil_Mud"
    },
    {
      "x": -10,
      "y": 36,
      "z": 2,
      "name": "Soil_Mud_Dry"
    },
    {
      "x": -10,
      "y": 37,
      "z": 2,
      "name": "Soil_Mud_Dry"
    },
    {
      "x": -10,
      "y": 27,
      "z": 3,
      "name": "Soil_Mud_Dry"
    },
    {
      "x": -10,
      "y": 28,
      "z": 3,
      "name": "Soil_Mud_Dry"
    },
    {
      "x": -10,
      "y": 29,
      "z": 3,
      "name": "Soil_Mud_Dry"
    },
    {
      "x": -10,
      "y": 30,
      "z": 3,
      "name": "Soil_Mud"
    },
    {
      "x": -10,
      "y": 31,
      "z": 3,
      "name": "Soil_Mud"
    },
    {
      "x": -10,
      "y": 32,
      "z": 3,
      "name": "Soil_Mud"
    },
    {
      "x": -10,
      "y": 33,
      "z": 3,
      "name": "Soil_Mud"
    },
    {
      "x": -10,
      "y": 34,
      "z": 3,
      "name": "Soil_Mud_Dry"
    },
    {
      "x": -10,
      "y": 35,
      "z": 3,
      "name": "Soil_Mud_Dry"
    },
    {
      "x": -10,
      "y": 36,
      "z": 3,
      "name": "Soil_Mud"
    },
    {
      "x": -10,
      "y": 37,
      "z": 3,
      "name": "Soil_Mud"
    },
    {
      "x": -10,
      "y": 26,
      "z": 4,
      "name": "Soil_Mud_Dry"
    },
    {
      "x": -10,
      "y": 27,
      "z": 4,
      "name": "Soil_Mud"
    },
    {
      "x": -10,
      "y": 28,
      "z": 4,
      "name": "Soil_Mud_Dry"
    },
    {
      "x": -10,
      "y": 29,
      "z": 4,
      "name": "Soil_Mud"
    },
    {
      "x": -10,
      "y": 30,
      "z": 4,
      "name": "Soil_Mud"
    },
    {
      "x": -10,
      "y": 31,
      "z": 4,
      "name": "Soil_Mud_Dry"
    },
    {
      "x": -10,
      "y": 32,
      "z": 4,
      "name": "Soil_Mud"
    },
    {
      "x": -10,
      "y": 33,
      "z": 4,
      "name": "Soil_Mud"
    },
    {
      "x": -10,
      "y": 34,
      "z": 4,
      "name": "Soil_Mud"
    },
    {
      "x": -10,
      "y": 35,
      "z": 4,
      "name": "Soil_Mud"
    },
    {
      "x": -10,
      "y": 36,
      "z": 4,
      "name": "Soil_Mud"
    },
    {
      "x": -10,
      "y": 37,
      "z": 4,
      "name": "Soil_Mud"
    },
    {
      "x": -10,
      "y": 38,
      "z": 4,
      "name": "Soil_Mud"
    },
    {
      "x": -10,
      "y": 26,
      "z": 5,
      "name": "Soil_Mud"
    },
    {
      "x": -10,
      "y": 27,
      "z": 5,
      "name": "Soil_Mud_Dry"
    },
    {
      "x": -10,
      "y": 28,
      "z": 5,
      "name": "Soil_Mud"
    },
    {
      "x": -10,
      "y": 29,
      "z": 5,
      "name": "Soil_Mud_Dry"
    },
    {
      "x": -10,
      "y": 30,
      "z": 5,
      "name": "Soil_Mud"
    },
    {
      "x": -10,
      "y": 31,
      "z": 5,
      "name": "Soil_Mud"
    },
    {
      "x": -10,
      "y": 32,
      "z": 5,
      "name": "Soil_Mud_Dry"
    },
    {
      "x": -10,
      "y": 33,
      "z": 5,
      "name": "Soil_Mud"
    },
    {
      "x": -10,
      "y": 34,
      "z": 5,
      "name": "Soil_Mud_Dry"
    },
    {
      "x": -10,
      "y": 35,
      "z": 5,
      "name": "Soil_Mud"
    },
    {
      "x": -10,
      "y": 36,
      "z": 5,
      "name": "Soil_Mud"
    },
    {
      "x": -10,
      "y": 37,
      "z": 5,
      "name": "Soil_Mud_Dry"
    },
    {
      "x": -10,
      "y": 38,
      "z": 5,
      "name": "Soil_Mud"
    },
    {
      "x": -10,
      "y": 39,
      "z": 5,
      "name": "Plant_Crop_Mushroom_Glowing_Purple"
    },
    {
      "x": -10,
      "y": 26,
      "z": 6,
      "name": "Soil_Mud"
    },
    {
      "x": -10,
      "y": 27,
      "z": 6,
      "name": "Soil_Mud"
    },
    {
      "x": -10,
      "y": 28,
      "z": 6,
      "name": "Soil_Mud_Dry"
    },
    {
      "x": -10,
      "y": 29,
      "z": 6,
      "name": "Soil_Mud"
    },
    {
      "x": -10,
      "y": 30,
      "z": 6,
      "name": "Soil_Mud"
    },
    {
      "x": -10,
      "y": 31,
      "z": 6,
      "name": "Soil_Mud_Dry"
    },
    {
      "x": -10,
      "y": 32,
      "z": 6,
      "name": "Soil_Mud"
    },
    {
      "x": -10,
      "y": 33,
      "z": 6,
      "name": "Soil_Mud_Dry"
    },
    {
      "x": -10,
      "y": 34,
      "z": 6,
      "name": "Soil_Mud"
    },
    {
      "x": -10,
      "y": 35,
      "z": 6,
      "name": "Soil_Mud"
    },
    {
      "x": -10,
      "y": 36,
      "z": 6,
      "name": "Soil_Mud_Dry"
    },
    {
      "x": -10,
      "y": 37,
      "z": 6,
      "name": "Soil_Mud"
    },
    {
      "x": -10,
      "y": 38,
      "z": 6,
      "name": "Soil_Mud_Dry"
    },
    {
      "x": -10,
      "y": 25,
      "z": 7,
      "name": "Soil_Mud_Dry"
    },
    {
      "x": -10,
      "y": 26,
      "z": 7,
      "name": "Soil_Mud"
    },
    {
      "x": -10,
      "y": 27,
      "z": 7,
      "name": "Soil_Mud_Dry"
    },
    {
      "x": -10,
      "y": 28,
      "z": 7,
      "name": "Soil_Mud"
    },
    {
      "x": -10,
      "y": 29,
      "z": 7,
      "name": "Soil_Mud_Dry"
    },
    {
      "x": -10,
      "y": 30,
      "z": 7,
      "name": "Soil_Mud"
    },
    {
      "x": -10,
      "y": 31,
      "z": 7,
      "name": "Soil_Mud_Dry"
    },
    {
      "x": -10,
      "y": 32,
      "z": 7,
      "name": "Soil_Mud"
    },
    {
      "x": -10,
      "y": 33,
      "z": 7,
      "name": "Soil_Mud_Dry"
    },
    {
      "x": -10,
      "y": 34,
      "z": 7,
      "name": "Soil_Mud"
    },
    {
      "x": -10,
      "y": 35,
      "z": 7,
      "name": "Soil_Mud_Dry"
    },
    {
      "x": -10,
      "y": 36,
      "z": 7,
      "name": "Soil_Mud"
    },
    {
      "x": -10,
      "y": 37,
      "z": 7,
      "name": "Soil_Mud_Dry"
    },
    {
      "x": -10,
      "y": 38,
      "z": 7,
      "name": "Soil_Mud_Dry"
    },
    {
      "x": -10,
      "y": 39,
      "z": 7,
      "name": "Plant_Crop_Mushroom_Glowing_Purple"
    },
    {
      "x": -10,
      "y": 28,
      "z": 8,
      "name": "Soil_Mud_Dry"
    },
    {
      "x": -10,
      "y": 29,
      "z": 8,
      "name": "Soil_Mud"
    },
    {
      "x": -10,
      "y": 30,
      "z": 8,
      "name": "Soil_Mud"
    },
    {
      "x": -10,
      "y": 31,
      "z": 8,
      "name": "Soil_Mud"
    },
    {
      "x": -10,
      "y": 32,
      "z": 8,
      "name": "Soil_Mud"
    },
    {
      "x": -10,
      "y": 33,
      "z": 8,
      "name": "Soil_Mud_Dry"
    },
    {
      "x": -10,
      "y": 34,
      "z": 8,
      "name": "Soil_Mud"
    },
    {
      "x": -10,
      "y": 35,
      "z": 8,
      "name": "Soil_Mud_Dry"
    },
    {
      "x": -10,
      "y": 36,
      "z": 8,
      "name": "Soil_Mud"
    },
    {
      "x": -10,
      "y": 37,
      "z": 8,
      "name": "Soil_Mud"
    },
    {
      "x": -10,
      "y": 38,
      "z": 8,
      "name": "Soil_Mud_Dry"
    },
    {
      "x": -10,
      "y": 39,
      "z": 8,
      "name": "Soil_Mud"
    },
    {
      "x": -10,
      "y": 30,
      "z": 9,
      "name": "Soil_Mud"
    },
    {
      "x": -10,
      "y": 31,
      "z": 9,
      "name": "Soil_Mud"
    },
    {
      "x": -10,
      "y": 32,
      "z": 9,
      "name": "Soil_Mud"
    },
    {
      "x": -10,
      "y": 33,
      "z": 9,
      "name": "Soil_Mud"
    },
    {
      "x": -10,
      "y": 34,
      "z": 9,
      "name": "Soil_Mud"
    },
    {
      "x": -10,
      "y": 35,
      "z": 9,
      "name": "Soil_Mud_Dry"
    },
    {
      "x": -10,
      "y": 36,
      "z": 9,
      "name": "Soil_Mud"
    },
    {
      "x": -10,
      "y": 37,
      "z": 9,
      "name": "Soil_Mud"
    },
    {
      "x": -10,
      "y": 38,
      "z": 9,
      "name": "Soil_Mud_Dry"
    },
    {
      "x": -10,
      "y": 39,
      "z": 9,
      "name": "Soil_Mud_Dry"
    },
    {
      "x": -10,
      "y": 27,
      "z": 10,
      "name": "Rock_Crystal_Purple_Medium",
      "rotation": 7
    },
    {
      "x": -10,
      "y": 29,
      "z": 10,
      "name": "Rock_Crystal_Purple_Medium",
      "rotation": 7
    },
    {
      "x": -10,
      "y": 30,
      "z": 10,
      "name": "Soil_Mud"
    },
    {
      "x": -10,
      "y": 31,
      "z": 10,
      "name": "Soil_Mud_Dry"
    },
    {
      "x": -10,
      "y": 32,
      "z": 10,
      "name": "Soil_Mud"
    },
    {
      "x": -10,
      "y": 33,
      "z": 10,
      "name": "Soil_Mud_Dry"
    },
    {
      "x": -10,
      "y": 34,
      "z": 10,
      "name": "Soil_Mud"
    },
    {
      "x": -10,
      "y": 35,
      "z": 10,
      "name": "Soil_Mud"
    },
    {
      "x": -10,
      "y": 36,
      "z": 10,
      "name": "Soil_Mud"
    },
    {
      "x": -10,
      "y": 37,
      "z": 10,
      "name": "Soil_Mud_Dry"
    },
    {
      "x": -10,
      "y": 38,
      "z": 10,
      "name": "Soil_Mud"
    },
    {
      "x": -10,
      "y": 39,
      "z": 10,
      "name": "Soil_Mud"
    },
    {
      "x": -10,
      "y": 30,
      "z": 11,
      "name": "Soil_Mud"
    },
    {
      "x": -10,
      "y": 31,
      "z": 11,
      "name": "Soil_Mud"
    },
    {
      "x": -10,
      "y": 32,
      "z": 11,
      "name": "Soil_Mud"
    },
    {
      "x": -10,
      "y": 33,
      "z": 11,
      "name": "Soil_Mud"
    },
    {
      "x": -10,
      "y": 34,
      "z": 11,
      "name": "Soil_Mud"
    },
    {
      "x": -10,
      "y": 35,
      "z": 11,
      "name": "Soil_Mud"
    },
    {
      "x": -10,
      "y": 36,
      "z": 11,
      "name": "Soil_Mud"
    },
    {
      "x": -10,
      "y": 37,
      "z": 11,
      "name": "Soil_Mud"
    },
    {
      "x": -10,
      "y": 38,
      "z": 11,
      "name": "Soil_Mud"
    },
    {
      "x": -10,
      "y": 39,
      "z": 11,
      "name": "Soil_Mud_Dry"
    },
    {
      "x": -10,
      "y": 31,
      "z": 12,
      "name": "Soil_Mud_Dry"
    },
    {
      "x": -10,
      "y": 32,
      "z": 12,
      "name": "Soil_Mud"
    },
    {
      "x": -10,
      "y": 33,
      "z": 12,
      "name": "Soil_Mud"
    },
    {
      "x": -10,
      "y": 34,
      "z": 12,
      "name": "Soil_Mud"
    },
    {
      "x": -10,
      "y": 35,
      "z": 12,
      "name": "Soil_Mud"
    },
    {
      "x": -10,
      "y": 36,
      "z": 12,
      "name": "Soil_Mud_Dry"
    },
    {
      "x": -10,
      "y": 37,
      "z": 12,
      "name": "Soil_Mud_Dry"
    },
    {
      "x": -10,
      "y": 38,
      "z": 12,
      "name": "Soil_Mud"
    },
    {
      "x": -10,
      "y": 39,
      "z": 12,
      "name": "Soil_Mud"
    },
    {
      "x": -10,
      "y": 32,
      "z": 13,
      "name": "Soil_Mud"
    },
    {
      "x": -10,
      "y": 33,
      "z": 13,
      "name": "Soil_Mud"
    },
    {
      "x": -10,
      "y": 34,
      "z": 13,
      "name": "Soil_Mud"
    },
    {
      "x": -10,
      "y": 35,
      "z": 13,
      "name": "Soil_Mud"
    },
    {
      "x": -10,
      "y": 36,
      "z": 13,
      "name": "Soil_Mud_Dry"
    },
    {
      "x": -10,
      "y": 37,
      "z": 13,
      "name": "Soil_Mud"
    },
    {
      "x": -10,
      "y": 38,
      "z": 13,
      "name": "Soil_Mud"
    },
    {
      "x": -10,
      "y": 39,
      "z": 13,
      "name": "Soil_Mud_Dry"
    },
    {
      "x": -10,
      "y": 34,
      "z": 14,
      "name": "Soil_Mud"
    },
    {
      "x": -10,
      "y": 35,
      "z": 14,
      "name": "Soil_Mud"
    },
    {
      "x": -10,
      "y": 36,
      "z": 14,
      "name": "Soil_Mud"
    },
    {
      "x": -10,
      "y": 37,
      "z": 14,
      "name": "Soil_Mud_Dry"
    },
    {
      "x": -10,
      "y": 38,
      "z": 14,
      "name": "Soil_Mud_Dry"
    },
    {
      "x": -10,
      "y": 39,
      "z": 14,
      "name": "Soil_Mud"
    },
    {
      "x": -10,
      "y": 39,
      "z": 15,
      "name": "Soil_Mud"
    },
    {
      "x": -9,
      "y": 11,
      "z": -4,
      "name": "Soil_Mud_Dry"
    },
    {
      "x": -9,
      "y": 12,
      "z": -4,
      "name": "Soil_Mud_Dry"
    },
    {
      "x": -9,
      "y": 13,
      "z": -4,
      "name": "Plant_Crop_Mushroom_Shelve_Brown"
    },
    {
      "x": -9,
      "y": 11,
      "z": -3,
      "name": "Soil_Mud"
    },
    {
      "x": -9,
      "y": 12,
      "z": -3,
      "name": "Soil_Mud"
    },
    {
      "x": -9,
      "y": 13,
      "z": -3,
      "name": "Plant_Crop_Mushroom_Shelve_Brown"
    },
    {
      "x": -9,
      "y": 10,
      "z": -2,
      "name": "Soil_Mud"
    },
    {
      "x": -9,
      "y": 11,
      "z": -2,
      "name": "Soil_Mud"
    },
    {
      "x": -9,
      "y": 12,
      "z": -2,
      "name": "Soil_Mud_Dry"
    },
    {
      "x": -9,
      "y": 32,
      "z": -2,
      "name": "Soil_Mud_Dry"
    },
    {
      "x": -9,
      "y": 33,
      "z": -2,
      "name": "Soil_Mud"
    },
