{
  "version": 8,
  "blockIdVersion": 11,
  "anchorX": 0,
  "anchorY": 0,
  "anchorZ": 0,
  "blocks": [
    {
      "x": -18,
      "y": 14,
      "z": 3,
      "name": "Ore_Iron_Basalt_Cracked"
    },
    {
      "x": -18,
      "y": 15,
      "z": 3,
      "name": "Ore_Iron_Basalt_Cracked"
    },
    {
      "x": -18,
      "y": 16,
      "z": 3,
      "name": "Rock_Basalt"
    },
    {
      "x": -18,
      "y": 17,
      "z": 3,
      "name": "Rock_Basalt"
    },
    {
      "x": -18,
      "y": 13,
      "z": 4,
      "name": "Rock_Basalt"
    },
    {
      "x": -18,
      "y": 14,
      "z": 4,
      "name": "Rock_Basalt"
    },
    {
      "x": -18,
      "y": 15,
      "z": 4,
      "name": "Rock_Basalt"
    },
    {
      "x": -18,
      "y": 16,
      "z": 4,
      "name": "Rock_Basalt"
    },
    {
      "x": -18,
      "y": 17,
      "z": 4,
      "name": "Rock_Basalt"
    },
    {
      "x": -18,
      "y": 14,
      "z": 5,
      "name": "Ore_Iron_Basalt_Cracked"
    },
    {
      "x": -18,
      "y": 15,
      "z": 5,
      "name": "Rock_Basalt"
    },
    {
      "x": -18,
      "y": 16,
      "z": 5,
      "name": "Rock_Basalt"
    },
    {
      "x": -18,
      "y": 17,
      "z": 5,
      "name": "Rock_Basalt"
    },
    {
      "x": -18,
      "y": 14,
      "z": 6,
      "name": "Rock_Basalt"
    },
    {
      "x": -18,
      "y": 15,
      "z": 6,
      "name": "Rock_Basalt"
    },
    {
      "x": -18,
      "y": 16,
      "z": 6,
      "name": "Rock_Basalt"
    },
    {
      "x": -18,
      "y": 17,
      "z": 6,
      "name": "Rock_Basalt"
    },
    {
      "x": -18,
      "y": 15,
      "z": 7,
      "name": "Rock_Basalt"
    },
    {
      "x": -18,
      "y": 16,
      "z": 7,
      "name": "Rock_Basalt"
    },
    {
      "x": -18,
      "y": 14,
      "z": 8,
      "name": "Rock_Basalt"
    },
    {
      "x": -18,
      "y": 15,
      "z": 8,
      "name": "Rock_Basalt"
    },
    {
      "x": -18,
      "y": 16,
      "z": 8,
      "name": "Ore_Iron_Basalt_Cracked"
    },
    {
      "x": -18,
      "y": 14,
      "z": 9,
      "name": "Ore_Iron_Basalt_Cracked"
    },
    {
      "x": -18,
      "y": 15,
      "z": 9,
      "name": "Rock_Basalt"
    },
    {
      "x": -18,
      "y": 16,
      "z": 9,
      "name": "Rock_Basalt"
    },
    {
      "x": -18,
      "y": 14,
      "z": 10,
      "name": "Rock_Basalt"
    },
    {
      "x": -18,
      "y": 15,
      "z": 10,
      "name": "Rock_Basalt"
    },
    {
      "x": -17,
      "y": 16,
      "z": -14,
      "name": "Rock_Basalt"
    },
    {
      "x": -17,
      "y": 17,
      "z": -14,
      "name": "Rock_Basalt"
    },
    {
      "x": -17,
      "y": 13,
      "z": -13,
      "name": "Rock_Basalt_Stalactite_Large",
      "filler": 31744,
      "rotation": 8
    },
    {
      "x": -17,
      "y": 14,
      "z": -13,
      "name": "Rock_Basalt_Stalactite_Large",
      "rotation": 8
    },
    {
      "x": -17,
      "y": 15,
      "z": -13,
      "name": "Rock_Basalt"
    },
    {
      "x": -17,
      "y": 16,
      "z": -13,
      "name": "Rock_Basalt"
    },
    {
      "x": -17,
      "y": 17,
      "z": -13,
      "name": "Rock_Basalt"
    },
    {
      "x": -17,
      "y": 18,
      "z": -13,
      "name": "Rock_Basalt"
    },
    {
      "x": -17,
      "y": 15,
      "z": -12,
      "name": "Rock_Basalt"
    },
    {
      "x": -17,
      "y": 16,
      "z": -12,
      "name": "Rock_Basalt"
    },
    {
      "x": -17,
      "y": 17,
      "z": -12,
      "name": "Rock_Basalt"
    },
    {
      "x": -17,
      "y": 14,
      "z": 2,
      "name": "Rock_Basalt"
    },
    {
      "x": -17,
      "y": 15,
      "z": 2,
      "name": "Ore_Iron_Basalt_Cracked"
    },
    {
      "x": -17,
      "y": 16,
      "z": 2,
      "name": "Ore_Iron_Basalt_Cracked"
    },
    {
      "x": -17,
      "y": 17,
      "z": 2,
      "name": "Rock_Basalt"
    },
    {
      "x": -17,
      "y": 18,
      "z": 2,
      "name": "Rubble_Basalt"
    },
    {
      "x": -17,
      "y": 12,
      "z": 3,
      "name": "Rock_Basalt"
    },
    {
      "x": -17,
      "y": 13,
      "z": 3,
      "name": "Rock_Basalt"
    },
    {
      "x": -17,
      "y": 14,
      "z": 3,
      "name": "Rock_Basalt"
    },
    {
      "x": -17,
      "y": 15,
      "z": 3,
      "name": "Rock_Basalt"
    },
    {
      "x": -17,
      "y": 16,
      "z": 3,
      "name": "Rock_Basalt"
    },
    {
      "x": -17,
      "y": 17,
      "z": 3,
      "name": "Rock_Basalt"
    },
    {
      "x": -17,
      "y": 11,
      "z": 4,
      "name": "Rock_Basalt"
    },
    {
      "x": -17,
      "y": 12,
      "z": 4,
      "name": "Rock_Basalt"
    },
    {
      "x": -17,
      "y": 13,
      "z": 4,
      "name": "Rock_Basalt"
    },
    {
      "x": -17,
      "y": 14,
      "z": 4,
      "name": "Rock_Basalt"
    },
    {
      "x": -17,
      "y": 15,
      "z": 4,
      "name": "Rock_Basalt"
    },
    {
      "x": -17,
      "y": 16,
      "z": 4,
      "name": "Rock_Basalt"
    },
    {
      "x": -17,
      "y": 17,
      "z": 4,
      "name": "Rock_Basalt"
    },
    {
      "x": -17,
      "y": 18,
      "z": 4,
      "name": "Rock_Basalt"
    },
    {
      "x": -17,
      "y": 11,
      "z": 5,
      "name": "Ore_Iron_Basalt_Cracked"
    },
    {
      "x": -17,
      "y": 12,
      "z": 5,
      "name": "Rock_Basalt"
    },
    {
      "x": -17,
      "y": 13,
      "z": 5,
      "name": "Rock_Basalt"
    },
    {
      "x": -17,
      "y": 14,
      "z": 5,
      "name": "Rock_Basalt"
    },
    {
      "x": -17,
      "y": 15,
      "z": 5,
      "name": "Rock_Basalt"
    },
    {
      "x": -17,
      "y": 16,
      "z": 5,
      "name": "Rock_Basalt"
    },
    {
      "x": -17,
      "y": 17,
      "z": 5,
      "name": "Rock_Basalt"
    },
    {
      "x": -17,
      "y": 18,
      "z": 5,
      "name": "Rock_Basalt"
    },
    {
      "x": -17,
      "y": 11,
      "z": 6,
      "name": "Ore_Iron_Basalt_Cracked"
    },
    {
      "x": -17,
      "y": 12,
      "z": 6,
      "name": "Rock_Basalt"
    },
    {
      "x": -17,
      "y": 13,
      "z": 6,
      "name": "Rock_Basalt"
    },
    {
      "x": -17,
      "y": 14,
      "z": 6,
      "name": "Rock_Basalt"
    },
    {
      "x": -17,
      "y": 15,
      "z": 6,
      "name": "Rock_Basalt"
    },
    {
      "x": -17,
      "y": 16,
      "z": 6,
      "name": "Rock_Basalt"
    },
    {
      "x": -17,
      "y": 17,
      "z": 6,
      "name": "Rock_Basalt"
    },
    {
      "x": -17,
      "y": 18,
      "z": 6,
      "name": "Ore_Iron_Basalt_Cracked"
    },
    {
      "x": -17,
      "y": 6,
      "z": 7,
      "name": "Rock_Basalt_Stalactite_Large",
      "filler": 31744,
      "rotation": 8
    },
    {
      "x": -17,
      "y": 7,
      "z": 7,
      "name": "Rock_Basalt_Stalactite_Large",
      "rotation": 8
    },
    {
      "x": -17,
      "y": 8,
      "z": 7,
      "name": "Rock_Basalt"
    },
    {
      "x": -17,
      "y": 9,
      "z": 7,
      "name": "Rock_Basalt"
    },
    {
      "x": -17,
      "y": 10,
      "z": 7,
      "name": "Rock_Basalt"
    },
    {
      "x": -17,
      "y": 11,
      "z": 7,
      "name": "Ore_Iron_Basalt_Cracked"
    },
    {
      "x": -17,
      "y": 12,
      "z": 7,
      "name": "Rock_Basalt"
    },
    {
      "x": -17,
      "y": 13,
      "z": 7,
      "name": "Rock_Basalt"
    },
    {
      "x": -17,
      "y": 14,
      "z": 7,
      "name": "Rock_Basalt"
    },
    {
      "x": -17,
      "y": 15,
      "z": 7,
      "name": "Rock_Basalt"
    },
    {
      "x": -17,
      "y": 16,
      "z": 7,
      "name": "Rock_Basalt"
    },
    {
      "x": -17,
      "y": 17,
      "z": 7,
      "name": "Rock_Basalt"
    },
    {
      "x": -17,
      "y": 18,
      "z": 7,
      "name": "Ore_Iron_Basalt_Cracked"
    },
    {
      "x": -17,
      "y": 11,
      "z": 8,
      "name": "Ore_Iron_Basalt_Cracked"
    },
    {
      "x": -17,
      "y": 12,
      "z": 8,
      "name": "Rock_Basalt"
    },
    {
      "x": -17,
      "y": 13,
      "z": 8,
      "name": "Rock_Basalt"
    },
    {
      "x": -17,
      "y": 14,
      "z": 8,
      "name": "Rock_Basalt"
    },
    {
      "x": -17,
      "y": 15,
      "z": 8,
      "name": "Rock_Basalt"
    },
    {
      "x": -17,
      "y": 16,
      "z": 8,
      "name": "Rock_Basalt"
    },
    {
      "x": -17,
      "y": 17,
      "z": 8,
      "name": "Rock_Basalt"
    },
    {
      "x": -17,
      "y": 18,
      "z": 8,
      "name": "Rubble_Basalt"
    },
    {
      "x": -17,
      "y": 11,
      "z": 9,
      "name": "Ore_Iron_Basalt_Cracked"
    },
    {
      "x": -17,
      "y": 12,
      "z": 9,
      "name": "Rock_Basalt"
    },
    {
      "x": -17,
      "y": 13,
      "z": 9,
      "name": "Rock_Basalt"
    },
    {
      "x": -17,
      "y": 14,
      "z": 9,
      "name": "Rock_Basalt"
    },
    {
      "x": -17,
      "y": 15,
      "z": 9,
      "name": "Rock_Basalt"
    },
    {
      "x": -17,
      "y": 16,
      "z": 9,
      "name": "Rock_Basalt"
    },
    {
      "x": -17,
      "y": 17,
      "z": 9,
      "name": "Rock_Basalt"
    },
    {
      "x": -17,
      "y": 11,
      "z": 10,
      "name": "Ore_Iron_Basalt_Cracked"
    },
    {
      "x": -17,
      "y": 12,
      "z": 10,
      "name": "Rock_Basalt"
    },
    {
      "x": -17,
      "y": 13,
      "z": 10,
      "name": "Rock_Basalt"
    },
    {
      "x": -17,
      "y": 14,
      "z": 10,
      "name": "Rock_Basalt"
    },
    {
      "x": -17,
      "y": 15,
      "z": 10,
      "name": "Rock_Basalt"
    },
    {
      "x": -17,
      "y": 16,
      "z": 10,
      "name": "Rock_Basalt"
    },
    {
      "x": -17,
      "y": 17,
      "z": 10,
      "name": "Rock_Basalt"
    },
    {
      "x": -17,
      "y": 11,
      "z": 11,
      "name": "Rock_Basalt"
    },
    {
      "x": -17,
      "y": 12,
      "z": 11,
      "name": "Rock_Basalt"
    },
    {
      "x": -17,
      "y": 13,
      "z": 11,
      "name": "Rock_Basalt"
    },
    {
      "x": -17,
      "y": 14,
      "z": 11,
      "name": "Rock_Basalt"
    },
    {
      "x": -17,
      "y": 15,
      "z": 11,
      "name": "Rock_Basalt"
    },
    {
      "x": -17,
      "y": 16,
      "z": 11,
      "name": "Rock_Basalt"
    },
    {
      "x": -17,
      "y": 17,
      "z": 11,
      "name": "Rock_Basalt"
    },
    {
      "x": -17,
      "y": 12,
      "z": 12,
      "name": "Ore_Iron_Basalt_Cracked"
    },
    {
      "x": -17,
      "y": 13,
      "z": 12,
      "name": "Rock_Basalt"
    },
    {
      "x": -17,
      "y": 14,
      "z": 12,
      "name": "Rock_Basalt"
    },
    {
      "x": -17,
      "y": 15,
      "z": 12,
      "name": "Rock_Basalt"
    },
    {
      "x": -17,
      "y": 16,
      "z": 12,
      "name": "Rock_Basalt"
    },
    {
      "x": -17,
      "y": 17,
      "z": 12,
      "name": "Rock_Basalt"
    },
    {
      "x": -17,
      "y": 13,
      "z": 13,
      "name": "Rock_Basalt"
    },
    {
      "x": -17,
      "y": 14,
      "z": 13,
      "name": "Ore_Iron_Basalt_Cracked"
    },
    {
      "x": -17,
      "y": 15,
      "z": 13,
      "name": "Rock_Basalt"
    },
    {
      "x": -17,
      "y": 16,
      "z": 13,
      "name": "Rock_Basalt"
    },
    {
      "x": -17,
      "y": 17,
      "z": 13,
      "name": "Ore_Iron_Basalt_Cracked"
    },
    {
      "x": -17,
      "y": 13,
      "z": 14,
      "name": "Ore_Iron_Basalt_Cracked"
    },
    {
      "x": -17,
      "y": 14,
      "z": 14,
      "name": "Rock_Basalt"
    },
    {
      "x": -17,
      "y": 15,
      "z": 14,
      "name": "Rock_Basalt"
    },
    {
      "x": -17,
      "y": 16,
      "z": 14,
      "name": "Rock_Basalt"
    },
    {
      "x": -17,
      "y": 17,
      "z": 14,
      "name": "Rock_Basalt"
    },
    {
      "x": -17,
      "y": 15,
      "z": 15,
      "name": "Ore_Iron_Basalt_Cracked"
    },
    {
      "x": -17,
      "y": 16,
      "z": 15,
      "name": "Rock_Basalt"
    },
    {
      "x": -17,
      "y": 17,
      "z": 15,
      "name": "Rock_Basalt_Cobble"
    },
    {
      "x": -17,
      "y": 15,
      "z": 16,
      "name": "Rock_Basalt"
    },
    {
      "x": -17,
      "y": 16,
      "z": 16,
      "name": "Rock_Basalt"
    },
    {
      "x": -17,
      "y": 17,
      "z": 16,
      "name": "Rock_Basalt"
    },
    {
      "x": -17,
      "y": 18,
      "z": 16,
      "name": "Rock_Basalt"
    },
    {
      "x": -17,
      "y": 14,
      "z": 17,
      "name": "Rock_Basalt"
    },
    {
      "x": -17,
      "y": 15,
      "z": 17,
      "name": "Rock_Basalt"
    },
    {
      "x": -17,
      "y": 16,
      "z": 17,
      "name": "Rock_Basalt"
    },
    {
      "x": -17,
      "y": 17,
      "z": 17,
      "name": "Rock_Basalt"
    },
    {
      "x": -17,
      "y": 15,
      "z": 18,
      "name": "Rock_Basalt"
    },
    {
      "x": -17,
      "y": 16,
      "z": 18,
      "name": "Rock_Basalt"
    },
    {
      "x": -16,
      "y": 16,
      "z": -15,
      "name": "Rock_Basalt"
    },
    {
      "x": -16,
      "y": 17,
      "z": -15,
      "name": "Rock_Basalt"
    },
    {
      "x": -16,
      "y": 14,
      "z": -14,
      "name": "Rock_Basalt"
    },
    {
      "x": -16,
      "y": 15,
      "z": -14,
      "name": "Rock_Basalt"
    },
    {
      "x": -16,
      "y": 16,
      "z": -14,
      "name": "Rock_Basalt"
    },
    {
      "x": -16,
      "y": 17,
      "z": -14,
      "name": "Rock_Basalt"
    },
    {
      "x": -16,
      "y": 18,
      "z": -14,
      "name": "Rock_Basalt"
    },
    {
      "x": -16,
      "y": 11,
      "z": -13,
      "name": "Rock_Basalt_Stalactite_Large",
      "filler": 31744,
      "rotation": 8
    },
    {
      "x": -16,
      "y": 12,
      "z": -13,
      "name": "Rock_Basalt_Stalactite_Large",
      "rotation": 8
    },
    {
      "x": -16,
      "y": 13,
      "z": -13,
      "name": "Rock_Basalt"
    },
    {
      "x": -16,
      "y": 14,
      "z": -13,
      "name": "Rock_Basalt"
    },
    {
      "x": -16,
      "y": 15,
      "z": -13,
      "name": "Rock_Basalt"
    },
    {
      "x": -16,
      "y": 16,
      "z": -13,
      "name": "Rock_Basalt"
    },
    {
      "x": -16,
      "y": 17,
      "z": -13,
      "name": "Rock_Basalt"
    },
    {
      "x": -16,
      "y": 18,
      "z": -13,
      "name": "Rock_Basalt"
    },
    {
      "x": -16,
      "y": 19,
      "z": -13,
      "name": "Rubble_Basalt_Medium"
    },
    {
      "x": -16,
      "y": 14,
      "z": -12,
      "name": "Rock_Basalt"
    },
    {
      "x": -16,
      "y": 15,
      "z": -12,
      "name": "Rock_Basalt"
    },
    {
      "x": -16,
      "y": 16,
      "z": -12,
      "name": "Rock_Basalt"
    },
    {
      "x": -16,
      "y": 17,
      "z": -12,
      "name": "Rock_Basalt"
    },
    {
      "x": -16,
      "y": 18,
      "z": -12,
      "name": "Rock_Basalt"
    },
    {
      "x": -16,
      "y": 14,
      "z": -11,
      "name": "Ore_Iron_Basalt_Cracked"
    },
    {
      "x": -16,
      "y": 15,
      "z": -11,
      "name": "Rock_Basalt"
    },
    {
      "x": -16,
      "y": 16,
      "z": -11,
      "name": "Rock_Basalt"
    },
    {
      "x": -16,
      "y": 17,
      "z": -11,
      "name": "Rock_Basalt"
    },
    {
      "x": -16,
      "y": 18,
      "z": -11,
      "name": "Rubble_Basalt"
    },
    {
      "x": -16,
      "y": 17,
      "z": 1,
      "name": "Rock_Basalt"
    },
    {
      "x": -16,
      "y": 13,
      "z": 2,
      "name": "Ore_Iron_Basalt_Cracked"
    },
    {
      "x": -16,
      "y": 14,
      "z": 2,
      "name": "Ore_Iron_Basalt_Cracked"
    },
    {
      "x": -16,
      "y": 15,
      "z": 2,
      "name": "Ore_Iron_Basalt_Cracked"
    },
    {
      "x": -16,
      "y": 16,
      "z": 2,
      "name": "Ore_Iron_Basalt_Cracked"
    },
    {
      "x": -16,
      "y": 17,
      "z": 2,
      "name": "Rock_Basalt"
    },
    {
      "x": -16,
      "y": 18,
      "z": 2,
      "name": "Rock_Basalt"
    },
    {
      "x": -16,
      "y": 11,
      "z": 3,
      "name": "Rock_Basalt"
    },
    {
      "x": -16,
      "y": 12,
      "z": 3,
      "name": "Rock_Basalt"
    },
    {
      "x": -16,
      "y": 13,
      "z": 3,
      "name": "Rock_Basalt"
    },
    {
      "x": -16,
      "y": 14,
      "z": 3,
      "name": "Rock_Basalt"
    },
    {
      "x": -16,
      "y": 15,
      "z": 3,
      "name": "Rock_Basalt"
    },
    {
      "x": -16,
      "y": 16,
      "z": 3,
      "name": "Rock_Basalt"
    },
    {
      "x": -16,
      "y": 17,
      "z": 3,
      "name": "Rock_Basalt"
    },
    {
      "x": -16,
      "y": 18,
      "z": 3,
      "name": "Rock_Basalt"
    },
    {
      "x": -16,
      "y": 19,
      "z": 3,
      "name": "Rubble_Basalt_Medium"
    },
    {
      "x": -16,
      "y": 11,
      "z": 4,
      "name": "Ore_Iron_Basalt_Cracked"
    },
    {
      "x": -16,
      "y": 12,
      "z": 4,
      "name": "Rock_Basalt"
    },
    {
      "x": -16,
      "y": 13,
      "z": 4,
      "name": "Rock_Basalt"
    },
    {
      "x": -16,
      "y": 14,
      "z": 4,
      "name": "Rock_Basalt"
    },
    {
      "x": -16,
      "y": 15,
      "z": 4,
      "name": "Rock_Basalt"
    },
    {
      "x": -16,
      "y": 16,
      "z": 4,
      "name": "Rock_Basalt"
    },
    {
      "x": -16,
      "y": 17,
      "z": 4,
      "name": "Rock_Basalt"
    },
    {
      "x": -16,
      "y": 18,
      "z": 4,
      "name": "Rock_Basalt"
    },
    {
      "x": -16,
      "y": 10,
      "z": 5,
      "name": "Rock_Basalt"
    },
    {
      "x": -16,
      "y": 11,
      "z": 5,
      "name": "Rock_Basalt"
    },
    {
      "x": -16,
      "y": 12,
      "z": 5,
      "name": "Rock_Basalt"
    },
    {
      "x": -16,
      "y": 13,
      "z": 5,
      "name": "Rock_Basalt"
    },
    {
      "x": -16,
      "y": 14,
      "z": 5,
      "name": "Rock_Basalt"
    },
    {
      "x": -16,
      "y": 15,
      "z": 5,
      "name": "Rock_Basalt"
    },
    {
      "x": -16,
      "y": 16,
      "z": 5,
      "name": "Rock_Basalt"
    },
    {
      "x": -16,
      "y": 17,
      "z": 5,
      "name": "Rock_Basalt"
    },
    {
      "x": -16,
      "y": 18,
      "z": 5,
      "name": "Rock_Basalt"
    },
    {
      "x": -16,
      "y": 19,
      "z": 5,
      "name": "Ore_Iron_Basalt_Cracked"
    },
    {
      "x": -16,
      "y": 20,
      "z": 5,
      "name": "Rubble_Basalt"
    },
    {
      "x": -16,
      "y": 10,
      "z": 6,
      "name": "Rock_Basalt"
    },
    {
      "x": -16,
      "y": 11,
      "z": 6,
      "name": "Rock_Basalt"
    },
    {
      "x": -16,
      "y": 12,
      "z": 6,
      "name": "Rock_Basalt"
    },
    {
      "x": -16,
      "y": 13,
      "z": 6,
      "name": "Rock_Basalt"
    },
    {
      "x": -16,
      "y": 14,
      "z": 6,
      "name": "Rock_Basalt"
    },
    {
      "x": -16,
      "y": 15,
      "z": 6,
      "name": "Rock_Basalt"
    },
    {
      "x": -16,
      "y": 16,
      "z": 6,
      "name": "Rock_Basalt"
    },
    {
      "x": -16,
      "y": 17,
      "z": 6,
      "name": "Rock_Basalt"
    },
    {
      "x": -16,
      "y": 18,
      "z": 6,
      "name": "Rock_Basalt"
    },
    {
      "x": -16,
      "y": 19,
      "z": 6,
      "name": "Rock_Basalt"
    },
    {
      "x": -16,
      "y": 9,
      "z": 7,
      "name": "Rock_Basalt"
    },
    {
      "x": -16,
      "y": 10,
      "z": 7,
      "name": "Rock_Basalt"
    },
    {
      "x": -16,
      "y": 11,
      "z": 7,
      "name": "Rock_Basalt"
    },
    {
      "x": -16,
      "y": 12,
      "z": 7,
      "name": "Rock_Basalt"
    },
    {
      "x": -16,
      "y": 13,
      "z": 7,
      "name": "Rock_Basalt"
    },
    {
      "x": -16,
      "y": 14,
      "z": 7,
      "name": "Rock_Basalt"
    },
    {
      "x": -16,
      "y": 15,
      "z": 7,
      "name": "Rock_Basalt"
    },
    {
      "x": -16,
      "y": 16,
      "z": 7,
      "name": "Rock_Basalt"
    },
    {
      "x": -16,
      "y": 17,
      "z": 7,
      "name": "Rock_Basalt"
    },
    {
      "x": -16,
      "y": 18,
      "z": 7,
      "name": "Rock_Basalt"
    },
    {
      "x": -16,
      "y": 19,
      "z": 7,
      "name": "Rubble_Basalt_Medium"
    },
    {
      "x": -16,
      "y": 8,
      "z": 8,
      "name": "Rock_Basalt"
    },
    {
      "x": -16,
      "y": 9,
      "z": 8,
      "name": "Rock_Basalt"
    },
    {
      "x": -16,
      "y": 10,
      "z": 8,
      "name": "Rock_Basalt"
    },
    {
      "x": -16,
      "y": 11,
      "z": 8,
      "name": "Rock_Basalt"
    },
    {
      "x": -16,
      "y": 12,
      "z": 8,
      "name": "Rock_Basalt"
    },
    {
      "x": -16,
      "y": 13,
      "z": 8,
      "name": "Rock_Basalt"
    },
    {
      "x": -16,
      "y": 14,
      "z": 8,
      "name": "Rock_Basalt"
    },
    {
      "x": -16,
      "y": 15,
      "z": 8,
      "name": "Rock_Basalt"
    },
    {
      "x": -16,
      "y": 16,
      "z": 8,
      "name": "Rock_Basalt"
    },
    {
      "x": -16,
      "y": 17,
      "z": 8,
      "name": "Rock_Basalt"
    },
    {
      "x": -16,
      "y": 18,
      "z": 8,
      "name": "Rock_Basalt"
    },
    {
      "x": -16,
      "y": 8,
      "z": 9,
      "name": "Ore_Iron_Basalt_Cracked"
    },
    {
      "x": -16,
      "y": 9,
      "z": 9,
      "name": "Rock_Basalt"
    },
    {
      "x": -16,
      "y": 10,
      "z": 9,
      "name": "Rock_Basalt"
    },
    {
      "x": -16,
      "y": 11,
      "z": 9,
      "name": "Rock_Basalt"
    },
    {
      "x": -16,
      "y": 12,
      "z": 9,
      "name": "Rock_Basalt"
    },
    {
      "x": -16,
      "y": 13,
      "z": 9,
      "name": "Rock_Basalt"
    },
    {
      "x": -16,
      "y": 14,
      "z": 9,
      "name": "Rock_Basalt"
    },
    {
      "x": -16,
      "y": 15,
      "z": 9,
      "name": "Rock_Basalt"
    },
    {
      "x": -16,
      "y": 16,
      "z": 9,
      "name": "Rock_Basalt"
    },
    {
      "x": -16,
      "y": 17,
      "z": 9,
      "name": "Rock_Basalt"
    },
    {
      "x": -16,
      "y": 18,
      "z": 9,
      "name": "Rock_Basalt"
    },
    {
      "x": -16,
      "y": 8,
      "z": 10,
      "name": "Ore_Iron_Basalt_Cracked"
    },
    {
      "x": -16,
      "y": 9,
      "z": 10,
      "name": "Ore_Iron_Basalt_Cracked"
    },
    {
      "x": -16,
      "y": 10,
      "z": 10,
      "name": "Rock_Basalt"
    },
    {
      "x": -16,
      "y": 11,
      "z": 10,
      "name": "Rock_Basalt"
    },
    {
      "x": -16,
      "y": 12,
      "z": 10,
      "name": "Rock_Basalt"
    },
    {
      "x": -16,
      "y": 13,
      "z": 10,
      "name": "Rock_Basalt"
    },
    {
      "x": -16,
      "y": 14,
      "z": 10,
      "name": "Rock_Basalt"
    },
    {
      "x": -16,
      "y": 15,
      "z": 10,
      "name": "Rock_Basalt"
    },
    {
      "x": -16,
      "y": 16,
      "z": 10,
      "name": "Rock_Basalt"
    },
    {
      "x": -16,
      "y": 17,
      "z": 10,
      "name": "Rock_Basalt"
    },
    {
      "x": -16,
      "y": 18,
      "z": 10,
      "name": "Rock_Basalt"
    },
    {
      "x": -16,
      "y": 10,
      "z": 11,
      "name": "Ore_Iron_Basalt_Cracked"
    },
    {
      "x": -16,
      "y": 11,
      "z": 11,
      "name": "Rock_Basalt"
    },
    {
      "x": -16,
      "y": 12,
      "z": 11,
      "name": "Rock_Basalt"
    },
    {
      "x": -16,
      "y": 13,
      "z": 11,
      "name": "Rock_Basalt"
    },
    {
      "x": -16,
      "y": 14,
      "z": 11,
      "name": "Rock_Basalt"
    },
    {
      "x": -16,
      "y": 15,
      "z": 11,
      "name": "Rock_Basalt"
    },
    {
      "x": -16,
      "y": 16,
      "z": 11,
      "name": "Rock_Basalt"
    },
    {
      "x": -16,
      "y": 17,
      "z": 11,
      "name": "Rock_Basalt"
    },
    {
      "x": -16,
      "y": 18,
      "z": 11,
      "name": "Rock_Basalt"
    },
    {
      "x": -16,
      "y": 10,
      "z": 12,
      "name": "Rock_Basalt"
    },
    {
      "x": -16,
      "y": 11,
      "z": 12,
      "name": "Rock_Basalt"
    },
    {
      "x": -16,
      "y": 12,
      "z": 12,
      "name": "Rock_Basalt"
    },
    {
      "x": -16,
      "y": 13,
      "z": 12,
      "name": "Rock_Basalt"
    },
    {
      "x": -16,
      "y": 14,
      "z": 12,
      "name": "Rock_Basalt"
    },
    {
      "x": -16,
      "y": 15,
      "z": 12,
      "name": "Rock_Basalt"
    },
    {
      "x": -16,
      "y": 16,
      "z": 12,
      "name": "Rock_Basalt"
    },
    {
      "x": -16,
      "y": 17,
      "z": 12,
      "name": "Rock_Basalt"
    },
    {
      "x": -16,
      "y": 18,
      "z": 12,
      "name": "Rock_Basalt"
    },
    {
      "x": -16,
      "y": 19,
      "z": 12,
      "name": "Rubble_Basalt"
    },
    {
      "x": -16,
      "y": 20,
      "z": 12,
      "name": "Rock_Crystal_Purple_Medium",
      "rotation": 7
    },
    {
      "x": -16,
      "y": 11,
      "z": 13,
      "name": "Rock_Basalt"
    },
    {
      "x": -16,
      "y": 12,
      "z": 13,
      "name": "Rock_Basalt"
    },
    {
      "x": -16,
      "y": 13,
      "z": 13,
      "name": "Rock_Basalt"
    },
    {
      "x": -16,
      "y": 14,
      "z": 13,
      "name": "Rock_Basalt"
    },
    {
      "x": -16,
      "y": 15,
      "z": 13,
      "name": "Rock_Basalt"
    },
    {
      "x": -16,
      "y": 16,
      "z": 13,
      "name": "Rock_Basalt"
    },
    {
      "x": -16,
      "y": 17,
      "z": 13,
      "name": "Rock_Basalt"
    },
    {
      "x": -16,
      "y": 18,
      "z": 13,
      "name": "Rock_Basalt"
    },
    {
      "x": -16,
      "y": 11,
      "z": 14,
      "name": "Rock_Basalt"
    },
    {
      "x": -16,
      "y": 12,
      "z": 14,
      "name": "Rock_Basalt"
    },
    {
      "x": -16,
      "y": 13,
      "z": 14,
      "name": "Rock_Basalt"
    },
    {
      "x": -16,
      "y": 14,
      "z": 14,
      "name": "Rock_Basalt"
    },
    {
      "x": -16,
      "y": 15,
      "z": 14,
      "name": "Rock_Basalt"
    },
    {
      "x": -16,
      "y": 16,
      "z": 14,
      "name": "Rock_Basalt"
    },
    {
      "x": -16,
      "y": 17,
      "z": 14,
      "name": "Rock_Basalt"
    },
    {
      "x": -16,
      "y": 18,
      "z": 14,
      "name": "Rock_Basalt_Cobble"
    },
    {
      "x": -16,
      "y": 13,
      "z": 15,
      "name": "Rock_Basalt"
    },
    {
      "x": -16,
      "y": 14,
      "z": 15,
      "name": "Rock_Basalt"
    },
    {
      "x": -16,
      "y": 15,
      "z": 15,
      "name": "Rock_Basalt"
    },
    {
      "x": -16,
      "y": 16,
      "z": 15,
      "name": "Rock_Basalt"
    },
    {
      "x": -16,
      "y": 17,
      "z": 15,
      "name": "Rock_Basalt"
    },
    {
      "x": -16,
      "y": 18,
      "z": 15,
      "name": "Rock_Basalt_Cobble"
    },
    {
      "x": -16,
      "y": 13,
      "z": 16,
      "name": "Rock_Basalt"
    },
    {
      "x": -16,
      "y": 14,
      "z": 16,
      "name": "Rock_Basalt"
    },
    {
      "x": -16,
      "y": 15,
      "z": 16,
      "name": "Rock_Basalt"
    },
    {
      "x": -16,
      "y": 16,
      "z": 16,
      "name": "Rock_Basalt"
    },
    {
      "x": -16,
      "y": 17,
      "z": 16,
      "name": "Rock_Basalt"
    },
    {
      "x": -16,
      "y": 18,
      "z": 16,
      "name": "Rock_Basalt"
    },
    {
      "x": -16,
      "y": 19,
      "z": 16,
      "name": "Rock_Basalt_Cobble"
    },
    {
      "x": -16,
      "y": 14,
      "z": 17,
      "name": "Ore_Iron_Basalt_Cracked"
    },
    {
      "x": -16,
      "y": 15,
      "z": 17,
      "name": "Rock_Basalt"
    },
    {
      "x": -16,
      "y": 16,
      "z": 17,
      "name": "Rock_Basalt"
    },
    {
      "x": -16,
      "y": 17,
      "z": 17,
      "name": "Rock_Basalt"
    },
    {
      "x": -16,
      "y": 18,
      "z": 17,
      "name": "Rock_Basalt"
    },
    {
      "x": -16,
      "y": 19,
      "z": 17,
      "name": "Rock_Basalt"
    },
    {
      "x": -16,
      "y": 8,
      "z": 18,
      "name": "Rock_Basalt_Stalactite_Large",
      "filler": 31744,
      "rotation": 8
    },
    {
      "x": -16,
      "y": 9,
      "z": 18,
      "name": "Rock_Basalt_Stalactite_Large",
      "rotation": 8
    },
    {
      "x": -16,
      "y": 10,
      "z": 18,
      "name": "Rock_Basalt"
    },
    {
      "x": -16,
      "y": 11,
      "z": 18,
      "name": "Rock_Basalt"
    },
    {
      "x": -16,
      "y": 12,
      "z": 18,
      "name": "Rock_Basalt"
    },
    {
      "x": -16,
      "y": 13,
      "z": 18,
      "name": "Ore_Iron_Basalt_Cracked"
    },
    {
      "x": -16,
      "y": 14,
      "z": 18,
      "name": "Rock_Basalt"
    },
    {
      "x": -16,
      "y": 15,
      "z": 18,
      "name": "Ore_Iron_Basalt_Cracked"
    },
    {
      "x": -16,
      "y": 16,
      "z": 18,
      "name": "Rock_Basalt"
    },
    {
      "x": -16,
      "y": 17,
      "z": 18,
      "name": "Rock_Basalt"
    },
    {
      "x": -16,
      "y": 18,
      "z": 18,
      "name": "Rock_Basalt"
    },
    {
      "x": -16,
      "y": 14,
      "z": 19,
      "name": "Rock_Basalt"
    },
    {
      "x": -16,
      "y": 15,
      "z": 19,
      "name": "Ore_Iron_Basalt_Cracked"
    },
    {
      "x": -16,
      "y": 16,
      "z": 19,
      "name": "Rock_Basalt"
    },
    {
      "x": -15,
      "y": 14,
      "z": -15,
      "name": "Rock_Basalt"
    },
    {
      "x": -15,
      "y": 15,
      "z": -15,
      "name": "Rock_Basalt"
    },
    {
      "x": -15,
      "y": 16,
      "z": -15,
      "name": "Rock_Basalt"
    },
    {
      "x": -15,
      "y": 17,
      "z": -15,
      "name": "Rock_Basalt"
    },
    {
      "x": -15,
      "y": 13,
      "z": -14,
      "name": "Rock_Basalt"
    },
    {
      "x": -15,
      "y": 14,
      "z": -14,
      "name": "Rock_Basalt"
    },
    {
      "x": -15,
      "y": 15,
      "z": -14,
      "name": "Rock_Basalt"
    },
    {
      "x": -15,
      "y": 16,
      "z": -14,
      "name": "Rock_Basalt"
    },
    {
      "x": -15,
      "y": 17,
      "z": -14,
      "name": "Rock_Basalt"
    },
    {
      "x": -15,
      "y": 18,
      "z": -14,
      "name": "Rock_Basalt"
    },
    {
      "x": -15,
      "y": 12,
      "z": -13,
      "name": "Rock_Basalt"
    },
    {
      "x": -15,
      "y": 13,
      "z": -13,
      "name": "Rock_Basalt"
    },
    {
      "x": -15,
      "y": 14,
      "z": -13,
      "name": "Rock_Basalt"
    },
    {
      "x": -15,
      "y": 15,
      "z": -13,
      "name": "Rock_Basalt"
    },
    {
      "x": -15,
      "y": 16,
      "z": -13,
      "name": "Rock_Basalt"
    },
    {
      "x": -15,
      "y": 17,
      "z": -13,
      "name": "Rock_Basalt"
    },
    {
      "x": -15,
      "y": 18,
      "z": -13,
      "name": "Rock_Basalt"
    },
    {
      "x": -15,
      "y": 12,
      "z": -12,
      "name": "Rock_Basalt"
    },
    {
      "x": -15,
      "y": 13,
      "z": -12,
      "name": "Rock_Basalt"
    },
    {
      "x": -15,
      "y": 14,
      "z": -12,
      "name": "Rock_Basalt"
    },
    {
      "x": -15,
      "y": 15,
      "z": -12,
      "name": "Rock_Basalt"
    },
    {
      "x": -15,
      "y": 16,
      "z": -12,
      "name": "Rock_Basalt"
    },
    {
      "x": -15,
      "y": 17,
      "z": -12,
      "name": "Rock_Basalt"
    },
    {
      "x": -15,
      "y": 18,
      "z": -12,
      "name": "Rock_Basalt"
    },
    {
      "x": -15,
      "y": 13,
      "z": -11,
      "name": "Rock_Basalt"
    },
    {
      "x": -15,
      "y": 14,
      "z": -11,
      "name": "Rock_Basalt"
    },
    {
      "x": -15,
      "y": 15,
      "z": -11,
      "name": "Rock_Basalt"
    },
    {
      "x": -15,
      "y": 16,
      "z": -11,
      "name": "Rock_Basalt"
    },
    {
      "x": -15,
      "y": 17,
      "z": -11,
      "name": "Rock_Basalt"
    },
    {
      "x": -15,
      "y": 18,
      "z": -11,
      "name": "Rock_Basalt"
    },
    {
      "x": -15,
      "y": 14,
      "z": -10,
      "name": "Rock_Basalt"
    },
    {
      "x": -15,
      "y": 15,
      "z": -10,
      "name": "Rock_Basalt"
    },
    {
      "x": -15,
      "y": 16,
      "z": -10,
      "name": "Rock_Basalt"
    },
    {
      "x": -15,
      "y": 14,
      "z": 2,
      "name": "Rock_Basalt"
    },
    {
      "x": -15,
      "y": 15,
      "z": 2,
      "name": "Ore_Iron_Basalt_Cracked"
    },
    {
      "x": -15,
      "y": 16,
      "z": 2,
      "name": "Rock_Basalt"
    },
    {
      "x": -15,
      "y": 17,
      "z": 2,
      "name": "Rock_Basalt"
    },
    {
      "x": -15,
      "y": 18,
      "z": 2,
      "name": "Rock_Basalt"
    },
    {
      "x": -15,
      "y": 12,
      "z": 3,
      "name": "Rock_Basalt"
    },
    {
      "x": -15,
      "y": 13,
      "z": 3,
      "name": "Ore_Iron_Basalt_Cracked"
    },
    {
      "x": -15,
      "y": 14,
      "z": 3,
      "name": "Rock_Basalt"
    },
    {
      "x": -15,
      "y": 15,
      "z": 3,
      "name": "Rock_Basalt"
    },
    {
      "x": -15,
      "y": 16,
      "z": 3,
      "name": "Rock_Basalt"
    },
    {
      "x": -15,
      "y": 17,
      "z": 3,
      "name": "Rock_Basalt"
    },
    {
      "x": -15,
      "y": 18,
      "z": 3,
      "name": "Ore_Iron_Basalt_Cracked"
    },
    {
      "x": -15,
      "y": 11,
      "z": 4,
      "name": "Rock_Basalt"
    },
    {
      "x": -15,
      "y": 12,
      "z": 4,
      "name": "Rock_Basalt"
    },
    {
      "x": -15,
      "y": 13,
      "z": 4,
      "name": "Rock_Basalt"
    },
    {
      "x": -15,
      "y": 14,
      "z": 4,
      "name": "Rock_Basalt"
    },
    {
      "x": -15,
      "y": 15,
      "z": 4,
      "name": "Rock_Basalt"
    },
    {
      "x": -15,
      "y": 16,
      "z": 4,
      "name": "Rock_Basalt"
    },
    {
      "x": -15,
      "y": 17,
      "z": 4,
      "name": "Rock_Basalt"
    },
    {
      "x": -15,
      "y": 18,
      "z": 4,
      "name": "Rock_Basalt"
    },
    {
      "x": -15,
      "y": 10,
      "z": 5,
      "name": "Rock_Basalt"
    },
    {
      "x": -15,
      "y": 11,
      "z": 5,
      "name": "Rock_Basalt"
    },
    {
      "x": -15,
      "y": 12,
      "z": 5,
      "name": "Rock_Basalt"
    },
    {
      "x": -15,
      "y": 13,
      "z": 5,
      "name": "Rock_Basalt"
    },
    {
      "x": -15,
      "y": 14,
      "z": 5,
      "name": "Rock_Basalt"
    },
    {
      "x": -15,
      "y": 15,
      "z": 5,
      "name": "Rock_Basalt"
    },
    {
      "x": -15,
      "y": 16,
      "z": 5,
      "name": "Rock_Basalt"
    },
    {
      "x": -15,
      "y": 17,
      "z": 5,
      "name": "Rock_Basalt"
    },
    {
      "x": -15,
      "y": 18,
      "z": 5,
      "name": "Rock_Basalt"
    },
    {
      "x": -15,
      "y": 19,
      "z": 5,
      "name": "Ore_Iron_Basalt_Cracked"
    },
    {
      "x": -15,
      "y": 6,
      "z": 6,
      "name": "Rock_Basalt_Stalactite_Large",
      "filler": 31744,
      "rotation": 8
    },
    {
      "x": -15,
      "y": 7,
      "z": 6,
      "name": "Rock_Basalt_Stalactite_Large",
      "rotation": 8
    },
    {
      "x": -15,
      "y": 8,
      "z": 6,
      "name": "Rock_Basalt"
    },
    {
      "x": -15,
      "y": 9,
      "z": 6,
      "name": "Rock_Basalt"
    },
    {
      "x": -15,
      "y": 10,
      "z": 6,
      "name": "Rock_Basalt"
    },
    {
      "x": -15,
      "y": 11,
      "z": 6,
      "name": "Rock_Basalt"
    },
    {
      "x": -15,
      "y": 12,
      "z": 6,
      "name": "Rock_Basalt"
    },
    {
      "x": -15,
      "y": 13,
      "z": 6,
      "name": "Rock_Basalt"
    },
    {
      "x": -15,
      "y": 14,
      "z": 6,
      "name": "Rock_Basalt"
    },
    {
      "x": -15,
      "y": 15,
      "z": 6,
      "name": "Rock_Basalt"
    },
    {
      "x": -15,
      "y": 16,
      "z": 6,
      "name": "Rock_Basalt"
    },
    {
      "x": -15,
      "y": 17,
      "z": 6,
      "name": "Rock_Basalt"
    },
    {
      "x": -15,
      "y": 18,
      "z": 6,
      "name": "Rock_Basalt"
    },
    {
      "x": -15,
      "y": 19,
      "z": 6,
      "name": "Rock_Basalt"
    },
    {
      "x": -15,
      "y": 9,
      "z": 7,
      "name": "Ore_Iron_Basalt_Cracked"
    },
    {
      "x": -15,
      "y": 10,
      "z": 7,
      "name": "Rock_Basalt"
    },
    {
      "x": -15,
      "y": 11,
      "z": 7,
      "name": "Rock_Basalt"
    },
    {
      "x": -15,
      "y": 12,
      "z": 7,
      "name": "Rock_Basalt"
    },
    {
      "x": -15,
      "y": 13,
      "z": 7,
      "name": "Rock_Basalt"
    },
    {
      "x": -15,
      "y": 14,
      "z": 7,
      "name": "Rock_Basalt"
    },
    {
      "x": -15,
      "y": 15,
      "z": 7,
      "name": "Rock_Basalt"
    },
    {
      "x": -15,
      "y": 16,
      "z": 7,
      "name": "Rock_Basalt"
    },
    {
      "x": -15,
      "y": 17,
      "z": 7,
      "name": "Rock_Basalt"
    },
    {
      "x": -15,
      "y": 18,
      "z": 7,
      "name": "Rock_Basalt"
    },
    {
      "x": -15,
      "y": 19,
      "z": 7,
      "name": "Rock_Basalt"
    },
    {
      "x": -15,
      "y": 8,
      "z": 8,
      "name": "Rock_Basalt"
    },
    {
      "x": -15,
      "y": 9,
      "z": 8,
      "name": "Rock_Basalt"
    },
    {
      "x": -15,
      "y": 10,
      "z": 8,
      "name": "Rock_Basalt"
    },
    {
      "x": -15,
      "y": 11,
      "z": 8,
      "name": "Rock_Basalt"
    },
    {
      "x": -15,
      "y": 12,
      "z": 8,
      "name": "Rock_Basalt"
    },
    {
      "x": -15,
      "y": 13,
      "z": 8,
      "name": "Rock_Basalt"
    },
    {
      "x": -15,
      "y": 14,
      "z": 8,
      "name": "Rock_Basalt"
    },
    {
      "x": -15,
      "y": 15,
      "z": 8,
      "name": "Rock_Basalt"
    },
    {
      "x": -15,
      "y": 16,
      "z": 8,
      "name": "Rock_Basalt"
    },
    {
      "x": -15,
      "y": 17,
      "z": 8,
      "name": "Rock_Basalt"
    },
    {
      "x": -15,
      "y": 18,
      "z": 8,
      "name": "Rock_Basalt"
    },
    {
      "x": -15,
      "y": 19,
      "z": 8,
      "name": "Ore_Iron_Basalt_Cracked"
    },
    {
      "x": -15,
      "y": 7,
      "z": 9,
      "name": "Rock_Basalt"
    },
    {
      "x": -15,
      "y": 8,
      "z": 9,
      "name": "Ore_Iron_Basalt_Cracked"
    },
    {
      "x": -15,
      "y": 9,
      "z": 9,
      "name": "Rock_Basalt"
    },
    {
      "x": -15,
      "y": 10,
      "z": 9,
      "name": "Rock_Basalt"
    },
    {
      "x": -15,
      "y": 11,
      "z": 9,
      "name": "Rock_Basalt"
    },
    {
      "x": -15,
      "y": 12,
      "z": 9,
      "name": "Rock_Basalt"
    },
    {
      "x": -15,
      "y": 13,
      "z": 9,
      "name": "Rock_Basalt"
    },
    {
      "x": -15,
      "y": 14,
      "z": 9,
      "name": "Rock_Basalt"
    },
    {
      "x": -15,
      "y": 15,
      "z": 9,
      "name": "Rock_Basalt"
    },
    {
      "x": -15,
      "y": 16,
      "z": 9,
      "name": "Rock_Basalt"
    },
    {
      "x": -15,
      "y": 17,
      "z": 9,
      "name": "Rock_Basalt"
    },
    {
      "x": -15,
      "y": 18,
      "z": 9,
      "name": "Rock_Basalt"
    },
    {
      "x": -15,
      "y": 19,
      "z": 9,
      "name": "Rock_Basalt"
    },
    {
      "x": -15,
      "y": 8,
      "z": 10,
      "name": "Rock_Basalt"
    },
    {
      "x": -15,
      "y": 9,
      "z": 10,
      "name": "Ore_Iron_Basalt_Cracked"
    },
    {
      "x": -15,
      "y": 10,
      "z": 10,
      "name": "Rock_Basalt"
    },
    {
      "x": -15,
      "y": 11,
      "z": 10,
      "name": "Rock_Basalt"
    },
    {
      "x": -15,
      "y": 12,
      "z": 10,
      "name": "Rock_Basalt"
    },
    {
      "x": -15,
      "y": 13,
      "z": 10,
      "name": "Rock_Basalt"
    },
    {
      "x": -15,
      "y": 14,
      "z": 10,
      "name": "Rock_Basalt"
    },
    {
      "x": -15,
      "y": 15,
      "z": 10,
      "name": "Rock_Basalt"
    },
    {
      "x": -15,
      "y": 16,
      "z": 10,
      "name": "Rock_Basalt"
    },
    {
      "x": -15,
      "y": 17,
      "z": 10,
      "name": "Rock_Basalt"
    },
    {
      "x": -15,
      "y": 18,
      "z": 10,
      "name": "Rock_Basalt"
    },
    {
      "x": -15,
      "y": 9,
      "z": 11,
      "name": "Rock_Basalt"
    },
    {
      "x": -15,
      "y": 10,
      "z": 11,
      "name": "Rock_Basalt"
    },
    {
      "x": -15,
      "y": 11,
      "z": 11,
      "name": "Rock_Basalt"
    },
    {
      "x": -15,
      "y": 12,
      "z": 11,
      "name": "Rock_Basalt"
    },
    {
      "x": -15,
      "y": 13,
      "z": 11,
      "name": "Rock_Basalt"
    },
    {
      "x": -15,
      "y": 14,
      "z": 11,
      "name": "Rock_Basalt"
    },
    {
      "x": -15,
      "y": 15,
      "z": 11,
      "name": "Rock_Basalt"
    },
    {
      "x": -15,
      "y": 16,
      "z": 11,
      "name": "Rock_Basalt"
    },
    {
      "x": -15,
      "y": 17,
      "z": 11,
      "name": "Rock_Basalt"
    },
    {
      "x": -15,
      "y": 18,
      "z": 11,
      "name": "Rock_Basalt"
    },
    {
      "x": -15,
      "y": 19,
      "z": 11,
      "name": "Rock_Crystal_Purple_Medium",
      "rotation": 7
    },
    {
      "x": -15,
      "y": 21,
      "z": 11,
      "name": "Rock_Crystal_Purple_Medium",
      "rotation": 7
    },
    {
      "x": -15,
      "y": 8,
      "z": 12,
      "name": "Rock_Basalt"
    },
    {
      "x": -15,
      "y": 10,
      "z": 12,
      "name": "Rock_Basalt"
    },
    {
      "x": -15,
      "y": 11,
      "z": 12,
      "name": "Rock_Basalt"
    },
    {
      "x": -15,
      "y": 12,
      "z": 12,
      "name": "Rock_Basalt"
    },
    {
      "x": -15,
      "y": 13,
      "z": 12,
      "name": "Rock_Basalt"
    },
    {
      "x": -15,
      "y": 14,
      "z": 12,
      "name": "Rock_Basalt"
    },
    {
      "x": -15,
      "y": 15,
      "z": 12,
      "name": "Rock_Basalt"
    },
    {
      "x": -15,
      "y": 16,
      "z": 12,
      "name": "Rock_Basalt"
    },
    {
      "x": -15,
      "y": 17,
      "z": 12,
      "name": "Rock_Basalt"
    },
    {
      "x": -15,
      "y": 18,
      "z": 12,
      "name": "Rock_Basalt"
    },
    {
      "x": -15,
      "y": 19,
      "z": 12,
      "name": "Rock_Crystal_Purple_Block"
    },
    {
      "x": -15,
      "y": 20,
      "z": 12,
      "name": "Rock_Crystal_Purple_Block"
    },
    {
      "x": -15,
      "y": 21,
      "z": 12,
      "name": "Rock_Crystal_Purple_Block"
    },
    {
      "x": -15,
      "y": 22,
      "z": 12,
      "name": "Rock_Crystal_Purple_Medium"
    },
    {
      "x": -15,
      "y": 10,
      "z": 13,
      "name": "Rock_Basalt"
    },
    {
      "x": -15,
      "y": 11,
      "z": 13,
      "name": "Rock_Basalt"
    },
    {
      "x": -15,
      "y": 12,
      "z": 13,
      "name": "Rock_Basalt"
    },
    {
      "x": -15,
      "y": 13,
      "z": 13,
      "name": "Rock_Basalt"
    },
    {
      "x": -15,
      "y": 14,
      "z": 13,
      "name": "Rock_Basalt"
    },
    {
      "x": -15,
      "y": 15,
      "z": 13,
      "name": "Rock_Basalt"
    },
    {
      "x": -15,
      "y": 16,
      "z": 13,
      "name": "Rock_Basalt"
    },
    {
      "x": -15,
      "y": 17,
      "z": 13,
      "name": "Rock_Basalt"
    },
    {
      "x": -15,
      "y": 18,
      "z": 13,
      "name": "Rock_Basalt"
    },
    {
      "x": -15,
      "y": 19,
      "z": 13,
      "name": "Rock_Basalt"
    },
    {
      "x": -15,
      "y": 20,
      "z": 13,
      "name": "Rock_Crystal_Purple_Medium",
      "rotation": 4
    },
    {
      "x": -15,
      "y": 11,
      "z": 14,
      "name": "Rock_Basalt"
    },
    {
      "x": -15,
      "y": 12,
      "z": 14,
      "name": "Rock_Basalt"
    },
    {
      "x": -15,
      "y": 13,
      "z": 14,
      "name": "Rock_Basalt"
    },
    {
      "x": -15,
      "y": 14,
      "z": 14,
      "name": "Rock_Basalt"
    },
    {
      "x": -15,
      "y": 15,
      "z": 14,
      "name": "Rock_Basalt"
    },
    {
      "x": -15,
      "y": 16,
      "z": 14,
      "name": "Rock_Basalt"
    },
    {
      "x": -15,
      "y": 17,
      "z": 14,
      "name": "Rock_Basalt"
    },
    {
      "x": -15,
      "y": 18,
      "z": 14,
      "name": "Rock_Basalt"
    },
    {
      "x": -15,
      "y": 19,
      "z": 14,
      "name": "Rock_Basalt_Cobble"
    },
    {
      "x": -15,
      "y": 11,
      "z": 15,
      "name": "Rock_Basalt"
    },
    {
      "x": -15,
      "y": 12,
      "z": 15,
      "name": "Rock_Basalt"
    },
    {
      "x": -15,
      "y": 13,
      "z": 15,
      "name": "Rock_Basalt"
    },
    {
      "x": -15,
      "y": 14,
      "z": 15,
      "name": "Rock_Basalt"
    },
    {
      "x": -15,
      "y": 15,
      "z": 15,
      "name": "Rock_Basalt"
    },
    {
      "x": -15,
      "y": 16,
      "z": 15,
      "name": "Rock_Basalt"
    },
    {
      "x": -15,
      "y": 17,
      "z": 15,
      "name": "Rock_Basalt"
    },
    {
      "x": -15,
      "y": 18,
      "z": 15,
      "name": "Rock_Basalt"
    },
    {
      "x": -15,
      "y": 19,
      "z": 15,
      "name": "Rock_Basalt_Cobble"
    },
    {
      "x": -15,
      "y": 12,
      "z": 16,
      "name": "Rock_Basalt"
    },
    {
      "x": -15,
      "y": 13,
      "z": 16,
      "name": "Rock_Basalt"
    },
    {
      "x": -15,
      "y": 14,
      "z": 16,
      "name": "Rock_Basalt"
    },
    {
      "x": -15,
      "y": 15,
      "z": 16,
      "name": "Rock_Basalt"
    },
    {
      "x": -15,
      "y": 16,
      "z": 16,
      "name": "Rock_Basalt"
    },
    {
      "x": -15,
      "y": 17,
      "z": 16,
      "name": "Rock_Basalt"
    },
    {
      "x": -15,
      "y": 18,
      "z": 16,
      "name": "Rock_Basalt"
    },
    {
      "x": -15,
      "y": 19,
      "z": 16,
      "name": "Rock_Basalt"
    },
    {
      "x": -15,
      "y": 13,
      "z": 17,
      "name": "Ore_Iron_Basalt_Cracked"
    },
    {
      "x": -15,
      "y": 14,
      "z": 17,
      "name": "Rock_Basalt"
    },
    {
      "x": -15,
      "y": 15,
      "z": 17,
      "name": "Rock_Basalt"
    },
    {
      "x": -15,
      "y": 16,
      "z": 17,
      "name": "Rock_Basalt"
    },
    {
      "x": -15,
      "y": 17,
      "z": 17,
      "name": "Rock_Basalt"
    },
    {
      "x": -15,
      "y": 18,
      "z": 17,
      "name": "Rock_Basalt"
    },
    {
      "x": -15,
      "y": 19,
      "z": 17,
      "name": "Rock_Basalt"
    },
    {
      "x": -15,
      "y": 20,
      "z": 17,
      "name": "Rubble_Basalt_Medium"
    },
    {
      "x": -15,
      "y": 12,
      "z": 18,
      "name": "Ore_Iron_Basalt_Cracked"
    },
    {
      "x": -15,
      "y": 13,
      "z": 18,
      "name": "Ore_Iron_Basalt_Cracked"
    },
    {
      "x": -15,
      "y": 14,
      "z": 18,
      "name": "Ore_Iron_Basalt_Cracked"
    },
    {
      "x": -15,
      "y": 15,
      "z": 18,
      "name": "Rock_Basalt"
    },
    {
      "x": -15,
      "y": 16,
      "z": 18,
      "name": "Rock_Basalt"
    },
    {
      "x": -15,
      "y": 17,
      "z": 18,
      "name": "Rock_Basalt"
    },
    {
      "x": -15,
      "y": 18,
      "z": 18,
      "name": "Rock_Basalt"
    },
    {
      "x": -15,
      "y": 19,
      "z": 18,
      "name": "Rock_Basalt"
    },
    {
      "x": -15,
      "y": 14,
      "z": 19,
      "name": "Rock_Basalt"
    },
    {
      "x": -15,
      "y": 15,
      "z": 19,
      "name": "Ore_Iron_Basalt_Cracked"
    },
    {
      "x": -15,
      "y": 16,
      "z": 19,
      "name": "Rock_Basalt"
    },
    {
      "x": -15,
      "y": 17,
      "z": 19,
      "name": "Ore_Iron_Basalt_Cracked"
    },
    {
      "x": -15,
      "y": 18,
      "z": 19,
      "name": "Rubble_Basalt"
    },
    {
      "x": -14,
      "y": 13,
      "z": -15,
      "name": "Rock_Basalt"
    },
    {
      "x": -14,
      "y": 14,
      "z": -15,
      "name": "Rock_Basalt"
    },
    {
      "x": -14,
      "y": 15,
      "z": -15,
      "name": "Rock_Basalt"
    },
    {
      "x": -14,
      "y": 16,
      "z": -15,
      "name": "Rock_Basalt"
    },
    {
      "x": -14,
      "y": 17,
      "z": -15,
      "name": "Rock_Basalt"
    },
    {
      "x": -14,
      "y": 12,
      "z": -14,
      "name": "Rock_Basalt"
    },
    {
      "x": -14,
      "y": 13,
      "z": -14,
      "name": "Rock_Basalt"
    },
    {
      "x": -14,
      "y": 14,
      "z": -14,
      "name": "Rock_Basalt"
    },
    {
      "x": -14,
      "y": 15,
      "z": -14,
      "name": "Rock_Basalt"
    },
    {
      "x": -14,
      "y": 16,
      "z": -14,
      "name": "Rock_Basalt"
    },
    {
      "x": -14,
      "y": 17,
      "z": -14,
      "name": "Rock_Basalt"
    },
    {
      "x": -14,
      "y": 18,
      "z": -14,
      "name": "Rock_Basalt"
    },
    {
      "x": -14,
      "y": 11,
      "z": -13,
      "name": "Rock_Basalt"
    },
    {
      "x": -14,
      "y": 12,
      "z": -13,
      "name": "Rock_Basalt"
    },
    {
      "x": -14,
      "y": 13,
      "z": -13,
      "name": "Rock_Basalt"
    },
    {
      "x": -14,
      "y": 14,
      "z": -13,
      "name": "Rock_Basalt"
    },
    {
      "x": -14,
      "y": 15,
      "z": -13,
      "name": "Rock_Basalt"
    },
    {
      "x": -14,
      "y": 16,
      "z": -13,
      "name": "Rock_Basalt"
    },
    {
      "x": -14,
      "y": 17,
      "z": -13,
      "name": "Rock_Basalt"
    },
    {
      "x": -14,
      "y": 18,
      "z": -13,
      "name": "Rock_Basalt"
    },
    {
      "x": -14,
      "y": 11,
      "z": -12,
      "name": "Rock_Basalt"
    },
    {
      "x": -14,
      "y": 12,
      "z": -12,
      "name": "Rock_Basalt"
    },
    {
      "x": -14,
      "y": 13,
      "z": -12,
      "name": "Rock_Basalt"
    },
    {
      "x": -14,
      "y": 14,
      "z": -12,
      "name": "Rock_Basalt"
    },
    {
      "x": -14,
      "y": 15,
      "z": -12,
      "name": "Rock_Basalt"
    },
    {
      "x": -14,
      "y": 16,
      "z": -12,
      "name": "Rock_Basalt"
    },
    {
      "x": -14,
      "y": 17,
      "z": -12,
      "name": "Rock_Basalt"
    },
    {
      "x": -14,
      "y": 18,
      "z": -12,
      "name": "Rock_Basalt_Cobble"
    },
    {
      "x": -14,
      "y": 12,
      "z": -11,
      "name": "Rock_Basalt"
    },
    {
      "x": -14,
      "y": 13,
      "z": -11,
      "name": "Rock_Basalt"
    },
    {
      "x": -14,
      "y": 14,
      "z": -11,
      "name": "Rock_Basalt"
    },
    {
      "x": -14,
      "y": 15,
      "z": -11,
      "name": "Rock_Basalt"
    },
    {
      "x": -14,
      "y": 16,
      "z": -11,
      "name": "Rock_Basalt"
    },
    {
      "x": -14,
      "y": 17,
      "z": -11,
      "name": "Rock_Basalt"
    },
    {
      "x": -14,
      "y": 18,
      "z": -11,
      "name": "Rock_Basalt_Cobble"
    },
    {
      "x": -14,
      "y": 12,
      "z": -10,
      "name": "Rock_Basalt"
    },
    {
      "x": -14,
      "y": 13,
      "z": -10,
      "name": "Rock_Basalt"
    },
    {
      "x": -14,
      "y": 14,
      "z": -10,
      "name": "Rock_Basalt"
    },
    {
      "x": -14,
      "y": 15,
      "z": -10,
      "name": "Rock_Basalt"
    },
    {
      "x": -14,
      "y": 16,
      "z": -10,
      "name": "Rock_Basalt"
    },
    {
      "x": -14,
      "y": 17,
      "z": -10,
      "name": "Rock_Basalt"
    },
    {
      "x": -14,
      "y": 18,
      "z": -10,
      "name": "Rubble_Basalt_Medium"
    },
    {
      "x": -14,
      "y": 14,
      "z": -9,
      "name": "Rock_Basalt"
    },
    {
      "x": -14,
      "y": 15,
      "z": -9,
      "name": "Rock_Basalt"
    },
    {
      "x": -14,
      "y": 16,
      "z": -9,
      "name": "Rock_Basalt"
    },
    {
      "x": -14,
      "y": 15,
      "z": -8,
      "name": "Rock_Basalt"
    },
    {
      "x": -14,
      "y": 12,
      "z": -5,
      "name": "Rock_Basalt"
    },
    {
      "x": -14,
      "y": 13,
      "z": -5,
      "name": "Rock_Basalt"
    },
    {
      "x": -14,
      "y": 14,
      "z": -5,
      "name": "Ore_Iron_Basalt_Cracked"
    },
    {
      "x": -14,
      "y": 13,
      "z": -4,
      "name": "Rock_Basalt"
    },
    {
      "x": -14,
      "y": 14,
      "z": -4,
      "name": "Ore_Iron_Basalt_Cracked"
    },
    {
      "x": -14,
      "y": 15,
      "z": -4,
      "name": "Rock_Basalt"
    },
    {
      "x": -14,
      "y": 16,
      "z": -4,
      "name": "Rock_Basalt"
    },
    {
      "x": -14,
      "y": 16,
      "z": -3,
      "name": "Rock_Basalt"
    },
    {
      "x": -14,
      "y": 17,
      "z": 2,
      "name": "Rock_Basalt"
    },
    {
      "x": -14,
      "y": 13,
      "z": 3,
      "name": "Ore_Iron_Basalt_Cracked"
    },
    {
      "x": -14,
      "y": 14,
      "z": 3,
      "name": "Rock_Basalt"
    },
    {
      "x": -14,
      "y": 15,
      "z": 3,
      "name": "Rock_Basalt"
    },
    {
      "x": -14,
      "y": 16,
      "z": 3,
      "name": "Rock_Basalt"
    },
    {
      "x": -14,
      "y": 17,
      "z": 3,
      "name": "Rock_Basalt"
    },
    {
      "x": -14,
      "y": 11,
      "z": 4,
      "name": "Rock_Basalt"
    },
    {
      "x": -14,
      "y": 12,
      "z": 4,
      "name": "Rock_Basalt"
    },
    {
      "x": -14,
      "y": 13,
      "z": 4,
      "name": "Ore_Iron_Basalt_Cracked"
    },
    {
      "x": -14,
      "y": 14,
      "z": 4,
      "name": "Rock_Basalt"
    },
    {
      "x": -14,
      "y": 15,
      "z": 4,
      "name": "Rock_Basalt"
    },
    {
      "x": -14,
      "y": 16,
      "z": 4,
      "name": "Rock_Basalt"
    },
    {
      "x": -14,
      "y": 17,
      "z": 4,
      "name": "Rock_Basalt"
    },
    {
      "x": -14,
      "y": 18,
      "z": 4,
      "name": "Rock_Basalt"
    },
    {
      "x": -14,
      "y": 10,
      "z": 5,
      "name": "Rock_Basalt"
    },
    {
      "x": -14,
      "y": 11,
      "z": 5,
      "name": "Ore_Iron_Basalt_Cracked"
    },
    {
      "x": -14,
      "y": 12,
      "z": 5,
      "name": "Rock_Basalt"
    },
    {
      "x": -14,
      "y": 13,
      "z": 5,
      "name": "Rock_Basalt"
    },
    {
      "x": -14,
      "y": 14,
      "z": 5,
      "name": "Rock_Basalt"
    },
    {
      "x": -14,
      "y": 15,
      "z": 5,
      "name": "Rock_Basalt"
    },
    {
      "x": -14,
      "y": 16,
      "z": 5,
      "name": "Rock_Basalt"
    },
    {
      "x": -14,
      "y": 17,
      "z": 5,
      "name": "Rock_Basalt"
    },
    {
      "x": -14,
      "y": 18,
      "z": 5,
      "name": "Rock_Basalt"
    },
    {
      "x": -14,
      "y": 9,
      "z": 6,
      "name": "Rock_Basalt"
    },
    {
      "x": -14,
      "y": 10,
      "z": 6,
      "name": "Rock_Basalt"
    },
    {
      "x": -14,
      "y": 11,
      "z": 6,
      "name": "Rock_Basalt"
    },
    {
      "x": -14,
      "y": 12,
      "z": 6,
      "name": "Rock_Basalt"
    },
    {
      "x": -14,
      "y": 13,
      "z": 6,
      "name": "Rock_Basalt"
    },
    {
      "x": -14,
      "y": 14,
      "z": 6,
      "name": "Rock_Basalt"
    },
    {
      "x": -14,
      "y": 15,
      "z": 6,
      "name": "Rock_Basalt"
    },
    {
      "x": -14,
      "y": 16,
      "z": 6,
      "name": "Rock_Basalt"
    },
    {
      "x": -14,
      "y": 17,
      "z": 6,
      "name": "Rock_Basalt"
    },
    {
      "x": -14,
      "y": 18,
      "z": 6,
      "name": "Rock_Basalt"
    },
    {
      "x": -14,
      "y": 19,
      "z": 6,
      "name": "Rock_Basalt"
    },
    {
      "x": -14,
      "y": 9,
      "z": 7,
      "name": "Ore_Iron_Basalt_Cracked"
    },
    {
      "x": -14,
      "y": 10,
      "z": 7,
      "name": "Rock_Basalt"
    },
    {
      "x": -14,
      "y": 11,
      "z": 7,
      "name": "Rock_Basalt"
    },
    {
      "x": -14,
      "y": 12,
      "z": 7,
      "name": "Rock_Basalt"
    },
    {
      "x": -14,
      "y": 13,
      "z": 7,
      "name": "Rock_Basalt"
    },
    {
      "x": -14,
      "y": 14,
      "z": 7,
      "name": "Rock_Basalt"
    },
    {
      "x": -14,
      "y": 15,
      "z": 7,
      "name": "Rock_Basalt"
    },
    {
      "x": -14,
      "y": 16,
      "z": 7,
      "name": "Rock_Basalt"
    },
    {
      "x": -14,
      "y": 17,
      "z": 7,
      "name": "Rock_Basalt"
    },
    {
      "x": -14,
      "y": 18,
      "z": 7,
      "name": "Rock_Basalt"
    },
    {
      "x": -14,
      "y": 19,
      "z": 7,
      "name": "Rock_Basalt"
    },
    {
      "x": -14,
      "y": 8,
      "z": 8,
      "name": "Rock_Basalt"
    },
    {
      "x": -14,
      "y": 9,
      "z": 8,
      "name": "Rock_Basalt"
    },
    {
      "x": -14,
      "y": 10,
      "z": 8,
      "name": "Rock_Basalt"
    },
    {
      "x": -14,
      "y": 11,
      "z": 8,
      "name": "Rock_Basalt"
    },
    {
      "x": -14,
      "y": 12,
      "z": 8,
      "name": "Rock_Basalt"
    },
    {
      "x": -14,
      "y": 13,
      "z": 8,
      "name": "Rock_Basalt"
    },
    {
      "x": -14,
      "y": 14,
      "z": 8,
      "name": "Rock_Basalt"
    },
    {
      "x": -14,
      "y": 15,
      "z": 8,
      "name": "Rock_Basalt"
    },
    {
      "x": -14,
      "y": 16,
      "z": 8,
      "name": "Rock_Basalt"
    },
    {
      "x": -14,
      "y": 17,
      "z": 8,
      "name": "Rock_Basalt"
    },
    {
      "x": -14,
      "y": 18,
      "z": 8,
      "name": "Rock_Basalt"
    },
    {
      "x": -14,
      "y": 19,
      "z": 8,
      "name": "Rock_Basalt"
    },
    {
      "x": -14,
      "y": 8,
      "z": 9,
      "name": "Rock_Basalt"
    },
    {
      "x": -14,
      "y": 9,
      "z": 9,
      "name": "Rock_Basalt"
    },
    {
      "x": -14,
      "y": 10,
      "z": 9,
      "name": "Rock_Basalt"
    },
    {
      "x": -14,
      "y": 11,
      "z": 9,
      "name": "Rock_Basalt"
    },
    {
      "x": -14,
      "y": 12,
      "z": 9,
      "name": "Rock_Basalt"
    },
    {
      "x": -14,
      "y": 13,
      "z": 9,
      "name": "Rock_Basalt"
    },
    {
      "x": -14,
      "y": 14,
      "z": 9,
      "name": "Rock_Basalt"
    },
    {
      "x": -14,
      "y": 15,
      "z": 9,
      "name": "Rock_Basalt"
    },
    {
      "x": -14,
      "y": 16,
      "z": 9,
      "name": "Rock_Basalt"
    },
    {
      "x": -14,
      "y": 17,
      "z": 9,
      "name": "Rock_Basalt"
    },
    {
      "x": -14,
      "y": 18,
      "z": 9,
      "name": "Rock_Basalt"
    },
    {
      "x": -14,
      "y": 19,
      "z": 9,
      "name": "Rock_Basalt"
    },
    {
      "x": -14,
      "y": 8,
      "z": 10,
      "name": "Rock_Basalt"
    },
    {
      "x": -14,
      "y": 9,
      "z": 10,
      "name": "Rock_Basalt"
    },
    {
      "x": -14,
      "y": 10,
      "z": 10,
      "name": "Rock_Basalt"
    },
    {
      "x": -14,
      "y": 11,
      "z": 10,
      "name": "Rock_Basalt"
    },
    {
      "x": -14,
      "y": 12,
      "z": 10,
      "name": "Rock_Basalt"
    },
    {
      "x": -14,
      "y": 13,
      "z": 10,
      "name": "Rock_Basalt"
    },
    {
      "x": -14,
      "y": 14,
      "z": 10,
      "name": "Rock_Basalt"
    },
    {
      "x": -14,
      "y": 15,
      "z": 10,
      "name": "Rock_Basalt"
    },
    {
      "x": -14,
      "y": 16,
      "z": 10,
      "name": "Rock_Basalt"
    },
    {
      "x": -14,
      "y": 17,
      "z": 10,
      "name": "Rock_Basalt"
    },
    {
      "x": -14,
      "y": 18,
      "z": 10,
      "name": "Rock_Basalt"
    },
    {
      "x": -14,
      "y": 19,
      "z": 10,
      "name": "Rock_Basalt"
    },
    {
      "x": -14,
      "y": 20,
      "z": 10,
      "name": "Rock_Crystal_Purple_Medium",
      "rotation": 6
    },
    {
      "x": -14,
      "y": 21,
      "z": 10,
      "name": "Rock_Crystal_Purple_Medium",
      "rotation": 6
    },
    {
      "x": -14,
      "y": 22,
      "z": 10,
      "name": "Rock_Crystal_Purple_Medium",
      "rotation": 6
    },
    {
      "x": -14,
      "y": 9,
      "z": 11,
      "name": "Rock_Basalt"
    },
    {
      "x": -14,
      "y": 10,
      "z": 11,
      "name": "Rock_Basalt"
    },
    {
      "x": -14,
      "y": 11,
      "z": 11,
      "name": "Rock_Basalt"
    },
    {
      "x": -14,
      "y": 12,
      "z": 11,
      "name": "Rock_Basalt"
    },
    {
      "x": -14,
      "y": 13,
      "z": 11,
      "name": "Rock_Basalt"
    },
    {
      "x": -14,
      "y": 14,
      "z": 11,
      "name": "Rock_Basalt"
    },
    {
      "x": -14,
      "y": 15,
      "z": 11,
      "name": "Rock_Basalt"
    },
    {
      "x": -14,
      "y": 16,
      "z": 11,
      "name": "Rock_Basalt"
    },
    {
      "x": -14,
      "y": 17,
      "z": 11,
      "name": "Rock_Basalt"
    },
    {
      "x": -14,
      "y": 18,
      "z": 11,
      "name": "Rock_Basalt"
    },
    {
      "x": -14,
      "y": 19,
      "z": 11,
      "name": "Rock_Crystal_Purple_Block"
    },
    {
      "x": -14,
      "y": 20,
      "z": 11,
      "name": "Rock_Crystal_Purple_Block"
    },
    {
      "x": -14,
      "y": 21,
      "z": 11,
      "name": "Rock_Crystal_Purple_Block"
    },
    {
      "x": -14,
      "y": 22,
      "z": 11,
      "name": "Rock_Crystal_Purple_Block"
    },
    {
      "x": -14,
      "y": 23,
      "z": 11,
      "name": "Rock_Crystal_Purple_Large",
      "rotation": 6
    },
    {
      "x": -14,
      "y": 9,
      "z": 12,
      "name": "Rock_Basalt"
    },
    {
      "x": -14,
      "y": 10,
      "z": 12,
      "name": "Rock_Basalt"
    },
    {
      "x": -14,
      "y": 11,
      "z": 12,
      "name": "Rock_Basalt"
    },
    {
      "x": -14,
      "y": 12,
      "z": 12,
      "name": "Rock_Basalt"
    },
    {
      "x": -14,
      "y": 13,
      "z": 12,
      "name": "Rock_Basalt"
    },
    {
      "x": -14,
      "y": 14,
      "z": 12,
      "name": "Rock_Basalt"
    },
    {
      "x": -14,
      "y": 15,
      "z": 12,
      "name": "Rock_Basalt"
    },
    {
      "x": -14,
      "y": 16,
      "z": 12,
      "name": "Rock_Basalt"
    },
    {
      "x": -14,
      "y": 17,
      "z": 12,
      "name": "Rock_Basalt"
    },
    {
      "x": -14,
      "y": 18,
      "z": 12,
      "name": "Rock_Basalt"
    },
    {
      "x": -14,
      "y": 19,
      "z": 12,
      "name": "Rock_Crystal_Purple_Block"
    },
    {
      "x": -14,
      "y": 20,
      "z": 12,
      "name": "Rock_Crystal_Purple_Block"
    },
    {
      "x": -14,
      "y": 21,
      "z": 12,
      "name": "Rock_Crystal_Purple_Block"
    },
    {
      "x": -14,
      "y": 22,
      "z": 12,
      "name": "Rock_Crystal_Purple_Block"
    },
    {
      "x": -14,
      "y": 23,
      "z": 12,
      "name": "Rock_Crystal_Purple_Block"
    },
    {
      "x": -14,
      "y": 24,
      "z": 12,
      "name": "Rock_Crystal_Purple_Large"
    },
    {
      "x": -14,
      "y": 10,
      "z": 13,
      "name": "Rock_Basalt"
    },
    {
      "x": -14,
      "y": 11,
      "z": 13,
      "name": "Rock_Basalt"
    },
    {
      "x": -14,
      "y": 12,
      "z": 13,
      "name": "Rock_Basalt"
    },
    {
      "x": -14,
      "y": 13,
      "z": 13,
      "name": "Rock_Basalt"
    },
    {
      "x": -14,
      "y": 14,
      "z": 13,
      "name": "Rock_Basalt"
    },
    {
      "x": -14,
      "y": 15,
      "z": 13,
      "name": "Rock_Basalt"
    },
    {
      "x": -14,
      "y": 16,
      "z": 13,
      "name": "Rock_Basalt"
    },
    {
      "x": -14,
      "y": 17,
      "z": 13,
      "name": "Rock_Basalt"
    },
    {
      "x": -14,
      "y": 18,
      "z": 13,
      "name": "Rock_Basalt"
    },
    {
      "x": -14,
      "y": 19,
      "z": 13,
      "name": "Rock_Crystal_Purple_Block"
    },
    {
      "x": -14,
      "y": 20,
      "z": 13,
      "name": "Rock_Crystal_Purple_Block"
    },
    {
      "x": -14,
      "y": 21,
      "z": 13,
      "name": "Rock_Crystal_Purple_Medium"
    },
    {
      "x": -14,
      "y": 22,
      "z": 13,
      "name": "Rock_Crystal_Purple_Medium",
      "rotation": 4
    },
    {
      "x": -14,
      "y": 10,
      "z": 14,
      "name": "Rock_Basalt"
    },
    {
      "x": -14,
      "y": 11,
      "z": 14,
      "name": "Rock_Basalt"
    },
    {
      "x": -14,
      "y": 12,
      "z": 14,
      "name": "Rock_Basalt"
    },
    {
      "x": -14,
      "y": 13,
      "z": 14,
      "name": "Rock_Basalt"
    },
    {
      "x": -14,
      "y": 14,
      "z": 14,
      "name": "Rock_Basalt"
    },
    {
      "x": -14,
      "y": 15,
      "z": 14,
      "name": "Rock_Basalt"
    },
    {
      "x": -14,
      "y": 16,
      "z": 14,
      "name": "Rock_Basalt"
    },
    {
      "x": -14,
      "y": 17,
      "z": 14,
      "name": "Rock_Basalt"
    },
    {
      "x": -14,
      "y": 18,
      "z": 14,
      "name": "Rock_Basalt"
    },
    {
      "x": -14,
      "y": 19,
      "z": 14,
      "name": "Rock_Basalt"
    },
    {
      "x": -14,
      "y": 20,
      "z": 14,
      "name": "Rock_Crystal_Purple_Medium"
    },
    {
      "x": -14,
      "y": 11,
      "z": 15,
      "name": "Rock_Basalt"
    },
    {
      "x": -14,
      "y": 12,
      "z": 15,
      "name": "Rock_Basalt"
    },
    {
      "x": -14,
      "y": 13,
      "z": 15,
      "name": "Rock_Basalt"
    },
    {
      "x": -14,
      "y": 14,
      "z": 15,
      "name": "Rock_Basalt"
    },
    {
      "x": -14,
      "y": 15,
      "z": 15,
      "name": "Rock_Basalt"
    },
    {
      "x": -14,
      "y": 16,
      "z": 15,
      "name": "Rock_Basalt"
    },
    {
      "x": -14,
      "y": 17,
      "z": 15,
      "name": "Rock_Basalt"
    },
    {
      "x": -14,
      "y": 18,
      "z": 15,
      "name": "Rock_Basalt"
    },
    {
      "x": -14,
      "y": 19,
      "z": 15,
      "name": "Rock_Basalt_Cobble"
    },
    {
      "x": -14,
      "y": 11,
      "z": 16,
      "name": "Rock_Basalt"
    },
    {
      "x": -14,
      "y": 12,
      "z": 16,
      "name": "Rock_Basalt"
    },
    {
      "x": -14,
      "y": 13,
      "z": 16,
      "name": "Rock_Basalt"
    },
    {
      "x": -14,
      "y": 14,
      "z": 16,
      "name": "Rock_Basalt"
    },
    {
      "x": -14,
      "y": 15,
      "z": 16,
      "name": "Rock_Basalt"
    },
    {
      "x": -14,
      "y": 16,
      "z": 16,
      "name": "Rock_Basalt"
    },
    {
      "x": -14,
      "y": 17,
      "z": 16,
      "name": "Rock_Basalt"
    },
    {
      "x": -14,
      "y": 18,
      "z": 16,
      "name": "Rock_Basalt"
    },
    {
      "x": -14,
      "y": 19,
      "z": 16,
      "name": "Rock_Basalt"
    },
    {
      "x": -14,
      "y": 20,
      "z": 16,
      "name": "Rubble_Basalt"
    },
    {
      "x": -14,
      "y": 11,
      "z": 17,
      "name": "Ore_Iron_Basalt_Cracked"
    },
    {
      "x": -14,
      "y": 12,
      "z": 17,
      "name": "Ore_Iron_Basalt_Cracked"
    },
    {
      "x": -14,
      "y": 13,
      "z": 17,
      "name": "Rock_Basalt"
    },
    {
      "x": -14,
      "y": 14,
      "z": 17,
      "name": "Rock_Basalt"
    },
    {
      "x": -14,
      "y": 15,
      "z": 17,
      "name": "Rock_Basalt"
    },
    {
      "x": -14,
      "y": 16,
      "z": 17,
      "name": "Rock_Basalt"
    },
    {
      "x": -14,
      "y": 17,
      "z": 17,
      "name": "Rock_Basalt"
    },
    {
      "x": -14,
      "y": 18,
      "z": 17,
      "name": "Rock_Basalt"
    },
    {
      "x": -14,
      "y": 19,
      "z": 17,
      "name": "Rock_Basalt"
    },
    {
      "x": -14,
      "y": 20,
      "z": 17,
      "name": "Rubble_Basalt"
    },
    {
      "x": -14,
      "y": 12,
      "z": 18,
      "name": "Ore_Iron_Basalt_Cracked"
    },
    {
      "x": -14,
      "y": 13,
      "z": 18,
      "name": "Ore_Iron_Basalt_Cracked"
    },
    {
      "x": -14,
      "y": 14,
      "z": 18,
      "name": "Rock_Basalt"
    },
    {
      "x": -14,
      "y": 15,
      "z": 18,
      "name": "Rock_Basalt"
    },
    {
      "x": -14,
      "y": 16,
      "z": 18,
      "name": "Rock_Basalt"
    },
    {
      "x": -14,
      "y": 17,
      "z": 18,
      "name": "Rock_Basalt"
    },
    {
      "x": -14,
      "y": 18,
      "z": 18,
      "name": "Rock_Basalt"
    },
    {
      "x": -14,
      "y": 19,
      "z": 18,
      "name": "Rock_Basalt"
    },
    {
      "x": -14,
      "y": 15,
      "z": 19,
      "name": "Ore_Iron_Basalt_Cracked"
    },
    {
      "x": -14,
      "y": 16,
      "z": 19,
      "name": "Rock_Basalt"
    },
    {
      "x": -14,
      "y": 17,
      "z": 19,
      "name": "Ore_Iron_Basalt_Cracked"
    },
    {
      "x": -13,
      "y": 13,
      "z": -16,
      "name": "Rock_Basalt"
    },
    {
      "x": -13,
      "y": 14,
      "z": -16,
      "name": "Rock_Basalt"
    },
    {
      "x": -13,
      "y": 15,
      "z": -16,
      "name": "Rock_Basalt"
    },
    {
      "x": -13,
      "y": 16,
      "z": -16,
      "name": "Rock_Basalt"
    },
    {
      "x": -13,
      "y": 12,
      "z": -15,
      "name": "Rock_Basalt"
    },
    {
      "x": -13,
      "y": 13,
      "z": -15,
      "name": "Rock_Basalt"
    },
    {
      "x": -13,
      "y": 14,
      "z": -15,
      "name": "Rock_Basalt"
    },
    {
      "x": -13,
      "y": 15,
      "z": -15,
      "name": "Rock_Basalt"
    },
    {
      "x": -13,
      "y": 16,
      "z": -15,
      "name": "Rock_Basalt"
    },
    {
      "x": -13,
      "y": 17,
      "z": -15,
      "name": "Rock_Basalt"
    },
    {
      "x": -13,
      "y": 18,
      "z": -15,
      "name": "Rubble_Basalt"
    },
    {
      "x": -13,
      "y": 11,
      "z": -14,
      "name": "Rock_Basalt"
    },
    {
      "x": -13,
      "y": 12,
      "z": -14,
      "name": "Rock_Basalt"
    },
    {
      "x": -13,
      "y": 13,
      "z": -14,
      "name": "Rock_Basalt"
    },
    {
      "x": -13,
      "y": 14,
      "z": -14,
      "name": "Rock_Basalt"
    },
    {
      "x": -13,
      "y": 15,
      "z": -14,
      "name": "Rock_Basalt"
    },
    {
      "x": -13,
      "y": 16,
      "z": -14,
      "name": "Rock_Basalt"
    },
    {
      "x": -13,
      "y": 17,
      "z": -14,
      "name": "Rock_Basalt"
    },
    {
      "x": -13,
      "y": 18,
      "z": -14,
      "name": "Rock_Basalt"
    },
    {
      "x": -13,
      "y": 10,
      "z": -13,
      "name": "Rock_Basalt"
    },
    {
      "x": -13,
      "y": 11,
      "z": -13,
      "name": "Rock_Basalt"
    },
    {
      "x": -13,
      "y": 12,
      "z": -13,
      "name": "Rock_Basalt"
    },
    {
      "x": -13,
      "y": 13,
      "z": -13,
      "name": "Rock_Basalt"
    },
    {
      "x": -13,
      "y": 14,
      "z": -13,
      "name": "Rock_Basalt"
    },
    {
      "x": -13,
      "y": 15,
      "z": -13,
      "name": "Rock_Basalt"
    },
    {
      "x": -13,
      "y": 16,
      "z": -13,
      "name": "Rock_Basalt"
    },
    {
      "x": -13,
      "y": 17,
      "z": -13,
      "name": "Rock_Basalt"
    },
    {
      "x": -13,
      "y": 18,
      "z": -13,
      "name": "Rock_Basalt"
    },
    {
      "x": -13,
      "y": 10,
      "z": -12,
      "name": "Rock_Basalt"
    },
    {
      "x": -13,
      "y": 11,
      "z": -12,
      "name": "Rock_Basalt"
    },
    {
      "x": -13,
      "y": 12,
      "z": -12,
      "name": "Rock_Basalt"
    },
    {
      "x": -13,
      "y": 13,
      "z": -12,
      "name": "Rock_Basalt"
    },
    {
      "x": -13,
      "y": 14,
      "z": -12,
      "name": "Rock_Basalt"
    },
    {
      "x": -13,
      "y": 15,
      "z": -12,
      "name": "Rock_Basalt"
    },
    {
      "x": -13,
      "y": 16,
      "z": -12,
      "name": "Rock_Basalt"
    },
    {
      "x": -13,
      "y": 17,
      "z": -12,
      "name": "Rock_Basalt"
    },
    {
      "x": -13,
      "y": 18,
      "z": -12,
      "name": "Rock_Basalt_Cobble"
    },
    {
      "x": -13,
      "y": 10,
      "z": -11,
      "name": "Rock_Basalt"
    },
    {
      "x": -13,
      "y": 11,
      "z": -11,
      "name": "Rock_Basalt"
    },
    {
      "x": -13,
      "y": 12,
      "z": -11,
      "name": "Rock_Basalt"
    },
    {
      "x": -13,
      "y": 13,
      "z": -11,
      "name": "Rock_Basalt"
    },
    {
      "x": -13,
      "y": 14,
      "z": -11,
      "name": "Rock_Basalt"
    },
    {
      "x": -13,
      "y": 15,
      "z": -11,
      "name": "Rock_Basalt"
    },
    {
      "x": -13,
      "y": 16,
      "z": -11,
      "name": "Rock_Basalt"
    },
    {
      "x": -13,
      "y": 17,
      "z": -11,
      "name": "Rock_Basalt"
    },
    {
      "x": -13,
      "y": 18,
      "z": -11,
      "name": "Rock_Basalt_Cobble"
    },
    {
      "x": -13,
      "y": 9,
      "z": -10,
      "name": "Rock_Basalt_Stalactite_Large",
      "filler": 31744,
      "rotation": 8
    },
    {
      "x": -13,
      "y": 10,
      "z": -10,
      "name": "Rock_Basalt_Stalactite_Large",
      "rotation": 8
    },
    {
      "x": -13,
      "y": 11,
      "z": -10,
      "name": "Rock_Basalt"
    },
    {
      "x": -13,
      "y": 12,
      "z": -10,
      "name": "Rock_Basalt"
    },
    {
      "x": -13,
      "y": 13,
      "z": -10,
      "name": "Rock_Basalt"
    },
    {
      "x": -13,
      "y": 14,
      "z": -10,
      "name": "Rock_Basalt"
    },
    {
      "x": -13,
      "y": 15,
      "z": -10,
      "name": "Rock_Basalt"
    },
    {
      "x": -13,
      "y": 16,
      "z": -10,
      "name": "Rock_Basalt"
    },
    {
      "x": -13,
      "y": 17,
      "z": -10,
      "name": "Rock_Basalt_Cobble"
    },
    {
      "x": -13,
      "y": 12,
      "z": -9,
      "name": "Rock_Basalt"
    },
    {
      "x": -13,
      "y": 13,
      "z": -9,
      "name": "Rock_Basalt"
    },
    {
      "x": -13,
      "y": 14,
      "z": -9,
      "name": "Rock_Basalt"
    },
    {
      "x": -13,
      "y": 15,
      "z": -9,
      "name": "Rock_Basalt"
    },
    {
      "x": -13,
      "y": 16,
      "z": -9,
      "name": "Rock_Basalt"
    },
    {
      "x": -13,
      "y": 17,
      "z": -9,
      "name": "Rock_Basalt"
    },
    {
      "x": -13,
      "y": 12,
      "z": -8,
      "name": "Rock_Basalt"
    },
    {
      "x": -13,
      "y": 13,
      "z": -8,
      "name": "Rock_Basalt"
    },
    {
      "x": -13,
      "y": 14,
      "z": -8,
      "name": "Rock_Basalt"
    },
    {
      "x": -13,
      "y": 15,
      "z": -8,
      "name": "Rock_Basalt"
    },
    {
      "x": -13,
      "y": 16,
      "z": -8,
      "name": "Rock_Basalt"
    },
    {
      "x": -13,
      "y": 12,
      "z": -7,
      "name": "Ore_Iron_Basalt_Cracked"
    },
    {
      "x": -13,
      "y": 13,
      "z": -7,
      "name": "Rock_Basalt"
    },
    {
      "x": -13,
      "y": 14,
      "z": -7,
      "name": "Rock_Basalt"
    },
    {
      "x": -13,
      "y": 15,
      "z": -7,
      "name": "Rock_Basalt"
    },
    {
      "x": -13,
      "y": 16,
      "z": -7,
      "name": "Rock_Basalt"
    },
    {
      "x": -13,
      "y": 11,
      "z": -6,
      "name": "Rock_Basalt"
    },
    {
      "x": -13,
      "y": 12,
      "z": -6,
      "name": "Ore_Iron_Basalt_Cracked"
    },
    {
      "x": -13,
      "y": 13,
      "z": -6,
      "name": "Rock_Basalt"
    },
    {
      "x": -13,
      "y": 14,
      "z": -6,
      "name": "Rock_Basalt"
    },
    {
      "x": -13,
      "y": 15,
      "z": -6,
      "name": "Rock_Basalt"
    },
    {
      "x": -13,
      "y": 16,
      "z": -6,
      "name": "Rock_Basalt"
    },
    {
      "x": -13,
      "y": 11,
      "z": -5,
      "name": "Rock_Basalt"
    },
    {
      "x": -13,
      "y": 12,
      "z": -5,
      "name": "Rock_Basalt"
    },
    {
      "x": -13,
      "y": 13,
      "z": -5,
      "name": "Rock_Basalt"
    },
    {
      "x": -13,
      "y": 14,
      "z": -5,
      "name": "Rock_Basalt"
    },
    {
      "x": -13,
      "y": 15,
      "z": -5,
      "name": "Rock_Basalt"
    },
    {
      "x": -13,
      "y": 16,
      "z": -5,
      "name": "Rock_Basalt"
    },
    {
      "x": -13,
      "y": 11,
      "z": -4,
      "name": "Ore_Iron_Basalt_Cracked"
    },
    {
      "x": -13,
      "y": 12,
      "z": -4,
      "name": "Rock_Basalt"
    },
    {
      "x": -13,
      "y": 13,
      "z": -4,
      "name": "Ore_Iron_Basalt_Cracked"
    },
    {
      "x": -13,
      "y": 14,
      "z": -4,
      "name": "Rock_Basalt"
    },
    {
      "x": -13,
      "y": 15,
      "z": -4,
      "name": "Rock_Basalt"
    },
    {
      "x": -13,
      "y": 16,
      "z": -4,
      "name": "Rock_Basalt"
    },
    {
      "x": -13,
      "y": 13,
      "z": -3,
      "name": "Ore_Iron_Basalt_Cracked"
    },
    {
      "x": -13,
      "y": 14,
      "z": -3,
      "name": "Rock_Basalt"
    },
    {
      "x": -13,
      "y": 15,
      "z": -3,
      "name": "Ore_Iron_Basalt_Cracked"
    },
    {
      "x": -13,
      "y": 16,
      "z": -3,
      "name": "Rock_Basalt"
    },
    {
      "x": -13,
      "y": 17,
      "z": -3,
      "name": "Rock_Basalt"
    },
    {
      "x": -13,
      "y": 16,
      "z": 3,
      "name": "Ore_Iron_Basalt_Cracked"
    },
    {
      "x": -13,
      "y": 13,
      "z": 4,
      "name": "Rock_Basalt"
    },
    {
      "x": -13,
      "y": 14,
      "z": 4,
      "name": "Rock_Basalt"
    },
    {
      "x": -13,
      "y": 15,
      "z": 4,
      "name": "Rock_Basalt"
    },
    {
      "x": -13,
      "y": 16,
      "z": 4,
      "name": "Rock_Basalt"
    },
    {
      "x": -13,
      "y": 17,
      "z": 4,
      "name": "Ore_Iron_Basalt_Cracked"
    },
    {
      "x": -13,
      "y": 11,
      "z": 5,
      "name": "Rock_Basalt"
    },
    {
      "x": -13,
      "y": 12,
      "z": 5,
      "name": "Ore_Iron_Basalt_Cracked"
    },
    {
      "x": -13,
      "y": 13,
      "z": 5,
      "name": "Rock_Basalt"
    },
    {
      "x": -13,
      "y": 14,
      "z": 5,
      "name": "Rock_Basalt"
    },
    {
      "x": -13,
      "y": 15,
      "z": 5,
      "name": "Rock_Basalt"
    },
    {
      "x": -13,
      "y": 16,
      "z": 5,
      "name": "Rock_Basalt"
    },
    {
      "x": -13,
      "y": 17,
      "z": 5,
      "name": "Rock_Basalt"
    },
    {
      "x": -13,
      "y": 18,
      "z": 5,
      "name": "Rock_Basalt"
    },
    {
      "x": -13,
      "y": 10,
      "z": 6,
      "name": "Rock_Basalt"
    },
    {
      "x": -13,
      "y": 11,
      "z": 6,
      "name": "Rock_Basalt"
    },
    {
      "x": -13,
      "y": 12,
      "z": 6,
      "name": "Rock_Basalt"
    },
    {
      "x": -13,
      "y": 13,
      "z": 6,
      "name": "Rock_Basalt"
    },
    {
      "x": -13,
      "y": 14,
      "z": 6,
      "name": "Rock_Basalt"
    },
    {
      "x": -13,
      "y": 15,
      "z": 6,
      "name": "Rock_Basalt"
    },
    {
      "x": -13,
      "y": 16,
      "z": 6,
      "name": "Rock_Basalt"
    },
    {
      "x": -13,
      "y": 17,
      "z": 6,
      "name": "Rock_Basalt"
    },
    {
      "x": -13,
      "y": 18,
      "z": 6,
      "name": "Plant_Moss_Rug_Pink"
    },
    {
      "x": -13,
      "y": 9,
      "z": 7,
      "name": "Rock_Basalt"
    },
    {
      "x": -13,
      "y": 10,
      "z": 7,
      "name": "Rock_Basalt"
    },
    {
      "x": -13,
      "y": 11,
      "z": 7,
      "name": "Rock_Basalt"
    },
    {
      "x": -13,
      "y": 12,
      "z": 7,
      "name": "Rock_Basalt"
    },
    {
      "x": -13,
      "y": 13,
      "z": 7,
      "name": "Rock_Basalt"
    },
    {
      "x": -13,
      "y": 14,
      "z": 7,
      "name": "Rock_Basalt"
    },
    {
      "x": -13,
      "y": 15,
      "z": 7,
      "name": "Rock_Basalt"
    },
    {
      "x": -13,
      "y": 16,
      "z": 7,
      "name": "Rock_Basalt"
    },
    {
      "x": -13,
      "y": 17,
      "z": 7,
      "name": "Rock_Basalt"
    },
    {
      "x": -13,
      "y": 18,
      "z": 7,
      "name": "Rock_Basalt"
    },
    {
      "x": -13,
      "y": 19,
      "z": 7,
      "name": "Rock_Basalt"
    },
    {
      "x": -13,
      "y": 9,
      "z": 8,
      "name": "Rock_Basalt"
    },
    {
      "x": -13,
      "y": 10,
      "z": 8,
      "name": "Rock_Basalt"
    },
    {
      "x": -13,
      "y": 11,
      "z": 8,
      "name": "Rock_Basalt"
    },
    {
      "x": -13,
      "y": 12,
      "z": 8,
      "name": "Rock_Basalt"
    },
    {
      "x": -13,
      "y": 13,
      "z": 8,
      "name": "Rock_Basalt"
    },
    {
      "x": -13,
      "y": 14,
      "z": 8,
      "name": "Rock_Basalt"
    },
    {
      "x": -13,
      "y": 15,
      "z": 8,
      "name": "Rock_Basalt"
    },
    {
      "x": -13,
      "y": 16,
      "z": 8,
      "name": "Rock_Basalt"
    },
    {
      "x": -13,
      "y": 17,
      "z": 8,
      "name": "Rock_Basalt"
    },
    {
      "x": -13,
      "y": 18,
      "z": 8,
      "name": "Rock_Basalt"
    },
    {
      "x": -13,
      "y": 19,
      "z": 8,
      "name": "Rock_Basalt"
    },
    {
      "x": -13,
      "y": 9,
      "z": 9,
      "name": "Rock_Basalt"
    },
    {
      "x": -13,
      "y": 10,
      "z": 9,
      "name": "Rock_Basalt"
    },
    {
      "x": -13,
      "y": 11,
      "z": 9,
      "name": "Rock_Basalt"
    },
    {
      "x": -13,
      "y": 12,
      "z": 9,
      "name": "Rock_Basalt"
    },
    {
      "x": -13,
      "y": 13,
      "z": 9,
      "name": "Rock_Basalt"
    },
    {
      "x": -13,
      "y": 14,
      "z": 9,
      "name": "Rock_Basalt"
    },
    {
      "x": -13,
      "y": 15,
      "z": 9,
      "name": "Rock_Basalt"
    },
    {
      "x": -13,
      "y": 16,
      "z": 9,
      "name": "Rock_Basalt"
    },
    {
      "x": -13,
      "y": 17,
      "z": 9,
      "name": "Rock_Basalt"
    },
    {
      "x": -13,
      "y": 18,
      "z": 9,
      "name": "Rock_Basalt"
    },
    {
      "x": -13,
      "y": 19,
      "z": 9,
      "name": "Rock_Basalt"
    },
    {
      "x": -13,
      "y": 9,
      "z": 10,
      "name": "Rock_Basalt"
    },
    {
      "x": -13,
      "y": 10,
      "z": 10,
      "name": "Rock_Basalt"
    },
    {
      "x": -13,
      "y": 11,
      "z": 10,
      "name": "Rock_Basalt"
    },
    {
      "x": -13,
      "y": 12,
      "z": 10,
      "name": "Rock_Basalt"
    },
    {
      "x": -13,
      "y": 13,
      "z": 10,
      "name": "Rock_Basalt"
    },
    {
      "x": -13,
      "y": 14,
      "z": 10,
      "name": "Rock_Basalt"
    },
    {
      "x": -13,
      "y": 15,
      "z": 10,
      "name": "Rock_Basalt"
    },
    {
      "x": -13,
      "y": 16,
      "z": 10,
      "name": "Rock_Basalt"
    },
    {
      "x": -13,
      "y": 17,
      "z": 10,
      "name": "Rock_Basalt"
    },
    {
      "x": -13,
      "y": 18,
      "z": 10,
      "name": "Rock_Basalt"
    },
    {
      "x": -13,
      "y": 19,
      "z": 10,
      "name": "Rock_Basalt"
    },
    {
      "x": -13,
      "y": 9,
      "z": 11,
      "name": "Rock_Basalt"
    },
    {
      "x": -13,
      "y": 10,
      "z": 11,
      "name": "Rock_Basalt"
    },
    {
      "x": -13,
      "y": 11,
      "z": 11,
      "name": "Rock_Basalt"
    },
    {
      "x": -13,
      "y": 12,
      "z": 11,
      "name": "Rock_Basalt"
    },
    {
      "x": -13,
      "y": 13,
      "z": 11,
      "name": "Rock_Basalt"
    },
    {
      "x": -13,
      "y": 14,
      "z": 11,
      "name": "Rock_Basalt"
    },
    {
      "x": -13,
      "y": 15,
      "z": 11,
      "name": "Rock_Basalt"
    },
    {
      "x": -13,
      "y": 16,
      "z": 11,
      "name": "Rock_Basalt"
    },
    {
      "x": -13,
      "y": 17,
      "z": 11,
      "name": "Rock_Basalt"
    },
    {
      "x": -13,
      "y": 18,
      "z": 11,
      "name": "Rock_Basalt"
    },
    {
      "x": -13,
      "y": 19,
      "z": 11,
      "name": "Rock_Basalt"
    },
    {
      "x": -13,
      "y": 20,
      "z": 11,
      "name": "Rock_Crystal_Purple_Medium"
    },
    {
      "x": -13,
      "y": 21,
      "z": 11,
      "name": "Rock_Crystal_Purple_Medium",
      "rotation": 6
    },
    {
      "x": -13,
      "y": 10,
      "z": 12,
      "name": "Rock_Basalt"
    },
    {
      "x": -13,
      "y": 11,
      "z": 12,
      "name": "Rock_Basalt"
    },
    {
      "x": -13,
      "y": 12,
      "z": 12,
      "name": "Rock_Basalt"
    },
    {
      "x": -13,
      "y": 13,
      "z": 12,
      "name": "Rock_Basalt"
    },
    {
      "x": -13,
      "y": 14,
      "z": 12,
      "name": "Rock_Basalt"
    },
    {
      "x": -13,
      "y": 15,
      "z": 12,
      "name": "Rock_Basalt"
    },
    {
      "x": -13,
      "y": 16,
      "z": 12,
      "name": "Rock_Basalt"
    },
    {
      "x": -13,
      "y": 17,
      "z": 12,
      "name": "Rock_Basalt"
    },
    {
      "x": -13,
      "y": 18,
      "z": 12,
      "name": "Rock_Basalt"
    },
    {
      "x": -13,
      "y": 19,
      "z": 12,
      "name": "Rock_Crystal_Purple_Block",
      "rotation": 4
    },
    {
      "x": -13,
      "y": 20,
      "z": 12,
      "name": "Rock_Crystal_Purple_Block"
    },
    {
      "x": -13,
      "y": 21,
      "z": 12,
      "name": "Rock_Crystal_Purple_Block"
    },
    {
      "x": -13,
      "y": 22,
      "z": 12,
      "name": "Rock_Crystal_Purple_Medium"
    },
    {
      "x": -13,
      "y": 23,
      "z": 12,
      "name": "Rock_Crystal_Purple_Medium",
      "rotation": 5
    },
    {
      "x": -13,
      "y": 10,
      "z": 13,
      "name": "Rock_Basalt"
    },
    {
      "x": -13,
      "y": 11,
      "z": 13,
      "name": "Rock_Basalt"
    },
    {
      "x": -13,
      "y": 12,
      "z": 13,
      "name": "Rock_Basalt"
    },
    {
      "x": -13,
      "y": 13,
      "z": 13,
      "name": "Rock_Basalt"
    },
    {
      "x": -13,
      "y": 14,
      "z": 13,
      "name": "Rock_Basalt"
    },
    {
      "x": -13,
      "y": 15,
      "z": 13,
      "name": "Rock_Basalt"
    },
    {
      "x": -13,
      "y": 16,
      "z": 13,
      "name": "Rock_Basalt"
    },
    {
      "x": -13,
      "y": 17,
      "z": 13,
      "name": "Rock_Basalt"
    },
    {
      "x": -13,
      "y": 18,
      "z": 13,
      "name": "Rock_Basalt"
    },
    {
      "x": -13,
      "y": 19,
      "z": 13,
      "name": "Rock_Basalt"
    },
    {
      "x": -13,
      "y": 20,
      "z": 13,
      "name": "Rock_Crystal_Purple_Medium",
      "rotation": 4
    },
    {
      "x": -13,
      "y": 10,
      "z": 14,
      "name": "Rock_Basalt"
    },
    {
      "x": -13,
      "y": 11,
      "z": 14,
      "name": "Rock_Basalt"
    },
    {
      "x": -13,
      "y": 12,
      "z": 14,
      "name": "Rock_Basalt"
    },
    {
      "x": -13,
      "y": 13,
      "z": 14,
      "name": "Rock_Basalt"
    },
    {
      "x": -13,
      "y": 14,
      "z": 14,
      "name": "Rock_Basalt"
    },
    {
      "x": -13,
      "y": 15,
      "z": 14,
      "name": "Rock_Basalt"
    },
    {
      "x": -13,
      "y": 16,
      "z": 14,
      "name": "Rock_Basalt"
    },
    {
      "x": -13,
      "y": 17,
      "z": 14,
      "name": "Rock_Basalt"
    },
    {
      "x": -13,
      "y": 18,
      "z": 14,
      "name": "Rock_Basalt"
    },
    {
      "x": -13,
      "y": 19,
      "z": 14,
      "name": "Rock_Basalt"
    },
    {
      "x": -13,
      "y": 10,
      "z": 15,
      "name": "Ore_Iron_Basalt_Cracked"
    },
    {
      "x": -13,
      "y": 11,
      "z": 15,
      "name": "Rock_Basalt"
    },
    {
      "x": -13,
      "y": 12,
      "z": 15,
      "name": "Rock_Basalt"
    },
    {
      "x": -13,
      "y": 13,
      "z": 15,
      "name": "Rock_Basalt"
    },
    {
      "x": -13,
      "y": 14,
      "z": 15,
      "name": "Rock_Basalt"
    },
    {
      "x": -13,
      "y": 15,
      "z": 15,
      "name": "Rock_Basalt"
    },
    {
      "x": -13,
      "y": 16,
      "z": 15,
      "name": "Rock_Basalt"
    },
    {
      "x": -13,
      "y": 17,
      "z": 15,
      "name": "Rock_Basalt"
    },
    {
      "x": -13,
      "y": 18,
      "z": 15,
      "name": "Rock_Basalt"
    },
    {
      "x": -13,
      "y": 19,
      "z": 15,
      "name": "Rock_Basalt"
    },
    {
      "x": -13,
      "y": 11,
      "z": 16,
      "name": "Rock_Basalt"
    },
    {
      "x": -13,
      "y": 12,
      "z": 16,
      "name": "Rock_Basalt"
    },
    {
      "x": -13,
      "y": 13,
      "z": 16,
      "name": "Rock_Basalt"
    },
    {
      "x": -13,
      "y": 14,
      "z": 16,
      "name": "Rock_Basalt"
    },
    {
      "x": -13,
      "y": 15,
      "z": 16,
      "name": "Rock_Basalt"
    },
    {
      "x": -13,
      "y": 16,
      "z": 16,
      "name": "Rock_Basalt"
    },
    {
      "x": -13,
      "y": 17,
      "z": 16,
      "name": "Rock_Basalt"
    },
    {
      "x": -13,
      "y": 18,
      "z": 16,
      "name": "Rock_Basalt"
    },
    {
      "x": -13,
      "y": 19,
      "z": 16,
      "name": "Rock_Basalt"
    },
    {
      "x": -13,
      "y": 11,
      "z": 17,
      "name": "Rock_Basalt"
    },
    {
      "x": -13,
      "y": 12,
      "z": 17,
      "name": "Ore_Iron_Basalt_Cracked"
    },
    {
      "x": -13,
      "y": 13,
      "z": 17,
      "name": "Ore_Iron_Basalt_Cracked"
    },
    {
      "x": -13,
      "y": 14,
      "z": 17,
      "name": "Rock_Basalt"
    },
    {
      "x": -13,
      "y": 15,
      "z": 17,
      "name": "Rock_Basalt"
    },
    {
      "x": -13,
      "y": 16,
      "z": 17,
      "name": "Rock_Basalt"
    },
    {
      "x": -13,
      "y": 17,
      "z": 17,
      "name": "Rock_Basalt"
    },
    {
      "x": -13,
      "y": 18,
      "z": 17,
      "name": "Rock_Basalt"
    },
    {
      "x": -13,
      "y": 19,
      "z": 17,
      "name": "Rock_Basalt"
    },
    {
      "x": -13,
      "y": 13,
      "z": 18,
      "name": "Ore_Iron_Basalt_Cracked"
    },
    {
      "x": -13,
      "y": 14,
      "z": 18,
      "name": "Rock_Basalt"
    },
    {
      "x": -13,
      "y": 15,
      "z": 18,
      "name": "Rock_Basalt"
    },
    {
      "x": -13,
      "y": 16,
      "z": 18,
      "name": "Rock_Basalt"
    },
    {
      "x": -13,
      "y": 17,
      "z": 18,
      "name": "Rock_Basalt"
    },
    {
      "x": -13,
      "y": 18,
      "z": 18,
      "name": "Rock_Basalt"
    },
    {
      "x": -13,
      "y": 19,
      "z": 18,
      "name": "Rubble_Basalt_Medium"
    },
    {
      "x": -12,
      "y": 14,
      "z": -17,
      "name": "Ore_Iron_Basalt"
    },
    {
      "x": -12,
      "y": 15,
      "z": -17,
      "name": "Soil_Basalt_Gravel"
    },
    {
      "x": -12,
      "y": 16,
      "z": -17,
      "name": "Plant_Moss_Rug_Pink"
    },
    {
      "x": -12,
      "y": 12,
      "z": -16,
      "name": "Rock_Basalt"
    },
    {
      "x": -12,
      "y": 13,
      "z": -16,
      "name": "Rock_Basalt"
    },
    {
      "x": -12,
      "y": 14,
      "z": -16,
      "name": "Rock_Basalt"
    },
    {
      "x": -12,
      "y": 15,
      "z": -16,
      "name": "Ore_Iron_Basalt_Cracked"
    },
    {
      "x": -12,
      "y": 16,
      "z": -16,
      "name": "Rock_Basalt"
    },
    {
      "x": -12,
      "y": 17,
      "z": -16,
      "name": "Plant_Moss_Rug_Pink"
    },
    {
      "x": -12,
      "y": 10,
      "z": -15,
      "name": "Rock_Basalt"
    },
    {
      "x": -12,
      "y": 11,
      "z": -15,
      "name": "Rock_Basalt"
    },
    {
      "x": -12,
      "y": 12,
      "z": -15,
      "name": "Rock_Basalt"
    },
    {
      "x": -12,
      "y": 13,
      "z": -15,
      "name": "Rock_Basalt"
    },
    {
      "x": -12,
      "y": 14,
      "z": -15,
      "name": "Rock_Basalt"
    },
    {
      "x": -12,
      "y": 15,
      "z": -15,
      "name": "Rock_Basalt"
    },
    {
      "x": -12,
      "y": 16,
      "z": -15,
      "name": "Rock_Basalt"
    },
    {
      "x": -12,
      "y": 17,
      "z": -15,
      "name": "Rock_Basalt"
    },
    {
      "x": -12,
      "y": 10,
      "z": -14,
      "name": "Rock_Basalt"
    },
    {
      "x": -12,
      "y": 11,
      "z": -14,
      "name": "Rock_Basalt"
    },
    {
      "x": -12,
      "y": 12,
      "z": -14,
      "name": "Rock_Basalt"
    },
    {
      "x": -12,
      "y": 13,
      "z": -14,
      "name": "Rock_Basalt"
    },
    {
      "x": -12,
      "y": 14,
      "z": -14,
      "name": "Rock_Basalt"
    },
    {
      "x": -12,
      "y": 15,
      "z": -14,
      "name": "Rock_Basalt"
    },
    {
      "x": -12,
      "y": 16,
      "z": -14,
      "name": "Rock_Basalt"
    },
    {
      "x": -12,
      "y": 17,
      "z": -14,
      "name": "Rock_Basalt"
    },
    {
      "x": -12,
      "y": 18,
      "z": -14,
      "name": "Rock_Basalt"
    },
    {
      "x": -12,
      "y": 9,
      "z": -13,
      "name": "Ore_Iron_Basalt_Cracked"
    },
    {
      "x": -12,
      "y": 10,
      "z": -13,
      "name": "Rock_Basalt"
    },
    {
      "x": -12,
      "y": 11,
      "z": -13,
      "name": "Rock_Basalt"
    },
    {
      "x": -12,
      "y": 12,
      "z": -13,
      "name": "Rock_Basalt"
    },
    {
      "x": -12,
      "y": 13,
      "z": -13,
      "name": "Rock_Basalt"
    },
    {
      "x": -12,
      "y": 14,
      "z": -13,
      "name": "Rock_Basalt"
    },
    {
      "x": -12,
      "y": 15,
      "z": -13,
      "name": "Rock_Basalt"
    },
    {
      "x": -12,
      "y": 16,
      "z": -13,
      "name": "Rock_Basalt"
    },
    {
      "x": -12,
      "y": 17,
      "z": -13,
      "name": "Rock_Basalt"
    },
    {
      "x": -12,
      "y": 18,
      "z": -13,
      "name": "Rock_Basalt"
    },
    {
      "x": -12,
      "y": 9,
      "z": -12,
      "name": "Rock_Basalt"
    },
    {
      "x": -12,
      "y": 10,
      "z": -12,
      "name": "Rock_Basalt"
    },
    {
      "x": -12,
      "y": 11,
      "z": -12,
      "name": "Rock_Basalt"
    },
    {
      "x": -12,
      "y": 12,
      "z": -12,
      "name": "Rock_Basalt"
    },
    {
      "x": -12,
      "y": 13,
      "z": -12,
      "name": "Rock_Basalt"
    },
    {
      "x": -12,
      "y": 14,
      "z": -12,
      "name": "Rock_Basalt"
    },
    {
      "x": -12,
      "y": 15,
      "z": -12,
      "name": "Rock_Basalt"
    },
    {
      "x": -12,
      "y": 16,
      "z": -12,
      "name": "Rock_Basalt"
    },
    {
      "x": -12,
      "y": 17,
      "z": -12,
      "name": "Rock_Basalt"
    },
    {
      "x": -12,
      "y": 18,
      "z": -12,
      "name": "Rock_Basalt"
    },
    {
      "x": -12,
      "y": 9,
      "z": -11,
      "name": "Rock_Basalt"
    },
    {
      "x": -12,
      "y": 10,
      "z": -11,
      "name": "Rock_Basalt"
    },
    {
      "x": -12,
      "y": 11,
      "z": -11,
      "name": "Rock_Basalt"
    },
    {
      "x": -12,
      "y": 12,
      "z": -11,
      "name": "Rock_Basalt"
    },
    {
      "x": -12,
      "y": 13,
      "z": -11,
      "name": "Rock_Basalt"
    },
    {
      "x": -12,
      "y": 14,
      "z": -11,
      "name": "Rock_Basalt"
    },
    {
      "x": -12,
      "y": 15,
      "z": -11,
      "name": "Rock_Basalt"
    },
    {
      "x": -12,
      "y": 16,
      "z": -11,
      "name": "Rock_Basalt"
    },
    {
      "x": -12,
      "y": 17,
      "z": -11,
      "name": "Rock_Basalt"
    },
    {
      "x": -12,
      "y": 18,
      "z": -11,
      "name": "Rock_Basalt_Cobble"
    },
    {
      "x": -12,
      "y": 10,
      "z": -10,
      "name": "Rock_Basalt"
    },
    {
      "x": -12,
      "y": 11,
      "z": -10,
      "name": "Rock_Basalt"
    },
    {
      "x": -12,
      "y": 12,
      "z": -10,
      "name": "Rock_Basalt"
    },
    {
      "x": -12,
      "y": 13,
      "z": -10,
      "name": "Rock_Basalt"
    },
    {
      "x": -12,
      "y": 14,
      "z": -10,
      "name": "Rock_Basalt"
    },
    {
      "x": -12,
      "y": 15,
      "z": -10,
      "name": "Rock_Basalt"
    },
    {
      "x": -12,
      "y": 16,
      "z": -10,
      "name": "Rock_Basalt"
    },
    {
      "x": -12,
      "y": 17,
      "z": -10,
      "name": "Rock_Basalt_Cobble"
    },
    {
      "x": -12,
      "y": 11,
      "z": -9,
      "name": "Rock_Basalt"
    },
    {
      "x": -12,
      "y": 12,
      "z": -9,
      "name": "Rock_Basalt"
    },
    {
      "x": -12,
      "y": 13,
      "z": -9,
      "name": "Rock_Basalt"
    },
    {
      "x": -12,
      "y": 14,
      "z": -9,
      "name": "Rock_Basalt"
    },
    {
      "x": -12,
      "y": 15,
      "z": -9,
      "name": "Rock_Basalt"
    },
    {
      "x": -12,
      "y": 16,
      "z": -9,
      "name": "Rock_Basalt"
    },
    {
      "x": -12,
      "y": 17,
      "z": -9,
      "name": "Rock_Basalt"
    },
    {
      "x": -12,
      "y": 11,
      "z": -8,
      "name": "Rock_Basalt"
    },
    {
      "x": -12,
      "y": 12,
      "z": -8,
      "name": "Rock_Basalt"
    },
    {
      "x": -12,
      "y": 13,
      "z": -8,
      "name": "Rock_Basalt"
    },
    {
      "x": -12,
      "y": 14,
      "z": -8,
      "name": "Rock_Basalt"
    },
    {
      "x": -12,
      "y": 15,
      "z": -8,
      "name": "Rock_Basalt"
    },
    {
      "x": -12,
      "y": 16,
      "z": -8,
      "name": "Rock_Basalt"
    },
    {
      "x": -12,
      "y": 17,
      "z": -8,
      "name": "Ore_Silver_Basalt"
    },
    {
      "x": -12,
      "y": 10,
      "z": -7,
      "name": "Ore_Iron_Basalt_Cracked"
    },
    {
      "x": -12,
      "y": 11,
      "z": -7,
      "name": "Rock_Basalt"
    },
    {
      "x": -12,
      "y": 12,
      "z": -7,
      "name": "Rock_Basalt"
    },
    {
      "x": -12,
      "y": 13,
      "z": -7,
      "name": "Rock_Basalt"
    },
    {
      "x": -12,
      "y": 14,
      "z": -7,
      "name": "Rock_Basalt"
    },
    {
      "x": -12,
      "y": 15,
      "z": -7,
      "name": "Rock_Basalt"
    },
    {
      "x": -12,
      "y": 16,
      "z": -7,
      "name": "Rock_Basalt"
    },
    {
      "x": -12,
      "y": 17,
      "z": -7,
      "name": "Rock_Basalt"
    },
    {
      "x": -12,
      "y": 10,
      "z": -6,
      "name": "Rock_Basalt"
    },
    {
      "x": -12,
      "y": 11,
      "z": -6,
      "name": "Rock_Basalt"
    },
    {
      "x": -12,
      "y": 12,
      "z": -6,
      "name": "Rock_Basalt"
    },
    {
      "x": -12,
      "y": 13,
      "z": -6,
      "name": "Rock_Basalt"
    },
    {
      "x": -12,
      "y": 14,
      "z": -6,
      "name": "Rock_Basalt"
    },
    {
      "x": -12,
      "y": 15,
      "z": -6,
      "name": "Rock_Basalt"
    },
    {
      "x": -12,
      "y": 16,
      "z": -6,
      "name": "Rock_Basalt"
    },
    {
      "x": -12,
      "y": 17,
      "z": -6,
      "name": "Rock_Basalt"
    },
    {
      "x": -12,
      "y": 10,
      "z": -5,
      "name": "Rock_Basalt"
    },
    {
      "x": -12,
      "y": 11,
      "z": -5,
      "name": "Ore_Iron_Basalt_Cracked"
    },
    {
      "x": -12,
      "y": 12,
      "z": -5,
      "name": "Rock_Basalt"
    },
    {
      "x": -12,
      "y": 13,
      "z": -5,
      "name": "Rock_Basalt"
    },
    {
      "x": -12,
      "y": 14,
      "z": -5,
      "name": "Rock_Basalt"
    },
    {
      "x": -12,
      "y": 15,
      "z": -5,
      "name": "Rock_Basalt"
    },
    {
      "x": -12,
      "y": 16,
      "z": -5,
      "name": "Rock_Basalt"
    },
    {
      "x": -12,
      "y": 17,
      "z": -5,
      "name": "Ore_Iron_Basalt_Cracked"
    },
    {
      "x": -12,
      "y": 10,
      "z": -4,
      "name": "Ore_Iron_Basalt_Cracked"
    },
    {
      "x": -12,
      "y": 11,
      "z": -4,
      "name": "Ore_Iron_Basalt_Cracked"
    },
    {
      "x": -12,
      "y": 12,
      "z": -4,
      "name": "Rock_Basalt"
    },
    {
      "x": -12,
      "y": 13,
      "z": -4,
      "name": "Rock_Basalt"
    },
    {
      "x": -12,
      "y": 14,
      "z": -4,
      "name": "Rock_Basalt"
    },
    {
      "x": -12,
      "y": 15,
      "z": -4,
      "name": "Rock_Basalt"
