{
  "version": 8,
  "blockIdVersion": 11,
  "anchorX": 0,
  "anchorY": 0,
  "anchorZ": 0,
  "blocks": [
    {
      "x": -19,
      "y": 45,
      "z": -2,
      "name": "Soil_Mud"
    },
    {
      "x": -19,
      "y": 42,
      "z": -1,
      "name": "Soil_Mud"
    },
    {
      "x": -19,
      "y": 43,
      "z": -1,
      "name": "Soil_Mud_Dry"
    },
    {
      "x": -19,
      "y": 44,
      "z": -1,
      "name": "Soil_Mud_Dry"
    },
    {
      "x": -19,
      "y": 45,
      "z": -1,
      "name": "Soil_Mud"
    },
    {
      "x": -19,
      "y": 46,
      "z": -1,
      "name": "Plant_Flower_Bushy_Violet"
    },
    {
      "x": -19,
      "y": 42,
      "z": 0,
      "name": "Soil_Mud"
    },
    {
      "x": -19,
      "y": 43,
      "z": 0,
      "name": "Soil_Mud"
    },
    {
      "x": -19,
      "y": 44,
      "z": 0,
      "name": "Soil_Mud"
    },
    {
      "x": -19,
      "y": 45,
      "z": 0,
      "name": "Soil_Mud"
    },
    {
      "x": -19,
      "y": 42,
      "z": 1,
      "name": "Soil_Mud_Dry"
    },
    {
      "x": -19,
      "y": 43,
      "z": 1,
      "name": "Soil_Mud_Dry"
    },
    {
      "x": -18,
      "y": 42,
      "z": -3,
      "name": "Soil_Mud"
    },
    {
      "x": -18,
      "y": 43,
      "z": -3,
      "name": "Soil_Mud"
    },
    {
      "x": -18,
      "y": 44,
      "z": -3,
      "name": "Soil_Mud_Dry"
    },
    {
      "x": -18,
      "y": 45,
      "z": -3,
      "name": "Soil_Mud"
    },
    {
      "x": -18,
      "y": 40,
      "z": -2,
      "name": "Soil_Mud"
    },
    {
      "x": -18,
      "y": 41,
      "z": -2,
      "name": "Soil_Mud_Dry"
    },
    {
      "x": -18,
      "y": 42,
      "z": -2,
      "name": "Soil_Mud_Dry"
    },
    {
      "x": -18,
      "y": 43,
      "z": -2,
      "name": "Soil_Mud"
    },
    {
      "x": -18,
      "y": 44,
      "z": -2,
      "name": "Soil_Mud"
    },
    {
      "x": -18,
      "y": 45,
      "z": -2,
      "name": "Soil_Mud"
    },
    {
      "x": -18,
      "y": 46,
      "z": -2,
      "name": "Plant_Crop_Mushroom_Glowing_Violet"
    },
    {
      "x": -18,
      "y": 39,
      "z": -1,
      "name": "Soil_Mud"
    },
    {
      "x": -18,
      "y": 40,
      "z": -1,
      "name": "Soil_Mud"
    },
    {
      "x": -18,
      "y": 41,
      "z": -1,
      "name": "Soil_Mud_Dry"
    },
    {
      "x": -18,
      "y": 42,
      "z": -1,
      "name": "Soil_Mud"
    },
    {
      "x": -18,
      "y": 43,
      "z": -1,
      "name": "Soil_Mud"
    },
    {
      "x": -18,
      "y": 44,
      "z": -1,
      "name": "Soil_Mud"
    },
    {
      "x": -18,
      "y": 45,
      "z": -1,
      "name": "Soil_Mud"
    },
    {
      "x": -18,
      "y": 46,
      "z": -1,
      "name": "Plant_Grass_Cave_Short"
    },
    {
      "x": -18,
      "y": 37,
      "z": 0,
      "name": "Soil_Mud_Dry"
    },
    {
      "x": -18,
      "y": 38,
      "z": 0,
      "name": "Soil_Mud"
    },
    {
      "x": -18,
      "y": 39,
      "z": 0,
      "name": "Soil_Mud"
    },
    {
      "x": -18,
      "y": 40,
      "z": 0,
      "name": "Soil_Mud"
    },
    {
      "x": -18,
      "y": 41,
      "z": 0,
      "name": "Soil_Mud_Dry"
    },
    {
      "x": -18,
      "y": 42,
      "z": 0,
      "name": "Soil_Mud"
    },
    {
      "x": -18,
      "y": 43,
      "z": 0,
      "name": "Soil_Mud"
    },
    {
      "x": -18,
      "y": 44,
      "z": 0,
      "name": "Soil_Mud_Dry"
    },
    {
      "x": -18,
      "y": 45,
      "z": 0,
      "name": "Soil_Mud_Dry"
    },
    {
      "x": -18,
      "y": 46,
      "z": 0,
      "name": "Plant_Crop_Mushroom_Cap_Brown"
    },
    {
      "x": -18,
      "y": 39,
      "z": 1,
      "name": "Soil_Mud"
    },
    {
      "x": -18,
      "y": 40,
      "z": 1,
      "name": "Soil_Mud"
    },
    {
      "x": -18,
      "y": 41,
      "z": 1,
      "name": "Soil_Mud"
    },
    {
      "x": -18,
      "y": 42,
      "z": 1,
      "name": "Soil_Mud"
    },
    {
      "x": -18,
      "y": 43,
      "z": 1,
      "name": "Soil_Mud"
    },
    {
      "x": -18,
      "y": 44,
      "z": 1,
      "name": "Soil_Mud_Dry"
    },
    {
      "x": -18,
      "y": 40,
      "z": 2,
      "name": "Soil_Mud"
    },
    {
      "x": -18,
      "y": 41,
      "z": 2,
      "name": "Soil_Mud"
    },
    {
      "x": -18,
      "y": 42,
      "z": 2,
      "name": "Soil_Mud"
    },
    {
      "x": -18,
      "y": 43,
      "z": 2,
      "name": "Soil_Mud"
    },
    {
      "x": -18,
      "y": 44,
      "z": 2,
      "name": "Soil_Mud_Dry"
    },
    {
      "x": -17,
      "y": 42,
      "z": -4,
      "name": "Soil_Mud"
    },
    {
      "x": -17,
      "y": 43,
      "z": -4,
      "name": "Soil_Mud"
    },
    {
      "x": -17,
      "y": 44,
      "z": -4,
      "name": "Soil_Mud_Dry"
    },
    {
      "x": -17,
      "y": 45,
      "z": -4,
      "name": "Soil_Mud"
    },
    {
      "x": -17,
      "y": 46,
      "z": -4,
      "name": "Plant_Flower_Bushy_Violet"
    },
    {
      "x": -17,
      "y": 39,
      "z": -3,
      "name": "Soil_Mud"
    },
    {
      "x": -17,
      "y": 40,
      "z": -3,
      "name": "Soil_Mud"
    },
    {
      "x": -17,
      "y": 41,
      "z": -3,
      "name": "Soil_Mud"
    },
    {
      "x": -17,
      "y": 42,
      "z": -3,
      "name": "Soil_Mud_Dry"
    },
    {
      "x": -17,
      "y": 43,
      "z": -3,
      "name": "Soil_Mud"
    },
    {
      "x": -17,
      "y": 44,
      "z": -3,
      "name": "Soil_Mud"
    },
    {
      "x": -17,
      "y": 45,
      "z": -3,
      "name": "Soil_Mud"
    },
    {
      "x": -17,
      "y": 38,
      "z": -2,
      "name": "Soil_Mud_Dry"
    },
    {
      "x": -17,
      "y": 39,
      "z": -2,
      "name": "Soil_Mud"
    },
    {
      "x": -17,
      "y": 40,
      "z": -2,
      "name": "Soil_Mud"
    },
    {
      "x": -17,
      "y": 41,
      "z": -2,
      "name": "Soil_Mud"
    },
    {
      "x": -17,
      "y": 42,
      "z": -2,
      "name": "Soil_Mud"
    },
    {
      "x": -17,
      "y": 43,
      "z": -2,
      "name": "Soil_Mud"
    },
    {
      "x": -17,
      "y": 44,
      "z": -2,
      "name": "Soil_Mud_Dry"
    },
    {
      "x": -17,
      "y": 45,
      "z": -2,
      "name": "Soil_Mud"
    },
    {
      "x": -17,
      "y": 46,
      "z": -2,
      "name": "Plant_Flower_Bushy_Purple"
    },
    {
      "x": -17,
      "y": 36,
      "z": -1,
      "name": "Soil_Mud"
    },
    {
      "x": -17,
      "y": 37,
      "z": -1,
      "name": "Soil_Mud"
    },
    {
      "x": -17,
      "y": 38,
      "z": -1,
      "name": "Soil_Mud"
    },
    {
      "x": -17,
      "y": 39,
      "z": -1,
      "name": "Soil_Mud_Dry"
    },
    {
      "x": -17,
      "y": 40,
      "z": -1,
      "name": "Soil_Mud"
    },
    {
      "x": -17,
      "y": 41,
      "z": -1,
      "name": "Soil_Mud"
    },
    {
      "x": -17,
      "y": 42,
      "z": -1,
      "name": "Soil_Mud"
    },
    {
      "x": -17,
      "y": 43,
      "z": -1,
      "name": "Soil_Mud"
    },
    {
      "x": -17,
      "y": 44,
      "z": -1,
      "name": "Soil_Mud"
    },
    {
      "x": -17,
      "y": 45,
      "z": -1,
      "name": "Soil_Mud_Dry"
    },
    {
      "x": -17,
      "y": 35,
      "z": 0,
      "name": "Soil_Mud"
    },
    {
      "x": -17,
      "y": 36,
      "z": 0,
      "name": "Soil_Mud"
    },
    {
      "x": -17,
      "y": 37,
      "z": 0,
      "name": "Soil_Mud"
    },
    {
      "x": -17,
      "y": 38,
      "z": 0,
      "name": "Soil_Mud"
    },
    {
      "x": -17,
      "y": 39,
      "z": 0,
      "name": "Soil_Mud"
    },
    {
      "x": -17,
      "y": 40,
      "z": 0,
      "name": "Soil_Mud"
    },
    {
      "x": -17,
      "y": 41,
      "z": 0,
      "name": "Soil_Mud_Dry"
    },
    {
      "x": -17,
      "y": 42,
      "z": 0,
      "name": "Soil_Mud"
    },
    {
      "x": -17,
      "y": 43,
      "z": 0,
      "name": "Soil_Mud_Dry"
    },
    {
      "x": -17,
      "y": 44,
      "z": 0,
      "name": "Soil_Mud"
    },
    {
      "x": -17,
      "y": 45,
      "z": 0,
      "name": "Soil_Mud_Dry"
    },
    {
      "x": -17,
      "y": 36,
      "z": 1,
      "name": "Soil_Mud_Dry"
    },
    {
      "x": -17,
      "y": 37,
      "z": 1,
      "name": "Soil_Mud"
    },
    {
      "x": -17,
      "y": 38,
      "z": 1,
      "name": "Soil_Mud"
    },
    {
      "x": -17,
      "y": 39,
      "z": 1,
      "name": "Soil_Mud"
    },
    {
      "x": -17,
      "y": 40,
      "z": 1,
      "name": "Soil_Mud"
    },
    {
      "x": -17,
      "y": 41,
      "z": 1,
      "name": "Soil_Mud"
    },
    {
      "x": -17,
      "y": 42,
      "z": 1,
      "name": "Soil_Mud_Dry"
    },
    {
      "x": -17,
      "y": 43,
      "z": 1,
      "name": "Soil_Mud"
    },
    {
      "x": -17,
      "y": 44,
      "z": 1,
      "name": "Soil_Mud_Dry"
    },
    {
      "x": -17,
      "y": 45,
      "z": 1,
      "name": "Soil_Mud"
    },
    {
      "x": -17,
      "y": 38,
      "z": 2,
      "name": "Soil_Mud"
    },
    {
      "x": -17,
      "y": 39,
      "z": 2,
      "name": "Soil_Mud"
    },
    {
      "x": -17,
      "y": 40,
      "z": 2,
      "name": "Soil_Mud"
    },
    {
      "x": -17,
      "y": 41,
      "z": 2,
      "name": "Soil_Mud"
    },
    {
      "x": -17,
      "y": 42,
      "z": 2,
      "name": "Soil_Mud"
    },
    {
      "x": -17,
      "y": 43,
      "z": 2,
      "name": "Soil_Mud"
    },
    {
      "x": -17,
      "y": 44,
      "z": 2,
      "name": "Soil_Mud"
    },
    {
      "x": -17,
      "y": 45,
      "z": 2,
      "name": "Soil_Mud_Dry"
    },
    {
      "x": -17,
      "y": 37,
      "z": 3,
      "name": "Plant_Moss_Cave_Red"
    },
    {
      "x": -17,
      "y": 38,
      "z": 3,
      "name": "Soil_Mud_Dry"
    },
    {
      "x": -17,
      "y": 39,
      "z": 3,
      "name": "Soil_Mud"
    },
    {
      "x": -17,
      "y": 41,
      "z": 3,
      "name": "Soil_Mud"
    },
    {
      "x": -17,
      "y": 42,
      "z": 3,
      "name": "Soil_Mud"
    },
    {
      "x": -17,
      "y": 43,
      "z": 3,
      "name": "Soil_Mud"
    },
    {
      "x": -17,
      "y": 44,
      "z": 3,
      "name": "Soil_Mud"
    },
    {
      "x": -16,
      "y": 44,
      "z": -5,
      "name": "Soil_Mud"
    },
    {
      "x": -16,
      "y": 45,
      "z": -5,
      "name": "Soil_Mud"
    },
    {
      "x": -16,
      "y": 40,
      "z": -4,
      "name": "Soil_Mud"
    },
    {
      "x": -16,
      "y": 41,
      "z": -4,
      "name": "Soil_Mud"
    },
    {
      "x": -16,
      "y": 42,
      "z": -4,
      "name": "Soil_Mud"
    },
    {
      "x": -16,
      "y": 43,
      "z": -4,
      "name": "Soil_Mud"
    },
    {
      "x": -16,
      "y": 44,
      "z": -4,
      "name": "Soil_Mud"
    },
    {
      "x": -16,
      "y": 45,
      "z": -4,
      "name": "Soil_Mud_Dry"
    },
    {
      "x": -16,
      "y": 38,
      "z": -3,
      "name": "Soil_Mud"
    },
    {
      "x": -16,
      "y": 39,
      "z": -3,
      "name": "Soil_Mud_Dry"
    },
    {
      "x": -16,
      "y": 40,
      "z": -3,
      "name": "Soil_Mud"
    },
    {
      "x": -16,
      "y": 41,
      "z": -3,
      "name": "Soil_Mud_Dry"
    },
    {
      "x": -16,
      "y": 42,
      "z": -3,
      "name": "Soil_Mud"
    },
    {
      "x": -16,
      "y": 43,
      "z": -3,
      "name": "Soil_Mud"
    },
    {
      "x": -16,
      "y": 44,
      "z": -3,
      "name": "Soil_Mud_Dry"
    },
    {
      "x": -16,
      "y": 45,
      "z": -3,
      "name": "Soil_Mud"
    },
    {
      "x": -16,
      "y": 46,
      "z": -3,
      "name": "Plant_Crop_Mushroom_Glowing_Purple"
    },
    {
      "x": -16,
      "y": 36,
      "z": -2,
      "name": "Soil_Mud"
    },
    {
      "x": -16,
      "y": 37,
      "z": -2,
      "name": "Soil_Mud"
    },
    {
      "x": -16,
      "y": 38,
      "z": -2,
      "name": "Soil_Mud"
    },
    {
      "x": -16,
      "y": 39,
      "z": -2,
      "name": "Soil_Mud"
    },
    {
      "x": -16,
      "y": 40,
      "z": -2,
      "name": "Soil_Mud_Dry"
    },
    {
      "x": -16,
      "y": 41,
      "z": -2,
      "name": "Soil_Mud"
    },
    {
      "x": -16,
      "y": 42,
      "z": -2,
      "name": "Soil_Mud_Dry"
    },
    {
      "x": -16,
      "y": 43,
      "z": -2,
      "name": "Soil_Mud_Dry"
    },
    {
      "x": -16,
      "y": 44,
      "z": -2,
      "name": "Soil_Mud"
    },
    {
      "x": -16,
      "y": 45,
      "z": -2,
      "name": "Soil_Mud"
    },
    {
      "x": -16,
      "y": 46,
      "z": -2,
      "name": "Plant_Moss_Rug_Pink"
    },
    {
      "x": -16,
      "y": 35,
      "z": -1,
      "name": "Soil_Mud_Dry"
    },
    {
      "x": -16,
      "y": 36,
      "z": -1,
      "name": "Soil_Mud"
    },
    {
      "x": -16,
      "y": 37,
      "z": -1,
      "name": "Soil_Mud_Dry"
    },
    {
      "x": -16,
      "y": 38,
      "z": -1,
      "name": "Soil_Mud"
    },
    {
      "x": -16,
      "y": 39,
      "z": -1,
      "name": "Soil_Mud"
    },
    {
      "x": -16,
      "y": 40,
      "z": -1,
      "name": "Soil_Mud"
    },
    {
      "x": -16,
      "y": 41,
      "z": -1,
      "name": "Soil_Mud"
    },
    {
      "x": -16,
      "y": 42,
      "z": -1,
      "name": "Soil_Mud"
    },
    {
      "x": -16,
      "y": 43,
      "z": -1,
      "name": "Soil_Mud_Dry"
    },
    {
      "x": -16,
      "y": 44,
      "z": -1,
      "name": "Soil_Mud_Dry"
    },
    {
      "x": -16,
      "y": 45,
      "z": -1,
      "name": "Soil_Mud"
    },
    {
      "x": -16,
      "y": 46,
      "z": -1,
      "name": "Plant_Moss_Rug_Pink"
    },
    {
      "x": -16,
      "y": 53,
      "z": -1,
      "name": "Plant_Crop_Mushroom_Block_Purple",
      "rotation": 1
    },
    {
      "x": -16,
      "y": 36,
      "z": 0,
      "name": "Soil_Mud_Dry"
    },
    {
      "x": -16,
      "y": 37,
      "z": 0,
      "name": "Soil_Mud"
    },
    {
      "x": -16,
      "y": 38,
      "z": 0,
      "name": "Soil_Mud"
    },
    {
      "x": -16,
      "y": 39,
      "z": 0,
      "name": "Soil_Mud"
    },
    {
      "x": -16,
      "y": 40,
      "z": 0,
      "name": "Soil_Mud_Dry"
    },
    {
      "x": -16,
      "y": 41,
      "z": 0,
      "name": "Soil_Mud"
    },
    {
      "x": -16,
      "y": 42,
      "z": 0,
      "name": "Soil_Mud_Dry"
    },
    {
      "x": -16,
      "y": 43,
      "z": 0,
      "name": "Soil_Mud"
    },
    {
      "x": -16,
      "y": 44,
      "z": 0,
      "name": "Soil_Mud"
    },
    {
      "x": -16,
      "y": 45,
      "z": 0,
      "name": "Soil_Mud"
    },
    {
      "x": -16,
      "y": 53,
      "z": 0,
      "name": "Plant_Crop_Mushroom_Block_Purple",
      "rotation": 1
    },
    {
      "x": -16,
      "y": 36,
      "z": 1,
      "name": "Soil_Mud_Dry"
    },
    {
      "x": -16,
      "y": 37,
      "z": 1,
      "name": "Soil_Mud"
    },
    {
      "x": -16,
      "y": 38,
      "z": 1,
      "name": "Soil_Mud_Dry"
    },
    {
      "x": -16,
      "y": 39,
      "z": 1,
      "name": "Soil_Mud"
    },
    {
      "x": -16,
      "y": 40,
      "z": 1,
      "name": "Soil_Mud_Dry"
    },
    {
      "x": -16,
      "y": 41,
      "z": 1,
      "name": "Soil_Mud_Dry"
    },
    {
      "x": -16,
      "y": 42,
      "z": 1,
      "name": "Soil_Mud"
    },
    {
      "x": -16,
      "y": 43,
      "z": 1,
      "name": "Soil_Mud_Dry"
    },
    {
      "x": -16,
      "y": 44,
      "z": 1,
      "name": "Soil_Mud_Dry"
    },
    {
      "x": -16,
      "y": 45,
      "z": 1,
      "name": "Soil_Mud"
    },
    {
      "x": -16,
      "y": 53,
      "z": 1,
      "name": "Plant_Crop_Mushroom_Block_Purple",
      "rotation": 1
    },
    {
      "x": -16,
      "y": 37,
      "z": 2,
      "name": "Soil_Mud"
    },
    {
      "x": -16,
      "y": 38,
      "z": 2,
      "name": "Soil_Mud_Dry"
    },
    {
      "x": -16,
      "y": 39,
      "z": 2,
      "name": "Soil_Mud"
    },
    {
      "x": -16,
      "y": 40,
      "z": 2,
      "name": "Soil_Mud"
    },
    {
      "x": -16,
      "y": 41,
      "z": 2,
      "name": "Soil_Mud"
    },
    {
      "x": -16,
      "y": 42,
      "z": 2,
      "name": "Soil_Mud"
    },
    {
      "x": -16,
      "y": 43,
      "z": 2,
      "name": "Soil_Mud"
    },
    {
      "x": -16,
      "y": 44,
      "z": 2,
      "name": "Soil_Mud"
    },
    {
      "x": -16,
      "y": 45,
      "z": 2,
      "name": "Soil_Mud_Dry"
    },
    {
      "x": -16,
      "y": 46,
      "z": 2,
      "name": "Plant_Moss_Rug_Pink"
    },
    {
      "x": -16,
      "y": 37,
      "z": 3,
      "name": "Soil_Mud"
    },
    {
      "x": -16,
      "y": 38,
      "z": 3,
      "name": "Soil_Mud"
    },
    {
      "x": -16,
      "y": 39,
      "z": 3,
      "name": "Soil_Mud_Dry"
    },
    {
      "x": -16,
      "y": 40,
      "z": 3,
      "name": "Soil_Mud"
    },
    {
      "x": -16,
      "y": 41,
      "z": 3,
      "name": "Soil_Mud_Dry"
    },
    {
      "x": -16,
      "y": 42,
      "z": 3,
      "name": "Soil_Mud_Dry"
    },
    {
      "x": -16,
      "y": 43,
      "z": 3,
      "name": "Soil_Mud"
    },
    {
      "x": -16,
      "y": 44,
      "z": 3,
      "name": "Soil_Mud_Dry"
    },
    {
      "x": -16,
      "y": 41,
      "z": 4,
      "name": "Soil_Mud_Dry"
    },
    {
      "x": -16,
      "y": 42,
      "z": 4,
      "name": "Soil_Mud"
    },
    {
      "x": -16,
      "y": 43,
      "z": 4,
      "name": "Soil_Mud"
    },
    {
      "x": -15,
      "y": 42,
      "z": -5,
      "name": "Soil_Mud"
    },
    {
      "x": -15,
      "y": 43,
      "z": -5,
      "name": "Soil_Mud"
    },
    {
      "x": -15,
      "y": 44,
      "z": -5,
      "name": "Soil_Mud"
    },
    {
      "x": -15,
      "y": 45,
      "z": -5,
      "name": "Soil_Mud"
    },
    {
      "x": -15,
      "y": 39,
      "z": -4,
      "name": "Soil_Mud"
    },
    {
      "x": -15,
      "y": 40,
      "z": -4,
      "name": "Soil_Mud"
    },
    {
      "x": -15,
      "y": 41,
      "z": -4,
      "name": "Soil_Mud"
    },
    {
      "x": -15,
      "y": 42,
      "z": -4,
      "name": "Soil_Mud_Dry"
    },
    {
      "x": -15,
      "y": 43,
      "z": -4,
      "name": "Soil_Mud"
    },
    {
      "x": -15,
      "y": 44,
      "z": -4,
      "name": "Soil_Mud"
    },
    {
      "x": -15,
      "y": 45,
      "z": -4,
      "name": "Soil_Mud"
    },
    {
      "x": -15,
      "y": 37,
      "z": -3,
      "name": "Soil_Mud_Dry"
    },
    {
      "x": -15,
      "y": 38,
      "z": -3,
      "name": "Soil_Mud"
    },
    {
      "x": -15,
      "y": 39,
      "z": -3,
      "name": "Soil_Mud"
    },
    {
      "x": -15,
      "y": 40,
      "z": -3,
      "name": "Soil_Mud"
    },
    {
      "x": -15,
      "y": 41,
      "z": -3,
      "name": "Soil_Mud"
    },
    {
      "x": -15,
      "y": 42,
      "z": -3,
      "name": "Soil_Mud"
    },
    {
      "x": -15,
      "y": 43,
      "z": -3,
      "name": "Soil_Mud"
    },
    {
      "x": -15,
      "y": 44,
      "z": -3,
      "name": "Soil_Mud"
    },
    {
      "x": -15,
      "y": 45,
      "z": -3,
      "name": "Soil_Mud"
    },
    {
      "x": -15,
      "y": 36,
      "z": -2,
      "name": "Soil_Mud_Dry"
    },
    {
      "x": -15,
      "y": 37,
      "z": -2,
      "name": "Soil_Mud_Dry"
    },
    {
      "x": -15,
      "y": 38,
      "z": -2,
      "name": "Soil_Mud"
    },
    {
      "x": -15,
      "y": 39,
      "z": -2,
      "name": "Soil_Mud"
    },
    {
      "x": -15,
      "y": 40,
      "z": -2,
      "name": "Soil_Mud_Dry"
    },
    {
      "x": -15,
      "y": 41,
      "z": -2,
      "name": "Soil_Mud"
    },
    {
      "x": -15,
      "y": 42,
      "z": -2,
      "name": "Soil_Mud"
    },
    {
      "x": -15,
      "y": 43,
      "z": -2,
      "name": "Soil_Mud"
    },
    {
      "x": -15,
      "y": 44,
      "z": -2,
      "name": "Soil_Mud_Dry"
    },
    {
      "x": -15,
      "y": 45,
      "z": -2,
      "name": "Soil_Mud_Dry"
    },
    {
      "x": -15,
      "y": 34,
      "z": -1,
      "name": "Soil_Mud"
    },
    {
      "x": -15,
      "y": 35,
      "z": -1,
      "name": "Soil_Mud_Dry"
    },
    {
      "x": -15,
      "y": 36,
      "z": -1,
      "name": "Soil_Mud"
    },
    {
      "x": -15,
      "y": 37,
      "z": -1,
      "name": "Soil_Mud"
    },
    {
      "x": -15,
      "y": 38,
      "z": -1,
      "name": "Soil_Mud_Dry"
    },
    {
      "x": -15,
      "y": 39,
      "z": -1,
      "name": "Soil_Mud"
    },
    {
      "x": -15,
      "y": 40,
      "z": -1,
      "name": "Soil_Mud"
    },
    {
      "x": -15,
      "y": 41,
      "z": -1,
      "name": "Soil_Mud"
    },
    {
      "x": -15,
      "y": 42,
      "z": -1,
      "name": "Soil_Mud"
    },
    {
      "x": -15,
      "y": 43,
      "z": -1,
      "name": "Soil_Mud"
    },
    {
      "x": -15,
      "y": 44,
      "z": -1,
      "name": "Soil_Mud_Dry"
    },
    {
      "x": -15,
      "y": 45,
      "z": -1,
      "name": "Soil_Mud"
    },
    {
      "x": -15,
      "y": 46,
      "z": -1,
      "name": "Plant_Crop_Mushroom_Glowing_Purple"
    },
    {
      "x": -15,
      "y": 52,
      "z": -1,
      "name": "Plant_Crop_Mushroom_Block_Purple_Mycelium",
      "rotation": 1
    },
    {
      "x": -15,
      "y": 53,
      "z": -1,
      "name": "Plant_Crop_Mushroom_Block_Purple",
      "rotation": 1
    },
    {
      "x": -15,
      "y": 34,
      "z": 0,
      "name": "Soil_Mud"
    },
    {
      "x": -15,
      "y": 35,
      "z": 0,
      "name": "Soil_Mud_Dry"
    },
    {
      "x": -15,
      "y": 36,
      "z": 0,
      "name": "Soil_Mud_Dry"
    },
    {
      "x": -15,
      "y": 37,
      "z": 0,
      "name": "Soil_Mud_Dry"
    },
    {
      "x": -15,
      "y": 38,
      "z": 0,
      "name": "Soil_Mud"
    },
    {
      "x": -15,
      "y": 39,
      "z": 0,
      "name": "Soil_Mud_Dry"
    },
    {
      "x": -15,
      "y": 40,
      "z": 0,
      "name": "Soil_Mud"
    },
    {
      "x": -15,
      "y": 41,
      "z": 0,
      "name": "Soil_Mud_Dry"
    },
    {
      "x": -15,
      "y": 42,
      "z": 0,
      "name": "Soil_Mud_Dry"
    },
    {
      "x": -15,
      "y": 43,
      "z": 0,
      "name": "Soil_Mud_Dry"
    },
    {
      "x": -15,
      "y": 44,
      "z": 0,
      "name": "Soil_Mud"
    },
    {
      "x": -15,
      "y": 45,
      "z": 0,
      "name": "Soil_Mud"
    },
    {
      "x": -15,
      "y": 53,
      "z": 0,
      "name": "Plant_Crop_Mushroom_Block_Purple",
      "rotation": 1
    },
    {
      "x": -15,
      "y": 54,
      "z": 0,
      "name": "Plant_Crop_Mushroom_Block_Purple",
      "rotation": 1
    },
    {
      "x": -15,
      "y": 32,
      "z": 1,
      "name": "Rock_Crystal_Purple_Medium",
      "rotation": 7
    },
    {
      "x": -15,
      "y": 33,
      "z": 1,
      "name": "Rock_Crystal_Purple_Medium",
      "rotation": 7
    },
    {
      "x": -15,
      "y": 34,
      "z": 1,
      "name": "Rock_Crystal_Purple_Medium",
      "rotation": 7
    },
    {
      "x": -15,
      "y": 35,
      "z": 1,
      "name": "Soil_Mud"
    },
    {
      "x": -15,
      "y": 36,
      "z": 1,
      "name": "Soil_Mud_Dry"
    },
    {
      "x": -15,
      "y": 37,
      "z": 1,
      "name": "Soil_Mud_Dry"
    },
    {
      "x": -15,
      "y": 38,
      "z": 1,
      "name": "Soil_Mud"
    },
    {
      "x": -15,
      "y": 39,
      "z": 1,
      "name": "Soil_Mud_Dry"
    },
    {
      "x": -15,
      "y": 40,
      "z": 1,
      "name": "Soil_Mud_Dry"
    },
    {
      "x": -15,
      "y": 41,
      "z": 1,
      "name": "Soil_Mud"
    },
    {
      "x": -15,
      "y": 42,
      "z": 1,
      "name": "Soil_Mud"
    },
    {
      "x": -15,
      "y": 43,
      "z": 1,
      "name": "Soil_Mud_Dry"
    },
    {
      "x": -15,
      "y": 44,
      "z": 1,
      "name": "Soil_Mud"
    },
    {
      "x": -15,
      "y": 45,
      "z": 1,
      "name": "Soil_Mud"
    },
    {
      "x": -15,
      "y": 46,
      "z": 1,
      "name": "Plant_Flower_Bushy_Violet"
    },
    {
      "x": -15,
      "y": 53,
      "z": 1,
      "name": "Plant_Crop_Mushroom_Block_Purple",
      "rotation": 1
    },
    {
      "x": -15,
      "y": 54,
      "z": 1,
      "name": "Plant_Crop_Mushroom_Block_Purple",
      "rotation": 1
    },
    {
      "x": -15,
      "y": 35,
      "z": 2,
      "name": "Soil_Mud_Dry"
    },
    {
      "x": -15,
      "y": 36,
      "z": 2,
      "name": "Soil_Mud_Dry"
    },
    {
      "x": -15,
      "y": 37,
      "z": 2,
      "name": "Soil_Mud"
    },
    {
      "x": -15,
      "y": 38,
      "z": 2,
      "name": "Soil_Mud_Dry"
    },
    {
      "x": -15,
      "y": 39,
      "z": 2,
      "name": "Soil_Mud"
    },
    {
      "x": -15,
      "y": 40,
      "z": 2,
      "name": "Soil_Mud"
    },
    {
      "x": -15,
      "y": 41,
      "z": 2,
      "name": "Soil_Mud"
    },
    {
      "x": -15,
      "y": 42,
      "z": 2,
      "name": "Soil_Mud_Dry"
    },
    {
      "x": -15,
      "y": 43,
      "z": 2,
      "name": "Soil_Mud"
    },
    {
      "x": -15,
      "y": 44,
      "z": 2,
      "name": "Soil_Mud"
    },
    {
      "x": -15,
      "y": 45,
      "z": 2,
      "name": "Soil_Mud"
    },
    {
      "x": -15,
      "y": 53,
      "z": 2,
      "name": "Plant_Crop_Mushroom_Block_Purple",
      "rotation": 1
    },
    {
      "x": -15,
      "y": 54,
      "z": 2,
      "name": "Plant_Crop_Mushroom_Block_Purple",
      "rotation": 1
    },
    {
      "x": -15,
      "y": 36,
      "z": 3,
      "name": "Soil_Mud"
    },
    {
      "x": -15,
      "y": 37,
      "z": 3,
      "name": "Soil_Mud_Dry"
    },
    {
      "x": -15,
      "y": 38,
      "z": 3,
      "name": "Soil_Mud"
    },
    {
      "x": -15,
      "y": 39,
      "z": 3,
      "name": "Soil_Mud"
    },
    {
      "x": -15,
      "y": 40,
      "z": 3,
      "name": "Soil_Mud"
    },
    {
      "x": -15,
      "y": 41,
      "z": 3,
      "name": "Soil_Mud"
    },
    {
      "x": -15,
      "y": 42,
      "z": 3,
      "name": "Soil_Mud"
    },
    {
      "x": -15,
      "y": 43,
      "z": 3,
      "name": "Soil_Mud"
    },
    {
      "x": -15,
      "y": 44,
      "z": 3,
      "name": "Soil_Mud_Dry"
    },
    {
      "x": -15,
      "y": 45,
      "z": 3,
      "name": "Soil_Mud_Dry"
    },
    {
      "x": -15,
      "y": 53,
      "z": 3,
      "name": "Plant_Crop_Mushroom_Block_Purple",
      "rotation": 1
    },
    {
      "x": -15,
      "y": 38,
      "z": 4,
      "name": "Soil_Mud"
    },
    {
      "x": -15,
      "y": 39,
      "z": 4,
      "name": "Soil_Mud_Dry"
    },
    {
      "x": -15,
      "y": 40,
      "z": 4,
      "name": "Soil_Mud"
    },
    {
      "x": -15,
      "y": 41,
      "z": 4,
      "name": "Soil_Mud_Dry"
    },
    {
      "x": -15,
      "y": 42,
      "z": 4,
      "name": "Soil_Mud"
    },
    {
      "x": -15,
      "y": 43,
      "z": 4,
      "name": "Soil_Mud"
    },
    {
      "x": -15,
      "y": 44,
      "z": 4,
      "name": "Soil_Mud"
    },
    {
      "x": -14,
      "y": 42,
      "z": -5,
      "name": "Soil_Mud_Dry"
    },
    {
      "x": -14,
      "y": 43,
      "z": -5,
      "name": "Soil_Mud"
    },
    {
      "x": -14,
      "y": 44,
      "z": -5,
      "name": "Soil_Mud"
    },
    {
      "x": -14,
      "y": 45,
      "z": -5,
      "name": "Soil_Mud"
    },
    {
      "x": -14,
      "y": 13,
      "z": -4,
      "name": "Plant_Crop_Mushroom_Shelve_Brown"
    },
    {
      "x": -14,
      "y": 38,
      "z": -4,
      "name": "Soil_Mud"
    },
    {
      "x": -14,
      "y": 39,
      "z": -4,
      "name": "Soil_Mud"
    },
    {
      "x": -14,
      "y": 40,
      "z": -4,
      "name": "Soil_Mud"
    },
    {
      "x": -14,
      "y": 41,
      "z": -4,
      "name": "Soil_Mud"
    },
    {
      "x": -14,
      "y": 42,
      "z": -4,
      "name": "Soil_Mud"
    },
    {
      "x": -14,
      "y": 43,
      "z": -4,
      "name": "Soil_Mud"
    },
    {
      "x": -14,
      "y": 44,
      "z": -4,
      "name": "Soil_Mud"
    },
    {
      "x": -14,
      "y": 45,
      "z": -4,
      "name": "Soil_Mud"
    },
    {
      "x": -14,
      "y": 37,
      "z": -3,
      "name": "Soil_Mud"
    },
    {
      "x": -14,
      "y": 38,
      "z": -3,
      "name": "Soil_Mud"
    },
    {
      "x": -14,
      "y": 39,
      "z": -3,
      "name": "Soil_Mud"
    },
    {
      "x": -14,
      "y": 40,
      "z": -3,
      "name": "Soil_Mud"
    },
    {
      "x": -14,
      "y": 41,
      "z": -3,
      "name": "Soil_Mud"
    },
    {
      "x": -14,
      "y": 42,
      "z": -3,
      "name": "Soil_Mud"
    },
    {
      "x": -14,
      "y": 43,
      "z": -3,
      "name": "Soil_Mud"
    },
    {
      "x": -14,
      "y": 44,
      "z": -3,
      "name": "Soil_Mud"
    },
    {
      "x": -14,
      "y": 45,
      "z": -3,
      "name": "Soil_Mud"
    },
    {
      "x": -14,
      "y": 46,
      "z": -3,
      "name": "Plant_Crop_Mushroom_Glowing_Purple"
    },
    {
      "x": -14,
      "y": 12,
      "z": -2,
      "name": "Plant_Crop_Mushroom_Shelve_Brown"
    },
    {
      "x": -14,
      "y": 34,
      "z": -2,
      "name": "Soil_Mud"
    },
    {
      "x": -14,
      "y": 35,
      "z": -2,
      "name": "Soil_Mud"
    },
    {
      "x": -14,
      "y": 36,
      "z": -2,
      "name": "Soil_Mud_Dry"
    },
    {
      "x": -14,
      "y": 37,
      "z": -2,
      "name": "Soil_Mud_Dry"
    },
    {
      "x": -14,
      "y": 38,
      "z": -2,
      "name": "Soil_Mud"
    },
    {
      "x": -14,
      "y": 39,
      "z": -2,
      "name": "Soil_Mud_Dry"
    },
    {
      "x": -14,
      "y": 40,
      "z": -2,
      "name": "Soil_Mud_Dry"
    },
    {
      "x": -14,
      "y": 41,
      "z": -2,
      "name": "Soil_Mud"
    },
    {
      "x": -14,
      "y": 42,
      "z": -2,
      "name": "Soil_Mud"
    },
    {
      "x": -14,
      "y": 43,
      "z": -2,
      "name": "Soil_Mud"
    },
    {
      "x": -14,
      "y": 44,
      "z": -2,
      "name": "Soil_Mud"
    },
    {
      "x": -14,
      "y": 45,
      "z": -2,
      "name": "Soil_Mud"
    },
    {
      "x": -14,
      "y": 53,
      "z": -2,
      "name": "Plant_Crop_Mushroom_Block_Purple",
      "rotation": 1
    },
    {
      "x": -14,
      "y": 34,
      "z": -1,
      "name": "Soil_Mud"
    },
    {
      "x": -14,
      "y": 35,
      "z": -1,
      "name": "Soil_Mud"
    },
    {
      "x": -14,
      "y": 36,
      "z": -1,
      "name": "Soil_Mud"
    },
    {
      "x": -14,
      "y": 37,
      "z": -1,
      "name": "Soil_Mud_Dry"
    },
    {
      "x": -14,
      "y": 38,
      "z": -1,
      "name": "Soil_Mud_Dry"
    },
    {
      "x": -14,
      "y": 39,
      "z": -1,
      "name": "Soil_Mud_Dry"
    },
    {
      "x": -14,
      "y": 40,
      "z": -1,
      "name": "Soil_Mud"
    },
    {
      "x": -14,
      "y": 41,
      "z": -1,
      "name": "Soil_Mud_Dry"
    },
    {
      "x": -14,
      "y": 42,
      "z": -1,
      "name": "Soil_Mud"
    },
    {
      "x": -14,
      "y": 43,
      "z": -1,
      "name": "Soil_Mud_Dry"
    },
    {
      "x": -14,
      "y": 44,
      "z": -1,
      "name": "Soil_Mud"
    },
    {
      "x": -14,
      "y": 45,
      "z": -1,
      "name": "Soil_Mud"
    },
    {
      "x": -14,
      "y": 46,
      "z": -1,
      "name": "Plant_Flower_Bushy_Purple"
    },
    {
      "x": -14,
      "y": 52,
      "z": -1,
      "name": "Plant_Crop_Mushroom_Block_Purple_Mycelium",
      "rotation": 1
    },
    {
      "x": -14,
      "y": 53,
      "z": -1,
      "name": "Plant_Crop_Mushroom_Block_Purple",
      "rotation": 1
    },
    {
      "x": -14,
      "y": 54,
      "z": -1,
      "name": "Plant_Crop_Mushroom_Block_Purple",
      "rotation": 1
    },
    {
      "x": -14,
      "y": 33,
      "z": 0,
      "name": "Rock_Crystal_Purple_Medium",
      "rotation": 7
    },
    {
      "x": -14,
      "y": 34,
      "z": 0,
      "name": "Soil_Mud"
    },
    {
      "x": -14,
      "y": 35,
      "z": 0,
      "name": "Soil_Mud_Dry"
    },
    {
      "x": -14,
      "y": 36,
      "z": 0,
      "name": "Soil_Mud"
    },
    {
      "x": -14,
      "y": 37,
      "z": 0,
      "name": "Soil_Mud_Dry"
    },
    {
      "x": -14,
      "y": 38,
      "z": 0,
      "name": "Soil_Mud_Dry"
    },
    {
      "x": -14,
      "y": 39,
      "z": 0,
      "name": "Soil_Mud"
    },
    {
      "x": -14,
      "y": 40,
      "z": 0,
      "name": "Soil_Mud_Dry"
    },
    {
      "x": -14,
      "y": 41,
      "z": 0,
      "name": "Soil_Mud"
    },
    {
      "x": -14,
      "y": 42,
      "z": 0,
      "name": "Soil_Mud"
    },
    {
      "x": -14,
      "y": 43,
      "z": 0,
      "name": "Soil_Mud"
    },
    {
      "x": -14,
      "y": 44,
      "z": 0,
      "name": "Soil_Mud"
    },
    {
      "x": -14,
      "y": 45,
      "z": 0,
      "name": "Soil_Mud_Dry"
    },
    {
      "x": -14,
      "y": 52,
      "z": 0,
      "name": "Plant_Crop_Mushroom_Block_Purple_Mycelium",
      "rotation": 1
    },
    {
      "x": -14,
      "y": 53,
      "z": 0,
      "name": "Plant_Crop_Mushroom_Block_Purple",
      "rotation": 1
    },
    {
      "x": -14,
      "y": 54,
      "z": 0,
      "name": "Plant_Crop_Mushroom_Block_Purple",
      "rotation": 1
    },
    {
      "x": -14,
      "y": 30,
      "z": 1,
      "name": "Rock_Crystal_Purple_Medium",
      "rotation": 7
    },
    {
      "x": -14,
      "y": 31,
      "z": 1,
      "name": "Rock_Crystal_Purple_Medium",
      "rotation": 8
    },
    {
      "x": -14,
      "y": 32,
      "z": 1,
      "name": "Rock_Crystal_Purple_Block"
    },
    {
      "x": -14,
      "y": 33,
      "z": 1,
      "name": "Rock_Crystal_Purple_Block"
    },
    {
      "x": -14,
      "y": 34,
      "z": 1,
      "name": "Rock_Crystal_Purple_Block"
    },
    {
      "x": -14,
      "y": 35,
      "z": 1,
      "name": "Rock_Crystal_Purple_Block"
    },
    {
      "x": -14,
      "y": 36,
      "z": 1,
      "name": "Rock_Crystal_Purple_Block"
    },
    {
      "x": -14,
      "y": 37,
      "z": 1,
      "name": "Rock_Crystal_Purple_Block"
    },
    {
      "x": -14,
      "y": 38,
      "z": 1,
      "name": "Rock_Crystal_Purple_Block"
    },
    {
      "x": -14,
      "y": 39,
      "z": 1,
      "name": "Soil_Mud_Dry"
    },
    {
      "x": -14,
      "y": 40,
      "z": 1,
      "name": "Soil_Mud_Dry"
    },
    {
      "x": -14,
      "y": 41,
      "z": 1,
      "name": "Soil_Mud"
    },
    {
      "x": -14,
      "y": 42,
      "z": 1,
      "name": "Soil_Mud"
    },
    {
      "x": -14,
      "y": 43,
      "z": 1,
      "name": "Soil_Mud"
    },
    {
      "x": -14,
      "y": 44,
      "z": 1,
      "name": "Soil_Mud"
    },
    {
      "x": -14,
      "y": 45,
      "z": 1,
      "name": "Soil_Mud"
    },
    {
      "x": -14,
      "y": 53,
      "z": 1,
      "name": "Plant_Crop_Mushroom_Block_Purple_Mycelium",
      "rotation": 1
    },
    {
      "x": -14,
      "y": 54,
      "z": 1,
      "name": "Rock_Crystal_Purple_Block",
      "rotation": 1
    },
    {
      "x": -14,
      "y": 55,
      "z": 1,
      "name": "Plant_Crop_Mushroom_Block_Purple",
      "rotation": 1
    },
    {
      "x": -14,
      "y": 31,
      "z": 2,
      "name": "Rock_Crystal_Purple_Medium",
      "rotation": 7
    },
    {
      "x": -14,
      "y": 32,
      "z": 2,
      "name": "Rock_Crystal_Purple_Medium",
      "rotation": 4
    },
    {
      "x": -14,
      "y": 33,
      "z": 2,
      "name": "Rock_Crystal_Purple_Medium",
      "rotation": 4
    },
    {
      "x": -14,
      "y": 34,
      "z": 2,
      "name": "Rock_Crystal_Purple_Medium",
      "rotation": 4
    },
    {
      "x": -14,
      "y": 35,
      "z": 2,
      "name": "Soil_Mud_Dry"
    },
    {
      "x": -14,
      "y": 36,
      "z": 2,
      "name": "Soil_Mud"
    },
    {
      "x": -14,
      "y": 37,
      "z": 2,
      "name": "Soil_Mud"
    },
    {
      "x": -14,
      "y": 38,
      "z": 2,
      "name": "Soil_Mud"
    },
    {
      "x": -14,
      "y": 39,
      "z": 2,
      "name": "Soil_Mud"
    },
    {
      "x": -14,
      "y": 40,
      "z": 2,
      "name": "Soil_Mud_Dry"
    },
    {
      "x": -14,
      "y": 41,
      "z": 2,
      "name": "Soil_Mud"
    },
    {
      "x": -14,
      "y": 42,
      "z": 2,
      "name": "Soil_Mud"
    },
    {
      "x": -14,
      "y": 43,
      "z": 2,
      "name": "Soil_Mud"
    },
    {
      "x": -14,
      "y": 44,
      "z": 2,
      "name": "Soil_Mud"
    },
    {
      "x": -14,
      "y": 45,
      "z": 2,
      "name": "Soil_Mud"
    },
    {
      "x": -14,
      "y": 54,
      "z": 2,
      "name": "Plant_Crop_Mushroom_Block_Purple",
      "rotation": 1
    },
    {
      "x": -14,
      "y": 36,
      "z": 3,
      "name": "Soil_Mud"
    },
    {
      "x": -14,
      "y": 37,
      "z": 3,
      "name": "Soil_Mud_Dry"
    },
    {
      "x": -14,
      "y": 38,
      "z": 3,
      "name": "Soil_Mud_Dry"
    },
    {
      "x": -14,
      "y": 39,
      "z": 3,
      "name": "Soil_Mud"
    },
    {
      "x": -14,
      "y": 40,
      "z": 3,
      "name": "Soil_Mud_Dry"
    },
    {
      "x": -14,
      "y": 41,
      "z": 3,
      "name": "Soil_Mud_Dry"
    },
    {
      "x": -14,
      "y": 42,
      "z": 3,
      "name": "Soil_Mud"
    },
    {
      "x": -14,
      "y": 43,
      "z": 3,
      "name": "Soil_Mud_Dry"
    },
    {
      "x": -14,
      "y": 44,
      "z": 3,
      "name": "Soil_Mud"
    },
    {
      "x": -14,
      "y": 45,
      "z": 3,
      "name": "Soil_Mud_Dry"
    },
    {
      "x": -14,
      "y": 52,
      "z": 3,
      "name": "Plant_Crop_Mushroom_Block_Purple_Mycelium",
      "rotation": 1
    },
    {
      "x": -14,
      "y": 53,
      "z": 3,
      "name": "Plant_Crop_Mushroom_Block_Purple",
      "rotation": 1
    },
    {
      "x": -14,
      "y": 54,
      "z": 3,
      "name": "Plant_Crop_Mushroom_Block_Purple",
      "rotation": 1
    },
    {
      "x": -14,
      "y": 37,
      "z": 4,
      "name": "Soil_Mud"
    },
    {
      "x": -14,
      "y": 38,
      "z": 4,
      "name": "Soil_Mud_Dry"
    },
    {
      "x": -14,
      "y": 39,
      "z": 4,
      "name": "Soil_Mud"
    },
    {
      "x": -14,
      "y": 40,
      "z": 4,
      "name": "Soil_Mud"
    },
    {
      "x": -14,
      "y": 41,
      "z": 4,
      "name": "Soil_Mud_Dry"
    },
    {
      "x": -14,
      "y": 42,
      "z": 4,
      "name": "Soil_Mud"
    },
    {
      "x": -14,
      "y": 43,
      "z": 4,
      "name": "Soil_Mud"
    },
    {
      "x": -14,
      "y": 44,
      "z": 4,
      "name": "Soil_Mud"
    },
    {
      "x": -13,
      "y": 44,
      "z": -6,
      "name": "Soil_Mud"
    },
    {
      "x": -13,
      "y": 45,
      "z": -6,
      "name": "Soil_Mud_Dry"
    },
    {
      "x": -13,
      "y": 42,
      "z": -5,
      "name": "Soil_Mud"
    },
    {
      "x": -13,
      "y": 43,
      "z": -5,
      "name": "Soil_Mud"
    },
    {
      "x": -13,
      "y": 44,
      "z": -5,
      "name": "Soil_Mud"
    },
    {
      "x": -13,
      "y": 45,
      "z": -5,
      "name": "Soil_Mud"
    },
    {
      "x": -13,
      "y": 12,
      "z": -4,
      "name": "Soil_Mud_Dry"
    },
    {
      "x": -13,
      "y": 13,
      "z": -4,
      "name": "Soil_Mud_Dry"
    },
    {
      "x": -13,
      "y": 14,
      "z": -4,
      "name": "Plant_Crop_Mushroom_Cap_Brown"
    },
    {
      "x": -13,
      "y": 39,
      "z": -4,
      "name": "Soil_Mud"
    },
    {
      "x": -13,
      "y": 40,
      "z": -4,
      "name": "Soil_Mud_Dry"
    },
    {
      "x": -13,
      "y": 41,
      "z": -4,
      "name": "Soil_Mud"
    },
    {
      "x": -13,
      "y": 42,
      "z": -4,
      "name": "Soil_Mud"
    },
    {
      "x": -13,
      "y": 43,
      "z": -4,
      "name": "Soil_Mud"
    },
    {
      "x": -13,
      "y": 44,
      "z": -4,
      "name": "Soil_Mud"
    },
    {
      "x": -13,
      "y": 45,
      "z": -4,
      "name": "Soil_Mud"
    },
    {
      "x": -13,
      "y": 10,
      "z": -3,
      "name": "Soil_Mud"
    },
    {
      "x": -13,
      "y": 11,
      "z": -3,
      "name": "Soil_Mud_Dry"
    },
    {
      "x": -13,
      "y": 12,
      "z": -3,
      "name": "Soil_Mud_Dry"
    },
    {
      "x": -13,
      "y": 13,
      "z": -3,
      "name": "Soil_Mud"
    },
    {
      "x": -13,
      "y": 37,
      "z": -3,
      "name": "Soil_Mud"
    },
    {
      "x": -13,
      "y": 38,
      "z": -3,
      "name": "Soil_Mud"
    },
    {
      "x": -13,
      "y": 39,
      "z": -3,
      "name": "Soil_Mud_Dry"
    },
    {
      "x": -13,
      "y": 40,
      "z": -3,
      "name": "Soil_Mud"
    },
    {
      "x": -13,
      "y": 41,
      "z": -3,
      "name": "Soil_Mud"
    },
    {
      "x": -13,
      "y": 42,
      "z": -3,
      "name": "Soil_Mud_Dry"
    },
    {
      "x": -13,
      "y": 43,
      "z": -3,
      "name": "Soil_Mud"
    },
    {
      "x": -13,
      "y": 44,
      "z": -3,
      "name": "Soil_Mud"
    },
    {
      "x": -13,
      "y": 45,
      "z": -3,
      "name": "Soil_Mud_Dry"
    },
    {
      "x": -13,
      "y": 8,
      "z": -2,
      "name": "Soil_Mud"
    },
    {
      "x": -13,
      "y": 9,
      "z": -2,
      "name": "Soil_Mud"
    },
    {
      "x": -13,
      "y": 10,
      "z": -2,
      "name": "Soil_Mud_Dry"
    },
    {
      "x": -13,
      "y": 11,
      "z": -2,
      "name": "Soil_Mud_Dry"
    },
    {
      "x": -13,
      "y": 12,
      "z": -2,
      "name": "Soil_Mud"
    },
    {
      "x": -13,
      "y": 13,
      "z": -2,
      "name": "Soil_Mud"
    },
    {
      "x": -13,
      "y": 14,
      "z": -2,
      "name": "Plant_Crop_Mushroom_Glowing_Purple"
    },
    {
      "x": -13,
      "y": 34,
      "z": -2,
      "name": "Soil_Mud"
    },
    {
      "x": -13,
      "y": 35,
      "z": -2,
      "name": "Soil_Mud"
    },
    {
      "x": -13,
      "y": 36,
      "z": -2,
      "name": "Soil_Mud"
    },
    {
      "x": -13,
      "y": 37,
      "z": -2,
      "name": "Soil_Mud"
    },
    {
      "x": -13,
      "y": 38,
      "z": -2,
      "name": "Soil_Mud"
    },
    {
      "x": -13,
      "y": 39,
      "z": -2,
      "name": "Soil_Mud"
    },
    {
      "x": -13,
      "y": 40,
      "z": -2,
      "name": "Soil_Mud"
    },
    {
      "x": -13,
      "y": 41,
      "z": -2,
      "name": "Soil_Mud"
    },
    {
      "x": -13,
      "y": 42,
      "z": -2,
      "name": "Soil_Mud_Dry"
    },
    {
      "x": -13,
      "y": 43,
      "z": -2,
      "name": "Soil_Mud_Dry"
    },
    {
      "x": -13,
      "y": 44,
      "z": -2,
      "name": "Soil_Mud_Dry"
    },
    {
      "x": -13,
      "y": 45,
      "z": -2,
      "name": "Soil_Mud"
    },
    {
      "x": -13,
      "y": 46,
      "z": -2,
      "name": "Plant_Flower_Bushy_Violet"
    },
    {
      "x": -13,
      "y": 53,
      "z": -2,
      "name": "Plant_Crop_Mushroom_Block_Purple",
      "rotation": 1
    },
    {
      "x": -13,
      "y": 9,
      "z": -1,
      "name": "Soil_Mud_Dry"
    },
    {
      "x": -13,
      "y": 10,
      "z": -1,
      "name": "Soil_Mud_Dry"
    },
    {
      "x": -13,
      "y": 11,
      "z": -1,
      "name": "Soil_Mud_Dry"
    },
    {
      "x": -13,
      "y": 12,
      "z": -1,
      "name": "Soil_Mud"
    },
    {
      "x": -13,
      "y": 13,
      "z": -1,
      "name": "Soil_Mud"
    },
    {
      "x": -13,
      "y": 33,
      "z": -1,
      "name": "Rock_Crystal_Purple_Large",
      "rotation": 6
    },
    {
      "x": -13,
      "y": 34,
      "z": -1,
      "name": "Soil_Mud"
    },
    {
      "x": -13,
      "y": 35,
      "z": -1,
      "name": "Soil_Mud_Dry"
    },
    {
      "x": -13,
      "y": 36,
      "z": -1,
      "name": "Soil_Mud"
    },
    {
      "x": -13,
      "y": 37,
      "z": -1,
      "name": "Soil_Mud"
    },
    {
      "x": -13,
      "y": 38,
      "z": -1,
      "name": "Soil_Mud_Dry"
    },
    {
      "x": -13,
      "y": 39,
      "z": -1,
      "name": "Soil_Mud"
    },
    {
      "x": -13,
      "y": 40,
      "z": -1,
      "name": "Soil_Mud"
    },
    {
      "x": -13,
      "y": 41,
      "z": -1,
      "name": "Soil_Mud"
    },
    {
      "x": -13,
      "y": 42,
      "z": -1,
      "name": "Soil_Mud"
    },
    {
      "x": -13,
      "y": 43,
      "z": -1,
      "name": "Soil_Mud"
    },
    {
      "x": -13,
      "y": 44,
      "z": -1,
      "name": "Soil_Mud"
    },
    {
      "x": -13,
      "y": 45,
      "z": -1,
      "name": "Soil_Mud_Dry"
    },
    {
      "x": -13,
      "y": 53,
      "z": -1,
      "name": "Plant_Crop_Mushroom_Block_Purple",
      "rotation": 1
    },
    {
      "x": -13,
      "y": 54,
      "z": -1,
      "name": "Plant_Crop_Mushroom_Block_Purple",
      "rotation": 1
    },
    {
      "x": -13,
      "y": 55,
      "z": -1,
      "name": "Plant_Crop_Mushroom_Glowing_Purple",
      "rotation": 1
    },
    {
      "x": -13,
      "y": 13,
      "z": 0,
      "name": "Soil_Mud_Dry"
    },
    {
      "x": -13,
      "y": 30,
      "z": 0,
      "name": "Rock_Crystal_Purple_Medium",
      "rotation": 6
    },
    {
      "x": -13,
      "y": 31,
      "z": 0,
      "name": "Rock_Crystal_Purple_Medium",
      "rotation": 6
    },
    {
      "x": -13,
      "y": 32,
      "z": 0,
      "name": "Rock_Crystal_Purple_Large",
      "rotation": 8
    },
    {
      "x": -13,
      "y": 33,
      "z": 0,
      "name": "Rock_Crystal_Purple_Block"
    },
    {
      "x": -13,
      "y": 34,
      "z": 0,
      "name": "Rock_Crystal_Purple_Block"
    },
    {
      "x": -13,
      "y": 35,
      "z": 0,
      "name": "Rock_Crystal_Purple_Block"
    },
    {
      "x": -13,
      "y": 36,
      "z": 0,
      "name": "Rock_Crystal_Purple_Block"
    },
    {
      "x": -13,
      "y": 37,
      "z": 0,
      "name": "Rock_Crystal_Purple_Block"
    },
    {
      "x": -13,
      "y": 38,
      "z": 0,
      "name": "Rock_Crystal_Purple_Block"
    },
    {
      "x": -13,
      "y": 39,
      "z": 0,
      "name": "Soil_Mud"
    },
    {
      "x": -13,
      "y": 40,
      "z": 0,
      "name": "Soil_Mud"
    },
    {
      "x": -13,
      "y": 41,
      "z": 0,
      "name": "Soil_Mud"
    },
    {
      "x": -13,
      "y": 42,
      "z": 0,
      "name": "Soil_Mud"
    },
    {
      "x": -13,
      "y": 43,
      "z": 0,
      "name": "Soil_Mud"
    },
    {
      "x": -13,
      "y": 44,
      "z": 0,
      "name": "Soil_Mud_Dry"
    },
    {
      "x": -13,
      "y": 45,
      "z": 0,
      "name": "Soil_Mud_Dry"
    },
    {
      "x": -13,
      "y": 46,
      "z": 0,
      "name": "Plant_Grass_Cave_Short"
    },
    {
      "x": -13,
      "y": 54,
      "z": 0,
      "name": "Plant_Crop_Mushroom_Block_Purple",
      "rotation": 1
    },
    {
      "x": -13,
      "y": 55,
      "z": 0,
      "name": "Plant_Crop_Mushroom_Block_Purple",
      "rotation": 1
    },
    {
      "x": -13,
      "y": 29,
      "z": 1,
      "name": "Rock_Crystal_Purple_Large",
      "rotation": 8
    },
    {
      "x": -13,
      "y": 30,
      "z": 1,
      "name": "Rock_Crystal_Purple_Block"
    },
    {
      "x": -13,
      "y": 31,
      "z": 1,
      "name": "Rock_Crystal_Purple_Block"
    },
    {
      "x": -13,
      "y": 32,
      "z": 1,
      "name": "Rock_Crystal_Purple_Block"
    },
    {
      "x": -13,
      "y": 33,
      "z": 1,
      "name": "Rock_Crystal_Purple_Block"
    },
    {
      "x": -13,
      "y": 34,
      "z": 1,
      "name": "Rock_Crystal_Purple_Block"
    },
    {
      "x": -13,
      "y": 35,
      "z": 1,
      "name": "Rock_Crystal_Purple_Block"
    },
    {
      "x": -13,
      "y": 36,
      "z": 1,
      "name": "Rock_Crystal_Purple_Block"
    },
    {
      "x": -13,
      "y": 37,
      "z": 1,
      "name": "Rock_Crystal_Purple_Block"
    },
    {
      "x": -13,
      "y": 38,
      "z": 1,
      "name": "Rock_Crystal_Purple_Block"
    },
    {
      "x": -13,
      "y": 39,
      "z": 1,
      "name": "Soil_Mud"
    },
    {
      "x": -13,
      "y": 40,
      "z": 1,
      "name": "Soil_Mud_Dry"
    },
    {
      "x": -13,
      "y": 41,
      "z": 1,
      "name": "Soil_Mud"
    },
    {
      "x": -13,
      "y": 42,
      "z": 1,
      "name": "Soil_Mud"
    },
    {
      "x": -13,
      "y": 43,
      "z": 1,
      "name": "Soil_Mud"
    },
    {
      "x": -13,
      "y": 44,
      "z": 1,
      "name": "Soil_Mud"
    },
    {
      "x": -13,
      "y": 45,
      "z": 1,
      "name": "Plant_Crop_Mushroom_Block_Purple_Trunk",
      "rotation": 1
    },
    {
      "x": -13,
      "y": 46,
      "z": 1,
      "name": "Plant_Crop_Mushroom_Block_Purple_Trunk",
      "rotation": 1
    },
    {
      "x": -13,
      "y": 47,
      "z": 1,
      "name": "Plant_Crop_Mushroom_Block_Purple_Trunk",
      "rotation": 1
    },
    {
      "x": -13,
      "y": 48,
      "z": 1,
      "name": "Plant_Crop_Mushroom_Block_Purple_Trunk",
      "rotation": 1
    },
    {
      "x": -13,
      "y": 49,
      "z": 1,
      "name": "Plant_Crop_Mushroom_Block_Purple_Trunk",
      "rotation": 1
    },
    {
      "x": -13,
      "y": 50,
      "z": 1,
      "name": "Plant_Crop_Mushroom_Block_Purple_Trunk",
      "rotation": 1
    },
    {
      "x": -13,
      "y": 51,
      "z": 1,
      "name": "Plant_Crop_Mushroom_Block_Purple_Trunk",
      "rotation": 1
    },
    {
      "x": -13,
      "y": 52,
      "z": 1,
      "name": "Plant_Crop_Mushroom_Block_Purple_Trunk",
      "rotation": 1
    },
    {
      "x": -13,
      "y": 53,
      "z": 1,
      "name": "Plant_Crop_Mushroom_Block_Purple_Trunk",
      "rotation": 1
    },
    {
      "x": -13,
      "y": 54,
      "z": 1,
      "name": "Plant_Crop_Mushroom_Block_Purple",
      "rotation": 1
    },
    {
      "x": -13,
      "y": 55,
      "z": 1,
      "name": "Plant_Crop_Mushroom_Block_Purple",
      "rotation": 1
    },
    {
      "x": -13,
      "y": 30,
      "z": 2,
      "name": "Rock_Crystal_Purple_Medium",
      "rotation": 8
    },
    {
      "x": -13,
      "y": 31,
      "z": 2,
      "name": "Rock_Crystal_Purple_Block"
    },
    {
      "x": -13,
      "y": 32,
      "z": 2,
      "name": "Rock_Crystal_Purple_Block"
    },
    {
      "x": -13,
      "y": 33,
      "z": 2,
      "name": "Rock_Crystal_Purple_Block"
    },
    {
      "x": -13,
      "y": 34,
      "z": 2,
      "name": "Rock_Crystal_Purple_Block"
    },
    {
      "x": -13,
      "y": 35,
      "z": 2,
      "name": "Rock_Crystal_Purple_Block"
    },
    {
      "x": -13,
      "y": 36,
      "z": 2,
      "name": "Rock_Crystal_Purple_Block"
    },
    {
      "x": -13,
      "y": 37,
      "z": 2,
      "name": "Rock_Crystal_Purple_Block"
    },
    {
      "x": -13,
      "y": 38,
      "z": 2,
      "name": "Rock_Crystal_Purple_Block"
    },
    {
      "x": -13,
      "y": 39,
      "z": 2,
      "name": "Soil_Mud"
    },
    {
      "x": -13,
      "y": 40,
      "z": 2,
      "name": "Soil_Mud_Dry"
    },
    {
      "x": -13,
      "y": 41,
      "z": 2,
      "name": "Soil_Mud"
    },
    {
      "x": -13,
      "y": 42,
      "z": 2,
      "name": "Soil_Mud"
    },
    {
      "x": -13,
      "y": 43,
      "z": 2,
      "name": "Soil_Mud"
    },
    {
      "x": -13,
      "y": 44,
      "z": 2,
      "name": "Soil_Mud_Dry"
    },
    {
      "x": -13,
      "y": 45,
      "z": 2,
      "name": "Soil_Mud"
    },
    {
      "x": -13,
      "y": 54,
      "z": 2,
      "name": "Plant_Crop_Mushroom_Block_Purple",
      "rotation": 1
    },
    {
      "x": -13,
      "y": 55,
      "z": 2,
      "name": "Plant_Crop_Mushroom_Block_Purple",
      "rotation": 1
    },
    {
      "x": -13,
      "y": 31,
      "z": 3,
      "name": "Rock_Crystal_Purple_Medium",
      "rotation": 4
    },
    {
      "x": -13,
      "y": 32,
      "z": 3,
      "name": "Rock_Crystal_Purple_Medium",
      "rotation": 4
    },
    {
      "x": -13,
      "y": 33,
      "z": 3,
      "name": "Rock_Crystal_Purple_Medium",
      "rotation": 4
    },
    {
      "x": -13,
      "y": 34,
      "z": 3,
      "name": "Rock_Crystal_Purple_Medium",
      "rotation": 4
    },
    {
      "x": -13,
      "y": 35,
      "z": 3,
      "name": "Rock_Crystal_Purple_Medium",
      "rotation": 4
    },
    {
      "x": -13,
      "y": 37,
      "z": 3,
      "name": "Soil_Mud_Dry"
    },
    {
      "x": -13,
      "y": 38,
      "z": 3,
      "name": "Soil_Mud"
    },
    {
      "x": -13,
      "y": 39,
      "z": 3,
      "name": "Soil_Mud"
    },
    {
      "x": -13,
      "y": 40,
      "z": 3,
      "name": "Soil_Mud_Dry"
    },
    {
      "x": -13,
      "y": 41,
      "z": 3,
      "name": "Soil_Mud"
    },
    {
      "x": -13,
      "y": 42,
      "z": 3,
      "name": "Soil_Mud_Dry"
    },
    {
      "x": -13,
      "y": 43,
      "z": 3,
      "name": "Soil_Mud"
    },
    {
      "x": -13,
      "y": 44,
      "z": 3,
      "name": "Soil_Mud"
    },
    {
      "x": -13,
      "y": 45,
      "z": 3,
      "name": "Soil_Mud_Dry"
    },
    {
      "x": -13,
      "y": 46,
      "z": 3,
      "name": "Plant_Grass_Cave_Short"
    },
    {
      "x": -13,
      "y": 53,
      "z": 3,
      "name": "Plant_Crop_Mushroom_Block_Purple",
      "rotation": 1
    },
    {
      "x": -13,
      "y": 54,
      "z": 3,
      "name": "Plant_Crop_Mushroom_Block_Purple",
      "rotation": 1
    },
    {
      "x": -13,
      "y": 38,
      "z": 4,
      "name": "Soil_Mud"
    },
    {
      "x": -13,
      "y": 39,
      "z": 4,
      "name": "Soil_Mud"
    },
    {
      "x": -13,
      "y": 40,
      "z": 4,
      "name": "Soil_Mud"
    },
    {
      "x": -13,
      "y": 41,
      "z": 4,
      "name": "Soil_Mud_Dry"
    },
    {
      "x": -13,
      "y": 42,
      "z": 4,
      "name": "Soil_Mud_Dry"
    },
    {
      "x": -13,
      "y": 43,
      "z": 4,
      "name": "Soil_Mud"
    },
    {
      "x": -13,
      "y": 44,
      "z": 4,
      "name": "Soil_Mud"
    },
    {
      "x": -13,
      "y": 45,
      "z": 4,
      "name": "Soil_Mud"
    },
    {
      "x": -13,
      "y": 53,
      "z": 4,
      "name": "Plant_Crop_Mushroom_Block_Purple",
      "rotation": 1
    },
    {
      "x": -13,
      "y": 42,
      "z": 5,
      "name": "Soil_Mud"
    },
    {
      "x": -13,
      "y": 43,
      "z": 5,
      "name": "Soil_Mud"
    },
    {
      "x": -13,
      "y": 42,
      "z": 6,
      "name": "Plant_Crop_Mushroom_Shelve_Brown"
    },
    {
      "x": -12,
      "y": 42,
      "z": -7,
      "name": "Soil_Mud_Dry"
    },
    {
      "x": -12,
      "y": 43,
      "z": -7,
      "name": "Soil_Mud"
    },
    {
      "x": -12,
      "y": 44,
      "z": -7,
      "name": "Soil_Mud"
    },
    {
      "x": -12,
      "y": 45,
      "z": -7,
      "name": "Soil_Mud_Dry"
    },
    {
      "x": -12,
      "y": 46,
      "z": -7,
      "name": "Plant_Bush_Dead_Tall"
    },
    {
      "x": -12,
      "y": 12,
      "z": -6,
      "name": "Plant_Crop_Mushroom_Shelve_Brown"
    },
    {
      "x": -12,
      "y": 40,
      "z": -6,
      "name": "Soil_Mud_Dry"
    },
    {
      "x": -12,
      "y": 41,
      "z": -6,
      "name": "Soil_Mud"
    },
    {
      "x": -12,
      "y": 42,
      "z": -6,
      "name": "Soil_Mud_Dry"
    },
    {
      "x": -12,
      "y": 43,
      "z": -6,
      "name": "Soil_Mud_Dry"
    },
    {
      "x": -12,
      "y": 44,
      "z": -6,
      "name": "Soil_Mud_Dry"
    },
    {
      "x": -12,
      "y": 45,
      "z": -6,
      "name": "Soil_Mud_Dry"
    },
    {
      "x": -12,
      "y": 8,
      "z": -5,
      "name": "Soil_Mud"
    },
    {
      "x": -12,
      "y": 9,
      "z": -5,
      "name": "Soil_Mud"
    },
    {
      "x": -12,
      "y": 10,
      "z": -5,
      "name": "Soil_Mud"
    },
    {
      "x": -12,
      "y": 11,
      "z": -5,
      "name": "Soil_Mud_Dry"
    },
    {
      "x": -12,
      "y": 12,
      "z": -5,
      "name": "Soil_Mud"
    },
    {
      "x": -12,
      "y": 13,
      "z": -5,
      "name": "Soil_Mud"
    },
    {
      "x": -12,
      "y": 39,
      "z": -5,
      "name": "Soil_Mud"
    },
    {
      "x": -12,
      "y": 40,
      "z": -5,
      "name": "Soil_Mud_Dry"
    },
    {
      "x": -12,
      "y": 41,
      "z": -5,
      "name": "Soil_Mud"
    },
    {
      "x": -12,
      "y": 42,
      "z": -5,
      "name": "Soil_Mud_Dry"
    },
    {
      "x": -12,
      "y": 43,
      "z": -5,
      "name": "Soil_Mud"
    },
    {
      "x": -12,
      "y": 44,
      "z": -5,
      "name": "Soil_Mud"
    },
    {
      "x": -12,
      "y": 45,
      "z": -5,
      "name": "Soil_Mud"
    },
    {
      "x": -12,
      "y": 46,
      "z": -5,
      "name": "Plant_Crop_Mushroom_Cap_Brown"
    },
    {
      "x": -12,
      "y": 8,
      "z": -4,
      "name": "Soil_Mud"
    },
    {
      "x": -12,
      "y": 9,
      "z": -4,
      "name": "Soil_Mud"
    },
    {
      "x": -12,
      "y": 10,
      "z": -4,
      "name": "Soil_Mud"
    },
    {
      "x": -12,
      "y": 11,
      "z": -4,
      "name": "Soil_Mud"
    },
    {
      "x": -12,
      "y": 12,
      "z": -4,
      "name": "Soil_Mud"
    },
    {
      "x": -12,
      "y": 13,
      "z": -4,
      "name": "Soil_Mud"
    },
    {
      "x": -12,
      "y": 14,
      "z": -4,
      "name": "Plant_Flower_Bushy_Violet"
    },
    {
      "x": -12,
      "y": 36,
      "z": -4,
      "name": "Soil_Mud"
    },
    {
      "x": -12,
      "y": 37,
      "z": -4,
      "name": "Soil_Mud"
    },
    {
      "x": -12,
      "y": 38,
      "z": -4,
      "name": "Soil_Mud"
    },
    {
      "x": -12,
      "y": 39,
      "z": -4,
      "name": "Soil_Mud_Dry"
    },
    {
      "x": -12,
      "y": 40,
      "z": -4,
      "name": "Soil_Mud"
    },
    {
      "x": -12,
      "y": 41,
      "z": -4,
      "name": "Soil_Mud"
    },
    {
      "x": -12,
      "y": 42,
      "z": -4,
      "name": "Soil_Mud"
    },
    {
      "x": -12,
      "y": 43,
      "z": -4,
      "name": "Soil_Mud"
    },
    {
      "x": -12,
      "y": 44,
      "z": -4,
      "name": "Soil_Mud_Dry"
    },
    {
      "x": -12,
      "y": 45,
      "z": -4,
      "name": "Soil_Mud"
    },
    {
      "x": -12,
      "y": 5,
      "z": -3,
      "name": "Soil_Mud"
    },
    {
      "x": -12,
      "y": 6,
      "z": -3,
      "name": "Soil_Mud_Dry"
    },
    {
      "x": -12,
      "y": 7,
      "z": -3,
      "name": "Soil_Mud_Dry"
    },
    {
      "x": -12,
      "y": 8,
      "z": -3,
      "name": "Soil_Mud"
    },
    {
      "x": -12,
      "y": 9,
      "z": -3,
      "name": "Soil_Mud"
    },
    {
      "x": -12,
      "y": 10,
      "z": -3,
      "name": "Soil_Mud"
    },
    {
      "x": -12,
      "y": 11,
      "z": -3,
      "name": "Soil_Mud_Dry"
    },
    {
      "x": -12,
      "y": 12,
      "z": -3,
      "name": "Soil_Mud"
    },
    {
      "x": -12,
      "y": 13,
      "z": -3,
      "name": "Soil_Mud"
    },
    {
      "x": -12,
      "y": 37,
      "z": -3,
      "name": "Soil_Mud"
    },
    {
      "x": -12,
      "y": 38,
      "z": -3,
      "name": "Soil_Mud"
    },
    {
      "x": -12,
      "y": 39,
      "z": -3,
      "name": "Soil_Mud"
    },
    {
      "x": -12,
      "y": 40,
      "z": -3,
      "name": "Soil_Mud_Dry"
    },
    {
      "x": -12,
      "y": 41,
      "z": -3,
      "name": "Soil_Mud"
    },
    {
      "x": -12,
      "y": 42,
      "z": -3,
      "name": "Soil_Mud"
    },
    {
      "x": -12,
      "y": 43,
      "z": -3,
      "name": "Soil_Mud"
    },
    {
      "x": -12,
      "y": 44,
      "z": -3,
      "name": "Soil_Mud_Dry"
    },
    {
      "x": -12,
      "y": 45,
      "z": -3,
      "name": "Soil_Mud_Dry"
    },
    {
      "x": -12,
      "y": 5,
      "z": -2,
      "name": "Soil_Mud_Dry"
    },
    {
      "x": -12,
      "y": 6,
      "z": -2,
      "name": "Soil_Mud_Dry"
    },
    {
      "x": -12,
      "y": 7,
      "z": -2,
      "name": "Soil_Mud"
    },
    {
      "x": -12,
      "y": 8,
      "z": -2,
      "name": "Soil_Mud"
    },
    {
      "x": -12,
      "y": 9,
      "z": -2,
      "name": "Soil_Mud"
    },
    {
      "x": -12,
      "y": 10,
      "z": -2,
      "name": "Soil_Mud"
    },
    {
      "x": -12,
      "y": 11,
      "z": -2,
      "name": "Soil_Mud"
    },
    {
      "x": -12,
      "y": 12,
      "z": -2,
      "name": "Soil_Mud"
    },
    {
      "x": -12,
      "y": 13,
      "z": -2,
      "name": "Soil_Mud_Dry"
    },
    {
      "x": -12,
      "y": 36,
      "z": -2,
      "name": "Soil_Mud"
    },
    {
      "x": -12,
      "y": 37,
      "z": -2,
      "name": "Soil_Mud_Dry"
    },
    {
      "x": -12,
      "y": 38,
      "z": -2,
      "name": "Soil_Mud"
    },
    {
      "x": -12,
      "y": 39,
      "z": -2,
      "name": "Soil_Mud"
    },
    {
      "x": -12,
      "y": 40,
      "z": -2,
      "name": "Soil_Mud"
    },
    {
      "x": -12,
      "y": 41,
      "z": -2,
      "name": "Soil_Mud"
    },
    {
      "x": -12,
      "y": 42,
      "z": -2,
      "name": "Soil_Mud_Dry"
    },
    {
      "x": -12,
      "y": 43,
      "z": -2,
      "name": "Soil_Mud"
    },
    {
      "x": -12,
      "y": 44,
      "z": -2,
      "name": "Soil_Mud_Dry"
    },
    {
      "x": -12,
      "y": 45,
      "z": -2,
      "name": "Soil_Mud"
    },
    {
      "x": -12,
      "y": 7,
      "z": -1,
      "name": "Soil_Mud_Dry"
    },
    {
      "x": -12,
      "y": 8,
      "z": -1,
      "name": "Soil_Mud_Dry"
    },
    {
      "x": -12,
      "y": 9,
      "z": -1,
      "name": "Soil_Mud"
    },
    {
      "x": -12,
      "y": 10,
      "z": -1,
      "name": "Soil_Mud"
    },
    {
      "x": -12,
      "y": 11,
      "z": -1,
      "name": "Soil_Mud_Dry"
    },
    {
      "x": -12,
      "y": 12,
      "z": -1,
      "name": "Soil_Mud_Dry"
    },
    {
      "x": -12,
      "y": 13,
      "z": -1,
      "name": "Soil_Mud_Dry"
    },
    {
      "x": -12,
      "y": 35,
      "z": -1,
      "name": "Soil_Mud"
    },
    {
      "x": -12,
      "y": 36,
      "z": -1,
      "name": "Soil_Mud"
    },
    {
      "x": -12,
      "y": 37,
      "z": -1,
      "name": "Soil_Mud"
    },
    {
      "x": -12,
      "y": 38,
      "z": -1,
      "name": "Soil_Mud_Dry"
    },
    {
      "x": -12,
      "y": 39,
      "z": -1,
      "name": "Soil_Mud_Dry"
    },
    {
      "x": -12,
      "y": 40,
      "z": -1,
      "name": "Soil_Mud_Dry"
    },
    {
      "x": -12,
      "y": 41,
      "z": -1,
      "name": "Soil_Mud"
    },
    {
      "x": -12,
      "y": 42,
      "z": -1,
      "name": "Soil_Mud"
    },
    {
      "x": -12,
      "y": 43,
      "z": -1,
      "name": "Soil_Mud"
    },
    {
      "x": -12,
      "y": 44,
      "z": -1,
      "name": "Soil_Mud"
    },
    {
      "x": -12,
      "y": 45,
      "z": -1,
      "name": "Soil_Mud"
    },
    {
      "x": -12,
      "y": 52,
      "z": -1,
      "name": "Plant_Crop_Mushroom_Block_Purple_Mycelium",
      "rotation": 1
    },
    {
      "x": -12,
      "y": 53,
      "z": -1,
      "name": "Plant_Crop_Mushroom_Block_Purple",
      "rotation": 1
    },
    {
      "x": -12,
      "y": 54,
      "z": -1,
      "name": "Plant_Crop_Mushroom_Block_Purple",
      "rotation": 1
    },
    {
      "x": -12,
      "y": 7,
      "z": 0,
      "name": "Soil_Mud"
    },
    {
      "x": -12,
      "y": 8,
      "z": 0,
      "name": "Soil_Mud"
    },
    {
      "x": -12,
      "y": 9,
      "z": 0,
      "name": "Soil_Mud"
    },
    {
      "x": -12,
      "y": 10,
      "z": 0,
      "name": "Soil_Mud"
    },
    {
      "x": -12,
      "y": 11,
      "z": 0,
      "name": "Soil_Mud"
    },
    {
      "x": -12,
      "y": 12,
      "z": 0,
      "name": "Soil_Mud_Dry"
    },
    {
      "x": -12,
      "y": 13,
      "z": 0,
      "name": "Soil_Mud_Dry"
    },
    {
      "x": -12,
      "y": 33,
      "z": 0,
      "name": "Rock_Crystal_Purple_Medium",
      "rotation": 5
    },
    {
      "x": -12,
      "y": 35,
      "z": 0,
      "name": "Plant_Moss_Cave_Red"
    },
    {
      "x": -12,
      "y": 36,
      "z": 0,
      "name": "Soil_Mud"
    },
    {
      "x": -12,
      "y": 37,
      "z": 0,
      "name": "Soil_Mud"
    },
    {
      "x": -12,
      "y": 38,
      "z": 0,
      "name": "Soil_Mud"
    },
    {
      "x": -12,
      "y": 39,
      "z": 0,
      "name": "Soil_Mud_Dry"
    },
    {
      "x": -12,
      "y": 40,
      "z": 0,
      "name": "Soil_Mud"
    },
    {
      "x": -12,
      "y": 41,
      "z": 0,
      "name": "Soil_Mud"
    },
    {
      "x": -12,
      "y": 42,
      "z": 0,
      "name": "Soil_Mud_Dry"
    },
    {
      "x": -12,
      "y": 43,
      "z": 0,
      "name": "Soil_Mud"
    },
    {
      "x": -12,
      "y": 44,
      "z": 0,
      "name": "Soil_Mud"
    },
    {
      "x": -12,
      "y": 45,
      "z": 0,
      "name": "Soil_Mud_Dry"
    },
    {
      "x": -12,
      "y": 46,
      "z": 0,
      "name": "Plant_Flower_Bushy_Violet"
    },
    {
      "x": -12,
      "y": 53,
      "z": 0,
      "name": "Plant_Crop_Mushroom_Block_Purple_Mycelium",
      "rotation": 1
    },
    {
      "x": -12,
      "y": 54,
      "z": 0,
      "name": "Plant_Crop_Mushroom_Block_Purple",
      "rotation": 1
    },
    {
      "x": -12,
      "y": 7,
      "z": 1,
      "name": "Soil_Mud"
    },
    {
      "x": -12,
      "y": 8,
      "z": 1,
      "name": "Soil_Mud"
    },
    {
      "x": -12,
      "y": 9,
      "z": 1,
      "name": "Soil_Mud"
    },
    {
      "x": -12,
      "y": 10,
      "z": 1,
      "name": "Soil_Mud"
    },
    {
      "x": -12,
      "y": 11,
      "z": 1,
      "name": "Soil_Mud"
    },
    {
      "x": -12,
      "y": 12,
      "z": 1,
      "name": "Soil_Mud_Dry"
    },
    {
      "x": -12,
      "y": 13,
      "z": 1,
      "name": "Soil_Mud"
    },
    {
      "x": -12,
      "y": 30,
      "z": 1,
      "name": "Rock_Crystal_Purple_Medium",
      "rotation": 5
    },
    {
      "x": -12,
      "y": 32,
      "z": 1,
      "name": "Rock_Crystal_Purple_Medium",
      "rotation": 5
    },
    {
      "x": -12,
      "y": 33,
      "z": 1,
      "name": "Rock_Crystal_Purple_Block"
    },
    {
      "x": -12,
      "y": 34,
      "z": 1,
      "name": "Rock_Crystal_Purple_Block"
    },
    {
      "x": -12,
      "y": 35,
      "z": 1,
      "name": "Rock_Crystal_Purple_Block"
    },
    {
      "x": -12,
      "y": 36,
      "z": 1,
      "name": "Rock_Crystal_Purple_Block"
    },
    {
      "x": -12,
      "y": 37,
      "z": 1,
      "name": "Rock_Crystal_Purple_Block"
    },
    {
      "x": -12,
      "y": 38,
      "z": 1,
      "name": "Rock_Crystal_Purple_Block"
    },
    {
      "x": -12,
      "y": 39,
      "z": 1,
      "name": "Soil_Mud_Dry"
    },
    {
      "x": -12,
      "y": 40,
      "z": 1,
      "name": "Soil_Mud"
    },
    {
      "x": -12,
      "y": 41,
      "z": 1,
      "name": "Soil_Mud_Dry"
    },
    {
      "x": -12,
      "y": 42,
      "z": 1,
      "name": "Soil_Mud"
    },
    {
      "x": -12,
      "y": 43,
      "z": 1,
      "name": "Soil_Mud_Dry"
    },
    {
      "x": -12,
      "y": 44,
      "z": 1,
      "name": "Soil_Mud"
    },
    {
      "x": -12,
      "y": 45,
      "z": 1,
      "name": "Soil_Mud"
    },
    {
      "x": -12,
      "y": 53,
      "z": 1,
      "name": "Plant_Crop_Mushroom_Block_Purple_Mycelium",
      "rotation": 1
    },
    {
      "x": -12,
      "y": 54,
      "z": 1,
      "name": "Rock_Crystal_Purple_Block",
      "rotation": 1
    },
    {
      "x": -12,
      "y": 55,
      "z": 1,
      "name": "Plant_Crop_Mushroom_Block_Purple",
      "rotation": 1
    },
    {
      "x": -12,
      "y": 31,
      "z": 2,
      "name": "Rock_Crystal_Purple_Medium",
      "rotation": 5
    },
    {
      "x": -12,
      "y": 32,
      "z": 2,
      "name": "Rock_Crystal_Purple_Medium",
      "rotation": 5
    },
    {
      "x": -12,
      "y": 33,
      "z": 2,
      "name": "Rock_Crystal_Purple_Medium",
      "rotation": 4
    },
    {
      "x": -12,
      "y": 34,
      "z": 2,
      "name": "Rock_Crystal_Purple_Medium",
      "rotation": 4
    },
    {
      "x": -12,
      "y": 35,
      "z": 2,
      "name": "Plant_Moss_Cave_Red"
    },
    {
      "x": -12,
      "y": 36,
      "z": 2,
      "name": "Plant_Moss_Cave_Red"
    },
    {
      "x": -12,
      "y": 37,
      "z": 2,
      "name": "Soil_Mud_Dry"
    },
    {
      "x": -12,
      "y": 38,
      "z": 2,
      "name": "Soil_Mud"
    },
    {
      "x": -12,
      "y": 39,
      "z": 2,
      "name": "Soil_Mud"
    },
    {
      "x": -12,
      "y": 40,
      "z": 2,
      "name": "Soil_Mud_Dry"
    },
    {
      "x": -12,
      "y": 41,
      "z": 2,
      "name": "Soil_Mud"
    },
    {
      "x": -12,
      "y": 42,
      "z": 2,
      "name": "Soil_Mud_Dry"
    },
    {
      "x": -12,
      "y": 43,
      "z": 2,
      "name": "Soil_Mud"
    },
    {
      "x": -12,
      "y": 44,
      "z": 2,
      "name": "Soil_Mud"
    },
    {
      "x": -12,
      "y": 45,
      "z": 2,
      "name": "Soil_Mud"
    },
    {
      "x": -12,
      "y": 46,
      "z": 2,
      "name": "Soil_Mud_Dry"
    },
    {
      "x": -12,
      "y": 47,
      "z": 2,
      "name": "Plant_Crop_Mushroom_Cap_Brown"
    },
    {
      "x": -12,
      "y": 53,
      "z": 2,
      "name": "Plant_Crop_Mushroom_Block_Purple_Mycelium",
      "rotation": 1
    },
    {
      "x": -12,
      "y": 54,
      "z": 2,
      "name": "Plant_Crop_Mushroom_Block_Purple",
      "rotation": 1
    },
    {
      "x": -12,
      "y": 55,
      "z": 2,
      "name": "Plant_Crop_Mushroom_Glowing_Purple",
      "rotation": 1
    },
    {
      "x": -12,
      "y": 38,
      "z": 3,
      "name": "Soil_Mud"
    },
    {
      "x": -12,
      "y": 39,
      "z": 3,
      "name": "Soil_Mud"
    },
    {
      "x": -12,
      "y": 40,
      "z": 3,
      "name": "Soil_Mud_Dry"
    },
    {
      "x": -12,
      "y": 41,
      "z": 3,
      "name": "Soil_Mud"
    },
    {
      "x": -12,
      "y": 42,
      "z": 3,
      "name": "Soil_Mud_Dry"
    },
    {
      "x": -12,
      "y": 43,
      "z": 3,
      "name": "Soil_Mud"
    },
    {
      "x": -12,
      "y": 44,
      "z": 3,
      "name": "Soil_Mud_Dry"
    },
    {
      "x": -12,
      "y": 45,
      "z": 3,
      "name": "Soil_Mud"
    },
    {
      "x": -12,
      "y": 46,
      "z": 3,
      "name": "Plant_Crop_Mushroom_Glowing_Purple"
    },
    {
      "x": -12,
      "y": 52,
      "z": 3,
      "name": "Plant_Crop_Mushroom_Block_Purple_Mycelium",
      "rotation": 1
    },
    {
      "x": -12,
      "y": 53,
      "z": 3,
      "name": "Rock_Crystal_Purple_Block",
      "rotation": 1
    },
    {
      "x": -12,
      "y": 54,
      "z": 3,
      "name": "Plant_Crop_Mushroom_Block_Purple",
      "rotation": 1
    },
    {
      "x": -12,
      "y": 55,
      "z": 3,
      "name": "Plant_Crop_Mushroom_Glowing_Purple",
      "rotation": 1
    },
    {
      "x": -12,
      "y": 39,
      "z": 4,
      "name": "Soil_Mud"
    },
    {
      "x": -12,
      "y": 40,
      "z": 4,
      "name": "Soil_Mud"
    },
    {
      "x": -12,
      "y": 41,
      "z": 4,
      "name": "Soil_Mud"
    },
    {
      "x": -12,
      "y": 42,
      "z": 4,
      "name": "Soil_Mud"
    },
    {
      "x": -12,
      "y": 43,
      "z": 4,
      "name": "Soil_Mud_Dry"
    },
    {
      "x": -12,
      "y": 44,
      "z": 4,
      "name": "Soil_Mud"
    },
    {
      "x": -12,
      "y": 45,
      "z": 4,
      "name": "Soil_Mud"
    },
    {
      "x": -12,
      "y": 53,
      "z": 4,
      "name": "Plant_Crop_Mushroom_Block_Purple",
      "rotation": 1
    },
    {
      "x": -12,
      "y": 43,
      "z": 5,
      "name": "Soil_Mud"
    },
    {
      "x": -12,
      "y": 44,
      "z": 5,
      "name": "Soil_Mud"
    },
    {
      "x": -11,
      "y": 42,
      "z": -8,
      "name": "Soil_Mud"
    },
    {
      "x": -11,
      "y": 43,
      "z": -8,
      "name": "Soil_Mud"
    },
    {
      "x": -11,
      "y": 44,
      "z": -8,
      "name": "Soil_Mud_Dry"
    },
    {
      "x": -11,
      "y": 45,
      "z": -8,
      "name": "Soil_Mud"
    },
    {
      "x": -11,
      "y": 46,
      "z": -8,
      "name": "Plant_Bush_Dead_Tall"
    },
    {
      "x": -11,
      "y": 39,
      "z": -7,
      "name": "Soil_Mud"
    },
    {
      "x": -11,
      "y": 40,
      "z": -7,
      "name": "Soil_Mud_Dry"
    },
    {
      "x": -11,
      "y": 41,
      "z": -7,
      "name": "Soil_Mud_Dry"
    },
    {
      "x": -11,
      "y": 42,
      "z": -7,
      "name": "Soil_Mud_Dry"
    },
    {
      "x": -11,
      "y": 43,
      "z": -7,
      "name": "Soil_Mud_Dry"
    },
    {
      "x": -11,
      "y": 44,
      "z": -7,
      "name": "Soil_Mud"
    },
    {
      "x": -11,
      "y": 45,
      "z": -7,
      "name": "Plant_Bush_Dead_Tall"
    },
    {
      "x": -11,
      "y": 9,
      "z": -6,
      "name": "Soil_Mud"
    },
    {
      "x": -11,
      "y": 10,
      "z": -6,
      "name": "Soil_Mud_Dry"
    },
    {
      "x": -11,
      "y": 11,
      "z": -6,
      "name": "Soil_Mud"
    },
    {
      "x": -11,
      "y": 12,
      "z": -6,
      "name": "Soil_Mud"
    },
    {
      "x": -11,
      "y": 13,
      "z": -6,
      "name": "Soil_Mud"
    },
    {
      "x": -11,
      "y": 36,
      "z": -6,
      "name": "Plant_Moss_Cave_Red"
    },
    {
      "x": -11,
      "y": 37,
      "z": -6,
      "name": "Soil_Mud"
    },
    {
      "x": -11,
      "y": 38,
      "z": -6,
      "name": "Soil_Mud"
    },
    {
      "x": -11,
      "y": 39,
      "z": -6,
      "name": "Soil_Mud_Dry"
    },
    {
      "x": -11,
      "y": 40,
      "z": -6,
      "name": "Soil_Mud"
    },
    {
      "x": -11,
      "y": 41,
      "z": -6,
      "name": "Soil_Mud"
    },
    {
      "x": -11,
      "y": 42,
      "z": -6,
      "name": "Soil_Mud"
    },
    {
      "x": -11,
      "y": 43,
      "z": -6,
      "name": "Soil_Mud"
    },
    {
      "x": -11,
      "y": 44,
      "z": -6,
      "name": "Soil_Mud"
    },
    {
      "x": -11,
      "y": 45,
      "z": -6,
      "name": "Soil_Mud"
    },
    {
      "x": -11,
      "y": 46,
      "z": -6,
      "name": "Plant_Flower_Bushy_Purple"
    },
    {
      "x": -11,
      "y": 5,
      "z": -5,
      "name": "Soil_Mud"
    },
    {
      "x": -11,
      "y": 6,
      "z": -5,
      "name": "Soil_Mud_Dry"
    },
    {
      "x": -11,
      "y": 7,
      "z": -5,
      "name": "Soil_Mud_Dry"
    },
    {
      "x": -11,
      "y": 8,
      "z": -5,
      "name": "Soil_Mud"
    },
    {
      "x": -11,
      "y": 9,
      "z": -5,
      "name": "Soil_Mud"
    },
    {
      "x": -11,
      "y": 10,
      "z": -5,
      "name": "Soil_Mud_Dry"
    },
    {
      "x": -11,
      "y": 11,
      "z": -5,
      "name": "Soil_Mud"
    },
    {
      "x": -11,
      "y": 12,
      "z": -5,
      "name": "Soil_Mud"
    },
    {
      "x": -11,
      "y": 13,
      "z": -5,
      "name": "Soil_Mud_Dry"
    },
    {
      "x": -11,
      "y": 37,
      "z": -5,
      "name": "Soil_Mud"
    },
    {
      "x": -11,
      "y": 38,
      "z": -5,
      "name": "Soil_Mud"
    },
    {
      "x": -11,
      "y": 39,
      "z": -5,
      "name": "Soil_Mud_Dry"
    },
    {
      "x": -11,
      "y": 40,
      "z": -5,
      "name": "Soil_Mud"
    },
    {
      "x": -11,
      "y": 41,
      "z": -5,
      "name": "Soil_Mud"
    },
    {
      "x": -11,
      "y": 42,
      "z": -5,
      "name": "Soil_Mud"
    },
    {
      "x": -11,
      "y": 43,
      "z": -5,
      "name": "Soil_Mud_Dry"
    },
    {
      "x": -11,
      "y": 44,
      "z": -5,
      "name": "Soil_Mud_Dry"
    },
    {
      "x": -11,
      "y": 45,
      "z": -5,
      "name": "Soil_Mud_Dry"
    },
    {
      "x": -11,
      "y": 5,
      "z": -4,
      "name": "Soil_Mud_Dry"
    },
    {
      "x": -11,
      "y": 6,
      "z": -4,
      "name": "Soil_Mud"
    },
    {
      "x": -11,
      "y": 7,
      "z": -4,
      "name": "Soil_Mud_Dry"
    },
    {
      "x": -11,
      "y": 8,
      "z": -4,
      "name": "Soil_Mud_Dry"
    },
    {
      "x": -11,
      "y": 9,
      "z": -4,
      "name": "Soil_Mud"
    },
    {
      "x": -11,
      "y": 10,
      "z": -4,
      "name": "Soil_Mud"
    },
    {
      "x": -11,
      "y": 11,
      "z": -4,
      "name": "Soil_Mud_Dry"
    },
    {
      "x": -11,
      "y": 12,
      "z": -4,
      "name": "Soil_Mud_Dry"
    },
    {
      "x": -11,
      "y": 13,
      "z": -4,
      "name": "Soil_Mud"
    },
    {
      "x": -11,
      "y": 35,
      "z": -4,
      "name": "Soil_Mud"
    },
    {
      "x": -11,
      "y": 36,
      "z": -4,
      "name": "Soil_Mud_Dry"
    },
    {
      "x": -11,
      "y": 37,
      "z": -4,
      "name": "Soil_Mud"
    },
    {
      "x": -11,
      "y": 38,
      "z": -4,
      "name": "Soil_Mud"
    },
    {
      "x": -11,
      "y": 39,
      "z": -4,
      "name": "Soil_Mud"
    },
    {
      "x": -11,
      "y": 40,
      "z": -4,
      "name": "Soil_Mud"
    },
    {
      "x": -11,
      "y": 41,
      "z": -4,
      "name": "Soil_Mud_Dry"
    },
    {
      "x": -11,
      "y": 42,
      "z": -4,
      "name": "Soil_Mud"
    },
    {
      "x": -11,
      "y": 43,
      "z": -4,
      "name": "Soil_Mud"
    },
    {
      "x": -11,
      "y": 44,
      "z": -4,
      "name": "Soil_Mud"
    },
    {
      "x": -11,
      "y": 45,
      "z": -4,
      "name": "Soil_Mud"
    },
    {
      "x": -11,
      "y": 46,
      "z": -4,
      "name": "Plant_Crop_Mushroom_Cap_Brown"
    },
    {
      "x": -11,
      "y": 4,
      "z": -3,
      "name": "Soil_Mud"
    },
    {
      "x": -11,
      "y": 5,
      "z": -3,
      "name": "Soil_Mud"
    },
    {
      "x": -11,
      "y": 6,
      "z": -3,
      "name": "Soil_Mud"
    },
    {
      "x": -11,
      "y": 7,
      "z": -3,
      "name": "Soil_Mud"
    },
    {
      "x": -11,
      "y": 8,
      "z": -3,
      "name": "Soil_Mud"
    },
    {
      "x": -11,
      "y": 9,
      "z": -3,
      "name": "Soil_Mud"
    },
    {
      "x": -11,
      "y": 10,
      "z": -3,
      "name": "Soil_Mud"
    },
    {
      "x": -11,
      "y": 11,
      "z": -3,
      "name": "Soil_Mud"
    },
    {
      "x": -11,
      "y": 12,
      "z": -3,
      "name": "Soil_Mud"
    },
    {
      "x": -11,
      "y": 13,
      "z": -3,
      "name": "Soil_Mud"
    },
    {
      "x": -11,
      "y": 34,
      "z": -3,
      "name": "Plant_Moss_Cave_Red"
    },
    {
      "x": -11,
      "y": 35,
      "z": -3,
      "name": "Soil_Mud"
    },
    {
      "x": -11,
      "y": 36,
      "z": -3,
      "name": "Soil_Mud"
    },
    {
      "x": -11,
      "y": 37,
      "z": -3,
      "name": "Soil_Mud_Dry"
    },
    {
      "x": -11,
      "y": 38,
      "z": -3,
      "name": "Soil_Mud_Dry"
    },
    {
      "x": -11,
      "y": 39,
      "z": -3,
      "name": "Soil_Mud"
    },
    {
      "x": -11,
      "y": 40,
      "z": -3,
      "name": "Soil_Mud"
    },
    {
      "x": -11,
      "y": 41,
      "z": -3,
      "name": "Soil_Mud"
    },
    {
      "x": -11,
      "y": 42,
      "z": -3,
      "name": "Soil_Mud"
    },
    {
      "x": -11,
      "y": 43,
      "z": -3,
      "name": "Soil_Mud"
    },
    {
      "x": -11,
      "y": 44,
      "z": -3,
      "name": "Soil_Mud"
    },
    {
      "x": -11,
      "y": 45,
      "z": -3,
      "name": "Soil_Mud"
    },
    {
      "x": -11,
      "y": 5,
      "z": -2,
      "name": "Soil_Mud_Dry"
    },
    {
      "x": -11,
      "y": 6,
      "z": -2,
      "name": "Soil_Mud"
    },
    {
      "x": -11,
      "y": 7,
      "z": -2,
      "name": "Soil_Mud_Dry"
    },
    {
      "x": -11,
      "y": 8,
      "z": -2,
      "name": "Soil_Mud"
    },
    {
      "x": -11,
      "y": 9,
      "z": -2,
      "name": "Soil_Mud"
    },
    {
      "x": -11,
      "y": 10,
      "z": -2,
      "name": "Soil_Mud"
    },
    {
      "x": -11,
      "y": 11,
      "z": -2,
      "name": "Soil_Mud"
    },
    {
      "x": -11,
      "y": 12,
      "z": -2,
      "name": "Soil_Mud"
    },
    {
      "x": -11,
      "y": 13,
      "z": -2,
      "name": "Soil_Mud"
    },
    {
      "x": -11,
      "y": 34,
      "z": -2,
      "name": "Soil_Mud"
    },
    {
      "x": -11,
      "y": 35,
      "z": -2,
      "name": "Soil_Mud_Dry"
    },
    {
      "x": -11,
      "y": 36,
      "z": -2,
      "name": "Soil_Mud"
    },
    {
      "x": -11,
      "y": 37,
      "z": -2,
      "name": "Soil_Mud"
    },
    {
      "x": -11,
      "y": 38,
      "z": -2,
      "name": "Soil_Mud"
    },
    {
      "x": -11,
      "y": 39,
      "z": -2,
      "name": "Soil_Mud"
    },
    {
      "x": -11,
      "y": 40,
      "z": -2,
      "name": "Soil_Mud_Dry"
    },
    {
      "x": -11,
      "y": 41,
      "z": -2,
      "name": "Soil_Mud"
    },
    {
      "x": -11,
      "y": 42,
      "z": -2,
      "name": "Soil_Mud"
    },
    {
      "x": -11,
      "y": 43,
      "z": -2,
      "name": "Soil_Mud"
    },
    {
      "x": -11,
      "y": 44,
      "z": -2,
      "name": "Soil_Mud_Dry"
    },
    {
      "x": -11,
      "y": 45,
      "z": -2,
      "name": "Soil_Mud"
    },
    {
      "x": -11,
      "y": 5,
      "z": -1,
      "name": "Soil_Mud"
    },
    {
      "x": -11,
      "y": 6,
      "z": -1,
      "name": "Soil_Mud_Dry"
    },
    {
      "x": -11,
      "y": 7,
      "z": -1,
      "name": "Soil_Mud"
    },
    {
      "x": -11,
      "y": 8,
      "z": -1,
      "name": "Soil_Mud"
    },
    {
      "x": -11,
      "y": 9,
      "z": -1,
      "name": "Soil_Mud"
    },
    {
      "x": -11,
      "y": 10,
      "z": -1,
      "name": "Soil_Mud"
    },
    {
      "x": -11,
      "y": 11,
      "z": -1,
      "name": "Soil_Mud"
    },
    {
      "x": -11,
      "y": 12,
      "z": -1,
      "name": "Soil_Mud"
    },
    {
      "x": -11,
      "y": 13,
      "z": -1,
      "name": "Soil_Mud"
    },
    {
      "x": -11,
      "y": 14,
      "z": -1,
      "name": "Plant_Grass_Cave_Short"
    },
    {
      "x": -11,
      "y": 32,
      "z": -1,
      "name": "Soil_Mud"
    },
    {
      "x": -11,
      "y": 33,
      "z": -1,
      "name": "Soil_Mud"
    },
    {
      "x": -11,
      "y": 34,
      "z": -1,
      "name": "Soil_Mud"
    },
    {
      "x": -11,
      "y": 35,
      "z": -1,
      "name": "Soil_Mud_Dry"
    },
    {
      "x": -11,
      "y": 36,
      "z": -1,
      "name": "Soil_Mud"
    },
    {
      "x": -11,
      "y": 37,
      "z": -1,
      "name": "Soil_Mud"
    },
    {
      "x": -11,
      "y": 38,
      "z": -1,
      "name": "Soil_Mud_Dry"
    },
    {
      "x": -11,
      "y": 39,
      "z": -1,
      "name": "Soil_Mud"
    },
    {
      "x": -11,
      "y": 40,
      "z": -1,
      "name": "Soil_Mud"
    },
    {
      "x": -11,
      "y": 41,
      "z": -1,
      "name": "Soil_Mud_Dry"
    },
    {
      "x": -11,
      "y": 42,
      "z": -1,
      "name": "Soil_Mud_Dry"
    },
    {
      "x": -11,
      "y": 43,
      "z": -1,
      "name": "Soil_Mud_Dry"
    },
    {
      "x": -11,
      "y": 44,
      "z": -1,
      "name": "Soil_Mud"
    },
    {
      "x": -11,
      "y": 45,
      "z": -1,
      "name": "Soil_Mud"
    },
    {
      "x": -11,
      "y": 46,
      "z": -1,
      "name": "Plant_Crop_Mushroom_Cap_Brown"
    },
    {
      "x": -11,
      "y": 52,
      "z": -1,
      "name": "Plant_Crop_Mushroom_Block_Purple_Mycelium",
      "rotation": 1
    },
    {
      "x": -11,
      "y": 53,
      "z": -1,
      "name": "Plant_Crop_Mushroom_Block_Purple",
      "rotation": 1
    },
    {
      "x": -11,
      "y": 6,
      "z": 0,
      "name": "Soil_Mud_Dry"
    },
    {
      "x": -11,
      "y": 7,
      "z": 0,
      "name": "Soil_Mud"
    },
    {
      "x": -11,
      "y": 8,
      "z": 0,
      "name": "Soil_Mud"
    },
    {
      "x": -11,
      "y": 9,
      "z": 0,
      "name": "Soil_Mud_Dry"
    },
    {
      "x": -11,
      "y": 10,
      "z": 0,
      "name": "Soil_Mud_Dry"
    },
    {
      "x": -11,
      "y": 11,
      "z": 0,
      "name": "Soil_Mud_Dry"
    },
    {
      "x": -11,
      "y": 12,
      "z": 0,
      "name": "Soil_Mud"
    },
    {
      "x": -11,
      "y": 13,
      "z": 0,
      "name": "Soil_Mud"
    },
    {
      "x": -11,
      "y": 14,
      "z": 0,
      "name": "Rubble_Volcanic_Medium"
    },
    {
      "x": -11,
      "y": 34,
      "z": 0,
      "name": "Soil_Mud"
    },
    {
      "x": -11,
      "y": 35,
      "z": 0,
      "name": "Soil_Mud"
    },
    {
      "x": -11,
      "y": 36,
      "z": 0,
      "name": "Soil_Mud_Dry"
    },
    {
      "x": -11,
      "y": 37,
      "z": 0,
      "name": "Soil_Mud"
    },
    {
      "x": -11,
      "y": 38,
      "z": 0,
      "name": "Soil_Mud"
    },
    {
      "x": -11,
      "y": 39,
      "z": 0,
      "name": "Soil_Mud_Dry"
    },
    {
      "x": -11,
      "y": 40,
      "z": 0,
      "name": "Soil_Mud"
    },
    {
      "x": -11,
      "y": 41,
      "z": 0,
      "name": "Soil_Mud"
    },
    {
      "x": -11,
      "y": 42,
      "z": 0,
      "name": "Soil_Mud_Dry"
    },
    {
      "x": -11,
      "y": 43,
      "z": 0,
      "name": "Soil_Mud_Dry"
    },
    {
      "x": -11,
      "y": 44,
      "z": 0,
      "name": "Soil_Mud"
    },
    {
      "x": -11,
      "y": 45,
      "z": 0,
      "name": "Soil_Mud"
    },
    {
      "x": -11,
      "y": 46,
      "z": 0,
      "name": "Soil_Mud_Dry"
    },
    {
      "x": -11,
      "y": 52,
      "z": 0,
      "name": "Plant_Crop_Mushroom_Block_Purple_Mycelium",
      "rotation": 1
    },
    {
      "x": -11,
      "y": 53,
      "z": 0,
      "name": "Plant_Crop_Mushroom_Block_Purple",
      "rotation": 1
    },
    {
      "x": -11,
      "y": 54,
      "z": 0,
      "name": "Plant_Crop_Mushroom_Block_Purple",
      "rotation": 1
    },
    {
      "x": -11,
      "y": 7,
      "z": 1,
      "name": "Soil_Mud"
    },
    {
      "x": -11,
      "y": 8,
      "z": 1,
      "name": "Soil_Mud_Dry"
    },
    {
      "x": -11,
      "y": 9,
      "z": 1,
      "name": "Soil_Mud_Dry"
    },
    {
      "x": -11,
      "y": 10,
      "z": 1,
      "name": "Soil_Mud"
    },
    {
      "x": -11,
      "y": 11,
      "z": 1,
      "name": "Soil_Mud"
    },
    {
      "x": -11,
      "y": 12,
      "z": 1,
      "name": "Soil_Mud"
    },
    {
      "x": -11,
      "y": 13,
      "z": 1,
      "name": "Soil_Mud"
    },
    {
      "x": -11,
      "y": 33,
      "z": 1,
      "name": "Soil_Mud"
    },
    {
      "x": -11,
      "y": 34,
      "z": 1,
      "name": "Soil_Mud_Dry"
    },
    {
      "x": -11,
      "y": 35,
      "z": 1,
      "name": "Soil_Mud_Dry"
    },
    {
      "x": -11,
      "y": 36,
      "z": 1,
      "name": "Soil_Mud"
    },
    {
      "x": -11,
      "y": 37,
      "z": 1,
      "name": "Soil_Mud_Dry"
    },
    {
      "x": -11,
      "y": 38,
      "z": 1,
      "name": "Soil_Mud"
    },
    {
      "x": -11,
      "y": 39,
      "z": 1,
      "name": "Soil_Mud_Dry"
    },
    {
      "x": -11,
      "y": 40,
      "z": 1,
      "name": "Soil_Mud_Dry"
    },
    {
      "x": -11,
      "y": 41,
      "z": 1,
      "name": "Soil_Mud"
    },
    {
      "x": -11,
      "y": 42,
      "z": 1,
      "name": "Soil_Mud"
    },
    {
      "x": -11,
      "y": 43,
      "z": 1,
      "name": "Soil_Mud_Dry"
    },
    {
      "x": -11,
      "y": 44,
      "z": 1,
      "name": "Soil_Mud"
    },
    {
      "x": -11,
      "y": 45,
      "z": 1,
      "name": "Soil_Mud"
    },
    {
      "x": -11,
      "y": 46,
      "z": 1,
      "name": "Soil_Mud_Dry"
    },
    {
      "x": -11,
      "y": 53,
      "z": 1,
      "name": "Plant_Crop_Mushroom_Block_Purple",
      "rotation": 1
    },
    {
      "x": -11,
      "y": 54,
      "z": 1,
      "name": "Plant_Crop_Mushroom_Block_Purple",
      "rotation": 1
    },
    {
      "x": -11,
      "y": 8,
      "z": 2,
      "name": "Soil_Mud_Dry"
    },
    {
      "x": -11,
      "y": 9,
      "z": 2,
      "name": "Soil_Mud_Dry"
    },
    {
      "x": -11,
      "y": 10,
      "z": 2,
      "name": "Soil_Mud"
    },
    {
      "x": -11,
      "y": 11,
      "z": 2,
      "name": "Soil_Mud_Dry"
    },
    {
      "x": -11,
      "y": 12,
      "z": 2,
      "name": "Soil_Mud"
    },
    {
      "x": -11,
      "y": 13,
      "z": 2,
      "name": "Soil_Mud_Dry"
    },
    {
      "x": -11,
      "y": 33,
      "z": 2,
      "name": "Rock_Crystal_Purple_Medium",
      "rotation": 4
    },
    {
      "x": -11,
      "y": 35,
      "z": 2,
      "name": "Soil_Mud"
    },
    {
      "x": -11,
      "y": 36,
      "z": 2,
      "name": "Soil_Mud_Dry"
    },
    {
      "x": -11,
      "y": 37,
      "z": 2,
      "name": "Soil_Mud_Dry"
    },
    {
      "x": -11,
      "y": 38,
      "z": 2,
      "name": "Soil_Mud"
    },
    {
      "x": -11,
      "y": 39,
      "z": 2,
      "name": "Soil_Mud"
    },
    {
      "x": -11,
      "y": 40,
      "z": 2,
      "name": "Soil_Mud"
    },
    {
      "x": -11,
      "y": 41,
      "z": 2,
      "name": "Soil_Mud_Dry"
    },
    {
      "x": -11,
      "y": 42,
      "z": 2,
      "name": "Soil_Mud_Dry"
    },
    {
      "x": -11,
      "y": 43,
      "z": 2,
      "name": "Soil_Mud"
    },
    {
      "x": -11,
      "y": 44,
      "z": 2,
      "name": "Soil_Mud_Dry"
    },
    {
      "x": -11,
      "y": 45,
      "z": 2,
      "name": "Soil_Mud"
    },
    {
      "x": -11,
      "y": 46,
      "z": 2,
      "name": "Soil_Mud"
    },
    {
      "x": -11,
      "y": 52,
      "z": 2,
      "name": "Plant_Crop_Mushroom_Block_Purple_Mycelium",
      "rotation": 1
    },
    {
      "x": -11,
      "y": 53,
      "z": 2,
      "name": "Plant_Crop_Mushroom_Block_Purple",
      "rotation": 1
    },
    {
      "x": -11,
      "y": 54,
      "z": 2,
      "name": "Plant_Crop_Mushroom_Block_Purple",
      "rotation": 1
    },
    {
      "x": -11,
      "y": 55,
      "z": 2,
      "name": "Plant_Crop_Mushroom_Glowing_Purple",
      "rotation": 1
    },
    {
      "x": -11,
      "y": 36,
      "z": 3,
      "name": "Soil_Mud"
    },
    {
      "x": -11,
      "y": 37,
      "z": 3,
      "name": "Soil_Mud"
    },
    {
      "x": -11,
      "y": 38,
      "z": 3,
      "name": "Soil_Mud"
    },
    {
      "x": -11,
      "y": 39,
      "z": 3,
      "name": "Soil_Mud"
    },
    {
      "x": -11,
      "y": 40,
      "z": 3,
      "name": "Soil_Mud_Dry"
    },
    {
      "x": -11,
      "y": 41,
      "z": 3,
      "name": "Soil_Mud"
    },
    {
      "x": -11,
      "y": 42,
      "z": 3,
      "name": "Soil_Mud"
    },
    {
      "x": -11,
      "y": 43,
      "z": 3,
      "name": "Soil_Mud"
    },
    {
      "x": -11,
      "y": 44,
      "z": 3,
      "name": "Soil_Mud_Dry"
    },
    {
      "x": -11,
      "y": 45,
      "z": 3,
      "name": "Soil_Mud"
    },
    {
      "x": -11,
      "y": 46,
      "z": 3,
      "name": "Soil_Mud"
    },
    {
      "x": -11,
      "y": 53,
      "z": 3,
      "name": "Plant_Crop_Mushroom_Block_Purple",
      "rotation": 1
    },
    {
      "x": -11,
      "y": 39,
      "z": 4,
      "name": "Soil_Mud_Dry"
    },
    {
      "x": -11,
      "y": 40,
      "z": 4,
      "name": "Soil_Mud"
    },
    {
      "x": -11,
      "y": 41,
      "z": 4,
      "name": "Soil_Mud"
    },
    {
      "x": -11,
      "y": 42,
      "z": 4,
      "name": "Soil_Mud"
    },
    {
      "x": -11,
      "y": 43,
      "z": 4,
      "name": "Soil_Mud"
    },
    {
      "x": -11,
      "y": 44,
      "z": 4,
      "name": "Soil_Mud"
    },
    {
      "x": -11,
      "y": 45,
      "z": 4,
      "name": "Soil_Mud"
    },
    {
      "x": -11,
      "y": 46,
      "z": 4,
      "name": "Soil_Mud"
    },
    {
      "x": -11,
      "y": 47,
      "z": 4,
      "name": "Plant_Crop_Mushroom_Glowing_Violet"
    },
    {
      "x": -11,
      "y": 53,
      "z": 4,
      "name": "Plant_Crop_Mushroom_Block_Purple",
      "rotation": 1
    },
    {
      "x": -11,
      "y": 41,
      "z": 5,
      "name": "Soil_Mud"
    },
    {
      "x": -11,
      "y": 42,
      "z": 5,
      "name": "Soil_Mud"
    },
    {
      "x": -11,
      "y": 43,
      "z": 5,
      "name": "Soil_Mud"
    },
    {
      "x": -11,
      "y": 44,
      "z": 5,
      "name": "Soil_Mud"
    },
    {
      "x": -11,
      "y": 45,
      "z": 5,
      "name": "Soil_Mud_Dry"
    },
    {
      "x": -11,
      "y": 46,
      "z": 5,
      "name": "Soil_Mud"
    },
    {
      "x": -11,
      "y": 40,
      "z": 6,
      "name": "Soil_Mud_Dry"
    },
    {
      "x": -11,
      "y": 41,
      "z": 6,
      "name": "Soil_Mud"
    },
    {
      "x": -11,
      "y": 42,
      "z": 6,
      "name": "Soil_Mud"
    },
    {
      "x": -11,
      "y": 43,
      "z": 6,
      "name": "Soil_Mud_Dry"
    },
    {
      "x": -11,
      "y": 44,
      "z": 6,
      "name": "Soil_Mud_Dry"
    },
    {
      "x": -11,
      "y": 45,
      "z": 6,
      "name": "Soil_Mud"
    },
    {
      "x": -11,
      "y": 46,
      "z": 6,
      "name": "Plant_Flower_Bushy_Violet"
    },
    {
      "x": -10,
      "y": 40,
      "z": -8,
      "name": "Soil_Mud"
    },
    {
      "x": -10,
      "y": 41,
      "z": -8,
      "name": "Soil_Mud_Dry"
    },
    {
      "x": -10,
      "y": 42,
      "z": -8,
      "name": "Soil_Mud"
    },
    {
      "x": -10,
      "y": 43,
      "z": -8,
      "name": "Soil_Mud"
    },
    {
      "x": -10,
      "y": 44,
      "z": -8,
      "name": "Soil_Mud_Dry"
    },
    {
      "x": -10,
      "y": 45,
      "z": -8,
      "name": "Plant_Bush_Dead_Tall"
    },
    {
      "x": -10,
      "y": 13,
      "z": -7,
      "name": "Soil_Mud"
    },
    {
      "x": -10,
      "y": 38,
      "z": -7,
      "name": "Soil_Mud"
    },
    {
      "x": -10,
      "y": 39,
      "z": -7,
      "name": "Soil_Mud"
    },
    {
      "x": -10,
      "y": 40,
      "z": -7,
      "name": "Soil_Mud_Dry"
    },
    {
      "x": -10,
      "y": 41,
      "z": -7,
      "name": "Soil_Mud"
    },
    {
      "x": -10,
      "y": 42,
      "z": -7,
      "name": "Soil_Mud"
    },
    {
      "x": -10,
      "y": 43,
      "z": -7,
      "name": "Soil_Mud_Dry"
    },
    {
      "x": -10,
      "y": 44,
      "z": -7,
      "name": "Soil_Mud_Dry"
    },
    {
      "x": -10,
      "y": 45,
      "z": -7,
      "name": "Soil_Mud"
    },
    {
      "x": -10,
      "y": 46,
      "z": -7,
      "name": "Plant_Bush_Dead_Tall"
    },
    {
      "x": -10,
      "y": 6,
      "z": -6,
      "name": "Soil_Mud"
    },
    {
      "x": -10,
      "y": 7,
      "z": -6,
      "name": "Soil_Mud"
    },
    {
      "x": -10,
      "y": 8,
      "z": -6,
      "name": "Soil_Mud"
    },
    {
      "x": -10,
      "y": 9,
      "z": -6,
      "name": "Soil_Mud"
    },
    {
      "x": -10,
      "y": 10,
      "z": -6,
      "name": "Soil_Mud"
    },
    {
      "x": -10,
      "y": 11,
      "z": -6,
      "name": "Soil_Mud_Dry"
    },
    {
      "x": -10,
      "y": 12,
      "z": -6,
      "name": "Soil_Mud_Dry"
    },
    {
      "x": -10,
      "y": 13,
      "z": -6,
      "name": "Soil_Mud_Dry"
    },
    {
      "x": -10,
      "y": 36,
      "z": -6,
      "name": "Soil_Mud"
    },
    {
      "x": -10,
      "y": 37,
      "z": -6,
      "name": "Soil_Mud"
    },
    {
      "x": -10,
      "y": 38,
      "z": -6,
      "name": "Soil_Mud"
    },
    {
      "x": -10,
      "y": 39,
      "z": -6,
      "name": "Soil_Mud"
    },
    {
      "x": -10,
      "y": 40,
      "z": -6,
      "name": "Soil_Mud"
    },
    {
      "x": -10,
      "y": 41,
      "z": -6,
      "name": "Soil_Mud_Dry"
    },
    {
      "x": -10,
      "y": 42,
      "z": -6,
      "name": "Soil_Mud"
    },
    {
      "x": -10,
      "y": 43,
      "z": -6,
      "name": "Soil_Mud"
    },
    {
      "x": -10,
      "y": 44,
      "z": -6,
      "name": "Soil_Mud_Dry"
    },
    {
      "x": -10,
      "y": 45,
      "z": -6,
      "name": "Soil_Mud"
    },
    {
      "x": -10,
      "y": 46,
      "z": -6,
      "name": "Plant_Crop_Mushroom_Glowing_Purple"
    },
    {
      "x": -10,
      "y": 6,
      "z": -5,
      "name": "Soil_Mud"
    },
    {
      "x": -10,
      "y": 7,
      "z": -5,
      "name": "Soil_Mud"
    },
    {
      "x": -10,
      "y": 8,
      "z": -5,
      "name": "Soil_Mud_Dry"
    },
    {
      "x": -10,
      "y": 9,
      "z": -5,
      "name": "Soil_Mud_Dry"
    },
    {
      "x": -10,
      "y": 10,
      "z": -5,
      "name": "Soil_Mud_Dry"
    },
    {
      "x": -10,
      "y": 11,
      "z": -5,
      "name": "Soil_Mud"
    },
    {
      "x": -10,
      "y": 12,
      "z": -5,
      "name": "Soil_Mud_Dry"
    },
    {
      "x": -10,
      "y": 13,
      "z": -5,
      "name": "Soil_Mud_Dry"
    },
    {
      "x": -10,
      "y": 34,
      "z": -5,
      "name": "Soil_Mud"
    },
    {
      "x": -10,
      "y": 35,
      "z": -5,
      "name": "Soil_Mud_Dry"
    },
    {
      "x": -10,
      "y": 36,
      "z": -5,
      "name": "Soil_Mud"
    },
    {
      "x": -10,
      "y": 37,
      "z": -5,
      "name": "Soil_Mud"
    },
    {
      "x": -10,
      "y": 38,
      "z": -5,
      "name": "Soil_Mud"
    },
    {
      "x": -10,
      "y": 39,
      "z": -5,
      "name": "Soil_Mud"
    },
    {
      "x": -10,
      "y": 40,
      "z": -5,
      "name": "Soil_Mud"
    },
    {
      "x": -10,
      "y": 41,
      "z": -5,
      "name": "Soil_Mud"
    },
    {
      "x": -10,
      "y": 42,
      "z": -5,
      "name": "Soil_Mud"
    },
    {
      "x": -10,
      "y": 43,
      "z": -5,
      "name": "Soil_Mud_Dry"
    },
    {
      "x": -10,
      "y": 44,
      "z": -5,
      "name": "Soil_Mud_Dry"
    },
    {
      "x": -10,
      "y": 45,
      "z": -5,
      "name": "Soil_Mud"
    },
    {
      "x": -10,
      "y": 4,
      "z": -4,
      "name": "Plant_Moss_Cave_Red"
    },
    {
      "x": -10,
      "y": 5,
      "z": -4,
      "name": "Soil_Mud"
    },
    {
      "x": -10,
      "y": 6,
      "z": -4,
      "name": "Soil_Mud"
    },
    {
      "x": -10,
      "y": 7,
      "z": -4,
      "name": "Soil_Mud"
    },
    {
      "x": -10,
      "y": 8,
      "z": -4,
      "name": "Soil_Mud"
    },
    {
      "x": -10,
      "y": 9,
      "z": -4,
      "name": "Soil_Mud_Dry"
    },
    {
      "x": -10,
      "y": 10,
      "z": -4,
      "name": "Soil_Mud"
    },
    {
      "x": -10,
      "y": 11,
      "z": -4,
      "name": "Soil_Mud"
    },
    {
      "x": -10,
      "y": 12,
      "z": -4,
      "name": "Soil_Mud"
    },
    {
      "x": -10,
      "y": 13,
      "z": -4,
      "name": "Rock_Volcanic_Brick"
    },
    {
      "x": -10,
      "y": 14,
      "z": -4,
      "name": "Rock_Volcanic_Brick_Pillar_Base"
    },
    {
      "x": -10,
      "y": 15,
      "z": -4,
      "name": "Rock_Volcanic_Brick_Pillar_Middle"
    },
    {
      "x": -10,
      "y": 16,
      "z": -4,
      "name": "Rock_Volcanic_Brick_Pillar_Middle"
    },
    {
      "x": -10,
      "y": 17,
      "z": -4,
      "name": "Rubble_Volcanic"
    },
    {
      "x": -10,
      "y": 34,
      "z": -4,
      "name": "Plant_Moss_Cave_Red"
    },
    {
      "x": -10,
      "y": 35,
      "z": -4,
      "name": "Soil_Mud"
    },
    {
      "x": -10,
      "y": 36,
      "z": -4,
      "name": "Soil_Mud"
    },
    {
      "x": -10,
      "y": 37,
      "z": -4,
      "name": "Soil_Mud_Dry"
    },
    {
      "x": -10,
      "y": 38,
      "z": -4,
      "name": "Soil_Mud"
