{
  "version": 8,
  "blockIdVersion": 11,
  "anchorX": 0,
  "anchorY": 0,
  "anchorZ": 0,
  "blocks": [
    {
      "x": -17,
      "y": 26,
      "z": -11,
      "name": "Plant_Crop_Mushroom_Shelve_Yellow"
    },
    {
      "x": -16,
      "y": 25,
      "z": -15,
      "name": "Rock_Sandstone_Red"
    },
    {
      "x": -16,
      "y": 26,
      "z": -15,
      "name": "Rock_Sandstone_Red"
    },
    {
      "x": -16,
      "y": 24,
      "z": -14,
      "name": "Rock_Sandstone_Red"
    },
    {
      "x": -16,
      "y": 25,
      "z": -14,
      "name": "Rock_Sandstone_Red"
    },
    {
      "x": -16,
      "y": 26,
      "z": -14,
      "name": "Rock_Sandstone_Red"
    },
    {
      "x": -16,
      "y": 27,
      "z": -14,
      "name": "Rock_Sandstone_Red"
    },
    {
      "x": -16,
      "y": 20,
      "z": -13,
      "name": "Rock_Sandstone_Red_Stalactite_Large",
      "filler": 31744,
      "rotation": 8
    },
    {
      "x": -16,
      "y": 21,
      "z": -13,
      "name": "Rock_Sandstone_Red_Stalactite_Large",
      "rotation": 8
    },
    {
      "x": -16,
      "y": 22,
      "z": -13,
      "name": "Rock_Sandstone_Red"
    },
    {
      "x": -16,
      "y": 23,
      "z": -13,
      "name": "Rock_Sandstone_Red_Cobble"
    },
    {
      "x": -16,
      "y": 24,
      "z": -13,
      "name": "Rock_Sandstone_Red"
    },
    {
      "x": -16,
      "y": 25,
      "z": -13,
      "name": "Rock_Sandstone_Red"
    },
    {
      "x": -16,
      "y": 26,
      "z": -13,
      "name": "Rock_Sandstone_Red"
    },
    {
      "x": -16,
      "y": 27,
      "z": -13,
      "name": "Rock_Sandstone_Red"
    },
    {
      "x": -16,
      "y": 28,
      "z": -13,
      "name": "Rock_Sandstone_Red_Cobble"
    },
    {
      "x": -16,
      "y": 23,
      "z": -12,
      "name": "Rock_Sandstone_Red"
    },
    {
      "x": -16,
      "y": 24,
      "z": -12,
      "name": "Ore_Gold_Sandstone"
    },
    {
      "x": -16,
      "y": 25,
      "z": -12,
      "name": "Rock_Sandstone_Red"
    },
    {
      "x": -16,
      "y": 26,
      "z": -12,
      "name": "Rock_Sandstone_Red"
    },
    {
      "x": -16,
      "y": 27,
      "z": -12,
      "name": "Rock_Sandstone_Red"
    },
    {
      "x": -16,
      "y": 28,
      "z": -12,
      "name": "Rock_Sandstone_Red"
    },
    {
      "x": -16,
      "y": 24,
      "z": -11,
      "name": "Rock_Sandstone_Red"
    },
    {
      "x": -16,
      "y": 25,
      "z": -11,
      "name": "Rock_Sandstone_Red"
    },
    {
      "x": -16,
      "y": 26,
      "z": -11,
      "name": "Rock_Sandstone_Red"
    },
    {
      "x": -16,
      "y": 27,
      "z": -11,
      "name": "Rock_Sandstone_Red"
    },
    {
      "x": -16,
      "y": 28,
      "z": -11,
      "name": "Rock_Sandstone_Red"
    },
    {
      "x": -16,
      "y": 29,
      "z": -11,
      "name": "Rubble_Sandstone_Red"
    },
    {
      "x": -16,
      "y": 26,
      "z": -10,
      "name": "Rock_Sandstone_Red"
    },
    {
      "x": -16,
      "y": 27,
      "z": -10,
      "name": "Rock_Sandstone_Red"
    },
    {
      "x": -16,
      "y": 28,
      "z": -10,
      "name": "Rock_Sandstone_Red"
    },
    {
      "x": -16,
      "y": 29,
      "z": -10,
      "name": "Rubble_Sandstone_Red_Medium"
    },
    {
      "x": -16,
      "y": 27,
      "z": -9,
      "name": "Rock_Sandstone_Red"
    },
    {
      "x": -16,
      "y": 28,
      "z": -9,
      "name": "Rock_Sandstone_Red"
    },
    {
      "x": -16,
      "y": 29,
      "z": -9,
      "name": "Rock_Sandstone_Red"
    },
    {
      "x": -16,
      "y": 30,
      "z": -9,
      "name": "Rubble_Sandstone_Red"
    },
    {
      "x": -16,
      "y": 27,
      "z": -8,
      "name": "Plant_Crop_Mushroom_Shelve_Yellow"
    },
    {
      "x": -16,
      "y": 28,
      "z": -8,
      "name": "Rock_Sandstone_Red"
    },
    {
      "x": -16,
      "y": 29,
      "z": -8,
      "name": "Rock_Sandstone_Red"
    },
    {
      "x": -16,
      "y": 28,
      "z": -7,
      "name": "Plant_Crop_Mushroom_Shelve_Yellow"
    },
    {
      "x": -16,
      "y": 29,
      "z": -5,
      "name": "Plant_Crop_Mushroom_Shelve_Yellow"
    },
    {
      "x": -16,
      "y": 29,
      "z": -2,
      "name": "Plant_Crop_Mushroom_Shelve_Yellow"
    },
    {
      "x": -15,
      "y": 23,
      "z": -16,
      "name": "Rock_Sandstone_Red"
    },
    {
      "x": -15,
      "y": 25,
      "z": -16,
      "name": "Rock_Sandstone_Red"
    },
    {
      "x": -15,
      "y": 26,
      "z": -16,
      "name": "Rock_Sandstone_Red"
    },
    {
      "x": -15,
      "y": 22,
      "z": -15,
      "name": "Rock_Sandstone_Red"
    },
    {
      "x": -15,
      "y": 23,
      "z": -15,
      "name": "Rock_Sandstone_Red"
    },
    {
      "x": -15,
      "y": 24,
      "z": -15,
      "name": "Rock_Sandstone_Red"
    },
    {
      "x": -15,
      "y": 25,
      "z": -15,
      "name": "Rock_Sandstone_Red"
    },
    {
      "x": -15,
      "y": 26,
      "z": -15,
      "name": "Rock_Sandstone_Red"
    },
    {
      "x": -15,
      "y": 27,
      "z": -15,
      "name": "Rock_Sandstone_Red"
    },
    {
      "x": -15,
      "y": 28,
      "z": -15,
      "name": "Soil_Sand_Red"
    },
    {
      "x": -15,
      "y": 21,
      "z": -14,
      "name": "Rock_Sandstone_Red"
    },
    {
      "x": -15,
      "y": 22,
      "z": -14,
      "name": "Rock_Sandstone_Red"
    },
    {
      "x": -15,
      "y": 23,
      "z": -14,
      "name": "Rock_Sandstone_Red"
    },
    {
      "x": -15,
      "y": 24,
      "z": -14,
      "name": "Rock_Sandstone_Red"
    },
    {
      "x": -15,
      "y": 25,
      "z": -14,
      "name": "Rock_Sandstone_Red"
    },
    {
      "x": -15,
      "y": 26,
      "z": -14,
      "name": "Rock_Sandstone_Red"
    },
    {
      "x": -15,
      "y": 27,
      "z": -14,
      "name": "Soil_Gravel_Sand_Red"
    },
    {
      "x": -15,
      "y": 28,
      "z": -14,
      "name": "Soil_Sand_Red"
    },
    {
      "x": -15,
      "y": 21,
      "z": -13,
      "name": "Rock_Sandstone_Red"
    },
    {
      "x": -15,
      "y": 22,
      "z": -13,
      "name": "Rock_Sandstone_Red"
    },
    {
      "x": -15,
      "y": 23,
      "z": -13,
      "name": "Rock_Sandstone_Red"
    },
    {
      "x": -15,
      "y": 24,
      "z": -13,
      "name": "Rock_Sandstone_Red"
    },
    {
      "x": -15,
      "y": 25,
      "z": -13,
      "name": "Rock_Sandstone_Red"
    },
    {
      "x": -15,
      "y": 26,
      "z": -13,
      "name": "Rock_Sandstone_Red"
    },
    {
      "x": -15,
      "y": 27,
      "z": -13,
      "name": "Rock_Sandstone_Red"
    },
    {
      "x": -15,
      "y": 28,
      "z": -13,
      "name": "Soil_Gravel_Sand_Red"
    },
    {
      "x": -15,
      "y": 29,
      "z": -13,
      "name": "Soil_Sand_Red"
    },
    {
      "x": -15,
      "y": 21,
      "z": -12,
      "name": "Rock_Sandstone_Red"
    },
    {
      "x": -15,
      "y": 22,
      "z": -12,
      "name": "Rock_Sandstone_Red"
    },
    {
      "x": -15,
      "y": 23,
      "z": -12,
      "name": "Rock_Sandstone_Red"
    },
    {
      "x": -15,
      "y": 24,
      "z": -12,
      "name": "Ore_Gold_Sandstone"
    },
    {
      "x": -15,
      "y": 25,
      "z": -12,
      "name": "Rock_Sandstone_Red"
    },
    {
      "x": -15,
      "y": 26,
      "z": -12,
      "name": "Rock_Sandstone_Red"
    },
    {
      "x": -15,
      "y": 27,
      "z": -12,
      "name": "Rock_Sandstone_Red"
    },
    {
      "x": -15,
      "y": 28,
      "z": -12,
      "name": "Soil_Sand_Red"
    },
    {
      "x": -15,
      "y": 29,
      "z": -12,
      "name": "Soil_Gravel_Sand_Red"
    },
    {
      "x": -15,
      "y": 30,
      "z": -12,
      "name": "Plant_Crop_Mushroom_Glowing_Red"
    },
    {
      "x": -15,
      "y": 22,
      "z": -11,
      "name": "Rock_Sandstone_Red"
    },
    {
      "x": -15,
      "y": 23,
      "z": -11,
      "name": "Rock_Sandstone_Red"
    },
    {
      "x": -15,
      "y": 24,
      "z": -11,
      "name": "Rock_Sandstone_Red"
    },
    {
      "x": -15,
      "y": 25,
      "z": -11,
      "name": "Rock_Sandstone_Red"
    },
    {
      "x": -15,
      "y": 26,
      "z": -11,
      "name": "Rock_Sandstone_Red"
    },
    {
      "x": -15,
      "y": 27,
      "z": -11,
      "name": "Rock_Sandstone_Red"
    },
    {
      "x": -15,
      "y": 28,
      "z": -11,
      "name": "Soil_Sand_Red"
    },
    {
      "x": -15,
      "y": 29,
      "z": -11,
      "name": "Soil_Sand_Red"
    },
    {
      "x": -15,
      "y": 23,
      "z": -10,
      "name": "Rock_Sandstone_Red"
    },
    {
      "x": -15,
      "y": 24,
      "z": -10,
      "name": "Rock_Sandstone_Red"
    },
    {
      "x": -15,
      "y": 25,
      "z": -10,
      "name": "Rock_Sandstone_Red"
    },
    {
      "x": -15,
      "y": 26,
      "z": -10,
      "name": "Rock_Sandstone_Red"
    },
    {
      "x": -15,
      "y": 27,
      "z": -10,
      "name": "Rock_Sandstone_Red"
    },
    {
      "x": -15,
      "y": 28,
      "z": -10,
      "name": "Rock_Sandstone_Red"
    },
    {
      "x": -15,
      "y": 29,
      "z": -10,
      "name": "Soil_Sand_Red"
    },
    {
      "x": -15,
      "y": 30,
      "z": -10,
      "name": "Soil_Sand_Red"
    },
    {
      "x": -15,
      "y": 25,
      "z": -9,
      "name": "Rock_Sandstone_Red"
    },
    {
      "x": -15,
      "y": 26,
      "z": -9,
      "name": "Rock_Sandstone_Red"
    },
    {
      "x": -15,
      "y": 27,
      "z": -9,
      "name": "Rock_Sandstone_Red"
    },
    {
      "x": -15,
      "y": 28,
      "z": -9,
      "name": "Rock_Sandstone_Red"
    },
    {
      "x": -15,
      "y": 29,
      "z": -9,
      "name": "Rock_Sandstone_Red_Cobble"
    },
    {
      "x": -15,
      "y": 30,
      "z": -9,
      "name": "Soil_Gravel_Sand_Red"
    },
    {
      "x": -15,
      "y": 24,
      "z": -8,
      "name": "Rock_Sandstone_Red"
    },
    {
      "x": -15,
      "y": 25,
      "z": -8,
      "name": "Rock_Sandstone_Red"
    },
    {
      "x": -15,
      "y": 26,
      "z": -8,
      "name": "Rock_Sandstone_Red"
    },
    {
      "x": -15,
      "y": 27,
      "z": -8,
      "name": "Rock_Sandstone_Red"
    },
    {
      "x": -15,
      "y": 28,
      "z": -8,
      "name": "Rock_Sandstone_Red"
    },
    {
      "x": -15,
      "y": 29,
      "z": -8,
      "name": "Rock_Sandstone_Red"
    },
    {
      "x": -15,
      "y": 30,
      "z": -8,
      "name": "Soil_Sand_Red"
    },
    {
      "x": -15,
      "y": 31,
      "z": -8,
      "name": "Soil_Sand_Red"
    },
    {
      "x": -15,
      "y": 25,
      "z": -7,
      "name": "Rock_Sandstone_Red"
    },
    {
      "x": -15,
      "y": 26,
      "z": -7,
      "name": "Rock_Sandstone_Red"
    },
    {
      "x": -15,
      "y": 27,
      "z": -7,
      "name": "Rock_Sandstone_Red"
    },
    {
      "x": -15,
      "y": 28,
      "z": -7,
      "name": "Rock_Sandstone_Red"
    },
    {
      "x": -15,
      "y": 29,
      "z": -7,
      "name": "Rock_Sandstone_Red"
    },
    {
      "x": -15,
      "y": 30,
      "z": -7,
      "name": "Rock_Sandstone_Red"
    },
    {
      "x": -15,
      "y": 31,
      "z": -7,
      "name": "Rock_Sandstone_Red"
    },
    {
      "x": -15,
      "y": 32,
      "z": -7,
      "name": "Rubble_Sandstone_Red"
    },
    {
      "x": -15,
      "y": 26,
      "z": -6,
      "name": "Rock_Sandstone_Red"
    },
    {
      "x": -15,
      "y": 27,
      "z": -6,
      "name": "Rock_Sandstone_Red"
    },
    {
      "x": -15,
      "y": 28,
      "z": -6,
      "name": "Rock_Sandstone_Red"
    },
    {
      "x": -15,
      "y": 29,
      "z": -6,
      "name": "Rock_Sandstone_Red"
    },
    {
      "x": -15,
      "y": 30,
      "z": -6,
      "name": "Rock_Sandstone_Red"
    },
    {
      "x": -15,
      "y": 31,
      "z": -6,
      "name": "Rock_Sandstone_Red"
    },
    {
      "x": -15,
      "y": 28,
      "z": -5,
      "name": "Rock_Sandstone_Red"
    },
    {
      "x": -15,
      "y": 29,
      "z": -5,
      "name": "Rock_Sandstone_Red"
    },
    {
      "x": -15,
      "y": 30,
      "z": -5,
      "name": "Rock_Sandstone_Red"
    },
    {
      "x": -15,
      "y": 31,
      "z": -5,
      "name": "Rock_Sandstone_Red"
    },
    {
      "x": -15,
      "y": 32,
      "z": -5,
      "name": "Soil_Gravel_Sand_Red"
    },
    {
      "x": -15,
      "y": 28,
      "z": -4,
      "name": "Rock_Sandstone_Red"
    },
    {
      "x": -15,
      "y": 29,
      "z": -4,
      "name": "Rock_Sandstone_Red"
    },
    {
      "x": -15,
      "y": 30,
      "z": -4,
      "name": "Rock_Sandstone_Red"
    },
    {
      "x": -15,
      "y": 31,
      "z": -4,
      "name": "Rock_Sandstone_Red"
    },
    {
      "x": -15,
      "y": 32,
      "z": -4,
      "name": "Rock_Sandstone_Red"
    },
    {
      "x": -15,
      "y": 25,
      "z": -3,
      "name": "Plant_Moss_Cave_Red"
    },
    {
      "x": -15,
      "y": 26,
      "z": -3,
      "name": "Plant_Moss_Cave_Red"
    },
    {
      "x": -15,
      "y": 27,
      "z": -3,
      "name": "Rock_Sandstone_Red"
    },
    {
      "x": -15,
      "y": 28,
      "z": -3,
      "name": "Rock_Sandstone_Red"
    },
    {
      "x": -15,
      "y": 29,
      "z": -3,
      "name": "Rock_Sandstone_Red"
    },
    {
      "x": -15,
      "y": 30,
      "z": -3,
      "name": "Rock_Sandstone_Red"
    },
    {
      "x": -15,
      "y": 31,
      "z": -3,
      "name": "Rock_Sandstone_Red"
    },
    {
      "x": -15,
      "y": 32,
      "z": -3,
      "name": "Rock_Sandstone_Red"
    },
    {
      "x": -15,
      "y": 33,
      "z": -3,
      "name": "Rubble_Sandstone_Red_Medium"
    },
    {
      "x": -15,
      "y": 28,
      "z": -2,
      "name": "Rock_Sandstone_Red"
    },
    {
      "x": -15,
      "y": 29,
      "z": -2,
      "name": "Rock_Sandstone_Red"
    },
    {
      "x": -15,
      "y": 30,
      "z": -2,
      "name": "Rock_Sandstone_Red"
    },
    {
      "x": -15,
      "y": 31,
      "z": -2,
      "name": "Rock_Sandstone_Red"
    },
    {
      "x": -15,
      "y": 32,
      "z": -2,
      "name": "Rock_Sandstone_Red"
    },
    {
      "x": -15,
      "y": 33,
      "z": -2,
      "name": "Rubble_Sandstone_Red"
    },
    {
      "x": -15,
      "y": 29,
      "z": -1,
      "name": "Rock_Sandstone_Red"
    },
    {
      "x": -15,
      "y": 30,
      "z": -1,
      "name": "Rock_Sandstone_Red"
    },
    {
      "x": -15,
      "y": 31,
      "z": -1,
      "name": "Rock_Sandstone_Red"
    },
    {
      "x": -15,
      "y": 32,
      "z": -1,
      "name": "Rock_Sandstone_Red"
    },
    {
      "x": -15,
      "y": 30,
      "z": 1,
      "name": "Plant_Crop_Mushroom_Shelve_Yellow"
    },
    {
      "x": -14,
      "y": 24,
      "z": -17,
      "name": "Rock_Sandstone_Red"
    },
    {
      "x": -14,
      "y": 22,
      "z": -16,
      "name": "Rock_Sandstone_Red"
    },
    {
      "x": -14,
      "y": 23,
      "z": -16,
      "name": "Rock_Sandstone_Red"
    },
    {
      "x": -14,
      "y": 24,
      "z": -16,
      "name": "Rock_Sandstone_Red"
    },
    {
      "x": -14,
      "y": 25,
      "z": -16,
      "name": "Rock_Sandstone_Red"
    },
    {
      "x": -14,
      "y": 26,
      "z": -16,
      "name": "Rock_Sandstone_Red"
    },
    {
      "x": -14,
      "y": 27,
      "z": -16,
      "name": "Rock_Sandstone_Red"
    },
    {
      "x": -14,
      "y": 28,
      "z": -16,
      "name": "Rubble_Sandstone_Red_Medium"
    },
    {
      "x": -14,
      "y": 21,
      "z": -15,
      "name": "Rock_Sandstone_Red"
    },
    {
      "x": -14,
      "y": 22,
      "z": -15,
      "name": "Rock_Sandstone_Red"
    },
    {
      "x": -14,
      "y": 23,
      "z": -15,
      "name": "Rock_Sandstone_Red"
    },
    {
      "x": -14,
      "y": 24,
      "z": -15,
      "name": "Rock_Sandstone_Red"
    },
    {
      "x": -14,
      "y": 25,
      "z": -15,
      "name": "Rock_Sandstone_Red"
    },
    {
      "x": -14,
      "y": 26,
      "z": -15,
      "name": "Rock_Sandstone_Red"
    },
    {
      "x": -14,
      "y": 27,
      "z": -15,
      "name": "Rock_Sandstone_Red"
    },
    {
      "x": -14,
      "y": 28,
      "z": -15,
      "name": "Soil_Gravel_Sand_Red"
    },
    {
      "x": -14,
      "y": 20,
      "z": -14,
      "name": "Rock_Sandstone_Red"
    },
    {
      "x": -14,
      "y": 21,
      "z": -14,
      "name": "Rock_Sandstone_Red"
    },
    {
      "x": -14,
      "y": 22,
      "z": -14,
      "name": "Rock_Sandstone_Red"
    },
    {
      "x": -14,
      "y": 23,
      "z": -14,
      "name": "Rock_Sandstone_Red"
    },
    {
      "x": -14,
      "y": 24,
      "z": -14,
      "name": "Rock_Sandstone_Red"
    },
    {
      "x": -14,
      "y": 25,
      "z": -14,
      "name": "Rock_Sandstone_Red"
    },
    {
      "x": -14,
      "y": 26,
      "z": -14,
      "name": "Rock_Sandstone_Red"
    },
    {
      "x": -14,
      "y": 27,
      "z": -14,
      "name": "Rock_Sandstone_Red"
    },
    {
      "x": -14,
      "y": 28,
      "z": -14,
      "name": "Soil_Gravel_Sand_Red"
    },
    {
      "x": -14,
      "y": 29,
      "z": -14,
      "name": "Soil_Sand_Red"
    },
    {
      "x": -14,
      "y": 30,
      "z": -14,
      "name": "Plant_Bush_Crystal"
    },
    {
      "x": -14,
      "y": 20,
      "z": -13,
      "name": "Rock_Sandstone_Red"
    },
    {
      "x": -14,
      "y": 21,
      "z": -13,
      "name": "Rock_Sandstone_Red"
    },
    {
      "x": -14,
      "y": 22,
      "z": -13,
      "name": "Rock_Sandstone_Red"
    },
    {
      "x": -14,
      "y": 23,
      "z": -13,
      "name": "Rock_Sandstone_Red"
    },
    {
      "x": -14,
      "y": 24,
      "z": -13,
      "name": "Rock_Sandstone_Red"
    },
    {
      "x": -14,
      "y": 25,
      "z": -13,
      "name": "Rock_Sandstone_Red"
    },
    {
      "x": -14,
      "y": 26,
      "z": -13,
      "name": "Rock_Sandstone_Red"
    },
    {
      "x": -14,
      "y": 27,
      "z": -13,
      "name": "Rock_Sandstone_Red"
    },
    {
      "x": -14,
      "y": 28,
      "z": -13,
      "name": "Rock_Sandstone_Red_Cobble"
    },
    {
      "x": -14,
      "y": 29,
      "z": -13,
      "name": "Soil_Sand_Red"
    },
    {
      "x": -14,
      "y": 17,
      "z": -12,
      "name": "Rock_Crystal_Red_Medium",
      "rotation": 7
    },
    {
      "x": -14,
      "y": 18,
      "z": -12,
      "name": "Rock_Crystal_Red_Medium",
      "rotation": 7
    },
    {
      "x": -14,
      "y": 19,
      "z": -12,
      "name": "Rock_Crystal_Red_Medium",
      "rotation": 7
    },
    {
      "x": -14,
      "y": 20,
      "z": -12,
      "name": "Rock_Sandstone_Red"
    },
    {
      "x": -14,
      "y": 21,
      "z": -12,
      "name": "Rock_Sandstone_Red"
    },
    {
      "x": -14,
      "y": 22,
      "z": -12,
      "name": "Rock_Sandstone_Red"
    },
    {
      "x": -14,
      "y": 23,
      "z": -12,
      "name": "Rock_Sandstone_Red"
    },
    {
      "x": -14,
      "y": 24,
      "z": -12,
      "name": "Ore_Gold_Sandstone"
    },
    {
      "x": -14,
      "y": 25,
      "z": -12,
      "name": "Rock_Sandstone_Red"
    },
    {
      "x": -14,
      "y": 26,
      "z": -12,
      "name": "Rock_Sandstone_Red"
    },
    {
      "x": -14,
      "y": 27,
      "z": -12,
      "name": "Rock_Sandstone_Red"
    },
    {
      "x": -14,
      "y": 28,
      "z": -12,
      "name": "Soil_Sand_Red"
    },
    {
      "x": -14,
      "y": 29,
      "z": -12,
      "name": "Rock_Sandstone_Red_Cobble"
    },
    {
      "x": -14,
      "y": 30,
      "z": -12,
      "name": "Soil_Sand_Red"
    },
    {
      "x": -14,
      "y": 31,
      "z": -12,
      "name": "Plant_Bush_Arid"
    },
    {
      "x": -14,
      "y": 21,
      "z": -11,
      "name": "Rock_Sandstone_Red"
    },
    {
      "x": -14,
      "y": 22,
      "z": -11,
      "name": "Rock_Sandstone_Red"
    },
    {
      "x": -14,
      "y": 23,
      "z": -11,
      "name": "Rock_Sandstone_Red"
    },
    {
      "x": -14,
      "y": 24,
      "z": -11,
      "name": "Rock_Sandstone_Red"
    },
    {
      "x": -14,
      "y": 25,
      "z": -11,
      "name": "Rock_Sandstone_Red"
    },
    {
      "x": -14,
      "y": 26,
      "z": -11,
      "name": "Rock_Sandstone_Red"
    },
    {
      "x": -14,
      "y": 27,
      "z": -11,
      "name": "Rock_Sandstone_Red"
    },
    {
      "x": -14,
      "y": 28,
      "z": -11,
      "name": "Rock_Sandstone_Red"
    },
    {
      "x": -14,
      "y": 29,
      "z": -11,
      "name": "Rock_Sandstone_Red"
    },
    {
      "x": -14,
      "y": 30,
      "z": -11,
      "name": "Rock_Sandstone_Red"
    },
    {
      "x": -14,
      "y": 21,
      "z": -10,
      "name": "Plant_Bush_Dead_Hanging"
    },
    {
      "x": -14,
      "y": 22,
      "z": -10,
      "name": "Rock_Sandstone_Red"
    },
    {
      "x": -14,
      "y": 23,
      "z": -10,
      "name": "Rock_Sandstone_Red"
    },
    {
      "x": -14,
      "y": 24,
      "z": -10,
      "name": "Rock_Sandstone_Red"
    },
    {
      "x": -14,
      "y": 25,
      "z": -10,
      "name": "Rock_Sandstone_Red"
    },
    {
      "x": -14,
      "y": 26,
      "z": -10,
      "name": "Rock_Sandstone_Red"
    },
    {
      "x": -14,
      "y": 27,
      "z": -10,
      "name": "Rock_Sandstone_Red"
    },
    {
      "x": -14,
      "y": 28,
      "z": -10,
      "name": "Soil_Sand_Red"
    },
    {
      "x": -14,
      "y": 29,
      "z": -10,
      "name": "Soil_Sand_Red"
    },
    {
      "x": -14,
      "y": 30,
      "z": -10,
      "name": "Soil_Sand_Red"
    },
    {
      "x": -14,
      "y": 31,
      "z": -10,
      "name": "Soil_Sand_Red"
    },
    {
      "x": -14,
      "y": 32,
      "z": -10,
      "name": "Plant_Bush_Arid"
    },
    {
      "x": -14,
      "y": 22,
      "z": -9,
      "name": "Plant_Moss_Cave_Red"
    },
    {
      "x": -14,
      "y": 23,
      "z": -9,
      "name": "Rock_Sandstone_Red"
    },
    {
      "x": -14,
      "y": 24,
      "z": -9,
      "name": "Rock_Sandstone_Red"
    },
    {
      "x": -14,
      "y": 25,
      "z": -9,
      "name": "Rock_Sandstone_Red"
    },
    {
      "x": -14,
      "y": 26,
      "z": -9,
      "name": "Rock_Sandstone_Red"
    },
    {
      "x": -14,
      "y": 27,
      "z": -9,
      "name": "Rock_Sandstone_Red"
    },
    {
      "x": -14,
      "y": 28,
      "z": -9,
      "name": "Rock_Sandstone_Red"
    },
    {
      "x": -14,
      "y": 29,
      "z": -9,
      "name": "Rock_Sandstone_Red"
    },
    {
      "x": -14,
      "y": 30,
      "z": -9,
      "name": "Soil_Sand_Red"
    },
    {
      "x": -14,
      "y": 31,
      "z": -9,
      "name": "Soil_Sand_Red"
    },
    {
      "x": -14,
      "y": 23,
      "z": -8,
      "name": "Rock_Sandstone_Red"
    },
    {
      "x": -14,
      "y": 24,
      "z": -8,
      "name": "Rock_Sandstone_Red"
    },
    {
      "x": -14,
      "y": 25,
      "z": -8,
      "name": "Rock_Sandstone_Red"
    },
    {
      "x": -14,
      "y": 26,
      "z": -8,
      "name": "Rock_Sandstone_Red"
    },
    {
      "x": -14,
      "y": 27,
      "z": -8,
      "name": "Rock_Sandstone_Red"
    },
    {
      "x": -14,
      "y": 28,
      "z": -8,
      "name": "Rock_Sandstone_Red"
    },
    {
      "x": -14,
      "y": 29,
      "z": -8,
      "name": "Rock_Sandstone_Red"
    },
    {
      "x": -14,
      "y": 30,
      "z": -8,
      "name": "Rock_Sandstone_Red"
    },
    {
      "x": -14,
      "y": 31,
      "z": -8,
      "name": "Soil_Sand_Red"
    },
    {
      "x": -14,
      "y": 32,
      "z": -8,
      "name": "Soil_Gravel_Sand_Red"
    },
    {
      "x": -14,
      "y": 22,
      "z": -7,
      "name": "Plant_Moss_Cave_Red"
    },
    {
      "x": -14,
      "y": 23,
      "z": -7,
      "name": "Rock_Sandstone_Red"
    },
    {
      "x": -14,
      "y": 24,
      "z": -7,
      "name": "Rock_Sandstone_Red"
    },
    {
      "x": -14,
      "y": 25,
      "z": -7,
      "name": "Rock_Sandstone_Red"
    },
    {
      "x": -14,
      "y": 26,
      "z": -7,
      "name": "Rock_Sandstone_Red"
    },
    {
      "x": -14,
      "y": 27,
      "z": -7,
      "name": "Rock_Sandstone_Red"
    },
    {
      "x": -14,
      "y": 28,
      "z": -7,
      "name": "Rock_Sandstone_Red"
    },
    {
      "x": -14,
      "y": 29,
      "z": -7,
      "name": "Rock_Sandstone_Red"
    },
    {
      "x": -14,
      "y": 30,
      "z": -7,
      "name": "Rock_Sandstone_Red"
    },
    {
      "x": -14,
      "y": 31,
      "z": -7,
      "name": "Rock_Sandstone_Red_Cobble"
    },
    {
      "x": -14,
      "y": 32,
      "z": -7,
      "name": "Soil_Sand_Red"
    },
    {
      "x": -14,
      "y": 24,
      "z": -6,
      "name": "Rock_Sandstone_Red"
    },
    {
      "x": -14,
      "y": 25,
      "z": -6,
      "name": "Rock_Sandstone_Red"
    },
    {
      "x": -14,
      "y": 26,
      "z": -6,
      "name": "Rock_Sandstone_Red"
    },
    {
      "x": -14,
      "y": 27,
      "z": -6,
      "name": "Rock_Sandstone_Red"
    },
    {
      "x": -14,
      "y": 28,
      "z": -6,
      "name": "Rock_Sandstone_Red"
    },
    {
      "x": -14,
      "y": 29,
      "z": -6,
      "name": "Rock_Sandstone_Red"
    },
    {
      "x": -14,
      "y": 30,
      "z": -6,
      "name": "Rock_Sandstone_Red"
    },
    {
      "x": -14,
      "y": 31,
      "z": -6,
      "name": "Rock_Sandstone_Red"
    },
    {
      "x": -14,
      "y": 32,
      "z": -6,
      "name": "Soil_Sand_Red"
    },
    {
      "x": -14,
      "y": 25,
      "z": -5,
      "name": "Rock_Sandstone_Red"
    },
    {
      "x": -14,
      "y": 26,
      "z": -5,
      "name": "Rock_Sandstone_Red"
    },
    {
      "x": -14,
      "y": 27,
      "z": -5,
      "name": "Rock_Sandstone_Red"
    },
    {
      "x": -14,
      "y": 28,
      "z": -5,
      "name": "Rock_Sandstone_Red"
    },
    {
      "x": -14,
      "y": 29,
      "z": -5,
      "name": "Rock_Sandstone_Red"
    },
    {
      "x": -14,
      "y": 30,
      "z": -5,
      "name": "Rock_Sandstone_Red"
    },
    {
      "x": -14,
      "y": 31,
      "z": -5,
      "name": "Rock_Sandstone_Red"
    },
    {
      "x": -14,
      "y": 32,
      "z": -5,
      "name": "Rock_Sandstone_Red"
    },
    {
      "x": -14,
      "y": 33,
      "z": -5,
      "name": "Soil_Sand_Red"
    },
    {
      "x": -14,
      "y": 26,
      "z": -4,
      "name": "Rock_Sandstone_Red"
    },
    {
      "x": -14,
      "y": 27,
      "z": -4,
      "name": "Rock_Sandstone_Red"
    },
    {
      "x": -14,
      "y": 28,
      "z": -4,
      "name": "Rock_Sandstone_Red"
    },
    {
      "x": -14,
      "y": 29,
      "z": -4,
      "name": "Rock_Sandstone_Red"
    },
    {
      "x": -14,
      "y": 30,
      "z": -4,
      "name": "Rock_Sandstone_Red"
    },
    {
      "x": -14,
      "y": 31,
      "z": -4,
      "name": "Rock_Sandstone_Red"
    },
    {
      "x": -14,
      "y": 32,
      "z": -4,
      "name": "Soil_Sand_Red"
    },
    {
      "x": -14,
      "y": 33,
      "z": -4,
      "name": "Rock_Sandstone_Red_Cobble"
    },
    {
      "x": -14,
      "y": 34,
      "z": -4,
      "name": "Plant_Crop_Mushroom_Glowing_Red"
    },
    {
      "x": -14,
      "y": 26,
      "z": -3,
      "name": "Rock_Sandstone_Red"
    },
    {
      "x": -14,
      "y": 27,
      "z": -3,
      "name": "Rock_Sandstone_Red"
    },
    {
      "x": -14,
      "y": 28,
      "z": -3,
      "name": "Rock_Sandstone_Red"
    },
    {
      "x": -14,
      "y": 29,
      "z": -3,
      "name": "Rock_Sandstone_Red"
    },
    {
      "x": -14,
      "y": 30,
      "z": -3,
      "name": "Rock_Sandstone_Red"
    },
    {
      "x": -14,
      "y": 31,
      "z": -3,
      "name": "Rock_Sandstone_Red"
    },
    {
      "x": -14,
      "y": 32,
      "z": -3,
      "name": "Rock_Sandstone_Red"
    },
    {
      "x": -14,
      "y": 33,
      "z": -3,
      "name": "Soil_Sand_Red"
    },
    {
      "x": -14,
      "y": 25,
      "z": -2,
      "name": "Plant_Bush_Dead_Hanging"
    },
    {
      "x": -14,
      "y": 26,
      "z": -2,
      "name": "Rock_Sandstone_Red"
    },
    {
      "x": -14,
      "y": 27,
      "z": -2,
      "name": "Rock_Sandstone_Red"
    },
    {
      "x": -14,
      "y": 28,
      "z": -2,
      "name": "Rock_Sandstone_Red"
    },
    {
      "x": -14,
      "y": 29,
      "z": -2,
      "name": "Rock_Sandstone_Red"
    },
    {
      "x": -14,
      "y": 30,
      "z": -2,
      "name": "Rock_Sandstone_Red"
    },
    {
      "x": -14,
      "y": 31,
      "z": -2,
      "name": "Rock_Sandstone_Red"
    },
    {
      "x": -14,
      "y": 32,
      "z": -2,
      "name": "Rock_Sandstone_Red"
    },
    {
      "x": -14,
      "y": 33,
      "z": -2,
      "name": "Soil_Sand_Red"
    },
    {
      "x": -14,
      "y": 27,
      "z": -1,
      "name": "Rock_Sandstone_Red"
    },
    {
      "x": -14,
      "y": 28,
      "z": -1,
      "name": "Rock_Sandstone_Red"
    },
    {
      "x": -14,
      "y": 29,
      "z": -1,
      "name": "Rock_Sandstone_Red"
    },
    {
      "x": -14,
      "y": 30,
      "z": -1,
      "name": "Rock_Sandstone_Red"
    },
    {
      "x": -14,
      "y": 31,
      "z": -1,
      "name": "Rock_Sandstone_Red"
    },
    {
      "x": -14,
      "y": 32,
      "z": -1,
      "name": "Rock_Sandstone_Red"
    },
    {
      "x": -14,
      "y": 33,
      "z": -1,
      "name": "Soil_Sand_Red"
    },
    {
      "x": -14,
      "y": 28,
      "z": 0,
      "name": "Rock_Sandstone_Red"
    },
    {
      "x": -14,
      "y": 29,
      "z": 0,
      "name": "Rock_Sandstone_Red"
    },
    {
      "x": -14,
      "y": 30,
      "z": 0,
      "name": "Rock_Sandstone_Red"
    },
    {
      "x": -14,
      "y": 31,
      "z": 0,
      "name": "Rock_Sandstone_Red"
    },
    {
      "x": -14,
      "y": 32,
      "z": 0,
      "name": "Soil_Sand_Red"
    },
    {
      "x": -14,
      "y": 33,
      "z": 0,
      "name": "Rock_Sandstone_Red_Cobble"
    },
    {
      "x": -14,
      "y": 30,
      "z": 1,
      "name": "Rock_Sandstone_Red"
    },
    {
      "x": -14,
      "y": 31,
      "z": 1,
      "name": "Rock_Sandstone_Red"
    },
    {
      "x": -14,
      "y": 32,
      "z": 1,
      "name": "Soil_Sand_Red"
    },
    {
      "x": -13,
      "y": 23,
      "z": -17,
      "name": "Rock_Sandstone_Red"
    },
    {
      "x": -13,
      "y": 24,
      "z": -17,
      "name": "Rock_Sandstone_Red"
    },
    {
      "x": -13,
      "y": 25,
      "z": -17,
      "name": "Rock_Sandstone_Red"
    },
    {
      "x": -13,
      "y": 26,
      "z": -17,
      "name": "Rock_Sandstone_Red"
    },
    {
      "x": -13,
      "y": 27,
      "z": -17,
      "name": "Rubble_Sandstone_Red_Medium"
    },
    {
      "x": -13,
      "y": 21,
      "z": -16,
      "name": "Rock_Sandstone_Red"
    },
    {
      "x": -13,
      "y": 22,
      "z": -16,
      "name": "Rock_Sandstone_Red"
    },
    {
      "x": -13,
      "y": 23,
      "z": -16,
      "name": "Rock_Sandstone_Red"
    },
    {
      "x": -13,
      "y": 24,
      "z": -16,
      "name": "Rock_Sandstone_Red"
    },
    {
      "x": -13,
      "y": 25,
      "z": -16,
      "name": "Rock_Sandstone_Red"
    },
    {
      "x": -13,
      "y": 26,
      "z": -16,
      "name": "Rock_Sandstone_Red"
    },
    {
      "x": -13,
      "y": 27,
      "z": -16,
      "name": "Soil_Gravel_Sand_Red"
    },
    {
      "x": -13,
      "y": 28,
      "z": -16,
      "name": "Soil_Sand_Red"
    },
    {
      "x": -13,
      "y": 20,
      "z": -15,
      "name": "Rock_Sandstone_Red"
    },
    {
      "x": -13,
      "y": 21,
      "z": -15,
      "name": "Rock_Sandstone_Red"
    },
    {
      "x": -13,
      "y": 22,
      "z": -15,
      "name": "Rock_Sandstone_Red"
    },
    {
      "x": -13,
      "y": 23,
      "z": -15,
      "name": "Rock_Sandstone_Red"
    },
    {
      "x": -13,
      "y": 24,
      "z": -15,
      "name": "Rock_Sandstone_Red"
    },
    {
      "x": -13,
      "y": 25,
      "z": -15,
      "name": "Rock_Sandstone_Red"
    },
    {
      "x": -13,
      "y": 26,
      "z": -15,
      "name": "Rock_Sandstone_Red"
    },
    {
      "x": -13,
      "y": 27,
      "z": -15,
      "name": "Rock_Sandstone_Red"
    },
    {
      "x": -13,
      "y": 28,
      "z": -15,
      "name": "Soil_Sand_Red"
    },
    {
      "x": -13,
      "y": 29,
      "z": -15,
      "name": "Soil_Sand_Red"
    },
    {
      "x": -13,
      "y": 19,
      "z": -14,
      "name": "Rock_Sandstone_Red"
    },
    {
      "x": -13,
      "y": 20,
      "z": -14,
      "name": "Rock_Sandstone_Red"
    },
    {
      "x": -13,
      "y": 21,
      "z": -14,
      "name": "Rock_Sandstone_Red"
    },
    {
      "x": -13,
      "y": 22,
      "z": -14,
      "name": "Rock_Sandstone_Red"
    },
    {
      "x": -13,
      "y": 23,
      "z": -14,
      "name": "Rock_Sandstone_Red"
    },
    {
      "x": -13,
      "y": 24,
      "z": -14,
      "name": "Rock_Sandstone_Red"
    },
    {
      "x": -13,
      "y": 25,
      "z": -14,
      "name": "Rock_Sandstone_Red"
    },
    {
      "x": -13,
      "y": 26,
      "z": -14,
      "name": "Rock_Sandstone_Red"
    },
    {
      "x": -13,
      "y": 27,
      "z": -14,
      "name": "Rock_Sandstone_Red"
    },
    {
      "x": -13,
      "y": 28,
      "z": -14,
      "name": "Soil_Sand_Red"
    },
    {
      "x": -13,
      "y": 29,
      "z": -14,
      "name": "Soil_Sand_Red"
    },
    {
      "x": -13,
      "y": 17,
      "z": -13,
      "name": "Rock_Crystal_Red_Medium",
      "rotation": 6
    },
    {
      "x": -13,
      "y": 18,
      "z": -13,
      "name": "Rock_Crystal_Red_Medium",
      "rotation": 6
    },
    {
      "x": -13,
      "y": 19,
      "z": -13,
      "name": "Rock_Sandstone_Red"
    },
    {
      "x": -13,
      "y": 20,
      "z": -13,
      "name": "Rock_Sandstone_Red"
    },
    {
      "x": -13,
      "y": 21,
      "z": -13,
      "name": "Rock_Sandstone_Red"
    },
    {
      "x": -13,
      "y": 22,
      "z": -13,
      "name": "Rock_Sandstone_Red"
    },
    {
      "x": -13,
      "y": 23,
      "z": -13,
      "name": "Rock_Sandstone_Red"
    },
    {
      "x": -13,
      "y": 24,
      "z": -13,
      "name": "Rock_Sandstone_Red"
    },
    {
      "x": -13,
      "y": 25,
      "z": -13,
      "name": "Rock_Sandstone_Red"
    },
    {
      "x": -13,
      "y": 26,
      "z": -13,
      "name": "Rock_Sandstone_Red"
    },
    {
      "x": -13,
      "y": 27,
      "z": -13,
      "name": "Rock_Sandstone_Red"
    },
    {
      "x": -13,
      "y": 28,
      "z": -13,
      "name": "Rock_Sandstone_Red_Cobble"
    },
    {
      "x": -13,
      "y": 29,
      "z": -13,
      "name": "Soil_Sand_Red"
    },
    {
      "x": -13,
      "y": 30,
      "z": -13,
      "name": "Soil_Gravel_Sand_Red"
    },
    {
      "x": -13,
      "y": 16,
      "z": -12,
      "name": "Rock_Crystal_Red_Medium",
      "rotation": 8
    },
    {
      "x": -13,
      "y": 17,
      "z": -12,
      "name": "Rock_Crystal_Red_Block"
    },
    {
      "x": -13,
      "y": 18,
      "z": -12,
      "name": "Rock_Crystal_Red_Block"
    },
    {
      "x": -13,
      "y": 19,
      "z": -12,
      "name": "Rock_Crystal_Red_Block"
    },
    {
      "x": -13,
      "y": 20,
      "z": -12,
      "name": "Rock_Crystal_Red_Block"
    },
    {
      "x": -13,
      "y": 21,
      "z": -12,
      "name": "Rock_Crystal_Red_Block"
    },
    {
      "x": -13,
      "y": 22,
      "z": -12,
      "name": "Rock_Crystal_Red_Block"
    },
    {
      "x": -13,
      "y": 23,
      "z": -12,
      "name": "Rock_Sandstone_Red"
    },
    {
      "x": -13,
      "y": 24,
      "z": -12,
      "name": "Ore_Gold_Sandstone"
    },
    {
      "x": -13,
      "y": 25,
      "z": -12,
      "name": "Rock_Sandstone_Red"
    },
    {
      "x": -13,
      "y": 26,
      "z": -12,
      "name": "Rock_Sandstone_Red"
    },
    {
      "x": -13,
      "y": 27,
      "z": -12,
      "name": "Rock_Sandstone_Red"
    },
    {
      "x": -13,
      "y": 28,
      "z": -12,
      "name": "Soil_Sand_Red"
    },
    {
      "x": -13,
      "y": 29,
      "z": -12,
      "name": "Soil_Sand_Red"
    },
    {
      "x": -13,
      "y": 30,
      "z": -12,
      "name": "Soil_Sand_Red"
    },
    {
      "x": -13,
      "y": 19,
      "z": -11,
      "name": "Rock_Crystal_Red_Medium",
      "rotation": 4
    },
    {
      "x": -13,
      "y": 20,
      "z": -11,
      "name": "Rock_Sandstone_Red"
    },
    {
      "x": -13,
      "y": 21,
      "z": -11,
      "name": "Rock_Sandstone_Red"
    },
    {
      "x": -13,
      "y": 22,
      "z": -11,
      "name": "Rock_Sandstone_Red"
    },
    {
      "x": -13,
      "y": 23,
      "z": -11,
      "name": "Rock_Sandstone_Red"
    },
    {
      "x": -13,
      "y": 24,
      "z": -11,
      "name": "Rock_Sandstone_Red"
    },
    {
      "x": -13,
      "y": 25,
      "z": -11,
      "name": "Rock_Sandstone_Red"
    },
    {
      "x": -13,
      "y": 26,
      "z": -11,
      "name": "Rock_Sandstone_Red"
    },
    {
      "x": -13,
      "y": 27,
      "z": -11,
      "name": "Rock_Sandstone_Red"
    },
    {
      "x": -13,
      "y": 28,
      "z": -11,
      "name": "Rock_Sandstone_Red"
    },
    {
      "x": -13,
      "y": 29,
      "z": -11,
      "name": "Soil_Sand_Red"
    },
    {
      "x": -13,
      "y": 30,
      "z": -11,
      "name": "Rock_Sandstone_Red_Cobble"
    },
    {
      "x": -13,
      "y": 31,
      "z": -11,
      "name": "Soil_Sand_Red"
    },
    {
      "x": -13,
      "y": 20,
      "z": -10,
      "name": "Plant_Moss_Cave_Red"
    },
    {
      "x": -13,
      "y": 21,
      "z": -10,
      "name": "Rock_Sandstone_Red"
    },
    {
      "x": -13,
      "y": 22,
      "z": -10,
      "name": "Rock_Sandstone_Red"
    },
    {
      "x": -13,
      "y": 23,
      "z": -10,
      "name": "Rock_Sandstone_Red"
    },
    {
      "x": -13,
      "y": 24,
      "z": -10,
      "name": "Rock_Sandstone_Red"
    },
    {
      "x": -13,
      "y": 25,
      "z": -10,
      "name": "Rock_Sandstone_Red"
    },
    {
      "x": -13,
      "y": 26,
      "z": -10,
      "name": "Rock_Sandstone_Red"
    },
    {
      "x": -13,
      "y": 27,
      "z": -10,
      "name": "Rock_Sandstone_Red"
    },
    {
      "x": -13,
      "y": 28,
      "z": -10,
      "name": "Rock_Sandstone_Red"
    },
    {
      "x": -13,
      "y": 29,
      "z": -10,
      "name": "Soil_Sand_Red"
    },
    {
      "x": -13,
      "y": 30,
      "z": -10,
      "name": "Soil_Sand_Red"
    },
    {
      "x": -13,
      "y": 31,
      "z": -10,
      "name": "Soil_Sand_Red"
    },
    {
      "x": -13,
      "y": 21,
      "z": -9,
      "name": "Plant_Moss_Cave_Red"
    },
    {
      "x": -13,
      "y": 22,
      "z": -9,
      "name": "Rock_Sandstone_Red"
    },
    {
      "x": -13,
      "y": 23,
      "z": -9,
      "name": "Rock_Sandstone_Red"
    },
    {
      "x": -13,
      "y": 24,
      "z": -9,
      "name": "Rock_Sandstone_Red"
    },
    {
      "x": -13,
      "y": 25,
      "z": -9,
      "name": "Rock_Sandstone_Red"
    },
    {
      "x": -13,
      "y": 26,
      "z": -9,
      "name": "Rock_Sandstone_Red"
    },
    {
      "x": -13,
      "y": 27,
      "z": -9,
      "name": "Rock_Sandstone_Red"
    },
    {
      "x": -13,
      "y": 28,
      "z": -9,
      "name": "Rock_Sandstone_Red"
    },
    {
      "x": -13,
      "y": 29,
      "z": -9,
      "name": "Rock_Sandstone_Red"
    },
    {
      "x": -13,
      "y": 30,
      "z": -9,
      "name": "Soil_Sand_Red"
    },
    {
      "x": -13,
      "y": 31,
      "z": -9,
      "name": "Soil_Sand_Red"
    },
    {
      "x": -13,
      "y": 22,
      "z": -8,
      "name": "Rock_Sandstone_Red"
    },
    {
      "x": -13,
      "y": 23,
      "z": -8,
      "name": "Rock_Sandstone_Red"
    },
    {
      "x": -13,
      "y": 24,
      "z": -8,
      "name": "Rock_Sandstone_Red"
    },
    {
      "x": -13,
      "y": 25,
      "z": -8,
      "name": "Rock_Sandstone_Red"
    },
    {
      "x": -13,
      "y": 26,
      "z": -8,
      "name": "Rock_Sandstone_Red"
    },
    {
      "x": -13,
      "y": 27,
      "z": -8,
      "name": "Rock_Sandstone_Red"
    },
    {
      "x": -13,
      "y": 28,
      "z": -8,
      "name": "Rock_Sandstone_Red"
    },
    {
      "x": -13,
      "y": 29,
      "z": -8,
      "name": "Rock_Sandstone_Red"
    },
    {
      "x": -13,
      "y": 30,
      "z": -8,
      "name": "Rock_Sandstone_Red"
    },
    {
      "x": -13,
      "y": 31,
      "z": -8,
      "name": "Soil_Gravel_Sand_Red"
    },
    {
      "x": -13,
      "y": 32,
      "z": -8,
      "name": "Soil_Sand_Red"
    },
    {
      "x": -13,
      "y": 21,
      "z": -7,
      "name": "Plant_Moss_Cave_Red"
    },
    {
      "x": -13,
      "y": 22,
      "z": -7,
      "name": "Rock_Sandstone_Red"
    },
    {
      "x": -13,
      "y": 23,
      "z": -7,
      "name": "Rock_Sandstone_Red"
    },
    {
      "x": -13,
      "y": 24,
      "z": -7,
      "name": "Rock_Sandstone_Red"
    },
    {
      "x": -13,
      "y": 25,
      "z": -7,
      "name": "Rock_Sandstone_Red"
    },
    {
      "x": -13,
      "y": 26,
      "z": -7,
      "name": "Rock_Sandstone_Red"
    },
    {
      "x": -13,
      "y": 27,
      "z": -7,
      "name": "Rock_Sandstone_Red"
    },
    {
      "x": -13,
      "y": 28,
      "z": -7,
      "name": "Rock_Sandstone_Red"
    },
    {
      "x": -13,
      "y": 29,
      "z": -7,
      "name": "Rock_Sandstone_Red"
    },
    {
      "x": -13,
      "y": 30,
      "z": -7,
      "name": "Rock_Sandstone_Red"
    },
    {
      "x": -13,
      "y": 31,
      "z": -7,
      "name": "Rock_Sandstone_Red"
    },
    {
      "x": -13,
      "y": 32,
      "z": -7,
      "name": "Soil_Gravel_Sand_Red"
    },
    {
      "x": -13,
      "y": 23,
      "z": -6,
      "name": "Rock_Sandstone_Red"
    },
    {
      "x": -13,
      "y": 24,
      "z": -6,
      "name": "Rock_Sandstone_Red"
    },
    {
      "x": -13,
      "y": 25,
      "z": -6,
      "name": "Rock_Sandstone_Red"
    },
    {
      "x": -13,
      "y": 26,
      "z": -6,
      "name": "Rock_Sandstone_Red"
    },
    {
      "x": -13,
      "y": 27,
      "z": -6,
      "name": "Rock_Sandstone_Red"
    },
    {
      "x": -13,
      "y": 28,
      "z": -6,
      "name": "Rock_Sandstone_Red"
    },
    {
      "x": -13,
      "y": 29,
      "z": -6,
      "name": "Rock_Sandstone_Red"
    },
    {
      "x": -13,
      "y": 30,
      "z": -6,
      "name": "Rock_Sandstone_Red"
    },
    {
      "x": -13,
      "y": 31,
      "z": -6,
      "name": "Soil_Sand_Red"
    },
    {
      "x": -13,
      "y": 32,
      "z": -6,
      "name": "Soil_Sand_Red"
    },
    {
      "x": -13,
      "y": 33,
      "z": -6,
      "name": "Soil_Sand_Red"
    },
    {
      "x": -13,
      "y": 24,
      "z": -5,
      "name": "Rock_Sandstone_Red"
    },
    {
      "x": -13,
      "y": 25,
      "z": -5,
      "name": "Rock_Sandstone_Red"
    },
    {
      "x": -13,
      "y": 26,
      "z": -5,
      "name": "Rock_Sandstone_Red"
    },
    {
      "x": -13,
      "y": 27,
      "z": -5,
      "name": "Rock_Sandstone_Red"
    },
    {
      "x": -13,
      "y": 28,
      "z": -5,
      "name": "Rock_Sandstone_Red"
    },
    {
      "x": -13,
      "y": 29,
      "z": -5,
      "name": "Rock_Sandstone_Red"
    },
    {
      "x": -13,
      "y": 30,
      "z": -5,
      "name": "Rock_Sandstone_Red"
    },
    {
      "x": -13,
      "y": 31,
      "z": -5,
      "name": "Rock_Sandstone_Red"
    },
    {
      "x": -13,
      "y": 32,
      "z": -5,
      "name": "Rock_Sandstone_Red"
    },
    {
      "x": -13,
      "y": 33,
      "z": -5,
      "name": "Rock_Sandstone_Red"
    },
    {
      "x": -13,
      "y": 25,
      "z": -4,
      "name": "Rock_Sandstone_Red"
    },
    {
      "x": -13,
      "y": 26,
      "z": -4,
      "name": "Rock_Sandstone_Red"
    },
    {
      "x": -13,
      "y": 27,
      "z": -4,
      "name": "Rock_Sandstone_Red"
    },
    {
      "x": -13,
      "y": 28,
      "z": -4,
      "name": "Rock_Sandstone_Red"
    },
    {
      "x": -13,
      "y": 29,
      "z": -4,
      "name": "Rock_Sandstone_Red"
    },
    {
      "x": -13,
      "y": 30,
      "z": -4,
      "name": "Rock_Sandstone_Red"
    },
    {
      "x": -13,
      "y": 31,
      "z": -4,
      "name": "Rock_Sandstone_Red"
    },
    {
      "x": -13,
      "y": 32,
      "z": -4,
      "name": "Rock_Sandstone_Red"
    },
    {
      "x": -13,
      "y": 33,
      "z": -4,
      "name": "Soil_Sand_Red"
    },
    {
      "x": -13,
      "y": 34,
      "z": -4,
      "name": "Soil_Sand_Red"
    },
    {
      "x": -13,
      "y": 35,
      "z": -4,
      "name": "Plant_Flower_Bushy_Red"
    },
    {
      "x": -13,
      "y": 25,
      "z": -3,
      "name": "Rock_Sandstone_Red"
    },
    {
      "x": -13,
      "y": 26,
      "z": -3,
      "name": "Rock_Sandstone_Red"
    },
    {
      "x": -13,
      "y": 27,
      "z": -3,
      "name": "Rock_Sandstone_Red"
    },
    {
      "x": -13,
      "y": 28,
      "z": -3,
      "name": "Rock_Sandstone_Red"
    },
    {
      "x": -13,
      "y": 29,
      "z": -3,
      "name": "Rock_Sandstone_Red"
    },
    {
      "x": -13,
      "y": 30,
      "z": -3,
      "name": "Rock_Sandstone_Red"
    },
    {
      "x": -13,
      "y": 31,
      "z": -3,
      "name": "Rock_Sandstone_Red"
    },
    {
      "x": -13,
      "y": 32,
      "z": -3,
      "name": "Rock_Sandstone_Red"
    },
    {
      "x": -13,
      "y": 33,
      "z": -3,
      "name": "Rock_Sandstone_Red"
    },
    {
      "x": -13,
      "y": 34,
      "z": -3,
      "name": "Rock_Sandstone_Red"
    },
    {
      "x": -13,
      "y": 35,
      "z": -3,
      "name": "Rubble_Sandstone_Red"
    },
    {
      "x": -13,
      "y": 25,
      "z": -2,
      "name": "Rock_Sandstone_Red"
    },
    {
      "x": -13,
      "y": 26,
      "z": -2,
      "name": "Rock_Sandstone_Red"
    },
    {
      "x": -13,
      "y": 27,
      "z": -2,
      "name": "Rock_Sandstone_Red"
    },
    {
      "x": -13,
      "y": 28,
      "z": -2,
      "name": "Rock_Sandstone_Red"
    },
    {
      "x": -13,
      "y": 29,
      "z": -2,
      "name": "Rock_Sandstone_Red"
    },
    {
      "x": -13,
      "y": 30,
      "z": -2,
      "name": "Rock_Sandstone_Red"
    },
    {
      "x": -13,
      "y": 31,
      "z": -2,
      "name": "Rock_Sandstone_Red"
    },
    {
      "x": -13,
      "y": 32,
      "z": -2,
      "name": "Rock_Sandstone_Red"
    },
    {
      "x": -13,
      "y": 33,
      "z": -2,
      "name": "Rock_Sandstone_Red"
    },
    {
      "x": -13,
      "y": 34,
      "z": -2,
      "name": "Soil_Sand_Red"
    },
    {
      "x": -13,
      "y": 26,
      "z": -1,
      "name": "Rock_Sandstone_Red"
    },
    {
      "x": -13,
      "y": 27,
      "z": -1,
      "name": "Rock_Sandstone_Red"
    },
    {
      "x": -13,
      "y": 28,
      "z": -1,
      "name": "Rock_Sandstone_Red"
    },
    {
      "x": -13,
      "y": 29,
      "z": -1,
      "name": "Rock_Sandstone_Red"
    },
    {
      "x": -13,
      "y": 30,
      "z": -1,
      "name": "Rock_Sandstone_Red"
    },
    {
      "x": -13,
      "y": 31,
      "z": -1,
      "name": "Rock_Sandstone_Red"
    },
    {
      "x": -13,
      "y": 32,
      "z": -1,
      "name": "Rock_Sandstone_Red"
    },
    {
      "x": -13,
      "y": 33,
      "z": -1,
      "name": "Soil_Sand_Red"
    },
    {
      "x": -13,
      "y": 34,
      "z": -1,
      "name": "Soil_Sand_Red"
    },
    {
      "x": -13,
      "y": 27,
      "z": 0,
      "name": "Rock_Sandstone_Red"
    },
    {
      "x": -13,
      "y": 28,
      "z": 0,
      "name": "Rock_Sandstone_Red"
    },
    {
      "x": -13,
      "y": 29,
      "z": 0,
      "name": "Rock_Sandstone_Red"
    },
    {
      "x": -13,
      "y": 30,
      "z": 0,
      "name": "Rock_Sandstone_Red"
    },
    {
      "x": -13,
      "y": 31,
      "z": 0,
      "name": "Rock_Sandstone_Red"
    },
    {
      "x": -13,
      "y": 32,
      "z": 0,
      "name": "Rock_Sandstone_Red"
    },
    {
      "x": -13,
      "y": 33,
      "z": 0,
      "name": "Rock_Sandstone_Red_Cobble"
    },
    {
      "x": -13,
      "y": 34,
      "z": 0,
      "name": "Soil_Sand_Red"
    },
    {
      "x": -13,
      "y": 27,
      "z": 1,
      "name": "Rock_Sandstone_Red"
    },
    {
      "x": -13,
      "y": 28,
      "z": 1,
      "name": "Rock_Sandstone_Red"
    },
    {
      "x": -13,
      "y": 29,
      "z": 1,
      "name": "Rock_Sandstone_Red"
    },
    {
      "x": -13,
      "y": 30,
      "z": 1,
      "name": "Rock_Sandstone_Red"
    },
    {
      "x": -13,
      "y": 31,
      "z": 1,
      "name": "Rock_Sandstone_Red"
    },
    {
      "x": -13,
      "y": 32,
      "z": 1,
      "name": "Soil_Sand_Red"
    },
    {
      "x": -13,
      "y": 33,
      "z": 1,
      "name": "Soil_Sand_Red"
    },
    {
      "x": -13,
      "y": 28,
      "z": 2,
      "name": "Rock_Sandstone_Red"
    },
    {
      "x": -13,
      "y": 29,
      "z": 2,
      "name": "Rock_Sandstone_Red"
    },
    {
      "x": -13,
      "y": 30,
      "z": 2,
      "name": "Rock_Sandstone_Red"
    },
    {
      "x": -13,
      "y": 31,
      "z": 2,
      "name": "Rock_Sandstone_Red"
    },
    {
      "x": -13,
      "y": 32,
      "z": 2,
      "name": "Soil_Sand_Red"
    },
    {
      "x": -13,
      "y": 33,
      "z": 2,
      "name": "Soil_Sand_Red"
    },
    {
      "x": -13,
      "y": 34,
      "z": 2,
      "name": "Plant_Bush_Crystal"
    },
    {
      "x": -13,
      "y": 29,
      "z": 3,
      "name": "Rock_Sandstone_Red"
    },
    {
      "x": -13,
      "y": 30,
      "z": 3,
      "name": "Rock_Sandstone_Red"
    },
    {
      "x": -13,
      "y": 31,
      "z": 3,
      "name": "Rock_Sandstone_Red"
    },
    {
      "x": -13,
      "y": 32,
      "z": 3,
      "name": "Soil_Sand_Red"
    },
    {
      "x": -13,
      "y": 33,
      "z": 3,
      "name": "Rock_Sandstone_Red_Cobble"
    },
    {
      "x": -13,
      "y": 30,
      "z": 4,
      "name": "Rock_Sandstone_Red"
    },
    {
      "x": -13,
      "y": 31,
      "z": 4,
      "name": "Rock_Sandstone_Red"
    },
    {
      "x": -13,
      "y": 32,
      "z": 4,
      "name": "Rock_Sandstone_Red"
    },
    {
      "x": -13,
      "y": 33,
      "z": 4,
      "name": "Soil_Gravel_Sand_Red"
    },
    {
      "x": -13,
      "y": 32,
      "z": 5,
      "name": "Soil_Sand_Red"
    },
    {
      "x": -13,
      "y": 33,
      "z": 5,
      "name": "Soil_Sand_Red"
    },
    {
      "x": -12,
      "y": 22,
      "z": -17,
      "name": "Rock_Sandstone_Red"
    },
    {
      "x": -12,
      "y": 23,
      "z": -17,
      "name": "Rock_Sandstone_Red"
    },
    {
      "x": -12,
      "y": 24,
      "z": -17,
      "name": "Rock_Sandstone_Red"
    },
    {
      "x": -12,
      "y": 25,
      "z": -17,
      "name": "Rock_Sandstone_Red"
    },
    {
      "x": -12,
      "y": 26,
      "z": -17,
      "name": "Rock_Sandstone_Red"
    },
    {
      "x": -12,
      "y": 27,
      "z": -17,
      "name": "Rock_Sandstone_Red"
    },
    {
      "x": -12,
      "y": 28,
      "z": -17,
      "name": "Rock_Sandstone_Red"
    },
    {
      "x": -12,
      "y": 21,
      "z": -16,
      "name": "Rock_Sandstone_Red"
    },
    {
      "x": -12,
      "y": 22,
      "z": -16,
      "name": "Rock_Sandstone_Red"
    },
    {
      "x": -12,
      "y": 23,
      "z": -16,
      "name": "Rock_Sandstone_Red"
    },
    {
      "x": -12,
      "y": 24,
      "z": -16,
      "name": "Rock_Sandstone_Red"
    },
    {
      "x": -12,
      "y": 25,
      "z": -16,
      "name": "Rock_Sandstone_Red"
    },
    {
      "x": -12,
      "y": 26,
      "z": -16,
      "name": "Rock_Sandstone_Red"
    },
    {
      "x": -12,
      "y": 27,
      "z": -16,
      "name": "Soil_Sand_Red"
    },
    {
      "x": -12,
      "y": 28,
      "z": -16,
      "name": "Rock_Sandstone_Red_Cobble"
    },
    {
      "x": -12,
      "y": 20,
      "z": -15,
      "name": "Rock_Sandstone_Red"
    },
    {
      "x": -12,
      "y": 21,
      "z": -15,
      "name": "Rock_Sandstone_Red"
    },
    {
      "x": -12,
      "y": 22,
      "z": -15,
      "name": "Rock_Sandstone_Red"
    },
    {
      "x": -12,
      "y": 23,
      "z": -15,
      "name": "Rock_Sandstone_Red"
    },
    {
      "x": -12,
      "y": 24,
      "z": -15,
      "name": "Rock_Sandstone_Red"
    },
    {
      "x": -12,
      "y": 25,
      "z": -15,
      "name": "Rock_Sandstone_Red"
    },
    {
      "x": -12,
      "y": 26,
      "z": -15,
      "name": "Rock_Sandstone_Red"
    },
    {
      "x": -12,
      "y": 27,
      "z": -15,
      "name": "Rock_Sandstone_Red"
    },
    {
      "x": -12,
      "y": 28,
      "z": -15,
      "name": "Rock_Sandstone_Red_Cobble"
    },
    {
      "x": -12,
      "y": 29,
      "z": -15,
      "name": "Soil_Sand_Red"
    },
    {
      "x": -12,
      "y": 15,
      "z": -14,
      "name": "Rock_Crystal_Red_Medium",
      "rotation": 6
    },
    {
      "x": -12,
      "y": 16,
      "z": -14,
      "name": "Rock_Crystal_Red_Medium",
      "rotation": 6
    },
    {
      "x": -12,
      "y": 17,
      "z": -14,
      "name": "Rock_Crystal_Red_Medium",
      "rotation": 6
    },
    {
      "x": -12,
      "y": 18,
      "z": -14,
      "name": "Rock_Crystal_Red_Medium",
      "rotation": 6
    },
    {
      "x": -12,
      "y": 19,
      "z": -14,
      "name": "Rock_Sandstone_Red"
    },
    {
      "x": -12,
      "y": 20,
      "z": -14,
      "name": "Rock_Sandstone_Red"
    },
    {
      "x": -12,
      "y": 21,
      "z": -14,
      "name": "Rock_Sandstone_Red"
    },
    {
      "x": -12,
      "y": 22,
      "z": -14,
      "name": "Rock_Sandstone_Red"
    },
    {
      "x": -12,
      "y": 23,
      "z": -14,
      "name": "Rock_Sandstone_Red"
    },
    {
      "x": -12,
      "y": 24,
      "z": -14,
      "name": "Rock_Sandstone_Red"
    },
    {
      "x": -12,
      "y": 25,
      "z": -14,
      "name": "Rock_Sandstone_Red"
    },
    {
      "x": -12,
      "y": 26,
      "z": -14,
      "name": "Rock_Sandstone_Red"
    },
    {
      "x": -12,
      "y": 27,
      "z": -14,
      "name": "Rock_Sandstone_Red_Cobble"
    },
    {
      "x": -12,
      "y": 28,
      "z": -14,
      "name": "Soil_Sand_Red"
    },
    {
      "x": -12,
      "y": 29,
      "z": -14,
      "name": "Rock_Sandstone_Red_Cobble"
    },
    {
      "x": -12,
      "y": 14,
      "z": -13,
      "name": "Rock_Crystal_Red_Large",
      "rotation": 8
    },
    {
      "x": -12,
      "y": 15,
      "z": -13,
      "name": "Rock_Crystal_Red_Block"
    },
    {
      "x": -12,
      "y": 16,
      "z": -13,
      "name": "Rock_Crystal_Red_Block"
    },
    {
      "x": -12,
      "y": 17,
      "z": -13,
      "name": "Rock_Crystal_Red_Block"
    },
    {
      "x": -12,
      "y": 18,
      "z": -13,
      "name": "Rock_Crystal_Red_Block"
    },
    {
      "x": -12,
      "y": 19,
      "z": -13,
      "name": "Rock_Crystal_Red_Block"
    },
    {
      "x": -12,
      "y": 20,
      "z": -13,
      "name": "Rock_Crystal_Red_Block"
    },
    {
      "x": -12,
      "y": 21,
      "z": -13,
      "name": "Rock_Crystal_Red_Block"
    },
    {
      "x": -12,
      "y": 22,
      "z": -13,
      "name": "Rock_Crystal_Red_Block"
    },
    {
      "x": -12,
      "y": 23,
      "z": -13,
      "name": "Rock_Sandstone_Red"
    },
    {
      "x": -12,
      "y": 24,
      "z": -13,
      "name": "Rock_Sandstone_Red"
    },
    {
      "x": -12,
      "y": 25,
      "z": -13,
      "name": "Rock_Sandstone_Red"
    },
    {
      "x": -12,
      "y": 26,
      "z": -13,
      "name": "Rock_Sandstone_Red"
    },
    {
      "x": -12,
      "y": 27,
      "z": -13,
      "name": "Rock_Sandstone_Red"
    },
    {
      "x": -12,
      "y": 28,
      "z": -13,
      "name": "Rock_Sandstone_Red"
    },
    {
      "x": -12,
      "y": 29,
      "z": -13,
      "name": "Rock_Sandstone_Red"
    },
    {
      "x": -12,
      "y": 30,
      "z": -13,
      "name": "Rock_Sandstone_Red"
    },
    {
      "x": -12,
      "y": 31,
      "z": -13,
      "name": "Rubble_Sandstone_Red_Medium"
    },
    {
      "x": -12,
      "y": 15,
      "z": -12,
      "name": "Rock_Crystal_Red_Large",
      "rotation": 8
    },
    {
      "x": -12,
      "y": 16,
      "z": -12,
      "name": "Rock_Crystal_Red_Block"
    },
    {
      "x": -12,
      "y": 17,
      "z": -12,
      "name": "Rock_Crystal_Red_Block"
    },
    {
      "x": -12,
      "y": 18,
      "z": -12,
      "name": "Rock_Crystal_Red_Block"
    },
    {
      "x": -12,
      "y": 19,
      "z": -12,
      "name": "Rock_Crystal_Red_Block"
    },
    {
      "x": -12,
      "y": 20,
      "z": -12,
      "name": "Rock_Crystal_Red_Block"
    },
    {
      "x": -12,
      "y": 21,
      "z": -12,
      "name": "Rock_Crystal_Red_Block"
    },
    {
      "x": -12,
      "y": 22,
      "z": -12,
      "name": "Rock_Crystal_Red_Block"
    },
    {
      "x": -12,
      "y": 23,
      "z": -12,
      "name": "Rock_Sandstone_Red"
    },
    {
      "x": -12,
      "y": 24,
      "z": -12,
      "name": "Ore_Gold_Sandstone"
    },
    {
      "x": -12,
      "y": 25,
      "z": -12,
      "name": "Rock_Sandstone_Red"
    },
    {
      "x": -12,
      "y": 26,
      "z": -12,
      "name": "Rock_Sandstone_Red"
    },
    {
      "x": -12,
      "y": 27,
      "z": -12,
      "name": "Rock_Sandstone_Red"
    },
    {
      "x": -12,
      "y": 28,
      "z": -12,
      "name": "Rock_Sandstone_Red"
    },
    {
      "x": -12,
      "y": 29,
      "z": -12,
      "name": "Rock_Sandstone_Red_Cobble"
    },
    {
      "x": -12,
      "y": 30,
      "z": -12,
      "name": "Soil_Sand_Red"
    },
    {
      "x": -12,
      "y": 16,
      "z": -11,
      "name": "Rock_Crystal_Red_Medium",
      "rotation": 4
    },
    {
      "x": -12,
      "y": 18,
      "z": -11,
      "name": "Rock_Crystal_Red_Large",
      "rotation": 8
    },
    {
      "x": -12,
      "y": 19,
      "z": -11,
      "name": "Rock_Crystal_Red_Block"
    },
    {
      "x": -12,
      "y": 20,
      "z": -11,
      "name": "Rock_Crystal_Red_Block"
    },
    {
      "x": -12,
      "y": 21,
      "z": -11,
      "name": "Rock_Crystal_Red_Block"
    },
    {
      "x": -12,
      "y": 22,
      "z": -11,
      "name": "Rock_Crystal_Red_Block"
    },
    {
      "x": -12,
      "y": 23,
      "z": -11,
      "name": "Rock_Sandstone_Red"
    },
    {
      "x": -12,
      "y": 24,
      "z": -11,
      "name": "Rock_Sandstone_Red"
    },
    {
      "x": -12,
      "y": 25,
      "z": -11,
      "name": "Rock_Sandstone_Red"
    },
    {
      "x": -12,
      "y": 26,
      "z": -11,
      "name": "Rock_Sandstone_Red"
    },
    {
      "x": -12,
      "y": 27,
      "z": -11,
      "name": "Rock_Sandstone_Red"
    },
    {
      "x": -12,
      "y": 28,
      "z": -11,
      "name": "Rock_Sandstone_Red"
    },
    {
      "x": -12,
      "y": 29,
      "z": -11,
      "name": "Rock_Sandstone_Red"
    },
    {
      "x": -12,
      "y": 30,
      "z": -11,
      "name": "Soil_Sand_Red"
    },
    {
      "x": -12,
      "y": 31,
      "z": -11,
      "name": "Soil_Sand_Red"
    },
    {
      "x": -12,
      "y": 21,
      "z": -10,
      "name": "Rock_Sandstone_Red"
    },
    {
      "x": -12,
      "y": 22,
      "z": -10,
      "name": "Rock_Sandstone_Red"
    },
    {
      "x": -12,
      "y": 23,
      "z": -10,
      "name": "Rock_Sandstone_Red"
    },
    {
      "x": -12,
      "y": 24,
      "z": -10,
      "name": "Rock_Sandstone_Red"
    },
    {
      "x": -12,
      "y": 25,
      "z": -10,
      "name": "Rock_Sandstone_Red"
    },
    {
      "x": -12,
      "y": 26,
      "z": -10,
      "name": "Rock_Sandstone_Red"
    },
    {
      "x": -12,
      "y": 27,
      "z": -10,
      "name": "Rock_Sandstone_Red"
    },
    {
      "x": -12,
      "y": 28,
      "z": -10,
      "name": "Rock_Sandstone_Red"
    },
    {
      "x": -12,
      "y": 29,
      "z": -10,
      "name": "Rock_Sandstone_Red"
    },
    {
      "x": -12,
      "y": 30,
      "z": -10,
      "name": "Soil_Sand_Red"
    },
    {
      "x": -12,
      "y": 31,
      "z": -10,
      "name": "Soil_Sand_Red"
    },
    {
      "x": -12,
      "y": 20,
      "z": -9,
      "name": "Plant_Moss_Cave_Red"
    },
    {
      "x": -12,
      "y": 21,
      "z": -9,
      "name": "Rock_Sandstone_Red"
    },
    {
      "x": -12,
      "y": 22,
      "z": -9,
      "name": "Rock_Sandstone_Red"
    },
    {
      "x": -12,
      "y": 23,
      "z": -9,
      "name": "Rock_Sandstone_Red"
    },
    {
      "x": -12,
      "y": 24,
      "z": -9,
      "name": "Rock_Sandstone_Red"
    },
    {
      "x": -12,
      "y": 25,
      "z": -9,
      "name": "Rock_Sandstone_Red"
    },
    {
      "x": -12,
      "y": 26,
      "z": -9,
      "name": "Rock_Sandstone_Red"
    },
    {
      "x": -12,
      "y": 27,
      "z": -9,
      "name": "Rock_Sandstone_Red"
    },
    {
      "x": -12,
      "y": 28,
      "z": -9,
      "name": "Rock_Sandstone_Red"
    },
    {
      "x": -12,
      "y": 29,
      "z": -9,
      "name": "Rock_Sandstone_Red"
    },
    {
      "x": -12,
      "y": 30,
      "z": -9,
      "name": "Rock_Sandstone_Red"
    },
    {
      "x": -12,
      "y": 31,
      "z": -9,
      "name": "Soil_Sand_Red"
    },
    {
      "x": -12,
      "y": 32,
      "z": -9,
      "name": "Soil_Sand_Red"
    },
    {
      "x": -12,
      "y": 19,
      "z": -8,
      "name": "Plant_Bush_Dead_Hanging"
    },
    {
      "x": -12,
      "y": 20,
      "z": -8,
      "name": "Plant_Bush_Dead_Hanging"
    },
    {
      "x": -12,
      "y": 21,
      "z": -8,
      "name": "Rock_Sandstone_Red"
    },
    {
      "x": -12,
      "y": 22,
      "z": -8,
      "name": "Rock_Sandstone_Red"
    },
    {
      "x": -12,
      "y": 23,
      "z": -8,
      "name": "Rock_Sandstone_Red"
    },
    {
      "x": -12,
      "y": 24,
      "z": -8,
      "name": "Rock_Sandstone_Red"
    },
    {
      "x": -12,
      "y": 25,
      "z": -8,
      "name": "Rock_Sandstone_Red"
    },
    {
      "x": -12,
      "y": 26,
      "z": -8,
      "name": "Rock_Sandstone_Red"
    },
    {
      "x": -12,
      "y": 27,
      "z": -8,
      "name": "Rock_Sandstone_Red"
    },
    {
      "x": -12,
      "y": 28,
      "z": -8,
      "name": "Rock_Sandstone_Red"
    },
    {
      "x": -12,
      "y": 29,
      "z": -8,
      "name": "Rock_Sandstone_Red"
    },
    {
      "x": -12,
      "y": 30,
      "z": -8,
      "name": "Rock_Sandstone_Red"
    },
    {
      "x": -12,
      "y": 31,
      "z": -8,
      "name": "Rock_Sandstone_Red"
    },
    {
      "x": -12,
      "y": 32,
      "z": -8,
      "name": "Rock_Sandstone_Red"
    },
    {
      "x": -12,
      "y": 21,
      "z": -7,
      "name": "Rock_Sandstone_Red"
    },
    {
      "x": -12,
      "y": 22,
      "z": -7,
      "name": "Rock_Sandstone_Red"
    },
    {
      "x": -12,
      "y": 23,
      "z": -7,
      "name": "Rock_Sandstone_Red"
    },
    {
      "x": -12,
      "y": 24,
      "z": -7,
      "name": "Rock_Sandstone_Red"
    },
    {
      "x": -12,
      "y": 25,
      "z": -7,
      "name": "Rock_Sandstone_Red"
    },
    {
      "x": -12,
      "y": 26,
      "z": -7,
      "name": "Rock_Sandstone_Red"
    },
    {
      "x": -12,
      "y": 27,
      "z": -7,
      "name": "Rock_Sandstone_Red"
    },
    {
      "x": -12,
      "y": 28,
      "z": -7,
      "name": "Rock_Sandstone_Red"
    },
    {
      "x": -12,
      "y": 29,
      "z": -7,
      "name": "Rock_Sandstone_Red"
    },
    {
      "x": -12,
      "y": 30,
      "z": -7,
      "name": "Rock_Sandstone_Red"
    },
    {
      "x": -12,
      "y": 31,
      "z": -7,
      "name": "Soil_Sand_Red"
    },
    {
      "x": -12,
      "y": 32,
      "z": -7,
      "name": "Rock_Sandstone_Red_Cobble"
    },
    {
      "x": -12,
      "y": 33,
      "z": -7,
      "name": "Soil_Sand_Red"
    },
    {
      "x": -12,
      "y": 22,
      "z": -6,
      "name": "Rock_Sandstone_Red"
    },
    {
      "x": -12,
      "y": 23,
      "z": -6,
      "name": "Rock_Sandstone_Red"
    },
    {
      "x": -12,
      "y": 24,
      "z": -6,
      "name": "Rock_Sandstone_Red"
    },
    {
      "x": -12,
      "y": 25,
      "z": -6,
      "name": "Rock_Sandstone_Red"
    },
    {
      "x": -12,
      "y": 26,
      "z": -6,
      "name": "Rock_Sandstone_Red"
    },
    {
      "x": -12,
      "y": 27,
      "z": -6,
      "name": "Rock_Sandstone_Red"
    },
    {
      "x": -12,
      "y": 28,
      "z": -6,
      "name": "Rock_Sandstone_Red"
    },
    {
      "x": -12,
      "y": 29,
      "z": -6,
      "name": "Rock_Sandstone_Red"
    },
    {
      "x": -12,
      "y": 30,
      "z": -6,
      "name": "Rock_Sandstone_Red"
    },
    {
      "x": -12,
      "y": 31,
      "z": -6,
      "name": "Rock_Sandstone_Red"
    },
    {
      "x": -12,
      "y": 32,
      "z": -6,
      "name": "Soil_Sand_Red"
    },
    {
      "x": -12,
      "y": 33,
      "z": -6,
      "name": "Soil_Gravel_Sand_Red"
    },
    {
      "x": -12,
      "y": 23,
      "z": -5,
      "name": "Rock_Sandstone_Red"
    },
    {
      "x": -12,
      "y": 24,
      "z": -5,
      "name": "Rock_Sandstone_Red"
    },
    {
      "x": -12,
      "y": 25,
      "z": -5,
      "name": "Rock_Sandstone_Red"
    },
    {
      "x": -12,
      "y": 26,
      "z": -5,
      "name": "Rock_Sandstone_Red"
    },
    {
      "x": -12,
      "y": 27,
      "z": -5,
      "name": "Rock_Sandstone_Red"
    },
    {
      "x": -12,
      "y": 28,
      "z": -5,
      "name": "Rock_Sandstone_Red"
    },
    {
      "x": -12,
      "y": 29,
      "z": -5,
      "name": "Rock_Sandstone_Red"
    },
    {
      "x": -12,
      "y": 30,
      "z": -5,
      "name": "Rock_Sandstone_Red"
    },
    {
      "x": -12,
      "y": 31,
      "z": -5,
      "name": "Soil_Sand_Red"
    },
    {
      "x": -12,
      "y": 32,
      "z": -5,
      "name": "Rock_Sandstone_Red_Cobble"
    },
    {
      "x": -12,
      "y": 33,
      "z": -5,
      "name": "Soil_Sand_Red"
    },
    {
      "x": -12,
      "y": 34,
      "z": -5,
      "name": "Soil_Sand_Red"
    },
    {
      "x": -12,
      "y": 35,
      "z": -5,
      "name": "Plant_Flower_Bushy_Red"
    },
    {
      "x": -12,
      "y": 24,
      "z": -4,
      "name": "Rock_Sandstone_Red"
    },
    {
      "x": -12,
      "y": 25,
      "z": -4,
      "name": "Rock_Sandstone_Red"
    },
    {
      "x": -12,
      "y": 26,
      "z": -4,
      "name": "Rock_Sandstone_Red"
    },
    {
      "x": -12,
      "y": 27,
      "z": -4,
      "name": "Rock_Sandstone_Red"
    },
    {
      "x": -12,
      "y": 28,
      "z": -4,
      "name": "Rock_Sandstone_Red"
    },
    {
      "x": -12,
      "y": 29,
      "z": -4,
      "name": "Rock_Sandstone_Red"
    },
    {
      "x": -12,
      "y": 30,
      "z": -4,
      "name": "Rock_Sandstone_Red"
    },
    {
      "x": -12,
      "y": 31,
      "z": -4,
      "name": "Rock_Sandstone_Red"
    },
    {
      "x": -12,
      "y": 32,
      "z": -4,
      "name": "Soil_Sand_Red"
    },
    {
      "x": -12,
      "y": 33,
      "z": -4,
      "name": "Soil_Sand_Red"
    },
    {
      "x": -12,
      "y": 34,
      "z": -4,
      "name": "Soil_Sand_Red"
    },
    {
      "x": -12,
      "y": 22,
      "z": -3,
      "name": "Rock_Sandstone_Red_Stalactite_Large",
      "filler": 31744,
      "rotation": 8
    },
    {
      "x": -12,
      "y": 23,
      "z": -3,
      "name": "Rock_Sandstone_Red_Stalactite_Large",
      "rotation": 8
    },
    {
      "x": -12,
      "y": 24,
      "z": -3,
      "name": "Rock_Sandstone_Red"
    },
    {
      "x": -12,
      "y": 25,
      "z": -3,
      "name": "Rock_Sandstone_Red"
    },
    {
      "x": -12,
      "y": 26,
      "z": -3,
      "name": "Rock_Sandstone_Red"
    },
    {
      "x": -12,
      "y": 27,
      "z": -3,
      "name": "Rock_Sandstone_Red"
    },
    {
      "x": -12,
      "y": 28,
      "z": -3,
      "name": "Rock_Sandstone_Red"
    },
    {
      "x": -12,
      "y": 29,
      "z": -3,
      "name": "Rock_Sandstone_Red"
    },
    {
      "x": -12,
      "y": 30,
      "z": -3,
      "name": "Rock_Sandstone_Red"
    },
    {
      "x": -12,
      "y": 31,
      "z": -3,
      "name": "Rock_Sandstone_Red"
    },
    {
      "x": -12,
      "y": 32,
      "z": -3,
      "name": "Rock_Sandstone_Red"
    },
    {
      "x": -12,
      "y": 33,
      "z": -3,
      "name": "Soil_Sand_Red"
    },
    {
      "x": -12,
      "y": 34,
      "z": -3,
      "name": "Soil_Sand_Red"
    },
    {
      "x": -12,
      "y": 24,
      "z": -2,
      "name": "Rock_Sandstone_Red"
    },
    {
      "x": -12,
      "y": 25,
      "z": -2,
      "name": "Rock_Sandstone_Red"
    },
    {
      "x": -12,
      "y": 26,
      "z": -2,
      "name": "Rock_Sandstone_Red"
    },
    {
      "x": -12,
      "y": 27,
      "z": -2,
      "name": "Rock_Sandstone_Red"
    },
    {
      "x": -12,
      "y": 28,
      "z": -2,
      "name": "Rock_Sandstone_Red"
    },
    {
      "x": -12,
      "y": 29,
      "z": -2,
      "name": "Rock_Sandstone_Red"
    },
    {
      "x": -12,
      "y": 30,
      "z": -2,
      "name": "Rock_Sandstone_Red"
    },
    {
      "x": -12,
      "y": 31,
      "z": -2,
      "name": "Rock_Sandstone_Red"
    },
    {
      "x": -12,
      "y": 32,
      "z": -2,
      "name": "Rock_Sandstone_Red"
    },
    {
      "x": -12,
      "y": 33,
      "z": -2,
      "name": "Rock_Sandstone_Red"
    },
    {
      "x": -12,
      "y": 34,
      "z": -2,
      "name": "Soil_Sand_Red"
    },
    {
      "x": -12,
      "y": 25,
      "z": -1,
      "name": "Rock_Sandstone_Red"
    },
    {
      "x": -12,
      "y": 26,
      "z": -1,
      "name": "Rock_Sandstone_Red"
    },
    {
      "x": -12,
      "y": 27,
      "z": -1,
      "name": "Rock_Sandstone_Red"
    },
    {
      "x": -12,
      "y": 28,
      "z": -1,
      "name": "Rock_Sandstone_Red"
    },
    {
      "x": -12,
      "y": 29,
      "z": -1,
      "name": "Rock_Sandstone_Red"
    },
    {
      "x": -12,
      "y": 30,
      "z": -1,
      "name": "Rock_Sandstone_Red"
    },
    {
      "x": -12,
      "y": 31,
      "z": -1,
      "name": "Rock_Sandstone_Red"
    },
    {
      "x": -12,
      "y": 32,
      "z": -1,
      "name": "Rock_Sandstone_Red_Cobble"
    },
    {
      "x": -12,
      "y": 33,
      "z": -1,
      "name": "Rock_Sandstone_Red_Cobble"
    },
    {
      "x": -12,
      "y": 34,
      "z": -1,
      "name": "Soil_Sand_Red"
    },
    {
      "x": -12,
      "y": 26,
      "z": 0,
      "name": "Rock_Sandstone_Red"
    },
    {
      "x": -12,
      "y": 27,
      "z": 0,
      "name": "Rock_Sandstone_Red"
    },
    {
      "x": -12,
      "y": 28,
      "z": 0,
      "name": "Rock_Sandstone_Red"
    },
    {
      "x": -12,
      "y": 29,
      "z": 0,
      "name": "Rock_Sandstone_Red"
    },
    {
      "x": -12,
      "y": 30,
      "z": 0,
      "name": "Rock_Sandstone_Red"
    },
    {
      "x": -12,
      "y": 31,
      "z": 0,
      "name": "Rock_Sandstone_Red"
    },
    {
      "x": -12,
      "y": 32,
      "z": 0,
      "name": "Soil_Sand_Red"
    },
    {
      "x": -12,
      "y": 33,
      "z": 0,
      "name": "Soil_Sand_Red"
    },
    {
      "x": -12,
      "y": 34,
      "z": 0,
      "name": "Soil_Sand_Red"
    },
    {
      "x": -12,
      "y": 26,
      "z": 1,
      "name": "Rock_Sandstone_Red"
    },
    {
      "x": -12,
      "y": 27,
      "z": 1,
      "name": "Rock_Sandstone_Red"
    },
    {
      "x": -12,
      "y": 28,
      "z": 1,
      "name": "Rock_Sandstone_Red"
    },
    {
      "x": -12,
      "y": 29,
      "z": 1,
      "name": "Rock_Sandstone_Red"
    },
    {
      "x": -12,
      "y": 30,
      "z": 1,
      "name": "Rock_Sandstone_Red"
    },
    {
      "x": -12,
      "y": 31,
      "z": 1,
      "name": "Rock_Sandstone_Red"
    },
    {
      "x": -12,
      "y": 32,
      "z": 1,
      "name": "Soil_Gravel_Sand_Red"
    },
    {
      "x": -12,
      "y": 33,
      "z": 1,
      "name": "Soil_Sand_Red"
    },
    {
      "x": -12,
      "y": 34,
      "z": 1,
      "name": "Soil_Sand_Red"
    },
    {
      "x": -12,
      "y": 26,
      "z": 2,
      "name": "Rock_Sandstone_Red"
    },
    {
      "x": -12,
      "y": 27,
      "z": 2,
      "name": "Rock_Sandstone_Red"
    },
    {
      "x": -12,
      "y": 28,
      "z": 2,
      "name": "Rock_Sandstone_Red"
    },
    {
      "x": -12,
      "y": 29,
      "z": 2,
      "name": "Rock_Sandstone_Red"
    },
    {
      "x": -12,
      "y": 30,
      "z": 2,
      "name": "Rock_Sandstone_Red"
    },
    {
      "x": -12,
      "y": 31,
      "z": 2,
      "name": "Rock_Sandstone_Red"
    },
    {
      "x": -12,
      "y": 32,
      "z": 2,
      "name": "Rock_Sandstone_Red_Cobble"
    },
    {
      "x": -12,
      "y": 33,
      "z": 2,
      "name": "Rock_Sandstone_Red_Cobble"
    },
    {
      "x": -12,
      "y": 34,
      "z": 2,
      "name": "Soil_Sand_Red"
    },
    {
      "x": -12,
      "y": 27,
      "z": 3,
      "name": "Rock_Sandstone_Red"
    },
    {
      "x": -12,
      "y": 28,
      "z": 3,
      "name": "Rock_Sandstone_Red"
    },
    {
      "x": -12,
      "y": 29,
      "z": 3,
      "name": "Rock_Sandstone_Red"
    },
    {
      "x": -12,
      "y": 30,
      "z": 3,
      "name": "Rock_Sandstone_Red"
    },
    {
      "x": -12,
      "y": 31,
      "z": 3,
      "name": "Rock_Sandstone_Red"
    },
    {
      "x": -12,
      "y": 32,
      "z": 3,
      "name": "Rock_Sandstone_Red"
    },
    {
      "x": -12,
      "y": 33,
      "z": 3,
      "name": "Soil_Sand_Red"
    },
    {
      "x": -12,
      "y": 34,
      "z": 3,
      "name": "Soil_Gravel_Sand_Red"
    },
    {
      "x": -12,
      "y": 28,
      "z": 4,
      "name": "Rock_Sandstone_Red"
    },
    {
      "x": -12,
      "y": 29,
      "z": 4,
      "name": "Rock_Sandstone_Red"
    },
    {
      "x": -12,
      "y": 30,
      "z": 4,
      "name": "Rock_Sandstone_Red"
    },
    {
      "x": -12,
      "y": 31,
      "z": 4,
      "name": "Rock_Sandstone_Red"
    },
    {
      "x": -12,
      "y": 32,
      "z": 4,
      "name": "Rock_Sandstone_Red"
    },
    {
      "x": -12,
      "y": 33,
      "z": 4,
      "name": "Rock_Sandstone_Red_Cobble"
    },
    {
      "x": -12,
      "y": 34,
      "z": 4,
      "name": "Soil_Sand_Red"
    },
    {
      "x": -12,
      "y": 28,
      "z": 5,
      "name": "Rock_Sandstone_Red"
    },
    {
      "x": -12,
      "y": 29,
      "z": 5,
      "name": "Rock_Sandstone_Red"
    },
    {
      "x": -12,
      "y": 30,
      "z": 5,
      "name": "Rock_Sandstone_Red"
    },
    {
      "x": -12,
      "y": 31,
      "z": 5,
      "name": "Rock_Sandstone_Red"
    },
    {
      "x": -12,
      "y": 32,
      "z": 5,
      "name": "Rock_Sandstone_Red"
    },
    {
      "x": -12,
      "y": 33,
      "z": 5,
      "name": "Soil_Sand_Red"
    },
    {
      "x": -12,
      "y": 34,
      "z": 5,
      "name": "Soil_Sand_Red"
    },
    {
      "x": -12,
      "y": 29,
      "z": 6,
      "name": "Rock_Sandstone_Red"
    },
    {
      "x": -12,
      "y": 30,
      "z": 6,
      "name": "Rock_Sandstone_Red"
    },
    {
      "x": -12,
      "y": 31,
      "z": 6,
      "name": "Rock_Sandstone_Red"
    },
    {
      "x": -12,
      "y": 32,
      "z": 6,
      "name": "Soil_Sand_Red"
    },
    {
      "x": -12,
      "y": 33,
      "z": 6,
      "name": "Soil_Gravel_Sand_Red"
    },
    {
      "x": -12,
      "y": 34,
      "z": 6,
      "name": "Plant_Crop_Health3"
    },
    {
      "x": -12,
      "y": 29,
      "z": 7,
      "name": "Plant_Crop_Mushroom_Shelve_Yellow"
    },
    {
      "x": -12,
      "y": 32,
      "z": 7,
      "name": "Soil_Gravel_Sand_Red"
    },
    {
      "x": -11,
      "y": 23,
      "z": -17,
      "name": "Rock_Sandstone_Red"
    },
    {
      "x": -11,
      "y": 24,
      "z": -17,
      "name": "Rock_Sandstone_Red"
    },
    {
      "x": -11,
      "y": 25,
      "z": -17,
      "name": "Rock_Sandstone_Red"
    },
    {
      "x": -11,
      "y": 26,
      "z": -17,
      "name": "Rock_Sandstone_Red"
    },
    {
      "x": -11,
      "y": 27,
      "z": -17,
      "name": "Rock_Sandstone_Red"
    },
    {
      "x": -11,
      "y": 28,
      "z": -17,
      "name": "Rubble_Sandstone_Red_Medium"
    },
    {
      "x": -11,
      "y": 21,
      "z": -16,
      "name": "Rock_Sandstone_Red"
    },
    {
      "x": -11,
      "y": 22,
      "z": -16,
      "name": "Rock_Sandstone_Red"
    },
    {
      "x": -11,
      "y": 23,
      "z": -16,
      "name": "Rock_Sandstone_Red"
    },
    {
      "x": -11,
      "y": 24,
      "z": -16,
      "name": "Rock_Sandstone_Red"
    },
    {
      "x": -11,
      "y": 25,
      "z": -16,
      "name": "Rock_Sandstone_Red"
    },
    {
      "x": -11,
      "y": 26,
      "z": -16,
      "name": "Rock_Sandstone_Red"
    },
    {
      "x": -11,
      "y": 27,
      "z": -16,
      "name": "Rock_Sandstone_Red_Cobble"
    },
    {
      "x": -11,
      "y": 28,
      "z": -16,
      "name": "Soil_Sand_Red"
    },
    {
      "x": -11,
      "y": 20,
      "z": -15,
      "name": "Rock_Sandstone_Red"
    },
    {
      "x": -11,
      "y": 21,
      "z": -15,
      "name": "Rock_Sandstone_Red"
    },
    {
      "x": -11,
      "y": 22,
      "z": -15,
      "name": "Rock_Sandstone_Red"
    },
    {
      "x": -11,
      "y": 23,
      "z": -15,
      "name": "Rock_Sandstone_Red"
    },
    {
      "x": -11,
      "y": 24,
      "z": -15,
      "name": "Rock_Sandstone_Red"
    },
    {
      "x": -11,
      "y": 25,
      "z": -15,
      "name": "Rock_Sandstone_Red"
    },
    {
      "x": -11,
      "y": 26,
      "z": -15,
      "name": "Rock_Sandstone_Red"
    },
    {
      "x": -11,
      "y": 27,
      "z": -15,
      "name": "Soil_Sand_Red"
    },
    {
      "x": -11,
      "y": 28,
      "z": -15,
      "name": "Soil_Gravel_Sand_Red"
    },
    {
      "x": -11,
      "y": 29,
      "z": -15,
      "name": "Rock_Sandstone_Red_Cobble"
    },
    {
      "x": -11,
      "y": 19,
      "z": -14,
      "name": "Rock_Sandstone_Red"
    },
    {
      "x": -11,
      "y": 20,
      "z": -14,
      "name": "Rock_Sandstone_Red"
    },
    {
      "x": -11,
      "y": 21,
      "z": -14,
      "name": "Rock_Sandstone_Red"
    },
    {
      "x": -11,
      "y": 22,
      "z": -14,
      "name": "Rock_Sandstone_Red"
    },
    {
      "x": -11,
      "y": 23,
      "z": -14,
      "name": "Rock_Sandstone_Red"
    },
    {
      "x": -11,
      "y": 24,
      "z": -14,
      "name": "Rock_Sandstone_Red"
    },
    {
      "x": -11,
      "y": 25,
      "z": -14,
      "name": "Rock_Sandstone_Red"
    },
    {
      "x": -11,
      "y": 26,
      "z": -14,
      "name": "Rock_Sandstone_Red"
    },
    {
      "x": -11,
      "y": 27,
      "z": -14,
      "name": "Soil_Sand_Red"
    },
    {
      "x": -11,
      "y": 28,
      "z": -14,
      "name": "Soil_Sand_Red"
    },
    {
      "x": -11,
      "y": 29,
      "z": -14,
      "name": "Rock_Sandstone_Red_Cobble"
    },
    {
      "x": -11,
      "y": 15,
      "z": -13,
      "name": "Rock_Crystal_Red_Medium",
      "rotation": 5
    },
    {
      "x": -11,
      "y": 16,
      "z": -13,
      "name": "Rock_Crystal_Red_Medium",
      "rotation": 5
    },
    {
      "x": -11,
      "y": 18,
      "z": -13,
      "name": "Rock_Crystal_Red_Medium",
      "rotation": 6
    },
    {
      "x": -11,
      "y": 19,
      "z": -13,
      "name": "Rock_Sandstone_Red"
    },
    {
      "x": -11,
      "y": 20,
      "z": -13,
      "name": "Rock_Sandstone_Red"
    },
    {
      "x": -11,
      "y": 21,
      "z": -13,
      "name": "Rock_Sandstone_Red"
    },
    {
      "x": -11,
      "y": 22,
      "z": -13,
      "name": "Rock_Sandstone_Red"
    },
    {
      "x": -11,
      "y": 23,
      "z": -13,
      "name": "Rock_Sandstone_Red"
    },
    {
      "x": -11,
      "y": 24,
      "z": -13,
      "name": "Rock_Sandstone_Red"
    },
    {
      "x": -11,
      "y": 25,
      "z": -13,
      "name": "Rock_Sandstone_Red"
    },
    {
      "x": -11,
      "y": 26,
      "z": -13,
      "name": "Rock_Sandstone_Red"
    },
    {
      "x": -11,
      "y": 27,
      "z": -13,
      "name": "Rock_Sandstone_Red"
    },
    {
      "x": -11,
      "y": 28,
      "z": -13,
      "name": "Rock_Sandstone_Red"
    },
    {
      "x": -11,
      "y": 29,
      "z": -13,
      "name": "Rock_Sandstone_Red"
    },
    {
      "x": -11,
      "y": 30,
      "z": -13,
      "name": "Rock_Sandstone_Red"
    },
    {
      "x": -11,
      "y": 31,
      "z": -13,
      "name": "Rubble_Sandstone_Red_Medium"
    },
    {
      "x": -11,
      "y": 17,
      "z": -12,
      "name": "Rock_Crystal_Red_Large",
      "rotation": 8
    },
    {
      "x": -11,
      "y": 18,
      "z": -12,
      "name": "Rock_Crystal_Red_Block"
    },
    {
      "x": -11,
      "y": 19,
      "z": -12,
      "name": "Rock_Crystal_Red_Block"
    },
    {
      "x": -11,
      "y": 20,
      "z": -12,
      "name": "Rock_Crystal_Red_Block"
    },
    {
      "x": -11,
      "y": 21,
      "z": -12,
      "name": "Rock_Crystal_Red_Block"
    },
    {
      "x": -11,
      "y": 22,
      "z": -12,
      "name": "Rock_Crystal_Red_Block"
    },
    {
      "x": -11,
      "y": 23,
      "z": -12,
      "name": "Rock_Sandstone_Red"
    },
    {
      "x": -11,
      "y": 24,
      "z": -12,
      "name": "Ore_Gold_Sandstone"
    },
    {
      "x": -11,
      "y": 25,
      "z": -12,
      "name": "Rock_Sandstone_Red"
    },
    {
      "x": -11,
      "y": 26,
      "z": -12,
      "name": "Rock_Sandstone_Red"
    },
    {
      "x": -11,
      "y": 27,
      "z": -12,
      "name": "Rock_Sandstone_Red"
    },
    {
      "x": -11,
      "y": 28,
      "z": -12,
      "name": "Rock_Sandstone_Red"
    },
    {
      "x": -11,
      "y": 29,
      "z": -12,
      "name": "Rock_Sandstone_Red"
    },
    {
      "x": -11,
      "y": 30,
      "z": -12,
      "name": "Rock_Sandstone_Red"
    },
    {
      "x": -11,
      "y": 19,
      "z": -11,
      "name": "Rock_Crystal_Red_Large",
      "rotation": 5
    },
    {
      "x": -11,
      "y": 20,
      "z": -11,
      "name": "Rock_Sandstone_Red"
    },
    {
      "x": -11,
      "y": 21,
      "z": -11,
      "name": "Rock_Sandstone_Red"
    },
    {
      "x": -11,
      "y": 22,
      "z": -11,
      "name": "Rock_Sandstone_Red"
    },
    {
      "x": -11,
      "y": 23,
      "z": -11,
      "name": "Rock_Sandstone_Red"
    },
    {
      "x": -11,
      "y": 24,
      "z": -11,
      "name": "Rock_Sandstone_Red"
    },
    {
      "x": -11,
      "y": 25,
      "z": -11,
      "name": "Rock_Sandstone_Red"
    },
    {
      "x": -11,
      "y": 26,
      "z": -11,
      "name": "Rock_Sandstone_Red"
    },
    {
      "x": -11,
      "y": 27,
      "z": -11,
      "name": "Rock_Sandstone_Red"
    },
    {
      "x": -11,
      "y": 28,
      "z": -11,
      "name": "Rock_Sandstone_Red"
    },
    {
      "x": -11,
      "y": 29,
      "z": -11,
      "name": "Rock_Sandstone_Red"
    },
    {
      "x": -11,
      "y": 30,
      "z": -11,
      "name": "Rock_Sandstone_Red"
    },
    {
      "x": -11,
      "y": 31,
      "z": -11,
      "name": "Rock_Sandstone_Red"
    },
    {
      "x": -11,
      "y": 21,
      "z": -10,
      "name": "Rock_Sandstone_Red"
    },
    {
      "x": -11,
      "y": 22,
      "z": -10,
      "name": "Rock_Sandstone_Red"
    },
    {
      "x": -11,
      "y": 23,
      "z": -10,
      "name": "Rock_Sandstone_Red"
    },
    {
      "x": -11,
      "y": 24,
      "z": -10,
      "name": "Rock_Sandstone_Red"
    },
    {
      "x": -11,
      "y": 25,
      "z": -10,
      "name": "Rock_Sandstone_Red"
    },
    {
      "x": -11,
      "y": 26,
      "z": -10,
      "name": "Rock_Sandstone_Red"
    },
    {
      "x": -11,
      "y": 27,
      "z": -10,
      "name": "Rock_Sandstone_Red"
    },
    {
      "x": -11,
      "y": 28,
      "z": -10,
      "name": "Rock_Sandstone_Red"
    },
    {
      "x": -11,
      "y": 29,
      "z": -10,
      "name": "Rock_Sandstone_Red"
    },
    {
      "x": -11,
      "y": 30,
      "z": -10,
      "name": "Rock_Sandstone_Red"
    },
    {
      "x": -11,
      "y": 31,
      "z": -10,
      "name": "Rock_Sandstone_Red"
    },
    {
      "x": -11,
      "y": 21,
      "z": -9,
      "name": "Rock_Sandstone_Red"
    },
    {
      "x": -11,
      "y": 22,
      "z": -9,
      "name": "Rock_Sandstone_Red"
    },
    {
      "x": -11,
      "y": 23,
      "z": -9,
      "name": "Rock_Sandstone_Red"
    },
    {
      "x": -11,
      "y": 24,
      "z": -9,
      "name": "Rock_Sandstone_Red"
    },
    {
      "x": -11,
      "y": 25,
      "z": -9,
      "name": "Rock_Sandstone_Red"
    },
    {
      "x": -11,
      "y": 26,
      "z": -9,
      "name": "Rock_Sandstone_Red"
    },
    {
      "x": -11,
      "y": 27,
      "z": -9,
      "name": "Rock_Sandstone_Red"
    },
    {
      "x": -11,
      "y": 28,
      "z": -9,
      "name": "Rock_Sandstone_Red"
    },
    {
      "x": -11,
      "y": 29,
      "z": -9,
      "name": "Rock_Sandstone_Red"
    },
    {
      "x": -11,
      "y": 30,
      "z": -9,
      "name": "Rock_Sandstone_Red"
    },
    {
      "x": -11,
      "y": 31,
      "z": -9,
      "name": "Rock_Sandstone_Red"
    },
    {
      "x": -11,
      "y": 32,
      "z": -9,
      "name": "Rock_Sandstone_Red"
    },
    {
      "x": -11,
      "y": 33,
      "z": -9,
      "name": "Rubble_Sandstone_Red"
    },
    {
      "x": -11,
      "y": 21,
      "z": -8,
      "name": "Rock_Sandstone_Red"
    },
    {
      "x": -11,
      "y": 22,
      "z": -8,
      "name": "Rock_Sandstone_Red"
    },
    {
      "x": -11,
      "y": 23,
      "z": -8,
      "name": "Rock_Sandstone_Red"
    },
    {
      "x": -11,
      "y": 24,
      "z": -8,
      "name": "Rock_Sandstone_Red"
    },
    {
      "x": -11,
      "y": 25,
      "z": -8,
      "name": "Rock_Sandstone_Red"
    },
    {
      "x": -11,
      "y": 26,
      "z": -8,
      "name": "Rock_Sandstone_Red"
    },
    {
      "x": -11,
      "y": 27,
      "z": -8,
      "name": "Rock_Sandstone_Red"
    },
    {
      "x": -11,
      "y": 28,
      "z": -8,
      "name": "Rock_Sandstone_Red"
    },
    {
      "x": -11,
      "y": 29,
      "z": -8,
      "name": "Rock_Sandstone_Red"
    },
    {
      "x": -11,
      "y": 30,
      "z": -8,
      "name": "Rock_Sandstone_Red"
    },
    {
      "x": -11,
      "y": 31,
      "z": -8,
      "name": "Rock_Sandstone_Red"
    },
    {
      "x": -11,
      "y": 32,
      "z": -8,
      "name": "Soil_Sand_Red"
    },
    {
      "x": -11,
      "y": 21,
      "z": -7,
      "name": "Rock_Sandstone_Red"
    },
    {
      "x": -11,
      "y": 22,
      "z": -7,
      "name": "Rock_Sandstone_Red"
    },
    {
      "x": -11,
      "y": 23,
      "z": -7,
      "name": "Rock_Sandstone_Red"
    },
    {
      "x": -11,
      "y": 24,
      "z": -7,
      "name": "Rock_Sandstone_Red"
    },
    {
      "x": -11,
      "y": 25,
      "z": -7,
      "name": "Rock_Sandstone_Red"
    },
    {
      "x": -11,
      "y": 26,
      "z": -7,
      "name": "Rock_Sandstone_Red"
    },
    {
      "x": -11,
      "y": 27,
      "z": -7,
      "name": "Rock_Sandstone_Red"
    },
    {
      "x": -11,
      "y": 28,
      "z": -7,
      "name": "Rock_Sandstone_Red"
    },
    {
      "x": -11,
      "y": 29,
      "z": -7,
      "name": "Rock_Sandstone_Red"
    },
    {
      "x": -11,
      "y": 30,
      "z": -7,
      "name": "Rock_Sandstone_Red"
    },
    {
      "x": -11,
      "y": 31,
      "z": -7,
      "name": "Soil_Sand_Red"
    },
    {
      "x": -11,
      "y": 32,
      "z": -7,
      "name": "Soil_Sand_Red"
    },
    {
      "x": -11,
      "y": 33,
      "z": -7,
      "name": "Soil_Sand_Red"
    },
    {
      "x": -11,
      "y": 21,
      "z": -6,
      "name": "Plant_Moss_Cave_Red"
    },
    {
      "x": -11,
      "y": 22,
      "z": -6,
      "name": "Rock_Sandstone_Red"
    },
    {
      "x": -11,
      "y": 23,
      "z": -6,
      "name": "Rock_Sandstone_Red"
    },
    {
      "x": -11,
      "y": 24,
      "z": -6,
      "name": "Rock_Sandstone_Red"
    },
    {
      "x": -11,
      "y": 25,
      "z": -6,
      "name": "Rock_Sandstone_Red"
    },
    {
      "x": -11,
      "y": 26,
      "z": -6,
      "name": "Rock_Sandstone_Red"
    },
    {
      "x": -11,
      "y": 27,
      "z": -6,
      "name": "Rock_Sandstone_Red"
    },
    {
      "x": -11,
      "y": 28,
      "z": -6,
      "name": "Rock_Sandstone_Red"
    },
    {
      "x": -11,
      "y": 29,
      "z": -6,
      "name": "Rock_Sandstone_Red"
    },
    {
      "x": -11,
      "y": 30,
      "z": -6,
      "name": "Rock_Sandstone_Red"
    },
    {
      "x": -11,
      "y": 31,
      "z": -6,
      "name": "Rock_Sandstone_Red"
    },
    {
      "x": -11,
      "y": 32,
      "z": -6,
      "name": "Soil_Sand_Red"
    },
    {
      "x": -11,
      "y": 33,
      "z": -6,
      "name": "Soil_Sand_Red"
    },
    {
      "x": -11,
      "y": 23,
      "z": -5,
      "name": "Rock_Sandstone_Red"
    },
    {
      "x": -11,
      "y": 24,
      "z": -5,
      "name": "Rock_Sandstone_Red"
    },
    {
      "x": -11,
      "y": 25,
      "z": -5,
      "name": "Rock_Sandstone_Red"
    },
    {
      "x": -11,
      "y": 26,
      "z": -5,
      "name": "Rock_Sandstone_Red"
    },
    {
      "x": -11,
      "y": 27,
      "z": -5,
      "name": "Rock_Sandstone_Red"
    },
    {
      "x": -11,
      "y": 28,
      "z": -5,
      "name": "Rock_Sandstone_Red"
    },
    {
      "x": -11,
      "y": 29,
      "z": -5,
      "name": "Rock_Sandstone_Red"
    },
    {
      "x": -11,
      "y": 30,
      "z": -5,
      "name": "Rock_Sandstone_Red"
    },
    {
      "x": -11,
      "y": 31,
      "z": -5,
      "name": "Rock_Sandstone_Red"
    },
    {
      "x": -11,
      "y": 32,
      "z": -5,
      "name": "Soil_Sand_Red"
    },
    {
      "x": -11,
      "y": 33,
      "z": -5,
      "name": "Soil_Sand_Red"
    },
    {
      "x": -11,
      "y": 34,
      "z": -5,
      "name": "Rock_Sandstone_Red_Cobble"
    },
    {
      "x": -11,
      "y": 24,
      "z": -4,
      "name": "Rock_Sandstone_Red"
    },
    {
      "x": -11,
      "y": 25,
      "z": -4,
      "name": "Rock_Sandstone_Red"
    },
    {
      "x": -11,
      "y": 26,
      "z": -4,
      "name": "Rock_Sandstone_Red"
    },
    {
      "x": -11,
      "y": 27,
      "z": -4,
      "name": "Rock_Sandstone_Red"
    },
    {
      "x": -11,
      "y": 28,
      "z": -4,
      "name": "Rock_Sandstone_Red"
    },
    {
      "x": -11,
      "y": 29,
      "z": -4,
      "name": "Rock_Sandstone_Red"
    },
    {
      "x": -11,
      "y": 30,
      "z": -4,
      "name": "Rock_Sandstone_Red"
    },
    {
      "x": -11,
      "y": 31,
      "z": -4,
      "name": "Rock_Sandstone_Red"
    },
    {
      "x": -11,
      "y": 32,
      "z": -4,
      "name": "Soil_Sand_Red"
    },
    {
      "x": -11,
      "y": 33,
      "z": -4,
      "name": "Soil_Sand_Red"
    },
    {
      "x": -11,
      "y": 34,
      "z": -4,
      "name": "Rock_Sandstone_Red_Cobble"
    },
    {
      "x": -11,
      "y": 24,
      "z": -3,
      "name": "Rock_Sandstone_Red"
    },
    {
      "x": -11,
      "y": 25,
      "z": -3,
      "name": "Rock_Sandstone_Red"
    },
    {
      "x": -11,
      "y": 26,
      "z": -3,
      "name": "Rock_Sandstone_Red"
    },
    {
      "x": -11,
      "y": 27,
      "z": -3,
      "name": "Rock_Sandstone_Red"
    },
    {
      "x": -11,
      "y": 28,
      "z": -3,
      "name": "Rock_Sandstone_Red"
    },
    {
      "x": -11,
      "y": 29,
      "z": -3,
      "name": "Rock_Sandstone_Red"
    },
    {
      "x": -11,
      "y": 30,
      "z": -3,
      "name": "Rock_Sandstone_Red"
    },
    {
      "x": -11,
      "y": 31,
      "z": -3,
      "name": "Rock_Sandstone_Red"
    },
    {
      "x": -11,
      "y": 32,
      "z": -3,
      "name": "Rock_Sandstone_Red"
    },
    {
      "x": -11,
      "y": 33,
      "z": -3,
      "name": "Rock_Sandstone_Red_Cobble"
    },
    {
      "x": -11,
      "y": 34,
      "z": -3,
      "name": "Soil_Gravel_Sand_Red"
    },
    {
      "x": -11,
      "y": 24,
      "z": -2,
      "name": "Rock_Sandstone_Red"
    },
    {
      "x": -11,
      "y": 25,
      "z": -2,
      "name": "Rock_Sandstone_Red"
    },
    {
      "x": -11,
      "y": 26,
      "z": -2,
      "name": "Rock_Sandstone_Red"
    },
    {
      "x": -11,
      "y": 27,
      "z": -2,
      "name": "Rock_Sandstone_Red"
    },
    {
      "x": -11,
      "y": 28,
      "z": -2,
      "name": "Rock_Sandstone_Red"
    },
    {
      "x": -11,
      "y": 29,
      "z": -2,
      "name": "Rock_Sandstone_Red"
    },
    {
      "x": -11,
      "y": 30,
      "z": -2,
      "name": "Rock_Sandstone_Red"
    },
    {
      "x": -11,
      "y": 31,
      "z": -2,
      "name": "Rock_Sandstone_Red"
    },
    {
      "x": -11,
      "y": 32,
      "z": -2,
      "name": "Rock_Sandstone_Red"
    },
    {
      "x": -11,
      "y": 33,
      "z": -2,
      "name": "Rock_Sandstone_Red"
    },
    {
      "x": -11,
      "y": 34,
      "z": -2,
      "name": "Soil_Sand_Red"
    },
    {
      "x": -11,
      "y": 25,
      "z": -1,
      "name": "Rock_Sandstone_Red"
    },
    {
      "x": -11,
      "y": 26,
      "z": -1,
      "name": "Rock_Sandstone_Red"
    },
    {
      "x": -11,
      "y": 27,
      "z": -1,
      "name": "Rock_Sandstone_Red"
    },
    {
      "x": -11,
      "y": 28,
      "z": -1,
      "name": "Rock_Sandstone_Red"
    },
    {
      "x": -11,
      "y": 29,
      "z": -1,
      "name": "Rock_Sandstone_Red"
    },
    {
      "x": -11,
      "y": 30,
      "z": -1,
      "name": "Rock_Sandstone_Red"
    },
    {
      "x": -11,
      "y": 31,
      "z": -1,
      "name": "Rock_Sandstone_Red"
    },
    {
      "x": -11,
      "y": 32,
      "z": -1,
      "name": "Rock_Sandstone_Red"
    },
    {
      "x": -11,
      "y": 33,
      "z": -1,
      "name": "Soil_Sand_Red"
    },
    {
      "x": -11,
      "y": 34,
      "z": -1,
      "name": "Soil_Sand_Red"
    },
    {
      "x": -11,
      "y": 25,
      "z": 0,
      "name": "Rock_Sandstone_Red"
    },
    {
      "x": -11,
      "y": 26,
      "z": 0,
      "name": "Rock_Sandstone_Red"
    },
    {
      "x": -11,
      "y": 27,
      "z": 0,
      "name": "Rock_Sandstone_Red"
    },
    {
      "x": -11,
      "y": 28,
      "z": 0,
      "name": "Rock_Sandstone_Red"
    },
    {
      "x": -11,
      "y": 29,
      "z": 0,
      "name": "Rock_Sandstone_Red"
    },
    {
      "x": -11,
      "y": 30,
      "z": 0,
      "name": "Rock_Sandstone_Red"
    },
    {
      "x": -11,
      "y": 31,
      "z": 0,
      "name": "Rock_Sandstone_Red"
    },
    {
      "x": -11,
      "y": 32,
      "z": 0,
      "name": "Rock_Sandstone_Red"
    },
    {
      "x": -11,
      "y": 33,
      "z": 0,
      "name": "Rock_Sandstone_Red_Cobble"
    },
    {
      "x": -11,
      "y": 34,
      "z": 0,
      "name": "Rock_Sandstone_Red_Cobble"
    },
    {
      "x": -11,
      "y": 21,
      "z": 1,
      "name": "Rock_Crystal_Red_Medium",
      "rotation": 7
    },
    {
      "x": -11,
      "y": 22,
      "z": 1,
      "name": "Rock_Crystal_Red_Medium",
      "rotation": 7
    },
    {
      "x": -11,
      "y": 23,
      "z": 1,
      "name": "Rock_Crystal_Red_Medium",
      "rotation": 7
    },
    {
      "x": -11,
      "y": 24,
      "z": 1,
      "name": "Rock_Crystal_Red_Medium",
      "rotation": 7
    },
    {
      "x": -11,
      "y": 25,
      "z": 1,
      "name": "Rock_Sandstone_Red"
    },
    {
      "x": -11,
      "y": 26,
      "z": 1,
      "name": "Rock_Sandstone_Red"
    },
    {
      "x": -11,
      "y": 27,
      "z": 1,
      "name": "Rock_Sandstone_Red"
    },
    {
      "x": -11,
      "y": 28,
      "z": 1,
      "name": "Rock_Sandstone_Red"
    },
    {
      "x": -11,
      "y": 29,
      "z": 1,
      "name": "Rock_Sandstone_Red"
    },
    {
      "x": -11,
      "y": 30,
      "z": 1,
      "name": "Rock_Sandstone_Red"
    },
    {
      "x": -11,
      "y": 31,
      "z": 1,
      "name": "Rock_Sandstone_Red"
    },
    {
      "x": -11,
      "y": 32,
      "z": 1,
      "name": "Soil_Gravel_Sand_Red"
    },
    {
      "x": -11,
      "y": 33,
      "z": 1,
      "name": "Soil_Sand_Red"
    },
    {
      "x": -11,
      "y": 34,
      "z": 1,
      "name": "Soil_Sand_Red"
    },
    {
      "x": -11,
      "y": 24,
      "z": 2,
      "name": "Rock_Crystal_Red_Medium",
      "rotation": 7
    },
    {
      "x": -11,
      "y": 25,
      "z": 2,
      "name": "Rock_Sandstone_Red"
    },
    {
      "x": -11,
      "y": 26,
      "z": 2,
      "name": "Rock_Sandstone_Red"
    },
    {
      "x": -11,
      "y": 27,
      "z": 2,
      "name": "Rock_Sandstone_Red"
    },
    {
      "x": -11,
      "y": 28,
      "z": 2,
      "name": "Rock_Sandstone_Red"
    },
    {
      "x": -11,
      "y": 29,
      "z": 2,
      "name": "Rock_Sandstone_Red"
    },
    {
      "x": -11,
      "y": 30,
      "z": 2,
      "name": "Rock_Sandstone_Red"
    },
    {
      "x": -11,
      "y": 31,
      "z": 2,
      "name": "Rock_Sandstone_Red"
    },
    {
      "x": -11,
      "y": 32,
      "z": 2,
      "name": "Rock_Sandstone_Red"
    },
    {
      "x": -11,
      "y": 33,
      "z": 2,
      "name": "Soil_Sand_Red"
    },
    {
      "x": -11,
      "y": 34,
      "z": 2,
      "name": "Soil_Sand_Red"
    },
    {
      "x": -11,
      "y": 26,
      "z": 3,
      "name": "Rock_Sandstone_Red"
    },
    {
      "x": -11,
      "y": 27,
      "z": 3,
      "name": "Rock_Sandstone_Red"
    },
    {
      "x": -11,
      "y": 28,
      "z": 3,
      "name": "Rock_Sandstone_Red"
    },
    {
      "x": -11,
      "y": 29,
      "z": 3,
      "name": "Rock_Sandstone_Red"
    },
    {
      "x": -11,
      "y": 30,
      "z": 3,
      "name": "Rock_Sandstone_Red"
    },
    {
      "x": -11,
      "y": 31,
      "z": 3,
      "name": "Rock_Sandstone_Red"
    },
    {
      "x": -11,
      "y": 32,
      "z": 3,
      "name": "Rock_Sandstone_Red"
    },
    {
      "x": -11,
      "y": 33,
      "z": 3,
      "name": "Rock_Sandstone_Red"
    },
    {
      "x": -11,
      "y": 34,
      "z": 3,
      "name": "Rock_Sandstone_Red_Cobble"
    },
    {
      "x": -11,
      "y": 35,
      "z": 3,
      "name": "Soil_Sand_Red"
    },
    {
      "x": -11,
      "y": 27,
      "z": 4,
      "name": "Rock_Sandstone_Red"
    },
    {
      "x": -11,
      "y": 28,
      "z": 4,
      "name": "Rock_Sandstone_Red"
    },
    {
      "x": -11,
      "y": 29,
      "z": 4,
      "name": "Rock_Sandstone_Red"
    },
    {
      "x": -11,
      "y": 30,
      "z": 4,
      "name": "Rock_Sandstone_Red"
    },
    {
      "x": -11,
      "y": 31,
      "z": 4,
      "name": "Rock_Sandstone_Red"
    },
    {
      "x": -11,
      "y": 32,
      "z": 4,
      "name": "Rock_Sandstone_Red"
    },
    {
      "x": -11,
      "y": 33,
      "z": 4,
      "name": "Rock_Sandstone_Red"
    },
    {
      "x": -11,
      "y": 34,
      "z": 4,
      "name": "Rock_Sandstone_Red"
    },
    {
      "x": -11,
