{
  "version": 8,
  "blockIdVersion": 11,
  "anchorX": 0,
  "anchorY": 0,
  "anchorZ": 0,
  "blocks": [
    {
      "x": -19,
      "y": 11,
      "z": -16,
      "name": "Rock_Volcanic"
    },
    {
      "x": -19,
      "y": 12,
      "z": -16,
      "name": "Rock_Volcanic"
    },
    {
      "x": -19,
      "y": 13,
      "z": -16,
      "name": "Rock_Volcanic_Cracked_Lava"
    },
    {
      "x": -19,
      "y": 10,
      "z": -15,
      "name": "Rock_Volcanic_Cracked_Lava"
    },
    {
      "x": -19,
      "y": 11,
      "z": -15,
      "name": "Rock_Volcanic"
    },
    {
      "x": -19,
      "y": 12,
      "z": -15,
      "name": "Rock_Volcanic"
    },
    {
      "x": -19,
      "y": 13,
      "z": -15,
      "name": "Soil_Volcanic_Gravel"
    },
    {
      "x": -19,
      "y": 14,
      "z": -15,
      "name": "Soil_Volcanic_Gravel"
    },
    {
      "x": -19,
      "y": 11,
      "z": -14,
      "name": "Rock_Volcanic_Cracked_Lava"
    },
    {
      "x": -19,
      "y": 12,
      "z": -14,
      "name": "Rock_Volcanic"
    },
    {
      "x": -19,
      "y": 13,
      "z": -14,
      "name": "Soil_Volcanic_Gravel"
    },
    {
      "x": -19,
      "y": 14,
      "z": -14,
      "name": "Soil_Volcanic_Gravel"
    },
    {
      "x": -19,
      "y": 15,
      "z": -14,
      "name": "Plant_Bramble_Dead_Twisted"
    },
    {
      "x": -19,
      "y": 57,
      "z": -2,
      "name": "Wood_Petrified_Trunk_Full"
    },
    {
      "x": -19,
      "y": 58,
      "z": -2,
      "name": "Wood_Petrified_Trunk_Full"
    },
    {
      "x": -18,
      "y": 12,
      "z": -18,
      "name": "Rock_Volcanic_Cracked_Lava"
    },
    {
      "x": -18,
      "y": 13,
      "z": -18,
      "name": "Soil_Volcanic_Gravel"
    },
    {
      "x": -18,
      "y": 8,
      "z": -17,
      "name": "Rock_Volcanic"
    },
    {
      "x": -18,
      "y": 9,
      "z": -17,
      "name": "Rock_Volcanic"
    },
    {
      "x": -18,
      "y": 10,
      "z": -17,
      "name": "Rock_Volcanic"
    },
    {
      "x": -18,
      "y": 11,
      "z": -17,
      "name": "Rock_Volcanic"
    },
    {
      "x": -18,
      "y": 12,
      "z": -17,
      "name": "Rock_Volcanic"
    },
    {
      "x": -18,
      "y": 13,
      "z": -17,
      "name": "Soil_Volcanic_Gravel"
    },
    {
      "x": -18,
      "y": 14,
      "z": -17,
      "name": "Soil_Volcanic_Gravel"
    },
    {
      "x": -18,
      "y": 15,
      "z": -17,
      "name": "Plant_Bramble_Dead_Twisted"
    },
    {
      "x": -18,
      "y": 7,
      "z": -16,
      "name": "Rock_Volcanic_Cracked_Lava"
    },
    {
      "x": -18,
      "y": 8,
      "z": -16,
      "name": "Rock_Volcanic"
    },
    {
      "x": -18,
      "y": 9,
      "z": -16,
      "name": "Rock_Volcanic"
    },
    {
      "x": -18,
      "y": 10,
      "z": -16,
      "name": "Rock_Volcanic"
    },
    {
      "x": -18,
      "y": 11,
      "z": -16,
      "name": "Rock_Volcanic"
    },
    {
      "x": -18,
      "y": 12,
      "z": -16,
      "name": "Rock_Volcanic"
    },
    {
      "x": -18,
      "y": 13,
      "z": -16,
      "name": "Soil_Volcanic_Gravel"
    },
    {
      "x": -18,
      "y": 14,
      "z": -16,
      "name": "Rock_Volcanic"
    },
    {
      "x": -18,
      "y": 4,
      "z": -15,
      "name": "Rock_Volcanic_Stalactite_Large",
      "filler": 31744,
      "rotation": 8
    },
    {
      "x": -18,
      "y": 5,
      "z": -15,
      "name": "Rock_Volcanic_Stalactite_Large",
      "rotation": 8
    },
    {
      "x": -18,
      "y": 6,
      "z": -15,
      "name": "Rock_Volcanic_Cracked_Lava"
    },
    {
      "x": -18,
      "y": 7,
      "z": -15,
      "name": "Rock_Volcanic"
    },
    {
      "x": -18,
      "y": 8,
      "z": -15,
      "name": "Rock_Volcanic"
    },
    {
      "x": -18,
      "y": 9,
      "z": -15,
      "name": "Rock_Volcanic"
    },
    {
      "x": -18,
      "y": 10,
      "z": -15,
      "name": "Rock_Volcanic"
    },
    {
      "x": -18,
      "y": 11,
      "z": -15,
      "name": "Rock_Volcanic"
    },
    {
      "x": -18,
      "y": 12,
      "z": -15,
      "name": "Rock_Volcanic_Cracked_Lava"
    },
    {
      "x": -18,
      "y": 13,
      "z": -15,
      "name": "Soil_Volcanic_Gravel"
    },
    {
      "x": -18,
      "y": 14,
      "z": -15,
      "name": "Rock_Volcanic_Cracked_Lava"
    },
    {
      "x": -18,
      "y": 5,
      "z": -14,
      "name": "Rock_Volcanic_Stalactite_Large",
      "filler": 31744,
      "rotation": 8
    },
    {
      "x": -18,
      "y": 6,
      "z": -14,
      "name": "Rock_Volcanic_Stalactite_Large",
      "rotation": 8
    },
    {
      "x": -18,
      "y": 7,
      "z": -14,
      "name": "Rock_Volcanic"
    },
    {
      "x": -18,
      "y": 8,
      "z": -14,
      "name": "Rock_Volcanic"
    },
    {
      "x": -18,
      "y": 9,
      "z": -14,
      "name": "Rock_Volcanic"
    },
    {
      "x": -18,
      "y": 10,
      "z": -14,
      "name": "Rock_Volcanic"
    },
    {
      "x": -18,
      "y": 11,
      "z": -14,
      "name": "Rock_Volcanic"
    },
    {
      "x": -18,
      "y": 12,
      "z": -14,
      "name": "Rock_Volcanic"
    },
    {
      "x": -18,
      "y": 13,
      "z": -14,
      "name": "Rock_Volcanic"
    },
    {
      "x": -18,
      "y": 14,
      "z": -14,
      "name": "Soil_Volcanic_Gravel"
    },
    {
      "x": -18,
      "y": 15,
      "z": -14,
      "name": "Rock_Volcanic"
    },
    {
      "x": -18,
      "y": 8,
      "z": -13,
      "name": "Rock_Volcanic"
    },
    {
      "x": -18,
      "y": 9,
      "z": -13,
      "name": "Rock_Volcanic"
    },
    {
      "x": -18,
      "y": 10,
      "z": -13,
      "name": "Rock_Volcanic"
    },
    {
      "x": -18,
      "y": 11,
      "z": -13,
      "name": "Rock_Volcanic"
    },
    {
      "x": -18,
      "y": 12,
      "z": -13,
      "name": "Rock_Volcanic"
    },
    {
      "x": -18,
      "y": 13,
      "z": -13,
      "name": "Soil_Volcanic_Gravel"
    },
    {
      "x": -18,
      "y": 14,
      "z": -13,
      "name": "Soil_Volcanic_Gravel"
    },
    {
      "x": -18,
      "y": 12,
      "z": -12,
      "name": "Rock_Volcanic"
    },
    {
      "x": -18,
      "y": 13,
      "z": -12,
      "name": "Rock_Volcanic"
    },
    {
      "x": -18,
      "y": 14,
      "z": -12,
      "name": "Rock_Volcanic_Cracked_Lava"
    },
    {
      "x": -18,
      "y": 29,
      "z": -7,
      "name": "Rock_Volcanic"
    },
    {
      "x": -18,
      "y": 30,
      "z": -7,
      "name": "Rock_Volcanic"
    },
    {
      "x": -18,
      "y": 29,
      "z": -6,
      "name": "Rock_Volcanic_Cracked_Lava"
    },
    {
      "x": -18,
      "y": 30,
      "z": -6,
      "name": "Rock_Volcanic"
    },
    {
      "x": -18,
      "y": 29,
      "z": -5,
      "name": "Rock_Volcanic"
    },
    {
      "x": -18,
      "y": 30,
      "z": -5,
      "name": "Rock_Volcanic"
    },
    {
      "x": -18,
      "y": 55,
      "z": -2,
      "name": "Wood_Petrified_Trunk_Full"
    },
    {
      "x": -18,
      "y": 56,
      "z": -2,
      "name": "Wood_Petrified_Trunk_Full"
    },
    {
      "x": -18,
      "y": 57,
      "z": -2,
      "name": "Wood_Petrified_Trunk_Full"
    },
    {
      "x": -18,
      "y": 58,
      "z": -2,
      "name": "Wood_Petrified_Trunk_Full"
    },
    {
      "x": -18,
      "y": 59,
      "z": -2,
      "name": "Wood_Petrified_Trunk_Full"
    },
    {
      "x": -18,
      "y": 53,
      "z": -1,
      "name": "Wood_Petrified_Trunk_Full"
    },
    {
      "x": -18,
      "y": 54,
      "z": -1,
      "name": "Wood_Petrified_Trunk_Full"
    },
    {
      "x": -18,
      "y": 46,
      "z": 8,
      "name": "Plant_Moss_Wall_Red",
      "rotation": 3
    },
    {
      "x": -18,
      "y": 51,
      "z": 12,
      "name": "Wood_Petrified_Trunk_Full"
    },
    {
      "x": -17,
      "y": 6,
      "z": -18,
      "name": "Rock_Volcanic_Stalactite_Large",
      "filler": 31744,
      "rotation": 8
    },
    {
      "x": -17,
      "y": 7,
      "z": -18,
      "name": "Rock_Volcanic_Stalactite_Large",
      "rotation": 8
    },
    {
      "x": -17,
      "y": 8,
      "z": -18,
      "name": "Rock_Volcanic_Cracked_Lava"
    },
    {
      "x": -17,
      "y": 9,
      "z": -18,
      "name": "Rock_Volcanic_Cracked_Lava"
    },
    {
      "x": -17,
      "y": 10,
      "z": -18,
      "name": "Rock_Volcanic"
    },
    {
      "x": -17,
      "y": 11,
      "z": -18,
      "name": "Rock_Volcanic"
    },
    {
      "x": -17,
      "y": 12,
      "z": -18,
      "name": "Rock_Volcanic_Cracked_Lava"
    },
    {
      "x": -17,
      "y": 13,
      "z": -18,
      "name": "Rock_Volcanic"
    },
    {
      "x": -17,
      "y": 14,
      "z": -18,
      "name": "Soil_Volcanic_Gravel"
    },
    {
      "x": -17,
      "y": 4,
      "z": -17,
      "name": "Rock_Volcanic_Stalactite_Large",
      "filler": 31744,
      "rotation": 8
    },
    {
      "x": -17,
      "y": 5,
      "z": -17,
      "name": "Rock_Volcanic_Stalactite_Large",
      "rotation": 8
    },
    {
      "x": -17,
      "y": 6,
      "z": -17,
      "name": "Rock_Volcanic"
    },
    {
      "x": -17,
      "y": 7,
      "z": -17,
      "name": "Rock_Volcanic"
    },
    {
      "x": -17,
      "y": 8,
      "z": -17,
      "name": "Rock_Volcanic"
    },
    {
      "x": -17,
      "y": 9,
      "z": -17,
      "name": "Rock_Volcanic"
    },
    {
      "x": -17,
      "y": 10,
      "z": -17,
      "name": "Rock_Volcanic"
    },
    {
      "x": -17,
      "y": 11,
      "z": -17,
      "name": "Rock_Volcanic"
    },
    {
      "x": -17,
      "y": 12,
      "z": -17,
      "name": "Rock_Volcanic"
    },
    {
      "x": -17,
      "y": 13,
      "z": -17,
      "name": "Rock_Volcanic_Cracked_Lava"
    },
    {
      "x": -17,
      "y": 14,
      "z": -17,
      "name": "Soil_Volcanic_Gravel"
    },
    {
      "x": -17,
      "y": 15,
      "z": -17,
      "name": "Rubble_Magma_Cooled"
    },
    {
      "x": -17,
      "y": 6,
      "z": -16,
      "name": "Rock_Volcanic_Cracked_Lava"
    },
    {
      "x": -17,
      "y": 7,
      "z": -16,
      "name": "Rock_Volcanic"
    },
    {
      "x": -17,
      "y": 8,
      "z": -16,
      "name": "Rock_Volcanic"
    },
    {
      "x": -17,
      "y": 9,
      "z": -16,
      "name": "Rock_Volcanic_Cracked_Lava"
    },
    {
      "x": -17,
      "y": 10,
      "z": -16,
      "name": "Rock_Volcanic_Cracked_Lava"
    },
    {
      "x": -17,
      "y": 11,
      "z": -16,
      "name": "Rock_Volcanic"
    },
    {
      "x": -17,
      "y": 12,
      "z": -16,
      "name": "Rock_Volcanic_Cracked_Lava"
    },
    {
      "x": -17,
      "y": 13,
      "z": -16,
      "name": "Rock_Volcanic"
    },
    {
      "x": -17,
      "y": 14,
      "z": -16,
      "name": "Soil_Volcanic_Gravel"
    },
    {
      "x": -17,
      "y": 15,
      "z": -16,
      "name": "Soil_Volcanic_Gravel"
    },
    {
      "x": -17,
      "y": 16,
      "z": -16,
      "name": "Rubble_Magma_Cooled"
    },
    {
      "x": -17,
      "y": 4,
      "z": -15,
      "name": "Rock_Crystal_Red_Medium",
      "rotation": 7
    },
    {
      "x": -17,
      "y": 5,
      "z": -15,
      "name": "Rock_Volcanic"
    },
    {
      "x": -17,
      "y": 6,
      "z": -15,
      "name": "Rock_Volcanic"
    },
    {
      "x": -17,
      "y": 7,
      "z": -15,
      "name": "Soil_Volcanic_Gravel"
    },
    {
      "x": -17,
      "y": 8,
      "z": -15,
      "name": "Rock_Volcanic"
    },
    {
      "x": -17,
      "y": 9,
      "z": -15,
      "name": "Rock_Volcanic"
    },
    {
      "x": -17,
      "y": 10,
      "z": -15,
      "name": "Rock_Volcanic"
    },
    {
      "x": -17,
      "y": 11,
      "z": -15,
      "name": "Rock_Volcanic"
    },
    {
      "x": -17,
      "y": 12,
      "z": -15,
      "name": "Rock_Volcanic"
    },
    {
      "x": -17,
      "y": 13,
      "z": -15,
      "name": "Rock_Volcanic"
    },
    {
      "x": -17,
      "y": 14,
      "z": -15,
      "name": "Rock_Volcanic_Cracked_Lava"
    },
    {
      "x": -17,
      "y": 15,
      "z": -15,
      "name": "Soil_Volcanic_Gravel"
    },
    {
      "x": -17,
      "y": 5,
      "z": -14,
      "name": "Rock_Volcanic_Cracked_Lava"
    },
    {
      "x": -17,
      "y": 6,
      "z": -14,
      "name": "Soil_Volcanic_Gravel"
    },
    {
      "x": -17,
      "y": 7,
      "z": -14,
      "name": "Rock_Volcanic_Cracked_Lava"
    },
    {
      "x": -17,
      "y": 8,
      "z": -14,
      "name": "Rock_Volcanic"
    },
    {
      "x": -17,
      "y": 9,
      "z": -14,
      "name": "Rock_Volcanic_Cracked_Lava"
    },
    {
      "x": -17,
      "y": 10,
      "z": -14,
      "name": "Rock_Volcanic"
    },
    {
      "x": -17,
      "y": 11,
      "z": -14,
      "name": "Rock_Volcanic_Cracked_Lava"
    },
    {
      "x": -17,
      "y": 12,
      "z": -14,
      "name": "Soil_Volcanic_Gravel"
    },
    {
      "x": -17,
      "y": 13,
      "z": -14,
      "name": "Rock_Volcanic_Cracked_Lava"
    },
    {
      "x": -17,
      "y": 14,
      "z": -14,
      "name": "Rock_Volcanic"
    },
    {
      "x": -17,
      "y": 15,
      "z": -14,
      "name": "Soil_Volcanic_Gravel"
    },
    {
      "x": -17,
      "y": 4,
      "z": -13,
      "name": "Rock_Volcanic_Stalactite_Large",
      "filler": 31744,
      "rotation": 8
    },
    {
      "x": -17,
      "y": 5,
      "z": -13,
      "name": "Rock_Volcanic_Stalactite_Large",
      "rotation": 8
    },
    {
      "x": -17,
      "y": 6,
      "z": -13,
      "name": "Rock_Volcanic_Cracked_Lava"
    },
    {
      "x": -17,
      "y": 7,
      "z": -13,
      "name": "Rock_Volcanic"
    },
    {
      "x": -17,
      "y": 8,
      "z": -13,
      "name": "Rock_Volcanic"
    },
    {
      "x": -17,
      "y": 9,
      "z": -13,
      "name": "Rock_Volcanic_Cracked_Lava"
    },
    {
      "x": -17,
      "y": 10,
      "z": -13,
      "name": "Rock_Volcanic_Cracked_Lava"
    },
    {
      "x": -17,
      "y": 11,
      "z": -13,
      "name": "Rock_Volcanic_Cracked_Lava"
    },
    {
      "x": -17,
      "y": 12,
      "z": -13,
      "name": "Rock_Volcanic"
    },
    {
      "x": -17,
      "y": 13,
      "z": -13,
      "name": "Soil_Volcanic_Gravel"
    },
    {
      "x": -17,
      "y": 14,
      "z": -13,
      "name": "Rock_Volcanic_Cracked_Lava"
    },
    {
      "x": -17,
      "y": 15,
      "z": -13,
      "name": "Soil_Volcanic_Gravel"
    },
    {
      "x": -17,
      "y": 8,
      "z": -12,
      "name": "Rock_Volcanic"
    },
    {
      "x": -17,
      "y": 9,
      "z": -12,
      "name": "Rock_Volcanic"
    },
    {
      "x": -17,
      "y": 10,
      "z": -12,
      "name": "Rock_Volcanic"
    },
    {
      "x": -17,
      "y": 11,
      "z": -12,
      "name": "Rock_Volcanic"
    },
    {
      "x": -17,
      "y": 12,
      "z": -12,
      "name": "Rock_Volcanic"
    },
    {
      "x": -17,
      "y": 13,
      "z": -12,
      "name": "Rock_Volcanic"
    },
    {
      "x": -17,
      "y": 14,
      "z": -12,
      "name": "Rock_Volcanic_Cracked_Lava"
    },
    {
      "x": -17,
      "y": 29,
      "z": -9,
      "name": "Plant_Vine_Red_Hanging"
    },
    {
      "x": -17,
      "y": 30,
      "z": -9,
      "name": "Rock_Volcanic_Cracked_Lava"
    },
    {
      "x": -17,
      "y": 24,
      "z": -8,
      "name": "Rock_Volcanic"
    },
    {
      "x": -17,
      "y": 26,
      "z": -8,
      "name": "Rock_Volcanic"
    },
    {
      "x": -17,
      "y": 27,
      "z": -8,
      "name": "Rock_Volcanic_Cracked_Lava"
    },
    {
      "x": -17,
      "y": 28,
      "z": -8,
      "name": "Rock_Volcanic"
    },
    {
      "x": -17,
      "y": 29,
      "z": -8,
      "name": "Rock_Volcanic"
    },
    {
      "x": -17,
      "y": 30,
      "z": -8,
      "name": "Rock_Volcanic"
    },
    {
      "x": -17,
      "y": 31,
      "z": -8,
      "name": "Rock_Volcanic"
    },
    {
      "x": -17,
      "y": 22,
      "z": -7,
      "name": "Plant_Vine_Red_Hanging"
    },
    {
      "x": -17,
      "y": 23,
      "z": -7,
      "name": "Rock_Volcanic"
    },
    {
      "x": -17,
      "y": 24,
      "z": -7,
      "name": "Rock_Volcanic"
    },
    {
      "x": -17,
      "y": 25,
      "z": -7,
      "name": "Rock_Volcanic"
    },
    {
      "x": -17,
      "y": 26,
      "z": -7,
      "name": "Rock_Volcanic"
    },
    {
      "x": -17,
      "y": 27,
      "z": -7,
      "name": "Rock_Volcanic"
    },
    {
      "x": -17,
      "y": 28,
      "z": -7,
      "name": "Rock_Volcanic"
    },
    {
      "x": -17,
      "y": 29,
      "z": -7,
      "name": "Rock_Volcanic"
    },
    {
      "x": -17,
      "y": 30,
      "z": -7,
      "name": "Rock_Volcanic"
    },
    {
      "x": -17,
      "y": 31,
      "z": -7,
      "name": "Rock_Volcanic"
    },
    {
      "x": -17,
      "y": 22,
      "z": -6,
      "name": "Rock_Volcanic"
    },
    {
      "x": -17,
      "y": 23,
      "z": -6,
      "name": "Rock_Volcanic"
    },
    {
      "x": -17,
      "y": 24,
      "z": -6,
      "name": "Rock_Volcanic"
    },
    {
      "x": -17,
      "y": 25,
      "z": -6,
      "name": "Rock_Volcanic"
    },
    {
      "x": -17,
      "y": 26,
      "z": -6,
      "name": "Rock_Volcanic"
    },
    {
      "x": -17,
      "y": 27,
      "z": -6,
      "name": "Rock_Volcanic"
    },
    {
      "x": -17,
      "y": 28,
      "z": -6,
      "name": "Rock_Volcanic"
    },
    {
      "x": -17,
      "y": 29,
      "z": -6,
      "name": "Rock_Volcanic"
    },
    {
      "x": -17,
      "y": 30,
      "z": -6,
      "name": "Rock_Volcanic"
    },
    {
      "x": -17,
      "y": 31,
      "z": -6,
      "name": "Rock_Volcanic"
    },
    {
      "x": -17,
      "y": 23,
      "z": -5,
      "name": "Rock_Volcanic"
    },
    {
      "x": -17,
      "y": 24,
      "z": -5,
      "name": "Rock_Volcanic"
    },
    {
      "x": -17,
      "y": 25,
      "z": -5,
      "name": "Rock_Volcanic"
    },
    {
      "x": -17,
      "y": 26,
      "z": -5,
      "name": "Rock_Volcanic"
    },
    {
      "x": -17,
      "y": 27,
      "z": -5,
      "name": "Rock_Volcanic"
    },
    {
      "x": -17,
      "y": 28,
      "z": -5,
      "name": "Rock_Volcanic_Cracked_Lava"
    },
    {
      "x": -17,
      "y": 29,
      "z": -5,
      "name": "Rock_Volcanic"
    },
    {
      "x": -17,
      "y": 30,
      "z": -5,
      "name": "Rock_Volcanic"
    },
    {
      "x": -17,
      "y": 31,
      "z": -5,
      "name": "Soil_Volcanic_Gravel"
    },
    {
      "x": -17,
      "y": 25,
      "z": -4,
      "name": "Rock_Volcanic"
    },
    {
      "x": -17,
      "y": 26,
      "z": -4,
      "name": "Rock_Volcanic"
    },
    {
      "x": -17,
      "y": 27,
      "z": -4,
      "name": "Rock_Volcanic"
    },
    {
      "x": -17,
      "y": 28,
      "z": -4,
      "name": "Rock_Volcanic"
    },
    {
      "x": -17,
      "y": 29,
      "z": -4,
      "name": "Rock_Volcanic"
    },
    {
      "x": -17,
      "y": 30,
      "z": -4,
      "name": "Rock_Volcanic"
    },
    {
      "x": -17,
      "y": 31,
      "z": -4,
      "name": "Soil_Volcanic_Gravel"
    },
    {
      "x": -17,
      "y": 27,
      "z": -3,
      "name": "Rock_Volcanic_Cracked_Lava"
    },
    {
      "x": -17,
      "y": 28,
      "z": -3,
      "name": "Rock_Volcanic"
    },
    {
      "x": -17,
      "y": 29,
      "z": -3,
      "name": "Rock_Volcanic"
    },
    {
      "x": -17,
      "y": 30,
      "z": -3,
      "name": "Rock_Volcanic_Cracked_Lava"
    },
    {
      "x": -17,
      "y": 31,
      "z": -3,
      "name": "Soil_Volcanic_Gravel"
    },
    {
      "x": -17,
      "y": 32,
      "z": -3,
      "name": "Rock_Volcanic_Stalactite_Small"
    },
    {
      "x": -17,
      "y": 27,
      "z": -2,
      "name": "Rock_Volcanic_Cracked_Lava"
    },
    {
      "x": -17,
      "y": 28,
      "z": -2,
      "name": "Rock_Volcanic"
    },
    {
      "x": -17,
      "y": 29,
      "z": -2,
      "name": "Rock_Volcanic"
    },
    {
      "x": -17,
      "y": 30,
      "z": -2,
      "name": "Soil_Volcanic_Gravel"
    },
    {
      "x": -17,
      "y": 54,
      "z": -2,
      "name": "Wood_Petrified_Trunk_Full"
    },
    {
      "x": -17,
      "y": 55,
      "z": -2,
      "name": "Wood_Petrified_Trunk_Full"
    },
    {
      "x": -17,
      "y": 56,
      "z": -2,
      "name": "Wood_Petrified_Trunk_Full"
    },
    {
      "x": -17,
      "y": 57,
      "z": -2,
      "name": "Wood_Petrified_Trunk_Full"
    },
    {
      "x": -17,
      "y": 58,
      "z": -2,
      "name": "Wood_Petrified_Trunk_Full"
    },
    {
      "x": -17,
      "y": 59,
      "z": -2,
      "name": "Wood_Petrified_Trunk_Full"
    },
    {
      "x": -17,
      "y": 60,
      "z": -2,
      "name": "Wood_Petrified_Trunk_Full"
    },
    {
      "x": -17,
      "y": 29,
      "z": -1,
      "name": "Rock_Volcanic_Cracked_Lava"
    },
    {
      "x": -17,
      "y": 30,
      "z": -1,
      "name": "Soil_Volcanic_Gravel"
    },
    {
      "x": -17,
      "y": 50,
      "z": -1,
      "name": "Plant_Moss_Wall_Red",
      "rotation": 3
    },
    {
      "x": -17,
      "y": 51,
      "z": -1,
      "name": "Plant_Moss_Wall_Red",
      "rotation": 3
    },
    {
      "x": -17,
      "y": 52,
      "z": -1,
      "name": "Wood_Petrified_Trunk_Full"
    },
    {
      "x": -17,
      "y": 53,
      "z": -1,
      "name": "Wood_Petrified_Trunk_Full"
    },
    {
      "x": -17,
      "y": 54,
      "z": -1,
      "name": "Wood_Petrified_Trunk_Full"
    },
    {
      "x": -17,
      "y": 45,
      "z": 4,
      "name": "Plant_Moss_Wall_Red",
      "rotation": 3
    },
    {
      "x": -17,
      "y": 45,
      "z": 5,
      "name": "Plant_Moss_Wall_Red",
      "rotation": 3
    },
    {
      "x": -17,
      "y": 45,
      "z": 6,
      "name": "Plant_Moss_Wall_Red",
      "rotation": 3
    },
    {
      "x": -17,
      "y": 46,
      "z": 6,
      "name": "Wood_Petrified_Trunk_Full"
    },
    {
      "x": -17,
      "y": 47,
      "z": 6,
      "name": "Plant_Moss_Rug_Red"
    },
    {
      "x": -17,
      "y": 46,
      "z": 7,
      "name": "Plant_Moss_Wall_Red",
      "rotation": 3
    },
    {
      "x": -17,
      "y": 45,
      "z": 8,
      "name": "Plant_Moss_Cave_Red",
      "rotation": 8
    },
    {
      "x": -17,
      "y": 46,
      "z": 8,
      "name": "Wood_Petrified_Trunk_Full"
    },
    {
      "x": -17,
      "y": 47,
      "z": 8,
      "name": "Wood_Petrified_Trunk_Full"
    },
    {
      "x": -17,
      "y": 48,
      "z": 8,
      "name": "Plant_Moss_Rug_Red"
    },
    {
      "x": -17,
      "y": 47,
      "z": 9,
      "name": "Plant_Moss_Wall_Red",
      "rotation": 3
    },
    {
      "x": -17,
      "y": 47,
      "z": 10,
      "name": "Plant_Moss_Wall_Red",
      "rotation": 3
    },
    {
      "x": -17,
      "y": 49,
      "z": 11,
      "name": "Wood_Petrified_Trunk_Full"
    },
    {
      "x": -17,
      "y": 50,
      "z": 12,
      "name": "Wood_Petrified_Trunk_Full"
    },
    {
      "x": -17,
      "y": 51,
      "z": 12,
      "name": "Wood_Petrified_Trunk_Full"
    },
    {
      "x": -16,
      "y": 11,
      "z": -19,
      "name": "Rock_Volcanic"
    },
    {
      "x": -16,
      "y": 12,
      "z": -19,
      "name": "Rock_Volcanic_Cracked_Lava"
    },
    {
      "x": -16,
      "y": 13,
      "z": -19,
      "name": "Rock_Volcanic"
    },
    {
      "x": -16,
      "y": 14,
      "z": -19,
      "name": "Soil_Volcanic_Gravel"
    },
    {
      "x": -16,
      "y": 8,
      "z": -18,
      "name": "Rock_Volcanic_Cracked_Lava"
    },
    {
      "x": -16,
      "y": 9,
      "z": -18,
      "name": "Rock_Volcanic"
    },
    {
      "x": -16,
      "y": 10,
      "z": -18,
      "name": "Rock_Volcanic"
    },
    {
      "x": -16,
      "y": 11,
      "z": -18,
      "name": "Rock_Volcanic"
    },
    {
      "x": -16,
      "y": 12,
      "z": -18,
      "name": "Rock_Volcanic"
    },
    {
      "x": -16,
      "y": 13,
      "z": -18,
      "name": "Soil_Volcanic_Gravel"
    },
    {
      "x": -16,
      "y": 14,
      "z": -18,
      "name": "Soil_Volcanic_Gravel"
    },
    {
      "x": -16,
      "y": 15,
      "z": -18,
      "name": "Soil_Volcanic_Gravel"
    },
    {
      "x": -16,
      "y": 16,
      "z": -18,
      "name": "Plant_Bramble_Dead_Twisted"
    },
    {
      "x": -16,
      "y": 6,
      "z": -17,
      "name": "Rock_Volcanic"
    },
    {
      "x": -16,
      "y": 7,
      "z": -17,
      "name": "Rock_Volcanic_Cracked_Lava"
    },
    {
      "x": -16,
      "y": 8,
      "z": -17,
      "name": "Rock_Volcanic_Cracked_Lava"
    },
    {
      "x": -16,
      "y": 9,
      "z": -17,
      "name": "Rock_Volcanic"
    },
    {
      "x": -16,
      "y": 10,
      "z": -17,
      "name": "Rock_Volcanic"
    },
    {
      "x": -16,
      "y": 11,
      "z": -17,
      "name": "Rock_Volcanic"
    },
    {
      "x": -16,
      "y": 12,
      "z": -17,
      "name": "Rock_Volcanic"
    },
    {
      "x": -16,
      "y": 13,
      "z": -17,
      "name": "Rock_Volcanic"
    },
    {
      "x": -16,
      "y": 14,
      "z": -17,
      "name": "Soil_Volcanic_Gravel"
    },
    {
      "x": -16,
      "y": 15,
      "z": -17,
      "name": "Rock_Magma_Cooled_Brick"
    },
    {
      "x": -16,
      "y": 16,
      "z": -17,
      "name": "Rock_Magma_Cooled_Brick_Pillar_Base"
    },
    {
      "x": -16,
      "y": 17,
      "z": -17,
      "name": "Rubble_Magma_Cooled_Medium"
    },
    {
      "x": -16,
      "y": 3,
      "z": -16,
      "name": "Rock_Crystal_Red_Medium",
      "rotation": 7
    },
    {
      "x": -16,
      "y": 4,
      "z": -16,
      "name": "Rock_Crystal_Red_Medium",
      "rotation": 6
    },
    {
      "x": -16,
      "y": 5,
      "z": -16,
      "name": "Rock_Crystal_Red_Medium",
      "rotation": 6
    },
    {
      "x": -16,
      "y": 6,
      "z": -16,
      "name": "Rock_Volcanic"
    },
    {
      "x": -16,
      "y": 7,
      "z": -16,
      "name": "Soil_Volcanic_Gravel"
    },
    {
      "x": -16,
      "y": 8,
      "z": -16,
      "name": "Soil_Volcanic_Gravel"
    },
    {
      "x": -16,
      "y": 9,
      "z": -16,
      "name": "Rock_Volcanic"
    },
    {
      "x": -16,
      "y": 10,
      "z": -16,
      "name": "Rock_Volcanic"
    },
    {
      "x": -16,
      "y": 11,
      "z": -16,
      "name": "Rock_Volcanic_Cracked_Lava"
    },
    {
      "x": -16,
      "y": 12,
      "z": -16,
      "name": "Rock_Volcanic_Cracked_Lava"
    },
    {
      "x": -16,
      "y": 13,
      "z": -16,
      "name": "Soil_Volcanic_Gravel"
    },
    {
      "x": -16,
      "y": 14,
      "z": -16,
      "name": "Soil_Volcanic_Gravel"
    },
    {
      "x": -16,
      "y": 15,
      "z": -16,
      "name": "Rock_Magma_Cooled_Brick"
    },
    {
      "x": -16,
      "y": 1,
      "z": -15,
      "name": "Rock_Crystal_Red_Medium",
      "rotation": 7
    },
    {
      "x": -16,
      "y": 2,
      "z": -15,
      "name": "Rock_Crystal_Red_Medium",
      "rotation": 7
    },
    {
      "x": -16,
      "y": 3,
      "z": -15,
      "name": "Rock_Crystal_Red_Medium",
      "rotation": 7
    },
    {
      "x": -16,
      "y": 4,
      "z": -15,
      "name": "Rock_Crystal_Red_Block"
    },
    {
      "x": -16,
      "y": 5,
      "z": -15,
      "name": "Rock_Crystal_Red_Block"
    },
    {
      "x": -16,
      "y": 6,
      "z": -15,
      "name": "Rock_Crystal_Red_Block",
      "rotation": 5
    },
    {
      "x": -16,
      "y": 7,
      "z": -15,
      "name": "Rock_Crystal_Red_Block",
      "rotation": 5
    },
    {
      "x": -16,
      "y": 8,
      "z": -15,
      "name": "Rock_Volcanic"
    },
    {
      "x": -16,
      "y": 9,
      "z": -15,
      "name": "Rock_Volcanic"
    },
    {
      "x": -16,
      "y": 10,
      "z": -15,
      "name": "Rock_Volcanic"
    },
    {
      "x": -16,
      "y": 11,
      "z": -15,
      "name": "Rock_Volcanic_Cracked_Lava"
    },
    {
      "x": -16,
      "y": 12,
      "z": -15,
      "name": "Rock_Volcanic"
    },
    {
      "x": -16,
      "y": 13,
      "z": -15,
      "name": "Soil_Volcanic_Gravel"
    },
    {
      "x": -16,
      "y": 14,
      "z": -15,
      "name": "Rock_Magma_Cooled_Brick"
    },
    {
      "x": -16,
      "y": 15,
      "z": -15,
      "name": "Rock_Magma_Cooled_Brick"
    },
    {
      "x": -16,
      "y": 16,
      "z": -15,
      "name": "Block_Spawner_Block",
      "components": {
        "Components": {
          "PlacedByInteraction": {
            "WhoPlacedUuid": {
              "$binary": "3XRzOktQTQGfL/+8x7+CHA==",
              "$type": "04"
            }
          },
          "BlockSpawner": {
            "BlockSpawnerId": "Zone4_Encounters_Tier4"
          }
        }
      },
      "rotation": 1
    },
    {
      "x": -16,
      "y": 3,
      "z": -14,
      "name": "Rock_Crystal_Red_Medium",
      "rotation": 7
    },
    {
      "x": -16,
      "y": 4,
      "z": -14,
      "name": "Rock_Crystal_Red_Large",
      "rotation": 4
    },
    {
      "x": -16,
      "y": 5,
      "z": -14,
      "name": "Rock_Volcanic"
    },
    {
      "x": -16,
      "y": 6,
      "z": -14,
      "name": "Rock_Volcanic_Cracked_Lava"
    },
    {
      "x": -16,
      "y": 7,
      "z": -14,
      "name": "Rock_Volcanic_Cracked_Lava"
    },
    {
      "x": -16,
      "y": 8,
      "z": -14,
      "name": "Rock_Volcanic"
    },
    {
      "x": -16,
      "y": 9,
      "z": -14,
      "name": "Rock_Volcanic"
    },
    {
      "x": -16,
      "y": 10,
      "z": -14,
      "name": "Rock_Volcanic"
    },
    {
      "x": -16,
      "y": 11,
      "z": -14,
      "name": "Rock_Volcanic"
    },
    {
      "x": -16,
      "y": 12,
      "z": -14,
      "name": "Rock_Volcanic_Cracked_Lava"
    },
    {
      "x": -16,
      "y": 13,
      "z": -14,
      "name": "Rock_Volcanic"
    },
    {
      "x": -16,
      "y": 14,
      "z": -14,
      "name": "Soil_Volcanic_Gravel"
    },
    {
      "x": -16,
      "y": 15,
      "z": -14,
      "name": "Rock_Magma_Cooled_Brick"
    },
    {
      "x": -16,
      "y": 16,
      "z": -14,
      "name": "Rock_Magma_Cooled_Brick_Pillar_Base"
    },
    {
      "x": -16,
      "y": 17,
      "z": -14,
      "name": "Rock_Magma_Cooled_Brick_Pillar_Middle"
    },
    {
      "x": -16,
      "y": 18,
      "z": -14,
      "name": "Rubble_Magma_Cooled_Medium"
    },
    {
      "x": -16,
      "y": 7,
      "z": -13,
      "name": "Rock_Volcanic"
    },
    {
      "x": -16,
      "y": 8,
      "z": -13,
      "name": "Rock_Volcanic"
    },
    {
      "x": -16,
      "y": 9,
      "z": -13,
      "name": "Rock_Volcanic"
    },
    {
      "x": -16,
      "y": 10,
      "z": -13,
      "name": "Rock_Volcanic_Cracked_Lava"
    },
    {
      "x": -16,
      "y": 11,
      "z": -13,
      "name": "Rock_Volcanic"
    },
    {
      "x": -16,
      "y": 12,
      "z": -13,
      "name": "Rock_Volcanic"
    },
    {
      "x": -16,
      "y": 13,
      "z": -13,
      "name": "Rock_Volcanic"
    },
    {
      "x": -16,
      "y": 14,
      "z": -13,
      "name": "Soil_Volcanic_Gravel"
    },
    {
      "x": -16,
      "y": 15,
      "z": -13,
      "name": "Soil_Volcanic_Gravel"
    },
    {
      "x": -16,
      "y": 16,
      "z": -13,
      "name": "Plant_Bramble_Dead_Twisted"
    },
    {
      "x": -16,
      "y": 7,
      "z": -12,
      "name": "Rock_Volcanic"
    },
    {
      "x": -16,
      "y": 8,
      "z": -12,
      "name": "Rock_Volcanic"
    },
    {
      "x": -16,
      "y": 9,
      "z": -12,
      "name": "Rock_Volcanic_Cracked_Lava"
    },
    {
      "x": -16,
      "y": 10,
      "z": -12,
      "name": "Rock_Volcanic"
    },
    {
      "x": -16,
      "y": 11,
      "z": -12,
      "name": "Rock_Volcanic"
    },
    {
      "x": -16,
      "y": 12,
      "z": -12,
      "name": "Soil_Volcanic_Gravel"
    },
    {
      "x": -16,
      "y": 13,
      "z": -12,
      "name": "Soil_Volcanic_Gravel"
    },
    {
      "x": -16,
      "y": 14,
      "z": -12,
      "name": "Soil_Volcanic_Gravel"
    },
    {
      "x": -16,
      "y": 15,
      "z": -12,
      "name": "Rock_Volcanic"
    },
    {
      "x": -16,
      "y": 11,
      "z": -11,
      "name": "Rock_Volcanic_Cracked_Lava"
    },
    {
      "x": -16,
      "y": 12,
      "z": -11,
      "name": "Soil_Volcanic_Gravel"
    },
    {
      "x": -16,
      "y": 13,
      "z": -11,
      "name": "Soil_Volcanic_Gravel"
    },
    {
      "x": -16,
      "y": 14,
      "z": -11,
      "name": "Soil_Volcanic_Gravel"
    },
    {
      "x": -16,
      "y": 30,
      "z": -10,
      "name": "Rock_Volcanic"
    },
    {
      "x": -16,
      "y": 23,
      "z": -9,
      "name": "Plant_Moss_Cave_Red"
    },
    {
      "x": -16,
      "y": 24,
      "z": -9,
      "name": "Rock_Volcanic"
    },
    {
      "x": -16,
      "y": 25,
      "z": -9,
      "name": "Rock_Volcanic"
    },
    {
      "x": -16,
      "y": 26,
      "z": -9,
      "name": "Rock_Volcanic"
    },
    {
      "x": -16,
      "y": 27,
      "z": -9,
      "name": "Rock_Volcanic"
    },
    {
      "x": -16,
      "y": 28,
      "z": -9,
      "name": "Rock_Volcanic_Cracked_Lava"
    },
    {
      "x": -16,
      "y": 29,
      "z": -9,
      "name": "Rock_Volcanic"
    },
    {
      "x": -16,
      "y": 30,
      "z": -9,
      "name": "Rock_Volcanic"
    },
    {
      "x": -16,
      "y": 31,
      "z": -9,
      "name": "Soil_Volcanic_Gravel"
    },
    {
      "x": -16,
      "y": 22,
      "z": -8,
      "name": "Rock_Volcanic"
    },
    {
      "x": -16,
      "y": 23,
      "z": -8,
      "name": "Rock_Volcanic"
    },
    {
      "x": -16,
      "y": 24,
      "z": -8,
      "name": "Rock_Volcanic"
    },
    {
      "x": -16,
      "y": 25,
      "z": -8,
      "name": "Rock_Volcanic"
    },
    {
      "x": -16,
      "y": 26,
      "z": -8,
      "name": "Rock_Volcanic"
    },
    {
      "x": -16,
      "y": 27,
      "z": -8,
      "name": "Rock_Volcanic"
    },
    {
      "x": -16,
      "y": 28,
      "z": -8,
      "name": "Rock_Volcanic"
    },
    {
      "x": -16,
      "y": 29,
      "z": -8,
      "name": "Rock_Volcanic"
    },
    {
      "x": -16,
      "y": 30,
      "z": -8,
      "name": "Rock_Volcanic"
    },
    {
      "x": -16,
      "y": 31,
      "z": -8,
      "name": "Rock_Volcanic"
    },
    {
      "x": -16,
      "y": 21,
      "z": -7,
      "name": "Rock_Volcanic"
    },
    {
      "x": -16,
      "y": 22,
      "z": -7,
      "name": "Rock_Volcanic"
    },
    {
      "x": -16,
      "y": 23,
      "z": -7,
      "name": "Rock_Volcanic"
    },
    {
      "x": -16,
      "y": 24,
      "z": -7,
      "name": "Rock_Volcanic"
    },
    {
      "x": -16,
      "y": 25,
      "z": -7,
      "name": "Rock_Volcanic"
    },
    {
      "x": -16,
      "y": 26,
      "z": -7,
      "name": "Rock_Volcanic"
    },
    {
      "x": -16,
      "y": 27,
      "z": -7,
      "name": "Rock_Volcanic"
    },
    {
      "x": -16,
      "y": 28,
      "z": -7,
      "name": "Rock_Volcanic"
    },
    {
      "x": -16,
      "y": 29,
      "z": -7,
      "name": "Rock_Volcanic"
    },
    {
      "x": -16,
      "y": 30,
      "z": -7,
      "name": "Rock_Volcanic"
    },
    {
      "x": -16,
      "y": 31,
      "z": -7,
      "name": "Rock_Volcanic"
    },
    {
      "x": -16,
      "y": 21,
      "z": -6,
      "name": "Rock_Volcanic"
    },
    {
      "x": -16,
      "y": 22,
      "z": -6,
      "name": "Rock_Volcanic"
    },
    {
      "x": -16,
      "y": 23,
      "z": -6,
      "name": "Rock_Volcanic"
    },
    {
      "x": -16,
      "y": 24,
      "z": -6,
      "name": "Rock_Volcanic"
    },
    {
      "x": -16,
      "y": 25,
      "z": -6,
      "name": "Rock_Volcanic"
    },
    {
      "x": -16,
      "y": 26,
      "z": -6,
      "name": "Rock_Volcanic"
    },
    {
      "x": -16,
      "y": 27,
      "z": -6,
      "name": "Rock_Volcanic"
    },
    {
      "x": -16,
      "y": 28,
      "z": -6,
      "name": "Rock_Volcanic"
    },
    {
      "x": -16,
      "y": 29,
      "z": -6,
      "name": "Rock_Volcanic"
    },
    {
      "x": -16,
      "y": 30,
      "z": -6,
      "name": "Rock_Volcanic"
    },
    {
      "x": -16,
      "y": 31,
      "z": -6,
      "name": "Rock_Volcanic"
    },
    {
      "x": -16,
      "y": 32,
      "z": -6,
      "name": "Soil_Volcanic_Gravel"
    },
    {
      "x": -16,
      "y": 21,
      "z": -5,
      "name": "Rock_Volcanic"
    },
    {
      "x": -16,
      "y": 22,
      "z": -5,
      "name": "Rock_Volcanic"
    },
    {
      "x": -16,
      "y": 23,
      "z": -5,
      "name": "Rock_Volcanic"
    },
    {
      "x": -16,
      "y": 24,
      "z": -5,
      "name": "Rock_Volcanic"
    },
    {
      "x": -16,
      "y": 25,
      "z": -5,
      "name": "Rock_Volcanic"
    },
    {
      "x": -16,
      "y": 26,
      "z": -5,
      "name": "Rock_Volcanic"
    },
    {
      "x": -16,
      "y": 27,
      "z": -5,
      "name": "Rock_Volcanic"
    },
    {
      "x": -16,
      "y": 28,
      "z": -5,
      "name": "Rock_Volcanic"
    },
    {
      "x": -16,
      "y": 29,
      "z": -5,
      "name": "Rock_Volcanic"
    },
    {
      "x": -16,
      "y": 30,
      "z": -5,
      "name": "Rock_Volcanic"
    },
    {
      "x": -16,
      "y": 31,
      "z": -5,
      "name": "Rock_Volcanic"
    },
    {
      "x": -16,
      "y": 32,
      "z": -5,
      "name": "Soil_Volcanic_Gravel"
    },
    {
      "x": -16,
      "y": 22,
      "z": -4,
      "name": "Rock_Volcanic"
    },
    {
      "x": -16,
      "y": 23,
      "z": -4,
      "name": "Rock_Volcanic"
    },
    {
      "x": -16,
      "y": 24,
      "z": -4,
      "name": "Rock_Volcanic"
    },
    {
      "x": -16,
      "y": 25,
      "z": -4,
      "name": "Rock_Volcanic"
    },
    {
      "x": -16,
      "y": 26,
      "z": -4,
      "name": "Rock_Volcanic"
    },
    {
      "x": -16,
      "y": 27,
      "z": -4,
      "name": "Rock_Volcanic"
    },
    {
      "x": -16,
      "y": 28,
      "z": -4,
      "name": "Rock_Volcanic"
    },
    {
      "x": -16,
      "y": 29,
      "z": -4,
      "name": "Rock_Volcanic"
    },
    {
      "x": -16,
      "y": 30,
      "z": -4,
      "name": "Rock_Volcanic_Cracked_Lava"
    },
    {
      "x": -16,
      "y": 31,
      "z": -4,
      "name": "Soil_Volcanic_Gravel"
    },
    {
      "x": -16,
      "y": 32,
      "z": -4,
      "name": "Soil_Volcanic_Gravel"
    },
    {
      "x": -16,
      "y": 33,
      "z": -4,
      "name": "Rock_Volcanic_Stalactite_Small"
    },
    {
      "x": -16,
      "y": 23,
      "z": -3,
      "name": "Rock_Volcanic"
    },
    {
      "x": -16,
      "y": 24,
      "z": -3,
      "name": "Rock_Volcanic"
    },
    {
      "x": -16,
      "y": 25,
      "z": -3,
      "name": "Rock_Volcanic_Cracked_Lava"
    },
    {
      "x": -16,
      "y": 26,
      "z": -3,
      "name": "Rock_Volcanic"
    },
    {
      "x": -16,
      "y": 27,
      "z": -3,
      "name": "Rock_Volcanic"
    },
    {
      "x": -16,
      "y": 28,
      "z": -3,
      "name": "Rock_Volcanic"
    },
    {
      "x": -16,
      "y": 29,
      "z": -3,
      "name": "Rock_Volcanic"
    },
    {
      "x": -16,
      "y": 30,
      "z": -3,
      "name": "Rock_Volcanic"
    },
    {
      "x": -16,
      "y": 31,
      "z": -3,
      "name": "Rock_Volcanic_Cracked_Lava"
    },
    {
      "x": -16,
      "y": 32,
      "z": -3,
      "name": "Soil_Volcanic_Gravel"
    },
    {
      "x": -16,
      "y": 23,
      "z": -2,
      "name": "Rock_Volcanic"
    },
    {
      "x": -16,
      "y": 24,
      "z": -2,
      "name": "Rock_Volcanic"
    },
    {
      "x": -16,
      "y": 25,
      "z": -2,
      "name": "Rock_Volcanic_Cracked_Lava"
    },
    {
      "x": -16,
      "y": 26,
      "z": -2,
      "name": "Rock_Volcanic"
    },
    {
      "x": -16,
      "y": 27,
      "z": -2,
      "name": "Rock_Volcanic"
    },
    {
      "x": -16,
      "y": 28,
      "z": -2,
      "name": "Rock_Volcanic"
    },
    {
      "x": -16,
      "y": 29,
      "z": -2,
      "name": "Rock_Volcanic"
    },
    {
      "x": -16,
      "y": 30,
      "z": -2,
      "name": "Soil_Volcanic_Gravel"
    },
    {
      "x": -16,
      "y": 31,
      "z": -2,
      "name": "Soil_Volcanic_Gravel"
    },
    {
      "x": -16,
      "y": 32,
      "z": -2,
      "name": "Plant_Crop_Wheat_Stage_4_Burnt"
    },
    {
      "x": -16,
      "y": 33,
      "z": -2,
      "name": "Plant_Crop_Wheat_Stage_4_Burnt",
      "filler": 1024
    },
    {
      "x": -16,
      "y": 50,
      "z": -2,
      "name": "Plant_Moss_Wall_Red",
      "rotation": 2
    },
    {
      "x": -16,
      "y": 51,
      "z": -2,
      "name": "Plant_Moss_Wall_Red",
      "rotation": 2
    },
    {
      "x": -16,
      "y": 53,
      "z": -2,
      "name": "Wood_Petrified_Trunk_Full"
    },
    {
      "x": -16,
      "y": 54,
      "z": -2,
      "name": "Wood_Petrified_Trunk_Full"
    },
    {
      "x": -16,
      "y": 55,
      "z": -2,
      "name": "Wood_Petrified_Trunk_Full"
    },
    {
      "x": -16,
      "y": 56,
      "z": -2,
      "name": "Wood_Petrified_Trunk_Full"
    },
    {
      "x": -16,
      "y": 57,
      "z": -2,
      "name": "Wood_Petrified_Trunk_Full"
    },
    {
      "x": -16,
      "y": 58,
      "z": -2,
      "name": "Wood_Petrified_Trunk_Full"
    },
    {
      "x": -16,
      "y": 59,
      "z": -2,
      "name": "Wood_Petrified_Trunk_Full"
    },
    {
      "x": -16,
      "y": 22,
      "z": -1,
      "name": "Rock_Volcanic"
    },
    {
      "x": -16,
      "y": 23,
      "z": -1,
      "name": "Rock_Volcanic"
    },
    {
      "x": -16,
      "y": 24,
      "z": -1,
      "name": "Rock_Volcanic"
    },
    {
      "x": -16,
      "y": 25,
      "z": -1,
      "name": "Rock_Volcanic"
    },
    {
      "x": -16,
      "y": 26,
      "z": -1,
      "name": "Rock_Volcanic"
    },
    {
      "x": -16,
      "y": 27,
      "z": -1,
      "name": "Rock_Volcanic"
    },
    {
      "x": -16,
      "y": 28,
      "z": -1,
      "name": "Rock_Volcanic"
    },
    {
      "x": -16,
      "y": 29,
      "z": -1,
      "name": "Rock_Volcanic_Cracked_Lava"
    },
    {
      "x": -16,
      "y": 30,
      "z": -1,
      "name": "Soil_Volcanic_Gravel"
    },
    {
      "x": -16,
      "y": 31,
      "z": -1,
      "name": "Soil_Volcanic_Gravel"
    },
    {
      "x": -16,
      "y": 50,
      "z": -1,
      "name": "Wood_Petrified_Trunk_Full"
    },
    {
      "x": -16,
      "y": 51,
      "z": -1,
      "name": "Wood_Petrified_Trunk_Full"
    },
    {
      "x": -16,
      "y": 52,
      "z": -1,
      "name": "Wood_Petrified_Trunk_Full"
    },
    {
      "x": -16,
      "y": 53,
      "z": -1,
      "name": "Wood_Petrified_Trunk_Full"
    },
    {
      "x": -16,
      "y": 59,
      "z": -1,
      "name": "Wood_Petrified_Trunk_Full"
    },
    {
      "x": -16,
      "y": 60,
      "z": -1,
      "name": "Wood_Petrified_Trunk_Full"
    },
    {
      "x": -16,
      "y": 23,
      "z": 0,
      "name": "Rock_Volcanic"
    },
    {
      "x": -16,
      "y": 24,
      "z": 0,
      "name": "Rock_Volcanic"
    },
    {
      "x": -16,
      "y": 25,
      "z": 0,
      "name": "Rock_Volcanic"
    },
    {
      "x": -16,
      "y": 26,
      "z": 0,
      "name": "Rock_Volcanic"
    },
    {
      "x": -16,
      "y": 27,
      "z": 0,
      "name": "Rock_Volcanic"
    },
    {
      "x": -16,
      "y": 28,
      "z": 0,
      "name": "Rock_Volcanic"
    },
    {
      "x": -16,
      "y": 29,
      "z": 0,
      "name": "Rock_Volcanic_Cracked_Lava"
    },
    {
      "x": -16,
      "y": 30,
      "z": 0,
      "name": "Soil_Volcanic_Gravel"
    },
    {
      "x": -16,
      "y": 31,
      "z": 0,
      "name": "Soil_Volcanic_Gravel"
    },
    {
      "x": -16,
      "y": 32,
      "z": 0,
      "name": "Plant_Bramble_Dead_Lavathorn"
    },
    {
      "x": -16,
      "y": 23,
      "z": 1,
      "name": "Rock_Volcanic_Cracked_Lava"
    },
    {
      "x": -16,
      "y": 24,
      "z": 1,
      "name": "Rock_Volcanic_Cracked_Lava"
    },
    {
      "x": -16,
      "y": 25,
      "z": 1,
      "name": "Rock_Volcanic"
    },
    {
      "x": -16,
      "y": 26,
      "z": 1,
      "name": "Rock_Volcanic"
    },
    {
      "x": -16,
      "y": 27,
      "z": 1,
      "name": "Rock_Volcanic"
    },
    {
      "x": -16,
      "y": 28,
      "z": 1,
      "name": "Rock_Volcanic"
    },
    {
      "x": -16,
      "y": 29,
      "z": 1,
      "name": "Soil_Volcanic_Gravel"
    },
    {
      "x": -16,
      "y": 30,
      "z": 1,
      "name": "Soil_Volcanic_Gravel"
    },
    {
      "x": -16,
      "y": 31,
      "z": 1,
      "name": "Plant_Bush_Dead_Tall"
    },
    {
      "x": -16,
      "y": 22,
      "z": 2,
      "name": "Plant_Moss_Cave_Red"
    },
    {
      "x": -16,
      "y": 23,
      "z": 2,
      "name": "Rock_Volcanic_Cracked_Lava"
    },
    {
      "x": -16,
      "y": 24,
      "z": 2,
      "name": "Rock_Volcanic_Cracked_Lava"
    },
    {
      "x": -16,
      "y": 25,
      "z": 2,
      "name": "Rock_Volcanic"
    },
    {
      "x": -16,
      "y": 26,
      "z": 2,
      "name": "Rock_Volcanic"
    },
    {
      "x": -16,
      "y": 27,
      "z": 2,
      "name": "Rock_Volcanic"
    },
    {
      "x": -16,
      "y": 28,
      "z": 2,
      "name": "Rock_Volcanic"
    },
    {
      "x": -16,
      "y": 29,
      "z": 2,
      "name": "Rock_Volcanic"
    },
    {
      "x": -16,
      "y": 30,
      "z": 2,
      "name": "Plant_Bush_Dead_Tall"
    },
    {
      "x": -16,
      "y": 46,
      "z": 2,
      "name": "Plant_Moss_Wall_Red",
      "rotation": 3
    },
    {
      "x": -16,
      "y": 47,
      "z": 2,
      "name": "Wood_Petrified_Trunk_Full"
    },
    {
      "x": -16,
      "y": 48,
      "z": 2,
      "name": "Plant_Moss_Rug_Red"
    },
    {
      "x": -16,
      "y": 23,
      "z": 3,
      "name": "Rock_Volcanic"
    },
    {
      "x": -16,
      "y": 24,
      "z": 3,
      "name": "Rock_Volcanic"
    },
    {
      "x": -16,
      "y": 25,
      "z": 3,
      "name": "Rock_Volcanic"
    },
    {
      "x": -16,
      "y": 26,
      "z": 3,
      "name": "Rock_Volcanic"
    },
    {
      "x": -16,
      "y": 27,
      "z": 3,
      "name": "Rock_Volcanic"
    },
    {
      "x": -16,
      "y": 28,
      "z": 3,
      "name": "Rock_Volcanic"
    },
    {
      "x": -16,
      "y": 45,
      "z": 3,
      "name": "Plant_Moss_Wall_Red",
      "rotation": 3
    },
    {
      "x": -16,
      "y": 46,
      "z": 3,
      "name": "Wood_Petrified_Trunk_Full"
    },
    {
      "x": -16,
      "y": 47,
      "z": 3,
      "name": "Plant_Moss_Rug_Red"
    },
    {
      "x": -16,
      "y": 45,
      "z": 4,
      "name": "Wood_Petrified_Trunk_Full"
    },
    {
      "x": -16,
      "y": 46,
      "z": 4,
      "name": "Wood_Petrified_Trunk_Full"
    },
    {
      "x": -16,
      "y": 47,
      "z": 4,
      "name": "Plant_Moss_Rug_Red"
    },
    {
      "x": -16,
      "y": 44,
      "z": 5,
      "name": "Plant_Moss_Cave_Red",
      "rotation": 8
    },
    {
      "x": -16,
      "y": 45,
      "z": 5,
      "name": "Wood_Petrified_Trunk_Full"
    },
    {
      "x": -16,
      "y": 46,
      "z": 5,
      "name": "Wood_Petrified_Trunk_Full"
    },
    {
      "x": -16,
      "y": 47,
      "z": 5,
      "name": "Plant_Moss_Rug_Red"
    },
    {
      "x": -16,
      "y": 44,
      "z": 6,
      "name": "Plant_Moss_Cave_Red",
      "rotation": 8
    },
    {
      "x": -16,
      "y": 45,
      "z": 6,
      "name": "Wood_Petrified_Trunk_Full"
    },
    {
      "x": -16,
      "y": 46,
      "z": 6,
      "name": "Wood_Petrified_Trunk_Full"
    },
    {
      "x": -16,
      "y": 47,
      "z": 6,
      "name": "Plant_Moss_Rug_Red"
    },
    {
      "x": -16,
      "y": 44,
      "z": 7,
      "name": "Plant_Moss_Cave_Red",
      "rotation": 8
    },
    {
      "x": -16,
      "y": 45,
      "z": 7,
      "name": "Wood_Petrified_Trunk_Full"
    },
    {
      "x": -16,
      "y": 46,
      "z": 7,
      "name": "Wood_Petrified_Trunk_Full"
    },
    {
      "x": -16,
      "y": 47,
      "z": 7,
      "name": "Plant_Moss_Rug_Red"
    },
    {
      "x": -16,
      "y": 44,
      "z": 8,
      "name": "Plant_Moss_Cave_Red",
      "rotation": 8
    },
    {
      "x": -16,
      "y": 45,
      "z": 8,
      "name": "Wood_Petrified_Trunk_Full"
    },
    {
      "x": -16,
      "y": 46,
      "z": 8,
      "name": "Wood_Petrified_Trunk_Full"
    },
    {
      "x": -16,
      "y": 47,
      "z": 8,
      "name": "Plant_Moss_Rug_Red"
    },
    {
      "x": -16,
      "y": 46,
      "z": 9,
      "name": "Wood_Petrified_Trunk_Full"
    },
    {
      "x": -16,
      "y": 47,
      "z": 9,
      "name": "Wood_Petrified_Trunk_Full"
    },
    {
      "x": -16,
      "y": 48,
      "z": 9,
      "name": "Plant_Moss_Rug_Red"
    },
    {
      "x": -16,
      "y": 46,
      "z": 10,
      "name": "Plant_Moss_Cave_Red",
      "rotation": 8
    },
    {
      "x": -16,
      "y": 47,
      "z": 10,
      "name": "Wood_Petrified_Trunk_Full"
    },
    {
      "x": -16,
      "y": 48,
      "z": 10,
      "name": "Plant_Moss_Rug_Red"
    },
    {
      "x": -16,
      "y": 47,
      "z": 11,
      "name": "Plant_Moss_Wall_Red",
      "rotation": 3
    },
    {
      "x": -16,
      "y": 48,
      "z": 11,
      "name": "Wood_Petrified_Trunk_Full"
    },
    {
      "x": -16,
      "y": 49,
      "z": 11,
      "name": "Wood_Petrified_Trunk_Full"
    },
    {
      "x": -16,
      "y": 49,
      "z": 12,
      "name": "Wood_Petrified_Trunk_Full"
    },
    {
      "x": -16,
      "y": 50,
      "z": 12,
      "name": "Wood_Petrified_Trunk_Full"
    },
    {
      "x": -16,
      "y": 51,
      "z": 12,
      "name": "Wood_Petrified_Trunk_Full"
    },
    {
      "x": -15,
      "y": 8,
      "z": -19,
      "name": "Rock_Volcanic_Stalactite_Large",
      "filler": 31744,
      "rotation": 8
    },
    {
      "x": -15,
      "y": 9,
      "z": -19,
      "name": "Rock_Volcanic_Stalactite_Large",
      "rotation": 8
    },
    {
      "x": -15,
      "y": 10,
      "z": -19,
      "name": "Rock_Volcanic"
    },
    {
      "x": -15,
      "y": 11,
      "z": -19,
      "name": "Rock_Volcanic"
    },
    {
      "x": -15,
      "y": 12,
      "z": -19,
      "name": "Rock_Volcanic"
    },
    {
      "x": -15,
      "y": 13,
      "z": -19,
      "name": "Soil_Volcanic_Gravel"
    },
    {
      "x": -15,
      "y": 14,
      "z": -19,
      "name": "Soil_Volcanic_Gravel"
    },
    {
      "x": -15,
      "y": 15,
      "z": -19,
      "name": "Plant_Bramble_Dead_Twisted"
    },
    {
      "x": -15,
      "y": 6,
      "z": -18,
      "name": "Rock_Volcanic_Stalactite_Large",
      "filler": 31744,
      "rotation": 8
    },
    {
      "x": -15,
      "y": 7,
      "z": -18,
      "name": "Rock_Volcanic_Stalactite_Large",
      "rotation": 8
    },
    {
      "x": -15,
      "y": 8,
      "z": -18,
      "name": "Rock_Volcanic_Cracked_Lava"
    },
    {
      "x": -15,
      "y": 9,
      "z": -18,
      "name": "Rock_Volcanic"
    },
    {
      "x": -15,
      "y": 10,
      "z": -18,
      "name": "Rock_Volcanic"
    },
    {
      "x": -15,
      "y": 11,
      "z": -18,
      "name": "Rock_Volcanic"
    },
    {
      "x": -15,
      "y": 12,
      "z": -18,
      "name": "Rock_Volcanic"
    },
    {
      "x": -15,
      "y": 13,
      "z": -18,
      "name": "Rock_Volcanic"
    },
    {
      "x": -15,
      "y": 14,
      "z": -18,
      "name": "Rock_Volcanic_Cracked_Lava"
    },
    {
      "x": -15,
      "y": 15,
      "z": -18,
      "name": "Soil_Volcanic_Gravel"
    },
    {
      "x": -15,
      "y": 2,
      "z": -17,
      "name": "Rock_Crystal_Red_Medium",
      "rotation": 6
    },
    {
      "x": -15,
      "y": 3,
      "z": -17,
      "name": "Rock_Crystal_Red_Medium",
      "rotation": 6
    },
    {
      "x": -15,
      "y": 4,
      "z": -17,
      "name": "Rock_Crystal_Red_Medium",
      "rotation": 6
    },
    {
      "x": -15,
      "y": 5,
      "z": -17,
      "name": "Rock_Crystal_Red_Medium",
      "rotation": 6
    },
    {
      "x": -15,
      "y": 6,
      "z": -17,
      "name": "Rock_Volcanic"
    },
    {
      "x": -15,
      "y": 7,
      "z": -17,
      "name": "Rock_Volcanic"
    },
    {
      "x": -15,
      "y": 8,
      "z": -17,
      "name": "Soil_Volcanic_Gravel"
    },
    {
      "x": -15,
      "y": 9,
      "z": -17,
      "name": "Rock_Volcanic"
    },
    {
      "x": -15,
      "y": 10,
      "z": -17,
      "name": "Rock_Volcanic"
    },
    {
      "x": -15,
      "y": 11,
      "z": -17,
      "name": "Rock_Volcanic"
    },
    {
      "x": -15,
      "y": 12,
      "z": -17,
      "name": "Rock_Volcanic_Cracked_Lava"
    },
    {
      "x": -15,
      "y": 13,
      "z": -17,
      "name": "Rock_Volcanic_Cracked_Lava"
    },
    {
      "x": -15,
      "y": 14,
      "z": -17,
      "name": "Soil_Volcanic_Gravel"
    },
    {
      "x": -15,
      "y": 15,
      "z": -17,
      "name": "Rock_Magma_Cooled_Brick"
    },
    {
      "x": -15,
      "y": 1,
      "z": -16,
      "name": "Rock_Crystal_Red_Large",
      "rotation": 8
    },
    {
      "x": -15,
      "y": 2,
      "z": -16,
      "name": "Rock_Crystal_Red_Block"
    },
    {
      "x": -15,
      "y": 3,
      "z": -16,
      "name": "Rock_Crystal_Red_Block"
    },
    {
      "x": -15,
      "y": 4,
      "z": -16,
      "name": "Rock_Crystal_Red_Block"
    },
    {
      "x": -15,
      "y": 5,
      "z": -16,
      "name": "Rock_Crystal_Red_Block"
    },
    {
      "x": -15,
      "y": 6,
      "z": -16,
      "name": "Rock_Volcanic"
    },
    {
      "x": -15,
      "y": 7,
      "z": -16,
      "name": "Rock_Volcanic"
    },
    {
      "x": -15,
      "y": 8,
      "z": -16,
      "name": "Rock_Volcanic"
    },
    {
      "x": -15,
      "y": 9,
      "z": -16,
      "name": "Rock_Volcanic_Cracked_Lava"
    },
    {
      "x": -15,
      "y": 10,
      "z": -16,
      "name": "Rock_Volcanic"
    },
    {
      "x": -15,
      "y": 11,
      "z": -16,
      "name": "Rock_Volcanic"
    },
    {
      "x": -15,
      "y": 12,
      "z": -16,
      "name": "Soil_Volcanic_Gravel"
    },
    {
      "x": -15,
      "y": 13,
      "z": -16,
      "name": "Soil_Volcanic_Gravel"
    },
    {
      "x": -15,
      "y": 14,
      "z": -16,
      "name": "Rock_Volcanic_Cracked_Lava"
    },
    {
      "x": -15,
      "y": 15,
      "z": -16,
      "name": "Rock_Magma_Cooled_Brick"
    },
    {
      "x": -15,
      "y": 0,
      "z": -15,
      "name": "Rock_Crystal_Red_Large",
      "rotation": 8
    },
    {
      "x": -15,
      "y": 1,
      "z": -15,
      "name": "Rock_Crystal_Red_Block"
    },
    {
      "x": -15,
      "y": 2,
      "z": -15,
      "name": "Rock_Crystal_Red_Block"
    },
    {
      "x": -15,
      "y": 3,
      "z": -15,
      "name": "Rock_Crystal_Red_Block"
    },
    {
      "x": -15,
      "y": 4,
      "z": -15,
      "name": "Rock_Volcanic_Cracked_Lava"
    },
    {
      "x": -15,
      "y": 5,
      "z": -15,
      "name": "Rock_Volcanic"
    },
    {
      "x": -15,
      "y": 6,
      "z": -15,
      "name": "Rock_Crystal_Red_Block",
      "rotation": 4
    },
    {
      "x": -15,
      "y": 7,
      "z": -15,
      "name": "Rock_Volcanic"
    },
    {
      "x": -15,
      "y": 8,
      "z": -15,
      "name": "Soil_Dirt"
    },
    {
      "x": -15,
      "y": 9,
      "z": -15,
      "name": "Spawn_Labyrinth_Red_Circle"
    },
    {
      "x": -15,
      "y": 10,
      "z": -15,
      "name": "Rock_Volcanic"
    },
    {
      "x": -15,
      "y": 11,
      "z": -15,
      "name": "Rock_Volcanic"
    },
    {
      "x": -15,
      "y": 12,
      "z": -15,
      "name": "Rock_Volcanic"
    },
    {
      "x": -15,
      "y": 13,
      "z": -15,
      "name": "Rock_Volcanic"
    },
    {
      "x": -15,
      "y": 14,
      "z": -15,
      "name": "Soil_Volcanic_Gravel"
    },
    {
      "x": -15,
      "y": 15,
      "z": -15,
      "name": "Rock_Magma_Cooled_Brick"
    },
    {
      "x": -15,
      "y": 1,
      "z": -14,
      "name": "Rock_Crystal_Red_Large",
      "rotation": 4
    },
    {
      "x": -15,
      "y": 2,
      "z": -14,
      "name": "Rock_Crystal_Red_Large",
      "rotation": 4
    },
    {
      "x": -15,
      "y": 3,
      "z": -14,
      "name": "Rock_Crystal_Red_Block"
    },
    {
      "x": -15,
      "y": 4,
      "z": -14,
      "name": "Rock_Crystal_Red_Block"
    },
    {
      "x": -15,
      "y": 5,
      "z": -14,
      "name": "Rock_Crystal_Red_Block"
    },
    {
      "x": -15,
      "y": 6,
      "z": -14,
      "name": "Rock_Crystal_Red_Block"
    },
    {
      "x": -15,
      "y": 7,
      "z": -14,
      "name": "Rock_Crystal_Red_Block"
    },
    {
      "x": -15,
      "y": 8,
      "z": -14,
      "name": "Rock_Volcanic"
    },
    {
      "x": -15,
      "y": 9,
      "z": -14,
      "name": "Rock_Volcanic_Cracked_Lava"
    },
    {
      "x": -15,
      "y": 10,
      "z": -14,
      "name": "Rock_Volcanic_Cracked_Lava"
    },
    {
      "x": -15,
      "y": 11,
      "z": -14,
      "name": "Rock_Volcanic"
    },
    {
      "x": -15,
      "y": 12,
      "z": -14,
      "name": "Soil_Volcanic_Gravel"
    },
    {
      "x": -15,
      "y": 13,
      "z": -14,
      "name": "Rock_Volcanic_Cracked_Lava"
    },
    {
      "x": -15,
      "y": 14,
      "z": -14,
      "name": "Rock_Magma_Cooled_Brick"
    },
    {
      "x": -15,
      "y": 15,
      "z": -14,
      "name": "Rock_Magma_Cooled_Brick"
    },
    {
      "x": -15,
      "y": 4,
      "z": -13,
      "name": "Rock_Crystal_Red_Large",
      "rotation": 4
    },
    {
      "x": -15,
      "y": 5,
      "z": -13,
      "name": "Rock_Volcanic"
    },
    {
      "x": -15,
      "y": 6,
      "z": -13,
      "name": "Rock_Volcanic"
    },
    {
      "x": -15,
      "y": 7,
      "z": -13,
      "name": "Rock_Volcanic"
    },
    {
      "x": -15,
      "y": 8,
      "z": -13,
      "name": "Rock_Volcanic"
    },
    {
      "x": -15,
      "y": 9,
      "z": -13,
      "name": "Rock_Volcanic"
    },
    {
      "x": -15,
      "y": 10,
      "z": -13,
      "name": "Rock_Volcanic"
    },
    {
      "x": -15,
      "y": 11,
      "z": -13,
      "name": "Rock_Volcanic_Cracked_Lava"
    },
    {
      "x": -15,
      "y": 12,
      "z": -13,
      "name": "Soil_Volcanic_Gravel"
    },
    {
      "x": -15,
      "y": 13,
      "z": -13,
      "name": "Rock_Volcanic"
    },
    {
      "x": -15,
      "y": 14,
      "z": -13,
      "name": "Rock_Volcanic"
    },
    {
      "x": -15,
      "y": 15,
      "z": -13,
      "name": "Rock_Volcanic"
    },
    {
      "x": -15,
      "y": 6,
      "z": -12,
      "name": "Rock_Volcanic"
    },
    {
      "x": -15,
      "y": 7,
      "z": -12,
      "name": "Rock_Volcanic"
    },
    {
      "x": -15,
      "y": 8,
      "z": -12,
      "name": "Rock_Volcanic"
    },
    {
      "x": -15,
      "y": 9,
      "z": -12,
      "name": "Rock_Volcanic"
    },
    {
      "x": -15,
      "y": 10,
      "z": -12,
      "name": "Rock_Volcanic"
    },
    {
      "x": -15,
      "y": 11,
      "z": -12,
      "name": "Rock_Volcanic"
    },
    {
      "x": -15,
      "y": 12,
      "z": -12,
      "name": "Rock_Volcanic"
    },
    {
      "x": -15,
      "y": 13,
      "z": -12,
      "name": "Soil_Volcanic_Gravel"
    },
    {
      "x": -15,
      "y": 14,
      "z": -12,
      "name": "Rock_Volcanic_Cracked_Lava"
    },
    {
      "x": -15,
      "y": 15,
      "z": -12,
      "name": "Soil_Volcanic_Gravel"
    },
    {
      "x": -15,
      "y": 10,
      "z": -11,
      "name": "Rock_Volcanic_Cracked_Lava"
    },
    {
      "x": -15,
      "y": 11,
      "z": -11,
      "name": "Rock_Volcanic_Cracked_Lava"
    },
    {
      "x": -15,
      "y": 12,
      "z": -11,
      "name": "Rock_Volcanic"
    },
    {
      "x": -15,
      "y": 13,
      "z": -11,
      "name": "Soil_Volcanic_Gravel"
    },
    {
      "x": -15,
      "y": 14,
      "z": -11,
      "name": "Soil_Volcanic_Gravel"
    },
    {
      "x": -15,
      "y": 15,
      "z": -11,
      "name": "Plant_Bramble_Dead_Twisted"
    },
    {
      "x": -15,
      "y": 24,
      "z": -10,
      "name": "Rock_Volcanic"
    },
    {
      "x": -15,
      "y": 25,
      "z": -10,
      "name": "Rock_Volcanic"
    },
    {
      "x": -15,
      "y": 26,
      "z": -10,
      "name": "Rock_Volcanic"
    },
    {
      "x": -15,
      "y": 27,
      "z": -10,
      "name": "Rock_Volcanic"
    },
    {
      "x": -15,
      "y": 28,
      "z": -10,
      "name": "Rock_Volcanic"
    },
    {
      "x": -15,
      "y": 29,
      "z": -10,
      "name": "Rock_Volcanic"
    },
    {
      "x": -15,
      "y": 30,
      "z": -10,
      "name": "Rock_Volcanic"
    },
    {
      "x": -15,
      "y": 31,
      "z": -10,
      "name": "Rock_Volcanic"
    },
    {
      "x": -15,
      "y": 22,
      "z": -9,
      "name": "Rock_Volcanic"
    },
    {
      "x": -15,
      "y": 23,
      "z": -9,
      "name": "Rock_Volcanic"
    },
    {
      "x": -15,
      "y": 24,
      "z": -9,
      "name": "Rock_Volcanic"
    },
    {
      "x": -15,
      "y": 25,
      "z": -9,
      "name": "Rock_Volcanic"
    },
    {
      "x": -15,
      "y": 26,
      "z": -9,
      "name": "Rock_Volcanic"
    },
    {
      "x": -15,
      "y": 27,
      "z": -9,
      "name": "Rock_Volcanic"
    },
    {
      "x": -15,
      "y": 28,
      "z": -9,
      "name": "Rock_Volcanic"
    },
    {
      "x": -15,
      "y": 29,
      "z": -9,
      "name": "Rock_Volcanic"
    },
    {
      "x": -15,
      "y": 30,
      "z": -9,
      "name": "Rock_Volcanic"
    },
    {
      "x": -15,
      "y": 31,
      "z": -9,
      "name": "Rock_Volcanic_Cracked_Lava"
    },
    {
      "x": -15,
      "y": 32,
      "z": -9,
      "name": "Soil_Volcanic_Gravel"
    },
    {
      "x": -15,
      "y": 33,
      "z": -9,
      "name": "Plant_Bramble_Dead_Lavathorn"
    },
    {
      "x": -15,
      "y": 20,
      "z": -8,
      "name": "Rock_Volcanic"
    },
    {
      "x": -15,
      "y": 21,
      "z": -8,
      "name": "Rock_Volcanic"
    },
    {
      "x": -15,
      "y": 22,
      "z": -8,
      "name": "Rock_Volcanic"
    },
    {
      "x": -15,
      "y": 23,
      "z": -8,
      "name": "Rock_Volcanic"
    },
    {
      "x": -15,
      "y": 24,
      "z": -8,
      "name": "Rock_Volcanic"
    },
    {
      "x": -15,
      "y": 25,
      "z": -8,
      "name": "Rock_Volcanic"
    },
    {
      "x": -15,
      "y": 26,
      "z": -8,
      "name": "Rock_Volcanic"
    },
    {
      "x": -15,
      "y": 27,
      "z": -8,
      "name": "Rock_Volcanic"
    },
    {
      "x": -15,
      "y": 28,
      "z": -8,
      "name": "Rock_Volcanic"
    },
    {
      "x": -15,
      "y": 29,
      "z": -8,
      "name": "Rock_Volcanic"
    },
    {
      "x": -15,
      "y": 30,
      "z": -8,
      "name": "Rock_Volcanic"
    },
    {
      "x": -15,
      "y": 31,
      "z": -8,
      "name": "Soil_Volcanic_Gravel"
    },
    {
      "x": -15,
      "y": 32,
      "z": -8,
      "name": "Soil_Volcanic_Gravel"
    },
    {
      "x": -15,
      "y": 33,
      "z": -8,
      "name": "Plant_Bush_Dead_Tall"
    },
    {
      "x": -15,
      "y": 19,
      "z": -7,
      "name": "Rock_Volcanic"
    },
    {
      "x": -15,
      "y": 20,
      "z": -7,
      "name": "Rock_Volcanic"
    },
    {
      "x": -15,
      "y": 21,
      "z": -7,
      "name": "Rock_Volcanic"
    },
    {
      "x": -15,
      "y": 22,
      "z": -7,
      "name": "Rock_Volcanic"
    },
    {
      "x": -15,
      "y": 23,
      "z": -7,
      "name": "Rock_Volcanic"
    },
    {
      "x": -15,
      "y": 24,
      "z": -7,
      "name": "Rock_Volcanic"
    },
    {
      "x": -15,
      "y": 25,
      "z": -7,
      "name": "Rock_Volcanic"
    },
    {
      "x": -15,
      "y": 26,
      "z": -7,
      "name": "Rock_Volcanic"
    },
    {
      "x": -15,
      "y": 27,
      "z": -7,
      "name": "Rock_Volcanic"
    },
    {
      "x": -15,
      "y": 28,
      "z": -7,
      "name": "Rock_Volcanic"
    },
    {
      "x": -15,
      "y": 29,
      "z": -7,
      "name": "Rock_Volcanic"
    },
    {
      "x": -15,
      "y": 30,
      "z": -7,
      "name": "Rock_Volcanic"
    },
    {
      "x": -15,
      "y": 31,
      "z": -7,
      "name": "Soil_Volcanic_Gravel"
    },
    {
      "x": -15,
      "y": 32,
      "z": -7,
      "name": "Soil_Volcanic_Gravel"
    },
    {
      "x": -15,
      "y": 18,
      "z": -6,
      "name": "Rock_Volcanic"
    },
    {
      "x": -15,
      "y": 19,
      "z": -6,
      "name": "Rock_Volcanic"
    },
    {
      "x": -15,
      "y": 20,
      "z": -6,
      "name": "Rock_Volcanic"
    },
    {
      "x": -15,
      "y": 21,
      "z": -6,
      "name": "Rock_Volcanic"
    },
    {
      "x": -15,
      "y": 22,
      "z": -6,
      "name": "Rock_Volcanic"
    },
    {
      "x": -15,
      "y": 23,
      "z": -6,
      "name": "Rock_Volcanic"
    },
    {
      "x": -15,
      "y": 24,
      "z": -6,
      "name": "Rock_Volcanic"
    },
    {
      "x": -15,
      "y": 25,
      "z": -6,
      "name": "Rock_Volcanic"
    },
    {
      "x": -15,
      "y": 26,
      "z": -6,
      "name": "Rock_Volcanic"
    },
    {
      "x": -15,
      "y": 27,
      "z": -6,
      "name": "Rock_Volcanic"
    },
    {
      "x": -15,
      "y": 28,
      "z": -6,
      "name": "Rock_Volcanic"
    },
    {
      "x": -15,
      "y": 29,
      "z": -6,
      "name": "Rock_Volcanic"
    },
    {
      "x": -15,
      "y": 30,
      "z": -6,
      "name": "Rock_Volcanic"
    },
    {
      "x": -15,
      "y": 31,
      "z": -6,
      "name": "Soil_Volcanic_Gravel"
    },
    {
      "x": -15,
      "y": 32,
      "z": -6,
      "name": "Soil_Volcanic_Gravel"
    },
    {
      "x": -15,
      "y": 33,
      "z": -6,
      "name": "Plant_Bramble_Dead_Lavathorn"
    },
    {
      "x": -15,
      "y": 16,
      "z": -5,
      "name": "Rock_Crystal_Red_Medium",
      "rotation": 7
    },
    {
      "x": -15,
      "y": 18,
      "z": -5,
      "name": "Rock_Volcanic"
    },
    {
      "x": -15,
      "y": 19,
      "z": -5,
      "name": "Rock_Volcanic"
    },
    {
      "x": -15,
      "y": 20,
      "z": -5,
      "name": "Rock_Volcanic"
    },
    {
      "x": -15,
      "y": 21,
      "z": -5,
      "name": "Rock_Volcanic"
    },
    {
      "x": -15,
      "y": 22,
      "z": -5,
      "name": "Rock_Volcanic"
    },
    {
      "x": -15,
      "y": 23,
      "z": -5,
      "name": "Rock_Volcanic"
    },
    {
      "x": -15,
      "y": 24,
      "z": -5,
      "name": "Rock_Volcanic"
    },
    {
      "x": -15,
      "y": 25,
      "z": -5,
      "name": "Rock_Volcanic"
    },
    {
      "x": -15,
      "y": 26,
      "z": -5,
      "name": "Rock_Volcanic"
    },
    {
      "x": -15,
      "y": 27,
      "z": -5,
      "name": "Rock_Volcanic"
    },
    {
      "x": -15,
      "y": 28,
      "z": -5,
      "name": "Rock_Volcanic"
    },
    {
      "x": -15,
      "y": 29,
      "z": -5,
      "name": "Rock_Volcanic"
    },
    {
      "x": -15,
      "y": 30,
      "z": -5,
      "name": "Rock_Volcanic"
    },
    {
      "x": -15,
      "y": 31,
      "z": -5,
      "name": "Rock_Volcanic_Cracked_Lava"
    },
    {
      "x": -15,
      "y": 32,
      "z": -5,
      "name": "Soil_Volcanic_Gravel"
    },
    {
      "x": -15,
      "y": 33,
      "z": -5,
      "name": "Rubble_Volcanic_Medium"
    },
    {
      "x": -15,
      "y": 20,
      "z": -4,
      "name": "Rock_Volcanic"
    },
    {
      "x": -15,
      "y": 21,
      "z": -4,
      "name": "Rock_Volcanic"
    },
    {
      "x": -15,
      "y": 22,
      "z": -4,
      "name": "Rock_Volcanic"
    },
    {
      "x": -15,
      "y": 23,
      "z": -4,
      "name": "Rock_Volcanic"
    },
    {
      "x": -15,
      "y": 24,
      "z": -4,
      "name": "Rock_Volcanic"
    },
    {
      "x": -15,
      "y": 25,
      "z": -4,
      "name": "Rock_Volcanic"
    },
    {
      "x": -15,
      "y": 26,
      "z": -4,
      "name": "Rock_Volcanic"
    },
    {
      "x": -15,
      "y": 27,
      "z": -4,
      "name": "Rock_Volcanic"
    },
    {
      "x": -15,
      "y": 28,
      "z": -4,
      "name": "Rock_Volcanic"
    },
    {
      "x": -15,
      "y": 29,
      "z": -4,
      "name": "Rock_Volcanic"
    },
    {
      "x": -15,
      "y": 30,
      "z": -4,
      "name": "Soil_Volcanic_Gravel"
    },
    {
      "x": -15,
      "y": 31,
      "z": -4,
      "name": "Soil_Volcanic_Gravel"
    },
    {
      "x": -15,
      "y": 32,
      "z": -4,
      "name": "Soil_Volcanic_Gravel"
    },
    {
      "x": -15,
      "y": 21,
      "z": -3,
      "name": "Rock_Volcanic"
    },
    {
      "x": -15,
      "y": 22,
      "z": -3,
      "name": "Rock_Volcanic"
    },
    {
      "x": -15,
      "y": 23,
      "z": -3,
      "name": "Rock_Volcanic"
    },
    {
      "x": -15,
      "y": 24,
      "z": -3,
      "name": "Rock_Volcanic"
    },
    {
      "x": -15,
      "y": 25,
      "z": -3,
      "name": "Rock_Volcanic"
    },
    {
      "x": -15,
      "y": 26,
      "z": -3,
      "name": "Rock_Volcanic"
    },
    {
      "x": -15,
      "y": 27,
      "z": -3,
      "name": "Rock_Volcanic"
    },
    {
      "x": -15,
      "y": 28,
      "z": -3,
      "name": "Rock_Volcanic"
    },
    {
      "x": -15,
      "y": 29,
      "z": -3,
      "name": "Rock_Volcanic"
    },
    {
      "x": -15,
      "y": 30,
      "z": -3,
      "name": "Rock_Volcanic_Cracked_Lava"
    },
    {
      "x": -15,
      "y": 31,
      "z": -3,
      "name": "Soil_Volcanic_Gravel"
    },
    {
      "x": -15,
      "y": 32,
      "z": -3,
      "name": "Rock_Volcanic"
    },
    {
      "x": -15,
      "y": 33,
      "z": -3,
      "name": "Rubble_Volcanic_Medium"
    },
    {
      "x": -15,
      "y": 20,
      "z": -2,
      "name": "Rock_Volcanic"
    },
    {
      "x": -15,
      "y": 21,
      "z": -2,
      "name": "Rock_Volcanic"
    },
    {
      "x": -15,
      "y": 22,
      "z": -2,
      "name": "Rock_Volcanic"
    },
    {
      "x": -15,
      "y": 23,
      "z": -2,
      "name": "Rock_Volcanic"
    },
    {
      "x": -15,
      "y": 24,
      "z": -2,
      "name": "Rock_Volcanic"
    },
    {
      "x": -15,
      "y": 25,
      "z": -2,
      "name": "Rock_Volcanic"
    },
    {
      "x": -15,
      "y": 26,
      "z": -2,
      "name": "Rock_Volcanic"
    },
    {
      "x": -15,
      "y": 27,
      "z": -2,
      "name": "Rock_Volcanic"
    },
    {
      "x": -15,
      "y": 28,
      "z": -2,
      "name": "Rock_Volcanic"
    },
    {
      "x": -15,
      "y": 29,
      "z": -2,
      "name": "Soil_Volcanic_Gravel"
    },
    {
      "x": -15,
      "y": 30,
      "z": -2,
      "name": "Rock_Volcanic_Cracked_Lava"
    },
    {
      "x": -15,
      "y": 31,
      "z": -2,
      "name": "Rock_Volcanic"
    },
    {
      "x": -15,
      "y": 32,
      "z": -2,
      "name": "Soil_Volcanic_Gravel"
    },
    {
      "x": -15,
      "y": 33,
      "z": -2,
      "name": "Plant_Crop_Wheat_Stage_4_Burnt"
    },
    {
      "x": -15,
      "y": 34,
      "z": -2,
      "name": "Plant_Crop_Wheat_Stage_4_Burnt",
      "filler": 1024
    },
    {
      "x": -15,
      "y": 50,
      "z": -2,
      "name": "Plant_Moss_Wall_Red",
      "rotation": 2
    },
    {
      "x": -15,
      "y": 52,
      "z": -2,
      "name": "Wood_Petrified_Trunk_Full"
    },
    {
      "x": -15,
      "y": 53,
      "z": -2,
      "name": "Wood_Petrified_Trunk_Full"
    },
    {
      "x": -15,
      "y": 54,
      "z": -2,
      "name": "Wood_Petrified_Trunk_Full"
    },
    {
      "x": -15,
      "y": 55,
      "z": -2,
      "name": "Wood_Petrified_Trunk_Full"
    },
    {
      "x": -15,
      "y": 56,
      "z": -2,
      "name": "Wood_Petrified_Trunk_Full"
    },
    {
      "x": -15,
      "y": 57,
      "z": -2,
      "name": "Wood_Petrified_Trunk_Full"
    },
    {
      "x": -15,
      "y": 58,
      "z": -2,
      "name": "Wood_Petrified_Trunk_Full"
    },
    {
      "x": -15,
      "y": 20,
      "z": -1,
      "name": "Plant_Moss_Cave_Red"
    },
    {
      "x": -15,
      "y": 21,
      "z": -1,
      "name": "Rock_Volcanic"
    },
    {
      "x": -15,
      "y": 22,
      "z": -1,
      "name": "Rock_Volcanic"
    },
    {
      "x": -15,
      "y": 23,
      "z": -1,
      "name": "Rock_Volcanic"
    },
    {
      "x": -15,
      "y": 24,
      "z": -1,
      "name": "Rock_Volcanic"
    },
    {
      "x": -15,
      "y": 25,
      "z": -1,
      "name": "Rock_Volcanic"
    },
    {
      "x": -15,
      "y": 26,
      "z": -1,
      "name": "Rock_Volcanic"
    },
    {
      "x": -15,
      "y": 27,
      "z": -1,
      "name": "Rock_Volcanic"
    },
    {
      "x": -15,
      "y": 28,
      "z": -1,
      "name": "Rock_Volcanic"
    },
    {
      "x": -15,
      "y": 29,
      "z": -1,
      "name": "Rock_Volcanic"
    },
    {
      "x": -15,
      "y": 30,
      "z": -1,
      "name": "Soil_Volcanic_Gravel"
    },
    {
      "x": -15,
      "y": 31,
      "z": -1,
      "name": "Soil_Volcanic_Gravel"
    },
    {
      "x": -15,
      "y": 32,
      "z": -1,
      "name": "Soil_Volcanic_Gravel"
    },
    {
      "x": -15,
      "y": 33,
      "z": -1,
      "name": "Plant_Crop_Wheat_Stage_4_Burnt"
    },
    {
      "x": -15,
      "y": 34,
      "z": -1,
      "name": "Plant_Crop_Wheat_Stage_4_Burnt",
      "filler": 1024
    },
    {
      "x": -15,
      "y": 49,
      "z": -1,
      "name": "Plant_Moss_Wall_Red",
      "rotation": 3
    },
    {
      "x": -15,
      "y": 50,
      "z": -1,
      "name": "Wood_Petrified_Trunk_Full"
    },
    {
      "x": -15,
      "y": 51,
      "z": -1,
      "name": "Wood_Petrified_Trunk_Full"
    },
    {
      "x": -15,
      "y": 52,
      "z": -1,
      "name": "Wood_Petrified_Trunk_Full"
    },
    {
      "x": -15,
      "y": 58,
      "z": -1,
      "name": "Wood_Petrified_Trunk_Full"
    },
    {
      "x": -15,
      "y": 59,
      "z": -1,
      "name": "Wood_Petrified_Trunk_Full"
    },
    {
      "x": -15,
      "y": 60,
      "z": -1,
      "name": "Wood_Petrified_Trunk_Full"
    },
    {
      "x": -15,
      "y": 22,
      "z": 0,
      "name": "Rock_Volcanic"
    },
    {
      "x": -15,
      "y": 23,
      "z": 0,
      "name": "Rock_Volcanic"
    },
    {
      "x": -15,
      "y": 24,
      "z": 0,
      "name": "Rock_Volcanic"
    },
    {
      "x": -15,
      "y": 25,
      "z": 0,
      "name": "Rock_Volcanic"
    },
    {
      "x": -15,
      "y": 26,
      "z": 0,
      "name": "Rock_Volcanic"
    },
    {
      "x": -15,
      "y": 27,
      "z": 0,
      "name": "Rock_Volcanic"
    },
    {
      "x": -15,
      "y": 28,
      "z": 0,
      "name": "Rock_Volcanic"
    },
    {
      "x": -15,
      "y": 29,
      "z": 0,
      "name": "Rock_Volcanic"
    },
    {
      "x": -15,
      "y": 30,
      "z": 0,
      "name": "Soil_Volcanic_Gravel"
    },
    {
      "x": -15,
      "y": 31,
      "z": 0,
      "name": "Soil_Volcanic_Gravel"
    },
    {
      "x": -15,
      "y": 49,
      "z": 0,
      "name": "Plant_Moss_Wall_Red",
      "rotation": 3
    },
    {
      "x": -15,
      "y": 50,
      "z": 0,
      "name": "Plant_Moss_Wall_Red"
    },
    {
      "x": -15,
      "y": 60,
      "z": 0,
      "name": "Wood_Petrified_Trunk_Full"
    },
    {
      "x": -15,
      "y": 61,
      "z": 0,
      "name": "Wood_Petrified_Trunk_Full"
    },
    {
      "x": -15,
      "y": 20,
      "z": 1,
      "name": "Rock_Volcanic"
    },
    {
      "x": -15,
      "y": 21,
      "z": 1,
      "name": "Rock_Volcanic"
    },
    {
      "x": -15,
      "y": 22,
      "z": 1,
      "name": "Rock_Volcanic"
    },
    {
      "x": -15,
      "y": 23,
      "z": 1,
      "name": "Rock_Volcanic"
    },
    {
      "x": -15,
      "y": 24,
      "z": 1,
      "name": "Rock_Volcanic_Cracked_Lava"
    },
    {
      "x": -15,
      "y": 25,
      "z": 1,
      "name": "Rock_Volcanic"
    },
    {
      "x": -15,
      "y": 26,
      "z": 1,
      "name": "Rock_Volcanic"
    },
    {
      "x": -15,
      "y": 27,
      "z": 1,
      "name": "Rock_Volcanic"
    },
    {
      "x": -15,
      "y": 28,
      "z": 1,
      "name": "Rock_Volcanic"
    },
    {
      "x": -15,
      "y": 29,
      "z": 1,
      "name": "Soil_Volcanic_Gravel"
    },
    {
      "x": -15,
      "y": 30,
      "z": 1,
      "name": "Rock_Volcanic_Cracked_Lava"
    },
    {
      "x": -15,
      "y": 31,
      "z": 1,
      "name": "Soil_Volcanic_Gravel"
    },
    {
      "x": -15,
      "y": 32,
      "z": 1,
      "name": "Rubble_Volcanic"
    },
    {
      "x": -15,
      "y": 47,
      "z": 1,
      "name": "Plant_Moss_Wall_Red",
      "rotation": 3
    },
    {
      "x": -15,
      "y": 48,
      "z": 1,
      "name": "Plant_Moss_Wall_Red",
      "rotation": 3
    },
    {
      "x": -15,
      "y": 61,
      "z": 1,
      "name": "Wood_Petrified_Trunk_Full"
    },
    {
      "x": -15,
      "y": 21,
      "z": 2,
      "name": "Rock_Volcanic"
    },
    {
      "x": -15,
      "y": 22,
      "z": 2,
      "name": "Rock_Volcanic"
    },
    {
      "x": -15,
      "y": 23,
      "z": 2,
      "name": "Rock_Volcanic"
    },
    {
      "x": -15,
      "y": 24,
      "z": 2,
      "name": "Rock_Volcanic"
    },
    {
      "x": -15,
      "y": 25,
      "z": 2,
      "name": "Rock_Volcanic"
    },
    {
      "x": -15,
      "y": 26,
      "z": 2,
      "name": "Rock_Volcanic"
    },
    {
      "x": -15,
      "y": 27,
      "z": 2,
      "name": "Rock_Volcanic"
    },
    {
      "x": -15,
      "y": 28,
      "z": 2,
      "name": "Rock_Volcanic"
    },
    {
      "x": -15,
      "y": 29,
      "z": 2,
      "name": "Rock_Volcanic_Cracked_Lava"
    },
    {
      "x": -15,
      "y": 30,
      "z": 2,
      "name": "Soil_Volcanic_Gravel"
    },
    {
      "x": -15,
      "y": 46,
      "z": 2,
      "name": "Wood_Petrified_Trunk_Full"
    },
    {
      "x": -15,
      "y": 47,
      "z": 2,
      "name": "Wood_Petrified_Trunk_Full"
    },
    {
      "x": -15,
      "y": 48,
      "z": 2,
      "name": "Plant_Moss_Rug_Red"
    },
    {
      "x": -15,
      "y": 21,
      "z": 3,
      "name": "Rock_Volcanic"
    },
    {
      "x": -15,
      "y": 22,
      "z": 3,
      "name": "Rock_Volcanic"
    },
    {
      "x": -15,
      "y": 23,
      "z": 3,
      "name": "Rock_Volcanic"
    },
    {
      "x": -15,
      "y": 24,
      "z": 3,
      "name": "Rock_Volcanic"
    },
    {
      "x": -15,
      "y": 25,
      "z": 3,
      "name": "Rock_Volcanic"
    },
    {
      "x": -15,
      "y": 26,
      "z": 3,
      "name": "Rock_Volcanic"
    },
    {
      "x": -15,
      "y": 27,
      "z": 3,
      "name": "Rock_Volcanic"
    },
    {
      "x": -15,
      "y": 28,
      "z": 3,
      "name": "Rock_Volcanic"
    },
    {
      "x": -15,
      "y": 29,
      "z": 3,
      "name": "Rock_Volcanic"
    },
    {
      "x": -15,
      "y": 30,
      "z": 3,
      "name": "Soil_Volcanic_Gravel"
    },
    {
      "x": -15,
      "y": 44,
      "z": 3,
      "name": "Wood_Petrified_Trunk_Full"
    },
    {
      "x": -15,
      "y": 45,
      "z": 3,
      "name": "Wood_Petrified_Trunk_Full"
    },
    {
      "x": -15,
      "y": 46,
      "z": 3,
      "name": "Wood_Petrified_Trunk_Full"
    },
    {
      "x": -15,
      "y": 47,
      "z": 3,
      "name": "Plant_Moss_Rug_Red"
    },
    {
      "x": -15,
      "y": 22,
      "z": 4,
      "name": "Rock_Volcanic_Cracked_Lava"
    },
    {
      "x": -15,
      "y": 23,
      "z": 4,
      "name": "Rock_Volcanic"
    },
    {
      "x": -15,
      "y": 24,
      "z": 4,
      "name": "Rock_Volcanic"
    },
    {
      "x": -15,
      "y": 25,
      "z": 4,
      "name": "Rock_Volcanic"
    },
    {
      "x": -15,
      "y": 26,
      "z": 4,
      "name": "Rock_Volcanic"
    },
    {
      "x": -15,
      "y": 27,
      "z": 4,
      "name": "Rock_Volcanic"
    },
    {
      "x": -15,
      "y": 28,
      "z": 4,
      "name": "Rock_Volcanic"
    },
    {
      "x": -15,
      "y": 29,
      "z": 4,
      "name": "Soil_Volcanic_Gravel"
    },
    {
      "x": -15,
      "y": 43,
      "z": 4,
      "name": "Plant_Moss_Cave_Red",
      "rotation": 8
    },
    {
      "x": -15,
      "y": 44,
      "z": 4,
      "name": "Wood_Petrified_Trunk_Full"
    },
    {
      "x": -15,
      "y": 45,
      "z": 4,
      "name": "Wood_Petrified_Trunk_Full"
    },
    {
      "x": -15,
      "y": 46,
      "z": 4,
      "name": "Plant_Moss_Rug_Red"
    },
    {
      "x": -15,
      "y": 25,
      "z": 5,
      "name": "Rock_Volcanic_Cracked_Lava"
    },
    {
      "x": -15,
      "y": 26,
      "z": 5,
      "name": "Rock_Volcanic"
    },
    {
      "x": -15,
      "y": 27,
      "z": 5,
      "name": "Rock_Volcanic"
    },
    {
      "x": -15,
      "y": 28,
      "z": 5,
      "name": "Rock_Volcanic"
    },
    {
      "x": -15,
      "y": 29,
      "z": 5,
      "name": "Soil_Volcanic_Gravel"
    },
    {
      "x": -15,
      "y": 43,
      "z": 5,
      "name": "Plant_Moss_Cave_Red",
      "rotation": 8
    },
    {
      "x": -15,
      "y": 44,
      "z": 5,
      "name": "Wood_Petrified_Trunk_Full"
    },
    {
      "x": -15,
      "y": 45,
      "z": 5,
      "name": "Wood_Petrified_Trunk_Full"
    },
    {
      "x": -15,
      "y": 46,
      "z": 5,
      "name": "Plant_Moss_Rug_Red"
    },
    {
      "x": -15,
      "y": 27,
      "z": 6,
      "name": "Rock_Volcanic"
    },
    {
      "x": -15,
      "y": 28,
      "z": 6,
      "name": "Rock_Volcanic"
    },
    {
      "x": -15,
      "y": 44,
      "z": 6,
      "name": "Wood_Petrified_Trunk_Full"
    },
    {
      "x": -15,
      "y": 45,
      "z": 6,
      "name": "Wood_Petrified_Trunk_Full"
    },
    {
      "x": -15,
      "y": 46,
      "z": 6,
      "name": "Plant_Moss_Rug_Red"
    },
    {
      "x": -15,
      "y": 43,
      "z": 7,
      "name": "Plant_Moss_Cave_Red",
      "rotation": 8
    },
    {
      "x": -15,
      "y": 44,
      "z": 7,
      "name": "Wood_Petrified_Trunk_Full"
    },
    {
      "x": -15,
      "y": 45,
      "z": 7,
      "name": "Wood_Petrified_Trunk_Full"
    },
    {
      "x": -15,
      "y": 46,
      "z": 7,
      "name": "Plant_Moss_Rug_Red"
    },
    {
      "x": -15,
      "y": 44,
      "z": 8,
      "name": "Wood_Petrified_Trunk_Full"
    },
    {
      "x": -15,
      "y": 45,
      "z": 8,
      "name": "Wood_Petrified_Trunk_Full"
    },
    {
      "x": -15,
      "y": 46,
      "z": 8,
      "name": "Wood_Petrified_Trunk_Full"
    },
    {
      "x": -15,
      "y": 47,
      "z": 8,
      "name": "Plant_Moss_Rug_Red"
    },
    {
      "x": -15,
      "y": 44,
      "z": 9,
      "name": "Wood_Petrified_Trunk_Full"
    },
    {
      "x": -15,
      "y": 45,
      "z": 9,
      "name": "Wood_Petrified_Trunk_Full"
    },
    {
      "x": -15,
      "y": 46,
      "z": 9,
      "name": "Wood_Petrified_Trunk_Full"
    },
    {
      "x": -15,
      "y": 47,
      "z": 9,
      "name": "Plant_Moss_Rug_Red"
    },
    {
      "x": -15,
      "y": 45,
      "z": 10,
      "name": "Wood_Petrified_Trunk_Full"
    },
    {
      "x": -15,
      "y": 46,
      "z": 10,
      "name": "Wood_Petrified_Trunk_Full"
    },
    {
      "x": -15,
      "y": 47,
      "z": 10,
      "name": "Wood_Petrified_Trunk_Full"
    },
    {
      "x": -15,
      "y": 48,
      "z": 10,
      "name": "Plant_Moss_Rug_Red"
    },
    {
      "x": -15,
      "y": 47,
      "z": 11,
      "name": "Wood_Petrified_Trunk_Full"
    },
    {
      "x": -15,
      "y": 48,
      "z": 11,
      "name": "Wood_Petrified_Trunk_Full"
    },
    {
      "x": -15,
      "y": 49,
      "z": 11,
      "name": "Wood_Petrified_Trunk_Full"
    },
    {
      "x": -15,
      "y": 50,
      "z": 11,
      "name": "Wood_Petrified_Trunk_Full"
    },
    {
      "x": -15,
      "y": 48,
      "z": 12,
      "name": "Wood_Petrified_Trunk_Full"
    },
    {
      "x": -15,
      "y": 49,
      "z": 12,
      "name": "Wood_Petrified_Trunk_Full"
    },
    {
      "x": -15,
      "y": 50,
      "z": 12,
      "name": "Wood_Petrified_Trunk_Full"
    },
    {
      "x": -15,
      "y": 51,
      "z": 12,
      "name": "Wood_Petrified_Trunk_Full"
    },
    {
      "x": -15,
      "y": 52,
      "z": 12,
      "name": "Wood_Petrified_Trunk_Full"
    },
    {
      "x": -14,
      "y": 11,
      "z": -19,
      "name": "Rock_Volcanic"
    },
    {
      "x": -14,
      "y": 12,
      "z": -19,
      "name": "Rock_Volcanic"
    },
    {
      "x": -14,
      "y": 13,
      "z": -19,
      "name": "Rock_Volcanic"
    },
    {
      "x": -14,
      "y": 14,
      "z": -19,
      "name": "Soil_Volcanic_Gravel"
    },
    {
      "x": -14,
      "y": 8,
      "z": -18,
      "name": "Rock_Volcanic_Cracked_Lava"
    },
    {
      "x": -14,
      "y": 9,
      "z": -18,
      "name": "Rock_Volcanic"
    },
    {
      "x": -14,
      "y": 10,
      "z": -18,
      "name": "Rock_Volcanic"
    },
    {
      "x": -14,
      "y": 11,
      "z": -18,
      "name": "Rock_Volcanic_Cracked_Lava"
    },
    {
      "x": -14,
      "y": 12,
      "z": -18,
      "name": "Rock_Volcanic"
    },
    {
      "x": -14,
      "y": 13,
      "z": -18,
      "name": "Rock_Volcanic"
    },
    {
      "x": -14,
      "y": 14,
      "z": -18,
      "name": "Rock_Volcanic_Cracked_Lava"
    },
    {
      "x": -14,
      "y": 15,
      "z": -18,
      "name": "Soil_Volcanic_Gravel"
    },
    {
      "x": -14,
      "y": 6,
      "z": -17,
      "name": "Rock_Volcanic"
    },
    {
      "x": -14,
      "y": 7,
      "z": -17,
      "name": "Rock_Volcanic"
    },
    {
      "x": -14,
      "y": 8,
      "z": -17,
      "name": "Soil_Volcanic_Gravel"
    },
    {
      "x": -14,
      "y": 9,
      "z": -17,
      "name": "Rock_Volcanic"
    },
    {
      "x": -14,
      "y": 10,
      "z": -17,
      "name": "Rock_Volcanic"
    },
    {
      "x": -14,
      "y": 11,
      "z": -17,
      "name": "Rock_Volcanic_Cracked_Lava"
    },
    {
      "x": -14,
      "y": 12,
      "z": -17,
      "name": "Soil_Volcanic_Gravel"
    },
    {
      "x": -14,
      "y": 13,
      "z": -17,
      "name": "Rock_Volcanic"
    },
    {
      "x": -14,
      "y": 14,
      "z": -17,
      "name": "Soil_Volcanic_Gravel"
    },
    {
      "x": -14,
      "y": 15,
      "z": -17,
      "name": "Rock_Magma_Cooled_Brick"
    },
    {
      "x": -14,
      "y": 16,
      "z": -17,
      "name": "Rubble_Magma_Cooled"
    },
    {
      "x": -14,
      "y": 4,
      "z": -16,
      "name": "Rock_Crystal_Red_Large",
      "rotation": 5
    },
    {
      "x": -14,
      "y": 5,
      "z": -16,
      "name": "Rock_Crystal_Red_Large",
      "rotation": 5
    },
    {
      "x": -14,
      "y": 6,
      "z": -16,
      "name": "Rock_Volcanic"
    },
    {
      "x": -14,
      "y": 7,
      "z": -16,
      "name": "Soil_Volcanic_Gravel"
    },
    {
      "x": -14,
      "y": 8,
      "z": -16,
      "name": "Soil_Volcanic_Gravel"
    },
    {
      "x": -14,
      "y": 9,
      "z": -16,
      "name": "Rock_Volcanic"
    },
    {
      "x": -14,
      "y": 10,
      "z": -16,
      "name": "Rock_Volcanic_Cracked_Lava"
    },
    {
      "x": -14,
      "y": 11,
      "z": -16,
      "name": "Rock_Volcanic_Cracked_Lava"
    },
    {
      "x": -14,
      "y": 12,
      "z": -16,
      "name": "Soil_Volcanic_Gravel"
    },
    {
      "x": -14,
      "y": 13,
      "z": -16,
      "name": "Rock_Volcanic"
    },
    {
      "x": -14,
      "y": 14,
      "z": -16,
      "name": "Soil_Volcanic_Gravel"
    },
    {
      "x": -14,
      "y": 15,
      "z": -16,
      "name": "Rock_Magma_Cooled_Brick"
    },
    {
      "x": -14,
      "y": 2,
      "z": -15,
      "name": "Rock_Crystal_Red_Large",
      "rotation": 8
    },
    {
      "x": -14,
      "y": 3,
      "z": -15,
      "name": "Rock_Crystal_Red_Block"
    },
    {
      "x": -14,
      "y": 4,
      "z": -15,
      "name": "Rock_Crystal_Red_Block"
    },
    {
      "x": -14,
      "y": 5,
      "z": -15,
      "name": "Rock_Crystal_Red_Block"
    },
    {
      "x": -14,
      "y": 6,
      "z": -15,
      "name": "Rock_Crystal_Red_Block"
    },
    {
      "x": -14,
      "y": 7,
      "z": -15,
      "name": "Rock_Crystal_Red_Block"
    },
    {
      "x": -14,
      "y": 8,
      "z": -15,
      "name": "Rock_Volcanic"
    },
    {
      "x": -14,
      "y": 9,
      "z": -15,
      "name": "Rock_Volcanic_Cracked_Lava"
    },
    {
      "x": -14,
      "y": 10,
      "z": -15,
      "name": "Rock_Volcanic"
    },
    {
      "x": -14,
      "y": 11,
      "z": -15,
      "name": "Rock_Volcanic"
    },
    {
      "x": -14,
      "y": 12,
      "z": -15,
      "name": "Soil_Volcanic_Gravel"
    },
    {
      "x": -14,
      "y": 13,
      "z": -15,
      "name": "Rock_Volcanic"
    },
    {
      "x": -14,
      "y": 14,
      "z": -15,
      "name": "Soil_Volcanic_Gravel"
    },
    {
      "x": -14,
      "y": 15,
      "z": -15,
      "name": "Rock_Magma_Cooled_Brick"
    },
    {
      "x": -14,
      "y": 3,
      "z": -14,
      "name": "Rock_Crystal_Red_Large",
      "rotation": 4
    },
    {
      "x": -14,
      "y": 5,
      "z": -14,
      "name": "Rock_Volcanic"
    },
    {
      "x": -14,
      "y": 6,
      "z": -14,
      "name": "Rock_Volcanic"
    },
    {
      "x": -14,
      "y": 7,
      "z": -14,
      "name": "Soil_Volcanic_Gravel"
    },
    {
      "x": -14,
      "y": 8,
      "z": -14,
      "name": "Soil_Volcanic_Gravel"
    },
    {
      "x": -14,
      "y": 9,
      "z": -14,
      "name": "Rock_Volcanic"
    },
    {
      "x": -14,
      "y": 10,
      "z": -14,
      "name": "Rock_Volcanic"
    },
    {
      "x": -14,
      "y": 11,
      "z": -14,
      "name": "Rock_Volcanic"
    },
    {
      "x": -14,
      "y": 12,
      "z": -14,
      "name": "Rock_Volcanic"
    },
    {
      "x": -14,
      "y": 13,
      "z": -14,
      "name": "Rock_Volcanic_Cracked_Lava"
    },
    {
      "x": -14,
      "y": 14,
      "z": -14,
      "name": "Soil_Volcanic_Gravel"
    },
    {
      "x": -14,
      "y": 15,
      "z": -14,
      "name": "Rock_Magma_Cooled_Brick"
    },
    {
      "x": -14,
      "y": 4,
      "z": -13,
      "name": "Rock_Crystal_Red_Large",
      "rotation": 8
    },
    {
      "x": -14,
      "y": 5,
      "z": -13,
      "name": "Rock_Volcanic_Cracked_Lava"
    },
    {
      "x": -14,
      "y": 6,
      "z": -13,
      "name": "Soil_Volcanic_Gravel"
    },
    {
      "x": -14,
      "y": 7,
      "z": -13,
      "name": "Rock_Volcanic_Cracked_Lava"
    },
    {
      "x": -14,
      "y": 8,
      "z": -13,
      "name": "Soil_Volcanic_Gravel"
    },
    {
      "x": -14,
      "y": 9,
      "z": -13,
      "name": "Rock_Volcanic"
    },
    {
      "x": -14,
      "y": 10,
      "z": -13,
      "name": "Rock_Volcanic"
    },
    {
      "x": -14,
      "y": 11,
      "z": -13,
      "name": "Rock_Volcanic"
    },
    {
      "x": -14,
      "y": 12,
      "z": -13,
      "name": "Rock_Volcanic"
    },
    {
      "x": -14,
      "y": 13,
      "z": -13,
      "name": "Soil_Volcanic_Gravel"
    },
    {
      "x": -14,
      "y": 14,
      "z": -13,
      "name": "Soil_Volcanic_Gravel"
    },
    {
      "x": -14,
      "y": 15,
      "z": -13,
      "name": "Soil_Volcanic_Gravel"
    },
    {
      "x": -14,
      "y": 16,
      "z": -13,
      "name": "Rubble_Magma_Cooled"
    },
    {
      "x": -14,
      "y": 4,
      "z": -12,
      "name": "Rock_Volcanic_Stalactite_Large",
      "filler": 31744,
      "rotation": 8
    },
    {
      "x": -14,
      "y": 5,
      "z": -12,
      "name": "Rock_Volcanic_Stalactite_Large",
      "rotation": 8
    },
    {
      "x": -14,
      "y": 6,
      "z": -12,
      "name": "Rock_Volcanic_Cracked_Lava"
    },
    {
      "x": -14,
      "y": 7,
      "z": -12,
      "name": "Soil_Volcanic_Gravel"
    },
    {
      "x": -14,
      "y": 8,
      "z": -12,
      "name": "Rock_Volcanic"
    },
    {
      "x": -14,
      "y": 9,
      "z": -12,
      "name": "Rock_Volcanic"
    },
    {
      "x": -14,
      "y": 10,
      "z": -12,
      "name": "Rock_Volcanic"
    },
    {
      "x": -14,
      "y": 11,
      "z": -12,
      "name": "Rock_Volcanic_Cracked_Lava"
    },
    {
      "x": -14,
      "y": 12,
      "z": -12,
      "name": "Rock_Volcanic_Cracked_Lava"
    },
    {
      "x": -14,
      "y": 13,
      "z": -12,
      "name": "Soil_Volcanic_Gravel"
    },
    {
      "x": -14,
      "y": 14,
      "z": -12,
      "name": "Rock_Volcanic_Cracked_Lava"
    },
    {
      "x": -14,
      "y": 15,
      "z": -12,
      "name": "Rock_Volcanic"
    },
    {
      "x": -14,
      "y": 11,
      "z": -11,
      "name": "Rock_Volcanic_Cracked_Lava"
    },
    {
      "x": -14,
      "y": 12,
      "z": -11,
      "name": "Rock_Volcanic"
    },
    {
      "x": -14,
      "y": 13,
      "z": -11,
      "name": "Rock_Volcanic"
    },
    {
      "x": -14,
      "y": 14,
      "z": -11,
      "name": "Rock_Volcanic"
    },
    {
      "x": -14,
      "y": 29,
      "z": -11,
      "name": "Rock_Volcanic_Cracked_Lava"
    },
    {
      "x": -14,
      "y": 30,
      "z": -11,
      "name": "Rock_Volcanic"
    },
    {
      "x": -14,
      "y": 23,
      "z": -10,
      "name": "Rock_Volcanic"
    },
    {
      "x": -14,
      "y": 24,
      "z": -10,
      "name": "Rock_Volcanic"
    },
    {
      "x": -14,
      "y": 25,
      "z": -10,
      "name": "Rock_Volcanic"
    },
    {
      "x": -14,
      "y": 26,
      "z": -10,
      "name": "Rock_Volcanic"
    },
    {
      "x": -14,
      "y": 27,
      "z": -10,
      "name": "Rock_Volcanic"
    },
    {
      "x": -14,
      "y": 28,
      "z": -10,
      "name": "Rock_Volcanic"
    },
    {
      "x": -14,
      "y": 29,
      "z": -10,
      "name": "Rock_Volcanic"
    },
    {
      "x": -14,
      "y": 30,
      "z": -10,
      "name": "Rock_Volcanic"
    },
    {
      "x": -14,
      "y": 31,
      "z": -10,
      "name": "Soil_Volcanic_Gravel"
    },
    {
      "x": -14,
      "y": 32,
      "z": -10,
      "name": "Soil_Volcanic_Gravel"
    },
    {
      "x": -14,
      "y": 21,
      "z": -9,
      "name": "Rock_Volcanic"
    },
    {
      "x": -14,
      "y": 22,
      "z": -9,
      "name": "Rock_Volcanic"
    },
    {
      "x": -14,
      "y": 23,
      "z": -9,
      "name": "Rock_Volcanic"
    },
    {
      "x": -14,
      "y": 24,
      "z": -9,
      "name": "Rock_Volcanic"
    },
    {
      "x": -14,
      "y": 25,
      "z": -9,
      "name": "Rock_Volcanic"
    },
    {
      "x": -14,
      "y": 26,
      "z": -9,
      "name": "Rock_Volcanic"
    },
    {
      "x": -14,
      "y": 27,
      "z": -9,
      "name": "Rock_Volcanic"
    },
    {
      "x": -14,
      "y": 28,
      "z": -9,
      "name": "Rock_Volcanic"
    },
    {
      "x": -14,
      "y": 29,
      "z": -9,
      "name": "Rock_Volcanic"
    },
    {
      "x": -14,
      "y": 30,
      "z": -9,
      "name": "Soil_Volcanic_Gravel"
    },
    {
      "x": -14,
      "y": 31,
      "z": -9,
      "name": "Soil_Volcanic_Gravel"
    },
    {
      "x": -14,
      "y": 32,
      "z": -9,
      "name": "Rock_Volcanic"
    },
    {
      "x": -14,
      "y": 33,
      "z": -9,
      "name": "Rubble_Volcanic_Medium"
    },
    {
      "x": -14,
      "y": 19,
      "z": -8,
      "name": "Rock_Volcanic"
    },
    {
      "x": -14,
      "y": 20,
      "z": -8,
      "name": "Rock_Volcanic"
    },
    {
      "x": -14,
      "y": 21,
      "z": -8,
      "name": "Rock_Volcanic"
    },
    {
      "x": -14,
      "y": 22,
      "z": -8,
      "name": "Rock_Volcanic"
    },
    {
      "x": -14,
      "y": 23,
      "z": -8,
      "name": "Rock_Volcanic"
    },
    {
      "x": -14,
      "y": 24,
      "z": -8,
      "name": "Rock_Volcanic"
    },
    {
      "x": -14,
      "y": 25,
      "z": -8,
      "name": "Rock_Volcanic"
    },
    {
      "x": -14,
      "y": 26,
      "z": -8,
      "name": "Rock_Volcanic"
    },
    {
      "x": -14,
      "y": 27,
      "z": -8,
      "name": "Rock_Volcanic"
    },
    {
      "x": -14,
      "y": 28,
      "z": -8,
      "name": "Rock_Volcanic"
    },
    {
      "x": -14,
      "y": 29,
      "z": -8,
      "name": "Rock_Volcanic"
    },
    {
      "x": -14,
      "y": 30,
      "z": -8,
      "name": "Rock_Volcanic"
    },
    {
      "x": -14,
      "y": 31,
      "z": -8,
      "name": "Soil_Volcanic_Gravel"
    },
    {
      "x": -14,
      "y": 32,
      "z": -8,
      "name": "Rock_Volcanic"
    },
    {
      "x": -14,
      "y": 18,
      "z": -7,
      "name": "Rock_Volcanic"
    },
    {
      "x": -14,
      "y": 19,
      "z": -7,
      "name": "Rock_Volcanic"
    },
    {
      "x": -14,
      "y": 20,
      "z": -7,
      "name": "Rock_Volcanic"
    },
    {
      "x": -14,
      "y": 21,
      "z": -7,
      "name": "Rock_Volcanic"
    },
    {
      "x": -14,
      "y": 22,
      "z": -7,
      "name": "Rock_Volcanic"
    },
    {
      "x": -14,
      "y": 23,
      "z": -7,
      "name": "Rock_Volcanic"
    },
    {
      "x": -14,
      "y": 24,
      "z": -7,
      "name": "Rock_Volcanic"
    },
    {
      "x": -14,
      "y": 25,
      "z": -7,
      "name": "Rock_Volcanic"
    },
    {
      "x": -14,
      "y": 26,
      "z": -7,
      "name": "Rock_Volcanic"
    },
    {
      "x": -14,
      "y": 27,
      "z": -7,
      "name": "Rock_Volcanic"
    },
    {
      "x": -14,
      "y": 28,
      "z": -7,
      "name": "Rock_Volcanic"
    },
    {
      "x": -14,
      "y": 29,
      "z": -7,
      "name": "Rock_Volcanic"
    },
    {
      "x": -14,
      "y": 30,
      "z": -7,
      "name": "Soil_Volcanic_Gravel"
    },
    {
      "x": -14,
      "y": 31,
      "z": -7,
      "name": "Soil_Volcanic_Gravel"
    },
    {
      "x": -14,
      "y": 32,
      "z": -7,
      "name": "Rock_Volcanic"
    },
    {
      "x": -14,
      "y": 33,
      "z": -7,
      "name": "Plant_Bramble_Dead_Lavathorn"
    },
    {
      "x": -14,
      "y": 15,
      "z": -6,
      "name": "Rock_Crystal_Red_Medium",
      "rotation": 7
    },
    {
      "x": -14,
      "y": 16,
      "z": -6,
      "name": "Rock_Crystal_Red_Medium",
      "rotation": 6
    },
    {
      "x": -14,
      "y": 17,
      "z": -6,
      "name": "Rock_Crystal_Red_Medium",
      "rotation": 7
    },
    {
      "x": -14,
      "y": 18,
      "z": -6,
      "name": "Rock_Volcanic"
    },
    {
      "x": -14,
      "y": 19,
      "z": -6,
      "name": "Rock_Volcanic"
    },
    {
      "x": -14,
      "y": 20,
      "z": -6,
      "name": "Rock_Volcanic"
    },
    {
      "x": -14,
      "y": 21,
      "z": -6,
      "name": "Rock_Volcanic"
    },
    {
      "x": -14,
      "y": 22,
      "z": -6,
      "name": "Rock_Volcanic"
    },
    {
      "x": -14,
      "y": 23,
      "z": -6,
      "name": "Rock_Volcanic"
    },
    {
      "x": -14,
      "y": 24,
      "z": -6,
      "name": "Rock_Volcanic"
    },
    {
      "x": -14,
      "y": 25,
      "z": -6,
      "name": "Rock_Volcanic"
    },
    {
      "x": -14,
      "y": 26,
      "z": -6,
      "name": "Rock_Volcanic"
    },
    {
      "x": -14,
      "y": 27,
      "z": -6,
      "name": "Rock_Volcanic"
    },
    {
      "x": -14,
      "y": 28,
      "z": -6,
