{
  "version": 8,
  "blockIdVersion": 11,
  "anchorX": 0,
  "anchorY": 0,
  "anchorZ": 0,
  "blocks": [
    {
      "x": -22,
      "y": 15,
      "z": 14,
      "name": "Soil_Sand_Red"
    },
    {
      "x": -22,
      "y": 16,
      "z": 14,
      "name": "Soil_Sand_Red"
    },
    {
      "x": -22,
      "y": 14,
      "z": 15,
      "name": "Rock_Sandstone_Red"
    },
    {
      "x": -22,
      "y": 15,
      "z": 15,
      "name": "Soil_Sand_Red"
    },
    {
      "x": -22,
      "y": 16,
      "z": 15,
      "name": "Soil_Sand_Red"
    },
    {
      "x": -22,
      "y": 14,
      "z": 16,
      "name": "Rock_Sandstone_Red"
    },
    {
      "x": -22,
      "y": 15,
      "z": 16,
      "name": "Rock_Sandstone_Red"
    },
    {
      "x": -22,
      "y": 16,
      "z": 16,
      "name": "Rock_Sandstone_Red_Cobble"
    },
    {
      "x": -22,
      "y": 13,
      "z": 17,
      "name": "Rock_Sandstone_Red"
    },
    {
      "x": -22,
      "y": 14,
      "z": 17,
      "name": "Rock_Sandstone_Red"
    },
    {
      "x": -22,
      "y": 15,
      "z": 17,
      "name": "Rock_Sandstone_Red"
    },
    {
      "x": -22,
      "y": 16,
      "z": 17,
      "name": "Rock_Sandstone_Red_Cobble"
    },
    {
      "x": -22,
      "y": 13,
      "z": 18,
      "name": "Rock_Sandstone_Red"
    },
    {
      "x": -22,
      "y": 14,
      "z": 18,
      "name": "Rock_Sandstone_Red"
    },
    {
      "x": -21,
      "y": 14,
      "z": 13,
      "name": "Rock_Sandstone_Red"
    },
    {
      "x": -21,
      "y": 15,
      "z": 13,
      "name": "Rock_Sandstone_Red_Cobble"
    },
    {
      "x": -21,
      "y": 16,
      "z": 13,
      "name": "Soil_Sand_Red"
    },
    {
      "x": -21,
      "y": 17,
      "z": 13,
      "name": "Rock_Sandstone_Red_Cobble"
    },
    {
      "x": -21,
      "y": 12,
      "z": 14,
      "name": "Rock_Sandstone_Red"
    },
    {
      "x": -21,
      "y": 13,
      "z": 14,
      "name": "Rock_Sandstone_Red"
    },
    {
      "x": -21,
      "y": 14,
      "z": 14,
      "name": "Soil_Sand_Red"
    },
    {
      "x": -21,
      "y": 15,
      "z": 14,
      "name": "Soil_Sand_Red"
    },
    {
      "x": -21,
      "y": 16,
      "z": 14,
      "name": "Soil_Gravel_Sand_Red"
    },
    {
      "x": -21,
      "y": 11,
      "z": 15,
      "name": "Rock_Sandstone_Red"
    },
    {
      "x": -21,
      "y": 12,
      "z": 15,
      "name": "Rock_Sandstone_Red"
    },
    {
      "x": -21,
      "y": 13,
      "z": 15,
      "name": "Rock_Sandstone_Red"
    },
    {
      "x": -21,
      "y": 14,
      "z": 15,
      "name": "Rock_Sandstone_Red"
    },
    {
      "x": -21,
      "y": 15,
      "z": 15,
      "name": "Soil_Sand_Red"
    },
    {
      "x": -21,
      "y": 16,
      "z": 15,
      "name": "Soil_Sand_Red"
    },
    {
      "x": -21,
      "y": 10,
      "z": 16,
      "name": "Rock_Sandstone_Red"
    },
    {
      "x": -21,
      "y": 11,
      "z": 16,
      "name": "Rock_Sandstone_Red"
    },
    {
      "x": -21,
      "y": 12,
      "z": 16,
      "name": "Rock_Sandstone_Red"
    },
    {
      "x": -21,
      "y": 13,
      "z": 16,
      "name": "Rock_Sandstone_Red"
    },
    {
      "x": -21,
      "y": 14,
      "z": 16,
      "name": "Rock_Sandstone_Red"
    },
    {
      "x": -21,
      "y": 15,
      "z": 16,
      "name": "Soil_Sand_Red"
    },
    {
      "x": -21,
      "y": 16,
      "z": 16,
      "name": "Soil_Sand_Red"
    },
    {
      "x": -21,
      "y": 11,
      "z": 17,
      "name": "Rock_Sandstone_Red"
    },
    {
      "x": -21,
      "y": 12,
      "z": 17,
      "name": "Rock_Sandstone_Red"
    },
    {
      "x": -21,
      "y": 13,
      "z": 17,
      "name": "Rock_Sandstone_Red"
    },
    {
      "x": -21,
      "y": 14,
      "z": 17,
      "name": "Rock_Sandstone_Red"
    },
    {
      "x": -21,
      "y": 15,
      "z": 17,
      "name": "Soil_Sand_Red"
    },
    {
      "x": -21,
      "y": 16,
      "z": 17,
      "name": "Soil_Sand_Red"
    },
    {
      "x": -21,
      "y": 17,
      "z": 17,
      "name": "Plant_Bush_Arid_Red"
    },
    {
      "x": -21,
      "y": 14,
      "z": 18,
      "name": "Rock_Sandstone_Red"
    },
    {
      "x": -21,
      "y": 15,
      "z": 18,
      "name": "Rock_Sandstone_Red_Cobble"
    },
    {
      "x": -20,
      "y": 15,
      "z": 12,
      "name": "Rock_Sandstone_Red_Cobble"
    },
    {
      "x": -20,
      "y": 16,
      "z": 12,
      "name": "Soil_Sand_Red"
    },
    {
      "x": -20,
      "y": 17,
      "z": 12,
      "name": "Soil_Sand_Red"
    },
    {
      "x": -20,
      "y": 11,
      "z": 13,
      "name": "Rock_Sandstone_Red"
    },
    {
      "x": -20,
      "y": 12,
      "z": 13,
      "name": "Rock_Sandstone_Red"
    },
    {
      "x": -20,
      "y": 13,
      "z": 13,
      "name": "Rock_Sandstone_Red"
    },
    {
      "x": -20,
      "y": 14,
      "z": 13,
      "name": "Rock_Sandstone_Red"
    },
    {
      "x": -20,
      "y": 15,
      "z": 13,
      "name": "Soil_Gravel_Sand_Red"
    },
    {
      "x": -20,
      "y": 16,
      "z": 13,
      "name": "Soil_Gravel_Sand_Red"
    },
    {
      "x": -20,
      "y": 10,
      "z": 14,
      "name": "Rock_Sandstone_Red"
    },
    {
      "x": -20,
      "y": 11,
      "z": 14,
      "name": "Rock_Sandstone_Red"
    },
    {
      "x": -20,
      "y": 12,
      "z": 14,
      "name": "Rock_Sandstone_Red"
    },
    {
      "x": -20,
      "y": 13,
      "z": 14,
      "name": "Rock_Sandstone_Red"
    },
    {
      "x": -20,
      "y": 14,
      "z": 14,
      "name": "Rock_Sandstone_Red"
    },
    {
      "x": -20,
      "y": 15,
      "z": 14,
      "name": "Rock_Sandstone_Red_Cobble"
    },
    {
      "x": -20,
      "y": 16,
      "z": 14,
      "name": "Soil_Sand_Red"
    },
    {
      "x": -20,
      "y": 17,
      "z": 14,
      "name": "Soil_Sand_Red"
    },
    {
      "x": -20,
      "y": 18,
      "z": 14,
      "name": "Plant_Bush_Arid_Red"
    },
    {
      "x": -20,
      "y": 9,
      "z": 15,
      "name": "Rock_Sandstone_Red"
    },
    {
      "x": -20,
      "y": 10,
      "z": 15,
      "name": "Rock_Sandstone_Red"
    },
    {
      "x": -20,
      "y": 11,
      "z": 15,
      "name": "Rock_Sandstone_Red"
    },
    {
      "x": -20,
      "y": 12,
      "z": 15,
      "name": "Rock_Sandstone_Red"
    },
    {
      "x": -20,
      "y": 13,
      "z": 15,
      "name": "Rock_Sandstone_Red"
    },
    {
      "x": -20,
      "y": 14,
      "z": 15,
      "name": "Rock_Sandstone_Red"
    },
    {
      "x": -20,
      "y": 15,
      "z": 15,
      "name": "Soil_Sand_Red"
    },
    {
      "x": -20,
      "y": 16,
      "z": 15,
      "name": "Soil_Gravel_Sand_Red"
    },
    {
      "x": -20,
      "y": 17,
      "z": 15,
      "name": "Soil_Sand_Red"
    },
    {
      "x": -20,
      "y": 9,
      "z": 16,
      "name": "Rock_Sandstone_Red"
    },
    {
      "x": -20,
      "y": 10,
      "z": 16,
      "name": "Rock_Sandstone_Red"
    },
    {
      "x": -20,
      "y": 11,
      "z": 16,
      "name": "Rock_Sandstone_Red"
    },
    {
      "x": -20,
      "y": 12,
      "z": 16,
      "name": "Rock_Sandstone_Red"
    },
    {
      "x": -20,
      "y": 13,
      "z": 16,
      "name": "Rock_Sandstone_Red"
    },
    {
      "x": -20,
      "y": 14,
      "z": 16,
      "name": "Rock_Sandstone_Red"
    },
    {
      "x": -20,
      "y": 15,
      "z": 16,
      "name": "Rock_Sandstone_Red"
    },
    {
      "x": -20,
      "y": 16,
      "z": 16,
      "name": "Soil_Sand_Red"
    },
    {
      "x": -20,
      "y": 17,
      "z": 16,
      "name": "Soil_Sand_Red"
    },
    {
      "x": -20,
      "y": 9,
      "z": 17,
      "name": "Rock_Sandstone_Red"
    },
    {
      "x": -20,
      "y": 10,
      "z": 17,
      "name": "Rock_Sandstone_Red"
    },
    {
      "x": -20,
      "y": 11,
      "z": 17,
      "name": "Rock_Sandstone_Red"
    },
    {
      "x": -20,
      "y": 12,
      "z": 17,
      "name": "Rock_Sandstone_Red"
    },
    {
      "x": -20,
      "y": 13,
      "z": 17,
      "name": "Rock_Sandstone_Red"
    },
    {
      "x": -20,
      "y": 14,
      "z": 17,
      "name": "Rock_Sandstone_Red"
    },
    {
      "x": -20,
      "y": 15,
      "z": 17,
      "name": "Soil_Sand_Red"
    },
    {
      "x": -20,
      "y": 16,
      "z": 17,
      "name": "Soil_Sand_Red"
    },
    {
      "x": -20,
      "y": 17,
      "z": 17,
      "name": "Rock_Sandstone_Red_Cobble"
    },
    {
      "x": -20,
      "y": 10,
      "z": 18,
      "name": "Rock_Sandstone_Red"
    },
    {
      "x": -20,
      "y": 11,
      "z": 18,
      "name": "Rock_Sandstone_Red"
    },
    {
      "x": -20,
      "y": 12,
      "z": 18,
      "name": "Rock_Sandstone_Red"
    },
    {
      "x": -20,
      "y": 13,
      "z": 18,
      "name": "Rock_Sandstone_Red"
    },
    {
      "x": -20,
      "y": 14,
      "z": 18,
      "name": "Rock_Sandstone_Red"
    },
    {
      "x": -20,
      "y": 15,
      "z": 18,
      "name": "Soil_Gravel_Sand_Red"
    },
    {
      "x": -20,
      "y": 16,
      "z": 18,
      "name": "Soil_Sand_Red"
    },
    {
      "x": -20,
      "y": 13,
      "z": 19,
      "name": "Rock_Sandstone_Red"
    },
    {
      "x": -20,
      "y": 14,
      "z": 19,
      "name": "Rock_Sandstone_Red"
    },
    {
      "x": -19,
      "y": 14,
      "z": 11,
      "name": "Plant_Crop_Mushroom_Shelve_Yellow"
    },
    {
      "x": -19,
      "y": 17,
      "z": 11,
      "name": "Soil_Gravel_Sand_Red"
    },
    {
      "x": -19,
      "y": 12,
      "z": 12,
      "name": "Rock_Sandstone_Red"
    },
    {
      "x": -19,
      "y": 13,
      "z": 12,
      "name": "Rock_Sandstone_Red"
    },
    {
      "x": -19,
      "y": 14,
      "z": 12,
      "name": "Rock_Sandstone_Red"
    },
    {
      "x": -19,
      "y": 15,
      "z": 12,
      "name": "Soil_Sand_Red"
    },
    {
      "x": -19,
      "y": 16,
      "z": 12,
      "name": "Soil_Gravel_Sand_Red"
    },
    {
      "x": -19,
      "y": 17,
      "z": 12,
      "name": "Soil_Sand_Red"
    },
    {
      "x": -19,
      "y": 10,
      "z": 13,
      "name": "Rock_Sandstone_Red"
    },
    {
      "x": -19,
      "y": 11,
      "z": 13,
      "name": "Rock_Sandstone_Red"
    },
    {
      "x": -19,
      "y": 12,
      "z": 13,
      "name": "Rock_Sandstone_Red"
    },
    {
      "x": -19,
      "y": 13,
      "z": 13,
      "name": "Rock_Sandstone_Red"
    },
    {
      "x": -19,
      "y": 14,
      "z": 13,
      "name": "Rock_Sandstone_Red"
    },
    {
      "x": -19,
      "y": 15,
      "z": 13,
      "name": "Soil_Sand_Red"
    },
    {
      "x": -19,
      "y": 16,
      "z": 13,
      "name": "Soil_Sand_Red"
    },
    {
      "x": -19,
      "y": 17,
      "z": 13,
      "name": "Soil_Gravel_Sand_Red"
    },
    {
      "x": -19,
      "y": 9,
      "z": 14,
      "name": "Rock_Sandstone_Red"
    },
    {
      "x": -19,
      "y": 10,
      "z": 14,
      "name": "Rock_Sandstone_Red"
    },
    {
      "x": -19,
      "y": 11,
      "z": 14,
      "name": "Rock_Sandstone_Red"
    },
    {
      "x": -19,
      "y": 12,
      "z": 14,
      "name": "Rock_Sandstone_Red"
    },
    {
      "x": -19,
      "y": 13,
      "z": 14,
      "name": "Rock_Sandstone_Red"
    },
    {
      "x": -19,
      "y": 14,
      "z": 14,
      "name": "Rock_Sandstone_Red"
    },
    {
      "x": -19,
      "y": 15,
      "z": 14,
      "name": "Rock_Sandstone_Red"
    },
    {
      "x": -19,
      "y": 16,
      "z": 14,
      "name": "Rock_Sandstone_Red"
    },
    {
      "x": -19,
      "y": 17,
      "z": 14,
      "name": "Soil_Sand_Red"
    },
    {
      "x": -19,
      "y": 18,
      "z": 14,
      "name": "Rock_Sandstone_Red_Cobble"
    },
    {
      "x": -19,
      "y": 8,
      "z": 15,
      "name": "Rock_Sandstone_Red"
    },
    {
      "x": -19,
      "y": 9,
      "z": 15,
      "name": "Rock_Sandstone_Red"
    },
    {
      "x": -19,
      "y": 10,
      "z": 15,
      "name": "Rock_Sandstone_Red"
    },
    {
      "x": -19,
      "y": 11,
      "z": 15,
      "name": "Rock_Sandstone_Red"
    },
    {
      "x": -19,
      "y": 12,
      "z": 15,
      "name": "Rock_Sandstone_Red"
    },
    {
      "x": -19,
      "y": 13,
      "z": 15,
      "name": "Rock_Sandstone_Red"
    },
    {
      "x": -19,
      "y": 14,
      "z": 15,
      "name": "Rock_Sandstone_Red"
    },
    {
      "x": -19,
      "y": 15,
      "z": 15,
      "name": "Rock_Sandstone_Red"
    },
    {
      "x": -19,
      "y": 16,
      "z": 15,
      "name": "Soil_Sand_Red"
    },
    {
      "x": -19,
      "y": 17,
      "z": 15,
      "name": "Soil_Gravel_Sand_Red"
    },
    {
      "x": -19,
      "y": 18,
      "z": 15,
      "name": "Soil_Sand_Red"
    },
    {
      "x": -19,
      "y": 8,
      "z": 16,
      "name": "Rock_Sandstone_Red"
    },
    {
      "x": -19,
      "y": 9,
      "z": 16,
      "name": "Rock_Sandstone_Red"
    },
    {
      "x": -19,
      "y": 10,
      "z": 16,
      "name": "Rock_Sandstone_Red"
    },
    {
      "x": -19,
      "y": 11,
      "z": 16,
      "name": "Rock_Sandstone_Red"
    },
    {
      "x": -19,
      "y": 12,
      "z": 16,
      "name": "Rock_Sandstone_Red"
    },
    {
      "x": -19,
      "y": 13,
      "z": 16,
      "name": "Rock_Sandstone_Red"
    },
    {
      "x": -19,
      "y": 14,
      "z": 16,
      "name": "Rock_Sandstone_Red"
    },
    {
      "x": -19,
      "y": 15,
      "z": 16,
      "name": "Rock_Sandstone_Red"
    },
    {
      "x": -19,
      "y": 16,
      "z": 16,
      "name": "Soil_Sand_Red"
    },
    {
      "x": -19,
      "y": 17,
      "z": 16,
      "name": "Soil_Gravel_Sand_Red"
    },
    {
      "x": -19,
      "y": 18,
      "z": 16,
      "name": "Plant_Flower_Bushy_Red"
    },
    {
      "x": -19,
      "y": 8,
      "z": 17,
      "name": "Rock_Sandstone_Red"
    },
    {
      "x": -19,
      "y": 9,
      "z": 17,
      "name": "Rock_Sandstone_Red"
    },
    {
      "x": -19,
      "y": 10,
      "z": 17,
      "name": "Rock_Sandstone_Red"
    },
    {
      "x": -19,
      "y": 11,
      "z": 17,
      "name": "Rock_Sandstone_Red"
    },
    {
      "x": -19,
      "y": 12,
      "z": 17,
      "name": "Rock_Sandstone_Red"
    },
    {
      "x": -19,
      "y": 13,
      "z": 17,
      "name": "Rock_Sandstone_Red"
    },
    {
      "x": -19,
      "y": 14,
      "z": 17,
      "name": "Rock_Sandstone_Red"
    },
    {
      "x": -19,
      "y": 15,
      "z": 17,
      "name": "Rock_Sandstone_Red"
    },
    {
      "x": -19,
      "y": 16,
      "z": 17,
      "name": "Rock_Sandstone_Red_Cobble"
    },
    {
      "x": -19,
      "y": 17,
      "z": 17,
      "name": "Soil_Sand_Red"
    },
    {
      "x": -19,
      "y": 18,
      "z": 17,
      "name": "Plant_Crop_Mushroom_Glowing_Red"
    },
    {
      "x": -19,
      "y": 9,
      "z": 18,
      "name": "Rock_Sandstone_Red"
    },
    {
      "x": -19,
      "y": 10,
      "z": 18,
      "name": "Rock_Sandstone_Red"
    },
    {
      "x": -19,
      "y": 11,
      "z": 18,
      "name": "Rock_Sandstone_Red"
    },
    {
      "x": -19,
      "y": 12,
      "z": 18,
      "name": "Rock_Sandstone_Red"
    },
    {
      "x": -19,
      "y": 13,
      "z": 18,
      "name": "Rock_Sandstone_Red"
    },
    {
      "x": -19,
      "y": 14,
      "z": 18,
      "name": "Rock_Sandstone_Red"
    },
    {
      "x": -19,
      "y": 15,
      "z": 18,
      "name": "Soil_Sand_Red"
    },
    {
      "x": -19,
      "y": 16,
      "z": 18,
      "name": "Rock_Sandstone_Red_Cobble"
    },
    {
      "x": -19,
      "y": 10,
      "z": 19,
      "name": "Rock_Sandstone_Red"
    },
    {
      "x": -19,
      "y": 11,
      "z": 19,
      "name": "Rock_Sandstone_Red"
    },
    {
      "x": -19,
      "y": 12,
      "z": 19,
      "name": "Rock_Sandstone_Red"
    },
    {
      "x": -19,
      "y": 13,
      "z": 19,
      "name": "Rock_Sandstone_Red"
    },
    {
      "x": -19,
      "y": 14,
      "z": 19,
      "name": "Soil_Sand_Red"
    },
    {
      "x": -19,
      "y": 15,
      "z": 19,
      "name": "Soil_Gravel_Sand_Red"
    },
    {
      "x": -19,
      "y": 13,
      "z": 20,
      "name": "Rock_Sandstone_Red"
    },
    {
      "x": -18,
      "y": 14,
      "z": 11,
      "name": "Rock_Sandstone_Red"
    },
    {
      "x": -18,
      "y": 15,
      "z": 11,
      "name": "Rock_Sandstone_Red"
    },
    {
      "x": -18,
      "y": 16,
      "z": 11,
      "name": "Soil_Sand_Red"
    },
    {
      "x": -18,
      "y": 17,
      "z": 11,
      "name": "Soil_Sand_Red"
    },
    {
      "x": -18,
      "y": 18,
      "z": 11,
      "name": "Soil_Sand_Red"
    },
    {
      "x": -18,
      "y": 11,
      "z": 12,
      "name": "Rock_Sandstone_Red"
    },
    {
      "x": -18,
      "y": 12,
      "z": 12,
      "name": "Rock_Sandstone_Red"
    },
    {
      "x": -18,
      "y": 13,
      "z": 12,
      "name": "Rock_Sandstone_Red"
    },
    {
      "x": -18,
      "y": 14,
      "z": 12,
      "name": "Rock_Sandstone_Red"
    },
    {
      "x": -18,
      "y": 15,
      "z": 12,
      "name": "Rock_Sandstone_Red"
    },
    {
      "x": -18,
      "y": 16,
      "z": 12,
      "name": "Soil_Sand_Red"
    },
    {
      "x": -18,
      "y": 17,
      "z": 12,
      "name": "Soil_Gravel_Sand_Red"
    },
    {
      "x": -18,
      "y": 18,
      "z": 12,
      "name": "Soil_Sand_Red"
    },
    {
      "x": -18,
      "y": 9,
      "z": 13,
      "name": "Rock_Sandstone_Red"
    },
    {
      "x": -18,
      "y": 10,
      "z": 13,
      "name": "Rock_Sandstone_Red"
    },
    {
      "x": -18,
      "y": 11,
      "z": 13,
      "name": "Rock_Sandstone_Red"
    },
    {
      "x": -18,
      "y": 12,
      "z": 13,
      "name": "Rock_Sandstone_Red"
    },
    {
      "x": -18,
      "y": 13,
      "z": 13,
      "name": "Rock_Sandstone_Red"
    },
    {
      "x": -18,
      "y": 14,
      "z": 13,
      "name": "Rock_Sandstone_Red"
    },
    {
      "x": -18,
      "y": 15,
      "z": 13,
      "name": "Rock_Sandstone_Red"
    },
    {
      "x": -18,
      "y": 16,
      "z": 13,
      "name": "Soil_Sand_Red"
    },
    {
      "x": -18,
      "y": 17,
      "z": 13,
      "name": "Soil_Sand_Red"
    },
    {
      "x": -18,
      "y": 18,
      "z": 13,
      "name": "Rock_Sandstone_Red_Cobble"
    },
    {
      "x": -18,
      "y": 19,
      "z": 13,
      "name": "Plant_Bush_Crystal"
    },
    {
      "x": -18,
      "y": 6,
      "z": 14,
      "name": "Rock_Sandstone_Red_Stalactite_Large",
      "filler": 31744,
      "rotation": 8
    },
    {
      "x": -18,
      "y": 7,
      "z": 14,
      "name": "Rock_Sandstone_Red_Stalactite_Large",
      "rotation": 8
    },
    {
      "x": -18,
      "y": 8,
      "z": 14,
      "name": "Rock_Sandstone_Red"
    },
    {
      "x": -18,
      "y": 9,
      "z": 14,
      "name": "Rock_Sandstone_Red"
    },
    {
      "x": -18,
      "y": 10,
      "z": 14,
      "name": "Rock_Sandstone_Red"
    },
    {
      "x": -18,
      "y": 11,
      "z": 14,
      "name": "Rock_Sandstone_Red"
    },
    {
      "x": -18,
      "y": 12,
      "z": 14,
      "name": "Rock_Sandstone_Red"
    },
    {
      "x": -18,
      "y": 13,
      "z": 14,
      "name": "Rock_Sandstone_Red"
    },
    {
      "x": -18,
      "y": 14,
      "z": 14,
      "name": "Rock_Sandstone_Red"
    },
    {
      "x": -18,
      "y": 15,
      "z": 14,
      "name": "Rock_Sandstone_Red"
    },
    {
      "x": -18,
      "y": 16,
      "z": 14,
      "name": "Soil_Sand_Red"
    },
    {
      "x": -18,
      "y": 17,
      "z": 14,
      "name": "Soil_Sand_Red"
    },
    {
      "x": -18,
      "y": 18,
      "z": 14,
      "name": "Soil_Sand_Red"
    },
    {
      "x": -18,
      "y": 19,
      "z": 14,
      "name": "Plant_Flower_Bushy_Orange"
    },
    {
      "x": -18,
      "y": 7,
      "z": 15,
      "name": "Rock_Sandstone_Red"
    },
    {
      "x": -18,
      "y": 8,
      "z": 15,
      "name": "Rock_Sandstone_Red"
    },
    {
      "x": -18,
      "y": 9,
      "z": 15,
      "name": "Rock_Sandstone_Red"
    },
    {
      "x": -18,
      "y": 10,
      "z": 15,
      "name": "Rock_Sandstone_Red"
    },
    {
      "x": -18,
      "y": 11,
      "z": 15,
      "name": "Rock_Sandstone_Red"
    },
    {
      "x": -18,
      "y": 12,
      "z": 15,
      "name": "Rock_Sandstone_Red"
    },
    {
      "x": -18,
      "y": 13,
      "z": 15,
      "name": "Rock_Sandstone_Red"
    },
    {
      "x": -18,
      "y": 14,
      "z": 15,
      "name": "Rock_Sandstone_Red"
    },
    {
      "x": -18,
      "y": 15,
      "z": 15,
      "name": "Rock_Sandstone_Red"
    },
    {
      "x": -18,
      "y": 16,
      "z": 15,
      "name": "Rock_Sandstone_Red"
    },
    {
      "x": -18,
      "y": 17,
      "z": 15,
      "name": "Rock_Sandstone_Red_Cobble"
    },
    {
      "x": -18,
      "y": 18,
      "z": 15,
      "name": "Soil_Sand_Red"
    },
    {
      "x": -18,
      "y": 5,
      "z": 16,
      "name": "Rock_Sandstone_Red_Stalactite_Large",
      "filler": 31744,
      "rotation": 8
    },
    {
      "x": -18,
      "y": 6,
      "z": 16,
      "name": "Rock_Sandstone_Red_Stalactite_Large",
      "rotation": 8
    },
    {
      "x": -18,
      "y": 7,
      "z": 16,
      "name": "Rock_Sandstone_Red"
    },
    {
      "x": -18,
      "y": 8,
      "z": 16,
      "name": "Rock_Sandstone_Red"
    },
    {
      "x": -18,
      "y": 9,
      "z": 16,
      "name": "Rock_Sandstone_Red"
    },
    {
      "x": -18,
      "y": 10,
      "z": 16,
      "name": "Rock_Sandstone_Red"
    },
    {
      "x": -18,
      "y": 11,
      "z": 16,
      "name": "Rock_Sandstone_Red"
    },
    {
      "x": -18,
      "y": 12,
      "z": 16,
      "name": "Rock_Sandstone_Red"
    },
    {
      "x": -18,
      "y": 13,
      "z": 16,
      "name": "Rock_Sandstone_Red"
    },
    {
      "x": -18,
      "y": 14,
      "z": 16,
      "name": "Rock_Sandstone_Red"
    },
    {
      "x": -18,
      "y": 15,
      "z": 16,
      "name": "Rock_Sandstone_Red"
    },
    {
      "x": -18,
      "y": 16,
      "z": 16,
      "name": "Soil_Sand_Red"
    },
    {
      "x": -18,
      "y": 17,
      "z": 16,
      "name": "Soil_Gravel_Sand_Red"
    },
    {
      "x": -18,
      "y": 18,
      "z": 16,
      "name": "Soil_Sand_Red"
    },
    {
      "x": -18,
      "y": 7,
      "z": 17,
      "name": "Rock_Sandstone_Red"
    },
    {
      "x": -18,
      "y": 8,
      "z": 17,
      "name": "Rock_Sandstone_Red"
    },
    {
      "x": -18,
      "y": 9,
      "z": 17,
      "name": "Rock_Sandstone_Red"
    },
    {
      "x": -18,
      "y": 10,
      "z": 17,
      "name": "Rock_Sandstone_Red"
    },
    {
      "x": -18,
      "y": 11,
      "z": 17,
      "name": "Rock_Sandstone_Red"
    },
    {
      "x": -18,
      "y": 12,
      "z": 17,
      "name": "Rock_Sandstone_Red"
    },
    {
      "x": -18,
      "y": 13,
      "z": 17,
      "name": "Rock_Sandstone_Red"
    },
    {
      "x": -18,
      "y": 14,
      "z": 17,
      "name": "Rock_Sandstone_Red"
    },
    {
      "x": -18,
      "y": 15,
      "z": 17,
      "name": "Rock_Sandstone_Red_Cobble"
    },
    {
      "x": -18,
      "y": 16,
      "z": 17,
      "name": "Soil_Sand_Red"
    },
    {
      "x": -18,
      "y": 17,
      "z": 17,
      "name": "Soil_Sand_Red"
    },
    {
      "x": -18,
      "y": 8,
      "z": 18,
      "name": "Rock_Sandstone_Red"
    },
    {
      "x": -18,
      "y": 9,
      "z": 18,
      "name": "Rock_Sandstone_Red"
    },
    {
      "x": -18,
      "y": 10,
      "z": 18,
      "name": "Rock_Sandstone_Red"
    },
    {
      "x": -18,
      "y": 11,
      "z": 18,
      "name": "Rock_Sandstone_Red"
    },
    {
      "x": -18,
      "y": 12,
      "z": 18,
      "name": "Rock_Sandstone_Red"
    },
    {
      "x": -18,
      "y": 13,
      "z": 18,
      "name": "Rock_Sandstone_Red"
    },
    {
      "x": -18,
      "y": 14,
      "z": 18,
      "name": "Rock_Sandstone_Red"
    },
    {
      "x": -18,
      "y": 15,
      "z": 18,
      "name": "Soil_Sand_Red"
    },
    {
      "x": -18,
      "y": 16,
      "z": 18,
      "name": "Soil_Sand_Red"
    },
    {
      "x": -18,
      "y": 17,
      "z": 18,
      "name": "Soil_Sand_Red"
    },
    {
      "x": -18,
      "y": 18,
      "z": 18,
      "name": "Plant_Flower_Bushy_Red"
    },
    {
      "x": -18,
      "y": 9,
      "z": 19,
      "name": "Rock_Sandstone_Red"
    },
    {
      "x": -18,
      "y": 10,
      "z": 19,
      "name": "Rock_Sandstone_Red"
    },
    {
      "x": -18,
      "y": 11,
      "z": 19,
      "name": "Rock_Sandstone_Red"
    },
    {
      "x": -18,
      "y": 12,
      "z": 19,
      "name": "Rock_Sandstone_Red"
    },
    {
      "x": -18,
      "y": 13,
      "z": 19,
      "name": "Rock_Sandstone_Red"
    },
    {
      "x": -18,
      "y": 14,
      "z": 19,
      "name": "Rock_Sandstone_Red"
    },
    {
      "x": -18,
      "y": 15,
      "z": 19,
      "name": "Soil_Sand_Red"
    },
    {
      "x": -18,
      "y": 16,
      "z": 19,
      "name": "Soil_Sand_Red"
    },
    {
      "x": -18,
      "y": 11,
      "z": 20,
      "name": "Rock_Sandstone_Red"
    },
    {
      "x": -18,
      "y": 12,
      "z": 20,
      "name": "Rock_Sandstone_Red"
    },
    {
      "x": -18,
      "y": 13,
      "z": 20,
      "name": "Rock_Sandstone_Red"
    },
    {
      "x": -18,
      "y": 14,
      "z": 20,
      "name": "Rubble_Sandstone_Red"
    },
    {
      "x": -17,
      "y": 15,
      "z": 10,
      "name": "Plant_Crop_Mushroom_Shelve_Yellow"
    },
    {
      "x": -17,
      "y": 17,
      "z": 10,
      "name": "Soil_Sand_Red"
    },
    {
      "x": -17,
      "y": 18,
      "z": 10,
      "name": "Rock_Sandstone_Red_Cobble"
    },
    {
      "x": -17,
      "y": 19,
      "z": 10,
      "name": "Plant_Bush_Crystal"
    },
    {
      "x": -17,
      "y": 14,
      "z": 11,
      "name": "Rock_Sandstone_Red"
    },
    {
      "x": -17,
      "y": 15,
      "z": 11,
      "name": "Rock_Sandstone_Red"
    },
    {
      "x": -17,
      "y": 16,
      "z": 11,
      "name": "Rock_Sandstone_Red"
    },
    {
      "x": -17,
      "y": 17,
      "z": 11,
      "name": "Rock_Sandstone_Red_Cobble"
    },
    {
      "x": -17,
      "y": 18,
      "z": 11,
      "name": "Soil_Sand_Red"
    },
    {
      "x": -17,
      "y": 19,
      "z": 11,
      "name": "Soil_Sand_Red"
    },
    {
      "x": -17,
      "y": 10,
      "z": 12,
      "name": "Rock_Sandstone_Red"
    },
    {
      "x": -17,
      "y": 11,
      "z": 12,
      "name": "Rock_Sandstone_Red"
    },
    {
      "x": -17,
      "y": 12,
      "z": 12,
      "name": "Rock_Sandstone_Red"
    },
    {
      "x": -17,
      "y": 13,
      "z": 12,
      "name": "Rock_Sandstone_Red"
    },
    {
      "x": -17,
      "y": 14,
      "z": 12,
      "name": "Rock_Sandstone_Red"
    },
    {
      "x": -17,
      "y": 15,
      "z": 12,
      "name": "Rock_Sandstone_Red"
    },
    {
      "x": -17,
      "y": 16,
      "z": 12,
      "name": "Rock_Sandstone_Red"
    },
    {
      "x": -17,
      "y": 17,
      "z": 12,
      "name": "Soil_Sand_Red"
    },
    {
      "x": -17,
      "y": 18,
      "z": 12,
      "name": "Rock_Sandstone_Red_Cobble"
    },
    {
      "x": -17,
      "y": 19,
      "z": 12,
      "name": "Rock_Sandstone_Red_Cobble"
    },
    {
      "x": -17,
      "y": 9,
      "z": 13,
      "name": "Rock_Sandstone_Red"
    },
    {
      "x": -17,
      "y": 10,
      "z": 13,
      "name": "Rock_Sandstone_Red"
    },
    {
      "x": -17,
      "y": 11,
      "z": 13,
      "name": "Rock_Sandstone_Red"
    },
    {
      "x": -17,
      "y": 12,
      "z": 13,
      "name": "Rock_Sandstone_Red"
    },
    {
      "x": -17,
      "y": 13,
      "z": 13,
      "name": "Rock_Sandstone_Red"
    },
    {
      "x": -17,
      "y": 14,
      "z": 13,
      "name": "Rock_Sandstone_Red"
    },
    {
      "x": -17,
      "y": 15,
      "z": 13,
      "name": "Rock_Sandstone_Red"
    },
    {
      "x": -17,
      "y": 16,
      "z": 13,
      "name": "Rock_Sandstone_Red"
    },
    {
      "x": -17,
      "y": 17,
      "z": 13,
      "name": "Soil_Sand_Red"
    },
    {
      "x": -17,
      "y": 18,
      "z": 13,
      "name": "Soil_Sand_Red"
    },
    {
      "x": -17,
      "y": 19,
      "z": 13,
      "name": "Soil_Sand_Red"
    },
    {
      "x": -17,
      "y": 8,
      "z": 14,
      "name": "Rock_Sandstone_Red"
    },
    {
      "x": -17,
      "y": 9,
      "z": 14,
      "name": "Rock_Sandstone_Red"
    },
    {
      "x": -17,
      "y": 10,
      "z": 14,
      "name": "Rock_Sandstone_Red"
    },
    {
      "x": -17,
      "y": 11,
      "z": 14,
      "name": "Rock_Sandstone_Red"
    },
    {
      "x": -17,
      "y": 12,
      "z": 14,
      "name": "Rock_Sandstone_Red"
    },
    {
      "x": -17,
      "y": 13,
      "z": 14,
      "name": "Rock_Sandstone_Red"
    },
    {
      "x": -17,
      "y": 14,
      "z": 14,
      "name": "Rock_Sandstone_Red"
    },
    {
      "x": -17,
      "y": 15,
      "z": 14,
      "name": "Rock_Sandstone_Red"
    },
    {
      "x": -17,
      "y": 16,
      "z": 14,
      "name": "Rock_Sandstone_Red"
    },
    {
      "x": -17,
      "y": 17,
      "z": 14,
      "name": "Rock_Sandstone_Red"
    },
    {
      "x": -17,
      "y": 18,
      "z": 14,
      "name": "Soil_Sand_Red"
    },
    {
      "x": -17,
      "y": 19,
      "z": 14,
      "name": "Soil_Sand_Red"
    },
    {
      "x": -17,
      "y": 6,
      "z": 15,
      "name": "Rock_Crystal_Red_Medium",
      "rotation": 6
    },
    {
      "x": -17,
      "y": 7,
      "z": 15,
      "name": "Rock_Sandstone_Red"
    },
    {
      "x": -17,
      "y": 8,
      "z": 15,
      "name": "Rock_Sandstone_Red"
    },
    {
      "x": -17,
      "y": 9,
      "z": 15,
      "name": "Rock_Sandstone_Red"
    },
    {
      "x": -17,
      "y": 10,
      "z": 15,
      "name": "Rock_Sandstone_Red"
    },
    {
      "x": -17,
      "y": 11,
      "z": 15,
      "name": "Rock_Sandstone_Red"
    },
    {
      "x": -17,
      "y": 12,
      "z": 15,
      "name": "Rock_Sandstone_Red"
    },
    {
      "x": -17,
      "y": 13,
      "z": 15,
      "name": "Rock_Sandstone_Red"
    },
    {
      "x": -17,
      "y": 14,
      "z": 15,
      "name": "Rock_Sandstone_Red"
    },
    {
      "x": -17,
      "y": 15,
      "z": 15,
      "name": "Rock_Sandstone_Red"
    },
    {
      "x": -17,
      "y": 16,
      "z": 15,
      "name": "Rock_Sandstone_Red"
    },
    {
      "x": -17,
      "y": 17,
      "z": 15,
      "name": "Rock_Sandstone_Red"
    },
    {
      "x": -17,
      "y": 18,
      "z": 15,
      "name": "Rock_Sandstone_Red"
    },
    {
      "x": -17,
      "y": 19,
      "z": 15,
      "name": "Rock_Sandstone_Red"
    },
    {
      "x": -17,
      "y": 20,
      "z": 15,
      "name": "Rubble_Sandstone_Red_Medium"
    },
    {
      "x": -17,
      "y": 4,
      "z": 16,
      "name": "Rock_Crystal_Red_Medium",
      "rotation": 7
    },
    {
      "x": -17,
      "y": 5,
      "z": 16,
      "name": "Rock_Crystal_Red_Large",
      "rotation": 8
    },
    {
      "x": -17,
      "y": 6,
      "z": 16,
      "name": "Rock_Crystal_Red_Block"
    },
    {
      "x": -17,
      "y": 7,
      "z": 16,
      "name": "Rock_Crystal_Red_Block"
    },
    {
      "x": -17,
      "y": 8,
      "z": 16,
      "name": "Rock_Crystal_Red_Block"
    },
    {
      "x": -17,
      "y": 9,
      "z": 16,
      "name": "Rock_Crystal_Red_Block"
    },
    {
      "x": -17,
      "y": 10,
      "z": 16,
      "name": "Rock_Crystal_Red_Block"
    },
    {
      "x": -17,
      "y": 11,
      "z": 16,
      "name": "Rock_Sandstone_Red"
    },
    {
      "x": -17,
      "y": 12,
      "z": 16,
      "name": "Rock_Sandstone_Red"
    },
    {
      "x": -17,
      "y": 13,
      "z": 16,
      "name": "Rock_Sandstone_Red"
    },
    {
      "x": -17,
      "y": 14,
      "z": 16,
      "name": "Rock_Sandstone_Red"
    },
    {
      "x": -17,
      "y": 15,
      "z": 16,
      "name": "Rock_Sandstone_Red"
    },
    {
      "x": -17,
      "y": 16,
      "z": 16,
      "name": "Rock_Sandstone_Red_Cobble"
    },
    {
      "x": -17,
      "y": 17,
      "z": 16,
      "name": "Soil_Sand_Red"
    },
    {
      "x": -17,
      "y": 18,
      "z": 16,
      "name": "Soil_Sand_Red"
    },
    {
      "x": -17,
      "y": 6,
      "z": 17,
      "name": "Rock_Crystal_Red_Medium",
      "rotation": 4
    },
    {
      "x": -17,
      "y": 7,
      "z": 17,
      "name": "Rock_Sandstone_Red"
    },
    {
      "x": -17,
      "y": 8,
      "z": 17,
      "name": "Rock_Sandstone_Red"
    },
    {
      "x": -17,
      "y": 9,
      "z": 17,
      "name": "Rock_Sandstone_Red"
    },
    {
      "x": -17,
      "y": 10,
      "z": 17,
      "name": "Rock_Sandstone_Red"
    },
    {
      "x": -17,
      "y": 11,
      "z": 17,
      "name": "Rock_Sandstone_Red"
    },
    {
      "x": -17,
      "y": 12,
      "z": 17,
      "name": "Rock_Sandstone_Red"
    },
    {
      "x": -17,
      "y": 13,
      "z": 17,
      "name": "Rock_Sandstone_Red"
    },
    {
      "x": -17,
      "y": 14,
      "z": 17,
      "name": "Rock_Sandstone_Red"
    },
    {
      "x": -17,
      "y": 15,
      "z": 17,
      "name": "Rock_Sandstone_Red"
    },
    {
      "x": -17,
      "y": 16,
      "z": 17,
      "name": "Soil_Sand_Red"
    },
    {
      "x": -17,
      "y": 17,
      "z": 17,
      "name": "Soil_Sand_Red"
    },
    {
      "x": -17,
      "y": 18,
      "z": 17,
      "name": "Soil_Gravel_Sand_Red"
    },
    {
      "x": -17,
      "y": 8,
      "z": 18,
      "name": "Rock_Sandstone_Red"
    },
    {
      "x": -17,
      "y": 9,
      "z": 18,
      "name": "Rock_Sandstone_Red"
    },
    {
      "x": -17,
      "y": 10,
      "z": 18,
      "name": "Rock_Sandstone_Red"
    },
    {
      "x": -17,
      "y": 11,
      "z": 18,
      "name": "Rock_Sandstone_Red"
    },
    {
      "x": -17,
      "y": 12,
      "z": 18,
      "name": "Rock_Sandstone_Red"
    },
    {
      "x": -17,
      "y": 13,
      "z": 18,
      "name": "Rock_Sandstone_Red"
    },
    {
      "x": -17,
      "y": 14,
      "z": 18,
      "name": "Rock_Sandstone_Red"
    },
    {
      "x": -17,
      "y": 15,
      "z": 18,
      "name": "Rock_Sandstone_Red_Cobble"
    },
    {
      "x": -17,
      "y": 16,
      "z": 18,
      "name": "Soil_Sand_Red"
    },
    {
      "x": -17,
      "y": 17,
      "z": 18,
      "name": "Soil_Gravel_Sand_Red"
    },
    {
      "x": -17,
      "y": 9,
      "z": 19,
      "name": "Rock_Sandstone_Red"
    },
    {
      "x": -17,
      "y": 10,
      "z": 19,
      "name": "Rock_Sandstone_Red"
    },
    {
      "x": -17,
      "y": 11,
      "z": 19,
      "name": "Rock_Sandstone_Red"
    },
    {
      "x": -17,
      "y": 12,
      "z": 19,
      "name": "Rock_Sandstone_Red"
    },
    {
      "x": -17,
      "y": 13,
      "z": 19,
      "name": "Rock_Sandstone_Red"
    },
    {
      "x": -17,
      "y": 14,
      "z": 19,
      "name": "Rock_Sandstone_Red"
    },
    {
      "x": -17,
      "y": 15,
      "z": 19,
      "name": "Soil_Gravel_Sand_Red"
    },
    {
      "x": -17,
      "y": 16,
      "z": 19,
      "name": "Soil_Gravel_Sand_Red"
    },
    {
      "x": -17,
      "y": 12,
      "z": 20,
      "name": "Rock_Sandstone_Red"
    },
    {
      "x": -17,
      "y": 13,
      "z": 20,
      "name": "Rock_Sandstone_Red"
    },
    {
      "x": -17,
      "y": 14,
      "z": 20,
      "name": "Rock_Sandstone_Red"
    },
    {
      "x": -17,
      "y": 15,
      "z": 20,
      "name": "Rubble_Sandstone_Red"
    },
    {
      "x": -16,
      "y": 17,
      "z": 9,
      "name": "Rock_Sandstone_Red"
    },
    {
      "x": -16,
      "y": 18,
      "z": 9,
      "name": "Rock_Sandstone_Red"
    },
    {
      "x": -16,
      "y": 19,
      "z": 9,
      "name": "Soil_Sand_Red"
    },
    {
      "x": -16,
      "y": 20,
      "z": 9,
      "name": "Soil_Sand_Red"
    },
    {
      "x": -16,
      "y": 14,
      "z": 10,
      "name": "Rock_Sandstone_Red"
    },
    {
      "x": -16,
      "y": 15,
      "z": 10,
      "name": "Rock_Sandstone_Red"
    },
    {
      "x": -16,
      "y": 16,
      "z": 10,
      "name": "Rock_Sandstone_Red"
    },
    {
      "x": -16,
      "y": 17,
      "z": 10,
      "name": "Rock_Sandstone_Red"
    },
    {
      "x": -16,
      "y": 18,
      "z": 10,
      "name": "Rock_Sandstone_Red_Cobble"
    },
    {
      "x": -16,
      "y": 19,
      "z": 10,
      "name": "Soil_Sand_Red"
    },
    {
      "x": -16,
      "y": 12,
      "z": 11,
      "name": "Plant_Bush_Dead_Hanging"
    },
    {
      "x": -16,
      "y": 13,
      "z": 11,
      "name": "Rock_Sandstone_Red"
    },
    {
      "x": -16,
      "y": 14,
      "z": 11,
      "name": "Rock_Sandstone_Red"
    },
    {
      "x": -16,
      "y": 15,
      "z": 11,
      "name": "Rock_Sandstone_Red"
    },
    {
      "x": -16,
      "y": 16,
      "z": 11,
      "name": "Rock_Sandstone_Red"
    },
    {
      "x": -16,
      "y": 17,
      "z": 11,
      "name": "Rock_Sandstone_Red"
    },
    {
      "x": -16,
      "y": 18,
      "z": 11,
      "name": "Rock_Sandstone_Red"
    },
    {
      "x": -16,
      "y": 19,
      "z": 11,
      "name": "Rock_Sandstone_Red"
    },
    {
      "x": -16,
      "y": 20,
      "z": 11,
      "name": "Soil_Sand_Red"
    },
    {
      "x": -16,
      "y": 11,
      "z": 12,
      "name": "Rock_Sandstone_Red"
    },
    {
      "x": -16,
      "y": 12,
      "z": 12,
      "name": "Rock_Sandstone_Red"
    },
    {
      "x": -16,
      "y": 13,
      "z": 12,
      "name": "Rock_Sandstone_Red"
    },
    {
      "x": -16,
      "y": 14,
      "z": 12,
      "name": "Rock_Sandstone_Red"
    },
    {
      "x": -16,
      "y": 15,
      "z": 12,
      "name": "Rock_Sandstone_Red"
    },
    {
      "x": -16,
      "y": 16,
      "z": 12,
      "name": "Rock_Sandstone_Red"
    },
    {
      "x": -16,
      "y": 17,
      "z": 12,
      "name": "Rock_Sandstone_Red"
    },
    {
      "x": -16,
      "y": 18,
      "z": 12,
      "name": "Rock_Sandstone_Red_Cobble"
    },
    {
      "x": -16,
      "y": 19,
      "z": 12,
      "name": "Soil_Sand_Red"
    },
    {
      "x": -16,
      "y": 20,
      "z": 12,
      "name": "Soil_Sand_Red"
    },
    {
      "x": -16,
      "y": 9,
      "z": 13,
      "name": "Rock_Sandstone_Red"
    },
    {
      "x": -16,
      "y": 10,
      "z": 13,
      "name": "Rock_Sandstone_Red"
    },
    {
      "x": -16,
      "y": 11,
      "z": 13,
      "name": "Rock_Sandstone_Red"
    },
    {
      "x": -16,
      "y": 12,
      "z": 13,
      "name": "Rock_Sandstone_Red"
    },
    {
      "x": -16,
      "y": 13,
      "z": 13,
      "name": "Rock_Sandstone_Red"
    },
    {
      "x": -16,
      "y": 14,
      "z": 13,
      "name": "Rock_Sandstone_Red"
    },
    {
      "x": -16,
      "y": 15,
      "z": 13,
      "name": "Rock_Sandstone_Red"
    },
    {
      "x": -16,
      "y": 16,
      "z": 13,
      "name": "Rock_Sandstone_Red"
    },
    {
      "x": -16,
      "y": 17,
      "z": 13,
      "name": "Rock_Sandstone_Red"
    },
    {
      "x": -16,
      "y": 18,
      "z": 13,
      "name": "Rock_Sandstone_Red"
    },
    {
      "x": -16,
      "y": 19,
      "z": 13,
      "name": "Rock_Sandstone_Red"
    },
    {
      "x": -16,
      "y": 20,
      "z": 13,
      "name": "Rock_Sandstone_Red_Cobble"
    },
    {
      "x": -16,
      "y": 8,
      "z": 14,
      "name": "Rock_Sandstone_Red"
    },
    {
      "x": -16,
      "y": 9,
      "z": 14,
      "name": "Rock_Sandstone_Red"
    },
    {
      "x": -16,
      "y": 10,
      "z": 14,
      "name": "Rock_Sandstone_Red"
    },
    {
      "x": -16,
      "y": 11,
      "z": 14,
      "name": "Rock_Sandstone_Red"
    },
    {
      "x": -16,
      "y": 12,
      "z": 14,
      "name": "Rock_Sandstone_Red"
    },
    {
      "x": -16,
      "y": 13,
      "z": 14,
      "name": "Rock_Sandstone_Red"
    },
    {
      "x": -16,
      "y": 14,
      "z": 14,
      "name": "Rock_Sandstone_Red"
    },
    {
      "x": -16,
      "y": 15,
      "z": 14,
      "name": "Rock_Sandstone_Red"
    },
    {
      "x": -16,
      "y": 16,
      "z": 14,
      "name": "Rock_Sandstone_Red"
    },
    {
      "x": -16,
      "y": 17,
      "z": 14,
      "name": "Rock_Sandstone_Red"
    },
    {
      "x": -16,
      "y": 18,
      "z": 14,
      "name": "Rock_Sandstone_Red"
    },
    {
      "x": -16,
      "y": 19,
      "z": 14,
      "name": "Rock_Sandstone_Red"
    },
    {
      "x": -16,
      "y": 20,
      "z": 14,
      "name": "Rock_Sandstone_Red"
    },
    {
      "x": -16,
      "y": 5,
      "z": 15,
      "name": "Rock_Crystal_Red_Medium",
      "rotation": 8
    },
    {
      "x": -16,
      "y": 6,
      "z": 15,
      "name": "Rock_Crystal_Red_Block"
    },
    {
      "x": -16,
      "y": 7,
      "z": 15,
      "name": "Rock_Crystal_Red_Block"
    },
    {
      "x": -16,
      "y": 8,
      "z": 15,
      "name": "Rock_Crystal_Red_Block"
    },
    {
      "x": -16,
      "y": 9,
      "z": 15,
      "name": "Rock_Crystal_Red_Block"
    },
    {
      "x": -16,
      "y": 10,
      "z": 15,
      "name": "Rock_Crystal_Red_Block"
    },
    {
      "x": -16,
      "y": 11,
      "z": 15,
      "name": "Rock_Sandstone_Red"
    },
    {
      "x": -16,
      "y": 12,
      "z": 15,
      "name": "Rock_Sandstone_Red"
    },
    {
      "x": -16,
      "y": 13,
      "z": 15,
      "name": "Rock_Sandstone_Red"
    },
    {
      "x": -16,
      "y": 14,
      "z": 15,
      "name": "Rock_Sandstone_Red"
    },
    {
      "x": -16,
      "y": 15,
      "z": 15,
      "name": "Rock_Sandstone_Red"
    },
    {
      "x": -16,
      "y": 16,
      "z": 15,
      "name": "Rock_Sandstone_Red"
    },
    {
      "x": -16,
      "y": 17,
      "z": 15,
      "name": "Soil_Sand_Red"
    },
    {
      "x": -16,
      "y": 18,
      "z": 15,
      "name": "Soil_Sand_Red"
    },
    {
      "x": -16,
      "y": 19,
      "z": 15,
      "name": "Soil_Sand_Red"
    },
    {
      "x": -16,
      "y": 3,
      "z": 16,
      "name": "Rock_Crystal_Red_Large",
      "rotation": 8
    },
    {
      "x": -16,
      "y": 4,
      "z": 16,
      "name": "Rock_Crystal_Red_Block"
    },
    {
      "x": -16,
      "y": 5,
      "z": 16,
      "name": "Rock_Crystal_Red_Block"
    },
    {
      "x": -16,
      "y": 6,
      "z": 16,
      "name": "Rock_Crystal_Red_Block"
    },
    {
      "x": -16,
      "y": 7,
      "z": 16,
      "name": "Rock_Crystal_Red_Block"
    },
    {
      "x": -16,
      "y": 8,
      "z": 16,
      "name": "Rock_Crystal_Red_Block"
    },
    {
      "x": -16,
      "y": 9,
      "z": 16,
      "name": "Rock_Crystal_Red_Block"
    },
    {
      "x": -16,
      "y": 10,
      "z": 16,
      "name": "Rock_Crystal_Red_Block"
    },
    {
      "x": -16,
      "y": 11,
      "z": 16,
      "name": "Rock_Sandstone_Red"
    },
    {
      "x": -16,
      "y": 12,
      "z": 16,
      "name": "Rock_Sandstone_Red"
    },
    {
      "x": -16,
      "y": 13,
      "z": 16,
      "name": "Rock_Sandstone_Red"
    },
    {
      "x": -16,
      "y": 14,
      "z": 16,
      "name": "Rock_Sandstone_Red"
    },
    {
      "x": -16,
      "y": 15,
      "z": 16,
      "name": "Rock_Sandstone_Red"
    },
    {
      "x": -16,
      "y": 16,
      "z": 16,
      "name": "Rock_Sandstone_Red"
    },
    {
      "x": -16,
      "y": 17,
      "z": 16,
      "name": "Rock_Sandstone_Red_Cobble"
    },
    {
      "x": -16,
      "y": 18,
      "z": 16,
      "name": "Soil_Sand_Red"
    },
    {
      "x": -16,
      "y": 19,
      "z": 16,
      "name": "Soil_Sand_Red"
    },
    {
      "x": -16,
      "y": 4,
      "z": 17,
      "name": "Rock_Crystal_Red_Large",
      "rotation": 8
    },
    {
      "x": -16,
      "y": 5,
      "z": 17,
      "name": "Rock_Crystal_Red_Block"
    },
    {
      "x": -16,
      "y": 6,
      "z": 17,
      "name": "Rock_Crystal_Red_Block"
    },
    {
      "x": -16,
      "y": 7,
      "z": 17,
      "name": "Rock_Crystal_Red_Block"
    },
    {
      "x": -16,
      "y": 8,
      "z": 17,
      "name": "Rock_Crystal_Red_Block"
    },
    {
      "x": -16,
      "y": 9,
      "z": 17,
      "name": "Rock_Crystal_Red_Block"
    },
    {
      "x": -16,
      "y": 10,
      "z": 17,
      "name": "Rock_Crystal_Red_Block"
    },
    {
      "x": -16,
      "y": 11,
      "z": 17,
      "name": "Rock_Sandstone_Red"
    },
    {
      "x": -16,
      "y": 12,
      "z": 17,
      "name": "Rock_Sandstone_Red"
    },
    {
      "x": -16,
      "y": 13,
      "z": 17,
      "name": "Rock_Sandstone_Red"
    },
    {
      "x": -16,
      "y": 14,
      "z": 17,
      "name": "Rock_Sandstone_Red"
    },
    {
      "x": -16,
      "y": 15,
      "z": 17,
      "name": "Rock_Sandstone_Red"
    },
    {
      "x": -16,
      "y": 16,
      "z": 17,
      "name": "Soil_Gravel_Sand_Red"
    },
    {
      "x": -16,
      "y": 17,
      "z": 17,
      "name": "Soil_Sand_Red"
    },
    {
      "x": -16,
      "y": 18,
      "z": 17,
      "name": "Soil_Sand_Red"
    },
    {
      "x": -16,
      "y": 6,
      "z": 18,
      "name": "Rock_Crystal_Red_Medium",
      "rotation": 4
    },
    {
      "x": -16,
      "y": 8,
      "z": 18,
      "name": "Rock_Sandstone_Red"
    },
    {
      "x": -16,
      "y": 9,
      "z": 18,
      "name": "Rock_Sandstone_Red"
    },
    {
      "x": -16,
      "y": 10,
      "z": 18,
      "name": "Rock_Sandstone_Red"
    },
    {
      "x": -16,
      "y": 11,
      "z": 18,
      "name": "Rock_Sandstone_Red"
    },
    {
      "x": -16,
      "y": 12,
      "z": 18,
      "name": "Rock_Sandstone_Red"
    },
    {
      "x": -16,
      "y": 13,
      "z": 18,
      "name": "Rock_Sandstone_Red"
    },
    {
      "x": -16,
      "y": 14,
      "z": 18,
      "name": "Rock_Sandstone_Red"
    },
    {
      "x": -16,
      "y": 15,
      "z": 18,
      "name": "Rock_Sandstone_Red"
    },
    {
      "x": -16,
      "y": 16,
      "z": 18,
      "name": "Rock_Sandstone_Red_Cobble"
    },
    {
      "x": -16,
      "y": 17,
      "z": 18,
      "name": "Rock_Sandstone_Red_Cobble"
    },
    {
      "x": -16,
      "y": 18,
      "z": 18,
      "name": "Plant_Flower_Bushy_Orange"
    },
    {
      "x": -16,
      "y": 9,
      "z": 19,
      "name": "Rock_Sandstone_Red"
    },
    {
      "x": -16,
      "y": 10,
      "z": 19,
      "name": "Rock_Sandstone_Red"
    },
    {
      "x": -16,
      "y": 11,
      "z": 19,
      "name": "Rock_Sandstone_Red"
    },
    {
      "x": -16,
      "y": 12,
      "z": 19,
      "name": "Rock_Sandstone_Red"
    },
    {
      "x": -16,
      "y": 13,
      "z": 19,
      "name": "Rock_Sandstone_Red"
    },
    {
      "x": -16,
      "y": 14,
      "z": 19,
      "name": "Rock_Sandstone_Red"
    },
    {
      "x": -16,
      "y": 15,
      "z": 19,
      "name": "Rock_Sandstone_Red"
    },
    {
      "x": -16,
      "y": 16,
      "z": 19,
      "name": "Soil_Sand_Red"
    },
    {
      "x": -16,
      "y": 13,
      "z": 20,
      "name": "Rock_Sandstone_Red"
    },
    {
      "x": -16,
      "y": 14,
      "z": 20,
      "name": "Rock_Sandstone_Red"
    },
    {
      "x": -16,
      "y": 13,
      "z": 21,
      "name": "Plant_Crop_Mushroom_Shelve_Yellow"
    },
    {
      "x": -15,
      "y": 17,
      "z": 8,
      "name": "Plant_Crop_Mushroom_Shelve_Yellow"
    },
    {
      "x": -15,
      "y": 19,
      "z": 8,
      "name": "Rock_Sandstone_Red_Cobble"
    },
    {
      "x": -15,
      "y": 20,
      "z": 8,
      "name": "Soil_Sand_Red"
    },
    {
      "x": -15,
      "y": 15,
      "z": 9,
      "name": "Rock_Sandstone_Red"
    },
    {
      "x": -15,
      "y": 16,
      "z": 9,
      "name": "Rock_Sandstone_Red"
    },
    {
      "x": -15,
      "y": 17,
      "z": 9,
      "name": "Rock_Sandstone_Red"
    },
    {
      "x": -15,
      "y": 18,
      "z": 9,
      "name": "Soil_Sand_Red"
    },
    {
      "x": -15,
      "y": 19,
      "z": 9,
      "name": "Soil_Sand_Red"
    },
    {
      "x": -15,
      "y": 20,
      "z": 9,
      "name": "Soil_Sand_Red"
    },
    {
      "x": -15,
      "y": 21,
      "z": 9,
      "name": "Plant_Bush_Arid"
    },
    {
      "x": -15,
      "y": 13,
      "z": 10,
      "name": "Rock_Sandstone_Red"
    },
    {
      "x": -15,
      "y": 14,
      "z": 10,
      "name": "Rock_Sandstone_Red"
    },
    {
      "x": -15,
      "y": 15,
      "z": 10,
      "name": "Rock_Sandstone_Red"
    },
    {
      "x": -15,
      "y": 16,
      "z": 10,
      "name": "Rock_Sandstone_Red"
    },
    {
      "x": -15,
      "y": 17,
      "z": 10,
      "name": "Rock_Sandstone_Red"
    },
    {
      "x": -15,
      "y": 18,
      "z": 10,
      "name": "Soil_Sand_Red"
    },
    {
      "x": -15,
      "y": 19,
      "z": 10,
      "name": "Soil_Sand_Red"
    },
    {
      "x": -15,
      "y": 20,
      "z": 10,
      "name": "Rock_Sandstone_Red_Cobble"
    },
    {
      "x": -15,
      "y": 21,
      "z": 10,
      "name": "Soil_Sand_Red"
    },
    {
      "x": -15,
      "y": 12,
      "z": 11,
      "name": "Rock_Sandstone_Red"
    },
    {
      "x": -15,
      "y": 13,
      "z": 11,
      "name": "Rock_Sandstone_Red"
    },
    {
      "x": -15,
      "y": 14,
      "z": 11,
      "name": "Rock_Sandstone_Red"
    },
    {
      "x": -15,
      "y": 15,
      "z": 11,
      "name": "Rock_Sandstone_Red"
    },
    {
      "x": -15,
      "y": 16,
      "z": 11,
      "name": "Rock_Sandstone_Red"
    },
    {
      "x": -15,
      "y": 17,
      "z": 11,
      "name": "Rock_Sandstone_Red"
    },
    {
      "x": -15,
      "y": 18,
      "z": 11,
      "name": "Rock_Sandstone_Red"
    },
    {
      "x": -15,
      "y": 19,
      "z": 11,
      "name": "Soil_Sand_Red"
    },
    {
      "x": -15,
      "y": 20,
      "z": 11,
      "name": "Soil_Sand_Red"
    },
    {
      "x": -15,
      "y": 21,
      "z": 11,
      "name": "Soil_Sand_Red"
    },
    {
      "x": -15,
      "y": 11,
      "z": 12,
      "name": "Rock_Sandstone_Red"
    },
    {
      "x": -15,
      "y": 12,
      "z": 12,
      "name": "Rock_Sandstone_Red"
    },
    {
      "x": -15,
      "y": 13,
      "z": 12,
      "name": "Rock_Sandstone_Red"
    },
    {
      "x": -15,
      "y": 14,
      "z": 12,
      "name": "Rock_Sandstone_Red"
    },
    {
      "x": -15,
      "y": 15,
      "z": 12,
      "name": "Rock_Sandstone_Red"
    },
    {
      "x": -15,
      "y": 16,
      "z": 12,
      "name": "Rock_Sandstone_Red"
    },
    {
      "x": -15,
      "y": 17,
      "z": 12,
      "name": "Rock_Sandstone_Red"
    },
    {
      "x": -15,
      "y": 18,
      "z": 12,
      "name": "Rock_Sandstone_Red"
    },
    {
      "x": -15,
      "y": 19,
      "z": 12,
      "name": "Rock_Sandstone_Red"
    },
    {
      "x": -15,
      "y": 20,
      "z": 12,
      "name": "Rock_Sandstone_Red"
    },
    {
      "x": -15,
      "y": 21,
      "z": 12,
      "name": "Rock_Sandstone_Red"
    },
    {
      "x": -15,
      "y": 10,
      "z": 13,
      "name": "Rock_Sandstone_Red"
    },
    {
      "x": -15,
      "y": 11,
      "z": 13,
      "name": "Rock_Sandstone_Red"
    },
    {
      "x": -15,
      "y": 12,
      "z": 13,
      "name": "Rock_Sandstone_Red"
    },
    {
      "x": -15,
      "y": 13,
      "z": 13,
      "name": "Rock_Sandstone_Red"
    },
    {
      "x": -15,
      "y": 14,
      "z": 13,
      "name": "Rock_Sandstone_Red"
    },
    {
      "x": -15,
      "y": 15,
      "z": 13,
      "name": "Rock_Sandstone_Red"
    },
    {
      "x": -15,
      "y": 16,
      "z": 13,
      "name": "Rock_Sandstone_Red"
    },
    {
      "x": -15,
      "y": 17,
      "z": 13,
      "name": "Rock_Sandstone_Red"
    },
    {
      "x": -15,
      "y": 18,
      "z": 13,
      "name": "Rock_Sandstone_Red"
    },
    {
      "x": -15,
      "y": 19,
      "z": 13,
      "name": "Rock_Sandstone_Red"
    },
    {
      "x": -15,
      "y": 20,
      "z": 13,
      "name": "Rock_Sandstone_Red"
    },
    {
      "x": -15,
      "y": 21,
      "z": 13,
      "name": "Rock_Sandstone_Red"
    },
    {
      "x": -15,
      "y": 9,
      "z": 14,
      "name": "Rock_Sandstone_Red"
    },
    {
      "x": -15,
      "y": 10,
      "z": 14,
      "name": "Rock_Sandstone_Red"
    },
    {
      "x": -15,
      "y": 11,
      "z": 14,
      "name": "Rock_Sandstone_Red"
    },
    {
      "x": -15,
      "y": 12,
      "z": 14,
      "name": "Rock_Sandstone_Red"
    },
    {
      "x": -15,
      "y": 13,
      "z": 14,
      "name": "Rock_Sandstone_Red"
    },
    {
      "x": -15,
      "y": 14,
      "z": 14,
      "name": "Rock_Sandstone_Red"
    },
    {
      "x": -15,
      "y": 15,
      "z": 14,
      "name": "Rock_Sandstone_Red"
    },
    {
      "x": -15,
      "y": 16,
      "z": 14,
      "name": "Rock_Sandstone_Red"
    },
    {
      "x": -15,
      "y": 17,
      "z": 14,
      "name": "Rock_Sandstone_Red"
    },
    {
      "x": -15,
      "y": 18,
      "z": 14,
      "name": "Rock_Sandstone_Red"
    },
    {
      "x": -15,
      "y": 19,
      "z": 14,
      "name": "Rock_Sandstone_Red"
    },
    {
      "x": -15,
      "y": 20,
      "z": 14,
      "name": "Rock_Sandstone_Red"
    },
    {
      "x": -15,
      "y": 21,
      "z": 14,
      "name": "Rubble_Sandstone_Red"
    },
    {
      "x": -15,
      "y": 6,
      "z": 15,
      "name": "Rock_Crystal_Red_Medium",
      "rotation": 5
    },
    {
      "x": -15,
      "y": 8,
      "z": 15,
      "name": "Rock_Sandstone_Red"
    },
    {
      "x": -15,
      "y": 9,
      "z": 15,
      "name": "Rock_Sandstone_Red"
    },
    {
      "x": -15,
      "y": 10,
      "z": 15,
      "name": "Rock_Sandstone_Red"
    },
    {
      "x": -15,
      "y": 11,
      "z": 15,
      "name": "Rock_Sandstone_Red"
    },
    {
      "x": -15,
      "y": 12,
      "z": 15,
      "name": "Rock_Sandstone_Red"
    },
    {
      "x": -15,
      "y": 13,
      "z": 15,
      "name": "Rock_Sandstone_Red"
    },
    {
      "x": -15,
      "y": 14,
      "z": 15,
      "name": "Rock_Sandstone_Red"
    },
    {
      "x": -15,
      "y": 15,
      "z": 15,
      "name": "Rock_Sandstone_Red"
    },
    {
      "x": -15,
      "y": 16,
      "z": 15,
      "name": "Rock_Sandstone_Red"
    },
    {
      "x": -15,
      "y": 17,
      "z": 15,
      "name": "Rock_Sandstone_Red"
    },
    {
      "x": -15,
      "y": 18,
      "z": 15,
      "name": "Rock_Sandstone_Red"
    },
    {
      "x": -15,
      "y": 19,
      "z": 15,
      "name": "Rock_Sandstone_Red"
    },
    {
      "x": -15,
      "y": 20,
      "z": 15,
      "name": "Rock_Sandstone_Red"
    },
    {
      "x": -15,
      "y": 4,
      "z": 16,
      "name": "Rock_Crystal_Red_Medium",
      "rotation": 5
    },
    {
      "x": -15,
      "y": 5,
      "z": 16,
      "name": "Rock_Crystal_Red_Block"
    },
    {
      "x": -15,
      "y": 6,
      "z": 16,
      "name": "Rock_Crystal_Red_Block"
    },
    {
      "x": -15,
      "y": 7,
      "z": 16,
      "name": "Rock_Crystal_Red_Block"
    },
    {
      "x": -15,
      "y": 8,
      "z": 16,
      "name": "Rock_Crystal_Red_Block"
    },
    {
      "x": -15,
      "y": 9,
      "z": 16,
      "name": "Rock_Crystal_Red_Block"
    },
    {
      "x": -15,
      "y": 10,
      "z": 16,
      "name": "Rock_Crystal_Red_Block"
    },
    {
      "x": -15,
      "y": 11,
      "z": 16,
      "name": "Rock_Sandstone_Red"
    },
    {
      "x": -15,
      "y": 12,
      "z": 16,
      "name": "Rock_Sandstone_Red"
    },
    {
      "x": -15,
      "y": 13,
      "z": 16,
      "name": "Rock_Sandstone_Red"
    },
    {
      "x": -15,
      "y": 14,
      "z": 16,
      "name": "Rock_Sandstone_Red"
    },
    {
      "x": -15,
      "y": 15,
      "z": 16,
      "name": "Rock_Sandstone_Red"
    },
    {
      "x": -15,
      "y": 16,
      "z": 16,
      "name": "Rock_Sandstone_Red"
    },
    {
      "x": -15,
      "y": 17,
      "z": 16,
      "name": "Rock_Sandstone_Red"
    },
    {
      "x": -15,
      "y": 18,
      "z": 16,
      "name": "Rock_Sandstone_Red_Cobble"
    },
    {
      "x": -15,
      "y": 19,
      "z": 16,
      "name": "Soil_Sand_Red"
    },
    {
      "x": -15,
      "y": 5,
      "z": 17,
      "name": "Rock_Crystal_Red_Medium",
      "rotation": 5
    },
    {
      "x": -15,
      "y": 6,
      "z": 17,
      "name": "Rock_Crystal_Red_Medium",
      "rotation": 5
    },
    {
      "x": -15,
      "y": 7,
      "z": 17,
      "name": "Rock_Crystal_Red_Medium",
      "rotation": 8
    },
    {
      "x": -15,
      "y": 8,
      "z": 17,
      "name": "Rock_Sandstone_Red"
    },
    {
      "x": -15,
      "y": 9,
      "z": 17,
      "name": "Rock_Sandstone_Red"
    },
    {
      "x": -15,
      "y": 10,
      "z": 17,
      "name": "Rock_Sandstone_Red"
    },
    {
      "x": -15,
      "y": 11,
      "z": 17,
      "name": "Rock_Sandstone_Red"
    },
    {
      "x": -15,
      "y": 12,
      "z": 17,
      "name": "Rock_Sandstone_Red"
    },
    {
      "x": -15,
      "y": 13,
      "z": 17,
      "name": "Rock_Sandstone_Red"
    },
    {
      "x": -15,
      "y": 14,
      "z": 17,
      "name": "Rock_Sandstone_Red"
    },
    {
      "x": -15,
      "y": 15,
      "z": 17,
      "name": "Rock_Sandstone_Red"
    },
    {
      "x": -15,
      "y": 16,
      "z": 17,
      "name": "Soil_Sand_Red"
    },
    {
      "x": -15,
      "y": 17,
      "z": 17,
      "name": "Rock_Sandstone_Red_Cobble"
    },
    {
      "x": -15,
      "y": 18,
      "z": 17,
      "name": "Soil_Sand_Red"
    },
    {
      "x": -15,
      "y": 9,
      "z": 18,
      "name": "Rock_Sandstone_Red"
    },
    {
      "x": -15,
      "y": 10,
      "z": 18,
      "name": "Rock_Sandstone_Red"
    },
    {
      "x": -15,
      "y": 11,
      "z": 18,
      "name": "Rock_Sandstone_Red"
    },
    {
      "x": -15,
      "y": 12,
      "z": 18,
      "name": "Rock_Sandstone_Red"
    },
    {
      "x": -15,
      "y": 13,
      "z": 18,
      "name": "Rock_Sandstone_Red"
    },
    {
      "x": -15,
      "y": 14,
      "z": 18,
      "name": "Rock_Sandstone_Red"
    },
    {
      "x": -15,
      "y": 15,
      "z": 18,
      "name": "Rock_Sandstone_Red"
    },
    {
      "x": -15,
      "y": 16,
      "z": 18,
      "name": "Rock_Sandstone_Red"
    },
    {
      "x": -15,
      "y": 17,
      "z": 18,
      "name": "Rock_Sandstone_Red"
    },
    {
      "x": -15,
      "y": 11,
      "z": 19,
      "name": "Rock_Sandstone_Red"
    },
    {
      "x": -15,
      "y": 12,
      "z": 19,
      "name": "Rock_Sandstone_Red"
    },
    {
      "x": -15,
      "y": 13,
      "z": 19,
      "name": "Rock_Sandstone_Red"
    },
    {
      "x": -15,
      "y": 14,
      "z": 19,
      "name": "Rock_Sandstone_Red"
    },
    {
      "x": -15,
      "y": 15,
      "z": 19,
      "name": "Rock_Sandstone_Red"
    },
    {
      "x": -15,
      "y": 16,
      "z": 19,
      "name": "Rock_Sandstone_Red"
    },
    {
      "x": -15,
      "y": 14,
      "z": 20,
      "name": "Plant_Crop_Mushroom_Shelve_Yellow"
    },
    {
      "x": -14,
      "y": 24,
      "z": 2,
      "name": "Plant_Crop_Mushroom_Shelve_Yellow"
    },
    {
      "x": -14,
      "y": 23,
      "z": 3,
      "name": "Plant_Crop_Mushroom_Shelve_Yellow"
    },
    {
      "x": -14,
      "y": 22,
      "z": 4,
      "name": "Plant_Crop_Mushroom_Shelve_Yellow"
    },
    {
      "x": -14,
      "y": 23,
      "z": 4,
      "name": "Rock_Sandstone_Red"
    },
    {
      "x": -14,
      "y": 24,
      "z": 4,
      "name": "Soil_Sand_Red"
    },
    {
      "x": -14,
      "y": 25,
      "z": 4,
      "name": "Soil_Sand_Red"
    },
    {
      "x": -14,
      "y": 21,
      "z": 5,
      "name": "Rock_Sandstone_Red"
    },
    {
      "x": -14,
      "y": 22,
      "z": 5,
      "name": "Rock_Sandstone_Red"
    },
    {
      "x": -14,
      "y": 23,
      "z": 5,
      "name": "Rock_Sandstone_Red"
    },
    {
      "x": -14,
      "y": 24,
      "z": 5,
      "name": "Soil_Sand_Red"
    },
    {
      "x": -14,
      "y": 25,
      "z": 5,
      "name": "Rock_Sandstone_Red_Cobble"
    },
    {
      "x": -14,
      "y": 20,
      "z": 6,
      "name": "Plant_Crop_Mushroom_Shelve_Yellow"
    },
    {
      "x": -14,
      "y": 22,
      "z": 6,
      "name": "Rock_Sandstone_Red"
    },
    {
      "x": -14,
      "y": 23,
      "z": 6,
      "name": "Rock_Sandstone_Red"
    },
    {
      "x": -14,
      "y": 24,
      "z": 6,
      "name": "Rock_Sandstone_Red"
    },
    {
      "x": -14,
      "y": 25,
      "z": 6,
      "name": "Soil_Gravel_Sand_Red"
    },
    {
      "x": -14,
      "y": 23,
      "z": 7,
      "name": "Rock_Sandstone_Red"
    },
    {
      "x": -14,
      "y": 24,
      "z": 7,
      "name": "Rock_Sandstone_Red"
    },
    {
      "x": -14,
      "y": 25,
      "z": 7,
      "name": "Rock_Sandstone_Red"
    },
    {
      "x": -14,
      "y": 17,
      "z": 8,
      "name": "Rock_Sandstone_Red"
    },
    {
      "x": -14,
      "y": 18,
      "z": 8,
      "name": "Rock_Sandstone_Red"
    },
    {
      "x": -14,
      "y": 19,
      "z": 8,
      "name": "Rock_Sandstone_Red"
    },
    {
      "x": -14,
      "y": 20,
      "z": 8,
      "name": "Soil_Sand_Red"
    },
    {
      "x": -14,
      "y": 24,
      "z": 8,
      "name": "Rock_Sandstone_Red"
    },
    {
      "x": -14,
      "y": 25,
      "z": 8,
      "name": "Soil_Sand_Red"
    },
    {
      "x": -14,
      "y": 14,
      "z": 9,
      "name": "Rock_Sandstone_Red"
    },
    {
      "x": -14,
      "y": 15,
      "z": 9,
      "name": "Rock_Sandstone_Red"
    },
    {
      "x": -14,
      "y": 16,
      "z": 9,
      "name": "Rock_Sandstone_Red"
    },
    {
      "x": -14,
      "y": 17,
      "z": 9,
      "name": "Rock_Sandstone_Red"
    },
    {
      "x": -14,
      "y": 18,
      "z": 9,
      "name": "Rock_Sandstone_Red"
    },
    {
      "x": -14,
      "y": 19,
      "z": 9,
      "name": "Rock_Sandstone_Red"
    },
    {
      "x": -14,
      "y": 20,
      "z": 9,
      "name": "Rock_Sandstone_Red"
    },
    {
      "x": -14,
      "y": 21,
      "z": 9,
      "name": "Rubble_Sandstone_Red"
    },
    {
      "x": -14,
      "y": 22,
      "z": 9,
      "name": "Rock_Sandstone_Red"
    },
    {
      "x": -14,
      "y": 23,
      "z": 9,
      "name": "Rock_Sandstone_Red"
    },
    {
      "x": -14,
      "y": 24,
      "z": 9,
      "name": "Rock_Sandstone_Red"
    },
    {
      "x": -14,
      "y": 12,
      "z": 10,
      "name": "Rock_Sandstone_Red"
    },
    {
      "x": -14,
      "y": 13,
      "z": 10,
      "name": "Rock_Sandstone_Red"
    },
    {
      "x": -14,
      "y": 14,
      "z": 10,
      "name": "Rock_Sandstone_Red"
    },
    {
      "x": -14,
      "y": 15,
      "z": 10,
      "name": "Rock_Sandstone_Red"
    },
    {
      "x": -14,
      "y": 16,
      "z": 10,
      "name": "Rock_Sandstone_Red"
    },
    {
      "x": -14,
      "y": 17,
      "z": 10,
      "name": "Rock_Sandstone_Red"
    },
    {
      "x": -14,
      "y": 18,
      "z": 10,
      "name": "Rock_Sandstone_Red"
    },
    {
      "x": -14,
      "y": 19,
      "z": 10,
      "name": "Rock_Sandstone_Red"
    },
    {
      "x": -14,
      "y": 20,
      "z": 10,
      "name": "Rock_Sandstone_Red"
    },
    {
      "x": -14,
      "y": 21,
      "z": 10,
      "name": "Rubble_Sandstone_Red"
    },
    {
      "x": -14,
      "y": 22,
      "z": 10,
      "name": "Rock_Sandstone_Red"
    },
    {
      "x": -14,
      "y": 23,
      "z": 10,
      "name": "Rock_Sandstone_Red"
    },
    {
      "x": -14,
      "y": 24,
      "z": 10,
      "name": "Rock_Sandstone_Red"
    },
    {
      "x": -14,
      "y": 25,
      "z": 10,
      "name": "Rock_Sandstone_Red"
    },
    {
      "x": -14,
      "y": 26,
      "z": 10,
      "name": "Rubble_Sandstone_Red_Medium"
    },
    {
      "x": -14,
      "y": 11,
      "z": 11,
      "name": "Rock_Sandstone_Red"
    },
    {
      "x": -14,
      "y": 12,
      "z": 11,
      "name": "Rock_Sandstone_Red"
    },
    {
      "x": -14,
      "y": 13,
      "z": 11,
      "name": "Rock_Sandstone_Red"
    },
    {
      "x": -14,
      "y": 14,
      "z": 11,
      "name": "Rock_Sandstone_Red"
    },
    {
      "x": -14,
      "y": 15,
      "z": 11,
      "name": "Rock_Sandstone_Red"
    },
    {
      "x": -14,
      "y": 16,
      "z": 11,
      "name": "Rock_Sandstone_Red"
    },
    {
      "x": -14,
      "y": 17,
      "z": 11,
      "name": "Rock_Sandstone_Red"
    },
    {
      "x": -14,
      "y": 18,
      "z": 11,
      "name": "Rock_Sandstone_Red"
    },
    {
      "x": -14,
      "y": 19,
      "z": 11,
      "name": "Rock_Sandstone_Red"
    },
    {
      "x": -14,
      "y": 20,
      "z": 11,
      "name": "Rock_Sandstone_Red"
    },
    {
      "x": -14,
      "y": 21,
      "z": 11,
      "name": "Rock_Sandstone_Red"
    },
    {
      "x": -14,
      "y": 22,
      "z": 11,
      "name": "Rock_Sandstone_Red"
    },
    {
      "x": -14,
      "y": 23,
      "z": 11,
      "name": "Rubble_Sandstone_Red_Medium"
    },
    {
      "x": -14,
      "y": 24,
      "z": 11,
      "name": "Rock_Sandstone_Red"
    },
    {
      "x": -14,
      "y": 25,
      "z": 11,
      "name": "Rock_Sandstone_Red"
    },
    {
      "x": -14,
      "y": 26,
      "z": 11,
      "name": "Rubble_Sandstone_Red_Medium"
    },
    {
      "x": -14,
      "y": 8,
      "z": 12,
      "name": "Rock_Sandstone_Red_Stalactite_Large",
      "filler": 31744,
      "rotation": 8
    },
    {
      "x": -14,
      "y": 9,
      "z": 12,
      "name": "Rock_Sandstone_Red_Stalactite_Large",
      "rotation": 8
    },
    {
      "x": -14,
      "y": 10,
      "z": 12,
      "name": "Rock_Sandstone_Red"
    },
    {
      "x": -14,
      "y": 11,
      "z": 12,
      "name": "Rock_Sandstone_Red"
    },
    {
      "x": -14,
      "y": 12,
      "z": 12,
      "name": "Rock_Sandstone_Red"
    },
    {
      "x": -14,
      "y": 13,
      "z": 12,
      "name": "Rock_Sandstone_Red"
    },
    {
      "x": -14,
      "y": 14,
      "z": 12,
      "name": "Rock_Sandstone_Red"
    },
    {
      "x": -14,
      "y": 15,
      "z": 12,
      "name": "Rock_Sandstone_Red"
    },
    {
      "x": -14,
      "y": 16,
      "z": 12,
      "name": "Rock_Sandstone_Red"
    },
    {
      "x": -14,
      "y": 17,
      "z": 12,
      "name": "Rock_Sandstone_Red"
    },
    {
      "x": -14,
      "y": 18,
      "z": 12,
      "name": "Rock_Sandstone_Red"
    },
    {
      "x": -14,
      "y": 19,
      "z": 12,
      "name": "Rock_Sandstone_Red"
    },
    {
      "x": -14,
      "y": 20,
      "z": 12,
      "name": "Rock_Sandstone_Red"
    },
    {
      "x": -14,
      "y": 21,
      "z": 12,
      "name": "Rock_Sandstone_Red"
    },
    {
      "x": -14,
      "y": 22,
      "z": 12,
      "name": "Soil_Sand_Red"
    },
    {
      "x": -14,
      "y": 25,
      "z": 12,
      "name": "Rock_Sandstone_Red"
    },
    {
      "x": -14,
      "y": 10,
      "z": 13,
      "name": "Rock_Sandstone_Red"
    },
    {
      "x": -14,
      "y": 11,
      "z": 13,
      "name": "Rock_Sandstone_Red"
    },
    {
      "x": -14,
      "y": 12,
      "z": 13,
      "name": "Rock_Sandstone_Red"
    },
    {
      "x": -14,
      "y": 13,
      "z": 13,
      "name": "Rock_Sandstone_Red"
    },
    {
      "x": -14,
      "y": 14,
      "z": 13,
      "name": "Rock_Sandstone_Red"
    },
    {
      "x": -14,
      "y": 15,
      "z": 13,
      "name": "Rock_Sandstone_Red"
    },
    {
      "x": -14,
      "y": 16,
      "z": 13,
      "name": "Rock_Sandstone_Red"
    },
    {
      "x": -14,
      "y": 17,
      "z": 13,
      "name": "Rock_Sandstone_Red"
    },
    {
      "x": -14,
      "y": 18,
      "z": 13,
      "name": "Rock_Sandstone_Red"
    },
    {
      "x": -14,
      "y": 19,
      "z": 13,
      "name": "Rock_Sandstone_Red"
    },
    {
      "x": -14,
      "y": 20,
      "z": 13,
      "name": "Rock_Sandstone_Red"
    },
    {
      "x": -14,
      "y": 21,
      "z": 13,
      "name": "Rock_Sandstone_Red_Cobble"
    },
    {
      "x": -14,
      "y": 10,
      "z": 14,
      "name": "Rock_Sandstone_Red"
    },
    {
      "x": -14,
      "y": 11,
      "z": 14,
      "name": "Rock_Sandstone_Red"
    },
    {
      "x": -14,
      "y": 12,
      "z": 14,
      "name": "Rock_Sandstone_Red"
    },
    {
      "x": -14,
      "y": 13,
      "z": 14,
      "name": "Rock_Sandstone_Red"
    },
    {
      "x": -14,
      "y": 14,
      "z": 14,
      "name": "Rock_Sandstone_Red"
    },
    {
      "x": -14,
      "y": 15,
      "z": 14,
      "name": "Rock_Sandstone_Red"
    },
    {
      "x": -14,
      "y": 16,
      "z": 14,
      "name": "Rock_Sandstone_Red"
    },
    {
      "x": -14,
      "y": 17,
      "z": 14,
      "name": "Rock_Sandstone_Red"
    },
    {
      "x": -14,
      "y": 18,
      "z": 14,
      "name": "Rock_Sandstone_Red"
    },
    {
      "x": -14,
      "y": 19,
      "z": 14,
      "name": "Rock_Sandstone_Red"
    },
    {
      "x": -14,
      "y": 20,
      "z": 14,
      "name": "Soil_Sand_Red"
    },
    {
      "x": -14,
      "y": 21,
      "z": 14,
      "name": "Soil_Sand_Red"
    },
    {
      "x": -14,
      "y": 9,
      "z": 15,
      "name": "Rock_Sandstone_Red"
    },
    {
      "x": -14,
      "y": 10,
      "z": 15,
      "name": "Rock_Sandstone_Red"
    },
    {
      "x": -14,
      "y": 11,
      "z": 15,
      "name": "Rock_Sandstone_Red"
    },
    {
      "x": -14,
      "y": 12,
      "z": 15,
      "name": "Rock_Sandstone_Red"
    },
    {
      "x": -14,
      "y": 13,
      "z": 15,
      "name": "Rock_Sandstone_Red"
    },
    {
      "x": -14,
      "y": 14,
      "z": 15,
      "name": "Rock_Sandstone_Red"
    },
    {
      "x": -14,
      "y": 15,
      "z": 15,
      "name": "Rock_Sandstone_Red"
    },
    {
      "x": -14,
      "y": 16,
      "z": 15,
      "name": "Rock_Sandstone_Red"
    },
    {
      "x": -14,
      "y": 17,
      "z": 15,
      "name": "Rock_Sandstone_Red"
    },
    {
      "x": -14,
      "y": 18,
      "z": 15,
      "name": "Soil_Sand_Red"
    },
    {
      "x": -14,
      "y": 19,
      "z": 15,
      "name": "Rock_Sandstone_Red_Cobble"
    },
    {
      "x": -14,
      "y": 20,
      "z": 15,
      "name": "Soil_Sand_Red"
    },
    {
      "x": -14,
      "y": 5,
      "z": 16,
      "name": "Rock_Crystal_Red_Medium",
      "rotation": 5
    },
    {
      "x": -14,
      "y": 9,
      "z": 16,
      "name": "Rock_Sandstone_Red"
    },
    {
      "x": -14,
      "y": 10,
      "z": 16,
      "name": "Rock_Sandstone_Red"
    },
    {
      "x": -14,
      "y": 11,
      "z": 16,
      "name": "Rock_Sandstone_Red"
    },
    {
      "x": -14,
      "y": 12,
      "z": 16,
      "name": "Rock_Sandstone_Red"
    },
    {
      "x": -14,
      "y": 13,
      "z": 16,
      "name": "Rock_Sandstone_Red"
    },
    {
      "x": -14,
      "y": 14,
      "z": 16,
      "name": "Rock_Sandstone_Red"
    },
    {
      "x": -14,
      "y": 15,
      "z": 16,
      "name": "Rock_Sandstone_Red"
    },
    {
      "x": -14,
      "y": 16,
      "z": 16,
      "name": "Rock_Sandstone_Red"
    },
    {
      "x": -14,
      "y": 17,
      "z": 16,
      "name": "Rock_Sandstone_Red"
    },
    {
      "x": -14,
      "y": 18,
      "z": 16,
      "name": "Rock_Sandstone_Red"
    },
    {
      "x": -14,
      "y": 19,
      "z": 16,
      "name": "Soil_Sand_Red"
    },
    {
      "x": -14,
      "y": 20,
      "z": 16,
      "name": "Rock_Sandstone_Red_Cobble"
    },
    {
      "x": -14,
      "y": 9,
      "z": 17,
      "name": "Rock_Sandstone_Red"
    },
    {
      "x": -14,
      "y": 10,
      "z": 17,
      "name": "Rock_Sandstone_Red"
    },
    {
      "x": -14,
      "y": 11,
      "z": 17,
      "name": "Rock_Sandstone_Red"
    },
    {
      "x": -14,
      "y": 12,
      "z": 17,
      "name": "Rock_Sandstone_Red"
    },
    {
      "x": -14,
      "y": 13,
      "z": 17,
      "name": "Rock_Sandstone_Red"
    },
    {
      "x": -14,
      "y": 14,
      "z": 17,
      "name": "Rock_Sandstone_Red"
    },
    {
      "x": -14,
      "y": 15,
      "z": 17,
      "name": "Rock_Sandstone_Red"
    },
    {
      "x": -14,
      "y": 16,
      "z": 17,
      "name": "Rock_Sandstone_Red"
    },
    {
      "x": -14,
      "y": 17,
      "z": 17,
      "name": "Rock_Sandstone_Red_Cobble"
    },
    {
      "x": -14,
      "y": 18,
      "z": 17,
      "name": "Soil_Gravel_Sand_Red"
    },
    {
      "x": -14,
      "y": 19,
      "z": 17,
      "name": "Soil_Sand_Red"
    },
    {
      "x": -14,
      "y": 10,
      "z": 18,
      "name": "Plant_Moss_Cave_Red"
    },
    {
      "x": -14,
      "y": 11,
      "z": 18,
      "name": "Rock_Sandstone_Red"
    },
    {
      "x": -14,
      "y": 12,
      "z": 18,
      "name": "Rock_Sandstone_Red"
    },
    {
      "x": -14,
      "y": 13,
      "z": 18,
      "name": "Rock_Sandstone_Red"
    },
    {
      "x": -14,
      "y": 14,
      "z": 18,
      "name": "Rock_Sandstone_Red"
    },
    {
      "x": -14,
      "y": 15,
      "z": 18,
      "name": "Rock_Sandstone_Red"
    },
    {
      "x": -14,
      "y": 16,
      "z": 18,
      "name": "Rock_Sandstone_Red"
    },
    {
      "x": -14,
      "y": 17,
      "z": 18,
      "name": "Rock_Sandstone_Red_Cobble"
    },
    {
      "x": -14,
      "y": 18,
      "z": 18,
      "name": "Soil_Sand_Red"
    },
    {
      "x": -14,
      "y": 14,
      "z": 19,
      "name": "Rock_Sandstone_Red"
    },
    {
      "x": -14,
      "y": 15,
      "z": 19,
      "name": "Rock_Sandstone_Red"
    },
    {
      "x": -14,
      "y": 16,
      "z": 19,
      "name": "Rock_Sandstone_Red"
    },
    {
      "x": -14,
      "y": 17,
      "z": 19,
      "name": "Rubble_Sandstone_Red_Medium"
    },
    {
      "x": -13,
      "y": 24,
      "z": 2,
      "name": "Rock_Sandstone_Red_Cobble"
    },
    {
      "x": -13,
      "y": 25,
      "z": 2,
      "name": "Soil_Sand_Red"
    },
    {
      "x": -13,
      "y": 26,
      "z": 2,
      "name": "Rock_Sandstone_Red_Cobble"
    },
    {
      "x": -13,
      "y": 17,
      "z": 3,
      "name": "Rock_Crystal_Red_Medium",
      "rotation": 7
    },
    {
      "x": -13,
      "y": 19,
      "z": 3,
      "name": "Rock_Crystal_Red_Medium",
      "rotation": 7
    },
    {
      "x": -13,
      "y": 21,
      "z": 3,
      "name": "Rock_Sandstone_Red"
    },
    {
      "x": -13,
      "y": 22,
      "z": 3,
      "name": "Rock_Sandstone_Red"
    },
    {
      "x": -13,
      "y": 23,
      "z": 3,
      "name": "Rock_Sandstone_Red"
    },
    {
      "x": -13,
      "y": 24,
      "z": 3,
      "name": "Rock_Sandstone_Red"
    },
    {
      "x": -13,
      "y": 25,
      "z": 3,
      "name": "Soil_Sand_Red"
    },
    {
      "x": -13,
      "y": 26,
      "z": 3,
      "name": "Soil_Gravel_Sand_Red"
    },
    {
      "x": -13,
      "y": 27,
      "z": 3,
      "name": "Soil_Gravel_Sand_Red"
    },
    {
      "x": -13,
      "y": 20,
      "z": 4,
      "name": "Rock_Sandstone_Red"
    },
    {
      "x": -13,
      "y": 21,
      "z": 4,
      "name": "Rock_Sandstone_Red"
    },
    {
      "x": -13,
      "y": 22,
      "z": 4,
      "name": "Rock_Sandstone_Red"
    },
    {
      "x": -13,
      "y": 23,
      "z": 4,
      "name": "Rock_Sandstone_Red"
    },
    {
      "x": -13,
      "y": 24,
      "z": 4,
      "name": "Rock_Sandstone_Red"
    },
    {
      "x": -13,
      "y": 25,
      "z": 4,
      "name": "Rock_Sandstone_Red"
    },
    {
      "x": -13,
      "y": 26,
      "z": 4,
      "name": "Soil_Gravel_Sand_Red"
    },
    {
      "x": -13,
      "y": 27,
      "z": 4,
      "name": "Soil_Sand_Red"
    },
    {
      "x": -13,
      "y": 20,
      "z": 5,
      "name": "Rock_Sandstone_Red"
    },
    {
      "x": -13,
      "y": 21,
      "z": 5,
      "name": "Rock_Sandstone_Red"
    },
    {
      "x": -13,
      "y": 22,
      "z": 5,
      "name": "Rock_Sandstone_Red"
    },
    {
      "x": -13,
      "y": 23,
      "z": 5,
      "name": "Rock_Sandstone_Red"
    },
    {
      "x": -13,
      "y": 24,
      "z": 5,
      "name": "Soil_Gravel_Sand_Red"
    },
    {
      "x": -13,
      "y": 25,
      "z": 5,
      "name": "Rock_Sandstone_Red_Cobble"
    },
    {
      "x": -13,
      "y": 26,
      "z": 5,
      "name": "Soil_Sand_Red"
    },
    {
      "x": -13,
      "y": 27,
      "z": 5,
      "name": "Plant_Bush_Arid_Red"
    },
    {
      "x": -13,
      "y": 20,
      "z": 6,
      "name": "Rock_Sandstone_Red"
    },
    {
      "x": -13,
      "y": 21,
      "z": 6,
      "name": "Rock_Sandstone_Red"
    },
    {
      "x": -13,
      "y": 22,
      "z": 6,
      "name": "Rock_Sandstone_Red"
    },
    {
      "x": -13,
      "y": 23,
      "z": 6,
      "name": "Rock_Sandstone_Red"
    },
    {
      "x": -13,
      "y": 24,
      "z": 6,
      "name": "Rock_Sandstone_Red"
    },
    {
      "x": -13,
      "y": 25,
      "z": 6,
      "name": "Soil_Sand_Red"
    },
    {
      "x": -13,
      "y": 26,
      "z": 6,
      "name": "Rock_Sandstone_Red_Cobble"
    },
    {
      "x": -13,
      "y": 21,
      "z": 7,
      "name": "Rock_Sandstone_Red"
    },
    {
      "x": -13,
      "y": 22,
      "z": 7,
      "name": "Rock_Sandstone_Red"
    },
    {
      "x": -13,
      "y": 23,
      "z": 7,
      "name": "Rock_Sandstone_Red"
    },
    {
      "x": -13,
      "y": 24,
      "z": 7,
      "name": "Rock_Sandstone_Red"
    },
    {
      "x": -13,
      "y": 25,
      "z": 7,
      "name": "Rock_Sandstone_Red"
    },
    {
      "x": -13,
      "y": 26,
      "z": 7,
      "name": "Soil_Sand_Red"
    },
    {
      "x": -13,
      "y": 17,
      "z": 8,
      "name": "Rock_Sandstone_Red"
    },
    {
      "x": -13,
      "y": 18,
      "z": 8,
      "name": "Rock_Sandstone_Red"
    },
    {
      "x": -13,
      "y": 19,
      "z": 8,
      "name": "Rock_Sandstone_Red"
    },
    {
      "x": -13,
      "y": 20,
      "z": 8,
      "name": "Rock_Sandstone_Red"
    },
    {
      "x": -13,
      "y": 21,
      "z": 8,
      "name": "Rock_Sandstone_Red"
    },
    {
      "x": -13,
      "y": 22,
      "z": 8,
      "name": "Rock_Sandstone_Red"
    },
    {
      "x": -13,
      "y": 23,
      "z": 8,
      "name": "Rock_Sandstone_Red"
    },
    {
      "x": -13,
      "y": 24,
      "z": 8,
      "name": "Rock_Sandstone_Red"
    },
    {
      "x": -13,
      "y": 25,
      "z": 8,
      "name": "Rock_Sandstone_Red"
    },
    {
      "x": -13,
      "y": 26,
      "z": 8,
      "name": "Rock_Sandstone_Red"
    },
    {
      "x": -13,
      "y": 27,
      "z": 8,
      "name": "Rubble_Sandstone_Red"
    },
    {
      "x": -13,
      "y": 13,
      "z": 9,
      "name": "Rock_Sandstone_Red"
    },
    {
      "x": -13,
      "y": 14,
      "z": 9,
      "name": "Rock_Sandstone_Red"
    },
    {
      "x": -13,
      "y": 15,
      "z": 9,
      "name": "Rock_Sandstone_Red"
    },
    {
      "x": -13,
      "y": 16,
      "z": 9,
      "name": "Rock_Sandstone_Red"
    },
    {
      "x": -13,
      "y": 17,
      "z": 9,
      "name": "Rock_Sandstone_Red"
    },
    {
      "x": -13,
      "y": 18,
      "z": 9,
      "name": "Rock_Sandstone_Red"
    },
    {
      "x": -13,
      "y": 19,
      "z": 9,
      "name": "Rock_Sandstone_Red"
    },
    {
      "x": -13,
      "y": 20,
      "z": 9,
      "name": "Rock_Sandstone_Red"
    },
    {
      "x": -13,
      "y": 21,
      "z": 9,
      "name": "Rock_Sandstone_Red"
    },
    {
      "x": -13,
      "y": 22,
      "z": 9,
      "name": "Rock_Sandstone_Red"
    },
    {
      "x": -13,
      "y": 23,
      "z": 9,
      "name": "Rock_Sandstone_Red"
    },
    {
      "x": -13,
      "y": 24,
      "z": 9,
      "name": "Rock_Sandstone_Red"
    },
    {
      "x": -13,
      "y": 25,
      "z": 9,
      "name": "Rock_Sandstone_Red"
    },
    {
      "x": -13,
      "y": 26,
      "z": 9,
      "name": "Rock_Sandstone_Red"
    },
    {
      "x": -13,
      "y": 12,
      "z": 10,
      "name": "Rock_Sandstone_Red"
    },
    {
      "x": -13,
      "y": 13,
      "z": 10,
      "name": "Rock_Sandstone_Red"
    },
    {
      "x": -13,
      "y": 14,
      "z": 10,
      "name": "Rock_Sandstone_Red"
    },
    {
      "x": -13,
      "y": 15,
      "z": 10,
      "name": "Rock_Sandstone_Red"
    },
    {
      "x": -13,
      "y": 16,
      "z": 10,
      "name": "Rock_Sandstone_Red"
    },
    {
      "x": -13,
      "y": 17,
      "z": 10,
      "name": "Rock_Sandstone_Red"
    },
    {
      "x": -13,
      "y": 18,
      "z": 10,
      "name": "Rock_Sandstone_Red"
    },
    {
      "x": -13,
      "y": 19,
      "z": 10,
      "name": "Rock_Sandstone_Red"
    },
    {
      "x": -13,
      "y": 20,
      "z": 10,
      "name": "Rock_Sandstone_Red"
    },
    {
      "x": -13,
      "y": 21,
      "z": 10,
      "name": "Rock_Sandstone_Red"
    },
    {
      "x": -13,
      "y": 22,
      "z": 10,
      "name": "Rock_Sandstone_Red"
    },
    {
      "x": -13,
      "y": 23,
      "z": 10,
      "name": "Rock_Sandstone_Red"
    },
    {
      "x": -13,
      "y": 24,
      "z": 10,
      "name": "Rock_Sandstone_Red"
    },
    {
      "x": -13,
      "y": 25,
      "z": 10,
      "name": "Rock_Sandstone_Red"
    },
    {
      "x": -13,
      "y": 26,
      "z": 10,
      "name": "Rock_Sandstone_Red"
    },
    {
      "x": -13,
      "y": 27,
      "z": 10,
      "name": "Rubble_Sandstone_Red_Medium"
    },
    {
      "x": -13,
      "y": 11,
      "z": 11,
      "name": "Rock_Sandstone_Red"
    },
    {
      "x": -13,
      "y": 12,
      "z": 11,
      "name": "Rock_Sandstone_Red"
    },
    {
      "x": -13,
      "y": 13,
      "z": 11,
      "name": "Rock_Sandstone_Red"
    },
    {
      "x": -13,
      "y": 14,
      "z": 11,
      "name": "Rock_Sandstone_Red"
    },
    {
      "x": -13,
      "y": 15,
      "z": 11,
      "name": "Rock_Sandstone_Red"
    },
    {
      "x": -13,
      "y": 16,
      "z": 11,
      "name": "Rock_Sandstone_Red"
    },
    {
      "x": -13,
      "y": 17,
      "z": 11,
      "name": "Rock_Sandstone_Red"
    },
    {
      "x": -13,
      "y": 18,
      "z": 11,
      "name": "Rock_Sandstone_Red"
    },
    {
      "x": -13,
      "y": 19,
      "z": 11,
      "name": "Rock_Sandstone_Red"
    },
    {
      "x": -13,
      "y": 20,
      "z": 11,
      "name": "Rock_Sandstone_Red"
    },
    {
      "x": -13,
      "y": 21,
      "z": 11,
      "name": "Rock_Sandstone_Red"
    },
    {
      "x": -13,
      "y": 22,
      "z": 11,
      "name": "Rock_Sandstone_Red"
    },
    {
      "x": -13,
      "y": 23,
      "z": 11,
      "name": "Rock_Sandstone_Red"
    },
    {
      "x": -13,
      "y": 24,
      "z": 11,
      "name": "Soil_Gravel_Sand_Red"
    },
    {
      "x": -13,
      "y": 25,
      "z": 11,
      "name": "Soil_Sand_Red"
    },
    {
      "x": -13,
      "y": 10,
      "z": 12,
      "name": "Rock_Sandstone_Red"
    },
    {
      "x": -13,
      "y": 11,
      "z": 12,
      "name": "Rock_Sandstone_Red"
    },
    {
      "x": -13,
      "y": 12,
      "z": 12,
      "name": "Rock_Sandstone_Red"
    },
    {
      "x": -13,
      "y": 13,
      "z": 12,
      "name": "Rock_Sandstone_Red"
    },
    {
      "x": -13,
      "y": 14,
      "z": 12,
      "name": "Rock_Sandstone_Red"
    },
    {
      "x": -13,
      "y": 15,
      "z": 12,
      "name": "Rock_Sandstone_Red"
    },
    {
      "x": -13,
      "y": 16,
      "z": 12,
      "name": "Rock_Sandstone_Red"
    },
    {
      "x": -13,
      "y": 17,
      "z": 12,
      "name": "Rock_Sandstone_Red"
    },
    {
      "x": -13,
      "y": 18,
      "z": 12,
      "name": "Rock_Sandstone_Red"
    },
    {
      "x": -13,
      "y": 19,
      "z": 12,
      "name": "Rock_Sandstone_Red"
    },
    {
      "x": -13,
      "y": 20,
      "z": 12,
      "name": "Rock_Sandstone_Red"
    },
    {
      "x": -13,
      "y": 21,
      "z": 12,
      "name": "Rock_Sandstone_Red"
    },
    {
      "x": -13,
      "y": 22,
      "z": 12,
      "name": "Rock_Sandstone_Red"
    },
    {
      "x": -13,
      "y": 23,
      "z": 12,
      "name": "Rock_Sandstone_Red"
    },
    {
      "x": -13,
      "y": 24,
      "z": 12,
      "name": "Soil_Sand_Red"
    },
    {
      "x": -13,
      "y": 10,
      "z": 13,
      "name": "Rock_Sandstone_Red"
    },
    {
      "x": -13,
      "y": 11,
      "z": 13,
      "name": "Rock_Sandstone_Red"
    },
    {
      "x": -13,
      "y": 12,
      "z": 13,
      "name": "Rock_Sandstone_Red"
    },
    {
      "x": -13,
      "y": 13,
      "z": 13,
      "name": "Rock_Sandstone_Red"
    },
    {
      "x": -13,
      "y": 14,
      "z": 13,
      "name": "Rock_Sandstone_Red"
    },
    {
      "x": -13,
      "y": 15,
      "z": 13,
      "name": "Rock_Sandstone_Red"
    },
    {
      "x": -13,
      "y": 16,
      "z": 13,
      "name": "Rock_Sandstone_Red"
    },
    {
      "x": -13,
      "y": 17,
      "z": 13,
      "name": "Rock_Sandstone_Red"
    },
    {
      "x": -13,
      "y": 18,
      "z": 13,
      "name": "Rock_Sandstone_Red"
    },
    {
      "x": -13,
      "y": 19,
      "z": 13,
      "name": "Rock_Sandstone_Red"
    },
    {
      "x": -13,
      "y": 20,
      "z": 13,
      "name": "Rock_Sandstone_Red"
    },
    {
      "x": -13,
      "y": 21,
      "z": 13,
      "name": "Soil_Sand_Red"
    },
    {
      "x": -13,
      "y": 22,
      "z": 13,
      "name": "Soil_Sand_Red"
    },
    {
      "x": -13,
      "y": 8,
      "z": 14,
      "name": "Rock_Sandstone_Red_Stalactite_Large",
      "filler": 31744,
      "rotation": 8
    },
    {
      "x": -13,
      "y": 9,
      "z": 14,
      "name": "Rock_Sandstone_Red_Stalactite_Large",
      "rotation": 8
    },
    {
      "x": -13,
      "y": 10,
      "z": 14,
      "name": "Rock_Sandstone_Red"
    },
    {
      "x": -13,
      "y": 11,
      "z": 14,
      "name": "Rock_Sandstone_Red"
    },
    {
      "x": -13,
      "y": 12,
      "z": 14,
      "name": "Rock_Sandstone_Red"
    },
    {
      "x": -13,
      "y": 13,
      "z": 14,
      "name": "Rock_Sandstone_Red"
    },
    {
      "x": -13,
      "y": 14,
      "z": 14,
      "name": "Rock_Sandstone_Red"
    },
    {
      "x": -13,
      "y": 15,
      "z": 14,
      "name": "Rock_Sandstone_Red"
    },
    {
      "x": -13,
      "y": 16,
      "z": 14,
      "name": "Rock_Sandstone_Red"
    },
    {
      "x": -13,
      "y": 17,
      "z": 14,
      "name": "Rock_Sandstone_Red"
    },
    {
      "x": -13,
      "y": 18,
      "z": 14,
      "name": "Rock_Sandstone_Red"
    },
    {
      "x": -13,
      "y": 19,
      "z": 14,
      "name": "Rock_Sandstone_Red"
    },
    {
      "x": -13,
      "y": 20,
      "z": 14,
      "name": "Rock_Sandstone_Red"
    },
    {
      "x": -13,
      "y": 21,
      "z": 14,
      "name": "Rock_Sandstone_Red"
    },
    {
      "x": -13,
      "y": 22,
      "z": 14,
      "name": "Rock_Sandstone_Red"
    },
    {
      "x": -13,
      "y": 11,
      "z": 15,
      "name": "Rock_Sandstone_Red"
    },
    {
      "x": -13,
      "y": 12,
      "z": 15,
      "name": "Rock_Sandstone_Red"
    },
    {
      "x": -13,
      "y": 13,
      "z": 15,
      "name": "Rock_Sandstone_Red"
    },
    {
      "x": -13,
      "y": 14,
      "z": 15,
      "name": "Rock_Sandstone_Red"
    },
    {
      "x": -13,
      "y": 15,
      "z": 15,
      "name": "Rock_Sandstone_Red"
    },
    {
      "x": -13,
      "y": 16,
      "z": 15,
      "name": "Rock_Sandstone_Red"
    },
    {
      "x": -13,
      "y": 17,
      "z": 15,
      "name": "Rock_Sandstone_Red"
    },
    {
      "x": -13,
      "y": 18,
      "z": 15,
      "name": "Rock_Sandstone_Red"
    },
    {
      "x": -13,
      "y": 19,
      "z": 15,
      "name": "Rock_Sandstone_Red"
    },
    {
      "x": -13,
      "y": 20,
      "z": 15,
      "name": "Rock_Sandstone_Red"
    },
    {
      "x": -13,
      "y": 21,
      "z": 15,
      "name": "Rock_Sandstone_Red"
    },
    {
      "x": -13,
      "y": 22,
      "z": 15,
      "name": "Rubble_Sandstone_Red"
    },
    {
      "x": -13,
      "y": 10,
      "z": 16,
      "name": "Rock_Sandstone_Red"
    },
    {
      "x": -13,
      "y": 11,
      "z": 16,
      "name": "Rock_Sandstone_Red"
    },
    {
      "x": -13,
      "y": 12,
      "z": 16,
      "name": "Rock_Sandstone_Red"
    },
    {
      "x": -13,
      "y": 13,
      "z": 16,
      "name": "Rock_Sandstone_Red"
    },
    {
      "x": -13,
      "y": 14,
      "z": 16,
      "name": "Rock_Sandstone_Red"
    },
    {
      "x": -13,
      "y": 15,
      "z": 16,
      "name": "Rock_Sandstone_Red"
    },
    {
      "x": -13,
      "y": 16,
      "z": 16,
      "name": "Rock_Sandstone_Red"
    },
    {
      "x": -13,
      "y": 17,
      "z": 16,
      "name": "Rock_Sandstone_Red"
    },
    {
      "x": -13,
      "y": 18,
      "z": 16,
      "name": "Rock_Sandstone_Red_Cobble"
    },
    {
      "x": -13,
      "y": 19,
      "z": 16,
      "name": "Rock_Sandstone_Red_Cobble"
    },
    {
      "x": -13,
      "y": 20,
      "z": 16,
      "name": "Soil_Sand_Red"
    },
    {
      "x": -13,
      "y": 10,
      "z": 17,
      "name": "Plant_Moss_Cave_Red"
    },
    {
      "x": -13,
      "y": 11,
      "z": 17,
      "name": "Rock_Sandstone_Red"
    },
    {
      "x": -13,
      "y": 12,
      "z": 17,
      "name": "Rock_Sandstone_Red"
    },
    {
      "x": -13,
      "y": 13,
      "z": 17,
      "name": "Rock_Sandstone_Red"
    },
    {
      "x": -13,
      "y": 14,
      "z": 17,
      "name": "Rock_Sandstone_Red"
    },
    {
      "x": -13,
      "y": 15,
      "z": 17,
      "name": "Rock_Sandstone_Red"
    },
    {
      "x": -13,
      "y": 16,
      "z": 17,
      "name": "Rock_Sandstone_Red"
    },
    {
      "x": -13,
      "y": 17,
      "z": 17,
      "name": "Soil_Sand_Red"
    },
    {
      "x": -13,
      "y": 18,
      "z": 17,
      "name": "Soil_Sand_Red"
    },
    {
      "x": -13,
      "y": 19,
      "z": 17,
      "name": "Rock_Sandstone_Red_Cobble"
    },
    {
      "x": -13,
      "y": 13,
      "z": 18,
      "name": "Rock_Sandstone_Red"
    },
    {
      "x": -13,
      "y": 14,
      "z": 18,
      "name": "Rock_Sandstone_Red"
    },
    {
      "x": -13,
      "y": 15,
      "z": 18,
      "name": "Rock_Sandstone_Red"
    },
    {
      "x": -13,
      "y": 16,
      "z": 18,
      "name": "Rock_Sandstone_Red"
    },
    {
      "x": -13,
      "y": 17,
      "z": 18,
      "name": "Rock_Sandstone_Red"
    },
    {
      "x": -13,
      "y": 18,
      "z": 18,
      "name": "Soil_Sand_Red"
    },
    {
      "x": -13,
      "y": 15,
      "z": 19,
      "name": "Plant_Crop_Mushroom_Shelve_Yellow"
    },
    {
      "x": -12,
      "y": 25,
      "z": 0,
      "name": "Plant_Crop_Mushroom_Shelve_Yellow"
    },
    {
      "x": -12,
      "y": 24,
      "z": 1,
      "name": "Rock_Sandstone_Red"
    },
    {
      "x": -12,
      "y": 25,
      "z": 1,
      "name": "Soil_Sand_Red"
    },
    {
      "x": -12,
      "y": 26,
      "z": 1,
      "name": "Soil_Sand_Red"
    },
    {
      "x": -12,
      "y": 17,
      "z": 2,
      "name": "Rock_Crystal_Red_Medium",
      "rotation": 6
    },
    {
      "x": -12,
      "y": 18,
      "z": 2,
      "name": "Rock_Crystal_Red_Medium",
      "rotation": 6
    },
    {
      "x": -12,
      "y": 20,
      "z": 2,
      "name": "Rock_Crystal_Red_Medium",
      "rotation": 7
    },
    {
      "x": -12,
      "y": 21,
      "z": 2,
      "name": "Rock_Sandstone_Red"
    },
    {
      "x": -12,
      "y": 22,
      "z": 2,
      "name": "Rock_Sandstone_Red"
    },
    {
      "x": -12,
      "y": 23,
      "z": 2,
      "name": "Rock_Sandstone_Red"
    },
    {
      "x": -12,
      "y": 24,
      "z": 2,
      "name": "Soil_Sand_Red"
    },
    {
      "x": -12,
      "y": 25,
      "z": 2,
      "name": "Soil_Sand_Red"
    },
    {
      "x": -12,
      "y": 26,
      "z": 2,
      "name": "Soil_Gravel_Sand_Red"
    },
    {
      "x": -12,
      "y": 27,
      "z": 2,
      "name": "Soil_Gravel_Sand_Red"
    },
    {
      "x": -12,
      "y": 15,
      "z": 3,
      "name": "Rock_Crystal_Red_Medium",
      "rotation": 7
    },
    {
      "x": -12,
      "y": 16,
      "z": 3,
      "name": "Rock_Crystal_Red_Medium",
      "rotation": 7
    },
    {
      "x": -12,
      "y": 17,
      "z": 3,
      "name": "Rock_Crystal_Red_Block"
    },
    {
      "x": -12,
      "y": 18,
      "z": 3,
      "name": "Rock_Crystal_Red_Block"
    },
    {
      "x": -12,
      "y": 19,
      "z": 3,
      "name": "Rock_Crystal_Red_Block"
    },
    {
      "x": -12,
      "y": 20,
      "z": 3,
      "name": "Rock_Crystal_Red_Block"
    },
    {
      "x": -12,
      "y": 21,
      "z": 3,
      "name": "Rock_Crystal_Red_Block"
    },
    {
      "x": -12,
      "y": 22,
      "z": 3,
      "name": "Rock_Crystal_Red_Block"
    },
    {
      "x": -12,
      "y": 23,
      "z": 3,
      "name": "Rock_Sandstone_Red"
    },
    {
      "x": -12,
      "y": 24,
      "z": 3,
      "name": "Rock_Sandstone_Red"
    },
    {
      "x": -12,
      "y": 25,
      "z": 3,
      "name": "Rock_Sandstone_Red"
    },
    {
      "x": -12,
      "y": 26,
      "z": 3,
      "name": "Soil_Sand_Red"
    },
    {
      "x": -12,
      "y": 27,
      "z": 3,
      "name": "Soil_Sand_Red"
    },
    {
      "x": -12,
      "y": 17,
      "z": 4,
      "name": "Rock_Crystal_Red_Medium",
      "rotation": 4
    },
    {
      "x": -12,
      "y": 18,
      "z": 4,
      "name": "Rock_Crystal_Red_Medium",
      "rotation": 8
    },
    {
      "x": -12,
      "y": 19,
      "z": 4,
      "name": "Rock_Sandstone_Red"
    },
    {
      "x": -12,
      "y": 20,
      "z": 4,
      "name": "Rock_Sandstone_Red"
    },
    {
      "x": -12,
      "y": 21,
      "z": 4,
      "name": "Rock_Sandstone_Red"
    },
    {
      "x": -12,
      "y": 22,
      "z": 4,
      "name": "Rock_Sandstone_Red"
    },
    {
      "x": -12,
      "y": 23,
      "z": 4,
      "name": "Rock_Sandstone_Red"
    },
    {
      "x": -12,
      "y": 24,
      "z": 4,
      "name": "Rock_Sandstone_Red"
    },
    {
      "x": -12,
      "y": 25,
      "z": 4,
      "name": "Soil_Sand_Red"
    },
    {
      "x": -12,
      "y": 26,
      "z": 4,
      "name": "Soil_Sand_Red"
    },
    {
      "x": -12,
      "y": 27,
      "z": 4,
      "name": "Rock_Sandstone_Red_Cobble"
    },
    {
      "x": -12,
      "y": 19,
      "z": 5,
      "name": "Rock_Sandstone_Red"
    },
    {
      "x": -12,
      "y": 20,
      "z": 5,
      "name": "Rock_Sandstone_Red"
    },
    {
      "x": -12,
      "y": 21,
      "z": 5,
      "name": "Rock_Sandstone_Red"
    },
    {
      "x": -12,
      "y": 22,
      "z": 5,
      "name": "Rock_Sandstone_Red"
    },
    {
      "x": -12,
      "y": 23,
      "z": 5,
      "name": "Rock_Sandstone_Red"
    },
    {
      "x": -12,
      "y": 24,
      "z": 5,
      "name": "Rock_Sandstone_Red"
    },
    {
      "x": -12,
      "y": 25,
      "z": 5,
      "name": "Rock_Sandstone_Red"
    },
    {
      "x": -12,
      "y": 26,
      "z": 5,
      "name": "Rock_Sandstone_Red"
    },
    {
      "x": -12,
      "y": 27,
      "z": 5,
      "name": "Rock_Sandstone_Red"
    },
    {
      "x": -12,
      "y": 19,
      "z": 6,
      "name": "Rock_Sandstone_Red"
    },
    {
      "x": -12,
      "y": 20,
      "z": 6,
      "name": "Rock_Sandstone_Red"
    },
    {
      "x": -12,
      "y": 21,
      "z": 6,
      "name": "Rock_Sandstone_Red"
    },
    {
      "x": -12,
      "y": 22,
      "z": 6,
      "name": "Rock_Sandstone_Red"
    },
    {
      "x": -12,
      "y": 23,
      "z": 6,
      "name": "Rock_Sandstone_Red"
    },
    {
      "x": -12,
      "y": 24,
      "z": 6,
      "name": "Rock_Sandstone_Red"
    },
    {
      "x": -12,
      "y": 25,
      "z": 6,
      "name": "Soil_Sand_Red"
    },
    {
      "x": -12,
      "y": 26,
      "z": 6,
      "name": "Soil_Sand_Red"
    },
    {
      "x": -12,
      "y": 27,
      "z": 6,
      "name": "Soil_Sand_Red"
    },
    {
      "x": -12,
      "y": 19,
      "z": 7,
      "name": "Rock_Sandstone_Red"
    },
    {
      "x": -12,
      "y": 20,
      "z": 7,
      "name": "Rock_Sandstone_Red"
    },
    {
      "x": -12,
      "y": 21,
      "z": 7,
      "name": "Rock_Sandstone_Red"
    },
    {
      "x": -12,
      "y": 22,
      "z": 7,
      "name": "Rock_Sandstone_Red"
    },
    {
      "x": -12,
      "y": 23,
      "z": 7,
      "name": "Rock_Sandstone_Red"
    },
    {
      "x": -12,
      "y": 24,
      "z": 7,
      "name": "Rock_Sandstone_Red"
    },
    {
      "x": -12,
      "y": 25,
      "z": 7,
      "name": "Rock_Sandstone_Red"
    },
    {
      "x": -12,
      "y": 26,
      "z": 7,
      "name": "Rock_Sandstone_Red"
    },
    {
      "x": -12,
      "y": 27,
      "z": 7,
      "name": "Soil_Sand_Red"
    },
    {
      "x": -12,
      "y": 17,
      "z": 8,
      "name": "Rock_Sandstone_Red"
    },
    {
      "x": -12,
      "y": 18,
      "z": 8,
      "name": "Rock_Sandstone_Red"
    },
    {
      "x": -12,
      "y": 19,
      "z": 8,
      "name": "Rock_Sandstone_Red"
    },
    {
      "x": -12,
      "y": 20,
      "z": 8,
      "name": "Rock_Sandstone_Red"
    },
    {
      "x": -12,
      "y": 21,
      "z": 8,
      "name": "Rock_Sandstone_Red"
    },
    {
      "x": -12,
      "y": 22,
      "z": 8,
      "name": "Rock_Sandstone_Red"
    },
    {
      "x": -12,
      "y": 23,
      "z": 8,
      "name": "Rock_Sandstone_Red"
    },
    {
      "x": -12,
      "y": 24,
      "z": 8,
      "name": "Rock_Sandstone_Red"
    },
    {
      "x": -12,
      "y": 25,
      "z": 8,
      "name": "Rock_Sandstone_Red"
    },
    {
      "x": -12,
      "y": 26,
      "z": 8,
      "name": "Rock_Sandstone_Red"
    },
    {
      "x": -12,
      "y": 27,
      "z": 8,
      "name": "Soil_Sand_Red"
    },
    {
      "x": -12,
      "y": 14,
      "z": 9,
      "name": "Rock_Sandstone_Red"
    },
    {
      "x": -12,
      "y": 15,
      "z": 9,
      "name": "Rock_Sandstone_Red"
    },
    {
      "x": -12,
      "y": 16,
      "z": 9,
      "name": "Rock_Sandstone_Red"
    },
    {
      "x": -12,
      "y": 17,
      "z": 9,
      "name": "Rock_Sandstone_Red"
    },
    {
      "x": -12,
      "y": 18,
      "z": 9,
      "name": "Rock_Sandstone_Red"
    },
    {
      "x": -12,
      "y": 19,
      "z": 9,
      "name": "Rock_Sandstone_Red"
    },
    {
      "x": -12,
      "y": 20,
      "z": 9,
      "name": "Rock_Sandstone_Red"
    },
    {
      "x": -12,
      "y": 21,
      "z": 9,
      "name": "Rock_Sandstone_Red"
    },
    {
      "x": -12,
      "y": 22,
      "z": 9,
      "name": "Rock_Sandstone_Red"
    },
    {
      "x": -12,
      "y": 23,
      "z": 9,
      "name": "Rock_Sandstone_Red"
    },
    {
      "x": -12,
      "y": 24,
      "z": 9,
      "name": "Rock_Sandstone_Red"
    },
    {
      "x": -12,
      "y": 25,
      "z": 9,
      "name": "Rock_Sandstone_Red"
    },
    {
      "x": -12,
      "y": 26,
      "z": 9,
      "name": "Rock_Sandstone_Red"
    },
    {
      "x": -12,
      "y": 27,
      "z": 9,
      "name": "Rock_Sandstone_Red"
    },
    {
      "x": -12,
      "y": 28,
