{
  "version": 8,
  "blockIdVersion": 11,
  "anchorX": 0,
  "anchorY": 0,
  "anchorZ": 0,
  "blocks": [
    {
      "x": -19,
      "y": 33,
      "z": 10,
      "name": "Rock_Volcanic_Cracked_Lava"
    },
    {
      "x": -19,
      "y": 34,
      "z": 11,
      "name": "Rock_Volcanic"
    },
    {
      "x": -19,
      "y": 35,
      "z": 11,
      "name": "Soil_Volcanic_Gravel"
    },
    {
      "x": -19,
      "y": 36,
      "z": 11,
      "name": "Soil_Volcanic_Gravel"
    },
    {
      "x": -18,
      "y": 18,
      "z": -17,
      "name": "Rock_Volcanic_Cracked_Lava"
    },
    {
      "x": -18,
      "y": 15,
      "z": -16,
      "name": "Rock_Volcanic_Cracked_Lava"
    },
    {
      "x": -18,
      "y": 16,
      "z": -16,
      "name": "Soil_Volcanic_Gravel"
    },
    {
      "x": -18,
      "y": 17,
      "z": -16,
      "name": "Rock_Volcanic"
    },
    {
      "x": -18,
      "y": 18,
      "z": -16,
      "name": "Rock_Volcanic_Cracked_Lava"
    },
    {
      "x": -18,
      "y": 19,
      "z": -16,
      "name": "Rock_Volcanic"
    },
    {
      "x": -18,
      "y": 20,
      "z": -16,
      "name": "Rock_Volcanic"
    },
    {
      "x": -18,
      "y": 21,
      "z": -16,
      "name": "Rock_Volcanic"
    },
    {
      "x": -18,
      "y": 14,
      "z": -15,
      "name": "Rock_Volcanic"
    },
    {
      "x": -18,
      "y": 15,
      "z": -15,
      "name": "Rock_Volcanic"
    },
    {
      "x": -18,
      "y": 16,
      "z": -15,
      "name": "Rock_Volcanic"
    },
    {
      "x": -18,
      "y": 17,
      "z": -15,
      "name": "Rock_Volcanic"
    },
    {
      "x": -18,
      "y": 18,
      "z": -15,
      "name": "Rock_Volcanic"
    },
    {
      "x": -18,
      "y": 19,
      "z": -15,
      "name": "Rock_Volcanic"
    },
    {
      "x": -18,
      "y": 20,
      "z": -15,
      "name": "Rock_Volcanic"
    },
    {
      "x": -18,
      "y": 21,
      "z": -15,
      "name": "Rock_Volcanic"
    },
    {
      "x": -18,
      "y": 15,
      "z": -14,
      "name": "Rock_Volcanic"
    },
    {
      "x": -18,
      "y": 16,
      "z": -14,
      "name": "Rock_Volcanic"
    },
    {
      "x": -18,
      "y": 17,
      "z": -14,
      "name": "Rock_Volcanic"
    },
    {
      "x": -18,
      "y": 18,
      "z": -14,
      "name": "Rock_Volcanic"
    },
    {
      "x": -18,
      "y": 19,
      "z": -14,
      "name": "Rock_Volcanic"
    },
    {
      "x": -18,
      "y": 20,
      "z": -14,
      "name": "Rock_Volcanic"
    },
    {
      "x": -18,
      "y": 21,
      "z": -14,
      "name": "Rock_Volcanic"
    },
    {
      "x": -18,
      "y": 22,
      "z": -14,
      "name": "Soil_Volcanic_Gravel"
    },
    {
      "x": -18,
      "y": 13,
      "z": -13,
      "name": "Rock_Volcanic_Stalactite_Small",
      "rotation": 8
    },
    {
      "x": -18,
      "y": 14,
      "z": -13,
      "name": "Rock_Volcanic"
    },
    {
      "x": -18,
      "y": 15,
      "z": -13,
      "name": "Rock_Volcanic"
    },
    {
      "x": -18,
      "y": 16,
      "z": -13,
      "name": "Rock_Volcanic_Cracked_Lava"
    },
    {
      "x": -18,
      "y": 17,
      "z": -13,
      "name": "Rock_Volcanic_Cracked_Lava"
    },
    {
      "x": -18,
      "y": 18,
      "z": -13,
      "name": "Rock_Volcanic"
    },
    {
      "x": -18,
      "y": 19,
      "z": -13,
      "name": "Rock_Volcanic"
    },
    {
      "x": -18,
      "y": 20,
      "z": -13,
      "name": "Rock_Volcanic"
    },
    {
      "x": -18,
      "y": 21,
      "z": -13,
      "name": "Soil_Volcanic_Gravel"
    },
    {
      "x": -18,
      "y": 14,
      "z": -12,
      "name": "Rock_Volcanic_Stalactite_Small",
      "rotation": 8
    },
    {
      "x": -18,
      "y": 15,
      "z": -12,
      "name": "Rock_Volcanic_Cracked_Lava"
    },
    {
      "x": -18,
      "y": 16,
      "z": -12,
      "name": "Rock_Volcanic_Cracked_Lava"
    },
    {
      "x": -18,
      "y": 17,
      "z": -12,
      "name": "Rock_Volcanic_Cracked_Lava"
    },
    {
      "x": -18,
      "y": 18,
      "z": -12,
      "name": "Rock_Volcanic"
    },
    {
      "x": -18,
      "y": 19,
      "z": -12,
      "name": "Rock_Volcanic"
    },
    {
      "x": -18,
      "y": 20,
      "z": -12,
      "name": "Rock_Volcanic"
    },
    {
      "x": -18,
      "y": 18,
      "z": -11,
      "name": "Rock_Volcanic_Cracked_Lava"
    },
    {
      "x": -18,
      "y": 19,
      "z": -11,
      "name": "Rock_Volcanic"
    },
    {
      "x": -18,
      "y": 30,
      "z": 8,
      "name": "Rock_Volcanic"
    },
    {
      "x": -18,
      "y": 31,
      "z": 8,
      "name": "Rock_Volcanic"
    },
    {
      "x": -18,
      "y": 32,
      "z": 8,
      "name": "Rock_Volcanic_Cracked_Lava"
    },
    {
      "x": -18,
      "y": 33,
      "z": 8,
      "name": "Rock_Volcanic"
    },
    {
      "x": -18,
      "y": 34,
      "z": 8,
      "name": "Soil_Volcanic_Gravel"
    },
    {
      "x": -18,
      "y": 29,
      "z": 9,
      "name": "Rock_Volcanic_Cracked_Lava"
    },
    {
      "x": -18,
      "y": 30,
      "z": 9,
      "name": "Rock_Volcanic"
    },
    {
      "x": -18,
      "y": 31,
      "z": 9,
      "name": "Rock_Volcanic"
    },
    {
      "x": -18,
      "y": 32,
      "z": 9,
      "name": "Rock_Volcanic"
    },
    {
      "x": -18,
      "y": 33,
      "z": 9,
      "name": "Rock_Volcanic"
    },
    {
      "x": -18,
      "y": 34,
      "z": 9,
      "name": "Soil_Volcanic_Gravel"
    },
    {
      "x": -18,
      "y": 35,
      "z": 9,
      "name": "Soil_Volcanic_Gravel"
    },
    {
      "x": -18,
      "y": 36,
      "z": 9,
      "name": "Soil_Volcanic_Gravel"
    },
    {
      "x": -18,
      "y": 29,
      "z": 10,
      "name": "Rock_Volcanic"
    },
    {
      "x": -18,
      "y": 30,
      "z": 10,
      "name": "Rock_Volcanic"
    },
    {
      "x": -18,
      "y": 31,
      "z": 10,
      "name": "Rock_Volcanic"
    },
    {
      "x": -18,
      "y": 32,
      "z": 10,
      "name": "Rock_Volcanic"
    },
    {
      "x": -18,
      "y": 33,
      "z": 10,
      "name": "Rock_Volcanic"
    },
    {
      "x": -18,
      "y": 34,
      "z": 10,
      "name": "Soil_Volcanic_Gravel"
    },
    {
      "x": -18,
      "y": 35,
      "z": 10,
      "name": "Soil_Volcanic_Gravel"
    },
    {
      "x": -18,
      "y": 36,
      "z": 10,
      "name": "Rock_Volcanic"
    },
    {
      "x": -18,
      "y": 29,
      "z": 11,
      "name": "Rock_Volcanic"
    },
    {
      "x": -18,
      "y": 30,
      "z": 11,
      "name": "Rock_Volcanic"
    },
    {
      "x": -18,
      "y": 31,
      "z": 11,
      "name": "Rock_Volcanic"
    },
    {
      "x": -18,
      "y": 32,
      "z": 11,
      "name": "Rock_Volcanic_Cracked_Lava"
    },
    {
      "x": -18,
      "y": 33,
      "z": 11,
      "name": "Rock_Volcanic"
    },
    {
      "x": -18,
      "y": 34,
      "z": 11,
      "name": "Soil_Volcanic_Gravel"
    },
    {
      "x": -18,
      "y": 35,
      "z": 11,
      "name": "Soil_Volcanic_Gravel"
    },
    {
      "x": -18,
      "y": 36,
      "z": 11,
      "name": "Rock_Volcanic"
    },
    {
      "x": -18,
      "y": 30,
      "z": 12,
      "name": "Rock_Volcanic"
    },
    {
      "x": -18,
      "y": 31,
      "z": 12,
      "name": "Rock_Volcanic"
    },
    {
      "x": -18,
      "y": 32,
      "z": 12,
      "name": "Rock_Volcanic"
    },
    {
      "x": -18,
      "y": 33,
      "z": 12,
      "name": "Rock_Volcanic_Cracked_Lava"
    },
    {
      "x": -18,
      "y": 34,
      "z": 12,
      "name": "Rock_Volcanic_Cracked_Lava"
    },
    {
      "x": -18,
      "y": 35,
      "z": 12,
      "name": "Soil_Volcanic_Gravel"
    },
    {
      "x": -18,
      "y": 36,
      "z": 12,
      "name": "Soil_Volcanic_Gravel"
    },
    {
      "x": -18,
      "y": 37,
      "z": 12,
      "name": "Rock_Volcanic"
    },
    {
      "x": -18,
      "y": 38,
      "z": 12,
      "name": "Soil_Volcanic_Gravel"
    },
    {
      "x": -18,
      "y": 39,
      "z": 12,
      "name": "Plant_Bramble_Dead_Twisted"
    },
    {
      "x": -18,
      "y": 33,
      "z": 13,
      "name": "Rock_Volcanic_Cracked_Lava"
    },
    {
      "x": -18,
      "y": 34,
      "z": 13,
      "name": "Rock_Volcanic"
    },
    {
      "x": -18,
      "y": 35,
      "z": 13,
      "name": "Soil_Volcanic_Gravel"
    },
    {
      "x": -18,
      "y": 36,
      "z": 13,
      "name": "Soil_Volcanic_Gravel"
    },
    {
      "x": -18,
      "y": 37,
      "z": 13,
      "name": "Soil_Volcanic_Gravel"
    },
    {
      "x": -18,
      "y": 38,
      "z": 13,
      "name": "Soil_Volcanic_Gravel"
    },
    {
      "x": -17,
      "y": 18,
      "z": -18,
      "name": "Rock_Volcanic"
    },
    {
      "x": -17,
      "y": 19,
      "z": -18,
      "name": "Rock_Volcanic"
    },
    {
      "x": -17,
      "y": 16,
      "z": -17,
      "name": "Rock_Volcanic"
    },
    {
      "x": -17,
      "y": 17,
      "z": -17,
      "name": "Rock_Volcanic"
    },
    {
      "x": -17,
      "y": 18,
      "z": -17,
      "name": "Rock_Volcanic"
    },
    {
      "x": -17,
      "y": 19,
      "z": -17,
      "name": "Rock_Volcanic"
    },
    {
      "x": -17,
      "y": 20,
      "z": -17,
      "name": "Rock_Volcanic"
    },
    {
      "x": -17,
      "y": 21,
      "z": -17,
      "name": "Rock_Volcanic"
    },
    {
      "x": -17,
      "y": 15,
      "z": -16,
      "name": "Rock_Volcanic"
    },
    {
      "x": -17,
      "y": 16,
      "z": -16,
      "name": "Soil_Volcanic_Gravel"
    },
    {
      "x": -17,
      "y": 17,
      "z": -16,
      "name": "Rock_Volcanic"
    },
    {
      "x": -17,
      "y": 18,
      "z": -16,
      "name": "Rock_Volcanic"
    },
    {
      "x": -17,
      "y": 19,
      "z": -16,
      "name": "Rock_Volcanic"
    },
    {
      "x": -17,
      "y": 20,
      "z": -16,
      "name": "Rock_Volcanic"
    },
    {
      "x": -17,
      "y": 21,
      "z": -16,
      "name": "Rock_Volcanic"
    },
    {
      "x": -17,
      "y": 22,
      "z": -16,
      "name": "Rock_Volcanic"
    },
    {
      "x": -17,
      "y": 23,
      "z": -16,
      "name": "Plant_Bush_Dead_Tall"
    },
    {
      "x": -17,
      "y": 13,
      "z": -15,
      "name": "Rock_Volcanic"
    },
    {
      "x": -17,
      "y": 14,
      "z": -15,
      "name": "Soil_Volcanic_Gravel"
    },
    {
      "x": -17,
      "y": 15,
      "z": -15,
      "name": "Soil_Volcanic_Gravel"
    },
    {
      "x": -17,
      "y": 16,
      "z": -15,
      "name": "Rock_Volcanic"
    },
    {
      "x": -17,
      "y": 17,
      "z": -15,
      "name": "Rock_Volcanic_Cracked_Lava"
    },
    {
      "x": -17,
      "y": 18,
      "z": -15,
      "name": "Rock_Volcanic"
    },
    {
      "x": -17,
      "y": 19,
      "z": -15,
      "name": "Rock_Volcanic"
    },
    {
      "x": -17,
      "y": 20,
      "z": -15,
      "name": "Rock_Volcanic"
    },
    {
      "x": -17,
      "y": 21,
      "z": -15,
      "name": "Soil_Volcanic_Gravel"
    },
    {
      "x": -17,
      "y": 22,
      "z": -15,
      "name": "Soil_Volcanic_Gravel"
    },
    {
      "x": -17,
      "y": 14,
      "z": -14,
      "name": "Rock_Volcanic"
    },
    {
      "x": -17,
      "y": 15,
      "z": -14,
      "name": "Rock_Volcanic_Cracked_Lava"
    },
    {
      "x": -17,
      "y": 16,
      "z": -14,
      "name": "Rock_Volcanic_Cracked_Lava"
    },
    {
      "x": -17,
      "y": 17,
      "z": -14,
      "name": "Rock_Volcanic_Cracked_Lava"
    },
    {
      "x": -17,
      "y": 18,
      "z": -14,
      "name": "Rock_Volcanic"
    },
    {
      "x": -17,
      "y": 19,
      "z": -14,
      "name": "Rock_Volcanic"
    },
    {
      "x": -17,
      "y": 20,
      "z": -14,
      "name": "Rock_Volcanic"
    },
    {
      "x": -17,
      "y": 21,
      "z": -14,
      "name": "Rock_Volcanic"
    },
    {
      "x": -17,
      "y": 22,
      "z": -14,
      "name": "Rock_Volcanic"
    },
    {
      "x": -17,
      "y": 12,
      "z": -13,
      "name": "Rock_Volcanic"
    },
    {
      "x": -17,
      "y": 13,
      "z": -13,
      "name": "Rock_Volcanic"
    },
    {
      "x": -17,
      "y": 14,
      "z": -13,
      "name": "Soil_Volcanic_Gravel"
    },
    {
      "x": -17,
      "y": 15,
      "z": -13,
      "name": "Soil_Volcanic_Gravel"
    },
    {
      "x": -17,
      "y": 16,
      "z": -13,
      "name": "Soil_Volcanic_Gravel"
    },
    {
      "x": -17,
      "y": 17,
      "z": -13,
      "name": "Rock_Volcanic"
    },
    {
      "x": -17,
      "y": 18,
      "z": -13,
      "name": "Rock_Volcanic"
    },
    {
      "x": -17,
      "y": 19,
      "z": -13,
      "name": "Rock_Volcanic"
    },
    {
      "x": -17,
      "y": 20,
      "z": -13,
      "name": "Rock_Volcanic"
    },
    {
      "x": -17,
      "y": 21,
      "z": -13,
      "name": "Soil_Volcanic_Gravel"
    },
    {
      "x": -17,
      "y": 22,
      "z": -13,
      "name": "Soil_Volcanic_Gravel"
    },
    {
      "x": -17,
      "y": 15,
      "z": -12,
      "name": "Rock_Volcanic_Stalactite_Small",
      "rotation": 8
    },
    {
      "x": -17,
      "y": 16,
      "z": -12,
      "name": "Rock_Volcanic"
    },
    {
      "x": -17,
      "y": 17,
      "z": -12,
      "name": "Rock_Volcanic"
    },
    {
      "x": -17,
      "y": 18,
      "z": -12,
      "name": "Rock_Volcanic"
    },
    {
      "x": -17,
      "y": 19,
      "z": -12,
      "name": "Rock_Volcanic"
    },
    {
      "x": -17,
      "y": 20,
      "z": -12,
      "name": "Rock_Volcanic"
    },
    {
      "x": -17,
      "y": 21,
      "z": -12,
      "name": "Rock_Volcanic"
    },
    {
      "x": -17,
      "y": 22,
      "z": -12,
      "name": "Rock_Volcanic"
    },
    {
      "x": -17,
      "y": 17,
      "z": -11,
      "name": "Rock_Volcanic"
    },
    {
      "x": -17,
      "y": 18,
      "z": -11,
      "name": "Rock_Volcanic"
    },
    {
      "x": -17,
      "y": 19,
      "z": -11,
      "name": "Rock_Volcanic_Cracked_Lava"
    },
    {
      "x": -17,
      "y": 20,
      "z": -11,
      "name": "Rock_Volcanic"
    },
    {
      "x": -17,
      "y": 21,
      "z": -11,
      "name": "Soil_Volcanic_Gravel"
    },
    {
      "x": -17,
      "y": 18,
      "z": -10,
      "name": "Rock_Volcanic"
    },
    {
      "x": -17,
      "y": 30,
      "z": 7,
      "name": "Rock_Volcanic"
    },
    {
      "x": -17,
      "y": 31,
      "z": 7,
      "name": "Rock_Volcanic"
    },
    {
      "x": -17,
      "y": 32,
      "z": 7,
      "name": "Rock_Volcanic"
    },
    {
      "x": -17,
      "y": 33,
      "z": 7,
      "name": "Rock_Volcanic"
    },
    {
      "x": -17,
      "y": 34,
      "z": 7,
      "name": "Soil_Volcanic_Gravel"
    },
    {
      "x": -17,
      "y": 28,
      "z": 8,
      "name": "Rock_Volcanic"
    },
    {
      "x": -17,
      "y": 29,
      "z": 8,
      "name": "Rock_Volcanic"
    },
    {
      "x": -17,
      "y": 30,
      "z": 8,
      "name": "Rock_Volcanic"
    },
    {
      "x": -17,
      "y": 31,
      "z": 8,
      "name": "Rock_Volcanic"
    },
    {
      "x": -17,
      "y": 32,
      "z": 8,
      "name": "Rock_Volcanic"
    },
    {
      "x": -17,
      "y": 33,
      "z": 8,
      "name": "Rock_Volcanic"
    },
    {
      "x": -17,
      "y": 34,
      "z": 8,
      "name": "Soil_Volcanic_Gravel"
    },
    {
      "x": -17,
      "y": 35,
      "z": 8,
      "name": "Soil_Volcanic_Gravel"
    },
    {
      "x": -17,
      "y": 36,
      "z": 8,
      "name": "Soil_Volcanic_Gravel"
    },
    {
      "x": -17,
      "y": 26,
      "z": 9,
      "name": "Plant_Moss_Cave_Red",
      "rotation": 8
    },
    {
      "x": -17,
      "y": 27,
      "z": 9,
      "name": "Rock_Volcanic"
    },
    {
      "x": -17,
      "y": 28,
      "z": 9,
      "name": "Rock_Volcanic"
    },
    {
      "x": -17,
      "y": 29,
      "z": 9,
      "name": "Rock_Volcanic"
    },
    {
      "x": -17,
      "y": 30,
      "z": 9,
      "name": "Rock_Volcanic"
    },
    {
      "x": -17,
      "y": 31,
      "z": 9,
      "name": "Rock_Volcanic"
    },
    {
      "x": -17,
      "y": 32,
      "z": 9,
      "name": "Rock_Volcanic"
    },
    {
      "x": -17,
      "y": 33,
      "z": 9,
      "name": "Rock_Volcanic"
    },
    {
      "x": -17,
      "y": 34,
      "z": 9,
      "name": "Soil_Volcanic_Gravel"
    },
    {
      "x": -17,
      "y": 35,
      "z": 9,
      "name": "Soil_Volcanic_Gravel"
    },
    {
      "x": -17,
      "y": 36,
      "z": 9,
      "name": "Soil_Volcanic_Gravel"
    },
    {
      "x": -17,
      "y": 37,
      "z": 9,
      "name": "Soil_Volcanic_Gravel"
    },
    {
      "x": -17,
      "y": 26,
      "z": 10,
      "name": "Plant_Moss_Cave_Red",
      "rotation": 8
    },
    {
      "x": -17,
      "y": 27,
      "z": 10,
      "name": "Rock_Volcanic"
    },
    {
      "x": -17,
      "y": 28,
      "z": 10,
      "name": "Rock_Volcanic"
    },
    {
      "x": -17,
      "y": 29,
      "z": 10,
      "name": "Rock_Volcanic"
    },
    {
      "x": -17,
      "y": 30,
      "z": 10,
      "name": "Rock_Volcanic_Cracked_Lava"
    },
    {
      "x": -17,
      "y": 31,
      "z": 10,
      "name": "Rock_Volcanic"
    },
    {
      "x": -17,
      "y": 32,
      "z": 10,
      "name": "Rock_Volcanic"
    },
    {
      "x": -17,
      "y": 33,
      "z": 10,
      "name": "Rock_Volcanic"
    },
    {
      "x": -17,
      "y": 34,
      "z": 10,
      "name": "Rock_Volcanic"
    },
    {
      "x": -17,
      "y": 35,
      "z": 10,
      "name": "Soil_Volcanic_Gravel"
    },
    {
      "x": -17,
      "y": 36,
      "z": 10,
      "name": "Rock_Volcanic"
    },
    {
      "x": -17,
      "y": 26,
      "z": 11,
      "name": "Plant_Moss_Cave_Red",
      "rotation": 8
    },
    {
      "x": -17,
      "y": 27,
      "z": 11,
      "name": "Rock_Volcanic"
    },
    {
      "x": -17,
      "y": 28,
      "z": 11,
      "name": "Rock_Volcanic"
    },
    {
      "x": -17,
      "y": 29,
      "z": 11,
      "name": "Rock_Volcanic"
    },
    {
      "x": -17,
      "y": 30,
      "z": 11,
      "name": "Rock_Volcanic"
    },
    {
      "x": -17,
      "y": 31,
      "z": 11,
      "name": "Rock_Volcanic"
    },
    {
      "x": -17,
      "y": 32,
      "z": 11,
      "name": "Rock_Volcanic_Cracked_Lava"
    },
    {
      "x": -17,
      "y": 33,
      "z": 11,
      "name": "Rock_Volcanic"
    },
    {
      "x": -17,
      "y": 34,
      "z": 11,
      "name": "Soil_Volcanic_Gravel"
    },
    {
      "x": -17,
      "y": 35,
      "z": 11,
      "name": "Soil_Volcanic_Gravel"
    },
    {
      "x": -17,
      "y": 36,
      "z": 11,
      "name": "Rock_Volcanic"
    },
    {
      "x": -17,
      "y": 28,
      "z": 12,
      "name": "Rock_Volcanic_Cracked_Lava"
    },
    {
      "x": -17,
      "y": 29,
      "z": 12,
      "name": "Rock_Volcanic"
    },
    {
      "x": -17,
      "y": 30,
      "z": 12,
      "name": "Rock_Volcanic"
    },
    {
      "x": -17,
      "y": 31,
      "z": 12,
      "name": "Rock_Volcanic"
    },
    {
      "x": -17,
      "y": 32,
      "z": 12,
      "name": "Rock_Volcanic"
    },
    {
      "x": -17,
      "y": 33,
      "z": 12,
      "name": "Rock_Volcanic"
    },
    {
      "x": -17,
      "y": 34,
      "z": 12,
      "name": "Rock_Volcanic"
    },
    {
      "x": -17,
      "y": 35,
      "z": 12,
      "name": "Rock_Volcanic"
    },
    {
      "x": -17,
      "y": 36,
      "z": 12,
      "name": "Soil_Volcanic_Gravel"
    },
    {
      "x": -17,
      "y": 37,
      "z": 12,
      "name": "Soil_Volcanic_Gravel"
    },
    {
      "x": -17,
      "y": 38,
      "z": 12,
      "name": "Soil_Volcanic_Gravel"
    },
    {
      "x": -17,
      "y": 30,
      "z": 13,
      "name": "Rock_Volcanic"
    },
    {
      "x": -17,
      "y": 31,
      "z": 13,
      "name": "Rock_Volcanic"
    },
    {
      "x": -17,
      "y": 32,
      "z": 13,
      "name": "Rock_Volcanic_Cracked_Lava"
    },
    {
      "x": -17,
      "y": 33,
      "z": 13,
      "name": "Rock_Volcanic"
    },
    {
      "x": -17,
      "y": 34,
      "z": 13,
      "name": "Soil_Volcanic_Gravel"
    },
    {
      "x": -17,
      "y": 35,
      "z": 13,
      "name": "Rock_Volcanic"
    },
    {
      "x": -17,
      "y": 36,
      "z": 13,
      "name": "Rock_Volcanic"
    },
    {
      "x": -17,
      "y": 37,
      "z": 13,
      "name": "Soil_Volcanic_Gravel"
    },
    {
      "x": -17,
      "y": 38,
      "z": 13,
      "name": "Soil_Volcanic_Gravel"
    },
    {
      "x": -17,
      "y": 33,
      "z": 14,
      "name": "Rock_Volcanic"
    },
    {
      "x": -17,
      "y": 34,
      "z": 14,
      "name": "Rock_Volcanic"
    },
    {
      "x": -17,
      "y": 35,
      "z": 14,
      "name": "Soil_Volcanic_Gravel"
    },
    {
      "x": -17,
      "y": 36,
      "z": 14,
      "name": "Soil_Volcanic_Gravel"
    },
    {
      "x": -17,
      "y": 37,
      "z": 14,
      "name": "Soil_Volcanic_Gravel"
    },
    {
      "x": -16,
      "y": 15,
      "z": -18,
      "name": "Rock_Volcanic_Cracked_Lava"
    },
    {
      "x": -16,
      "y": 16,
      "z": -18,
      "name": "Soil_Volcanic_Gravel"
    },
    {
      "x": -16,
      "y": 17,
      "z": -18,
      "name": "Rock_Volcanic"
    },
    {
      "x": -16,
      "y": 18,
      "z": -18,
      "name": "Rock_Volcanic"
    },
    {
      "x": -16,
      "y": 19,
      "z": -18,
      "name": "Rock_Volcanic"
    },
    {
      "x": -16,
      "y": 20,
      "z": -18,
      "name": "Rock_Volcanic"
    },
    {
      "x": -16,
      "y": 21,
      "z": -18,
      "name": "Rock_Volcanic"
    },
    {
      "x": -16,
      "y": 14,
      "z": -17,
      "name": "Rock_Volcanic"
    },
    {
      "x": -16,
      "y": 15,
      "z": -17,
      "name": "Soil_Volcanic_Gravel"
    },
    {
      "x": -16,
      "y": 16,
      "z": -17,
      "name": "Soil_Volcanic_Gravel"
    },
    {
      "x": -16,
      "y": 17,
      "z": -17,
      "name": "Rock_Volcanic"
    },
    {
      "x": -16,
      "y": 18,
      "z": -17,
      "name": "Rock_Volcanic_Cracked_Lava"
    },
    {
      "x": -16,
      "y": 19,
      "z": -17,
      "name": "Rock_Volcanic"
    },
    {
      "x": -16,
      "y": 20,
      "z": -17,
      "name": "Rock_Volcanic"
    },
    {
      "x": -16,
      "y": 21,
      "z": -17,
      "name": "Soil_Volcanic_Gravel"
    },
    {
      "x": -16,
      "y": 22,
      "z": -17,
      "name": "Soil_Volcanic_Gravel"
    },
    {
      "x": -16,
      "y": 12,
      "z": -16,
      "name": "Rock_Volcanic"
    },
    {
      "x": -16,
      "y": 13,
      "z": -16,
      "name": "Soil_Volcanic_Gravel"
    },
    {
      "x": -16,
      "y": 14,
      "z": -16,
      "name": "Soil_Volcanic_Gravel"
    },
    {
      "x": -16,
      "y": 15,
      "z": -16,
      "name": "Rock_Volcanic"
    },
    {
      "x": -16,
      "y": 16,
      "z": -16,
      "name": "Soil_Volcanic_Gravel"
    },
    {
      "x": -16,
      "y": 17,
      "z": -16,
      "name": "Rock_Volcanic"
    },
    {
      "x": -16,
      "y": 18,
      "z": -16,
      "name": "Rock_Volcanic"
    },
    {
      "x": -16,
      "y": 19,
      "z": -16,
      "name": "Rock_Volcanic"
    },
    {
      "x": -16,
      "y": 20,
      "z": -16,
      "name": "Rock_Volcanic"
    },
    {
      "x": -16,
      "y": 21,
      "z": -16,
      "name": "Soil_Volcanic_Gravel"
    },
    {
      "x": -16,
      "y": 22,
      "z": -16,
      "name": "Soil_Volcanic_Gravel"
    },
    {
      "x": -16,
      "y": 10,
      "z": -15,
      "name": "Rock_Volcanic"
    },
    {
      "x": -16,
      "y": 11,
      "z": -15,
      "name": "Rock_Volcanic_Cracked_Lava"
    },
    {
      "x": -16,
      "y": 12,
      "z": -15,
      "name": "Soil_Volcanic_Gravel"
    },
    {
      "x": -16,
      "y": 13,
      "z": -15,
      "name": "Soil_Volcanic_Gravel"
    },
    {
      "x": -16,
      "y": 14,
      "z": -15,
      "name": "Soil_Volcanic_Gravel"
    },
    {
      "x": -16,
      "y": 15,
      "z": -15,
      "name": "Rock_Volcanic"
    },
    {
      "x": -16,
      "y": 16,
      "z": -15,
      "name": "Soil_Volcanic_Gravel"
    },
    {
      "x": -16,
      "y": 17,
      "z": -15,
      "name": "Rock_Volcanic"
    },
    {
      "x": -16,
      "y": 18,
      "z": -15,
      "name": "Rock_Volcanic"
    },
    {
      "x": -16,
      "y": 19,
      "z": -15,
      "name": "Rock_Volcanic"
    },
    {
      "x": -16,
      "y": 20,
      "z": -15,
      "name": "Rock_Volcanic"
    },
    {
      "x": -16,
      "y": 21,
      "z": -15,
      "name": "Soil_Volcanic_Gravel"
    },
    {
      "x": -16,
      "y": 22,
      "z": -15,
      "name": "Soil_Volcanic_Gravel"
    },
    {
      "x": -16,
      "y": 23,
      "z": -15,
      "name": "Rock_Volcanic"
    },
    {
      "x": -16,
      "y": 9,
      "z": -14,
      "name": "Rock_Crystal_Red_Medium",
      "rotation": 7
    },
    {
      "x": -16,
      "y": 10,
      "z": -14,
      "name": "Rock_Volcanic"
    },
    {
      "x": -16,
      "y": 11,
      "z": -14,
      "name": "Soil_Volcanic_Gravel"
    },
    {
      "x": -16,
      "y": 12,
      "z": -14,
      "name": "Soil_Volcanic_Gravel"
    },
    {
      "x": -16,
      "y": 13,
      "z": -14,
      "name": "Rock_Volcanic"
    },
    {
      "x": -16,
      "y": 14,
      "z": -14,
      "name": "Soil_Volcanic_Gravel"
    },
    {
      "x": -16,
      "y": 15,
      "z": -14,
      "name": "Rock_Volcanic"
    },
    {
      "x": -16,
      "y": 16,
      "z": -14,
      "name": "Soil_Volcanic_Gravel"
    },
    {
      "x": -16,
      "y": 17,
      "z": -14,
      "name": "Soil_Volcanic_Gravel"
    },
    {
      "x": -16,
      "y": 18,
      "z": -14,
      "name": "Rock_Volcanic"
    },
    {
      "x": -16,
      "y": 19,
      "z": -14,
      "name": "Rock_Volcanic"
    },
    {
      "x": -16,
      "y": 20,
      "z": -14,
      "name": "Rock_Volcanic"
    },
    {
      "x": -16,
      "y": 21,
      "z": -14,
      "name": "Rock_Volcanic"
    },
    {
      "x": -16,
      "y": 22,
      "z": -14,
      "name": "Soil_Volcanic_Gravel"
    },
    {
      "x": -16,
      "y": 23,
      "z": -14,
      "name": "Soil_Volcanic_Gravel"
    },
    {
      "x": -16,
      "y": 10,
      "z": -13,
      "name": "Rock_Volcanic"
    },
    {
      "x": -16,
      "y": 11,
      "z": -13,
      "name": "Soil_Volcanic_Gravel"
    },
    {
      "x": -16,
      "y": 12,
      "z": -13,
      "name": "Soil_Volcanic_Gravel"
    },
    {
      "x": -16,
      "y": 13,
      "z": -13,
      "name": "Rock_Volcanic"
    },
    {
      "x": -16,
      "y": 14,
      "z": -13,
      "name": "Soil_Volcanic_Gravel"
    },
    {
      "x": -16,
      "y": 15,
      "z": -13,
      "name": "Soil_Volcanic_Gravel"
    },
    {
      "x": -16,
      "y": 16,
      "z": -13,
      "name": "Soil_Volcanic_Gravel"
    },
    {
      "x": -16,
      "y": 17,
      "z": -13,
      "name": "Rock_Volcanic"
    },
    {
      "x": -16,
      "y": 18,
      "z": -13,
      "name": "Rock_Volcanic"
    },
    {
      "x": -16,
      "y": 19,
      "z": -13,
      "name": "Rock_Volcanic"
    },
    {
      "x": -16,
      "y": 20,
      "z": -13,
      "name": "Rock_Volcanic"
    },
    {
      "x": -16,
      "y": 21,
      "z": -13,
      "name": "Rock_Volcanic"
    },
    {
      "x": -16,
      "y": 22,
      "z": -13,
      "name": "Soil_Volcanic_Gravel"
    },
    {
      "x": -16,
      "y": 23,
      "z": -13,
      "name": "Rock_Volcanic"
    },
    {
      "x": -16,
      "y": 12,
      "z": -12,
      "name": "Rock_Volcanic_Stalactite_Small",
      "rotation": 8
    },
    {
      "x": -16,
      "y": 13,
      "z": -12,
      "name": "Rock_Volcanic"
    },
    {
      "x": -16,
      "y": 14,
      "z": -12,
      "name": "Soil_Volcanic_Gravel"
    },
    {
      "x": -16,
      "y": 15,
      "z": -12,
      "name": "Rock_Volcanic"
    },
    {
      "x": -16,
      "y": 16,
      "z": -12,
      "name": "Rock_Volcanic"
    },
    {
      "x": -16,
      "y": 17,
      "z": -12,
      "name": "Soil_Volcanic_Gravel"
    },
    {
      "x": -16,
      "y": 18,
      "z": -12,
      "name": "Rock_Volcanic"
    },
    {
      "x": -16,
      "y": 19,
      "z": -12,
      "name": "Rock_Volcanic"
    },
    {
      "x": -16,
      "y": 20,
      "z": -12,
      "name": "Rock_Volcanic"
    },
    {
      "x": -16,
      "y": 21,
      "z": -12,
      "name": "Soil_Volcanic_Gravel"
    },
    {
      "x": -16,
      "y": 22,
      "z": -12,
      "name": "Rock_Volcanic"
    },
    {
      "x": -16,
      "y": 15,
      "z": -11,
      "name": "Rock_Volcanic"
    },
    {
      "x": -16,
      "y": 16,
      "z": -11,
      "name": "Rock_Volcanic"
    },
    {
      "x": -16,
      "y": 17,
      "z": -11,
      "name": "Rock_Volcanic"
    },
    {
      "x": -16,
      "y": 18,
      "z": -11,
      "name": "Rock_Volcanic"
    },
    {
      "x": -16,
      "y": 19,
      "z": -11,
      "name": "Rock_Volcanic"
    },
    {
      "x": -16,
      "y": 20,
      "z": -11,
      "name": "Rock_Volcanic"
    },
    {
      "x": -16,
      "y": 21,
      "z": -11,
      "name": "Soil_Volcanic_Gravel"
    },
    {
      "x": -16,
      "y": 22,
      "z": -11,
      "name": "Soil_Volcanic_Gravel"
    },
    {
      "x": -16,
      "y": 13,
      "z": -10,
      "name": "Rock_Volcanic_Stalactite_Small",
      "rotation": 8
    },
    {
      "x": -16,
      "y": 14,
      "z": -10,
      "name": "Rock_Volcanic"
    },
    {
      "x": -16,
      "y": 15,
      "z": -10,
      "name": "Soil_Volcanic_Gravel"
    },
    {
      "x": -16,
      "y": 16,
      "z": -10,
      "name": "Soil_Volcanic_Gravel"
    },
    {
      "x": -16,
      "y": 17,
      "z": -10,
      "name": "Rock_Volcanic"
    },
    {
      "x": -16,
      "y": 18,
      "z": -10,
      "name": "Rock_Volcanic_Cracked_Lava"
    },
    {
      "x": -16,
      "y": 19,
      "z": -10,
      "name": "Rock_Volcanic"
    },
    {
      "x": -16,
      "y": 20,
      "z": -10,
      "name": "Rock_Volcanic"
    },
    {
      "x": -16,
      "y": 21,
      "z": -10,
      "name": "Rock_Volcanic"
    },
    {
      "x": -16,
      "y": 22,
      "z": -10,
      "name": "Soil_Volcanic_Gravel"
    },
    {
      "x": -16,
      "y": 30,
      "z": 6,
      "name": "Rock_Volcanic"
    },
    {
      "x": -16,
      "y": 31,
      "z": 6,
      "name": "Rock_Volcanic_Cracked_Lava"
    },
    {
      "x": -16,
      "y": 32,
      "z": 6,
      "name": "Rock_Volcanic_Cracked_Lava"
    },
    {
      "x": -16,
      "y": 33,
      "z": 6,
      "name": "Rock_Volcanic"
    },
    {
      "x": -16,
      "y": 34,
      "z": 6,
      "name": "Soil_Volcanic_Gravel"
    },
    {
      "x": -16,
      "y": 28,
      "z": 7,
      "name": "Rock_Volcanic_Cracked_Lava"
    },
    {
      "x": -16,
      "y": 29,
      "z": 7,
      "name": "Rock_Volcanic"
    },
    {
      "x": -16,
      "y": 30,
      "z": 7,
      "name": "Rock_Volcanic"
    },
    {
      "x": -16,
      "y": 31,
      "z": 7,
      "name": "Rock_Volcanic"
    },
    {
      "x": -16,
      "y": 32,
      "z": 7,
      "name": "Rock_Volcanic"
    },
    {
      "x": -16,
      "y": 33,
      "z": 7,
      "name": "Soil_Volcanic_Gravel"
    },
    {
      "x": -16,
      "y": 34,
      "z": 7,
      "name": "Soil_Volcanic_Gravel"
    },
    {
      "x": -16,
      "y": 35,
      "z": 7,
      "name": "Rock_Volcanic"
    },
    {
      "x": -16,
      "y": 36,
      "z": 7,
      "name": "Plant_Bramble_Dead_Twisted"
    },
    {
      "x": -16,
      "y": 28,
      "z": 8,
      "name": "Rock_Volcanic"
    },
    {
      "x": -16,
      "y": 29,
      "z": 8,
      "name": "Rock_Volcanic"
    },
    {
      "x": -16,
      "y": 30,
      "z": 8,
      "name": "Rock_Volcanic_Cracked_Lava"
    },
    {
      "x": -16,
      "y": 31,
      "z": 8,
      "name": "Rock_Volcanic"
    },
    {
      "x": -16,
      "y": 32,
      "z": 8,
      "name": "Rock_Volcanic"
    },
    {
      "x": -16,
      "y": 33,
      "z": 8,
      "name": "Rock_Volcanic"
    },
    {
      "x": -16,
      "y": 34,
      "z": 8,
      "name": "Soil_Volcanic_Gravel"
    },
    {
      "x": -16,
      "y": 35,
      "z": 8,
      "name": "Soil_Volcanic_Gravel"
    },
    {
      "x": -16,
      "y": 36,
      "z": 8,
      "name": "Soil_Volcanic_Gravel"
    },
    {
      "x": -16,
      "y": 25,
      "z": 9,
      "name": "Rock_Volcanic"
    },
    {
      "x": -16,
      "y": 26,
      "z": 9,
      "name": "Soil_Volcanic_Gravel"
    },
    {
      "x": -16,
      "y": 27,
      "z": 9,
      "name": "Rock_Volcanic"
    },
    {
      "x": -16,
      "y": 28,
      "z": 9,
      "name": "Rock_Volcanic_Cracked_Lava"
    },
    {
      "x": -16,
      "y": 29,
      "z": 9,
      "name": "Rock_Volcanic"
    },
    {
      "x": -16,
      "y": 30,
      "z": 9,
      "name": "Rock_Volcanic_Cracked_Lava"
    },
    {
      "x": -16,
      "y": 31,
      "z": 9,
      "name": "Rock_Volcanic"
    },
    {
      "x": -16,
      "y": 32,
      "z": 9,
      "name": "Rock_Volcanic"
    },
    {
      "x": -16,
      "y": 33,
      "z": 9,
      "name": "Rock_Volcanic"
    },
    {
      "x": -16,
      "y": 34,
      "z": 9,
      "name": "Rock_Volcanic"
    },
    {
      "x": -16,
      "y": 35,
      "z": 9,
      "name": "Soil_Volcanic_Gravel"
    },
    {
      "x": -16,
      "y": 36,
      "z": 9,
      "name": "Soil_Volcanic_Gravel"
    },
    {
      "x": -16,
      "y": 37,
      "z": 9,
      "name": "Soil_Volcanic_Gravel"
    },
    {
      "x": -16,
      "y": 38,
      "z": 9,
      "name": "Rubble_Volcanic"
    },
    {
      "x": -16,
      "y": 21,
      "z": 10,
      "name": "Rock_Crystal_Red_Medium",
      "rotation": 7
    },
    {
      "x": -16,
      "y": 22,
      "z": 10,
      "name": "Rock_Crystal_Red_Medium",
      "rotation": 7
    },
    {
      "x": -16,
      "y": 24,
      "z": 10,
      "name": "Rock_Volcanic"
    },
    {
      "x": -16,
      "y": 25,
      "z": 10,
      "name": "Rock_Volcanic"
    },
    {
      "x": -16,
      "y": 26,
      "z": 10,
      "name": "Rock_Volcanic_Cracked_Lava"
    },
    {
      "x": -16,
      "y": 27,
      "z": 10,
      "name": "Soil_Volcanic_Gravel"
    },
    {
      "x": -16,
      "y": 28,
      "z": 10,
      "name": "Rock_Volcanic"
    },
    {
      "x": -16,
      "y": 29,
      "z": 10,
      "name": "Rock_Volcanic"
    },
    {
      "x": -16,
      "y": 30,
      "z": 10,
      "name": "Rock_Volcanic"
    },
    {
      "x": -16,
      "y": 31,
      "z": 10,
      "name": "Rock_Volcanic"
    },
    {
      "x": -16,
      "y": 32,
      "z": 10,
      "name": "Rock_Volcanic"
    },
    {
      "x": -16,
      "y": 33,
      "z": 10,
      "name": "Rock_Volcanic"
    },
    {
      "x": -16,
      "y": 34,
      "z": 10,
      "name": "Rock_Volcanic"
    },
    {
      "x": -16,
      "y": 35,
      "z": 10,
      "name": "Rock_Volcanic"
    },
    {
      "x": -16,
      "y": 36,
      "z": 10,
      "name": "Rock_Volcanic"
    },
    {
      "x": -16,
      "y": 37,
      "z": 10,
      "name": "Soil_Volcanic_Gravel"
    },
    {
      "x": -16,
      "y": 25,
      "z": 11,
      "name": "Rock_Volcanic"
    },
    {
      "x": -16,
      "y": 26,
      "z": 11,
      "name": "Rock_Volcanic"
    },
    {
      "x": -16,
      "y": 27,
      "z": 11,
      "name": "Rock_Volcanic_Cracked_Lava"
    },
    {
      "x": -16,
      "y": 28,
      "z": 11,
      "name": "Rock_Volcanic"
    },
    {
      "x": -16,
      "y": 29,
      "z": 11,
      "name": "Rock_Volcanic"
    },
    {
      "x": -16,
      "y": 30,
      "z": 11,
      "name": "Rock_Volcanic_Cracked_Lava"
    },
    {
      "x": -16,
      "y": 31,
      "z": 11,
      "name": "Rock_Volcanic"
    },
    {
      "x": -16,
      "y": 32,
      "z": 11,
      "name": "Rock_Volcanic_Cracked_Lava"
    },
    {
      "x": -16,
      "y": 33,
      "z": 11,
      "name": "Rock_Volcanic_Cracked_Lava"
    },
    {
      "x": -16,
      "y": 34,
      "z": 11,
      "name": "Rock_Volcanic"
    },
    {
      "x": -16,
      "y": 35,
      "z": 11,
      "name": "Soil_Volcanic_Gravel"
    },
    {
      "x": -16,
      "y": 36,
      "z": 11,
      "name": "Soil_Volcanic_Gravel"
    },
    {
      "x": -16,
      "y": 37,
      "z": 11,
      "name": "Rock_Volcanic"
    },
    {
      "x": -16,
      "y": 26,
      "z": 12,
      "name": "Rock_Volcanic_Cracked_Lava"
    },
    {
      "x": -16,
      "y": 27,
      "z": 12,
      "name": "Rock_Volcanic_Cracked_Lava"
    },
    {
      "x": -16,
      "y": 28,
      "z": 12,
      "name": "Rock_Volcanic"
    },
    {
      "x": -16,
      "y": 29,
      "z": 12,
      "name": "Rock_Volcanic"
    },
    {
      "x": -16,
      "y": 30,
      "z": 12,
      "name": "Rock_Volcanic"
    },
    {
      "x": -16,
      "y": 31,
      "z": 12,
      "name": "Rock_Volcanic"
    },
    {
      "x": -16,
      "y": 32,
      "z": 12,
      "name": "Rock_Volcanic"
    },
    {
      "x": -16,
      "y": 33,
      "z": 12,
      "name": "Rock_Volcanic"
    },
    {
      "x": -16,
      "y": 34,
      "z": 12,
      "name": "Soil_Volcanic_Gravel"
    },
    {
      "x": -16,
      "y": 35,
      "z": 12,
      "name": "Soil_Volcanic_Gravel"
    },
    {
      "x": -16,
      "y": 36,
      "z": 12,
      "name": "Rock_Volcanic"
    },
    {
      "x": -16,
      "y": 37,
      "z": 12,
      "name": "Soil_Volcanic_Gravel"
    },
    {
      "x": -16,
      "y": 38,
      "z": 12,
      "name": "Soil_Volcanic_Gravel"
    },
    {
      "x": -16,
      "y": 27,
      "z": 13,
      "name": "Plant_Moss_Cave_Red",
      "rotation": 8
    },
    {
      "x": -16,
      "y": 28,
      "z": 13,
      "name": "Rock_Volcanic"
    },
    {
      "x": -16,
      "y": 29,
      "z": 13,
      "name": "Rock_Volcanic"
    },
    {
      "x": -16,
      "y": 30,
      "z": 13,
      "name": "Rock_Volcanic"
    },
    {
      "x": -16,
      "y": 31,
      "z": 13,
      "name": "Rock_Volcanic"
    },
    {
      "x": -16,
      "y": 32,
      "z": 13,
      "name": "Rock_Volcanic"
    },
    {
      "x": -16,
      "y": 33,
      "z": 13,
      "name": "Rock_Volcanic"
    },
    {
      "x": -16,
      "y": 34,
      "z": 13,
      "name": "Soil_Volcanic_Gravel"
    },
    {
      "x": -16,
      "y": 35,
      "z": 13,
      "name": "Soil_Volcanic_Gravel"
    },
    {
      "x": -16,
      "y": 36,
      "z": 13,
      "name": "Rock_Volcanic"
    },
    {
      "x": -16,
      "y": 37,
      "z": 13,
      "name": "Soil_Volcanic_Gravel"
    },
    {
      "x": -16,
      "y": 38,
      "z": 13,
      "name": "Soil_Volcanic_Gravel"
    },
    {
      "x": -16,
      "y": 30,
      "z": 14,
      "name": "Rock_Volcanic_Cracked_Lava"
    },
    {
      "x": -16,
      "y": 31,
      "z": 14,
      "name": "Rock_Volcanic_Cracked_Lava"
    },
    {
      "x": -16,
      "y": 32,
      "z": 14,
      "name": "Rock_Volcanic"
    },
    {
      "x": -16,
      "y": 33,
      "z": 14,
      "name": "Rock_Volcanic"
    },
    {
      "x": -16,
      "y": 34,
      "z": 14,
      "name": "Rock_Volcanic"
    },
    {
      "x": -16,
      "y": 35,
      "z": 14,
      "name": "Rock_Volcanic"
    },
    {
      "x": -16,
      "y": 36,
      "z": 14,
      "name": "Rock_Volcanic"
    },
    {
      "x": -15,
      "y": 19,
      "z": -19,
      "name": "Rock_Volcanic"
    },
    {
      "x": -15,
      "y": 20,
      "z": -19,
      "name": "Rock_Volcanic"
    },
    {
      "x": -15,
      "y": 21,
      "z": -19,
      "name": "Rock_Volcanic"
    },
    {
      "x": -15,
      "y": 14,
      "z": -18,
      "name": "Rock_Volcanic_Cracked_Lava"
    },
    {
      "x": -15,
      "y": 15,
      "z": -18,
      "name": "Soil_Volcanic_Gravel"
    },
    {
      "x": -15,
      "y": 16,
      "z": -18,
      "name": "Soil_Volcanic_Gravel"
    },
    {
      "x": -15,
      "y": 17,
      "z": -18,
      "name": "Rock_Volcanic"
    },
    {
      "x": -15,
      "y": 18,
      "z": -18,
      "name": "Rock_Volcanic"
    },
    {
      "x": -15,
      "y": 19,
      "z": -18,
      "name": "Rock_Volcanic"
    },
    {
      "x": -15,
      "y": 20,
      "z": -18,
      "name": "Rock_Volcanic"
    },
    {
      "x": -15,
      "y": 21,
      "z": -18,
      "name": "Soil_Volcanic_Gravel"
    },
    {
      "x": -15,
      "y": 12,
      "z": -17,
      "name": "Rock_Volcanic"
    },
    {
      "x": -15,
      "y": 13,
      "z": -17,
      "name": "Soil_Volcanic_Gravel"
    },
    {
      "x": -15,
      "y": 14,
      "z": -17,
      "name": "Rock_Volcanic"
    },
    {
      "x": -15,
      "y": 15,
      "z": -17,
      "name": "Soil_Volcanic_Gravel"
    },
    {
      "x": -15,
      "y": 16,
      "z": -17,
      "name": "Soil_Volcanic_Gravel"
    },
    {
      "x": -15,
      "y": 17,
      "z": -17,
      "name": "Rock_Volcanic"
    },
    {
      "x": -15,
      "y": 18,
      "z": -17,
      "name": "Rock_Volcanic"
    },
    {
      "x": -15,
      "y": 19,
      "z": -17,
      "name": "Rock_Volcanic"
    },
    {
      "x": -15,
      "y": 20,
      "z": -17,
      "name": "Rock_Volcanic"
    },
    {
      "x": -15,
      "y": 21,
      "z": -17,
      "name": "Soil_Volcanic_Gravel"
    },
    {
      "x": -15,
      "y": 22,
      "z": -17,
      "name": "Soil_Volcanic_Gravel"
    },
    {
      "x": -15,
      "y": 23,
      "z": -17,
      "name": "Plant_Bramble_Dead_Twisted"
    },
    {
      "x": -15,
      "y": 10,
      "z": -16,
      "name": "Rock_Volcanic_Stalactite_Small",
      "rotation": 8
    },
    {
      "x": -15,
      "y": 11,
      "z": -16,
      "name": "Rock_Volcanic"
    },
    {
      "x": -15,
      "y": 12,
      "z": -16,
      "name": "Soil_Volcanic_Gravel"
    },
    {
      "x": -15,
      "y": 13,
      "z": -16,
      "name": "Rock_Volcanic"
    },
    {
      "x": -15,
      "y": 14,
      "z": -16,
      "name": "Rock_Volcanic"
    },
    {
      "x": -15,
      "y": 15,
      "z": -16,
      "name": "Soil_Volcanic_Gravel"
    },
    {
      "x": -15,
      "y": 16,
      "z": -16,
      "name": "Soil_Volcanic_Gravel"
    },
    {
      "x": -15,
      "y": 17,
      "z": -16,
      "name": "Rock_Volcanic"
    },
    {
      "x": -15,
      "y": 18,
      "z": -16,
      "name": "Rock_Volcanic"
    },
    {
      "x": -15,
      "y": 19,
      "z": -16,
      "name": "Rock_Volcanic"
    },
    {
      "x": -15,
      "y": 20,
      "z": -16,
      "name": "Rock_Volcanic"
    },
    {
      "x": -15,
      "y": 21,
      "z": -16,
      "name": "Soil_Volcanic_Gravel"
    },
    {
      "x": -15,
      "y": 22,
      "z": -16,
      "name": "Soil_Volcanic_Gravel"
    },
    {
      "x": -15,
      "y": 23,
      "z": -16,
      "name": "Soil_Volcanic_Gravel"
    },
    {
      "x": -15,
      "y": 7,
      "z": -15,
      "name": "Rock_Crystal_Red_Medium",
      "rotation": 7
    },
    {
      "x": -15,
      "y": 9,
      "z": -15,
      "name": "Rock_Crystal_Red_Medium",
      "rotation": 7
    },
    {
      "x": -15,
      "y": 10,
      "z": -15,
      "name": "Rock_Volcanic"
    },
    {
      "x": -15,
      "y": 11,
      "z": -15,
      "name": "Rock_Volcanic"
    },
    {
      "x": -15,
      "y": 17,
      "z": -15,
      "name": "Rock_Volcanic"
    },
    {
      "x": -15,
      "y": 18,
      "z": -15,
      "name": "Rock_Volcanic"
    },
    {
      "x": -15,
      "y": 19,
      "z": -15,
      "name": "Rock_Volcanic"
    },
    {
      "x": -15,
      "y": 20,
      "z": -15,
      "name": "Rock_Volcanic"
    },
    {
      "x": -15,
      "y": 21,
      "z": -15,
      "name": "Soil_Volcanic_Gravel"
    },
    {
      "x": -15,
      "y": 22,
      "z": -15,
      "name": "Rock_Volcanic"
    },
    {
      "x": -15,
      "y": 23,
      "z": -15,
      "name": "Rock_Magma_Cooled_Brick"
    },
    {
      "x": -15,
      "y": 24,
      "z": -15,
      "name": "Rock_Magma_Cooled_Brick_Pillar_Base"
    },
    {
      "x": -15,
      "y": 25,
      "z": -15,
      "name": "Rubble_Magma_Cooled"
    },
    {
      "x": -15,
      "y": 6,
      "z": -14,
      "name": "Rock_Crystal_Red_Medium",
      "rotation": 7
    },
    {
      "x": -15,
      "y": 7,
      "z": -14,
      "name": "Rock_Crystal_Red_Medium",
      "rotation": 7
    },
    {
      "x": -15,
      "y": 8,
      "z": -14,
      "name": "Rock_Crystal_Red_Medium",
      "rotation": 7
    },
    {
      "x": -15,
      "y": 9,
      "z": -14,
      "name": "Rock_Crystal_Red_Block"
    },
    {
      "x": -15,
      "y": 10,
      "z": -14,
      "name": "Rock_Crystal_Red_Block"
    },
    {
      "x": -15,
      "y": 11,
      "z": -14,
      "name": "Soil_Volcanic_Gravel"
    },
    {
      "x": -15,
      "y": 12,
      "z": -14,
      "name": "Rock_Volcanic"
    },
    {
      "x": -15,
      "y": 13,
      "z": -14,
      "name": "Soil_Volcanic_Gravel"
    },
    {
      "x": -15,
      "y": 14,
      "z": -14,
      "name": "Soil_Volcanic_Gravel"
    },
    {
      "x": -15,
      "y": 15,
      "z": -14,
      "name": "Soil_Volcanic_Gravel"
    },
    {
      "x": -15,
      "y": 16,
      "z": -14,
      "name": "Rock_Volcanic"
    },
    {
      "x": -15,
      "y": 17,
      "z": -14,
      "name": "Rock_Volcanic"
    },
    {
      "x": -15,
      "y": 18,
      "z": -14,
      "name": "Rock_Volcanic"
    },
    {
      "x": -15,
      "y": 19,
      "z": -14,
      "name": "Rock_Volcanic"
    },
    {
      "x": -15,
      "y": 20,
      "z": -14,
      "name": "Rock_Volcanic"
    },
    {
      "x": -15,
      "y": 21,
      "z": -14,
      "name": "Soil_Volcanic_Gravel"
    },
    {
      "x": -15,
      "y": 22,
      "z": -14,
      "name": "Rock_Volcanic"
    },
    {
      "x": -15,
      "y": 23,
      "z": -14,
      "name": "Rock_Magma_Cooled_Brick"
    },
    {
      "x": -15,
      "y": 24,
      "z": -14,
      "name": "Rubble_Magma_Cooled"
    },
    {
      "x": -15,
      "y": 9,
      "z": -13,
      "name": "Rock_Crystal_Red_Medium",
      "rotation": 4
    },
    {
      "x": -15,
      "y": 10,
      "z": -13,
      "name": "Rock_Volcanic_Cracked_Lava"
    },
    {
      "x": -15,
      "y": 11,
      "z": -13,
      "name": "Soil_Volcanic_Gravel"
    },
    {
      "x": -15,
      "y": 12,
      "z": -13,
      "name": "Soil_Volcanic_Gravel"
    },
    {
      "x": -15,
      "y": 13,
      "z": -13,
      "name": "Soil_Volcanic_Gravel"
    },
    {
      "x": -15,
      "y": 14,
      "z": -13,
      "name": "Soil_Volcanic_Gravel"
    },
    {
      "x": -15,
      "y": 15,
      "z": -13,
      "name": "Soil_Volcanic_Gravel"
    },
    {
      "x": -15,
      "y": 16,
      "z": -13,
      "name": "Rock_Volcanic"
    },
    {
      "x": -15,
      "y": 17,
      "z": -13,
      "name": "Soil_Volcanic_Gravel"
    },
    {
      "x": -15,
      "y": 18,
      "z": -13,
      "name": "Rock_Volcanic"
    },
    {
      "x": -15,
      "y": 19,
      "z": -13,
      "name": "Rock_Volcanic"
    },
    {
      "x": -15,
      "y": 20,
      "z": -13,
      "name": "Rock_Volcanic"
    },
    {
      "x": -15,
      "y": 21,
      "z": -13,
      "name": "Soil_Volcanic_Gravel"
    },
    {
      "x": -15,
      "y": 22,
      "z": -13,
      "name": "Rock_Volcanic"
    },
    {
      "x": -15,
      "y": 23,
      "z": -13,
      "name": "Rock_Magma_Cooled_Brick"
    },
    {
      "x": -15,
      "y": 24,
      "z": -13,
      "name": "Block_Spawner_Block",
      "components": {
        "Components": {
          "PlacedByInteraction": {
            "WhoPlacedUuid": {
              "$binary": "3XRzOktQTQGfL/+8x7+CHA==",
              "$type": "04"
            }
          },
          "BlockSpawner": {
            "BlockSpawnerId": "Zone4_Encounters_Tier4"
          }
        }
      },
      "rotation": 1
    },
    {
      "x": -15,
      "y": 10,
      "z": -12,
      "name": "Rock_Volcanic"
    },
    {
      "x": -15,
      "y": 11,
      "z": -12,
      "name": "Rock_Volcanic"
    },
    {
      "x": -15,
      "y": 12,
      "z": -12,
      "name": "Soil_Volcanic_Gravel"
    },
    {
      "x": -15,
      "y": 13,
      "z": -12,
      "name": "Rock_Volcanic"
    },
    {
      "x": -15,
      "y": 14,
      "z": -12,
      "name": "Rock_Volcanic"
    },
    {
      "x": -15,
      "y": 15,
      "z": -12,
      "name": "Rock_Volcanic"
    },
    {
      "x": -15,
      "y": 16,
      "z": -12,
      "name": "Soil_Volcanic_Gravel"
    },
    {
      "x": -15,
      "y": 17,
      "z": -12,
      "name": "Rock_Volcanic"
    },
    {
      "x": -15,
      "y": 18,
      "z": -12,
      "name": "Rock_Volcanic"
    },
    {
      "x": -15,
      "y": 19,
      "z": -12,
      "name": "Rock_Volcanic"
    },
    {
      "x": -15,
      "y": 20,
      "z": -12,
      "name": "Rock_Volcanic"
    },
    {
      "x": -15,
      "y": 21,
      "z": -12,
      "name": "Soil_Volcanic_Gravel"
    },
    {
      "x": -15,
      "y": 22,
      "z": -12,
      "name": "Rock_Volcanic"
    },
    {
      "x": -15,
      "y": 23,
      "z": -12,
      "name": "Rock_Magma_Cooled_Brick"
    },
    {
      "x": -15,
      "y": 24,
      "z": -12,
      "name": "Rock_Magma_Cooled_Brick_Pillar_Base"
    },
    {
      "x": -15,
      "y": 25,
      "z": -12,
      "name": "Rock_Magma_Cooled_Brick_Pillar_Middle"
    },
    {
      "x": -15,
      "y": 26,
      "z": -12,
      "name": "Rock_Magma_Cooled_Brick_Pillar_Middle"
    },
    {
      "x": -15,
      "y": 10,
      "z": -11,
      "name": "Plant_Vine_Red_Hanging"
    },
    {
      "x": -15,
      "y": 11,
      "z": -11,
      "name": "Plant_Vine_Red_Hanging"
    },
    {
      "x": -15,
      "y": 12,
      "z": -11,
      "name": "Rock_Volcanic"
    },
    {
      "x": -15,
      "y": 13,
      "z": -11,
      "name": "Rock_Volcanic"
    },
    {
      "x": -15,
      "y": 14,
      "z": -11,
      "name": "Rock_Volcanic"
    },
    {
      "x": -15,
      "y": 15,
      "z": -11,
      "name": "Rock_Volcanic"
    },
    {
      "x": -15,
      "y": 16,
      "z": -11,
      "name": "Rock_Volcanic"
    },
    {
      "x": -15,
      "y": 17,
      "z": -11,
      "name": "Rock_Volcanic"
    },
    {
      "x": -15,
      "y": 18,
      "z": -11,
      "name": "Rock_Volcanic"
    },
    {
      "x": -15,
      "y": 19,
      "z": -11,
      "name": "Rock_Volcanic"
    },
    {
      "x": -15,
      "y": 20,
      "z": -11,
      "name": "Rock_Volcanic"
    },
    {
      "x": -15,
      "y": 21,
      "z": -11,
      "name": "Soil_Volcanic_Gravel"
    },
    {
      "x": -15,
      "y": 22,
      "z": -11,
      "name": "Rock_Volcanic"
    },
    {
      "x": -15,
      "y": 23,
      "z": -11,
      "name": "Soil_Volcanic_Gravel"
    },
    {
      "x": -15,
      "y": 15,
      "z": -10,
      "name": "Rock_Volcanic"
    },
    {
      "x": -15,
      "y": 16,
      "z": -10,
      "name": "Soil_Volcanic_Gravel"
    },
    {
      "x": -15,
      "y": 17,
      "z": -10,
      "name": "Soil_Volcanic_Gravel"
    },
    {
      "x": -15,
      "y": 18,
      "z": -10,
      "name": "Rock_Volcanic"
    },
    {
      "x": -15,
      "y": 19,
      "z": -10,
      "name": "Rock_Volcanic"
    },
    {
      "x": -15,
      "y": 20,
      "z": -10,
      "name": "Rock_Volcanic"
    },
    {
      "x": -15,
      "y": 21,
      "z": -10,
      "name": "Soil_Volcanic_Gravel"
    },
    {
      "x": -15,
      "y": 22,
      "z": -10,
      "name": "Soil_Volcanic_Gravel"
    },
    {
      "x": -15,
      "y": 19,
      "z": -9,
      "name": "Rock_Volcanic_Cracked_Lava"
    },
    {
      "x": -15,
      "y": 20,
      "z": -9,
      "name": "Rock_Volcanic_Cracked_Lava"
    },
    {
      "x": -15,
      "y": 21,
      "z": -9,
      "name": "Rock_Volcanic"
    },
    {
      "x": -15,
      "y": 33,
      "z": 5,
      "name": "Soil_Volcanic_Gravel"
    },
    {
      "x": -15,
      "y": 29,
      "z": 6,
      "name": "Rock_Volcanic"
    },
    {
      "x": -15,
      "y": 30,
      "z": 6,
      "name": "Rock_Volcanic"
    },
    {
      "x": -15,
      "y": 31,
      "z": 6,
      "name": "Rock_Volcanic"
    },
    {
      "x": -15,
      "y": 32,
      "z": 6,
      "name": "Rock_Volcanic"
    },
    {
      "x": -15,
      "y": 33,
      "z": 6,
      "name": "Rock_Volcanic"
    },
    {
      "x": -15,
      "y": 34,
      "z": 6,
      "name": "Rock_Volcanic"
    },
    {
      "x": -15,
      "y": 35,
      "z": 6,
      "name": "Soil_Volcanic_Gravel"
    },
    {
      "x": -15,
      "y": 27,
      "z": 7,
      "name": "Rock_Volcanic"
    },
    {
      "x": -15,
      "y": 28,
      "z": 7,
      "name": "Rock_Volcanic"
    },
    {
      "x": -15,
      "y": 29,
      "z": 7,
      "name": "Rock_Volcanic_Cracked_Lava"
    },
    {
      "x": -15,
      "y": 30,
      "z": 7,
      "name": "Rock_Volcanic"
    },
    {
      "x": -15,
      "y": 31,
      "z": 7,
      "name": "Rock_Volcanic"
    },
    {
      "x": -15,
      "y": 32,
      "z": 7,
      "name": "Rock_Volcanic"
    },
    {
      "x": -15,
      "y": 33,
      "z": 7,
      "name": "Rock_Volcanic"
    },
    {
      "x": -15,
      "y": 34,
      "z": 7,
      "name": "Soil_Volcanic_Gravel"
    },
    {
      "x": -15,
      "y": 35,
      "z": 7,
      "name": "Soil_Volcanic_Gravel"
    },
    {
      "x": -15,
      "y": 36,
      "z": 7,
      "name": "Soil_Volcanic_Gravel"
    },
    {
      "x": -15,
      "y": 26,
      "z": 8,
      "name": "Rock_Volcanic"
    },
    {
      "x": -15,
      "y": 27,
      "z": 8,
      "name": "Rock_Volcanic_Cracked_Lava"
    },
    {
      "x": -15,
      "y": 28,
      "z": 8,
      "name": "Rock_Volcanic"
    },
    {
      "x": -15,
      "y": 29,
      "z": 8,
      "name": "Rock_Volcanic"
    },
    {
      "x": -15,
      "y": 30,
      "z": 8,
      "name": "Rock_Volcanic"
    },
    {
      "x": -15,
      "y": 31,
      "z": 8,
      "name": "Rock_Volcanic"
    },
    {
      "x": -15,
      "y": 32,
      "z": 8,
      "name": "Rock_Volcanic"
    },
    {
      "x": -15,
      "y": 33,
      "z": 8,
      "name": "Soil_Volcanic_Gravel"
    },
    {
      "x": -15,
      "y": 34,
      "z": 8,
      "name": "Rock_Volcanic"
    },
    {
      "x": -15,
      "y": 35,
      "z": 8,
      "name": "Rock_Volcanic"
    },
    {
      "x": -15,
      "y": 36,
      "z": 8,
      "name": "Soil_Volcanic_Gravel"
    },
    {
      "x": -15,
      "y": 37,
      "z": 8,
      "name": "Soil_Volcanic_Gravel"
    },
    {
      "x": -15,
      "y": 22,
      "z": 9,
      "name": "Rock_Crystal_Red_Medium",
      "rotation": 7
    },
    {
      "x": -15,
      "y": 23,
      "z": 9,
      "name": "Rock_Volcanic"
    },
    {
      "x": -15,
      "y": 24,
      "z": 9,
      "name": "Rock_Volcanic"
    },
    {
      "x": -15,
      "y": 25,
      "z": 9,
      "name": "Soil_Volcanic_Gravel"
    },
    {
      "x": -15,
      "y": 26,
      "z": 9,
      "name": "Rock_Volcanic"
    },
    {
      "x": -15,
      "y": 27,
      "z": 9,
      "name": "Rock_Volcanic"
    },
    {
      "x": -15,
      "y": 28,
      "z": 9,
      "name": "Rock_Volcanic"
    },
    {
      "x": -15,
      "y": 29,
      "z": 9,
      "name": "Rock_Volcanic"
    },
    {
      "x": -15,
      "y": 30,
      "z": 9,
      "name": "Rock_Volcanic"
    },
    {
      "x": -15,
      "y": 31,
      "z": 9,
      "name": "Rock_Volcanic"
    },
    {
      "x": -15,
      "y": 32,
      "z": 9,
      "name": "Rock_Volcanic"
    },
    {
      "x": -15,
      "y": 33,
      "z": 9,
      "name": "Rock_Volcanic"
    },
    {
      "x": -15,
      "y": 34,
      "z": 9,
      "name": "Soil_Volcanic_Gravel"
    },
    {
      "x": -15,
      "y": 35,
      "z": 9,
      "name": "Soil_Volcanic_Gravel"
    },
    {
      "x": -15,
      "y": 36,
      "z": 9,
      "name": "Soil_Volcanic_Gravel"
    },
    {
      "x": -15,
      "y": 37,
      "z": 9,
      "name": "Soil_Volcanic_Gravel"
    },
    {
      "x": -15,
      "y": 19,
      "z": 10,
      "name": "Rock_Crystal_Red_Large",
      "rotation": 8
    },
    {
      "x": -15,
      "y": 20,
      "z": 10,
      "name": "Rock_Crystal_Red_Block"
    },
    {
      "x": -15,
      "y": 21,
      "z": 10,
      "name": "Rock_Crystal_Red_Block"
    },
    {
      "x": -15,
      "y": 22,
      "z": 10,
      "name": "Rock_Crystal_Red_Block"
    },
    {
      "x": -15,
      "y": 23,
      "z": 10,
      "name": "Rock_Crystal_Red_Block"
    },
    {
      "x": -15,
      "y": 24,
      "z": 10,
      "name": "Rock_Crystal_Red_Block"
    },
    {
      "x": -15,
      "y": 25,
      "z": 10,
      "name": "Rock_Crystal_Red_Block"
    },
    {
      "x": -15,
      "y": 26,
      "z": 10,
      "name": "Soil_Volcanic_Gravel"
    },
    {
      "x": -15,
      "y": 27,
      "z": 10,
      "name": "Rock_Volcanic"
    },
    {
      "x": -15,
      "y": 28,
      "z": 10,
      "name": "Rock_Volcanic"
    },
    {
      "x": -15,
      "y": 29,
      "z": 10,
      "name": "Rock_Volcanic"
    },
    {
      "x": -15,
      "y": 30,
      "z": 10,
      "name": "Rock_Volcanic"
    },
    {
      "x": -15,
      "y": 31,
      "z": 10,
      "name": "Rock_Volcanic_Cracked_Lava"
    },
    {
      "x": -15,
      "y": 32,
      "z": 10,
      "name": "Rock_Volcanic"
    },
    {
      "x": -15,
      "y": 33,
      "z": 10,
      "name": "Rock_Volcanic"
    },
    {
      "x": -15,
      "y": 34,
      "z": 10,
      "name": "Soil_Volcanic_Gravel"
    },
    {
      "x": -15,
      "y": 35,
      "z": 10,
      "name": "Soil_Volcanic_Gravel"
    },
    {
      "x": -15,
      "y": 36,
      "z": 10,
      "name": "Soil_Volcanic_Gravel"
    },
    {
      "x": -15,
      "y": 37,
      "z": 10,
      "name": "Soil_Volcanic_Gravel"
    },
    {
      "x": -15,
      "y": 38,
      "z": 10,
      "name": "Soil_Volcanic_Gravel"
    },
    {
      "x": -15,
      "y": 20,
      "z": 11,
      "name": "Rock_Crystal_Red_Medium",
      "rotation": 4
    },
    {
      "x": -15,
      "y": 21,
      "z": 11,
      "name": "Rock_Crystal_Red_Medium",
      "rotation": 4
    },
    {
      "x": -15,
      "y": 23,
      "z": 11,
      "name": "Rock_Crystal_Red_Medium",
      "rotation": 7
    },
    {
      "x": -15,
      "y": 24,
      "z": 11,
      "name": "Rock_Volcanic"
    },
    {
      "x": -15,
      "y": 25,
      "z": 11,
      "name": "Rock_Volcanic"
    },
    {
      "x": -15,
      "y": 26,
      "z": 11,
      "name": "Soil_Volcanic_Gravel"
    },
    {
      "x": -15,
      "y": 27,
      "z": 11,
      "name": "Rock_Volcanic"
    },
    {
      "x": -15,
      "y": 28,
      "z": 11,
      "name": "Rock_Volcanic"
    },
    {
      "x": -15,
      "y": 29,
      "z": 11,
      "name": "Rock_Volcanic"
    },
    {
      "x": -15,
      "y": 30,
      "z": 11,
      "name": "Rock_Volcanic"
    },
    {
      "x": -15,
      "y": 31,
      "z": 11,
      "name": "Rock_Volcanic"
    },
    {
      "x": -15,
      "y": 32,
      "z": 11,
      "name": "Rock_Volcanic"
    },
    {
      "x": -15,
      "y": 33,
      "z": 11,
      "name": "Rock_Volcanic"
    },
    {
      "x": -15,
      "y": 34,
      "z": 11,
      "name": "Rock_Volcanic"
    },
    {
      "x": -15,
      "y": 35,
      "z": 11,
      "name": "Soil_Volcanic_Gravel"
    },
    {
      "x": -15,
      "y": 36,
      "z": 11,
      "name": "Soil_Volcanic_Gravel"
    },
    {
      "x": -15,
      "y": 37,
      "z": 11,
      "name": "Soil_Volcanic_Gravel"
    },
    {
      "x": -15,
      "y": 38,
      "z": 11,
      "name": "Soil_Volcanic_Gravel"
    },
    {
      "x": -15,
      "y": 25,
      "z": 12,
      "name": "Rock_Volcanic"
    },
    {
      "x": -15,
      "y": 26,
      "z": 12,
      "name": "Rock_Volcanic_Cracked_Lava"
    },
    {
      "x": -15,
      "y": 27,
      "z": 12,
      "name": "Rock_Volcanic"
    },
    {
      "x": -15,
      "y": 28,
      "z": 12,
      "name": "Rock_Volcanic"
    },
    {
      "x": -15,
      "y": 29,
      "z": 12,
      "name": "Rock_Volcanic_Cracked_Lava"
    },
    {
      "x": -15,
      "y": 30,
      "z": 12,
      "name": "Rock_Volcanic"
    },
    {
      "x": -15,
      "y": 31,
      "z": 12,
      "name": "Rock_Volcanic_Cracked_Lava"
    },
    {
      "x": -15,
      "y": 32,
      "z": 12,
      "name": "Rock_Volcanic"
    },
    {
      "x": -15,
      "y": 33,
      "z": 12,
      "name": "Rock_Volcanic"
    },
    {
      "x": -15,
      "y": 34,
      "z": 12,
      "name": "Soil_Volcanic_Gravel"
    },
    {
      "x": -15,
      "y": 35,
      "z": 12,
      "name": "Soil_Volcanic_Gravel"
    },
    {
      "x": -15,
      "y": 36,
      "z": 12,
      "name": "Soil_Volcanic_Gravel"
    },
    {
      "x": -15,
      "y": 37,
      "z": 12,
      "name": "Soil_Volcanic_Gravel"
    },
    {
      "x": -15,
      "y": 38,
      "z": 12,
      "name": "Soil_Volcanic_Gravel"
    },
    {
      "x": -15,
      "y": 27,
      "z": 13,
      "name": "Rock_Volcanic"
    },
    {
      "x": -15,
      "y": 28,
      "z": 13,
      "name": "Rock_Volcanic"
    },
    {
      "x": -15,
      "y": 29,
      "z": 13,
      "name": "Rock_Volcanic"
    },
    {
      "x": -15,
      "y": 30,
      "z": 13,
      "name": "Rock_Volcanic"
    },
    {
      "x": -15,
      "y": 31,
      "z": 13,
      "name": "Rock_Volcanic"
    },
    {
      "x": -15,
      "y": 32,
      "z": 13,
      "name": "Rock_Volcanic"
    },
    {
      "x": -15,
      "y": 33,
      "z": 13,
      "name": "Rock_Volcanic"
    },
    {
      "x": -15,
      "y": 34,
      "z": 13,
      "name": "Rock_Volcanic"
    },
    {
      "x": -15,
      "y": 35,
      "z": 13,
      "name": "Soil_Volcanic_Gravel"
    },
    {
      "x": -15,
      "y": 36,
      "z": 13,
      "name": "Rock_Volcanic"
    },
    {
      "x": -15,
      "y": 37,
      "z": 13,
      "name": "Soil_Volcanic_Gravel"
    },
    {
      "x": -15,
      "y": 29,
      "z": 14,
      "name": "Rock_Volcanic"
    },
    {
      "x": -15,
      "y": 30,
      "z": 14,
      "name": "Rock_Volcanic"
    },
    {
      "x": -15,
      "y": 31,
      "z": 14,
      "name": "Rock_Volcanic"
    },
    {
      "x": -15,
      "y": 32,
      "z": 14,
      "name": "Rock_Volcanic"
    },
    {
      "x": -15,
      "y": 33,
      "z": 14,
      "name": "Rock_Volcanic"
    },
    {
      "x": -15,
      "y": 34,
      "z": 14,
      "name": "Rock_Volcanic"
    },
    {
      "x": -15,
      "y": 35,
      "z": 14,
      "name": "Rock_Volcanic"
    },
    {
      "x": -15,
      "y": 36,
      "z": 14,
      "name": "Soil_Volcanic_Gravel"
    },
    {
      "x": -15,
      "y": 33,
      "z": 15,
      "name": "Rock_Volcanic"
    },
    {
      "x": -14,
      "y": 18,
      "z": -19,
      "name": "Rock_Volcanic_Cracked_Lava"
    },
    {
      "x": -14,
      "y": 19,
      "z": -19,
      "name": "Rock_Volcanic"
    },
    {
      "x": -14,
      "y": 20,
      "z": -19,
      "name": "Rock_Volcanic_Cracked_Lava"
    },
    {
      "x": -14,
      "y": 21,
      "z": -19,
      "name": "Rock_Volcanic_Cracked_Lava"
    },
    {
      "x": -14,
      "y": 17,
      "z": -18,
      "name": "Rock_Volcanic"
    },
    {
      "x": -14,
      "y": 18,
      "z": -18,
      "name": "Rock_Volcanic"
    },
    {
      "x": -14,
      "y": 19,
      "z": -18,
      "name": "Rock_Volcanic"
    },
    {
      "x": -14,
      "y": 20,
      "z": -18,
      "name": "Rock_Volcanic"
    },
    {
      "x": -14,
      "y": 21,
      "z": -18,
      "name": "Rock_Volcanic"
    },
    {
      "x": -14,
      "y": 17,
      "z": -17,
      "name": "Rock_Volcanic"
    },
    {
      "x": -14,
      "y": 18,
      "z": -17,
      "name": "Rock_Volcanic"
    },
    {
      "x": -14,
      "y": 19,
      "z": -17,
      "name": "Rock_Volcanic"
    },
    {
      "x": -14,
      "y": 20,
      "z": -17,
      "name": "Rock_Volcanic"
    },
    {
      "x": -14,
      "y": 21,
      "z": -17,
      "name": "Rock_Volcanic"
    },
    {
      "x": -14,
      "y": 22,
      "z": -17,
      "name": "Soil_Volcanic_Gravel"
    },
    {
      "x": -14,
      "y": 7,
      "z": -16,
      "name": "Rock_Crystal_Red_Medium",
      "rotation": 6
    },
    {
      "x": -14,
      "y": 8,
      "z": -16,
      "name": "Rock_Crystal_Red_Medium",
      "rotation": 6
    },
    {
      "x": -14,
      "y": 12,
      "z": -16,
      "name": "Rock_Volcanic"
    },
    {
      "x": -14,
      "y": 13,
      "z": -16,
      "name": "Rock_Volcanic"
    },
    {
      "x": -14,
      "y": 14,
      "z": -16,
      "name": "Rock_Volcanic"
    },
    {
      "x": -14,
      "y": 15,
      "z": -16,
      "name": "Soil_Volcanic_Gravel"
    },
    {
      "x": -14,
      "y": 16,
      "z": -16,
      "name": "Rock_Volcanic"
    },
    {
      "x": -14,
      "y": 17,
      "z": -16,
      "name": "Soil_Volcanic_Gravel"
    },
    {
      "x": -14,
      "y": 18,
      "z": -16,
      "name": "Rock_Volcanic"
    },
    {
      "x": -14,
      "y": 19,
      "z": -16,
      "name": "Rock_Volcanic"
    },
    {
      "x": -14,
      "y": 20,
      "z": -16,
      "name": "Rock_Volcanic"
    },
    {
      "x": -14,
      "y": 21,
      "z": -16,
      "name": "Soil_Volcanic_Gravel"
    },
    {
      "x": -14,
      "y": 22,
      "z": -16,
      "name": "Rock_Volcanic"
    },
    {
      "x": -14,
      "y": 23,
      "z": -16,
      "name": "Rock_Volcanic"
    },
    {
      "x": -14,
      "y": 24,
      "z": -16,
      "name": "Rubble_Magma_Cooled"
    },
    {
      "x": -14,
      "y": 6,
      "z": -15,
      "name": "Rock_Crystal_Red_Medium",
      "rotation": 8
    },
    {
      "x": -14,
      "y": 7,
      "z": -15,
      "name": "Rock_Crystal_Red_Block"
    },
    {
      "x": -14,
      "y": 8,
      "z": -15,
      "name": "Rock_Crystal_Red_Block"
    },
    {
      "x": -14,
      "y": 9,
      "z": -15,
      "name": "Rock_Crystal_Red_Block"
    },
    {
      "x": -14,
      "y": 10,
      "z": -15,
      "name": "Rock_Volcanic"
    },
    {
      "x": -14,
      "y": 11,
      "z": -15,
      "name": "Soil_Volcanic_Gravel"
    },
    {
      "x": -14,
      "y": 12,
      "z": -15,
      "name": "Rock_Volcanic"
    },
    {
      "x": -14,
      "y": 13,
      "z": -15,
      "name": "Rock_Volcanic"
    },
    {
      "x": -14,
      "y": 14,
      "z": -15,
      "name": "Rock_Volcanic"
    },
    {
      "x": -14,
      "y": 15,
      "z": -15,
      "name": "Soil_Volcanic_Gravel"
    },
    {
      "x": -14,
      "y": 16,
      "z": -15,
      "name": "Soil_Volcanic_Gravel"
    },
    {
      "x": -14,
      "y": 17,
      "z": -15,
      "name": "Soil_Volcanic_Gravel"
    },
    {
      "x": -14,
      "y": 18,
      "z": -15,
      "name": "Rock_Volcanic"
    },
    {
      "x": -14,
      "y": 19,
      "z": -15,
      "name": "Rock_Volcanic"
    },
    {
      "x": -14,
      "y": 20,
      "z": -15,
      "name": "Soil_Volcanic_Gravel"
    },
    {
      "x": -14,
      "y": 21,
      "z": -15,
      "name": "Soil_Volcanic_Gravel"
    },
    {
      "x": -14,
      "y": 22,
      "z": -15,
      "name": "Soil_Volcanic_Gravel"
    },
    {
      "x": -14,
      "y": 23,
      "z": -15,
      "name": "Rock_Magma_Cooled_Brick"
    },
    {
      "x": -14,
      "y": 24,
      "z": -15,
      "name": "Rock_Magma_Cooled_Brick_Pillar_Middle",
      "rotation": 5
    },
    {
      "x": -14,
      "y": 5,
      "z": -14,
      "name": "Rock_Crystal_Red_Large",
      "rotation": 8
    },
    {
      "x": -14,
      "y": 6,
      "z": -14,
      "name": "Rock_Crystal_Red_Block"
    },
    {
      "x": -14,
      "y": 7,
      "z": -14,
      "name": "Rock_Crystal_Red_Block"
    },
    {
      "x": -14,
      "y": 8,
      "z": -14,
      "name": "Rock_Crystal_Red_Block"
    },
    {
      "x": -14,
      "y": 9,
      "z": -14,
      "name": "Rock_Crystal_Red_Block"
    },
    {
      "x": -14,
      "y": 10,
      "z": -14,
      "name": "Rock_Crystal_Red_Block"
    },
    {
      "x": -14,
      "y": 11,
      "z": -14,
      "name": "Soil_Dirt"
    },
    {
      "x": -14,
      "y": 12,
      "z": -14,
      "name": "Spawn_Labyrinth_Red_Circle"
    },
    {
      "x": -14,
      "y": 13,
      "z": -14,
      "name": "Rock_Volcanic"
    },
    {
      "x": -14,
      "y": 14,
      "z": -14,
      "name": "Rock_Volcanic"
    },
    {
      "x": -14,
      "y": 15,
      "z": -14,
      "name": "Rock_Volcanic"
    },
    {
      "x": -14,
      "y": 16,
      "z": -14,
      "name": "Rock_Volcanic"
    },
    {
      "x": -14,
      "y": 17,
      "z": -14,
      "name": "Rock_Volcanic"
    },
    {
      "x": -14,
      "y": 18,
      "z": -14,
      "name": "Rock_Volcanic"
    },
    {
      "x": -14,
      "y": 19,
      "z": -14,
      "name": "Rock_Volcanic"
    },
    {
      "x": -14,
      "y": 20,
      "z": -14,
      "name": "Soil_Volcanic_Gravel"
    },
    {
      "x": -14,
      "y": 21,
      "z": -14,
      "name": "Rock_Volcanic"
    },
    {
      "x": -14,
      "y": 22,
      "z": -14,
      "name": "Soil_Volcanic_Gravel"
    },
    {
      "x": -14,
      "y": 23,
      "z": -14,
      "name": "Rock_Magma_Cooled_Brick"
    },
    {
      "x": -14,
      "y": 6,
      "z": -13,
      "name": "Rock_Crystal_Red_Medium",
      "rotation": 4
    },
    {
      "x": -14,
      "y": 7,
      "z": -13,
      "name": "Rock_Crystal_Red_Large",
      "rotation": 8
    },
    {
      "x": -14,
      "y": 8,
      "z": -13,
      "name": "Rock_Crystal_Red_Block"
    },
    {
      "x": -14,
      "y": 9,
      "z": -13,
      "name": "Rock_Crystal_Red_Block"
    },
    {
      "x": -14,
      "y": 10,
      "z": -13,
      "name": "Rock_Crystal_Red_Block"
    },
    {
      "x": -14,
      "y": 11,
      "z": -13,
      "name": "Rock_Volcanic"
    },
    {
      "x": -14,
      "y": 12,
      "z": -13,
      "name": "Rock_Volcanic"
    },
    {
      "x": -14,
      "y": 13,
      "z": -13,
      "name": "Rock_Volcanic"
    },
    {
      "x": -14,
      "y": 14,
      "z": -13,
      "name": "Rock_Volcanic"
    },
    {
      "x": -14,
      "y": 15,
      "z": -13,
      "name": "Rock_Volcanic"
    },
    {
      "x": -14,
      "y": 16,
      "z": -13,
      "name": "Rock_Volcanic"
    },
    {
      "x": -14,
      "y": 17,
      "z": -13,
      "name": "Soil_Volcanic_Gravel"
    },
    {
      "x": -14,
      "y": 18,
      "z": -13,
      "name": "Rock_Volcanic"
    },
    {
      "x": -14,
      "y": 19,
      "z": -13,
      "name": "Rock_Volcanic"
    },
    {
      "x": -14,
      "y": 20,
      "z": -13,
      "name": "Soil_Volcanic_Gravel"
    },
    {
      "x": -14,
      "y": 21,
      "z": -13,
      "name": "Rock_Volcanic"
    },
    {
      "x": -14,
      "y": 22,
      "z": -13,
      "name": "Soil_Volcanic_Gravel"
    },
    {
      "x": -14,
      "y": 23,
      "z": -13,
      "name": "Rock_Magma_Cooled_Brick"
    },
    {
      "x": -14,
      "y": 8,
      "z": -12,
      "name": "Rock_Crystal_Red_Medium",
      "rotation": 4
    },
    {
      "x": -14,
      "y": 9,
      "z": -12,
      "name": "Rock_Crystal_Red_Medium",
      "rotation": 4
    },
    {
      "x": -14,
      "y": 10,
      "z": -12,
      "name": "Rock_Volcanic"
    },
    {
      "x": -14,
      "y": 11,
      "z": -12,
      "name": "Rock_Volcanic"
    },
    {
      "x": -14,
      "y": 12,
      "z": -12,
      "name": "Rock_Volcanic"
    },
    {
      "x": -14,
      "y": 13,
      "z": -12,
      "name": "Rock_Volcanic"
    },
    {
      "x": -14,
      "y": 14,
      "z": -12,
      "name": "Rock_Volcanic"
    },
    {
      "x": -14,
      "y": 15,
      "z": -12,
      "name": "Rock_Volcanic"
    },
    {
      "x": -14,
      "y": 16,
      "z": -12,
      "name": "Rock_Volcanic"
    },
    {
      "x": -14,
      "y": 17,
      "z": -12,
      "name": "Rock_Volcanic"
    },
    {
      "x": -14,
      "y": 18,
      "z": -12,
      "name": "Rock_Volcanic"
    },
    {
      "x": -14,
      "y": 19,
      "z": -12,
      "name": "Rock_Volcanic"
    },
    {
      "x": -14,
      "y": 20,
      "z": -12,
      "name": "Rock_Volcanic"
    },
    {
      "x": -14,
      "y": 21,
      "z": -12,
      "name": "Rock_Volcanic"
    },
    {
      "x": -14,
      "y": 22,
      "z": -12,
      "name": "Rock_Volcanic"
    },
    {
      "x": -14,
      "y": 23,
      "z": -12,
      "name": "Rock_Magma_Cooled_Brick"
    },
    {
      "x": -14,
      "y": 13,
      "z": -11,
      "name": "Rock_Volcanic"
    },
    {
      "x": -14,
      "y": 14,
      "z": -11,
      "name": "Rock_Volcanic"
    },
    {
      "x": -14,
      "y": 15,
      "z": -11,
      "name": "Rock_Volcanic"
    },
    {
      "x": -14,
      "y": 16,
      "z": -11,
      "name": "Rock_Volcanic"
    },
    {
      "x": -14,
      "y": 17,
      "z": -11,
      "name": "Rock_Volcanic"
    },
    {
      "x": -14,
      "y": 18,
      "z": -11,
      "name": "Rock_Volcanic"
    },
    {
      "x": -14,
      "y": 19,
      "z": -11,
      "name": "Rock_Volcanic"
    },
    {
      "x": -14,
      "y": 20,
      "z": -11,
      "name": "Soil_Volcanic_Gravel"
    },
    {
      "x": -14,
      "y": 21,
      "z": -11,
      "name": "Rock_Volcanic"
    },
    {
      "x": -14,
      "y": 22,
      "z": -11,
      "name": "Soil_Volcanic_Gravel"
    },
    {
      "x": -14,
      "y": 23,
      "z": -11,
      "name": "Soil_Volcanic_Gravel"
    },
    {
      "x": -14,
      "y": 24,
      "z": -11,
      "name": "Rubble_Magma_Cooled_Medium"
    },
    {
      "x": -14,
      "y": 14,
      "z": -10,
      "name": "Rock_Volcanic"
    },
    {
      "x": -14,
      "y": 15,
      "z": -10,
      "name": "Soil_Volcanic_Gravel"
    },
    {
      "x": -14,
      "y": 16,
      "z": -10,
      "name": "Soil_Volcanic_Gravel"
    },
    {
      "x": -14,
      "y": 17,
      "z": -10,
      "name": "Rock_Volcanic"
    },
    {
      "x": -14,
      "y": 18,
      "z": -10,
      "name": "Soil_Volcanic_Gravel"
    },
    {
      "x": -14,
      "y": 19,
      "z": -10,
      "name": "Rock_Volcanic"
    },
    {
      "x": -14,
      "y": 20,
      "z": -10,
      "name": "Rock_Volcanic"
    },
    {
      "x": -14,
      "y": 21,
      "z": -10,
      "name": "Soil_Volcanic_Gravel"
    },
    {
      "x": -14,
      "y": 22,
      "z": -10,
      "name": "Rock_Volcanic"
    },
    {
      "x": -14,
      "y": 16,
      "z": -9,
      "name": "Plant_Vine_Red_Hanging"
    },
    {
      "x": -14,
      "y": 17,
      "z": -9,
      "name": "Soil_Volcanic_Gravel"
    },
    {
      "x": -14,
      "y": 18,
      "z": -9,
      "name": "Rock_Volcanic"
    },
    {
      "x": -14,
      "y": 19,
      "z": -9,
      "name": "Rock_Volcanic"
    },
    {
      "x": -14,
      "y": 20,
      "z": -9,
      "name": "Rock_Volcanic"
    },
    {
      "x": -14,
      "y": 21,
      "z": -9,
      "name": "Rock_Volcanic_Cracked_Lava"
    },
    {
      "x": -14,
      "y": 32,
      "z": 4,
      "name": "Rock_Volcanic"
    },
    {
      "x": -14,
      "y": 33,
      "z": 4,
      "name": "Soil_Volcanic_Gravel"
    },
    {
      "x": -14,
      "y": 34,
      "z": 4,
      "name": "Soil_Volcanic_Gravel"
    },
    {
      "x": -14,
      "y": 35,
      "z": 4,
      "name": "Plant_Bush_Dead_Twisted"
    },
    {
      "x": -14,
      "y": 31,
      "z": 5,
      "name": "Rock_Volcanic"
    },
    {
      "x": -14,
      "y": 32,
      "z": 5,
      "name": "Rock_Volcanic"
    },
    {
      "x": -14,
      "y": 33,
      "z": 5,
      "name": "Soil_Volcanic_Gravel"
    },
    {
      "x": -14,
      "y": 34,
      "z": 5,
      "name": "Rock_Volcanic"
    },
    {
      "x": -14,
      "y": 35,
      "z": 5,
      "name": "Soil_Volcanic_Gravel"
    },
    {
      "x": -14,
      "y": 29,
      "z": 6,
      "name": "Rock_Volcanic_Cracked_Lava"
    },
    {
      "x": -14,
      "y": 30,
      "z": 6,
      "name": "Rock_Volcanic_Cracked_Lava"
    },
    {
      "x": -14,
      "y": 31,
      "z": 6,
      "name": "Rock_Volcanic"
    },
    {
      "x": -14,
      "y": 32,
      "z": 6,
      "name": "Rock_Volcanic"
    },
    {
      "x": -14,
      "y": 33,
      "z": 6,
      "name": "Soil_Volcanic_Gravel"
    },
    {
      "x": -14,
      "y": 34,
      "z": 6,
      "name": "Rock_Volcanic"
    },
    {
      "x": -14,
      "y": 35,
      "z": 6,
      "name": "Soil_Volcanic_Gravel"
    },
    {
      "x": -14,
      "y": 36,
      "z": 6,
      "name": "Soil_Volcanic_Gravel"
    },
    {
      "x": -14,
      "y": 27,
      "z": 7,
      "name": "Rock_Volcanic"
    },
    {
      "x": -14,
      "y": 28,
      "z": 7,
      "name": "Rock_Volcanic_Cracked_Lava"
    },
    {
      "x": -14,
      "y": 29,
      "z": 7,
      "name": "Rock_Volcanic_Cracked_Lava"
    },
    {
      "x": -14,
      "y": 30,
      "z": 7,
      "name": "Rock_Volcanic_Cracked_Lava"
    },
    {
      "x": -14,
      "y": 31,
      "z": 7,
      "name": "Rock_Volcanic"
    },
    {
      "x": -14,
      "y": 32,
      "z": 7,
      "name": "Rock_Volcanic"
    },
    {
      "x": -14,
      "y": 33,
      "z": 7,
      "name": "Soil_Volcanic_Gravel"
    },
    {
      "x": -14,
      "y": 34,
      "z": 7,
      "name": "Soil_Volcanic_Gravel"
    },
    {
      "x": -14,
      "y": 35,
      "z": 7,
      "name": "Rock_Volcanic"
    },
    {
      "x": -14,
      "y": 36,
      "z": 7,
      "name": "Rock_Magma_Cooled"
    },
    {
      "x": -14,
      "y": 22,
      "z": 8,
      "name": "Rock_Crystal_Red_Medium",
      "rotation": 6
    },
    {
      "x": -14,
      "y": 23,
      "z": 8,
      "name": "Rock_Volcanic"
    },
    {
      "x": -14,
      "y": 24,
      "z": 8,
      "name": "Rock_Volcanic"
    },
    {
      "x": -14,
      "y": 25,
      "z": 8,
      "name": "Rock_Volcanic"
    },
    {
      "x": -14,
      "y": 26,
      "z": 8,
      "name": "Rock_Volcanic"
    },
    {
      "x": -14,
      "y": 27,
      "z": 8,
      "name": "Rock_Volcanic_Cracked_Lava"
    },
    {
      "x": -14,
      "y": 28,
      "z": 8,
      "name": "Rock_Volcanic_Cracked_Lava"
    },
    {
      "x": -14,
      "y": 29,
      "z": 8,
      "name": "Rock_Volcanic_Cracked_Lava"
    },
    {
      "x": -14,
      "y": 30,
      "z": 8,
      "name": "Rock_Volcanic_Cracked_Lava"
    },
    {
      "x": -14,
      "y": 31,
      "z": 8,
      "name": "Rock_Volcanic_Cracked_Lava"
    },
    {
      "x": -14,
      "y": 32,
      "z": 8,
      "name": "Rock_Volcanic"
    },
    {
      "x": -14,
      "y": 33,
      "z": 8,
      "name": "Rock_Volcanic"
    },
    {
      "x": -14,
      "y": 34,
      "z": 8,
      "name": "Rock_Volcanic"
    },
    {
      "x": -14,
      "y": 35,
      "z": 8,
      "name": "Ore_Adamantite_Magma_Cracked"
    },
    {
      "x": -14,
      "y": 36,
      "z": 8,
      "name": "Rock_Magma_Cooled"
    },
    {
      "x": -14,
      "y": 37,
      "z": 8,
      "name": "Rock_Magma_Cooled"
    },
    {
      "x": -14,
      "y": 18,
      "z": 9,
      "name": "Rock_Crystal_Red_Large",
      "rotation": 8
    },
    {
      "x": -14,
      "y": 19,
      "z": 9,
      "name": "Rock_Crystal_Red_Block"
    },
    {
      "x": -14,
      "y": 20,
      "z": 9,
      "name": "Rock_Crystal_Red_Block"
    },
    {
      "x": -14,
      "y": 21,
      "z": 9,
      "name": "Rock_Crystal_Red_Block"
    },
    {
      "x": -14,
      "y": 22,
      "z": 9,
      "name": "Rock_Crystal_Red_Block"
    },
    {
      "x": -14,
      "y": 23,
      "z": 9,
      "name": "Rock_Crystal_Red_Block"
    },
    {
      "x": -14,
      "y": 24,
      "z": 9,
      "name": "Soil_Volcanic_Gravel"
    },
    {
      "x": -14,
      "y": 25,
      "z": 9,
      "name": "Soil_Volcanic_Gravel"
    },
    {
      "x": -14,
      "y": 26,
      "z": 9,
      "name": "Rock_Volcanic"
    },
    {
      "x": -14,
      "y": 27,
      "z": 9,
      "name": "Rock_Volcanic"
    },
    {
      "x": -14,
      "y": 28,
      "z": 9,
      "name": "Rock_Volcanic"
    },
    {
      "x": -14,
      "y": 29,
      "z": 9,
      "name": "Rock_Volcanic_Cracked_Lava"
    },
    {
      "x": -14,
      "y": 30,
      "z": 9,
      "name": "Rock_Volcanic"
    },
    {
      "x": -14,
      "y": 31,
      "z": 9,
      "name": "Rock_Volcanic_Cracked_Lava"
    },
    {
      "x": -14,
      "y": 32,
      "z": 9,
      "name": "Rock_Volcanic"
    },
    {
      "x": -14,
      "y": 33,
      "z": 9,
      "name": "Soil_Volcanic_Gravel"
    },
    {
      "x": -14,
      "y": 34,
      "z": 9,
      "name": "Soil_Volcanic_Gravel"
    },
    {
      "x": -14,
      "y": 35,
      "z": 9,
      "name": "Soil_Volcanic_Gravel"
    },
    {
      "x": -14,
      "y": 36,
      "z": 9,
      "name": "Rock_Volcanic"
    },
    {
      "x": -14,
      "y": 37,
      "z": 9,
      "name": "Soil_Volcanic_Gravel"
    },
    {
      "x": -14,
      "y": 38,
      "z": 9,
      "name": "Soil_Volcanic_Gravel"
    },
    {
      "x": -14,
      "y": 17,
      "z": 10,
      "name": "Rock_Crystal_Red_Large",
      "rotation": 8
    },
    {
      "x": -14,
      "y": 18,
      "z": 10,
      "name": "Rock_Crystal_Red_Block"
    },
    {
      "x": -14,
      "y": 19,
      "z": 10,
      "name": "Rock_Crystal_Red_Block"
    },
    {
      "x": -14,
      "y": 20,
      "z": 10,
      "name": "Rock_Crystal_Red_Block"
    },
    {
      "x": -14,
      "y": 21,
      "z": 10,
      "name": "Rock_Crystal_Red_Block"
    },
    {
      "x": -14,
      "y": 22,
      "z": 10,
      "name": "Rock_Crystal_Red_Block"
    },
    {
      "x": -14,
      "y": 23,
      "z": 10,
      "name": "Rock_Crystal_Red_Block"
    },
    {
      "x": -14,
      "y": 24,
      "z": 10,
      "name": "Rock_Crystal_Red_Block"
    },
    {
      "x": -14,
      "y": 25,
      "z": 10,
      "name": "Rock_Crystal_Red_Block"
    },
    {
      "x": -14,
      "y": 26,
      "z": 10,
      "name": "Rock_Crystal_Red_Block"
    },
    {
      "x": -14,
      "y": 27,
      "z": 10,
      "name": "Rock_Crystal_Red_Block"
    },
    {
      "x": -14,
      "y": 28,
      "z": 10,
      "name": "Rock_Crystal_Red_Block"
    },
    {
      "x": -14,
      "y": 29,
      "z": 10,
      "name": "Rock_Volcanic"
    },
    {
      "x": -14,
      "y": 30,
      "z": 10,
      "name": "Rock_Volcanic"
    },
    {
      "x": -14,
      "y": 31,
      "z": 10,
      "name": "Rock_Volcanic"
    },
    {
      "x": -14,
      "y": 32,
      "z": 10,
      "name": "Rock_Volcanic_Cracked_Lava"
    },
    {
      "x": -14,
      "y": 33,
      "z": 10,
      "name": "Rock_Volcanic"
    },
    {
      "x": -14,
      "y": 34,
      "z": 10,
      "name": "Soil_Volcanic_Gravel"
    },
    {
      "x": -14,
      "y": 35,
      "z": 10,
      "name": "Soil_Volcanic_Gravel"
    },
    {
      "x": -14,
      "y": 36,
      "z": 10,
      "name": "Soil_Volcanic_Gravel"
    },
    {
      "x": -14,
      "y": 37,
      "z": 10,
      "name": "Soil_Volcanic_Gravel"
    },
    {
      "x": -14,
      "y": 38,
      "z": 10,
      "name": "Soil_Volcanic_Gravel"
    },
    {
      "x": -14,
      "y": 39,
      "z": 10,
      "name": "Plant_Bramble_Dead_Lavathorn"
    },
    {
      "x": -14,
      "y": 18,
      "z": 11,
      "name": "Rock_Crystal_Red_Medium",
      "rotation": 4
    },
    {
      "x": -14,
      "y": 19,
      "z": 11,
      "name": "Rock_Crystal_Red_Medium",
      "rotation": 4
    },
    {
      "x": -14,
      "y": 20,
      "z": 11,
      "name": "Rock_Crystal_Red_Medium",
      "rotation": 8
    },
    {
      "x": -14,
      "y": 21,
      "z": 11,
      "name": "Rock_Crystal_Red_Block"
    },
    {
      "x": -14,
      "y": 22,
      "z": 11,
      "name": "Rock_Crystal_Red_Block"
    },
    {
      "x": -14,
      "y": 23,
      "z": 11,
      "name": "Rock_Crystal_Red_Block"
    },
    {
      "x": -14,
      "y": 24,
      "z": 11,
      "name": "Rock_Crystal_Red_Block"
    },
    {
      "x": -14,
      "y": 25,
      "z": 11,
      "name": "Rock_Crystal_Red_Block"
    },
    {
      "x": -14,
      "y": 26,
      "z": 11,
      "name": "Rock_Volcanic"
    },
    {
      "x": -14,
      "y": 27,
      "z": 11,
      "name": "Rock_Volcanic"
    },
    {
      "x": -14,
      "y": 28,
      "z": 11,
      "name": "Rock_Volcanic_Cracked_Lava"
    },
    {
      "x": -14,
      "y": 29,
      "z": 11,
      "name": "Rock_Volcanic_Cracked_Lava"
    },
    {
      "x": -14,
      "y": 30,
      "z": 11,
      "name": "Rock_Volcanic"
    },
    {
      "x": -14,
      "y": 31,
      "z": 11,
      "name": "Rock_Volcanic"
    },
    {
      "x": -14,
      "y": 32,
      "z": 11,
      "name": "Rock_Volcanic"
    },
    {
      "x": -14,
      "y": 33,
      "z": 11,
      "name": "Rock_Volcanic"
    },
    {
      "x": -14,
      "y": 34,
      "z": 11,
      "name": "Rock_Volcanic"
    },
    {
      "x": -14,
      "y": 35,
      "z": 11,
      "name": "Soil_Volcanic_Gravel"
    },
    {
      "x": -14,
      "y": 36,
      "z": 11,
      "name": "Soil_Volcanic_Gravel"
    },
    {
      "x": -14,
      "y": 37,
      "z": 11,
      "name": "Soil_Volcanic_Gravel"
    },
    {
      "x": -14,
      "y": 38,
      "z": 11,
      "name": "Soil_Volcanic_Gravel"
    },
    {
      "x": -14,
      "y": 39,
      "z": 11,
      "name": "Rubble_Volcanic"
    },
    {
      "x": -14,
      "y": 21,
      "z": 12,
      "name": "Rock_Crystal_Red_Medium",
      "rotation": 4
    },
    {
      "x": -14,
      "y": 22,
      "z": 12,
      "name": "Rock_Crystal_Red_Medium",
      "rotation": 4
    },
    {
      "x": -14,
      "y": 24,
      "z": 12,
      "name": "Rock_Volcanic"
    },
    {
      "x": -14,
      "y": 25,
      "z": 12,
      "name": "Rock_Volcanic"
    },
    {
      "x": -14,
      "y": 26,
      "z": 12,
      "name": "Rock_Volcanic"
    },
    {
      "x": -14,
      "y": 27,
      "z": 12,
      "name": "Rock_Volcanic"
    },
    {
      "x": -14,
      "y": 28,
      "z": 12,
      "name": "Rock_Volcanic_Cracked_Lava"
    },
    {
      "x": -14,
      "y": 29,
      "z": 12,
      "name": "Rock_Volcanic"
    },
    {
      "x": -14,
      "y": 30,
      "z": 12,
      "name": "Rock_Volcanic_Cracked_Lava"
    },
    {
      "x": -14,
      "y": 31,
      "z": 12,
      "name": "Rock_Volcanic"
    },
    {
      "x": -14,
      "y": 32,
      "z": 12,
      "name": "Rock_Volcanic"
    },
    {
      "x": -14,
      "y": 33,
      "z": 12,
      "name": "Rock_Volcanic"
    },
    {
      "x": -14,
      "y": 34,
      "z": 12,
      "name": "Soil_Volcanic_Gravel"
    },
    {
      "x": -14,
      "y": 35,
      "z": 12,
      "name": "Soil_Volcanic_Gravel"
    },
    {
      "x": -14,
      "y": 36,
      "z": 12,
      "name": "Soil_Volcanic_Gravel"
    },
    {
      "x": -14,
      "y": 37,
      "z": 12,
      "name": "Soil_Volcanic_Gravel"
    },
    {
      "x": -14,
      "y": 38,
      "z": 12,
      "name": "Soil_Volcanic_Gravel"
    },
    {
      "x": -14,
      "y": 27,
      "z": 13,
      "name": "Rock_Volcanic"
    },
    {
      "x": -14,
      "y": 28,
      "z": 13,
      "name": "Rock_Volcanic"
    },
    {
      "x": -14,
      "y": 29,
      "z": 13,
      "name": "Rock_Volcanic"
    },
    {
      "x": -14,
      "y": 30,
      "z": 13,
      "name": "Rock_Volcanic"
    },
    {
      "x": -14,
      "y": 31,
      "z": 13,
      "name": "Rock_Volcanic"
    },
    {
      "x": -14,
      "y": 32,
      "z": 13,
      "name": "Rock_Volcanic"
    },
    {
      "x": -14,
      "y": 33,
      "z": 13,
      "name": "Rock_Volcanic"
    },
    {
      "x": -14,
      "y": 34,
      "z": 13,
      "name": "Rock_Volcanic"
    },
    {
      "x": -14,
      "y": 35,
      "z": 13,
      "name": "Soil_Volcanic_Gravel"
    },
    {
      "x": -14,
      "y": 36,
      "z": 13,
      "name": "Soil_Volcanic_Gravel"
    },
    {
      "x": -14,
      "y": 37,
      "z": 13,
      "name": "Soil_Volcanic_Gravel"
    },
    {
      "x": -14,
      "y": 25,
      "z": 14,
      "name": "Rock_Volcanic"
    },
    {
      "x": -14,
      "y": 26,
      "z": 14,
      "name": "Rock_Volcanic_Cracked_Lava"
    },
    {
      "x": -14,
      "y": 27,
      "z": 14,
      "name": "Rock_Volcanic_Cracked_Lava"
    },
    {
      "x": -14,
      "y": 28,
      "z": 14,
      "name": "Rock_Volcanic_Cracked_Lava"
    },
    {
      "x": -14,
      "y": 29,
      "z": 14,
      "name": "Rock_Volcanic"
    },
    {
      "x": -14,
      "y": 30,
      "z": 14,
      "name": "Rock_Volcanic"
    },
    {
      "x": -14,
      "y": 31,
      "z": 14,
      "name": "Rock_Volcanic"
    },
    {
      "x": -14,
      "y": 32,
      "z": 14,
      "name": "Rock_Volcanic"
    },
    {
      "x": -14,
      "y": 33,
      "z": 14,
      "name": "Rock_Volcanic"
    },
    {
      "x": -14,
      "y": 34,
      "z": 14,
      "name": "Rock_Volcanic"
    },
    {
      "x": -14,
      "y": 35,
      "z": 14,
      "name": "Soil_Volcanic_Gravel"
    },
    {
      "x": -14,
      "y": 36,
      "z": 14,
      "name": "Soil_Volcanic_Gravel"
    },
    {
      "x": -14,
      "y": 25,
      "z": 15,
      "name": "Plant_Moss_Cave_Red",
      "rotation": 8
    },
    {
      "x": -14,
      "y": 26,
      "z": 15,
      "name": "Rock_Volcanic"
    },
    {
      "x": -14,
      "y": 27,
      "z": 15,
      "name": "Rock_Volcanic_Cracked_Lava"
    },
    {
      "x": -14,
      "y": 28,
      "z": 15,
      "name": "Rock_Volcanic"
    },
    {
      "x": -14,
      "y": 29,
      "z": 15,
      "name": "Rock_Volcanic_Cracked_Lava"
    },
    {
      "x": -14,
      "y": 30,
      "z": 15,
      "name": "Rock_Volcanic"
    },
    {
      "x": -14,
      "y": 31,
      "z": 15,
      "name": "Rock_Volcanic"
    },
    {
      "x": -14,
      "y": 32,
      "z": 15,
      "name": "Rock_Volcanic"
    },
    {
      "x": -14,
      "y": 33,
      "z": 15,
      "name": "Rock_Volcanic"
    },
    {
      "x": -14,
      "y": 34,
      "z": 15,
      "name": "Rock_Volcanic"
    },
    {
      "x": -14,
      "y": 35,
      "z": 15,
      "name": "Soil_Volcanic_Gravel"
    },
    {
      "x": -14,
      "y": 29,
      "z": 16,
      "name": "Rock_Volcanic"
    },
    {
      "x": -14,
      "y": 30,
      "z": 16,
      "name": "Rock_Volcanic_Cracked_Lava"
    },
    {
      "x": -13,
      "y": 19,
      "z": -19,
      "name": "Rock_Volcanic"
    },
    {
      "x": -13,
      "y": 20,
      "z": -19,
      "name": "Rock_Volcanic"
    },
    {
      "x": -13,
      "y": 21,
      "z": -19,
      "name": "Rock_Volcanic_Cracked_Lava"
    },
    {
      "x": -13,
      "y": 15,
      "z": -18,
      "name": "Rock_Volcanic"
    },
    {
      "x": -13,
      "y": 16,
      "z": -18,
      "name": "Rock_Volcanic"
    },
    {
      "x": -13,
      "y": 17,
      "z": -18,
      "name": "Rock_Volcanic"
    },
    {
      "x": -13,
      "y": 18,
      "z": -18,
      "name": "Rock_Volcanic"
    },
    {
      "x": -13,
      "y": 19,
      "z": -18,
      "name": "Rock_Volcanic"
    },
    {
      "x": -13,
      "y": 20,
      "z": -18,
      "name": "Rock_Volcanic"
    },
    {
      "x": -13,
      "y": 21,
      "z": -18,
      "name": "Rock_Volcanic"
    },
    {
      "x": -13,
      "y": 22,
      "z": -18,
      "name": "Rock_Volcanic"
    },
    {
      "x": -13,
      "y": 14,
      "z": -17,
      "name": "Rock_Volcanic"
    },
    {
      "x": -13,
      "y": 15,
      "z": -17,
      "name": "Soil_Volcanic_Gravel"
    },
    {
      "x": -13,
      "y": 16,
      "z": -17,
      "name": "Soil_Volcanic_Gravel"
    },
    {
      "x": -13,
      "y": 17,
      "z": -17,
      "name": "Soil_Volcanic_Gravel"
    },
    {
      "x": -13,
      "y": 18,
      "z": -17,
      "name": "Rock_Volcanic"
    },
    {
      "x": -13,
      "y": 19,
      "z": -17,
      "name": "Rock_Volcanic"
    },
    {
      "x": -13,
      "y": 20,
      "z": -17,
      "name": "Rock_Volcanic"
    },
    {
      "x": -13,
      "y": 21,
      "z": -17,
      "name": "Soil_Volcanic_Gravel"
    },
    {
      "x": -13,
      "y": 22,
      "z": -17,
      "name": "Soil_Volcanic_Gravel"
    },
    {
      "x": -13,
      "y": 23,
      "z": -17,
      "name": "Plant_Bramble_Dead_Lavathorn"
    },
    {
      "x": -13,
      "y": 11,
      "z": -16,
      "name": "Rock_Volcanic"
    },
    {
      "x": -13,
      "y": 12,
      "z": -16,
      "name": "Rock_Volcanic"
    },
    {
      "x": -13,
      "y": 13,
      "z": -16,
      "name": "Soil_Volcanic_Gravel"
    },
    {
      "x": -13,
      "y": 14,
      "z": -16,
      "name": "Rock_Volcanic"
    },
    {
      "x": -13,
      "y": 15,
      "z": -16,
      "name": "Soil_Volcanic_Gravel"
    },
    {
      "x": -13,
      "y": 16,
      "z": -16,
      "name": "Soil_Volcanic_Gravel"
    },
    {
      "x": -13,
      "y": 17,
      "z": -16,
      "name": "Rock_Volcanic"
    },
    {
      "x": -13,
      "y": 18,
      "z": -16,
      "name": "Rock_Volcanic"
    },
    {
      "x": -13,
      "y": 19,
      "z": -16,
      "name": "Rock_Volcanic"
    },
    {
      "x": -13,
      "y": 20,
      "z": -16,
      "name": "Rock_Volcanic"
    },
    {
      "x": -13,
      "y": 21,
      "z": -16,
      "name": "Rock_Volcanic"
    },
    {
      "x": -13,
      "y": 22,
      "z": -16,
      "name": "Rock_Volcanic"
    },
    {
      "x": -13,
      "y": 7,
      "z": -15,
      "name": "Rock_Crystal_Red_Medium",
      "rotation": 6
    },
    {
      "x": -13,
      "y": 8,
      "z": -15,
      "name": "Rock_Crystal_Red_Medium",
      "rotation": 5
    },
    {
      "x": -13,
      "y": 9,
      "z": -15,
      "name": "Rock_Crystal_Red_Medium",
      "rotation": 5
    },
    {
      "x": -13,
      "y": 10,
      "z": -15,
      "name": "Rock_Volcanic"
    },
    {
      "x": -13,
      "y": 11,
      "z": -15,
      "name": "Rock_Volcanic"
    },
    {
      "x": -13,
      "y": 12,
      "z": -15,
      "name": "Rock_Volcanic"
    },
    {
      "x": -13,
      "y": 13,
      "z": -15,
      "name": "Rock_Volcanic"
    },
    {
      "x": -13,
      "y": 18,
      "z": -15,
      "name": "Rock_Volcanic"
    },
    {
      "x": -13,
      "y": 19,
      "z": -15,
      "name": "Rock_Volcanic"
    },
    {
      "x": -13,
      "y": 20,
      "z": -15,
      "name": "Rock_Volcanic"
    },
    {
      "x": -13,
      "y": 21,
      "z": -15,
      "name": "Soil_Volcanic_Gravel"
    },
    {
      "x": -13,
      "y": 22,
      "z": -15,
      "name": "Rock_Volcanic"
    },
    {
      "x": -13,
      "y": 23,
      "z": -15,
      "name": "Rock_Magma_Cooled_Brick"
    },
    {
      "x": -13,
      "y": 6,
      "z": -14,
      "name": "Rock_Crystal_Red_Large",
      "rotation": 8
    },
    {
      "x": -13,
      "y": 7,
      "z": -14,
      "name": "Rock_Crystal_Red_Block"
    },
    {
      "x": -13,
      "y": 8,
      "z": -14,
      "name": "Rock_Crystal_Red_Block"
    },
    {
      "x": -13,
      "y": 9,
      "z": -14,
      "name": "Rock_Crystal_Red_Block"
    },
    {
      "x": -13,
      "y": 10,
      "z": -14,
      "name": "Rock_Crystal_Red_Block"
    },
    {
      "x": -13,
      "y": 11,
      "z": -14,
      "name": "Soil_Volcanic_Gravel"
    },
    {
      "x": -13,
      "y": 12,
      "z": -14,
      "name": "Rock_Volcanic"
    },
    {
      "x": -13,
      "y": 13,
      "z": -14,
      "name": "Soil_Volcanic_Gravel"
    },
    {
      "x": -13,
      "y": 14,
      "z": -14,
      "name": "Soil_Volcanic_Gravel"
    },
    {
      "x": -13,
      "y": 15,
      "z": -14,
      "name": "Soil_Volcanic_Gravel"
    },
    {
      "x": -13,
      "y": 16,
      "z": -14,
      "name": "Soil_Volcanic_Gravel"
    },
    {
      "x": -13,
      "y": 17,
      "z": -14,
      "name": "Soil_Volcanic_Gravel"
    },
    {
      "x": -13,
      "y": 18,
      "z": -14,
      "name": "Rock_Volcanic"
    },
    {
      "x": -13,
      "y": 19,
      "z": -14,
      "name": "Rock_Volcanic"
    },
    {
      "x": -13,
      "y": 20,
      "z": -14,
      "name": "Soil_Volcanic_Gravel"
    },
    {
      "x": -13,
      "y": 21,
      "z": -14,
      "name": "Rock_Volcanic"
    },
    {
      "x": -13,
      "y": 22,
      "z": -14,
      "name": "Rock_Volcanic"
    },
    {
      "x": -13,
      "y": 23,
      "z": -14,
      "name": "Rock_Magma_Cooled_Brick"
    },
    {
      "x": -13,
      "y": 8,
      "z": -13,
      "name": "Rock_Crystal_Red_Medium",
      "rotation": 5
    },
    {
      "x": -13,
      "y": 10,
      "z": -13,
      "name": "Rock_Volcanic"
    },
    {
      "x": -13,
      "y": 11,
      "z": -13,
      "name": "Rock_Volcanic"
    },
    {
      "x": -13,
      "y": 12,
      "z": -13,
      "name": "Rock_Volcanic"
    },
    {
      "x": -13,
      "y": 13,
      "z": -13,
      "name": "Rock_Volcanic"
    },
    {
      "x": -13,
      "y": 14,
      "z": -13,
      "name": "Rock_Volcanic"
    },
    {
      "x": -13,
      "y": 16,
      "z": -13,
      "name": "Rock_Volcanic"
    },
    {
      "x": -13,
      "y": 17,
      "z": -13,
      "name": "Soil_Volcanic_Gravel"
    },
    {
      "x": -13,
      "y": 18,
      "z": -13,
      "name": "Soil_Volcanic_Gravel"
    },
    {
      "x": -13,
      "y": 19,
      "z": -13,
      "name": "Rock_Volcanic"
    },
    {
      "x": -13,
      "y": 20,
      "z": -13,
      "name": "Rock_Volcanic"
    },
    {
      "x": -13,
      "y": 21,
      "z": -13,
      "name": "Soil_Volcanic_Gravel"
    },
    {
      "x": -13,
      "y": 22,
      "z": -13,
      "name": "Rock_Volcanic"
    },
    {
      "x": -13,
      "y": 23,
      "z": -13,
      "name": "Rock_Magma_Cooled_Brick"
    },
    {
      "x": -13,
      "y": 9,
      "z": -12,
      "name": "Rock_Volcanic_Stalactite_Small",
      "rotation": 8
    },
    {
      "x": -13,
      "y": 10,
      "z": -12,
      "name": "Rock_Volcanic"
    },
    {
      "x": -13,
      "y": 11,
      "z": -12,
      "name": "Soil_Volcanic_Gravel"
    },
    {
      "x": -13,
      "y": 12,
      "z": -12,
      "name": "Soil_Volcanic_Gravel"
    },
    {
      "x": -13,
      "y": 13,
      "z": -12,
      "name": "Rock_Volcanic"
    },
    {
      "x": -13,
      "y": 14,
      "z": -12,
      "name": "Soil_Volcanic_Gravel"
    },
    {
      "x": -13,
      "y": 15,
      "z": -12,
      "name": "Rock_Volcanic"
    },
    {
      "x": -13,
      "y": 16,
      "z": -12,
      "name": "Rock_Volcanic"
    },
    {
      "x": -13,
      "y": 17,
      "z": -12,
      "name": "Soil_Volcanic_Gravel"
    },
    {
      "x": -13,
      "y": 18,
      "z": -12,
      "name": "Rock_Volcanic"
    },
    {
      "x": -13,
      "y": 19,
      "z": -12,
      "name": "Rock_Volcanic"
    },
    {
      "x": -13,
      "y": 20,
      "z": -12,
      "name": "Rock_Volcanic"
    },
    {
      "x": -13,
      "y": 21,
      "z": -12,
      "name": "Soil_Volcanic_Gravel"
    },
    {
      "x": -13,
      "y": 22,
      "z": -12,
      "name": "Rock_Volcanic"
    },
    {
      "x": -13,
      "y": 23,
      "z": -12,
      "name": "Rock_Magma_Cooled_Brick"
    },
    {
      "x": -13,
      "y": 12,
      "z": -11,
      "name": "Rock_Volcanic"
    },
    {
      "x": -13,
      "y": 13,
      "z": -11,
      "name": "Rock_Volcanic"
    },
    {
      "x": -13,
      "y": 14,
      "z": -11,
      "name": "Soil_Volcanic_Gravel"
    },
    {
      "x": -13,
      "y": 15,
      "z": -11,
      "name": "Soil_Volcanic_Gravel"
    },
    {
      "x": -13,
      "y": 16,
      "z": -11,
