{
  "version": 8,
  "blockIdVersion": 11,
  "anchorX": 0,
  "anchorY": 0,
  "anchorZ": 0,
  "blocks": [
    {
      "x": -20,
      "y": 14,
      "z": -1,
      "name": "Rock_Stone_Stalactite_Large",
      "filler": 31744,
      "rotation": 8
    },
    {
      "x": -20,
      "y": 15,
      "z": -1,
      "name": "Rock_Stone_Stalactite_Large",
      "rotation": 8
    },
    {
      "x": -20,
      "y": 16,
      "z": -1,
      "name": "Rock_Stone"
    },
    {
      "x": -20,
      "y": 17,
      "z": -1,
      "name": "Rock_Stone"
    },
    {
      "x": -20,
      "y": 18,
      "z": -1,
      "name": "Rock_Stone"
    },
    {
      "x": -20,
      "y": 19,
      "z": -1,
      "name": "Rock_Stone"
    },
    {
      "x": -20,
      "y": 13,
      "z": 0,
      "name": "Rock_Stone_Stalactite_Large",
      "filler": 31744,
      "rotation": 8
    },
    {
      "x": -20,
      "y": 14,
      "z": 0,
      "name": "Rock_Stone_Stalactite_Large",
      "rotation": 8
    },
    {
      "x": -20,
      "y": 15,
      "z": 0,
      "name": "Rock_Stone"
    },
    {
      "x": -20,
      "y": 16,
      "z": 0,
      "name": "Rock_Stone"
    },
    {
      "x": -20,
      "y": 17,
      "z": 0,
      "name": "Rock_Stone"
    },
    {
      "x": -20,
      "y": 18,
      "z": 0,
      "name": "Rock_Stone"
    },
    {
      "x": -20,
      "y": 19,
      "z": 0,
      "name": "Rock_Stone"
    },
    {
      "x": -20,
      "y": 16,
      "z": 1,
      "name": "Rock_Stone"
    },
    {
      "x": -20,
      "y": 17,
      "z": 1,
      "name": "Rock_Stone"
    },
    {
      "x": -20,
      "y": 18,
      "z": 1,
      "name": "Rock_Stone"
    },
    {
      "x": -20,
      "y": 19,
      "z": 1,
      "name": "Rock_Stone"
    },
    {
      "x": -19,
      "y": 15,
      "z": -5,
      "name": "Rock_Stone_Stalactite_Small",
      "rotation": 8
    },
    {
      "x": -19,
      "y": 16,
      "z": -5,
      "name": "Rock_Stone"
    },
    {
      "x": -19,
      "y": 17,
      "z": -5,
      "name": "Rock_Stone"
    },
    {
      "x": -19,
      "y": 18,
      "z": -5,
      "name": "Rock_Stone"
    },
    {
      "x": -19,
      "y": 14,
      "z": -4,
      "name": "Rock_Stone_Stalactite_Small",
      "rotation": 8
    },
    {
      "x": -19,
      "y": 15,
      "z": -4,
      "name": "Rock_Stone"
    },
    {
      "x": -19,
      "y": 16,
      "z": -4,
      "name": "Rock_Stone"
    },
    {
      "x": -19,
      "y": 17,
      "z": -4,
      "name": "Rock_Stone"
    },
    {
      "x": -19,
      "y": 18,
      "z": -4,
      "name": "Soil_Gravel"
    },
    {
      "x": -19,
      "y": 16,
      "z": -3,
      "name": "Rock_Stone"
    },
    {
      "x": -19,
      "y": 17,
      "z": -3,
      "name": "Rock_Stone"
    },
    {
      "x": -19,
      "y": 18,
      "z": -3,
      "name": "Rock_Stone"
    },
    {
      "x": -19,
      "y": 19,
      "z": -3,
      "name": "Soil_Gravel"
    },
    {
      "x": -19,
      "y": 14,
      "z": -2,
      "name": "Rock_Stone"
    },
    {
      "x": -19,
      "y": 15,
      "z": -2,
      "name": "Rock_Stone"
    },
    {
      "x": -19,
      "y": 16,
      "z": -2,
      "name": "Rock_Stone"
    },
    {
      "x": -19,
      "y": 17,
      "z": -2,
      "name": "Rock_Stone"
    },
    {
      "x": -19,
      "y": 18,
      "z": -2,
      "name": "Rock_Stone"
    },
    {
      "x": -19,
      "y": 19,
      "z": -2,
      "name": "Soil_Gravel"
    },
    {
      "x": -19,
      "y": 12,
      "z": -1,
      "name": "Rock_Stone"
    },
    {
      "x": -19,
      "y": 13,
      "z": -1,
      "name": "Rock_Stone"
    },
    {
      "x": -19,
      "y": 14,
      "z": -1,
      "name": "Rock_Stone"
    },
    {
      "x": -19,
      "y": 15,
      "z": -1,
      "name": "Rock_Stone"
    },
    {
      "x": -19,
      "y": 16,
      "z": -1,
      "name": "Rock_Stone"
    },
    {
      "x": -19,
      "y": 17,
      "z": -1,
      "name": "Rock_Stone"
    },
    {
      "x": -19,
      "y": 18,
      "z": -1,
      "name": "Rock_Stone"
    },
    {
      "x": -19,
      "y": 19,
      "z": -1,
      "name": "Rock_Stone"
    },
    {
      "x": -19,
      "y": 12,
      "z": 0,
      "name": "Rock_Stone"
    },
    {
      "x": -19,
      "y": 13,
      "z": 0,
      "name": "Rock_Stone"
    },
    {
      "x": -19,
      "y": 14,
      "z": 0,
      "name": "Rock_Stone"
    },
    {
      "x": -19,
      "y": 15,
      "z": 0,
      "name": "Rock_Stone"
    },
    {
      "x": -19,
      "y": 16,
      "z": 0,
      "name": "Rock_Stone"
    },
    {
      "x": -19,
      "y": 17,
      "z": 0,
      "name": "Rock_Stone"
    },
    {
      "x": -19,
      "y": 18,
      "z": 0,
      "name": "Rock_Stone"
    },
    {
      "x": -19,
      "y": 19,
      "z": 0,
      "name": "Rock_Stone"
    },
    {
      "x": -19,
      "y": 20,
      "z": 0,
      "name": "Rock_Stone_Stalactite_Large"
    },
    {
      "x": -19,
      "y": 21,
      "z": 0,
      "name": "Rock_Stone_Stalactite_Large",
      "filler": 1024
    },
    {
      "x": -19,
      "y": 12,
      "z": 1,
      "name": "Rock_Stone"
    },
    {
      "x": -19,
      "y": 13,
      "z": 1,
      "name": "Rock_Stone"
    },
    {
      "x": -19,
      "y": 16,
      "z": 1,
      "name": "Rock_Stone"
    },
    {
      "x": -19,
      "y": 17,
      "z": 1,
      "name": "Rock_Stone"
    },
    {
      "x": -19,
      "y": 18,
      "z": 1,
      "name": "Rock_Stone"
    },
    {
      "x": -19,
      "y": 19,
      "z": 1,
      "name": "Rock_Stone"
    },
    {
      "x": -19,
      "y": 17,
      "z": 2,
      "name": "Rock_Stone"
    },
    {
      "x": -19,
      "y": 18,
      "z": 2,
      "name": "Rock_Stone"
    },
    {
      "x": -19,
      "y": 19,
      "z": 2,
      "name": "Rock_Stone"
    },
    {
      "x": -19,
      "y": 20,
      "z": 2,
      "name": "Rock_Stone"
    },
    {
      "x": -19,
      "y": 17,
      "z": 3,
      "name": "Rock_Stone"
    },
    {
      "x": -19,
      "y": 18,
      "z": 3,
      "name": "Rock_Stone"
    },
    {
      "x": -19,
      "y": 19,
      "z": 3,
      "name": "Rock_Stone"
    },
    {
      "x": -19,
      "y": 20,
      "z": 3,
      "name": "Rock_Stone"
    },
    {
      "x": -19,
      "y": 21,
      "z": 3,
      "name": "Rock_Stone_Stalactite_Small"
    },
    {
      "x": -19,
      "y": 18,
      "z": 4,
      "name": "Rock_Stone"
    },
    {
      "x": -19,
      "y": 19,
      "z": 4,
      "name": "Rock_Stone"
    },
    {
      "x": -19,
      "y": 20,
      "z": 4,
      "name": "Rock_Stone"
    },
    {
      "x": -19,
      "y": 20,
      "z": 5,
      "name": "Rock_Stone"
    },
    {
      "x": -19,
      "y": 19,
      "z": 6,
      "name": "Rock_Stone"
    },
    {
      "x": -19,
      "y": 20,
      "z": 6,
      "name": "Rock_Stone"
    },
    {
      "x": -18,
      "y": 16,
      "z": -10,
      "name": "Rock_Stone"
    },
    {
      "x": -18,
      "y": 17,
      "z": -10,
      "name": "Rock_Stone"
    },
    {
      "x": -18,
      "y": 18,
      "z": -10,
      "name": "Rock_Stone"
    },
    {
      "x": -18,
      "y": 15,
      "z": -9,
      "name": "Rock_Stone"
    },
    {
      "x": -18,
      "y": 16,
      "z": -9,
      "name": "Rock_Stone"
    },
    {
      "x": -18,
      "y": 17,
      "z": -9,
      "name": "Rock_Stone"
    },
    {
      "x": -18,
      "y": 18,
      "z": -9,
      "name": "Rock_Stone"
    },
    {
      "x": -18,
      "y": 19,
      "z": -9,
      "name": "Rock_Stone_Stalactite_Small"
    },
    {
      "x": -18,
      "y": 16,
      "z": -8,
      "name": "Rock_Stone"
    },
    {
      "x": -18,
      "y": 17,
      "z": -8,
      "name": "Rock_Stone"
    },
    {
      "x": -18,
      "y": 18,
      "z": -8,
      "name": "Rock_Stone"
    },
    {
      "x": -18,
      "y": 14,
      "z": -6,
      "name": "Rock_Stone"
    },
    {
      "x": -18,
      "y": 15,
      "z": -6,
      "name": "Rock_Stone"
    },
    {
      "x": -18,
      "y": 16,
      "z": -6,
      "name": "Rock_Stone"
    },
    {
      "x": -18,
      "y": 17,
      "z": -6,
      "name": "Rock_Stone"
    },
    {
      "x": -18,
      "y": 18,
      "z": -6,
      "name": "Rock_Stone"
    },
    {
      "x": -18,
      "y": 12,
      "z": -5,
      "name": "Rock_Stone"
    },
    {
      "x": -18,
      "y": 13,
      "z": -5,
      "name": "Rock_Stone"
    },
    {
      "x": -18,
      "y": 14,
      "z": -5,
      "name": "Rock_Stone"
    },
    {
      "x": -18,
      "y": 15,
      "z": -5,
      "name": "Rock_Stone"
    },
    {
      "x": -18,
      "y": 16,
      "z": -5,
      "name": "Rock_Stone"
    },
    {
      "x": -18,
      "y": 17,
      "z": -5,
      "name": "Rock_Stone"
    },
    {
      "x": -18,
      "y": 18,
      "z": -5,
      "name": "Soil_Gravel_Mossy"
    },
    {
      "x": -18,
      "y": 12,
      "z": -4,
      "name": "Rock_Stone"
    },
    {
      "x": -18,
      "y": 13,
      "z": -4,
      "name": "Rock_Stone"
    },
    {
      "x": -18,
      "y": 14,
      "z": -4,
      "name": "Rock_Stone"
    },
    {
      "x": -18,
      "y": 15,
      "z": -4,
      "name": "Rock_Stone"
    },
    {
      "x": -18,
      "y": 16,
      "z": -4,
      "name": "Rock_Stone"
    },
    {
      "x": -18,
      "y": 17,
      "z": -4,
      "name": "Rock_Stone"
    },
    {
      "x": -18,
      "y": 18,
      "z": -4,
      "name": "Soil_Gravel"
    },
    {
      "x": -18,
      "y": 11,
      "z": -3,
      "name": "Rock_Stone_Stalactite_Small",
      "rotation": 8
    },
    {
      "x": -18,
      "y": 12,
      "z": -3,
      "name": "Rock_Stone"
    },
    {
      "x": -18,
      "y": 13,
      "z": -3,
      "name": "Rock_Stone"
    },
    {
      "x": -18,
      "y": 14,
      "z": -3,
      "name": "Rock_Stone"
    },
    {
      "x": -18,
      "y": 15,
      "z": -3,
      "name": "Rock_Stone"
    },
    {
      "x": -18,
      "y": 16,
      "z": -3,
      "name": "Rock_Stone"
    },
    {
      "x": -18,
      "y": 17,
      "z": -3,
      "name": "Rock_Stone"
    },
    {
      "x": -18,
      "y": 18,
      "z": -3,
      "name": "Rock_Stone"
    },
    {
      "x": -18,
      "y": 19,
      "z": -3,
      "name": "Soil_Gravel"
    },
    {
      "x": -18,
      "y": 12,
      "z": -2,
      "name": "Rock_Stone"
    },
    {
      "x": -18,
      "y": 13,
      "z": -2,
      "name": "Rock_Stone"
    },
    {
      "x": -18,
      "y": 14,
      "z": -2,
      "name": "Rock_Stone"
    },
    {
      "x": -18,
      "y": 15,
      "z": -2,
      "name": "Rock_Stone"
    },
    {
      "x": -18,
      "y": 16,
      "z": -2,
      "name": "Rock_Stone"
    },
    {
      "x": -18,
      "y": 17,
      "z": -2,
      "name": "Rock_Stone"
    },
    {
      "x": -18,
      "y": 18,
      "z": -2,
      "name": "Ore_Copper_Stone"
    },
    {
      "x": -18,
      "y": 19,
      "z": -2,
      "name": "Rock_Stone"
    },
    {
      "x": -18,
      "y": 20,
      "z": -2,
      "name": "Soil_Gravel"
    },
    {
      "x": -18,
      "y": 10,
      "z": -1,
      "name": "Rock_Stone"
    },
    {
      "x": -18,
      "y": 11,
      "z": -1,
      "name": "Rock_Stone"
    },
    {
      "x": -18,
      "y": 12,
      "z": -1,
      "name": "Rock_Stone"
    },
    {
      "x": -18,
      "y": 13,
      "z": -1,
      "name": "Rock_Stone"
    },
    {
      "x": -18,
      "y": 14,
      "z": -1,
      "name": "Rock_Stone"
    },
    {
      "x": -18,
      "y": 15,
      "z": -1,
      "name": "Rock_Stone"
    },
    {
      "x": -18,
      "y": 16,
      "z": -1,
      "name": "Rock_Stone"
    },
    {
      "x": -18,
      "y": 17,
      "z": -1,
      "name": "Rock_Stone"
    },
    {
      "x": -18,
      "y": 18,
      "z": -1,
      "name": "Rock_Stone"
    },
    {
      "x": -18,
      "y": 19,
      "z": -1,
      "name": "Rock_Stone"
    },
    {
      "x": -18,
      "y": 20,
      "z": -1,
      "name": "Soil_Gravel"
    },
    {
      "x": -18,
      "y": 8,
      "z": 0,
      "name": "Rock_Stone_Stalactite_Small",
      "rotation": 8
    },
    {
      "x": -18,
      "y": 9,
      "z": 0,
      "name": "Rock_Stone"
    },
    {
      "x": -18,
      "y": 10,
      "z": 0,
      "name": "Rock_Stone"
    },
    {
      "x": -18,
      "y": 11,
      "z": 0,
      "name": "Rock_Stone"
    },
    {
      "x": -18,
      "y": 12,
      "z": 0,
      "name": "Rock_Stone"
    },
    {
      "x": -18,
      "y": 13,
      "z": 0,
      "name": "Rock_Stone"
    },
    {
      "x": -18,
      "y": 14,
      "z": 0,
      "name": "Rock_Stone"
    },
    {
      "x": -18,
      "y": 15,
      "z": 0,
      "name": "Rock_Stone"
    },
    {
      "x": -18,
      "y": 16,
      "z": 0,
      "name": "Rock_Stone"
    },
    {
      "x": -18,
      "y": 17,
      "z": 0,
      "name": "Rock_Stone"
    },
    {
      "x": -18,
      "y": 18,
      "z": 0,
      "name": "Rock_Stone"
    },
    {
      "x": -18,
      "y": 19,
      "z": 0,
      "name": "Rock_Stone"
    },
    {
      "x": -18,
      "y": 20,
      "z": 0,
      "name": "Soil_Gravel"
    },
    {
      "x": -18,
      "y": 11,
      "z": 1,
      "name": "Rock_Stone"
    },
    {
      "x": -18,
      "y": 12,
      "z": 1,
      "name": "Rock_Stone"
    },
    {
      "x": -18,
      "y": 13,
      "z": 1,
      "name": "Rock_Stone"
    },
    {
      "x": -18,
      "y": 18,
      "z": 1,
      "name": "Rock_Stone"
    },
    {
      "x": -18,
      "y": 19,
      "z": 1,
      "name": "Rock_Stone"
    },
    {
      "x": -18,
      "y": 20,
      "z": 1,
      "name": "Soil_Gravel"
    },
    {
      "x": -18,
      "y": 12,
      "z": 2,
      "name": "Rock_Stone"
    },
    {
      "x": -18,
      "y": 13,
      "z": 2,
      "name": "Rock_Stone"
    },
    {
      "x": -18,
      "y": 18,
      "z": 2,
      "name": "Rock_Stone"
    },
    {
      "x": -18,
      "y": 19,
      "z": 2,
      "name": "Rock_Stone"
    },
    {
      "x": -18,
      "y": 20,
      "z": 2,
      "name": "Rock_Stone"
    },
    {
      "x": -18,
      "y": 21,
      "z": 2,
      "name": "Soil_Gravel"
    },
    {
      "x": -18,
      "y": 18,
      "z": 3,
      "name": "Rock_Stone"
    },
    {
      "x": -18,
      "y": 19,
      "z": 3,
      "name": "Rock_Stone"
    },
    {
      "x": -18,
      "y": 20,
      "z": 3,
      "name": "Rock_Stone"
    },
    {
      "x": -18,
      "y": 21,
      "z": 3,
      "name": "Soil_Gravel"
    },
    {
      "x": -18,
      "y": 14,
      "z": 4,
      "name": "Rock_Stone"
    },
    {
      "x": -18,
      "y": 15,
      "z": 4,
      "name": "Rock_Stone"
    },
    {
      "x": -18,
      "y": 16,
      "z": 4,
      "name": "Rock_Stone"
    },
    {
      "x": -18,
      "y": 17,
      "z": 4,
      "name": "Rock_Stone"
    },
    {
      "x": -18,
      "y": 18,
      "z": 4,
      "name": "Rock_Stone"
    },
    {
      "x": -18,
      "y": 19,
      "z": 4,
      "name": "Rock_Stone"
    },
    {
      "x": -18,
      "y": 20,
      "z": 4,
      "name": "Rock_Stone"
    },
    {
      "x": -18,
      "y": 21,
      "z": 4,
      "name": "Soil_Gravel"
    },
    {
      "x": -18,
      "y": 16,
      "z": 5,
      "name": "Rock_Stone"
    },
    {
      "x": -18,
      "y": 17,
      "z": 5,
      "name": "Rock_Stone"
    },
    {
      "x": -18,
      "y": 18,
      "z": 5,
      "name": "Rock_Stone"
    },
    {
      "x": -18,
      "y": 19,
      "z": 5,
      "name": "Rock_Stone"
    },
    {
      "x": -18,
      "y": 20,
      "z": 5,
      "name": "Rock_Stone"
    },
    {
      "x": -18,
      "y": 21,
      "z": 5,
      "name": "Soil_Gravel"
    },
    {
      "x": -18,
      "y": 16,
      "z": 6,
      "name": "Rock_Stone"
    },
    {
      "x": -18,
      "y": 17,
      "z": 6,
      "name": "Rock_Stone"
    },
    {
      "x": -18,
      "y": 18,
      "z": 6,
      "name": "Rock_Stone"
    },
    {
      "x": -18,
      "y": 19,
      "z": 6,
      "name": "Rock_Stone"
    },
    {
      "x": -18,
      "y": 20,
      "z": 6,
      "name": "Rock_Stone"
    },
    {
      "x": -18,
      "y": 21,
      "z": 6,
      "name": "Rock_Stone"
    },
    {
      "x": -18,
      "y": 16,
      "z": 7,
      "name": "Rock_Stone"
    },
    {
      "x": -18,
      "y": 17,
      "z": 7,
      "name": "Rock_Stone"
    },
    {
      "x": -18,
      "y": 18,
      "z": 7,
      "name": "Rock_Stone"
    },
    {
      "x": -18,
      "y": 19,
      "z": 7,
      "name": "Rock_Stone"
    },
    {
      "x": -18,
      "y": 20,
      "z": 7,
      "name": "Rock_Stone"
    },
    {
      "x": -18,
      "y": 21,
      "z": 7,
      "name": "Rock_Stone"
    },
    {
      "x": -18,
      "y": 18,
      "z": 8,
      "name": "Rock_Stone"
    },
    {
      "x": -18,
      "y": 19,
      "z": 8,
      "name": "Rock_Stone"
    },
    {
      "x": -18,
      "y": 20,
      "z": 8,
      "name": "Rock_Stone"
    },
    {
      "x": -18,
      "y": 21,
      "z": 8,
      "name": "Rock_Stone"
    },
    {
      "x": -18,
      "y": 22,
      "z": 8,
      "name": "Rock_Stone_Stalactite_Large"
    },
    {
      "x": -18,
      "y": 23,
      "z": 8,
      "name": "Rock_Stone_Stalactite_Large",
      "filler": 1024
    },
    {
      "x": -18,
      "y": 20,
      "z": 9,
      "name": "Rock_Stone"
    },
    {
      "x": -17,
      "y": 14,
      "z": -11,
      "name": "Rock_Stone"
    },
    {
      "x": -17,
      "y": 15,
      "z": -11,
      "name": "Rock_Stone"
    },
    {
      "x": -17,
      "y": 16,
      "z": -11,
      "name": "Rock_Stone"
    },
    {
      "x": -17,
      "y": 17,
      "z": -11,
      "name": "Rock_Stone"
    },
    {
      "x": -17,
      "y": 18,
      "z": -11,
      "name": "Rock_Stone"
    },
    {
      "x": -17,
      "y": 12,
      "z": -10,
      "name": "Rock_Stone"
    },
    {
      "x": -17,
      "y": 13,
      "z": -10,
      "name": "Rock_Stone"
    },
    {
      "x": -17,
      "y": 14,
      "z": -10,
      "name": "Rock_Stone"
    },
    {
      "x": -17,
      "y": 15,
      "z": -10,
      "name": "Rock_Stone"
    },
    {
      "x": -17,
      "y": 16,
      "z": -10,
      "name": "Rock_Stone"
    },
    {
      "x": -17,
      "y": 17,
      "z": -10,
      "name": "Rock_Stone"
    },
    {
      "x": -17,
      "y": 18,
      "z": -10,
      "name": "Rock_Stone"
    },
    {
      "x": -17,
      "y": 12,
      "z": -9,
      "name": "Rock_Stone"
    },
    {
      "x": -17,
      "y": 13,
      "z": -9,
      "name": "Rock_Stone"
    },
    {
      "x": -17,
      "y": 14,
      "z": -9,
      "name": "Rock_Stone"
    },
    {
      "x": -17,
      "y": 15,
      "z": -9,
      "name": "Rock_Stone"
    },
    {
      "x": -17,
      "y": 16,
      "z": -9,
      "name": "Rock_Stone"
    },
    {
      "x": -17,
      "y": 17,
      "z": -9,
      "name": "Rock_Stone"
    },
    {
      "x": -17,
      "y": 18,
      "z": -9,
      "name": "Rock_Stone"
    },
    {
      "x": -17,
      "y": 12,
      "z": -8,
      "name": "Rock_Stone"
    },
    {
      "x": -17,
      "y": 13,
      "z": -8,
      "name": "Rock_Stone"
    },
    {
      "x": -17,
      "y": 14,
      "z": -8,
      "name": "Rock_Stone"
    },
    {
      "x": -17,
      "y": 15,
      "z": -8,
      "name": "Rock_Stone"
    },
    {
      "x": -17,
      "y": 16,
      "z": -8,
      "name": "Rock_Stone"
    },
    {
      "x": -17,
      "y": 17,
      "z": -8,
      "name": "Rock_Stone"
    },
    {
      "x": -17,
      "y": 18,
      "z": -8,
      "name": "Soil_Gravel"
    },
    {
      "x": -17,
      "y": 14,
      "z": -7,
      "name": "Rock_Stone"
    },
    {
      "x": -17,
      "y": 15,
      "z": -7,
      "name": "Rock_Stone"
    },
    {
      "x": -17,
      "y": 16,
      "z": -7,
      "name": "Rock_Stone"
    },
    {
      "x": -17,
      "y": 17,
      "z": -7,
      "name": "Rock_Stone"
    },
    {
      "x": -17,
      "y": 18,
      "z": -7,
      "name": "Soil_Gravel"
    },
    {
      "x": -17,
      "y": 10,
      "z": -6,
      "name": "Rock_Stone_Stalactite_Large",
      "filler": 31744,
      "rotation": 8
    },
    {
      "x": -17,
      "y": 11,
      "z": -6,
      "name": "Rock_Stone_Stalactite_Large",
      "rotation": 8
    },
    {
      "x": -17,
      "y": 12,
      "z": -6,
      "name": "Rock_Stone"
    },
    {
      "x": -17,
      "y": 13,
      "z": -6,
      "name": "Rock_Stone"
    },
    {
      "x": -17,
      "y": 14,
      "z": -6,
      "name": "Rock_Stone"
    },
    {
      "x": -17,
      "y": 15,
      "z": -6,
      "name": "Rock_Stone"
    },
    {
      "x": -17,
      "y": 16,
      "z": -6,
      "name": "Rock_Stone"
    },
    {
      "x": -17,
      "y": 17,
      "z": -6,
      "name": "Rock_Stone"
    },
    {
      "x": -17,
      "y": 18,
      "z": -6,
      "name": "Rock_Stone"
    },
    {
      "x": -17,
      "y": 19,
      "z": -6,
      "name": "Soil_Gravel"
    },
    {
      "x": -17,
      "y": 10,
      "z": -5,
      "name": "Rock_Stone_Stalactite_Small",
      "rotation": 8
    },
    {
      "x": -17,
      "y": 11,
      "z": -5,
      "name": "Rock_Stone"
    },
    {
      "x": -17,
      "y": 12,
      "z": -5,
      "name": "Rock_Stone"
    },
    {
      "x": -17,
      "y": 13,
      "z": -5,
      "name": "Rock_Stone"
    },
    {
      "x": -17,
      "y": 14,
      "z": -5,
      "name": "Rock_Stone"
    },
    {
      "x": -17,
      "y": 15,
      "z": -5,
      "name": "Rock_Stone"
    },
    {
      "x": -17,
      "y": 16,
      "z": -5,
      "name": "Rock_Stone"
    },
    {
      "x": -17,
      "y": 17,
      "z": -5,
      "name": "Rock_Stone"
    },
    {
      "x": -17,
      "y": 18,
      "z": -5,
      "name": "Rock_Stone"
    },
    {
      "x": -17,
      "y": 19,
      "z": -5,
      "name": "Soil_Gravel"
    },
    {
      "x": -17,
      "y": 8,
      "z": -4,
      "name": "Rock_Stone_Stalactite_Small",
      "rotation": 8
    },
    {
      "x": -17,
      "y": 9,
      "z": -4,
      "name": "Rock_Stone"
    },
    {
      "x": -17,
      "y": 10,
      "z": -4,
      "name": "Rock_Stone"
    },
    {
      "x": -17,
      "y": 11,
      "z": -4,
      "name": "Rock_Stone"
    },
    {
      "x": -17,
      "y": 12,
      "z": -4,
      "name": "Rock_Stone"
    },
    {
      "x": -17,
      "y": 13,
      "z": -4,
      "name": "Rock_Stone"
    },
    {
      "x": -17,
      "y": 14,
      "z": -4,
      "name": "Rock_Stone"
    },
    {
      "x": -17,
      "y": 15,
      "z": -4,
      "name": "Rock_Stone"
    },
    {
      "x": -17,
      "y": 16,
      "z": -4,
      "name": "Rock_Stone"
    },
    {
      "x": -17,
      "y": 17,
      "z": -4,
      "name": "Ore_Copper_Stone"
    },
    {
      "x": -17,
      "y": 18,
      "z": -4,
      "name": "Rock_Stone"
    },
    {
      "x": -17,
      "y": 19,
      "z": -4,
      "name": "Soil_Gravel"
    },
    {
      "x": -17,
      "y": 11,
      "z": -3,
      "name": "Rock_Stone"
    },
    {
      "x": -17,
      "y": 12,
      "z": -3,
      "name": "Rock_Stone"
    },
    {
      "x": -17,
      "y": 13,
      "z": -3,
      "name": "Rock_Stone"
    },
    {
      "x": -17,
      "y": 14,
      "z": -3,
      "name": "Rock_Stone"
    },
    {
      "x": -17,
      "y": 15,
      "z": -3,
      "name": "Rock_Stone"
    },
    {
      "x": -17,
      "y": 16,
      "z": -3,
      "name": "Rock_Stone"
    },
    {
      "x": -17,
      "y": 17,
      "z": -3,
      "name": "Rock_Stone"
    },
    {
      "x": -17,
      "y": 18,
      "z": -3,
      "name": "Rock_Stone"
    },
    {
      "x": -17,
      "y": 19,
      "z": -3,
      "name": "Rock_Stone"
    },
    {
      "x": -17,
      "y": 20,
      "z": -3,
      "name": "Soil_Gravel"
    },
    {
      "x": -17,
      "y": 12,
      "z": -2,
      "name": "Rock_Stone"
    },
    {
      "x": -17,
      "y": 13,
      "z": -2,
      "name": "Rock_Stone"
    },
    {
      "x": -17,
      "y": 14,
      "z": -2,
      "name": "Rock_Stone"
    },
    {
      "x": -17,
      "y": 15,
      "z": -2,
      "name": "Rock_Stone"
    },
    {
      "x": -17,
      "y": 16,
      "z": -2,
      "name": "Rock_Stone"
    },
    {
      "x": -17,
      "y": 17,
      "z": -2,
      "name": "Rock_Stone"
    },
    {
      "x": -17,
      "y": 18,
      "z": -2,
      "name": "Rock_Stone"
    },
    {
      "x": -17,
      "y": 19,
      "z": -2,
      "name": "Rock_Stone"
    },
    {
      "x": -17,
      "y": 20,
      "z": -2,
      "name": "Soil_Gravel"
    },
    {
      "x": -17,
      "y": 9,
      "z": -1,
      "name": "Rock_Stone"
    },
    {
      "x": -17,
      "y": 10,
      "z": -1,
      "name": "Rock_Stone"
    },
    {
      "x": -17,
      "y": 11,
      "z": -1,
      "name": "Rock_Stone"
    },
    {
      "x": -17,
      "y": 12,
      "z": -1,
      "name": "Rock_Stone"
    },
    {
      "x": -17,
      "y": 13,
      "z": -1,
      "name": "Rock_Stone"
    },
    {
      "x": -17,
      "y": 14,
      "z": -1,
      "name": "Rock_Stone"
    },
    {
      "x": -17,
      "y": 15,
      "z": -1,
      "name": "Rock_Stone"
    },
    {
      "x": -17,
      "y": 16,
      "z": -1,
      "name": "Rock_Stone"
    },
    {
      "x": -17,
      "y": 17,
      "z": -1,
      "name": "Rock_Stone"
    },
    {
      "x": -17,
      "y": 18,
      "z": -1,
      "name": "Rock_Stone"
    },
    {
      "x": -17,
      "y": 19,
      "z": -1,
      "name": "Rock_Stone"
    },
    {
      "x": -17,
      "y": 20,
      "z": -1,
      "name": "Soil_Gravel"
    },
    {
      "x": -17,
      "y": 7,
      "z": 0,
      "name": "Rock_Stone_Stalactite_Small",
      "rotation": 8
    },
    {
      "x": -17,
      "y": 8,
      "z": 0,
      "name": "Rock_Stone"
    },
    {
      "x": -17,
      "y": 9,
      "z": 0,
      "name": "Rock_Stone"
    },
    {
      "x": -17,
      "y": 10,
      "z": 0,
      "name": "Rock_Stone"
    },
    {
      "x": -17,
      "y": 11,
      "z": 0,
      "name": "Rock_Stone"
    },
    {
      "x": -17,
      "y": 12,
      "z": 0,
      "name": "Rock_Stone"
    },
    {
      "x": -17,
      "y": 13,
      "z": 0,
      "name": "Rock_Stone"
    },
    {
      "x": -17,
      "y": 14,
      "z": 0,
      "name": "Rock_Stone"
    },
    {
      "x": -17,
      "y": 15,
      "z": 0,
      "name": "Rock_Stone"
    },
    {
      "x": -17,
      "y": 16,
      "z": 0,
      "name": "Rock_Stone"
    },
    {
      "x": -17,
      "y": 17,
      "z": 0,
      "name": "Rock_Stone"
    },
    {
      "x": -17,
      "y": 18,
      "z": 0,
      "name": "Rock_Stone"
    },
    {
      "x": -17,
      "y": 19,
      "z": 0,
      "name": "Rock_Stone"
    },
    {
      "x": -17,
      "y": 20,
      "z": 0,
      "name": "Rock_Stone"
    },
    {
      "x": -17,
      "y": 21,
      "z": 0,
      "name": "Soil_Gravel"
    },
    {
      "x": -17,
      "y": 11,
      "z": 1,
      "name": "Rock_Stone"
    },
    {
      "x": -17,
      "y": 12,
      "z": 1,
      "name": "Rock_Stone"
    },
    {
      "x": -17,
      "y": 13,
      "z": 1,
      "name": "Rock_Stone"
    },
    {
      "x": -17,
      "y": 15,
      "z": 1,
      "name": "Rock_Crystal_Purple_Medium",
      "rotation": 7
    },
    {
      "x": -17,
      "y": 18,
      "z": 1,
      "name": "Rock_Stone"
    },
    {
      "x": -17,
      "y": 19,
      "z": 1,
      "name": "Rock_Stone"
    },
    {
      "x": -17,
      "y": 20,
      "z": 1,
      "name": "Rock_Stone"
    },
    {
      "x": -17,
      "y": 21,
      "z": 1,
      "name": "Soil_Gravel"
    },
    {
      "x": -17,
      "y": 12,
      "z": 2,
      "name": "Rock_Stone"
    },
    {
      "x": -17,
      "y": 13,
      "z": 2,
      "name": "Rock_Stone"
    },
    {
      "x": -17,
      "y": 18,
      "z": 2,
      "name": "Rock_Stone"
    },
    {
      "x": -17,
      "y": 19,
      "z": 2,
      "name": "Rock_Stone"
    },
    {
      "x": -17,
      "y": 20,
      "z": 2,
      "name": "Rock_Stone"
    },
    {
      "x": -17,
      "y": 21,
      "z": 2,
      "name": "Soil_Gravel"
    },
    {
      "x": -17,
      "y": 13,
      "z": 3,
      "name": "Rock_Stone"
    },
    {
      "x": -17,
      "y": 18,
      "z": 3,
      "name": "Rock_Stone"
    },
    {
      "x": -17,
      "y": 19,
      "z": 3,
      "name": "Rock_Stone"
    },
    {
      "x": -17,
      "y": 20,
      "z": 3,
      "name": "Rock_Stone"
    },
    {
      "x": -17,
      "y": 21,
      "z": 3,
      "name": "Soil_Gravel"
    },
    {
      "x": -17,
      "y": 13,
      "z": 4,
      "name": "Rock_Stone"
    },
    {
      "x": -17,
      "y": 14,
      "z": 4,
      "name": "Rock_Stone"
    },
    {
      "x": -17,
      "y": 17,
      "z": 4,
      "name": "Rock_Stone"
    },
    {
      "x": -17,
      "y": 18,
      "z": 4,
      "name": "Rock_Stone"
    },
    {
      "x": -17,
      "y": 19,
      "z": 4,
      "name": "Rock_Stone"
    },
    {
      "x": -17,
      "y": 20,
      "z": 4,
      "name": "Rock_Stone"
    },
    {
      "x": -17,
      "y": 21,
      "z": 4,
      "name": "Rock_Stone"
    },
    {
      "x": -17,
      "y": 22,
      "z": 4,
      "name": "Soil_Gravel_Mossy"
    },
    {
      "x": -17,
      "y": 14,
      "z": 5,
      "name": "Rock_Stone"
    },
    {
      "x": -17,
      "y": 15,
      "z": 5,
      "name": "Rock_Stone"
    },
    {
      "x": -17,
      "y": 16,
      "z": 5,
      "name": "Rock_Stone"
    },
    {
      "x": -17,
      "y": 17,
      "z": 5,
      "name": "Rock_Stone"
    },
    {
      "x": -17,
      "y": 18,
      "z": 5,
      "name": "Rock_Stone"
    },
    {
      "x": -17,
      "y": 19,
      "z": 5,
      "name": "Rock_Stone"
    },
    {
      "x": -17,
      "y": 20,
      "z": 5,
      "name": "Rock_Stone"
    },
    {
      "x": -17,
      "y": 21,
      "z": 5,
      "name": "Rock_Stone"
    },
    {
      "x": -17,
      "y": 22,
      "z": 5,
      "name": "Soil_Gravel"
    },
    {
      "x": -17,
      "y": 15,
      "z": 6,
      "name": "Rock_Stone"
    },
    {
      "x": -17,
      "y": 16,
      "z": 6,
      "name": "Rock_Stone"
    },
    {
      "x": -17,
      "y": 17,
      "z": 6,
      "name": "Rock_Stone"
    },
    {
      "x": -17,
      "y": 18,
      "z": 6,
      "name": "Rock_Stone"
    },
    {
      "x": -17,
      "y": 19,
      "z": 6,
      "name": "Rock_Stone"
    },
    {
      "x": -17,
      "y": 20,
      "z": 6,
      "name": "Rock_Stone"
    },
    {
      "x": -17,
      "y": 21,
      "z": 6,
      "name": "Rock_Stone"
    },
    {
      "x": -17,
      "y": 22,
      "z": 6,
      "name": "Soil_Gravel"
    },
    {
      "x": -17,
      "y": 15,
      "z": 7,
      "name": "Rock_Stone"
    },
    {
      "x": -17,
      "y": 16,
      "z": 7,
      "name": "Rock_Stone"
    },
    {
      "x": -17,
      "y": 17,
      "z": 7,
      "name": "Rock_Stone"
    },
    {
      "x": -17,
      "y": 18,
      "z": 7,
      "name": "Rock_Stone"
    },
    {
      "x": -17,
      "y": 19,
      "z": 7,
      "name": "Rock_Stone"
    },
    {
      "x": -17,
      "y": 20,
      "z": 7,
      "name": "Rock_Stone"
    },
    {
      "x": -17,
      "y": 21,
      "z": 7,
      "name": "Soil_Gravel_Mossy"
    },
    {
      "x": -17,
      "y": 15,
      "z": 8,
      "name": "Rock_Stone"
    },
    {
      "x": -17,
      "y": 16,
      "z": 8,
      "name": "Rock_Stone"
    },
    {
      "x": -17,
      "y": 17,
      "z": 8,
      "name": "Rock_Stone"
    },
    {
      "x": -17,
      "y": 18,
      "z": 8,
      "name": "Rock_Stone"
    },
    {
      "x": -17,
      "y": 19,
      "z": 8,
      "name": "Rock_Stone"
    },
    {
      "x": -17,
      "y": 20,
      "z": 8,
      "name": "Rock_Stone"
    },
    {
      "x": -17,
      "y": 21,
      "z": 8,
      "name": "Rock_Stone"
    },
    {
      "x": -17,
      "y": 15,
      "z": 9,
      "name": "Rock_Stone"
    },
    {
      "x": -17,
      "y": 16,
      "z": 9,
      "name": "Rock_Stone"
    },
    {
      "x": -17,
      "y": 17,
      "z": 9,
      "name": "Rock_Stone"
    },
    {
      "x": -17,
      "y": 18,
      "z": 9,
      "name": "Rock_Stone"
    },
    {
      "x": -17,
      "y": 19,
      "z": 9,
      "name": "Rock_Stone"
    },
    {
      "x": -17,
      "y": 20,
      "z": 9,
      "name": "Rock_Stone"
    },
    {
      "x": -17,
      "y": 21,
      "z": 9,
      "name": "Rock_Stone"
    },
    {
      "x": -17,
      "y": 17,
      "z": 10,
      "name": "Rock_Stone"
    },
    {
      "x": -17,
      "y": 18,
      "z": 10,
      "name": "Rock_Stone"
    },
    {
      "x": -17,
      "y": 19,
      "z": 10,
      "name": "Rock_Stone"
    },
    {
      "x": -17,
      "y": 20,
      "z": 10,
      "name": "Rock_Stone"
    },
    {
      "x": -17,
      "y": 21,
      "z": 10,
      "name": "Rock_Stone"
    },
    {
      "x": -17,
      "y": 19,
      "z": 11,
      "name": "Rock_Stone"
    },
    {
      "x": -17,
      "y": 20,
      "z": 11,
      "name": "Rock_Stone"
    },
    {
      "x": -17,
      "y": 21,
      "z": 11,
      "name": "Rock_Stone"
    },
    {
      "x": -17,
      "y": 20,
      "z": 12,
      "name": "Rock_Stone"
    },
    {
      "x": -17,
      "y": 21,
      "z": 12,
      "name": "Rock_Stone"
    },
    {
      "x": -17,
      "y": 22,
      "z": 12,
      "name": "Rock_Stone_Stalactite_Small"
    },
    {
      "x": -16,
      "y": 16,
      "z": -12,
      "name": "Rock_Stone"
    },
    {
      "x": -16,
      "y": 17,
      "z": -12,
      "name": "Rock_Stone"
    },
    {
      "x": -16,
      "y": 12,
      "z": -11,
      "name": "Rock_Stone"
    },
    {
      "x": -16,
      "y": 13,
      "z": -11,
      "name": "Rock_Stone"
    },
    {
      "x": -16,
      "y": 14,
      "z": -11,
      "name": "Rock_Stone"
    },
    {
      "x": -16,
      "y": 15,
      "z": -11,
      "name": "Rock_Stone"
    },
    {
      "x": -16,
      "y": 16,
      "z": -11,
      "name": "Rock_Stone"
    },
    {
      "x": -16,
      "y": 17,
      "z": -11,
      "name": "Rock_Stone"
    },
    {
      "x": -16,
      "y": 18,
      "z": -11,
      "name": "Rock_Stone"
    },
    {
      "x": -16,
      "y": 9,
      "z": -10,
      "name": "Rock_Stone_Stalactite_Large",
      "filler": 31744,
      "rotation": 8
    },
    {
      "x": -16,
      "y": 10,
      "z": -10,
      "name": "Rock_Stone_Stalactite_Large",
      "rotation": 8
    },
    {
      "x": -16,
      "y": 11,
      "z": -10,
      "name": "Rock_Stone"
    },
    {
      "x": -16,
      "y": 12,
      "z": -10,
      "name": "Rock_Stone"
    },
    {
      "x": -16,
      "y": 13,
      "z": -10,
      "name": "Rock_Stone"
    },
    {
      "x": -16,
      "y": 14,
      "z": -10,
      "name": "Rock_Stone"
    },
    {
      "x": -16,
      "y": 15,
      "z": -10,
      "name": "Rock_Stone"
    },
    {
      "x": -16,
      "y": 16,
      "z": -10,
      "name": "Rock_Stone"
    },
    {
      "x": -16,
      "y": 17,
      "z": -10,
      "name": "Rock_Stone"
    },
    {
      "x": -16,
      "y": 18,
      "z": -10,
      "name": "Rock_Stone"
    },
    {
      "x": -16,
      "y": 19,
      "z": -10,
      "name": "Rock_Stone"
    },
    {
      "x": -16,
      "y": 9,
      "z": -9,
      "name": "Rock_Stone_Stalactite_Large",
      "filler": 31744,
      "rotation": 8
    },
    {
      "x": -16,
      "y": 10,
      "z": -9,
      "name": "Rock_Stone_Stalactite_Large",
      "rotation": 8
    },
    {
      "x": -16,
      "y": 11,
      "z": -9,
      "name": "Rock_Stone"
    },
    {
      "x": -16,
      "y": 12,
      "z": -9,
      "name": "Rock_Stone"
    },
    {
      "x": -16,
      "y": 13,
      "z": -9,
      "name": "Rock_Stone"
    },
    {
      "x": -16,
      "y": 14,
      "z": -9,
      "name": "Rock_Stone"
    },
    {
      "x": -16,
      "y": 15,
      "z": -9,
      "name": "Rock_Stone"
    },
    {
      "x": -16,
      "y": 16,
      "z": -9,
      "name": "Rock_Stone"
    },
    {
      "x": -16,
      "y": 17,
      "z": -9,
      "name": "Rock_Stone"
    },
    {
      "x": -16,
      "y": 18,
      "z": -9,
      "name": "Rock_Stone"
    },
    {
      "x": -16,
      "y": 19,
      "z": -9,
      "name": "Soil_Gravel_Mossy"
    },
    {
      "x": -16,
      "y": 11,
      "z": -8,
      "name": "Rock_Stone"
    },
    {
      "x": -16,
      "y": 12,
      "z": -8,
      "name": "Rock_Stone"
    },
    {
      "x": -16,
      "y": 13,
      "z": -8,
      "name": "Rock_Stone"
    },
    {
      "x": -16,
      "y": 14,
      "z": -8,
      "name": "Rock_Stone"
    },
    {
      "x": -16,
      "y": 15,
      "z": -8,
      "name": "Rock_Stone"
    },
    {
      "x": -16,
      "y": 16,
      "z": -8,
      "name": "Rock_Stone"
    },
    {
      "x": -16,
      "y": 17,
      "z": -8,
      "name": "Rock_Stone"
    },
    {
      "x": -16,
      "y": 18,
      "z": -8,
      "name": "Rock_Stone"
    },
    {
      "x": -16,
      "y": 19,
      "z": -8,
      "name": "Soil_Gravel"
    },
    {
      "x": -16,
      "y": 12,
      "z": -7,
      "name": "Rock_Stone"
    },
    {
      "x": -16,
      "y": 13,
      "z": -7,
      "name": "Rock_Stone"
    },
    {
      "x": -16,
      "y": 14,
      "z": -7,
      "name": "Rock_Stone"
    },
    {
      "x": -16,
      "y": 15,
      "z": -7,
      "name": "Rock_Stone"
    },
    {
      "x": -16,
      "y": 16,
      "z": -7,
      "name": "Rock_Stone"
    },
    {
      "x": -16,
      "y": 17,
      "z": -7,
      "name": "Ore_Copper_Stone"
    },
    {
      "x": -16,
      "y": 18,
      "z": -7,
      "name": "Rock_Stone"
    },
    {
      "x": -16,
      "y": 19,
      "z": -7,
      "name": "Soil_Gravel"
    },
    {
      "x": -16,
      "y": 12,
      "z": -6,
      "name": "Rock_Stone"
    },
    {
      "x": -16,
      "y": 13,
      "z": -6,
      "name": "Rock_Stone"
    },
    {
      "x": -16,
      "y": 14,
      "z": -6,
      "name": "Rock_Stone"
    },
    {
      "x": -16,
      "y": 15,
      "z": -6,
      "name": "Rock_Stone"
    },
    {
      "x": -16,
      "y": 16,
      "z": -6,
      "name": "Rock_Stone"
    },
    {
      "x": -16,
      "y": 17,
      "z": -6,
      "name": "Rock_Stone"
    },
    {
      "x": -16,
      "y": 18,
      "z": -6,
      "name": "Rock_Stone"
    },
    {
      "x": -16,
      "y": 19,
      "z": -6,
      "name": "Rock_Stone"
    },
    {
      "x": -16,
      "y": 20,
      "z": -6,
      "name": "Soil_Gravel_Mossy"
    },
    {
      "x": -16,
      "y": 10,
      "z": -5,
      "name": "Rock_Stone"
    },
    {
      "x": -16,
      "y": 11,
      "z": -5,
      "name": "Rock_Stone"
    },
    {
      "x": -16,
      "y": 12,
      "z": -5,
      "name": "Rock_Stone"
    },
    {
      "x": -16,
      "y": 13,
      "z": -5,
      "name": "Rock_Stone"
    },
    {
      "x": -16,
      "y": 14,
      "z": -5,
      "name": "Rock_Stone"
    },
    {
      "x": -16,
      "y": 15,
      "z": -5,
      "name": "Rock_Stone"
    },
    {
      "x": -16,
      "y": 16,
      "z": -5,
      "name": "Rock_Stone"
    },
    {
      "x": -16,
      "y": 17,
      "z": -5,
      "name": "Rock_Stone"
    },
    {
      "x": -16,
      "y": 18,
      "z": -5,
      "name": "Rock_Stone"
    },
    {
      "x": -16,
      "y": 19,
      "z": -5,
      "name": "Rock_Stone"
    },
    {
      "x": -16,
      "y": 20,
      "z": -5,
      "name": "Soil_Gravel"
    },
    {
      "x": -16,
      "y": 7,
      "z": -4,
      "name": "Rock_Stone_Stalactite_Small",
      "rotation": 8
    },
    {
      "x": -16,
      "y": 8,
      "z": -4,
      "name": "Rock_Stone"
    },
    {
      "x": -16,
      "y": 9,
      "z": -4,
      "name": "Rock_Stone"
    },
    {
      "x": -16,
      "y": 10,
      "z": -4,
      "name": "Rock_Stone"
    },
    {
      "x": -16,
      "y": 11,
      "z": -4,
      "name": "Rock_Stone"
    },
    {
      "x": -16,
      "y": 12,
      "z": -4,
      "name": "Rock_Stone"
    },
    {
      "x": -16,
      "y": 13,
      "z": -4,
      "name": "Rock_Stone"
    },
    {
      "x": -16,
      "y": 14,
      "z": -4,
      "name": "Rock_Stone"
    },
    {
      "x": -16,
      "y": 15,
      "z": -4,
      "name": "Rock_Stone"
    },
    {
      "x": -16,
      "y": 16,
      "z": -4,
      "name": "Rock_Stone"
    },
    {
      "x": -16,
      "y": 17,
      "z": -4,
      "name": "Rock_Stone"
    },
    {
      "x": -16,
      "y": 18,
      "z": -4,
      "name": "Rock_Stone"
    },
    {
      "x": -16,
      "y": 19,
      "z": -4,
      "name": "Ore_Iron_Stone"
    },
    {
      "x": -16,
      "y": 20,
      "z": -4,
      "name": "Soil_Gravel"
    },
    {
      "x": -16,
      "y": 11,
      "z": -3,
      "name": "Rock_Stone"
    },
    {
      "x": -16,
      "y": 12,
      "z": -3,
      "name": "Rock_Stone"
    },
    {
      "x": -16,
      "y": 13,
      "z": -3,
      "name": "Rock_Stone"
    },
    {
      "x": -16,
      "y": 14,
      "z": -3,
      "name": "Rock_Stone"
    },
    {
      "x": -16,
      "y": 15,
      "z": -3,
      "name": "Rock_Stone"
    },
    {
      "x": -16,
      "y": 16,
      "z": -3,
      "name": "Rock_Stone"
    },
    {
      "x": -16,
      "y": 17,
      "z": -3,
      "name": "Rock_Stone"
    },
    {
      "x": -16,
      "y": 18,
      "z": -3,
      "name": "Rock_Stone"
    },
    {
      "x": -16,
      "y": 19,
      "z": -3,
      "name": "Rock_Stone"
    },
    {
      "x": -16,
      "y": 20,
      "z": -3,
      "name": "Soil_Gravel_Mossy"
    },
    {
      "x": -16,
      "y": 12,
      "z": -2,
      "name": "Rock_Stone"
    },
    {
      "x": -16,
      "y": 13,
      "z": -2,
      "name": "Rock_Stone"
    },
    {
      "x": -16,
      "y": 14,
      "z": -2,
      "name": "Rock_Stone"
    },
    {
      "x": -16,
      "y": 15,
      "z": -2,
      "name": "Rock_Stone"
    },
    {
      "x": -16,
      "y": 16,
      "z": -2,
      "name": "Rock_Stone"
    },
    {
      "x": -16,
      "y": 17,
      "z": -2,
      "name": "Rock_Stone"
    },
    {
      "x": -16,
      "y": 18,
      "z": -2,
      "name": "Rock_Stone"
    },
    {
      "x": -16,
      "y": 19,
      "z": -2,
      "name": "Rock_Stone"
    },
    {
      "x": -16,
      "y": 20,
      "z": -2,
      "name": "Soil_Gravel"
    },
    {
      "x": -16,
      "y": 11,
      "z": -1,
      "name": "Rock_Stone"
    },
    {
      "x": -16,
      "y": 12,
      "z": -1,
      "name": "Rock_Stone"
    },
    {
      "x": -16,
      "y": 13,
      "z": -1,
      "name": "Rock_Stone"
    },
    {
      "x": -16,
      "y": 14,
      "z": -1,
      "name": "Rock_Stone"
    },
    {
      "x": -16,
      "y": 15,
      "z": -1,
      "name": "Rock_Stone"
    },
    {
      "x": -16,
      "y": 16,
      "z": -1,
      "name": "Rock_Stone"
    },
    {
      "x": -16,
      "y": 17,
      "z": -1,
      "name": "Rock_Stone"
    },
    {
      "x": -16,
      "y": 18,
      "z": -1,
      "name": "Rock_Stone"
    },
    {
      "x": -16,
      "y": 19,
      "z": -1,
      "name": "Ore_Copper_Stone"
    },
    {
      "x": -16,
      "y": 20,
      "z": -1,
      "name": "Rock_Stone"
    },
    {
      "x": -16,
      "y": 21,
      "z": -1,
      "name": "Soil_Gravel"
    },
    {
      "x": -16,
      "y": 11,
      "z": 0,
      "name": "Rock_Stone"
    },
    {
      "x": -16,
      "y": 12,
      "z": 0,
      "name": "Rock_Stone"
    },
    {
      "x": -16,
      "y": 13,
      "z": 0,
      "name": "Rock_Stone"
    },
    {
      "x": -16,
      "y": 14,
      "z": 0,
      "name": "Rock_Stone"
    },
    {
      "x": -16,
      "y": 15,
      "z": 0,
      "name": "Rock_Stone"
    },
    {
      "x": -16,
      "y": 16,
      "z": 0,
      "name": "Rock_Stone"
    },
    {
      "x": -16,
      "y": 17,
      "z": 0,
      "name": "Rock_Stone"
    },
    {
      "x": -16,
      "y": 18,
      "z": 0,
      "name": "Rock_Stone"
    },
    {
      "x": -16,
      "y": 19,
      "z": 0,
      "name": "Rock_Stone"
    },
    {
      "x": -16,
      "y": 20,
      "z": 0,
      "name": "Rock_Stone"
    },
    {
      "x": -16,
      "y": 21,
      "z": 0,
      "name": "Soil_Gravel_Mossy"
    },
    {
      "x": -16,
      "y": 11,
      "z": 1,
      "name": "Rock_Stone"
    },
    {
      "x": -16,
      "y": 12,
      "z": 1,
      "name": "Rock_Stone"
    },
    {
      "x": -16,
      "y": 13,
      "z": 1,
      "name": "Rock_Stone"
    },
    {
      "x": -16,
      "y": 14,
      "z": 1,
      "name": "Rock_Crystal_Purple_Block"
    },
    {
      "x": -16,
      "y": 15,
      "z": 1,
      "name": "Rock_Crystal_Purple_Block"
    },
    {
      "x": -16,
      "y": 16,
      "z": 1,
      "name": "Rock_Crystal_Purple_Medium"
    },
    {
      "x": -16,
      "y": 18,
      "z": 1,
      "name": "Rock_Stone"
    },
    {
      "x": -16,
      "y": 19,
      "z": 1,
      "name": "Rock_Stone"
    },
    {
      "x": -16,
      "y": 20,
      "z": 1,
      "name": "Rock_Stone"
    },
    {
      "x": -16,
      "y": 21,
      "z": 1,
      "name": "Soil_Gravel"
    },
    {
      "x": -16,
      "y": 12,
      "z": 2,
      "name": "Rock_Stone"
    },
    {
      "x": -16,
      "y": 13,
      "z": 2,
      "name": "Rock_Stone"
    },
    {
      "x": -16,
      "y": 14,
      "z": 2,
      "name": "Rock_Crystal_Purple_Medium"
    },
    {
      "x": -16,
      "y": 18,
      "z": 2,
      "name": "Rock_Stone"
    },
    {
      "x": -16,
      "y": 19,
      "z": 2,
      "name": "Rock_Stone"
    },
    {
      "x": -16,
      "y": 20,
      "z": 2,
      "name": "Rock_Stone"
    },
    {
      "x": -16,
      "y": 21,
      "z": 2,
      "name": "Soil_Gravel"
    },
    {
      "x": -16,
      "y": 12,
      "z": 3,
      "name": "Rock_Stone"
    },
    {
      "x": -16,
      "y": 13,
      "z": 3,
      "name": "Rock_Stone"
    },
    {
      "x": -16,
      "y": 18,
      "z": 3,
      "name": "Rock_Stone"
    },
    {
      "x": -16,
      "y": 19,
      "z": 3,
      "name": "Rock_Stone"
    },
    {
      "x": -16,
      "y": 20,
      "z": 3,
      "name": "Ore_Copper_Stone"
    },
    {
      "x": -16,
      "y": 21,
      "z": 3,
      "name": "Rock_Stone"
    },
    {
      "x": -16,
      "y": 22,
      "z": 3,
      "name": "Soil_Gravel"
    },
    {
      "x": -16,
      "y": 13,
      "z": 4,
      "name": "Rock_Stone"
    },
    {
      "x": -16,
      "y": 14,
      "z": 4,
      "name": "Rock_Stone"
    },
    {
      "x": -16,
      "y": 15,
      "z": 4,
      "name": "Rock_Stone"
    },
    {
      "x": -16,
      "y": 16,
      "z": 4,
      "name": "Rock_Stone"
    },
    {
      "x": -16,
      "y": 17,
      "z": 4,
      "name": "Rock_Stone"
    },
    {
      "x": -16,
      "y": 18,
      "z": 4,
      "name": "Rock_Stone"
    },
    {
      "x": -16,
      "y": 19,
      "z": 4,
      "name": "Rock_Stone"
    },
    {
      "x": -16,
      "y": 20,
      "z": 4,
      "name": "Rock_Stone"
    },
    {
      "x": -16,
      "y": 21,
      "z": 4,
      "name": "Rock_Stone"
    },
    {
      "x": -16,
      "y": 22,
      "z": 4,
      "name": "Soil_Gravel_Mossy"
    },
    {
      "x": -16,
      "y": 14,
      "z": 5,
      "name": "Rock_Stone"
    },
    {
      "x": -16,
      "y": 15,
      "z": 5,
      "name": "Rock_Stone"
    },
    {
      "x": -16,
      "y": 16,
      "z": 5,
      "name": "Rock_Stone"
    },
    {
      "x": -16,
      "y": 17,
      "z": 5,
      "name": "Rock_Stone"
    },
    {
      "x": -16,
      "y": 18,
      "z": 5,
      "name": "Rock_Stone"
    },
    {
      "x": -16,
      "y": 19,
      "z": 5,
      "name": "Rock_Stone"
    },
    {
      "x": -16,
      "y": 20,
      "z": 5,
      "name": "Rock_Stone"
    },
    {
      "x": -16,
      "y": 21,
      "z": 5,
      "name": "Ore_Iron_Stone"
    },
    {
      "x": -16,
      "y": 22,
      "z": 5,
      "name": "Soil_Gravel"
    },
    {
      "x": -16,
      "y": 14,
      "z": 6,
      "name": "Rock_Stone"
    },
    {
      "x": -16,
      "y": 15,
      "z": 6,
      "name": "Rock_Stone"
    },
    {
      "x": -16,
      "y": 16,
      "z": 6,
      "name": "Rock_Stone"
    },
    {
      "x": -16,
      "y": 17,
      "z": 6,
      "name": "Rock_Stone"
    },
    {
      "x": -16,
      "y": 18,
      "z": 6,
      "name": "Rock_Stone"
    },
    {
      "x": -16,
      "y": 19,
      "z": 6,
      "name": "Rock_Stone"
    },
    {
      "x": -16,
      "y": 20,
      "z": 6,
      "name": "Rock_Stone"
    },
    {
      "x": -16,
      "y": 21,
      "z": 6,
      "name": "Rock_Stone"
    },
    {
      "x": -16,
      "y": 22,
      "z": 6,
      "name": "Soil_Gravel_Mossy"
    },
    {
      "x": -16,
      "y": 13,
      "z": 7,
      "name": "Rock_Stone"
    },
    {
      "x": -16,
      "y": 14,
      "z": 7,
      "name": "Rock_Stone"
    },
    {
      "x": -16,
      "y": 15,
      "z": 7,
      "name": "Rock_Stone"
    },
    {
      "x": -16,
      "y": 16,
      "z": 7,
      "name": "Rock_Stone"
    },
    {
      "x": -16,
      "y": 17,
      "z": 7,
      "name": "Rock_Stone"
    },
    {
      "x": -16,
      "y": 18,
      "z": 7,
      "name": "Rock_Stone"
    },
    {
      "x": -16,
      "y": 19,
      "z": 7,
      "name": "Rock_Stone"
    },
    {
      "x": -16,
      "y": 20,
      "z": 7,
      "name": "Rock_Stone"
    },
    {
      "x": -16,
      "y": 21,
      "z": 7,
      "name": "Rock_Stone"
    },
    {
      "x": -16,
      "y": 22,
      "z": 7,
      "name": "Soil_Gravel"
    },
    {
      "x": -16,
      "y": 14,
      "z": 8,
      "name": "Rock_Stone"
    },
    {
      "x": -16,
      "y": 15,
      "z": 8,
      "name": "Rock_Stone"
    },
    {
      "x": -16,
      "y": 16,
      "z": 8,
      "name": "Rock_Stone"
    },
    {
      "x": -16,
      "y": 17,
      "z": 8,
      "name": "Rock_Stone"
    },
    {
      "x": -16,
      "y": 18,
      "z": 8,
      "name": "Rock_Stone"
    },
    {
      "x": -16,
      "y": 19,
      "z": 8,
      "name": "Rock_Stone"
    },
    {
      "x": -16,
      "y": 20,
      "z": 8,
      "name": "Rock_Stone"
    },
    {
      "x": -16,
      "y": 21,
      "z": 8,
      "name": "Rock_Stone"
    },
    {
      "x": -16,
      "y": 22,
      "z": 8,
      "name": "Soil_Gravel"
    },
    {
      "x": -16,
      "y": 14,
      "z": 9,
      "name": "Rock_Stone"
    },
    {
      "x": -16,
      "y": 15,
      "z": 9,
      "name": "Rock_Stone"
    },
    {
      "x": -16,
      "y": 16,
      "z": 9,
      "name": "Rock_Stone"
    },
    {
      "x": -16,
      "y": 17,
      "z": 9,
      "name": "Rock_Stone"
    },
    {
      "x": -16,
      "y": 18,
      "z": 9,
      "name": "Rock_Stone"
    },
    {
      "x": -16,
      "y": 19,
      "z": 9,
      "name": "Rock_Stone"
    },
    {
      "x": -16,
      "y": 20,
      "z": 9,
      "name": "Rock_Stone"
    },
    {
      "x": -16,
      "y": 21,
      "z": 9,
      "name": "Rock_Stone"
    },
    {
      "x": -16,
      "y": 22,
      "z": 9,
      "name": "Soil_Gravel"
    },
    {
      "x": -16,
      "y": 15,
      "z": 10,
      "name": "Rock_Stone"
    },
    {
      "x": -16,
      "y": 16,
      "z": 10,
      "name": "Rock_Stone"
    },
    {
      "x": -16,
      "y": 17,
      "z": 10,
      "name": "Rock_Stone"
    },
    {
      "x": -16,
      "y": 18,
      "z": 10,
      "name": "Rock_Stone"
    },
    {
      "x": -16,
      "y": 19,
      "z": 10,
      "name": "Rock_Stone"
    },
    {
      "x": -16,
      "y": 20,
      "z": 10,
      "name": "Rock_Stone"
    },
    {
      "x": -16,
      "y": 21,
      "z": 10,
      "name": "Rock_Stone"
    },
    {
      "x": -16,
      "y": 22,
      "z": 10,
      "name": "Rock_Stone"
    },
    {
      "x": -16,
      "y": 16,
      "z": 11,
      "name": "Rock_Stone"
    },
    {
      "x": -16,
      "y": 17,
      "z": 11,
      "name": "Rock_Stone"
    },
    {
      "x": -16,
      "y": 18,
      "z": 11,
      "name": "Rock_Stone"
    },
    {
      "x": -16,
      "y": 19,
      "z": 11,
      "name": "Rock_Stone"
    },
    {
      "x": -16,
      "y": 20,
      "z": 11,
      "name": "Rock_Stone"
    },
    {
      "x": -16,
      "y": 21,
      "z": 11,
      "name": "Rock_Stone"
    },
    {
      "x": -16,
      "y": 22,
      "z": 11,
      "name": "Rock_Stone"
    },
    {
      "x": -16,
      "y": 23,
      "z": 11,
      "name": "Rock_Stone_Stalactite_Large"
    },
    {
      "x": -16,
      "y": 24,
      "z": 11,
      "name": "Rock_Stone_Stalactite_Large",
      "filler": 1024
    },
    {
      "x": -16,
      "y": 16,
      "z": 12,
      "name": "Rock_Stone"
    },
    {
      "x": -16,
      "y": 17,
      "z": 12,
      "name": "Rock_Stone"
    },
    {
      "x": -16,
      "y": 18,
      "z": 12,
      "name": "Rock_Stone"
    },
    {
      "x": -16,
      "y": 19,
      "z": 12,
      "name": "Rock_Stone"
    },
    {
      "x": -16,
      "y": 20,
      "z": 12,
      "name": "Rock_Stone"
    },
    {
      "x": -16,
      "y": 21,
      "z": 12,
      "name": "Rock_Stone"
    },
    {
      "x": -16,
      "y": 22,
      "z": 12,
      "name": "Soil_Gravel"
    },
    {
      "x": -16,
      "y": 18,
      "z": 13,
      "name": "Rock_Stone"
    },
    {
      "x": -16,
      "y": 19,
      "z": 13,
      "name": "Rock_Stone"
    },
    {
      "x": -16,
      "y": 20,
      "z": 13,
      "name": "Rock_Stone"
    },
    {
      "x": -16,
      "y": 21,
      "z": 13,
      "name": "Rock_Stone"
    },
    {
      "x": -15,
      "y": 14,
      "z": -13,
      "name": "Rock_Stone"
    },
    {
      "x": -15,
      "y": 15,
      "z": -13,
      "name": "Rock_Stone"
    },
    {
      "x": -15,
      "y": 16,
      "z": -13,
      "name": "Rock_Stone"
    },
    {
      "x": -15,
      "y": 17,
      "z": -13,
      "name": "Rock_Stone"
    },
    {
      "x": -15,
      "y": 12,
      "z": -12,
      "name": "Rock_Stone"
    },
    {
      "x": -15,
      "y": 13,
      "z": -12,
      "name": "Rock_Stone"
    },
    {
      "x": -15,
      "y": 14,
      "z": -12,
      "name": "Rock_Stone"
    },
    {
      "x": -15,
      "y": 15,
      "z": -12,
      "name": "Rock_Stone"
    },
    {
      "x": -15,
      "y": 16,
      "z": -12,
      "name": "Rock_Stone"
    },
    {
      "x": -15,
      "y": 17,
      "z": -12,
      "name": "Rock_Stone"
    },
    {
      "x": -15,
      "y": 18,
      "z": -12,
      "name": "Rock_Stone"
    },
    {
      "x": -15,
      "y": 12,
      "z": -11,
      "name": "Rock_Stone"
    },
    {
      "x": -15,
      "y": 13,
      "z": -11,
      "name": "Rock_Stone"
    },
    {
      "x": -15,
      "y": 14,
      "z": -11,
      "name": "Rock_Stone"
    },
    {
      "x": -15,
      "y": 15,
      "z": -11,
      "name": "Rock_Stone"
    },
    {
      "x": -15,
      "y": 16,
      "z": -11,
      "name": "Rock_Stone"
    },
    {
      "x": -15,
      "y": 17,
      "z": -11,
      "name": "Rock_Stone"
    },
    {
      "x": -15,
      "y": 18,
      "z": -11,
      "name": "Rock_Stone"
    },
    {
      "x": -15,
      "y": 19,
      "z": -11,
      "name": "Rock_Stone"
    },
    {
      "x": -15,
      "y": 7,
      "z": -10,
      "name": "Rock_Stone_Stalactite_Small",
      "rotation": 8
    },
    {
      "x": -15,
      "y": 8,
      "z": -10,
      "name": "Rock_Stone"
    },
    {
      "x": -15,
      "y": 9,
      "z": -10,
      "name": "Rock_Stone"
    },
    {
      "x": -15,
      "y": 10,
      "z": -10,
      "name": "Rock_Stone"
    },
    {
      "x": -15,
      "y": 11,
      "z": -10,
      "name": "Rock_Stone"
    },
    {
      "x": -15,
      "y": 12,
      "z": -10,
      "name": "Rock_Stone"
    },
    {
      "x": -15,
      "y": 13,
      "z": -10,
      "name": "Rock_Stone"
    },
    {
      "x": -15,
      "y": 14,
      "z": -10,
      "name": "Rock_Stone"
    },
    {
      "x": -15,
      "y": 15,
      "z": -10,
      "name": "Rock_Stone"
    },
    {
      "x": -15,
      "y": 16,
      "z": -10,
      "name": "Rock_Stone"
    },
    {
      "x": -15,
      "y": 17,
      "z": -10,
      "name": "Rock_Stone"
    },
    {
      "x": -15,
      "y": 18,
      "z": -10,
      "name": "Rock_Stone"
    },
    {
      "x": -15,
      "y": 19,
      "z": -10,
      "name": "Soil_Gravel_Mossy"
    },
    {
      "x": -15,
      "y": 10,
      "z": -9,
      "name": "Rock_Stone"
    },
    {
      "x": -15,
      "y": 11,
      "z": -9,
      "name": "Rock_Stone"
    },
    {
      "x": -15,
      "y": 12,
      "z": -9,
      "name": "Rock_Stone"
    },
    {
      "x": -15,
      "y": 13,
      "z": -9,
      "name": "Rock_Stone"
    },
    {
      "x": -15,
      "y": 14,
      "z": -9,
      "name": "Rock_Stone"
    },
    {
      "x": -15,
      "y": 15,
      "z": -9,
      "name": "Rock_Stone"
    },
    {
      "x": -15,
      "y": 16,
      "z": -9,
      "name": "Rock_Stone"
    },
    {
      "x": -15,
      "y": 17,
      "z": -9,
      "name": "Rock_Stone"
    },
    {
      "x": -15,
      "y": 18,
      "z": -9,
      "name": "Rock_Stone"
    },
    {
      "x": -15,
      "y": 19,
      "z": -9,
      "name": "Rock_Stone"
    },
    {
      "x": -15,
      "y": 20,
      "z": -9,
      "name": "Soil_Gravel"
    },
    {
      "x": -15,
      "y": 11,
      "z": -8,
      "name": "Rock_Stone"
    },
    {
      "x": -15,
      "y": 12,
      "z": -8,
      "name": "Rock_Stone"
    },
    {
      "x": -15,
      "y": 13,
      "z": -8,
      "name": "Rock_Stone"
    },
    {
      "x": -15,
      "y": 14,
      "z": -8,
      "name": "Rock_Stone"
    },
    {
      "x": -15,
      "y": 15,
      "z": -8,
      "name": "Rock_Stone"
    },
    {
      "x": -15,
      "y": 16,
      "z": -8,
      "name": "Rock_Stone"
    },
    {
      "x": -15,
      "y": 17,
      "z": -8,
      "name": "Rock_Stone"
    },
    {
      "x": -15,
      "y": 18,
      "z": -8,
      "name": "Rock_Stone"
    },
    {
      "x": -15,
      "y": 19,
      "z": -8,
      "name": "Rock_Stone"
    },
    {
      "x": -15,
      "y": 20,
      "z": -8,
      "name": "Soil_Gravel"
    },
    {
      "x": -15,
      "y": 9,
      "z": -7,
      "name": "Rock_Crystal_Purple_Medium",
      "rotation": 7
    },
    {
      "x": -15,
      "y": 10,
      "z": -7,
      "name": "Rock_Crystal_Purple_Medium",
      "rotation": 7
    },
    {
      "x": -15,
      "y": 12,
      "z": -7,
      "name": "Rock_Stone"
    },
    {
      "x": -15,
      "y": 13,
      "z": -7,
      "name": "Rock_Stone"
    },
    {
      "x": -15,
      "y": 14,
      "z": -7,
      "name": "Rock_Stone"
    },
    {
      "x": -15,
      "y": 15,
      "z": -7,
      "name": "Rock_Stone"
    },
    {
      "x": -15,
      "y": 16,
      "z": -7,
      "name": "Rock_Stone"
    },
    {
      "x": -15,
      "y": 17,
      "z": -7,
      "name": "Rock_Stone"
    },
    {
      "x": -15,
      "y": 18,
      "z": -7,
      "name": "Rock_Stone"
    },
    {
      "x": -15,
      "y": 19,
      "z": -7,
      "name": "Ore_Iron_Stone"
    },
    {
      "x": -15,
      "y": 20,
      "z": -7,
      "name": "Soil_Gravel_Mossy"
    },
    {
      "x": -15,
      "y": 12,
      "z": -6,
      "name": "Rock_Stone"
    },
    {
      "x": -15,
      "y": 13,
      "z": -6,
      "name": "Rock_Stone"
    },
    {
      "x": -15,
      "y": 14,
      "z": -6,
      "name": "Rock_Stone"
    },
    {
      "x": -15,
      "y": 15,
      "z": -6,
      "name": "Rock_Stone"
    },
    {
      "x": -15,
      "y": 16,
      "z": -6,
      "name": "Rock_Stone"
    },
    {
      "x": -15,
      "y": 17,
      "z": -6,
      "name": "Rock_Stone"
    },
    {
      "x": -15,
      "y": 18,
      "z": -6,
      "name": "Rock_Stone"
    },
    {
      "x": -15,
      "y": 19,
      "z": -6,
      "name": "Rock_Stone"
    },
    {
      "x": -15,
      "y": 20,
      "z": -6,
      "name": "Soil_Gravel"
    },
    {
      "x": -15,
      "y": 11,
      "z": -5,
      "name": "Rock_Stone"
    },
    {
      "x": -15,
      "y": 12,
      "z": -5,
      "name": "Rock_Stone"
    },
    {
      "x": -15,
      "y": 13,
      "z": -5,
      "name": "Rock_Stone"
    },
    {
      "x": -15,
      "y": 14,
      "z": -5,
      "name": "Rock_Stone"
    },
    {
      "x": -15,
      "y": 15,
      "z": -5,
      "name": "Rock_Stone"
    },
    {
      "x": -15,
      "y": 16,
      "z": -5,
      "name": "Rock_Stone"
    },
    {
      "x": -15,
      "y": 17,
      "z": -5,
      "name": "Rock_Stone"
    },
    {
      "x": -15,
      "y": 18,
      "z": -5,
      "name": "Rock_Stone"
    },
    {
      "x": -15,
      "y": 19,
      "z": -5,
      "name": "Rock_Stone"
    },
    {
      "x": -15,
      "y": 20,
      "z": -5,
      "name": "Soil_Gravel"
    },
    {
      "x": -15,
      "y": 9,
      "z": -4,
      "name": "Rock_Stone_Stalactite_Large",
      "filler": 31744,
      "rotation": 8
    },
    {
      "x": -15,
      "y": 10,
      "z": -4,
      "name": "Rock_Stone_Stalactite_Large",
      "rotation": 8
    },
    {
      "x": -15,
      "y": 11,
      "z": -4,
      "name": "Rock_Stone"
    },
    {
      "x": -15,
      "y": 12,
      "z": -4,
      "name": "Rock_Stone"
    },
    {
      "x": -15,
      "y": 13,
      "z": -4,
      "name": "Rock_Stone"
    },
    {
      "x": -15,
      "y": 14,
      "z": -4,
      "name": "Rock_Stone"
    },
    {
      "x": -15,
      "y": 15,
      "z": -4,
      "name": "Rock_Stone"
    },
    {
      "x": -15,
      "y": 16,
      "z": -4,
      "name": "Rock_Stone"
    },
    {
      "x": -15,
      "y": 17,
      "z": -4,
      "name": "Rock_Stone"
    },
    {
      "x": -15,
      "y": 18,
      "z": -4,
      "name": "Rock_Stone"
    },
    {
      "x": -15,
      "y": 19,
      "z": -4,
      "name": "Rock_Stone"
    },
    {
      "x": -15,
      "y": 20,
      "z": -4,
      "name": "Soil_Gravel"
    },
    {
      "x": -15,
      "y": 11,
      "z": -3,
      "name": "Rock_Stone"
    },
    {
      "x": -15,
      "y": 12,
      "z": -3,
      "name": "Rock_Stone"
    },
    {
      "x": -15,
      "y": 13,
      "z": -3,
      "name": "Rock_Stone"
    },
    {
      "x": -15,
      "y": 14,
      "z": -3,
      "name": "Rock_Stone"
    },
    {
      "x": -15,
      "y": 15,
      "z": -3,
      "name": "Rock_Stone"
    },
    {
      "x": -15,
      "y": 16,
      "z": -3,
      "name": "Rock_Stone"
    },
    {
      "x": -15,
      "y": 17,
      "z": -3,
      "name": "Rock_Stone"
    },
    {
      "x": -15,
      "y": 18,
      "z": -3,
      "name": "Rock_Stone"
    },
    {
      "x": -15,
      "y": 19,
      "z": -3,
      "name": "Rock_Stone"
    },
    {
      "x": -15,
      "y": 20,
      "z": -3,
      "name": "Rock_Stone"
    },
    {
      "x": -15,
      "y": 21,
      "z": -3,
      "name": "Soil_Gravel"
    },
    {
      "x": -15,
      "y": 9,
      "z": -2,
      "name": "Rock_Stone_Stalactite_Large",
      "filler": 31744,
      "rotation": 8
    },
    {
      "x": -15,
      "y": 10,
      "z": -2,
      "name": "Rock_Stone_Stalactite_Large",
      "rotation": 8
    },
    {
      "x": -15,
      "y": 11,
      "z": -2,
      "name": "Rock_Stone"
    },
    {
      "x": -15,
      "y": 12,
      "z": -2,
      "name": "Rock_Stone"
    },
    {
      "x": -15,
      "y": 13,
      "z": -2,
      "name": "Rock_Stone"
    },
    {
      "x": -15,
      "y": 14,
      "z": -2,
      "name": "Rock_Stone"
    },
    {
      "x": -15,
      "y": 15,
      "z": -2,
      "name": "Rock_Stone"
    },
    {
      "x": -15,
      "y": 16,
      "z": -2,
      "name": "Rock_Stone"
    },
    {
      "x": -15,
      "y": 17,
      "z": -2,
      "name": "Rock_Stone"
    },
    {
      "x": -15,
      "y": 18,
      "z": -2,
      "name": "Rock_Stone"
    },
    {
      "x": -15,
      "y": 19,
      "z": -2,
      "name": "Rock_Stone"
    },
    {
      "x": -15,
      "y": 20,
      "z": -2,
      "name": "Rock_Stone"
    },
    {
      "x": -15,
      "y": 21,
      "z": -2,
      "name": "Soil_Gravel"
    },
    {
      "x": -15,
      "y": 11,
      "z": -1,
      "name": "Rock_Stone"
    },
    {
      "x": -15,
      "y": 12,
      "z": -1,
      "name": "Rock_Stone"
    },
    {
      "x": -15,
      "y": 13,
      "z": -1,
      "name": "Rock_Stone"
    },
    {
      "x": -15,
      "y": 14,
      "z": -1,
      "name": "Rock_Stone"
    },
    {
      "x": -15,
      "y": 15,
      "z": -1,
      "name": "Rock_Stone"
    },
    {
      "x": -15,
      "y": 16,
      "z": -1,
      "name": "Rock_Stone"
    },
    {
      "x": -15,
      "y": 17,
      "z": -1,
      "name": "Rock_Stone"
    },
    {
      "x": -15,
      "y": 18,
      "z": -1,
      "name": "Rock_Stone"
    },
    {
      "x": -15,
      "y": 19,
      "z": -1,
      "name": "Rock_Stone"
    },
    {
      "x": -15,
      "y": 20,
      "z": -1,
      "name": "Rock_Stone"
    },
    {
      "x": -15,
      "y": 21,
      "z": -1,
      "name": "Soil_Gravel"
    },
    {
      "x": -15,
      "y": 10,
      "z": 0,
      "name": "Rock_Stone_Stalactite_Large",
      "filler": 31744,
      "rotation": 8
    },
    {
      "x": -15,
      "y": 11,
      "z": 0,
      "name": "Rock_Stone_Stalactite_Large",
      "rotation": 8
    },
    {
      "x": -15,
      "y": 12,
      "z": 0,
      "name": "Rock_Stone"
    },
    {
      "x": -15,
      "y": 13,
      "z": 0,
      "name": "Rock_Stone"
    },
    {
      "x": -15,
      "y": 14,
      "z": 0,
      "name": "Rock_Stone"
    },
    {
      "x": -15,
      "y": 18,
      "z": 0,
      "name": "Rock_Stone"
    },
    {
      "x": -15,
      "y": 19,
      "z": 0,
      "name": "Rock_Stone"
    },
    {
      "x": -15,
      "y": 20,
      "z": 0,
      "name": "Rock_Stone"
    },
    {
      "x": -15,
      "y": 21,
      "z": 0,
      "name": "Soil_Gravel_Mossy"
    },
    {
      "x": -15,
      "y": 12,
      "z": 1,
      "name": "Rock_Stone"
    },
    {
      "x": -15,
      "y": 13,
      "z": 1,
      "name": "Rock_Stone"
    },
    {
      "x": -15,
      "y": 14,
      "z": 1,
      "name": "Rock_Crystal_Purple_Large"
    },
    {
      "x": -15,
      "y": 18,
      "z": 1,
      "name": "Rock_Stone"
    },
    {
      "x": -15,
      "y": 19,
      "z": 1,
      "name": "Rock_Stone"
    },
    {
      "x": -15,
      "y": 20,
      "z": 1,
      "name": "Rock_Stone"
    },
    {
      "x": -15,
      "y": 21,
      "z": 1,
      "name": "Soil_Gravel_Mossy"
    },
    {
      "x": -15,
      "y": 12,
      "z": 2,
      "name": "Rock_Stone"
    },
    {
      "x": -15,
      "y": 13,
      "z": 2,
      "name": "Rock_Stone"
    },
    {
      "x": -15,
      "y": 18,
      "z": 2,
      "name": "Rock_Stone"
    },
    {
      "x": -15,
      "y": 19,
      "z": 2,
      "name": "Rock_Stone"
    },
    {
      "x": -15,
      "y": 20,
      "z": 2,
      "name": "Rock_Stone"
    },
    {
      "x": -15,
      "y": 21,
      "z": 2,
      "name": "Rock_Stone"
    },
    {
      "x": -15,
      "y": 22,
      "z": 2,
      "name": "Soil_Gravel"
    },
    {
      "x": -15,
      "y": 12,
      "z": 3,
      "name": "Rock_Stone"
    },
    {
      "x": -15,
      "y": 13,
      "z": 3,
      "name": "Rock_Stone"
    },
    {
      "x": -15,
      "y": 17,
      "z": 3,
      "name": "Rock_Stone"
    },
    {
      "x": -15,
      "y": 18,
      "z": 3,
      "name": "Rock_Stone"
    },
    {
      "x": -15,
      "y": 19,
      "z": 3,
      "name": "Rock_Stone"
    },
    {
      "x": -15,
      "y": 20,
      "z": 3,
      "name": "Rock_Stone"
    },
    {
      "x": -15,
      "y": 21,
      "z": 3,
      "name": "Rock_Stone"
    },
    {
      "x": -15,
      "y": 22,
      "z": 3,
      "name": "Soil_Gravel"
    },
    {
      "x": -15,
      "y": 13,
      "z": 4,
      "name": "Rock_Stone"
    },
    {
      "x": -15,
      "y": 14,
      "z": 4,
      "name": "Rock_Stone"
    },
    {
      "x": -15,
      "y": 15,
      "z": 4,
      "name": "Rock_Stone"
    },
    {
      "x": -15,
      "y": 16,
      "z": 4,
      "name": "Rock_Stone"
    },
    {
      "x": -15,
      "y": 17,
      "z": 4,
      "name": "Rock_Stone"
    },
    {
      "x": -15,
      "y": 18,
      "z": 4,
      "name": "Rock_Stone"
    },
    {
      "x": -15,
      "y": 19,
      "z": 4,
      "name": "Rock_Stone"
    },
    {
      "x": -15,
      "y": 20,
      "z": 4,
      "name": "Rock_Stone"
    },
    {
      "x": -15,
      "y": 21,
      "z": 4,
      "name": "Rock_Stone"
    },
    {
      "x": -15,
      "y": 22,
      "z": 4,
      "name": "Soil_Gravel"
    },
    {
      "x": -15,
      "y": 14,
      "z": 5,
      "name": "Rock_Stone"
    },
    {
      "x": -15,
      "y": 15,
      "z": 5,
      "name": "Rock_Stone"
    },
    {
      "x": -15,
      "y": 16,
      "z": 5,
      "name": "Rock_Stone"
    },
    {
      "x": -15,
      "y": 17,
      "z": 5,
      "name": "Rock_Stone"
    },
    {
      "x": -15,
      "y": 18,
      "z": 5,
      "name": "Rock_Stone"
    },
    {
      "x": -15,
      "y": 19,
      "z": 5,
      "name": "Rock_Stone"
    },
    {
      "x": -15,
      "y": 20,
      "z": 5,
      "name": "Rock_Stone"
    },
    {
      "x": -15,
      "y": 21,
      "z": 5,
      "name": "Ore_Iron_Stone"
    },
    {
      "x": -15,
      "y": 22,
      "z": 5,
      "name": "Soil_Gravel_Mossy"
    },
    {
      "x": -15,
      "y": 15,
      "z": 6,
      "name": "Rock_Stone"
    },
    {
      "x": -15,
      "y": 16,
      "z": 6,
      "name": "Rock_Stone"
    },
    {
      "x": -15,
      "y": 17,
      "z": 6,
      "name": "Rock_Stone"
    },
    {
      "x": -15,
      "y": 18,
      "z": 6,
      "name": "Rock_Stone"
    },
    {
      "x": -15,
      "y": 19,
      "z": 6,
      "name": "Rock_Stone"
    },
    {
      "x": -15,
      "y": 20,
      "z": 6,
      "name": "Rock_Stone"
    },
    {
      "x": -15,
      "y": 21,
      "z": 6,
      "name": "Ore_Iron_Stone"
    },
    {
      "x": -15,
      "y": 22,
      "z": 6,
      "name": "Soil_Gravel"
    },
    {
      "x": -15,
      "y": 11,
      "z": 7,
      "name": "Rock_Stone"
    },
    {
      "x": -15,
      "y": 12,
      "z": 7,
      "name": "Rock_Stone"
    },
    {
      "x": -15,
      "y": 13,
      "z": 7,
      "name": "Rock_Stone"
    },
    {
      "x": -15,
      "y": 14,
      "z": 7,
      "name": "Rock_Stone"
    },
    {
      "x": -15,
      "y": 15,
      "z": 7,
      "name": "Rock_Stone"
    },
    {
      "x": -15,
      "y": 16,
      "z": 7,
      "name": "Rock_Stone"
    },
    {
      "x": -15,
      "y": 17,
      "z": 7,
      "name": "Rock_Stone"
    },
    {
      "x": -15,
      "y": 18,
      "z": 7,
      "name": "Rock_Stone"
    },
    {
      "x": -15,
      "y": 19,
      "z": 7,
      "name": "Rock_Stone"
    },
    {
      "x": -15,
      "y": 20,
      "z": 7,
      "name": "Rock_Stone"
    },
    {
      "x": -15,
      "y": 21,
      "z": 7,
      "name": "Rock_Stone"
    },
    {
      "x": -15,
      "y": 22,
      "z": 7,
      "name": "Soil_Gravel"
    },
    {
      "x": -15,
      "y": 12,
      "z": 8,
      "name": "Rock_Stone"
    },
    {
      "x": -15,
      "y": 13,
      "z": 8,
      "name": "Rock_Stone"
    },
    {
      "x": -15,
      "y": 14,
      "z": 8,
      "name": "Rock_Stone"
    },
    {
      "x": -15,
      "y": 15,
      "z": 8,
      "name": "Rock_Stone"
    },
    {
      "x": -15,
      "y": 16,
      "z": 8,
      "name": "Rock_Stone"
    },
    {
      "x": -15,
      "y": 17,
      "z": 8,
      "name": "Rock_Stone"
    },
    {
      "x": -15,
      "y": 18,
      "z": 8,
      "name": "Rock_Stone"
    },
    {
      "x": -15,
      "y": 19,
      "z": 8,
      "name": "Rock_Stone"
    },
    {
      "x": -15,
      "y": 20,
      "z": 8,
      "name": "Rock_Stone"
    },
    {
      "x": -15,
      "y": 21,
      "z": 8,
      "name": "Rock_Stone"
    },
    {
      "x": -15,
      "y": 22,
      "z": 8,
      "name": "Soil_Gravel_Mossy"
    },
    {
      "x": -15,
      "y": 14,
      "z": 9,
      "name": "Rock_Stone"
    },
    {
      "x": -15,
      "y": 15,
      "z": 9,
      "name": "Rock_Stone"
    },
    {
      "x": -15,
      "y": 16,
      "z": 9,
      "name": "Rock_Stone"
    },
    {
      "x": -15,
      "y": 17,
      "z": 9,
      "name": "Rock_Stone"
    },
    {
      "x": -15,
      "y": 18,
      "z": 9,
      "name": "Rock_Stone"
    },
    {
      "x": -15,
      "y": 19,
      "z": 9,
      "name": "Rock_Stone"
    },
    {
      "x": -15,
      "y": 20,
      "z": 9,
      "name": "Rock_Stone"
    },
    {
      "x": -15,
      "y": 21,
      "z": 9,
      "name": "Rock_Stone"
    },
    {
      "x": -15,
      "y": 22,
      "z": 9,
      "name": "Rock_Stone"
    },
    {
      "x": -15,
      "y": 23,
      "z": 9,
      "name": "Soil_Gravel"
    },
    {
      "x": -15,
      "y": 15,
      "z": 10,
      "name": "Rock_Stone"
    },
    {
      "x": -15,
      "y": 16,
      "z": 10,
      "name": "Rock_Stone"
    },
    {
      "x": -15,
      "y": 17,
      "z": 10,
      "name": "Rock_Stone"
    },
    {
      "x": -15,
      "y": 18,
      "z": 10,
      "name": "Rock_Stone"
    },
    {
      "x": -15,
      "y": 19,
      "z": 10,
      "name": "Rock_Stone"
    },
    {
      "x": -15,
      "y": 20,
      "z": 10,
      "name": "Rock_Stone"
    },
    {
      "x": -15,
      "y": 21,
      "z": 10,
      "name": "Rock_Stone"
    },
    {
      "x": -15,
      "y": 22,
      "z": 10,
      "name": "Rock_Stone"
    },
    {
      "x": -15,
      "y": 23,
      "z": 10,
      "name": "Soil_Gravel"
    },
    {
      "x": -15,
      "y": 13,
      "z": 11,
      "name": "Rock_Stone"
    },
    {
      "x": -15,
      "y": 14,
      "z": 11,
      "name": "Rock_Stone"
    },
    {
      "x": -15,
      "y": 15,
      "z": 11,
      "name": "Rock_Stone"
    },
    {
      "x": -15,
      "y": 16,
      "z": 11,
      "name": "Rock_Stone"
    },
    {
      "x": -15,
      "y": 17,
      "z": 11,
      "name": "Rock_Stone"
    },
    {
      "x": -15,
      "y": 18,
      "z": 11,
      "name": "Rock_Stone"
    },
    {
      "x": -15,
      "y": 19,
      "z": 11,
      "name": "Rock_Stone"
    },
    {
      "x": -15,
      "y": 20,
      "z": 11,
      "name": "Rock_Stone"
    },
    {
      "x": -15,
      "y": 21,
      "z": 11,
      "name": "Rock_Stone"
    },
    {
      "x": -15,
      "y": 22,
      "z": 11,
      "name": "Soil_Gravel"
    },
    {
      "x": -15,
      "y": 15,
      "z": 12,
      "name": "Rock_Stone"
    },
    {
      "x": -15,
      "y": 16,
      "z": 12,
      "name": "Rock_Stone"
    },
    {
      "x": -15,
      "y": 17,
      "z": 12,
      "name": "Rock_Stone"
    },
    {
      "x": -15,
      "y": 18,
      "z": 12,
      "name": "Rock_Stone"
    },
    {
      "x": -15,
      "y": 19,
      "z": 12,
      "name": "Rock_Stone"
    },
    {
      "x": -15,
      "y": 20,
      "z": 12,
      "name": "Rock_Stone"
    },
    {
      "x": -15,
      "y": 21,
      "z": 12,
      "name": "Rock_Stone"
    },
    {
      "x": -15,
      "y": 22,
      "z": 12,
      "name": "Soil_Gravel"
    },
    {
      "x": -15,
      "y": 14,
      "z": 13,
      "name": "Rock_Stone_Stalactite_Large",
      "filler": 31744,
      "rotation": 8
    },
    {
      "x": -15,
      "y": 15,
      "z": 13,
      "name": "Rock_Stone_Stalactite_Large",
      "rotation": 8
    },
    {
      "x": -15,
      "y": 16,
      "z": 13,
      "name": "Rock_Stone"
    },
    {
      "x": -15,
      "y": 17,
      "z": 13,
      "name": "Rock_Stone"
    },
    {
      "x": -15,
      "y": 18,
      "z": 13,
      "name": "Rock_Stone"
    },
    {
      "x": -15,
      "y": 19,
      "z": 13,
      "name": "Rock_Stone"
    },
    {
      "x": -15,
      "y": 20,
      "z": 13,
      "name": "Ore_Copper_Stone"
    },
    {
      "x": -15,
      "y": 21,
      "z": 13,
      "name": "Rock_Stone"
    },
    {
      "x": -15,
      "y": 22,
      "z": 13,
      "name": "Soil_Gravel"
    },
    {
      "x": -15,
      "y": 20,
      "z": 14,
      "name": "Ore_Copper_Stone"
    },
    {
      "x": -15,
      "y": 21,
      "z": 14,
      "name": "Rock_Stone"
    },
    {
      "x": -15,
      "y": 22,
      "z": 14,
      "name": "Soil_Gravel"
    },
    {
      "x": -14,
      "y": 16,
      "z": -14,
      "name": "Rock_Stone"
    },
    {
      "x": -14,
      "y": 17,
      "z": -14,
      "name": "Rock_Stone"
    },
    {
      "x": -14,
      "y": 18,
      "z": -14,
      "name": "Rock_Stone"
    },
    {
      "x": -14,
      "y": 12,
      "z": -13,
      "name": "Rock_Stone"
    },
    {
      "x": -14,
      "y": 13,
      "z": -13,
      "name": "Rock_Stone"
    },
    {
      "x": -14,
      "y": 14,
      "z": -13,
      "name": "Rock_Stone"
    },
    {
      "x": -14,
      "y": 15,
      "z": -13,
      "name": "Rock_Stone"
    },
    {
      "x": -14,
      "y": 16,
      "z": -13,
      "name": "Rock_Stone"
    },
    {
      "x": -14,
      "y": 17,
      "z": -13,
      "name": "Rock_Stone"
    },
    {
      "x": -14,
      "y": 18,
      "z": -13,
      "name": "Rock_Stone"
    },
    {
      "x": -14,
      "y": 11,
      "z": -12,
      "name": "Rock_Stone"
    },
    {
      "x": -14,
      "y": 12,
      "z": -12,
      "name": "Rock_Stone"
    },
    {
      "x": -14,
      "y": 13,
      "z": -12,
      "name": "Rock_Stone"
    },
    {
      "x": -14,
      "y": 14,
      "z": -12,
      "name": "Rock_Stone"
    },
    {
      "x": -14,
      "y": 15,
      "z": -12,
      "name": "Rock_Stone"
    },
    {
      "x": -14,
      "y": 16,
      "z": -12,
      "name": "Rock_Stone"
    },
    {
      "x": -14,
      "y": 17,
      "z": -12,
      "name": "Rock_Stone"
    },
    {
      "x": -14,
      "y": 18,
      "z": -12,
      "name": "Rock_Stone"
    },
    {
      "x": -14,
      "y": 19,
      "z": -12,
      "name": "Rock_Stone"
    },
    {
      "x": -14,
      "y": 20,
      "z": -12,
      "name": "Rock_Stone_Stalactite_Large"
    },
    {
      "x": -14,
      "y": 21,
      "z": -12,
      "name": "Rock_Stone_Stalactite_Large",
      "filler": 1024
    },
    {
      "x": -14,
      "y": 11,
      "z": -11,
      "name": "Rock_Stone"
    },
    {
      "x": -14,
      "y": 12,
      "z": -11,
      "name": "Rock_Stone"
    },
    {
      "x": -14,
      "y": 13,
      "z": -11,
      "name": "Rock_Stone"
    },
    {
      "x": -14,
      "y": 14,
      "z": -11,
      "name": "Rock_Stone"
    },
    {
      "x": -14,
      "y": 15,
      "z": -11,
      "name": "Rock_Stone"
    },
    {
      "x": -14,
      "y": 16,
      "z": -11,
      "name": "Rock_Stone"
    },
    {
      "x": -14,
      "y": 17,
      "z": -11,
      "name": "Rock_Stone"
    },
    {
      "x": -14,
      "y": 18,
      "z": -11,
      "name": "Rock_Stone"
    },
    {
      "x": -14,
      "y": 19,
      "z": -11,
      "name": "Rock_Stone"
    },
    {
      "x": -14,
      "y": 10,
      "z": -10,
      "name": "Rock_Stone_Stalactite_Small",
      "rotation": 8
    },
    {
      "x": -14,
      "y": 11,
      "z": -10,
      "name": "Rock_Stone"
    },
    {
      "x": -14,
      "y": 12,
      "z": -10,
      "name": "Rock_Stone"
    },
    {
      "x": -14,
      "y": 13,
      "z": -10,
      "name": "Rock_Stone"
    },
    {
      "x": -14,
      "y": 14,
      "z": -10,
      "name": "Rock_Stone"
    },
    {
      "x": -14,
      "y": 15,
      "z": -10,
      "name": "Rock_Stone"
    },
    {
      "x": -14,
      "y": 16,
      "z": -10,
      "name": "Rock_Stone"
    },
    {
      "x": -14,
      "y": 17,
      "z": -10,
      "name": "Rock_Stone"
    },
    {
      "x": -14,
      "y": 18,
      "z": -10,
      "name": "Rock_Stone"
    },
    {
      "x": -14,
      "y": 19,
      "z": -10,
      "name": "Rock_Stone"
    },
    {
      "x": -14,
      "y": 20,
      "z": -10,
      "name": "Soil_Gravel"
    },
    {
      "x": -14,
      "y": 11,
      "z": -9,
      "name": "Rock_Stone"
    },
    {
      "x": -14,
      "y": 12,
      "z": -9,
      "name": "Rock_Stone"
    },
    {
      "x": -14,
      "y": 13,
      "z": -9,
      "name": "Rock_Stone"
    },
    {
      "x": -14,
      "y": 14,
      "z": -9,
      "name": "Rock_Stone"
    },
    {
      "x": -14,
      "y": 15,
      "z": -9,
      "name": "Rock_Stone"
    },
    {
      "x": -14,
      "y": 16,
      "z": -9,
      "name": "Rock_Stone"
    },
    {
      "x": -14,
      "y": 17,
      "z": -9,
      "name": "Rock_Stone"
    },
    {
      "x": -14,
      "y": 18,
      "z": -9,
      "name": "Rock_Stone"
    },
    {
      "x": -14,
      "y": 19,
      "z": -9,
      "name": "Rock_Stone"
    },
    {
      "x": -14,
      "y": 20,
      "z": -9,
      "name": "Soil_Gravel"
    },
    {
      "x": -14,
      "y": 8,
      "z": -8,
      "name": "Rock_Crystal_Purple_Medium",
      "rotation": 7
    },
    {
      "x": -14,
      "y": 9,
      "z": -8,
      "name": "Rock_Crystal_Purple_Medium",
      "rotation": 6
    },
    {
      "x": -14,
      "y": 11,
      "z": -8,
      "name": "Rock_Stone"
    },
    {
      "x": -14,
      "y": 12,
      "z": -8,
      "name": "Rock_Stone"
    },
    {
      "x": -14,
      "y": 13,
      "z": -8,
      "name": "Rock_Stone"
    },
    {
      "x": -14,
      "y": 14,
      "z": -8,
      "name": "Rock_Stone"
    },
    {
      "x": -14,
      "y": 15,
      "z": -8,
      "name": "Rock_Stone"
    },
    {
      "x": -14,
      "y": 16,
      "z": -8,
      "name": "Rock_Stone"
    },
    {
      "x": -14,
      "y": 17,
      "z": -8,
      "name": "Rock_Stone"
    },
    {
      "x": -14,
      "y": 18,
      "z": -8,
      "name": "Rock_Stone"
    },
    {
      "x": -14,
      "y": 19,
      "z": -8,
      "name": "Rock_Stone"
    },
    {
      "x": -14,
      "y": 20,
      "z": -8,
      "name": "Soil_Gravel"
    },
    {
      "x": -14,
      "y": 8,
      "z": -7,
      "name": "Rock_Crystal_Purple_Large",
      "rotation": 8
    },
    {
      "x": -14,
      "y": 9,
      "z": -7,
      "name": "Rock_Crystal_Purple_Block"
    },
    {
      "x": -14,
      "y": 10,
      "z": -7,
      "name": "Rock_Crystal_Purple_Block"
    },
    {
      "x": -14,
      "y": 11,
      "z": -7,
      "name": "Rock_Crystal_Purple_Block"
    },
    {
      "x": -14,
      "y": 12,
      "z": -7,
      "name": "Rock_Crystal_Purple_Block"
    },
    {
      "x": -14,
      "y": 13,
      "z": -7,
      "name": "Rock_Crystal_Purple_Block"
    },
    {
      "x": -14,
      "y": 14,
      "z": -7,
      "name": "Rock_Stone"
    },
    {
      "x": -14,
      "y": 15,
      "z": -7,
      "name": "Rock_Stone"
    },
    {
      "x": -14,
      "y": 16,
      "z": -7,
      "name": "Rock_Stone"
    },
    {
      "x": -14,
      "y": 17,
      "z": -7,
      "name": "Rock_Stone"
    },
    {
      "x": -14,
      "y": 18,
      "z": -7,
      "name": "Rock_Stone"
    },
    {
      "x": -14,
      "y": 19,
      "z": -7,
      "name": "Rock_Stone"
    },
    {
      "x": -14,
      "y": 20,
      "z": -7,
      "name": "Soil_Gravel"
    },
    {
      "x": -14,
      "y": 9,
      "z": -6,
      "name": "Rock_Crystal_Purple_Medium",
      "rotation": 7
    },
    {
      "x": -14,
      "y": 10,
      "z": -6,
      "name": "Rock_Crystal_Purple_Medium",
      "rotation": 4
    },
    {
      "x": -14,
      "y": 11,
      "z": -6,
      "name": "Rock_Stone_Stalactite_Small",
      "rotation": 8
    },
    {
      "x": -14,
      "y": 12,
      "z": -6,
      "name": "Rock_Stone"
    },
    {
      "x": -14,
      "y": 13,
      "z": -6,
      "name": "Rock_Stone"
    },
    {
      "x": -14,
      "y": 14,
      "z": -6,
      "name": "Rock_Stone"
    },
    {
      "x": -14,
      "y": 15,
      "z": -6,
      "name": "Rock_Stone"
    },
    {
      "x": -14,
      "y": 16,
      "z": -6,
      "name": "Rock_Stone"
    },
    {
      "x": -14,
      "y": 17,
      "z": -6,
      "name": "Rock_Stone"
    },
    {
      "x": -14,
      "y": 18,
      "z": -6,
      "name": "Rock_Stone"
    },
    {
      "x": -14,
      "y": 19,
      "z": -6,
      "name": "Ore_Copper_Stone"
    },
    {
      "x": -14,
      "y": 20,
      "z": -6,
      "name": "Rock_Stone"
    },
    {
      "x": -14,
      "y": 21,
      "z": -6,
      "name": "Soil_Gravel"
    },
    {
      "x": -14,
      "y": 12,
      "z": -5,
      "name": "Rock_Stone"
    },
    {
      "x": -14,
      "y": 13,
      "z": -5,
      "name": "Rock_Stone"
    },
    {
      "x": -14,
      "y": 14,
      "z": -5,
      "name": "Rock_Stone"
    },
    {
      "x": -14,
      "y": 15,
      "z": -5,
      "name": "Rock_Stone"
    },
    {
      "x": -14,
      "y": 16,
      "z": -5,
      "name": "Rock_Stone"
    },
    {
      "x": -14,
      "y": 17,
      "z": -5,
      "name": "Rock_Stone"
    },
    {
      "x": -14,
      "y": 18,
      "z": -5,
      "name": "Rock_Stone"
    },
    {
      "x": -14,
      "y": 19,
      "z": -5,
      "name": "Rock_Stone"
    },
    {
      "x": -14,
      "y": 20,
      "z": -5,
      "name": "Rock_Stone"
    },
    {
      "x": -14,
      "y": 21,
      "z": -5,
      "name": "Soil_Gravel"
    },
    {
      "x": -14,
      "y": 12,
      "z": -4,
      "name": "Rock_Stone"
    },
    {
      "x": -14,
      "y": 13,
      "z": -4,
      "name": "Rock_Stone"
    },
    {
      "x": -14,
      "y": 14,
      "z": -4,
      "name": "Rock_Stone"
    },
    {
      "x": -14,
      "y": 15,
      "z": -4,
      "name": "Rock_Stone"
    },
    {
      "x": -14,
      "y": 16,
      "z": -4,
      "name": "Rock_Stone"
    },
    {
      "x": -14,
      "y": 17,
      "z": -4,
      "name": "Rock_Stone"
    },
    {
      "x": -14,
      "y": 18,
      "z": -4,
      "name": "Rock_Stone"
    },
    {
      "x": -14,
      "y": 19,
      "z": -4,
      "name": "Rock_Stone"
    },
    {
      "x": -14,
      "y": 20,
      "z": -4,
      "name": "Ore_Iron_Stone"
    },
    {
      "x": -14,
      "y": 21,
      "z": -4,
      "name": "Soil_Gravel"
    },
    {
      "x": -14,
      "y": 11,
      "z": -3,
      "name": "Rock_Stone"
    },
    {
      "x": -14,
      "y": 12,
      "z": -3,
      "name": "Rock_Stone"
    },
    {
      "x": -14,
      "y": 13,
      "z": -3,
      "name": "Rock_Stone"
    },
    {
      "x": -14,
      "y": 14,
      "z": -3,
      "name": "Rock_Stone"
    },
    {
      "x": -14,
      "y": 15,
      "z": -3,
      "name": "Rock_Stone"
    },
    {
      "x": -14,
      "y": 16,
      "z": -3,
      "name": "Rock_Stone"
    },
    {
      "x": -14,
      "y": 17,
      "z": -3,
      "name": "Rock_Stone"
    },
    {
      "x": -14,
      "y": 18,
      "z": -3,
      "name": "Rock_Stone"
    },
    {
      "x": -14,
      "y": 19,
      "z": -3,
      "name": "Ore_Copper_Stone"
    },
    {
      "x": -14,
      "y": 20,
      "z": -3,
      "name": "Rock_Stone"
    },
    {
      "x": -14,
      "y": 21,
      "z": -3,
      "name": "Soil_Gravel_Mossy"
    },
    {
      "x": -14,
      "y": 10,
      "z": -2,
      "name": "Rock_Stone"
    },
    {
      "x": -14,
      "y": 11,
      "z": -2,
      "name": "Rock_Stone"
    },
    {
      "x": -14,
      "y": 12,
      "z": -2,
      "name": "Rock_Stone"
    },
    {
      "x": -14,
      "y": 13,
      "z": -2,
      "name": "Rock_Stone"
    },
    {
      "x": -14,
      "y": 14,
      "z": -2,
      "name": "Rock_Stone"
    },
    {
      "x": -14,
      "y": 15,
      "z": -2,
      "name": "Rock_Stone"
    },
    {
      "x": -14,
      "y": 16,
      "z": -2,
      "name": "Rock_Stone"
    },
    {
      "x": -14,
      "y": 17,
      "z": -2,
      "name": "Rock_Stone"
    },
    {
      "x": -14,
      "y": 18,
      "z": -2,
      "name": "Rock_Stone"
    },
    {
      "x": -14,
      "y": 19,
      "z": -2,
      "name": "Rock_Stone"
    },
    {
      "x": -14,
      "y": 20,
      "z": -2,
      "name": "Rock_Stone"
    },
    {
      "x": -14,
      "y": 21,
      "z": -2,
      "name": "Rock_Stone"
    },
    {
      "x": -14,
      "y": 22,
      "z": -2,
      "name": "Rock_Stone_Stalactite_Small"
    },
    {
      "x": -14,
      "y": 11,
      "z": -1,
      "name": "Rock_Stone"
    },
    {
      "x": -14,
      "y": 12,
      "z": -1,
      "name": "Rock_Stone"
    },
    {
      "x": -14,
      "y": 13,
      "z": -1,
      "name": "Rock_Stone"
    },
    {
      "x": -14,
      "y": 14,
      "z": -1,
      "name": "Rock_Stone"
    },
    {
      "x": -14,
      "y": 15,
      "z": -1,
      "name": "Rock_Stone"
    },
    {
      "x": -14,
      "y": 16,
      "z": -1,
      "name": "Rock_Stone"
    },
    {
      "x": -14,
      "y": 17,
      "z": -1,
      "name": "Rock_Stone"
    },
    {
      "x": -14,
      "y": 18,
      "z": -1,
      "name": "Rock_Stone"
    },
    {
      "x": -14,
      "y": 19,
      "z": -1,
      "name": "Rock_Stone"
    },
    {
      "x": -14,
      "y": 20,
      "z": -1,
      "name": "Rock_Stone"
    },
    {
      "x": -14,
      "y": 21,
      "z": -1,
      "name": "Rock_Stone"
    },
    {
      "x": -14,
      "y": 12,
      "z": 0,
      "name": "Rock_Stone"
    },
    {
      "x": -14,
      "y": 13,
      "z": 0,
      "name": "Rock_Stone"
    },
    {
      "x": -14,
      "y": 14,
      "z": 0,
      "name": "Rock_Stone"
    },
    {
      "x": -14,
      "y": 18,
      "z": 0,
      "name": "Rock_Stone"
    },
    {
      "x": -14,
      "y": 19,
      "z": 0,
      "name": "Rock_Stone"
    },
    {
      "x": -14,
      "y": 20,
      "z": 0,
      "name": "Rock_Stone"
    },
    {
      "x": -14,
      "y": 21,
      "z": 0,
      "name": "Rock_Stone"
    },
    {
      "x": -14,
      "y": 9,
      "z": 1,
      "name": "Rock_Stone_Stalactite_Large",
      "filler": 31744,
      "rotation": 8
    },
    {
      "x": -14,
      "y": 10,
      "z": 1,
      "name": "Rock_Stone_Stalactite_Large",
      "rotation": 8
    },
    {
      "x": -14,
      "y": 11,
      "z": 1,
      "name": "Rock_Stone"
    },
    {
      "x": -14,
      "y": 12,
      "z": 1,
      "name": "Rock_Stone"
    },
    {
      "x": -14,
      "y": 13,
      "z": 1,
      "name": "Rock_Stone"
    },
    {
      "x": -14,
      "y": 18,
      "z": 1,
      "name": "Rock_Stone"
    },
    {
      "x": -14,
      "y": 19,
      "z": 1,
      "name": "Rock_Stone"
    },
    {
      "x": -14,
      "y": 20,
      "z": 1,
      "name": "Rock_Stone"
    },
    {
      "x": -14,
      "y": 21,
      "z": 1,
      "name": "Soil_Gravel"
    },
    {
      "x": -14,
      "y": 11,
      "z": 2,
      "name": "Rock_Stone"
    },
    {
      "x": -14,
      "y": 12,
      "z": 2,
      "name": "Rock_Stone"
    },
    {
      "x": -14,
      "y": 13,
      "z": 2,
      "name": "Rock_Stone"
    },
    {
      "x": -14,
      "y": 18,
      "z": 2,
      "name": "Rock_Stone"
    },
    {
      "x": -14,
      "y": 19,
      "z": 2,
      "name": "Rock_Stone"
    },
    {
      "x": -14,
      "y": 20,
      "z": 2,
      "name": "Rock_Stone"
    },
    {
      "x": -14,
      "y": 21,
      "z": 2,
      "name": "Rock_Stone"
    },
    {
      "x": -14,
      "y": 22,
      "z": 2,
      "name": "Soil_Gravel_Mossy"
    },
    {
      "x": -14,
      "y": 9,
      "z": 3,
      "name": "Rock_Stone_Stalactite_Large",
      "filler": 31744,
      "rotation": 8
    },
    {
      "x": -14,
      "y": 10,
      "z": 3,
      "name": "Rock_Stone_Stalactite_Large",
      "rotation": 8
    },
    {
      "x": -14,
      "y": 11,
      "z": 3,
      "name": "Rock_Stone"
    },
    {
      "x": -14,
      "y": 12,
      "z": 3,
      "name": "Rock_Stone"
    },
    {
      "x": -14,
      "y": 13,
      "z": 3,
      "name": "Rock_Stone"
    },
    {
      "x": -14,
      "y": 14,
      "z": 3,
      "name": "Rock_Stone"
    },
    {
      "x": -14,
      "y": 15,
      "z": 3,
      "name": "Rock_Stone_Stalactite_Large"
    },
    {
      "x": -14,
      "y": 16,
      "z": 3,
      "name": "Rock_Stone_Stalactite_Large",
      "filler": 1024
    },
    {
      "x": -14,
      "y": 17,
      "z": 3,
      "name": "Rock_Stone"
    },
    {
      "x": -14,
      "y": 18,
      "z": 3,
      "name": "Rock_Stone"
    },
    {
      "x": -14,
      "y": 19,
      "z": 3,
      "name": "Rock_Stone"
    },
    {
      "x": -14,
      "y": 20,
      "z": 3,
      "name": "Rock_Stone"
    },
    {
      "x": -14,
      "y": 21,
      "z": 3,
      "name": "Rock_Stone"
    },
    {
      "x": -14,
      "y": 22,
      "z": 3,
      "name": "Soil_Gravel_Mossy"
    },
    {
      "x": -14,
      "y": 12,
      "z": 4,
      "name": "Rock_Stone"
    },
    {
      "x": -14,
      "y": 13,
      "z": 4,
      "name": "Rock_Stone"
    },
    {
      "x": -14,
      "y": 14,
      "z": 4,
      "name": "Rock_Stone"
    },
    {
      "x": -14,
      "y": 15,
      "z": 4,
      "name": "Rock_Stone"
    },
    {
      "x": -14,
      "y": 16,
      "z": 4,
      "name": "Rock_Stone"
    },
    {
      "x": -14,
      "y": 17,
      "z": 4,
      "name": "Rock_Stone"
    },
    {
      "x": -14,
      "y": 18,
      "z": 4,
      "name": "Rock_Stone"
    },
    {
      "x": -14,
      "y": 19,
      "z": 4,
      "name": "Rock_Stone"
    },
    {
      "x": -14,
      "y": 20,
      "z": 4,
      "name": "Rock_Stone"
    },
    {
      "x": -14,
      "y": 21,
      "z": 4,
      "name": "Rock_Stone"
    },
    {
      "x": -14,
      "y": 22,
      "z": 4,
      "name": "Soil_Gravel_Mossy"
    },
    {
      "x": -14,
      "y": 16,
      "z": 5,
      "name": "Rock_Stone"
    },
    {
      "x": -14,
      "y": 17,
      "z": 5,
      "name": "Rock_Stone"
    },
    {
      "x": -14,
      "y": 18,
      "z": 5,
      "name": "Rock_Stone"
    },
    {
      "x": -14,
      "y": 19,
      "z": 5,
      "name": "Rock_Stone"
    },
    {
      "x": -14,
      "y": 20,
      "z": 5,
      "name": "Rock_Stone"
    },
    {
      "x": -14,
      "y": 21,
      "z": 5,
      "name": "Rock_Stone"
    },
    {
      "x": -14,
      "y": 22,
      "z": 5,
      "name": "Soil_Gravel"
    },
    {
      "x": -14,
      "y": 15,
      "z": 6,
      "name": "Rock_Stone"
    },
    {
      "x": -14,
      "y": 16,
      "z": 6,
      "name": "Rock_Stone"
    },
    {
      "x": -14,
      "y": 17,
      "z": 6,
      "name": "Rock_Stone"
    },
    {
      "x": -14,
      "y": 18,
      "z": 6,
      "name": "Rock_Stone"
    },
    {
      "x": -14,
      "y": 19,
      "z": 6,
      "name": "Rock_Stone"
    },
    {
      "x": -14,
      "y": 20,
      "z": 6,
      "name": "Rock_Stone"
    },
    {
      "x": -14,
      "y": 21,
      "z": 6,
      "name": "Rock_Stone"
    },
    {
      "x": -14,
      "y": 22,
      "z": 6,
      "name": "Soil_Gravel"
    },
    {
      "x": -14,
      "y": 14,
      "z": 7,
      "name": "Rock_Stone"
    },
    {
      "x": -14,
      "y": 15,
      "z": 7,
      "name": "Rock_Stone"
    },
    {
      "x": -14,
      "y": 16,
      "z": 7,
      "name": "Rock_Stone"
    },
    {
      "x": -14,
      "y": 17,
      "z": 7,
      "name": "Rock_Stone"
    },
    {
      "x": -14,
      "y": 18,
      "z": 7,
      "name": "Rock_Stone"
    },
    {
      "x": -14,
      "y": 19,
      "z": 7,
      "name": "Rock_Stone"
    },
    {
      "x": -14,
      "y": 20,
      "z": 7,
      "name": "Rock_Stone"
    },
    {
      "x": -14,
      "y": 21,
      "z": 7,
      "name": "Rock_Stone"
    },
    {
      "x": -14,
      "y": 22,
      "z": 7,
      "name": "Soil_Gravel"
    },
    {
      "x": -14,
      "y": 14,
      "z": 8,
      "name": "Rock_Stone"
    },
    {
      "x": -14,
      "y": 15,
      "z": 8,
      "name": "Rock_Stone"
    },
    {
      "x": -14,
      "y": 16,
      "z": 8,
      "name": "Rock_Stone"
    },
    {
      "x": -14,
      "y": 17,
      "z": 8,
      "name": "Rock_Stone"
    },
    {
      "x": -14,
      "y": 18,
      "z": 8,
      "name": "Rock_Stone"
    },
    {
      "x": -14,
      "y": 19,
      "z": 8,
      "name": "Rock_Stone"
    },
    {
      "x": -14,
      "y": 20,
      "z": 8,
      "name": "Rock_Stone"
    },
    {
      "x": -14,
      "y": 21,
      "z": 8,
      "name": "Rock_Stone"
    },
    {
      "x": -14,
      "y": 22,
      "z": 8,
      "name": "Soil_Gravel"
    },
    {
      "x": -14,
      "y": 10,
      "z": 9,
      "name": "Rock_Crystal_Purple_Medium",
      "rotation": 7
    },
    {
      "x": -14,
      "y": 11,
      "z": 9,
      "name": "Rock_Crystal_Purple_Medium",
      "rotation": 7
    },
    {
      "x": -14,
      "y": 13,
      "z": 9,
      "name": "Rock_Crystal_Purple_Medium",
      "rotation": 7
    },
    {
      "x": -14,
      "y": 14,
      "z": 9,
      "name": "Rock_Stone"
    },
    {
      "x": -14,
      "y": 15,
      "z": 9,
      "name": "Rock_Stone"
    },
    {
      "x": -14,
      "y": 16,
      "z": 9,
      "name": "Rock_Stone"
    },
    {
      "x": -14,
      "y": 17,
      "z": 9,
      "name": "Rock_Stone"
    },
    {
      "x": -14,
      "y": 18,
      "z": 9,
      "name": "Rock_Stone"
    },
    {
      "x": -14,
      "y": 19,
      "z": 9,
      "name": "Rock_Stone"
    },
    {
      "x": -14,
      "y": 20,
      "z": 9,
      "name": "Rock_Stone"
    },
    {
      "x": -14,
      "y": 21,
      "z": 9,
      "name": "Rock_Stone"
    },
    {
      "x": -14,
      "y": 22,
      "z": 9,
      "name": "Soil_Gravel"
    },
    {
      "x": -14,
      "y": 15,
      "z": 10,
      "name": "Rock_Stone"
    },
    {
      "x": -14,
      "y": 16,
      "z": 10,
      "name": "Rock_Stone"
    },
    {
      "x": -14,
      "y": 17,
      "z": 10,
      "name": "Rock_Stone"
    },
    {
      "x": -14,
      "y": 18,
      "z": 10,
      "name": "Rock_Stone"
    },
    {
      "x": -14,
      "y": 19,
      "z": 10,
      "name": "Rock_Stone"
    },
    {
      "x": -14,
      "y": 20,
      "z": 10,
      "name": "Rock_Stone"
    },
    {
      "x": -14,
      "y": 21,
      "z": 10,
      "name": "Rock_Stone"
    },
    {
      "x": -14,
      "y": 22,
      "z": 10,
      "name": "Rock_Stone"
    },
    {
      "x": -14,
      "y": 23,
      "z": 10,
      "name": "Soil_Gravel"
    },
    {
      "x": -14,
      "y": 12,
      "z": 11,
      "name": "Rock_Stone"
    },
    {
      "x": -14,
      "y": 13,
      "z": 11,
      "name": "Rock_Stone"
    },
    {
      "x": -14,
      "y": 14,
      "z": 11,
      "name": "Rock_Stone"
    },
    {
      "x": -14,
      "y": 15,
      "z": 11,
      "name": "Rock_Stone"
    },
    {
      "x": -14,
      "y": 16,
      "z": 11,
      "name": "Rock_Stone"
    },
    {
      "x": -14,
      "y": 17,
      "z": 11,
      "name": "Rock_Stone"
    },
    {
      "x": -14,
      "y": 18,
      "z": 11,
      "name": "Rock_Stone"
    },
    {
      "x": -14,
      "y": 19,
      "z": 11,
      "name": "Rock_Stone"
    },
    {
      "x": -14,
      "y": 20,
      "z": 11,
      "name": "Rock_Stone"
    },
    {
      "x": -14,
      "y": 21,
      "z": 11,
      "name": "Rock_Stone"
    },
    {
      "x": -14,
      "y": 22,
      "z": 11,
      "name": "Rock_Stone"
    },
    {
      "x": -14,
      "y": 23,
      "z": 11,
      "name": "Soil_Gravel_Mossy"
    },
    {
      "x": -14,
      "y": 15,
      "z": 12,
      "name": "Rock_Stone"
    },
    {
      "x": -14,
      "y": 16,
      "z": 12,
      "name": "Rock_Stone"
    },
    {
      "x": -14,
      "y": 17,
      "z": 12,
      "name": "Rock_Stone"
    },
    {
      "x": -14,
      "y": 18,
