{
  "version": 8,
  "blockIdVersion": 11,
  "anchorX": 0,
  "anchorY": 0,
  "anchorZ": 0,
  "blocks": [
    {
      "x": -18,
      "y": 30,
      "z": -11,
      "name": "Rock_Slate"
    },
    {
      "x": -18,
      "y": 31,
      "z": -11,
      "name": "Rock_Slate"
    },
    {
      "x": -18,
      "y": 32,
      "z": -11,
      "name": "Rock_Slate"
    },
    {
      "x": -18,
      "y": 30,
      "z": -10,
      "name": "Rock_Slate"
    },
    {
      "x": -18,
      "y": 31,
      "z": -10,
      "name": "Rock_Slate"
    },
    {
      "x": -18,
      "y": 11,
      "z": 15,
      "name": "Rock_Slate"
    },
    {
      "x": -18,
      "y": 12,
      "z": 15,
      "name": "Ore_Cobalt_Slate_Cracked"
    },
    {
      "x": -18,
      "y": 13,
      "z": 15,
      "name": "Soil_Slate_Gravel"
    },
    {
      "x": -18,
      "y": 14,
      "z": 15,
      "name": "Soil_Ash"
    },
    {
      "x": -18,
      "y": 8,
      "z": 16,
      "name": "Rock_Slate"
    },
    {
      "x": -18,
      "y": 9,
      "z": 16,
      "name": "Rock_Slate"
    },
    {
      "x": -18,
      "y": 10,
      "z": 16,
      "name": "Rock_Slate"
    },
    {
      "x": -18,
      "y": 11,
      "z": 16,
      "name": "Rock_Slate"
    },
    {
      "x": -18,
      "y": 12,
      "z": 16,
      "name": "Rock_Slate"
    },
    {
      "x": -18,
      "y": 13,
      "z": 16,
      "name": "Rock_Slate"
    },
    {
      "x": -18,
      "y": 14,
      "z": 16,
      "name": "Soil_Ash"
    },
    {
      "x": -18,
      "y": 15,
      "z": 16,
      "name": "Soil_Ash"
    },
    {
      "x": -18,
      "y": 7,
      "z": 17,
      "name": "Soil_Ash"
    },
    {
      "x": -18,
      "y": 8,
      "z": 17,
      "name": "Rock_Slate"
    },
    {
      "x": -18,
      "y": 9,
      "z": 17,
      "name": "Rock_Slate"
    },
    {
      "x": -18,
      "y": 10,
      "z": 17,
      "name": "Rock_Slate"
    },
    {
      "x": -18,
      "y": 11,
      "z": 17,
      "name": "Rock_Slate"
    },
    {
      "x": -18,
      "y": 12,
      "z": 17,
      "name": "Rock_Slate"
    },
    {
      "x": -18,
      "y": 13,
      "z": 17,
      "name": "Soil_Ash"
    },
    {
      "x": -18,
      "y": 14,
      "z": 17,
      "name": "Soil_Ash"
    },
    {
      "x": -18,
      "y": 15,
      "z": 17,
      "name": "Soil_Ash"
    },
    {
      "x": -18,
      "y": 8,
      "z": 18,
      "name": "Rock_Slate"
    },
    {
      "x": -18,
      "y": 9,
      "z": 18,
      "name": "Rock_Slate"
    },
    {
      "x": -18,
      "y": 10,
      "z": 18,
      "name": "Rock_Slate"
    },
    {
      "x": -18,
      "y": 11,
      "z": 18,
      "name": "Rock_Slate"
    },
    {
      "x": -18,
      "y": 12,
      "z": 18,
      "name": "Rock_Slate"
    },
    {
      "x": -18,
      "y": 13,
      "z": 18,
      "name": "Soil_Slate_Gravel"
    },
    {
      "x": -18,
      "y": 14,
      "z": 18,
      "name": "Soil_Ash"
    },
    {
      "x": -18,
      "y": 15,
      "z": 18,
      "name": "Soil_Slate_Gravel"
    },
    {
      "x": -18,
      "y": 9,
      "z": 19,
      "name": "Soil_Ash"
    },
    {
      "x": -18,
      "y": 11,
      "z": 19,
      "name": "Rock_Slate"
    },
    {
      "x": -18,
      "y": 12,
      "z": 19,
      "name": "Rock_Slate"
    },
    {
      "x": -18,
      "y": 13,
      "z": 19,
      "name": "Rock_Slate"
    },
    {
      "x": -18,
      "y": 14,
      "z": 19,
      "name": "Soil_Ash"
    },
    {
      "x": -17,
      "y": 30,
      "z": -13,
      "name": "Rock_Slate"
    },
    {
      "x": -17,
      "y": 31,
      "z": -13,
      "name": "Rock_Slate"
    },
    {
      "x": -17,
      "y": 28,
      "z": -12,
      "name": "Rock_Slate"
    },
    {
      "x": -17,
      "y": 29,
      "z": -12,
      "name": "Rock_Slate"
    },
    {
      "x": -17,
      "y": 30,
      "z": -12,
      "name": "Rock_Slate"
    },
    {
      "x": -17,
      "y": 31,
      "z": -12,
      "name": "Rock_Slate"
    },
    {
      "x": -17,
      "y": 32,
      "z": -12,
      "name": "Soil_Ash"
    },
    {
      "x": -17,
      "y": 27,
      "z": -11,
      "name": "Rock_Slate"
    },
    {
      "x": -17,
      "y": 28,
      "z": -11,
      "name": "Rock_Slate"
    },
    {
      "x": -17,
      "y": 29,
      "z": -11,
      "name": "Rock_Slate"
    },
    {
      "x": -17,
      "y": 30,
      "z": -11,
      "name": "Rock_Slate"
    },
    {
      "x": -17,
      "y": 31,
      "z": -11,
      "name": "Rock_Slate"
    },
    {
      "x": -17,
      "y": 32,
      "z": -11,
      "name": "Rock_Slate"
    },
    {
      "x": -17,
      "y": 26,
      "z": -10,
      "name": "Rock_Slate"
    },
    {
      "x": -17,
      "y": 27,
      "z": -10,
      "name": "Rock_Slate"
    },
    {
      "x": -17,
      "y": 28,
      "z": -10,
      "name": "Rock_Slate"
    },
    {
      "x": -17,
      "y": 29,
      "z": -10,
      "name": "Rock_Slate"
    },
    {
      "x": -17,
      "y": 30,
      "z": -10,
      "name": "Rock_Slate"
    },
    {
      "x": -17,
      "y": 31,
      "z": -10,
      "name": "Soil_Ash"
    },
    {
      "x": -17,
      "y": 32,
      "z": -10,
      "name": "Soil_Slate_Gravel"
    },
    {
      "x": -17,
      "y": 26,
      "z": -9,
      "name": "Rock_Slate"
    },
    {
      "x": -17,
      "y": 27,
      "z": -9,
      "name": "Rock_Slate"
    },
    {
      "x": -17,
      "y": 28,
      "z": -9,
      "name": "Rock_Slate"
    },
    {
      "x": -17,
      "y": 29,
      "z": -9,
      "name": "Rock_Slate"
    },
    {
      "x": -17,
      "y": 30,
      "z": -9,
      "name": "Rock_Slate"
    },
    {
      "x": -17,
      "y": 31,
      "z": -9,
      "name": "Soil_Ash"
    },
    {
      "x": -17,
      "y": 32,
      "z": -9,
      "name": "Soil_Ash"
    },
    {
      "x": -17,
      "y": 27,
      "z": -8,
      "name": "Rock_Slate"
    },
    {
      "x": -17,
      "y": 28,
      "z": -8,
      "name": "Rock_Slate"
    },
    {
      "x": -17,
      "y": 29,
      "z": -8,
      "name": "Soil_Ash"
    },
    {
      "x": -17,
      "y": 30,
      "z": -8,
      "name": "Soil_Ash"
    },
    {
      "x": -17,
      "y": 31,
      "z": -8,
      "name": "Rock_Slate"
    },
    {
      "x": -17,
      "y": 10,
      "z": 14,
      "name": "Rock_Slate"
    },
    {
      "x": -17,
      "y": 11,
      "z": 14,
      "name": "Rock_Slate"
    },
    {
      "x": -17,
      "y": 12,
      "z": 14,
      "name": "Ore_Cobalt_Slate_Cracked"
    },
    {
      "x": -17,
      "y": 13,
      "z": 14,
      "name": "Soil_Ash"
    },
    {
      "x": -17,
      "y": 14,
      "z": 14,
      "name": "Soil_Slate_Gravel"
    },
    {
      "x": -17,
      "y": 9,
      "z": 15,
      "name": "Rock_Slate"
    },
    {
      "x": -17,
      "y": 10,
      "z": 15,
      "name": "Rock_Slate"
    },
    {
      "x": -17,
      "y": 11,
      "z": 15,
      "name": "Rock_Slate"
    },
    {
      "x": -17,
      "y": 12,
      "z": 15,
      "name": "Rock_Slate"
    },
    {
      "x": -17,
      "y": 13,
      "z": 15,
      "name": "Soil_Ash"
    },
    {
      "x": -17,
      "y": 14,
      "z": 15,
      "name": "Soil_Ash"
    },
    {
      "x": -17,
      "y": 15,
      "z": 15,
      "name": "Soil_Ash"
    },
    {
      "x": -17,
      "y": 6,
      "z": 16,
      "name": "Rock_Slate"
    },
    {
      "x": -17,
      "y": 7,
      "z": 16,
      "name": "Rock_Slate"
    },
    {
      "x": -17,
      "y": 8,
      "z": 16,
      "name": "Rock_Slate"
    },
    {
      "x": -17,
      "y": 9,
      "z": 16,
      "name": "Rock_Slate"
    },
    {
      "x": -17,
      "y": 10,
      "z": 16,
      "name": "Rock_Slate"
    },
    {
      "x": -17,
      "y": 11,
      "z": 16,
      "name": "Rock_Slate"
    },
    {
      "x": -17,
      "y": 12,
      "z": 16,
      "name": "Rock_Slate"
    },
    {
      "x": -17,
      "y": 13,
      "z": 16,
      "name": "Soil_Slate_Gravel"
    },
    {
      "x": -17,
      "y": 14,
      "z": 16,
      "name": "Soil_Ash"
    },
    {
      "x": -17,
      "y": 15,
      "z": 16,
      "name": "Soil_Ash"
    },
    {
      "x": -17,
      "y": 16,
      "z": 16,
      "name": "Rock_Slate_Brick_Decorative"
    },
    {
      "x": -17,
      "y": 17,
      "z": 16,
      "name": "Rock_Slate_Brick_Pillar_Base"
    },
    {
      "x": -17,
      "y": 18,
      "z": 16,
      "name": "Rock_Slate_Brick_Pillar_Middle"
    },
    {
      "x": -17,
      "y": 19,
      "z": 16,
      "name": "Rubble_Slate"
    },
    {
      "x": -17,
      "y": 4,
      "z": 17,
      "name": "Rock_Crystal_Purple_Medium",
      "rotation": 7
    },
    {
      "x": -17,
      "y": 5,
      "z": 17,
      "name": "Rock_Crystal_Purple_Medium",
      "rotation": 7
    },
    {
      "x": -17,
      "y": 6,
      "z": 17,
      "name": "Rock_Slate"
    },
    {
      "x": -17,
      "y": 7,
      "z": 17,
      "name": "Rock_Slate"
    },
    {
      "x": -17,
      "y": 8,
      "z": 17,
      "name": "Rock_Slate"
    },
    {
      "x": -17,
      "y": 9,
      "z": 17,
      "name": "Rock_Slate"
    },
    {
      "x": -17,
      "y": 10,
      "z": 17,
      "name": "Rock_Slate"
    },
    {
      "x": -17,
      "y": 11,
      "z": 17,
      "name": "Rock_Slate"
    },
    {
      "x": -17,
      "y": 12,
      "z": 17,
      "name": "Rock_Slate"
    },
    {
      "x": -17,
      "y": 13,
      "z": 17,
      "name": "Rock_Slate"
    },
    {
      "x": -17,
      "y": 14,
      "z": 17,
      "name": "Soil_Ash"
    },
    {
      "x": -17,
      "y": 15,
      "z": 17,
      "name": "Rock_Slate"
    },
    {
      "x": -17,
      "y": 16,
      "z": 17,
      "name": "Rock_Slate_Brick"
    },
    {
      "x": -17,
      "y": 17,
      "z": 17,
      "name": "Rock_Slate_Brick_Pillar_Middle",
      "rotation": 4
    },
    {
      "x": -17,
      "y": 6,
      "z": 18,
      "name": "Rock_Slate"
    },
    {
      "x": -17,
      "y": 7,
      "z": 18,
      "name": "Rock_Slate"
    },
    {
      "x": -17,
      "y": 8,
      "z": 18,
      "name": "Rock_Slate"
    },
    {
      "x": -17,
      "y": 9,
      "z": 18,
      "name": "Rock_Slate"
    },
    {
      "x": -17,
      "y": 10,
      "z": 18,
      "name": "Rock_Slate"
    },
    {
      "x": -17,
      "y": 11,
      "z": 18,
      "name": "Rock_Slate"
    },
    {
      "x": -17,
      "y": 12,
      "z": 18,
      "name": "Rock_Slate"
    },
    {
      "x": -17,
      "y": 13,
      "z": 18,
      "name": "Rock_Slate"
    },
    {
      "x": -17,
      "y": 14,
      "z": 18,
      "name": "Soil_Slate_Gravel"
    },
    {
      "x": -17,
      "y": 15,
      "z": 18,
      "name": "Soil_Ash"
    },
    {
      "x": -17,
      "y": 16,
      "z": 18,
      "name": "Rock_Slate_Brick"
    },
    {
      "x": -17,
      "y": 17,
      "z": 18,
      "name": "Block_Spawner_Block",
      "components": {
        "Components": {
          "PlacedByInteraction": {
            "WhoPlacedUuid": {
              "$binary": "3XRzOktQTQGfL/+8x7+CHA==",
              "$type": "04"
            }
          },
          "BlockSpawner": {
            "BlockSpawnerId": "Zone4_Encounters_Tier4"
          }
        }
      },
      "rotation": 1
    },
    {
      "x": -17,
      "y": 5,
      "z": 19,
      "name": "Plant_Bush_Dead_Hanging"
    },
    {
      "x": -17,
      "y": 6,
      "z": 19,
      "name": "Rock_Slate"
    },
    {
      "x": -17,
      "y": 7,
      "z": 19,
      "name": "Rock_Slate"
    },
    {
      "x": -17,
      "y": 8,
      "z": 19,
      "name": "Rock_Slate"
    },
    {
      "x": -17,
      "y": 9,
      "z": 19,
      "name": "Rock_Slate"
    },
    {
      "x": -17,
      "y": 10,
      "z": 19,
      "name": "Rock_Slate"
    },
    {
      "x": -17,
      "y": 11,
      "z": 19,
      "name": "Rock_Slate"
    },
    {
      "x": -17,
      "y": 12,
      "z": 19,
      "name": "Rock_Slate"
    },
    {
      "x": -17,
      "y": 13,
      "z": 19,
      "name": "Soil_Ash"
    },
    {
      "x": -17,
      "y": 14,
      "z": 19,
      "name": "Soil_Ash"
    },
    {
      "x": -17,
      "y": 15,
      "z": 19,
      "name": "Soil_Slate_Gravel"
    },
    {
      "x": -17,
      "y": 16,
      "z": 19,
      "name": "Rock_Slate_Brick_Decorative"
    },
    {
      "x": -17,
      "y": 17,
      "z": 19,
      "name": "Rock_Slate_Brick_Pillar_Base"
    },
    {
      "x": -17,
      "y": 18,
      "z": 19,
      "name": "Rock_Slate_Brick_Pillar_Middle"
    },
    {
      "x": -17,
      "y": 19,
      "z": 19,
      "name": "Rubble_Slate"
    },
    {
      "x": -17,
      "y": 9,
      "z": 20,
      "name": "Rock_Slate"
    },
    {
      "x": -17,
      "y": 10,
      "z": 20,
      "name": "Rock_Slate"
    },
    {
      "x": -17,
      "y": 11,
      "z": 20,
      "name": "Rock_Slate"
    },
    {
      "x": -17,
      "y": 12,
      "z": 20,
      "name": "Rock_Slate"
    },
    {
      "x": -17,
      "y": 13,
      "z": 20,
      "name": "Soil_Ash"
    },
    {
      "x": -17,
      "y": 14,
      "z": 20,
      "name": "Rock_Slate"
    },
    {
      "x": -16,
      "y": 28,
      "z": -13,
      "name": "Rock_Slate"
    },
    {
      "x": -16,
      "y": 29,
      "z": -13,
      "name": "Rock_Slate"
    },
    {
      "x": -16,
      "y": 30,
      "z": -13,
      "name": "Rock_Slate"
    },
    {
      "x": -16,
      "y": 31,
      "z": -13,
      "name": "Rock_Slate"
    },
    {
      "x": -16,
      "y": 26,
      "z": -12,
      "name": "Rock_Slate"
    },
    {
      "x": -16,
      "y": 27,
      "z": -12,
      "name": "Rock_Slate"
    },
    {
      "x": -16,
      "y": 28,
      "z": -12,
      "name": "Rock_Slate"
    },
    {
      "x": -16,
      "y": 29,
      "z": -12,
      "name": "Rock_Slate"
    },
    {
      "x": -16,
      "y": 30,
      "z": -12,
      "name": "Rock_Slate"
    },
    {
      "x": -16,
      "y": 31,
      "z": -12,
      "name": "Rock_Slate"
    },
    {
      "x": -16,
      "y": 32,
      "z": -12,
      "name": "Soil_Slate_Gravel"
    },
    {
      "x": -16,
      "y": 25,
      "z": -11,
      "name": "Rock_Slate"
    },
    {
      "x": -16,
      "y": 26,
      "z": -11,
      "name": "Rock_Slate"
    },
    {
      "x": -16,
      "y": 27,
      "z": -11,
      "name": "Rock_Slate"
    },
    {
      "x": -16,
      "y": 28,
      "z": -11,
      "name": "Rock_Slate"
    },
    {
      "x": -16,
      "y": 29,
      "z": -11,
      "name": "Rock_Slate"
    },
    {
      "x": -16,
      "y": 30,
      "z": -11,
      "name": "Rock_Slate"
    },
    {
      "x": -16,
      "y": 31,
      "z": -11,
      "name": "Rock_Slate"
    },
    {
      "x": -16,
      "y": 32,
      "z": -11,
      "name": "Soil_Ash"
    },
    {
      "x": -16,
      "y": 33,
      "z": -11,
      "name": "Soil_Ash"
    },
    {
      "x": -16,
      "y": 25,
      "z": -10,
      "name": "Rock_Slate"
    },
    {
      "x": -16,
      "y": 26,
      "z": -10,
      "name": "Rock_Slate"
    },
    {
      "x": -16,
      "y": 27,
      "z": -10,
      "name": "Rock_Slate"
    },
    {
      "x": -16,
      "y": 28,
      "z": -10,
      "name": "Rock_Slate"
    },
    {
      "x": -16,
      "y": 29,
      "z": -10,
      "name": "Rock_Slate"
    },
    {
      "x": -16,
      "y": 30,
      "z": -10,
      "name": "Rock_Slate"
    },
    {
      "x": -16,
      "y": 31,
      "z": -10,
      "name": "Soil_Ash"
    },
    {
      "x": -16,
      "y": 32,
      "z": -10,
      "name": "Soil_Ash"
    },
    {
      "x": -16,
      "y": 33,
      "z": -10,
      "name": "Rock_Slate"
    },
    {
      "x": -16,
      "y": 24,
      "z": -9,
      "name": "Rock_Slate"
    },
    {
      "x": -16,
      "y": 25,
      "z": -9,
      "name": "Rock_Slate"
    },
    {
      "x": -16,
      "y": 26,
      "z": -9,
      "name": "Rock_Slate"
    },
    {
      "x": -16,
      "y": 27,
      "z": -9,
      "name": "Rock_Slate"
    },
    {
      "x": -16,
      "y": 28,
      "z": -9,
      "name": "Rock_Slate"
    },
    {
      "x": -16,
      "y": 29,
      "z": -9,
      "name": "Soil_Slate_Gravel"
    },
    {
      "x": -16,
      "y": 30,
      "z": -9,
      "name": "Rock_Slate"
    },
    {
      "x": -16,
      "y": 31,
      "z": -9,
      "name": "Soil_Ash"
    },
    {
      "x": -16,
      "y": 32,
      "z": -9,
      "name": "Soil_Ash"
    },
    {
      "x": -16,
      "y": 24,
      "z": -8,
      "name": "Rock_Slate"
    },
    {
      "x": -16,
      "y": 25,
      "z": -8,
      "name": "Rock_Slate"
    },
    {
      "x": -16,
      "y": 26,
      "z": -8,
      "name": "Rock_Slate"
    },
    {
      "x": -16,
      "y": 27,
      "z": -8,
      "name": "Rock_Slate"
    },
    {
      "x": -16,
      "y": 28,
      "z": -8,
      "name": "Rock_Slate"
    },
    {
      "x": -16,
      "y": 29,
      "z": -8,
      "name": "Rock_Slate"
    },
    {
      "x": -16,
      "y": 30,
      "z": -8,
      "name": "Soil_Ash"
    },
    {
      "x": -16,
      "y": 31,
      "z": -8,
      "name": "Soil_Ash"
    },
    {
      "x": -16,
      "y": 32,
      "z": -8,
      "name": "Soil_Slate_Gravel"
    },
    {
      "x": -16,
      "y": 24,
      "z": -7,
      "name": "Rock_Slate"
    },
    {
      "x": -16,
      "y": 25,
      "z": -7,
      "name": "Rock_Slate"
    },
    {
      "x": -16,
      "y": 26,
      "z": -7,
      "name": "Rock_Slate"
    },
    {
      "x": -16,
      "y": 27,
      "z": -7,
      "name": "Rock_Slate"
    },
    {
      "x": -16,
      "y": 28,
      "z": -7,
      "name": "Soil_Ash"
    },
    {
      "x": -16,
      "y": 29,
      "z": -7,
      "name": "Soil_Slate_Gravel"
    },
    {
      "x": -16,
      "y": 30,
      "z": -7,
      "name": "Soil_Ash"
    },
    {
      "x": -16,
      "y": 25,
      "z": -6,
      "name": "Rock_Slate"
    },
    {
      "x": -16,
      "y": 26,
      "z": -6,
      "name": "Rock_Slate"
    },
    {
      "x": -16,
      "y": 27,
      "z": -6,
      "name": "Rock_Slate"
    },
    {
      "x": -16,
      "y": 28,
      "z": -6,
      "name": "Rock_Slate"
    },
    {
      "x": -16,
      "y": 29,
      "z": -6,
      "name": "Soil_Slate_Gravel"
    },
    {
      "x": -16,
      "y": 30,
      "z": -6,
      "name": "Soil_Slate_Gravel"
    },
    {
      "x": -16,
      "y": 23,
      "z": -5,
      "name": "Plant_Crop_Mushroom_Block_Purple_Mycelium"
    },
    {
      "x": -16,
      "y": 24,
      "z": -5,
      "name": "Ore_Cobalt_Slate_Cracked"
    },
    {
      "x": -16,
      "y": 25,
      "z": -5,
      "name": "Rock_Slate"
    },
    {
      "x": -16,
      "y": 26,
      "z": -5,
      "name": "Rock_Slate"
    },
    {
      "x": -16,
      "y": 27,
      "z": -5,
      "name": "Soil_Ash"
    },
    {
      "x": -16,
      "y": 25,
      "z": -4,
      "name": "Rock_Slate"
    },
    {
      "x": -16,
      "y": 14,
      "z": 13,
      "name": "Soil_Slate_Gravel"
    },
    {
      "x": -16,
      "y": 8,
      "z": 14,
      "name": "Rock_Slate"
    },
    {
      "x": -16,
      "y": 9,
      "z": 14,
      "name": "Rock_Slate"
    },
    {
      "x": -16,
      "y": 10,
      "z": 14,
      "name": "Rock_Slate"
    },
    {
      "x": -16,
      "y": 11,
      "z": 14,
      "name": "Rock_Slate"
    },
    {
      "x": -16,
      "y": 12,
      "z": 14,
      "name": "Rock_Slate"
    },
    {
      "x": -16,
      "y": 13,
      "z": 14,
      "name": "Soil_Slate_Gravel"
    },
    {
      "x": -16,
      "y": 14,
      "z": 14,
      "name": "Rock_Slate"
    },
    {
      "x": -16,
      "y": 6,
      "z": 15,
      "name": "Rock_Slate"
    },
    {
      "x": -16,
      "y": 7,
      "z": 15,
      "name": "Rock_Slate"
    },
    {
      "x": -16,
      "y": 8,
      "z": 15,
      "name": "Rock_Slate"
    },
    {
      "x": -16,
      "y": 9,
      "z": 15,
      "name": "Rock_Slate"
    },
    {
      "x": -16,
      "y": 10,
      "z": 15,
      "name": "Rock_Slate"
    },
    {
      "x": -16,
      "y": 11,
      "z": 15,
      "name": "Rock_Slate"
    },
    {
      "x": -16,
      "y": 12,
      "z": 15,
      "name": "Rock_Slate"
    },
    {
      "x": -16,
      "y": 13,
      "z": 15,
      "name": "Soil_Slate_Gravel"
    },
    {
      "x": -16,
      "y": 14,
      "z": 15,
      "name": "Rock_Slate"
    },
    {
      "x": -16,
      "y": 15,
      "z": 15,
      "name": "Soil_Ash"
    },
    {
      "x": -16,
      "y": 16,
      "z": 15,
      "name": "Rock_Slate_Brick"
    },
    {
      "x": -16,
      "y": 17,
      "z": 15,
      "name": "Rubble_Slate_Medium"
    },
    {
      "x": -16,
      "y": 2,
      "z": 16,
      "name": "Rock_Crystal_Purple_Medium",
      "rotation": 7
    },
    {
      "x": -16,
      "y": 4,
      "z": 16,
      "name": "Rock_Crystal_Purple_Medium",
      "rotation": 6
    },
    {
      "x": -16,
      "y": 5,
      "z": 16,
      "name": "Rock_Slate"
    },
    {
      "x": -16,
      "y": 6,
      "z": 16,
      "name": "Rock_Slate"
    },
    {
      "x": -16,
      "y": 7,
      "z": 16,
      "name": "Rock_Slate"
    },
    {
      "x": -16,
      "y": 8,
      "z": 16,
      "name": "Rock_Slate"
    },
    {
      "x": -16,
      "y": 9,
      "z": 16,
      "name": "Rock_Slate"
    },
    {
      "x": -16,
      "y": 10,
      "z": 16,
      "name": "Rock_Slate"
    },
    {
      "x": -16,
      "y": 11,
      "z": 16,
      "name": "Rock_Slate"
    },
    {
      "x": -16,
      "y": 12,
      "z": 16,
      "name": "Rock_Slate"
    },
    {
      "x": -16,
      "y": 13,
      "z": 16,
      "name": "Rock_Slate"
    },
    {
      "x": -16,
      "y": 14,
      "z": 16,
      "name": "Rock_Slate"
    },
    {
      "x": -16,
      "y": 15,
      "z": 16,
      "name": "Rock_Slate"
    },
    {
      "x": -16,
      "y": 16,
      "z": 16,
      "name": "Rock_Slate_Brick"
    },
    {
      "x": -16,
      "y": 1,
      "z": 17,
      "name": "Rock_Crystal_Purple_Medium",
      "rotation": 7
    },
    {
      "x": -16,
      "y": 2,
      "z": 17,
      "name": "Rock_Crystal_Purple_Large",
      "rotation": 7
    },
    {
      "x": -16,
      "y": 3,
      "z": 17,
      "name": "Rock_Crystal_Purple_Large",
      "rotation": 8
    },
    {
      "x": -16,
      "y": 4,
      "z": 17,
      "name": "Rock_Crystal_Purple_Block"
    },
    {
      "x": -16,
      "y": 5,
      "z": 17,
      "name": "Rock_Crystal_Purple_Block"
    },
    {
      "x": -16,
      "y": 6,
      "z": 17,
      "name": "Rock_Slate"
    },
    {
      "x": -16,
      "y": 7,
      "z": 17,
      "name": "Rock_Slate"
    },
    {
      "x": -16,
      "y": 8,
      "z": 17,
      "name": "Rock_Slate"
    },
    {
      "x": -16,
      "y": 9,
      "z": 17,
      "name": "Rock_Slate"
    },
    {
      "x": -16,
      "y": 10,
      "z": 17,
      "name": "Rock_Slate"
    },
    {
      "x": -16,
      "y": 11,
      "z": 17,
      "name": "Rock_Slate"
    },
    {
      "x": -16,
      "y": 12,
      "z": 17,
      "name": "Rock_Slate"
    },
    {
      "x": -16,
      "y": 13,
      "z": 17,
      "name": "Soil_Slate_Gravel"
    },
    {
      "x": -16,
      "y": 14,
      "z": 17,
      "name": "Rock_Slate"
    },
    {
      "x": -16,
      "y": 15,
      "z": 17,
      "name": "Soil_Ash"
    },
    {
      "x": -16,
      "y": 16,
      "z": 17,
      "name": "Rock_Slate_Brick"
    },
    {
      "x": -16,
      "y": 17,
      "z": 17,
      "name": "Rubble_Slate"
    },
    {
      "x": -16,
      "y": 4,
      "z": 18,
      "name": "Rock_Crystal_Purple_Large",
      "rotation": 8
    },
    {
      "x": -16,
      "y": 5,
      "z": 18,
      "name": "Rock_Slate"
    },
    {
      "x": -16,
      "y": 6,
      "z": 18,
      "name": "Rock_Slate"
    },
    {
      "x": -16,
      "y": 7,
      "z": 18,
      "name": "Rock_Slate"
    },
    {
      "x": -16,
      "y": 8,
      "z": 18,
      "name": "Rock_Slate"
    },
    {
      "x": -16,
      "y": 9,
      "z": 18,
      "name": "Rock_Slate"
    },
    {
      "x": -16,
      "y": 10,
      "z": 18,
      "name": "Rock_Slate"
    },
    {
      "x": -16,
      "y": 11,
      "z": 18,
      "name": "Rock_Slate"
    },
    {
      "x": -16,
      "y": 12,
      "z": 18,
      "name": "Rock_Slate"
    },
    {
      "x": -16,
      "y": 13,
      "z": 18,
      "name": "Rock_Slate"
    },
    {
      "x": -16,
      "y": 14,
      "z": 18,
      "name": "Soil_Slate_Gravel"
    },
    {
      "x": -16,
      "y": 15,
      "z": 18,
      "name": "Rock_Slate"
    },
    {
      "x": -16,
      "y": 16,
      "z": 18,
      "name": "Rock_Slate_Brick"
    },
    {
      "x": -16,
      "y": 6,
      "z": 19,
      "name": "Rock_Slate"
    },
    {
      "x": -16,
      "y": 7,
      "z": 19,
      "name": "Rock_Slate"
    },
    {
      "x": -16,
      "y": 8,
      "z": 19,
      "name": "Rock_Slate"
    },
    {
      "x": -16,
      "y": 9,
      "z": 19,
      "name": "Rock_Slate"
    },
    {
      "x": -16,
      "y": 10,
      "z": 19,
      "name": "Rock_Slate"
    },
    {
      "x": -16,
      "y": 11,
      "z": 19,
      "name": "Rock_Slate"
    },
    {
      "x": -16,
      "y": 12,
      "z": 19,
      "name": "Rock_Slate"
    },
    {
      "x": -16,
      "y": 13,
      "z": 19,
      "name": "Rock_Slate"
    },
    {
      "x": -16,
      "y": 14,
      "z": 19,
      "name": "Soil_Slate_Gravel"
    },
    {
      "x": -16,
      "y": 15,
      "z": 19,
      "name": "Soil_Ash"
    },
    {
      "x": -16,
      "y": 16,
      "z": 19,
      "name": "Rock_Slate_Brick"
    },
    {
      "x": -16,
      "y": 6,
      "z": 20,
      "name": "Rock_Slate"
    },
    {
      "x": -16,
      "y": 7,
      "z": 20,
      "name": "Rock_Slate"
    },
    {
      "x": -16,
      "y": 8,
      "z": 20,
      "name": "Rock_Slate"
    },
    {
      "x": -16,
      "y": 9,
      "z": 20,
      "name": "Rock_Slate"
    },
    {
      "x": -16,
      "y": 10,
      "z": 20,
      "name": "Rock_Slate"
    },
    {
      "x": -16,
      "y": 11,
      "z": 20,
      "name": "Rock_Slate"
    },
    {
      "x": -16,
      "y": 12,
      "z": 20,
      "name": "Rock_Slate"
    },
    {
      "x": -16,
      "y": 13,
      "z": 20,
      "name": "Soil_Ash"
    },
    {
      "x": -16,
      "y": 14,
      "z": 20,
      "name": "Rock_Slate"
    },
    {
      "x": -16,
      "y": 15,
      "z": 20,
      "name": "Soil_Slate_Gravel"
    },
    {
      "x": -16,
      "y": 12,
      "z": 21,
      "name": "Rock_Slate"
    },
    {
      "x": -16,
      "y": 14,
      "z": 21,
      "name": "Rock_Slate"
    },
    {
      "x": -15,
      "y": 27,
      "z": -13,
      "name": "Rock_Slate"
    },
    {
      "x": -15,
      "y": 28,
      "z": -13,
      "name": "Rock_Slate"
    },
    {
      "x": -15,
      "y": 29,
      "z": -13,
      "name": "Rock_Slate"
    },
    {
      "x": -15,
      "y": 30,
      "z": -13,
      "name": "Rock_Slate"
    },
    {
      "x": -15,
      "y": 31,
      "z": -13,
      "name": "Rock_Slate"
    },
    {
      "x": -15,
      "y": 32,
      "z": -13,
      "name": "Rock_Slate"
    },
    {
      "x": -15,
      "y": 26,
      "z": -12,
      "name": "Rock_Slate"
    },
    {
      "x": -15,
      "y": 27,
      "z": -12,
      "name": "Rock_Slate"
    },
    {
      "x": -15,
      "y": 28,
      "z": -12,
      "name": "Rock_Slate"
    },
    {
      "x": -15,
      "y": 29,
      "z": -12,
      "name": "Rock_Slate"
    },
    {
      "x": -15,
      "y": 30,
      "z": -12,
      "name": "Rock_Slate"
    },
    {
      "x": -15,
      "y": 31,
      "z": -12,
      "name": "Rock_Slate"
    },
    {
      "x": -15,
      "y": 32,
      "z": -12,
      "name": "Rock_Slate"
    },
    {
      "x": -15,
      "y": 33,
      "z": -12,
      "name": "Soil_Ash"
    },
    {
      "x": -15,
      "y": 23,
      "z": -11,
      "name": "Plant_Crop_Mushroom_Block_Purple_Mycelium"
    },
    {
      "x": -15,
      "y": 24,
      "z": -11,
      "name": "Rock_Slate"
    },
    {
      "x": -15,
      "y": 25,
      "z": -11,
      "name": "Rock_Slate"
    },
    {
      "x": -15,
      "y": 26,
      "z": -11,
      "name": "Rock_Slate"
    },
    {
      "x": -15,
      "y": 27,
      "z": -11,
      "name": "Rock_Slate"
    },
    {
      "x": -15,
      "y": 28,
      "z": -11,
      "name": "Rock_Slate"
    },
    {
      "x": -15,
      "y": 29,
      "z": -11,
      "name": "Rock_Slate"
    },
    {
      "x": -15,
      "y": 30,
      "z": -11,
      "name": "Rock_Slate"
    },
    {
      "x": -15,
      "y": 31,
      "z": -11,
      "name": "Soil_Ash"
    },
    {
      "x": -15,
      "y": 32,
      "z": -11,
      "name": "Rock_Slate"
    },
    {
      "x": -15,
      "y": 33,
      "z": -11,
      "name": "Soil_Ash"
    },
    {
      "x": -15,
      "y": 23,
      "z": -10,
      "name": "Rock_Slate"
    },
    {
      "x": -15,
      "y": 24,
      "z": -10,
      "name": "Rock_Slate"
    },
    {
      "x": -15,
      "y": 25,
      "z": -10,
      "name": "Rock_Slate"
    },
    {
      "x": -15,
      "y": 26,
      "z": -10,
      "name": "Rock_Slate"
    },
    {
      "x": -15,
      "y": 27,
      "z": -10,
      "name": "Rock_Slate"
    },
    {
      "x": -15,
      "y": 28,
      "z": -10,
      "name": "Rock_Slate"
    },
    {
      "x": -15,
      "y": 29,
      "z": -10,
      "name": "Rock_Slate"
    },
    {
      "x": -15,
      "y": 30,
      "z": -10,
      "name": "Rock_Slate"
    },
    {
      "x": -15,
      "y": 31,
      "z": -10,
      "name": "Soil_Ash"
    },
    {
      "x": -15,
      "y": 32,
      "z": -10,
      "name": "Soil_Ash"
    },
    {
      "x": -15,
      "y": 33,
      "z": -10,
      "name": "Soil_Ash"
    },
    {
      "x": -15,
      "y": 34,
      "z": -10,
      "name": "Soil_Ash"
    },
    {
      "x": -15,
      "y": 21,
      "z": -9,
      "name": "Plant_Crop_Mushroom_Block_Purple_Mycelium"
    },
    {
      "x": -15,
      "y": 22,
      "z": -9,
      "name": "Plant_Bush_Dead_Hanging"
    },
    {
      "x": -15,
      "y": 23,
      "z": -9,
      "name": "Rock_Slate"
    },
    {
      "x": -15,
      "y": 24,
      "z": -9,
      "name": "Rock_Slate"
    },
    {
      "x": -15,
      "y": 25,
      "z": -9,
      "name": "Rock_Slate"
    },
    {
      "x": -15,
      "y": 26,
      "z": -9,
      "name": "Rock_Slate"
    },
    {
      "x": -15,
      "y": 27,
      "z": -9,
      "name": "Rock_Slate"
    },
    {
      "x": -15,
      "y": 28,
      "z": -9,
      "name": "Rock_Slate"
    },
    {
      "x": -15,
      "y": 29,
      "z": -9,
      "name": "Soil_Ash"
    },
    {
      "x": -15,
      "y": 30,
      "z": -9,
      "name": "Soil_Ash"
    },
    {
      "x": -15,
      "y": 31,
      "z": -9,
      "name": "Soil_Ash"
    },
    {
      "x": -15,
      "y": 32,
      "z": -9,
      "name": "Rock_Slate"
    },
    {
      "x": -15,
      "y": 33,
      "z": -9,
      "name": "Soil_Slate_Gravel"
    },
    {
      "x": -15,
      "y": 22,
      "z": -8,
      "name": "Ore_Cobalt_Slate_Cracked"
    },
    {
      "x": -15,
      "y": 23,
      "z": -8,
      "name": "Rock_Slate"
    },
    {
      "x": -15,
      "y": 24,
      "z": -8,
      "name": "Rock_Slate"
    },
    {
      "x": -15,
      "y": 25,
      "z": -8,
      "name": "Rock_Slate"
    },
    {
      "x": -15,
      "y": 26,
      "z": -8,
      "name": "Rock_Slate"
    },
    {
      "x": -15,
      "y": 27,
      "z": -8,
      "name": "Soil_Ash"
    },
    {
      "x": -15,
      "y": 28,
      "z": -8,
      "name": "Rock_Slate"
    },
    {
      "x": -15,
      "y": 29,
      "z": -8,
      "name": "Soil_Slate_Gravel"
    },
    {
      "x": -15,
      "y": 30,
      "z": -8,
      "name": "Soil_Ash"
    },
    {
      "x": -15,
      "y": 31,
      "z": -8,
      "name": "Soil_Ash"
    },
    {
      "x": -15,
      "y": 32,
      "z": -8,
      "name": "Soil_Slate_Gravel"
    },
    {
      "x": -15,
      "y": 33,
      "z": -8,
      "name": "Soil_Ash"
    },
    {
      "x": -15,
      "y": 22,
      "z": -7,
      "name": "Rock_Slate"
    },
    {
      "x": -15,
      "y": 23,
      "z": -7,
      "name": "Rock_Slate"
    },
    {
      "x": -15,
      "y": 24,
      "z": -7,
      "name": "Rock_Slate"
    },
    {
      "x": -15,
      "y": 25,
      "z": -7,
      "name": "Rock_Slate"
    },
    {
      "x": -15,
      "y": 26,
      "z": -7,
      "name": "Rock_Slate"
    },
    {
      "x": -15,
      "y": 27,
      "z": -7,
      "name": "Rock_Slate"
    },
    {
      "x": -15,
      "y": 28,
      "z": -7,
      "name": "Soil_Ash"
    },
    {
      "x": -15,
      "y": 29,
      "z": -7,
      "name": "Soil_Slate_Gravel"
    },
    {
      "x": -15,
      "y": 30,
      "z": -7,
      "name": "Rock_Slate"
    },
    {
      "x": -15,
      "y": 31,
      "z": -7,
      "name": "Soil_Slate_Gravel"
    },
    {
      "x": -15,
      "y": 32,
      "z": -7,
      "name": "Soil_Slate_Gravel"
    },
    {
      "x": -15,
      "y": 21,
      "z": -6,
      "name": "Rock_Slate"
    },
    {
      "x": -15,
      "y": 22,
      "z": -6,
      "name": "Rock_Slate"
    },
    {
      "x": -15,
      "y": 23,
      "z": -6,
      "name": "Rock_Slate"
    },
    {
      "x": -15,
      "y": 24,
      "z": -6,
      "name": "Rock_Slate"
    },
    {
      "x": -15,
      "y": 25,
      "z": -6,
      "name": "Rock_Slate"
    },
    {
      "x": -15,
      "y": 26,
      "z": -6,
      "name": "Rock_Slate"
    },
    {
      "x": -15,
      "y": 27,
      "z": -6,
      "name": "Rock_Slate"
    },
    {
      "x": -15,
      "y": 28,
      "z": -6,
      "name": "Soil_Ash"
    },
    {
      "x": -15,
      "y": 29,
      "z": -6,
      "name": "Soil_Ash"
    },
    {
      "x": -15,
      "y": 30,
      "z": -6,
      "name": "Soil_Slate_Gravel"
    },
    {
      "x": -15,
      "y": 31,
      "z": -6,
      "name": "Soil_Slate_Gravel"
    },
    {
      "x": -15,
      "y": 19,
      "z": -5,
      "name": "Plant_Crop_Mushroom_Block_Purple_Mycelium"
    },
    {
      "x": -15,
      "y": 20,
      "z": -5,
      "name": "Rock_Slate"
    },
    {
      "x": -15,
      "y": 21,
      "z": -5,
      "name": "Rock_Slate"
    },
    {
      "x": -15,
      "y": 22,
      "z": -5,
      "name": "Rock_Slate"
    },
    {
      "x": -15,
      "y": 23,
      "z": -5,
      "name": "Rock_Slate"
    },
    {
      "x": -15,
      "y": 24,
      "z": -5,
      "name": "Rock_Slate"
    },
    {
      "x": -15,
      "y": 25,
      "z": -5,
      "name": "Rock_Slate"
    },
    {
      "x": -15,
      "y": 26,
      "z": -5,
      "name": "Rock_Slate"
    },
    {
      "x": -15,
      "y": 27,
      "z": -5,
      "name": "Rock_Slate"
    },
    {
      "x": -15,
      "y": 28,
      "z": -5,
      "name": "Rock_Slate"
    },
    {
      "x": -15,
      "y": 29,
      "z": -5,
      "name": "Rock_Slate"
    },
    {
      "x": -15,
      "y": 30,
      "z": -5,
      "name": "Soil_Ash"
    },
    {
      "x": -15,
      "y": 18,
      "z": -4,
      "name": "Plant_Crop_Mushroom_Block_Purple_Mycelium"
    },
    {
      "x": -15,
      "y": 19,
      "z": -4,
      "name": "Ore_Cobalt_Slate_Cracked"
    },
    {
      "x": -15,
      "y": 20,
      "z": -4,
      "name": "Rock_Slate"
    },
    {
      "x": -15,
      "y": 21,
      "z": -4,
      "name": "Ore_Cobalt_Slate_Cracked"
    },
    {
      "x": -15,
      "y": 22,
      "z": -4,
      "name": "Rock_Slate"
    },
    {
      "x": -15,
      "y": 23,
      "z": -4,
      "name": "Rock_Slate"
    },
    {
      "x": -15,
      "y": 24,
      "z": -4,
      "name": "Soil_Ash"
    },
    {
      "x": -15,
      "y": 25,
      "z": -4,
      "name": "Soil_Ash"
    },
    {
      "x": -15,
      "y": 26,
      "z": -4,
      "name": "Soil_Slate_Gravel"
    },
    {
      "x": -15,
      "y": 27,
      "z": -4,
      "name": "Rock_Slate"
    },
    {
      "x": -15,
      "y": 28,
      "z": -4,
      "name": "Soil_Ash"
    },
    {
      "x": -15,
      "y": 19,
      "z": -3,
      "name": "Plant_Crop_Mushroom_Block_Purple_Mycelium"
    },
    {
      "x": -15,
      "y": 20,
      "z": -3,
      "name": "Rock_Slate"
    },
    {
      "x": -15,
      "y": 21,
      "z": -3,
      "name": "Rock_Slate"
    },
    {
      "x": -15,
      "y": 22,
      "z": -3,
      "name": "Rock_Slate"
    },
    {
      "x": -15,
      "y": 23,
      "z": -3,
      "name": "Soil_Slate_Gravel"
    },
    {
      "x": -15,
      "y": 24,
      "z": -3,
      "name": "Rock_Slate"
    },
    {
      "x": -15,
      "y": 25,
      "z": -3,
      "name": "Rock_Slate"
    },
    {
      "x": -15,
      "y": 26,
      "z": -3,
      "name": "Soil_Slate_Gravel"
    },
    {
      "x": -15,
      "y": 27,
      "z": -3,
      "name": "Soil_Slate_Gravel"
    },
    {
      "x": -15,
      "y": 21,
      "z": -2,
      "name": "Rock_Slate"
    },
    {
      "x": -15,
      "y": 22,
      "z": -2,
      "name": "Rock_Slate"
    },
    {
      "x": -15,
      "y": 23,
      "z": -2,
      "name": "Soil_Ash"
    },
    {
      "x": -15,
      "y": 24,
      "z": -2,
      "name": "Rock_Slate"
    },
    {
      "x": -15,
      "y": 25,
      "z": -2,
      "name": "Rock_Slate"
    },
    {
      "x": -15,
      "y": 26,
      "z": -2,
      "name": "Soil_Ash"
    },
    {
      "x": -15,
      "y": 27,
      "z": -2,
      "name": "Plant_Coral_Bush_Purple"
    },
    {
      "x": -15,
      "y": 25,
      "z": -1,
      "name": "Soil_Ash"
    },
    {
      "x": -15,
      "y": 18,
      "z": 4,
      "name": "Rock_Crystal_Pink_Small",
      "rotation": 7
    },
    {
      "x": -15,
      "y": 18,
      "z": 5,
      "name": "Plant_Coral_Bush_Violet"
    },
    {
      "x": -15,
      "y": 14,
      "z": 6,
      "name": "Soil_Ash"
    },
    {
      "x": -15,
      "y": 15,
      "z": 6,
      "name": "Soil_Ash"
    },
    {
      "x": -15,
      "y": 16,
      "z": 7,
      "name": "Rock_Crystal_Pink_Small",
      "rotation": 7
    },
    {
      "x": -15,
      "y": 17,
      "z": 7,
      "name": "Plant_Coral_Bush_Violet"
    },
    {
      "x": -15,
      "y": 13,
      "z": 13,
      "name": "Soil_Ash"
    },
    {
      "x": -15,
      "y": 7,
      "z": 14,
      "name": "Plant_Crop_Mushroom_Block_Purple_Mycelium"
    },
    {
      "x": -15,
      "y": 8,
      "z": 14,
      "name": "Rock_Slate"
    },
    {
      "x": -15,
      "y": 9,
      "z": 14,
      "name": "Rock_Slate"
    },
    {
      "x": -15,
      "y": 10,
      "z": 14,
      "name": "Rock_Slate"
    },
    {
      "x": -15,
      "y": 11,
      "z": 14,
      "name": "Rock_Slate"
    },
    {
      "x": -15,
      "y": 12,
      "z": 14,
      "name": "Rock_Slate"
    },
    {
      "x": -15,
      "y": 13,
      "z": 14,
      "name": "Soil_Ash"
    },
    {
      "x": -15,
      "y": 14,
      "z": 14,
      "name": "Soil_Ash"
    },
    {
      "x": -15,
      "y": 2,
      "z": 15,
      "name": "Rock_Crystal_Purple_Medium",
      "rotation": 6
    },
    {
      "x": -15,
      "y": 3,
      "z": 15,
      "name": "Rock_Crystal_Purple_Medium",
      "rotation": 6
    },
    {
      "x": -15,
      "y": 4,
      "z": 15,
      "name": "Rock_Crystal_Purple_Medium",
      "rotation": 6
    },
    {
      "x": -15,
      "y": 5,
      "z": 15,
      "name": "Rock_Slate"
    },
    {
      "x": -15,
      "y": 6,
      "z": 15,
      "name": "Rock_Slate"
    },
    {
      "x": -15,
      "y": 7,
      "z": 15,
      "name": "Rock_Slate"
    },
    {
      "x": -15,
      "y": 8,
      "z": 15,
      "name": "Rock_Slate"
    },
    {
      "x": -15,
      "y": 9,
      "z": 15,
      "name": "Rock_Slate"
    },
    {
      "x": -15,
      "y": 10,
      "z": 15,
      "name": "Rock_Slate"
    },
    {
      "x": -15,
      "y": 11,
      "z": 15,
      "name": "Rock_Slate"
    },
    {
      "x": -15,
      "y": 12,
      "z": 15,
      "name": "Rock_Slate"
    },
    {
      "x": -15,
      "y": 13,
      "z": 15,
      "name": "Soil_Ash"
    },
    {
      "x": -15,
      "y": 14,
      "z": 15,
      "name": "Soil_Slate_Gravel"
    },
    {
      "x": -15,
      "y": 15,
      "z": 15,
      "name": "Soil_Ash"
    },
    {
      "x": -15,
      "y": 16,
      "z": 15,
      "name": "Rubble_Slate_Medium"
    },
    {
      "x": -15,
      "y": 1,
      "z": 16,
      "name": "Rock_Crystal_Purple_Medium",
      "rotation": 6
    },
    {
      "x": -15,
      "y": 2,
      "z": 16,
      "name": "Rock_Crystal_Purple_Block"
    },
    {
      "x": -15,
      "y": 3,
      "z": 16,
      "name": "Rock_Crystal_Purple_Block"
    },
    {
      "x": -15,
      "y": 4,
      "z": 16,
      "name": "Rock_Crystal_Purple_Block"
    },
    {
      "x": -15,
      "y": 5,
      "z": 16,
      "name": "Rock_Crystal_Purple_Block"
    },
    {
      "x": -15,
      "y": 6,
      "z": 16,
      "name": "Rock_Slate"
    },
    {
      "x": -15,
      "y": 7,
      "z": 16,
      "name": "Rock_Slate"
    },
    {
      "x": -15,
      "y": 8,
      "z": 16,
      "name": "Rock_Slate"
    },
    {
      "x": -15,
      "y": 9,
      "z": 16,
      "name": "Rock_Slate"
    },
    {
      "x": -15,
      "y": 10,
      "z": 16,
      "name": "Rock_Slate"
    },
    {
      "x": -15,
      "y": 11,
      "z": 16,
      "name": "Rock_Slate"
    },
    {
      "x": -15,
      "y": 12,
      "z": 16,
      "name": "Rock_Slate"
    },
    {
      "x": -15,
      "y": 13,
      "z": 16,
      "name": "Rock_Slate"
    },
    {
      "x": -15,
      "y": 14,
      "z": 16,
      "name": "Soil_Slate_Gravel"
    },
    {
      "x": -15,
      "y": 15,
      "z": 16,
      "name": "Soil_Ash"
    },
    {
      "x": -15,
      "y": 16,
      "z": 16,
      "name": "Rock_Slate_Brick"
    },
    {
      "x": -15,
      "y": 17,
      "z": 16,
      "name": "Rubble_Slate_Medium"
    },
    {
      "x": -15,
      "y": 0,
      "z": 17,
      "name": "Rock_Crystal_Purple_Large",
      "rotation": 8
    },
    {
      "x": -15,
      "y": 1,
      "z": 17,
      "name": "Rock_Crystal_Purple_Block"
    },
    {
      "x": -15,
      "y": 2,
      "z": 17,
      "name": "Rock_Crystal_Purple_Block"
    },
    {
      "x": -15,
      "y": 3,
      "z": 17,
      "name": "Rock_Crystal_Purple_Block"
    },
    {
      "x": -15,
      "y": 4,
      "z": 17,
      "name": "Rock_Crystal_Purple_Block"
    },
    {
      "x": -15,
      "y": 5,
      "z": 17,
      "name": "Rock_Crystal_Purple_Block"
    },
    {
      "x": -15,
      "y": 6,
      "z": 17,
      "name": "Rock_Crystal_Purple_Block"
    },
    {
      "x": -15,
      "y": 7,
      "z": 17,
      "name": "Soil_Dirt"
    },
    {
      "x": -15,
      "y": 8,
      "z": 17,
      "name": "Spawn_Labyrinth_Purple_Circle"
    },
    {
      "x": -15,
      "y": 9,
      "z": 17,
      "name": "Rock_Slate"
    },
    {
      "x": -15,
      "y": 10,
      "z": 17,
      "name": "Rock_Slate"
    },
    {
      "x": -15,
      "y": 11,
      "z": 17,
      "name": "Rock_Slate"
    },
    {
      "x": -15,
      "y": 12,
      "z": 17,
      "name": "Rock_Slate"
    },
    {
      "x": -15,
      "y": 13,
      "z": 17,
      "name": "Soil_Ash"
    },
    {
      "x": -15,
      "y": 14,
      "z": 17,
      "name": "Soil_Ash"
    },
    {
      "x": -15,
      "y": 15,
      "z": 17,
      "name": "Soil_Ash"
    },
    {
      "x": -15,
      "y": 16,
      "z": 17,
      "name": "Rock_Slate_Brick"
    },
    {
      "x": -15,
      "y": 2,
      "z": 18,
      "name": "Rock_Crystal_Purple_Medium",
      "rotation": 8
    },
    {
      "x": -15,
      "y": 3,
      "z": 18,
      "name": "Rock_Crystal_Purple_Block"
    },
    {
      "x": -15,
      "y": 4,
      "z": 18,
      "name": "Rock_Crystal_Purple_Block"
    },
    {
      "x": -15,
      "y": 5,
      "z": 18,
      "name": "Rock_Slate"
    },
    {
      "x": -15,
      "y": 6,
      "z": 18,
      "name": "Rock_Slate"
    },
    {
      "x": -15,
      "y": 7,
      "z": 18,
      "name": "Rock_Slate"
    },
    {
      "x": -15,
      "y": 8,
      "z": 18,
      "name": "Rock_Slate"
    },
    {
      "x": -15,
      "y": 9,
      "z": 18,
      "name": "Rock_Slate"
    },
    {
      "x": -15,
      "y": 10,
      "z": 18,
      "name": "Rock_Slate"
    },
    {
      "x": -15,
      "y": 11,
      "z": 18,
      "name": "Rock_Slate"
    },
    {
      "x": -15,
      "y": 12,
      "z": 18,
      "name": "Rock_Slate"
    },
    {
      "x": -15,
      "y": 13,
      "z": 18,
      "name": "Soil_Slate_Gravel"
    },
    {
      "x": -15,
      "y": 14,
      "z": 18,
      "name": "Rock_Slate"
    },
    {
      "x": -15,
      "y": 15,
      "z": 18,
      "name": "Soil_Slate_Gravel"
    },
    {
      "x": -15,
      "y": 16,
      "z": 18,
      "name": "Rock_Slate_Brick"
    },
    {
      "x": -15,
      "y": 3,
      "z": 19,
      "name": "Rock_Crystal_Purple_Medium",
      "rotation": 4
    },
    {
      "x": -15,
      "y": 4,
      "z": 19,
      "name": "Rock_Crystal_Purple_Medium",
      "rotation": 8
    },
    {
      "x": -15,
      "y": 5,
      "z": 19,
      "name": "Rock_Slate"
    },
    {
      "x": -15,
      "y": 6,
      "z": 19,
      "name": "Rock_Slate"
    },
    {
      "x": -15,
      "y": 7,
      "z": 19,
      "name": "Rock_Slate"
    },
    {
      "x": -15,
      "y": 8,
      "z": 19,
      "name": "Rock_Slate"
    },
    {
      "x": -15,
      "y": 9,
      "z": 19,
      "name": "Rock_Slate"
    },
    {
      "x": -15,
      "y": 10,
      "z": 19,
      "name": "Rock_Slate"
    },
    {
      "x": -15,
      "y": 11,
      "z": 19,
      "name": "Rock_Slate"
    },
    {
      "x": -15,
      "y": 12,
      "z": 19,
      "name": "Rock_Slate"
    },
    {
      "x": -15,
      "y": 13,
      "z": 19,
      "name": "Soil_Slate_Gravel"
    },
    {
      "x": -15,
      "y": 14,
      "z": 19,
      "name": "Soil_Slate_Gravel"
    },
    {
      "x": -15,
      "y": 15,
      "z": 19,
      "name": "Soil_Ash"
    },
    {
      "x": -15,
      "y": 16,
      "z": 19,
      "name": "Rock_Slate_Brick"
    },
    {
      "x": -15,
      "y": 6,
      "z": 20,
      "name": "Rock_Slate"
    },
    {
      "x": -15,
      "y": 7,
      "z": 20,
      "name": "Rock_Slate"
    },
    {
      "x": -15,
      "y": 8,
      "z": 20,
      "name": "Rock_Slate"
    },
    {
      "x": -15,
      "y": 9,
      "z": 20,
      "name": "Rock_Slate"
    },
    {
      "x": -15,
      "y": 10,
      "z": 20,
      "name": "Rock_Slate"
    },
    {
      "x": -15,
      "y": 11,
      "z": 20,
      "name": "Rock_Slate"
    },
    {
      "x": -15,
      "y": 12,
      "z": 20,
      "name": "Rock_Slate"
    },
    {
      "x": -15,
      "y": 13,
      "z": 20,
      "name": "Soil_Ash"
    },
    {
      "x": -15,
      "y": 14,
      "z": 20,
      "name": "Rock_Slate"
    },
    {
      "x": -15,
      "y": 15,
      "z": 20,
      "name": "Rock_Slate"
    },
    {
      "x": -15,
      "y": 11,
      "z": 21,
      "name": "Rock_Slate"
    },
    {
      "x": -15,
      "y": 12,
      "z": 21,
      "name": "Rock_Slate"
    },
    {
      "x": -15,
      "y": 13,
      "z": 21,
      "name": "Rock_Slate"
    },
    {
      "x": -15,
      "y": 14,
      "z": 21,
      "name": "Rock_Slate"
    },
    {
      "x": -15,
      "y": 15,
      "z": 21,
      "name": "Plant_Flower_Bushy_Purple"
    },
    {
      "x": -14,
      "y": 27,
      "z": -13,
      "name": "Rock_Slate"
    },
    {
      "x": -14,
      "y": 28,
      "z": -13,
      "name": "Rock_Slate"
    },
    {
      "x": -14,
      "y": 29,
      "z": -13,
      "name": "Rock_Slate"
    },
    {
      "x": -14,
      "y": 30,
      "z": -13,
      "name": "Rock_Slate"
    },
    {
      "x": -14,
      "y": 31,
      "z": -13,
      "name": "Rock_Slate"
    },
    {
      "x": -14,
      "y": 32,
      "z": -13,
      "name": "Soil_Ash"
    },
    {
      "x": -14,
      "y": 24,
      "z": -12,
      "name": "Plant_Crop_Mushroom_Block_Purple_Mycelium"
    },
    {
      "x": -14,
      "y": 25,
      "z": -12,
      "name": "Rock_Slate"
    },
    {
      "x": -14,
      "y": 26,
      "z": -12,
      "name": "Rock_Slate"
    },
    {
      "x": -14,
      "y": 27,
      "z": -12,
      "name": "Rock_Slate"
    },
    {
      "x": -14,
      "y": 28,
      "z": -12,
      "name": "Rock_Slate"
    },
    {
      "x": -14,
      "y": 29,
      "z": -12,
      "name": "Rock_Slate"
    },
    {
      "x": -14,
      "y": 30,
      "z": -12,
      "name": "Rock_Slate"
    },
    {
      "x": -14,
      "y": 31,
      "z": -12,
      "name": "Rock_Slate"
    },
    {
      "x": -14,
      "y": 32,
      "z": -12,
      "name": "Soil_Ash"
    },
    {
      "x": -14,
      "y": 33,
      "z": -12,
      "name": "Plant_Coral_Model_Purple"
    },
    {
      "x": -14,
      "y": 23,
      "z": -11,
      "name": "Rock_Slate"
    },
    {
      "x": -14,
      "y": 24,
      "z": -11,
      "name": "Rock_Slate"
    },
    {
      "x": -14,
      "y": 25,
      "z": -11,
      "name": "Rock_Slate"
    },
    {
      "x": -14,
      "y": 26,
      "z": -11,
      "name": "Rock_Slate"
    },
    {
      "x": -14,
      "y": 27,
      "z": -11,
      "name": "Rock_Slate"
    },
    {
      "x": -14,
      "y": 28,
      "z": -11,
      "name": "Rock_Slate"
    },
    {
      "x": -14,
      "y": 29,
      "z": -11,
      "name": "Rock_Slate"
    },
    {
      "x": -14,
      "y": 30,
      "z": -11,
      "name": "Rock_Slate"
    },
    {
      "x": -14,
      "y": 31,
      "z": -11,
      "name": "Rock_Slate"
    },
    {
      "x": -14,
      "y": 32,
      "z": -11,
      "name": "Soil_Slate_Gravel"
    },
    {
      "x": -14,
      "y": 33,
      "z": -11,
      "name": "Soil_Ash"
    },
    {
      "x": -14,
      "y": 22,
      "z": -10,
      "name": "Rock_Slate"
    },
    {
      "x": -14,
      "y": 23,
      "z": -10,
      "name": "Rock_Slate"
    },
    {
      "x": -14,
      "y": 24,
      "z": -10,
      "name": "Rock_Slate"
    },
    {
      "x": -14,
      "y": 25,
      "z": -10,
      "name": "Rock_Slate"
    },
    {
      "x": -14,
      "y": 26,
      "z": -10,
      "name": "Rock_Slate"
    },
    {
      "x": -14,
      "y": 27,
      "z": -10,
      "name": "Rock_Slate"
    },
    {
      "x": -14,
      "y": 28,
      "z": -10,
      "name": "Rock_Slate"
    },
    {
      "x": -14,
      "y": 29,
      "z": -10,
      "name": "Rock_Slate"
    },
    {
      "x": -14,
      "y": 30,
      "z": -10,
      "name": "Rock_Slate"
    },
    {
      "x": -14,
      "y": 31,
      "z": -10,
      "name": "Soil_Slate_Gravel"
    },
    {
      "x": -14,
      "y": 32,
      "z": -10,
      "name": "Soil_Ash"
    },
    {
      "x": -14,
      "y": 33,
      "z": -10,
      "name": "Soil_Ash"
    },
    {
      "x": -14,
      "y": 21,
      "z": -9,
      "name": "Rock_Slate"
    },
    {
      "x": -14,
      "y": 22,
      "z": -9,
      "name": "Rock_Slate"
    },
    {
      "x": -14,
      "y": 23,
      "z": -9,
      "name": "Rock_Slate"
    },
    {
      "x": -14,
      "y": 24,
      "z": -9,
      "name": "Rock_Slate"
    },
    {
      "x": -14,
      "y": 25,
      "z": -9,
      "name": "Rock_Slate"
    },
    {
      "x": -14,
      "y": 26,
      "z": -9,
      "name": "Rock_Slate"
    },
    {
      "x": -14,
      "y": 27,
      "z": -9,
      "name": "Rock_Slate"
    },
    {
      "x": -14,
      "y": 28,
      "z": -9,
      "name": "Soil_Ash"
    },
    {
      "x": -14,
      "y": 29,
      "z": -9,
      "name": "Soil_Slate_Gravel"
    },
    {
      "x": -14,
      "y": 30,
      "z": -9,
      "name": "Soil_Ash"
    },
    {
      "x": -14,
      "y": 31,
      "z": -9,
      "name": "Soil_Ash"
    },
    {
      "x": -14,
      "y": 32,
      "z": -9,
      "name": "Soil_Ash"
    },
    {
      "x": -14,
      "y": 33,
      "z": -9,
      "name": "Soil_Ash"
    },
    {
      "x": -14,
      "y": 19,
      "z": -8,
      "name": "Plant_Bush_Dead_Hanging"
    },
    {
      "x": -14,
      "y": 20,
      "z": -8,
      "name": "Rock_Slate"
    },
    {
      "x": -14,
      "y": 21,
      "z": -8,
      "name": "Rock_Slate"
    },
    {
      "x": -14,
      "y": 22,
      "z": -8,
      "name": "Rock_Slate"
    },
    {
      "x": -14,
      "y": 23,
      "z": -8,
      "name": "Rock_Slate"
    },
    {
      "x": -14,
      "y": 24,
      "z": -8,
      "name": "Rock_Slate"
    },
    {
      "x": -14,
      "y": 25,
      "z": -8,
      "name": "Rock_Slate"
    },
    {
      "x": -14,
      "y": 26,
      "z": -8,
      "name": "Rock_Slate"
    },
    {
      "x": -14,
      "y": 27,
      "z": -8,
      "name": "Soil_Ash"
    },
    {
      "x": -14,
      "y": 28,
      "z": -8,
      "name": "Soil_Ash"
    },
    {
      "x": -14,
      "y": 29,
      "z": -8,
      "name": "Soil_Slate_Gravel"
    },
    {
      "x": -14,
      "y": 30,
      "z": -8,
      "name": "Soil_Ash"
    },
    {
      "x": -14,
      "y": 31,
      "z": -8,
      "name": "Soil_Ash"
    },
    {
      "x": -14,
      "y": 32,
      "z": -8,
      "name": "Soil_Ash"
    },
    {
      "x": -14,
      "y": 33,
      "z": -8,
      "name": "Rock_Slate"
    },
    {
      "x": -14,
      "y": 21,
      "z": -7,
      "name": "Rock_Slate"
    },
    {
      "x": -14,
      "y": 22,
      "z": -7,
      "name": "Rock_Slate"
    },
    {
      "x": -14,
      "y": 23,
      "z": -7,
      "name": "Rock_Slate"
    },
    {
      "x": -14,
      "y": 24,
      "z": -7,
      "name": "Rock_Slate"
    },
    {
      "x": -14,
      "y": 25,
      "z": -7,
      "name": "Rock_Slate"
    },
    {
      "x": -14,
      "y": 26,
      "z": -7,
      "name": "Rock_Slate"
    },
    {
      "x": -14,
      "y": 27,
      "z": -7,
      "name": "Rock_Slate"
    },
    {
      "x": -14,
      "y": 28,
      "z": -7,
      "name": "Rock_Slate"
    },
    {
      "x": -14,
      "y": 29,
      "z": -7,
      "name": "Rock_Slate"
    },
    {
      "x": -14,
      "y": 30,
      "z": -7,
      "name": "Soil_Slate_Gravel"
    },
    {
      "x": -14,
      "y": 31,
      "z": -7,
      "name": "Soil_Slate_Gravel"
    },
    {
      "x": -14,
      "y": 32,
      "z": -7,
      "name": "Soil_Slate_Gravel"
    },
    {
      "x": -14,
      "y": 19,
      "z": -6,
      "name": "Rock_Slate"
    },
    {
      "x": -14,
      "y": 20,
      "z": -6,
      "name": "Rock_Slate"
    },
    {
      "x": -14,
      "y": 21,
      "z": -6,
      "name": "Rock_Slate"
    },
    {
      "x": -14,
      "y": 22,
      "z": -6,
      "name": "Rock_Slate"
    },
    {
      "x": -14,
      "y": 23,
      "z": -6,
      "name": "Rock_Slate"
    },
    {
      "x": -14,
      "y": 24,
      "z": -6,
      "name": "Rock_Slate"
    },
    {
      "x": -14,
      "y": 25,
      "z": -6,
      "name": "Rock_Slate"
    },
    {
      "x": -14,
      "y": 26,
      "z": -6,
      "name": "Rock_Slate"
    },
    {
      "x": -14,
      "y": 27,
      "z": -6,
      "name": "Rock_Slate"
    },
    {
      "x": -14,
      "y": 28,
      "z": -6,
      "name": "Soil_Ash"
    },
    {
      "x": -14,
      "y": 29,
      "z": -6,
      "name": "Rock_Slate"
    },
    {
      "x": -14,
      "y": 30,
      "z": -6,
      "name": "Soil_Ash"
    },
    {
      "x": -14,
      "y": 31,
      "z": -6,
      "name": "Soil_Slate_Gravel"
    },
    {
      "x": -14,
      "y": 17,
      "z": -5,
      "name": "Plant_Crop_Mushroom_Block_Purple_Mycelium"
    },
    {
      "x": -14,
      "y": 18,
      "z": -5,
      "name": "Rock_Slate"
    },
    {
      "x": -14,
      "y": 19,
      "z": -5,
      "name": "Rock_Slate"
    },
    {
      "x": -14,
      "y": 20,
      "z": -5,
      "name": "Rock_Slate"
    },
    {
      "x": -14,
      "y": 21,
      "z": -5,
      "name": "Rock_Slate"
    },
    {
      "x": -14,
      "y": 22,
      "z": -5,
      "name": "Rock_Slate"
    },
    {
      "x": -14,
      "y": 23,
      "z": -5,
      "name": "Rock_Slate"
    },
    {
      "x": -14,
      "y": 24,
      "z": -5,
      "name": "Rock_Slate"
    },
    {
      "x": -14,
      "y": 25,
      "z": -5,
      "name": "Rock_Slate"
    },
    {
      "x": -14,
      "y": 26,
      "z": -5,
      "name": "Rock_Slate"
    },
    {
      "x": -14,
      "y": 27,
      "z": -5,
      "name": "Soil_Ash"
    },
    {
      "x": -14,
      "y": 28,
      "z": -5,
      "name": "Soil_Ash"
    },
    {
      "x": -14,
      "y": 29,
      "z": -5,
      "name": "Rock_Slate"
    },
    {
      "x": -14,
      "y": 30,
      "z": -5,
      "name": "Soil_Ash"
    },
    {
      "x": -14,
      "y": 16,
      "z": -4,
      "name": "Soil_Ash"
    },
    {
      "x": -14,
      "y": 17,
      "z": -4,
      "name": "Rock_Slate"
    },
    {
      "x": -14,
      "y": 18,
      "z": -4,
      "name": "Rock_Slate"
    },
    {
      "x": -14,
      "y": 19,
      "z": -4,
      "name": "Ore_Cobalt_Slate_Cracked"
    },
    {
      "x": -14,
      "y": 20,
      "z": -4,
      "name": "Rock_Slate"
    },
    {
      "x": -14,
      "y": 21,
      "z": -4,
      "name": "Rock_Slate"
    },
    {
      "x": -14,
      "y": 22,
      "z": -4,
      "name": "Rock_Slate"
    },
    {
      "x": -14,
      "y": 23,
      "z": -4,
      "name": "Rock_Slate"
    },
    {
      "x": -14,
      "y": 24,
      "z": -4,
      "name": "Soil_Ash"
    },
    {
      "x": -14,
      "y": 25,
      "z": -4,
      "name": "Rock_Slate"
    },
    {
      "x": -14,
      "y": 26,
      "z": -4,
      "name": "Rock_Slate"
    },
    {
      "x": -14,
      "y": 27,
      "z": -4,
      "name": "Rock_Slate"
    },
    {
      "x": -14,
      "y": 28,
      "z": -4,
      "name": "Rock_Slate"
    },
    {
      "x": -14,
      "y": 29,
      "z": -4,
      "name": "Soil_Slate_Gravel"
    },
    {
      "x": -14,
      "y": 17,
      "z": -3,
      "name": "Plant_Crop_Mushroom_Block_Purple_Mycelium"
    },
    {
      "x": -14,
      "y": 18,
      "z": -3,
      "name": "Rock_Slate"
    },
    {
      "x": -14,
      "y": 19,
      "z": -3,
      "name": "Rock_Slate"
    },
    {
      "x": -14,
      "y": 20,
      "z": -3,
      "name": "Ore_Cobalt_Slate_Cracked"
    },
    {
      "x": -14,
      "y": 21,
      "z": -3,
      "name": "Rock_Slate"
    },
    {
      "x": -14,
      "y": 22,
      "z": -3,
      "name": "Rock_Slate"
    },
    {
      "x": -14,
      "y": 23,
      "z": -3,
      "name": "Soil_Ash"
    },
    {
      "x": -14,
      "y": 24,
      "z": -3,
      "name": "Soil_Ash"
    },
    {
      "x": -14,
      "y": 25,
      "z": -3,
      "name": "Rock_Slate"
    },
    {
      "x": -14,
      "y": 26,
      "z": -3,
      "name": "Rock_Slate"
    },
    {
      "x": -14,
      "y": 27,
      "z": -3,
      "name": "Rock_Slate"
    },
    {
      "x": -14,
      "y": 28,
      "z": -3,
      "name": "Soil_Slate_Gravel"
    },
    {
      "x": -14,
      "y": 18,
      "z": -2,
      "name": "Soil_Slate_Gravel"
    },
    {
      "x": -14,
      "y": 19,
      "z": -2,
      "name": "Soil_Slate_Gravel"
    },
    {
      "x": -14,
      "y": 20,
      "z": -2,
      "name": "Rock_Slate"
    },
    {
      "x": -14,
      "y": 21,
      "z": -2,
      "name": "Rock_Slate"
    },
    {
      "x": -14,
      "y": 22,
      "z": -2,
      "name": "Soil_Ash"
    },
    {
      "x": -14,
      "y": 23,
      "z": -2,
      "name": "Soil_Ash"
    },
    {
      "x": -14,
      "y": 24,
      "z": -2,
      "name": "Rock_Slate"
    },
    {
      "x": -14,
      "y": 25,
      "z": -2,
      "name": "Soil_Ash"
    },
    {
      "x": -14,
      "y": 26,
      "z": -2,
      "name": "Soil_Ash"
    },
    {
      "x": -14,
      "y": 27,
      "z": -2,
      "name": "Soil_Ash"
    },
    {
      "x": -14,
      "y": 18,
      "z": -1,
      "name": "Plant_Crop_Mushroom_Block_Purple_Mycelium"
    },
    {
      "x": -14,
      "y": 19,
      "z": -1,
      "name": "Soil_Ash"
    },
    {
      "x": -14,
      "y": 20,
      "z": -1,
      "name": "Rock_Slate"
    },
    {
      "x": -14,
      "y": 21,
      "z": -1,
      "name": "Soil_Ash"
    },
    {
      "x": -14,
      "y": 22,
      "z": -1,
      "name": "Soil_Ash"
    },
    {
      "x": -14,
      "y": 23,
      "z": -1,
      "name": "Rock_Slate"
    },
    {
      "x": -14,
      "y": 24,
      "z": -1,
      "name": "Rock_Slate"
    },
    {
      "x": -14,
      "y": 25,
      "z": -1,
      "name": "Rock_Slate"
    },
    {
      "x": -14,
      "y": 26,
      "z": -1,
      "name": "Rock_Slate"
    },
    {
      "x": -14,
      "y": 21,
      "z": 0,
      "name": "Rock_Slate"
    },
    {
      "x": -14,
      "y": 22,
      "z": 0,
      "name": "Soil_Ash"
    },
    {
      "x": -14,
      "y": 23,
      "z": 0,
      "name": "Soil_Slate_Gravel"
    },
    {
      "x": -14,
      "y": 24,
      "z": 0,
      "name": "Soil_Ash"
    },
    {
      "x": -14,
      "y": 25,
      "z": 0,
      "name": "Rock_Slate"
    },
    {
      "x": -14,
      "y": 16,
      "z": 3,
      "name": "Plant_Crop_Mushroom_Block_Purple_Mycelium"
    },
    {
      "x": -14,
      "y": 17,
      "z": 3,
      "name": "Rock_Slate"
    },
    {
      "x": -14,
      "y": 18,
      "z": 3,
      "name": "Rock_Slate"
    },
    {
      "x": -14,
      "y": 19,
      "z": 3,
      "name": "Rock_Slate"
    },
    {
      "x": -14,
      "y": 20,
      "z": 3,
      "name": "Soil_Slate_Gravel"
    },
    {
      "x": -14,
      "y": 13,
      "z": 4,
      "name": "Ore_Cobalt_Slate_Cracked"
    },
    {
      "x": -14,
      "y": 14,
      "z": 4,
      "name": "Rock_Slate"
    },
    {
      "x": -14,
      "y": 15,
      "z": 4,
      "name": "Soil_Ash"
    },
    {
      "x": -14,
      "y": 16,
      "z": 4,
      "name": "Soil_Slate_Gravel"
    },
    {
      "x": -14,
      "y": 17,
      "z": 4,
      "name": "Soil_Ash"
    },
    {
      "x": -14,
      "y": 18,
      "z": 4,
      "name": "Plant_Coral_Block_Violet"
    },
    {
      "x": -14,
      "y": 19,
      "z": 4,
      "name": "Plant_Coral_Block_Violet"
    },
    {
      "x": -14,
      "y": 20,
      "z": 4,
      "name": "Plant_Coral_Bush_Violet"
    },
    {
      "x": -14,
      "y": 12,
      "z": 5,
      "name": "Rock_Slate"
    },
    {
      "x": -14,
      "y": 13,
      "z": 5,
      "name": "Rock_Slate"
    },
    {
      "x": -14,
      "y": 14,
      "z": 5,
      "name": "Soil_Slate_Gravel"
    },
    {
      "x": -14,
      "y": 15,
      "z": 5,
      "name": "Soil_Ash"
    },
    {
      "x": -14,
      "y": 16,
      "z": 5,
      "name": "Soil_Slate_Gravel"
    },
    {
      "x": -14,
      "y": 17,
      "z": 5,
      "name": "Plant_Coral_Block_Violet"
    },
    {
      "x": -14,
      "y": 18,
      "z": 5,
      "name": "Plant_Coral_Block_Violet"
    },
    {
      "x": -14,
      "y": 19,
      "z": 5,
      "name": "Soil_Slate_Gravel"
    },
    {
      "x": -14,
      "y": 20,
      "z": 5,
      "name": "Soil_Slate_Gravel"
    },
    {
      "x": -14,
      "y": 11,
      "z": 6,
      "name": "Ore_Cobalt_Slate_Cracked"
    },
    {
      "x": -14,
      "y": 12,
      "z": 6,
      "name": "Rock_Slate"
    },
    {
      "x": -14,
      "y": 13,
      "z": 6,
      "name": "Rock_Slate"
    },
    {
      "x": -14,
      "y": 14,
      "z": 6,
      "name": "Ore_Cobalt_Slate_Cracked"
    },
    {
      "x": -14,
      "y": 15,
      "z": 6,
      "name": "Rock_Slate"
    },
    {
      "x": -14,
      "y": 16,
      "z": 6,
      "name": "Soil_Ash"
    },
    {
      "x": -14,
      "y": 17,
      "z": 6,
      "name": "Plant_Coral_Block_Violet"
    },
    {
      "x": -14,
      "y": 18,
      "z": 6,
      "name": "Rock_Slate"
    },
    {
      "x": -14,
      "y": 19,
      "z": 6,
      "name": "Soil_Ash"
    },
    {
      "x": -14,
      "y": 20,
      "z": 6,
      "name": "Rock_Slate"
    },
    {
      "x": -14,
      "y": 12,
      "z": 7,
      "name": "Rock_Slate"
    },
    {
      "x": -14,
      "y": 13,
      "z": 7,
      "name": "Rock_Slate"
    },
    {
      "x": -14,
      "y": 14,
      "z": 7,
      "name": "Rock_Slate"
    },
    {
      "x": -14,
      "y": 15,
      "z": 7,
      "name": "Rock_Slate"
    },
    {
      "x": -14,
      "y": 16,
      "z": 7,
      "name": "Plant_Coral_Block_Violet"
    },
    {
      "x": -14,
      "y": 17,
      "z": 7,
      "name": "Plant_Coral_Block_Violet"
    },
    {
      "x": -14,
      "y": 18,
      "z": 7,
      "name": "Rock_Slate"
    },
    {
      "x": -14,
      "y": 19,
      "z": 7,
      "name": "Soil_Slate_Gravel"
    },
    {
      "x": -14,
      "y": 15,
      "z": 8,
      "name": "Rock_Slate"
    },
    {
      "x": -14,
      "y": 16,
      "z": 8,
      "name": "Rock_Slate"
    },
    {
      "x": -14,
      "y": 17,
      "z": 8,
      "name": "Rock_Slate"
    },
    {
      "x": -14,
      "y": 18,
      "z": 8,
      "name": "Soil_Ash"
    },
    {
      "x": -14,
      "y": 19,
      "z": 8,
      "name": "Rock_Slate"
    },
    {
      "x": -14,
      "y": 9,
      "z": 14,
      "name": "Rock_Slate"
    },
    {
      "x": -14,
      "y": 10,
      "z": 14,
      "name": "Rock_Slate"
    },
    {
      "x": -14,
      "y": 11,
      "z": 14,
      "name": "Rock_Slate"
    },
    {
      "x": -14,
      "y": 12,
      "z": 14,
      "name": "Rock_Slate"
    },
    {
      "x": -14,
      "y": 13,
      "z": 14,
      "name": "Soil_Ash"
    },
    {
      "x": -14,
      "y": 14,
      "z": 14,
      "name": "Soil_Ash"
    },
    {
      "x": -14,
      "y": 5,
      "z": 15,
      "name": "Plant_Crop_Mushroom_Block_Purple_Mycelium"
    },
    {
      "x": -14,
      "y": 6,
      "z": 15,
      "name": "Rock_Slate"
    },
    {
      "x": -14,
      "y": 7,
      "z": 15,
      "name": "Rock_Slate"
    },
    {
      "x": -14,
      "y": 8,
      "z": 15,
      "name": "Rock_Slate"
    },
    {
      "x": -14,
      "y": 9,
      "z": 15,
      "name": "Rock_Slate"
    },
    {
      "x": -14,
      "y": 10,
      "z": 15,
      "name": "Rock_Slate"
    },
    {
      "x": -14,
      "y": 11,
      "z": 15,
      "name": "Rock_Slate"
    },
    {
      "x": -14,
      "y": 12,
      "z": 15,
      "name": "Rock_Slate"
    },
    {
      "x": -14,
      "y": 13,
      "z": 15,
      "name": "Soil_Slate_Gravel"
    },
    {
      "x": -14,
      "y": 14,
      "z": 15,
      "name": "Soil_Ash"
    },
    {
      "x": -14,
      "y": 15,
      "z": 15,
      "name": "Soil_Ash"
    },
    {
      "x": -14,
      "y": 2,
      "z": 16,
      "name": "Rock_Crystal_Purple_Medium",
      "rotation": 6
    },
    {
      "x": -14,
      "y": 4,
      "z": 16,
      "name": "Rock_Crystal_Purple_Medium",
      "rotation": 5
    },
    {
      "x": -14,
      "y": 5,
      "z": 16,
      "name": "Rock_Slate"
    },
    {
      "x": -14,
      "y": 6,
      "z": 16,
      "name": "Rock_Slate"
    },
    {
      "x": -14,
      "y": 7,
      "z": 16,
      "name": "Rock_Slate"
    },
    {
      "x": -14,
      "y": 8,
      "z": 16,
      "name": "Rock_Slate"
    },
    {
      "x": -14,
      "y": 9,
      "z": 16,
      "name": "Rock_Slate"
    },
    {
      "x": -14,
      "y": 10,
      "z": 16,
      "name": "Rock_Slate"
    },
    {
      "x": -14,
      "y": 11,
      "z": 16,
      "name": "Rock_Slate"
    },
    {
      "x": -14,
      "y": 12,
      "z": 16,
      "name": "Rock_Slate"
    },
    {
      "x": -14,
      "y": 13,
      "z": 16,
      "name": "Soil_Ash"
    },
    {
      "x": -14,
      "y": 14,
      "z": 16,
      "name": "Soil_Ash"
    },
    {
      "x": -14,
      "y": 15,
      "z": 16,
      "name": "Rock_Slate"
    },
    {
      "x": -14,
      "y": 16,
      "z": 16,
      "name": "Rock_Slate_Brick_Decorative"
    },
    {
      "x": -14,
      "y": 17,
      "z": 16,
      "name": "Rock_Slate_Brick_Pillar_Base"
    },
    {
      "x": -14,
      "y": 18,
      "z": 16,
      "name": "Rock_Slate_Brick_Pillar_Middle"
    },
    {
      "x": -14,
      "y": 19,
      "z": 16,
      "name": "Rubble_Slate"
    },
    {
      "x": -14,
      "y": 2,
      "z": 17,
      "name": "Rock_Crystal_Purple_Block"
    },
    {
      "x": -14,
      "y": 3,
      "z": 17,
      "name": "Rock_Crystal_Purple_Block"
    },
    {
      "x": -14,
      "y": 4,
      "z": 17,
      "name": "Rock_Crystal_Purple_Block"
    },
    {
      "x": -14,
      "y": 5,
      "z": 17,
      "name": "Rock_Slate"
    },
    {
      "x": -14,
      "y": 6,
      "z": 17,
      "name": "Rock_Slate"
    },
    {
      "x": -14,
      "y": 7,
      "z": 17,
      "name": "Rock_Slate"
    },
    {
      "x": -14,
      "y": 8,
      "z": 17,
      "name": "Rock_Slate"
    },
    {
      "x": -14,
      "y": 9,
      "z": 17,
      "name": "Rock_Slate"
    },
    {
      "x": -14,
      "y": 10,
      "z": 17,
      "name": "Rock_Slate"
    },
    {
      "x": -14,
      "y": 11,
      "z": 17,
      "name": "Rock_Slate"
    },
    {
      "x": -14,
      "y": 12,
      "z": 17,
      "name": "Rock_Slate"
    },
    {
      "x": -14,
      "y": 13,
      "z": 17,
      "name": "Soil_Ash"
    },
    {
      "x": -14,
      "y": 14,
      "z": 17,
      "name": "Soil_Slate_Gravel"
    },
    {
      "x": -14,
      "y": 15,
      "z": 17,
      "name": "Soil_Slate_Gravel"
    },
    {
      "x": -14,
      "y": 16,
      "z": 17,
      "name": "Rock_Slate_Brick"
    },
    {
      "x": -14,
      "y": 17,
      "z": 17,
      "name": "Rubble_Slate"
    },
    {
      "x": -14,
      "y": 3,
      "z": 18,
      "name": "Rock_Crystal_Purple_Medium",
      "rotation": 4
    },
    {
      "x": -14,
      "y": 4,
      "z": 18,
      "name": "Rock_Crystal_Purple_Medium",
      "rotation": 4
    },
    {
      "x": -14,
      "y": 5,
      "z": 18,
      "name": "Rock_Slate"
    },
    {
      "x": -14,
      "y": 6,
      "z": 18,
      "name": "Rock_Slate"
    },
    {
      "x": -14,
      "y": 7,
      "z": 18,
      "name": "Rock_Slate"
    },
    {
      "x": -14,
      "y": 8,
      "z": 18,
      "name": "Rock_Slate"
    },
    {
      "x": -14,
      "y": 9,
      "z": 18,
      "name": "Rock_Slate"
    },
    {
      "x": -14,
      "y": 10,
      "z": 18,
      "name": "Rock_Slate"
    },
    {
      "x": -14,
      "y": 11,
      "z": 18,
      "name": "Rock_Slate"
    },
    {
      "x": -14,
      "y": 12,
      "z": 18,
      "name": "Rock_Slate"
    },
    {
      "x": -14,
      "y": 13,
      "z": 18,
      "name": "Soil_Ash"
    },
    {
      "x": -14,
      "y": 14,
      "z": 18,
      "name": "Rock_Slate"
    },
    {
      "x": -14,
      "y": 15,
      "z": 18,
      "name": "Soil_Slate_Gravel"
    },
    {
      "x": -14,
      "y": 16,
      "z": 18,
      "name": "Rock_Slate_Brick"
    },
    {
      "x": -14,
      "y": 6,
      "z": 19,
      "name": "Rock_Slate"
    },
    {
      "x": -14,
      "y": 7,
      "z": 19,
      "name": "Rock_Slate"
    },
    {
      "x": -14,
      "y": 8,
      "z": 19,
      "name": "Rock_Slate"
    },
    {
      "x": -14,
      "y": 9,
      "z": 19,
      "name": "Rock_Slate"
    },
    {
      "x": -14,
      "y": 10,
      "z": 19,
      "name": "Rock_Slate"
    },
    {
      "x": -14,
      "y": 11,
      "z": 19,
      "name": "Rock_Slate"
    },
    {
      "x": -14,
      "y": 12,
      "z": 19,
      "name": "Rock_Slate"
    },
    {
      "x": -14,
      "y": 13,
      "z": 19,
      "name": "Soil_Ash"
    },
    {
      "x": -14,
      "y": 14,
      "z": 19,
      "name": "Soil_Ash"
    },
    {
      "x": -14,
      "y": 15,
      "z": 19,
      "name": "Soil_Ash"
    },
    {
      "x": -14,
      "y": 16,
      "z": 19,
      "name": "Rock_Slate_Brick_Decorative"
    },
    {
      "x": -14,
      "y": 17,
      "z": 19,
      "name": "Rock_Slate_Brick_Pillar_Base"
    },
    {
      "x": -14,
      "y": 18,
      "z": 19,
      "name": "Rubble_Slate_Medium"
    },
    {
      "x": -14,
      "y": 8,
      "z": 20,
      "name": "Rock_Slate"
    },
    {
      "x": -14,
      "y": 9,
      "z": 20,
      "name": "Rock_Slate"
    },
    {
      "x": -14,
      "y": 10,
      "z": 20,
      "name": "Rock_Slate"
    },
    {
      "x": -14,
      "y": 11,
      "z": 20,
      "name": "Rock_Slate"
    },
    {
      "x": -14,
      "y": 12,
      "z": 20,
      "name": "Rock_Slate"
    },
    {
      "x": -14,
      "y": 13,
      "z": 20,
      "name": "Soil_Slate_Gravel"
    },
    {
      "x": -14,
      "y": 14,
      "z": 20,
      "name": "Soil_Ash"
    },
    {
      "x": -14,
      "y": 15,
      "z": 20,
      "name": "Soil_Ash"
    },
    {
      "x": -14,
      "y": 12,
      "z": 21,
      "name": "Rock_Slate"
    },
    {
      "x": -14,
      "y": 13,
      "z": 21,
      "name": "Rock_Slate"
    },
    {
      "x": -14,
      "y": 14,
      "z": 21,
      "name": "Soil_Slate_Gravel"
    },
    {
      "x": -13,
      "y": 28,
      "z": -13,
      "name": "Rock_Slate"
    },
    {
      "x": -13,
      "y": 29,
      "z": -13,
      "name": "Rock_Slate"
    },
    {
      "x": -13,
      "y": 30,
      "z": -13,
      "name": "Rock_Slate"
    },
    {
      "x": -13,
      "y": 31,
      "z": -13,
      "name": "Rock_Slate"
    },
    {
      "x": -13,
      "y": 26,
      "z": -12,
      "name": "Rock_Slate"
    },
    {
      "x": -13,
      "y": 27,
      "z": -12,
      "name": "Rock_Slate"
    },
    {
      "x": -13,
      "y": 28,
      "z": -12,
      "name": "Rock_Slate"
    },
    {
      "x": -13,
      "y": 29,
      "z": -12,
      "name": "Rock_Slate"
    },
    {
      "x": -13,
      "y": 30,
      "z": -12,
      "name": "Rock_Slate"
    },
    {
      "x": -13,
      "y": 31,
      "z": -12,
      "name": "Soil_Ash"
    },
    {
      "x": -13,
      "y": 32,
      "z": -12,
      "name": "Soil_Ash"
    },
    {
      "x": -13,
      "y": 33,
      "z": -12,
      "name": "Soil_Ash"
    },
    {
      "x": -13,
      "y": 23,
      "z": -11,
      "name": "Rock_Slate"
    },
    {
      "x": -13,
      "y": 24,
      "z": -11,
      "name": "Rock_Slate"
    },
    {
      "x": -13,
      "y": 25,
      "z": -11,
      "name": "Rock_Slate"
    },
    {
      "x": -13,
      "y": 26,
      "z": -11,
      "name": "Rock_Slate"
    },
    {
      "x": -13,
      "y": 27,
      "z": -11,
      "name": "Rock_Slate"
    },
    {
      "x": -13,
      "y": 28,
      "z": -11,
      "name": "Rock_Slate"
    },
    {
      "x": -13,
      "y": 29,
      "z": -11,
      "name": "Rock_Slate"
    },
    {
      "x": -13,
      "y": 30,
      "z": -11,
      "name": "Rock_Slate"
    },
    {
      "x": -13,
      "y": 31,
      "z": -11,
      "name": "Soil_Ash"
    },
    {
      "x": -13,
      "y": 32,
      "z": -11,
      "name": "Soil_Slate_Gravel"
    },
    {
      "x": -13,
      "y": 33,
      "z": -11,
      "name": "Soil_Slate_Gravel"
    },
    {
      "x": -13,
      "y": 21,
      "z": -10,
      "name": "Rock_Slate"
    },
    {
      "x": -13,
      "y": 22,
      "z": -10,
      "name": "Rock_Slate"
    },
    {
      "x": -13,
      "y": 23,
      "z": -10,
      "name": "Rock_Slate"
    },
    {
      "x": -13,
      "y": 24,
      "z": -10,
      "name": "Rock_Slate"
    },
    {
      "x": -13,
      "y": 25,
      "z": -10,
      "name": "Rock_Slate"
    },
    {
      "x": -13,
      "y": 26,
      "z": -10,
      "name": "Rock_Slate"
    },
    {
      "x": -13,
      "y": 27,
      "z": -10,
      "name": "Rock_Slate"
    },
    {
      "x": -13,
      "y": 28,
      "z": -10,
      "name": "Rock_Slate"
    },
    {
      "x": -13,
      "y": 29,
      "z": -10,
      "name": "Rock_Slate"
    },
    {
      "x": -13,
      "y": 30,
      "z": -10,
      "name": "Rock_Slate"
    },
    {
      "x": -13,
      "y": 31,
      "z": -10,
      "name": "Soil_Slate_Gravel"
    },
    {
      "x": -13,
      "y": 32,
      "z": -10,
      "name": "Soil_Ash"
    },
    {
      "x": -13,
      "y": 33,
      "z": -10,
      "name": "Rock_Slate"
    },
    {
      "x": -13,
      "y": 34,
      "z": -10,
      "name": "Soil_Ash"
    },
    {
      "x": -13,
      "y": 20,
      "z": -9,
      "name": "Rock_Slate"
    },
    {
      "x": -13,
      "y": 21,
      "z": -9,
      "name": "Rock_Slate"
    },
    {
      "x": -13,
      "y": 22,
      "z": -9,
      "name": "Rock_Slate"
    },
    {
      "x": -13,
      "y": 23,
      "z": -9,
      "name": "Rock_Slate"
    },
    {
      "x": -13,
      "y": 24,
      "z": -9,
      "name": "Rock_Slate"
    },
    {
      "x": -13,
      "y": 25,
      "z": -9,
      "name": "Rock_Slate"
    },
    {
      "x": -13,
      "y": 26,
      "z": -9,
      "name": "Rock_Slate"
    },
    {
      "x": -13,
      "y": 27,
      "z": -9,
      "name": "Rock_Slate"
    },
    {
      "x": -13,
      "y": 28,
      "z": -9,
      "name": "Rock_Slate"
    },
    {
      "x": -13,
      "y": 29,
      "z": -9,
      "name": "Soil_Slate_Gravel"
    },
    {
      "x": -13,
      "y": 30,
      "z": -9,
      "name": "Soil_Slate_Gravel"
    },
    {
      "x": -13,
      "y": 31,
      "z": -9,
      "name": "Soil_Slate_Gravel"
    },
    {
      "x": -13,
      "y": 32,
      "z": -9,
      "name": "Soil_Ash"
    },
    {
      "x": -13,
      "y": 33,
      "z": -9,
      "name": "Soil_Ash"
    },
    {
      "x": -13,
      "y": 20,
      "z": -8,
      "name": "Rock_Slate"
    },
    {
      "x": -13,
      "y": 21,
      "z": -8,
      "name": "Rock_Slate"
    },
    {
      "x": -13,
      "y": 22,
      "z": -8,
      "name": "Rock_Slate"
    },
    {
      "x": -13,
      "y": 23,
      "z": -8,
      "name": "Rock_Slate"
    },
    {
      "x": -13,
      "y": 24,
      "z": -8,
      "name": "Rock_Slate"
    },
    {
      "x": -13,
      "y": 25,
      "z": -8,
      "name": "Rock_Slate"
    },
    {
      "x": -13,
      "y": 26,
      "z": -8,
      "name": "Rock_Slate"
    },
    {
      "x": -13,
      "y": 27,
      "z": -8,
      "name": "Rock_Slate"
    },
    {
      "x": -13,
      "y": 28,
      "z": -8,
      "name": "Rock_Slate"
    },
    {
      "x": -13,
      "y": 29,
      "z": -8,
      "name": "Soil_Ash"
    },
    {
      "x": -13,
      "y": 30,
      "z": -8,
      "name": "Soil_Ash"
    },
    {
      "x": -13,
      "y": 31,
      "z": -8,
      "name": "Rock_Slate"
    },
    {
      "x": -13,
      "y": 32,
      "z": -8,
      "name": "Soil_Slate_Gravel"
    },
    {
      "x": -13,
      "y": 33,
      "z": -8,
      "name": "Rock_Slate"
    },
    {
      "x": -13,
      "y": 34,
      "z": -8,
      "name": "Plant_Coral_Bush_Purple"
    },
    {
      "x": -13,
      "y": 20,
      "z": -7,
      "name": "Rock_Slate"
    },
    {
      "x": -13,
      "y": 21,
      "z": -7,
      "name": "Ore_Cobalt_Slate_Cracked"
    },
    {
      "x": -13,
      "y": 22,
      "z": -7,
      "name": "Rock_Slate"
    },
    {
      "x": -13,
      "y": 23,
      "z": -7,
      "name": "Rock_Slate"
    },
    {
      "x": -13,
      "y": 24,
      "z": -7,
      "name": "Rock_Slate"
    },
    {
      "x": -13,
      "y": 25,
      "z": -7,
      "name": "Rock_Slate"
    },
    {
      "x": -13,
      "y": 26,
      "z": -7,
      "name": "Rock_Slate"
    },
    {
      "x": -13,
      "y": 27,
      "z": -7,
      "name": "Soil_Slate_Gravel"
    },
    {
      "x": -13,
      "y": 28,
      "z": -7,
      "name": "Soil_Slate_Gravel"
    },
    {
      "x": -13,
      "y": 29,
      "z": -7,
      "name": "Rock_Slate"
    },
    {
      "x": -13,
      "y": 30,
      "z": -7,
      "name": "Soil_Ash"
    },
    {
      "x": -13,
      "y": 31,
      "z": -7,
      "name": "Soil_Slate_Gravel"
    },
    {
      "x": -13,
      "y": 32,
      "z": -7,
      "name": "Rock_Slate"
    },
    {
      "x": -13,
      "y": 15,
      "z": -6,
      "name": "Plant_Bush_Dead_Hanging"
    },
    {
      "x": -13,
      "y": 16,
      "z": -6,
      "name": "Plant_Crop_Mushroom_Block_Purple_Mycelium"
    },
    {
      "x": -13,
      "y": 17,
      "z": -6,
      "name": "Plant_Crop_Mushroom_Block_Purple_Mycelium"
    },
    {
      "x": -13,
      "y": 18,
      "z": -6,
      "name": "Rock_Slate"
    },
    {
      "x": -13,
      "y": 19,
      "z": -6,
      "name": "Rock_Slate"
    },
    {
      "x": -13,
      "y": 20,
      "z": -6,
      "name": "Rock_Slate"
    },
    {
      "x": -13,
      "y": 21,
      "z": -6,
      "name": "Rock_Slate"
    },
    {
      "x": -13,
      "y": 22,
      "z": -6,
      "name": "Rock_Slate"
    },
    {
      "x": -13,
      "y": 23,
      "z": -6,
      "name": "Rock_Slate"
    },
    {
      "x": -13,
      "y": 24,
      "z": -6,
      "name": "Rock_Slate"
    },
    {
      "x": -13,
      "y": 25,
      "z": -6,
      "name": "Rock_Slate"
    },
    {
      "x": -13,
      "y": 26,
      "z": -6,
      "name": "Rock_Slate"
    },
    {
      "x": -13,
      "y": 27,
      "z": -6,
      "name": "Rock_Slate"
    },
    {
      "x": -13,
      "y": 28,
      "z": -6,
      "name": "Rock_Slate"
    },
    {
      "x": -13,
      "y": 29,
      "z": -6,
      "name": "Rock_Slate"
    },
    {
      "x": -13,
      "y": 30,
      "z": -6,
      "name": "Rock_Slate"
    },
    {
      "x": -13,
      "y": 31,
      "z": -6,
      "name": "Soil_Ash"
    },
    {
      "x": -13,
      "y": 32,
      "z": -6,
      "name": "Soil_Slate_Gravel"
    },
    {
      "x": -13,
      "y": 16,
      "z": -5,
      "name": "Soil_Slate_Gravel"
    },
    {
      "x": -13,
      "y": 17,
      "z": -5,
      "name": "Rock_Slate"
    },
    {
      "x": -13,
      "y": 18,
      "z": -5,
      "name": "Rock_Slate"
    },
    {
      "x": -13,
      "y": 19,
      "z": -5,
      "name": "Rock_Slate"
    },
    {
      "x": -13,
      "y": 20,
      "z": -5,
      "name": "Rock_Slate"
    },
    {
      "x": -13,
      "y": 21,
      "z": -5,
      "name": "Rock_Slate"
    },
    {
      "x": -13,
      "y": 22,
      "z": -5,
      "name": "Rock_Slate"
    },
    {
      "x": -13,
      "y": 23,
      "z": -5,
      "name": "Soil_Slate_Gravel"
    },
    {
      "x": -13,
      "y": 24,
      "z": -5,
      "name": "Rock_Slate"
    },
    {
      "x": -13,
      "y": 25,
      "z": -5,
      "name": "Rock_Slate"
    },
    {
      "x": -13,
      "y": 26,
      "z": -5,
      "name": "Rock_Slate"
    },
    {
      "x": -13,
      "y": 27,
      "z": -5,
      "name": "Soil_Slate_Gravel"
    },
    {
      "x": -13,
      "y": 28,
      "z": -5,
      "name": "Soil_Ash"
    },
    {
      "x": -13,
      "y": 29,
      "z": -5,
      "name": "Rock_Slate"
    },
    {
      "x": -13,
      "y": 30,
      "z": -5,
      "name": "Soil_Ash"
    },
    {
      "x": -13,
      "y": 31,
      "z": -5,
      "name": "Soil_Ash"
    },
    {
      "x": -13,
      "y": 15,
      "z": -4,
      "name": "Soil_Ash"
    },
    {
      "x": -13,
      "y": 16,
      "z": -4,
      "name": "Soil_Slate_Gravel"
    },
    {
      "x": -13,
      "y": 17,
      "z": -4,
      "name": "Rock_Slate"
    },
    {
      "x": -13,
      "y": 18,
      "z": -4,
      "name": "Soil_Ash"
    },
    {
      "x": -13,
      "y": 19,
      "z": -4,
      "name": "Soil_Slate_Gravel"
    },
    {
      "x": -13,
      "y": 20,
      "z": -4,
      "name": "Rock_Slate"
    },
    {
      "x": -13,
      "y": 21,
      "z": -4,
      "name": "Rock_Slate"
    },
    {
      "x": -13,
      "y": 22,
      "z": -4,
      "name": "Rock_Slate"
    },
    {
      "x": -13,
      "y": 23,
      "z": -4,
      "name": "Soil_Slate_Gravel"
    },
    {
      "x": -13,
      "y": 24,
      "z": -4,
      "name": "Soil_Ash"
    },
    {
      "x": -13,
      "y": 25,
      "z": -4,
      "name": "Rock_Slate"
    },
    {
      "x": -13,
      "y": 26,
      "z": -4,
      "name": "Rock_Slate"
    },
    {
      "x": -13,
      "y": 27,
      "z": -4,
      "name": "Soil_Ash"
    },
    {
      "x": -13,
      "y": 28,
      "z": -4,
      "name": "Rock_Slate"
    },
    {
      "x": -13,
      "y": 29,
      "z": -4,
      "name": "Rock_Slate"
    },
    {
      "x": -13,
      "y": 30,
      "z": -4,
      "name": "Rock_Slate"
    },
    {
      "x": -13,
      "y": 17,
      "z": -3,
      "name": "Soil_Ash"
    },
    {
      "x": -13,
      "y": 18,
      "z": -3,
      "name": "Rock_Slate"
    },
    {
      "x": -13,
      "y": 19,
      "z": -3,
      "name": "Soil_Slate_Gravel"
    },
    {
      "x": -13,
      "y": 20,
      "z": -3,
      "name": "Rock_Slate"
    },
    {
      "x": -13,
      "y": 21,
      "z": -3,
      "name": "Rock_Slate"
    },
    {
      "x": -13,
      "y": 22,
      "z": -3,
      "name": "Rock_Slate"
    },
    {
      "x": -13,
      "y": 23,
      "z": -3,
      "name": "Soil_Ash"
    },
    {
      "x": -13,
      "y": 24,
      "z": -3,
      "name": "Rock_Slate"
    },
    {
      "x": -13,
      "y": 25,
      "z": -3,
      "name": "Soil_Slate_Gravel"
    },
    {
      "x": -13,
      "y": 26,
      "z": -3,
      "name": "Soil_Slate_Gravel"
    },
    {
      "x": -13,
      "y": 27,
      "z": -3,
      "name": "Rock_Slate"
    },
    {
      "x": -13,
      "y": 28,
      "z": -3,
      "name": "Soil_Slate_Gravel"
    },
    {
      "x": -13,
      "y": 29,
      "z": -3,
      "name": "Rock_Slate"
    },
    {
      "x": -13,
      "y": 17,
      "z": -2,
      "name": "Rock_Slate"
    },
    {
      "x": -13,
      "y": 18,
      "z": -2,
      "name": "Soil_Ash"
    },
    {
      "x": -13,
      "y": 19,
      "z": -2,
      "name": "Soil_Ash"
    },
    {
      "x": -13,
      "y": 20,
      "z": -2,
      "name": "Rock_Slate"
    },
    {
      "x": -13,
      "y": 21,
      "z": -2,
      "name": "Rock_Slate"
    },
    {
      "x": -13,
      "y": 22,
      "z": -2,
      "name": "Soil_Ash"
    },
    {
      "x": -13,
      "y": 23,
      "z": -2,
      "name": "Soil_Ash"
    },
    {
      "x": -13,
      "y": 24,
      "z": -2,
      "name": "Rock_Slate"
    },
    {
      "x": -13,
      "y": 25,
      "z": -2,
      "name": "Rock_Slate"
    },
    {
      "x": -13,
      "y": 26,
      "z": -2,
      "name": "Soil_Ash"
    },
    {
      "x": -13,
      "y": 27,
      "z": -2,
      "name": "Rock_Slate"
    },
    {
      "x": -13,
      "y": 28,
      "z": -2,
      "name": "Soil_Ash"
    },
    {
      "x": -13,
      "y": 16,
      "z": -1,
      "name": "Soil_Ash"
    },
    {
      "x": -13,
      "y": 17,
      "z": -1,
      "name": "Rock_Slate"
    },
    {
      "x": -13,
      "y": 18,
      "z": -1,
      "name": "Soil_Slate_Gravel"
    },
    {
      "x": -13,
      "y": 19,
      "z": -1,
      "name": "Rock_Slate"
    },
    {
      "x": -13,
      "y": 20,
      "z": -1,
      "name": "Soil_Ash"
    },
    {
      "x": -13,
      "y": 21,
      "z": -1,
      "name": "Rock_Slate"
    },
    {
      "x": -13,
      "y": 22,
      "z": -1,
      "name": "Rock_Slate"
    },
    {
      "x": -13,
      "y": 23,
      "z": -1,
      "name": "Soil_Ash"
    },
    {
      "x": -13,
      "y": 24,
      "z": -1,
      "name": "Soil_Slate_Gravel"
    },
    {
      "x": -13,
      "y": 25,
      "z": -1,
      "name": "Soil_Ash"
    },
    {
      "x": -13,
      "y": 26,
      "z": -1,
      "name": "Soil_Ash"
    },
    {
      "x": -13,
      "y": 27,
      "z": -1,
      "name": "Soil_Ash"
    },
    {
      "x": -13,
      "y": 16,
      "z": 0,
      "name": "Soil_Slate_Gravel"
    },
    {
      "x": -13,
      "y": 17,
      "z": 0,
      "name": "Rock_Slate"
    },
    {
      "x": -13,
      "y": 18,
      "z": 0,
      "name": "Rock_Slate"
    },
    {
      "x": -13,
      "y": 19,
      "z": 0,
      "name": "Rock_Slate"
    },
    {
      "x": -13,
      "y": 20,
      "z": 0,
      "name": "Ore_Cobalt_Slate_Cracked"
    },
    {
      "x": -13,
      "y": 21,
      "z": 0,
      "name": "Ore_Cobalt_Slate_Cracked"
    },
    {
      "x": -13,
      "y": 22,
      "z": 0,
      "name": "Rock_Slate"
    },
    {
      "x": -13,
      "y": 23,
      "z": 0,
      "name": "Rock_Slate"
    },
    {
      "x": -13,
      "y": 24,
      "z": 0,
      "name": "Soil_Slate_Gravel"
    },
    {
      "x": -13,
      "y": 25,
      "z": 0,
      "name": "Rock_Slate"
    },
    {
      "x": -13,
      "y": 26,
      "z": 0,
      "name": "Soil_Ash"
    },
    {
      "x": -13,
      "y": 17,
      "z": 1,
      "name": "Soil_Ash"
    },
    {
      "x": -13,
      "y": 18,
      "z": 1,
      "name": "Rock_Slate"
    },
    {
      "x": -13,
      "y": 19,
      "z": 1,
      "name": "Soil_Ash"
    },
    {
      "x": -13,
      "y": 20,
      "z": 1,
      "name": "Soil_Ash"
    },
    {
      "x": -13,
      "y": 21,
      "z": 1,
      "name": "Rock_Slate"
    },
    {
      "x": -13,
      "y": 22,
      "z": 1,
      "name": "Ore_Cobalt_Slate"
    },
    {
      "x": -13,
      "y": 23,
      "z": 1,
      "name": "Soil_Ash"
    },
    {
      "x": -13,
      "y": 24,
      "z": 1,
      "name": "Soil_Ash"
    },
    {
      "x": -13,
      "y": 17,
      "z": 2,
      "name": "Plant_Bush_Dead_Hanging"
    },
    {
      "x": -13,
      "y": 18,
      "z": 2,
      "name": "Rock_Slate"
    },
    {
      "x": -13,
      "y": 19,
      "z": 2,
      "name": "Rock_Slate"
    },
    {
      "x": -13,
      "y": 20,
      "z": 2,
      "name": "Soil_Ash"
    },
    {
      "x": -13,
      "y": 21,
      "z": 2,
      "name": "Rock_Slate"
    },
    {
      "x": -13,
      "y": 22,
      "z": 2,
      "name": "Soil_Ash"
    },
    {
      "x": -13,
      "y": 23,
      "z": 2,
      "name": "Ore_Cobalt_Slate"
    },
    {
      "x": -13,
      "y": 24,
      "z": 2,
      "name": "Soil_Ash"
    },
    {
      "x": -13,
      "y": 25,
      "z": 2,
      "name": "Soil_Ash"
    },
    {
      "x": -13,
      "y": 12,
      "z": 3,
      "name": "Plant_Bush_Dead_Hanging"
    },
    {
      "x": -13,
      "y": 13,
      "z": 3,
      "name": "Rock_Slate"
    },
    {
      "x": -13,
      "y": 14,
      "z": 3,
      "name": "Rock_Slate"
    },
    {
      "x": -13,
      "y": 15,
      "z": 3,
      "name": "Ore_Cobalt_Slate_Cracked"
    },
    {
      "x": -13,
      "y": 16,
      "z": 3,
      "name": "Ore_Cobalt_Slate_Cracked"
    },
    {
      "x": -13,
      "y": 17,
      "z": 3,
      "name": "Ore_Cobalt_Slate_Cracked"
    },
    {
      "x": -13,
      "y": 18,
      "z": 3,
      "name": "Soil_Ash"
    },
    {
      "x": -13,
      "y": 19,
      "z": 3,
      "name": "Soil_Ash"
    },
    {
      "x": -13,
      "y": 20,
      "z": 3,
      "name": "Soil_Slate_Gravel"
    },
    {
      "x": -13,
      "y": 21,
      "z": 3,
      "name": "Soil_Ash"
    },
    {
      "x": -13,
      "y": 22,
      "z": 3,
      "name": "Soil_Ash"
    },
    {
      "x": -13,
      "y": 11,
      "z": 4,
      "name": "Rock_Slate"
    },
    {
      "x": -13,
      "y": 12,
      "z": 4,
      "name": "Ore_Cobalt_Slate_Cracked"
    },
    {
      "x": -13,
      "y": 13,
      "z": 4,
      "name": "Rock_Slate"
    },
    {
      "x": -13,
      "y": 14,
      "z": 4,
      "name": "Rock_Slate"
    },
    {
      "x": -13,
      "y": 15,
      "z": 4,
      "name": "Soil_Ash"
    },
    {
      "x": -13,
      "y": 16,
      "z": 4,
      "name": "Soil_Ash"
    },
    {
      "x": -13,
      "y": 17,
      "z": 4,
      "name": "Soil_Ash"
    },
    {
      "x": -13,
      "y": 18,
      "z": 4,
      "name": "Soil_Slate_Gravel"
    },
    {
      "x": -13,
      "y": 19,
      "z": 4,
      "name": "Plant_Coral_Block_Violet"
    },
    {
      "x": -13,
      "y": 20,
      "z": 4,
      "name": "Rock_Crystal_Pink_Small",
      "rotation": 7
    },
    {
      "x": -13,
      "y": 10,
      "z": 5,
      "name": "Rock_Slate"
    },
    {
      "x": -13,
      "y": 11,
      "z": 5,
      "name": "Ore_Cobalt_Slate_Cracked"
    },
    {
      "x": -13,
      "y": 12,
      "z": 5,
      "name": "Rock_Slate"
    },
    {
      "x": -13,
      "y": 13,
      "z": 5,
      "name": "Rock_Slate"
    },
    {
      "x": -13,
      "y": 14,
      "z": 5,
      "name": "Rock_Slate"
    },
    {
      "x": -13,
      "y": 15,
      "z": 5,
      "name": "Rock_Slate"
    },
    {
      "x": -13,
      "y": 16,
      "z": 5,
      "name": "Soil_Ash"
    },
    {
      "x": -13,
      "y": 17,
      "z": 5,
      "name": "Rock_Slate"
    },
    {
      "x": -13,
      "y": 18,
      "z": 5,
      "name": "Soil_Ash"
    },
    {
      "x": -13,
      "y": 19,
      "z": 5,
      "name": "Rock_Slate"
    },
    {
      "x": -13,
      "y": 20,
      "z": 5,
      "name": "Soil_Ash"
    },
    {
      "x": -13,
      "y": 9,
      "z": 6,
      "name": "Rock_Slate"
    },
    {
      "x": -13,
      "y": 10,
      "z": 6,
      "name": "Rock_Slate"
    },
    {
      "x": -13,
      "y": 11,
      "z": 6,
      "name": "Rock_Slate"
    },
    {
      "x": -13,
      "y": 12,
      "z": 6,
      "name": "Rock_Slate"
    },
    {
      "x": -13,
      "y": 13,
      "z": 6,
      "name": "Ore_Cobalt_Slate_Cracked"
    },
    {
      "x": -13,
      "y": 14,
      "z": 6,
      "name": "Rock_Slate"
    },
    {
      "x": -13,
      "y": 15,
      "z": 6,
      "name": "Rock_Slate"
    },
    {
      "x": -13,
      "y": 16,
      "z": 6,
      "name": "Soil_Ash"
    },
    {
      "x": -13,
      "y": 17,
      "z": 6,
      "name": "Soil_Ash"
    },
    {
      "x": -13,
      "y": 18,
      "z": 6,
      "name": "Rock_Slate"
    },
    {
      "x": -13,
      "y": 19,
      "z": 6,
      "name": "Soil_Ash"
    },
    {
      "x": -13,
      "y": 20,
      "z": 6,
      "name": "Rock_Slate"
    },
    {
      "x": -13,
      "y": 10,
      "z": 7,
      "name": "Rock_Slate"
    },
    {
      "x": -13,
      "y": 11,
      "z": 7,
      "name": "Rock_Slate"
    },
    {
      "x": -13,
      "y": 12,
      "z": 7,
      "name": "Rock_Slate"
    },
    {
      "x": -13,
      "y": 13,
      "z": 7,
      "name": "Rock_Slate"
    },
    {
      "x": -13,
      "y": 14,
      "z": 7,
      "name": "Rock_Slate"
    },
    {
      "x": -13,
      "y": 15,
      "z": 7,
      "name": "Rock_Slate"
    },
    {
      "x": -13,
      "y": 16,
      "z": 7,
      "name": "Soil_Slate_Gravel"
    },
    {
      "x": -13,
      "y": 17,
      "z": 7,
      "name": "Soil_Ash"
    },
    {
      "x": -13,
      "y": 18,
      "z": 7,
      "name": "Soil_Slate_Gravel"
    },
    {
      "x": -13,
      "y": 19,
      "z": 7,
      "name": "Soil_Slate_Gravel"
    },
    {
      "x": -13,
      "y": 20,
      "z": 7,
      "name": "Soil_Ash"
    },
    {
      "x": -13,
      "y": 11,
      "z": 8,
      "name": "Rock_Slate"
    },
    {
      "x": -13,
      "y": 12,
      "z": 8,
      "name": "Rock_Slate"
    },
    {
      "x": -13,
      "y": 13,
      "z": 8,
      "name": "Rock_Slate"
    },
    {
      "x": -13,
      "y": 14,
      "z": 8,
      "name": "Rock_Slate"
    },
    {
      "x": -13,
      "y": 15,
      "z": 8,
      "name": "Rock_Slate"
    },
    {
      "x": -13,
      "y": 16,
      "z": 8,
      "name": "Rock_Slate"
    },
    {
      "x": -13,
      "y": 17,
      "z": 8,
      "name": "Rock_Slate"
    },
    {
      "x": -13,
      "y": 18,
      "z": 8,
      "name": "Soil_Slate_Gravel"
    },
    {
      "x": -13,
      "y": 19,
      "z": 8,
      "name": "Rock_Slate"
    },
    {
      "x": -13,
      "y": 15,
      "z": 9,
      "name": "Ore_Cobalt_Slate_Cracked"
    },
    {
      "x": -13,
      "y": 16,
      "z": 9,
      "name": "Ore_Cobalt_Slate_Cracked"
    },
    {
      "x": -13,
      "y": 17,
      "z": 9,
      "name": "Rock_Slate"
    },
    {
      "x": -13,
      "y": 18,
      "z": 9,
      "name": "Rock_Slate"
    },
    {
      "x": -13,
      "y": 19,
      "z": 9,
      "name": "Rock_Slate"
    },
    {
      "x": -13,
      "y": 10,
      "z": 14,
      "name": "Rock_Slate"
    },
    {
      "x": -13,
      "y": 11,
      "z": 14,
      "name": "Rock_Slate"
    },
    {
      "x": -13,
      "y": 12,
      "z": 14,
      "name": "Rock_Slate"
    },
    {
      "x": -13,
      "y": 9,
      "z": 15,
      "name": "Rock_Slate"
    },
    {
      "x": -13,
      "y": 10,
      "z": 15,
      "name": "Rock_Slate"
    },
    {
      "x": -13,
      "y": 11,
      "z": 15,
      "name": "Rock_Slate"
    },
    {
      "x": -13,
      "y": 12,
      "z": 15,
      "name": "Rock_Slate"
    },
    {
      "x": -13,
      "y": 13,
      "z": 15,
      "name": "Rock_Slate"
    },
    {
      "x": -13,
      "y": 14,
      "z": 15,
      "name": "Rock_Slate"
    },
    {
      "x": -13,
      "y": 6,
      "z": 16,
      "name": "Rock_Slate"
    },
    {
      "x": -13,
      "y": 7,
      "z": 16,
      "name": "Rock_Slate"
    },
    {
      "x": -13,
      "y": 8,
      "z": 16,
      "name": "Rock_Slate"
    },
    {
      "x": -13,
      "y": 9,
      "z": 16,
      "name": "Rock_Slate"
    },
    {
      "x": -13,
      "y": 10,
      "z": 16,
      "name": "Rock_Slate"
    },
    {
      "x": -13,
      "y": 11,
      "z": 16,
      "name": "Rock_Slate"
    },
    {
      "x": -13,
      "y": 12,
      "z": 16,
      "name": "Rock_Slate"
    },
    {
      "x": -13,
      "y": 13,
      "z": 16,
      "name": "Soil_Ash"
    },
    {
      "x": -13,
      "y": 14,
      "z": 16,
      "name": "Soil_Ash"
    },
    {
      "x": -13,
      "y": 15,
      "z": 16,
      "name": "Rock_Slate"
    },
    {
      "x": -13,
      "y": 2,
      "z": 17,
      "name": "Rock_Crystal_Purple_Medium",
      "rotation": 5
    },
    {
      "x": -13,
      "y": 4,
      "z": 17,
      "name": "Rock_Slate"
    },
    {
      "x": -13,
      "y": 5,
      "z": 17,
      "name": "Rock_Slate"
    },
    {
      "x": -13,
      "y": 6,
      "z": 17,
      "name": "Rock_Slate"
    },
    {
      "x": -13,
      "y": 7,
      "z": 17,
      "name": "Rock_Slate"
    },
    {
      "x": -13,
      "y": 8,
      "z": 17,
      "name": "Rock_Slate"
    },
    {
      "x": -13,
      "y": 9,
      "z": 17,
      "name": "Rock_Slate"
    },
    {
      "x": -13,
      "y": 10,
      "z": 17,
      "name": "Rock_Slate"
    },
    {
      "x": -13,
      "y": 11,
      "z": 17,
      "name": "Rock_Slate"
    },
    {
      "x": -13,
      "y": 12,
      "z": 17,
      "name": "Rock_Slate"
    },
    {
      "x": -13,
      "y": 13,
      "z": 17,
      "name": "Rock_Slate"
    },
    {
      "x": -13,
      "y": 14,
      "z": 17,
      "name": "Soil_Ash"
    },
    {
      "x": -13,
      "y": 15,
      "z": 17,
      "name": "Soil_Ash"
    },
    {
      "x": -13,
      "y": 5,
      "z": 18,
      "name": "Rock_Slate"
    },
    {
      "x": -13,
      "y": 6,
      "z": 18,
      "name": "Rock_Slate"
    },
    {
      "x": -13,
      "y": 7,
      "z": 18,
      "name": "Rock_Slate"
    },
    {
      "x": -13,
      "y": 8,
      "z": 18,
      "name": "Rock_Slate"
    },
    {
      "x": -13,
      "y": 9,
      "z": 18,
      "name": "Rock_Slate"
    },
    {
      "x": -13,
      "y": 10,
      "z": 18,
      "name": "Rock_Slate"
    },
    {
      "x": -13,
      "y": 11,
      "z": 18,
      "name": "Rock_Slate"
    },
    {
      "x": -13,
      "y": 12,
      "z": 18,
      "name": "Rock_Slate"
    },
    {
      "x": -13,
      "y": 13,
      "z": 18,
      "name": "Soil_Ash"
    },
    {
      "x": -13,
      "y": 14,
      "z": 18,
      "name": "Rock_Slate"
    },
    {
      "x": -13,
      "y": 15,
      "z": 18,
      "name": "Soil_Ash"
    },
    {
      "x": -13,
      "y": 16,
      "z": 18,
      "name": "Rock_Slate"
    },
    {
      "x": -13,
      "y": 7,
      "z": 19,
