{
  "version": 8,
  "blockIdVersion": 11,
  "anchorX": 0,
  "anchorY": 0,
  "anchorZ": 0,
  "blocks": [
    {
      "x": -14,
      "y": 19,
      "z": 0,
      "name": "Rock_Slate"
    },
    {
      "x": -14,
      "y": 22,
      "z": 0,
      "name": "Ore_Cobalt_Slate"
    },
    {
      "x": -14,
      "y": 23,
      "z": 0,
      "name": "Ore_Cobalt_Slate"
    },
    {
      "x": -14,
      "y": 24,
      "z": 0,
      "name": "Rock_Slate"
    },
    {
      "x": -14,
      "y": 25,
      "z": 0,
      "name": "Soil_Slate_Gravel"
    },
    {
      "x": -14,
      "y": 17,
      "z": 1,
      "name": "Plant_Bush_Dead_Hanging"
    },
    {
      "x": -14,
      "y": 18,
      "z": 1,
      "name": "Ore_Cobalt_Slate_Cracked"
    },
    {
      "x": -14,
      "y": 19,
      "z": 1,
      "name": "Rock_Slate"
    },
    {
      "x": -14,
      "y": 20,
      "z": 1,
      "name": "Rock_Slate"
    },
    {
      "x": -14,
      "y": 21,
      "z": 1,
      "name": "Rock_Slate"
    },
    {
      "x": -14,
      "y": 22,
      "z": 1,
      "name": "Ore_Cobalt_Slate"
    },
    {
      "x": -14,
      "y": 23,
      "z": 1,
      "name": "Ore_Cobalt_Slate"
    },
    {
      "x": -14,
      "y": 24,
      "z": 1,
      "name": "Soil_Ash"
    },
    {
      "x": -14,
      "y": 25,
      "z": 1,
      "name": "Soil_Slate_Gravel"
    },
    {
      "x": -14,
      "y": 17,
      "z": 2,
      "name": "Ore_Cobalt_Slate_Cracked"
    },
    {
      "x": -14,
      "y": 18,
      "z": 2,
      "name": "Rock_Slate"
    },
    {
      "x": -14,
      "y": 19,
      "z": 2,
      "name": "Rock_Slate"
    },
    {
      "x": -14,
      "y": 20,
      "z": 2,
      "name": "Rock_Slate"
    },
    {
      "x": -14,
      "y": 21,
      "z": 2,
      "name": "Rock_Slate"
    },
    {
      "x": -14,
      "y": 22,
      "z": 2,
      "name": "Rock_Slate"
    },
    {
      "x": -14,
      "y": 23,
      "z": 2,
      "name": "Soil_Slate_Gravel"
    },
    {
      "x": -14,
      "y": 24,
      "z": 2,
      "name": "Soil_Slate_Gravel"
    },
    {
      "x": -14,
      "y": 25,
      "z": 2,
      "name": "Soil_Ash"
    },
    {
      "x": -14,
      "y": 18,
      "z": 3,
      "name": "Rock_Slate"
    },
    {
      "x": -14,
      "y": 19,
      "z": 3,
      "name": "Rock_Slate"
    },
    {
      "x": -14,
      "y": 20,
      "z": 3,
      "name": "Rock_Slate"
    },
    {
      "x": -14,
      "y": 21,
      "z": 3,
      "name": "Rock_Slate"
    },
    {
      "x": -14,
      "y": 22,
      "z": 3,
      "name": "Soil_Ash"
    },
    {
      "x": -14,
      "y": 23,
      "z": 3,
      "name": "Soil_Ash"
    },
    {
      "x": -14,
      "y": 24,
      "z": 3,
      "name": "Soil_Ash"
    },
    {
      "x": -14,
      "y": 20,
      "z": 4,
      "name": "Rock_Slate"
    },
    {
      "x": -14,
      "y": 21,
      "z": 4,
      "name": "Rock_Slate"
    },
    {
      "x": -14,
      "y": 22,
      "z": 4,
      "name": "Soil_Ash"
    },
    {
      "x": -14,
      "y": 23,
      "z": 4,
      "name": "Rock_Slate"
    },
    {
      "x": -13,
      "y": 23,
      "z": -2,
      "name": "Rock_Slate"
    },
    {
      "x": -13,
      "y": 24,
      "z": -2,
      "name": "Rock_Slate"
    },
    {
      "x": -13,
      "y": 25,
      "z": -2,
      "name": "Rock_Slate"
    },
    {
      "x": -13,
      "y": 19,
      "z": -1,
      "name": "Rock_Slate"
    },
    {
      "x": -13,
      "y": 20,
      "z": -1,
      "name": "Rock_Slate"
    },
    {
      "x": -13,
      "y": 21,
      "z": -1,
      "name": "Rock_Slate"
    },
    {
      "x": -13,
      "y": 22,
      "z": -1,
      "name": "Rock_Slate"
    },
    {
      "x": -13,
      "y": 23,
      "z": -1,
      "name": "Rock_Slate"
    },
    {
      "x": -13,
      "y": 24,
      "z": -1,
      "name": "Soil_Ash"
    },
    {
      "x": -13,
      "y": 25,
      "z": -1,
      "name": "Rock_Slate"
    },
    {
      "x": -13,
      "y": 26,
      "z": -1,
      "name": "Soil_Ash"
    },
    {
      "x": -13,
      "y": 15,
      "z": 0,
      "name": "Plant_Crop_Mushroom_Block_Purple_Mycelium"
    },
    {
      "x": -13,
      "y": 16,
      "z": 0,
      "name": "Plant_Crop_Mushroom_Block_Purple_Mycelium"
    },
    {
      "x": -13,
      "y": 17,
      "z": 0,
      "name": "Rock_Slate"
    },
    {
      "x": -13,
      "y": 18,
      "z": 0,
      "name": "Rock_Slate"
    },
    {
      "x": -13,
      "y": 19,
      "z": 0,
      "name": "Rock_Slate"
    },
    {
      "x": -13,
      "y": 20,
      "z": 0,
      "name": "Rock_Slate"
    },
    {
      "x": -13,
      "y": 21,
      "z": 0,
      "name": "Rock_Slate"
    },
    {
      "x": -13,
      "y": 22,
      "z": 0,
      "name": "Ore_Cobalt_Slate"
    },
    {
      "x": -13,
      "y": 23,
      "z": 0,
      "name": "Ore_Cobalt_Slate"
    },
    {
      "x": -13,
      "y": 24,
      "z": 0,
      "name": "Rock_Slate"
    },
    {
      "x": -13,
      "y": 25,
      "z": 0,
      "name": "Soil_Ash"
    },
    {
      "x": -13,
      "y": 26,
      "z": 0,
      "name": "Soil_Slate_Gravel"
    },
    {
      "x": -13,
      "y": 15,
      "z": 1,
      "name": "Plant_Crop_Mushroom_Block_Purple_Mycelium"
    },
    {
      "x": -13,
      "y": 16,
      "z": 1,
      "name": "Ore_Cobalt_Slate_Cracked"
    },
    {
      "x": -13,
      "y": 17,
      "z": 1,
      "name": "Ore_Cobalt_Slate_Cracked"
    },
    {
      "x": -13,
      "y": 18,
      "z": 1,
      "name": "Rock_Slate"
    },
    {
      "x": -13,
      "y": 19,
      "z": 1,
      "name": "Rock_Slate"
    },
    {
      "x": -13,
      "y": 20,
      "z": 1,
      "name": "Rock_Slate"
    },
    {
      "x": -13,
      "y": 21,
      "z": 1,
      "name": "Rock_Slate"
    },
    {
      "x": -13,
      "y": 22,
      "z": 1,
      "name": "Ore_Cobalt_Slate"
    },
    {
      "x": -13,
      "y": 23,
      "z": 1,
      "name": "Ore_Cobalt_Slate"
    },
    {
      "x": -13,
      "y": 24,
      "z": 1,
      "name": "Soil_Ash"
    },
    {
      "x": -13,
      "y": 25,
      "z": 1,
      "name": "Soil_Slate_Gravel"
    },
    {
      "x": -13,
      "y": 15,
      "z": 2,
      "name": "Rock_Slate"
    },
    {
      "x": -13,
      "y": 16,
      "z": 2,
      "name": "Rock_Slate"
    },
    {
      "x": -13,
      "y": 17,
      "z": 2,
      "name": "Ore_Cobalt_Slate_Cracked"
    },
    {
      "x": -13,
      "y": 18,
      "z": 2,
      "name": "Rock_Slate"
    },
    {
      "x": -13,
      "y": 19,
      "z": 2,
      "name": "Rock_Slate"
    },
    {
      "x": -13,
      "y": 20,
      "z": 2,
      "name": "Rock_Slate"
    },
    {
      "x": -13,
      "y": 21,
      "z": 2,
      "name": "Rock_Slate"
    },
    {
      "x": -13,
      "y": 22,
      "z": 2,
      "name": "Rock_Slate"
    },
    {
      "x": -13,
      "y": 23,
      "z": 2,
      "name": "Rock_Slate"
    },
    {
      "x": -13,
      "y": 24,
      "z": 2,
      "name": "Soil_Ash"
    },
    {
      "x": -13,
      "y": 25,
      "z": 2,
      "name": "Soil_Ash"
    },
    {
      "x": -13,
      "y": 26,
      "z": 2,
      "name": "Soil_Ash"
    },
    {
      "x": -13,
      "y": 16,
      "z": 3,
      "name": "Rock_Slate"
    },
    {
      "x": -13,
      "y": 17,
      "z": 3,
      "name": "Rock_Slate"
    },
    {
      "x": -13,
      "y": 18,
      "z": 3,
      "name": "Rock_Slate"
    },
    {
      "x": -13,
      "y": 19,
      "z": 3,
      "name": "Rock_Slate"
    },
    {
      "x": -13,
      "y": 20,
      "z": 3,
      "name": "Rock_Slate"
    },
    {
      "x": -13,
      "y": 21,
      "z": 3,
      "name": "Rock_Slate"
    },
    {
      "x": -13,
      "y": 22,
      "z": 3,
      "name": "Soil_Ash"
    },
    {
      "x": -13,
      "y": 23,
      "z": 3,
      "name": "Rock_Slate"
    },
    {
      "x": -13,
      "y": 24,
      "z": 3,
      "name": "Soil_Ash"
    },
    {
      "x": -13,
      "y": 25,
      "z": 3,
      "name": "Soil_Ash"
    },
    {
      "x": -13,
      "y": 17,
      "z": 4,
      "name": "Rock_Slate"
    },
    {
      "x": -13,
      "y": 18,
      "z": 4,
      "name": "Ore_Cobalt_Slate_Cracked"
    },
    {
      "x": -13,
      "y": 19,
      "z": 4,
      "name": "Rock_Slate"
    },
    {
      "x": -13,
      "y": 20,
      "z": 4,
      "name": "Rock_Slate"
    },
    {
      "x": -13,
      "y": 21,
      "z": 4,
      "name": "Rock_Slate"
    },
    {
      "x": -13,
      "y": 22,
      "z": 4,
      "name": "Rock_Slate"
    },
    {
      "x": -13,
      "y": 23,
      "z": 4,
      "name": "Soil_Ash"
    },
    {
      "x": -13,
      "y": 24,
      "z": 4,
      "name": "Soil_Ash"
    },
    {
      "x": -13,
      "y": 25,
      "z": 4,
      "name": "Soil_Ash"
    },
    {
      "x": -13,
      "y": 19,
      "z": 5,
      "name": "Rock_Slate"
    },
    {
      "x": -13,
      "y": 20,
      "z": 5,
      "name": "Rock_Slate"
    },
    {
      "x": -13,
      "y": 21,
      "z": 5,
      "name": "Rock_Slate"
    },
    {
      "x": -13,
      "y": 22,
      "z": 5,
      "name": "Rock_Slate"
    },
    {
      "x": -13,
      "y": 23,
      "z": 5,
      "name": "Soil_Slate_Gravel"
    },
    {
      "x": -13,
      "y": 24,
      "z": 5,
      "name": "Soil_Ash"
    },
    {
      "x": -13,
      "y": 20,
      "z": 6,
      "name": "Ore_Cobalt_Slate_Cracked"
    },
    {
      "x": -13,
      "y": 21,
      "z": 6,
      "name": "Soil_Slate_Gravel"
    },
    {
      "x": -13,
      "y": 22,
      "z": 6,
      "name": "Rock_Slate"
    },
    {
      "x": -12,
      "y": 24,
      "z": -4,
      "name": "Rock_Slate"
    },
    {
      "x": -12,
      "y": 25,
      "z": -4,
      "name": "Soil_Ash"
    },
    {
      "x": -12,
      "y": 26,
      "z": -4,
      "name": "Rock_Slate"
    },
    {
      "x": -12,
      "y": 27,
      "z": -4,
      "name": "Soil_Slate_Gravel"
    },
    {
      "x": -12,
      "y": 22,
      "z": -3,
      "name": "Rock_Slate"
    },
    {
      "x": -12,
      "y": 23,
      "z": -3,
      "name": "Rock_Slate"
    },
    {
      "x": -12,
      "y": 24,
      "z": -3,
      "name": "Rock_Slate"
    },
    {
      "x": -12,
      "y": 25,
      "z": -3,
      "name": "Soil_Ash"
    },
    {
      "x": -12,
      "y": 26,
      "z": -3,
      "name": "Rock_Slate"
    },
    {
      "x": -12,
      "y": 27,
      "z": -3,
      "name": "Rock_Slate"
    },
    {
      "x": -12,
      "y": 20,
      "z": -2,
      "name": "Rock_Slate"
    },
    {
      "x": -12,
      "y": 21,
      "z": -2,
      "name": "Rock_Slate"
    },
    {
      "x": -12,
      "y": 22,
      "z": -2,
      "name": "Rock_Slate"
    },
    {
      "x": -12,
      "y": 23,
      "z": -2,
      "name": "Rock_Slate"
    },
    {
      "x": -12,
      "y": 24,
      "z": -2,
      "name": "Rock_Slate"
    },
    {
      "x": -12,
      "y": 25,
      "z": -2,
      "name": "Rock_Slate"
    },
    {
      "x": -12,
      "y": 26,
      "z": -2,
      "name": "Soil_Ash"
    },
    {
      "x": -12,
      "y": 27,
      "z": -2,
      "name": "Rock_Slate"
    },
    {
      "x": -12,
      "y": 18,
      "z": -1,
      "name": "Rock_Slate"
    },
    {
      "x": -12,
      "y": 19,
      "z": -1,
      "name": "Rock_Slate"
    },
    {
      "x": -12,
      "y": 20,
      "z": -1,
      "name": "Rock_Slate"
    },
    {
      "x": -12,
      "y": 21,
      "z": -1,
      "name": "Rock_Slate"
    },
    {
      "x": -12,
      "y": 22,
      "z": -1,
      "name": "Rock_Slate"
    },
    {
      "x": -12,
      "y": 23,
      "z": -1,
      "name": "Rock_Slate"
    },
    {
      "x": -12,
      "y": 24,
      "z": -1,
      "name": "Soil_Ash"
    },
    {
      "x": -12,
      "y": 25,
      "z": -1,
      "name": "Soil_Ash"
    },
    {
      "x": -12,
      "y": 26,
      "z": -1,
      "name": "Rock_Slate"
    },
    {
      "x": -12,
      "y": 27,
      "z": -1,
      "name": "Soil_Ash"
    },
    {
      "x": -12,
      "y": 15,
      "z": 0,
      "name": "Plant_Crop_Mushroom_Block_Purple_Mycelium"
    },
    {
      "x": -12,
      "y": 16,
      "z": 0,
      "name": "Rock_Slate"
    },
    {
      "x": -12,
      "y": 17,
      "z": 0,
      "name": "Rock_Slate"
    },
    {
      "x": -12,
      "y": 18,
      "z": 0,
      "name": "Rock_Slate"
    },
    {
      "x": -12,
      "y": 19,
      "z": 0,
      "name": "Rock_Slate"
    },
    {
      "x": -12,
      "y": 20,
      "z": 0,
      "name": "Rock_Slate"
    },
    {
      "x": -12,
      "y": 21,
      "z": 0,
      "name": "Rock_Slate"
    },
    {
      "x": -12,
      "y": 22,
      "z": 0,
      "name": "Ore_Cobalt_Slate"
    },
    {
      "x": -12,
      "y": 23,
      "z": 0,
      "name": "Ore_Cobalt_Slate"
    },
    {
      "x": -12,
      "y": 24,
      "z": 0,
      "name": "Rock_Slate"
    },
    {
      "x": -12,
      "y": 25,
      "z": 0,
      "name": "Soil_Ash"
    },
    {
      "x": -12,
      "y": 26,
      "z": 0,
      "name": "Soil_Ash"
    },
    {
      "x": -12,
      "y": 27,
      "z": 0,
      "name": "Soil_Slate_Gravel"
    },
    {
      "x": -12,
      "y": 13,
      "z": 1,
      "name": "Plant_Crop_Mushroom_Block_Purple_Mycelium"
    },
    {
      "x": -12,
      "y": 14,
      "z": 1,
      "name": "Plant_Crop_Mushroom_Block_Purple_Mycelium"
    },
    {
      "x": -12,
      "y": 15,
      "z": 1,
      "name": "Ore_Cobalt_Slate_Cracked"
    },
    {
      "x": -12,
      "y": 16,
      "z": 1,
      "name": "Ore_Cobalt_Slate_Cracked"
    },
    {
      "x": -12,
      "y": 17,
      "z": 1,
      "name": "Rock_Slate"
    },
    {
      "x": -12,
      "y": 18,
      "z": 1,
      "name": "Rock_Slate"
    },
    {
      "x": -12,
      "y": 19,
      "z": 1,
      "name": "Rock_Slate"
    },
    {
      "x": -12,
      "y": 20,
      "z": 1,
      "name": "Rock_Slate"
    },
    {
      "x": -12,
      "y": 21,
      "z": 1,
      "name": "Rock_Slate"
    },
    {
      "x": -12,
      "y": 22,
      "z": 1,
      "name": "Ore_Cobalt_Slate"
    },
    {
      "x": -12,
      "y": 23,
      "z": 1,
      "name": "Soil_Slate_Gravel"
    },
    {
      "x": -12,
      "y": 24,
      "z": 1,
      "name": "Soil_Ash"
    },
    {
      "x": -12,
      "y": 25,
      "z": 1,
      "name": "Soil_Ash"
    },
    {
      "x": -12,
      "y": 26,
      "z": 1,
      "name": "Soil_Slate_Gravel"
    },
    {
      "x": -12,
      "y": 27,
      "z": 1,
      "name": "Soil_Ash"
    },
    {
      "x": -12,
      "y": 14,
      "z": 2,
      "name": "Rock_Slate"
    },
    {
      "x": -12,
      "y": 15,
      "z": 2,
      "name": "Rock_Slate"
    },
    {
      "x": -12,
      "y": 16,
      "z": 2,
      "name": "Rock_Slate"
    },
    {
      "x": -12,
      "y": 17,
      "z": 2,
      "name": "Rock_Slate"
    },
    {
      "x": -12,
      "y": 18,
      "z": 2,
      "name": "Rock_Slate"
    },
    {
      "x": -12,
      "y": 19,
      "z": 2,
      "name": "Rock_Slate"
    },
    {
      "x": -12,
      "y": 20,
      "z": 2,
      "name": "Rock_Slate"
    },
    {
      "x": -12,
      "y": 21,
      "z": 2,
      "name": "Rock_Slate"
    },
    {
      "x": -12,
      "y": 22,
      "z": 2,
      "name": "Rock_Slate"
    },
    {
      "x": -12,
      "y": 23,
      "z": 2,
      "name": "Soil_Slate_Gravel"
    },
    {
      "x": -12,
      "y": 24,
      "z": 2,
      "name": "Rock_Slate"
    },
    {
      "x": -12,
      "y": 25,
      "z": 2,
      "name": "Rock_Slate"
    },
    {
      "x": -12,
      "y": 26,
      "z": 2,
      "name": "Soil_Ash"
    },
    {
      "x": -12,
      "y": 27,
      "z": 2,
      "name": "Plant_Coral_Bush_Poisoned"
    },
    {
      "x": -12,
      "y": 15,
      "z": 3,
      "name": "Ore_Cobalt_Slate_Cracked"
    },
    {
      "x": -12,
      "y": 16,
      "z": 3,
      "name": "Rock_Slate"
    },
    {
      "x": -12,
      "y": 17,
      "z": 3,
      "name": "Rock_Slate"
    },
    {
      "x": -12,
      "y": 18,
      "z": 3,
      "name": "Rock_Slate"
    },
    {
      "x": -12,
      "y": 19,
      "z": 3,
      "name": "Rock_Slate"
    },
    {
      "x": -12,
      "y": 20,
      "z": 3,
      "name": "Rock_Slate"
    },
    {
      "x": -12,
      "y": 21,
      "z": 3,
      "name": "Rock_Slate"
    },
    {
      "x": -12,
      "y": 22,
      "z": 3,
      "name": "Soil_Ash"
    },
    {
      "x": -12,
      "y": 23,
      "z": 3,
      "name": "Soil_Ash"
    },
    {
      "x": -12,
      "y": 24,
      "z": 3,
      "name": "Soil_Slate_Gravel"
    },
    {
      "x": -12,
      "y": 25,
      "z": 3,
      "name": "Rock_Slate"
    },
    {
      "x": -12,
      "y": 26,
      "z": 3,
      "name": "Soil_Slate_Gravel"
    },
    {
      "x": -12,
      "y": 15,
      "z": 4,
      "name": "Plant_Crop_Mushroom_Block_Purple_Mycelium"
    },
    {
      "x": -12,
      "y": 16,
      "z": 4,
      "name": "Rock_Slate"
    },
    {
      "x": -12,
      "y": 17,
      "z": 4,
      "name": "Rock_Slate"
    },
    {
      "x": -12,
      "y": 18,
      "z": 4,
      "name": "Rock_Slate"
    },
    {
      "x": -12,
      "y": 19,
      "z": 4,
      "name": "Rock_Slate"
    },
    {
      "x": -12,
      "y": 20,
      "z": 4,
      "name": "Rock_Slate"
    },
    {
      "x": -12,
      "y": 21,
      "z": 4,
      "name": "Rock_Slate"
    },
    {
      "x": -12,
      "y": 22,
      "z": 4,
      "name": "Soil_Ash"
    },
    {
      "x": -12,
      "y": 23,
      "z": 4,
      "name": "Soil_Slate_Gravel"
    },
    {
      "x": -12,
      "y": 24,
      "z": 4,
      "name": "Soil_Slate_Gravel"
    },
    {
      "x": -12,
      "y": 25,
      "z": 4,
      "name": "Soil_Ash"
    },
    {
      "x": -12,
      "y": 26,
      "z": 4,
      "name": "Soil_Slate_Gravel"
    },
    {
      "x": -12,
      "y": 15,
      "z": 5,
      "name": "Rock_Slate"
    },
    {
      "x": -12,
      "y": 16,
      "z": 5,
      "name": "Rock_Slate"
    },
    {
      "x": -12,
      "y": 17,
      "z": 5,
      "name": "Rock_Slate"
    },
    {
      "x": -12,
      "y": 18,
      "z": 5,
      "name": "Rock_Slate"
    },
    {
      "x": -12,
      "y": 19,
      "z": 5,
      "name": "Rock_Slate"
    },
    {
      "x": -12,
      "y": 20,
      "z": 5,
      "name": "Rock_Slate"
    },
    {
      "x": -12,
      "y": 21,
      "z": 5,
      "name": "Soil_Slate_Gravel"
    },
    {
      "x": -12,
      "y": 22,
      "z": 5,
      "name": "Soil_Ash"
    },
    {
      "x": -12,
      "y": 23,
      "z": 5,
      "name": "Soil_Ash"
    },
    {
      "x": -12,
      "y": 24,
      "z": 5,
      "name": "Soil_Ash"
    },
    {
      "x": -12,
      "y": 25,
      "z": 5,
      "name": "Rock_Slate"
    },
    {
      "x": -12,
      "y": 17,
      "z": 6,
      "name": "Rock_Slate"
    },
    {
      "x": -12,
      "y": 18,
      "z": 6,
      "name": "Rock_Slate"
    },
    {
      "x": -12,
      "y": 19,
      "z": 6,
      "name": "Rock_Slate"
    },
    {
      "x": -12,
      "y": 20,
      "z": 6,
      "name": "Rock_Slate"
    },
    {
      "x": -12,
      "y": 21,
      "z": 6,
      "name": "Rock_Slate"
    },
    {
      "x": -12,
      "y": 22,
      "z": 6,
      "name": "Rock_Slate"
    },
    {
      "x": -12,
      "y": 23,
      "z": 6,
      "name": "Rock_Slate"
    },
    {
      "x": -12,
      "y": 24,
      "z": 6,
      "name": "Soil_Slate_Gravel"
    },
    {
      "x": -12,
      "y": 18,
      "z": 7,
      "name": "Rock_Slate"
    },
    {
      "x": -12,
      "y": 19,
      "z": 7,
      "name": "Rock_Slate"
    },
    {
      "x": -12,
      "y": 20,
      "z": 7,
      "name": "Soil_Ash"
    },
    {
      "x": -12,
      "y": 21,
      "z": 7,
      "name": "Soil_Ash"
    },
    {
      "x": -12,
      "y": 22,
      "z": 7,
      "name": "Soil_Ash"
    },
    {
      "x": -11,
      "y": 26,
      "z": -10,
      "name": "Rock_Slate"
    },
    {
      "x": -11,
      "y": 30,
      "z": -10,
      "name": "Rock_Slate"
    },
    {
      "x": -11,
      "y": 31,
      "z": -10,
      "name": "Rock_Slate"
    },
    {
      "x": -11,
      "y": 32,
      "z": -10,
      "name": "Soil_Ash"
    },
    {
      "x": -11,
      "y": 33,
      "z": -10,
      "name": "Soil_Ash"
    },
    {
      "x": -11,
      "y": 25,
      "z": -9,
      "name": "Rock_Slate"
    },
    {
      "x": -11,
      "y": 26,
      "z": -9,
      "name": "Rock_Slate"
    },
    {
      "x": -11,
      "y": 27,
      "z": -9,
      "name": "Rock_Slate"
    },
    {
      "x": -11,
      "y": 28,
      "z": -9,
      "name": "Rock_Slate"
    },
    {
      "x": -11,
      "y": 29,
      "z": -9,
      "name": "Rock_Slate"
    },
    {
      "x": -11,
      "y": 30,
      "z": -9,
      "name": "Soil_Ash"
    },
    {
      "x": -11,
      "y": 31,
      "z": -9,
      "name": "Soil_Ash"
    },
    {
      "x": -11,
      "y": 32,
      "z": -9,
      "name": "Soil_Ash"
    },
    {
      "x": -11,
      "y": 33,
      "z": -9,
      "name": "Soil_Ash"
    },
    {
      "x": -11,
      "y": 26,
      "z": -8,
      "name": "Rock_Slate"
    },
    {
      "x": -11,
      "y": 27,
      "z": -8,
      "name": "Rock_Slate"
    },
    {
      "x": -11,
      "y": 28,
      "z": -8,
      "name": "Rock_Slate"
    },
    {
      "x": -11,
      "y": 29,
      "z": -8,
      "name": "Soil_Ash"
    },
    {
      "x": -11,
      "y": 30,
      "z": -8,
      "name": "Soil_Ash"
    },
    {
      "x": -11,
      "y": 31,
      "z": -8,
      "name": "Rock_Slate"
    },
    {
      "x": -11,
      "y": 32,
      "z": -8,
      "name": "Soil_Slate_Gravel"
    },
    {
      "x": -11,
      "y": 33,
      "z": -8,
      "name": "Soil_Ash"
    },
    {
      "x": -11,
      "y": 25,
      "z": -7,
      "name": "Rock_Slate"
    },
    {
      "x": -11,
      "y": 26,
      "z": -7,
      "name": "Rock_Slate"
    },
    {
      "x": -11,
      "y": 27,
      "z": -7,
      "name": "Rock_Slate"
    },
    {
      "x": -11,
      "y": 28,
      "z": -7,
      "name": "Soil_Ash"
    },
    {
      "x": -11,
      "y": 29,
      "z": -7,
      "name": "Soil_Slate_Gravel"
    },
    {
      "x": -11,
      "y": 30,
      "z": -7,
      "name": "Rock_Slate"
    },
    {
      "x": -11,
      "y": 31,
      "z": -7,
      "name": "Soil_Ash"
    },
    {
      "x": -11,
      "y": 32,
      "z": -7,
      "name": "Soil_Ash"
    },
    {
      "x": -11,
      "y": 24,
      "z": -6,
      "name": "Rock_Slate"
    },
    {
      "x": -11,
      "y": 25,
      "z": -6,
      "name": "Rock_Slate"
    },
    {
      "x": -11,
      "y": 26,
      "z": -6,
      "name": "Soil_Ash"
    },
    {
      "x": -11,
      "y": 27,
      "z": -6,
      "name": "Rock_Slate"
    },
    {
      "x": -11,
      "y": 28,
      "z": -6,
      "name": "Soil_Slate_Gravel"
    },
    {
      "x": -11,
      "y": 29,
      "z": -6,
      "name": "Soil_Ash"
    },
    {
      "x": -11,
      "y": 30,
      "z": -6,
      "name": "Rock_Slate"
    },
    {
      "x": -11,
      "y": 31,
      "z": -6,
      "name": "Soil_Ash"
    },
    {
      "x": -11,
      "y": 23,
      "z": -5,
      "name": "Rock_Slate"
    },
    {
      "x": -11,
      "y": 24,
      "z": -5,
      "name": "Rock_Slate"
    },
    {
      "x": -11,
      "y": 25,
      "z": -5,
      "name": "Soil_Slate_Gravel"
    },
    {
      "x": -11,
      "y": 26,
      "z": -5,
      "name": "Soil_Slate_Gravel"
    },
    {
      "x": -11,
      "y": 27,
      "z": -5,
      "name": "Soil_Ash"
    },
    {
      "x": -11,
      "y": 28,
      "z": -5,
      "name": "Rock_Slate"
    },
    {
      "x": -11,
      "y": 29,
      "z": -5,
      "name": "Soil_Slate_Gravel"
    },
    {
      "x": -11,
      "y": 30,
      "z": -5,
      "name": "Rock_Slate"
    },
    {
      "x": -11,
      "y": 22,
      "z": -4,
      "name": "Rock_Slate"
    },
    {
      "x": -11,
      "y": 23,
      "z": -4,
      "name": "Rock_Slate"
    },
    {
      "x": -11,
      "y": 24,
      "z": -4,
      "name": "Rock_Slate"
    },
    {
      "x": -11,
      "y": 25,
      "z": -4,
      "name": "Rock_Slate"
    },
    {
      "x": -11,
      "y": 26,
      "z": -4,
      "name": "Rock_Slate"
    },
    {
      "x": -11,
      "y": 27,
      "z": -4,
      "name": "Soil_Ash"
    },
    {
      "x": -11,
      "y": 28,
      "z": -4,
      "name": "Soil_Ash"
    },
    {
      "x": -11,
      "y": 29,
      "z": -4,
      "name": "Rock_Slate"
    },
    {
      "x": -11,
      "y": 30,
      "z": -4,
      "name": "Rock_Slate"
    },
    {
      "x": -11,
      "y": 19,
      "z": -3,
      "name": "Rock_Slate"
    },
    {
      "x": -11,
      "y": 20,
      "z": -3,
      "name": "Rock_Slate"
    },
    {
      "x": -11,
      "y": 21,
      "z": -3,
      "name": "Rock_Slate"
    },
    {
      "x": -11,
      "y": 22,
      "z": -3,
      "name": "Rock_Slate"
    },
    {
      "x": -11,
      "y": 23,
      "z": -3,
      "name": "Rock_Slate"
    },
    {
      "x": -11,
      "y": 24,
      "z": -3,
      "name": "Rock_Slate"
    },
    {
      "x": -11,
      "y": 25,
      "z": -3,
      "name": "Soil_Ash"
    },
    {
      "x": -11,
      "y": 26,
      "z": -3,
      "name": "Rock_Slate"
    },
    {
      "x": -11,
      "y": 27,
      "z": -3,
      "name": "Soil_Ash"
    },
    {
      "x": -11,
      "y": 28,
      "z": -3,
      "name": "Rock_Slate"
    },
    {
      "x": -11,
      "y": 29,
      "z": -3,
      "name": "Rock_Slate"
    },
    {
      "x": -11,
      "y": 18,
      "z": -2,
      "name": "Rock_Slate"
    },
    {
      "x": -11,
      "y": 19,
      "z": -2,
      "name": "Rock_Slate"
    },
    {
      "x": -11,
      "y": 20,
      "z": -2,
      "name": "Rock_Slate"
    },
    {
      "x": -11,
      "y": 21,
      "z": -2,
      "name": "Rock_Slate"
    },
    {
      "x": -11,
      "y": 22,
      "z": -2,
      "name": "Rock_Slate"
    },
    {
      "x": -11,
      "y": 23,
      "z": -2,
      "name": "Rock_Slate"
    },
    {
      "x": -11,
      "y": 24,
      "z": -2,
      "name": "Soil_Slate_Gravel"
    },
    {
      "x": -11,
      "y": 25,
      "z": -2,
      "name": "Soil_Ash"
    },
    {
      "x": -11,
      "y": 26,
      "z": -2,
      "name": "Soil_Ash"
    },
    {
      "x": -11,
      "y": 27,
      "z": -2,
      "name": "Rock_Slate"
    },
    {
      "x": -11,
      "y": 28,
      "z": -2,
      "name": "Soil_Ash"
    },
    {
      "x": -11,
      "y": 17,
      "z": -1,
      "name": "Rock_Slate"
    },
    {
      "x": -11,
      "y": 18,
      "z": -1,
      "name": "Rock_Slate"
    },
    {
      "x": -11,
      "y": 19,
      "z": -1,
      "name": "Rock_Slate"
    },
    {
      "x": -11,
      "y": 20,
      "z": -1,
      "name": "Rock_Slate"
    },
    {
      "x": -11,
      "y": 21,
      "z": -1,
      "name": "Rock_Slate"
    },
    {
      "x": -11,
      "y": 22,
      "z": -1,
      "name": "Rock_Slate"
    },
    {
      "x": -11,
      "y": 23,
      "z": -1,
      "name": "Rock_Slate"
    },
    {
      "x": -11,
      "y": 24,
      "z": -1,
      "name": "Soil_Slate_Gravel"
    },
    {
      "x": -11,
      "y": 25,
      "z": -1,
      "name": "Soil_Slate_Gravel"
    },
    {
      "x": -11,
      "y": 26,
      "z": -1,
      "name": "Soil_Ash"
    },
    {
      "x": -11,
      "y": 27,
      "z": -1,
      "name": "Soil_Ash"
    },
    {
      "x": -11,
      "y": 28,
      "z": -1,
      "name": "Soil_Ash"
    },
    {
      "x": -11,
      "y": 14,
      "z": 0,
      "name": "Plant_Crop_Mushroom_Block_Purple_Mycelium"
    },
    {
      "x": -11,
      "y": 15,
      "z": 0,
      "name": "Rock_Slate"
    },
    {
      "x": -11,
      "y": 16,
      "z": 0,
      "name": "Rock_Slate"
    },
    {
      "x": -11,
      "y": 17,
      "z": 0,
      "name": "Rock_Slate"
    },
    {
      "x": -11,
      "y": 18,
      "z": 0,
      "name": "Rock_Slate"
    },
    {
      "x": -11,
      "y": 19,
      "z": 0,
      "name": "Rock_Slate"
    },
    {
      "x": -11,
      "y": 20,
      "z": 0,
      "name": "Rock_Slate"
    },
    {
      "x": -11,
      "y": 21,
      "z": 0,
      "name": "Rock_Slate"
    },
    {
      "x": -11,
      "y": 22,
      "z": 0,
      "name": "Ore_Cobalt_Slate"
    },
    {
      "x": -11,
      "y": 23,
      "z": 0,
      "name": "Soil_Ash"
    },
    {
      "x": -11,
      "y": 24,
      "z": 0,
      "name": "Soil_Ash"
    },
    {
      "x": -11,
      "y": 25,
      "z": 0,
      "name": "Soil_Slate_Gravel"
    },
    {
      "x": -11,
      "y": 26,
      "z": 0,
      "name": "Soil_Ash"
    },
    {
      "x": -11,
      "y": 27,
      "z": 0,
      "name": "Soil_Ash"
    },
    {
      "x": -11,
      "y": 28,
      "z": 0,
      "name": "Soil_Ash"
    },
    {
      "x": -11,
      "y": 14,
      "z": 1,
      "name": "Rock_Slate"
    },
    {
      "x": -11,
      "y": 15,
      "z": 1,
      "name": "Rock_Slate"
    },
    {
      "x": -11,
      "y": 16,
      "z": 1,
      "name": "Rock_Slate"
    },
    {
      "x": -11,
      "y": 17,
      "z": 1,
      "name": "Rock_Slate"
    },
    {
      "x": -11,
      "y": 18,
      "z": 1,
      "name": "Rock_Slate"
    },
    {
      "x": -11,
      "y": 19,
      "z": 1,
      "name": "Rock_Slate"
    },
    {
      "x": -11,
      "y": 20,
      "z": 1,
      "name": "Rock_Slate"
    },
    {
      "x": -11,
      "y": 21,
      "z": 1,
      "name": "Rock_Slate"
    },
    {
      "x": -11,
      "y": 22,
      "z": 1,
      "name": "Ore_Cobalt_Slate"
    },
    {
      "x": -11,
      "y": 23,
      "z": 1,
      "name": "Soil_Ash"
    },
    {
      "x": -11,
      "y": 24,
      "z": 1,
      "name": "Rock_Slate"
    },
    {
      "x": -11,
      "y": 25,
      "z": 1,
      "name": "Soil_Ash"
    },
    {
      "x": -11,
      "y": 26,
      "z": 1,
      "name": "Soil_Slate_Gravel"
    },
    {
      "x": -11,
      "y": 27,
      "z": 1,
      "name": "Soil_Ash"
    },
    {
      "x": -11,
      "y": 28,
      "z": 1,
      "name": "Plant_Flower_Bushy_Purple"
    },
    {
      "x": -11,
      "y": 13,
      "z": 2,
      "name": "Plant_Crop_Mushroom_Block_Purple_Mycelium"
    },
    {
      "x": -11,
      "y": 14,
      "z": 2,
      "name": "Rock_Slate"
    },
    {
      "x": -11,
      "y": 15,
      "z": 2,
      "name": "Rock_Slate"
    },
    {
      "x": -11,
      "y": 16,
      "z": 2,
      "name": "Rock_Slate"
    },
    {
      "x": -11,
      "y": 17,
      "z": 2,
      "name": "Rock_Slate"
    },
    {
      "x": -11,
      "y": 18,
      "z": 2,
      "name": "Rock_Slate"
    },
    {
      "x": -11,
      "y": 19,
      "z": 2,
      "name": "Rock_Slate"
    },
    {
      "x": -11,
      "y": 20,
      "z": 2,
      "name": "Rock_Slate"
    },
    {
      "x": -11,
      "y": 21,
      "z": 2,
      "name": "Rock_Slate"
    },
    {
      "x": -11,
      "y": 22,
      "z": 2,
      "name": "Soil_Ash"
    },
    {
      "x": -11,
      "y": 23,
      "z": 2,
      "name": "Soil_Slate_Gravel"
    },
    {
      "x": -11,
      "y": 24,
      "z": 2,
      "name": "Rock_Slate"
    },
    {
      "x": -11,
      "y": 25,
      "z": 2,
      "name": "Soil_Ash"
    },
    {
      "x": -11,
      "y": 26,
      "z": 2,
      "name": "Soil_Ash"
    },
    {
      "x": -11,
      "y": 27,
      "z": 2,
      "name": "Soil_Ash"
    },
    {
      "x": -11,
      "y": 14,
      "z": 3,
      "name": "Rock_Slate"
    },
    {
      "x": -11,
      "y": 15,
      "z": 3,
      "name": "Rock_Slate"
    },
    {
      "x": -11,
      "y": 16,
      "z": 3,
      "name": "Rock_Slate"
    },
    {
      "x": -11,
      "y": 17,
      "z": 3,
      "name": "Rock_Slate"
    },
    {
      "x": -11,
      "y": 18,
      "z": 3,
      "name": "Rock_Slate"
    },
    {
      "x": -11,
      "y": 19,
      "z": 3,
      "name": "Rock_Slate"
    },
    {
      "x": -11,
      "y": 20,
      "z": 3,
      "name": "Rock_Slate"
    },
    {
      "x": -11,
      "y": 21,
      "z": 3,
      "name": "Rock_Slate"
    },
    {
      "x": -11,
      "y": 22,
      "z": 3,
      "name": "Soil_Ash"
    },
    {
      "x": -11,
      "y": 23,
      "z": 3,
      "name": "Rock_Slate"
    },
    {
      "x": -11,
      "y": 24,
      "z": 3,
      "name": "Rock_Slate"
    },
    {
      "x": -11,
      "y": 25,
      "z": 3,
      "name": "Soil_Ash"
    },
    {
      "x": -11,
      "y": 26,
      "z": 3,
      "name": "Soil_Ash"
    },
    {
      "x": -11,
      "y": 14,
      "z": 4,
      "name": "Rock_Slate"
    },
    {
      "x": -11,
      "y": 15,
      "z": 4,
      "name": "Rock_Slate"
    },
    {
      "x": -11,
      "y": 16,
      "z": 4,
      "name": "Rock_Slate"
    },
    {
      "x": -11,
      "y": 17,
      "z": 4,
      "name": "Rock_Slate"
    },
    {
      "x": -11,
      "y": 18,
      "z": 4,
      "name": "Rock_Slate"
    },
    {
      "x": -11,
      "y": 19,
      "z": 4,
      "name": "Rock_Slate"
    },
    {
      "x": -11,
      "y": 20,
      "z": 4,
      "name": "Rock_Slate"
    },
    {
      "x": -11,
      "y": 21,
      "z": 4,
      "name": "Rock_Slate"
    },
    {
      "x": -11,
      "y": 22,
      "z": 4,
      "name": "Soil_Ash"
    },
    {
      "x": -11,
      "y": 23,
      "z": 4,
      "name": "Soil_Ash"
    },
    {
      "x": -11,
      "y": 24,
      "z": 4,
      "name": "Soil_Ash"
    },
    {
      "x": -11,
      "y": 25,
      "z": 4,
      "name": "Soil_Ash"
    },
    {
      "x": -11,
      "y": 26,
      "z": 4,
      "name": "Soil_Ash"
    },
    {
      "x": -11,
      "y": 13,
      "z": 5,
      "name": "Rock_Slate"
    },
    {
      "x": -11,
      "y": 14,
      "z": 5,
      "name": "Rock_Slate"
    },
    {
      "x": -11,
      "y": 15,
      "z": 5,
      "name": "Rock_Slate"
    },
    {
      "x": -11,
      "y": 16,
      "z": 5,
      "name": "Rock_Slate"
    },
    {
      "x": -11,
      "y": 17,
      "z": 5,
      "name": "Rock_Slate"
    },
    {
      "x": -11,
      "y": 18,
      "z": 5,
      "name": "Rock_Slate"
    },
    {
      "x": -11,
      "y": 19,
      "z": 5,
      "name": "Rock_Slate"
    },
    {
      "x": -11,
      "y": 20,
      "z": 5,
      "name": "Rock_Slate"
    },
    {
      "x": -11,
      "y": 21,
      "z": 5,
      "name": "Soil_Ash"
    },
    {
      "x": -11,
      "y": 22,
      "z": 5,
      "name": "Soil_Ash"
    },
    {
      "x": -11,
      "y": 23,
      "z": 5,
      "name": "Soil_Ash"
    },
    {
      "x": -11,
      "y": 24,
      "z": 5,
      "name": "Soil_Ash"
    },
    {
      "x": -11,
      "y": 25,
      "z": 5,
      "name": "Soil_Ash"
    },
    {
      "x": -11,
      "y": 14,
      "z": 6,
      "name": "Ore_Cobalt_Slate_Cracked"
    },
    {
      "x": -11,
      "y": 15,
      "z": 6,
      "name": "Rock_Slate"
    },
    {
      "x": -11,
      "y": 16,
      "z": 6,
      "name": "Rock_Slate"
    },
    {
      "x": -11,
      "y": 17,
      "z": 6,
      "name": "Rock_Slate"
    },
    {
      "x": -11,
      "y": 18,
      "z": 6,
      "name": "Rock_Slate"
    },
    {
      "x": -11,
      "y": 19,
      "z": 6,
      "name": "Rock_Slate"
    },
    {
      "x": -11,
      "y": 20,
      "z": 6,
      "name": "Rock_Slate"
    },
    {
      "x": -11,
      "y": 21,
      "z": 6,
      "name": "Soil_Ash"
    },
    {
      "x": -11,
      "y": 22,
      "z": 6,
      "name": "Soil_Ash"
    },
    {
      "x": -11,
      "y": 23,
      "z": 6,
      "name": "Soil_Ash"
    },
    {
      "x": -11,
      "y": 24,
      "z": 6,
      "name": "Rock_Slate"
    },
    {
      "x": -11,
      "y": 25,
      "z": 6,
      "name": "Soil_Slate_Gravel"
    },
    {
      "x": -11,
      "y": 26,
      "z": 6,
      "name": "Plant_Coral_Model_Purple"
    },
    {
      "x": -11,
      "y": 15,
      "z": 7,
      "name": "Rock_Slate"
    },
    {
      "x": -11,
      "y": 16,
      "z": 7,
      "name": "Rock_Slate"
    },
    {
      "x": -11,
      "y": 17,
      "z": 7,
      "name": "Rock_Slate"
    },
    {
      "x": -11,
      "y": 18,
      "z": 7,
      "name": "Rock_Slate"
    },
    {
      "x": -11,
      "y": 19,
      "z": 7,
      "name": "Rock_Slate"
    },
    {
      "x": -11,
      "y": 20,
      "z": 7,
      "name": "Soil_Ash"
    },
    {
      "x": -11,
      "y": 21,
      "z": 7,
      "name": "Soil_Slate_Gravel"
    },
    {
      "x": -11,
      "y": 22,
      "z": 7,
      "name": "Soil_Ash"
    },
    {
      "x": -11,
      "y": 23,
      "z": 7,
      "name": "Soil_Ash"
    },
    {
      "x": -11,
      "y": 24,
      "z": 7,
      "name": "Soil_Ash"
    },
    {
      "x": -11,
      "y": 17,
      "z": 8,
      "name": "Rock_Slate"
    },
    {
      "x": -11,
      "y": 18,
      "z": 8,
      "name": "Rock_Slate"
    },
    {
      "x": -11,
      "y": 19,
      "z": 8,
      "name": "Rock_Slate"
    },
    {
      "x": -11,
      "y": 20,
      "z": 8,
      "name": "Rock_Slate"
    },
    {
      "x": -11,
      "y": 21,
      "z": 8,
      "name": "Soil_Ash"
    },
    {
      "x": -11,
      "y": 22,
      "z": 8,
      "name": "Soil_Ash"
    },
    {
      "x": -11,
      "y": 19,
      "z": 9,
      "name": "Ore_Cobalt_Slate_Cracked"
    },
    {
      "x": -11,
      "y": 20,
      "z": 9,
      "name": "Soil_Ash"
    },
    {
      "x": -11,
      "y": 21,
      "z": 9,
      "name": "Soil_Ash"
    },
    {
      "x": -10,
      "y": 27,
      "z": -12,
      "name": "Rock_Slate"
    },
    {
      "x": -10,
      "y": 23,
      "z": -11,
      "name": "Ore_Cobalt_Slate_Cracked"
    },
    {
      "x": -10,
      "y": 24,
      "z": -11,
      "name": "Rock_Slate"
    },
    {
      "x": -10,
      "y": 25,
      "z": -11,
      "name": "Rock_Slate"
    },
    {
      "x": -10,
      "y": 26,
      "z": -11,
      "name": "Rock_Slate"
    },
    {
      "x": -10,
      "y": 27,
      "z": -11,
      "name": "Rock_Slate"
    },
    {
      "x": -10,
      "y": 28,
      "z": -11,
      "name": "Rock_Slate"
    },
    {
      "x": -10,
      "y": 29,
      "z": -11,
      "name": "Rock_Slate"
    },
    {
      "x": -10,
      "y": 30,
      "z": -11,
      "name": "Rock_Slate"
    },
    {
      "x": -10,
      "y": 31,
      "z": -11,
      "name": "Rock_Slate"
    },
    {
      "x": -10,
      "y": 32,
      "z": -11,
      "name": "Soil_Ash"
    },
    {
      "x": -10,
      "y": 33,
      "z": -11,
      "name": "Soil_Ash"
    },
    {
      "x": -10,
      "y": 34,
      "z": -11,
      "name": "Soil_Slate_Gravel"
    },
    {
      "x": -10,
      "y": 22,
      "z": -10,
      "name": "Rock_Slate"
    },
    {
      "x": -10,
      "y": 23,
      "z": -10,
      "name": "Rock_Slate"
    },
    {
      "x": -10,
      "y": 24,
      "z": -10,
      "name": "Ore_Cobalt_Slate_Cracked"
    },
    {
      "x": -10,
      "y": 25,
      "z": -10,
      "name": "Rock_Slate"
    },
    {
      "x": -10,
      "y": 26,
      "z": -10,
      "name": "Rock_Slate"
    },
    {
      "x": -10,
      "y": 27,
      "z": -10,
      "name": "Rock_Slate"
    },
    {
      "x": -10,
      "y": 28,
      "z": -10,
      "name": "Rock_Slate"
    },
    {
      "x": -10,
      "y": 29,
      "z": -10,
      "name": "Rock_Slate"
    },
    {
      "x": -10,
      "y": 30,
      "z": -10,
      "name": "Rock_Slate"
    },
    {
      "x": -10,
      "y": 31,
      "z": -10,
      "name": "Soil_Ash"
    },
    {
      "x": -10,
      "y": 32,
      "z": -10,
      "name": "Rock_Slate"
    },
    {
      "x": -10,
      "y": 33,
      "z": -10,
      "name": "Rock_Slate"
    },
    {
      "x": -10,
      "y": 34,
      "z": -10,
      "name": "Soil_Ash"
    },
    {
      "x": -10,
      "y": 35,
      "z": -10,
      "name": "Plant_Coral_Model_Pink"
    },
    {
      "x": -10,
      "y": 21,
      "z": -9,
      "name": "Rock_Slate"
    },
    {
      "x": -10,
      "y": 22,
      "z": -9,
      "name": "Rock_Slate"
    },
    {
      "x": -10,
      "y": 23,
      "z": -9,
      "name": "Rock_Slate"
    },
    {
      "x": -10,
      "y": 24,
      "z": -9,
      "name": "Rock_Slate"
    },
    {
      "x": -10,
      "y": 25,
      "z": -9,
      "name": "Rock_Slate"
    },
    {
      "x": -10,
      "y": 26,
      "z": -9,
      "name": "Rock_Slate"
    },
    {
      "x": -10,
      "y": 27,
      "z": -9,
      "name": "Rock_Slate"
    },
    {
      "x": -10,
      "y": 28,
      "z": -9,
      "name": "Rock_Slate"
    },
    {
      "x": -10,
      "y": 29,
      "z": -9,
      "name": "Rock_Slate"
    },
    {
      "x": -10,
      "y": 30,
      "z": -9,
      "name": "Soil_Ash"
    },
    {
      "x": -10,
      "y": 31,
      "z": -9,
      "name": "Soil_Ash"
    },
    {
      "x": -10,
      "y": 32,
      "z": -9,
      "name": "Rock_Slate"
    },
    {
      "x": -10,
      "y": 33,
      "z": -9,
      "name": "Soil_Ash"
    },
    {
      "x": -10,
      "y": 34,
      "z": -9,
      "name": "Soil_Slate_Gravel"
    },
    {
      "x": -10,
      "y": 35,
      "z": -9,
      "name": "Plant_Coral_Bush_Purple"
    },
    {
      "x": -10,
      "y": 22,
      "z": -8,
      "name": "Rock_Slate"
    },
    {
      "x": -10,
      "y": 23,
      "z": -8,
      "name": "Rock_Slate"
    },
    {
      "x": -10,
      "y": 24,
      "z": -8,
      "name": "Rock_Slate"
    },
    {
      "x": -10,
      "y": 25,
      "z": -8,
      "name": "Rock_Slate"
    },
    {
      "x": -10,
      "y": 26,
      "z": -8,
      "name": "Rock_Slate"
    },
    {
      "x": -10,
      "y": 27,
      "z": -8,
      "name": "Rock_Slate"
    },
    {
      "x": -10,
      "y": 28,
      "z": -8,
      "name": "Rock_Slate"
    },
    {
      "x": -10,
      "y": 29,
      "z": -8,
      "name": "Soil_Ash"
    },
    {
      "x": -10,
      "y": 30,
      "z": -8,
      "name": "Soil_Slate_Gravel"
    },
    {
      "x": -10,
      "y": 31,
      "z": -8,
      "name": "Soil_Slate_Gravel"
    },
    {
      "x": -10,
      "y": 32,
      "z": -8,
      "name": "Soil_Ash"
    },
    {
      "x": -10,
      "y": 33,
      "z": -8,
      "name": "Soil_Slate_Gravel"
    },
    {
      "x": -10,
      "y": 34,
      "z": -8,
      "name": "Soil_Ash"
    },
    {
      "x": -10,
      "y": 23,
      "z": -7,
      "name": "Rock_Slate"
    },
    {
      "x": -10,
      "y": 24,
      "z": -7,
      "name": "Rock_Slate"
    },
    {
      "x": -10,
      "y": 25,
      "z": -7,
      "name": "Rock_Slate"
    },
    {
      "x": -10,
      "y": 26,
      "z": -7,
      "name": "Rock_Slate"
    },
    {
      "x": -10,
      "y": 27,
      "z": -7,
      "name": "Rock_Slate"
    },
    {
      "x": -10,
      "y": 28,
      "z": -7,
      "name": "Soil_Ash"
    },
    {
      "x": -10,
      "y": 29,
      "z": -7,
      "name": "Soil_Ash"
    },
    {
      "x": -10,
      "y": 30,
      "z": -7,
      "name": "Soil_Ash"
    },
    {
      "x": -10,
      "y": 31,
      "z": -7,
      "name": "Soil_Slate_Gravel"
    },
    {
      "x": -10,
      "y": 32,
      "z": -7,
      "name": "Soil_Ash"
    },
    {
      "x": -10,
      "y": 33,
      "z": -7,
      "name": "Soil_Ash"
    },
    {
      "x": -10,
      "y": 22,
      "z": -6,
      "name": "Rock_Slate"
    },
    {
      "x": -10,
      "y": 23,
      "z": -6,
      "name": "Rock_Slate"
    },
    {
      "x": -10,
      "y": 24,
      "z": -6,
      "name": "Rock_Slate"
    },
    {
      "x": -10,
      "y": 25,
      "z": -6,
      "name": "Rock_Slate"
    },
    {
      "x": -10,
      "y": 26,
      "z": -6,
      "name": "Soil_Slate_Gravel"
    },
    {
      "x": -10,
      "y": 27,
      "z": -6,
      "name": "Rock_Slate"
    },
    {
      "x": -10,
      "y": 28,
      "z": -6,
      "name": "Soil_Ash"
    },
    {
      "x": -10,
      "y": 29,
      "z": -6,
      "name": "Rock_Slate"
    },
    {
      "x": -10,
      "y": 30,
      "z": -6,
      "name": "Soil_Slate_Gravel"
    },
    {
      "x": -10,
      "y": 31,
      "z": -6,
      "name": "Soil_Slate_Gravel"
    },
    {
      "x": -10,
      "y": 32,
      "z": -6,
      "name": "Soil_Ash"
    },
    {
      "x": -10,
      "y": 33,
      "z": -6,
      "name": "Soil_Ash"
    },
    {
      "x": -10,
      "y": 21,
      "z": -5,
      "name": "Rock_Slate"
    },
    {
      "x": -10,
      "y": 22,
      "z": -5,
      "name": "Rock_Slate"
    },
    {
      "x": -10,
      "y": 23,
      "z": -5,
      "name": "Rock_Slate"
    },
    {
      "x": -10,
      "y": 24,
      "z": -5,
      "name": "Rock_Slate"
    },
    {
      "x": -10,
      "y": 25,
      "z": -5,
      "name": "Rock_Slate"
    },
    {
      "x": -10,
      "y": 26,
      "z": -5,
      "name": "Soil_Ash"
    },
    {
      "x": -10,
      "y": 27,
      "z": -5,
      "name": "Soil_Ash"
    },
    {
      "x": -10,
      "y": 28,
      "z": -5,
      "name": "Soil_Slate_Gravel"
    },
    {
      "x": -10,
      "y": 29,
      "z": -5,
      "name": "Rock_Slate"
    },
    {
      "x": -10,
      "y": 30,
      "z": -5,
      "name": "Rock_Slate"
    },
    {
      "x": -10,
      "y": 31,
      "z": -5,
      "name": "Soil_Ash"
    },
    {
      "x": -10,
      "y": 32,
      "z": -5,
      "name": "Soil_Ash"
    },
    {
      "x": -10,
      "y": 20,
      "z": -4,
      "name": "Rock_Slate"
    },
    {
      "x": -10,
      "y": 21,
      "z": -4,
      "name": "Rock_Slate"
    },
    {
      "x": -10,
      "y": 22,
      "z": -4,
      "name": "Rock_Slate"
    },
    {
      "x": -10,
      "y": 23,
      "z": -4,
      "name": "Rock_Slate"
    },
    {
      "x": -10,
      "y": 24,
      "z": -4,
      "name": "Rock_Slate"
    },
    {
      "x": -10,
      "y": 25,
      "z": -4,
      "name": "Rock_Slate"
    },
    {
      "x": -10,
      "y": 26,
      "z": -4,
      "name": "Soil_Ash"
    },
    {
      "x": -10,
      "y": 27,
      "z": -4,
      "name": "Rock_Slate"
    },
    {
      "x": -10,
      "y": 28,
      "z": -4,
      "name": "Soil_Ash"
    },
    {
      "x": -10,
      "y": 29,
      "z": -4,
      "name": "Soil_Ash"
    },
    {
      "x": -10,
      "y": 30,
      "z": -4,
      "name": "Soil_Ash"
    },
    {
      "x": -10,
      "y": 31,
      "z": -4,
      "name": "Soil_Ash"
    },
    {
      "x": -10,
      "y": 18,
      "z": -3,
      "name": "Rock_Slate"
    },
    {
      "x": -10,
      "y": 19,
      "z": -3,
      "name": "Rock_Slate"
    },
    {
      "x": -10,
      "y": 20,
      "z": -3,
      "name": "Rock_Slate"
    },
    {
      "x": -10,
      "y": 21,
      "z": -3,
      "name": "Rock_Slate"
    },
    {
      "x": -10,
      "y": 22,
      "z": -3,
      "name": "Rock_Slate"
    },
    {
      "x": -10,
      "y": 23,
      "z": -3,
      "name": "Rock_Slate"
    },
    {
      "x": -10,
      "y": 24,
      "z": -3,
      "name": "Rock_Slate"
    },
    {
      "x": -10,
      "y": 25,
      "z": -3,
      "name": "Soil_Slate_Gravel"
    },
    {
      "x": -10,
      "y": 26,
      "z": -3,
      "name": "Rock_Slate"
    },
    {
      "x": -10,
      "y": 27,
      "z": -3,
      "name": "Soil_Slate_Gravel"
    },
    {
      "x": -10,
      "y": 28,
      "z": -3,
      "name": "Rock_Slate"
    },
    {
      "x": -10,
      "y": 29,
      "z": -3,
      "name": "Rock_Slate"
    },
    {
      "x": -10,
      "y": 30,
      "z": -3,
      "name": "Rock_Slate"
    },
    {
      "x": -10,
      "y": 17,
      "z": -2,
      "name": "Rock_Slate"
    },
    {
      "x": -10,
      "y": 18,
      "z": -2,
      "name": "Rock_Slate"
    },
    {
      "x": -10,
      "y": 19,
      "z": -2,
      "name": "Rock_Slate"
    },
    {
      "x": -10,
      "y": 20,
      "z": -2,
      "name": "Rock_Slate"
    },
    {
      "x": -10,
      "y": 21,
      "z": -2,
      "name": "Rock_Slate"
    },
    {
      "x": -10,
      "y": 22,
      "z": -2,
      "name": "Rock_Slate"
    },
    {
      "x": -10,
      "y": 23,
      "z": -2,
      "name": "Rock_Slate"
    },
    {
      "x": -10,
      "y": 24,
      "z": -2,
      "name": "Soil_Ash"
    },
    {
      "x": -10,
      "y": 25,
      "z": -2,
      "name": "Rock_Slate"
    },
    {
      "x": -10,
      "y": 26,
      "z": -2,
      "name": "Soil_Ash"
    },
    {
      "x": -10,
      "y": 27,
      "z": -2,
      "name": "Soil_Slate_Gravel"
    },
    {
      "x": -10,
      "y": 28,
      "z": -2,
      "name": "Soil_Ash"
    },
    {
      "x": -10,
      "y": 29,
      "z": -2,
      "name": "Rock_Slate"
    },
    {
      "x": -10,
      "y": 16,
      "z": -1,
      "name": "Ore_Cobalt_Slate_Cracked"
    },
    {
      "x": -10,
      "y": 17,
      "z": -1,
      "name": "Rock_Slate"
    },
    {
      "x": -10,
      "y": 18,
      "z": -1,
      "name": "Rock_Slate"
    },
    {
      "x": -10,
      "y": 19,
      "z": -1,
      "name": "Rock_Slate"
    },
    {
      "x": -10,
      "y": 20,
      "z": -1,
      "name": "Rock_Slate"
    },
    {
      "x": -10,
      "y": 21,
      "z": -1,
      "name": "Rock_Slate"
    },
    {
      "x": -10,
      "y": 22,
      "z": -1,
      "name": "Rock_Slate"
    },
    {
      "x": -10,
      "y": 23,
      "z": -1,
      "name": "Rock_Slate"
    },
    {
      "x": -10,
      "y": 24,
      "z": -1,
      "name": "Soil_Ash"
    },
    {
      "x": -10,
      "y": 25,
      "z": -1,
      "name": "Soil_Ash"
    },
    {
      "x": -10,
      "y": 26,
      "z": -1,
      "name": "Soil_Slate_Gravel"
    },
    {
      "x": -10,
      "y": 27,
      "z": -1,
      "name": "Soil_Ash"
    },
    {
      "x": -10,
      "y": 28,
      "z": -1,
      "name": "Soil_Ash"
    },
    {
      "x": -10,
      "y": 29,
      "z": -1,
      "name": "Soil_Ash"
    },
    {
      "x": -10,
      "y": 30,
      "z": -1,
      "name": "Plant_Coral_Model_Purple"
    },
    {
      "x": -10,
      "y": 15,
      "z": 0,
      "name": "Plant_Crop_Mushroom_Block_Purple_Mycelium"
    },
    {
      "x": -10,
      "y": 16,
      "z": 0,
      "name": "Rock_Slate"
    },
    {
      "x": -10,
      "y": 17,
      "z": 0,
      "name": "Rock_Slate"
    },
    {
      "x": -10,
      "y": 18,
      "z": 0,
      "name": "Rock_Slate"
    },
    {
      "x": -10,
      "y": 19,
      "z": 0,
      "name": "Rock_Slate"
    },
    {
      "x": -10,
      "y": 20,
      "z": 0,
      "name": "Rock_Slate"
    },
    {
      "x": -10,
      "y": 21,
      "z": 0,
      "name": "Rock_Slate"
    },
    {
      "x": -10,
      "y": 22,
      "z": 0,
      "name": "Ore_Cobalt_Slate"
    },
    {
      "x": -10,
      "y": 23,
      "z": 0,
      "name": "Soil_Slate_Gravel"
    },
    {
      "x": -10,
      "y": 24,
      "z": 0,
      "name": "Soil_Slate_Gravel"
    },
    {
      "x": -10,
      "y": 25,
      "z": 0,
      "name": "Soil_Ash"
    },
    {
      "x": -10,
      "y": 26,
      "z": 0,
      "name": "Rock_Slate"
    },
    {
      "x": -10,
      "y": 27,
      "z": 0,
      "name": "Rock_Slate"
    },
    {
      "x": -10,
      "y": 28,
      "z": 0,
      "name": "Soil_Ash"
    },
    {
      "x": -10,
      "y": 15,
      "z": 1,
      "name": "Rock_Slate"
    },
    {
      "x": -10,
      "y": 16,
      "z": 1,
      "name": "Rock_Slate"
    },
    {
      "x": -10,
      "y": 17,
      "z": 1,
      "name": "Rock_Slate"
    },
    {
      "x": -10,
      "y": 18,
      "z": 1,
      "name": "Rock_Slate"
    },
    {
      "x": -10,
      "y": 19,
      "z": 1,
      "name": "Rock_Slate"
    },
    {
      "x": -10,
      "y": 20,
      "z": 1,
      "name": "Rock_Slate"
    },
    {
      "x": -10,
      "y": 21,
      "z": 1,
      "name": "Rock_Slate"
    },
    {
      "x": -10,
      "y": 22,
      "z": 1,
      "name": "Soil_Slate_Gravel"
    },
    {
      "x": -10,
      "y": 23,
      "z": 1,
      "name": "Ore_Cobalt_Slate"
    },
    {
      "x": -10,
      "y": 24,
      "z": 1,
      "name": "Soil_Ash"
    },
    {
      "x": -10,
      "y": 25,
      "z": 1,
      "name": "Soil_Slate_Gravel"
    },
    {
      "x": -10,
      "y": 26,
      "z": 1,
      "name": "Rock_Slate"
    },
    {
      "x": -10,
      "y": 27,
      "z": 1,
      "name": "Soil_Ash"
    },
    {
      "x": -10,
      "y": 28,
      "z": 1,
      "name": "Soil_Ash"
    },
    {
      "x": -10,
      "y": 14,
      "z": 2,
      "name": "Rock_Slate"
    },
    {
      "x": -10,
      "y": 15,
      "z": 2,
      "name": "Rock_Slate"
    },
    {
      "x": -10,
      "y": 16,
      "z": 2,
      "name": "Rock_Slate"
    },
    {
      "x": -10,
      "y": 17,
      "z": 2,
      "name": "Rock_Slate"
    },
    {
      "x": -10,
      "y": 18,
      "z": 2,
      "name": "Rock_Slate"
    },
    {
      "x": -10,
      "y": 19,
      "z": 2,
      "name": "Rock_Slate"
    },
    {
      "x": -10,
      "y": 20,
      "z": 2,
      "name": "Rock_Slate"
    },
    {
      "x": -10,
      "y": 21,
      "z": 2,
      "name": "Rock_Slate"
    },
    {
      "x": -10,
      "y": 22,
      "z": 2,
      "name": "Rock_Slate"
    },
    {
      "x": -10,
      "y": 23,
      "z": 2,
      "name": "Rock_Slate"
    },
    {
      "x": -10,
      "y": 24,
      "z": 2,
      "name": "Soil_Ash"
    },
    {
      "x": -10,
      "y": 25,
      "z": 2,
      "name": "Soil_Ash"
    },
    {
      "x": -10,
      "y": 26,
      "z": 2,
      "name": "Soil_Ash"
    },
    {
      "x": -10,
      "y": 27,
      "z": 2,
      "name": "Soil_Ash"
    },
    {
      "x": -10,
      "y": 14,
      "z": 3,
      "name": "Rock_Slate"
    },
    {
      "x": -10,
      "y": 15,
      "z": 3,
      "name": "Rock_Slate"
    },
    {
      "x": -10,
      "y": 16,
      "z": 3,
      "name": "Rock_Slate"
    },
    {
      "x": -10,
      "y": 17,
      "z": 3,
      "name": "Rock_Slate"
    },
    {
      "x": -10,
      "y": 18,
      "z": 3,
      "name": "Rock_Slate"
    },
    {
      "x": -10,
      "y": 19,
      "z": 3,
      "name": "Rock_Slate"
    },
    {
      "x": -10,
      "y": 20,
      "z": 3,
      "name": "Rock_Slate"
    },
    {
      "x": -10,
      "y": 21,
      "z": 3,
      "name": "Rock_Slate"
    },
    {
      "x": -10,
      "y": 22,
      "z": 3,
      "name": "Rock_Slate"
    },
    {
      "x": -10,
      "y": 23,
      "z": 3,
      "name": "Soil_Slate_Gravel"
    },
    {
      "x": -10,
      "y": 24,
      "z": 3,
      "name": "Rock_Slate"
    },
    {
      "x": -10,
      "y": 25,
      "z": 3,
      "name": "Soil_Ash"
    },
    {
      "x": -10,
      "y": 26,
      "z": 3,
      "name": "Soil_Ash"
    },
    {
      "x": -10,
      "y": 13,
      "z": 4,
      "name": "Rock_Slate"
    },
    {
      "x": -10,
      "y": 14,
      "z": 4,
      "name": "Rock_Slate"
    },
    {
      "x": -10,
      "y": 15,
      "z": 4,
      "name": "Rock_Slate"
    },
    {
      "x": -10,
      "y": 16,
      "z": 4,
      "name": "Rock_Slate"
    },
    {
      "x": -10,
      "y": 17,
      "z": 4,
      "name": "Rock_Slate"
    },
    {
      "x": -10,
      "y": 18,
      "z": 4,
      "name": "Rock_Slate"
    },
    {
      "x": -10,
      "y": 19,
      "z": 4,
      "name": "Rock_Slate"
    },
    {
      "x": -10,
      "y": 20,
      "z": 4,
      "name": "Rock_Slate"
    },
    {
      "x": -10,
      "y": 21,
      "z": 4,
      "name": "Soil_Ash"
    },
    {
      "x": -10,
      "y": 22,
      "z": 4,
      "name": "Soil_Ash"
    },
    {
      "x": -10,
      "y": 23,
      "z": 4,
      "name": "Soil_Ash"
    },
    {
      "x": -10,
      "y": 24,
      "z": 4,
      "name": "Soil_Slate_Gravel"
    },
    {
      "x": -10,
      "y": 25,
      "z": 4,
      "name": "Soil_Ash"
    },
    {
      "x": -10,
      "y": 26,
      "z": 4,
      "name": "Soil_Ash"
    },
    {
      "x": -10,
      "y": 12,
      "z": 5,
      "name": "Rock_Slate"
    },
    {
      "x": -10,
      "y": 13,
      "z": 5,
      "name": "Rock_Slate"
    },
    {
      "x": -10,
      "y": 14,
      "z": 5,
      "name": "Rock_Slate"
    },
    {
      "x": -10,
      "y": 15,
      "z": 5,
      "name": "Rock_Slate"
    },
    {
      "x": -10,
      "y": 16,
      "z": 5,
      "name": "Rock_Slate"
    },
    {
      "x": -10,
      "y": 17,
      "z": 5,
      "name": "Rock_Slate"
    },
    {
      "x": -10,
      "y": 18,
      "z": 5,
      "name": "Rock_Slate"
    },
    {
      "x": -10,
      "y": 19,
      "z": 5,
      "name": "Rock_Slate"
    },
    {
      "x": -10,
      "y": 20,
      "z": 5,
      "name": "Rock_Slate"
    },
    {
      "x": -10,
      "y": 21,
      "z": 5,
      "name": "Soil_Ash"
    },
    {
      "x": -10,
      "y": 22,
      "z": 5,
      "name": "Soil_Slate_Gravel"
    },
    {
      "x": -10,
      "y": 23,
      "z": 5,
      "name": "Rock_Slate"
    },
    {
      "x": -10,
      "y": 24,
      "z": 5,
      "name": "Soil_Ash"
    },
    {
      "x": -10,
      "y": 25,
      "z": 5,
      "name": "Soil_Slate_Gravel"
    },
    {
      "x": -10,
      "y": 11,
      "z": 6,
      "name": "Plant_Crop_Mushroom_Block_Purple_Mycelium"
    },
    {
      "x": -10,
      "y": 12,
      "z": 6,
      "name": "Plant_Crop_Mushroom_Block_Purple_Mycelium"
    },
    {
      "x": -10,
      "y": 13,
      "z": 6,
      "name": "Rock_Slate"
    },
    {
      "x": -10,
      "y": 14,
      "z": 6,
      "name": "Rock_Slate"
    },
    {
      "x": -10,
      "y": 15,
      "z": 6,
      "name": "Rock_Slate"
    },
    {
      "x": -10,
      "y": 16,
      "z": 6,
      "name": "Rock_Slate"
    },
    {
      "x": -10,
      "y": 17,
      "z": 6,
      "name": "Rock_Slate"
    },
    {
      "x": -10,
      "y": 18,
      "z": 6,
      "name": "Rock_Slate"
    },
    {
      "x": -10,
      "y": 19,
      "z": 6,
      "name": "Rock_Slate"
    },
    {
      "x": -10,
      "y": 20,
      "z": 6,
      "name": "Rock_Slate"
    },
    {
      "x": -10,
      "y": 21,
      "z": 6,
      "name": "Rock_Slate"
    },
    {
      "x": -10,
      "y": 22,
      "z": 6,
      "name": "Rock_Slate"
    },
    {
      "x": -10,
      "y": 23,
      "z": 6,
      "name": "Soil_Ash"
    },
    {
      "x": -10,
      "y": 24,
      "z": 6,
      "name": "Soil_Ash"
    },
    {
      "x": -10,
      "y": 25,
      "z": 6,
      "name": "Soil_Ash"
    },
    {
      "x": -10,
      "y": 14,
      "z": 7,
      "name": "Rock_Slate"
    },
    {
      "x": -10,
      "y": 15,
      "z": 7,
      "name": "Rock_Slate"
    },
    {
      "x": -10,
      "y": 16,
      "z": 7,
      "name": "Rock_Slate"
    },
    {
      "x": -10,
      "y": 17,
      "z": 7,
      "name": "Rock_Slate"
    },
    {
      "x": -10,
      "y": 18,
      "z": 7,
      "name": "Rock_Slate"
    },
    {
      "x": -10,
      "y": 19,
      "z": 7,
      "name": "Rock_Slate"
    },
    {
      "x": -10,
      "y": 20,
      "z": 7,
      "name": "Soil_Ash"
    },
    {
      "x": -10,
      "y": 21,
      "z": 7,
      "name": "Soil_Ash"
    },
    {
      "x": -10,
      "y": 22,
      "z": 7,
      "name": "Rock_Slate"
    },
    {
      "x": -10,
      "y": 23,
      "z": 7,
      "name": "Soil_Slate_Gravel"
    },
    {
      "x": -10,
      "y": 24,
      "z": 7,
      "name": "Soil_Slate_Gravel"
    },
    {
      "x": -10,
      "y": 13,
      "z": 8,
      "name": "Plant_Bush_Dead_Hanging"
    },
    {
      "x": -10,
      "y": 14,
      "z": 8,
      "name": "Rock_Slate"
    },
    {
      "x": -10,
      "y": 15,
      "z": 8,
      "name": "Rock_Slate"
    },
    {
      "x": -10,
      "y": 16,
      "z": 8,
      "name": "Rock_Slate"
    },
    {
      "x": -10,
      "y": 17,
      "z": 8,
      "name": "Rock_Slate"
    },
    {
      "x": -10,
      "y": 18,
      "z": 8,
      "name": "Rock_Slate"
    },
    {
      "x": -10,
      "y": 19,
      "z": 8,
      "name": "Soil_Ash"
    },
    {
      "x": -10,
      "y": 20,
      "z": 8,
      "name": "Soil_Ash"
    },
    {
      "x": -10,
      "y": 21,
      "z": 8,
      "name": "Soil_Slate_Gravel"
    },
    {
      "x": -10,
      "y": 22,
      "z": 8,
      "name": "Soil_Slate_Gravel"
    },
    {
      "x": -10,
      "y": 23,
      "z": 8,
      "name": "Soil_Ash"
    },
    {
      "x": -10,
      "y": 15,
      "z": 9,
      "name": "Rock_Slate"
    },
    {
      "x": -10,
      "y": 16,
      "z": 9,
      "name": "Rock_Slate"
    },
    {
      "x": -10,
      "y": 17,
      "z": 9,
      "name": "Rock_Slate"
    },
    {
      "x": -10,
      "y": 18,
      "z": 9,
      "name": "Rock_Slate"
    },
    {
      "x": -10,
      "y": 19,
      "z": 9,
      "name": "Rock_Slate"
    },
    {
      "x": -10,
      "y": 20,
      "z": 9,
      "name": "Soil_Ash"
    },
    {
      "x": -10,
      "y": 21,
      "z": 9,
      "name": "Soil_Ash"
    },
    {
      "x": -10,
      "y": 22,
      "z": 9,
      "name": "Rock_Slate"
    },
    {
      "x": -10,
      "y": 16,
      "z": 10,
      "name": "Rock_Slate"
    },
    {
      "x": -10,
      "y": 18,
      "z": 10,
      "name": "Rock_Slate"
    },
    {
      "x": -10,
      "y": 19,
      "z": 10,
      "name": "Rock_Slate"
    },
    {
      "x": -10,
      "y": 20,
      "z": 10,
      "name": "Rock_Slate"
    },
    {
      "x": -10,
      "y": 21,
      "z": 10,
      "name": "Soil_Slate_Gravel"
    },
    {
      "x": -9,
      "y": 23,
      "z": -12,
      "name": "Rock_Slate"
    },
    {
      "x": -9,
      "y": 24,
      "z": -12,
      "name": "Rock_Slate"
    },
    {
      "x": -9,
      "y": 25,
      "z": -12,
      "name": "Rock_Slate"
    },
    {
      "x": -9,
      "y": 26,
      "z": -12,
      "name": "Rock_Slate"
    },
    {
      "x": -9,
      "y": 27,
      "z": -12,
      "name": "Rock_Slate"
    },
    {
      "x": -9,
      "y": 28,
      "z": -12,
      "name": "Rock_Slate"
    },
    {
      "x": -9,
      "y": 29,
      "z": -12,
      "name": "Rock_Slate"
    },
    {
      "x": -9,
      "y": 30,
      "z": -12,
      "name": "Rock_Slate"
    },
    {
      "x": -9,
      "y": 31,
      "z": -12,
      "name": "Rock_Slate"
    },
    {
      "x": -9,
      "y": 32,
      "z": -12,
      "name": "Soil_Ash"
    },
    {
      "x": -9,
      "y": 33,
      "z": -12,
      "name": "Soil_Ash"
    },
    {
      "x": -9,
      "y": 34,
      "z": -12,
      "name": "Soil_Slate_Gravel"
    },
    {
      "x": -9,
      "y": 21,
      "z": -11,
      "name": "Rock_Slate"
    },
    {
      "x": -9,
      "y": 22,
      "z": -11,
      "name": "Ore_Cobalt_Slate_Cracked"
    },
    {
      "x": -9,
      "y": 23,
      "z": -11,
      "name": "Rock_Slate"
    },
    {
      "x": -9,
      "y": 24,
      "z": -11,
      "name": "Rock_Slate"
    },
    {
      "x": -9,
      "y": 25,
      "z": -11,
      "name": "Ore_Cobalt_Slate_Cracked"
    },
    {
      "x": -9,
      "y": 26,
      "z": -11,
      "name": "Rock_Slate"
    },
    {
      "x": -9,
      "y": 27,
      "z": -11,
      "name": "Rock_Slate"
    },
    {
      "x": -9,
      "y": 28,
      "z": -11,
      "name": "Rock_Slate"
    },
    {
      "x": -9,
      "y": 29,
      "z": -11,
      "name": "Rock_Slate"
    },
    {
      "x": -9,
      "y": 30,
      "z": -11,
      "name": "Rock_Slate"
    },
    {
      "x": -9,
      "y": 31,
      "z": -11,
      "name": "Rock_Slate"
    },
    {
      "x": -9,
      "y": 32,
      "z": -11,
      "name": "Soil_Ash"
    },
    {
      "x": -9,
      "y": 33,
      "z": -11,
      "name": "Soil_Ash"
    },
    {
      "x": -9,
      "y": 34,
      "z": -11,
      "name": "Soil_Slate_Gravel"
    },
    {
      "x": -9,
      "y": 35,
      "z": -11,
      "name": "Soil_Ash"
    },
    {
      "x": -9,
      "y": 19,
      "z": -10,
      "name": "Plant_Bush_Dead_Hanging"
    },
    {
      "x": -9,
      "y": 20,
      "z": -10,
      "name": "Rock_Slate"
    },
    {
      "x": -9,
      "y": 21,
      "z": -10,
      "name": "Rock_Slate"
    },
    {
      "x": -9,
      "y": 22,
      "z": -10,
      "name": "Ore_Cobalt_Slate_Cracked"
    },
    {
      "x": -9,
      "y": 23,
      "z": -10,
      "name": "Rock_Slate"
    },
    {
      "x": -9,
      "y": 24,
      "z": -10,
      "name": "Rock_Slate"
    },
    {
      "x": -9,
      "y": 25,
      "z": -10,
      "name": "Rock_Slate"
    },
    {
      "x": -9,
      "y": 26,
      "z": -10,
      "name": "Rock_Slate"
    },
    {
      "x": -9,
      "y": 27,
      "z": -10,
      "name": "Rock_Slate"
    },
    {
      "x": -9,
      "y": 28,
      "z": -10,
      "name": "Rock_Slate"
    },
    {
      "x": -9,
      "y": 29,
      "z": -10,
      "name": "Rock_Slate"
    },
    {
      "x": -9,
      "y": 30,
      "z": -10,
      "name": "Rock_Slate"
    },
    {
      "x": -9,
      "y": 31,
      "z": -10,
      "name": "Rock_Slate"
    },
    {
      "x": -9,
      "y": 32,
      "z": -10,
      "name": "Soil_Slate_Gravel"
    },
    {
      "x": -9,
      "y": 33,
      "z": -10,
      "name": "Soil_Slate_Gravel"
    },
    {
      "x": -9,
      "y": 34,
      "z": -10,
      "name": "Soil_Ash"
    },
    {
      "x": -9,
      "y": 35,
      "z": -10,
      "name": "Soil_Ash"
    },
    {
      "x": -9,
      "y": 19,
      "z": -9,
      "name": "Rock_Slate"
    },
    {
      "x": -9,
      "y": 20,
      "z": -9,
      "name": "Rock_Slate"
    },
    {
      "x": -9,
      "y": 21,
      "z": -9,
      "name": "Rock_Slate"
    },
    {
      "x": -9,
      "y": 22,
      "z": -9,
      "name": "Rock_Slate"
    },
    {
      "x": -9,
      "y": 23,
      "z": -9,
      "name": "Rock_Slate"
    },
    {
      "x": -9,
      "y": 24,
      "z": -9,
      "name": "Rock_Slate"
    },
    {
      "x": -9,
      "y": 25,
      "z": -9,
      "name": "Rock_Slate"
    },
    {
      "x": -9,
      "y": 26,
      "z": -9,
      "name": "Rock_Slate"
    },
    {
      "x": -9,
      "y": 27,
      "z": -9,
      "name": "Rock_Slate"
    },
    {
      "x": -9,
      "y": 28,
      "z": -9,
      "name": "Rock_Slate"
    },
    {
      "x": -9,
      "y": 29,
      "z": -9,
      "name": "Rock_Slate"
    },
    {
      "x": -9,
      "y": 30,
      "z": -9,
      "name": "Rock_Slate"
    },
    {
      "x": -9,
      "y": 31,
      "z": -9,
      "name": "Soil_Ash"
    },
    {
      "x": -9,
      "y": 32,
      "z": -9,
      "name": "Soil_Ash"
    },
    {
      "x": -9,
      "y": 33,
      "z": -9,
      "name": "Soil_Ash"
    },
    {
      "x": -9,
      "y": 34,
      "z": -9,
      "name": "Soil_Ash"
    },
    {
      "x": -9,
      "y": 35,
      "z": -9,
      "name": "Soil_Ash"
    },
    {
      "x": -9,
      "y": 20,
      "z": -8,
      "name": "Rock_Slate"
    },
    {
      "x": -9,
      "y": 21,
      "z": -8,
      "name": "Ore_Cobalt_Slate_Cracked"
    },
    {
      "x": -9,
      "y": 22,
      "z": -8,
      "name": "Rock_Slate"
    },
    {
      "x": -9,
      "y": 23,
      "z": -8,
      "name": "Rock_Slate"
    },
    {
      "x": -9,
      "y": 24,
      "z": -8,
      "name": "Rock_Slate"
    },
    {
      "x": -9,
      "y": 25,
      "z": -8,
      "name": "Rock_Slate"
    },
    {
      "x": -9,
      "y": 26,
      "z": -8,
      "name": "Rock_Slate"
    },
    {
      "x": -9,
      "y": 27,
      "z": -8,
      "name": "Rock_Slate"
    },
    {
      "x": -9,
      "y": 28,
      "z": -8,
      "name": "Rock_Slate"
    },
    {
      "x": -9,
      "y": 29,
      "z": -8,
      "name": "Soil_Ash"
    },
    {
      "x": -9,
      "y": 30,
      "z": -8,
      "name": "Rock_Slate"
    },
    {
      "x": -9,
      "y": 31,
      "z": -8,
      "name": "Soil_Slate_Gravel"
    },
    {
      "x": -9,
      "y": 32,
      "z": -8,
      "name": "Soil_Ash"
    },
    {
      "x": -9,
      "y": 33,
      "z": -8,
      "name": "Rock_Slate"
    },
    {
      "x": -9,
      "y": 34,
      "z": -8,
      "name": "Soil_Ash"
    },
    {
      "x": -9,
      "y": 35,
      "z": -8,
      "name": "Soil_Ash"
    },
    {
      "x": -9,
      "y": 21,
      "z": -7,
      "name": "Rock_Slate"
    },
    {
      "x": -9,
      "y": 22,
      "z": -7,
      "name": "Rock_Slate"
    },
    {
      "x": -9,
      "y": 23,
      "z": -7,
      "name": "Rock_Slate"
    },
    {
      "x": -9,
      "y": 24,
      "z": -7,
      "name": "Rock_Slate"
    },
    {
      "x": -9,
      "y": 25,
      "z": -7,
      "name": "Rock_Slate"
    },
    {
      "x": -9,
      "y": 26,
      "z": -7,
      "name": "Rock_Slate"
    },
    {
      "x": -9,
      "y": 27,
      "z": -7,
      "name": "Rock_Slate"
    },
    {
      "x": -9,
      "y": 28,
      "z": -7,
      "name": "Rock_Slate"
    },
    {
      "x": -9,
      "y": 29,
      "z": -7,
      "name": "Soil_Ash"
    },
    {
      "x": -9,
      "y": 30,
      "z": -7,
      "name": "Rock_Slate"
    },
    {
      "x": -9,
      "y": 31,
      "z": -7,
      "name": "Soil_Slate_Gravel"
    },
    {
      "x": -9,
      "y": 32,
      "z": -7,
      "name": "Soil_Ash"
    },
    {
      "x": -9,
      "y": 33,
      "z": -7,
      "name": "Soil_Ash"
    },
    {
      "x": -9,
      "y": 34,
      "z": -7,
      "name": "Soil_Ash"
    },
    {
      "x": -9,
      "y": 21,
      "z": -6,
      "name": "Rock_Slate"
    },
    {
      "x": -9,
      "y": 22,
      "z": -6,
      "name": "Rock_Slate"
    },
    {
      "x": -9,
      "y": 23,
      "z": -6,
      "name": "Rock_Slate"
    },
    {
      "x": -9,
      "y": 24,
      "z": -6,
      "name": "Rock_Slate"
    },
    {
      "x": -9,
      "y": 25,
      "z": -6,
      "name": "Rock_Slate"
    },
    {
      "x": -9,
      "y": 26,
      "z": -6,
      "name": "Rock_Slate"
    },
    {
      "x": -9,
      "y": 27,
      "z": -6,
      "name": "Rock_Slate"
    },
    {
      "x": -9,
      "y": 28,
      "z": -6,
      "name": "Soil_Slate_Gravel"
    },
    {
      "x": -9,
      "y": 29,
      "z": -6,
      "name": "Soil_Ash"
    },
    {
      "x": -9,
      "y": 30,
      "z": -6,
      "name": "Soil_Ash"
    },
    {
      "x": -9,
      "y": 31,
      "z": -6,
      "name": "Soil_Ash"
    },
    {
      "x": -9,
      "y": 32,
      "z": -6,
      "name": "Soil_Ash"
    },
    {
      "x": -9,
      "y": 33,
      "z": -6,
      "name": "Soil_Ash"
    },
    {
      "x": -9,
      "y": 20,
      "z": -5,
      "name": "Ore_Cobalt_Slate_Cracked"
    },
    {
      "x": -9,
      "y": 21,
      "z": -5,
      "name": "Rock_Slate"
    },
    {
      "x": -9,
      "y": 22,
      "z": -5,
      "name": "Rock_Slate"
    },
    {
      "x": -9,
      "y": 23,
      "z": -5,
      "name": "Rock_Slate"
    },
    {
      "x": -9,
      "y": 24,
      "z": -5,
      "name": "Rock_Slate"
    },
    {
      "x": -9,
      "y": 25,
      "z": -5,
      "name": "Rock_Slate"
    },
    {
      "x": -9,
      "y": 26,
      "z": -5,
      "name": "Soil_Ash"
    },
    {
      "x": -9,
      "y": 27,
      "z": -5,
      "name": "Soil_Ash"
    },
    {
      "x": -9,
      "y": 28,
      "z": -5,
      "name": "Soil_Ash"
    },
    {
      "x": -9,
      "y": 29,
      "z": -5,
      "name": "Rock_Slate"
    },
    {
      "x": -9,
      "y": 30,
      "z": -5,
      "name": "Soil_Ash"
    },
    {
      "x": -9,
      "y": 31,
      "z": -5,
      "name": "Rock_Slate"
    },
    {
      "x": -9,
      "y": 32,
      "z": -5,
      "name": "Soil_Ash"
    },
    {
      "x": -9,
      "y": 19,
      "z": -4,
      "name": "Rock_Slate"
    },
    {
      "x": -9,
      "y": 20,
      "z": -4,
      "name": "Rock_Slate"
    },
    {
      "x": -9,
      "y": 21,
      "z": -4,
      "name": "Rock_Slate"
    },
    {
      "x": -9,
      "y": 22,
      "z": -4,
      "name": "Rock_Slate"
    },
    {
      "x": -9,
      "y": 23,
      "z": -4,
      "name": "Rock_Slate"
    },
    {
      "x": -9,
      "y": 24,
      "z": -4,
      "name": "Rock_Slate"
    },
    {
      "x": -9,
      "y": 25,
      "z": -4,
      "name": "Rock_Slate"
    },
    {
      "x": -9,
      "y": 26,
      "z": -4,
      "name": "Soil_Ash"
    },
    {
      "x": -9,
      "y": 27,
      "z": -4,
      "name": "Soil_Ash"
    },
    {
      "x": -9,
      "y": 28,
      "z": -4,
      "name": "Soil_Ash"
    },
    {
      "x": -9,
      "y": 29,
      "z": -4,
      "name": "Rock_Slate"
    },
    {
      "x": -9,
      "y": 30,
      "z": -4,
      "name": "Soil_Ash"
    },
    {
      "x": -9,
      "y": 31,
      "z": -4,
      "name": "Soil_Ash"
    },
    {
      "x": -9,
      "y": 32,
      "z": -4,
      "name": "Soil_Ash"
    },
    {
      "x": -9,
      "y": 17,
      "z": -3,
      "name": "Rock_Slate"
    },
    {
      "x": -9,
      "y": 18,
      "z": -3,
      "name": "Rock_Slate"
    },
    {
      "x": -9,
      "y": 19,
      "z": -3,
      "name": "Rock_Slate"
    },
    {
      "x": -9,
      "y": 20,
      "z": -3,
      "name": "Rock_Slate"
    },
    {
      "x": -9,
      "y": 21,
      "z": -3,
      "name": "Rock_Slate"
    },
    {
      "x": -9,
      "y": 22,
      "z": -3,
      "name": "Rock_Slate"
    },
    {
      "x": -9,
      "y": 23,
      "z": -3,
      "name": "Rock_Slate"
    },
    {
      "x": -9,
      "y": 24,
      "z": -3,
      "name": "Rock_Slate"
    },
    {
      "x": -9,
      "y": 25,
      "z": -3,
      "name": "Soil_Slate_Gravel"
    },
    {
      "x": -9,
      "y": 26,
      "z": -3,
      "name": "Soil_Ash"
    },
    {
      "x": -9,
      "y": 27,
      "z": -3,
      "name": "Rock_Slate"
    },
    {
      "x": -9,
      "y": 28,
      "z": -3,
      "name": "Rock_Slate"
    },
    {
      "x": -9,
      "y": 29,
      "z": -3,
      "name": "Soil_Ash"
    },
    {
      "x": -9,
      "y": 30,
      "z": -3,
      "name": "Rock_Slate"
    },
    {
      "x": -9,
      "y": 31,
      "z": -3,
      "name": "Rock_Slate"
    },
    {
      "x": -9,
      "y": 14,
      "z": -2,
      "name": "Plant_Crop_Mushroom_Block_Purple_Mycelium"
    },
    {
      "x": -9,
      "y": 15,
      "z": -2,
      "name": "Plant_Crop_Mushroom_Block_Purple_Mycelium"
    },
    {
      "x": -9,
      "y": 16,
      "z": -2,
      "name": "Ore_Cobalt_Slate_Cracked"
    },
    {
      "x": -9,
      "y": 17,
      "z": -2,
      "name": "Rock_Slate"
    },
    {
      "x": -9,
      "y": 18,
      "z": -2,
      "name": "Rock_Slate"
    },
    {
      "x": -9,
      "y": 19,
      "z": -2,
      "name": "Rock_Slate"
    },
    {
      "x": -9,
      "y": 20,
      "z": -2,
      "name": "Rock_Slate"
    },
    {
      "x": -9,
      "y": 21,
      "z": -2,
      "name": "Rock_Slate"
    },
    {
      "x": -9,
      "y": 22,
      "z": -2,
      "name": "Rock_Slate"
    },
    {
      "x": -9,
      "y": 23,
      "z": -2,
      "name": "Rock_Slate"
    },
    {
      "x": -9,
      "y": 24,
      "z": -2,
      "name": "Rock_Slate"
    },
    {
      "x": -9,
      "y": 25,
      "z": -2,
      "name": "Soil_Slate_Gravel"
    },
    {
      "x": -9,
      "y": 26,
      "z": -2,
      "name": "Soil_Ash"
    },
    {
      "x": -9,
      "y": 27,
      "z": -2,
      "name": "Rock_Slate"
    },
    {
      "x": -9,
      "y": 28,
      "z": -2,
      "name": "Soil_Slate_Gravel"
    },
    {
      "x": -9,
      "y": 29,
      "z": -2,
      "name": "Soil_Ash"
    },
    {
      "x": -9,
      "y": 30,
      "z": -2,
      "name": "Rock_Slate"
    },
    {
      "x": -9,
      "y": 16,
      "z": -1,
      "name": "Rock_Slate"
    },
    {
      "x": -9,
      "y": 17,
      "z": -1,
      "name": "Rock_Slate"
    },
    {
      "x": -9,
      "y": 18,
      "z": -1,
      "name": "Rock_Slate"
    },
    {
      "x": -9,
      "y": 19,
      "z": -1,
      "name": "Rock_Slate"
    },
    {
      "x": -9,
      "y": 20,
      "z": -1,
      "name": "Rock_Slate"
    },
    {
      "x": -9,
      "y": 21,
      "z": -1,
      "name": "Rock_Slate"
    },
    {
      "x": -9,
      "y": 22,
      "z": -1,
      "name": "Rock_Slate"
    },
    {
      "x": -9,
      "y": 23,
      "z": -1,
      "name": "Rock_Slate"
    },
    {
      "x": -9,
      "y": 24,
      "z": -1,
      "name": "Rock_Slate"
    },
    {
      "x": -9,
      "y": 25,
      "z": -1,
      "name": "Rock_Slate"
    },
    {
      "x": -9,
      "y": 26,
      "z": -1,
      "name": "Soil_Ash"
    },
    {
      "x": -9,
      "y": 27,
      "z": -1,
      "name": "Soil_Ash"
    },
    {
      "x": -9,
      "y": 28,
      "z": -1,
      "name": "Soil_Ash"
    },
    {
      "x": -9,
      "y": 29,
      "z": -1,
      "name": "Rock_Slate"
    },
    {
      "x": -9,
      "y": 15,
      "z": 0,
      "name": "Rock_Slate"
    },
    {
      "x": -9,
      "y": 16,
      "z": 0,
      "name": "Rock_Slate"
    },
    {
      "x": -9,
      "y": 17,
      "z": 0,
      "name": "Rock_Slate"
    },
    {
      "x": -9,
      "y": 18,
      "z": 0,
      "name": "Rock_Slate"
    },
    {
      "x": -9,
      "y": 19,
      "z": 0,
      "name": "Rock_Slate"
    },
    {
      "x": -9,
      "y": 20,
      "z": 0,
      "name": "Rock_Slate"
    },
    {
      "x": -9,
      "y": 21,
      "z": 0,
      "name": "Rock_Slate"
    },
    {
      "x": -9,
      "y": 22,
      "z": 0,
      "name": "Ore_Cobalt_Slate"
    },
    {
      "x": -9,
      "y": 23,
      "z": 0,
      "name": "Soil_Slate_Gravel"
    },
    {
      "x": -9,
      "y": 24,
      "z": 0,
      "name": "Soil_Ash"
    },
    {
      "x": -9,
      "y": 25,
      "z": 0,
      "name": "Soil_Ash"
    },
    {
      "x": -9,
      "y": 26,
      "z": 0,
      "name": "Soil_Ash"
    },
    {
      "x": -9,
      "y": 27,
      "z": 0,
      "name": "Soil_Ash"
    },
    {
      "x": -9,
      "y": 28,
      "z": 0,
      "name": "Soil_Ash"
    },
    {
      "x": -9,
      "y": 14,
      "z": 1,
      "name": "Rock_Slate"
    },
    {
      "x": -9,
      "y": 15,
      "z": 1,
      "name": "Ore_Cobalt_Slate_Cracked"
    },
    {
      "x": -9,
      "y": 16,
      "z": 1,
      "name": "Rock_Slate"
    },
    {
      "x": -9,
      "y": 17,
      "z": 1,
      "name": "Rock_Slate"
    },
    {
      "x": -9,
      "y": 18,
      "z": 1,
      "name": "Rock_Slate"
    },
    {
      "x": -9,
      "y": 19,
      "z": 1,
      "name": "Rock_Slate"
    },
    {
      "x": -9,
      "y": 20,
      "z": 1,
      "name": "Rock_Slate"
    },
    {
      "x": -9,
      "y": 21,
      "z": 1,
      "name": "Rock_Slate"
    },
    {
      "x": -9,
      "y": 22,
      "z": 1,
      "name": "Ore_Cobalt_Slate"
    },
    {
      "x": -9,
      "y": 23,
      "z": 1,
      "name": "Soil_Ash"
    },
    {
      "x": -9,
      "y": 24,
      "z": 1,
      "name": "Soil_Ash"
    },
    {
      "x": -9,
      "y": 25,
      "z": 1,
      "name": "Soil_Slate_Gravel"
    },
    {
      "x": -9,
      "y": 26,
      "z": 1,
      "name": "Soil_Slate_Gravel"
    },
    {
      "x": -9,
      "y": 27,
      "z": 1,
      "name": "Rock_Slate"
    },
    {
      "x": -9,
      "y": 28,
      "z": 1,
      "name": "Soil_Ash"
    },
    {
      "x": -9,
      "y": 13,
      "z": 2,
      "name": "Rock_Slate"
    },
    {
      "x": -9,
      "y": 14,
      "z": 2,
      "name": "Rock_Slate"
    },
    {
      "x": -9,
      "y": 15,
      "z": 2,
      "name": "Rock_Slate"
    },
    {
      "x": -9,
      "y": 16,
      "z": 2,
      "name": "Rock_Slate"
    },
    {
      "x": -9,
      "y": 17,
      "z": 2,
      "name": "Rock_Slate"
    },
    {
      "x": -9,
      "y": 18,
      "z": 2,
      "name": "Rock_Slate"
    },
    {
      "x": -9,
      "y": 19,
      "z": 2,
      "name": "Rock_Slate"
    },
    {
      "x": -9,
      "y": 20,
      "z": 2,
      "name": "Rock_Slate"
    },
    {
      "x": -9,
      "y": 21,
      "z": 2,
      "name": "Rock_Slate"
    },
    {
      "x": -9,
      "y": 22,
      "z": 2,
      "name": "Soil_Ash"
    },
    {
      "x": -9,
      "y": 23,
      "z": 2,
      "name": "Soil_Ash"
    },
    {
      "x": -9,
      "y": 24,
      "z": 2,
      "name": "Soil_Slate_Gravel"
    },
    {
      "x": -9,
      "y": 25,
      "z": 2,
      "name": "Soil_Slate_Gravel"
    },
    {
      "x": -9,
      "y": 26,
      "z": 2,
      "name": "Soil_Ash"
    },
    {
      "x": -9,
      "y": 27,
      "z": 2,
      "name": "Soil_Ash"
    },
    {
      "x": -9,
      "y": 13,
      "z": 3,
      "name": "Rock_Slate"
    },
    {
      "x": -9,
      "y": 14,
      "z": 3,
      "name": "Rock_Slate"
    },
    {
      "x": -9,
      "y": 15,
      "z": 3,
      "name": "Rock_Slate"
    },
    {
      "x": -9,
      "y": 16,
      "z": 3,
      "name": "Rock_Slate"
    },
    {
      "x": -9,
      "y": 17,
      "z": 3,
      "name": "Rock_Slate"
    },
    {
      "x": -9,
      "y": 18,
      "z": 3,
      "name": "Rock_Slate"
    },
    {
      "x": -9,
      "y": 19,
      "z": 3,
      "name": "Rock_Slate"
    },
    {
      "x": -9,
      "y": 20,
      "z": 3,
      "name": "Rock_Slate"
    },
    {
      "x": -9,
      "y": 21,
      "z": 3,
      "name": "Soil_Ash"
    },
    {
      "x": -9,
      "y": 22,
      "z": 3,
      "name": "Rock_Slate"
    },
    {
      "x": -9,
      "y": 23,
      "z": 3,
      "name": "Rock_Slate"
    },
    {
      "x": -9,
      "y": 24,
      "z": 3,
      "name": "Soil_Ash"
    },
    {
      "x": -9,
      "y": 25,
      "z": 3,
      "name": "Soil_Ash"
    },
    {
      "x": -9,
      "y": 26,
      "z": 3,
      "name": "Rock_Slate"
    },
    {
      "x": -9,
      "y": 12,
      "z": 4,
      "name": "Rock_Slate"
    },
    {
      "x": -9,
      "y": 13,
      "z": 4,
      "name": "Rock_Slate"
    },
    {
      "x": -9,
      "y": 14,
      "z": 4,
      "name": "Rock_Slate"
    },
    {
      "x": -9,
      "y": 15,
      "z": 4,
      "name": "Rock_Slate"
    },
    {
      "x": -9,
      "y": 16,
      "z": 4,
      "name": "Rock_Slate"
    },
    {
      "x": -9,
      "y": 17,
      "z": 4,
      "name": "Rock_Slate"
    },
    {
      "x": -9,
      "y": 18,
      "z": 4,
      "name": "Rock_Slate"
    },
    {
      "x": -9,
      "y": 19,
      "z": 4,
      "name": "Rock_Slate"
    },
    {
      "x": -9,
      "y": 20,
      "z": 4,
      "name": "Rock_Slate"
    },
    {
      "x": -9,
      "y": 21,
      "z": 4,
      "name": "Soil_Ash"
    },
    {
      "x": -9,
      "y": 22,
      "z": 4,
      "name": "Rock_Slate"
    },
    {
      "x": -9,
      "y": 23,
      "z": 4,
      "name": "Rock_Slate"
    },
    {
      "x": -9,
      "y": 24,
      "z": 4,
      "name": "Soil_Ash"
    },
    {
      "x": -9,
      "y": 25,
      "z": 4,
      "name": "Rock_Slate"
    },
    {
      "x": -9,
      "y": 26,
      "z": 4,
      "name": "Soil_Ash"
    },
    {
      "x": -9,
      "y": 12,
      "z": 5,
      "name": "Ore_Cobalt_Slate_Cracked"
    },
    {
      "x": -9,
      "y": 13,
      "z": 5,
      "name": "Rock_Slate"
    },
    {
      "x": -9,
      "y": 14,
      "z": 5,
      "name": "Rock_Slate"
    },
    {
      "x": -9,
      "y": 15,
      "z": 5,
      "name": "Rock_Slate"
    },
    {
      "x": -9,
      "y": 16,
      "z": 5,
      "name": "Rock_Slate"
    },
    {
      "x": -9,
      "y": 17,
      "z": 5,
      "name": "Rock_Slate"
    },
    {
      "x": -9,
      "y": 18,
      "z": 5,
      "name": "Rock_Slate"
    },
    {
      "x": -9,
      "y": 19,
      "z": 5,
      "name": "Rock_Slate"
    },
    {
      "x": -9,
      "y": 20,
      "z": 5,
      "name": "Rock_Slate"
    },
    {
      "x": -9,
      "y": 21,
      "z": 5,
      "name": "Rock_Slate"
    },
    {
      "x": -9,
      "y": 22,
      "z": 5,
      "name": "Soil_Ash"
    },
    {
      "x": -9,
      "y": 23,
      "z": 5,
      "name": "Soil_Slate_Gravel"
    },
    {
      "x": -9,
      "y": 24,
      "z": 5,
      "name": "Soil_Ash"
    },
    {
      "x": -9,
      "y": 25,
      "z": 5,
      "name": "Soil_Ash"
    },
    {
      "x": -9,
      "y": 12,
      "z": 6,
      "name": "Rock_Slate"
    },
    {
      "x": -9,
      "y": 13,
      "z": 6,
      "name": "Rock_Slate"
    },
    {
      "x": -9,
      "y": 14,
      "z": 6,
      "name": "Rock_Slate"
    },
    {
      "x": -9,
      "y": 15,
      "z": 6,
      "name": "Rock_Slate"
    },
    {
      "x": -9,
      "y": 16,
      "z": 6,
      "name": "Rock_Slate"
    },
    {
      "x": -9,
      "y": 17,
      "z": 6,
      "name": "Rock_Slate"
    },
    {
      "x": -9,
      "y": 18,
      "z": 6,
      "name": "Rock_Slate"
    },
    {
      "x": -9,
      "y": 19,
      "z": 6,
      "name": "Rock_Slate"
    },
    {
      "x": -9,
      "y": 20,
      "z": 6,
      "name": "Soil_Ash"
    },
    {
      "x": -9,
      "y": 21,
      "z": 6,
      "name": "Soil_Ash"
    },
    {
      "x": -9,
      "y": 22,
      "z": 6,
      "name": "Soil_Ash"
    },
    {
      "x": -9,
      "y": 23,
      "z": 6,
      "name": "Soil_Ash"
    },
    {
      "x": -9,
      "y": 24,
      "z": 6,
      "name": "Soil_Slate_Gravel"
    },
    {
      "x": -9,
      "y": 25,
      "z": 6,
      "name": "Soil_Ash"
    },
    {
      "x": -9,
      "y": 13,
      "z": 7,
      "name": "Rock_Slate"
    },
    {
      "x": -9,
      "y": 14,
      "z": 7,
      "name": "Rock_Slate"
    },
    {
      "x": -9,
      "y": 15,
      "z": 7,
      "name": "Rock_Slate"
    },
    {
      "x": -9,
      "y": 16,
      "z": 7,
      "name": "Rock_Slate"
    },
    {
      "x": -9,
      "y": 17,
      "z": 7,
      "name": "Rock_Slate"
    },
    {
      "x": -9,
      "y": 18,
      "z": 7,
      "name": "Rock_Slate"
    },
    {
      "x": -9,
      "y": 19,
      "z": 7,
      "name": "Soil_Ash"
    },
    {
      "x": -9,
      "y": 20,
      "z": 7,
      "name": "Rock_Slate"
    },
    {
      "x": -9,
      "y": 21,
      "z": 7,
      "name": "Soil_Slate_Gravel"
    },
    {
      "x": -9,
      "y": 22,
      "z": 7,
      "name": "Soil_Ash"
    },
    {
      "x": -9,
      "y": 23,
      "z": 7,
      "name": "Soil_Ash"
    },
    {
      "x": -9,
      "y": 24,
      "z": 7,
      "name": "Soil_Ash"
    },
    {
      "x": -9,
      "y": 12,
      "z": 8,
      "name": "Ore_Cobalt_Slate_Cracked"
    },
    {
      "x": -9,
      "y": 13,
      "z": 8,
      "name": "Rock_Slate"
    },
    {
      "x": -9,
      "y": 14,
      "z": 8,
      "name": "Ore_Cobalt_Slate_Cracked"
    },
    {
      "x": -9,
      "y": 15,
      "z": 8,
      "name": "Rock_Slate"
    },
    {
      "x": -9,
      "y": 16,
      "z": 8,
      "name": "Rock_Slate"
    },
    {
      "x": -9,
      "y": 17,
      "z": 8,
      "name": "Rock_Slate"
    },
    {
      "x": -9,
      "y": 18,
      "z": 8,
      "name": "Rock_Slate"
    },
    {
      "x": -9,
      "y": 19,
      "z": 8,
      "name": "Rock_Slate"
    },
    {
      "x": -9,
      "y": 20,
      "z": 8,
      "name": "Soil_Ash"
    },
    {
      "x": -9,
      "y": 21,
      "z": 8,
      "name": "Soil_Ash"
    },
    {
      "x": -9,
      "y": 22,
      "z": 8,
      "name": "Soil_Slate_Gravel"
    },
    {
      "x": -9,
      "y": 23,
      "z": 8,
      "name": "Soil_Slate_Gravel"
    },
    {
      "x": -9,
      "y": 11,
      "z": 9,
      "name": "Plant_Crop_Mushroom_Block_Purple_Mycelium"
    },
    {
      "x": -9,
      "y": 12,
      "z": 9,
      "name": "Plant_Bush_Dead_Hanging"
    },
    {
      "x": -9,
      "y": 13,
      "z": 9,
      "name": "Rock_Slate"
    },
    {
      "x": -9,
      "y": 14,
      "z": 9,
      "name": "Rock_Slate"
    },
    {
      "x": -9,
      "y": 15,
      "z": 9,
      "name": "Rock_Slate"
    },
    {
      "x": -9,
      "y": 16,
      "z": 9,
      "name": "Rock_Slate"
    },
    {
      "x": -9,
      "y": 17,
      "z": 9,
      "name": "Rock_Slate"
    },
    {
      "x": -9,
      "y": 18,
      "z": 9,
      "name": "Rock_Slate"
    },
    {
      "x": -9,
      "y": 19,
      "z": 9,
      "name": "Soil_Ash"
    },
    {
      "x": -9,
      "y": 20,
      "z": 9,
      "name": "Soil_Ash"
    },
    {
      "x": -9,
      "y": 21,
      "z": 9,
      "name": "Rock_Slate"
    },
    {
      "x": -9,
      "y": 22,
      "z": 9,
      "name": "Rock_Slate"
    },
    {
      "x": -9,
      "y": 23,
      "z": 9,
      "name": "Soil_Ash"
    },
    {
      "x": -9,
      "y": 14,
      "z": 10,
      "name": "Ore_Cobalt_Slate_Cracked"
    },
    {
      "x": -9,
      "y": 15,
      "z": 10,
      "name": "Rock_Slate"
    },
    {
      "x": -9,
      "y": 16,
      "z": 10,
      "name": "Rock_Slate"
    },
    {
      "x": -9,
      "y": 17,
      "z": 10,
      "name": "Rock_Slate"
    },
    {
      "x": -9,
      "y": 18,
      "z": 10,
      "name": "Rock_Slate"
    },
    {
      "x": -9,
      "y": 19,
      "z": 10,
      "name": "Soil_Slate_Gravel"
    },
    {
      "x": -9,
      "y": 20,
      "z": 10,
      "name": "Soil_Ash"
    },
    {
      "x": -9,
      "y": 21,
      "z": 10,
      "name": "Soil_Slate_Gravel"
    },
    {
      "x": -9,
      "y": 22,
      "z": 10,
      "name": "Rock_Slate"
    },
    {
      "x": -9,
      "y": 17,
      "z": 11,
      "name": "Rock_Slate"
    },
    {
      "x": -9,
      "y": 18,
      "z": 11,
      "name": "Rock_Slate"
    },
    {
      "x": -9,
      "y": 19,
      "z": 11,
      "name": "Soil_Ash"
    },
    {
      "x": -9,
      "y": 20,
      "z": 11,
      "name": "Soil_Ash"
    },
    {
      "x": -8,
      "y": 26,
      "z": -13,
      "name": "Ore_Cobalt_Slate_Cracked"
    },
    {
      "x": -8,
      "y": 27,
      "z": -13,
      "name": "Rock_Slate"
    },
    {
      "x": -8,
      "y": 28,
      "z": -13,
      "name": "Rock_Slate"
    },
    {
      "x": -8,
      "y": 29,
      "z": -13,
      "name": "Rock_Slate"
    },
    {
      "x": -8,
      "y": 30,
      "z": -13,
      "name": "Rock_Slate"
    },
    {
      "x": -8,
      "y": 31,
      "z": -13,
      "name": "Soil_Slate_Gravel"
    },
    {
      "x": -8,
      "y": 32,
      "z": -13,
      "name": "Rock_Slate"
    },
    {
      "x": -8,
      "y": 22,
      "z": -12,
      "name": "Rock_Slate"
    },
    {
      "x": -8,
      "y": 23,
      "z": -12,
      "name": "Rock_Slate"
    },
    {
      "x": -8,
      "y": 24,
      "z": -12,
      "name": "Rock_Slate"
    },
    {
      "x": -8,
      "y": 25,
      "z": -12,
      "name": "Rock_Slate"
    },
    {
      "x": -8,
      "y": 26,
      "z": -12,
      "name": "Rock_Slate"
    },
    {
      "x": -8,
      "y": 27,
      "z": -12,
      "name": "Rock_Slate"
    },
    {
      "x": -8,
      "y": 28,
      "z": -12,
      "name": "Rock_Slate"
    },
    {
      "x": -8,
      "y": 29,
      "z": -12,
      "name": "Rock_Slate"
    },
    {
      "x": -8,
      "y": 30,
      "z": -12,
      "name": "Rock_Slate"
    },
    {
      "x": -8,
      "y": 31,
      "z": -12,
      "name": "Soil_Ash"
    },
    {
      "x": -8,
      "y": 32,
      "z": -12,
      "name": "Soil_Slate_Gravel"
    },
    {
      "x": -8,
      "y": 33,
      "z": -12,
      "name": "Soil_Ash"
    },
    {
      "x": -8,
      "y": 34,
      "z": -12,
      "name": "Soil_Slate_Gravel"
    },
    {
      "x": -8,
      "y": 20,
      "z": -11,
      "name": "Rock_Slate"
    },
    {
      "x": -8,
      "y": 21,
      "z": -11,
      "name": "Rock_Slate"
    },
    {
      "x": -8,
      "y": 22,
      "z": -11,
      "name": "Rock_Slate"
    },
    {
      "x": -8,
      "y": 23,
      "z": -11,
      "name": "Rock_Slate"
    },
    {
      "x": -8,
      "y": 24,
      "z": -11,
      "name": "Rock_Slate"
    },
    {
      "x": -8,
      "y": 25,
      "z": -11,
      "name": "Rock_Slate"
    },
    {
      "x": -8,
      "y": 26,
      "z": -11,
      "name": "Rock_Slate"
    },
    {
      "x": -8,
      "y": 27,
      "z": -11,
      "name": "Rock_Slate"
    },
    {
      "x": -8,
      "y": 28,
      "z": -11,
      "name": "Rock_Slate"
    },
    {
      "x": -8,
      "y": 29,
      "z": -11,
      "name": "Rock_Slate"
    },
    {
      "x": -8,
      "y": 30,
      "z": -11,
      "name": "Rock_Slate"
    },
    {
      "x": -8,
      "y": 31,
      "z": -11,
      "name": "Rock_Slate"
    },
    {
      "x": -8,
      "y": 32,
      "z": -11,
      "name": "Rock_Slate"
    },
    {
      "x": -8,
      "y": 33,
      "z": -11,
      "name": "Soil_Slate_Gravel"
    },
    {
      "x": -8,
      "y": 34,
      "z": -11,
      "name": "Rock_Slate"
    },
    {
      "x": -8,
      "y": 35,
      "z": -11,
      "name": "Soil_Ash"
    },
    {
      "x": -8,
      "y": 19,
      "z": -10,
      "name": "Rock_Slate"
    },
    {
      "x": -8,
      "y": 20,
      "z": -10,
      "name": "Rock_Slate"
    },
    {
      "x": -8,
      "y": 21,
      "z": -10,
      "name": "Rock_Slate"
    },
    {
      "x": -8,
      "y": 22,
      "z": -10,
      "name": "Ore_Cobalt_Slate_Cracked"
    },
    {
      "x": -8,
      "y": 23,
      "z": -10,
      "name": "Rock_Slate"
    },
    {
      "x": -8,
      "y": 24,
      "z": -10,
      "name": "Ore_Cobalt_Slate_Cracked"
    },
    {
      "x": -8,
      "y": 25,
      "z": -10,
      "name": "Rock_Slate"
    },
    {
      "x": -8,
      "y": 26,
      "z": -10,
      "name": "Rock_Slate"
    },
    {
      "x": -8,
      "y": 27,
      "z": -10,
      "name": "Rock_Slate"
    },
    {
      "x": -8,
      "y": 28,
      "z": -10,
      "name": "Rock_Slate"
    },
    {
      "x": -8,
      "y": 29,
      "z": -10,
      "name": "Rock_Slate"
    },
    {
      "x": -8,
      "y": 30,
      "z": -10,
      "name": "Rock_Slate"
    },
    {
      "x": -8,
      "y": 31,
      "z": -10,
      "name": "Soil_Ash"
    },
    {
      "x": -8,
      "y": 32,
      "z": -10,
      "name": "Soil_Ash"
    },
    {
      "x": -8,
      "y": 33,
      "z": -10,
      "name": "Soil_Slate_Gravel"
    },
    {
      "x": -8,
      "y": 34,
      "z": -10,
      "name": "Rock_Slate"
    },
    {
      "x": -8,
      "y": 35,
      "z": -10,
      "name": "Rock_Slate"
    },
    {
      "x": -8,
      "y": 18,
      "z": -9,
      "name": "Rock_Slate"
    },
    {
      "x": -8,
      "y": 19,
      "z": -9,
      "name": "Rock_Slate"
    },
    {
      "x": -8,
      "y": 20,
      "z": -9,
      "name": "Rock_Slate"
    },
    {
      "x": -8,
      "y": 21,
      "z": -9,
      "name": "Rock_Slate"
    },
    {
      "x": -8,
      "y": 22,
      "z": -9,
      "name": "Rock_Slate"
    },
    {
      "x": -8,
      "y": 23,
      "z": -9,
      "name": "Rock_Slate"
    },
    {
      "x": -8,
      "y": 24,
      "z": -9,
      "name": "Rock_Slate"
    },
    {
      "x": -8,
      "y": 25,
      "z": -9,
      "name": "Rock_Slate"
    },
    {
      "x": -8,
      "y": 26,
      "z": -9,
      "name": "Rock_Slate"
    },
    {
      "x": -8,
      "y": 27,
      "z": -9,
      "name": "Rock_Slate"
    },
    {
      "x": -8,
      "y": 28,
      "z": -9,
      "name": "Rock_Slate"
    },
    {
      "x": -8,
      "y": 29,
      "z": -9,
      "name": "Rock_Slate"
    },
    {
      "x": -8,
      "y": 30,
      "z": -9,
      "name": "Soil_Ash"
    },
    {
      "x": -8,
      "y": 31,
      "z": -9,
      "name": "Rock_Slate"
    },
    {
      "x": -8,
      "y": 32,
      "z": -9,
      "name": "Soil_Ash"
    },
    {
      "x": -8,
      "y": 33,
      "z": -9,
      "name": "Soil_Ash"
    },
    {
      "x": -8,
      "y": 34,
      "z": -9,
      "name": "Soil_Ash"
    },
    {
      "x": -8,
      "y": 35,
      "z": -9,
      "name": "Soil_Ash"
    },
    {
      "x": -8,
      "y": 19,
      "z": -8,
      "name": "Rock_Slate"
    },
    {
      "x": -8,
      "y": 20,
      "z": -8,
      "name": "Rock_Slate"
    },
    {
      "x": -8,
      "y": 21,
      "z": -8,
      "name": "Ore_Cobalt_Slate_Cracked"
    },
    {
      "x": -8,
      "y": 22,
      "z": -8,
      "name": "Rock_Slate"
    },
    {
      "x": -8,
      "y": 23,
      "z": -8,
      "name": "Rock_Slate"
    },
    {
      "x": -8,
      "y": 24,
      "z": -8,
      "name": "Rock_Slate"
    },
    {
      "x": -8,
      "y": 25,
      "z": -8,
      "name": "Rock_Slate"
    },
    {
      "x": -8,
      "y": 26,
      "z": -8,
      "name": "Rock_Slate"
    },
    {
      "x": -8,
      "y": 27,
      "z": -8,
      "name": "Rock_Slate"
    },
    {
      "x": -8,
      "y": 28,
      "z": -8,
      "name": "Rock_Slate"
    },
    {
      "x": -8,
      "y": 29,
      "z": -8,
      "name": "Soil_Ash"
    },
    {
      "x": -8,
      "y": 30,
      "z": -8,
      "name": "Soil_Ash"
    },
    {
      "x": -8,
      "y": 31,
      "z": -8,
      "name": "Soil_Ash"
    },
    {
      "x": -8,
      "y": 32,
      "z": -8,
      "name": "Rock_Slate"
    },
    {
      "x": -8,
      "y": 33,
      "z": -8,
      "name": "Soil_Ash"
    },
    {
      "x": -8,
      "y": 34,
      "z": -8,
      "name": "Rock_Slate"
    },
    {
      "x": -8,
      "y": 35,
      "z": -8,
      "name": "Soil_Ash"
    },
    {
      "x": -8,
      "y": 20,
      "z": -7,
      "name": "Rock_Slate"
    },
    {
      "x": -8,
      "y": 21,
      "z": -7,
      "name": "Ore_Cobalt_Slate_Cracked"
    },
    {
      "x": -8,
      "y": 22,
      "z": -7,
      "name": "Rock_Slate"
    },
    {
      "x": -8,
      "y": 23,
      "z": -7,
      "name": "Rock_Slate"
    },
    {
      "x": -8,
      "y": 24,
      "z": -7,
      "name": "Rock_Slate"
    },
    {
      "x": -8,
      "y": 25,
      "z": -7,
      "name": "Rock_Slate"
    },
    {
      "x": -8,
      "y": 26,
      "z": -7,
      "name": "Rock_Slate"
    },
    {
      "x": -8,
      "y": 27,
      "z": -7,
      "name": "Rock_Slate"
    },
    {
      "x": -8,
      "y": 28,
      "z": -7,
      "name": "Soil_Ash"
    },
    {
      "x": -8,
      "y": 29,
      "z": -7,
      "name": "Rock_Slate"
    },
    {
      "x": -8,
      "y": 30,
      "z": -7,
      "name": "Soil_Ash"
    },
    {
      "x": -8,
      "y": 31,
      "z": -7,
      "name": "Soil_Ash"
    },
    {
      "x": -8,
      "y": 32,
      "z": -7,
      "name": "Soil_Slate_Gravel"
    },
    {
      "x": -8,
      "y": 33,
      "z": -7,
      "name": "Soil_Ash"
    },
    {
      "x": -8,
      "y": 34,
      "z": -7,
      "name": "Soil_Ash"
    },
    {
      "x": -8,
      "y": 20,
      "z": -6,
      "name": "Rock_Slate"
    },
    {
      "x": -8,
      "y": 21,
      "z": -6,
      "name": "Rock_Slate"
    },
    {
      "x": -8,
      "y": 22,
      "z": -6,
      "name": "Rock_Slate"
    },
    {
      "x": -8,
      "y": 23,
      "z": -6,
      "name": "Rock_Slate"
    },
    {
      "x": -8,
      "y": 24,
      "z": -6,
      "name": "Rock_Slate"
    },
    {
      "x": -8,
      "y": 25,
      "z": -6,
      "name": "Rock_Slate"
    },
    {
      "x": -8,
      "y": 26,
      "z": -6,
      "name": "Rock_Slate"
    },
    {
      "x": -8,
      "y": 27,
      "z": -6,
      "name": "Rock_Slate"
    },
    {
      "x": -8,
      "y": 28,
      "z": -6,
      "name": "Rock_Slate"
    },
    {
      "x": -8,
      "y": 29,
      "z": -6,
      "name": "Rock_Slate"
    },
    {
      "x": -8,
      "y": 30,
      "z": -6,
      "name": "Soil_Ash"
    },
    {
      "x": -8,
      "y": 31,
      "z": -6,
      "name": "Soil_Ash"
    },
    {
      "x": -8,
      "y": 32,
      "z": -6,
      "name": "Soil_Ash"
    },
    {
      "x": -8,
      "y": 33,
      "z": -6,
      "name": "Rock_Slate"
    },
    {
      "x": -8,
      "y": 34,
      "z": -6,
      "name": "Soil_Ash"
    },
    {
      "x": -8,
      "y": 20,
      "z": -5,
      "name": "Rock_Slate"
    },
    {
      "x": -8,
      "y": 21,
      "z": -5,
      "name": "Rock_Slate"
    },
    {
      "x": -8,
      "y": 22,
      "z": -5,
      "name": "Rock_Slate"
    },
    {
      "x": -8,
      "y": 23,
      "z": -5,
      "name": "Rock_Slate"
    },
    {
      "x": -8,
      "y": 24,
      "z": -5,
