{
  "version": 8,
  "blockIdVersion": 11,
  "anchorX": 0,
  "anchorY": 0,
  "anchorZ": 0,
  "blocks": [
    {
      "x": -17,
      "y": 27,
      "z": -8,
      "name": "Ore_Cobalt_Slate_Cracked"
    },
    {
      "x": -16,
      "y": 23,
      "z": -10,
      "name": "Rock_Slate"
    },
    {
      "x": -16,
      "y": 24,
      "z": -10,
      "name": "Rock_Slate"
    },
    {
      "x": -16,
      "y": 25,
      "z": -10,
      "name": "Rock_Slate"
    },
    {
      "x": -16,
      "y": 26,
      "z": -10,
      "name": "Rock_Slate"
    },
    {
      "x": -16,
      "y": 27,
      "z": -10,
      "name": "Rock_Slate"
    },
    {
      "x": -16,
      "y": 22,
      "z": -9,
      "name": "Rock_Slate"
    },
    {
      "x": -16,
      "y": 23,
      "z": -9,
      "name": "Rock_Slate"
    },
    {
      "x": -16,
      "y": 24,
      "z": -9,
      "name": "Rock_Slate"
    },
    {
      "x": -16,
      "y": 25,
      "z": -9,
      "name": "Rock_Slate"
    },
    {
      "x": -16,
      "y": 26,
      "z": -9,
      "name": "Rock_Slate"
    },
    {
      "x": -16,
      "y": 27,
      "z": -9,
      "name": "Rock_Slate"
    },
    {
      "x": -16,
      "y": 28,
      "z": -9,
      "name": "Rock_Slate"
    },
    {
      "x": -16,
      "y": 22,
      "z": -8,
      "name": "Rock_Slate"
    },
    {
      "x": -16,
      "y": 23,
      "z": -8,
      "name": "Rock_Slate"
    },
    {
      "x": -16,
      "y": 24,
      "z": -8,
      "name": "Rock_Slate"
    },
    {
      "x": -16,
      "y": 25,
      "z": -8,
      "name": "Rock_Slate"
    },
    {
      "x": -16,
      "y": 26,
      "z": -8,
      "name": "Rock_Slate"
    },
    {
      "x": -16,
      "y": 27,
      "z": -8,
      "name": "Rock_Slate"
    },
    {
      "x": -16,
      "y": 28,
      "z": -8,
      "name": "Rock_Slate"
    },
    {
      "x": -16,
      "y": 23,
      "z": -7,
      "name": "Ore_Cobalt_Slate_Cracked"
    },
    {
      "x": -16,
      "y": 24,
      "z": -7,
      "name": "Rock_Slate"
    },
    {
      "x": -16,
      "y": 25,
      "z": -7,
      "name": "Rock_Slate"
    },
    {
      "x": -16,
      "y": 26,
      "z": -7,
      "name": "Rock_Slate"
    },
    {
      "x": -16,
      "y": 27,
      "z": -7,
      "name": "Rock_Slate"
    },
    {
      "x": -15,
      "y": 21,
      "z": -11,
      "name": "Plant_Crop_Mushroom_Block_Purple_Mycelium"
    },
    {
      "x": -15,
      "y": 22,
      "z": -11,
      "name": "Rock_Slate"
    },
    {
      "x": -15,
      "y": 23,
      "z": -11,
      "name": "Rock_Slate"
    },
    {
      "x": -15,
      "y": 24,
      "z": -11,
      "name": "Rock_Slate"
    },
    {
      "x": -15,
      "y": 25,
      "z": -11,
      "name": "Rock_Slate"
    },
    {
      "x": -15,
      "y": 26,
      "z": -11,
      "name": "Rock_Slate"
    },
    {
      "x": -15,
      "y": 27,
      "z": -11,
      "name": "Rock_Slate"
    },
    {
      "x": -15,
      "y": 19,
      "z": -10,
      "name": "Rock_Slate"
    },
    {
      "x": -15,
      "y": 20,
      "z": -10,
      "name": "Rock_Slate"
    },
    {
      "x": -15,
      "y": 21,
      "z": -10,
      "name": "Rock_Slate"
    },
    {
      "x": -15,
      "y": 22,
      "z": -10,
      "name": "Rock_Slate"
    },
    {
      "x": -15,
      "y": 23,
      "z": -10,
      "name": "Rock_Slate"
    },
    {
      "x": -15,
      "y": 24,
      "z": -10,
      "name": "Rock_Slate"
    },
    {
      "x": -15,
      "y": 25,
      "z": -10,
      "name": "Rock_Slate"
    },
    {
      "x": -15,
      "y": 26,
      "z": -10,
      "name": "Rock_Slate"
    },
    {
      "x": -15,
      "y": 27,
      "z": -10,
      "name": "Rock_Slate"
    },
    {
      "x": -15,
      "y": 28,
      "z": -10,
      "name": "Rock_Slate"
    },
    {
      "x": -15,
      "y": 17,
      "z": -9,
      "name": "Plant_Crop_Mushroom_Block_Purple_Mycelium"
    },
    {
      "x": -15,
      "y": 18,
      "z": -9,
      "name": "Rock_Slate"
    },
    {
      "x": -15,
      "y": 19,
      "z": -9,
      "name": "Rock_Slate"
    },
    {
      "x": -15,
      "y": 20,
      "z": -9,
      "name": "Rock_Slate"
    },
    {
      "x": -15,
      "y": 21,
      "z": -9,
      "name": "Rock_Slate"
    },
    {
      "x": -15,
      "y": 22,
      "z": -9,
      "name": "Rock_Slate"
    },
    {
      "x": -15,
      "y": 23,
      "z": -9,
      "name": "Rock_Slate"
    },
    {
      "x": -15,
      "y": 24,
      "z": -9,
      "name": "Rock_Slate"
    },
    {
      "x": -15,
      "y": 25,
      "z": -9,
      "name": "Rock_Slate"
    },
    {
      "x": -15,
      "y": 26,
      "z": -9,
      "name": "Rock_Slate"
    },
    {
      "x": -15,
      "y": 27,
      "z": -9,
      "name": "Soil_Ash"
    },
    {
      "x": -15,
      "y": 28,
      "z": -9,
      "name": "Rock_Slate"
    },
    {
      "x": -15,
      "y": 29,
      "z": -9,
      "name": "Soil_Slate_Gravel"
    },
    {
      "x": -15,
      "y": 19,
      "z": -8,
      "name": "Rock_Slate"
    },
    {
      "x": -15,
      "y": 20,
      "z": -8,
      "name": "Rock_Slate"
    },
    {
      "x": -15,
      "y": 21,
      "z": -8,
      "name": "Rock_Slate"
    },
    {
      "x": -15,
      "y": 22,
      "z": -8,
      "name": "Rock_Slate"
    },
    {
      "x": -15,
      "y": 23,
      "z": -8,
      "name": "Rock_Slate"
    },
    {
      "x": -15,
      "y": 24,
      "z": -8,
      "name": "Rock_Slate"
    },
    {
      "x": -15,
      "y": 25,
      "z": -8,
      "name": "Rock_Slate"
    },
    {
      "x": -15,
      "y": 26,
      "z": -8,
      "name": "Rock_Slate"
    },
    {
      "x": -15,
      "y": 27,
      "z": -8,
      "name": "Soil_Ash"
    },
    {
      "x": -15,
      "y": 28,
      "z": -8,
      "name": "Rock_Slate"
    },
    {
      "x": -15,
      "y": 29,
      "z": -8,
      "name": "Rock_Slate"
    },
    {
      "x": -15,
      "y": 18,
      "z": -7,
      "name": "Rock_Slate"
    },
    {
      "x": -15,
      "y": 19,
      "z": -7,
      "name": "Rock_Slate"
    },
    {
      "x": -15,
      "y": 20,
      "z": -7,
      "name": "Rock_Slate"
    },
    {
      "x": -15,
      "y": 21,
      "z": -7,
      "name": "Rock_Slate"
    },
    {
      "x": -15,
      "y": 22,
      "z": -7,
      "name": "Rock_Slate"
    },
    {
      "x": -15,
      "y": 23,
      "z": -7,
      "name": "Rock_Slate"
    },
    {
      "x": -15,
      "y": 24,
      "z": -7,
      "name": "Rock_Slate"
    },
    {
      "x": -15,
      "y": 25,
      "z": -7,
      "name": "Rock_Slate"
    },
    {
      "x": -15,
      "y": 26,
      "z": -7,
      "name": "Soil_Ash"
    },
    {
      "x": -15,
      "y": 27,
      "z": -7,
      "name": "Rock_Slate"
    },
    {
      "x": -15,
      "y": 28,
      "z": -7,
      "name": "Soil_Ash"
    },
    {
      "x": -15,
      "y": 22,
      "z": -6,
      "name": "Ore_Cobalt_Slate_Cracked"
    },
    {
      "x": -15,
      "y": 23,
      "z": -6,
      "name": "Rock_Slate"
    },
    {
      "x": -15,
      "y": 24,
      "z": -6,
      "name": "Rock_Slate"
    },
    {
      "x": -15,
      "y": 25,
      "z": -6,
      "name": "Rock_Slate"
    },
    {
      "x": -15,
      "y": 26,
      "z": -6,
      "name": "Rock_Slate"
    },
    {
      "x": -15,
      "y": 27,
      "z": -6,
      "name": "Soil_Ash"
    },
    {
      "x": -15,
      "y": 28,
      "z": -6,
      "name": "Soil_Ash"
    },
    {
      "x": -15,
      "y": 24,
      "z": -5,
      "name": "Rock_Slate"
    },
    {
      "x": -15,
      "y": 25,
      "z": -5,
      "name": "Rock_Slate"
    },
    {
      "x": -15,
      "y": 26,
      "z": -5,
      "name": "Rock_Slate"
    },
    {
      "x": -14,
      "y": 22,
      "z": -12,
      "name": "Rock_Slate"
    },
    {
      "x": -14,
      "y": 23,
      "z": -12,
      "name": "Rock_Slate"
    },
    {
      "x": -14,
      "y": 24,
      "z": -12,
      "name": "Rock_Slate"
    },
    {
      "x": -14,
      "y": 25,
      "z": -12,
      "name": "Rock_Slate"
    },
    {
      "x": -14,
      "y": 26,
      "z": -12,
      "name": "Rock_Slate"
    },
    {
      "x": -14,
      "y": 27,
      "z": -12,
      "name": "Soil_Slate_Gravel"
    },
    {
      "x": -14,
      "y": 19,
      "z": -11,
      "name": "Rock_Slate"
    },
    {
      "x": -14,
      "y": 20,
      "z": -11,
      "name": "Rock_Slate"
    },
    {
      "x": -14,
      "y": 21,
      "z": -11,
      "name": "Rock_Slate"
    },
    {
      "x": -14,
      "y": 22,
      "z": -11,
      "name": "Rock_Slate"
    },
    {
      "x": -14,
      "y": 23,
      "z": -11,
      "name": "Rock_Slate"
    },
    {
      "x": -14,
      "y": 24,
      "z": -11,
      "name": "Rock_Slate"
    },
    {
      "x": -14,
      "y": 25,
      "z": -11,
      "name": "Rock_Slate"
    },
    {
      "x": -14,
      "y": 26,
      "z": -11,
      "name": "Rock_Slate"
    },
    {
      "x": -14,
      "y": 27,
      "z": -11,
      "name": "Rock_Slate"
    },
    {
      "x": -14,
      "y": 28,
      "z": -11,
      "name": "Soil_Slate_Gravel"
    },
    {
      "x": -14,
      "y": 18,
      "z": -10,
      "name": "Rock_Slate"
    },
    {
      "x": -14,
      "y": 19,
      "z": -10,
      "name": "Rock_Slate"
    },
    {
      "x": -14,
      "y": 20,
      "z": -10,
      "name": "Rock_Slate"
    },
    {
      "x": -14,
      "y": 21,
      "z": -10,
      "name": "Rock_Slate"
    },
    {
      "x": -14,
      "y": 22,
      "z": -10,
      "name": "Rock_Slate"
    },
    {
      "x": -14,
      "y": 23,
      "z": -10,
      "name": "Rock_Slate"
    },
    {
      "x": -14,
      "y": 24,
      "z": -10,
      "name": "Rock_Slate"
    },
    {
      "x": -14,
      "y": 25,
      "z": -10,
      "name": "Rock_Slate"
    },
    {
      "x": -14,
      "y": 26,
      "z": -10,
      "name": "Rock_Slate"
    },
    {
      "x": -14,
      "y": 27,
      "z": -10,
      "name": "Soil_Ash"
    },
    {
      "x": -14,
      "y": 28,
      "z": -10,
      "name": "Rock_Slate"
    },
    {
      "x": -14,
      "y": 17,
      "z": -9,
      "name": "Rock_Slate"
    },
    {
      "x": -14,
      "y": 18,
      "z": -9,
      "name": "Rock_Slate"
    },
    {
      "x": -14,
      "y": 19,
      "z": -9,
      "name": "Rock_Slate"
    },
    {
      "x": -14,
      "y": 20,
      "z": -9,
      "name": "Rock_Slate"
    },
    {
      "x": -14,
      "y": 21,
      "z": -9,
      "name": "Rock_Slate"
    },
    {
      "x": -14,
      "y": 22,
      "z": -9,
      "name": "Rock_Slate"
    },
    {
      "x": -14,
      "y": 23,
      "z": -9,
      "name": "Rock_Slate"
    },
    {
      "x": -14,
      "y": 24,
      "z": -9,
      "name": "Rock_Slate"
    },
    {
      "x": -14,
      "y": 25,
      "z": -9,
      "name": "Rock_Slate"
    },
    {
      "x": -14,
      "y": 26,
      "z": -9,
      "name": "Soil_Slate_Gravel"
    },
    {
      "x": -14,
      "y": 27,
      "z": -9,
      "name": "Soil_Ash"
    },
    {
      "x": -14,
      "y": 28,
      "z": -9,
      "name": "Soil_Ash"
    },
    {
      "x": -14,
      "y": 29,
      "z": -9,
      "name": "Soil_Ash"
    },
    {
      "x": -14,
      "y": 17,
      "z": -8,
      "name": "Rock_Slate"
    },
    {
      "x": -14,
      "y": 18,
      "z": -8,
      "name": "Rock_Slate"
    },
    {
      "x": -14,
      "y": 19,
      "z": -8,
      "name": "Rock_Slate"
    },
    {
      "x": -14,
      "y": 20,
      "z": -8,
      "name": "Rock_Slate"
    },
    {
      "x": -14,
      "y": 21,
      "z": -8,
      "name": "Rock_Slate"
    },
    {
      "x": -14,
      "y": 22,
      "z": -8,
      "name": "Rock_Slate"
    },
    {
      "x": -14,
      "y": 23,
      "z": -8,
      "name": "Rock_Slate"
    },
    {
      "x": -14,
      "y": 24,
      "z": -8,
      "name": "Rock_Slate"
    },
    {
      "x": -14,
      "y": 25,
      "z": -8,
      "name": "Rock_Slate"
    },
    {
      "x": -14,
      "y": 26,
      "z": -8,
      "name": "Soil_Ash"
    },
    {
      "x": -14,
      "y": 27,
      "z": -8,
      "name": "Soil_Ash"
    },
    {
      "x": -14,
      "y": 28,
      "z": -8,
      "name": "Rock_Slate"
    },
    {
      "x": -14,
      "y": 29,
      "z": -8,
      "name": "Soil_Ash"
    },
    {
      "x": -14,
      "y": 19,
      "z": -7,
      "name": "Rock_Slate"
    },
    {
      "x": -14,
      "y": 20,
      "z": -7,
      "name": "Rock_Slate"
    },
    {
      "x": -14,
      "y": 21,
      "z": -7,
      "name": "Rock_Slate"
    },
    {
      "x": -14,
      "y": 22,
      "z": -7,
      "name": "Rock_Slate"
    },
    {
      "x": -14,
      "y": 23,
      "z": -7,
      "name": "Rock_Slate"
    },
    {
      "x": -14,
      "y": 24,
      "z": -7,
      "name": "Rock_Slate"
    },
    {
      "x": -14,
      "y": 25,
      "z": -7,
      "name": "Rock_Slate"
    },
    {
      "x": -14,
      "y": 26,
      "z": -7,
      "name": "Soil_Ash"
    },
    {
      "x": -14,
      "y": 27,
      "z": -7,
      "name": "Soil_Ash"
    },
    {
      "x": -14,
      "y": 28,
      "z": -7,
      "name": "Soil_Ash"
    },
    {
      "x": -14,
      "y": 29,
      "z": -7,
      "name": "Rock_Slate"
    },
    {
      "x": -14,
      "y": 18,
      "z": -6,
      "name": "Rock_Slate"
    },
    {
      "x": -14,
      "y": 19,
      "z": -6,
      "name": "Rock_Slate"
    },
    {
      "x": -14,
      "y": 20,
      "z": -6,
      "name": "Rock_Slate"
    },
    {
      "x": -14,
      "y": 21,
      "z": -6,
      "name": "Rock_Slate"
    },
    {
      "x": -14,
      "y": 22,
      "z": -6,
      "name": "Rock_Slate"
    },
    {
      "x": -14,
      "y": 23,
      "z": -6,
      "name": "Rock_Slate"
    },
    {
      "x": -14,
      "y": 24,
      "z": -6,
      "name": "Rock_Slate"
    },
    {
      "x": -14,
      "y": 25,
      "z": -6,
      "name": "Rock_Slate"
    },
    {
      "x": -14,
      "y": 26,
      "z": -6,
      "name": "Rock_Slate"
    },
    {
      "x": -14,
      "y": 27,
      "z": -6,
      "name": "Rock_Slate"
    },
    {
      "x": -14,
      "y": 28,
      "z": -6,
      "name": "Soil_Slate_Gravel"
    },
    {
      "x": -14,
      "y": 20,
      "z": -5,
      "name": "Rock_Slate"
    },
    {
      "x": -14,
      "y": 21,
      "z": -5,
      "name": "Rock_Slate"
    },
    {
      "x": -14,
      "y": 22,
      "z": -5,
      "name": "Rock_Slate"
    },
    {
      "x": -14,
      "y": 23,
      "z": -5,
      "name": "Rock_Slate"
    },
    {
      "x": -14,
      "y": 24,
      "z": -5,
      "name": "Rock_Slate"
    },
    {
      "x": -14,
      "y": 25,
      "z": -5,
      "name": "Rock_Slate"
    },
    {
      "x": -14,
      "y": 26,
      "z": -5,
      "name": "Soil_Ash"
    },
    {
      "x": -14,
      "y": 27,
      "z": -5,
      "name": "Rock_Slate"
    },
    {
      "x": -14,
      "y": 28,
      "z": -5,
      "name": "Soil_Ash"
    },
    {
      "x": -14,
      "y": 21,
      "z": -4,
      "name": "Ore_Cobalt_Slate_Cracked"
    },
    {
      "x": -14,
      "y": 22,
      "z": -4,
      "name": "Ore_Cobalt_Slate_Cracked"
    },
    {
      "x": -14,
      "y": 23,
      "z": -4,
      "name": "Rock_Slate"
    },
    {
      "x": -14,
      "y": 24,
      "z": -4,
      "name": "Rock_Slate"
    },
    {
      "x": -14,
      "y": 25,
      "z": -4,
      "name": "Soil_Slate_Gravel"
    },
    {
      "x": -14,
      "y": 26,
      "z": -4,
      "name": "Soil_Ash"
    },
    {
      "x": -14,
      "y": 27,
      "z": -4,
      "name": "Soil_Ash"
    },
    {
      "x": -14,
      "y": 25,
      "z": -3,
      "name": "Rock_Slate"
    },
    {
      "x": -14,
      "y": 25,
      "z": 9,
      "name": "Rock_Slate"
    },
    {
      "x": -14,
      "y": 26,
      "z": 9,
      "name": "Rock_Slate"
    },
    {
      "x": -14,
      "y": 27,
      "z": 9,
      "name": "Rock_Slate"
    },
    {
      "x": -14,
      "y": 28,
      "z": 9,
      "name": "Soil_Slate_Gravel"
    },
    {
      "x": -14,
      "y": 21,
      "z": 10,
      "name": "Plant_Crop_Mushroom_Block_Purple_Mycelium"
    },
    {
      "x": -14,
      "y": 22,
      "z": 10,
      "name": "Rock_Slate"
    },
    {
      "x": -14,
      "y": 24,
      "z": 10,
      "name": "Rock_Slate"
    },
    {
      "x": -14,
      "y": 25,
      "z": 10,
      "name": "Rock_Slate"
    },
    {
      "x": -14,
      "y": 26,
      "z": 10,
      "name": "Rock_Slate"
    },
    {
      "x": -14,
      "y": 27,
      "z": 10,
      "name": "Rock_Slate"
    },
    {
      "x": -14,
      "y": 28,
      "z": 10,
      "name": "Soil_Ash"
    },
    {
      "x": -14,
      "y": 29,
      "z": 10,
      "name": "Rock_Slate"
    },
    {
      "x": -14,
      "y": 23,
      "z": 11,
      "name": "Rock_Slate"
    },
    {
      "x": -14,
      "y": 25,
      "z": 11,
      "name": "Rock_Slate"
    },
    {
      "x": -14,
      "y": 26,
      "z": 11,
      "name": "Rock_Slate"
    },
    {
      "x": -14,
      "y": 27,
      "z": 11,
      "name": "Rock_Slate"
    },
    {
      "x": -14,
      "y": 28,
      "z": 11,
      "name": "Soil_Ash"
    },
    {
      "x": -14,
      "y": 29,
      "z": 11,
      "name": "Rock_Slate"
    },
    {
      "x": -13,
      "y": 24,
      "z": -13,
      "name": "Rock_Slate"
    },
    {
      "x": -13,
      "y": 25,
      "z": -13,
      "name": "Rock_Slate"
    },
    {
      "x": -13,
      "y": 20,
      "z": -12,
      "name": "Rock_Slate"
    },
    {
      "x": -13,
      "y": 21,
      "z": -12,
      "name": "Rock_Slate"
    },
    {
      "x": -13,
      "y": 22,
      "z": -12,
      "name": "Rock_Slate"
    },
    {
      "x": -13,
      "y": 23,
      "z": -12,
      "name": "Rock_Slate"
    },
    {
      "x": -13,
      "y": 24,
      "z": -12,
      "name": "Rock_Slate"
    },
    {
      "x": -13,
      "y": 25,
      "z": -12,
      "name": "Rock_Slate"
    },
    {
      "x": -13,
      "y": 26,
      "z": -12,
      "name": "Soil_Ash"
    },
    {
      "x": -13,
      "y": 27,
      "z": -12,
      "name": "Soil_Ash"
    },
    {
      "x": -13,
      "y": 18,
      "z": -11,
      "name": "Rock_Slate"
    },
    {
      "x": -13,
      "y": 19,
      "z": -11,
      "name": "Rock_Slate"
    },
    {
      "x": -13,
      "y": 20,
      "z": -11,
      "name": "Rock_Slate"
    },
    {
      "x": -13,
      "y": 21,
      "z": -11,
      "name": "Rock_Slate"
    },
    {
      "x": -13,
      "y": 22,
      "z": -11,
      "name": "Rock_Slate"
    },
    {
      "x": -13,
      "y": 23,
      "z": -11,
      "name": "Rock_Slate"
    },
    {
      "x": -13,
      "y": 24,
      "z": -11,
      "name": "Rock_Slate"
    },
    {
      "x": -13,
      "y": 25,
      "z": -11,
      "name": "Rock_Slate"
    },
    {
      "x": -13,
      "y": 26,
      "z": -11,
      "name": "Soil_Ash"
    },
    {
      "x": -13,
      "y": 27,
      "z": -11,
      "name": "Rock_Slate"
    },
    {
      "x": -13,
      "y": 28,
      "z": -11,
      "name": "Rock_Slate"
    },
    {
      "x": -13,
      "y": 15,
      "z": -10,
      "name": "Rock_Slate"
    },
    {
      "x": -13,
      "y": 16,
      "z": -10,
      "name": "Rock_Slate"
    },
    {
      "x": -13,
      "y": 17,
      "z": -10,
      "name": "Rock_Slate"
    },
    {
      "x": -13,
      "y": 18,
      "z": -10,
      "name": "Rock_Slate"
    },
    {
      "x": -13,
      "y": 19,
      "z": -10,
      "name": "Rock_Slate"
    },
    {
      "x": -13,
      "y": 20,
      "z": -10,
      "name": "Rock_Slate"
    },
    {
      "x": -13,
      "y": 21,
      "z": -10,
      "name": "Rock_Slate"
    },
    {
      "x": -13,
      "y": 22,
      "z": -10,
      "name": "Rock_Slate"
    },
    {
      "x": -13,
      "y": 23,
      "z": -10,
      "name": "Rock_Slate"
    },
    {
      "x": -13,
      "y": 24,
      "z": -10,
      "name": "Rock_Slate"
    },
    {
      "x": -13,
      "y": 25,
      "z": -10,
      "name": "Rock_Slate"
    },
    {
      "x": -13,
      "y": 26,
      "z": -10,
      "name": "Rock_Slate"
    },
    {
      "x": -13,
      "y": 27,
      "z": -10,
      "name": "Soil_Ash"
    },
    {
      "x": -13,
      "y": 28,
      "z": -10,
      "name": "Soil_Ash"
    },
    {
      "x": -13,
      "y": 17,
      "z": -9,
      "name": "Rock_Slate"
    },
    {
      "x": -13,
      "y": 18,
      "z": -9,
      "name": "Rock_Slate"
    },
    {
      "x": -13,
      "y": 19,
      "z": -9,
      "name": "Rock_Slate"
    },
    {
      "x": -13,
      "y": 20,
      "z": -9,
      "name": "Rock_Slate"
    },
    {
      "x": -13,
      "y": 21,
      "z": -9,
      "name": "Rock_Slate"
    },
    {
      "x": -13,
      "y": 22,
      "z": -9,
      "name": "Rock_Slate"
    },
    {
      "x": -13,
      "y": 23,
      "z": -9,
      "name": "Rock_Slate"
    },
    {
      "x": -13,
      "y": 24,
      "z": -9,
      "name": "Rock_Slate"
    },
    {
      "x": -13,
      "y": 25,
      "z": -9,
      "name": "Soil_Ash"
    },
    {
      "x": -13,
      "y": 26,
      "z": -9,
      "name": "Soil_Ash"
    },
    {
      "x": -13,
      "y": 27,
      "z": -9,
      "name": "Rock_Slate"
    },
    {
      "x": -13,
      "y": 28,
      "z": -9,
      "name": "Soil_Ash"
    },
    {
      "x": -13,
      "y": 29,
      "z": -9,
      "name": "Soil_Slate_Gravel"
    },
    {
      "x": -13,
      "y": 17,
      "z": -8,
      "name": "Rock_Slate"
    },
    {
      "x": -13,
      "y": 18,
      "z": -8,
      "name": "Rock_Slate"
    },
    {
      "x": -13,
      "y": 19,
      "z": -8,
      "name": "Rock_Slate"
    },
    {
      "x": -13,
      "y": 20,
      "z": -8,
      "name": "Rock_Slate"
    },
    {
      "x": -13,
      "y": 21,
      "z": -8,
      "name": "Rock_Slate"
    },
    {
      "x": -13,
      "y": 22,
      "z": -8,
      "name": "Rock_Slate"
    },
    {
      "x": -13,
      "y": 23,
      "z": -8,
      "name": "Rock_Slate"
    },
    {
      "x": -13,
      "y": 24,
      "z": -8,
      "name": "Rock_Slate"
    },
    {
      "x": -13,
      "y": 25,
      "z": -8,
      "name": "Soil_Ash"
    },
    {
      "x": -13,
      "y": 26,
      "z": -8,
      "name": "Soil_Ash"
    },
    {
      "x": -13,
      "y": 27,
      "z": -8,
      "name": "Soil_Ash"
    },
    {
      "x": -13,
      "y": 28,
      "z": -8,
      "name": "Soil_Ash"
    },
    {
      "x": -13,
      "y": 29,
      "z": -8,
      "name": "Soil_Ash"
    },
    {
      "x": -13,
      "y": 18,
      "z": -7,
      "name": "Rock_Slate"
    },
    {
      "x": -13,
      "y": 19,
      "z": -7,
      "name": "Rock_Slate"
    },
    {
      "x": -13,
      "y": 20,
      "z": -7,
      "name": "Rock_Slate"
    },
    {
      "x": -13,
      "y": 21,
      "z": -7,
      "name": "Rock_Slate"
    },
    {
      "x": -13,
      "y": 22,
      "z": -7,
      "name": "Rock_Slate"
    },
    {
      "x": -13,
      "y": 23,
      "z": -7,
      "name": "Rock_Slate"
    },
    {
      "x": -13,
      "y": 24,
      "z": -7,
      "name": "Rock_Slate"
    },
    {
      "x": -13,
      "y": 25,
      "z": -7,
      "name": "Soil_Ash"
    },
    {
      "x": -13,
      "y": 26,
      "z": -7,
      "name": "Soil_Ash"
    },
    {
      "x": -13,
      "y": 27,
      "z": -7,
      "name": "Rock_Slate"
    },
    {
      "x": -13,
      "y": 28,
      "z": -7,
      "name": "Soil_Slate_Gravel"
    },
    {
      "x": -13,
      "y": 29,
      "z": -7,
      "name": "Rock_Slate"
    },
    {
      "x": -13,
      "y": 17,
      "z": -6,
      "name": "Rock_Slate"
    },
    {
      "x": -13,
      "y": 18,
      "z": -6,
      "name": "Rock_Slate"
    },
    {
      "x": -13,
      "y": 19,
      "z": -6,
      "name": "Rock_Slate"
    },
    {
      "x": -13,
      "y": 20,
      "z": -6,
      "name": "Rock_Slate"
    },
    {
      "x": -13,
      "y": 21,
      "z": -6,
      "name": "Rock_Slate"
    },
    {
      "x": -13,
      "y": 22,
      "z": -6,
      "name": "Rock_Slate"
    },
    {
      "x": -13,
      "y": 23,
      "z": -6,
      "name": "Rock_Slate"
    },
    {
      "x": -13,
      "y": 24,
      "z": -6,
      "name": "Rock_Slate"
    },
    {
      "x": -13,
      "y": 25,
      "z": -6,
      "name": "Soil_Ash"
    },
    {
      "x": -13,
      "y": 26,
      "z": -6,
      "name": "Rock_Slate"
    },
    {
      "x": -13,
      "y": 27,
      "z": -6,
      "name": "Soil_Ash"
    },
    {
      "x": -13,
      "y": 28,
      "z": -6,
      "name": "Soil_Slate_Gravel"
    },
    {
      "x": -13,
      "y": 17,
      "z": -5,
      "name": "Rock_Slate"
    },
    {
      "x": -13,
      "y": 18,
      "z": -5,
      "name": "Rock_Slate"
    },
    {
      "x": -13,
      "y": 19,
      "z": -5,
      "name": "Rock_Slate"
    },
    {
      "x": -13,
      "y": 20,
      "z": -5,
      "name": "Rock_Slate"
    },
    {
      "x": -13,
      "y": 21,
      "z": -5,
      "name": "Rock_Slate"
    },
    {
      "x": -13,
      "y": 22,
      "z": -5,
      "name": "Rock_Slate"
    },
    {
      "x": -13,
      "y": 23,
      "z": -5,
      "name": "Rock_Slate"
    },
    {
      "x": -13,
      "y": 24,
      "z": -5,
      "name": "Rock_Slate"
    },
    {
      "x": -13,
      "y": 25,
      "z": -5,
      "name": "Soil_Ash"
    },
    {
      "x": -13,
      "y": 26,
      "z": -5,
      "name": "Soil_Ash"
    },
    {
      "x": -13,
      "y": 27,
      "z": -5,
      "name": "Rock_Slate"
    },
    {
      "x": -13,
      "y": 28,
      "z": -5,
      "name": "Soil_Slate_Gravel"
    },
    {
      "x": -13,
      "y": 18,
      "z": -4,
      "name": "Rock_Slate"
    },
    {
      "x": -13,
      "y": 19,
      "z": -4,
      "name": "Rock_Slate"
    },
    {
      "x": -13,
      "y": 20,
      "z": -4,
      "name": "Rock_Slate"
    },
    {
      "x": -13,
      "y": 21,
      "z": -4,
      "name": "Rock_Slate"
    },
    {
      "x": -13,
      "y": 22,
      "z": -4,
      "name": "Rock_Slate"
    },
    {
      "x": -13,
      "y": 23,
      "z": -4,
      "name": "Rock_Slate"
    },
    {
      "x": -13,
      "y": 24,
      "z": -4,
      "name": "Rock_Slate"
    },
    {
      "x": -13,
      "y": 25,
      "z": -4,
      "name": "Soil_Ash"
    },
    {
      "x": -13,
      "y": 26,
      "z": -4,
      "name": "Rock_Slate"
    },
    {
      "x": -13,
      "y": 27,
      "z": -4,
      "name": "Soil_Ash"
    },
    {
      "x": -13,
      "y": 21,
      "z": -3,
      "name": "Rock_Slate"
    },
    {
      "x": -13,
      "y": 22,
      "z": -3,
      "name": "Rock_Slate"
    },
    {
      "x": -13,
      "y": 23,
      "z": -3,
      "name": "Rock_Slate"
    },
    {
      "x": -13,
      "y": 24,
      "z": -3,
      "name": "Soil_Slate_Gravel"
    },
    {
      "x": -13,
      "y": 25,
      "z": -3,
      "name": "Soil_Ash"
    },
    {
      "x": -13,
      "y": 26,
      "z": -3,
      "name": "Soil_Ash"
    },
    {
      "x": -13,
      "y": 27,
      "z": -3,
      "name": "Soil_Slate_Gravel"
    },
    {
      "x": -13,
      "y": 22,
      "z": -2,
      "name": "Rock_Slate"
    },
    {
      "x": -13,
      "y": 23,
      "z": -2,
      "name": "Rock_Slate"
    },
    {
      "x": -13,
      "y": 24,
      "z": -2,
      "name": "Soil_Slate_Gravel"
    },
    {
      "x": -13,
      "y": 25,
      "z": -2,
      "name": "Soil_Ash"
    },
    {
      "x": -13,
      "y": 26,
      "z": -2,
      "name": "Rock_Slate"
    },
    {
      "x": -13,
      "y": 27,
      "z": -2,
      "name": "Plant_Coral_Model_Pink"
    },
    {
      "x": -13,
      "y": 23,
      "z": -1,
      "name": "Rock_Slate"
    },
    {
      "x": -13,
      "y": 24,
      "z": -1,
      "name": "Soil_Slate_Gravel"
    },
    {
      "x": -13,
      "y": 25,
      "z": -1,
      "name": "Rock_Slate"
    },
    {
      "x": -13,
      "y": 26,
      "z": -1,
      "name": "Soil_Ash"
    },
    {
      "x": -13,
      "y": 22,
      "z": 0,
      "name": "Ore_Cobalt_Slate_Cracked"
    },
    {
      "x": -13,
      "y": 23,
      "z": 0,
      "name": "Ore_Cobalt_Slate"
    },
    {
      "x": -13,
      "y": 24,
      "z": 0,
      "name": "Rock_Slate"
    },
    {
      "x": -13,
      "y": 25,
      "z": 0,
      "name": "Soil_Slate_Gravel"
    },
    {
      "x": -13,
      "y": 26,
      "z": 0,
      "name": "Soil_Ash"
    },
    {
      "x": -13,
      "y": 27,
      "z": 0,
      "name": "Soil_Slate_Gravel"
    },
    {
      "x": -13,
      "y": 23,
      "z": 1,
      "name": "Ore_Cobalt_Slate"
    },
    {
      "x": -13,
      "y": 24,
      "z": 1,
      "name": "Soil_Ash"
    },
    {
      "x": -13,
      "y": 25,
      "z": 1,
      "name": "Soil_Ash"
    },
    {
      "x": -13,
      "y": 26,
      "z": 1,
      "name": "Soil_Ash"
    },
    {
      "x": -13,
      "y": 27,
      "z": 1,
      "name": "Soil_Ash"
    },
    {
      "x": -13,
      "y": 24,
      "z": 8,
      "name": "Rock_Slate"
    },
    {
      "x": -13,
      "y": 25,
      "z": 8,
      "name": "Rock_Slate"
    },
    {
      "x": -13,
      "y": 26,
      "z": 8,
      "name": "Soil_Ash"
    },
    {
      "x": -13,
      "y": 27,
      "z": 8,
      "name": "Soil_Ash"
    },
    {
      "x": -13,
      "y": 28,
      "z": 8,
      "name": "Soil_Ash"
    },
    {
      "x": -13,
      "y": 29,
      "z": 8,
      "name": "Soil_Slate_Gravel"
    },
    {
      "x": -13,
      "y": 21,
      "z": 9,
      "name": "Rock_Slate"
    },
    {
      "x": -13,
      "y": 22,
      "z": 9,
      "name": "Rock_Slate"
    },
    {
      "x": -13,
      "y": 23,
      "z": 9,
      "name": "Rock_Slate"
    },
    {
      "x": -13,
      "y": 24,
      "z": 9,
      "name": "Rock_Slate"
    },
    {
      "x": -13,
      "y": 25,
      "z": 9,
      "name": "Rock_Slate"
    },
    {
      "x": -13,
      "y": 26,
      "z": 9,
      "name": "Rock_Slate"
    },
    {
      "x": -13,
      "y": 27,
      "z": 9,
      "name": "Rock_Slate"
    },
    {
      "x": -13,
      "y": 28,
      "z": 9,
      "name": "Soil_Ash"
    },
    {
      "x": -13,
      "y": 29,
      "z": 9,
      "name": "Soil_Ash"
    },
    {
      "x": -13,
      "y": 19,
      "z": 10,
      "name": "Plant_Bush_Dead_Hanging"
    },
    {
      "x": -13,
      "y": 20,
      "z": 10,
      "name": "Rock_Slate"
    },
    {
      "x": -13,
      "y": 21,
      "z": 10,
      "name": "Rock_Slate"
    },
    {
      "x": -13,
      "y": 22,
      "z": 10,
      "name": "Rock_Slate"
    },
    {
      "x": -13,
      "y": 23,
      "z": 10,
      "name": "Rock_Slate"
    },
    {
      "x": -13,
      "y": 24,
      "z": 10,
      "name": "Rock_Slate"
    },
    {
      "x": -13,
      "y": 25,
      "z": 10,
      "name": "Rock_Slate"
    },
    {
      "x": -13,
      "y": 26,
      "z": 10,
      "name": "Rock_Slate"
    },
    {
      "x": -13,
      "y": 27,
      "z": 10,
      "name": "Rock_Slate"
    },
    {
      "x": -13,
      "y": 28,
      "z": 10,
      "name": "Rock_Slate"
    },
    {
      "x": -13,
      "y": 29,
      "z": 10,
      "name": "Soil_Slate_Gravel"
    },
    {
      "x": -13,
      "y": 30,
      "z": 10,
      "name": "Soil_Ash"
    },
    {
      "x": -13,
      "y": 21,
      "z": 11,
      "name": "Rock_Slate"
    },
    {
      "x": -13,
      "y": 22,
      "z": 11,
      "name": "Rock_Slate"
    },
    {
      "x": -13,
      "y": 23,
      "z": 11,
      "name": "Rock_Slate"
    },
    {
      "x": -13,
      "y": 24,
      "z": 11,
      "name": "Rock_Slate"
    },
    {
      "x": -13,
      "y": 25,
      "z": 11,
      "name": "Rock_Slate"
    },
    {
      "x": -13,
      "y": 26,
      "z": 11,
      "name": "Rock_Slate"
    },
    {
      "x": -13,
      "y": 27,
      "z": 11,
      "name": "Rock_Slate"
    },
    {
      "x": -13,
      "y": 28,
      "z": 11,
      "name": "Soil_Slate_Gravel"
    },
    {
      "x": -13,
      "y": 29,
      "z": 11,
      "name": "Soil_Slate_Gravel"
    },
    {
      "x": -13,
      "y": 30,
      "z": 11,
      "name": "Rock_Slate"
    },
    {
      "x": -13,
      "y": 22,
      "z": 12,
      "name": "Rock_Slate"
    },
    {
      "x": -13,
      "y": 24,
      "z": 12,
      "name": "Rock_Slate"
    },
    {
      "x": -13,
      "y": 25,
      "z": 12,
      "name": "Rock_Slate"
    },
    {
      "x": -13,
      "y": 26,
      "z": 12,
      "name": "Rock_Slate"
    },
    {
      "x": -13,
      "y": 27,
      "z": 12,
      "name": "Rock_Slate"
    },
    {
      "x": -13,
      "y": 28,
      "z": 12,
      "name": "Soil_Ash"
    },
    {
      "x": -13,
      "y": 29,
      "z": 12,
      "name": "Soil_Slate_Gravel"
    },
    {
      "x": -13,
      "y": 26,
      "z": 13,
      "name": "Rock_Crystal_Pink_Small",
      "rotation": 7
    },
    {
      "x": -13,
      "y": 27,
      "z": 13,
      "name": "Plant_Coral_Bush_Violet"
    },
    {
      "x": -12,
      "y": 22,
      "z": -13,
      "name": "Rock_Slate"
    },
    {
      "x": -12,
      "y": 23,
      "z": -13,
      "name": "Rock_Slate"
    },
    {
      "x": -12,
      "y": 24,
      "z": -13,
      "name": "Rock_Slate"
    },
    {
      "x": -12,
      "y": 25,
      "z": -13,
      "name": "Rock_Slate"
    },
    {
      "x": -12,
      "y": 26,
      "z": -13,
      "name": "Rock_Slate"
    },
    {
      "x": -12,
      "y": 27,
      "z": -13,
      "name": "Plant_Coral_Bush_Purple"
    },
    {
      "x": -12,
      "y": 20,
      "z": -12,
      "name": "Rock_Slate"
    },
    {
      "x": -12,
      "y": 21,
      "z": -12,
      "name": "Rock_Slate"
    },
    {
      "x": -12,
      "y": 22,
      "z": -12,
      "name": "Rock_Slate"
    },
    {
      "x": -12,
      "y": 23,
      "z": -12,
      "name": "Rock_Slate"
    },
    {
      "x": -12,
      "y": 24,
      "z": -12,
      "name": "Rock_Slate"
    },
    {
      "x": -12,
      "y": 25,
      "z": -12,
      "name": "Rock_Slate"
    },
    {
      "x": -12,
      "y": 26,
      "z": -12,
      "name": "Soil_Ash"
    },
    {
      "x": -12,
      "y": 27,
      "z": -12,
      "name": "Rock_Slate"
    },
    {
      "x": -12,
      "y": 18,
      "z": -11,
      "name": "Plant_Crop_Mushroom_Block_Purple_Mycelium"
    },
    {
      "x": -12,
      "y": 19,
      "z": -11,
      "name": "Rock_Slate"
    },
    {
      "x": -12,
      "y": 20,
      "z": -11,
      "name": "Rock_Slate"
    },
    {
      "x": -12,
      "y": 21,
      "z": -11,
      "name": "Rock_Slate"
    },
    {
      "x": -12,
      "y": 22,
      "z": -11,
      "name": "Rock_Slate"
    },
    {
      "x": -12,
      "y": 23,
      "z": -11,
      "name": "Rock_Slate"
    },
    {
      "x": -12,
      "y": 24,
      "z": -11,
      "name": "Rock_Slate"
    },
    {
      "x": -12,
      "y": 25,
      "z": -11,
      "name": "Rock_Slate"
    },
    {
      "x": -12,
      "y": 26,
      "z": -11,
      "name": "Soil_Ash"
    },
    {
      "x": -12,
      "y": 27,
      "z": -11,
      "name": "Soil_Ash"
    },
    {
      "x": -12,
      "y": 28,
      "z": -11,
      "name": "Soil_Ash"
    },
    {
      "x": -12,
      "y": 18,
      "z": -10,
      "name": "Rock_Slate"
    },
    {
      "x": -12,
      "y": 19,
      "z": -10,
      "name": "Rock_Slate"
    },
    {
      "x": -12,
      "y": 20,
      "z": -10,
      "name": "Rock_Slate"
    },
    {
      "x": -12,
      "y": 21,
      "z": -10,
      "name": "Rock_Slate"
    },
    {
      "x": -12,
      "y": 22,
      "z": -10,
      "name": "Rock_Slate"
    },
    {
      "x": -12,
      "y": 23,
      "z": -10,
      "name": "Rock_Slate"
    },
    {
      "x": -12,
      "y": 24,
      "z": -10,
      "name": "Rock_Slate"
    },
    {
      "x": -12,
      "y": 25,
      "z": -10,
      "name": "Rock_Slate"
    },
    {
      "x": -12,
      "y": 26,
      "z": -10,
      "name": "Soil_Ash"
    },
    {
      "x": -12,
      "y": 27,
      "z": -10,
      "name": "Soil_Ash"
    },
    {
      "x": -12,
      "y": 28,
      "z": -10,
      "name": "Soil_Ash"
    },
    {
      "x": -12,
      "y": 16,
      "z": -9,
      "name": "Plant_Crop_Mushroom_Block_Purple_Mycelium"
    },
    {
      "x": -12,
      "y": 17,
      "z": -9,
      "name": "Rock_Slate"
    },
    {
      "x": -12,
      "y": 18,
      "z": -9,
      "name": "Rock_Slate"
    },
    {
      "x": -12,
      "y": 19,
      "z": -9,
      "name": "Rock_Slate"
    },
    {
      "x": -12,
      "y": 20,
      "z": -9,
      "name": "Rock_Slate"
    },
    {
      "x": -12,
      "y": 21,
      "z": -9,
      "name": "Rock_Slate"
    },
    {
      "x": -12,
      "y": 22,
      "z": -9,
      "name": "Rock_Slate"
    },
    {
      "x": -12,
      "y": 23,
      "z": -9,
      "name": "Rock_Slate"
    },
    {
      "x": -12,
      "y": 24,
      "z": -9,
      "name": "Rock_Slate"
    },
    {
      "x": -12,
      "y": 25,
      "z": -9,
      "name": "Rock_Slate"
    },
    {
      "x": -12,
      "y": 26,
      "z": -9,
      "name": "Soil_Slate_Gravel"
    },
    {
      "x": -12,
      "y": 27,
      "z": -9,
      "name": "Soil_Slate_Gravel"
    },
    {
      "x": -12,
      "y": 28,
      "z": -9,
      "name": "Soil_Slate_Gravel"
    },
    {
      "x": -12,
      "y": 18,
      "z": -8,
      "name": "Rock_Slate"
    },
    {
      "x": -12,
      "y": 19,
      "z": -8,
      "name": "Rock_Slate"
    },
    {
      "x": -12,
      "y": 20,
      "z": -8,
      "name": "Rock_Slate"
    },
    {
      "x": -12,
      "y": 21,
      "z": -8,
      "name": "Rock_Slate"
    },
    {
      "x": -12,
      "y": 22,
      "z": -8,
      "name": "Rock_Slate"
    },
    {
      "x": -12,
      "y": 23,
      "z": -8,
      "name": "Rock_Slate"
    },
    {
      "x": -12,
      "y": 24,
      "z": -8,
      "name": "Rock_Slate"
    },
    {
      "x": -12,
      "y": 25,
      "z": -8,
      "name": "Rock_Slate"
    },
    {
      "x": -12,
      "y": 26,
      "z": -8,
      "name": "Soil_Ash"
    },
    {
      "x": -12,
      "y": 27,
      "z": -8,
      "name": "Soil_Ash"
    },
    {
      "x": -12,
      "y": 28,
      "z": -8,
      "name": "Soil_Ash"
    },
    {
      "x": -12,
      "y": 29,
      "z": -8,
      "name": "Soil_Ash"
    },
    {
      "x": -12,
      "y": 17,
      "z": -7,
      "name": "Rock_Slate"
    },
    {
      "x": -12,
      "y": 18,
      "z": -7,
      "name": "Rock_Slate"
    },
    {
      "x": -12,
      "y": 19,
      "z": -7,
      "name": "Rock_Slate"
    },
    {
      "x": -12,
      "y": 20,
      "z": -7,
      "name": "Rock_Slate"
    },
    {
      "x": -12,
      "y": 21,
      "z": -7,
      "name": "Rock_Slate"
    },
    {
      "x": -12,
      "y": 22,
      "z": -7,
      "name": "Rock_Slate"
    },
    {
      "x": -12,
      "y": 23,
      "z": -7,
      "name": "Rock_Slate"
    },
    {
      "x": -12,
      "y": 24,
      "z": -7,
      "name": "Rock_Slate"
    },
    {
      "x": -12,
      "y": 25,
      "z": -7,
      "name": "Soil_Ash"
    },
    {
      "x": -12,
      "y": 26,
      "z": -7,
      "name": "Soil_Ash"
    },
    {
      "x": -12,
      "y": 27,
      "z": -7,
      "name": "Soil_Ash"
    },
    {
      "x": -12,
      "y": 28,
      "z": -7,
      "name": "Soil_Ash"
    },
    {
      "x": -12,
      "y": 29,
      "z": -7,
      "name": "Plant_Flower_Bushy_Purple"
    },
    {
      "x": -12,
      "y": 16,
      "z": -6,
      "name": "Rock_Slate"
    },
    {
      "x": -12,
      "y": 17,
      "z": -6,
      "name": "Rock_Slate"
    },
    {
      "x": -12,
      "y": 18,
      "z": -6,
      "name": "Rock_Slate"
    },
    {
      "x": -12,
      "y": 19,
      "z": -6,
      "name": "Rock_Slate"
    },
    {
      "x": -12,
      "y": 20,
      "z": -6,
      "name": "Rock_Slate"
    },
    {
      "x": -12,
      "y": 21,
      "z": -6,
      "name": "Rock_Slate"
    },
    {
      "x": -12,
      "y": 22,
      "z": -6,
      "name": "Rock_Slate"
    },
    {
      "x": -12,
      "y": 23,
      "z": -6,
      "name": "Rock_Slate"
    },
    {
      "x": -12,
      "y": 24,
      "z": -6,
      "name": "Rock_Slate"
    },
    {
      "x": -12,
      "y": 25,
      "z": -6,
      "name": "Soil_Slate_Gravel"
    },
    {
      "x": -12,
      "y": 26,
      "z": -6,
      "name": "Soil_Ash"
    },
    {
      "x": -12,
      "y": 27,
      "z": -6,
      "name": "Soil_Slate_Gravel"
    },
    {
      "x": -12,
      "y": 28,
      "z": -6,
      "name": "Soil_Slate_Gravel"
    },
    {
      "x": -12,
      "y": 16,
      "z": -5,
      "name": "Plant_Crop_Mushroom_Block_Purple_Mycelium"
    },
    {
      "x": -12,
      "y": 17,
      "z": -5,
      "name": "Rock_Slate"
    },
    {
      "x": -12,
      "y": 18,
      "z": -5,
      "name": "Rock_Slate"
    },
    {
      "x": -12,
      "y": 19,
      "z": -5,
      "name": "Rock_Slate"
    },
    {
      "x": -12,
      "y": 20,
      "z": -5,
      "name": "Rock_Slate"
    },
    {
      "x": -12,
      "y": 21,
      "z": -5,
      "name": "Rock_Slate"
    },
    {
      "x": -12,
      "y": 22,
      "z": -5,
      "name": "Rock_Slate"
    },
    {
      "x": -12,
      "y": 23,
      "z": -5,
      "name": "Rock_Slate"
    },
    {
      "x": -12,
      "y": 24,
      "z": -5,
      "name": "Rock_Slate"
    },
    {
      "x": -12,
      "y": 25,
      "z": -5,
      "name": "Rock_Slate"
    },
    {
      "x": -12,
      "y": 26,
      "z": -5,
      "name": "Rock_Slate"
    },
    {
      "x": -12,
      "y": 27,
      "z": -5,
      "name": "Soil_Ash"
    },
    {
      "x": -12,
      "y": 28,
      "z": -5,
      "name": "Rock_Slate"
    },
    {
      "x": -12,
      "y": 18,
      "z": -4,
      "name": "Rock_Slate"
    },
    {
      "x": -12,
      "y": 19,
      "z": -4,
      "name": "Rock_Slate"
    },
    {
      "x": -12,
      "y": 20,
      "z": -4,
      "name": "Rock_Slate"
    },
    {
      "x": -12,
      "y": 21,
      "z": -4,
      "name": "Rock_Slate"
    },
    {
      "x": -12,
      "y": 22,
      "z": -4,
      "name": "Rock_Slate"
    },
    {
      "x": -12,
      "y": 23,
      "z": -4,
      "name": "Rock_Slate"
    },
    {
      "x": -12,
      "y": 24,
      "z": -4,
      "name": "Soil_Ash"
    },
    {
      "x": -12,
      "y": 25,
      "z": -4,
      "name": "Soil_Slate_Gravel"
    },
    {
      "x": -12,
      "y": 26,
      "z": -4,
      "name": "Soil_Slate_Gravel"
    },
    {
      "x": -12,
      "y": 27,
      "z": -4,
      "name": "Soil_Ash"
    },
    {
      "x": -12,
      "y": 17,
      "z": -3,
      "name": "Ore_Cobalt_Slate_Cracked"
    },
    {
      "x": -12,
      "y": 18,
      "z": -3,
      "name": "Rock_Slate"
    },
    {
      "x": -12,
      "y": 19,
      "z": -3,
      "name": "Rock_Slate"
    },
    {
      "x": -12,
      "y": 20,
      "z": -3,
      "name": "Rock_Slate"
    },
    {
      "x": -12,
      "y": 21,
      "z": -3,
      "name": "Rock_Slate"
    },
    {
      "x": -12,
      "y": 22,
      "z": -3,
      "name": "Rock_Slate"
    },
    {
      "x": -12,
      "y": 23,
      "z": -3,
      "name": "Rock_Slate"
    },
    {
      "x": -12,
      "y": 24,
      "z": -3,
      "name": "Soil_Ash"
    },
    {
      "x": -12,
      "y": 25,
      "z": -3,
      "name": "Rock_Slate"
    },
    {
      "x": -12,
      "y": 26,
      "z": -3,
      "name": "Soil_Slate_Gravel"
    },
    {
      "x": -12,
      "y": 27,
      "z": -3,
      "name": "Soil_Slate_Gravel"
    },
    {
      "x": -12,
      "y": 18,
      "z": -2,
      "name": "Rock_Slate"
    },
    {
      "x": -12,
      "y": 19,
      "z": -2,
      "name": "Rock_Slate"
    },
    {
      "x": -12,
      "y": 20,
      "z": -2,
      "name": "Rock_Slate"
    },
    {
      "x": -12,
      "y": 21,
      "z": -2,
      "name": "Rock_Slate"
    },
    {
      "x": -12,
      "y": 22,
      "z": -2,
      "name": "Rock_Slate"
    },
    {
      "x": -12,
      "y": 23,
      "z": -2,
      "name": "Rock_Slate"
    },
    {
      "x": -12,
      "y": 24,
      "z": -2,
      "name": "Rock_Slate"
    },
    {
      "x": -12,
      "y": 25,
      "z": -2,
      "name": "Rock_Slate"
    },
    {
      "x": -12,
      "y": 26,
      "z": -2,
      "name": "Soil_Ash"
    },
    {
      "x": -12,
      "y": 27,
      "z": -2,
      "name": "Soil_Ash"
    },
    {
      "x": -12,
      "y": 19,
      "z": -1,
      "name": "Rock_Slate"
    },
    {
      "x": -12,
      "y": 20,
      "z": -1,
      "name": "Ore_Cobalt_Slate_Cracked"
    },
    {
      "x": -12,
      "y": 21,
      "z": -1,
      "name": "Rock_Slate"
    },
    {
      "x": -12,
      "y": 22,
      "z": -1,
      "name": "Rock_Slate"
    },
    {
      "x": -12,
      "y": 23,
      "z": -1,
      "name": "Rock_Slate"
    },
    {
      "x": -12,
      "y": 24,
      "z": -1,
      "name": "Soil_Ash"
    },
    {
      "x": -12,
      "y": 25,
      "z": -1,
      "name": "Rock_Slate"
    },
    {
      "x": -12,
      "y": 26,
      "z": -1,
      "name": "Soil_Ash"
    },
    {
      "x": -12,
      "y": 27,
      "z": -1,
      "name": "Soil_Ash"
    },
    {
      "x": -12,
      "y": 18,
      "z": 0,
      "name": "Rock_Slate"
    },
    {
      "x": -12,
      "y": 19,
      "z": 0,
      "name": "Rock_Slate"
    },
    {
      "x": -12,
      "y": 20,
      "z": 0,
      "name": "Rock_Slate"
    },
    {
      "x": -12,
      "y": 21,
      "z": 0,
      "name": "Rock_Slate"
    },
    {
      "x": -12,
      "y": 22,
      "z": 0,
      "name": "Ore_Cobalt_Slate"
    },
    {
      "x": -12,
      "y": 23,
      "z": 0,
      "name": "Ore_Cobalt_Slate"
    },
    {
      "x": -12,
      "y": 24,
      "z": 0,
      "name": "Rock_Slate"
    },
    {
      "x": -12,
      "y": 25,
      "z": 0,
      "name": "Rock_Slate"
    },
    {
      "x": -12,
      "y": 26,
      "z": 0,
      "name": "Rock_Slate"
    },
    {
      "x": -12,
      "y": 19,
      "z": 1,
      "name": "Rock_Slate"
    },
    {
      "x": -12,
      "y": 20,
      "z": 1,
      "name": "Rock_Slate"
    },
    {
      "x": -12,
      "y": 21,
      "z": 1,
      "name": "Ore_Cobalt_Slate_Cracked"
    },
    {
      "x": -12,
      "y": 22,
      "z": 1,
      "name": "Ore_Cobalt_Slate"
    },
    {
      "x": -12,
      "y": 23,
      "z": 1,
      "name": "Ore_Cobalt_Slate"
    },
    {
      "x": -12,
      "y": 24,
      "z": 1,
      "name": "Rock_Slate"
    },
    {
      "x": -12,
      "y": 25,
      "z": 1,
      "name": "Soil_Slate_Gravel"
    },
    {
      "x": -12,
      "y": 26,
      "z": 1,
      "name": "Soil_Slate_Gravel"
    },
    {
      "x": -12,
      "y": 27,
      "z": 1,
      "name": "Soil_Ash"
    },
    {
      "x": -12,
      "y": 20,
      "z": 2,
      "name": "Rock_Slate"
    },
    {
      "x": -12,
      "y": 21,
      "z": 2,
      "name": "Ore_Cobalt_Slate_Cracked"
    },
    {
      "x": -12,
      "y": 22,
      "z": 2,
      "name": "Rock_Slate"
    },
    {
      "x": -12,
      "y": 23,
      "z": 2,
      "name": "Rock_Slate"
    },
    {
      "x": -12,
      "y": 24,
      "z": 2,
      "name": "Ore_Cobalt_Slate_Cracked"
    },
    {
      "x": -12,
      "y": 25,
      "z": 2,
      "name": "Rock_Slate"
    },
    {
      "x": -12,
      "y": 26,
      "z": 2,
      "name": "Soil_Slate_Gravel"
    },
    {
      "x": -12,
      "y": 27,
      "z": 2,
      "name": "Soil_Ash"
    },
    {
      "x": -12,
      "y": 24,
      "z": 3,
      "name": "Soil_Slate_Gravel"
    },
    {
      "x": -12,
      "y": 23,
      "z": 7,
      "name": "Rock_Slate"
    },
    {
      "x": -12,
      "y": 24,
      "z": 7,
      "name": "Rock_Slate"
    },
    {
      "x": -12,
      "y": 25,
      "z": 7,
      "name": "Soil_Ash"
    },
    {
      "x": -12,
      "y": 26,
      "z": 7,
      "name": "Soil_Ash"
    },
    {
      "x": -12,
      "y": 27,
      "z": 7,
      "name": "Soil_Slate_Gravel"
    },
    {
      "x": -12,
      "y": 28,
      "z": 7,
      "name": "Soil_Ash"
    },
    {
      "x": -12,
      "y": 22,
      "z": 8,
      "name": "Rock_Slate"
    },
    {
      "x": -12,
      "y": 23,
      "z": 8,
      "name": "Rock_Slate"
    },
    {
      "x": -12,
      "y": 24,
      "z": 8,
      "name": "Rock_Slate"
    },
    {
      "x": -12,
      "y": 25,
      "z": 8,
      "name": "Rock_Slate"
    },
    {
      "x": -12,
      "y": 26,
      "z": 8,
      "name": "Soil_Slate_Gravel"
    },
    {
      "x": -12,
      "y": 27,
      "z": 8,
      "name": "Rock_Slate"
    },
    {
      "x": -12,
      "y": 28,
      "z": 8,
      "name": "Soil_Ash"
    },
    {
      "x": -12,
      "y": 29,
      "z": 8,
      "name": "Soil_Ash"
    },
    {
      "x": -12,
      "y": 20,
      "z": 9,
      "name": "Rock_Slate"
    },
    {
      "x": -12,
      "y": 21,
      "z": 9,
      "name": "Rock_Slate"
    },
    {
      "x": -12,
      "y": 22,
      "z": 9,
      "name": "Rock_Slate"
    },
    {
      "x": -12,
      "y": 23,
      "z": 9,
      "name": "Rock_Slate"
    },
    {
      "x": -12,
      "y": 24,
      "z": 9,
      "name": "Rock_Slate"
    },
    {
      "x": -12,
      "y": 25,
      "z": 9,
      "name": "Rock_Slate"
    },
    {
      "x": -12,
      "y": 26,
      "z": 9,
      "name": "Rock_Slate"
    },
    {
      "x": -12,
      "y": 27,
      "z": 9,
      "name": "Soil_Ash"
    },
    {
      "x": -12,
      "y": 28,
      "z": 9,
      "name": "Soil_Ash"
    },
    {
      "x": -12,
      "y": 29,
      "z": 9,
      "name": "Soil_Ash"
    },
    {
      "x": -12,
      "y": 30,
      "z": 9,
      "name": "Soil_Ash"
    },
    {
      "x": -12,
      "y": 19,
      "z": 10,
      "name": "Rock_Slate"
    },
    {
      "x": -12,
      "y": 20,
      "z": 10,
      "name": "Rock_Slate"
    },
    {
      "x": -12,
      "y": 21,
      "z": 10,
      "name": "Rock_Slate"
    },
    {
      "x": -12,
      "y": 22,
      "z": 10,
      "name": "Rock_Slate"
    },
    {
      "x": -12,
      "y": 23,
      "z": 10,
      "name": "Rock_Slate"
    },
    {
      "x": -12,
      "y": 24,
      "z": 10,
      "name": "Rock_Slate"
    },
    {
      "x": -12,
      "y": 25,
      "z": 10,
      "name": "Rock_Slate"
    },
    {
      "x": -12,
      "y": 26,
      "z": 10,
      "name": "Soil_Ash"
    },
    {
      "x": -12,
      "y": 27,
      "z": 10,
      "name": "Soil_Slate_Gravel"
    },
    {
      "x": -12,
      "y": 28,
      "z": 10,
      "name": "Soil_Ash"
    },
    {
      "x": -12,
      "y": 29,
      "z": 10,
      "name": "Plant_Coral_Block_Violet"
    },
    {
      "x": -12,
      "y": 30,
      "z": 10,
      "name": "Rock_Crystal_Pink_Small"
    },
    {
      "x": -12,
      "y": 20,
      "z": 11,
      "name": "Rock_Slate"
    },
    {
      "x": -12,
      "y": 21,
      "z": 11,
      "name": "Rock_Slate"
    },
    {
      "x": -12,
      "y": 22,
      "z": 11,
      "name": "Rock_Slate"
    },
    {
      "x": -12,
      "y": 23,
      "z": 11,
      "name": "Rock_Slate"
    },
    {
      "x": -12,
      "y": 24,
      "z": 11,
      "name": "Rock_Slate"
    },
    {
      "x": -12,
      "y": 25,
      "z": 11,
      "name": "Rock_Slate"
    },
    {
      "x": -12,
      "y": 26,
      "z": 11,
      "name": "Soil_Ash"
    },
    {
      "x": -12,
      "y": 27,
      "z": 11,
      "name": "Rock_Slate"
    },
    {
      "x": -12,
      "y": 28,
      "z": 11,
      "name": "Soil_Ash"
    },
    {
      "x": -12,
      "y": 29,
      "z": 11,
      "name": "Plant_Coral_Block_Violet"
    },
    {
      "x": -12,
      "y": 21,
      "z": 12,
      "name": "Rock_Slate"
    },
    {
      "x": -12,
      "y": 22,
      "z": 12,
      "name": "Rock_Slate"
    },
    {
      "x": -12,
      "y": 23,
      "z": 12,
      "name": "Rock_Slate"
    },
    {
      "x": -12,
      "y": 24,
      "z": 12,
      "name": "Rock_Slate"
    },
    {
      "x": -12,
      "y": 25,
      "z": 12,
      "name": "Rock_Slate"
    },
    {
      "x": -12,
      "y": 26,
      "z": 12,
      "name": "Rock_Slate"
    },
    {
      "x": -12,
      "y": 27,
      "z": 12,
      "name": "Soil_Ash"
    },
    {
      "x": -12,
      "y": 28,
      "z": 12,
      "name": "Plant_Coral_Block_Violet"
    },
    {
      "x": -12,
      "y": 29,
      "z": 12,
      "name": "Plant_Coral_Bush_Violet"
    },
    {
      "x": -12,
      "y": 25,
      "z": 13,
      "name": "Rock_Slate"
    },
    {
      "x": -12,
      "y": 26,
      "z": 13,
      "name": "Plant_Coral_Block_Violet"
    },
    {
      "x": -12,
      "y": 27,
      "z": 13,
      "name": "Plant_Coral_Block_Violet"
    },
    {
      "x": -12,
      "y": 28,
      "z": 13,
      "name": "Rock_Crystal_Pink_Small"
    },
    {
      "x": -12,
      "y": 26,
      "z": 14,
      "name": "Plant_Coral_Bush_Violet"
    },
    {
      "x": -11,
      "y": 23,
      "z": -14,
      "name": "Rock_Slate"
    },
    {
      "x": -11,
      "y": 24,
      "z": -14,
      "name": "Rock_Slate"
    },
    {
      "x": -11,
      "y": 25,
      "z": -14,
      "name": "Rock_Slate"
    },
    {
      "x": -11,
      "y": 21,
      "z": -13,
      "name": "Rock_Slate"
    },
    {
      "x": -11,
      "y": 22,
      "z": -13,
      "name": "Rock_Slate"
    },
    {
      "x": -11,
      "y": 23,
      "z": -13,
      "name": "Rock_Slate"
    },
    {
      "x": -11,
      "y": 24,
      "z": -13,
      "name": "Rock_Slate"
    },
    {
      "x": -11,
      "y": 25,
      "z": -13,
      "name": "Rock_Slate"
    },
    {
      "x": -11,
      "y": 26,
      "z": -13,
      "name": "Rock_Slate"
    },
    {
      "x": -11,
      "y": 20,
      "z": -12,
      "name": "Rock_Slate"
    },
    {
      "x": -11,
      "y": 21,
      "z": -12,
      "name": "Rock_Slate"
    },
    {
      "x": -11,
      "y": 22,
      "z": -12,
      "name": "Rock_Slate"
    },
    {
      "x": -11,
      "y": 23,
      "z": -12,
      "name": "Rock_Slate"
    },
    {
      "x": -11,
      "y": 24,
      "z": -12,
      "name": "Rock_Slate"
    },
    {
      "x": -11,
      "y": 25,
      "z": -12,
      "name": "Rock_Slate"
    },
    {
      "x": -11,
      "y": 26,
      "z": -12,
      "name": "Soil_Ash"
    },
    {
      "x": -11,
      "y": 27,
      "z": -12,
      "name": "Soil_Ash"
    },
    {
      "x": -11,
      "y": 19,
      "z": -11,
      "name": "Rock_Slate"
    },
    {
      "x": -11,
      "y": 20,
      "z": -11,
      "name": "Rock_Slate"
    },
    {
      "x": -11,
      "y": 21,
      "z": -11,
      "name": "Rock_Slate"
    },
    {
      "x": -11,
      "y": 22,
      "z": -11,
      "name": "Rock_Slate"
    },
    {
      "x": -11,
      "y": 23,
      "z": -11,
      "name": "Rock_Slate"
    },
    {
      "x": -11,
      "y": 24,
      "z": -11,
      "name": "Rock_Slate"
    },
    {
      "x": -11,
      "y": 25,
      "z": -11,
      "name": "Soil_Ash"
    },
    {
      "x": -11,
      "y": 26,
      "z": -11,
      "name": "Soil_Ash"
    },
    {
      "x": -11,
      "y": 27,
      "z": -11,
      "name": "Soil_Slate_Gravel"
    },
    {
      "x": -11,
      "y": 28,
      "z": -11,
      "name": "Soil_Ash"
    },
    {
      "x": -11,
      "y": 19,
      "z": -10,
      "name": "Rock_Slate"
    },
    {
      "x": -11,
      "y": 20,
      "z": -10,
      "name": "Rock_Slate"
    },
    {
      "x": -11,
      "y": 21,
      "z": -10,
      "name": "Rock_Slate"
    },
    {
      "x": -11,
      "y": 22,
      "z": -10,
      "name": "Rock_Slate"
    },
    {
      "x": -11,
      "y": 23,
      "z": -10,
      "name": "Rock_Slate"
    },
    {
      "x": -11,
      "y": 24,
      "z": -10,
      "name": "Rock_Slate"
    },
    {
      "x": -11,
      "y": 25,
      "z": -10,
      "name": "Soil_Ash"
    },
    {
      "x": -11,
      "y": 26,
      "z": -10,
      "name": "Rock_Slate"
    },
    {
      "x": -11,
      "y": 27,
      "z": -10,
      "name": "Soil_Ash"
    },
    {
      "x": -11,
      "y": 28,
      "z": -10,
      "name": "Soil_Ash"
    },
    {
      "x": -11,
      "y": 18,
      "z": -9,
      "name": "Rock_Slate"
    },
    {
      "x": -11,
      "y": 19,
      "z": -9,
      "name": "Rock_Slate"
    },
    {
      "x": -11,
      "y": 20,
      "z": -9,
      "name": "Rock_Slate"
    },
    {
      "x": -11,
      "y": 21,
      "z": -9,
      "name": "Rock_Slate"
    },
    {
      "x": -11,
      "y": 22,
      "z": -9,
      "name": "Rock_Slate"
    },
    {
      "x": -11,
      "y": 23,
      "z": -9,
      "name": "Rock_Slate"
    },
    {
      "x": -11,
      "y": 24,
      "z": -9,
      "name": "Rock_Slate"
    },
    {
      "x": -11,
      "y": 25,
      "z": -9,
      "name": "Soil_Ash"
    },
    {
      "x": -11,
      "y": 26,
      "z": -9,
      "name": "Rock_Slate"
    },
    {
      "x": -11,
      "y": 27,
      "z": -9,
      "name": "Soil_Ash"
    },
    {
      "x": -11,
      "y": 28,
      "z": -9,
      "name": "Soil_Slate_Gravel"
    },
    {
      "x": -11,
      "y": 16,
      "z": -8,
      "name": "Rock_Slate"
    },
    {
      "x": -11,
      "y": 17,
      "z": -8,
      "name": "Rock_Slate"
    },
    {
      "x": -11,
      "y": 18,
      "z": -8,
      "name": "Rock_Slate"
    },
    {
      "x": -11,
      "y": 19,
      "z": -8,
      "name": "Rock_Slate"
    },
    {
      "x": -11,
      "y": 20,
      "z": -8,
      "name": "Rock_Slate"
    },
    {
      "x": -11,
      "y": 21,
      "z": -8,
      "name": "Rock_Slate"
    },
    {
      "x": -11,
      "y": 22,
      "z": -8,
      "name": "Rock_Slate"
    },
    {
      "x": -11,
      "y": 23,
      "z": -8,
      "name": "Rock_Slate"
    },
    {
      "x": -11,
      "y": 24,
      "z": -8,
      "name": "Rock_Slate"
    },
    {
      "x": -11,
      "y": 25,
      "z": -8,
      "name": "Soil_Ash"
    },
    {
      "x": -11,
      "y": 26,
      "z": -8,
      "name": "Soil_Slate_Gravel"
    },
    {
      "x": -11,
      "y": 27,
      "z": -8,
      "name": "Soil_Ash"
    },
    {
      "x": -11,
      "y": 28,
      "z": -8,
      "name": "Rock_Slate"
    },
    {
      "x": -11,
      "y": 15,
      "z": -7,
      "name": "Plant_Bush_Dead_Hanging"
    },
    {
      "x": -11,
      "y": 16,
      "z": -7,
      "name": "Rock_Slate"
    },
    {
      "x": -11,
      "y": 17,
      "z": -7,
      "name": "Rock_Slate"
    },
    {
      "x": -11,
      "y": 18,
      "z": -7,
      "name": "Rock_Slate"
    },
    {
      "x": -11,
      "y": 19,
      "z": -7,
      "name": "Rock_Slate"
    },
    {
      "x": -11,
      "y": 20,
      "z": -7,
      "name": "Rock_Slate"
    },
    {
      "x": -11,
      "y": 21,
      "z": -7,
      "name": "Rock_Slate"
    },
    {
      "x": -11,
      "y": 22,
      "z": -7,
      "name": "Rock_Slate"
    },
    {
      "x": -11,
      "y": 23,
      "z": -7,
      "name": "Rock_Slate"
    },
    {
      "x": -11,
      "y": 24,
      "z": -7,
      "name": "Rock_Slate"
    },
    {
      "x": -11,
      "y": 25,
      "z": -7,
      "name": "Soil_Ash"
    },
    {
      "x": -11,
      "y": 26,
      "z": -7,
      "name": "Soil_Slate_Gravel"
    },
    {
      "x": -11,
      "y": 27,
      "z": -7,
      "name": "Soil_Ash"
    },
    {
      "x": -11,
      "y": 28,
      "z": -7,
      "name": "Soil_Ash"
    },
    {
      "x": -11,
      "y": 15,
      "z": -6,
      "name": "Rock_Slate"
    },
    {
      "x": -11,
      "y": 16,
      "z": -6,
      "name": "Rock_Slate"
    },
    {
      "x": -11,
      "y": 17,
      "z": -6,
      "name": "Rock_Slate"
    },
    {
      "x": -11,
      "y": 18,
      "z": -6,
      "name": "Rock_Slate"
    },
    {
      "x": -11,
      "y": 19,
      "z": -6,
      "name": "Rock_Slate"
    },
    {
      "x": -11,
      "y": 20,
      "z": -6,
      "name": "Rock_Slate"
    },
    {
      "x": -11,
      "y": 21,
      "z": -6,
      "name": "Rock_Slate"
    },
    {
      "x": -11,
      "y": 22,
      "z": -6,
      "name": "Rock_Slate"
    },
    {
      "x": -11,
      "y": 23,
      "z": -6,
      "name": "Rock_Slate"
    },
    {
      "x": -11,
      "y": 24,
      "z": -6,
      "name": "Soil_Ash"
    },
    {
      "x": -11,
      "y": 25,
      "z": -6,
      "name": "Soil_Ash"
    },
    {
      "x": -11,
      "y": 26,
      "z": -6,
      "name": "Soil_Ash"
    },
    {
      "x": -11,
      "y": 27,
      "z": -6,
      "name": "Soil_Ash"
    },
    {
      "x": -11,
      "y": 28,
      "z": -6,
      "name": "Soil_Ash"
    },
    {
      "x": -11,
      "y": 16,
      "z": -5,
      "name": "Rock_Slate"
    },
    {
      "x": -11,
      "y": 17,
      "z": -5,
      "name": "Rock_Slate"
    },
    {
      "x": -11,
      "y": 18,
      "z": -5,
      "name": "Rock_Slate"
    },
    {
      "x": -11,
      "y": 19,
      "z": -5,
      "name": "Rock_Slate"
    },
    {
      "x": -11,
      "y": 20,
      "z": -5,
      "name": "Rock_Slate"
    },
    {
      "x": -11,
      "y": 21,
      "z": -5,
      "name": "Rock_Slate"
    },
    {
      "x": -11,
      "y": 22,
      "z": -5,
      "name": "Rock_Slate"
    },
    {
      "x": -11,
      "y": 23,
      "z": -5,
      "name": "Rock_Slate"
    },
    {
      "x": -11,
      "y": 24,
      "z": -5,
      "name": "Rock_Slate"
    },
    {
      "x": -11,
      "y": 25,
      "z": -5,
      "name": "Soil_Ash"
    },
    {
      "x": -11,
      "y": 26,
      "z": -5,
      "name": "Soil_Slate_Gravel"
    },
    {
      "x": -11,
      "y": 27,
      "z": -5,
      "name": "Soil_Ash"
    },
    {
      "x": -11,
      "y": 28,
      "z": -5,
      "name": "Soil_Ash"
    },
    {
      "x": -11,
      "y": 16,
      "z": -4,
      "name": "Rock_Slate"
    },
    {
      "x": -11,
      "y": 17,
      "z": -4,
      "name": "Rock_Slate"
    },
    {
      "x": -11,
      "y": 18,
      "z": -4,
      "name": "Rock_Slate"
    },
    {
      "x": -11,
      "y": 19,
      "z": -4,
      "name": "Rock_Slate"
    },
    {
      "x": -11,
      "y": 20,
      "z": -4,
      "name": "Rock_Slate"
    },
    {
      "x": -11,
      "y": 21,
      "z": -4,
      "name": "Rock_Slate"
    },
    {
      "x": -11,
      "y": 22,
      "z": -4,
      "name": "Rock_Slate"
    },
    {
      "x": -11,
      "y": 23,
      "z": -4,
      "name": "Rock_Slate"
    },
    {
      "x": -11,
      "y": 24,
      "z": -4,
      "name": "Soil_Ash"
    },
    {
      "x": -11,
      "y": 25,
      "z": -4,
      "name": "Rock_Slate"
    },
    {
      "x": -11,
      "y": 26,
      "z": -4,
      "name": "Soil_Ash"
    },
    {
      "x": -11,
      "y": 27,
      "z": -4,
      "name": "Soil_Ash"
    },
    {
      "x": -11,
      "y": 28,
      "z": -4,
      "name": "Plant_Crop_Mushroom_Glowing_Purple"
    },
    {
      "x": -11,
      "y": 15,
      "z": -3,
      "name": "Rock_Slate"
    },
    {
      "x": -11,
      "y": 16,
      "z": -3,
      "name": "Rock_Slate"
    },
    {
      "x": -11,
      "y": 17,
      "z": -3,
      "name": "Rock_Slate"
    },
    {
      "x": -11,
      "y": 18,
      "z": -3,
      "name": "Rock_Slate"
    },
    {
      "x": -11,
      "y": 19,
      "z": -3,
      "name": "Rock_Slate"
    },
    {
      "x": -11,
      "y": 20,
      "z": -3,
      "name": "Rock_Slate"
    },
    {
      "x": -11,
      "y": 21,
      "z": -3,
      "name": "Rock_Slate"
    },
    {
      "x": -11,
      "y": 22,
      "z": -3,
      "name": "Rock_Slate"
    },
    {
      "x": -11,
      "y": 23,
      "z": -3,
      "name": "Rock_Slate"
    },
    {
      "x": -11,
      "y": 24,
      "z": -3,
      "name": "Soil_Ash"
    },
    {
      "x": -11,
      "y": 25,
      "z": -3,
      "name": "Rock_Slate"
    },
    {
      "x": -11,
      "y": 26,
      "z": -3,
      "name": "Soil_Ash"
    },
    {
      "x": -11,
      "y": 27,
      "z": -3,
      "name": "Soil_Ash"
    },
    {
      "x": -11,
      "y": 16,
      "z": -2,
      "name": "Rock_Slate"
    },
    {
      "x": -11,
      "y": 17,
      "z": -2,
      "name": "Rock_Slate"
    },
    {
      "x": -11,
      "y": 18,
      "z": -2,
      "name": "Rock_Slate"
    },
    {
      "x": -11,
      "y": 19,
      "z": -2,
      "name": "Rock_Slate"
    },
    {
      "x": -11,
      "y": 20,
      "z": -2,
      "name": "Rock_Slate"
    },
    {
      "x": -11,
      "y": 21,
      "z": -2,
      "name": "Rock_Slate"
    },
    {
      "x": -11,
      "y": 22,
      "z": -2,
      "name": "Rock_Slate"
    },
    {
      "x": -11,
      "y": 23,
      "z": -2,
      "name": "Rock_Slate"
    },
    {
      "x": -11,
      "y": 24,
      "z": -2,
      "name": "Soil_Ash"
    },
    {
      "x": -11,
      "y": 25,
      "z": -2,
      "name": "Soil_Ash"
    },
    {
      "x": -11,
      "y": 26,
      "z": -2,
      "name": "Soil_Ash"
    },
    {
      "x": -11,
      "y": 27,
      "z": -2,
      "name": "Soil_Ash"
    },
    {
      "x": -11,
      "y": 17,
      "z": -1,
      "name": "Rock_Slate"
    },
    {
      "x": -11,
      "y": 18,
      "z": -1,
      "name": "Rock_Slate"
    },
    {
      "x": -11,
      "y": 19,
      "z": -1,
      "name": "Rock_Slate"
    },
    {
      "x": -11,
      "y": 20,
      "z": -1,
      "name": "Rock_Slate"
    },
    {
      "x": -11,
      "y": 21,
      "z": -1,
      "name": "Rock_Slate"
    },
    {
      "x": -11,
      "y": 22,
      "z": -1,
      "name": "Rock_Slate"
    },
    {
      "x": -11,
      "y": 23,
      "z": -1,
      "name": "Rock_Slate"
    },
    {
      "x": -11,
      "y": 24,
      "z": -1,
      "name": "Rock_Slate"
    },
    {
      "x": -11,
      "y": 25,
      "z": -1,
      "name": "Soil_Ash"
    },
    {
      "x": -11,
      "y": 26,
      "z": -1,
      "name": "Rock_Slate"
    },
    {
      "x": -11,
      "y": 27,
      "z": -1,
      "name": "Soil_Ash"
    },
    {
      "x": -11,
      "y": 16,
      "z": 0,
      "name": "Rock_Slate"
    },
    {
      "x": -11,
      "y": 17,
      "z": 0,
      "name": "Rock_Slate"
    },
    {
      "x": -11,
      "y": 18,
      "z": 0,
      "name": "Rock_Slate"
    },
    {
      "x": -11,
      "y": 19,
      "z": 0,
      "name": "Rock_Slate"
    },
    {
      "x": -11,
      "y": 20,
      "z": 0,
      "name": "Rock_Slate"
    },
    {
      "x": -11,
      "y": 21,
      "z": 0,
      "name": "Rock_Slate"
    },
    {
      "x": -11,
      "y": 22,
      "z": 0,
      "name": "Ore_Cobalt_Slate"
    },
    {
      "x": -11,
      "y": 23,
      "z": 0,
      "name": "Soil_Ash"
    },
    {
      "x": -11,
      "y": 24,
      "z": 0,
      "name": "Rock_Slate"
    },
    {
      "x": -11,
      "y": 25,
      "z": 0,
      "name": "Soil_Ash"
    },
    {
      "x": -11,
      "y": 26,
      "z": 0,
      "name": "Soil_Ash"
    },
    {
      "x": -11,
      "y": 27,
      "z": 0,
      "name": "Soil_Ash"
    },
    {
      "x": -11,
      "y": 17,
      "z": 1,
      "name": "Rock_Slate"
    },
    {
      "x": -11,
      "y": 18,
      "z": 1,
      "name": "Rock_Slate"
    },
    {
      "x": -11,
      "y": 19,
      "z": 1,
      "name": "Rock_Slate"
    },
    {
      "x": -11,
      "y": 20,
      "z": 1,
      "name": "Rock_Slate"
    },
    {
      "x": -11,
      "y": 21,
      "z": 1,
      "name": "Rock_Slate"
    },
    {
      "x": -11,
      "y": 22,
      "z": 1,
      "name": "Ore_Cobalt_Slate"
    },
    {
      "x": -11,
      "y": 23,
      "z": 1,
      "name": "Soil_Ash"
    },
    {
      "x": -11,
      "y": 24,
      "z": 1,
      "name": "Soil_Slate_Gravel"
    },
    {
      "x": -11,
      "y": 25,
      "z": 1,
      "name": "Rock_Slate"
    },
    {
      "x": -11,
      "y": 26,
      "z": 1,
      "name": "Soil_Ash"
    },
    {
      "x": -11,
      "y": 27,
      "z": 1,
      "name": "Soil_Ash"
    },
    {
      "x": -11,
      "y": 18,
      "z": 2,
      "name": "Rock_Slate"
    },
    {
      "x": -11,
      "y": 19,
      "z": 2,
      "name": "Rock_Slate"
    },
    {
      "x": -11,
      "y": 20,
      "z": 2,
      "name": "Rock_Slate"
    },
    {
      "x": -11,
      "y": 21,
      "z": 2,
      "name": "Rock_Slate"
    },
    {
      "x": -11,
      "y": 22,
      "z": 2,
      "name": "Ore_Cobalt_Slate_Cracked"
    },
    {
      "x": -11,
      "y": 23,
      "z": 2,
      "name": "Soil_Ash"
    },
    {
      "x": -11,
      "y": 24,
      "z": 2,
      "name": "Soil_Ash"
    },
    {
      "x": -11,
      "y": 25,
      "z": 2,
      "name": "Rock_Slate"
    },
    {
      "x": -11,
      "y": 26,
      "z": 2,
      "name": "Rock_Slate"
    },
    {
      "x": -11,
      "y": 20,
      "z": 3,
      "name": "Ore_Cobalt_Slate_Cracked"
    },
    {
      "x": -11,
      "y": 21,
      "z": 3,
      "name": "Rock_Slate"
    },
    {
      "x": -11,
      "y": 22,
      "z": 3,
      "name": "Rock_Slate"
    },
    {
      "x": -11,
      "y": 23,
      "z": 3,
      "name": "Ore_Cobalt_Slate_Cracked"
    },
    {
      "x": -11,
      "y": 24,
      "z": 3,
      "name": "Rock_Slate"
    },
    {
      "x": -11,
      "y": 25,
      "z": 3,
      "name": "Soil_Ash"
    },
    {
      "x": -11,
      "y": 26,
      "z": 3,
      "name": "Soil_Slate_Gravel"
    },
    {
      "x": -11,
      "y": 27,
      "z": 3,
      "name": "Plant_Flower_Bushy_Violet"
    },
    {
      "x": -11,
      "y": 24,
      "z": 4,
      "name": "Rock_Slate"
    },
    {
      "x": -11,
      "y": 25,
      "z": 4,
      "name": "Soil_Ash"
    },
    {
      "x": -11,
      "y": 26,
      "z": 4,
      "name": "Plant_Flower_Bushy_Purple"
    },
    {
      "x": -11,
      "y": 24,
      "z": 5,
      "name": "Rock_Slate"
    },
    {
      "x": -11,
      "y": 25,
      "z": 5,
      "name": "Rock_Slate"
    },
    {
      "x": -11,
      "y": 26,
      "z": 5,
      "name": "Rock_Slate"
    },
    {
      "x": -11,
      "y": 27,
      "z": 5,
      "name": "Plant_Coral_Model_Pink"
    },
    {
      "x": -11,
      "y": 21,
      "z": 6,
      "name": "Plant_Crop_Mushroom_Block_Purple_Mycelium"
    },
    {
      "x": -11,
      "y": 22,
      "z": 6,
      "name": "Plant_Crop_Mushroom_Block_Purple_Mycelium"
    },
    {
      "x": -11,
      "y": 23,
      "z": 6,
      "name": "Rock_Slate"
    },
    {
      "x": -11,
      "y": 24,
      "z": 6,
      "name": "Soil_Ash"
    },
    {
      "x": -11,
      "y": 25,
      "z": 6,
      "name": "Rock_Slate"
    },
    {
      "x": -11,
      "y": 26,
      "z": 6,
      "name": "Soil_Ash"
    },
    {
      "x": -11,
      "y": 27,
      "z": 6,
      "name": "Soil_Ash"
    },
    {
      "x": -11,
      "y": 22,
      "z": 7,
      "name": "Rock_Slate"
    },
    {
      "x": -11,
      "y": 23,
      "z": 7,
      "name": "Rock_Slate"
    },
    {
      "x": -11,
      "y": 24,
      "z": 7,
      "name": "Rock_Slate"
    },
    {
      "x": -11,
      "y": 25,
      "z": 7,
      "name": "Rock_Slate"
    },
    {
      "x": -11,
      "y": 26,
      "z": 7,
      "name": "Rock_Slate"
    },
    {
      "x": -11,
      "y": 27,
      "z": 7,
      "name": "Soil_Ash"
    },
    {
      "x": -11,
      "y": 28,
      "z": 7,
      "name": "Soil_Ash"
    },
    {
      "x": -11,
      "y": 20,
      "z": 8,
      "name": "Rock_Slate"
    },
    {
      "x": -11,
      "y": 21,
      "z": 8,
      "name": "Rock_Slate"
    },
    {
      "x": -11,
      "y": 22,
      "z": 8,
      "name": "Rock_Slate"
    },
    {
      "x": -11,
      "y": 23,
      "z": 8,
      "name": "Rock_Slate"
    },
    {
      "x": -11,
      "y": 24,
      "z": 8,
      "name": "Rock_Slate"
    },
    {
      "x": -11,
      "y": 25,
      "z": 8,
      "name": "Soil_Ash"
    },
    {
      "x": -11,
      "y": 26,
      "z": 8,
      "name": "Rock_Slate"
    },
    {
      "x": -11,
      "y": 27,
      "z": 8,
      "name": "Soil_Ash"
    },
    {
      "x": -11,
      "y": 28,
      "z": 8,
      "name": "Rock_Slate"
    },
    {
      "x": -11,
      "y": 29,
      "z": 8,
      "name": "Soil_Ash"
    },
    {
      "x": -11,
      "y": 18,
      "z": 9,
      "name": "Plant_Crop_Mushroom_Block_Purple_Mycelium"
    },
    {
      "x": -11,
      "y": 19,
      "z": 9,
      "name": "Ore_Cobalt_Slate_Cracked"
    },
    {
      "x": -11,
      "y": 20,
      "z": 9,
      "name": "Rock_Slate"
    },
    {
      "x": -11,
      "y": 21,
      "z": 9,
      "name": "Rock_Slate"
    },
    {
      "x": -11,
      "y": 22,
      "z": 9,
      "name": "Rock_Slate"
    },
    {
      "x": -11,
      "y": 23,
      "z": 9,
      "name": "Rock_Slate"
    },
    {
      "x": -11,
      "y": 24,
      "z": 9,
      "name": "Rock_Slate"
    },
    {
      "x": -11,
      "y": 25,
      "z": 9,
      "name": "Rock_Slate"
    },
    {
      "x": -11,
      "y": 26,
      "z": 9,
      "name": "Soil_Ash"
    },
    {
      "x": -11,
      "y": 27,
      "z": 9,
      "name": "Soil_Ash"
    },
    {
      "x": -11,
      "y": 28,
      "z": 9,
      "name": "Soil_Ash"
    },
    {
      "x": -11,
      "y": 29,
      "z": 9,
      "name": "Rock_Slate"
    },
    {
      "x": -11,
      "y": 30,
      "z": 9,
      "name": "Soil_Ash"
    },
    {
      "x": -11,
      "y": 19,
      "z": 10,
      "name": "Rock_Slate"
    },
    {
      "x": -11,
      "y": 20,
      "z": 10,
      "name": "Ore_Cobalt_Slate_Cracked"
    },
    {
      "x": -11,
      "y": 21,
      "z": 10,
      "name": "Rock_Slate"
    },
    {
      "x": -11,
      "y": 22,
      "z": 10,
      "name": "Rock_Slate"
    },
    {
      "x": -11,
      "y": 23,
      "z": 10,
      "name": "Rock_Slate"
    },
    {
      "x": -11,
      "y": 24,
      "z": 10,
      "name": "Rock_Slate"
    },
    {
      "x": -11,
      "y": 25,
      "z": 10,
      "name": "Rock_Slate"
    },
    {
      "x": -11,
      "y": 26,
      "z": 10,
      "name": "Soil_Ash"
    },
    {
      "x": -11,
      "y": 27,
      "z": 10,
      "name": "Soil_Slate_Gravel"
    },
    {
      "x": -11,
      "y": 28,
      "z": 10,
      "name": "Rock_Slate"
    },
    {
      "x": -11,
      "y": 29,
      "z": 10,
      "name": "Plant_Coral_Block_Violet"
    },
    {
      "x": -11,
      "y": 30,
      "z": 10,
      "name": "Plant_Coral_Bush_Violet"
    },
    {
      "x": -11,
      "y": 18,
      "z": 11,
      "name": "Plant_Crop_Mushroom_Block_Purple_Mycelium"
    },
    {
      "x": -11,
      "y": 19,
      "z": 11,
      "name": "Rock_Slate"
    },
    {
      "x": -11,
      "y": 20,
      "z": 11,
      "name": "Rock_Slate"
    },
    {
      "x": -11,
      "y": 21,
      "z": 11,
      "name": "Rock_Slate"
    },
    {
      "x": -11,
      "y": 22,
      "z": 11,
      "name": "Rock_Slate"
    },
    {
      "x": -11,
      "y": 23,
      "z": 11,
      "name": "Rock_Slate"
    },
    {
      "x": -11,
      "y": 24,
      "z": 11,
      "name": "Rock_Slate"
    },
    {
      "x": -11,
      "y": 25,
      "z": 11,
      "name": "Rock_Slate"
    },
    {
      "x": -11,
      "y": 26,
      "z": 11,
      "name": "Soil_Slate_Gravel"
    },
    {
      "x": -11,
      "y": 27,
      "z": 11,
      "name": "Soil_Slate_Gravel"
    },
    {
      "x": -11,
      "y": 28,
      "z": 11,
      "name": "Soil_Slate_Gravel"
    },
    {
      "x": -11,
      "y": 29,
      "z": 11,
      "name": "Soil_Ash"
    },
    {
      "x": -11,
      "y": 30,
      "z": 11,
      "name": "Soil_Ash"
    },
    {
      "x": -11,
      "y": 20,
      "z": 12,
      "name": "Rock_Slate"
    },
    {
      "x": -11,
      "y": 21,
      "z": 12,
      "name": "Rock_Slate"
    },
    {
      "x": -11,
      "y": 22,
      "z": 12,
      "name": "Rock_Slate"
    },
    {
      "x": -11,
      "y": 23,
      "z": 12,
      "name": "Rock_Slate"
    },
    {
      "x": -11,
      "y": 24,
      "z": 12,
      "name": "Rock_Slate"
    },
    {
      "x": -11,
      "y": 25,
      "z": 12,
      "name": "Rock_Slate"
    },
    {
      "x": -11,
      "y": 26,
      "z": 12,
      "name": "Soil_Slate_Gravel"
    },
    {
      "x": -11,
      "y": 27,
      "z": 12,
      "name": "Rock_Slate"
    },
    {
      "x": -11,
      "y": 28,
      "z": 12,
      "name": "Rock_Slate"
    },
    {
      "x": -11,
      "y": 29,
      "z": 12,
      "name": "Soil_Ash"
    },
    {
      "x": -11,
      "y": 30,
      "z": 12,
      "name": "Soil_Ash"
    },
    {
      "x": -11,
      "y": 23,
      "z": 13,
      "name": "Rock_Slate"
    },
    {
      "x": -11,
      "y": 24,
      "z": 13,
      "name": "Rock_Slate"
    },
    {
      "x": -11,
      "y": 25,
      "z": 13,
      "name": "Rock_Slate"
    },
    {
      "x": -11,
      "y": 26,
      "z": 13,
      "name": "Rock_Slate"
    },
    {
      "x": -11,
      "y": 27,
      "z": 13,
      "name": "Soil_Ash"
    },
    {
      "x": -11,
      "y": 28,
      "z": 13,
      "name": "Rock_Slate"
    },
    {
      "x": -11,
      "y": 29,
      "z": 13,
      "name": "Rock_Slate"
    },
    {
      "x": -10,
      "y": 21,
      "z": -14,
      "name": "Rock_Slate"
    },
    {
      "x": -10,
      "y": 22,
      "z": -14,
      "name": "Rock_Slate"
    },
    {
      "x": -10,
      "y": 23,
      "z": -14,
      "name": "Rock_Slate"
    },
    {
      "x": -10,
      "y": 24,
      "z": -14,
      "name": "Rock_Slate"
    },
    {
      "x": -10,
      "y": 25,
      "z": -14,
      "name": "Rock_Slate"
    },
    {
      "x": -10,
      "y": 18,
      "z": -13,
      "name": "Rock_Slate"
    },
    {
      "x": -10,
      "y": 19,
      "z": -13,
      "name": "Rock_Slate"
    },
    {
      "x": -10,
      "y": 20,
      "z": -13,
      "name": "Rock_Slate"
    },
    {
      "x": -10,
      "y": 21,
      "z": -13,
      "name": "Rock_Slate"
    },
    {
      "x": -10,
      "y": 22,
      "z": -13,
      "name": "Rock_Slate"
    },
    {
      "x": -10,
      "y": 23,
      "z": -13,
      "name": "Rock_Slate"
    },
    {
      "x": -10,
      "y": 24,
      "z": -13,
      "name": "Rock_Slate"
    },
    {
      "x": -10,
      "y": 25,
      "z": -13,
      "name": "Rock_Slate"
    },
    {
      "x": -10,
      "y": 26,
      "z": -13,
      "name": "Soil_Ash"
    },
    {
      "x": -10,
      "y": 17,
      "z": -12,
      "name": "Plant_Bush_Dead_Hanging"
    },
    {
      "x": -10,
      "y": 18,
      "z": -12,
      "name": "Plant_Bush_Dead_Hanging"
    },
    {
      "x": -10,
      "y": 19,
      "z": -12,
      "name": "Rock_Slate"
    },
    {
      "x": -10,
      "y": 20,
      "z": -12,
      "name": "Rock_Slate"
    },
    {
      "x": -10,
      "y": 21,
      "z": -12,
      "name": "Rock_Slate"
    },
    {
      "x": -10,
      "y": 22,
      "z": -12,
      "name": "Rock_Slate"
    },
    {
      "x": -10,
      "y": 23,
      "z": -12,
      "name": "Rock_Slate"
    },
    {
      "x": -10,
      "y": 24,
      "z": -12,
      "name": "Rock_Slate"
    },
    {
      "x": -10,
      "y": 25,
      "z": -12,
      "name": "Rock_Slate"
    },
    {
      "x": -10,
      "y": 26,
      "z": -12,
      "name": "Soil_Ash"
    },
    {
      "x": -10,
      "y": 27,
      "z": -12,
      "name": "Soil_Slate_Gravel"
    },
    {
      "x": -10,
      "y": 19,
      "z": -11,
      "name": "Rock_Slate"
    },
    {
      "x": -10,
      "y": 20,
      "z": -11,
      "name": "Rock_Slate"
    },
    {
      "x": -10,
      "y": 21,
      "z": -11,
      "name": "Rock_Slate"
    },
    {
      "x": -10,
      "y": 22,
      "z": -11,
      "name": "Rock_Slate"
    },
    {
      "x": -10,
      "y": 23,
      "z": -11,
      "name": "Rock_Slate"
    },
    {
      "x": -10,
      "y": 24,
      "z": -11,
      "name": "Rock_Slate"
    },
    {
      "x": -10,
      "y": 25,
      "z": -11,
      "name": "Rock_Slate"
    },
    {
      "x": -10,
      "y": 26,
      "z": -11,
      "name": "Soil_Ash"
    },
    {
      "x": -10,
      "y": 27,
      "z": -11,
      "name": "Soil_Ash"
    },
    {
      "x": -10,
      "y": 28,
      "z": -11,
      "name": "Soil_Ash"
    },
    {
      "x": -10,
      "y": 18,
      "z": -10,
      "name": "Rock_Slate"
    },
    {
      "x": -10,
      "y": 19,
      "z": -10,
      "name": "Rock_Slate"
    },
    {
      "x": -10,
      "y": 20,
      "z": -10,
      "name": "Rock_Slate"
    },
    {
      "x": -10,
      "y": 21,
      "z": -10,
      "name": "Rock_Slate"
    },
    {
      "x": -10,
      "y": 22,
      "z": -10,
      "name": "Rock_Slate"
    },
    {
      "x": -10,
      "y": 23,
      "z": -10,
      "name": "Rock_Slate"
    },
    {
      "x": -10,
      "y": 24,
      "z": -10,
      "name": "Rock_Slate"
    },
    {
      "x": -10,
      "y": 25,
      "z": -10,
      "name": "Soil_Ash"
    },
    {
      "x": -10,
      "y": 26,
      "z": -10,
      "name": "Soil_Ash"
    },
    {
      "x": -10,
      "y": 27,
      "z": -10,
      "name": "Soil_Ash"
    },
    {
      "x": -10,
      "y": 28,
      "z": -10,
      "name": "Rock_Slate"
    },
    {
      "x": -10,
      "y": 29,
      "z": -10,
      "name": "Plant_Coral_Bush_Purple"
    },
    {
      "x": -10,
      "y": 18,
      "z": -9,
      "name": "Rock_Slate"
    },
    {
      "x": -10,
      "y": 19,
      "z": -9,
      "name": "Rock_Slate"
    },
    {
      "x": -10,
      "y": 20,
      "z": -9,
      "name": "Rock_Slate"
    },
    {
      "x": -10,
      "y": 21,
      "z": -9,
      "name": "Rock_Slate"
    },
    {
      "x": -10,
      "y": 22,
      "z": -9,
      "name": "Rock_Slate"
    },
    {
      "x": -10,
      "y": 23,
      "z": -9,
      "name": "Rock_Slate"
    },
    {
      "x": -10,
      "y": 24,
      "z": -9,
      "name": "Rock_Slate"
    },
    {
      "x": -10,
      "y": 25,
      "z": -9,
      "name": "Rock_Slate"
    },
    {
      "x": -10,
      "y": 26,
      "z": -9,
      "name": "Soil_Slate_Gravel"
    },
    {
      "x": -10,
      "y": 27,
      "z": -9,
      "name": "Soil_Ash"
    },
    {
      "x": -10,
      "y": 28,
      "z": -9,
      "name": "Soil_Ash"
    },
    {
      "x": -10,
      "y": 29,
      "z": -9,
      "name": "Plant_Coral_Model_Purple"
    },
    {
      "x": -10,
      "y": 15,
      "z": -8,
      "name": "Plant_Crop_Mushroom_Block_Purple_Mycelium"
    },
    {
      "x": -10,
      "y": 16,
      "z": -8,
      "name": "Plant_Bush_Dead_Hanging"
    },
    {
      "x": -10,
      "y": 17,
      "z": -8,
      "name": "Rock_Slate"
    },
    {
      "x": -10,
      "y": 18,
      "z": -8,
      "name": "Rock_Slate"
    },
    {
      "x": -10,
      "y": 19,
      "z": -8,
      "name": "Rock_Slate"
    },
    {
      "x": -10,
      "y": 20,
      "z": -8,
      "name": "Rock_Slate"
    },
    {
      "x": -10,
      "y": 21,
      "z": -8,
      "name": "Rock_Slate"
    },
    {
      "x": -10,
      "y": 22,
      "z": -8,
      "name": "Rock_Slate"
    },
    {
      "x": -10,
      "y": 23,
      "z": -8,
      "name": "Rock_Slate"
    },
    {
      "x": -10,
      "y": 24,
      "z": -8,
      "name": "Soil_Slate_Gravel"
    },
    {
      "x": -10,
      "y": 25,
      "z": -8,
      "name": "Soil_Slate_Gravel"
    },
    {
      "x": -10,
      "y": 26,
      "z": -8,
      "name": "Soil_Ash"
    },
    {
      "x": -10,
      "y": 27,
      "z": -8,
      "name": "Soil_Ash"
    },
    {
      "x": -10,
      "y": 28,
      "z": -8,
      "name": "Soil_Slate_Gravel"
    },
    {
      "x": -10,
      "y": 17,
      "z": -7,
      "name": "Rock_Slate"
    },
    {
      "x": -10,
      "y": 18,
      "z": -7,
      "name": "Rock_Slate"
    },
    {
      "x": -10,
      "y": 19,
      "z": -7,
      "name": "Rock_Slate"
    },
    {
      "x": -10,
      "y": 20,
      "z": -7,
      "name": "Rock_Slate"
    },
    {
      "x": -10,
      "y": 21,
      "z": -7,
      "name": "Rock_Slate"
    },
    {
      "x": -10,
      "y": 22,
      "z": -7,
      "name": "Rock_Slate"
    },
    {
      "x": -10,
      "y": 23,
      "z": -7,
      "name": "Rock_Slate"
    },
    {
      "x": -10,
      "y": 24,
      "z": -7,
      "name": "Soil_Ash"
    },
    {
      "x": -10,
      "y": 25,
      "z": -7,
      "name": "Soil_Ash"
    },
    {
      "x": -10,
      "y": 26,
      "z": -7,
      "name": "Soil_Ash"
    },
    {
      "x": -10,
      "y": 27,
      "z": -7,
      "name": "Soil_Ash"
    },
    {
      "x": -10,
      "y": 28,
      "z": -7,
      "name": "Soil_Ash"
    },
    {
      "x": -10,
      "y": 16,
      "z": -6,
      "name": "Rock_Slate"
    },
    {
      "x": -10,
      "y": 17,
      "z": -6,
      "name": "Rock_Slate"
    },
    {
      "x": -10,
      "y": 18,
      "z": -6,
      "name": "Rock_Slate"
    },
    {
      "x": -10,
      "y": 19,
      "z": -6,
      "name": "Rock_Slate"
    },
    {
      "x": -10,
      "y": 20,
      "z": -6,
      "name": "Rock_Slate"
    },
    {
      "x": -10,
      "y": 21,
      "z": -6,
      "name": "Rock_Slate"
    },
    {
      "x": -10,
      "y": 22,
      "z": -6,
      "name": "Rock_Slate"
    },
    {
      "x": -10,
      "y": 23,
      "z": -6,
      "name": "Rock_Slate"
    },
    {
      "x": -10,
      "y": 24,
      "z": -6,
      "name": "Rock_Slate"
    },
    {
      "x": -10,
      "y": 25,
      "z": -6,
      "name": "Soil_Slate_Gravel"
    },
    {
      "x": -10,
      "y": 26,
      "z": -6,
      "name": "Soil_Ash"
    },
    {
      "x": -10,
      "y": 27,
      "z": -6,
      "name": "Soil_Ash"
    },
    {
      "x": -10,
      "y": 28,
      "z": -6,
      "name": "Soil_Ash"
    },
    {
      "x": -10,
      "y": 16,
      "z": -5,
      "name": "Rock_Slate"
    },
    {
      "x": -10,
      "y": 17,
      "z": -5,
      "name": "Rock_Slate"
    },
    {
      "x": -10,
      "y": 18,
      "z": -5,
      "name": "Rock_Slate"
    },
    {
      "x": -10,
      "y": 19,
      "z": -5,
      "name": "Rock_Slate"
    },
    {
      "x": -10,
      "y": 20,
      "z": -5,
      "name": "Rock_Slate"
    },
    {
      "x": -10,
      "y": 21,
      "z": -5,
      "name": "Rock_Slate"
    },
    {
      "x": -10,
      "y": 22,
      "z": -5,
      "name": "Rock_Slate"
    },
    {
      "x": -10,
      "y": 23,
      "z": -5,
      "name": "Rock_Slate"
    },
    {
      "x": -10,
      "y": 24,
      "z": -5,
      "name": "Soil_Ash"
    },
    {
      "x": -10,
      "y": 25,
      "z": -5,
      "name": "Soil_Slate_Gravel"
    },
    {
      "x": -10,
      "y": 26,
      "z": -5,
      "name": "Rock_Slate"
    },
    {
      "x": -10,
      "y": 27,
      "z": -5,
      "name": "Rock_Slate"
    },
    {
      "x": -10,
      "y": 28,
      "z": -5,
      "name": "Soil_Slate_Gravel"
    },
    {
      "x": -10,
      "y": 15,
      "z": -4,
      "name": "Rock_Slate"
    },
    {
      "x": -10,
      "y": 16,
      "z": -4,
      "name": "Rock_Slate"
    },
    {
      "x": -10,
      "y": 17,
      "z": -4,
      "name": "Rock_Slate"
    },
    {
      "x": -10,
      "y": 18,
      "z": -4,
      "name": "Rock_Slate"
    },
    {
      "x": -10,
      "y": 19,
      "z": -4,
      "name": "Rock_Slate"
    },
    {
      "x": -10,
      "y": 20,
      "z": -4,
      "name": "Rock_Slate"
    },
    {
      "x": -10,
      "y": 21,
      "z": -4,
      "name": "Rock_Slate"
    },
    {
      "x": -10,
      "y": 22,
      "z": -4,
      "name": "Rock_Slate"
    },
    {
      "x": -10,
      "y": 23,
      "z": -4,
      "name": "Rock_Slate"
    },
    {
      "x": -10,
      "y": 24,
      "z": -4,
      "name": "Soil_Ash"
    },
    {
      "x": -10,
      "y": 25,
      "z": -4,
      "name": "Soil_Ash"
    },
    {
      "x": -10,
      "y": 26,
      "z": -4,
      "name": "Rock_Slate"
    },
    {
      "x": -10,
      "y": 27,
      "z": -4,
      "name": "Soil_Ash"
    },
    {
      "x": -10,
      "y": 14,
      "z": -3,
      "name": "Rock_Slate"
    },
    {
      "x": -10,
      "y": 15,
      "z": -3,
      "name": "Ore_Cobalt_Slate_Cracked"
    },
    {
      "x": -10,
      "y": 16,
      "z": -3,
      "name": "Rock_Slate"
    },
    {
      "x": -10,
      "y": 17,
      "z": -3,
      "name": "Rock_Slate"
    },
    {
      "x": -10,
      "y": 18,
      "z": -3,
      "name": "Rock_Slate"
    },
    {
      "x": -10,
      "y": 19,
      "z": -3,
      "name": "Rock_Slate"
    },
    {
      "x": -10,
      "y": 20,
      "z": -3,
      "name": "Rock_Slate"
    },
    {
      "x": -10,
      "y": 21,
      "z": -3,
      "name": "Rock_Slate"
    },
    {
      "x": -10,
      "y": 22,
      "z": -3,
      "name": "Rock_Slate"
    },
    {
      "x": -10,
      "y": 23,
      "z": -3,
      "name": "Rock_Slate"
    },
    {
      "x": -10,
      "y": 24,
      "z": -3,
      "name": "Soil_Slate_Gravel"
    },
    {
      "x": -10,
      "y": 25,
      "z": -3,
      "name": "Soil_Ash"
    },
    {
      "x": -10,
      "y": 26,
      "z": -3,
      "name": "Soil_Ash"
    },
    {
      "x": -10,
      "y": 27,
      "z": -3,
      "name": "Soil_Ash"
    },
    {
      "x": -10,
      "y": 15,
      "z": -2,
      "name": "Rock_Slate"
    },
    {
      "x": -10,
      "y": 16,
      "z": -2,
      "name": "Ore_Cobalt_Slate_Cracked"
    },
    {
      "x": -10,
      "y": 17,
      "z": -2,
      "name": "Rock_Slate"
    },
    {
      "x": -10,
      "y": 18,
      "z": -2,
      "name": "Rock_Slate"
    },
    {
      "x": -10,
      "y": 19,
      "z": -2,
      "name": "Rock_Slate"
    },
    {
      "x": -10,
      "y": 20,
      "z": -2,
      "name": "Rock_Slate"
    },
    {
      "x": -10,
      "y": 21,
      "z": -2,
      "name": "Rock_Slate"
    },
    {
      "x": -10,
      "y": 22,
      "z": -2,
      "name": "Rock_Slate"
    },
    {
      "x": -10,
      "y": 23,
      "z": -2,
      "name": "Rock_Slate"
    },
    {
      "x": -10,
      "y": 24,
      "z": -2,
      "name": "Soil_Ash"
    },
    {
      "x": -10,
      "y": 25,
      "z": -2,
      "name": "Soil_Ash"
    },
    {
      "x": -10,
      "y": 26,
      "z": -2,
      "name": "Soil_Ash"
    },
    {
      "x": -10,
      "y": 27,
      "z": -2,
      "name": "Soil_Ash"
    },
    {
      "x": -10,
      "y": 16,
      "z": -1,
      "name": "Rock_Slate"
    },
    {
      "x": -10,
      "y": 17,
      "z": -1,
      "name": "Ore_Cobalt_Slate_Cracked"
    },
    {
      "x": -10,
      "y": 18,
      "z": -1,
      "name": "Rock_Slate"
    },
    {
      "x": -10,
      "y": 19,
      "z": -1,
      "name": "Rock_Slate"
    },
    {
      "x": -10,
      "y": 20,
      "z": -1,
      "name": "Rock_Slate"
    },
    {
      "x": -10,
      "y": 21,
      "z": -1,
      "name": "Rock_Slate"
    },
    {
      "x": -10,
      "y": 22,
      "z": -1,
      "name": "Rock_Slate"
    },
    {
      "x": -10,
      "y": 23,
      "z": -1,
      "name": "Soil_Slate_Gravel"
    },
    {
      "x": -10,
      "y": 24,
      "z": -1,
      "name": "Rock_Slate"
    },
    {
      "x": -10,
      "y": 25,
      "z": -1,
      "name": "Soil_Ash"
    },
    {
      "x": -10,
      "y": 26,
      "z": -1,
      "name": "Soil_Ash"
    },
    {
      "x": -10,
      "y": 27,
      "z": -1,
      "name": "Soil_Ash"
    },
    {
      "x": -10,
      "y": 15,
      "z": 0,
      "name": "Rock_Slate"
    },
    {
      "x": -10,
      "y": 16,
      "z": 0,
      "name": "Rock_Slate"
    },
    {
      "x": -10,
      "y": 17,
      "z": 0,
      "name": "Rock_Slate"
    },
    {
      "x": -10,
      "y": 18,
      "z": 0,
      "name": "Rock_Slate"
    },
    {
      "x": -10,
      "y": 19,
      "z": 0,
      "name": "Rock_Slate"
    },
    {
      "x": -10,
      "y": 20,
      "z": 0,
      "name": "Rock_Slate"
    },
    {
      "x": -10,
      "y": 21,
      "z": 0,
      "name": "Rock_Slate"
    },
    {
      "x": -10,
      "y": 22,
      "z": 0,
      "name": "Ore_Cobalt_Slate"
    },
    {
      "x": -10,
      "y": 23,
      "z": 0,
      "name": "Soil_Ash"
    },
    {
      "x": -10,
      "y": 24,
      "z": 0,
      "name": "Soil_Ash"
    },
    {
      "x": -10,
      "y": 25,
      "z": 0,
      "name": "Soil_Ash"
    },
    {
      "x": -10,
      "y": 26,
      "z": 0,
      "name": "Soil_Ash"
    },
    {
      "x": -10,
      "y": 27,
      "z": 0,
      "name": "Soil_Ash"
    },
    {
      "x": -10,
      "y": 16,
      "z": 1,
      "name": "Rock_Slate"
    },
    {
      "x": -10,
      "y": 17,
      "z": 1,
      "name": "Rock_Slate"
    },
    {
      "x": -10,
      "y": 18,
      "z": 1,
      "name": "Rock_Slate"
    },
    {
      "x": -10,
      "y": 19,
      "z": 1,
      "name": "Rock_Slate"
    },
    {
      "x": -10,
      "y": 20,
      "z": 1,
      "name": "Rock_Slate"
    },
    {
      "x": -10,
      "y": 21,
      "z": 1,
      "name": "Rock_Slate"
    },
    {
      "x": -10,
      "y": 22,
      "z": 1,
      "name": "Ore_Cobalt_Slate"
    },
    {
      "x": -10,
      "y": 23,
      "z": 1,
      "name": "Ore_Cobalt_Slate"
    },
    {
      "x": -10,
      "y": 24,
      "z": 1,
      "name": "Soil_Slate_Gravel"
    },
    {
      "x": -10,
      "y": 25,
      "z": 1,
      "name": "Soil_Slate_Gravel"
    },
    {
      "x": -10,
      "y": 26,
      "z": 1,
      "name": "Rock_Slate"
    },
    {
      "x": -10,
      "y": 17,
      "z": 2,
      "name": "Ore_Cobalt_Slate_Cracked"
    },
    {
      "x": -10,
      "y": 18,
      "z": 2,
      "name": "Rock_Slate"
    },
    {
      "x": -10,
      "y": 19,
      "z": 2,
      "name": "Rock_Slate"
    },
    {
      "x": -10,
      "y": 20,
      "z": 2,
      "name": "Rock_Slate"
    },
    {
      "x": -10,
      "y": 21,
      "z": 2,
      "name": "Rock_Slate"
    },
    {
      "x": -10,
      "y": 22,
      "z": 2,
      "name": "Ore_Cobalt_Slate_Cracked"
    },
    {
      "x": -10,
      "y": 23,
      "z": 2,
      "name": "Soil_Ash"
    },
    {
      "x": -10,
      "y": 24,
      "z": 2,
      "name": "Rock_Slate"
    },
    {
      "x": -10,
      "y": 25,
      "z": 2,
      "name": "Soil_Ash"
    },
    {
      "x": -10,
      "y": 26,
      "z": 2,
      "name": "Soil_Slate_Gravel"
    },
    {
      "x": -10,
      "y": 27,
      "z": 2,
      "name": "Plant_Coral_Bush_Poisoned"
    },
    {
      "x": -10,
      "y": 19,
      "z": 3,
      "name": "Rock_Slate"
    },
    {
      "x": -10,
      "y": 20,
      "z": 3,
      "name": "Rock_Slate"
    },
    {
      "x": -10,
      "y": 21,
      "z": 3,
      "name": "Rock_Slate"
    },
    {
      "x": -10,
      "y": 22,
      "z": 3,
      "name": "Ore_Cobalt_Slate_Cracked"
    },
    {
      "x": -10,
      "y": 23,
      "z": 3,
      "name": "Soil_Ash"
    },
    {
      "x": -10,
      "y": 24,
      "z": 3,
      "name": "Soil_Ash"
    },
    {
      "x": -10,
      "y": 25,
      "z": 3,
      "name": "Soil_Ash"
    },
    {
      "x": -10,
      "y": 26,
      "z": 3,
      "name": "Soil_Slate_Gravel"
    },
    {
      "x": -10,
      "y": 27,
      "z": 3,
      "name": "Plant_Coral_Bush_Poisoned"
    },
    {
      "x": -10,
      "y": 23,
      "z": 4,
      "name": "Rock_Slate"
    },
    {
      "x": -10,
      "y": 24,
      "z": 4,
      "name": "Rock_Slate"
    },
    {
      "x": -10,
      "y": 25,
      "z": 4,
      "name": "Soil_Ash"
    },
    {
      "x": -10,
      "y": 26,
      "z": 4,
      "name": "Soil_Slate_Gravel"
    },
    {
      "x": -10,
      "y": 22,
      "z": 5,
      "name": "Rock_Slate"
    },
    {
      "x": -10,
      "y": 23,
      "z": 5,
      "name": "Rock_Slate"
    },
    {
      "x": -10,
      "y": 24,
      "z": 5,
      "name": "Soil_Slate_Gravel"
    },
    {
      "x": -10,
      "y": 25,
      "z": 5,
      "name": "Soil_Ash"
    },
    {
      "x": -10,
      "y": 26,
      "z": 5,
      "name": "Rock_Slate"
    },
    {
      "x": -10,
      "y": 27,
      "z": 5,
      "name": "Soil_Ash"
    },
    {
      "x": -10,
      "y": 22,
      "z": 6,
      "name": "Rock_Slate"
    },
    {
      "x": -10,
      "y": 23,
      "z": 6,
      "name": "Rock_Slate"
    },
    {
      "x": -10,
      "y": 24,
      "z": 6,
      "name": "Rock_Slate"
    },
    {
      "x": -10,
      "y": 25,
      "z": 6,
      "name": "Rock_Slate"
    },
    {
      "x": -10,
      "y": 26,
      "z": 6,
      "name": "Soil_Slate_Gravel"
    },
    {
      "x": -10,
      "y": 27,
      "z": 6,
      "name": "Soil_Ash"
    },
    {
      "x": -10,
      "y": 28,
      "z": 6,
      "name": "Rock_Slate"
    },
    {
      "x": -10,
      "y": 29,
      "z": 6,
      "name": "Plant_Coral_Model_Purple"
    },
    {
      "x": -10,
      "y": 21,
      "z": 7,
      "name": "Rock_Slate"
    },
    {
      "x": -10,
      "y": 22,
      "z": 7,
      "name": "Rock_Slate"
    },
    {
      "x": -10,
      "y": 23,
      "z": 7,
      "name": "Rock_Slate"
    },
    {
      "x": -10,
      "y": 24,
      "z": 7,
      "name": "Rock_Slate"
    },
    {
      "x": -10,
      "y": 25,
      "z": 7,
      "name": "Soil_Slate_Gravel"
    },
    {
      "x": -10,
      "y": 26,
      "z": 7,
      "name": "Soil_Ash"
    },
    {
      "x": -10,
      "y": 27,
      "z": 7,
      "name": "Rock_Slate"
    },
    {
      "x": -10,
      "y": 28,
      "z": 7,
      "name": "Soil_Slate_Gravel"
    },
    {
      "x": -10,
      "y": 29,
      "z": 7,
      "name": "Soil_Ash"
    },
    {
      "x": -10,
      "y": 19,
      "z": 8,
      "name": "Plant_Crop_Mushroom_Block_Purple_Mycelium"
    },
    {
      "x": -10,
      "y": 20,
      "z": 8,
      "name": "Plant_Crop_Mushroom_Block_Purple_Mycelium"
    },
    {
      "x": -10,
      "y": 21,
      "z": 8,
      "name": "Rock_Slate"
    },
    {
      "x": -10,
      "y": 22,
      "z": 8,
      "name": "Rock_Slate"
    },
    {
      "x": -10,
      "y": 23,
      "z": 8,
      "name": "Rock_Slate"
    },
    {
      "x": -10,
      "y": 24,
      "z": 8,
      "name": "Rock_Slate"
    },
    {
      "x": -10,
      "y": 25,
      "z": 8,
      "name": "Rock_Slate"
    },
    {
      "x": -10,
      "y": 26,
      "z": 8,
      "name": "Rock_Slate"
    },
    {
      "x": -10,
      "y": 27,
      "z": 8,
      "name": "Soil_Ash"
    },
    {
      "x": -10,
      "y": 28,
      "z": 8,
      "name": "Soil_Ash"
    },
    {
      "x": -10,
      "y": 29,
      "z": 8,
      "name": "Soil_Ash"
    },
    {
      "x": -10,
      "y": 20,
      "z": 9,
      "name": "Rock_Slate"
    },
    {
      "x": -10,
      "y": 21,
      "z": 9,
      "name": "Rock_Slate"
    },
    {
      "x": -10,
      "y": 22,
      "z": 9,
      "name": "Rock_Slate"
    },
    {
      "x": -10,
      "y": 23,
      "z": 9,
      "name": "Rock_Slate"
    },
    {
      "x": -10,
      "y": 24,
      "z": 9,
      "name": "Rock_Slate"
    },
    {
      "x": -10,
      "y": 25,
      "z": 9,
      "name": "Soil_Ash"
    },
    {
      "x": -10,
      "y": 26,
      "z": 9,
      "name": "Soil_Ash"
    },
    {
      "x": -10,
      "y": 27,
      "z": 9,
      "name": "Soil_Ash"
    },
    {
      "x": -10,
      "y": 28,
      "z": 9,
      "name": "Soil_Ash"
    },
    {
      "x": -10,
      "y": 29,
      "z": 9,
      "name": "Soil_Slate_Gravel"
    },
    {
      "x": -10,
      "y": 30,
      "z": 9,
      "name": "Soil_Slate_Gravel"
    },
    {
      "x": -10,
      "y": 31,
      "z": 9,
      "name": "Plant_Coral_Model_Pink"
    },
    {
      "x": -10,
      "y": 19,
      "z": 10,
      "name": "Rock_Slate"
    },
    {
      "x": -10,
      "y": 20,
      "z": 10,
      "name": "Rock_Slate"
    },
    {
      "x": -10,
      "y": 21,
      "z": 10,
      "name": "Rock_Slate"
    },
    {
      "x": -10,
      "y": 22,
      "z": 10,
      "name": "Rock_Slate"
    },
    {
      "x": -10,
      "y": 23,
      "z": 10,
      "name": "Rock_Slate"
    },
    {
      "x": -10,
      "y": 24,
      "z": 10,
      "name": "Rock_Slate"
    },
    {
