{
  "version": 8,
  "blockIdVersion": 11,
  "anchorX": 0,
  "anchorY": 0,
  "anchorZ": 0,
  "blocks": [
    {
      "x": -17,
      "y": 21,
      "z": -11,
      "name": "Soil_Sand_White"
    },
    {
      "x": -17,
      "y": 20,
      "z": -10,
      "name": "Soil_Sand_White"
    },
    {
      "x": -17,
      "y": 23,
      "z": 0,
      "name": "Rock_Sandstone_White"
    },
    {
      "x": -17,
      "y": 24,
      "z": 0,
      "name": "Rock_Sandstone_White"
    },
    {
      "x": -17,
      "y": 22,
      "z": 1,
      "name": "Rock_Sandstone_White"
    },
    {
      "x": -17,
      "y": 23,
      "z": 1,
      "name": "Rock_Sandstone_White"
    },
    {
      "x": -17,
      "y": 24,
      "z": 1,
      "name": "Rock_Sandstone_White"
    },
    {
      "x": -17,
      "y": 25,
      "z": 1,
      "name": "Soil_Sand_White"
    },
    {
      "x": -17,
      "y": 21,
      "z": 2,
      "name": "Rock_Sandstone_White"
    },
    {
      "x": -17,
      "y": 22,
      "z": 2,
      "name": "Rock_Sandstone_White"
    },
    {
      "x": -17,
      "y": 23,
      "z": 2,
      "name": "Rock_Sandstone_White"
    },
    {
      "x": -17,
      "y": 24,
      "z": 2,
      "name": "Rock_Sandstone_White"
    },
    {
      "x": -17,
      "y": 25,
      "z": 2,
      "name": "Soil_Sand_White"
    },
    {
      "x": -17,
      "y": 26,
      "z": 2,
      "name": "Soil_Sand_White"
    },
    {
      "x": -17,
      "y": 22,
      "z": 3,
      "name": "Rock_Sandstone_White"
    },
    {
      "x": -17,
      "y": 23,
      "z": 3,
      "name": "Rock_Sandstone_White"
    },
    {
      "x": -17,
      "y": 24,
      "z": 3,
      "name": "Rock_Sandstone_White"
    },
    {
      "x": -17,
      "y": 25,
      "z": 3,
      "name": "Soil_Sand_White"
    },
    {
      "x": -17,
      "y": 26,
      "z": 3,
      "name": "Soil_Sand_White"
    },
    {
      "x": -17,
      "y": 23,
      "z": 4,
      "name": "Rock_Sandstone_White"
    },
    {
      "x": -17,
      "y": 24,
      "z": 4,
      "name": "Rock_Sandstone_White"
    },
    {
      "x": -17,
      "y": 21,
      "z": 14,
      "name": "Soil_Sand_White"
    },
    {
      "x": -17,
      "y": 18,
      "z": 15,
      "name": "Soil_Sand_White"
    },
    {
      "x": -17,
      "y": 19,
      "z": 15,
      "name": "Plant_Cactus_Flat_2"
    },
    {
      "x": -17,
      "y": 20,
      "z": 15,
      "name": "Rock_Sandstone_White"
    },
    {
      "x": -17,
      "y": 21,
      "z": 15,
      "name": "Rock_Sandstone_White"
    },
    {
      "x": -17,
      "y": 21,
      "z": 16,
      "name": "Soil_Sand_White"
    },
    {
      "x": -16,
      "y": 18,
      "z": -12,
      "name": "Rock_Sandstone_White"
    },
    {
      "x": -16,
      "y": 19,
      "z": -12,
      "name": "Rock_Sandstone_White"
    },
    {
      "x": -16,
      "y": 20,
      "z": -12,
      "name": "Soil_Sand_White"
    },
    {
      "x": -16,
      "y": 21,
      "z": -12,
      "name": "Soil_Sand_White"
    },
    {
      "x": -16,
      "y": 22,
      "z": -12,
      "name": "Plant_Cactus_Flat_2"
    },
    {
      "x": -16,
      "y": 17,
      "z": -11,
      "name": "Rock_Sandstone_White"
    },
    {
      "x": -16,
      "y": 18,
      "z": -11,
      "name": "Rock_Sandstone_White"
    },
    {
      "x": -16,
      "y": 19,
      "z": -11,
      "name": "Rock_Sandstone_White"
    },
    {
      "x": -16,
      "y": 20,
      "z": -11,
      "name": "Rock_Sandstone_White"
    },
    {
      "x": -16,
      "y": 21,
      "z": -11,
      "name": "Soil_Sand_White"
    },
    {
      "x": -16,
      "y": 22,
      "z": -11,
      "name": "Soil_Gravel_Sand_White"
    },
    {
      "x": -16,
      "y": 16,
      "z": -10,
      "name": "Rock_Sandstone_White"
    },
    {
      "x": -16,
      "y": 17,
      "z": -10,
      "name": "Rock_Sandstone_White"
    },
    {
      "x": -16,
      "y": 18,
      "z": -10,
      "name": "Rock_Sandstone_White"
    },
    {
      "x": -16,
      "y": 19,
      "z": -10,
      "name": "Rock_Sandstone_White"
    },
    {
      "x": -16,
      "y": 20,
      "z": -10,
      "name": "Soil_Gravel_Sand_White"
    },
    {
      "x": -16,
      "y": 21,
      "z": -10,
      "name": "Soil_Gravel_Sand_White"
    },
    {
      "x": -16,
      "y": 22,
      "z": -10,
      "name": "Soil_Sand_White"
    },
    {
      "x": -16,
      "y": 23,
      "z": -10,
      "name": "Soil_Sand_White"
    },
    {
      "x": -16,
      "y": 17,
      "z": -9,
      "name": "Rock_Sandstone_White"
    },
    {
      "x": -16,
      "y": 18,
      "z": -9,
      "name": "Rock_Sandstone_White"
    },
    {
      "x": -16,
      "y": 19,
      "z": -9,
      "name": "Rock_Sandstone_White"
    },
    {
      "x": -16,
      "y": 20,
      "z": -9,
      "name": "Rock_Sandstone_White"
    },
    {
      "x": -16,
      "y": 21,
      "z": -9,
      "name": "Soil_Sand_White"
    },
    {
      "x": -16,
      "y": 22,
      "z": -9,
      "name": "Soil_Sand_White"
    },
    {
      "x": -16,
      "y": 23,
      "z": -9,
      "name": "Soil_Sand_White"
    },
    {
      "x": -16,
      "y": 24,
      "z": -9,
      "name": "Soil_Sand_White"
    },
    {
      "x": -16,
      "y": 18,
      "z": -8,
      "name": "Rock_Sandstone_White"
    },
    {
      "x": -16,
      "y": 19,
      "z": -8,
      "name": "Rock_Sandstone_White"
    },
    {
      "x": -16,
      "y": 20,
      "z": -8,
      "name": "Rock_Sandstone_White"
    },
    {
      "x": -16,
      "y": 21,
      "z": -8,
      "name": "Soil_Sand_White"
    },
    {
      "x": -16,
      "y": 22,
      "z": -8,
      "name": "Soil_Sand_White"
    },
    {
      "x": -16,
      "y": 23,
      "z": -8,
      "name": "Soil_Gravel_Sand_White"
    },
    {
      "x": -16,
      "y": 23,
      "z": -1,
      "name": "Rock_Sandstone_White"
    },
    {
      "x": -16,
      "y": 24,
      "z": -1,
      "name": "Rock_Sandstone_White"
    },
    {
      "x": -16,
      "y": 25,
      "z": -1,
      "name": "Soil_Sand_White"
    },
    {
      "x": -16,
      "y": 21,
      "z": 0,
      "name": "Rock_Sandstone_White"
    },
    {
      "x": -16,
      "y": 22,
      "z": 0,
      "name": "Rock_Sandstone_White"
    },
    {
      "x": -16,
      "y": 23,
      "z": 0,
      "name": "Rock_Sandstone_White"
    },
    {
      "x": -16,
      "y": 24,
      "z": 0,
      "name": "Rock_Sandstone_White"
    },
    {
      "x": -16,
      "y": 25,
      "z": 0,
      "name": "Soil_Sand_White"
    },
    {
      "x": -16,
      "y": 26,
      "z": 0,
      "name": "Soil_Sand_White"
    },
    {
      "x": -16,
      "y": 20,
      "z": 1,
      "name": "Rock_Sandstone_White"
    },
    {
      "x": -16,
      "y": 21,
      "z": 1,
      "name": "Rock_Sandstone_White"
    },
    {
      "x": -16,
      "y": 22,
      "z": 1,
      "name": "Rock_Sandstone_White"
    },
    {
      "x": -16,
      "y": 23,
      "z": 1,
      "name": "Rock_Sandstone_White"
    },
    {
      "x": -16,
      "y": 24,
      "z": 1,
      "name": "Rock_Sandstone_White"
    },
    {
      "x": -16,
      "y": 25,
      "z": 1,
      "name": "Soil_Sand_White"
    },
    {
      "x": -16,
      "y": 26,
      "z": 1,
      "name": "Soil_Sand_White"
    },
    {
      "x": -16,
      "y": 27,
      "z": 1,
      "name": "Soil_Sand_White"
    },
    {
      "x": -16,
      "y": 28,
      "z": 1,
      "name": "Plant_Bush_Arid_Sharp"
    },
    {
      "x": -16,
      "y": 19,
      "z": 2,
      "name": "Rock_Sandstone_White"
    },
    {
      "x": -16,
      "y": 20,
      "z": 2,
      "name": "Rock_Sandstone_White"
    },
    {
      "x": -16,
      "y": 21,
      "z": 2,
      "name": "Rock_Sandstone_White"
    },
    {
      "x": -16,
      "y": 22,
      "z": 2,
      "name": "Rock_Sandstone_White"
    },
    {
      "x": -16,
      "y": 23,
      "z": 2,
      "name": "Rock_Sandstone_White"
    },
    {
      "x": -16,
      "y": 24,
      "z": 2,
      "name": "Rock_Sandstone_White"
    },
    {
      "x": -16,
      "y": 25,
      "z": 2,
      "name": "Soil_Sand_White"
    },
    {
      "x": -16,
      "y": 26,
      "z": 2,
      "name": "Soil_Sand_White"
    },
    {
      "x": -16,
      "y": 27,
      "z": 2,
      "name": "Soil_Sand_White"
    },
    {
      "x": -16,
      "y": 28,
      "z": 2,
      "name": "Soil_Sand_White"
    },
    {
      "x": -16,
      "y": 20,
      "z": 3,
      "name": "Rock_Sandstone_White"
    },
    {
      "x": -16,
      "y": 21,
      "z": 3,
      "name": "Rock_Sandstone_White"
    },
    {
      "x": -16,
      "y": 22,
      "z": 3,
      "name": "Rock_Sandstone_White"
    },
    {
      "x": -16,
      "y": 23,
      "z": 3,
      "name": "Rock_Sandstone_White"
    },
    {
      "x": -16,
      "y": 24,
      "z": 3,
      "name": "Rock_Sandstone_White"
    },
    {
      "x": -16,
      "y": 25,
      "z": 3,
      "name": "Rock_Sandstone_White"
    },
    {
      "x": -16,
      "y": 26,
      "z": 3,
      "name": "Soil_Sand_White"
    },
    {
      "x": -16,
      "y": 27,
      "z": 3,
      "name": "Soil_Sand_White"
    },
    {
      "x": -16,
      "y": 28,
      "z": 3,
      "name": "Soil_Sand_White"
    },
    {
      "x": -16,
      "y": 21,
      "z": 4,
      "name": "Rock_Sandstone_White"
    },
    {
      "x": -16,
      "y": 22,
      "z": 4,
      "name": "Rock_Sandstone_White"
    },
    {
      "x": -16,
      "y": 23,
      "z": 4,
      "name": "Rock_Sandstone_White"
    },
    {
      "x": -16,
      "y": 24,
      "z": 4,
      "name": "Rock_Sandstone_White"
    },
    {
      "x": -16,
      "y": 25,
      "z": 4,
      "name": "Soil_Sand_White"
    },
    {
      "x": -16,
      "y": 26,
      "z": 4,
      "name": "Soil_Gravel_Sand_White"
    },
    {
      "x": -16,
      "y": 27,
      "z": 4,
      "name": "Soil_Gravel_Sand_White"
    },
    {
      "x": -16,
      "y": 23,
      "z": 5,
      "name": "Rock_Sandstone_White"
    },
    {
      "x": -16,
      "y": 24,
      "z": 5,
      "name": "Rock_Sandstone_White"
    },
    {
      "x": -16,
      "y": 25,
      "z": 5,
      "name": "Soil_Gravel_Sand_White"
    },
    {
      "x": -16,
      "y": 16,
      "z": 13,
      "name": "Rock_Sandstone_White"
    },
    {
      "x": -16,
      "y": 17,
      "z": 13,
      "name": "Rock_Sandstone_White"
    },
    {
      "x": -16,
      "y": 18,
      "z": 13,
      "name": "Rock_Sandstone_White"
    },
    {
      "x": -16,
      "y": 19,
      "z": 13,
      "name": "Rock_Sandstone_White"
    },
    {
      "x": -16,
      "y": 20,
      "z": 13,
      "name": "Soil_Sand_White"
    },
    {
      "x": -16,
      "y": 21,
      "z": 13,
      "name": "Soil_Sand_White"
    },
    {
      "x": -16,
      "y": 15,
      "z": 14,
      "name": "Rock_Sandstone_White"
    },
    {
      "x": -16,
      "y": 16,
      "z": 14,
      "name": "Rock_Sandstone_White"
    },
    {
      "x": -16,
      "y": 17,
      "z": 14,
      "name": "Rock_Sandstone_White"
    },
    {
      "x": -16,
      "y": 18,
      "z": 14,
      "name": "Rock_Sandstone_White"
    },
    {
      "x": -16,
      "y": 19,
      "z": 14,
      "name": "Rock_Sandstone_White"
    },
    {
      "x": -16,
      "y": 20,
      "z": 14,
      "name": "Rock_Sandstone_White"
    },
    {
      "x": -16,
      "y": 21,
      "z": 14,
      "name": "Soil_Sand_White"
    },
    {
      "x": -16,
      "y": 22,
      "z": 14,
      "name": "Soil_Gravel_Sand_White"
    },
    {
      "x": -16,
      "y": 13,
      "z": 15,
      "name": "Rock_Sandstone_White_Stalactite_Small",
      "rotation": 9
    },
    {
      "x": -16,
      "y": 14,
      "z": 15,
      "name": "Rock_Sandstone_White"
    },
    {
      "x": -16,
      "y": 15,
      "z": 15,
      "name": "Rock_Sandstone_White"
    },
    {
      "x": -16,
      "y": 16,
      "z": 15,
      "name": "Rock_Sandstone_White"
    },
    {
      "x": -16,
      "y": 17,
      "z": 15,
      "name": "Rock_Sandstone_White"
    },
    {
      "x": -16,
      "y": 18,
      "z": 15,
      "name": "Rock_Sandstone_White"
    },
    {
      "x": -16,
      "y": 19,
      "z": 15,
      "name": "Rock_Sandstone_White"
    },
    {
      "x": -16,
      "y": 20,
      "z": 15,
      "name": "Rock_Sandstone_White"
    },
    {
      "x": -16,
      "y": 21,
      "z": 15,
      "name": "Soil_Sand_White"
    },
    {
      "x": -16,
      "y": 22,
      "z": 15,
      "name": "Soil_Sand_White"
    },
    {
      "x": -16,
      "y": 23,
      "z": 15,
      "name": "Rubble_Sandstone_White_Medium"
    },
    {
      "x": -16,
      "y": 15,
      "z": 16,
      "name": "Rock_Sandstone_White"
    },
    {
      "x": -16,
      "y": 16,
      "z": 16,
      "name": "Rock_Sandstone_White"
    },
    {
      "x": -16,
      "y": 17,
      "z": 16,
      "name": "Rock_Sandstone_White"
    },
    {
      "x": -16,
      "y": 18,
      "z": 16,
      "name": "Rock_Sandstone_White"
    },
    {
      "x": -16,
      "y": 19,
      "z": 16,
      "name": "Rock_Sandstone_White"
    },
    {
      "x": -16,
      "y": 20,
      "z": 16,
      "name": "Rock_Sandstone_White"
    },
    {
      "x": -16,
      "y": 21,
      "z": 16,
      "name": "Rock_Sandstone_White"
    },
    {
      "x": -16,
      "y": 22,
      "z": 16,
      "name": "Rock_Sandstone_White"
    },
    {
      "x": -16,
      "y": 16,
      "z": 17,
      "name": "Rock_Sandstone_White"
    },
    {
      "x": -16,
      "y": 17,
      "z": 17,
      "name": "Rock_Sandstone_White"
    },
    {
      "x": -16,
      "y": 18,
      "z": 17,
      "name": "Rock_Sandstone_White"
    },
    {
      "x": -16,
      "y": 19,
      "z": 17,
      "name": "Rock_Sandstone_White"
    },
    {
      "x": -16,
      "y": 20,
      "z": 17,
      "name": "Soil_Sand_White"
    },
    {
      "x": -16,
      "y": 21,
      "z": 17,
      "name": "Soil_Sand_White"
    },
    {
      "x": -15,
      "y": 16,
      "z": -12,
      "name": "Rock_Sandstone_White"
    },
    {
      "x": -15,
      "y": 17,
      "z": -12,
      "name": "Rock_Sandstone_White"
    },
    {
      "x": -15,
      "y": 18,
      "z": -12,
      "name": "Rock_Sandstone_White"
    },
    {
      "x": -15,
      "y": 19,
      "z": -12,
      "name": "Rock_Sandstone_White"
    },
    {
      "x": -15,
      "y": 20,
      "z": -12,
      "name": "Rock_Sandstone_White"
    },
    {
      "x": -15,
      "y": 21,
      "z": -12,
      "name": "Soil_Sand_White"
    },
    {
      "x": -15,
      "y": 22,
      "z": -12,
      "name": "Soil_Sand_White"
    },
    {
      "x": -15,
      "y": 23,
      "z": -12,
      "name": "Soil_Sand_White"
    },
    {
      "x": -15,
      "y": 15,
      "z": -11,
      "name": "Rock_Sandstone_White"
    },
    {
      "x": -15,
      "y": 16,
      "z": -11,
      "name": "Rock_Sandstone_White"
    },
    {
      "x": -15,
      "y": 17,
      "z": -11,
      "name": "Rock_Sandstone_White"
    },
    {
      "x": -15,
      "y": 18,
      "z": -11,
      "name": "Rock_Sandstone_White"
    },
    {
      "x": -15,
      "y": 19,
      "z": -11,
      "name": "Rock_Sandstone_White"
    },
    {
      "x": -15,
      "y": 20,
      "z": -11,
      "name": "Soil_Gravel_Sand_White"
    },
    {
      "x": -15,
      "y": 21,
      "z": -11,
      "name": "Soil_Sand_White"
    },
    {
      "x": -15,
      "y": 22,
      "z": -11,
      "name": "Soil_Sand_White"
    },
    {
      "x": -15,
      "y": 23,
      "z": -11,
      "name": "Soil_Sand_White"
    },
    {
      "x": -15,
      "y": 14,
      "z": -10,
      "name": "Rock_Sandstone_White"
    },
    {
      "x": -15,
      "y": 15,
      "z": -10,
      "name": "Rock_Sandstone_White"
    },
    {
      "x": -15,
      "y": 16,
      "z": -10,
      "name": "Rock_Sandstone_White"
    },
    {
      "x": -15,
      "y": 17,
      "z": -10,
      "name": "Rock_Sandstone_White"
    },
    {
      "x": -15,
      "y": 18,
      "z": -10,
      "name": "Rock_Sandstone_White"
    },
    {
      "x": -15,
      "y": 19,
      "z": -10,
      "name": "Rock_Sandstone_White"
    },
    {
      "x": -15,
      "y": 20,
      "z": -10,
      "name": "Rock_Sandstone_White"
    },
    {
      "x": -15,
      "y": 21,
      "z": -10,
      "name": "Rock_Sandstone_White"
    },
    {
      "x": -15,
      "y": 22,
      "z": -10,
      "name": "Rock_Sandstone_White"
    },
    {
      "x": -15,
      "y": 23,
      "z": -10,
      "name": "Soil_Sand_White"
    },
    {
      "x": -15,
      "y": 24,
      "z": -10,
      "name": "Soil_Gravel_Sand_White"
    },
    {
      "x": -15,
      "y": 15,
      "z": -9,
      "name": "Rock_Sandstone_White"
    },
    {
      "x": -15,
      "y": 16,
      "z": -9,
      "name": "Rock_Sandstone_White"
    },
    {
      "x": -15,
      "y": 17,
      "z": -9,
      "name": "Rock_Sandstone_White"
    },
    {
      "x": -15,
      "y": 18,
      "z": -9,
      "name": "Rock_Sandstone_White"
    },
    {
      "x": -15,
      "y": 19,
      "z": -9,
      "name": "Rock_Sandstone_White"
    },
    {
      "x": -15,
      "y": 20,
      "z": -9,
      "name": "Rock_Sandstone_White"
    },
    {
      "x": -15,
      "y": 21,
      "z": -9,
      "name": "Soil_Sand_White"
    },
    {
      "x": -15,
      "y": 22,
      "z": -9,
      "name": "Soil_Sand_White"
    },
    {
      "x": -15,
      "y": 23,
      "z": -9,
      "name": "Soil_Sand_White"
    },
    {
      "x": -15,
      "y": 24,
      "z": -9,
      "name": "Soil_Sand_White"
    },
    {
      "x": -15,
      "y": 16,
      "z": -8,
      "name": "Rock_Sandstone_White"
    },
    {
      "x": -15,
      "y": 17,
      "z": -8,
      "name": "Rock_Sandstone_White"
    },
    {
      "x": -15,
      "y": 18,
      "z": -8,
      "name": "Rock_Sandstone_White"
    },
    {
      "x": -15,
      "y": 19,
      "z": -8,
      "name": "Rock_Sandstone_White"
    },
    {
      "x": -15,
      "y": 20,
      "z": -8,
      "name": "Rock_Sandstone_White"
    },
    {
      "x": -15,
      "y": 21,
      "z": -8,
      "name": "Soil_Sand_White"
    },
    {
      "x": -15,
      "y": 22,
      "z": -8,
      "name": "Soil_Gravel_Sand_White"
    },
    {
      "x": -15,
      "y": 23,
      "z": -8,
      "name": "Soil_Gravel_Sand_White"
    },
    {
      "x": -15,
      "y": 24,
      "z": -8,
      "name": "Soil_Sand_White"
    },
    {
      "x": -15,
      "y": 18,
      "z": -7,
      "name": "Rock_Sandstone_White"
    },
    {
      "x": -15,
      "y": 19,
      "z": -7,
      "name": "Rock_Sandstone_White"
    },
    {
      "x": -15,
      "y": 20,
      "z": -7,
      "name": "Rock_Sandstone_White"
    },
    {
      "x": -15,
      "y": 21,
      "z": -7,
      "name": "Rock_Sandstone_White"
    },
    {
      "x": -15,
      "y": 22,
      "z": -7,
      "name": "Soil_Sand_White"
    },
    {
      "x": -15,
      "y": 23,
      "z": -7,
      "name": "Soil_Gravel_Sand_White"
    },
    {
      "x": -15,
      "y": 24,
      "z": -7,
      "name": "Soil_Sand_White"
    },
    {
      "x": -15,
      "y": 20,
      "z": -6,
      "name": "Rock_Sandstone_White"
    },
    {
      "x": -15,
      "y": 21,
      "z": -6,
      "name": "Soil_Gravel_Sand_White"
    },
    {
      "x": -15,
      "y": 22,
      "z": -6,
      "name": "Soil_Sand_White"
    },
    {
      "x": -15,
      "y": 23,
      "z": -6,
      "name": "Soil_Sand_White"
    },
    {
      "x": -15,
      "y": 22,
      "z": -5,
      "name": "Soil_Sand_White"
    },
    {
      "x": -15,
      "y": 23,
      "z": -5,
      "name": "Soil_Sand_White"
    },
    {
      "x": -15,
      "y": 20,
      "z": -2,
      "name": "Rock_Sandstone_White"
    },
    {
      "x": -15,
      "y": 21,
      "z": -2,
      "name": "Rock_Sandstone_White"
    },
    {
      "x": -15,
      "y": 22,
      "z": -2,
      "name": "Rock_Sandstone_White"
    },
    {
      "x": -15,
      "y": 23,
      "z": -2,
      "name": "Soil_Sand_White"
    },
    {
      "x": -15,
      "y": 24,
      "z": -2,
      "name": "Soil_Sand_White"
    },
    {
      "x": -15,
      "y": 25,
      "z": -2,
      "name": "Soil_Gravel_Sand_White"
    },
    {
      "x": -15,
      "y": 26,
      "z": -2,
      "name": "Soil_Sand_White"
    },
    {
      "x": -15,
      "y": 19,
      "z": -1,
      "name": "Rock_Sandstone_White"
    },
    {
      "x": -15,
      "y": 20,
      "z": -1,
      "name": "Rock_Sandstone_White"
    },
    {
      "x": -15,
      "y": 21,
      "z": -1,
      "name": "Rock_Sandstone_White"
    },
    {
      "x": -15,
      "y": 22,
      "z": -1,
      "name": "Rock_Sandstone_White"
    },
    {
      "x": -15,
      "y": 23,
      "z": -1,
      "name": "Rock_Sandstone_White"
    },
    {
      "x": -15,
      "y": 24,
      "z": -1,
      "name": "Rock_Sandstone_White"
    },
    {
      "x": -15,
      "y": 25,
      "z": -1,
      "name": "Soil_Sand_White"
    },
    {
      "x": -15,
      "y": 26,
      "z": -1,
      "name": "Soil_Sand_White"
    },
    {
      "x": -15,
      "y": 20,
      "z": 0,
      "name": "Rock_Sandstone_White"
    },
    {
      "x": -15,
      "y": 21,
      "z": 0,
      "name": "Rock_Sandstone_White"
    },
    {
      "x": -15,
      "y": 22,
      "z": 0,
      "name": "Rock_Sandstone_White"
    },
    {
      "x": -15,
      "y": 23,
      "z": 0,
      "name": "Rock_Sandstone_White"
    },
    {
      "x": -15,
      "y": 24,
      "z": 0,
      "name": "Soil_Sand_White"
    },
    {
      "x": -15,
      "y": 25,
      "z": 0,
      "name": "Soil_Sand_White"
    },
    {
      "x": -15,
      "y": 26,
      "z": 0,
      "name": "Soil_Sand_White"
    },
    {
      "x": -15,
      "y": 27,
      "z": 0,
      "name": "Soil_Sand_White"
    },
    {
      "x": -15,
      "y": 19,
      "z": 1,
      "name": "Rock_Sandstone_White"
    },
    {
      "x": -15,
      "y": 20,
      "z": 1,
      "name": "Rock_Sandstone_White"
    },
    {
      "x": -15,
      "y": 21,
      "z": 1,
      "name": "Rock_Sandstone_White"
    },
    {
      "x": -15,
      "y": 22,
      "z": 1,
      "name": "Rock_Sandstone_White"
    },
    {
      "x": -15,
      "y": 23,
      "z": 1,
      "name": "Rock_Sandstone_White"
    },
    {
      "x": -15,
      "y": 24,
      "z": 1,
      "name": "Rock_Sandstone_White"
    },
    {
      "x": -15,
      "y": 25,
      "z": 1,
      "name": "Soil_Gravel_Sand_White"
    },
    {
      "x": -15,
      "y": 26,
      "z": 1,
      "name": "Soil_Sand_White"
    },
    {
      "x": -15,
      "y": 27,
      "z": 1,
      "name": "Soil_Sand_White"
    },
    {
      "x": -15,
      "y": 28,
      "z": 1,
      "name": "Soil_Gravel_Sand_White"
    },
    {
      "x": -15,
      "y": 18,
      "z": 2,
      "name": "Rock_Sandstone_White"
    },
    {
      "x": -15,
      "y": 19,
      "z": 2,
      "name": "Rock_Sandstone_White"
    },
    {
      "x": -15,
      "y": 20,
      "z": 2,
      "name": "Rock_Sandstone_White"
    },
    {
      "x": -15,
      "y": 21,
      "z": 2,
      "name": "Rock_Sandstone_White"
    },
    {
      "x": -15,
      "y": 22,
      "z": 2,
      "name": "Rock_Sandstone_White"
    },
    {
      "x": -15,
      "y": 23,
      "z": 2,
      "name": "Rock_Sandstone_White"
    },
    {
      "x": -15,
      "y": 24,
      "z": 2,
      "name": "Soil_Sand_White"
    },
    {
      "x": -15,
      "y": 25,
      "z": 2,
      "name": "Soil_Sand_White"
    },
    {
      "x": -15,
      "y": 26,
      "z": 2,
      "name": "Soil_Sand_White"
    },
    {
      "x": -15,
      "y": 27,
      "z": 2,
      "name": "Soil_Sand_White"
    },
    {
      "x": -15,
      "y": 28,
      "z": 2,
      "name": "Soil_Gravel_Sand_White"
    },
    {
      "x": -15,
      "y": 19,
      "z": 3,
      "name": "Rock_Sandstone_White"
    },
    {
      "x": -15,
      "y": 20,
      "z": 3,
      "name": "Rock_Sandstone_White"
    },
    {
      "x": -15,
      "y": 21,
      "z": 3,
      "name": "Rock_Sandstone_White"
    },
    {
      "x": -15,
      "y": 22,
      "z": 3,
      "name": "Rock_Sandstone_White"
    },
    {
      "x": -15,
      "y": 23,
      "z": 3,
      "name": "Rock_Sandstone_White"
    },
    {
      "x": -15,
      "y": 24,
      "z": 3,
      "name": "Rock_Sandstone_White"
    },
    {
      "x": -15,
      "y": 25,
      "z": 3,
      "name": "Soil_Sand_White"
    },
    {
      "x": -15,
      "y": 26,
      "z": 3,
      "name": "Soil_Sand_White"
    },
    {
      "x": -15,
      "y": 27,
      "z": 3,
      "name": "Soil_Sand_White"
    },
    {
      "x": -15,
      "y": 28,
      "z": 3,
      "name": "Soil_Sand_White"
    },
    {
      "x": -15,
      "y": 20,
      "z": 4,
      "name": "Rock_Sandstone_White"
    },
    {
      "x": -15,
      "y": 21,
      "z": 4,
      "name": "Rock_Sandstone_White"
    },
    {
      "x": -15,
      "y": 22,
      "z": 4,
      "name": "Rock_Sandstone_White"
    },
    {
      "x": -15,
      "y": 23,
      "z": 4,
      "name": "Rock_Sandstone_White"
    },
    {
      "x": -15,
      "y": 24,
      "z": 4,
      "name": "Rock_Sandstone_White"
    },
    {
      "x": -15,
      "y": 25,
      "z": 4,
      "name": "Rock_Sandstone_White"
    },
    {
      "x": -15,
      "y": 26,
      "z": 4,
      "name": "Soil_Sand_White"
    },
    {
      "x": -15,
      "y": 27,
      "z": 4,
      "name": "Soil_Sand_White"
    },
    {
      "x": -15,
      "y": 28,
      "z": 4,
      "name": "Soil_Sand_White"
    },
    {
      "x": -15,
      "y": 22,
      "z": 5,
      "name": "Rock_Sandstone_White"
    },
    {
      "x": -15,
      "y": 23,
      "z": 5,
      "name": "Rock_Sandstone_White"
    },
    {
      "x": -15,
      "y": 24,
      "z": 5,
      "name": "Rock_Sandstone_White"
    },
    {
      "x": -15,
      "y": 25,
      "z": 5,
      "name": "Rock_Sandstone_White"
    },
    {
      "x": -15,
      "y": 26,
      "z": 5,
      "name": "Soil_Sand_White"
    },
    {
      "x": -15,
      "y": 27,
      "z": 5,
      "name": "Soil_Sand_White"
    },
    {
      "x": -15,
      "y": 28,
      "z": 5,
      "name": "Soil_Sand_White"
    },
    {
      "x": -15,
      "y": 26,
      "z": 6,
      "name": "Soil_Sand_White"
    },
    {
      "x": -15,
      "y": 27,
      "z": 6,
      "name": "Soil_Gravel_Sand_White"
    },
    {
      "x": -15,
      "y": 16,
      "z": 12,
      "name": "Rock_Sandstone_White"
    },
    {
      "x": -15,
      "y": 17,
      "z": 12,
      "name": "Rock_Sandstone_White"
    },
    {
      "x": -15,
      "y": 18,
      "z": 12,
      "name": "Soil_Sand_White"
    },
    {
      "x": -15,
      "y": 19,
      "z": 12,
      "name": "Soil_Sand_White"
    },
    {
      "x": -15,
      "y": 20,
      "z": 12,
      "name": "Soil_Gravel_Sand_White"
    },
    {
      "x": -15,
      "y": 21,
      "z": 12,
      "name": "Soil_Sand_White"
    },
    {
      "x": -15,
      "y": 22,
      "z": 12,
      "name": "Rubble_Sandstone_White_Medium"
    },
    {
      "x": -15,
      "y": 13,
      "z": 13,
      "name": "Rock_Sandstone_White_Stalactite_Small",
      "rotation": 8
    },
    {
      "x": -15,
      "y": 14,
      "z": 13,
      "name": "Rock_Sandstone_White"
    },
    {
      "x": -15,
      "y": 15,
      "z": 13,
      "name": "Rock_Sandstone_White"
    },
    {
      "x": -15,
      "y": 16,
      "z": 13,
      "name": "Rock_Sandstone_White"
    },
    {
      "x": -15,
      "y": 17,
      "z": 13,
      "name": "Rock_Sandstone_White"
    },
    {
      "x": -15,
      "y": 18,
      "z": 13,
      "name": "Rock_Sandstone_White"
    },
    {
      "x": -15,
      "y": 19,
      "z": 13,
      "name": "Rock_Sandstone_White"
    },
    {
      "x": -15,
      "y": 20,
      "z": 13,
      "name": "Rock_Sandstone_White"
    },
    {
      "x": -15,
      "y": 21,
      "z": 13,
      "name": "Rock_Sandstone_White"
    },
    {
      "x": -15,
      "y": 22,
      "z": 13,
      "name": "Rock_Sandstone_White_Brick"
    },
    {
      "x": -15,
      "y": 23,
      "z": 13,
      "name": "Rock_Sandstone_White_Brick_Pillar_Base"
    },
    {
      "x": -15,
      "y": 24,
      "z": 13,
      "name": "Rock_Sandstone_White_Brick_Pillar_Middle"
    },
    {
      "x": -15,
      "y": 25,
      "z": 13,
      "name": "Rubble_Sandstone_White"
    },
    {
      "x": -15,
      "y": 13,
      "z": 14,
      "name": "Rock_Sandstone_White"
    },
    {
      "x": -15,
      "y": 14,
      "z": 14,
      "name": "Rock_Sandstone_White"
    },
    {
      "x": -15,
      "y": 15,
      "z": 14,
      "name": "Rock_Sandstone_White"
    },
    {
      "x": -15,
      "y": 16,
      "z": 14,
      "name": "Rock_Sandstone_White"
    },
    {
      "x": -15,
      "y": 17,
      "z": 14,
      "name": "Rock_Sandstone_White"
    },
    {
      "x": -15,
      "y": 18,
      "z": 14,
      "name": "Rock_Sandstone_White"
    },
    {
      "x": -15,
      "y": 19,
      "z": 14,
      "name": "Rock_Sandstone_White"
    },
    {
      "x": -15,
      "y": 20,
      "z": 14,
      "name": "Rock_Sandstone_White"
    },
    {
      "x": -15,
      "y": 21,
      "z": 14,
      "name": "Rock_Sandstone_White"
    },
    {
      "x": -15,
      "y": 22,
      "z": 14,
      "name": "Rock_Sandstone_White_Brick"
    },
    {
      "x": -15,
      "y": 23,
      "z": 14,
      "name": "Rock_Sandstone_White_Brick_Pillar_Middle",
      "rotation": 4
    },
    {
      "x": -15,
      "y": 11,
      "z": 15,
      "name": "Rock_Crystal_Yellow_Large",
      "rotation": 7
    },
    {
      "x": -15,
      "y": 12,
      "z": 15,
      "name": "Rock_Sandstone_White"
    },
    {
      "x": -15,
      "y": 13,
      "z": 15,
      "name": "Rock_Sandstone_White"
    },
    {
      "x": -15,
      "y": 14,
      "z": 15,
      "name": "Rock_Sandstone_White"
    },
    {
      "x": -15,
      "y": 15,
      "z": 15,
      "name": "Rock_Sandstone_White"
    },
    {
      "x": -15,
      "y": 16,
      "z": 15,
      "name": "Rock_Sandstone_White"
    },
    {
      "x": -15,
      "y": 17,
      "z": 15,
      "name": "Rock_Sandstone_White"
    },
    {
      "x": -15,
      "y": 18,
      "z": 15,
      "name": "Rock_Sandstone_White"
    },
    {
      "x": -15,
      "y": 19,
      "z": 15,
      "name": "Rock_Sandstone_White"
    },
    {
      "x": -15,
      "y": 20,
      "z": 15,
      "name": "Rock_Sandstone_White"
    },
    {
      "x": -15,
      "y": 21,
      "z": 15,
      "name": "Rock_Sandstone_White"
    },
    {
      "x": -15,
      "y": 22,
      "z": 15,
      "name": "Rock_Sandstone_White_Brick"
    },
    {
      "x": -15,
      "y": 23,
      "z": 15,
      "name": "Rubble_Sandstone_White_Medium"
    },
    {
      "x": -15,
      "y": 13,
      "z": 16,
      "name": "Rock_Sandstone_White"
    },
    {
      "x": -15,
      "y": 14,
      "z": 16,
      "name": "Rock_Sandstone_White"
    },
    {
      "x": -15,
      "y": 15,
      "z": 16,
      "name": "Rock_Sandstone_White"
    },
    {
      "x": -15,
      "y": 16,
      "z": 16,
      "name": "Rock_Sandstone_White"
    },
    {
      "x": -15,
      "y": 17,
      "z": 16,
      "name": "Rock_Sandstone_White"
    },
    {
      "x": -15,
      "y": 18,
      "z": 16,
      "name": "Rock_Sandstone_White"
    },
    {
      "x": -15,
      "y": 19,
      "z": 16,
      "name": "Rock_Sandstone_White"
    },
    {
      "x": -15,
      "y": 20,
      "z": 16,
      "name": "Rock_Sandstone_White"
    },
    {
      "x": -15,
      "y": 21,
      "z": 16,
      "name": "Rock_Sandstone_White"
    },
    {
      "x": -15,
      "y": 22,
      "z": 16,
      "name": "Rock_Sandstone_White_Brick"
    },
    {
      "x": -15,
      "y": 23,
      "z": 16,
      "name": "Rock_Sandstone_White_Brick_Pillar_Base"
    },
    {
      "x": -15,
      "y": 24,
      "z": 16,
      "name": "Rock_Sandstone_White_Brick_Pillar_Middle"
    },
    {
      "x": -15,
      "y": 25,
      "z": 16,
      "name": "Rock_Sandstone_White_Brick_Pillar_Middle"
    },
    {
      "x": -15,
      "y": 26,
      "z": 16,
      "name": "Rubble_Sandstone_White_Medium"
    },
    {
      "x": -15,
      "y": 14,
      "z": 17,
      "name": "Rock_Sandstone_White"
    },
    {
      "x": -15,
      "y": 15,
      "z": 17,
      "name": "Rock_Sandstone_White"
    },
    {
      "x": -15,
      "y": 16,
      "z": 17,
      "name": "Rock_Sandstone_White"
    },
    {
      "x": -15,
      "y": 17,
      "z": 17,
      "name": "Rock_Sandstone_White"
    },
    {
      "x": -15,
      "y": 18,
      "z": 17,
      "name": "Rock_Sandstone_White"
    },
    {
      "x": -15,
      "y": 19,
      "z": 17,
      "name": "Rock_Sandstone_White"
    },
    {
      "x": -15,
      "y": 20,
      "z": 17,
      "name": "Soil_Sand_White"
    },
    {
      "x": -15,
      "y": 21,
      "z": 17,
      "name": "Soil_Sand_White"
    },
    {
      "x": -15,
      "y": 22,
      "z": 17,
      "name": "Soil_Sand_White"
    },
    {
      "x": -15,
      "y": 16,
      "z": 18,
      "name": "Rock_Sandstone_White"
    },
    {
      "x": -15,
      "y": 17,
      "z": 18,
      "name": "Rock_Sandstone_White"
    },
    {
      "x": -15,
      "y": 18,
      "z": 18,
      "name": "Rock_Sandstone_White"
    },
    {
      "x": -15,
      "y": 19,
      "z": 18,
      "name": "Soil_Sand_White"
    },
    {
      "x": -15,
      "y": 20,
      "z": 18,
      "name": "Soil_Sand_White"
    },
    {
      "x": -15,
      "y": 21,
      "z": 18,
      "name": "Soil_Sand_White"
    },
    {
      "x": -15,
      "y": 22,
      "z": 18,
      "name": "Plant_Cactus_Flat_3"
    },
    {
      "x": -14,
      "y": 17,
      "z": -13,
      "name": "Rock_Sandstone_White"
    },
    {
      "x": -14,
      "y": 18,
      "z": -13,
      "name": "Rock_Sandstone_White"
    },
    {
      "x": -14,
      "y": 19,
      "z": -13,
      "name": "Rock_Sandstone_White"
    },
    {
      "x": -14,
      "y": 20,
      "z": -13,
      "name": "Soil_Sand_White"
    },
    {
      "x": -14,
      "y": 21,
      "z": -13,
      "name": "Soil_Sand_White"
    },
    {
      "x": -14,
      "y": 22,
      "z": -13,
      "name": "Soil_Sand_White"
    },
    {
      "x": -14,
      "y": 23,
      "z": -13,
      "name": "Soil_Sand_White"
    },
    {
      "x": -14,
      "y": 15,
      "z": -12,
      "name": "Rock_Sandstone_White"
    },
    {
      "x": -14,
      "y": 16,
      "z": -12,
      "name": "Rock_Sandstone_White"
    },
    {
      "x": -14,
      "y": 17,
      "z": -12,
      "name": "Rock_Sandstone_White"
    },
    {
      "x": -14,
      "y": 18,
      "z": -12,
      "name": "Rock_Sandstone_White"
    },
    {
      "x": -14,
      "y": 19,
      "z": -12,
      "name": "Rock_Sandstone_White"
    },
    {
      "x": -14,
      "y": 20,
      "z": -12,
      "name": "Rock_Sandstone_White"
    },
    {
      "x": -14,
      "y": 21,
      "z": -12,
      "name": "Soil_Sand_White"
    },
    {
      "x": -14,
      "y": 22,
      "z": -12,
      "name": "Soil_Sand_White"
    },
    {
      "x": -14,
      "y": 23,
      "z": -12,
      "name": "Soil_Sand_White"
    },
    {
      "x": -14,
      "y": 24,
      "z": -12,
      "name": "Soil_Sand_White"
    },
    {
      "x": -14,
      "y": 14,
      "z": -11,
      "name": "Rock_Sandstone_White"
    },
    {
      "x": -14,
      "y": 15,
      "z": -11,
      "name": "Rock_Sandstone_White"
    },
    {
      "x": -14,
      "y": 16,
      "z": -11,
      "name": "Rock_Sandstone_White"
    },
    {
      "x": -14,
      "y": 17,
      "z": -11,
      "name": "Rock_Sandstone_White"
    },
    {
      "x": -14,
      "y": 18,
      "z": -11,
      "name": "Rock_Sandstone_White"
    },
    {
      "x": -14,
      "y": 19,
      "z": -11,
      "name": "Rock_Sandstone_White"
    },
    {
      "x": -14,
      "y": 20,
      "z": -11,
      "name": "Rock_Sandstone_White"
    },
    {
      "x": -14,
      "y": 21,
      "z": -11,
      "name": "Soil_Sand_White"
    },
    {
      "x": -14,
      "y": 22,
      "z": -11,
      "name": "Soil_Sand_White"
    },
    {
      "x": -14,
      "y": 23,
      "z": -11,
      "name": "Soil_Sand_White"
    },
    {
      "x": -14,
      "y": 24,
      "z": -11,
      "name": "Soil_Sand_White"
    },
    {
      "x": -14,
      "y": 25,
      "z": -11,
      "name": "Plant_Flower_Bushy_Yellow"
    },
    {
      "x": -14,
      "y": 13,
      "z": -10,
      "name": "Rock_Sandstone_White"
    },
    {
      "x": -14,
      "y": 14,
      "z": -10,
      "name": "Rock_Sandstone_White"
    },
    {
      "x": -14,
      "y": 15,
      "z": -10,
      "name": "Rock_Sandstone_White"
    },
    {
      "x": -14,
      "y": 16,
      "z": -10,
      "name": "Rock_Sandstone_White"
    },
    {
      "x": -14,
      "y": 17,
      "z": -10,
      "name": "Rock_Sandstone_White"
    },
    {
      "x": -14,
      "y": 18,
      "z": -10,
      "name": "Rock_Sandstone_White"
    },
    {
      "x": -14,
      "y": 19,
      "z": -10,
      "name": "Rock_Sandstone_White"
    },
    {
      "x": -14,
      "y": 20,
      "z": -10,
      "name": "Soil_Sand_White"
    },
    {
      "x": -14,
      "y": 21,
      "z": -10,
      "name": "Soil_Sand_White"
    },
    {
      "x": -14,
      "y": 22,
      "z": -10,
      "name": "Soil_Sand_White"
    },
    {
      "x": -14,
      "y": 23,
      "z": -10,
      "name": "Soil_Sand_White"
    },
    {
      "x": -14,
      "y": 24,
      "z": -10,
      "name": "Soil_Sand_White"
    },
    {
      "x": -14,
      "y": 14,
      "z": -9,
      "name": "Rock_Sandstone_White"
    },
    {
      "x": -14,
      "y": 15,
      "z": -9,
      "name": "Rock_Sandstone_White"
    },
    {
      "x": -14,
      "y": 16,
      "z": -9,
      "name": "Rock_Sandstone_White"
    },
    {
      "x": -14,
      "y": 17,
      "z": -9,
      "name": "Rock_Sandstone_White"
    },
    {
      "x": -14,
      "y": 18,
      "z": -9,
      "name": "Rock_Sandstone_White"
    },
    {
      "x": -14,
      "y": 19,
      "z": -9,
      "name": "Rock_Sandstone_White"
    },
    {
      "x": -14,
      "y": 20,
      "z": -9,
      "name": "Rock_Sandstone_White"
    },
    {
      "x": -14,
      "y": 21,
      "z": -9,
      "name": "Soil_Gravel_Sand_White"
    },
    {
      "x": -14,
      "y": 22,
      "z": -9,
      "name": "Soil_Sand_White"
    },
    {
      "x": -14,
      "y": 23,
      "z": -9,
      "name": "Soil_Sand_White"
    },
    {
      "x": -14,
      "y": 24,
      "z": -9,
      "name": "Soil_Sand_White"
    },
    {
      "x": -14,
      "y": 25,
      "z": -9,
      "name": "Soil_Sand_White"
    },
    {
      "x": -14,
      "y": 15,
      "z": -8,
      "name": "Rock_Sandstone_White"
    },
    {
      "x": -14,
      "y": 16,
      "z": -8,
      "name": "Rock_Sandstone_White"
    },
    {
      "x": -14,
      "y": 17,
      "z": -8,
      "name": "Rock_Sandstone_White"
    },
    {
      "x": -14,
      "y": 18,
      "z": -8,
      "name": "Rock_Sandstone_White"
    },
    {
      "x": -14,
      "y": 19,
      "z": -8,
      "name": "Rock_Sandstone_White"
    },
    {
      "x": -14,
      "y": 20,
      "z": -8,
      "name": "Rock_Sandstone_White"
    },
    {
      "x": -14,
      "y": 21,
      "z": -8,
      "name": "Soil_Sand_White"
    },
    {
      "x": -14,
      "y": 22,
      "z": -8,
      "name": "Soil_Sand_White"
    },
    {
      "x": -14,
      "y": 23,
      "z": -8,
      "name": "Soil_Sand_White"
    },
    {
      "x": -14,
      "y": 24,
      "z": -8,
      "name": "Soil_Sand_White"
    },
    {
      "x": -14,
      "y": 25,
      "z": -8,
      "name": "Soil_Sand_White"
    },
    {
      "x": -14,
      "y": 15,
      "z": -7,
      "name": "Rock_Sandstone_White"
    },
    {
      "x": -14,
      "y": 16,
      "z": -7,
      "name": "Rock_Sandstone_White"
    },
    {
      "x": -14,
      "y": 17,
      "z": -7,
      "name": "Rock_Sandstone_White"
    },
    {
      "x": -14,
      "y": 18,
      "z": -7,
      "name": "Rock_Sandstone_White"
    },
    {
      "x": -14,
      "y": 19,
      "z": -7,
      "name": "Rock_Sandstone_White"
    },
    {
      "x": -14,
      "y": 20,
      "z": -7,
      "name": "Rock_Sandstone_White"
    },
    {
      "x": -14,
      "y": 21,
      "z": -7,
      "name": "Soil_Sand_White"
    },
    {
      "x": -14,
      "y": 22,
      "z": -7,
      "name": "Soil_Sand_White"
    },
    {
      "x": -14,
      "y": 23,
      "z": -7,
      "name": "Soil_Sand_White"
    },
    {
      "x": -14,
      "y": 24,
      "z": -7,
      "name": "Soil_Gravel_Sand_White"
    },
    {
      "x": -14,
      "y": 25,
      "z": -7,
      "name": "Soil_Gravel_Sand_White"
    },
    {
      "x": -14,
      "y": 16,
      "z": -6,
      "name": "Rock_Sandstone_White"
    },
    {
      "x": -14,
      "y": 17,
      "z": -6,
      "name": "Rock_Sandstone_White"
    },
    {
      "x": -14,
      "y": 18,
      "z": -6,
      "name": "Rock_Sandstone_White"
    },
    {
      "x": -14,
      "y": 19,
      "z": -6,
      "name": "Rock_Sandstone_White"
    },
    {
      "x": -14,
      "y": 20,
      "z": -6,
      "name": "Rock_Sandstone_White"
    },
    {
      "x": -14,
      "y": 21,
      "z": -6,
      "name": "Rock_Sandstone_White"
    },
    {
      "x": -14,
      "y": 22,
      "z": -6,
      "name": "Soil_Sand_White"
    },
    {
      "x": -14,
      "y": 23,
      "z": -6,
      "name": "Soil_Sand_White"
    },
    {
      "x": -14,
      "y": 24,
      "z": -6,
      "name": "Soil_Sand_White"
    },
    {
      "x": -14,
      "y": 17,
      "z": -5,
      "name": "Rock_Sandstone_White"
    },
    {
      "x": -14,
      "y": 18,
      "z": -5,
      "name": "Rock_Sandstone_White"
    },
    {
      "x": -14,
      "y": 19,
      "z": -5,
      "name": "Rock_Sandstone_White"
    },
    {
      "x": -14,
      "y": 20,
      "z": -5,
      "name": "Rock_Sandstone_White"
    },
    {
      "x": -14,
      "y": 21,
      "z": -5,
      "name": "Rock_Sandstone_White"
    },
    {
      "x": -14,
      "y": 22,
      "z": -5,
      "name": "Soil_Gravel_Sand_White"
    },
    {
      "x": -14,
      "y": 23,
      "z": -5,
      "name": "Soil_Sand_White"
    },
    {
      "x": -14,
      "y": 24,
      "z": -5,
      "name": "Soil_Sand_White"
    },
    {
      "x": -14,
      "y": 25,
      "z": -5,
      "name": "Plant_Bush_Arid"
    },
    {
      "x": -14,
      "y": 20,
      "z": -4,
      "name": "Rock_Sandstone_White"
    },
    {
      "x": -14,
      "y": 21,
      "z": -4,
      "name": "Rock_Sandstone_White"
    },
    {
      "x": -14,
      "y": 22,
      "z": -4,
      "name": "Rock_Sandstone_White"
    },
    {
      "x": -14,
      "y": 23,
      "z": -4,
      "name": "Soil_Sand_White"
    },
    {
      "x": -14,
      "y": 24,
      "z": -4,
      "name": "Soil_Sand_White"
    },
    {
      "x": -14,
      "y": 25,
      "z": -4,
      "name": "Soil_Gravel_Sand_White"
    },
    {
      "x": -14,
      "y": 26,
      "z": -4,
      "name": "Plant_Flower_Bushy_Yellow"
    },
    {
      "x": -14,
      "y": 17,
      "z": -3,
      "name": "Rock_Sandstone_White"
    },
    {
      "x": -14,
      "y": 18,
      "z": -3,
      "name": "Rock_Sandstone_White"
    },
    {
      "x": -14,
      "y": 19,
      "z": -3,
      "name": "Rock_Sandstone_White"
    },
    {
      "x": -14,
      "y": 20,
      "z": -3,
      "name": "Rock_Sandstone_White"
    },
    {
      "x": -14,
      "y": 21,
      "z": -3,
      "name": "Rock_Sandstone_White"
    },
    {
      "x": -14,
      "y": 22,
      "z": -3,
      "name": "Rock_Sandstone_White"
    },
    {
      "x": -14,
      "y": 23,
      "z": -3,
      "name": "Soil_Gravel_Sand_White"
    },
    {
      "x": -14,
      "y": 24,
      "z": -3,
      "name": "Soil_Sand_White"
    },
    {
      "x": -14,
      "y": 25,
      "z": -3,
      "name": "Soil_Sand_White"
    },
    {
      "x": -14,
      "y": 16,
      "z": -2,
      "name": "Rock_Sandstone_White"
    },
    {
      "x": -14,
      "y": 17,
      "z": -2,
      "name": "Rock_Sandstone_White"
    },
    {
      "x": -14,
      "y": 18,
      "z": -2,
      "name": "Rock_Sandstone_White"
    },
    {
      "x": -14,
      "y": 19,
      "z": -2,
      "name": "Rock_Sandstone_White"
    },
    {
      "x": -14,
      "y": 20,
      "z": -2,
      "name": "Rock_Sandstone_White"
    },
    {
      "x": -14,
      "y": 21,
      "z": -2,
      "name": "Rock_Sandstone_White"
    },
    {
      "x": -14,
      "y": 22,
      "z": -2,
      "name": "Rock_Sandstone_White"
    },
    {
      "x": -14,
      "y": 23,
      "z": -2,
      "name": "Rock_Sandstone_White"
    },
    {
      "x": -14,
      "y": 24,
      "z": -2,
      "name": "Soil_Sand_White"
    },
    {
      "x": -14,
      "y": 25,
      "z": -2,
      "name": "Soil_Gravel_Sand_White"
    },
    {
      "x": -14,
      "y": 26,
      "z": -2,
      "name": "Soil_Sand_White"
    },
    {
      "x": -14,
      "y": 15,
      "z": -1,
      "name": "Rock_Sandstone_White"
    },
    {
      "x": -14,
      "y": 16,
      "z": -1,
      "name": "Rock_Sandstone_White"
    },
    {
      "x": -14,
      "y": 17,
      "z": -1,
      "name": "Rock_Sandstone_White"
    },
    {
      "x": -14,
      "y": 18,
      "z": -1,
      "name": "Rock_Sandstone_White"
    },
    {
      "x": -14,
      "y": 19,
      "z": -1,
      "name": "Rock_Sandstone_White"
    },
    {
      "x": -14,
      "y": 20,
      "z": -1,
      "name": "Rock_Sandstone_White"
    },
    {
      "x": -14,
      "y": 21,
      "z": -1,
      "name": "Rock_Sandstone_White"
    },
    {
      "x": -14,
      "y": 22,
      "z": -1,
      "name": "Rock_Sandstone_White"
    },
    {
      "x": -14,
      "y": 23,
      "z": -1,
      "name": "Rock_Sandstone_White"
    },
    {
      "x": -14,
      "y": 24,
      "z": -1,
      "name": "Soil_Sand_White"
    },
    {
      "x": -14,
      "y": 25,
      "z": -1,
      "name": "Soil_Sand_White"
    },
    {
      "x": -14,
      "y": 26,
      "z": -1,
      "name": "Soil_Sand_White"
    },
    {
      "x": -14,
      "y": 27,
      "z": -1,
      "name": "Soil_Sand_White"
    },
    {
      "x": -14,
      "y": 28,
      "z": -1,
      "name": "Plant_Flower_Bushy_Yellow"
    },
    {
      "x": -14,
      "y": 16,
      "z": 0,
      "name": "Rock_Sandstone_White"
    },
    {
      "x": -14,
      "y": 17,
      "z": 0,
      "name": "Rock_Sandstone_White"
    },
    {
      "x": -14,
      "y": 18,
      "z": 0,
      "name": "Rock_Sandstone_White"
    },
    {
      "x": -14,
      "y": 19,
      "z": 0,
      "name": "Rock_Sandstone_White"
    },
    {
      "x": -14,
      "y": 20,
      "z": 0,
      "name": "Rock_Sandstone_White"
    },
    {
      "x": -14,
      "y": 21,
      "z": 0,
      "name": "Rock_Sandstone_White"
    },
    {
      "x": -14,
      "y": 22,
      "z": 0,
      "name": "Rock_Sandstone_White"
    },
    {
      "x": -14,
      "y": 23,
      "z": 0,
      "name": "Rock_Sandstone_White"
    },
    {
      "x": -14,
      "y": 24,
      "z": 0,
      "name": "Soil_Sand_White"
    },
    {
      "x": -14,
      "y": 25,
      "z": 0,
      "name": "Soil_Gravel_Sand_White"
    },
    {
      "x": -14,
      "y": 26,
      "z": 0,
      "name": "Soil_Gravel_Sand_White"
    },
    {
      "x": -14,
      "y": 27,
      "z": 0,
      "name": "Soil_Sand_White"
    },
    {
      "x": -14,
      "y": 17,
      "z": 1,
      "name": "Rock_Sandstone_White"
    },
    {
      "x": -14,
      "y": 18,
      "z": 1,
      "name": "Rock_Sandstone_White"
    },
    {
      "x": -14,
      "y": 19,
      "z": 1,
      "name": "Rock_Sandstone_White"
    },
    {
      "x": -14,
      "y": 20,
      "z": 1,
      "name": "Rock_Sandstone_White"
    },
    {
      "x": -14,
      "y": 21,
      "z": 1,
      "name": "Rock_Sandstone_White"
    },
    {
      "x": -14,
      "y": 22,
      "z": 1,
      "name": "Rock_Sandstone_White"
    },
    {
      "x": -14,
      "y": 23,
      "z": 1,
      "name": "Rock_Sandstone_White"
    },
    {
      "x": -14,
      "y": 24,
      "z": 1,
      "name": "Rock_Sandstone_White"
    },
    {
      "x": -14,
      "y": 25,
      "z": 1,
      "name": "Rock_Sandstone_White"
    },
    {
      "x": -14,
      "y": 26,
      "z": 1,
      "name": "Rock_Sandstone_White"
    },
    {
      "x": -14,
      "y": 27,
      "z": 1,
      "name": "Soil_Sand_White"
    },
    {
      "x": -14,
      "y": 28,
      "z": 1,
      "name": "Soil_Sand_White"
    },
    {
      "x": -14,
      "y": 18,
      "z": 2,
      "name": "Rock_Sandstone_White"
    },
    {
      "x": -14,
      "y": 19,
      "z": 2,
      "name": "Rock_Sandstone_White"
    },
    {
      "x": -14,
      "y": 20,
      "z": 2,
      "name": "Rock_Sandstone_White"
    },
    {
      "x": -14,
      "y": 21,
      "z": 2,
      "name": "Rock_Sandstone_White"
    },
    {
      "x": -14,
      "y": 22,
      "z": 2,
      "name": "Rock_Sandstone_White"
    },
    {
      "x": -14,
      "y": 23,
      "z": 2,
      "name": "Rock_Sandstone_White"
    },
    {
      "x": -14,
      "y": 24,
      "z": 2,
      "name": "Soil_Sand_White"
    },
    {
      "x": -14,
      "y": 25,
      "z": 2,
      "name": "Soil_Sand_White"
    },
    {
      "x": -14,
      "y": 26,
      "z": 2,
      "name": "Soil_Sand_White"
    },
    {
      "x": -14,
      "y": 27,
      "z": 2,
      "name": "Soil_Gravel_Sand_White"
    },
    {
      "x": -14,
      "y": 28,
      "z": 2,
      "name": "Soil_Sand_White"
    },
    {
      "x": -14,
      "y": 18,
      "z": 3,
      "name": "Rock_Sandstone_White"
    },
    {
      "x": -14,
      "y": 19,
      "z": 3,
      "name": "Rock_Sandstone_White"
    },
    {
      "x": -14,
      "y": 20,
      "z": 3,
      "name": "Rock_Sandstone_White"
    },
    {
      "x": -14,
      "y": 21,
      "z": 3,
      "name": "Rock_Sandstone_White"
    },
    {
      "x": -14,
      "y": 22,
      "z": 3,
      "name": "Rock_Sandstone_White"
    },
    {
      "x": -14,
      "y": 23,
      "z": 3,
      "name": "Rock_Sandstone_White"
    },
    {
      "x": -14,
      "y": 24,
      "z": 3,
      "name": "Soil_Sand_White"
    },
    {
      "x": -14,
      "y": 25,
      "z": 3,
      "name": "Soil_Sand_White"
    },
    {
      "x": -14,
      "y": 26,
      "z": 3,
      "name": "Soil_Sand_White"
    },
    {
      "x": -14,
      "y": 27,
      "z": 3,
      "name": "Soil_Sand_White"
    },
    {
      "x": -14,
      "y": 28,
      "z": 3,
      "name": "Soil_Sand_White"
    },
    {
      "x": -14,
      "y": 19,
      "z": 4,
      "name": "Rock_Sandstone_White"
    },
    {
      "x": -14,
      "y": 20,
      "z": 4,
      "name": "Rock_Sandstone_White"
    },
    {
      "x": -14,
      "y": 21,
      "z": 4,
      "name": "Rock_Sandstone_White"
    },
    {
      "x": -14,
      "y": 22,
      "z": 4,
      "name": "Rock_Sandstone_White"
    },
    {
      "x": -14,
      "y": 23,
      "z": 4,
      "name": "Rock_Sandstone_White"
    },
    {
      "x": -14,
      "y": 24,
      "z": 4,
      "name": "Rock_Sandstone_White"
    },
    {
      "x": -14,
      "y": 25,
      "z": 4,
      "name": "Soil_Gravel_Sand_White"
    },
    {
      "x": -14,
      "y": 26,
      "z": 4,
      "name": "Soil_Sand_White"
    },
    {
      "x": -14,
      "y": 27,
      "z": 4,
      "name": "Soil_Gravel_Sand_White"
    },
    {
      "x": -14,
      "y": 28,
      "z": 4,
      "name": "Soil_Sand_White"
    },
    {
      "x": -14,
      "y": 21,
      "z": 5,
      "name": "Rock_Sandstone_White"
    },
    {
      "x": -14,
      "y": 22,
      "z": 5,
      "name": "Rock_Sandstone_White"
    },
    {
      "x": -14,
      "y": 23,
      "z": 5,
      "name": "Rock_Sandstone_White"
    },
    {
      "x": -14,
      "y": 24,
      "z": 5,
      "name": "Rock_Sandstone_White"
    },
    {
      "x": -14,
      "y": 25,
      "z": 5,
      "name": "Rock_Sandstone_White"
    },
    {
      "x": -14,
      "y": 26,
      "z": 5,
      "name": "Soil_Sand_White"
    },
    {
      "x": -14,
      "y": 27,
      "z": 5,
      "name": "Soil_Sand_White"
    },
    {
      "x": -14,
      "y": 28,
      "z": 5,
      "name": "Soil_Sand_White"
    },
    {
      "x": -14,
      "y": 25,
      "z": 6,
      "name": "Soil_Sand_White"
    },
    {
      "x": -14,
      "y": 26,
      "z": 6,
      "name": "Soil_Sand_White"
    },
    {
      "x": -14,
      "y": 27,
      "z": 6,
      "name": "Soil_Sand_White"
    },
    {
      "x": -14,
      "y": 28,
      "z": 6,
      "name": "Soil_Sand_White"
    },
    {
      "x": -14,
      "y": 19,
      "z": 11,
      "name": "Soil_Sand_White"
    },
    {
      "x": -14,
      "y": 20,
      "z": 11,
      "name": "Soil_Sand_White"
    },
    {
      "x": -14,
      "y": 21,
      "z": 11,
      "name": "Soil_Gravel_Sand_White"
    },
    {
      "x": -14,
      "y": 22,
      "z": 11,
      "name": "Plant_Crop_Stamina1"
    },
    {
      "x": -14,
      "y": 15,
      "z": 12,
      "name": "Rock_Sandstone_White"
    },
    {
      "x": -14,
      "y": 16,
      "z": 12,
      "name": "Rock_Sandstone_White"
    },
    {
      "x": -14,
      "y": 17,
      "z": 12,
      "name": "Rock_Sandstone_White"
    },
    {
      "x": -14,
      "y": 18,
      "z": 12,
      "name": "Rock_Sandstone_White"
    },
    {
      "x": -14,
      "y": 19,
      "z": 12,
      "name": "Soil_Sand_White"
    },
    {
      "x": -14,
      "y": 20,
      "z": 12,
      "name": "Soil_Sand_White"
    },
    {
      "x": -14,
      "y": 21,
      "z": 12,
      "name": "Soil_Sand_White"
    },
    {
      "x": -14,
      "y": 22,
      "z": 12,
      "name": "Soil_Sand_White"
    },
    {
      "x": -14,
      "y": 13,
      "z": 13,
      "name": "Rock_Sandstone_White"
    },
    {
      "x": -14,
      "y": 14,
      "z": 13,
      "name": "Rock_Sandstone_White"
    },
    {
      "x": -14,
      "y": 15,
      "z": 13,
      "name": "Rock_Sandstone_White"
    },
    {
      "x": -14,
      "y": 16,
      "z": 13,
      "name": "Rock_Sandstone_White"
    },
    {
      "x": -14,
      "y": 17,
      "z": 13,
      "name": "Rock_Sandstone_White"
    },
    {
      "x": -14,
      "y": 18,
      "z": 13,
      "name": "Rock_Sandstone_White"
    },
    {
      "x": -14,
      "y": 19,
      "z": 13,
      "name": "Rock_Sandstone_White"
    },
    {
      "x": -14,
      "y": 20,
      "z": 13,
      "name": "Rock_Sandstone_White"
    },
    {
      "x": -14,
      "y": 21,
      "z": 13,
      "name": "Rock_Sandstone_White"
    },
    {
      "x": -14,
      "y": 22,
      "z": 13,
      "name": "Rock_Sandstone_White_Brick"
    },
    {
      "x": -14,
      "y": 9,
      "z": 14,
      "name": "Rock_Crystal_Yellow_Medium",
      "rotation": 6
    },
    {
      "x": -14,
      "y": 10,
      "z": 14,
      "name": "Rock_Crystal_Yellow_Medium",
      "rotation": 6
    },
    {
      "x": -14,
      "y": 11,
      "z": 14,
      "name": "Rock_Crystal_Yellow_Medium",
      "rotation": 6
    },
    {
      "x": -14,
      "y": 12,
      "z": 14,
      "name": "Rock_Sandstone_White"
    },
    {
      "x": -14,
      "y": 13,
      "z": 14,
      "name": "Rock_Sandstone_White"
    },
    {
      "x": -14,
      "y": 14,
      "z": 14,
      "name": "Rock_Sandstone_White"
    },
    {
      "x": -14,
      "y": 15,
      "z": 14,
      "name": "Rock_Sandstone_White"
    },
    {
      "x": -14,
      "y": 16,
      "z": 14,
      "name": "Rock_Sandstone_White"
    },
    {
      "x": -14,
      "y": 17,
      "z": 14,
      "name": "Rock_Sandstone_White"
    },
    {
      "x": -14,
      "y": 18,
      "z": 14,
      "name": "Rock_Sandstone_White"
    },
    {
      "x": -14,
      "y": 19,
      "z": 14,
      "name": "Rock_Sandstone_White"
    },
    {
      "x": -14,
      "y": 20,
      "z": 14,
      "name": "Rock_Sandstone_White"
    },
    {
      "x": -14,
      "y": 21,
      "z": 14,
      "name": "Rock_Sandstone_White"
    },
    {
      "x": -14,
      "y": 22,
      "z": 14,
      "name": "Rock_Sandstone_White_Brick"
    },
    {
      "x": -14,
      "y": 23,
      "z": 14,
      "name": "Block_Spawner_Block",
      "components": {
        "Components": {
          "PlacedByInteraction": {
            "WhoPlacedUuid": {
              "$binary": "3XRzOktQTQGfL/+8x7+CHA==",
              "$type": "04"
            }
          },
          "BlockSpawner": {
            "BlockSpawnerId": "Zone4_Encounters_Tier4"
          }
        }
      },
      "rotation": 1
    },
    {
      "x": -14,
      "y": 8,
      "z": 15,
      "name": "Rock_Crystal_Yellow_Medium",
      "rotation": 8
    },
    {
      "x": -14,
      "y": 9,
      "z": 15,
      "name": "Rock_Crystal_Yellow_Block"
    },
    {
      "x": -14,
      "y": 10,
      "z": 15,
      "name": "Rock_Crystal_Yellow_Block"
    },
    {
      "x": -14,
      "y": 11,
      "z": 15,
      "name": "Rock_Crystal_Yellow_Block"
    },
    {
      "x": -14,
      "y": 12,
      "z": 15,
      "name": "Rock_Crystal_Yellow_Block"
    },
    {
      "x": -14,
      "y": 13,
      "z": 15,
      "name": "Rock_Crystal_Yellow_Block"
    },
    {
      "x": -14,
      "y": 14,
      "z": 15,
      "name": "Rock_Crystal_Yellow_Block"
    },
    {
      "x": -14,
      "y": 15,
      "z": 15,
      "name": "Rock_Sandstone_White"
    },
    {
      "x": -14,
      "y": 16,
      "z": 15,
      "name": "Rock_Sandstone_White"
    },
    {
      "x": -14,
      "y": 17,
      "z": 15,
      "name": "Rock_Sandstone_White"
    },
    {
      "x": -14,
      "y": 18,
      "z": 15,
      "name": "Rock_Sandstone_White"
    },
    {
      "x": -14,
      "y": 19,
      "z": 15,
      "name": "Rock_Sandstone_White"
    },
    {
      "x": -14,
      "y": 20,
      "z": 15,
      "name": "Rock_Sandstone_White"
    },
    {
      "x": -14,
      "y": 21,
      "z": 15,
      "name": "Rock_Sandstone_White"
    },
    {
      "x": -14,
      "y": 22,
      "z": 15,
      "name": "Rock_Sandstone_White_Brick"
    },
    {
      "x": -14,
      "y": 8,
      "z": 16,
      "name": "Rock_Crystal_Yellow_Medium",
      "rotation": 7
    },
    {
      "x": -14,
      "y": 9,
      "z": 16,
      "name": "Rock_Crystal_Yellow_Medium",
      "rotation": 4
    },
    {
      "x": -14,
      "y": 11,
      "z": 16,
      "name": "Rock_Crystal_Yellow_Large",
      "rotation": 7
    },
    {
      "x": -14,
      "y": 12,
      "z": 16,
      "name": "Rock_Sandstone_White"
    },
    {
      "x": -14,
      "y": 13,
      "z": 16,
      "name": "Rock_Sandstone_White"
    },
    {
      "x": -14,
      "y": 14,
      "z": 16,
      "name": "Rock_Sandstone_White"
    },
    {
      "x": -14,
      "y": 15,
      "z": 16,
      "name": "Rock_Sandstone_White"
    },
    {
      "x": -14,
      "y": 16,
      "z": 16,
      "name": "Rock_Sandstone_White"
    },
    {
      "x": -14,
      "y": 17,
      "z": 16,
      "name": "Rock_Sandstone_White"
    },
    {
      "x": -14,
      "y": 18,
      "z": 16,
      "name": "Rock_Sandstone_White"
    },
    {
      "x": -14,
      "y": 19,
      "z": 16,
      "name": "Rock_Sandstone_White"
    },
    {
      "x": -14,
      "y": 20,
      "z": 16,
      "name": "Rock_Sandstone_White"
    },
    {
      "x": -14,
      "y": 21,
      "z": 16,
      "name": "Rock_Sandstone_White"
    },
    {
      "x": -14,
      "y": 22,
      "z": 16,
      "name": "Rock_Sandstone_White_Brick"
    },
    {
      "x": -14,
      "y": 23,
      "z": 16,
      "name": "Rock_Sandstone_White_Brick_Pillar_Middle",
      "rotation": 7
    },
    {
      "x": -14,
      "y": 12,
      "z": 17,
      "name": "Rock_Sandstone_White_Stalactite_Small",
      "rotation": 9
    },
    {
      "x": -14,
      "y": 13,
      "z": 17,
      "name": "Rock_Sandstone_White"
    },
    {
      "x": -14,
      "y": 14,
      "z": 17,
      "name": "Rock_Sandstone_White"
    },
    {
      "x": -14,
      "y": 15,
      "z": 17,
      "name": "Rock_Sandstone_White"
    },
    {
      "x": -14,
      "y": 16,
      "z": 17,
      "name": "Rock_Sandstone_White"
    },
    {
      "x": -14,
      "y": 17,
      "z": 17,
      "name": "Rock_Sandstone_White"
    },
    {
      "x": -14,
      "y": 18,
      "z": 17,
      "name": "Rock_Sandstone_White"
    },
    {
      "x": -14,
      "y": 19,
      "z": 17,
      "name": "Rock_Sandstone_White"
    },
    {
      "x": -14,
      "y": 20,
      "z": 17,
      "name": "Soil_Sand_White"
    },
    {
      "x": -14,
      "y": 21,
      "z": 17,
      "name": "Soil_Sand_White"
    },
    {
      "x": -14,
      "y": 22,
      "z": 17,
      "name": "Soil_Sand_White"
    },
    {
      "x": -14,
      "y": 15,
      "z": 18,
      "name": "Rock_Sandstone_White"
    },
    {
      "x": -14,
      "y": 16,
      "z": 18,
      "name": "Rock_Sandstone_White"
    },
    {
      "x": -14,
      "y": 17,
      "z": 18,
      "name": "Rock_Sandstone_White"
    },
    {
      "x": -14,
      "y": 18,
      "z": 18,
      "name": "Rock_Sandstone_White"
    },
    {
      "x": -14,
      "y": 19,
      "z": 18,
      "name": "Rock_Sandstone_White"
    },
    {
      "x": -14,
      "y": 20,
      "z": 18,
      "name": "Soil_Sand_White"
    },
    {
      "x": -14,
      "y": 21,
      "z": 18,
      "name": "Soil_Sand_White"
    },
    {
      "x": -14,
      "y": 22,
      "z": 18,
      "name": "Soil_Sand_White"
    },
    {
      "x": -14,
      "y": 19,
      "z": 19,
      "name": "Soil_Sand_White"
    },
    {
      "x": -14,
      "y": 20,
      "z": 19,
      "name": "Soil_Sand_White"
    },
    {
      "x": -14,
      "y": 21,
      "z": 19,
      "name": "Soil_Sand_White"
    },
    {
      "x": -13,
      "y": 16,
      "z": -13,
      "name": "Rock_Sandstone_White"
    },
    {
      "x": -13,
      "y": 17,
      "z": -13,
      "name": "Rock_Sandstone_White"
    },
    {
      "x": -13,
      "y": 18,
      "z": -13,
      "name": "Rock_Sandstone_White"
    },
    {
      "x": -13,
      "y": 19,
      "z": -13,
      "name": "Rock_Sandstone_White"
    },
    {
      "x": -13,
      "y": 20,
      "z": -13,
      "name": "Rock_Sandstone_White"
    },
    {
      "x": -13,
      "y": 21,
      "z": -13,
      "name": "Soil_Sand_White"
    },
    {
      "x": -13,
      "y": 22,
      "z": -13,
      "name": "Soil_Sand_White"
    },
    {
      "x": -13,
      "y": 23,
      "z": -13,
      "name": "Soil_Sand_White"
    },
    {
      "x": -13,
      "y": 14,
      "z": -12,
      "name": "Rock_Sandstone_White"
    },
    {
      "x": -13,
      "y": 15,
      "z": -12,
      "name": "Rock_Sandstone_White"
    },
    {
      "x": -13,
      "y": 16,
      "z": -12,
      "name": "Rock_Sandstone_White"
    },
    {
      "x": -13,
      "y": 17,
      "z": -12,
      "name": "Rock_Sandstone_White"
    },
    {
      "x": -13,
      "y": 18,
      "z": -12,
      "name": "Rock_Sandstone_White"
    },
    {
      "x": -13,
      "y": 19,
      "z": -12,
      "name": "Rock_Sandstone_White"
    },
    {
      "x": -13,
      "y": 20,
      "z": -12,
      "name": "Soil_Sand_White"
    },
    {
      "x": -13,
      "y": 21,
      "z": -12,
      "name": "Soil_Sand_White"
    },
    {
      "x": -13,
      "y": 22,
      "z": -12,
      "name": "Soil_Sand_White"
    },
    {
      "x": -13,
      "y": 23,
      "z": -12,
      "name": "Soil_Sand_White"
    },
    {
      "x": -13,
      "y": 13,
      "z": -11,
      "name": "Rock_Sandstone_White"
    },
    {
      "x": -13,
      "y": 14,
      "z": -11,
      "name": "Rock_Sandstone_White"
    },
    {
      "x": -13,
      "y": 15,
      "z": -11,
      "name": "Rock_Sandstone_White"
    },
    {
      "x": -13,
      "y": 16,
      "z": -11,
      "name": "Rock_Sandstone_White"
    },
    {
      "x": -13,
      "y": 17,
      "z": -11,
      "name": "Rock_Sandstone_White"
    },
    {
      "x": -13,
      "y": 18,
      "z": -11,
      "name": "Rock_Sandstone_White"
    },
    {
      "x": -13,
      "y": 19,
      "z": -11,
      "name": "Rock_Sandstone_White"
    },
    {
      "x": -13,
      "y": 20,
      "z": -11,
      "name": "Rock_Sandstone_White"
    },
    {
      "x": -13,
      "y": 21,
      "z": -11,
      "name": "Soil_Sand_White"
    },
    {
      "x": -13,
      "y": 22,
      "z": -11,
      "name": "Soil_Sand_White"
    },
    {
      "x": -13,
      "y": 23,
      "z": -11,
      "name": "Soil_Sand_White"
    },
    {
      "x": -13,
      "y": 24,
      "z": -11,
      "name": "Soil_Sand_White"
    },
    {
      "x": -13,
      "y": 13,
      "z": -10,
      "name": "Rock_Sandstone_White"
    },
    {
      "x": -13,
      "y": 14,
      "z": -10,
      "name": "Rock_Sandstone_White"
    },
    {
      "x": -13,
      "y": 15,
      "z": -10,
      "name": "Rock_Sandstone_White"
    },
    {
      "x": -13,
      "y": 16,
      "z": -10,
      "name": "Rock_Sandstone_White"
    },
    {
      "x": -13,
      "y": 17,
      "z": -10,
      "name": "Rock_Sandstone_White"
    },
    {
      "x": -13,
      "y": 18,
      "z": -10,
      "name": "Rock_Sandstone_White"
    },
    {
      "x": -13,
      "y": 19,
      "z": -10,
      "name": "Rock_Sandstone_White"
    },
    {
      "x": -13,
      "y": 20,
      "z": -10,
      "name": "Rock_Sandstone_White"
    },
    {
      "x": -13,
      "y": 21,
      "z": -10,
      "name": "Soil_Sand_White"
    },
    {
      "x": -13,
      "y": 22,
      "z": -10,
      "name": "Soil_Sand_White"
    },
    {
      "x": -13,
      "y": 23,
      "z": -10,
      "name": "Soil_Sand_White"
    },
    {
      "x": -13,
      "y": 24,
      "z": -10,
      "name": "Soil_Sand_White"
    },
    {
      "x": -13,
      "y": 13,
      "z": -9,
      "name": "Rock_Sandstone_White"
    },
    {
      "x": -13,
      "y": 14,
      "z": -9,
      "name": "Rock_Sandstone_White"
    },
    {
      "x": -13,
      "y": 15,
      "z": -9,
      "name": "Rock_Sandstone_White"
    },
    {
      "x": -13,
      "y": 16,
      "z": -9,
      "name": "Rock_Sandstone_White"
    },
    {
      "x": -13,
      "y": 17,
      "z": -9,
      "name": "Rock_Sandstone_White"
    },
    {
      "x": -13,
      "y": 18,
      "z": -9,
      "name": "Rock_Sandstone_White"
    },
    {
      "x": -13,
      "y": 19,
      "z": -9,
      "name": "Rock_Sandstone_White"
    },
    {
      "x": -13,
      "y": 20,
      "z": -9,
      "name": "Rock_Sandstone_White"
    },
    {
      "x": -13,
      "y": 21,
      "z": -9,
      "name": "Rock_Sandstone_White"
    },
    {
      "x": -13,
      "y": 22,
      "z": -9,
      "name": "Soil_Sand_White"
    },
    {
      "x": -13,
      "y": 23,
      "z": -9,
      "name": "Soil_Sand_White"
    },
    {
      "x": -13,
      "y": 24,
      "z": -9,
      "name": "Soil_Sand_White"
    },
    {
      "x": -13,
      "y": 25,
      "z": -9,
      "name": "Soil_Sand_White"
    },
    {
      "x": -13,
      "y": 14,
      "z": -8,
      "name": "Rock_Sandstone_White"
    },
    {
      "x": -13,
      "y": 15,
      "z": -8,
      "name": "Rock_Sandstone_White"
    },
    {
      "x": -13,
      "y": 16,
      "z": -8,
      "name": "Rock_Sandstone_White"
    },
    {
      "x": -13,
      "y": 17,
      "z": -8,
      "name": "Rock_Sandstone_White"
    },
    {
      "x": -13,
      "y": 18,
      "z": -8,
      "name": "Rock_Sandstone_White"
    },
    {
      "x": -13,
      "y": 19,
      "z": -8,
      "name": "Rock_Sandstone_White"
    },
    {
      "x": -13,
      "y": 20,
      "z": -8,
      "name": "Rock_Sandstone_White"
    },
    {
      "x": -13,
      "y": 21,
      "z": -8,
      "name": "Soil_Sand_White"
    },
    {
      "x": -13,
      "y": 22,
      "z": -8,
      "name": "Soil_Sand_White"
    },
    {
      "x": -13,
      "y": 23,
      "z": -8,
      "name": "Soil_Sand_White"
    },
    {
      "x": -13,
      "y": 24,
      "z": -8,
      "name": "Soil_Sand_White"
    },
    {
      "x": -13,
      "y": 25,
      "z": -8,
      "name": "Soil_Sand_White"
    },
    {
      "x": -13,
      "y": 13,
      "z": -7,
      "name": "Rock_Sandstone_White"
    },
    {
      "x": -13,
      "y": 14,
      "z": -7,
      "name": "Rock_Sandstone_White"
    },
    {
      "x": -13,
      "y": 15,
      "z": -7,
      "name": "Rock_Sandstone_White"
    },
    {
      "x": -13,
      "y": 16,
      "z": -7,
      "name": "Rock_Sandstone_White"
    },
    {
      "x": -13,
      "y": 17,
      "z": -7,
      "name": "Rock_Sandstone_White"
    },
    {
      "x": -13,
      "y": 18,
      "z": -7,
      "name": "Rock_Sandstone_White"
    },
    {
      "x": -13,
      "y": 19,
      "z": -7,
      "name": "Rock_Sandstone_White"
    },
    {
      "x": -13,
      "y": 20,
      "z": -7,
      "name": "Rock_Sandstone_White"
    },
    {
      "x": -13,
      "y": 21,
      "z": -7,
      "name": "Soil_Sand_White"
    },
    {
      "x": -13,
      "y": 22,
      "z": -7,
      "name": "Soil_Sand_White"
    },
    {
      "x": -13,
      "y": 23,
      "z": -7,
      "name": "Soil_Sand_White"
    },
    {
      "x": -13,
      "y": 24,
      "z": -7,
      "name": "Soil_Sand_White"
    },
    {
      "x": -13,
      "y": 25,
      "z": -7,
      "name": "Soil_Gravel_Sand_White"
    },
    {
      "x": -13,
      "y": 14,
      "z": -6,
      "name": "Rock_Sandstone_White"
    },
    {
      "x": -13,
      "y": 15,
      "z": -6,
      "name": "Rock_Sandstone_White"
    },
    {
      "x": -13,
      "y": 16,
      "z": -6,
      "name": "Rock_Sandstone_White"
    },
    {
      "x": -13,
      "y": 17,
      "z": -6,
      "name": "Rock_Sandstone_White"
    },
    {
      "x": -13,
      "y": 18,
      "z": -6,
      "name": "Rock_Sandstone_White"
    },
    {
      "x": -13,
      "y": 19,
      "z": -6,
      "name": "Rock_Sandstone_White"
    },
    {
      "x": -13,
      "y": 20,
      "z": -6,
      "name": "Rock_Sandstone_White"
    },
    {
      "x": -13,
      "y": 21,
      "z": -6,
      "name": "Rock_Sandstone_White"
    },
    {
      "x": -13,
      "y": 22,
      "z": -6,
      "name": "Rock_Sandstone_White"
    },
    {
      "x": -13,
      "y": 23,
      "z": -6,
      "name": "Soil_Sand_White"
    },
    {
      "x": -13,
      "y": 24,
      "z": -6,
      "name": "Soil_Sand_White"
    },
    {
      "x": -13,
      "y": 25,
      "z": -6,
      "name": "Soil_Gravel_Sand_White"
    },
    {
      "x": -13,
      "y": 15,
      "z": -5,
      "name": "Rock_Sandstone_White"
    },
    {
      "x": -13,
      "y": 16,
      "z": -5,
      "name": "Rock_Sandstone_White"
    },
    {
      "x": -13,
      "y": 17,
      "z": -5,
      "name": "Rock_Sandstone_White"
    },
    {
      "x": -13,
      "y": 18,
      "z": -5,
      "name": "Rock_Sandstone_White"
    },
    {
      "x": -13,
      "y": 19,
      "z": -5,
      "name": "Rock_Sandstone_White"
    },
    {
      "x": -13,
      "y": 20,
      "z": -5,
      "name": "Rock_Sandstone_White"
    },
    {
      "x": -13,
      "y": 21,
      "z": -5,
      "name": "Rock_Sandstone_White"
    },
    {
      "x": -13,
      "y": 22,
      "z": -5,
      "name": "Soil_Sand_White"
    },
    {
      "x": -13,
      "y": 23,
      "z": -5,
      "name": "Soil_Sand_White"
    },
    {
      "x": -13,
      "y": 24,
      "z": -5,
      "name": "Soil_Gravel_Sand_White"
    },
    {
      "x": -13,
      "y": 25,
      "z": -5,
      "name": "Soil_Sand_White"
    },
    {
      "x": -13,
      "y": 16,
      "z": -4,
      "name": "Rock_Sandstone_White"
    },
    {
      "x": -13,
      "y": 17,
      "z": -4,
      "name": "Rock_Sandstone_White"
    },
    {
      "x": -13,
      "y": 18,
      "z": -4,
      "name": "Rock_Sandstone_White"
    },
    {
      "x": -13,
      "y": 19,
      "z": -4,
      "name": "Rock_Sandstone_White"
    },
    {
      "x": -13,
      "y": 20,
      "z": -4,
      "name": "Rock_Sandstone_White"
    },
    {
      "x": -13,
      "y": 21,
      "z": -4,
      "name": "Rock_Sandstone_White"
    },
    {
      "x": -13,
      "y": 22,
      "z": -4,
      "name": "Rock_Sandstone_White"
    },
    {
      "x": -13,
      "y": 23,
      "z": -4,
      "name": "Soil_Sand_White"
    },
    {
      "x": -13,
      "y": 24,
      "z": -4,
      "name": "Soil_Sand_White"
    },
    {
      "x": -13,
      "y": 25,
      "z": -4,
      "name": "Soil_Sand_White"
    },
    {
      "x": -13,
      "y": 26,
      "z": -4,
      "name": "Plant_Flower_Bushy_Yellow"
    },
    {
      "x": -13,
      "y": 15,
      "z": -3,
      "name": "Rock_Sandstone_White"
    },
    {
      "x": -13,
      "y": 16,
      "z": -3,
      "name": "Rock_Sandstone_White"
    },
    {
      "x": -13,
      "y": 17,
      "z": -3,
      "name": "Rock_Sandstone_White"
    },
    {
      "x": -13,
      "y": 18,
      "z": -3,
      "name": "Rock_Sandstone_White"
    },
    {
      "x": -13,
      "y": 19,
      "z": -3,
      "name": "Rock_Sandstone_White"
    },
    {
      "x": -13,
      "y": 20,
      "z": -3,
      "name": "Rock_Sandstone_White"
    },
    {
      "x": -13,
      "y": 21,
      "z": -3,
      "name": "Rock_Sandstone_White"
    },
    {
      "x": -13,
      "y": 22,
      "z": -3,
      "name": "Rock_Sandstone_White"
    },
    {
      "x": -13,
      "y": 23,
      "z": -3,
      "name": "Rock_Sandstone_White"
    },
    {
      "x": -13,
      "y": 24,
      "z": -3,
      "name": "Soil_Sand_White"
    },
    {
      "x": -13,
      "y": 25,
      "z": -3,
      "name": "Soil_Sand_White"
    },
    {
      "x": -13,
      "y": 26,
      "z": -3,
      "name": "Soil_Sand_White"
    },
    {
      "x": -13,
      "y": 11,
      "z": -2,
      "name": "Rock_Crystal_Yellow_Medium",
      "rotation": 7
    },
    {
      "x": -13,
      "y": 12,
      "z": -2,
      "name": "Rock_Crystal_Yellow_Medium",
      "rotation": 7
    },
    {
      "x": -13,
      "y": 13,
      "z": -2,
      "name": "Rock_Crystal_Yellow_Medium",
      "rotation": 7
    },
    {
      "x": -13,
      "y": 14,
      "z": -2,
      "name": "Rock_Sandstone_White"
    },
    {
      "x": -13,
      "y": 15,
      "z": -2,
      "name": "Rock_Sandstone_White"
    },
    {
      "x": -13,
      "y": 16,
      "z": -2,
      "name": "Rock_Sandstone_White"
    },
    {
      "x": -13,
      "y": 17,
      "z": -2,
      "name": "Rock_Sandstone_White"
    },
    {
      "x": -13,
      "y": 18,
      "z": -2,
      "name": "Rock_Sandstone_White"
    },
    {
      "x": -13,
      "y": 19,
      "z": -2,
      "name": "Rock_Sandstone_White"
    },
    {
      "x": -13,
      "y": 20,
      "z": -2,
      "name": "Rock_Sandstone_White"
    },
    {
      "x": -13,
      "y": 21,
      "z": -2,
      "name": "Rock_Sandstone_White"
    },
    {
      "x": -13,
      "y": 22,
      "z": -2,
      "name": "Rock_Sandstone_White"
    },
    {
      "x": -13,
      "y": 23,
      "z": -2,
      "name": "Rock_Sandstone_White"
    },
    {
      "x": -13,
      "y": 24,
      "z": -2,
      "name": "Soil_Sand_White"
    },
    {
      "x": -13,
      "y": 25,
      "z": -2,
      "name": "Soil_Sand_White"
    },
    {
      "x": -13,
      "y": 26,
      "z": -2,
      "name": "Soil_Sand_White"
    },
    {
      "x": -13,
      "y": 27,
      "z": -2,
      "name": "Soil_Gravel_Sand_White"
    },
    {
      "x": -13,
      "y": 13,
      "z": -1,
      "name": "Rock_Sandstone_White"
    },
    {
      "x": -13,
      "y": 14,
      "z": -1,
      "name": "Rock_Sandstone_White"
    },
    {
      "x": -13,
      "y": 15,
      "z": -1,
      "name": "Rock_Sandstone_White"
    },
    {
      "x": -13,
      "y": 16,
      "z": -1,
      "name": "Rock_Sandstone_White"
    },
    {
      "x": -13,
      "y": 17,
      "z": -1,
      "name": "Rock_Sandstone_White"
    },
    {
      "x": -13,
      "y": 18,
      "z": -1,
      "name": "Rock_Sandstone_White"
    },
    {
      "x": -13,
      "y": 19,
      "z": -1,
      "name": "Rock_Sandstone_White"
    },
    {
      "x": -13,
      "y": 20,
      "z": -1,
      "name": "Rock_Sandstone_White"
    },
    {
      "x": -13,
      "y": 21,
      "z": -1,
      "name": "Rock_Sandstone_White"
    },
    {
      "x": -13,
      "y": 22,
      "z": -1,
      "name": "Rock_Sandstone_White"
    },
    {
      "x": -13,
      "y": 23,
      "z": -1,
      "name": "Rock_Sandstone_White"
    },
    {
      "x": -13,
      "y": 24,
      "z": -1,
      "name": "Soil_Sand_White"
    },
    {
      "x": -13,
      "y": 25,
      "z": -1,
      "name": "Soil_Sand_White"
    },
    {
      "x": -13,
      "y": 26,
      "z": -1,
      "name": "Soil_Sand_White"
    },
    {
      "x": -13,
      "y": 27,
      "z": -1,
      "name": "Soil_Sand_White"
    },
    {
      "x": -13,
      "y": 14,
      "z": 0,
      "name": "Rock_Sandstone_White"
    },
    {
      "x": -13,
      "y": 15,
      "z": 0,
      "name": "Rock_Sandstone_White"
    },
    {
      "x": -13,
      "y": 16,
      "z": 0,
      "name": "Rock_Sandstone_White"
    },
    {
      "x": -13,
      "y": 17,
      "z": 0,
      "name": "Rock_Sandstone_White"
    },
    {
      "x": -13,
      "y": 18,
      "z": 0,
      "name": "Rock_Sandstone_White"
    },
    {
      "x": -13,
      "y": 19,
      "z": 0,
      "name": "Rock_Sandstone_White"
    },
    {
      "x": -13,
      "y": 20,
      "z": 0,
      "name": "Rock_Sandstone_White"
    },
    {
      "x": -13,
      "y": 21,
      "z": 0,
      "name": "Rock_Sandstone_White"
    },
    {
      "x": -13,
      "y": 22,
      "z": 0,
      "name": "Rock_Sandstone_White"
    },
    {
      "x": -13,
      "y": 23,
      "z": 0,
      "name": "Rock_Sandstone_White"
    },
    {
      "x": -13,
      "y": 24,
      "z": 0,
      "name": "Soil_Sand_White"
    },
    {
      "x": -13,
      "y": 25,
      "z": 0,
      "name": "Soil_Sand_White"
    },
    {
      "x": -13,
      "y": 26,
      "z": 0,
      "name": "Soil_Sand_White"
    },
    {
      "x": -13,
      "y": 27,
      "z": 0,
      "name": "Soil_Sand_White"
    },
    {
      "x": -13,
      "y": 15,
      "z": 1,
      "name": "Rock_Sandstone_White"
    },
    {
      "x": -13,
      "y": 16,
      "z": 1,
      "name": "Rock_Sandstone_White"
    },
    {
      "x": -13,
      "y": 17,
      "z": 1,
      "name": "Rock_Sandstone_White"
    },
    {
      "x": -13,
      "y": 18,
      "z": 1,
      "name": "Rock_Sandstone_White"
    },
    {
      "x": -13,
      "y": 19,
      "z": 1,
      "name": "Rock_Sandstone_White"
    },
    {
      "x": -13,
      "y": 20,
      "z": 1,
      "name": "Rock_Sandstone_White"
    },
    {
      "x": -13,
      "y": 21,
      "z": 1,
      "name": "Rock_Sandstone_White"
    },
    {
      "x": -13,
      "y": 22,
      "z": 1,
      "name": "Rock_Sandstone_White"
    },
    {
      "x": -13,
      "y": 23,
      "z": 1,
      "name": "Rock_Sandstone_White"
    },
    {
      "x": -13,
      "y": 24,
      "z": 1,
      "name": "Rock_Sandstone_White"
    },
    {
      "x": -13,
      "y": 25,
      "z": 1,
      "name": "Soil_Sand_White"
    },
    {
      "x": -13,
      "y": 26,
      "z": 1,
      "name": "Soil_Sand_White"
    },
    {
      "x": -13,
      "y": 27,
      "z": 1,
      "name": "Soil_Gravel_Sand_White"
    },
    {
      "x": -13,
      "y": 28,
      "z": 1,
      "name": "Soil_Sand_White"
    },
    {
      "x": -13,
      "y": 17,
      "z": 2,
      "name": "Rock_Sandstone_White"
    },
    {
      "x": -13,
      "y": 18,
      "z": 2,
      "name": "Rock_Sandstone_White"
    },
    {
      "x": -13,
      "y": 19,
      "z": 2,
      "name": "Rock_Sandstone_White"
    },
    {
      "x": -13,
      "y": 20,
      "z": 2,
      "name": "Rock_Sandstone_White"
    },
    {
      "x": -13,
      "y": 21,
      "z": 2,
      "name": "Rock_Sandstone_White"
    },
    {
      "x": -13,
      "y": 22,
      "z": 2,
      "name": "Rock_Sandstone_White"
    },
    {
      "x": -13,
      "y": 23,
      "z": 2,
      "name": "Rock_Sandstone_White"
    },
    {
      "x": -13,
      "y": 24,
      "z": 2,
      "name": "Rock_Sandstone_White"
    },
    {
      "x": -13,
      "y": 25,
      "z": 2,
      "name": "Soil_Sand_White"
    },
    {
      "x": -13,
      "y": 26,
      "z": 2,
      "name": "Soil_Sand_White"
    },
    {
      "x": -13,
      "y": 27,
      "z": 2,
      "name": "Soil_Sand_White"
    },
    {
      "x": -13,
      "y": 28,
      "z": 2,
      "name": "Soil_Sand_White"
    },
    {
      "x": -13,
      "y": 19,
      "z": 3,
      "name": "Rock_Sandstone_White"
    },
    {
      "x": -13,
      "y": 20,
      "z": 3,
      "name": "Rock_Sandstone_White"
    },
    {
      "x": -13,
      "y": 21,
      "z": 3,
      "name": "Rock_Sandstone_White"
    },
    {
      "x": -13,
      "y": 22,
      "z": 3,
      "name": "Rock_Sandstone_White"
    },
    {
      "x": -13,
      "y": 23,
      "z": 3,
      "name": "Rock_Sandstone_White"
    },
    {
      "x": -13,
      "y": 24,
      "z": 3,
      "name": "Soil_Gravel_Sand_White"
    },
    {
      "x": -13,
      "y": 25,
      "z": 3,
      "name": "Soil_Sand_White"
    },
    {
      "x": -13,
      "y": 26,
      "z": 3,
      "name": "Soil_Sand_White"
    },
    {
      "x": -13,
      "y": 27,
      "z": 3,
      "name": "Soil_Gravel_Sand_White"
    },
    {
      "x": -13,
      "y": 28,
      "z": 3,
      "name": "Soil_Sand_White"
    },
    {
      "x": -13,
      "y": 20,
      "z": 4,
      "name": "Rock_Sandstone_White"
    },
    {
      "x": -13,
      "y": 21,
      "z": 4,
      "name": "Rock_Sandstone_White"
    },
    {
      "x": -13,
      "y": 22,
      "z": 4,
      "name": "Rock_Sandstone_White"
    },
    {
      "x": -13,
      "y": 23,
      "z": 4,
      "name": "Rock_Sandstone_White"
    },
    {
      "x": -13,
      "y": 24,
      "z": 4,
      "name": "Rock_Sandstone_White"
    },
    {
      "x": -13,
      "y": 25,
      "z": 4,
      "name": "Soil_Sand_White"
    },
    {
      "x": -13,
      "y": 26,
      "z": 4,
      "name": "Soil_Sand_White"
    },
    {
      "x": -13,
      "y": 27,
      "z": 4,
      "name": "Soil_Sand_White"
    },
    {
      "x": -13,
      "y": 28,
      "z": 4,
      "name": "Soil_Sand_White"
    },
    {
      "x": -13,
      "y": 22,
      "z": 5,
      "name": "Rock_Sandstone_White"
    },
    {
      "x": -13,
      "y": 23,
      "z": 5,
      "name": "Rock_Sandstone_White"
    },
    {
      "x": -13,
      "y": 24,
      "z": 5,
      "name": "Rock_Sandstone_White"
    },
    {
      "x": -13,
      "y": 25,
      "z": 5,
      "name": "Rock_Sandstone_White"
    },
    {
      "x": -13,
      "y": 26,
      "z": 5,
      "name": "Soil_Sand_White"
    },
    {
      "x": -13,
      "y": 27,
      "z": 5,
      "name": "Soil_Sand_White"
    },
    {
      "x": -13,
      "y": 28,
      "z": 5,
      "name": "Soil_Sand_White"
    },
    {
      "x": -13,
      "y": 26,
      "z": 6,
      "name": "Soil_Gravel_Sand_White"
    },
    {
      "x": -13,
      "y": 27,
      "z": 6,
      "name": "Soil_Sand_White"
    },
    {
      "x": -13,
      "y": 28,
      "z": 6,
      "name": "Soil_Sand_White"
    },
    {
      "x": -13,
      "y": 29,
      "z": 6,
      "name": "Plant_Crop_Stamina1"
    },
    {
      "x": -13,
      "y": 18,
      "z": 11,
      "name": "Rock_Sandstone_White"
    },
    {
      "x": -13,
      "y": 19,
      "z": 11,
      "name": "Soil_Sand_White"
    },
    {
      "x": -13,
      "y": 20,
      "z": 11,
      "name": "Soil_Gravel_Sand_White"
    },
    {
      "x": -13,
      "y": 21,
      "z": 11,
      "name": "Soil_Sand_White"
    },
    {
      "x": -13,
      "y": 22,
      "z": 11,
      "name": "Soil_Gravel_Sand_White"
    },
    {
      "x": -13,
      "y": 13,
      "z": 12,
      "name": "Rock_Sandstone_White_Stalactite_Small",
      "rotation": 8
    },
    {
      "x": -13,
      "y": 14,
      "z": 12,
      "name": "Rock_Sandstone_White"
    },
    {
      "x": -13,
      "y": 15,
      "z": 12,
      "name": "Rock_Sandstone_White"
    },
    {
      "x": -13,
      "y": 16,
      "z": 12,
      "name": "Rock_Sandstone_White"
    },
    {
      "x": -13,
      "y": 17,
      "z": 12,
      "name": "Rock_Sandstone_White"
    },
    {
      "x": -13,
      "y": 18,
      "z": 12,
      "name": "Rock_Sandstone_White"
    },
    {
      "x": -13,
      "y": 19,
      "z": 12,
      "name": "Soil_Sand_White"
    },
    {
      "x": -13,
      "y": 20,
      "z": 12,
      "name": "Soil_Sand_White"
    },
    {
      "x": -13,
      "y": 21,
      "z": 12,
      "name": "Soil_Sand_White"
    },
    {
      "x": -13,
      "y": 22,
      "z": 12,
      "name": "Soil_Sand_White"
    },
    {
      "x": -13,
      "y": 23,
      "z": 12,
      "name": "Rubble_Sandstone_White"
    },
    {
      "x": -13,
      "y": 10,
      "z": 13,
      "name": "Rock_Crystal_Yellow_Medium",
      "rotation": 6
    },
    {
      "x": -13,
      "y": 11,
      "z": 13,
      "name": "Rock_Crystal_Yellow_Medium",
      "rotation": 6
    },
    {
      "x": -13,
      "y": 12,
      "z": 13,
      "name": "Rock_Crystal_Yellow_Medium",
      "rotation": 6
    },
    {
      "x": -13,
      "y": 13,
      "z": 13,
      "name": "Rock_Sandstone_White"
    },
    {
      "x": -13,
      "y": 14,
      "z": 13,
      "name": "Rock_Sandstone_White"
    },
    {
      "x": -13,
      "y": 15,
      "z": 13,
      "name": "Rock_Sandstone_White"
    },
    {
      "x": -13,
      "y": 16,
      "z": 13,
      "name": "Rock_Sandstone_White"
    },
    {
      "x": -13,
      "y": 17,
      "z": 13,
      "name": "Rock_Sandstone_White"
    },
    {
      "x": -13,
      "y": 18,
      "z": 13,
      "name": "Rock_Sandstone_White"
    },
    {
      "x": -13,
      "y": 19,
      "z": 13,
      "name": "Rock_Sandstone_White"
    },
    {
      "x": -13,
      "y": 20,
      "z": 13,
      "name": "Rock_Sandstone_White"
    },
    {
      "x": -13,
      "y": 21,
      "z": 13,
      "name": "Rock_Sandstone_White"
    },
    {
      "x": -13,
      "y": 22,
      "z": 13,
      "name": "Rock_Sandstone_White_Brick"
    },
    {
      "x": -13,
      "y": 7,
      "z": 14,
      "name": "Rock_Crystal_Yellow_Medium",
      "rotation": 6
    },
    {
      "x": -13,
      "y": 8,
      "z": 14,
      "name": "Rock_Crystal_Yellow_Medium",
      "rotation": 6
    },
    {
      "x": -13,
      "y": 9,
      "z": 14,
      "name": "Rock_Crystal_Yellow_Large",
      "rotation": 8
    },
    {
      "x": -13,
      "y": 10,
      "z": 14,
      "name": "Rock_Crystal_Yellow_Block"
    },
    {
      "x": -13,
      "y": 11,
      "z": 14,
      "name": "Rock_Crystal_Yellow_Block"
    },
    {
      "x": -13,
      "y": 12,
      "z": 14,
      "name": "Rock_Crystal_Yellow_Block"
    },
    {
      "x": -13,
      "y": 13,
      "z": 14,
      "name": "Rock_Crystal_Yellow_Block"
    },
    {
      "x": -13,
      "y": 14,
      "z": 14,
      "name": "Rock_Crystal_Yellow_Block"
    },
    {
      "x": -13,
      "y": 15,
      "z": 14,
      "name": "Rock_Sandstone_White"
    },
    {
      "x": -13,
      "y": 16,
      "z": 14,
      "name": "Rock_Sandstone_White"
    },
    {
      "x": -13,
      "y": 17,
      "z": 14,
      "name": "Rock_Sandstone_White"
    },
    {
      "x": -13,
      "y": 18,
      "z": 14,
      "name": "Rock_Sandstone_White"
    },
    {
      "x": -13,
      "y": 19,
      "z": 14,
      "name": "Rock_Sandstone_White"
    },
    {
      "x": -13,
      "y": 20,
      "z": 14,
      "name": "Rock_Sandstone_White"
    },
    {
      "x": -13,
      "y": 21,
      "z": 14,
      "name": "Rock_Sandstone_White"
    },
    {
      "x": -13,
      "y": 22,
      "z": 14,
      "name": "Rock_Sandstone_White_Brick"
    },
    {
      "x": -13,
      "y": 6,
      "z": 15,
      "name": "Rock_Crystal_Yellow_Large",
      "rotation": 8
    },
    {
      "x": -13,
      "y": 7,
      "z": 15,
      "name": "Rock_Crystal_Yellow_Block"
    },
    {
      "x": -13,
      "y": 8,
      "z": 15,
      "name": "Rock_Crystal_Yellow_Block"
    },
    {
      "x": -13,
      "y": 9,
      "z": 15,
      "name": "Rock_Crystal_Yellow_Block"
    },
    {
      "x": -13,
      "y": 10,
      "z": 15,
      "name": "Rock_Crystal_Yellow_Block"
    },
    {
      "x": -13,
      "y": 11,
      "z": 15,
      "name": "Rock_Crystal_Yellow_Block"
    },
    {
      "x": -13,
      "y": 12,
      "z": 15,
      "name": "Soil_Dirt"
    },
    {
      "x": -13,
      "y": 13,
      "z": 15,
      "name": "Spawn_Labyrinth_Yellow_Circle"
    },
    {
      "x": -13,
      "y": 14,
      "z": 15,
      "name": "Rock_Crystal_Yellow_Block"
    },
    {
      "x": -13,
      "y": 15,
      "z": 15,
      "name": "Rock_Sandstone_White"
    },
    {
      "x": -13,
      "y": 16,
      "z": 15,
      "name": "Rock_Sandstone_White"
    },
    {
      "x": -13,
      "y": 17,
      "z": 15,
      "name": "Rock_Sandstone_White"
    },
    {
      "x": -13,
      "y": 18,
      "z": 15,
      "name": "Rock_Sandstone_White"
    },
    {
      "x": -13,
      "y": 19,
      "z": 15,
      "name": "Rock_Sandstone_White"
    },
    {
      "x": -13,
      "y": 20,
      "z": 15,
      "name": "Rock_Sandstone_White"
    },
    {
      "x": -13,
      "y": 21,
      "z": 15,
      "name": "Rock_Sandstone_White"
    },
    {
      "x": -13,
      "y": 22,
      "z": 15,
      "name": "Rock_Sandstone_White_Brick"
    },
    {
      "x": -13,
      "y": 7,
      "z": 16,
      "name": "Rock_Crystal_Yellow_Large",
      "rotation": 8
    },
    {
      "x": -13,
      "y": 8,
      "z": 16,
      "name": "Rock_Crystal_Yellow_Block"
    },
    {
      "x": -13,
      "y": 9,
      "z": 16,
      "name": "Rock_Crystal_Yellow_Block"
    },
    {
      "x": -13,
      "y": 10,
      "z": 16,
      "name": "Rock_Crystal_Yellow_Block"
    },
    {
      "x": -13,
      "y": 11,
      "z": 16,
      "name": "Rock_Crystal_Yellow_Block"
    },
    {
      "x": -13,
      "y": 12,
      "z": 16,
      "name": "Rock_Crystal_Yellow_Block"
    },
    {
      "x": -13,
      "y": 13,
      "z": 16,
      "name": "Rock_Crystal_Yellow_Block"
    },
    {
      "x": -13,
      "y": 14,
      "z": 16,
      "name": "Rock_Crystal_Yellow_Block"
    },
    {
      "x": -13,
      "y": 15,
      "z": 16,
      "name": "Rock_Sandstone_White"
    },
    {
      "x": -13,
      "y": 16,
      "z": 16,
      "name": "Rock_Sandstone_White"
    },
    {
      "x": -13,
      "y": 17,
      "z": 16,
      "name": "Rock_Sandstone_White"
    },
    {
      "x": -13,
      "y": 18,
      "z": 16,
      "name": "Rock_Sandstone_White"
    },
    {
      "x": -13,
      "y": 19,
      "z": 16,
      "name": "Rock_Sandstone_White"
    },
    {
      "x": -13,
      "y": 20,
      "z": 16,
      "name": "Rock_Sandstone_White"
    },
    {
      "x": -13,
      "y": 21,
      "z": 16,
      "name": "Rock_Sandstone_White"
    },
    {
      "x": -13,
      "y": 22,
      "z": 16,
      "name": "Rock_Sandstone_White_Brick"
    },
    {
      "x": -13,
      "y": 23,
      "z": 16,
      "name": "Rock_Sandstone_White_Brick_Pillar_Middle",
      "rotation": 7
    },
    {
      "x": -13,
      "y": 10,
      "z": 17,
      "name": "Rock_Crystal_Yellow_Medium",
      "rotation": 4
    },
    {
      "x": -13,
      "y": 11,
      "z": 17,
      "name": "Rock_Crystal_Yellow_Medium",
      "rotation": 4
    },
    {
      "x": -13,
      "y": 12,
      "z": 17,
      "name": "Rock_Sandstone_White"
    },
    {
      "x": -13,
      "y": 13,
      "z": 17,
      "name": "Rock_Sandstone_White"
    },
    {
      "x": -13,
      "y": 14,
      "z": 17,
      "name": "Rock_Sandstone_White"
    },
    {
      "x": -13,
      "y": 15,
      "z": 17,
      "name": "Rock_Sandstone_White"
    },
    {
      "x": -13,
      "y": 16,
      "z": 17,
      "name": "Rock_Sandstone_White"
    },
    {
      "x": -13,
      "y": 17,
      "z": 17,
      "name": "Rock_Sandstone_White"
    },
    {
      "x": -13,
      "y": 18,
      "z": 17,
      "name": "Rock_Sandstone_White"
    },
    {
      "x": -13,
      "y": 19,
      "z": 17,
      "name": "Rock_Sandstone_White"
    },
    {
      "x": -13,
      "y": 20,
      "z": 17,
      "name": "Rock_Sandstone_White"
    },
    {
      "x": -13,
      "y": 21,
      "z": 17,
      "name": "Soil_Sand_White"
    },
    {
      "x": -13,
      "y": 22,
      "z": 17,
      "name": "Soil_Gravel_Sand_White"
    },
    {
      "x": -13,
      "y": 12,
      "z": 18,
      "name": "Rock_Sandstone_White_Stalactite_Large",
      "filler": 31744,
      "rotation": 8
    },
    {
      "x": -13,
      "y": 13,
      "z": 18,
      "name": "Rock_Sandstone_White_Stalactite_Large",
      "rotation": 8
    },
    {
      "x": -13,
      "y": 14,
      "z": 18,
      "name": "Rock_Sandstone_White"
    },
    {
      "x": -13,
      "y": 15,
      "z": 18,
      "name": "Rock_Sandstone_White"
    },
    {
      "x": -13,
      "y": 16,
      "z": 18,
      "name": "Rock_Sandstone_White"
    },
    {
      "x": -13,
      "y": 17,
      "z": 18,
      "name": "Rock_Sandstone_White"
    },
    {
      "x": -13,
      "y": 18,
      "z": 18,
      "name": "Soil_Sand_White"
    },
    {
      "x": -13,
      "y": 19,
      "z": 18,
      "name": "Soil_Sand_White"
    },
    {
      "x": -13,
      "y": 20,
      "z": 18,
      "name": "Soil_Sand_White"
    },
    {
      "x": -13,
      "y": 21,
      "z": 18,
      "name": "Soil_Sand_White"
    },
    {
      "x": -13,
      "y": 18,
      "z": 19,
      "name": "Soil_Sand_White"
    },
    {
      "x": -13,
      "y": 19,
      "z": 19,
      "name": "Soil_Sand_White"
    },
    {
      "x": -13,
      "y": 20,
      "z": 19,
      "name": "Soil_Sand_White"
    },
    {
      "x": -13,
      "y": 21,
      "z": 19,
      "name": "Soil_Sand_White"
    },
    {
      "x": -12,
      "y": 17,
      "z": -13,
      "name": "Rock_Sandstone_White"
    },
    {
      "x": -12,
      "y": 18,
      "z": -13,
      "name": "Rock_Sandstone_White"
    },
    {
      "x": -12,
      "y": 19,
      "z": -13,
      "name": "Rock_Sandstone_White"
    },
    {
      "x": -12,
      "y": 20,
      "z": -13,
      "name": "Rock_Sandstone_White"
    },
    {
      "x": -12,
      "y": 21,
      "z": -13,
      "name": "Soil_Sand_White"
    },
    {
      "x": -12,
      "y": 22,
      "z": -13,
      "name": "Soil_Sand_White"
    },
    {
      "x": -12,
      "y": 15,
      "z": -12,
      "name": "Rock_Sandstone_White"
    },
    {
      "x": -12,
      "y": 16,
      "z": -12,
      "name": "Rock_Sandstone_White"
    },
    {
      "x": -12,
      "y": 17,
      "z": -12,
      "name": "Rock_Sandstone_White"
    },
    {
      "x": -12,
      "y": 18,
      "z": -12,
      "name": "Rock_Sandstone_White"
    },
    {
      "x": -12,
      "y": 19,
      "z": -12,
      "name": "Rock_Sandstone_White"
    },
    {
      "x": -12,
      "y": 20,
      "z": -12,
      "name": "Soil_Sand_White"
    },
    {
      "x": -12,
      "y": 21,
      "z": -12,
      "name": "Soil_Gravel_Sand_White"
    },
    {
      "x": -12,
      "y": 22,
      "z": -12,
      "name": "Soil_Gravel_Sand_White"
    },
    {
      "x": -12,
      "y": 23,
      "z": -12,
      "name": "Soil_Sand_White"
    },
    {
      "x": -12,
      "y": 24,
      "z": -12,
      "name": "Plant_Cactus_Flat_2"
    },
    {
      "x": -12,
      "y": 14,
      "z": -11,
      "name": "Rock_Sandstone_White"
    },
    {
      "x": -12,
      "y": 15,
      "z": -11,
      "name": "Rock_Sandstone_White"
    },
    {
      "x": -12,
      "y": 16,
      "z": -11,
      "name": "Rock_Sandstone_White"
    },
    {
      "x": -12,
      "y": 17,
      "z": -11,
      "name": "Rock_Sandstone_White"
    },
    {
      "x": -12,
      "y": 18,
      "z": -11,
      "name": "Rock_Sandstone_White"
    },
    {
      "x": -12,
      "y": 19,
      "z": -11,
      "name": "Rock_Sandstone_White"
    },
    {
      "x": -12,
      "y": 20,
      "z": -11,
      "name": "Soil_Sand_White"
    },
    {
      "x": -12,
      "y": 21,
      "z": -11,
      "name": "Soil_Sand_White"
    },
    {
      "x": -12,
      "y": 22,
      "z": -11,
      "name": "Soil_Gravel_Sand_White"
    },
    {
      "x": -12,
      "y": 23,
      "z": -11,
      "name": "Soil_Sand_White"
    },
    {
      "x": -12,
      "y": 24,
      "z": -11,
      "name": "Soil_Sand_White"
    },
    {
      "x": -12,
      "y": 25,
      "z": -11,
      "name": "Plant_Flower_Flax_Orange"
    },
    {
      "x": -12,
      "y": 12,
      "z": -10,
      "name": "Rock_Sandstone_White_Stalactite_Small",
      "rotation": 9
    },
    {
      "x": -12,
      "y": 13,
      "z": -10,
      "name": "Rock_Sandstone_White"
    },
    {
      "x": -12,
      "y": 14,
      "z": -10,
      "name": "Rock_Sandstone_White"
    },
    {
      "x": -12,
      "y": 15,
      "z": -10,
      "name": "Rock_Sandstone_White"
    },
    {
      "x": -12,
      "y": 16,
      "z": -10,
      "name": "Rock_Sandstone_White"
    },
    {
      "x": -12,
      "y": 17,
      "z": -10,
      "name": "Rock_Sandstone_White"
    },
    {
      "x": -12,
      "y": 18,
      "z": -10,
      "name": "Rock_Sandstone_White"
    },
    {
      "x": -12,
      "y": 19,
      "z": -10,
      "name": "Rock_Sandstone_White"
    },
    {
      "x": -12,
      "y": 20,
      "z": -10,
      "name": "Rock_Sandstone_White"
    },
    {
      "x": -12,
      "y": 21,
      "z": -10,
      "name": "Soil_Sand_White"
    },
    {
      "x": -12,
      "y": 22,
      "z": -10,
      "name": "Soil_Sand_White"
    },
    {
      "x": -12,
      "y": 23,
      "z": -10,
      "name": "Soil_Sand_White"
    },
    {
      "x": -12,
      "y": 24,
      "z": -10,
      "name": "Soil_Sand_White"
    },
    {
      "x": -12,
      "y": 14,
      "z": -9,
      "name": "Rock_Sandstone_White"
    },
    {
      "x": -12,
      "y": 15,
      "z": -9,
      "name": "Rock_Sandstone_White"
    },
    {
      "x": -12,
      "y": 16,
      "z": -9,
      "name": "Rock_Sandstone_White"
    },
    {
      "x": -12,
      "y": 17,
      "z": -9,
      "name": "Rock_Sandstone_White"
    },
    {
      "x": -12,
      "y": 18,
      "z": -9,
      "name": "Rock_Sandstone_White"
    },
    {
      "x": -12,
      "y": 19,
      "z": -9,
      "name": "Rock_Sandstone_White"
    },
    {
      "x": -12,
      "y": 20,
      "z": -9,
      "name": "Rock_Sandstone_White"
    },
    {
      "x": -12,
      "y": 21,
      "z": -9,
      "name": "Rock_Sandstone_White"
    },
    {
      "x": -12,
      "y": 22,
      "z": -9,
      "name": "Soil_Sand_White"
    },
    {
      "x": -12,
      "y": 23,
      "z": -9,
      "name": "Soil_Sand_White"
    },
    {
      "x": -12,
      "y": 24,
      "z": -9,
      "name": "Soil_Sand_White"
    },
    {
      "x": -12,
      "y": 25,
      "z": -9,
      "name": "Soil_Sand_White"
    },
    {
      "x": -12,
      "y": 13,
      "z": -8,
      "name": "Rock_Sandstone_White"
    },
    {
      "x": -12,
      "y": 14,
      "z": -8,
      "name": "Rock_Sandstone_White"
    },
    {
      "x": -12,
      "y": 15,
      "z": -8,
      "name": "Rock_Sandstone_White"
    },
    {
      "x": -12,
      "y": 16,
      "z": -8,
      "name": "Rock_Sandstone_White"
    },
    {
      "x": -12,
      "y": 17,
      "z": -8,
      "name": "Rock_Sandstone_White"
    },
    {
      "x": -12,
      "y": 18,
      "z": -8,
      "name": "Rock_Sandstone_White"
    },
    {
      "x": -12,
      "y": 19,
      "z": -8,
      "name": "Rock_Sandstone_White"
    },
    {
      "x": -12,
      "y": 20,
      "z": -8,
