{
  "version": 8,
  "blockIdVersion": 11,
  "anchorX": 0,
  "anchorY": 0,
  "anchorZ": 0,
  "blocks": [
    {
      "x": -9,
      "y": 22,
      "z": -8,
      "name": "Ore_Thorium_Sandstone"
    },
    {
      "x": -9,
      "y": 23,
      "z": -8,
      "name": "Rock_Sandstone_White"
    },
    {
      "x": -9,
      "y": 24,
      "z": -8,
      "name": "Rock_Sandstone_White"
    },
    {
      "x": -9,
      "y": 25,
      "z": -8,
      "name": "Soil_Sand_White"
    },
    {
      "x": -9,
      "y": 26,
      "z": -8,
      "name": "Soil_Sand_White"
    },
    {
      "x": -9,
      "y": 21,
      "z": -7,
      "name": "Rock_Sandstone_White_Cobble"
    },
    {
      "x": -9,
      "y": 22,
      "z": -7,
      "name": "Rock_Sandstone_White"
    },
    {
      "x": -9,
      "y": 23,
      "z": -7,
      "name": "Rock_Sandstone_White"
    },
    {
      "x": -9,
      "y": 24,
      "z": -7,
      "name": "Rock_Sandstone_White"
    },
    {
      "x": -9,
      "y": 25,
      "z": -7,
      "name": "Rock_Sandstone_White"
    },
    {
      "x": -9,
      "y": 26,
      "z": -7,
      "name": "Soil_Sand_White"
    },
    {
      "x": -9,
      "y": 22,
      "z": -6,
      "name": "Rock_Sandstone_White"
    },
    {
      "x": -9,
      "y": 23,
      "z": -6,
      "name": "Rock_Sandstone_White"
    },
    {
      "x": -9,
      "y": 24,
      "z": -6,
      "name": "Rock_Sandstone_White"
    },
    {
      "x": -9,
      "y": 25,
      "z": -6,
      "name": "Soil_Sand_White"
    },
    {
      "x": -9,
      "y": 26,
      "z": -6,
      "name": "Soil_Sand_White"
    },
    {
      "x": -8,
      "y": 23,
      "z": -10,
      "name": "Rock_Sandstone_White"
    },
    {
      "x": -8,
      "y": 24,
      "z": -10,
      "name": "Rock_Sandstone_White"
    },
    {
      "x": -8,
      "y": 25,
      "z": -10,
      "name": "Soil_Sand_White"
    },
    {
      "x": -8,
      "y": 26,
      "z": -10,
      "name": "Soil_Sand_White"
    },
    {
      "x": -8,
      "y": 19,
      "z": -9,
      "name": "Rock_Sandstone_White"
    },
    {
      "x": -8,
      "y": 20,
      "z": -9,
      "name": "Rock_Sandstone_White"
    },
    {
      "x": -8,
      "y": 21,
      "z": -9,
      "name": "Rock_Sandstone_White"
    },
    {
      "x": -8,
      "y": 22,
      "z": -9,
      "name": "Rock_Sandstone_White"
    },
    {
      "x": -8,
      "y": 23,
      "z": -9,
      "name": "Rock_Sandstone_White"
    },
    {
      "x": -8,
      "y": 24,
      "z": -9,
      "name": "Soil_Sand_White"
    },
    {
      "x": -8,
      "y": 25,
      "z": -9,
      "name": "Soil_Sand_White"
    },
    {
      "x": -8,
      "y": 26,
      "z": -9,
      "name": "Soil_Sand_White"
    },
    {
      "x": -8,
      "y": 17,
      "z": -8,
      "name": "Rock_Sandstone_White_Stalactite_Small",
      "rotation": 9
    },
    {
      "x": -8,
      "y": 18,
      "z": -8,
      "name": "Rock_Sandstone_White"
    },
    {
      "x": -8,
      "y": 19,
      "z": -8,
      "name": "Rock_Sandstone_White"
    },
    {
      "x": -8,
      "y": 20,
      "z": -8,
      "name": "Rock_Sandstone_White_Cobble"
    },
    {
      "x": -8,
      "y": 21,
      "z": -8,
      "name": "Rock_Sandstone_White"
    },
    {
      "x": -8,
      "y": 22,
      "z": -8,
      "name": "Ore_Thorium_Sandstone"
    },
    {
      "x": -8,
      "y": 23,
      "z": -8,
      "name": "Rock_Sandstone_White"
    },
    {
      "x": -8,
      "y": 24,
      "z": -8,
      "name": "Soil_Sand_White"
    },
    {
      "x": -8,
      "y": 25,
      "z": -8,
      "name": "Soil_Sand_White"
    },
    {
      "x": -8,
      "y": 26,
      "z": -8,
      "name": "Soil_Sand_White"
    },
    {
      "x": -8,
      "y": 17,
      "z": -7,
      "name": "Rock_Sandstone_White"
    },
    {
      "x": -8,
      "y": 18,
      "z": -7,
      "name": "Rock_Sandstone_White"
    },
    {
      "x": -8,
      "y": 19,
      "z": -7,
      "name": "Rock_Sandstone_White"
    },
    {
      "x": -8,
      "y": 20,
      "z": -7,
      "name": "Rock_Sandstone_White_Cobble"
    },
    {
      "x": -8,
      "y": 21,
      "z": -7,
      "name": "Rock_Sandstone_White"
    },
    {
      "x": -8,
      "y": 22,
      "z": -7,
      "name": "Rock_Sandstone_White"
    },
    {
      "x": -8,
      "y": 23,
      "z": -7,
      "name": "Rock_Sandstone_White"
    },
    {
      "x": -8,
      "y": 24,
      "z": -7,
      "name": "Soil_Sand_White"
    },
    {
      "x": -8,
      "y": 25,
      "z": -7,
      "name": "Soil_Sand_White"
    },
    {
      "x": -8,
      "y": 26,
      "z": -7,
      "name": "Soil_Sand_White"
    },
    {
      "x": -8,
      "y": 18,
      "z": -6,
      "name": "Rock_Sandstone_White_Cobble"
    },
    {
      "x": -8,
      "y": 19,
      "z": -6,
      "name": "Rock_Sandstone_White"
    },
    {
      "x": -8,
      "y": 20,
      "z": -6,
      "name": "Rock_Sandstone_White"
    },
    {
      "x": -8,
      "y": 21,
      "z": -6,
      "name": "Rock_Sandstone_White"
    },
    {
      "x": -8,
      "y": 22,
      "z": -6,
      "name": "Rock_Sandstone_White"
    },
    {
      "x": -8,
      "y": 23,
      "z": -6,
      "name": "Rock_Sandstone_White"
    },
    {
      "x": -8,
      "y": 24,
      "z": -6,
      "name": "Soil_Sand_White"
    },
    {
      "x": -8,
      "y": 25,
      "z": -6,
      "name": "Soil_Sand_White"
    },
    {
      "x": -8,
      "y": 26,
      "z": -6,
      "name": "Soil_Sand_White"
    },
    {
      "x": -8,
      "y": 19,
      "z": -5,
      "name": "Rock_Sandstone_White"
    },
    {
      "x": -8,
      "y": 20,
      "z": -5,
      "name": "Rock_Sandstone_White"
    },
    {
      "x": -8,
      "y": 21,
      "z": -5,
      "name": "Rock_Sandstone_White"
    },
    {
      "x": -8,
      "y": 22,
      "z": -5,
      "name": "Rock_Sandstone_White"
    },
    {
      "x": -8,
      "y": 23,
      "z": -5,
      "name": "Rock_Sandstone_White"
    },
    {
      "x": -8,
      "y": 24,
      "z": -5,
      "name": "Rock_Sandstone_White_Cobble"
    },
    {
      "x": -8,
      "y": 25,
      "z": -5,
      "name": "Soil_Sand_White"
    },
    {
      "x": -8,
      "y": 26,
      "z": -5,
      "name": "Soil_Sand_White"
    },
    {
      "x": -8,
      "y": 23,
      "z": -4,
      "name": "Rock_Sandstone_White"
    },
    {
      "x": -8,
      "y": 24,
      "z": -4,
      "name": "Rock_Sandstone_White"
    },
    {
      "x": -8,
      "y": 25,
      "z": -4,
      "name": "Rock_Sandstone_White_Cobble"
    },
    {
      "x": -8,
      "y": 26,
      "z": -4,
      "name": "Rock_Sandstone_White"
    },
    {
      "x": -8,
      "y": 14,
      "z": 7,
      "name": "Soil_Sand_White"
    },
    {
      "x": -8,
      "y": 15,
      "z": 7,
      "name": "Soil_Sand_White"
    },
    {
      "x": -8,
      "y": 16,
      "z": 7,
      "name": "Soil_Sand_White"
    },
    {
      "x": -8,
      "y": 17,
      "z": 7,
      "name": "Soil_Gravel_Sand_White"
    },
    {
      "x": -8,
      "y": 13,
      "z": 8,
      "name": "Rock_Sandstone_White_Cobble"
    },
    {
      "x": -8,
      "y": 14,
      "z": 8,
      "name": "Soil_Sand_White"
    },
    {
      "x": -8,
      "y": 15,
      "z": 8,
      "name": "Soil_Sand_White"
    },
    {
      "x": -8,
      "y": 16,
      "z": 8,
      "name": "Soil_Sand_White"
    },
    {
      "x": -8,
      "y": 17,
      "z": 8,
      "name": "Soil_Sand_White"
    },
    {
      "x": -8,
      "y": 14,
      "z": 9,
      "name": "Soil_Gravel_Sand_White"
    },
    {
      "x": -8,
      "y": 15,
      "z": 9,
      "name": "Soil_Sand_White"
    },
    {
      "x": -8,
      "y": 16,
      "z": 9,
      "name": "Soil_Sand_White"
    },
    {
      "x": -8,
      "y": 17,
      "z": 9,
      "name": "Soil_Sand_White"
    },
    {
      "x": -7,
      "y": 29,
      "z": -16,
      "name": "Rock_Sandstone_White"
    },
    {
      "x": -7,
      "y": 30,
      "z": -16,
      "name": "Rock_Sandstone_White"
    },
    {
      "x": -7,
      "y": 31,
      "z": -16,
      "name": "Soil_Sand_White"
    },
    {
      "x": -7,
      "y": 32,
      "z": -16,
      "name": "Soil_Gravel_Sand_White"
    },
    {
      "x": -7,
      "y": 33,
      "z": -16,
      "name": "Soil_Sand_White"
    },
    {
      "x": -7,
      "y": 28,
      "z": -15,
      "name": "Rock_Sandstone_White_Cobble"
    },
    {
      "x": -7,
      "y": 29,
      "z": -15,
      "name": "Rock_Sandstone_White"
    },
    {
      "x": -7,
      "y": 30,
      "z": -15,
      "name": "Rock_Sandstone_White_Cobble"
    },
    {
      "x": -7,
      "y": 31,
      "z": -15,
      "name": "Soil_Sand_White"
    },
    {
      "x": -7,
      "y": 32,
      "z": -15,
      "name": "Soil_Sand_White"
    },
    {
      "x": -7,
      "y": 33,
      "z": -15,
      "name": "Soil_Sand_White"
    },
    {
      "x": -7,
      "y": 29,
      "z": -14,
      "name": "Rock_Sandstone_White_Cobble"
    },
    {
      "x": -7,
      "y": 30,
      "z": -14,
      "name": "Rock_Sandstone_White"
    },
    {
      "x": -7,
      "y": 31,
      "z": -14,
      "name": "Rock_Sandstone_White"
    },
    {
      "x": -7,
      "y": 32,
      "z": -14,
      "name": "Soil_Sand_White"
    },
    {
      "x": -7,
      "y": 33,
      "z": -14,
      "name": "Soil_Sand_White"
    },
    {
      "x": -7,
      "y": 19,
      "z": -10,
      "name": "Rock_Sandstone_White"
    },
    {
      "x": -7,
      "y": 20,
      "z": -10,
      "name": "Rock_Sandstone_White"
    },
    {
      "x": -7,
      "y": 21,
      "z": -10,
      "name": "Rock_Sandstone_White"
    },
    {
      "x": -7,
      "y": 22,
      "z": -10,
      "name": "Rock_Sandstone_White"
    },
    {
      "x": -7,
      "y": 23,
      "z": -10,
      "name": "Rock_Sandstone_White"
    },
    {
      "x": -7,
      "y": 24,
      "z": -10,
      "name": "Rock_Sandstone_White"
    },
    {
      "x": -7,
      "y": 25,
      "z": -10,
      "name": "Soil_Sand_White"
    },
    {
      "x": -7,
      "y": 26,
      "z": -10,
      "name": "Soil_Sand_White"
    },
    {
      "x": -7,
      "y": 17,
      "z": -9,
      "name": "Rock_Sandstone_White_Cobble"
    },
    {
      "x": -7,
      "y": 18,
      "z": -9,
      "name": "Rock_Sandstone_White"
    },
    {
      "x": -7,
      "y": 19,
      "z": -9,
      "name": "Rock_Sandstone_White"
    },
    {
      "x": -7,
      "y": 20,
      "z": -9,
      "name": "Rock_Sandstone_White"
    },
    {
      "x": -7,
      "y": 21,
      "z": -9,
      "name": "Rock_Sandstone_White"
    },
    {
      "x": -7,
      "y": 22,
      "z": -9,
      "name": "Rock_Sandstone_White"
    },
    {
      "x": -7,
      "y": 23,
      "z": -9,
      "name": "Rock_Sandstone_White"
    },
    {
      "x": -7,
      "y": 24,
      "z": -9,
      "name": "Rock_Sandstone_White"
    },
    {
      "x": -7,
      "y": 25,
      "z": -9,
      "name": "Rock_Sandstone_White_Cobble"
    },
    {
      "x": -7,
      "y": 26,
      "z": -9,
      "name": "Soil_Sand_White"
    },
    {
      "x": -7,
      "y": 16,
      "z": -8,
      "name": "Rock_Sandstone_White"
    },
    {
      "x": -7,
      "y": 17,
      "z": -8,
      "name": "Rock_Sandstone_White"
    },
    {
      "x": -7,
      "y": 18,
      "z": -8,
      "name": "Rock_Sandstone_White"
    },
    {
      "x": -7,
      "y": 19,
      "z": -8,
      "name": "Rock_Sandstone_White"
    },
    {
      "x": -7,
      "y": 20,
      "z": -8,
      "name": "Rock_Sandstone_White"
    },
    {
      "x": -7,
      "y": 21,
      "z": -8,
      "name": "Rock_Sandstone_White_Cobble"
    },
    {
      "x": -7,
      "y": 22,
      "z": -8,
      "name": "Rock_Sandstone_White_Cobble"
    },
    {
      "x": -7,
      "y": 23,
      "z": -8,
      "name": "Rock_Sandstone_White"
    },
    {
      "x": -7,
      "y": 24,
      "z": -8,
      "name": "Rock_Sandstone_White"
    },
    {
      "x": -7,
      "y": 25,
      "z": -8,
      "name": "Rock_Sandstone_White"
    },
    {
      "x": -7,
      "y": 26,
      "z": -8,
      "name": "Soil_Sand_White"
    },
    {
      "x": -7,
      "y": 14,
      "z": -7,
      "name": "Rock_Sandstone_White_Stalactite_Small",
      "rotation": 9
    },
    {
      "x": -7,
      "y": 15,
      "z": -7,
      "name": "Rock_Sandstone_White"
    },
    {
      "x": -7,
      "y": 16,
      "z": -7,
      "name": "Rock_Sandstone_White"
    },
    {
      "x": -7,
      "y": 17,
      "z": -7,
      "name": "Rock_Sandstone_White"
    },
    {
      "x": -7,
      "y": 18,
      "z": -7,
      "name": "Rock_Sandstone_White"
    },
    {
      "x": -7,
      "y": 19,
      "z": -7,
      "name": "Rock_Sandstone_White_Cobble"
    },
    {
      "x": -7,
      "y": 20,
      "z": -7,
      "name": "Rock_Sandstone_White_Cobble"
    },
    {
      "x": -7,
      "y": 21,
      "z": -7,
      "name": "Rock_Sandstone_White"
    },
    {
      "x": -7,
      "y": 22,
      "z": -7,
      "name": "Rock_Sandstone_White"
    },
    {
      "x": -7,
      "y": 23,
      "z": -7,
      "name": "Rock_Sandstone_White"
    },
    {
      "x": -7,
      "y": 24,
      "z": -7,
      "name": "Rock_Sandstone_White"
    },
    {
      "x": -7,
      "y": 25,
      "z": -7,
      "name": "Soil_Sand_White"
    },
    {
      "x": -7,
      "y": 26,
      "z": -7,
      "name": "Soil_Sand_White"
    },
    {
      "x": -7,
      "y": 16,
      "z": -6,
      "name": "Rock_Sandstone_White"
    },
    {
      "x": -7,
      "y": 17,
      "z": -6,
      "name": "Rock_Sandstone_White"
    },
    {
      "x": -7,
      "y": 18,
      "z": -6,
      "name": "Rock_Sandstone_White_Cobble"
    },
    {
      "x": -7,
      "y": 19,
      "z": -6,
      "name": "Rock_Sandstone_White"
    },
    {
      "x": -7,
      "y": 20,
      "z": -6,
      "name": "Rock_Sandstone_White"
    },
    {
      "x": -7,
      "y": 21,
      "z": -6,
      "name": "Rock_Sandstone_White"
    },
    {
      "x": -7,
      "y": 22,
      "z": -6,
      "name": "Rock_Sandstone_White"
    },
    {
      "x": -7,
      "y": 23,
      "z": -6,
      "name": "Rock_Sandstone_White"
    },
    {
      "x": -7,
      "y": 24,
      "z": -6,
      "name": "Rock_Sandstone_White"
    },
    {
      "x": -7,
      "y": 25,
      "z": -6,
      "name": "Soil_Sand_White"
    },
    {
      "x": -7,
      "y": 26,
      "z": -6,
      "name": "Soil_Gravel_Sand_White"
    },
    {
      "x": -7,
      "y": 17,
      "z": -5,
      "name": "Rock_Sandstone_White"
    },
    {
      "x": -7,
      "y": 18,
      "z": -5,
      "name": "Rock_Sandstone_White"
    },
    {
      "x": -7,
      "y": 19,
      "z": -5,
      "name": "Rock_Sandstone_White"
    },
    {
      "x": -7,
      "y": 20,
      "z": -5,
      "name": "Rock_Sandstone_White_Cobble"
    },
    {
      "x": -7,
      "y": 21,
      "z": -5,
      "name": "Rock_Sandstone_White_Cobble"
    },
    {
      "x": -7,
      "y": 22,
      "z": -5,
      "name": "Rock_Sandstone_White"
    },
    {
      "x": -7,
      "y": 23,
      "z": -5,
      "name": "Rock_Sandstone_White"
    },
    {
      "x": -7,
      "y": 24,
      "z": -5,
      "name": "Rock_Sandstone_White"
    },
    {
      "x": -7,
      "y": 25,
      "z": -5,
      "name": "Rock_Sandstone_White"
    },
    {
      "x": -7,
      "y": 26,
      "z": -5,
      "name": "Soil_Gravel_Sand_White"
    },
    {
      "x": -7,
      "y": 27,
      "z": -5,
      "name": "Plant_Bush_Arid_Sharp"
    },
    {
      "x": -7,
      "y": 19,
      "z": -4,
      "name": "Rock_Sandstone_White"
    },
    {
      "x": -7,
      "y": 20,
      "z": -4,
      "name": "Rock_Sandstone_White"
    },
    {
      "x": -7,
      "y": 21,
      "z": -4,
      "name": "Rock_Sandstone_White"
    },
    {
      "x": -7,
      "y": 22,
      "z": -4,
      "name": "Rock_Sandstone_White"
    },
    {
      "x": -7,
      "y": 23,
      "z": -4,
      "name": "Rock_Sandstone_White"
    },
    {
      "x": -7,
      "y": 24,
      "z": -4,
      "name": "Rock_Sandstone_White"
    },
    {
      "x": -7,
      "y": 25,
      "z": -4,
      "name": "Soil_Sand_White"
    },
    {
      "x": -7,
      "y": 26,
      "z": -4,
      "name": "Soil_Sand_White"
    },
    {
      "x": -7,
      "y": 11,
      "z": 6,
      "name": "Rock_Sandstone_White"
    },
    {
      "x": -7,
      "y": 12,
      "z": 6,
      "name": "Rock_Sandstone_White"
    },
    {
      "x": -7,
      "y": 13,
      "z": 6,
      "name": "Rock_Sandstone_White"
    },
    {
      "x": -7,
      "y": 14,
      "z": 6,
      "name": "Soil_Sand_White"
    },
    {
      "x": -7,
      "y": 15,
      "z": 6,
      "name": "Soil_Sand_White"
    },
    {
      "x": -7,
      "y": 16,
      "z": 6,
      "name": "Soil_Sand_White"
    },
    {
      "x": -7,
      "y": 17,
      "z": 6,
      "name": "Soil_Gravel_Sand_White"
    },
    {
      "x": -7,
      "y": 10,
      "z": 7,
      "name": "Rock_Sandstone_White_Cobble"
    },
    {
      "x": -7,
      "y": 11,
      "z": 7,
      "name": "Rock_Sandstone_White"
    },
    {
      "x": -7,
      "y": 12,
      "z": 7,
      "name": "Rock_Sandstone_White"
    },
    {
      "x": -7,
      "y": 13,
      "z": 7,
      "name": "Rock_Sandstone_White"
    },
    {
      "x": -7,
      "y": 14,
      "z": 7,
      "name": "Soil_Sand_White"
    },
    {
      "x": -7,
      "y": 15,
      "z": 7,
      "name": "Soil_Sand_White"
    },
    {
      "x": -7,
      "y": 16,
      "z": 7,
      "name": "Soil_Gravel_Sand_White"
    },
    {
      "x": -7,
      "y": 17,
      "z": 7,
      "name": "Soil_Sand_White"
    },
    {
      "x": -7,
      "y": 9,
      "z": 8,
      "name": "Rock_Sandstone_White"
    },
    {
      "x": -7,
      "y": 10,
      "z": 8,
      "name": "Rock_Sandstone_White"
    },
    {
      "x": -7,
      "y": 11,
      "z": 8,
      "name": "Rock_Sandstone_White"
    },
    {
      "x": -7,
      "y": 12,
      "z": 8,
      "name": "Rock_Sandstone_White"
    },
    {
      "x": -7,
      "y": 13,
      "z": 8,
      "name": "Rock_Sandstone_White"
    },
    {
      "x": -7,
      "y": 14,
      "z": 8,
      "name": "Soil_Sand_White"
    },
    {
      "x": -7,
      "y": 15,
      "z": 8,
      "name": "Soil_Sand_White"
    },
    {
      "x": -7,
      "y": 16,
      "z": 8,
      "name": "Soil_Sand_White"
    },
    {
      "x": -7,
      "y": 17,
      "z": 8,
      "name": "Soil_Sand_White"
    },
    {
      "x": -7,
      "y": 18,
      "z": 8,
      "name": "Rubble_Sandstone_White_Medium"
    },
    {
      "x": -7,
      "y": 8,
      "z": 9,
      "name": "Rock_Sandstone_White_Stalactite_Large",
      "filler": 31744,
      "rotation": 8
    },
    {
      "x": -7,
      "y": 9,
      "z": 9,
      "name": "Rock_Sandstone_White_Stalactite_Large",
      "rotation": 8
    },
    {
      "x": -7,
      "y": 10,
      "z": 9,
      "name": "Rock_Sandstone_White_Cobble"
    },
    {
      "x": -7,
      "y": 11,
      "z": 9,
      "name": "Rock_Sandstone_White"
    },
    {
      "x": -7,
      "y": 12,
      "z": 9,
      "name": "Rock_Sandstone_White_Cobble"
    },
    {
      "x": -7,
      "y": 13,
      "z": 9,
      "name": "Rock_Sandstone_White"
    },
    {
      "x": -7,
      "y": 14,
      "z": 9,
      "name": "Rock_Sandstone_White"
    },
    {
      "x": -7,
      "y": 15,
      "z": 9,
      "name": "Soil_Sand_White"
    },
    {
      "x": -7,
      "y": 16,
      "z": 9,
      "name": "Soil_Gravel_Sand_White"
    },
    {
      "x": -7,
      "y": 17,
      "z": 9,
      "name": "Soil_Sand_White"
    },
    {
      "x": -7,
      "y": 11,
      "z": 10,
      "name": "Rock_Sandstone_White"
    },
    {
      "x": -7,
      "y": 12,
      "z": 10,
      "name": "Rock_Sandstone_White"
    },
    {
      "x": -7,
      "y": 13,
      "z": 10,
      "name": "Rock_Sandstone_White_Cobble"
    },
    {
      "x": -7,
      "y": 14,
      "z": 10,
      "name": "Rock_Sandstone_White"
    },
    {
      "x": -7,
      "y": 15,
      "z": 10,
      "name": "Soil_Sand_White"
    },
    {
      "x": -7,
      "y": 16,
      "z": 10,
      "name": "Soil_Gravel_Sand_White"
    },
    {
      "x": -7,
      "y": 17,
      "z": 10,
      "name": "Soil_Sand_White"
    },
    {
      "x": -7,
      "y": 18,
      "z": 10,
      "name": "Plant_Cactus_Flat_2"
    },
    {
      "x": -7,
      "y": 15,
      "z": 11,
      "name": "Soil_Sand_White"
    },
    {
      "x": -7,
      "y": 16,
      "z": 11,
      "name": "Soil_Sand_White"
    },
    {
      "x": -6,
      "y": 30,
      "z": -18,
      "name": "Rock_Sandstone_White"
    },
    {
      "x": -6,
      "y": 31,
      "z": -18,
      "name": "Soil_Sand_White"
    },
    {
      "x": -6,
      "y": 32,
      "z": -18,
      "name": "Soil_Sand_White"
    },
    {
      "x": -6,
      "y": 33,
      "z": -18,
      "name": "Soil_Sand_White"
    },
    {
      "x": -6,
      "y": 26,
      "z": -17,
      "name": "Rock_Sandstone_White"
    },
    {
      "x": -6,
      "y": 27,
      "z": -17,
      "name": "Rock_Sandstone_White"
    },
    {
      "x": -6,
      "y": 28,
      "z": -17,
      "name": "Rock_Sandstone_White_Cobble"
    },
    {
      "x": -6,
      "y": 29,
      "z": -17,
      "name": "Rock_Sandstone_White"
    },
    {
      "x": -6,
      "y": 30,
      "z": -17,
      "name": "Rock_Sandstone_White_Cobble"
    },
    {
      "x": -6,
      "y": 31,
      "z": -17,
      "name": "Soil_Sand_White"
    },
    {
      "x": -6,
      "y": 32,
      "z": -17,
      "name": "Soil_Sand_White"
    },
    {
      "x": -6,
      "y": 33,
      "z": -17,
      "name": "Soil_Sand_White"
    },
    {
      "x": -6,
      "y": 25,
      "z": -16,
      "name": "Rock_Sandstone_White"
    },
    {
      "x": -6,
      "y": 26,
      "z": -16,
      "name": "Rock_Sandstone_White"
    },
    {
      "x": -6,
      "y": 27,
      "z": -16,
      "name": "Rock_Sandstone_White"
    },
    {
      "x": -6,
      "y": 28,
      "z": -16,
      "name": "Rock_Sandstone_White"
    },
    {
      "x": -6,
      "y": 29,
      "z": -16,
      "name": "Rock_Sandstone_White"
    },
    {
      "x": -6,
      "y": 30,
      "z": -16,
      "name": "Rock_Sandstone_White"
    },
    {
      "x": -6,
      "y": 31,
      "z": -16,
      "name": "Soil_Sand_White"
    },
    {
      "x": -6,
      "y": 32,
      "z": -16,
      "name": "Soil_Sand_White"
    },
    {
      "x": -6,
      "y": 33,
      "z": -16,
      "name": "Soil_Sand_White"
    },
    {
      "x": -6,
      "y": 24,
      "z": -15,
      "name": "Rock_Sandstone_White"
    },
    {
      "x": -6,
      "y": 25,
      "z": -15,
      "name": "Rock_Sandstone_White"
    },
    {
      "x": -6,
      "y": 26,
      "z": -15,
      "name": "Rock_Sandstone_White"
    },
    {
      "x": -6,
      "y": 27,
      "z": -15,
      "name": "Rock_Sandstone_White_Cobble"
    },
    {
      "x": -6,
      "y": 28,
      "z": -15,
      "name": "Rock_Sandstone_White"
    },
    {
      "x": -6,
      "y": 29,
      "z": -15,
      "name": "Rock_Sandstone_White"
    },
    {
      "x": -6,
      "y": 30,
      "z": -15,
      "name": "Rock_Sandstone_White_Cobble"
    },
    {
      "x": -6,
      "y": 31,
      "z": -15,
      "name": "Rock_Sandstone_White"
    },
    {
      "x": -6,
      "y": 32,
      "z": -15,
      "name": "Soil_Sand_White"
    },
    {
      "x": -6,
      "y": 33,
      "z": -15,
      "name": "Soil_Sand_White"
    },
    {
      "x": -6,
      "y": 25,
      "z": -14,
      "name": "Rock_Sandstone_White"
    },
    {
      "x": -6,
      "y": 26,
      "z": -14,
      "name": "Rock_Sandstone_White"
    },
    {
      "x": -6,
      "y": 27,
      "z": -14,
      "name": "Rock_Sandstone_White"
    },
    {
      "x": -6,
      "y": 28,
      "z": -14,
      "name": "Rock_Sandstone_White"
    },
    {
      "x": -6,
      "y": 29,
      "z": -14,
      "name": "Rock_Sandstone_White"
    },
    {
      "x": -6,
      "y": 30,
      "z": -14,
      "name": "Rock_Sandstone_White"
    },
    {
      "x": -6,
      "y": 31,
      "z": -14,
      "name": "Soil_Gravel_Sand_White"
    },
    {
      "x": -6,
      "y": 32,
      "z": -14,
      "name": "Soil_Sand_White"
    },
    {
      "x": -6,
      "y": 33,
      "z": -14,
      "name": "Soil_Sand_White"
    },
    {
      "x": -6,
      "y": 24,
      "z": -13,
      "name": "Rock_Sandstone_White"
    },
    {
      "x": -6,
      "y": 25,
      "z": -13,
      "name": "Rock_Sandstone_White"
    },
    {
      "x": -6,
      "y": 26,
      "z": -13,
      "name": "Rock_Sandstone_White_Cobble"
    },
    {
      "x": -6,
      "y": 27,
      "z": -13,
      "name": "Rock_Sandstone_White"
    },
    {
      "x": -6,
      "y": 28,
      "z": -13,
      "name": "Rock_Sandstone_White"
    },
    {
      "x": -6,
      "y": 29,
      "z": -13,
      "name": "Rock_Sandstone_White"
    },
    {
      "x": -6,
      "y": 30,
      "z": -13,
      "name": "Rock_Sandstone_White"
    },
    {
      "x": -6,
      "y": 31,
      "z": -13,
      "name": "Soil_Gravel_Sand_White"
    },
    {
      "x": -6,
      "y": 32,
      "z": -13,
      "name": "Soil_Sand_White"
    },
    {
      "x": -6,
      "y": 33,
      "z": -13,
      "name": "Soil_Sand_White"
    },
    {
      "x": -6,
      "y": 23,
      "z": -12,
      "name": "Rock_Sandstone_White"
    },
    {
      "x": -6,
      "y": 24,
      "z": -12,
      "name": "Rock_Sandstone_White"
    },
    {
      "x": -6,
      "y": 25,
      "z": -12,
      "name": "Rock_Sandstone_White"
    },
    {
      "x": -6,
      "y": 26,
      "z": -12,
      "name": "Rock_Sandstone_White"
    },
    {
      "x": -6,
      "y": 27,
      "z": -12,
      "name": "Rock_Sandstone_White"
    },
    {
      "x": -6,
      "y": 28,
      "z": -12,
      "name": "Rock_Sandstone_White"
    },
    {
      "x": -6,
      "y": 30,
      "z": -12,
      "name": "Rock_Sandstone_White"
    },
    {
      "x": -6,
      "y": 31,
      "z": -12,
      "name": "Rock_Sandstone_White_Cobble"
    },
    {
      "x": -6,
      "y": 32,
      "z": -12,
      "name": "Soil_Gravel_Sand_White"
    },
    {
      "x": -6,
      "y": 33,
      "z": -12,
      "name": "Soil_Gravel_Sand_White"
    },
    {
      "x": -6,
      "y": 22,
      "z": -11,
      "name": "Rock_Sandstone_White"
    },
    {
      "x": -6,
      "y": 23,
      "z": -11,
      "name": "Rock_Sandstone_White"
    },
    {
      "x": -6,
      "y": 24,
      "z": -11,
      "name": "Rock_Sandstone_White"
    },
    {
      "x": -6,
      "y": 25,
      "z": -11,
      "name": "Rock_Sandstone_White"
    },
    {
      "x": -6,
      "y": 26,
      "z": -11,
      "name": "Rock_Sandstone_White"
    },
    {
      "x": -6,
      "y": 27,
      "z": -11,
      "name": "Rock_Sandstone_White"
    },
    {
      "x": -6,
      "y": 28,
      "z": -11,
      "name": "Rock_Sandstone_White"
    },
    {
      "x": -6,
      "y": 18,
      "z": -10,
      "name": "Rock_Sandstone_White"
    },
    {
      "x": -6,
      "y": 19,
      "z": -10,
      "name": "Rock_Sandstone_White"
    },
    {
      "x": -6,
      "y": 20,
      "z": -10,
      "name": "Rock_Sandstone_White"
    },
    {
      "x": -6,
      "y": 21,
      "z": -10,
      "name": "Rock_Sandstone_White_Cobble"
    },
    {
      "x": -6,
      "y": 22,
      "z": -10,
      "name": "Rock_Sandstone_White"
    },
    {
      "x": -6,
      "y": 23,
      "z": -10,
      "name": "Rock_Sandstone_White"
    },
    {
      "x": -6,
      "y": 24,
      "z": -10,
      "name": "Rock_Sandstone_White"
    },
    {
      "x": -6,
      "y": 25,
      "z": -10,
      "name": "Soil_Sand_White"
    },
    {
      "x": -6,
      "y": 26,
      "z": -10,
      "name": "Soil_Sand_White"
    },
    {
      "x": -6,
      "y": 27,
      "z": -10,
      "name": "Plant_Cactus_Flat_3"
    },
    {
      "x": -6,
      "y": 16,
      "z": -9,
      "name": "Rock_Sandstone_White"
    },
    {
      "x": -6,
      "y": 17,
      "z": -9,
      "name": "Rock_Sandstone_White"
    },
    {
      "x": -6,
      "y": 18,
      "z": -9,
      "name": "Rock_Sandstone_White"
    },
    {
      "x": -6,
      "y": 19,
      "z": -9,
      "name": "Rock_Sandstone_White"
    },
    {
      "x": -6,
      "y": 20,
      "z": -9,
      "name": "Rock_Sandstone_White"
    },
    {
      "x": -6,
      "y": 21,
      "z": -9,
      "name": "Rock_Sandstone_White"
    },
    {
      "x": -6,
      "y": 22,
      "z": -9,
      "name": "Rock_Sandstone_White"
    },
    {
      "x": -6,
      "y": 23,
      "z": -9,
      "name": "Rock_Sandstone_White"
    },
    {
      "x": -6,
      "y": 24,
      "z": -9,
      "name": "Rock_Sandstone_White_Cobble"
    },
    {
      "x": -6,
      "y": 25,
      "z": -9,
      "name": "Soil_Sand_White"
    },
    {
      "x": -6,
      "y": 26,
      "z": -9,
      "name": "Soil_Sand_White"
    },
    {
      "x": -6,
      "y": 15,
      "z": -8,
      "name": "Rock_Sandstone_White"
    },
    {
      "x": -6,
      "y": 16,
      "z": -8,
      "name": "Rock_Sandstone_White"
    },
    {
      "x": -6,
      "y": 17,
      "z": -8,
      "name": "Rock_Sandstone_White"
    },
    {
      "x": -6,
      "y": 18,
      "z": -8,
      "name": "Rock_Sandstone_White"
    },
    {
      "x": -6,
      "y": 19,
      "z": -8,
      "name": "Rock_Sandstone_White"
    },
    {
      "x": -6,
      "y": 20,
      "z": -8,
      "name": "Rock_Sandstone_White"
    },
    {
      "x": -6,
      "y": 21,
      "z": -8,
      "name": "Rock_Sandstone_White"
    },
    {
      "x": -6,
      "y": 22,
      "z": -8,
      "name": "Ore_Thorium_Sandstone"
    },
    {
      "x": -6,
      "y": 23,
      "z": -8,
      "name": "Rock_Sandstone_White"
    },
    {
      "x": -6,
      "y": 24,
      "z": -8,
      "name": "Rock_Sandstone_White_Cobble"
    },
    {
      "x": -6,
      "y": 25,
      "z": -8,
      "name": "Rock_Sandstone_White"
    },
    {
      "x": -6,
      "y": 26,
      "z": -8,
      "name": "Soil_Sand_White"
    },
    {
      "x": -6,
      "y": 14,
      "z": -7,
      "name": "Rock_Sandstone_White"
    },
    {
      "x": -6,
      "y": 15,
      "z": -7,
      "name": "Rock_Sandstone_White"
    },
    {
      "x": -6,
      "y": 16,
      "z": -7,
      "name": "Rock_Sandstone_White"
    },
    {
      "x": -6,
      "y": 17,
      "z": -7,
      "name": "Rock_Sandstone_White"
    },
    {
      "x": -6,
      "y": 18,
      "z": -7,
      "name": "Rock_Sandstone_White"
    },
    {
      "x": -6,
      "y": 19,
      "z": -7,
      "name": "Rock_Sandstone_White"
    },
    {
      "x": -6,
      "y": 20,
      "z": -7,
      "name": "Rock_Sandstone_White"
    },
    {
      "x": -6,
      "y": 21,
      "z": -7,
      "name": "Rock_Sandstone_White"
    },
    {
      "x": -6,
      "y": 22,
      "z": -7,
      "name": "Rock_Sandstone_White_Cobble"
    },
    {
      "x": -6,
      "y": 23,
      "z": -7,
      "name": "Rock_Sandstone_White"
    },
    {
      "x": -6,
      "y": 24,
      "z": -7,
      "name": "Rock_Sandstone_White_Cobble"
    },
    {
      "x": -6,
      "y": 25,
      "z": -7,
      "name": "Soil_Sand_White"
    },
    {
      "x": -6,
      "y": 26,
      "z": -7,
      "name": "Soil_Sand_White"
    },
    {
      "x": -6,
      "y": 15,
      "z": -6,
      "name": "Rock_Sandstone_White_Cobble"
    },
    {
      "x": -6,
      "y": 16,
      "z": -6,
      "name": "Rock_Sandstone_White"
    },
    {
      "x": -6,
      "y": 17,
      "z": -6,
      "name": "Rock_Sandstone_White"
    },
    {
      "x": -6,
      "y": 18,
      "z": -6,
      "name": "Rock_Sandstone_White"
    },
    {
      "x": -6,
      "y": 19,
      "z": -6,
      "name": "Rock_Sandstone_White"
    },
    {
      "x": -6,
      "y": 20,
      "z": -6,
      "name": "Rock_Sandstone_White"
    },
    {
      "x": -6,
      "y": 21,
      "z": -6,
      "name": "Rock_Sandstone_White"
    },
    {
      "x": -6,
      "y": 22,
      "z": -6,
      "name": "Rock_Sandstone_White_Cobble"
    },
    {
      "x": -6,
      "y": 23,
      "z": -6,
      "name": "Rock_Sandstone_White"
    },
    {
      "x": -6,
      "y": 24,
      "z": -6,
      "name": "Soil_Sand_White"
    },
    {
      "x": -6,
      "y": 25,
      "z": -6,
      "name": "Soil_Sand_White"
    },
    {
      "x": -6,
      "y": 26,
      "z": -6,
      "name": "Soil_Gravel_Sand_White"
    },
    {
      "x": -6,
      "y": 27,
      "z": -6,
      "name": "Soil_Sand_White"
    },
    {
      "x": -6,
      "y": 16,
      "z": -5,
      "name": "Rock_Sandstone_White"
    },
    {
      "x": -6,
      "y": 17,
      "z": -5,
      "name": "Rock_Sandstone_White"
    },
    {
      "x": -6,
      "y": 18,
      "z": -5,
      "name": "Rock_Sandstone_White_Cobble"
    },
    {
      "x": -6,
      "y": 19,
      "z": -5,
      "name": "Rock_Sandstone_White"
    },
    {
      "x": -6,
      "y": 20,
      "z": -5,
      "name": "Rock_Sandstone_White"
    },
    {
      "x": -6,
      "y": 21,
      "z": -5,
      "name": "Rock_Sandstone_White"
    },
    {
      "x": -6,
      "y": 22,
      "z": -5,
      "name": "Rock_Sandstone_White"
    },
    {
      "x": -6,
      "y": 23,
      "z": -5,
      "name": "Rock_Sandstone_White"
    },
    {
      "x": -6,
      "y": 24,
      "z": -5,
      "name": "Rock_Sandstone_White"
    },
    {
      "x": -6,
      "y": 25,
      "z": -5,
      "name": "Rock_Sandstone_White_Cobble"
    },
    {
      "x": -6,
      "y": 26,
      "z": -5,
      "name": "Soil_Sand_White"
    },
    {
      "x": -6,
      "y": 27,
      "z": -5,
      "name": "Soil_Sand_White"
    },
    {
      "x": -6,
      "y": 18,
      "z": -4,
      "name": "Rock_Sandstone_White"
    },
    {
      "x": -6,
      "y": 19,
      "z": -4,
      "name": "Rock_Sandstone_White"
    },
    {
      "x": -6,
      "y": 20,
      "z": -4,
      "name": "Rock_Sandstone_White"
    },
    {
      "x": -6,
      "y": 21,
      "z": -4,
      "name": "Rock_Sandstone_White"
    },
    {
      "x": -6,
      "y": 22,
      "z": -4,
      "name": "Rock_Sandstone_White"
    },
    {
      "x": -6,
      "y": 23,
      "z": -4,
      "name": "Rock_Sandstone_White"
    },
    {
      "x": -6,
      "y": 24,
      "z": -4,
      "name": "Rock_Sandstone_White"
    },
    {
      "x": -6,
      "y": 25,
      "z": -4,
      "name": "Rock_Sandstone_White"
    },
    {
      "x": -6,
      "y": 26,
      "z": -4,
      "name": "Rock_Sandstone_White"
    },
    {
      "x": -6,
      "y": 27,
      "z": -4,
      "name": "Rock_Sandstone_White"
    },
    {
      "x": -6,
      "y": 22,
      "z": -3,
      "name": "Rock_Sandstone_White"
    },
    {
      "x": -6,
      "y": 23,
      "z": -3,
      "name": "Rock_Sandstone_White"
    },
    {
      "x": -6,
      "y": 24,
      "z": -3,
      "name": "Rock_Sandstone_White_Cobble"
    },
    {
      "x": -6,
      "y": 25,
      "z": -3,
      "name": "Soil_Sand_White"
    },
    {
      "x": -6,
      "y": 26,
      "z": -3,
      "name": "Soil_Sand_White"
    },
    {
      "x": -6,
      "y": 11,
      "z": 5,
      "name": "Rock_Sandstone_White_Cobble"
    },
    {
      "x": -6,
      "y": 12,
      "z": 5,
      "name": "Rock_Sandstone_White"
    },
    {
      "x": -6,
      "y": 13,
      "z": 5,
      "name": "Rock_Sandstone_White"
    },
    {
      "x": -6,
      "y": 14,
      "z": 5,
      "name": "Soil_Sand_White"
    },
    {
      "x": -6,
      "y": 15,
      "z": 5,
      "name": "Soil_Gravel_Sand_White"
    },
    {
      "x": -6,
      "y": 16,
      "z": 5,
      "name": "Soil_Gravel_Sand_White"
    },
    {
      "x": -6,
      "y": 17,
      "z": 5,
      "name": "Soil_Sand_White"
    },
    {
      "x": -6,
      "y": 9,
      "z": 6,
      "name": "Rock_Sandstone_White_Cobble"
    },
    {
      "x": -6,
      "y": 10,
      "z": 6,
      "name": "Rock_Sandstone_White"
    },
    {
      "x": -6,
      "y": 11,
      "z": 6,
      "name": "Rock_Sandstone_White_Cobble"
    },
    {
      "x": -6,
      "y": 12,
      "z": 6,
      "name": "Rock_Sandstone_White"
    },
    {
      "x": -6,
      "y": 13,
      "z": 6,
      "name": "Rock_Sandstone_White_Cobble"
    },
    {
      "x": -6,
      "y": 14,
      "z": 6,
      "name": "Rock_Sandstone_White"
    },
    {
      "x": -6,
      "y": 15,
      "z": 6,
      "name": "Rock_Sandstone_White_Cobble"
    },
    {
      "x": -6,
      "y": 16,
      "z": 6,
      "name": "Rock_Sandstone_White_Cobble"
    },
    {
      "x": -6,
      "y": 17,
      "z": 6,
      "name": "Rock_Sandstone_White_Brick"
    },
    {
      "x": -6,
      "y": 18,
      "z": 6,
      "name": "Rock_Sandstone_White_Brick_Pillar_Base"
    },
    {
      "x": -6,
      "y": 19,
      "z": 6,
      "name": "Rock_Sandstone_White_Brick_Pillar_Middle"
    },
    {
      "x": -6,
      "y": 20,
      "z": 6,
      "name": "Rock_Sandstone_White_Brick_Pillar_Middle"
    },
    {
      "x": -6,
      "y": 21,
      "z": 6,
      "name": "Rock_Sandstone_White_Brick_Pillar_Middle"
    },
    {
      "x": -6,
      "y": 22,
      "z": 6,
      "name": "Rubble_Sandstone_White"
    },
    {
      "x": -6,
      "y": 8,
      "z": 7,
      "name": "Rock_Sandstone_White"
    },
    {
      "x": -6,
      "y": 9,
      "z": 7,
      "name": "Rock_Sandstone_White"
    },
    {
      "x": -6,
      "y": 10,
      "z": 7,
      "name": "Rock_Sandstone_White"
    },
    {
      "x": -6,
      "y": 11,
      "z": 7,
      "name": "Rock_Sandstone_White"
    },
    {
      "x": -6,
      "y": 12,
      "z": 7,
      "name": "Rock_Sandstone_White"
    },
    {
      "x": -6,
      "y": 13,
      "z": 7,
      "name": "Rock_Sandstone_White_Cobble"
    },
    {
      "x": -6,
      "y": 14,
      "z": 7,
      "name": "Rock_Sandstone_White"
    },
    {
      "x": -6,
      "y": 15,
      "z": 7,
      "name": "Rock_Sandstone_White"
    },
    {
      "x": -6,
      "y": 16,
      "z": 7,
      "name": "Rock_Sandstone_White"
    },
    {
      "x": -6,
      "y": 17,
      "z": 7,
      "name": "Rock_Sandstone_White_Brick"
    },
    {
      "x": -6,
      "y": 5,
      "z": 8,
      "name": "Rock_Crystal_Yellow_Medium",
      "rotation": 7
    },
    {
      "x": -6,
      "y": 6,
      "z": 8,
      "name": "Rock_Crystal_Yellow_Medium",
      "rotation": 7
    },
    {
      "x": -6,
      "y": 7,
      "z": 8,
      "name": "Rock_Crystal_Yellow_Medium",
      "rotation": 7
    },
    {
      "x": -6,
      "y": 8,
      "z": 8,
      "name": "Rock_Sandstone_White_Cobble"
    },
    {
      "x": -6,
      "y": 9,
      "z": 8,
      "name": "Rock_Sandstone_White"
    },
    {
      "x": -6,
      "y": 10,
      "z": 8,
      "name": "Rock_Sandstone_White"
    },
    {
      "x": -6,
      "y": 11,
      "z": 8,
      "name": "Rock_Sandstone_White"
    },
    {
      "x": -6,
      "y": 12,
      "z": 8,
      "name": "Rock_Sandstone_White"
    },
    {
      "x": -6,
      "y": 13,
      "z": 8,
      "name": "Rock_Sandstone_White"
    },
    {
      "x": -6,
      "y": 14,
      "z": 8,
      "name": "Rock_Sandstone_White"
    },
    {
      "x": -6,
      "y": 15,
      "z": 8,
      "name": "Rock_Sandstone_White"
    },
    {
      "x": -6,
      "y": 16,
      "z": 8,
      "name": "Rock_Sandstone_White"
    },
    {
      "x": -6,
      "y": 17,
      "z": 8,
      "name": "Rock_Sandstone_White_Brick"
    },
    {
      "x": -6,
      "y": 18,
      "z": 8,
      "name": "Block_Spawner_Block",
      "components": {
        "Components": {
          "PlacedByInteraction": {
            "WhoPlacedUuid": {
              "$binary": "3XRzOktQTQGfL/+8x7+CHA==",
              "$type": "04"
            }
          },
          "BlockSpawner": {
            "BlockSpawnerId": "Zone4_Encounters_Tier4"
          }
        }
      },
      "rotation": 1
    },
    {
      "x": -6,
      "y": 8,
      "z": 9,
      "name": "Rock_Sandstone_White"
    },
    {
      "x": -6,
      "y": 9,
      "z": 9,
      "name": "Rock_Sandstone_White_Cobble"
    },
    {
      "x": -6,
      "y": 10,
      "z": 9,
      "name": "Rock_Sandstone_White"
    },
    {
      "x": -6,
      "y": 11,
      "z": 9,
      "name": "Rock_Sandstone_White"
    },
    {
      "x": -6,
      "y": 12,
      "z": 9,
      "name": "Rock_Sandstone_White"
    },
    {
      "x": -6,
      "y": 13,
      "z": 9,
      "name": "Rock_Sandstone_White"
    },
    {
      "x": -6,
      "y": 14,
      "z": 9,
      "name": "Rock_Sandstone_White"
    },
    {
      "x": -6,
      "y": 15,
      "z": 9,
      "name": "Rock_Sandstone_White_Cobble"
    },
    {
      "x": -6,
      "y": 16,
      "z": 9,
      "name": "Rock_Sandstone_White"
    },
    {
      "x": -6,
      "y": 17,
      "z": 9,
      "name": "Rock_Sandstone_White_Brick"
    },
    {
      "x": -6,
      "y": 18,
      "z": 9,
      "name": "Rock_Sandstone_White_Brick_Pillar_Base"
    },
    {
      "x": -6,
      "y": 19,
      "z": 9,
      "name": "Rock_Sandstone_White_Brick_Pillar_Middle"
    },
    {
      "x": -6,
      "y": 20,
      "z": 9,
      "name": "Rubble_Sandstone_White_Medium"
    },
    {
      "x": -6,
      "y": 9,
      "z": 10,
      "name": "Rock_Sandstone_White"
    },
    {
      "x": -6,
      "y": 10,
      "z": 10,
      "name": "Rock_Sandstone_White"
    },
    {
      "x": -6,
      "y": 11,
      "z": 10,
      "name": "Rock_Sandstone_White"
    },
    {
      "x": -6,
      "y": 12,
      "z": 10,
      "name": "Rock_Sandstone_White"
    },
    {
      "x": -6,
      "y": 13,
      "z": 10,
      "name": "Rock_Sandstone_White"
    },
    {
      "x": -6,
      "y": 14,
      "z": 10,
      "name": "Soil_Sand_White"
    },
    {
      "x": -6,
      "y": 15,
      "z": 10,
      "name": "Soil_Sand_White"
    },
    {
      "x": -6,
      "y": 16,
      "z": 10,
      "name": "Soil_Sand_White"
    },
    {
      "x": -6,
      "y": 17,
      "z": 10,
      "name": "Soil_Sand_White"
    },
    {
      "x": -6,
      "y": 11,
      "z": 11,
      "name": "Rock_Sandstone_White"
    },
    {
      "x": -6,
      "y": 12,
      "z": 11,
      "name": "Rock_Sandstone_White_Cobble"
    },
    {
      "x": -6,
      "y": 13,
      "z": 11,
      "name": "Rock_Sandstone_White_Cobble"
    },
    {
      "x": -6,
      "y": 14,
      "z": 11,
      "name": "Soil_Sand_White"
    },
    {
      "x": -6,
      "y": 15,
      "z": 11,
      "name": "Soil_Gravel_Sand_White"
    },
    {
      "x": -6,
      "y": 16,
      "z": 11,
      "name": "Soil_Sand_White"
    },
    {
      "x": -5,
      "y": 26,
      "z": -18,
      "name": "Rock_Sandstone_White"
    },
    {
      "x": -5,
      "y": 27,
      "z": -18,
      "name": "Rock_Sandstone_White"
    },
    {
      "x": -5,
      "y": 28,
      "z": -18,
      "name": "Rock_Sandstone_White"
    },
    {
      "x": -5,
      "y": 29,
      "z": -18,
      "name": "Rock_Sandstone_White"
    },
    {
      "x": -5,
      "y": 30,
      "z": -18,
      "name": "Rock_Sandstone_White"
    },
    {
      "x": -5,
      "y": 31,
      "z": -18,
      "name": "Soil_Sand_White"
    },
    {
      "x": -5,
      "y": 32,
      "z": -18,
      "name": "Soil_Gravel_Sand_White"
    },
    {
      "x": -5,
      "y": 33,
      "z": -18,
      "name": "Soil_Gravel_Sand_White"
    },
    {
      "x": -5,
      "y": 24,
      "z": -17,
      "name": "Rock_Sandstone_White"
    },
    {
      "x": -5,
      "y": 25,
      "z": -17,
      "name": "Rock_Sandstone_White"
    },
    {
      "x": -5,
      "y": 26,
      "z": -17,
      "name": "Rock_Sandstone_White"
    },
    {
      "x": -5,
      "y": 27,
      "z": -17,
      "name": "Rock_Sandstone_White"
    },
    {
      "x": -5,
      "y": 28,
      "z": -17,
      "name": "Rock_Sandstone_White"
    },
    {
      "x": -5,
      "y": 29,
      "z": -17,
      "name": "Rock_Sandstone_White"
    },
    {
      "x": -5,
      "y": 30,
      "z": -17,
      "name": "Rock_Sandstone_White_Cobble"
    },
    {
      "x": -5,
      "y": 31,
      "z": -17,
      "name": "Soil_Sand_White"
    },
    {
      "x": -5,
      "y": 32,
      "z": -17,
      "name": "Soil_Sand_White"
    },
    {
      "x": -5,
      "y": 33,
      "z": -17,
      "name": "Soil_Sand_White"
    },
    {
      "x": -5,
      "y": 22,
      "z": -16,
      "name": "Rock_Sandstone_White_Stalactite_Small",
      "rotation": 8
    },
    {
      "x": -5,
      "y": 23,
      "z": -16,
      "name": "Rock_Sandstone_White"
    },
    {
      "x": -5,
      "y": 24,
      "z": -16,
      "name": "Rock_Sandstone_White_Cobble"
    },
    {
      "x": -5,
      "y": 25,
      "z": -16,
      "name": "Rock_Sandstone_White"
    },
    {
      "x": -5,
      "y": 26,
      "z": -16,
      "name": "Rock_Sandstone_White"
    },
    {
      "x": -5,
      "y": 27,
      "z": -16,
      "name": "Rock_Sandstone_White"
    },
    {
      "x": -5,
      "y": 28,
      "z": -16,
      "name": "Rock_Sandstone_White"
    },
    {
      "x": -5,
      "y": 29,
      "z": -16,
      "name": "Rock_Sandstone_White"
    },
    {
      "x": -5,
      "y": 30,
      "z": -16,
      "name": "Soil_Sand_White"
    },
    {
      "x": -5,
      "y": 31,
      "z": -16,
      "name": "Soil_Gravel_Sand_White"
    },
    {
      "x": -5,
      "y": 32,
      "z": -16,
      "name": "Soil_Sand_White"
    },
    {
      "x": -5,
      "y": 33,
      "z": -16,
      "name": "Soil_Sand_White"
    },
    {
      "x": -5,
      "y": 22,
      "z": -15,
      "name": "Rock_Sandstone_White"
    },
    {
      "x": -5,
      "y": 23,
      "z": -15,
      "name": "Rock_Sandstone_White"
    },
    {
      "x": -5,
      "y": 24,
      "z": -15,
      "name": "Rock_Sandstone_White"
    },
    {
      "x": -5,
      "y": 25,
      "z": -15,
      "name": "Rock_Sandstone_White"
    },
    {
      "x": -5,
      "y": 26,
      "z": -15,
      "name": "Rock_Sandstone_White"
    },
    {
      "x": -5,
      "y": 27,
      "z": -15,
      "name": "Rock_Sandstone_White"
    },
    {
      "x": -5,
      "y": 28,
      "z": -15,
      "name": "Rock_Sandstone_White"
    },
    {
      "x": -5,
      "y": 29,
      "z": -15,
      "name": "Rock_Sandstone_White"
    },
    {
      "x": -5,
      "y": 30,
      "z": -15,
      "name": "Rock_Sandstone_White"
    },
    {
      "x": -5,
      "y": 31,
      "z": -15,
      "name": "Soil_Sand_White"
    },
    {
      "x": -5,
      "y": 32,
      "z": -15,
      "name": "Soil_Sand_White"
    },
    {
      "x": -5,
      "y": 33,
      "z": -15,
      "name": "Soil_Sand_White"
    },
    {
      "x": -5,
      "y": 36,
      "z": -15,
      "name": "Rock_Crystal_Yellow_Medium",
      "rotation": 7
    },
    {
      "x": -5,
      "y": 37,
      "z": -15,
      "name": "Rock_Crystal_Yellow_Medium",
      "rotation": 7
    },
    {
      "x": -5,
      "y": 38,
      "z": -15,
      "name": "Rock_Crystal_Yellow_Medium",
      "rotation": 7
    },
    {
      "x": -5,
      "y": 21,
      "z": -14,
      "name": "Rock_Sandstone_White"
    },
    {
      "x": -5,
      "y": 22,
      "z": -14,
      "name": "Rock_Sandstone_White"
    },
    {
      "x": -5,
      "y": 23,
      "z": -14,
      "name": "Rock_Sandstone_White"
    },
    {
      "x": -5,
      "y": 24,
      "z": -14,
      "name": "Rock_Sandstone_White_Cobble"
    },
    {
      "x": -5,
      "y": 25,
      "z": -14,
      "name": "Rock_Sandstone_White"
    },
    {
      "x": -5,
      "y": 26,
      "z": -14,
      "name": "Rock_Sandstone_White"
    },
    {
      "x": -5,
      "y": 27,
      "z": -14,
      "name": "Rock_Sandstone_White"
    },
    {
      "x": -5,
      "y": 28,
      "z": -14,
      "name": "Rock_Sandstone_White_Cobble"
    },
    {
      "x": -5,
      "y": 29,
      "z": -14,
      "name": "Rock_Sandstone_White"
    },
    {
      "x": -5,
      "y": 30,
      "z": -14,
      "name": "Rock_Sandstone_White"
    },
    {
      "x": -5,
      "y": 31,
      "z": -14,
      "name": "Soil_Gravel_Sand_White"
    },
    {
      "x": -5,
      "y": 32,
      "z": -14,
      "name": "Soil_Sand_White"
    },
    {
      "x": -5,
      "y": 33,
      "z": -14,
      "name": "Soil_Sand_White"
    },
    {
      "x": -5,
      "y": 20,
      "z": -13,
      "name": "Rock_Sandstone_White"
    },
    {
      "x": -5,
      "y": 21,
      "z": -13,
      "name": "Rock_Sandstone_White"
    },
    {
      "x": -5,
      "y": 22,
      "z": -13,
      "name": "Rock_Sandstone_White"
    },
    {
      "x": -5,
      "y": 23,
      "z": -13,
      "name": "Rock_Sandstone_White_Cobble"
    },
    {
      "x": -5,
      "y": 24,
      "z": -13,
      "name": "Rock_Sandstone_White"
    },
    {
      "x": -5,
      "y": 25,
      "z": -13,
      "name": "Rock_Sandstone_White_Cobble"
    },
    {
      "x": -5,
      "y": 26,
      "z": -13,
      "name": "Rock_Sandstone_White"
    },
    {
      "x": -5,
      "y": 27,
      "z": -13,
      "name": "Rock_Sandstone_White_Cobble"
    },
    {
      "x": -5,
      "y": 28,
      "z": -13,
      "name": "Rock_Sandstone_White"
    },
    {
      "x": -5,
      "y": 29,
      "z": -13,
      "name": "Rock_Sandstone_White"
    },
    {
      "x": -5,
      "y": 30,
      "z": -13,
      "name": "Rock_Sandstone_White"
    },
    {
      "x": -5,
      "y": 31,
      "z": -13,
      "name": "Rock_Sandstone_White"
    },
    {
      "x": -5,
      "y": 32,
      "z": -13,
      "name": "Rock_Sandstone_White"
    },
    {
      "x": -5,
      "y": 33,
      "z": -13,
      "name": "Soil_Sand_White"
    },
    {
      "x": -5,
      "y": 19,
      "z": -12,
      "name": "Rock_Sandstone_White"
    },
    {
      "x": -5,
      "y": 20,
      "z": -12,
      "name": "Rock_Sandstone_White"
    },
    {
      "x": -5,
      "y": 21,
      "z": -12,
      "name": "Rock_Sandstone_White"
    },
    {
      "x": -5,
      "y": 22,
      "z": -12,
      "name": "Rock_Sandstone_White"
    },
    {
      "x": -5,
      "y": 23,
      "z": -12,
      "name": "Rock_Sandstone_White_Cobble"
    },
    {
      "x": -5,
      "y": 24,
      "z": -12,
      "name": "Rock_Sandstone_White"
    },
    {
      "x": -5,
      "y": 25,
      "z": -12,
      "name": "Rock_Sandstone_White"
    },
    {
      "x": -5,
      "y": 26,
      "z": -12,
      "name": "Rock_Sandstone_White"
    },
    {
      "x": -5,
      "y": 27,
      "z": -12,
      "name": "Rock_Sandstone_White"
    },
    {
      "x": -5,
      "y": 28,
      "z": -12,
      "name": "Rock_Sandstone_White"
    },
    {
      "x": -5,
      "y": 29,
      "z": -12,
      "name": "Rock_Sandstone_White"
    },
    {
      "x": -5,
      "y": 30,
      "z": -12,
      "name": "Soil_Sand_White"
    },
    {
      "x": -5,
      "y": 31,
      "z": -12,
      "name": "Soil_Sand_White"
    },
    {
      "x": -5,
      "y": 32,
      "z": -12,
      "name": "Soil_Sand_White"
    },
    {
      "x": -5,
      "y": 33,
      "z": -12,
      "name": "Soil_Sand_White"
    },
    {
      "x": -5,
      "y": 15,
      "z": -11,
      "name": "Rock_Crystal_Yellow_Medium",
      "rotation": 7
    },
    {
      "x": -5,
      "y": 16,
      "z": -11,
      "name": "Rock_Crystal_Yellow_Medium",
      "rotation": 7
    },
    {
      "x": -5,
      "y": 17,
      "z": -11,
      "name": "Rock_Crystal_Yellow_Medium",
      "rotation": 7
    },
    {
      "x": -5,
      "y": 18,
      "z": -11,
      "name": "Rock_Crystal_Yellow_Medium",
      "rotation": 7
    },
    {
      "x": -5,
      "y": 19,
      "z": -11,
      "name": "Rock_Crystal_Yellow_Medium",
      "rotation": 7
    },
    {
      "x": -5,
      "y": 20,
      "z": -11,
      "name": "Rock_Sandstone_White"
    },
    {
      "x": -5,
      "y": 21,
      "z": -11,
      "name": "Rock_Sandstone_White"
    },
    {
      "x": -5,
      "y": 22,
      "z": -11,
      "name": "Rock_Sandstone_White"
    },
    {
      "x": -5,
      "y": 23,
      "z": -11,
      "name": "Rock_Sandstone_White"
    },
    {
      "x": -5,
      "y": 24,
      "z": -11,
      "name": "Rock_Sandstone_White"
    },
    {
      "x": -5,
      "y": 25,
      "z": -11,
      "name": "Rock_Sandstone_White"
    },
    {
      "x": -5,
      "y": 26,
      "z": -11,
      "name": "Rock_Sandstone_White"
    },
    {
      "x": -5,
      "y": 27,
      "z": -11,
      "name": "Rock_Sandstone_White"
    },
    {
      "x": -5,
      "y": 28,
      "z": -11,
      "name": "Rock_Sandstone_White"
    },
    {
      "x": -5,
      "y": 17,
      "z": -10,
      "name": "Rock_Sandstone_White"
    },
    {
      "x": -5,
      "y": 18,
      "z": -10,
      "name": "Rock_Sandstone_White"
    },
    {
      "x": -5,
      "y": 19,
      "z": -10,
      "name": "Rock_Sandstone_White"
    },
    {
      "x": -5,
      "y": 20,
      "z": -10,
      "name": "Rock_Sandstone_White"
    },
    {
      "x": -5,
      "y": 21,
      "z": -10,
      "name": "Rock_Sandstone_White"
    },
    {
      "x": -5,
      "y": 22,
      "z": -10,
      "name": "Rock_Sandstone_White"
    },
    {
      "x": -5,
      "y": 23,
      "z": -10,
      "name": "Rock_Sandstone_White"
    },
    {
      "x": -5,
      "y": 24,
      "z": -10,
      "name": "Rock_Sandstone_White"
    },
    {
      "x": -5,
      "y": 25,
      "z": -10,
      "name": "Rock_Sandstone_White"
    },
    {
      "x": -5,
      "y": 26,
      "z": -10,
      "name": "Rock_Sandstone_White"
    },
    {
      "x": -5,
      "y": 27,
      "z": -10,
      "name": "Soil_Sand_White"
    },
    {
      "x": -5,
      "y": 28,
      "z": -10,
      "name": "Soil_Sand_White"
    },
    {
      "x": -5,
      "y": 15,
      "z": -9,
      "name": "Rock_Sandstone_White"
    },
    {
      "x": -5,
      "y": 16,
      "z": -9,
      "name": "Rock_Sandstone_White"
    },
    {
      "x": -5,
      "y": 17,
      "z": -9,
      "name": "Rock_Sandstone_White"
    },
    {
      "x": -5,
      "y": 18,
      "z": -9,
      "name": "Rock_Sandstone_White"
    },
    {
      "x": -5,
      "y": 19,
      "z": -9,
      "name": "Rock_Sandstone_White"
    },
    {
      "x": -5,
      "y": 20,
      "z": -9,
      "name": "Rock_Sandstone_White"
    },
    {
      "x": -5,
      "y": 21,
      "z": -9,
      "name": "Rock_Sandstone_White_Cobble"
    },
    {
      "x": -5,
      "y": 22,
      "z": -9,
      "name": "Rock_Sandstone_White_Cobble"
    },
    {
      "x": -5,
      "y": 23,
      "z": -9,
      "name": "Rock_Sandstone_White"
    },
    {
      "x": -5,
      "y": 24,
      "z": -9,
      "name": "Rock_Sandstone_White"
    },
    {
      "x": -5,
      "y": 25,
      "z": -9,
      "name": "Rock_Sandstone_White"
    },
    {
      "x": -5,
      "y": 26,
      "z": -9,
      "name": "Rock_Sandstone_White"
    },
    {
      "x": -5,
      "y": 27,
      "z": -9,
      "name": "Rock_Sandstone_White"
    },
    {
      "x": -5,
      "y": 28,
      "z": -9,
      "name": "Rock_Sandstone_White"
    },
    {
      "x": -5,
      "y": 13,
      "z": -8,
      "name": "Rock_Sandstone_White_Stalactite_Small",
      "rotation": 9
    },
    {
      "x": -5,
      "y": 14,
      "z": -8,
      "name": "Rock_Sandstone_White"
    },
    {
      "x": -5,
      "y": 15,
      "z": -8,
      "name": "Rock_Sandstone_White"
    },
    {
      "x": -5,
      "y": 16,
      "z": -8,
      "name": "Rock_Sandstone_White"
    },
    {
      "x": -5,
      "y": 17,
      "z": -8,
      "name": "Rock_Sandstone_White"
    },
    {
      "x": -5,
      "y": 18,
      "z": -8,
      "name": "Rock_Sandstone_White_Cobble"
    },
    {
      "x": -5,
      "y": 19,
      "z": -8,
      "name": "Rock_Sandstone_White_Cobble"
    },
    {
      "x": -5,
      "y": 20,
      "z": -8,
      "name": "Rock_Sandstone_White"
    },
    {
      "x": -5,
      "y": 21,
      "z": -8,
      "name": "Rock_Sandstone_White"
    },
    {
      "x": -5,
      "y": 22,
      "z": -8,
      "name": "Ore_Thorium_Sandstone"
    },
    {
      "x": -5,
      "y": 23,
      "z": -8,
      "name": "Rock_Sandstone_White"
    },
    {
      "x": -5,
      "y": 24,
      "z": -8,
      "name": "Rock_Sandstone_White_Cobble"
    },
    {
      "x": -5,
      "y": 25,
      "z": -8,
      "name": "Rock_Sandstone_White_Cobble"
    },
    {
      "x": -5,
      "y": 26,
      "z": -8,
      "name": "Soil_Sand_White"
    },
    {
      "x": -5,
      "y": 27,
      "z": -8,
      "name": "Soil_Sand_White"
    },
    {
      "x": -5,
      "y": 14,
      "z": -7,
      "name": "Rock_Sandstone_White_Cobble"
    },
    {
      "x": -5,
      "y": 15,
      "z": -7,
      "name": "Rock_Sandstone_White_Cobble"
    },
    {
      "x": -5,
      "y": 16,
      "z": -7,
      "name": "Rock_Sandstone_White"
    },
    {
      "x": -5,
      "y": 17,
      "z": -7,
      "name": "Rock_Sandstone_White"
    },
    {
      "x": -5,
      "y": 18,
      "z": -7,
      "name": "Rock_Sandstone_White"
    },
    {
      "x": -5,
      "y": 19,
      "z": -7,
      "name": "Rock_Sandstone_White"
    },
    {
      "x": -5,
      "y": 20,
      "z": -7,
      "name": "Rock_Sandstone_White"
    },
    {
      "x": -5,
      "y": 21,
      "z": -7,
      "name": "Rock_Sandstone_White_Cobble"
    },
    {
      "x": -5,
      "y": 22,
      "z": -7,
      "name": "Rock_Sandstone_White"
    },
    {
      "x": -5,
      "y": 23,
      "z": -7,
      "name": "Rock_Sandstone_White"
    },
    {
      "x": -5,
      "y": 24,
      "z": -7,
      "name": "Rock_Sandstone_White"
    },
    {
      "x": -5,
      "y": 25,
      "z": -7,
      "name": "Soil_Gravel_Sand_White"
    },
    {
      "x": -5,
      "y": 26,
      "z": -7,
      "name": "Soil_Sand_White"
    },
    {
      "x": -5,
      "y": 27,
      "z": -7,
      "name": "Soil_Sand_White"
    },
    {
      "x": -5,
      "y": 14,
      "z": -6,
      "name": "Rock_Sandstone_White_Cobble"
    },
    {
      "x": -5,
      "y": 15,
      "z": -6,
      "name": "Rock_Sandstone_White"
    },
    {
      "x": -5,
      "y": 16,
      "z": -6,
      "name": "Rock_Sandstone_White"
    },
    {
      "x": -5,
      "y": 17,
      "z": -6,
      "name": "Rock_Sandstone_White"
    },
    {
      "x": -5,
      "y": 18,
      "z": -6,
      "name": "Rock_Sandstone_White"
    },
    {
      "x": -5,
      "y": 19,
      "z": -6,
      "name": "Rock_Sandstone_White"
    },
    {
      "x": -5,
      "y": 20,
      "z": -6,
      "name": "Rock_Sandstone_White"
    },
    {
      "x": -5,
      "y": 21,
      "z": -6,
      "name": "Rock_Sandstone_White"
    },
    {
      "x": -5,
      "y": 22,
      "z": -6,
      "name": "Rock_Sandstone_White"
    },
    {
      "x": -5,
      "y": 23,
      "z": -6,
      "name": "Rock_Sandstone_White"
    },
    {
      "x": -5,
      "y": 24,
      "z": -6,
      "name": "Rock_Sandstone_White"
    },
    {
      "x": -5,
      "y": 25,
      "z": -6,
      "name": "Soil_Sand_White"
    },
    {
      "x": -5,
      "y": 26,
      "z": -6,
      "name": "Soil_Sand_White"
    },
    {
      "x": -5,
      "y": 27,
      "z": -6,
      "name": "Soil_Sand_White"
    },
    {
      "x": -5,
      "y": 15,
      "z": -5,
      "name": "Rock_Sandstone_White"
    },
    {
      "x": -5,
      "y": 16,
      "z": -5,
      "name": "Rock_Sandstone_White"
    },
    {
      "x": -5,
      "y": 17,
      "z": -5,
      "name": "Rock_Sandstone_White"
    },
    {
      "x": -5,
      "y": 18,
      "z": -5,
      "name": "Rock_Sandstone_White"
    },
    {
      "x": -5,
      "y": 19,
      "z": -5,
      "name": "Rock_Sandstone_White"
    },
    {
      "x": -5,
      "y": 20,
      "z": -5,
      "name": "Rock_Sandstone_White_Cobble"
    },
    {
      "x": -5,
      "y": 21,
      "z": -5,
      "name": "Rock_Sandstone_White"
    },
    {
      "x": -5,
      "y": 22,
      "z": -5,
      "name": "Rock_Sandstone_White_Cobble"
    },
    {
      "x": -5,
      "y": 23,
      "z": -5,
      "name": "Rock_Sandstone_White"
    },
    {
      "x": -5,
      "y": 24,
      "z": -5,
      "name": "Soil_Gravel_Sand_White"
    },
    {
      "x": -5,
      "y": 25,
      "z": -5,
      "name": "Soil_Sand_White"
    },
    {
      "x": -5,
      "y": 26,
      "z": -5,
      "name": "Soil_Gravel_Sand_White"
    },
    {
      "x": -5,
      "y": 27,
      "z": -5,
      "name": "Soil_Gravel_Sand_White"
    },
    {
      "x": -5,
      "y": 17,
      "z": -4,
      "name": "Rock_Sandstone_White"
    },
    {
      "x": -5,
      "y": 18,
      "z": -4,
      "name": "Rock_Sandstone_White"
    },
    {
      "x": -5,
      "y": 19,
      "z": -4,
      "name": "Rock_Sandstone_White"
    },
    {
      "x": -5,
      "y": 20,
      "z": -4,
      "name": "Rock_Sandstone_White"
    },
    {
      "x": -5,
      "y": 21,
      "z": -4,
      "name": "Rock_Sandstone_White"
    },
    {
      "x": -5,
      "y": 22,
      "z": -4,
      "name": "Rock_Sandstone_White"
    },
    {
      "x": -5,
      "y": 23,
      "z": -4,
      "name": "Rock_Sandstone_White"
    },
    {
      "x": -5,
      "y": 24,
      "z": -4,
      "name": "Rock_Sandstone_White_Cobble"
    },
    {
      "x": -5,
      "y": 25,
      "z": -4,
      "name": "Soil_Sand_White"
    },
    {
      "x": -5,
      "y": 26,
      "z": -4,
      "name": "Soil_Gravel_Sand_White"
    },
    {
      "x": -5,
      "y": 27,
      "z": -4,
      "name": "Soil_Sand_White"
    },
    {
      "x": -5,
      "y": 19,
      "z": -3,
      "name": "Rock_Sandstone_White"
    },
    {
      "x": -5,
      "y": 20,
      "z": -3,
      "name": "Rock_Sandstone_White"
    },
    {
      "x": -5,
      "y": 21,
      "z": -3,
      "name": "Rock_Sandstone_White"
    },
    {
      "x": -5,
      "y": 22,
      "z": -3,
      "name": "Rock_Sandstone_White"
    },
    {
      "x": -5,
      "y": 23,
      "z": -3,
      "name": "Rock_Sandstone_White"
    },
    {
      "x": -5,
      "y": 24,
      "z": -3,
      "name": "Rock_Sandstone_White"
    },
    {
      "x": -5,
      "y": 25,
      "z": -3,
      "name": "Rock_Sandstone_White"
    },
    {
      "x": -5,
      "y": 26,
      "z": -3,
      "name": "Soil_Gravel_Sand_White"
    },
    {
      "x": -5,
      "y": 27,
      "z": -3,
      "name": "Soil_Sand_White"
    },
    {
      "x": -5,
      "y": 23,
      "z": -2,
      "name": "Rock_Sandstone_White"
    },
    {
      "x": -5,
      "y": 24,
      "z": -2,
      "name": "Rock_Sandstone_White"
    },
    {
      "x": -5,
      "y": 25,
      "z": -2,
      "name": "Rock_Sandstone_White_Cobble"
    },
    {
      "x": -5,
      "y": 26,
      "z": -2,
      "name": "Rock_Sandstone_White"
    },
    {
      "x": -5,
      "y": 27,
      "z": -2,
      "name": "Rock_Sandstone_White"
    },
    {
      "x": -5,
      "y": 13,
      "z": 4,
      "name": "Rock_Sandstone_White_Stalactite_Small",
      "rotation": 8
    },
    {
      "x": -5,
      "y": 14,
      "z": 4,
      "name": "Rock_Sandstone_White"
    },
    {
      "x": -5,
      "y": 15,
      "z": 4,
      "name": "Soil_Sand_White"
    },
    {
      "x": -5,
      "y": 16,
      "z": 4,
      "name": "Soil_Sand_White"
    },
    {
      "x": -5,
      "y": 17,
      "z": 4,
      "name": "Soil_Sand_White"
    },
    {
      "x": -5,
      "y": 10,
      "z": 5,
      "name": "Rock_Sandstone_White_Cobble"
    },
    {
      "x": -5,
      "y": 11,
      "z": 5,
      "name": "Rock_Sandstone_White"
    },
    {
      "x": -5,
      "y": 12,
      "z": 5,
      "name": "Rock_Sandstone_White"
    },
    {
      "x": -5,
      "y": 13,
      "z": 5,
      "name": "Rock_Sandstone_White"
    },
    {
      "x": -5,
      "y": 14,
      "z": 5,
      "name": "Soil_Sand_White"
    },
    {
      "x": -5,
      "y": 15,
      "z": 5,
      "name": "Soil_Sand_White"
    },
    {
      "x": -5,
      "y": 16,
      "z": 5,
      "name": "Soil_Sand_White"
    },
    {
      "x": -5,
      "y": 17,
      "z": 5,
      "name": "Soil_Sand_White"
    },
    {
      "x": -5,
      "y": 18,
      "z": 5,
      "name": "Rubble_Sandstone_White"
    },
    {
      "x": -5,
      "y": 8,
      "z": 6,
      "name": "Rock_Sandstone_White"
    },
    {
      "x": -5,
      "y": 9,
      "z": 6,
      "name": "Rock_Sandstone_White"
    },
    {
      "x": -5,
      "y": 10,
      "z": 6,
      "name": "Rock_Sandstone_White"
    },
    {
      "x": -5,
      "y": 11,
      "z": 6,
      "name": "Rock_Sandstone_White_Cobble"
    },
    {
      "x": -5,
      "y": 12,
      "z": 6,
      "name": "Rock_Sandstone_White_Cobble"
    },
    {
      "x": -5,
      "y": 13,
      "z": 6,
      "name": "Rock_Sandstone_White"
    },
    {
      "x": -5,
      "y": 14,
      "z": 6,
      "name": "Rock_Sandstone_White"
    },
    {
      "x": -5,
      "y": 15,
      "z": 6,
      "name": "Rock_Sandstone_White"
    },
    {
      "x": -5,
      "y": 16,
      "z": 6,
      "name": "Rock_Sandstone_White_Cobble"
    },
    {
      "x": -5,
      "y": 17,
      "z": 6,
      "name": "Rock_Sandstone_White_Brick"
    },
    {
      "x": -5,
      "y": 18,
      "z": 6,
      "name": "Rock_Sandstone_White_Brick_Pillar_Middle",
      "rotation": 7
    },
    {
      "x": -5,
      "y": 3,
      "z": 7,
      "name": "Rock_Crystal_Yellow_Medium",
      "rotation": 7
    },
    {
      "x": -5,
      "y": 4,
      "z": 7,
      "name": "Rock_Crystal_Yellow_Medium",
      "rotation": 7
    },
    {
      "x": -5,
      "y": 6,
      "z": 7,
      "name": "Rock_Crystal_Yellow_Medium",
      "rotation": 6
    },
    {
      "x": -5,
      "y": 7,
      "z": 7,
      "name": "Rock_Sandstone_White"
    },
    {
      "x": -5,
      "y": 8,
      "z": 7,
      "name": "Rock_Sandstone_White"
    },
    {
      "x": -5,
      "y": 9,
      "z": 7,
      "name": "Rock_Sandstone_White_Cobble"
    },
    {
      "x": -5,
      "y": 10,
      "z": 7,
      "name": "Rock_Sandstone_White"
    },
    {
      "x": -5,
      "y": 11,
      "z": 7,
      "name": "Rock_Sandstone_White"
    },
    {
      "x": -5,
      "y": 12,
      "z": 7,
      "name": "Rock_Sandstone_White"
    },
    {
      "x": -5,
      "y": 13,
      "z": 7,
      "name": "Rock_Sandstone_White_Cobble"
    },
    {
      "x": -5,
      "y": 14,
      "z": 7,
      "name": "Rock_Sandstone_White"
    },
    {
      "x": -5,
      "y": 15,
      "z": 7,
      "name": "Rock_Sandstone_White"
    },
    {
      "x": -5,
      "y": 16,
      "z": 7,
      "name": "Rock_Sandstone_White"
    },
    {
      "x": -5,
      "y": 17,
      "z": 7,
      "name": "Rock_Sandstone_White_Brick"
    },
    {
      "x": -5,
      "y": 2,
      "z": 8,
      "name": "Rock_Crystal_Yellow_Medium",
      "rotation": 7
    },
    {
      "x": -5,
      "y": 3,
      "z": 8,
      "name": "Rock_Crystal_Yellow_Medium",
      "rotation": 7
    },
    {
      "x": -5,
      "y": 4,
      "z": 8,
      "name": "Rock_Crystal_Yellow_Large",
      "rotation": 8
    },
    {
      "x": -5,
      "y": 5,
      "z": 8,
      "name": "Rock_Crystal_Yellow_Block"
    },
    {
      "x": -5,
      "y": 6,
      "z": 8,
      "name": "Rock_Crystal_Yellow_Block"
    },
    {
      "x": -5,
      "y": 7,
      "z": 8,
      "name": "Rock_Crystal_Yellow_Block",
      "rotation": 5
    },
    {
      "x": -5,
      "y": 8,
      "z": 8,
      "name": "Rock_Crystal_Yellow_Block"
    },
    {
      "x": -5,
      "y": 9,
      "z": 8,
      "name": "Rock_Crystal_Yellow_Block"
    },
    {
      "x": -5,
      "y": 10,
      "z": 8,
      "name": "Rock_Sandstone_White_Cobble"
    },
    {
      "x": -5,
      "y": 11,
      "z": 8,
      "name": "Rock_Sandstone_White"
    },
    {
      "x": -5,
      "y": 12,
      "z": 8,
      "name": "Rock_Sandstone_White_Cobble"
    },
    {
      "x": -5,
      "y": 13,
      "z": 8,
      "name": "Rock_Sandstone_White"
    },
    {
      "x": -5,
      "y": 14,
      "z": 8,
      "name": "Rock_Sandstone_White"
    },
    {
      "x": -5,
      "y": 15,
      "z": 8,
      "name": "Rock_Sandstone_White"
    },
    {
      "x": -5,
      "y": 16,
      "z": 8,
      "name": "Rock_Sandstone_White"
    },
    {
      "x": -5,
      "y": 17,
      "z": 8,
      "name": "Rock_Sandstone_White_Brick"
    },
    {
      "x": -5,
      "y": 4,
      "z": 9,
      "name": "Rock_Crystal_Yellow_Medium",
      "rotation": 7
    },
    {
      "x": -5,
      "y": 5,
      "z": 9,
      "name": "Rock_Crystal_Yellow_Medium",
      "rotation": 4
    },
    {
      "x": -5,
      "y": 6,
      "z": 9,
      "name": "Rock_Crystal_Yellow_Medium",
      "rotation": 4
    },
    {
      "x": -5,
      "y": 7,
      "z": 9,
      "name": "Rock_Sandstone_White"
    },
    {
      "x": -5,
      "y": 8,
      "z": 9,
      "name": "Rock_Sandstone_White"
    },
    {
      "x": -5,
      "y": 9,
      "z": 9,
      "name": "Rock_Sandstone_White"
    },
    {
      "x": -5,
      "y": 10,
      "z": 9,
      "name": "Rock_Sandstone_White"
    },
    {
      "x": -5,
      "y": 11,
      "z": 9,
      "name": "Rock_Sandstone_White"
    },
    {
      "x": -5,
      "y": 12,
      "z": 9,
      "name": "Rock_Sandstone_White"
    },
    {
      "x": -5,
      "y": 13,
      "z": 9,
      "name": "Rock_Sandstone_White"
    },
    {
      "x": -5,
      "y": 14,
      "z": 9,
      "name": "Rock_Sandstone_White"
    },
    {
      "x": -5,
      "y": 15,
      "z": 9,
      "name": "Rock_Sandstone_White"
    },
    {
      "x": -5,
      "y": 16,
      "z": 9,
      "name": "Rock_Sandstone_White"
    },
    {
      "x": -5,
      "y": 17,
      "z": 9,
      "name": "Rock_Sandstone_White_Brick"
    },
    {
      "x": -5,
      "y": 8,
      "z": 10,
      "name": "Rock_Sandstone_White"
    },
    {
      "x": -5,
      "y": 9,
      "z": 10,
      "name": "Rock_Sandstone_White"
    },
    {
      "x": -5,
      "y": 10,
      "z": 10,
      "name": "Rock_Sandstone_White"
    },
    {
      "x": -5,
      "y": 11,
      "z": 10,
      "name": "Rock_Sandstone_White"
    },
    {
      "x": -5,
      "y": 12,
      "z": 10,
      "name": "Rock_Sandstone_White"
    },
    {
      "x": -5,
      "y": 13,
      "z": 10,
      "name": "Rock_Sandstone_White"
    },
    {
      "x": -5,
      "y": 14,
      "z": 10,
      "name": "Soil_Sand_White"
    },
    {
      "x": -5,
      "y": 15,
      "z": 10,
      "name": "Soil_Sand_White"
    },
    {
      "x": -5,
      "y": 16,
      "z": 10,
      "name": "Soil_Sand_White"
    },
    {
      "x": -5,
      "y": 17,
      "z": 10,
      "name": "Soil_Sand_White"
    },
    {
      "x": -5,
      "y": 10,
      "z": 11,
      "name": "Rock_Sandstone_White"
    },
    {
      "x": -5,
      "y": 11,
      "z": 11,
      "name": "Rock_Sandstone_White"
    },
    {
      "x": -5,
      "y": 12,
      "z": 11,
      "name": "Rock_Sandstone_White"
    },
    {
      "x": -5,
      "y": 13,
      "z": 11,
      "name": "Rock_Sandstone_White"
    },
    {
      "x": -5,
      "y": 14,
      "z": 11,
      "name": "Rock_Sandstone_White"
    },
    {
      "x": -5,
      "y": 15,
      "z": 11,
      "name": "Soil_Sand_White"
    },
    {
      "x": -5,
      "y": 16,
      "z": 11,
      "name": "Soil_Sand_White"
    },
    {
      "x": -5,
      "y": 17,
      "z": 11,
      "name": "Soil_Gravel_Sand_White"
    },
    {
      "x": -5,
      "y": 14,
      "z": 12,
      "name": "Rock_Sandstone_White"
    },
    {
      "x": -5,
      "y": 15,
      "z": 12,
      "name": "Soil_Gravel_Sand_White"
    },
    {
      "x": -5,
      "y": 16,
      "z": 12,
      "name": "Soil_Gravel_Sand_White"
    },
    {
      "x": -4,
      "y": 29,
      "z": -19,
      "name": "Rock_Sandstone_White"
    },
    {
      "x": -4,
      "y": 30,
      "z": -19,
      "name": "Rock_Sandstone_White_Cobble"
    },
    {
      "x": -4,
      "y": 31,
      "z": -19,
      "name": "Soil_Sand_White"
    },
    {
      "x": -4,
      "y": 32,
      "z": -19,
      "name": "Soil_Sand_White"
    },
    {
      "x": -4,
      "y": 33,
      "z": -19,
      "name": "Soil_Sand_White"
    },
    {
      "x": -4,
      "y": 25,
      "z": -18,
      "name": "Rock_Sandstone_White"
    },
    {
      "x": -4,
      "y": 26,
      "z": -18,
      "name": "Rock_Sandstone_White"
    },
    {
      "x": -4,
      "y": 27,
      "z": -18,
      "name": "Rock_Sandstone_White"
    },
    {
      "x": -4,
      "y": 28,
      "z": -18,
      "name": "Rock_Sandstone_White"
    },
    {
      "x": -4,
      "y": 29,
      "z": -18,
      "name": "Rock_Sandstone_White"
    },
    {
      "x": -4,
      "y": 30,
      "z": -18,
      "name": "Rock_Sandstone_White"
    },
    {
      "x": -4,
      "y": 31,
      "z": -18,
      "name": "Soil_Sand_White"
    },
    {
      "x": -4,
      "y": 32,
      "z": -18,
      "name": "Soil_Sand_White"
    },
    {
      "x": -4,
      "y": 33,
      "z": -18,
      "name": "Soil_Sand_White"
    },
    {
      "x": -4,
      "y": 23,
      "z": -17,
      "name": "Rock_Sandstone_White"
    },
    {
      "x": -4,
      "y": 24,
      "z": -17,
      "name": "Rock_Sandstone_White"
    },
    {
      "x": -4,
      "y": 25,
      "z": -17,
      "name": "Rock_Sandstone_White"
    },
    {
      "x": -4,
      "y": 26,
      "z": -17,
      "name": "Rock_Sandstone_White"
    },
    {
      "x": -4,
      "y": 27,
      "z": -17,
      "name": "Rock_Sandstone_White"
    },
    {
      "x": -4,
      "y": 28,
      "z": -17,
      "name": "Rock_Sandstone_White_Cobble"
    },
    {
      "x": -4,
      "y": 29,
      "z": -17,
      "name": "Rock_Sandstone_White"
    },
    {
      "x": -4,
      "y": 30,
      "z": -17,
      "name": "Rock_Sandstone_White"
    },
    {
      "x": -4,
      "y": 31,
      "z": -17,
      "name": "Rock_Sandstone_White"
    },
    {
      "x": -4,
      "y": 32,
      "z": -17,
      "name": "Soil_Sand_White"
    },
    {
      "x": -4,
      "y": 33,
      "z": -17,
      "name": "Soil_Sand_White"
    },
    {
      "x": -4,
      "y": 22,
      "z": -16,
      "name": "Rock_Sandstone_White"
    },
    {
      "x": -4,
      "y": 23,
      "z": -16,
      "name": "Rock_Sandstone_White"
    },
    {
      "x": -4,
      "y": 24,
      "z": -16,
      "name": "Rock_Sandstone_White"
    },
    {
      "x": -4,
      "y": 25,
      "z": -16,
      "name": "Rock_Sandstone_White"
    },
    {
      "x": -4,
      "y": 26,
      "z": -16,
      "name": "Rock_Sandstone_White"
    },
    {
      "x": -4,
      "y": 27,
      "z": -16,
      "name": "Rock_Sandstone_White"
    },
    {
      "x": -4,
      "y": 28,
      "z": -16,
      "name": "Rock_Sandstone_White_Cobble"
    },
    {
      "x": -4,
      "y": 29,
      "z": -16,
      "name": "Rock_Sandstone_White_Cobble"
    },
    {
      "x": -4,
      "y": 30,
      "z": -16,
      "name": "Rock_Sandstone_White"
    },
    {
      "x": -4,
      "y": 31,
      "z": -16,
      "name": "Soil_Sand_White"
    },
    {
      "x": -4,
      "y": 32,
      "z": -16,
      "name": "Soil_Sand_White"
    },
    {
      "x": -4,
      "y": 33,
      "z": -16,
      "name": "Soil_Sand_White"
    },
    {
      "x": -4,
      "y": 35,
      "z": -16,
      "name": "Rock_Crystal_Yellow_Medium",
      "rotation": 7
    },
    {
      "x": -4,
      "y": 36,
      "z": -16,
      "name": "Rock_Crystal_Yellow_Medium",
      "rotation": 7
    },
    {
      "x": -4,
      "y": 39,
      "z": -16,
      "name": "Rock_Crystal_Yellow_Medium",
      "rotation": 7
    },
    {
      "x": -4,
      "y": 41,
      "z": -16,
      "name": "Rock_Crystal_Yellow_Medium",
      "rotation": 7
    },
    {
      "x": -4,
      "y": 21,
      "z": -15,
      "name": "Rock_Sandstone_White"
    },
    {
      "x": -4,
      "y": 22,
      "z": -15,
      "name": "Rock_Sandstone_White"
    },
    {
      "x": -4,
      "y": 23,
      "z": -15,
      "name": "Rock_Sandstone_White_Cobble"
    },
    {
      "x": -4,
      "y": 24,
      "z": -15,
      "name": "Rock_Sandstone_White"
    },
    {
      "x": -4,
      "y": 25,
      "z": -15,
      "name": "Rock_Sandstone_White"
    },
    {
      "x": -4,
      "y": 26,
      "z": -15,
      "name": "Rock_Sandstone_White"
    },
    {
      "x": -4,
      "y": 27,
      "z": -15,
      "name": "Rock_Sandstone_White"
    },
    {
      "x": -4,
      "y": 28,
      "z": -15,
      "name": "Rock_Sandstone_White"
    },
    {
      "x": -4,
      "y": 29,
      "z": -15,
      "name": "Rock_Sandstone_White"
    },
    {
      "x": -4,
      "y": 30,
      "z": -15,
      "name": "Rock_Sandstone_White"
    },
    {
      "x": -4,
      "y": 31,
      "z": -15,
      "name": "Rock_Crystal_Yellow_Block"
    },
    {
      "x": -4,
      "y": 32,
      "z": -15,
      "name": "Rock_Crystal_Yellow_Block"
    },
    {
      "x": -4,
      "y": 33,
      "z": -15,
      "name": "Rock_Crystal_Yellow_Block"
    },
    {
      "x": -4,
      "y": 34,
      "z": -15,
      "name": "Rock_Crystal_Yellow_Block"
    },
    {
      "x": -4,
      "y": 35,
      "z": -15,
      "name": "Rock_Crystal_Yellow_Block"
    },
    {
      "x": -4,
      "y": 36,
      "z": -15,
      "name": "Rock_Crystal_Yellow_Block"
    },
    {
      "x": -4,
      "y": 37,
      "z": -15,
      "name": "Rock_Crystal_Yellow_Block"
    },
    {
      "x": -4,
      "y": 38,
      "z": -15,
      "name": "Rock_Crystal_Yellow_Block"
    },
    {
      "x": -4,
      "y": 39,
      "z": -15,
      "name": "Rock_Crystal_Yellow_Large"
    },
    {
      "x": -4,
      "y": 40,
      "z": -15,
      "name": "Rock_Crystal_Yellow_Medium",
      "rotation": 7
    },
    {
      "x": -4,
      "y": 41,
      "z": -15,
      "name": "Rock_Crystal_Yellow_Medium",
      "rotation": 7
    },
    {
      "x": -4,
      "y": 42,
      "z": -15,
      "name": "Rock_Crystal_Yellow_Medium",
      "rotation": 7
    },
    {
      "x": -4,
      "y": 19,
      "z": -14,
      "name": "Rock_Sandstone_White"
    },
    {
      "x": -4,
      "y": 20,
      "z": -14,
      "name": "Rock_Sandstone_White"
    },
    {
      "x": -4,
      "y": 21,
      "z": -14,
      "name": "Rock_Sandstone_White"
    },
    {
      "x": -4,
      "y": 22,
      "z": -14,
      "name": "Rock_Sandstone_White"
    },
    {
      "x": -4,
      "y": 23,
      "z": -14,
      "name": "Rock_Sandstone_White"
    },
    {
      "x": -4,
      "y": 24,
      "z": -14,
      "name": "Rock_Sandstone_White_Cobble"
    },
    {
      "x": -4,
      "y": 25,
      "z": -14,
      "name": "Rock_Sandstone_White"
    },
    {
      "x": -4,
      "y": 26,
      "z": -14,
      "name": "Rock_Sandstone_White"
    },
    {
      "x": -4,
      "y": 27,
      "z": -14,
      "name": "Rock_Sandstone_White"
    },
    {
      "x": -4,
      "y": 28,
      "z": -14,
      "name": "Rock_Sandstone_White"
    },
    {
      "x": -4,
      "y": 29,
      "z": -14,
      "name": "Rock_Sandstone_White"
    },
    {
      "x": -4,
      "y": 30,
      "z": -14,
      "name": "Rock_Sandstone_White"
    },
    {
      "x": -4,
      "y": 31,
      "z": -14,
      "name": "Soil_Gravel_Sand_White"
    },
    {
      "x": -4,
      "y": 32,
      "z": -14,
      "name": "Soil_Sand_White"
    },
    {
      "x": -4,
      "y": 33,
      "z": -14,
      "name": "Soil_Gravel_Sand_White"
    },
    {
      "x": -4,
      "y": 35,
      "z": -14,
      "name": "Rock_Crystal_Yellow_Medium",
      "rotation": 7
    },
    {
      "x": -4,
      "y": 36,
      "z": -14,
      "name": "Rock_Crystal_Yellow_Medium",
      "rotation": 4
    },
    {
      "x": -4,
      "y": 37,
      "z": -14,
      "name": "Rock_Crystal_Yellow_Medium",
      "rotation": 7
    },
    {
      "x": -4,
      "y": 39,
      "z": -14,
      "name": "Rock_Crystal_Yellow_Medium",
      "rotation": 7
    },
    {
      "x": -4,
      "y": 18,
      "z": -13,
      "name": "Rock_Sandstone_White"
    },
    {
      "x": -4,
      "y": 19,
      "z": -13,
      "name": "Rock_Sandstone_White"
    },
    {
      "x": -4,
      "y": 20,
      "z": -13,
      "name": "Rock_Sandstone_White"
    },
    {
      "x": -4,
      "y": 21,
      "z": -13,
      "name": "Rock_Sandstone_White"
    },
    {
      "x": -4,
      "y": 22,
      "z": -13,
      "name": "Rock_Sandstone_White"
    },
    {
      "x": -4,
      "y": 23,
      "z": -13,
      "name": "Rock_Sandstone_White"
    },
    {
      "x": -4,
      "y": 24,
      "z": -13,
      "name": "Rock_Sandstone_White"
    },
    {
      "x": -4,
      "y": 25,
      "z": -13,
      "name": "Rock_Sandstone_White"
    },
    {
      "x": -4,
      "y": 26,
      "z": -13,
      "name": "Rock_Sandstone_White"
    },
    {
      "x": -4,
      "y": 27,
      "z": -13,
      "name": "Rock_Sandstone_White_Cobble"
    },
    {
      "x": -4,
      "y": 28,
      "z": -13,
      "name": "Rock_Sandstone_White"
    },
    {
      "x": -4,
      "y": 29,
      "z": -13,
      "name": "Rock_Sandstone_White"
    },
    {
      "x": -4,
      "y": 30,
      "z": -13,
      "name": "Soil_Sand_White"
    },
    {
      "x": -4,
      "y": 31,
      "z": -13,
      "name": "Soil_Sand_White"
    },
    {
      "x": -4,
      "y": 32,
      "z": -13,
      "name": "Soil_Sand_White"
    },
    {
      "x": -4,
      "y": 33,
      "z": -13,
      "name": "Soil_Sand_White"
    },
    {
      "x": -4,
      "y": 34,
      "z": -13,
      "name": "Rock_Crystal_Yellow_Large"
    },
    {
      "x": -4,
      "y": 15,
      "z": -12,
      "name": "Rock_Crystal_Yellow_Large",
      "rotation": 6
    },
    {
      "x": -4,
      "y": 16,
      "z": -12,
      "name": "Rock_Crystal_Yellow_Medium",
      "rotation": 8
    },
    {
      "x": -4,
      "y": 17,
      "z": -12,
      "name": "Rock_Sandstone_White"
    },
    {
      "x": -4,
      "y": 18,
      "z": -12,
      "name": "Rock_Sandstone_White"
    },
    {
      "x": -4,
      "y": 19,
      "z": -12,
      "name": "Rock_Sandstone_White"
    },
    {
      "x": -4,
      "y": 20,
      "z": -12,
      "name": "Rock_Sandstone_White"
    },
    {
      "x": -4,
      "y": 21,
      "z": -12,
      "name": "Rock_Sandstone_White"
    },
    {
      "x": -4,
      "y": 22,
      "z": -12,
      "name": "Rock_Sandstone_White"
    },
    {
      "x": -4,
      "y": 23,
      "z": -12,
      "name": "Rock_Sandstone_White"
    },
    {
      "x": -4,
      "y": 24,
      "z": -12,
      "name": "Rock_Sandstone_White"
    },
    {
      "x": -4,
      "y": 25,
      "z": -12,
      "name": "Rock_Sandstone_White_Cobble"
    },
    {
      "x": -4,
      "y": 26,
      "z": -12,
      "name": "Rock_Sandstone_White"
    },
    {
      "x": -4,
      "y": 27,
      "z": -12,
      "name": "Rock_Sandstone_White"
    },
    {
      "x": -4,
      "y": 28,
      "z": -12,
      "name": "Rock_Sandstone_White_Cobble"
    },
    {
      "x": -4,
      "y": 29,
      "z": -12,
      "name": "Rock_Sandstone_White"
    },
    {
      "x": -4,
      "y": 30,
      "z": -12,
      "name": "Soil_Sand_White"
    },
    {
      "x": -4,
      "y": 31,
      "z": -12,
      "name": "Soil_Sand_White"
    },
    {
      "x": -4,
      "y": 32,
      "z": -12,
      "name": "Soil_Sand_White"
    },
    {
      "x": -4,
      "y": 33,
      "z": -12,
      "name": "Soil_Sand_White"
    },
    {
      "x": -4,
      "y": 12,
      "z": -11,
      "name": "Rock_Crystal_Yellow_Large",
      "rotation": 7
    },
    {
      "x": -4,
      "y": 13,
      "z": -11,
      "name": "Rock_Crystal_Yellow_Large",
      "rotation": 7
    },
    {
      "x": -4,
      "y": 14,
      "z": -11,
      "name": "Rock_Crystal_Yellow_Large",
      "rotation": 8
    },
    {
      "x": -4,
      "y": 15,
      "z": -11,
      "name": "Rock_Crystal_Yellow_Block"
    },
    {
      "x": -4,
      "y": 16,
      "z": -11,
      "name": "Rock_Crystal_Yellow_Block"
    },
    {
      "x": -4,
      "y": 17,
      "z": -11,
      "name": "Rock_Crystal_Yellow_Block"
    },
    {
      "x": -4,
      "y": 18,
      "z": -11,
      "name": "Rock_Crystal_Yellow_Block"
    },
    {
      "x": -4,
      "y": 19,
      "z": -11,
      "name": "Rock_Crystal_Yellow_Block"
    },
    {
      "x": -4,
      "y": 20,
      "z": -11,
      "name": "Rock_Crystal_Yellow_Block"
    },
    {
      "x": -4,
      "y": 21,
      "z": -11,
      "name": "Rock_Sandstone_White"
    },
    {
      "x": -4,
      "y": 22,
      "z": -11,
      "name": "Rock_Sandstone_White"
    },
    {
      "x": -4,
      "y": 23,
      "z": -11,
      "name": "Rock_Sandstone_White"
    },
    {
      "x": -4,
      "y": 24,
      "z": -11,
      "name": "Rock_Sandstone_White_Cobble"
    },
    {
      "x": -4,
      "y": 25,
      "z": -11,
      "name": "Rock_Sandstone_White"
    },
    {
      "x": -4,
      "y": 26,
      "z": -11,
      "name": "Rock_Sandstone_White"
    },
    {
      "x": -4,
      "y": 27,
      "z": -11,
      "name": "Rock_Sandstone_White"
    },
    {
      "x": -4,
      "y": 28,
      "z": -11,
      "name": "Rock_Sandstone_White"
    },
    {
      "x": -4,
      "y": 29,
      "z": -11,
      "name": "Rock_Sandstone_White"
    },
    {
      "x": -4,
      "y": 30,
      "z": -11,
      "name": "Rock_Sandstone_White"
    },
    {
      "x": -4,
      "y": 31,
      "z": -11,
      "name": "Soil_Sand_White"
    },
    {
      "x": -4,
      "y": 32,
      "z": -11,
      "name": "Soil_Sand_White"
    },
    {
      "x": -4,
      "y": 33,
      "z": -11,
      "name": "Soil_Sand_White"
    },
    {
      "x": -4,
      "y": 15,
      "z": -10,
      "name": "Rock_Crystal_Yellow_Medium",
      "rotation": 7
    },
    {
      "x": -4,
      "y": 16,
      "z": -10,
      "name": "Rock_Crystal_Yellow_Medium",
      "rotation": 7
    },
    {
      "x": -4,
      "y": 17,
      "z": -10,
      "name": "Rock_Crystal_Yellow_Medium",
      "rotation": 7
    },
    {
      "x": -4,
      "y": 18,
      "z": -10,
      "name": "Rock_Sandstone_White"
    },
    {
      "x": -4,
      "y": 19,
      "z": -10,
      "name": "Rock_Sandstone_White"
    },
    {
      "x": -4,
      "y": 20,
      "z": -10,
      "name": "Rock_Sandstone_White"
    },
    {
      "x": -4,
      "y": 21,
      "z": -10,
      "name": "Rock_Sandstone_White"
    },
    {
      "x": -4,
      "y": 22,
      "z": -10,
      "name": "Rock_Sandstone_White"
    },
    {
      "x": -4,
      "y": 23,
      "z": -10,
      "name": "Rock_Sandstone_White"
    },
    {
      "x": -4,
      "y": 24,
      "z": -10,
      "name": "Rock_Sandstone_White"
    },
    {
      "x": -4,
      "y": 25,
      "z": -10,
      "name": "Rock_Sandstone_White"
    },
    {
      "x": -4,
      "y": 26,
      "z": -10,
      "name": "Rock_Sandstone_White"
    },
    {
      "x": -4,
      "y": 27,
      "z": -10,
      "name": "Rock_Sandstone_White"
    },
    {
      "x": -4,
      "y": 28,
      "z": -10,
      "name": "Rock_Sandstone_White"
    },
    {
      "x": -4,
      "y": 16,
      "z": -9,
      "name": "Rock_Sandstone_White"
    },
    {
      "x": -4,
      "y": 17,
      "z": -9,
      "name": "Rock_Sandstone_White"
    },
    {
      "x": -4,
      "y": 18,
      "z": -9,
      "name": "Rock_Sandstone_White_Cobble"
    },
    {
      "x": -4,
      "y": 19,
      "z": -9,
      "name": "Rock_Sandstone_White"
    },
    {
      "x": -4,
      "y": 20,
      "z": -9,
      "name": "Rock_Sandstone_White"
    },
    {
      "x": -4,
      "y": 21,
      "z": -9,
      "name": "Rock_Sandstone_White"
    },
    {
      "x": -4,
      "y": 22,
      "z": -9,
      "name": "Rock_Sandstone_White"
    },
    {
      "x": -4,
      "y": 23,
      "z": -9,
      "name": "Rock_Sandstone_White"
    },
    {
      "x": -4,
      "y": 24,
      "z": -9,
      "name": "Rock_Sandstone_White"
    },
    {
      "x": -4,
      "y": 25,
      "z": -9,
      "name": "Rock_Sandstone_White"
    },
    {
      "x": -4,
      "y": 26,
      "z": -9,
      "name": "Rock_Sandstone_White"
    },
    {
      "x": -4,
      "y": 27,
      "z": -9,
      "name": "Soil_Sand_White"
    },
    {
      "x": -4,
      "y": 28,
      "z": -9,
      "name": "Soil_Sand_White"
    },
    {
      "x": -4,
      "y": 15,
      "z": -8,
      "name": "Rock_Sandstone_White"
    },
    {
      "x": -4,
      "y": 16,
      "z": -8,
      "name": "Rock_Sandstone_White"
    },
    {
      "x": -4,
      "y": 17,
      "z": -8,
      "name": "Rock_Sandstone_White"
    },
    {
      "x": -4,
      "y": 18,
      "z": -8,
      "name": "Rock_Sandstone_White"
    },
    {
      "x": -4,
      "y": 19,
      "z": -8,
      "name": "Rock_Sandstone_White"
    },
    {
      "x": -4,
      "y": 20,
      "z": -8,
      "name": "Rock_Sandstone_White"
    },
    {
      "x": -4,
      "y": 21,
      "z": -8,
      "name": "Rock_Sandstone_White"
    },
    {
      "x": -4,
      "y": 22,
      "z": -8,
      "name": "Ore_Thorium_Sandstone"
    },
    {
      "x": -4,
      "y": 23,
      "z": -8,
      "name": "Rock_Sandstone_White"
    },
    {
      "x": -4,
      "y": 24,
      "z": -8,
      "name": "Rock_Sandstone_White"
    },
    {
      "x": -4,
      "y": 25,
      "z": -8,
      "name": "Soil_Sand_White"
    },
    {
      "x": -4,
      "y": 26,
      "z": -8,
      "name": "Soil_Sand_White"
    },
    {
      "x": -4,
      "y": 27,
      "z": -8,
      "name": "Soil_Sand_White"
    },
    {
      "x": -4,
      "y": 14,
      "z": -7,
      "name": "Rock_Sandstone_White"
    },
    {
      "x": -4,
      "y": 15,
      "z": -7,
      "name": "Rock_Sandstone_White"
    },
    {
      "x": -4,
      "y": 16,
      "z": -7,
      "name": "Rock_Sandstone_White"
    },
    {
      "x": -4,
      "y": 17,
      "z": -7,
      "name": "Rock_Sandstone_White"
    },
    {
      "x": -4,
      "y": 18,
      "z": -7,
      "name": "Rock_Sandstone_White"
    },
    {
      "x": -4,
      "y": 19,
      "z": -7,
      "name": "Rock_Sandstone_White"
    },
    {
      "x": -4,
      "y": 20,
      "z": -7,
      "name": "Rock_Sandstone_White"
    },
    {
      "x": -4,
      "y": 21,
      "z": -7,
      "name": "Rock_Sandstone_White"
    },
    {
      "x": -4,
      "y": 22,
      "z": -7,
      "name": "Rock_Sandstone_White"
    },
    {
      "x": -4,
      "y": 23,
      "z": -7,
      "name": "Rock_Sandstone_White"
    },
    {
      "x": -4,
      "y": 24,
      "z": -7,
      "name": "Rock_Sandstone_White"
    },
    {
      "x": -4,
      "y": 25,
      "z": -7,
      "name": "Soil_Sand_White"
    },
    {
      "x": -4,
      "y": 26,
      "z": -7,
      "name": "Soil_Sand_White"
    },
    {
      "x": -4,
      "y": 27,
      "z": -7,
      "name": "Soil_Gravel_Sand_White"
    },
    {
      "x": -4,
      "y": 15,
      "z": -6,
      "name": "Rock_Sandstone_White_Cobble"
    },
    {
      "x": -4,
      "y": 16,
      "z": -6,
      "name": "Rock_Sandstone_White"
    },
    {
      "x": -4,
      "y": 17,
      "z": -6,
      "name": "Rock_Sandstone_White"
    },
    {
      "x": -4,
      "y": 18,
      "z": -6,
      "name": "Rock_Sandstone_White"
    },
    {
      "x": -4,
      "y": 19,
      "z": -6,
      "name": "Rock_Sandstone_White_Cobble"
    },
    {
      "x": -4,
      "y": 20,
      "z": -6,
      "name": "Rock_Sandstone_White"
    },
    {
      "x": -4,
      "y": 21,
      "z": -6,
      "name": "Rock_Sandstone_White"
    },
    {
      "x": -4,
      "y": 22,
      "z": -6,
      "name": "Rock_Sandstone_White"
    },
    {
      "x": -4,
      "y": 23,
      "z": -6,
      "name": "Rock_Sandstone_White"
    },
    {
      "x": -4,
      "y": 24,
      "z": -6,
      "name": "Soil_Sand_White"
    },
    {
      "x": -4,
      "y": 25,
      "z": -6,
      "name": "Soil_Sand_White"
    },
    {
      "x": -4,
      "y": 26,
      "z": -6,
      "name": "Soil_Sand_White"
    },
    {
      "x": -4,
      "y": 27,
      "z": -6,
      "name": "Soil_Sand_White"
    },
    {
      "x": -4,
      "y": 15,
      "z": -5,
      "name": "Rock_Sandstone_White"
    },
    {
      "x": -4,
      "y": 16,
      "z": -5,
      "name": "Rock_Sandstone_White"
    },
    {
      "x": -4,
      "y": 17,
      "z": -5,
      "name": "Rock_Sandstone_White"
    },
    {
      "x": -4,
      "y": 18,
      "z": -5,
      "name": "Rock_Sandstone_White"
    },
    {
      "x": -4,
      "y": 19,
      "z": -5,
      "name": "Rock_Sandstone_White_Cobble"
    },
    {
      "x": -4,
      "y": 20,
      "z": -5,
      "name": "Rock_Sandstone_White"
    },
    {
      "x": -4,
      "y": 21,
      "z": -5,
      "name": "Rock_Sandstone_White"
    },
    {
      "x": -4,
      "y": 22,
      "z": -5,
      "name": "Rock_Sandstone_White"
    },
    {
      "x": -4,
      "y": 23,
      "z": -5,
      "name": "Rock_Sandstone_White"
    },
    {
      "x": -4,
      "y": 24,
      "z": -5,
      "name": "Soil_Sand_White"
    },
    {
      "x": -4,
      "y": 25,
      "z": -5,
      "name": "Soil_Sand_White"
    },
    {
      "x": -4,
      "y": 26,
      "z": -5,
      "name": "Soil_Gravel_Sand_White"
    },
    {
      "x": -4,
      "y": 27,
      "z": -5,
      "name": "Soil_Sand_White"
    },
    {
      "x": -4,
      "y": 28,
      "z": -5,
      "name": "Plant_Cactus_Flat_3"
    },
    {
      "x": -4,
      "y": 16,
      "z": -4,
      "name": "Rock_Sandstone_White_Cobble"
    },
    {
      "x": -4,
      "y": 17,
      "z": -4,
      "name": "Rock_Sandstone_White"
    },
    {
      "x": -4,
      "y": 18,
      "z": -4,
      "name": "Rock_Sandstone_White"
    },
    {
      "x": -4,
      "y": 19,
      "z": -4,
      "name": "Rock_Sandstone_White"
    },
    {
      "x": -4,
      "y": 20,
      "z": -4,
      "name": "Rock_Sandstone_White"
    },
    {
      "x": -4,
      "y": 21,
      "z": -4,
      "name": "Rock_Sandstone_White"
    },
    {
      "x": -4,
      "y": 22,
      "z": -4,
      "name": "Rock_Sandstone_White"
    },
    {
      "x": -4,
      "y": 23,
      "z": -4,
      "name": "Rock_Sandstone_White"
    },
    {
      "x": -4,
      "y": 24,
      "z": -4,
      "name": "Rock_Sandstone_White"
    },
    {
      "x": -4,
      "y": 25,
      "z": -4,
      "name": "Soil_Sand_White"
    },
    {
      "x": -4,
      "y": 26,
      "z": -4,
      "name": "Soil_Sand_White"
    },
    {
      "x": -4,
      "y": 27,
      "z": -4,
      "name": "Soil_Sand_White"
    },
    {
      "x": -4,
      "y": 17,
      "z": -3,
      "name": "Rock_Sandstone_White_Cobble"
    },
    {
      "x": -4,
      "y": 18,
      "z": -3,
      "name": "Rock_Sandstone_White"
    },
    {
      "x": -4,
      "y": 19,
      "z": -3,
      "name": "Rock_Sandstone_White"
    },
    {
      "x": -4,
      "y": 20,
      "z": -3,
      "name": "Rock_Sandstone_White"
    },
    {
      "x": -4,
      "y": 21,
      "z": -3,
      "name": "Rock_Sandstone_White"
    },
    {
      "x": -4,
      "y": 22,
      "z": -3,
      "name": "Rock_Sandstone_White"
    },
    {
      "x": -4,
      "y": 23,
      "z": -3,
      "name": "Rock_Sandstone_White"
    },
    {
      "x": -4,
      "y": 24,
      "z": -3,
      "name": "Rock_Sandstone_White"
    },
    {
      "x": -4,
      "y": 25,
      "z": -3,
      "name": "Rock_Sandstone_White"
    },
    {
      "x": -4,
      "y": 26,
      "z": -3,
      "name": "Soil_Sand_White"
    },
    {
      "x": -4,
      "y": 27,
      "z": -3,
      "name": "Soil_Sand_White"
    },
    {
      "x": -4,
      "y": 19,
      "z": -2,
      "name": "Rock_Sandstone_White"
    },
    {
      "x": -4,
      "y": 20,
      "z": -2,
      "name": "Rock_Sandstone_White"
    },
    {
      "x": -4,
      "y": 21,
      "z": -2,
      "name": "Rock_Sandstone_White"
    },
    {
      "x": -4,
      "y": 22,
      "z": -2,
      "name": "Rock_Sandstone_White"
    },
    {
      "x": -4,
      "y": 23,
      "z": -2,
      "name": "Rock_Sandstone_White"
    },
    {
      "x": -4,
      "y": 24,
      "z": -2,
      "name": "Rock_Sandstone_White"
    },
    {
      "x": -4,
      "y": 25,
      "z": -2,
      "name": "Rock_Sandstone_White"
    },
    {
      "x": -4,
      "y": 26,
      "z": -2,
      "name": "Soil_Sand_White"
    },
    {
      "x": -4,
      "y": 27,
      "z": -2,
      "name": "Soil_Sand_White"
    },
    {
      "x": -4,
      "y": 12,
      "z": 4,
      "name": "Rock_Sandstone_White_Stalactite_Small",
      "rotation": 8
    },
    {
      "x": -4,
      "y": 13,
      "z": 4,
      "name": "Rock_Sandstone_White"
    },
    {
      "x": -4,
      "y": 14,
      "z": 4,
      "name": "Rock_Sandstone_White"
    },
    {
      "x": -4,
      "y": 15,
      "z": 4,
      "name": "Soil_Sand_White"
    },
    {
      "x": -4,
      "y": 16,
      "z": 4,
      "name": "Soil_Gravel_Sand_White"
    },
    {
      "x": -4,
      "y": 17,
      "z": 4,
      "name": "Soil_Sand_White"
    },
    {
      "x": -4,
      "y": 9,
      "z": 5,
      "name": "Rock_Sandstone_White"
    },
    {
      "x": -4,
      "y": 10,
      "z": 5,
      "name": "Rock_Sandstone_White_Cobble"
    },
    {
      "x": -4,
      "y": 11,
      "z": 5,
      "name": "Rock_Sandstone_White_Cobble"
    },
    {
      "x": -4,
      "y": 12,
      "z": 5,
      "name": "Rock_Sandstone_White"
    },
    {
      "x": -4,
      "y": 13,
      "z": 5,
      "name": "Rock_Sandstone_White"
    },
    {
      "x": -4,
      "y": 14,
      "z": 5,
      "name": "Soil_Gravel_Sand_White"
    },
    {
      "x": -4,
      "y": 15,
      "z": 5,
      "name": "Soil_Sand_White"
    },
    {
      "x": -4,
      "y": 16,
      "z": 5,
      "name": "Soil_Sand_White"
    },
    {
      "x": -4,
      "y": 17,
      "z": 5,
      "name": "Soil_Sand_White"
    },
    {
      "x": -4,
      "y": 3,
      "z": 6,
      "name": "Rock_Crystal_Yellow_Medium",
      "rotation": 6
    },
    {
      "x": -4,
      "y": 5,
      "z": 6,
      "name": "Rock_Crystal_Yellow_Medium",
      "rotation": 6
    },
    {
      "x": -4,
      "y": 6,
      "z": 6,
      "name": "Rock_Crystal_Yellow_Medium",
      "rotation": 6
    },
    {
      "x": -4,
      "y": 7,
      "z": 6,
      "name": "Rock_Sandstone_White"
    },
    {
      "x": -4,
      "y": 8,
      "z": 6,
      "name": "Rock_Sandstone_White"
    },
    {
      "x": -4,
      "y": 9,
      "z": 6,
      "name": "Rock_Sandstone_White"
    },
    {
      "x": -4,
      "y": 10,
      "z": 6,
      "name": "Rock_Sandstone_White"
    },
    {
      "x": -4,
      "y": 11,
      "z": 6,
      "name": "Rock_Sandstone_White"
    },
    {
      "x": -4,
      "y": 12,
      "z": 6,
      "name": "Rock_Sandstone_White_Cobble"
    },
    {
      "x": -4,
      "y": 13,
      "z": 6,
      "name": "Rock_Sandstone_White"
    },
    {
      "x": -4,
      "y": 14,
      "z": 6,
      "name": "Rock_Sandstone_White"
    },
    {
      "x": -4,
      "y": 15,
      "z": 6,
      "name": "Rock_Sandstone_White"
    },
    {
      "x": -4,
      "y": 16,
      "z": 6,
      "name": "Rock_Sandstone_White"
    },
    {
      "x": -4,
      "y": 17,
      "z": 6,
      "name": "Rock_Sandstone_White_Brick"
    },
    {
      "x": -4,
      "y": 18,
      "z": 6,
      "name": "Rock_Sandstone_White_Brick_Pillar_Middle",
      "rotation": 7
    },
    {
      "x": -4,
      "y": 2,
      "z": 7,
      "name": "Rock_Crystal_Yellow_Medium",
      "rotation": 6
    },
    {
      "x": -4,
      "y": 3,
      "z": 7,
      "name": "Rock_Crystal_Yellow_Block"
    },
    {
      "x": -4,
      "y": 4,
      "z": 7,
      "name": "Rock_Crystal_Yellow_Block"
    },
    {
      "x": -4,
      "y": 5,
      "z": 7,
      "name": "Rock_Crystal_Yellow_Block"
    },
    {
      "x": -4,
      "y": 6,
      "z": 7,
      "name": "Rock_Crystal_Yellow_Block"
    },
    {
      "x": -4,
      "y": 7,
      "z": 7,
      "name": "Rock_Crystal_Yellow_Block"
    },
    {
      "x": -4,
      "y": 8,
      "z": 7,
