{
  "version": 8,
  "blockIdVersion": 11,
  "anchorX": 0,
  "anchorY": 0,
  "anchorZ": 0,
  "blocks": [
    {
      "x": -22,
      "y": 21,
      "z": -17,
      "name": "Rock_Sandstone"
    },
    {
      "x": -22,
      "y": 22,
      "z": -17,
      "name": "Rock_Sandstone"
    },
    {
      "x": -22,
      "y": 23,
      "z": -17,
      "name": "Soil_Sand"
    },
    {
      "x": -22,
      "y": 21,
      "z": -16,
      "name": "Rock_Sandstone"
    },
    {
      "x": -22,
      "y": 22,
      "z": -16,
      "name": "Rock_Sandstone"
    },
    {
      "x": -22,
      "y": 23,
      "z": -16,
      "name": "Rock_Sandstone"
    },
    {
      "x": -22,
      "y": 21,
      "z": -15,
      "name": "Rock_Sandstone"
    },
    {
      "x": -22,
      "y": 22,
      "z": -15,
      "name": "Rock_Sandstone"
    },
    {
      "x": -22,
      "y": 23,
      "z": -15,
      "name": "Rock_Sandstone"
    },
    {
      "x": -22,
      "y": 24,
      "z": -15,
      "name": "Soil_Sand"
    },
    {
      "x": -22,
      "y": 24,
      "z": -14,
      "name": "Soil_Sand"
    },
    {
      "x": -21,
      "y": 21,
      "z": -19,
      "name": "Rock_Sandstone"
    },
    {
      "x": -21,
      "y": 22,
      "z": -19,
      "name": "Soil_Sand"
    },
    {
      "x": -21,
      "y": 23,
      "z": -19,
      "name": "Soil_Sand"
    },
    {
      "x": -21,
      "y": 19,
      "z": -18,
      "name": "Rock_Sandstone"
    },
    {
      "x": -21,
      "y": 20,
      "z": -18,
      "name": "Rock_Sandstone"
    },
    {
      "x": -21,
      "y": 21,
      "z": -18,
      "name": "Rock_Sandstone"
    },
    {
      "x": -21,
      "y": 22,
      "z": -18,
      "name": "Soil_Sand"
    },
    {
      "x": -21,
      "y": 23,
      "z": -18,
      "name": "Soil_Sand"
    },
    {
      "x": -21,
      "y": 24,
      "z": -18,
      "name": "Soil_Sand"
    },
    {
      "x": -21,
      "y": 18,
      "z": -17,
      "name": "Rock_Sandstone"
    },
    {
      "x": -21,
      "y": 19,
      "z": -17,
      "name": "Rock_Sandstone"
    },
    {
      "x": -21,
      "y": 20,
      "z": -17,
      "name": "Rock_Sandstone"
    },
    {
      "x": -21,
      "y": 21,
      "z": -17,
      "name": "Rock_Sandstone"
    },
    {
      "x": -21,
      "y": 22,
      "z": -17,
      "name": "Rock_Sandstone"
    },
    {
      "x": -21,
      "y": 23,
      "z": -17,
      "name": "Rock_Sandstone"
    },
    {
      "x": -21,
      "y": 24,
      "z": -17,
      "name": "Soil_Sand"
    },
    {
      "x": -21,
      "y": 17,
      "z": -16,
      "name": "Rock_Sandstone"
    },
    {
      "x": -21,
      "y": 18,
      "z": -16,
      "name": "Rock_Sandstone"
    },
    {
      "x": -21,
      "y": 19,
      "z": -16,
      "name": "Rock_Sandstone"
    },
    {
      "x": -21,
      "y": 20,
      "z": -16,
      "name": "Rock_Sandstone"
    },
    {
      "x": -21,
      "y": 21,
      "z": -16,
      "name": "Rock_Sandstone"
    },
    {
      "x": -21,
      "y": 22,
      "z": -16,
      "name": "Rock_Sandstone"
    },
    {
      "x": -21,
      "y": 23,
      "z": -16,
      "name": "Soil_Gravel_Sand"
    },
    {
      "x": -21,
      "y": 24,
      "z": -16,
      "name": "Soil_Sand"
    },
    {
      "x": -21,
      "y": 18,
      "z": -15,
      "name": "Rock_Sandstone"
    },
    {
      "x": -21,
      "y": 19,
      "z": -15,
      "name": "Rock_Sandstone"
    },
    {
      "x": -21,
      "y": 20,
      "z": -15,
      "name": "Rock_Sandstone"
    },
    {
      "x": -21,
      "y": 21,
      "z": -15,
      "name": "Rock_Sandstone"
    },
    {
      "x": -21,
      "y": 22,
      "z": -15,
      "name": "Rock_Sandstone"
    },
    {
      "x": -21,
      "y": 23,
      "z": -15,
      "name": "Rock_Sandstone"
    },
    {
      "x": -21,
      "y": 24,
      "z": -15,
      "name": "Soil_Sand"
    },
    {
      "x": -21,
      "y": 19,
      "z": -14,
      "name": "Rock_Sandstone"
    },
    {
      "x": -21,
      "y": 20,
      "z": -14,
      "name": "Rock_Sandstone"
    },
    {
      "x": -21,
      "y": 21,
      "z": -14,
      "name": "Rock_Sandstone"
    },
    {
      "x": -21,
      "y": 22,
      "z": -14,
      "name": "Rock_Sandstone"
    },
    {
      "x": -21,
      "y": 23,
      "z": -14,
      "name": "Soil_Sand"
    },
    {
      "x": -21,
      "y": 24,
      "z": -14,
      "name": "Soil_Sand"
    },
    {
      "x": -21,
      "y": 21,
      "z": -13,
      "name": "Rock_Sandstone"
    },
    {
      "x": -21,
      "y": 22,
      "z": -13,
      "name": "Rock_Sandstone"
    },
    {
      "x": -21,
      "y": 23,
      "z": -13,
      "name": "Rock_Sandstone"
    },
    {
      "x": -21,
      "y": 24,
      "z": -13,
      "name": "Rock_Sandstone"
    },
    {
      "x": -20,
      "y": 20,
      "z": -20,
      "name": "Soil_Gravel_Sand"
    },
    {
      "x": -20,
      "y": 21,
      "z": -20,
      "name": "Soil_Gravel_Sand"
    },
    {
      "x": -20,
      "y": 18,
      "z": -19,
      "name": "Rock_Sandstone"
    },
    {
      "x": -20,
      "y": 19,
      "z": -19,
      "name": "Rock_Sandstone"
    },
    {
      "x": -20,
      "y": 20,
      "z": -19,
      "name": "Rock_Sandstone"
    },
    {
      "x": -20,
      "y": 21,
      "z": -19,
      "name": "Rock_Sandstone"
    },
    {
      "x": -20,
      "y": 22,
      "z": -19,
      "name": "Soil_Gravel_Sand"
    },
    {
      "x": -20,
      "y": 23,
      "z": -19,
      "name": "Soil_Sand"
    },
    {
      "x": -20,
      "y": 17,
      "z": -18,
      "name": "Rock_Sandstone"
    },
    {
      "x": -20,
      "y": 18,
      "z": -18,
      "name": "Rock_Sandstone"
    },
    {
      "x": -20,
      "y": 19,
      "z": -18,
      "name": "Rock_Sandstone"
    },
    {
      "x": -20,
      "y": 20,
      "z": -18,
      "name": "Rock_Sandstone"
    },
    {
      "x": -20,
      "y": 21,
      "z": -18,
      "name": "Rock_Sandstone"
    },
    {
      "x": -20,
      "y": 22,
      "z": -18,
      "name": "Soil_Sand"
    },
    {
      "x": -20,
      "y": 23,
      "z": -18,
      "name": "Soil_Sand"
    },
    {
      "x": -20,
      "y": 16,
      "z": -17,
      "name": "Rock_Sandstone"
    },
    {
      "x": -20,
      "y": 17,
      "z": -17,
      "name": "Rock_Sandstone"
    },
    {
      "x": -20,
      "y": 18,
      "z": -17,
      "name": "Rock_Sandstone"
    },
    {
      "x": -20,
      "y": 19,
      "z": -17,
      "name": "Rock_Sandstone"
    },
    {
      "x": -20,
      "y": 20,
      "z": -17,
      "name": "Rock_Sandstone"
    },
    {
      "x": -20,
      "y": 21,
      "z": -17,
      "name": "Rock_Sandstone"
    },
    {
      "x": -20,
      "y": 22,
      "z": -17,
      "name": "Rock_Sandstone"
    },
    {
      "x": -20,
      "y": 23,
      "z": -17,
      "name": "Soil_Sand"
    },
    {
      "x": -20,
      "y": 24,
      "z": -17,
      "name": "Soil_Sand"
    },
    {
      "x": -20,
      "y": 16,
      "z": -16,
      "name": "Rock_Sandstone"
    },
    {
      "x": -20,
      "y": 17,
      "z": -16,
      "name": "Rock_Sandstone"
    },
    {
      "x": -20,
      "y": 18,
      "z": -16,
      "name": "Rock_Sandstone"
    },
    {
      "x": -20,
      "y": 19,
      "z": -16,
      "name": "Rock_Sandstone"
    },
    {
      "x": -20,
      "y": 20,
      "z": -16,
      "name": "Rock_Sandstone"
    },
    {
      "x": -20,
      "y": 21,
      "z": -16,
      "name": "Rock_Sandstone"
    },
    {
      "x": -20,
      "y": 22,
      "z": -16,
      "name": "Rock_Sandstone"
    },
    {
      "x": -20,
      "y": 23,
      "z": -16,
      "name": "Soil_Sand"
    },
    {
      "x": -20,
      "y": 24,
      "z": -16,
      "name": "Soil_Sand"
    },
    {
      "x": -20,
      "y": 16,
      "z": -15,
      "name": "Rock_Sandstone"
    },
    {
      "x": -20,
      "y": 17,
      "z": -15,
      "name": "Rock_Sandstone"
    },
    {
      "x": -20,
      "y": 18,
      "z": -15,
      "name": "Rock_Sandstone"
    },
    {
      "x": -20,
      "y": 19,
      "z": -15,
      "name": "Rock_Sandstone"
    },
    {
      "x": -20,
      "y": 20,
      "z": -15,
      "name": "Rock_Sandstone"
    },
    {
      "x": -20,
      "y": 21,
      "z": -15,
      "name": "Rock_Sandstone"
    },
    {
      "x": -20,
      "y": 22,
      "z": -15,
      "name": "Rock_Sandstone"
    },
    {
      "x": -20,
      "y": 23,
      "z": -15,
      "name": "Rock_Sandstone"
    },
    {
      "x": -20,
      "y": 24,
      "z": -15,
      "name": "Soil_Sand"
    },
    {
      "x": -20,
      "y": 17,
      "z": -14,
      "name": "Rock_Sandstone"
    },
    {
      "x": -20,
      "y": 18,
      "z": -14,
      "name": "Rock_Sandstone"
    },
    {
      "x": -20,
      "y": 19,
      "z": -14,
      "name": "Rock_Sandstone"
    },
    {
      "x": -20,
      "y": 20,
      "z": -14,
      "name": "Rock_Sandstone"
    },
    {
      "x": -20,
      "y": 21,
      "z": -14,
      "name": "Rock_Sandstone"
    },
    {
      "x": -20,
      "y": 22,
      "z": -14,
      "name": "Soil_Sand"
    },
    {
      "x": -20,
      "y": 23,
      "z": -14,
      "name": "Soil_Sand"
    },
    {
      "x": -20,
      "y": 24,
      "z": -14,
      "name": "Soil_Sand"
    },
    {
      "x": -20,
      "y": 17,
      "z": -13,
      "name": "Plant_Crop_Mushroom_Shelve_Yellow"
    },
    {
      "x": -20,
      "y": 18,
      "z": -13,
      "name": "Rock_Sandstone"
    },
    {
      "x": -20,
      "y": 19,
      "z": -13,
      "name": "Rock_Sandstone"
    },
    {
      "x": -20,
      "y": 20,
      "z": -13,
      "name": "Rock_Sandstone"
    },
    {
      "x": -20,
      "y": 21,
      "z": -13,
      "name": "Rock_Sandstone"
    },
    {
      "x": -20,
      "y": 22,
      "z": -13,
      "name": "Rock_Sandstone"
    },
    {
      "x": -20,
      "y": 23,
      "z": -13,
      "name": "Rock_Sandstone"
    },
    {
      "x": -20,
      "y": 24,
      "z": -13,
      "name": "Rock_Sandstone"
    },
    {
      "x": -20,
      "y": 25,
      "z": -13,
      "name": "Rubble_Sandstone"
    },
    {
      "x": -20,
      "y": 21,
      "z": -12,
      "name": "Rock_Sandstone"
    },
    {
      "x": -20,
      "y": 22,
      "z": -12,
      "name": "Rock_Sandstone"
    },
    {
      "x": -20,
      "y": 23,
      "z": -12,
      "name": "Soil_Sand"
    },
    {
      "x": -20,
      "y": 24,
      "z": -12,
      "name": "Soil_Sand"
    },
    {
      "x": -19,
      "y": 19,
      "z": -20,
      "name": "Rock_Sandstone"
    },
    {
      "x": -19,
      "y": 20,
      "z": -20,
      "name": "Rock_Sandstone"
    },
    {
      "x": -19,
      "y": 21,
      "z": -20,
      "name": "Rock_Sandstone"
    },
    {
      "x": -19,
      "y": 22,
      "z": -20,
      "name": "Soil_Gravel_Sand"
    },
    {
      "x": -19,
      "y": 23,
      "z": -20,
      "name": "Plant_Flower_Flax_Orange"
    },
    {
      "x": -19,
      "y": 17,
      "z": -19,
      "name": "Rock_Sandstone"
    },
    {
      "x": -19,
      "y": 18,
      "z": -19,
      "name": "Rock_Sandstone"
    },
    {
      "x": -19,
      "y": 19,
      "z": -19,
      "name": "Rock_Sandstone"
    },
    {
      "x": -19,
      "y": 20,
      "z": -19,
      "name": "Rock_Sandstone"
    },
    {
      "x": -19,
      "y": 21,
      "z": -19,
      "name": "Rock_Sandstone"
    },
    {
      "x": -19,
      "y": 22,
      "z": -19,
      "name": "Soil_Gravel_Sand"
    },
    {
      "x": -19,
      "y": 23,
      "z": -19,
      "name": "Soil_Sand"
    },
    {
      "x": -19,
      "y": 16,
      "z": -18,
      "name": "Rock_Sandstone"
    },
    {
      "x": -19,
      "y": 17,
      "z": -18,
      "name": "Rock_Sandstone"
    },
    {
      "x": -19,
      "y": 18,
      "z": -18,
      "name": "Rock_Sandstone"
    },
    {
      "x": -19,
      "y": 19,
      "z": -18,
      "name": "Rock_Sandstone"
    },
    {
      "x": -19,
      "y": 20,
      "z": -18,
      "name": "Rock_Sandstone"
    },
    {
      "x": -19,
      "y": 21,
      "z": -18,
      "name": "Rock_Sandstone"
    },
    {
      "x": -19,
      "y": 22,
      "z": -18,
      "name": "Rock_Sandstone"
    },
    {
      "x": -19,
      "y": 23,
      "z": -18,
      "name": "Soil_Sand"
    },
    {
      "x": -19,
      "y": 24,
      "z": -18,
      "name": "Soil_Sand"
    },
    {
      "x": -19,
      "y": 15,
      "z": -17,
      "name": "Rock_Sandstone"
    },
    {
      "x": -19,
      "y": 16,
      "z": -17,
      "name": "Rock_Sandstone"
    },
    {
      "x": -19,
      "y": 17,
      "z": -17,
      "name": "Rock_Sandstone"
    },
    {
      "x": -19,
      "y": 18,
      "z": -17,
      "name": "Rock_Sandstone"
    },
    {
      "x": -19,
      "y": 19,
      "z": -17,
      "name": "Rock_Sandstone"
    },
    {
      "x": -19,
      "y": 20,
      "z": -17,
      "name": "Rock_Sandstone"
    },
    {
      "x": -19,
      "y": 21,
      "z": -17,
      "name": "Rock_Sandstone"
    },
    {
      "x": -19,
      "y": 22,
      "z": -17,
      "name": "Rock_Sandstone"
    },
    {
      "x": -19,
      "y": 23,
      "z": -17,
      "name": "Rock_Sandstone"
    },
    {
      "x": -19,
      "y": 24,
      "z": -17,
      "name": "Rock_Sandstone"
    },
    {
      "x": -19,
      "y": 25,
      "z": -17,
      "name": "Rubble_Sandstone_Medium"
    },
    {
      "x": -19,
      "y": 12,
      "z": -16,
      "name": "Rock_Crystal_Yellow_Medium",
      "rotation": 7
    },
    {
      "x": -19,
      "y": 13,
      "z": -16,
      "name": "Rock_Crystal_Yellow_Medium",
      "rotation": 7
    },
    {
      "x": -19,
      "y": 15,
      "z": -16,
      "name": "Rock_Sandstone"
    },
    {
      "x": -19,
      "y": 16,
      "z": -16,
      "name": "Rock_Sandstone"
    },
    {
      "x": -19,
      "y": 17,
      "z": -16,
      "name": "Rock_Sandstone"
    },
    {
      "x": -19,
      "y": 18,
      "z": -16,
      "name": "Rock_Sandstone"
    },
    {
      "x": -19,
      "y": 19,
      "z": -16,
      "name": "Rock_Sandstone"
    },
    {
      "x": -19,
      "y": 20,
      "z": -16,
      "name": "Rock_Sandstone"
    },
    {
      "x": -19,
      "y": 21,
      "z": -16,
      "name": "Rock_Sandstone"
    },
    {
      "x": -19,
      "y": 22,
      "z": -16,
      "name": "Rock_Sandstone"
    },
    {
      "x": -19,
      "y": 23,
      "z": -16,
      "name": "Rock_Sandstone"
    },
    {
      "x": -19,
      "y": 24,
      "z": -16,
      "name": "Soil_Sand"
    },
    {
      "x": -19,
      "y": 15,
      "z": -15,
      "name": "Rock_Sandstone"
    },
    {
      "x": -19,
      "y": 16,
      "z": -15,
      "name": "Rock_Sandstone"
    },
    {
      "x": -19,
      "y": 17,
      "z": -15,
      "name": "Rock_Sandstone"
    },
    {
      "x": -19,
      "y": 18,
      "z": -15,
      "name": "Rock_Sandstone"
    },
    {
      "x": -19,
      "y": 19,
      "z": -15,
      "name": "Rock_Sandstone"
    },
    {
      "x": -19,
      "y": 20,
      "z": -15,
      "name": "Rock_Sandstone"
    },
    {
      "x": -19,
      "y": 21,
      "z": -15,
      "name": "Rock_Sandstone"
    },
    {
      "x": -19,
      "y": 22,
      "z": -15,
      "name": "Rock_Sandstone"
    },
    {
      "x": -19,
      "y": 23,
      "z": -15,
      "name": "Soil_Sand"
    },
    {
      "x": -19,
      "y": 24,
      "z": -15,
      "name": "Soil_Sand"
    },
    {
      "x": -19,
      "y": 16,
      "z": -14,
      "name": "Rock_Sandstone"
    },
    {
      "x": -19,
      "y": 17,
      "z": -14,
      "name": "Rock_Sandstone"
    },
    {
      "x": -19,
      "y": 18,
      "z": -14,
      "name": "Rock_Sandstone"
    },
    {
      "x": -19,
      "y": 19,
      "z": -14,
      "name": "Rock_Sandstone"
    },
    {
      "x": -19,
      "y": 20,
      "z": -14,
      "name": "Rock_Sandstone"
    },
    {
      "x": -19,
      "y": 21,
      "z": -14,
      "name": "Rock_Sandstone"
    },
    {
      "x": -19,
      "y": 22,
      "z": -14,
      "name": "Rock_Sandstone"
    },
    {
      "x": -19,
      "y": 23,
      "z": -14,
      "name": "Soil_Sand"
    },
    {
      "x": -19,
      "y": 24,
      "z": -14,
      "name": "Soil_Sand"
    },
    {
      "x": -19,
      "y": 17,
      "z": -13,
      "name": "Rock_Sandstone"
    },
    {
      "x": -19,
      "y": 18,
      "z": -13,
      "name": "Rock_Sandstone"
    },
    {
      "x": -19,
      "y": 19,
      "z": -13,
      "name": "Rock_Sandstone"
    },
    {
      "x": -19,
      "y": 20,
      "z": -13,
      "name": "Rock_Sandstone"
    },
    {
      "x": -19,
      "y": 21,
      "z": -13,
      "name": "Rock_Sandstone"
    },
    {
      "x": -19,
      "y": 22,
      "z": -13,
      "name": "Rock_Sandstone"
    },
    {
      "x": -19,
      "y": 23,
      "z": -13,
      "name": "Soil_Sand"
    },
    {
      "x": -19,
      "y": 24,
      "z": -13,
      "name": "Soil_Sand"
    },
    {
      "x": -19,
      "y": 17,
      "z": -12,
      "name": "Plant_Crop_Mushroom_Shelve_Yellow"
    },
    {
      "x": -19,
      "y": 19,
      "z": -12,
      "name": "Rock_Sandstone"
    },
    {
      "x": -19,
      "y": 20,
      "z": -12,
      "name": "Rock_Sandstone"
    },
    {
      "x": -19,
      "y": 21,
      "z": -12,
      "name": "Rock_Sandstone"
    },
    {
      "x": -19,
      "y": 22,
      "z": -12,
      "name": "Rock_Sandstone"
    },
    {
      "x": -19,
      "y": 23,
      "z": -12,
      "name": "Soil_Sand"
    },
    {
      "x": -19,
      "y": 24,
      "z": -12,
      "name": "Soil_Gravel_Sand"
    },
    {
      "x": -19,
      "y": 19,
      "z": -11,
      "name": "Plant_Crop_Mushroom_Shelve_Yellow"
    },
    {
      "x": -19,
      "y": 23,
      "z": -11,
      "name": "Rock_Sandstone"
    },
    {
      "x": -19,
      "y": 24,
      "z": -11,
      "name": "Rock_Sandstone"
    },
    {
      "x": -19,
      "y": 25,
      "z": -11,
      "name": "Rock_Sandstone"
    },
    {
      "x": -19,
      "y": 26,
      "z": -11,
      "name": "Rubble_Sandstone"
    },
    {
      "x": -19,
      "y": 21,
      "z": -10,
      "name": "Plant_Crop_Mushroom_Shelve_Yellow"
    },
    {
      "x": -19,
      "y": 26,
      "z": -10,
      "name": "Soil_Sand"
    },
    {
      "x": -19,
      "y": 27,
      "z": -10,
      "name": "Plant_Flower_Bushy_Yellow"
    },
    {
      "x": -18,
      "y": 18,
      "z": -20,
      "name": "Rock_Sandstone"
    },
    {
      "x": -18,
      "y": 19,
      "z": -20,
      "name": "Rock_Sandstone"
    },
    {
      "x": -18,
      "y": 20,
      "z": -20,
      "name": "Soil_Sand"
    },
    {
      "x": -18,
      "y": 21,
      "z": -20,
      "name": "Soil_Sand"
    },
    {
      "x": -18,
      "y": 16,
      "z": -19,
      "name": "Rock_Sandstone"
    },
    {
      "x": -18,
      "y": 17,
      "z": -19,
      "name": "Rock_Sandstone"
    },
    {
      "x": -18,
      "y": 18,
      "z": -19,
      "name": "Rock_Sandstone"
    },
    {
      "x": -18,
      "y": 19,
      "z": -19,
      "name": "Rock_Sandstone"
    },
    {
      "x": -18,
      "y": 20,
      "z": -19,
      "name": "Rock_Sandstone"
    },
    {
      "x": -18,
      "y": 21,
      "z": -19,
      "name": "Rock_Sandstone"
    },
    {
      "x": -18,
      "y": 22,
      "z": -19,
      "name": "Soil_Sand"
    },
    {
      "x": -18,
      "y": 23,
      "z": -19,
      "name": "Soil_Gravel_Sand"
    },
    {
      "x": -18,
      "y": 15,
      "z": -18,
      "name": "Rock_Sandstone"
    },
    {
      "x": -18,
      "y": 16,
      "z": -18,
      "name": "Rock_Sandstone"
    },
    {
      "x": -18,
      "y": 17,
      "z": -18,
      "name": "Rock_Sandstone"
    },
    {
      "x": -18,
      "y": 18,
      "z": -18,
      "name": "Rock_Sandstone"
    },
    {
      "x": -18,
      "y": 19,
      "z": -18,
      "name": "Rock_Sandstone"
    },
    {
      "x": -18,
      "y": 20,
      "z": -18,
      "name": "Rock_Sandstone"
    },
    {
      "x": -18,
      "y": 21,
      "z": -18,
      "name": "Rock_Sandstone"
    },
    {
      "x": -18,
      "y": 22,
      "z": -18,
      "name": "Rock_Sandstone"
    },
    {
      "x": -18,
      "y": 23,
      "z": -18,
      "name": "Rock_Sandstone"
    },
    {
      "x": -18,
      "y": 24,
      "z": -18,
      "name": "Rock_Sandstone"
    },
    {
      "x": -18,
      "y": 25,
      "z": -18,
      "name": "Rubble_Sandstone_Medium"
    },
    {
      "x": -18,
      "y": 11,
      "z": -17,
      "name": "Rock_Crystal_Yellow_Medium",
      "rotation": 7
    },
    {
      "x": -18,
      "y": 12,
      "z": -17,
      "name": "Rock_Crystal_Yellow_Medium",
      "rotation": 7
    },
    {
      "x": -18,
      "y": 14,
      "z": -17,
      "name": "Rock_Sandstone"
    },
    {
      "x": -18,
      "y": 15,
      "z": -17,
      "name": "Rock_Sandstone"
    },
    {
      "x": -18,
      "y": 16,
      "z": -17,
      "name": "Rock_Sandstone"
    },
    {
      "x": -18,
      "y": 17,
      "z": -17,
      "name": "Rock_Sandstone"
    },
    {
      "x": -18,
      "y": 18,
      "z": -17,
      "name": "Rock_Sandstone"
    },
    {
      "x": -18,
      "y": 19,
      "z": -17,
      "name": "Rock_Sandstone"
    },
    {
      "x": -18,
      "y": 20,
      "z": -17,
      "name": "Rock_Sandstone"
    },
    {
      "x": -18,
      "y": 21,
      "z": -17,
      "name": "Rock_Sandstone"
    },
    {
      "x": -18,
      "y": 22,
      "z": -17,
      "name": "Rock_Sandstone"
    },
    {
      "x": -18,
      "y": 23,
      "z": -17,
      "name": "Rock_Sandstone"
    },
    {
      "x": -18,
      "y": 24,
      "z": -17,
      "name": "Rock_Sandstone"
    },
    {
      "x": -18,
      "y": 25,
      "z": -17,
      "name": "Rubble_Sandstone"
    },
    {
      "x": -18,
      "y": 11,
      "z": -16,
      "name": "Rock_Crystal_Yellow_Medium",
      "rotation": 7
    },
    {
      "x": -18,
      "y": 12,
      "z": -16,
      "name": "Rock_Crystal_Yellow_Block"
    },
    {
      "x": -18,
      "y": 13,
      "z": -16,
      "name": "Rock_Crystal_Yellow_Block"
    },
    {
      "x": -18,
      "y": 14,
      "z": -16,
      "name": "Rock_Crystal_Yellow_Block"
    },
    {
      "x": -18,
      "y": 15,
      "z": -16,
      "name": "Rock_Crystal_Yellow_Block"
    },
    {
      "x": -18,
      "y": 16,
      "z": -16,
      "name": "Rock_Crystal_Yellow_Block"
    },
    {
      "x": -18,
      "y": 17,
      "z": -16,
      "name": "Rock_Crystal_Yellow_Block"
    },
    {
      "x": -18,
      "y": 18,
      "z": -16,
      "name": "Rock_Sandstone"
    },
    {
      "x": -18,
      "y": 19,
      "z": -16,
      "name": "Rock_Sandstone"
    },
    {
      "x": -18,
      "y": 20,
      "z": -16,
      "name": "Rock_Sandstone"
    },
    {
      "x": -18,
      "y": 21,
      "z": -16,
      "name": "Rock_Sandstone"
    },
    {
      "x": -18,
      "y": 22,
      "z": -16,
      "name": "Rock_Sandstone"
    },
    {
      "x": -18,
      "y": 23,
      "z": -16,
      "name": "Rock_Sandstone"
    },
    {
      "x": -18,
      "y": 24,
      "z": -16,
      "name": "Rock_Sandstone"
    },
    {
      "x": -18,
      "y": 25,
      "z": -16,
      "name": "Rubble_Sandstone"
    },
    {
      "x": -18,
      "y": 12,
      "z": -15,
      "name": "Rock_Crystal_Yellow_Medium",
      "rotation": 7
    },
    {
      "x": -18,
      "y": 13,
      "z": -15,
      "name": "Rock_Crystal_Yellow_Medium",
      "rotation": 4
    },
    {
      "x": -18,
      "y": 14,
      "z": -15,
      "name": "Rock_Sandstone"
    },
    {
      "x": -18,
      "y": 15,
      "z": -15,
      "name": "Rock_Sandstone"
    },
    {
      "x": -18,
      "y": 16,
      "z": -15,
      "name": "Rock_Sandstone"
    },
    {
      "x": -18,
      "y": 17,
      "z": -15,
      "name": "Rock_Sandstone"
    },
    {
      "x": -18,
      "y": 18,
      "z": -15,
      "name": "Rock_Sandstone"
    },
    {
      "x": -18,
      "y": 19,
      "z": -15,
      "name": "Rock_Sandstone"
    },
    {
      "x": -18,
      "y": 20,
      "z": -15,
      "name": "Rock_Sandstone"
    },
    {
      "x": -18,
      "y": 21,
      "z": -15,
      "name": "Rock_Sandstone"
    },
    {
      "x": -18,
      "y": 22,
      "z": -15,
      "name": "Rock_Sandstone"
    },
    {
      "x": -18,
      "y": 23,
      "z": -15,
      "name": "Rock_Sandstone"
    },
    {
      "x": -18,
      "y": 24,
      "z": -15,
      "name": "Soil_Sand"
    },
    {
      "x": -18,
      "y": 25,
      "z": -15,
      "name": "Soil_Sand"
    },
    {
      "x": -18,
      "y": 15,
      "z": -14,
      "name": "Rock_Sandstone"
    },
    {
      "x": -18,
      "y": 16,
      "z": -14,
      "name": "Rock_Sandstone"
    },
    {
      "x": -18,
      "y": 17,
      "z": -14,
      "name": "Rock_Sandstone"
    },
    {
      "x": -18,
      "y": 18,
      "z": -14,
      "name": "Rock_Sandstone"
    },
    {
      "x": -18,
      "y": 19,
      "z": -14,
      "name": "Rock_Sandstone"
    },
    {
      "x": -18,
      "y": 20,
      "z": -14,
      "name": "Rock_Sandstone"
    },
    {
      "x": -18,
      "y": 21,
      "z": -14,
      "name": "Rock_Sandstone"
    },
    {
      "x": -18,
      "y": 22,
      "z": -14,
      "name": "Rock_Sandstone"
    },
    {
      "x": -18,
      "y": 23,
      "z": -14,
      "name": "Rock_Sandstone"
    },
    {
      "x": -18,
      "y": 24,
      "z": -14,
      "name": "Rock_Sandstone"
    },
    {
      "x": -18,
      "y": 25,
      "z": -14,
      "name": "Rock_Sandstone"
    },
    {
      "x": -18,
      "y": 14,
      "z": -13,
      "name": "Rock_Sandstone_Stalactite_Large",
      "filler": 31744,
      "rotation": 8
    },
    {
      "x": -18,
      "y": 15,
      "z": -13,
      "name": "Rock_Sandstone_Stalactite_Large",
      "rotation": 8
    },
    {
      "x": -18,
      "y": 16,
      "z": -13,
      "name": "Rock_Sandstone"
    },
    {
      "x": -18,
      "y": 17,
      "z": -13,
      "name": "Rock_Sandstone"
    },
    {
      "x": -18,
      "y": 18,
      "z": -13,
      "name": "Rock_Sandstone"
    },
    {
      "x": -18,
      "y": 19,
      "z": -13,
      "name": "Rock_Sandstone"
    },
    {
      "x": -18,
      "y": 20,
      "z": -13,
      "name": "Rock_Sandstone"
    },
    {
      "x": -18,
      "y": 21,
      "z": -13,
      "name": "Rock_Sandstone"
    },
    {
      "x": -18,
      "y": 22,
      "z": -13,
      "name": "Rock_Sandstone"
    },
    {
      "x": -18,
      "y": 23,
      "z": -13,
      "name": "Rock_Sandstone"
    },
    {
      "x": -18,
      "y": 24,
      "z": -13,
      "name": "Rock_Sandstone"
    },
    {
      "x": -18,
      "y": 25,
      "z": -13,
      "name": "Soil_Sand"
    },
    {
      "x": -18,
      "y": 17,
      "z": -12,
      "name": "Plant_Crop_Mushroom_Shelve_Yellow"
    },
    {
      "x": -18,
      "y": 18,
      "z": -12,
      "name": "Rock_Sandstone"
    },
    {
      "x": -18,
      "y": 19,
      "z": -12,
      "name": "Rock_Sandstone"
    },
    {
      "x": -18,
      "y": 20,
      "z": -12,
      "name": "Rock_Sandstone"
    },
    {
      "x": -18,
      "y": 21,
      "z": -12,
      "name": "Rock_Sandstone"
    },
    {
      "x": -18,
      "y": 22,
      "z": -12,
      "name": "Rock_Sandstone"
    },
    {
      "x": -18,
      "y": 23,
      "z": -12,
      "name": "Rock_Sandstone"
    },
    {
      "x": -18,
      "y": 24,
      "z": -12,
      "name": "Rock_Sandstone"
    },
    {
      "x": -18,
      "y": 25,
      "z": -12,
      "name": "Soil_Sand"
    },
    {
      "x": -18,
      "y": 19,
      "z": -11,
      "name": "Plant_Crop_Mushroom_Shelve_Yellow"
    },
    {
      "x": -18,
      "y": 20,
      "z": -11,
      "name": "Rock_Sandstone"
    },
    {
      "x": -18,
      "y": 21,
      "z": -11,
      "name": "Rock_Sandstone"
    },
    {
      "x": -18,
      "y": 22,
      "z": -11,
      "name": "Rock_Sandstone"
    },
    {
      "x": -18,
      "y": 23,
      "z": -11,
      "name": "Rock_Sandstone"
    },
    {
      "x": -18,
      "y": 24,
      "z": -11,
      "name": "Rock_Sandstone"
    },
    {
      "x": -18,
      "y": 25,
      "z": -11,
      "name": "Soil_Gravel_Sand"
    },
    {
      "x": -18,
      "y": 21,
      "z": -10,
      "name": "Rock_Sandstone"
    },
    {
      "x": -18,
      "y": 22,
      "z": -10,
      "name": "Rock_Sandstone"
    },
    {
      "x": -18,
      "y": 23,
      "z": -10,
      "name": "Rock_Sandstone"
    },
    {
      "x": -18,
      "y": 24,
      "z": -10,
      "name": "Rock_Sandstone"
    },
    {
      "x": -18,
      "y": 25,
      "z": -10,
      "name": "Rock_Sandstone"
    },
    {
      "x": -18,
      "y": 23,
      "z": -9,
      "name": "Rock_Sandstone"
    },
    {
      "x": -18,
      "y": 24,
      "z": -9,
      "name": "Rock_Sandstone"
    },
    {
      "x": -18,
      "y": 25,
      "z": -9,
      "name": "Rock_Sandstone"
    },
    {
      "x": -18,
      "y": 26,
      "z": -9,
      "name": "Soil_Sand"
    },
    {
      "x": -18,
      "y": 28,
      "z": -7,
      "name": "Rock_Sandstone"
    },
    {
      "x": -18,
      "y": 29,
      "z": -7,
      "name": "Rubble_Sandstone"
    },
    {
      "x": -18,
      "y": 28,
      "z": -6,
      "name": "Rock_Sandstone"
    },
    {
      "x": -18,
      "y": 29,
      "z": -6,
      "name": "Rock_Sandstone"
    },
    {
      "x": -18,
      "y": 28,
      "z": -5,
      "name": "Rock_Sandstone"
    },
    {
      "x": -18,
      "y": 27,
      "z": -1,
      "name": "Plant_Crop_Mushroom_Shelve_Yellow"
    },
    {
      "x": -18,
      "y": 31,
      "z": -1,
      "name": "Rock_Sandstone"
    },
    {
      "x": -18,
      "y": 32,
      "z": -1,
      "name": "Rubble_Sandstone_Medium"
    },
    {
      "x": -18,
      "y": 31,
      "z": 0,
      "name": "Rock_Sandstone"
    },
    {
      "x": -17,
      "y": 17,
      "z": -20,
      "name": "Rock_Sandstone"
    },
    {
      "x": -17,
      "y": 18,
      "z": -20,
      "name": "Rock_Sandstone"
    },
    {
      "x": -17,
      "y": 19,
      "z": -20,
      "name": "Rock_Sandstone"
    },
    {
      "x": -17,
      "y": 20,
      "z": -20,
      "name": "Soil_Sand"
    },
    {
      "x": -17,
      "y": 21,
      "z": -20,
      "name": "Soil_Gravel_Sand"
    },
    {
      "x": -17,
      "y": 16,
      "z": -19,
      "name": "Rock_Sandstone"
    },
    {
      "x": -17,
      "y": 17,
      "z": -19,
      "name": "Rock_Sandstone"
    },
    {
      "x": -17,
      "y": 18,
      "z": -19,
      "name": "Rock_Sandstone"
    },
    {
      "x": -17,
      "y": 19,
      "z": -19,
      "name": "Rock_Sandstone"
    },
    {
      "x": -17,
      "y": 20,
      "z": -19,
      "name": "Rock_Sandstone"
    },
    {
      "x": -17,
      "y": 21,
      "z": -19,
      "name": "Rock_Sandstone"
    },
    {
      "x": -17,
      "y": 22,
      "z": -19,
      "name": "Soil_Gravel_Sand"
    },
    {
      "x": -17,
      "y": 23,
      "z": -19,
      "name": "Soil_Sand"
    },
    {
      "x": -17,
      "y": 11,
      "z": -18,
      "name": "Rock_Crystal_Yellow_Medium",
      "rotation": 6
    },
    {
      "x": -17,
      "y": 12,
      "z": -18,
      "name": "Rock_Crystal_Yellow_Medium",
      "rotation": 6
    },
    {
      "x": -17,
      "y": 13,
      "z": -18,
      "name": "Rock_Crystal_Yellow_Medium",
      "rotation": 6
    },
    {
      "x": -17,
      "y": 15,
      "z": -18,
      "name": "Rock_Sandstone"
    },
    {
      "x": -17,
      "y": 16,
      "z": -18,
      "name": "Rock_Sandstone"
    },
    {
      "x": -17,
      "y": 17,
      "z": -18,
      "name": "Rock_Sandstone"
    },
    {
      "x": -17,
      "y": 18,
      "z": -18,
      "name": "Rock_Sandstone"
    },
    {
      "x": -17,
      "y": 19,
      "z": -18,
      "name": "Rock_Sandstone"
    },
    {
      "x": -17,
      "y": 20,
      "z": -18,
      "name": "Rock_Sandstone"
    },
    {
      "x": -17,
      "y": 21,
      "z": -18,
      "name": "Rock_Sandstone"
    },
    {
      "x": -17,
      "y": 22,
      "z": -18,
      "name": "Rock_Sandstone"
    },
    {
      "x": -17,
      "y": 23,
      "z": -18,
      "name": "Rock_Sandstone"
    },
    {
      "x": -17,
      "y": 10,
      "z": -17,
      "name": "Rock_Crystal_Yellow_Large",
      "rotation": 8
    },
    {
      "x": -17,
      "y": 11,
      "z": -17,
      "name": "Rock_Crystal_Yellow_Block"
    },
    {
      "x": -17,
      "y": 12,
      "z": -17,
      "name": "Rock_Crystal_Yellow_Block"
    },
    {
      "x": -17,
      "y": 13,
      "z": -17,
      "name": "Rock_Crystal_Yellow_Block"
    },
    {
      "x": -17,
      "y": 14,
      "z": -17,
      "name": "Rock_Crystal_Yellow_Block"
    },
    {
      "x": -17,
      "y": 15,
      "z": -17,
      "name": "Rock_Crystal_Yellow_Block"
    },
    {
      "x": -17,
      "y": 16,
      "z": -17,
      "name": "Rock_Crystal_Yellow_Block"
    },
    {
      "x": -17,
      "y": 17,
      "z": -17,
      "name": "Rock_Crystal_Yellow_Block"
    },
    {
      "x": -17,
      "y": 18,
      "z": -17,
      "name": "Rock_Sandstone"
    },
    {
      "x": -17,
      "y": 19,
      "z": -17,
      "name": "Rock_Sandstone"
    },
    {
      "x": -17,
      "y": 20,
      "z": -17,
      "name": "Rock_Sandstone"
    },
    {
      "x": -17,
      "y": 21,
      "z": -17,
      "name": "Rock_Sandstone"
    },
    {
      "x": -17,
      "y": 22,
      "z": -17,
      "name": "Rock_Sandstone"
    },
    {
      "x": -17,
      "y": 23,
      "z": -17,
      "name": "Rock_Sandstone"
    },
    {
      "x": -17,
      "y": 24,
      "z": -17,
      "name": "Rock_Sandstone"
    },
    {
      "x": -17,
      "y": 25,
      "z": -17,
      "name": "Rubble_Sandstone"
    },
    {
      "x": -17,
      "y": 9,
      "z": -16,
      "name": "Rock_Crystal_Yellow_Large",
      "rotation": 8
    },
    {
      "x": -17,
      "y": 10,
      "z": -16,
      "name": "Rock_Crystal_Yellow_Block"
    },
    {
      "x": -17,
      "y": 11,
      "z": -16,
      "name": "Rock_Crystal_Yellow_Block"
    },
    {
      "x": -17,
      "y": 12,
      "z": -16,
      "name": "Rock_Crystal_Yellow_Block"
    },
    {
      "x": -17,
      "y": 13,
      "z": -16,
      "name": "Rock_Crystal_Yellow_Block"
    },
    {
      "x": -17,
      "y": 14,
      "z": -16,
      "name": "Rock_Crystal_Yellow_Block"
    },
    {
      "x": -17,
      "y": 15,
      "z": -16,
      "name": "Rock_Crystal_Yellow_Block"
    },
    {
      "x": -17,
      "y": 16,
      "z": -16,
      "name": "Rock_Crystal_Yellow_Block"
    },
    {
      "x": -17,
      "y": 17,
      "z": -16,
      "name": "Rock_Crystal_Yellow_Block"
    },
    {
      "x": -17,
      "y": 18,
      "z": -16,
      "name": "Rock_Sandstone"
    },
    {
      "x": -17,
      "y": 19,
      "z": -16,
      "name": "Rock_Sandstone"
    },
    {
      "x": -17,
      "y": 20,
      "z": -16,
      "name": "Rock_Sandstone"
    },
    {
      "x": -17,
      "y": 21,
      "z": -16,
      "name": "Rock_Sandstone"
    },
    {
      "x": -17,
      "y": 22,
      "z": -16,
      "name": "Rock_Sandstone"
    },
    {
      "x": -17,
      "y": 23,
      "z": -16,
      "name": "Rock_Sandstone"
    },
    {
      "x": -17,
      "y": 24,
      "z": -16,
      "name": "Rock_Sandstone"
    },
    {
      "x": -17,
      "y": 25,
      "z": -16,
      "name": "Rock_Sandstone"
    },
    {
      "x": -17,
      "y": 10,
      "z": -15,
      "name": "Rock_Crystal_Yellow_Medium",
      "rotation": 4
    },
    {
      "x": -17,
      "y": 11,
      "z": -15,
      "name": "Rock_Crystal_Yellow_Medium",
      "rotation": 4
    },
    {
      "x": -17,
      "y": 12,
      "z": -15,
      "name": "Rock_Crystal_Yellow_Block"
    },
    {
      "x": -17,
      "y": 13,
      "z": -15,
      "name": "Rock_Crystal_Yellow_Block"
    },
    {
      "x": -17,
      "y": 14,
      "z": -15,
      "name": "Rock_Crystal_Yellow_Block"
    },
    {
      "x": -17,
      "y": 15,
      "z": -15,
      "name": "Rock_Crystal_Yellow_Block"
    },
    {
      "x": -17,
      "y": 16,
      "z": -15,
      "name": "Rock_Crystal_Yellow_Block"
    },
    {
      "x": -17,
      "y": 17,
      "z": -15,
      "name": "Rock_Crystal_Yellow_Block"
    },
    {
      "x": -17,
      "y": 18,
      "z": -15,
      "name": "Rock_Sandstone"
    },
    {
      "x": -17,
      "y": 19,
      "z": -15,
      "name": "Rock_Sandstone"
    },
    {
      "x": -17,
      "y": 20,
      "z": -15,
      "name": "Rock_Sandstone"
    },
    {
      "x": -17,
      "y": 21,
      "z": -15,
      "name": "Rock_Sandstone"
    },
    {
      "x": -17,
      "y": 22,
      "z": -15,
      "name": "Rock_Sandstone"
    },
    {
      "x": -17,
      "y": 23,
      "z": -15,
      "name": "Rock_Sandstone"
    },
    {
      "x": -17,
      "y": 24,
      "z": -15,
      "name": "Rock_Sandstone"
    },
    {
      "x": -17,
      "y": 25,
      "z": -15,
      "name": "Rock_Sandstone"
    },
    {
      "x": -17,
      "y": 12,
      "z": -14,
      "name": "Rock_Crystal_Yellow_Medium",
      "rotation": 4
    },
    {
      "x": -17,
      "y": 13,
      "z": -14,
      "name": "Rock_Crystal_Yellow_Medium",
      "rotation": 4
    },
    {
      "x": -17,
      "y": 14,
      "z": -14,
      "name": "Rock_Crystal_Yellow_Medium",
      "rotation": 4
    },
    {
      "x": -17,
      "y": 15,
      "z": -14,
      "name": "Rock_Sandstone"
    },
    {
      "x": -17,
      "y": 16,
      "z": -14,
      "name": "Rock_Sandstone"
    },
    {
      "x": -17,
      "y": 17,
      "z": -14,
      "name": "Rock_Sandstone"
    },
    {
      "x": -17,
      "y": 18,
      "z": -14,
      "name": "Rock_Sandstone"
    },
    {
      "x": -17,
      "y": 19,
      "z": -14,
      "name": "Rock_Sandstone"
    },
    {
      "x": -17,
      "y": 20,
      "z": -14,
      "name": "Rock_Sandstone"
    },
    {
      "x": -17,
      "y": 21,
      "z": -14,
      "name": "Rock_Sandstone"
    },
    {
      "x": -17,
      "y": 22,
      "z": -14,
      "name": "Rock_Sandstone"
    },
    {
      "x": -17,
      "y": 23,
      "z": -14,
      "name": "Rock_Sandstone"
    },
    {
      "x": -17,
      "y": 24,
      "z": -14,
      "name": "Rock_Sandstone"
    },
    {
      "x": -17,
      "y": 25,
      "z": -14,
      "name": "Rock_Sandstone"
    },
    {
      "x": -17,
      "y": 14,
      "z": -13,
      "name": "Rock_Sandstone_Stalactite_Large",
      "filler": 31744,
      "rotation": 8
    },
    {
      "x": -17,
      "y": 15,
      "z": -13,
      "name": "Rock_Sandstone_Stalactite_Large",
      "rotation": 8
    },
    {
      "x": -17,
      "y": 16,
      "z": -13,
      "name": "Rock_Sandstone"
    },
    {
      "x": -17,
      "y": 17,
      "z": -13,
      "name": "Rock_Sandstone"
    },
    {
      "x": -17,
      "y": 18,
      "z": -13,
      "name": "Rock_Sandstone"
    },
    {
      "x": -17,
      "y": 19,
      "z": -13,
      "name": "Rock_Sandstone"
    },
    {
      "x": -17,
      "y": 20,
      "z": -13,
      "name": "Rock_Sandstone"
    },
    {
      "x": -17,
      "y": 21,
      "z": -13,
      "name": "Rock_Sandstone"
    },
    {
      "x": -17,
      "y": 22,
      "z": -13,
      "name": "Rock_Sandstone"
    },
    {
      "x": -17,
      "y": 23,
      "z": -13,
      "name": "Rock_Sandstone"
    },
    {
      "x": -17,
      "y": 24,
      "z": -13,
      "name": "Rock_Sandstone"
    },
    {
      "x": -17,
      "y": 25,
      "z": -13,
      "name": "Rock_Sandstone"
    },
    {
      "x": -17,
      "y": 26,
      "z": -13,
      "name": "Rock_Sandstone"
    },
    {
      "x": -17,
      "y": 15,
      "z": -12,
      "name": "Rock_Sandstone_Stalactite_Large",
      "filler": 31744,
      "rotation": 8
    },
    {
      "x": -17,
      "y": 16,
      "z": -12,
      "name": "Rock_Sandstone_Stalactite_Large",
      "rotation": 8
    },
    {
      "x": -17,
      "y": 17,
      "z": -12,
      "name": "Rock_Sandstone"
    },
    {
      "x": -17,
      "y": 18,
      "z": -12,
      "name": "Rock_Sandstone"
    },
    {
      "x": -17,
      "y": 19,
      "z": -12,
      "name": "Rock_Sandstone"
    },
    {
      "x": -17,
      "y": 20,
      "z": -12,
      "name": "Rock_Sandstone"
    },
    {
      "x": -17,
      "y": 21,
      "z": -12,
      "name": "Rock_Sandstone"
    },
    {
      "x": -17,
      "y": 22,
      "z": -12,
      "name": "Rock_Sandstone"
    },
    {
      "x": -17,
      "y": 23,
      "z": -12,
      "name": "Rock_Sandstone"
    },
    {
      "x": -17,
      "y": 24,
      "z": -12,
      "name": "Rock_Sandstone"
    },
    {
      "x": -17,
      "y": 25,
      "z": -12,
      "name": "Rock_Sandstone"
    },
    {
      "x": -17,
      "y": 26,
      "z": -12,
      "name": "Soil_Sand"
    },
    {
      "x": -17,
      "y": 18,
      "z": -11,
      "name": "Rock_Sandstone"
    },
    {
      "x": -17,
      "y": 19,
      "z": -11,
      "name": "Rock_Sandstone"
    },
    {
      "x": -17,
      "y": 20,
      "z": -11,
      "name": "Rock_Sandstone"
    },
    {
      "x": -17,
      "y": 21,
      "z": -11,
      "name": "Rock_Sandstone"
    },
    {
      "x": -17,
      "y": 22,
      "z": -11,
      "name": "Rock_Sandstone"
    },
    {
      "x": -17,
      "y": 23,
      "z": -11,
      "name": "Rock_Sandstone"
    },
    {
      "x": -17,
      "y": 24,
      "z": -11,
      "name": "Rock_Sandstone"
    },
    {
      "x": -17,
      "y": 25,
      "z": -11,
      "name": "Soil_Sand"
    },
    {
      "x": -17,
      "y": 26,
      "z": -11,
      "name": "Soil_Sand"
    },
    {
      "x": -17,
      "y": 19,
      "z": -10,
      "name": "Rock_Sandstone"
    },
    {
      "x": -17,
      "y": 20,
      "z": -10,
      "name": "Rock_Sandstone"
    },
    {
      "x": -17,
      "y": 21,
      "z": -10,
      "name": "Rock_Sandstone"
    },
    {
      "x": -17,
      "y": 22,
      "z": -10,
      "name": "Rock_Sandstone"
    },
    {
      "x": -17,
      "y": 23,
      "z": -10,
      "name": "Rock_Sandstone"
    },
    {
      "x": -17,
      "y": 24,
      "z": -10,
      "name": "Rock_Sandstone"
    },
    {
      "x": -17,
      "y": 25,
      "z": -10,
      "name": "Rock_Sandstone"
    },
    {
      "x": -17,
      "y": 26,
      "z": -10,
      "name": "Rock_Sandstone"
    },
    {
      "x": -17,
      "y": 27,
      "z": -10,
      "name": "Rock_Sandstone"
    },
    {
      "x": -17,
      "y": 20,
      "z": -9,
      "name": "Rock_Sandstone"
    },
    {
      "x": -17,
      "y": 21,
      "z": -9,
      "name": "Rock_Sandstone"
    },
    {
      "x": -17,
      "y": 22,
      "z": -9,
      "name": "Rock_Sandstone"
    },
    {
      "x": -17,
      "y": 23,
      "z": -9,
      "name": "Rock_Sandstone"
    },
    {
      "x": -17,
      "y": 24,
      "z": -9,
      "name": "Rock_Sandstone"
    },
    {
      "x": -17,
      "y": 25,
      "z": -9,
      "name": "Rock_Sandstone"
    },
    {
      "x": -17,
      "y": 26,
      "z": -9,
      "name": "Rock_Sandstone"
    },
    {
      "x": -17,
      "y": 27,
      "z": -9,
      "name": "Rock_Sandstone"
    },
    {
      "x": -17,
      "y": 23,
      "z": -8,
      "name": "Rock_Sandstone"
    },
    {
      "x": -17,
      "y": 24,
      "z": -8,
      "name": "Rock_Sandstone"
    },
    {
      "x": -17,
      "y": 25,
      "z": -8,
      "name": "Rock_Sandstone"
    },
    {
      "x": -17,
      "y": 26,
      "z": -8,
      "name": "Rock_Sandstone"
    },
    {
      "x": -17,
      "y": 27,
      "z": -8,
      "name": "Soil_Gravel_Sand"
    },
    {
      "x": -17,
      "y": 28,
      "z": -8,
      "name": "Soil_Sand"
    },
    {
      "x": -17,
      "y": 25,
      "z": -7,
      "name": "Rock_Sandstone"
    },
    {
      "x": -17,
      "y": 26,
      "z": -7,
      "name": "Rock_Sandstone"
    },
    {
      "x": -17,
      "y": 27,
      "z": -7,
      "name": "Rock_Sandstone"
    },
    {
      "x": -17,
      "y": 28,
      "z": -7,
      "name": "Rock_Sandstone"
    },
    {
      "x": -17,
      "y": 29,
      "z": -7,
      "name": "Rock_Sandstone"
    },
    {
      "x": -17,
      "y": 30,
      "z": -7,
      "name": "Rock_Sandstone"
    },
    {
      "x": -17,
      "y": 31,
      "z": -7,
      "name": "Rubble_Sandstone"
    },
    {
      "x": -17,
      "y": 24,
      "z": -6,
      "name": "Rock_Sandstone"
    },
    {
      "x": -17,
      "y": 25,
      "z": -6,
      "name": "Rock_Sandstone"
    },
    {
      "x": -17,
      "y": 26,
      "z": -6,
      "name": "Rock_Sandstone"
    },
    {
      "x": -17,
      "y": 27,
      "z": -6,
      "name": "Rock_Sandstone"
    },
    {
      "x": -17,
      "y": 28,
      "z": -6,
      "name": "Rock_Sandstone"
    },
    {
      "x": -17,
      "y": 29,
      "z": -6,
      "name": "Rock_Sandstone"
    },
    {
      "x": -17,
      "y": 30,
      "z": -6,
      "name": "Soil_Sand"
    },
    {
      "x": -17,
      "y": 31,
      "z": -6,
      "name": "Soil_Gravel_Sand"
    },
    {
      "x": -17,
      "y": 25,
      "z": -5,
      "name": "Rock_Sandstone"
    },
    {
      "x": -17,
      "y": 26,
      "z": -5,
      "name": "Rock_Sandstone"
    },
    {
      "x": -17,
      "y": 27,
      "z": -5,
      "name": "Rock_Sandstone"
    },
    {
      "x": -17,
      "y": 28,
      "z": -5,
      "name": "Rock_Sandstone"
    },
    {
      "x": -17,
      "y": 29,
      "z": -5,
      "name": "Rock_Sandstone"
    },
    {
      "x": -17,
      "y": 30,
      "z": -5,
      "name": "Soil_Sand"
    },
    {
      "x": -17,
      "y": 31,
      "z": -5,
      "name": "Soil_Sand"
    },
    {
      "x": -17,
      "y": 26,
      "z": -4,
      "name": "Rock_Sandstone"
    },
    {
      "x": -17,
      "y": 27,
      "z": -4,
      "name": "Rock_Sandstone"
    },
    {
      "x": -17,
      "y": 28,
      "z": -4,
      "name": "Rock_Sandstone"
    },
    {
      "x": -17,
      "y": 29,
      "z": -4,
      "name": "Rock_Sandstone"
    },
    {
      "x": -17,
      "y": 30,
      "z": -4,
      "name": "Rock_Sandstone"
    },
    {
      "x": -17,
      "y": 31,
      "z": -4,
      "name": "Soil_Sand"
    },
    {
      "x": -17,
      "y": 28,
      "z": -3,
      "name": "Rock_Sandstone"
    },
    {
      "x": -17,
      "y": 29,
      "z": -3,
      "name": "Rock_Sandstone"
    },
    {
      "x": -17,
      "y": 30,
      "z": -3,
      "name": "Ore_Gold_Sandstone"
    },
    {
      "x": -17,
      "y": 31,
      "z": -3,
      "name": "Soil_Sand"
    },
    {
      "x": -17,
      "y": 32,
      "z": -3,
      "name": "Soil_Sand"
    },
    {
      "x": -17,
      "y": 28,
      "z": -2,
      "name": "Rock_Sandstone"
    },
    {
      "x": -17,
      "y": 29,
      "z": -2,
      "name": "Rock_Sandstone"
    },
    {
      "x": -17,
      "y": 30,
      "z": -2,
      "name": "Rock_Sandstone"
    },
    {
      "x": -17,
      "y": 31,
      "z": -2,
      "name": "Soil_Sand"
    },
    {
      "x": -17,
      "y": 32,
      "z": -2,
      "name": "Soil_Sand"
    },
    {
      "x": -17,
      "y": 27,
      "z": -1,
      "name": "Rock_Sandstone"
    },
    {
      "x": -17,
      "y": 28,
      "z": -1,
      "name": "Rock_Sandstone"
    },
    {
      "x": -17,
      "y": 29,
      "z": -1,
      "name": "Rock_Sandstone"
    },
    {
      "x": -17,
      "y": 30,
      "z": -1,
      "name": "Rock_Sandstone"
    },
    {
      "x": -17,
      "y": 31,
      "z": -1,
      "name": "Rock_Sandstone"
    },
    {
      "x": -17,
      "y": 32,
      "z": -1,
      "name": "Soil_Sand"
    },
    {
      "x": -17,
      "y": 28,
      "z": 0,
      "name": "Rock_Sandstone"
    },
    {
      "x": -17,
      "y": 29,
      "z": 0,
      "name": "Rock_Sandstone"
    },
    {
      "x": -17,
      "y": 30,
      "z": 0,
      "name": "Rock_Sandstone"
    },
    {
      "x": -17,
      "y": 31,
      "z": 0,
      "name": "Soil_Gravel_Sand"
    },
    {
      "x": -17,
      "y": 29,
      "z": 1,
      "name": "Rock_Sandstone"
    },
    {
      "x": -17,
      "y": 30,
      "z": 1,
      "name": "Rock_Sandstone"
    },
    {
      "x": -17,
      "y": 31,
      "z": 1,
      "name": "Rock_Sandstone"
    },
    {
      "x": -17,
      "y": 31,
      "z": 2,
      "name": "Rock_Sandstone"
    },
    {
      "x": -16,
      "y": 18,
      "z": -21,
      "name": "Plant_Crop_Mushroom_Shelve_Yellow"
    },
    {
      "x": -16,
      "y": 18,
      "z": -20,
      "name": "Rock_Sandstone"
    },
    {
      "x": -16,
      "y": 19,
      "z": -20,
      "name": "Soil_Sand"
    },
    {
      "x": -16,
      "y": 20,
      "z": -20,
      "name": "Soil_Sand"
    },
    {
      "x": -16,
      "y": 21,
      "z": -20,
      "name": "Soil_Sand"
    },
    {
      "x": -16,
      "y": 22,
      "z": -20,
      "name": "Plant_Crop_Mushroom_Glowing_Orange"
    },
    {
      "x": -16,
      "y": 16,
      "z": -19,
      "name": "Rock_Sandstone"
    },
    {
      "x": -16,
      "y": 17,
      "z": -19,
      "name": "Rock_Sandstone"
    },
    {
      "x": -16,
      "y": 18,
      "z": -19,
      "name": "Rock_Sandstone"
    },
    {
      "x": -16,
      "y": 19,
      "z": -19,
      "name": "Rock_Sandstone"
    },
    {
      "x": -16,
      "y": 20,
      "z": -19,
      "name": "Rock_Sandstone"
    },
    {
      "x": -16,
      "y": 21,
      "z": -19,
      "name": "Soil_Sand"
    },
    {
      "x": -16,
      "y": 22,
      "z": -19,
      "name": "Soil_Sand"
    },
    {
      "x": -16,
      "y": 15,
      "z": -18,
      "name": "Rock_Sandstone"
    },
    {
      "x": -16,
      "y": 16,
      "z": -18,
      "name": "Rock_Sandstone"
    },
    {
      "x": -16,
      "y": 17,
      "z": -18,
      "name": "Rock_Sandstone"
    },
    {
      "x": -16,
      "y": 18,
      "z": -18,
      "name": "Rock_Sandstone"
    },
    {
      "x": -16,
      "y": 19,
      "z": -18,
      "name": "Rock_Sandstone"
    },
    {
      "x": -16,
      "y": 20,
      "z": -18,
      "name": "Rock_Sandstone"
    },
    {
      "x": -16,
      "y": 21,
      "z": -18,
      "name": "Rock_Sandstone"
    },
    {
      "x": -16,
      "y": 22,
      "z": -18,
      "name": "Soil_Sand"
    },
    {
      "x": -16,
      "y": 23,
      "z": -18,
      "name": "Soil_Sand"
    },
    {
      "x": -16,
      "y": 11,
      "z": -17,
      "name": "Rock_Crystal_Yellow_Medium",
      "rotation": 5
    },
    {
      "x": -16,
      "y": 12,
      "z": -17,
      "name": "Rock_Crystal_Yellow_Medium",
      "rotation": 5
    },
    {
      "x": -16,
      "y": 14,
      "z": -17,
      "name": "Rock_Sandstone"
    },
    {
      "x": -16,
      "y": 15,
      "z": -17,
      "name": "Rock_Sandstone"
    },
    {
      "x": -16,
      "y": 16,
      "z": -17,
      "name": "Rock_Sandstone"
    },
    {
      "x": -16,
      "y": 17,
      "z": -17,
      "name": "Rock_Sandstone"
    },
    {
      "x": -16,
      "y": 18,
      "z": -17,
      "name": "Rock_Sandstone"
    },
    {
      "x": -16,
      "y": 19,
      "z": -17,
      "name": "Rock_Sandstone"
    },
    {
      "x": -16,
      "y": 20,
      "z": -17,
      "name": "Rock_Sandstone"
    },
    {
      "x": -16,
      "y": 21,
      "z": -17,
      "name": "Rock_Sandstone"
    },
    {
      "x": -16,
      "y": 22,
      "z": -17,
      "name": "Rock_Sandstone"
    },
    {
      "x": -16,
      "y": 23,
      "z": -17,
      "name": "Rock_Sandstone"
    },
    {
      "x": -16,
      "y": 24,
      "z": -17,
      "name": "Rock_Sandstone"
    },
    {
      "x": -16,
      "y": 25,
      "z": -17,
      "name": "Rock_Sandstone"
    },
    {
      "x": -16,
      "y": 26,
      "z": -17,
      "name": "Rubble_Sandstone"
    },
    {
      "x": -16,
      "y": 10,
      "z": -16,
      "name": "Rock_Crystal_Yellow_Medium",
      "rotation": 5
    },
    {
      "x": -16,
      "y": 11,
      "z": -16,
      "name": "Rock_Crystal_Yellow_Medium",
      "rotation": 5
    },
    {
      "x": -16,
      "y": 12,
      "z": -16,
      "name": "Rock_Crystal_Yellow_Medium",
      "rotation": 8
    },
    {
      "x": -16,
      "y": 13,
      "z": -16,
      "name": "Rock_Crystal_Yellow_Block"
    },
    {
      "x": -16,
      "y": 14,
      "z": -16,
      "name": "Rock_Crystal_Yellow_Block"
    },
    {
      "x": -16,
      "y": 15,
      "z": -16,
      "name": "Rock_Crystal_Yellow_Block"
    },
    {
      "x": -16,
      "y": 16,
      "z": -16,
      "name": "Rock_Crystal_Yellow_Block"
    },
    {
      "x": -16,
      "y": 17,
      "z": -16,
      "name": "Rock_Crystal_Yellow_Block"
    },
    {
      "x": -16,
      "y": 18,
      "z": -16,
      "name": "Rock_Sandstone"
    },
    {
      "x": -16,
      "y": 19,
      "z": -16,
      "name": "Rock_Sandstone"
    },
    {
      "x": -16,
      "y": 20,
      "z": -16,
      "name": "Rock_Sandstone"
    },
    {
      "x": -16,
      "y": 21,
      "z": -16,
      "name": "Rock_Sandstone"
    },
    {
      "x": -16,
      "y": 22,
      "z": -16,
      "name": "Rock_Sandstone"
    },
    {
      "x": -16,
      "y": 23,
      "z": -16,
      "name": "Rock_Sandstone"
    },
    {
      "x": -16,
      "y": 24,
      "z": -16,
      "name": "Rock_Sandstone"
    },
    {
      "x": -16,
      "y": 25,
      "z": -16,
      "name": "Rock_Sandstone"
    },
    {
      "x": -16,
      "y": 26,
      "z": -16,
      "name": "Rubble_Sandstone_Medium"
    },
    {
      "x": -16,
      "y": 12,
      "z": -15,
      "name": "Rock_Crystal_Yellow_Medium",
      "rotation": 5
    },
    {
      "x": -16,
      "y": 14,
      "z": -15,
      "name": "Rock_Sandstone"
    },
    {
      "x": -16,
      "y": 15,
      "z": -15,
      "name": "Rock_Sandstone"
    },
    {
      "x": -16,
      "y": 16,
      "z": -15,
      "name": "Rock_Sandstone"
    },
    {
      "x": -16,
      "y": 17,
      "z": -15,
      "name": "Rock_Sandstone"
    },
    {
      "x": -16,
      "y": 18,
      "z": -15,
      "name": "Rock_Sandstone"
    },
    {
      "x": -16,
      "y": 19,
      "z": -15,
      "name": "Rock_Sandstone"
    },
    {
      "x": -16,
      "y": 20,
      "z": -15,
      "name": "Rock_Sandstone"
    },
    {
      "x": -16,
      "y": 21,
      "z": -15,
      "name": "Rock_Sandstone"
    },
    {
      "x": -16,
      "y": 22,
      "z": -15,
      "name": "Rock_Sandstone"
    },
    {
      "x": -16,
      "y": 23,
      "z": -15,
      "name": "Rock_Sandstone"
    },
    {
      "x": -16,
      "y": 24,
      "z": -15,
      "name": "Rock_Sandstone"
    },
    {
      "x": -16,
      "y": 25,
      "z": -15,
      "name": "Rock_Sandstone"
    },
    {
      "x": -16,
      "y": 15,
      "z": -14,
      "name": "Rock_Sandstone"
    },
    {
      "x": -16,
      "y": 16,
      "z": -14,
      "name": "Rock_Sandstone"
    },
    {
      "x": -16,
      "y": 17,
      "z": -14,
      "name": "Rock_Sandstone"
    },
    {
      "x": -16,
      "y": 18,
      "z": -14,
      "name": "Rock_Sandstone"
    },
    {
      "x": -16,
      "y": 19,
      "z": -14,
      "name": "Rock_Sandstone"
    },
    {
      "x": -16,
      "y": 20,
      "z": -14,
      "name": "Rock_Sandstone"
    },
    {
      "x": -16,
      "y": 21,
      "z": -14,
      "name": "Rock_Sandstone"
    },
    {
      "x": -16,
      "y": 22,
      "z": -14,
      "name": "Rock_Sandstone"
    },
    {
      "x": -16,
      "y": 23,
      "z": -14,
      "name": "Rock_Sandstone"
    },
    {
      "x": -16,
      "y": 24,
      "z": -14,
      "name": "Rock_Sandstone"
    },
    {
      "x": -16,
      "y": 25,
      "z": -14,
      "name": "Rock_Sandstone"
    },
    {
      "x": -16,
      "y": 26,
      "z": -14,
      "name": "Soil_Sand"
    },
    {
      "x": -16,
      "y": 16,
      "z": -13,
      "name": "Rock_Sandstone"
    },
    {
      "x": -16,
      "y": 17,
      "z": -13,
      "name": "Rock_Sandstone"
    },
    {
      "x": -16,
      "y": 18,
      "z": -13,
      "name": "Rock_Sandstone"
    },
    {
      "x": -16,
      "y": 19,
      "z": -13,
      "name": "Rock_Sandstone"
    },
    {
      "x": -16,
      "y": 20,
      "z": -13,
      "name": "Rock_Sandstone"
    },
    {
      "x": -16,
      "y": 21,
      "z": -13,
      "name": "Rock_Sandstone"
    },
    {
      "x": -16,
      "y": 22,
      "z": -13,
      "name": "Rock_Sandstone"
    },
    {
      "x": -16,
      "y": 23,
      "z": -13,
      "name": "Rock_Sandstone"
    },
    {
      "x": -16,
      "y": 24,
      "z": -13,
      "name": "Rock_Sandstone"
    },
    {
      "x": -16,
      "y": 25,
      "z": -13,
      "name": "Rock_Sandstone"
    },
    {
      "x": -16,
      "y": 26,
      "z": -13,
      "name": "Rock_Sandstone"
    },
    {
      "x": -16,
      "y": 27,
      "z": -13,
      "name": "Rubble_Sandstone_Medium"
    },
    {
      "x": -16,
      "y": 17,
      "z": -12,
      "name": "Rock_Sandstone"
    },
    {
      "x": -16,
      "y": 18,
      "z": -12,
      "name": "Rock_Sandstone"
    },
    {
      "x": -16,
      "y": 19,
      "z": -12,
      "name": "Rock_Sandstone"
    },
    {
      "x": -16,
      "y": 20,
      "z": -12,
      "name": "Rock_Sandstone"
    },
    {
      "x": -16,
      "y": 21,
      "z": -12,
      "name": "Rock_Sandstone"
    },
    {
      "x": -16,
      "y": 22,
      "z": -12,
      "name": "Rock_Sandstone"
    },
    {
      "x": -16,
      "y": 23,
      "z": -12,
      "name": "Rock_Sandstone"
    },
    {
      "x": -16,
      "y": 24,
      "z": -12,
      "name": "Rock_Sandstone"
    },
    {
      "x": -16,
      "y": 25,
      "z": -12,
      "name": "Rock_Sandstone"
    },
    {
      "x": -16,
      "y": 26,
      "z": -12,
      "name": "Rock_Sandstone"
    },
    {
      "x": -16,
      "y": 27,
      "z": -12,
      "name": "Rock_Sandstone"
    },
    {
      "x": -16,
      "y": 17,
      "z": -11,
      "name": "Rock_Sandstone"
    },
    {
      "x": -16,
      "y": 18,
      "z": -11,
      "name": "Rock_Sandstone"
    },
    {
      "x": -16,
      "y": 19,
      "z": -11,
      "name": "Rock_Sandstone"
    },
    {
      "x": -16,
      "y": 20,
      "z": -11,
      "name": "Rock_Sandstone"
    },
    {
      "x": -16,
      "y": 21,
      "z": -11,
      "name": "Rock_Sandstone"
    },
    {
      "x": -16,
      "y": 22,
      "z": -11,
      "name": "Rock_Sandstone"
    },
    {
      "x": -16,
      "y": 23,
      "z": -11,
      "name": "Rock_Sandstone"
    },
    {
      "x": -16,
      "y": 24,
      "z": -11,
      "name": "Rock_Sandstone"
    },
    {
      "x": -16,
      "y": 25,
      "z": -11,
      "name": "Rock_Sandstone"
    },
    {
      "x": -16,
      "y": 26,
      "z": -11,
      "name": "Rock_Sandstone"
    },
    {
      "x": -16,
      "y": 27,
      "z": -11,
      "name": "Rock_Sandstone"
    },
    {
      "x": -16,
      "y": 18,
      "z": -10,
      "name": "Rock_Sandstone"
    },
    {
      "x": -16,
      "y": 19,
      "z": -10,
      "name": "Rock_Sandstone"
    },
    {
      "x": -16,
      "y": 20,
      "z": -10,
      "name": "Rock_Sandstone"
    },
    {
      "x": -16,
      "y": 21,
      "z": -10,
      "name": "Rock_Sandstone"
    },
    {
      "x": -16,
      "y": 22,
      "z": -10,
      "name": "Rock_Sandstone"
    },
    {
      "x": -16,
      "y": 23,
      "z": -10,
      "name": "Rock_Sandstone"
    },
    {
      "x": -16,
      "y": 24,
      "z": -10,
      "name": "Rock_Sandstone"
    },
    {
      "x": -16,
      "y": 25,
      "z": -10,
      "name": "Rock_Sandstone"
    },
    {
      "x": -16,
      "y": 26,
      "z": -10,
      "name": "Rock_Sandstone"
    },
    {
      "x": -16,
      "y": 27,
      "z": -10,
      "name": "Soil_Sand"
    },
    {
      "x": -16,
      "y": 28,
      "z": -10,
      "name": "Soil_Sand"
    },
    {
      "x": -16,
      "y": 19,
      "z": -9,
      "name": "Rock_Sandstone"
    },
    {
      "x": -16,
      "y": 20,
      "z": -9,
      "name": "Rock_Sandstone"
    },
    {
      "x": -16,
      "y": 21,
      "z": -9,
      "name": "Rock_Sandstone"
    },
    {
      "x": -16,
      "y": 22,
      "z": -9,
      "name": "Rock_Sandstone"
    },
    {
      "x": -16,
      "y": 23,
      "z": -9,
      "name": "Rock_Sandstone"
    },
    {
      "x": -16,
      "y": 24,
      "z": -9,
      "name": "Rock_Sandstone"
    },
    {
      "x": -16,
      "y": 25,
      "z": -9,
      "name": "Rock_Sandstone"
    },
    {
      "x": -16,
      "y": 26,
      "z": -9,
      "name": "Rock_Sandstone"
    },
    {
      "x": -16,
      "y": 27,
      "z": -9,
      "name": "Rock_Sandstone"
    },
    {
      "x": -16,
      "y": 28,
      "z": -9,
      "name": "Rock_Sandstone"
    },
    {
      "x": -16,
      "y": 29,
      "z": -9,
      "name": "Soil_Gravel_Sand"
    },
    {
      "x": -16,
      "y": 30,
      "z": -9,
      "name": "Plant_Bush_Arid"
    },
    {
      "x": -16,
      "y": 39,
      "z": -9,
      "name": "Wood_Ash_Branch_Corner",
      "rotation": 9
    },
    {
      "x": -16,
      "y": 19,
      "z": -8,
      "name": "Rock_Sandstone_Stalactite_Large",
      "filler": 31744,
      "rotation": 8
    },
    {
      "x": -16,
      "y": 20,
      "z": -8,
      "name": "Rock_Sandstone_Stalactite_Large",
      "rotation": 8
    },
    {
      "x": -16,
      "y": 21,
      "z": -8,
      "name": "Rock_Sandstone"
    },
    {
      "x": -16,
      "y": 22,
      "z": -8,
      "name": "Rock_Sandstone"
    },
    {
      "x": -16,
      "y": 23,
      "z": -8,
      "name": "Rock_Sandstone"
    },
    {
      "x": -16,
      "y": 24,
      "z": -8,
      "name": "Rock_Sandstone"
    },
    {
      "x": -16,
      "y": 25,
      "z": -8,
      "name": "Rock_Sandstone"
    },
    {
      "x": -16,
      "y": 26,
      "z": -8,
      "name": "Rock_Sandstone"
    },
    {
      "x": -16,
      "y": 27,
      "z": -8,
      "name": "Rock_Sandstone"
    },
    {
      "x": -16,
      "y": 28,
      "z": -8,
      "name": "Rock_Sandstone"
    },
    {
      "x": -16,
      "y": 29,
      "z": -8,
      "name": "Soil_Sand"
    },
    {
      "x": -16,
      "y": 30,
      "z": -8,
      "name": "Soil_Sand"
    },
    {
      "x": -16,
      "y": 23,
      "z": -7,
      "name": "Rock_Sandstone"
    },
    {
      "x": -16,
      "y": 24,
      "z": -7,
      "name": "Rock_Sandstone"
    },
    {
      "x": -16,
      "y": 25,
      "z": -7,
      "name": "Rock_Sandstone"
    },
    {
      "x": -16,
      "y": 26,
      "z": -7,
      "name": "Rock_Sandstone"
    },
    {
      "x": -16,
      "y": 27,
      "z": -7,
      "name": "Rock_Sandstone"
    },
    {
      "x": -16,
      "y": 28,
      "z": -7,
      "name": "Rock_Sandstone"
    },
    {
      "x": -16,
      "y": 29,
      "z": -7,
      "name": "Rock_Sandstone"
    },
    {
      "x": -16,
      "y": 30,
      "z": -7,
      "name": "Soil_Sand"
    },
    {
      "x": -16,
      "y": 31,
      "z": -7,
      "name": "Soil_Sand"
    },
    {
      "x": -16,
      "y": 23,
      "z": -6,
      "name": "Rock_Sandstone"
    },
    {
      "x": -16,
      "y": 24,
      "z": -6,
      "name": "Rock_Sandstone"
    },
    {
      "x": -16,
      "y": 25,
      "z": -6,
      "name": "Rock_Sandstone"
    },
    {
      "x": -16,
      "y": 26,
      "z": -6,
      "name": "Rock_Sandstone"
    },
    {
      "x": -16,
      "y": 27,
      "z": -6,
      "name": "Rock_Sandstone"
    },
    {
      "x": -16,
      "y": 28,
      "z": -6,
      "name": "Rock_Sandstone"
    },
    {
      "x": -16,
      "y": 29,
      "z": -6,
      "name": "Rock_Sandstone"
    },
    {
      "x": -16,
      "y": 30,
      "z": -6,
      "name": "Soil_Sand"
    },
    {
      "x": -16,
      "y": 31,
      "z": -6,
      "name": "Soil_Sand"
    },
    {
      "x": -16,
      "y": 32,
      "z": -6,
      "name": "Soil_Gravel_Sand"
    },
    {
      "x": -16,
      "y": 23,
      "z": -5,
      "name": "Rock_Sandstone"
    },
    {
      "x": -16,
      "y": 24,
      "z": -5,
      "name": "Rock_Sandstone"
    },
    {
      "x": -16,
      "y": 25,
      "z": -5,
      "name": "Rock_Sandstone"
    },
    {
      "x": -16,
      "y": 26,
      "z": -5,
      "name": "Rock_Sandstone"
    },
    {
      "x": -16,
      "y": 27,
      "z": -5,
      "name": "Rock_Sandstone"
    },
    {
      "x": -16,
      "y": 28,
      "z": -5,
      "name": "Rock_Sandstone"
    },
    {
      "x": -16,
      "y": 29,
      "z": -5,
      "name": "Rock_Sandstone"
    },
    {
      "x": -16,
      "y": 30,
      "z": -5,
      "name": "Soil_Sand"
    },
    {
      "x": -16,
      "y": 31,
      "z": -5,
      "name": "Soil_Sand"
    },
    {
      "x": -16,
      "y": 32,
      "z": -5,
      "name": "Soil_Sand"
    },
    {
      "x": -16,
      "y": 33,
      "z": -5,
      "name": "Plant_Flower_Flax_Orange"
    },
    {
      "x": -16,
      "y": 24,
      "z": -4,
      "name": "Rock_Sandstone"
    },
    {
      "x": -16,
      "y": 25,
      "z": -4,
      "name": "Rock_Sandstone"
    },
    {
      "x": -16,
      "y": 26,
      "z": -4,
      "name": "Rock_Sandstone"
    },
    {
      "x": -16,
      "y": 27,
      "z": -4,
      "name": "Rock_Sandstone"
    },
    {
      "x": -16,
      "y": 28,
      "z": -4,
      "name": "Rock_Sandstone"
    },
    {
      "x": -16,
      "y": 29,
      "z": -4,
      "name": "Rock_Sandstone"
    },
    {
      "x": -16,
      "y": 30,
      "z": -4,
      "name": "Soil_Sand"
    },
    {
      "x": -16,
      "y": 31,
      "z": -4,
      "name": "Soil_Gravel_Sand"
    },
    {
      "x": -16,
      "y": 32,
      "z": -4,
      "name": "Soil_Gravel_Sand"
    },
    {
      "x": -16,
      "y": 33,
      "z": -4,
      "name": "Soil_Sand"
    },
    {
      "x": -16,
      "y": 25,
      "z": -3,
      "name": "Rock_Sandstone"
    },
    {
      "x": -16,
      "y": 26,
      "z": -3,
      "name": "Rock_Sandstone"
    },
    {
      "x": -16,
      "y": 27,
      "z": -3,
      "name": "Rock_Sandstone"
    },
    {
      "x": -16,
      "y": 28,
      "z": -3,
      "name": "Rock_Sandstone"
    },
    {
      "x": -16,
      "y": 29,
      "z": -3,
      "name": "Rock_Sandstone"
    },
    {
      "x": -16,
      "y": 30,
      "z": -3,
      "name": "Ore_Gold_Sandstone"
    },
    {
      "x": -16,
      "y": 31,
      "z": -3,
      "name": "Soil_Sand"
    },
    {
      "x": -16,
      "y": 32,
      "z": -3,
      "name": "Soil_Sand"
    },
    {
      "x": -16,
      "y": 33,
      "z": -3,
      "name": "Soil_Sand"
    },
    {
      "x": -16,
      "y": 26,
      "z": -2,
      "name": "Rock_Sandstone"
    },
    {
      "x": -16,
      "y": 27,
      "z": -2,
      "name": "Rock_Sandstone"
    },
    {
      "x": -16,
      "y": 28,
      "z": -2,
      "name": "Rock_Sandstone"
    },
    {
      "x": -16,
      "y": 29,
      "z": -2,
      "name": "Rock_Sandstone"
    },
    {
      "x": -16,
      "y": 30,
      "z": -2,
      "name": "Rock_Sandstone"
    },
    {
      "x": -16,
      "y": 31,
      "z": -2,
      "name": "Rock_Sandstone"
    },
    {
      "x": -16,
      "y": 32,
      "z": -2,
      "name": "Rock_Sandstone"
    },
    {
      "x": -16,
      "y": 33,
      "z": -2,
      "name": "Rock_Sandstone"
    },
    {
      "x": -16,
      "y": 26,
      "z": -1,
      "name": "Rock_Sandstone"
    },
    {
      "x": -16,
      "y": 27,
      "z": -1,
      "name": "Rock_Sandstone"
    },
    {
      "x": -16,
      "y": 28,
      "z": -1,
      "name": "Rock_Sandstone"
    },
    {
      "x": -16,
      "y": 29,
      "z": -1,
      "name": "Rock_Sandstone"
    },
    {
      "x": -16,
      "y": 30,
      "z": -1,
      "name": "Rock_Sandstone"
    },
    {
      "x": -16,
      "y": 31,
      "z": -1,
      "name": "Soil_Sand"
    },
    {
      "x": -16,
      "y": 32,
      "z": -1,
      "name": "Soil_Gravel_Sand"
    },
    {
      "x": -16,
      "y": 33,
      "z": -1,
      "name": "Soil_Sand"
    },
    {
      "x": -16,
      "y": 24,
      "z": 0,
      "name": "Rock_Sandstone_Stalactite_Large",
      "filler": 31744,
      "rotation": 8
    },
    {
      "x": -16,
      "y": 25,
      "z": 0,
      "name": "Rock_Sandstone_Stalactite_Large",
      "rotation": 8
    },
    {
      "x": -16,
      "y": 26,
      "z": 0,
      "name": "Rock_Sandstone"
    },
    {
      "x": -16,
      "y": 27,
      "z": 0,
      "name": "Rock_Sandstone"
    },
    {
      "x": -16,
      "y": 28,
      "z": 0,
      "name": "Rock_Sandstone"
    },
    {
      "x": -16,
      "y": 29,
      "z": 0,
      "name": "Rock_Sandstone"
    },
    {
      "x": -16,
      "y": 30,
      "z": 0,
      "name": "Rock_Sandstone"
    },
    {
      "x": -16,
      "y": 31,
      "z": 0,
      "name": "Rock_Sandstone"
    },
    {
      "x": -16,
      "y": 32,
      "z": 0,
      "name": "Soil_Gravel_Sand"
    },
    {
      "x": -16,
      "y": 33,
      "z": 0,
      "name": "Soil_Sand"
    },
    {
      "x": -16,
      "y": 27,
      "z": 1,
      "name": "Rock_Sandstone"
    },
    {
      "x": -16,
      "y": 28,
      "z": 1,
      "name": "Rock_Sandstone"
    },
    {
      "x": -16,
      "y": 29,
      "z": 1,
      "name": "Rock_Sandstone"
    },
    {
      "x": -16,
      "y": 30,
      "z": 1,
      "name": "Rock_Sandstone"
    },
    {
      "x": -16,
      "y": 31,
      "z": 1,
      "name": "Soil_Gravel_Sand"
    },
    {
      "x": -16,
      "y": 32,
      "z": 1,
      "name": "Soil_Sand"
    },
    {
      "x": -16,
      "y": 28,
      "z": 2,
      "name": "Rock_Sandstone"
    },
    {
      "x": -16,
      "y": 29,
      "z": 2,
      "name": "Rock_Sandstone"
    },
    {
      "x": -16,
      "y": 30,
      "z": 2,
      "name": "Rock_Sandstone"
    },
    {
      "x": -16,
      "y": 31,
      "z": 2,
      "name": "Rock_Sandstone"
    },
    {
      "x": -15,
      "y": 17,
      "z": -19,
      "name": "Rock_Sandstone"
    },
    {
      "x": -15,
      "y": 18,
      "z": -19,
      "name": "Rock_Sandstone"
    },
    {
      "x": -15,
      "y": 19,
      "z": -19,
      "name": "Rock_Sandstone"
    },
    {
      "x": -15,
      "y": 20,
      "z": -19,
      "name": "Rock_Sandstone"
    },
    {
      "x": -15,
      "y": 21,
      "z": -19,
      "name": "Soil_Sand"
    },
    {
      "x": -15,
      "y": 22,
      "z": -19,
      "name": "Soil_Sand"
    },
    {
      "x": -15,
      "y": 16,
      "z": -18,
      "name": "Rock_Sandstone"
    },
    {
      "x": -15,
      "y": 17,
      "z": -18,
      "name": "Rock_Sandstone"
    },
    {
      "x": -15,
      "y": 18,
      "z": -18,
      "name": "Rock_Sandstone"
    },
    {
      "x": -15,
      "y": 19,
      "z": -18,
      "name": "Rock_Sandstone"
    },
    {
      "x": -15,
      "y": 20,
      "z": -18,
      "name": "Rock_Sandstone"
    },
    {
      "x": -15,
      "y": 21,
      "z": -18,
      "name": "Soil_Sand"
    },
    {
      "x": -15,
      "y": 22,
      "z": -18,
      "name": "Soil_Sand"
    },
    {
      "x": -15,
      "y": 23,
      "z": -18,
      "name": "Soil_Sand"
    },
    {
      "x": -15,
      "y": 15,
      "z": -17,
      "name": "Rock_Sandstone"
    },
    {
      "x": -15,
      "y": 16,
      "z": -17,
      "name": "Rock_Sandstone"
    },
    {
      "x": -15,
      "y": 17,
      "z": -17,
      "name": "Rock_Sandstone"
    },
    {
      "x": -15,
      "y": 18,
      "z": -17,
      "name": "Rock_Sandstone"
    },
    {
      "x": -15,
      "y": 19,
      "z": -17,
      "name": "Rock_Sandstone"
    },
    {
      "x": -15,
      "y": 20,
      "z": -17,
      "name": "Rock_Sandstone"
    },
    {
      "x": -15,
      "y": 21,
      "z": -17,
      "name": "Rock_Sandstone"
    },
    {
      "x": -15,
      "y": 22,
      "z": -17,
      "name": "Rock_Sandstone"
    },
    {
      "x": -15,
      "y": 23,
      "z": -17,
      "name": "Soil_Sand"
    },
    {
      "x": -15,
      "y": 24,
      "z": -17,
      "name": "Soil_Sand"
    },
    {
      "x": -15,
      "y": 15,
      "z": -16,
      "name": "Rock_Sandstone"
    },
    {
      "x": -15,
      "y": 16,
      "z": -16,
      "name": "Rock_Sandstone"
    },
    {
      "x": -15,
      "y": 17,
      "z": -16,
      "name": "Rock_Sandstone"
    },
    {
      "x": -15,
      "y": 18,
      "z": -16,
      "name": "Rock_Sandstone"
    },
    {
      "x": -15,
      "y": 19,
      "z": -16,
      "name": "Rock_Sandstone"
    },
    {
      "x": -15,
      "y": 20,
      "z": -16,
      "name": "Rock_Sandstone"
    },
    {
      "x": -15,
      "y": 21,
      "z": -16,
      "name": "Rock_Sandstone"
    },
    {
      "x": -15,
      "y": 22,
      "z": -16,
      "name": "Rock_Sandstone"
    },
    {
      "x": -15,
      "y": 23,
      "z": -16,
      "name": "Soil_Sand"
    },
    {
      "x": -15,
      "y": 24,
      "z": -16,
      "name": "Soil_Sand"
    },
    {
      "x": -15,
      "y": 25,
      "z": -16,
      "name": "Soil_Sand"
    },
    {
      "x": -15,
      "y": 26,
      "z": -16,
      "name": "Plant_Crop_Stamina2"
    },
    {
      "x": -15,
      "y": 15,
      "z": -15,
      "name": "Rock_Sandstone"
    },
    {
      "x": -15,
      "y": 16,
      "z": -15,
      "name": "Rock_Sandstone"
    },
    {
      "x": -15,
      "y": 17,
      "z": -15,
      "name": "Rock_Sandstone"
    },
    {
      "x": -15,
      "y": 18,
      "z": -15,
      "name": "Rock_Sandstone"
    },
    {
      "x": -15,
      "y": 19,
      "z": -15,
      "name": "Rock_Sandstone"
    },
    {
      "x": -15,
      "y": 20,
      "z": -15,
      "name": "Rock_Sandstone"
    },
    {
      "x": -15,
      "y": 21,
      "z": -15,
      "name": "Rock_Sandstone"
    },
    {
      "x": -15,
      "y": 22,
      "z": -15,
      "name": "Rock_Sandstone"
    },
    {
      "x": -15,
      "y": 23,
      "z": -15,
      "name": "Rock_Sandstone"
    },
    {
      "x": -15,
      "y": 24,
      "z": -15,
      "name": "Rock_Sandstone"
    },
    {
      "x": -15,
      "y": 25,
      "z": -15,
      "name": "Rock_Sandstone"
    },
    {
      "x": -15,
      "y": 26,
      "z": -15,
      "name": "Rock_Sandstone"
    },
    {
      "x": -15,
      "y": 16,
      "z": -14,
      "name": "Rock_Sandstone"
    },
    {
      "x": -15,
      "y": 17,
      "z": -14,
      "name": "Rock_Sandstone"
    },
    {
      "x": -15,
      "y": 18,
      "z": -14,
      "name": "Rock_Sandstone"
    },
    {
      "x": -15,
      "y": 19,
      "z": -14,
      "name": "Rock_Sandstone"
    },
    {
      "x": -15,
      "y": 20,
      "z": -14,
      "name": "Rock_Sandstone"
    },
    {
      "x": -15,
      "y": 21,
      "z": -14,
      "name": "Rock_Sandstone"
    },
    {
      "x": -15,
      "y": 22,
      "z": -14,
      "name": "Rock_Sandstone"
    },
    {
      "x": -15,
      "y": 23,
      "z": -14,
      "name": "Rock_Sandstone"
    },
    {
      "x": -15,
      "y": 24,
      "z": -14,
      "name": "Rock_Sandstone"
    },
    {
      "x": -15,
      "y": 25,
      "z": -14,
      "name": "Soil_Sand"
    },
    {
      "x": -15,
      "y": 26,
      "z": -14,
      "name": "Soil_Sand"
    },
    {
      "x": -15,
      "y": 16,
      "z": -13,
      "name": "Rock_Sandstone"
    },
    {
      "x": -15,
      "y": 17,
      "z": -13,
      "name": "Rock_Sandstone"
    },
    {
      "x": -15,
      "y": 18,
      "z": -13,
      "name": "Rock_Sandstone"
    },
    {
      "x": -15,
      "y": 19,
      "z": -13,
      "name": "Rock_Sandstone"
    },
    {
      "x": -15,
      "y": 20,
      "z": -13,
      "name": "Rock_Sandstone"
    },
    {
      "x": -15,
      "y": 21,
      "z": -13,
      "name": "Rock_Sandstone"
    },
    {
      "x": -15,
      "y": 22,
      "z": -13,
      "name": "Rock_Sandstone"
    },
    {
      "x": -15,
      "y": 23,
      "z": -13,
      "name": "Rock_Sandstone"
    },
    {
      "x": -15,
      "y": 24,
      "z": -13,
      "name": "Rock_Sandstone"
    },
    {
      "x": -15,
      "y": 25,
      "z": -13,
      "name": "Rock_Sandstone"
    },
    {
      "x": -15,
      "y": 26,
      "z": -13,
      "name": "Soil_Gravel_Sand"
    },
    {
      "x": -15,
      "y": 27,
      "z": -13,
      "name": "Soil_Sand"
    },
    {
      "x": -15,
      "y": 16,
      "z": -12,
      "name": "Rock_Sandstone"
    },
    {
      "x": -15,
      "y": 17,
      "z": -12,
      "name": "Rock_Sandstone"
    },
    {
      "x": -15,
      "y": 18,
      "z": -12,
      "name": "Rock_Sandstone"
    },
    {
      "x": -15,
      "y": 19,
      "z": -12,
      "name": "Rock_Sandstone"
    },
    {
      "x": -15,
      "y": 20,
      "z": -12,
      "name": "Rock_Sandstone"
    },
    {
      "x": -15,
      "y": 21,
      "z": -12,
      "name": "Rock_Sandstone"
    },
    {
      "x": -15,
      "y": 22,
      "z": -12,
      "name": "Rock_Sandstone"
    },
    {
      "x": -15,
      "y": 23,
      "z": -12,
      "name": "Rock_Sandstone"
    },
    {
      "x": -15,
      "y": 24,
      "z": -12,
      "name": "Rock_Sandstone"
    },
    {
      "x": -15,
      "y": 25,
      "z": -12,
      "name": "Rock_Sandstone"
    },
    {
      "x": -15,
      "y": 26,
      "z": -12,
      "name": "Rock_Sandstone"
    },
    {
      "x": -15,
      "y": 27,
      "z": -12,
      "name": "Soil_Sand"
    },
    {
      "x": -15,
      "y": 28,
      "z": -12,
      "name": "Plant_Crop_Mushroom_Glowing_Red"
    },
    {
      "x": -15,
      "y": 16,
      "z": -11,
      "name": "Rock_Sandstone"
    },
    {
      "x": -15,
      "y": 17,
      "z": -11,
      "name": "Rock_Sandstone"
    },
    {
      "x": -15,
      "y": 18,
      "z": -11,
      "name": "Rock_Sandstone"
    },
    {
      "x": -15,
      "y": 19,
      "z": -11,
      "name": "Rock_Sandstone"
    },
    {
      "x": -15,
      "y": 20,
      "z": -11,
      "name": "Rock_Sandstone"
    },
    {
      "x": -15,
      "y": 21,
      "z": -11,
      "name": "Rock_Sandstone"
    },
    {
      "x": -15,
      "y": 22,
      "z": -11,
      "name": "Rock_Sandstone"
    },
    {
      "x": -15,
      "y": 23,
      "z": -11,
      "name": "Rock_Sandstone"
    },
    {
      "x": -15,
      "y": 24,
      "z": -11,
      "name": "Rock_Sandstone"
    },
    {
      "x": -15,
      "y": 25,
      "z": -11,
      "name": "Rock_Sandstone"
    },
    {
      "x": -15,
      "y": 26,
      "z": -11,
      "name": "Rock_Sandstone"
    },
    {
      "x": -15,
      "y": 27,
      "z": -11,
      "name": "Rock_Sandstone"
    },
    {
      "x": -15,
      "y": 28,
      "z": -11,
      "name": "Rock_Sandstone"
    },
    {
      "x": -15,
      "y": 15,
      "z": -10,
      "name": "Rock_Sandstone_Stalactite_Large",
      "filler": 31744,
      "rotation": 8
    },
    {
      "x": -15,
      "y": 16,
      "z": -10,
      "name": "Rock_Sandstone_Stalactite_Large",
      "rotation": 8
    },
    {
      "x": -15,
      "y": 17,
      "z": -10,
      "name": "Rock_Sandstone"
    },
    {
      "x": -15,
      "y": 18,
      "z": -10,
      "name": "Rock_Sandstone"
    },
    {
      "x": -15,
      "y": 19,
      "z": -10,
      "name": "Rock_Sandstone"
    },
    {
      "x": -15,
      "y": 20,
      "z": -10,
      "name": "Rock_Sandstone"
    },
    {
      "x": -15,
      "y": 21,
      "z": -10,
      "name": "Rock_Sandstone"
    },
    {
      "x": -15,
      "y": 22,
      "z": -10,
      "name": "Rock_Sandstone"
    },
    {
      "x": -15,
      "y": 23,
      "z": -10,
      "name": "Rock_Sandstone"
    },
    {
      "x": -15,
      "y": 24,
      "z": -10,
      "name": "Rock_Sandstone"
    },
    {
      "x": -15,
      "y": 25,
      "z": -10,
      "name": "Rock_Sandstone"
    },
    {
      "x": -15,
      "y": 26,
      "z": -10,
      "name": "Rock_Sandstone"
    },
    {
      "x": -15,
      "y": 27,
      "z": -10,
      "name": "Rock_Sandstone"
    },
    {
      "x": -15,
      "y": 28,
      "z": -10,
      "name": "Soil_Sand"
    },
    {
      "x": -15,
      "y": 29,
      "z": -10,
      "name": "Soil_Sand"
    },
    {
      "x": -15,
      "y": 30,
      "z": -10,
      "name": "Plant_Crop_Stamina2"
    },
    {
      "x": -15,
      "y": 18,
      "z": -9,
      "name": "Rock_Sandstone"
    },
    {
      "x": -15,
      "y": 19,
      "z": -9,
      "name": "Rock_Sandstone"
    },
    {
      "x": -15,
      "y": 20,
      "z": -9,
      "name": "Rock_Sandstone"
    },
    {
      "x": -15,
      "y": 21,
      "z": -9,
      "name": "Rock_Sandstone"
    },
    {
      "x": -15,
      "y": 22,
      "z": -9,
      "name": "Rock_Sandstone"
    },
    {
      "x": -15,
      "y": 23,
      "z": -9,
      "name": "Rock_Sandstone"
    },
    {
      "x": -15,
      "y": 24,
      "z": -9,
      "name": "Rock_Sandstone"
    },
    {
      "x": -15,
      "y": 25,
      "z": -9,
      "name": "Rock_Sandstone"
    },
    {
      "x": -15,
      "y": 26,
      "z": -9,
      "name": "Rock_Sandstone"
    },
    {
      "x": -15,
      "y": 27,
      "z": -9,
      "name": "Rock_Sandstone"
    },
    {
      "x": -15,
      "y": 28,
      "z": -9,
      "name": "Rock_Sandstone"
    },
    {
      "x": -15,
      "y": 29,
      "z": -9,
      "name": "Rock_Sandstone"
    },
    {
      "x": -15,
      "y": 30,
      "z": -9,
      "name": "Soil_Sand"
    },
    {
      "x": -15,
      "y": 39,
      "z": -9,
      "name": "Wood_Ash_Branch_Long",
      "rotation": 5
    },
    {
      "x": -15,
      "y": 20,
      "z": -8,
      "name": "Rock_Sandstone"
    },
    {
      "x": -15,
      "y": 21,
      "z": -8,
      "name": "Rock_Sandstone"
    },
    {
      "x": -15,
      "y": 22,
      "z": -8,
      "name": "Rock_Sandstone"
    },
    {
      "x": -15,
      "y": 23,
      "z": -8,
      "name": "Rock_Sandstone"
    },
    {
      "x": -15,
      "y": 24,
      "z": -8,
      "name": "Rock_Sandstone"
    },
    {
      "x": -15,
      "y": 25,
      "z": -8,
      "name": "Rock_Sandstone"
    },
    {
      "x": -15,
      "y": 26,
      "z": -8,
      "name": "Rock_Sandstone"
    },
    {
      "x": -15,
      "y": 27,
      "z": -8,
      "name": "Rock_Sandstone"
    },
    {
      "x": -15,
      "y": 28,
      "z": -8,
      "name": "Rock_Sandstone"
    },
    {
      "x": -15,
      "y": 29,
      "z": -8,
      "name": "Soil_Sand"
    },
    {
      "x": -15,
      "y": 30,
      "z": -8,
      "name": "Soil_Gravel_Sand"
    },
    {
      "x": -15,
      "y": 31,
      "z": -8,
      "name": "Soil_Sand"
    },
    {
      "x": -15,
      "y": 22,
      "z": -7,
      "name": "Rock_Sandstone"
    },
    {
      "x": -15,
      "y": 23,
      "z": -7,
      "name": "Rock_Sandstone"
    },
    {
      "x": -15,
      "y": 24,
      "z": -7,
      "name": "Rock_Sandstone"
    },
    {
      "x": -15,
      "y": 25,
      "z": -7,
      "name": "Rock_Sandstone"
    },
    {
      "x": -15,
      "y": 26,
      "z": -7,
      "name": "Rock_Sandstone"
    },
    {
      "x": -15,
      "y": 27,
      "z": -7,
      "name": "Rock_Sandstone"
    },
    {
      "x": -15,
      "y": 28,
      "z": -7,
      "name": "Rock_Sandstone"
    },
    {
      "x": -15,
      "y": 29,
      "z": -7,
      "name": "Rock_Sandstone"
    },
    {
      "x": -15,
      "y": 30,
      "z": -7,
      "name": "Soil_Sand"
    },
    {
      "x": -15,
      "y": 31,
      "z": -7,
      "name": "Soil_Sand"
    },
    {
      "x": -15,
      "y": 32,
      "z": -7,
      "name": "Soil_Gravel_Sand"
    },
    {
      "x": -15,
      "y": 33,
      "z": -7,
      "name": "Plant_Flower_Bushy_Yellow"
    },
    {
      "x": -15,
      "y": 22,
      "z": -6,
      "name": "Rock_Sandstone"
    },
    {
      "x": -15,
      "y": 23,
      "z": -6,
      "name": "Rock_Sandstone"
    },
    {
      "x": -15,
      "y": 24,
      "z": -6,
      "name": "Rock_Sandstone"
    },
    {
      "x": -15,
      "y": 25,
      "z": -6,
      "name": "Rock_Sandstone"
    },
    {
      "x": -15,
      "y": 26,
      "z": -6,
      "name": "Rock_Sandstone"
    },
    {
      "x": -15,
      "y": 27,
      "z": -6,
      "name": "Rock_Sandstone"
    },
    {
      "x": -15,
      "y": 28,
      "z": -6,
      "name": "Rock_Sandstone"
    },
    {
      "x": -15,
      "y": 29,
      "z": -6,
      "name": "Rock_Sandstone"
    },
    {
      "x": -15,
      "y": 30,
      "z": -6,
      "name": "Soil_Sand"
    },
    {
      "x": -15,
      "y": 31,
      "z": -6,
      "name": "Soil_Sand"
    },
    {
      "x": -15,
      "y": 32,
      "z": -6,
      "name": "Soil_Sand"
    },
    {
      "x": -15,
      "y": 22,
      "z": -5,
      "name": "Rock_Sandstone"
    },
    {
      "x": -15,
      "y": 23,
      "z": -5,
      "name": "Rock_Sandstone"
    },
    {
      "x": -15,
      "y": 24,
      "z": -5,
      "name": "Rock_Sandstone"
    },
    {
      "x": -15,
      "y": 25,
      "z": -5,
      "name": "Rock_Sandstone"
    },
    {
      "x": -15,
      "y": 26,
      "z": -5,
      "name": "Rock_Sandstone"
    },
    {
      "x": -15,
      "y": 27,
      "z": -5,
      "name": "Rock_Sandstone"
    },
    {
      "x": -15,
      "y": 28,
      "z": -5,
      "name": "Rock_Sandstone"
    },
    {
      "x": -15,
      "y": 29,
      "z": -5,
      "name": "Rock_Sandstone"
    },
    {
      "x": -15,
      "y": 30,
      "z": -5,
      "name": "Soil_Sand"
    },
    {
      "x": -15,
      "y": 31,
      "z": -5,
      "name": "Soil_Sand"
    },
    {
      "x": -15,
      "y": 32,
      "z": -5,
      "name": "Soil_Gravel_Sand"
    },
    {
      "x": -15,
      "y": 33,
      "z": -5,
      "name": "Soil_Sand"
    },
    {
      "x": -15,
      "y": 23,
      "z": -4,
      "name": "Rock_Sandstone"
    },
    {
      "x": -15,
      "y": 24,
      "z": -4,
      "name": "Rock_Sandstone"
    },
    {
      "x": -15,
      "y": 25,
      "z": -4,
      "name": "Rock_Sandstone"
    },
    {
      "x": -15,
      "y": 26,
      "z": -4,
      "name": "Rock_Sandstone"
    },
    {
      "x": -15,
      "y": 27,
      "z": -4,
      "name": "Rock_Sandstone"
    },
    {
      "x": -15,
      "y": 28,
      "z": -4,
      "name": "Rock_Sandstone"
    },
    {
      "x": -15,
      "y": 29,
      "z": -4,
      "name": "Rock_Sandstone"
    },
    {
      "x": -15,
      "y": 30,
      "z": -4,
      "name": "Rock_Sandstone"
    },
    {
      "x": -15,
      "y": 31,
      "z": -4,
      "name": "Soil_Gravel_Sand"
    },
    {
      "x": -15,
      "y": 32,
      "z": -4,
      "name": "Soil_Sand"
    },
    {
      "x": -15,
      "y": 33,
      "z": -4,
      "name": "Soil_Sand"
    },
    {
      "x": -15,
      "y": 34,
      "z": -4,
      "name": "Plant_Flower_Bushy_Yellow"
    },
    {
      "x": -15,
      "y": 24,
      "z": -3,
      "name": "Rock_Sandstone"
    },
    {
      "x": -15,
      "y": 25,
      "z": -3,
      "name": "Rock_Sandstone"
    },
    {
      "x": -15,
      "y": 26,
      "z": -3,
      "name": "Rock_Sandstone"
    },
    {
      "x": -15,
      "y": 27,
      "z": -3,
      "name": "Rock_Sandstone"
    },
    {
      "x": -15,
      "y": 28,
      "z": -3,
      "name": "Rock_Sandstone"
    },
    {
      "x": -15,
      "y": 29,
      "z": -3,
      "name": "Rock_Sandstone"
    },
    {
      "x": -15,
      "y": 30,
      "z": -3,
      "name": "Ore_Gold_Sandstone"
    },
    {
      "x": -15,
      "y": 31,
      "z": -3,
      "name": "Rock_Sandstone"
    },
    {
      "x": -15,
      "y": 32,
      "z": -3,
      "name": "Rock_Sandstone"
    },
    {
      "x": -15,
      "y": 33,
      "z": -3,
      "name": "Rock_Sandstone"
    },
    {
      "x": -15,
      "y": 34,
      "z": -3,
      "name": "Soil_Gravel_Sand"
    },
    {
      "x": -15,
      "y": 25,
      "z": -2,
      "name": "Rock_Sandstone"
    },
    {
      "x": -15,
      "y": 26,
      "z": -2,
      "name": "Rock_Sandstone"
    },
    {
      "x": -15,
      "y": 27,
      "z": -2,
      "name": "Rock_Sandstone"
    },
    {
      "x": -15,
      "y": 28,
      "z": -2,
      "name": "Rock_Sandstone"
    },
    {
      "x": -15,
      "y": 29,
      "z": -2,
      "name": "Rock_Sandstone"
    },
    {
      "x": -15,
      "y": 30,
      "z": -2,
      "name": "Rock_Sandstone"
    },
    {
      "x": -15,
      "y": 31,
      "z": -2,
      "name": "Rock_Sandstone"
    },
    {
      "x": -15,
      "y": 32,
      "z": -2,
      "name": "Rock_Sandstone"
    },
    {
      "x": -15,
      "y": 33,
      "z": -2,
      "name": "Soil_Sand"
    },
    {
      "x": -15,
      "y": 34,
      "z": -2,
      "name": "Soil_Sand"
    },
    {
      "x": -15,
      "y": 25,
      "z": -1,
      "name": "Rock_Sandstone"
    },
    {
      "x": -15,
      "y": 26,
      "z": -1,
      "name": "Rock_Sandstone"
    },
    {
      "x": -15,
      "y": 27,
      "z": -1,
      "name": "Rock_Sandstone"
    },
    {
      "x": -15,
      "y": 28,
      "z": -1,
      "name": "Rock_Sandstone"
    },
    {
      "x": -15,
      "y": 29,
      "z": -1,
      "name": "Rock_Sandstone"
    },
    {
      "x": -15,
      "y": 30,
      "z": -1,
      "name": "Rock_Sandstone"
    },
    {
      "x": -15,
      "y": 31,
      "z": -1,
      "name": "Rock_Sandstone"
    },
    {
      "x": -15,
      "y": 32,
      "z": -1,
      "name": "Soil_Gravel_Sand"
    },
    {
      "x": -15,
      "y": 33,
      "z": -1,
      "name": "Soil_Sand"
    },
    {
      "x": -15,
      "y": 34,
      "z": -1,
      "name": "Soil_Sand"
    },
    {
      "x": -15,
      "y": 25,
      "z": 0,
      "name": "Rock_Sandstone"
    },
    {
      "x": -15,
      "y": 26,
      "z": 0,
      "name": "Rock_Sandstone"
    },
    {
      "x": -15,
      "y": 27,
      "z": 0,
      "name": "Rock_Sandstone"
    },
    {
      "x": -15,
      "y": 28,
      "z": 0,
      "name": "Rock_Sandstone"
    },
    {
      "x": -15,
      "y": 29,
      "z": 0,
      "name": "Rock_Sandstone"
    },
    {
      "x": -15,
      "y": 30,
      "z": 0,
      "name": "Rock_Sandstone"
    },
    {
      "x": -15,
      "y": 31,
      "z": 0,
      "name": "Rock_Sandstone"
    },
    {
      "x": -15,
      "y": 32,
      "z": 0,
      "name": "Soil_Sand"
    },
    {
      "x": -15,
      "y": 33,
      "z": 0,
      "name": "Soil_Sand"
    },
    {
      "x": -15,
      "y": 26,
      "z": 1,
      "name": "Rock_Sandstone"
    },
    {
      "x": -15,
      "y": 27,
      "z": 1,
      "name": "Rock_Sandstone"
    },
    {
      "x": -15,
      "y": 28,
      "z": 1,
      "name": "Rock_Sandstone"
    },
    {
      "x": -15,
      "y": 29,
      "z": 1,
      "name": "Rock_Sandstone"
    },
    {
      "x": -15,
      "y": 30,
      "z": 1,
      "name": "Rock_Sandstone"
    },
    {
      "x": -15,
      "y": 31,
      "z": 1,
      "name": "Rock_Sandstone"
    },
    {
      "x": -15,
      "y": 32,
      "z": 1,
      "name": "Soil_Sand"
    },
    {
      "x": -15,
      "y": 33,
      "z": 1,
      "name": "Soil_Gravel_Sand"
    },
    {
      "x": -15,
      "y": 26,
      "z": 2,
      "name": "Plant_Crop_Mushroom_Shelve_Yellow"
    },
    {
      "x": -15,
      "y": 27,
      "z": 2,
      "name": "Rock_Sandstone"
    },
    {
      "x": -15,
      "y": 28,
      "z": 2,
      "name": "Rock_Sandstone"
    },
    {
      "x": -15,
      "y": 29,
      "z": 2,
      "name": "Rock_Sandstone"
    },
    {
      "x": -15,
      "y": 30,
      "z": 2,
      "name": "Rock_Sandstone"
    },
    {
      "x": -15,
      "y": 31,
      "z": 2,
      "name": "Rock_Sandstone"
    },
    {
      "x": -15,
      "y": 32,
      "z": 2,
      "name": "Rock_Sandstone"
    },
    {
      "x": -15,
      "y": 28,
      "z": 3,
      "name": "Plant_Crop_Mushroom_Shelve_Yellow"
    },
    {
      "x": -15,
      "y": 29,
      "z": 3,
      "name": "Rock_Sandstone"
    },
    {
      "x": -15,
      "y": 30,
      "z": 3,
      "name": "Rock_Sandstone"
    },
    {
      "x": -15,
      "y": 31,
      "z": 3,
      "name": "Rock_Sandstone"
    },
    {
      "x": -15,
      "y": 29,
      "z": 4,
      "name": "Plant_Crop_Mushroom_Shelve_Yellow"
    },
    {
      "x": -14,
      "y": 17,
      "z": -19,
      "name": "Plant_Crop_Mushroom_Shelve_Yellow"
    },
    {
      "x": -14,
      "y": 18,
      "z": -19,
      "name": "Rock_Sandstone"
    },
    {
      "x": -14,
      "y": 19,
      "z": -19,
      "name": "Rock_Sandstone"
    },
    {
      "x": -14,
      "y": 20,
      "z": -19,
      "name": "Rubble_Sandstone_Medium"
    },
    {
      "x": -14,
      "y": 17,
      "z": -18,
      "name": "Rock_Sandstone"
    },
    {
      "x": -14,
      "y": 18,
      "z": -18,
      "name": "Rock_Sandstone"
    },
    {
      "x": -14,
      "y": 19,
      "z": -18,
      "name": "Rock_Sandstone"
    },
    {
      "x": -14,
      "y": 20,
      "z": -18,
      "name": "Rock_Sandstone"
    },
    {
      "x": -14,
      "y": 21,
      "z": -18,
      "name": "Rock_Sandstone"
    },
    {
      "x": -14,
      "y": 22,
      "z": -18,
      "name": "Rock_Sandstone"
    },
    {
      "x": -14,
      "y": 23,
      "z": -18,
      "name": "Soil_Sand"
    },
    {
      "x": -14,
      "y": 16,
      "z": -17,
      "name": "Rock_Sandstone"
    },
    {
      "x": -14,
      "y": 17,
      "z": -17,
      "name": "Rock_Sandstone"
    },
    {
      "x": -14,
      "y": 18,
      "z": -17,
      "name": "Rock_Sandstone"
    },
    {
      "x": -14,
      "y": 19,
      "z": -17,
      "name": "Rock_Sandstone"
    },
    {
      "x": -14,
      "y": 20,
      "z": -17,
      "name": "Rock_Sandstone"
    },
    {
      "x": -14,
      "y": 21,
      "z": -17,
      "name": "Rock_Sandstone"
    },
    {
      "x": -14,
      "y": 22,
      "z": -17,
      "name": "Rock_Sandstone"
    },
    {
      "x": -14,
      "y": 23,
      "z": -17,
      "name": "Soil_Sand"
    },
    {
      "x": -14,
      "y": 24,
      "z": -17,
      "name": "Soil_Sand"
    },
    {
      "x": -14,
      "y": 16,
      "z": -16,
      "name": "Rock_Sandstone"
    },
    {
      "x": -14,
      "y": 17,
      "z": -16,
      "name": "Rock_Sandstone"
    },
    {
      "x": -14,
      "y": 18,
      "z": -16,
      "name": "Rock_Sandstone"
    },
    {
      "x": -14,
      "y": 19,
      "z": -16,
      "name": "Rock_Sandstone"
    },
    {
      "x": -14,
      "y": 20,
      "z": -16,
      "name": "Rock_Sandstone"
    },
    {
      "x": -14,
      "y": 21,
      "z": -16,
      "name": "Rock_Sandstone"
    },
    {
      "x": -14,
      "y": 22,
      "z": -16,
      "name": "Rock_Sandstone"
    },
    {
      "x": -14,
      "y": 23,
      "z": -16,
      "name": "Rock_Sandstone"
    },
    {
      "x": -14,
      "y": 24,
      "z": -16,
      "name": "Rock_Sandstone"
    },
    {
      "x": -14,
      "y": 25,
      "z": -16,
      "name": "Rock_Sandstone"
    },
    {
      "x": -14,
      "y": 16,
      "z": -15,
      "name": "Rock_Sandstone"
    },
    {
      "x": -14,
      "y": 17,
      "z": -15,
      "name": "Rock_Sandstone"
    },
    {
      "x": -14,
      "y": 18,
      "z": -15,
      "name": "Rock_Sandstone"
    },
    {
      "x": -14,
      "y": 19,
      "z": -15,
      "name": "Rock_Sandstone"
    },
    {
      "x": -14,
      "y": 20,
      "z": -15,
      "name": "Rock_Sandstone"
    },
    {
      "x": -14,
      "y": 21,
      "z": -15,
      "name": "Rock_Sandstone"
    },
    {
      "x": -14,
      "y": 22,
      "z": -15,
      "name": "Rock_Sandstone"
    },
    {
      "x": -14,
      "y": 23,
      "z": -15,
      "name": "Rock_Sandstone"
    },
    {
      "x": -14,
      "y": 24,
      "z": -15,
      "name": "Rock_Sandstone"
    },
    {
      "x": -14,
      "y": 25,
      "z": -15,
      "name": "Rock_Sandstone"
    },
    {
      "x": -14,
      "y": 26,
      "z": -15,
      "name": "Rock_Sandstone"
    },
    {
      "x": -14,
      "y": 17,
      "z": -14,
      "name": "Rock_Sandstone"
    },
    {
      "x": -14,
      "y": 18,
      "z": -14,
      "name": "Rock_Sandstone"
    },
    {
      "x": -14,
      "y": 19,
      "z": -14,
      "name": "Rock_Sandstone"
    },
    {
      "x": -14,
      "y": 20,
      "z": -14,
      "name": "Rock_Sandstone"
    },
    {
      "x": -14,
      "y": 21,
      "z": -14,
      "name": "Rock_Sandstone"
    },
    {
      "x": -14,
      "y": 22,
      "z": -14,
      "name": "Rock_Sandstone"
    },
    {
      "x": -14,
      "y": 23,
      "z": -14,
      "name": "Rock_Sandstone"
    },
    {
      "x": -14,
      "y": 24,
      "z": -14,
      "name": "Rock_Sandstone"
    },
    {
      "x": -14,
      "y": 25,
      "z": -14,
      "name": "Rock_Sandstone"
    },
    {
      "x": -14,
      "y": 26,
      "z": -14,
      "name": "Soil_Sand"
    },
    {
      "x": -14,
      "y": 27,
      "z": -14,
      "name": "Soil_Sand"
    },
    {
      "x": -14,
      "y": 16,
      "z": -13,
      "name": "Rock_Sandstone"
    },
    {
      "x": -14,
      "y": 17,
      "z": -13,
      "name": "Rock_Sandstone"
    },
    {
      "x": -14,
      "y": 18,
      "z": -13,
      "name": "Rock_Sandstone"
    },
    {
      "x": -14,
      "y": 19,
      "z": -13,
      "name": "Rock_Sandstone"
    },
    {
      "x": -14,
      "y": 20,
      "z": -13,
      "name": "Rock_Sandstone"
    },
    {
      "x": -14,
      "y": 21,
      "z": -13,
      "name": "Rock_Sandstone"
    },
    {
      "x": -14,
      "y": 22,
      "z": -13,
      "name": "Rock_Sandstone"
    },
    {
      "x": -14,
      "y": 23,
      "z": -13,
      "name": "Rock_Sandstone"
    },
    {
      "x": -14,
      "y": 24,
      "z": -13,
      "name": "Rock_Sandstone"
    },
    {
      "x": -14,
      "y": 25,
      "z": -13,
      "name": "Rock_Sandstone"
    },
    {
      "x": -14,
      "y": 26,
      "z": -13,
      "name": "Rock_Sandstone"
    },
    {
      "x": -14,
      "y": 27,
      "z": -13,
      "name": "Soil_Sand"
    },
    {
      "x": -14,
      "y": 28,
      "z": -13,
      "name": "Soil_Sand"
    },
    {
      "x": -14,
      "y": 29,
      "z": -13,
      "name": "Plant_Crop_Mushroom_Glowing_Orange"
    },
    {
      "x": -14,
      "y": 16,
      "z": -12,
      "name": "Rock_Sandstone"
    },
    {
      "x": -14,
      "y": 17,
      "z": -12,
      "name": "Rock_Sandstone"
    },
    {
      "x": -14,
      "y": 18,
      "z": -12,
      "name": "Rock_Sandstone"
    },
    {
      "x": -14,
      "y": 19,
      "z": -12,
      "name": "Rock_Sandstone"
    },
    {
      "x": -14,
      "y": 20,
      "z": -12,
      "name": "Rock_Sandstone"
    },
    {
      "x": -14,
      "y": 21,
      "z": -12,
      "name": "Rock_Sandstone"
    },
    {
      "x": -14,
      "y": 22,
      "z": -12,
      "name": "Rock_Sandstone"
    },
    {
      "x": -14,
      "y": 23,
      "z": -12,
      "name": "Rock_Sandstone"
    },
    {
      "x": -14,
      "y": 24,
      "z": -12,
      "name": "Rock_Sandstone"
    },
    {
      "x": -14,
      "y": 25,
      "z": -12,
      "name": "Rock_Sandstone"
    },
    {
      "x": -14,
      "y": 26,
      "z": -12,
      "name": "Rock_Sandstone"
    },
    {
      "x": -14,
      "y": 27,
      "z": -12,
      "name": "Rock_Sandstone"
    },
    {
      "x": -14,
      "y": 28,
      "z": -12,
      "name": "Rock_Sandstone"
    },
    {
      "x": -14,
      "y": 29,
      "z": -12,
      "name": "Soil_Gravel_Sand"
    },
    {
      "x": -14,
      "y": 30,
      "z": -12,
      "name": "Soil_Gravel_Sand"
    },
    {
      "x": -14,
      "y": 16,
      "z": -11,
      "name": "Rock_Sandstone"
    },
    {
      "x": -14,
      "y": 17,
      "z": -11,
      "name": "Rock_Sandstone"
    },
    {
      "x": -14,
      "y": 18,
