{
  "version": 8,
  "blockIdVersion": 11,
  "anchorX": 0,
  "anchorY": 0,
  "anchorZ": 0,
  "blocks": [
    {
      "x": -15,
      "y": 29,
      "z": 1,
      "name": "Plant_Crop_Mushroom_Shelve_Yellow"
    },
    {
      "x": -15,
      "y": 29,
      "z": 3,
      "name": "Plant_Crop_Mushroom_Shelve_Yellow"
    },
    {
      "x": -15,
      "y": 29,
      "z": 4,
      "name": "Rock_Sandstone"
    },
    {
      "x": -15,
      "y": 29,
      "z": 5,
      "name": "Soil_Sand"
    },
    {
      "x": -15,
      "y": 30,
      "z": 5,
      "name": "Soil_Gravel_Sand"
    },
    {
      "x": -14,
      "y": 29,
      "z": 1,
      "name": "Rock_Sandstone"
    },
    {
      "x": -14,
      "y": 30,
      "z": 1,
      "name": "Rubble_Sandstone_Medium"
    },
    {
      "x": -14,
      "y": 27,
      "z": 2,
      "name": "Rock_Sandstone"
    },
    {
      "x": -14,
      "y": 28,
      "z": 2,
      "name": "Rock_Sandstone"
    },
    {
      "x": -14,
      "y": 29,
      "z": 2,
      "name": "Rock_Sandstone"
    },
    {
      "x": -14,
      "y": 30,
      "z": 2,
      "name": "Rock_Sandstone"
    },
    {
      "x": -14,
      "y": 31,
      "z": 2,
      "name": "Rubble_Sandstone"
    },
    {
      "x": -14,
      "y": 26,
      "z": 3,
      "name": "Rock_Sandstone"
    },
    {
      "x": -14,
      "y": 27,
      "z": 3,
      "name": "Rock_Sandstone"
    },
    {
      "x": -14,
      "y": 28,
      "z": 3,
      "name": "Ore_Gold_Sandstone"
    },
    {
      "x": -14,
      "y": 29,
      "z": 3,
      "name": "Rock_Sandstone"
    },
    {
      "x": -14,
      "y": 30,
      "z": 3,
      "name": "Rock_Sandstone"
    },
    {
      "x": -14,
      "y": 25,
      "z": 4,
      "name": "Rock_Sandstone"
    },
    {
      "x": -14,
      "y": 26,
      "z": 4,
      "name": "Rock_Sandstone"
    },
    {
      "x": -14,
      "y": 27,
      "z": 4,
      "name": "Rock_Sandstone"
    },
    {
      "x": -14,
      "y": 28,
      "z": 4,
      "name": "Rock_Sandstone"
    },
    {
      "x": -14,
      "y": 29,
      "z": 4,
      "name": "Soil_Sand"
    },
    {
      "x": -14,
      "y": 30,
      "z": 4,
      "name": "Soil_Sand"
    },
    {
      "x": -14,
      "y": 26,
      "z": 5,
      "name": "Rock_Sandstone"
    },
    {
      "x": -14,
      "y": 27,
      "z": 5,
      "name": "Rock_Sandstone"
    },
    {
      "x": -14,
      "y": 28,
      "z": 5,
      "name": "Rock_Sandstone"
    },
    {
      "x": -14,
      "y": 29,
      "z": 5,
      "name": "Rock_Sandstone"
    },
    {
      "x": -14,
      "y": 30,
      "z": 5,
      "name": "Soil_Sand"
    },
    {
      "x": -14,
      "y": 27,
      "z": 6,
      "name": "Rock_Sandstone"
    },
    {
      "x": -14,
      "y": 28,
      "z": 6,
      "name": "Rock_Sandstone"
    },
    {
      "x": -14,
      "y": 29,
      "z": 6,
      "name": "Soil_Sand"
    },
    {
      "x": -14,
      "y": 30,
      "z": 6,
      "name": "Soil_Sand"
    },
    {
      "x": -14,
      "y": 29,
      "z": 7,
      "name": "Soil_Sand"
    },
    {
      "x": -14,
      "y": 30,
      "z": 7,
      "name": "Soil_Sand"
    },
    {
      "x": -14,
      "y": 26,
      "z": 9,
      "name": "Plant_Crop_Mushroom_Shelve_Yellow"
    },
    {
      "x": -14,
      "y": 27,
      "z": 9,
      "name": "Plant_Crop_Mushroom_Shelve_Yellow"
    },
    {
      "x": -14,
      "y": 26,
      "z": 11,
      "name": "Soil_Sand"
    },
    {
      "x": -14,
      "y": 27,
      "z": 11,
      "name": "Plant_Crop_Mushroom_Glowing_Red"
    },
    {
      "x": -14,
      "y": 23,
      "z": 12,
      "name": "Rock_Sandstone"
    },
    {
      "x": -14,
      "y": 24,
      "z": 12,
      "name": "Rock_Sandstone"
    },
    {
      "x": -14,
      "y": 25,
      "z": 12,
      "name": "Soil_Sand"
    },
    {
      "x": -14,
      "y": 26,
      "z": 12,
      "name": "Soil_Sand"
    },
    {
      "x": -14,
      "y": 23,
      "z": 13,
      "name": "Rock_Sandstone"
    },
    {
      "x": -14,
      "y": 24,
      "z": 13,
      "name": "Rock_Sandstone"
    },
    {
      "x": -14,
      "y": 25,
      "z": 13,
      "name": "Rock_Sandstone"
    },
    {
      "x": -14,
      "y": 26,
      "z": 13,
      "name": "Rock_Sandstone"
    },
    {
      "x": -14,
      "y": 23,
      "z": 14,
      "name": "Rock_Sandstone"
    },
    {
      "x": -14,
      "y": 24,
      "z": 14,
      "name": "Rock_Sandstone"
    },
    {
      "x": -14,
      "y": 25,
      "z": 14,
      "name": "Soil_Sand"
    },
    {
      "x": -14,
      "y": 26,
      "z": 14,
      "name": "Soil_Sand"
    },
    {
      "x": -14,
      "y": 26,
      "z": 15,
      "name": "Rock_Sandstone"
    },
    {
      "x": -13,
      "y": 29,
      "z": 0,
      "name": "Rock_Sandstone"
    },
    {
      "x": -13,
      "y": 26,
      "z": 1,
      "name": "Rock_Sandstone"
    },
    {
      "x": -13,
      "y": 27,
      "z": 1,
      "name": "Rock_Sandstone"
    },
    {
      "x": -13,
      "y": 28,
      "z": 1,
      "name": "Rock_Sandstone"
    },
    {
      "x": -13,
      "y": 29,
      "z": 1,
      "name": "Rock_Sandstone"
    },
    {
      "x": -13,
      "y": 30,
      "z": 1,
      "name": "Rock_Sandstone"
    },
    {
      "x": -13,
      "y": 25,
      "z": 2,
      "name": "Rock_Sandstone"
    },
    {
      "x": -13,
      "y": 26,
      "z": 2,
      "name": "Rock_Sandstone"
    },
    {
      "x": -13,
      "y": 27,
      "z": 2,
      "name": "Rock_Sandstone"
    },
    {
      "x": -13,
      "y": 28,
      "z": 2,
      "name": "Rock_Sandstone"
    },
    {
      "x": -13,
      "y": 29,
      "z": 2,
      "name": "Rock_Sandstone"
    },
    {
      "x": -13,
      "y": 30,
      "z": 2,
      "name": "Rock_Sandstone"
    },
    {
      "x": -13,
      "y": 31,
      "z": 2,
      "name": "Rock_Sandstone"
    },
    {
      "x": -13,
      "y": 32,
      "z": 2,
      "name": "Rubble_Sandstone_Medium"
    },
    {
      "x": -13,
      "y": 24,
      "z": 3,
      "name": "Rock_Sandstone"
    },
    {
      "x": -13,
      "y": 25,
      "z": 3,
      "name": "Rock_Sandstone"
    },
    {
      "x": -13,
      "y": 26,
      "z": 3,
      "name": "Rock_Sandstone"
    },
    {
      "x": -13,
      "y": 27,
      "z": 3,
      "name": "Rock_Sandstone"
    },
    {
      "x": -13,
      "y": 28,
      "z": 3,
      "name": "Ore_Gold_Sandstone"
    },
    {
      "x": -13,
      "y": 29,
      "z": 3,
      "name": "Rock_Sandstone"
    },
    {
      "x": -13,
      "y": 30,
      "z": 3,
      "name": "Rock_Sandstone"
    },
    {
      "x": -13,
      "y": 31,
      "z": 3,
      "name": "Rock_Sandstone"
    },
    {
      "x": -13,
      "y": 32,
      "z": 3,
      "name": "Rubble_Sandstone"
    },
    {
      "x": -13,
      "y": 24,
      "z": 4,
      "name": "Rock_Sandstone"
    },
    {
      "x": -13,
      "y": 25,
      "z": 4,
      "name": "Rock_Sandstone"
    },
    {
      "x": -13,
      "y": 26,
      "z": 4,
      "name": "Rock_Sandstone"
    },
    {
      "x": -13,
      "y": 27,
      "z": 4,
      "name": "Rock_Sandstone"
    },
    {
      "x": -13,
      "y": 28,
      "z": 4,
      "name": "Rock_Sandstone"
    },
    {
      "x": -13,
      "y": 29,
      "z": 4,
      "name": "Rock_Sandstone"
    },
    {
      "x": -13,
      "y": 30,
      "z": 4,
      "name": "Rock_Sandstone"
    },
    {
      "x": -13,
      "y": 31,
      "z": 4,
      "name": "Rock_Sandstone"
    },
    {
      "x": -13,
      "y": 32,
      "z": 4,
      "name": "Rubble_Sandstone_Medium"
    },
    {
      "x": -13,
      "y": 35,
      "z": 4,
      "name": "Wood_Ash_Branch_Corner",
      "rotation": 3
    },
    {
      "x": -13,
      "y": 36,
      "z": 4,
      "name": "Wood_Ash_Branch_Corner",
      "rotation": 8
    },
    {
      "x": -13,
      "y": 24,
      "z": 5,
      "name": "Rock_Sandstone"
    },
    {
      "x": -13,
      "y": 25,
      "z": 5,
      "name": "Rock_Sandstone"
    },
    {
      "x": -13,
      "y": 26,
      "z": 5,
      "name": "Rock_Sandstone"
    },
    {
      "x": -13,
      "y": 27,
      "z": 5,
      "name": "Rock_Sandstone"
    },
    {
      "x": -13,
      "y": 28,
      "z": 5,
      "name": "Rock_Sandstone"
    },
    {
      "x": -13,
      "y": 29,
      "z": 5,
      "name": "Rock_Sandstone"
    },
    {
      "x": -13,
      "y": 30,
      "z": 5,
      "name": "Rock_Sandstone"
    },
    {
      "x": -13,
      "y": 31,
      "z": 5,
      "name": "Soil_Sand"
    },
    {
      "x": -13,
      "y": 36,
      "z": 5,
      "name": "Wood_Ash_Branch_Corner"
    },
    {
      "x": -13,
      "y": 25,
      "z": 6,
      "name": "Rock_Sandstone"
    },
    {
      "x": -13,
      "y": 26,
      "z": 6,
      "name": "Rock_Sandstone"
    },
    {
      "x": -13,
      "y": 27,
      "z": 6,
      "name": "Rock_Sandstone"
    },
    {
      "x": -13,
      "y": 28,
      "z": 6,
      "name": "Rock_Sandstone"
    },
    {
      "x": -13,
      "y": 29,
      "z": 6,
      "name": "Soil_Sand"
    },
    {
      "x": -13,
      "y": 30,
      "z": 6,
      "name": "Soil_Sand"
    },
    {
      "x": -13,
      "y": 24,
      "z": 7,
      "name": "Rock_Sandstone"
    },
    {
      "x": -13,
      "y": 25,
      "z": 7,
      "name": "Rock_Sandstone"
    },
    {
      "x": -13,
      "y": 26,
      "z": 7,
      "name": "Rock_Sandstone"
    },
    {
      "x": -13,
      "y": 27,
      "z": 7,
      "name": "Rock_Sandstone"
    },
    {
      "x": -13,
      "y": 28,
      "z": 7,
      "name": "Rock_Sandstone"
    },
    {
      "x": -13,
      "y": 29,
      "z": 7,
      "name": "Soil_Sand"
    },
    {
      "x": -13,
      "y": 30,
      "z": 7,
      "name": "Soil_Sand"
    },
    {
      "x": -13,
      "y": 24,
      "z": 8,
      "name": "Rock_Sandstone"
    },
    {
      "x": -13,
      "y": 25,
      "z": 8,
      "name": "Rock_Sandstone"
    },
    {
      "x": -13,
      "y": 26,
      "z": 8,
      "name": "Rock_Sandstone"
    },
    {
      "x": -13,
      "y": 27,
      "z": 8,
      "name": "Rock_Sandstone"
    },
    {
      "x": -13,
      "y": 28,
      "z": 8,
      "name": "Plant_Moss_Cave_Yellow"
    },
    {
      "x": -13,
      "y": 29,
      "z": 8,
      "name": "Rock_Sandstone"
    },
    {
      "x": -13,
      "y": 30,
      "z": 8,
      "name": "Soil_Sand"
    },
    {
      "x": -13,
      "y": 24,
      "z": 9,
      "name": "Rock_Sandstone"
    },
    {
      "x": -13,
      "y": 25,
      "z": 9,
      "name": "Soil_Sand"
    },
    {
      "x": -13,
      "y": 26,
      "z": 9,
      "name": "Soil_Gravel_Sand"
    },
    {
      "x": -13,
      "y": 27,
      "z": 9,
      "name": "Soil_Gravel_Sand"
    },
    {
      "x": -13,
      "y": 23,
      "z": 10,
      "name": "Rock_Sandstone"
    },
    {
      "x": -13,
      "y": 24,
      "z": 10,
      "name": "Rock_Sandstone"
    },
    {
      "x": -13,
      "y": 25,
      "z": 10,
      "name": "Rock_Sandstone"
    },
    {
      "x": -13,
      "y": 26,
      "z": 10,
      "name": "Rock_Sandstone"
    },
    {
      "x": -13,
      "y": 27,
      "z": 10,
      "name": "Rock_Sandstone"
    },
    {
      "x": -13,
      "y": 21,
      "z": 11,
      "name": "Rock_Sandstone"
    },
    {
      "x": -13,
      "y": 22,
      "z": 11,
      "name": "Rock_Sandstone"
    },
    {
      "x": -13,
      "y": 23,
      "z": 11,
      "name": "Rock_Sandstone"
    },
    {
      "x": -13,
      "y": 24,
      "z": 11,
      "name": "Rock_Sandstone"
    },
    {
      "x": -13,
      "y": 25,
      "z": 11,
      "name": "Soil_Sand"
    },
    {
      "x": -13,
      "y": 26,
      "z": 11,
      "name": "Soil_Sand"
    },
    {
      "x": -13,
      "y": 27,
      "z": 11,
      "name": "Plant_Crop_Mushroom_Glowing_Orange"
    },
    {
      "x": -13,
      "y": 20,
      "z": 12,
      "name": "Rock_Sandstone"
    },
    {
      "x": -13,
      "y": 21,
      "z": 12,
      "name": "Rock_Sandstone"
    },
    {
      "x": -13,
      "y": 22,
      "z": 12,
      "name": "Rock_Sandstone"
    },
    {
      "x": -13,
      "y": 23,
      "z": 12,
      "name": "Rock_Sandstone"
    },
    {
      "x": -13,
      "y": 24,
      "z": 12,
      "name": "Rock_Sandstone"
    },
    {
      "x": -13,
      "y": 25,
      "z": 12,
      "name": "Soil_Sand"
    },
    {
      "x": -13,
      "y": 26,
      "z": 12,
      "name": "Soil_Gravel_Sand"
    },
    {
      "x": -13,
      "y": 19,
      "z": 13,
      "name": "Rock_Sandstone"
    },
    {
      "x": -13,
      "y": 20,
      "z": 13,
      "name": "Rock_Sandstone"
    },
    {
      "x": -13,
      "y": 21,
      "z": 13,
      "name": "Rock_Sandstone"
    },
    {
      "x": -13,
      "y": 22,
      "z": 13,
      "name": "Rock_Sandstone"
    },
    {
      "x": -13,
      "y": 23,
      "z": 13,
      "name": "Rock_Sandstone"
    },
    {
      "x": -13,
      "y": 24,
      "z": 13,
      "name": "Rock_Sandstone"
    },
    {
      "x": -13,
      "y": 25,
      "z": 13,
      "name": "Soil_Sand"
    },
    {
      "x": -13,
      "y": 26,
      "z": 13,
      "name": "Soil_Sand"
    },
    {
      "x": -13,
      "y": 20,
      "z": 14,
      "name": "Rock_Sandstone"
    },
    {
      "x": -13,
      "y": 21,
      "z": 14,
      "name": "Rock_Sandstone"
    },
    {
      "x": -13,
      "y": 22,
      "z": 14,
      "name": "Rock_Sandstone"
    },
    {
      "x": -13,
      "y": 23,
      "z": 14,
      "name": "Rock_Sandstone"
    },
    {
      "x": -13,
      "y": 24,
      "z": 14,
      "name": "Rock_Sandstone"
    },
    {
      "x": -13,
      "y": 25,
      "z": 14,
      "name": "Rock_Sandstone"
    },
    {
      "x": -13,
      "y": 26,
      "z": 14,
      "name": "Soil_Sand"
    },
    {
      "x": -13,
      "y": 21,
      "z": 15,
      "name": "Rock_Sandstone"
    },
    {
      "x": -13,
      "y": 22,
      "z": 15,
      "name": "Rock_Sandstone"
    },
    {
      "x": -13,
      "y": 23,
      "z": 15,
      "name": "Rock_Sandstone"
    },
    {
      "x": -13,
      "y": 24,
      "z": 15,
      "name": "Rock_Sandstone"
    },
    {
      "x": -13,
      "y": 25,
      "z": 15,
      "name": "Soil_Sand"
    },
    {
      "x": -13,
      "y": 26,
      "z": 15,
      "name": "Soil_Sand"
    },
    {
      "x": -13,
      "y": 23,
      "z": 16,
      "name": "Rock_Sandstone"
    },
    {
      "x": -13,
      "y": 24,
      "z": 16,
      "name": "Rock_Sandstone"
    },
    {
      "x": -13,
      "y": 25,
      "z": 16,
      "name": "Soil_Sand"
    },
    {
      "x": -13,
      "y": 26,
      "z": 16,
      "name": "Soil_Sand"
    },
    {
      "x": -12,
      "y": 27,
      "z": 0,
      "name": "Rock_Sandstone"
    },
    {
      "x": -12,
      "y": 28,
      "z": 0,
      "name": "Rock_Sandstone"
    },
    {
      "x": -12,
      "y": 29,
      "z": 0,
      "name": "Rock_Sandstone"
    },
    {
      "x": -12,
      "y": 30,
      "z": 0,
      "name": "Rubble_Sandstone_Medium"
    },
    {
      "x": -12,
      "y": 25,
      "z": 1,
      "name": "Rock_Sandstone"
    },
    {
      "x": -12,
      "y": 26,
      "z": 1,
      "name": "Rock_Sandstone"
    },
    {
      "x": -12,
      "y": 27,
      "z": 1,
      "name": "Rock_Sandstone"
    },
    {
      "x": -12,
      "y": 28,
      "z": 1,
      "name": "Rock_Sandstone"
    },
    {
      "x": -12,
      "y": 29,
      "z": 1,
      "name": "Rock_Sandstone"
    },
    {
      "x": -12,
      "y": 30,
      "z": 1,
      "name": "Rock_Sandstone"
    },
    {
      "x": -12,
      "y": 31,
      "z": 1,
      "name": "Rock_Sandstone"
    },
    {
      "x": -12,
      "y": 32,
      "z": 1,
      "name": "Rubble_Sandstone_Medium"
    },
    {
      "x": -12,
      "y": 24,
      "z": 2,
      "name": "Rock_Sandstone"
    },
    {
      "x": -12,
      "y": 25,
      "z": 2,
      "name": "Rock_Sandstone"
    },
    {
      "x": -12,
      "y": 26,
      "z": 2,
      "name": "Rock_Sandstone"
    },
    {
      "x": -12,
      "y": 27,
      "z": 2,
      "name": "Rock_Sandstone"
    },
    {
      "x": -12,
      "y": 28,
      "z": 2,
      "name": "Rock_Sandstone"
    },
    {
      "x": -12,
      "y": 29,
      "z": 2,
      "name": "Rock_Sandstone"
    },
    {
      "x": -12,
      "y": 30,
      "z": 2,
      "name": "Rock_Sandstone"
    },
    {
      "x": -12,
      "y": 31,
      "z": 2,
      "name": "Rock_Sandstone"
    },
    {
      "x": -12,
      "y": 32,
      "z": 2,
      "name": "Rubble_Sandstone"
    },
    {
      "x": -12,
      "y": 23,
      "z": 3,
      "name": "Rock_Sandstone"
    },
    {
      "x": -12,
      "y": 24,
      "z": 3,
      "name": "Rock_Sandstone"
    },
    {
      "x": -12,
      "y": 25,
      "z": 3,
      "name": "Rock_Sandstone"
    },
    {
      "x": -12,
      "y": 26,
      "z": 3,
      "name": "Rock_Sandstone"
    },
    {
      "x": -12,
      "y": 27,
      "z": 3,
      "name": "Rock_Sandstone"
    },
    {
      "x": -12,
      "y": 28,
      "z": 3,
      "name": "Ore_Gold_Sandstone"
    },
    {
      "x": -12,
      "y": 29,
      "z": 3,
      "name": "Rock_Sandstone"
    },
    {
      "x": -12,
      "y": 30,
      "z": 3,
      "name": "Rock_Sandstone"
    },
    {
      "x": -12,
      "y": 31,
      "z": 3,
      "name": "Rock_Sandstone"
    },
    {
      "x": -12,
      "y": 23,
      "z": 4,
      "name": "Rock_Sandstone"
    },
    {
      "x": -12,
      "y": 24,
      "z": 4,
      "name": "Rock_Sandstone"
    },
    {
      "x": -12,
      "y": 25,
      "z": 4,
      "name": "Rock_Sandstone"
    },
    {
      "x": -12,
      "y": 26,
      "z": 4,
      "name": "Rock_Sandstone"
    },
    {
      "x": -12,
      "y": 27,
      "z": 4,
      "name": "Rock_Sandstone"
    },
    {
      "x": -12,
      "y": 28,
      "z": 4,
      "name": "Rock_Sandstone"
    },
    {
      "x": -12,
      "y": 29,
      "z": 4,
      "name": "Rock_Sandstone"
    },
    {
      "x": -12,
      "y": 30,
      "z": 4,
      "name": "Rock_Sandstone"
    },
    {
      "x": -12,
      "y": 31,
      "z": 4,
      "name": "Soil_Gravel_Sand"
    },
    {
      "x": -12,
      "y": 32,
      "z": 4,
      "name": "Soil_Sand"
    },
    {
      "x": -12,
      "y": 35,
      "z": 4,
      "name": "Wood_Ash_Branch_Long",
      "rotation": 5
    },
    {
      "x": -12,
      "y": 23,
      "z": 5,
      "name": "Rock_Sandstone"
    },
    {
      "x": -12,
      "y": 24,
      "z": 5,
      "name": "Rock_Sandstone"
    },
    {
      "x": -12,
      "y": 25,
      "z": 5,
      "name": "Rock_Sandstone"
    },
    {
      "x": -12,
      "y": 26,
      "z": 5,
      "name": "Rock_Sandstone"
    },
    {
      "x": -12,
      "y": 27,
      "z": 5,
      "name": "Rock_Sandstone"
    },
    {
      "x": -12,
      "y": 28,
      "z": 5,
      "name": "Rock_Sandstone"
    },
    {
      "x": -12,
      "y": 29,
      "z": 5,
      "name": "Rock_Sandstone"
    },
    {
      "x": -12,
      "y": 30,
      "z": 5,
      "name": "Soil_Sand"
    },
    {
      "x": -12,
      "y": 31,
      "z": 5,
      "name": "Soil_Sand"
    },
    {
      "x": -12,
      "y": 22,
      "z": 6,
      "name": "Rock_Sandstone"
    },
    {
      "x": -12,
      "y": 23,
      "z": 6,
      "name": "Rock_Sandstone"
    },
    {
      "x": -12,
      "y": 24,
      "z": 6,
      "name": "Rock_Sandstone"
    },
    {
      "x": -12,
      "y": 25,
      "z": 6,
      "name": "Rock_Sandstone"
    },
    {
      "x": -12,
      "y": 26,
      "z": 6,
      "name": "Rock_Sandstone"
    },
    {
      "x": -12,
      "y": 27,
      "z": 6,
      "name": "Rock_Sandstone"
    },
    {
      "x": -12,
      "y": 28,
      "z": 6,
      "name": "Rock_Sandstone"
    },
    {
      "x": -12,
      "y": 29,
      "z": 6,
      "name": "Soil_Sand"
    },
    {
      "x": -12,
      "y": 30,
      "z": 6,
      "name": "Soil_Sand"
    },
    {
      "x": -12,
      "y": 31,
      "z": 6,
      "name": "Soil_Gravel_Sand"
    },
    {
      "x": -12,
      "y": 21,
      "z": 7,
      "name": "Rock_Sandstone"
    },
    {
      "x": -12,
      "y": 22,
      "z": 7,
      "name": "Rock_Sandstone"
    },
    {
      "x": -12,
      "y": 23,
      "z": 7,
      "name": "Rock_Sandstone"
    },
    {
      "x": -12,
      "y": 24,
      "z": 7,
      "name": "Rock_Sandstone"
    },
    {
      "x": -12,
      "y": 25,
      "z": 7,
      "name": "Rock_Sandstone"
    },
    {
      "x": -12,
      "y": 26,
      "z": 7,
      "name": "Rock_Sandstone"
    },
    {
      "x": -12,
      "y": 27,
      "z": 7,
      "name": "Rock_Sandstone"
    },
    {
      "x": -12,
      "y": 28,
      "z": 7,
      "name": "Rock_Sandstone"
    },
    {
      "x": -12,
      "y": 29,
      "z": 7,
      "name": "Soil_Sand"
    },
    {
      "x": -12,
      "y": 30,
      "z": 7,
      "name": "Soil_Gravel_Sand"
    },
    {
      "x": -12,
      "y": 31,
      "z": 7,
      "name": "Soil_Sand"
    },
    {
      "x": -12,
      "y": 32,
      "z": 7,
      "name": "Plant_Crop_Mushroom_Glowing_Red"
    },
    {
      "x": -12,
      "y": 20,
      "z": 8,
      "name": "Rock_Sandstone"
    },
    {
      "x": -12,
      "y": 21,
      "z": 8,
      "name": "Rock_Sandstone"
    },
    {
      "x": -12,
      "y": 22,
      "z": 8,
      "name": "Rock_Sandstone"
    },
    {
      "x": -12,
      "y": 23,
      "z": 8,
      "name": "Rock_Sandstone"
    },
    {
      "x": -12,
      "y": 24,
      "z": 8,
      "name": "Rock_Sandstone"
    },
    {
      "x": -12,
      "y": 25,
      "z": 8,
      "name": "Rock_Sandstone"
    },
    {
      "x": -12,
      "y": 26,
      "z": 8,
      "name": "Rock_Sandstone"
    },
    {
      "x": -12,
      "y": 27,
      "z": 8,
      "name": "Rock_Sandstone"
    },
    {
      "x": -12,
      "y": 28,
      "z": 8,
      "name": "Rock_Sandstone"
    },
    {
      "x": -12,
      "y": 29,
      "z": 8,
      "name": "Soil_Sand"
    },
    {
      "x": -12,
      "y": 30,
      "z": 8,
      "name": "Soil_Gravel_Sand"
    },
    {
      "x": -12,
      "y": 21,
      "z": 9,
      "name": "Rock_Sandstone"
    },
    {
      "x": -12,
      "y": 22,
      "z": 9,
      "name": "Rock_Sandstone"
    },
    {
      "x": -12,
      "y": 23,
      "z": 9,
      "name": "Rock_Sandstone"
    },
    {
      "x": -12,
      "y": 24,
      "z": 9,
      "name": "Rock_Sandstone"
    },
    {
      "x": -12,
      "y": 25,
      "z": 9,
      "name": "Rock_Sandstone"
    },
    {
      "x": -12,
      "y": 26,
      "z": 9,
      "name": "Soil_Gravel_Sand"
    },
    {
      "x": -12,
      "y": 27,
      "z": 9,
      "name": "Soil_Sand"
    },
    {
      "x": -12,
      "y": 20,
      "z": 10,
      "name": "Rock_Sandstone"
    },
    {
      "x": -12,
      "y": 21,
      "z": 10,
      "name": "Rock_Sandstone"
    },
    {
      "x": -12,
      "y": 22,
      "z": 10,
      "name": "Rock_Sandstone"
    },
    {
      "x": -12,
      "y": 23,
      "z": 10,
      "name": "Rock_Sandstone"
    },
    {
      "x": -12,
      "y": 24,
      "z": 10,
      "name": "Rock_Sandstone"
    },
    {
      "x": -12,
      "y": 25,
      "z": 10,
      "name": "Rock_Sandstone"
    },
    {
      "x": -12,
      "y": 26,
      "z": 10,
      "name": "Rock_Sandstone"
    },
    {
      "x": -12,
      "y": 27,
      "z": 10,
      "name": "Soil_Gravel_Sand"
    },
    {
      "x": -12,
      "y": 19,
      "z": 11,
      "name": "Rock_Sandstone"
    },
    {
      "x": -12,
      "y": 20,
      "z": 11,
      "name": "Rock_Sandstone"
    },
    {
      "x": -12,
      "y": 21,
      "z": 11,
      "name": "Rock_Sandstone"
    },
    {
      "x": -12,
      "y": 22,
      "z": 11,
      "name": "Rock_Sandstone"
    },
    {
      "x": -12,
      "y": 23,
      "z": 11,
      "name": "Rock_Sandstone"
    },
    {
      "x": -12,
      "y": 24,
      "z": 11,
      "name": "Rock_Sandstone"
    },
    {
      "x": -12,
      "y": 25,
      "z": 11,
      "name": "Rock_Sandstone"
    },
    {
      "x": -12,
      "y": 26,
      "z": 11,
      "name": "Soil_Gravel_Sand"
    },
    {
      "x": -12,
      "y": 27,
      "z": 11,
      "name": "Soil_Sand"
    },
    {
      "x": -12,
      "y": 17,
      "z": 12,
      "name": "Rock_Sandstone_Stalactite_Small",
      "rotation": 8
    },
    {
      "x": -12,
      "y": 18,
      "z": 12,
      "name": "Rock_Sandstone"
    },
    {
      "x": -12,
      "y": 19,
      "z": 12,
      "name": "Rock_Sandstone"
    },
    {
      "x": -12,
      "y": 20,
      "z": 12,
      "name": "Rock_Sandstone"
    },
    {
      "x": -12,
      "y": 21,
      "z": 12,
      "name": "Rock_Sandstone"
    },
    {
      "x": -12,
      "y": 22,
      "z": 12,
      "name": "Rock_Sandstone"
    },
    {
      "x": -12,
      "y": 23,
      "z": 12,
      "name": "Rock_Sandstone"
    },
    {
      "x": -12,
      "y": 24,
      "z": 12,
      "name": "Rock_Sandstone"
    },
    {
      "x": -12,
      "y": 25,
      "z": 12,
      "name": "Rock_Sandstone"
    },
    {
      "x": -12,
      "y": 26,
      "z": 12,
      "name": "Soil_Sand"
    },
    {
      "x": -12,
      "y": 18,
      "z": 13,
      "name": "Rock_Sandstone"
    },
    {
      "x": -12,
      "y": 19,
      "z": 13,
      "name": "Rock_Sandstone"
    },
    {
      "x": -12,
      "y": 20,
      "z": 13,
      "name": "Rock_Sandstone"
    },
    {
      "x": -12,
      "y": 21,
      "z": 13,
      "name": "Rock_Sandstone"
    },
    {
      "x": -12,
      "y": 22,
      "z": 13,
      "name": "Rock_Sandstone"
    },
    {
      "x": -12,
      "y": 23,
      "z": 13,
      "name": "Rock_Sandstone"
    },
    {
      "x": -12,
      "y": 24,
      "z": 13,
      "name": "Rock_Sandstone"
    },
    {
      "x": -12,
      "y": 25,
      "z": 13,
      "name": "Soil_Sand"
    },
    {
      "x": -12,
      "y": 26,
      "z": 13,
      "name": "Soil_Sand"
    },
    {
      "x": -12,
      "y": 18,
      "z": 14,
      "name": "Rock_Sandstone"
    },
    {
      "x": -12,
      "y": 19,
      "z": 14,
      "name": "Rock_Sandstone"
    },
    {
      "x": -12,
      "y": 20,
      "z": 14,
      "name": "Rock_Sandstone"
    },
    {
      "x": -12,
      "y": 21,
      "z": 14,
      "name": "Rock_Sandstone"
    },
    {
      "x": -12,
      "y": 22,
      "z": 14,
      "name": "Rock_Sandstone"
    },
    {
      "x": -12,
      "y": 23,
      "z": 14,
      "name": "Rock_Sandstone"
    },
    {
      "x": -12,
      "y": 24,
      "z": 14,
      "name": "Rock_Sandstone"
    },
    {
      "x": -12,
      "y": 25,
      "z": 14,
      "name": "Rock_Sandstone"
    },
    {
      "x": -12,
      "y": 26,
      "z": 14,
      "name": "Rock_Sandstone"
    },
    {
      "x": -12,
      "y": 19,
      "z": 15,
      "name": "Rock_Sandstone"
    },
    {
      "x": -12,
      "y": 20,
      "z": 15,
      "name": "Rock_Sandstone"
    },
    {
      "x": -12,
      "y": 21,
      "z": 15,
      "name": "Rock_Sandstone"
    },
    {
      "x": -12,
      "y": 22,
      "z": 15,
      "name": "Rock_Sandstone"
    },
    {
      "x": -12,
      "y": 23,
      "z": 15,
      "name": "Rock_Sandstone"
    },
    {
      "x": -12,
      "y": 24,
      "z": 15,
      "name": "Rock_Sandstone"
    },
    {
      "x": -12,
      "y": 25,
      "z": 15,
      "name": "Soil_Sand"
    },
    {
      "x": -12,
      "y": 26,
      "z": 15,
      "name": "Soil_Sand"
    },
    {
      "x": -12,
      "y": 20,
      "z": 16,
      "name": "Rock_Sandstone"
    },
    {
      "x": -12,
      "y": 21,
      "z": 16,
      "name": "Rock_Sandstone"
    },
    {
      "x": -12,
      "y": 22,
      "z": 16,
      "name": "Rock_Sandstone"
    },
    {
      "x": -12,
      "y": 23,
      "z": 16,
      "name": "Soil_Sand"
    },
    {
      "x": -12,
      "y": 24,
      "z": 16,
      "name": "Soil_Sand"
    },
    {
      "x": -12,
      "y": 25,
      "z": 16,
      "name": "Soil_Gravel_Sand"
    },
    {
      "x": -12,
      "y": 23,
      "z": 17,
      "name": "Rock_Sandstone"
    },
    {
      "x": -12,
      "y": 24,
      "z": 17,
      "name": "Rock_Sandstone"
    },
    {
      "x": -11,
      "y": 12,
      "z": -3,
      "name": "Plant_Crop_Mushroom_Shelve_Yellow"
    },
    {
      "x": -11,
      "y": 29,
      "z": -1,
      "name": "Rock_Sandstone"
    },
    {
      "x": -11,
      "y": 26,
      "z": 0,
      "name": "Rock_Sandstone"
    },
    {
      "x": -11,
      "y": 27,
      "z": 0,
      "name": "Rock_Sandstone"
    },
    {
      "x": -11,
      "y": 28,
      "z": 0,
      "name": "Rock_Sandstone"
    },
    {
      "x": -11,
      "y": 29,
      "z": 0,
      "name": "Rock_Sandstone"
    },
    {
      "x": -11,
      "y": 30,
      "z": 0,
      "name": "Rock_Sandstone"
    },
    {
      "x": -11,
      "y": 31,
      "z": 0,
      "name": "Rubble_Sandstone"
    },
    {
      "x": -11,
      "y": 24,
      "z": 1,
      "name": "Rock_Sandstone"
    },
    {
      "x": -11,
      "y": 25,
      "z": 1,
      "name": "Rock_Sandstone"
    },
    {
      "x": -11,
      "y": 26,
      "z": 1,
      "name": "Rock_Sandstone"
    },
    {
      "x": -11,
      "y": 27,
      "z": 1,
      "name": "Rock_Sandstone"
    },
    {
      "x": -11,
      "y": 28,
      "z": 1,
      "name": "Rock_Sandstone"
    },
    {
      "x": -11,
      "y": 29,
      "z": 1,
      "name": "Rock_Sandstone"
    },
    {
      "x": -11,
      "y": 30,
      "z": 1,
      "name": "Rock_Sandstone"
    },
    {
      "x": -11,
      "y": 31,
      "z": 1,
      "name": "Rock_Sandstone"
    },
    {
      "x": -11,
      "y": 23,
      "z": 2,
      "name": "Rock_Sandstone"
    },
    {
      "x": -11,
      "y": 24,
      "z": 2,
      "name": "Rock_Sandstone"
    },
    {
      "x": -11,
      "y": 25,
      "z": 2,
      "name": "Rock_Sandstone"
    },
    {
      "x": -11,
      "y": 26,
      "z": 2,
      "name": "Rock_Sandstone"
    },
    {
      "x": -11,
      "y": 27,
      "z": 2,
      "name": "Rock_Sandstone"
    },
    {
      "x": -11,
      "y": 28,
      "z": 2,
      "name": "Rock_Sandstone"
    },
    {
      "x": -11,
      "y": 29,
      "z": 2,
      "name": "Rock_Sandstone"
    },
    {
      "x": -11,
      "y": 30,
      "z": 2,
      "name": "Rock_Sandstone"
    },
    {
      "x": -11,
      "y": 31,
      "z": 2,
      "name": "Soil_Sand"
    },
    {
      "x": -11,
      "y": 22,
      "z": 3,
      "name": "Rock_Sandstone"
    },
    {
      "x": -11,
      "y": 23,
      "z": 3,
      "name": "Rock_Sandstone"
    },
    {
      "x": -11,
      "y": 24,
      "z": 3,
      "name": "Rock_Sandstone"
    },
    {
      "x": -11,
      "y": 25,
      "z": 3,
      "name": "Rock_Sandstone"
    },
    {
      "x": -11,
      "y": 26,
      "z": 3,
      "name": "Rock_Sandstone"
    },
    {
      "x": -11,
      "y": 27,
      "z": 3,
      "name": "Rock_Sandstone"
    },
    {
      "x": -11,
      "y": 28,
      "z": 3,
      "name": "Ore_Gold_Sandstone"
    },
    {
      "x": -11,
      "y": 29,
      "z": 3,
      "name": "Rock_Sandstone"
    },
    {
      "x": -11,
      "y": 30,
      "z": 3,
      "name": "Rock_Sandstone"
    },
    {
      "x": -11,
      "y": 31,
      "z": 3,
      "name": "Rock_Sandstone"
    },
    {
      "x": -11,
      "y": 32,
      "z": 3,
      "name": "Soil_Sand"
    },
    {
      "x": -11,
      "y": 22,
      "z": 4,
      "name": "Rock_Sandstone"
    },
    {
      "x": -11,
      "y": 23,
      "z": 4,
      "name": "Rock_Sandstone"
    },
    {
      "x": -11,
      "y": 24,
      "z": 4,
      "name": "Rock_Sandstone"
    },
    {
      "x": -11,
      "y": 25,
      "z": 4,
      "name": "Rock_Sandstone"
    },
    {
      "x": -11,
      "y": 26,
      "z": 4,
      "name": "Rock_Sandstone"
    },
    {
      "x": -11,
      "y": 27,
      "z": 4,
      "name": "Rock_Sandstone"
    },
    {
      "x": -11,
      "y": 28,
      "z": 4,
      "name": "Rock_Sandstone"
    },
    {
      "x": -11,
      "y": 29,
      "z": 4,
      "name": "Rock_Sandstone"
    },
    {
      "x": -11,
      "y": 30,
      "z": 4,
      "name": "Soil_Gravel_Sand"
    },
    {
      "x": -11,
      "y": 31,
      "z": 4,
      "name": "Soil_Sand"
    },
    {
      "x": -11,
      "y": 32,
      "z": 4,
      "name": "Soil_Sand"
    },
    {
      "x": -11,
      "y": 35,
      "z": 4,
      "name": "Wood_Ash_Trunk_Full",
      "rotation": 5
    },
    {
      "x": -11,
      "y": 36,
      "z": 4,
      "name": "Wood_Ash_Trunk_Full"
    },
    {
      "x": -11,
      "y": 37,
      "z": 4,
      "name": "Wood_Ash_Branch_Long"
    },
    {
      "x": -11,
      "y": 38,
      "z": 4,
      "name": "Wood_Ash_Branch_Corner",
      "rotation": 9
    },
    {
      "x": -11,
      "y": 21,
      "z": 5,
      "name": "Rock_Sandstone"
    },
    {
      "x": -11,
      "y": 22,
      "z": 5,
      "name": "Rock_Sandstone"
    },
    {
      "x": -11,
      "y": 23,
      "z": 5,
      "name": "Rock_Sandstone"
    },
    {
      "x": -11,
      "y": 24,
      "z": 5,
      "name": "Rock_Sandstone"
    },
    {
      "x": -11,
      "y": 25,
      "z": 5,
      "name": "Rock_Sandstone"
    },
    {
      "x": -11,
      "y": 26,
      "z": 5,
      "name": "Rock_Sandstone"
    },
    {
      "x": -11,
      "y": 27,
      "z": 5,
      "name": "Rock_Sandstone"
    },
    {
      "x": -11,
      "y": 28,
      "z": 5,
      "name": "Rock_Sandstone"
    },
    {
      "x": -11,
      "y": 29,
      "z": 5,
      "name": "Rock_Sandstone"
    },
    {
      "x": -11,
      "y": 30,
      "z": 5,
      "name": "Rock_Sandstone"
    },
    {
      "x": -11,
      "y": 31,
      "z": 5,
      "name": "Soil_Sand"
    },
    {
      "x": -11,
      "y": 32,
      "z": 5,
      "name": "Soil_Sand"
    },
    {
      "x": -11,
      "y": 20,
      "z": 6,
      "name": "Rock_Sandstone"
    },
    {
      "x": -11,
      "y": 21,
      "z": 6,
      "name": "Rock_Sandstone"
    },
    {
      "x": -11,
      "y": 22,
      "z": 6,
      "name": "Rock_Sandstone"
    },
    {
      "x": -11,
      "y": 23,
      "z": 6,
      "name": "Rock_Sandstone"
    },
    {
      "x": -11,
      "y": 24,
      "z": 6,
      "name": "Rock_Sandstone"
    },
    {
      "x": -11,
      "y": 25,
      "z": 6,
      "name": "Rock_Sandstone"
    },
    {
      "x": -11,
      "y": 26,
      "z": 6,
      "name": "Rock_Sandstone"
    },
    {
      "x": -11,
      "y": 27,
      "z": 6,
      "name": "Rock_Sandstone"
    },
    {
      "x": -11,
      "y": 28,
      "z": 6,
      "name": "Rock_Sandstone"
    },
    {
      "x": -11,
      "y": 29,
      "z": 6,
      "name": "Soil_Sand"
    },
    {
      "x": -11,
      "y": 30,
      "z": 6,
      "name": "Soil_Gravel_Sand"
    },
    {
      "x": -11,
      "y": 31,
      "z": 6,
      "name": "Soil_Sand"
    },
    {
      "x": -11,
      "y": 32,
      "z": 6,
      "name": "Plant_Crop_Mushroom_Glowing_Orange"
    },
    {
      "x": -11,
      "y": 19,
      "z": 7,
      "name": "Rock_Sandstone"
    },
    {
      "x": -11,
      "y": 20,
      "z": 7,
      "name": "Rock_Sandstone"
    },
    {
      "x": -11,
      "y": 21,
      "z": 7,
      "name": "Rock_Sandstone"
    },
    {
      "x": -11,
      "y": 22,
      "z": 7,
      "name": "Rock_Sandstone"
    },
    {
      "x": -11,
      "y": 23,
      "z": 7,
      "name": "Rock_Sandstone"
    },
    {
      "x": -11,
      "y": 24,
      "z": 7,
      "name": "Rock_Sandstone"
    },
    {
      "x": -11,
      "y": 25,
      "z": 7,
      "name": "Rock_Sandstone"
    },
    {
      "x": -11,
      "y": 26,
      "z": 7,
      "name": "Rock_Sandstone"
    },
    {
      "x": -11,
      "y": 27,
      "z": 7,
      "name": "Rock_Sandstone"
    },
    {
      "x": -11,
      "y": 28,
      "z": 7,
      "name": "Rock_Sandstone"
    },
    {
      "x": -11,
      "y": 29,
      "z": 7,
      "name": "Rock_Sandstone"
    },
    {
      "x": -11,
      "y": 30,
      "z": 7,
      "name": "Soil_Sand"
    },
    {
      "x": -11,
      "y": 31,
      "z": 7,
      "name": "Soil_Sand"
    },
    {
      "x": -11,
      "y": 19,
      "z": 8,
      "name": "Rock_Sandstone"
    },
    {
      "x": -11,
      "y": 20,
      "z": 8,
      "name": "Rock_Sandstone"
    },
    {
      "x": -11,
      "y": 21,
      "z": 8,
      "name": "Rock_Sandstone"
    },
    {
      "x": -11,
      "y": 22,
      "z": 8,
      "name": "Rock_Sandstone"
    },
    {
      "x": -11,
      "y": 23,
      "z": 8,
      "name": "Rock_Sandstone"
    },
    {
      "x": -11,
      "y": 24,
      "z": 8,
      "name": "Rock_Sandstone"
    },
    {
      "x": -11,
      "y": 25,
      "z": 8,
      "name": "Rock_Sandstone"
    },
    {
      "x": -11,
      "y": 26,
      "z": 8,
      "name": "Rock_Sandstone"
    },
    {
      "x": -11,
      "y": 27,
      "z": 8,
      "name": "Rock_Sandstone"
    },
    {
      "x": -11,
      "y": 28,
      "z": 8,
      "name": "Rock_Sandstone"
    },
    {
      "x": -11,
      "y": 29,
      "z": 8,
      "name": "Soil_Gravel_Sand"
    },
    {
      "x": -11,
      "y": 30,
      "z": 8,
      "name": "Soil_Sand"
    },
    {
      "x": -11,
      "y": 31,
      "z": 8,
      "name": "Soil_Sand"
    },
    {
      "x": -11,
      "y": 32,
      "z": 8,
      "name": "Plant_Flower_Flax_Orange"
    },
    {
      "x": -11,
      "y": 19,
      "z": 9,
      "name": "Rock_Sandstone"
    },
    {
      "x": -11,
      "y": 20,
      "z": 9,
      "name": "Rock_Sandstone"
    },
    {
      "x": -11,
      "y": 21,
      "z": 9,
      "name": "Rock_Sandstone"
    },
    {
      "x": -11,
      "y": 22,
      "z": 9,
      "name": "Rock_Sandstone"
    },
    {
      "x": -11,
      "y": 23,
      "z": 9,
      "name": "Rock_Sandstone"
    },
    {
      "x": -11,
      "y": 24,
      "z": 9,
      "name": "Rock_Sandstone"
    },
    {
      "x": -11,
      "y": 25,
      "z": 9,
      "name": "Rock_Sandstone"
    },
    {
      "x": -11,
      "y": 26,
      "z": 9,
      "name": "Rock_Sandstone"
    },
    {
      "x": -11,
      "y": 27,
      "z": 9,
      "name": "Rock_Sandstone"
    },
    {
      "x": -11,
      "y": 28,
      "z": 9,
      "name": "Rock_Sandstone"
    },
    {
      "x": -11,
      "y": 29,
      "z": 9,
      "name": "Soil_Sand"
    },
    {
      "x": -11,
      "y": 30,
      "z": 9,
      "name": "Soil_Sand"
    },
    {
      "x": -11,
      "y": 19,
      "z": 10,
      "name": "Rock_Sandstone"
    },
    {
      "x": -11,
      "y": 20,
      "z": 10,
      "name": "Rock_Sandstone"
    },
    {
      "x": -11,
      "y": 21,
      "z": 10,
      "name": "Rock_Sandstone"
    },
    {
      "x": -11,
      "y": 22,
      "z": 10,
      "name": "Rock_Sandstone"
    },
    {
      "x": -11,
      "y": 23,
      "z": 10,
      "name": "Rock_Sandstone"
    },
    {
      "x": -11,
      "y": 24,
      "z": 10,
      "name": "Rock_Sandstone"
    },
    {
      "x": -11,
      "y": 25,
      "z": 10,
      "name": "Rock_Sandstone"
    },
    {
      "x": -11,
      "y": 26,
      "z": 10,
      "name": "Rock_Sandstone"
    },
    {
      "x": -11,
      "y": 27,
      "z": 10,
      "name": "Soil_Gravel_Sand"
    },
    {
      "x": -11,
      "y": 28,
      "z": 10,
      "name": "Soil_Sand"
    },
    {
      "x": -11,
      "y": 17,
      "z": 11,
      "name": "Plant_Roots_Cave"
    },
    {
      "x": -11,
      "y": 18,
      "z": 11,
      "name": "Rock_Sandstone"
    },
    {
      "x": -11,
      "y": 19,
      "z": 11,
      "name": "Rock_Sandstone"
    },
    {
      "x": -11,
      "y": 20,
      "z": 11,
      "name": "Rock_Sandstone"
    },
    {
      "x": -11,
      "y": 21,
      "z": 11,
      "name": "Rock_Sandstone"
    },
    {
      "x": -11,
      "y": 22,
      "z": 11,
      "name": "Rock_Sandstone"
    },
    {
      "x": -11,
      "y": 23,
      "z": 11,
      "name": "Rock_Sandstone"
    },
    {
      "x": -11,
      "y": 24,
      "z": 11,
      "name": "Rock_Sandstone"
    },
    {
      "x": -11,
      "y": 25,
      "z": 11,
      "name": "Rock_Sandstone"
    },
    {
      "x": -11,
      "y": 26,
      "z": 11,
      "name": "Rock_Sandstone"
    },
    {
      "x": -11,
      "y": 27,
      "z": 11,
      "name": "Rock_Sandstone"
    },
    {
      "x": -11,
      "y": 17,
      "z": 12,
      "name": "Rock_Sandstone"
    },
    {
      "x": -11,
      "y": 18,
      "z": 12,
      "name": "Rock_Sandstone"
    },
    {
      "x": -11,
      "y": 19,
      "z": 12,
      "name": "Rock_Sandstone"
    },
    {
      "x": -11,
      "y": 20,
      "z": 12,
      "name": "Rock_Sandstone"
    },
    {
      "x": -11,
      "y": 21,
      "z": 12,
      "name": "Rock_Sandstone"
    },
    {
      "x": -11,
      "y": 22,
      "z": 12,
      "name": "Rock_Sandstone"
    },
    {
      "x": -11,
      "y": 23,
      "z": 12,
      "name": "Rock_Sandstone"
    },
    {
      "x": -11,
      "y": 24,
      "z": 12,
      "name": "Rock_Sandstone"
    },
    {
      "x": -11,
      "y": 25,
      "z": 12,
      "name": "Rock_Sandstone"
    },
    {
      "x": -11,
      "y": 26,
      "z": 12,
      "name": "Rock_Sandstone"
    },
    {
      "x": -11,
      "y": 27,
      "z": 12,
      "name": "Rock_Sandstone"
    },
    {
      "x": -11,
      "y": 28,
      "z": 12,
      "name": "Rubble_Sandstone"
    },
    {
      "x": -11,
      "y": 17,
      "z": 13,
      "name": "Rock_Sandstone"
    },
    {
      "x": -11,
      "y": 18,
      "z": 13,
      "name": "Rock_Sandstone"
    },
    {
      "x": -11,
      "y": 19,
      "z": 13,
      "name": "Rock_Sandstone"
    },
    {
      "x": -11,
      "y": 20,
      "z": 13,
      "name": "Rock_Sandstone"
    },
    {
      "x": -11,
      "y": 21,
      "z": 13,
      "name": "Rock_Sandstone"
    },
    {
      "x": -11,
      "y": 22,
      "z": 13,
      "name": "Rock_Sandstone"
    },
    {
      "x": -11,
      "y": 23,
      "z": 13,
      "name": "Rock_Sandstone"
    },
    {
      "x": -11,
      "y": 24,
      "z": 13,
      "name": "Rock_Sandstone"
    },
    {
      "x": -11,
      "y": 25,
      "z": 13,
      "name": "Rock_Sandstone"
    },
    {
      "x": -11,
      "y": 26,
      "z": 13,
      "name": "Soil_Sand"
    },
    {
      "x": -11,
      "y": 17,
      "z": 14,
      "name": "Rock_Sandstone"
    },
    {
      "x": -11,
      "y": 18,
      "z": 14,
      "name": "Rock_Sandstone"
    },
    {
      "x": -11,
      "y": 19,
      "z": 14,
      "name": "Rock_Sandstone"
    },
    {
      "x": -11,
      "y": 20,
      "z": 14,
      "name": "Rock_Sandstone"
    },
    {
      "x": -11,
      "y": 21,
      "z": 14,
      "name": "Rock_Sandstone"
    },
    {
      "x": -11,
      "y": 22,
      "z": 14,
      "name": "Rock_Sandstone"
    },
    {
      "x": -11,
      "y": 23,
      "z": 14,
      "name": "Rock_Sandstone"
    },
    {
      "x": -11,
      "y": 24,
      "z": 14,
      "name": "Rock_Sandstone"
    },
    {
      "x": -11,
      "y": 25,
      "z": 14,
      "name": "Soil_Sand"
    },
    {
      "x": -11,
      "y": 26,
      "z": 14,
      "name": "Soil_Sand"
    },
    {
      "x": -11,
      "y": 18,
      "z": 15,
      "name": "Rock_Sandstone"
    },
    {
      "x": -11,
      "y": 19,
      "z": 15,
      "name": "Rock_Sandstone"
    },
    {
      "x": -11,
      "y": 20,
      "z": 15,
      "name": "Rock_Sandstone"
    },
    {
      "x": -11,
      "y": 21,
      "z": 15,
      "name": "Rock_Sandstone"
    },
    {
      "x": -11,
      "y": 22,
      "z": 15,
      "name": "Rock_Sandstone"
    },
    {
      "x": -11,
      "y": 23,
      "z": 15,
      "name": "Rock_Sandstone"
    },
    {
      "x": -11,
      "y": 24,
      "z": 15,
      "name": "Rock_Sandstone"
    },
    {
      "x": -11,
      "y": 25,
      "z": 15,
      "name": "Soil_Sand"
    },
    {
      "x": -11,
      "y": 26,
      "z": 15,
      "name": "Soil_Sand"
    },
    {
      "x": -11,
      "y": 19,
      "z": 16,
      "name": "Rock_Sandstone"
    },
    {
      "x": -11,
      "y": 20,
      "z": 16,
      "name": "Rock_Sandstone"
    },
    {
      "x": -11,
      "y": 21,
      "z": 16,
      "name": "Rock_Sandstone"
    },
    {
      "x": -11,
      "y": 22,
      "z": 16,
      "name": "Rock_Sandstone"
    },
    {
      "x": -11,
      "y": 23,
      "z": 16,
      "name": "Soil_Sand"
    },
    {
      "x": -11,
      "y": 24,
      "z": 16,
      "name": "Soil_Gravel_Sand"
    },
    {
      "x": -11,
      "y": 25,
      "z": 16,
      "name": "Soil_Sand"
    },
    {
      "x": -11,
      "y": 21,
      "z": 17,
      "name": "Rock_Sandstone"
    },
    {
      "x": -11,
      "y": 22,
      "z": 17,
      "name": "Rock_Sandstone"
    },
    {
      "x": -11,
      "y": 23,
      "z": 17,
      "name": "Soil_Gravel_Sand"
    },
    {
      "x": -11,
      "y": 24,
      "z": 17,
      "name": "Soil_Sand"
    },
    {
      "x": -10,
      "y": 37,
      "z": -7,
      "name": "Rock_Sandstone"
    },
    {
      "x": -10,
      "y": 11,
      "z": -5,
      "name": "Plant_Crop_Mushroom_Shelve_Yellow"
    },
    {
      "x": -10,
      "y": 10,
      "z": -4,
      "name": "Rock_Sandstone"
    },
    {
      "x": -10,
      "y": 11,
      "z": -4,
      "name": "Rock_Sandstone"
    },
    {
      "x": -10,
      "y": 12,
      "z": -4,
      "name": "Soil_Gravel_Sand"
    },
    {
      "x": -10,
      "y": 13,
      "z": -4,
      "name": "Soil_Gravel_Sand"
    },
    {
      "x": -10,
      "y": 10,
      "z": -3,
      "name": "Rock_Sandstone"
    },
    {
      "x": -10,
      "y": 11,
      "z": -3,
      "name": "Rock_Sandstone"
    },
    {
      "x": -10,
      "y": 12,
      "z": -3,
      "name": "Soil_Sand"
    },
    {
      "x": -10,
      "y": 13,
      "z": -3,
      "name": "Soil_Sand"
    },
    {
      "x": -10,
      "y": 10,
      "z": -2,
      "name": "Rock_Sandstone"
    },
    {
      "x": -10,
      "y": 11,
      "z": -2,
      "name": "Rock_Sandstone"
    },
    {
      "x": -10,
      "y": 12,
      "z": -2,
      "name": "Soil_Sand"
    },
    {
      "x": -10,
      "y": 13,
      "z": -2,
      "name": "Soil_Sand"
    },
    {
      "x": -10,
      "y": 12,
      "z": -1,
      "name": "Plant_Crop_Mushroom_Shelve_Yellow"
    },
    {
      "x": -10,
      "y": 29,
      "z": -1,
      "name": "Rock_Sandstone"
    },
    {
      "x": -10,
      "y": 30,
      "z": -1,
      "name": "Plant_Crop_Mushroom_Shelve_Yellow"
    },
    {
      "x": -10,
      "y": 12,
      "z": 0,
      "name": "Plant_Crop_Mushroom_Shelve_Yellow"
    },
    {
      "x": -10,
      "y": 25,
      "z": 0,
      "name": "Rock_Sandstone"
    },
    {
      "x": -10,
      "y": 26,
      "z": 0,
      "name": "Rock_Sandstone"
    },
    {
      "x": -10,
      "y": 27,
      "z": 0,
      "name": "Rock_Sandstone"
    },
    {
      "x": -10,
      "y": 28,
      "z": 0,
      "name": "Rock_Sandstone"
    },
    {
      "x": -10,
      "y": 29,
      "z": 0,
      "name": "Rock_Sandstone"
    },
    {
      "x": -10,
      "y": 30,
      "z": 0,
      "name": "Rock_Sandstone"
    },
    {
      "x": -10,
      "y": 31,
      "z": 0,
      "name": "Rock_Sandstone"
    },
    {
      "x": -10,
      "y": 24,
      "z": 1,
      "name": "Rock_Sandstone"
    },
    {
      "x": -10,
      "y": 25,
      "z": 1,
      "name": "Rock_Sandstone"
    },
    {
      "x": -10,
      "y": 26,
      "z": 1,
      "name": "Rock_Sandstone"
    },
    {
      "x": -10,
      "y": 27,
      "z": 1,
      "name": "Rock_Sandstone"
    },
    {
      "x": -10,
      "y": 28,
      "z": 1,
      "name": "Rock_Sandstone"
    },
    {
      "x": -10,
      "y": 29,
      "z": 1,
      "name": "Rock_Sandstone"
    },
    {
      "x": -10,
      "y": 30,
      "z": 1,
      "name": "Rock_Sandstone"
    },
    {
      "x": -10,
      "y": 31,
      "z": 1,
      "name": "Soil_Sand"
    },
    {
      "x": -10,
      "y": 21,
      "z": 2,
      "name": "Rock_Sandstone_Stalactite_Large",
      "filler": 31744,
      "rotation": 8
    },
    {
      "x": -10,
      "y": 22,
      "z": 2,
      "name": "Rock_Sandstone_Stalactite_Large",
      "rotation": 8
    },
    {
      "x": -10,
      "y": 23,
      "z": 2,
      "name": "Rock_Sandstone"
    },
    {
      "x": -10,
      "y": 24,
      "z": 2,
      "name": "Rock_Sandstone"
    },
    {
      "x": -10,
      "y": 25,
      "z": 2,
      "name": "Rock_Sandstone"
    },
    {
      "x": -10,
      "y": 26,
      "z": 2,
      "name": "Rock_Sandstone"
    },
    {
      "x": -10,
      "y": 27,
      "z": 2,
      "name": "Rock_Sandstone"
    },
    {
      "x": -10,
      "y": 28,
      "z": 2,
      "name": "Rock_Sandstone"
    },
    {
      "x": -10,
      "y": 29,
      "z": 2,
      "name": "Rock_Sandstone"
    },
    {
      "x": -10,
      "y": 30,
      "z": 2,
      "name": "Soil_Sand"
    },
    {
      "x": -10,
      "y": 31,
      "z": 2,
      "name": "Soil_Sand"
    },
    {
      "x": -10,
      "y": 32,
      "z": 2,
      "name": "Soil_Sand"
    },
    {
      "x": -10,
      "y": 22,
      "z": 3,
      "name": "Rock_Sandstone"
    },
    {
      "x": -10,
      "y": 23,
      "z": 3,
      "name": "Rock_Sandstone"
    },
    {
      "x": -10,
      "y": 24,
      "z": 3,
      "name": "Rock_Sandstone"
    },
    {
      "x": -10,
      "y": 25,
      "z": 3,
      "name": "Rock_Sandstone"
    },
    {
      "x": -10,
      "y": 26,
      "z": 3,
      "name": "Rock_Sandstone"
    },
    {
      "x": -10,
      "y": 27,
      "z": 3,
      "name": "Rock_Sandstone"
    },
    {
      "x": -10,
      "y": 28,
      "z": 3,
      "name": "Ore_Gold_Sandstone"
    },
    {
      "x": -10,
      "y": 29,
      "z": 3,
      "name": "Rock_Sandstone"
    },
    {
      "x": -10,
      "y": 30,
      "z": 3,
      "name": "Rock_Sandstone"
    },
    {
      "x": -10,
      "y": 31,
      "z": 3,
      "name": "Soil_Sand"
    },
    {
      "x": -10,
      "y": 32,
      "z": 3,
      "name": "Soil_Sand"
    },
    {
      "x": -10,
      "y": 35,
      "z": 3,
      "name": "Wood_Ash_Branch_Corner",
      "rotation": 9
    },
    {
      "x": -10,
      "y": 22,
      "z": 4,
      "name": "Rock_Sandstone"
    },
    {
      "x": -10,
      "y": 23,
      "z": 4,
      "name": "Rock_Sandstone"
    },
    {
      "x": -10,
      "y": 24,
      "z": 4,
      "name": "Rock_Sandstone"
    },
    {
      "x": -10,
      "y": 25,
      "z": 4,
      "name": "Rock_Sandstone"
    },
    {
      "x": -10,
      "y": 26,
      "z": 4,
      "name": "Rock_Sandstone"
    },
    {
      "x": -10,
      "y": 27,
      "z": 4,
      "name": "Rock_Sandstone"
    },
    {
      "x": -10,
      "y": 28,
      "z": 4,
      "name": "Rock_Sandstone"
    },
    {
      "x": -10,
      "y": 29,
      "z": 4,
      "name": "Rock_Sandstone"
    },
    {
      "x": -10,
      "y": 30,
      "z": 4,
      "name": "Soil_Sand"
    },
    {
      "x": -10,
      "y": 31,
      "z": 4,
      "name": "Soil_Sand"
    },
    {
      "x": -10,
      "y": 32,
      "z": 4,
      "name": "Soil_Sand"
    },
    {
      "x": -10,
      "y": 35,
      "z": 4,
      "name": "Wood_Ash_Trunk",
      "rotation": 5
    },
    {
      "x": -10,
      "y": 38,
      "z": 4,
      "name": "Wood_Ash_Branch_Long",
      "rotation": 5
    },
    {
      "x": -10,
      "y": 20,
      "z": 5,
      "name": "Rock_Sandstone"
    },
    {
      "x": -10,
      "y": 21,
      "z": 5,
      "name": "Rubble_Sandstone"
    },
    {
      "x": -10,
      "y": 23,
      "z": 5,
      "name": "Rock_Sandstone"
    },
    {
      "x": -10,
      "y": 24,
      "z": 5,
      "name": "Rock_Sandstone"
    },
    {
      "x": -10,
      "y": 25,
      "z": 5,
      "name": "Rock_Sandstone"
    },
    {
      "x": -10,
      "y": 26,
      "z": 5,
      "name": "Rock_Sandstone"
    },
    {
      "x": -10,
      "y": 27,
      "z": 5,
      "name": "Rock_Sandstone"
    },
    {
      "x": -10,
      "y": 28,
      "z": 5,
      "name": "Rock_Sandstone"
    },
    {
      "x": -10,
      "y": 29,
      "z": 5,
      "name": "Rock_Sandstone"
    },
    {
      "x": -10,
      "y": 30,
      "z": 5,
      "name": "Soil_Sand"
    },
    {
      "x": -10,
      "y": 31,
      "z": 5,
      "name": "Soil_Sand"
    },
    {
      "x": -10,
      "y": 32,
      "z": 5,
      "name": "Soil_Gravel_Sand"
    },
    {
      "x": -10,
      "y": 33,
      "z": 5,
      "name": "Plant_Crop_Stamina2"
    },
    {
      "x": -10,
      "y": 19,
      "z": 6,
      "name": "Rock_Sandstone"
    },
    {
      "x": -10,
      "y": 20,
      "z": 6,
      "name": "Rock_Sandstone"
    },
    {
      "x": -10,
      "y": 21,
      "z": 6,
      "name": "Rock_Sandstone_Stalactite_Large"
    },
    {
      "x": -10,
      "y": 22,
      "z": 6,
      "name": "Rock_Sandstone_Stalactite_Large",
      "filler": 1024
    },
    {
      "x": -10,
      "y": 23,
      "z": 6,
      "name": "Rock_Sandstone"
    },
    {
      "x": -10,
      "y": 24,
      "z": 6,
      "name": "Rock_Sandstone"
    },
    {
      "x": -10,
      "y": 25,
      "z": 6,
      "name": "Rock_Sandstone"
    },
    {
      "x": -10,
      "y": 26,
      "z": 6,
      "name": "Rock_Sandstone"
    },
    {
      "x": -10,
      "y": 27,
      "z": 6,
      "name": "Rock_Sandstone"
    },
    {
      "x": -10,
      "y": 28,
      "z": 6,
      "name": "Rock_Sandstone"
    },
    {
      "x": -10,
      "y": 29,
      "z": 6,
      "name": "Rock_Sandstone"
    },
    {
      "x": -10,
      "y": 30,
      "z": 6,
      "name": "Rock_Sandstone"
    },
    {
      "x": -10,
      "y": 31,
      "z": 6,
      "name": "Soil_Sand"
    },
    {
      "x": -10,
      "y": 32,
      "z": 6,
      "name": "Soil_Gravel_Sand"
    },
    {
      "x": -10,
      "y": 18,
      "z": 7,
      "name": "Rock_Sandstone"
    },
    {
      "x": -10,
      "y": 19,
      "z": 7,
      "name": "Rock_Sandstone"
    },
    {
      "x": -10,
      "y": 20,
      "z": 7,
      "name": "Rock_Sandstone"
    },
    {
      "x": -10,
      "y": 21,
      "z": 7,
      "name": "Rock_Sandstone"
    },
    {
      "x": -10,
      "y": 22,
      "z": 7,
      "name": "Rock_Sandstone"
    },
    {
      "x": -10,
      "y": 24,
      "z": 7,
      "name": "Rock_Sandstone"
    },
    {
      "x": -10,
      "y": 25,
      "z": 7,
      "name": "Rock_Sandstone"
    },
    {
      "x": -10,
      "y": 26,
      "z": 7,
      "name": "Rock_Sandstone"
    },
    {
      "x": -10,
      "y": 27,
      "z": 7,
      "name": "Rock_Sandstone"
    },
    {
      "x": -10,
      "y": 28,
      "z": 7,
      "name": "Rock_Sandstone"
    },
    {
      "x": -10,
      "y": 29,
      "z": 7,
      "name": "Rock_Sandstone"
    },
    {
      "x": -10,
      "y": 30,
      "z": 7,
      "name": "Rock_Sandstone"
    },
    {
      "x": -10,
      "y": 31,
      "z": 7,
      "name": "Soil_Sand"
    },
    {
      "x": -10,
      "y": 32,
      "z": 7,
      "name": "Plant_Bush_Arid"
    },
    {
      "x": -10,
      "y": 17,
      "z": 8,
      "name": "Plant_Moss_Cave_Yellow"
    },
    {
      "x": -10,
      "y": 18,
      "z": 8,
      "name": "Rock_Sandstone"
    },
    {
      "x": -10,
      "y": 19,
      "z": 8,
      "name": "Rock_Sandstone"
    },
    {
      "x": -10,
      "y": 20,
      "z": 8,
      "name": "Rock_Sandstone"
    },
    {
      "x": -10,
      "y": 21,
      "z": 8,
      "name": "Rock_Sandstone"
    },
    {
      "x": -10,
      "y": 22,
      "z": 8,
      "name": "Rock_Sandstone"
    },
    {
      "x": -10,
      "y": 23,
      "z": 8,
      "name": "Rock_Sandstone"
    },
    {
      "x": -10,
      "y": 24,
      "z": 8,
      "name": "Rock_Sandstone"
    },
    {
      "x": -10,
      "y": 25,
      "z": 8,
      "name": "Rock_Sandstone"
    },
    {
      "x": -10,
      "y": 26,
      "z": 8,
      "name": "Rock_Sandstone"
    },
    {
      "x": -10,
      "y": 27,
      "z": 8,
      "name": "Rock_Sandstone"
    },
    {
      "x": -10,
      "y": 28,
      "z": 8,
      "name": "Rock_Sandstone"
    },
    {
      "x": -10,
      "y": 29,
      "z": 8,
      "name": "Rock_Sandstone"
    },
    {
      "x": -10,
      "y": 30,
      "z": 8,
      "name": "Rock_Sandstone"
    },
    {
      "x": -10,
      "y": 31,
      "z": 8,
      "name": "Soil_Gravel_Sand"
    },
    {
      "x": -10,
      "y": 32,
      "z": 8,
      "name": "Plant_Crop_Stamina2"
    },
    {
      "x": -10,
      "y": 18,
      "z": 9,
      "name": "Rock_Sandstone"
    },
    {
      "x": -10,
      "y": 19,
      "z": 9,
      "name": "Rock_Sandstone"
    },
    {
      "x": -10,
      "y": 20,
      "z": 9,
      "name": "Rock_Sandstone"
    },
    {
      "x": -10,
      "y": 21,
      "z": 9,
      "name": "Rock_Sandstone"
    },
    {
      "x": -10,
      "y": 22,
      "z": 9,
      "name": "Rock_Sandstone"
    },
    {
      "x": -10,
      "y": 23,
      "z": 9,
      "name": "Rock_Sandstone"
    },
    {
      "x": -10,
      "y": 24,
      "z": 9,
      "name": "Rock_Sandstone"
    },
    {
      "x": -10,
      "y": 25,
      "z": 9,
      "name": "Rock_Sandstone"
    },
    {
      "x": -10,
      "y": 26,
      "z": 9,
      "name": "Rock_Sandstone"
    },
    {
      "x": -10,
      "y": 27,
      "z": 9,
      "name": "Rock_Sandstone"
    },
    {
      "x": -10,
      "y": 28,
      "z": 9,
      "name": "Rock_Sandstone"
    },
    {
      "x": -10,
      "y": 29,
      "z": 9,
      "name": "Rock_Sandstone"
    },
    {
      "x": -10,
      "y": 30,
      "z": 9,
      "name": "Rock_Sandstone"
    },
    {
      "x": -10,
      "y": 31,
      "z": 9,
      "name": "Rubble_Sandstone"
    },
    {
      "x": -10,
      "y": 18,
      "z": 10,
      "name": "Rock_Sandstone"
    },
    {
      "x": -10,
      "y": 19,
      "z": 10,
      "name": "Rock_Sandstone"
    },
    {
      "x": -10,
      "y": 20,
      "z": 10,
      "name": "Rock_Sandstone"
    },
    {
      "x": -10,
      "y": 21,
      "z": 10,
      "name": "Rock_Sandstone"
    },
    {
      "x": -10,
      "y": 22,
      "z": 10,
      "name": "Rock_Sandstone"
    },
    {
      "x": -10,
      "y": 23,
      "z": 10,
      "name": "Rock_Sandstone"
    },
    {
      "x": -10,
      "y": 24,
      "z": 10,
      "name": "Rock_Sandstone"
    },
    {
      "x": -10,
      "y": 25,
      "z": 10,
      "name": "Rock_Sandstone"
    },
    {
      "x": -10,
      "y": 26,
      "z": 10,
      "name": "Rock_Sandstone"
    },
    {
      "x": -10,
      "y": 27,
      "z": 10,
      "name": "Rock_Sandstone"
    },
    {
      "x": -10,
      "y": 28,
      "z": 10,
      "name": "Rock_Sandstone"
    },
    {
      "x": -10,
      "y": 29,
      "z": 10,
      "name": "Rock_Sandstone"
    },
    {
      "x": -10,
      "y": 30,
      "z": 10,
      "name": "Rubble_Sandstone_Medium"
    },
    {
      "x": -10,
      "y": 17,
      "z": 11,
      "name": "Rock_Sandstone"
    },
    {
      "x": -10,
      "y": 18,
      "z": 11,
      "name": "Rock_Sandstone"
    },
    {
      "x": -10,
      "y": 19,
      "z": 11,
      "name": "Rock_Sandstone"
    },
    {
      "x": -10,
      "y": 20,
      "z": 11,
      "name": "Rock_Sandstone"
    },
    {
      "x": -10,
      "y": 21,
      "z": 11,
      "name": "Rock_Sandstone"
    },
    {
      "x": -10,
      "y": 22,
      "z": 11,
      "name": "Rock_Sandstone"
    },
    {
      "x": -10,
      "y": 23,
      "z": 11,
      "name": "Rock_Sandstone"
    },
    {
      "x": -10,
      "y": 24,
      "z": 11,
      "name": "Rock_Sandstone"
    },
    {
      "x": -10,
      "y": 25,
      "z": 11,
      "name": "Rock_Sandstone"
    },
    {
      "x": -10,
      "y": 26,
      "z": 11,
      "name": "Rock_Sandstone"
    },
    {
      "x": -10,
      "y": 27,
      "z": 11,
      "name": "Rock_Sandstone"
    },
    {
      "x": -10,
      "y": 28,
      "z": 11,
      "name": "Rock_Sandstone"
    },
    {
      "x": -10,
      "y": 16,
      "z": 12,
      "name": "Rock_Sandstone"
    },
    {
      "x": -10,
      "y": 17,
      "z": 12,
      "name": "Rock_Sandstone"
    },
    {
      "x": -10,
      "y": 18,
      "z": 12,
      "name": "Rock_Sandstone"
    },
    {
      "x": -10,
      "y": 19,
      "z": 12,
      "name": "Rock_Sandstone"
    },
    {
      "x": -10,
      "y": 20,
      "z": 12,
      "name": "Rock_Sandstone"
    },
    {
      "x": -10,
      "y": 21,
      "z": 12,
      "name": "Rock_Sandstone"
    },
    {
      "x": -10,
      "y": 22,
      "z": 12,
      "name": "Rock_Sandstone"
    },
    {
      "x": -10,
      "y": 23,
      "z": 12,
      "name": "Rock_Sandstone"
    },
    {
      "x": -10,
      "y": 24,
      "z": 12,
      "name": "Rock_Sandstone"
    },
    {
      "x": -10,
      "y": 25,
      "z": 12,
      "name": "Rock_Sandstone"
    },
    {
      "x": -10,
      "y": 26,
      "z": 12,
      "name": "Rock_Sandstone"
    },
    {
      "x": -10,
      "y": 27,
      "z": 12,
      "name": "Rock_Sandstone"
    },
    {
      "x": -10,
      "y": 15,
      "z": 13,
      "name": "Plant_Roots_Cave"
    },
    {
      "x": -10,
      "y": 16,
      "z": 13,
      "name": "Rock_Sandstone"
    },
    {
      "x": -10,
      "y": 17,
      "z": 13,
      "name": "Rock_Sandstone"
    },
    {
      "x": -10,
      "y": 18,
      "z": 13,
      "name": "Rock_Sandstone"
    },
    {
      "x": -10,
      "y": 19,
      "z": 13,
      "name": "Rock_Sandstone"
    },
    {
      "x": -10,
      "y": 20,
      "z": 13,
      "name": "Rock_Sandstone"
    },
    {
      "x": -10,
      "y": 21,
      "z": 13,
      "name": "Rock_Sandstone"
    },
    {
      "x": -10,
      "y": 22,
      "z": 13,
      "name": "Rock_Sandstone"
    },
    {
      "x": -10,
      "y": 23,
      "z": 13,
      "name": "Rock_Sandstone"
    },
    {
      "x": -10,
      "y": 24,
      "z": 13,
      "name": "Rock_Sandstone"
    },
    {
      "x": -10,
      "y": 25,
      "z": 13,
      "name": "Rock_Sandstone"
    },
    {
      "x": -10,
      "y": 26,
      "z": 13,
      "name": "Rock_Sandstone"
    },
    {
      "x": -10,
      "y": 27,
      "z": 13,
      "name": "Rock_Sandstone"
    },
    {
      "x": -10,
      "y": 16,
      "z": 14,
      "name": "Rock_Sandstone"
    },
    {
      "x": -10,
      "y": 17,
      "z": 14,
      "name": "Rock_Sandstone"
    },
    {
      "x": -10,
      "y": 18,
      "z": 14,
      "name": "Rock_Sandstone"
    },
    {
      "x": -10,
      "y": 19,
      "z": 14,
      "name": "Rock_Sandstone"
    },
    {
      "x": -10,
      "y": 20,
      "z": 14,
      "name": "Rock_Sandstone"
    },
    {
      "x": -10,
      "y": 21,
      "z": 14,
      "name": "Rock_Sandstone"
    },
    {
      "x": -10,
      "y": 22,
      "z": 14,
      "name": "Rock_Sandstone"
    },
    {
      "x": -10,
      "y": 23,
      "z": 14,
      "name": "Rock_Sandstone"
    },
    {
      "x": -10,
      "y": 24,
      "z": 14,
      "name": "Rock_Sandstone"
    },
    {
      "x": -10,
      "y": 25,
      "z": 14,
      "name": "Soil_Gravel_Sand"
    },
    {
      "x": -10,
      "y": 26,
      "z": 14,
      "name": "Soil_Gravel_Sand"
    },
    {
      "x": -10,
      "y": 16,
      "z": 15,
      "name": "Rock_Sandstone_Stalactite_Small",
      "rotation": 8
    },
    {
      "x": -10,
      "y": 17,
      "z": 15,
      "name": "Rock_Sandstone"
    },
    {
      "x": -10,
      "y": 18,
      "z": 15,
      "name": "Rock_Sandstone"
    },
    {
      "x": -10,
      "y": 19,
      "z": 15,
      "name": "Rock_Sandstone"
    },
    {
      "x": -10,
      "y": 20,
      "z": 15,
      "name": "Rock_Sandstone"
    },
    {
      "x": -10,
      "y": 21,
      "z": 15,
      "name": "Rock_Sandstone"
    },
    {
      "x": -10,
      "y": 22,
      "z": 15,
      "name": "Rock_Sandstone"
    },
    {
      "x": -10,
      "y": 23,
      "z": 15,
      "name": "Rock_Sandstone"
    },
    {
      "x": -10,
      "y": 24,
      "z": 15,
      "name": "Soil_Sand"
    },
    {
      "x": -10,
      "y": 25,
      "z": 15,
      "name": "Soil_Gravel_Sand"
    },
    {
      "x": -10,
      "y": 26,
      "z": 15,
      "name": "Soil_Sand"
    },
    {
      "x": -10,
      "y": 27,
      "z": 15,
      "name": "Plant_Crop_Mushroom_Glowing_Red"
    },
    {
      "x": -10,
      "y": 18,
      "z": 16,
      "name": "Rock_Sandstone"
    },
    {
      "x": -10,
      "y": 19,
      "z": 16,
      "name": "Rock_Sandstone"
    },
    {
      "x": -10,
      "y": 20,
      "z": 16,
      "name": "Rock_Sandstone"
    },
    {
      "x": -10,
      "y": 21,
      "z": 16,
      "name": "Rock_Sandstone"
    },
    {
      "x": -10,
      "y": 22,
      "z": 16,
      "name": "Rock_Sandstone"
    },
    {
      "x": -10,
      "y": 23,
      "z": 16,
      "name": "Soil_Sand"
    },
    {
      "x": -10,
      "y": 24,
      "z": 16,
      "name": "Soil_Sand"
    },
    {
      "x": -10,
      "y": 25,
      "z": 16,
      "name": "Soil_Sand"
    },
    {
      "x": -10,
      "y": 20,
      "z": 17,
      "name": "Rock_Sandstone"
    },
    {
      "x": -10,
      "y": 21,
      "z": 17,
      "name": "Rock_Sandstone"
    },
    {
      "x": -10,
      "y": 22,
      "z": 17,
      "name": "Rock_Sandstone"
    },
    {
      "x": -10,
      "y": 23,
      "z": 17,
      "name": "Rock_Sandstone"
    },
    {
      "x": -10,
      "y": 24,
      "z": 17,
      "name": "Soil_Gravel_Sand"
    },
    {
      "x": -10,
      "y": 25,
      "z": 17,
      "name": "Soil_Sand"
    },
    {
      "x": -9,
      "y": 35,
      "z": -10,
      "name": "Rock_Sandstone"
    },
    {
      "x": -9,
      "y": 34,
      "z": -9,
      "name": "Rock_Sandstone"
    },
    {
      "x": -9,
      "y": 35,
      "z": -9,
      "name": "Rock_Sandstone"
    },
    {
      "x": -9,
      "y": 36,
      "z": -9,
      "name": "Rock_Sandstone"
    },
    {
      "x": -9,
      "y": 37,
      "z": -9,
      "name": "Rock_Sandstone"
    },
    {
      "x": -9,
      "y": 33,
      "z": -8,
      "name": "Rock_Sandstone"
    },
    {
      "x": -9,
      "y": 34,
      "z": -8,
      "name": "Rock_Sandstone"
    },
    {
      "x": -9,
      "y": 35,
      "z": -8,
      "name": "Rock_Sandstone"
    },
    {
      "x": -9,
      "y": 36,
      "z": -8,
      "name": "Rock_Sandstone"
    },
    {
      "x": -9,
      "y": 37,
      "z": -8,
      "name": "Rock_Sandstone"
    },
    {
      "x": -9,
      "y": 38,
      "z": -8,
      "name": "Rock_Sandstone"
    },
    {
      "x": -9,
      "y": 34,
      "z": -7,
      "name": "Rock_Sandstone"
    },
    {
      "x": -9,
      "y": 35,
      "z": -7,
      "name": "Rock_Sandstone"
    },
    {
      "x": -9,
      "y": 36,
      "z": -7,
      "name": "Rock_Sandstone"
    },
    {
      "x": -9,
      "y": 37,
      "z": -7,
      "name": "Rock_Sandstone"
    },
    {
      "x": -9,
      "y": 38,
      "z": -7,
      "name": "Rubble_Sandstone_Medium"
    },
    {
      "x": -9,
      "y": 8,
      "z": -6,
      "name": "Rock_Sandstone_Stalactite_Large",
      "filler": 31744,
      "rotation": 8
    },
    {
      "x": -9,
      "y": 9,
      "z": -6,
      "name": "Rock_Sandstone_Stalactite_Large",
      "rotation": 8
    },
    {
      "x": -9,
      "y": 10,
      "z": -6,
      "name": "Rock_Sandstone"
    },
    {
      "x": -9,
      "y": 11,
      "z": -6,
      "name": "Rock_Sandstone"
    },
    {
      "x": -9,
      "y": 12,
      "z": -6,
      "name": "Rock_Sandstone"
    },
    {
      "x": -9,
      "y": 13,
      "z": -6,
      "name": "Soil_Sand"
    },
    {
      "x": -9,
      "y": 35,
      "z": -6,
      "name": "Rock_Sandstone"
    },
    {
      "x": -9,
      "y": 36,
      "z": -6,
      "name": "Rock_Sandstone"
    },
    {
      "x": -9,
      "y": 37,
      "z": -6,
      "name": "Rock_Sandstone"
    },
    {
      "x": -9,
      "y": 9,
      "z": -5,
      "name": "Rock_Sandstone"
    },
    {
      "x": -9,
      "y": 10,
      "z": -5,
      "name": "Rock_Sandstone"
    },
    {
      "x": -9,
      "y": 11,
      "z": -5,
      "name": "Rock_Sandstone"
    },
    {
      "x": -9,
      "y": 12,
      "z": -5,
      "name": "Soil_Sand"
    },
    {
      "x": -9,
      "y": 13,
      "z": -5,
      "name": "Soil_Gravel_Sand"
    },
    {
      "x": -9,
      "y": 9,
      "z": -4,
      "name": "Rock_Sandstone"
    },
    {
      "x": -9,
      "y": 10,
      "z": -4,
      "name": "Rock_Sandstone"
    },
    {
      "x": -9,
      "y": 11,
      "z": -4,
      "name": "Rock_Sandstone"
    },
    {
      "x": -9,
      "y": 12,
      "z": -4,
      "name": "Soil_Sand"
    },
    {
      "x": -9,
      "y": 13,
      "z": -4,
      "name": "Soil_Sand"
    },
    {
      "x": -9,
      "y": 14,
      "z": -4,
      "name": "Rubble_Sandstone"
    },
    {
      "x": -9,
      "y": 9,
      "z": -3,
      "name": "Rock_Sandstone"
    },
    {
      "x": -9,
      "y": 10,
      "z": -3,
      "name": "Rock_Sandstone"
    },
    {
      "x": -9,
      "y": 11,
      "z": -3,
      "name": "Rock_Sandstone"
    },
    {
      "x": -9,
      "y": 12,
      "z": -3,
      "name": "Soil_Sand"
    },
    {
      "x": -9,
      "y": 13,
      "z": -3,
      "name": "Soil_Sand"
    },
    {
      "x": -9,
      "y": 9,
      "z": -2,
      "name": "Rock_Sandstone"
    },
    {
      "x": -9,
      "y": 10,
      "z": -2,
      "name": "Rock_Sandstone"
    },
    {
      "x": -9,
      "y": 11,
      "z": -2,
      "name": "Soil_Sand"
    },
    {
      "x": -9,
      "y": 12,
      "z": -2,
      "name": "Soil_Sand"
    },
    {
      "x": -9,
      "y": 13,
      "z": -2,
      "name": "Soil_Sand"
    },
    {
      "x": -9,
      "y": 14,
      "z": -2,
      "name": "Plant_Crop_Stamina2"
    },
    {
      "x": -9,
      "y": 8,
      "z": -1,
      "name": "Rock_Sandstone"
    },
    {
      "x": -9,
      "y": 9,
      "z": -1,
      "name": "Rock_Sandstone"
    },
    {
      "x": -9,
      "y": 10,
      "z": -1,
      "name": "Rock_Sandstone"
    },
    {
      "x": -9,
      "y": 11,
      "z": -1,
      "name": "Rock_Sandstone"
    },
    {
      "x": -9,
      "y": 12,
      "z": -1,
      "name": "Soil_Sand"
    },
    {
      "x": -9,
      "y": 13,
      "z": -1,
      "name": "Soil_Sand"
    },
    {
      "x": -9,
      "y": 29,
      "z": -1,
      "name": "Plant_Crop_Mushroom_Shelve_Yellow"
    },
    {
      "x": -9,
      "y": 10,
      "z": 0,
      "name": "Rock_Sandstone"
    },
    {
      "x": -9,
      "y": 11,
      "z": 0,
      "name": "Soil_Sand"
    },
    {
      "x": -9,
      "y": 12,
      "z": 0,
      "name": "Soil_Gravel_Sand"
    },
    {
      "x": -9,
      "y": 13,
      "z": 0,
      "name": "Soil_Sand"
    },
    {
      "x": -9,
      "y": 14,
      "z": 0,
      "name": "Plant_Bush_Arid"
    },
    {
      "x": -9,
      "y": 24,
      "z": 0,
      "name": "Rock_Sandstone_Stalactite_Large",
      "filler": 31744,
      "rotation": 8
    },
    {
      "x": -9,
      "y": 25,
      "z": 0,
      "name": "Rock_Sandstone_Stalactite_Large",
      "rotation": 8
    },
    {
      "x": -9,
      "y": 26,
      "z": 0,
      "name": "Rock_Sandstone"
    },
    {
      "x": -9,
      "y": 27,
      "z": 0,
      "name": "Rock_Sandstone"
    },
    {
      "x": -9,
      "y": 28,
      "z": 0,
      "name": "Rock_Sandstone"
    },
    {
      "x": -9,
      "y": 29,
      "z": 0,
      "name": "Rock_Sandstone"
    },
    {
      "x": -9,
      "y": 30,
      "z": 0,
      "name": "Rock_Sandstone"
    },
    {
      "x": -9,
      "y": 31,
      "z": 0,
      "name": "Soil_Sand"
    },
    {
      "x": -9,
      "y": 32,
      "z": 0,
      "name": "Plant_Crop_Mushroom_Shelve_Yellow"
    },
    {
      "x": -9,
      "y": 12,
      "z": 1,
      "name": "Plant_Crop_Mushroom_Shelve_Yellow"
    },
    {
      "x": -9,
      "y": 24,
      "z": 1,
      "name": "Rock_Sandstone"
    },
    {
      "x": -9,
      "y": 25,
      "z": 1,
      "name": "Rock_Sandstone"
    },
    {
      "x": -9,
      "y": 26,
      "z": 1,
      "name": "Rock_Sandstone"
    },
    {
      "x": -9,
      "y": 27,
      "z": 1,
      "name": "Rock_Sandstone"
    },
    {
      "x": -9,
      "y": 28,
      "z": 1,
      "name": "Rock_Sandstone"
    },
    {
      "x": -9,
      "y": 29,
      "z": 1,
      "name": "Rock_Sandstone"
    },
    {
      "x": -9,
      "y": 30,
      "z": 1,
      "name": "Rock_Sandstone"
    },
    {
      "x": -9,
      "y": 31,
      "z": 1,
      "name": "Soil_Sand"
    },
    {
      "x": -9,
      "y": 23,
      "z": 2,
      "name": "Rock_Sandstone"
    },
    {
      "x": -9,
      "y": 24,
      "z": 2,
      "name": "Rock_Sandstone"
    },
    {
      "x": -9,
      "y": 25,
      "z": 2,
      "name": "Rock_Sandstone"
    },
    {
      "x": -9,
      "y": 26,
      "z": 2,
      "name": "Rock_Sandstone"
    },
    {
      "x": -9,
      "y": 27,
      "z": 2,
      "name": "Rock_Sandstone"
    },
    {
      "x": -9,
      "y": 28,
      "z": 2,
      "name": "Rock_Sandstone"
    },
    {
      "x": -9,
      "y": 29,
      "z": 2,
      "name": "Rock_Sandstone"
    },
    {
      "x": -9,
      "y": 30,
      "z": 2,
      "name": "Rock_Sandstone"
    },
    {
      "x": -9,
      "y": 31,
      "z": 2,
      "name": "Rock_Sandstone"
    },
    {
      "x": -9,
      "y": 32,
      "z": 2,
      "name": "Soil_Sand"
    },
    {
      "x": -9,
      "y": 23,
      "z": 3,
      "name": "Rock_Sandstone"
    },
    {
      "x": -9,
      "y": 24,
      "z": 3,
      "name": "Rock_Sandstone"
    },
    {
      "x": -9,
      "y": 25,
      "z": 3,
      "name": "Rock_Sandstone"
    },
    {
      "x": -9,
      "y": 26,
      "z": 3,
      "name": "Rock_Sandstone"
    },
    {
      "x": -9,
      "y": 27,
      "z": 3,
      "name": "Rock_Sandstone"
    },
    {
      "x": -9,
      "y": 28,
      "z": 3,
      "name": "Ore_Gold_Sandstone"
    },
    {
      "x": -9,
      "y": 29,
      "z": 3,
      "name": "Rock_Sandstone"
    },
    {
      "x": -9,
      "y": 30,
      "z": 3,
      "name": "Soil_Sand"
    },
    {
      "x": -9,
      "y": 31,
      "z": 3,
      "name": "Soil_Sand"
    },
    {
      "x": -9,
      "y": 32,
      "z": 3,
      "name": "Soil_Sand"
    },
    {
      "x": -9,
      "y": 34,
      "z": 3,
      "name": "Wood_Ash_Branch_Corner",
      "rotation": 2
    },
    {
      "x": -9,
      "y": 35,
      "z": 3,
      "name": "Wood_Ash_Branch_Corner",
      "rotation": 11
    },
    {
      "x": -9,
      "y": 23,
      "z": 4,
      "name": "Rock_Sandstone"
    },
    {
      "x": -9,
      "y": 24,
      "z": 4,
      "name": "Rock_Sandstone"
    },
    {
      "x": -9,
      "y": 25,
      "z": 4,
      "name": "Rock_Sandstone"
    },
    {
      "x": -9,
      "y": 26,
      "z": 4,
      "name": "Rock_Sandstone"
    },
    {
      "x": -9,
      "y": 27,
      "z": 4,
      "name": "Rock_Sandstone"
    },
    {
      "x": -9,
      "y": 28,
      "z": 4,
      "name": "Rock_Sandstone"
    },
    {
      "x": -9,
      "y": 29,
      "z": 4,
      "name": "Rock_Sandstone"
    },
    {
      "x": -9,
      "y": 30,
      "z": 4,
      "name": "Rock_Sandstone"
    },
    {
      "x": -9,
      "y": 31,
      "z": 4,
      "name": "Soil_Sand"
    },
    {
      "x": -9,
      "y": 32,
      "z": 4,
      "name": "Soil_Sand"
    },
    {
      "x": -9,
      "y": 34,
      "z": 4,
      "name": "Wood_Ash_Trunk_Full",
      "rotation": 5
    },
    {
      "x": -9,
      "y": 35,
      "z": 4,
      "name": "Wood_Ash_Trunk",
      "rotation": 5
    },
    {
      "x": -9,
      "y": 37,
      "z": 4,
      "name": "Wood_Ash_Branch_Corner",
      "rotation": 1
    },
    {
      "x": -9,
      "y": 38,
      "z": 4,
      "name": "Wood_Ash_Branch_Corner",
      "rotation": 11
    },
    {
      "x": -9,
      "y": 19,
      "z": 5,
      "name": "Rock_Sandstone"
    },
    {
      "x": -9,
      "y": 20,
      "z": 5,
      "name": "Rock_Sandstone"
    },
    {
      "x": -9,
      "y": 24,
      "z": 5,
      "name": "Rock_Sandstone"
    },
    {
      "x": -9,
      "y": 25,
      "z": 5,
      "name": "Rock_Sandstone"
    },
    {
      "x": -9,
      "y": 26,
      "z": 5,
      "name": "Rock_Sandstone"
    },
    {
      "x": -9,
      "y": 27,
      "z": 5,
      "name": "Rock_Sandstone"
    },
    {
      "x": -9,
      "y": 28,
      "z": 5,
      "name": "Rock_Sandstone"
    },
    {
      "x": -9,
      "y": 29,
      "z": 5,
      "name": "Rock_Sandstone"
    },
    {
      "x": -9,
      "y": 30,
      "z": 5,
      "name": "Rock_Sandstone"
    },
    {
      "x": -9,
      "y": 31,
      "z": 5,
      "name": "Soil_Sand"
    },
    {
      "x": -9,
      "y": 32,
      "z": 5,
      "name": "Soil_Sand"
    },
    {
      "x": -9,
      "y": 18,
      "z": 6,
      "name": "Rock_Sandstone"
    },
    {
      "x": -9,
      "y": 19,
      "z": 6,
      "name": "Rock_Sandstone"
    },
    {
      "x": -9,
      "y": 20,
      "z": 6,
      "name": "Rock_Sandstone"
    },
    {
      "x": -9,
      "y": 25,
      "z": 6,
      "name": "Rock_Sandstone"
    },
    {
      "x": -9,
      "y": 26,
      "z": 6,
      "name": "Rock_Sandstone"
    },
    {
      "x": -9,
      "y": 27,
      "z": 6,
      "name": "Rock_Sandstone"
    },
    {
      "x": -9,
      "y": 28,
      "z": 6,
      "name": "Rock_Sandstone"
    },
    {
      "x": -9,
      "y": 29,
      "z": 6,
      "name": "Rock_Sandstone"
    },
    {
      "x": -9,
      "y": 30,
      "z": 6,
      "name": "Rock_Sandstone"
    },
    {
      "x": -9,
      "y": 31,
      "z": 6,
      "name": "Rock_Sandstone"
    },
    {
      "x": -9,
      "y": 32,
      "z": 6,
      "name": "Soil_Sand"
    },
    {
      "x": -9,
      "y": 17,
      "z": 7,
      "name": "Rock_Sandstone"
    },
    {
      "x": -9,
      "y": 18,
      "z": 7,
      "name": "Rock_Sandstone"
    },
    {
      "x": -9,
      "y": 19,
      "z": 7,
      "name": "Rock_Sandstone"
    },
    {
      "x": -9,
      "y": 20,
      "z": 7,
      "name": "Rock_Sandstone"
    },
    {
      "x": -9,
      "y": 26,
      "z": 7,
      "name": "Rock_Sandstone"
    },
    {
      "x": -9,
      "y": 27,
      "z": 7,
      "name": "Rock_Sandstone"
    },
    {
      "x": -9,
      "y": 28,
      "z": 7,
      "name": "Rock_Sandstone"
    },
    {
      "x": -9,
      "y": 29,
      "z": 7,
      "name": "Rock_Sandstone"
    },
    {
      "x": -9,
      "y": 30,
      "z": 7,
      "name": "Rock_Sandstone"
    },
    {
      "x": -9,
      "y": 31,
      "z": 7,
      "name": "Soil_Sand"
    },
    {
      "x": -9,
      "y": 17,
      "z": 8,
      "name": "Rock_Sandstone"
    },
    {
      "x": -9,
      "y": 18,
      "z": 8,
      "name": "Rock_Sandstone"
    },
    {
      "x": -9,
      "y": 19,
      "z": 8,
      "name": "Rock_Sandstone"
    },
    {
      "x": -9,
      "y": 20,
      "z": 8,
      "name": "Rock_Sandstone"
    },
    {
      "x": -9,
      "y": 21,
      "z": 8,
      "name": "Rock_Sandstone"
    },
    {
      "x": -9,
      "y": 22,
      "z": 8,
      "name": "Rock_Sandstone"
    },
    {
      "x": -9,
      "y": 23,
      "z": 8,
      "name": "Rubble_Sandstone"
    },
    {
      "x": -9,
      "y": 27,
      "z": 8,
      "name": "Rock_Sandstone"
    },
    {
      "x": -9,
      "y": 28,
      "z": 8,
      "name": "Rock_Sandstone"
    },
    {
      "x": -9,
      "y": 29,
      "z": 8,
      "name": "Rock_Sandstone"
    },
    {
      "x": -9,
      "y": 30,
      "z": 8,
      "name": "Soil_Sand"
    },
    {
      "x": -9,
      "y": 31,
      "z": 8,
      "name": "Soil_Gravel_Sand"
    },
    {
      "x": -9,
      "y": 32,
      "z": 8,
      "name": "Plant_Crop_Mushroom_Glowing_Red"
    },
    {
      "x": -9,
      "y": 17,
      "z": 9,
      "name": "Rock_Sandstone"
    },
    {
      "x": -9,
      "y": 18,
      "z": 9,
      "name": "Rock_Sandstone"
    },
    {
      "x": -9,
      "y": 19,
      "z": 9,
      "name": "Rock_Sandstone"
    },
    {
      "x": -9,
      "y": 20,
      "z": 9,
      "name": "Rock_Sandstone"
    },
    {
      "x": -9,
      "y": 21,
      "z": 9,
      "name": "Rock_Sandstone"
    },
    {
      "x": -9,
      "y": 22,
      "z": 9,
      "name": "Rock_Sandstone"
    },
    {
      "x": -9,
      "y": 23,
      "z": 9,
      "name": "Rock_Sandstone"
    },
    {
      "x": -9,
      "y": 24,
      "z": 9,
      "name": "Rock_Sandstone"
    },
    {
      "x": -9,
      "y": 25,
      "z": 9,
      "name": "Rock_Sandstone"
    },
    {
      "x": -9,
      "y": 26,
      "z": 9,
      "name": "Rock_Sandstone"
    },
    {
      "x": -9,
      "y": 27,
      "z": 9,
      "name": "Rock_Sandstone"
    },
    {
      "x": -9,
      "y": 28,
      "z": 9,
      "name": "Rock_Sandstone"
    },
    {
      "x": -9,
      "y": 29,
      "z": 9,
      "name": "Rock_Sandstone"
    },
    {
      "x": -9,
      "y": 30,
      "z": 9,
      "name": "Rock_Sandstone"
    },
    {
      "x": -9,
      "y": 31,
      "z": 9,
      "name": "Rubble_Sandstone"
    },
    {
      "x": -9,
      "y": 16,
      "z": 10,
      "name": "Rock_Sandstone_Stalactite_Small",
      "rotation": 8
    },
    {
      "x": -9,
      "y": 17,
      "z": 10,
      "name": "Rock_Sandstone"
    },
    {
      "x": -9,
      "y": 18,
      "z": 10,
      "name": "Rock_Sandstone"
    },
    {
      "x": -9,
      "y": 19,
      "z": 10,
      "name": "Rock_Sandstone"
    },
    {
      "x": -9,
      "y": 20,
      "z": 10,
      "name": "Rock_Sandstone"
    },
    {
      "x": -9,
      "y": 21,
      "z": 10,
      "name": "Rock_Sandstone"
    },
    {
      "x": -9,
      "y": 22,
      "z": 10,
      "name": "Rock_Sandstone"
    },
    {
      "x": -9,
      "y": 23,
      "z": 10,
      "name": "Rock_Sandstone"
    },
    {
      "x": -9,
      "y": 24,
      "z": 10,
      "name": "Rock_Sandstone"
    },
    {
      "x": -9,
      "y": 25,
      "z": 10,
      "name": "Rock_Sandstone"
    },
    {
      "x": -9,
      "y": 26,
      "z": 10,
      "name": "Rock_Sandstone"
    },
    {
      "x": -9,
      "y": 27,
      "z": 10,
      "name": "Rock_Sandstone"
    },
    {
      "x": -9,
      "y": 28,
      "z": 10,
      "name": "Rock_Sandstone"
    },
    {
      "x": -9,
      "y": 29,
      "z": 10,
      "name": "Rock_Sandstone"
    },
    {
      "x": -9,
      "y": 30,
      "z": 10,
      "name": "Rubble_Sandstone_Medium"
    },
    {
      "x": -9,
      "y": 17,
      "z": 11,
      "name": "Rock_Sandstone"
    },
    {
      "x": -9,
      "y": 18,
      "z": 11,
      "name": "Rock_Sandstone"
    },
    {
      "x": -9,
      "y": 19,
      "z": 11,
      "name": "Rock_Sandstone"
    },
    {
      "x": -9,
      "y": 20,
      "z": 11,
      "name": "Rock_Sandstone"
    },
    {
      "x": -9,
      "y": 21,
      "z": 11,
      "name": "Rock_Sandstone"
    },
    {
      "x": -9,
      "y": 22,
      "z": 11,
      "name": "Rock_Sandstone"
    },
    {
      "x": -9,
      "y": 23,
      "z": 11,
      "name": "Rock_Sandstone"
    },
    {
      "x": -9,
      "y": 24,
      "z": 11,
      "name": "Rock_Sandstone"
    },
    {
      "x": -9,
      "y": 25,
      "z": 11,
      "name": "Rock_Sandstone"
    },
    {
      "x": -9,
      "y": 26,
      "z": 11,
      "name": "Rock_Sandstone"
    },
    {
      "x": -9,
      "y": 27,
      "z": 11,
      "name": "Rock_Sandstone"
    },
    {
      "x": -9,
      "y": 28,
      "z": 11,
      "name": "Rock_Sandstone"
    },
    {
      "x": -9,
      "y": 17,
      "z": 12,
      "name": "Rock_Sandstone"
    },
    {
      "x": -9,
      "y": 18,
      "z": 12,
      "name": "Rock_Sandstone"
    },
    {
      "x": -9,
      "y": 19,
      "z": 12,
      "name": "Rock_Sandstone"
    },
    {
      "x": -9,
      "y": 20,
      "z": 12,
      "name": "Rock_Sandstone"
    },
    {
      "x": -9,
      "y": 21,
      "z": 12,
      "name": "Rock_Sandstone"
    },
    {
      "x": -9,
      "y": 22,
      "z": 12,
      "name": "Rock_Sandstone"
    },
    {
      "x": -9,
      "y": 23,
      "z": 12,
      "name": "Rock_Sandstone"
    },
    {
      "x": -9,
      "y": 24,
      "z": 12,
      "name": "Rock_Sandstone"
    },
    {
      "x": -9,
      "y": 25,
      "z": 12,
      "name": "Rock_Sandstone"
    },
    {
      "x": -9,
      "y": 26,
      "z": 12,
      "name": "Rock_Sandstone"
    },
    {
      "x": -9,
      "y": 27,
      "z": 12,
      "name": "Rock_Sandstone"
    },
    {
      "x": -9,
      "y": 28,
      "z": 12,
      "name": "Rock_Sandstone"
    },
    {
      "x": -9,
      "y": 29,
      "z": 12,
      "name": "Rubble_Sandstone_Medium"
    },
    {
      "x": -9,
      "y": 16,
      "z": 13,
      "name": "Rock_Sandstone"
    },
    {
      "x": -9,
      "y": 17,
      "z": 13,
      "name": "Rock_Sandstone"
    },
    {
      "x": -9,
      "y": 18,
      "z": 13,
      "name": "Rock_Sandstone"
    },
    {
      "x": -9,
      "y": 19,
      "z": 13,
      "name": "Rock_Sandstone"
    },
    {
      "x": -9,
      "y": 20,
      "z": 13,
      "name": "Rock_Sandstone"
    },
    {
      "x": -9,
      "y": 21,
      "z": 13,
      "name": "Rock_Sandstone"
    },
    {
      "x": -9,
      "y": 22,
      "z": 13,
      "name": "Rock_Sandstone"
    },
    {
      "x": -9,
      "y": 23,
      "z": 13,
      "name": "Rock_Sandstone"
    },
    {
      "x": -9,
      "y": 24,
      "z": 13,
      "name": "Rock_Sandstone"
    },
    {
      "x": -9,
      "y": 25,
      "z": 13,
      "name": "Rock_Sandstone"
    },
    {
      "x": -9,
      "y": 26,
      "z": 13,
      "name": "Rock_Sandstone"
    },
    {
      "x": -9,
      "y": 27,
      "z": 13,
      "name": "Rock_Sandstone"
    },
    {
      "x": -9,
      "y": 28,
      "z": 13,
      "name": "Rubble_Sandstone_Medium"
    },
    {
      "x": -9,
      "y": 16,
      "z": 14,
      "name": "Rock_Sandstone"
    },
    {
      "x": -9,
      "y": 17,
      "z": 14,
      "name": "Rock_Sandstone"
    },
    {
      "x": -9,
      "y": 18,
      "z": 14,
      "name": "Rock_Sandstone"
    },
    {
      "x": -9,
      "y": 19,
      "z": 14,
      "name": "Rock_Sandstone"
    },
    {
      "x": -9,
      "y": 20,
      "z": 14,
      "name": "Rock_Sandstone"
    },
    {
      "x": -9,
      "y": 21,
      "z": 14,
      "name": "Rock_Sandstone"
    },
    {
      "x": -9,
      "y": 22,
      "z": 14,
      "name": "Rock_Sandstone"
    },
    {
      "x": -9,
      "y": 23,
      "z": 14,
      "name": "Rock_Sandstone"
    },
    {
      "x": -9,
      "y": 24,
      "z": 14,
      "name": "Rock_Sandstone"
    },
    {
      "x": -9,
      "y": 25,
      "z": 14,
      "name": "Rock_Sandstone"
    },
    {
      "x": -9,
      "y": 26,
      "z": 14,
      "name": "Soil_Sand"
    },
    {
      "x": -9,
      "y": 27,
      "z": 14,
      "name": "Soil_Gravel_Sand"
    },
    {
      "x": -9,
      "y": 16,
      "z": 15,
      "name": "Rock_Sandstone_Stalactite_Small",
      "rotation": 8
    },
    {
      "x": -9,
      "y": 17,
      "z": 15,
      "name": "Rock_Sandstone"
    },
    {
      "x": -9,
      "y": 18,
      "z": 15,
      "name": "Rock_Sandstone"
    },
    {
      "x": -9,
      "y": 19,
      "z": 15,
      "name": "Rock_Sandstone"
    },
    {
      "x": -9,
      "y": 20,
      "z": 15,
      "name": "Rock_Sandstone"
    },
    {
      "x": -9,
      "y": 21,
      "z": 15,
      "name": "Rock_Sandstone"
    },
    {
      "x": -9,
      "y": 22,
      "z": 15,
      "name": "Rock_Sandstone"
    },
    {
      "x": -9,
      "y": 23,
      "z": 15,
      "name": "Rock_Sandstone"
    },
    {
      "x": -9,
      "y": 24,
      "z": 15,
      "name": "Rock_Sandstone"
    },
    {
      "x": -9,
      "y": 25,
      "z": 15,
      "name": "Soil_Sand"
    },
    {
      "x": -9,
      "y": 26,
      "z": 15,
      "name": "Soil_Gravel_Sand"
    },
    {
      "x": -9,
      "y": 17,
      "z": 16,
      "name": "Rock_Sandstone_Stalactite_Small",
      "rotation": 8
    },
    {
      "x": -9,
      "y": 18,
      "z": 16,
      "name": "Rock_Sandstone"
    },
    {
      "x": -9,
      "y": 19,
      "z": 16,
      "name": "Rock_Sandstone"
    },
    {
      "x": -9,
      "y": 20,
      "z": 16,
      "name": "Rock_Sandstone"
    },
    {
      "x": -9,
      "y": 21,
      "z": 16,
      "name": "Rock_Sandstone"
    },
    {
      "x": -9,
      "y": 22,
      "z": 16,
      "name": "Rock_Sandstone"
    },
    {
      "x": -9,
      "y": 23,
      "z": 16,
      "name": "Rock_Sandstone"
    },
    {
      "x": -9,
      "y": 24,
      "z": 16,
      "name": "Soil_Sand"
    },
    {
      "x": -9,
      "y": 25,
      "z": 16,
      "name": "Soil_Sand"
    },
    {
      "x": -9,
      "y": 26,
      "z": 16,
      "name": "Soil_Sand"
    },
    {
      "x": -9,
      "y": 19,
      "z": 17,
      "name": "Rock_Sandstone"
    },
    {
      "x": -9,
      "y": 20,
      "z": 17,
      "name": "Rock_Sandstone"
    },
    {
      "x": -9,
      "y": 21,
      "z": 17,
      "name": "Rock_Sandstone"
    },
    {
      "x": -9,
      "y": 22,
      "z": 17,
      "name": "Rock_Sandstone"
    },
    {
      "x": -9,
      "y": 23,
      "z": 17,
      "name": "Rock_Sandstone"
    },
    {
      "x": -9,
      "y": 24,
      "z": 17,
      "name": "Rock_Sandstone"
    },
    {
      "x": -9,
      "y": 25,
      "z": 17,
      "name": "Soil_Sand"
    },
    {
      "x": -8,
      "y": 34,
      "z": -11,
      "name": "Rock_Sandstone"
    },
    {
      "x": -8,
      "y": 35,
      "z": -11,
      "name": "Rock_Sandstone"
    },
    {
      "x": -8,
      "y": 36,
      "z": -11,
      "name": "Rock_Sandstone"
    },
    {
      "x": -8,
      "y": 37,
      "z": -11,
      "name": "Rock_Sandstone"
    },
    {
      "x": -8,
      "y": 38,
      "z": -11,
      "name": "Rubble_Sandstone_Medium"
    },
    {
      "x": -8,
      "y": 33,
      "z": -10,
      "name": "Rock_Sandstone"
    },
    {
      "x": -8,
      "y": 34,
      "z": -10,
      "name": "Rock_Sandstone"
    },
    {
      "x": -8,
      "y": 35,
      "z": -10,
      "name": "Rock_Sandstone"
    },
    {
      "x": -8,
      "y": 36,
      "z": -10,
      "name": "Rock_Sandstone"
    },
    {
      "x": -8,
      "y": 37,
      "z": -10,
      "name": "Rock_Sandstone"
    },
    {
      "x": -8,
      "y": 38,
      "z": -10,
      "name": "Rock_Sandstone"
    },
    {
      "x": -8,
      "y": 39,
      "z": -10,
      "name": "Rubble_Sandstone"
    },
    {
      "x": -8,
      "y": 32,
      "z": -9,
      "name": "Rock_Sandstone"
    },
    {
      "x": -8,
      "y": 33,
      "z": -9,
      "name": "Rock_Sandstone"
    },
    {
      "x": -8,
      "y": 34,
      "z": -9,
      "name": "Rock_Sandstone"
    },
    {
      "x": -8,
      "y": 35,
      "z": -9,
      "name": "Rock_Sandstone"
    },
    {
      "x": -8,
      "y": 36,
      "z": -9,
      "name": "Rock_Sandstone"
    },
    {
      "x": -8,
      "y": 37,
      "z": -9,
      "name": "Rock_Sandstone"
    },
    {
      "x": -8,
      "y": 38,
      "z": -9,
      "name": "Rock_Sandstone"
    },
    {
      "x": -8,
      "y": 39,
      "z": -9,
      "name": "Soil_Sand"
    },
    {
      "x": -8,
      "y": 40,
      "z": -9,
      "name": "Plant_Crop_Mushroom_Glowing_Red"
    },
    {
      "x": -8,
      "y": 32,
      "z": -8,
      "name": "Rock_Sandstone"
    },
    {
      "x": -8,
      "y": 33,
      "z": -8,
      "name": "Rock_Sandstone"
    },
    {
      "x": -8,
      "y": 34,
      "z": -8,
      "name": "Rock_Sandstone"
    },
    {
      "x": -8,
      "y": 35,
      "z": -8,
      "name": "Rock_Sandstone"
    },
    {
      "x": -8,
      "y": 36,
      "z": -8,
      "name": "Rock_Sandstone"
    },
    {
      "x": -8,
      "y": 37,
      "z": -8,
      "name": "Rock_Sandstone"
    },
    {
      "x": -8,
      "y": 38,
      "z": -8,
      "name": "Rock_Sandstone"
    },
    {
      "x": -8,
      "y": 39,
      "z": -8,
      "name": "Soil_Sand"
    },
    {
      "x": -8,
      "y": 10,
      "z": -7,
      "name": "Rock_Sandstone"
    },
    {
      "x": -8,
      "y": 11,
      "z": -7,
      "name": "Rock_Sandstone"
    },
    {
      "x": -8,
      "y": 12,
      "z": -7,
      "name": "Rock_Sandstone"
    },
    {
      "x": -8,
      "y": 13,
      "z": -7,
      "name": "Soil_Sand"
    },
    {
      "x": -8,
      "y": 32,
      "z": -7,
      "name": "Rock_Sandstone"
    },
    {
      "x": -8,
      "y": 33,
      "z": -7,
      "name": "Rock_Sandstone"
    },
    {
      "x": -8,
      "y": 34,
      "z": -7,
      "name": "Rock_Sandstone"
    },
    {
      "x": -8,
      "y": 35,
      "z": -7,
      "name": "Rock_Sandstone"
    },
    {
      "x": -8,
      "y": 36,
      "z": -7,
      "name": "Rock_Sandstone"
    },
    {
      "x": -8,
      "y": 37,
      "z": -7,
      "name": "Rock_Sandstone"
    },
    {
      "x": -8,
      "y": 38,
      "z": -7,
      "name": "Rock_Sandstone"
    },
    {
      "x": -8,
      "y": 39,
      "z": -7,
      "name": "Rock_Sandstone"
    },
    {
      "x": -8,
      "y": 40,
      "z": -7,
      "name": "Rubble_Sandstone_Medium"
    },
    {
      "x": -8,
      "y": 8,
      "z": -6,
      "name": "Rock_Sandstone"
    },
    {
      "x": -8,
      "y": 9,
      "z": -6,
      "name": "Rock_Sandstone"
    },
    {
      "x": -8,
      "y": 10,
      "z": -6,
      "name": "Rock_Sandstone"
    },
    {
      "x": -8,
      "y": 11,
      "z": -6,
      "name": "Rock_Sandstone"
    },
    {
      "x": -8,
      "y": 12,
      "z": -6,
      "name": "Soil_Sand"
    },
    {
      "x": -8,
      "y": 13,
      "z": -6,
      "name": "Soil_Sand"
    },
    {
      "x": -8,
      "y": 14,
      "z": -6,
      "name": "Rubble_Sandstone"
    },
    {
      "x": -8,
      "y": 33,
      "z": -6,
      "name": "Rock_Sandstone"
    },
    {
      "x": -8,
      "y": 34,
      "z": -6,
      "name": "Rock_Sandstone"
    },
    {
      "x": -8,
      "y": 35,
      "z": -6,
      "name": "Rock_Sandstone"
    },
    {
      "x": -8,
      "y": 36,
      "z": -6,
      "name": "Rock_Sandstone"
    },
    {
      "x": -8,
      "y": 37,
      "z": -6,
      "name": "Rock_Sandstone"
    },
    {
      "x": -8,
      "y": 38,
      "z": -6,
      "name": "Rock_Sandstone"
    },
    {
      "x": -8,
      "y": 39,
      "z": -6,
      "name": "Rock_Sandstone"
    },
    {
      "x": -8,
      "y": 40,
      "z": -6,
      "name": "Rubble_Sandstone"
    },
    {
      "x": -8,
      "y": 8,
      "z": -5,
      "name": "Rock_Sandstone"
    },
    {
      "x": -8,
      "y": 9,
      "z": -5,
      "name": "Rock_Sandstone"
    },
    {
      "x": -8,
      "y": 10,
      "z": -5,
      "name": "Rock_Sandstone"
    },
    {
      "x": -8,
      "y": 11,
      "z": -5,
      "name": "Soil_Sand"
    },
    {
      "x": -8,
      "y": 12,
      "z": -5,
      "name": "Soil_Sand"
    },
    {
      "x": -8,
      "y": 13,
      "z": -5,
      "name": "Rock_Sandstone_Brick_Decorative"
    },
    {
      "x": -8,
      "y": 34,
      "z": -5,
      "name": "Rock_Sandstone"
    },
    {
      "x": -8,
      "y": 35,
      "z": -5,
      "name": "Rock_Sandstone"
    },
    {
      "x": -8,
      "y": 36,
      "z": -5,
      "name": "Rock_Sandstone"
    },
    {
      "x": -8,
      "y": 37,
      "z": -5,
      "name": "Rock_Sandstone"
    },
    {
      "x": -8,
      "y": 38,
      "z": -5,
      "name": "Rock_Sandstone"
    },
    {
      "x": -8,
      "y": 7,
      "z": -4,
      "name": "Rock_Sandstone"
    },
    {
      "x": -8,
      "y": 8,
      "z": -4,
      "name": "Rock_Sandstone"
    },
    {
      "x": -8,
      "y": 9,
      "z": -4,
      "name": "Rock_Sandstone"
    },
    {
      "x": -8,
      "y": 10,
      "z": -4,
      "name": "Rock_Sandstone"
    },
    {
      "x": -8,
      "y": 11,
      "z": -4,
      "name": "Rock_Sandstone"
    },
    {
      "x": -8,
      "y": 12,
      "z": -4,
      "name": "Soil_Sand"
    },
    {
      "x": -8,
      "y": 13,
      "z": -4,
      "name": "Rock_Sandstone_Brick_Decorative"
    },
    {
      "x": -8,
      "y": 14,
      "z": -4,
      "name": "Rock_Sandstone_Brick_Pillar_Base"
    },
    {
      "x": -8,
      "y": 15,
      "z": -4,
      "name": "Rock_Sandstone_Brick_Pillar_Middle"
    },
    {
      "x": -8,
      "y": 37,
      "z": -4,
      "name": "Rock_Sandstone"
    },
    {
      "x": -8,
      "y": 7,
      "z": -3,
      "name": "Rock_Sandstone"
    },
    {
      "x": -8,
      "y": 8,
      "z": -3,
      "name": "Rock_Sandstone"
    },
    {
      "x": -8,
      "y": 9,
      "z": -3,
      "name": "Rock_Sandstone"
    },
    {
      "x": -8,
      "y": 10,
      "z": -3,
      "name": "Rock_Sandstone"
    },
    {
      "x": -8,
      "y": 11,
      "z": -3,
      "name": "Soil_Sand"
    },
    {
      "x": -8,
      "y": 12,
      "z": -3,
      "name": "Soil_Sand"
    },
    {
      "x": -8,
      "y": 13,
      "z": -3,
      "name": "Rock_Sandstone_Brick_Decorative"
    },
    {
      "x": -8,
      "y": 8,
      "z": -2,
      "name": "Rock_Sandstone"
    },
    {
      "x": -8,
      "y": 9,
      "z": -2,
      "name": "Rock_Sandstone"
    },
    {
      "x": -8,
      "y": 10,
      "z": -2,
      "name": "Rock_Sandstone"
    },
    {
      "x": -8,
      "y": 11,
      "z": -2,
      "name": "Soil_Sand"
    },
    {
      "x": -8,
      "y": 12,
      "z": -2,
      "name": "Soil_Sand"
    },
    {
      "x": -8,
      "y": 13,
      "z": -2,
      "name": "Soil_Sand"
    },
    {
      "x": -8,
      "y": 8,
      "z": -1,
      "name": "Rock_Sandstone"
    },
    {
      "x": -8,
      "y": 9,
      "z": -1,
      "name": "Rock_Sandstone"
    },
    {
      "x": -8,
      "y": 10,
      "z": -1,
      "name": "Rock_Sandstone"
    },
    {
      "x": -8,
      "y": 11,
      "z": -1,
      "name": "Soil_Sand"
    },
    {
      "x": -8,
      "y": 12,
      "z": -1,
      "name": "Soil_Sand"
    },
    {
      "x": -8,
      "y": 13,
      "z": -1,
      "name": "Soil_Gravel_Sand"
    },
    {
      "x": -8,
      "y": 8,
      "z": 0,
      "name": "Rock_Sandstone"
    },
    {
      "x": -8,
      "y": 9,
      "z": 0,
      "name": "Rock_Sandstone"
    },
    {
      "x": -8,
      "y": 10,
      "z": 0,
      "name": "Rock_Sandstone"
    },
    {
      "x": -8,
      "y": 11,
      "z": 0,
      "name": "Soil_Sand"
    },
    {
      "x": -8,
      "y": 12,
      "z": 0,
      "name": "Soil_Gravel_Sand"
    },
    {
      "x": -8,
      "y": 13,
      "z": 0,
      "name": "Soil_Sand"
    },
    {
      "x": -8,
      "y": 14,
      "z": 0,
      "name": "Plant_Crop_Mushroom_Shelve_Yellow"
    },
    {
      "x": -8,
      "y": 27,
      "z": 0,
      "name": "Rock_Sandstone"
    },
    {
      "x": -8,
      "y": 28,
      "z": 0,
      "name": "Rock_Sandstone"
    },
    {
      "x": -8,
      "y": 29,
      "z": 0,
      "name": "Rock_Sandstone"
    },
    {
      "x": -8,
      "y": 30,
      "z": 0,
      "name": "Rock_Sandstone"
    },
    {
      "x": -8,
      "y": 31,
      "z": 0,
      "name": "Rock_Sandstone"
    },
    {
      "x": -8,
      "y": 10,
      "z": 1,
      "name": "Rock_Sandstone"
    },
    {
      "x": -8,
      "y": 11,
      "z": 1,
      "name": "Soil_Sand"
    },
    {
      "x": -8,
      "y": 12,
      "z": 1,
      "name": "Soil_Sand"
    },
    {
      "x": -8,
      "y": 13,
      "z": 1,
      "name": "Soil_Sand"
    },
    {
      "x": -8,
      "y": 25,
      "z": 1,
      "name": "Rock_Sandstone"
    },
    {
      "x": -8,
      "y": 26,
      "z": 1,
      "name": "Rock_Sandstone"
    },
