{
  "version": 8,
  "blockIdVersion": 11,
  "anchorX": 0,
  "anchorY": 0,
  "anchorZ": 0,
  "blocks": [
    {
      "x": -6,
      "y": 1,
      "z": -3,
      "name": "Rock_Sandstone_Red"
    },
    {
      "x": -6,
      "y": 1,
      "z": -2,
      "name": "Rock_Sandstone_Red"
    },
    {
      "x": -6,
      "y": 2,
      "z": -2,
      "name": "Rock_Sandstone_Red"
    },
    {
      "x": -6,
      "y": 3,
      "z": -2,
      "name": "Soil_Sand_Red"
    },
    {
      "x": -6,
      "y": 1,
      "z": -1,
      "name": "Rock_Sandstone_Red"
    },
    {
      "x": -6,
      "y": 2,
      "z": -1,
      "name": "Rock_Sandstone_Red"
    },
    {
      "x": -6,
      "y": 3,
      "z": -1,
      "name": "Soil_Sand_Red"
    },
    {
      "x": -6,
      "y": 0,
      "z": 0,
      "name": "Rock_Sandstone_Red"
    },
    {
      "x": -6,
      "y": 1,
      "z": 0,
      "name": "Rock_Sandstone_Red"
    },
    {
      "x": -6,
      "y": 2,
      "z": 0,
      "name": "Soil_Sand_Red"
    },
    {
      "x": -6,
      "y": 1,
      "z": 1,
      "name": "Rock_Sandstone_Red"
    },
    {
      "x": -5,
      "y": 1,
      "z": -4,
      "name": "Rock_Sandstone_Red"
    },
    {
      "x": -5,
      "y": 0,
      "z": -3,
      "name": "Rock_Sandstone_Red"
    },
    {
      "x": -5,
      "y": 1,
      "z": -3,
      "name": "Rock_Sandstone_Red"
    },
    {
      "x": -5,
      "y": 2,
      "z": -3,
      "name": "Rock_Sandstone_Red"
    },
    {
      "x": -5,
      "y": 3,
      "z": -3,
      "name": "Rock_Sandstone_Red"
    },
    {
      "x": -5,
      "y": 4,
      "z": -3,
      "name": "Rubble_Sandstone_Red_Medium"
    },
    {
      "x": -5,
      "y": 0,
      "z": -2,
      "name": "Rock_Sandstone_Red"
    },
    {
      "x": -5,
      "y": 1,
      "z": -2,
      "name": "Rock_Sandstone_Red"
    },
    {
      "x": -5,
      "y": 2,
      "z": -2,
      "name": "Rock_Sandstone_Red"
    },
    {
      "x": -5,
      "y": 3,
      "z": -2,
      "name": "Rock_Sandstone_Red"
    },
    {
      "x": -5,
      "y": 4,
      "z": -2,
      "name": "Soil_Sand_Red"
    },
    {
      "x": -5,
      "y": 0,
      "z": -1,
      "name": "Rock_Sandstone_Red"
    },
    {
      "x": -5,
      "y": 1,
      "z": -1,
      "name": "Rock_Sandstone_Red"
    },
    {
      "x": -5,
      "y": 2,
      "z": -1,
      "name": "Rock_Sandstone_Red"
    },
    {
      "x": -5,
      "y": 3,
      "z": -1,
      "name": "Rock_Sandstone_Red"
    },
    {
      "x": -5,
      "y": 4,
      "z": -1,
      "name": "Soil_Sand_Red"
    },
    {
      "x": -5,
      "y": 0,
      "z": 0,
      "name": "Rock_Sandstone_Red"
    },
    {
      "x": -5,
      "y": 1,
      "z": 0,
      "name": "Rock_Sandstone_Red"
    },
    {
      "x": -5,
      "y": 2,
      "z": 0,
      "name": "Rock_Sandstone_Red"
    },
    {
      "x": -5,
      "y": 3,
      "z": 0,
      "name": "Soil_Sand_Red"
    },
    {
      "x": -5,
      "y": 1,
      "z": 1,
      "name": "Rock_Sandstone_Red"
    },
    {
      "x": -5,
      "y": 2,
      "z": 1,
      "name": "Soil_Sand_Red"
    },
    {
      "x": -5,
      "y": 1,
      "z": 2,
      "name": "Rock_Sandstone_Red"
    },
    {
      "x": -5,
      "y": 1,
      "z": 3,
      "name": "Rock_Sandstone_Red"
    },
    {
      "x": -5,
      "y": 1,
      "z": 4,
      "name": "Rock_Sandstone_Red"
    },
    {
      "x": -4,
      "y": 1,
      "z": -4,
      "name": "Rock_Sandstone_Red"
    },
    {
      "x": -4,
      "y": 2,
      "z": -4,
      "name": "Plant_Vine_Wall_Dry",
      "rotation": 3
    },
    {
      "x": -4,
      "y": 3,
      "z": -4,
      "name": "Plant_Vine_Wall_Dry",
      "rotation": 3
    },
    {
      "x": -4,
      "y": 0,
      "z": -3,
      "name": "Rock_Sandstone_Red"
    },
    {
      "x": -4,
      "y": 1,
      "z": -3,
      "name": "Rock_Sandstone_Red"
    },
    {
      "x": -4,
      "y": 2,
      "z": -3,
      "name": "Rock_Sandstone_Red"
    },
    {
      "x": -4,
      "y": 3,
      "z": -3,
      "name": "Rock_Sandstone_Red"
    },
    {
      "x": -4,
      "y": 4,
      "z": -3,
      "name": "Soil_Sand_Red"
    },
    {
      "x": -4,
      "y": 0,
      "z": -2,
      "name": "Rock_Sandstone_Red"
    },
    {
      "x": -4,
      "y": 1,
      "z": -2,
      "name": "Rock_Sandstone_Red"
    },
    {
      "x": -4,
      "y": 2,
      "z": -2,
      "name": "Rock_Sandstone_Red"
    },
    {
      "x": -4,
      "y": 3,
      "z": -2,
      "name": "Rock_Sandstone_Red"
    },
    {
      "x": -4,
      "y": 4,
      "z": -2,
      "name": "Soil_Sand_Red"
    },
    {
      "x": -4,
      "y": 0,
      "z": -1,
      "name": "Rock_Sandstone_Red"
    },
    {
      "x": -4,
      "y": 1,
      "z": -1,
      "name": "Rock_Sandstone_Red"
    },
    {
      "x": -4,
      "y": 2,
      "z": -1,
      "name": "Rock_Sandstone_Red"
    },
    {
      "x": -4,
      "y": 3,
      "z": -1,
      "name": "Rock_Sandstone_Red"
    },
    {
      "x": -4,
      "y": 4,
      "z": -1,
      "name": "Soil_Sand_Red"
    },
    {
      "x": -4,
      "y": 0,
      "z": 0,
      "name": "Rock_Sandstone_Red"
    },
    {
      "x": -4,
      "y": 1,
      "z": 0,
      "name": "Rock_Sandstone_Red"
    },
    {
      "x": -4,
      "y": 2,
      "z": 0,
      "name": "Rock_Sandstone_Red"
    },
    {
      "x": -4,
      "y": 3,
      "z": 0,
      "name": "Rock_Sandstone_Red"
    },
    {
      "x": -4,
      "y": 4,
      "z": 0,
      "name": "Soil_Sand_Red"
    },
    {
      "x": -4,
      "y": 0,
      "z": 1,
      "name": "Rock_Sandstone_Red"
    },
    {
      "x": -4,
      "y": 1,
      "z": 1,
      "name": "Rock_Sandstone_Red"
    },
    {
      "x": -4,
      "y": 2,
      "z": 1,
      "name": "Rock_Sandstone_Red"
    },
    {
      "x": -4,
      "y": 3,
      "z": 1,
      "name": "Soil_Sand_Red"
    },
    {
      "x": -4,
      "y": 4,
      "z": 1,
      "name": "Plant_Bush_Dead_Tall"
    },
    {
      "x": -4,
      "y": 0,
      "z": 2,
      "name": "Rock_Sandstone_Red"
    },
    {
      "x": -4,
      "y": 1,
      "z": 2,
      "name": "Rock_Sandstone_Red"
    },
    {
      "x": -4,
      "y": 2,
      "z": 2,
      "name": "Rock_Sandstone_Red"
    },
    {
      "x": -4,
      "y": 0,
      "z": 3,
      "name": "Rock_Sandstone_Red"
    },
    {
      "x": -4,
      "y": 1,
      "z": 3,
      "name": "Rock_Sandstone_Red"
    },
    {
      "x": -4,
      "y": 2,
      "z": 3,
      "name": "Rock_Sandstone_Red"
    },
    {
      "x": -4,
      "y": 3,
      "z": 3,
      "name": "Rock_Sandstone_Red"
    },
    {
      "x": -4,
      "y": 1,
      "z": 4,
      "name": "Rock_Sandstone_Red"
    },
    {
      "x": -4,
      "y": 2,
      "z": 4,
      "name": "Rock_Sandstone_Red"
    },
    {
      "x": -4,
      "y": 3,
      "z": 4,
      "name": "Rubble_Sandstone_Red"
    },
    {
      "x": -4,
      "y": 1,
      "z": 5,
      "name": "Rock_Sandstone_Red"
    },
    {
      "x": -3,
      "y": 1,
      "z": -5,
      "name": "Rock_Sandstone_Red"
    },
    {
      "x": -3,
      "y": 2,
      "z": -5,
      "name": "Plant_Vine_Wall_Dry",
      "rotation": 2
    },
    {
      "x": -3,
      "y": 3,
      "z": -5,
      "name": "Plant_Vine_Wall_Dry",
      "rotation": 2
    },
    {
      "x": -3,
      "y": 0,
      "z": -4,
      "name": "Rock_Sandstone_Red"
    },
    {
      "x": -3,
      "y": 1,
      "z": -4,
      "name": "Rock_Sandstone_Red"
    },
    {
      "x": -3,
      "y": 2,
      "z": -4,
      "name": "Rock_Sandstone_Red"
    },
    {
      "x": -3,
      "y": 3,
      "z": -4,
      "name": "Soil_Sand_Red"
    },
    {
      "x": -3,
      "y": 4,
      "z": -4,
      "name": "Plant_Vine_Rug"
    },
    {
      "x": -3,
      "y": 0,
      "z": -3,
      "name": "Rock_Sandstone_Red"
    },
    {
      "x": -3,
      "y": 1,
      "z": -3,
      "name": "Rock_Sandstone_Red"
    },
    {
      "x": -3,
      "y": 2,
      "z": -3,
      "name": "Rock_Sandstone_Red"
    },
    {
      "x": -3,
      "y": 3,
      "z": -3,
      "name": "Rock_Sandstone_Red"
    },
    {
      "x": -3,
      "y": 4,
      "z": -3,
      "name": "Soil_Sand_Red"
    },
    {
      "x": -3,
      "y": 0,
      "z": -2,
      "name": "Rock_Sandstone_Red"
    },
    {
      "x": -3,
      "y": 1,
      "z": -2,
      "name": "Rock_Sandstone_Red"
    },
    {
      "x": -3,
      "y": 2,
      "z": -2,
      "name": "Rock_Sandstone_Red"
    },
    {
      "x": -3,
      "y": 3,
      "z": -2,
      "name": "Rock_Sandstone_Red"
    },
    {
      "x": -3,
      "y": 4,
      "z": -2,
      "name": "Soil_Sand_Red"
    },
    {
      "x": -3,
      "y": 0,
      "z": -1,
      "name": "Rock_Sandstone_Red"
    },
    {
      "x": -3,
      "y": 1,
      "z": -1,
      "name": "Rock_Sandstone_Red"
    },
    {
      "x": -3,
      "y": 2,
      "z": -1,
      "name": "Rock_Sandstone_Red"
    },
    {
      "x": -3,
      "y": 3,
      "z": -1,
      "name": "Rock_Sandstone_Red"
    },
    {
      "x": -3,
      "y": 4,
      "z": -1,
      "name": "Soil_Sand_Red"
    },
    {
      "x": -3,
      "y": 0,
      "z": 0,
      "name": "Rock_Sandstone_Red"
    },
    {
      "x": -3,
      "y": 1,
      "z": 0,
      "name": "Rock_Sandstone_Red"
    },
    {
      "x": -3,
      "y": 2,
      "z": 0,
      "name": "Rock_Sandstone_Red"
    },
    {
      "x": -3,
      "y": 3,
      "z": 0,
      "name": "Rock_Sandstone_Red"
    },
    {
      "x": -3,
      "y": 4,
      "z": 0,
      "name": "Soil_Sand_Red"
    },
    {
      "x": -3,
      "y": 0,
      "z": 1,
      "name": "Rock_Sandstone_Red"
    },
    {
      "x": -3,
      "y": 1,
      "z": 1,
      "name": "Rock_Sandstone_Red"
    },
    {
      "x": -3,
      "y": 2,
      "z": 1,
      "name": "Rock_Sandstone_Red"
    },
    {
      "x": -3,
      "y": 3,
      "z": 1,
      "name": "Rock_Sandstone_Red"
    },
    {
      "x": -3,
      "y": 4,
      "z": 1,
      "name": "Soil_Sand_Red"
    },
    {
      "x": -3,
      "y": 0,
      "z": 2,
      "name": "Rock_Sandstone_Red"
    },
    {
      "x": -3,
      "y": 1,
      "z": 2,
      "name": "Rock_Sandstone_Red"
    },
    {
      "x": -3,
      "y": 2,
      "z": 2,
      "name": "Rock_Sandstone_Red"
    },
    {
      "x": -3,
      "y": 3,
      "z": 2,
      "name": "Soil_Sand_Red"
    },
    {
      "x": -3,
      "y": 0,
      "z": 3,
      "name": "Rock_Sandstone_Red"
    },
    {
      "x": -3,
      "y": 1,
      "z": 3,
      "name": "Rock_Sandstone_Red"
    },
    {
      "x": -3,
      "y": 2,
      "z": 3,
      "name": "Rock_Sandstone_Red"
    },
    {
      "x": -3,
      "y": 3,
      "z": 3,
      "name": "Rock_Sandstone_Red"
    },
    {
      "x": -3,
      "y": 4,
      "z": 3,
      "name": "Rubble_Sandstone_Red"
    },
    {
      "x": -3,
      "y": 0,
      "z": 4,
      "name": "Rock_Sandstone_Red"
    },
    {
      "x": -3,
      "y": 1,
      "z": 4,
      "name": "Rock_Sandstone_Red"
    },
    {
      "x": -3,
      "y": 2,
      "z": 4,
      "name": "Rock_Sandstone_Red"
    },
    {
      "x": -3,
      "y": 3,
      "z": 4,
      "name": "Rock_Sandstone_Red"
    },
    {
      "x": -3,
      "y": 4,
      "z": 4,
      "name": "Plant_Vine_Rug"
    },
    {
      "x": -3,
      "y": 1,
      "z": 5,
      "name": "Rock_Sandstone_Red"
    },
    {
      "x": -3,
      "y": 2,
      "z": 5,
      "name": "Plant_Vine_Wall_Dry"
    },
    {
      "x": -3,
      "y": 3,
      "z": 5,
      "name": "Plant_Vine_Wall_Dry"
    },
    {
      "x": -2,
      "y": 0,
      "z": -5,
      "name": "Rock_Sandstone_Red"
    },
    {
      "x": -2,
      "y": 1,
      "z": -5,
      "name": "Rock_Sandstone_Red"
    },
    {
      "x": -2,
      "y": 0,
      "z": -4,
      "name": "Rock_Sandstone_Red"
    },
    {
      "x": -2,
      "y": 1,
      "z": -4,
      "name": "Rock_Sandstone_Red"
    },
    {
      "x": -2,
      "y": 2,
      "z": -4,
      "name": "Rock_Sandstone_Red"
    },
    {
      "x": -2,
      "y": 3,
      "z": -4,
      "name": "Rock_Sandstone_Red"
    },
    {
      "x": -2,
      "y": 4,
      "z": -4,
      "name": "Soil_Sand_Red"
    },
    {
      "x": -2,
      "y": 0,
      "z": -3,
      "name": "Rock_Sandstone_Red"
    },
    {
      "x": -2,
      "y": 1,
      "z": -3,
      "name": "Rock_Sandstone_Red"
    },
    {
      "x": -2,
      "y": 2,
      "z": -3,
      "name": "Rock_Sandstone_Red"
    },
    {
      "x": -2,
      "y": 3,
      "z": -3,
      "name": "Rock_Sandstone_Red"
    },
    {
      "x": -2,
      "y": 4,
      "z": -3,
      "name": "Soil_Sand_Red"
    },
    {
      "x": -2,
      "y": 0,
      "z": -2,
      "name": "Rock_Sandstone_Red"
    },
    {
      "x": -2,
      "y": 1,
      "z": -2,
      "name": "Rock_Sandstone_Red"
    },
    {
      "x": -2,
      "y": 2,
      "z": -2,
      "name": "Rock_Sandstone_Red"
    },
    {
      "x": -2,
      "y": 3,
      "z": -2,
      "name": "Rock_Sandstone_Red"
    },
    {
      "x": -2,
      "y": 4,
      "z": -2,
      "name": "Soil_Sand_Red"
    },
    {
      "x": -2,
      "y": 0,
      "z": -1,
      "name": "Rock_Sandstone_Red"
    },
    {
      "x": -2,
      "y": 1,
      "z": -1,
      "name": "Rock_Sandstone_Red"
    },
    {
      "x": -2,
      "y": 2,
      "z": -1,
      "name": "Rock_Sandstone_Red"
    },
    {
      "x": -2,
      "y": 3,
      "z": -1,
      "name": "Rock_Sandstone_Red"
    },
    {
      "x": -2,
      "y": 4,
      "z": -1,
      "name": "Soil_Sand_Red"
    },
    {
      "x": -2,
      "y": 0,
      "z": 0,
      "name": "Rock_Sandstone_Red"
    },
    {
      "x": -2,
      "y": 1,
      "z": 0,
      "name": "Rock_Sandstone_Red"
    },
    {
      "x": -2,
      "y": 2,
      "z": 0,
      "name": "Rock_Sandstone_Red"
    },
    {
      "x": -2,
      "y": 3,
      "z": 0,
      "name": "Rock_Sandstone_Red"
    },
    {
      "x": -2,
      "y": 4,
      "z": 0,
      "name": "Soil_Sand_Red"
    },
    {
      "x": -2,
      "y": 5,
      "z": 0,
      "name": "Rubble_Sandstone_Red_Medium"
    },
    {
      "x": -2,
      "y": 0,
      "z": 1,
      "name": "Rock_Sandstone_Red"
    },
    {
      "x": -2,
      "y": 1,
      "z": 1,
      "name": "Rock_Sandstone_Red"
    },
    {
      "x": -2,
      "y": 2,
      "z": 1,
      "name": "Rock_Sandstone_Red"
    },
    {
      "x": -2,
      "y": 3,
      "z": 1,
      "name": "Rock_Sandstone_Red"
    },
    {
      "x": -2,
      "y": 4,
      "z": 1,
      "name": "Soil_Sand_Red"
    },
    {
      "x": -2,
      "y": 5,
      "z": 1,
      "name": "Rubble_Sandstone_Red"
    },
    {
      "x": -2,
      "y": 0,
      "z": 2,
      "name": "Rock_Sandstone_Red"
    },
    {
      "x": -2,
      "y": 1,
      "z": 2,
      "name": "Rock_Sandstone_Red"
    },
    {
      "x": -2,
      "y": 2,
      "z": 2,
      "name": "Rock_Sandstone_Red"
    },
    {
      "x": -2,
      "y": 3,
      "z": 2,
      "name": "Rock_Sandstone_Red"
    },
    {
      "x": -2,
      "y": 4,
      "z": 2,
      "name": "Soil_Sand_Red"
    },
    {
      "x": -2,
      "y": 0,
      "z": 3,
      "name": "Rock_Sandstone_Red"
    },
    {
      "x": -2,
      "y": 1,
      "z": 3,
      "name": "Rock_Sandstone_Red"
    },
    {
      "x": -2,
      "y": 2,
      "z": 3,
      "name": "Rock_Sandstone_Red"
    },
    {
      "x": -2,
      "y": 3,
      "z": 3,
      "name": "Rock_Sandstone_Red"
    },
    {
      "x": -2,
      "y": 4,
      "z": 3,
      "name": "Soil_Sand_Red"
    },
    {
      "x": -2,
      "y": 0,
      "z": 4,
      "name": "Rock_Sandstone_Red"
    },
    {
      "x": -2,
      "y": 1,
      "z": 4,
      "name": "Rock_Sandstone_Red"
    },
    {
      "x": -2,
      "y": 2,
      "z": 4,
      "name": "Rock_Sandstone_Red"
    },
    {
      "x": -2,
      "y": 3,
      "z": 4,
      "name": "Rock_Sandstone_Red"
    },
    {
      "x": -2,
      "y": 4,
      "z": 4,
      "name": "Soil_Sand_Red"
    },
    {
      "x": -2,
      "y": 0,
      "z": 5,
      "name": "Rock_Sandstone_Red"
    },
    {
      "x": -2,
      "y": 1,
      "z": 5,
      "name": "Rock_Sandstone_Red"
    },
    {
      "x": -2,
      "y": 2,
      "z": 5,
      "name": "Rock_Sandstone_Red"
    },
    {
      "x": -2,
      "y": 1,
      "z": 6,
      "name": "Rock_Sandstone_Red"
    },
    {
      "x": -1,
      "y": 0,
      "z": -5,
      "name": "Rock_Sandstone_Red"
    },
    {
      "x": -1,
      "y": 1,
      "z": -5,
      "name": "Rock_Sandstone_Red"
    },
    {
      "x": -1,
      "y": 0,
      "z": -4,
      "name": "Rock_Sandstone_Red"
    },
    {
      "x": -1,
      "y": 1,
      "z": -4,
      "name": "Rock_Sandstone_Red"
    },
    {
      "x": -1,
      "y": 2,
      "z": -4,
      "name": "Rock_Sandstone_Red"
    },
    {
      "x": -1,
      "y": 3,
      "z": -4,
      "name": "Rock_Sandstone_Red"
    },
    {
      "x": -1,
      "y": 4,
      "z": -4,
      "name": "Soil_Sand_Red"
    },
    {
      "x": -1,
      "y": 0,
      "z": -3,
      "name": "Rock_Sandstone_Red"
    },
    {
      "x": -1,
      "y": 1,
      "z": -3,
      "name": "Rock_Sandstone_Red"
    },
    {
      "x": -1,
      "y": 2,
      "z": -3,
      "name": "Rock_Sandstone_Red"
    },
    {
      "x": -1,
      "y": 3,
      "z": -3,
      "name": "Rock_Sandstone_Red"
    },
    {
      "x": -1,
      "y": 4,
      "z": -3,
      "name": "Soil_Sand_Red"
    },
    {
      "x": -1,
      "y": 0,
      "z": -2,
      "name": "Rock_Sandstone_Red"
    },
    {
      "x": -1,
      "y": 1,
      "z": -2,
      "name": "Rock_Sandstone_Red"
    },
    {
      "x": -1,
      "y": 2,
      "z": -2,
      "name": "Rock_Sandstone_Red"
    },
    {
      "x": -1,
      "y": 3,
      "z": -2,
      "name": "Rock_Sandstone_Red"
    },
    {
      "x": -1,
      "y": 4,
      "z": -2,
      "name": "Soil_Sand_Red"
    },
    {
      "x": -1,
      "y": 0,
      "z": -1,
      "name": "Rock_Sandstone_Red"
    },
    {
      "x": -1,
      "y": 1,
      "z": -1,
      "name": "Rock_Sandstone_Red"
    },
    {
      "x": -1,
      "y": 2,
      "z": -1,
      "name": "Rock_Sandstone_Red"
    },
    {
      "x": -1,
      "y": 3,
      "z": -1,
      "name": "Rock_Sandstone_Red"
    },
    {
      "x": -1,
      "y": 4,
      "z": -1,
      "name": "Rock_Sandstone_Red_Cobble"
    },
    {
      "x": -1,
      "y": 5,
      "z": -1,
      "name": "Rubble_Sandstone_Red_Medium"
    },
    {
      "x": -1,
      "y": 0,
      "z": 0,
      "name": "Rock_Sandstone_Red"
    },
    {
      "x": -1,
      "y": 1,
      "z": 0,
      "name": "Rock_Sandstone_Red"
    },
    {
      "x": -1,
      "y": 2,
      "z": 0,
      "name": "Rock_Sandstone_Red"
    },
    {
      "x": -1,
      "y": 3,
      "z": 0,
      "name": "Rock_Sandstone_Red"
    },
    {
      "x": -1,
      "y": 4,
      "z": 0,
      "name": "Rock_Sandstone_Red_Cobble"
    },
    {
      "x": -1,
      "y": 5,
      "z": 0,
      "name": "Rubble_Sandstone_Red_Medium"
    },
    {
      "x": -1,
      "y": 0,
      "z": 1,
      "name": "Rock_Sandstone_Red"
    },
    {
      "x": -1,
      "y": 1,
      "z": 1,
      "name": "Rock_Sandstone_Red"
    },
    {
      "x": -1,
      "y": 2,
      "z": 1,
      "name": "Rock_Sandstone_Red"
    },
    {
      "x": -1,
      "y": 3,
      "z": 1,
      "name": "Rock_Sandstone_Red"
    },
    {
      "x": -1,
      "y": 4,
      "z": 1,
      "name": "Rock_Sandstone_Red_Cobble"
    },
    {
      "x": -1,
      "y": 5,
      "z": 1,
      "name": "Rubble_Sandstone_Red_Medium"
    },
    {
      "x": -1,
      "y": 0,
      "z": 2,
      "name": "Rock_Sandstone_Red"
    },
    {
      "x": -1,
      "y": 1,
      "z": 2,
      "name": "Rock_Sandstone_Red"
    },
    {
      "x": -1,
      "y": 2,
      "z": 2,
      "name": "Rock_Sandstone_Red"
    },
    {
      "x": -1,
      "y": 3,
      "z": 2,
      "name": "Rock_Sandstone_Red"
    },
    {
      "x": -1,
      "y": 4,
      "z": 2,
      "name": "Soil_Sand_Red"
    },
    {
      "x": -1,
      "y": 0,
      "z": 3,
      "name": "Rock_Sandstone_Red"
    },
    {
      "x": -1,
      "y": 1,
      "z": 3,
      "name": "Rock_Sandstone_Red"
    },
    {
      "x": -1,
      "y": 2,
      "z": 3,
      "name": "Rock_Sandstone_Red"
    },
    {
      "x": -1,
      "y": 3,
      "z": 3,
      "name": "Rock_Sandstone_Red"
    },
    {
      "x": -1,
      "y": 4,
      "z": 3,
      "name": "Soil_Sand_Red"
    },
    {
      "x": -1,
      "y": 0,
      "z": 4,
      "name": "Rock_Sandstone_Red"
    },
    {
      "x": -1,
      "y": 1,
      "z": 4,
      "name": "Rock_Sandstone_Red"
    },
    {
      "x": -1,
      "y": 2,
      "z": 4,
      "name": "Rock_Sandstone_Red"
    },
    {
      "x": -1,
      "y": 3,
      "z": 4,
      "name": "Rock_Sandstone_Red"
    },
    {
      "x": -1,
      "y": 4,
      "z": 4,
      "name": "Soil_Sand_Red"
    },
    {
      "x": -1,
      "y": 0,
      "z": 5,
      "name": "Rock_Sandstone_Red"
    },
    {
      "x": -1,
      "y": 1,
      "z": 5,
      "name": "Rock_Sandstone_Red"
    },
    {
      "x": -1,
      "y": 2,
      "z": 5,
      "name": "Rock_Sandstone_Red"
    },
    {
      "x": -1,
      "y": 3,
      "z": 5,
      "name": "Rock_Sandstone_Red"
    },
    {
      "x": -1,
      "y": 1,
      "z": 6,
      "name": "Rock_Sandstone_Red"
    },
    {
      "x": 0,
      "y": 1,
      "z": -5,
      "name": "Rock_Sandstone_Red"
    },
    {
      "x": 0,
      "y": 2,
      "z": -5,
      "name": "Rock_Sandstone_Red"
    },
    {
      "x": 0,
      "y": 3,
      "z": -5,
      "name": "Rock_Sandstone_Red"
    },
    {
      "x": 0,
      "y": 4,
      "z": -5,
      "name": "Soil_Sand_Red"
    },
    {
      "x": 0,
      "y": 0,
      "z": -4,
      "name": "Rock_Sandstone_Red"
    },
    {
      "x": 0,
      "y": 1,
      "z": -4,
      "name": "Rock_Sandstone_Red"
    },
    {
      "x": 0,
      "y": 2,
      "z": -4,
      "name": "Rock_Sandstone_Red"
    },
    {
      "x": 0,
      "y": 3,
      "z": -4,
      "name": "Rock_Sandstone_Red"
    },
    {
      "x": 0,
      "y": 4,
      "z": -4,
      "name": "Soil_Sand_Red"
    },
    {
      "x": 0,
      "y": 0,
      "z": -3,
      "name": "Rock_Sandstone_Red"
    },
    {
      "x": 0,
      "y": 1,
      "z": -3,
      "name": "Rock_Sandstone_Red"
    },
    {
      "x": 0,
      "y": 2,
      "z": -3,
      "name": "Rock_Sandstone_Red"
    },
    {
      "x": 0,
      "y": 3,
      "z": -3,
      "name": "Rock_Sandstone_Red"
    },
    {
      "x": 0,
      "y": 4,
      "z": -3,
      "name": "Soil_Sand_Red"
    },
    {
      "x": 0,
      "y": 5,
      "z": -3,
      "name": "Rubble_Sandstone_Red_Medium"
    },
    {
      "x": 0,
      "y": 0,
      "z": -2,
      "name": "Rock_Sandstone_Red"
    },
    {
      "x": 0,
      "y": 1,
      "z": -2,
      "name": "Rock_Sandstone_Red"
    },
    {
      "x": 0,
      "y": 2,
      "z": -2,
      "name": "Rock_Sandstone_Red"
    },
    {
      "x": 0,
      "y": 3,
      "z": -2,
      "name": "Rock_Sandstone_Red"
    },
    {
      "x": 0,
      "y": 4,
      "z": -2,
      "name": "Rock_Sandstone_Red_Cobble"
    },
    {
      "x": 0,
      "y": 5,
      "z": -2,
      "name": "Rubble_Sandstone_Red_Medium"
    },
    {
      "x": 0,
      "y": 0,
      "z": -1,
      "name": "Rock_Sandstone_Red"
    },
    {
      "x": 0,
      "y": 1,
      "z": -1,
      "name": "Rock_Sandstone_Red"
    },
    {
      "x": 0,
      "y": 2,
      "z": -1,
      "name": "Rock_Sandstone_Red"
    },
    {
      "x": 0,
      "y": 3,
      "z": -1,
      "name": "Rock_Sandstone_Red"
    },
    {
      "x": 0,
      "y": 4,
      "z": -1,
      "name": "Rock_Sandstone_Red_Cobble"
    },
    {
      "x": 0,
      "y": 5,
      "z": -1,
      "name": "Rock_Sandstone_Red_Cobble"
    },
    {
      "x": 0,
      "y": 6,
      "z": -1,
      "name": "Rubble_Sandstone_Red_Medium"
    },
    {
      "x": 0,
      "y": 0,
      "z": 0,
      "name": "Rock_Sandstone_Red"
    },
    {
      "x": 0,
      "y": 1,
      "z": 0,
      "name": "Rock_Sandstone_Red"
    },
    {
      "x": 0,
      "y": 2,
      "z": 0,
      "name": "Rock_Sandstone_Red"
    },
    {
      "x": 0,
      "y": 3,
      "z": 0,
      "name": "Rock_Sandstone_Red"
    },
    {
      "x": 0,
      "y": 4,
      "z": 0,
      "name": "Rock_Sandstone_Red_Cobble"
    },
    {
      "x": 0,
      "y": 5,
      "z": 0,
      "name": "Rubble_Sandstone_Red_Medium"
    },
    {
      "x": 0,
      "y": 0,
      "z": 1,
      "name": "Rock_Sandstone_Red"
    },
    {
      "x": 0,
      "y": 1,
      "z": 1,
      "name": "Rock_Sandstone_Red"
    },
    {
      "x": 0,
      "y": 2,
      "z": 1,
      "name": "Rock_Sandstone_Red"
    },
    {
      "x": 0,
      "y": 3,
      "z": 1,
      "name": "Rock_Sandstone_Red"
    },
    {
      "x": 0,
      "y": 4,
      "z": 1,
      "name": "Soil_Sand_Red"
    },
    {
      "x": 0,
      "y": 0,
      "z": 2,
      "name": "Rock_Sandstone_Red"
    },
    {
      "x": 0,
      "y": 1,
      "z": 2,
      "name": "Rock_Sandstone_Red"
    },
    {
      "x": 0,
      "y": 2,
      "z": 2,
      "name": "Rock_Sandstone_Red"
    },
    {
      "x": 0,
      "y": 3,
      "z": 2,
      "name": "Rock_Sandstone_Red"
    },
    {
      "x": 0,
      "y": 4,
      "z": 2,
      "name": "Soil_Sand_Red"
    },
    {
      "x": 0,
      "y": 0,
      "z": 3,
      "name": "Rock_Sandstone_Red"
    },
    {
      "x": 0,
      "y": 1,
      "z": 3,
      "name": "Rock_Sandstone_Red"
    },
    {
      "x": 0,
      "y": 2,
      "z": 3,
      "name": "Rock_Sandstone_Red"
    },
    {
      "x": 0,
      "y": 3,
      "z": 3,
      "name": "Rock_Sandstone_Red"
    },
    {
      "x": 0,
      "y": 4,
      "z": 3,
      "name": "Soil_Sand_Red"
    },
    {
      "x": 0,
      "y": 0,
      "z": 4,
      "name": "Rock_Sandstone_Red"
    },
    {
      "x": 0,
      "y": 1,
      "z": 4,
      "name": "Rock_Sandstone_Red"
    },
    {
      "x": 0,
      "y": 2,
      "z": 4,
      "name": "Rock_Sandstone_Red"
    },
    {
      "x": 0,
      "y": 3,
      "z": 4,
      "name": "Rock_Sandstone_Red"
    },
    {
      "x": 0,
      "y": 4,
      "z": 4,
      "name": "Soil_Sand_Red"
    },
    {
      "x": 0,
      "y": 0,
      "z": 5,
      "name": "Rock_Sandstone_Red"
    },
    {
      "x": 0,
      "y": 1,
      "z": 5,
      "name": "Rock_Sandstone_Red"
    },
    {
      "x": 0,
      "y": 2,
      "z": 5,
      "name": "Rock_Sandstone_Red"
    },
    {
      "x": 0,
      "y": 3,
      "z": 5,
      "name": "Soil_Sand_Red"
    },
    {
      "x": 0,
      "y": 1,
      "z": 6,
      "name": "Rock_Sandstone_Red"
    },
    {
      "x": 0,
      "y": 2,
      "z": 6,
      "name": "Rock_Sandstone_Red"
    },
    {
      "x": 1,
      "y": 1,
      "z": -5,
      "name": "Rock_Sandstone_Red"
    },
    {
      "x": 1,
      "y": 2,
      "z": -5,
      "name": "Rock_Sandstone_Red"
    },
    {
      "x": 1,
      "y": 3,
      "z": -5,
      "name": "Rock_Sandstone_Red"
    },
    {
      "x": 1,
      "y": 4,
      "z": -5,
      "name": "Soil_Sand_Red"
    },
    {
      "x": 1,
      "y": 0,
      "z": -4,
      "name": "Rock_Sandstone_Red"
    },
    {
      "x": 1,
      "y": 1,
      "z": -4,
      "name": "Rock_Sandstone_Red"
    },
    {
      "x": 1,
      "y": 2,
      "z": -4,
      "name": "Rock_Sandstone_Red"
    },
    {
      "x": 1,
      "y": 3,
      "z": -4,
      "name": "Rock_Sandstone_Red"
    },
    {
      "x": 1,
      "y": 4,
      "z": -4,
      "name": "Soil_Sand_Red"
    },
    {
      "x": 1,
      "y": 0,
      "z": -3,
      "name": "Rock_Sandstone_Red"
    },
    {
      "x": 1,
      "y": 1,
      "z": -3,
      "name": "Rock_Sandstone_Red"
    },
    {
      "x": 1,
      "y": 2,
      "z": -3,
      "name": "Rock_Sandstone_Red"
    },
    {
      "x": 1,
      "y": 3,
      "z": -3,
      "name": "Rock_Sandstone_Red"
    },
    {
      "x": 1,
      "y": 4,
      "z": -3,
      "name": "Soil_Sand_Red"
    },
    {
      "x": 1,
      "y": 5,
      "z": -3,
      "name": "Rubble_Sandstone_Red"
    },
    {
      "x": 1,
      "y": 0,
      "z": -2,
      "name": "Rock_Sandstone_Red"
    },
    {
      "x": 1,
      "y": 1,
      "z": -2,
      "name": "Rock_Sandstone_Red"
    },
    {
      "x": 1,
      "y": 2,
      "z": -2,
      "name": "Rock_Sandstone_Red"
    },
    {
      "x": 1,
      "y": 3,
      "z": -2,
      "name": "Rock_Sandstone_Red"
    },
    {
      "x": 1,
      "y": 4,
      "z": -2,
      "name": "Rock_Sandstone_Red_Cobble"
    },
    {
      "x": 1,
      "y": 5,
      "z": -2,
      "name": "Rubble_Sandstone_Red"
    },
    {
      "x": 1,
      "y": 0,
      "z": -1,
      "name": "Rock_Sandstone_Red"
    },
    {
      "x": 1,
      "y": 1,
      "z": -1,
      "name": "Rock_Sandstone_Red"
    },
    {
      "x": 1,
      "y": 2,
      "z": -1,
      "name": "Rock_Sandstone_Red"
    },
    {
      "x": 1,
      "y": 3,
      "z": -1,
      "name": "Rock_Sandstone_Red"
    },
    {
      "x": 1,
      "y": 4,
      "z": -1,
      "name": "Rock_Sandstone_Red_Cobble"
    },
    {
      "x": 1,
      "y": 5,
      "z": -1,
      "name": "Rubble_Sandstone_Red_Medium"
    },
    {
      "x": 1,
      "y": 0,
      "z": 0,
      "name": "Rock_Sandstone_Red"
    },
    {
      "x": 1,
      "y": 1,
      "z": 0,
      "name": "Rock_Sandstone_Red"
    },
    {
      "x": 1,
      "y": 2,
      "z": 0,
      "name": "Rock_Sandstone_Red"
    },
    {
      "x": 1,
      "y": 3,
      "z": 0,
      "name": "Rock_Sandstone_Red"
    },
    {
      "x": 1,
      "y": 4,
      "z": 0,
      "name": "Soil_Sand_Red"
    },
    {
      "x": 1,
      "y": 0,
      "z": 1,
      "name": "Rock_Sandstone_Red"
    },
    {
      "x": 1,
      "y": 1,
      "z": 1,
      "name": "Rock_Sandstone_Red"
    },
    {
      "x": 1,
      "y": 2,
      "z": 1,
      "name": "Rock_Sandstone_Red"
    },
    {
      "x": 1,
      "y": 3,
      "z": 1,
      "name": "Rock_Sandstone_Red"
    },
    {
      "x": 1,
      "y": 4,
      "z": 1,
      "name": "Soil_Sand_Red"
    },
    {
      "x": 1,
      "y": 0,
      "z": 2,
      "name": "Rock_Sandstone_Red"
    },
    {
      "x": 1,
      "y": 1,
      "z": 2,
      "name": "Rock_Sandstone_Red"
    },
    {
      "x": 1,
      "y": 2,
      "z": 2,
      "name": "Rock_Sandstone_Red"
    },
    {
      "x": 1,
      "y": 3,
      "z": 2,
      "name": "Soil_Sand_Red"
    },
    {
      "x": 1,
      "y": 0,
      "z": 3,
      "name": "Rock_Sandstone_Red"
    },
    {
      "x": 1,
      "y": 1,
      "z": 3,
      "name": "Rock_Sandstone_Red"
    },
    {
      "x": 1,
      "y": 2,
      "z": 3,
      "name": "Rock_Sandstone_Red"
    },
    {
      "x": 1,
      "y": 3,
      "z": 3,
      "name": "Soil_Sand_Red"
    },
    {
      "x": 1,
      "y": 0,
      "z": 4,
      "name": "Rock_Sandstone_Red"
    },
    {
      "x": 1,
      "y": 1,
      "z": 4,
      "name": "Rock_Sandstone_Red"
    },
    {
      "x": 1,
      "y": 2,
      "z": 4,
      "name": "Rock_Sandstone_Red"
    },
    {
      "x": 1,
      "y": 3,
      "z": 4,
      "name": "Soil_Sand_Red"
    },
    {
      "x": 1,
      "y": 0,
      "z": 5,
      "name": "Rock_Sandstone_Red"
    },
    {
      "x": 1,
      "y": 1,
      "z": 5,
      "name": "Rock_Sandstone_Red"
    },
    {
      "x": 1,
      "y": 2,
      "z": 5,
      "name": "Rock_Sandstone_Red"
    },
    {
      "x": 1,
      "y": 3,
      "z": 5,
      "name": "Soil_Sand_Red"
    },
    {
      "x": 1,
      "y": 1,
      "z": 6,
      "name": "Rock_Sandstone_Red"
    },
    {
      "x": 1,
      "y": 2,
      "z": 6,
      "name": "Rock_Sandstone_Red"
    },
    {
      "x": 2,
      "y": 1,
      "z": -5,
      "name": "Rock_Sandstone_Red"
    },
    {
      "x": 2,
      "y": 1,
      "z": -4,
      "name": "Rock_Sandstone_Red"
    },
    {
      "x": 2,
      "y": 2,
      "z": -4,
      "name": "Rock_Sandstone_Red"
    },
    {
      "x": 2,
      "y": 3,
      "z": -4,
      "name": "Rock_Sandstone_Red"
    },
    {
      "x": 2,
      "y": 4,
      "z": -4,
      "name": "Soil_Sand_Red"
    },
    {
      "x": 2,
      "y": 0,
      "z": -3,
      "name": "Rock_Sandstone_Red"
    },
    {
      "x": 2,
      "y": 1,
      "z": -3,
      "name": "Rock_Sandstone_Red"
    },
    {
      "x": 2,
      "y": 2,
      "z": -3,
      "name": "Rock_Sandstone_Red"
    },
    {
      "x": 2,
      "y": 3,
      "z": -3,
      "name": "Rock_Sandstone_Red"
    },
    {
      "x": 2,
      "y": 4,
      "z": -3,
      "name": "Soil_Sand_Red"
    },
    {
      "x": 2,
      "y": 0,
      "z": -2,
      "name": "Rock_Sandstone_Red"
    },
    {
      "x": 2,
      "y": 1,
      "z": -2,
      "name": "Rock_Sandstone_Red"
    },
    {
      "x": 2,
      "y": 2,
      "z": -2,
      "name": "Rock_Sandstone_Red"
    },
    {
      "x": 2,
      "y": 3,
      "z": -2,
      "name": "Rock_Sandstone_Red"
    },
    {
      "x": 2,
      "y": 4,
      "z": -2,
      "name": "Soil_Sand_Red"
    },
    {
      "x": 2,
      "y": 0,
      "z": -1,
      "name": "Rock_Sandstone_Red"
    },
    {
      "x": 2,
      "y": 1,
      "z": -1,
      "name": "Rock_Sandstone_Red"
    },
    {
      "x": 2,
      "y": 2,
      "z": -1,
      "name": "Rock_Sandstone_Red"
    },
    {
      "x": 2,
      "y": 3,
      "z": -1,
      "name": "Rock_Sandstone_Red"
    },
    {
      "x": 2,
      "y": 4,
      "z": -1,
      "name": "Soil_Sand_Red"
    },
    {
      "x": 2,
      "y": 0,
      "z": 0,
      "name": "Rock_Sandstone_Red"
    },
    {
      "x": 2,
      "y": 1,
      "z": 0,
      "name": "Rock_Sandstone_Red"
    },
    {
      "x": 2,
      "y": 2,
      "z": 0,
      "name": "Rock_Sandstone_Red"
    },
    {
      "x": 2,
      "y": 3,
      "z": 0,
      "name": "Rock_Sandstone_Red"
    },
    {
      "x": 2,
      "y": 4,
      "z": 0,
      "name": "Soil_Sand_Red"
    },
    {
      "x": 2,
      "y": 0,
      "z": 1,
      "name": "Rock_Sandstone_Red"
    },
    {
      "x": 2,
      "y": 1,
      "z": 1,
      "name": "Rock_Sandstone_Red"
    },
    {
      "x": 2,
      "y": 2,
      "z": 1,
      "name": "Rock_Sandstone_Red"
    },
    {
      "x": 2,
      "y": 3,
      "z": 1,
      "name": "Soil_Sand_Red"
    },
    {
      "x": 2,
      "y": 0,
      "z": 2,
      "name": "Rock_Sandstone_Red"
    },
    {
      "x": 2,
      "y": 1,
      "z": 2,
      "name": "Rock_Sandstone_Red"
    },
    {
      "x": 2,
      "y": 2,
      "z": 2,
      "name": "Rock_Sandstone_Red"
    },
    {
      "x": 2,
      "y": 3,
      "z": 2,
      "name": "Soil_Sand_Red"
    },
    {
      "x": 2,
      "y": 0,
      "z": 3,
      "name": "Rock_Sandstone_Red"
    },
    {
      "x": 2,
      "y": 1,
      "z": 3,
      "name": "Rock_Sandstone_Red"
    },
    {
      "x": 2,
      "y": 2,
      "z": 3,
      "name": "Rock_Sandstone_Red"
    },
    {
      "x": 2,
      "y": 3,
      "z": 3,
      "name": "Soil_Sand_Red"
    },
    {
      "x": 2,
      "y": 0,
      "z": 4,
      "name": "Rock_Sandstone_Red"
    },
    {
      "x": 2,
      "y": 1,
      "z": 4,
      "name": "Rock_Sandstone_Red"
    },
    {
      "x": 2,
      "y": 2,
      "z": 4,
      "name": "Rock_Sandstone_Red"
    },
    {
      "x": 2,
      "y": 3,
      "z": 4,
      "name": "Soil_Sand_Red"
    },
    {
      "x": 2,
      "y": 0,
      "z": 5,
      "name": "Rock_Sandstone_Red"
    },
    {
      "x": 2,
      "y": 1,
      "z": 5,
      "name": "Rock_Sandstone_Red"
    },
    {
      "x": 2,
      "y": 2,
      "z": 5,
      "name": "Rock_Sandstone_Red"
    },
    {
      "x": 2,
      "y": 3,
      "z": 5,
      "name": "Soil_Sand_Red"
    },
    {
      "x": 2,
      "y": 1,
      "z": 6,
      "name": "Rock_Sandstone_Red"
    },
    {
      "x": 2,
      "y": 2,
      "z": 6,
      "name": "Soil_Sand_Red"
    },
    {
      "x": 3,
      "y": 1,
      "z": -4,
      "name": "Rock_Sandstone_Red"
    },
    {
      "x": 3,
      "y": 0,
      "z": -3,
      "name": "Rock_Sandstone_Red"
    },
    {
      "x": 3,
      "y": 1,
      "z": -3,
      "name": "Rock_Sandstone_Red"
    },
    {
      "x": 3,
      "y": 2,
      "z": -3,
      "name": "Rock_Sandstone_Red"
    },
    {
      "x": 3,
      "y": 3,
      "z": -3,
      "name": "Soil_Sand_Red"
    },
    {
      "x": 3,
      "y": 4,
      "z": -3,
      "name": "Soil_Sand_Red"
    },
    {
      "x": 3,
      "y": 0,
      "z": -2,
      "name": "Rock_Sandstone_Red"
    },
    {
      "x": 3,
      "y": 1,
      "z": -2,
      "name": "Rock_Sandstone_Red"
    },
    {
      "x": 3,
      "y": 2,
      "z": -2,
      "name": "Rock_Sandstone_Red"
    },
    {
      "x": 3,
      "y": 3,
      "z": -2,
      "name": "Rock_Sandstone_Red"
    },
    {
      "x": 3,
      "y": 4,
      "z": -2,
      "name": "Soil_Sand_Red"
    },
    {
      "x": 3,
      "y": 0,
      "z": -1,
      "name": "Rock_Sandstone_Red"
    },
    {
      "x": 3,
      "y": 1,
      "z": -1,
      "name": "Rock_Sandstone_Red"
    },
    {
      "x": 3,
      "y": 2,
      "z": -1,
      "name": "Rock_Sandstone_Red"
    },
    {
      "x": 3,
      "y": 3,
      "z": -1,
      "name": "Rock_Sandstone_Red"
    },
    {
      "x": 3,
      "y": 4,
      "z": -1,
      "name": "Soil_Sand_Red"
    },
    {
      "x": 3,
      "y": 0,
      "z": 0,
      "name": "Rock_Sandstone_Red"
    },
    {
      "x": 3,
      "y": 1,
      "z": 0,
      "name": "Rock_Sandstone_Red"
    },
    {
      "x": 3,
      "y": 2,
      "z": 0,
      "name": "Rock_Sandstone_Red"
    },
    {
      "x": 3,
      "y": 3,
      "z": 0,
      "name": "Soil_Sand_Red"
    },
    {
      "x": 3,
      "y": 0,
      "z": 1,
      "name": "Rock_Sandstone_Red"
    },
    {
      "x": 3,
      "y": 1,
      "z": 1,
      "name": "Rock_Sandstone_Red"
    },
    {
      "x": 3,
      "y": 2,
      "z": 1,
      "name": "Rock_Sandstone_Red"
    },
    {
      "x": 3,
      "y": 3,
      "z": 1,
      "name": "Soil_Sand_Red"
    },
    {
      "x": 3,
      "y": 0,
      "z": 2,
      "name": "Rock_Sandstone_Red"
    },
    {
      "x": 3,
      "y": 1,
      "z": 2,
      "name": "Rock_Sandstone_Red"
    },
    {
      "x": 3,
      "y": 2,
      "z": 2,
      "name": "Rock_Sandstone_Red"
    },
    {
      "x": 3,
      "y": 3,
      "z": 2,
      "name": "Soil_Sand_Red"
    },
    {
      "x": 3,
      "y": 0,
      "z": 3,
      "name": "Rock_Sandstone_Red"
    },
    {
      "x": 3,
      "y": 1,
      "z": 3,
      "name": "Rock_Sandstone_Red"
    },
    {
      "x": 3,
      "y": 2,
      "z": 3,
      "name": "Rock_Sandstone_Red"
    },
    {
      "x": 3,
      "y": 3,
      "z": 3,
      "name": "Soil_Sand_Red"
    },
    {
      "x": 3,
      "y": 0,
      "z": 4,
      "name": "Rock_Sandstone_Red"
    },
    {
      "x": 3,
      "y": 1,
      "z": 4,
      "name": "Rock_Sandstone_Red"
    },
    {
      "x": 3,
      "y": 2,
      "z": 4,
      "name": "Rock_Sandstone_Red"
    },
    {
      "x": 3,
      "y": 3,
      "z": 4,
      "name": "Soil_Sand_Red"
    },
    {
      "x": 3,
      "y": 1,
      "z": 5,
      "name": "Rock_Sandstone_Red"
    },
    {
      "x": 3,
      "y": 2,
      "z": 5,
      "name": "Soil_Sand_Red"
    },
    {
      "x": 4,
      "y": 1,
      "z": -3,
      "name": "Rock_Sandstone_Red"
    },
    {
      "x": 4,
      "y": 0,
      "z": -2,
      "name": "Rock_Sandstone_Red"
    },
    {
      "x": 4,
      "y": 1,
      "z": -2,
      "name": "Rock_Sandstone_Red"
    },
    {
      "x": 4,
      "y": 2,
      "z": -2,
      "name": "Rock_Sandstone_Red"
    },
    {
      "x": 4,
      "y": 3,
      "z": -2,
      "name": "Soil_Sand_Red"
    },
    {
      "x": 4,
      "y": 4,
      "z": -2,
      "name": "Plant_Bush_Dead_Tall"
    },
    {
      "x": 4,
      "y": 0,
      "z": -1,
      "name": "Rock_Sandstone_Red"
    },
    {
      "x": 4,
      "y": 1,
      "z": -1,
      "name": "Rock_Sandstone_Red"
    },
    {
      "x": 4,
      "y": 2,
      "z": -1,
      "name": "Rock_Sandstone_Red"
    },
    {
      "x": 4,
      "y": 3,
      "z": -1,
      "name": "Rock_Sandstone_Red"
    },
    {
      "x": 4,
      "y": 4,
      "z": -1,
      "name": "Soil_Sand_Red"
    },
    {
      "x": 4,
      "y": 0,
      "z": 0,
      "name": "Rock_Sandstone_Red"
    },
    {
      "x": 4,
      "y": 1,
      "z": 0,
      "name": "Rock_Sandstone_Red"
    },
    {
      "x": 4,
      "y": 2,
      "z": 0,
      "name": "Rock_Sandstone_Red"
    },
    {
      "x": 4,
      "y": 3,
      "z": 0,
      "name": "Rock_Sandstone_Red"
    },
    {
      "x": 4,
      "y": 4,
      "z": 0,
      "name": "Soil_Sand_Red"
    },
    {
      "x": 4,
      "y": 0,
      "z": 1,
      "name": "Rock_Sandstone_Red"
    },
    {
      "x": 4,
      "y": 1,
      "z": 1,
      "name": "Rock_Sandstone_Red"
    },
    {
      "x": 4,
      "y": 2,
      "z": 1,
      "name": "Rock_Sandstone_Red"
    },
    {
      "x": 4,
      "y": 3,
      "z": 1,
      "name": "Soil_Sand_Red"
    },
    {
      "x": 4,
      "y": 0,
      "z": 2,
      "name": "Rock_Sandstone_Red"
    },
    {
      "x": 4,
      "y": 1,
      "z": 2,
      "name": "Rock_Sandstone_Red"
    },
    {
      "x": 4,
      "y": 2,
      "z": 2,
      "name": "Rock_Sandstone_Red"
    },
    {
      "x": 4,
      "y": 3,
      "z": 2,
      "name": "Soil_Sand_Red"
    },
    {
      "x": 4,
      "y": 0,
      "z": 3,
      "name": "Rock_Sandstone_Red"
    },
    {
      "x": 4,
      "y": 1,
      "z": 3,
      "name": "Rock_Sandstone_Red"
    },
    {
      "x": 4,
      "y": 2,
      "z": 3,
      "name": "Rock_Sandstone_Red"
    },
    {
      "x": 4,
      "y": 3,
      "z": 3,
      "name": "Soil_Sand_Red"
    },
    {
      "x": 4,
      "y": 1,
      "z": 4,
      "name": "Rock_Sandstone_Red"
    },
    {
      "x": 4,
      "y": 2,
      "z": 4,
      "name": "Soil_Sand_Red"
    },
    {
      "x": 5,
      "y": 1,
      "z": -3,
      "name": "Rock_Sandstone_Red"
    },
    {
      "x": 5,
      "y": 1,
      "z": -2,
      "name": "Rock_Sandstone_Red"
    },
    {
      "x": 5,
      "y": 2,
      "z": -2,
      "name": "Rock_Sandstone_Red"
    },
    {
      "x": 5,
      "y": 3,
      "z": -2,
      "name": "Soil_Sand_Red"
    },
    {
      "x": 5,
      "y": 0,
      "z": -1,
      "name": "Rock_Sandstone_Red"
    },
    {
      "x": 5,
      "y": 1,
      "z": -1,
      "name": "Rock_Sandstone_Red"
    },
    {
      "x": 5,
      "y": 2,
      "z": -1,
      "name": "Rock_Sandstone_Red"
    },
    {
      "x": 5,
      "y": 3,
      "z": -1,
      "name": "Soil_Sand_Red"
    },
    {
      "x": 5,
      "y": 0,
      "z": 0,
      "name": "Rock_Sandstone_Red"
    },
    {
      "x": 5,
      "y": 1,
      "z": 0,
      "name": "Rock_Sandstone_Red"
    },
    {
      "x": 5,
      "y": 2,
      "z": 0,
      "name": "Rock_Sandstone_Red"
    },
    {
      "x": 5,
      "y": 3,
      "z": 0,
      "name": "Soil_Sand_Red"
    },
    {
      "x": 5,
      "y": 1,
      "z": 1,
      "name": "Rock_Sandstone_Red"
    },
    {
      "x": 5,
      "y": 2,
      "z": 1,
      "name": "Rock_Sandstone_Red"
    },
    {
      "x": 5,
      "y": 3,
      "z": 1,
      "name": "Soil_Sand_Red"
    },
    {
      "x": 5,
      "y": 1,
      "z": 2,
      "name": "Rock_Sandstone_Red"
    },
    {
      "x": 5,
      "y": 2,
      "z": 2,
      "name": "Soil_Sand_Red"
    },
    {
      "x": 5,
      "y": 1,
      "z": 3,
      "name": "Rock_Sandstone_Red"
    },
    {
      "x": 5,
      "y": 2,
      "z": 3,
      "name": "Soil_Sand_Red"
    },
    {
      "x": 6,
      "y": 1,
      "z": -2,
      "name": "Rock_Sandstone_Red"
    },
    {
      "x": 6,
      "y": 1,
      "z": -1,
      "name": "Rock_Sandstone_Red"
    },
    {
      "x": 6,
      "y": 2,
      "z": -1,
      "name": "Soil_Sand_Red"
    },
    {
      "x": 6,
      "y": 0,
      "z": 0,
      "name": "Rock_Sandstone_Red"
    },
    {
      "x": 6,
      "y": 1,
      "z": 0,
      "name": "Rock_Sandstone_Red"
    },
    {
      "x": 6,
      "y": 2,
      "z": 0,
      "name": "Soil_Sand_Red"
    },
    {
      "x": 6,
      "y": 1,
      "z": 1,
      "name": "Rock_Sandstone_Red"
    }
  ],
  "fluids": [
    {
      "x": -6,
      "y": 1,
      "z": -3,
      "name": "Empty",
      "level": 0
    },
    {
      "x": -6,
      "y": 1,
      "z": -2,
      "name": "Empty",
      "level": 0
    },
    {
      "x": -6,
      "y": 2,
      "z": -2,
      "name": "Empty",
      "level": 0
    },
    {
      "x": -6,
      "y": 3,
      "z": -2,
      "name": "Empty",
      "level": 0
    },
    {
      "x": -6,
      "y": 1,
      "z": -1,
      "name": "Empty",
      "level": 0
    },
    {
      "x": -6,
      "y": 2,
      "z": -1,
      "name": "Empty",
      "level": 0
    },
    {
      "x": -6,
      "y": 3,
      "z": -1,
      "name": "Empty",
      "level": 0
    },
    {
      "x": -6,
      "y": 0,
      "z": 0,
      "name": "Empty",
      "level": 0
    },
    {
      "x": -6,
      "y": 1,
      "z": 0,
      "name": "Empty",
      "level": 0
    },
    {
      "x": -6,
      "y": 2,
      "z": 0,
      "name": "Empty",
      "level": 0
    },
    {
      "x": -6,
      "y": 1,
      "z": 1,
      "name": "Empty",
      "level": 0
    },
    {
      "x": -5,
      "y": 1,
      "z": -4,
      "name": "Empty",
      "level": 0
    },
    {
      "x": -5,
      "y": 0,
      "z": -3,
      "name": "Empty",
      "level": 0
    },
    {
      "x": -5,
      "y": 1,
      "z": -3,
      "name": "Empty",
      "level": 0
    },
    {
      "x": -5,
      "y": 2,
      "z": -3,
      "name": "Empty",
      "level": 0
    },
    {
      "x": -5,
      "y": 3,
      "z": -3,
      "name": "Empty",
      "level": 0
    },
    {
      "x": -5,
      "y": 4,
      "z": -3,
      "name": "Empty",
      "level": 0
    },
    {
      "x": -5,
      "y": 0,
      "z": -2,
      "name": "Empty",
      "level": 0
    },
    {
      "x": -5,
      "y": 1,
      "z": -2,
      "name": "Empty",
      "level": 0
    },
    {
      "x": -5,
      "y": 2,
      "z": -2,
      "name": "Empty",
      "level": 0
    },
    {
      "x": -5,
      "y": 3,
      "z": -2,
      "name": "Empty",
      "level": 0
    },
    {
      "x": -5,
      "y": 4,
      "z": -2,
      "name": "Empty",
      "level": 0
    },
    {
      "x": -5,
      "y": 0,
      "z": -1,
      "name": "Empty",
      "level": 0
    },
    {
      "x": -5,
      "y": 1,
      "z": -1,
      "name": "Empty",
      "level": 0
    },
    {
      "x": -5,
      "y": 2,
      "z": -1,
      "name": "Empty",
      "level": 0
    },
    {
      "x": -5,
      "y": 3,
      "z": -1,
      "name": "Empty",
      "level": 0
    },
    {
      "x": -5,
      "y": 4,
      "z": -1,
      "name": "Empty",
      "level": 0
    },
    {
      "x": -5,
      "y": 0,
      "z": 0,
      "name": "Empty",
      "level": 0
    },
    {
      "x": -5,
      "y": 1,
      "z": 0,
      "name": "Empty",
      "level": 0
    },
    {
      "x": -5,
      "y": 2,
      "z": 0,
      "name": "Empty",
      "level": 0
    },
    {
      "x": -5,
      "y": 3,
      "z": 0,
      "name": "Empty",
      "level": 0
    },
    {
      "x": -5,
      "y": 1,
      "z": 1,
      "name": "Empty",
      "level": 0
    },
    {
      "x": -5,
      "y": 2,
      "z": 1,
      "name": "Empty",
      "level": 0
    },
    {
      "x": -5,
      "y": 1,
      "z": 2,
      "name": "Empty",
      "level": 0
    },
    {
      "x": -5,
      "y": 1,
      "z": 3,
      "name": "Empty",
      "level": 0
    },
    {
      "x": -5,
      "y": 1,
      "z": 4,
      "name": "Empty",
      "level": 0
    },
    {
      "x": -4,
      "y": 1,
      "z": -4,
      "name": "Empty",
      "level": 0
    },
    {
      "x": -4,
      "y": 2,
      "z": -4,
      "name": "Empty",
      "level": 0
    },
    {
      "x": -4,
      "y": 3,
      "z": -4,
      "name": "Empty",
      "level": 0
    },
    {
      "x": -4,
      "y": 0,
      "z": -3,
      "name": "Empty",
      "level": 0
    },
    {
      "x": -4,
      "y": 1,
      "z": -3,
      "name": "Empty",
      "level": 0
    },
    {
      "x": -4,
      "y": 2,
      "z": -3,
      "name": "Empty",
      "level": 0
    },
    {
      "x": -4,
      "y": 3,
      "z": -3,
      "name": "Empty",
      "level": 0
    },
    {
      "x": -4,
      "y": 4,
      "z": -3,
      "name": "Empty",
      "level": 0
    },
    {
      "x": -4,
      "y": 0,
      "z": -2,
      "name": "Empty",
      "level": 0
    },
    {
      "x": -4,
      "y": 1,
      "z": -2,
      "name": "Empty",
      "level": 0
    },
    {
      "x": -4,
      "y": 2,
      "z": -2,
      "name": "Empty",
      "level": 0
    },
    {
      "x": -4,
      "y": 3,
      "z": -2,
      "name": "Empty",
      "level": 0
    },
    {
      "x": -4,
      "y": 4,
      "z": -2,
      "name": "Empty",
      "level": 0
    },
    {
      "x": -4,
      "y": 0,
      "z": -1,
      "name": "Empty",
      "level": 0
    },
    {
      "x": -4,
      "y": 1,
      "z": -1,
      "name": "Empty",
      "level": 0
    },
    {
      "x": -4,
      "y": 2,
      "z": -1,
      "name": "Empty",
      "level": 0
    },
    {
      "x": -4,
      "y": 3,
      "z": -1,
      "name": "Empty",
      "level": 0
    },
    {
      "x": -4,
      "y": 4,
      "z": -1,
      "name": "Empty",
      "level": 0
    },
    {
      "x": -4,
      "y": 0,
      "z": 0,
      "name": "Empty",
      "level": 0
    },
    {
      "x": -4,
      "y": 1,
      "z": 0,
      "name": "Empty",
      "level": 0
    },
    {
      "x": -4,
      "y": 2,
      "z": 0,
      "name": "Empty",
      "level": 0
    },
    {
      "x": -4,
      "y": 3,
      "z": 0,
      "name": "Empty",
      "level": 0
    },
    {
      "x": -4,
      "y": 4,
      "z": 0,
      "name": "Empty",
      "level": 0
    },
    {
      "x": -4,
      "y": 0,
      "z": 1,
      "name": "Empty",
      "level": 0
    },
    {
      "x": -4,
      "y": 1,
      "z": 1,
      "name": "Empty",
      "level": 0
    },
    {
      "x": -4,
      "y": 2,
      "z": 1,
      "name": "Empty",
      "level": 0
    },
    {
      "x": -4,
      "y": 3,
      "z": 1,
      "name": "Empty",
      "level": 0
    },
    {
      "x": -4,
      "y": 4,
      "z": 1,
      "name": "Empty",
      "level": 0
    },
    {
      "x": -4,
      "y": 0,
      "z": 2,
      "name": "Empty",
      "level": 0
    },
    {
      "x": -4,
      "y": 1,
      "z": 2,
      "name": "Empty",
      "level": 0
    },
    {
      "x": -4,
      "y": 2,
      "z": 2,
      "name": "Empty",
      "level": 0
    },
    {
      "x": -4,
      "y": 0,
      "z": 3,
      "name": "Empty",
      "level": 0
    },
    {
      "x": -4,
      "y": 1,
      "z": 3,
      "name": "Empty",
      "level": 0
    },
    {
      "x": -4,
      "y": 2,
      "z": 3,
      "name": "Empty",
      "level": 0
    },
    {
      "x": -4,
      "y": 3,
      "z": 3,
      "name": "Empty",
      "level": 0
    },
    {
      "x": -4,
      "y": 1,
      "z": 4,
      "name": "Empty",
      "level": 0
    },
    {
      "x": -4,
      "y": 2,
      "z": 4,
      "name": "Empty",
      "level": 0
    },
    {
      "x": -4,
      "y": 3,
      "z": 4,
      "name": "Empty",
      "level": 0
    },
    {
      "x": -4,
      "y": 1,
      "z": 5,
      "name": "Empty",
      "level": 0
    },
    {
      "x": -3,
      "y": 1,
      "z": -5,
      "name": "Empty",
      "level": 0
    },
    {
      "x": -3,
      "y": 2,
      "z": -5,
      "name": "Empty",
      "level": 0
    },
    {
      "x": -3,
      "y": 3,
      "z": -5,
      "name": "Empty",
      "level": 0
    },
    {
      "x": -3,
      "y": 0,
      "z": -4,
      "name": "Empty",
      "level": 0
    },
    {
      "x": -3,
      "y": 1,
      "z": -4,
      "name": "Empty",
      "level": 0
    },
    {
      "x": -3,
      "y": 2,
      "z": -4,
      "name": "Empty",
      "level": 0
    },
    {
      "x": -3,
      "y": 3,
      "z": -4,
      "name": "Empty",
      "level": 0
    },
    {
      "x": -3,
      "y": 4,
      "z": -4,
      "name": "Empty",
      "level": 0
    },
    {
      "x": -3,
      "y": 0,
      "z": -3,
      "name": "Empty",
      "level": 0
    },
    {
      "x": -3,
      "y": 1,
      "z": -3,
      "name": "Empty",
      "level": 0
    },
    {
      "x": -3,
      "y": 2,
      "z": -3,
      "name": "Empty",
      "level": 0
    },
    {
      "x": -3,
      "y": 3,
      "z": -3,
      "name": "Empty",
      "level": 0
    },
    {
      "x": -3,
      "y": 4,
      "z": -3,
      "name": "Empty",
      "level": 0
    },
    {
      "x": -3,
      "y": 0,
      "z": -2,
      "name": "Empty",
      "level": 0
    },
    {
      "x": -3,
      "y": 1,
      "z": -2,
      "name": "Empty",
      "level": 0
    },
    {
      "x": -3,
      "y": 2,
      "z": -2,
      "name": "Empty",
      "level": 0
    },
    {
      "x": -3,
      "y": 3,
      "z": -2,
      "name": "Empty",
      "level": 0
    },
    {
      "x": -3,
      "y": 4,
      "z": -2,
      "name": "Empty",
      "level": 0
    },
    {
      "x": -3,
      "y": 0,
      "z": -1,
      "name": "Empty",
      "level": 0
    },
    {
      "x": -3,
      "y": 1,
      "z": -1,
      "name": "Empty",
      "level": 0
    },
    {
      "x": -3,
      "y": 2,
      "z": -1,
      "name": "Empty",
      "level": 0
    },
    {
      "x": -3,
      "y": 3,
      "z": -1,
      "name": "Empty",
      "level": 0
    },
    {
      "x": -3,
      "y": 4,
      "z": -1,
      "name": "Empty",
      "level": 0
    },
    {
      "x": -3,
      "y": 0,
      "z": 0,
      "name": "Empty",
      "level": 0
    },
    {
      "x": -3,
      "y": 1,
      "z": 0,
      "name": "Empty",
      "level": 0
    },
    {
      "x": -3,
      "y": 2,
      "z": 0,
      "name": "Empty",
      "level": 0
    },
    {
      "x": -3,
      "y": 3,
      "z": 0,
      "name": "Empty",
      "level": 0
    },
    {
      "x": -3,
      "y": 4,
      "z": 0,
      "name": "Empty",
      "level": 0
    },
    {
      "x": -3,
      "y": 0,
      "z": 1,
      "name": "Empty",
      "level": 0
    },
    {
      "x": -3,
      "y": 1,
      "z": 1,
      "name": "Empty",
      "level": 0
    },
    {
      "x": -3,
      "y": 2,
      "z": 1,
      "name": "Empty",
      "level": 0
    },
    {
      "x": -3,
      "y": 3,
      "z": 1,
      "name": "Empty",
      "level": 0
    },
    {
      "x": -3,
      "y": 4,
      "z": 1,
      "name": "Empty",
      "level": 0
    },
    {
      "x": -3,
      "y": 0,
      "z": 2,
      "name": "Empty",
      "level": 0
    },
    {
      "x": -3,
      "y": 1,
      "z": 2,
      "name": "Empty",
      "level": 0
    },
    {
      "x": -3,
      "y": 2,
      "z": 2,
      "name": "Empty",
      "level": 0
    },
    {
      "x": -3,
      "y": 3,
      "z": 2,
      "name": "Empty",
      "level": 0
    },
    {
      "x": -3,
      "y": 0,
      "z": 3,
      "name": "Empty",
      "level": 0
    },
    {
      "x": -3,
      "y": 1,
      "z": 3,
      "name": "Empty",
      "level": 0
    },
    {
      "x": -3,
      "y": 2,
      "z": 3,
      "name": "Empty",
      "level": 0
    },
    {
      "x": -3,
      "y": 3,
      "z": 3,
      "name": "Empty",
      "level": 0
    },
    {
      "x": -3,
      "y": 4,
      "z": 3,
      "name": "Empty",
      "level": 0
    },
    {
      "x": -3,
      "y": 0,
      "z": 4,
      "name": "Empty",
      "level": 0
    },
    {
      "x": -3,
      "y": 1,
      "z": 4,
      "name": "Empty",
      "level": 0
    },
    {
      "x": -3,
      "y": 2,
      "z": 4,
      "name": "Empty",
      "level": 0
    },
    {
      "x": -3,
      "y": 3,
      "z": 4,
      "name": "Empty",
      "level": 0
    },
    {
      "x": -3,
      "y": 4,
      "z": 4,
      "name": "Empty",
      "level": 0
    },
    {
      "x": -3,
      "y": 1,
      "z": 5,
      "name": "Empty",
      "level": 0
    },
    {
      "x": -3,
      "y": 2,
      "z": 5,
      "name": "Empty",
      "level": 0
    },
    {
      "x": -3,
      "y": 3,
      "z": 5,
      "name": "Empty",
      "level": 0
    },
    {
      "x": -2,
      "y": 0,
      "z": -5,
      "name": "Empty",
      "level": 0
    },
    {
      "x": -2,
      "y": 1,
      "z": -5,
      "name": "Empty",
      "level": 0
    },
    {
      "x": -2,
      "y": 0,
      "z": -4,
      "name": "Empty",
      "level": 0
    },
    {
      "x": -2,
      "y": 1,
      "z": -4,
      "name": "Empty",
      "level": 0
    },
    {
      "x": -2,
      "y": 2,
      "z": -4,
      "name": "Empty",
      "level": 0
    },
    {
      "x": -2,
      "y": 3,
      "z": -4,
      "name": "Empty",
      "level": 0
    },
    {
      "x": -2,
      "y": 4,
      "z": -4,
      "name": "Empty",
      "level": 0
    },
    {
      "x": -2,
      "y": 0,
      "z": -3,
      "name": "Empty",
      "level": 0
    },
    {
      "x": -2,
      "y": 1,
      "z": -3,
      "name": "Empty",
      "level": 0
    },
    {
      "x": -2,
      "y": 2,
      "z": -3,
      "name": "Empty",
      "level": 0
    },
    {
      "x": -2,
      "y": 3,
      "z": -3,
      "name": "Empty",
      "level": 0
    },
    {
      "x": -2,
      "y": 4,
      "z": -3,
      "name": "Empty",
      "level": 0
    },
    {
      "x": -2,
      "y": 0,
      "z": -2,
      "name": "Empty",
      "level": 0
    },
    {
      "x": -2,
      "y": 1,
      "z": -2,
      "name": "Empty",
      "level": 0
    },
    {
      "x": -2,
      "y": 2,
      "z": -2,
      "name": "Empty",
      "level": 0
    },
    {
      "x": -2,
      "y": 3,
      "z": -2,
      "name": "Empty",
      "level": 0
    },
    {
      "x": -2,
      "y": 4,
      "z": -2,
      "name": "Empty",
      "level": 0
    },
    {
      "x": -2,
      "y": 0,
      "z": -1,
      "name": "Empty",
      "level": 0
    },
    {
      "x": -2,
      "y": 1,
      "z": -1,
      "name": "Empty",
      "level": 0
    },
    {
      "x": -2,
      "y": 2,
      "z": -1,
      "name": "Empty",
      "level": 0
    },
    {
      "x": -2,
      "y": 3,
      "z": -1,
      "name": "Empty",
      "level": 0
    },
    {
      "x": -2,
      "y": 4,
      "z": -1,
      "name": "Empty",
      "level": 0
    },
    {
      "x": -2,
      "y": 0,
      "z": 0,
      "name": "Empty",
      "level": 0
    },
    {
      "x": -2,
      "y": 1,
      "z": 0,
      "name": "Empty",
      "level": 0
    },
    {
      "x": -2,
      "y": 2,
      "z": 0,
      "name": "Empty",
      "level": 0
    },
    {
      "x": -2,
      "y": 3,
      "z": 0,
      "name": "Empty",
      "level": 0
    },
    {
      "x": -2,
      "y": 4,
      "z": 0,
      "name": "Empty",
      "level": 0
    },
    {
      "x": -2,
      "y": 5,
      "z": 0,
      "name": "Empty",
      "level": 0
    },
    {
      "x": -2,
      "y": 0,
      "z": 1,
      "name": "Empty",
      "level": 0
    },
    {
      "x": -2,
      "y": 1,
      "z": 1,
      "name": "Empty",
      "level": 0
    },
    {
      "x": -2,
      "y": 2,
      "z": 1,
      "name": "Empty",
      "level": 0
    },
    {
      "x": -2,
      "y": 3,
      "z": 1,
      "name": "Empty",
      "level": 0
    },
    {
      "x": -2,
      "y": 4,
      "z": 1,
      "name": "Empty",
      "level": 0
    },
    {
      "x": -2,
      "y": 5,
      "z": 1,
      "name": "Empty",
      "level": 0
    },
    {
      "x": -2,
      "y": 0,
      "z": 2,
      "name": "Empty",
      "level": 0
    },
    {
      "x": -2,
      "y": 1,
      "z": 2,
      "name": "Empty",
      "level": 0
    },
    {
      "x": -2,
      "y": 2,
      "z": 2,
      "name": "Empty",
      "level": 0
    },
    {
      "x": -2,
      "y": 3,
      "z": 2,
      "name": "Empty",
      "level": 0
    },
    {
      "x": -2,
      "y": 4,
      "z": 2,
      "name": "Empty",
      "level": 0
    },
    {
      "x": -2,
      "y": 0,
      "z": 3,
      "name": "Empty",
      "level": 0
    },
    {
      "x": -2,
      "y": 1,
      "z": 3,
      "name": "Empty",
      "level": 0
    },
    {
      "x": -2,
      "y": 2,
      "z": 3,
      "name": "Empty",
      "level": 0
    },
    {
      "x": -2,
      "y": 3,
      "z": 3,
      "name": "Empty",
      "level": 0
    },
    {
      "x": -2,
      "y": 4,
      "z": 3,
      "name": "Empty",
      "level": 0
    },
    {
      "x": -2,
      "y": 0,
      "z": 4,
      "name": "Empty",
      "level": 0
    },
    {
      "x": -2,
      "y": 1,
      "z": 4,
      "name": "Empty",
      "level": 0
    },
    {
      "x": -2,
      "y": 2,
      "z": 4,
      "name": "Empty",
      "level": 0
    },
    {
      "x": -2,
      "y": 3,
      "z": 4,
      "name": "Empty",
      "level": 0
    },
    {
      "x": -2,
      "y": 4,
      "z": 4,
      "name": "Empty",
      "level": 0
    },
    {
      "x": -2,
      "y": 0,
      "z": 5,
      "name": "Empty",
      "level": 0
    },
    {
      "x": -2,
      "y": 1,
      "z": 5,
      "name": "Empty",
      "level": 0
    },
    {
      "x": -2,
      "y": 2,
      "z": 5,
      "name": "Empty",
      "level": 0
    },
    {
      "x": -2,
      "y": 1,
      "z": 6,
      "name": "Empty",
      "level": 0
    },
    {
      "x": -1,
      "y": 0,
      "z": -5,
      "name": "Empty",
      "level": 0
    },
    {
      "x": -1,
      "y": 1,
      "z": -5,
      "name": "Empty",
      "level": 0
    },
    {
      "x": -1,
      "y": 0,
      "z": -4,
      "name": "Empty",
      "level": 0
    },
    {
      "x": -1,
      "y": 1,
      "z": -4,
      "name": "Empty",
      "level": 0
    },
    {
      "x": -1,
      "y": 2,
      "z": -4,
      "name": "Empty",
      "level": 0
    },
    {
      "x": -1,
      "y": 3,
      "z": -4,
      "name": "Empty",
      "level": 0
    },
    {
      "x": -1,
      "y": 4,
      "z": -4,
      "name": "Empty",
      "level": 0
    },
    {
      "x": -1,
      "y": 0,
      "z": -3,
      "name": "Empty",
      "level": 0
    },
    {
      "x": -1,
      "y": 1,
      "z": -3,
      "name": "Empty",
      "level": 0
    },
    {
      "x": -1,
      "y": 2,
      "z": -3,
      "name": "Empty",
      "level": 0
    },
    {
      "x": -1,
      "y": 3,
      "z": -3,
      "name": "Empty",
      "level": 0
    },
    {
      "x": -1,
      "y": 4,
      "z": -3,
      "name": "Empty",
      "level": 0
    },
    {
      "x": -1,
      "y": 0,
      "z": -2,
      "name": "Empty",
      "level": 0
    },
    {
      "x": -1,
      "y": 1,
      "z": -2,
      "name": "Empty",
      "level": 0
    },
    {
      "x": -1,
      "y": 2,
      "z": -2,
      "name": "Empty",
      "level": 0
    },
    {
      "x": -1,
      "y": 3,
      "z": -2,
      "name": "Empty",
      "level": 0
    },
    {
      "x": -1,
      "y": 4,
      "z": -2,
      "name": "Empty",
      "level": 0
    },
    {
      "x": -1,
      "y": 0,
      "z": -1,
      "name": "Empty",
      "level": 0
    },
    {
      "x": -1,
      "y": 1,
      "z": -1,
      "name": "Empty",
      "level": 0
    },
    {
      "x": -1,
      "y": 2,
      "z": -1,
      "name": "Empty",
      "level": 0
    },
    {
      "x": -1,
      "y": 3,
      "z": -1,
      "name": "Empty",
      "level": 0
    },
    {
      "x": -1,
      "y": 4,
      "z": -1,
      "name": "Empty",
      "level": 0
    },
    {
      "x": -1,
      "y": 5,
      "z": -1,
      "name": "Empty",
      "level": 0
    },
    {
      "x": -1,
      "y": 0,
      "z": 0,
      "name": "Empty",
      "level": 0
    },
    {
      "x": -1,
      "y": 1,
      "z": 0,
      "name": "Empty",
      "level": 0
    },
    {
      "x": -1,
      "y": 2,
      "z": 0,
      "name": "Empty",
      "level": 0
    },
    {
      "x": -1,
      "y": 3,
      "z": 0,
      "name": "Empty",
      "level": 0
    },
    {
      "x": -1,
      "y": 4,
      "z": 0,
      "name": "Empty",
      "level": 0
    },
    {
      "x": -1,
      "y": 5,
      "z": 0,
      "name": "Empty",
      "level": 0
    },
    {
      "x": -1,
      "y": 0,
      "z": 1,
      "name": "Empty",
      "level": 0
    },
    {
      "x": -1,
      "y": 1,
      "z": 1,
      "name": "Empty",
      "level": 0
    },
    {
      "x": -1,
      "y": 2,
      "z": 1,
      "name": "Empty",
      "level": 0
    },
    {
      "x": -1,
      "y": 3,
      "z": 1,
      "name": "Empty",
      "level": 0
    },
    {
      "x": -1,
      "y": 4,
      "z": 1,
      "name": "Empty",
      "level": 0
    },
    {
      "x": -1,
      "y": 5,
      "z": 1,
      "name": "Empty",
      "level": 0
    },
    {
      "x": -1,
      "y": 0,
      "z": 2,
      "name": "Empty",
      "level": 0
    },
    {
      "x": -1,
      "y": 1,
      "z": 2,
      "name": "Empty",
      "level": 0
    },
    {
      "x": -1,
      "y": 2,
      "z": 2,
      "name": "Empty",
      "level": 0
    },
    {
      "x": -1,
      "y": 3,
      "z": 2,
      "name": "Empty",
      "level": 0
    },
    {
      "x": -1,
      "y": 4,
      "z": 2,
      "name": "Empty",
      "level": 0
    },
    {
      "x": -1,
      "y": 0,
      "z": 3,
      "name": "Empty",
      "level": 0
    },
    {
      "x": -1,
      "y": 1,
      "z": 3,
      "name": "Empty",
      "level": 0
    },
    {
      "x": -1,
      "y": 2,
      "z": 3,
      "name": "Empty",
      "level": 0
    },
    {
      "x": -1,
      "y": 3,
      "z": 3,
      "name": "Empty",
      "level": 0
    },
    {
      "x": -1,
      "y": 4,
      "z": 3,
      "name": "Empty",
      "level": 0
    },
    {
      "x": -1,
      "y": 0,
      "z": 4,
      "name": "Empty",
      "level": 0
    },
    {
      "x": -1,
      "y": 1,
      "z": 4,
      "name": "Empty",
      "level": 0
    },
    {
      "x": -1,
      "y": 2,
      "z": 4,
      "name": "Empty",
      "level": 0
    },
    {
      "x": -1,
      "y": 3,
      "z": 4,
      "name": "Empty",
      "level": 0
    },
    {
      "x": -1,
      "y": 4,
      "z": 4,
      "name": "Empty",
      "level": 0
    },
    {
      "x": -1,
      "y": 0,
      "z": 5,
      "name": "Empty",
      "level": 0
    },
    {
      "x": -1,
      "y": 1,
      "z": 5,
      "name": "Empty",
      "level": 0
    },
    {
      "x": -1,
      "y": 2,
      "z": 5,
      "name": "Empty",
      "level": 0
    },
    {
      "x": -1,
      "y": 3,
      "z": 5,
      "name": "Empty",
      "level": 0
    },
    {
      "x": -1,
      "y": 1,
      "z": 6,
      "name": "Empty",
      "level": 0
    },
    {
      "x": 0,
      "y": 1,
      "z": -5,
      "name": "Empty",
      "level": 0
    },
    {
      "x": 0,
      "y": 2,
      "z": -5,
      "name": "Empty",
      "level": 0
    },
    {
      "x": 0,
      "y": 3,
      "z": -5,
      "name": "Empty",
      "level": 0
    },
    {
      "x": 0,
      "y": 4,
      "z": -5,
      "name": "Empty",
      "level": 0
    },
    {
      "x": 0,
      "y": 0,
      "z": -4,
      "name": "Empty",
      "level": 0
    },
    {
      "x": 0,
      "y": 1,
      "z": -4,
      "name": "Empty",
      "level": 0
    },
    {
      "x": 0,
      "y": 2,
      "z": -4,
      "name": "Empty",
      "level": 0
    },
    {
      "x": 0,
      "y": 3,
      "z": -4,
      "name": "Empty",
      "level": 0
    },
    {
      "x": 0,
      "y": 4,
      "z": -4,
      "name": "Empty",
      "level": 0
    },
    {
      "x": 0,
      "y": 0,
      "z": -3,
      "name": "Empty",
      "level": 0
    },
    {
      "x": 0,
      "y": 1,
      "z": -3,
      "name": "Empty",
      "level": 0
    },
    {
      "x": 0,
      "y": 2,
      "z": -3,
      "name": "Empty",
      "level": 0
    },
    {
      "x": 0,
      "y": 3,
      "z": -3,
      "name": "Empty",
      "level": 0
    },
    {
      "x": 0,
      "y": 4,
      "z": -3,
      "name": "Empty",
      "level": 0
    },
    {
      "x": 0,
      "y": 5,
      "z": -3,
      "name": "Empty",
      "level": 0
    },
    {
      "x": 0,
      "y": 0,
      "z": -2,
      "name": "Empty",
      "level": 0
    },
    {
      "x": 0,
      "y": 1,
      "z": -2,
      "name": "Empty",
      "level": 0
    },
    {
      "x": 0,
      "y": 2,
      "z": -2,
      "name": "Empty",
      "level": 0
    },
    {
      "x": 0,
      "y": 3,
      "z": -2,
      "name": "Empty",
      "level": 0
    },
    {
      "x": 0,
      "y": 4,
      "z": -2,
      "name": "Empty",
      "level": 0
    },
    {
      "x": 0,
      "y": 5,
      "z": -2,
      "name": "Empty",
      "level": 0
    },
    {
      "x": 0,
      "y": 0,
      "z": -1,
      "name": "Empty",
      "level": 0
    },
    {
      "x": 0,
      "y": 1,
      "z": -1,
      "name": "Empty",
      "level": 0
    },
    {
      "x": 0,
      "y": 2,
      "z": -1,
      "name": "Empty",
      "level": 0
    },
    {
      "x": 0,
      "y": 3,
      "z": -1,
      "name": "Empty",
      "level": 0
    },
    {
      "x": 0,
      "y": 4,
      "z": -1,
      "name": "Empty",
      "level": 0
    },
    {
      "x": 0,
      "y": 5,
      "z": -1,
      "name": "Empty",
      "level": 0
    },
    {
      "x": 0,
      "y": 6,
      "z": -1,
      "name": "Empty",
      "level": 0
    },
    {
      "x": 0,
      "y": 0,
      "z": 0,
      "name": "Empty",
      "level": 0
    },
    {
      "x": 0,
      "y": 1,
      "z": 0,
      "name": "Empty",
      "level": 0
    },
    {
      "x": 0,
      "y": 2,
      "z": 0,
      "name": "Empty",
      "level": 0
    },
    {
      "x": 0,
      "y": 3,
      "z": 0,
      "name": "Empty",
      "level": 0
    },
    {
      "x": 0,
      "y": 4,
      "z": 0,
      "name": "Empty",
      "level": 0
    },
    {
      "x": 0,
      "y": 5,
      "z": 0,
      "name": "Empty",
      "level": 0
    },
    {
      "x": 0,
      "y": 0,
      "z": 1,
      "name": "Empty",
      "level": 0
    },
    {
      "x": 0,
      "y": 1,
      "z": 1,
      "name": "Empty",
      "level": 0
    },
    {
      "x": 0,
      "y": 2,
      "z": 1,
      "name": "Empty",
      "level": 0
    },
    {
      "x": 0,
      "y": 3,
      "z": 1,
      "name": "Empty",
      "level": 0
    },
    {
      "x": 0,
      "y": 4,
      "z": 1,
      "name": "Empty",
      "level": 0
    },
    {
      "x": 0,
      "y": 0,
      "z": 2,
      "name": "Empty",
      "level": 0
    },
    {
      "x": 0,
      "y": 1,
      "z": 2,
      "name": "Empty",
      "level": 0
    },
    {
      "x": 0,
      "y": 2,
      "z": 2,
      "name": "Empty",
      "level": 0
    },
    {
      "x": 0,
      "y": 3,
      "z": 2,
      "name": "Empty",
      "level": 0
    },
    {
      "x": 0,
      "y": 4,
      "z": 2,
      "name": "Empty",
      "level": 0
    },
    {
      "x": 0,
      "y": 0,
      "z": 3,
      "name": "Empty",
      "level": 0
    },
    {
      "x": 0,
      "y": 1,
      "z": 3,
      "name": "Empty",
      "level": 0
    },
    {
      "x": 0,
      "y": 2,
      "z": 3,
      "name": "Empty",
      "level": 0
    },
    {
      "x": 0,
      "y": 3,
      "z": 3,
      "name": "Empty",
      "level": 0
    },
    {
      "x": 0,
      "y": 4,
      "z": 3,
      "name": "Empty",
      "level": 0
    },
    {
      "x": 0,
      "y": 0,
      "z": 4,
      "name": "Empty",
      "level": 0
    },
    {
      "x": 0,
      "y": 1,
      "z": 4,
      "name": "Empty",
      "level": 0
    },
    {
      "x": 0,
      "y": 2,
      "z": 4,
      "name": "Empty",
      "level": 0
    },
    {
      "x": 0,
      "y": 3,
      "z": 4,
      "name": "Empty",
      "level": 0
    },
    {
      "x": 0,
      "y": 4,
      "z": 4,
      "name": "Empty",
      "level": 0
    },
    {
      "x": 0,
      "y": 0,
      "z": 5,
      "name": "Empty",
      "level": 0
    },
    {
      "x": 0,
      "y": 1,
      "z": 5,
      "name": "Empty",
      "level": 0
    },
    {
      "x": 0,
      "y": 2,
      "z": 5,
      "name": "Empty",
      "level": 0
    },
    {
      "x": 0,
      "y": 3,
      "z": 5,
      "name": "Empty",
      "level": 0
    },
    {
      "x": 0,
      "y": 1,
      "z": 6,
      "name": "Empty",
      "level": 0
    },
    {
      "x": 0,
      "y": 2,
      "z": 6,
      "name": "Empty",
      "level": 0
    },
    {
      "x": 1,
      "y": 1,
      "z": -5,
      "name": "Empty",
      "level": 0
    },
    {
      "x": 1,
      "y": 2,
      "z": -5,
      "name": "Empty",
      "level": 0
    },
    {
      "x": 1,
      "y": 3,
      "z": -5,
      "name": "Empty",
      "level": 0
    },
    {
      "x": 1,
      "y": 4,
      "z": -5,
      "name": "Empty",
      "level": 0
    },
    {
      "x": 1,
      "y": 0,
      "z": -4,
      "name": "Empty",
      "level": 0
    },
    {
      "x": 1,
      "y": 1,
      "z": -4,
      "name": "Empty",
      "level": 0
    },
    {
      "x": 1,
      "y": 2,
      "z": -4,
      "name": "Empty",
      "level": 0
    },
    {
      "x": 1,
      "y": 3,
      "z": -4,
      "name": "Empty",
      "level": 0
    },
    {
      "x": 1,
      "y": 4,
      "z": -4,
      "name": "Empty",
      "level": 0
    },
    {
      "x": 1,
      "y": 0,
      "z": -3,
      "name": "Empty",
      "level": 0
    },
    {
      "x": 1,
      "y": 1,
      "z": -3,
      "name": "Empty",
      "level": 0
    },
    {
      "x": 1,
      "y": 2,
      "z": -3,
      "name": "Empty",
      "level": 0
    },
    {
      "x": 1,
      "y": 3,
      "z": -3,
      "name": "Empty",
      "level": 0
    },
    {
      "x": 1,
      "y": 4,
      "z": -3,
      "name": "Empty",
      "level": 0
    },
    {
      "x": 1,
      "y": 5,
      "z": -3,
      "name": "Empty",
      "level": 0
    },
    {
      "x": 1,
      "y": 0,
      "z": -2,
      "name": "Empty",
      "level": 0
    },
    {
      "x": 1,
      "y": 1,
      "z": -2,
      "name": "Empty",
      "level": 0
    },
    {
      "x": 1,
      "y": 2,
      "z": -2,
      "name": "Empty",
      "level": 0
    },
    {
      "x": 1,
      "y": 3,
      "z": -2,
      "name": "Empty",
      "level": 0
    },
    {
      "x": 1,
      "y": 4,
      "z": -2,
      "name": "Empty",
      "level": 0
    },
    {
      "x": 1,
      "y": 5,
      "z": -2,
      "name": "Empty",
      "level": 0
    },
    {
      "x": 1,
      "y": 0,
      "z": -1,
      "name": "Empty",
      "level": 0
    },
    {
      "x": 1,
      "y": 1,
      "z": -1,
      "name": "Empty",
      "level": 0
    },
    {
      "x": 1,
      "y": 2,
      "z": -1,
      "name": "Empty",
      "level": 0
    },
    {
      "x": 1,
      "y": 3,
      "z": -1,
      "name": "Empty",
      "level": 0
    },
    {
      "x": 1,
      "y": 4,
      "z": -1,
      "name": "Empty",
      "level": 0
    },
    {
      "x": 1,
      "y": 5,
      "z": -1,
      "name": "Empty",
      "level": 0
    },
    {
      "x": 1,
      "y": 0,
      "z": 0,
      "name": "Empty",
      "level": 0
    },
    {
      "x": 1,
      "y": 1,
      "z": 0,
      "name": "Empty",
      "level": 0
    },
    {
      "x": 1,
      "y": 2,
      "z": 0,
      "name": "Empty",
      "level": 0
    },
    {
      "x": 1,
      "y": 3,
      "z": 0,
      "name": "Empty",
      "level": 0
    },
    {
      "x": 1,
      "y": 4,
      "z": 0,
      "name": "Empty",
      "level": 0
    },
    {
      "x": 1,
      "y": 0,
      "z": 1,
      "name": "Empty",
      "level": 0
    },
    {
      "x": 1,
      "y": 1,
      "z": 1,
      "name": "Empty",
      "level": 0
    },
    {
      "x": 1,
      "y": 2,
      "z": 1,
      "name": "Empty",
      "level": 0
    },
    {
      "x": 1,
      "y": 3,
      "z": 1,
      "name": "Empty",
      "level": 0
    },
    {
      "x": 1,
      "y": 4,
      "z": 1,
      "name": "Empty",
      "level": 0
    },
    {
      "x": 1,
      "y": 0,
      "z": 2,
      "name": "Empty",
      "level": 0
    },
    {
      "x": 1,
      "y": 1,
      "z": 2,
      "name": "Empty",
      "level": 0
    },
    {
      "x": 1,
      "y": 2,
      "z": 2,
      "name": "Empty",
      "level": 0
    },
    {
      "x": 1,
      "y": 3,
      "z": 2,
      "name": "Empty",
      "level": 0
    },
    {
      "x": 1,
      "y": 0,
      "z": 3,
      "name": "Empty",
      "level": 0
    },
    {
      "x": 1,
      "y": 1,
      "z": 3,
      "name": "Empty",
      "level": 0
    },
    {
      "x": 1,
      "y": 2,
      "z": 3,
      "name": "Empty",
      "level": 0
    },
    {
      "x": 1,
      "y": 3,
      "z": 3,
      "name": "Empty",
      "level": 0
    },
    {
      "x": 1,
      "y": 0,
      "z": 4,
      "name": "Empty",
      "level": 0
    },
    {
      "x": 1,
      "y": 1,
      "z": 4,
      "name": "Empty",
      "level": 0
    },
    {
      "x": 1,
      "y": 2,
      "z": 4,
      "name": "Empty",
      "level": 0
    },
    {
      "x": 1,
      "y": 3,
      "z": 4,
      "name": "Empty",
      "level": 0
    },
    {
      "x": 1,
      "y": 0,
      "z": 5,
      "name": "Empty",
      "level": 0
    },
    {
      "x": 1,
      "y": 1,
      "z": 5,
      "name": "Empty",
      "level": 0
    },
    {
      "x": 1,
      "y": 2,
      "z": 5,
      "name": "Empty",
      "level": 0
    },
    {
      "x": 1,
      "y": 3,
      "z": 5,
      "name": "Empty",
      "level": 0
    },
    {
      "x": 1,
      "y": 1,
      "z": 6,
      "name": "Empty",
      "level": 0
    },
    {
      "x": 1,
      "y": 2,
      "z": 6,
      "name": "Empty",
      "level": 0
    },
    {
      "x": 2,
      "y": 1,
      "z": -5,
      "name": "Empty",
      "level": 0
    },
    {
      "x": 2,
      "y": 1,
      "z": -4,
      "name": "Empty",
      "level": 0
    },
    {
      "x": 2,
      "y": 2,
      "z": -4,
      "name": "Empty",
      "level": 0
    },
    {
      "x": 2,
      "y": 3,
      "z": -4,
      "name": "Empty",
      "level": 0
    },
    {
      "x": 2,
      "y": 4,
      "z": -4,
      "name": "Empty",
      "level": 0
    },
    {
      "x": 2,
      "y": 0,
      "z": -3,
      "name": "Empty",
      "level": 0
    },
    {
      "x": 2,
      "y": 1,
      "z": -3,
      "name": "Empty",
      "level": 0
    },
    {
      "x": 2,
      "y": 2,
      "z": -3,
      "name": "Empty",
      "level": 0
    },
    {
      "x": 2,
      "y": 3,
      "z": -3,
      "name": "Empty",
      "level": 0
    },
    {
      "x": 2,
      "y": 4,
      "z": -3,
      "name": "Empty",
      "level": 0
    },
    {
      "x": 2,
      "y": 0,
      "z": -2,
      "name": "Empty",
      "level": 0
    },
    {
      "x": 2,
      "y": 1,
      "z": -2,
      "name": "Empty",
      "level": 0
    },
    {
      "x": 2,
      "y": 2,
      "z": -2,
      "name": "Empty",
      "level": 0
    },
    {
      "x": 2,
      "y": 3,
      "z": -2,
      "name": "Empty",
      "level": 0
    },
    {
      "x": 2,
      "y": 4,
      "z": -2,
      "name": "Empty",
      "level": 0
    },
    {
      "x": 2,
      "y": 0,
      "z": -1,
      "name": "Empty",
      "level": 0
    },
    {
      "x": 2,
      "y": 1,
      "z": -1,
      "name": "Empty",
      "level": 0
    },
    {
      "x": 2,
      "y": 2,
      "z": -1,
      "name": "Empty",
      "level": 0
    },
    {
      "x": 2,
      "y": 3,
      "z": -1,
      "name": "Empty",
      "level": 0
    },
    {
      "x": 2,
      "y": 4,
      "z": -1,
      "name": "Empty",
      "level": 0
    },
    {
      "x": 2,
      "y": 0,
      "z": 0,
      "name": "Empty",
      "level": 0
    },
    {
      "x": 2,
      "y": 1,
      "z": 0,
      "name": "Empty",
      "level": 0
    },
    {
      "x": 2,
      "y": 2,
      "z": 0,
      "name": "Empty",
      "level": 0
    },
    {
      "x": 2,
      "y": 3,
      "z": 0,
      "name": "Empty",
      "level": 0
    },
    {
      "x": 2,
      "y": 4,
      "z": 0,
      "name": "Empty",
      "level": 0
    },
    {
      "x": 2,
      "y": 0,
      "z": 1,
      "name": "Empty",
      "level": 0
    },
    {
      "x": 2,
      "y": 1,
      "z": 1,
      "name": "Empty",
      "level": 0
    },
    {
      "x": 2,
      "y": 2,
      "z": 1,
      "name": "Empty",
      "level": 0
    },
    {
      "x": 2,
      "y": 3,
      "z": 1,
      "name": "Empty",
      "level": 0
    },
    {
      "x": 2,
      "y": 0,
      "z": 2,
      "name": "Empty",
      "level": 0
    },
    {
      "x": 2,
      "y": 1,
      "z": 2,
      "name": "Empty",
      "level": 0
    },
    {
      "x": 2,
      "y": 2,
      "z": 2,
      "name": "Empty",
      "level": 0
    },
    {
      "x": 2,
      "y": 3,
      "z": 2,
      "name": "Empty",
      "level": 0
    },
    {
      "x": 2,
      "y": 0,
      "z": 3,
      "name": "Empty",
      "level": 0
    },
    {
      "x": 2,
      "y": 1,
      "z": 3,
      "name": "Empty",
      "level": 0
    },
    {
      "x": 2,
      "y": 2,
      "z": 3,
      "name": "Empty",
      "level": 0
    },
    {
      "x": 2,
      "y": 3,
      "z": 3,
      "name": "Empty",
      "level": 0
    },
    {
      "x": 2,
      "y": 0,
      "z": 4,
      "name": "Empty",
      "level": 0
    },
    {
      "x": 2,
      "y": 1,
      "z": 4,
      "name": "Empty",
      "level": 0
    },
    {
      "x": 2,
      "y": 2,
      "z": 4,
      "name": "Empty",
      "level": 0
    },
    {
      "x": 2,
      "y": 3,
      "z": 4,
      "name": "Empty",
      "level": 0
    },
    {
      "x": 2,
      "y": 0,
      "z": 5,
      "name": "Empty",
      "level": 0
    },
    {
      "x": 2,
      "y": 1,
      "z": 5,
      "name": "Empty",
      "level": 0
    },
    {
      "x": 2,
      "y": 2,
      "z": 5,
      "name": "Empty",
      "level": 0
    },
    {
      "x": 2,
      "y": 3,
      "z": 5,
      "name": "Empty",
      "level": 0
    },
    {
      "x": 2,
      "y": 1,
      "z": 6,
      "name": "Empty",
      "level": 0
    },
    {
      "x": 2,
      "y": 2,
      "z": 6,
      "name": "Empty",
      "level": 0
    },
    {
      "x": 3,
      "y": 1,
      "z": -4,
      "name": "Empty",
      "level": 0
    },
    {
      "x": 3,
      "y": 0,
      "z": -3,
      "name": "Empty",
      "level": 0
    },
    {
      "x": 3,
      "y": 1,
      "z": -3,
      "name": "Empty",
      "level": 0
    },
    {
      "x": 3,
      "y": 2,
      "z": -3,
      "name": "Empty",
      "level": 0
    },
    {
      "x": 3,
      "y": 3,
      "z": -3,
      "name": "Empty",
      "level": 0
    },
    {
      "x": 3,
      "y": 4,
      "z": -3,
      "name": "Empty",
      "level": 0
    },
    {
      "x": 3,
      "y": 0,
      "z": -2,
      "name": "Empty",
      "level": 0
    },
    {
      "x": 3,
      "y": 1,
      "z": -2,
      "name": "Empty",
      "level": 0
    },
    {
      "x": 3,
      "y": 2,
      "z": -2,
      "name": "Empty",
      "level": 0
    },
    {
      "x": 3,
      "y": 3,
      "z": -2,
      "name": "Empty",
      "level": 0
    },
    {
      "x": 3,
      "y": 4,
      "z": -2,
      "name": "Empty",
      "level": 0
    },
    {
      "x": 3,
      "y": 0,
      "z": -1,
      "name": "Empty",
      "level": 0
    },
    {
      "x": 3,
      "y": 1,
      "z": -1,
      "name": "Empty",
      "level": 0
    },
    {
      "x": 3,
      "y": 2,
      "z": -1,
      "name": "Empty",
      "level": 0
    },
    {
      "x": 3,
      "y": 3,
      "z": -1,
      "name": "Empty",
      "level": 0
    },
    {
      "x": 3,
      "y": 4,
      "z": -1,
      "name": "Empty",
      "level": 0
    },
    {
      "x": 3,
      "y": 0,
      "z": 0,
      "name": "Empty",
      "level": 0
    },
    {
      "x": 3,
      "y": 1,
      "z": 0,
      "name": "Empty",
      "level": 0
    },
    {
      "x": 3,
      "y": 2,
      "z": 0,
      "name": "Empty",
      "level": 0
    },
    {
      "x": 3,
      "y": 3,
      "z": 0,
      "name": "Empty",
      "level": 0
    },
    {
      "x": 3,
      "y": 0,
      "z": 1,
      "name": "Empty",
      "level": 0
    },
    {
      "x": 3,
      "y": 1,
      "z": 1,
      "name": "Empty",
      "level": 0
    },
    {
      "x": 3,
      "y": 2,
      "z": 1,
      "name": "Empty",
      "level": 0
    },
    {
      "x": 3,
      "y": 3,
      "z": 1,
      "name": "Empty",
      "level": 0
    },
    {
      "x": 3,
      "y": 0,
      "z": 2,
      "name": "Empty",
      "level": 0
    },
    {
      "x": 3,
      "y": 1,
      "z": 2,
      "name": "Empty",
      "level": 0
    },
    {
      "x": 3,
      "y": 2,
      "z": 2,
      "name": "Empty",
      "level": 0
    },
    {
      "x": 3,
      "y": 3,
      "z": 2,
      "name": "Empty",
      "level": 0
    },
    {
      "x": 3,
      "y": 0,
      "z": 3,
      "name": "Empty",
      "level": 0
    },
    {
      "x": 3,
      "y": 1,
      "z": 3,
      "name": "Empty",
      "level": 0
    },
    {
      "x": 3,
      "y": 2,
      "z": 3,
      "name": "Empty",
      "level": 0
    },
    {
      "x": 3,
      "y": 3,
      "z": 3,
      "name": "Empty",
      "level": 0
    },
    {
      "x": 3,
      "y": 0,
      "z": 4,
      "name": "Empty",
      "level": 0
    },
    {
      "x": 3,
      "y": 1,
      "z": 4,
      "name": "Empty",
      "level": 0
    },
    {
      "x": 3,
      "y": 2,
      "z": 4,
      "name": "Empty",
      "level": 0
    },
    {
      "x": 3,
      "y": 3,
      "z": 4,
      "name": "Empty",
      "level": 0
    },
    {
      "x": 3,
      "y": 1,
      "z": 5,
      "name": "Empty",
      "level": 0
    },
    {
      "x": 3,
      "y": 2,
      "z": 5,
      "name": "Empty",
      "level": 0
    },
    {
      "x": 4,
      "y": 1,
      "z": -3,
      "name": "Empty",
      "level": 0
    },
    {
      "x": 4,
      "y": 0,
      "z": -2,
      "name": "Empty",
      "level": 0
    },
    {
      "x": 4,
      "y": 1,
      "z": -2,
      "name": "Empty",
      "level": 0
    },
    {
      "x": 4,
      "y": 2,
      "z": -2,
      "name": "Empty",
      "level": 0
    },
    {
      "x": 4,
      "y": 3,
      "z": -2,
      "name": "Empty",
      "level": 0
    },
    {
      "x": 4,
      "y": 4,
      "z": -2,
      "name": "Empty",
      "level": 0
    },
    {
      "x": 4,
      "y": 0,
      "z": -1,
      "name": "Empty",
      "level": 0
    },
    {
      "x": 4,
      "y": 1,
      "z": -1,
      "name": "Empty",
      "level": 0
    },
    {
      "x": 4,
      "y": 2,
      "z": -1,
      "name": "Empty",
      "level": 0
    },
    {
      "x": 4,
      "y": 3,
      "z": -1,
      "name": "Empty",
      "level": 0
    },
    {
      "x": 4,
      "y": 4,
      "z": -1,
      "name": "Empty",
      "level": 0
    },
    {
      "x": 4,
      "y": 0,
      "z": 0,
      "name": "Empty",
      "level": 0
    },
    {
      "x": 4,
      "y": 1,
      "z": 0,
      "name": "Empty",
      "level": 0
    },
    {
      "x": 4,
      "y": 2,
      "z": 0,
      "name": "Empty",
      "level": 0
    },
    {
      "x": 4,
      "y": 3,
      "z": 0,
      "name": "Empty",
      "level": 0
    },
    {
      "x": 4,
      "y": 4,
      "z": 0,
      "name": "Empty",
      "level": 0
    },
    {
      "x": 4,
      "y": 0,
      "z": 1,
      "name": "Empty",
      "level": 0
    },
    {
      "x": 4,
      "y": 1,
      "z": 1,
      "name": "Empty",
      "level": 0
    },
    {
      "x": 4,
      "y": 2,
      "z": 1,
      "name": "Empty",
      "level": 0
    },
    {
      "x": 4,
      "y": 3,
      "z": 1,
      "name": "Empty",
      "level": 0
    },
    {
      "x": 4,
      "y": 0,
      "z": 2,
      "name": "Empty",
      "level": 0
    },
    {
      "x": 4,
      "y": 1,
      "z": 2,
      "name": "Empty",
      "level": 0
    },
    {
      "x": 4,
      "y": 2,
      "z": 2,
      "name": "Empty",
      "level": 0
    },
    {
      "x": 4,
      "y": 3,
      "z": 2,
      "name": "Empty",
      "level": 0
    },
    {
      "x": 4,
      "y": 0,
      "z": 3,
      "name": "Empty",
      "level": 0
    },
    {
      "x": 4,
      "y": 1,
      "z": 3,
      "name": "Empty",
      "level": 0
    },
    {
      "x": 4,
      "y": 2,
      "z": 3,
      "name": "Empty",
      "level": 0
    },
    {
      "x": 4,
      "y": 3,
      "z": 3,
      "name": "Empty",
      "level": 0
    },
    {
      "x": 4,
      "y": 1,
      "z": 4,
      "name": "Empty",
      "level": 0
    },
    {
      "x": 4,
      "y": 2,
      "z": 4,
      "name": "Empty",
      "level": 0
    },
    {
      "x": 5,
      "y": 1,
      "z": -3,
      "name": "Empty",
      "level": 0
    },
    {
      "x": 5,
      "y": 1,
      "z": -2,
      "name": "Empty",
      "level": 0
    },
    {
      "x": 5,
      "y": 2,
      "z": -2,
      "name": "Empty",
      "level": 0
    },
    {
      "x": 5,
      "y": 3,
      "z": -2,
      "name": "Empty",
      "level": 0
    },
    {
      "x": 5,
      "y": 0,
      "z": -1,
      "name": "Empty",
      "level": 0
    },
    {
      "x": 5,
      "y": 1,
      "z": -1,
      "name": "Empty",
      "level": 0
    },
    {
      "x": 5,
      "y": 2,
      "z": -1,
      "name": "Empty",
      "level": 0
    },
    {
      "x": 5,
      "y": 3,
      "z": -1,
      "name": "Empty",
      "level": 0
    },
    {
      "x": 5,
      "y": 0,
      "z": 0,
      "name": "Empty",
      "level": 0
    },
    {
      "x": 5,
      "y": 1,
      "z": 0,
      "name": "Empty",
      "level": 0
    },
    {
      "x": 5,
      "y": 2,
      "z": 0,
      "name": "Empty",
      "level": 0
    },
    {
      "x": 5,
      "y": 3,
      "z": 0,
      "name": "Empty",
      "level": 0
    },
    {
      "x": 5,
      "y": 1,
      "z": 1,
      "name": "Empty",
      "level": 0
    },
    {
      "x": 5,
      "y": 2,
      "z": 1,
      "name": "Empty",
      "level": 0
    },
    {
      "x": 5,
      "y": 3,
      "z": 1,
      "name": "Empty",
      "level": 0
    },
    {
      "x": 5,
      "y": 1,
      "z": 2,
      "name": "Empty",
      "level": 0
    },
    {
      "x": 5,
      "y": 2,
      "z": 2,
      "name": "Empty",
      "level": 0
    },
    {
      "x": 5,
      "y": 1,
      "z": 3,
      "name": "Empty",
      "level": 0
    },
    {
      "x": 5,
      "y": 2,
      "z": 3,
      "name": "Empty",
      "level": 0
    },
    {
      "x": 6,
      "y": 1,
      "z": -2,
      "name": "Empty",
      "level": 0
    },
    {
      "x": 6,
      "y": 1,
      "z": -1,
      "name": "Empty",
      "level": 0
    },
    {
      "x": 6,
      "y": 2,
      "z": -1,
      "name": "Empty",
      "level": 0
    },
    {
      "x": 6,
      "y": 0,
      "z": 0,
      "name": "Empty",
      "level": 0
    },
    {
      "x": 6,
      "y": 1,
      "z": 0,
      "name": "Empty",
      "level": 0
    },
    {
      "x": 6,
      "y": 2,
      "z": 0,
      "name": "Empty",
      "level": 0
    },
    {
      "x": 6,
      "y": 1,
      "z": 1,
      "name": "Empty",
      "level": 0
    }
  ]
}