{
  "version": 8,
  "blockIdVersion": 11,
  "anchorX": 0,
  "anchorY": 0,
  "anchorZ": 0,
  "blocks": [
    {
      "x": -14,
      "y": 32,
      "z": -17,
      "name": "Fullmetal_Plant_Leaves_Crystal_Cyan"
    },
    {
      "x": -13,
      "y": 32,
      "z": -18,
      "name": "Fullmetal_Plant_Leaves_Crystal_Cyan",
      "support": 2
    },
    {
      "x": -13,
      "y": 32,
      "z": -17,
      "name": "Fullmetal_Plant_Leaves_Crystal_Cyan",
      "support": 1
    },
    {
      "x": -13,
      "y": 32,
      "z": -16,
      "name": "Fullmetal_Plant_Leaves_Crystal_Cyan",
      "support": 2
    },
    {
      "x": -13,
      "y": 32,
      "z": -15,
      "name": "Fullmetal_Plant_Leaves_Crystal_Cyan",
      "support": 3
    },
    {
      "x": -13,
      "y": 21,
      "z": -11,
      "name": "Fullmetal_Plant_Leaves_Crystal_Cyan"
    },
    {
      "x": -13,
      "y": 21,
      "z": -10,
      "name": "Fullmetal_Plant_Leaves_Crystal_Cyan"
    },
    {
      "x": -13,
      "y": 21,
      "z": -9,
      "name": "Fullmetal_Plant_Leaves_Crystal_Cyan"
    },
    {
      "x": -13,
      "y": 31,
      "z": -9,
      "name": "Fullmetal_Plant_Leaves_Crystal_Cyan",
      "support": 4
    },
    {
      "x": -12,
      "y": 32,
      "z": -19,
      "name": "Fullmetal_Plant_Leaves_Crystal_Cyan",
      "support": 2
    },
    {
      "x": -12,
      "y": 30,
      "z": -18,
      "name": "Fullmetal_Plant_Leaves_Crystal_Cyan",
      "support": 1
    },
    {
      "x": -12,
      "y": 31,
      "z": -18,
      "name": "Fullmetal_Plant_Leaves_Crystal_Cyan"
    },
    {
      "x": -12,
      "y": 32,
      "z": -18,
      "name": "Fullmetal_Plant_Leaves_Crystal_Cyan",
      "support": 1
    },
    {
      "x": -12,
      "y": 31,
      "z": -17,
      "name": "Fullmetal_Plant_Leaves_Crystal_Cyan",
      "support": 1
    },
    {
      "x": -12,
      "y": 32,
      "z": -17,
      "name": "Fullmetal_Plant_Leaves_Crystal_Cyan",
      "support": 2
    },
    {
      "x": -12,
      "y": 32,
      "z": -16,
      "name": "Fullmetal_Plant_Leaves_Crystal_Cyan",
      "support": 3
    },
    {
      "x": -12,
      "y": 31,
      "z": -15,
      "name": "Fullmetal_Plant_Leaves_Crystal_Cyan",
      "support": 3
    },
    {
      "x": -12,
      "y": 32,
      "z": -15,
      "name": "Fullmetal_Plant_Leaves_Crystal_Cyan",
      "support": 2
    },
    {
      "x": -12,
      "y": 31,
      "z": -14,
      "name": "Fullmetal_Plant_Leaves_Crystal_Cyan",
      "support": 3
    },
    {
      "x": -12,
      "y": 32,
      "z": -14,
      "name": "Fullmetal_Plant_Leaves_Crystal_Cyan",
      "support": 2
    },
    {
      "x": -12,
      "y": 21,
      "z": -13,
      "name": "Fullmetal_Plant_Leaves_Crystal_Cyan"
    },
    {
      "x": -12,
      "y": 31,
      "z": -13,
      "name": "Fullmetal_Plant_Leaves_Crystal_Cyan",
      "support": 4
    },
    {
      "x": -12,
      "y": 20,
      "z": -12,
      "name": "Fullmetal_Plant_Leaves_Crystal_Cyan"
    },
    {
      "x": -12,
      "y": 21,
      "z": -12,
      "name": "Fullmetal_Plant_Leaves_Crystal_Cyan"
    },
    {
      "x": -12,
      "y": 21,
      "z": -11,
      "name": "Fullmetal_Plant_Leaves_Crystal_Cyan"
    },
    {
      "x": -12,
      "y": 22,
      "z": -11,
      "name": "Fullmetal_Plant_Leaves_Crystal_Cyan"
    },
    {
      "x": -12,
      "y": 21,
      "z": -10,
      "name": "Fullmetal_Plant_Leaves_Crystal_Cyan"
    },
    {
      "x": -12,
      "y": 22,
      "z": -10,
      "name": "Fullmetal_Plant_Leaves_Crystal_Cyan"
    },
    {
      "x": -12,
      "y": 31,
      "z": -10,
      "name": "Fullmetal_Plant_Leaves_Crystal_Cyan",
      "support": 4
    },
    {
      "x": -12,
      "y": 20,
      "z": -9,
      "name": "Fullmetal_Plant_Leaves_Crystal_Cyan"
    },
    {
      "x": -12,
      "y": 21,
      "z": -9,
      "name": "Fullmetal_Plant_Leaves_Crystal_Cyan"
    },
    {
      "x": -12,
      "y": 22,
      "z": -9,
      "name": "Fullmetal_Plant_Leaves_Crystal_Cyan"
    },
    {
      "x": -12,
      "y": 31,
      "z": -9,
      "name": "Fullmetal_Plant_Leaves_Crystal_Cyan",
      "support": 3
    },
    {
      "x": -12,
      "y": 21,
      "z": -8,
      "name": "Fullmetal_Plant_Leaves_Crystal_Cyan"
    },
    {
      "x": -12,
      "y": 22,
      "z": -8,
      "name": "Fullmetal_Plant_Leaves_Crystal_Cyan"
    },
    {
      "x": -12,
      "y": 31,
      "z": -8,
      "name": "Fullmetal_Plant_Leaves_Crystal_Cyan",
      "support": 4
    },
    {
      "x": -12,
      "y": 21,
      "z": -7,
      "name": "Fullmetal_Plant_Leaves_Crystal_Cyan"
    },
    {
      "x": -12,
      "y": 22,
      "z": -7,
      "name": "Fullmetal_Plant_Leaves_Crystal_Cyan"
    },
    {
      "x": -12,
      "y": 21,
      "z": -6,
      "name": "Fullmetal_Plant_Leaves_Crystal_Cyan"
    },
    {
      "x": -11,
      "y": 30,
      "z": -21,
      "name": "Fullmetal_Plant_Leaves_Crystal_Cyan",
      "support": 2
    },
    {
      "x": -11,
      "y": 31,
      "z": -21,
      "name": "Fullmetal_Plant_Leaves_Crystal_Cyan",
      "support": 1
    },
    {
      "x": -11,
      "y": 31,
      "z": -20,
      "name": "Fullmetal_Plant_Leaves_Crystal_Cyan"
    },
    {
      "x": -11,
      "y": 32,
      "z": -20,
      "name": "Fullmetal_Plant_Leaves_Crystal_Cyan",
      "support": 1
    },
    {
      "x": -11,
      "y": 31,
      "z": -19,
      "name": "Fullmetal_Plant_Leaves_Crystal_Cyan"
    },
    {
      "x": -11,
      "y": 32,
      "z": -19,
      "name": "Fullmetal_Plant_Leaves_Crystal_Cyan",
      "support": 1
    },
    {
      "x": -11,
      "y": 31,
      "z": -18,
      "name": "Wood_Crystal_Branch_Long",
      "rotation": 5
    },
    {
      "x": -11,
      "y": 32,
      "z": -18,
      "name": "Fullmetal_Plant_Leaves_Crystal_Cyan"
    },
    {
      "x": -11,
      "y": 31,
      "z": -17,
      "name": "Fullmetal_Plant_Leaves_Crystal_Cyan"
    },
    {
      "x": -11,
      "y": 32,
      "z": -17,
      "name": "Fullmetal_Plant_Leaves_Crystal_Cyan",
      "support": 1
    },
    {
      "x": -11,
      "y": 33,
      "z": -17,
      "name": "Fullmetal_Plant_Leaves_Crystal_Cyan",
      "support": 2
    },
    {
      "x": -11,
      "y": 31,
      "z": -16,
      "name": "Fullmetal_Plant_Leaves_Crystal_Cyan",
      "support": 1
    },
    {
      "x": -11,
      "y": 32,
      "z": -16,
      "name": "Fullmetal_Plant_Leaves_Crystal_Cyan",
      "support": 2
    },
    {
      "x": -11,
      "y": 33,
      "z": -16,
      "name": "Fullmetal_Plant_Leaves_Crystal_Cyan",
      "support": 3
    },
    {
      "x": -11,
      "y": 36,
      "z": -16,
      "name": "Fullmetal_Plant_Leaves_Crystal_Cyan",
      "support": 4
    },
    {
      "x": -11,
      "y": 32,
      "z": -15,
      "name": "Fullmetal_Plant_Leaves_Crystal_Cyan",
      "support": 1
    },
    {
      "x": -11,
      "y": 21,
      "z": -14,
      "name": "Fullmetal_Plant_Leaves_Crystal_Cyan"
    },
    {
      "x": -11,
      "y": 31,
      "z": -14,
      "name": "Plant_Fruit_Azure",
      "rotation": 8
    },
    {
      "x": -11,
      "y": 32,
      "z": -14,
      "name": "Fullmetal_Plant_Leaves_Crystal_Cyan",
      "support": 1
    },
    {
      "x": -11,
      "y": 33,
      "z": -14,
      "name": "Fullmetal_Plant_Leaves_Crystal_Cyan",
      "support": 2
    },
    {
      "x": -11,
      "y": 21,
      "z": -13,
      "name": "Fullmetal_Plant_Leaves_Crystal_Cyan"
    },
    {
      "x": -11,
      "y": 31,
      "z": -13,
      "name": "Fullmetal_Plant_Leaves_Crystal_Cyan",
      "support": 3
    },
    {
      "x": -11,
      "y": 32,
      "z": -13,
      "name": "Fullmetal_Plant_Leaves_Crystal_Cyan",
      "support": 2
    },
    {
      "x": -11,
      "y": 20,
      "z": -12,
      "name": "Fullmetal_Plant_Leaves_Crystal_Cyan"
    },
    {
      "x": -11,
      "y": 21,
      "z": -12,
      "name": "Fullmetal_Plant_Leaves_Crystal_Cyan"
    },
    {
      "x": -11,
      "y": 22,
      "z": -12,
      "name": "Fullmetal_Plant_Leaves_Crystal_Cyan"
    },
    {
      "x": -11,
      "y": 20,
      "z": -11,
      "name": "Fullmetal_Plant_Leaves_Crystal_Cyan"
    },
    {
      "x": -11,
      "y": 21,
      "z": -11,
      "name": "Fullmetal_Plant_Leaves_Crystal_Cyan"
    },
    {
      "x": -11,
      "y": 22,
      "z": -11,
      "name": "Fullmetal_Plant_Leaves_Crystal_Cyan"
    },
    {
      "x": -11,
      "y": 23,
      "z": -11,
      "name": "Fullmetal_Plant_Leaves_Crystal_Cyan"
    },
    {
      "x": -11,
      "y": 21,
      "z": -10,
      "name": "Fullmetal_Plant_Leaves_Crystal_Cyan"
    },
    {
      "x": -11,
      "y": 22,
      "z": -10,
      "name": "Fullmetal_Plant_Leaves_Crystal_Cyan"
    },
    {
      "x": -11,
      "y": 23,
      "z": -10,
      "name": "Fullmetal_Plant_Leaves_Crystal_Cyan"
    },
    {
      "x": -11,
      "y": 31,
      "z": -10,
      "name": "Fullmetal_Plant_Leaves_Crystal_Cyan",
      "support": 3
    },
    {
      "x": -11,
      "y": 21,
      "z": -9,
      "name": "Fullmetal_Plant_Leaves_Crystal_Cyan"
    },
    {
      "x": -11,
      "y": 22,
      "z": -9,
      "name": "Fullmetal_Plant_Leaves_Crystal_Cyan"
    },
    {
      "x": -11,
      "y": 23,
      "z": -9,
      "name": "Fullmetal_Plant_Leaves_Crystal_Cyan"
    },
    {
      "x": -11,
      "y": 31,
      "z": -9,
      "name": "Fullmetal_Plant_Leaves_Crystal_Cyan",
      "support": 2
    },
    {
      "x": -11,
      "y": 21,
      "z": -8,
      "name": "Fullmetal_Plant_Leaves_Crystal_Cyan"
    },
    {
      "x": -11,
      "y": 22,
      "z": -8,
      "name": "Fullmetal_Plant_Leaves_Crystal_Cyan"
    },
    {
      "x": -11,
      "y": 30,
      "z": -8,
      "name": "Fullmetal_Plant_Leaves_Crystal_Cyan",
      "support": 4
    },
    {
      "x": -11,
      "y": 31,
      "z": -8,
      "name": "Fullmetal_Plant_Leaves_Crystal_Cyan",
      "support": 3
    },
    {
      "x": -11,
      "y": 32,
      "z": -8,
      "name": "Fullmetal_Plant_Leaves_Crystal_Cyan",
      "support": 4
    },
    {
      "x": -11,
      "y": 21,
      "z": -7,
      "name": "Fullmetal_Plant_Leaves_Crystal_Cyan"
    },
    {
      "x": -11,
      "y": 22,
      "z": -7,
      "name": "Fullmetal_Plant_Leaves_Crystal_Cyan"
    },
    {
      "x": -11,
      "y": 31,
      "z": -7,
      "name": "Fullmetal_Plant_Leaves_Crystal_Cyan",
      "support": 4
    },
    {
      "x": -11,
      "y": 21,
      "z": -6,
      "name": "Fullmetal_Plant_Leaves_Crystal_Cyan"
    },
    {
      "x": -11,
      "y": 22,
      "z": -6,
      "name": "Fullmetal_Plant_Leaves_Crystal_Cyan"
    },
    {
      "x": -11,
      "y": 21,
      "z": -5,
      "name": "Fullmetal_Plant_Leaves_Crystal_Cyan"
    },
    {
      "x": -11,
      "y": 22,
      "z": -5,
      "name": "Fullmetal_Plant_Leaves_Crystal_Cyan"
    },
    {
      "x": -11,
      "y": 32,
      "z": -4,
      "name": "Fullmetal_Plant_Leaves_Crystal_Cyan"
    },
    {
      "x": -11,
      "y": 33,
      "z": -4,
      "name": "Fullmetal_Plant_Leaves_Crystal_Cyan"
    },
    {
      "x": -11,
      "y": 32,
      "z": -3,
      "name": "Fullmetal_Plant_Leaves_Crystal_Cyan"
    },
    {
      "x": -11,
      "y": 33,
      "z": -3,
      "name": "Fullmetal_Plant_Leaves_Crystal_Cyan"
    },
    {
      "x": -11,
      "y": 32,
      "z": -2,
      "name": "Fullmetal_Plant_Leaves_Crystal_Cyan"
    },
    {
      "x": -11,
      "y": 33,
      "z": -2,
      "name": "Fullmetal_Plant_Leaves_Crystal_Cyan"
    },
    {
      "x": -10,
      "y": 31,
      "z": -21,
      "name": "Fullmetal_Plant_Leaves_Crystal_Cyan"
    },
    {
      "x": -10,
      "y": 32,
      "z": -21,
      "name": "Fullmetal_Plant_Leaves_Crystal_Cyan",
      "support": 1
    },
    {
      "x": -10,
      "y": 31,
      "z": -20,
      "name": "Wood_Crystal_Branch_Corner",
      "support": 1,
      "rotation": 2
    },
    {
      "x": -10,
      "y": 32,
      "z": -20,
      "name": "Fullmetal_Plant_Leaves_Crystal_Cyan"
    },
    {
      "x": -10,
      "y": 31,
      "z": -19,
      "name": "Wood_Crystal_Branch_Long",
      "rotation": 4
    },
    {
      "x": -10,
      "y": 32,
      "z": -19,
      "name": "Fullmetal_Plant_Leaves_Crystal_Cyan"
    },
    {
      "x": -10,
      "y": 33,
      "z": -19,
      "name": "Fullmetal_Plant_Leaves_Crystal_Cyan",
      "support": 1
    },
    {
      "x": -10,
      "y": 34,
      "z": -19,
      "name": "Fullmetal_Plant_Leaves_Crystal_Cyan",
      "support": 2
    },
    {
      "x": -10,
      "y": 31,
      "z": -18,
      "name": "Wood_Crystal_Trunk_Full",
      "support": 4
    },
    {
      "x": -10,
      "y": 32,
      "z": -18,
      "name": "Fullmetal_Plant_Leaves_Crystal_Cyan"
    },
    {
      "x": -10,
      "y": 31,
      "z": -17,
      "name": "Wood_Crystal_Trunk_Full",
      "support": 3
    },
    {
      "x": -10,
      "y": 32,
      "z": -17,
      "name": "Fullmetal_Plant_Leaves_Crystal_Cyan"
    },
    {
      "x": -10,
      "y": 33,
      "z": -17,
      "name": "Fullmetal_Plant_Leaves_Crystal_Cyan",
      "support": 1
    },
    {
      "x": -10,
      "y": 36,
      "z": -17,
      "name": "Fullmetal_Plant_Leaves_Crystal_Cyan",
      "support": 4
    },
    {
      "x": -10,
      "y": 21,
      "z": -16,
      "name": "Fullmetal_Plant_Leaves_Crystal_Cyan"
    },
    {
      "x": -10,
      "y": 31,
      "z": -16,
      "name": "Fullmetal_Plant_Leaves_Crystal_Cyan"
    },
    {
      "x": -10,
      "y": 32,
      "z": -16,
      "name": "Fullmetal_Plant_Leaves_Crystal_Cyan",
      "support": 1
    },
    {
      "x": -10,
      "y": 33,
      "z": -16,
      "name": "Fullmetal_Plant_Leaves_Crystal_Cyan",
      "support": 2
    },
    {
      "x": -10,
      "y": 35,
      "z": -16,
      "name": "Fullmetal_Plant_Leaves_Crystal_Cyan",
      "support": 4
    },
    {
      "x": -10,
      "y": 36,
      "z": -16,
      "name": "Fullmetal_Plant_Leaves_Crystal_Cyan",
      "support": 3
    },
    {
      "x": -10,
      "y": 37,
      "z": -16,
      "name": "Fullmetal_Plant_Leaves_Crystal_Cyan",
      "support": 4
    },
    {
      "x": -10,
      "y": 21,
      "z": -15,
      "name": "Fullmetal_Plant_Leaves_Crystal_Cyan"
    },
    {
      "x": -10,
      "y": 31,
      "z": -15,
      "name": "Wood_Crystal_Branch_Corner",
      "rotation": 2
    },
    {
      "x": -10,
      "y": 32,
      "z": -15,
      "name": "Fullmetal_Plant_Leaves_Crystal_Cyan"
    },
    {
      "x": -10,
      "y": 33,
      "z": -15,
      "name": "Fullmetal_Plant_Leaves_Crystal_Cyan",
      "support": 1
    },
    {
      "x": -10,
      "y": 35,
      "z": -15,
      "name": "Fullmetal_Plant_Leaves_Crystal_Cyan",
      "support": 3
    },
    {
      "x": -10,
      "y": 36,
      "z": -15,
      "name": "Fullmetal_Plant_Leaves_Crystal_Cyan",
      "support": 4
    },
    {
      "x": -10,
      "y": 21,
      "z": -14,
      "name": "Fullmetal_Plant_Leaves_Crystal_Cyan"
    },
    {
      "x": -10,
      "y": 22,
      "z": -14,
      "name": "Fullmetal_Plant_Leaves_Crystal_Cyan"
    },
    {
      "x": -10,
      "y": 31,
      "z": -14,
      "name": "Wood_Crystal_Trunk_Full",
      "support": 2
    },
    {
      "x": -10,
      "y": 32,
      "z": -14,
      "name": "Fullmetal_Plant_Leaves_Crystal_Cyan"
    },
    {
      "x": -10,
      "y": 33,
      "z": -14,
      "name": "Fullmetal_Plant_Leaves_Crystal_Cyan",
      "support": 1
    },
    {
      "x": -10,
      "y": 35,
      "z": -14,
      "name": "Fullmetal_Plant_Leaves_Crystal_Cyan",
      "support": 4
    },
    {
      "x": -10,
      "y": 21,
      "z": -13,
      "name": "Fullmetal_Plant_Leaves_Crystal_Cyan"
    },
    {
      "x": -10,
      "y": 22,
      "z": -13,
      "name": "Fullmetal_Plant_Leaves_Crystal_Cyan"
    },
    {
      "x": -10,
      "y": 33,
      "z": -13,
      "name": "Fullmetal_Plant_Leaves_Crystal_Cyan",
      "support": 2
    },
    {
      "x": -10,
      "y": 22,
      "z": -12,
      "name": "Fullmetal_Plant_Leaves_Crystal_Cyan"
    },
    {
      "x": -10,
      "y": 20,
      "z": -11,
      "name": "Fullmetal_Plant_Leaves_Crystal_Cyan"
    },
    {
      "x": -10,
      "y": 21,
      "z": -11,
      "name": "Fullmetal_Plant_Leaves_Crystal_Cyan"
    },
    {
      "x": -10,
      "y": 22,
      "z": -11,
      "name": "Fullmetal_Plant_Leaves_Crystal_Cyan"
    },
    {
      "x": -10,
      "y": 23,
      "z": -11,
      "name": "Fullmetal_Plant_Leaves_Crystal_Cyan"
    },
    {
      "x": -10,
      "y": 19,
      "z": -10,
      "name": "Wood_Crystal_Roots"
    },
    {
      "x": -10,
      "y": 20,
      "z": -10,
      "name": "Wood_Crystal_Trunk_Full"
    },
    {
      "x": -10,
      "y": 21,
      "z": -10,
      "name": "Fullmetal_Plant_Leaves_Crystal_Cyan"
    },
    {
      "x": -10,
      "y": 22,
      "z": -10,
      "name": "Fullmetal_Plant_Leaves_Crystal_Cyan"
    },
    {
      "x": -10,
      "y": 23,
      "z": -10,
      "name": "Fullmetal_Plant_Leaves_Crystal_Cyan"
    },
    {
      "x": -10,
      "y": 20,
      "z": -9,
      "name": "Fullmetal_Plant_Leaves_Crystal_Cyan"
    },
    {
      "x": -10,
      "y": 21,
      "z": -9,
      "name": "Fullmetal_Plant_Leaves_Crystal_Cyan"
    },
    {
      "x": -10,
      "y": 22,
      "z": -9,
      "name": "Fullmetal_Plant_Leaves_Crystal_Cyan"
    },
    {
      "x": -10,
      "y": 23,
      "z": -9,
      "name": "Fullmetal_Plant_Leaves_Crystal_Cyan"
    },
    {
      "x": -10,
      "y": 31,
      "z": -9,
      "name": "Fullmetal_Plant_Leaves_Crystal_Cyan",
      "support": 1
    },
    {
      "x": -10,
      "y": 21,
      "z": -8,
      "name": "Fullmetal_Plant_Leaves_Crystal_Cyan"
    },
    {
      "x": -10,
      "y": 22,
      "z": -8,
      "name": "Fullmetal_Plant_Leaves_Crystal_Cyan"
    },
    {
      "x": -10,
      "y": 23,
      "z": -8,
      "name": "Fullmetal_Plant_Leaves_Crystal_Cyan"
    },
    {
      "x": -10,
      "y": 30,
      "z": -8,
      "name": "Fullmetal_Plant_Leaves_Crystal_Cyan",
      "support": 3
    },
    {
      "x": -10,
      "y": 31,
      "z": -8,
      "name": "Fullmetal_Plant_Leaves_Crystal_Cyan",
      "support": 2
    },
    {
      "x": -10,
      "y": 20,
      "z": -7,
      "name": "Fullmetal_Plant_Leaves_Crystal_Cyan"
    },
    {
      "x": -10,
      "y": 21,
      "z": -7,
      "name": "Fullmetal_Plant_Leaves_Crystal_Cyan"
    },
    {
      "x": -10,
      "y": 22,
      "z": -7,
      "name": "Fullmetal_Plant_Leaves_Crystal_Cyan"
    },
    {
      "x": -10,
      "y": 31,
      "z": -7,
      "name": "Fullmetal_Plant_Leaves_Crystal_Cyan",
      "support": 3
    },
    {
      "x": -10,
      "y": 20,
      "z": -6,
      "name": "Fullmetal_Plant_Leaves_Crystal_Cyan"
    },
    {
      "x": -10,
      "y": 21,
      "z": -6,
      "name": "Fullmetal_Plant_Leaves_Crystal_Cyan"
    },
    {
      "x": -10,
      "y": 22,
      "z": -6,
      "name": "Fullmetal_Plant_Leaves_Crystal_Cyan"
    },
    {
      "x": -10,
      "y": 23,
      "z": -6,
      "name": "Fullmetal_Plant_Leaves_Crystal_Cyan"
    },
    {
      "x": -10,
      "y": -8,
      "z": -5,
      "name": "Wood_Crystal_Roots"
    },
    {
      "x": -10,
      "y": -7,
      "z": -5,
      "name": "Wood_Crystal_Trunk"
    },
    {
      "x": -10,
      "y": -6,
      "z": -5,
      "name": "Wood_Crystal_Trunk"
    },
    {
      "x": -10,
      "y": -5,
      "z": -5,
      "name": "Wood_Crystal_Trunk"
    },
    {
      "x": -10,
      "y": -4,
      "z": -5,
      "name": "Wood_Crystal_Trunk_Full"
    },
    {
      "x": -10,
      "y": 21,
      "z": -5,
      "name": "Fullmetal_Plant_Leaves_Crystal_Cyan"
    },
    {
      "x": -10,
      "y": 22,
      "z": -5,
      "name": "Fullmetal_Plant_Leaves_Crystal_Cyan"
    },
    {
      "x": -10,
      "y": 32,
      "z": -5,
      "name": "Fullmetal_Plant_Leaves_Crystal_Cyan"
    },
    {
      "x": -10,
      "y": 33,
      "z": -5,
      "name": "Fullmetal_Plant_Leaves_Crystal_Cyan"
    },
    {
      "x": -10,
      "y": -6,
      "z": -4,
      "name": "Wood_Crystal_Trunk"
    },
    {
      "x": -10,
      "y": -5,
      "z": -4,
      "name": "Wood_Crystal_Trunk"
    },
    {
      "x": -10,
      "y": -4,
      "z": -4,
      "name": "Wood_Crystal_Trunk"
    },
    {
      "x": -10,
      "y": -3,
      "z": -4,
      "name": "Wood_Crystal_Trunk_Full"
    },
    {
      "x": -10,
      "y": 22,
      "z": -4,
      "name": "Fullmetal_Plant_Leaves_Crystal_Cyan"
    },
    {
      "x": -10,
      "y": 31,
      "z": -4,
      "name": "Fullmetal_Plant_Leaves_Crystal_Cyan"
    },
    {
      "x": -10,
      "y": 32,
      "z": -4,
      "name": "Fullmetal_Plant_Leaves_Crystal_Cyan"
    },
    {
      "x": -10,
      "y": 33,
      "z": -4,
      "name": "Fullmetal_Plant_Leaves_Crystal_Cyan"
    },
    {
      "x": -10,
      "y": 31,
      "z": -3,
      "name": "Fullmetal_Plant_Leaves_Crystal_Cyan"
    },
    {
      "x": -10,
      "y": 32,
      "z": -3,
      "name": "Fullmetal_Plant_Leaves_Crystal_Cyan"
    },
    {
      "x": -10,
      "y": 33,
      "z": -3,
      "name": "Fullmetal_Plant_Leaves_Crystal_Cyan"
    },
    {
      "x": -10,
      "y": 31,
      "z": -2,
      "name": "Fullmetal_Plant_Leaves_Crystal_Cyan"
    },
    {
      "x": -10,
      "y": 32,
      "z": -2,
      "name": "Fullmetal_Plant_Leaves_Crystal_Cyan"
    },
    {
      "x": -10,
      "y": 33,
      "z": -2,
      "name": "Fullmetal_Plant_Leaves_Crystal_Cyan"
    },
    {
      "x": -10,
      "y": 31,
      "z": -1,
      "name": "Fullmetal_Plant_Leaves_Crystal_Cyan"
    },
    {
      "x": -10,
      "y": 32,
      "z": -1,
      "name": "Fullmetal_Plant_Leaves_Crystal_Cyan"
    },
    {
      "x": -10,
      "y": 33,
      "z": -1,
      "name": "Fullmetal_Plant_Leaves_Crystal_Cyan"
    },
    {
      "x": -9,
      "y": 32,
      "z": -21,
      "name": "Fullmetal_Plant_Leaves_Crystal_Cyan",
      "support": 2
    },
    {
      "x": -9,
      "y": 32,
      "z": -20,
      "name": "Fullmetal_Plant_Leaves_Crystal_Cyan",
      "support": 1
    },
    {
      "x": -9,
      "y": 29,
      "z": -19,
      "name": "Fullmetal_Plant_Leaves_Crystal_Cyan",
      "support": 2
    },
    {
      "x": -9,
      "y": 30,
      "z": -19,
      "name": "Fullmetal_Plant_Leaves_Crystal_Cyan",
      "support": 1
    },
    {
      "x": -9,
      "y": 31,
      "z": -19,
      "name": "Fullmetal_Plant_Leaves_Crystal_Cyan"
    },
    {
      "x": -9,
      "y": 32,
      "z": -19,
      "name": "Fullmetal_Plant_Leaves_Crystal_Cyan",
      "support": 1
    },
    {
      "x": -9,
      "y": 31,
      "z": -18,
      "name": "Fullmetal_Plant_Leaves_Crystal_Cyan"
    },
    {
      "x": -9,
      "y": 32,
      "z": -18,
      "name": "Fullmetal_Plant_Leaves_Crystal_Cyan",
      "support": 1
    },
    {
      "x": -9,
      "y": 21,
      "z": -17,
      "name": "Fullmetal_Plant_Leaves_Crystal_Cyan"
    },
    {
      "x": -9,
      "y": 31,
      "z": -17,
      "name": "Wood_Crystal_Trunk_Full",
      "support": 2
    },
    {
      "x": -9,
      "y": 32,
      "z": -17,
      "name": "Fullmetal_Plant_Leaves_Crystal_Cyan"
    },
    {
      "x": -9,
      "y": 33,
      "z": -17,
      "name": "Fullmetal_Plant_Leaves_Crystal_Cyan",
      "support": 1
    },
    {
      "x": -9,
      "y": 35,
      "z": -17,
      "name": "Fullmetal_Plant_Leaves_Crystal_Cyan",
      "support": 4
    },
    {
      "x": -9,
      "y": 36,
      "z": -17,
      "name": "Fullmetal_Plant_Leaves_Crystal_Cyan",
      "support": 3
    },
    {
      "x": -9,
      "y": 37,
      "z": -17,
      "name": "Fullmetal_Plant_Leaves_Crystal_Cyan",
      "support": 4
    },
    {
      "x": -9,
      "y": 21,
      "z": -16,
      "name": "Fullmetal_Plant_Leaves_Crystal_Cyan"
    },
    {
      "x": -9,
      "y": 32,
      "z": -16,
      "name": "Fullmetal_Plant_Leaves_Crystal_Cyan",
      "support": 1
    },
    {
      "x": -9,
      "y": 33,
      "z": -16,
      "name": "Fullmetal_Plant_Leaves_Crystal_Cyan",
      "support": 2
    },
    {
      "x": -9,
      "y": 35,
      "z": -16,
      "name": "Fullmetal_Plant_Leaves_Crystal_Cyan",
      "support": 3
    },
    {
      "x": -9,
      "y": 36,
      "z": -16,
      "name": "Fullmetal_Plant_Leaves_Crystal_Cyan",
      "support": 2
    },
    {
      "x": -9,
      "y": 37,
      "z": -16,
      "name": "Fullmetal_Plant_Leaves_Crystal_Cyan",
      "support": 3
    },
    {
      "x": -9,
      "y": 20,
      "z": -15,
      "name": "Fullmetal_Plant_Leaves_Crystal_Cyan"
    },
    {
      "x": -9,
      "y": 21,
      "z": -15,
      "name": "Fullmetal_Plant_Leaves_Crystal_Cyan"
    },
    {
      "x": -9,
      "y": 22,
      "z": -15,
      "name": "Fullmetal_Plant_Leaves_Crystal_Cyan"
    },
    {
      "x": -9,
      "y": 32,
      "z": -15,
      "name": "Fullmetal_Plant_Leaves_Crystal_Cyan",
      "support": 1
    },
    {
      "x": -9,
      "y": 35,
      "z": -15,
      "name": "Fullmetal_Plant_Leaves_Crystal_Cyan",
      "support": 2
    },
    {
      "x": -9,
      "y": 36,
      "z": -15,
      "name": "Fullmetal_Plant_Leaves_Crystal_Cyan",
      "support": 3
    },
    {
      "x": -9,
      "y": 37,
      "z": -15,
      "name": "Fullmetal_Plant_Leaves_Crystal_Cyan",
      "support": 4
    },
    {
      "x": -9,
      "y": 20,
      "z": -14,
      "name": "Fullmetal_Plant_Leaves_Crystal_Cyan"
    },
    {
      "x": -9,
      "y": 21,
      "z": -14,
      "name": "Fullmetal_Plant_Leaves_Crystal_Cyan"
    },
    {
      "x": -9,
      "y": 22,
      "z": -14,
      "name": "Fullmetal_Plant_Leaves_Crystal_Cyan"
    },
    {
      "x": -9,
      "y": 23,
      "z": -14,
      "name": "Fullmetal_Plant_Leaves_Crystal_Cyan"
    },
    {
      "x": -9,
      "y": 30,
      "z": -14,
      "name": "Wood_Crystal_Roots"
    },
    {
      "x": -9,
      "y": 31,
      "z": -14,
      "name": "Wood_Crystal_Trunk_Full",
      "support": 1
    },
    {
      "x": -9,
      "y": 32,
      "z": -14,
      "name": "Fullmetal_Plant_Leaves_Crystal_Cyan"
    },
    {
      "x": -9,
      "y": 35,
      "z": -14,
      "name": "Fullmetal_Plant_Leaves_Crystal_Cyan",
      "support": 3
    },
    {
      "x": -9,
      "y": 36,
      "z": -14,
      "name": "Fullmetal_Plant_Leaves_Crystal_Cyan",
      "support": 4
    },
    {
      "x": -9,
      "y": 21,
      "z": -13,
      "name": "Fullmetal_Plant_Leaves_Crystal_Cyan"
    },
    {
      "x": -9,
      "y": 22,
      "z": -13,
      "name": "Fullmetal_Plant_Leaves_Crystal_Cyan"
    },
    {
      "x": -9,
      "y": 32,
      "z": -13,
      "name": "Fullmetal_Plant_Leaves_Crystal_Cyan",
      "support": 1
    },
    {
      "x": -9,
      "y": 35,
      "z": -13,
      "name": "Fullmetal_Plant_Leaves_Crystal_Cyan",
      "support": 4
    },
    {
      "x": -9,
      "y": 20,
      "z": -12,
      "name": "Wood_Crystal_Branch_Corner",
      "rotation": 2
    },
    {
      "x": -9,
      "y": 21,
      "z": -12,
      "name": "Fullmetal_Plant_Leaves_Crystal_Cyan"
    },
    {
      "x": -9,
      "y": 30,
      "z": -12,
      "name": "Wood_Crystal_Trunk_Full",
      "support": 3
    },
    {
      "x": -9,
      "y": 20,
      "z": -11,
      "name": "Wood_Crystal_Branch_Long",
      "rotation": 4
    },
    {
      "x": -9,
      "y": 21,
      "z": -11,
      "name": "Fullmetal_Plant_Leaves_Crystal_Cyan"
    },
    {
      "x": -9,
      "y": 30,
      "z": -11,
      "name": "Wood_Crystal_Trunk_Full",
      "support": 4
    },
    {
      "x": -9,
      "y": 31,
      "z": -11,
      "name": "Wood_Crystal_Trunk_Full"
    },
    {
      "x": -9,
      "y": 19,
      "z": -10,
      "name": "Wood_Crystal_Roots"
    },
    {
      "x": -9,
      "y": 20,
      "z": -10,
      "name": "Wood_Crystal_Trunk_Full"
    },
    {
      "x": -9,
      "y": 21,
      "z": -10,
      "name": "Fullmetal_Plant_Leaves_Crystal_Cyan"
    },
    {
      "x": -9,
      "y": 22,
      "z": -10,
      "name": "Fullmetal_Plant_Leaves_Crystal_Cyan"
    },
    {
      "x": -9,
      "y": 23,
      "z": -10,
      "name": "Fullmetal_Plant_Leaves_Crystal_Cyan"
    },
    {
      "x": -9,
      "y": 31,
      "z": -10,
      "name": "Wood_Crystal_Trunk_Full",
      "support": 1
    },
    {
      "x": -9,
      "y": 20,
      "z": -9,
      "name": "Wood_Crystal_Trunk_Full"
    },
    {
      "x": -9,
      "y": 21,
      "z": -9,
      "name": "Fullmetal_Plant_Leaves_Crystal_Cyan"
    },
    {
      "x": -9,
      "y": 22,
      "z": -9,
      "name": "Fullmetal_Plant_Leaves_Crystal_Cyan"
    },
    {
      "x": -9,
      "y": 23,
      "z": -9,
      "name": "Fullmetal_Plant_Leaves_Crystal_Cyan"
    },
    {
      "x": -9,
      "y": 30,
      "z": -9,
      "name": "Fullmetal_Plant_Leaves_Crystal_Cyan",
      "support": 1
    },
    {
      "x": -9,
      "y": 31,
      "z": -9,
      "name": "Fullmetal_Plant_Leaves_Crystal_Cyan"
    },
    {
      "x": -9,
      "y": 20,
      "z": -8,
      "name": "Fullmetal_Plant_Leaves_Crystal_Cyan"
    },
    {
      "x": -9,
      "y": 21,
      "z": -8,
      "name": "Fullmetal_Plant_Leaves_Crystal_Cyan"
    },
    {
      "x": -9,
      "y": 22,
      "z": -8,
      "name": "Fullmetal_Plant_Leaves_Crystal_Cyan"
    },
    {
      "x": -9,
      "y": 23,
      "z": -8,
      "name": "Fullmetal_Plant_Leaves_Crystal_Cyan"
    },
    {
      "x": -9,
      "y": 31,
      "z": -8,
      "name": "Fullmetal_Plant_Leaves_Crystal_Cyan",
      "support": 1
    },
    {
      "x": -9,
      "y": 21,
      "z": -7,
      "name": "Wood_Crystal_Trunk_Full"
    },
    {
      "x": -9,
      "y": 22,
      "z": -7,
      "name": "Fullmetal_Plant_Leaves_Crystal_Cyan"
    },
    {
      "x": -9,
      "y": 23,
      "z": -7,
      "name": "Fullmetal_Plant_Leaves_Crystal_Cyan"
    },
    {
      "x": -9,
      "y": 21,
      "z": -6,
      "name": "Fullmetal_Plant_Leaves_Crystal_Cyan"
    },
    {
      "x": -9,
      "y": 22,
      "z": -6,
      "name": "Fullmetal_Plant_Leaves_Crystal_Cyan"
    },
    {
      "x": -9,
      "y": 23,
      "z": -6,
      "name": "Fullmetal_Plant_Leaves_Crystal_Cyan"
    },
    {
      "x": -9,
      "y": 33,
      "z": -6,
      "name": "Fullmetal_Plant_Leaves_Crystal_Cyan"
    },
    {
      "x": -9,
      "y": -7,
      "z": -5,
      "name": "Wood_Crystal_Roots"
    },
    {
      "x": -9,
      "y": -6,
      "z": -5,
      "name": "Wood_Crystal_Trunk"
    },
    {
      "x": -9,
      "y": -5,
      "z": -5,
      "name": "Wood_Crystal_Trunk"
    },
    {
      "x": -9,
      "y": -4,
      "z": -5,
      "name": "Wood_Crystal_Trunk_Full"
    },
    {
      "x": -9,
      "y": 20,
      "z": -5,
      "name": "Fullmetal_Plant_Leaves_Crystal_Cyan"
    },
    {
      "x": -9,
      "y": 21,
      "z": -5,
      "name": "Fullmetal_Plant_Leaves_Crystal_Cyan"
    },
    {
      "x": -9,
      "y": 22,
      "z": -5,
      "name": "Fullmetal_Plant_Leaves_Crystal_Cyan"
    },
    {
      "x": -9,
      "y": 33,
      "z": -5,
      "name": "Fullmetal_Plant_Leaves_Crystal_Cyan"
    },
    {
      "x": -9,
      "y": -6,
      "z": -4,
      "name": "Wood_Crystal_Roots"
    },
    {
      "x": -9,
      "y": -5,
      "z": -4,
      "name": "Wood_Crystal_Trunk"
    },
    {
      "x": -9,
      "y": -4,
      "z": -4,
      "name": "Wood_Crystal_Trunk"
    },
    {
      "x": -9,
      "y": -3,
      "z": -4,
      "name": "Wood_Crystal_Trunk"
    },
    {
      "x": -9,
      "y": -2,
      "z": -4,
      "name": "Wood_Crystal_Trunk_Full"
    },
    {
      "x": -9,
      "y": 21,
      "z": -4,
      "name": "Fullmetal_Plant_Leaves_Crystal_Cyan"
    },
    {
      "x": -9,
      "y": 22,
      "z": -4,
      "name": "Fullmetal_Plant_Leaves_Crystal_Cyan"
    },
    {
      "x": -9,
      "y": 32,
      "z": -4,
      "name": "Fullmetal_Plant_Leaves_Crystal_Cyan"
    },
    {
      "x": -9,
      "y": 33,
      "z": -4,
      "name": "Fullmetal_Plant_Leaves_Crystal_Cyan"
    },
    {
      "x": -9,
      "y": 34,
      "z": -4,
      "name": "Fullmetal_Plant_Leaves_Crystal_Cyan"
    },
    {
      "x": -9,
      "y": -4,
      "z": -3,
      "name": "Wood_Crystal_Trunk"
    },
    {
      "x": -9,
      "y": -3,
      "z": -3,
      "name": "Wood_Crystal_Trunk"
    },
    {
      "x": -9,
      "y": -2,
      "z": -3,
      "name": "Wood_Crystal_Trunk_Full"
    },
    {
      "x": -9,
      "y": 32,
      "z": -3,
      "name": "Fullmetal_Plant_Leaves_Crystal_Cyan"
    },
    {
      "x": -9,
      "y": 33,
      "z": -3,
      "name": "Fullmetal_Plant_Leaves_Crystal_Cyan"
    },
    {
      "x": -9,
      "y": 34,
      "z": -3,
      "name": "Fullmetal_Plant_Leaves_Crystal_Cyan"
    },
    {
      "x": -9,
      "y": 31,
      "z": -2,
      "name": "Fullmetal_Plant_Leaves_Crystal_Cyan"
    },
    {
      "x": -9,
      "y": 32,
      "z": -2,
      "name": "Fullmetal_Plant_Leaves_Crystal_Cyan"
    },
    {
      "x": -9,
      "y": 33,
      "z": -2,
      "name": "Fullmetal_Plant_Leaves_Crystal_Cyan"
    },
    {
      "x": -9,
      "y": 34,
      "z": -2,
      "name": "Fullmetal_Plant_Leaves_Crystal_Cyan"
    },
    {
      "x": -9,
      "y": 31,
      "z": -1,
      "name": "Fullmetal_Plant_Leaves_Crystal_Cyan"
    },
    {
      "x": -9,
      "y": 32,
      "z": -1,
      "name": "Fullmetal_Plant_Leaves_Crystal_Cyan"
    },
    {
      "x": -9,
      "y": 34,
      "z": -1,
      "name": "Fullmetal_Plant_Leaves_Crystal_Cyan"
    },
    {
      "x": -9,
      "y": 32,
      "z": 0,
      "name": "Fullmetal_Plant_Leaves_Crystal_Cyan"
    },
    {
      "x": -8,
      "y": 32,
      "z": -21,
      "name": "Fullmetal_Plant_Leaves_Crystal_Cyan",
      "support": 2
    },
    {
      "x": -8,
      "y": 31,
      "z": -20,
      "name": "Fullmetal_Plant_Leaves_Crystal_Cyan"
    },
    {
      "x": -8,
      "y": 32,
      "z": -20,
      "name": "Fullmetal_Plant_Leaves_Crystal_Cyan",
      "support": 1
    },
    {
      "x": -8,
      "y": 31,
      "z": -19,
      "name": "Wood_Crystal_Trunk_Full",
      "support": 3
    },
    {
      "x": -8,
      "y": 32,
      "z": -19,
      "name": "Fullmetal_Plant_Leaves_Crystal_Cyan"
    },
    {
      "x": -8,
      "y": 31,
      "z": -18,
      "name": "Wood_Crystal_Trunk_Full",
      "support": 2
    },
    {
      "x": -8,
      "y": 32,
      "z": -18,
      "name": "Fullmetal_Plant_Leaves_Crystal_Cyan"
    },
    {
      "x": -8,
      "y": 21,
      "z": -17,
      "name": "Fullmetal_Plant_Leaves_Crystal_Cyan"
    },
    {
      "x": -8,
      "y": 31,
      "z": -17,
      "name": "Wood_Crystal_Trunk_Full",
      "support": 1
    },
    {
      "x": -8,
      "y": 32,
      "z": -17,
      "name": "Fullmetal_Plant_Leaves_Crystal_Cyan"
    },
    {
      "x": -8,
      "y": 33,
      "z": -17,
      "name": "Fullmetal_Plant_Leaves_Crystal_Cyan",
      "support": 1
    },
    {
      "x": -8,
      "y": 37,
      "z": -17,
      "name": "Fullmetal_Plant_Leaves_Crystal_Cyan",
      "support": 3
    },
    {
      "x": -8,
      "y": 21,
      "z": -16,
      "name": "Fullmetal_Plant_Leaves_Crystal_Cyan"
    },
    {
      "x": -8,
      "y": 22,
      "z": -16,
      "name": "Fullmetal_Plant_Leaves_Crystal_Cyan"
    },
    {
      "x": -8,
      "y": 30,
      "z": -16,
      "name": "Wood_Crystal_Trunk_Full",
      "support": 4
    },
    {
      "x": -8,
      "y": 31,
      "z": -16,
      "name": "Wood_Crystal_Trunk_Full"
    },
    {
      "x": -8,
      "y": 33,
      "z": -16,
      "name": "Fullmetal_Plant_Leaves_Crystal_Cyan",
      "support": 2
    },
    {
      "x": -8,
      "y": 36,
      "z": -16,
      "name": "Fullmetal_Plant_Leaves_Crystal_Cyan",
      "support": 1
    },
    {
      "x": -8,
      "y": 37,
      "z": -16,
      "name": "Fullmetal_Plant_Leaves_Crystal_Cyan",
      "support": 2
    },
    {
      "x": -8,
      "y": 38,
      "z": -16,
      "name": "Fullmetal_Plant_Leaves_Crystal_Cyan",
      "support": 3
    },
    {
      "x": -8,
      "y": 20,
      "z": -15,
      "name": "Fullmetal_Plant_Leaves_Crystal_Cyan"
    },
    {
      "x": -8,
      "y": 21,
      "z": -15,
      "name": "Fullmetal_Plant_Leaves_Crystal_Cyan"
    },
    {
      "x": -8,
      "y": 22,
      "z": -15,
      "name": "Fullmetal_Plant_Leaves_Crystal_Cyan"
    },
    {
      "x": -8,
      "y": 23,
      "z": -15,
      "name": "Fullmetal_Plant_Leaves_Crystal_Cyan"
    },
    {
      "x": -8,
      "y": 30,
      "z": -15,
      "name": "Wood_Crystal_Trunk_Full",
      "support": 3
    },
    {
      "x": -8,
      "y": 35,
      "z": -15,
      "name": "Fullmetal_Plant_Leaves_Crystal_Cyan",
      "support": 1
    },
    {
      "x": -8,
      "y": 37,
      "z": -15,
      "name": "Fullmetal_Plant_Leaves_Crystal_Cyan",
      "support": 3
    },
    {
      "x": -8,
      "y": 20,
      "z": -14,
      "name": "Wood_Crystal_Trunk_Full"
    },
    {
      "x": -8,
      "y": 21,
      "z": -14,
      "name": "Fullmetal_Plant_Leaves_Crystal_Cyan"
    },
    {
      "x": -8,
      "y": 22,
      "z": -14,
      "name": "Fullmetal_Plant_Leaves_Crystal_Cyan"
    },
    {
      "x": -8,
      "y": 23,
      "z": -14,
      "name": "Fullmetal_Plant_Leaves_Crystal_Cyan"
    },
    {
      "x": -8,
      "y": 29,
      "z": -14,
      "name": "Wood_Crystal_Roots"
    },
    {
      "x": -8,
      "y": 30,
      "z": -14,
      "name": "Wood_Crystal_Trunk_Full",
      "support": 2
    },
    {
      "x": -8,
      "y": 31,
      "z": -14,
      "name": "Wood_Crystal_Trunk_Full"
    },
    {
      "x": -8,
      "y": 35,
      "z": -14,
      "name": "Fullmetal_Plant_Leaves_Crystal_Cyan",
      "support": 2
    },
    {
      "x": -8,
      "y": 20,
      "z": -13,
      "name": "Fullmetal_Plant_Leaves_Crystal_Cyan"
    },
    {
      "x": -8,
      "y": 21,
      "z": -13,
      "name": "Fullmetal_Plant_Leaves_Crystal_Cyan"
    },
    {
      "x": -8,
      "y": 22,
      "z": -13,
      "name": "Fullmetal_Plant_Leaves_Crystal_Cyan"
    },
    {
      "x": -8,
      "y": 30,
      "z": -13,
      "name": "Wood_Crystal_Trunk_Full",
      "support": 1
    },
    {
      "x": -8,
      "y": 35,
      "z": -13,
      "name": "Fullmetal_Plant_Leaves_Crystal_Cyan",
      "support": 3
    },
    {
      "x": -8,
      "y": 30,
      "z": -12,
      "name": "Wood_Crystal_Trunk_Full",
      "support": 2
    },
    {
      "x": -8,
      "y": 20,
      "z": -11,
      "name": "Wood_Crystal_Branch_Corner",
      "rotation": 2
    },
    {
      "x": -8,
      "y": 21,
      "z": -11,
      "name": "Fullmetal_Plant_Leaves_Crystal_Cyan"
    },
    {
      "x": -8,
      "y": 20,
      "z": -10,
      "name": "Wood_Crystal_Trunk_Full"
    },
    {
      "x": -8,
      "y": 37,
      "z": -10,
      "name": "Fullmetal_Plant_Leaves_Crystal_Cyan",
      "support": 4
    },
    {
      "x": -8,
      "y": 21,
      "z": -9,
      "name": "Fullmetal_Plant_Leaves_Crystal_Cyan"
    },
    {
      "x": -8,
      "y": 22,
      "z": -9,
      "name": "Fullmetal_Plant_Leaves_Crystal_Cyan"
    },
    {
      "x": -8,
      "y": 23,
      "z": -9,
      "name": "Fullmetal_Plant_Leaves_Crystal_Cyan"
    },
    {
      "x": -8,
      "y": 21,
      "z": -8,
      "name": "Fullmetal_Plant_Leaves_Crystal_Cyan"
    },
    {
      "x": -8,
      "y": 22,
      "z": -8,
      "name": "Fullmetal_Plant_Leaves_Crystal_Cyan"
    },
    {
      "x": -8,
      "y": 23,
      "z": -8,
      "name": "Fullmetal_Plant_Leaves_Crystal_Cyan"
    },
    {
      "x": -8,
      "y": 37,
      "z": -8,
      "name": "Fullmetal_Plant_Leaves_Crystal_Cyan",
      "support": 4
    },
    {
      "x": -8,
      "y": 21,
      "z": -7,
      "name": "Wood_Crystal_Trunk_Full"
    },
    {
      "x": -8,
      "y": 22,
      "z": -7,
      "name": "Fullmetal_Plant_Leaves_Crystal_Cyan"
    },
    {
      "x": -8,
      "y": 23,
      "z": -7,
      "name": "Fullmetal_Plant_Leaves_Crystal_Cyan"
    },
    {
      "x": -8,
      "y": 21,
      "z": -6,
      "name": "Fullmetal_Plant_Leaves_Crystal_Cyan"
    },
    {
      "x": -8,
      "y": 22,
      "z": -6,
      "name": "Fullmetal_Plant_Leaves_Crystal_Cyan"
    },
    {
      "x": -8,
      "y": 23,
      "z": -6,
      "name": "Fullmetal_Plant_Leaves_Crystal_Cyan"
    },
    {
      "x": -8,
      "y": 31,
      "z": -6,
      "name": "Wood_Crystal_Trunk_Full"
    },
    {
      "x": -8,
      "y": 33,
      "z": -6,
      "name": "Fullmetal_Plant_Leaves_Crystal_Cyan"
    },
    {
      "x": -8,
      "y": -4,
      "z": -5,
      "name": "Wood_Crystal_Trunk"
    },
    {
      "x": -8,
      "y": -3,
      "z": -5,
      "name": "Wood_Crystal_Trunk"
    },
    {
      "x": -8,
      "y": -2,
      "z": -5,
      "name": "Wood_Crystal_Trunk_Full"
    },
    {
      "x": -8,
      "y": 22,
      "z": -5,
      "name": "Fullmetal_Plant_Leaves_Crystal_Cyan"
    },
    {
      "x": -8,
      "y": 23,
      "z": -5,
      "name": "Fullmetal_Plant_Leaves_Crystal_Cyan"
    },
    {
      "x": -8,
      "y": 31,
      "z": -5,
      "name": "Wood_Crystal_Trunk_Full"
    },
    {
      "x": -8,
      "y": 33,
      "z": -5,
      "name": "Fullmetal_Plant_Leaves_Crystal_Cyan"
    },
    {
      "x": -8,
      "y": 34,
      "z": -5,
      "name": "Fullmetal_Plant_Leaves_Crystal_Cyan"
    },
    {
      "x": -8,
      "y": -5,
      "z": -4,
      "name": "Wood_Crystal_Trunk"
    },
    {
      "x": -8,
      "y": -4,
      "z": -4,
      "name": "Wood_Crystal_Trunk"
    },
    {
      "x": -8,
      "y": -3,
      "z": -4,
      "name": "Wood_Crystal_Trunk"
    },
    {
      "x": -8,
      "y": -2,
      "z": -4,
      "name": "Wood_Crystal_Trunk"
    },
    {
      "x": -8,
      "y": -1,
      "z": -4,
      "name": "Wood_Crystal_Trunk_Full"
    },
    {
      "x": -8,
      "y": 21,
      "z": -4,
      "name": "Fullmetal_Plant_Leaves_Crystal_Cyan"
    },
    {
      "x": -8,
      "y": 22,
      "z": -4,
      "name": "Fullmetal_Plant_Leaves_Crystal_Cyan"
    },
    {
      "x": -8,
      "y": 23,
      "z": -4,
      "name": "Fullmetal_Plant_Leaves_Crystal_Cyan"
    },
    {
      "x": -8,
      "y": 32,
      "z": -4,
      "name": "Plant_Fruit_Azure",
      "rotation": 8
    },
    {
      "x": -8,
      "y": 33,
      "z": -4,
      "name": "Fullmetal_Plant_Leaves_Crystal_Cyan"
    },
    {
      "x": -8,
      "y": 34,
      "z": -4,
      "name": "Fullmetal_Plant_Leaves_Crystal_Cyan"
    },
    {
      "x": -8,
      "y": -5,
      "z": -3,
      "name": "Wood_Crystal_Roots"
    },
    {
      "x": -8,
      "y": -4,
      "z": -3,
      "name": "Wood_Crystal_Trunk"
    },
    {
      "x": -8,
      "y": -3,
      "z": -3,
      "name": "Wood_Crystal_Trunk"
    },
    {
      "x": -8,
      "y": -2,
      "z": -3,
      "name": "Wood_Crystal_Trunk"
    },
    {
      "x": -8,
      "y": -1,
      "z": -3,
      "name": "Wood_Crystal_Trunk"
    },
    {
      "x": -8,
      "y": 0,
      "z": -3,
      "name": "Wood_Crystal_Trunk_Full"
    },
    {
      "x": -8,
      "y": 21,
      "z": -3,
      "name": "Fullmetal_Plant_Leaves_Crystal_Cyan"
    },
    {
      "x": -8,
      "y": 22,
      "z": -3,
      "name": "Fullmetal_Plant_Leaves_Crystal_Cyan"
    },
    {
      "x": -8,
      "y": 32,
      "z": -3,
      "name": "Wood_Crystal_Branch_Corner",
      "rotation": 3
    },
    {
      "x": -8,
      "y": 33,
      "z": -3,
      "name": "Fullmetal_Plant_Leaves_Crystal_Cyan"
    },
    {
      "x": -8,
      "y": 34,
      "z": -3,
      "name": "Fullmetal_Plant_Leaves_Crystal_Cyan"
    },
    {
      "x": -8,
      "y": 35,
      "z": -3,
      "name": "Fullmetal_Plant_Leaves_Crystal_Cyan"
    },
    {
      "x": -8,
      "y": 22,
      "z": -2,
      "name": "Fullmetal_Plant_Leaves_Crystal_Cyan"
    },
    {
      "x": -8,
      "y": 32,
      "z": -2,
      "name": "Fullmetal_Plant_Leaves_Crystal_Cyan"
    },
    {
      "x": -8,
      "y": 33,
      "z": -2,
      "name": "Fullmetal_Plant_Leaves_Crystal_Cyan"
    },
    {
      "x": -8,
      "y": 34,
      "z": -2,
      "name": "Fullmetal_Plant_Leaves_Crystal_Cyan"
    },
    {
      "x": -8,
      "y": 35,
      "z": -2,
      "name": "Fullmetal_Plant_Leaves_Crystal_Cyan"
    },
    {
      "x": -8,
      "y": 32,
      "z": -1,
      "name": "Fullmetal_Plant_Leaves_Crystal_Cyan"
    },
    {
      "x": -8,
      "y": 34,
      "z": -1,
      "name": "Fullmetal_Plant_Leaves_Crystal_Cyan"
    },
    {
      "x": -7,
      "y": 32,
      "z": -22,
      "name": "Fullmetal_Plant_Leaves_Crystal_Cyan",
      "support": 4
    },
    {
      "x": -7,
      "y": 32,
      "z": -21,
      "name": "Fullmetal_Plant_Leaves_Crystal_Cyan",
      "support": 3
    },
    {
      "x": -7,
      "y": 32,
      "z": -20,
      "name": "Fullmetal_Plant_Leaves_Crystal_Cyan",
      "support": 2
    },
    {
      "x": -7,
      "y": 32,
      "z": -19,
      "name": "Fullmetal_Plant_Leaves_Crystal_Cyan",
      "support": 1
    },
    {
      "x": -7,
      "y": 36,
      "z": -19,
      "name": "Fullmetal_Plant_Leaves_Crystal_Cyan",
      "support": 4
    },
    {
      "x": -7,
      "y": 21,
      "z": -18,
      "name": "Fullmetal_Plant_Leaves_Crystal_Cyan"
    },
    {
      "x": -7,
      "y": 32,
      "z": -18,
      "name": "Fullmetal_Plant_Leaves_Crystal_Cyan",
      "support": 1
    },
    {
      "x": -7,
      "y": 33,
      "z": -18,
      "name": "Fullmetal_Plant_Leaves_Crystal_Cyan",
      "support": 2
    },
    {
      "x": -7,
      "y": 36,
      "z": -18,
      "name": "Fullmetal_Plant_Leaves_Crystal_Cyan",
      "support": 3
    },
    {
      "x": -7,
      "y": 37,
      "z": -18,
      "name": "Fullmetal_Plant_Leaves_Crystal_Cyan",
      "support": 4
    },
    {
      "x": -7,
      "y": 21,
      "z": -17,
      "name": "Fullmetal_Plant_Leaves_Crystal_Cyan"
    },
    {
      "x": -7,
      "y": 32,
      "z": -17,
      "name": "Fullmetal_Plant_Leaves_Crystal_Cyan",
      "support": 1
    },
    {
      "x": -7,
      "y": 33,
      "z": -17,
      "name": "Fullmetal_Plant_Leaves_Crystal_Cyan",
      "support": 2
    },
    {
      "x": -7,
      "y": 37,
      "z": -17,
      "name": "Fullmetal_Plant_Leaves_Crystal_Cyan",
      "support": 3
    },
    {
      "x": -7,
      "y": 20,
      "z": -16,
      "name": "Fullmetal_Plant_Leaves_Crystal_Cyan"
    },
    {
      "x": -7,
      "y": 21,
      "z": -16,
      "name": "Fullmetal_Plant_Leaves_Crystal_Cyan"
    },
    {
      "x": -7,
      "y": 22,
      "z": -16,
      "name": "Fullmetal_Plant_Leaves_Crystal_Cyan"
    },
    {
      "x": -7,
      "y": 32,
      "z": -16,
      "name": "Fullmetal_Plant_Leaves_Crystal_Cyan",
      "support": 2
    },
    {
      "x": -7,
      "y": 33,
      "z": -16,
      "name": "Fullmetal_Plant_Leaves_Crystal_Cyan",
      "support": 3
    },
    {
      "x": -7,
      "y": 35,
      "z": -16,
      "name": "Wood_Crystal_Trunk_Full",
      "support": 5
    },
    {
      "x": -7,
      "y": 36,
      "z": -16,
      "name": "Fullmetal_Plant_Leaves_Crystal_Cyan"
    },
    {
      "x": -7,
      "y": 20,
      "z": -15,
      "name": "Wood_Crystal_Branch_Long",
      "rotation": 4
    },
    {
      "x": -7,
      "y": 21,
      "z": -15,
      "name": "Fullmetal_Plant_Leaves_Crystal_Cyan"
    },
    {
      "x": -7,
      "y": 22,
      "z": -15,
      "name": "Fullmetal_Plant_Leaves_Crystal_Cyan"
    },
    {
      "x": -7,
      "y": 35,
      "z": -15,
      "name": "Fullmetal_Plant_Leaves_Crystal_Cyan"
    },
    {
      "x": -7,
      "y": 36,
      "z": -15,
      "name": "Fullmetal_Plant_Leaves_Crystal_Cyan",
      "support": 1
    },
    {
      "x": -7,
      "y": 19,
      "z": -14,
      "name": "Wood_Crystal_Roots"
    },
    {
      "x": -7,
      "y": 20,
      "z": -14,
      "name": "Wood_Crystal_Trunk_Full"
    },
    {
      "x": -7,
      "y": 21,
      "z": -14,
      "name": "Fullmetal_Plant_Leaves_Crystal_Cyan"
    },
    {
      "x": -7,
      "y": 35,
      "z": -14,
      "name": "Fullmetal_Plant_Leaves_Crystal_Cyan",
      "support": 1
    },
    {
      "x": -7,
      "y": 36,
      "z": -14,
      "name": "Fullmetal_Plant_Leaves_Crystal_Cyan",
      "support": 2
    },
    {
      "x": -7,
      "y": 19,
      "z": -13,
      "name": "Wood_Crystal_Roots"
    },
    {
      "x": -7,
      "y": 20,
      "z": -13,
      "name": "Wood_Crystal_Trunk_Full"
    },
    {
      "x": -7,
      "y": 21,
      "z": -13,
      "name": "Fullmetal_Plant_Leaves_Crystal_Cyan"
    },
    {
      "x": -7,
      "y": 29,
      "z": -13,
      "name": "Wood_Crystal_Trunk_Full",
      "support": 4
    },
    {
      "x": -7,
      "y": 30,
      "z": -13,
      "name": "Wood_Crystal_Trunk_Full"
    },
    {
      "x": -7,
      "y": 35,
      "z": -13,
      "name": "Fullmetal_Plant_Leaves_Crystal_Cyan",
      "support": 2
    },
    {
      "x": -7,
      "y": 20,
      "z": -12,
      "name": "Wood_Crystal_Trunk_Full"
    },
    {
      "x": -7,
      "y": 30,
      "z": -12,
      "name": "Wood_Crystal_Trunk_Full",
      "support": 1
    },
    {
      "x": -7,
      "y": 35,
      "z": -11,
      "name": "Fullmetal_Plant_Leaves_Crystal_Cyan",
      "support": 4
    },
    {
      "x": -7,
      "y": 37,
      "z": -11,
      "name": "Fullmetal_Plant_Leaves_Crystal_Cyan",
      "support": 4
    },
    {
      "x": -7,
      "y": 20,
      "z": -10,
      "name": "Wood_Crystal_Trunk_Full"
    },
    {
      "x": -7,
      "y": 22,
      "z": -10,
      "name": "Fullmetal_Plant_Leaves_Crystal_Cyan"
    },
    {
      "x": -7,
      "y": 35,
      "z": -10,
      "name": "Fullmetal_Plant_Leaves_Crystal_Cyan",
      "support": 3
    },
    {
      "x": -7,
      "y": 37,
      "z": -10,
      "name": "Fullmetal_Plant_Leaves_Crystal_Cyan",
      "support": 3
    },
    {
      "x": -7,
      "y": 19,
      "z": -9,
      "name": "Fullmetal_Plant_Leaves_Crystal_Cyan"
    },
    {
      "x": -7,
      "y": 20,
      "z": -9,
      "name": "Fullmetal_Plant_Leaves_Crystal_Cyan"
    },
    {
      "x": -7,
      "y": 21,
      "z": -9,
      "name": "Fullmetal_Plant_Leaves_Crystal_Cyan"
    },
    {
      "x": -7,
      "y": 22,
      "z": -9,
      "name": "Fullmetal_Plant_Leaves_Crystal_Cyan"
    },
    {
      "x": -7,
      "y": 23,
      "z": -9,
      "name": "Fullmetal_Plant_Leaves_Crystal_Cyan"
    },
    {
      "x": -7,
      "y": 22,
      "z": -8,
      "name": "Fullmetal_Plant_Leaves_Crystal_Cyan"
    },
    {
      "x": -7,
      "y": 23,
      "z": -8,
      "name": "Fullmetal_Plant_Leaves_Crystal_Cyan"
    },
    {
      "x": -7,
      "y": 37,
      "z": -8,
      "name": "Fullmetal_Plant_Leaves_Crystal_Cyan",
      "support": 3
    },
    {
      "x": -7,
      "y": 21,
      "z": -7,
      "name": "Wood_Crystal_Trunk_Full"
    },
    {
      "x": -7,
      "y": 23,
      "z": -7,
      "name": "Fullmetal_Plant_Leaves_Crystal_Cyan"
    },
    {
      "x": -7,
      "y": 37,
      "z": -7,
      "name": "Fullmetal_Plant_Leaves_Crystal_Cyan",
      "support": 2
    },
    {
      "x": -7,
      "y": 21,
      "z": -6,
      "name": "Fullmetal_Plant_Leaves_Crystal_Cyan"
    },
    {
      "x": -7,
      "y": 22,
      "z": -6,
      "name": "Fullmetal_Plant_Leaves_Crystal_Cyan"
    },
    {
      "x": -7,
      "y": 23,
      "z": -6,
      "name": "Fullmetal_Plant_Leaves_Crystal_Cyan"
    },
    {
      "x": -7,
      "y": -3,
      "z": -5,
      "name": "Wood_Crystal_Trunk"
    },
    {
      "x": -7,
      "y": -2,
      "z": -5,
      "name": "Wood_Crystal_Trunk"
    },
    {
      "x": -7,
      "y": -1,
      "z": -5,
      "name": "Wood_Crystal_Trunk_Full"
    },
    {
      "x": -7,
      "y": 21,
      "z": -5,
      "name": "Fullmetal_Plant_Leaves_Crystal_Cyan"
    },
    {
      "x": -7,
      "y": 22,
      "z": -5,
      "name": "Fullmetal_Plant_Leaves_Crystal_Cyan"
    },
    {
      "x": -7,
      "y": 23,
      "z": -5,
      "name": "Fullmetal_Plant_Leaves_Crystal_Cyan"
    },
    {
      "x": -7,
      "y": 31,
      "z": -5,
      "name": "Wood_Crystal_Trunk_Full"
    },
    {
      "x": -7,
      "y": 34,
      "z": -5,
      "name": "Fullmetal_Plant_Leaves_Crystal_Cyan"
    },
    {
      "x": -7,
      "y": -4,
      "z": -4,
      "name": "Wood_Crystal_Trunk"
    },
    {
      "x": -7,
      "y": -3,
      "z": -4,
      "name": "Wood_Crystal_Trunk"
    },
    {
      "x": -7,
      "y": -2,
      "z": -4,
      "name": "Wood_Crystal_Trunk"
    },
    {
      "x": -7,
      "y": -1,
      "z": -4,
      "name": "Wood_Crystal_Trunk"
    },
    {
      "x": -7,
      "y": 0,
      "z": -4,
      "name": "Wood_Crystal_Trunk"
    },
    {
      "x": -7,
      "y": 1,
      "z": -4,
      "name": "Wood_Crystal_Trunk_Full"
    },
    {
      "x": -7,
      "y": 2,
      "z": -4,
      "name": "Plant_Crop_Mana2"
    },
    {
      "x": -7,
      "y": 21,
      "z": -4,
      "name": "Fullmetal_Plant_Leaves_Crystal_Cyan"
    },
    {
      "x": -7,
      "y": 22,
      "z": -4,
      "name": "Fullmetal_Plant_Leaves_Crystal_Cyan"
    },
    {
      "x": -7,
      "y": 33,
      "z": -4,
      "name": "Fullmetal_Plant_Leaves_Crystal_Cyan"
    },
    {
      "x": -7,
      "y": 34,
      "z": -4,
      "name": "Fullmetal_Plant_Leaves_Crystal_Cyan"
    },
    {
      "x": -7,
      "y": 35,
      "z": -4,
      "name": "Fullmetal_Plant_Leaves_Crystal_Cyan"
    },
    {
      "x": -7,
      "y": -4,
      "z": -3,
      "name": "Wood_Crystal_Trunk"
    },
    {
      "x": -7,
      "y": -3,
      "z": -3,
      "name": "Wood_Crystal_Trunk"
    },
    {
      "x": -7,
      "y": -2,
      "z": -3,
      "name": "Wood_Crystal_Trunk"
    },
    {
      "x": -7,
      "y": -1,
      "z": -3,
      "name": "Wood_Crystal_Trunk"
    },
    {
      "x": -7,
      "y": 0,
      "z": -3,
      "name": "Wood_Crystal_Trunk"
    },
    {
      "x": -7,
      "y": 1,
      "z": -3,
      "name": "Wood_Crystal_Trunk"
    },
    {
      "x": -7,
      "y": 2,
      "z": -3,
      "name": "Wood_Crystal_Trunk_Full"
    },
    {
      "x": -7,
      "y": 22,
      "z": -3,
      "name": "Fullmetal_Plant_Leaves_Crystal_Cyan"
    },
    {
      "x": -7,
      "y": 32,
      "z": -3,
      "name": "Wood_Crystal_Branch_Long",
      "rotation": 5
    },
    {
      "x": -7,
      "y": 33,
      "z": -3,
      "name": "Fullmetal_Plant_Leaves_Crystal_Cyan"
    },
    {
      "x": -7,
      "y": 34,
      "z": -3,
      "name": "Fullmetal_Plant_Leaves_Crystal_Cyan"
    },
    {
      "x": -7,
      "y": -2,
      "z": -2,
      "name": "Wood_Crystal_Trunk"
    },
    {
      "x": -7,
      "y": -1,
      "z": -2,
      "name": "Wood_Crystal_Trunk"
    },
    {
      "x": -7,
      "y": 0,
      "z": -2,
      "name": "Wood_Crystal_Trunk"
    },
    {
      "x": -7,
      "y": 1,
      "z": -2,
      "name": "Wood_Crystal_Trunk"
    },
    {
      "x": -7,
      "y": 2,
      "z": -2,
      "name": "Wood_Crystal_Trunk_Full"
    },
    {
      "x": -7,
      "y": 22,
      "z": -2,
      "name": "Fullmetal_Plant_Leaves_Crystal_Cyan"
    },
    {
      "x": -7,
      "y": 33,
      "z": -2,
      "name": "Fullmetal_Plant_Leaves_Crystal_Cyan"
    },
    {
      "x": -7,
      "y": 34,
      "z": -2,
      "name": "Fullmetal_Plant_Leaves_Crystal_Cyan"
    },
    {
      "x": -7,
      "y": 35,
      "z": -2,
      "name": "Fullmetal_Plant_Leaves_Crystal_Cyan"
    },
    {
      "x": -7,
      "y": 34,
      "z": -1,
      "name": "Fullmetal_Plant_Leaves_Crystal_Cyan"
    },
    {
      "x": -7,
      "y": 22,
      "z": 0,
      "name": "Fullmetal_Plant_Leaves_Crystal_Cyan"
    },
    {
      "x": -6,
      "y": 32,
      "z": -23,
      "name": "Fullmetal_Plant_Leaves_Crystal_Cyan",
      "support": 4
    },
    {
      "x": -6,
      "y": 31,
      "z": -22,
      "name": "Fullmetal_Plant_Leaves_Crystal_Cyan",
      "support": 4
    },
    {
      "x": -6,
      "y": 32,
      "z": -22,
      "name": "Fullmetal_Plant_Leaves_Crystal_Cyan",
      "support": 3
    },
    {
      "x": -6,
      "y": 32,
      "z": -21,
      "name": "Fullmetal_Plant_Leaves_Crystal_Cyan",
      "support": 3
    },
    {
      "x": -6,
      "y": 35,
      "z": -20,
      "name": "Fullmetal_Plant_Leaves_Crystal_Cyan",
      "support": 3
    },
    {
      "x": -6,
      "y": 36,
      "z": -20,
      "name": "Fullmetal_Plant_Leaves_Crystal_Cyan",
      "support": 4
    },
    {
      "x": -6,
      "y": 35,
      "z": -19,
      "name": "Fullmetal_Plant_Leaves_Crystal_Cyan",
      "support": 2
    },
    {
      "x": -6,
      "y": 36,
      "z": -19,
      "name": "Fullmetal_Plant_Leaves_Crystal_Cyan",
      "support": 3
    },
    {
      "x": -6,
      "y": 21,
      "z": -18,
      "name": "Fullmetal_Plant_Leaves_Crystal_Cyan"
    },
    {
      "x": -6,
      "y": 32,
      "z": -18,
      "name": "Fullmetal_Plant_Leaves_Crystal_Cyan",
      "support": 2
    },
    {
      "x": -6,
      "y": 33,
      "z": -18,
      "name": "Fullmetal_Plant_Leaves_Crystal_Cyan",
      "support": 3
    },
    {
      "x": -6,
      "y": 35,
      "z": -18,
      "name": "Fullmetal_Plant_Leaves_Crystal_Cyan",
      "support": 1
    },
    {
      "x": -6,
      "y": 36,
      "z": -18,
      "name": "Fullmetal_Plant_Leaves_Crystal_Cyan",
      "support": 2
    },
    {
      "x": -6,
      "y": 37,
      "z": -18,
      "name": "Fullmetal_Plant_Leaves_Crystal_Cyan",
      "support": 3
    },
    {
      "x": -6,
      "y": 38,
      "z": -18,
      "name": "Fullmetal_Plant_Leaves_Crystal_Cyan",
      "support": 4
    },
    {
      "x": -6,
      "y": 21,
      "z": -17,
      "name": "Fullmetal_Plant_Leaves_Crystal_Cyan"
    },
    {
      "x": -6,
      "y": 32,
      "z": -17,
      "name": "Fullmetal_Plant_Leaves_Crystal_Cyan",
      "support": 2
    },
    {
      "x": -6,
      "y": 35,
      "z": -17,
      "name": "Fullmetal_Plant_Leaves_Crystal_Cyan"
    },
    {
      "x": -6,
      "y": 36,
      "z": -17,
      "name": "Fullmetal_Plant_Leaves_Crystal_Cyan",
      "support": 1
    },
    {
      "x": -6,
      "y": 37,
      "z": -17,
      "name": "Fullmetal_Plant_Leaves_Crystal_Cyan",
      "support": 2
    },
    {
      "x": -6,
      "y": 38,
      "z": -17,
      "name": "Fullmetal_Plant_Leaves_Crystal_Cyan",
      "support": 3
    },
    {
      "x": -6,
      "y": 20,
      "z": -16,
      "name": "Fullmetal_Plant_Leaves_Crystal_Cyan"
    },
    {
      "x": -6,
      "y": 21,
      "z": -16,
      "name": "Fullmetal_Plant_Leaves_Crystal_Cyan"
    },
    {
      "x": -6,
      "y": 32,
      "z": -16,
      "name": "Fullmetal_Plant_Leaves_Crystal_Cyan",
      "support": 3
    },
    {
      "x": -6,
      "y": 33,
      "z": -16,
      "name": "Fullmetal_Plant_Leaves_Crystal_Cyan",
      "support": 4
    },
    {
      "x": -6,
      "y": 35,
      "z": -16,
      "name": "Wood_Crystal_Trunk_Full",
      "support": 4
    },
    {
      "x": -6,
      "y": 36,
      "z": -16,
      "name": "Fullmetal_Plant_Leaves_Crystal_Cyan"
    },
    {
      "x": -6,
      "y": 37,
      "z": -16,
      "name": "Fullmetal_Plant_Leaves_Crystal_Cyan",
      "support": 1
    },
    {
      "x": -6,
      "y": 38,
      "z": -16,
      "name": "Fullmetal_Plant_Leaves_Crystal_Cyan",
      "support": 2
    },
    {
      "x": -6,
      "y": 20,
      "z": -15,
      "name": "Fullmetal_Plant_Leaves_Crystal_Cyan"
    },
    {
      "x": -6,
      "y": 21,
      "z": -15,
      "name": "Fullmetal_Plant_Leaves_Crystal_Cyan"
    },
    {
      "x": -6,
      "y": 22,
      "z": -15,
      "name": "Fullmetal_Plant_Leaves_Crystal_Cyan"
    },
    {
      "x": -6,
      "y": 35,
      "z": -15,
      "name": "Fullmetal_Plant_Leaves_Crystal_Cyan"
    },
    {
      "x": -6,
      "y": 36,
      "z": -15,
      "name": "Fullmetal_Plant_Leaves_Crystal_Cyan",
      "support": 1
    },
    {
      "x": -6,
      "y": 37,
      "z": -15,
      "name": "Fullmetal_Plant_Leaves_Crystal_Cyan",
      "support": 2
    },
    {
      "x": -6,
      "y": 38,
      "z": -15,
      "name": "Fullmetal_Plant_Leaves_Crystal_Cyan",
      "support": 3
    },
    {
      "x": -6,
      "y": 20,
      "z": -14,
      "name": "Fullmetal_Plant_Leaves_Crystal_Cyan"
    },
    {
      "x": -6,
      "y": 21,
      "z": -14,
      "name": "Fullmetal_Plant_Leaves_Crystal_Cyan"
    },
    {
      "x": -6,
      "y": 22,
      "z": -14,
      "name": "Fullmetal_Plant_Leaves_Crystal_Cyan"
    },
    {
      "x": -6,
      "y": 23,
      "z": -14,
      "name": "Fullmetal_Plant_Leaves_Crystal_Cyan"
    },
    {
      "x": -6,
      "y": 35,
      "z": -14,
      "name": "Fullmetal_Plant_Leaves_Crystal_Cyan",
      "support": 1
    },
    {
      "x": -6,
      "y": 36,
      "z": -14,
      "name": "Fullmetal_Plant_Leaves_Crystal_Cyan",
      "support": 2
    },
    {
      "x": -6,
      "y": 37,
      "z": -14,
      "name": "Fullmetal_Plant_Leaves_Crystal_Cyan",
      "support": 3
    },
    {
      "x": -6,
      "y": 20,
      "z": -13,
      "name": "Wood_Crystal_Branch_Long",
      "rotation": 5
    },
    {
      "x": -6,
      "y": 21,
      "z": -13,
      "name": "Fullmetal_Plant_Leaves_Crystal_Cyan"
    },
    {
      "x": -6,
      "y": 22,
      "z": -13,
      "name": "Fullmetal_Plant_Leaves_Crystal_Cyan"
    },
    {
      "x": -6,
      "y": 23,
      "z": -13,
      "name": "Fullmetal_Plant_Leaves_Crystal_Cyan"
    },
    {
      "x": -6,
      "y": 29,
      "z": -13,
      "name": "Wood_Crystal_Trunk_Full",
      "support": 3
    },
    {
      "x": -6,
      "y": 30,
      "z": -13,
      "name": "Wood_Crystal_Trunk_Full"
    },
    {
      "x": -6,
      "y": 35,
      "z": -13,
      "name": "Fullmetal_Plant_Leaves_Crystal_Cyan",
      "support": 2
    },
    {
      "x": -6,
      "y": 36,
      "z": -13,
      "name": "Fullmetal_Plant_Leaves_Crystal_Cyan",
      "support": 3
    },
    {
      "x": -6,
      "y": 20,
      "z": -12,
      "name": "Wood_Crystal_Trunk_Full"
    },
    {
      "x": -6,
      "y": 21,
      "z": -12,
      "name": "Fullmetal_Plant_Leaves_Crystal_Cyan"
    },
    {
      "x": -6,
      "y": 35,
      "z": -12,
      "name": "Fullmetal_Plant_Leaves_Crystal_Cyan",
      "support": 3
    },
    {
      "x": -6,
      "y": 20,
      "z": -11,
      "name": "Wood_Crystal_Trunk_Full"
    },
    {
      "x": -6,
      "y": 21,
      "z": -11,
      "name": "Fullmetal_Plant_Leaves_Crystal_Cyan"
    },
    {
      "x": -6,
      "y": 35,
      "z": -11,
      "name": "Fullmetal_Plant_Leaves_Crystal_Cyan",
      "support": 3
    },
    {
      "x": -6,
      "y": 36,
      "z": -11,
      "name": "Fullmetal_Plant_Leaves_Crystal_Cyan",
      "support": 2
    },
    {
      "x": -6,
      "y": 37,
      "z": -11,
      "name": "Fullmetal_Plant_Leaves_Crystal_Cyan",
      "support": 3
    },
    {
      "x": -6,
      "y": 20,
      "z": -10,
      "name": "Wood_Crystal_Trunk_Full"
    },
    {
      "x": -6,
      "y": 22,
      "z": -10,
      "name": "Fullmetal_Plant_Leaves_Crystal_Cyan"
    },
    {
      "x": -6,
      "y": 35,
      "z": -10,
      "name": "Fullmetal_Plant_Leaves_Crystal_Cyan",
      "support": 2
    },
    {
      "x": -6,
      "y": 37,
      "z": -10,
      "name": "Fullmetal_Plant_Leaves_Crystal_Cyan",
      "support": 2
    },
    {
      "x": -6,
      "y": 38,
      "z": -10,
      "name": "Fullmetal_Plant_Leaves_Crystal_Cyan",
      "support": 3
    },
    {
      "x": -6,
      "y": 22,
      "z": -9,
      "name": "Fullmetal_Plant_Leaves_Crystal_Cyan"
    },
    {
      "x": -6,
      "y": 23,
      "z": -9,
      "name": "Fullmetal_Plant_Leaves_Crystal_Cyan"
    },
    {
      "x": -6,
      "y": 35,
      "z": -9,
      "name": "Fullmetal_Plant_Leaves_Crystal_Cyan",
      "support": 1
    },
    {
      "x": -6,
      "y": 37,
      "z": -9,
      "name": "Fullmetal_Plant_Leaves_Crystal_Cyan",
      "support": 1
    },
    {
      "x": -6,
      "y": 22,
      "z": -8,
      "name": "Fullmetal_Plant_Leaves_Crystal_Cyan"
    },
    {
      "x": -6,
      "y": 23,
      "z": -8,
      "name": "Fullmetal_Plant_Leaves_Crystal_Cyan"
    },
    {
      "x": -6,
      "y": 36,
      "z": -8,
      "name": "Fullmetal_Plant_Leaves_Crystal_Cyan",
      "support": 1
    },
    {
      "x": -6,
      "y": 37,
      "z": -8,
      "name": "Fullmetal_Plant_Leaves_Crystal_Cyan",
      "support": 2
    },
    {
      "x": -6,
      "y": 38,
      "z": -8,
      "name": "Fullmetal_Plant_Leaves_Crystal_Cyan",
      "support": 3
    },
    {
      "x": -6,
      "y": 21,
      "z": -7,
      "name": "Wood_Crystal_Trunk_Full"
    },
    {
      "x": -6,
      "y": 23,
      "z": -7,
      "name": "Fullmetal_Plant_Leaves_Crystal_Cyan"
    },
    {
      "x": -6,
      "y": 36,
      "z": -7,
      "name": "Fullmetal_Plant_Leaves_Crystal_Cyan",
      "support": 2
    },
    {
      "x": -6,
      "y": 37,
      "z": -7,
      "name": "Fullmetal_Plant_Leaves_Crystal_Cyan",
      "support": 1
    },
    {
      "x": -6,
      "y": 38,
      "z": -7,
      "name": "Fullmetal_Plant_Leaves_Crystal_Cyan",
      "support": 2
    },
    {
      "x": -6,
      "y": 21,
      "z": -6,
      "name": "Wood_Crystal_Branch_Long",
      "rotation": 4
    },
    {
      "x": -6,
      "y": 22,
      "z": -6,
      "name": "Fullmetal_Plant_Leaves_Crystal_Cyan"
    },
    {
      "x": -6,
      "y": 31,
      "z": -6,
      "name": "Wood_Crystal_Branch_Corner",
      "rotation": 2
    },
    {
      "x": -6,
      "y": 37,
      "z": -6,
      "name": "Fullmetal_Plant_Leaves_Crystal_Cyan"
    },
    {
      "x": -6,
      "y": -1,
      "z": -5,
      "name": "Wood_Crystal_Trunk"
    },
    {
      "x": -6,
      "y": 0,
      "z": -5,
      "name": "Wood_Crystal_Trunk_Full"
    },
    {
      "x": -6,
      "y": 21,
      "z": -5,
      "name": "Wood_Crystal_Branch_Corner"
    },
    {
      "x": -6,
      "y": 22,
      "z": -5,
      "name": "Fullmetal_Plant_Leaves_Crystal_Cyan"
    },
    {
      "x": -6,
      "y": 31,
      "z": -5,
      "name": "Wood_Crystal_Trunk_Full"
    },
    {
      "x": -6,
      "y": -4,
      "z": -4,
      "name": "Wood_Crystal_Roots"
    },
    {
      "x": -6,
      "y": -3,
      "z": -4,
      "name": "Wood_Crystal_Trunk"
    },
    {
      "x": -6,
      "y": -2,
      "z": -4,
      "name": "Wood_Crystal_Trunk"
    },
    {
      "x": -6,
      "y": -1,
      "z": -4,
      "name": "Wood_Crystal_Trunk"
    },
    {
      "x": -6,
      "y": 0,
      "z": -4,
      "name": "Wood_Crystal_Trunk"
    },
    {
      "x": -6,
      "y": 1,
      "z": -4,
      "name": "Wood_Crystal_Trunk_Full"
    },
    {
      "x": -6,
      "y": 22,
      "z": -4,
      "name": "Fullmetal_Plant_Leaves_Crystal_Cyan"
    },
    {
      "x": -6,
      "y": -3,
      "z": -3,
      "name": "Wood_Crystal_Trunk"
    },
    {
      "x": -6,
      "y": -2,
      "z": -3,
      "name": "Wood_Crystal_Trunk"
    },
    {
      "x": -6,
      "y": -1,
      "z": -3,
      "name": "Wood_Crystal_Trunk"
    },
    {
      "x": -6,
      "y": 0,
      "z": -3,
      "name": "Wood_Crystal_Trunk"
    },
    {
      "x": -6,
      "y": 1,
      "z": -3,
      "name": "Wood_Crystal_Trunk"
    },
    {
      "x": -6,
      "y": 2,
      "z": -3,
      "name": "Wood_Crystal_Trunk"
    },
    {
      "x": -6,
      "y": 3,
      "z": -3,
      "name": "Wood_Crystal_Trunk_Full"
    },
    {
      "x": -6,
      "y": 21,
      "z": -3,
      "name": "Wood_Crystal_Branch_Corner",
      "rotation": 3
    },
    {
      "x": -6,
      "y": 22,
      "z": -3,
      "name": "Fullmetal_Plant_Leaves_Crystal_Cyan"
    },
    {
      "x": -6,
      "y": 23,
      "z": -3,
      "name": "Fullmetal_Plant_Leaves_Crystal_Cyan"
    },
    {
      "x": -6,
      "y": 32,
      "z": -3,
      "name": "Wood_Crystal_Trunk_Full"
    },
    {
      "x": -6,
      "y": 34,
      "z": -3,
      "name": "Fullmetal_Plant_Leaves_Crystal_Cyan"
    },
    {
      "x": -6,
      "y": -3,
      "z": -2,
      "name": "Wood_Crystal_Trunk"
    },
    {
      "x": -6,
      "y": -2,
      "z": -2,
      "name": "Wood_Crystal_Trunk"
    },
    {
      "x": -6,
      "y": -1,
      "z": -2,
      "name": "Wood_Crystal_Trunk"
    },
    {
      "x": -6,
      "y": 0,
      "z": -2,
      "name": "Wood_Crystal_Trunk"
    },
    {
      "x": -6,
      "y": 1,
      "z": -2,
      "name": "Wood_Crystal_Trunk"
    },
    {
      "x": -6,
      "y": 2,
      "z": -2,
      "name": "Wood_Crystal_Trunk"
    },
    {
      "x": -6,
      "y": 3,
      "z": -2,
      "name": "Wood_Crystal_Trunk"
    },
    {
      "x": -6,
      "y": 4,
      "z": -2,
      "name": "Wood_Crystal_Trunk_Full"
    },
    {
      "x": -6,
      "y": 6,
      "z": -2,
      "name": "Fullmetal_Plant_Flower_Common_Cyan",
      "rotation": 7
    },
    {
      "x": -6,
      "y": 7,
      "z": -2,
      "name": "Fullmetal_Plant_Flower_Common_Cyan",
      "rotation": 7
    },
    {
      "x": -6,
      "y": 19,
      "z": -2,
      "name": "Fullmetal_Plant_Leaves_Crystal_Cyan"
    },
    {
      "x": -6,
      "y": 20,
      "z": -2,
      "name": "Fullmetal_Plant_Leaves_Crystal_Cyan"
    },
    {
      "x": -6,
      "y": 21,
      "z": -2,
      "name": "Fullmetal_Plant_Leaves_Crystal_Cyan"
    },
    {
      "x": -6,
      "y": 22,
      "z": -2,
      "name": "Fullmetal_Plant_Leaves_Crystal_Cyan"
    },
    {
      "x": -6,
      "y": 23,
      "z": -2,
      "name": "Fullmetal_Plant_Leaves_Crystal_Cyan"
    },
    {
      "x": -6,
      "y": 34,
      "z": -2,
      "name": "Fullmetal_Plant_Leaves_Crystal_Cyan"
    },
    {
      "x": -6,
      "y": -1,
      "z": -1,
      "name": "Wood_Crystal_Trunk"
    },
    {
      "x": -6,
      "y": 0,
      "z": -1,
      "name": "Wood_Crystal_Trunk"
    },
    {
      "x": -6,
      "y": 1,
      "z": -1,
      "name": "Wood_Crystal_Trunk"
    },
    {
      "x": -6,
      "y": 2,
      "z": -1,
      "name": "Wood_Crystal_Trunk"
    },
    {
      "x": -6,
      "y": 3,
      "z": -1,
      "name": "Wood_Crystal_Trunk"
    },
    {
      "x": -6,
      "y": 4,
      "z": -1,
      "name": "Wood_Crystal_Trunk"
    },
    {
      "x": -6,
      "y": 5,
      "z": -1,
      "name": "Wood_Crystal_Trunk_Full"
    },
    {
      "x": -6,
      "y": 8,
      "z": -1,
      "name": "Fullmetal_Plant_Flower_Common_Cyan",
      "rotation": 7
    },
    {
      "x": -6,
      "y": 22,
      "z": -1,
      "name": "Fullmetal_Plant_Leaves_Crystal_Cyan"
    },
    {
      "x": -6,
      "y": 0,
      "z": 0,
      "name": "Wood_Crystal_Trunk"
    },
    {
      "x": -6,
      "y": 1,
      "z": 0,
      "name": "Wood_Crystal_Trunk"
    },
    {
      "x": -6,
      "y": 2,
      "z": 0,
      "name": "Wood_Crystal_Trunk"
    },
    {
      "x": -6,
      "y": 3,
      "z": 0,
      "name": "Wood_Crystal_Trunk_Full"
    },
    {
      "x": -6,
      "y": 22,
      "z": 0,
      "name": "Fullmetal_Plant_Leaves_Crystal_Cyan"
    },
    {
      "x": -6,
      "y": 23,
      "z": 0,
      "name": "Fullmetal_Plant_Leaves_Crystal_Cyan"
    },
    {
      "x": -6,
      "y": 22,
      "z": 1,
      "name": "Fullmetal_Plant_Leaves_Crystal_Cyan"
    },
    {
      "x": -6,
      "y": 33,
      "z": 1,
      "name": "Fullmetal_Plant_Leaves_Crystal_Cyan"
    },
    {
      "x": -5,
      "y": 32,
      "z": -25,
      "name": "Fullmetal_Plant_Leaves_Crystal_Cyan",
      "support": 4
    },
    {
      "x": -5,
      "y": 32,
      "z": -24,
      "name": "Fullmetal_Plant_Leaves_Crystal_Cyan",
      "support": 4
    },
    {
      "x": -5,
      "y": 32,
      "z": -23,
      "name": "Fullmetal_Plant_Leaves_Crystal_Cyan",
      "support": 3
    },
    {
      "x": -5,
      "y": 33,
      "z": -23,
      "name": "Fullmetal_Plant_Leaves_Crystal_Cyan",
      "support": 4
    },
    {
      "x": -5,
      "y": 32,
      "z": -22,
      "name": "Fullmetal_Plant_Leaves_Crystal_Cyan",
      "support": 2
    },
    {
      "x": -5,
      "y": 32,
      "z": -21,
      "name": "Fullmetal_Plant_Leaves_Crystal_Cyan",
      "support": 2
    },
    {
      "x": -5,
      "y": 33,
      "z": -21,
      "name": "Fullmetal_Plant_Leaves_Crystal_Cyan",
      "support": 3
    },
    {
      "x": -5,
      "y": 32,
      "z": -20,
      "name": "Fullmetal_Plant_Leaves_Crystal_Cyan",
      "support": 3
    },
    {
      "x": -5,
      "y": 33,
      "z": -20,
      "name": "Fullmetal_Plant_Leaves_Crystal_Cyan",
      "support": 4
    },
    {
      "x": -5,
      "y": 32,
      "z": -19,
      "name": "Fullmetal_Plant_Leaves_Crystal_Cyan",
      "support": 4
    },
    {
      "x": -5,
      "y": 35,
      "z": -19,
      "name": "Fullmetal_Plant_Leaves_Crystal_Cyan",
      "support": 1
    },
    {
      "x": -5,
      "y": 36,
      "z": -19,
      "name": "Fullmetal_Plant_Leaves_Crystal_Cyan",
      "support": 2
    },
    {
      "x": -5,
      "y": 32,
      "z": -18,
      "name": "Fullmetal_Plant_Leaves_Crystal_Cyan",
      "support": 3
    },
    {
      "x": -5,
      "y": 35,
      "z": -18,
      "name": "Fullmetal_Plant_Leaves_Crystal_Cyan"
    },
    {
      "x": -5,
      "y": 36,
      "z": -18,
      "name": "Fullmetal_Plant_Leaves_Crystal_Cyan",
      "support": 1
    },
    {
      "x": -5,
      "y": 21,
      "z": -17,
      "name": "Fullmetal_Plant_Leaves_Crystal_Cyan"
    },
    {
      "x": -5,
      "y": 32,
      "z": -17,
      "name": "Fullmetal_Plant_Leaves_Crystal_Cyan",
      "support": 3
    },
    {
      "x": -5,
      "y": 35,
      "z": -17,
      "name": "Wood_Crystal_Trunk_Full",
      "support": 4
    },
    {
      "x": -5,
      "y": 36,
      "z": -17,
      "name": "Fullmetal_Plant_Leaves_Crystal_Cyan"
    },
    {
      "x": -5,
      "y": 21,
      "z": -16,
      "name": "Fullmetal_Plant_Leaves_Crystal_Cyan"
    },
    {
      "x": -5,
      "y": 22,
      "z": -16,
      "name": "Fullmetal_Plant_Leaves_Crystal_Cyan"
    },
    {
      "x": -5,
      "y": 32,
      "z": -16,
      "name": "Fullmetal_Plant_Leaves_Crystal_Cyan",
      "support": 4
    },
    {
      "x": -5,
      "y": 35,
      "z": -16,
      "name": "Wood_Crystal_Trunk_Full",
      "support": 3
    },
    {
      "x": -5,
      "y": 37,
      "z": -16,
      "name": "Fullmetal_Plant_Leaves_Crystal_Cyan",
      "support": 2
    },
    {
      "x": -5,
      "y": 21,
      "z": -15,
      "name": "Fullmetal_Plant_Leaves_Crystal_Cyan"
    },
    {
      "x": -5,
      "y": 22,
      "z": -15,
      "name": "Fullmetal_Plant_Leaves_Crystal_Cyan"
    },
    {
      "x": -5,
      "y": 30,
      "z": -15,
      "name": "Wood_Crystal_Trunk_Full",
      "support": 2
    },
    {
      "x": -5,
      "y": 35,
      "z": -15,
      "name": "Fullmetal_Plant_Leaves_Crystal_Cyan"
    },
    {
      "x": -5,
      "y": 36,
      "z": -15,
      "name": "Fullmetal_Plant_Leaves_Crystal_Cyan",
      "support": 1
    },
    {
      "x": -5,
      "y": 37,
      "z": -15,
      "name": "Fullmetal_Plant_Leaves_Crystal_Cyan",
      "support": 2
    },
    {
      "x": -5,
      "y": 38,
      "z": -15,
      "name": "Fullmetal_Plant_Leaves_Crystal_Cyan",
      "support": 3
    },
    {
      "x": -5,
      "y": 21,
      "z": -14,
      "name": "Fullmetal_Plant_Leaves_Crystal_Cyan"
    },
    {
      "x": -5,
      "y": 30,
      "z": -14,
      "name": "Wood_Crystal_Trunk_Full",
      "support": 1
    },
    {
      "x": -5,
      "y": 35,
      "z": -14,
      "name": "Fullmetal_Plant_Leaves_Crystal_Cyan",
      "support": 1
    },
    {
      "x": -5,
      "y": 36,
      "z": -14,
      "name": "Fullmetal_Plant_Leaves_Crystal_Cyan",
      "support": 2
    },
    {
      "x": -5,
      "y": 20,
      "z": -13,
      "name": "Wood_Crystal_Branch_Long",
      "rotation": 5
    },
    {
      "x": -5,
      "y": 21,
      "z": -13,
      "name": "Fullmetal_Plant_Leaves_Crystal_Cyan"
    },
    {
      "x": -5,
      "y": 22,
      "z": -13,
      "name": "Fullmetal_Plant_Leaves_Crystal_Cyan"
    },
    {
      "x": -5,
      "y": 29,
      "z": -13,
      "name": "Wood_Crystal_Trunk_Full",
      "support": 2
    },
    {
      "x": -5,
      "y": 30,
      "z": -13,
      "name": "Wood_Crystal_Trunk_Full"
    },
    {
      "x": -5,
      "y": 35,
      "z": -13,
      "name": "Fullmetal_Plant_Leaves_Crystal_Cyan",
      "support": 2
    },
    {
      "x": -5,
      "y": 36,
      "z": -13,
      "name": "Fullmetal_Plant_Leaves_Crystal_Cyan",
      "support": 3
    },
    {
      "x": -5,
      "y": 21,
      "z": -12,
      "name": "Fullmetal_Plant_Leaves_Crystal_Cyan"
    },
    {
      "x": -5,
      "y": 35,
      "z": -12,
      "name": "Fullmetal_Plant_Leaves_Crystal_Cyan",
      "support": 3
    },
    {
      "x": -5,
      "y": 36,
      "z": -12,
      "name": "Fullmetal_Plant_Leaves_Crystal_Cyan",
      "support": 2
    },
    {
      "x": -5,
      "y": 37,
      "z": -12,
      "name": "Fullmetal_Plant_Leaves_Crystal_Cyan",
      "support": 3
    },
    {
      "x": -5,
      "y": 35,
      "z": -11,
      "name": "Fullmetal_Plant_Leaves_Crystal_Cyan",
      "support": 2
    },
    {
      "x": -5,
      "y": 36,
      "z": -11,
      "name": "Fullmetal_Plant_Leaves_Crystal_Cyan",
      "support": 1
    },
    {
      "x": -5,
      "y": 37,
      "z": -11,
      "name": "Fullmetal_Plant_Leaves_Crystal_Cyan",
      "support": 2
    },
    {
      "x": -5,
      "y": 18,
      "z": -10,
      "name": "Wood_Crystal_Roots"
    },
    {
      "x": -5,
      "y": 19,
      "z": -10,
      "name": "Wood_Crystal_Trunk_Full"
    },
    {
      "x": -5,
      "y": 20,
      "z": -10,
      "name": "Wood_Crystal_Trunk_Full"
    },
    {
      "x": -5,
      "y": 22,
      "z": -10,
      "name": "Fullmetal_Plant_Leaves_Crystal_Cyan"
    },
    {
      "x": -5,
      "y": 35,
      "z": -10,
      "name": "Fullmetal_Plant_Leaves_Crystal_Cyan",
      "support": 1
    },
    {
      "x": -5,
      "y": 36,
      "z": -10,
      "name": "Fullmetal_Plant_Leaves_Crystal_Cyan"
    },
    {
      "x": -5,
      "y": 37,
      "z": -10,
      "name": "Fullmetal_Plant_Leaves_Crystal_Cyan",
      "support": 1
    },
    {
      "x": -5,
      "y": 19,
      "z": -9,
      "name": "Wood_Crystal_Trunk_Full"
    },
    {
      "x": -5,
      "y": 22,
      "z": -9,
      "name": "Fullmetal_Plant_Leaves_Crystal_Cyan"
    },
    {
      "x": -5,
      "y": 35,
      "z": -9,
      "name": "Fullmetal_Plant_Leaves_Crystal_Cyan"
    },
    {
      "x": -5,
      "y": 36,
      "z": -9,
      "name": "Wood_Crystal_Trunk_Full",
      "support": 5
    },
    {
      "x": -5,
      "y": 37,
      "z": -9,
      "name": "Fullmetal_Plant_Leaves_Crystal_Cyan"
    },
    {
      "x": -5,
      "y": 38,
      "z": -9,
      "name": "Fullmetal_Plant_Leaves_Crystal_Cyan",
      "support": 1
    },
    {
      "x": -5,
      "y": 39,
      "z": -9,
      "name": "Fullmetal_Plant_Leaves_Crystal_Cyan",
      "support": 2
    },
    {
      "x": -5,
      "y": 21,
      "z": -8,
      "name": "Plant_Fruit_Azure",
      "rotation": 8
    },
    {
      "x": -5,
      "y": 22,
      "z": -8,
      "name": "Fullmetal_Plant_Leaves_Crystal_Cyan"
    },
    {
      "x": -5,
      "y": 36,
      "z": -8,
      "name": "Fullmetal_Plant_Leaves_Crystal_Cyan"
    },
    {
      "x": -5,
      "y": 38,
      "z": -8,
      "name": "Fullmetal_Plant_Leaves_Crystal_Cyan",
      "support": 2
    },
    {
      "x": -5,
      "y": 21,
      "z": -7,
      "name": "Wood_Crystal_Trunk_Full"
    },
    {
      "x": -5,
      "y": 30,
      "z": -7,
      "name": "Wood_Crystal_Trunk_Full"
    },
    {
      "x": -5,
      "y": 37,
      "z": -7,
      "name": "Fullmetal_Plant_Leaves_Crystal_Cyan",
      "support": 1
    },
    {
      "x": -5,
      "y": 38,
      "z": -7,
      "name": "Fullmetal_Plant_Leaves_Crystal_Cyan",
      "support": 2
    },
    {
      "x": -5,
      "y": 22,
      "z": -6,
      "name": "Fullmetal_Plant_Leaves_Crystal_Cyan"
    },
    {
      "x": -5,
      "y": 30,
      "z": -6,
      "name": "Wood_Crystal_Trunk_Full"
    },
    {
      "x": -5,
      "y": 37,
      "z": -6,
      "name": "Fullmetal_Plant_Leaves_Crystal_Cyan"
    },
    {
      "x": -5,
      "y": 22,
      "z": -5,
      "name": "Fullmetal_Plant_Leaves_Crystal_Cyan"
    },
    {
      "x": -5,
      "y": 30,
      "z": -5,
      "name": "Wood_Crystal_Trunk_Full"
    },
    {
      "x": -5,
      "y": 31,
      "z": -5,
      "name": "Wood_Crystal_Trunk_Full"
    },
    {
      "x": -5,
      "y": 32,
      "z": -5,
      "name": "Wood_Crystal_Trunk_Full"
    },
    {
      "x": -5,
      "y": -2,
      "z": -4,
      "name": "Wood_Crystal_Trunk"
    },
    {
      "x": -5,
      "y": -1,
      "z": -4,
      "name": "Wood_Crystal_Trunk"
    },
    {
      "x": -5,
      "y": 0,
      "z": -4,
      "name": "Wood_Crystal_Trunk"
    },
    {
      "x": -5,
      "y": 1,
      "z": -4,
      "name": "Wood_Crystal_Trunk"
    },
    {
      "x": -5,
      "y": 2,
      "z": -4,
      "name": "Wood_Crystal_Trunk_Full"
    },
    {
      "x": -5,
      "y": 22,
      "z": -4,
      "name": "Fullmetal_Plant_Leaves_Crystal_Cyan"
    },
    {
      "x": -5,
      "y": 31,
      "z": -4,
      "name": "Wood_Crystal_Trunk_Full"
    },
    {
      "x": -5,
      "y": 32,
      "z": -4,
      "name": "Wood_Crystal_Trunk_Full"
    },
    {
      "x": -5,
      "y": 36,
      "z": -4,
      "name": "Fullmetal_Plant_Leaves_Crystal_Cyan"
    },
    {
      "x": -5,
      "y": -2,
      "z": -3,
      "name": "Wood_Crystal_Trunk"
    },
    {
      "x": -5,
      "y": -1,
      "z": -3,
      "name": "Wood_Crystal_Trunk"
    },
    {
      "x": -5,
      "y": 0,
      "z": -3,
      "name": "Wood_Crystal_Trunk"
    },
    {
      "x": -5,
      "y": 1,
      "z": -3,
      "name": "Wood_Crystal_Trunk"
    },
    {
      "x": -5,
      "y": 2,
      "z": -3,
      "name": "Wood_Crystal_Trunk"
    },
    {
      "x": -5,
      "y": 3,
      "z": -3,
      "name": "Wood_Crystal_Trunk"
    },
    {
      "x": -5,
      "y": 4,
      "z": -3,
      "name": "Wood_Crystal_Trunk_Full"
    },
    {
      "x": -5,
      "y": 6,
      "z": -3,
      "name": "Fullmetal_Plant_Flower_Common_Cyan",
      "rotation": 6
    },
    {
      "x": -5,
      "y": 7,
      "z": -3,
      "name": "Fullmetal_Plant_Flower_Common_Cyan",
      "rotation": 6
    },
    {
      "x": -5,
      "y": 21,
      "z": -3,
      "name": "Wood_Crystal_Branch_Long",
      "rotation": 5
    },
    {
      "x": -5,
      "y": 22,
      "z": -3,
      "name": "Fullmetal_Plant_Leaves_Crystal_Cyan"
    },
    {
      "x": -5,
      "y": 23,
      "z": -3,
      "name": "Fullmetal_Plant_Leaves_Crystal_Cyan"
    },
    {
      "x": -5,
      "y": 32,
      "z": -3,
      "name": "Wood_Crystal_Trunk_Full"
    },
    {
      "x": -5,
      "y": -3,
      "z": -2,
      "name": "Wood_Crystal_Roots"
    },
    {
      "x": -5,
      "y": -2,
      "z": -2,
      "name": "Wood_Crystal_Trunk"
    },
    {
      "x": -5,
      "y": -1,
      "z": -2,
      "name": "Wood_Crystal_Trunk"
    },
    {
      "x": -5,
      "y": 0,
      "z": -2,
      "name": "Wood_Crystal_Trunk"
    },
    {
      "x": -5,
      "y": 1,
      "z": -2,
      "name": "Wood_Crystal_Trunk"
    },
    {
      "x": -5,
      "y": 2,
      "z": -2,
      "name": "Wood_Crystal_Trunk"
    },
    {
      "x": -5,
      "y": 3,
      "z": -2,
      "name": "Wood_Crystal_Trunk"
    },
    {
      "x": -5,
      "y": 4,
      "z": -2,
      "name": "Wood_Crystal_Trunk"
    },
    {
      "x": -5,
      "y": 5,
      "z": -2,
      "name": "Wood_Crystal_Trunk"
    },
    {
      "x": -5,
      "y": 6,
      "z": -2,
      "name": "Wood_Crystal_Trunk"
    },
    {
      "x": -5,
      "y": 7,
      "z": -2,
      "name": "Wood_Crystal_Trunk_Full"
    },
    {
      "x": -5,
      "y": 8,
      "z": -2,
      "name": "Fullmetal_Plant_Flower_Common_Cyan"
    },
    {
      "x": -5,
      "y": 9,
      "z": -2,
      "name": "Fullmetal_Plant_Flower_Common_Cyan",
      "rotation": 7
    },
    {
      "x": -5,
      "y": 10,
      "z": -2,
      "name": "Fullmetal_Plant_Flower_Common_Cyan",
      "rotation": 7
    },
    {
      "x": -5,
      "y": 11,
      "z": -2,
      "name": "Fullmetal_Plant_Flower_Common_Cyan",
      "rotation": 7
    },
    {
      "x": -5,
      "y": 13,
      "z": -2,
      "name": "Wood_Crystal_Branch_Corner",
      "rotation": 3
    },
    {
      "x": -5,
      "y": 22,
      "z": -2,
      "name": "Fullmetal_Plant_Leaves_Crystal_Cyan"
    },
    {
      "x": -5,
      "y": 23,
      "z": -2,
      "name": "Fullmetal_Plant_Leaves_Crystal_Cyan"
    },
    {
      "x": -5,
      "y": -2,
      "z": -1,
      "name": "Wood_Crystal_Trunk"
    },
    {
      "x": -5,
      "y": -1,
      "z": -1,
      "name": "Wood_Crystal_Trunk"
    },
    {
      "x": -5,
      "y": 0,
      "z": -1,
      "name": "Wood_Crystal_Trunk"
    },
    {
      "x": -5,
      "y": 1,
      "z": -1,
      "name": "Wood_Crystal_Trunk"
    },
    {
      "x": -5,
      "y": 2,
      "z": -1,
      "name": "Wood_Crystal_Trunk"
    },
    {
      "x": -5,
      "y": 3,
      "z": -1,
      "name": "Wood_Crystal_Trunk"
    },
    {
      "x": -5,
      "y": 4,
      "z": -1,
      "name": "Wood_Crystal_Trunk"
    },
    {
      "x": -5,
      "y": 5,
      "z": -1,
      "name": "Wood_Crystal_Trunk"
    },
    {
      "x": -5,
      "y": 6,
      "z": -1,
      "name": "Wood_Crystal_Trunk"
    },
    {
      "x": -5,
      "y": 7,
      "z": -1,
      "name": "Wood_Crystal_Trunk"
    },
    {
      "x": -5,
      "y": 8,
      "z": -1,
      "name": "Wood_Crystal_Trunk_Full"
    },
    {
      "x": -5,
      "y": 9,
      "z": -1,
      "name": "Fullmetal_Plant_Flower_Common_Cyan"
    },
    {
      "x": -5,
      "y": 10,
      "z": -1,
      "name": "Wood_Crystal_Branch_Short",
      "rotation": 3
    },
    {
      "x": -5,
      "y": 21,
      "z": -1,
      "name": "Fullmetal_Plant_Leaves_Crystal_Cyan"
    },
    {
      "x": -5,
      "y": 22,
      "z": -1,
      "name": "Fullmetal_Plant_Leaves_Crystal_Cyan"
    },
    {
      "x": -5,
      "y": 23,
      "z": -1,
      "name": "Fullmetal_Plant_Leaves_Crystal_Cyan"
    },
    {
      "x": -5,
      "y": -1,
      "z": 0,
      "name": "Wood_Crystal_Trunk"
    },
    {
      "x": -5,
      "y": 0,
      "z": 0,
      "name": "Wood_Crystal_Trunk"
    },
    {
      "x": -5,
      "y": 1,
      "z": 0,
      "name": "Wood_Crystal_Trunk"
    },
    {
      "x": -5,
      "y": 2,
      "z": 0,
      "name": "Wood_Crystal_Trunk"
    },
    {
      "x": -5,
      "y": 3,
      "z": 0,
      "name": "Wood_Crystal_Trunk"
    },
    {
      "x": -5,
      "y": 4,
      "z": 0,
      "name": "Wood_Crystal_Trunk"
    },
    {
      "x": -5,
      "y": 5,
      "z": 0,
      "name": "Wood_Crystal_Trunk"
    },
    {
      "x": -5,
      "y": 6,
      "z": 0,
      "name": "Wood_Crystal_Trunk"
    },
    {
      "x": -5,
      "y": 7,
      "z": 0,
      "name": "Wood_Crystal_Trunk"
    },
    {
      "x": -5,
      "y": 8,
      "z": 0,
      "name": "Wood_Crystal_Trunk_Full"
    },
    {
      "x": -5,
      "y": 21,
      "z": 0,
      "name": "Fullmetal_Plant_Leaves_Crystal_Cyan"
    },
    {
      "x": -5,
      "y": 22,
      "z": 0,
      "name": "Fullmetal_Plant_Leaves_Crystal_Cyan"
    },
    {
      "x": -5,
      "y": 23,
      "z": 0,
      "name": "Fullmetal_Plant_Leaves_Crystal_Cyan"
    },
    {
      "x": -5,
      "y": 33,
      "z": 0,
      "name": "Fullmetal_Plant_Leaves_Crystal_Cyan"
    },
    {
      "x": -5,
      "y": 34,
      "z": 0,
      "name": "Fullmetal_Plant_Leaves_Crystal_Cyan"
    },
    {
      "x": -5,
      "y": 1,
      "z": 1,
      "name": "Wood_Crystal_Trunk"
    },
    {
      "x": -5,
      "y": 2,
      "z": 1,
      "name": "Wood_Crystal_Trunk"
    },
    {
      "x": -5,
      "y": 3,
      "z": 1,
      "name": "Wood_Crystal_Trunk"
    },
    {
      "x": -5,
      "y": 4,
      "z": 1,
      "name": "Wood_Crystal_Trunk"
    },
    {
      "x": -5,
      "y": 5,
      "z": 1,
      "name": "Wood_Crystal_Trunk"
    },
    {
      "x": -5,
      "y": 6,
      "z": 1,
      "name": "Wood_Crystal_Trunk_Full"
    },
    {
      "x": -5,
      "y": 22,
      "z": 1,
      "name": "Fullmetal_Plant_Leaves_Crystal_Cyan"
    },
    {
      "x": -5,
      "y": 33,
      "z": 1,
      "name": "Fullmetal_Plant_Leaves_Crystal_Cyan"
    },
    {
      "x": -5,
      "y": 34,
      "z": 1,
      "name": "Fullmetal_Plant_Leaves_Crystal_Cyan"
    },
    {
      "x": -5,
      "y": 22,
      "z": 2,
      "name": "Fullmetal_Plant_Leaves_Crystal_Cyan"
    },
    {
      "x": -5,
      "y": 33,
      "z": 2,
      "name": "Fullmetal_Plant_Leaves_Crystal_Cyan"
    },
    {
      "x": -4,
      "y": 32,
      "z": -25,
      "name": "Fullmetal_Plant_Leaves_Crystal_Cyan",
      "support": 3
    },
    {
      "x": -4,
      "y": 32,
      "z": -24,
      "name": "Fullmetal_Plant_Leaves_Crystal_Cyan",
      "support": 3
    },
    {
      "x": -4,
      "y": 33,
      "z": -24,
      "name": "Fullmetal_Plant_Leaves_Crystal_Cyan",
      "support": 4
    },
    {
      "x": -4,
      "y": 32,
      "z": -23,
      "name": "Fullmetal_Plant_Leaves_Crystal_Cyan",
      "support": 2
    },
    {
      "x": -4,
      "y": 33,
      "z": -23,
      "name": "Fullmetal_Plant_Leaves_Crystal_Cyan",
      "support": 3
    },
    {
      "x": -4,
      "y": 32,
      "z": -22,
      "name": "Fullmetal_Plant_Leaves_Crystal_Cyan",
      "support": 1
    },
    {
      "x": -4,
      "y": 33,
      "z": -22,
      "name": "Fullmetal_Plant_Leaves_Crystal_Cyan",
      "support": 2
    },
    {
      "x": -4,
      "y": 32,
      "z": -21,
      "name": "Fullmetal_Plant_Leaves_Crystal_Cyan",
      "support": 1
    },
    {
      "x": -4,
      "y": 36,
      "z": -19,
      "name": "Fullmetal_Plant_Leaves_Crystal_Cyan",
      "support": 3
    },
    {
      "x": -4,
      "y": 21,
      "z": -16,
      "name": "Fullmetal_Plant_Leaves_Crystal_Cyan"
    },
    {
      "x": -4,
      "y": 35,
      "z": -16,
      "name": "Wood_Crystal_Trunk_Full",
      "support": 2
    },
    {
      "x": -4,
      "y": 37,
      "z": -16,
      "name": "Fullmetal_Plant_Leaves_Crystal_Cyan",
      "support": 3
    },
    {
      "x": -4,
      "y": 21,
      "z": -15,
      "name": "Fullmetal_Plant_Leaves_Crystal_Cyan"
    },
    {
      "x": -4,
      "y": 21,
      "z": -14,
      "name": "Fullmetal_Plant_Leaves_Crystal_Cyan"
    },
    {
      "x": -4,
      "y": 29,
      "z": -14,
      "name": "Wood_Crystal_Trunk_Full",
      "support": 2
    },
    {
      "x": -4,
      "y": 36,
      "z": -14,
      "name": "Fullmetal_Plant_Leaves_Crystal_Cyan",
      "support": 2
    },
    {
      "x": -4,
      "y": 20,
      "z": -13,
      "name": "Wood_Crystal_Branch_Corner",
      "rotation": 1
    },
    {
      "x": -4,
      "y": 21,
      "z": -13,
      "name": "Fullmetal_Plant_Leaves_Crystal_Cyan"
    },
    {
      "x": -4,
      "y": 29,
      "z": -13,
      "name": "Wood_Crystal_Trunk_Full",
      "support": 1
    },
    {
      "x": -4,
      "y": 36,
      "z": -13,
      "name": "Fullmetal_Plant_Leaves_Crystal_Cyan",
      "support": 3
    },
    {
      "x": -4,
      "y": 37,
      "z": -13,
      "name": "Fullmetal_Plant_Leaves_Crystal_Cyan",
      "support": 4
    },
    {
      "x": -4,
      "y": 20,
      "z": -12,
      "name": "Fullmetal_Plant_Leaves_Crystal_Cyan"
    },
    {
      "x": -4,
      "y": 21,
      "z": -12,
      "name": "Fullmetal_Plant_Leaves_Crystal_Cyan"
    },
    {
      "x": -4,
      "y": 35,
      "z": -12,
      "name": "Fullmetal_Plant_Leaves_Crystal_Cyan",
      "support": 4
    },
    {
      "x": -4,
      "y": 36,
      "z": -12,
      "name": "Fullmetal_Plant_Leaves_Crystal_Cyan",
      "support": 3
    },
    {
      "x": -4,
      "y": 37,
      "z": -12,
      "name": "Fullmetal_Plant_Leaves_Crystal_Cyan",
      "support": 3
    },
    {
      "x": -4,
      "y": 35,
      "z": -11,
      "name": "Fullmetal_Plant_Leaves_Crystal_Cyan",
      "support": 3
    },
    {
      "x": -4,
      "y": 36,
      "z": -11,
      "name": "Fullmetal_Plant_Leaves_Crystal_Cyan",
      "support": 2
    },
    {
      "x": -4,
      "y": 37,
      "z": -11,
      "name": "Fullmetal_Plant_Leaves_Crystal_Cyan",
      "support": 2
    },
    {
      "x": -4,
      "y": 38,
      "z": -11,
      "name": "Fullmetal_Plant_Leaves_Crystal_Cyan",
      "support": 3
    },
    {
      "x": -4,
      "y": 35,
      "z": -10,
      "name": "Fullmetal_Plant_Leaves_Crystal_Cyan",
      "support": 2
    },
    {
      "x": -4,
      "y": 37,
      "z": -10,
      "name": "Fullmetal_Plant_Leaves_Crystal_Cyan",
      "support": 1
    },
    {
      "x": -4,
      "y": 18,
      "z": -9,
      "name": "Wood_Crystal_Trunk_Full"
    },
    {
      "x": -4,
      "y": 19,
      "z": -9,
      "name": "Wood_Crystal_Trunk_Full"
    },
    {
      "x": -4,
      "y": 22,
      "z": -9,
      "name": "Wood_Crystal_Trunk_Full"
    },
    {
      "x": -4,
      "y": 36,
      "z": -9,
      "name": "Wood_Crystal_Trunk_Full",
      "support": 4
    },
    {
      "x": -4,
      "y": 37,
      "z": -9,
      "name": "Fullmetal_Plant_Leaves_Crystal_Cyan"
    },
    {
      "x": -4,
      "y": 17,
      "z": -8,
      "name": "Wood_Crystal_Trunk_Full"
    },
    {
      "x": -4,
      "y": 18,
      "z": -8,
      "name": "Wood_Crystal_Trunk"
    },
    {
      "x": -4,
      "y": 19,
      "z": -8,
      "name": "Wood_Crystal_Trunk_Full"
    },
    {
      "x": -4,
      "y": 22,
      "z": -8,
      "name": "Fullmetal_Plant_Leaves_Crystal_Cyan"
    },
    {
      "x": -4,
      "y": 36,
      "z": -8,
      "name": "Fullmetal_Plant_Leaves_Crystal_Cyan"
    },
    {
      "x": -4,
      "y": 20,
      "z": -7,
      "name": "Wood_Crystal_Trunk_Full"
    },
    {
      "x": -4,
      "y": 21,
      "z": -7,
      "name": "Wood_Crystal_Trunk_Full"
    },
    {
      "x": -4,
      "y": 29,
      "z": -7,
      "name": "Wood_Crystal_Roots"
    },
    {
      "x": -4,
      "y": 30,
      "z": -7,
      "name": "Wood_Crystal_Trunk_Full"
    },
    {
      "x": -4,
      "y": 31,
      "z": -7,
      "name": "Wood_Crystal_Trunk_Full"
    },
    {
      "x": -4,
      "y": 36,
      "z": -7,
      "name": "Fullmetal_Plant_Leaves_Crystal_Cyan"
    },
    {
      "x": -4,
      "y": 37,
      "z": -7,
      "name": "Fullmetal_Plant_Leaves_Crystal_Cyan",
      "support": 1
    },
    {
      "x": -4,
      "y": 18,
      "z": -6,
      "name": "Wood_Crystal_Trunk_Full"
    },
    {
      "x": -4,
      "y": 19,
      "z": -6,
      "name": "Wood_Crystal_Trunk"
    },
    {
      "x": -4,
      "y": 20,
      "z": -6,
      "name": "Wood_Crystal_Trunk_Full"
    },
    {
      "x": -4,
      "y": 31,
      "z": -6,
      "name": "Wood_Crystal_Trunk_Full"
    },
    {
      "x": -4,
      "y": 32,
      "z": -6,
      "name": "Wood_Crystal_Trunk_Full"
    },
    {
      "x": -4,
      "y": 36,
      "z": -6,
      "name": "Fullmetal_Plant_Leaves_Crystal_Cyan"
    },
    {
      "x": -4,
      "y": 37,
      "z": -6,
      "name": "Fullmetal_Plant_Leaves_Crystal_Cyan"
    },
    {
      "x": -4,
      "y": 20,
      "z": -5,
      "name": "Wood_Crystal_Trunk_Full"
    },
    {
      "x": -4,
      "y": 21,
      "z": -5,
      "name": "Wood_Crystal_Trunk_Full"
    },
    {
      "x": -4,
      "y": 32,
      "z": -5,
      "name": "Wood_Crystal_Trunk_Full"
    },
    {
      "x": -4,
      "y": 36,
      "z": -5,
      "name": "Fullmetal_Plant_Leaves_Crystal_Cyan"
    },
    {
      "x": -4,
      "y": -1,
      "z": -4,
      "name": "Wood_Crystal_Trunk"
    },
    {
      "x": -4,
      "y": 0,
      "z": -4,
      "name": "Wood_Crystal_Trunk"
    },
    {
      "x": -4,
      "y": 1,
      "z": -4,
      "name": "Wood_Crystal_Trunk"
    },
    {
      "x": -4,
      "y": 2,
      "z": -4,
      "name": "Wood_Crystal_Trunk"
    },
    {
      "x": -4,
      "y": 3,
      "z": -4,
      "name": "Wood_Crystal_Trunk"
    },
    {
      "x": -4,
      "y": 4,
      "z": -4,
      "name": "Wood_Crystal_Trunk_Full"
    },
    {
      "x": -4,
      "y": 21,
      "z": -4,
      "name": "Wood_Crystal_Trunk_Full"
    },
    {
      "x": -4,
      "y": 36,
      "z": -4,
      "name": "Fullmetal_Plant_Leaves_Crystal_Cyan"
    },
    {
      "x": -4,
      "y": 37,
      "z": -4,
      "name": "Fullmetal_Plant_Leaves_Crystal_Cyan"
    },
    {
      "x": -4,
      "y": -2,
      "z": -3,
      "name": "Wood_Crystal_Trunk"
    },
    {
      "x": -4,
      "y": -1,
      "z": -3,
      "name": "Wood_Crystal_Trunk"
    },
    {
      "x": -4,
      "y": 0,
      "z": -3,
      "name": "Wood_Crystal_Trunk"
    },
    {
      "x": -4,
      "y": 1,
      "z": -3,
      "name": "Wood_Crystal_Trunk"
    },
    {
      "x": -4,
      "y": 2,
      "z": -3,
      "name": "Wood_Crystal_Trunk"
    },
    {
      "x": -4,
      "y": 3,
      "z": -3,
      "name": "Wood_Crystal_Trunk"
    },
    {
      "x": -4,
      "y": 4,
      "z": -3,
      "name": "Wood_Crystal_Trunk"
    },
    {
      "x": -4,
      "y": 5,
      "z": -3,
      "name": "Wood_Crystal_Trunk"
    },
    {
      "x": -4,
      "y": 6,
      "z": -3,
      "name": "Wood_Crystal_Trunk"
    },
    {
      "x": -4,
      "y": 7,
      "z": -3,
      "name": "Wood_Crystal_Trunk"
    },
    {
      "x": -4,
      "y": 8,
      "z": -3,
      "name": "Wood_Crystal_Trunk_Full"
    },
    {
      "x": -4,
      "y": 21,
      "z": -3,
      "name": "Wood_Crystal_Trunk_Full"
    },
    {
      "x": -4,
      "y": 23,
      "z": -3,
      "name": "Fullmetal_Plant_Leaves_Crystal_Cyan"
    },
    {
      "x": -4,
      "y": 32,
      "z": -3,
      "name": "Wood_Crystal_Trunk_Full"
    },
    {
      "x": -4,
      "y": 36,
      "z": -3,
      "name": "Fullmetal_Plant_Leaves_Crystal_Cyan"
    },
    {
      "x": -4,
      "y": -2,
      "z": -2,
      "name": "Wood_Crystal_Trunk"
    },
    {
      "x": -4,
      "y": -1,
      "z": -2,
      "name": "Wood_Crystal_Trunk"
    },
    {
      "x": -4,
      "y": 0,
      "z": -2,
      "name": "Wood_Crystal_Trunk"
    },
    {
      "x": -4,
      "y": 1,
      "z": -2,
      "name": "Wood_Crystal_Trunk"
    },
    {
      "x": -4,
      "y": 2,
      "z": -2,
      "name": "Wood_Crystal_Trunk"
    },
    {
      "x": -4,
      "y": 3,
      "z": -2,
      "name": "Wood_Crystal_Trunk"
    },
    {
      "x": -4,
      "y": 4,
      "z": -2,
      "name": "Wood_Crystal_Trunk"
    },
    {
      "x": -4,
      "y": 5,
      "z": -2,
      "name": "Wood_Crystal_Trunk"
    },
    {
      "x": -4,
      "y": 6,
      "z": -2,
      "name": "Wood_Crystal_Trunk"
    },
    {
      "x": -4,
      "y": 7,
      "z": -2,
      "name": "Wood_Crystal_Trunk"
    },
    {
      "x": -4,
      "y": 8,
      "z": -2,
      "name": "Wood_Crystal_Trunk"
    },
    {
      "x": -4,
      "y": 9,
      "z": -2,
      "name": "Wood_Crystal_Trunk"
    },
    {
      "x": -4,
      "y": 10,
      "z": -2,
      "name": "Wood_Crystal_Trunk"
    },
    {
      "x": -4,
      "y": 11,
      "z": -2,
      "name": "Wood_Crystal_Trunk"
    },
    {
      "x": -4,
      "y": 12,
      "z": -2,
      "name": "Wood_Crystal_Trunk"
    },
    {
      "x": -4,
      "y": 13,
      "z": -2,
      "name": "Wood_Crystal_Trunk_Full"
    },
    {
      "x": -4,
      "y": 21,
      "z": -2,
      "name": "Wood_Crystal_Trunk_Full"
    },
    {
      "x": -4,
      "y": 23,
      "z": -2,
      "name": "Fullmetal_Plant_Leaves_Crystal_Cyan"
    },
    {
      "x": -4,
      "y": -2,
      "z": -1,
      "name": "Wood_Crystal_Trunk"
    },
    {
      "x": -4,
      "y": -1,
      "z": -1,
