{
  "version": 8,
  "blockIdVersion": 11,
  "anchorX": 0,
  "anchorY": 0,
  "anchorZ": 0,
  "blocks": [
    {
      "x": -24,
      "y": 26,
      "z": -9,
      "name": "Fullmetal_Plant_Leaves_Crystal_Cyan"
    },
    {
      "x": -24,
      "y": 26,
      "z": -8,
      "name": "Fullmetal_Plant_Leaves_Crystal_Cyan"
    },
    {
      "x": -24,
      "y": 26,
      "z": -7,
      "name": "Fullmetal_Plant_Leaves_Crystal_Cyan"
    },
    {
      "x": -24,
      "y": 26,
      "z": -6,
      "name": "Fullmetal_Plant_Leaves_Crystal_Cyan"
    },
    {
      "x": -23,
      "y": 26,
      "z": -10,
      "name": "Fullmetal_Plant_Leaves_Crystal_Cyan"
    },
    {
      "x": -23,
      "y": 26,
      "z": -9,
      "name": "Fullmetal_Plant_Leaves_Crystal_Cyan"
    },
    {
      "x": -23,
      "y": 23,
      "z": -8,
      "name": "Fullmetal_Plant_Leaves_Crystal_Cyan"
    },
    {
      "x": -23,
      "y": 24,
      "z": -8,
      "name": "Fullmetal_Plant_Leaves_Crystal_Cyan"
    },
    {
      "x": -23,
      "y": 25,
      "z": -8,
      "name": "Fullmetal_Plant_Leaves_Crystal_Cyan"
    },
    {
      "x": -23,
      "y": 26,
      "z": -8,
      "name": "Fullmetal_Plant_Leaves_Crystal_Cyan"
    },
    {
      "x": -23,
      "y": 26,
      "z": -7,
      "name": "Fullmetal_Plant_Leaves_Crystal_Cyan"
    },
    {
      "x": -23,
      "y": 26,
      "z": -6,
      "name": "Fullmetal_Plant_Leaves_Crystal_Cyan"
    },
    {
      "x": -23,
      "y": 26,
      "z": -5,
      "name": "Fullmetal_Plant_Leaves_Crystal_Cyan"
    },
    {
      "x": -22,
      "y": 26,
      "z": -12,
      "name": "Fullmetal_Plant_Leaves_Crystal_Cyan"
    },
    {
      "x": -22,
      "y": 26,
      "z": -11,
      "name": "Fullmetal_Plant_Leaves_Crystal_Cyan"
    },
    {
      "x": -22,
      "y": 26,
      "z": -10,
      "name": "Fullmetal_Plant_Leaves_Crystal_Cyan"
    },
    {
      "x": -22,
      "y": 27,
      "z": -10,
      "name": "Fullmetal_Plant_Leaves_Crystal_Cyan"
    },
    {
      "x": -22,
      "y": 25,
      "z": -9,
      "name": "Fullmetal_Plant_Leaves_Crystal_Cyan"
    },
    {
      "x": -22,
      "y": 26,
      "z": -9,
      "name": "Fullmetal_Plant_Leaves_Crystal_Cyan"
    },
    {
      "x": -22,
      "y": 27,
      "z": -9,
      "name": "Fullmetal_Plant_Leaves_Crystal_Cyan"
    },
    {
      "x": -22,
      "y": 26,
      "z": -8,
      "name": "Wood_Crystal_Trunk_Full"
    },
    {
      "x": -22,
      "y": 27,
      "z": -8,
      "name": "Fullmetal_Plant_Leaves_Crystal_Cyan"
    },
    {
      "x": -22,
      "y": 28,
      "z": -8,
      "name": "Fullmetal_Plant_Leaves_Crystal_Cyan"
    },
    {
      "x": -22,
      "y": 26,
      "z": -7,
      "name": "Fullmetal_Plant_Leaves_Crystal_Cyan"
    },
    {
      "x": -22,
      "y": 27,
      "z": -7,
      "name": "Fullmetal_Plant_Leaves_Crystal_Cyan"
    },
    {
      "x": -22,
      "y": 26,
      "z": -6,
      "name": "Fullmetal_Plant_Leaves_Crystal_Cyan"
    },
    {
      "x": -22,
      "y": 27,
      "z": -6,
      "name": "Fullmetal_Plant_Leaves_Crystal_Cyan"
    },
    {
      "x": -22,
      "y": 25,
      "z": -5,
      "name": "Fullmetal_Plant_Leaves_Crystal_Cyan"
    },
    {
      "x": -22,
      "y": 26,
      "z": -5,
      "name": "Fullmetal_Plant_Leaves_Crystal_Cyan"
    },
    {
      "x": -22,
      "y": 27,
      "z": -5,
      "name": "Fullmetal_Plant_Leaves_Crystal_Cyan"
    },
    {
      "x": -22,
      "y": 26,
      "z": -4,
      "name": "Fullmetal_Plant_Leaves_Crystal_Cyan"
    },
    {
      "x": -22,
      "y": 26,
      "z": -3,
      "name": "Fullmetal_Plant_Leaves_Crystal_Cyan"
    },
    {
      "x": -22,
      "y": 26,
      "z": -2,
      "name": "Fullmetal_Plant_Leaves_Crystal_Cyan"
    },
    {
      "x": -22,
      "y": 26,
      "z": -1,
      "name": "Fullmetal_Plant_Leaves_Crystal_Cyan"
    },
    {
      "x": -21,
      "y": 26,
      "z": -12,
      "name": "Fullmetal_Plant_Leaves_Crystal_Cyan"
    },
    {
      "x": -21,
      "y": 26,
      "z": -11,
      "name": "Fullmetal_Plant_Leaves_Crystal_Cyan"
    },
    {
      "x": -21,
      "y": 27,
      "z": -11,
      "name": "Fullmetal_Plant_Leaves_Crystal_Cyan"
    },
    {
      "x": -21,
      "y": 27,
      "z": -10,
      "name": "Fullmetal_Plant_Leaves_Crystal_Cyan"
    },
    {
      "x": -21,
      "y": 26,
      "z": -9,
      "name": "Fullmetal_Plant_Leaves_Crystal_Cyan"
    },
    {
      "x": -21,
      "y": 27,
      "z": -9,
      "name": "Fullmetal_Plant_Leaves_Crystal_Cyan"
    },
    {
      "x": -21,
      "y": 26,
      "z": -8,
      "name": "Wood_Crystal_Trunk_Full"
    },
    {
      "x": -21,
      "y": 27,
      "z": -8,
      "name": "Fullmetal_Plant_Leaves_Crystal_Cyan"
    },
    {
      "x": -21,
      "y": 28,
      "z": -8,
      "name": "Fullmetal_Plant_Leaves_Crystal_Cyan"
    },
    {
      "x": -21,
      "y": 26,
      "z": -7,
      "name": "Fullmetal_Plant_Leaves_Crystal_Cyan"
    },
    {
      "x": -21,
      "y": 27,
      "z": -7,
      "name": "Fullmetal_Plant_Leaves_Crystal_Cyan"
    },
    {
      "x": -21,
      "y": 26,
      "z": -6,
      "name": "Fullmetal_Plant_Leaves_Crystal_Cyan"
    },
    {
      "x": -21,
      "y": 27,
      "z": -6,
      "name": "Fullmetal_Plant_Leaves_Crystal_Cyan"
    },
    {
      "x": -21,
      "y": 25,
      "z": -5,
      "name": "Fullmetal_Plant_Leaves_Crystal_Cyan"
    },
    {
      "x": -21,
      "y": 26,
      "z": -5,
      "name": "Fullmetal_Plant_Leaves_Crystal_Cyan"
    },
    {
      "x": -21,
      "y": 27,
      "z": -5,
      "name": "Fullmetal_Plant_Leaves_Crystal_Cyan"
    },
    {
      "x": -21,
      "y": 26,
      "z": -4,
      "name": "Fullmetal_Plant_Leaves_Crystal_Cyan"
    },
    {
      "x": -21,
      "y": 26,
      "z": -3,
      "name": "Fullmetal_Plant_Leaves_Crystal_Cyan"
    },
    {
      "x": -21,
      "y": 25,
      "z": -1,
      "name": "Fullmetal_Plant_Leaves_Crystal_Cyan"
    },
    {
      "x": -21,
      "y": 26,
      "z": -1,
      "name": "Fullmetal_Plant_Leaves_Crystal_Cyan"
    },
    {
      "x": -20,
      "y": 25,
      "z": -13,
      "name": "Fullmetal_Plant_Leaves_Crystal_Cyan"
    },
    {
      "x": -20,
      "y": 26,
      "z": -12,
      "name": "Fullmetal_Plant_Leaves_Crystal_Cyan"
    },
    {
      "x": -20,
      "y": 24,
      "z": -11,
      "name": "Fullmetal_Plant_Leaves_Crystal_Cyan"
    },
    {
      "x": -20,
      "y": 25,
      "z": -11,
      "name": "Fullmetal_Plant_Leaves_Crystal_Cyan"
    },
    {
      "x": -20,
      "y": 26,
      "z": -11,
      "name": "Fullmetal_Plant_Leaves_Crystal_Cyan"
    },
    {
      "x": -20,
      "y": 27,
      "z": -11,
      "name": "Fullmetal_Plant_Leaves_Crystal_Cyan"
    },
    {
      "x": -20,
      "y": 25,
      "z": -10,
      "name": "Fullmetal_Plant_Leaves_Crystal_Cyan"
    },
    {
      "x": -20,
      "y": 27,
      "z": -10,
      "name": "Fullmetal_Plant_Leaves_Crystal_Cyan"
    },
    {
      "x": -20,
      "y": 26,
      "z": -9,
      "name": "Wood_Crystal_Branch_Corner",
      "rotation": 2
    },
    {
      "x": -20,
      "y": 27,
      "z": -9,
      "name": "Fullmetal_Plant_Leaves_Crystal_Cyan"
    },
    {
      "x": -20,
      "y": 26,
      "z": -8,
      "name": "Wood_Crystal_Trunk_Full"
    },
    {
      "x": -20,
      "y": 27,
      "z": -8,
      "name": "Fullmetal_Plant_Leaves_Crystal_Cyan"
    },
    {
      "x": -20,
      "y": 27,
      "z": -7,
      "name": "Fullmetal_Plant_Leaves_Crystal_Cyan"
    },
    {
      "x": -20,
      "y": 28,
      "z": -7,
      "name": "Fullmetal_Plant_Leaves_Crystal_Cyan"
    },
    {
      "x": -20,
      "y": 25,
      "z": -6,
      "name": "Wood_Crystal_Branch_Corner",
      "rotation": 2
    },
    {
      "x": -20,
      "y": 26,
      "z": -6,
      "name": "Fullmetal_Plant_Leaves_Crystal_Cyan"
    },
    {
      "x": -20,
      "y": 27,
      "z": -6,
      "name": "Fullmetal_Plant_Leaves_Crystal_Cyan"
    },
    {
      "x": -20,
      "y": 28,
      "z": -6,
      "name": "Fullmetal_Plant_Leaves_Crystal_Cyan"
    },
    {
      "x": -20,
      "y": 25,
      "z": -5,
      "name": "Wood_Crystal_Branch_Long",
      "rotation": 4
    },
    {
      "x": -20,
      "y": 26,
      "z": -5,
      "name": "Fullmetal_Plant_Leaves_Crystal_Cyan"
    },
    {
      "x": -20,
      "y": 27,
      "z": -5,
      "name": "Fullmetal_Plant_Leaves_Crystal_Cyan"
    },
    {
      "x": -20,
      "y": 24,
      "z": -4,
      "name": "Wood_Crystal_Roots"
    },
    {
      "x": -20,
      "y": 25,
      "z": -4,
      "name": "Wood_Crystal_Trunk_Full"
    },
    {
      "x": -20,
      "y": 26,
      "z": -4,
      "name": "Fullmetal_Plant_Leaves_Crystal_Cyan"
    },
    {
      "x": -20,
      "y": 27,
      "z": -4,
      "name": "Fullmetal_Plant_Leaves_Crystal_Cyan"
    },
    {
      "x": -20,
      "y": 25,
      "z": -3,
      "name": "Fullmetal_Plant_Leaves_Crystal_Cyan"
    },
    {
      "x": -20,
      "y": 26,
      "z": -3,
      "name": "Fullmetal_Plant_Leaves_Crystal_Cyan"
    },
    {
      "x": -20,
      "y": 25,
      "z": -2,
      "name": "Fullmetal_Plant_Leaves_Crystal_Cyan"
    },
    {
      "x": -20,
      "y": 26,
      "z": -2,
      "name": "Fullmetal_Plant_Leaves_Crystal_Cyan"
    },
    {
      "x": -20,
      "y": 24,
      "z": -1,
      "name": "Fullmetal_Plant_Leaves_Crystal_Cyan"
    },
    {
      "x": -20,
      "y": 25,
      "z": -1,
      "name": "Fullmetal_Plant_Leaves_Crystal_Cyan"
    },
    {
      "x": -20,
      "y": 26,
      "z": -1,
      "name": "Fullmetal_Plant_Leaves_Crystal_Cyan"
    },
    {
      "x": -20,
      "y": 25,
      "z": 0,
      "name": "Fullmetal_Plant_Leaves_Crystal_Cyan"
    },
    {
      "x": -20,
      "y": 25,
      "z": 1,
      "name": "Fullmetal_Plant_Leaves_Crystal_Cyan"
    },
    {
      "x": -19,
      "y": 25,
      "z": -13,
      "name": "Fullmetal_Plant_Leaves_Crystal_Cyan"
    },
    {
      "x": -19,
      "y": 23,
      "z": -12,
      "name": "Fullmetal_Plant_Leaves_Crystal_Cyan"
    },
    {
      "x": -19,
      "y": 24,
      "z": -12,
      "name": "Fullmetal_Plant_Leaves_Crystal_Cyan"
    },
    {
      "x": -19,
      "y": 25,
      "z": -12,
      "name": "Fullmetal_Plant_Leaves_Crystal_Cyan"
    },
    {
      "x": -19,
      "y": 24,
      "z": -11,
      "name": "Fullmetal_Plant_Leaves_Crystal_Cyan"
    },
    {
      "x": -19,
      "y": 25,
      "z": -11,
      "name": "Fullmetal_Plant_Leaves_Crystal_Cyan"
    },
    {
      "x": -19,
      "y": 26,
      "z": -11,
      "name": "Fullmetal_Plant_Leaves_Crystal_Cyan"
    },
    {
      "x": -19,
      "y": 27,
      "z": -11,
      "name": "Fullmetal_Plant_Leaves_Crystal_Cyan"
    },
    {
      "x": -19,
      "y": 24,
      "z": -10,
      "name": "Fullmetal_Plant_Leaves_Crystal_Cyan"
    },
    {
      "x": -19,
      "y": 25,
      "z": -10,
      "name": "Fullmetal_Plant_Leaves_Crystal_Cyan"
    },
    {
      "x": -19,
      "y": 26,
      "z": -10,
      "name": "Wood_Crystal_Trunk_Full"
    },
    {
      "x": -19,
      "y": 27,
      "z": -10,
      "name": "Fullmetal_Plant_Leaves_Crystal_Cyan"
    },
    {
      "x": -19,
      "y": 25,
      "z": -9,
      "name": "Fullmetal_Plant_Leaves_Crystal_Cyan"
    },
    {
      "x": -19,
      "y": 26,
      "z": -9,
      "name": "Wood_Crystal_Trunk_Full"
    },
    {
      "x": -19,
      "y": 27,
      "z": -9,
      "name": "Fullmetal_Plant_Leaves_Crystal_Cyan"
    },
    {
      "x": -19,
      "y": 28,
      "z": -9,
      "name": "Fullmetal_Plant_Leaves_Crystal_Cyan"
    },
    {
      "x": -19,
      "y": 26,
      "z": -8,
      "name": "Wood_Crystal_Trunk_Full"
    },
    {
      "x": -19,
      "y": 27,
      "z": -8,
      "name": "Fullmetal_Plant_Leaves_Crystal_Cyan"
    },
    {
      "x": -19,
      "y": 28,
      "z": -8,
      "name": "Fullmetal_Plant_Leaves_Crystal_Cyan"
    },
    {
      "x": -19,
      "y": 26,
      "z": -7,
      "name": "Wood_Crystal_Trunk_Full"
    },
    {
      "x": -19,
      "y": 27,
      "z": -7,
      "name": "Fullmetal_Plant_Leaves_Crystal_Cyan"
    },
    {
      "x": -19,
      "y": 28,
      "z": -7,
      "name": "Fullmetal_Plant_Leaves_Crystal_Cyan"
    },
    {
      "x": -19,
      "y": 27,
      "z": -6,
      "name": "Fullmetal_Plant_Leaves_Crystal_Cyan"
    },
    {
      "x": -19,
      "y": 28,
      "z": -6,
      "name": "Fullmetal_Plant_Leaves_Crystal_Cyan"
    },
    {
      "x": -19,
      "y": 27,
      "z": -5,
      "name": "Fullmetal_Plant_Leaves_Crystal_Cyan"
    },
    {
      "x": -19,
      "y": 28,
      "z": -5,
      "name": "Fullmetal_Plant_Leaves_Crystal_Cyan"
    },
    {
      "x": -19,
      "y": 24,
      "z": -4,
      "name": "Wood_Crystal_Roots"
    },
    {
      "x": -19,
      "y": 25,
      "z": -4,
      "name": "Wood_Crystal_Trunk_Full"
    },
    {
      "x": -19,
      "y": 26,
      "z": -4,
      "name": "Fullmetal_Plant_Leaves_Crystal_Cyan"
    },
    {
      "x": -19,
      "y": 27,
      "z": -4,
      "name": "Fullmetal_Plant_Leaves_Crystal_Cyan"
    },
    {
      "x": -19,
      "y": 28,
      "z": -4,
      "name": "Fullmetal_Plant_Leaves_Crystal_Cyan"
    },
    {
      "x": -19,
      "y": 29,
      "z": -4,
      "name": "Fullmetal_Plant_Leaves_Crystal_Cyan"
    },
    {
      "x": -19,
      "y": 25,
      "z": -3,
      "name": "Wood_Crystal_Trunk_Full"
    },
    {
      "x": -19,
      "y": 26,
      "z": -3,
      "name": "Fullmetal_Plant_Leaves_Crystal_Cyan"
    },
    {
      "x": -19,
      "y": 27,
      "z": -3,
      "name": "Fullmetal_Plant_Leaves_Crystal_Cyan"
    },
    {
      "x": -19,
      "y": 29,
      "z": -3,
      "name": "Fullmetal_Plant_Leaves_Crystal_Cyan"
    },
    {
      "x": -19,
      "y": 25,
      "z": -2,
      "name": "Fullmetal_Plant_Leaves_Crystal_Cyan"
    },
    {
      "x": -19,
      "y": 26,
      "z": -2,
      "name": "Fullmetal_Plant_Leaves_Crystal_Cyan"
    },
    {
      "x": -19,
      "y": 29,
      "z": -2,
      "name": "Fullmetal_Plant_Leaves_Crystal_Cyan"
    },
    {
      "x": -19,
      "y": 24,
      "z": -1,
      "name": "Fullmetal_Plant_Leaves_Crystal_Cyan"
    },
    {
      "x": -19,
      "y": 25,
      "z": -1,
      "name": "Fullmetal_Plant_Leaves_Crystal_Cyan"
    },
    {
      "x": -19,
      "y": 26,
      "z": -1,
      "name": "Fullmetal_Plant_Leaves_Crystal_Cyan"
    },
    {
      "x": -19,
      "y": 24,
      "z": 0,
      "name": "Fullmetal_Plant_Leaves_Crystal_Cyan"
    },
    {
      "x": -19,
      "y": 25,
      "z": 0,
      "name": "Fullmetal_Plant_Leaves_Crystal_Cyan"
    },
    {
      "x": -19,
      "y": 26,
      "z": 0,
      "name": "Fullmetal_Plant_Leaves_Crystal_Cyan"
    },
    {
      "x": -19,
      "y": 28,
      "z": 0,
      "name": "Fullmetal_Plant_Leaves_Crystal_Cyan"
    },
    {
      "x": -19,
      "y": 25,
      "z": 1,
      "name": "Fullmetal_Plant_Leaves_Crystal_Cyan"
    },
    {
      "x": -19,
      "y": 28,
      "z": 1,
      "name": "Fullmetal_Plant_Leaves_Crystal_Cyan"
    },
    {
      "x": -19,
      "y": 28,
      "z": 2,
      "name": "Fullmetal_Plant_Leaves_Crystal_Cyan"
    },
    {
      "x": -19,
      "y": 24,
      "z": 5,
      "name": "Fullmetal_Plant_Leaves_Crystal_Cyan"
    },
    {
      "x": -19,
      "y": 24,
      "z": 7,
      "name": "Fullmetal_Plant_Leaves_Crystal_Cyan"
    },
    {
      "x": -18,
      "y": 25,
      "z": -14,
      "name": "Fullmetal_Plant_Leaves_Crystal_Cyan"
    },
    {
      "x": -18,
      "y": 26,
      "z": -14,
      "name": "Fullmetal_Plant_Leaves_Crystal_Cyan"
    },
    {
      "x": -18,
      "y": 25,
      "z": -13,
      "name": "Fullmetal_Plant_Leaves_Crystal_Cyan"
    },
    {
      "x": -18,
      "y": 26,
      "z": -13,
      "name": "Fullmetal_Plant_Leaves_Crystal_Cyan"
    },
    {
      "x": -18,
      "y": 24,
      "z": -12,
      "name": "Fullmetal_Plant_Leaves_Crystal_Cyan"
    },
    {
      "x": -18,
      "y": 25,
      "z": -12,
      "name": "Fullmetal_Plant_Leaves_Crystal_Cyan"
    },
    {
      "x": -18,
      "y": 26,
      "z": -12,
      "name": "Fullmetal_Plant_Leaves_Crystal_Cyan"
    },
    {
      "x": -18,
      "y": 24,
      "z": -11,
      "name": "Fullmetal_Plant_Leaves_Crystal_Cyan"
    },
    {
      "x": -18,
      "y": 25,
      "z": -11,
      "name": "Fullmetal_Plant_Leaves_Crystal_Cyan"
    },
    {
      "x": -18,
      "y": 26,
      "z": -11,
      "name": "Fullmetal_Plant_Leaves_Crystal_Cyan"
    },
    {
      "x": -18,
      "y": 24,
      "z": -10,
      "name": "Fullmetal_Plant_Leaves_Crystal_Cyan"
    },
    {
      "x": -18,
      "y": 25,
      "z": -10,
      "name": "Fullmetal_Plant_Leaves_Crystal_Cyan"
    },
    {
      "x": -18,
      "y": 26,
      "z": -10,
      "name": "Fullmetal_Plant_Leaves_Crystal_Cyan"
    },
    {
      "x": -18,
      "y": 27,
      "z": -10,
      "name": "Fullmetal_Plant_Leaves_Crystal_Cyan"
    },
    {
      "x": -18,
      "y": 24,
      "z": -9,
      "name": "Fullmetal_Plant_Leaves_Crystal_Cyan"
    },
    {
      "x": -18,
      "y": 25,
      "z": -9,
      "name": "Fullmetal_Plant_Leaves_Crystal_Cyan"
    },
    {
      "x": -18,
      "y": 26,
      "z": -9,
      "name": "Fullmetal_Plant_Leaves_Crystal_Cyan"
    },
    {
      "x": -18,
      "y": 27,
      "z": -9,
      "name": "Fullmetal_Plant_Leaves_Crystal_Cyan"
    },
    {
      "x": -18,
      "y": 28,
      "z": -9,
      "name": "Fullmetal_Plant_Leaves_Crystal_Cyan"
    },
    {
      "x": -18,
      "y": 26,
      "z": -8,
      "name": "Fullmetal_Plant_Leaves_Crystal_Cyan"
    },
    {
      "x": -18,
      "y": 27,
      "z": -8,
      "name": "Fullmetal_Plant_Leaves_Crystal_Cyan"
    },
    {
      "x": -18,
      "y": 28,
      "z": -8,
      "name": "Fullmetal_Plant_Leaves_Crystal_Cyan"
    },
    {
      "x": -18,
      "y": 25,
      "z": -7,
      "name": "Wood_Crystal_Trunk_Full"
    },
    {
      "x": -18,
      "y": 26,
      "z": -7,
      "name": "Wood_Crystal_Trunk_Full"
    },
    {
      "x": -18,
      "y": 27,
      "z": -7,
      "name": "Fullmetal_Plant_Leaves_Crystal_Cyan"
    },
    {
      "x": -18,
      "y": 28,
      "z": -7,
      "name": "Fullmetal_Plant_Leaves_Crystal_Cyan"
    },
    {
      "x": -18,
      "y": 27,
      "z": -6,
      "name": "Fullmetal_Plant_Leaves_Crystal_Cyan"
    },
    {
      "x": -18,
      "y": 28,
      "z": -6,
      "name": "Fullmetal_Plant_Leaves_Crystal_Cyan"
    },
    {
      "x": -18,
      "y": 29,
      "z": -6,
      "name": "Fullmetal_Plant_Leaves_Crystal_Cyan"
    },
    {
      "x": -18,
      "y": 27,
      "z": -5,
      "name": "Fullmetal_Plant_Leaves_Crystal_Cyan"
    },
    {
      "x": -18,
      "y": 28,
      "z": -5,
      "name": "Fullmetal_Plant_Leaves_Crystal_Cyan"
    },
    {
      "x": -18,
      "y": 29,
      "z": -5,
      "name": "Fullmetal_Plant_Leaves_Crystal_Cyan"
    },
    {
      "x": -18,
      "y": 25,
      "z": -4,
      "name": "Wood_Crystal_Trunk_Full"
    },
    {
      "x": -18,
      "y": 27,
      "z": -4,
      "name": "Fullmetal_Plant_Leaves_Crystal_Cyan"
    },
    {
      "x": -18,
      "y": 29,
      "z": -4,
      "name": "Fullmetal_Plant_Leaves_Crystal_Cyan"
    },
    {
      "x": -18,
      "y": 26,
      "z": -3,
      "name": "Fullmetal_Plant_Leaves_Crystal_Cyan"
    },
    {
      "x": -18,
      "y": 27,
      "z": -3,
      "name": "Fullmetal_Plant_Leaves_Crystal_Cyan"
    },
    {
      "x": -18,
      "y": 28,
      "z": -3,
      "name": "Fullmetal_Plant_Leaves_Crystal_Cyan"
    },
    {
      "x": -18,
      "y": 29,
      "z": -3,
      "name": "Fullmetal_Plant_Leaves_Crystal_Cyan"
    },
    {
      "x": -18,
      "y": 30,
      "z": -3,
      "name": "Fullmetal_Plant_Leaves_Crystal_Cyan"
    },
    {
      "x": -18,
      "y": 25,
      "z": -2,
      "name": "Fullmetal_Plant_Leaves_Crystal_Cyan"
    },
    {
      "x": -18,
      "y": 26,
      "z": -2,
      "name": "Fullmetal_Plant_Leaves_Crystal_Cyan"
    },
    {
      "x": -18,
      "y": 27,
      "z": -2,
      "name": "Fullmetal_Plant_Leaves_Crystal_Cyan"
    },
    {
      "x": -18,
      "y": 28,
      "z": -2,
      "name": "Fullmetal_Plant_Leaves_Crystal_Cyan"
    },
    {
      "x": -18,
      "y": 29,
      "z": -2,
      "name": "Fullmetal_Plant_Leaves_Crystal_Cyan"
    },
    {
      "x": -18,
      "y": 30,
      "z": -2,
      "name": "Fullmetal_Plant_Leaves_Crystal_Cyan"
    },
    {
      "x": -18,
      "y": 25,
      "z": -1,
      "name": "Fullmetal_Plant_Leaves_Crystal_Cyan"
    },
    {
      "x": -18,
      "y": 26,
      "z": -1,
      "name": "Fullmetal_Plant_Leaves_Crystal_Cyan"
    },
    {
      "x": -18,
      "y": 28,
      "z": -1,
      "name": "Fullmetal_Plant_Leaves_Crystal_Cyan"
    },
    {
      "x": -18,
      "y": 29,
      "z": -1,
      "name": "Fullmetal_Plant_Leaves_Crystal_Cyan"
    },
    {
      "x": -18,
      "y": 24,
      "z": 0,
      "name": "Fullmetal_Plant_Leaves_Crystal_Cyan"
    },
    {
      "x": -18,
      "y": 25,
      "z": 0,
      "name": "Fullmetal_Plant_Leaves_Crystal_Cyan"
    },
    {
      "x": -18,
      "y": 26,
      "z": 0,
      "name": "Fullmetal_Plant_Leaves_Crystal_Cyan"
    },
    {
      "x": -18,
      "y": 28,
      "z": 0,
      "name": "Fullmetal_Plant_Leaves_Crystal_Cyan"
    },
    {
      "x": -18,
      "y": 24,
      "z": 1,
      "name": "Fullmetal_Plant_Leaves_Crystal_Cyan"
    },
    {
      "x": -18,
      "y": 28,
      "z": 1,
      "name": "Fullmetal_Plant_Leaves_Crystal_Cyan"
    },
    {
      "x": -18,
      "y": 29,
      "z": 1,
      "name": "Fullmetal_Plant_Leaves_Crystal_Cyan"
    },
    {
      "x": -18,
      "y": 25,
      "z": 2,
      "name": "Fullmetal_Plant_Leaves_Crystal_Cyan"
    },
    {
      "x": -18,
      "y": 28,
      "z": 2,
      "name": "Fullmetal_Plant_Leaves_Crystal_Cyan"
    },
    {
      "x": -18,
      "y": 29,
      "z": 2,
      "name": "Fullmetal_Plant_Leaves_Crystal_Cyan"
    },
    {
      "x": -18,
      "y": 28,
      "z": 3,
      "name": "Fullmetal_Plant_Leaves_Crystal_Cyan"
    },
    {
      "x": -18,
      "y": 24,
      "z": 4,
      "name": "Fullmetal_Plant_Leaves_Crystal_Cyan"
    },
    {
      "x": -18,
      "y": 24,
      "z": 5,
      "name": "Fullmetal_Plant_Leaves_Crystal_Cyan"
    },
    {
      "x": -18,
      "y": 25,
      "z": 5,
      "name": "Fullmetal_Plant_Leaves_Crystal_Cyan"
    },
    {
      "x": -18,
      "y": 23,
      "z": 7,
      "name": "Fullmetal_Plant_Leaves_Crystal_Cyan"
    },
    {
      "x": -18,
      "y": 24,
      "z": 7,
      "name": "Fullmetal_Plant_Leaves_Crystal_Cyan"
    },
    {
      "x": -18,
      "y": 23,
      "z": 8,
      "name": "Fullmetal_Plant_Leaves_Crystal_Cyan"
    },
    {
      "x": -18,
      "y": 24,
      "z": 8,
      "name": "Fullmetal_Plant_Leaves_Crystal_Cyan"
    },
    {
      "x": -17,
      "y": 25,
      "z": -13,
      "name": "Fullmetal_Plant_Leaves_Crystal_Cyan"
    },
    {
      "x": -17,
      "y": 26,
      "z": -13,
      "name": "Fullmetal_Plant_Leaves_Crystal_Cyan"
    },
    {
      "x": -17,
      "y": 24,
      "z": -12,
      "name": "Fullmetal_Plant_Leaves_Crystal_Cyan"
    },
    {
      "x": -17,
      "y": 25,
      "z": -12,
      "name": "Fullmetal_Plant_Leaves_Crystal_Cyan"
    },
    {
      "x": -17,
      "y": 26,
      "z": -12,
      "name": "Fullmetal_Plant_Leaves_Crystal_Cyan"
    },
    {
      "x": -17,
      "y": 24,
      "z": -11,
      "name": "Fullmetal_Plant_Leaves_Crystal_Cyan"
    },
    {
      "x": -17,
      "y": 25,
      "z": -11,
      "name": "Fullmetal_Plant_Leaves_Crystal_Cyan"
    },
    {
      "x": -17,
      "y": 26,
      "z": -11,
      "name": "Fullmetal_Plant_Leaves_Crystal_Cyan"
    },
    {
      "x": -17,
      "y": 25,
      "z": -10,
      "name": "Fullmetal_Plant_Leaves_Crystal_Cyan"
    },
    {
      "x": -17,
      "y": 26,
      "z": -10,
      "name": "Fullmetal_Plant_Leaves_Crystal_Cyan"
    },
    {
      "x": -17,
      "y": 27,
      "z": -10,
      "name": "Fullmetal_Plant_Leaves_Crystal_Cyan"
    },
    {
      "x": -17,
      "y": 25,
      "z": -9,
      "name": "Fullmetal_Plant_Leaves_Crystal_Cyan"
    },
    {
      "x": -17,
      "y": 26,
      "z": -9,
      "name": "Fullmetal_Plant_Leaves_Crystal_Cyan"
    },
    {
      "x": -17,
      "y": 27,
      "z": -9,
      "name": "Fullmetal_Plant_Leaves_Crystal_Cyan"
    },
    {
      "x": -17,
      "y": 28,
      "z": -9,
      "name": "Fullmetal_Plant_Leaves_Crystal_Cyan"
    },
    {
      "x": -17,
      "y": 25,
      "z": -8,
      "name": "Wood_Crystal_Branch_Corner",
      "rotation": 2
    },
    {
      "x": -17,
      "y": 26,
      "z": -8,
      "name": "Fullmetal_Plant_Leaves_Crystal_Cyan"
    },
    {
      "x": -17,
      "y": 27,
      "z": -8,
      "name": "Fullmetal_Plant_Leaves_Crystal_Cyan"
    },
    {
      "x": -17,
      "y": 25,
      "z": -7,
      "name": "Wood_Crystal_Trunk_Full"
    },
    {
      "x": -17,
      "y": 27,
      "z": -7,
      "name": "Fullmetal_Plant_Leaves_Crystal_Cyan"
    },
    {
      "x": -17,
      "y": 28,
      "z": -7,
      "name": "Fullmetal_Plant_Leaves_Crystal_Cyan"
    },
    {
      "x": -17,
      "y": 25,
      "z": -6,
      "name": "Wood_Crystal_Trunk_Full"
    },
    {
      "x": -17,
      "y": 27,
      "z": -6,
      "name": "Fullmetal_Plant_Leaves_Crystal_Cyan"
    },
    {
      "x": -17,
      "y": 28,
      "z": -6,
      "name": "Fullmetal_Plant_Leaves_Crystal_Cyan"
    },
    {
      "x": -17,
      "y": 29,
      "z": -6,
      "name": "Fullmetal_Plant_Leaves_Crystal_Cyan"
    },
    {
      "x": -17,
      "y": 25,
      "z": -5,
      "name": "Wood_Crystal_Trunk_Full"
    },
    {
      "x": -17,
      "y": 27,
      "z": -5,
      "name": "Fullmetal_Plant_Leaves_Crystal_Cyan"
    },
    {
      "x": -17,
      "y": 28,
      "z": -5,
      "name": "Fullmetal_Plant_Leaves_Crystal_Cyan"
    },
    {
      "x": -17,
      "y": 29,
      "z": -5,
      "name": "Fullmetal_Plant_Leaves_Crystal_Cyan"
    },
    {
      "x": -17,
      "y": 30,
      "z": -5,
      "name": "Fullmetal_Plant_Leaves_Crystal_Cyan"
    },
    {
      "x": -17,
      "y": 25,
      "z": -4,
      "name": "Wood_Crystal_Trunk_Full"
    },
    {
      "x": -17,
      "y": 27,
      "z": -4,
      "name": "Fullmetal_Plant_Leaves_Crystal_Cyan"
    },
    {
      "x": -17,
      "y": 29,
      "z": -4,
      "name": "Fullmetal_Plant_Leaves_Crystal_Cyan"
    },
    {
      "x": -17,
      "y": 30,
      "z": -4,
      "name": "Fullmetal_Plant_Leaves_Crystal_Cyan"
    },
    {
      "x": -17,
      "y": 25,
      "z": -3,
      "name": "Wood_Crystal_Trunk_Full"
    },
    {
      "x": -17,
      "y": 26,
      "z": -3,
      "name": "Fullmetal_Plant_Leaves_Crystal_Cyan"
    },
    {
      "x": -17,
      "y": 27,
      "z": -3,
      "name": "Fullmetal_Plant_Leaves_Crystal_Cyan"
    },
    {
      "x": -17,
      "y": 29,
      "z": -3,
      "name": "Fullmetal_Plant_Leaves_Crystal_Cyan"
    },
    {
      "x": -17,
      "y": 30,
      "z": -3,
      "name": "Fullmetal_Plant_Leaves_Crystal_Cyan"
    },
    {
      "x": -17,
      "y": 24,
      "z": -2,
      "name": "Fullmetal_Plant_Leaves_Crystal_Cyan"
    },
    {
      "x": -17,
      "y": 25,
      "z": -2,
      "name": "Wood_Crystal_Trunk_Full"
    },
    {
      "x": -17,
      "y": 26,
      "z": -2,
      "name": "Fullmetal_Plant_Leaves_Crystal_Cyan"
    },
    {
      "x": -17,
      "y": 28,
      "z": -2,
      "name": "Fullmetal_Plant_Leaves_Crystal_Cyan"
    },
    {
      "x": -17,
      "y": 29,
      "z": -2,
      "name": "Fullmetal_Plant_Leaves_Crystal_Cyan"
    },
    {
      "x": -17,
      "y": 30,
      "z": -2,
      "name": "Fullmetal_Plant_Leaves_Crystal_Cyan"
    },
    {
      "x": -17,
      "y": 24,
      "z": -1,
      "name": "Fullmetal_Plant_Leaves_Crystal_Cyan"
    },
    {
      "x": -17,
      "y": 25,
      "z": -1,
      "name": "Fullmetal_Plant_Leaves_Crystal_Cyan"
    },
    {
      "x": -17,
      "y": 26,
      "z": -1,
      "name": "Fullmetal_Plant_Leaves_Crystal_Cyan"
    },
    {
      "x": -17,
      "y": 27,
      "z": -1,
      "name": "Fullmetal_Plant_Leaves_Crystal_Cyan"
    },
    {
      "x": -17,
      "y": 28,
      "z": -1,
      "name": "Fullmetal_Plant_Leaves_Crystal_Cyan"
    },
    {
      "x": -17,
      "y": 29,
      "z": -1,
      "name": "Fullmetal_Plant_Leaves_Crystal_Cyan"
    },
    {
      "x": -17,
      "y": 24,
      "z": 0,
      "name": "Fullmetal_Plant_Leaves_Crystal_Cyan"
    },
    {
      "x": -17,
      "y": 25,
      "z": 0,
      "name": "Fullmetal_Plant_Leaves_Crystal_Cyan"
    },
    {
      "x": -17,
      "y": 26,
      "z": 0,
      "name": "Fullmetal_Plant_Leaves_Crystal_Cyan"
    },
    {
      "x": -17,
      "y": 27,
      "z": 0,
      "name": "Fullmetal_Plant_Leaves_Crystal_Cyan"
    },
    {
      "x": -17,
      "y": 28,
      "z": 0,
      "name": "Fullmetal_Plant_Leaves_Crystal_Cyan"
    },
    {
      "x": -17,
      "y": 29,
      "z": 0,
      "name": "Fullmetal_Plant_Leaves_Crystal_Cyan"
    },
    {
      "x": -17,
      "y": 24,
      "z": 1,
      "name": "Fullmetal_Plant_Leaves_Crystal_Cyan"
    },
    {
      "x": -17,
      "y": 25,
      "z": 1,
      "name": "Fullmetal_Plant_Leaves_Crystal_Cyan"
    },
    {
      "x": -17,
      "y": 27,
      "z": 1,
      "name": "Fullmetal_Plant_Leaves_Crystal_Cyan"
    },
    {
      "x": -17,
      "y": 28,
      "z": 1,
      "name": "Fullmetal_Plant_Leaves_Crystal_Cyan"
    },
    {
      "x": -17,
      "y": 29,
      "z": 1,
      "name": "Fullmetal_Plant_Leaves_Crystal_Cyan"
    },
    {
      "x": -17,
      "y": 24,
      "z": 2,
      "name": "Fullmetal_Plant_Leaves_Crystal_Cyan"
    },
    {
      "x": -17,
      "y": 25,
      "z": 2,
      "name": "Fullmetal_Plant_Leaves_Crystal_Cyan"
    },
    {
      "x": -17,
      "y": 27,
      "z": 2,
      "name": "Fullmetal_Plant_Leaves_Crystal_Cyan"
    },
    {
      "x": -17,
      "y": 28,
      "z": 2,
      "name": "Fullmetal_Plant_Leaves_Crystal_Cyan"
    },
    {
      "x": -17,
      "y": 29,
      "z": 2,
      "name": "Fullmetal_Plant_Leaves_Crystal_Cyan"
    },
    {
      "x": -17,
      "y": 23,
      "z": 3,
      "name": "Fullmetal_Plant_Leaves_Crystal_Cyan"
    },
    {
      "x": -17,
      "y": 24,
      "z": 3,
      "name": "Fullmetal_Plant_Leaves_Crystal_Cyan"
    },
    {
      "x": -17,
      "y": 25,
      "z": 3,
      "name": "Fullmetal_Plant_Leaves_Crystal_Cyan"
    },
    {
      "x": -17,
      "y": 28,
      "z": 3,
      "name": "Fullmetal_Plant_Leaves_Crystal_Cyan"
    },
    {
      "x": -17,
      "y": 29,
      "z": 3,
      "name": "Fullmetal_Plant_Leaves_Crystal_Cyan"
    },
    {
      "x": -17,
      "y": 24,
      "z": 4,
      "name": "Fullmetal_Plant_Leaves_Crystal_Cyan"
    },
    {
      "x": -17,
      "y": 25,
      "z": 4,
      "name": "Fullmetal_Plant_Leaves_Crystal_Cyan"
    },
    {
      "x": -17,
      "y": 27,
      "z": 4,
      "name": "Fullmetal_Plant_Leaves_Crystal_Cyan"
    },
    {
      "x": -17,
      "y": 28,
      "z": 4,
      "name": "Fullmetal_Plant_Leaves_Crystal_Cyan"
    },
    {
      "x": -17,
      "y": 24,
      "z": 5,
      "name": "Fullmetal_Plant_Leaves_Crystal_Cyan"
    },
    {
      "x": -17,
      "y": 25,
      "z": 5,
      "name": "Fullmetal_Plant_Leaves_Crystal_Cyan"
    },
    {
      "x": -17,
      "y": 28,
      "z": 5,
      "name": "Fullmetal_Plant_Leaves_Crystal_Cyan"
    },
    {
      "x": -17,
      "y": 23,
      "z": 6,
      "name": "Fullmetal_Plant_Leaves_Crystal_Cyan"
    },
    {
      "x": -17,
      "y": 25,
      "z": 6,
      "name": "Fullmetal_Plant_Leaves_Crystal_Cyan"
    },
    {
      "x": -17,
      "y": 28,
      "z": 6,
      "name": "Fullmetal_Plant_Leaves_Crystal_Cyan"
    },
    {
      "x": -17,
      "y": 29,
      "z": 6,
      "name": "Fullmetal_Plant_Leaves_Crystal_Cyan"
    },
    {
      "x": -17,
      "y": 23,
      "z": 7,
      "name": "Fullmetal_Plant_Leaves_Crystal_Cyan"
    },
    {
      "x": -17,
      "y": 24,
      "z": 7,
      "name": "Fullmetal_Plant_Leaves_Crystal_Cyan"
    },
    {
      "x": -17,
      "y": 25,
      "z": 7,
      "name": "Fullmetal_Plant_Leaves_Crystal_Cyan"
    },
    {
      "x": -17,
      "y": 28,
      "z": 7,
      "name": "Fullmetal_Plant_Leaves_Crystal_Cyan"
    },
    {
      "x": -17,
      "y": 29,
      "z": 7,
      "name": "Fullmetal_Plant_Leaves_Crystal_Cyan"
    },
    {
      "x": -17,
      "y": 23,
      "z": 8,
      "name": "Fullmetal_Plant_Leaves_Crystal_Cyan"
    },
    {
      "x": -17,
      "y": 24,
      "z": 8,
      "name": "Fullmetal_Plant_Leaves_Crystal_Cyan"
    },
    {
      "x": -17,
      "y": 28,
      "z": 8,
      "name": "Fullmetal_Plant_Leaves_Crystal_Cyan"
    },
    {
      "x": -17,
      "y": 23,
      "z": 9,
      "name": "Fullmetal_Plant_Leaves_Crystal_Cyan"
    },
    {
      "x": -17,
      "y": 24,
      "z": 9,
      "name": "Fullmetal_Plant_Leaves_Crystal_Cyan"
    },
    {
      "x": -17,
      "y": 28,
      "z": 9,
      "name": "Fullmetal_Plant_Leaves_Crystal_Cyan"
    },
    {
      "x": -17,
      "y": 23,
      "z": 14,
      "name": "Fullmetal_Plant_Leaves_Crystal_Cyan"
    },
    {
      "x": -17,
      "y": 24,
      "z": 14,
      "name": "Fullmetal_Plant_Leaves_Crystal_Cyan"
    },
    {
      "x": -16,
      "y": 25,
      "z": -13,
      "name": "Fullmetal_Plant_Leaves_Crystal_Cyan"
    },
    {
      "x": -16,
      "y": 24,
      "z": -12,
      "name": "Fullmetal_Plant_Leaves_Crystal_Cyan"
    },
    {
      "x": -16,
      "y": 25,
      "z": -12,
      "name": "Fullmetal_Plant_Leaves_Crystal_Cyan"
    },
    {
      "x": -16,
      "y": 26,
      "z": -12,
      "name": "Fullmetal_Plant_Leaves_Crystal_Cyan"
    },
    {
      "x": -16,
      "y": 24,
      "z": -11,
      "name": "Fullmetal_Plant_Leaves_Crystal_Cyan"
    },
    {
      "x": -16,
      "y": 25,
      "z": -11,
      "name": "Fullmetal_Plant_Leaves_Crystal_Cyan"
    },
    {
      "x": -16,
      "y": 26,
      "z": -11,
      "name": "Fullmetal_Plant_Leaves_Crystal_Cyan"
    },
    {
      "x": -16,
      "y": 25,
      "z": -10,
      "name": "Fullmetal_Plant_Leaves_Crystal_Cyan"
    },
    {
      "x": -16,
      "y": 26,
      "z": -10,
      "name": "Fullmetal_Plant_Leaves_Crystal_Cyan"
    },
    {
      "x": -16,
      "y": 27,
      "z": -10,
      "name": "Fullmetal_Plant_Leaves_Crystal_Cyan"
    },
    {
      "x": -16,
      "y": 24,
      "z": -9,
      "name": "Wood_Crystal_Branch_Corner",
      "rotation": 3
    },
    {
      "x": -16,
      "y": 26,
      "z": -9,
      "name": "Fullmetal_Plant_Leaves_Crystal_Cyan"
    },
    {
      "x": -16,
      "y": 27,
      "z": -9,
      "name": "Fullmetal_Plant_Leaves_Crystal_Cyan"
    },
    {
      "x": -16,
      "y": 26,
      "z": -8,
      "name": "Fullmetal_Plant_Leaves_Crystal_Cyan"
    },
    {
      "x": -16,
      "y": 27,
      "z": -8,
      "name": "Fullmetal_Plant_Leaves_Crystal_Cyan"
    },
    {
      "x": -16,
      "y": 28,
      "z": -8,
      "name": "Fullmetal_Plant_Leaves_Crystal_Cyan"
    },
    {
      "x": -16,
      "y": 28,
      "z": -7,
      "name": "Fullmetal_Plant_Leaves_Crystal_Cyan"
    },
    {
      "x": -16,
      "y": 29,
      "z": -7,
      "name": "Fullmetal_Plant_Leaves_Crystal_Cyan"
    },
    {
      "x": -16,
      "y": 24,
      "z": -6,
      "name": "Wood_Crystal_Trunk_Full"
    },
    {
      "x": -16,
      "y": 25,
      "z": -6,
      "name": "Wood_Crystal_Trunk_Full"
    },
    {
      "x": -16,
      "y": 27,
      "z": -6,
      "name": "Fullmetal_Plant_Leaves_Crystal_Cyan"
    },
    {
      "x": -16,
      "y": 28,
      "z": -6,
      "name": "Fullmetal_Plant_Leaves_Crystal_Cyan"
    },
    {
      "x": -16,
      "y": 29,
      "z": -6,
      "name": "Fullmetal_Plant_Leaves_Crystal_Cyan"
    },
    {
      "x": -16,
      "y": 30,
      "z": -6,
      "name": "Fullmetal_Plant_Leaves_Crystal_Cyan"
    },
    {
      "x": -16,
      "y": 29,
      "z": -5,
      "name": "Fullmetal_Plant_Leaves_Crystal_Cyan"
    },
    {
      "x": -16,
      "y": 30,
      "z": -5,
      "name": "Fullmetal_Plant_Leaves_Crystal_Cyan"
    },
    {
      "x": -16,
      "y": 24,
      "z": -4,
      "name": "Plant_Fruit_Azure",
      "rotation": 8
    },
    {
      "x": -16,
      "y": 25,
      "z": -4,
      "name": "Fullmetal_Plant_Leaves_Crystal_Cyan"
    },
    {
      "x": -16,
      "y": 28,
      "z": -4,
      "name": "Fullmetal_Plant_Leaves_Crystal_Cyan"
    },
    {
      "x": -16,
      "y": 29,
      "z": -4,
      "name": "Fullmetal_Plant_Leaves_Crystal_Cyan"
    },
    {
      "x": -16,
      "y": 25,
      "z": -3,
      "name": "Wood_Crystal_Branch_Corner",
      "rotation": 1
    },
    {
      "x": -16,
      "y": 26,
      "z": -3,
      "name": "Fullmetal_Plant_Leaves_Crystal_Cyan"
    },
    {
      "x": -16,
      "y": 27,
      "z": -3,
      "name": "Fullmetal_Plant_Leaves_Crystal_Cyan"
    },
    {
      "x": -16,
      "y": 28,
      "z": -3,
      "name": "Fullmetal_Plant_Leaves_Crystal_Cyan"
    },
    {
      "x": -16,
      "y": 29,
      "z": -3,
      "name": "Fullmetal_Plant_Leaves_Crystal_Cyan"
    },
    {
      "x": -16,
      "y": 30,
      "z": -3,
      "name": "Fullmetal_Plant_Leaves_Crystal_Cyan"
    },
    {
      "x": -16,
      "y": 24,
      "z": -2,
      "name": "Fullmetal_Plant_Leaves_Crystal_Cyan"
    },
    {
      "x": -16,
      "y": 26,
      "z": -2,
      "name": "Fullmetal_Plant_Leaves_Crystal_Cyan"
    },
    {
      "x": -16,
      "y": 29,
      "z": -2,
      "name": "Fullmetal_Plant_Leaves_Crystal_Cyan"
    },
    {
      "x": -16,
      "y": 30,
      "z": -2,
      "name": "Fullmetal_Plant_Leaves_Crystal_Cyan"
    },
    {
      "x": -16,
      "y": 25,
      "z": -1,
      "name": "Fullmetal_Plant_Leaves_Crystal_Cyan"
    },
    {
      "x": -16,
      "y": 26,
      "z": -1,
      "name": "Fullmetal_Plant_Leaves_Crystal_Cyan"
    },
    {
      "x": -16,
      "y": 27,
      "z": -1,
      "name": "Fullmetal_Plant_Leaves_Crystal_Cyan"
    },
    {
      "x": -16,
      "y": 28,
      "z": -1,
      "name": "Fullmetal_Plant_Leaves_Crystal_Cyan"
    },
    {
      "x": -16,
      "y": 29,
      "z": -1,
      "name": "Fullmetal_Plant_Leaves_Crystal_Cyan"
    },
    {
      "x": -16,
      "y": 30,
      "z": -1,
      "name": "Fullmetal_Plant_Leaves_Crystal_Cyan"
    },
    {
      "x": -16,
      "y": 23,
      "z": 0,
      "name": "Fullmetal_Plant_Leaves_Crystal_Cyan"
    },
    {
      "x": -16,
      "y": 24,
      "z": 0,
      "name": "Fullmetal_Plant_Leaves_Crystal_Cyan"
    },
    {
      "x": -16,
      "y": 25,
      "z": 0,
      "name": "Fullmetal_Plant_Leaves_Crystal_Cyan"
    },
    {
      "x": -16,
      "y": 28,
      "z": 0,
      "name": "Fullmetal_Plant_Leaves_Crystal_Cyan"
    },
    {
      "x": -16,
      "y": 29,
      "z": 0,
      "name": "Fullmetal_Plant_Leaves_Crystal_Cyan"
    },
    {
      "x": -16,
      "y": 30,
      "z": 0,
      "name": "Fullmetal_Plant_Leaves_Crystal_Cyan"
    },
    {
      "x": -16,
      "y": 23,
      "z": 1,
      "name": "Fullmetal_Plant_Leaves_Crystal_Cyan"
    },
    {
      "x": -16,
      "y": 24,
      "z": 1,
      "name": "Fullmetal_Plant_Leaves_Crystal_Cyan"
    },
    {
      "x": -16,
      "y": 25,
      "z": 1,
      "name": "Fullmetal_Plant_Leaves_Crystal_Cyan"
    },
    {
      "x": -16,
      "y": 26,
      "z": 1,
      "name": "Fullmetal_Plant_Leaves_Crystal_Cyan"
    },
    {
      "x": -16,
      "y": 27,
      "z": 1,
      "name": "Fullmetal_Plant_Leaves_Crystal_Cyan"
    },
    {
      "x": -16,
      "y": 28,
      "z": 1,
      "name": "Fullmetal_Plant_Leaves_Crystal_Cyan"
    },
    {
      "x": -16,
      "y": 23,
      "z": 2,
      "name": "Fullmetal_Plant_Leaves_Crystal_Cyan"
    },
    {
      "x": -16,
      "y": 24,
      "z": 2,
      "name": "Fullmetal_Plant_Leaves_Crystal_Cyan"
    },
    {
      "x": -16,
      "y": 25,
      "z": 2,
      "name": "Fullmetal_Plant_Leaves_Crystal_Cyan"
    },
    {
      "x": -16,
      "y": 26,
      "z": 2,
      "name": "Fullmetal_Plant_Leaves_Crystal_Cyan"
    },
    {
      "x": -16,
      "y": 27,
      "z": 2,
      "name": "Fullmetal_Plant_Leaves_Crystal_Cyan"
    },
    {
      "x": -16,
      "y": 28,
      "z": 2,
      "name": "Fullmetal_Plant_Leaves_Crystal_Cyan"
    },
    {
      "x": -16,
      "y": 29,
      "z": 2,
      "name": "Fullmetal_Plant_Leaves_Crystal_Cyan"
    },
    {
      "x": -16,
      "y": 23,
      "z": 3,
      "name": "Fullmetal_Plant_Leaves_Crystal_Cyan"
    },
    {
      "x": -16,
      "y": 24,
      "z": 3,
      "name": "Fullmetal_Plant_Leaves_Crystal_Cyan"
    },
    {
      "x": -16,
      "y": 25,
      "z": 3,
      "name": "Fullmetal_Plant_Leaves_Crystal_Cyan"
    },
    {
      "x": -16,
      "y": 27,
      "z": 3,
      "name": "Fullmetal_Plant_Leaves_Crystal_Cyan"
    },
    {
      "x": -16,
      "y": 28,
      "z": 3,
      "name": "Fullmetal_Plant_Leaves_Crystal_Cyan"
    },
    {
      "x": -16,
      "y": 29,
      "z": 3,
      "name": "Fullmetal_Plant_Leaves_Crystal_Cyan"
    },
    {
      "x": -16,
      "y": 23,
      "z": 4,
      "name": "Fullmetal_Plant_Leaves_Crystal_Cyan"
    },
    {
      "x": -16,
      "y": 25,
      "z": 4,
      "name": "Fullmetal_Plant_Leaves_Crystal_Cyan"
    },
    {
      "x": -16,
      "y": 27,
      "z": 4,
      "name": "Fullmetal_Plant_Leaves_Crystal_Cyan"
    },
    {
      "x": -16,
      "y": 28,
      "z": 4,
      "name": "Fullmetal_Plant_Leaves_Crystal_Cyan"
    },
    {
      "x": -16,
      "y": 23,
      "z": 5,
      "name": "Fullmetal_Plant_Leaves_Crystal_Cyan"
    },
    {
      "x": -16,
      "y": 24,
      "z": 5,
      "name": "Fullmetal_Plant_Leaves_Crystal_Cyan"
    },
    {
      "x": -16,
      "y": 25,
      "z": 5,
      "name": "Fullmetal_Plant_Leaves_Crystal_Cyan"
    },
    {
      "x": -16,
      "y": 28,
      "z": 5,
      "name": "Fullmetal_Plant_Leaves_Crystal_Cyan"
    },
    {
      "x": -16,
      "y": 25,
      "z": 6,
      "name": "Fullmetal_Plant_Leaves_Crystal_Cyan"
    },
    {
      "x": -16,
      "y": 28,
      "z": 6,
      "name": "Fullmetal_Plant_Leaves_Crystal_Cyan"
    },
    {
      "x": -16,
      "y": 29,
      "z": 6,
      "name": "Fullmetal_Plant_Leaves_Crystal_Cyan"
    },
    {
      "x": -16,
      "y": 23,
      "z": 7,
      "name": "Fullmetal_Plant_Leaves_Crystal_Cyan"
    },
    {
      "x": -16,
      "y": 24,
      "z": 7,
      "name": "Fullmetal_Plant_Leaves_Crystal_Cyan"
    },
    {
      "x": -16,
      "y": 25,
      "z": 7,
      "name": "Fullmetal_Plant_Leaves_Crystal_Cyan"
    },
    {
      "x": -16,
      "y": 28,
      "z": 7,
      "name": "Fullmetal_Plant_Leaves_Crystal_Cyan"
    },
    {
      "x": -16,
      "y": 29,
      "z": 7,
      "name": "Fullmetal_Plant_Leaves_Crystal_Cyan"
    },
    {
      "x": -16,
      "y": 22,
      "z": 8,
      "name": "Fullmetal_Plant_Leaves_Crystal_Cyan"
    },
    {
      "x": -16,
      "y": 23,
      "z": 8,
      "name": "Fullmetal_Plant_Leaves_Crystal_Cyan"
    },
    {
      "x": -16,
      "y": 24,
      "z": 8,
      "name": "Fullmetal_Plant_Leaves_Crystal_Cyan"
    },
    {
      "x": -16,
      "y": 28,
      "z": 8,
      "name": "Fullmetal_Plant_Leaves_Crystal_Cyan"
    },
    {
      "x": -16,
      "y": 22,
      "z": 9,
      "name": "Fullmetal_Plant_Leaves_Crystal_Cyan"
    },
    {
      "x": -16,
      "y": 23,
      "z": 9,
      "name": "Fullmetal_Plant_Leaves_Crystal_Cyan"
    },
    {
      "x": -16,
      "y": 24,
      "z": 9,
      "name": "Fullmetal_Plant_Leaves_Crystal_Cyan"
    },
    {
      "x": -16,
      "y": 27,
      "z": 9,
      "name": "Fullmetal_Plant_Leaves_Crystal_Cyan"
    },
    {
      "x": -16,
      "y": 28,
      "z": 9,
      "name": "Fullmetal_Plant_Leaves_Crystal_Cyan"
    },
    {
      "x": -16,
      "y": 23,
      "z": 10,
      "name": "Fullmetal_Plant_Leaves_Crystal_Cyan"
    },
    {
      "x": -16,
      "y": 24,
      "z": 10,
      "name": "Fullmetal_Plant_Leaves_Crystal_Cyan"
    },
    {
      "x": -16,
      "y": 28,
      "z": 10,
      "name": "Fullmetal_Plant_Leaves_Crystal_Cyan"
    },
    {
      "x": -16,
      "y": 29,
      "z": 11,
      "name": "Fullmetal_Plant_Leaves_Crystal_Cyan"
    },
    {
      "x": -16,
      "y": 23,
      "z": 12,
      "name": "Fullmetal_Plant_Leaves_Crystal_Cyan"
    },
    {
      "x": -16,
      "y": 23,
      "z": 13,
      "name": "Fullmetal_Plant_Leaves_Crystal_Cyan"
    },
    {
      "x": -16,
      "y": 24,
      "z": 13,
      "name": "Fullmetal_Plant_Leaves_Crystal_Cyan"
    },
    {
      "x": -16,
      "y": 23,
      "z": 14,
      "name": "Fullmetal_Plant_Leaves_Crystal_Cyan"
    },
    {
      "x": -16,
      "y": 24,
      "z": 14,
      "name": "Fullmetal_Plant_Leaves_Crystal_Cyan"
    },
    {
      "x": -16,
      "y": 23,
      "z": 15,
      "name": "Fullmetal_Plant_Leaves_Crystal_Cyan"
    },
    {
      "x": -16,
      "y": 23,
      "z": 16,
      "name": "Fullmetal_Plant_Leaves_Crystal_Cyan"
    },
    {
      "x": -15,
      "y": 25,
      "z": -12,
      "name": "Fullmetal_Plant_Leaves_Crystal_Cyan"
    },
    {
      "x": -15,
      "y": 25,
      "z": -11,
      "name": "Fullmetal_Plant_Leaves_Crystal_Cyan"
    },
    {
      "x": -15,
      "y": 26,
      "z": -11,
      "name": "Fullmetal_Plant_Leaves_Crystal_Cyan"
    },
    {
      "x": -15,
      "y": 26,
      "z": -10,
      "name": "Fullmetal_Plant_Leaves_Crystal_Cyan"
    },
    {
      "x": -15,
      "y": 23,
      "z": -9,
      "name": "Wood_Crystal_Roots"
    },
    {
      "x": -15,
      "y": 24,
      "z": -9,
      "name": "Wood_Crystal_Trunk_Full"
    },
    {
      "x": -15,
      "y": 26,
      "z": -9,
      "name": "Fullmetal_Plant_Leaves_Crystal_Cyan"
    },
    {
      "x": -15,
      "y": 27,
      "z": -9,
      "name": "Fullmetal_Plant_Leaves_Crystal_Cyan"
    },
    {
      "x": -15,
      "y": 23,
      "z": -8,
      "name": "Wood_Crystal_Roots"
    },
    {
      "x": -15,
      "y": 24,
      "z": -8,
      "name": "Wood_Crystal_Trunk_Full"
    },
    {
      "x": -15,
      "y": 27,
      "z": -8,
      "name": "Fullmetal_Plant_Leaves_Crystal_Cyan"
    },
    {
      "x": -15,
      "y": 24,
      "z": -7,
      "name": "Wood_Crystal_Trunk_Full"
    },
    {
      "x": -15,
      "y": 28,
      "z": -7,
      "name": "Fullmetal_Plant_Leaves_Crystal_Cyan"
    },
    {
      "x": -15,
      "y": 24,
      "z": -6,
      "name": "Wood_Crystal_Trunk_Full"
    },
    {
      "x": -15,
      "y": 25,
      "z": -6,
      "name": "Wood_Crystal_Trunk_Full"
    },
    {
      "x": -15,
      "y": 29,
      "z": -6,
      "name": "Fullmetal_Plant_Leaves_Crystal_Cyan"
    },
    {
      "x": -15,
      "y": 24,
      "z": -5,
      "name": "Wood_Crystal_Trunk_Full"
    },
    {
      "x": -15,
      "y": 25,
      "z": -5,
      "name": "Wood_Crystal_Trunk_Full"
    },
    {
      "x": -15,
      "y": 28,
      "z": -5,
      "name": "Fullmetal_Plant_Leaves_Crystal_Cyan"
    },
    {
      "x": -15,
      "y": 29,
      "z": -5,
      "name": "Fullmetal_Plant_Leaves_Crystal_Cyan"
    },
    {
      "x": -15,
      "y": 30,
      "z": -5,
      "name": "Fullmetal_Plant_Leaves_Crystal_Cyan"
    },
    {
      "x": -15,
      "y": 25,
      "z": -4,
      "name": "Fullmetal_Plant_Leaves_Crystal_Cyan"
    },
    {
      "x": -15,
      "y": 28,
      "z": -4,
      "name": "Wood_Crystal_Trunk_Full"
    },
    {
      "x": -15,
      "y": 29,
      "z": -4,
      "name": "Fullmetal_Plant_Leaves_Crystal_Cyan"
    },
    {
      "x": -15,
      "y": 25,
      "z": -3,
      "name": "Fullmetal_Plant_Leaves_Crystal_Cyan"
    },
    {
      "x": -15,
      "y": 28,
      "z": -3,
      "name": "Wood_Crystal_Trunk_Full"
    },
    {
      "x": -15,
      "y": 29,
      "z": -3,
      "name": "Fullmetal_Plant_Leaves_Crystal_Cyan"
    },
    {
      "x": -15,
      "y": 30,
      "z": -3,
      "name": "Fullmetal_Plant_Leaves_Crystal_Cyan"
    },
    {
      "x": -15,
      "y": 26,
      "z": -2,
      "name": "Fullmetal_Plant_Leaves_Crystal_Cyan"
    },
    {
      "x": -15,
      "y": 29,
      "z": -2,
      "name": "Fullmetal_Plant_Leaves_Crystal_Cyan"
    },
    {
      "x": -15,
      "y": 24,
      "z": -1,
      "name": "Fullmetal_Plant_Leaves_Crystal_Cyan"
    },
    {
      "x": -15,
      "y": 25,
      "z": -1,
      "name": "Fullmetal_Plant_Leaves_Crystal_Cyan"
    },
    {
      "x": -15,
      "y": 26,
      "z": -1,
      "name": "Fullmetal_Plant_Leaves_Crystal_Cyan"
    },
    {
      "x": -15,
      "y": 28,
      "z": -1,
      "name": "Fullmetal_Plant_Leaves_Crystal_Cyan"
    },
    {
      "x": -15,
      "y": 29,
      "z": -1,
      "name": "Fullmetal_Plant_Leaves_Crystal_Cyan"
    },
    {
      "x": -15,
      "y": 30,
      "z": -1,
      "name": "Fullmetal_Plant_Leaves_Crystal_Cyan"
    },
    {
      "x": -15,
      "y": 23,
      "z": 0,
      "name": "Fullmetal_Plant_Leaves_Crystal_Cyan"
    },
    {
      "x": -15,
      "y": 24,
      "z": 0,
      "name": "Fullmetal_Plant_Leaves_Crystal_Cyan"
    },
    {
      "x": -15,
      "y": 25,
      "z": 0,
      "name": "Fullmetal_Plant_Leaves_Crystal_Cyan"
    },
    {
      "x": -15,
      "y": 26,
      "z": 0,
      "name": "Fullmetal_Plant_Leaves_Crystal_Cyan"
    },
    {
      "x": -15,
      "y": 28,
      "z": 0,
      "name": "Fullmetal_Plant_Leaves_Crystal_Cyan"
    },
    {
      "x": -15,
      "y": 23,
      "z": 1,
      "name": "Fullmetal_Plant_Leaves_Crystal_Cyan"
    },
    {
      "x": -15,
      "y": 24,
      "z": 1,
      "name": "Fullmetal_Plant_Leaves_Crystal_Cyan"
    },
    {
      "x": -15,
      "y": 25,
      "z": 1,
      "name": "Fullmetal_Plant_Leaves_Crystal_Cyan"
    },
    {
      "x": -15,
      "y": 26,
      "z": 1,
      "name": "Fullmetal_Plant_Leaves_Crystal_Cyan"
    },
    {
      "x": -15,
      "y": 27,
      "z": 1,
      "name": "Wood_Crystal_Trunk_Full"
    },
    {
      "x": -15,
      "y": 28,
      "z": 1,
      "name": "Fullmetal_Plant_Leaves_Crystal_Cyan"
    },
    {
      "x": -15,
      "y": 29,
      "z": 1,
      "name": "Fullmetal_Plant_Leaves_Crystal_Cyan"
    },
    {
      "x": -15,
      "y": 23,
      "z": 2,
      "name": "Fullmetal_Plant_Leaves_Crystal_Cyan"
    },
    {
      "x": -15,
      "y": 25,
      "z": 2,
      "name": "Fullmetal_Plant_Leaves_Crystal_Cyan"
    },
    {
      "x": -15,
      "y": 27,
      "z": 2,
      "name": "Fullmetal_Plant_Leaves_Crystal_Cyan"
    },
    {
      "x": -15,
      "y": 28,
      "z": 2,
      "name": "Fullmetal_Plant_Leaves_Crystal_Cyan"
    },
    {
      "x": -15,
      "y": 23,
      "z": 3,
      "name": "Fullmetal_Plant_Leaves_Crystal_Cyan"
    },
    {
      "x": -15,
      "y": 24,
      "z": 3,
      "name": "Fullmetal_Plant_Leaves_Crystal_Cyan"
    },
    {
      "x": -15,
      "y": 25,
      "z": 3,
      "name": "Fullmetal_Plant_Leaves_Crystal_Cyan"
    },
    {
      "x": -15,
      "y": 27,
      "z": 3,
      "name": "Fullmetal_Plant_Leaves_Crystal_Cyan"
    },
    {
      "x": -15,
      "y": 28,
      "z": 3,
      "name": "Fullmetal_Plant_Leaves_Crystal_Cyan"
    },
    {
      "x": -15,
      "y": 29,
      "z": 3,
      "name": "Fullmetal_Plant_Leaves_Crystal_Cyan"
    },
    {
      "x": -15,
      "y": 25,
      "z": 4,
      "name": "Fullmetal_Plant_Leaves_Crystal_Cyan"
    },
    {
      "x": -15,
      "y": 27,
      "z": 4,
      "name": "Fullmetal_Plant_Leaves_Crystal_Cyan"
    },
    {
      "x": -15,
      "y": 28,
      "z": 4,
      "name": "Fullmetal_Plant_Leaves_Crystal_Cyan"
    },
    {
      "x": -15,
      "y": 23,
      "z": 5,
      "name": "Fullmetal_Plant_Leaves_Crystal_Cyan"
    },
    {
      "x": -15,
      "y": 25,
      "z": 5,
      "name": "Fullmetal_Plant_Leaves_Crystal_Cyan"
    },
    {
      "x": -15,
      "y": 27,
      "z": 5,
      "name": "Fullmetal_Plant_Leaves_Crystal_Cyan"
    },
    {
      "x": -15,
      "y": 28,
      "z": 5,
      "name": "Fullmetal_Plant_Leaves_Crystal_Cyan"
    },
    {
      "x": -15,
      "y": 29,
      "z": 5,
      "name": "Fullmetal_Plant_Leaves_Crystal_Cyan"
    },
    {
      "x": -15,
      "y": 23,
      "z": 6,
      "name": "Wood_Crystal_Trunk_Full"
    },
    {
      "x": -15,
      "y": 25,
      "z": 6,
      "name": "Fullmetal_Plant_Leaves_Crystal_Cyan"
    },
    {
      "x": -15,
      "y": 28,
      "z": 6,
      "name": "Fullmetal_Plant_Leaves_Crystal_Cyan"
    },
    {
      "x": -15,
      "y": 29,
      "z": 6,
      "name": "Fullmetal_Plant_Leaves_Crystal_Cyan"
    },
    {
      "x": -15,
      "y": 22,
      "z": 7,
      "name": "Fullmetal_Plant_Leaves_Crystal_Cyan"
    },
    {
      "x": -15,
      "y": 23,
      "z": 7,
      "name": "Fullmetal_Plant_Leaves_Crystal_Cyan"
    },
    {
      "x": -15,
      "y": 25,
      "z": 7,
      "name": "Fullmetal_Plant_Leaves_Crystal_Cyan"
    },
    {
      "x": -15,
      "y": 28,
      "z": 7,
      "name": "Fullmetal_Plant_Leaves_Crystal_Cyan"
    },
    {
      "x": -15,
      "y": 22,
      "z": 8,
      "name": "Fullmetal_Plant_Leaves_Crystal_Cyan"
    },
    {
      "x": -15,
      "y": 23,
      "z": 8,
      "name": "Fullmetal_Plant_Leaves_Crystal_Cyan"
    },
    {
      "x": -15,
      "y": 28,
      "z": 8,
      "name": "Fullmetal_Plant_Leaves_Crystal_Cyan"
    },
    {
      "x": -15,
      "y": 29,
      "z": 8,
      "name": "Fullmetal_Plant_Leaves_Crystal_Cyan"
    },
    {
      "x": -15,
      "y": 22,
      "z": 9,
      "name": "Fullmetal_Plant_Leaves_Crystal_Cyan"
    },
    {
      "x": -15,
      "y": 23,
      "z": 9,
      "name": "Fullmetal_Plant_Leaves_Crystal_Cyan"
    },
    {
      "x": -15,
      "y": 24,
      "z": 9,
      "name": "Fullmetal_Plant_Leaves_Crystal_Cyan"
    },
    {
      "x": -15,
      "y": 28,
      "z": 9,
      "name": "Fullmetal_Plant_Leaves_Crystal_Cyan"
    },
    {
      "x": -15,
      "y": 29,
      "z": 9,
      "name": "Fullmetal_Plant_Leaves_Crystal_Cyan"
    },
    {
      "x": -15,
      "y": 22,
      "z": 10,
      "name": "Fullmetal_Plant_Leaves_Crystal_Cyan"
    },
    {
      "x": -15,
      "y": 23,
      "z": 10,
      "name": "Fullmetal_Plant_Leaves_Crystal_Cyan"
    },
    {
      "x": -15,
      "y": 29,
      "z": 10,
      "name": "Fullmetal_Plant_Leaves_Crystal_Cyan"
    },
    {
      "x": -15,
      "y": 23,
      "z": 11,
      "name": "Fullmetal_Plant_Leaves_Crystal_Cyan"
    },
    {
      "x": -15,
      "y": 29,
      "z": 11,
      "name": "Fullmetal_Plant_Leaves_Crystal_Cyan"
    },
    {
      "x": -15,
      "y": 30,
      "z": 11,
      "name": "Fullmetal_Plant_Leaves_Crystal_Cyan"
    },
    {
      "x": -15,
      "y": 22,
      "z": 12,
      "name": "Fullmetal_Plant_Leaves_Crystal_Cyan"
    },
    {
      "x": -15,
      "y": 23,
      "z": 12,
      "name": "Fullmetal_Plant_Leaves_Crystal_Cyan"
    },
    {
      "x": -15,
      "y": 24,
      "z": 12,
      "name": "Fullmetal_Plant_Leaves_Crystal_Cyan"
    },
    {
      "x": -15,
      "y": 29,
      "z": 12,
      "name": "Fullmetal_Plant_Leaves_Crystal_Cyan"
    },
    {
      "x": -15,
      "y": 22,
      "z": 13,
      "name": "Fullmetal_Plant_Leaves_Crystal_Cyan"
    },
    {
      "x": -15,
      "y": 23,
      "z": 13,
      "name": "Fullmetal_Plant_Leaves_Crystal_Cyan"
    },
    {
      "x": -15,
      "y": 24,
      "z": 13,
      "name": "Fullmetal_Plant_Leaves_Crystal_Cyan"
    },
    {
      "x": -15,
      "y": 29,
      "z": 13,
      "name": "Fullmetal_Plant_Leaves_Crystal_Cyan"
    },
    {
      "x": -15,
      "y": 22,
      "z": 14,
      "name": "Fullmetal_Plant_Leaves_Crystal_Cyan"
    },
    {
      "x": -15,
      "y": 23,
      "z": 14,
      "name": "Fullmetal_Plant_Leaves_Crystal_Cyan"
    },
    {
      "x": -15,
      "y": 24,
      "z": 14,
      "name": "Fullmetal_Plant_Leaves_Crystal_Cyan"
    },
    {
      "x": -15,
      "y": 21,
      "z": 15,
      "name": "Fullmetal_Plant_Leaves_Crystal_Cyan"
    },
    {
      "x": -15,
      "y": 22,
      "z": 15,
      "name": "Fullmetal_Plant_Leaves_Crystal_Cyan"
    },
    {
      "x": -15,
      "y": 23,
      "z": 15,
      "name": "Fullmetal_Plant_Leaves_Crystal_Cyan"
    },
    {
      "x": -15,
      "y": 24,
      "z": 16,
      "name": "Fullmetal_Plant_Leaves_Crystal_Cyan"
    },
    {
      "x": -15,
      "y": 24,
      "z": 17,
      "name": "Fullmetal_Plant_Leaves_Crystal_Cyan"
    },
    {
      "x": -15,
      "y": 24,
      "z": 18,
      "name": "Fullmetal_Plant_Leaves_Crystal_Cyan"
    },
    {
      "x": -14,
      "y": 25,
      "z": -11,
      "name": "Fullmetal_Plant_Leaves_Crystal_Cyan"
    },
    {
      "x": -14,
      "y": 24,
      "z": -10,
      "name": "Fullmetal_Plant_Leaves_Crystal_Cyan"
    },
    {
      "x": -14,
      "y": 26,
      "z": -10,
      "name": "Fullmetal_Plant_Leaves_Crystal_Cyan"
    },
    {
      "x": -14,
      "y": 23,
      "z": -9,
      "name": "Wood_Crystal_Roots"
    },
    {
      "x": -14,
      "y": 24,
      "z": -9,
      "name": "Wood_Crystal_Trunk_Full"
    },
    {
      "x": -14,
      "y": 26,
      "z": -9,
      "name": "Fullmetal_Plant_Leaves_Crystal_Cyan"
    },
    {
      "x": -14,
      "y": 27,
      "z": -8,
      "name": "Fullmetal_Plant_Leaves_Crystal_Cyan"
    },
    {
      "x": -14,
      "y": 28,
      "z": -8,
      "name": "Fullmetal_Plant_Leaves_Crystal_Cyan"
    },
    {
      "x": -14,
      "y": 26,
      "z": -7,
      "name": "Fullmetal_Plant_Leaves_Crystal_Cyan"
    },
    {
      "x": -14,
      "y": 27,
      "z": -7,
      "name": "Fullmetal_Plant_Leaves_Crystal_Cyan"
    },
    {
      "x": -14,
      "y": 28,
      "z": -7,
      "name": "Fullmetal_Plant_Leaves_Crystal_Cyan"
    },
    {
      "x": -14,
      "y": 28,
      "z": -6,
      "name": "Fullmetal_Plant_Leaves_Crystal_Cyan"
    },
    {
      "x": -14,
      "y": 29,
      "z": -6,
      "name": "Fullmetal_Plant_Leaves_Crystal_Cyan"
    },
    {
      "x": -14,
      "y": 24,
      "z": -5,
      "name": "Wood_Crystal_Trunk_Full"
    },
    {
      "x": -14,
      "y": 25,
      "z": -5,
      "name": "Wood_Crystal_Trunk_Full"
    },
    {
      "x": -14,
      "y": 28,
      "z": -5,
      "name": "Fullmetal_Plant_Leaves_Crystal_Cyan"
    },
    {
      "x": -14,
      "y": 29,
      "z": -5,
      "name": "Fullmetal_Plant_Leaves_Crystal_Cyan"
    },
    {
      "x": -14,
      "y": 30,
      "z": -5,
      "name": "Fullmetal_Plant_Leaves_Crystal_Cyan"
    },
    {
      "x": -14,
      "y": 29,
      "z": -4,
      "name": "Fullmetal_Plant_Leaves_Crystal_Cyan"
    },
    {
      "x": -14,
      "y": 30,
      "z": -4,
      "name": "Fullmetal_Plant_Leaves_Crystal_Cyan"
    },
    {
      "x": -14,
      "y": 25,
      "z": -3,
      "name": "Fullmetal_Plant_Leaves_Crystal_Cyan"
    },
    {
      "x": -14,
      "y": 28,
      "z": -3,
      "name": "Wood_Crystal_Trunk_Full"
    },
    {
      "x": -14,
      "y": 29,
      "z": -3,
      "name": "Fullmetal_Plant_Leaves_Crystal_Cyan"
    },
    {
      "x": -14,
      "y": 30,
      "z": -3,
      "name": "Fullmetal_Plant_Leaves_Crystal_Cyan"
    },
    {
      "x": -14,
      "y": 25,
      "z": -2,
      "name": "Fullmetal_Plant_Leaves_Crystal_Cyan"
    },
    {
      "x": -14,
      "y": 28,
      "z": -2,
      "name": "Wood_Crystal_Trunk_Full"
    },
    {
      "x": -14,
      "y": 29,
      "z": -2,
      "name": "Fullmetal_Plant_Leaves_Crystal_Cyan"
    },
    {
      "x": -14,
      "y": 30,
      "z": -2,
      "name": "Fullmetal_Plant_Leaves_Crystal_Cyan"
    },
    {
      "x": -14,
      "y": 24,
      "z": -1,
      "name": "Fullmetal_Plant_Leaves_Crystal_Cyan"
    },
    {
      "x": -14,
      "y": 25,
      "z": -1,
      "name": "Fullmetal_Plant_Leaves_Crystal_Cyan"
    },
    {
      "x": -14,
      "y": 29,
      "z": -1,
      "name": "Fullmetal_Plant_Leaves_Crystal_Cyan"
    },
    {
      "x": -14,
      "y": 30,
      "z": -1,
      "name": "Fullmetal_Plant_Leaves_Crystal_Cyan"
    },
    {
      "x": -14,
      "y": 23,
      "z": 0,
      "name": "Fullmetal_Plant_Leaves_Crystal_Cyan"
    },
    {
      "x": -14,
      "y": 24,
      "z": 0,
      "name": "Fullmetal_Plant_Leaves_Crystal_Cyan"
    },
    {
      "x": -14,
      "y": 25,
      "z": 0,
      "name": "Fullmetal_Plant_Leaves_Crystal_Cyan"
    },
    {
      "x": -14,
      "y": 26,
      "z": 0,
      "name": "Fullmetal_Plant_Leaves_Crystal_Cyan"
    },
    {
      "x": -14,
      "y": 28,
      "z": 0,
      "name": "Fullmetal_Plant_Leaves_Crystal_Cyan"
    },
    {
      "x": -14,
      "y": 30,
      "z": 0,
      "name": "Fullmetal_Plant_Leaves_Crystal_Cyan"
    },
    {
      "x": -14,
      "y": 23,
      "z": 1,
      "name": "Fullmetal_Plant_Leaves_Crystal_Cyan"
    },
    {
      "x": -14,
      "y": 24,
      "z": 1,
      "name": "Fullmetal_Plant_Leaves_Crystal_Cyan"
    },
    {
      "x": -14,
      "y": 25,
      "z": 1,
      "name": "Fullmetal_Plant_Leaves_Crystal_Cyan"
    },
    {
      "x": -14,
      "y": 26,
      "z": 1,
      "name": "Fullmetal_Plant_Leaves_Crystal_Cyan"
    },
    {
      "x": -14,
      "y": 27,
      "z": 1,
      "name": "Wood_Crystal_Trunk_Full"
    },
    {
      "x": -14,
      "y": 28,
      "z": 1,
      "name": "Fullmetal_Plant_Leaves_Crystal_Cyan"
    },
    {
      "x": -14,
      "y": 30,
      "z": 1,
      "name": "Fullmetal_Plant_Leaves_Crystal_Cyan"
    },
    {
      "x": -14,
      "y": 22,
      "z": 2,
      "name": "Fullmetal_Plant_Leaves_Crystal_Cyan"
    },
    {
      "x": -14,
      "y": 23,
      "z": 2,
      "name": "Fullmetal_Plant_Leaves_Crystal_Cyan"
    },
    {
      "x": -14,
      "y": 24,
      "z": 2,
      "name": "Fullmetal_Plant_Leaves_Crystal_Cyan"
    },
    {
      "x": -14,
      "y": 25,
      "z": 2,
      "name": "Fullmetal_Plant_Leaves_Crystal_Cyan"
    },
    {
      "x": -14,
      "y": 27,
      "z": 2,
      "name": "Wood_Crystal_Trunk_Full"
    },
    {
      "x": -14,
      "y": 28,
      "z": 2,
      "name": "Fullmetal_Plant_Leaves_Crystal_Cyan"
    },
    {
      "x": -14,
      "y": 22,
      "z": 3,
      "name": "Fullmetal_Plant_Leaves_Crystal_Cyan"
    },
    {
      "x": -14,
      "y": 23,
      "z": 3,
      "name": "Fullmetal_Plant_Leaves_Crystal_Cyan"
    },
    {
      "x": -14,
      "y": 25,
      "z": 3,
      "name": "Fullmetal_Plant_Leaves_Crystal_Cyan"
    },
    {
      "x": -14,
      "y": 27,
      "z": 3,
      "name": "Fullmetal_Plant_Leaves_Crystal_Cyan"
    },
    {
      "x": -14,
      "y": 28,
      "z": 3,
      "name": "Fullmetal_Plant_Leaves_Crystal_Cyan"
    },
    {
      "x": -14,
      "y": 29,
      "z": 3,
      "name": "Fullmetal_Plant_Leaves_Crystal_Cyan"
    },
    {
      "x": -14,
      "y": 23,
      "z": 4,
      "name": "Fullmetal_Plant_Leaves_Crystal_Cyan"
    },
    {
      "x": -14,
      "y": 25,
      "z": 4,
      "name": "Fullmetal_Plant_Leaves_Crystal_Cyan"
    },
    {
      "x": -14,
      "y": 27,
      "z": 4,
      "name": "Fullmetal_Plant_Leaves_Crystal_Cyan"
    },
    {
      "x": -14,
      "y": 28,
      "z": 4,
      "name": "Fullmetal_Plant_Leaves_Crystal_Cyan"
    },
    {
      "x": -14,
      "y": 23,
      "z": 5,
      "name": "Fullmetal_Plant_Leaves_Crystal_Cyan"
    },
    {
      "x": -14,
      "y": 25,
      "z": 5,
      "name": "Fullmetal_Plant_Leaves_Crystal_Cyan"
    },
    {
      "x": -14,
      "y": 27,
      "z": 5,
      "name": "Fullmetal_Plant_Leaves_Crystal_Cyan"
    },
    {
      "x": -14,
      "y": 28,
      "z": 5,
      "name": "Fullmetal_Plant_Leaves_Crystal_Cyan"
    },
    {
      "x": -14,
      "y": 22,
      "z": 6,
      "name": "Wood_Crystal_Roots"
    },
    {
      "x": -14,
      "y": 23,
      "z": 6,
      "name": "Wood_Crystal_Trunk_Full"
    },
    {
      "x": -14,
      "y": 27,
      "z": 6,
      "name": "Wood_Crystal_Trunk_Full"
    },
    {
      "x": -14,
      "y": 28,
      "z": 6,
      "name": "Fullmetal_Plant_Leaves_Crystal_Cyan"
    },
    {
      "x": -14,
      "y": 22,
      "z": 7,
      "name": "Fullmetal_Plant_Leaves_Crystal_Cyan"
    },
    {
      "x": -14,
      "y": 23,
      "z": 7,
      "name": "Fullmetal_Plant_Leaves_Crystal_Cyan"
    },
    {
      "x": -14,
      "y": 25,
      "z": 7,
      "name": "Fullmetal_Plant_Leaves_Crystal_Cyan"
    },
    {
      "x": -14,
      "y": 28,
      "z": 7,
      "name": "Fullmetal_Plant_Leaves_Crystal_Cyan"
    },
    {
      "x": -14,
      "y": 29,
      "z": 7,
      "name": "Fullmetal_Plant_Leaves_Crystal_Cyan"
    },
    {
      "x": -14,
      "y": 30,
      "z": 7,
      "name": "Fullmetal_Plant_Leaves_Crystal_Cyan"
    },
    {
      "x": -14,
      "y": 23,
      "z": 8,
      "name": "Fullmetal_Plant_Leaves_Crystal_Cyan"
    },
    {
      "x": -14,
      "y": 24,
      "z": 8,
      "name": "Fullmetal_Plant_Leaves_Crystal_Cyan"
    },
    {
      "x": -14,
      "y": 28,
      "z": 8,
      "name": "Fullmetal_Plant_Leaves_Crystal_Cyan"
    },
    {
      "x": -14,
      "y": 29,
      "z": 8,
      "name": "Fullmetal_Plant_Leaves_Crystal_Cyan"
    },
    {
      "x": -14,
      "y": 30,
      "z": 8,
      "name": "Fullmetal_Plant_Leaves_Crystal_Cyan"
    },
    {
      "x": -14,
      "y": 23,
      "z": 9,
      "name": "Fullmetal_Plant_Leaves_Crystal_Cyan"
    },
    {
      "x": -14,
      "y": 24,
      "z": 9,
      "name": "Fullmetal_Plant_Leaves_Crystal_Cyan"
    },
    {
      "x": -14,
      "y": 28,
      "z": 9,
      "name": "Fullmetal_Plant_Leaves_Crystal_Cyan"
    },
    {
      "x": -14,
      "y": 29,
      "z": 9,
      "name": "Fullmetal_Plant_Leaves_Crystal_Cyan"
    },
    {
      "x": -14,
      "y": 30,
      "z": 9,
      "name": "Fullmetal_Plant_Leaves_Crystal_Cyan"
    },
    {
      "x": -14,
      "y": 23,
      "z": 10,
      "name": "Fullmetal_Plant_Leaves_Crystal_Cyan"
    },
    {
      "x": -14,
      "y": 24,
      "z": 10,
      "name": "Fullmetal_Plant_Leaves_Crystal_Cyan"
    },
    {
      "x": -14,
      "y": 28,
      "z": 10,
      "name": "Fullmetal_Plant_Leaves_Crystal_Cyan"
    },
    {
      "x": -14,
      "y": 29,
      "z": 10,
      "name": "Fullmetal_Plant_Leaves_Crystal_Cyan"
    },
    {
      "x": -14,
      "y": 30,
      "z": 10,
      "name": "Fullmetal_Plant_Leaves_Crystal_Cyan"
    },
    {
      "x": -14,
      "y": 22,
      "z": 11,
      "name": "Plant_Fruit_Azure",
      "rotation": 8
    },
    {
      "x": -14,
      "y": 23,
      "z": 11,
      "name": "Fullmetal_Plant_Leaves_Crystal_Cyan"
    },
    {
      "x": -14,
      "y": 24,
      "z": 11,
      "name": "Fullmetal_Plant_Leaves_Crystal_Cyan"
    },
    {
      "x": -14,
      "y": 29,
      "z": 11,
      "name": "Fullmetal_Plant_Leaves_Crystal_Cyan"
    },
    {
      "x": -14,
      "y": 30,
      "z": 11,
      "name": "Fullmetal_Plant_Leaves_Crystal_Cyan"
    },
    {
      "x": -14,
      "y": 22,
      "z": 12,
      "name": "Fullmetal_Plant_Leaves_Crystal_Cyan"
    },
    {
      "x": -14,
      "y": 23,
      "z": 12,
      "name": "Fullmetal_Plant_Leaves_Crystal_Cyan"
    },
    {
      "x": -14,
      "y": 24,
      "z": 12,
      "name": "Fullmetal_Plant_Leaves_Crystal_Cyan"
    },
    {
      "x": -14,
      "y": 29,
      "z": 12,
      "name": "Fullmetal_Plant_Leaves_Crystal_Cyan"
    },
    {
      "x": -14,
      "y": 30,
      "z": 12,
      "name": "Fullmetal_Plant_Leaves_Crystal_Cyan"
    },
    {
      "x": -14,
      "y": 22,
      "z": 13,
      "name": "Fullmetal_Plant_Leaves_Crystal_Cyan"
    },
    {
      "x": -14,
      "y": 23,
      "z": 13,
      "name": "Fullmetal_Plant_Leaves_Crystal_Cyan"
    },
    {
      "x": -14,
      "y": 24,
      "z": 13,
      "name": "Fullmetal_Plant_Leaves_Crystal_Cyan"
    },
    {
      "x": -14,
      "y": 29,
      "z": 13,
      "name": "Fullmetal_Plant_Leaves_Crystal_Cyan"
    },
    {
      "x": -14,
      "y": 22,
      "z": 14,
      "name": "Fullmetal_Plant_Leaves_Crystal_Cyan"
    },
    {
      "x": -14,
      "y": 23,
      "z": 14,
      "name": "Fullmetal_Plant_Leaves_Crystal_Cyan"
    },
    {
      "x": -14,
      "y": 24,
      "z": 14,
      "name": "Fullmetal_Plant_Leaves_Crystal_Cyan"
    },
    {
      "x": -14,
      "y": 22,
      "z": 15,
      "name": "Fullmetal_Plant_Leaves_Crystal_Cyan"
    },
    {
      "x": -14,
      "y": 23,
      "z": 15,
      "name": "Fullmetal_Plant_Leaves_Crystal_Cyan"
    },
    {
      "x": -14,
      "y": 24,
      "z": 15,
      "name": "Fullmetal_Plant_Leaves_Crystal_Cyan"
    },
    {
      "x": -14,
      "y": 25,
      "z": 15,
      "name": "Fullmetal_Plant_Leaves_Crystal_Cyan"
    },
    {
      "x": -14,
      "y": 22,
      "z": 16,
      "name": "Fullmetal_Plant_Leaves_Crystal_Cyan"
    },
    {
      "x": -14,
      "y": 23,
      "z": 16,
      "name": "Fullmetal_Plant_Leaves_Crystal_Cyan"
    },
    {
      "x": -14,
      "y": 24,
      "z": 16,
      "name": "Fullmetal_Plant_Leaves_Crystal_Cyan"
    },
    {
      "x": -14,
      "y": 25,
      "z": 16,
      "name": "Fullmetal_Plant_Leaves_Crystal_Cyan"
    },
    {
      "x": -14,
      "y": 24,
      "z": 17,
      "name": "Fullmetal_Plant_Leaves_Crystal_Cyan"
    },
    {
      "x": -14,
      "y": 25,
      "z": 17,
      "name": "Fullmetal_Plant_Leaves_Crystal_Cyan"
    },
    {
      "x": -14,
      "y": 24,
      "z": 18,
      "name": "Fullmetal_Plant_Leaves_Crystal_Cyan"
    },
    {
      "x": -13,
      "y": 24,
      "z": -10,
      "name": "Fullmetal_Plant_Leaves_Crystal_Cyan"
    },
    {
      "x": -13,
      "y": 26,
      "z": -9,
      "name": "Fullmetal_Plant_Leaves_Crystal_Cyan"
    },
    {
      "x": -13,
      "y": 28,
      "z": -8,
      "name": "Fullmetal_Plant_Leaves_Crystal_Cyan"
    },
    {
      "x": -13,
      "y": 28,
      "z": -7,
      "name": "Fullmetal_Plant_Leaves_Crystal_Cyan"
    },
    {
      "x": -13,
      "y": 28,
      "z": -6,
      "name": "Fullmetal_Plant_Leaves_Crystal_Cyan"
    },
    {
      "x": -13,
      "y": 29,
      "z": -6,
      "name": "Fullmetal_Plant_Leaves_Crystal_Cyan"
    },
    {
      "x": -13,
      "y": 23,
      "z": -5,
      "name": "Wood_Crystal_Trunk_Full"
    },
    {
      "x": -13,
      "y": 24,
      "z": -5,
      "name": "Wood_Crystal_Trunk_Full"
    },
    {
      "x": -13,
      "y": 28,
      "z": -5,
      "name": "Fullmetal_Plant_Leaves_Crystal_Cyan"
    },
    {
      "x": -13,
      "y": 29,
      "z": -5,
      "name": "Fullmetal_Plant_Leaves_Crystal_Cyan"
    },
    {
      "x": -13,
      "y": 30,
      "z": -5,
      "name": "Fullmetal_Plant_Leaves_Crystal_Cyan"
    },
    {
      "x": -13,
      "y": 24,
      "z": -4,
      "name": "Wood_Crystal_Trunk_Full"
    },
    {
      "x": -13,
      "y": 29,
      "z": -4,
      "name": "Fullmetal_Plant_Leaves_Crystal_Cyan"
    },
    {
      "x": -13,
      "y": 30,
      "z": -4,
      "name": "Fullmetal_Plant_Leaves_Crystal_Cyan"
    },
    {
      "x": -13,
      "y": 29,
      "z": -3,
      "name": "Fullmetal_Plant_Leaves_Crystal_Cyan"
    },
    {
      "x": -13,
      "y": 30,
      "z": -3,
      "name": "Fullmetal_Plant_Leaves_Crystal_Cyan"
    },
    {
      "x": -13,
      "y": 25,
      "z": -2,
      "name": "Fullmetal_Plant_Leaves_Crystal_Cyan"
    },
    {
      "x": -13,
      "y": 28,
      "z": -2,
      "name": "Wood_Crystal_Trunk_Full"
    },
    {
      "x": -13,
      "y": 29,
      "z": -2,
      "name": "Fullmetal_Plant_Leaves_Crystal_Cyan"
    },
    {
      "x": -13,
      "y": 30,
      "z": -2,
      "name": "Fullmetal_Plant_Leaves_Crystal_Cyan"
    },
    {
      "x": -13,
      "y": 23,
      "z": -1,
      "name": "Plant_Fruit_Azure",
      "rotation": 8
    },
    {
      "x": -13,
      "y": 24,
      "z": -1,
      "name": "Fullmetal_Plant_Leaves_Crystal_Cyan"
    },
    {
      "x": -13,
      "y": 27,
      "z": -1,
      "name": "Wood_Crystal_Trunk_Full"
    },
    {
      "x": -13,
      "y": 28,
      "z": -1,
      "name": "Wood_Crystal_Trunk_Full"
    },
    {
      "x": -13,
      "y": 30,
      "z": -1,
      "name": "Fullmetal_Plant_Leaves_Crystal_Cyan"
    },
    {
      "x": -13,
      "y": 23,
      "z": 0,
      "name": "Fullmetal_Plant_Leaves_Crystal_Cyan"
    },
    {
      "x": -13,
      "y": 24,
      "z": 0,
      "name": "Fullmetal_Plant_Leaves_Crystal_Cyan"
    },
    {
      "x": -13,
      "y": 25,
      "z": 0,
      "name": "Fullmetal_Plant_Leaves_Crystal_Cyan"
    },
    {
      "x": -13,
      "y": 27,
      "z": 0,
      "name": "Wood_Crystal_Trunk_Full"
    },
    {
      "x": -13,
      "y": 30,
      "z": 0,
      "name": "Fullmetal_Plant_Leaves_Crystal_Cyan"
    },
    {
      "x": -13,
      "y": 22,
      "z": 1,
      "name": "Fullmetal_Plant_Leaves_Crystal_Cyan"
    },
    {
      "x": -13,
      "y": 23,
      "z": 1,
      "name": "Fullmetal_Plant_Leaves_Crystal_Cyan"
    },
    {
      "x": -13,
      "y": 24,
      "z": 1,
      "name": "Fullmetal_Plant_Leaves_Crystal_Cyan"
    },
    {
      "x": -13,
      "y": 25,
      "z": 1,
      "name": "Fullmetal_Plant_Leaves_Crystal_Cyan"
    },
    {
      "x": -13,
      "y": 26,
      "z": 1,
      "name": "Fullmetal_Plant_Leaves_Crystal_Cyan"
    },
    {
      "x": -13,
      "y": 27,
      "z": 1,
      "name": "Wood_Crystal_Trunk_Full"
    },
    {
      "x": -13,
      "y": 23,
      "z": 2,
      "name": "Fullmetal_Plant_Leaves_Crystal_Cyan"
    },
    {
      "x": -13,
      "y": 25,
      "z": 2,
      "name": "Fullmetal_Plant_Leaves_Crystal_Cyan"
    },
    {
      "x": -13,
      "y": 26,
      "z": 2,
      "name": "Fullmetal_Plant_Leaves_Crystal_Cyan"
    },
    {
      "x": -13,
      "y": 27,
      "z": 2,
      "name": "Fullmetal_Plant_Leaves_Crystal_Cyan"
    },
    {
      "x": -13,
      "y": 28,
      "z": 2,
      "name": "Fullmetal_Plant_Leaves_Crystal_Cyan"
    },
    {
      "x": -13,
      "y": 23,
      "z": 3,
      "name": "Fullmetal_Plant_Leaves_Crystal_Cyan"
    },
    {
      "x": -13,
      "y": 25,
      "z": 3,
      "name": "Fullmetal_Plant_Leaves_Crystal_Cyan"
    },
    {
      "x": -13,
      "y": 26,
      "z": 3,
      "name": "Fullmetal_Plant_Leaves_Crystal_Cyan"
    },
    {
      "x": -13,
      "y": 27,
      "z": 3,
      "name": "Fullmetal_Plant_Leaves_Crystal_Cyan"
    },
    {
      "x": -13,
      "y": 28,
      "z": 3,
      "name": "Fullmetal_Plant_Leaves_Crystal_Cyan"
    },
    {
      "x": -13,
      "y": 22,
      "z": 4,
      "name": "Wood_Crystal_Branch_Corner",
      "rotation": 3
    },
    {
      "x": -13,
      "y": 23,
      "z": 4,
      "name": "Fullmetal_Plant_Leaves_Crystal_Cyan"
    },
    {
      "x": -13,
      "y": 25,
      "z": 4,
      "name": "Fullmetal_Plant_Leaves_Crystal_Cyan"
    },
    {
      "x": -13,
      "y": 27,
      "z": 4,
      "name": "Fullmetal_Plant_Leaves_Crystal_Cyan"
    },
    {
      "x": -13,
      "y": 28,
      "z": 4,
      "name": "Fullmetal_Plant_Leaves_Crystal_Cyan"
    },
    {
      "x": -13,
      "y": 27,
      "z": 5,
      "name": "Fullmetal_Plant_Leaves_Crystal_Cyan"
    },
    {
      "x": -13,
      "y": 28,
      "z": 5,
      "name": "Fullmetal_Plant_Leaves_Crystal_Cyan"
    },
    {
      "x": -13,
      "y": 22,
      "z": 6,
      "name": "Wood_Crystal_Roots"
    },
    {
      "x": -13,
      "y": 23,
      "z": 6,
      "name": "Wood_Crystal_Trunk_Full"
    },
    {
      "x": -13,
      "y": 27,
      "z": 6,
      "name": "Wood_Crystal_Trunk_Full"
    },
    {
      "x": -13,
      "y": 28,
      "z": 6,
      "name": "Fullmetal_Plant_Leaves_Crystal_Cyan"
    },
    {
      "x": -13,
      "y": 28,
      "z": 7,
      "name": "Fullmetal_Plant_Leaves_Crystal_Cyan"
    },
    {
      "x": -13,
      "y": 29,
      "z": 7,
      "name": "Fullmetal_Plant_Leaves_Crystal_Cyan"
    },
    {
      "x": -13,
      "y": 22,
      "z": 8,
      "name": "Fullmetal_Plant_Leaves_Crystal_Cyan"
    },
    {
      "x": -13,
      "y": 24,
      "z": 8,
      "name": "Fullmetal_Plant_Leaves_Crystal_Cyan"
    },
    {
      "x": -13,
      "y": 29,
      "z": 8,
      "name": "Fullmetal_Plant_Leaves_Crystal_Cyan"
    },
    {
      "x": -13,
      "y": 30,
      "z": 8,
      "name": "Fullmetal_Plant_Leaves_Crystal_Cyan"
    },
    {
      "x": -13,
      "y": 22,
      "z": 9,
      "name": "Fullmetal_Plant_Leaves_Crystal_Cyan"
    },
    {
      "x": -13,
      "y": 24,
      "z": 9,
      "name": "Fullmetal_Plant_Leaves_Crystal_Cyan"
    },
    {
      "x": -13,
      "y": 29,
      "z": 9,
      "name": "Fullmetal_Plant_Leaves_Crystal_Cyan"
    },
    {
      "x": -13,
      "y": 30,
      "z": 9,
      "name": "Fullmetal_Plant_Leaves_Crystal_Cyan"
    },
    {
      "x": -13,
      "y": 22,
      "z": 10,
      "name": "Fullmetal_Plant_Leaves_Crystal_Cyan"
    },
    {
      "x": -13,
      "y": 24,
      "z": 10,
      "name": "Fullmetal_Plant_Leaves_Crystal_Cyan"
    },
    {
      "x": -13,
      "y": 28,
      "z": 10,
      "name": "Wood_Crystal_Trunk_Full"
    },
    {
      "x": -13,
      "y": 29,
      "z": 10,
      "name": "Fullmetal_Plant_Leaves_Crystal_Cyan"
    },
    {
      "x": -13,
      "y": 24,
      "z": 11,
      "name": "Fullmetal_Plant_Leaves_Crystal_Cyan"
    },
    {
      "x": -13,
      "y": 28,
      "z": 11,
      "name": "Fullmetal_Plant_Leaves_Crystal_Cyan"
    },
    {
      "x": -13,
      "y": 29,
      "z": 11,
      "name": "Fullmetal_Plant_Leaves_Crystal_Cyan"
    },
    {
      "x": -13,
      "y": 23,
      "z": 12,
      "name": "Fullmetal_Plant_Leaves_Crystal_Cyan"
    },
    {
      "x": -13,
      "y": 24,
      "z": 12,
      "name": "Fullmetal_Plant_Leaves_Crystal_Cyan"
    },
    {
      "x": -13,
      "y": 25,
      "z": 12,
      "name": "Fullmetal_Plant_Leaves_Crystal_Cyan"
    },
    {
      "x": -13,
      "y": 29,
      "z": 12,
      "name": "Fullmetal_Plant_Leaves_Crystal_Cyan"
    },
    {
      "x": -13,
      "y": 30,
      "z": 12,
      "name": "Fullmetal_Plant_Leaves_Crystal_Cyan"
    },
    {
      "x": -13,
      "y": 23,
      "z": 13,
      "name": "Fullmetal_Plant_Leaves_Crystal_Cyan"
    },
    {
      "x": -13,
      "y": 24,
      "z": 13,
      "name": "Fullmetal_Plant_Leaves_Crystal_Cyan"
    },
    {
      "x": -13,
      "y": 25,
      "z": 13,
      "name": "Fullmetal_Plant_Leaves_Crystal_Cyan"
    },
    {
      "x": -13,
      "y": 29,
      "z": 13,
      "name": "Fullmetal_Plant_Leaves_Crystal_Cyan"
    },
    {
      "x": -13,
      "y": 22,
      "z": 14,
      "name": "Fullmetal_Plant_Leaves_Crystal_Cyan"
    },
    {
      "x": -13,
      "y": 23,
      "z": 14,
      "name": "Fullmetal_Plant_Leaves_Crystal_Cyan"
    },
    {
      "x": -13,
      "y": 24,
      "z": 14,
      "name": "Fullmetal_Plant_Leaves_Crystal_Cyan"
    },
    {
      "x": -13,
      "y": 25,
      "z": 14,
      "name": "Fullmetal_Plant_Leaves_Crystal_Cyan"
    },
    {
      "x": -13,
      "y": 26,
      "z": 14,
      "name": "Fullmetal_Plant_Leaves_Crystal_Cyan"
    },
    {
      "x": -13,
      "y": 27,
      "z": 14,
      "name": "Fullmetal_Plant_Leaves_Crystal_Cyan"
    },
    {
      "x": -13,
      "y": 28,
      "z": 14,
      "name": "Fullmetal_Plant_Leaves_Crystal_Cyan"
    },
    {
      "x": -13,
      "y": 29,
      "z": 14,
      "name": "Fullmetal_Plant_Leaves_Crystal_Cyan"
    },
    {
      "x": -13,
      "y": 22,
      "z": 15,
      "name": "Fullmetal_Plant_Leaves_Crystal_Cyan"
    },
    {
      "x": -13,
      "y": 23,
      "z": 15,
      "name": "Fullmetal_Plant_Leaves_Crystal_Cyan"
    },
    {
      "x": -13,
      "y": 24,
      "z": 15,
      "name": "Wood_Crystal_Trunk_Full"
    },
    {
      "x": -13,
      "y": 25,
      "z": 15,
      "name": "Fullmetal_Plant_Leaves_Crystal_Cyan"
    },
    {
      "x": -13,
      "y": 23,
      "z": 16,
      "name": "Fullmetal_Plant_Leaves_Crystal_Cyan"
    },
    {
      "x": -13,
      "y": 25,
      "z": 16,
      "name": "Fullmetal_Plant_Leaves_Crystal_Cyan"
    },
    {
      "x": -13,
      "y": 24,
      "z": 17,
      "name": "Wood_Crystal_Branch_Corner",
      "rotation": 3
    },
    {
      "x": -13,
      "y": 25,
      "z": 17,
      "name": "Fullmetal_Plant_Leaves_Crystal_Cyan"
    },
    {
      "x": -13,
      "y": 24,
      "z": 18,
      "name": "Fullmetal_Plant_Leaves_Crystal_Cyan"
    },
    {
      "x": -13,
      "y": 25,
      "z": 18,
      "name": "Fullmetal_Plant_Leaves_Crystal_Cyan"
    },
    {
      "x": -13,
      "y": 24,
      "z": 19,
      "name": "Fullmetal_Plant_Leaves_Crystal_Cyan"
    },
    {
      "x": -12,
      "y": 24,
      "z": -12,
      "name": "Fullmetal_Plant_Leaves_Crystal_Cyan"
    },
    {
      "x": -12,
      "y": 24,
      "z": -11,
      "name": "Fullmetal_Plant_Leaves_Crystal_Cyan"
    },
    {
      "x": -12,
      "y": 24,
      "z": -10,
      "name": "Fullmetal_Plant_Leaves_Crystal_Cyan"
    },
    {
      "x": -12,
      "y": 28,
      "z": -8,
      "name": "Fullmetal_Plant_Leaves_Crystal_Cyan"
    },
    {
      "x": -12,
      "y": 29,
      "z": -8,
      "name": "Fullmetal_Plant_Leaves_Crystal_Cyan"
    },
    {
      "x": -12,
      "y": 28,
      "z": -7,
      "name": "Fullmetal_Plant_Leaves_Crystal_Cyan"
    },
    {
      "x": -12,
      "y": 29,
      "z": -7,
      "name": "Fullmetal_Plant_Leaves_Crystal_Cyan"
    },
    {
      "x": -12,
      "y": 28,
      "z": -6,
      "name": "Fullmetal_Plant_Leaves_Crystal_Cyan"
    },
    {
      "x": -12,
      "y": 28,
      "z": -5,
      "name": "Fullmetal_Plant_Leaves_Crystal_Cyan"
    },
    {
      "x": -12,
      "y": 29,
      "z": -5,
      "name": "Fullmetal_Plant_Leaves_Crystal_Cyan"
    },
    {
      "x": -12,
      "y": 30,
      "z": -5,
      "name": "Fullmetal_Plant_Leaves_Crystal_Cyan"
    },
    {
      "x": -12,
      "y": 23,
      "z": -4,
      "name": "Wood_Crystal_Trunk_Full"
    },
    {
      "x": -12,
      "y": 24,
      "z": -4,
      "name": "Wood_Crystal_Trunk_Full"
    },
    {
      "x": -12,
      "y": 28,
      "z": -4,
      "name": "Fullmetal_Plant_Leaves_Crystal_Cyan"
    },
    {
      "x": -12,
      "y": 29,
      "z": -4,
      "name": "Fullmetal_Plant_Leaves_Crystal_Cyan"
    },
    {
      "x": -12,
      "y": 29,
      "z": -3,
      "name": "Fullmetal_Plant_Leaves_Crystal_Cyan"
    },
    {
      "x": -12,
      "y": 30,
      "z": -3,
      "name": "Fullmetal_Plant_Leaves_Crystal_Cyan"
    },
    {
      "x": -12,
      "y": 30,
      "z": -2,
      "name": "Fullmetal_Plant_Leaves_Crystal_Cyan"
    },
    {
      "x": -12,
      "y": 24,
      "z": -1,
      "name": "Wood_Crystal_Trunk_Full"
    },
    {
      "x": -12,
      "y": 27,
      "z": -1,
      "name": "Wood_Crystal_Trunk_Full",
      "rotation": 5
    },
    {
      "x": -12,
      "y": 28,
      "z": -1,
      "name": "Wood_Crystal_Trunk_Full"
    },
    {
      "x": -12,
      "y": 30,
      "z": -1,
      "name": "Fullmetal_Plant_Leaves_Crystal_Cyan"
    },
    {
      "x": -12,
      "y": 23,
      "z": 0,
      "name": "Fullmetal_Plant_Leaves_Crystal_Cyan"
    },
    {
      "x": -12,
      "y": 25,
      "z": 0,
      "name": "Fullmetal_Plant_Leaves_Crystal_Cyan"
    },
    {
      "x": -12,
      "y": 23,
      "z": 1,
      "name": "Fullmetal_Plant_Leaves_Crystal_Cyan"
    },
    {
      "x": -12,
      "y": 25,
      "z": 1,
      "name": "Fullmetal_Plant_Leaves_Crystal_Cyan"
    },
    {
      "x": -12,
      "y": 26,
      "z": 1,
      "name": "Fullmetal_Plant_Leaves_Crystal_Cyan"
    },
    {
      "x": -12,
      "y": 27,
      "z": 1,
      "name": "Fullmetal_Plant_Leaves_Crystal_Cyan"
    },
    {
      "x": -12,
      "y": 23,
      "z": 2,
      "name": "Fullmetal_Plant_Leaves_Crystal_Cyan"
    },
    {
      "x": -12,
      "y": 25,
      "z": 2,
      "name": "Fullmetal_Plant_Leaves_Crystal_Cyan"
    },
    {
      "x": -12,
      "y": 26,
      "z": 2,
      "name": "Fullmetal_Plant_Leaves_Crystal_Cyan"
    },
    {
      "x": -12,
      "y": 27,
      "z": 2,
      "name": "Fullmetal_Plant_Leaves_Crystal_Cyan"
    },
    {
      "x": -12,
      "y": 23,
      "z": 3,
      "name": "Fullmetal_Plant_Leaves_Crystal_Cyan"
    },
    {
      "x": -12,
      "y": 25,
      "z": 3,
      "name": "Fullmetal_Plant_Leaves_Crystal_Cyan"
    },
    {
      "x": -12,
      "y": 27,
      "z": 3,
      "name": "Fullmetal_Plant_Leaves_Crystal_Cyan"
    },
    {
      "x": -12,
      "y": 28,
      "z": 3,
      "name": "Fullmetal_Plant_Leaves_Crystal_Cyan"
    },
    {
      "x": -12,
      "y": 22,
      "z": 4,
      "name": "Wood_Crystal_Trunk_Full"
    },
    {
      "x": -12,
      "y": 25,
      "z": 4,
      "name": "Fullmetal_Plant_Leaves_Crystal_Cyan"
    },
    {
      "x": -12,
      "y": 27,
      "z": 4,
      "name": "Fullmetal_Plant_Leaves_Crystal_Cyan"
    },
    {
      "x": -12,
      "y": 15,
      "z": 5,
      "name": "Fullmetal_Plant_Leaves_Crystal_Cyan"
    },
    {
      "x": -12,
      "y": 27,
      "z": 5,
      "name": "Fullmetal_Plant_Leaves_Crystal_Cyan"
    },
    {
      "x": -12,
      "y": 30,
      "z": 5,
      "name": "Fullmetal_Plant_Leaves_Crystal_Cyan"
    },
    {
      "x": -12,
      "y": 15,
      "z": 6,
      "name": "Fullmetal_Plant_Leaves_Crystal_Cyan"
    },
    {
      "x": -12,
      "y": 21,
      "z": 6,
      "name": "Wood_Crystal_Roots"
    },
    {
      "x": -12,
      "y": 22,
      "z": 6,
      "name": "Wood_Crystal_Trunk_Full"
    },
    {
      "x": -12,
      "y": 23,
      "z": 6,
      "name": "Wood_Crystal_Trunk_Full"
    },
    {
      "x": -12,
      "y": 27,
      "z": 6,
      "name": "Wood_Crystal_Trunk_Full"
    },
    {
      "x": -12,
      "y": 30,
      "z": 6,
      "name": "Fullmetal_Plant_Leaves_Crystal_Cyan"
    },
    {
      "x": -12,
      "y": 15,
      "z": 7,
      "name": "Fullmetal_Plant_Leaves_Crystal_Cyan"
    },
    {
      "x": -12,
      "y": 23,
      "z": 7,
      "name": "Wood_Crystal_Trunk_Full"
    },
    {
      "x": -12,
      "y": 29,
      "z": 7,
      "name": "Fullmetal_Plant_Leaves_Crystal_Cyan"
    },
    {
      "x": -12,
      "y": 30,
      "z": 7,
      "name": "Fullmetal_Plant_Leaves_Crystal_Cyan"
    },
    {
      "x": -12,
      "y": 24,
      "z": 8,
      "name": "Fullmetal_Plant_Leaves_Crystal_Cyan"
    },
    {
      "x": -12,
      "y": 29,
      "z": 8,
      "name": "Fullmetal_Plant_Leaves_Crystal_Cyan"
    },
    {
      "x": -12,
      "y": 30,
      "z": 8,
      "name": "Fullmetal_Plant_Leaves_Crystal_Cyan"
    },
    {
      "x": -12,
      "y": 24,
      "z": 9,
      "name": "Fullmetal_Plant_Leaves_Crystal_Cyan"
    },
    {
      "x": -12,
      "y": 28,
      "z": 9,
      "name": "Wood_Crystal_Trunk_Full"
    },
    {
      "x": -12,
      "y": 29,
      "z": 9,
      "name": "Fullmetal_Plant_Leaves_Crystal_Cyan"
    },
    {
      "x": -12,
      "y": 30,
      "z": 9,
      "name": "Fullmetal_Plant_Leaves_Crystal_Cyan"
    },
    {
      "x": -12,
      "y": 22,
      "z": 10,
      "name": "Wood_Crystal_Trunk_Full"
    },
    {
      "x": -12,
      "y": 24,
      "z": 10,
      "name": "Fullmetal_Plant_Leaves_Crystal_Cyan"
    },
    {
      "x": -12,
      "y": 28,
      "z": 10,
      "name": "Wood_Crystal_Trunk_Full"
    },
    {
      "x": -12,
      "y": 29,
      "z": 10,
      "name": "Fullmetal_Plant_Leaves_Crystal_Cyan"
    },
    {
      "x": -12,
      "y": 30,
      "z": 10,
      "name": "Fullmetal_Plant_Leaves_Crystal_Cyan"
    },
    {
      "x": -12,
      "y": 22,
      "z": 11,
      "name": "Wood_Crystal_Trunk_Full"
    },
    {
      "x": -12,
      "y": 24,
      "z": 11,
      "name": "Fullmetal_Plant_Leaves_Crystal_Cyan"
    },
    {
      "x": -12,
      "y": 25,
      "z": 11,
      "name": "Fullmetal_Plant_Leaves_Crystal_Cyan"
    },
    {
      "x": -12,
      "y": 28,
      "z": 11,
      "name": "Fullmetal_Plant_Leaves_Crystal_Cyan"
    },
    {
      "x": -12,
      "y": 29,
      "z": 11,
      "name": "Fullmetal_Plant_Leaves_Crystal_Cyan"
    },
    {
      "x": -12,
      "y": 30,
      "z": 11,
      "name": "Fullmetal_Plant_Leaves_Crystal_Cyan"
    },
    {
      "x": -12,
      "y": 22,
      "z": 12,
      "name": "Wood_Crystal_Branch_Long",
      "rotation": 4
    },
    {
      "x": -12,
      "y": 24,
      "z": 12,
      "name": "Fullmetal_Plant_Leaves_Crystal_Cyan"
    },
    {
      "x": -12,
      "y": 25,
      "z": 12,
      "name": "Fullmetal_Plant_Leaves_Crystal_Cyan"
    },
    {
      "x": -12,
      "y": 29,
      "z": 12,
      "name": "Fullmetal_Plant_Leaves_Crystal_Cyan"
    },
    {
      "x": -12,
      "y": 30,
      "z": 12,
      "name": "Fullmetal_Plant_Leaves_Crystal_Cyan"
    },
    {
      "x": -12,
      "y": 22,
      "z": 13,
      "name": "Wood_Crystal_Branch_Long",
      "rotation": 4
    },
    {
      "x": -12,
      "y": 23,
      "z": 13,
      "name": "Fullmetal_Plant_Leaves_Crystal_Cyan"
    },
    {
      "x": -12,
      "y": 24,
      "z": 13,
      "name": "Fullmetal_Plant_Leaves_Crystal_Cyan"
    },
    {
      "x": -12,
      "y": 25,
      "z": 13,
      "name": "Fullmetal_Plant_Leaves_Crystal_Cyan"
    },
    {
      "x": -12,
      "y": 26,
      "z": 13,
      "name": "Fullmetal_Plant_Leaves_Crystal_Cyan"
    },
    {
      "x": -12,
      "y": 28,
      "z": 13,
      "name": "Fullmetal_Plant_Leaves_Crystal_Cyan"
    },
    {
      "x": -12,
      "y": 29,
      "z": 13,
      "name": "Fullmetal_Plant_Leaves_Crystal_Cyan"
    },
    {
      "x": -12,
      "y": 30,
      "z": 13,
      "name": "Fullmetal_Plant_Leaves_Crystal_Cyan"
    },
    {
      "x": -12,
      "y": 22,
      "z": 14,
      "name": "Wood_Crystal_Branch_Corner"
    },
    {
      "x": -12,
      "y": 23,
      "z": 14,
      "name": "Fullmetal_Plant_Leaves_Crystal_Cyan"
    },
    {
      "x": -12,
      "y": 24,
      "z": 14,
      "name": "Fullmetal_Plant_Leaves_Crystal_Cyan"
    },
    {
      "x": -12,
      "y": 25,
      "z": 14,
      "name": "Fullmetal_Plant_Leaves_Crystal_Cyan"
    },
    {
      "x": -12,
      "y": 26,
      "z": 14,
      "name": "Fullmetal_Plant_Leaves_Crystal_Cyan"
    },
    {
      "x": -12,
      "y": 29,
      "z": 14,
      "name": "Fullmetal_Plant_Leaves_Crystal_Cyan"
    },
    {
      "x": -12,
      "y": 23,
      "z": 15,
      "name": "Fullmetal_Plant_Leaves_Crystal_Cyan"
    },
    {
      "x": -12,
      "y": 24,
      "z": 15,
      "name": "Wood_Crystal_Trunk_Full"
    },
    {
      "x": -12,
      "y": 25,
      "z": 15,
      "name": "Fullmetal_Plant_Leaves_Crystal_Cyan"
    },
    {
      "x": -12,
      "y": 26,
      "z": 15,
      "name": "Fullmetal_Plant_Leaves_Crystal_Cyan"
    },
    {
      "x": -12,
      "y": 25,
      "z": 16,
      "name": "Fullmetal_Plant_Leaves_Crystal_Cyan"
    },
    {
      "x": -12,
      "y": 24,
      "z": 17,
      "name": "Wood_Crystal_Branch_Long",
      "rotation": 5
    },
    {
      "x": -12,
      "y": 25,
      "z": 17,
      "name": "Fullmetal_Plant_Leaves_Crystal_Cyan"
    },
    {
      "x": -12,
      "y": 23,
      "z": 18,
      "name": "Fullmetal_Plant_Leaves_Crystal_Cyan"
    },
    {
      "x": -12,
      "y": 24,
      "z": 18,
      "name": "Fullmetal_Plant_Leaves_Crystal_Cyan"
    },
    {
      "x": -12,
      "y": 25,
      "z": 18,
      "name": "Fullmetal_Plant_Leaves_Crystal_Cyan"
    },
    {
      "x": -12,
      "y": 24,
      "z": 19,
      "name": "Fullmetal_Plant_Leaves_Crystal_Cyan"
    },
    {
      "x": -12,
      "y": 24,
      "z": 20,
      "name": "Fullmetal_Plant_Leaves_Crystal_Cyan"
    },
    {
      "x": -11,
      "y": 24,
      "z": -11,
      "name": "Fullmetal_Plant_Leaves_Crystal_Cyan"
    },
    {
      "x": -11,
      "y": 28,
      "z": -8,
      "name": "Fullmetal_Plant_Leaves_Crystal_Cyan"
    },
    {
      "x": -11,
      "y": 29,
      "z": -8,
      "name": "Fullmetal_Plant_Leaves_Crystal_Cyan"
    },
    {
      "x": -11,
      "y": 28,
      "z": -7,
      "name": "Fullmetal_Plant_Leaves_Crystal_Cyan"
    },
    {
      "x": -11,
      "y": 29,
      "z": -7,
      "name": "Fullmetal_Plant_Leaves_Crystal_Cyan"
    },
    {
      "x": -11,
      "y": 28,
      "z": -6,
      "name": "Fullmetal_Plant_Leaves_Crystal_Cyan"
    },
    {
      "x": -11,
      "y": 29,
      "z": -6,
      "name": "Fullmetal_Plant_Leaves_Crystal_Cyan"
    },
    {
      "x": -11,
      "y": 27,
      "z": -5,
      "name": "Wood_Crystal_Trunk_Full"
    },
    {
      "x": -11,
      "y": 28,
      "z": -5,
      "name": "Fullmetal_Plant_Leaves_Crystal_Cyan"
    },
    {
      "x": -11,
      "y": 23,
      "z": -4,
      "name": "Wood_Crystal_Trunk_Full"
    },
    {
      "x": -11,
      "y": 24,
      "z": -4,
      "name": "Wood_Crystal_Trunk_Full"
    },
    {
      "x": -11,
      "y": 27,
      "z": -4,
      "name": "Wood_Crystal_Trunk_Full"
    },
    {
      "x": -11,
      "y": 28,
      "z": -4,
      "name": "Fullmetal_Plant_Leaves_Crystal_Cyan"
    },
    {
      "x": -11,
      "y": 23,
      "z": -3,
      "name": "Wood_Crystal_Trunk_Full",
      "rotation": 4
    },
    {
      "x": -11,
      "y": 24,
      "z": -3,
      "name": "Wood_Crystal_Trunk_Full"
    },
    {
      "x": -11,
      "y": 27,
      "z": -3,
      "name": "Wood_Crystal_Trunk_Full"
    },
    {
      "x": -11,
      "y": 24,
      "z": -2,
      "name": "Wood_Crystal_Trunk_Full"
    },
    {
      "x": -11,
      "y": 27,
      "z": -2,
      "name": "Wood_Crystal_Trunk_Full"
    },
    {
      "x": -11,
      "y": 30,
      "z": -2,
      "name": "Fullmetal_Plant_Leaves_Crystal_Cyan"
    },
    {
      "x": -11,
      "y": 24,
      "z": -1,
      "name": "Wood_Crystal_Trunk_Full"
    },
    {
      "x": -11,
      "y": 27,
      "z": -1,
      "name": "Wood_Crystal_Trunk_Full"
    },
    {
      "x": -11,
      "y": 28,
      "z": -1,
      "name": "Wood_Crystal_Trunk_Full"
    },
    {
      "x": -11,
      "y": 23,
      "z": 0,
      "name": "Fullmetal_Plant_Leaves_Crystal_Cyan"
    },
    {
      "x": -11,
      "y": 24,
      "z": 0,
      "name": "Fullmetal_Plant_Leaves_Crystal_Cyan"
    },
    {
      "x": -11,
      "y": 26,
      "z": 0,
      "name": "Wood_Crystal_Trunk_Full"
    },
    {
      "x": -11,
      "y": 27,
      "z": 0,
      "name": "Wood_Crystal_Trunk_Full"
    },
    {
      "x": -11,
      "y": 23,
      "z": 1,
      "name": "Fullmetal_Plant_Leaves_Crystal_Cyan"
    },
    {
      "x": -11,
      "y": 24,
      "z": 1,
      "name": "Fullmetal_Plant_Leaves_Crystal_Cyan"
    },
    {
      "x": -11,
      "y": 25,
      "z": 1,
      "name": "Fullmetal_Plant_Leaves_Crystal_Cyan"
    },
    {
      "x": -11,
      "y": 26,
      "z": 1,
      "name": "Fullmetal_Plant_Leaves_Crystal_Cyan"
    },
    {
      "x": -11,
      "y": 14,
      "z": 2,
      "name": "Fullmetal_Plant_Leaves_Crystal_Cyan"
    },
    {
      "x": -11,
      "y": 23,
      "z": 2,
      "name": "Fullmetal_Plant_Leaves_Crystal_Cyan"
    },
    {
      "x": -11,
      "y": 24,
      "z": 2,
      "name": "Fullmetal_Plant_Leaves_Crystal_Cyan"
    },
    {
      "x": -11,
      "y": 25,
      "z": 2,
      "name": "Fullmetal_Plant_Leaves_Crystal_Cyan"
    },
    {
      "x": -11,
      "y": 26,
      "z": 2,
      "name": "Fullmetal_Plant_Leaves_Crystal_Cyan"
    },
    {
      "x": -11,
      "y": 27,
      "z": 2,
      "name": "Fullmetal_Plant_Leaves_Crystal_Cyan"
    },
    {
      "x": -11,
      "y": 14,
      "z": 3,
      "name": "Fullmetal_Plant_Leaves_Crystal_Cyan"
    },
    {
      "x": -11,
      "y": 15,
      "z": 3,
      "name": "Fullmetal_Plant_Leaves_Crystal_Cyan"
    },
    {
      "x": -11,
      "y": 23,
      "z": 3,
      "name": "Fullmetal_Plant_Leaves_Crystal_Cyan"
    },
    {
      "x": -11,
      "y": 24,
      "z": 3,
      "name": "Fullmetal_Plant_Leaves_Crystal_Cyan"
    },
    {
      "x": -11,
      "y": 25,
      "z": 3,
      "name": "Fullmetal_Plant_Leaves_Crystal_Cyan"
    },
    {
      "x": -11,
      "y": 26,
      "z": 3,
      "name": "Fullmetal_Plant_Leaves_Crystal_Cyan"
    },
    {
      "x": -11,
      "y": 27,
      "z": 3,
      "name": "Fullmetal_Plant_Leaves_Crystal_Cyan"
    },
    {
      "x": -11,
      "y": 15,
      "z": 4,
      "name": "Fullmetal_Plant_Leaves_Crystal_Cyan"
    },
    {
      "x": -11,
      "y": 22,
      "z": 4,
      "name": "Wood_Crystal_Trunk_Full"
    },
    {
      "x": -11,
      "y": 25,
      "z": 4,
      "name": "Fullmetal_Plant_Leaves_Crystal_Cyan"
    },
    {
      "x": -11,
      "y": 26,
      "z": 4,
      "name": "Fullmetal_Plant_Leaves_Crystal_Cyan"
    },
    {
      "x": -11,
      "y": 27,
      "z": 4,
      "name": "Fullmetal_Plant_Leaves_Crystal_Cyan"
    },
    {
      "x": -11,
      "y": 15,
      "z": 5,
      "name": "Fullmetal_Plant_Leaves_Crystal_Cyan"
    },
    {
      "x": -11,
      "y": 22,
      "z": 5,
      "name": "Wood_Crystal_Trunk_Full"
    },
    {
      "x": -11,
      "y": 25,
      "z": 5,
      "name": "Fullmetal_Plant_Leaves_Crystal_Cyan"
    },
    {
      "x": -11,
      "y": 14,
      "z": 6,
      "name": "Fullmetal_Plant_Leaves_Crystal_Cyan"
    },
    {
      "x": -11,
      "y": 15,
      "z": 6,
      "name": "Fullmetal_Plant_Leaves_Crystal_Cyan"
    },
    {
      "x": -11,
      "y": 16,
      "z": 6,
      "name": "Fullmetal_Plant_Leaves_Crystal_Cyan"
    },
    {
      "x": -11,
      "y": 22,
      "z": 6,
      "name": "Wood_Crystal_Trunk_Full"
    },
    {
      "x": -11,
      "y": 27,
      "z": 6,
      "name": "Wood_Crystal_Trunk_Full"
    },
    {
      "x": -11,
      "y": 30,
      "z": 6,
      "name": "Fullmetal_Plant_Leaves_Crystal_Cyan"
    },
    {
      "x": -11,
      "y": 15,
      "z": 7,
      "name": "Fullmetal_Plant_Leaves_Crystal_Cyan"
    },
    {
      "x": -11,
      "y": 22,
      "z": 7,
      "name": "Fullmetal_Plant_Leaves_Crystal_Cyan"
    },
    {
      "x": -11,
      "y": 24,
      "z": 7,
      "name": "Fullmetal_Plant_Leaves_Crystal_Cyan"
    },
    {
      "x": -11,
      "y": 30,
      "z": 7,
      "name": "Fullmetal_Plant_Leaves_Crystal_Cyan"
    },
    {
      "x": -11,
      "y": 14,
      "z": 8,
      "name": "Fullmetal_Plant_Leaves_Crystal_Cyan"
    },
    {
      "x": -11,
      "y": 22,
      "z": 8,
      "name": "Fullmetal_Plant_Leaves_Crystal_Cyan"
    },
    {
      "x": -11,
      "y": 28,
      "z": 8,
      "name": "Wood_Crystal_Trunk_Full"
    },
    {
      "x": -11,
      "y": 29,
      "z": 8,
      "name": "Fullmetal_Plant_Leaves_Crystal_Cyan"
    },
    {
      "x": -11,
      "y": 30,
      "z": 8,
      "name": "Fullmetal_Plant_Leaves_Crystal_Cyan"
    },
    {
      "x": -11,
      "y": 15,
      "z": 9,
      "name": "Fullmetal_Plant_Leaves_Crystal_Cyan"
    },
    {
      "x": -11,
      "y": 24,
      "z": 9,
      "name": "Fullmetal_Plant_Leaves_Crystal_Cyan"
    },
    {
      "x": -11,
      "y": 28,
      "z": 9,
      "name": "Wood_Crystal_Trunk_Full"
    },
    {
      "x": -11,
      "y": 29,
      "z": 9,
      "name": "Fullmetal_Plant_Leaves_Crystal_Cyan"
    },
    {
      "x": -11,
      "y": 30,
      "z": 9,
      "name": "Fullmetal_Plant_Leaves_Crystal_Cyan"
    },
    {
      "x": -11,
      "y": 29,
      "z": 10,
      "name": "Fullmetal_Plant_Leaves_Crystal_Cyan"
    },
    {
      "x": -11,
      "y": 22,
      "z": 11,
      "name": "Wood_Crystal_Trunk_Full"
    },
    {
      "x": -11,
      "y": 25,
      "z": 11,
      "name": "Fullmetal_Plant_Leaves_Crystal_Cyan"
    },
    {
      "x": -11,
      "y": 29,
      "z": 11,
