{
  "version": 8,
  "blockIdVersion": 11,
  "anchorX": 0,
  "anchorY": 0,
  "anchorZ": 0,
  "blocks": [
    {
      "x": -21,
      "y": 32,
      "z": 4,
      "name": "Fullmetal_Plant_Leaves_Crystal_Cyan"
    },
    {
      "x": -21,
      "y": 33,
      "z": 4,
      "name": "Fullmetal_Plant_Leaves_Crystal_Cyan"
    },
    {
      "x": -21,
      "y": 32,
      "z": 5,
      "name": "Fullmetal_Plant_Leaves_Crystal_Cyan"
    },
    {
      "x": -21,
      "y": 33,
      "z": 5,
      "name": "Fullmetal_Plant_Leaves_Crystal_Cyan"
    },
    {
      "x": -21,
      "y": 33,
      "z": 6,
      "name": "Fullmetal_Plant_Leaves_Crystal_Cyan"
    },
    {
      "x": -20,
      "y": 32,
      "z": 3,
      "name": "Fullmetal_Plant_Leaves_Crystal_Cyan"
    },
    {
      "x": -20,
      "y": 33,
      "z": 3,
      "name": "Fullmetal_Plant_Leaves_Crystal_Cyan"
    },
    {
      "x": -20,
      "y": 32,
      "z": 4,
      "name": "Fullmetal_Plant_Leaves_Crystal_Cyan"
    },
    {
      "x": -20,
      "y": 33,
      "z": 4,
      "name": "Fullmetal_Plant_Leaves_Crystal_Cyan"
    },
    {
      "x": -20,
      "y": 34,
      "z": 4,
      "name": "Fullmetal_Plant_Leaves_Crystal_Cyan"
    },
    {
      "x": -20,
      "y": 32,
      "z": 5,
      "name": "Fullmetal_Plant_Leaves_Crystal_Cyan"
    },
    {
      "x": -20,
      "y": 33,
      "z": 5,
      "name": "Fullmetal_Plant_Leaves_Crystal_Cyan"
    },
    {
      "x": -20,
      "y": 34,
      "z": 5,
      "name": "Fullmetal_Plant_Leaves_Crystal_Cyan"
    },
    {
      "x": -20,
      "y": 32,
      "z": 6,
      "name": "Fullmetal_Plant_Leaves_Crystal_Cyan"
    },
    {
      "x": -20,
      "y": 33,
      "z": 6,
      "name": "Fullmetal_Plant_Leaves_Crystal_Cyan"
    },
    {
      "x": -20,
      "y": 34,
      "z": 6,
      "name": "Fullmetal_Plant_Leaves_Crystal_Cyan"
    },
    {
      "x": -20,
      "y": 33,
      "z": 7,
      "name": "Fullmetal_Plant_Leaves_Crystal_Cyan"
    },
    {
      "x": -19,
      "y": 32,
      "z": 0,
      "name": "Fullmetal_Plant_Leaves_Crystal_Cyan"
    },
    {
      "x": -19,
      "y": 33,
      "z": 0,
      "name": "Fullmetal_Plant_Leaves_Crystal_Cyan"
    },
    {
      "x": -19,
      "y": 32,
      "z": 1,
      "name": "Fullmetal_Plant_Leaves_Crystal_Cyan"
    },
    {
      "x": -19,
      "y": 33,
      "z": 1,
      "name": "Fullmetal_Plant_Leaves_Crystal_Cyan"
    },
    {
      "x": -19,
      "y": 32,
      "z": 2,
      "name": "Fullmetal_Plant_Leaves_Crystal_Cyan"
    },
    {
      "x": -19,
      "y": 33,
      "z": 2,
      "name": "Fullmetal_Plant_Leaves_Crystal_Cyan"
    },
    {
      "x": -19,
      "y": 33,
      "z": 3,
      "name": "Fullmetal_Plant_Leaves_Crystal_Cyan"
    },
    {
      "x": -19,
      "y": 31,
      "z": 4,
      "name": "Plant_Fruit_Azure",
      "rotation": 8
    },
    {
      "x": -19,
      "y": 32,
      "z": 4,
      "name": "Fullmetal_Plant_Leaves_Crystal_Cyan"
    },
    {
      "x": -19,
      "y": 33,
      "z": 4,
      "name": "Fullmetal_Plant_Leaves_Crystal_Cyan"
    },
    {
      "x": -19,
      "y": 34,
      "z": 4,
      "name": "Fullmetal_Plant_Leaves_Crystal_Cyan"
    },
    {
      "x": -19,
      "y": 35,
      "z": 4,
      "name": "Fullmetal_Plant_Leaves_Crystal_Cyan"
    },
    {
      "x": -19,
      "y": 32,
      "z": 5,
      "name": "Fullmetal_Plant_Leaves_Crystal_Cyan"
    },
    {
      "x": -19,
      "y": 33,
      "z": 5,
      "name": "Fullmetal_Plant_Leaves_Crystal_Cyan"
    },
    {
      "x": -19,
      "y": 34,
      "z": 5,
      "name": "Fullmetal_Plant_Leaves_Crystal_Cyan"
    },
    {
      "x": -19,
      "y": 35,
      "z": 5,
      "name": "Fullmetal_Plant_Leaves_Crystal_Cyan"
    },
    {
      "x": -19,
      "y": 32,
      "z": 6,
      "name": "Fullmetal_Plant_Leaves_Crystal_Cyan"
    },
    {
      "x": -19,
      "y": 33,
      "z": 6,
      "name": "Fullmetal_Plant_Leaves_Crystal_Cyan"
    },
    {
      "x": -19,
      "y": 34,
      "z": 6,
      "name": "Fullmetal_Plant_Leaves_Crystal_Cyan"
    },
    {
      "x": -19,
      "y": 35,
      "z": 6,
      "name": "Fullmetal_Plant_Leaves_Crystal_Cyan"
    },
    {
      "x": -19,
      "y": 32,
      "z": 7,
      "name": "Fullmetal_Plant_Leaves_Crystal_Cyan"
    },
    {
      "x": -19,
      "y": 33,
      "z": 7,
      "name": "Fullmetal_Plant_Leaves_Crystal_Cyan"
    },
    {
      "x": -19,
      "y": 34,
      "z": 7,
      "name": "Fullmetal_Plant_Leaves_Crystal_Cyan"
    },
    {
      "x": -19,
      "y": 33,
      "z": 8,
      "name": "Fullmetal_Plant_Leaves_Crystal_Cyan"
    },
    {
      "x": -18,
      "y": 32,
      "z": -2,
      "name": "Fullmetal_Plant_Leaves_Crystal_Cyan"
    },
    {
      "x": -18,
      "y": 30,
      "z": -1,
      "name": "Fullmetal_Plant_Leaves_Crystal_Cyan"
    },
    {
      "x": -18,
      "y": 31,
      "z": -1,
      "name": "Fullmetal_Plant_Leaves_Crystal_Cyan"
    },
    {
      "x": -18,
      "y": 32,
      "z": -1,
      "name": "Fullmetal_Plant_Leaves_Crystal_Cyan"
    },
    {
      "x": -18,
      "y": 31,
      "z": 0,
      "name": "Fullmetal_Plant_Leaves_Crystal_Cyan"
    },
    {
      "x": -18,
      "y": 32,
      "z": 0,
      "name": "Fullmetal_Plant_Leaves_Crystal_Cyan"
    },
    {
      "x": -18,
      "y": 33,
      "z": 0,
      "name": "Fullmetal_Plant_Leaves_Crystal_Cyan"
    },
    {
      "x": -18,
      "y": 34,
      "z": 0,
      "name": "Fullmetal_Plant_Leaves_Crystal_Cyan"
    },
    {
      "x": -18,
      "y": 32,
      "z": 1,
      "name": "Fullmetal_Plant_Leaves_Crystal_Cyan"
    },
    {
      "x": -18,
      "y": 33,
      "z": 1,
      "name": "Fullmetal_Plant_Leaves_Crystal_Cyan"
    },
    {
      "x": -18,
      "y": 34,
      "z": 1,
      "name": "Fullmetal_Plant_Leaves_Crystal_Cyan"
    },
    {
      "x": -18,
      "y": 32,
      "z": 2,
      "name": "Fullmetal_Plant_Leaves_Crystal_Cyan"
    },
    {
      "x": -18,
      "y": 35,
      "z": 3,
      "name": "Fullmetal_Plant_Leaves_Crystal_Cyan"
    },
    {
      "x": -18,
      "y": 32,
      "z": 4,
      "name": "Fullmetal_Plant_Leaves_Crystal_Cyan"
    },
    {
      "x": -18,
      "y": 33,
      "z": 4,
      "name": "Fullmetal_Plant_Leaves_Crystal_Cyan"
    },
    {
      "x": -18,
      "y": 34,
      "z": 4,
      "name": "Fullmetal_Plant_Leaves_Crystal_Cyan"
    },
    {
      "x": -18,
      "y": 35,
      "z": 4,
      "name": "Fullmetal_Plant_Leaves_Crystal_Cyan"
    },
    {
      "x": -18,
      "y": 32,
      "z": 5,
      "name": "Fullmetal_Plant_Leaves_Crystal_Cyan"
    },
    {
      "x": -18,
      "y": 33,
      "z": 5,
      "name": "Fullmetal_Plant_Leaves_Crystal_Cyan"
    },
    {
      "x": -18,
      "y": 34,
      "z": 5,
      "name": "Fullmetal_Plant_Leaves_Crystal_Cyan"
    },
    {
      "x": -18,
      "y": 35,
      "z": 5,
      "name": "Fullmetal_Plant_Leaves_Crystal_Cyan"
    },
    {
      "x": -18,
      "y": 33,
      "z": 6,
      "name": "Fullmetal_Plant_Leaves_Crystal_Cyan"
    },
    {
      "x": -18,
      "y": 34,
      "z": 6,
      "name": "Fullmetal_Plant_Leaves_Crystal_Cyan"
    },
    {
      "x": -18,
      "y": 35,
      "z": 6,
      "name": "Fullmetal_Plant_Leaves_Crystal_Cyan"
    },
    {
      "x": -18,
      "y": 33,
      "z": 7,
      "name": "Fullmetal_Plant_Leaves_Crystal_Cyan"
    },
    {
      "x": -18,
      "y": 34,
      "z": 7,
      "name": "Fullmetal_Plant_Leaves_Crystal_Cyan"
    },
    {
      "x": -18,
      "y": 32,
      "z": 8,
      "name": "Fullmetal_Plant_Leaves_Crystal_Cyan"
    },
    {
      "x": -18,
      "y": 34,
      "z": 8,
      "name": "Fullmetal_Plant_Leaves_Crystal_Cyan"
    },
    {
      "x": -17,
      "y": 32,
      "z": -2,
      "name": "Fullmetal_Plant_Leaves_Crystal_Cyan"
    },
    {
      "x": -17,
      "y": 33,
      "z": -2,
      "name": "Fullmetal_Plant_Leaves_Crystal_Cyan"
    },
    {
      "x": -17,
      "y": 32,
      "z": -1,
      "name": "Fullmetal_Plant_Leaves_Crystal_Cyan"
    },
    {
      "x": -17,
      "y": 33,
      "z": -1,
      "name": "Fullmetal_Plant_Leaves_Crystal_Cyan"
    },
    {
      "x": -17,
      "y": 34,
      "z": -1,
      "name": "Fullmetal_Plant_Leaves_Crystal_Cyan"
    },
    {
      "x": -17,
      "y": 31,
      "z": 0,
      "name": "Fullmetal_Plant_Leaves_Crystal_Cyan"
    },
    {
      "x": -17,
      "y": 32,
      "z": 0,
      "name": "Fullmetal_Plant_Leaves_Crystal_Cyan"
    },
    {
      "x": -17,
      "y": 33,
      "z": 0,
      "name": "Fullmetal_Plant_Leaves_Crystal_Cyan"
    },
    {
      "x": -17,
      "y": 32,
      "z": 1,
      "name": "Fullmetal_Plant_Leaves_Crystal_Cyan"
    },
    {
      "x": -17,
      "y": 33,
      "z": 1,
      "name": "Fullmetal_Plant_Leaves_Crystal_Cyan"
    },
    {
      "x": -17,
      "y": 34,
      "z": 1,
      "name": "Fullmetal_Plant_Leaves_Crystal_Cyan"
    },
    {
      "x": -17,
      "y": 32,
      "z": 3,
      "name": "Fullmetal_Plant_Leaves_Crystal_Cyan"
    },
    {
      "x": -17,
      "y": 32,
      "z": 4,
      "name": "Wood_Crystal_Trunk_Full"
    },
    {
      "x": -17,
      "y": 33,
      "z": 4,
      "name": "Fullmetal_Plant_Leaves_Crystal_Cyan"
    },
    {
      "x": -17,
      "y": 35,
      "z": 4,
      "name": "Fullmetal_Plant_Leaves_Crystal_Cyan"
    },
    {
      "x": -17,
      "y": 32,
      "z": 5,
      "name": "Wood_Crystal_Trunk_Full"
    },
    {
      "x": -17,
      "y": 34,
      "z": 5,
      "name": "Fullmetal_Plant_Leaves_Crystal_Cyan"
    },
    {
      "x": -17,
      "y": 35,
      "z": 5,
      "name": "Fullmetal_Plant_Leaves_Crystal_Cyan"
    },
    {
      "x": -17,
      "y": 31,
      "z": 6,
      "name": "Plant_Fruit_Azure"
    },
    {
      "x": -17,
      "y": 32,
      "z": 6,
      "name": "Fullmetal_Plant_Leaves_Crystal_Cyan"
    },
    {
      "x": -17,
      "y": 34,
      "z": 6,
      "name": "Fullmetal_Plant_Leaves_Crystal_Cyan"
    },
    {
      "x": -17,
      "y": 35,
      "z": 6,
      "name": "Fullmetal_Plant_Leaves_Crystal_Cyan"
    },
    {
      "x": -17,
      "y": 32,
      "z": 7,
      "name": "Fullmetal_Plant_Leaves_Crystal_Cyan"
    },
    {
      "x": -17,
      "y": 33,
      "z": 7,
      "name": "Fullmetal_Plant_Leaves_Crystal_Cyan"
    },
    {
      "x": -17,
      "y": 31,
      "z": 8,
      "name": "Fullmetal_Plant_Leaves_Crystal_Cyan"
    },
    {
      "x": -17,
      "y": 32,
      "z": 8,
      "name": "Fullmetal_Plant_Leaves_Crystal_Cyan"
    },
    {
      "x": -17,
      "y": 33,
      "z": 8,
      "name": "Fullmetal_Plant_Leaves_Crystal_Cyan"
    },
    {
      "x": -17,
      "y": 32,
      "z": 9,
      "name": "Fullmetal_Plant_Leaves_Crystal_Cyan"
    },
    {
      "x": -16,
      "y": 32,
      "z": -3,
      "name": "Fullmetal_Plant_Leaves_Crystal_Cyan"
    },
    {
      "x": -16,
      "y": 31,
      "z": -2,
      "name": "Fullmetal_Plant_Leaves_Crystal_Cyan"
    },
    {
      "x": -16,
      "y": 32,
      "z": -2,
      "name": "Fullmetal_Plant_Leaves_Crystal_Cyan"
    },
    {
      "x": -16,
      "y": 33,
      "z": -2,
      "name": "Fullmetal_Plant_Leaves_Crystal_Cyan"
    },
    {
      "x": -16,
      "y": 31,
      "z": -1,
      "name": "Fullmetal_Plant_Leaves_Crystal_Cyan"
    },
    {
      "x": -16,
      "y": 32,
      "z": -1,
      "name": "Fullmetal_Plant_Leaves_Crystal_Cyan"
    },
    {
      "x": -16,
      "y": 33,
      "z": -1,
      "name": "Fullmetal_Plant_Leaves_Crystal_Cyan"
    },
    {
      "x": -16,
      "y": 34,
      "z": -1,
      "name": "Fullmetal_Plant_Leaves_Crystal_Cyan"
    },
    {
      "x": -16,
      "y": 31,
      "z": 0,
      "name": "Fullmetal_Plant_Leaves_Crystal_Cyan"
    },
    {
      "x": -16,
      "y": 32,
      "z": 0,
      "name": "Fullmetal_Plant_Leaves_Crystal_Cyan"
    },
    {
      "x": -16,
      "y": 33,
      "z": 0,
      "name": "Fullmetal_Plant_Leaves_Crystal_Cyan"
    },
    {
      "x": -16,
      "y": 34,
      "z": 0,
      "name": "Fullmetal_Plant_Leaves_Crystal_Cyan"
    },
    {
      "x": -16,
      "y": 31,
      "z": 1,
      "name": "Wood_Crystal_Trunk_Full"
    },
    {
      "x": -16,
      "y": 32,
      "z": 1,
      "name": "Fullmetal_Plant_Leaves_Crystal_Cyan"
    },
    {
      "x": -16,
      "y": 34,
      "z": 1,
      "name": "Fullmetal_Plant_Leaves_Crystal_Cyan"
    },
    {
      "x": -16,
      "y": 32,
      "z": 4,
      "name": "Wood_Crystal_Trunk_Full"
    },
    {
      "x": -16,
      "y": 34,
      "z": 6,
      "name": "Fullmetal_Plant_Leaves_Crystal_Cyan"
    },
    {
      "x": -16,
      "y": 31,
      "z": 7,
      "name": "Fullmetal_Plant_Leaves_Crystal_Cyan"
    },
    {
      "x": -16,
      "y": 32,
      "z": 7,
      "name": "Fullmetal_Plant_Leaves_Crystal_Cyan"
    },
    {
      "x": -16,
      "y": 34,
      "z": 7,
      "name": "Fullmetal_Plant_Leaves_Crystal_Cyan"
    },
    {
      "x": -16,
      "y": 31,
      "z": 8,
      "name": "Fullmetal_Plant_Leaves_Crystal_Cyan"
    },
    {
      "x": -16,
      "y": 32,
      "z": 8,
      "name": "Fullmetal_Plant_Leaves_Crystal_Cyan"
    },
    {
      "x": -16,
      "y": 33,
      "z": 8,
      "name": "Fullmetal_Plant_Leaves_Crystal_Cyan"
    },
    {
      "x": -16,
      "y": 34,
      "z": 8,
      "name": "Fullmetal_Plant_Leaves_Crystal_Cyan"
    },
    {
      "x": -16,
      "y": 32,
      "z": 9,
      "name": "Fullmetal_Plant_Leaves_Crystal_Cyan"
    },
    {
      "x": -16,
      "y": 33,
      "z": 9,
      "name": "Fullmetal_Plant_Leaves_Crystal_Cyan"
    },
    {
      "x": -16,
      "y": 32,
      "z": 10,
      "name": "Fullmetal_Plant_Leaves_Crystal_Cyan"
    },
    {
      "x": -15,
      "y": 32,
      "z": -3,
      "name": "Fullmetal_Plant_Leaves_Crystal_Cyan"
    },
    {
      "x": -15,
      "y": 33,
      "z": -3,
      "name": "Fullmetal_Plant_Leaves_Crystal_Cyan"
    },
    {
      "x": -15,
      "y": 30,
      "z": -2,
      "name": "Fullmetal_Plant_Leaves_Crystal_Cyan"
    },
    {
      "x": -15,
      "y": 32,
      "z": -2,
      "name": "Fullmetal_Plant_Leaves_Crystal_Cyan"
    },
    {
      "x": -15,
      "y": 33,
      "z": -2,
      "name": "Fullmetal_Plant_Leaves_Crystal_Cyan"
    },
    {
      "x": -15,
      "y": 30,
      "z": -1,
      "name": "Fullmetal_Plant_Leaves_Crystal_Cyan"
    },
    {
      "x": -15,
      "y": 32,
      "z": -1,
      "name": "Fullmetal_Plant_Leaves_Crystal_Cyan"
    },
    {
      "x": -15,
      "y": 33,
      "z": -1,
      "name": "Fullmetal_Plant_Leaves_Crystal_Cyan"
    },
    {
      "x": -15,
      "y": 34,
      "z": -1,
      "name": "Fullmetal_Plant_Leaves_Crystal_Cyan"
    },
    {
      "x": -15,
      "y": 30,
      "z": 0,
      "name": "Fullmetal_Plant_Leaves_Crystal_Cyan"
    },
    {
      "x": -15,
      "y": 32,
      "z": 0,
      "name": "Fullmetal_Plant_Leaves_Crystal_Cyan"
    },
    {
      "x": -15,
      "y": 33,
      "z": 0,
      "name": "Fullmetal_Plant_Leaves_Crystal_Cyan"
    },
    {
      "x": -15,
      "y": 34,
      "z": 0,
      "name": "Fullmetal_Plant_Leaves_Crystal_Cyan"
    },
    {
      "x": -15,
      "y": 30,
      "z": 1,
      "name": "Fullmetal_Plant_Leaves_Crystal_Cyan"
    },
    {
      "x": -15,
      "y": 31,
      "z": 1,
      "name": "Wood_Crystal_Trunk_Full"
    },
    {
      "x": -15,
      "y": 32,
      "z": 1,
      "name": "Fullmetal_Plant_Leaves_Crystal_Cyan"
    },
    {
      "x": -15,
      "y": 34,
      "z": 1,
      "name": "Fullmetal_Plant_Leaves_Crystal_Cyan"
    },
    {
      "x": -15,
      "y": 32,
      "z": 2,
      "name": "Fullmetal_Plant_Leaves_Crystal_Cyan"
    },
    {
      "x": -15,
      "y": 31,
      "z": 4,
      "name": "Wood_Crystal_Trunk_Full"
    },
    {
      "x": -15,
      "y": 32,
      "z": 4,
      "name": "Wood_Crystal_Trunk_Full"
    },
    {
      "x": -15,
      "y": 32,
      "z": 6,
      "name": "Fullmetal_Plant_Leaves_Crystal_Cyan"
    },
    {
      "x": -15,
      "y": 32,
      "z": 7,
      "name": "Fullmetal_Plant_Leaves_Crystal_Cyan"
    },
    {
      "x": -15,
      "y": 33,
      "z": 7,
      "name": "Fullmetal_Plant_Leaves_Crystal_Cyan"
    },
    {
      "x": -15,
      "y": 34,
      "z": 7,
      "name": "Fullmetal_Plant_Leaves_Crystal_Cyan"
    },
    {
      "x": -15,
      "y": 31,
      "z": 8,
      "name": "Fullmetal_Plant_Leaves_Crystal_Cyan"
    },
    {
      "x": -15,
      "y": 32,
      "z": 8,
      "name": "Fullmetal_Plant_Leaves_Crystal_Cyan"
    },
    {
      "x": -15,
      "y": 33,
      "z": 8,
      "name": "Fullmetal_Plant_Leaves_Crystal_Cyan"
    },
    {
      "x": -15,
      "y": 31,
      "z": 9,
      "name": "Fullmetal_Plant_Leaves_Crystal_Cyan"
    },
    {
      "x": -15,
      "y": 32,
      "z": 9,
      "name": "Fullmetal_Plant_Leaves_Crystal_Cyan"
    },
    {
      "x": -15,
      "y": 33,
      "z": 9,
      "name": "Fullmetal_Plant_Leaves_Crystal_Cyan"
    },
    {
      "x": -15,
      "y": 32,
      "z": 10,
      "name": "Fullmetal_Plant_Leaves_Crystal_Cyan"
    },
    {
      "x": -15,
      "y": 31,
      "z": 11,
      "name": "Fullmetal_Plant_Leaves_Crystal_Cyan"
    },
    {
      "x": -15,
      "y": 32,
      "z": 11,
      "name": "Fullmetal_Plant_Leaves_Crystal_Cyan"
    },
    {
      "x": -14,
      "y": 27,
      "z": -7,
      "name": "Fullmetal_Plant_Leaves_Crystal_Cyan"
    },
    {
      "x": -14,
      "y": 27,
      "z": -6,
      "name": "Fullmetal_Plant_Leaves_Crystal_Cyan"
    },
    {
      "x": -14,
      "y": 30,
      "z": -4,
      "name": "Fullmetal_Plant_Leaves_Crystal_Cyan"
    },
    {
      "x": -14,
      "y": 30,
      "z": -3,
      "name": "Fullmetal_Plant_Leaves_Crystal_Cyan"
    },
    {
      "x": -14,
      "y": 32,
      "z": -3,
      "name": "Fullmetal_Plant_Leaves_Crystal_Cyan"
    },
    {
      "x": -14,
      "y": -4,
      "z": -2,
      "name": "Wood_Crystal_Trunk_Full"
    },
    {
      "x": -14,
      "y": 29,
      "z": -2,
      "name": "Fullmetal_Plant_Leaves_Crystal_Cyan"
    },
    {
      "x": -14,
      "y": 30,
      "z": -2,
      "name": "Fullmetal_Plant_Leaves_Crystal_Cyan"
    },
    {
      "x": -14,
      "y": 32,
      "z": -2,
      "name": "Fullmetal_Plant_Leaves_Crystal_Cyan"
    },
    {
      "x": -14,
      "y": 33,
      "z": -2,
      "name": "Fullmetal_Plant_Leaves_Crystal_Cyan"
    },
    {
      "x": -14,
      "y": -5,
      "z": -1,
      "name": "Wood_Crystal_Roots"
    },
    {
      "x": -14,
      "y": -4,
      "z": -1,
      "name": "Wood_Crystal_Trunk_Full"
    },
    {
      "x": -14,
      "y": 29,
      "z": -1,
      "name": "Fullmetal_Plant_Leaves_Crystal_Cyan"
    },
    {
      "x": -14,
      "y": 30,
      "z": -1,
      "name": "Fullmetal_Plant_Leaves_Crystal_Cyan"
    },
    {
      "x": -14,
      "y": 32,
      "z": -1,
      "name": "Fullmetal_Plant_Leaves_Crystal_Cyan"
    },
    {
      "x": -14,
      "y": 33,
      "z": -1,
      "name": "Fullmetal_Plant_Leaves_Crystal_Cyan"
    },
    {
      "x": -14,
      "y": 30,
      "z": 0,
      "name": "Fullmetal_Plant_Leaves_Crystal_Cyan"
    },
    {
      "x": -14,
      "y": 31,
      "z": 0,
      "name": "Wood_Crystal_Trunk_Full"
    },
    {
      "x": -14,
      "y": 32,
      "z": 0,
      "name": "Fullmetal_Plant_Leaves_Crystal_Cyan"
    },
    {
      "x": -14,
      "y": 33,
      "z": 0,
      "name": "Fullmetal_Plant_Leaves_Crystal_Cyan"
    },
    {
      "x": -14,
      "y": 34,
      "z": 0,
      "name": "Fullmetal_Plant_Leaves_Crystal_Cyan"
    },
    {
      "x": -14,
      "y": 30,
      "z": 1,
      "name": "Fullmetal_Plant_Leaves_Crystal_Cyan"
    },
    {
      "x": -14,
      "y": 31,
      "z": 1,
      "name": "Wood_Crystal_Trunk_Full"
    },
    {
      "x": -14,
      "y": 31,
      "z": 2,
      "name": "Wood_Crystal_Trunk_Full"
    },
    {
      "x": -14,
      "y": 31,
      "z": 3,
      "name": "Wood_Crystal_Trunk_Full"
    },
    {
      "x": -14,
      "y": 31,
      "z": 4,
      "name": "Wood_Crystal_Trunk_Full"
    },
    {
      "x": -14,
      "y": 28,
      "z": 5,
      "name": "Fullmetal_Plant_Leaves_Crystal_Cyan"
    },
    {
      "x": -14,
      "y": 28,
      "z": 6,
      "name": "Fullmetal_Plant_Leaves_Crystal_Cyan"
    },
    {
      "x": -14,
      "y": 32,
      "z": 6,
      "name": "Fullmetal_Plant_Leaves_Crystal_Cyan"
    },
    {
      "x": -14,
      "y": 28,
      "z": 7,
      "name": "Fullmetal_Plant_Leaves_Crystal_Cyan"
    },
    {
      "x": -14,
      "y": 31,
      "z": 7,
      "name": "Wood_Crystal_Trunk_Full"
    },
    {
      "x": -14,
      "y": 32,
      "z": 7,
      "name": "Fullmetal_Plant_Leaves_Crystal_Cyan"
    },
    {
      "x": -14,
      "y": 31,
      "z": 8,
      "name": "Fullmetal_Plant_Leaves_Crystal_Cyan"
    },
    {
      "x": -14,
      "y": 32,
      "z": 8,
      "name": "Fullmetal_Plant_Leaves_Crystal_Cyan"
    },
    {
      "x": -14,
      "y": 33,
      "z": 8,
      "name": "Fullmetal_Plant_Leaves_Crystal_Cyan"
    },
    {
      "x": -14,
      "y": 31,
      "z": 9,
      "name": "Fullmetal_Plant_Leaves_Crystal_Cyan"
    },
    {
      "x": -14,
      "y": 32,
      "z": 9,
      "name": "Fullmetal_Plant_Leaves_Crystal_Cyan"
    },
    {
      "x": -14,
      "y": 31,
      "z": 10,
      "name": "Fullmetal_Plant_Leaves_Crystal_Cyan"
    },
    {
      "x": -14,
      "y": 32,
      "z": 10,
      "name": "Fullmetal_Plant_Leaves_Crystal_Cyan"
    },
    {
      "x": -14,
      "y": 33,
      "z": 10,
      "name": "Fullmetal_Plant_Leaves_Crystal_Cyan"
    },
    {
      "x": -14,
      "y": 31,
      "z": 11,
      "name": "Fullmetal_Plant_Leaves_Crystal_Cyan"
    },
    {
      "x": -14,
      "y": 32,
      "z": 11,
      "name": "Fullmetal_Plant_Leaves_Crystal_Cyan"
    },
    {
      "x": -14,
      "y": 32,
      "z": 12,
      "name": "Fullmetal_Plant_Leaves_Crystal_Cyan"
    },
    {
      "x": -13,
      "y": 27,
      "z": -9,
      "name": "Fullmetal_Plant_Leaves_Crystal_Cyan"
    },
    {
      "x": -13,
      "y": 27,
      "z": -8,
      "name": "Fullmetal_Plant_Leaves_Crystal_Cyan"
    },
    {
      "x": -13,
      "y": 26,
      "z": -7,
      "name": "Wood_Crystal_Branch_Corner",
      "rotation": 3
    },
    {
      "x": -13,
      "y": 27,
      "z": -7,
      "name": "Fullmetal_Plant_Leaves_Crystal_Cyan"
    },
    {
      "x": -13,
      "y": 27,
      "z": -6,
      "name": "Fullmetal_Plant_Leaves_Crystal_Cyan"
    },
    {
      "x": -13,
      "y": 28,
      "z": -6,
      "name": "Fullmetal_Plant_Leaves_Crystal_Cyan"
    },
    {
      "x": -13,
      "y": 27,
      "z": -5,
      "name": "Fullmetal_Plant_Leaves_Crystal_Cyan"
    },
    {
      "x": -13,
      "y": 30,
      "z": -4,
      "name": "Fullmetal_Plant_Leaves_Crystal_Cyan"
    },
    {
      "x": -13,
      "y": 32,
      "z": -4,
      "name": "Fullmetal_Plant_Leaves_Crystal_Cyan"
    },
    {
      "x": -13,
      "y": 29,
      "z": -3,
      "name": "Fullmetal_Plant_Leaves_Crystal_Cyan"
    },
    {
      "x": -13,
      "y": 30,
      "z": -3,
      "name": "Fullmetal_Plant_Leaves_Crystal_Cyan"
    },
    {
      "x": -13,
      "y": 32,
      "z": -3,
      "name": "Fullmetal_Plant_Leaves_Crystal_Cyan"
    },
    {
      "x": -13,
      "y": 29,
      "z": -2,
      "name": "Fullmetal_Plant_Leaves_Crystal_Cyan"
    },
    {
      "x": -13,
      "y": 30,
      "z": -2,
      "name": "Fullmetal_Plant_Leaves_Crystal_Cyan"
    },
    {
      "x": -13,
      "y": 32,
      "z": -2,
      "name": "Fullmetal_Plant_Leaves_Crystal_Cyan"
    },
    {
      "x": -13,
      "y": -4,
      "z": -1,
      "name": "Wood_Crystal_Trunk"
    },
    {
      "x": -13,
      "y": -3,
      "z": -1,
      "name": "Wood_Crystal_Trunk_Full"
    },
    {
      "x": -13,
      "y": 29,
      "z": -1,
      "name": "Fullmetal_Plant_Leaves_Crystal_Cyan"
    },
    {
      "x": -13,
      "y": 30,
      "z": -1,
      "name": "Fullmetal_Plant_Leaves_Crystal_Cyan"
    },
    {
      "x": -13,
      "y": 32,
      "z": -1,
      "name": "Fullmetal_Plant_Leaves_Crystal_Cyan"
    },
    {
      "x": -13,
      "y": -5,
      "z": 0,
      "name": "Wood_Crystal_Roots"
    },
    {
      "x": -13,
      "y": -4,
      "z": 0,
      "name": "Wood_Crystal_Trunk"
    },
    {
      "x": -13,
      "y": -3,
      "z": 0,
      "name": "Wood_Crystal_Trunk_Full"
    },
    {
      "x": -13,
      "y": 29,
      "z": 0,
      "name": "Plant_Fruit_Azure",
      "rotation": 8
    },
    {
      "x": -13,
      "y": 30,
      "z": 0,
      "name": "Fullmetal_Plant_Leaves_Crystal_Cyan"
    },
    {
      "x": -13,
      "y": 36,
      "z": 0,
      "name": "Fullmetal_Plant_Leaves_Crystal_Cyan"
    },
    {
      "x": -13,
      "y": 30,
      "z": 1,
      "name": "Fullmetal_Plant_Leaves_Crystal_Cyan"
    },
    {
      "x": -13,
      "y": 30,
      "z": 2,
      "name": "Fullmetal_Plant_Leaves_Crystal_Cyan"
    },
    {
      "x": -13,
      "y": 31,
      "z": 3,
      "name": "Wood_Crystal_Trunk_Full"
    },
    {
      "x": -13,
      "y": 27,
      "z": 4,
      "name": "Fullmetal_Plant_Leaves_Crystal_Cyan"
    },
    {
      "x": -13,
      "y": 28,
      "z": 4,
      "name": "Fullmetal_Plant_Leaves_Crystal_Cyan"
    },
    {
      "x": -13,
      "y": 28,
      "z": 5,
      "name": "Fullmetal_Plant_Leaves_Crystal_Cyan"
    },
    {
      "x": -13,
      "y": 28,
      "z": 6,
      "name": "Fullmetal_Plant_Leaves_Crystal_Cyan"
    },
    {
      "x": -13,
      "y": 29,
      "z": 6,
      "name": "Fullmetal_Plant_Leaves_Crystal_Cyan"
    },
    {
      "x": -13,
      "y": 28,
      "z": 7,
      "name": "Fullmetal_Plant_Leaves_Crystal_Cyan"
    },
    {
      "x": -13,
      "y": 29,
      "z": 7,
      "name": "Fullmetal_Plant_Leaves_Crystal_Cyan"
    },
    {
      "x": -13,
      "y": 31,
      "z": 7,
      "name": "Wood_Crystal_Trunk_Full"
    },
    {
      "x": -13,
      "y": 32,
      "z": 7,
      "name": "Fullmetal_Plant_Leaves_Crystal_Cyan"
    },
    {
      "x": -13,
      "y": 28,
      "z": 8,
      "name": "Fullmetal_Plant_Leaves_Crystal_Cyan"
    },
    {
      "x": -13,
      "y": 31,
      "z": 8,
      "name": "Wood_Crystal_Trunk_Full"
    },
    {
      "x": -13,
      "y": 34,
      "z": 8,
      "name": "Fullmetal_Plant_Leaves_Crystal_Cyan"
    },
    {
      "x": -13,
      "y": 28,
      "z": 9,
      "name": "Fullmetal_Plant_Leaves_Crystal_Cyan"
    },
    {
      "x": -13,
      "y": 32,
      "z": 9,
      "name": "Fullmetal_Plant_Leaves_Crystal_Cyan"
    },
    {
      "x": -13,
      "y": 33,
      "z": 9,
      "name": "Fullmetal_Plant_Leaves_Crystal_Cyan"
    },
    {
      "x": -13,
      "y": 34,
      "z": 9,
      "name": "Fullmetal_Plant_Leaves_Crystal_Cyan"
    },
    {
      "x": -13,
      "y": 32,
      "z": 10,
      "name": "Fullmetal_Plant_Leaves_Crystal_Cyan"
    },
    {
      "x": -13,
      "y": 33,
      "z": 10,
      "name": "Fullmetal_Plant_Leaves_Crystal_Cyan"
    },
    {
      "x": -13,
      "y": 31,
      "z": 11,
      "name": "Fullmetal_Plant_Leaves_Crystal_Cyan"
    },
    {
      "x": -13,
      "y": 32,
      "z": 11,
      "name": "Fullmetal_Plant_Leaves_Crystal_Cyan"
    },
    {
      "x": -13,
      "y": 33,
      "z": 11,
      "name": "Fullmetal_Plant_Leaves_Crystal_Cyan"
    },
    {
      "x": -13,
      "y": 32,
      "z": 12,
      "name": "Fullmetal_Plant_Leaves_Crystal_Cyan"
    },
    {
      "x": -12,
      "y": 25,
      "z": -10,
      "name": "Fullmetal_Plant_Leaves_Crystal_Cyan"
    },
    {
      "x": -12,
      "y": 27,
      "z": -10,
      "name": "Fullmetal_Plant_Leaves_Crystal_Cyan"
    },
    {
      "x": -12,
      "y": 27,
      "z": -9,
      "name": "Fullmetal_Plant_Leaves_Crystal_Cyan"
    },
    {
      "x": -12,
      "y": 28,
      "z": -9,
      "name": "Fullmetal_Plant_Leaves_Crystal_Cyan"
    },
    {
      "x": -12,
      "y": 26,
      "z": -8,
      "name": "Fullmetal_Plant_Leaves_Crystal_Cyan"
    },
    {
      "x": -12,
      "y": 27,
      "z": -8,
      "name": "Fullmetal_Plant_Leaves_Crystal_Cyan"
    },
    {
      "x": -12,
      "y": 28,
      "z": -8,
      "name": "Fullmetal_Plant_Leaves_Crystal_Cyan"
    },
    {
      "x": -12,
      "y": 26,
      "z": -7,
      "name": "Wood_Crystal_Branch_Long",
      "rotation": 5
    },
    {
      "x": -12,
      "y": 27,
      "z": -7,
      "name": "Fullmetal_Plant_Leaves_Crystal_Cyan"
    },
    {
      "x": -12,
      "y": 28,
      "z": -7,
      "name": "Fullmetal_Plant_Leaves_Crystal_Cyan"
    },
    {
      "x": -12,
      "y": 27,
      "z": -6,
      "name": "Fullmetal_Plant_Leaves_Crystal_Cyan"
    },
    {
      "x": -12,
      "y": 28,
      "z": -6,
      "name": "Fullmetal_Plant_Leaves_Crystal_Cyan"
    },
    {
      "x": -12,
      "y": 30,
      "z": -6,
      "name": "Fullmetal_Plant_Leaves_Crystal_Cyan"
    },
    {
      "x": -12,
      "y": 27,
      "z": -5,
      "name": "Fullmetal_Plant_Leaves_Crystal_Cyan"
    },
    {
      "x": -12,
      "y": 28,
      "z": -5,
      "name": "Fullmetal_Plant_Leaves_Crystal_Cyan"
    },
    {
      "x": -12,
      "y": 30,
      "z": -5,
      "name": "Fullmetal_Plant_Leaves_Crystal_Cyan"
    },
    {
      "x": -12,
      "y": 31,
      "z": -5,
      "name": "Fullmetal_Plant_Leaves_Crystal_Cyan"
    },
    {
      "x": -12,
      "y": 25,
      "z": -4,
      "name": "Fullmetal_Plant_Leaves_Crystal_Cyan"
    },
    {
      "x": -12,
      "y": 27,
      "z": -4,
      "name": "Fullmetal_Plant_Leaves_Crystal_Cyan"
    },
    {
      "x": -12,
      "y": 30,
      "z": -4,
      "name": "Fullmetal_Plant_Leaves_Crystal_Cyan"
    },
    {
      "x": -12,
      "y": 31,
      "z": -4,
      "name": "Fullmetal_Plant_Leaves_Crystal_Cyan"
    },
    {
      "x": -12,
      "y": 29,
      "z": -3,
      "name": "Fullmetal_Plant_Leaves_Crystal_Cyan"
    },
    {
      "x": -12,
      "y": 30,
      "z": -3,
      "name": "Fullmetal_Plant_Leaves_Crystal_Cyan"
    },
    {
      "x": -12,
      "y": 32,
      "z": -3,
      "name": "Fullmetal_Plant_Leaves_Crystal_Cyan"
    },
    {
      "x": -12,
      "y": 36,
      "z": -3,
      "name": "Fullmetal_Plant_Leaves_Crystal_Cyan"
    },
    {
      "x": -12,
      "y": 29,
      "z": -2,
      "name": "Fullmetal_Plant_Leaves_Crystal_Cyan"
    },
    {
      "x": -12,
      "y": 30,
      "z": -2,
      "name": "Fullmetal_Plant_Leaves_Crystal_Cyan"
    },
    {
      "x": -12,
      "y": 32,
      "z": -2,
      "name": "Fullmetal_Plant_Leaves_Crystal_Cyan"
    },
    {
      "x": -12,
      "y": 30,
      "z": -1,
      "name": "Fullmetal_Plant_Leaves_Crystal_Cyan"
    },
    {
      "x": -12,
      "y": 32,
      "z": -1,
      "name": "Fullmetal_Plant_Leaves_Crystal_Cyan"
    },
    {
      "x": -12,
      "y": 35,
      "z": -1,
      "name": "Fullmetal_Plant_Leaves_Crystal_Cyan"
    },
    {
      "x": -12,
      "y": 36,
      "z": -1,
      "name": "Fullmetal_Plant_Leaves_Crystal_Cyan"
    },
    {
      "x": -12,
      "y": -4,
      "z": 0,
      "name": "Wood_Crystal_Trunk"
    },
    {
      "x": -12,
      "y": -3,
      "z": 0,
      "name": "Wood_Crystal_Trunk_Full"
    },
    {
      "x": -12,
      "y": 29,
      "z": 0,
      "name": "Fullmetal_Plant_Leaves_Crystal_Cyan"
    },
    {
      "x": -12,
      "y": 30,
      "z": 0,
      "name": "Fullmetal_Plant_Leaves_Crystal_Cyan"
    },
    {
      "x": -12,
      "y": 32,
      "z": 0,
      "name": "Fullmetal_Plant_Leaves_Crystal_Cyan"
    },
    {
      "x": -12,
      "y": 35,
      "z": 0,
      "name": "Fullmetal_Plant_Leaves_Crystal_Cyan"
    },
    {
      "x": -12,
      "y": 36,
      "z": 0,
      "name": "Fullmetal_Plant_Leaves_Crystal_Cyan"
    },
    {
      "x": -12,
      "y": 37,
      "z": 0,
      "name": "Fullmetal_Plant_Leaves_Crystal_Cyan"
    },
    {
      "x": -12,
      "y": -4,
      "z": 1,
      "name": "Wood_Crystal_Trunk"
    },
    {
      "x": -12,
      "y": -3,
      "z": 1,
      "name": "Wood_Crystal_Trunk"
    },
    {
      "x": -12,
      "y": -2,
      "z": 1,
      "name": "Wood_Crystal_Trunk_Full"
    },
    {
      "x": -12,
      "y": 30,
      "z": 1,
      "name": "Fullmetal_Plant_Leaves_Crystal_Cyan"
    },
    {
      "x": -12,
      "y": -3,
      "z": 2,
      "name": "Wood_Crystal_Trunk"
    },
    {
      "x": -12,
      "y": -2,
      "z": 2,
      "name": "Wood_Crystal_Trunk_Full"
    },
    {
      "x": -12,
      "y": 30,
      "z": 2,
      "name": "Fullmetal_Plant_Leaves_Crystal_Cyan"
    },
    {
      "x": -12,
      "y": 36,
      "z": 2,
      "name": "Fullmetal_Plant_Leaves_Crystal_Cyan"
    },
    {
      "x": -12,
      "y": 28,
      "z": 3,
      "name": "Fullmetal_Plant_Leaves_Crystal_Cyan"
    },
    {
      "x": -12,
      "y": 30,
      "z": 3,
      "name": "Wood_Crystal_Trunk_Full"
    },
    {
      "x": -12,
      "y": 31,
      "z": 3,
      "name": "Wood_Crystal_Trunk_Full"
    },
    {
      "x": -12,
      "y": 27,
      "z": 4,
      "name": "Fullmetal_Plant_Leaves_Crystal_Cyan"
    },
    {
      "x": -12,
      "y": 28,
      "z": 4,
      "name": "Fullmetal_Plant_Leaves_Crystal_Cyan"
    },
    {
      "x": -12,
      "y": 31,
      "z": 4,
      "name": "Wood_Crystal_Trunk_Full"
    },
    {
      "x": -12,
      "y": 28,
      "z": 5,
      "name": "Fullmetal_Plant_Leaves_Crystal_Cyan"
    },
    {
      "x": -12,
      "y": 31,
      "z": 5,
      "name": "Wood_Crystal_Trunk_Full"
    },
    {
      "x": -12,
      "y": 37,
      "z": 5,
      "name": "Fullmetal_Plant_Leaves_Crystal_Cyan"
    },
    {
      "x": -12,
      "y": 28,
      "z": 6,
      "name": "Fullmetal_Plant_Leaves_Crystal_Cyan"
    },
    {
      "x": -12,
      "y": 29,
      "z": 6,
      "name": "Fullmetal_Plant_Leaves_Crystal_Cyan"
    },
    {
      "x": -12,
      "y": 31,
      "z": 6,
      "name": "Wood_Crystal_Trunk_Full"
    },
    {
      "x": -12,
      "y": 37,
      "z": 6,
      "name": "Fullmetal_Plant_Leaves_Crystal_Cyan"
    },
    {
      "x": -12,
      "y": 28,
      "z": 7,
      "name": "Fullmetal_Plant_Leaves_Crystal_Cyan"
    },
    {
      "x": -12,
      "y": 29,
      "z": 7,
      "name": "Fullmetal_Plant_Leaves_Crystal_Cyan"
    },
    {
      "x": -12,
      "y": 31,
      "z": 7,
      "name": "Wood_Crystal_Trunk_Full"
    },
    {
      "x": -12,
      "y": 34,
      "z": 7,
      "name": "Fullmetal_Plant_Leaves_Crystal_Cyan"
    },
    {
      "x": -12,
      "y": 37,
      "z": 7,
      "name": "Fullmetal_Plant_Leaves_Crystal_Cyan"
    },
    {
      "x": -12,
      "y": 28,
      "z": 8,
      "name": "Fullmetal_Plant_Leaves_Crystal_Cyan"
    },
    {
      "x": -12,
      "y": 32,
      "z": 8,
      "name": "Fullmetal_Plant_Leaves_Crystal_Cyan"
    },
    {
      "x": -12,
      "y": 33,
      "z": 8,
      "name": "Fullmetal_Plant_Leaves_Crystal_Cyan"
    },
    {
      "x": -12,
      "y": 34,
      "z": 8,
      "name": "Fullmetal_Plant_Leaves_Crystal_Cyan"
    },
    {
      "x": -12,
      "y": 27,
      "z": 9,
      "name": "Fullmetal_Plant_Leaves_Crystal_Cyan"
    },
    {
      "x": -12,
      "y": 28,
      "z": 9,
      "name": "Fullmetal_Plant_Leaves_Crystal_Cyan"
    },
    {
      "x": -12,
      "y": 31,
      "z": 9,
      "name": "Fullmetal_Plant_Leaves_Crystal_Cyan"
    },
    {
      "x": -12,
      "y": 32,
      "z": 9,
      "name": "Fullmetal_Plant_Leaves_Crystal_Cyan"
    },
    {
      "x": -12,
      "y": 33,
      "z": 9,
      "name": "Fullmetal_Plant_Leaves_Crystal_Cyan"
    },
    {
      "x": -12,
      "y": 34,
      "z": 9,
      "name": "Fullmetal_Plant_Leaves_Crystal_Cyan"
    },
    {
      "x": -12,
      "y": 28,
      "z": 10,
      "name": "Fullmetal_Plant_Leaves_Crystal_Cyan"
    },
    {
      "x": -12,
      "y": 31,
      "z": 10,
      "name": "Fullmetal_Plant_Leaves_Crystal_Cyan"
    },
    {
      "x": -12,
      "y": 32,
      "z": 10,
      "name": "Fullmetal_Plant_Leaves_Crystal_Cyan"
    },
    {
      "x": -12,
      "y": 33,
      "z": 10,
      "name": "Fullmetal_Plant_Leaves_Crystal_Cyan"
    },
    {
      "x": -12,
      "y": 29,
      "z": 11,
      "name": "Fullmetal_Plant_Leaves_Crystal_Cyan"
    },
    {
      "x": -12,
      "y": 31,
      "z": 11,
      "name": "Fullmetal_Plant_Leaves_Crystal_Cyan"
    },
    {
      "x": -12,
      "y": 32,
      "z": 11,
      "name": "Fullmetal_Plant_Leaves_Crystal_Cyan"
    },
    {
      "x": -12,
      "y": 33,
      "z": 11,
      "name": "Fullmetal_Plant_Leaves_Crystal_Cyan"
    },
    {
      "x": -12,
      "y": 32,
      "z": 12,
      "name": "Fullmetal_Plant_Leaves_Crystal_Cyan"
    },
    {
      "x": -11,
      "y": 26,
      "z": -12,
      "name": "Fullmetal_Plant_Leaves_Crystal_Cyan"
    },
    {
      "x": -11,
      "y": 26,
      "z": -11,
      "name": "Fullmetal_Plant_Leaves_Crystal_Cyan"
    },
    {
      "x": -11,
      "y": 25,
      "z": -10,
      "name": "Fullmetal_Plant_Leaves_Crystal_Cyan"
    },
    {
      "x": -11,
      "y": 26,
      "z": -10,
      "name": "Fullmetal_Plant_Leaves_Crystal_Cyan"
    },
    {
      "x": -11,
      "y": 27,
      "z": -10,
      "name": "Fullmetal_Plant_Leaves_Crystal_Cyan"
    },
    {
      "x": -11,
      "y": 28,
      "z": -10,
      "name": "Fullmetal_Plant_Leaves_Crystal_Cyan"
    },
    {
      "x": -11,
      "y": 27,
      "z": -9,
      "name": "Fullmetal_Plant_Leaves_Crystal_Cyan"
    },
    {
      "x": -11,
      "y": 28,
      "z": -9,
      "name": "Fullmetal_Plant_Leaves_Crystal_Cyan"
    },
    {
      "x": -11,
      "y": 26,
      "z": -8,
      "name": "Fullmetal_Plant_Leaves_Crystal_Cyan"
    },
    {
      "x": -11,
      "y": 27,
      "z": -8,
      "name": "Fullmetal_Plant_Leaves_Crystal_Cyan"
    },
    {
      "x": -11,
      "y": 28,
      "z": -8,
      "name": "Fullmetal_Plant_Leaves_Crystal_Cyan"
    },
    {
      "x": -11,
      "y": 17,
      "z": -7,
      "name": "Fullmetal_Plant_Leaves_Crystal_Cyan"
    },
    {
      "x": -11,
      "y": 26,
      "z": -7,
      "name": "Wood_Crystal_Trunk_Full"
    },
    {
      "x": -11,
      "y": 27,
      "z": -7,
      "name": "Fullmetal_Plant_Leaves_Crystal_Cyan"
    },
    {
      "x": -11,
      "y": 28,
      "z": -7,
      "name": "Fullmetal_Plant_Leaves_Crystal_Cyan"
    },
    {
      "x": -11,
      "y": 17,
      "z": -6,
      "name": "Fullmetal_Plant_Leaves_Crystal_Cyan"
    },
    {
      "x": -11,
      "y": 26,
      "z": -6,
      "name": "Wood_Crystal_Branch_Corner"
    },
    {
      "x": -11,
      "y": 27,
      "z": -6,
      "name": "Fullmetal_Plant_Leaves_Crystal_Cyan"
    },
    {
      "x": -11,
      "y": 28,
      "z": -6,
      "name": "Fullmetal_Plant_Leaves_Crystal_Cyan"
    },
    {
      "x": -11,
      "y": 30,
      "z": -6,
      "name": "Fullmetal_Plant_Leaves_Crystal_Cyan"
    },
    {
      "x": -11,
      "y": 27,
      "z": -5,
      "name": "Fullmetal_Plant_Leaves_Crystal_Cyan"
    },
    {
      "x": -11,
      "y": 28,
      "z": -5,
      "name": "Fullmetal_Plant_Leaves_Crystal_Cyan"
    },
    {
      "x": -11,
      "y": 30,
      "z": -5,
      "name": "Fullmetal_Plant_Leaves_Crystal_Cyan"
    },
    {
      "x": -11,
      "y": 31,
      "z": -5,
      "name": "Fullmetal_Plant_Leaves_Crystal_Cyan"
    },
    {
      "x": -11,
      "y": 25,
      "z": -4,
      "name": "Fullmetal_Plant_Leaves_Crystal_Cyan"
    },
    {
      "x": -11,
      "y": 27,
      "z": -4,
      "name": "Fullmetal_Plant_Leaves_Crystal_Cyan"
    },
    {
      "x": -11,
      "y": 30,
      "z": -4,
      "name": "Fullmetal_Plant_Leaves_Crystal_Cyan"
    },
    {
      "x": -11,
      "y": 31,
      "z": -4,
      "name": "Fullmetal_Plant_Leaves_Crystal_Cyan"
    },
    {
      "x": -11,
      "y": 25,
      "z": -3,
      "name": "Fullmetal_Plant_Leaves_Crystal_Cyan"
    },
    {
      "x": -11,
      "y": 29,
      "z": -3,
      "name": "Fullmetal_Plant_Leaves_Crystal_Cyan"
    },
    {
      "x": -11,
      "y": 30,
      "z": -3,
      "name": "Fullmetal_Plant_Leaves_Crystal_Cyan"
    },
    {
      "x": -11,
      "y": 36,
      "z": -3,
      "name": "Fullmetal_Plant_Leaves_Crystal_Cyan"
    },
    {
      "x": -11,
      "y": 29,
      "z": -2,
      "name": "Wood_Crystal_Trunk_Full"
    },
    {
      "x": -11,
      "y": 30,
      "z": -2,
      "name": "Fullmetal_Plant_Leaves_Crystal_Cyan"
    },
    {
      "x": -11,
      "y": 32,
      "z": -2,
      "name": "Fullmetal_Plant_Leaves_Crystal_Cyan"
    },
    {
      "x": -11,
      "y": 35,
      "z": -2,
      "name": "Fullmetal_Plant_Leaves_Crystal_Cyan"
    },
    {
      "x": -11,
      "y": 29,
      "z": -1,
      "name": "Wood_Crystal_Trunk_Full"
    },
    {
      "x": -11,
      "y": 32,
      "z": -1,
      "name": "Fullmetal_Plant_Leaves_Crystal_Cyan"
    },
    {
      "x": -11,
      "y": 35,
      "z": -1,
      "name": "Fullmetal_Plant_Leaves_Crystal_Cyan"
    },
    {
      "x": -11,
      "y": 36,
      "z": -1,
      "name": "Fullmetal_Plant_Leaves_Crystal_Cyan"
    },
    {
      "x": -11,
      "y": 37,
      "z": -1,
      "name": "Fullmetal_Plant_Leaves_Crystal_Cyan"
    },
    {
      "x": -11,
      "y": -3,
      "z": 0,
      "name": "Wood_Crystal_Trunk"
    },
    {
      "x": -11,
      "y": -2,
      "z": 0,
      "name": "Wood_Crystal_Trunk_Full"
    },
    {
      "x": -11,
      "y": 29,
      "z": 0,
      "name": "Fullmetal_Plant_Leaves_Crystal_Cyan"
    },
    {
      "x": -11,
      "y": 30,
      "z": 0,
      "name": "Fullmetal_Plant_Leaves_Crystal_Cyan"
    },
    {
      "x": -11,
      "y": 35,
      "z": 0,
      "name": "Fullmetal_Plant_Leaves_Crystal_Cyan"
    },
    {
      "x": -11,
      "y": 36,
      "z": 0,
      "name": "Fullmetal_Plant_Leaves_Crystal_Cyan"
    },
    {
      "x": -11,
      "y": 37,
      "z": 0,
      "name": "Fullmetal_Plant_Leaves_Crystal_Cyan"
    },
    {
      "x": -11,
      "y": 38,
      "z": 0,
      "name": "Fullmetal_Plant_Leaves_Crystal_Cyan"
    },
    {
      "x": -11,
      "y": -4,
      "z": 1,
      "name": "Wood_Crystal_Roots"
    },
    {
      "x": -11,
      "y": -3,
      "z": 1,
      "name": "Wood_Crystal_Trunk"
    },
    {
      "x": -11,
      "y": -2,
      "z": 1,
      "name": "Wood_Crystal_Trunk_Full"
    },
    {
      "x": -11,
      "y": 30,
      "z": 1,
      "name": "Fullmetal_Plant_Leaves_Crystal_Cyan"
    },
    {
      "x": -11,
      "y": 35,
      "z": 1,
      "name": "Fullmetal_Plant_Leaves_Crystal_Cyan"
    },
    {
      "x": -11,
      "y": 37,
      "z": 1,
      "name": "Fullmetal_Plant_Leaves_Crystal_Cyan"
    },
    {
      "x": -11,
      "y": -3,
      "z": 2,
      "name": "Wood_Crystal_Trunk"
    },
    {
      "x": -11,
      "y": -2,
      "z": 2,
      "name": "Wood_Crystal_Trunk"
    },
    {
      "x": -11,
      "y": -1,
      "z": 2,
      "name": "Wood_Crystal_Trunk_Full"
    },
    {
      "x": -11,
      "y": 36,
      "z": 2,
      "name": "Fullmetal_Plant_Leaves_Crystal_Cyan"
    },
    {
      "x": -11,
      "y": 37,
      "z": 2,
      "name": "Fullmetal_Plant_Leaves_Crystal_Cyan"
    },
    {
      "x": -11,
      "y": 27,
      "z": 3,
      "name": "Fullmetal_Plant_Leaves_Crystal_Cyan"
    },
    {
      "x": -11,
      "y": 28,
      "z": 3,
      "name": "Fullmetal_Plant_Leaves_Crystal_Cyan"
    },
    {
      "x": -11,
      "y": 30,
      "z": 3,
      "name": "Wood_Crystal_Trunk_Full"
    },
    {
      "x": -11,
      "y": 31,
      "z": 3,
      "name": "Wood_Crystal_Trunk_Full"
    },
    {
      "x": -11,
      "y": 36,
      "z": 3,
      "name": "Fullmetal_Plant_Leaves_Crystal_Cyan"
    },
    {
      "x": -11,
      "y": 27,
      "z": 4,
      "name": "Fullmetal_Plant_Leaves_Crystal_Cyan"
    },
    {
      "x": -11,
      "y": 28,
      "z": 4,
      "name": "Fullmetal_Plant_Leaves_Crystal_Cyan"
    },
    {
      "x": -11,
      "y": 37,
      "z": 4,
      "name": "Fullmetal_Plant_Leaves_Crystal_Cyan"
    },
    {
      "x": -11,
      "y": 27,
      "z": 5,
      "name": "Fullmetal_Plant_Leaves_Crystal_Cyan"
    },
    {
      "x": -11,
      "y": 28,
      "z": 5,
      "name": "Fullmetal_Plant_Leaves_Crystal_Cyan"
    },
    {
      "x": -11,
      "y": 29,
      "z": 5,
      "name": "Fullmetal_Plant_Leaves_Crystal_Cyan"
    },
    {
      "x": -11,
      "y": 37,
      "z": 5,
      "name": "Fullmetal_Plant_Leaves_Crystal_Cyan"
    },
    {
      "x": -11,
      "y": 28,
      "z": 6,
      "name": "Fullmetal_Plant_Leaves_Crystal_Cyan"
    },
    {
      "x": -11,
      "y": 29,
      "z": 6,
      "name": "Fullmetal_Plant_Leaves_Crystal_Cyan"
    },
    {
      "x": -11,
      "y": 33,
      "z": 6,
      "name": "Fullmetal_Plant_Leaves_Crystal_Cyan"
    },
    {
      "x": -11,
      "y": 37,
      "z": 6,
      "name": "Fullmetal_Plant_Leaves_Crystal_Cyan"
    },
    {
      "x": -11,
      "y": 28,
      "z": 7,
      "name": "Fullmetal_Plant_Leaves_Crystal_Cyan"
    },
    {
      "x": -11,
      "y": 33,
      "z": 7,
      "name": "Fullmetal_Plant_Leaves_Crystal_Cyan"
    },
    {
      "x": -11,
      "y": 34,
      "z": 7,
      "name": "Fullmetal_Plant_Leaves_Crystal_Cyan"
    },
    {
      "x": -11,
      "y": 37,
      "z": 7,
      "name": "Fullmetal_Plant_Leaves_Crystal_Cyan"
    },
    {
      "x": -11,
      "y": 28,
      "z": 8,
      "name": "Fullmetal_Plant_Leaves_Crystal_Cyan"
    },
    {
      "x": -11,
      "y": 29,
      "z": 8,
      "name": "Fullmetal_Plant_Leaves_Crystal_Cyan"
    },
    {
      "x": -11,
      "y": 31,
      "z": 8,
      "name": "Fullmetal_Plant_Leaves_Crystal_Cyan"
    },
    {
      "x": -11,
      "y": 32,
      "z": 8,
      "name": "Fullmetal_Plant_Leaves_Crystal_Cyan"
    },
    {
      "x": -11,
      "y": 33,
      "z": 8,
      "name": "Fullmetal_Plant_Leaves_Crystal_Cyan"
    },
    {
      "x": -11,
      "y": 37,
      "z": 8,
      "name": "Fullmetal_Plant_Leaves_Crystal_Cyan"
    },
    {
      "x": -11,
      "y": 28,
      "z": 9,
      "name": "Fullmetal_Plant_Leaves_Crystal_Cyan"
    },
    {
      "x": -11,
      "y": 29,
      "z": 9,
      "name": "Fullmetal_Plant_Leaves_Crystal_Cyan"
    },
    {
      "x": -11,
      "y": 31,
      "z": 9,
      "name": "Fullmetal_Plant_Leaves_Crystal_Cyan"
    },
    {
      "x": -11,
      "y": 32,
      "z": 9,
      "name": "Fullmetal_Plant_Leaves_Crystal_Cyan"
    },
    {
      "x": -11,
      "y": 33,
      "z": 9,
      "name": "Fullmetal_Plant_Leaves_Crystal_Cyan"
    },
    {
      "x": -11,
      "y": 34,
      "z": 9,
      "name": "Fullmetal_Plant_Leaves_Crystal_Cyan"
    },
    {
      "x": -11,
      "y": 29,
      "z": 10,
      "name": "Fullmetal_Plant_Leaves_Crystal_Cyan"
    },
    {
      "x": -11,
      "y": 31,
      "z": 10,
      "name": "Fullmetal_Plant_Leaves_Crystal_Cyan"
    },
    {
      "x": -11,
      "y": 32,
      "z": 10,
      "name": "Fullmetal_Plant_Leaves_Crystal_Cyan"
    },
    {
      "x": -11,
      "y": 33,
      "z": 10,
      "name": "Fullmetal_Plant_Leaves_Crystal_Cyan"
    },
    {
      "x": -11,
      "y": 29,
      "z": 11,
      "name": "Fullmetal_Plant_Leaves_Crystal_Cyan"
    },
    {
      "x": -11,
      "y": 30,
      "z": 11,
      "name": "Fullmetal_Plant_Leaves_Crystal_Cyan"
    },
    {
      "x": -11,
      "y": 32,
      "z": 11,
      "name": "Fullmetal_Plant_Leaves_Crystal_Cyan"
    },
    {
      "x": -11,
      "y": 29,
      "z": 12,
      "name": "Fullmetal_Plant_Leaves_Crystal_Cyan"
    },
    {
      "x": -11,
      "y": 29,
      "z": 13,
      "name": "Fullmetal_Plant_Leaves_Crystal_Cyan"
    },
    {
      "x": -10,
      "y": 26,
      "z": -12,
      "name": "Fullmetal_Plant_Leaves_Crystal_Cyan"
    },
    {
      "x": -10,
      "y": 26,
      "z": -11,
      "name": "Fullmetal_Plant_Leaves_Crystal_Cyan"
    },
    {
      "x": -10,
      "y": 27,
      "z": -11,
      "name": "Fullmetal_Plant_Leaves_Crystal_Cyan"
    },
    {
      "x": -10,
      "y": 26,
      "z": -10,
      "name": "Fullmetal_Plant_Leaves_Crystal_Cyan"
    },
    {
      "x": -10,
      "y": 27,
      "z": -10,
      "name": "Fullmetal_Plant_Leaves_Crystal_Cyan"
    },
    {
      "x": -10,
      "y": 28,
      "z": -10,
      "name": "Fullmetal_Plant_Leaves_Crystal_Cyan"
    },
    {
      "x": -10,
      "y": 17,
      "z": -9,
      "name": "Fullmetal_Plant_Leaves_Crystal_Cyan"
    },
    {
      "x": -10,
      "y": 26,
      "z": -9,
      "name": "Fullmetal_Plant_Leaves_Crystal_Cyan"
    },
    {
      "x": -10,
      "y": 27,
      "z": -9,
      "name": "Fullmetal_Plant_Leaves_Crystal_Cyan"
    },
    {
      "x": -10,
      "y": 28,
      "z": -9,
      "name": "Fullmetal_Plant_Leaves_Crystal_Cyan"
    },
    {
      "x": -10,
      "y": 35,
      "z": -9,
      "name": "Fullmetal_Plant_Leaves_Crystal_Cyan"
    },
    {
      "x": -10,
      "y": 14,
      "z": -8,
      "name": "Fullmetal_Plant_Leaves_Crystal_Cyan"
    },
    {
      "x": -10,
      "y": 15,
      "z": -8,
      "name": "Fullmetal_Plant_Leaves_Crystal_Cyan"
    },
    {
      "x": -10,
      "y": 16,
      "z": -8,
      "name": "Fullmetal_Plant_Leaves_Crystal_Cyan"
    },
    {
      "x": -10,
      "y": 17,
      "z": -8,
      "name": "Fullmetal_Plant_Leaves_Crystal_Cyan"
    },
    {
      "x": -10,
      "y": 27,
      "z": -8,
      "name": "Fullmetal_Plant_Leaves_Crystal_Cyan"
    },
    {
      "x": -10,
      "y": 28,
      "z": -8,
      "name": "Fullmetal_Plant_Leaves_Crystal_Cyan"
    },
    {
      "x": -10,
      "y": 34,
      "z": -8,
      "name": "Fullmetal_Plant_Leaves_Crystal_Cyan"
    },
    {
      "x": -10,
      "y": 35,
      "z": -8,
      "name": "Fullmetal_Plant_Leaves_Crystal_Cyan"
    },
    {
      "x": -10,
      "y": 17,
      "z": -7,
      "name": "Fullmetal_Plant_Leaves_Crystal_Cyan"
    },
    {
      "x": -10,
      "y": 26,
      "z": -7,
      "name": "Wood_Crystal_Trunk_Full"
    },
    {
      "x": -10,
      "y": 27,
      "z": -7,
      "name": "Fullmetal_Plant_Leaves_Crystal_Cyan"
    },
    {
      "x": -10,
      "y": 35,
      "z": -7,
      "name": "Fullmetal_Plant_Leaves_Crystal_Cyan"
    },
    {
      "x": -10,
      "y": 16,
      "z": -6,
      "name": "Fullmetal_Plant_Leaves_Crystal_Cyan"
    },
    {
      "x": -10,
      "y": 17,
      "z": -6,
      "name": "Fullmetal_Plant_Leaves_Crystal_Cyan"
    },
    {
      "x": -10,
      "y": 28,
      "z": -6,
      "name": "Fullmetal_Plant_Leaves_Crystal_Cyan"
    },
    {
      "x": -10,
      "y": 30,
      "z": -6,
      "name": "Fullmetal_Plant_Leaves_Crystal_Cyan"
    },
    {
      "x": -10,
      "y": 17,
      "z": -5,
      "name": "Fullmetal_Plant_Leaves_Crystal_Cyan"
    },
    {
      "x": -10,
      "y": 27,
      "z": -5,
      "name": "Fullmetal_Plant_Leaves_Crystal_Cyan"
    },
    {
      "x": -10,
      "y": 28,
      "z": -5,
      "name": "Fullmetal_Plant_Leaves_Crystal_Cyan"
    },
    {
      "x": -10,
      "y": 30,
      "z": -5,
      "name": "Fullmetal_Plant_Leaves_Crystal_Cyan"
    },
    {
      "x": -10,
      "y": 31,
      "z": -5,
      "name": "Fullmetal_Plant_Leaves_Crystal_Cyan"
    },
    {
      "x": -10,
      "y": 36,
      "z": -5,
      "name": "Fullmetal_Plant_Leaves_Crystal_Cyan"
    },
    {
      "x": -10,
      "y": 17,
      "z": -4,
      "name": "Fullmetal_Plant_Leaves_Crystal_Cyan"
    },
    {
      "x": -10,
      "y": 25,
      "z": -4,
      "name": "Fullmetal_Plant_Leaves_Crystal_Cyan"
    },
    {
      "x": -10,
      "y": 27,
      "z": -4,
      "name": "Fullmetal_Plant_Leaves_Crystal_Cyan"
    },
    {
      "x": -10,
      "y": 28,
      "z": -4,
      "name": "Fullmetal_Plant_Leaves_Crystal_Cyan"
    },
    {
      "x": -10,
      "y": 30,
      "z": -4,
      "name": "Fullmetal_Plant_Leaves_Crystal_Cyan"
    },
    {
      "x": -10,
      "y": 31,
      "z": -4,
      "name": "Fullmetal_Plant_Leaves_Crystal_Cyan"
    },
    {
      "x": -10,
      "y": 32,
      "z": -4,
      "name": "Fullmetal_Plant_Leaves_Crystal_Cyan"
    },
    {
      "x": -10,
      "y": 36,
      "z": -4,
      "name": "Fullmetal_Plant_Leaves_Crystal_Cyan"
    },
    {
      "x": -10,
      "y": 16,
      "z": -3,
      "name": "Fullmetal_Plant_Leaves_Crystal_Cyan"
    },
    {
      "x": -10,
      "y": 24,
      "z": -3,
      "name": "Fullmetal_Plant_Leaves_Crystal_Cyan"
    },
    {
      "x": -10,
      "y": 25,
      "z": -3,
      "name": "Fullmetal_Plant_Leaves_Crystal_Cyan"
    },
    {
      "x": -10,
      "y": 26,
      "z": -3,
      "name": "Fullmetal_Plant_Leaves_Crystal_Cyan"
    },
    {
      "x": -10,
      "y": 27,
      "z": -3,
      "name": "Fullmetal_Plant_Leaves_Crystal_Cyan"
    },
    {
      "x": -10,
      "y": 30,
      "z": -3,
      "name": "Fullmetal_Plant_Leaves_Crystal_Cyan"
    },
    {
      "x": -10,
      "y": 36,
      "z": -3,
      "name": "Fullmetal_Plant_Leaves_Crystal_Cyan"
    },
    {
      "x": -10,
      "y": 37,
      "z": -3,
      "name": "Fullmetal_Plant_Leaves_Crystal_Cyan"
    },
    {
      "x": -10,
      "y": 16,
      "z": -2,
      "name": "Fullmetal_Plant_Leaves_Crystal_Cyan"
    },
    {
      "x": -10,
      "y": 25,
      "z": -2,
      "name": "Fullmetal_Plant_Leaves_Crystal_Cyan"
    },
    {
      "x": -10,
      "y": 30,
      "z": -2,
      "name": "Fullmetal_Plant_Leaves_Crystal_Cyan"
    },
    {
      "x": -10,
      "y": 35,
      "z": -2,
      "name": "Fullmetal_Plant_Leaves_Crystal_Cyan"
    },
    {
      "x": -10,
      "y": 36,
      "z": -2,
      "name": "Fullmetal_Plant_Leaves_Crystal_Cyan"
    },
    {
      "x": -10,
      "y": 37,
      "z": -2,
      "name": "Fullmetal_Plant_Leaves_Crystal_Cyan"
    },
    {
      "x": -10,
      "y": 29,
      "z": -1,
      "name": "Wood_Crystal_Trunk_Full"
    },
    {
      "x": -10,
      "y": 35,
      "z": -1,
      "name": "Fullmetal_Plant_Leaves_Crystal_Cyan"
    },
    {
      "x": -10,
      "y": 37,
      "z": -1,
      "name": "Fullmetal_Plant_Leaves_Crystal_Cyan"
    },
    {
      "x": -10,
      "y": 38,
      "z": -1,
      "name": "Fullmetal_Plant_Leaves_Crystal_Cyan"
    },
    {
      "x": -10,
      "y": -2,
      "z": 0,
      "name": "Wood_Crystal_Trunk_Full"
    },
    {
      "x": -10,
      "y": 35,
      "z": 0,
      "name": "Fullmetal_Plant_Leaves_Crystal_Cyan"
    },
    {
      "x": -10,
      "y": 36,
      "z": 0,
      "name": "Fullmetal_Plant_Leaves_Crystal_Cyan"
    },
    {
      "x": -10,
      "y": 37,
      "z": 0,
      "name": "Fullmetal_Plant_Leaves_Crystal_Cyan"
    },
    {
      "x": -10,
      "y": 38,
      "z": 0,
      "name": "Fullmetal_Plant_Leaves_Crystal_Cyan"
    },
    {
      "x": -10,
      "y": -3,
      "z": 1,
      "name": "Wood_Crystal_Trunk"
    },
    {
      "x": -10,
      "y": -2,
      "z": 1,
      "name": "Wood_Crystal_Trunk_Full"
    },
    {
      "x": -10,
      "y": 26,
      "z": 1,
      "name": "Fullmetal_Plant_Leaves_Crystal_Cyan"
    },
    {
      "x": -10,
      "y": 30,
      "z": 1,
      "name": "Fullmetal_Plant_Leaves_Crystal_Cyan"
    },
    {
      "x": -10,
      "y": 35,
      "z": 1,
      "name": "Fullmetal_Plant_Leaves_Crystal_Cyan"
    },
    {
      "x": -10,
      "y": 36,
      "z": 1,
      "name": "Fullmetal_Plant_Leaves_Crystal_Cyan"
    },
    {
      "x": -10,
      "y": 37,
      "z": 1,
      "name": "Fullmetal_Plant_Leaves_Crystal_Cyan"
    },
    {
      "x": -10,
      "y": -4,
      "z": 2,
      "name": "Wood_Crystal_Roots"
    },
    {
      "x": -10,
      "y": -3,
      "z": 2,
      "name": "Wood_Crystal_Trunk"
    },
    {
      "x": -10,
      "y": -2,
      "z": 2,
      "name": "Wood_Crystal_Trunk"
    },
    {
      "x": -10,
      "y": -1,
      "z": 2,
      "name": "Wood_Crystal_Trunk_Full"
    },
    {
      "x": -10,
      "y": 27,
      "z": 2,
      "name": "Fullmetal_Plant_Leaves_Crystal_Cyan"
    },
    {
      "x": -10,
      "y": 30,
      "z": 2,
      "name": "Wood_Crystal_Trunk_Full"
    },
    {
      "x": -10,
      "y": 36,
      "z": 2,
      "name": "Fullmetal_Plant_Leaves_Crystal_Cyan"
    },
    {
      "x": -10,
      "y": 37,
      "z": 2,
      "name": "Fullmetal_Plant_Leaves_Crystal_Cyan"
    },
    {
      "x": -10,
      "y": -2,
      "z": 3,
      "name": "Wood_Crystal_Trunk"
    },
    {
      "x": -10,
      "y": -1,
      "z": 3,
      "name": "Wood_Crystal_Trunk_Full"
    },
    {
      "x": -10,
      "y": 27,
      "z": 3,
      "name": "Fullmetal_Plant_Leaves_Crystal_Cyan"
    },
    {
      "x": -10,
      "y": 28,
      "z": 3,
      "name": "Fullmetal_Plant_Leaves_Crystal_Cyan"
    },
    {
      "x": -10,
      "y": 30,
      "z": 3,
      "name": "Wood_Crystal_Trunk_Full"
    },
    {
      "x": -10,
      "y": 36,
      "z": 3,
      "name": "Fullmetal_Plant_Leaves_Crystal_Cyan"
    },
    {
      "x": -10,
      "y": 27,
      "z": 4,
      "name": "Fullmetal_Plant_Leaves_Crystal_Cyan"
    },
    {
      "x": -10,
      "y": 28,
      "z": 4,
      "name": "Fullmetal_Plant_Leaves_Crystal_Cyan"
    },
    {
      "x": -10,
      "y": 36,
      "z": 4,
      "name": "Wood_Crystal_Branch_Corner",
      "rotation": 3
    },
    {
      "x": -10,
      "y": 27,
      "z": 5,
      "name": "Fullmetal_Plant_Leaves_Crystal_Cyan"
    },
    {
      "x": -10,
      "y": 28,
      "z": 5,
      "name": "Fullmetal_Plant_Leaves_Crystal_Cyan"
    },
    {
      "x": -10,
      "y": 30,
      "z": 5,
      "name": "Wood_Crystal_Trunk_Full"
    },
    {
      "x": -10,
      "y": 36,
      "z": 5,
      "name": "Fullmetal_Plant_Leaves_Crystal_Cyan"
    },
    {
      "x": -10,
      "y": 37,
      "z": 5,
      "name": "Fullmetal_Plant_Leaves_Crystal_Cyan"
    },
    {
      "x": -10,
      "y": 26,
      "z": 6,
      "name": "Wood_Crystal_Roots"
    },
    {
      "x": -10,
      "y": 27,
      "z": 6,
      "name": "Wood_Crystal_Trunk_Full"
    },
    {
      "x": -10,
      "y": 28,
      "z": 6,
      "name": "Fullmetal_Plant_Leaves_Crystal_Cyan"
    },
    {
      "x": -10,
      "y": 33,
      "z": 6,
      "name": "Fullmetal_Plant_Leaves_Crystal_Cyan"
    },
    {
      "x": -10,
      "y": 18,
      "z": 7,
      "name": "Fullmetal_Plant_Leaves_Crystal_Cyan"
    },
    {
      "x": -10,
      "y": 28,
      "z": 7,
      "name": "Fullmetal_Plant_Leaves_Crystal_Cyan"
    },
    {
      "x": -10,
      "y": 30,
      "z": 7,
      "name": "Fullmetal_Plant_Leaves_Crystal_Cyan"
    },
    {
      "x": -10,
      "y": 31,
      "z": 7,
      "name": "Fullmetal_Plant_Leaves_Crystal_Cyan"
    },
    {
      "x": -10,
      "y": 32,
      "z": 7,
      "name": "Fullmetal_Plant_Leaves_Crystal_Cyan"
    },
    {
      "x": -10,
      "y": 33,
      "z": 7,
      "name": "Fullmetal_Plant_Leaves_Crystal_Cyan"
    },
    {
      "x": -10,
      "y": 37,
      "z": 7,
      "name": "Fullmetal_Plant_Leaves_Crystal_Cyan"
    },
    {
      "x": -10,
      "y": 18,
      "z": 8,
      "name": "Fullmetal_Plant_Leaves_Crystal_Cyan"
    },
    {
      "x": -10,
      "y": 28,
      "z": 8,
      "name": "Fullmetal_Plant_Leaves_Crystal_Cyan"
    },
    {
      "x": -10,
      "y": 31,
      "z": 8,
      "name": "Fullmetal_Plant_Leaves_Crystal_Cyan"
    },
    {
      "x": -10,
      "y": 32,
      "z": 8,
      "name": "Fullmetal_Plant_Leaves_Crystal_Cyan"
    },
    {
      "x": -10,
      "y": 33,
      "z": 8,
      "name": "Fullmetal_Plant_Leaves_Crystal_Cyan"
    },
    {
      "x": -10,
      "y": 34,
      "z": 8,
      "name": "Fullmetal_Plant_Leaves_Crystal_Cyan"
    },
    {
      "x": -10,
      "y": 18,
      "z": 9,
      "name": "Fullmetal_Plant_Leaves_Crystal_Cyan"
    },
    {
      "x": -10,
      "y": 28,
      "z": 9,
      "name": "Fullmetal_Plant_Leaves_Crystal_Cyan"
    },
    {
      "x": -10,
      "y": 31,
      "z": 9,
      "name": "Fullmetal_Plant_Leaves_Crystal_Cyan"
    },
    {
      "x": -10,
      "y": 32,
      "z": 9,
      "name": "Fullmetal_Plant_Leaves_Crystal_Cyan"
    },
    {
      "x": -10,
      "y": 33,
      "z": 9,
      "name": "Fullmetal_Plant_Leaves_Crystal_Cyan"
    },
    {
      "x": -10,
      "y": 28,
      "z": 10,
      "name": "Fullmetal_Plant_Leaves_Crystal_Cyan"
    },
    {
      "x": -10,
      "y": 29,
      "z": 10,
      "name": "Fullmetal_Plant_Leaves_Crystal_Cyan"
    },
    {
      "x": -10,
      "y": 30,
      "z": 10,
      "name": "Fullmetal_Plant_Leaves_Crystal_Cyan"
    },
    {
      "x": -10,
      "y": 31,
      "z": 10,
      "name": "Fullmetal_Plant_Leaves_Crystal_Cyan"
    },
    {
      "x": -10,
      "y": 32,
      "z": 10,
      "name": "Fullmetal_Plant_Leaves_Crystal_Cyan"
    },
    {
      "x": -10,
      "y": 29,
      "z": 11,
      "name": "Fullmetal_Plant_Leaves_Crystal_Cyan"
    },
    {
      "x": -10,
      "y": 30,
      "z": 11,
      "name": "Fullmetal_Plant_Leaves_Crystal_Cyan"
    },
    {
      "x": -10,
      "y": 29,
      "z": 12,
      "name": "Fullmetal_Plant_Leaves_Crystal_Cyan"
    },
    {
      "x": -10,
      "y": 30,
      "z": 12,
      "name": "Fullmetal_Plant_Leaves_Crystal_Cyan"
    },
    {
      "x": -10,
      "y": 29,
      "z": 13,
      "name": "Fullmetal_Plant_Leaves_Crystal_Cyan"
    },
    {
      "x": -10,
      "y": 30,
      "z": 13,
      "name": "Fullmetal_Plant_Leaves_Crystal_Cyan"
    },
    {
      "x": -9,
      "y": 26,
      "z": -13,
      "name": "Fullmetal_Plant_Leaves_Crystal_Cyan"
    },
    {
      "x": -9,
      "y": 26,
      "z": -12,
      "name": "Fullmetal_Plant_Leaves_Crystal_Cyan"
    },
    {
      "x": -9,
      "y": 27,
      "z": -12,
      "name": "Fullmetal_Plant_Leaves_Crystal_Cyan"
    },
    {
      "x": -9,
      "y": 25,
      "z": -11,
      "name": "Fullmetal_Plant_Leaves_Crystal_Cyan"
    },
    {
      "x": -9,
      "y": 26,
      "z": -11,
      "name": "Fullmetal_Plant_Leaves_Crystal_Cyan"
    },
    {
      "x": -9,
      "y": 27,
      "z": -11,
      "name": "Fullmetal_Plant_Leaves_Crystal_Cyan"
    },
    {
      "x": -9,
      "y": 17,
      "z": -10,
      "name": "Fullmetal_Plant_Leaves_Crystal_Cyan"
    },
    {
      "x": -9,
      "y": 24,
      "z": -10,
      "name": "Plant_Fruit_Azure",
      "rotation": 8
    },
    {
      "x": -9,
      "y": 25,
      "z": -10,
      "name": "Fullmetal_Plant_Leaves_Crystal_Cyan"
    },
    {
      "x": -9,
      "y": 26,
      "z": -10,
      "name": "Fullmetal_Plant_Leaves_Crystal_Cyan"
    },
    {
      "x": -9,
      "y": 27,
      "z": -10,
      "name": "Fullmetal_Plant_Leaves_Crystal_Cyan"
    },
    {
      "x": -9,
      "y": 28,
      "z": -10,
      "name": "Fullmetal_Plant_Leaves_Crystal_Cyan"
    },
    {
      "x": -9,
      "y": 35,
      "z": -10,
      "name": "Fullmetal_Plant_Leaves_Crystal_Cyan"
    },
    {
      "x": -9,
      "y": 16,
      "z": -9,
      "name": "Fullmetal_Plant_Leaves_Crystal_Cyan"
    },
    {
      "x": -9,
      "y": 17,
      "z": -9,
      "name": "Fullmetal_Plant_Leaves_Crystal_Cyan"
    },
    {
      "x": -9,
      "y": 26,
      "z": -9,
      "name": "Wood_Crystal_Branch_Corner",
      "rotation": 2
    },
    {
      "x": -9,
      "y": 27,
      "z": -9,
      "name": "Fullmetal_Plant_Leaves_Crystal_Cyan"
    },
    {
      "x": -9,
      "y": 28,
      "z": -9,
      "name": "Fullmetal_Plant_Leaves_Crystal_Cyan"
    },
    {
      "x": -9,
      "y": 30,
      "z": -9,
      "name": "Fullmetal_Plant_Leaves_Crystal_Cyan"
    },
    {
      "x": -9,
      "y": 35,
      "z": -9,
      "name": "Fullmetal_Plant_Leaves_Crystal_Cyan"
    },
    {
      "x": -9,
      "y": 16,
      "z": -8,
      "name": "Fullmetal_Plant_Leaves_Crystal_Cyan"
    },
    {
      "x": -9,
      "y": 17,
      "z": -8,
      "name": "Fullmetal_Plant_Leaves_Crystal_Cyan"
    },
    {
      "x": -9,
      "y": 26,
      "z": -8,
      "name": "Wood_Crystal_Trunk_Full"
    },
    {
      "x": -9,
      "y": 27,
      "z": -8,
      "name": "Fullmetal_Plant_Leaves_Crystal_Cyan"
    },
    {
      "x": -9,
      "y": 28,
      "z": -8,
      "name": "Fullmetal_Plant_Leaves_Crystal_Cyan"
    },
    {
      "x": -9,
      "y": 30,
      "z": -8,
      "name": "Fullmetal_Plant_Leaves_Crystal_Cyan"
    },
    {
      "x": -9,
      "y": 34,
      "z": -8,
      "name": "Fullmetal_Plant_Leaves_Crystal_Cyan"
    },
    {
      "x": -9,
      "y": 35,
      "z": -8,
      "name": "Fullmetal_Plant_Leaves_Crystal_Cyan"
    },
    {
      "x": -9,
      "y": 36,
      "z": -8,
      "name": "Fullmetal_Plant_Leaves_Crystal_Cyan"
    },
    {
      "x": -9,
      "y": 16,
      "z": -7,
      "name": "Fullmetal_Plant_Leaves_Crystal_Cyan"
    },
    {
      "x": -9,
      "y": 17,
      "z": -7,
      "name": "Fullmetal_Plant_Leaves_Crystal_Cyan"
    },
    {
      "x": -9,
      "y": 18,
      "z": -7,
      "name": "Fullmetal_Plant_Leaves_Crystal_Cyan"
    },
    {
      "x": -9,
      "y": 25,
      "z": -7,
      "name": "Wood_Crystal_Roots"
    },
    {
      "x": -9,
      "y": 26,
      "z": -7,
      "name": "Wood_Crystal_Trunk_Full"
    },
    {
      "x": -9,
      "y": 27,
      "z": -7,
      "name": "Fullmetal_Plant_Leaves_Crystal_Cyan"
    },
    {
      "x": -9,
      "y": 28,
      "z": -7,
      "name": "Fullmetal_Plant_Leaves_Crystal_Cyan"
    },
    {
      "x": -9,
      "y": 34,
      "z": -7,
      "name": "Fullmetal_Plant_Leaves_Crystal_Cyan"
    },
    {
      "x": -9,
      "y": 35,
      "z": -7,
      "name": "Fullmetal_Plant_Leaves_Crystal_Cyan"
    },
    {
      "x": -9,
      "y": 16,
      "z": -6,
      "name": "Fullmetal_Plant_Leaves_Crystal_Cyan"
    },
    {
      "x": -9,
      "y": 17,
      "z": -6,
      "name": "Fullmetal_Plant_Leaves_Crystal_Cyan"
    },
    {
      "x": -9,
      "y": 25,
      "z": -6,
      "name": "Wood_Crystal_Roots"
    },
    {
      "x": -9,
      "y": 26,
      "z": -6,
      "name": "Wood_Crystal_Trunk_Full"
    },
    {
      "x": -9,
      "y": 28,
      "z": -6,
      "name": "Fullmetal_Plant_Leaves_Crystal_Cyan"
    },
    {
      "x": -9,
      "y": 35,
      "z": -6,
      "name": "Fullmetal_Plant_Leaves_Crystal_Cyan"
    },
    {
      "x": -9,
      "y": 17,
      "z": -5,
      "name": "Fullmetal_Plant_Leaves_Crystal_Cyan"
    },
    {
      "x": -9,
      "y": 28,
      "z": -5,
      "name": "Fullmetal_Plant_Leaves_Crystal_Cyan"
    },
    {
      "x": -9,
      "y": 35,
      "z": -5,
      "name": "Fullmetal_Plant_Leaves_Crystal_Cyan"
    },
    {
      "x": -9,
      "y": 16,
      "z": -4,
      "name": "Fullmetal_Plant_Leaves_Crystal_Cyan"
    },
    {
      "x": -9,
      "y": 17,
      "z": -4,
      "name": "Fullmetal_Plant_Leaves_Crystal_Cyan"
    },
    {
      "x": -9,
      "y": 25,
      "z": -4,
      "name": "Fullmetal_Plant_Leaves_Crystal_Cyan"
    },
    {
      "x": -9,
      "y": 27,
      "z": -4,
      "name": "Fullmetal_Plant_Leaves_Crystal_Cyan"
    },
    {
      "x": -9,
      "y": 31,
      "z": -4,
      "name": "Fullmetal_Plant_Leaves_Crystal_Cyan"
    },
    {
      "x": -9,
      "y": 36,
      "z": -4,
      "name": "Fullmetal_Plant_Leaves_Crystal_Cyan"
    },
    {
      "x": -9,
      "y": 13,
      "z": -3,
      "name": "Fullmetal_Plant_Leaves_Crystal_Cyan"
    },
    {
      "x": -9,
      "y": 14,
      "z": -3,
      "name": "Fullmetal_Plant_Leaves_Crystal_Cyan"
    },
    {
      "x": -9,
      "y": 15,
      "z": -3,
      "name": "Fullmetal_Plant_Leaves_Crystal_Cyan"
    },
    {
      "x": -9,
      "y": 16,
      "z": -3,
      "name": "Fullmetal_Plant_Leaves_Crystal_Cyan"
    },
    {
      "x": -9,
      "y": 24,
      "z": -3,
      "name": "Fullmetal_Plant_Leaves_Crystal_Cyan"
    },
    {
      "x": -9,
      "y": 25,
      "z": -3,
      "name": "Fullmetal_Plant_Leaves_Crystal_Cyan"
    },
    {
      "x": -9,
      "y": 26,
      "z": -3,
      "name": "Fullmetal_Plant_Leaves_Crystal_Cyan"
    },
    {
      "x": -9,
      "y": 27,
      "z": -3,
      "name": "Fullmetal_Plant_Leaves_Crystal_Cyan"
    },
    {
      "x": -9,
      "y": 30,
      "z": -3,
      "name": "Fullmetal_Plant_Leaves_Crystal_Cyan"
    },
    {
      "x": -9,
      "y": 35,
      "z": -3,
      "name": "Fullmetal_Plant_Leaves_Crystal_Cyan"
    },
    {
      "x": -9,
      "y": 36,
      "z": -3,
      "name": "Fullmetal_Plant_Leaves_Crystal_Cyan"
    },
    {
      "x": -9,
      "y": 16,
      "z": -2,
      "name": "Fullmetal_Plant_Leaves_Crystal_Cyan"
    },
    {
      "x": -9,
      "y": 25,
      "z": -2,
      "name": "Fullmetal_Plant_Leaves_Crystal_Cyan"
    },
    {
      "x": -9,
      "y": 26,
      "z": -2,
      "name": "Fullmetal_Plant_Leaves_Crystal_Cyan"
    },
    {
      "x": -9,
      "y": 30,
      "z": -2,
      "name": "Fullmetal_Plant_Leaves_Crystal_Cyan"
    },
    {
      "x": -9,
      "y": 35,
      "z": -2,
      "name": "Fullmetal_Plant_Leaves_Crystal_Cyan"
    },
    {
      "x": -9,
      "y": 36,
      "z": -2,
      "name": "Fullmetal_Plant_Leaves_Crystal_Cyan"
    },
    {
      "x": -9,
      "y": 38,
      "z": -2,
      "name": "Fullmetal_Plant_Leaves_Crystal_Cyan"
    },
    {
      "x": -9,
      "y": 16,
      "z": -1,
      "name": "Fullmetal_Plant_Leaves_Crystal_Cyan"
    },
    {
      "x": -9,
      "y": 25,
      "z": -1,
      "name": "Fullmetal_Plant_Leaves_Crystal_Cyan"
    },
    {
      "x": -9,
      "y": 29,
      "z": -1,
      "name": "Wood_Crystal_Trunk_Full"
    },
    {
      "x": -9,
      "y": 35,
      "z": -1,
      "name": "Wood_Crystal_Trunk_Full"
    },
    {
      "x": -9,
      "y": 36,
      "z": -1,
      "name": "Fullmetal_Plant_Leaves_Crystal_Cyan"
    },
    {
      "x": -9,
      "y": 37,
      "z": -1,
      "name": "Fullmetal_Plant_Leaves_Crystal_Cyan"
    },
    {
      "x": -9,
      "y": 38,
      "z": -1,
      "name": "Fullmetal_Plant_Leaves_Crystal_Cyan"
    },
    {
      "x": -9,
      "y": 16,
      "z": 0,
      "name": "Fullmetal_Plant_Leaves_Crystal_Cyan"
    },
    {
      "x": -9,
      "y": 35,
      "z": 0,
      "name": "Fullmetal_Plant_Leaves_Crystal_Cyan"
    },
    {
      "x": -9,
      "y": 36,
      "z": 0,
      "name": "Fullmetal_Plant_Leaves_Crystal_Cyan"
    },
    {
      "x": -9,
      "y": 37,
      "z": 0,
      "name": "Fullmetal_Plant_Leaves_Crystal_Cyan"
    },
    {
      "x": -9,
      "y": 38,
      "z": 0,
      "name": "Fullmetal_Plant_Leaves_Crystal_Cyan"
    },
    {
      "x": -9,
      "y": -3,
      "z": 1,
      "name": "Wood_Crystal_Roots"
    },
    {
      "x": -9,
      "y": -2,
      "z": 1,
      "name": "Wood_Crystal_Trunk"
    },
    {
      "x": -9,
      "y": -1,
      "z": 1,
      "name": "Wood_Crystal_Trunk_Full"
    },
    {
      "x": -9,
      "y": 16,
      "z": 1,
      "name": "Fullmetal_Plant_Leaves_Crystal_Cyan"
    },
    {
      "x": -9,
      "y": 25,
      "z": 1,
      "name": "Fullmetal_Plant_Leaves_Crystal_Cyan"
    },
    {
      "x": -9,
      "y": 26,
      "z": 1,
      "name": "Fullmetal_Plant_Leaves_Crystal_Cyan"
    },
    {
      "x": -9,
      "y": 27,
      "z": 1,
      "name": "Fullmetal_Plant_Leaves_Crystal_Cyan"
    },
    {
      "x": -9,
      "y": 35,
      "z": 1,
      "name": "Fullmetal_Plant_Leaves_Crystal_Cyan"
    },
    {
      "x": -9,
      "y": 36,
      "z": 1,
      "name": "Fullmetal_Plant_Leaves_Crystal_Cyan"
    },
    {
      "x": -9,
      "y": 37,
      "z": 1,
      "name": "Fullmetal_Plant_Leaves_Crystal_Cyan"
    },
    {
      "x": -9,
      "y": 38,
      "z": 1,
      "name": "Fullmetal_Plant_Leaves_Crystal_Cyan"
    },
    {
      "x": -9,
      "y": -3,
      "z": 2,
      "name": "Wood_Crystal_Trunk"
    },
    {
      "x": -9,
      "y": -2,
      "z": 2,
      "name": "Wood_Crystal_Trunk"
    },
    {
      "x": -9,
      "y": -1,
      "z": 2,
      "name": "Wood_Crystal_Trunk"
    },
    {
      "x": -9,
      "y": 0,
      "z": 2,
      "name": "Wood_Crystal_Trunk_Full"
    },
    {
      "x": -9,
      "y": 25,
      "z": 2,
      "name": "Fullmetal_Plant_Leaves_Crystal_Cyan"
    },
    {
      "x": -9,
      "y": 26,
      "z": 2,
      "name": "Fullmetal_Plant_Leaves_Crystal_Cyan"
    },
    {
      "x": -9,
      "y": 27,
      "z": 2,
      "name": "Fullmetal_Plant_Leaves_Crystal_Cyan"
    },
    {
      "x": -9,
      "y": 30,
      "z": 2,
      "name": "Wood_Crystal_Trunk_Full"
    },
    {
      "x": -9,
      "y": 38,
      "z": 2,
      "name": "Fullmetal_Plant_Leaves_Crystal_Cyan"
    },
    {
      "x": -9,
      "y": -3,
      "z": 3,
      "name": "Wood_Crystal_Trunk"
    },
    {
      "x": -9,
      "y": -2,
      "z": 3,
      "name": "Wood_Crystal_Trunk"
    },
    {
      "x": -9,
      "y": -1,
      "z": 3,
      "name": "Wood_Crystal_Trunk"
    },
    {
      "x": -9,
      "y": 0,
      "z": 3,
      "name": "Wood_Crystal_Trunk_Full"
    },
    {
      "x": -9,
      "y": 25,
      "z": 3,
      "name": "Fullmetal_Plant_Leaves_Crystal_Cyan"
    },
    {
      "x": -9,
      "y": 26,
      "z": 3,
      "name": "Fullmetal_Plant_Leaves_Crystal_Cyan"
    },
    {
      "x": -9,
      "y": 27,
      "z": 3,
      "name": "Fullmetal_Plant_Leaves_Crystal_Cyan"
    },
    {
      "x": -9,
      "y": 30,
      "z": 3,
      "name": "Wood_Crystal_Trunk_Full"
    },
    {
      "x": -9,
      "y": 37,
      "z": 3,
      "name": "Fullmetal_Plant_Leaves_Crystal_Cyan"
    },
    {
      "x": -9,
      "y": 38,
      "z": 3,
      "name": "Fullmetal_Plant_Leaves_Crystal_Cyan"
    },
    {
      "x": -9,
      "y": 17,
      "z": 4,
      "name": "Fullmetal_Plant_Leaves_Crystal_Cyan"
    },
    {
      "x": -9,
      "y": 27,
      "z": 4,
      "name": "Fullmetal_Plant_Leaves_Crystal_Cyan"
    },
    {
      "x": -9,
      "y": 28,
      "z": 4,
      "name": "Fullmetal_Plant_Leaves_Crystal_Cyan"
    },
    {
      "x": -9,
      "y": 30,
      "z": 4,
      "name": "Wood_Crystal_Trunk_Full"
    },
    {
      "x": -9,
      "y": 32,
      "z": 4,
      "name": "Fullmetal_Plant_Leaves_Crystal_Cyan"
    },
    {
      "x": -9,
      "y": 36,
      "z": 4,
      "name": "Wood_Crystal_Branch_Long",
      "rotation": 5
    },
    {
      "x": -9,
      "y": 37,
      "z": 4,
      "name": "Fullmetal_Plant_Leaves_Crystal_Cyan"
    },
    {
      "x": -9,
      "y": 17,
      "z": 5,
      "name": "Fullmetal_Plant_Leaves_Crystal_Cyan"
    },
    {
      "x": -9,
      "y": 18,
      "z": 5,
      "name": "Fullmetal_Plant_Leaves_Crystal_Cyan"
    },
    {
      "x": -9,
      "y": 27,
      "z": 5,
      "name": "Fullmetal_Plant_Leaves_Crystal_Cyan"
    },
    {
      "x": -9,
      "y": 28,
      "z": 5,
      "name": "Fullmetal_Plant_Leaves_Crystal_Cyan"
    },
    {
      "x": -9,
      "y": 30,
      "z": 5,
      "name": "Wood_Crystal_Trunk_Full"
    },
    {
      "x": -9,
      "y": 32,
      "z": 5,
      "name": "Fullmetal_Plant_Leaves_Crystal_Cyan"
    },
    {
      "x": -9,
      "y": 33,
      "z": 5,
      "name": "Fullmetal_Plant_Leaves_Crystal_Cyan"
    },
    {
      "x": -9,
      "y": 36,
      "z": 5,
      "name": "Fullmetal_Plant_Leaves_Crystal_Cyan"
    },
    {
      "x": -9,
      "y": 37,
      "z": 5,
      "name": "Fullmetal_Plant_Leaves_Crystal_Cyan"
    },
    {
      "x": -9,
      "y": 16,
      "z": 6,
      "name": "Fullmetal_Plant_Leaves_Crystal_Cyan"
    },
    {
      "x": -9,
      "y": 18,
      "z": 6,
      "name": "Fullmetal_Plant_Leaves_Crystal_Cyan"
    },
    {
      "x": -9,
      "y": 26,
      "z": 6,
      "name": "Wood_Crystal_Roots"
    },
    {
      "x": -9,
      "y": 27,
      "z": 6,
      "name": "Wood_Crystal_Trunk_Full"
    },
    {
      "x": -9,
      "y": 28,
      "z": 6,
      "name": "Fullmetal_Plant_Leaves_Crystal_Cyan"
    },
    {
      "x": -9,
      "y": 30,
      "z": 6,
      "name": "Wood_Crystal_Trunk_Full"
    },
    {
      "x": -9,
      "y": 31,
      "z": 6,
      "name": "Fullmetal_Plant_Leaves_Crystal_Cyan"
    },
    {
      "x": -9,
      "y": 32,
      "z": 6,
      "name": "Fullmetal_Plant_Leaves_Crystal_Cyan"
    },
    {
      "x": -9,
      "y": 37,
      "z": 6,
      "name": "Fullmetal_Plant_Leaves_Crystal_Cyan"
    },
    {
      "x": -9,
      "y": 38,
      "z": 6,
      "name": "Fullmetal_Plant_Leaves_Crystal_Cyan"
    },
    {
      "x": -9,
      "y": 18,
      "z": 7,
      "name": "Fullmetal_Plant_Leaves_Crystal_Cyan"
    },
    {
      "x": -9,
      "y": 28,
      "z": 7,
      "name": "Fullmetal_Plant_Leaves_Crystal_Cyan"
    },
    {
      "x": -9,
      "y": 30,
      "z": 7,
      "name": "Wood_Crystal_Trunk_Full"
    },
    {
      "x": -9,
      "y": 31,
      "z": 7,
      "name": "Fullmetal_Plant_Leaves_Crystal_Cyan"
    },
    {
      "x": -9,
      "y": 32,
      "z": 7,
      "name": "Fullmetal_Plant_Leaves_Crystal_Cyan"
    },
    {
      "x": -9,
      "y": 33,
      "z": 7,
      "name": "Fullmetal_Plant_Leaves_Crystal_Cyan"
    },
    {
      "x": -9,
      "y": 38,
      "z": 7,
      "name": "Fullmetal_Plant_Leaves_Crystal_Cyan"
    },
    {
      "x": -9,
      "y": 17,
      "z": 8,
      "name": "Fullmetal_Plant_Leaves_Crystal_Cyan"
    },
    {
      "x": -9,
      "y": 18,
      "z": 8,
      "name": "Fullmetal_Plant_Leaves_Crystal_Cyan"
    },
    {
      "x": -9,
      "y": 19,
      "z": 8,
      "name": "Fullmetal_Plant_Leaves_Crystal_Cyan"
    },
    {
      "x": -9,
      "y": 30,
      "z": 8,
      "name": "Fullmetal_Plant_Leaves_Crystal_Cyan"
    },
    {
      "x": -9,
      "y": 31,
      "z": 8,
      "name": "Fullmetal_Plant_Leaves_Crystal_Cyan"
    },
    {
      "x": -9,
      "y": 32,
      "z": 8,
      "name": "Fullmetal_Plant_Leaves_Crystal_Cyan"
    },
    {
      "x": -9,
      "y": 38,
      "z": 8,
      "name": "Fullmetal_Plant_Leaves_Crystal_Cyan"
    },
    {
      "x": -9,
      "y": 18,
      "z": 9,
      "name": "Fullmetal_Plant_Leaves_Crystal_Cyan"
    },
    {
      "x": -9,
      "y": 30,
      "z": 9,
      "name": "Fullmetal_Plant_Leaves_Crystal_Cyan"
    },
    {
      "x": -9,
      "y": 31,
      "z": 9,
      "name": "Fullmetal_Plant_Leaves_Crystal_Cyan"
    },
    {
      "x": -9,
      "y": 32,
      "z": 9,
      "name": "Fullmetal_Plant_Leaves_Crystal_Cyan"
    },
    {
      "x": -9,
      "y": 17,
      "z": 10,
      "name": "Fullmetal_Plant_Leaves_Crystal_Cyan"
    },
    {
      "x": -9,
      "y": 28,
      "z": 10,
      "name": "Wood_Crystal_Trunk_Full"
    },
    {
      "x": -9,
      "y": 29,
      "z": 10,
      "name": "Fullmetal_Plant_Leaves_Crystal_Cyan"
    },
    {
      "x": -9,
      "y": 31,
      "z": 10,
      "name": "Fullmetal_Plant_Leaves_Crystal_Cyan"
    },
    {
      "x": -9,
      "y": 32,
      "z": 10,
      "name": "Fullmetal_Plant_Leaves_Crystal_Cyan"
    },
    {
      "x": -9,
      "y": 37,
      "z": 10,
      "name": "Fullmetal_Plant_Leaves_Crystal_Cyan"
    },
    {
      "x": -9,
      "y": 28,
      "z": 11,
      "name": "Fullmetal_Plant_Leaves_Crystal_Cyan"
    },
    {
      "x": -9,
      "y": 29,
      "z": 11,
      "name": "Fullmetal_Plant_Leaves_Crystal_Cyan"
    },
    {
      "x": -9,
      "y": 29,
      "z": 12,
      "name": "Fullmetal_Plant_Leaves_Crystal_Cyan"
    },
    {
      "x": -9,
      "y": 30,
      "z": 12,
      "name": "Fullmetal_Plant_Leaves_Crystal_Cyan"
    },
    {
      "x": -9,
      "y": 29,
      "z": 13,
      "name": "Fullmetal_Plant_Leaves_Crystal_Cyan"
    },
    {
      "x": -9,
      "y": 30,
      "z": 13,
      "name": "Fullmetal_Plant_Leaves_Crystal_Cyan"
    },
    {
      "x": -9,
      "y": 29,
      "z": 14,
      "name": "Fullmetal_Plant_Leaves_Crystal_Cyan"
    },
    {
      "x": -8,
      "y": 32,
      "z": -14,
      "name": "Fullmetal_Plant_Leaves_Crystal_Cyan"
    },
    {
      "x": -8,
      "y": 26,
      "z": -13,
      "name": "Fullmetal_Plant_Leaves_Crystal_Cyan"
    },
    {
      "x": -8,
      "y": 17,
      "z": -12,
      "name": "Fullmetal_Plant_Leaves_Crystal_Cyan"
    },
    {
      "x": -8,
      "y": 25,
      "z": -12,
      "name": "Fullmetal_Plant_Leaves_Crystal_Cyan"
    },
    {
      "x": -8,
      "y": 26,
      "z": -12,
      "name": "Fullmetal_Plant_Leaves_Crystal_Cyan"
    },
    {
      "x": -8,
      "y": 16,
      "z": -11,
      "name": "Fullmetal_Plant_Leaves_Crystal_Cyan"
    },
    {
      "x": -8,
      "y": 17,
      "z": -11,
      "name": "Fullmetal_Plant_Leaves_Crystal_Cyan"
    },
    {
      "x": -8,
      "y": 26,
      "z": -11,
      "name": "Fullmetal_Plant_Leaves_Crystal_Cyan"
    },
    {
      "x": -8,
      "y": 16,
      "z": -10,
      "name": "Fullmetal_Plant_Leaves_Crystal_Cyan"
    },
    {
      "x": -8,
      "y": 17,
      "z": -10,
      "name": "Fullmetal_Plant_Leaves_Crystal_Cyan"
    },
    {
      "x": -8,
      "y": 25,
      "z": -10,
      "name": "Fullmetal_Plant_Leaves_Crystal_Cyan"
    },
    {
      "x": -8,
      "y": 26,
      "z": -10,
      "name": "Fullmetal_Plant_Leaves_Crystal_Cyan"
    },
    {
      "x": -8,
      "y": 27,
      "z": -10,
      "name": "Fullmetal_Plant_Leaves_Crystal_Cyan"
    },
    {
      "x": -8,
      "y": 30,
      "z": -10,
      "name": "Fullmetal_Plant_Leaves_Crystal_Cyan"
    },
    {
      "x": -8,
      "y": 35,
      "z": -10,
      "name": "Fullmetal_Plant_Leaves_Crystal_Cyan"
    },
    {
      "x": -8,
      "y": 36,
      "z": -10,
      "name": "Fullmetal_Plant_Leaves_Crystal_Cyan"
    },
    {
      "x": -8,
      "y": 16,
      "z": -9,
      "name": "Fullmetal_Plant_Leaves_Crystal_Cyan"
    },
    {
      "x": -8,
      "y": 17,
      "z": -9,
      "name": "Fullmetal_Plant_Leaves_Crystal_Cyan"
    },
    {
      "x": -8,
      "y": 18,
      "z": -9,
      "name": "Fullmetal_Plant_Leaves_Crystal_Cyan"
    },
    {
      "x": -8,
      "y": 26,
      "z": -9,
      "name": "Fullmetal_Plant_Leaves_Crystal_Cyan"
    },
    {
      "x": -8,
      "y": 27,
      "z": -9,
      "name": "Fullmetal_Plant_Leaves_Crystal_Cyan"
    },
    {
      "x": -8,
      "y": 30,
      "z": -9,
      "name": "Fullmetal_Plant_Leaves_Crystal_Cyan"
    },
    {
      "x": -8,
      "y": 35,
      "z": -9,
      "name": "Fullmetal_Plant_Leaves_Crystal_Cyan"
    },
    {
      "x": -8,
      "y": 36,
      "z": -9,
      "name": "Fullmetal_Plant_Leaves_Crystal_Cyan"
    },
    {
      "x": -8,
      "y": 17,
      "z": -8,
      "name": "Fullmetal_Plant_Leaves_Crystal_Cyan"
    },
    {
      "x": -8,
      "y": 18,
      "z": -8,
      "name": "Fullmetal_Plant_Leaves_Crystal_Cyan"
    },
    {
      "x": -8,
      "y": 26,
      "z": -8,
      "name": "Fullmetal_Plant_Leaves_Crystal_Cyan"
    },
    {
      "x": -8,
      "y": 27,
      "z": -8,
      "name": "Fullmetal_Plant_Leaves_Crystal_Cyan"
    },
    {
      "x": -8,
      "y": 28,
      "z": -8,
      "name": "Fullmetal_Plant_Leaves_Crystal_Cyan"
    },
    {
      "x": -8,
      "y": 30,
      "z": -8,
      "name": "Fullmetal_Plant_Leaves_Crystal_Cyan"
    },
    {
      "x": -8,
      "y": 31,
      "z": -8,
      "name": "Fullmetal_Plant_Leaves_Crystal_Cyan"
    },
    {
      "x": -8,
      "y": 34,
      "z": -8,
      "name": "Fullmetal_Plant_Leaves_Crystal_Cyan"
    },
    {
      "x": -8,
      "y": 35,
      "z": -8,
      "name": "Fullmetal_Plant_Leaves_Crystal_Cyan"
    },
    {
      "x": -8,
      "y": 36,
      "z": -8,
      "name": "Fullmetal_Plant_Leaves_Crystal_Cyan"
    },
    {
      "x": -8,
      "y": 16,
      "z": -7,
      "name": "Wood_Crystal_Branch_Corner",
      "rotation": 3
    },
    {
      "x": -8,
      "y": 17,
      "z": -7,
      "name": "Fullmetal_Plant_Leaves_Crystal_Cyan"
    },
    {
      "x": -8,
      "y": 18,
      "z": -7,
      "name": "Fullmetal_Plant_Leaves_Crystal_Cyan"
    },
    {
      "x": -8,
      "y": 27,
      "z": -7,
      "name": "Fullmetal_Plant_Leaves_Crystal_Cyan"
    },
    {
      "x": -8,
      "y": 30,
      "z": -7,
      "name": "Fullmetal_Plant_Leaves_Crystal_Cyan"
    },
    {
      "x": -8,
      "y": 34,
      "z": -7,
      "name": "Fullmetal_Plant_Leaves_Crystal_Cyan"
    },
    {
      "x": -8,
      "y": 35,
      "z": -7,
      "name": "Fullmetal_Plant_Leaves_Crystal_Cyan"
    },
    {
      "x": -8,
      "y": 36,
      "z": -7,
      "name": "Fullmetal_Plant_Leaves_Crystal_Cyan"
    },
    {
      "x": -8,
      "y": 17,
      "z": -6,
      "name": "Fullmetal_Plant_Leaves_Crystal_Cyan"
    },
    {
      "x": -8,
      "y": 18,
      "z": -6,
      "name": "Fullmetal_Plant_Leaves_Crystal_Cyan"
    },
    {
      "x": -8,
      "y": 24,
      "z": -6,
      "name": "Wood_Crystal_Roots"
    },
    {
      "x": -8,
      "y": 25,
      "z": -6,
      "name": "Wood_Crystal_Trunk_Full"
    },
    {
      "x": -8,
      "y": 26,
      "z": -6,
      "name": "Wood_Crystal_Trunk_Full"
    },
    {
      "x": -8,
      "y": 28,
      "z": -6,
      "name": "Fullmetal_Plant_Leaves_Crystal_Cyan"
    },
    {
      "x": -8,
      "y": 35,
      "z": -6,
      "name": "Fullmetal_Plant_Leaves_Crystal_Cyan"
    },
    {
      "x": -8,
      "y": 17,
      "z": -5,
      "name": "Fullmetal_Plant_Leaves_Crystal_Cyan"
    },
    {
      "x": -8,
      "y": 18,
      "z": -5,
      "name": "Fullmetal_Plant_Leaves_Crystal_Cyan"
    },
    {
      "x": -8,
      "y": 26,
      "z": -5,
      "name": "Wood_Crystal_Trunk_Full"
    },
    {
      "x": -8,
      "y": 28,
      "z": -5,
      "name": "Fullmetal_Plant_Leaves_Crystal_Cyan"
    },
    {
      "x": -8,
      "y": 35,
      "z": -5,
      "name": "Fullmetal_Plant_Leaves_Crystal_Cyan"
    },
    {
      "x": -8,
      "y": 36,
      "z": -5,
      "name": "Fullmetal_Plant_Leaves_Crystal_Cyan"
    },
    {
      "x": -8,
      "y": 16,
      "z": -4,
      "name": "Fullmetal_Plant_Leaves_Crystal_Cyan"
    },
    {
      "x": -8,
      "y": 17,
      "z": -4,
      "name": "Fullmetal_Plant_Leaves_Crystal_Cyan"
    },
    {
      "x": -8,
      "y": 36,
      "z": -4,
      "name": "Fullmetal_Plant_Leaves_Crystal_Cyan"
    },
    {
      "x": -8,
      "y": 37,
      "z": -4,
      "name": "Fullmetal_Plant_Leaves_Crystal_Cyan"
    },
    {
      "x": -8,
      "y": 15,
      "z": -3,
      "name": "Fullmetal_Plant_Leaves_Crystal_Cyan"
    },
    {
      "x": -8,
      "y": 16,
      "z": -3,
      "name": "Fullmetal_Plant_Leaves_Crystal_Cyan"
    },
    {
      "x": -8,
      "y": 17,
      "z": -3,
      "name": "Fullmetal_Plant_Leaves_Crystal_Cyan"
    },
    {
      "x": -8,
      "y": 25,
      "z": -3,
      "name": "Fullmetal_Plant_Leaves_Crystal_Cyan"
    },
    {
      "x": -8,
      "y": 35,
      "z": -3,
      "name": "Wood_Crystal_Trunk_Full"
    },
    {
      "x": -8,
      "y": 36,
      "z": -3,
      "name": "Fullmetal_Plant_Leaves_Crystal_Cyan"
    },
    {
      "x": -8,
      "y": 37,
      "z": -3,
      "name": "Fullmetal_Plant_Leaves_Crystal_Cyan"
    },
    {
      "x": -8,
      "y": 16,
      "z": -2,
      "name": "Fullmetal_Plant_Leaves_Crystal_Cyan"
    },
    {
      "x": -8,
      "y": 35,
      "z": -2,
      "name": "Wood_Crystal_Trunk_Full"
    },
    {
      "x": -8,
      "y": 36,
      "z": -2,
      "name": "Fullmetal_Plant_Leaves_Crystal_Cyan"
    },
    {
      "x": -8,
      "y": 37,
      "z": -2,
      "name": "Fullmetal_Plant_Leaves_Crystal_Cyan"
    },
    {
      "x": -8,
      "y": 38,
      "z": -2,
      "name": "Fullmetal_Plant_Leaves_Crystal_Cyan"
    },
    {
      "x": -8,
      "y": 15,
      "z": -1,
      "name": "Fullmetal_Plant_Leaves_Crystal_Cyan"
    },
    {
      "x": -8,
      "y": 16,
      "z": -1,
      "name": "Fullmetal_Plant_Leaves_Crystal_Cyan"
    },
    {
      "x": -8,
      "y": 29,
      "z": -1,
      "name": "Wood_Crystal_Trunk_Full"
    },
    {
      "x": -8,
      "y": 35,
      "z": -1,
      "name": "Wood_Crystal_Trunk_Full"
    },
    {
      "x": -8,
      "y": 36,
      "z": -1,
      "name": "Fullmetal_Plant_Leaves_Crystal_Cyan"
    },
    {
      "x": -8,
      "y": 37,
      "z": -1,
      "name": "Fullmetal_Plant_Leaves_Crystal_Cyan"
    },
    {
      "x": -8,
      "y": 38,
      "z": -1,
      "name": "Fullmetal_Plant_Leaves_Crystal_Cyan"
    },
    {
      "x": -8,
      "y": 16,
      "z": 0,
      "name": "Fullmetal_Plant_Leaves_Crystal_Cyan"
    },
    {
      "x": -8,
      "y": 25,
      "z": 0,
      "name": "Fullmetal_Plant_Leaves_Crystal_Cyan"
    },
    {
      "x": -8,
      "y": 29,
      "z": 0,
      "name": "Wood_Crystal_Trunk_Full"
    },
    {
      "x": -8,
      "y": 36,
      "z": 0,
      "name": "Fullmetal_Plant_Leaves_Crystal_Cyan"
    },
    {
      "x": -8,
      "y": 38,
      "z": 0,
      "name": "Fullmetal_Plant_Leaves_Crystal_Cyan"
    },
    {
      "x": -8,
      "y": -2,
      "z": 1,
      "name": "Wood_Crystal_Trunk"
    },
    {
      "x": -8,
      "y": -1,
      "z": 1,
      "name": "Wood_Crystal_Trunk_Full"
    },
    {
      "x": -8,
      "y": 16,
      "z": 1,
      "name": "Fullmetal_Plant_Leaves_Crystal_Cyan"
    },
    {
      "x": -8,
      "y": 25,
      "z": 1,
      "name": "Fullmetal_Plant_Leaves_Crystal_Cyan"
    },
    {
      "x": -8,
      "y": 26,
      "z": 1,
      "name": "Fullmetal_Plant_Leaves_Crystal_Cyan"
    },
    {
      "x": -8,
      "y": 27,
      "z": 1,
      "name": "Fullmetal_Plant_Leaves_Crystal_Cyan"
    },
    {
      "x": -8,
      "y": 28,
      "z": 1,
      "name": "Wood_Crystal_Trunk_Full"
    },
    {
      "x": -8,
      "y": 29,
      "z": 1,
      "name": "Wood_Crystal_Trunk_Full"
    },
    {
      "x": -8,
      "y": 36,
      "z": 1,
      "name": "Fullmetal_Plant_Leaves_Crystal_Cyan"
    },
    {
      "x": -8,
      "y": 38,
      "z": 1,
      "name": "Fullmetal_Plant_Leaves_Crystal_Cyan"
    },
    {
      "x": -8,
      "y": -3,
      "z": 2,
      "name": "Wood_Crystal_Trunk"
    },
    {
      "x": -8,
      "y": -2,
      "z": 2,
      "name": "Wood_Crystal_Trunk"
    },
    {
      "x": -8,
      "y": -1,
      "z": 2,
      "name": "Wood_Crystal_Trunk"
    },
    {
      "x": -8,
      "y": 0,
      "z": 2,
      "name": "Wood_Crystal_Trunk_Full"
    },
    {
      "x": -8,
      "y": 17,
      "z": 2,
      "name": "Fullmetal_Plant_Leaves_Crystal_Cyan"
    },
    {
      "x": -8,
      "y": 25,
      "z": 2,
      "name": "Fullmetal_Plant_Leaves_Crystal_Cyan"
    },
    {
      "x": -8,
      "y": 26,
      "z": 2,
      "name": "Fullmetal_Plant_Leaves_Crystal_Cyan"
    },
    {
      "x": -8,
      "y": 27,
      "z": 2,
      "name": "Fullmetal_Plant_Leaves_Crystal_Cyan"
    },
    {
      "x": -8,
      "y": 29,
      "z": 2,
      "name": "Wood_Crystal_Trunk_Full"
    },
    {
      "x": -8,
      "y": 30,
      "z": 2,
      "name": "Wood_Crystal_Trunk_Full"
    },
    {
      "x": -8,
      "y": 36,
      "z": 2,
      "name": "Fullmetal_Plant_Leaves_Crystal_Cyan"
    },
    {
      "x": -8,
      "y": 38,
      "z": 2,
      "name": "Fullmetal_Plant_Leaves_Crystal_Cyan"
    },
    {
      "x": -8,
      "y": -4,
      "z": 3,
      "name": "Wood_Crystal_Roots"
    },
    {
      "x": -8,
      "y": -3,
      "z": 3,
      "name": "Wood_Crystal_Trunk"
    },
    {
      "x": -8,
      "y": -2,
      "z": 3,
      "name": "Wood_Crystal_Trunk"
    },
    {
      "x": -8,
      "y": -1,
      "z": 3,
      "name": "Wood_Crystal_Trunk"
    },
    {
      "x": -8,
      "y": 0,
      "z": 3,
      "name": "Wood_Crystal_Trunk_Full"
    },
    {
      "x": -8,
      "y": 17,
      "z": 3,
      "name": "Fullmetal_Plant_Leaves_Crystal_Cyan"
    },
    {
      "x": -8,
      "y": 25,
      "z": 3,
      "name": "Fullmetal_Plant_Leaves_Crystal_Cyan"
    },
    {
      "x": -8,
      "y": 27,
      "z": 3,
      "name": "Fullmetal_Plant_Leaves_Crystal_Cyan"
    },
    {
      "x": -8,
      "y": 30,
      "z": 3,
      "name": "Wood_Crystal_Trunk_Full"
    },
    {
      "x": -8,
      "y": 38,
      "z": 3,
      "name": "Fullmetal_Plant_Leaves_Crystal_Cyan"
    },
    {
      "x": -8,
      "y": -2,
      "z": 4,
      "name": "Wood_Crystal_Trunk"
    },
    {
      "x": -8,
      "y": -1,
      "z": 4,
      "name": "Wood_Crystal_Trunk"
    },
    {
      "x": -8,
      "y": 0,
      "z": 4,
      "name": "Wood_Crystal_Trunk_Full"
    },
    {
      "x": -8,
      "y": 17,
      "z": 4,
      "name": "Fullmetal_Plant_Leaves_Crystal_Cyan"
    },
    {
      "x": -8,
      "y": 18,
      "z": 4,
      "name": "Fullmetal_Plant_Leaves_Crystal_Cyan"
    },
    {
      "x": -8,
      "y": 27,
      "z": 4,
      "name": "Fullmetal_Plant_Leaves_Crystal_Cyan"
    },
    {
      "x": -8,
      "y": 31,
      "z": 4,
      "name": "Fullmetal_Plant_Leaves_Crystal_Cyan"
    },
    {
      "x": -8,
      "y": 36,
      "z": 4,
      "name": "Wood_Crystal_Branch_Long",
      "rotation": 5
    },
    {
      "x": -8,
      "y": 37,
      "z": 4,
      "name": "Fullmetal_Plant_Leaves_Crystal_Cyan"
    },
    {
      "x": -8,
      "y": 16,
      "z": 5,
      "name": "Fullmetal_Plant_Leaves_Crystal_Cyan"
    },
    {
      "x": -8,
      "y": 17,
      "z": 5,
      "name": "Fullmetal_Plant_Leaves_Crystal_Cyan"
    },
    {
      "x": -8,
      "y": 18,
      "z": 5,
      "name": "Fullmetal_Plant_Leaves_Crystal_Cyan"
    },
    {
      "x": -8,
      "y": 27,
      "z": 5,
      "name": "Fullmetal_Plant_Leaves_Crystal_Cyan"
    },
    {
      "x": -8,
      "y": 31,
      "z": 5,
      "name": "Fullmetal_Plant_Leaves_Crystal_Cyan"
    },
    {
      "x": -8,
      "y": 32,
      "z": 5,
      "name": "Fullmetal_Plant_Leaves_Crystal_Cyan"
    },
    {
      "x": -8,
      "y": 37,
      "z": 5,
      "name": "Fullmetal_Plant_Leaves_Crystal_Cyan"
    },
    {
      "x": -8,
      "y": 38,
      "z": 5,
      "name": "Fullmetal_Plant_Leaves_Crystal_Cyan"
    },
    {
      "x": -8,
      "y": 39,
      "z": 5,
      "name": "Fullmetal_Plant_Leaves_Crystal_Cyan"
    },
    {
      "x": -8,
      "y": 14,
      "z": 6,
      "name": "Fullmetal_Plant_Leaves_Crystal_Cyan"
    },
    {
      "x": -8,
      "y": 15,
      "z": 6,
      "name": "Fullmetal_Plant_Leaves_Crystal_Cyan"
    },
    {
      "x": -8,
      "y": 16,
      "z": 6,
      "name": "Fullmetal_Plant_Leaves_Crystal_Cyan"
    },
    {
      "x": -8,
      "y": 17,
      "z": 6,
      "name": "Fullmetal_Plant_Leaves_Crystal_Cyan"
    },
    {
      "x": -8,
      "y": 18,
      "z": 6,
      "name": "Fullmetal_Plant_Leaves_Crystal_Cyan"
    },
    {
      "x": -8,
      "y": 19,
      "z": 6,
      "name": "Fullmetal_Plant_Leaves_Crystal_Cyan"
    },
    {
      "x": -8,
      "y": 27,
      "z": 6,
      "name": "Wood_Crystal_Trunk_Full"
    },
    {
      "x": -8,
      "y": 30,
      "z": 6,
      "name": "Wood_Crystal_Trunk_Full"
    },
    {
      "x": -8,
      "y": 31,
      "z": 6,
      "name": "Fullmetal_Plant_Leaves_Crystal_Cyan"
    },
    {
      "x": -8,
      "y": 32,
      "z": 6,
      "name": "Fullmetal_Plant_Leaves_Crystal_Cyan"
    },
    {
      "x": -8,
      "y": 37,
      "z": 6,
      "name": "Fullmetal_Plant_Leaves_Crystal_Cyan"
    },
    {
      "x": -8,
      "y": 38,
      "z": 6,
      "name": "Fullmetal_Plant_Leaves_Crystal_Cyan"
    },
    {
      "x": -8,
      "y": 17,
      "z": 7,
      "name": "Fullmetal_Plant_Leaves_Crystal_Cyan"
    },
    {
      "x": -8,
      "y": 18,
      "z": 7,
      "name": "Fullmetal_Plant_Leaves_Crystal_Cyan"
    },
    {
      "x": -8,
      "y": 19,
      "z": 7,
      "name": "Fullmetal_Plant_Leaves_Crystal_Cyan"
    },
    {
      "x": -8,
      "y": 30,
      "z": 7,
      "name": "Fullmetal_Plant_Leaves_Crystal_Cyan"
    },
    {
      "x": -8,
      "y": 31,
      "z": 7,
      "name": "Fullmetal_Plant_Leaves_Crystal_Cyan"
    },
    {
      "x": -8,
      "y": 32,
      "z": 7,
      "name": "Fullmetal_Plant_Leaves_Crystal_Cyan"
    },
    {
      "x": -8,
      "y": 36,
      "z": 7,
      "name": "Fullmetal_Plant_Leaves_Crystal_Cyan"
    },
    {
      "x": -8,
      "y": 38,
      "z": 7,
      "name": "Fullmetal_Plant_Leaves_Crystal_Cyan"
    },
    {
      "x": -8,
      "y": 18,
      "z": 8,
      "name": "Fullmetal_Plant_Leaves_Crystal_Cyan"
    },
    {
      "x": -8,
      "y": 19,
      "z": 8,
      "name": "Fullmetal_Plant_Leaves_Crystal_Cyan"
    },
    {
      "x": -8,
      "y": 30,
      "z": 8,
      "name": "Fullmetal_Plant_Leaves_Crystal_Cyan"
    },
    {
      "x": -8,
      "y": 31,
      "z": 8,
      "name": "Fullmetal_Plant_Leaves_Crystal_Cyan"
    },
    {
      "x": -8,
      "y": 32,
      "z": 8,
      "name": "Fullmetal_Plant_Leaves_Crystal_Cyan"
    },
    {
      "x": -8,
      "y": 36,
      "z": 8,
      "name": "Fullmetal_Plant_Leaves_Crystal_Cyan"
    },
    {
      "x": -8,
      "y": 38,
      "z": 8,
      "name": "Fullmetal_Plant_Leaves_Crystal_Cyan"
    },
    {
      "x": -8,
      "y": 17,
      "z": 9,
      "name": "Fullmetal_Plant_Leaves_Crystal_Cyan"
    },
    {
      "x": -8,
      "y": 18,
      "z": 9,
      "name": "Fullmetal_Plant_Leaves_Crystal_Cyan"
    },
    {
      "x": -8,
      "y": 27,
      "z": 9,
      "name": "Wood_Crystal_Roots"
    },
    {
      "x": -8,
      "y": 28,
      "z": 9,
      "name": "Wood_Crystal_Trunk_Full"
    },
    {
      "x": -8,
      "y": 31,
      "z": 9,
      "name": "Fullmetal_Plant_Leaves_Crystal_Cyan"
    },
    {
      "x": -8,
      "y": 36,
      "z": 9,
      "name": "Fullmetal_Plant_Leaves_Crystal_Cyan"
    },
    {
      "x": -8,
      "y": 17,
      "z": 10,
      "name": "Fullmetal_Plant_Leaves_Crystal_Cyan"
    },
    {
      "x": -8,
      "y": 18,
      "z": 10,
      "name": "Fullmetal_Plant_Leaves_Crystal_Cyan"
    },
    {
      "x": -8,
      "y": 27,
      "z": 10,
      "name": "Wood_Crystal_Roots"
    },
    {
      "x": -8,
      "y": 28,
      "z": 10,
      "name": "Wood_Crystal_Trunk_Full"
    },
    {
      "x": -8,
      "y": 29,
      "z": 10,
      "name": "Fullmetal_Plant_Leaves_Crystal_Cyan"
    },
    {
      "x": -8,
      "y": 30,
      "z": 10,
      "name": "Fullmetal_Plant_Leaves_Crystal_Cyan"
    },
    {
      "x": -8,
      "y": 31,
      "z": 10,
      "name": "Fullmetal_Plant_Leaves_Crystal_Cyan"
    },
    {
      "x": -8,
      "y": 36,
      "z": 10,
      "name": "Fullmetal_Plant_Leaves_Crystal_Cyan"
    },
    {
      "x": -8,
      "y": 37,
      "z": 10,
      "name": "Fullmetal_Plant_Leaves_Crystal_Cyan"
    },
    {
      "x": -8,
      "y": 18,
      "z": 11,
      "name": "Fullmetal_Plant_Leaves_Crystal_Cyan"
    },
    {
      "x": -8,
      "y": 28,
      "z": 11,
      "name": "Fullmetal_Plant_Leaves_Crystal_Cyan"
    },
    {
      "x": -8,
      "y": 29,
      "z": 11,
      "name": "Fullmetal_Plant_Leaves_Crystal_Cyan"
    },
    {
      "x": -8,
      "y": 30,
      "z": 11,
      "name": "Fullmetal_Plant_Leaves_Crystal_Cyan"
    },
    {
      "x": -8,
      "y": 36,
      "z": 11,
      "name": "Fullmetal_Plant_Leaves_Crystal_Cyan"
    },
    {
      "x": -8,
      "y": 37,
      "z": 11,
      "name": "Fullmetal_Plant_Leaves_Crystal_Cyan"
    },
    {
      "x": -8,
      "y": 29,
      "z": 12,
      "name": "Fullmetal_Plant_Leaves_Crystal_Cyan"
    },
    {
      "x": -8,
      "y": 30,
      "z": 12,
      "name": "Fullmetal_Plant_Leaves_Crystal_Cyan"
    },
    {
      "x": -8,
      "y": 28,
      "z": 13,
      "name": "Fullmetal_Plant_Leaves_Crystal_Cyan"
    },
    {
      "x": -8,
      "y": 29,
      "z": 13,
      "name": "Fullmetal_Plant_Leaves_Crystal_Cyan"
    },
    {
      "x": -8,
      "y": 30,
      "z": 13,
      "name": "Fullmetal_Plant_Leaves_Crystal_Cyan"
    },
    {
      "x": -8,
      "y": 29,
      "z": 14,
      "name": "Fullmetal_Plant_Leaves_Crystal_Cyan"
    },
    {
      "x": -8,
      "y": 32,
      "z": 14,
      "name": "Fullmetal_Plant_Leaves_Crystal_Cyan"
    },
    {
      "x": -8,
      "y": 32,
      "z": 15,
      "name": "Fullmetal_Plant_Leaves_Crystal_Cyan"
    },
    {
      "x": -7,
      "y": 32,
