{
  "version": 8,
  "blockIdVersion": 11,
  "anchorX": 0,
  "anchorY": 0,
  "anchorZ": 0,
  "blocks": [
    {
      "x": -7,
      "y": 14,
      "z": -7,
      "name": "Ore_Iron_Sandstone"
    },
    {
      "x": -7,
      "y": 13,
      "z": -6,
      "name": "Ore_Iron_Sandstone"
    },
    {
      "x": -6,
      "y": 13,
      "z": -7,
      "name": "Ore_Iron_Sandstone"
    },
    {
      "x": -6,
      "y": 12,
      "z": -6,
      "name": "Ore_Iron_Sandstone"
    },
    {
      "x": -6,
      "y": 13,
      "z": -6,
      "name": "Ore_Iron_Sandstone"
    },
    {
      "x": -6,
      "y": 14,
      "z": -6,
      "name": "Ore_Iron_Sandstone"
    },
    {
      "x": -6,
      "y": 12,
      "z": -5,
      "name": "Ore_Iron_Sandstone"
    },
    {
      "x": -6,
      "y": 13,
      "z": -5,
      "name": "Ore_Iron_Sandstone"
    },
    {
      "x": -5,
      "y": 12,
      "z": -6,
      "name": "Ore_Iron_Sandstone"
    },
    {
      "x": -5,
      "y": 13,
      "z": -6,
      "name": "Ore_Iron_Sandstone"
    },
    {
      "x": -5,
      "y": 11,
      "z": -5,
      "name": "Ore_Iron_Sandstone"
    },
    {
      "x": -5,
      "y": 12,
      "z": -5,
      "name": "Ore_Iron_Sandstone"
    },
    {
      "x": -5,
      "y": 13,
      "z": -5,
      "name": "Ore_Iron_Sandstone"
    },
    {
      "x": -5,
      "y": 11,
      "z": -4,
      "name": "Ore_Iron_Sandstone"
    },
    {
      "x": -5,
      "y": 12,
      "z": -4,
      "name": "Ore_Iron_Sandstone"
    },
    {
      "x": -5,
      "y": 10,
      "z": -3,
      "name": "Ore_Iron_Sandstone"
    },
    {
      "x": -4,
      "y": 11,
      "z": -5,
      "name": "Ore_Iron_Sandstone"
    },
    {
      "x": -4,
      "y": 12,
      "z": -5,
      "name": "Ore_Iron_Sandstone"
    },
    {
      "x": -4,
      "y": 10,
      "z": -4,
      "name": "Ore_Iron_Sandstone"
    },
    {
      "x": -4,
      "y": 11,
      "z": -4,
      "name": "Ore_Iron_Sandstone"
    },
    {
      "x": -4,
      "y": 12,
      "z": -4,
      "name": "Ore_Iron_Sandstone"
    },
    {
      "x": -4,
      "y": 9,
      "z": -3,
      "name": "Ore_Iron_Sandstone"
    },
    {
      "x": -4,
      "y": 10,
      "z": -3,
      "name": "Ore_Iron_Sandstone"
    },
    {
      "x": -4,
      "y": 11,
      "z": -3,
      "name": "Ore_Iron_Sandstone"
    },
    {
      "x": -4,
      "y": 9,
      "z": -2,
      "name": "Ore_Iron_Sandstone"
    },
    {
      "x": -4,
      "y": 10,
      "z": -2,
      "name": "Ore_Iron_Sandstone"
    },
    {
      "x": -4,
      "y": 8,
      "z": -1,
      "name": "Ore_Iron_Sandstone"
    },
    {
      "x": -4,
      "y": 7,
      "z": 0,
      "name": "Ore_Iron_Sandstone"
    },
    {
      "x": -3,
      "y": 11,
      "z": -4,
      "name": "Ore_Iron_Sandstone"
    },
    {
      "x": -3,
      "y": 9,
      "z": -3,
      "name": "Ore_Iron_Sandstone"
    },
    {
      "x": -3,
      "y": 10,
      "z": -3,
      "name": "Ore_Iron_Sandstone"
    },
    {
      "x": -3,
      "y": 8,
      "z": -2,
      "name": "Ore_Iron_Sandstone"
    },
    {
      "x": -3,
      "y": 9,
      "z": -2,
      "name": "Ore_Iron_Sandstone"
    },
    {
      "x": -3,
      "y": 10,
      "z": -2,
      "name": "Ore_Iron_Sandstone"
    },
    {
      "x": -3,
      "y": 7,
      "z": -1,
      "name": "Ore_Iron_Sandstone"
    },
    {
      "x": -3,
      "y": 8,
      "z": -1,
      "name": "Ore_Iron_Sandstone"
    },
    {
      "x": -3,
      "y": 9,
      "z": -1,
      "name": "Ore_Iron_Sandstone"
    },
    {
      "x": -3,
      "y": 6,
      "z": 0,
      "name": "Ore_Iron_Sandstone"
    },
    {
      "x": -3,
      "y": 7,
      "z": 0,
      "name": "Ore_Iron_Sandstone"
    },
    {
      "x": -3,
      "y": 8,
      "z": 0,
      "name": "Ore_Iron_Sandstone"
    },
    {
      "x": -3,
      "y": 7,
      "z": 1,
      "name": "Ore_Iron_Sandstone"
    },
    {
      "x": -2,
      "y": 9,
      "z": -2,
      "name": "Ore_Iron_Sandstone"
    },
    {
      "x": -2,
      "y": 6,
      "z": -1,
      "name": "Ore_Iron_Sandstone"
    },
    {
      "x": -2,
      "y": 8,
      "z": -1,
      "name": "Ore_Iron_Sandstone"
    },
    {
      "x": -2,
      "y": 5,
      "z": 0,
      "name": "Ore_Iron_Sandstone"
    },
    {
      "x": -2,
      "y": 6,
      "z": 0,
      "name": "Ore_Iron_Sandstone"
    },
    {
      "x": -2,
      "y": 7,
      "z": 0,
      "name": "Ore_Iron_Sandstone"
    },
    {
      "x": -2,
      "y": 6,
      "z": 1,
      "name": "Ore_Iron_Sandstone"
    },
    {
      "x": -1,
      "y": 5,
      "z": -1,
      "name": "Ore_Iron_Sandstone"
    },
    {
      "x": -1,
      "y": 4,
      "z": 0,
      "name": "Ore_Iron_Sandstone"
    },
    {
      "x": -1,
      "y": 5,
      "z": 0,
      "name": "Ore_Iron_Sandstone"
    },
    {
      "x": -1,
      "y": 6,
      "z": 0,
      "name": "Ore_Iron_Sandstone"
    },
    {
      "x": -1,
      "y": 5,
      "z": 1,
      "name": "Ore_Iron_Sandstone"
    },
    {
      "x": 0,
      "y": 4,
      "z": -1,
      "name": "Ore_Iron_Sandstone"
    },
    {
      "x": 0,
      "y": 5,
      "z": -1,
      "name": "Ore_Iron_Sandstone"
    },
    {
      "x": 0,
      "y": 3,
      "z": 0,
      "name": "Ore_Iron_Sandstone"
    },
    {
      "x": 0,
      "y": 4,
      "z": 0,
      "name": "Ore_Iron_Sandstone"
    },
    {
      "x": 0,
      "y": 5,
      "z": 0,
      "name": "Ore_Iron_Sandstone"
    },
    {
      "x": 0,
      "y": 6,
      "z": 0,
      "name": "Ore_Iron_Sandstone"
    },
    {
      "x": 0,
      "y": 4,
      "z": 1,
      "name": "Ore_Iron_Sandstone"
    },
    {
      "x": 0,
      "y": 5,
      "z": 1,
      "name": "Ore_Iron_Sandstone"
    },
    {
      "x": 0,
      "y": 6,
      "z": 1,
      "name": "Ore_Iron_Sandstone"
    },
    {
      "x": 1,
      "y": 4,
      "z": 0,
      "name": "Ore_Iron_Sandstone"
    },
    {
      "x": 1,
      "y": 5,
      "z": 0,
      "name": "Ore_Iron_Sandstone"
    },
    {
      "x": 1,
      "y": 6,
      "z": 0,
      "name": "Ore_Iron_Sandstone"
    },
    {
      "x": 1,
      "y": 3,
      "z": 1,
      "name": "Ore_Iron_Sandstone"
    },
    {
      "x": 1,
      "y": 4,
      "z": 1,
      "name": "Ore_Iron_Sandstone"
    },
    {
      "x": 1,
      "y": 5,
      "z": 1,
      "name": "Ore_Iron_Sandstone"
    },
    {
      "x": 1,
      "y": 6,
      "z": 1,
      "name": "Ore_Iron_Sandstone"
    },
    {
      "x": 1,
      "y": 7,
      "z": 1,
      "name": "Ore_Iron_Sandstone"
    },
    {
      "x": 1,
      "y": 4,
      "z": 2,
      "name": "Ore_Iron_Sandstone"
    },
    {
      "x": 1,
      "y": 5,
      "z": 2,
      "name": "Ore_Iron_Sandstone"
    },
    {
      "x": 1,
      "y": 6,
      "z": 2,
      "name": "Ore_Iron_Sandstone"
    },
    {
      "x": 2,
      "y": 5,
      "z": 0,
      "name": "Ore_Iron_Sandstone"
    },
    {
      "x": 2,
      "y": 4,
      "z": 1,
      "name": "Ore_Iron_Sandstone"
    },
    {
      "x": 2,
      "y": 5,
      "z": 1,
      "name": "Ore_Iron_Sandstone"
    },
    {
      "x": 2,
      "y": 6,
      "z": 1,
      "name": "Ore_Iron_Sandstone"
    },
    {
      "x": 2,
      "y": 5,
      "z": 2,
      "name": "Ore_Iron_Sandstone"
    },
    {
      "x": 3,
      "y": 6,
      "z": 0,
      "name": "Ore_Iron_Sandstone"
    },
    {
      "x": 3,
      "y": 5,
      "z": 1,
      "name": "Ore_Iron_Sandstone"
    },
    {
      "x": 3,
      "y": 6,
      "z": 1,
      "name": "Ore_Iron_Sandstone"
    },
    {
      "x": 3,
      "y": 7,
      "z": 1,
      "name": "Ore_Iron_Sandstone"
    },
    {
      "x": 3,
      "y": 6,
      "z": 2,
      "name": "Ore_Iron_Sandstone"
    },
    {
      "x": 3,
      "y": 7,
      "z": 2,
      "name": "Ore_Iron_Sandstone"
    },
    {
      "x": 4,
      "y": 6,
      "z": 1,
      "name": "Ore_Iron_Sandstone"
    },
    {
      "x": 4,
      "y": 7,
      "z": 1,
      "name": "Ore_Iron_Sandstone"
    },
    {
      "x": 4,
      "y": 6,
      "z": 2,
      "name": "Ore_Iron_Sandstone"
    },
    {
      "x": 4,
      "y": 7,
      "z": 2,
      "name": "Ore_Iron_Sandstone"
    },
    {
      "x": 4,
      "y": 8,
      "z": 2,
      "name": "Ore_Iron_Sandstone"
    },
    {
      "x": 4,
      "y": 7,
      "z": 3,
      "name": "Ore_Iron_Sandstone"
    },
    {
      "x": 5,
      "y": 8,
      "z": 1,
      "name": "Ore_Iron_Sandstone"
    },
    {
      "x": 5,
      "y": 7,
      "z": 2,
      "name": "Ore_Iron_Sandstone"
    },
    {
      "x": 5,
      "y": 8,
      "z": 2,
      "name": "Ore_Iron_Sandstone"
    },
    {
      "x": 5,
      "y": 9,
      "z": 2,
      "name": "Ore_Iron_Sandstone"
    },
    {
      "x": 5,
      "y": 7,
      "z": 3,
      "name": "Ore_Iron_Sandstone"
    },
    {
      "x": 5,
      "y": 8,
      "z": 3,
      "name": "Ore_Iron_Sandstone"
    },
    {
      "x": 5,
      "y": 8,
      "z": 4,
      "name": "Ore_Iron_Sandstone"
    },
    {
      "x": 6,
      "y": 7,
      "z": 2,
      "name": "Ore_Iron_Sandstone"
    },
    {
      "x": 6,
      "y": 8,
      "z": 2,
      "name": "Ore_Iron_Sandstone"
    },
    {
      "x": 6,
      "y": 6,
      "z": 3,
      "name": "Ore_Iron_Sandstone"
    },
    {
      "x": 6,
      "y": 7,
      "z": 3,
      "name": "Ore_Iron_Sandstone"
    },
    {
      "x": 6,
      "y": 8,
      "z": 3,
      "name": "Ore_Iron_Sandstone"
    },
    {
      "x": 6,
      "y": 7,
      "z": 4,
      "name": "Ore_Iron_Sandstone"
    },
    {
      "x": 6,
      "y": 8,
      "z": 4,
      "name": "Ore_Iron_Sandstone"
    },
    {
      "x": 6,
      "y": 9,
      "z": 4,
      "name": "Ore_Iron_Sandstone"
    },
    {
      "x": 6,
      "y": 7,
      "z": 5,
      "name": "Ore_Iron_Sandstone"
    },
    {
      "x": 6,
      "y": 8,
      "z": 5,
      "name": "Ore_Iron_Sandstone"
    },
    {
      "x": 7,
      "y": 7,
      "z": 3,
      "name": "Ore_Iron_Sandstone"
    },
    {
      "x": 7,
      "y": 7,
      "z": 4,
      "name": "Ore_Iron_Sandstone"
    },
    {
      "x": 7,
      "y": 8,
      "z": 4,
      "name": "Ore_Iron_Sandstone"
    },
    {
      "x": 7,
      "y": 6,
      "z": 5,
      "name": "Ore_Iron_Sandstone"
    },
    {
      "x": 7,
      "y": 7,
      "z": 5,
      "name": "Ore_Iron_Sandstone"
    },
    {
      "x": 7,
      "y": 8,
      "z": 5,
      "name": "Ore_Iron_Sandstone"
    },
    {
      "x": 7,
      "y": 7,
      "z": 6,
      "name": "Ore_Iron_Sandstone"
    },
    {
      "x": 8,
      "y": 6,
      "z": 4,
      "name": "Ore_Iron_Sandstone"
    },
    {
      "x": 8,
      "y": 5,
      "z": 5,
      "name": "Ore_Iron_Sandstone"
    },
    {
      "x": 8,
      "y": 6,
      "z": 5,
      "name": "Ore_Iron_Sandstone"
    },
    {
      "x": 8,
      "y": 7,
      "z": 5,
      "name": "Ore_Iron_Sandstone"
    },
    {
      "x": 8,
      "y": 5,
      "z": 6,
      "name": "Ore_Iron_Sandstone"
    },
    {
      "x": 8,
      "y": 6,
      "z": 6,
      "name": "Ore_Iron_Sandstone"
    },
    {
      "x": 9,
      "y": 5,
      "z": 5,
      "name": "Ore_Iron_Sandstone"
    },
    {
      "x": 9,
      "y": 6,
      "z": 5,
      "name": "Ore_Iron_Sandstone"
    },
    {
      "x": 9,
      "y": 4,
      "z": 6,
      "name": "Ore_Iron_Sandstone"
    },
    {
      "x": 9,
      "y": 5,
      "z": 6,
      "name": "Ore_Iron_Sandstone"
    },
    {
      "x": 9,
      "y": 6,
      "z": 6,
      "name": "Ore_Iron_Sandstone"
    },
    {
      "x": 9,
      "y": 7,
      "z": 6,
      "name": "Ore_Iron_Sandstone"
    },
    {
      "x": 9,
      "y": 5,
      "z": 7,
      "name": "Ore_Iron_Sandstone"
    },
    {
      "x": 9,
      "y": 6,
      "z": 7,
      "name": "Ore_Iron_Sandstone"
    },
    {
      "x": 9,
      "y": 7,
      "z": 7,
      "name": "Ore_Iron_Sandstone"
    },
    {
      "x": 10,
      "y": 5,
      "z": 6,
      "name": "Ore_Iron_Sandstone"
    },
    {
      "x": 10,
      "y": 6,
      "z": 6,
      "name": "Ore_Iron_Sandstone"
    },
    {
      "x": 10,
      "y": 7,
      "z": 6,
      "name": "Ore_Iron_Sandstone"
    },
    {
      "x": 10,
      "y": 6,
      "z": 7,
      "name": "Ore_Iron_Sandstone"
    },
    {
      "x": 10,
      "y": 7,
      "z": 7,
      "name": "Ore_Iron_Sandstone"
    },
    {
      "x": 10,
      "y": 8,
      "z": 7,
      "name": "Ore_Iron_Sandstone"
    },
    {
      "x": 10,
      "y": 7,
      "z": 8,
      "name": "Ore_Iron_Sandstone"
    },
    {
      "x": 11,
      "y": 7,
      "z": 7,
      "name": "Ore_Iron_Sandstone"
    },
    {
      "x": 11,
      "y": 6,
      "z": 8,
      "name": "Ore_Iron_Sandstone"
    }
  ],
  "fluids": [
    {
      "x": -7,
      "y": 14,
      "z": -7,
      "name": "Empty",
      "level": 0
    },
    {
      "x": -7,
      "y": 13,
      "z": -6,
      "name": "Empty",
      "level": 0
    },
    {
      "x": -6,
      "y": 13,
      "z": -7,
      "name": "Empty",
      "level": 0
    },
    {
      "x": -6,
      "y": 12,
      "z": -6,
      "name": "Empty",
      "level": 0
    },
    {
      "x": -6,
      "y": 13,
      "z": -6,
      "name": "Empty",
      "level": 0
    },
    {
      "x": -6,
      "y": 14,
      "z": -6,
      "name": "Empty",
      "level": 0
    },
    {
      "x": -6,
      "y": 12,
      "z": -5,
      "name": "Empty",
      "level": 0
    },
    {
      "x": -6,
      "y": 13,
      "z": -5,
      "name": "Empty",
      "level": 0
    },
    {
      "x": -5,
      "y": 12,
      "z": -6,
      "name": "Empty",
      "level": 0
    },
    {
      "x": -5,
      "y": 13,
      "z": -6,
      "name": "Empty",
      "level": 0
    },
    {
      "x": -5,
      "y": 11,
      "z": -5,
      "name": "Empty",
      "level": 0
    },
    {
      "x": -5,
      "y": 12,
      "z": -5,
      "name": "Empty",
      "level": 0
    },
    {
      "x": -5,
      "y": 13,
      "z": -5,
      "name": "Empty",
      "level": 0
    },
    {
      "x": -5,
      "y": 11,
      "z": -4,
      "name": "Empty",
      "level": 0
    },
    {
      "x": -5,
      "y": 12,
      "z": -4,
      "name": "Empty",
      "level": 0
    },
    {
      "x": -5,
      "y": 10,
      "z": -3,
      "name": "Empty",
      "level": 0
    },
    {
      "x": -4,
      "y": 11,
      "z": -5,
      "name": "Empty",
      "level": 0
    },
    {
      "x": -4,
      "y": 12,
      "z": -5,
      "name": "Empty",
      "level": 0
    },
    {
      "x": -4,
      "y": 10,
      "z": -4,
      "name": "Empty",
      "level": 0
    },
    {
      "x": -4,
      "y": 11,
      "z": -4,
      "name": "Empty",
      "level": 0
    },
    {
      "x": -4,
      "y": 12,
      "z": -4,
      "name": "Empty",
      "level": 0
    },
    {
      "x": -4,
      "y": 9,
      "z": -3,
      "name": "Empty",
      "level": 0
    },
    {
      "x": -4,
      "y": 10,
      "z": -3,
      "name": "Empty",
      "level": 0
    },
    {
      "x": -4,
      "y": 11,
      "z": -3,
      "name": "Empty",
      "level": 0
    },
    {
      "x": -4,
      "y": 9,
      "z": -2,
      "name": "Empty",
      "level": 0
    },
    {
      "x": -4,
      "y": 10,
      "z": -2,
      "name": "Empty",
      "level": 0
    },
    {
      "x": -4,
      "y": 8,
      "z": -1,
      "name": "Empty",
      "level": 0
    },
    {
      "x": -4,
      "y": 7,
      "z": 0,
      "name": "Empty",
      "level": 0
    },
    {
      "x": -3,
      "y": 11,
      "z": -4,
      "name": "Empty",
      "level": 0
    },
    {
      "x": -3,
      "y": 9,
      "z": -3,
      "name": "Empty",
      "level": 0
    },
    {
      "x": -3,
      "y": 10,
      "z": -3,
      "name": "Empty",
      "level": 0
    },
    {
      "x": -3,
      "y": 8,
      "z": -2,
      "name": "Empty",
      "level": 0
    },
    {
      "x": -3,
      "y": 9,
      "z": -2,
      "name": "Empty",
      "level": 0
    },
    {
      "x": -3,
      "y": 10,
      "z": -2,
      "name": "Empty",
      "level": 0
    },
    {
      "x": -3,
      "y": 7,
      "z": -1,
      "name": "Empty",
      "level": 0
    },
    {
      "x": -3,
      "y": 8,
      "z": -1,
      "name": "Empty",
      "level": 0
    },
    {
      "x": -3,
      "y": 9,
      "z": -1,
      "name": "Empty",
      "level": 0
    },
    {
      "x": -3,
      "y": 6,
      "z": 0,
      "name": "Empty",
      "level": 0
    },
    {
      "x": -3,
      "y": 7,
      "z": 0,
      "name": "Empty",
      "level": 0
    },
    {
      "x": -3,
      "y": 8,
      "z": 0,
      "name": "Empty",
      "level": 0
    },
    {
      "x": -3,
      "y": 7,
      "z": 1,
      "name": "Empty",
      "level": 0
    },
    {
      "x": -2,
      "y": 9,
      "z": -2,
      "name": "Empty",
      "level": 0
    },
    {
      "x": -2,
      "y": 6,
      "z": -1,
      "name": "Empty",
      "level": 0
    },
    {
      "x": -2,
      "y": 8,
      "z": -1,
      "name": "Empty",
      "level": 0
    },
    {
      "x": -2,
      "y": 5,
      "z": 0,
      "name": "Empty",
      "level": 0
    },
    {
      "x": -2,
      "y": 6,
      "z": 0,
      "name": "Empty",
      "level": 0
    },
    {
      "x": -2,
      "y": 7,
      "z": 0,
      "name": "Empty",
      "level": 0
    },
    {
      "x": -2,
      "y": 6,
      "z": 1,
      "name": "Empty",
      "level": 0
    },
    {
      "x": -1,
      "y": 5,
      "z": -1,
      "name": "Empty",
      "level": 0
    },
    {
      "x": -1,
      "y": 4,
      "z": 0,
      "name": "Empty",
      "level": 0
    },
    {
      "x": -1,
      "y": 5,
      "z": 0,
      "name": "Empty",
      "level": 0
    },
    {
      "x": -1,
      "y": 6,
      "z": 0,
      "name": "Empty",
      "level": 0
    },
    {
      "x": -1,
      "y": 5,
      "z": 1,
      "name": "Empty",
      "level": 0
    },
    {
      "x": 0,
      "y": 4,
      "z": -1,
      "name": "Empty",
      "level": 0
    },
    {
      "x": 0,
      "y": 5,
      "z": -1,
      "name": "Empty",
      "level": 0
    },
    {
      "x": 0,
      "y": 3,
      "z": 0,
      "name": "Empty",
      "level": 0
    },
    {
      "x": 0,
      "y": 4,
      "z": 0,
      "name": "Empty",
      "level": 0
    },
    {
      "x": 0,
      "y": 5,
      "z": 0,
      "name": "Empty",
      "level": 0
    },
    {
      "x": 0,
      "y": 6,
      "z": 0,
      "name": "Empty",
      "level": 0
    },
    {
      "x": 0,
      "y": 4,
      "z": 1,
      "name": "Empty",
      "level": 0
    },
    {
      "x": 0,
      "y": 5,
      "z": 1,
      "name": "Empty",
      "level": 0
    },
    {
      "x": 0,
      "y": 6,
      "z": 1,
      "name": "Empty",
      "level": 0
    },
    {
      "x": 1,
      "y": 4,
      "z": 0,
      "name": "Empty",
      "level": 0
    },
    {
      "x": 1,
      "y": 5,
      "z": 0,
      "name": "Empty",
      "level": 0
    },
    {
      "x": 1,
      "y": 6,
      "z": 0,
      "name": "Empty",
      "level": 0
    },
    {
      "x": 1,
      "y": 3,
      "z": 1,
      "name": "Empty",
      "level": 0
    },
    {
      "x": 1,
      "y": 4,
      "z": 1,
      "name": "Empty",
      "level": 0
    },
    {
      "x": 1,
      "y": 5,
      "z": 1,
      "name": "Empty",
      "level": 0
    },
    {
      "x": 1,
      "y": 6,
      "z": 1,
      "name": "Empty",
      "level": 0
    },
    {
      "x": 1,
      "y": 7,
      "z": 1,
      "name": "Empty",
      "level": 0
    },
    {
      "x": 1,
      "y": 4,
      "z": 2,
      "name": "Empty",
      "level": 0
    },
    {
      "x": 1,
      "y": 5,
      "z": 2,
      "name": "Empty",
      "level": 0
    },
    {
      "x": 1,
      "y": 6,
      "z": 2,
      "name": "Empty",
      "level": 0
    },
    {
      "x": 2,
      "y": 5,
      "z": 0,
      "name": "Empty",
      "level": 0
    },
    {
      "x": 2,
      "y": 4,
      "z": 1,
      "name": "Empty",
      "level": 0
    },
    {
      "x": 2,
      "y": 5,
      "z": 1,
      "name": "Empty",
      "level": 0
    },
    {
      "x": 2,
      "y": 6,
      "z": 1,
      "name": "Empty",
      "level": 0
    },
    {
      "x": 2,
      "y": 5,
      "z": 2,
      "name": "Empty",
      "level": 0
    },
    {
      "x": 3,
      "y": 6,
      "z": 0,
      "name": "Empty",
      "level": 0
    },
    {
      "x": 3,
      "y": 5,
      "z": 1,
      "name": "Empty",
      "level": 0
    },
    {
      "x": 3,
      "y": 6,
      "z": 1,
      "name": "Empty",
      "level": 0
    },
    {
      "x": 3,
      "y": 7,
      "z": 1,
      "name": "Empty",
      "level": 0
    },
    {
      "x": 3,
      "y": 6,
      "z": 2,
      "name": "Empty",
      "level": 0
    },
    {
      "x": 3,
      "y": 7,
      "z": 2,
      "name": "Empty",
      "level": 0
    },
    {
      "x": 4,
      "y": 6,
      "z": 1,
      "name": "Empty",
      "level": 0
    },
    {
      "x": 4,
      "y": 7,
      "z": 1,
      "name": "Empty",
      "level": 0
    },
    {
      "x": 4,
      "y": 6,
      "z": 2,
      "name": "Empty",
      "level": 0
    },
    {
      "x": 4,
      "y": 7,
      "z": 2,
      "name": "Empty",
      "level": 0
    },
    {
      "x": 4,
      "y": 8,
      "z": 2,
      "name": "Empty",
      "level": 0
    },
    {
      "x": 4,
      "y": 7,
      "z": 3,
      "name": "Empty",
      "level": 0
    },
    {
      "x": 5,
      "y": 8,
      "z": 1,
      "name": "Empty",
      "level": 0
    },
    {
      "x": 5,
      "y": 7,
      "z": 2,
      "name": "Empty",
      "level": 0
    },
    {
      "x": 5,
      "y": 8,
      "z": 2,
      "name": "Empty",
      "level": 0
    },
    {
      "x": 5,
      "y": 9,
      "z": 2,
      "name": "Empty",
      "level": 0
    },
    {
      "x": 5,
      "y": 7,
      "z": 3,
      "name": "Empty",
      "level": 0
    },
    {
      "x": 5,
      "y": 8,
      "z": 3,
      "name": "Empty",
      "level": 0
    },
    {
      "x": 5,
      "y": 8,
      "z": 4,
      "name": "Empty",
      "level": 0
    },
    {
      "x": 6,
      "y": 7,
      "z": 2,
      "name": "Empty",
      "level": 0
    },
    {
      "x": 6,
      "y": 8,
      "z": 2,
      "name": "Empty",
      "level": 0
    },
    {
      "x": 6,
      "y": 6,
      "z": 3,
      "name": "Empty",
      "level": 0
    },
    {
      "x": 6,
      "y": 7,
      "z": 3,
      "name": "Empty",
      "level": 0
    },
    {
      "x": 6,
      "y": 8,
      "z": 3,
      "name": "Empty",
      "level": 0
    },
    {
      "x": 6,
      "y": 7,
      "z": 4,
      "name": "Empty",
      "level": 0
    },
    {
      "x": 6,
      "y": 8,
      "z": 4,
      "name": "Empty",
      "level": 0
    },
    {
      "x": 6,
      "y": 9,
      "z": 4,
      "name": "Empty",
      "level": 0
    },
    {
      "x": 6,
      "y": 7,
      "z": 5,
      "name": "Empty",
      "level": 0
    },
    {
      "x": 6,
      "y": 8,
      "z": 5,
      "name": "Empty",
      "level": 0
    },
    {
      "x": 7,
      "y": 7,
      "z": 3,
      "name": "Empty",
      "level": 0
    },
    {
      "x": 7,
      "y": 7,
      "z": 4,
      "name": "Empty",
      "level": 0
    },
    {
      "x": 7,
      "y": 8,
      "z": 4,
      "name": "Empty",
      "level": 0
    },
    {
      "x": 7,
      "y": 6,
      "z": 5,
      "name": "Empty",
      "level": 0
    },
    {
      "x": 7,
      "y": 7,
      "z": 5,
      "name": "Empty",
      "level": 0
    },
    {
      "x": 7,
      "y": 8,
      "z": 5,
      "name": "Empty",
      "level": 0
    },
    {
      "x": 7,
      "y": 7,
      "z": 6,
      "name": "Empty",
      "level": 0
    },
    {
      "x": 8,
      "y": 6,
      "z": 4,
      "name": "Empty",
      "level": 0
    },
    {
      "x": 8,
      "y": 5,
      "z": 5,
      "name": "Empty",
      "level": 0
    },
    {
      "x": 8,
      "y": 6,
      "z": 5,
      "name": "Empty",
      "level": 0
    },
    {
      "x": 8,
      "y": 7,
      "z": 5,
      "name": "Empty",
      "level": 0
    },
    {
      "x": 8,
      "y": 5,
      "z": 6,
      "name": "Empty",
      "level": 0
    },
    {
      "x": 8,
      "y": 6,
      "z": 6,
      "name": "Empty",
      "level": 0
    },
    {
      "x": 9,
      "y": 5,
      "z": 5,
      "name": "Empty",
      "level": 0
    },
    {
      "x": 9,
      "y": 6,
      "z": 5,
      "name": "Empty",
      "level": 0
    },
    {
      "x": 9,
      "y": 4,
      "z": 6,
      "name": "Empty",
      "level": 0
    },
    {
      "x": 9,
      "y": 5,
      "z": 6,
      "name": "Empty",
      "level": 0
    },
    {
      "x": 9,
      "y": 6,
      "z": 6,
      "name": "Empty",
      "level": 0
    },
    {
      "x": 9,
      "y": 7,
      "z": 6,
      "name": "Empty",
      "level": 0
    },
    {
      "x": 9,
      "y": 5,
      "z": 7,
      "name": "Empty",
      "level": 0
    },
    {
      "x": 9,
      "y": 6,
      "z": 7,
      "name": "Empty",
      "level": 0
    },
    {
      "x": 9,
      "y": 7,
      "z": 7,
      "name": "Empty",
      "level": 0
    },
    {
      "x": 10,
      "y": 5,
      "z": 6,
      "name": "Empty",
      "level": 0
    },
    {
      "x": 10,
      "y": 6,
      "z": 6,
      "name": "Empty",
      "level": 0
    },
    {
      "x": 10,
      "y": 7,
      "z": 6,
      "name": "Empty",
      "level": 0
    },
    {
      "x": 10,
      "y": 6,
      "z": 7,
      "name": "Empty",
      "level": 0
    },
    {
      "x": 10,
      "y": 7,
      "z": 7,
      "name": "Empty",
      "level": 0
    },
    {
      "x": 10,
      "y": 8,
      "z": 7,
      "name": "Empty",
      "level": 0
    },
    {
      "x": 10,
      "y": 7,
      "z": 8,
      "name": "Empty",
      "level": 0
    },
    {
      "x": 11,
      "y": 7,
      "z": 7,
      "name": "Empty",
      "level": 0
    },
    {
      "x": 11,
      "y": 6,
      "z": 8,
      "name": "Empty",
      "level": 0
    }
  ]
}