{
  "version": 8,
  "blockIdVersion": 11,
  "anchorX": 0,
  "anchorY": 0,
  "anchorZ": 0,
  "blocks": [
    {
      "x": -3,
      "y": 5,
      "z": -2,
      "name": "Ore_Thorium_Sandstone"
    },
    {
      "x": -3,
      "y": 6,
      "z": -1,
      "name": "Ore_Thorium_Sandstone"
    },
    {
      "x": -2,
      "y": 5,
      "z": -3,
      "name": "Ore_Iron_Sandstone"
    },
    {
      "x": -2,
      "y": 4,
      "z": -2,
      "name": "Ore_Thorium_Sandstone"
    },
    {
      "x": -2,
      "y": 5,
      "z": -2,
      "name": "Ore_Iron_Sandstone"
    },
    {
      "x": -2,
      "y": 6,
      "z": -2,
      "name": "Ore_Iron_Sandstone"
    },
    {
      "x": -2,
      "y": 5,
      "z": -1,
      "name": "Ore_Iron_Sandstone"
    },
    {
      "x": -2,
      "y": 6,
      "z": -1,
      "name": "Ore_Thorium_Sandstone"
    },
    {
      "x": -2,
      "y": 7,
      "z": -1,
      "name": "Ore_Iron_Sandstone"
    },
    {
      "x": -2,
      "y": 6,
      "z": 0,
      "name": "Ore_Thorium_Sandstone"
    },
    {
      "x": -2,
      "y": 7,
      "z": 0,
      "name": "Ore_Iron_Sandstone"
    },
    {
      "x": -2,
      "y": 6,
      "z": 1,
      "name": "Ore_Iron_Sandstone"
    },
    {
      "x": -1,
      "y": 5,
      "z": -2,
      "name": "Ore_Iron_Sandstone"
    },
    {
      "x": -1,
      "y": 6,
      "z": -1,
      "name": "Ore_Iron_Sandstone"
    },
    {
      "x": -1,
      "y": 7,
      "z": -1,
      "name": "Ore_Iron_Sandstone"
    },
    {
      "x": -1,
      "y": 6,
      "z": 0,
      "name": "Ore_Thorium_Sandstone"
    },
    {
      "x": -1,
      "y": 7,
      "z": 0,
      "name": "Ore_Iron_Sandstone"
    },
    {
      "x": -1,
      "y": 8,
      "z": 0,
      "name": "Ore_Thorium_Sandstone"
    },
    {
      "x": -1,
      "y": 5,
      "z": 1,
      "name": "Ore_Iron_Sandstone"
    },
    {
      "x": -1,
      "y": 6,
      "z": 1,
      "name": "Ore_Thorium_Sandstone"
    },
    {
      "x": -1,
      "y": 7,
      "z": 1,
      "name": "Ore_Iron_Sandstone"
    },
    {
      "x": -1,
      "y": 6,
      "z": 2,
      "name": "Ore_Thorium_Sandstone"
    },
    {
      "x": -1,
      "y": 7,
      "z": 2,
      "name": "Ore_Iron_Sandstone"
    },
    {
      "x": 0,
      "y": 7,
      "z": 0,
      "name": "Ore_Thorium_Sandstone"
    },
    {
      "x": 0,
      "y": 6,
      "z": 1,
      "name": "Ore_Iron_Sandstone"
    },
    {
      "x": 0,
      "y": 7,
      "z": 1,
      "name": "Ore_Thorium_Sandstone"
    },
    {
      "x": 0,
      "y": 6,
      "z": 2,
      "name": "Ore_Thorium_Sandstone"
    },
    {
      "x": 0,
      "y": 7,
      "z": 2,
      "name": "Ore_Iron_Sandstone"
    },
    {
      "x": 0,
      "y": 8,
      "z": 2,
      "name": "Ore_Thorium_Sandstone"
    },
    {
      "x": 0,
      "y": 6,
      "z": 3,
      "name": "Ore_Iron_Sandstone"
    },
    {
      "x": 0,
      "y": 7,
      "z": 3,
      "name": "Ore_Iron_Sandstone"
    },
    {
      "x": 1,
      "y": 6,
      "z": 2,
      "name": "Ore_Thorium_Sandstone"
    },
    {
      "x": 1,
      "y": 7,
      "z": 2,
      "name": "Ore_Iron_Sandstone"
    },
    {
      "x": 1,
      "y": 5,
      "z": 3,
      "name": "Ore_Thorium_Sandstone"
    },
    {
      "x": 1,
      "y": 6,
      "z": 3,
      "name": "Ore_Iron_Sandstone"
    },
    {
      "x": 1,
      "y": 7,
      "z": 3,
      "name": "Ore_Thorium_Sandstone"
    },
    {
      "x": 1,
      "y": 6,
      "z": 4,
      "name": "Ore_Thorium_Sandstone"
    },
    {
      "x": 1,
      "y": 8,
      "z": 4,
      "name": "Ore_Iron_Sandstone"
    },
    {
      "x": 1,
      "y": 9,
      "z": 4,
      "name": "Ore_Iron_Sandstone"
    },
    {
      "x": 2,
      "y": 7,
      "z": 2,
      "name": "Ore_Iron_Sandstone"
    },
    {
      "x": 2,
      "y": 6,
      "z": 3,
      "name": "Ore_Thorium_Sandstone"
    },
    {
      "x": 2,
      "y": 7,
      "z": 3,
      "name": "Ore_Iron_Sandstone"
    },
    {
      "x": 2,
      "y": 8,
      "z": 3,
      "name": "Ore_Iron_Sandstone"
    },
    {
      "x": 2,
      "y": 9,
      "z": 3,
      "name": "Ore_Iron_Sandstone"
    },
    {
      "x": 2,
      "y": 7,
      "z": 4,
      "name": "Ore_Iron_Sandstone"
    },
    {
      "x": 2,
      "y": 8,
      "z": 4,
      "name": "Ore_Iron_Sandstone"
    },
    {
      "x": 2,
      "y": 9,
      "z": 4,
      "name": "Ore_Iron_Sandstone"
    },
    {
      "x": 2,
      "y": 10,
      "z": 4,
      "name": "Ore_Iron_Sandstone"
    },
    {
      "x": 2,
      "y": 6,
      "z": 5,
      "name": "Ore_Thorium_Sandstone"
    },
    {
      "x": 2,
      "y": 7,
      "z": 5,
      "name": "Ore_Iron_Sandstone"
    },
    {
      "x": 2,
      "y": 8,
      "z": 5,
      "name": "Ore_Iron_Sandstone"
    },
    {
      "x": 2,
      "y": 9,
      "z": 5,
      "name": "Ore_Thorium_Sandstone"
    },
    {
      "x": 3,
      "y": 7,
      "z": 3,
      "name": "Ore_Thorium_Sandstone"
    },
    {
      "x": 3,
      "y": 8,
      "z": 3,
      "name": "Ore_Iron_Sandstone"
    },
    {
      "x": 3,
      "y": 6,
      "z": 4,
      "name": "Ore_Iron_Sandstone"
    },
    {
      "x": 3,
      "y": 7,
      "z": 4,
      "name": "Ore_Iron_Sandstone"
    },
    {
      "x": 3,
      "y": 8,
      "z": 4,
      "name": "Ore_Thorium_Sandstone"
    },
    {
      "x": 3,
      "y": 9,
      "z": 4,
      "name": "Ore_Iron_Sandstone"
    },
    {
      "x": 3,
      "y": 5,
      "z": 5,
      "name": "Ore_Iron_Sandstone"
    },
    {
      "x": 3,
      "y": 6,
      "z": 5,
      "name": "Ore_Iron_Sandstone"
    },
    {
      "x": 3,
      "y": 7,
      "z": 5,
      "name": "Ore_Iron_Sandstone"
    },
    {
      "x": 3,
      "y": 8,
      "z": 5,
      "name": "Ore_Iron_Sandstone"
    },
    {
      "x": 3,
      "y": 6,
      "z": 6,
      "name": "Ore_Iron_Sandstone"
    },
    {
      "x": 3,
      "y": 7,
      "z": 6,
      "name": "Ore_Thorium_Sandstone"
    },
    {
      "x": 3,
      "y": 8,
      "z": 6,
      "name": "Ore_Thorium_Sandstone"
    },
    {
      "x": 4,
      "y": 7,
      "z": 4,
      "name": "Ore_Iron_Sandstone"
    },
    {
      "x": 4,
      "y": 8,
      "z": 4,
      "name": "Ore_Iron_Sandstone"
    },
    {
      "x": 4,
      "y": 6,
      "z": 5,
      "name": "Ore_Thorium_Sandstone"
    },
    {
      "x": 4,
      "y": 7,
      "z": 5,
      "name": "Ore_Thorium_Sandstone"
    }
  ],
  "fluids": [
    {
      "x": -3,
      "y": 5,
      "z": -2,
      "name": "Empty",
      "level": 0
    },
    {
      "x": -3,
      "y": 6,
      "z": -1,
      "name": "Empty",
      "level": 0
    },
    {
      "x": -2,
      "y": 5,
      "z": -3,
      "name": "Empty",
      "level": 0
    },
    {
      "x": -2,
      "y": 4,
      "z": -2,
      "name": "Empty",
      "level": 0
    },
    {
      "x": -2,
      "y": 5,
      "z": -2,
      "name": "Empty",
      "level": 0
    },
    {
      "x": -2,
      "y": 6,
      "z": -2,
      "name": "Empty",
      "level": 0
    },
    {
      "x": -2,
      "y": 5,
      "z": -1,
      "name": "Empty",
      "level": 0
    },
    {
      "x": -2,
      "y": 6,
      "z": -1,
      "name": "Empty",
      "level": 0
    },
    {
      "x": -2,
      "y": 7,
      "z": -1,
      "name": "Empty",
      "level": 0
    },
    {
      "x": -2,
      "y": 6,
      "z": 0,
      "name": "Empty",
      "level": 0
    },
    {
      "x": -2,
      "y": 7,
      "z": 0,
      "name": "Empty",
      "level": 0
    },
    {
      "x": -2,
      "y": 6,
      "z": 1,
      "name": "Empty",
      "level": 0
    },
    {
      "x": -1,
      "y": 5,
      "z": -2,
      "name": "Empty",
      "level": 0
    },
    {
      "x": -1,
      "y": 6,
      "z": -1,
      "name": "Empty",
      "level": 0
    },
    {
      "x": -1,
      "y": 7,
      "z": -1,
      "name": "Empty",
      "level": 0
    },
    {
      "x": -1,
      "y": 6,
      "z": 0,
      "name": "Empty",
      "level": 0
    },
    {
      "x": -1,
      "y": 7,
      "z": 0,
      "name": "Empty",
      "level": 0
    },
    {
      "x": -1,
      "y": 8,
      "z": 0,
      "name": "Empty",
      "level": 0
    },
    {
      "x": -1,
      "y": 5,
      "z": 1,
      "name": "Empty",
      "level": 0
    },
    {
      "x": -1,
      "y": 6,
      "z": 1,
      "name": "Empty",
      "level": 0
    },
    {
      "x": -1,
      "y": 7,
      "z": 1,
      "name": "Empty",
      "level": 0
    },
    {
      "x": -1,
      "y": 6,
      "z": 2,
      "name": "Empty",
      "level": 0
    },
    {
      "x": -1,
      "y": 7,
      "z": 2,
      "name": "Empty",
      "level": 0
    },
    {
      "x": 0,
      "y": 7,
      "z": 0,
      "name": "Empty",
      "level": 0
    },
    {
      "x": 0,
      "y": 6,
      "z": 1,
      "name": "Empty",
      "level": 0
    },
    {
      "x": 0,
      "y": 7,
      "z": 1,
      "name": "Empty",
      "level": 0
    },
    {
      "x": 0,
      "y": 6,
      "z": 2,
      "name": "Empty",
      "level": 0
    },
    {
      "x": 0,
      "y": 7,
      "z": 2,
      "name": "Empty",
      "level": 0
    },
    {
      "x": 0,
      "y": 8,
      "z": 2,
      "name": "Empty",
      "level": 0
    },
    {
      "x": 0,
      "y": 6,
      "z": 3,
      "name": "Empty",
      "level": 0
    },
    {
      "x": 0,
      "y": 7,
      "z": 3,
      "name": "Empty",
      "level": 0
    },
    {
      "x": 1,
      "y": 6,
      "z": 2,
      "name": "Empty",
      "level": 0
    },
    {
      "x": 1,
      "y": 7,
      "z": 2,
      "name": "Empty",
      "level": 0
    },
    {
      "x": 1,
      "y": 5,
      "z": 3,
      "name": "Empty",
      "level": 0
    },
    {
      "x": 1,
      "y": 6,
      "z": 3,
      "name": "Empty",
      "level": 0
    },
    {
      "x": 1,
      "y": 7,
      "z": 3,
      "name": "Empty",
      "level": 0
    },
    {
      "x": 1,
      "y": 6,
      "z": 4,
      "name": "Empty",
      "level": 0
    },
    {
      "x": 1,
      "y": 8,
      "z": 4,
      "name": "Empty",
      "level": 0
    },
    {
      "x": 1,
      "y": 9,
      "z": 4,
      "name": "Empty",
      "level": 0
    },
    {
      "x": 2,
      "y": 7,
      "z": 2,
      "name": "Empty",
      "level": 0
    },
    {
      "x": 2,
      "y": 6,
      "z": 3,
      "name": "Empty",
      "level": 0
    },
    {
      "x": 2,
      "y": 7,
      "z": 3,
      "name": "Empty",
      "level": 0
    },
    {
      "x": 2,
      "y": 8,
      "z": 3,
      "name": "Empty",
      "level": 0
    },
    {
      "x": 2,
      "y": 9,
      "z": 3,
      "name": "Empty",
      "level": 0
    },
    {
      "x": 2,
      "y": 7,
      "z": 4,
      "name": "Empty",
      "level": 0
    },
    {
      "x": 2,
      "y": 8,
      "z": 4,
      "name": "Empty",
      "level": 0
    },
    {
      "x": 2,
      "y": 9,
      "z": 4,
      "name": "Empty",
      "level": 0
    },
    {
      "x": 2,
      "y": 10,
      "z": 4,
      "name": "Empty",
      "level": 0
    },
    {
      "x": 2,
      "y": 6,
      "z": 5,
      "name": "Empty",
      "level": 0
    },
    {
      "x": 2,
      "y": 7,
      "z": 5,
      "name": "Empty",
      "level": 0
    },
    {
      "x": 2,
      "y": 8,
      "z": 5,
      "name": "Empty",
      "level": 0
    },
    {
      "x": 2,
      "y": 9,
      "z": 5,
      "name": "Empty",
      "level": 0
    },
    {
      "x": 3,
      "y": 7,
      "z": 3,
      "name": "Empty",
      "level": 0
    },
    {
      "x": 3,
      "y": 8,
      "z": 3,
      "name": "Empty",
      "level": 0
    },
    {
      "x": 3,
      "y": 6,
      "z": 4,
      "name": "Empty",
      "level": 0
    },
    {
      "x": 3,
      "y": 7,
      "z": 4,
      "name": "Empty",
      "level": 0
    },
    {
      "x": 3,
      "y": 8,
      "z": 4,
      "name": "Empty",
      "level": 0
    },
    {
      "x": 3,
      "y": 9,
      "z": 4,
      "name": "Empty",
      "level": 0
    },
    {
      "x": 3,
      "y": 5,
      "z": 5,
      "name": "Empty",
      "level": 0
    },
    {
      "x": 3,
      "y": 6,
      "z": 5,
      "name": "Empty",
      "level": 0
    },
    {
      "x": 3,
      "y": 7,
      "z": 5,
      "name": "Empty",
      "level": 0
    },
    {
      "x": 3,
      "y": 8,
      "z": 5,
      "name": "Empty",
      "level": 0
    },
    {
      "x": 3,
      "y": 6,
      "z": 6,
      "name": "Empty",
      "level": 0
    },
    {
      "x": 3,
      "y": 7,
      "z": 6,
      "name": "Empty",
      "level": 0
    },
    {
      "x": 3,
      "y": 8,
      "z": 6,
      "name": "Empty",
      "level": 0
    },
    {
      "x": 4,
      "y": 7,
      "z": 4,
      "name": "Empty",
      "level": 0
    },
    {
      "x": 4,
      "y": 8,
      "z": 4,
      "name": "Empty",
      "level": 0
    },
    {
      "x": 4,
      "y": 6,
      "z": 5,
      "name": "Empty",
      "level": 0
    },
    {
      "x": 4,
      "y": 7,
      "z": 5,
      "name": "Empty",
      "level": 0
    }
  ]
}