{
  "version": 8,
  "blockIdVersion": 11,
  "anchorX": 0,
  "anchorY": 0,
  "anchorZ": 0,
  "blocks": [
    {
      "x": -23,
      "y": 25,
      "z": 32,
      "name": "Plant_Moss_Wall_Yellow",
      "support": 15,
      "rotation": 3
    },
    {
      "x": -22,
      "y": 22,
      "z": 31,
      "name": "Plant_Moss_Wall_Yellow",
      "support": 15,
      "rotation": 3
    },
    {
      "x": -22,
      "y": 23,
      "z": 31,
      "name": "Plant_Moss_Wall_Yellow",
      "support": 15,
      "rotation": 3
    },
    {
      "x": -22,
      "y": 24,
      "z": 31,
      "name": "Plant_Moss_Wall_Yellow",
      "support": 15,
      "rotation": 3
    },
    {
      "x": -22,
      "y": 24,
      "z": 32,
      "name": "Plant_Moss_Cave_Yellow",
      "support": 15,
      "rotation": 34
    },
    {
      "x": -22,
      "y": 25,
      "z": 32,
      "name": "Rock_Volcanic"
    },
    {
      "x": -22,
      "y": 26,
      "z": 32,
      "name": "Plant_Moss_Rug_Yellow",
      "support": 15
    },
    {
      "x": -22,
      "y": 24,
      "z": 33,
      "name": "Plant_Moss_Wall_Yellow",
      "support": 15
    },
    {
      "x": -22,
      "y": 25,
      "z": 33,
      "name": "Plant_Moss_Wall_Yellow",
      "support": 15
    },
    {
      "x": -21,
      "y": 21,
      "z": 29,
      "name": "Plant_Moss_Wall_Yellow",
      "support": 15,
      "rotation": 3
    },
    {
      "x": -21,
      "y": 22,
      "z": 29,
      "name": "Plant_Moss_Wall_Yellow",
      "support": 15,
      "rotation": 3
    },
    {
      "x": -21,
      "y": 23,
      "z": 29,
      "name": "Plant_Moss_Wall_Yellow",
      "support": 15,
      "rotation": 3
    },
    {
      "x": -21,
      "y": 21,
      "z": 30,
      "name": "Plant_Moss_Wall_Yellow",
      "support": 15,
      "rotation": 3
    },
    {
      "x": -21,
      "y": 22,
      "z": 30,
      "name": "Plant_Moss_Wall_Yellow",
      "support": 15,
      "rotation": 3
    },
    {
      "x": -21,
      "y": 23,
      "z": 30,
      "name": "Plant_Moss_Wall_Yellow",
      "support": 15,
      "rotation": 3
    },
    {
      "x": -21,
      "y": 24,
      "z": 30,
      "name": "Plant_Moss_Wall_Yellow",
      "support": 15,
      "rotation": 2
    },
    {
      "x": -21,
      "y": 21,
      "z": 31,
      "name": "Rock_Crystal_Yellow_Small",
      "rotation": 34
    },
    {
      "x": -21,
      "y": 22,
      "z": 31,
      "name": "Rock_Volcanic"
    },
    {
      "x": -21,
      "y": 23,
      "z": 31,
      "name": "Rock_Volcanic"
    },
    {
      "x": -21,
      "y": 24,
      "z": 31,
      "name": "Rock_Volcanic"
    },
    {
      "x": -21,
      "y": 25,
      "z": 31,
      "name": "Plant_Moss_Rug_Yellow",
      "support": 15
    },
    {
      "x": -21,
      "y": 23,
      "z": 32,
      "name": "Plant_Moss_Cave_Yellow",
      "support": 15,
      "rotation": 34
    },
    {
      "x": -21,
      "y": 24,
      "z": 32,
      "name": "Rock_Volcanic_Cracked_Lava"
    },
    {
      "x": -21,
      "y": 25,
      "z": 32,
      "name": "Rock_Volcanic"
    },
    {
      "x": -21,
      "y": 26,
      "z": 32,
      "name": "Plant_Moss_Rug_Yellow",
      "support": 15
    },
    {
      "x": -21,
      "y": 23,
      "z": 33,
      "name": "Plant_Moss_Cave_Yellow",
      "support": 15,
      "rotation": 34
    },
    {
      "x": -21,
      "y": 24,
      "z": 33,
      "name": "Rock_Volcanic_Cracked_Lava"
    },
    {
      "x": -21,
      "y": 25,
      "z": 33,
      "name": "Rock_Volcanic"
    },
    {
      "x": -21,
      "y": 26,
      "z": 33,
      "name": "Plant_Moss_Rug_Yellow",
      "support": 15
    },
    {
      "x": -21,
      "y": 24,
      "z": 34,
      "name": "Plant_Moss_Wall_Yellow",
      "support": 15
    },
    {
      "x": -21,
      "y": 25,
      "z": 34,
      "name": "Plant_Moss_Wall_Yellow",
      "support": 15
    },
    {
      "x": -20,
      "y": 20,
      "z": 28,
      "name": "Plant_Moss_Wall_Yellow",
      "support": 15,
      "rotation": 3
    },
    {
      "x": -20,
      "y": 21,
      "z": 28,
      "name": "Plant_Moss_Wall_Yellow",
      "support": 15,
      "rotation": 3
    },
    {
      "x": -20,
      "y": 23,
      "z": 28,
      "name": "Plant_Moss_Wall_Yellow",
      "support": 15,
      "rotation": 2
    },
    {
      "x": -20,
      "y": 20,
      "z": 29,
      "name": "Plant_Moss_Cave_Yellow",
      "support": 15,
      "rotation": 34
    },
    {
      "x": -20,
      "y": 21,
      "z": 29,
      "name": "Rock_Volcanic"
    },
    {
      "x": -20,
      "y": 22,
      "z": 29,
      "name": "Rock_Volcanic"
    },
    {
      "x": -20,
      "y": 23,
      "z": 29,
      "name": "Rock_Volcanic"
    },
    {
      "x": -20,
      "y": 24,
      "z": 29,
      "name": "Plant_Moss_Rug_Yellow",
      "support": 15
    },
    {
      "x": -20,
      "y": 20,
      "z": 30,
      "name": "Plant_Moss_Cave_Yellow",
      "support": 15,
      "rotation": 34
    },
    {
      "x": -20,
      "y": 21,
      "z": 30,
      "name": "Rock_Volcanic"
    },
    {
      "x": -20,
      "y": 22,
      "z": 30,
      "name": "Rock_Volcanic"
    },
    {
      "x": -20,
      "y": 23,
      "z": 30,
      "name": "Rock_Volcanic"
    },
    {
      "x": -20,
      "y": 24,
      "z": 30,
      "name": "Plant_Moss_Rug_Yellow",
      "support": 15
    },
    {
      "x": -20,
      "y": 20,
      "z": 31,
      "name": "Plant_Moss_Cave_Yellow",
      "support": 15,
      "rotation": 34
    },
    {
      "x": -20,
      "y": 21,
      "z": 31,
      "name": "Rock_Volcanic"
    },
    {
      "x": -20,
      "y": 22,
      "z": 31,
      "name": "Rock_Volcanic"
    },
    {
      "x": -20,
      "y": 23,
      "z": 31,
      "name": "Rock_Volcanic"
    },
    {
      "x": -20,
      "y": 24,
      "z": 31,
      "name": "Rock_Volcanic_Cracked_Lava"
    },
    {
      "x": -20,
      "y": 25,
      "z": 31,
      "name": "Rock_Crystal_Yellow_Large"
    },
    {
      "x": -20,
      "y": 23,
      "z": 32,
      "name": "Plant_Moss_Wall_Yellow",
      "support": 15,
      "rotation": 1
    },
    {
      "x": -20,
      "y": 24,
      "z": 32,
      "name": "Plant_Moss_Wall_Yellow",
      "support": 15,
      "rotation": 1
    },
    {
      "x": -20,
      "y": 22,
      "z": 33,
      "name": "Rock_Volcanic_Stalactite_Large",
      "filler": 31744,
      "rotation": 34
    },
    {
      "x": -20,
      "y": 23,
      "z": 33,
      "name": "Rock_Volcanic_Stalactite_Large",
      "rotation": 34
    },
    {
      "x": -20,
      "y": 24,
      "z": 33,
      "name": "Rock_Volcanic_Cracked_Lava"
    },
    {
      "x": -20,
      "y": 25,
      "z": 33,
      "name": "Plant_Moss_Rug_Yellow",
      "support": 15
    },
    {
      "x": -20,
      "y": 24,
      "z": 34,
      "name": "Plant_Moss_Wall_Yellow",
      "support": 15
    },
    {
      "x": -19,
      "y": 20,
      "z": 24,
      "name": "Plant_Moss_Wall_Yellow",
      "support": 15,
      "rotation": 3
    },
    {
      "x": -19,
      "y": 18,
      "z": 25,
      "name": "Plant_Moss_Wall_Yellow",
      "support": 15,
      "rotation": 3
    },
    {
      "x": -19,
      "y": 18,
      "z": 26,
      "name": "Plant_Moss_Wall_Yellow",
      "support": 15,
      "rotation": 3
    },
    {
      "x": -19,
      "y": 19,
      "z": 26,
      "name": "Plant_Moss_Wall_Yellow",
      "support": 15,
      "rotation": 3
    },
    {
      "x": -19,
      "y": 20,
      "z": 27,
      "name": "Plant_Moss_Wall_Yellow",
      "support": 15,
      "rotation": 3
    },
    {
      "x": -19,
      "y": 21,
      "z": 27,
      "name": "Plant_Moss_Wall_Yellow",
      "support": 15,
      "rotation": 3
    },
    {
      "x": -19,
      "y": 19,
      "z": 28,
      "name": "Rock_Crystal_Yellow_Medium",
      "rotation": 34
    },
    {
      "x": -19,
      "y": 20,
      "z": 28,
      "name": "Rock_Volcanic"
    },
    {
      "x": -19,
      "y": 21,
      "z": 28,
      "name": "Rock_Volcanic_Cracked_Lava"
    },
    {
      "x": -19,
      "y": 22,
      "z": 28,
      "name": "Plant_Moss_Rug_Yellow",
      "support": 15
    },
    {
      "x": -19,
      "y": 18,
      "z": 29,
      "name": "Rock_Volcanic_Stalactite_Large",
      "filler": 31744,
      "rotation": 34
    },
    {
      "x": -19,
      "y": 19,
      "z": 29,
      "name": "Rock_Volcanic_Stalactite_Large",
      "rotation": 34
    },
    {
      "x": -19,
      "y": 20,
      "z": 29,
      "name": "Rock_Volcanic"
    },
    {
      "x": -19,
      "y": 21,
      "z": 29,
      "name": "Rock_Volcanic"
    },
    {
      "x": -19,
      "y": 22,
      "z": 29,
      "name": "Rock_Volcanic_Cracked_Lava"
    },
    {
      "x": -19,
      "y": 23,
      "z": 29,
      "name": "Rock_Crystal_Yellow_Medium"
    },
    {
      "x": -19,
      "y": 21,
      "z": 30,
      "name": "Rock_Volcanic"
    },
    {
      "x": -19,
      "y": 22,
      "z": 30,
      "name": "Rock_Volcanic"
    },
    {
      "x": -19,
      "y": 23,
      "z": 30,
      "name": "Rock_Volcanic"
    },
    {
      "x": -19,
      "y": 24,
      "z": 30,
      "name": "Plant_Moss_Rug_Yellow",
      "support": 15
    },
    {
      "x": -19,
      "y": 21,
      "z": 31,
      "name": "Plant_Moss_Wall_Yellow",
      "support": 15,
      "rotation": 1
    },
    {
      "x": -19,
      "y": 22,
      "z": 31,
      "name": "Plant_Moss_Wall_Yellow",
      "support": 15,
      "rotation": 1
    },
    {
      "x": -19,
      "y": 23,
      "z": 31,
      "name": "Plant_Moss_Wall_Yellow",
      "support": 15,
      "rotation": 1
    },
    {
      "x": -19,
      "y": 24,
      "z": 31,
      "name": "Plant_Moss_Wall_Yellow",
      "support": 15,
      "rotation": 1
    },
    {
      "x": -19,
      "y": 24,
      "z": 33,
      "name": "Plant_Moss_Wall_Yellow",
      "support": 15,
      "rotation": 1
    },
    {
      "x": -18,
      "y": 19,
      "z": 23,
      "name": "Plant_Moss_Wall_Yellow",
      "support": 15,
      "rotation": 3
    },
    {
      "x": -18,
      "y": 20,
      "z": 23,
      "name": "Plant_Moss_Wall_Yellow",
      "support": 15,
      "rotation": 3
    },
    {
      "x": -18,
      "y": 16,
      "z": 24,
      "name": "Ore_Gold_Volcanic"
    },
    {
      "x": -18,
      "y": 17,
      "z": 24,
      "name": "Rock_Volcanic"
    },
    {
      "x": -18,
      "y": 18,
      "z": 24,
      "name": "Rock_Volcanic"
    },
    {
      "x": -18,
      "y": 19,
      "z": 24,
      "name": "Rock_Volcanic_Cracked_Lava"
    },
    {
      "x": -18,
      "y": 20,
      "z": 24,
      "name": "Rock_Volcanic"
    },
    {
      "x": -18,
      "y": 21,
      "z": 24,
      "name": "Plant_Moss_Rug_Yellow",
      "support": 15
    },
    {
      "x": -18,
      "y": 16,
      "z": 25,
      "name": "Plant_Moss_Cave_Yellow",
      "support": 15,
      "rotation": 34
    },
    {
      "x": -18,
      "y": 17,
      "z": 25,
      "name": "Rock_Volcanic"
    },
    {
      "x": -18,
      "y": 18,
      "z": 25,
      "name": "Rock_Volcanic_Cracked_Lava"
    },
    {
      "x": -18,
      "y": 19,
      "z": 25,
      "name": "Plant_Moss_Rug_Yellow",
      "support": 15
    },
    {
      "x": -18,
      "y": 20,
      "z": 25,
      "name": "Plant_Moss_Wall_Yellow",
      "support": 15,
      "rotation": 3
    },
    {
      "x": -18,
      "y": 18,
      "z": 26,
      "name": "Rock_Volcanic"
    },
    {
      "x": -18,
      "y": 19,
      "z": 26,
      "name": "Rock_Volcanic"
    },
    {
      "x": -18,
      "y": 20,
      "z": 26,
      "name": "Plant_Moss_Rug_Yellow",
      "support": 15
    },
    {
      "x": -18,
      "y": 18,
      "z": 27,
      "name": "Plant_Moss_Cave_Yellow",
      "support": 15,
      "rotation": 34
    },
    {
      "x": -18,
      "y": 19,
      "z": 27,
      "name": "Rock_Volcanic_Cracked_Lava"
    },
    {
      "x": -18,
      "y": 20,
      "z": 27,
      "name": "Rock_Volcanic_Cracked_Lava"
    },
    {
      "x": -18,
      "y": 21,
      "z": 27,
      "name": "Rock_Volcanic"
    },
    {
      "x": -18,
      "y": 22,
      "z": 27,
      "name": "Plant_Moss_Rug_Yellow",
      "support": 15
    },
    {
      "x": -18,
      "y": 19,
      "z": 28,
      "name": "Rock_Crystal_Yellow_Medium",
      "rotation": 34
    },
    {
      "x": -18,
      "y": 20,
      "z": 28,
      "name": "Rock_Volcanic"
    },
    {
      "x": -18,
      "y": 21,
      "z": 28,
      "name": "Rock_Volcanic_Cracked_Lava"
    },
    {
      "x": -18,
      "y": 22,
      "z": 28,
      "name": "Plant_Moss_Rug_Yellow",
      "support": 15
    },
    {
      "x": -18,
      "y": 19,
      "z": 29,
      "name": "Rock_Volcanic_Stalactite_Small",
      "rotation": 34
    },
    {
      "x": -18,
      "y": 20,
      "z": 29,
      "name": "Rock_Volcanic"
    },
    {
      "x": -18,
      "y": 21,
      "z": 29,
      "name": "Rock_Volcanic_Cracked_Lava"
    },
    {
      "x": -18,
      "y": 22,
      "z": 29,
      "name": "Plant_Moss_Rug_Yellow",
      "support": 15
    },
    {
      "x": -18,
      "y": 20,
      "z": 30,
      "name": "Plant_Moss_Wall_Yellow",
      "support": 15,
      "rotation": 1
    },
    {
      "x": -18,
      "y": 21,
      "z": 30,
      "name": "Plant_Moss_Wall_Yellow",
      "support": 15,
      "rotation": 1
    },
    {
      "x": -18,
      "y": 22,
      "z": 30,
      "name": "Plant_Moss_Wall_Yellow",
      "support": 15,
      "rotation": 1
    },
    {
      "x": -18,
      "y": 23,
      "z": 30,
      "name": "Plant_Moss_Wall_Yellow",
      "support": 15,
      "rotation": 1
    },
    {
      "x": -17,
      "y": 18,
      "z": 21,
      "name": "Plant_Moss_Wall_Yellow",
      "support": 15,
      "rotation": 3
    },
    {
      "x": -17,
      "y": 19,
      "z": 22,
      "name": "Plant_Moss_Wall_Yellow",
      "support": 15,
      "rotation": 3
    },
    {
      "x": -17,
      "y": 20,
      "z": 22,
      "name": "Plant_Moss_Wall_Yellow",
      "support": 15,
      "rotation": 2
    },
    {
      "x": -17,
      "y": 15,
      "z": 23,
      "name": "Rock_Volcanic_Stalactite_Small",
      "rotation": 34
    },
    {
      "x": -17,
      "y": 16,
      "z": 23,
      "name": "Rock_Volcanic_Cracked_Lava"
    },
    {
      "x": -17,
      "y": 17,
      "z": 23,
      "name": "Rock_Volcanic"
    },
    {
      "x": -17,
      "y": 18,
      "z": 23,
      "name": "Rock_Volcanic"
    },
    {
      "x": -17,
      "y": 19,
      "z": 23,
      "name": "Rock_Volcanic_Cracked_Lava"
    },
    {
      "x": -17,
      "y": 20,
      "z": 23,
      "name": "Rock_Volcanic"
    },
    {
      "x": -17,
      "y": 21,
      "z": 23,
      "name": "Plant_Moss_Rug_Yellow",
      "support": 15
    },
    {
      "x": -17,
      "y": 16,
      "z": 24,
      "name": "Plant_Moss_Cave_Yellow",
      "support": 15,
      "rotation": 34
    },
    {
      "x": -17,
      "y": 17,
      "z": 24,
      "name": "Rock_Volcanic"
    },
    {
      "x": -17,
      "y": 18,
      "z": 24,
      "name": "Rock_Volcanic"
    },
    {
      "x": -17,
      "y": 19,
      "z": 24,
      "name": "Rock_Volcanic_Cracked_Lava"
    },
    {
      "x": -17,
      "y": 20,
      "z": 24,
      "name": "Rock_Volcanic"
    },
    {
      "x": -17,
      "y": 21,
      "z": 24,
      "name": "Rock_Volcanic"
    },
    {
      "x": -17,
      "y": 22,
      "z": 24,
      "name": "Plant_Moss_Rug_Yellow",
      "support": 15
    },
    {
      "x": -17,
      "y": 16,
      "z": 25,
      "name": "Plant_Moss_Cave_Yellow",
      "support": 15,
      "rotation": 34
    },
    {
      "x": -17,
      "y": 17,
      "z": 25,
      "name": "Rock_Volcanic"
    },
    {
      "x": -17,
      "y": 18,
      "z": 25,
      "name": "Rock_Volcanic_Cracked_Lava"
    },
    {
      "x": -17,
      "y": 19,
      "z": 25,
      "name": "Plant_Moss_Rug_Yellow",
      "support": 15
    },
    {
      "x": -17,
      "y": 20,
      "z": 25,
      "name": "Plant_Moss_Wall_Yellow",
      "support": 15,
      "rotation": 3
    },
    {
      "x": -17,
      "y": 21,
      "z": 25,
      "name": "Plant_Moss_Wall_Yellow",
      "support": 15
    },
    {
      "x": -17,
      "y": 17,
      "z": 26,
      "name": "Rock_Volcanic"
    },
    {
      "x": -17,
      "y": 18,
      "z": 26,
      "name": "Rock_Volcanic"
    },
    {
      "x": -17,
      "y": 19,
      "z": 26,
      "name": "Rock_Volcanic"
    },
    {
      "x": -17,
      "y": 20,
      "z": 26,
      "name": "Rock_Volcanic"
    },
    {
      "x": -17,
      "y": 21,
      "z": 26,
      "name": "Plant_Moss_Rug_Yellow",
      "support": 15
    },
    {
      "x": -17,
      "y": 19,
      "z": 27,
      "name": "Rock_Volcanic"
    },
    {
      "x": -17,
      "y": 20,
      "z": 27,
      "name": "Rock_Volcanic"
    },
    {
      "x": -17,
      "y": 21,
      "z": 27,
      "name": "Plant_Moss_Rug_Yellow",
      "support": 15
    },
    {
      "x": -17,
      "y": 19,
      "z": 28,
      "name": "Rock_Volcanic"
    },
    {
      "x": -17,
      "y": 20,
      "z": 28,
      "name": "Rock_Volcanic"
    },
    {
      "x": -17,
      "y": 21,
      "z": 28,
      "name": "Rock_Volcanic"
    },
    {
      "x": -17,
      "y": 22,
      "z": 28,
      "name": "Plant_Moss_Rug_Yellow",
      "support": 15
    },
    {
      "x": -17,
      "y": 19,
      "z": 29,
      "name": "Plant_Moss_Wall_Yellow",
      "support": 15
    },
    {
      "x": -17,
      "y": 20,
      "z": 29,
      "name": "Plant_Moss_Wall_Yellow",
      "support": 15,
      "rotation": 1
    },
    {
      "x": -17,
      "y": 21,
      "z": 29,
      "name": "Plant_Moss_Wall_Yellow",
      "support": 15,
      "rotation": 1
    },
    {
      "x": -16,
      "y": 14,
      "z": 17,
      "name": "Plant_Moss_Wall_Yellow",
      "support": 15,
      "rotation": 3
    },
    {
      "x": -16,
      "y": 16,
      "z": 19,
      "name": "Plant_Moss_Wall_Yellow",
      "support": 15,
      "rotation": 3
    },
    {
      "x": -16,
      "y": 17,
      "z": 19,
      "name": "Plant_Moss_Wall_Yellow",
      "support": 15,
      "rotation": 3
    },
    {
      "x": -16,
      "y": 15,
      "z": 20,
      "name": "Rock_Crystal_Yellow_Medium",
      "rotation": 7
    },
    {
      "x": -16,
      "y": 17,
      "z": 20,
      "name": "Plant_Moss_Wall_Yellow",
      "support": 15,
      "rotation": 3
    },
    {
      "x": -16,
      "y": 14,
      "z": 21,
      "name": "Plant_Moss_Cave_Yellow",
      "support": 15,
      "rotation": 34
    },
    {
      "x": -16,
      "y": 15,
      "z": 21,
      "name": "Rock_Volcanic_Cracked_Lava"
    },
    {
      "x": -16,
      "y": 16,
      "z": 21,
      "name": "Ore_Gold_Volcanic"
    },
    {
      "x": -16,
      "y": 17,
      "z": 21,
      "name": "Rock_Volcanic"
    },
    {
      "x": -16,
      "y": 18,
      "z": 21,
      "name": "Rock_Volcanic_Cracked_Lava"
    },
    {
      "x": -16,
      "y": 19,
      "z": 21,
      "name": "Plant_Moss_Rug_Yellow",
      "support": 15
    },
    {
      "x": -16,
      "y": 15,
      "z": 22,
      "name": "Ore_Gold_Volcanic"
    },
    {
      "x": -16,
      "y": 16,
      "z": 22,
      "name": "Ore_Gold_Volcanic"
    },
    {
      "x": -16,
      "y": 17,
      "z": 22,
      "name": "Rock_Volcanic_Cracked_Lava"
    },
    {
      "x": -16,
      "y": 18,
      "z": 22,
      "name": "Rock_Volcanic"
    },
    {
      "x": -16,
      "y": 19,
      "z": 22,
      "name": "Rock_Volcanic"
    },
    {
      "x": -16,
      "y": 20,
      "z": 22,
      "name": "Plant_Moss_Rug_Yellow",
      "support": 15
    },
    {
      "x": -16,
      "y": 14,
      "z": 23,
      "name": "Plant_Moss_Cave_Yellow",
      "support": 15,
      "rotation": 34
    },
    {
      "x": -16,
      "y": 15,
      "z": 23,
      "name": "Rock_Volcanic"
    },
    {
      "x": -16,
      "y": 16,
      "z": 23,
      "name": "Rock_Volcanic"
    },
    {
      "x": -16,
      "y": 17,
      "z": 23,
      "name": "Rock_Volcanic"
    },
    {
      "x": -16,
      "y": 18,
      "z": 23,
      "name": "Rock_Volcanic"
    },
    {
      "x": -16,
      "y": 19,
      "z": 23,
      "name": "Rock_Volcanic"
    },
    {
      "x": -16,
      "y": 20,
      "z": 23,
      "name": "Rock_Volcanic"
    },
    {
      "x": -16,
      "y": 21,
      "z": 23,
      "name": "Plant_Moss_Rug_Yellow",
      "support": 15
    },
    {
      "x": -16,
      "y": 16,
      "z": 24,
      "name": "Rock_Volcanic"
    },
    {
      "x": -16,
      "y": 17,
      "z": 24,
      "name": "Rock_Volcanic"
    },
    {
      "x": -16,
      "y": 18,
      "z": 24,
      "name": "Rock_Volcanic_Cracked_Lava"
    },
    {
      "x": -16,
      "y": 19,
      "z": 24,
      "name": "Rock_Volcanic"
    },
    {
      "x": -16,
      "y": 20,
      "z": 24,
      "name": "Rock_Volcanic"
    },
    {
      "x": -16,
      "y": 21,
      "z": 24,
      "name": "Plant_Moss_Rug_Yellow",
      "support": 15
    },
    {
      "x": -16,
      "y": 16,
      "z": 25,
      "name": "Plant_Moss_Cave_Yellow",
      "support": 15,
      "rotation": 34
    },
    {
      "x": -16,
      "y": 17,
      "z": 25,
      "name": "Rock_Volcanic"
    },
    {
      "x": -16,
      "y": 18,
      "z": 25,
      "name": "Rock_Volcanic_Cracked_Lava"
    },
    {
      "x": -16,
      "y": 19,
      "z": 25,
      "name": "Rock_Volcanic"
    },
    {
      "x": -16,
      "y": 20,
      "z": 25,
      "name": "Rock_Volcanic"
    },
    {
      "x": -16,
      "y": 21,
      "z": 25,
      "name": "Rock_Volcanic"
    },
    {
      "x": -16,
      "y": 22,
      "z": 25,
      "name": "Plant_Moss_Rug_Yellow",
      "support": 15
    },
    {
      "x": -16,
      "y": 15,
      "z": 26,
      "name": "Rock_Volcanic_Stalactite_Large",
      "filler": 31744,
      "rotation": 34
    },
    {
      "x": -16,
      "y": 16,
      "z": 26,
      "name": "Rock_Volcanic_Stalactite_Large",
      "rotation": 34
    },
    {
      "x": -16,
      "y": 17,
      "z": 26,
      "name": "Rock_Volcanic"
    },
    {
      "x": -16,
      "y": 18,
      "z": 26,
      "name": "Rock_Volcanic"
    },
    {
      "x": -16,
      "y": 19,
      "z": 26,
      "name": "Rock_Volcanic_Cracked_Lava"
    },
    {
      "x": -16,
      "y": 20,
      "z": 26,
      "name": "Rock_Volcanic"
    },
    {
      "x": -16,
      "y": 21,
      "z": 26,
      "name": "Plant_Moss_Rug_Yellow",
      "support": 15
    },
    {
      "x": -16,
      "y": 15,
      "z": 27,
      "name": "Rock_Volcanic_Stalactite_Large",
      "filler": 31744,
      "rotation": 34
    },
    {
      "x": -16,
      "y": 16,
      "z": 27,
      "name": "Rock_Volcanic_Stalactite_Large",
      "rotation": 34
    },
    {
      "x": -16,
      "y": 17,
      "z": 27,
      "name": "Rock_Volcanic"
    },
    {
      "x": -16,
      "y": 18,
      "z": 27,
      "name": "Rock_Volcanic"
    },
    {
      "x": -16,
      "y": 19,
      "z": 27,
      "name": "Rock_Volcanic_Cracked_Lava"
    },
    {
      "x": -16,
      "y": 20,
      "z": 27,
      "name": "Rock_Volcanic"
    },
    {
      "x": -16,
      "y": 21,
      "z": 27,
      "name": "Plant_Moss_Rug_Yellow",
      "support": 15
    },
    {
      "x": -16,
      "y": 17,
      "z": 28,
      "name": "Plant_Moss_Wall_Yellow",
      "support": 15
    },
    {
      "x": -16,
      "y": 18,
      "z": 28,
      "name": "Plant_Moss_Wall_Yellow",
      "support": 15
    },
    {
      "x": -16,
      "y": 19,
      "z": 28,
      "name": "Plant_Moss_Wall_Yellow",
      "support": 15,
      "rotation": 1
    },
    {
      "x": -16,
      "y": 20,
      "z": 28,
      "name": "Plant_Moss_Wall_Yellow",
      "support": 15,
      "rotation": 1
    },
    {
      "x": -16,
      "y": 21,
      "z": 28,
      "name": "Plant_Moss_Wall_Yellow",
      "support": 15,
      "rotation": 1
    },
    {
      "x": -15,
      "y": 14,
      "z": 16,
      "name": "Rock_Crystal_Yellow_Small",
      "rotation": 7
    },
    {
      "x": -15,
      "y": 12,
      "z": 17,
      "name": "Rock_Volcanic"
    },
    {
      "x": -15,
      "y": 13,
      "z": 17,
      "name": "Rock_Volcanic_Cracked_Lava"
    },
    {
      "x": -15,
      "y": 14,
      "z": 17,
      "name": "Rock_Volcanic_Cracked_Lava"
    },
    {
      "x": -15,
      "y": 15,
      "z": 17,
      "name": "Plant_Moss_Rug_Yellow",
      "support": 15
    },
    {
      "x": -15,
      "y": 14,
      "z": 18,
      "name": "Plant_Moss_Wall_Yellow",
      "support": 15,
      "rotation": 3
    },
    {
      "x": -15,
      "y": 15,
      "z": 18,
      "name": "Plant_Moss_Wall_Yellow",
      "support": 15,
      "rotation": 3
    },
    {
      "x": -15,
      "y": 16,
      "z": 18,
      "name": "Plant_Moss_Wall_Yellow",
      "support": 15,
      "rotation": 3
    },
    {
      "x": -15,
      "y": 17,
      "z": 18,
      "name": "Plant_Moss_Wall_Yellow",
      "support": 15,
      "rotation": 2
    },
    {
      "x": -15,
      "y": 15,
      "z": 19,
      "name": "Rock_Crystal_Yellow_Large",
      "rotation": 7
    },
    {
      "x": -15,
      "y": 16,
      "z": 19,
      "name": "Rock_Volcanic_Cracked_Lava"
    },
    {
      "x": -15,
      "y": 17,
      "z": 19,
      "name": "Rock_Volcanic"
    },
    {
      "x": -15,
      "y": 18,
      "z": 19,
      "name": "Plant_Moss_Rug_Yellow",
      "support": 15
    },
    {
      "x": -15,
      "y": 14,
      "z": 20,
      "name": "Rock_Volcanic_Cracked_Lava"
    },
    {
      "x": -15,
      "y": 15,
      "z": 20,
      "name": "Ore_Gold_Volcanic"
    },
    {
      "x": -15,
      "y": 16,
      "z": 20,
      "name": "Rock_Volcanic_Cracked_Lava"
    },
    {
      "x": -15,
      "y": 17,
      "z": 20,
      "name": "Rock_Volcanic"
    },
    {
      "x": -15,
      "y": 18,
      "z": 20,
      "name": "Plant_Moss_Rug_Yellow",
      "support": 15
    },
    {
      "x": -15,
      "y": 14,
      "z": 21,
      "name": "Rock_Volcanic"
    },
    {
      "x": -15,
      "y": 15,
      "z": 21,
      "name": "Ore_Gold_Volcanic"
    },
    {
      "x": -15,
      "y": 16,
      "z": 21,
      "name": "Ore_Gold_Volcanic"
    },
    {
      "x": -15,
      "y": 17,
      "z": 21,
      "name": "Rock_Volcanic"
    },
    {
      "x": -15,
      "y": 18,
      "z": 21,
      "name": "Rock_Volcanic"
    },
    {
      "x": -15,
      "y": 19,
      "z": 21,
      "name": "Plant_Moss_Rug_Yellow",
      "support": 15
    },
    {
      "x": -15,
      "y": 15,
      "z": 22,
      "name": "Rock_Volcanic"
    },
    {
      "x": -15,
      "y": 16,
      "z": 22,
      "name": "Rock_Volcanic"
    },
    {
      "x": -15,
      "y": 17,
      "z": 22,
      "name": "Rock_Volcanic"
    },
    {
      "x": -15,
      "y": 18,
      "z": 22,
      "name": "Rock_Volcanic_Cracked_Lava"
    },
    {
      "x": -15,
      "y": 19,
      "z": 22,
      "name": "Plant_Moss_Rug_Yellow",
      "support": 15
    },
    {
      "x": -15,
      "y": 20,
      "z": 22,
      "name": "Plant_Moss_Wall_Yellow",
      "support": 15,
      "rotation": 2
    },
    {
      "x": -15,
      "y": 14,
      "z": 23,
      "name": "Rock_Volcanic_Stalactite_Large",
      "filler": 31744,
      "rotation": 34
    },
    {
      "x": -15,
      "y": 15,
      "z": 23,
      "name": "Rock_Volcanic_Stalactite_Large",
      "rotation": 34
    },
    {
      "x": -15,
      "y": 16,
      "z": 23,
      "name": "Rock_Volcanic"
    },
    {
      "x": -15,
      "y": 17,
      "z": 23,
      "name": "Rock_Volcanic"
    },
    {
      "x": -15,
      "y": 18,
      "z": 23,
      "name": "Rock_Volcanic"
    },
    {
      "x": -15,
      "y": 19,
      "z": 23,
      "name": "Rock_Volcanic"
    },
    {
      "x": -15,
      "y": 20,
      "z": 23,
      "name": "Rock_Volcanic_Cracked_Lava"
    },
    {
      "x": -15,
      "y": 21,
      "z": 23,
      "name": "Plant_Moss_Rug_Yellow",
      "support": 15
    },
    {
      "x": -15,
      "y": 16,
      "z": 24,
      "name": "Rock_Volcanic"
    },
    {
      "x": -15,
      "y": 17,
      "z": 24,
      "name": "Rock_Volcanic"
    },
    {
      "x": -15,
      "y": 18,
      "z": 24,
      "name": "Rock_Volcanic_Cracked_Lava"
    },
    {
      "x": -15,
      "y": 19,
      "z": 24,
      "name": "Rock_Volcanic"
    },
    {
      "x": -15,
      "y": 20,
      "z": 24,
      "name": "Rock_Volcanic"
    },
    {
      "x": -15,
      "y": 21,
      "z": 24,
      "name": "Plant_Moss_Rug_Yellow",
      "support": 15
    },
    {
      "x": -15,
      "y": 15,
      "z": 25,
      "name": "Plant_Moss_Cave_Yellow",
      "support": 15,
      "rotation": 34
    },
    {
      "x": -15,
      "y": 16,
      "z": 25,
      "name": "Rock_Volcanic"
    },
    {
      "x": -15,
      "y": 17,
      "z": 25,
      "name": "Rock_Volcanic"
    },
    {
      "x": -15,
      "y": 18,
      "z": 25,
      "name": "Rock_Volcanic_Cracked_Lava"
    },
    {
      "x": -15,
      "y": 19,
      "z": 25,
      "name": "Rock_Volcanic"
    },
    {
      "x": -15,
      "y": 20,
      "z": 25,
      "name": "Rock_Volcanic_Cracked_Lava"
    },
    {
      "x": -15,
      "y": 21,
      "z": 25,
      "name": "Plant_Moss_Rug_Yellow",
      "support": 15
    },
    {
      "x": -15,
      "y": 17,
      "z": 26,
      "name": "Plant_Moss_Wall_Yellow",
      "support": 15
    },
    {
      "x": -15,
      "y": 18,
      "z": 26,
      "name": "Plant_Moss_Wall_Yellow",
      "support": 15
    },
    {
      "x": -15,
      "y": 19,
      "z": 26,
      "name": "Plant_Moss_Wall_Yellow",
      "support": 15,
      "rotation": 1
    },
    {
      "x": -15,
      "y": 20,
      "z": 26,
      "name": "Plant_Moss_Wall_Yellow",
      "support": 15,
      "rotation": 1
    },
    {
      "x": -15,
      "y": 17,
      "z": 27,
      "name": "Plant_Moss_Wall_Yellow",
      "support": 15,
      "rotation": 1
    },
    {
      "x": -15,
      "y": 18,
      "z": 27,
      "name": "Plant_Moss_Wall_Yellow",
      "support": 15,
      "rotation": 1
    },
    {
      "x": -15,
      "y": 19,
      "z": 27,
      "name": "Plant_Moss_Wall_Yellow",
      "support": 15,
      "rotation": 1
    },
    {
      "x": -15,
      "y": 20,
      "z": 27,
      "name": "Plant_Moss_Wall_Yellow",
      "support": 15,
      "rotation": 1
    },
    {
      "x": -14,
      "y": 14,
      "z": 15,
      "name": "Plant_Moss_Wall_Yellow",
      "support": 15,
      "rotation": 2
    },
    {
      "x": -14,
      "y": 11,
      "z": 16,
      "name": "Rock_Volcanic_Cracked_Lava"
    },
    {
      "x": -14,
      "y": 12,
      "z": 16,
      "name": "Rock_Volcanic"
    },
    {
      "x": -14,
      "y": 13,
      "z": 16,
      "name": "Rock_Volcanic"
    },
    {
      "x": -14,
      "y": 14,
      "z": 16,
      "name": "Rock_Volcanic"
    },
    {
      "x": -14,
      "y": 15,
      "z": 16,
      "name": "Plant_Moss_Rug_Yellow",
      "support": 15
    },
    {
      "x": -14,
      "y": 12,
      "z": 17,
      "name": "Rock_Volcanic"
    },
    {
      "x": -14,
      "y": 13,
      "z": 17,
      "name": "Rock_Volcanic_Cracked_Lava"
    },
    {
      "x": -14,
      "y": 14,
      "z": 17,
      "name": "Rock_Volcanic_Cracked_Lava"
    },
    {
      "x": -14,
      "y": 15,
      "z": 17,
      "name": "Plant_Moss_Rug_Yellow",
      "support": 15
    },
    {
      "x": -14,
      "y": 11,
      "z": 18,
      "name": "Rock_Volcanic_Stalactite_Small",
      "rotation": 34
    },
    {
      "x": -14,
      "y": 12,
      "z": 18,
      "name": "Rock_Volcanic"
    },
    {
      "x": -14,
      "y": 13,
      "z": 18,
      "name": "Rock_Volcanic"
    },
    {
      "x": -14,
      "y": 14,
      "z": 18,
      "name": "Rock_Volcanic"
    },
    {
      "x": -14,
      "y": 15,
      "z": 18,
      "name": "Rock_Volcanic"
    },
    {
      "x": -14,
      "y": 16,
      "z": 18,
      "name": "Rock_Volcanic"
    },
    {
      "x": -14,
      "y": 17,
      "z": 18,
      "name": "Rock_Crystal_Yellow_Medium"
    },
    {
      "x": -14,
      "y": 14,
      "z": 19,
      "name": "Rock_Volcanic"
    },
    {
      "x": -14,
      "y": 15,
      "z": 19,
      "name": "Ore_Gold_Volcanic"
    },
    {
      "x": -14,
      "y": 16,
      "z": 19,
      "name": "Ore_Gold_Volcanic"
    },
    {
      "x": -14,
      "y": 17,
      "z": 19,
      "name": "Rock_Volcanic"
    },
    {
      "x": -14,
      "y": 18,
      "z": 19,
      "name": "Plant_Moss_Rug_Yellow",
      "support": 15
    },
    {
      "x": -14,
      "y": 14,
      "z": 20,
      "name": "Rock_Volcanic_Cracked_Lava"
    },
    {
      "x": -14,
      "y": 15,
      "z": 20,
      "name": "Ore_Gold_Volcanic"
    },
    {
      "x": -14,
      "y": 16,
      "z": 20,
      "name": "Rock_Volcanic_Cracked_Lava"
    },
    {
      "x": -14,
      "y": 17,
      "z": 20,
      "name": "Rock_Volcanic"
    },
    {
      "x": -14,
      "y": 18,
      "z": 20,
      "name": "Plant_Moss_Rug_Yellow",
      "support": 15
    },
    {
      "x": -14,
      "y": 12,
      "z": 21,
      "name": "Rock_Volcanic_Stalactite_Large",
      "filler": 31744,
      "rotation": 34
    },
    {
      "x": -14,
      "y": 13,
      "z": 21,
      "name": "Rock_Volcanic_Stalactite_Large",
      "rotation": 34
    },
    {
      "x": -14,
      "y": 14,
      "z": 21,
      "name": "Rock_Volcanic_Cracked_Lava"
    },
    {
      "x": -14,
      "y": 15,
      "z": 21,
      "name": "Rock_Volcanic"
    },
    {
      "x": -14,
      "y": 16,
      "z": 21,
      "name": "Rock_Volcanic_Cracked_Lava"
    },
    {
      "x": -14,
      "y": 17,
      "z": 21,
      "name": "Rock_Volcanic"
    },
    {
      "x": -14,
      "y": 18,
      "z": 21,
      "name": "Rock_Volcanic"
    },
    {
      "x": -14,
      "y": 19,
      "z": 21,
      "name": "Plant_Moss_Rug_Yellow",
      "support": 15
    },
    {
      "x": -14,
      "y": 14,
      "z": 22,
      "name": "Plant_Moss_Cave_Yellow",
      "support": 15,
      "rotation": 34
    },
    {
      "x": -14,
      "y": 15,
      "z": 22,
      "name": "Rock_Volcanic_Cracked_Lava"
    },
    {
      "x": -14,
      "y": 16,
      "z": 22,
      "name": "Rock_Volcanic"
    },
    {
      "x": -14,
      "y": 17,
      "z": 22,
      "name": "Rock_Volcanic"
    },
    {
      "x": -14,
      "y": 18,
      "z": 22,
      "name": "Rock_Volcanic"
    },
    {
      "x": -14,
      "y": 19,
      "z": 22,
      "name": "Plant_Moss_Rug_Yellow",
      "support": 15
    },
    {
      "x": -14,
      "y": 15,
      "z": 23,
      "name": "Rock_Volcanic"
    },
    {
      "x": -14,
      "y": 16,
      "z": 23,
      "name": "Rock_Volcanic"
    },
    {
      "x": -14,
      "y": 17,
      "z": 23,
      "name": "Rock_Volcanic"
    },
    {
      "x": -14,
      "y": 18,
      "z": 23,
      "name": "Rock_Volcanic"
    },
    {
      "x": -14,
      "y": 19,
      "z": 23,
      "name": "Rock_Volcanic"
    },
    {
      "x": -14,
      "y": 16,
      "z": 24,
      "name": "Rock_Volcanic"
    },
    {
      "x": -14,
      "y": 17,
      "z": 24,
      "name": "Rock_Volcanic"
    },
    {
      "x": -14,
      "y": 18,
      "z": 24,
      "name": "Rock_Volcanic"
    },
    {
      "x": -14,
      "y": 19,
      "z": 24,
      "name": "Rock_Volcanic"
    },
    {
      "x": -14,
      "y": 20,
      "z": 24,
      "name": "Rock_Volcanic"
    },
    {
      "x": -14,
      "y": 21,
      "z": 24,
      "name": "Plant_Moss_Rug_Yellow",
      "support": 15
    },
    {
      "x": -14,
      "y": 18,
      "z": 25,
      "name": "Plant_Moss_Wall_Yellow",
      "support": 15,
      "rotation": 1
    },
    {
      "x": -14,
      "y": 19,
      "z": 25,
      "name": "Plant_Moss_Wall_Yellow",
      "support": 15,
      "rotation": 1
    },
    {
      "x": -14,
      "y": 20,
      "z": 25,
      "name": "Plant_Moss_Wall_Yellow",
      "support": 15,
      "rotation": 1
    },
    {
      "x": -13,
      "y": 9,
      "z": 15,
      "name": "Rock_Volcanic"
    },
    {
      "x": -13,
      "y": 10,
      "z": 15,
      "name": "Rock_Volcanic"
    },
    {
      "x": -13,
      "y": 11,
      "z": 15,
      "name": "Rock_Volcanic_Cracked_Lava"
    },
    {
      "x": -13,
      "y": 12,
      "z": 15,
      "name": "Rock_Volcanic"
    },
    {
      "x": -13,
      "y": 13,
      "z": 15,
      "name": "Rock_Crystal_Yellow_Large",
      "rotation": 7
    },
    {
      "x": -13,
      "y": 14,
      "z": 15,
      "name": "Rock_Volcanic_Cracked_Lava"
    },
    {
      "x": -13,
      "y": 15,
      "z": 15,
      "name": "Rock_Volcanic_Cracked_Lava"
    },
    {
      "x": -13,
      "y": 10,
      "z": 16,
      "name": "Rock_Volcanic"
    },
    {
      "x": -13,
      "y": 11,
      "z": 16,
      "name": "Rock_Volcanic"
    },
    {
      "x": -13,
      "y": 12,
      "z": 16,
      "name": "Rock_Volcanic"
    },
    {
      "x": -13,
      "y": 13,
      "z": 16,
      "name": "Rock_Crystal_Yellow_Block",
      "rotation": 5
    },
    {
      "x": -13,
      "y": 14,
      "z": 16,
      "name": "Rock_Volcanic_Cracked_Lava"
    },
    {
      "x": -13,
      "y": 15,
      "z": 16,
      "name": "Rock_Volcanic_Cracked_Lava"
    },
    {
      "x": -13,
      "y": 16,
      "z": 16,
      "name": "Rock_Volcanic"
    },
    {
      "x": -13,
      "y": 11,
      "z": 17,
      "name": "Rock_Magma_Cooled"
    },
    {
      "x": -13,
      "y": 12,
      "z": 17,
      "name": "Rock_Volcanic"
    },
    {
      "x": -13,
      "y": 13,
      "z": 17,
      "name": "Rock_Volcanic_Cracked_Lava"
    },
    {
      "x": -13,
      "y": 14,
      "z": 17,
      "name": "Rock_Volcanic"
    },
    {
      "x": -13,
      "y": 15,
      "z": 17,
      "name": "Rock_Volcanic"
    },
    {
      "x": -13,
      "y": 12,
      "z": 18,
      "name": "Rock_Magma_Cooled"
    },
    {
      "x": -13,
      "y": 13,
      "z": 18,
      "name": "Rock_Magma_Cooled"
    },
    {
      "x": -13,
      "y": 14,
      "z": 18,
      "name": "Rock_Volcanic"
    },
    {
      "x": -13,
      "y": 15,
      "z": 18,
      "name": "Ore_Gold_Volcanic"
    },
    {
      "x": -13,
      "y": 16,
      "z": 18,
      "name": "Ore_Gold_Volcanic"
    },
    {
      "x": -13,
      "y": 17,
      "z": 18,
      "name": "Rock_Volcanic"
    },
    {
      "x": -13,
      "y": 18,
      "z": 18,
      "name": "Rock_Crystal_Yellow_Medium"
    },
    {
      "x": -13,
      "y": 12,
      "z": 19,
      "name": "Rock_Volcanic"
    },
    {
      "x": -13,
      "y": 13,
      "z": 19,
      "name": "Rock_Volcanic"
    },
    {
      "x": -13,
      "y": 14,
      "z": 19,
      "name": "Rock_Volcanic"
    },
    {
      "x": -13,
      "y": 15,
      "z": 19,
      "name": "Rock_Volcanic"
    },
    {
      "x": -13,
      "y": 16,
      "z": 19,
      "name": "Rock_Volcanic"
    },
    {
      "x": -13,
      "y": 17,
      "z": 19,
      "name": "Rock_Volcanic"
    },
    {
      "x": -13,
      "y": 14,
      "z": 20,
      "name": "Rock_Volcanic_Cracked_Lava"
    },
    {
      "x": -13,
      "y": 15,
      "z": 20,
      "name": "Rock_Volcanic"
    },
    {
      "x": -13,
      "y": 16,
      "z": 20,
      "name": "Rock_Volcanic"
    },
    {
      "x": -13,
      "y": 17,
      "z": 20,
      "name": "Rock_Volcanic"
    },
    {
      "x": -13,
      "y": 18,
      "z": 20,
      "name": "Rock_Crystal_Yellow_Medium"
    },
    {
      "x": -13,
      "y": 14,
      "z": 21,
      "name": "Rock_Volcanic"
    },
    {
      "x": -13,
      "y": 15,
      "z": 21,
      "name": "Rock_Volcanic"
    },
    {
      "x": -13,
      "y": 16,
      "z": 21,
      "name": "Rock_Volcanic"
    },
    {
      "x": -13,
      "y": 17,
      "z": 21,
      "name": "Rock_Volcanic"
    },
    {
      "x": -13,
      "y": 18,
      "z": 21,
      "name": "Plant_Moss_Rug_Yellow",
      "support": 15
    },
    {
      "x": -13,
      "y": 14,
      "z": 22,
      "name": "Plant_Moss_Cave_Yellow",
      "support": 15,
      "rotation": 34
    },
    {
      "x": -13,
      "y": 15,
      "z": 22,
      "name": "Rock_Volcanic_Cracked_Lava"
    },
    {
      "x": -13,
      "y": 16,
      "z": 22,
      "name": "Rock_Volcanic"
    },
    {
      "x": -13,
      "y": 17,
      "z": 22,
      "name": "Rock_Volcanic"
    },
    {
      "x": -13,
      "y": 18,
      "z": 22,
      "name": "Rock_Volcanic"
    },
    {
      "x": -13,
      "y": 19,
      "z": 22,
      "name": "Plant_Moss_Rug_Yellow",
      "support": 15
    },
    {
      "x": -13,
      "y": 14,
      "z": 23,
      "name": "Plant_Moss_Cave_Yellow",
      "support": 15,
      "rotation": 34
    },
    {
      "x": -13,
      "y": 15,
      "z": 23,
      "name": "Rock_Volcanic"
    },
    {
      "x": -13,
      "y": 16,
      "z": 23,
      "name": "Rock_Volcanic_Cracked_Lava"
    },
    {
      "x": -13,
      "y": 17,
      "z": 23,
      "name": "Rock_Volcanic"
    },
    {
      "x": -13,
      "y": 18,
      "z": 23,
      "name": "Rock_Volcanic"
    },
    {
      "x": -13,
      "y": 19,
      "z": 23,
      "name": "Rock_Volcanic"
    },
    {
      "x": -13,
      "y": 20,
      "z": 23,
      "name": "Plant_Moss_Rug_Yellow",
      "support": 15
    },
    {
      "x": -13,
      "y": 17,
      "z": 24,
      "name": "Plant_Moss_Wall_Yellow",
      "support": 15,
      "rotation": 1
    },
    {
      "x": -13,
      "y": 18,
      "z": 24,
      "name": "Plant_Moss_Wall_Yellow",
      "support": 15,
      "rotation": 1
    },
    {
      "x": -13,
      "y": 19,
      "z": 24,
      "name": "Plant_Moss_Wall_Yellow",
      "support": 15,
      "rotation": 1
    },
    {
      "x": -13,
      "y": 20,
      "z": 24,
      "name": "Plant_Moss_Wall_Yellow",
      "support": 15,
      "rotation": 1
    },
    {
      "x": -12,
      "y": 13,
      "z": 12,
      "name": "Rock_Volcanic"
    },
    {
      "x": -12,
      "y": 14,
      "z": 12,
      "name": "Rock_Crystal_Yellow_Medium"
    },
    {
      "x": -12,
      "y": 15,
      "z": 13,
      "name": "Rock_Crystal_Yellow_Medium",
      "rotation": 7
    },
    {
      "x": -12,
      "y": 8,
      "z": 14,
      "name": "Rock_Volcanic"
    },
    {
      "x": -12,
      "y": 9,
      "z": 14,
      "name": "Rock_Volcanic"
    },
    {
      "x": -12,
      "y": 10,
      "z": 14,
      "name": "Rock_Volcanic"
    },
    {
      "x": -12,
      "y": 11,
      "z": 14,
      "name": "Rock_Crystal_Yellow_Medium",
      "rotation": 7
    },
    {
      "x": -12,
      "y": 12,
      "z": 14,
      "name": "Rock_Crystal_Yellow_Small",
      "rotation": 7
    },
    {
      "x": -12,
      "y": 13,
      "z": 14,
      "name": "Rock_Crystal_Yellow_Medium",
      "rotation": 7
    },
    {
      "x": -12,
      "y": 14,
      "z": 14,
      "name": "Rock_Volcanic"
    },
    {
      "x": -12,
      "y": 15,
      "z": 14,
      "name": "Rock_Volcanic"
    },
    {
      "x": -12,
      "y": 9,
      "z": 15,
      "name": "Rock_Volcanic_Stalactite_Small",
      "rotation": 34
    },
    {
      "x": -12,
      "y": 10,
      "z": 15,
      "name": "Rock_Volcanic"
    },
    {
      "x": -12,
      "y": 11,
      "z": 15,
      "name": "Rock_Volcanic"
    },
    {
      "x": -12,
      "y": 12,
      "z": 15,
      "name": "Rock_Volcanic"
    },
    {
      "x": -12,
      "y": 13,
      "z": 15,
      "name": "Rock_Crystal_Yellow_Block",
      "rotation": 5
    },
    {
      "x": -12,
      "y": 14,
      "z": 15,
      "name": "Rock_Volcanic"
    },
    {
      "x": -12,
      "y": 15,
      "z": 15,
      "name": "Rock_Volcanic"
    },
    {
      "x": -12,
      "y": 10,
      "z": 16,
      "name": "Rock_Magma_Cooled"
    },
    {
      "x": -12,
      "y": 11,
      "z": 16,
      "name": "Rock_Volcanic"
    },
    {
      "x": -12,
      "y": 12,
      "z": 16,
      "name": "Rock_Volcanic"
    },
    {
      "x": -12,
      "y": 13,
      "z": 16,
      "name": "Rock_Crystal_Yellow_Block",
      "rotation": 5
    },
    {
      "x": -12,
      "y": 14,
      "z": 16,
      "name": "Rock_Volcanic_Cracked_Lava"
    },
    {
      "x": -12,
      "y": 15,
      "z": 16,
      "name": "Rock_Volcanic_Cracked_Lava"
    },
    {
      "x": -12,
      "y": 16,
      "z": 16,
      "name": "Rock_Volcanic"
    },
    {
      "x": -12,
      "y": 10,
      "z": 17,
      "name": "Ore_Adamantite_Magma"
    },
    {
      "x": -12,
      "y": 11,
      "z": 17,
      "name": "Rock_Volcanic_Cracked_Lava"
    },
    {
      "x": -12,
      "y": 12,
      "z": 17,
      "name": "Rock_Volcanic"
    },
    {
      "x": -12,
      "y": 13,
      "z": 17,
      "name": "Rock_Volcanic"
    },
    {
      "x": -12,
      "y": 14,
      "z": 17,
      "name": "Rock_Volcanic"
    },
    {
      "x": -12,
      "y": 15,
      "z": 17,
      "name": "Ore_Gold_Volcanic"
    },
    {
      "x": -12,
      "y": 16,
      "z": 17,
      "name": "Ore_Gold_Volcanic"
    },
    {
      "x": -12,
      "y": 11,
      "z": 18,
      "name": "Ore_Adamantite_Magma"
    },
    {
      "x": -12,
      "y": 12,
      "z": 18,
      "name": "Rock_Volcanic_Cracked_Lava"
    },
    {
      "x": -12,
      "y": 13,
      "z": 18,
      "name": "Rock_Volcanic"
    },
    {
      "x": -12,
      "y": 14,
      "z": 18,
      "name": "Rock_Volcanic"
    },
    {
      "x": -12,
      "y": 15,
      "z": 18,
      "name": "Rock_Volcanic_Cracked_Lava"
    },
    {
      "x": -12,
      "y": 16,
      "z": 18,
      "name": "Rock_Volcanic"
    },
    {
      "x": -12,
      "y": 17,
      "z": 18,
      "name": "Rock_Crystal_Yellow_Large"
    },
    {
      "x": -12,
      "y": 12,
      "z": 19,
      "name": "Rock_Magma_Cooled"
    },
    {
      "x": -12,
      "y": 13,
      "z": 19,
      "name": "Rock_Volcanic"
    },
    {
      "x": -12,
      "y": 14,
      "z": 19,
      "name": "Rock_Volcanic"
    },
    {
      "x": -12,
      "y": 15,
      "z": 19,
      "name": "Rock_Volcanic"
    },
    {
      "x": -12,
      "y": 16,
      "z": 19,
      "name": "Rock_Volcanic"
    },
    {
      "x": -12,
      "y": 17,
      "z": 19,
      "name": "Rock_Crystal_Yellow_Medium"
    },
    {
      "x": -12,
      "y": 12,
      "z": 20,
      "name": "Rock_Volcanic_Stalactite_Large",
      "filler": 31744,
      "rotation": 34
    },
    {
      "x": -12,
      "y": 13,
      "z": 20,
      "name": "Rock_Volcanic_Stalactite_Large",
      "rotation": 34
    },
    {
      "x": -12,
      "y": 14,
      "z": 20,
      "name": "Rock_Volcanic_Cracked_Lava"
    },
    {
      "x": -12,
      "y": 15,
      "z": 20,
      "name": "Rock_Volcanic"
    },
    {
      "x": -12,
      "y": 16,
      "z": 20,
      "name": "Rock_Volcanic"
    },
    {
      "x": -12,
      "y": 17,
      "z": 20,
      "name": "Rock_Volcanic"
    },
    {
      "x": -12,
      "y": 18,
      "z": 20,
      "name": "Plant_Moss_Rug_Yellow",
      "support": 15
    },
    {
      "x": -12,
      "y": 14,
      "z": 21,
      "name": "Rock_Volcanic"
    },
    {
      "x": -12,
      "y": 15,
      "z": 21,
      "name": "Rock_Volcanic_Cracked_Lava"
    },
    {
      "x": -12,
      "y": 16,
      "z": 21,
      "name": "Rock_Volcanic"
    },
    {
      "x": -12,
      "y": 17,
      "z": 21,
      "name": "Rock_Volcanic"
    },
    {
      "x": -12,
      "y": 18,
      "z": 21,
      "name": "Plant_Moss_Rug_Yellow",
      "support": 15
    },
    {
      "x": -12,
      "y": 15,
      "z": 22,
      "name": "Rock_Volcanic"
    },
    {
      "x": -12,
      "y": 16,
      "z": 22,
      "name": "Rock_Volcanic"
    },
    {
      "x": -12,
      "y": 17,
      "z": 22,
      "name": "Rock_Volcanic"
    },
    {
      "x": -12,
      "y": 18,
      "z": 22,
      "name": "Plant_Moss_Rug_Yellow",
      "support": 15
    },
    {
      "x": -12,
      "y": 17,
      "z": 23,
      "name": "Plant_Moss_Wall_Yellow",
      "support": 15,
      "rotation": 1
    },
    {
      "x": -12,
      "y": 18,
      "z": 23,
      "name": "Plant_Moss_Wall_Yellow",
      "support": 15,
      "rotation": 1
    },
    {
      "x": -12,
      "y": 19,
      "z": 23,
      "name": "Plant_Moss_Wall_Yellow",
      "support": 15,
      "rotation": 1
    },
    {
      "x": -11,
      "y": 5,
      "z": 9,
      "name": "Rock_Volcanic"
    },
    {
      "x": -11,
      "y": 6,
      "z": 9,
      "name": "Rock_Volcanic_Cracked_Lava"
    },
    {
      "x": -11,
      "y": 7,
      "z": 9,
      "name": "Rock_Volcanic"
    },
    {
      "x": -11,
      "y": 8,
      "z": 9,
      "name": "Rock_Volcanic"
    },
    {
      "x": -11,
      "y": 9,
      "z": 9,
      "name": "Rock_Volcanic"
    },
    {
      "x": -11,
      "y": 8,
      "z": 10,
      "name": "Rock_Volcanic_Cracked_Lava"
    },
    {
      "x": -11,
      "y": 6,
      "z": 11,
      "name": "Rock_Volcanic_Cracked_Lava"
    },
    {
      "x": -11,
      "y": 10,
      "z": 11,
      "name": "Rock_Volcanic"
    },
    {
      "x": -11,
      "y": 11,
      "z": 11,
      "name": "Rock_Volcanic"
    },
    {
      "x": -11,
      "y": 12,
      "z": 11,
      "name": "Rock_Volcanic"
    },
    {
      "x": -11,
      "y": 13,
      "z": 11,
      "name": "Rock_Volcanic"
    },
    {
      "x": -11,
      "y": 8,
      "z": 12,
      "name": "Rock_Volcanic"
    },
    {
      "x": -11,
      "y": 10,
      "z": 12,
      "name": "Rock_Crystal_Yellow_Medium",
      "rotation": 7
    },
    {
      "x": -11,
      "y": 11,
      "z": 12,
      "name": "Rock_Crystal_Yellow_Medium",
      "rotation": 7
    },
    {
      "x": -11,
      "y": 12,
      "z": 12,
      "name": "Rock_Volcanic"
    },
    {
      "x": -11,
      "y": 13,
      "z": 12,
      "name": "Rock_Volcanic"
    },
    {
      "x": -11,
      "y": 14,
      "z": 12,
      "name": "Rock_Volcanic"
    },
    {
      "x": -11,
      "y": 15,
      "z": 12,
      "name": "Rock_Crystal_Yellow_Medium"
    },
    {
      "x": -11,
      "y": 7,
      "z": 13,
      "name": "Rock_Volcanic"
    },
    {
      "x": -11,
      "y": 8,
      "z": 13,
      "name": "Rock_Volcanic"
    },
    {
      "x": -11,
      "y": 9,
      "z": 13,
      "name": "Rock_Volcanic"
    },
    {
      "x": -11,
      "y": 10,
      "z": 13,
      "name": "Rock_Volcanic"
    },
    {
      "x": -11,
      "y": 11,
      "z": 13,
      "name": "Rock_Crystal_Yellow_Medium",
      "rotation": 7
    },
    {
      "x": -11,
      "y": 12,
      "z": 13,
      "name": "Rock_Volcanic_Cracked_Lava"
    },
    {
      "x": -11,
      "y": 13,
      "z": 13,
      "name": "Rock_Volcanic"
    },
    {
      "x": -11,
      "y": 14,
      "z": 13,
      "name": "Rock_Volcanic_Cracked_Lava"
    },
    {
      "x": -11,
      "y": 15,
      "z": 13,
      "name": "Rock_Volcanic"
    },
    {
      "x": -11,
      "y": 7,
      "z": 14,
      "name": "Rock_Volcanic_Cracked_Lava"
    },
    {
      "x": -11,
      "y": 8,
      "z": 14,
      "name": "Rock_Volcanic"
    },
    {
      "x": -11,
      "y": 9,
      "z": 14,
      "name": "Rock_Volcanic"
    },
    {
      "x": -11,
      "y": 10,
      "z": 14,
      "name": "Rock_Volcanic"
    },
    {
      "x": -11,
      "y": 11,
      "z": 14,
      "name": "Rock_Crystal_Yellow_Block",
      "rotation": 5
    },
    {
      "x": -11,
      "y": 12,
      "z": 14,
      "name": "Rock_Volcanic"
    },
    {
      "x": -11,
      "y": 13,
      "z": 14,
      "name": "Rock_Volcanic"
    },
    {
      "x": -11,
      "y": 14,
      "z": 14,
      "name": "Rock_Volcanic"
    },
    {
      "x": -11,
      "y": 15,
      "z": 14,
      "name": "Rock_Volcanic"
    },
    {
      "x": -11,
      "y": 9,
      "z": 15,
      "name": "Rock_Volcanic"
    },
    {
      "x": -11,
      "y": 10,
      "z": 15,
      "name": "Rock_Volcanic"
    },
    {
      "x": -11,
      "y": 11,
      "z": 15,
      "name": "Rock_Volcanic"
    },
    {
      "x": -11,
      "y": 12,
      "z": 15,
      "name": "Rock_Volcanic_Cracked_Lava"
    },
    {
      "x": -11,
      "y": 13,
      "z": 15,
      "name": "Rock_Volcanic"
    },
    {
      "x": -11,
      "y": 14,
      "z": 15,
      "name": "Rock_Volcanic"
    },
    {
      "x": -11,
      "y": 15,
      "z": 15,
      "name": "Ore_Gold_Volcanic"
    },
    {
      "x": -11,
      "y": 9,
      "z": 16,
      "name": "Ore_Adamantite_Magma"
    },
    {
      "x": -11,
      "y": 10,
      "z": 16,
      "name": "Rock_Volcanic_Cracked_Lava"
    },
    {
      "x": -11,
      "y": 11,
      "z": 16,
      "name": "Rock_Volcanic_Cracked_Lava"
    },
    {
      "x": -11,
      "y": 12,
      "z": 16,
      "name": "Rock_Volcanic"
    },
    {
      "x": -11,
      "y": 13,
      "z": 16,
      "name": "Rock_Volcanic"
    },
    {
      "x": -11,
      "y": 14,
      "z": 16,
      "name": "Rock_Volcanic"
    },
    {
      "x": -11,
      "y": 15,
      "z": 16,
      "name": "Ore_Gold_Volcanic"
    },
    {
      "x": -11,
      "y": 16,
      "z": 16,
      "name": "Ore_Gold_Volcanic"
    },
    {
      "x": -11,
      "y": 10,
      "z": 17,
      "name": "Rock_Magma_Cooled"
    },
    {
      "x": -11,
      "y": 11,
      "z": 17,
      "name": "Rock_Volcanic"
    },
    {
      "x": -11,
      "y": 12,
      "z": 17,
      "name": "Rock_Volcanic"
    },
    {
      "x": -11,
      "y": 13,
      "z": 17,
      "name": "Rock_Volcanic"
    },
    {
      "x": -11,
      "y": 14,
      "z": 17,
      "name": "Rock_Volcanic_Cracked_Lava"
    },
    {
      "x": -11,
      "y": 15,
      "z": 17,
      "name": "Rock_Volcanic_Cracked_Lava"
    },
    {
      "x": -11,
      "y": 16,
      "z": 17,
      "name": "Rock_Volcanic"
    },
    {
      "x": -11,
      "y": 10,
      "z": 18,
      "name": "Rock_Magma_Cooled"
    },
    {
      "x": -11,
      "y": 11,
      "z": 18,
      "name": "Rock_Volcanic"
    },
    {
      "x": -11,
      "y": 12,
      "z": 18,
      "name": "Rock_Volcanic"
    },
    {
      "x": -11,
      "y": 13,
      "z": 18,
      "name": "Rock_Volcanic"
    },
    {
      "x": -11,
      "y": 14,
      "z": 18,
      "name": "Rock_Volcanic_Cracked_Lava"
    },
    {
      "x": -11,
      "y": 15,
      "z": 18,
      "name": "Rock_Volcanic_Cracked_Lava"
    },
    {
      "x": -11,
      "y": 16,
      "z": 18,
      "name": "Rock_Volcanic"
    },
    {
      "x": -11,
      "y": 9,
      "z": 19,
      "name": "Rock_Volcanic_Stalactite_Large",
      "filler": 31744,
      "rotation": 34
    },
    {
      "x": -11,
      "y": 10,
      "z": 19,
      "name": "Rock_Volcanic_Stalactite_Large",
      "rotation": 34
    },
    {
      "x": -11,
      "y": 11,
      "z": 19,
      "name": "Rock_Volcanic"
    },
    {
      "x": -11,
      "y": 12,
      "z": 19,
      "name": "Rock_Volcanic"
    },
    {
      "x": -11,
      "y": 13,
      "z": 19,
      "name": "Rock_Volcanic"
    },
    {
      "x": -11,
      "y": 14,
      "z": 19,
      "name": "Rock_Volcanic_Cracked_Lava"
    },
    {
      "x": -11,
      "y": 15,
      "z": 19,
      "name": "Rock_Volcanic"
    },
    {
      "x": -11,
      "y": 16,
      "z": 19,
      "name": "Rock_Volcanic"
    },
    {
      "x": -11,
      "y": 17,
      "z": 19,
      "name": "Plant_Moss_Rug_Yellow",
      "support": 15
    },
    {
      "x": -11,
      "y": 12,
      "z": 20,
      "name": "Rock_Volcanic_Cracked_Lava"
    },
    {
      "x": -11,
      "y": 13,
      "z": 20,
      "name": "Rock_Volcanic"
    },
    {
      "x": -11,
      "y": 14,
      "z": 20,
      "name": "Rock_Volcanic"
    },
    {
      "x": -11,
      "y": 15,
      "z": 20,
      "name": "Rock_Volcanic"
    },
    {
      "x": -11,
      "y": 16,
      "z": 20,
      "name": "Plant_Moss_Rug_Yellow",
      "support": 15
    },
    {
      "x": -11,
      "y": 17,
      "z": 20,
      "name": "Plant_Moss_Wall_Yellow",
      "support": 15,
      "rotation": 1
    },
    {
      "x": -11,
      "y": 14,
      "z": 21,
      "name": "Rock_Volcanic"
    },
    {
      "x": -11,
      "y": 15,
      "z": 21,
      "name": "Rock_Volcanic_Cracked_Lava"
    },
    {
      "x": -11,
      "y": 16,
      "z": 21,
      "name": "Rock_Volcanic"
    },
    {
      "x": -11,
      "y": 17,
      "z": 21,
      "name": "Rock_Volcanic"
    },
    {
      "x": -11,
      "y": 18,
      "z": 21,
      "name": "Plant_Moss_Rug_Yellow",
      "support": 15
    },
    {
      "x": -11,
      "y": 16,
      "z": 22,
      "name": "Plant_Moss_Wall_Yellow",
      "support": 15,
      "rotation": 1
    },
    {
      "x": -11,
      "y": 17,
      "z": 22,
      "name": "Plant_Moss_Wall_Yellow",
      "support": 15,
      "rotation": 1
    },
    {
      "x": -10,
      "y": 4,
      "z": 8,
      "name": "Rock_Volcanic"
    },
    {
      "x": -10,
      "y": 5,
      "z": 8,
      "name": "Rock_Volcanic_Cracked_Lava"
    },
    {
      "x": -10,
      "y": 6,
      "z": 8,
      "name": "Rock_Volcanic"
    },
    {
      "x": -10,
      "y": 7,
      "z": 8,
      "name": "Rock_Volcanic"
    },
    {
      "x": -10,
      "y": 8,
      "z": 8,
      "name": "Rock_Volcanic"
    },
    {
      "x": -10,
      "y": 9,
      "z": 8,
      "name": "Rock_Volcanic"
    },
    {
      "x": -10,
      "y": 11,
      "z": 8,
      "name": "Rock_Volcanic"
    },
    {
      "x": -10,
      "y": 5,
      "z": 9,
      "name": "Rock_Volcanic"
    },
    {
      "x": -10,
      "y": 6,
      "z": 9,
      "name": "Rock_Volcanic_Cracked_Lava"
    },
    {
      "x": -10,
      "y": 7,
      "z": 9,
      "name": "Rock_Volcanic"
    },
    {
      "x": -10,
      "y": 8,
      "z": 9,
      "name": "Rock_Volcanic"
    },
    {
      "x": -10,
      "y": 9,
      "z": 9,
      "name": "Rock_Volcanic"
    },
    {
      "x": -10,
      "y": 5,
      "z": 10,
      "name": "Rock_Volcanic_Cracked_Lava"
    },
    {
      "x": -10,
      "y": 6,
      "z": 10,
      "name": "Rock_Volcanic_Cracked_Lava"
    },
    {
      "x": -10,
      "y": 7,
      "z": 10,
      "name": "Rock_Volcanic"
    },
    {
      "x": -10,
      "y": 8,
      "z": 10,
      "name": "Rock_Volcanic_Cracked_Lava"
    },
    {
      "x": -10,
      "y": 9,
      "z": 10,
      "name": "Rock_Volcanic"
    },
    {
      "x": -10,
      "y": 10,
      "z": 10,
      "name": "Rock_Volcanic"
    },
    {
      "x": -10,
      "y": 11,
      "z": 10,
      "name": "Rock_Volcanic_Cracked_Lava"
    },
    {
      "x": -10,
      "y": 12,
      "z": 10,
      "name": "Rock_Volcanic"
    },
    {
      "x": -10,
      "y": 5,
      "z": 11,
      "name": "Rock_Volcanic_Cracked_Lava"
    },
    {
      "x": -10,
      "y": 6,
      "z": 11,
      "name": "Rock_Volcanic"
    },
    {
      "x": -10,
      "y": 7,
      "z": 11,
      "name": "Rock_Volcanic"
    },
    {
      "x": -10,
      "y": 8,
      "z": 11,
      "name": "Rock_Volcanic"
    },
    {
      "x": -10,
      "y": 9,
      "z": 11,
      "name": "Rock_Volcanic_Cracked_Lava"
    },
    {
      "x": -10,
      "y": 10,
      "z": 11,
      "name": "Rock_Volcanic_Cracked_Lava"
    },
    {
      "x": -10,
      "y": 11,
      "z": 11,
      "name": "Rock_Volcanic"
    },
    {
      "x": -10,
      "y": 12,
      "z": 11,
      "name": "Rock_Volcanic_Cracked_Lava"
    },
    {
      "x": -10,
      "y": 6,
      "z": 12,
      "name": "Rock_Volcanic"
    },
    {
      "x": -10,
      "y": 7,
      "z": 12,
      "name": "Rock_Magma_Cooled"
    },
    {
      "x": -10,
      "y": 8,
      "z": 12,
      "name": "Rock_Volcanic"
    },
    {
      "x": -10,
      "y": 9,
      "z": 12,
      "name": "Rock_Crystal_Yellow_Large",
      "rotation": 7
    },
    {
      "x": -10,
      "y": 10,
      "z": 12,
      "name": "Rock_Volcanic_Cracked_Lava"
    },
    {
      "x": -10,
      "y": 11,
      "z": 12,
      "name": "Rock_Volcanic"
    },
    {
      "x": -10,
      "y": 12,
      "z": 12,
      "name": "Rock_Volcanic"
    },
    {
      "x": -10,
      "y": 13,
      "z": 12,
      "name": "Rock_Volcanic"
    },
    {
      "x": -10,
      "y": 8,
      "z": 13,
      "name": "Rock_Volcanic"
    },
    {
      "x": -10,
      "y": 9,
      "z": 13,
      "name": "Rock_Crystal_Yellow_Large",
      "rotation": 7
    },
    {
      "x": -10,
      "y": 10,
      "z": 13,
      "name": "Rock_Crystal_Yellow_Block",
      "rotation": 5
    },
    {
      "x": -10,
      "y": 11,
      "z": 13,
      "name": "Rock_Crystal_Yellow_Block",
      "rotation": 5
    },
    {
      "x": -10,
      "y": 12,
      "z": 13,
      "name": "Rock_Volcanic"
    },
    {
      "x": -10,
      "y": 13,
      "z": 13,
      "name": "Rock_Volcanic"
    },
    {
      "x": -10,
      "y": 14,
      "z": 13,
      "name": "Rock_Volcanic"
    },
    {
      "x": -10,
      "y": 9,
      "z": 14,
      "name": "Rock_Magma_Cooled"
    },
    {
      "x": -10,
      "y": 10,
      "z": 14,
      "name": "Rock_Volcanic"
    },
    {
      "x": -10,
      "y": 11,
      "z": 14,
      "name": "Rock_Volcanic"
    },
    {
      "x": -10,
      "y": 12,
      "z": 14,
      "name": "Rock_Volcanic_Cracked_Lava"
    },
    {
      "x": -10,
      "y": 13,
      "z": 14,
      "name": "Rock_Volcanic"
    },
    {
      "x": -10,
      "y": 14,
      "z": 14,
      "name": "Rock_Volcanic"
    },
    {
      "x": -10,
      "y": 15,
      "z": 14,
      "name": "Ore_Gold_Volcanic"
    },
    {
      "x": -10,
      "y": 9,
      "z": 15,
      "name": "Rock_Magma_Cooled"
    },
    {
      "x": -10,
      "y": 10,
      "z": 15,
      "name": "Rock_Volcanic"
    },
    {
      "x": -10,
      "y": 11,
      "z": 15,
      "name": "Rock_Volcanic"
    },
    {
      "x": -10,
      "y": 12,
      "z": 15,
      "name": "Rock_Volcanic_Cracked_Lava"
    },
    {
      "x": -10,
      "y": 13,
      "z": 15,
      "name": "Rock_Volcanic"
    },
    {
      "x": -10,
      "y": 14,
      "z": 15,
      "name": "Rock_Volcanic"
    },
    {
      "x": -10,
      "y": 15,
      "z": 15,
      "name": "Ore_Gold_Volcanic"
    },
    {
      "x": -10,
      "y": 9,
      "z": 16,
      "name": "Rock_Magma_Cooled"
    },
    {
      "x": -10,
      "y": 10,
      "z": 16,
      "name": "Rock_Volcanic"
    },
    {
      "x": -10,
      "y": 11,
      "z": 16,
      "name": "Rock_Volcanic"
    },
    {
      "x": -10,
      "y": 12,
      "z": 16,
      "name": "Rock_Volcanic"
    },
    {
      "x": -10,
      "y": 13,
      "z": 16,
      "name": "Rock_Volcanic"
    },
    {
      "x": -10,
      "y": 14,
      "z": 16,
      "name": "Rock_Volcanic"
    },
    {
      "x": -10,
      "y": 15,
      "z": 16,
      "name": "Rock_Volcanic"
    },
    {
      "x": -10,
      "y": 10,
      "z": 17,
      "name": "Rock_Volcanic"
    },
    {
      "x": -10,
      "y": 11,
      "z": 17,
      "name": "Rock_Volcanic"
    },
    {
      "x": -10,
      "y": 12,
      "z": 17,
      "name": "Rock_Volcanic"
    },
    {
      "x": -10,
      "y": 13,
      "z": 17,
      "name": "Rock_Volcanic_Cracked_Lava"
    },
    {
      "x": -10,
      "y": 14,
      "z": 17,
      "name": "Rock_Volcanic"
    },
    {
      "x": -10,
      "y": 15,
      "z": 17,
      "name": "Rock_Volcanic_Cracked_Lava"
    },
    {
      "x": -10,
      "y": 16,
      "z": 17,
      "name": "Rock_Volcanic"
    },
    {
      "x": -10,
      "y": 10,
      "z": 18,
      "name": "Rock_Volcanic"
    },
    {
      "x": -10,
      "y": 11,
      "z": 18,
      "name": "Rock_Volcanic"
    },
    {
      "x": -10,
      "y": 12,
      "z": 18,
      "name": "Rock_Volcanic"
    },
    {
      "x": -10,
      "y": 13,
      "z": 18,
      "name": "Rock_Volcanic"
    },
    {
      "x": -10,
      "y": 14,
      "z": 18,
      "name": "Rock_Volcanic"
    },
    {
      "x": -10,
      "y": 15,
      "z": 18,
      "name": "Rock_Volcanic"
    },
    {
      "x": -10,
      "y": 16,
      "z": 18,
      "name": "Plant_Moss_Rug_Yellow",
      "support": 15
    },
    {
      "x": -10,
      "y": 12,
      "z": 19,
      "name": "Rock_Volcanic"
    },
    {
      "x": -10,
      "y": 13,
      "z": 19,
      "name": "Rock_Volcanic"
    },
    {
      "x": -10,
      "y": 14,
      "z": 19,
      "name": "Rock_Volcanic"
    },
    {
      "x": -10,
      "y": 15,
      "z": 19,
      "name": "Plant_Moss_Rug_Yellow",
      "support": 15
    },
    {
      "x": -10,
      "y": 12,
      "z": 20,
      "name": "Rock_Volcanic"
    },
    {
      "x": -10,
      "y": 13,
      "z": 20,
      "name": "Rock_Volcanic"
    },
    {
      "x": -10,
      "y": 14,
      "z": 20,
      "name": "Rock_Volcanic"
    },
    {
      "x": -10,
      "y": 15,
      "z": 20,
      "name": "Plant_Moss_Rug_Yellow",
      "support": 15
    },
    {
      "x": -10,
      "y": 17,
      "z": 21,
      "name": "Plant_Moss_Wall_Yellow",
      "support": 15,
      "rotation": 1
    },
    {
      "x": -9,
      "y": 9,
      "z": 5,
      "name": "Rock_Volcanic"
    },
    {
      "x": -9,
      "y": 10,
      "z": 5,
      "name": "Rock_Volcanic"
    },
    {
      "x": -9,
      "y": 3,
      "z": 7,
      "name": "Rock_Volcanic"
    },
    {
      "x": -9,
      "y": 4,
      "z": 7,
      "name": "Rock_Volcanic"
    },
    {
      "x": -9,
      "y": 5,
      "z": 7,
      "name": "Rock_Volcanic_Cracked_Lava"
    },
    {
      "x": -9,
      "y": 6,
      "z": 7,
      "name": "Rock_Volcanic_Cracked_Lava"
    },
    {
      "x": -9,
      "y": 7,
      "z": 7,
      "name": "Rock_Volcanic_Cracked_Lava"
    },
    {
      "x": -9,
      "y": 8,
      "z": 7,
      "name": "Rock_Volcanic"
    },
    {
      "x": -9,
      "y": 9,
      "z": 7,
      "name": "Rock_Volcanic_Cracked_Lava"
    },
    {
      "x": -9,
      "y": 10,
      "z": 7,
      "name": "Rock_Volcanic"
    },
    {
      "x": -9,
      "y": 11,
      "z": 7,
      "name": "Rock_Volcanic"
    },
    {
      "x": -9,
      "y": 3,
      "z": 8,
      "name": "Rock_Volcanic"
    },
    {
      "x": -9,
      "y": 4,
      "z": 8,
      "name": "Rock_Volcanic_Cracked_Lava"
    },
    {
      "x": -9,
      "y": 5,
      "z": 8,
      "name": "Rock_Volcanic"
    },
    {
      "x": -9,
      "y": 6,
      "z": 8,
      "name": "Rock_Volcanic"
    },
    {
      "x": -9,
      "y": 7,
      "z": 8,
      "name": "Rock_Volcanic"
    },
    {
      "x": -9,
      "y": 8,
      "z": 8,
      "name": "Rock_Volcanic"
    },
    {
      "x": -9,
      "y": 9,
      "z": 8,
      "name": "Rock_Volcanic"
    },
    {
      "x": -9,
      "y": 10,
      "z": 8,
      "name": "Rock_Volcanic"
    },
    {
      "x": -9,
      "y": 11,
      "z": 8,
      "name": "Rock_Volcanic"
    },
    {
      "x": -9,
      "y": 12,
      "z": 8,
      "name": "Rock_Volcanic"
    },
    {
      "x": -9,
      "y": 4,
      "z": 9,
      "name": "Rock_Volcanic_Cracked_Lava"
    },
    {
      "x": -9,
      "y": 5,
      "z": 9,
      "name": "Rock_Volcanic"
    },
    {
      "x": -9,
      "y": 6,
      "z": 9,
      "name": "Rock_Volcanic_Cracked_Lava"
    },
    {
      "x": -9,
      "y": 7,
      "z": 9,
      "name": "Rock_Volcanic"
    },
    {
      "x": -9,
      "y": 8,
      "z": 9,
      "name": "Rock_Volcanic"
    },
    {
      "x": -9,
      "y": 9,
      "z": 9,
      "name": "Rock_Volcanic"
    },
    {
      "x": -9,
      "y": 10,
      "z": 9,
      "name": "Rock_Volcanic"
    },
    {
      "x": -9,
      "y": 11,
      "z": 9,
      "name": "Rock_Volcanic_Cracked_Lava"
    },
    {
      "x": -9,
      "y": 5,
      "z": 10,
      "name": "Rock_Volcanic_Cracked_Lava"
    },
    {
      "x": -9,
      "y": 6,
      "z": 10,
      "name": "Rock_Volcanic_Cracked_Lava"
    },
    {
      "x": -9,
      "y": 7,
      "z": 10,
      "name": "Rock_Volcanic"
    },
    {
      "x": -9,
      "y": 8,
      "z": 10,
      "name": "Rock_Volcanic"
    },
    {
      "x": -9,
      "y": 9,
      "z": 10,
      "name": "Rock_Volcanic_Cracked_Lava"
    },
    {
      "x": -9,
      "y": 10,
      "z": 10,
      "name": "Rock_Volcanic_Cracked_Lava"
    },
    {
      "x": -9,
      "y": 11,
      "z": 10,
      "name": "Rock_Volcanic"
    },
    {
      "x": -9,
      "y": 12,
      "z": 10,
      "name": "Rock_Volcanic"
    },
    {
      "x": -9,
      "y": 5,
      "z": 11,
      "name": "Rock_Volcanic_Cracked_Lava"
    },
    {
      "x": -9,
      "y": 6,
      "z": 11,
      "name": "Rock_Volcanic"
    },
    {
      "x": -9,
      "y": 7,
      "z": 11,
      "name": "Rock_Volcanic"
    },
    {
      "x": -9,
      "y": 8,
      "z": 11,
      "name": "Rock_Volcanic"
    },
    {
      "x": -9,
      "y": 9,
      "z": 11,
      "name": "Rock_Volcanic_Cracked_Lava"
    },
    {
      "x": -9,
      "y": 10,
      "z": 11,
      "name": "Rock_Volcanic_Cracked_Lava"
    },
    {
      "x": -9,
      "y": 11,
      "z": 11,
      "name": "Rock_Volcanic"
    },
    {
      "x": -9,
      "y": 12,
      "z": 11,
      "name": "Rock_Volcanic_Cracked_Lava"
    },
    {
      "x": -9,
      "y": 6,
      "z": 12,
      "name": "Rock_Magma_Cooled"
    },
    {
      "x": -9,
      "y": 7,
      "z": 12,
      "name": "Ore_Adamantite_Magma"
    },
    {
      "x": -9,
      "y": 8,
      "z": 12,
      "name": "Rock_Volcanic_Cracked_Lava"
    },
    {
      "x": -9,
      "y": 9,
      "z": 12,
      "name": "Rock_Crystal_Yellow_Block",
      "rotation": 5
    },
    {
      "x": -9,
      "y": 10,
      "z": 12,
      "name": "Rock_Volcanic_Cracked_Lava"
    },
    {
      "x": -9,
      "y": 11,
      "z": 12,
      "name": "Rock_Volcanic"
    },
    {
      "x": -9,
      "y": 12,
      "z": 12,
      "name": "Rock_Volcanic"
    },
    {
      "x": -9,
      "y": 13,
      "z": 12,
      "name": "Rock_Volcanic_Cracked_Lava"
    },
    {
      "x": -9,
      "y": 14,
      "z": 12,
      "name": "Rock_Crystal_Yellow_Medium"
    },
    {
      "x": -9,
      "y": 8,
      "z": 13,
      "name": "Rock_Magma_Cooled"
    },
    {
      "x": -9,
      "y": 9,
      "z": 13,
      "name": "Rock_Volcanic"
    },
    {
      "x": -9,
      "y": 10,
      "z": 13,
      "name": "Rock_Volcanic"
    },
    {
      "x": -9,
      "y": 11,
      "z": 13,
      "name": "Rock_Volcanic"
    },
    {
      "x": -9,
      "y": 12,
      "z": 13,
      "name": "Rock_Volcanic"
    },
    {
      "x": -9,
      "y": 13,
      "z": 13,
      "name": "Rock_Volcanic_Cracked_Lava"
    },
    {
      "x": -9,
      "y": 8,
      "z": 14,
      "name": "Rock_Magma_Cooled"
    },
    {
      "x": -9,
      "y": 9,
      "z": 14,
      "name": "Rock_Crystal_Yellow_Block",
      "rotation": 5
    },
    {
      "x": -9,
      "y": 10,
      "z": 14,
      "name": "Rock_Volcanic_Cracked_Lava"
    },
    {
      "x": -9,
      "y": 11,
      "z": 14,
      "name": "Rock_Volcanic"
    },
    {
      "x": -9,
      "y": 12,
      "z": 14,
      "name": "Rock_Volcanic"
    },
    {
      "x": -9,
      "y": 13,
      "z": 14,
      "name": "Rock_Volcanic"
    },
    {
      "x": -9,
      "y": 14,
      "z": 14,
      "name": "Rock_Volcanic_Cracked_Lava"
    },
    {
      "x": -9,
      "y": 9,
      "z": 15,
      "name": "Rock_Magma_Cooled"
    },
    {
      "x": -9,
      "y": 10,
      "z": 15,
      "name": "Rock_Volcanic"
    },
    {
      "x": -9,
      "y": 11,
      "z": 15,
      "name": "Rock_Volcanic"
    },
    {
      "x": -9,
      "y": 12,
      "z": 15,
      "name": "Rock_Volcanic"
    },
    {
      "x": -9,
      "y": 13,
      "z": 15,
      "name": "Rock_Volcanic"
    },
    {
      "x": -9,
      "y": 14,
      "z": 15,
      "name": "Rock_Volcanic"
    },
    {
      "x": -9,
      "y": 15,
      "z": 15,
      "name": "Rock_Volcanic"
    },
    {
      "x": -9,
      "y": 9,
      "z": 16,
      "name": "Rock_Volcanic"
    },
    {
      "x": -9,
      "y": 10,
      "z": 16,
      "name": "Rock_Volcanic"
    },
    {
      "x": -9,
      "y": 11,
      "z": 16,
      "name": "Rock_Volcanic"
    },
    {
      "x": -9,
      "y": 12,
      "z": 16,
      "name": "Rock_Volcanic_Cracked_Lava"
    },
    {
      "x": -9,
      "y": 13,
      "z": 16,
      "name": "Rock_Volcanic"
    },
    {
      "x": -9,
      "y": 14,
      "z": 16,
      "name": "Rock_Volcanic"
    },
    {
      "x": -9,
      "y": 15,
      "z": 16,
      "name": "Rock_Volcanic"
    },
    {
      "x": -9,
      "y": 9,
      "z": 17,
      "name": "Rock_Volcanic"
    },
    {
      "x": -9,
      "y": 10,
      "z": 17,
      "name": "Rock_Volcanic"
    },
    {
      "x": -9,
      "y": 11,
      "z": 17,
      "name": "Rock_Volcanic"
    },
    {
      "x": -9,
      "y": 12,
      "z": 17,
      "name": "Rock_Volcanic_Cracked_Lava"
    },
    {
      "x": -9,
      "y": 13,
      "z": 17,
      "name": "Rock_Volcanic"
    },
    {
      "x": -9,
      "y": 14,
      "z": 17,
      "name": "Rock_Volcanic"
    },
    {
      "x": -9,
      "y": 15,
      "z": 17,
      "name": "Rock_Volcanic"
    },
    {
      "x": -9,
      "y": 10,
      "z": 18,
      "name": "Rock_Volcanic"
    },
    {
      "x": -9,
      "y": 11,
      "z": 18,
      "name": "Rock_Volcanic"
    },
    {
      "x": -9,
      "y": 12,
      "z": 18,
      "name": "Rock_Volcanic_Cracked_Lava"
    },
    {
      "x": -9,
      "y": 13,
      "z": 18,
      "name": "Rock_Volcanic"
    },
    {
      "x": -9,
      "y": 14,
      "z": 18,
      "name": "Rock_Volcanic"
    },
    {
      "x": -9,
      "y": 15,
      "z": 18,
      "name": "Rock_Volcanic"
    },
    {
      "x": -9,
      "y": 16,
      "z": 18,
      "name": "Rock_Volcanic"
    },
    {
      "x": -8,
      "y": 5,
      "z": 4,
      "name": "Rock_Volcanic"
    },
    {
      "x": -8,
      "y": 6,
      "z": 4,
      "name": "Rock_Volcanic"
    },
    {
      "x": -8,
      "y": 7,
      "z": 4,
      "name": "Rock_Volcanic"
    },
    {
      "x": -8,
      "y": 8,
      "z": 4,
      "name": "Rock_Volcanic_Cracked_Lava"
    },
    {
      "x": -8,
      "y": 9,
      "z": 4,
      "name": "Rock_Volcanic"
    },
    {
      "x": -8,
      "y": 10,
      "z": 4,
      "name": "Rock_Volcanic_Cracked_Lava"
    },
    {
      "x": -8,
      "y": 9,
      "z": 5,
      "name": "Rock_Volcanic"
    },
    {
      "x": -8,
      "y": 10,
      "z": 5,
      "name": "Rock_Volcanic"
    },
    {
      "x": -8,
      "y": 3,
      "z": 6,
      "name": "Rock_Volcanic"
    },
    {
      "x": -8,
      "y": 4,
      "z": 6,
      "name": "Rock_Volcanic"
    },
    {
      "x": -8,
      "y": 5,
      "z": 6,
      "name": "Rock_Volcanic"
    },
    {
      "x": -8,
      "y": 6,
      "z": 6,
      "name": "Rock_Volcanic_Cracked_Lava"
    },
    {
      "x": -8,
      "y": 7,
      "z": 6,
      "name": "Rock_Volcanic"
    },
    {
      "x": -8,
      "y": 8,
      "z": 6,
      "name": "Rock_Volcanic"
    },
    {
      "x": -8,
      "y": 9,
      "z": 6,
      "name": "Rock_Volcanic"
    },
    {
      "x": -8,
      "y": 10,
      "z": 6,
      "name": "Rock_Volcanic"
    },
    {
      "x": -8,
      "y": 3,
      "z": 7,
      "name": "Rock_Volcanic"
    },
    {
      "x": -8,
      "y": 4,
      "z": 7,
      "name": "Rock_Volcanic"
    },
    {
      "x": -8,
      "y": 5,
      "z": 7,
      "name": "Rock_Volcanic_Cracked_Lava"
    },
    {
      "x": -8,
      "y": 6,
      "z": 7,
      "name": "Rock_Volcanic"
    },
    {
      "x": -8,
      "y": 7,
      "z": 7,
      "name": "Rock_Volcanic"
    },
    {
      "x": -8,
      "y": 8,
      "z": 7,
      "name": "Rock_Volcanic"
    },
    {
      "x": -8,
      "y": 9,
      "z": 7,
      "name": "Rock_Volcanic"
    },
    {
      "x": -8,
      "y": 10,
      "z": 7,
      "name": "Rock_Volcanic"
    },
    {
      "x": -8,
      "y": 11,
      "z": 7,
      "name": "Rock_Volcanic"
    },
    {
      "x": -8,
      "y": 3,
      "z": 8,
      "name": "Rock_Volcanic"
    },
    {
      "x": -8,
      "y": 4,
      "z": 8,
      "name": "Rock_Volcanic_Cracked_Lava"
    },
    {
      "x": -8,
      "y": 5,
      "z": 8,
      "name": "Rock_Volcanic"
    },
    {
      "x": -8,
      "y": 6,
      "z": 8,
      "name": "Rock_Volcanic"
    },
    {
      "x": -8,
      "y": 7,
      "z": 8,
      "name": "Rock_Volcanic"
    },
    {
      "x": -8,
      "y": 8,
      "z": 8,
      "name": "Rock_Volcanic"
    },
    {
      "x": -8,
      "y": 9,
      "z": 8,
      "name": "Rock_Volcanic"
    },
    {
      "x": -8,
      "y": 10,
      "z": 8,
      "name": "Rock_Volcanic"
    },
    {
      "x": -8,
      "y": 11,
      "z": 8,
      "name": "Rock_Volcanic"
    },
    {
      "x": -8,
      "y": 12,
      "z": 8,
      "name": "Rock_Volcanic"
    },
    {
      "x": -8,
      "y": 4,
      "z": 9,
      "name": "Rock_Volcanic"
    },
    {
      "x": -8,
      "y": 5,
      "z": 9,
      "name": "Ore_Gold_Volcanic"
    },
    {
      "x": -8,
      "y": 6,
      "z": 9,
      "name": "Rock_Volcanic"
    },
    {
      "x": -8,
      "y": 7,
      "z": 9,
      "name": "Rock_Volcanic"
    },
    {
      "x": -8,
      "y": 8,
      "z": 9,
      "name": "Rock_Volcanic"
    },
    {
      "x": -8,
      "y": 9,
      "z": 9,
      "name": "Rock_Volcanic"
    },
    {
      "x": -8,
      "y": 10,
      "z": 9,
      "name": "Rock_Volcanic"
    },
    {
      "x": -8,
      "y": 11,
      "z": 9,
      "name": "Rock_Volcanic"
    },
    {
      "x": -8,
      "y": 4,
      "z": 10,
      "name": "Rock_Volcanic"
    },
    {
      "x": -8,
      "y": 5,
      "z": 10,
      "name": "Rock_Volcanic"
    },
    {
      "x": -8,
      "y": 6,
      "z": 10,
      "name": "Rock_Volcanic"
    },
    {
      "x": -8,
      "y": 7,
      "z": 10,
      "name": "Rock_Volcanic"
    },
    {
      "x": -8,
      "y": 8,
      "z": 10,
      "name": "Rock_Volcanic_Cracked_Lava"
    },
    {
      "x": -8,
      "y": 9,
      "z": 10,
      "name": "Rock_Volcanic_Cracked_Lava"
    },
    {
      "x": -8,
      "y": 10,
      "z": 10,
      "name": "Rock_Volcanic"
    },
    {
      "x": -8,
      "y": 11,
      "z": 10,
      "name": "Rock_Volcanic"
    },
    {
      "x": -8,
      "y": 12,
      "z": 10,
      "name": "Rock_Volcanic_Cracked_Lava"
    },
    {
      "x": -8,
      "y": 5,
      "z": 11,
      "name": "Rock_Volcanic_Cracked_Lava"
    },
    {
      "x": -8,
      "y": 6,
      "z": 11,
      "name": "Rock_Volcanic"
    },
    {
      "x": -8,
      "y": 7,
      "z": 11,
      "name": "Rock_Volcanic"
    },
    {
      "x": -8,
      "y": 8,
      "z": 11,
      "name": "Rock_Volcanic"
    },
    {
      "x": -8,
      "y": 9,
      "z": 11,
      "name": "Rock_Volcanic"
    },
    {
      "x": -8,
      "y": 10,
      "z": 11,
      "name": "Rock_Volcanic"
    },
    {
      "x": -8,
      "y": 11,
      "z": 11,
      "name": "Rock_Volcanic"
    },
    {
      "x": -8,
      "y": 12,
      "z": 11,
      "name": "Rock_Volcanic"
    },
    {
      "x": -8,
      "y": 5,
      "z": 12,
      "name": "Rock_Magma_Cooled"
    },
    {
      "x": -8,
      "y": 6,
      "z": 12,
      "name": "Ore_Adamantite_Magma"
    },
    {
      "x": -8,
      "y": 7,
      "z": 12,
      "name": "Ore_Adamantite_Magma"
    },
    {
      "x": -8,
      "y": 8,
      "z": 12,
      "name": "Rock_Volcanic"
    },
    {
      "x": -8,
      "y": 9,
      "z": 12,
      "name": "Rock_Volcanic_Cracked_Lava"
    },
    {
      "x": -8,
      "y": 10,
      "z": 12,
      "name": "Rock_Volcanic"
    },
    {
      "x": -8,
      "y": 11,
      "z": 12,
      "name": "Rock_Volcanic"
    },
    {
      "x": -8,
      "y": 12,
      "z": 12,
      "name": "Rock_Volcanic"
    },
    {
      "x": -8,
      "y": 8,
      "z": 13,
      "name": "Ore_Adamantite_Magma"
    },
    {
      "x": -8,
      "y": 9,
      "z": 13,
      "name": "Rock_Volcanic_Cracked_Lava"
    },
    {
      "x": -8,
      "y": 10,
      "z": 13,
      "name": "Rock_Volcanic"
    },
    {
      "x": -8,
      "y": 11,
      "z": 13,
      "name": "Rock_Volcanic_Cracked_Lava"
    },
    {
      "x": -8,
      "y": 12,
      "z": 13,
      "name": "Rock_Volcanic"
    },
    {
      "x": -8,
      "y": 13,
      "z": 13,
      "name": "Rock_Volcanic"
    },
    {
      "x": -8,
      "y": 8,
      "z": 14,
      "name": "Rock_Magma_Cooled"
    },
    {
      "x": -8,
      "y": 9,
      "z": 14,
      "name": "Rock_Volcanic_Cracked_Lava"
    },
    {
      "x": -8,
      "y": 10,
      "z": 14,
      "name": "Rock_Volcanic"
    },
    {
      "x": -8,
      "y": 11,
      "z": 14,
      "name": "Rock_Volcanic_Cracked_Lava"
    },
    {
      "x": -8,
      "y": 12,
      "z": 14,
      "name": "Rock_Volcanic"
    },
    {
      "x": -8,
      "y": 13,
      "z": 14,
      "name": "Rock_Volcanic"
    },
    {
      "x": -8,
      "y": 9,
      "z": 15,
      "name": "Ore_Gold_Volcanic"
    },
    {
      "x": -8,
      "y": 10,
      "z": 15,
      "name": "Ore_Gold_Volcanic"
    },
    {
      "x": -8,
      "y": 11,
      "z": 15,
      "name": "Ore_Gold_Volcanic"
    },
    {
      "x": -8,
      "y": 12,
      "z": 15,
      "name": "Ore_Gold_Volcanic"
    },
    {
      "x": -8,
      "y": 13,
      "z": 15,
      "name": "Ore_Gold_Volcanic"
    },
    {
      "x": -8,
      "y": 14,
      "z": 15,
      "name": "Ore_Gold_Volcanic"
    },
    {
      "x": -8,
      "y": 15,
      "z": 15,
      "name": "Ore_Gold_Volcanic"
    },
    {
      "x": -8,
      "y": 9,
      "z": 16,
      "name": "Ore_Gold_Volcanic"
    },
    {
      "x": -8,
      "y": 10,
      "z": 16,
      "name": "Rock_Volcanic_Cracked_Lava"
    },
    {
      "x": -8,
      "y": 11,
      "z": 16,
      "name": "Ore_Gold_Volcanic"
    },
    {
      "x": -8,
      "y": 12,
      "z": 16,
      "name": "Ore_Gold_Volcanic"
    },
    {
      "x": -8,
      "y": 13,
      "z": 16,
      "name": "Ore_Gold_Volcanic"
    },
    {
      "x": -8,
      "y": 14,
      "z": 16,
      "name": "Ore_Gold_Volcanic"
    },
    {
      "x": -8,
      "y": 15,
      "z": 16,
      "name": "Ore_Gold_Volcanic"
    },
    {
      "x": -8,
      "y": 9,
      "z": 17,
      "name": "Rock_Volcanic"
    },
    {
      "x": -8,
      "y": 10,
      "z": 17,
      "name": "Rock_Volcanic"
    },
    {
      "x": -8,
      "y": 11,
      "z": 17,
      "name": "Rock_Volcanic"
    },
    {
      "x": -8,
      "y": 12,
      "z": 17,
      "name": "Rock_Volcanic"
    },
    {
      "x": -8,
      "y": 13,
      "z": 17,
      "name": "Rock_Volcanic"
    },
    {
      "x": -8,
      "y": 14,
      "z": 17,
      "name": "Rock_Volcanic"
    },
    {
      "x": -8,
      "y": 15,
      "z": 17,
      "name": "Rock_Volcanic"
    },
    {
      "x": -7,
      "y": -2,
      "z": 1,
      "name": "Rock_Volcanic_Cracked_Lava"
    },
    {
      "x": -7,
      "y": -1,
      "z": 1,
      "name": "Rock_Volcanic"
    },
    {
      "x": -7,
      "y": 0,
      "z": 1,
      "name": "Rock_Volcanic"
    },
    {
      "x": -7,
      "y": 1,
      "z": 1,
      "name": "Rock_Volcanic"
    },
    {
      "x": -7,
      "y": 2,
      "z": 1,
      "name": "Rock_Volcanic"
    },
    {
      "x": -7,
      "y": 5,
      "z": 1,
      "name": "Rock_Volcanic"
    },
    {
      "x": -7,
      "y": 6,
      "z": 1,
      "name": "Rock_Volcanic"
    },
    {
      "x": -7,
      "y": 0,
      "z": 2,
      "name": "Rock_Volcanic"
    },
    {
      "x": -7,
      "y": 1,
      "z": 2,
      "name": "Rock_Volcanic"
    },
    {
      "x": -7,
      "y": -1,
      "z": 3,
      "name": "Rock_Volcanic"
    },
    {
      "x": -7,
      "y": 0,
      "z": 3,
      "name": "Rock_Volcanic"
    },
    {
      "x": -7,
      "y": 1,
      "z": 3,
      "name": "Rock_Volcanic_Cracked_Lava"
    },
    {
      "x": -7,
      "y": 2,
      "z": 3,
      "name": "Rock_Volcanic_Cracked_Lava"
    },
    {
      "x": -7,
      "y": 3,
      "z": 3,
      "name": "Rock_Volcanic_Cracked_Lava"
    },
    {
      "x": -7,
      "y": 4,
      "z": 3,
      "name": "Rock_Volcanic_Cracked_Lava"
    },
    {
      "x": -7,
      "y": 5,
      "z": 3,
      "name": "Rock_Volcanic_Cracked_Lava"
    },
    {
      "x": -7,
      "y": 6,
      "z": 3,
      "name": "Rock_Volcanic"
    },
    {
      "x": -7,
      "y": 7,
      "z": 3,
      "name": "Rock_Volcanic"
    },
    {
      "x": -7,
      "y": 8,
      "z": 3,
      "name": "Rock_Volcanic"
    },
    {
      "x": -7,
      "y": 0,
      "z": 4,
      "name": "Rock_Volcanic"
    },
    {
      "x": -7,
      "y": 3,
      "z": 4,
      "name": "Rock_Volcanic"
    },
    {
      "x": -7,
      "y": 4,
      "z": 4,
      "name": "Rock_Volcanic"
    },
    {
      "x": -7,
      "y": 5,
      "z": 4,
      "name": "Rock_Volcanic"
    },
    {
      "x": -7,
      "y": 6,
      "z": 4,
      "name": "Rock_Volcanic"
    },
    {
      "x": -7,
      "y": 7,
      "z": 4,
      "name": "Rock_Volcanic"
    },
    {
      "x": -7,
      "y": 8,
      "z": 4,
      "name": "Rock_Volcanic"
    },
    {
      "x": -7,
      "y": 9,
      "z": 4,
      "name": "Rock_Volcanic"
    },
    {
      "x": -7,
      "y": 2,
      "z": 5,
      "name": "Rock_Volcanic"
    },
    {
      "x": -7,
      "y": 3,
      "z": 5,
      "name": "Rock_Volcanic_Cracked_Lava"
    },
    {
      "x": -7,
      "y": 4,
      "z": 5,
      "name": "Rock_Volcanic_Cracked_Lava"
    },
    {
      "x": -7,
      "y": 5,
      "z": 5,
      "name": "Rock_Volcanic"
    },
    {
      "x": -7,
      "y": 6,
      "z": 5,
      "name": "Rock_Volcanic"
    },
    {
      "x": -7,
      "y": 7,
      "z": 5,
      "name": "Rock_Volcanic_Cracked_Lava"
    },
    {
      "x": -7,
      "y": 8,
      "z": 5,
      "name": "Rock_Volcanic"
    },
    {
      "x": -7,
      "y": 9,
      "z": 5,
      "name": "Rock_Volcanic"
    },
    {
      "x": -7,
      "y": 10,
      "z": 5,
      "name": "Rock_Volcanic"
    },
    {
      "x": -7,
      "y": 3,
      "z": 6,
      "name": "Rock_Volcanic"
    },
    {
      "x": -7,
      "y": 4,
      "z": 6,
      "name": "Rock_Volcanic"
    },
    {
      "x": -7,
      "y": 5,
      "z": 6,
      "name": "Rock_Volcanic"
    },
    {
      "x": -7,
      "y": 6,
      "z": 6,
      "name": "Rock_Volcanic"
    },
    {
      "x": -7,
      "y": 7,
      "z": 6,
      "name": "Rock_Volcanic_Cracked_Lava"
    },
    {
      "x": -7,
      "y": 8,
      "z": 6,
      "name": "Rock_Volcanic"
    },
    {
      "x": -7,
      "y": 9,
      "z": 6,
      "name": "Rock_Volcanic"
    },
    {
      "x": -7,
      "y": 10,
      "z": 6,
      "name": "Rock_Volcanic"
    },
    {
      "x": -7,
      "y": 3,
      "z": 7,
      "name": "Rock_Volcanic"
    },
    {
      "x": -7,
      "y": 4,
      "z": 7,
      "name": "Rock_Volcanic"
    },
    {
      "x": -7,
      "y": 5,
      "z": 7,
      "name": "Rock_Volcanic"
    },
    {
      "x": -7,
      "y": 6,
      "z": 7,
      "name": "Rock_Volcanic"
    },
    {
      "x": -7,
      "y": 7,
      "z": 7,
      "name": "Rock_Volcanic_Cracked_Lava"
    },
    {
      "x": -7,
      "y": 8,
      "z": 7,
      "name": "Rock_Volcanic"
    },
    {
      "x": -7,
      "y": 9,
      "z": 7,
      "name": "Rock_Volcanic"
    },
    {
      "x": -7,
      "y": 10,
      "z": 7,
      "name": "Rock_Volcanic"
    },
    {
      "x": -7,
      "y": 3,
      "z": 8,
      "name": "Rock_Volcanic_Cracked_Lava"
    },
    {
      "x": -7,
      "y": 4,
      "z": 8,
      "name": "Rock_Volcanic"
    },
    {
      "x": -7,
      "y": 5,
      "z": 8,
      "name": "Ore_Gold_Volcanic"
    },
    {
      "x": -7,
      "y": 6,
      "z": 8,
      "name": "Rock_Volcanic"
    },
    {
      "x": -7,
      "y": 7,
      "z": 8,
      "name": "Rock_Volcanic"
    },
    {
      "x": -7,
      "y": 8,
      "z": 8,
      "name": "Rock_Volcanic"
    },
    {
      "x": -7,
      "y": 9,
      "z": 8,
      "name": "Rock_Volcanic"
    },
    {
      "x": -7,
      "y": 10,
      "z": 8,
      "name": "Rock_Volcanic_Cracked_Lava"
    },
    {
      "x": -7,
      "y": 11,
      "z": 8,
      "name": "Rock_Volcanic"
    },
    {
      "x": -7,
      "y": 12,
      "z": 8,
      "name": "Rock_Volcanic_Cracked_Lava"
    },
    {
      "x": -7,
      "y": 3,
      "z": 9,
      "name": "Rock_Volcanic"
    },
    {
      "x": -7,
      "y": 4,
      "z": 9,
      "name": "Rock_Volcanic"
    },
    {
      "x": -7,
      "y": 5,
      "z": 9,
      "name": "Rock_Volcanic_Cracked_Lava"
    },
    {
      "x": -7,
      "y": 6,
      "z": 9,
      "name": "Rock_Volcanic_Cracked_Lava"
    },
    {
      "x": -7,
      "y": 7,
      "z": 9,
      "name": "Rock_Volcanic_Cracked_Lava"
    },
    {
      "x": -7,
      "y": 8,
      "z": 9,
      "name": "Rock_Volcanic"
    },
    {
      "x": -7,
      "y": 9,
      "z": 9,
      "name": "Rock_Volcanic_Cracked_Lava"
    },
    {
      "x": -7,
      "y": 10,
      "z": 9,
      "name": "Rock_Volcanic"
    },
    {
      "x": -7,
      "y": 11,
      "z": 9,
      "name": "Rock_Volcanic_Cracked_Lava"
    },
    {
      "x": -7,
      "y": 12,
      "z": 9,
      "name": "Rock_Volcanic"
    },
    {
      "x": -7,
      "y": 4,
      "z": 10,
      "name": "Rock_Volcanic"
    },
    {
      "x": -7,
      "y": 5,
      "z": 10,
      "name": "Rock_Volcanic"
    },
    {
      "x": -7,
      "y": 6,
      "z": 10,
      "name": "Rock_Volcanic"
    },
    {
      "x": -7,
      "y": 7,
      "z": 10,
      "name": "Rock_Volcanic"
    },
    {
      "x": -7,
      "y": 8,
      "z": 10,
      "name": "Rock_Volcanic_Cracked_Lava"
    },
    {
      "x": -7,
      "y": 9,
      "z": 10,
      "name": "Rock_Volcanic_Cracked_Lava"
    },
    {
      "x": -7,
      "y": 10,
      "z": 10,
      "name": "Rock_Volcanic"
    },
    {
      "x": -7,
      "y": 11,
      "z": 10,
      "name": "Rock_Volcanic"
    },
    {
      "x": -7,
      "y": 12,
      "z": 10,
      "name": "Rock_Volcanic_Cracked_Lava"
    },
    {
      "x": -7,
      "y": 4,
      "z": 11,
      "name": "Rock_Volcanic_Cracked_Lava"
    },
    {
      "x": -7,
      "y": 5,
      "z": 11,
      "name": "Rock_Volcanic"
    },
    {
      "x": -7,
      "y": 6,
      "z": 11,
      "name": "Rock_Volcanic_Cracked_Lava"
    },
    {
      "x": -7,
      "y": 7,
      "z": 11,
      "name": "Rock_Volcanic"
    },
    {
      "x": -7,
      "y": 8,
      "z": 11,
      "name": "Rock_Volcanic"
    },
    {
      "x": -7,
      "y": 9,
      "z": 11,
      "name": "Rock_Volcanic"
    },
    {
      "x": -7,
      "y": 10,
      "z": 11,
      "name": "Rock_Volcanic"
    },
    {
      "x": -7,
      "y": 11,
      "z": 11,
      "name": "Rock_Volcanic"
    },
    {
      "x": -7,
      "y": 12,
      "z": 11,
      "name": "Rock_Volcanic"
    },
    {
      "x": -7,
      "y": 5,
      "z": 12,
      "name": "Rock_Volcanic_Cracked_Lava"
    },
    {
      "x": -7,
      "y": 6,
      "z": 12,
      "name": "Rock_Volcanic_Cracked_Lava"
    },
    {
      "x": -7,
      "y": 7,
      "z": 12,
      "name": "Rock_Volcanic"
    },
    {
      "x": -7,
      "y": 8,
      "z": 12,
      "name": "Rock_Volcanic"
    },
    {
      "x": -7,
      "y": 9,
      "z": 12,
      "name": "Rock_Volcanic"
    },
    {
      "x": -7,
      "y": 10,
      "z": 12,
      "name": "Rock_Volcanic"
    },
    {
      "x": -7,
      "y": 11,
      "z": 12,
      "name": "Rock_Volcanic"
    },
    {
      "x": -7,
      "y": 12,
      "z": 12,
      "name": "Rock_Volcanic"
    },
    {
      "x": -7,
      "y": 6,
      "z": 13,
      "name": "Rock_Volcanic_Cracked_Lava"
    },
    {
      "x": -7,
      "y": 7,
      "z": 13,
      "name": "Rock_Volcanic"
    },
    {
      "x": -7,
      "y": 8,
      "z": 13,
      "name": "Rock_Volcanic_Cracked_Lava"
    },
    {
      "x": -7,
      "y": 9,
      "z": 13,
      "name": "Rock_Volcanic"
    },
    {
      "x": -7,
      "y": 10,
      "z": 13,
      "name": "Rock_Volcanic_Cracked_Lava"
    },
    {
      "x": -7,
      "y": 11,
      "z": 13,
      "name": "Rock_Volcanic"
    },
    {
      "x": -7,
      "y": 12,
      "z": 13,
      "name": "Rock_Volcanic"
    },
    {
      "x": -7,
      "y": 13,
      "z": 13,
      "name": "Rock_Crystal_Yellow_Medium",
      "rotation": 6
    },
    {
      "x": -7,
      "y": 8,
      "z": 14,
      "name": "Rock_Volcanic"
    },
    {
      "x": -7,
      "y": 9,
      "z": 14,
      "name": "Rock_Volcanic"
    },
    {
      "x": -7,
      "y": 10,
      "z": 14,
      "name": "Rock_Volcanic_Cracked_Lava"
    },
    {
      "x": -7,
      "y": 11,
      "z": 14,
      "name": "Rock_Volcanic"
    },
    {
      "x": -7,
      "y": 12,
      "z": 14,
      "name": "Rock_Volcanic"
    },
    {
      "x": -7,
      "y": 13,
      "z": 14,
      "name": "Rock_Volcanic"
    },
    {
      "x": -7,
      "y": 14,
      "z": 14,
      "name": "Rock_Volcanic"
    },
    {
      "x": -7,
      "y": 15,
      "z": 14,
      "name": "Rock_Crystal_Yellow_Medium"
    },
    {
      "x": -7,
      "y": 9,
      "z": 15,
      "name": "Rock_Volcanic"
    },
    {
      "x": -7,
      "y": 10,
      "z": 15,
      "name": "Rock_Volcanic_Cracked_Lava"
    },
    {
      "x": -7,
      "y": 11,
      "z": 15,
      "name": "Rock_Volcanic"
    },
    {
      "x": -7,
      "y": 12,
      "z": 15,
      "name": "Rock_Volcanic"
    },
    {
      "x": -7,
      "y": 9,
      "z": 16,
      "name": "Rock_Volcanic"
    },
    {
      "x": -7,
      "y": 10,
      "z": 16,
      "name": "Rock_Volcanic_Cracked_Lava"
    },
    {
      "x": -7,
      "y": 11,
      "z": 16,
      "name": "Rock_Volcanic"
    },
    {
      "x": -7,
      "y": 12,
      "z": 16,
      "name": "Rock_Volcanic"
    },
    {
      "x": -6,
      "y": -2,
      "z": 0,
      "name": "Rock_Volcanic"
    },
    {
      "x": -6,
      "y": -1,
      "z": 0,
      "name": "Rock_Volcanic"
    },
    {
      "x": -6,
      "y": 0,
      "z": 0,
      "name": "Rock_Volcanic"
    },
    {
      "x": -6,
      "y": 1,
      "z": 0,
      "name": "Rock_Volcanic"
    },
    {
      "x": -6,
      "y": 2,
      "z": 0,
      "name": "Rock_Volcanic_Cracked_Lava"
    },
    {
      "x": -6,
      "y": 3,
      "z": 0,
      "name": "Rock_Volcanic"
    },
    {
      "x": -6,
      "y": 4,
      "z": 0,
      "name": "Rock_Volcanic_Cracked_Lava"
    },
    {
      "x": -6,
      "y": 5,
      "z": 0,
      "name": "Rock_Volcanic"
    },
    {
      "x": -6,
      "y": 6,
      "z": 0,
      "name": "Rock_Volcanic"
    },
    {
      "x": -6,
      "y": 7,
      "z": 0,
      "name": "Rock_Volcanic"
    },
    {
      "x": -6,
      "y": -1,
      "z": 1,
      "name": "Rock_Volcanic_Cracked_Lava"
    },
    {
      "x": -6,
      "y": 0,
      "z": 1,
      "name": "Rock_Volcanic"
    },
    {
      "x": -6,
      "y": 1,
      "z": 1,
      "name": "Rock_Volcanic"
    },
    {
      "x": -6,
      "y": 2,
      "z": 1,
      "name": "Rock_Volcanic"
    },
    {
      "x": -6,
      "y": 3,
      "z": 1,
      "name": "Rock_Volcanic"
    },
    {
      "x": -6,
      "y": 4,
      "z": 1,
      "name": "Rock_Volcanic_Cracked_Lava"
    },
    {
      "x": -6,
      "y": 5,
      "z": 1,
      "name": "Rock_Volcanic"
    },
    {
      "x": -6,
      "y": 6,
      "z": 1,
      "name": "Rock_Volcanic"
    },
    {
      "x": -6,
      "y": -2,
      "z": 2,
      "name": "Rock_Volcanic"
    },
    {
      "x": -6,
      "y": -1,
      "z": 2,
      "name": "Rock_Volcanic"
    },
    {
      "x": -6,
      "y": 0,
      "z": 2,
      "name": "Rock_Volcanic"
    },
    {
      "x": -6,
      "y": 1,
      "z": 2,
      "name": "Rock_Volcanic"
    },
    {
      "x": -6,
      "y": 2,
      "z": 2,
      "name": "Rock_Volcanic_Cracked_Lava"
    },
    {
      "x": -6,
      "y": 3,
      "z": 2,
      "name": "Rock_Volcanic"
    },
    {
      "x": -6,
      "y": 4,
      "z": 2,
      "name": "Rock_Volcanic"
    },
    {
      "x": -6,
      "y": 5,
      "z": 2,
      "name": "Rock_Volcanic"
    },
    {
      "x": -6,
      "y": 6,
      "z": 2,
      "name": "Rock_Volcanic"
    },
    {
      "x": -6,
      "y": 7,
      "z": 2,
      "name": "Rock_Volcanic_Cracked_Lava"
    },
    {
      "x": -6,
      "y": 8,
      "z": 2,
      "name": "Rock_Volcanic_Cracked_Lava"
    },
    {
      "x": -6,
      "y": 9,
      "z": 2,
      "name": "Rock_Volcanic"
    },
    {
      "x": -6,
      "y": -1,
      "z": 3,
      "name": "Rock_Volcanic_Cracked_Lava"
    },
    {
      "x": -6,
      "y": 0,
      "z": 3,
      "name": "Rock_Volcanic"
    },
    {
      "x": -6,
      "y": 1,
      "z": 3,
      "name": "Rock_Volcanic"
    },
    {
      "x": -6,
      "y": 2,
      "z": 3,
      "name": "Rock_Volcanic"
    },
    {
      "x": -6,
      "y": 3,
      "z": 3,
      "name": "Rock_Volcanic_Cracked_Lava"
    },
    {
      "x": -6,
      "y": 4,
      "z": 3,
      "name": "Rock_Volcanic"
    },
    {
      "x": -6,
      "y": 5,
      "z": 3,
      "name": "Rock_Volcanic_Cracked_Lava"
    },
    {
      "x": -6,
      "y": 6,
      "z": 3,
      "name": "Rock_Volcanic_Cracked_Lava"
    },
    {
      "x": -6,
      "y": 7,
      "z": 3,
      "name": "Rock_Volcanic"
    },
    {
      "x": -6,
      "y": 8,
      "z": 3,
      "name": "Rock_Volcanic_Cracked_Lava"
    },
    {
      "x": -6,
      "y": -1,
      "z": 4,
      "name": "Rock_Volcanic_Cracked_Lava"
    },
    {
      "x": -6,
      "y": 0,
      "z": 4,
      "name": "Rock_Volcanic"
    },
    {
      "x": -6,
      "y": 1,
      "z": 4,
      "name": "Rock_Volcanic"
    },
    {
      "x": -6,
      "y": 2,
      "z": 4,
      "name": "Rock_Volcanic"
    },
    {
      "x": -6,
      "y": 3,
      "z": 4,
      "name": "Rock_Volcanic_Cracked_Lava"
    },
    {
      "x": -6,
      "y": 4,
      "z": 4,
      "name": "Rock_Volcanic"
    },
    {
      "x": -6,
      "y": 5,
      "z": 4,
      "name": "Rock_Volcanic_Cracked_Lava"
    },
    {
      "x": -6,
      "y": 6,
      "z": 4,
      "name": "Rock_Volcanic_Cracked_Lava"
    },
    {
      "x": -6,
      "y": 7,
      "z": 4,
      "name": "Rock_Volcanic"
    },
    {
      "x": -6,
      "y": 8,
      "z": 4,
      "name": "Rock_Volcanic_Cracked_Lava"
    },
    {
      "x": -6,
      "y": 0,
      "z": 5,
      "name": "Rock_Volcanic"
    },
    {
      "x": -6,
      "y": 1,
      "z": 5,
      "name": "Rock_Volcanic_Cracked_Lava"
    },
    {
      "x": -6,
      "y": 2,
      "z": 5,
      "name": "Rock_Volcanic"
    },
    {
      "x": -6,
      "y": 3,
      "z": 5,
      "name": "Rock_Volcanic"
    },
    {
      "x": -6,
      "y": 4,
      "z": 5,
      "name": "Rock_Volcanic_Cracked_Lava"
    },
    {
      "x": -6,
      "y": 5,
      "z": 5,
      "name": "Rock_Volcanic"
    },
    {
      "x": -6,
      "y": 6,
      "z": 5,
      "name": "Rock_Volcanic"
    },
    {
      "x": -6,
      "y": 7,
      "z": 5,
      "name": "Rock_Volcanic"
    },
    {
      "x": -6,
      "y": 8,
      "z": 5,
      "name": "Rock_Volcanic"
    },
    {
      "x": -6,
      "y": 9,
      "z": 5,
      "name": "Rock_Volcanic"
    },
    {
      "x": -6,
      "y": 2,
      "z": 6,
      "name": "Rock_Volcanic"
    },
    {
      "x": -6,
      "y": 3,
      "z": 6,
      "name": "Rock_Volcanic"
    },
    {
      "x": -6,
      "y": 4,
      "z": 6,
      "name": "Rock_Volcanic"
    },
    {
      "x": -6,
      "y": 5,
      "z": 6,
      "name": "Ore_Gold_Volcanic"
    },
    {
      "x": -6,
      "y": 6,
      "z": 6,
      "name": "Rock_Volcanic_Cracked_Lava"
    },
    {
      "x": -6,
      "y": 7,
      "z": 6,
      "name": "Rock_Volcanic_Cracked_Lava"
    },
    {
      "x": -6,
      "y": 8,
      "z": 6,
      "name": "Rock_Volcanic"
    },
    {
      "x": -6,
      "y": 9,
      "z": 6,
      "name": "Rock_Volcanic_Cracked_Lava"
    },
    {
      "x": -6,
      "y": 10,
      "z": 6,
