{
  "version": 8,
  "blockIdVersion": 11,
  "anchorX": 0,
  "anchorY": 0,
  "anchorZ": 0,
  "blocks": [
    {
      "x": -22,
      "y": -21,
      "z": -28,
      "name": "Rock_Volcanic"
    },
    {
      "x": -21,
      "y": -21,
      "z": -28,
      "name": "Rock_Volcanic_Cracked_Lava"
    },
    {
      "x": -21,
      "y": -21,
      "z": -27,
      "name": "Rock_Volcanic"
    },
    {
      "x": -21,
      "y": -20,
      "z": -27,
      "name": "Rock_Volcanic"
    },
    {
      "x": -21,
      "y": -21,
      "z": -26,
      "name": "Rock_Volcanic"
    },
    {
      "x": -21,
      "y": -20,
      "z": -26,
      "name": "Rock_Volcanic"
    },
    {
      "x": -20,
      "y": -21,
      "z": -27,
      "name": "Rock_Volcanic"
    },
    {
      "x": -20,
      "y": -20,
      "z": -27,
      "name": "Rock_Volcanic_Cracked_Lava"
    },
    {
      "x": -20,
      "y": -21,
      "z": -26,
      "name": "Rock_Volcanic"
    },
    {
      "x": -20,
      "y": -19,
      "z": -26,
      "name": "Rock_Volcanic"
    },
    {
      "x": -20,
      "y": -21,
      "z": -25,
      "name": "Rock_Volcanic"
    },
    {
      "x": -20,
      "y": -20,
      "z": -25,
      "name": "Rock_Volcanic"
    },
    {
      "x": -20,
      "y": -19,
      "z": -25,
      "name": "Rock_Volcanic"
    },
    {
      "x": -19,
      "y": -21,
      "z": -26,
      "name": "Rock_Volcanic"
    },
    {
      "x": -19,
      "y": -19,
      "z": -26,
      "name": "Rock_Volcanic_Cracked_Lava"
    },
    {
      "x": -19,
      "y": -21,
      "z": -25,
      "name": "Rock_Volcanic_Cracked_Lava"
    },
    {
      "x": -19,
      "y": -20,
      "z": -25,
      "name": "Rock_Volcanic"
    },
    {
      "x": -19,
      "y": -19,
      "z": -25,
      "name": "Rock_Volcanic_Cracked_Lava"
    },
    {
      "x": -19,
      "y": -18,
      "z": -25,
      "name": "Rock_Volcanic_Cracked_Lava"
    },
    {
      "x": -19,
      "y": -21,
      "z": -24,
      "name": "Rock_Volcanic"
    },
    {
      "x": -19,
      "y": -20,
      "z": -24,
      "name": "Rock_Volcanic_Cracked_Lava"
    },
    {
      "x": -19,
      "y": -19,
      "z": -24,
      "name": "Rock_Volcanic"
    },
    {
      "x": -19,
      "y": -18,
      "z": -24,
      "name": "Rock_Volcanic"
    },
    {
      "x": -19,
      "y": -21,
      "z": -23,
      "name": "Rock_Volcanic"
    },
    {
      "x": -19,
      "y": -20,
      "z": -23,
      "name": "Rock_Volcanic"
    },
    {
      "x": -19,
      "y": -19,
      "z": -23,
      "name": "Rock_Volcanic"
    },
    {
      "x": -19,
      "y": -18,
      "z": -23,
      "name": "Rock_Volcanic"
    },
    {
      "x": -19,
      "y": -17,
      "z": -23,
      "name": "Rock_Volcanic_Cracked_Lava"
    },
    {
      "x": -19,
      "y": -20,
      "z": -22,
      "name": "Rock_Volcanic_Cracked_Lava"
    },
    {
      "x": -19,
      "y": -19,
      "z": -22,
      "name": "Rock_Volcanic_Cracked_Lava"
    },
    {
      "x": -19,
      "y": -18,
      "z": -22,
      "name": "Rock_Volcanic"
    },
    {
      "x": -19,
      "y": -17,
      "z": -22,
      "name": "Rock_Volcanic"
    },
    {
      "x": -19,
      "y": -16,
      "z": -22,
      "name": "Rock_Volcanic"
    },
    {
      "x": -18,
      "y": -21,
      "z": -27,
      "name": "Rock_Volcanic"
    },
    {
      "x": -18,
      "y": -20,
      "z": -27,
      "name": "Rock_Volcanic"
    },
    {
      "x": -18,
      "y": -19,
      "z": -27,
      "name": "Rock_Volcanic"
    },
    {
      "x": -18,
      "y": -21,
      "z": -26,
      "name": "Rock_Volcanic"
    },
    {
      "x": -18,
      "y": -20,
      "z": -26,
      "name": "Rock_Volcanic"
    },
    {
      "x": -18,
      "y": -19,
      "z": -26,
      "name": "Rock_Volcanic"
    },
    {
      "x": -18,
      "y": -18,
      "z": -26,
      "name": "Rock_Volcanic"
    },
    {
      "x": -18,
      "y": -21,
      "z": -25,
      "name": "Rock_Volcanic_Cracked_Lava"
    },
    {
      "x": -18,
      "y": -20,
      "z": -25,
      "name": "Rock_Volcanic_Cracked_Lava"
    },
    {
      "x": -18,
      "y": -19,
      "z": -25,
      "name": "Rock_Volcanic"
    },
    {
      "x": -18,
      "y": -18,
      "z": -25,
      "name": "Rock_Volcanic"
    },
    {
      "x": -18,
      "y": -21,
      "z": -24,
      "name": "Rock_Volcanic_Cracked_Lava"
    },
    {
      "x": -18,
      "y": -20,
      "z": -24,
      "name": "Rock_Volcanic_Cracked_Lava"
    },
    {
      "x": -18,
      "y": -19,
      "z": -24,
      "name": "Rock_Volcanic"
    },
    {
      "x": -18,
      "y": -18,
      "z": -24,
      "name": "Rock_Volcanic"
    },
    {
      "x": -18,
      "y": -17,
      "z": -24,
      "name": "Rock_Volcanic"
    },
    {
      "x": -18,
      "y": -20,
      "z": -23,
      "name": "Rock_Volcanic_Cracked_Lava"
    },
    {
      "x": -18,
      "y": -19,
      "z": -23,
      "name": "Rock_Volcanic"
    },
    {
      "x": -18,
      "y": -18,
      "z": -23,
      "name": "Rock_Volcanic"
    },
    {
      "x": -18,
      "y": -17,
      "z": -23,
      "name": "Rock_Volcanic"
    },
    {
      "x": -18,
      "y": -16,
      "z": -23,
      "name": "Rock_Volcanic"
    },
    {
      "x": -18,
      "y": -19,
      "z": -22,
      "name": "Rock_Volcanic_Cracked_Lava"
    },
    {
      "x": -18,
      "y": -18,
      "z": -22,
      "name": "Rock_Volcanic"
    },
    {
      "x": -18,
      "y": -17,
      "z": -22,
      "name": "Rock_Volcanic"
    },
    {
      "x": -18,
      "y": -16,
      "z": -22,
      "name": "Rock_Volcanic"
    },
    {
      "x": -18,
      "y": -19,
      "z": -21,
      "name": "Rock_Volcanic"
    },
    {
      "x": -18,
      "y": -18,
      "z": -21,
      "name": "Rock_Volcanic_Cracked_Lava"
    },
    {
      "x": -18,
      "y": -17,
      "z": -21,
      "name": "Rock_Volcanic_Cracked_Lava"
    },
    {
      "x": -18,
      "y": -16,
      "z": -21,
      "name": "Rock_Volcanic"
    },
    {
      "x": -17,
      "y": -21,
      "z": -26,
      "name": "Rock_Volcanic_Cracked_Lava"
    },
    {
      "x": -17,
      "y": -20,
      "z": -26,
      "name": "Rock_Volcanic"
    },
    {
      "x": -17,
      "y": -19,
      "z": -26,
      "name": "Rock_Volcanic"
    },
    {
      "x": -17,
      "y": -18,
      "z": -26,
      "name": "Rock_Volcanic_Cracked_Lava"
    },
    {
      "x": -17,
      "y": -21,
      "z": -25,
      "name": "Rock_Volcanic"
    },
    {
      "x": -17,
      "y": -20,
      "z": -25,
      "name": "Rock_Volcanic_Cracked_Lava"
    },
    {
      "x": -17,
      "y": -19,
      "z": -25,
      "name": "Rock_Volcanic"
    },
    {
      "x": -17,
      "y": -18,
      "z": -25,
      "name": "Rock_Volcanic"
    },
    {
      "x": -17,
      "y": -17,
      "z": -25,
      "name": "Rock_Volcanic"
    },
    {
      "x": -17,
      "y": -21,
      "z": -24,
      "name": "Rock_Volcanic"
    },
    {
      "x": -17,
      "y": -20,
      "z": -24,
      "name": "Rock_Volcanic_Cracked_Lava"
    },
    {
      "x": -17,
      "y": -19,
      "z": -24,
      "name": "Rock_Volcanic"
    },
    {
      "x": -17,
      "y": -18,
      "z": -24,
      "name": "Rock_Volcanic"
    },
    {
      "x": -17,
      "y": -17,
      "z": -24,
      "name": "Rock_Volcanic"
    },
    {
      "x": -17,
      "y": -20,
      "z": -23,
      "name": "Rock_Volcanic"
    },
    {
      "x": -17,
      "y": -19,
      "z": -23,
      "name": "Rock_Volcanic"
    },
    {
      "x": -17,
      "y": -18,
      "z": -23,
      "name": "Rock_Volcanic_Cracked_Lava"
    },
    {
      "x": -17,
      "y": -17,
      "z": -23,
      "name": "Rock_Volcanic"
    },
    {
      "x": -17,
      "y": -16,
      "z": -23,
      "name": "Rock_Volcanic"
    },
    {
      "x": -17,
      "y": -19,
      "z": -22,
      "name": "Rock_Volcanic_Cracked_Lava"
    },
    {
      "x": -17,
      "y": -18,
      "z": -22,
      "name": "Rock_Volcanic"
    },
    {
      "x": -17,
      "y": -17,
      "z": -22,
      "name": "Rock_Volcanic"
    },
    {
      "x": -17,
      "y": -16,
      "z": -22,
      "name": "Rock_Volcanic"
    },
    {
      "x": -17,
      "y": -20,
      "z": -21,
      "name": "Rock_Volcanic"
    },
    {
      "x": -17,
      "y": -19,
      "z": -21,
      "name": "Rock_Volcanic"
    },
    {
      "x": -17,
      "y": -18,
      "z": -21,
      "name": "Rock_Volcanic_Cracked_Lava"
    },
    {
      "x": -17,
      "y": -17,
      "z": -21,
      "name": "Rock_Volcanic"
    },
    {
      "x": -17,
      "y": -16,
      "z": -21,
      "name": "Rock_Volcanic"
    },
    {
      "x": -17,
      "y": -19,
      "z": -20,
      "name": "Rock_Volcanic_Cracked_Lava"
    },
    {
      "x": -17,
      "y": -18,
      "z": -20,
      "name": "Rock_Volcanic"
    },
    {
      "x": -17,
      "y": -17,
      "z": -20,
      "name": "Rock_Volcanic"
    },
    {
      "x": -17,
      "y": -16,
      "z": -20,
      "name": "Rock_Volcanic"
    },
    {
      "x": -17,
      "y": -15,
      "z": -20,
      "name": "Rock_Volcanic_Cracked_Lava"
    },
    {
      "x": -16,
      "y": -21,
      "z": -25,
      "name": "Rock_Volcanic_Cracked_Lava"
    },
    {
      "x": -16,
      "y": -20,
      "z": -25,
      "name": "Rock_Volcanic"
    },
    {
      "x": -16,
      "y": -19,
      "z": -25,
      "name": "Rock_Volcanic"
    },
    {
      "x": -16,
      "y": -18,
      "z": -25,
      "name": "Rock_Volcanic"
    },
    {
      "x": -16,
      "y": -17,
      "z": -25,
      "name": "Rock_Volcanic_Cracked_Lava"
    },
    {
      "x": -16,
      "y": -19,
      "z": -24,
      "name": "Rock_Volcanic_Cracked_Lava"
    },
    {
      "x": -16,
      "y": -18,
      "z": -24,
      "name": "Rock_Volcanic"
    },
    {
      "x": -16,
      "y": -17,
      "z": -24,
      "name": "Rock_Volcanic"
    },
    {
      "x": -16,
      "y": -16,
      "z": -24,
      "name": "Rock_Volcanic"
    },
    {
      "x": -16,
      "y": -19,
      "z": -23,
      "name": "Rock_Volcanic"
    },
    {
      "x": -16,
      "y": -18,
      "z": -23,
      "name": "Rock_Volcanic"
    },
    {
      "x": -16,
      "y": -17,
      "z": -23,
      "name": "Rock_Volcanic"
    },
    {
      "x": -16,
      "y": -16,
      "z": -23,
      "name": "Rock_Volcanic"
    },
    {
      "x": -16,
      "y": -15,
      "z": -23,
      "name": "Rock_Volcanic"
    },
    {
      "x": -16,
      "y": -19,
      "z": -22,
      "name": "Rock_Volcanic"
    },
    {
      "x": -16,
      "y": -18,
      "z": -22,
      "name": "Rock_Volcanic_Cracked_Lava"
    },
    {
      "x": -16,
      "y": -17,
      "z": -22,
      "name": "Rock_Volcanic"
    },
    {
      "x": -16,
      "y": -16,
      "z": -22,
      "name": "Rock_Volcanic"
    },
    {
      "x": -16,
      "y": -19,
      "z": -21,
      "name": "Rock_Volcanic"
    },
    {
      "x": -16,
      "y": -18,
      "z": -21,
      "name": "Rock_Volcanic"
    },
    {
      "x": -16,
      "y": -17,
      "z": -21,
      "name": "Rock_Volcanic"
    },
    {
      "x": -16,
      "y": -16,
      "z": -21,
      "name": "Rock_Volcanic_Cracked_Lava"
    },
    {
      "x": -16,
      "y": -15,
      "z": -21,
      "name": "Rock_Volcanic"
    },
    {
      "x": -16,
      "y": -14,
      "z": -21,
      "name": "Rock_Volcanic_Cracked_Lava"
    },
    {
      "x": -16,
      "y": -19,
      "z": -20,
      "name": "Rock_Volcanic"
    },
    {
      "x": -16,
      "y": -18,
      "z": -20,
      "name": "Rock_Volcanic"
    },
    {
      "x": -16,
      "y": -17,
      "z": -20,
      "name": "Rock_Volcanic"
    },
    {
      "x": -16,
      "y": -16,
      "z": -20,
      "name": "Rock_Volcanic_Cracked_Lava"
    },
    {
      "x": -16,
      "y": -15,
      "z": -20,
      "name": "Rock_Volcanic_Cracked_Lava"
    },
    {
      "x": -16,
      "y": -16,
      "z": -19,
      "name": "Rock_Volcanic"
    },
    {
      "x": -16,
      "y": -15,
      "z": -19,
      "name": "Rock_Volcanic_Cracked_Lava"
    },
    {
      "x": -16,
      "y": -14,
      "z": -18,
      "name": "Rock_Volcanic_Cracked_Lava"
    },
    {
      "x": -16,
      "y": -15,
      "z": -17,
      "name": "Rock_Volcanic"
    },
    {
      "x": -16,
      "y": -14,
      "z": -17,
      "name": "Rock_Volcanic"
    },
    {
      "x": -16,
      "y": -13,
      "z": -17,
      "name": "Rock_Volcanic"
    },
    {
      "x": -16,
      "y": -12,
      "z": -17,
      "name": "Rock_Volcanic"
    },
    {
      "x": -15,
      "y": -19,
      "z": -22,
      "name": "Rock_Volcanic"
    },
    {
      "x": -15,
      "y": -18,
      "z": -22,
      "name": "Rock_Volcanic"
    },
    {
      "x": -15,
      "y": -17,
      "z": -22,
      "name": "Rock_Volcanic"
    },
    {
      "x": -15,
      "y": -16,
      "z": -22,
      "name": "Rock_Volcanic"
    },
    {
      "x": -15,
      "y": -15,
      "z": -22,
      "name": "Rock_Volcanic"
    },
    {
      "x": -15,
      "y": -14,
      "z": -22,
      "name": "Rock_Volcanic"
    },
    {
      "x": -15,
      "y": -19,
      "z": -21,
      "name": "Rock_Volcanic"
    },
    {
      "x": -15,
      "y": -18,
      "z": -21,
      "name": "Rock_Volcanic"
    },
    {
      "x": -15,
      "y": -17,
      "z": -21,
      "name": "Rock_Volcanic"
    },
    {
      "x": -15,
      "y": -16,
      "z": -21,
      "name": "Rock_Volcanic"
    },
    {
      "x": -15,
      "y": -15,
      "z": -21,
      "name": "Rock_Volcanic_Cracked_Lava"
    },
    {
      "x": -15,
      "y": -14,
      "z": -21,
      "name": "Rock_Volcanic"
    },
    {
      "x": -15,
      "y": -19,
      "z": -20,
      "name": "Rock_Volcanic"
    },
    {
      "x": -15,
      "y": -18,
      "z": -20,
      "name": "Rock_Volcanic"
    },
    {
      "x": -15,
      "y": -17,
      "z": -20,
      "name": "Rock_Volcanic_Cracked_Lava"
    },
    {
      "x": -15,
      "y": -16,
      "z": -20,
      "name": "Rock_Volcanic"
    },
    {
      "x": -15,
      "y": -15,
      "z": -20,
      "name": "Rock_Volcanic_Cracked_Lava"
    },
    {
      "x": -15,
      "y": -14,
      "z": -20,
      "name": "Rock_Volcanic"
    },
    {
      "x": -15,
      "y": -18,
      "z": -19,
      "name": "Rock_Volcanic"
    },
    {
      "x": -15,
      "y": -17,
      "z": -19,
      "name": "Rock_Volcanic_Cracked_Lava"
    },
    {
      "x": -15,
      "y": -16,
      "z": -19,
      "name": "Rock_Volcanic"
    },
    {
      "x": -15,
      "y": -15,
      "z": -19,
      "name": "Rock_Volcanic"
    },
    {
      "x": -15,
      "y": -14,
      "z": -19,
      "name": "Rock_Volcanic"
    },
    {
      "x": -15,
      "y": -17,
      "z": -18,
      "name": "Rock_Volcanic_Cracked_Lava"
    },
    {
      "x": -15,
      "y": -16,
      "z": -18,
      "name": "Rock_Volcanic"
    },
    {
      "x": -15,
      "y": -15,
      "z": -18,
      "name": "Rock_Volcanic"
    },
    {
      "x": -15,
      "y": -14,
      "z": -18,
      "name": "Rock_Volcanic_Cracked_Lava"
    },
    {
      "x": -15,
      "y": -13,
      "z": -18,
      "name": "Rock_Volcanic"
    },
    {
      "x": -15,
      "y": -16,
      "z": -17,
      "name": "Rock_Volcanic"
    },
    {
      "x": -15,
      "y": -15,
      "z": -17,
      "name": "Rock_Volcanic"
    },
    {
      "x": -15,
      "y": -14,
      "z": -17,
      "name": "Rock_Volcanic"
    },
    {
      "x": -15,
      "y": -13,
      "z": -17,
      "name": "Rock_Volcanic"
    },
    {
      "x": -15,
      "y": -12,
      "z": -17,
      "name": "Rock_Volcanic"
    },
    {
      "x": -15,
      "y": -15,
      "z": -16,
      "name": "Rock_Volcanic"
    },
    {
      "x": -15,
      "y": -14,
      "z": -16,
      "name": "Rock_Volcanic"
    },
    {
      "x": -15,
      "y": -13,
      "z": -16,
      "name": "Rock_Volcanic"
    },
    {
      "x": -15,
      "y": -12,
      "z": -16,
      "name": "Rock_Volcanic"
    },
    {
      "x": -15,
      "y": -17,
      "z": -15,
      "name": "Rock_Volcanic"
    },
    {
      "x": -15,
      "y": -16,
      "z": -15,
      "name": "Rock_Volcanic"
    },
    {
      "x": -15,
      "y": -15,
      "z": -15,
      "name": "Rock_Volcanic"
    },
    {
      "x": -15,
      "y": -14,
      "z": -15,
      "name": "Rock_Volcanic"
    },
    {
      "x": -15,
      "y": -13,
      "z": -15,
      "name": "Rock_Volcanic"
    },
    {
      "x": -15,
      "y": -12,
      "z": -15,
      "name": "Rock_Volcanic"
    },
    {
      "x": -15,
      "y": -11,
      "z": -15,
      "name": "Rock_Volcanic"
    },
    {
      "x": -14,
      "y": -19,
      "z": -22,
      "name": "Rock_Volcanic_Cracked_Lava"
    },
    {
      "x": -14,
      "y": -18,
      "z": -22,
      "name": "Rock_Volcanic"
    },
    {
      "x": -14,
      "y": -17,
      "z": -22,
      "name": "Rock_Volcanic_Cracked_Lava"
    },
    {
      "x": -14,
      "y": -18,
      "z": -21,
      "name": "Rock_Volcanic"
    },
    {
      "x": -14,
      "y": -17,
      "z": -21,
      "name": "Rock_Volcanic"
    },
    {
      "x": -14,
      "y": -16,
      "z": -21,
      "name": "Rock_Volcanic"
    },
    {
      "x": -14,
      "y": -15,
      "z": -21,
      "name": "Rock_Volcanic"
    },
    {
      "x": -14,
      "y": -14,
      "z": -21,
      "name": "Rock_Volcanic_Cracked_Lava"
    },
    {
      "x": -14,
      "y": -17,
      "z": -20,
      "name": "Rock_Volcanic"
    },
    {
      "x": -14,
      "y": -16,
      "z": -20,
      "name": "Rock_Volcanic"
    },
    {
      "x": -14,
      "y": -15,
      "z": -20,
      "name": "Rock_Volcanic"
    },
    {
      "x": -14,
      "y": -14,
      "z": -20,
      "name": "Rock_Volcanic_Cracked_Lava"
    },
    {
      "x": -14,
      "y": -13,
      "z": -20,
      "name": "Rock_Volcanic"
    },
    {
      "x": -14,
      "y": -16,
      "z": -19,
      "name": "Rock_Volcanic"
    },
    {
      "x": -14,
      "y": -15,
      "z": -19,
      "name": "Rock_Volcanic"
    },
    {
      "x": -14,
      "y": -14,
      "z": -19,
      "name": "Rock_Volcanic"
    },
    {
      "x": -14,
      "y": -13,
      "z": -19,
      "name": "Rock_Volcanic_Cracked_Lava"
    },
    {
      "x": -14,
      "y": -12,
      "z": -19,
      "name": "Rock_Volcanic"
    },
    {
      "x": -14,
      "y": -16,
      "z": -18,
      "name": "Rock_Volcanic"
    },
    {
      "x": -14,
      "y": -15,
      "z": -18,
      "name": "Rock_Volcanic"
    },
    {
      "x": -14,
      "y": -14,
      "z": -18,
      "name": "Rock_Volcanic"
    },
    {
      "x": -14,
      "y": -13,
      "z": -18,
      "name": "Rock_Volcanic_Cracked_Lava"
    },
    {
      "x": -14,
      "y": -12,
      "z": -18,
      "name": "Rock_Volcanic"
    },
    {
      "x": -14,
      "y": -16,
      "z": -17,
      "name": "Rock_Volcanic_Cracked_Lava"
    },
    {
      "x": -14,
      "y": -15,
      "z": -17,
      "name": "Rock_Volcanic"
    },
    {
      "x": -14,
      "y": -14,
      "z": -17,
      "name": "Rock_Volcanic"
    },
    {
      "x": -14,
      "y": -13,
      "z": -17,
      "name": "Rock_Volcanic"
    },
    {
      "x": -14,
      "y": -12,
      "z": -17,
      "name": "Rock_Volcanic"
    },
    {
      "x": -14,
      "y": -11,
      "z": -17,
      "name": "Rock_Volcanic"
    },
    {
      "x": -14,
      "y": -16,
      "z": -16,
      "name": "Rock_Volcanic"
    },
    {
      "x": -14,
      "y": -15,
      "z": -16,
      "name": "Rock_Volcanic"
    },
    {
      "x": -14,
      "y": -14,
      "z": -16,
      "name": "Rock_Volcanic"
    },
    {
      "x": -14,
      "y": -13,
      "z": -16,
      "name": "Rock_Volcanic"
    },
    {
      "x": -14,
      "y": -12,
      "z": -16,
      "name": "Rock_Volcanic"
    },
    {
      "x": -14,
      "y": -17,
      "z": -15,
      "name": "Rock_Volcanic"
    },
    {
      "x": -14,
      "y": -16,
      "z": -15,
      "name": "Rock_Volcanic"
    },
    {
      "x": -14,
      "y": -15,
      "z": -15,
      "name": "Rock_Volcanic"
    },
    {
      "x": -14,
      "y": -14,
      "z": -15,
      "name": "Rock_Volcanic"
    },
    {
      "x": -14,
      "y": -13,
      "z": -15,
      "name": "Rock_Volcanic"
    },
    {
      "x": -14,
      "y": -12,
      "z": -15,
      "name": "Rock_Volcanic"
    },
    {
      "x": -14,
      "y": -11,
      "z": -15,
      "name": "Rock_Volcanic"
    },
    {
      "x": -14,
      "y": -10,
      "z": -15,
      "name": "Rock_Volcanic"
    },
    {
      "x": -14,
      "y": -17,
      "z": -14,
      "name": "Rock_Volcanic"
    },
    {
      "x": -14,
      "y": -16,
      "z": -14,
      "name": "Rock_Volcanic"
    },
    {
      "x": -14,
      "y": -15,
      "z": -14,
      "name": "Rock_Volcanic"
    },
    {
      "x": -14,
      "y": -14,
      "z": -14,
      "name": "Rock_Volcanic"
    },
    {
      "x": -14,
      "y": -13,
      "z": -14,
      "name": "Rock_Volcanic_Cracked_Lava"
    },
    {
      "x": -14,
      "y": -12,
      "z": -14,
      "name": "Rock_Volcanic"
    },
    {
      "x": -14,
      "y": -11,
      "z": -14,
      "name": "Rock_Volcanic"
    },
    {
      "x": -14,
      "y": -10,
      "z": -14,
      "name": "Rock_Volcanic"
    },
    {
      "x": -13,
      "y": -18,
      "z": -21,
      "name": "Rock_Volcanic"
    },
    {
      "x": -13,
      "y": -17,
      "z": -21,
      "name": "Rock_Volcanic_Cracked_Lava"
    },
    {
      "x": -13,
      "y": -16,
      "z": -21,
      "name": "Rock_Volcanic"
    },
    {
      "x": -13,
      "y": -15,
      "z": -21,
      "name": "Rock_Volcanic"
    },
    {
      "x": -13,
      "y": -14,
      "z": -21,
      "name": "Rock_Volcanic"
    },
    {
      "x": -13,
      "y": -17,
      "z": -20,
      "name": "Rock_Volcanic"
    },
    {
      "x": -13,
      "y": -16,
      "z": -20,
      "name": "Rock_Volcanic"
    },
    {
      "x": -13,
      "y": -15,
      "z": -20,
      "name": "Rock_Volcanic"
    },
    {
      "x": -13,
      "y": -14,
      "z": -20,
      "name": "Rock_Volcanic"
    },
    {
      "x": -13,
      "y": -13,
      "z": -20,
      "name": "Rock_Volcanic"
    },
    {
      "x": -13,
      "y": -12,
      "z": -20,
      "name": "Rock_Volcanic_Cracked_Lava"
    },
    {
      "x": -13,
      "y": -16,
      "z": -19,
      "name": "Rock_Volcanic"
    },
    {
      "x": -13,
      "y": -15,
      "z": -19,
      "name": "Rock_Volcanic_Cracked_Lava"
    },
    {
      "x": -13,
      "y": -14,
      "z": -19,
      "name": "Rock_Volcanic"
    },
    {
      "x": -13,
      "y": -13,
      "z": -19,
      "name": "Rock_Volcanic"
    },
    {
      "x": -13,
      "y": -12,
      "z": -19,
      "name": "Rock_Volcanic"
    },
    {
      "x": -13,
      "y": -16,
      "z": -18,
      "name": "Rock_Volcanic_Cracked_Lava"
    },
    {
      "x": -13,
      "y": -15,
      "z": -18,
      "name": "Rock_Volcanic"
    },
    {
      "x": -13,
      "y": -14,
      "z": -18,
      "name": "Rock_Volcanic"
    },
    {
      "x": -13,
      "y": -13,
      "z": -18,
      "name": "Rock_Volcanic"
    },
    {
      "x": -13,
      "y": -12,
      "z": -18,
      "name": "Rock_Volcanic"
    },
    {
      "x": -13,
      "y": -11,
      "z": -18,
      "name": "Rock_Volcanic"
    },
    {
      "x": -13,
      "y": -17,
      "z": -17,
      "name": "Rock_Volcanic"
    },
    {
      "x": -13,
      "y": -16,
      "z": -17,
      "name": "Rock_Volcanic"
    },
    {
      "x": -13,
      "y": -15,
      "z": -17,
      "name": "Rock_Volcanic"
    },
    {
      "x": -13,
      "y": -14,
      "z": -17,
      "name": "Rock_Volcanic"
    },
    {
      "x": -13,
      "y": -13,
      "z": -17,
      "name": "Rock_Volcanic"
    },
    {
      "x": -13,
      "y": -12,
      "z": -17,
      "name": "Rock_Volcanic"
    },
    {
      "x": -13,
      "y": -11,
      "z": -17,
      "name": "Rock_Volcanic"
    },
    {
      "x": -13,
      "y": -10,
      "z": -17,
      "name": "Rock_Volcanic"
    },
    {
      "x": -13,
      "y": -17,
      "z": -16,
      "name": "Rock_Volcanic"
    },
    {
      "x": -13,
      "y": -16,
      "z": -16,
      "name": "Rock_Volcanic_Cracked_Lava"
    },
    {
      "x": -13,
      "y": -15,
      "z": -16,
      "name": "Rock_Volcanic"
    },
    {
      "x": -13,
      "y": -14,
      "z": -16,
      "name": "Rock_Volcanic"
    },
    {
      "x": -13,
      "y": -13,
      "z": -16,
      "name": "Rock_Volcanic"
    },
    {
      "x": -13,
      "y": -12,
      "z": -16,
      "name": "Rock_Volcanic"
    },
    {
      "x": -13,
      "y": -11,
      "z": -16,
      "name": "Rock_Volcanic"
    },
    {
      "x": -13,
      "y": -10,
      "z": -16,
      "name": "Rock_Volcanic"
    },
    {
      "x": -13,
      "y": -17,
      "z": -15,
      "name": "Rock_Volcanic"
    },
    {
      "x": -13,
      "y": -16,
      "z": -15,
      "name": "Rock_Volcanic"
    },
    {
      "x": -13,
      "y": -15,
      "z": -15,
      "name": "Rock_Volcanic"
    },
    {
      "x": -13,
      "y": -14,
      "z": -15,
      "name": "Rock_Volcanic"
    },
    {
      "x": -13,
      "y": -13,
      "z": -15,
      "name": "Rock_Volcanic_Cracked_Lava"
    },
    {
      "x": -13,
      "y": -12,
      "z": -15,
      "name": "Rock_Volcanic"
    },
    {
      "x": -13,
      "y": -11,
      "z": -15,
      "name": "Rock_Volcanic"
    },
    {
      "x": -13,
      "y": -10,
      "z": -15,
      "name": "Rock_Volcanic"
    },
    {
      "x": -13,
      "y": -14,
      "z": -14,
      "name": "Rock_Volcanic"
    },
    {
      "x": -13,
      "y": -13,
      "z": -14,
      "name": "Rock_Volcanic"
    },
    {
      "x": -13,
      "y": -12,
      "z": -14,
      "name": "Rock_Volcanic"
    },
    {
      "x": -13,
      "y": -11,
      "z": -14,
      "name": "Rock_Volcanic"
    },
    {
      "x": -13,
      "y": -10,
      "z": -14,
      "name": "Rock_Volcanic_Cracked_Lava"
    },
    {
      "x": -13,
      "y": -9,
      "z": -14,
      "name": "Rock_Volcanic"
    },
    {
      "x": -13,
      "y": -12,
      "z": -13,
      "name": "Rock_Volcanic"
    },
    {
      "x": -13,
      "y": -11,
      "z": -13,
      "name": "Rock_Volcanic_Cracked_Lava"
    },
    {
      "x": -13,
      "y": -10,
      "z": -13,
      "name": "Rock_Volcanic"
    },
    {
      "x": -13,
      "y": -9,
      "z": -13,
      "name": "Rock_Volcanic"
    },
    {
      "x": -12,
      "y": -14,
      "z": -21,
      "name": "Rock_Volcanic"
    },
    {
      "x": -12,
      "y": -17,
      "z": -20,
      "name": "Rock_Volcanic"
    },
    {
      "x": -12,
      "y": -16,
      "z": -20,
      "name": "Rock_Volcanic_Cracked_Lava"
    },
    {
      "x": -12,
      "y": -15,
      "z": -20,
      "name": "Rock_Volcanic"
    },
    {
      "x": -12,
      "y": -14,
      "z": -20,
      "name": "Rock_Volcanic"
    },
    {
      "x": -12,
      "y": -13,
      "z": -20,
      "name": "Rock_Volcanic"
    },
    {
      "x": -12,
      "y": -12,
      "z": -20,
      "name": "Rock_Volcanic"
    },
    {
      "x": -12,
      "y": -16,
      "z": -19,
      "name": "Rock_Volcanic"
    },
    {
      "x": -12,
      "y": -15,
      "z": -19,
      "name": "Rock_Volcanic"
    },
    {
      "x": -12,
      "y": -14,
      "z": -19,
      "name": "Rock_Volcanic"
    },
    {
      "x": -12,
      "y": -13,
      "z": -19,
      "name": "Rock_Volcanic"
    },
    {
      "x": -12,
      "y": -12,
      "z": -19,
      "name": "Rock_Volcanic_Cracked_Lava"
    },
    {
      "x": -12,
      "y": -16,
      "z": -18,
      "name": "Rock_Volcanic"
    },
    {
      "x": -12,
      "y": -15,
      "z": -18,
      "name": "Rock_Volcanic"
    },
    {
      "x": -12,
      "y": -14,
      "z": -18,
      "name": "Rock_Volcanic"
    },
    {
      "x": -12,
      "y": -13,
      "z": -18,
      "name": "Rock_Volcanic"
    },
    {
      "x": -12,
      "y": -12,
      "z": -18,
      "name": "Rock_Volcanic"
    },
    {
      "x": -12,
      "y": -11,
      "z": -18,
      "name": "Rock_Volcanic"
    },
    {
      "x": -12,
      "y": -17,
      "z": -17,
      "name": "Rock_Volcanic"
    },
    {
      "x": -12,
      "y": -16,
      "z": -17,
      "name": "Rock_Volcanic"
    },
    {
      "x": -12,
      "y": -15,
      "z": -17,
      "name": "Rock_Volcanic"
    },
    {
      "x": -12,
      "y": -14,
      "z": -17,
      "name": "Rock_Volcanic"
    },
    {
      "x": -12,
      "y": -13,
      "z": -17,
      "name": "Rock_Volcanic"
    },
    {
      "x": -12,
      "y": -12,
      "z": -17,
      "name": "Rock_Volcanic"
    },
    {
      "x": -12,
      "y": -11,
      "z": -17,
      "name": "Rock_Volcanic"
    },
    {
      "x": -12,
      "y": -10,
      "z": -17,
      "name": "Rock_Volcanic"
    },
    {
      "x": -12,
      "y": -17,
      "z": -16,
      "name": "Rock_Volcanic_Cracked_Lava"
    },
    {
      "x": -12,
      "y": -16,
      "z": -16,
      "name": "Rock_Volcanic"
    },
    {
      "x": -12,
      "y": -15,
      "z": -16,
      "name": "Rock_Volcanic"
    },
    {
      "x": -12,
      "y": -14,
      "z": -16,
      "name": "Rock_Volcanic"
    },
    {
      "x": -12,
      "y": -13,
      "z": -16,
      "name": "Rock_Volcanic"
    },
    {
      "x": -12,
      "y": -12,
      "z": -16,
      "name": "Rock_Volcanic"
    },
    {
      "x": -12,
      "y": -11,
      "z": -16,
      "name": "Rock_Volcanic"
    },
    {
      "x": -12,
      "y": -10,
      "z": -16,
      "name": "Rock_Volcanic_Cracked_Lava"
    },
    {
      "x": -12,
      "y": -16,
      "z": -15,
      "name": "Rock_Volcanic"
    },
    {
      "x": -12,
      "y": -15,
      "z": -15,
      "name": "Rock_Volcanic"
    },
    {
      "x": -12,
      "y": -14,
      "z": -15,
      "name": "Rock_Volcanic"
    },
    {
      "x": -12,
      "y": -13,
      "z": -15,
      "name": "Rock_Volcanic"
    },
    {
      "x": -12,
      "y": -12,
      "z": -15,
      "name": "Rock_Volcanic_Cracked_Lava"
    },
    {
      "x": -12,
      "y": -11,
      "z": -15,
      "name": "Rock_Volcanic_Cracked_Lava"
    },
    {
      "x": -12,
      "y": -10,
      "z": -15,
      "name": "Rock_Volcanic"
    },
    {
      "x": -12,
      "y": -9,
      "z": -15,
      "name": "Rock_Volcanic"
    },
    {
      "x": -12,
      "y": -15,
      "z": -14,
      "name": "Rock_Volcanic"
    },
    {
      "x": -12,
      "y": -14,
      "z": -14,
      "name": "Rock_Volcanic"
    },
    {
      "x": -12,
      "y": -13,
      "z": -14,
      "name": "Rock_Volcanic"
    },
    {
      "x": -12,
      "y": -12,
      "z": -14,
      "name": "Rock_Volcanic"
    },
    {
      "x": -12,
      "y": -11,
      "z": -14,
      "name": "Rock_Volcanic"
    },
    {
      "x": -12,
      "y": -10,
      "z": -14,
      "name": "Rock_Volcanic"
    },
    {
      "x": -12,
      "y": -9,
      "z": -14,
      "name": "Rock_Volcanic"
    },
    {
      "x": -12,
      "y": -15,
      "z": -13,
      "name": "Rock_Volcanic"
    },
    {
      "x": -12,
      "y": -14,
      "z": -13,
      "name": "Rock_Volcanic"
    },
    {
      "x": -12,
      "y": -13,
      "z": -13,
      "name": "Rock_Volcanic"
    },
    {
      "x": -12,
      "y": -12,
      "z": -13,
      "name": "Rock_Volcanic"
    },
    {
      "x": -12,
      "y": -11,
      "z": -13,
      "name": "Rock_Volcanic"
    },
    {
      "x": -12,
      "y": -10,
      "z": -13,
      "name": "Rock_Volcanic"
    },
    {
      "x": -12,
      "y": -9,
      "z": -13,
      "name": "Rock_Volcanic"
    },
    {
      "x": -12,
      "y": -14,
      "z": -12,
      "name": "Rock_Volcanic"
    },
    {
      "x": -12,
      "y": -13,
      "z": -12,
      "name": "Rock_Volcanic"
    },
    {
      "x": -12,
      "y": -12,
      "z": -12,
      "name": "Rock_Volcanic_Cracked_Lava"
    },
    {
      "x": -12,
      "y": -11,
      "z": -12,
      "name": "Rock_Volcanic"
    },
    {
      "x": -12,
      "y": -10,
      "z": -12,
      "name": "Rock_Volcanic"
    },
    {
      "x": -12,
      "y": -9,
      "z": -12,
      "name": "Rock_Volcanic"
    },
    {
      "x": -12,
      "y": -14,
      "z": -11,
      "name": "Rock_Volcanic"
    },
    {
      "x": -12,
      "y": -13,
      "z": -11,
      "name": "Rock_Volcanic_Cracked_Lava"
    },
    {
      "x": -12,
      "y": -12,
      "z": -11,
      "name": "Rock_Volcanic"
    },
    {
      "x": -12,
      "y": -11,
      "z": -11,
      "name": "Rock_Volcanic"
    },
    {
      "x": -12,
      "y": -10,
      "z": -11,
      "name": "Rock_Volcanic"
    },
    {
      "x": -12,
      "y": -9,
      "z": -11,
      "name": "Rock_Volcanic"
    },
    {
      "x": -12,
      "y": -8,
      "z": -11,
      "name": "Rock_Volcanic_Cracked_Lava"
    },
    {
      "x": -12,
      "y": -7,
      "z": -11,
      "name": "Rock_Volcanic"
    },
    {
      "x": -11,
      "y": -15,
      "z": -20,
      "name": "Rock_Volcanic"
    },
    {
      "x": -11,
      "y": -13,
      "z": -20,
      "name": "Rock_Volcanic"
    },
    {
      "x": -11,
      "y": -12,
      "z": -20,
      "name": "Rock_Volcanic"
    },
    {
      "x": -11,
      "y": -16,
      "z": -19,
      "name": "Rock_Volcanic_Cracked_Lava"
    },
    {
      "x": -11,
      "y": -15,
      "z": -19,
      "name": "Rock_Volcanic"
    },
    {
      "x": -11,
      "y": -14,
      "z": -19,
      "name": "Rock_Volcanic"
    },
    {
      "x": -11,
      "y": -13,
      "z": -19,
      "name": "Rock_Volcanic"
    },
    {
      "x": -11,
      "y": -12,
      "z": -19,
      "name": "Rock_Volcanic"
    },
    {
      "x": -11,
      "y": -11,
      "z": -19,
      "name": "Rock_Volcanic"
    },
    {
      "x": -11,
      "y": -17,
      "z": -18,
      "name": "Rock_Volcanic"
    },
    {
      "x": -11,
      "y": -16,
      "z": -18,
      "name": "Rock_Volcanic"
    },
    {
      "x": -11,
      "y": -15,
      "z": -18,
      "name": "Rock_Volcanic"
    },
    {
      "x": -11,
      "y": -14,
      "z": -18,
      "name": "Rock_Volcanic_Cracked_Lava"
    },
    {
      "x": -11,
      "y": -13,
      "z": -18,
      "name": "Rock_Volcanic"
    },
    {
      "x": -11,
      "y": -12,
      "z": -18,
      "name": "Rock_Volcanic"
    },
    {
      "x": -11,
      "y": -11,
      "z": -18,
      "name": "Rock_Volcanic"
    },
    {
      "x": -11,
      "y": -10,
      "z": -18,
      "name": "Rock_Volcanic_Cracked_Lava"
    },
    {
      "x": -11,
      "y": -16,
      "z": -17,
      "name": "Rock_Volcanic_Cracked_Lava"
    },
    {
      "x": -11,
      "y": -15,
      "z": -17,
      "name": "Rock_Volcanic"
    },
    {
      "x": -11,
      "y": -14,
      "z": -17,
      "name": "Rock_Volcanic"
    },
    {
      "x": -11,
      "y": -13,
      "z": -17,
      "name": "Rock_Volcanic"
    },
    {
      "x": -11,
      "y": -12,
      "z": -17,
      "name": "Rock_Volcanic"
    },
    {
      "x": -11,
      "y": -11,
      "z": -17,
      "name": "Rock_Volcanic"
    },
    {
      "x": -11,
      "y": -10,
      "z": -17,
      "name": "Rock_Volcanic"
    },
    {
      "x": -11,
      "y": -9,
      "z": -17,
      "name": "Rock_Volcanic"
    },
    {
      "x": -11,
      "y": -17,
      "z": -16,
      "name": "Rock_Volcanic"
    },
    {
      "x": -11,
      "y": -16,
      "z": -16,
      "name": "Rock_Volcanic"
    },
    {
      "x": -11,
      "y": -15,
      "z": -16,
      "name": "Rock_Volcanic_Cracked_Lava"
    },
    {
      "x": -11,
      "y": -14,
      "z": -16,
      "name": "Rock_Volcanic"
    },
    {
      "x": -11,
      "y": -13,
      "z": -16,
      "name": "Rock_Volcanic"
    },
    {
      "x": -11,
      "y": -12,
      "z": -16,
      "name": "Rock_Volcanic"
    },
    {
      "x": -11,
      "y": -11,
      "z": -16,
      "name": "Rock_Volcanic_Cracked_Lava"
    },
    {
      "x": -11,
      "y": -10,
      "z": -16,
      "name": "Rock_Volcanic"
    },
    {
      "x": -11,
      "y": -16,
      "z": -15,
      "name": "Rock_Volcanic"
    },
    {
      "x": -11,
      "y": -15,
      "z": -15,
      "name": "Rock_Volcanic"
    },
    {
      "x": -11,
      "y": -14,
      "z": -15,
      "name": "Rock_Volcanic"
    },
    {
      "x": -11,
      "y": -13,
      "z": -15,
      "name": "Rock_Volcanic"
    },
    {
      "x": -11,
      "y": -12,
      "z": -15,
      "name": "Rock_Volcanic"
    },
    {
      "x": -11,
      "y": -11,
      "z": -15,
      "name": "Rock_Volcanic"
    },
    {
      "x": -11,
      "y": -10,
      "z": -15,
      "name": "Rock_Volcanic_Cracked_Lava"
    },
    {
      "x": -11,
      "y": -9,
      "z": -15,
      "name": "Rock_Volcanic"
    },
    {
      "x": -11,
      "y": -15,
      "z": -14,
      "name": "Rock_Volcanic"
    },
    {
      "x": -11,
      "y": -14,
      "z": -14,
      "name": "Rock_Volcanic_Cracked_Lava"
    },
    {
      "x": -11,
      "y": -13,
      "z": -14,
      "name": "Rock_Volcanic"
    },
    {
      "x": -11,
      "y": -12,
      "z": -14,
      "name": "Rock_Volcanic"
    },
    {
      "x": -11,
      "y": -11,
      "z": -14,
      "name": "Rock_Volcanic"
    },
    {
      "x": -11,
      "y": -10,
      "z": -14,
      "name": "Rock_Volcanic"
    },
    {
      "x": -11,
      "y": -9,
      "z": -14,
      "name": "Rock_Volcanic"
    },
    {
      "x": -11,
      "y": -14,
      "z": -13,
      "name": "Rock_Volcanic"
    },
    {
      "x": -11,
      "y": -13,
      "z": -13,
      "name": "Rock_Volcanic_Cracked_Lava"
    },
    {
      "x": -11,
      "y": -12,
      "z": -13,
      "name": "Rock_Volcanic"
    },
    {
      "x": -11,
      "y": -11,
      "z": -13,
      "name": "Rock_Volcanic"
    },
    {
      "x": -11,
      "y": -10,
      "z": -13,
      "name": "Rock_Volcanic"
    },
    {
      "x": -11,
      "y": -9,
      "z": -13,
      "name": "Rock_Volcanic"
    },
    {
      "x": -11,
      "y": -14,
      "z": -12,
      "name": "Rock_Volcanic"
    },
    {
      "x": -11,
      "y": -13,
      "z": -12,
      "name": "Rock_Volcanic"
    },
    {
      "x": -11,
      "y": -12,
      "z": -12,
      "name": "Rock_Volcanic"
    },
    {
      "x": -11,
      "y": -11,
      "z": -12,
      "name": "Rock_Volcanic"
    },
    {
      "x": -11,
      "y": -10,
      "z": -12,
      "name": "Rock_Volcanic"
    },
    {
      "x": -11,
      "y": -9,
      "z": -12,
      "name": "Rock_Volcanic"
    },
    {
      "x": -11,
      "y": -8,
      "z": -12,
      "name": "Rock_Volcanic"
    },
    {
      "x": -11,
      "y": -7,
      "z": -12,
      "name": "Rock_Volcanic"
    },
    {
      "x": -11,
      "y": -14,
      "z": -11,
      "name": "Rock_Volcanic"
    },
    {
      "x": -11,
      "y": -13,
      "z": -11,
      "name": "Rock_Volcanic_Cracked_Lava"
    },
    {
      "x": -11,
      "y": -12,
      "z": -11,
      "name": "Rock_Volcanic"
    },
    {
      "x": -11,
      "y": -11,
      "z": -11,
      "name": "Rock_Volcanic"
    },
    {
      "x": -11,
      "y": -10,
      "z": -11,
      "name": "Rock_Volcanic"
    },
    {
      "x": -11,
      "y": -9,
      "z": -11,
      "name": "Rock_Volcanic"
    },
    {
      "x": -11,
      "y": -8,
      "z": -11,
      "name": "Rock_Volcanic_Cracked_Lava"
    },
    {
      "x": -11,
      "y": -7,
      "z": -11,
      "name": "Rock_Volcanic"
    },
    {
      "x": -11,
      "y": -9,
      "z": -10,
      "name": "Rock_Volcanic"
    },
    {
      "x": -11,
      "y": -8,
      "z": -10,
      "name": "Rock_Volcanic"
    },
    {
      "x": -11,
      "y": -7,
      "z": -10,
      "name": "Rock_Volcanic_Cracked_Lava"
    },
    {
      "x": -11,
      "y": -6,
      "z": -10,
      "name": "Rock_Volcanic"
    },
    {
      "x": -10,
      "y": -16,
      "z": -16,
      "name": "Rock_Volcanic"
    },
    {
      "x": -10,
      "y": -15,
      "z": -16,
      "name": "Rock_Volcanic_Cracked_Lava"
    },
    {
      "x": -10,
      "y": -14,
      "z": -16,
      "name": "Rock_Volcanic"
    },
    {
      "x": -10,
      "y": -13,
      "z": -16,
      "name": "Rock_Volcanic"
    },
    {
      "x": -10,
      "y": -12,
      "z": -16,
      "name": "Rock_Volcanic_Cracked_Lava"
    },
    {
      "x": -10,
      "y": -11,
      "z": -16,
      "name": "Rock_Volcanic"
    },
    {
      "x": -10,
      "y": -10,
      "z": -16,
      "name": "Rock_Volcanic"
    },
    {
      "x": -10,
      "y": -9,
      "z": -16,
      "name": "Rock_Volcanic"
    },
    {
      "x": -10,
      "y": -14,
      "z": -15,
      "name": "Rock_Volcanic_Cracked_Lava"
    },
    {
      "x": -10,
      "y": -13,
      "z": -15,
      "name": "Rock_Volcanic"
    },
    {
      "x": -10,
      "y": -12,
      "z": -15,
      "name": "Rock_Volcanic"
    },
    {
      "x": -10,
      "y": -11,
      "z": -15,
      "name": "Rock_Volcanic"
    },
    {
      "x": -10,
      "y": -10,
      "z": -15,
      "name": "Rock_Volcanic_Cracked_Lava"
    },
    {
      "x": -10,
      "y": -9,
      "z": -15,
      "name": "Rock_Volcanic"
    },
    {
      "x": -10,
      "y": -14,
      "z": -14,
      "name": "Rock_Volcanic_Cracked_Lava"
    },
    {
      "x": -10,
      "y": -13,
      "z": -14,
      "name": "Rock_Volcanic"
    },
    {
      "x": -10,
      "y": -12,
      "z": -14,
      "name": "Rock_Volcanic"
    },
    {
      "x": -10,
      "y": -11,
      "z": -14,
      "name": "Rock_Volcanic"
    },
    {
      "x": -10,
      "y": -10,
      "z": -14,
      "name": "Rock_Volcanic_Cracked_Lava"
    },
    {
      "x": -10,
      "y": -9,
      "z": -14,
      "name": "Rock_Volcanic"
    },
    {
      "x": -10,
      "y": -14,
      "z": -13,
      "name": "Rock_Volcanic"
    },
    {
      "x": -10,
      "y": -13,
      "z": -13,
      "name": "Rock_Volcanic_Cracked_Lava"
    },
    {
      "x": -10,
      "y": -12,
      "z": -13,
      "name": "Rock_Volcanic"
    },
    {
      "x": -10,
      "y": -11,
      "z": -13,
      "name": "Rock_Volcanic"
    },
    {
      "x": -10,
      "y": -10,
      "z": -13,
      "name": "Rock_Volcanic"
    },
    {
      "x": -10,
      "y": -9,
      "z": -13,
      "name": "Rock_Volcanic"
    },
    {
      "x": -10,
      "y": -8,
      "z": -13,
      "name": "Rock_Volcanic"
    },
    {
      "x": -10,
      "y": -13,
      "z": -12,
      "name": "Rock_Volcanic"
    },
    {
      "x": -10,
      "y": -12,
      "z": -12,
      "name": "Rock_Volcanic"
    },
    {
      "x": -10,
      "y": -11,
      "z": -12,
      "name": "Rock_Volcanic"
    },
    {
      "x": -10,
      "y": -10,
      "z": -12,
      "name": "Rock_Volcanic"
    },
    {
      "x": -10,
      "y": -9,
      "z": -12,
      "name": "Rock_Volcanic"
    },
    {
      "x": -10,
      "y": -8,
      "z": -12,
      "name": "Rock_Volcanic"
    },
    {
      "x": -10,
      "y": -7,
      "z": -12,
      "name": "Rock_Volcanic"
    },
    {
      "x": -10,
      "y": -13,
      "z": -11,
      "name": "Rock_Volcanic"
    },
    {
      "x": -10,
      "y": -12,
      "z": -11,
      "name": "Rock_Volcanic"
    },
    {
      "x": -10,
      "y": -11,
      "z": -11,
      "name": "Rock_Volcanic"
    },
    {
      "x": -10,
      "y": -10,
      "z": -11,
      "name": "Rock_Volcanic_Cracked_Lava"
    },
    {
      "x": -10,
      "y": -9,
      "z": -11,
      "name": "Rock_Volcanic"
    },
    {
      "x": -10,
      "y": -8,
      "z": -11,
      "name": "Rock_Volcanic"
    },
    {
      "x": -10,
      "y": -7,
      "z": -11,
      "name": "Rock_Volcanic"
    },
    {
      "x": -10,
      "y": -6,
      "z": -11,
      "name": "Rock_Volcanic"
    },
    {
      "x": -10,
      "y": -14,
      "z": -10,
      "name": "Rock_Volcanic"
    },
    {
      "x": -10,
      "y": -13,
      "z": -10,
      "name": "Rock_Volcanic"
    },
    {
      "x": -10,
      "y": -12,
      "z": -10,
      "name": "Rock_Volcanic"
    },
    {
      "x": -10,
      "y": -11,
      "z": -10,
      "name": "Rock_Volcanic"
    },
    {
      "x": -10,
      "y": -10,
      "z": -10,
      "name": "Rock_Volcanic_Cracked_Lava"
    },
    {
      "x": -10,
      "y": -9,
      "z": -10,
      "name": "Rock_Volcanic_Cracked_Lava"
    },
    {
      "x": -10,
      "y": -8,
      "z": -10,
      "name": "Rock_Volcanic"
    },
    {
      "x": -10,
      "y": -7,
      "z": -10,
      "name": "Rock_Volcanic"
    },
    {
      "x": -10,
      "y": -6,
      "z": -10,
      "name": "Rock_Volcanic"
    },
    {
      "x": -10,
      "y": -10,
      "z": -9,
      "name": "Rock_Volcanic"
    },
    {
      "x": -10,
      "y": -9,
      "z": -9,
      "name": "Rock_Volcanic"
    },
    {
      "x": -10,
      "y": -8,
      "z": -9,
      "name": "Rock_Volcanic_Cracked_Lava"
    },
    {
      "x": -10,
      "y": -7,
      "z": -9,
      "name": "Rock_Volcanic_Cracked_Lava"
    },
    {
      "x": -10,
      "y": -6,
      "z": -9,
      "name": "Rock_Volcanic"
    },
    {
      "x": -10,
      "y": -11,
      "z": -8,
      "name": "Rock_Volcanic"
    },
    {
      "x": -10,
      "y": -10,
      "z": -8,
      "name": "Rock_Volcanic"
    },
    {
      "x": -10,
      "y": -9,
      "z": -8,
      "name": "Rock_Volcanic"
    },
    {
      "x": -10,
      "y": -8,
      "z": -8,
      "name": "Rock_Volcanic_Cracked_Lava"
    },
    {
      "x": -10,
      "y": -7,
      "z": -8,
      "name": "Rock_Volcanic"
    },
    {
      "x": -10,
      "y": -6,
      "z": -8,
      "name": "Rock_Volcanic"
    },
    {
      "x": -10,
      "y": -5,
      "z": -8,
      "name": "Rock_Volcanic"
    },
    {
      "x": -10,
      "y": -13,
      "z": -7,
      "name": "Rock_Volcanic"
    },
    {
      "x": -10,
      "y": -12,
      "z": -7,
      "name": "Rock_Volcanic"
    },
    {
      "x": -10,
      "y": -11,
      "z": -7,
      "name": "Rock_Volcanic"
    },
    {
      "x": -10,
      "y": -10,
      "z": -7,
      "name": "Rock_Volcanic"
    },
    {
      "x": -10,
      "y": -9,
      "z": -7,
      "name": "Rock_Volcanic_Cracked_Lava"
    },
    {
      "x": -10,
      "y": -8,
      "z": -7,
      "name": "Rock_Volcanic"
    },
    {
      "x": -10,
      "y": -7,
      "z": -7,
      "name": "Rock_Volcanic"
    },
    {
      "x": -10,
      "y": -6,
      "z": -7,
      "name": "Rock_Volcanic"
    },
    {
      "x": -10,
      "y": -5,
      "z": -7,
      "name": "Rock_Volcanic"
    },
    {
      "x": -10,
      "y": -4,
      "z": -7,
      "name": "Rock_Volcanic"
    },
    {
      "x": -10,
      "y": -9,
      "z": -6,
      "name": "Rock_Volcanic"
    },
    {
      "x": -10,
      "y": -8,
      "z": -6,
      "name": "Rock_Volcanic_Cracked_Lava"
    },
    {
      "x": -10,
      "y": -7,
      "z": -6,
      "name": "Rock_Volcanic"
    },
    {
      "x": -10,
      "y": -6,
      "z": -6,
      "name": "Rock_Volcanic_Cracked_Lava"
    },
    {
      "x": -10,
      "y": -5,
      "z": -6,
      "name": "Rock_Volcanic"
    },
    {
      "x": -10,
      "y": -4,
      "z": -6,
      "name": "Rock_Volcanic"
    },
    {
      "x": -9,
      "y": -15,
      "z": -16,
      "name": "Rock_Volcanic"
    },
    {
      "x": -9,
      "y": -14,
      "z": -16,
      "name": "Rock_Volcanic"
    },
    {
      "x": -9,
      "y": -13,
      "z": -16,
      "name": "Rock_Volcanic_Cracked_Lava"
    },
    {
      "x": -9,
      "y": -12,
      "z": -16,
      "name": "Rock_Volcanic"
    },
    {
      "x": -9,
      "y": -11,
      "z": -16,
      "name": "Rock_Volcanic"
    },
    {
      "x": -9,
      "y": -10,
      "z": -16,
      "name": "Rock_Volcanic"
    },
    {
      "x": -9,
      "y": -9,
      "z": -16,
      "name": "Rock_Volcanic_Cracked_Lava"
    },
    {
      "x": -9,
      "y": -14,
      "z": -15,
      "name": "Rock_Volcanic"
    },
    {
      "x": -9,
      "y": -13,
      "z": -15,
      "name": "Rock_Volcanic"
    },
    {
      "x": -9,
      "y": -12,
      "z": -15,
      "name": "Rock_Volcanic"
    },
    {
      "x": -9,
      "y": -11,
      "z": -15,
      "name": "Rock_Volcanic_Cracked_Lava"
    },
    {
      "x": -9,
      "y": -10,
      "z": -15,
      "name": "Rock_Volcanic_Cracked_Lava"
    },
    {
      "x": -9,
      "y": -9,
      "z": -15,
      "name": "Rock_Volcanic"
    },
    {
      "x": -9,
      "y": -8,
      "z": -15,
      "name": "Rock_Volcanic_Cracked_Lava"
    },
    {
      "x": -9,
      "y": -14,
      "z": -14,
      "name": "Rock_Volcanic_Cracked_Lava"
    },
    {
      "x": -9,
      "y": -13,
      "z": -14,
      "name": "Rock_Volcanic"
    },
    {
      "x": -9,
      "y": -12,
      "z": -14,
      "name": "Rock_Volcanic_Cracked_Lava"
    },
    {
      "x": -9,
      "y": -11,
      "z": -14,
      "name": "Rock_Volcanic"
    },
    {
      "x": -9,
      "y": -10,
      "z": -14,
      "name": "Rock_Volcanic"
    },
    {
      "x": -9,
      "y": -9,
      "z": -14,
      "name": "Rock_Volcanic"
    },
    {
      "x": -9,
      "y": -8,
      "z": -14,
      "name": "Rock_Volcanic"
    },
    {
      "x": -9,
      "y": -7,
      "z": -14,
      "name": "Rock_Volcanic"
    },
    {
      "x": -9,
      "y": -13,
      "z": -13,
      "name": "Rock_Volcanic"
    },
    {
      "x": -9,
      "y": -12,
      "z": -13,
      "name": "Rock_Volcanic"
    },
    {
      "x": -9,
      "y": -11,
      "z": -13,
      "name": "Rock_Volcanic"
    },
    {
      "x": -9,
      "y": -10,
      "z": -13,
      "name": "Rock_Volcanic_Cracked_Lava"
    },
    {
      "x": -9,
      "y": -9,
      "z": -13,
      "name": "Rock_Volcanic"
    },
    {
      "x": -9,
      "y": -8,
      "z": -13,
      "name": "Rock_Volcanic_Cracked_Lava"
    },
    {
      "x": -9,
      "y": -7,
      "z": -13,
      "name": "Rock_Volcanic"
    },
    {
      "x": -9,
      "y": -13,
      "z": -12,
      "name": "Rock_Volcanic"
    },
    {
      "x": -9,
      "y": -12,
      "z": -12,
      "name": "Rock_Volcanic"
    },
    {
      "x": -9,
      "y": -11,
      "z": -12,
      "name": "Rock_Volcanic_Cracked_Lava"
    },
    {
      "x": -9,
      "y": -10,
      "z": -12,
      "name": "Rock_Volcanic"
    },
    {
      "x": -9,
      "y": -9,
      "z": -12,
      "name": "Rock_Volcanic"
    },
    {
      "x": -9,
      "y": -8,
      "z": -12,
      "name": "Rock_Volcanic"
    },
    {
      "x": -9,
      "y": -7,
      "z": -12,
      "name": "Rock_Volcanic"
    },
    {
      "x": -9,
      "y": -6,
      "z": -12,
      "name": "Rock_Volcanic"
    },
    {
      "x": -9,
      "y": -13,
      "z": -11,
      "name": "Rock_Volcanic"
    },
    {
      "x": -9,
      "y": -12,
      "z": -11,
      "name": "Rock_Volcanic"
    },
    {
      "x": -9,
      "y": -11,
      "z": -11,
      "name": "Rock_Volcanic_Cracked_Lava"
    },
    {
      "x": -9,
      "y": -10,
      "z": -11,
      "name": "Rock_Volcanic"
    },
    {
      "x": -9,
      "y": -9,
      "z": -11,
      "name": "Rock_Volcanic_Cracked_Lava"
    },
    {
      "x": -9,
      "y": -8,
      "z": -11,
      "name": "Rock_Volcanic"
    },
    {
      "x": -9,
      "y": -7,
      "z": -11,
      "name": "Rock_Volcanic"
    },
    {
      "x": -9,
      "y": -6,
      "z": -11,
      "name": "Rock_Volcanic"
    },
    {
      "x": -9,
      "y": -13,
      "z": -10,
      "name": "Rock_Volcanic_Cracked_Lava"
    },
    {
      "x": -9,
      "y": -12,
      "z": -10,
      "name": "Rock_Volcanic"
    },
    {
      "x": -9,
      "y": -11,
      "z": -10,
      "name": "Rock_Volcanic_Cracked_Lava"
    },
    {
      "x": -9,
      "y": -10,
      "z": -10,
      "name": "Rock_Volcanic"
    },
    {
      "x": -9,
      "y": -9,
      "z": -10,
      "name": "Rock_Volcanic"
    },
    {
      "x": -9,
      "y": -8,
      "z": -10,
      "name": "Rock_Volcanic"
    },
    {
      "x": -9,
      "y": -7,
      "z": -10,
      "name": "Rock_Volcanic_Cracked_Lava"
    },
    {
      "x": -9,
      "y": -6,
      "z": -10,
      "name": "Rock_Volcanic"
    },
    {
      "x": -9,
      "y": -12,
      "z": -9,
      "name": "Rock_Volcanic_Cracked_Lava"
    },
    {
      "x": -9,
      "y": -11,
      "z": -9,
      "name": "Rock_Volcanic"
    },
    {
      "x": -9,
      "y": -10,
      "z": -9,
      "name": "Rock_Volcanic"
    },
    {
      "x": -9,
      "y": -9,
      "z": -9,
      "name": "Rock_Volcanic_Cracked_Lava"
    },
    {
      "x": -9,
      "y": -8,
      "z": -9,
      "name": "Rock_Volcanic_Cracked_Lava"
    },
    {
      "x": -9,
      "y": -7,
      "z": -9,
      "name": "Rock_Volcanic_Cracked_Lava"
    },
    {
      "x": -9,
      "y": -6,
      "z": -9,
      "name": "Rock_Volcanic"
    },
    {
      "x": -9,
      "y": -5,
      "z": -9,
      "name": "Rock_Volcanic"
    },
    {
      "x": -9,
      "y": -13,
      "z": -8,
      "name": "Rock_Volcanic"
    },
    {
      "x": -9,
      "y": -12,
      "z": -8,
      "name": "Rock_Volcanic"
    },
    {
      "x": -9,
      "y": -11,
      "z": -8,
      "name": "Rock_Volcanic"
    },
    {
      "x": -9,
      "y": -10,
      "z": -8,
      "name": "Rock_Volcanic"
    },
    {
      "x": -9,
      "y": -9,
      "z": -8,
      "name": "Rock_Volcanic"
    },
    {
      "x": -9,
      "y": -8,
      "z": -8,
      "name": "Rock_Volcanic"
    },
    {
      "x": -9,
      "y": -7,
      "z": -8,
      "name": "Rock_Volcanic"
    },
    {
      "x": -9,
      "y": -6,
      "z": -8,
      "name": "Rock_Volcanic"
    },
    {
      "x": -9,
      "y": -5,
      "z": -8,
      "name": "Rock_Volcanic"
    },
    {
      "x": -9,
      "y": -4,
      "z": -8,
      "name": "Rock_Volcanic_Cracked_Lava"
    },
    {
      "x": -9,
      "y": -13,
      "z": -7,
      "name": "Rock_Volcanic"
    },
    {
      "x": -9,
      "y": -12,
      "z": -7,
      "name": "Rock_Volcanic"
    },
    {
      "x": -9,
      "y": -11,
      "z": -7,
      "name": "Rock_Volcanic"
    },
    {
      "x": -9,
      "y": -10,
      "z": -7,
      "name": "Rock_Volcanic"
    },
    {
      "x": -9,
      "y": -9,
      "z": -7,
      "name": "Rock_Volcanic"
    },
    {
      "x": -9,
      "y": -8,
      "z": -7,
      "name": "Rock_Volcanic"
    },
    {
      "x": -9,
      "y": -7,
      "z": -7,
      "name": "Rock_Volcanic"
    },
    {
      "x": -9,
      "y": -6,
      "z": -7,
      "name": "Rock_Volcanic"
    },
    {
      "x": -9,
      "y": -5,
      "z": -7,
      "name": "Rock_Volcanic"
    },
    {
      "x": -9,
      "y": -4,
      "z": -7,
      "name": "Rock_Volcanic"
    },
    {
      "x": -9,
      "y": -11,
      "z": -6,
      "name": "Rock_Volcanic"
    },
    {
      "x": -9,
      "y": -10,
      "z": -6,
      "name": "Rock_Volcanic"
    },
    {
      "x": -9,
      "y": -9,
      "z": -6,
      "name": "Rock_Volcanic"
    },
    {
      "x": -9,
      "y": -8,
      "z": -6,
      "name": "Rock_Volcanic_Cracked_Lava"
    },
    {
      "x": -9,
      "y": -7,
      "z": -6,
      "name": "Rock_Volcanic"
    },
    {
      "x": -9,
      "y": -6,
      "z": -6,
      "name": "Rock_Volcanic"
    },
    {
      "x": -9,
      "y": -5,
      "z": -6,
      "name": "Rock_Volcanic_Cracked_Lava"
    },
    {
      "x": -9,
      "y": -4,
      "z": -6,
      "name": "Rock_Volcanic"
    },
    {
      "x": -9,
      "y": -3,
      "z": -6,
      "name": "Rock_Volcanic"
    },
    {
      "x": -9,
      "y": -8,
      "z": -5,
      "name": "Rock_Volcanic"
    },
    {
      "x": -9,
      "y": -7,
      "z": -5,
      "name": "Rock_Volcanic"
    },
    {
      "x": -9,
      "y": -6,
      "z": -5,
      "name": "Rock_Volcanic"
    },
    {
      "x": -9,
      "y": -5,
      "z": -5,
      "name": "Rock_Volcanic_Cracked_Lava"
    },
    {
      "x": -9,
      "y": -4,
      "z": -5,
      "name": "Rock_Volcanic"
    },
    {
      "x": -8,
      "y": -15,
      "z": -17,
      "name": "Rock_Volcanic"
    },
    {
      "x": -8,
      "y": -14,
      "z": -17,
      "name": "Rock_Volcanic_Cracked_Lava"
    },
    {
      "x": -8,
      "y": -13,
      "z": -17,
      "name": "Rock_Volcanic"
    },
    {
      "x": -8,
      "y": -12,
      "z": -17,
      "name": "Rock_Volcanic"
    },
    {
      "x": -8,
      "y": -11,
      "z": -17,
      "name": "Rock_Volcanic_Cracked_Lava"
    },
    {
      "x": -8,
      "y": -10,
      "z": -17,
      "name": "Rock_Volcanic"
    },
    {
      "x": -8,
      "y": -9,
      "z": -17,
      "name": "Rock_Volcanic"
    },
    {
      "x": -8,
      "y": -14,
      "z": -16,
      "name": "Rock_Volcanic"
    },
    {
      "x": -8,
      "y": -13,
      "z": -16,
      "name": "Rock_Volcanic"
    },
    {
      "x": -8,
      "y": -12,
      "z": -16,
      "name": "Rock_Volcanic"
    },
    {
      "x": -8,
      "y": -11,
      "z": -16,
      "name": "Rock_Volcanic"
    },
    {
      "x": -8,
      "y": -10,
      "z": -16,
      "name": "Rock_Volcanic"
    },
    {
      "x": -8,
      "y": -9,
      "z": -16,
      "name": "Rock_Volcanic_Cracked_Lava"
    },
    {
      "x": -8,
      "y": -8,
      "z": -16,
      "name": "Rock_Volcanic"
    },
    {
      "x": -8,
      "y": -14,
      "z": -15,
      "name": "Rock_Volcanic"
    },
    {
      "x": -8,
      "y": -13,
      "z": -15,
      "name": "Rock_Volcanic"
    },
    {
      "x": -8,
      "y": -12,
      "z": -15,
      "name": "Rock_Volcanic"
    },
    {
      "x": -8,
      "y": -11,
      "z": -15,
      "name": "Rock_Volcanic"
    },
    {
      "x": -8,
      "y": -10,
      "z": -15,
      "name": "Rock_Volcanic"
    },
    {
      "x": -8,
      "y": -9,
      "z": -15,
      "name": "Rock_Volcanic_Cracked_Lava"
    },
    {
      "x": -8,
      "y": -8,
      "z": -15,
      "name": "Rock_Volcanic"
    },
    {
      "x": -8,
      "y": -14,
      "z": -14,
      "name": "Rock_Volcanic"
    },
    {
      "x": -8,
      "y": -13,
      "z": -14,
      "name": "Rock_Volcanic_Cracked_Lava"
    },
    {
      "x": -8,
      "y": -12,
      "z": -14,
      "name": "Rock_Volcanic"
    },
    {
      "x": -8,
      "y": -11,
      "z": -14,
      "name": "Rock_Volcanic"
    },
    {
      "x": -8,
      "y": -10,
      "z": -14,
      "name": "Rock_Volcanic"
    },
    {
      "x": -8,
      "y": -9,
      "z": -14,
      "name": "Rock_Volcanic_Cracked_Lava"
    },
    {
      "x": -8,
      "y": -8,
      "z": -14,
      "name": "Rock_Volcanic"
    },
    {
      "x": -8,
      "y": -7,
      "z": -14,
      "name": "Rock_Volcanic"
    },
    {
      "x": -8,
      "y": -13,
      "z": -13,
      "name": "Rock_Volcanic"
    },
    {
      "x": -8,
      "y": -12,
      "z": -13,
      "name": "Rock_Volcanic"
    },
    {
      "x": -8,
      "y": -11,
      "z": -13,
      "name": "Rock_Volcanic"
    },
    {
      "x": -8,
      "y": -10,
      "z": -13,
      "name": "Rock_Volcanic"
    },
    {
      "x": -8,
      "y": -9,
      "z": -13,
      "name": "Rock_Volcanic"
    },
    {
      "x": -8,
      "y": -8,
      "z": -13,
      "name": "Rock_Volcanic"
    },
    {
      "x": -8,
      "y": -7,
      "z": -13,
      "name": "Rock_Volcanic"
    },
    {
      "x": -8,
      "y": -13,
      "z": -12,
      "name": "Rock_Volcanic"
    },
    {
      "x": -8,
      "y": -12,
      "z": -12,
      "name": "Rock_Volcanic"
    },
    {
      "x": -8,
      "y": -11,
      "z": -12,
      "name": "Rock_Volcanic_Cracked_Lava"
    },
    {
      "x": -8,
      "y": -10,
      "z": -12,
      "name": "Rock_Volcanic"
    },
    {
      "x": -8,
      "y": -9,
      "z": -12,
      "name": "Rock_Volcanic_Cracked_Lava"
    },
    {
      "x": -8,
      "y": -8,
      "z": -12,
      "name": "Rock_Volcanic"
    },
    {
      "x": -8,
      "y": -7,
      "z": -12,
      "name": "Rock_Volcanic"
    },
    {
      "x": -8,
      "y": -6,
      "z": -12,
      "name": "Rock_Volcanic_Cracked_Lava"
    },
    {
      "x": -8,
      "y": -5,
      "z": -12,
      "name": "Rock_Volcanic_Cracked_Lava"
    },
    {
      "x": -8,
      "y": -13,
      "z": -11,
      "name": "Rock_Volcanic"
    },
    {
      "x": -8,
      "y": -12,
      "z": -11,
      "name": "Rock_Volcanic"
    },
    {
      "x": -8,
      "y": -11,
      "z": -11,
      "name": "Rock_Volcanic"
    },
    {
      "x": -8,
      "y": -10,
      "z": -11,
      "name": "Rock_Volcanic"
    },
    {
      "x": -8,
      "y": -9,
      "z": -11,
      "name": "Rock_Volcanic"
    },
    {
      "x": -8,
      "y": -8,
      "z": -11,
      "name": "Rock_Volcanic"
    },
    {
      "x": -8,
      "y": -7,
      "z": -11,
      "name": "Rock_Volcanic_Cracked_Lava"
    },
    {
      "x": -8,
      "y": -6,
      "z": -11,
      "name": "Rock_Volcanic"
    },
    {
      "x": -8,
      "y": -5,
      "z": -11,
      "name": "Rock_Volcanic_Cracked_Lava"
    },
    {
      "x": -8,
      "y": -12,
      "z": -10,
      "name": "Rock_Volcanic_Cracked_Lava"
    },
    {
      "x": -8,
      "y": -11,
      "z": -10,
      "name": "Rock_Volcanic"
    },
    {
      "x": -8,
      "y": -10,
      "z": -10,
      "name": "Rock_Volcanic_Cracked_Lava"
    },
    {
      "x": -8,
      "y": -9,
      "z": -10,
      "name": "Rock_Volcanic_Cracked_Lava"
    },
    {
      "x": -8,
      "y": -8,
      "z": -10,
      "name": "Rock_Volcanic"
    },
    {
      "x": -8,
      "y": -7,
      "z": -10,
      "name": "Rock_Volcanic"
    },
    {
      "x": -8,
      "y": -6,
      "z": -10,
      "name": "Rock_Volcanic"
    },
    {
      "x": -8,
      "y": -5,
      "z": -10,
      "name": "Rock_Volcanic_Cracked_Lava"
    },
    {
      "x": -8,
      "y": -13,
      "z": -9,
      "name": "Rock_Volcanic_Cracked_Lava"
    },
    {
      "x": -8,
      "y": -12,
      "z": -9,
      "name": "Rock_Volcanic"
    },
    {
      "x": -8,
      "y": -11,
      "z": -9,
      "name": "Rock_Volcanic"
    },
    {
      "x": -8,
      "y": -10,
      "z": -9,
      "name": "Rock_Volcanic"
    },
    {
      "x": -8,
      "y": -9,
      "z": -9,
      "name": "Rock_Volcanic"
    },
    {
      "x": -8,
      "y": -8,
      "z": -9,
      "name": "Rock_Volcanic_Cracked_Lava"
    },
    {
      "x": -8,
      "y": -7,
      "z": -9,
      "name": "Rock_Volcanic"
    },
    {
      "x": -8,
      "y": -6,
      "z": -9,
      "name": "Rock_Volcanic"
    },
    {
      "x": -8,
      "y": -5,
      "z": -9,
      "name": "Rock_Volcanic_Cracked_Lava"
    },
    {
      "x": -8,
      "y": -4,
      "z": -9,
      "name": "Rock_Volcanic_Cracked_Lava"
    },
    {
      "x": -8,
      "y": -12,
      "z": -8,
      "name": "Rock_Volcanic"
    },
    {
      "x": -8,
      "y": -11,
      "z": -8,
      "name": "Rock_Volcanic"
    },
    {
      "x": -8,
      "y": -10,
      "z": -8,
      "name": "Rock_Volcanic"
    },
    {
      "x": -8,
      "y": -9,
      "z": -8,
      "name": "Rock_Volcanic"
    },
    {
      "x": -8,
      "y": -8,
      "z": -8,
      "name": "Rock_Volcanic"
    },
    {
      "x": -8,
      "y": -7,
      "z": -8,
      "name": "Rock_Volcanic"
    },
    {
      "x": -8,
      "y": -6,
      "z": -8,
      "name": "Rock_Volcanic"
    },
    {
      "x": -8,
      "y": -5,
      "z": -8,
      "name": "Rock_Volcanic"
    },
    {
      "x": -8,
      "y": -4,
      "z": -8,
      "name": "Rock_Volcanic"
    },
    {
      "x": -8,
      "y": -3,
      "z": -8,
      "name": "Rock_Volcanic"
    },
    {
      "x": -8,
      "y": -11,
      "z": -7,
      "name": "Rock_Volcanic"
    },
    {
      "x": -8,
      "y": -10,
      "z": -7,
      "name": "Rock_Volcanic"
    },
    {
      "x": -8,
      "y": -9,
      "z": -7,
      "name": "Rock_Volcanic"
    },
    {
      "x": -8,
      "y": -8,
      "z": -7,
      "name": "Rock_Volcanic"
    },
    {
      "x": -8,
      "y": -7,
      "z": -7,
      "name": "Rock_Volcanic"
    },
    {
      "x": -8,
      "y": -6,
      "z": -7,
      "name": "Rock_Volcanic"
    },
    {
      "x": -8,
      "y": -5,
      "z": -7,
      "name": "Rock_Volcanic"
    },
    {
      "x": -8,
      "y": -4,
      "z": -7,
      "name": "Rock_Volcanic"
    },
    {
      "x": -8,
      "y": -3,
      "z": -7,
      "name": "Rock_Volcanic"
    },
    {
      "x": -8,
      "y": -11,
      "z": -6,
      "name": "Rock_Volcanic"
    },
    {
      "x": -8,
      "y": -10,
      "z": -6,
      "name": "Rock_Volcanic"
    },
    {
      "x": -8,
      "y": -9,
      "z": -6,
      "name": "Rock_Volcanic"
    },
    {
      "x": -8,
      "y": -8,
      "z": -6,
      "name": "Rock_Volcanic"
    },
    {
      "x": -8,
      "y": -7,
      "z": -6,
      "name": "Rock_Volcanic"
    },
    {
      "x": -8,
      "y": -6,
      "z": -6,
      "name": "Rock_Volcanic"
    },
    {
      "x": -8,
      "y": -5,
      "z": -6,
      "name": "Rock_Volcanic"
    },
    {
      "x": -8,
      "y": -4,
      "z": -6,
      "name": "Rock_Volcanic"
    },
    {
      "x": -8,
      "y": -3,
      "z": -6,
      "name": "Rock_Volcanic"
    },
    {
      "x": -8,
      "y": -11,
      "z": -5,
      "name": "Rock_Volcanic"
    },
    {
      "x": -8,
      "y": -10,
      "z": -5,
      "name": "Rock_Volcanic"
    },
    {
      "x": -8,
      "y": -9,
      "z": -5,
      "name": "Rock_Volcanic"
    },
    {
      "x": -8,
      "y": -8,
      "z": -5,
      "name": "Rock_Volcanic"
    },
    {
      "x": -8,
      "y": -7,
      "z": -5,
      "name": "Rock_Volcanic"
    },
    {
      "x": -8,
      "y": -6,
      "z": -5,
      "name": "Rock_Volcanic"
    },
    {
      "x": -8,
      "y": -5,
      "z": -5,
      "name": "Rock_Volcanic_Cracked_Lava"
    },
    {
      "x": -8,
      "y": -4,
      "z": -5,
      "name": "Rock_Volcanic"
    },
    {
      "x": -8,
      "y": -3,
      "z": -5,
      "name": "Rock_Volcanic"
    },
    {
      "x": -7,
      "y": -14,
      "z": -16,
      "name": "Rock_Volcanic"
    },
    {
      "x": -7,
      "y": -13,
      "z": -16,
      "name": "Rock_Volcanic"
    },
    {
      "x": -7,
      "y": -14,
      "z": -15,
      "name": "Rock_Volcanic_Cracked_Lava"
    },
    {
      "x": -7,
      "y": -13,
      "z": -15,
      "name": "Rock_Volcanic"
    },
    {
      "x": -7,
      "y": -12,
      "z": -15,
      "name": "Rock_Volcanic_Cracked_Lava"
    },
    {
      "x": -7,
      "y": -11,
      "z": -15,
      "name": "Rock_Volcanic"
    },
    {
      "x": -7,
      "y": -10,
      "z": -15,
      "name": "Rock_Volcanic"
    },
    {
      "x": -7,
      "y": -9,
      "z": -15,
      "name": "Rock_Volcanic"
    },
    {
      "x": -7,
      "y": -7,
      "z": -15,
      "name": "Rock_Volcanic"
    },
    {
      "x": -7,
      "y": -13,
      "z": -14,
      "name": "Rock_Volcanic"
    },
    {
      "x": -7,
      "y": -12,
      "z": -14,
      "name": "Rock_Volcanic"
    },
    {
      "x": -7,
      "y": -11,
      "z": -14,
      "name": "Rock_Volcanic"
    },
    {
      "x": -7,
      "y": -10,
      "z": -14,
      "name": "Rock_Volcanic"
    },
    {
      "x": -7,
      "y": -9,
      "z": -14,
      "name": "Rock_Volcanic"
    },
    {
      "x": -7,
      "y": -8,
      "z": -14,
      "name": "Rock_Volcanic"
    },
    {
      "x": -7,
      "y": -7,
      "z": -14,
      "name": "Rock_Volcanic"
    },
    {
      "x": -7,
      "y": -6,
      "z": -14,
      "name": "Rock_Volcanic"
    },
    {
      "x": -7,
      "y": -13,
      "z": -13,
      "name": "Rock_Volcanic"
    },
    {
      "x": -7,
      "y": -12,
      "z": -13,
      "name": "Rock_Volcanic"
    },
    {
      "x": -7,
      "y": -11,
      "z": -13,
      "name": "Rock_Volcanic"
    },
    {
      "x": -7,
      "y": -10,
      "z": -13,
      "name": "Rock_Volcanic"
    },
    {
      "x": -7,
      "y": -9,
      "z": -13,
      "name": "Rock_Volcanic"
    },
    {
      "x": -7,
      "y": -8,
      "z": -13,
      "name": "Rock_Volcanic"
    },
    {
      "x": -7,
      "y": -7,
      "z": -13,
      "name": "Rock_Volcanic"
    },
    {
      "x": -7,
      "y": -6,
      "z": -13,
      "name": "Rock_Volcanic"
    },
    {
      "x": -7,
      "y": -5,
      "z": -13,
      "name": "Rock_Volcanic"
    },
    {
      "x": -7,
      "y": -13,
      "z": -12,
      "name": "Rock_Volcanic_Cracked_Lava"
    },
    {
      "x": -7,
      "y": -12,
      "z": -12,
      "name": "Rock_Volcanic"
    },
    {
      "x": -7,
      "y": -11,
      "z": -12,
      "name": "Rock_Volcanic"
    },
    {
      "x": -7,
      "y": -10,
      "z": -12,
      "name": "Rock_Volcanic"
    },
    {
      "x": -7,
      "y": -9,
      "z": -12,
      "name": "Rock_Volcanic"
    },
    {
      "x": -7,
      "y": -8,
      "z": -12,
      "name": "Rock_Volcanic"
    },
    {
      "x": -7,
      "y": -7,
      "z": -12,
      "name": "Rock_Volcanic"
    },
    {
      "x": -7,
      "y": -6,
      "z": -12,
      "name": "Rock_Volcanic_Cracked_Lava"
    },
    {
      "x": -7,
      "y": -5,
      "z": -12,
      "name": "Rock_Volcanic"
    },
    {
      "x": -7,
      "y": -12,
      "z": -11,
      "name": "Rock_Volcanic"
    },
    {
      "x": -7,
      "y": -11,
      "z": -11,
      "name": "Rock_Volcanic"
    },
    {
      "x": -7,
      "y": -10,
      "z": -11,
      "name": "Rock_Volcanic"
    },
    {
      "x": -7,
      "y": -9,
      "z": -11,
      "name": "Rock_Volcanic"
    },
    {
      "x": -7,
      "y": -8,
      "z": -11,
      "name": "Rock_Volcanic_Cracked_Lava"
    },
    {
      "x": -7,
      "y": -7,
      "z": -11,
      "name": "Rock_Volcanic"
    },
    {
      "x": -7,
      "y": -6,
      "z": -11,
      "name": "Rock_Volcanic"
    },
    {
      "x": -7,
      "y": -5,
      "z": -11,
      "name": "Rock_Volcanic"
    },
    {
      "x": -7,
      "y": -4,
      "z": -11,
      "name": "Rock_Volcanic_Cracked_Lava"
    },
    {
      "x": -7,
      "y": -13,
      "z": -10,
      "name": "Rock_Volcanic"
    },
    {
      "x": -7,
      "y": -12,
      "z": -10,
      "name": "Rock_Volcanic"
    },
    {
      "x": -7,
      "y": -11,
      "z": -10,
      "name": "Rock_Volcanic"
    },
    {
      "x": -7,
      "y": -10,
      "z": -10,
      "name": "Rock_Volcanic"
    },
    {
      "x": -7,
      "y": -9,
      "z": -10,
      "name": "Rock_Volcanic"
    },
    {
      "x": -7,
      "y": -8,
      "z": -10,
      "name": "Rock_Volcanic"
    },
    {
      "x": -7,
      "y": -7,
      "z": -10,
      "name": "Rock_Volcanic"
    },
    {
      "x": -7,
      "y": -6,
      "z": -10,
      "name": "Rock_Volcanic_Cracked_Lava"
    },
    {
      "x": -7,
      "y": -5,
      "z": -10,
      "name": "Rock_Volcanic"
    },
    {
      "x": -7,
      "y": -4,
      "z": -10,
      "name": "Rock_Volcanic"
    },
    {
      "x": -7,
      "y": -12,
      "z": -9,
      "name": "Rock_Volcanic"
    },
    {
      "x": -7,
      "y": -11,
      "z": -9,
      "name": "Rock_Volcanic"
    },
    {
      "x": -7,
      "y": -10,
      "z": -9,
      "name": "Rock_Volcanic_Cracked_Lava"
    },
    {
      "x": -7,
      "y": -9,
      "z": -9,
      "name": "Rock_Volcanic"
    },
    {
      "x": -7,
      "y": -8,
      "z": -9,
      "name": "Rock_Volcanic"
    },
    {
      "x": -7,
      "y": -7,
      "z": -9,
      "name": "Rock_Volcanic_Cracked_Lava"
    },
    {
      "x": -7,
      "y": -6,
      "z": -9,
      "name": "Rock_Volcanic_Cracked_Lava"
    },
    {
      "x": -7,
      "y": -5,
      "z": -9,
      "name": "Rock_Volcanic"
    },
    {
      "x": -7,
      "y": -4,
      "z": -9,
      "name": "Rock_Volcanic"
    },
    {
      "x": -7,
      "y": -3,
      "z": -9,
      "name": "Rock_Volcanic"
    },
    {
      "x": -7,
      "y": -11,
      "z": -8,
      "name": "Rock_Volcanic"
    },
    {
      "x": -7,
      "y": -10,
      "z": -8,
      "name": "Rock_Volcanic"
    },
    {
      "x": -7,
      "y": -9,
      "z": -8,
      "name": "Rock_Volcanic"
    },
    {
      "x": -7,
      "y": -8,
      "z": -8,
      "name": "Rock_Volcanic"
    },
    {
      "x": -7,
      "y": -7,
      "z": -8,
      "name": "Rock_Volcanic"
    },
    {
      "x": -7,
      "y": -6,
      "z": -8,
      "name": "Rock_Volcanic"
    },
    {
      "x": -7,
      "y": -5,
      "z": -8,
      "name": "Rock_Volcanic"
    },
    {
      "x": -7,
      "y": -4,
      "z": -8,
      "name": "Rock_Volcanic"
    },
    {
      "x": -7,
      "y": -3,
      "z": -8,
      "name": "Rock_Volcanic"
    },
    {
      "x": -7,
      "y": -11,
      "z": -7,
      "name": "Rock_Volcanic"
    },
    {
      "x": -7,
      "y": -10,
      "z": -7,
      "name": "Rock_Volcanic"
    },
    {
      "x": -7,
      "y": -9,
      "z": -7,
      "name": "Rock_Volcanic"
    },
    {
      "x": -7,
      "y": -8,
      "z": -7,
      "name": "Rock_Volcanic"
    },
    {
      "x": -7,
      "y": -7,
      "z": -7,
      "name": "Rock_Volcanic"
    },
    {
      "x": -7,
      "y": -6,
      "z": -7,
      "name": "Rock_Volcanic"
    },
    {
      "x": -7,
      "y": -5,
      "z": -7,
      "name": "Rock_Volcanic_Cracked_Lava"
    },
    {
      "x": -7,
      "y": -4,
      "z": -7,
      "name": "Rock_Volcanic"
    },
    {
      "x": -7,
      "y": -3,
      "z": -7,
      "name": "Rock_Volcanic"
    },
    {
      "x": -7,
      "y": -10,
      "z": -6,
      "name": "Rock_Volcanic"
    },
    {
      "x": -7,
      "y": -9,
      "z": -6,
      "name": "Rock_Volcanic_Cracked_Lava"
    },
    {
      "x": -7,
      "y": -8,
      "z": -6,
      "name": "Rock_Volcanic"
    },
    {
      "x": -7,
      "y": -7,
      "z": -6,
      "name": "Rock_Volcanic"
    },
    {
      "x": -7,
      "y": -6,
      "z": -6,
      "name": "Rock_Volcanic"
    },
    {
      "x": -7,
      "y": -5,
      "z": -6,
      "name": "Rock_Volcanic_Cracked_Lava"
    },
    {
      "x": -7,
      "y": -4,
      "z": -6,
      "name": "Rock_Volcanic"
    },
    {
      "x": -7,
      "y": -3,
      "z": -6,
      "name": "Rock_Volcanic"
    },
    {
      "x": -7,
      "y": -2,
      "z": -5,
      "name": "Rock_Volcanic"
    },
    {
      "x": -7,
      "y": -1,
      "z": -5,
      "name": "Rock_Volcanic"
    },
    {
      "x": -7,
      "y": -2,
      "z": -4,
      "name": "Rock_Volcanic"
    },
    {
      "x": -7,
      "y": -1,
      "z": -4,
      "name": "Rock_Volcanic"
    },
    {
      "x": -7,
      "y": -2,
      "z": -3,
      "name": "Rock_Volcanic"
    },
    {
      "x": -7,
      "y": -1,
      "z": -3,
      "name": "Rock_Volcanic"
    },
    {
      "x": -7,
      "y": -2,
      "z": -2,
      "name": "Rock_Volcanic"
    },
    {
      "x": -7,
      "y": -1,
      "z": -2,
      "name": "Rock_Volcanic"
    },
    {
      "x": -7,
      "y": -4,
      "z": -1,
      "name": "Rock_Volcanic_Cracked_Lava"
    },
    {
      "x": -7,
      "y": -3,
      "z": -1,
      "name": "Rock_Volcanic"
    },
    {
      "x": -7,
      "y": -2,
      "z": -1,
      "name": "Rock_Volcanic"
    },
    {
      "x": -7,
      "y": -1,
      "z": -1,
      "name": "Rock_Volcanic"
    },
    {
      "x": -7,
      "y": 0,
      "z": -1,
      "name": "Rock_Volcanic"
    },
    {
      "x": -7,
      "y": -6,
      "z": 0,
      "name": "Rock_Volcanic"
    },
    {
      "x": -7,
      "y": -5,
      "z": 0,
      "name": "Rock_Volcanic_Cracked_Lava"
    },
    {
      "x": -7,
      "y": -4,
      "z": 0,
      "name": "Rock_Volcanic"
    },
    {
      "x": -7,
      "y": -3,
      "z": 0,
      "name": "Rock_Volcanic"
    },
    {
      "x": -7,
      "y": -2,
      "z": 0,
      "name": "Rock_Volcanic"
    },
    {
      "x": -7,
      "y": -1,
      "z": 0,
      "name": "Rock_Volcanic"
    },
    {
      "x": -6,
      "y": -9,
      "z": -15,
      "name": "Rock_Volcanic"
    },
    {
      "x": -6,
      "y": -8,
      "z": -15,
      "name": "Rock_Volcanic_Cracked_Lava"
    },
    {
      "x": -6,
      "y": -7,
      "z": -15,
      "name": "Rock_Volcanic"
    },
    {
      "x": -6,
      "y": -10,
      "z": -14,
      "name": "Rock_Volcanic"
    },
    {
      "x": -6,
      "y": -9,
      "z": -14,
      "name": "Rock_Volcanic"
    },
    {
      "x": -6,
      "y": -8,
      "z": -14,
      "name": "Rock_Volcanic"
    },
    {
      "x": -6,
      "y": -7,
      "z": -14,
      "name": "Rock_Volcanic"
    },
    {
      "x": -6,
      "y": -6,
      "z": -14,
      "name": "Rock_Volcanic"
    },
    {
      "x": -6,
      "y": -5,
      "z": -14,
      "name": "Rock_Volcanic"
    },
    {
      "x": -6,
      "y": -10,
      "z": -13,
      "name": "Rock_Volcanic"
    },
    {
      "x": -6,
      "y": -9,
      "z": -13,
      "name": "Rock_Volcanic"
    },
    {
      "x": -6,
      "y": -8,
      "z": -13,
      "name": "Rock_Volcanic"
    },
    {
      "x": -6,
      "y": -7,
      "z": -13,
      "name": "Rock_Volcanic"
    },
    {
      "x": -6,
      "y": -6,
      "z": -13,
      "name": "Rock_Volcanic"
    },
    {
      "x": -6,
      "y": -5,
      "z": -13,
      "name": "Rock_Volcanic"
    },
    {
      "x": -6,
      "y": -11,
      "z": -12,
      "name": "Rock_Volcanic_Cracked_Lava"
    },
    {
      "x": -6,
      "y": -10,
      "z": -12,
      "name": "Rock_Volcanic"
    },
    {
      "x": -6,
      "y": -9,
      "z": -12,
      "name": "Rock_Volcanic"
    },
    {
      "x": -6,
      "y": -8,
      "z": -12,
      "name": "Rock_Volcanic"
    },
    {
      "x": -6,
      "y": -7,
      "z": -12,
      "name": "Rock_Volcanic"
    },
    {
      "x": -6,
      "y": -6,
      "z": -12,
      "name": "Rock_Volcanic"
    },
    {
      "x": -6,
      "y": -5,
      "z": -12,
      "name": "Rock_Volcanic"
    },
    {
      "x": -6,
      "y": -12,
      "z": -11,
      "name": "Rock_Volcanic"
    },
    {
      "x": -6,
      "y": -11,
      "z": -11,
      "name": "Rock_Volcanic"
    },
    {
      "x": -6,
      "y": -10,
      "z": -11,
      "name": "Rock_Volcanic"
    },
    {
      "x": -6,
      "y": -9,
      "z": -11,
      "name": "Rock_Volcanic"
    },
    {
      "x": -6,
      "y": -8,
      "z": -11,
      "name": "Rock_Volcanic"
    },
    {
      "x": -6,
      "y": -7,
      "z": -11,
      "name": "Rock_Volcanic"
    },
    {
      "x": -6,
      "y": -6,
      "z": -11,
      "name": "Rock_Volcanic_Cracked_Lava"
    },
    {
      "x": -6,
      "y": -5,
      "z": -11,
      "name": "Rock_Volcanic_Cracked_Lava"
    },
    {
      "x": -6,
      "y": -4,
      "z": -11,
      "name": "Rock_Volcanic"
    },
    {
      "x": -6,
      "y": -13,
      "z": -10,
      "name": "Rock_Volcanic"
    },
    {
      "x": -6,
      "y": -12,
      "z": -10,
      "name": "Rock_Volcanic"
    },
    {
      "x": -6,
      "y": -11,
      "z": -10,
      "name": "Rock_Volcanic"
    },
    {
      "x": -6,
      "y": -10,
      "z": -10,
      "name": "Rock_Volcanic"
    },
    {
      "x": -6,
      "y": -9,
      "z": -10,
      "name": "Rock_Volcanic"
    },
    {
      "x": -6,
      "y": -8,
      "z": -10,
      "name": "Rock_Volcanic"
    },
    {
      "x": -6,
      "y": -7,
      "z": -10,
      "name": "Rock_Volcanic"
    },
    {
      "x": -6,
      "y": -6,
      "z": -10,
      "name": "Rock_Volcanic_Cracked_Lava"
    },
    {
      "x": -6,
      "y": -5,
      "z": -10,
      "name": "Rock_Volcanic"
    },
    {
      "x": -6,
      "y": -4,
      "z": -10,
      "name": "Rock_Volcanic_Cracked_Lava"
    },
    {
      "x": -6,
      "y": -12,
      "z": -9,
      "name": "Rock_Volcanic"
    },
    {
      "x": -6,
      "y": -11,
      "z": -9,
      "name": "Rock_Volcanic"
    },
    {
      "x": -6,
      "y": -10,
      "z": -9,
      "name": "Rock_Volcanic"
    },
    {
      "x": -6,
      "y": -9,
      "z": -9,
      "name": "Rock_Volcanic"
    },
    {
      "x": -6,
      "y": -8,
      "z": -9,
      "name": "Rock_Volcanic"
    },
    {
      "x": -6,
      "y": -7,
      "z": -9,
      "name": "Rock_Volcanic"
    },
    {
      "x": -6,
      "y": -6,
      "z": -9,
      "name": "Rock_Volcanic"
    },
    {
      "x": -6,
      "y": -5,
      "z": -9,
      "name": "Rock_Volcanic"
    },
    {
      "x": -6,
      "y": -4,
      "z": -9,
      "name": "Rock_Volcanic"
    },
    {
      "x": -6,
      "y": -3,
      "z": -9,
      "name": "Rock_Volcanic_Cracked_Lava"
    },
    {
      "x": -6,
      "y": -11,
      "z": -8,
      "name": "Rock_Volcanic"
    },
    {
      "x": -6,
      "y": -10,
      "z": -8,
      "name": "Rock_Volcanic_Cracked_Lava"
    },
    {
      "x": -6,
      "y": -9,
      "z": -8,
      "name": "Rock_Volcanic_Cracked_Lava"
    },
    {
      "x": -6,
      "y": -8,
      "z": -8,
      "name": "Rock_Volcanic"
    },
    {
      "x": -6,
      "y": -7,
      "z": -8,
      "name": "Rock_Volcanic"
    },
    {
      "x": -6,
      "y": -6,
      "z": -8,
      "name": "Rock_Volcanic"
    },
    {
      "x": -6,
      "y": -5,
      "z": -8,
      "name": "Rock_Volcanic"
    },
    {
      "x": -6,
      "y": -4,
      "z": -8,
      "name": "Rock_Volcanic"
    },
    {
      "x": -6,
      "y": -3,
      "z": -8,
      "name": "Rock_Volcanic"
    },
    {
      "x": -6,
      "y": -11,
      "z": -7,
      "name": "Rock_Volcanic"
    },
    {
      "x": -6,
      "y": -10,
      "z": -7,
      "name": "Rock_Volcanic"
    },
    {
      "x": -6,
      "y": -9,
      "z": -7,
      "name": "Rock_Volcanic"
    },
    {
      "x": -6,
      "y": -8,
      "z": -7,
      "name": "Rock_Volcanic"
    },
    {
      "x": -6,
      "y": -7,
      "z": -7,
      "name": "Rock_Volcanic"
    },
    {
      "x": -6,
      "y": -6,
      "z": -7,
      "name": "Rock_Volcanic"
    },
    {
      "x": -6,
      "y": -5,
      "z": -7,
      "name": "Rock_Volcanic"
    },
    {
      "x": -6,
      "y": -4,
      "z": -7,
      "name": "Rock_Volcanic"
    },
    {
      "x": -6,
      "y": -3,
      "z": -7,
      "name": "Rock_Volcanic"
    },
    {
      "x": -6,
      "y": -9,
      "z": -6,
      "name": "Rock_Volcanic_Cracked_Lava"
    },
    {
      "x": -6,
      "y": -8,
      "z": -6,
      "name": "Rock_Volcanic"
    },
    {
      "x": -6,
      "y": -7,
      "z": -6,
      "name": "Rock_Volcanic"
    },
    {
      "x": -6,
      "y": -6,
      "z": -6,
      "name": "Rock_Volcanic"
    },
    {
      "x": -6,
      "y": -5,
      "z": -6,
      "name": "Rock_Volcanic"
    },
    {
      "x": -6,
      "y": -4,
      "z": -6,
      "name": "Rock_Volcanic"
    },
    {
      "x": -6,
      "y": -3,
      "z": -6,
      "name": "Rock_Volcanic"
    },
    {
      "x": -6,
      "y": -2,
      "z": -6,
      "name": "Rock_Volcanic"
    },
    {
      "x": -6,
      "y": -1,
      "z": -6,
      "name": "Rock_Volcanic"
    },
    {
      "x": -6,
      "y": -9,
      "z": -5,
      "name": "Rock_Volcanic_Cracked_Lava"
    },
    {
      "x": -6,
      "y": -8,
      "z": -5,
      "name": "Rock_Volcanic"
    },
    {
      "x": -6,
      "y": -7,
      "z": -5,
      "name": "Rock_Volcanic"
    },
    {
      "x": -6,
      "y": -6,
      "z": -5,
      "name": "Rock_Volcanic_Cracked_Lava"
    },
    {
      "x": -6,
      "y": -5,
      "z": -5,
      "name": "Rock_Volcanic"
    },
    {
      "x": -6,
      "y": -4,
      "z": -5,
      "name": "Rock_Volcanic"
    },
    {
      "x": -6,
      "y": -3,
      "z": -5,
      "name": "Rock_Volcanic"
    },
    {
      "x": -6,
      "y": -2,
      "z": -5,
      "name": "Rock_Volcanic_Cracked_Lava"
    },
    {
      "x": -6,
      "y": -1,
      "z": -5,
      "name": "Rock_Volcanic"
    },
    {
      "x": -6,
      "y": -9,
      "z": -4,
      "name": "Rock_Volcanic_Cracked_Lava"
    },
    {
      "x": -6,
      "y": -8,
      "z": -4,
      "name": "Rock_Volcanic"
    },
    {
      "x": -6,
      "y": -7,
      "z": -4,
      "name": "Rock_Volcanic"
    },
    {
      "x": -6,
      "y": -6,
      "z": -4,
      "name": "Rock_Volcanic_Cracked_Lava"
    },
    {
      "x": -6,
      "y": -5,
      "z": -4,
      "name": "Rock_Volcanic"
    },
    {
      "x": -6,
      "y": -4,
      "z": -4,
      "name": "Rock_Volcanic"
    },
    {
      "x": -6,
      "y": -3,
      "z": -4,
      "name": "Rock_Volcanic"
    },
    {
      "x": -6,
      "y": -2,
      "z": -4,
      "name": "Rock_Volcanic"
    },
    {
      "x": -6,
      "y": -1,
      "z": -4,
      "name": "Rock_Volcanic_Cracked_Lava"
    },
    {
      "x": -6,
      "y": 0,
      "z": -4,
      "name": "Rock_Volcanic"
    },
    {
      "x": -6,
      "y": 1,
      "z": -4,
      "name": "Rock_Volcanic"
    },
    {
      "x": -6,
      "y": -9,
      "z": -3,
      "name": "Rock_Volcanic"
    },
    {
      "x": -6,
      "y": -8,
      "z": -3,
      "name": "Rock_Volcanic"
    },
    {
      "x": -6,
      "y": -7,
      "z": -3,
      "name": "Rock_Volcanic"
    },
    {
      "x": -6,
      "y": -6,
      "z": -3,
      "name": "Rock_Volcanic"
    },
    {
      "x": -6,
      "y": -5,
      "z": -3,
      "name": "Rock_Volcanic"
    },
    {
      "x": -6,
      "y": -4,
      "z": -3,
      "name": "Rock_Volcanic"
    },
    {
      "x": -6,
      "y": -3,
      "z": -3,
      "name": "Rock_Volcanic"
    },
    {
      "x": -6,
      "y": -2,
      "z": -3,
      "name": "Rock_Volcanic"
    },
    {
      "x": -6,
      "y": -1,
      "z": -3,
      "name": "Rock_Volcanic"
    },
    {
      "x": -6,
      "y": 0,
      "z": -3,
      "name": "Rock_Volcanic"
    },
    {
      "x": -6,
      "y": 1,
      "z": -3,
      "name": "Rock_Volcanic"
    },
    {
      "x": -6,
      "y": -9,
      "z": -2,
      "name": "Rock_Volcanic"
    },
    {
      "x": -6,
      "y": -8,
      "z": -2,
      "name": "Rock_Volcanic"
    },
    {
      "x": -6,
      "y": -7,
      "z": -2,
      "name": "Rock_Volcanic"
    },
    {
      "x": -6,
      "y": -6,
      "z": -2,
      "name": "Rock_Volcanic_Cracked_Lava"
    },
    {
      "x": -6,
      "y": -5,
      "z": -2,
      "name": "Rock_Volcanic"
    },
    {
      "x": -6,
      "y": -4,
      "z": -2,
      "name": "Rock_Volcanic"
    },
    {
      "x": -6,
      "y": -3,
      "z": -2,
      "name": "Rock_Volcanic"
    },
    {
      "x": -6,
      "y": -2,
      "z": -2,
      "name": "Rock_Volcanic"
    },
    {
      "x": -6,
      "y": -1,
      "z": -2,
      "name": "Rock_Volcanic_Cracked_Lava"
    },
    {
      "x": -6,
      "y": 0,
      "z": -2,
      "name": "Rock_Volcanic_Cracked_Lava"
    },
    {
      "x": -6,
      "y": 1,
      "z": -2,
      "name": "Rock_Volcanic"
    },
    {
      "x": -6,
      "y": -9,
      "z": -1,
      "name": "Rock_Volcanic_Cracked_Lava"
    },
    {
      "x": -6,
      "y": -8,
      "z": -1,
      "name": "Rock_Volcanic_Cracked_Lava"
    },
    {
      "x": -6,
      "y": -7,
      "z": -1,
      "name": "Rock_Volcanic"
    },
    {
      "x": -6,
      "y": -6,
      "z": -1,
      "name": "Rock_Volcanic"
    },
    {
      "x": -6,
      "y": -5,
      "z": -1,
      "name": "Rock_Volcanic_Cracked_Lava"
    },
    {
      "x": -6,
      "y": -4,
      "z": -1,
      "name": "Rock_Volcanic_Cracked_Lava"
    },
    {
      "x": -6,
      "y": -3,
      "z": -1,
      "name": "Rock_Volcanic_Cracked_Lava"
    },
    {
      "x": -6,
      "y": -2,
      "z": -1,
      "name": "Rock_Volcanic"
    },
    {
      "x": -6,
      "y": -1,
      "z": -1,
      "name": "Rock_Volcanic_Cracked_Lava"
    },
    {
      "x": -6,
      "y": 0,
      "z": -1,
      "name": "Rock_Volcanic"
    },
    {
      "x": -6,
      "y": 1,
      "z": -1,
      "name": "Rock_Volcanic"
    },
    {
      "x": -6,
      "y": 2,
      "z": -1,
      "name": "Rock_Volcanic"
    },
    {
      "x": -6,
      "y": -9,
      "z": 0,
      "name": "Rock_Volcanic"
    },
    {
      "x": -6,
      "y": -8,
      "z": 0,
      "name": "Rock_Volcanic_Cracked_Lava"
    },
    {
      "x": -6,
      "y": -7,
      "z": 0,
      "name": "Rock_Volcanic"
    },
    {
      "x": -6,
      "y": -6,
      "z": 0,
      "name": "Rock_Volcanic_Cracked_Lava"
    },
    {
      "x": -6,
      "y": -5,
      "z": 0,
      "name": "Rock_Volcanic"
    },
    {
      "x": -6,
      "y": -4,
      "z": 0,
      "name": "Rock_Volcanic"
    },
    {
      "x": -6,
      "y": -3,
      "z": 0,
      "name": "Rock_Volcanic"
    },
    {
      "x": -6,
      "y": -2,
      "z": 0,
      "name": "Rock_Volcanic"
    },
    {
      "x": -6,
      "y": -1,
      "z": 0,
      "name": "Rock_Volcanic"
    },
    {
      "x": -6,
      "y": 0,
      "z": 0,
      "name": "Rock_Volcanic"
    },
    {
      "x": -6,
      "y": 1,
      "z": 0,
      "name": "Rock_Volcanic"
    },
    {
      "x": -5,
      "y": -12,
      "z": -11,
      "name": "Rock_Volcanic"
    },
    {
      "x": -5,
      "y": -11,
      "z": -11,
      "name": "Rock_Volcanic"
    },
    {
      "x": -5,
      "y": -10,
      "z": -11,
      "name": "Rock_Volcanic"
    },
    {
      "x": -5,
      "y": -9,
      "z": -11,
      "name": "Rock_Volcanic"
    },
    {
      "x": -5,
      "y": -8,
      "z": -11,
      "name": "Rock_Volcanic"
    },
    {
      "x": -5,
      "y": -7,
      "z": -11,
      "name": "Rock_Volcanic"
    },
    {
      "x": -5,
      "y": -6,
      "z": -11,
      "name": "Rock_Volcanic"
    },
    {
      "x": -5,
      "y": -5,
      "z": -11,
      "name": "Rock_Volcanic"
    },
    {
      "x": -5,
      "y": -4,
      "z": -11,
      "name": "Rock_Volcanic_Cracked_Lava"
    },
    {
      "x": -5,
      "y": -13,
      "z": -10,
      "name": "Rock_Volcanic"
    },
    {
      "x": -5,
      "y": -12,
      "z": -10,
      "name": "Rock_Volcanic_Cracked_Lava"
    },
    {
      "x": -5,
      "y": -11,
      "z": -10,
      "name": "Rock_Volcanic"
    },
    {
      "x": -5,
      "y": -10,
      "z": -10,
      "name": "Rock_Volcanic"
    },
    {
      "x": -5,
      "y": -9,
      "z": -10,
      "name": "Rock_Volcanic"
    },
    {
      "x": -5,
      "y": -8,
      "z": -10,
      "name": "Rock_Volcanic"
    },
    {
      "x": -5,
      "y": -7,
      "z": -10,
      "name": "Rock_Volcanic"
    },
    {
      "x": -5,
      "y": -6,
      "z": -10,
      "name": "Rock_Volcanic"
    },
    {
      "x": -5,
      "y": -5,
      "z": -10,
      "name": "Rock_Volcanic_Cracked_Lava"
    },
    {
      "x": -5,
      "y": -4,
      "z": -10,
      "name": "Rock_Volcanic"
    },
    {
      "x": -5,
      "y": -12,
      "z": -9,
      "name": "Rock_Volcanic"
    },
    {
      "x": -5,
      "y": -11,
      "z": -9,
      "name": "Rock_Volcanic"
    },
    {
      "x": -5,
      "y": -10,
      "z": -9,
      "name": "Rock_Volcanic_Cracked_Lava"
    },
    {
      "x": -5,
      "y": -9,
      "z": -9,
      "name": "Rock_Volcanic"
    },
    {
      "x": -5,
      "y": -8,
      "z": -9,
      "name": "Rock_Volcanic_Cracked_Lava"
    },
    {
      "x": -5,
      "y": -7,
      "z": -9,
      "name": "Rock_Volcanic"
    },
    {
      "x": -5,
      "y": -6,
      "z": -9,
      "name": "Rock_Volcanic"
    },
    {
      "x": -5,
      "y": -5,
      "z": -9,
      "name": "Rock_Volcanic"
    },
    {
      "x": -5,
      "y": -4,
      "z": -9,
      "name": "Rock_Volcanic"
    },
    {
      "x": -5,
      "y": -3,
      "z": -9,
      "name": "Rock_Volcanic_Cracked_Lava"
    },
    {
      "x": -5,
      "y": -11,
      "z": -8,
      "name": "Rock_Volcanic"
    },
    {
      "x": -5,
      "y": -10,
      "z": -8,
      "name": "Rock_Volcanic"
    },
    {
      "x": -5,
      "y": -9,
      "z": -8,
      "name": "Rock_Volcanic"
    },
    {
      "x": -5,
      "y": -8,
      "z": -8,
      "name": "Rock_Volcanic"
    },
    {
      "x": -5,
      "y": -7,
      "z": -8,
      "name": "Rock_Volcanic"
    },
    {
      "x": -5,
      "y": -6,
      "z": -8,
      "name": "Rock_Volcanic"
    },
    {
      "x": -5,
      "y": -5,
      "z": -8,
      "name": "Rock_Volcanic"
    },
    {
      "x": -5,
      "y": -4,
      "z": -8,
      "name": "Rock_Volcanic_Cracked_Lava"
    },
    {
      "x": -5,
      "y": -3,
      "z": -8,
      "name": "Rock_Volcanic"
    },
    {
      "x": -5,
      "y": -10,
      "z": -7,
      "name": "Rock_Volcanic"
    },
    {
      "x": -5,
      "y": -9,
      "z": -7,
      "name": "Rock_Volcanic"
    },
    {
      "x": -5,
      "y": -8,
      "z": -7,
      "name": "Rock_Volcanic_Cracked_Lava"
    },
    {
      "x": -5,
      "y": -7,
      "z": -7,
      "name": "Rock_Volcanic"
    },
    {
      "x": -5,
      "y": -6,
      "z": -7,
      "name": "Rock_Volcanic"
    },
    {
      "x": -5,
      "y": -5,
      "z": -7,
      "name": "Rock_Volcanic_Cracked_Lava"
    },
    {
      "x": -5,
      "y": -4,
      "z": -7,
      "name": "Rock_Volcanic_Cracked_Lava"
    },
    {
      "x": -5,
      "y": -3,
      "z": -7,
      "name": "Rock_Volcanic"
    },
    {
      "x": -5,
      "y": -9,
      "z": -6,
      "name": "Rock_Volcanic_Cracked_Lava"
    },
    {
      "x": -5,
      "y": -8,
      "z": -6,
      "name": "Rock_Volcanic"
    },
    {
      "x": -5,
      "y": -7,
      "z": -6,
      "name": "Rock_Volcanic"
    },
    {
      "x": -5,
      "y": -6,
      "z": -6,
      "name": "Rock_Volcanic"
    },
    {
      "x": -5,
      "y": -5,
      "z": -6,
      "name": "Rock_Volcanic"
    },
    {
      "x": -5,
      "y": -4,
      "z": -6,
      "name": "Rock_Volcanic"
    },
    {
      "x": -5,
      "y": -3,
      "z": -6,
      "name": "Rock_Volcanic"
    },
    {
      "x": -5,
      "y": -2,
      "z": -6,
      "name": "Rock_Volcanic"
    },
    {
      "x": -5,
      "y": -1,
      "z": -6,
      "name": "Rock_Volcanic"
    },
    {
      "x": -5,
      "y": -9,
      "z": -5,
      "name": "Rock_Volcanic"
    },
    {
      "x": -5,
      "y": -8,
      "z": -5,
      "name": "Rock_Volcanic"
    },
    {
      "x": -5,
      "y": -7,
      "z": -5,
      "name": "Rock_Volcanic"
    },
    {
      "x": -5,
      "y": -6,
      "z": -5,
      "name": "Rock_Volcanic_Cracked_Lava"
    },
    {
      "x": -5,
      "y": -5,
      "z": -5,
      "name": "Rock_Volcanic"
    },
    {
      "x": -5,
      "y": -4,
      "z": -5,
      "name": "Rock_Volcanic"
    },
    {
      "x": -5,
      "y": -3,
      "z": -5,
      "name": "Rock_Volcanic"
    },
    {
      "x": -5,
      "y": -2,
      "z": -5,
      "name": "Rock_Volcanic"
    },
    {
      "x": -5,
      "y": -1,
      "z": -5,
      "name": "Rock_Volcanic"
    },
    {
      "x": -5,
      "y": 0,
      "z": -5,
      "name": "Rock_Volcanic"
    },
    {
      "x": -5,
      "y": -9,
      "z": -4,
      "name": "Rock_Volcanic"
    },
    {
      "x": -5,
      "y": -8,
      "z": -4,
      "name": "Rock_Volcanic"
    },
    {
      "x": -5,
      "y": -7,
      "z": -4,
      "name": "Rock_Volcanic"
    },
    {
      "x": -5,
      "y": -6,
      "z": -4,
      "name": "Rock_Volcanic"
    },
    {
      "x": -5,
      "y": -5,
      "z": -4,
      "name": "Rock_Volcanic"
    },
    {
      "x": -5,
      "y": -4,
      "z": -4,
      "name": "Rock_Volcanic"
    },
    {
      "x": -5,
      "y": -3,
      "z": -4,
      "name": "Rock_Volcanic_Cracked_Lava"
    },
    {
      "x": -5,
      "y": -2,
      "z": -4,
      "name": "Rock_Volcanic"
    },
    {
      "x": -5,
      "y": -1,
      "z": -4,
      "name": "Rock_Volcanic"
    },
    {
      "x": -5,
      "y": 0,
      "z": -4,
      "name": "Rock_Volcanic_Cracked_Lava"
    },
    {
      "x": -5,
      "y": 1,
      "z": -4,
      "name": "Rock_Volcanic"
    },
    {
      "x": -5,
      "y": -9,
      "z": -3,
      "name": "Rock_Volcanic_Cracked_Lava"
    },
    {
      "x": -5,
      "y": -8,
      "z": -3,
      "name": "Rock_Volcanic"
    },
    {
      "x": -5,
      "y": -7,
      "z": -3,
      "name": "Rock_Volcanic_Cracked_Lava"
    },
    {
      "x": -5,
      "y": -6,
      "z": -3,
      "name": "Rock_Volcanic"
    },
    {
      "x": -5,
      "y": -5,
      "z": -3,
      "name": "Rock_Volcanic"
    },
    {
      "x": -5,
      "y": -4,
      "z": -3,
      "name": "Rock_Volcanic"
    },
    {
      "x": -5,
      "y": -3,
      "z": -3,
      "name": "Rock_Volcanic"
    },
    {
      "x": -5,
      "y": -2,
      "z": -3,
      "name": "Rock_Volcanic"
    },
    {
      "x": -5,
      "y": -1,
      "z": -3,
      "name": "Rock_Volcanic_Cracked_Lava"
    },
    {
      "x": -5,
      "y": 0,
      "z": -3,
      "name": "Rock_Volcanic"
    },
    {
      "x": -5,
      "y": 1,
      "z": -3,
      "name": "Rock_Volcanic_Cracked_Lava"
    },
    {
      "x": -5,
      "y": -9,
      "z": -2,
      "name": "Rock_Volcanic"
    },
    {
      "x": -5,
      "y": -8,
      "z": -2,
      "name": "Rock_Volcanic"
    },
    {
      "x": -5,
      "y": -7,
      "z": -2,
      "name": "Rock_Volcanic"
    },
    {
      "x": -5,
      "y": -6,
      "z": -2,
      "name": "Rock_Volcanic_Cracked_Lava"
    },
    {
      "x": -5,
      "y": -5,
      "z": -2,
      "name": "Rock_Volcanic"
    },
    {
      "x": -5,
      "y": -4,
      "z": -2,
      "name": "Rock_Volcanic"
    },
    {
      "x": -5,
      "y": -3,
      "z": -2,
      "name": "Rock_Volcanic"
    },
    {
      "x": -5,
      "y": -2,
      "z": -2,
      "name": "Rock_Volcanic"
    },
    {
      "x": -5,
      "y": -1,
      "z": -2,
      "name": "Rock_Volcanic"
    },
    {
      "x": -5,
      "y": 0,
      "z": -2,
      "name": "Rock_Volcanic"
    },
    {
      "x": -5,
      "y": 1,
      "z": -2,
      "name": "Rock_Volcanic"
    },
    {
      "x": -5,
      "y": -9,
      "z": -1,
      "name": "Rock_Volcanic"
    },
    {
      "x": -5,
      "y": -8,
      "z": -1,
      "name": "Rock_Volcanic"
    },
    {
      "x": -5,
      "y": -7,
      "z": -1,
      "name": "Rock_Volcanic_Cracked_Lava"
    },
    {
      "x": -5,
      "y": -6,
      "z": -1,
      "name": "Rock_Volcanic"
    },
    {
      "x": -5,
      "y": -5,
      "z": -1,
      "name": "Rock_Volcanic"
    },
    {
      "x": -5,
      "y": -4,
      "z": -1,
      "name": "Rock_Volcanic_Cracked_Lava"
    },
    {
      "x": -5,
      "y": -3,
      "z": -1,
      "name": "Rock_Volcanic"
    },
    {
      "x": -5,
      "y": -2,
      "z": -1,
      "name": "Rock_Volcanic_Cracked_Lava"
    },
    {
      "x": -5,
      "y": -1,
      "z": -1,
      "name": "Rock_Volcanic"
    },
    {
      "x": -5,
      "y": 0,
      "z": -1,
      "name": "Rock_Volcanic"
    },
    {
      "x": -5,
      "y": 1,
      "z": -1,
      "name": "Rock_Volcanic"
    },
    {
      "x": -5,
      "y": 2,
      "z": -1,
      "name": "Rock_Volcanic"
    },
    {
      "x": -5,
      "y": -9,
      "z": 0,
      "name": "Rock_Volcanic"
    },
    {
      "x": -5,
      "y": -8,
      "z": 0,
      "name": "Rock_Volcanic_Cracked_Lava"
    },
    {
      "x": -5,
      "y": -7,
      "z": 0,
      "name": "Rock_Volcanic"
    },
    {
      "x": -5,
      "y": -6,
      "z": 0,
      "name": "Rock_Volcanic_Cracked_Lava"
    },
    {
      "x": -5,
      "y": -5,
      "z": 0,
      "name": "Rock_Volcanic"
    },
    {
      "x": -5,
      "y": -4,
      "z": 0,
      "name": "Rock_Volcanic"
    },
    {
      "x": -5,
      "y": -3,
      "z": 0,
      "name": "Rock_Volcanic"
    },
    {
      "x": -5,
      "y": -2,
      "z": 0,
      "name": "Rock_Volcanic"
    },
    {
      "x": -5,
      "y": -1,
      "z": 0,
      "name": "Rock_Volcanic"
    },
    {
      "x": -5,
      "y": 0,
      "z": 0,
      "name": "Rock_Volcanic"
    },
    {
      "x": -5,
      "y": 1,
      "z": 0,
      "name": "Rock_Volcanic"
    },
    {
      "x": -4,
      "y": -12,
      "z": -11,
      "name": "Rock_Volcanic"
    },
    {
      "x": -4,
      "y": -11,
      "z": -11,
      "name": "Rock_Volcanic_Cracked_Lava"
    },
    {
      "x": -4,
      "y": -10,
      "z": -11,
      "name": "Rock_Volcanic"
    },
    {
      "x": -4,
      "y": -9,
