{
  "version": 8,
  "blockIdVersion": 11,
  "anchorX": 0,
  "anchorY": 0,
  "anchorZ": 0,
  "blocks": [
    {
      "x": -7,
      "y": -15,
      "z": -17,
      "name": "Rock_Volcanic"
    },
    {
      "x": -7,
      "y": -7,
      "z": -11,
      "name": "Rock_Volcanic"
    },
    {
      "x": -6,
      "y": -28,
      "z": -25,
      "name": "Rock_Volcanic"
    },
    {
      "x": -6,
      "y": -27,
      "z": -25,
      "name": "Rock_Volcanic"
    },
    {
      "x": -6,
      "y": -28,
      "z": -24,
      "name": "Rock_Volcanic"
    },
    {
      "x": -6,
      "y": -27,
      "z": -24,
      "name": "Rock_Volcanic"
    },
    {
      "x": -6,
      "y": -26,
      "z": -24,
      "name": "Rock_Volcanic"
    },
    {
      "x": -6,
      "y": -27,
      "z": -23,
      "name": "Rock_Volcanic"
    },
    {
      "x": -6,
      "y": -26,
      "z": -23,
      "name": "Rock_Volcanic"
    },
    {
      "x": -6,
      "y": -25,
      "z": -23,
      "name": "Rock_Volcanic_Cracked_Lava"
    },
    {
      "x": -6,
      "y": -24,
      "z": -22,
      "name": "Rock_Volcanic"
    },
    {
      "x": -6,
      "y": -23,
      "z": -22,
      "name": "Rock_Volcanic"
    },
    {
      "x": -6,
      "y": -22,
      "z": -22,
      "name": "Rock_Volcanic"
    },
    {
      "x": -6,
      "y": -25,
      "z": -21,
      "name": "Rock_Volcanic"
    },
    {
      "x": -6,
      "y": -24,
      "z": -21,
      "name": "Rock_Volcanic_Cracked_Lava"
    },
    {
      "x": -6,
      "y": -23,
      "z": -21,
      "name": "Rock_Volcanic"
    },
    {
      "x": -6,
      "y": -22,
      "z": -21,
      "name": "Rock_Volcanic"
    },
    {
      "x": -6,
      "y": -21,
      "z": -21,
      "name": "Rock_Volcanic"
    },
    {
      "x": -6,
      "y": -25,
      "z": -20,
      "name": "Rock_Volcanic"
    },
    {
      "x": -6,
      "y": -24,
      "z": -20,
      "name": "Rock_Volcanic_Cracked_Lava"
    },
    {
      "x": -6,
      "y": -23,
      "z": -20,
      "name": "Rock_Volcanic"
    },
    {
      "x": -6,
      "y": -22,
      "z": -20,
      "name": "Rock_Volcanic_Cracked_Lava"
    },
    {
      "x": -6,
      "y": -21,
      "z": -20,
      "name": "Rock_Volcanic"
    },
    {
      "x": -6,
      "y": -20,
      "z": -20,
      "name": "Rock_Volcanic"
    },
    {
      "x": -6,
      "y": -24,
      "z": -19,
      "name": "Rock_Volcanic_Cracked_Lava"
    },
    {
      "x": -6,
      "y": -23,
      "z": -19,
      "name": "Rock_Volcanic"
    },
    {
      "x": -6,
      "y": -22,
      "z": -19,
      "name": "Rock_Volcanic"
    },
    {
      "x": -6,
      "y": -21,
      "z": -19,
      "name": "Rock_Volcanic"
    },
    {
      "x": -6,
      "y": -20,
      "z": -19,
      "name": "Rock_Volcanic"
    },
    {
      "x": -6,
      "y": -19,
      "z": -19,
      "name": "Rock_Volcanic"
    },
    {
      "x": -6,
      "y": -23,
      "z": -18,
      "name": "Rock_Volcanic"
    },
    {
      "x": -6,
      "y": -22,
      "z": -18,
      "name": "Rock_Volcanic_Cracked_Lava"
    },
    {
      "x": -6,
      "y": -21,
      "z": -18,
      "name": "Rock_Volcanic"
    },
    {
      "x": -6,
      "y": -20,
      "z": -18,
      "name": "Rock_Volcanic"
    },
    {
      "x": -6,
      "y": -19,
      "z": -18,
      "name": "Rock_Volcanic"
    },
    {
      "x": -6,
      "y": -18,
      "z": -18,
      "name": "Rock_Volcanic"
    },
    {
      "x": -6,
      "y": -22,
      "z": -17,
      "name": "Rock_Volcanic_Cracked_Lava"
    },
    {
      "x": -6,
      "y": -21,
      "z": -17,
      "name": "Rock_Volcanic"
    },
    {
      "x": -6,
      "y": -20,
      "z": -17,
      "name": "Rock_Volcanic"
    },
    {
      "x": -6,
      "y": -19,
      "z": -17,
      "name": "Rock_Volcanic"
    },
    {
      "x": -6,
      "y": -18,
      "z": -17,
      "name": "Rock_Volcanic"
    },
    {
      "x": -6,
      "y": -17,
      "z": -17,
      "name": "Rock_Volcanic_Cracked_Lava"
    },
    {
      "x": -6,
      "y": -15,
      "z": -17,
      "name": "Rock_Volcanic_Cracked_Lava"
    },
    {
      "x": -6,
      "y": -16,
      "z": -16,
      "name": "Rock_Volcanic"
    },
    {
      "x": -6,
      "y": -15,
      "z": -16,
      "name": "Rock_Volcanic"
    },
    {
      "x": -6,
      "y": -14,
      "z": -16,
      "name": "Rock_Volcanic"
    },
    {
      "x": -6,
      "y": -17,
      "z": -15,
      "name": "Rock_Volcanic"
    },
    {
      "x": -6,
      "y": -16,
      "z": -15,
      "name": "Rock_Volcanic_Cracked_Lava"
    },
    {
      "x": -6,
      "y": -15,
      "z": -15,
      "name": "Rock_Volcanic"
    },
    {
      "x": -6,
      "y": -14,
      "z": -15,
      "name": "Rock_Volcanic"
    },
    {
      "x": -6,
      "y": -13,
      "z": -15,
      "name": "Rock_Volcanic"
    },
    {
      "x": -6,
      "y": -17,
      "z": -14,
      "name": "Rock_Volcanic_Cracked_Lava"
    },
    {
      "x": -6,
      "y": -16,
      "z": -14,
      "name": "Rock_Volcanic"
    },
    {
      "x": -6,
      "y": -15,
      "z": -14,
      "name": "Rock_Volcanic"
    },
    {
      "x": -6,
      "y": -14,
      "z": -14,
      "name": "Rock_Volcanic"
    },
    {
      "x": -6,
      "y": -13,
      "z": -14,
      "name": "Rock_Volcanic"
    },
    {
      "x": -6,
      "y": -12,
      "z": -14,
      "name": "Rock_Volcanic"
    },
    {
      "x": -6,
      "y": -11,
      "z": -14,
      "name": "Rock_Volcanic"
    },
    {
      "x": -6,
      "y": -18,
      "z": -13,
      "name": "Rock_Volcanic"
    },
    {
      "x": -6,
      "y": -17,
      "z": -13,
      "name": "Rock_Volcanic"
    },
    {
      "x": -6,
      "y": -16,
      "z": -13,
      "name": "Rock_Volcanic"
    },
    {
      "x": -6,
      "y": -15,
      "z": -13,
      "name": "Rock_Volcanic_Cracked_Lava"
    },
    {
      "x": -6,
      "y": -14,
      "z": -13,
      "name": "Rock_Volcanic"
    },
    {
      "x": -6,
      "y": -13,
      "z": -13,
      "name": "Rock_Volcanic"
    },
    {
      "x": -6,
      "y": -12,
      "z": -13,
      "name": "Rock_Volcanic"
    },
    {
      "x": -6,
      "y": -11,
      "z": -13,
      "name": "Rock_Volcanic"
    },
    {
      "x": -6,
      "y": -10,
      "z": -13,
      "name": "Rock_Volcanic"
    },
    {
      "x": -6,
      "y": -17,
      "z": -12,
      "name": "Rock_Volcanic"
    },
    {
      "x": -6,
      "y": -16,
      "z": -12,
      "name": "Rock_Volcanic"
    },
    {
      "x": -6,
      "y": -15,
      "z": -12,
      "name": "Rock_Volcanic"
    },
    {
      "x": -6,
      "y": -14,
      "z": -12,
      "name": "Rock_Volcanic"
    },
    {
      "x": -6,
      "y": -13,
      "z": -12,
      "name": "Rock_Volcanic_Cracked_Lava"
    },
    {
      "x": -6,
      "y": -12,
      "z": -12,
      "name": "Rock_Volcanic"
    },
    {
      "x": -6,
      "y": -11,
      "z": -12,
      "name": "Rock_Volcanic"
    },
    {
      "x": -6,
      "y": -10,
      "z": -12,
      "name": "Rock_Volcanic"
    },
    {
      "x": -6,
      "y": -9,
      "z": -12,
      "name": "Rock_Volcanic"
    },
    {
      "x": -6,
      "y": -7,
      "z": -11,
      "name": "Rock_Volcanic"
    },
    {
      "x": -6,
      "y": -6,
      "z": -11,
      "name": "Rock_Volcanic"
    },
    {
      "x": -6,
      "y": -8,
      "z": -10,
      "name": "Rock_Volcanic"
    },
    {
      "x": -6,
      "y": -7,
      "z": -10,
      "name": "Rock_Volcanic"
    },
    {
      "x": -6,
      "y": -6,
      "z": -10,
      "name": "Rock_Volcanic"
    },
    {
      "x": -6,
      "y": -5,
      "z": -10,
      "name": "Rock_Volcanic"
    },
    {
      "x": -6,
      "y": -8,
      "z": -9,
      "name": "Rock_Volcanic"
    },
    {
      "x": -6,
      "y": -7,
      "z": -9,
      "name": "Rock_Volcanic"
    },
    {
      "x": -6,
      "y": -6,
      "z": -9,
      "name": "Rock_Volcanic"
    },
    {
      "x": -6,
      "y": -5,
      "z": -9,
      "name": "Rock_Volcanic"
    },
    {
      "x": -6,
      "y": -4,
      "z": -9,
      "name": "Rock_Volcanic"
    },
    {
      "x": -6,
      "y": -9,
      "z": -8,
      "name": "Rock_Volcanic"
    },
    {
      "x": -6,
      "y": -8,
      "z": -8,
      "name": "Rock_Volcanic"
    },
    {
      "x": -6,
      "y": -7,
      "z": -8,
      "name": "Rock_Volcanic"
    },
    {
      "x": -6,
      "y": -6,
      "z": -8,
      "name": "Rock_Volcanic"
    },
    {
      "x": -6,
      "y": -5,
      "z": -8,
      "name": "Rock_Volcanic"
    },
    {
      "x": -6,
      "y": -4,
      "z": -8,
      "name": "Rock_Volcanic"
    },
    {
      "x": -6,
      "y": -3,
      "z": -8,
      "name": "Rock_Volcanic"
    },
    {
      "x": -6,
      "y": -10,
      "z": -7,
      "name": "Rock_Volcanic"
    },
    {
      "x": -6,
      "y": -9,
      "z": -7,
      "name": "Rock_Volcanic"
    },
    {
      "x": -6,
      "y": -8,
      "z": -7,
      "name": "Rock_Volcanic"
    },
    {
      "x": -6,
      "y": -7,
      "z": -7,
      "name": "Rock_Volcanic_Cracked_Lava"
    },
    {
      "x": -6,
      "y": -6,
      "z": -7,
      "name": "Rock_Volcanic"
    },
    {
      "x": -6,
      "y": -5,
      "z": -7,
      "name": "Rock_Volcanic"
    },
    {
      "x": -6,
      "y": -4,
      "z": -7,
      "name": "Rock_Volcanic"
    },
    {
      "x": -6,
      "y": -3,
      "z": -7,
      "name": "Rock_Volcanic"
    },
    {
      "x": -6,
      "y": -2,
      "z": -7,
      "name": "Rock_Volcanic"
    },
    {
      "x": -6,
      "y": -11,
      "z": -6,
      "name": "Rock_Volcanic"
    },
    {
      "x": -6,
      "y": -10,
      "z": -6,
      "name": "Rock_Volcanic_Cracked_Lava"
    },
    {
      "x": -6,
      "y": -9,
      "z": -6,
      "name": "Rock_Volcanic"
    },
    {
      "x": -6,
      "y": -8,
      "z": -6,
      "name": "Rock_Volcanic"
    },
    {
      "x": -6,
      "y": -7,
      "z": -6,
      "name": "Rock_Volcanic"
    },
    {
      "x": -6,
      "y": -6,
      "z": -6,
      "name": "Rock_Volcanic_Cracked_Lava"
    },
    {
      "x": -6,
      "y": -5,
      "z": -6,
      "name": "Rock_Volcanic"
    },
    {
      "x": -6,
      "y": -4,
      "z": -6,
      "name": "Rock_Volcanic"
    },
    {
      "x": -6,
      "y": -3,
      "z": -6,
      "name": "Rock_Volcanic"
    },
    {
      "x": -6,
      "y": -2,
      "z": -6,
      "name": "Rock_Volcanic"
    },
    {
      "x": -6,
      "y": -1,
      "z": -6,
      "name": "Rock_Volcanic"
    },
    {
      "x": -6,
      "y": 1,
      "z": -5,
      "name": "Rock_Volcanic"
    },
    {
      "x": -6,
      "y": 2,
      "z": -5,
      "name": "Rock_Volcanic"
    },
    {
      "x": -6,
      "y": 0,
      "z": -4,
      "name": "Rock_Volcanic_Cracked_Lava"
    },
    {
      "x": -6,
      "y": 1,
      "z": -4,
      "name": "Rock_Volcanic"
    },
    {
      "x": -6,
      "y": 2,
      "z": -4,
      "name": "Rock_Volcanic"
    },
    {
      "x": -6,
      "y": 3,
      "z": -4,
      "name": "Rock_Volcanic"
    },
    {
      "x": -6,
      "y": 0,
      "z": -3,
      "name": "Rock_Volcanic"
    },
    {
      "x": -6,
      "y": 1,
      "z": -3,
      "name": "Rock_Volcanic"
    },
    {
      "x": -6,
      "y": 2,
      "z": -3,
      "name": "Rock_Volcanic_Cracked_Lava"
    },
    {
      "x": -6,
      "y": 3,
      "z": -3,
      "name": "Rock_Volcanic"
    },
    {
      "x": -6,
      "y": 4,
      "z": -3,
      "name": "Rock_Volcanic"
    },
    {
      "x": -6,
      "y": 5,
      "z": -3,
      "name": "Rock_Volcanic"
    },
    {
      "x": -6,
      "y": -1,
      "z": -2,
      "name": "Rock_Volcanic_Cracked_Lava"
    },
    {
      "x": -6,
      "y": 0,
      "z": -2,
      "name": "Rock_Volcanic"
    },
    {
      "x": -6,
      "y": 1,
      "z": -2,
      "name": "Rock_Volcanic"
    },
    {
      "x": -6,
      "y": 2,
      "z": -2,
      "name": "Rock_Volcanic"
    },
    {
      "x": -6,
      "y": 3,
      "z": -2,
      "name": "Rock_Volcanic_Cracked_Lava"
    },
    {
      "x": -6,
      "y": 4,
      "z": -2,
      "name": "Rock_Volcanic_Cracked_Lava"
    },
    {
      "x": -6,
      "y": 5,
      "z": -2,
      "name": "Rock_Volcanic"
    },
    {
      "x": -6,
      "y": 6,
      "z": -2,
      "name": "Rock_Volcanic"
    },
    {
      "x": -6,
      "y": -2,
      "z": -1,
      "name": "Rock_Volcanic"
    },
    {
      "x": -6,
      "y": -1,
      "z": -1,
      "name": "Rock_Volcanic_Cracked_Lava"
    },
    {
      "x": -6,
      "y": 0,
      "z": -1,
      "name": "Rock_Volcanic"
    },
    {
      "x": -6,
      "y": 1,
      "z": -1,
      "name": "Rock_Volcanic"
    },
    {
      "x": -6,
      "y": 2,
      "z": -1,
      "name": "Rock_Volcanic"
    },
    {
      "x": -6,
      "y": 3,
      "z": -1,
      "name": "Rock_Volcanic"
    },
    {
      "x": -6,
      "y": 4,
      "z": -1,
      "name": "Rock_Volcanic"
    },
    {
      "x": -6,
      "y": 5,
      "z": -1,
      "name": "Rock_Volcanic"
    },
    {
      "x": -6,
      "y": 6,
      "z": -1,
      "name": "Rock_Volcanic"
    },
    {
      "x": -6,
      "y": 7,
      "z": -1,
      "name": "Rock_Volcanic"
    },
    {
      "x": -6,
      "y": -3,
      "z": 0,
      "name": "Rock_Volcanic_Cracked_Lava"
    },
    {
      "x": -6,
      "y": -2,
      "z": 0,
      "name": "Rock_Volcanic"
    },
    {
      "x": -6,
      "y": -1,
      "z": 0,
      "name": "Rock_Volcanic"
    },
    {
      "x": -6,
      "y": 0,
      "z": 0,
      "name": "Rock_Volcanic"
    },
    {
      "x": -6,
      "y": 1,
      "z": 0,
      "name": "Rock_Volcanic_Cracked_Lava"
    },
    {
      "x": -6,
      "y": 2,
      "z": 0,
      "name": "Rock_Volcanic_Cracked_Lava"
    },
    {
      "x": -6,
      "y": 3,
      "z": 0,
      "name": "Rock_Volcanic_Cracked_Lava"
    },
    {
      "x": -6,
      "y": 4,
      "z": 0,
      "name": "Rock_Volcanic"
    },
    {
      "x": -6,
      "y": 5,
      "z": 0,
      "name": "Rock_Volcanic"
    },
    {
      "x": -6,
      "y": 6,
      "z": 0,
      "name": "Rock_Volcanic_Cracked_Lava"
    },
    {
      "x": -6,
      "y": 7,
      "z": 0,
      "name": "Rock_Volcanic"
    },
    {
      "x": -6,
      "y": 8,
      "z": 0,
      "name": "Rock_Volcanic"
    },
    {
      "x": -5,
      "y": -28,
      "z": -26,
      "name": "Rock_Volcanic"
    },
    {
      "x": -5,
      "y": -28,
      "z": -25,
      "name": "Rock_Volcanic"
    },
    {
      "x": -5,
      "y": -27,
      "z": -25,
      "name": "Rock_Volcanic"
    },
    {
      "x": -5,
      "y": -28,
      "z": -24,
      "name": "Rock_Volcanic_Cracked_Lava"
    },
    {
      "x": -5,
      "y": -27,
      "z": -24,
      "name": "Rock_Volcanic"
    },
    {
      "x": -5,
      "y": -26,
      "z": -24,
      "name": "Rock_Volcanic"
    },
    {
      "x": -5,
      "y": -27,
      "z": -23,
      "name": "Rock_Volcanic"
    },
    {
      "x": -5,
      "y": -26,
      "z": -23,
      "name": "Rock_Volcanic"
    },
    {
      "x": -5,
      "y": -25,
      "z": -23,
      "name": "Rock_Volcanic"
    },
    {
      "x": -5,
      "y": -23,
      "z": -23,
      "name": "Rock_Volcanic"
    },
    {
      "x": -5,
      "y": -26,
      "z": -22,
      "name": "Rock_Volcanic_Cracked_Lava"
    },
    {
      "x": -5,
      "y": -25,
      "z": -22,
      "name": "Rock_Volcanic"
    },
    {
      "x": -5,
      "y": -24,
      "z": -22,
      "name": "Rock_Volcanic_Cracked_Lava"
    },
    {
      "x": -5,
      "y": -23,
      "z": -22,
      "name": "Rock_Volcanic"
    },
    {
      "x": -5,
      "y": -22,
      "z": -22,
      "name": "Rock_Volcanic"
    },
    {
      "x": -5,
      "y": -25,
      "z": -21,
      "name": "Rock_Volcanic"
    },
    {
      "x": -5,
      "y": -24,
      "z": -21,
      "name": "Rock_Volcanic"
    },
    {
      "x": -5,
      "y": -23,
      "z": -21,
      "name": "Rock_Volcanic"
    },
    {
      "x": -5,
      "y": -22,
      "z": -21,
      "name": "Rock_Volcanic"
    },
    {
      "x": -5,
      "y": -21,
      "z": -21,
      "name": "Rock_Volcanic_Cracked_Lava"
    },
    {
      "x": -5,
      "y": -25,
      "z": -20,
      "name": "Rock_Volcanic"
    },
    {
      "x": -5,
      "y": -24,
      "z": -20,
      "name": "Rock_Volcanic"
    },
    {
      "x": -5,
      "y": -23,
      "z": -20,
      "name": "Rock_Volcanic"
    },
    {
      "x": -5,
      "y": -22,
      "z": -20,
      "name": "Rock_Volcanic"
    },
    {
      "x": -5,
      "y": -21,
      "z": -20,
      "name": "Rock_Volcanic"
    },
    {
      "x": -5,
      "y": -20,
      "z": -20,
      "name": "Rock_Volcanic"
    },
    {
      "x": -5,
      "y": -24,
      "z": -19,
      "name": "Rock_Volcanic"
    },
    {
      "x": -5,
      "y": -23,
      "z": -19,
      "name": "Rock_Volcanic"
    },
    {
      "x": -5,
      "y": -22,
      "z": -19,
      "name": "Rock_Volcanic"
    },
    {
      "x": -5,
      "y": -21,
      "z": -19,
      "name": "Rock_Volcanic"
    },
    {
      "x": -5,
      "y": -20,
      "z": -19,
      "name": "Rock_Volcanic"
    },
    {
      "x": -5,
      "y": -19,
      "z": -19,
      "name": "Rock_Volcanic"
    },
    {
      "x": -5,
      "y": -23,
      "z": -18,
      "name": "Rock_Volcanic_Cracked_Lava"
    },
    {
      "x": -5,
      "y": -22,
      "z": -18,
      "name": "Rock_Volcanic"
    },
    {
      "x": -5,
      "y": -21,
      "z": -18,
      "name": "Rock_Volcanic_Cracked_Lava"
    },
    {
      "x": -5,
      "y": -20,
      "z": -18,
      "name": "Rock_Volcanic"
    },
    {
      "x": -5,
      "y": -19,
      "z": -18,
      "name": "Rock_Volcanic_Cracked_Lava"
    },
    {
      "x": -5,
      "y": -18,
      "z": -18,
      "name": "Rock_Volcanic"
    },
    {
      "x": -5,
      "y": -22,
      "z": -17,
      "name": "Rock_Volcanic"
    },
    {
      "x": -5,
      "y": -21,
      "z": -17,
      "name": "Rock_Volcanic"
    },
    {
      "x": -5,
      "y": -20,
      "z": -17,
      "name": "Rock_Volcanic"
    },
    {
      "x": -5,
      "y": -19,
      "z": -17,
      "name": "Rock_Volcanic"
    },
    {
      "x": -5,
      "y": -18,
      "z": -17,
      "name": "Rock_Volcanic"
    },
    {
      "x": -5,
      "y": -17,
      "z": -17,
      "name": "Rock_Volcanic"
    },
    {
      "x": -5,
      "y": -16,
      "z": -17,
      "name": "Rock_Volcanic"
    },
    {
      "x": -5,
      "y": -15,
      "z": -17,
      "name": "Rock_Volcanic"
    },
    {
      "x": -5,
      "y": -20,
      "z": -16,
      "name": "Rock_Volcanic"
    },
    {
      "x": -5,
      "y": -19,
      "z": -16,
      "name": "Rock_Volcanic"
    },
    {
      "x": -5,
      "y": -18,
      "z": -16,
      "name": "Rock_Volcanic"
    },
    {
      "x": -5,
      "y": -17,
      "z": -16,
      "name": "Rock_Volcanic_Cracked_Lava"
    },
    {
      "x": -5,
      "y": -16,
      "z": -16,
      "name": "Rock_Volcanic"
    },
    {
      "x": -5,
      "y": -15,
      "z": -16,
      "name": "Rock_Volcanic"
    },
    {
      "x": -5,
      "y": -14,
      "z": -16,
      "name": "Rock_Volcanic"
    },
    {
      "x": -5,
      "y": -19,
      "z": -15,
      "name": "Rock_Volcanic"
    },
    {
      "x": -5,
      "y": -18,
      "z": -15,
      "name": "Rock_Volcanic"
    },
    {
      "x": -5,
      "y": -17,
      "z": -15,
      "name": "Rock_Volcanic"
    },
    {
      "x": -5,
      "y": -16,
      "z": -15,
      "name": "Rock_Volcanic"
    },
    {
      "x": -5,
      "y": -15,
      "z": -15,
      "name": "Rock_Volcanic"
    },
    {
      "x": -5,
      "y": -14,
      "z": -15,
      "name": "Rock_Volcanic"
    },
    {
      "x": -5,
      "y": -13,
      "z": -15,
      "name": "Rock_Volcanic"
    },
    {
      "x": -5,
      "y": -12,
      "z": -15,
      "name": "Rock_Volcanic_Cracked_Lava"
    },
    {
      "x": -5,
      "y": -18,
      "z": -14,
      "name": "Rock_Volcanic"
    },
    {
      "x": -5,
      "y": -17,
      "z": -14,
      "name": "Rock_Volcanic_Cracked_Lava"
    },
    {
      "x": -5,
      "y": -16,
      "z": -14,
      "name": "Rock_Volcanic"
    },
    {
      "x": -5,
      "y": -15,
      "z": -14,
      "name": "Rock_Volcanic_Cracked_Lava"
    },
    {
      "x": -5,
      "y": -14,
      "z": -14,
      "name": "Rock_Volcanic"
    },
    {
      "x": -5,
      "y": -13,
      "z": -14,
      "name": "Rock_Volcanic_Cracked_Lava"
    },
    {
      "x": -5,
      "y": -12,
      "z": -14,
      "name": "Rock_Volcanic"
    },
    {
      "x": -5,
      "y": -11,
      "z": -14,
      "name": "Rock_Volcanic"
    },
    {
      "x": -5,
      "y": -18,
      "z": -13,
      "name": "Rock_Volcanic"
    },
    {
      "x": -5,
      "y": -17,
      "z": -13,
      "name": "Rock_Volcanic"
    },
    {
      "x": -5,
      "y": -16,
      "z": -13,
      "name": "Rock_Volcanic_Cracked_Lava"
    },
    {
      "x": -5,
      "y": -15,
      "z": -13,
      "name": "Rock_Volcanic"
    },
    {
      "x": -5,
      "y": -14,
      "z": -13,
      "name": "Rock_Volcanic"
    },
    {
      "x": -5,
      "y": -13,
      "z": -13,
      "name": "Rock_Volcanic_Cracked_Lava"
    },
    {
      "x": -5,
      "y": -12,
      "z": -13,
      "name": "Rock_Volcanic"
    },
    {
      "x": -5,
      "y": -11,
      "z": -13,
      "name": "Rock_Volcanic_Cracked_Lava"
    },
    {
      "x": -5,
      "y": -10,
      "z": -13,
      "name": "Rock_Volcanic_Cracked_Lava"
    },
    {
      "x": -5,
      "y": -17,
      "z": -12,
      "name": "Rock_Volcanic"
    },
    {
      "x": -5,
      "y": -16,
      "z": -12,
      "name": "Rock_Volcanic_Cracked_Lava"
    },
    {
      "x": -5,
      "y": -15,
      "z": -12,
      "name": "Rock_Volcanic"
    },
    {
      "x": -5,
      "y": -14,
      "z": -12,
      "name": "Rock_Volcanic"
    },
    {
      "x": -5,
      "y": -13,
      "z": -12,
      "name": "Rock_Volcanic"
    },
    {
      "x": -5,
      "y": -12,
      "z": -12,
      "name": "Rock_Volcanic"
    },
    {
      "x": -5,
      "y": -11,
      "z": -12,
      "name": "Rock_Volcanic"
    },
    {
      "x": -5,
      "y": -10,
      "z": -12,
      "name": "Rock_Volcanic"
    },
    {
      "x": -5,
      "y": -9,
      "z": -12,
      "name": "Rock_Volcanic"
    },
    {
      "x": -5,
      "y": -16,
      "z": -11,
      "name": "Rock_Volcanic"
    },
    {
      "x": -5,
      "y": -15,
      "z": -11,
      "name": "Rock_Volcanic_Cracked_Lava"
    },
    {
      "x": -5,
      "y": -14,
      "z": -11,
      "name": "Rock_Volcanic"
    },
    {
      "x": -5,
      "y": -13,
      "z": -11,
      "name": "Rock_Volcanic"
    },
    {
      "x": -5,
      "y": -12,
      "z": -11,
      "name": "Rock_Volcanic"
    },
    {
      "x": -5,
      "y": -11,
      "z": -11,
      "name": "Rock_Volcanic"
    },
    {
      "x": -5,
      "y": -10,
      "z": -11,
      "name": "Rock_Volcanic"
    },
    {
      "x": -5,
      "y": -9,
      "z": -11,
      "name": "Rock_Volcanic_Cracked_Lava"
    },
    {
      "x": -5,
      "y": -8,
      "z": -11,
      "name": "Rock_Volcanic"
    },
    {
      "x": -5,
      "y": -7,
      "z": -11,
      "name": "Rock_Volcanic"
    },
    {
      "x": -5,
      "y": -6,
      "z": -11,
      "name": "Rock_Volcanic"
    },
    {
      "x": -5,
      "y": -15,
      "z": -10,
      "name": "Rock_Volcanic"
    },
    {
      "x": -5,
      "y": -14,
      "z": -10,
      "name": "Rock_Volcanic"
    },
    {
      "x": -5,
      "y": -13,
      "z": -10,
      "name": "Rock_Volcanic"
    },
    {
      "x": -5,
      "y": -12,
      "z": -10,
      "name": "Rock_Volcanic"
    },
    {
      "x": -5,
      "y": -11,
      "z": -10,
      "name": "Rock_Volcanic_Cracked_Lava"
    },
    {
      "x": -5,
      "y": -10,
      "z": -10,
      "name": "Rock_Volcanic"
    },
    {
      "x": -5,
      "y": -9,
      "z": -10,
      "name": "Rock_Volcanic"
    },
    {
      "x": -5,
      "y": -8,
      "z": -10,
      "name": "Rock_Volcanic"
    },
    {
      "x": -5,
      "y": -7,
      "z": -10,
      "name": "Rock_Volcanic"
    },
    {
      "x": -5,
      "y": -6,
      "z": -10,
      "name": "Rock_Volcanic_Cracked_Lava"
    },
    {
      "x": -5,
      "y": -5,
      "z": -10,
      "name": "Rock_Volcanic"
    },
    {
      "x": -5,
      "y": -14,
      "z": -9,
      "name": "Rock_Volcanic"
    },
    {
      "x": -5,
      "y": -13,
      "z": -9,
      "name": "Rock_Volcanic"
    },
    {
      "x": -5,
      "y": -12,
      "z": -9,
      "name": "Rock_Volcanic"
    },
    {
      "x": -5,
      "y": -11,
      "z": -9,
      "name": "Rock_Volcanic_Cracked_Lava"
    },
    {
      "x": -5,
      "y": -10,
      "z": -9,
      "name": "Rock_Volcanic"
    },
    {
      "x": -5,
      "y": -9,
      "z": -9,
      "name": "Rock_Volcanic"
    },
    {
      "x": -5,
      "y": -8,
      "z": -9,
      "name": "Rock_Volcanic"
    },
    {
      "x": -5,
      "y": -7,
      "z": -9,
      "name": "Rock_Volcanic_Cracked_Lava"
    },
    {
      "x": -5,
      "y": -6,
      "z": -9,
      "name": "Rock_Volcanic"
    },
    {
      "x": -5,
      "y": -5,
      "z": -9,
      "name": "Rock_Volcanic"
    },
    {
      "x": -5,
      "y": -4,
      "z": -9,
      "name": "Rock_Volcanic_Cracked_Lava"
    },
    {
      "x": -5,
      "y": -13,
      "z": -8,
      "name": "Rock_Volcanic"
    },
    {
      "x": -5,
      "y": -12,
      "z": -8,
      "name": "Rock_Volcanic"
    },
    {
      "x": -5,
      "y": -11,
      "z": -8,
      "name": "Rock_Volcanic"
    },
    {
      "x": -5,
      "y": -10,
      "z": -8,
      "name": "Rock_Volcanic"
    },
    {
      "x": -5,
      "y": -9,
      "z": -8,
      "name": "Rock_Volcanic"
    },
    {
      "x": -5,
      "y": -8,
      "z": -8,
      "name": "Rock_Volcanic_Cracked_Lava"
    },
    {
      "x": -5,
      "y": -7,
      "z": -8,
      "name": "Rock_Volcanic"
    },
    {
      "x": -5,
      "y": -6,
      "z": -8,
      "name": "Rock_Volcanic_Cracked_Lava"
    },
    {
      "x": -5,
      "y": -5,
      "z": -8,
      "name": "Rock_Volcanic"
    },
    {
      "x": -5,
      "y": -4,
      "z": -8,
      "name": "Rock_Volcanic"
    },
    {
      "x": -5,
      "y": -3,
      "z": -8,
      "name": "Rock_Volcanic"
    },
    {
      "x": -5,
      "y": -11,
      "z": -7,
      "name": "Rock_Volcanic_Cracked_Lava"
    },
    {
      "x": -5,
      "y": -10,
      "z": -7,
      "name": "Rock_Volcanic"
    },
    {
      "x": -5,
      "y": -9,
      "z": -7,
      "name": "Rock_Volcanic"
    },
    {
      "x": -5,
      "y": -8,
      "z": -7,
      "name": "Rock_Volcanic"
    },
    {
      "x": -5,
      "y": -7,
      "z": -7,
      "name": "Rock_Volcanic"
    },
    {
      "x": -5,
      "y": -6,
      "z": -7,
      "name": "Rock_Volcanic_Cracked_Lava"
    },
    {
      "x": -5,
      "y": -5,
      "z": -7,
      "name": "Rock_Volcanic"
    },
    {
      "x": -5,
      "y": -4,
      "z": -7,
      "name": "Rock_Volcanic"
    },
    {
      "x": -5,
      "y": -3,
      "z": -7,
      "name": "Rock_Volcanic"
    },
    {
      "x": -5,
      "y": -2,
      "z": -7,
      "name": "Rock_Volcanic"
    },
    {
      "x": -5,
      "y": -1,
      "z": -7,
      "name": "Rock_Volcanic"
    },
    {
      "x": -5,
      "y": -11,
      "z": -6,
      "name": "Rock_Volcanic"
    },
    {
      "x": -5,
      "y": -10,
      "z": -6,
      "name": "Rock_Volcanic_Cracked_Lava"
    },
    {
      "x": -5,
      "y": -9,
      "z": -6,
      "name": "Rock_Volcanic"
    },
    {
      "x": -5,
      "y": -8,
      "z": -6,
      "name": "Rock_Volcanic"
    },
    {
      "x": -5,
      "y": -7,
      "z": -6,
      "name": "Rock_Volcanic"
    },
    {
      "x": -5,
      "y": -6,
      "z": -6,
      "name": "Rock_Volcanic_Cracked_Lava"
    },
    {
      "x": -5,
      "y": -5,
      "z": -6,
      "name": "Rock_Volcanic"
    },
    {
      "x": -5,
      "y": -4,
      "z": -6,
      "name": "Rock_Volcanic"
    },
    {
      "x": -5,
      "y": -3,
      "z": -6,
      "name": "Rock_Volcanic"
    },
    {
      "x": -5,
      "y": -2,
      "z": -6,
      "name": "Rock_Volcanic_Cracked_Lava"
    },
    {
      "x": -5,
      "y": -1,
      "z": -6,
      "name": "Rock_Volcanic_Cracked_Lava"
    },
    {
      "x": -5,
      "y": 0,
      "z": -6,
      "name": "Rock_Volcanic"
    },
    {
      "x": -5,
      "y": -11,
      "z": -5,
      "name": "Rock_Volcanic_Cracked_Lava"
    },
    {
      "x": -5,
      "y": -10,
      "z": -5,
      "name": "Rock_Volcanic"
    },
    {
      "x": -5,
      "y": -9,
      "z": -5,
      "name": "Rock_Volcanic_Cracked_Lava"
    },
    {
      "x": -5,
      "y": -8,
      "z": -5,
      "name": "Rock_Volcanic"
    },
    {
      "x": -5,
      "y": -7,
      "z": -5,
      "name": "Rock_Volcanic"
    },
    {
      "x": -5,
      "y": -6,
      "z": -5,
      "name": "Rock_Volcanic"
    },
    {
      "x": -5,
      "y": -5,
      "z": -5,
      "name": "Rock_Volcanic"
    },
    {
      "x": -5,
      "y": -4,
      "z": -5,
      "name": "Rock_Volcanic"
    },
    {
      "x": -5,
      "y": -3,
      "z": -5,
      "name": "Rock_Volcanic"
    },
    {
      "x": -5,
      "y": -2,
      "z": -5,
      "name": "Rock_Volcanic"
    },
    {
      "x": -5,
      "y": -1,
      "z": -5,
      "name": "Rock_Volcanic"
    },
    {
      "x": -5,
      "y": 0,
      "z": -5,
      "name": "Rock_Volcanic"
    },
    {
      "x": -5,
      "y": 1,
      "z": -5,
      "name": "Rock_Volcanic"
    },
    {
      "x": -5,
      "y": 2,
      "z": -5,
      "name": "Rock_Volcanic"
    },
    {
      "x": -5,
      "y": -9,
      "z": -4,
      "name": "Rock_Volcanic_Cracked_Lava"
    },
    {
      "x": -5,
      "y": -8,
      "z": -4,
      "name": "Rock_Volcanic"
    },
    {
      "x": -5,
      "y": -7,
      "z": -4,
      "name": "Rock_Volcanic_Cracked_Lava"
    },
    {
      "x": -5,
      "y": -6,
      "z": -4,
      "name": "Rock_Volcanic_Cracked_Lava"
    },
    {
      "x": -5,
      "y": -5,
      "z": -4,
      "name": "Rock_Volcanic"
    },
    {
      "x": -5,
      "y": -4,
      "z": -4,
      "name": "Rock_Volcanic_Cracked_Lava"
    },
    {
      "x": -5,
      "y": -3,
      "z": -4,
      "name": "Rock_Volcanic"
    },
    {
      "x": -5,
      "y": -2,
      "z": -4,
      "name": "Rock_Volcanic"
    },
    {
      "x": -5,
      "y": -1,
      "z": -4,
      "name": "Rock_Volcanic"
    },
    {
      "x": -5,
      "y": 0,
      "z": -4,
      "name": "Rock_Volcanic"
    },
    {
      "x": -5,
      "y": 1,
      "z": -4,
      "name": "Rock_Volcanic"
    },
    {
      "x": -5,
      "y": 2,
      "z": -4,
      "name": "Rock_Volcanic"
    },
    {
      "x": -5,
      "y": 3,
      "z": -4,
      "name": "Rock_Volcanic"
    },
    {
      "x": -5,
      "y": 4,
      "z": -4,
      "name": "Rock_Volcanic"
    },
    {
      "x": -5,
      "y": -8,
      "z": -3,
      "name": "Rock_Volcanic"
    },
    {
      "x": -5,
      "y": -7,
      "z": -3,
      "name": "Rock_Volcanic"
    },
    {
      "x": -5,
      "y": -6,
      "z": -3,
      "name": "Rock_Volcanic_Cracked_Lava"
    },
    {
      "x": -5,
      "y": -5,
      "z": -3,
      "name": "Rock_Volcanic_Cracked_Lava"
    },
    {
      "x": -5,
      "y": -4,
      "z": -3,
      "name": "Rock_Volcanic"
    },
    {
      "x": -5,
      "y": -3,
      "z": -3,
      "name": "Rock_Volcanic_Cracked_Lava"
    },
    {
      "x": -5,
      "y": -2,
      "z": -3,
      "name": "Rock_Volcanic_Cracked_Lava"
    },
    {
      "x": -5,
      "y": -1,
      "z": -3,
      "name": "Rock_Volcanic"
    },
    {
      "x": -5,
      "y": 0,
      "z": -3,
      "name": "Rock_Volcanic"
    },
    {
      "x": -5,
      "y": 1,
      "z": -3,
      "name": "Rock_Volcanic"
    },
    {
      "x": -5,
      "y": 2,
      "z": -3,
      "name": "Rock_Volcanic_Cracked_Lava"
    },
    {
      "x": -5,
      "y": 3,
      "z": -3,
      "name": "Rock_Volcanic_Cracked_Lava"
    },
    {
      "x": -5,
      "y": 4,
      "z": -3,
      "name": "Rock_Volcanic_Cracked_Lava"
    },
    {
      "x": -5,
      "y": 5,
      "z": -3,
      "name": "Rock_Volcanic_Cracked_Lava"
    },
    {
      "x": -5,
      "y": -7,
      "z": -2,
      "name": "Rock_Volcanic_Cracked_Lava"
    },
    {
      "x": -5,
      "y": -6,
      "z": -2,
      "name": "Rock_Volcanic"
    },
    {
      "x": -5,
      "y": -5,
      "z": -2,
      "name": "Rock_Volcanic"
    },
    {
      "x": -5,
      "y": -4,
      "z": -2,
      "name": "Rock_Volcanic"
    },
    {
      "x": -5,
      "y": -3,
      "z": -2,
      "name": "Rock_Volcanic"
    },
    {
      "x": -5,
      "y": -2,
      "z": -2,
      "name": "Rock_Volcanic"
    },
    {
      "x": -5,
      "y": -1,
      "z": -2,
      "name": "Rock_Volcanic_Cracked_Lava"
    },
    {
      "x": -5,
      "y": 0,
      "z": -2,
      "name": "Rock_Volcanic"
    },
    {
      "x": -5,
      "y": 1,
      "z": -2,
      "name": "Rock_Volcanic"
    },
    {
      "x": -5,
      "y": 2,
      "z": -2,
      "name": "Rock_Volcanic"
    },
    {
      "x": -5,
      "y": 3,
      "z": -2,
      "name": "Rock_Volcanic"
    },
    {
      "x": -5,
      "y": 4,
      "z": -2,
      "name": "Rock_Volcanic_Cracked_Lava"
    },
    {
      "x": -5,
      "y": 5,
      "z": -2,
      "name": "Rock_Volcanic"
    },
    {
      "x": -5,
      "y": 6,
      "z": -2,
      "name": "Rock_Volcanic"
    },
    {
      "x": -5,
      "y": -6,
      "z": -1,
      "name": "Rock_Volcanic"
    },
    {
      "x": -5,
      "y": -5,
      "z": -1,
      "name": "Rock_Volcanic"
    },
    {
      "x": -5,
      "y": -4,
      "z": -1,
      "name": "Rock_Volcanic"
    },
    {
      "x": -5,
      "y": -3,
      "z": -1,
      "name": "Rock_Volcanic"
    },
    {
      "x": -5,
      "y": -2,
      "z": -1,
      "name": "Rock_Volcanic"
    },
    {
      "x": -5,
      "y": -1,
      "z": -1,
      "name": "Rock_Volcanic_Cracked_Lava"
    },
    {
      "x": -5,
      "y": 0,
      "z": -1,
      "name": "Rock_Volcanic"
    },
    {
      "x": -5,
      "y": 1,
      "z": -1,
      "name": "Rock_Volcanic"
    },
    {
      "x": -5,
      "y": 2,
      "z": -1,
      "name": "Rock_Volcanic"
    },
    {
      "x": -5,
      "y": 3,
      "z": -1,
      "name": "Rock_Volcanic_Cracked_Lava"
    },
    {
      "x": -5,
      "y": 4,
      "z": -1,
      "name": "Rock_Volcanic"
    },
    {
      "x": -5,
      "y": 5,
      "z": -1,
      "name": "Rock_Volcanic"
    },
    {
      "x": -5,
      "y": 6,
      "z": -1,
      "name": "Rock_Volcanic"
    },
    {
      "x": -5,
      "y": 7,
      "z": -1,
      "name": "Rock_Volcanic_Cracked_Lava"
    },
    {
      "x": -5,
      "y": -5,
      "z": 0,
      "name": "Rock_Volcanic"
    },
    {
      "x": -5,
      "y": -4,
      "z": 0,
      "name": "Rock_Volcanic"
    },
    {
      "x": -5,
      "y": -3,
      "z": 0,
      "name": "Rock_Volcanic"
    },
    {
      "x": -5,
      "y": -2,
      "z": 0,
      "name": "Rock_Volcanic"
    },
    {
      "x": -5,
      "y": -1,
      "z": 0,
      "name": "Rock_Volcanic_Cracked_Lava"
    },
    {
      "x": -5,
      "y": 0,
      "z": 0,
      "name": "Rock_Volcanic"
    },
    {
      "x": -5,
      "y": 1,
      "z": 0,
      "name": "Rock_Volcanic"
    },
    {
      "x": -5,
      "y": 2,
      "z": 0,
      "name": "Rock_Volcanic"
    },
    {
      "x": -5,
      "y": 3,
      "z": 0,
      "name": "Rock_Volcanic"
    },
    {
      "x": -5,
      "y": 4,
      "z": 0,
      "name": "Rock_Volcanic"
    },
    {
      "x": -5,
      "y": 5,
      "z": 0,
      "name": "Rock_Volcanic"
    },
    {
      "x": -5,
      "y": 6,
      "z": 0,
      "name": "Rock_Volcanic"
    },
    {
      "x": -5,
      "y": 7,
      "z": 0,
      "name": "Rock_Volcanic"
    },
    {
      "x": -5,
      "y": 8,
      "z": 0,
      "name": "Rock_Volcanic"
    },
    {
      "x": -5,
      "y": -4,
      "z": 1,
      "name": "Rock_Volcanic"
    },
    {
      "x": -5,
      "y": -3,
      "z": 1,
      "name": "Rock_Volcanic"
    },
    {
      "x": -5,
      "y": -2,
      "z": 1,
      "name": "Rock_Volcanic"
    },
    {
      "x": -5,
      "y": -1,
      "z": 1,
      "name": "Rock_Volcanic"
    },
    {
      "x": -5,
      "y": 0,
      "z": 1,
      "name": "Rock_Volcanic"
    },
    {
      "x": -5,
      "y": 1,
      "z": 1,
      "name": "Rock_Volcanic"
    },
    {
      "x": -5,
      "y": 2,
      "z": 1,
      "name": "Rock_Volcanic"
    },
    {
      "x": -5,
      "y": 3,
      "z": 1,
      "name": "Rock_Volcanic"
    },
    {
      "x": -5,
      "y": 4,
      "z": 1,
      "name": "Rock_Volcanic"
    },
    {
      "x": -5,
      "y": 5,
      "z": 1,
      "name": "Rock_Volcanic"
    },
    {
      "x": -5,
      "y": 6,
      "z": 1,
      "name": "Rock_Volcanic"
    },
    {
      "x": -5,
      "y": 7,
      "z": 1,
      "name": "Rock_Volcanic"
    },
    {
      "x": -5,
      "y": 8,
      "z": 1,
      "name": "Rock_Volcanic"
    },
    {
      "x": -5,
      "y": -4,
      "z": 2,
      "name": "Rock_Volcanic"
    },
    {
      "x": -5,
      "y": -3,
      "z": 2,
      "name": "Rock_Volcanic"
    },
    {
      "x": -5,
      "y": -2,
      "z": 2,
      "name": "Rock_Volcanic"
    },
    {
      "x": -5,
      "y": -1,
      "z": 2,
      "name": "Rock_Volcanic_Cracked_Lava"
    },
    {
      "x": -5,
      "y": 0,
      "z": 2,
      "name": "Rock_Volcanic"
    },
    {
      "x": -5,
      "y": 1,
      "z": 2,
      "name": "Rock_Volcanic"
    },
    {
      "x": -5,
      "y": 2,
      "z": 2,
      "name": "Rock_Volcanic_Cracked_Lava"
    },
    {
      "x": -5,
      "y": 3,
      "z": 2,
      "name": "Rock_Volcanic_Cracked_Lava"
    },
    {
      "x": -5,
      "y": 4,
      "z": 2,
      "name": "Rock_Volcanic"
    },
    {
      "x": -5,
      "y": 5,
      "z": 2,
      "name": "Rock_Volcanic_Cracked_Lava"
    },
    {
      "x": -5,
      "y": 6,
      "z": 2,
      "name": "Rock_Volcanic"
    },
    {
      "x": -5,
      "y": 7,
      "z": 2,
      "name": "Rock_Volcanic_Cracked_Lava"
    },
    {
      "x": -5,
      "y": -3,
      "z": 3,
      "name": "Rock_Volcanic_Cracked_Lava"
    },
    {
      "x": -5,
      "y": -2,
      "z": 3,
      "name": "Rock_Volcanic"
    },
    {
      "x": -5,
      "y": -1,
      "z": 3,
      "name": "Rock_Volcanic"
    },
    {
      "x": -5,
      "y": 0,
      "z": 3,
      "name": "Rock_Volcanic"
    },
    {
      "x": -5,
      "y": 1,
      "z": 3,
      "name": "Rock_Volcanic"
    },
    {
      "x": -5,
      "y": 2,
      "z": 3,
      "name": "Rock_Volcanic"
    },
    {
      "x": -5,
      "y": 3,
      "z": 3,
      "name": "Rock_Volcanic_Cracked_Lava"
    },
    {
      "x": -5,
      "y": 4,
      "z": 3,
      "name": "Rock_Volcanic_Cracked_Lava"
    },
    {
      "x": -5,
      "y": 5,
      "z": 3,
      "name": "Rock_Volcanic"
    },
    {
      "x": -5,
      "y": 6,
      "z": 3,
      "name": "Rock_Volcanic"
    },
    {
      "x": -5,
      "y": 7,
      "z": 3,
      "name": "Rock_Volcanic"
    },
    {
      "x": -5,
      "y": -4,
      "z": 4,
      "name": "Rock_Volcanic_Stalactite_Large",
      "filler": 31744,
      "rotation": 8
    },
    {
      "x": -5,
      "y": -3,
      "z": 4,
      "name": "Rock_Volcanic_Stalactite_Large",
      "rotation": 8
    },
    {
      "x": -5,
      "y": -2,
      "z": 4,
      "name": "Rock_Volcanic"
    },
    {
      "x": -5,
      "y": -1,
      "z": 4,
      "name": "Rock_Volcanic"
    },
    {
      "x": -5,
      "y": 0,
      "z": 4,
      "name": "Rock_Volcanic_Cracked_Lava"
    },
    {
      "x": -5,
      "y": 1,
      "z": 4,
      "name": "Rock_Volcanic"
    },
    {
      "x": -5,
      "y": 2,
      "z": 4,
      "name": "Rock_Volcanic"
    },
    {
      "x": -5,
      "y": 3,
      "z": 4,
      "name": "Rock_Volcanic_Cracked_Lava"
    },
    {
      "x": -5,
      "y": 4,
      "z": 4,
      "name": "Rock_Volcanic"
    },
    {
      "x": -5,
      "y": 5,
      "z": 4,
      "name": "Rock_Volcanic"
    },
    {
      "x": -5,
      "y": 6,
      "z": 4,
      "name": "Rock_Volcanic"
    },
    {
      "x": -5,
      "y": 0,
      "z": 5,
      "name": "Rock_Volcanic"
    },
    {
      "x": -5,
      "y": 1,
      "z": 5,
      "name": "Rock_Volcanic"
    },
    {
      "x": -5,
      "y": 2,
      "z": 5,
      "name": "Rock_Volcanic"
    },
    {
      "x": -5,
      "y": 3,
      "z": 5,
      "name": "Rock_Volcanic"
    },
    {
      "x": -5,
      "y": 4,
      "z": 5,
      "name": "Rock_Volcanic"
    },
    {
      "x": -5,
      "y": 5,
      "z": 5,
      "name": "Rock_Volcanic_Cracked_Lava"
    },
    {
      "x": -5,
      "y": 1,
      "z": 6,
      "name": "Rock_Volcanic"
    },
    {
      "x": -5,
      "y": 2,
      "z": 6,
      "name": "Rock_Volcanic"
    },
    {
      "x": -5,
      "y": 3,
      "z": 6,
      "name": "Rock_Volcanic"
    },
    {
      "x": -5,
      "y": 4,
      "z": 6,
      "name": "Rock_Volcanic"
    },
    {
      "x": -4,
      "y": -23,
      "z": -23,
      "name": "Rock_Volcanic_Cracked_Lava"
    },
    {
      "x": -4,
      "y": -26,
      "z": -22,
      "name": "Rock_Volcanic_Cracked_Lava"
    },
    {
      "x": -4,
      "y": -25,
      "z": -22,
      "name": "Rock_Volcanic"
    },
    {
      "x": -4,
      "y": -24,
      "z": -22,
      "name": "Rock_Volcanic_Cracked_Lava"
    },
    {
      "x": -4,
      "y": -23,
      "z": -22,
      "name": "Rock_Volcanic"
    },
    {
      "x": -4,
      "y": -22,
      "z": -22,
      "name": "Rock_Volcanic"
    },
    {
      "x": -4,
      "y": -25,
      "z": -21,
      "name": "Rock_Volcanic"
    },
    {
      "x": -4,
      "y": -24,
      "z": -21,
      "name": "Rock_Volcanic"
    },
    {
      "x": -4,
      "y": -23,
      "z": -21,
      "name": "Rock_Volcanic_Cracked_Lava"
    },
    {
      "x": -4,
      "y": -22,
      "z": -21,
      "name": "Rock_Volcanic"
    },
    {
      "x": -4,
      "y": -21,
      "z": -21,
      "name": "Rock_Volcanic"
    },
    {
      "x": -4,
      "y": -25,
      "z": -20,
      "name": "Rock_Volcanic_Cracked_Lava"
    },
    {
      "x": -4,
      "y": -24,
      "z": -20,
      "name": "Rock_Volcanic"
    },
    {
      "x": -4,
      "y": -23,
      "z": -20,
      "name": "Rock_Volcanic_Cracked_Lava"
    },
    {
      "x": -4,
      "y": -22,
      "z": -20,
      "name": "Rock_Volcanic"
    },
    {
      "x": -4,
      "y": -21,
      "z": -20,
      "name": "Rock_Volcanic"
    },
    {
      "x": -4,
      "y": -20,
      "z": -20,
      "name": "Rock_Volcanic"
    },
    {
      "x": -4,
      "y": -24,
      "z": -19,
      "name": "Rock_Volcanic"
    },
    {
      "x": -4,
      "y": -23,
      "z": -19,
      "name": "Rock_Volcanic"
    },
    {
      "x": -4,
      "y": -22,
      "z": -19,
      "name": "Rock_Volcanic"
    },
    {
      "x": -4,
      "y": -21,
      "z": -19,
      "name": "Rock_Volcanic"
    },
    {
      "x": -4,
      "y": -20,
      "z": -19,
      "name": "Rock_Volcanic_Cracked_Lava"
    },
    {
      "x": -4,
      "y": -19,
      "z": -19,
      "name": "Rock_Volcanic"
    },
    {
      "x": -4,
      "y": -18,
      "z": -19,
      "name": "Rock_Volcanic"
    },
    {
      "x": -4,
      "y": -23,
      "z": -18,
      "name": "Rock_Volcanic"
    },
    {
      "x": -4,
      "y": -22,
      "z": -18,
      "name": "Rock_Volcanic"
    },
    {
      "x": -4,
      "y": -21,
      "z": -18,
      "name": "Rock_Volcanic"
    },
    {
      "x": -4,
      "y": -20,
      "z": -18,
      "name": "Rock_Volcanic"
    },
    {
      "x": -4,
      "y": -19,
      "z": -18,
      "name": "Rock_Volcanic"
    },
    {
      "x": -4,
      "y": -18,
      "z": -18,
      "name": "Rock_Volcanic"
    },
    {
      "x": -4,
      "y": -17,
      "z": -18,
      "name": "Rock_Volcanic"
    },
    {
      "x": -4,
      "y": -21,
      "z": -17,
      "name": "Rock_Volcanic"
    },
    {
      "x": -4,
      "y": -20,
      "z": -17,
      "name": "Rock_Volcanic"
    },
    {
      "x": -4,
      "y": -19,
      "z": -17,
      "name": "Rock_Volcanic_Cracked_Lava"
    },
    {
      "x": -4,
      "y": -18,
      "z": -17,
      "name": "Rock_Volcanic"
    },
    {
      "x": -4,
      "y": -17,
      "z": -17,
      "name": "Rock_Volcanic"
    },
    {
      "x": -4,
      "y": -16,
      "z": -17,
      "name": "Rock_Volcanic"
    },
    {
      "x": -4,
      "y": -15,
      "z": -17,
      "name": "Rock_Volcanic"
    },
    {
      "x": -4,
      "y": -20,
      "z": -16,
      "name": "Rock_Volcanic"
    },
    {
      "x": -4,
      "y": -19,
      "z": -16,
      "name": "Rock_Volcanic"
    },
    {
      "x": -4,
      "y": -18,
      "z": -16,
      "name": "Rock_Volcanic"
    },
    {
      "x": -4,
      "y": -17,
      "z": -16,
      "name": "Rock_Volcanic"
    },
    {
      "x": -4,
      "y": -16,
      "z": -16,
      "name": "Rock_Volcanic"
    },
    {
      "x": -4,
      "y": -15,
      "z": -16,
      "name": "Rock_Volcanic"
    },
    {
      "x": -4,
      "y": -14,
      "z": -16,
      "name": "Rock_Volcanic"
    },
    {
      "x": -4,
      "y": -13,
      "z": -16,
      "name": "Rock_Volcanic"
    },
    {
      "x": -4,
      "y": -19,
      "z": -15,
      "name": "Rock_Volcanic"
    },
    {
      "x": -4,
      "y": -18,
      "z": -15,
      "name": "Rock_Volcanic"
    },
    {
      "x": -4,
      "y": -17,
      "z": -15,
      "name": "Rock_Volcanic_Cracked_Lava"
    },
    {
      "x": -4,
      "y": -16,
      "z": -15,
      "name": "Rock_Volcanic"
    },
    {
      "x": -4,
      "y": -15,
      "z": -15,
      "name": "Rock_Volcanic"
    },
    {
      "x": -4,
      "y": -14,
      "z": -15,
      "name": "Rock_Volcanic"
    },
    {
      "x": -4,
      "y": -13,
      "z": -15,
      "name": "Rock_Volcanic_Cracked_Lava"
    },
    {
      "x": -4,
      "y": -12,
      "z": -15,
      "name": "Rock_Volcanic"
    },
    {
      "x": -4,
      "y": -18,
      "z": -14,
      "name": "Rock_Volcanic"
    },
    {
      "x": -4,
      "y": -17,
      "z": -14,
      "name": "Rock_Volcanic"
    },
    {
      "x": -4,
      "y": -16,
      "z": -14,
      "name": "Rock_Volcanic_Cracked_Lava"
    },
    {
      "x": -4,
      "y": -15,
      "z": -14,
      "name": "Rock_Volcanic_Cracked_Lava"
    },
    {
      "x": -4,
      "y": -14,
      "z": -14,
      "name": "Rock_Volcanic"
    },
    {
      "x": -4,
      "y": -13,
      "z": -14,
      "name": "Rock_Volcanic"
    },
    {
      "x": -4,
      "y": -12,
      "z": -14,
      "name": "Rock_Volcanic"
    },
    {
      "x": -4,
      "y": -11,
      "z": -14,
      "name": "Rock_Volcanic"
    },
    {
      "x": -4,
      "y": -18,
      "z": -13,
      "name": "Rock_Volcanic"
    },
    {
      "x": -4,
      "y": -17,
      "z": -13,
      "name": "Rock_Volcanic_Cracked_Lava"
    },
    {
      "x": -4,
      "y": -16,
      "z": -13,
      "name": "Rock_Volcanic"
    },
    {
      "x": -4,
      "y": -15,
      "z": -13,
      "name": "Rock_Volcanic"
    },
    {
      "x": -4,
      "y": -14,
      "z": -13,
      "name": "Rock_Volcanic_Cracked_Lava"
    },
    {
      "x": -4,
      "y": -13,
      "z": -13,
      "name": "Rock_Volcanic_Cracked_Lava"
    },
    {
      "x": -4,
      "y": -12,
      "z": -13,
      "name": "Rock_Volcanic"
    },
    {
      "x": -4,
      "y": -11,
      "z": -13,
      "name": "Rock_Volcanic"
    },
    {
      "x": -4,
      "y": -10,
      "z": -13,
      "name": "Rock_Volcanic"
    },
    {
      "x": -4,
      "y": -17,
      "z": -12,
      "name": "Rock_Volcanic"
    },
    {
      "x": -4,
      "y": -16,
      "z": -12,
      "name": "Rock_Volcanic_Cracked_Lava"
    },
    {
      "x": -4,
      "y": -15,
      "z": -12,
      "name": "Rock_Volcanic"
    },
    {
      "x": -4,
      "y": -14,
      "z": -12,
      "name": "Rock_Volcanic"
    },
    {
      "x": -4,
      "y": -13,
      "z": -12,
      "name": "Rock_Volcanic"
    },
    {
      "x": -4,
      "y": -12,
      "z": -12,
      "name": "Rock_Volcanic"
    },
    {
      "x": -4,
      "y": -11,
      "z": -12,
      "name": "Rock_Volcanic"
    },
    {
      "x": -4,
      "y": -10,
      "z": -12,
      "name": "Rock_Volcanic"
    },
    {
      "x": -4,
      "y": -9,
      "z": -12,
      "name": "Rock_Volcanic"
    },
    {
      "x": -4,
      "y": -16,
      "z": -11,
      "name": "Rock_Volcanic"
    },
    {
      "x": -4,
      "y": -15,
      "z": -11,
      "name": "Rock_Volcanic"
    },
    {
      "x": -4,
      "y": -14,
      "z": -11,
      "name": "Rock_Volcanic"
    },
    {
      "x": -4,
      "y": -13,
      "z": -11,
      "name": "Rock_Volcanic"
    },
    {
      "x": -4,
      "y": -12,
      "z": -11,
      "name": "Rock_Volcanic"
    },
    {
      "x": -4,
      "y": -11,
      "z": -11,
      "name": "Rock_Volcanic"
    },
    {
      "x": -4,
      "y": -10,
      "z": -11,
      "name": "Rock_Volcanic"
    },
    {
      "x": -4,
      "y": -9,
      "z": -11,
      "name": "Rock_Volcanic"
    },
    {
      "x": -4,
      "y": -8,
      "z": -11,
      "name": "Rock_Volcanic"
    },
    {
      "x": -4,
      "y": -7,
      "z": -11,
      "name": "Rock_Volcanic"
    },
    {
      "x": -4,
      "y": -6,
      "z": -11,
      "name": "Rock_Volcanic"
    },
    {
      "x": -4,
      "y": -15,
      "z": -10,
      "name": "Rock_Volcanic"
    },
    {
      "x": -4,
      "y": -14,
      "z": -10,
      "name": "Rock_Volcanic"
    },
    {
      "x": -4,
      "y": -13,
      "z": -10,
      "name": "Rock_Volcanic"
    },
    {
      "x": -4,
      "y": -12,
      "z": -10,
      "name": "Rock_Volcanic"
    },
    {
      "x": -4,
      "y": -11,
      "z": -10,
      "name": "Rock_Volcanic"
    },
    {
      "x": -4,
      "y": -10,
      "z": -10,
      "name": "Rock_Volcanic"
    },
    {
      "x": -4,
      "y": -9,
      "z": -10,
      "name": "Rock_Volcanic"
    },
    {
      "x": -4,
      "y": -8,
      "z": -10,
      "name": "Rock_Volcanic"
    },
    {
      "x": -4,
      "y": -7,
      "z": -10,
      "name": "Rock_Volcanic"
    },
    {
      "x": -4,
      "y": -6,
      "z": -10,
      "name": "Rock_Volcanic"
    },
    {
      "x": -4,
      "y": -5,
      "z": -10,
      "name": "Rock_Volcanic"
    },
    {
      "x": -4,
      "y": -14,
      "z": -9,
      "name": "Rock_Volcanic"
    },
    {
      "x": -4,
      "y": -13,
      "z": -9,
      "name": "Rock_Volcanic_Cracked_Lava"
    },
    {
      "x": -4,
      "y": -12,
      "z": -9,
      "name": "Rock_Volcanic_Cracked_Lava"
    },
    {
      "x": -4,
      "y": -11,
      "z": -9,
      "name": "Rock_Volcanic"
    },
    {
      "x": -4,
      "y": -10,
      "z": -9,
      "name": "Rock_Volcanic"
    },
    {
      "x": -4,
      "y": -9,
      "z": -9,
      "name": "Rock_Volcanic"
    },
    {
      "x": -4,
      "y": -8,
      "z": -9,
      "name": "Rock_Volcanic"
    },
    {
      "x": -4,
      "y": -7,
      "z": -9,
      "name": "Rock_Volcanic"
    },
    {
      "x": -4,
      "y": -6,
      "z": -9,
      "name": "Rock_Volcanic"
    },
    {
      "x": -4,
      "y": -5,
      "z": -9,
      "name": "Rock_Volcanic_Cracked_Lava"
    },
    {
      "x": -4,
      "y": -4,
      "z": -9,
      "name": "Rock_Volcanic"
    },
    {
      "x": -4,
      "y": -12,
      "z": -8,
      "name": "Rock_Volcanic"
    },
    {
      "x": -4,
      "y": -11,
      "z": -8,
      "name": "Rock_Volcanic"
    },
    {
      "x": -4,
      "y": -10,
      "z": -8,
      "name": "Rock_Volcanic"
    },
    {
      "x": -4,
      "y": -9,
      "z": -8,
      "name": "Rock_Volcanic_Cracked_Lava"
    },
    {
      "x": -4,
      "y": -8,
      "z": -8,
      "name": "Rock_Volcanic"
    },
    {
      "x": -4,
      "y": -7,
      "z": -8,
      "name": "Rock_Volcanic"
    },
    {
      "x": -4,
      "y": -6,
      "z": -8,
      "name": "Rock_Volcanic_Cracked_Lava"
    },
    {
      "x": -4,
      "y": -5,
      "z": -8,
      "name": "Rock_Volcanic_Cracked_Lava"
    },
    {
      "x": -4,
      "y": -4,
      "z": -8,
      "name": "Rock_Volcanic"
    },
    {
      "x": -4,
      "y": -3,
      "z": -8,
      "name": "Rock_Volcanic"
    },
    {
      "x": -4,
      "y": -2,
      "z": -8,
      "name": "Rock_Volcanic"
    },
    {
      "x": -4,
      "y": -11,
      "z": -7,
      "name": "Rock_Volcanic_Cracked_Lava"
    },
    {
      "x": -4,
      "y": -10,
      "z": -7,
      "name": "Rock_Volcanic"
    },
    {
      "x": -4,
      "y": -9,
      "z": -7,
      "name": "Rock_Volcanic_Cracked_Lava"
    },
    {
      "x": -4,
      "y": -8,
      "z": -7,
      "name": "Rock_Volcanic"
    },
    {
      "x": -4,
      "y": -7,
      "z": -7,
      "name": "Rock_Volcanic"
    },
    {
      "x": -4,
      "y": -6,
      "z": -7,
      "name": "Rock_Volcanic"
    },
    {
      "x": -4,
      "y": -5,
      "z": -7,
      "name": "Rock_Volcanic"
    },
    {
      "x": -4,
      "y": -4,
      "z": -7,
      "name": "Rock_Volcanic"
    },
    {
      "x": -4,
      "y": -3,
      "z": -7,
      "name": "Rock_Volcanic"
    },
    {
      "x": -4,
      "y": -2,
      "z": -7,
      "name": "Rock_Volcanic"
    },
    {
      "x": -4,
      "y": -1,
      "z": -7,
      "name": "Rock_Volcanic"
    },
    {
      "x": -4,
      "y": -11,
      "z": -6,
      "name": "Rock_Volcanic"
    },
    {
      "x": -4,
      "y": -10,
      "z": -6,
      "name": "Rock_Volcanic"
    },
    {
      "x": -4,
      "y": -9,
      "z": -6,
      "name": "Rock_Volcanic"
    },
    {
      "x": -4,
      "y": -8,
      "z": -6,
      "name": "Rock_Volcanic"
    },
    {
      "x": -4,
      "y": -7,
      "z": -6,
      "name": "Rock_Volcanic"
    },
    {
      "x": -4,
      "y": -6,
      "z": -6,
      "name": "Rock_Volcanic_Cracked_Lava"
    },
    {
      "x": -4,
      "y": -5,
      "z": -6,
      "name": "Rock_Volcanic"
    },
    {
      "x": -4,
      "y": -4,
      "z": -6,
      "name": "Rock_Volcanic"
    },
    {
      "x": -4,
      "y": -3,
      "z": -6,
      "name": "Rock_Volcanic"
    },
    {
      "x": -4,
      "y": -2,
      "z": -6,
      "name": "Rock_Volcanic_Cracked_Lava"
    },
    {
      "x": -4,
      "y": -1,
      "z": -6,
      "name": "Rock_Volcanic"
    },
    {
      "x": -4,
      "y": 0,
      "z": -6,
      "name": "Rock_Volcanic_Cracked_Lava"
    },
    {
      "x": -4,
      "y": -10,
      "z": -5,
      "name": "Rock_Volcanic"
    },
    {
      "x": -4,
      "y": -9,
      "z": -5,
      "name": "Rock_Volcanic"
    },
    {
      "x": -4,
      "y": -8,
      "z": -5,
      "name": "Rock_Volcanic"
    },
    {
      "x": -4,
      "y": -7,
      "z": -5,
      "name": "Rock_Volcanic"
    },
    {
      "x": -4,
      "y": -6,
      "z": -5,
      "name": "Rock_Volcanic"
    },
    {
      "x": -4,
      "y": -5,
      "z": -5,
      "name": "Rock_Volcanic"
    },
    {
      "x": -4,
      "y": -4,
      "z": -5,
      "name": "Rock_Volcanic"
    },
    {
      "x": -4,
      "y": -3,
      "z": -5,
      "name": "Rock_Volcanic_Cracked_Lava"
    },
    {
      "x": -4,
      "y": -2,
      "z": -5,
      "name": "Rock_Volcanic"
    },
    {
      "x": -4,
      "y": -1,
      "z": -5,
      "name": "Rock_Volcanic_Cracked_Lava"
    },
    {
      "x": -4,
      "y": 0,
      "z": -5,
      "name": "Rock_Volcanic"
    },
    {
      "x": -4,
      "y": 1,
      "z": -5,
      "name": "Rock_Volcanic_Cracked_Lava"
    },
    {
      "x": -4,
      "y": 2,
      "z": -5,
      "name": "Rock_Volcanic_Cracked_Lava"
    },
    {
      "x": -4,
      "y": 3,
      "z": -5,
      "name": "Rock_Volcanic_Cracked_Lava"
    },
    {
      "x": -4,
      "y": -9,
      "z": -4,
      "name": "Rock_Volcanic_Cracked_Lava"
    },
    {
      "x": -4,
      "y": -8,
      "z": -4,
      "name": "Rock_Volcanic"
    },
    {
      "x": -4,
      "y": -7,
      "z": -4,
      "name": "Rock_Volcanic"
    },
    {
      "x": -4,
      "y": -6,
      "z": -4,
      "name": "Rock_Volcanic"
    },
    {
      "x": -4,
      "y": -5,
      "z": -4,
      "name": "Rock_Volcanic"
    },
    {
      "x": -4,
      "y": -4,
      "z": -4,
      "name": "Rock_Volcanic"
    },
    {
      "x": -4,
      "y": -3,
      "z": -4,
      "name": "Rock_Volcanic_Cracked_Lava"
    },
    {
      "x": -4,
      "y": -2,
      "z": -4,
      "name": "Rock_Volcanic"
    },
    {
      "x": -4,
      "y": -1,
      "z": -4,
      "name": "Rock_Volcanic"
    },
    {
      "x": -4,
      "y": 0,
      "z": -4,
      "name": "Rock_Volcanic_Cracked_Lava"
    },
    {
      "x": -4,
      "y": 1,
      "z": -4,
      "name": "Rock_Volcanic"
    },
    {
      "x": -4,
      "y": 2,
      "z": -4,
      "name": "Rock_Volcanic"
    },
    {
      "x": -4,
      "y": 3,
      "z": -4,
      "name": "Rock_Volcanic_Cracked_Lava"
    },
    {
      "x": -4,
      "y": 4,
      "z": -4,
      "name": "Rock_Volcanic"
    },
    {
      "x": -4,
      "y": -8,
      "z": -3,
      "name": "Rock_Volcanic"
    },
    {
      "x": -4,
      "y": -7,
      "z": -3,
      "name": "Rock_Volcanic_Cracked_Lava"
    },
    {
      "x": -4,
      "y": -6,
      "z": -3,
      "name": "Rock_Volcanic"
    },
    {
      "x": -4,
      "y": -5,
      "z": -3,
      "name": "Rock_Volcanic"
    },
    {
      "x": -4,
      "y": -4,
      "z": -3,
      "name": "Rock_Volcanic"
    },
    {
      "x": -4,
      "y": -3,
      "z": -3,
      "name": "Rock_Volcanic_Cracked_Lava"
    },
    {
      "x": -4,
      "y": -2,
      "z": -3,
      "name": "Rock_Volcanic"
    },
    {
      "x": -4,
      "y": -1,
      "z": -3,
      "name": "Rock_Volcanic"
    },
    {
      "x": -4,
      "y": 0,
      "z": -3,
      "name": "Rock_Volcanic"
    },
    {
      "x": -4,
      "y": 1,
      "z": -3,
      "name": "Rock_Volcanic"
    },
    {
      "x": -4,
      "y": 2,
      "z": -3,
      "name": "Rock_Volcanic"
    },
    {
      "x": -4,
      "y": 3,
      "z": -3,
      "name": "Rock_Volcanic"
    },
    {
      "x": -4,
      "y": 4,
      "z": -3,
      "name": "Rock_Volcanic_Cracked_Lava"
    },
    {
      "x": -4,
      "y": 5,
      "z": -3,
      "name": "Rock_Volcanic"
    },
    {
      "x": -4,
      "y": -7,
      "z": -2,
      "name": "Rock_Volcanic_Cracked_Lava"
    },
    {
      "x": -4,
      "y": -6,
      "z": -2,
      "name": "Rock_Volcanic"
    },
    {
      "x": -4,
      "y": -5,
      "z": -2,
      "name": "Rock_Volcanic"
    },
    {
      "x": -4,
      "y": -4,
      "z": -2,
      "name": "Rock_Volcanic"
    },
    {
      "x": -4,
      "y": -3,
      "z": -2,
      "name": "Rock_Volcanic"
    },
    {
      "x": -4,
      "y": -2,
      "z": -2,
      "name": "Rock_Volcanic"
    },
    {
      "x": -4,
      "y": -1,
      "z": -2,
      "name": "Rock_Volcanic"
    },
    {
      "x": -4,
      "y": 0,
      "z": -2,
      "name": "Rock_Volcanic"
    },
    {
      "x": -4,
      "y": 1,
      "z": -2,
      "name": "Rock_Volcanic"
    },
    {
      "x": -4,
      "y": 2,
      "z": -2,
      "name": "Rock_Volcanic"
    },
    {
      "x": -4,
      "y": 3,
      "z": -2,
      "name": "Rock_Volcanic_Cracked_Lava"
    },
    {
      "x": -4,
      "y": 4,
      "z": -2,
      "name": "Rock_Volcanic"
    },
    {
      "x": -4,
      "y": 5,
      "z": -2,
      "name": "Rock_Volcanic"
    },
    {
      "x": -4,
      "y": 6,
      "z": -2,
      "name": "Rock_Volcanic"
    },
    {
      "x": -4,
      "y": -6,
      "z": -1,
      "name": "Rock_Volcanic"
    },
    {
      "x": -4,
      "y": -5,
      "z": -1,
      "name": "Rock_Volcanic"
    },
    {
      "x": -4,
      "y": -4,
      "z": -1,
      "name": "Rock_Volcanic"
    },
    {
      "x": -4,
      "y": -3,
      "z": -1,
      "name": "Rock_Volcanic"
    },
    {
      "x": -4,
      "y": -2,
      "z": -1,
      "name": "Rock_Volcanic"
    },
    {
      "x": -4,
      "y": -1,
      "z": -1,
      "name": "Rock_Volcanic"
    },
    {
      "x": -4,
      "y": 0,
      "z": -1,
      "name": "Rock_Volcanic"
    },
    {
      "x": -4,
      "y": 1,
      "z": -1,
      "name": "Rock_Volcanic_Cracked_Lava"
    },
    {
      "x": -4,
      "y": 2,
      "z": -1,
      "name": "Rock_Volcanic"
    },
    {
      "x": -4,
      "y": 3,
      "z": -1,
      "name": "Rock_Volcanic"
    },
    {
      "x": -4,
      "y": 4,
      "z": -1,
      "name": "Rock_Volcanic"
    },
    {
      "x": -4,
      "y": 5,
      "z": -1,
      "name": "Rock_Volcanic"
    },
    {
      "x": -4,
      "y": 6,
      "z": -1,
      "name": "Rock_Volcanic"
    },
    {
      "x": -4,
      "y": 7,
      "z": -1,
      "name": "Rock_Volcanic"
    },
    {
      "x": -4,
      "y": -5,
      "z": 0,
      "name": "Rock_Volcanic"
    },
    {
      "x": -4,
      "y": -4,
      "z": 0,
      "name": "Rock_Volcanic_Cracked_Lava"
    },
    {
      "x": -4,
      "y": -3,
      "z": 0,
      "name": "Rock_Volcanic_Cracked_Lava"
    },
    {
      "x": -4,
      "y": -2,
      "z": 0,
      "name": "Rock_Volcanic"
    },
    {
      "x": -4,
      "y": -1,
      "z": 0,
      "name": "Rock_Volcanic_Cracked_Lava"
    },
    {
      "x": -4,
      "y": 0,
      "z": 0,
      "name": "Rock_Volcanic"
    },
    {
      "x": -4,
      "y": 1,
      "z": 0,
      "name": "Rock_Volcanic"
    },
    {
      "x": -4,
      "y": 2,
      "z": 0,
      "name": "Rock_Volcanic_Cracked_Lava"
    },
    {
      "x": -4,
      "y": 3,
      "z": 0,
      "name": "Rock_Volcanic"
    },
    {
      "x": -4,
      "y": 4,
      "z": 0,
      "name": "Rock_Volcanic"
    },
    {
      "x": -4,
      "y": 5,
      "z": 0,
      "name": "Rock_Volcanic"
    },
    {
      "x": -4,
      "y": 6,
      "z": 0,
      "name": "Rock_Volcanic"
    },
    {
      "x": -4,
      "y": 7,
      "z": 0,
      "name": "Rock_Volcanic"
    },
    {
      "x": -4,
      "y": 8,
      "z": 0,
      "name": "Rock_Volcanic_Cracked_Lava"
    },
    {
      "x": -4,
      "y": -4,
      "z": 1,
      "name": "Rock_Volcanic"
    },
    {
      "x": -4,
      "y": -3,
      "z": 1,
      "name": "Rock_Volcanic"
    },
    {
      "x": -4,
      "y": -2,
      "z": 1,
      "name": "Rock_Volcanic_Cracked_Lava"
    },
    {
      "x": -4,
      "y": -1,
      "z": 1,
      "name": "Rock_Volcanic"
    },
    {
      "x": -4,
      "y": 0,
      "z": 1,
      "name": "Rock_Volcanic"
    },
    {
      "x": -4,
      "y": 1,
      "z": 1,
      "name": "Rock_Volcanic_Cracked_Lava"
    },
    {
      "x": -4,
      "y": 2,
      "z": 1,
      "name": "Rock_Volcanic_Cracked_Lava"
    },
    {
      "x": -4,
      "y": 3,
      "z": 1,
      "name": "Rock_Volcanic_Cracked_Lava"
    },
    {
      "x": -4,
      "y": 4,
      "z": 1,
      "name": "Rock_Volcanic"
    },
    {
      "x": -4,
      "y": 5,
      "z": 1,
      "name": "Rock_Volcanic_Cracked_Lava"
    },
    {
      "x": -4,
      "y": 6,
      "z": 1,
      "name": "Rock_Volcanic_Cracked_Lava"
    },
    {
      "x": -4,
      "y": 7,
      "z": 1,
      "name": "Rock_Volcanic"
    },
    {
      "x": -4,
      "y": 8,
      "z": 1,
      "name": "Rock_Volcanic"
    },
    {
      "x": -4,
      "y": -4,
      "z": 2,
      "name": "Rock_Volcanic_Cracked_Lava"
    },
    {
      "x": -4,
      "y": -3,
      "z": 2,
      "name": "Rock_Volcanic"
    },
    {
      "x": -4,
      "y": -2,
      "z": 2,
      "name": "Rock_Volcanic_Cracked_Lava"
    },
    {
      "x": -4,
      "y": -1,
      "z": 2,
      "name": "Rock_Volcanic"
    },
    {
      "x": -4,
      "y": 0,
      "z": 2,
      "name": "Rock_Volcanic_Cracked_Lava"
    },
    {
      "x": -4,
      "y": 1,
      "z": 2,
      "name": "Rock_Volcanic_Cracked_Lava"
    },
    {
      "x": -4,
      "y": 2,
      "z": 2,
      "name": "Rock_Volcanic"
    },
    {
      "x": -4,
      "y": 3,
      "z": 2,
      "name": "Rock_Volcanic"
    },
    {
      "x": -4,
      "y": 4,
      "z": 2,
      "name": "Rock_Volcanic"
    },
    {
      "x": -4,
      "y": 5,
      "z": 2,
      "name": "Rock_Volcanic"
    },
    {
      "x": -4,
      "y": 6,
      "z": 2,
      "name": "Rock_Volcanic"
    },
    {
      "x": -4,
      "y": 7,
      "z": 2,
      "name": "Rock_Volcanic"
    },
    {
      "x": -4,
      "y": 8,
      "z": 2,
      "name": "Rock_Volcanic"
    },
    {
      "x": -4,
      "y": 9,
      "z": 2,
      "name": "Rock_Volcanic"
    },
    {
      "x": -4,
      "y": -3,
      "z": 3,
      "name": "Rock_Volcanic_Cracked_Lava"
    },
    {
      "x": -4,
      "y": -2,
      "z": 3,
      "name": "Rock_Volcanic_Cracked_Lava"
    },
    {
      "x": -4,
      "y": -1,
      "z": 3,
      "name": "Rock_Volcanic"
    },
    {
      "x": -4,
      "y": 0,
      "z": 3,
      "name": "Rock_Volcanic"
    },
    {
      "x": -4,
      "y": 1,
      "z": 3,
      "name": "Rock_Volcanic_Cracked_Lava"
    },
    {
      "x": -4,
      "y": 2,
      "z": 3,
      "name": "Rock_Volcanic"
    },
    {
      "x": -4,
      "y": 3,
      "z": 3,
      "name": "Rock_Volcanic"
    },
    {
      "x": -4,
      "y": 4,
      "z": 3,
      "name": "Rock_Volcanic_Cracked_Lava"
    },
    {
      "x": -4,
      "y": 5,
      "z": 3,
      "name": "Rock_Volcanic_Cracked_Lava"
    },
    {
      "x": -4,
      "y": 6,
      "z": 3,
      "name": "Rock_Volcanic"
    },
    {
      "x": -4,
      "y": 7,
      "z": 3,
      "name": "Rock_Volcanic"
    },
    {
      "x": -4,
      "y": 8,
      "z": 3,
      "name": "Rock_Volcanic"
    },
    {
      "x": -4,
      "y": 9,
      "z": 3,
      "name": "Rock_Volcanic"
    },
    {
      "x": -4,
      "y": 10,
      "z": 3,
      "name": "Rock_Volcanic"
    },
    {
      "x": -4,
      "y": -1,
      "z": 4,
      "name": "Rock_Volcanic"
    },
    {
      "x": -4,
      "y": 0,
      "z": 4,
      "name": "Rock_Volcanic"
    },
    {
      "x": -4,
      "y": 1,
      "z": 4,
      "name": "Rock_Volcanic"
    },
    {
      "x": -4,
      "y": 2,
      "z": 4,
      "name": "Rock_Volcanic"
    },
    {
      "x": -4,
      "y": 3,
      "z": 4,
      "name": "Rock_Volcanic"
    },
    {
      "x": -4,
      "y": 4,
      "z": 4,
      "name": "Rock_Volcanic_Cracked_Lava"
    },
    {
      "x": -4,
      "y": 5,
      "z": 4,
      "name": "Rock_Volcanic"
    },
    {
      "x": -4,
      "y": 6,
      "z": 4,
      "name": "Rock_Volcanic_Cracked_Lava"
    },
    {
      "x": -4,
      "y": 7,
      "z": 4,
      "name": "Rock_Volcanic"
    },
    {
      "x": -4,
      "y": 8,
      "z": 4,
      "name": "Rock_Volcanic"
    },
    {
      "x": -4,
      "y": 9,
      "z": 4,
      "name": "Rock_Volcanic"
    },
    {
      "x": -4,
      "y": 10,
      "z": 4,
      "name": "Rock_Volcanic"
    },
    {
      "x": -4,
      "y": 11,
      "z": 4,
      "name": "Rock_Volcanic"
    },
    {
      "x": -4,
      "y": 12,
      "z": 4,
      "name": "Rock_Volcanic"
    },
    {
      "x": -4,
      "y": 0,
      "z": 5,
      "name": "Rock_Volcanic"
    },
    {
      "x": -4,
      "y": 1,
      "z": 5,
      "name": "Rock_Volcanic"
    },
    {
      "x": -4,
      "y": 2,
      "z": 5,
      "name": "Rock_Volcanic"
    },
    {
      "x": -4,
      "y": 3,
      "z": 5,
      "name": "Rock_Volcanic"
    },
    {
      "x": -4,
      "y": 4,
      "z": 5,
      "name": "Rock_Volcanic"
    },
    {
      "x": -4,
      "y": 5,
      "z": 5,
      "name": "Rock_Volcanic"
    },
    {
      "x": -4,
      "y": 6,
      "z": 5,
      "name": "Rock_Volcanic"
    },
    {
      "x": -4,
      "y": 7,
      "z": 5,
      "name": "Rock_Volcanic_Cracked_Lava"
    },
    {
      "x": -4,
      "y": 8,
      "z": 5,
      "name": "Rock_Volcanic"
    },
    {
      "x": -4,
      "y": 9,
      "z": 5,
      "name": "Rock_Volcanic"
    },
    {
      "x": -4,
      "y": 10,
      "z": 5,
      "name": "Rock_Volcanic"
    },
    {
      "x": -4,
      "y": 11,
      "z": 5,
      "name": "Rock_Volcanic"
    },
    {
      "x": -4,
      "y": 12,
      "z": 5,
      "name": "Rock_Volcanic"
    },
    {
      "x": -4,
      "y": 13,
      "z": 5,
      "name": "Rock_Volcanic"
    },
    {
      "x": -4,
      "y": 0,
      "z": 6,
      "name": "Rock_Volcanic_Stalactite_Small",
      "rotation": 8
    },
    {
      "x": -4,
      "y": 1,
      "z": 6,
      "name": "Rock_Volcanic"
    },
    {
      "x": -4,
      "y": 2,
      "z": 6,
      "name": "Rock_Volcanic"
    },
    {
      "x": -4,
      "y": 3,
      "z": 6,
      "name": "Rock_Volcanic"
    },
    {
      "x": -4,
      "y": 4,
      "z": 6,
      "name": "Rock_Volcanic_Cracked_Lava"
    },
    {
      "x": -4,
      "y": 5,
      "z": 6,
      "name": "Rock_Volcanic_Cracked_Lava"
    },
    {
      "x": -4,
      "y": 6,
      "z": 6,
      "name": "Rock_Volcanic_Cracked_Lava"
    },
    {
      "x": -4,
      "y": 7,
      "z": 6,
      "name": "Rock_Volcanic"
    },
    {
      "x": -4,
      "y": 8,
      "z": 6,
      "name": "Rock_Volcanic"
    },
    {
      "x": -4,
      "y": 9,
      "z": 6,
      "name": "Rock_Volcanic"
    },
    {
      "x": -4,
      "y": 10,
      "z": 6,
      "name": "Rock_Volcanic"
    },
    {
      "x": -4,
      "y": 11,
      "z": 6,
      "name": "Rock_Volcanic"
    },
    {
      "x": -4,
      "y": 12,
      "z": 6,
      "name": "Rock_Volcanic"
    },
    {
      "x": -4,
      "y": 13,
      "z": 6,
      "name": "Rock_Volcanic"
    },
    {
      "x": -4,
      "y": 14,
      "z": 6,
      "name": "Rock_Volcanic"
    },
    {
      "x": -4,
      "y": 2,
      "z": 7,
      "name": "Rock_Volcanic"
    },
    {
      "x": -4,
      "y": 3,
      "z": 7,
      "name": "Rock_Volcanic"
    },
    {
      "x": -3,
      "y": -24,
      "z": -22,
      "name": "Rock_Volcanic_Cracked_Lava"
    },
    {
      "x": -3,
      "y": -23,
      "z": -22,
      "name": "Rock_Volcanic"
    },
    {
      "x": -3,
      "y": -22,
      "z": -22,
      "name": "Rock_Volcanic"
    },
    {
      "x": -3,
      "y": -25,
      "z": -21,
      "name": "Rock_Volcanic"
    },
    {
      "x": -3,
      "y": -24,
      "z": -21,
      "name": "Rock_Volcanic"
    },
    {
      "x": -3,
      "y": -23,
      "z": -21,
      "name": "Rock_Volcanic"
    },
    {
      "x": -3,
      "y": -22,
      "z": -21,
      "name": "Rock_Volcanic"
    },
    {
      "x": -3,
      "y": -21,
      "z": -21,
      "name": "Rock_Volcanic"
    },
    {
      "x": -3,
      "y": -25,
      "z": -20,
      "name": "Rock_Volcanic_Cracked_Lava"
    },
    {
      "x": -3,
      "y": -24,
      "z": -20,
      "name": "Rock_Volcanic"
    },
    {
      "x": -3,
      "y": -23,
      "z": -20,
      "name": "Rock_Volcanic"
    },
    {
      "x": -3,
      "y": -22,
      "z": -20,
      "name": "Rock_Volcanic_Cracked_Lava"
    },
    {
      "x": -3,
      "y": -21,
      "z": -20,
      "name": "Rock_Volcanic_Cracked_Lava"
    },
    {
      "x": -3,
      "y": -20,
      "z": -20,
      "name": "Rock_Volcanic"
    },
    {
      "x": -3,
      "y": -19,
      "z": -20,
      "name": "Rock_Volcanic_Cracked_Lava"
    },
    {
      "x": -3,
      "y": -23,
      "z": -19,
      "name": "Rock_Volcanic"
    },
    {
      "x": -3,
      "y": -22,
      "z": -19,
      "name": "Rock_Volcanic"
    },
    {
      "x": -3,
      "y": -21,
      "z": -19,
      "name": "Rock_Volcanic"
    },
    {
      "x": -3,
      "y": -20,
      "z": -19,
      "name": "Rock_Volcanic_Cracked_Lava"
    },
    {
      "x": -3,
      "y": -19,
      "z": -19,
      "name": "Rock_Volcanic"
    },
    {
      "x": -3,
      "y": -18,
      "z": -19,
      "name": "Rock_Volcanic"
    },
    {
      "x": -3,
      "y": -22,
      "z": -18,
      "name": "Rock_Volcanic_Cracked_Lava"
    },
    {
      "x": -3,
      "y": -21,
      "z": -18,
      "name": "Rock_Volcanic"
    },
    {
      "x": -3,
      "y": -20,
      "z": -18,
      "name": "Rock_Volcanic"
    },
    {
      "x": -3,
      "y": -19,
      "z": -18,
      "name": "Rock_Volcanic"
    },
    {
      "x": -3,
      "y": -18,
      "z": -18,
      "name": "Rock_Volcanic"
    },
    {
      "x": -3,
      "y": -17,
      "z": -18,
      "name": "Rock_Volcanic"
    },
    {
      "x": -3,
      "y": -21,
      "z": -17,
      "name": "Rock_Volcanic"
    },
    {
      "x": -3,
      "y": -20,
      "z": -17,
      "name": "Rock_Volcanic"
    },
    {
      "x": -3,
      "y": -19,
      "z": -17,
      "name": "Rock_Volcanic"
    },
    {
      "x": -3,
      "y": -18,
      "z": -17,
      "name": "Rock_Volcanic"
    },
    {
      "x": -3,
      "y": -17,
      "z": -17,
      "name": "Rock_Volcanic"
    },
    {
      "x": -3,
      "y": -16,
      "z": -17,
      "name": "Rock_Volcanic"
    },
    {
      "x": -3,
      "y": -15,
      "z": -17,
      "name": "Rock_Volcanic"
    },
    {
      "x": -3,
      "y": -14,
      "z": -17,
      "name": "Rock_Volcanic"
    },
    {
      "x": -3,
      "y": -20,
      "z": -16,
      "name": "Rock_Volcanic"
    },
    {
      "x": -3,
      "y": -19,
      "z": -16,
      "name": "Rock_Volcanic"
    },
    {
      "x": -3,
      "y": -18,
      "z": -16,
      "name": "Rock_Volcanic"
    },
    {
      "x": -3,
      "y": -17,
      "z": -16,
      "name": "Rock_Volcanic"
    },
    {
      "x": -3,
      "y": -16,
      "z": -16,
      "name": "Rock_Volcanic"
    },
    {
      "x": -3,
      "y": -15,
      "z": -16,
      "name": "Rock_Volcanic"
    },
    {
      "x": -3,
      "y": -14,
      "z": -16,
      "name": "Rock_Volcanic"
    },
    {
      "x": -3,
      "y": -13,
      "z": -16,
      "name": "Rock_Volcanic"
    },
    {
      "x": -3,
      "y": -19,
      "z": -15,
      "name": "Rock_Volcanic"
    },
    {
      "x": -3,
      "y": -18,
      "z": -15,
      "name": "Rock_Volcanic"
    },
    {
      "x": -3,
      "y": -17,
      "z": -15,
      "name": "Rock_Volcanic"
    },
    {
      "x": -3,
      "y": -16,
      "z": -15,
      "name": "Rock_Volcanic"
    },
    {
      "x": -3,
      "y": -15,
      "z": -15,
      "name": "Rock_Volcanic"
    },
    {
      "x": -3,
      "y": -14,
      "z": -15,
      "name": "Rock_Volcanic"
    },
    {
      "x": -3,
      "y": -13,
      "z": -15,
      "name": "Rock_Volcanic_Cracked_Lava"
    },
    {
      "x": -3,
      "y": -12,
      "z": -15,
      "name": "Rock_Volcanic"
    },
    {
      "x": -3,
      "y": -18,
      "z": -14,
      "name": "Rock_Volcanic"
    },
    {
      "x": -3,
      "y": -17,
      "z": -14,
      "name": "Rock_Volcanic"
    },
    {
      "x": -3,
      "y": -16,
      "z": -14,
      "name": "Rock_Volcanic"
    },
    {
      "x": -3,
      "y": -15,
      "z": -14,
      "name": "Rock_Volcanic"
    },
    {
      "x": -3,
      "y": -14,
      "z": -14,
      "name": "Rock_Volcanic"
    },
    {
      "x": -3,
      "y": -13,
      "z": -14,
      "name": "Rock_Volcanic"
    },
    {
      "x": -3,
      "y": -12,
      "z": -14,
      "name": "Rock_Volcanic"
    },
    {
      "x": -3,
      "y": -11,
      "z": -14,
      "name": "Rock_Volcanic"
    },
    {
      "x": -3,
      "y": -18,
      "z": -13,
      "name": "Rock_Volcanic_Cracked_Lava"
    },
    {
      "x": -3,
      "y": -17,
      "z": -13,
      "name": "Rock_Volcanic"
    },
    {
      "x": -3,
      "y": -16,
      "z": -13,
      "name": "Rock_Volcanic"
    },
    {
      "x": -3,
      "y": -15,
      "z": -13,
      "name": "Rock_Volcanic"
    },
    {
      "x": -3,
      "y": -14,
      "z": -13,
      "name": "Rock_Volcanic"
    },
    {
      "x": -3,
      "y": -13,
      "z": -13,
      "name": "Rock_Volcanic"
    },
    {
      "x": -3,
      "y": -12,
      "z": -13,
      "name": "Rock_Volcanic"
    },
    {
      "x": -3,
      "y": -11,
      "z": -13,
      "name": "Rock_Volcanic"
    },
    {
      "x": -3,
      "y": -10,
      "z": -13,
      "name": "Rock_Volcanic"
    },
    {
      "x": -3,
      "y": -17,
      "z": -12,
      "name": "Rock_Volcanic"
    },
    {
      "x": -3,
      "y": -16,
      "z": -12,
      "name": "Rock_Volcanic"
    },
    {
      "x": -3,
      "y": -15,
      "z": -12,
      "name": "Rock_Volcanic"
    },
    {
      "x": -3,
      "y": -14,
      "z": -12,
      "name": "Rock_Volcanic"
    },
    {
      "x": -3,
      "y": -13,
      "z": -12,
      "name": "Rock_Volcanic"
    },
    {
      "x": -3,
      "y": -12,
      "z": -12,
      "name": "Rock_Volcanic"
    },
    {
      "x": -3,
      "y": -11,
      "z": -12,
      "name": "Rock_Volcanic"
    },
    {
      "x": -3,
      "y": -10,
      "z": -12,
      "name": "Rock_Volcanic"
    },
    {
      "x": -3,
      "y": -9,
      "z": -12,
      "name": "Rock_Volcanic"
    },
    {
      "x": -3,
      "y": -8,
      "z": -12,
      "name": "Rock_Volcanic"
    },
    {
      "x": -3,
      "y": -16,
      "z": -11,
      "name": "Rock_Volcanic"
    },
    {
      "x": -3,
      "y": -15,
      "z": -11,
      "name": "Rock_Volcanic_Cracked_Lava"
    },
    {
      "x": -3,
      "y": -14,
      "z": -11,
      "name": "Rock_Volcanic"
    },
    {
      "x": -3,
      "y": -13,
      "z": -11,
      "name": "Rock_Volcanic"
    },
    {
      "x": -3,
      "y": -12,
      "z": -11,
      "name": "Rock_Volcanic"
    },
    {
      "x": -3,
      "y": -11,
      "z": -11,
      "name": "Rock_Volcanic"
    },
    {
      "x": -3,
      "y": -10,
      "z": -11,
      "name": "Rock_Volcanic"
    },
    {
      "x": -3,
      "y": -9,
      "z": -11,
      "name": "Rock_Volcanic"
    },
    {
      "x": -3,
      "y": -8,
      "z": -11,
      "name": "Rock_Volcanic_Cracked_Lava"
    },
    {
      "x": -3,
      "y": -7,
      "z": -11,
      "name": "Rock_Volcanic"
    },
    {
      "x": -3,
      "y": -6,
      "z": -11,
      "name": "Rock_Volcanic"
    },
    {
      "x": -3,
      "y": -14,
      "z": -10,
      "name": "Rock_Volcanic_Cracked_Lava"
    },
    {
      "x": -3,
      "y": -13,
      "z": -10,
      "name": "Rock_Volcanic"
    },
    {
      "x": -3,
      "y": -12,
      "z": -10,
      "name": "Rock_Volcanic"
    },
    {
      "x": -3,
      "y": -11,
      "z": -10,
      "name": "Rock_Volcanic"
    },
    {
      "x": -3,
      "y": -10,
      "z": -10,
      "name": "Rock_Volcanic"
    },
    {
      "x": -3,
      "y": -9,
      "z": -10,
      "name": "Rock_Volcanic_Cracked_Lava"
    },
    {
      "x": -3,
      "y": -8,
      "z": -10,
      "name": "Rock_Volcanic"
    },
    {
      "x": -3,
      "y": -7,
      "z": -10,
      "name": "Rock_Volcanic_Cracked_Lava"
    },
    {
      "x": -3,
      "y": -6,
      "z": -10,
      "name": "Rock_Volcanic"
    },
    {
      "x": -3,
      "y": -5,
      "z": -10,
      "name": "Rock_Volcanic"
    },
    {
      "x": -3,
      "y": -13,
      "z": -9,
      "name": "Rock_Volcanic"
    },
    {
      "x": -3,
      "y": -12,
      "z": -9,
      "name": "Rock_Volcanic"
    },
    {
      "x": -3,
      "y": -11,
      "z": -9,
      "name": "Rock_Volcanic"
    },
    {
      "x": -3,
      "y": -10,
      "z": -9,
      "name": "Rock_Volcanic"
    },
    {
      "x": -3,
      "y": -9,
      "z": -9,
      "name": "Rock_Volcanic"
    },
    {
      "x": -3,
      "y": -8,
      "z": -9,
      "name": "Rock_Volcanic"
    },
    {
      "x": -3,
      "y": -7,
      "z": -9,
      "name": "Rock_Volcanic"
    },
    {
      "x": -3,
      "y": -6,
      "z": -9,
      "name": "Rock_Volcanic"
    },
    {
      "x": -3,
      "y": -5,
      "z": -9,
      "name": "Rock_Volcanic"
    },
    {
      "x": -3,
      "y": -4,
      "z": -9,
      "name": "Rock_Volcanic"
    },
    {
      "x": -3,
      "y": -3,
      "z": -9,
      "name": "Rock_Volcanic"
    },
    {
      "x": -3,
      "y": -12,
      "z": -8,
      "name": "Rock_Volcanic"
    },
    {
      "x": -3,
      "y": -11,
      "z": -8,
      "name": "Rock_Volcanic_Cracked_Lava"
    },
    {
      "x": -3,
      "y": -10,
      "z": -8,
      "name": "Rock_Volcanic"
    },
    {
      "x": -3,
      "y": -9,
      "z": -8,
      "name": "Rock_Volcanic"
    },
    {
      "x": -3,
      "y": -8,
      "z": -8,
      "name": "Rock_Volcanic_Cracked_Lava"
    },
    {
      "x": -3,
      "y": -7,
      "z": -8,
      "name": "Rock_Volcanic_Cracked_Lava"
    },
    {
      "x": -3,
      "y": -6,
      "z": -8,
      "name": "Rock_Volcanic"
    },
    {
      "x": -3,
      "y": -5,
      "z": -8,
      "name": "Rock_Volcanic"
    },
    {
      "x": -3,
      "y": -4,
      "z": -8,
      "name": "Rock_Volcanic_Cracked_Lava"
    },
    {
      "x": -3,
      "y": -3,
      "z": -8,
      "name": "Rock_Volcanic"
    },
    {
      "x": -3,
      "y": -2,
      "z": -8,
      "name": "Rock_Volcanic_Cracked_Lava"
    },
    {
      "x": -3,
      "y": -11,
      "z": -7,
      "name": "Rock_Volcanic"
    },
    {
      "x": -3,
      "y": -10,
      "z": -7,
      "name": "Rock_Volcanic"
    },
    {
      "x": -3,
      "y": -9,
      "z": -7,
      "name": "Rock_Volcanic"
    },
    {
      "x": -3,
      "y": -8,
      "z": -7,
      "name": "Rock_Volcanic"
    },
    {
      "x": -3,
      "y": -7,
      "z": -7,
      "name": "Rock_Volcanic"
    },
    {
      "x": -3,
      "y": -6,
      "z": -7,
      "name": "Rock_Volcanic"
    },
    {
      "x": -3,
      "y": -5,
      "z": -7,
      "name": "Rock_Volcanic"
    },
    {
      "x": -3,
      "y": -4,
      "z": -7,
      "name": "Rock_Volcanic"
    },
    {
      "x": -3,
      "y": -3,
      "z": -7,
      "name": "Rock_Volcanic"
    },
    {
      "x": -3,
      "y": -2,
      "z": -7,
      "name": "Rock_Volcanic"
    },
    {
      "x": -3,
      "y": -1,
      "z": -7,
      "name": "Rock_Volcanic"
    },
    {
      "x": -3,
      "y": -11,
      "z": -6,
      "name": "Rock_Volcanic"
    },
    {
      "x": -3,
      "y": -10,
      "z": -6,
      "name": "Rock_Volcanic"
    },
    {
      "x": -3,
      "y": -9,
      "z": -6,
      "name": "Rock_Volcanic"
    },
    {
      "x": -3,
      "y": -8,
      "z": -6,
      "name": "Rock_Volcanic"
    },
    {
      "x": -3,
      "y": -7,
      "z": -6,
      "name": "Rock_Volcanic"
    },
    {
      "x": -3,
      "y": -6,
      "z": -6,
      "name": "Rock_Volcanic"
    },
    {
      "x": -3,
      "y": -5,
      "z": -6,
      "name": "Rock_Volcanic"
    },
    {
      "x": -3,
      "y": -4,
      "z": -6,
      "name": "Rock_Volcanic_Cracked_Lava"
    },
    {
      "x": -3,
      "y": -3,
      "z": -6,
      "name": "Rock_Volcanic"
    },
    {
      "x": -3,
      "y": -2,
      "z": -6,
      "name": "Rock_Volcanic"
    },
    {
      "x": -3,
      "y": -1,
      "z": -6,
      "name": "Rock_Volcanic"
    },
    {
      "x": -3,
      "y": 0,
      "z": -6,
      "name": "Rock_Volcanic"
    },
    {
      "x": -3,
      "y": 2,
      "z": -6,
      "name": "Rock_Volcanic"
    },
    {
      "x": -3,
      "y": -10,
      "z": -5,
      "name": "Rock_Volcanic"
    },
    {
      "x": -3,
      "y": -9,
      "z": -5,
      "name": "Rock_Volcanic"
    },
    {
      "x": -3,
      "y": -8,
      "z": -5,
      "name": "Rock_Volcanic_Cracked_Lava"
    },
    {
      "x": -3,
      "y": -7,
      "z": -5,
      "name": "Rock_Volcanic"
    },
    {
      "x": -3,
      "y": -6,
      "z": -5,
      "name": "Rock_Volcanic"
    },
    {
      "x": -3,
      "y": -5,
      "z": -5,
      "name": "Rock_Volcanic_Cracked_Lava"
    },
    {
      "x": -3,
      "y": -4,
      "z": -5,
      "name": "Rock_Volcanic"
    },
    {
      "x": -3,
      "y": -3,
      "z": -5,
      "name": "Rock_Volcanic"
    },
    {
      "x": -3,
      "y": -2,
      "z": -5,
      "name": "Rock_Volcanic_Cracked_Lava"
    },
    {
      "x": -3,
      "y": -1,
      "z": -5,
      "name": "Rock_Volcanic"
    },
    {
      "x": -3,
      "y": 0,
      "z": -5,
      "name": "Rock_Volcanic"
    },
    {
      "x": -3,
      "y": 1,
      "z": -5,
      "name": "Rock_Volcanic"
    },
    {
      "x": -3,
      "y": 2,
      "z": -5,
      "name": "Rock_Volcanic"
    },
    {
      "x": -3,
      "y": 3,
      "z": -5,
      "name": "Rock_Volcanic"
    },
    {
      "x": -3,
      "y": -9,
      "z": -4,
      "name": "Rock_Volcanic"
    },
    {
      "x": -3,
      "y": -8,
      "z": -4,
      "name": "Rock_Volcanic"
    },
    {
      "x": -3,
      "y": -7,
      "z": -4,
      "name": "Rock_Volcanic"
    },
    {
      "x": -3,
      "y": -6,
      "z": -4,
      "name": "Rock_Volcanic_Cracked_Lava"
    },
    {
      "x": -3,
      "y": -5,
      "z": -4,
      "name": "Rock_Volcanic"
    },
    {
      "x": -3,
      "y": -4,
      "z": -4,
      "name": "Rock_Volcanic"
    },
    {
      "x": -3,
      "y": -3,
      "z": -4,
      "name": "Rock_Volcanic"
    },
    {
      "x": -3,
      "y": -2,
      "z": -4,
      "name": "Rock_Volcanic"
    },
    {
      "x": -3,
      "y": -1,
      "z": -4,
      "name": "Rock_Volcanic"
    },
    {
      "x": -3,
      "y": 0,
      "z": -4,
      "name": "Rock_Volcanic"
    },
    {
      "x": -3,
      "y": 1,
      "z": -4,
      "name": "Rock_Volcanic"
    },
    {
      "x": -3,
      "y": 2,
      "z": -4,
      "name": "Rock_Volcanic"
    },
    {
      "x": -3,
      "y": 3,
      "z": -4,
      "name": "Rock_Volcanic"
    },
    {
      "x": -3,
      "y": 4,
      "z": -4,
      "name": "Rock_Volcanic"
    },
    {
      "x": -3,
      "y": -8,
      "z": -3,
      "name": "Rock_Volcanic"
    },
    {
      "x": -3,
      "y": -7,
      "z": -3,
      "name": "Rock_Volcanic"
    },
    {
      "x": -3,
      "y": -6,
      "z": -3,
      "name": "Rock_Volcanic"
    },
    {
      "x": -3,
      "y": -5,
      "z": -3,
      "name": "Rock_Volcanic"
    },
    {
      "x": -3,
      "y": -4,
      "z": -3,
      "name": "Rock_Volcanic"
    },
    {
      "x": -3,
      "y": -3,
      "z": -3,
      "name": "Rock_Volcanic"
    },
    {
      "x": -3,
      "y": -2,
      "z": -3,
      "name": "Rock_Volcanic"
    },
    {
      "x": -3,
      "y": -1,
      "z": -3,
      "name": "Rock_Volcanic_Cracked_Lava"
    },
    {
      "x": -3,
      "y": 0,
      "z": -3,
      "name": "Rock_Volcanic"
    },
    {
      "x": -3,
      "y": 1,
      "z": -3,
      "name": "Rock_Volcanic"
    },
    {
      "x": -3,
      "y": 2,
      "z": -3,
      "name": "Rock_Volcanic"
    },
    {
      "x": -3,
      "y": 3,
      "z": -3,
      "name": "Rock_Volcanic"
    },
    {
      "x": -3,
      "y": 4,
      "z": -3,
      "name": "Rock_Volcanic"
    },
    {
      "x": -3,
      "y": 5,
      "z": -3,
      "name": "Rock_Volcanic"
    },
    {
      "x": -3,
      "y": -7,
      "z": -2,
      "name": "Rock_Volcanic"
    },
    {
      "x": -3,
      "y": -6,
      "z": -2,
      "name": "Rock_Volcanic"
    },
    {
      "x": -3,
      "y": -5,
      "z": -2,
      "name": "Rock_Volcanic"
    },
    {
      "x": -3,
      "y": -4,
      "z": -2,
      "name": "Rock_Volcanic_Cracked_Lava"
    },
    {
      "x": -3,
      "y": -3,
      "z": -2,
      "name": "Rock_Volcanic_Cracked_Lava"
    },
    {
      "x": -3,
      "y": -2,
      "z": -2,
      "name": "Rock_Volcanic_Cracked_Lava"
    },
    {
      "x": -3,
      "y": -1,
      "z": -2,
      "name": "Rock_Volcanic"
    },
    {
      "x": -3,
      "y": 0,
      "z": -2,
      "name": "Rock_Volcanic_Cracked_Lava"
    },
    {
      "x": -3,
      "y": 1,
      "z": -2,
      "name": "Rock_Volcanic"
    },
    {
      "x": -3,
      "y": 2,
      "z": -2,
      "name": "Rock_Volcanic"
    },
    {
      "x": -3,
      "y": 3,
      "z": -2,
      "name": "Rock_Volcanic"
    },
    {
      "x": -3,
      "y": 4,
      "z": -2,
      "name": "Rock_Volcanic"
    },
    {
      "x": -3,
      "y": 5,
      "z": -2,
      "name": "Rock_Volcanic"
    },
    {
      "x": -3,
      "y": 6,
      "z": -2,
      "name": "Rock_Volcanic_Cracked_Lava"
    },
    {
      "x": -3,
      "y": 7,
      "z": -2,
      "name": "Rock_Crystal_Yellow_Small",
      "rotation": 7
    },
    {
      "x": -3,
      "y": -5,
      "z": -1,
      "name": "Rock_Volcanic"
    },
    {
      "x": -3,
      "y": -4,
      "z": -1,
      "name": "Rock_Volcanic"
    },
    {
      "x": -3,
      "y": -3,
      "z": -1,
      "name": "Rock_Volcanic"
    },
    {
      "x": -3,
      "y": -2,
      "z": -1,
      "name": "Rock_Volcanic"
    },
    {
      "x": -3,
      "y": -1,
      "z": -1,
      "name": "Rock_Volcanic"
    },
    {
      "x": -3,
      "y": 0,
      "z": -1,
      "name": "Rock_Volcanic"
    },
    {
      "x": -3,
      "y": 1,
      "z": -1,
      "name": "Rock_Volcanic"
    },
    {
      "x": -3,
      "y": 2,
      "z": -1,
      "name": "Rock_Volcanic"
    },
    {
      "x": -3,
      "y": 3,
      "z": -1,
      "name": "Rock_Volcanic"
    },
    {
      "x": -3,
      "y": 4,
      "z": -1,
      "name": "Rock_Volcanic"
    },
    {
      "x": -3,
      "y": 5,
      "z": -1,
      "name": "Rock_Volcanic"
    },
    {
      "x": -3,
      "y": 6,
      "z": -1,
      "name": "Rock_Volcanic_Cracked_Lava"
    },
    {
      "x": -3,
      "y": 7,
      "z": -1,
      "name": "Rock_Volcanic_Cracked_Lava"
    },
    {
      "x": -3,
      "y": 8,
      "z": -1,
      "name": "Rock_Volcanic"
    },
    {
      "x": -3,
      "y": -4,
      "z": 0,
      "name": "Rock_Volcanic_Cracked_Lava"
    },
    {
      "x": -3,
      "y": -3,
      "z": 0,
      "name": "Rock_Volcanic_Cracked_Lava"
    },
    {
      "x": -3,
      "y": -2,
      "z": 0,
      "name": "Rock_Volcanic"
    },
    {
      "x": -3,
      "y": -1,
      "z": 0,
      "name": "Rock_Volcanic"
    },
    {
      "x": -3,
      "y": 0,
      "z": 0,
      "name": "Rock_Volcanic"
    },
    {
      "x": -3,
      "y": 1,
      "z": 0,
      "name": "Rock_Volcanic"
    },
    {
      "x": -3,
      "y": 2,
      "z": 0,
      "name": "Rock_Volcanic"
    },
    {
      "x": -3,
      "y": 3,
      "z": 0,
      "name": "Rock_Volcanic"
    },
    {
      "x": -3,
      "y": 4,
      "z": 0,
      "name": "Rock_Volcanic"
    },
    {
      "x": -3,
      "y": 5,
      "z": 0,
      "name": "Rock_Volcanic_Cracked_Lava"
    },
    {
      "x": -3,
      "y": 6,
      "z": 0,
      "name": "Rock_Volcanic_Cracked_Lava"
    },
    {
      "x": -3,
      "y": 7,
      "z": 0,
      "name": "Rock_Volcanic_Cracked_Lava"
    },
    {
      "x": -3,
      "y": 8,
      "z": 0,
      "name": "Rock_Volcanic_Cracked_Lava"
    },
    {
      "x": -3,
      "y": 9,
      "z": 0,
      "name": "Rock_Volcanic"
    },
    {
      "x": -3,
      "y": -4,
      "z": 1,
      "name": "Rock_Volcanic"
    },
    {
      "x": -3,
      "y": -3,
      "z": 1,
      "name": "Rock_Volcanic_Cracked_Lava"
    },
    {
      "x": -3,
      "y": -2,
      "z": 1,
      "name": "Rock_Volcanic"
    },
    {
      "x": -3,
      "y": -1,
      "z": 1,
      "name": "Rock_Volcanic"
    },
    {
      "x": -3,
      "y": 0,
      "z": 1,
      "name": "Rock_Volcanic"
    },
    {
      "x": -3,
      "y": 1,
      "z": 1,
      "name": "Rock_Volcanic"
    },
    {
      "x": -3,
      "y": 2,
      "z": 1,
      "name": "Rock_Volcanic"
    },
    {
      "x": -3,
      "y": 3,
      "z": 1,
      "name": "Rock_Volcanic"
    },
    {
      "x": -3,
      "y": 4,
      "z": 1,
      "name": "Rock_Volcanic_Cracked_Lava"
    },
    {
      "x": -3,
      "y": 5,
      "z": 1,
      "name": "Rock_Volcanic"
    },
    {
      "x": -3,
      "y": 6,
      "z": 1,
      "name": "Rock_Volcanic"
    },
    {
      "x": -3,
      "y": 7,
      "z": 1,
      "name": "Rock_Volcanic"
    },
    {
      "x": -3,
      "y": 8,
      "z": 1,
      "name": "Rock_Volcanic"
    },
    {
      "x": -3,
      "y": -4,
      "z": 2,
      "name": "Rock_Volcanic"
    },
    {
      "x": -3,
      "y": -3,
      "z": 2,
      "name": "Rock_Volcanic"
    },
    {
      "x": -3,
      "y": -2,
      "z": 2,
      "name": "Rock_Volcanic"
    },
    {
      "x": -3,
      "y": -1,
      "z": 2,
      "name": "Rock_Volcanic"
    },
    {
      "x": -3,
      "y": 0,
      "z": 2,
      "name": "Rock_Volcanic"
    },
    {
      "x": -3,
      "y": 1,
      "z": 2,
      "name": "Rock_Volcanic"
    },
    {
      "x": -3,
      "y": 2,
      "z": 2,
      "name": "Rock_Volcanic_Cracked_Lava"
    },
    {
      "x": -3,
      "y": 3,
      "z": 2,
      "name": "Rock_Volcanic"
    },
    {
      "x": -3,
      "y": 4,
      "z": 2,
      "name": "Rock_Volcanic"
    },
    {
      "x": -3,
      "y": 5,
      "z": 2,
      "name": "Rock_Volcanic"
    },
    {
      "x": -3,
      "y": 6,
      "z": 2,
      "name": "Rock_Volcanic"
    },
    {
      "x": -3,
      "y": 7,
      "z": 2,
      "name": "Rock_Volcanic"
    },
    {
      "x": -3,
      "y": 8,
      "z": 2,
      "name": "Rock_Volcanic"
    },
    {
      "x": -3,
      "y": 9,
      "z": 2,
      "name": "Rock_Volcanic_Cracked_Lava"
    },
    {
      "x": -3,
      "y": -2,
      "z": 3,
      "name": "Rock_Volcanic"
    },
    {
      "x": -3,
      "y": -1,
      "z": 3,
      "name": "Rock_Volcanic"
    },
    {
      "x": -3,
      "y": 0,
      "z": 3,
      "name": "Rock_Volcanic"
    },
    {
      "x": -3,
      "y": 1,
      "z": 3,
      "name": "Rock_Volcanic"
    },
    {
      "x": -3,
      "y": 2,
      "z": 3,
      "name": "Rock_Volcanic"
    },
    {
      "x": -3,
      "y": 3,
      "z": 3,
      "name": "Rock_Volcanic"
    },
    {
      "x": -3,
      "y": 4,
      "z": 3,
      "name": "Rock_Volcanic"
    },
    {
      "x": -3,
      "y": 5,
      "z": 3,
      "name": "Rock_Volcanic_Cracked_Lava"
    },
    {
      "x": -3,
      "y": 6,
      "z": 3,
      "name": "Rock_Volcanic"
    },
    {
      "x": -3,
      "y": 7,
      "z": 3,
      "name": "Rock_Volcanic"
    },
    {
      "x": -3,
      "y": 8,
      "z": 3,
      "name": "Rock_Volcanic"
    },
    {
      "x": -3,
      "y": 9,
      "z": 3,
      "name": "Rock_Volcanic"
    },
    {
      "x": -3,
      "y": 10,
      "z": 3,
      "name": "Rock_Volcanic"
    },
    {
      "x": -3,
      "y": 11,
      "z": 3,
      "name": "Rock_Volcanic"
    },
    {
      "x": -3,
      "y": -1,
      "z": 4,
      "name": "Rock_Volcanic"
    },
    {
      "x": -3,
      "y": 0,
      "z": 4,
      "name": "Rock_Volcanic"
    },
    {
      "x": -3,
      "y": 1,
      "z": 4,
      "name": "Rock_Volcanic_Cracked_Lava"
    },
    {
      "x": -3,
      "y": 2,
      "z": 4,
      "name": "Rock_Volcanic_Cracked_Lava"
    },
    {
      "x": -3,
      "y": 3,
      "z": 4,
      "name": "Rock_Volcanic_Cracked_Lava"
    },
    {
      "x": -3,
      "y": 4,
      "z": 4,
      "name": "Rock_Volcanic"
    },
    {
      "x": -3,
      "y": 5,
      "z": 4,
      "name": "Rock_Volcanic"
    },
    {
      "x": -3,
      "y": 6,
      "z": 4,
      "name": "Rock_Volcanic"
    },
    {
      "x": -3,
      "y": 7,
      "z": 4,
      "name": "Rock_Volcanic_Cracked_Lava"
    },
    {
      "x": -3,
      "y": 8,
      "z": 4,
      "name": "Rock_Volcanic"
    },
    {
      "x": -3,
      "y": 9,
      "z": 4,
      "name": "Rock_Volcanic"
    },
    {
      "x": -3,
      "y": 10,
      "z": 4,
      "name": "Rock_Volcanic"
    },
    {
      "x": -3,
      "y": 11,
      "z": 4,
      "name": "Rock_Volcanic"
    },
    {
      "x": -3,
      "y": 12,
      "z": 4,
      "name": "Rock_Volcanic"
    },
    {
      "x": -3,
      "y": 0,
      "z": 5,
      "name": "Rock_Volcanic"
    },
    {
      "x": -3,
      "y": 1,
      "z": 5,
      "name": "Rock_Volcanic"
    },
    {
      "x": -3,
      "y": 2,
      "z": 5,
      "name": "Rock_Volcanic"
    },
    {
      "x": -3,
      "y": 3,
      "z": 5,
      "name": "Rock_Volcanic"
    },
    {
      "x": -3,
      "y": 4,
      "z": 5,
      "name": "Rock_Volcanic"
    },
    {
      "x": -3,
      "y": 5,
      "z": 5,
      "name": "Rock_Volcanic"
    },
    {
      "x": -3,
      "y": 6,
      "z": 5,
      "name": "Rock_Volcanic"
    },
    {
      "x": -3,
      "y": 7,
      "z": 5,
      "name": "Rock_Volcanic"
    },
    {
      "x": -3,
      "y": 8,
      "z": 5,
      "name": "Rock_Volcanic"
    },
    {
      "x": -3,
      "y": 9,
      "z": 5,
      "name": "Rock_Volcanic"
    },
    {
      "x": -3,
      "y": 10,
      "z": 5,
      "name": "Rock_Volcanic"
    },
    {
      "x": -3,
      "y": 11,
      "z": 5,
      "name": "Rock_Volcanic_Cracked_Lava"
    },
    {
      "x": -3,
      "y": 12,
      "z": 5,
      "name": "Rock_Volcanic_Cracked_Lava"
    },
    {
      "x": -3,
      "y": 13,
      "z": 5,
      "name": "Rock_Volcanic_Cracked_Lava"
    },
    {
      "x": -3,
      "y": 1,
      "z": 6,
      "name": "Rock_Volcanic"
    },
    {
      "x": -3,
      "y": 2,
      "z": 6,
      "name": "Rock_Volcanic"
    },
    {
      "x": -3,
      "y": 3,
      "z": 6,
      "name": "Rock_Volcanic_Cracked_Lava"
    },
    {
      "x": -3,
      "y": 4,
      "z": 6,
      "name": "Rock_Volcanic_Cracked_Lava"
    },
    {
      "x": -3,
      "y": 5,
      "z": 6,
      "name": "Rock_Volcanic"
    },
    {
      "x": -3,
      "y": 6,
      "z": 6,
      "name": "Rock_Volcanic_Cracked_Lava"
    },
    {
      "x": -3,
      "y": 7,
      "z": 6,
      "name": "Rock_Volcanic_Cracked_Lava"
    },
    {
      "x": -3,
      "y": 8,
      "z": 6,
      "name": "Rock_Volcanic"
    },
    {
      "x": -3,
      "y": 9,
      "z": 6,
      "name": "Rock_Volcanic_Cracked_Lava"
    },
    {
      "x": -3,
      "y": 10,
      "z": 6,
      "name": "Rock_Volcanic_Cracked_Lava"
    },
    {
      "x": -3,
      "y": 11,
      "z": 6,
      "name": "Rock_Volcanic_Cracked_Lava"
    },
    {
      "x": -3,
      "y": 12,
      "z": 6,
      "name": "Rock_Volcanic"
    },
    {
      "x": -3,
      "y": 13,
      "z": 6,
      "name": "Rock_Volcanic"
    },
    {
      "x": -3,
      "y": 14,
      "z": 6,
      "name": "Rock_Volcanic_Cracked_Lava"
    },
    {
      "x": -3,
      "y": 15,
      "z": 6,
      "name": "Rock_Crystal_Yellow_Small"
    },
    {
      "x": -3,
      "y": 1,
      "z": 7,
      "name": "Rock_Volcanic_Stalactite_Small",
      "rotation": 8
    },
    {
      "x": -3,
      "y": 2,
      "z": 7,
      "name": "Rock_Volcanic_Cracked_Lava"
    },
    {
      "x": -3,
      "y": 3,
      "z": 7,
      "name": "Rock_Volcanic"
    },
    {
      "x": -3,
      "y": 4,
      "z": 7,
      "name": "Rock_Volcanic"
    },
    {
      "x": -3,
      "y": 5,
      "z": 7,
      "name": "Rock_Volcanic"
    },
    {
      "x": -3,
      "y": 6,
      "z": 7,
      "name": "Rock_Volcanic"
    },
    {
      "x": -3,
      "y": 7,
      "z": 7,
      "name": "Rock_Volcanic"
    },
    {
      "x": -3,
      "y": 8,
      "z": 7,
      "name": "Rock_Volcanic"
    },
    {
      "x": -3,
      "y": 9,
      "z": 7,
      "name": "Rock_Volcanic"
    },
    {
      "x": -3,
      "y": 10,
      "z": 7,
      "name": "Rock_Volcanic_Cracked_Lava"
    },
    {
      "x": -3,
      "y": 11,
      "z": 7,
      "name": "Rock_Volcanic_Cracked_Lava"
    },
    {
      "x": -3,
      "y": 12,
      "z": 7,
      "name": "Rock_Volcanic"
    },
    {
      "x": -3,
      "y": 13,
      "z": 7,
      "name": "Rock_Volcanic"
    },
    {
      "x": -3,
      "y": 14,
      "z": 7,
      "name": "Rock_Volcanic"
    },
    {
      "x": -3,
      "y": 15,
      "z": 7,
      "name": "Rock_Volcanic"
    },
    {
      "x": -3,
      "y": 4,
      "z": 8,
      "name": "Rock_Volcanic_Stalactite_Small",
      "rotation": 8
