{
  "version": 8,
  "blockIdVersion": 11,
  "anchorX": 0,
  "anchorY": 0,
  "anchorZ": 0,
  "blocks": [
    {
      "x": -5,
      "y": -17,
      "z": -32,
      "name": "Rock_Volcanic"
    },
    {
      "x": -5,
      "y": -17,
      "z": -31,
      "name": "Rock_Volcanic"
    },
    {
      "x": -5,
      "y": -16,
      "z": -31,
      "name": "Rock_Volcanic"
    },
    {
      "x": -5,
      "y": -17,
      "z": -30,
      "name": "Rock_Volcanic"
    },
    {
      "x": -5,
      "y": -16,
      "z": -30,
      "name": "Rock_Volcanic"
    },
    {
      "x": -5,
      "y": -17,
      "z": -28,
      "name": "Rock_Volcanic"
    },
    {
      "x": -5,
      "y": -16,
      "z": -28,
      "name": "Rock_Volcanic"
    },
    {
      "x": -5,
      "y": -15,
      "z": -28,
      "name": "Rock_Volcanic"
    },
    {
      "x": -5,
      "y": -17,
      "z": -27,
      "name": "Rock_Volcanic"
    },
    {
      "x": -5,
      "y": -16,
      "z": -27,
      "name": "Rock_Volcanic_Cracked_Lava"
    },
    {
      "x": -5,
      "y": -15,
      "z": -27,
      "name": "Rock_Volcanic"
    },
    {
      "x": -5,
      "y": -14,
      "z": -27,
      "name": "Rock_Volcanic"
    },
    {
      "x": -5,
      "y": -17,
      "z": -26,
      "name": "Rock_Volcanic"
    },
    {
      "x": -5,
      "y": -16,
      "z": -26,
      "name": "Rock_Volcanic"
    },
    {
      "x": -5,
      "y": -15,
      "z": -26,
      "name": "Rock_Volcanic"
    },
    {
      "x": -5,
      "y": -14,
      "z": -26,
      "name": "Rock_Volcanic"
    },
    {
      "x": -5,
      "y": -13,
      "z": -26,
      "name": "Rock_Volcanic_Cracked_Lava"
    },
    {
      "x": -5,
      "y": -16,
      "z": -25,
      "name": "Rock_Volcanic_Cracked_Lava"
    },
    {
      "x": -5,
      "y": -15,
      "z": -25,
      "name": "Rock_Volcanic_Cracked_Lava"
    },
    {
      "x": -5,
      "y": -14,
      "z": -25,
      "name": "Rock_Volcanic"
    },
    {
      "x": -5,
      "y": -13,
      "z": -25,
      "name": "Rock_Volcanic"
    },
    {
      "x": -5,
      "y": -12,
      "z": -25,
      "name": "Rock_Volcanic"
    },
    {
      "x": -5,
      "y": -15,
      "z": -24,
      "name": "Rock_Volcanic"
    },
    {
      "x": -5,
      "y": -14,
      "z": -24,
      "name": "Rock_Volcanic_Cracked_Lava"
    },
    {
      "x": -5,
      "y": -13,
      "z": -24,
      "name": "Rock_Volcanic_Cracked_Lava"
    },
    {
      "x": -5,
      "y": -12,
      "z": -24,
      "name": "Rock_Volcanic"
    },
    {
      "x": -5,
      "y": -16,
      "z": -23,
      "name": "Rock_Volcanic"
    },
    {
      "x": -5,
      "y": -15,
      "z": -23,
      "name": "Rock_Volcanic"
    },
    {
      "x": -5,
      "y": -14,
      "z": -23,
      "name": "Rock_Volcanic"
    },
    {
      "x": -5,
      "y": -13,
      "z": -23,
      "name": "Rock_Volcanic"
    },
    {
      "x": -5,
      "y": -12,
      "z": -23,
      "name": "Rock_Volcanic"
    },
    {
      "x": -5,
      "y": -15,
      "z": -22,
      "name": "Rock_Volcanic_Cracked_Lava"
    },
    {
      "x": -5,
      "y": -14,
      "z": -22,
      "name": "Rock_Volcanic"
    },
    {
      "x": -5,
      "y": -13,
      "z": -22,
      "name": "Rock_Volcanic"
    },
    {
      "x": -5,
      "y": -12,
      "z": -22,
      "name": "Rock_Volcanic"
    },
    {
      "x": -5,
      "y": -11,
      "z": -22,
      "name": "Rock_Volcanic_Cracked_Lava"
    },
    {
      "x": -5,
      "y": -12,
      "z": -21,
      "name": "Rock_Volcanic"
    },
    {
      "x": -5,
      "y": -11,
      "z": -21,
      "name": "Rock_Volcanic_Cracked_Lava"
    },
    {
      "x": -5,
      "y": -10,
      "z": -20,
      "name": "Rock_Volcanic_Cracked_Lava"
    },
    {
      "x": -5,
      "y": -9,
      "z": -20,
      "name": "Rock_Volcanic_Cracked_Lava"
    },
    {
      "x": -5,
      "y": -11,
      "z": -19,
      "name": "Rock_Volcanic"
    },
    {
      "x": -5,
      "y": -10,
      "z": -19,
      "name": "Rock_Volcanic"
    },
    {
      "x": -5,
      "y": -9,
      "z": -19,
      "name": "Rock_Volcanic"
    },
    {
      "x": -5,
      "y": -8,
      "z": -19,
      "name": "Rock_Volcanic"
    },
    {
      "x": -5,
      "y": -11,
      "z": -18,
      "name": "Rock_Volcanic"
    },
    {
      "x": -5,
      "y": -10,
      "z": -18,
      "name": "Rock_Volcanic"
    },
    {
      "x": -5,
      "y": -9,
      "z": -18,
      "name": "Rock_Volcanic"
    },
    {
      "x": -5,
      "y": -8,
      "z": -18,
      "name": "Rock_Volcanic"
    },
    {
      "x": -5,
      "y": -13,
      "z": -17,
      "name": "Rock_Volcanic"
    },
    {
      "x": -5,
      "y": -12,
      "z": -17,
      "name": "Rock_Volcanic"
    },
    {
      "x": -5,
      "y": -11,
      "z": -17,
      "name": "Rock_Volcanic"
    },
    {
      "x": -5,
      "y": -10,
      "z": -17,
      "name": "Rock_Volcanic"
    },
    {
      "x": -5,
      "y": -9,
      "z": -17,
      "name": "Rock_Volcanic"
    },
    {
      "x": -5,
      "y": -8,
      "z": -17,
      "name": "Rock_Volcanic"
    },
    {
      "x": -5,
      "y": -7,
      "z": -17,
      "name": "Rock_Volcanic"
    },
    {
      "x": -5,
      "y": -13,
      "z": -16,
      "name": "Rock_Volcanic"
    },
    {
      "x": -5,
      "y": -12,
      "z": -16,
      "name": "Rock_Volcanic"
    },
    {
      "x": -5,
      "y": -11,
      "z": -16,
      "name": "Rock_Volcanic"
    },
    {
      "x": -5,
      "y": -10,
      "z": -16,
      "name": "Rock_Volcanic"
    },
    {
      "x": -5,
      "y": -9,
      "z": -16,
      "name": "Rock_Volcanic_Cracked_Lava"
    },
    {
      "x": -5,
      "y": -8,
      "z": -16,
      "name": "Rock_Volcanic"
    },
    {
      "x": -5,
      "y": -7,
      "z": -16,
      "name": "Rock_Volcanic"
    },
    {
      "x": -5,
      "y": -6,
      "z": -16,
      "name": "Rock_Volcanic"
    },
    {
      "x": -5,
      "y": -10,
      "z": -15,
      "name": "Rock_Volcanic"
    },
    {
      "x": -5,
      "y": -9,
      "z": -15,
      "name": "Rock_Volcanic"
    },
    {
      "x": -5,
      "y": -8,
      "z": -15,
      "name": "Rock_Volcanic"
    },
    {
      "x": -5,
      "y": -7,
      "z": -15,
      "name": "Rock_Volcanic"
    },
    {
      "x": -5,
      "y": -6,
      "z": -15,
      "name": "Rock_Volcanic_Cracked_Lava"
    },
    {
      "x": -5,
      "y": -5,
      "z": -15,
      "name": "Rock_Volcanic"
    },
    {
      "x": -5,
      "y": -8,
      "z": -14,
      "name": "Rock_Volcanic"
    },
    {
      "x": -5,
      "y": -7,
      "z": -14,
      "name": "Rock_Volcanic_Cracked_Lava"
    },
    {
      "x": -5,
      "y": -6,
      "z": -14,
      "name": "Rock_Volcanic"
    },
    {
      "x": -5,
      "y": -5,
      "z": -14,
      "name": "Rock_Volcanic"
    },
    {
      "x": -5,
      "y": -3,
      "z": -12,
      "name": "Rock_Volcanic"
    },
    {
      "x": -5,
      "y": -5,
      "z": -11,
      "name": "Rock_Volcanic"
    },
    {
      "x": -5,
      "y": -4,
      "z": -11,
      "name": "Rock_Volcanic"
    },
    {
      "x": -5,
      "y": -3,
      "z": -11,
      "name": "Rock_Volcanic_Cracked_Lava"
    },
    {
      "x": -5,
      "y": -2,
      "z": -11,
      "name": "Rock_Volcanic"
    },
    {
      "x": -5,
      "y": -6,
      "z": -10,
      "name": "Rock_Volcanic"
    },
    {
      "x": -5,
      "y": -5,
      "z": -10,
      "name": "Rock_Volcanic"
    },
    {
      "x": -5,
      "y": -4,
      "z": -10,
      "name": "Rock_Volcanic_Cracked_Lava"
    },
    {
      "x": -5,
      "y": -3,
      "z": -10,
      "name": "Rock_Volcanic_Cracked_Lava"
    },
    {
      "x": -5,
      "y": -2,
      "z": -10,
      "name": "Rock_Volcanic"
    },
    {
      "x": -5,
      "y": -7,
      "z": -9,
      "name": "Rock_Volcanic"
    },
    {
      "x": -5,
      "y": -6,
      "z": -9,
      "name": "Rock_Volcanic"
    },
    {
      "x": -5,
      "y": -5,
      "z": -9,
      "name": "Rock_Volcanic"
    },
    {
      "x": -5,
      "y": -4,
      "z": -9,
      "name": "Rock_Volcanic_Cracked_Lava"
    },
    {
      "x": -5,
      "y": -3,
      "z": -9,
      "name": "Rock_Volcanic"
    },
    {
      "x": -5,
      "y": -2,
      "z": -9,
      "name": "Rock_Volcanic"
    },
    {
      "x": -5,
      "y": -1,
      "z": -9,
      "name": "Rock_Volcanic"
    },
    {
      "x": -5,
      "y": -9,
      "z": -8,
      "name": "Rock_Volcanic"
    },
    {
      "x": -5,
      "y": -8,
      "z": -8,
      "name": "Rock_Volcanic"
    },
    {
      "x": -5,
      "y": -7,
      "z": -8,
      "name": "Rock_Volcanic"
    },
    {
      "x": -5,
      "y": -6,
      "z": -8,
      "name": "Rock_Volcanic"
    },
    {
      "x": -5,
      "y": -5,
      "z": -8,
      "name": "Rock_Volcanic_Cracked_Lava"
    },
    {
      "x": -5,
      "y": -4,
      "z": -8,
      "name": "Rock_Volcanic"
    },
    {
      "x": -5,
      "y": -3,
      "z": -8,
      "name": "Rock_Volcanic"
    },
    {
      "x": -5,
      "y": -2,
      "z": -8,
      "name": "Rock_Volcanic"
    },
    {
      "x": -5,
      "y": -1,
      "z": -8,
      "name": "Rock_Volcanic"
    },
    {
      "x": -5,
      "y": 0,
      "z": -8,
      "name": "Rock_Volcanic"
    },
    {
      "x": -5,
      "y": -5,
      "z": -7,
      "name": "Rock_Volcanic"
    },
    {
      "x": -5,
      "y": -4,
      "z": -7,
      "name": "Rock_Volcanic_Cracked_Lava"
    },
    {
      "x": -5,
      "y": -3,
      "z": -7,
      "name": "Rock_Volcanic"
    },
    {
      "x": -5,
      "y": -2,
      "z": -7,
      "name": "Rock_Volcanic_Cracked_Lava"
    },
    {
      "x": -5,
      "y": -1,
      "z": -7,
      "name": "Rock_Volcanic"
    },
    {
      "x": -5,
      "y": 0,
      "z": -7,
      "name": "Rock_Volcanic"
    },
    {
      "x": -5,
      "y": -4,
      "z": -6,
      "name": "Rock_Volcanic"
    },
    {
      "x": -5,
      "y": -3,
      "z": -6,
      "name": "Rock_Volcanic"
    },
    {
      "x": -5,
      "y": -2,
      "z": -6,
      "name": "Rock_Volcanic"
    },
    {
      "x": -5,
      "y": -1,
      "z": -6,
      "name": "Rock_Volcanic_Cracked_Lava"
    },
    {
      "x": -5,
      "y": 0,
      "z": -6,
      "name": "Rock_Volcanic"
    },
    {
      "x": -5,
      "y": 2,
      "z": -3,
      "name": "Rock_Volcanic"
    },
    {
      "x": -5,
      "y": 3,
      "z": -3,
      "name": "Rock_Volcanic"
    },
    {
      "x": -5,
      "y": 0,
      "z": -2,
      "name": "Rock_Volcanic_Cracked_Lava"
    },
    {
      "x": -5,
      "y": 1,
      "z": -2,
      "name": "Rock_Volcanic"
    },
    {
      "x": -5,
      "y": 2,
      "z": -2,
      "name": "Rock_Volcanic"
    },
    {
      "x": -5,
      "y": 3,
      "z": -2,
      "name": "Rock_Volcanic"
    },
    {
      "x": -5,
      "y": 4,
      "z": -2,
      "name": "Rock_Volcanic"
    },
    {
      "x": -5,
      "y": -2,
      "z": -1,
      "name": "Rock_Volcanic"
    },
    {
      "x": -5,
      "y": -1,
      "z": -1,
      "name": "Rock_Volcanic_Cracked_Lava"
    },
    {
      "x": -5,
      "y": 0,
      "z": -1,
      "name": "Rock_Volcanic"
    },
    {
      "x": -5,
      "y": 1,
      "z": -1,
      "name": "Rock_Volcanic"
    },
    {
      "x": -5,
      "y": 2,
      "z": -1,
      "name": "Rock_Volcanic"
    },
    {
      "x": -5,
      "y": 3,
      "z": -1,
      "name": "Rock_Volcanic"
    },
    {
      "x": -5,
      "y": 4,
      "z": -1,
      "name": "Rock_Volcanic"
    },
    {
      "x": -5,
      "y": 5,
      "z": -1,
      "name": "Rock_Volcanic"
    },
    {
      "x": -5,
      "y": -3,
      "z": 0,
      "name": "Rock_Volcanic_Cracked_Lava"
    },
    {
      "x": -5,
      "y": -2,
      "z": 0,
      "name": "Rock_Volcanic"
    },
    {
      "x": -5,
      "y": -1,
      "z": 0,
      "name": "Rock_Volcanic_Cracked_Lava"
    },
    {
      "x": -5,
      "y": 0,
      "z": 0,
      "name": "Rock_Volcanic"
    },
    {
      "x": -5,
      "y": 1,
      "z": 0,
      "name": "Rock_Volcanic"
    },
    {
      "x": -5,
      "y": 2,
      "z": 0,
      "name": "Rock_Volcanic"
    },
    {
      "x": -5,
      "y": 3,
      "z": 0,
      "name": "Rock_Volcanic"
    },
    {
      "x": -5,
      "y": 4,
      "z": 0,
      "name": "Rock_Volcanic_Cracked_Lava"
    },
    {
      "x": -5,
      "y": 5,
      "z": 0,
      "name": "Rock_Volcanic"
    },
    {
      "x": -5,
      "y": -1,
      "z": 1,
      "name": "Rock_Volcanic_Cracked_Lava"
    },
    {
      "x": -5,
      "y": 0,
      "z": 1,
      "name": "Rock_Volcanic"
    },
    {
      "x": -5,
      "y": 1,
      "z": 1,
      "name": "Rock_Volcanic"
    },
    {
      "x": -5,
      "y": 2,
      "z": 1,
      "name": "Rock_Volcanic"
    },
    {
      "x": -5,
      "y": 3,
      "z": 1,
      "name": "Rock_Volcanic"
    },
    {
      "x": -5,
      "y": 4,
      "z": 1,
      "name": "Rock_Volcanic"
    },
    {
      "x": -5,
      "y": 5,
      "z": 1,
      "name": "Rock_Volcanic"
    },
    {
      "x": -5,
      "y": 6,
      "z": 1,
      "name": "Rock_Volcanic_Cracked_Lava"
    },
    {
      "x": -5,
      "y": 0,
      "z": 2,
      "name": "Rock_Volcanic"
    },
    {
      "x": -5,
      "y": 1,
      "z": 2,
      "name": "Rock_Volcanic"
    },
    {
      "x": -5,
      "y": 2,
      "z": 2,
      "name": "Rock_Volcanic"
    },
    {
      "x": -5,
      "y": 3,
      "z": 2,
      "name": "Rock_Volcanic"
    },
    {
      "x": -5,
      "y": 4,
      "z": 2,
      "name": "Rock_Volcanic"
    },
    {
      "x": -5,
      "y": 5,
      "z": 2,
      "name": "Rock_Volcanic_Cracked_Lava"
    },
    {
      "x": -5,
      "y": 5,
      "z": 3,
      "name": "Rock_Volcanic_Cracked_Lava"
    },
    {
      "x": -5,
      "y": 6,
      "z": 3,
      "name": "Rock_Volcanic"
    },
    {
      "x": -5,
      "y": 6,
      "z": 4,
      "name": "Rock_Volcanic"
    },
    {
      "x": -5,
      "y": 7,
      "z": 4,
      "name": "Rock_Volcanic_Cracked_Lava"
    },
    {
      "x": -4,
      "y": -17,
      "z": -32,
      "name": "Rock_Volcanic_Cracked_Lava"
    },
    {
      "x": -4,
      "y": -17,
      "z": -31,
      "name": "Rock_Volcanic"
    },
    {
      "x": -4,
      "y": -16,
      "z": -31,
      "name": "Rock_Volcanic"
    },
    {
      "x": -4,
      "y": -17,
      "z": -30,
      "name": "Rock_Volcanic"
    },
    {
      "x": -4,
      "y": -16,
      "z": -30,
      "name": "Rock_Volcanic_Cracked_Lava"
    },
    {
      "x": -4,
      "y": -17,
      "z": -29,
      "name": "Rock_Volcanic"
    },
    {
      "x": -4,
      "y": -15,
      "z": -29,
      "name": "Rock_Volcanic"
    },
    {
      "x": -4,
      "y": -17,
      "z": -28,
      "name": "Rock_Volcanic_Cracked_Lava"
    },
    {
      "x": -4,
      "y": -16,
      "z": -28,
      "name": "Rock_Volcanic"
    },
    {
      "x": -4,
      "y": -15,
      "z": -28,
      "name": "Rock_Volcanic_Cracked_Lava"
    },
    {
      "x": -4,
      "y": -14,
      "z": -28,
      "name": "Rock_Volcanic_Cracked_Lava"
    },
    {
      "x": -4,
      "y": -17,
      "z": -27,
      "name": "Rock_Volcanic_Cracked_Lava"
    },
    {
      "x": -4,
      "y": -16,
      "z": -27,
      "name": "Rock_Volcanic_Cracked_Lava"
    },
    {
      "x": -4,
      "y": -15,
      "z": -27,
      "name": "Rock_Volcanic"
    },
    {
      "x": -4,
      "y": -14,
      "z": -27,
      "name": "Rock_Volcanic"
    },
    {
      "x": -4,
      "y": -17,
      "z": -26,
      "name": "Rock_Volcanic_Cracked_Lava"
    },
    {
      "x": -4,
      "y": -16,
      "z": -26,
      "name": "Rock_Volcanic_Cracked_Lava"
    },
    {
      "x": -4,
      "y": -15,
      "z": -26,
      "name": "Rock_Volcanic"
    },
    {
      "x": -4,
      "y": -14,
      "z": -26,
      "name": "Rock_Volcanic"
    },
    {
      "x": -4,
      "y": -13,
      "z": -26,
      "name": "Rock_Volcanic"
    },
    {
      "x": -4,
      "y": -16,
      "z": -25,
      "name": "Rock_Volcanic_Cracked_Lava"
    },
    {
      "x": -4,
      "y": -15,
      "z": -25,
      "name": "Rock_Volcanic"
    },
    {
      "x": -4,
      "y": -14,
      "z": -25,
      "name": "Rock_Volcanic"
    },
    {
      "x": -4,
      "y": -13,
      "z": -25,
      "name": "Rock_Volcanic"
    },
    {
      "x": -4,
      "y": -12,
      "z": -25,
      "name": "Rock_Volcanic"
    },
    {
      "x": -4,
      "y": -15,
      "z": -24,
      "name": "Rock_Volcanic_Cracked_Lava"
    },
    {
      "x": -4,
      "y": -14,
      "z": -24,
      "name": "Rock_Volcanic"
    },
    {
      "x": -4,
      "y": -13,
      "z": -24,
      "name": "Rock_Volcanic"
    },
    {
      "x": -4,
      "y": -12,
      "z": -24,
      "name": "Rock_Volcanic"
    },
    {
      "x": -4,
      "y": -16,
      "z": -23,
      "name": "Rock_Volcanic"
    },
    {
      "x": -4,
      "y": -15,
      "z": -23,
      "name": "Rock_Volcanic"
    },
    {
      "x": -4,
      "y": -14,
      "z": -23,
      "name": "Rock_Volcanic_Cracked_Lava"
    },
    {
      "x": -4,
      "y": -13,
      "z": -23,
      "name": "Rock_Volcanic"
    },
    {
      "x": -4,
      "y": -12,
      "z": -23,
      "name": "Rock_Volcanic"
    },
    {
      "x": -4,
      "y": -15,
      "z": -22,
      "name": "Rock_Volcanic"
    },
    {
      "x": -4,
      "y": -14,
      "z": -22,
      "name": "Rock_Volcanic"
    },
    {
      "x": -4,
      "y": -13,
      "z": -22,
      "name": "Rock_Volcanic"
    },
    {
      "x": -4,
      "y": -12,
      "z": -22,
      "name": "Rock_Volcanic_Cracked_Lava"
    },
    {
      "x": -4,
      "y": -11,
      "z": -22,
      "name": "Rock_Volcanic_Cracked_Lava"
    },
    {
      "x": -4,
      "y": -14,
      "z": -21,
      "name": "Rock_Volcanic"
    },
    {
      "x": -4,
      "y": -13,
      "z": -21,
      "name": "Rock_Volcanic_Cracked_Lava"
    },
    {
      "x": -4,
      "y": -12,
      "z": -21,
      "name": "Rock_Volcanic"
    },
    {
      "x": -4,
      "y": -11,
      "z": -21,
      "name": "Rock_Volcanic"
    },
    {
      "x": -4,
      "y": -10,
      "z": -21,
      "name": "Rock_Volcanic"
    },
    {
      "x": -4,
      "y": -13,
      "z": -20,
      "name": "Rock_Volcanic_Cracked_Lava"
    },
    {
      "x": -4,
      "y": -12,
      "z": -20,
      "name": "Rock_Volcanic"
    },
    {
      "x": -4,
      "y": -11,
      "z": -20,
      "name": "Rock_Volcanic"
    },
    {
      "x": -4,
      "y": -10,
      "z": -20,
      "name": "Rock_Volcanic_Cracked_Lava"
    },
    {
      "x": -4,
      "y": -9,
      "z": -20,
      "name": "Rock_Volcanic"
    },
    {
      "x": -4,
      "y": -12,
      "z": -19,
      "name": "Rock_Volcanic"
    },
    {
      "x": -4,
      "y": -11,
      "z": -19,
      "name": "Rock_Volcanic"
    },
    {
      "x": -4,
      "y": -10,
      "z": -19,
      "name": "Rock_Volcanic"
    },
    {
      "x": -4,
      "y": -9,
      "z": -19,
      "name": "Rock_Volcanic"
    },
    {
      "x": -4,
      "y": -8,
      "z": -19,
      "name": "Rock_Volcanic"
    },
    {
      "x": -4,
      "y": -12,
      "z": -18,
      "name": "Rock_Volcanic"
    },
    {
      "x": -4,
      "y": -11,
      "z": -18,
      "name": "Rock_Volcanic"
    },
    {
      "x": -4,
      "y": -10,
      "z": -18,
      "name": "Rock_Volcanic"
    },
    {
      "x": -4,
      "y": -9,
      "z": -18,
      "name": "Rock_Volcanic"
    },
    {
      "x": -4,
      "y": -8,
      "z": -18,
      "name": "Rock_Volcanic"
    },
    {
      "x": -4,
      "y": -13,
      "z": -17,
      "name": "Rock_Volcanic"
    },
    {
      "x": -4,
      "y": -12,
      "z": -17,
      "name": "Rock_Volcanic"
    },
    {
      "x": -4,
      "y": -11,
      "z": -17,
      "name": "Rock_Volcanic"
    },
    {
      "x": -4,
      "y": -10,
      "z": -17,
      "name": "Rock_Volcanic"
    },
    {
      "x": -4,
      "y": -9,
      "z": -17,
      "name": "Rock_Volcanic"
    },
    {
      "x": -4,
      "y": -8,
      "z": -17,
      "name": "Rock_Volcanic"
    },
    {
      "x": -4,
      "y": -7,
      "z": -17,
      "name": "Rock_Volcanic"
    },
    {
      "x": -4,
      "y": -6,
      "z": -17,
      "name": "Rock_Volcanic"
    },
    {
      "x": -4,
      "y": -13,
      "z": -16,
      "name": "Rock_Volcanic"
    },
    {
      "x": -4,
      "y": -12,
      "z": -16,
      "name": "Rock_Volcanic"
    },
    {
      "x": -4,
      "y": -11,
      "z": -16,
      "name": "Rock_Volcanic"
    },
    {
      "x": -4,
      "y": -10,
      "z": -16,
      "name": "Rock_Volcanic"
    },
    {
      "x": -4,
      "y": -9,
      "z": -16,
      "name": "Rock_Volcanic_Cracked_Lava"
    },
    {
      "x": -4,
      "y": -8,
      "z": -16,
      "name": "Rock_Volcanic"
    },
    {
      "x": -4,
      "y": -7,
      "z": -16,
      "name": "Rock_Volcanic"
    },
    {
      "x": -4,
      "y": -6,
      "z": -16,
      "name": "Rock_Volcanic"
    },
    {
      "x": -4,
      "y": -12,
      "z": -15,
      "name": "Rock_Volcanic"
    },
    {
      "x": -4,
      "y": -11,
      "z": -15,
      "name": "Rock_Volcanic"
    },
    {
      "x": -4,
      "y": -10,
      "z": -15,
      "name": "Rock_Volcanic"
    },
    {
      "x": -4,
      "y": -9,
      "z": -15,
      "name": "Rock_Volcanic"
    },
    {
      "x": -4,
      "y": -8,
      "z": -15,
      "name": "Rock_Volcanic_Cracked_Lava"
    },
    {
      "x": -4,
      "y": -7,
      "z": -15,
      "name": "Rock_Volcanic_Cracked_Lava"
    },
    {
      "x": -4,
      "y": -6,
      "z": -15,
      "name": "Rock_Volcanic"
    },
    {
      "x": -4,
      "y": -5,
      "z": -15,
      "name": "Rock_Volcanic"
    },
    {
      "x": -4,
      "y": -11,
      "z": -14,
      "name": "Rock_Volcanic"
    },
    {
      "x": -4,
      "y": -10,
      "z": -14,
      "name": "Rock_Volcanic"
    },
    {
      "x": -4,
      "y": -9,
      "z": -14,
      "name": "Rock_Volcanic"
    },
    {
      "x": -4,
      "y": -8,
      "z": -14,
      "name": "Rock_Volcanic"
    },
    {
      "x": -4,
      "y": -7,
      "z": -14,
      "name": "Rock_Volcanic"
    },
    {
      "x": -4,
      "y": -6,
      "z": -14,
      "name": "Rock_Volcanic"
    },
    {
      "x": -4,
      "y": -5,
      "z": -14,
      "name": "Rock_Volcanic"
    },
    {
      "x": -4,
      "y": -10,
      "z": -13,
      "name": "Rock_Volcanic"
    },
    {
      "x": -4,
      "y": -9,
      "z": -13,
      "name": "Rock_Volcanic"
    },
    {
      "x": -4,
      "y": -8,
      "z": -13,
      "name": "Rock_Volcanic_Cracked_Lava"
    },
    {
      "x": -4,
      "y": -7,
      "z": -13,
      "name": "Rock_Volcanic"
    },
    {
      "x": -4,
      "y": -6,
      "z": -13,
      "name": "Rock_Volcanic"
    },
    {
      "x": -4,
      "y": -5,
      "z": -13,
      "name": "Rock_Volcanic"
    },
    {
      "x": -4,
      "y": -10,
      "z": -12,
      "name": "Rock_Volcanic"
    },
    {
      "x": -4,
      "y": -9,
      "z": -12,
      "name": "Rock_Volcanic_Cracked_Lava"
    },
    {
      "x": -4,
      "y": -8,
      "z": -12,
      "name": "Rock_Volcanic"
    },
    {
      "x": -4,
      "y": -7,
      "z": -12,
      "name": "Rock_Volcanic"
    },
    {
      "x": -4,
      "y": -6,
      "z": -12,
      "name": "Rock_Volcanic"
    },
    {
      "x": -4,
      "y": -5,
      "z": -12,
      "name": "Rock_Volcanic"
    },
    {
      "x": -4,
      "y": -4,
      "z": -12,
      "name": "Rock_Volcanic_Cracked_Lava"
    },
    {
      "x": -4,
      "y": -3,
      "z": -12,
      "name": "Rock_Volcanic"
    },
    {
      "x": -4,
      "y": -10,
      "z": -11,
      "name": "Rock_Volcanic"
    },
    {
      "x": -4,
      "y": -9,
      "z": -11,
      "name": "Rock_Volcanic"
    },
    {
      "x": -4,
      "y": -8,
      "z": -11,
      "name": "Rock_Volcanic"
    },
    {
      "x": -4,
      "y": -7,
      "z": -11,
      "name": "Rock_Volcanic"
    },
    {
      "x": -4,
      "y": -6,
      "z": -11,
      "name": "Rock_Volcanic_Cracked_Lava"
    },
    {
      "x": -4,
      "y": -5,
      "z": -11,
      "name": "Rock_Volcanic_Cracked_Lava"
    },
    {
      "x": -4,
      "y": -4,
      "z": -11,
      "name": "Rock_Volcanic"
    },
    {
      "x": -4,
      "y": -3,
      "z": -11,
      "name": "Rock_Volcanic"
    },
    {
      "x": -4,
      "y": -2,
      "z": -11,
      "name": "Rock_Volcanic"
    },
    {
      "x": -4,
      "y": -9,
      "z": -10,
      "name": "Rock_Volcanic"
    },
    {
      "x": -4,
      "y": -8,
      "z": -10,
      "name": "Rock_Volcanic"
    },
    {
      "x": -4,
      "y": -7,
      "z": -10,
      "name": "Rock_Volcanic_Cracked_Lava"
    },
    {
      "x": -4,
      "y": -6,
      "z": -10,
      "name": "Rock_Volcanic"
    },
    {
      "x": -4,
      "y": -5,
      "z": -10,
      "name": "Rock_Volcanic"
    },
    {
      "x": -4,
      "y": -4,
      "z": -10,
      "name": "Rock_Volcanic"
    },
    {
      "x": -4,
      "y": -3,
      "z": -10,
      "name": "Rock_Volcanic"
    },
    {
      "x": -4,
      "y": -2,
      "z": -10,
      "name": "Rock_Volcanic"
    },
    {
      "x": -4,
      "y": -8,
      "z": -9,
      "name": "Rock_Volcanic_Cracked_Lava"
    },
    {
      "x": -4,
      "y": -7,
      "z": -9,
      "name": "Rock_Volcanic"
    },
    {
      "x": -4,
      "y": -6,
      "z": -9,
      "name": "Rock_Volcanic"
    },
    {
      "x": -4,
      "y": -5,
      "z": -9,
      "name": "Rock_Volcanic_Cracked_Lava"
    },
    {
      "x": -4,
      "y": -4,
      "z": -9,
      "name": "Rock_Volcanic_Cracked_Lava"
    },
    {
      "x": -4,
      "y": -3,
      "z": -9,
      "name": "Rock_Volcanic_Cracked_Lava"
    },
    {
      "x": -4,
      "y": -2,
      "z": -9,
      "name": "Rock_Volcanic"
    },
    {
      "x": -4,
      "y": -1,
      "z": -9,
      "name": "Rock_Volcanic"
    },
    {
      "x": -4,
      "y": -9,
      "z": -8,
      "name": "Rock_Volcanic"
    },
    {
      "x": -4,
      "y": -8,
      "z": -8,
      "name": "Rock_Volcanic"
    },
    {
      "x": -4,
      "y": -7,
      "z": -8,
      "name": "Rock_Volcanic"
    },
    {
      "x": -4,
      "y": -6,
      "z": -8,
      "name": "Rock_Volcanic"
    },
    {
      "x": -4,
      "y": -5,
      "z": -8,
      "name": "Rock_Volcanic"
    },
    {
      "x": -4,
      "y": -4,
      "z": -8,
      "name": "Rock_Volcanic"
    },
    {
      "x": -4,
      "y": -3,
      "z": -8,
      "name": "Rock_Volcanic"
    },
    {
      "x": -4,
      "y": -2,
      "z": -8,
      "name": "Rock_Volcanic"
    },
    {
      "x": -4,
      "y": -1,
      "z": -8,
      "name": "Rock_Volcanic"
    },
    {
      "x": -4,
      "y": 0,
      "z": -8,
      "name": "Rock_Volcanic_Cracked_Lava"
    },
    {
      "x": -4,
      "y": -9,
      "z": -7,
      "name": "Rock_Volcanic"
    },
    {
      "x": -4,
      "y": -8,
      "z": -7,
      "name": "Rock_Volcanic"
    },
    {
      "x": -4,
      "y": -7,
      "z": -7,
      "name": "Rock_Volcanic"
    },
    {
      "x": -4,
      "y": -6,
      "z": -7,
      "name": "Rock_Volcanic"
    },
    {
      "x": -4,
      "y": -5,
      "z": -7,
      "name": "Rock_Volcanic"
    },
    {
      "x": -4,
      "y": -4,
      "z": -7,
      "name": "Rock_Volcanic"
    },
    {
      "x": -4,
      "y": -3,
      "z": -7,
      "name": "Rock_Volcanic"
    },
    {
      "x": -4,
      "y": -2,
      "z": -7,
      "name": "Rock_Volcanic"
    },
    {
      "x": -4,
      "y": -1,
      "z": -7,
      "name": "Rock_Volcanic"
    },
    {
      "x": -4,
      "y": 0,
      "z": -7,
      "name": "Rock_Volcanic"
    },
    {
      "x": -4,
      "y": -7,
      "z": -6,
      "name": "Rock_Volcanic"
    },
    {
      "x": -4,
      "y": -6,
      "z": -6,
      "name": "Rock_Volcanic"
    },
    {
      "x": -4,
      "y": -5,
      "z": -6,
      "name": "Rock_Volcanic"
    },
    {
      "x": -4,
      "y": -4,
      "z": -6,
      "name": "Rock_Volcanic_Cracked_Lava"
    },
    {
      "x": -4,
      "y": -3,
      "z": -6,
      "name": "Rock_Volcanic"
    },
    {
      "x": -4,
      "y": -2,
      "z": -6,
      "name": "Rock_Volcanic"
    },
    {
      "x": -4,
      "y": -1,
      "z": -6,
      "name": "Rock_Volcanic_Cracked_Lava"
    },
    {
      "x": -4,
      "y": 0,
      "z": -6,
      "name": "Rock_Volcanic"
    },
    {
      "x": -4,
      "y": 1,
      "z": -6,
      "name": "Rock_Volcanic"
    },
    {
      "x": -4,
      "y": -7,
      "z": -5,
      "name": "Rock_Volcanic"
    },
    {
      "x": -4,
      "y": -6,
      "z": -5,
      "name": "Rock_Volcanic"
    },
    {
      "x": -4,
      "y": -5,
      "z": -5,
      "name": "Rock_Volcanic"
    },
    {
      "x": -4,
      "y": -4,
      "z": -5,
      "name": "Rock_Volcanic"
    },
    {
      "x": -4,
      "y": -3,
      "z": -5,
      "name": "Rock_Volcanic"
    },
    {
      "x": -4,
      "y": -2,
      "z": -5,
      "name": "Rock_Volcanic"
    },
    {
      "x": -4,
      "y": -1,
      "z": -5,
      "name": "Rock_Volcanic_Cracked_Lava"
    },
    {
      "x": -4,
      "y": 0,
      "z": -5,
      "name": "Rock_Volcanic"
    },
    {
      "x": -4,
      "y": 1,
      "z": -5,
      "name": "Rock_Volcanic"
    },
    {
      "x": -4,
      "y": -6,
      "z": -4,
      "name": "Rock_Volcanic"
    },
    {
      "x": -4,
      "y": -5,
      "z": -4,
      "name": "Rock_Volcanic"
    },
    {
      "x": -4,
      "y": -4,
      "z": -4,
      "name": "Rock_Volcanic_Cracked_Lava"
    },
    {
      "x": -4,
      "y": -3,
      "z": -4,
      "name": "Rock_Volcanic"
    },
    {
      "x": -4,
      "y": -2,
      "z": -4,
      "name": "Rock_Volcanic_Cracked_Lava"
    },
    {
      "x": -4,
      "y": -1,
      "z": -4,
      "name": "Rock_Volcanic"
    },
    {
      "x": -4,
      "y": 0,
      "z": -4,
      "name": "Rock_Volcanic"
    },
    {
      "x": -4,
      "y": 1,
      "z": -4,
      "name": "Rock_Volcanic_Cracked_Lava"
    },
    {
      "x": -4,
      "y": -5,
      "z": -3,
      "name": "Rock_Volcanic_Cracked_Lava"
    },
    {
      "x": -4,
      "y": -4,
      "z": -3,
      "name": "Rock_Volcanic"
    },
    {
      "x": -4,
      "y": -3,
      "z": -3,
      "name": "Rock_Volcanic"
    },
    {
      "x": -4,
      "y": -2,
      "z": -3,
      "name": "Rock_Volcanic_Cracked_Lava"
    },
    {
      "x": -4,
      "y": -1,
      "z": -3,
      "name": "Rock_Volcanic"
    },
    {
      "x": -4,
      "y": 0,
      "z": -3,
      "name": "Rock_Volcanic"
    },
    {
      "x": -4,
      "y": 1,
      "z": -3,
      "name": "Rock_Volcanic"
    },
    {
      "x": -4,
      "y": 2,
      "z": -3,
      "name": "Rock_Volcanic_Cracked_Lava"
    },
    {
      "x": -4,
      "y": 3,
      "z": -3,
      "name": "Rock_Volcanic"
    },
    {
      "x": -4,
      "y": -5,
      "z": -2,
      "name": "Rock_Volcanic_Cracked_Lava"
    },
    {
      "x": -4,
      "y": -4,
      "z": -2,
      "name": "Rock_Volcanic"
    },
    {
      "x": -4,
      "y": -3,
      "z": -2,
      "name": "Rock_Volcanic"
    },
    {
      "x": -4,
      "y": -2,
      "z": -2,
      "name": "Rock_Volcanic_Cracked_Lava"
    },
    {
      "x": -4,
      "y": -1,
      "z": -2,
      "name": "Rock_Volcanic"
    },
    {
      "x": -4,
      "y": 0,
      "z": -2,
      "name": "Rock_Volcanic"
    },
    {
      "x": -4,
      "y": 1,
      "z": -2,
      "name": "Rock_Volcanic"
    },
    {
      "x": -4,
      "y": 2,
      "z": -2,
      "name": "Rock_Volcanic"
    },
    {
      "x": -4,
      "y": 3,
      "z": -2,
      "name": "Rock_Volcanic_Cracked_Lava"
    },
    {
      "x": -4,
      "y": 4,
      "z": -2,
      "name": "Rock_Volcanic"
    },
    {
      "x": -4,
      "y": 5,
      "z": -2,
      "name": "Rock_Volcanic"
    },
    {
      "x": -4,
      "y": -5,
      "z": -1,
      "name": "Rock_Volcanic"
    },
    {
      "x": -4,
      "y": -4,
      "z": -1,
      "name": "Rock_Volcanic"
    },
    {
      "x": -4,
      "y": -3,
      "z": -1,
      "name": "Rock_Volcanic"
    },
    {
      "x": -4,
      "y": -2,
      "z": -1,
      "name": "Rock_Volcanic"
    },
    {
      "x": -4,
      "y": -1,
      "z": -1,
      "name": "Rock_Volcanic"
    },
    {
      "x": -4,
      "y": 0,
      "z": -1,
      "name": "Rock_Volcanic"
    },
    {
      "x": -4,
      "y": 1,
      "z": -1,
      "name": "Rock_Volcanic"
    },
    {
      "x": -4,
      "y": 2,
      "z": -1,
      "name": "Rock_Volcanic"
    },
    {
      "x": -4,
      "y": 3,
      "z": -1,
      "name": "Rock_Volcanic"
    },
    {
      "x": -4,
      "y": 4,
      "z": -1,
      "name": "Rock_Volcanic"
    },
    {
      "x": -4,
      "y": 5,
      "z": -1,
      "name": "Rock_Volcanic"
    },
    {
      "x": -4,
      "y": -5,
      "z": 0,
      "name": "Rock_Volcanic"
    },
    {
      "x": -4,
      "y": -4,
      "z": 0,
      "name": "Rock_Volcanic"
    },
    {
      "x": -4,
      "y": -3,
      "z": 0,
      "name": "Rock_Volcanic"
    },
    {
      "x": -4,
      "y": -2,
      "z": 0,
      "name": "Rock_Volcanic_Cracked_Lava"
    },
    {
      "x": -4,
      "y": -1,
      "z": 0,
      "name": "Rock_Volcanic"
    },
    {
      "x": -4,
      "y": 0,
      "z": 0,
      "name": "Rock_Volcanic"
    },
    {
      "x": -4,
      "y": 1,
      "z": 0,
      "name": "Rock_Volcanic"
    },
    {
      "x": -4,
      "y": 2,
      "z": 0,
      "name": "Rock_Volcanic"
    },
    {
      "x": -4,
      "y": 3,
      "z": 0,
      "name": "Rock_Volcanic_Cracked_Lava"
    },
    {
      "x": -4,
      "y": 4,
      "z": 0,
      "name": "Rock_Volcanic_Cracked_Lava"
    },
    {
      "x": -4,
      "y": 5,
      "z": 0,
      "name": "Rock_Volcanic"
    },
    {
      "x": -4,
      "y": -5,
      "z": 1,
      "name": "Rock_Volcanic_Cracked_Lava"
    },
    {
      "x": -4,
      "y": -4,
      "z": 1,
      "name": "Rock_Volcanic_Cracked_Lava"
    },
    {
      "x": -4,
      "y": -3,
      "z": 1,
      "name": "Rock_Volcanic"
    },
    {
      "x": -4,
      "y": -2,
      "z": 1,
      "name": "Rock_Volcanic"
    },
    {
      "x": -4,
      "y": -1,
      "z": 1,
      "name": "Rock_Volcanic_Cracked_Lava"
    },
    {
      "x": -4,
      "y": 0,
      "z": 1,
      "name": "Rock_Volcanic_Cracked_Lava"
    },
    {
      "x": -4,
      "y": 1,
      "z": 1,
      "name": "Rock_Volcanic_Cracked_Lava"
    },
    {
      "x": -4,
      "y": 2,
      "z": 1,
      "name": "Rock_Volcanic"
    },
    {
      "x": -4,
      "y": 3,
      "z": 1,
      "name": "Rock_Volcanic_Cracked_Lava"
    },
    {
      "x": -4,
      "y": 4,
      "z": 1,
      "name": "Rock_Volcanic"
    },
    {
      "x": -4,
      "y": 5,
      "z": 1,
      "name": "Rock_Volcanic"
    },
    {
      "x": -4,
      "y": 6,
      "z": 1,
      "name": "Rock_Volcanic"
    },
    {
      "x": -4,
      "y": -5,
      "z": 2,
      "name": "Rock_Volcanic"
    },
    {
      "x": -4,
      "y": -4,
      "z": 2,
      "name": "Rock_Volcanic_Cracked_Lava"
    },
    {
      "x": -4,
      "y": -3,
      "z": 2,
      "name": "Rock_Volcanic"
    },
    {
      "x": -4,
      "y": -2,
      "z": 2,
      "name": "Rock_Volcanic_Cracked_Lava"
    },
    {
      "x": -4,
      "y": -1,
      "z": 2,
      "name": "Rock_Volcanic"
    },
    {
      "x": -4,
      "y": 0,
      "z": 2,
      "name": "Rock_Volcanic"
    },
    {
      "x": -4,
      "y": 1,
      "z": 2,
      "name": "Rock_Volcanic"
    },
    {
      "x": -4,
      "y": 2,
      "z": 2,
      "name": "Rock_Volcanic"
    },
    {
      "x": -4,
      "y": 3,
      "z": 2,
      "name": "Rock_Volcanic"
    },
    {
      "x": -4,
      "y": 4,
      "z": 2,
      "name": "Rock_Volcanic"
    },
    {
      "x": -4,
      "y": 5,
      "z": 2,
      "name": "Rock_Volcanic"
    },
    {
      "x": -4,
      "y": -4,
      "z": 3,
      "name": "Rock_Volcanic"
    },
    {
      "x": -4,
      "y": -3,
      "z": 3,
      "name": "Rock_Volcanic"
    },
    {
      "x": -4,
      "y": -2,
      "z": 3,
      "name": "Rock_Volcanic"
    },
    {
      "x": -4,
      "y": -1,
      "z": 3,
      "name": "Rock_Volcanic"
    },
    {
      "x": -4,
      "y": 0,
      "z": 3,
      "name": "Rock_Volcanic"
    },
    {
      "x": -4,
      "y": 1,
      "z": 3,
      "name": "Rock_Volcanic"
    },
    {
      "x": -4,
      "y": 2,
      "z": 3,
      "name": "Rock_Volcanic"
    },
    {
      "x": -4,
      "y": 3,
      "z": 3,
      "name": "Rock_Volcanic"
    },
    {
      "x": -4,
      "y": 4,
      "z": 3,
      "name": "Rock_Volcanic_Cracked_Lava"
    },
    {
      "x": -4,
      "y": 5,
      "z": 3,
      "name": "Rock_Volcanic"
    },
    {
      "x": -4,
      "y": 6,
      "z": 3,
      "name": "Rock_Volcanic"
    },
    {
      "x": -4,
      "y": -3,
      "z": 4,
      "name": "Rock_Volcanic"
    },
    {
      "x": -4,
      "y": -2,
      "z": 4,
      "name": "Rock_Volcanic"
    },
    {
      "x": -4,
      "y": -1,
      "z": 4,
      "name": "Rock_Volcanic"
    },
    {
      "x": -4,
      "y": 0,
      "z": 4,
      "name": "Rock_Volcanic"
    },
    {
      "x": -4,
      "y": 1,
      "z": 4,
      "name": "Rock_Volcanic"
    },
    {
      "x": -4,
      "y": 2,
      "z": 4,
      "name": "Rock_Volcanic"
    },
    {
      "x": -4,
      "y": 3,
      "z": 4,
      "name": "Rock_Volcanic"
    },
    {
      "x": -4,
      "y": 4,
      "z": 4,
      "name": "Rock_Volcanic"
    },
    {
      "x": -4,
      "y": 5,
      "z": 4,
      "name": "Rock_Volcanic"
    },
    {
      "x": -4,
      "y": 6,
      "z": 4,
      "name": "Rock_Volcanic"
    },
    {
      "x": -4,
      "y": 7,
      "z": 4,
      "name": "Rock_Volcanic_Cracked_Lava"
    },
    {
      "x": -4,
      "y": -2,
      "z": 5,
      "name": "Rock_Volcanic"
    },
    {
      "x": -4,
      "y": -1,
      "z": 5,
      "name": "Rock_Volcanic"
    },
    {
      "x": -4,
      "y": 0,
      "z": 5,
      "name": "Rock_Volcanic"
    },
    {
      "x": -4,
      "y": 1,
      "z": 5,
      "name": "Rock_Volcanic"
    },
    {
      "x": -4,
      "y": 2,
      "z": 5,
      "name": "Rock_Volcanic_Cracked_Lava"
    },
    {
      "x": -4,
      "y": 3,
      "z": 5,
      "name": "Rock_Volcanic"
    },
    {
      "x": -4,
      "y": 4,
      "z": 5,
      "name": "Rock_Volcanic_Cracked_Lava"
    },
    {
      "x": -4,
      "y": 5,
      "z": 5,
      "name": "Rock_Volcanic"
    },
    {
      "x": -4,
      "y": 6,
      "z": 5,
      "name": "Rock_Volcanic"
    },
    {
      "x": -4,
      "y": 7,
      "z": 5,
      "name": "Rock_Volcanic"
    },
    {
      "x": -4,
      "y": -1,
      "z": 6,
      "name": "Rock_Volcanic_Cracked_Lava"
    },
    {
      "x": -4,
      "y": 0,
      "z": 6,
      "name": "Rock_Volcanic"
    },
    {
      "x": -4,
      "y": 1,
      "z": 6,
      "name": "Rock_Volcanic"
    },
    {
      "x": -4,
      "y": 2,
      "z": 6,
      "name": "Rock_Volcanic"
    },
    {
      "x": -4,
      "y": 3,
      "z": 6,
      "name": "Rock_Volcanic"
    },
    {
      "x": -4,
      "y": 4,
      "z": 6,
      "name": "Rock_Volcanic_Cracked_Lava"
    },
    {
      "x": -4,
      "y": 5,
      "z": 6,
      "name": "Rock_Volcanic"
    },
    {
      "x": -4,
      "y": 6,
      "z": 6,
      "name": "Rock_Volcanic"
    },
    {
      "x": -4,
      "y": -2,
      "z": 7,
      "name": "Rock_Volcanic_Cracked_Lava"
    },
    {
      "x": -4,
      "y": -1,
      "z": 7,
      "name": "Rock_Volcanic"
    },
    {
      "x": -4,
      "y": 0,
      "z": 7,
      "name": "Rock_Volcanic"
    },
    {
      "x": -4,
      "y": 1,
      "z": 7,
      "name": "Rock_Volcanic"
    },
    {
      "x": -4,
      "y": 2,
      "z": 7,
      "name": "Rock_Volcanic"
    },
    {
      "x": -4,
      "y": 5,
      "z": 7,
      "name": "Rock_Volcanic"
    },
    {
      "x": -4,
      "y": 6,
      "z": 7,
      "name": "Rock_Volcanic"
    },
    {
      "x": -4,
      "y": 0,
      "z": 8,
      "name": "Rock_Volcanic"
    },
    {
      "x": -4,
      "y": 1,
      "z": 8,
      "name": "Rock_Volcanic"
    },
    {
      "x": -3,
      "y": -17,
      "z": -29,
      "name": "Rock_Volcanic"
    },
    {
      "x": -3,
      "y": -15,
      "z": -29,
      "name": "Rock_Volcanic_Cracked_Lava"
    },
    {
      "x": -3,
      "y": -17,
      "z": -28,
      "name": "Rock_Volcanic"
    },
    {
      "x": -3,
      "y": -16,
      "z": -28,
      "name": "Rock_Volcanic"
    },
    {
      "x": -3,
      "y": -15,
      "z": -28,
      "name": "Rock_Volcanic"
    },
    {
      "x": -3,
      "y": -14,
      "z": -28,
      "name": "Rock_Volcanic"
    },
    {
      "x": -3,
      "y": -17,
      "z": -27,
      "name": "Rock_Volcanic_Cracked_Lava"
    },
    {
      "x": -3,
      "y": -16,
      "z": -27,
      "name": "Rock_Volcanic_Cracked_Lava"
    },
    {
      "x": -3,
      "y": -15,
      "z": -27,
      "name": "Rock_Volcanic"
    },
    {
      "x": -3,
      "y": -14,
      "z": -27,
      "name": "Rock_Volcanic"
    },
    {
      "x": -3,
      "y": -17,
      "z": -26,
      "name": "Rock_Volcanic"
    },
    {
      "x": -3,
      "y": -16,
      "z": -26,
      "name": "Rock_Volcanic_Cracked_Lava"
    },
    {
      "x": -3,
      "y": -15,
      "z": -26,
      "name": "Rock_Volcanic"
    },
    {
      "x": -3,
      "y": -14,
      "z": -26,
      "name": "Rock_Volcanic"
    },
    {
      "x": -3,
      "y": -13,
      "z": -26,
      "name": "Rock_Volcanic"
    },
    {
      "x": -3,
      "y": -16,
      "z": -25,
      "name": "Rock_Volcanic"
    },
    {
      "x": -3,
      "y": -15,
      "z": -25,
      "name": "Rock_Volcanic"
    },
    {
      "x": -3,
      "y": -14,
      "z": -25,
      "name": "Rock_Volcanic_Cracked_Lava"
    },
    {
      "x": -3,
      "y": -13,
      "z": -25,
      "name": "Rock_Volcanic"
    },
    {
      "x": -3,
      "y": -12,
      "z": -25,
      "name": "Rock_Volcanic"
    },
    {
      "x": -3,
      "y": -15,
      "z": -24,
      "name": "Rock_Volcanic"
    },
    {
      "x": -3,
      "y": -14,
      "z": -24,
      "name": "Rock_Volcanic_Cracked_Lava"
    },
    {
      "x": -3,
      "y": -13,
      "z": -24,
      "name": "Rock_Volcanic"
    },
    {
      "x": -3,
      "y": -12,
      "z": -24,
      "name": "Rock_Volcanic"
    },
    {
      "x": -3,
      "y": -15,
      "z": -23,
      "name": "Rock_Volcanic"
    },
    {
      "x": -3,
      "y": -14,
      "z": -23,
      "name": "Rock_Volcanic"
    },
    {
      "x": -3,
      "y": -13,
      "z": -23,
      "name": "Rock_Volcanic"
    },
    {
      "x": -3,
      "y": -12,
      "z": -23,
      "name": "Rock_Volcanic_Cracked_Lava"
    },
    {
      "x": -3,
      "y": -11,
      "z": -23,
      "name": "Rock_Volcanic"
    },
    {
      "x": -3,
      "y": -10,
      "z": -23,
      "name": "Rock_Volcanic_Cracked_Lava"
    },
    {
      "x": -3,
      "y": -15,
      "z": -22,
      "name": "Rock_Volcanic"
    },
    {
      "x": -3,
      "y": -14,
      "z": -22,
      "name": "Rock_Volcanic"
    },
    {
      "x": -3,
      "y": -13,
      "z": -22,
      "name": "Rock_Volcanic_Cracked_Lava"
    },
    {
      "x": -3,
      "y": -12,
      "z": -22,
      "name": "Rock_Volcanic"
    },
    {
      "x": -3,
      "y": -11,
      "z": -22,
      "name": "Rock_Volcanic_Cracked_Lava"
    },
    {
      "x": -3,
      "y": -10,
      "z": -22,
      "name": "Rock_Volcanic"
    },
    {
      "x": -3,
      "y": -14,
      "z": -21,
      "name": "Rock_Volcanic_Cracked_Lava"
    },
    {
      "x": -3,
      "y": -13,
      "z": -21,
      "name": "Rock_Volcanic"
    },
    {
      "x": -3,
      "y": -12,
      "z": -21,
      "name": "Rock_Volcanic"
    },
    {
      "x": -3,
      "y": -11,
      "z": -21,
      "name": "Rock_Volcanic"
    },
    {
      "x": -3,
      "y": -10,
      "z": -21,
      "name": "Rock_Volcanic"
    },
    {
      "x": -3,
      "y": -13,
      "z": -20,
      "name": "Rock_Volcanic"
    },
    {
      "x": -3,
      "y": -12,
      "z": -20,
      "name": "Rock_Volcanic"
    },
    {
      "x": -3,
      "y": -11,
      "z": -20,
      "name": "Rock_Volcanic"
    },
    {
      "x": -3,
      "y": -10,
      "z": -20,
      "name": "Rock_Volcanic_Cracked_Lava"
    },
    {
      "x": -3,
      "y": -9,
      "z": -20,
      "name": "Rock_Volcanic"
    },
    {
      "x": -3,
      "y": -12,
      "z": -19,
      "name": "Rock_Volcanic"
    },
    {
      "x": -3,
      "y": -11,
      "z": -19,
      "name": "Rock_Volcanic"
    },
    {
      "x": -3,
      "y": -10,
      "z": -19,
      "name": "Rock_Volcanic"
    },
    {
      "x": -3,
      "y": -9,
      "z": -19,
      "name": "Rock_Volcanic_Cracked_Lava"
    },
    {
      "x": -3,
      "y": -8,
      "z": -19,
      "name": "Rock_Volcanic"
    },
    {
      "x": -3,
      "y": -12,
      "z": -18,
      "name": "Rock_Volcanic_Cracked_Lava"
    },
    {
      "x": -3,
      "y": -11,
      "z": -18,
      "name": "Rock_Volcanic"
    },
    {
      "x": -3,
      "y": -10,
      "z": -18,
      "name": "Rock_Volcanic"
    },
    {
      "x": -3,
      "y": -9,
      "z": -18,
      "name": "Rock_Volcanic"
    },
    {
      "x": -3,
      "y": -8,
      "z": -18,
      "name": "Rock_Volcanic"
    },
    {
      "x": -3,
      "y": -7,
      "z": -18,
      "name": "Rock_Volcanic"
    },
    {
      "x": -3,
      "y": -13,
      "z": -17,
      "name": "Rock_Volcanic_Cracked_Lava"
    },
    {
      "x": -3,
      "y": -12,
      "z": -17,
      "name": "Rock_Volcanic"
    },
    {
      "x": -3,
      "y": -11,
      "z": -17,
      "name": "Rock_Volcanic_Cracked_Lava"
    },
    {
      "x": -3,
      "y": -10,
      "z": -17,
      "name": "Rock_Volcanic"
    },
    {
      "x": -3,
      "y": -9,
      "z": -17,
      "name": "Rock_Volcanic"
    },
    {
      "x": -3,
      "y": -8,
      "z": -17,
      "name": "Rock_Volcanic"
    },
    {
      "x": -3,
      "y": -7,
      "z": -17,
      "name": "Rock_Volcanic"
    },
    {
      "x": -3,
      "y": -6,
      "z": -17,
      "name": "Rock_Volcanic_Cracked_Lava"
    },
    {
      "x": -3,
      "y": -13,
      "z": -16,
      "name": "Rock_Volcanic"
    },
    {
      "x": -3,
      "y": -12,
      "z": -16,
      "name": "Rock_Volcanic_Cracked_Lava"
    },
    {
      "x": -3,
      "y": -11,
      "z": -16,
      "name": "Rock_Volcanic"
    },
    {
      "x": -3,
      "y": -10,
      "z": -16,
      "name": "Rock_Volcanic"
    },
    {
      "x": -3,
      "y": -9,
      "z": -16,
      "name": "Rock_Volcanic"
    },
    {
      "x": -3,
      "y": -8,
      "z": -16,
      "name": "Rock_Volcanic"
    },
    {
      "x": -3,
      "y": -7,
      "z": -16,
      "name": "Rock_Volcanic"
    },
    {
      "x": -3,
      "y": -6,
      "z": -16,
      "name": "Rock_Volcanic"
    },
    {
      "x": -3,
      "y": -12,
      "z": -15,
      "name": "Rock_Volcanic"
    },
    {
      "x": -3,
      "y": -11,
      "z": -15,
      "name": "Rock_Volcanic"
    },
    {
      "x": -3,
      "y": -10,
      "z": -15,
      "name": "Rock_Volcanic"
    },
    {
      "x": -3,
      "y": -9,
      "z": -15,
      "name": "Rock_Volcanic"
    },
    {
      "x": -3,
      "y": -8,
      "z": -15,
      "name": "Rock_Volcanic"
    },
    {
      "x": -3,
      "y": -7,
      "z": -15,
      "name": "Rock_Volcanic"
    },
    {
      "x": -3,
      "y": -6,
      "z": -15,
      "name": "Rock_Volcanic_Cracked_Lava"
    },
    {
      "x": -3,
      "y": -5,
      "z": -15,
      "name": "Rock_Volcanic"
    },
    {
      "x": -3,
      "y": -11,
      "z": -14,
      "name": "Rock_Volcanic"
    },
    {
      "x": -3,
      "y": -10,
      "z": -14,
      "name": "Rock_Volcanic_Cracked_Lava"
    },
    {
      "x": -3,
      "y": -9,
      "z": -14,
      "name": "Rock_Volcanic"
    },
    {
      "x": -3,
      "y": -8,
      "z": -14,
      "name": "Rock_Volcanic"
    },
    {
      "x": -3,
      "y": -7,
      "z": -14,
      "name": "Rock_Volcanic"
    },
    {
      "x": -3,
      "y": -6,
      "z": -14,
      "name": "Rock_Volcanic"
    },
    {
      "x": -3,
      "y": -5,
      "z": -14,
      "name": "Rock_Volcanic"
    },
    {
      "x": -3,
      "y": -10,
      "z": -13,
      "name": "Rock_Volcanic"
    },
    {
      "x": -3,
      "y": -9,
      "z": -13,
      "name": "Rock_Volcanic_Cracked_Lava"
    },
    {
      "x": -3,
      "y": -8,
      "z": -13,
      "name": "Rock_Volcanic"
    },
    {
      "x": -3,
      "y": -7,
      "z": -13,
      "name": "Rock_Volcanic"
    },
    {
      "x": -3,
      "y": -6,
      "z": -13,
      "name": "Rock_Volcanic"
    },
    {
      "x": -3,
      "y": -5,
      "z": -13,
      "name": "Rock_Volcanic"
    },
    {
      "x": -3,
      "y": -10,
      "z": -12,
      "name": "Rock_Volcanic"
    },
    {
      "x": -3,
      "y": -9,
      "z": -12,
      "name": "Rock_Volcanic"
    },
    {
      "x": -3,
      "y": -8,
      "z": -12,
      "name": "Rock_Volcanic"
    },
    {
      "x": -3,
      "y": -7,
      "z": -12,
      "name": "Rock_Volcanic"
    },
    {
      "x": -3,
      "y": -6,
      "z": -12,
      "name": "Rock_Volcanic"
    },
    {
      "x": -3,
      "y": -5,
      "z": -12,
      "name": "Rock_Volcanic"
    },
    {
      "x": -3,
      "y": -4,
      "z": -12,
      "name": "Rock_Volcanic"
    },
    {
      "x": -3,
      "y": -3,
      "z": -12,
      "name": "Rock_Volcanic"
    },
    {
      "x": -3,
      "y": -9,
      "z": -11,
      "name": "Rock_Volcanic"
    },
    {
      "x": -3,
      "y": -8,
      "z": -11,
      "name": "Rock_Volcanic"
    },
    {
      "x": -3,
      "y": -7,
      "z": -11,
      "name": "Rock_Volcanic"
    },
    {
      "x": -3,
      "y": -6,
      "z": -11,
      "name": "Rock_Volcanic_Cracked_Lava"
    },
    {
      "x": -3,
      "y": -5,
      "z": -11,
      "name": "Rock_Volcanic"
    },
    {
      "x": -3,
      "y": -4,
      "z": -11,
      "name": "Rock_Volcanic"
    },
    {
      "x": -3,
      "y": -3,
      "z": -11,
      "name": "Rock_Volcanic"
    },
    {
      "x": -3,
      "y": -2,
      "z": -11,
      "name": "Rock_Volcanic"
    },
    {
      "x": -3,
      "y": -9,
      "z": -10,
      "name": "Rock_Volcanic_Cracked_Lava"
    },
    {
      "x": -3,
      "y": -8,
      "z": -10,
      "name": "Rock_Volcanic"
    },
    {
      "x": -3,
      "y": -7,
      "z": -10,
      "name": "Rock_Volcanic_Cracked_Lava"
    },
    {
      "x": -3,
      "y": -6,
      "z": -10,
      "name": "Rock_Volcanic"
    },
    {
      "x": -3,
      "y": -5,
      "z": -10,
      "name": "Rock_Volcanic"
    },
    {
      "x": -3,
      "y": -4,
      "z": -10,
      "name": "Rock_Volcanic"
    },
    {
      "x": -3,
      "y": -3,
      "z": -10,
      "name": "Rock_Volcanic_Cracked_Lava"
    },
    {
      "x": -3,
      "y": -2,
      "z": -10,
      "name": "Rock_Volcanic"
    },
    {
      "x": -3,
      "y": -8,
      "z": -9,
      "name": "Rock_Volcanic_Cracked_Lava"
    },
    {
      "x": -3,
      "y": -7,
      "z": -9,
      "name": "Rock_Volcanic"
    },
    {
      "x": -3,
      "y": -6,
      "z": -9,
      "name": "Rock_Volcanic_Cracked_Lava"
    },
    {
      "x": -3,
      "y": -5,
      "z": -9,
      "name": "Rock_Volcanic_Cracked_Lava"
    },
    {
      "x": -3,
      "y": -4,
      "z": -9,
      "name": "Rock_Volcanic"
    },
    {
      "x": -3,
      "y": -3,
      "z": -9,
      "name": "Rock_Volcanic"
    },
    {
      "x": -3,
      "y": -2,
      "z": -9,
      "name": "Rock_Volcanic"
    },
    {
      "x": -3,
      "y": -1,
      "z": -9,
      "name": "Rock_Volcanic_Cracked_Lava"
    },
    {
      "x": -3,
      "y": -9,
      "z": -8,
      "name": "Rock_Volcanic_Cracked_Lava"
    },
    {
      "x": -3,
      "y": -8,
      "z": -8,
      "name": "Rock_Volcanic"
    },
    {
      "x": -3,
      "y": -7,
      "z": -8,
      "name": "Rock_Volcanic"
    },
    {
      "x": -3,
      "y": -6,
      "z": -8,
      "name": "Rock_Volcanic"
    },
    {
      "x": -3,
      "y": -5,
      "z": -8,
      "name": "Rock_Volcanic"
    },
    {
      "x": -3,
      "y": -4,
      "z": -8,
      "name": "Rock_Volcanic_Cracked_Lava"
    },
    {
      "x": -3,
      "y": -3,
      "z": -8,
      "name": "Rock_Volcanic"
    },
    {
      "x": -3,
      "y": -2,
      "z": -8,
      "name": "Rock_Volcanic"
    },
    {
      "x": -3,
      "y": -1,
      "z": -8,
      "name": "Rock_Volcanic_Cracked_Lava"
    },
    {
      "x": -3,
      "y": 0,
      "z": -8,
      "name": "Rock_Volcanic_Cracked_Lava"
    },
    {
      "x": -3,
      "y": -8,
      "z": -7,
      "name": "Rock_Volcanic"
    },
    {
      "x": -3,
      "y": -7,
      "z": -7,
      "name": "Rock_Volcanic"
    },
    {
      "x": -3,
      "y": -6,
      "z": -7,
      "name": "Rock_Volcanic"
    },
    {
      "x": -3,
      "y": -5,
      "z": -7,
      "name": "Rock_Volcanic"
    },
    {
      "x": -3,
      "y": -4,
      "z": -7,
      "name": "Rock_Volcanic"
    },
    {
      "x": -3,
      "y": -3,
      "z": -7,
      "name": "Rock_Volcanic"
    },
    {
      "x": -3,
      "y": -2,
      "z": -7,
      "name": "Rock_Volcanic"
    },
    {
      "x": -3,
      "y": -1,
      "z": -7,
      "name": "Rock_Volcanic"
    },
    {
      "x": -3,
      "y": 0,
      "z": -7,
      "name": "Rock_Volcanic"
    },
    {
      "x": -3,
      "y": 1,
      "z": -7,
      "name": "Rock_Volcanic"
    },
    {
      "x": -3,
      "y": -7,
      "z": -6,
      "name": "Rock_Volcanic"
    },
    {
      "x": -3,
      "y": -6,
      "z": -6,
      "name": "Rock_Volcanic"
    },
    {
      "x": -3,
      "y": -5,
      "z": -6,
      "name": "Rock_Volcanic"
    },
    {
      "x": -3,
      "y": -4,
      "z": -6,
      "name": "Rock_Volcanic"
    },
    {
      "x": -3,
      "y": -3,
      "z": -6,
      "name": "Rock_Volcanic"
    },
    {
      "x": -3,
      "y": -2,
      "z": -6,
      "name": "Rock_Volcanic"
    },
    {
      "x": -3,
      "y": -1,
      "z": -6,
      "name": "Rock_Volcanic"
    },
    {
      "x": -3,
      "y": 0,
      "z": -6,
      "name": "Rock_Volcanic"
    },
    {
      "x": -3,
      "y": 1,
      "z": -6,
      "name": "Rock_Volcanic"
    },
    {
      "x": -3,
      "y": -7,
      "z": -5,
      "name": "Rock_Volcanic"
    },
    {
      "x": -3,
      "y": -6,
      "z": -5,
      "name": "Rock_Volcanic"
    },
    {
      "x": -3,
      "y": -5,
      "z": -5,
      "name": "Rock_Volcanic"
    },
    {
      "x": -3,
      "y": -4,
      "z": -5,
      "name": "Rock_Volcanic"
    },
    {
      "x": -3,
      "y": -3,
      "z": -5,
      "name": "Rock_Volcanic"
    },
    {
      "x": -3,
      "y": -2,
      "z": -5,
      "name": "Rock_Volcanic"
    },
    {
      "x": -3,
      "y": -1,
      "z": -5,
      "name": "Rock_Volcanic"
    },
    {
      "x": -3,
      "y": 0,
      "z": -5,
      "name": "Rock_Volcanic"
    },
    {
      "x": -3,
      "y": 1,
      "z": -5,
      "name": "Rock_Volcanic"
    },
    {
      "x": -3,
      "y": -6,
      "z": -4,
      "name": "Rock_Volcanic"
    },
    {
      "x": -3,
      "y": -5,
      "z": -4,
      "name": "Rock_Volcanic_Cracked_Lava"
    },
    {
      "x": -3,
      "y": -4,
      "z": -4,
      "name": "Rock_Volcanic"
    },
    {
      "x": -3,
      "y": -3,
      "z": -4,
      "name": "Rock_Volcanic"
    },
    {
      "x": -3,
      "y": -2,
      "z": -4,
      "name": "Rock_Volcanic"
    },
    {
      "x": -3,
      "y": -1,
      "z": -4,
      "name": "Rock_Volcanic"
    },
    {
      "x": -3,
      "y": 0,
      "z": -4,
      "name": "Rock_Volcanic"
    },
    {
      "x": -3,
      "y": 1,
      "z": -4,
      "name": "Rock_Volcanic"
    },
    {
      "x": -3,
      "y": -5,
      "z": -3,
      "name": "Rock_Volcanic"
    },
    {
      "x": -3,
      "y": -4,
      "z": -3,
      "name": "Rock_Volcanic"
    },
    {
      "x": -3,
      "y": -3,
      "z": -3,
      "name": "Rock_Volcanic"
    },
    {
      "x": -3,
      "y": -2,
      "z": -3,
      "name": "Rock_Volcanic_Cracked_Lava"
    },
    {
      "x": -3,
      "y": -1,
      "z": -3,
      "name": "Rock_Volcanic"
    },
    {
      "x": -3,
      "y": 0,
      "z": -3,
      "name": "Rock_Volcanic"
    },
    {
      "x": -3,
      "y": 1,
      "z": -3,
      "name": "Rock_Volcanic"
    },
    {
      "x": -3,
      "y": 2,
      "z": -3,
      "name": "Rock_Volcanic"
    },
    {
      "x": -3,
      "y": 3,
      "z": -3,
      "name": "Rock_Volcanic"
    },
    {
      "x": -3,
      "y": 4,
      "z": -3,
      "name": "Rock_Volcanic"
    },
    {
      "x": -3,
      "y": -5,
      "z": -2,
      "name": "Rock_Volcanic"
    },
    {
      "x": -3,
      "y": -4,
      "z": -2,
      "name": "Rock_Volcanic"
    },
    {
      "x": -3,
      "y": -3,
      "z": -2,
      "name": "Rock_Volcanic"
    },
    {
      "x": -3,
      "y": -2,
      "z": -2,
      "name": "Rock_Volcanic"
    },
    {
      "x": -3,
      "y": -1,
      "z": -2,
      "name": "Rock_Volcanic"
    },
    {
      "x": -3,
      "y": 0,
      "z": -2,
      "name": "Rock_Volcanic"
    },
    {
      "x": -3,
      "y": 1,
      "z": -2,
      "name": "Rock_Volcanic_Cracked_Lava"
    },
    {
      "x": -3,
      "y": 2,
      "z": -2,
      "name": "Rock_Volcanic"
    },
    {
      "x": -3,
      "y": 3,
      "z": -2,
      "name": "Rock_Volcanic"
    },
    {
      "x": -3,
      "y": 4,
      "z": -2,
      "name": "Rock_Volcanic_Cracked_Lava"
    },
    {
      "x": -3,
      "y": 5,
      "z": -2,
      "name": "Rock_Volcanic"
    },
    {
      "x": -3,
      "y": -5,
      "z": -1,
      "name": "Rock_Volcanic_Cracked_Lava"
    },
    {
      "x": -3,
      "y": -4,
      "z": -1,
      "name": "Rock_Volcanic"
    },
    {
      "x": -3,
      "y": -3,
      "z": -1,
      "name": "Rock_Volcanic_Cracked_Lava"
    },
    {
      "x": -3,
      "y": -2,
      "z": -1,
      "name": "Rock_Volcanic"
    },
    {
      "x": -3,
      "y": -1,
      "z": -1,
      "name": "Rock_Volcanic"
    },
    {
      "x": -3,
      "y": 0,
      "z": -1,
      "name": "Rock_Volcanic"
    },
    {
      "x": -3,
      "y": 1,
      "z": -1,
      "name": "Rock_Volcanic"
    },
    {
      "x": -3,
      "y": 2,
      "z": -1,
      "name": "Rock_Volcanic"
    },
    {
      "x": -3,
      "y": 3,
      "z": -1,
      "name": "Rock_Volcanic_Cracked_Lava"
    },
    {
      "x": -3,
      "y": 4,
      "z": -1,
      "name": "Rock_Volcanic"
    },
    {
      "x": -3,
      "y": 5,
      "z": -1,
      "name": "Rock_Volcanic_Cracked_Lava"
    },
    {
      "x": -3,
      "y": -5,
      "z": 0,
      "name": "Rock_Volcanic"
    },
    {
      "x": -3,
      "y": -4,
      "z": 0,
      "name": "Rock_Volcanic"
    },
    {
      "x": -3,
      "y": -3,
      "z": 0,
      "name": "Rock_Volcanic"
    },
    {
      "x": -3,
      "y": -2,
      "z": 0,
      "name": "Rock_Volcanic_Cracked_Lava"
    },
    {
      "x": -3,
      "y": -1,
      "z": 0,
      "name": "Rock_Volcanic"
    },
    {
      "x": -3,
      "y": 0,
      "z": 0,
      "name": "Rock_Volcanic"
    },
    {
      "x": -3,
      "y": 1,
      "z": 0,
      "name": "Rock_Volcanic"
    },
    {
      "x": -3,
      "y": 2,
      "z": 0,
      "name": "Rock_Volcanic"
    },
    {
      "x": -3,
      "y": 3,
      "z": 0,
      "name": "Rock_Volcanic"
    },
    {
      "x": -3,
      "y": 4,
      "z": 0,
      "name": "Rock_Volcanic"
    },
    {
      "x": -3,
      "y": 5,
      "z": 0,
      "name": "Rock_Volcanic"
    },
    {
      "x": -3,
      "y": -5,
      "z": 1,
      "name": "Rock_Volcanic"
    },
    {
      "x": -3,
      "y": -4,
      "z": 1,
      "name": "Rock_Volcanic"
    },
    {
      "x": -3,
      "y": -3,
      "z": 1,
      "name": "Rock_Volcanic_Cracked_Lava"
    },
    {
      "x": -3,
      "y": -2,
      "z": 1,
      "name": "Rock_Volcanic"
    },
    {
      "x": -3,
      "y": -1,
      "z": 1,
      "name": "Rock_Volcanic"
    },
    {
      "x": -3,
      "y": 0,
      "z": 1,
      "name": "Rock_Volcanic_Cracked_Lava"
    },
    {
      "x": -3,
      "y": 1,
      "z": 1,
      "name": "Rock_Volcanic"
    },
    {
      "x": -3,
      "y": 2,
      "z": 1,
      "name": "Rock_Volcanic_Cracked_Lava"
    },
    {
      "x": -3,
      "y": 3,
      "z": 1,
      "name": "Rock_Volcanic"
    },
    {
      "x": -3,
      "y": 4,
      "z": 1,
      "name": "Rock_Volcanic"
    },
    {
      "x": -3,
      "y": 5,
      "z": 1,
      "name": "Rock_Volcanic"
    },
    {
      "x": -3,
      "y": 6,
      "z": 1,
      "name": "Rock_Volcanic"
    },
    {
      "x": -3,
      "y": -5,
      "z": 2,
      "name": "Rock_Volcanic"
    },
    {
      "x": -3,
      "y": -4,
      "z": 2,
      "name": "Rock_Volcanic"
    },
    {
      "x": -3,
      "y": -3,
      "z": 2,
      "name": "Rock_Volcanic"
    },
    {
      "x": -3,
      "y": -2,
      "z": 2,
      "name": "Rock_Volcanic"
    },
    {
      "x": -3,
      "y": -1,
      "z": 2,
      "name": "Rock_Volcanic"
    },
    {
      "x": -3,
      "y": 0,
      "z": 2,
      "name": "Rock_Volcanic_Cracked_Lava"
    },
    {
      "x": -3,
      "y": 1,
      "z": 2,
      "name": "Rock_Volcanic_Cracked_Lava"
    },
    {
      "x": -3,
      "y": 2,
      "z": 2,
      "name": "Rock_Volcanic"
    },
    {
      "x": -3,
      "y": 3,
      "z": 2,
      "name": "Rock_Volcanic"
    },
    {
      "x": -3,
      "y": 4,
      "z": 2,
      "name": "Rock_Volcanic"
    },
    {
      "x": -3,
      "y": 5,
      "z": 2,
      "name": "Rock_Volcanic"
    },
    {
      "x": -3,
      "y": -4,
      "z": 3,
      "name": "Rock_Volcanic"
    },
    {
      "x": -3,
      "y": -3,
      "z": 3,
      "name": "Rock_Volcanic"
    },
    {
      "x": -3,
      "y": -2,
      "z": 3,
      "name": "Rock_Volcanic"
    },
    {
      "x": -3,
      "y": -1,
      "z": 3,
      "name": "Rock_Volcanic"
    },
    {
      "x": -3,
      "y": 0,
      "z": 3,
      "name": "Rock_Volcanic_Cracked_Lava"
    },
    {
      "x": -3,
      "y": 1,
      "z": 3,
      "name": "Rock_Volcanic"
    },
    {
      "x": -3,
      "y": 2,
      "z": 3,
      "name": "Rock_Volcanic_Cracked_Lava"
    },
    {
      "x": -3,
      "y": 3,
      "z": 3,
      "name": "Rock_Volcanic"
    },
    {
      "x": -3,
      "y": 4,
      "z": 3,
      "name": "Rock_Volcanic"
    },
    {
      "x": -3,
      "y": 5,
      "z": 3,
      "name": "Rock_Volcanic_Cracked_Lava"
    },
    {
      "x": -3,
      "y": 6,
      "z": 3,
      "name": "Rock_Volcanic"
    },
    {
      "x": -3,
      "y": -2,
      "z": 4,
      "name": "Rock_Volcanic"
    },
    {
      "x": -3,
      "y": -1,
      "z": 4,
      "name": "Rock_Volcanic"
    },
    {
      "x": -3,
      "y": 0,
      "z": 4,
      "name": "Rock_Volcanic"
    },
    {
      "x": -3,
      "y": 1,
      "z": 4,
      "name": "Rock_Volcanic"
    },
    {
      "x": -3,
      "y": 2,
      "z": 4,
      "name": "Rock_Volcanic"
    },
    {
      "x": -3,
      "y": 3,
      "z": 4,
      "name": "Rock_Volcanic_Cracked_Lava"
    },
    {
      "x": -3,
      "y": 4,
      "z": 4,
      "name": "Rock_Volcanic"
    },
    {
      "x": -3,
      "y": 5,
      "z": 4,
      "name": "Rock_Volcanic"
    },
    {
      "x": -3,
      "y": 6,
      "z": 4,
      "name": "Rock_Volcanic"
    },
    {
      "x": -3,
      "y": 7,
      "z": 4,
      "name": "Rock_Volcanic"
    },
    {
      "x": -3,
      "y": -2,
      "z": 5,
      "name": "Rock_Volcanic_Cracked_Lava"
    },
    {
      "x": -3,
      "y": -1,
      "z": 5,
      "name": "Rock_Volcanic"
    },
    {
      "x": -3,
      "y": 0,
      "z": 5,
      "name": "Rock_Volcanic"
    },
    {
      "x": -3,
      "y": 1,
      "z": 5,
      "name": "Rock_Volcanic_Cracked_Lava"
    },
    {
      "x": -3,
      "y": 2,
      "z": 5,
      "name": "Rock_Volcanic"
    },
    {
      "x": -3,
      "y": 3,
      "z": 5,
      "name": "Rock_Volcanic"
    },
    {
      "x": -3,
      "y": 4,
      "z": 5,
      "name": "Rock_Volcanic"
    },
    {
      "x": -3,
      "y": 5,
      "z": 5,
      "name": "Rock_Volcanic"
    },
    {
      "x": -3,
      "y": 6,
      "z": 5,
      "name": "Rock_Volcanic"
    },
    {
      "x": -3,
      "y": 7,
      "z": 5,
      "name": "Rock_Volcanic_Cracked_Lava"
    },
    {
      "x": -3,
      "y": -1,
      "z": 6,
      "name": "Rock_Volcanic_Cracked_Lava"
    },
    {
      "x": -3,
      "y": 0,
      "z": 6,
      "name": "Rock_Volcanic_Cracked_Lava"
    },
    {
      "x": -3,
      "y": 1,
      "z": 6,
      "name": "Rock_Volcanic"
    },
    {
      "x": -3,
      "y": 2,
      "z": 6,
      "name": "Rock_Volcanic"
    },
    {
      "x": -3,
      "y": 3,
      "z": 6,
      "name": "Rock_Volcanic"
    },
    {
      "x": -3,
      "y": 4,
      "z": 6,
      "name": "Rock_Volcanic"
    },
    {
      "x": -3,
      "y": 5,
      "z": 6,
      "name": "Rock_Volcanic_Cracked_Lava"
    },
    {
      "x": -3,
      "y": 6,
      "z": 6,
      "name": "Rock_Volcanic"
    },
    {
      "x": -3,
      "y": 7,
      "z": 6,
      "name": "Rock_Volcanic"
    },
    {
      "x": -3,
      "y": 8,
      "z": 6,
      "name": "Rock_Volcanic"
    },
    {
      "x": -3,
      "y": -2,
      "z": 7,
      "name": "Rock_Volcanic"
    },
    {
      "x": -3,
      "y": -1,
      "z": 7,
      "name": "Rock_Volcanic"
    },
    {
      "x": -3,
      "y": 0,
      "z": 7,
      "name": "Rock_Volcanic"
    },
    {
      "x": -3,
      "y": 1,
      "z": 7,
      "name": "Rock_Volcanic"
    },
    {
      "x": -3,
      "y": 2,
      "z": 7,
      "name": "Rock_Volcanic_Cracked_Lava"
    },
    {
      "x": -3,
      "y": 3,
      "z": 7,
      "name": "Rock_Volcanic"
    },
    {
      "x": -3,
      "y": 4,
      "z": 7,
      "name": "Rock_Volcanic"
    },
    {
      "x": -3,
      "y": 5,
      "z": 7,
      "name": "Rock_Volcanic"
    },
    {
      "x": -3,
      "y": 6,
      "z": 7,
      "name": "Rock_Volcanic"
    },
    {
      "x": -3,
      "y": 7,
      "z": 7,
      "name": "Rock_Volcanic_Cracked_Lava"
    },
    {
      "x": -3,
      "y": 8,
      "z": 7,
      "name": "Rock_Volcanic_Cracked_Lava"
    },
    {
      "x": -3,
      "y": 9,
      "z": 7,
      "name": "Rock_Volcanic"
    },
    {
      "x": -3,
      "y": -1,
      "z": 8,
      "name": "Rock_Volcanic"
    },
    {
      "x": -3,
      "y": 0,
      "z": 8,
      "name": "Rock_Volcanic"
    },
    {
      "x": -3,
      "y": 1,
      "z": 8,
      "name": "Rock_Volcanic_Cracked_Lava"
    },
    {
      "x": -3,
      "y": 2,
      "z": 8,
      "name": "Rock_Volcanic_Cracked_Lava"
    },
    {
      "x": -3,
      "y": 3,
      "z": 8,
      "name": "Rock_Volcanic_Cracked_Lava"
    },
    {
      "x": -3,
      "y": 4,
      "z": 8,
      "name": "Rock_Volcanic_Cracked_Lava"
    },
    {
      "x": -3,
      "y": 5,
      "z": 8,
      "name": "Rock_Volcanic_Cracked_Lava"
    },
    {
      "x": -3,
      "y": 6,
      "z": 8,
      "name": "Rock_Volcanic"
    },
    {
      "x": -3,
      "y": 7,
      "z": 8,
      "name": "Rock_Volcanic"
    },
    {
      "x": -3,
      "y": 8,
      "z": 8,
      "name": "Rock_Volcanic"
    },
    {
      "x": -3,
      "y": 0,
      "z": 9,
      "name": "Rock_Volcanic"
    },
    {
      "x": -3,
      "y": 3,
      "z": 9,
      "name": "Rock_Volcanic"
    },
    {
      "x": -3,
      "y": 4,
      "z": 9,
      "name": "Rock_Volcanic"
    },
    {
      "x": -3,
      "y": 5,
      "z": 9,
      "name": "Rock_Volcanic"
    },
    {
      "x": -3,
      "y": 6,
      "z": 9,
      "name": "Rock_Volcanic"
    },
    {
      "x": -3,
      "y": 7,
      "z": 9,
      "name": "Rock_Volcanic"
    },
    {
      "x": -3,
      "y": 8,
      "z": 9,
      "name": "Rock_Volcanic"
    },
    {
      "x": -3,
      "y": 9,
      "z": 9,
      "name": "Rock_Volcanic"
    },
    {
      "x": -3,
      "y": 5,
      "z": 10,
      "name": "Rock_Volcanic"
    },
    {
      "x": -3,
      "y": 6,
      "z": 10,
      "name": "Rock_Volcanic"
    },
    {
      "x": -3,
      "y": 7,
      "z": 10,
      "name": "Rock_Volcanic"
    },
    {
      "x": -3,
      "y": 8,
      "z": 10,
      "name": "Rock_Volcanic_Cracked_Lava"
    },
    {
      "x": -3,
      "y": 9,
      "z": 10,
      "name": "Rock_Volcanic"
    },
    {
      "x": -3,
      "y": 10,
      "z": 10,
      "name": "Rock_Volcanic_Cracked_Lava"
    },
    {
      "x": -3,
      "y": 9,
      "z": 11,
      "name": "Rock_Volcanic"
    },
    {
      "x": -3,
      "y": 10,
      "z": 11,
      "name": "Rock_Volcanic"
    },
    {
      "x": -2,
      "y": -17,
      "z": -28,
      "name": "Rock_Volcanic"
    },
    {
      "x": -2,
      "y": -16,
      "z": -28,
      "name": "Rock_Volcanic"
    },
    {
      "x": -2,
      "y": -15,
      "z": -28,
      "name": "Rock_Volcanic"
    },
    {
      "x": -2,
      "y": -17,
      "z": -27,
      "name": "Rock_Volcanic_Cracked_Lava"
    },
    {
      "x": -2,
      "y": -16,
      "z": -27,
      "name": "Rock_Volcanic"
    },
    {
      "x": -2,
      "y": -15,
      "z": -27,
      "name": "Rock_Volcanic"
    },
    {
      "x": -2,
      "y": -14,
      "z": -27,
      "name": "Rock_Volcanic_Cracked_Lava"
    },
    {
      "x": -2,
      "y": -17,
      "z": -26,
      "name": "Rock_Volcanic_Cracked_Lava"
    },
    {
      "x": -2,
      "y": -16,
      "z": -26,
      "name": "Rock_Volcanic"
    },
    {
      "x": -2,
      "y": -15,
      "z": -26,
      "name": "Rock_Volcanic"
    },
    {
      "x": -2,
      "y": -14,
      "z": -26,
      "name": "Rock_Volcanic"
    },
    {
      "x": -2,
      "y": -13,
      "z": -26,
      "name": "Rock_Volcanic_Cracked_Lava"
    },
    {
      "x": -2,
      "y": -15,
      "z": -25,
      "name": "Rock_Volcanic_Cracked_Lava"
    },
    {
      "x": -2,
      "y": -14,
      "z": -25,
      "name": "Rock_Volcanic"
    },
    {
      "x": -2,
      "y": -13,
      "z": -25,
      "name": "Rock_Volcanic"
    },
    {
      "x": -2,
      "y": -12,
      "z": -25,
      "name": "Rock_Volcanic"
    },
    {
      "x": -2,
      "y": -15,
      "z": -24,
      "name": "Rock_Volcanic"
    },
    {
      "x": -2,
      "y": -14,
      "z": -24,
      "name": "Rock_Volcanic"
    },
    {
      "x": -2,
      "y": -13,
      "z": -24,
      "name": "Rock_Volcanic"
    },
    {
      "x": -2,
      "y": -12,
      "z": -24,
      "name": "Rock_Volcanic"
    },
    {
      "x": -2,
      "y": -11,
      "z": -24,
      "name": "Rock_Volcanic"
    },
    {
      "x": -2,
      "y": -15,
      "z": -23,
      "name": "Rock_Volcanic"
    },
    {
      "x": -2,
      "y": -14,
      "z": -23,
      "name": "Rock_Volcanic"
    },
    {
      "x": -2,
      "y": -13,
      "z": -23,
      "name": "Rock_Volcanic"
    },
    {
      "x": -2,
      "y": -12,
      "z": -23,
      "name": "Rock_Volcanic"
    },
    {
      "x": -2,
      "y": -11,
      "z": -23,
      "name": "Rock_Volcanic"
    },
    {
      "x": -2,
      "y": -10,
      "z": -23,
      "name": "Rock_Volcanic"
    },
    {
      "x": -2,
      "y": -15,
      "z": -22,
      "name": "Rock_Volcanic"
    },
    {
      "x": -2,
      "y": -14,
      "z": -22,
      "name": "Rock_Volcanic"
    },
    {
      "x": -2,
      "y": -13,
      "z": -22,
      "name": "Rock_Volcanic"
    },
    {
      "x": -2,
      "y": -12,
      "z": -22,
      "name": "Rock_Volcanic"
    },
    {
      "x": -2,
      "y": -11,
      "z": -22,
      "name": "Rock_Volcanic_Cracked_Lava"
    },
    {
      "x": -2,
      "y": -10,
      "z": -22,
      "name": "Rock_Volcanic"
    },
    {
      "x": -2,
      "y": -14,
      "z": -21,
      "name": "Rock_Volcanic"
    },
    {
      "x": -2,
      "y": -13,
      "z": -21,
      "name": "Rock_Volcanic"
    },
    {
      "x": -2,
      "y": -12,
      "z": -21,
      "name": "Rock_Volcanic"
    },
    {
      "x": -2,
      "y": -11,
      "z": -21,
      "name": "Rock_Volcanic"
    },
    {
      "x": -2,
      "y": -10,
      "z": -21,
      "name": "Rock_Volcanic_Cracked_Lava"
    },
    {
      "x": -2,
      "y": -13,
      "z": -20,
      "name": "Rock_Volcanic"
    },
    {
      "x": -2,
      "y": -12,
      "z": -20,
      "name": "Rock_Volcanic"
    },
    {
      "x": -2,
      "y": -11,
      "z": -20,
      "name": "Rock_Volcanic"
    },
    {
      "x": -2,
      "y": -10,
      "z": -20,
      "name": "Rock_Volcanic"
    },
    {
      "x": -2,
      "y": -9,
      "z": -20,
      "name": "Rock_Volcanic"
    },
    {
      "x": -2,
      "y": -8,
      "z": -20,
      "name": "Rock_Volcanic_Cracked_Lava"
    },
    {
      "x": -2,
      "y": -12,
      "z": -19,
      "name": "Rock_Volcanic"
    },
    {
      "x": -2,
      "y": -11,
      "z": -19,
      "name": "Rock_Volcanic_Cracked_Lava"
    },
    {
      "x": -2,
      "y": -10,
      "z": -19,
      "name": "Rock_Volcanic"
    },
    {
      "x": -2,
      "y": -9,
      "z": -19,
      "name": "Rock_Volcanic"
    },
    {
      "x": -2,
      "y": -8,
      "z": -19,
      "name": "Rock_Volcanic"
    },
    {
      "x": -2,
      "y": -12,
      "z": -18,
      "name": "Rock_Volcanic_Cracked_Lava"
    },
    {
      "x": -2,
      "y": -11,
      "z": -18,
      "name": "Rock_Volcanic"
    },
    {
      "x": -2,
      "y": -10,
      "z": -18,
      "name": "Rock_Volcanic"
    },
    {
      "x": -2,
      "y": -9,
      "z": -18,
      "name": "Rock_Volcanic"
    },
    {
      "x": -2,
      "y": -8,
      "z": -18,
      "name": "Rock_Volcanic"
    },
    {
      "x": -2,
      "y": -7,
      "z": -18,
      "name": "Rock_Volcanic"
    },
    {
      "x": -2,
      "y": -13,
      "z": -17,
      "name": "Rock_Volcanic"
    },
    {
      "x": -2,
      "y": -12,
      "z": -17,
      "name": "Rock_Volcanic"
    },
    {
      "x": -2,
      "y": -11,
      "z": -17,
      "name": "Rock_Volcanic"
    },
    {
      "x": -2,
      "y": -10,
      "z": -17,
      "name": "Rock_Volcanic"
    },
    {
      "x": -2,
      "y": -9,
      "z": -17,
      "name": "Rock_Volcanic"
    },
    {
      "x": -2,
      "y": -8,
      "z": -17,
      "name": "Rock_Volcanic"
    },
    {
      "x": -2,
      "y": -7,
      "z": -17,
      "name": "Rock_Volcanic"
    },
    {
      "x": -2,
      "y": -6,
      "z": -17,
      "name": "Rock_Volcanic"
    },
    {
      "x": -2,
      "y": -13,
      "z": -16,
      "name": "Rock_Volcanic_Cracked_Lava"
    },
    {
      "x": -2,
      "y": -12,
      "z": -16,
      "name": "Rock_Volcanic"
    },
    {
      "x": -2,
      "y": -11,
      "z": -16,
      "name": "Rock_Volcanic"
    },
    {
      "x": -2,
      "y": -10,
      "z": -16,
      "name": "Rock_Volcanic"
    },
    {
      "x": -2,
      "y": -9,
      "z": -16,
      "name": "Rock_Volcanic"
    },
    {
      "x": -2,
      "y": -8,
      "z": -16,
      "name": "Rock_Volcanic"
    },
    {
      "x": -2,
      "y": -7,
      "z": -16,
      "name": "Rock_Volcanic"
    },
    {
      "x": -2,
      "y": -6,
      "z": -16,
      "name": "Rock_Volcanic_Cracked_Lava"
    },
    {
      "x": -2,
      "y": -12,
      "z": -15,
      "name": "Rock_Volcanic"
    },
    {
      "x": -2,
      "y": -11,
      "z": -15,
      "name": "Rock_Volcanic_Cracked_Lava"
    },
    {
      "x": -2,
      "y": -10,
      "z": -15,
      "name": "Rock_Volcanic"
    },
    {
      "x": -2,
      "y": -9,
      "z": -15,
      "name": "Rock_Volcanic"
    },
    {
      "x": -2,
      "y": -8,
      "z": -15,
      "name": "Rock_Volcanic_Cracked_Lava"
    },
    {
      "x": -2,
      "y": -7,
      "z": -15,
      "name": "Rock_Volcanic"
    },
    {
      "x": -2,
      "y": -6,
      "z": -15,
      "name": "Rock_Volcanic"
    },
    {
      "x": -2,
      "y": -5,
      "z": -15,
      "name": "Rock_Volcanic"
    },
    {
      "x": -2,
      "y": -10,
      "z": -14,
      "name": "Rock_Volcanic_Cracked_Lava"
    },
    {
      "x": -2,
      "y": -9,
      "z": -14,
      "name": "Rock_Volcanic"
    },
    {
      "x": -2,
      "y": -8,
      "z": -14,
      "name": "Rock_Volcanic"
    },
    {
      "x": -2,
      "y": -7,
      "z": -14,
      "name": "Rock_Volcanic"
    },
    {
      "x": -2,
      "y": -6,
      "z": -14,
      "name": "Rock_Volcanic_Cracked_Lava"
    },
    {
      "x": -2,
      "y": -5,
      "z": -14,
      "name": "Rock_Volcanic"
    },
    {
      "x": -2,
      "y": -10,
      "z": -13,
      "name": "Rock_Volcanic"
    },
    {
      "x": -2,
      "y": -9,
      "z": -13,
      "name": "Rock_Volcanic_Cracked_Lava"
    },
    {
      "x": -2,
      "y": -8,
      "z": -13,
      "name": "Rock_Volcanic"
    },
    {
      "x": -2,
      "y": -7,
      "z": -13,
      "name": "Rock_Volcanic"
    },
    {
      "x": -2,
      "y": -6,
      "z": -13,
      "name": "Rock_Volcanic"
    },
    {
      "x": -2,
      "y": -5,
      "z": -13,
      "name": "Rock_Volcanic"
    },
    {
      "x": -2,
      "y": -4,
      "z": -13,
      "name": "Rock_Volcanic"
    },
    {
      "x": -2,
      "y": -9,
      "z": -12,
      "name": "Rock_Volcanic"
    },
    {
      "x": -2,
      "y": -8,
      "z": -12,
      "name": "Rock_Volcanic"
    },
    {
      "x": -2,
      "y": -7,
      "z": -12,
      "name": "Rock_Volcanic"
    },
    {
      "x": -2,
      "y": -6,
      "z": -12,
      "name": "Rock_Volcanic"
    },
    {
      "x": -2,
      "y": -5,
      "z": -12,
      "name": "Rock_Volcanic"
    },
    {
      "x": -2,
      "y": -4,
      "z": -12,
      "name": "Rock_Volcanic"
    },
    {
      "x": -2,
      "y": -3,
      "z": -12,
      "name": "Rock_Volcanic"
    },
    {
      "x": -2,
      "y": -9,
      "z": -11,
      "name": "Rock_Volcanic"
    },
    {
      "x": -2,
      "y": -8,
      "z": -11,
      "name": "Rock_Volcanic"
    },
    {
      "x": -2,
      "y": -7,
      "z": -11,
      "name": "Rock_Volcanic_Cracked_Lava"
    },
    {
      "x": -2,
      "y": -6,
      "z": -11,
      "name": "Rock_Volcanic"
    },
    {
      "x": -2,
      "y": -5,
      "z": -11,
      "name": "Rock_Volcanic_Cracked_Lava"
    },
    {
      "x": -2,
      "y": -4,
      "z": -11,
      "name": "Rock_Volcanic"
    },
    {
      "x": -2,
      "y": -3,
      "z": -11,
      "name": "Rock_Volcanic"
    },
    {
      "x": -2,
      "y": -2,
      "z": -11,
      "name": "Rock_Volcanic"
    },
    {
      "x": -2,
      "y": -9,
      "z": -10,
      "name": "Rock_Volcanic"
    },
    {
      "x": -2,
      "y": -8,
      "z": -10,
      "name": "Rock_Volcanic"
    },
    {
      "x": -2,
      "y": -7,
      "z": -10,
      "name": "Rock_Volcanic"
    },
    {
      "x": -2,
      "y": -6,
      "z": -10,
      "name": "Rock_Volcanic"
    },
    {
      "x": -2,
      "y": -5,
      "z": -10,
      "name": "Rock_Volcanic"
    },
    {
      "x": -2,
      "y": -4,
      "z": -10,
      "name": "Rock_Volcanic"
    },
    {
      "x": -2,
      "y": -3,
      "z": -10,
      "name": "Rock_Volcanic_Cracked_Lava"
    },
    {
      "x": -2,
      "y": -2,
      "z": -10,
      "name": "Rock_Volcanic"
    },
    {
      "x": -2,
      "y": -8,
      "z": -9,
      "name": "Rock_Volcanic"
    },
    {
      "x": -2,
      "y": -7,
      "z": -9,
      "name": "Rock_Volcanic"
    },
    {
      "x": -2,
      "y": -6,
      "z": -9,
      "name": "Rock_Volcanic"
    },
    {
      "x": -2,
      "y": -5,
      "z": -9,
      "name": "Rock_Volcanic"
    },
    {
      "x": -2,
      "y": -4,
      "z": -9,
      "name": "Rock_Volcanic_Cracked_Lava"
    },
    {
      "x": -2,
      "y": -3,
      "z": -9,
      "name": "Rock_Volcanic"
    },
    {
      "x": -2,
      "y": -2,
      "z": -9,
      "name": "Rock_Volcanic"
    },
    {
      "x": -2,
      "y": -1,
      "z": -9,
      "name": "Rock_Volcanic"
    },
    {
      "x": -2,
      "y": 0,
      "z": -9,
      "name": "Rock_Volcanic_Cracked_Lava"
    },
    {
      "x": -2,
      "y": -9,
      "z": -8,
      "name": "Rock_Volcanic"
    },
    {
      "x": -2,
      "y": -8,
      "z": -8,
      "name": "Rock_Volcanic"
    },
    {
      "x": -2,
      "y": -7,
      "z": -8,
      "name": "Rock_Volcanic"
    },
    {
      "x": -2,
      "y": -6,
      "z": -8,
      "name": "Rock_Volcanic"
    },
    {
      "x": -2,
      "y": -5,
      "z": -8,
      "name": "Rock_Volcanic"
    },
    {
      "x": -2,
      "y": -4,
      "z": -8,
      "name": "Rock_Volcanic"
    },
    {
      "x": -2,
      "y": -3,
      "z": -8,
      "name": "Rock_Volcanic"
    },
    {
      "x": -2,
      "y": -2,
      "z": -8,
      "name": "Rock_Volcanic_Cracked_Lava"
    },
    {
      "x": -2,
      "y": -1,
      "z": -8,
      "name": "Rock_Volcanic"
    },
    {
      "x": -2,
      "y": 0,
      "z": -8,
      "name": "Rock_Volcanic"
    },
    {
      "x": -2,
      "y": -8,
      "z": -7,
      "name": "Rock_Volcanic"
    },
    {
      "x": -2,
      "y": -7,
      "z": -7,
      "name": "Rock_Volcanic"
    },
    {
      "x": -2,
      "y": -6,
      "z": -7,
      "name": "Rock_Volcanic_Cracked_Lava"
    },
    {
      "x": -2,
      "y": -5,
      "z": -7,
      "name": "Rock_Volcanic"
    },
    {
      "x": -2,
      "y": -4,
      "z": -7,
      "name": "Rock_Volcanic"
    },
    {
      "x": -2,
      "y": -3,
      "z": -7,
      "name": "Rock_Volcanic_Cracked_Lava"
    },
    {
      "x": -2,
      "y": -2,
      "z": -7,
      "name": "Rock_Volcanic_Cracked_Lava"
    },
    {
      "x": -2,
      "y": -1,
      "z": -7,
      "name": "Rock_Volcanic"
    },
    {
      "x": -2,
      "y": 0,
      "z": -7,
      "name": "Rock_Volcanic"
    },
    {
      "x": -2,
      "y": 1,
      "z": -7,
      "name": "Rock_Volcanic"
    },
    {
      "x": -2,
      "y": -7,
      "z": -6,
      "name": "Rock_Volcanic"
    },
    {
      "x": -2,
      "y": -6,
      "z": -6,
      "name": "Rock_Volcanic"
    },
    {
      "x": -2,
      "y": -5,
      "z": -6,
      "name": "Rock_Volcanic"
    },
    {
      "x": -2,
      "y": -4,
      "z": -6,
      "name": "Rock_Volcanic"
    },
    {
      "x": -2,
      "y": -3,
      "z": -6,
      "name": "Rock_Volcanic"
    },
    {
      "x": -2,
      "y": -2,
      "z": -6,
      "name": "Rock_Volcanic"
    },
    {
      "x": -2,
      "y": -1,
      "z": -6,
      "name": "Rock_Volcanic"
    },
    {
      "x": -2,
      "y": 0,
      "z": -6,
      "name": "Rock_Volcanic"
    },
    {
      "x": -2,
      "y": 1,
      "z": -6,
      "name": "Rock_Volcanic"
    },
    {
      "x": -2,
      "y": -7,
      "z": -5,
      "name": "Rock_Volcanic"
    },
    {
      "x": -2,
      "y": -6,
      "z": -5,
      "name": "Rock_Volcanic"
    },
    {
      "x": -2,
      "y": -5,
      "z": -5,
      "name": "Rock_Volcanic"
    },
    {
      "x": -2,
      "y": -4,
      "z": -5,
      "name": "Rock_Volcanic"
    },
    {
      "x": -2,
      "y": -3,
      "z": -5,
      "name": "Rock_Volcanic"
    },
    {
      "x": -2,
      "y": -2,
      "z": -5,
      "name": "Rock_Volcanic"
    },
    {
      "x": -2,
      "y": -1,
      "z": -5,
      "name": "Rock_Volcanic_Cracked_Lava"
    },
    {
      "x": -2,
      "y": 0,
      "z": -5,
      "name": "Rock_Volcanic"
    },
    {
      "x": -2,
      "y": 1,
      "z": -5,
      "name": "Rock_Volcanic"
    },
    {
      "x": -2,
      "y": -6,
      "z": -4,
      "name": "Rock_Volcanic"
    },
    {
      "x": -2,
      "y": -5,
      "z": -4,
      "name": "Rock_Volcanic_Cracked_Lava"
    },
    {
      "x": -2,
      "y": -4,
      "z": -4,
      "name": "Rock_Volcanic"
    },
    {
      "x": -2,
      "y": -3,
      "z": -4,
      "name": "Rock_Volcanic"
    },
    {
      "x": -2,
      "y": -2,
      "z": -4,
      "name": "Rock_Volcanic"
    },
    {
      "x": -2,
      "y": -1,
      "z": -4,
      "name": "Rock_Volcanic_Cracked_Lava"
    },
    {
      "x": -2,
      "y": 0,
      "z": -4,
      "name": "Rock_Volcanic"
    },
    {
      "x": -2,
      "y": 1,
      "z": -4,
      "name": "Rock_Volcanic"
    },
    {
      "x": -2,
      "y": 3,
      "z": -4,
      "name": "Rock_Volcanic"
    },
    {
      "x": -2,
      "y": -5,
      "z": -3,
      "name": "Rock_Volcanic"
    },
    {
      "x": -2,
      "y": -4,
      "z": -3,
      "name": "Rock_Volcanic"
    },
    {
      "x": -2,
      "y": -3,
      "z": -3,
      "name": "Rock_Volcanic"
    },
    {
      "x": -2,
      "y": -2,
      "z": -3,
      "name": "Rock_Volcanic_Cracked_Lava"
    },
    {
      "x": -2,
      "y": -1,
      "z": -3,
      "name": "Rock_Volcanic"
    },
    {
      "x": -2,
      "y": 0,
      "z": -3,
      "name": "Rock_Volcanic"
    },
    {
      "x": -2,
      "y": 1,
      "z": -3,
      "name": "Rock_Volcanic"
    },
    {
      "x": -2,
      "y": 2,
      "z": -3,
      "name": "Rock_Volcanic"
    },
    {
      "x": -2,
      "y": 3,
      "z": -3,
      "name": "Rock_Volcanic"
    },
    {
      "x": -2,
      "y": 4,
      "z": -3,
      "name": "Rock_Volcanic"
    },
    {
      "x": -2,
      "y": -5,
      "z": -2,
      "name": "Rock_Volcanic"
    },
    {
      "x": -2,
      "y": -4,
      "z": -2,
      "name": "Rock_Volcanic"
    },
    {
      "x": -2,
      "y": -3,
      "z": -2,
      "name": "Rock_Volcanic"
    },
    {
      "x": -2,
      "y": -2,
      "z": -2,
      "name": "Rock_Volcanic"
    },
    {
      "x": -2,
      "y": -1,
      "z": -2,
      "name": "Rock_Volcanic"
    },
    {
      "x": -2,
      "y": 0,
      "z": -2,
      "name": "Rock_Volcanic"
    },
    {
      "x": -2,
      "y": 1,
      "z": -2,
      "name": "Rock_Volcanic_Cracked_Lava"
    },
    {
      "x": -2,
      "y": 2,
      "z": -2,
      "name": "Rock_Volcanic_Cracked_Lava"
    },
    {
      "x": -2,
      "y": 3,
      "z": -2,
      "name": "Rock_Volcanic"
    },
    {
      "x": -2,
      "y": 4,
      "z": -2,
      "name": "Rock_Volcanic_Cracked_Lava"
    },
    {
      "x": -2,
      "y": 5,
      "z": -2,
      "name": "Rock_Volcanic_Cracked_Lava"
    },
    {
      "x": -2,
      "y": -5,
      "z": -1,
      "name": "Rock_Volcanic"
    },
    {
      "x": -2,
      "y": -4,
      "z": -1,
      "name": "Rock_Volcanic_Cracked_Lava"
    },
    {
      "x": -2,
      "y": -3,
      "z": -1,
      "name": "Rock_Volcanic"
    },
    {
      "x": -2,
      "y": -2,
      "z": -1,
      "name": "Rock_Volcanic"
    },
    {
      "x": -2,
      "y": -1,
      "z": -1,
      "name": "Rock_Volcanic"
    },
    {
      "x": -2,
      "y": 0,
      "z": -1,
      "name": "Rock_Volcanic"
    },
    {
      "x": -2,
      "y": 1,
      "z": -1,
      "name": "Rock_Volcanic"
    },
    {
      "x": -2,
      "y": 2,
      "z": -1,
      "name": "Rock_Volcanic"
    },
    {
      "x": -2,
      "y": 3,
      "z": -1,
      "name": "Rock_Volcanic"
    },
    {
      "x": -2,
      "y": 4,
      "z": -1,
      "name": "Rock_Volcanic"
    },
    {
      "x": -2,
      "y": 5,
      "z": -1,
      "name": "Rock_Volcanic"
    },
    {
      "x": -2,
      "y": -4,
      "z": 0,
      "name": "Rock_Volcanic_Cracked_Lava"
    },
    {
      "x": -2,
      "y": -3,
      "z": 0,
      "name": "Rock_Volcanic_Cracked_Lava"
    },
    {
      "x": -2,
      "y": -2,
      "z": 0,
      "name": "Rock_Volcanic"
    },
    {
      "x": -2,
      "y": -1,
      "z": 0,
      "name": "Rock_Volcanic"
    },
    {
      "x": -2,
      "y": 0,
      "z": 0,
      "name": "Rock_Volcanic_Cracked_Lava"
    },
    {
      "x": -2,
      "y": 1,
      "z": 0,
      "name": "Rock_Volcanic"
    },
    {
      "x": -2,
      "y": 2,
      "z": 0,
      "name": "Rock_Volcanic"
    },
    {
      "x": -2,
      "y": 3,
      "z": 0,
      "name": "Rock_Volcanic"
    },
    {
      "x": -2,
      "y": 4,
      "z": 0,
      "name": "Rock_Volcanic"
    },
    {
      "x": -2,
      "y": 5,
      "z": 0,
      "name": "Rock_Volcanic"
    },
    {
      "x": -2,
      "y": -5,
      "z": 1,
      "name": "Rock_Volcanic_Cracked_Lava"
    },
    {
      "x": -2,
      "y": -4,
      "z": 1,
      "name": "Rock_Volcanic"
    },
    {
      "x": -2,
      "y": -3,
      "z": 1,
      "name": "Rock_Volcanic"
    },
    {
      "x": -2,
      "y": -2,
      "z": 1,
      "name": "Rock_Volcanic"
    },
    {
      "x": -2,
      "y": -1,
      "z": 1,
      "name": "Rock_Volcanic"
    },
    {
      "x": -2,
      "y": 0,
      "z": 1,
      "name": "Rock_Volcanic_Cracked_Lava"
    },
    {
      "x": -2,
      "y": 1,
      "z": 1,
      "name": "Rock_Volcanic"
    },
    {
      "x": -2,
      "y": 2,
      "z": 1,
      "name": "Rock_Volcanic"
    },
    {
      "x": -2,
      "y": 3,
      "z": 1,
      "name": "Rock_Volcanic"
    },
    {
      "x": -2,
      "y": 4,
      "z": 1,
      "name": "Rock_Volcanic"
    },
    {
      "x": -2,
      "y": 5,
      "z": 1,
      "name": "Rock_Volcanic"
    },
    {
      "x": -2,
      "y": 6,
      "z": 1,
      "name": "Rock_Volcanic"
    },
    {
      "x": -2,
      "y": -5,
      "z": 2,
      "name": "Rock_Volcanic"
    },
    {
      "x": -2,
      "y": -4,
      "z": 2,
      "name": "Rock_Volcanic"
    },
    {
      "x": -2,
      "y": -3,
      "z": 2,
      "name": "Rock_Volcanic"
    },
    {
      "x": -2,
      "y": -2,
      "z": 2,
      "name": "Rock_Volcanic"
    },
    {
      "x": -2,
      "y": -1,
      "z": 2,
      "name": "Rock_Volcanic_Cracked_Lava"
    },
    {
      "x": -2,
      "y": 0,
      "z": 2,
      "name": "Rock_Volcanic"
    },
    {
      "x": -2,
      "y": 1,
      "z": 2,
      "name": "Rock_Volcanic"
    },
    {
      "x": -2,
      "y": 2,
      "z": 2,
      "name": "Rock_Volcanic"
    },
    {
      "x": -2,
      "y": 3,
      "z": 2,
      "name": "Rock_Volcanic"
    },
    {
      "x": -2,
      "y": 4,
      "z": 2,
      "name": "Rock_Volcanic"
    },
    {
      "x": -2,
      "y": 5,
      "z": 2,
      "name": "Rock_Volcanic"
    },
    {
      "x": -2,
      "y": -3,
      "z": 3,
      "name": "Rock_Volcanic"
    },
    {
      "x": -2,
      "y": -2,
      "z": 3,
      "name": "Rock_Volcanic"
    },
    {
      "x": -2,
      "y": -1,
      "z": 3,
      "name": "Rock_Volcanic"
    },
    {
      "x": -2,
      "y": 0,
      "z": 3,
      "name": "Rock_Volcanic"
    },
    {
      "x": -2,
      "y": 1,
      "z": 3,
      "name": "Rock_Volcanic"
    },
    {
      "x": -2,
      "y": 2,
      "z": 3,
      "name": "Rock_Volcanic"
    },
    {
      "x": -2,
      "y": 3,
      "z": 3,
      "name": "Rock_Volcanic"
    },
    {
      "x": -2,
      "y": 4,
      "z": 3,
      "name": "Rock_Volcanic_Cracked_Lava"
    },
    {
      "x": -2,
      "y": 5,
      "z": 3,
      "name": "Rock_Volcanic"
    },
    {
      "x": -2,
      "y": 6,
      "z": 3,
      "name": "Rock_Volcanic"
    },
    {
      "x": -2,
      "y": 7,
      "z": 3,
      "name": "Rock_Volcanic"
    },
    {
      "x": -2,
      "y": -2,
      "z": 4,
      "name": "Rock_Volcanic"
    },
    {
      "x": -2,
      "y": -1,
      "z": 4,
      "name": "Rock_Volcanic"
    },
    {
      "x": -2,
      "y": 0,
      "z": 4,
      "name": "Rock_Volcanic"
    },
    {
      "x": -2,
      "y": 1,
      "z": 4,
      "name": "Rock_Volcanic"
    },
    {
      "x": -2,
      "y": 2,
      "z": 4,
      "name": "Rock_Volcanic"
    },
    {
      "x": -2,
      "y": 3,
      "z": 4,
      "name": "Rock_Volcanic"
    },
    {
      "x": -2,
      "y": 4,
      "z": 4,
      "name": "Rock_Volcanic_Cracked_Lava"
    },
    {
      "x": -2,
      "y": 5,
      "z": 4,
      "name": "Rock_Volcanic"
    },
    {
      "x": -2,
      "y": 6,
      "z": 4,
      "name": "Rock_Volcanic"
    },
    {
      "x": -2,
      "y": 7,
      "z": 4,
      "name": "Rock_Volcanic"
    },
    {
      "x": -2,
      "y": 8,
      "z": 4,
      "name": "Rock_Volcanic"
    },
    {
      "x": -2,
      "y": -2,
      "z": 5,
      "name": "Rock_Volcanic"
    },
    {
      "x": -2,
      "y": -1,
      "z": 5,
      "name": "Rock_Volcanic_Cracked_Lava"
    },
    {
      "x": -2,
      "y": 0,
      "z": 5,
      "name": "Rock_Volcanic_Cracked_Lava"
    },
    {
      "x": -2,
      "y": 1,
      "z": 5,
      "name": "Rock_Volcanic"
    },
    {
      "x": -2,
      "y": 2,
      "z": 5,
      "name": "Rock_Volcanic_Cracked_Lava"
    },
    {
      "x": -2,
      "y": 3,
      "z": 5,
      "name": "Rock_Volcanic"
    },
    {
      "x": -2,
      "y": 4,
      "z": 5,
      "name": "Rock_Volcanic"
    },
    {
      "x": -2,
      "y": 5,
      "z": 5,
      "name": "Rock_Volcanic_Cracked_Lava"
    },
    {
      "x": -2,
      "y": 6,
      "z": 5,
      "name": "Rock_Volcanic"
    },
    {
      "x": -2,
      "y": 7,
      "z": 5,
      "name": "Rock_Volcanic"
    },
    {
      "x": -2,
      "y": -1,
      "z": 6,
      "name": "Rock_Volcanic"
    },
    {
      "x": -2,
      "y": 0,
      "z": 6,
      "name": "Rock_Volcanic"
    },
    {
      "x": -2,
      "y": 1,
      "z": 6,
      "name": "Rock_Volcanic"
    },
    {
      "x": -2,
      "y": 2,
      "z": 6,
      "name": "Rock_Volcanic_Cracked_Lava"
    },
    {
      "x": -2,
      "y": 3,
      "z": 6,
      "name": "Rock_Volcanic"
    },
    {
      "x": -2,
      "y": 4,
      "z": 6,
      "name": "Rock_Volcanic"
    },
    {
      "x": -2,
      "y": 5,
      "z": 6,
      "name": "Rock_Volcanic"
    },
    {
      "x": -2,
      "y": 6,
      "z": 6,
      "name": "Rock_Volcanic"
    },
    {
      "x": -2,
      "y": 7,
      "z": 6,
      "name": "Rock_Volcanic"
    },
    {
      "x": -2,
      "y": 8,
      "z": 6,
      "name": "Rock_Volcanic"
    },
    {
      "x": -2,
      "y": -2,
      "z": 7,
      "name": "Rock_Volcanic"
    },
    {
      "x": -2,
      "y": -1,
      "z": 7,
      "name": "Rock_Volcanic_Cracked_Lava"
    },
    {
      "x": -2,
      "y": 0,
      "z": 7,
      "name": "Rock_Volcanic"
    },
    {
      "x": -2,
      "y": 1,
      "z": 7,
      "name": "Rock_Volcanic"
    },
    {
      "x": -2,
      "y": 2,
      "z": 7,
      "name": "Rock_Volcanic"
    },
    {
      "x": -2,
      "y": 3,
      "z": 7,
      "name": "Rock_Volcanic"
    },
    {
      "x": -2,
      "y": 4,
      "z": 7,
      "name": "Rock_Volcanic"
    },
    {
      "x": -2,
      "y": 5,
      "z": 7,
      "name": "Rock_Volcanic"
    },
    {
      "x": -2,
      "y": 6,
      "z": 7,
      "name": "Rock_Volcanic"
    },
    {
      "x": -2,
      "y": 7,
      "z": 7,
      "name": "Rock_Volcanic_Cracked_Lava"
    },
    {
      "x": -2,
      "y": 8,
      "z": 7,
      "name": "Rock_Volcanic"
    },
    {
      "x": -2,
      "y": 9,
      "z": 7,
      "name": "Rock_Volcanic"
    },
    {
      "x": -2,
      "y": -1,
      "z": 8,
      "name": "Rock_Volcanic_Cracked_Lava"
    },
    {
      "x": -2,
      "y": 0,
      "z": 8,
      "name": "Rock_Volcanic"
    },
    {
      "x": -2,
      "y": 1,
      "z": 8,
      "name": "Rock_Volcanic"
    },
    {
      "x": -2,
      "y": 2,
      "z": 8,
      "name": "Rock_Volcanic"
    },
    {
      "x": -2,
      "y": 3,
      "z": 8,
      "name": "Rock_Volcanic_Cracked_Lava"
    },
    {
      "x": -2,
      "y": 4,
      "z": 8,
      "name": "Rock_Volcanic"
    },
    {
      "x": -2,
      "y": 5,
      "z": 8,
      "name": "Rock_Volcanic_Cracked_Lava"
    },
    {
      "x": -2,
      "y": 6,
      "z": 8,
      "name": "Rock_Volcanic_Cracked_Lava"
    },
    {
      "x": -2,
      "y": 7,
      "z": 8,
      "name": "Rock_Volcanic"
    },
    {
      "x": -2,
      "y": 8,
      "z": 8,
      "name": "Rock_Volcanic_Cracked_Lava"
    },
    {
      "x": -2,
      "y": 0,
      "z": 9,
      "name": "Rock_Volcanic"
    },
    {
      "x": -2,
      "y": 1,
      "z": 9,
      "name": "Rock_Volcanic"
    },
    {
      "x": -2,
      "y": 2,
      "z": 9,
      "name": "Rock_Volcanic_Cracked_Lava"
    },
    {
      "x": -2,
      "y": 3,
      "z": 9,
      "name": "Rock_Volcanic"
    },
    {
      "x": -2,
      "y": 4,
      "z": 9,
      "name": "Rock_Volcanic_Cracked_Lava"
    },
    {
      "x": -2,
      "y": 5,
      "z": 9,
      "name": "Rock_Volcanic"
    },
    {
      "x": -2,
      "y": 6,
      "z": 9,
      "name": "Rock_Volcanic_Cracked_Lava"
    },
    {
      "x": -2,
      "y": 7,
      "z": 9,
      "name": "Rock_Volcanic"
    },
    {
      "x": -2,
      "y": 8,
      "z": 9,
      "name": "Rock_Volcanic"
    },
    {
      "x": -2,
      "y": 9,
      "z": 9,
      "name": "Rock_Volcanic"
    },
    {
      "x": -2,
      "y": 2,
      "z": 10,
      "name": "Rock_Volcanic"
    },
    {
      "x": -2,
      "y": 3,
      "z": 10,
      "name": "Rock_Volcanic_Cracked_Lava"
    },
    {
      "x": -2,
      "y": 4,
      "z": 10,
      "name": "Rock_Volcanic_Cracked_Lava"
    },
    {
      "x": -2,
      "y": 5,
      "z": 10,
      "name": "Rock_Volcanic"
    },
    {
      "x": -2,
      "y": 6,
      "z": 10,
      "name": "Rock_Volcanic"
    },
    {
      "x": -2,
      "y": 7,
      "z": 10,
      "name": "Rock_Volcanic_Cracked_Lava"
    },
    {
      "x": -2,
      "y": 8,
      "z": 10,
      "name": "Rock_Volcanic"
    },
    {
      "x": -2,
      "y": 9,
      "z": 10,
      "name": "Rock_Volcanic"
    },
    {
      "x": -2,
      "y": 10,
      "z": 10,
      "name": "Rock_Volcanic"
    },
    {
      "x": -2,
      "y": 3,
      "z": 11,
      "name": "Rock_Volcanic"
    },
    {
      "x": -2,
      "y": 4,
      "z": 11,
      "name": "Rock_Volcanic"
    },
    {
      "x": -2,
      "y": 5,
      "z": 11,
      "name": "Rock_Volcanic"
    },
    {
      "x": -2,
      "y": 6,
      "z": 11,
      "name": "Rock_Volcanic_Cracked_Lava"
    },
    {
      "x": -2,
      "y": 7,
      "z": 11,
      "name": "Rock_Volcanic"
    },
    {
      "x": -2,
      "y": 8,
      "z": 11,
      "name": "Rock_Volcanic"
    },
    {
      "x": -2,
      "y": 9,
      "z": 11,
      "name": "Rock_Volcanic"
    },
    {
      "x": -2,
      "y": 10,
      "z": 11,
      "name": "Rock_Volcanic"
    },
    {
      "x": -2,
      "y": 3,
      "z": 12,
      "name": "Rock_Volcanic"
    },
    {
      "x": -2,
      "y": 4,
      "z": 12,
      "name": "Rock_Volcanic"
    },
    {
      "x": -2,
      "y": 5,
      "z": 12,
      "name": "Rock_Volcanic"
    },
    {
      "x": -2,
      "y": 6,
      "z": 12,
      "name": "Rock_Volcanic_Cracked_Lava"
    },
    {
      "x": -2,
      "y": 7,
      "z": 12,
      "name": "Rock_Volcanic_Cracked_Lava"
    },
    {
      "x": -2,
      "y": 8,
      "z": 12,
      "name": "Rock_Volcanic"
    },
    {
      "x": -2,
      "y": 9,
      "z": 12,
      "name": "Rock_Volcanic"
    },
    {
      "x": -2,
      "y": 10,
      "z": 12,
      "name": "Rock_Volcanic"
    },
    {
      "x": -2,
      "y": 11,
      "z": 12,
      "name": "Rock_Volcanic"
    },
    {
      "x": -2,
      "y": 3,
      "z": 13,
      "name": "Rock_Volcanic"
    },
    {
      "x": -2,
      "y": 4,
      "z": 13,
      "name": "Rock_Volcanic"
    },
    {
      "x": -2,
      "y": 5,
      "z": 13,
      "name": "Rock_Volcanic_Cracked_Lava"
    },
    {
      "x": -2,
      "y": 6,
      "z": 13,
      "name": "Rock_Volcanic_Cracked_Lava"
    },
    {
      "x": -2,
      "y": 7,
      "z": 13,
      "name": "Rock_Volcanic_Cracked_Lava"
    },
    {
      "x": -2,
      "y": 8,
      "z": 13,
      "name": "Rock_Volcanic"
    },
    {
      "x": -2,
      "y": 9,
      "z": 13,
