{
  "version": 8,
  "blockIdVersion": 11,
  "anchorX": 0,
  "anchorY": 0,
  "anchorZ": 0,
  "blocks": [
    {
      "x": -3,
      "y": 0,
      "z": 0,
      "name": "Plant_Crop_Mushroom_Block_Purple"
    },
    {
      "x": -3,
      "y": 1,
      "z": 0,
      "name": "Plant_Crop_Mushroom_Block_Purple"
    },
    {
      "x": -3,
      "y": 2,
      "z": 0,
      "name": "Plant_Crop_Mushroom_Block_Purple"
    },
    {
      "x": -3,
      "y": 0,
      "z": 1,
      "name": "Plant_Crop_Mushroom_Block_Purple"
    },
    {
      "x": -3,
      "y": 1,
      "z": 1,
      "name": "Plant_Crop_Mushroom_Block_Purple"
    },
    {
      "x": -3,
      "y": 2,
      "z": 1,
      "name": "Plant_Crop_Mushroom_Block_Purple"
    },
    {
      "x": -3,
      "y": 3,
      "z": 1,
      "name": "Plant_Crop_Mushroom_Glowing_Purple"
    },
    {
      "x": -2,
      "y": 0,
      "z": -1,
      "name": "Plant_Crop_Mushroom_Block_Purple"
    },
    {
      "x": -2,
      "y": 1,
      "z": -1,
      "name": "Plant_Crop_Mushroom_Block_Purple"
    },
    {
      "x": -2,
      "y": 2,
      "z": -1,
      "name": "Plant_Crop_Mushroom_Block_Purple"
    },
    {
      "x": -2,
      "y": 0,
      "z": 0,
      "name": "Plant_Crop_Mushroom_Block_Purple"
    },
    {
      "x": -2,
      "y": 1,
      "z": 0,
      "name": "Plant_Crop_Mushroom_Block_Purple"
    },
    {
      "x": -2,
      "y": 2,
      "z": 0,
      "name": "Plant_Crop_Mushroom_Block_Purple"
    },
    {
      "x": -2,
      "y": 3,
      "z": 0,
      "name": "Plant_Crop_Mushroom_Block_Purple"
    },
    {
      "x": -2,
      "y": 4,
      "z": 0,
      "name": "Plant_Moss_Rug_Pink"
    },
    {
      "x": -2,
      "y": 0,
      "z": 1,
      "name": "Plant_Crop_Mushroom_Block_Purple"
    },
    {
      "x": -2,
      "y": 1,
      "z": 1,
      "name": "Plant_Crop_Mushroom_Block_Purple"
    },
    {
      "x": -2,
      "y": 2,
      "z": 1,
      "name": "Plant_Crop_Mushroom_Block_Purple"
    },
    {
      "x": -2,
      "y": 3,
      "z": 1,
      "name": "Plant_Crop_Mushroom_Block_Purple"
    },
    {
      "x": -2,
      "y": 4,
      "z": 1,
      "name": "Plant_Moss_Rug_Pink"
    },
    {
      "x": -2,
      "y": 0,
      "z": 2,
      "name": "Plant_Crop_Mushroom_Block_Purple"
    },
    {
      "x": -2,
      "y": 1,
      "z": 2,
      "name": "Plant_Crop_Mushroom_Block_Purple"
    },
    {
      "x": -2,
      "y": 2,
      "z": 2,
      "name": "Plant_Crop_Mushroom_Block_Purple"
    },
    {
      "x": -2,
      "y": 3,
      "z": 2,
      "name": "Plant_Moss_Rug_Pink"
    },
    {
      "x": -1,
      "y": 0,
      "z": -2,
      "name": "Plant_Crop_Mushroom_Block_Purple"
    },
    {
      "x": -1,
      "y": 1,
      "z": -2,
      "name": "Plant_Crop_Mushroom_Block_Purple"
    },
    {
      "x": -1,
      "y": 2,
      "z": -2,
      "name": "Plant_Crop_Mushroom_Block_Purple"
    },
    {
      "x": -1,
      "y": 0,
      "z": -1,
      "name": "Plant_Crop_Mushroom_Block_Purple"
    },
    {
      "x": -1,
      "y": 1,
      "z": -1,
      "name": "Plant_Crop_Mushroom_Block_Purple"
    },
    {
      "x": -1,
      "y": 2,
      "z": -1,
      "name": "Plant_Crop_Mushroom_Block_Purple"
    },
    {
      "x": -1,
      "y": 3,
      "z": -1,
      "name": "Plant_Crop_Mushroom_Block_Purple"
    },
    {
      "x": -1,
      "y": 4,
      "z": -1,
      "name": "Plant_Moss_Rug_Pink"
    },
    {
      "x": -1,
      "y": 0,
      "z": 0,
      "name": "Plant_Crop_Mushroom_Block_Purple"
    },
    {
      "x": -1,
      "y": 1,
      "z": 0,
      "name": "Plant_Crop_Mushroom_Block_Purple"
    },
    {
      "x": -1,
      "y": 2,
      "z": 0,
      "name": "Plant_Crop_Mushroom_Block_Purple"
    },
    {
      "x": -1,
      "y": 3,
      "z": 0,
      "name": "Plant_Crop_Mushroom_Block_Purple"
    },
    {
      "x": -1,
      "y": 4,
      "z": 0,
      "name": "Plant_Crop_Mushroom_Block_Purple"
    },
    {
      "x": -1,
      "y": 5,
      "z": 0,
      "name": "Plant_Crop_Mushroom_Glowing_Violet"
    },
    {
      "x": -1,
      "y": 0,
      "z": 1,
      "name": "Plant_Crop_Mushroom_Block_Purple"
    },
    {
      "x": -1,
      "y": 1,
      "z": 1,
      "name": "Plant_Crop_Mushroom_Block_Purple"
    },
    {
      "x": -1,
      "y": 2,
      "z": 1,
      "name": "Plant_Crop_Mushroom_Block_Purple"
    },
    {
      "x": -1,
      "y": 3,
      "z": 1,
      "name": "Plant_Crop_Mushroom_Block_Purple"
    },
    {
      "x": -1,
      "y": 4,
      "z": 1,
      "name": "Plant_Crop_Mushroom_Block_Purple"
    },
    {
      "x": -1,
      "y": 5,
      "z": 1,
      "name": "Plant_Crop_Mushroom_Glowing_Purple"
    },
    {
      "x": -1,
      "y": 0,
      "z": 2,
      "name": "Plant_Crop_Mushroom_Block_Purple"
    },
    {
      "x": -1,
      "y": 1,
      "z": 2,
      "name": "Plant_Crop_Mushroom_Block_Purple"
    },
    {
      "x": -1,
      "y": 2,
      "z": 2,
      "name": "Plant_Crop_Mushroom_Block_Purple"
    },
    {
      "x": -1,
      "y": 3,
      "z": 2,
      "name": "Plant_Crop_Mushroom_Block_Purple"
    },
    {
      "x": -1,
      "y": 4,
      "z": 2,
      "name": "Plant_Crop_Mushroom_Block_Purple"
    },
    {
      "x": -1,
      "y": 0,
      "z": 3,
      "name": "Plant_Crop_Mushroom_Block_Purple"
    },
    {
      "x": -1,
      "y": 1,
      "z": 3,
      "name": "Plant_Crop_Mushroom_Block_Purple"
    },
    {
      "x": -1,
      "y": 2,
      "z": 3,
      "name": "Plant_Crop_Mushroom_Block_Purple"
    },
    {
      "x": -1,
      "y": 3,
      "z": 3,
      "name": "Plant_Moss_Rug_Pink"
    },
    {
      "x": 0,
      "y": 0,
      "z": -3,
      "name": "Plant_Crop_Mushroom_Block_Purple"
    },
    {
      "x": 0,
      "y": 1,
      "z": -3,
      "name": "Plant_Crop_Mushroom_Block_Purple"
    },
    {
      "x": 0,
      "y": 2,
      "z": -3,
      "name": "Plant_Crop_Mushroom_Block_Purple"
    },
    {
      "x": 0,
      "y": 3,
      "z": -3,
      "name": "Plant_Crop_Mushroom_Glowing_Violet"
    },
    {
      "x": 0,
      "y": 0,
      "z": -2,
      "name": "Plant_Crop_Mushroom_Block_Purple"
    },
    {
      "x": 0,
      "y": 1,
      "z": -2,
      "name": "Plant_Crop_Mushroom_Block_Purple"
    },
    {
      "x": 0,
      "y": 2,
      "z": -2,
      "name": "Plant_Crop_Mushroom_Block_Purple"
    },
    {
      "x": 0,
      "y": 3,
      "z": -2,
      "name": "Plant_Crop_Mushroom_Block_Purple"
    },
    {
      "x": 0,
      "y": 4,
      "z": -2,
      "name": "Plant_Moss_Rug_Pink"
    },
    {
      "x": 0,
      "y": 0,
      "z": -1,
      "name": "Plant_Crop_Mushroom_Block_Purple"
    },
    {
      "x": 0,
      "y": 1,
      "z": -1,
      "name": "Plant_Crop_Mushroom_Block_Purple"
    },
    {
      "x": 0,
      "y": 2,
      "z": -1,
      "name": "Plant_Crop_Mushroom_Block_Purple"
    },
    {
      "x": 0,
      "y": 3,
      "z": -1,
      "name": "Plant_Crop_Mushroom_Block_Purple"
    },
    {
      "x": 0,
      "y": 4,
      "z": -1,
      "name": "Plant_Moss_Rug_Pink"
    },
    {
      "x": 0,
      "y": 0,
      "z": 0,
      "name": "Plant_Crop_Mushroom_Block_Purple"
    },
    {
      "x": 0,
      "y": 1,
      "z": 0,
      "name": "Plant_Crop_Mushroom_Block_Purple"
    },
    {
      "x": 0,
      "y": 2,
      "z": 0,
      "name": "Plant_Crop_Mushroom_Block_Purple"
    },
    {
      "x": 0,
      "y": 3,
      "z": 0,
      "name": "Plant_Crop_Mushroom_Block_Purple"
    },
    {
      "x": 0,
      "y": 4,
      "z": 0,
      "name": "Plant_Crop_Mushroom_Block_Purple"
    },
    {
      "x": 0,
      "y": 5,
      "z": 0,
      "name": "Plant_Crop_Mushroom_Glowing_Purple"
    },
    {
      "x": 0,
      "y": 0,
      "z": 1,
      "name": "Plant_Crop_Mushroom_Block_Purple"
    },
    {
      "x": 0,
      "y": 1,
      "z": 1,
      "name": "Plant_Crop_Mushroom_Block_Purple"
    },
    {
      "x": 0,
      "y": 2,
      "z": 1,
      "name": "Plant_Crop_Mushroom_Block_Purple"
    },
    {
      "x": 0,
      "y": 3,
      "z": 1,
      "name": "Plant_Crop_Mushroom_Block_Purple"
    },
    {
      "x": 0,
      "y": 4,
      "z": 1,
      "name": "Plant_Crop_Mushroom_Block_Purple"
    },
    {
      "x": 0,
      "y": 5,
      "z": 1,
      "name": "Plant_Crop_Mushroom_Glowing_Violet"
    },
    {
      "x": 0,
      "y": 0,
      "z": 2,
      "name": "Plant_Crop_Mushroom_Block_Purple"
    },
    {
      "x": 0,
      "y": 1,
      "z": 2,
      "name": "Plant_Crop_Mushroom_Block_Purple"
    },
    {
      "x": 0,
      "y": 2,
      "z": 2,
      "name": "Plant_Crop_Mushroom_Block_Purple"
    },
    {
      "x": 0,
      "y": 3,
      "z": 2,
      "name": "Plant_Crop_Mushroom_Block_Purple"
    },
    {
      "x": 0,
      "y": 4,
      "z": 2,
      "name": "Plant_Crop_Mushroom_Block_Purple"
    },
    {
      "x": 0,
      "y": 0,
      "z": 3,
      "name": "Plant_Crop_Mushroom_Block_Purple"
    },
    {
      "x": 0,
      "y": 1,
      "z": 3,
      "name": "Plant_Crop_Mushroom_Block_Purple"
    },
    {
      "x": 0,
      "y": 2,
      "z": 3,
      "name": "Plant_Crop_Mushroom_Block_Purple"
    },
    {
      "x": 0,
      "y": 3,
      "z": 3,
      "name": "Plant_Crop_Mushroom_Block_Purple"
    },
    {
      "x": 0,
      "y": 4,
      "z": 3,
      "name": "Plant_Moss_Rug_Pink"
    },
    {
      "x": 1,
      "y": 0,
      "z": -3,
      "name": "Plant_Crop_Mushroom_Block_Purple"
    },
    {
      "x": 1,
      "y": 1,
      "z": -3,
      "name": "Plant_Crop_Mushroom_Block_Purple"
    },
    {
      "x": 1,
      "y": 2,
      "z": -3,
      "name": "Plant_Crop_Mushroom_Block_Purple"
    },
    {
      "x": 1,
      "y": 0,
      "z": -2,
      "name": "Plant_Crop_Mushroom_Block_Purple"
    },
    {
      "x": 1,
      "y": 1,
      "z": -2,
      "name": "Plant_Crop_Mushroom_Block_Purple"
    },
    {
      "x": 1,
      "y": 2,
      "z": -2,
      "name": "Plant_Crop_Mushroom_Block_Purple"
    },
    {
      "x": 1,
      "y": 3,
      "z": -2,
      "name": "Plant_Crop_Mushroom_Block_Purple"
    },
    {
      "x": 1,
      "y": 4,
      "z": -2,
      "name": "Plant_Moss_Rug_Pink"
    },
    {
      "x": 1,
      "y": 0,
      "z": -1,
      "name": "Plant_Crop_Mushroom_Block_Purple"
    },
    {
      "x": 1,
      "y": 1,
      "z": -1,
      "name": "Plant_Crop_Mushroom_Block_Purple"
    },
    {
      "x": 1,
      "y": 2,
      "z": -1,
      "name": "Plant_Crop_Mushroom_Block_Purple"
    },
    {
      "x": 1,
      "y": 3,
      "z": -1,
      "name": "Plant_Crop_Mushroom_Block_Purple"
    },
    {
      "x": 1,
      "y": 0,
      "z": 0,
      "name": "Plant_Crop_Mushroom_Block_Purple"
    },
    {
      "x": 1,
      "y": 1,
      "z": 0,
      "name": "Plant_Crop_Mushroom_Block_Purple"
    },
    {
      "x": 1,
      "y": 2,
      "z": 0,
      "name": "Plant_Crop_Mushroom_Block_Purple"
    },
    {
      "x": 1,
      "y": 3,
      "z": 0,
      "name": "Plant_Crop_Mushroom_Block_Purple"
    },
    {
      "x": 1,
      "y": 4,
      "z": 0,
      "name": "Plant_Crop_Mushroom_Block_Purple"
    },
    {
      "x": 1,
      "y": 0,
      "z": 1,
      "name": "Plant_Crop_Mushroom_Block_Purple"
    },
    {
      "x": 1,
      "y": 1,
      "z": 1,
      "name": "Plant_Crop_Mushroom_Block_Purple"
    },
    {
      "x": 1,
      "y": 2,
      "z": 1,
      "name": "Plant_Crop_Mushroom_Block_Purple"
    },
    {
      "x": 1,
      "y": 3,
      "z": 1,
      "name": "Plant_Crop_Mushroom_Block_Purple"
    },
    {
      "x": 1,
      "y": 4,
      "z": 1,
      "name": "Plant_Crop_Mushroom_Block_Purple"
    },
    {
      "x": 1,
      "y": 5,
      "z": 1,
      "name": "Plant_Moss_Rug_Pink"
    },
    {
      "x": 1,
      "y": 0,
      "z": 2,
      "name": "Plant_Crop_Mushroom_Block_Purple"
    },
    {
      "x": 1,
      "y": 1,
      "z": 2,
      "name": "Plant_Crop_Mushroom_Block_Purple"
    },
    {
      "x": 1,
      "y": 2,
      "z": 2,
      "name": "Plant_Crop_Mushroom_Block_Purple"
    },
    {
      "x": 1,
      "y": 3,
      "z": 2,
      "name": "Plant_Crop_Mushroom_Block_Purple"
    },
    {
      "x": 1,
      "y": 4,
      "z": 2,
      "name": "Plant_Crop_Mushroom_Block_Purple"
    },
    {
      "x": 1,
      "y": 0,
      "z": 3,
      "name": "Plant_Crop_Mushroom_Block_Purple"
    },
    {
      "x": 1,
      "y": 1,
      "z": 3,
      "name": "Plant_Crop_Mushroom_Block_Purple"
    },
    {
      "x": 1,
      "y": 2,
      "z": 3,
      "name": "Plant_Crop_Mushroom_Block_Purple"
    },
    {
      "x": 1,
      "y": 3,
      "z": 3,
      "name": "Plant_Crop_Mushroom_Block_Purple"
    },
    {
      "x": 1,
      "y": 4,
      "z": 3,
      "name": "Plant_Moss_Rug_Pink"
    },
    {
      "x": 2,
      "y": 0,
      "z": -2,
      "name": "Plant_Crop_Mushroom_Block_Purple"
    },
    {
      "x": 2,
      "y": 1,
      "z": -2,
      "name": "Plant_Crop_Mushroom_Block_Purple"
    },
    {
      "x": 2,
      "y": 2,
      "z": -2,
      "name": "Plant_Crop_Mushroom_Block_Purple"
    },
    {
      "x": 2,
      "y": 0,
      "z": -1,
      "name": "Plant_Crop_Mushroom_Block_Purple"
    },
    {
      "x": 2,
      "y": 1,
      "z": -1,
      "name": "Plant_Crop_Mushroom_Block_Purple"
    },
    {
      "x": 2,
      "y": 2,
      "z": -1,
      "name": "Plant_Crop_Mushroom_Block_Purple"
    },
    {
      "x": 2,
      "y": 3,
      "z": -1,
      "name": "Plant_Crop_Mushroom_Block_Purple"
    },
    {
      "x": 2,
      "y": 4,
      "z": -1,
      "name": "Plant_Crop_Mushroom_Glowing_Violet"
    },
    {
      "x": 2,
      "y": 0,
      "z": 0,
      "name": "Plant_Crop_Mushroom_Block_Purple"
    },
    {
      "x": 2,
      "y": 1,
      "z": 0,
      "name": "Plant_Crop_Mushroom_Block_Purple"
    },
    {
      "x": 2,
      "y": 2,
      "z": 0,
      "name": "Plant_Crop_Mushroom_Block_Purple"
    },
    {
      "x": 2,
      "y": 3,
      "z": 0,
      "name": "Plant_Crop_Mushroom_Block_Purple"
    },
    {
      "x": 2,
      "y": 4,
      "z": 0,
      "name": "Plant_Crop_Mushroom_Glowing_Purple"
    },
    {
      "x": 2,
      "y": 0,
      "z": 1,
      "name": "Plant_Crop_Mushroom_Block_Purple"
    },
    {
      "x": 2,
      "y": 1,
      "z": 1,
      "name": "Plant_Crop_Mushroom_Block_Purple"
    },
    {
      "x": 2,
      "y": 2,
      "z": 1,
      "name": "Plant_Crop_Mushroom_Block_Purple"
    },
    {
      "x": 2,
      "y": 3,
      "z": 1,
      "name": "Plant_Crop_Mushroom_Block_Purple"
    },
    {
      "x": 2,
      "y": 4,
      "z": 1,
      "name": "Plant_Crop_Mushroom_Block_Purple"
    },
    {
      "x": 2,
      "y": 5,
      "z": 1,
      "name": "Plant_Crop_Mushroom_Glowing_Purple"
    },
    {
      "x": 2,
      "y": 0,
      "z": 2,
      "name": "Plant_Crop_Mushroom_Block_Purple"
    },
    {
      "x": 2,
      "y": 1,
      "z": 2,
      "name": "Plant_Crop_Mushroom_Block_Purple"
    },
    {
      "x": 2,
      "y": 2,
      "z": 2,
      "name": "Plant_Crop_Mushroom_Block_Purple"
    },
    {
      "x": 2,
      "y": 3,
      "z": 2,
      "name": "Plant_Crop_Mushroom_Block_Purple"
    },
    {
      "x": 2,
      "y": 4,
      "z": 2,
      "name": "Plant_Crop_Mushroom_Block_Purple"
    },
    {
      "x": 2,
      "y": 5,
      "z": 2,
      "name": "Plant_Moss_Rug_Pink"
    },
    {
      "x": 3,
      "y": 0,
      "z": -1,
      "name": "Plant_Crop_Mushroom_Block_Purple"
    },
    {
      "x": 3,
      "y": 1,
      "z": -1,
      "name": "Plant_Crop_Mushroom_Block_Purple"
    },
    {
      "x": 3,
      "y": 2,
      "z": -1,
      "name": "Plant_Crop_Mushroom_Block_Purple"
    },
    {
      "x": 3,
      "y": 3,
      "z": -1,
      "name": "Plant_Moss_Rug_Pink"
    },
    {
      "x": 3,
      "y": 0,
      "z": 0,
      "name": "Plant_Crop_Mushroom_Block_Purple"
    },
    {
      "x": 3,
      "y": 1,
      "z": 0,
      "name": "Plant_Crop_Mushroom_Block_Purple"
    },
    {
      "x": 3,
      "y": 2,
      "z": 0,
      "name": "Plant_Crop_Mushroom_Block_Purple"
    },
    {
      "x": 3,
      "y": 3,
      "z": 0,
      "name": "Plant_Moss_Rug_Pink"
    },
    {
      "x": 3,
      "y": 0,
      "z": 1,
      "name": "Plant_Crop_Mushroom_Block_Purple"
    },
    {
      "x": 3,
      "y": 1,
      "z": 1,
      "name": "Plant_Crop_Mushroom_Block_Purple"
    },
    {
      "x": 3,
      "y": 2,
      "z": 1,
      "name": "Plant_Crop_Mushroom_Block_Purple"
    },
    {
      "x": 3,
      "y": 3,
      "z": 1,
      "name": "Plant_Moss_Rug_Pink"
    }
  ],
  "fluids": [
    {
      "x": -3,
      "y": 0,
      "z": 0,
      "name": "Empty",
      "level": 0
    },
    {
      "x": -3,
      "y": 1,
      "z": 0,
      "name": "Empty",
      "level": 0
    },
    {
      "x": -3,
      "y": 2,
      "z": 0,
      "name": "Empty",
      "level": 0
    },
    {
      "x": -3,
      "y": 0,
      "z": 1,
      "name": "Empty",
      "level": 0
    },
    {
      "x": -3,
      "y": 1,
      "z": 1,
      "name": "Empty",
      "level": 0
    },
    {
      "x": -3,
      "y": 2,
      "z": 1,
      "name": "Empty",
      "level": 0
    },
    {
      "x": -3,
      "y": 3,
      "z": 1,
      "name": "Empty",
      "level": 0
    },
    {
      "x": -2,
      "y": 0,
      "z": -1,
      "name": "Empty",
      "level": 0
    },
    {
      "x": -2,
      "y": 1,
      "z": -1,
      "name": "Empty",
      "level": 0
    },
    {
      "x": -2,
      "y": 2,
      "z": -1,
      "name": "Empty",
      "level": 0
    },
    {
      "x": -2,
      "y": 0,
      "z": 0,
      "name": "Empty",
      "level": 0
    },
    {
      "x": -2,
      "y": 1,
      "z": 0,
      "name": "Empty",
      "level": 0
    },
    {
      "x": -2,
      "y": 2,
      "z": 0,
      "name": "Empty",
      "level": 0
    },
    {
      "x": -2,
      "y": 3,
      "z": 0,
      "name": "Empty",
      "level": 0
    },
    {
      "x": -2,
      "y": 4,
      "z": 0,
      "name": "Empty",
      "level": 0
    },
    {
      "x": -2,
      "y": 0,
      "z": 1,
      "name": "Empty",
      "level": 0
    },
    {
      "x": -2,
      "y": 1,
      "z": 1,
      "name": "Empty",
      "level": 0
    },
    {
      "x": -2,
      "y": 2,
      "z": 1,
      "name": "Empty",
      "level": 0
    },
    {
      "x": -2,
      "y": 3,
      "z": 1,
      "name": "Empty",
      "level": 0
    },
    {
      "x": -2,
      "y": 4,
      "z": 1,
      "name": "Empty",
      "level": 0
    },
    {
      "x": -2,
      "y": 0,
      "z": 2,
      "name": "Empty",
      "level": 0
    },
    {
      "x": -2,
      "y": 1,
      "z": 2,
      "name": "Empty",
      "level": 0
    },
    {
      "x": -2,
      "y": 2,
      "z": 2,
      "name": "Empty",
      "level": 0
    },
    {
      "x": -2,
      "y": 3,
      "z": 2,
      "name": "Empty",
      "level": 0
    },
    {
      "x": -1,
      "y": 0,
      "z": -2,
      "name": "Empty",
      "level": 0
    },
    {
      "x": -1,
      "y": 1,
      "z": -2,
      "name": "Empty",
      "level": 0
    },
    {
      "x": -1,
      "y": 2,
      "z": -2,
      "name": "Empty",
      "level": 0
    },
    {
      "x": -1,
      "y": 0,
      "z": -1,
      "name": "Empty",
      "level": 0
    },
    {
      "x": -1,
      "y": 1,
      "z": -1,
      "name": "Empty",
      "level": 0
    },
    {
      "x": -1,
      "y": 2,
      "z": -1,
      "name": "Empty",
      "level": 0
    },
    {
      "x": -1,
      "y": 3,
      "z": -1,
      "name": "Empty",
      "level": 0
    },
    {
      "x": -1,
      "y": 4,
      "z": -1,
      "name": "Empty",
      "level": 0
    },
    {
      "x": -1,
      "y": 0,
      "z": 0,
      "name": "Empty",
      "level": 0
    },
    {
      "x": -1,
      "y": 1,
      "z": 0,
      "name": "Empty",
      "level": 0
    },
    {
      "x": -1,
      "y": 2,
      "z": 0,
      "name": "Empty",
      "level": 0
    },
    {
      "x": -1,
      "y": 3,
      "z": 0,
      "name": "Empty",
      "level": 0
    },
    {
      "x": -1,
      "y": 4,
      "z": 0,
      "name": "Empty",
      "level": 0
    },
    {
      "x": -1,
      "y": 5,
      "z": 0,
      "name": "Empty",
      "level": 0
    },
    {
      "x": -1,
      "y": 0,
      "z": 1,
      "name": "Empty",
      "level": 0
    },
    {
      "x": -1,
      "y": 1,
      "z": 1,
      "name": "Empty",
      "level": 0
    },
    {
      "x": -1,
      "y": 2,
      "z": 1,
      "name": "Empty",
      "level": 0
    },
    {
      "x": -1,
      "y": 3,
      "z": 1,
      "name": "Empty",
      "level": 0
    },
    {
      "x": -1,
      "y": 4,
      "z": 1,
      "name": "Empty",
      "level": 0
    },
    {
      "x": -1,
      "y": 5,
      "z": 1,
      "name": "Empty",
      "level": 0
    },
    {
      "x": -1,
      "y": 0,
      "z": 2,
      "name": "Empty",
      "level": 0
    },
    {
      "x": -1,
      "y": 1,
      "z": 2,
      "name": "Empty",
      "level": 0
    },
    {
      "x": -1,
      "y": 2,
      "z": 2,
      "name": "Empty",
      "level": 0
    },
    {
      "x": -1,
      "y": 3,
      "z": 2,
      "name": "Empty",
      "level": 0
    },
    {
      "x": -1,
      "y": 4,
      "z": 2,
      "name": "Empty",
      "level": 0
    },
    {
      "x": -1,
      "y": 0,
      "z": 3,
      "name": "Empty",
      "level": 0
    },
    {
      "x": -1,
      "y": 1,
      "z": 3,
      "name": "Empty",
      "level": 0
    },
    {
      "x": -1,
      "y": 2,
      "z": 3,
      "name": "Empty",
      "level": 0
    },
    {
      "x": -1,
      "y": 3,
      "z": 3,
      "name": "Empty",
      "level": 0
    },
    {
      "x": 0,
      "y": 0,
      "z": -3,
      "name": "Empty",
      "level": 0
    },
    {
      "x": 0,
      "y": 1,
      "z": -3,
      "name": "Empty",
      "level": 0
    },
    {
      "x": 0,
      "y": 2,
      "z": -3,
      "name": "Empty",
      "level": 0
    },
    {
      "x": 0,
      "y": 3,
      "z": -3,
      "name": "Empty",
      "level": 0
    },
    {
      "x": 0,
      "y": 0,
      "z": -2,
      "name": "Empty",
      "level": 0
    },
    {
      "x": 0,
      "y": 1,
      "z": -2,
      "name": "Empty",
      "level": 0
    },
    {
      "x": 0,
      "y": 2,
      "z": -2,
      "name": "Empty",
      "level": 0
    },
    {
      "x": 0,
      "y": 3,
      "z": -2,
      "name": "Empty",
      "level": 0
    },
    {
      "x": 0,
      "y": 4,
      "z": -2,
      "name": "Empty",
      "level": 0
    },
    {
      "x": 0,
      "y": 0,
      "z": -1,
      "name": "Empty",
      "level": 0
    },
    {
      "x": 0,
      "y": 1,
      "z": -1,
      "name": "Empty",
      "level": 0
    },
    {
      "x": 0,
      "y": 2,
      "z": -1,
      "name": "Empty",
      "level": 0
    },
    {
      "x": 0,
      "y": 3,
      "z": -1,
      "name": "Empty",
      "level": 0
    },
    {
      "x": 0,
      "y": 4,
      "z": -1,
      "name": "Empty",
      "level": 0
    },
    {
      "x": 0,
      "y": 0,
      "z": 0,
      "name": "Empty",
      "level": 0
    },
    {
      "x": 0,
      "y": 1,
      "z": 0,
      "name": "Empty",
      "level": 0
    },
    {
      "x": 0,
      "y": 2,
      "z": 0,
      "name": "Empty",
      "level": 0
    },
    {
      "x": 0,
      "y": 3,
      "z": 0,
      "name": "Empty",
      "level": 0
    },
    {
      "x": 0,
      "y": 4,
      "z": 0,
      "name": "Empty",
      "level": 0
    },
    {
      "x": 0,
      "y": 5,
      "z": 0,
      "name": "Empty",
      "level": 0
    },
    {
      "x": 0,
      "y": 0,
      "z": 1,
      "name": "Empty",
      "level": 0
    },
    {
      "x": 0,
      "y": 1,
      "z": 1,
      "name": "Empty",
      "level": 0
    },
    {
      "x": 0,
      "y": 2,
      "z": 1,
      "name": "Empty",
      "level": 0
    },
    {
      "x": 0,
      "y": 3,
      "z": 1,
      "name": "Empty",
      "level": 0
    },
    {
      "x": 0,
      "y": 4,
      "z": 1,
      "name": "Empty",
      "level": 0
    },
    {
      "x": 0,
      "y": 5,
      "z": 1,
      "name": "Empty",
      "level": 0
    },
    {
      "x": 0,
      "y": 0,
      "z": 2,
      "name": "Empty",
      "level": 0
    },
    {
      "x": 0,
      "y": 1,
      "z": 2,
      "name": "Empty",
      "level": 0
    },
    {
      "x": 0,
      "y": 2,
      "z": 2,
      "name": "Empty",
      "level": 0
    },
    {
      "x": 0,
      "y": 3,
      "z": 2,
      "name": "Empty",
      "level": 0
    },
    {
      "x": 0,
      "y": 4,
      "z": 2,
      "name": "Empty",
      "level": 0
    },
    {
      "x": 0,
      "y": 0,
      "z": 3,
      "name": "Empty",
      "level": 0
    },
    {
      "x": 0,
      "y": 1,
      "z": 3,
      "name": "Empty",
      "level": 0
    },
    {
      "x": 0,
      "y": 2,
      "z": 3,
      "name": "Empty",
      "level": 0
    },
    {
      "x": 0,
      "y": 3,
      "z": 3,
      "name": "Empty",
      "level": 0
    },
    {
      "x": 0,
      "y": 4,
      "z": 3,
      "name": "Empty",
      "level": 0
    },
    {
      "x": 1,
      "y": 0,
      "z": -3,
      "name": "Empty",
      "level": 0
    },
    {
      "x": 1,
      "y": 1,
      "z": -3,
      "name": "Empty",
      "level": 0
    },
    {
      "x": 1,
      "y": 2,
      "z": -3,
      "name": "Empty",
      "level": 0
    },
    {
      "x": 1,
      "y": 0,
      "z": -2,
      "name": "Empty",
      "level": 0
    },
    {
      "x": 1,
      "y": 1,
      "z": -2,
      "name": "Empty",
      "level": 0
    },
    {
      "x": 1,
      "y": 2,
      "z": -2,
      "name": "Empty",
      "level": 0
    },
    {
      "x": 1,
      "y": 3,
      "z": -2,
      "name": "Empty",
      "level": 0
    },
    {
      "x": 1,
      "y": 4,
      "z": -2,
      "name": "Empty",
      "level": 0
    },
    {
      "x": 1,
      "y": 0,
      "z": -1,
      "name": "Empty",
      "level": 0
    },
    {
      "x": 1,
      "y": 1,
      "z": -1,
      "name": "Empty",
      "level": 0
    },
    {
      "x": 1,
      "y": 2,
      "z": -1,
      "name": "Empty",
      "level": 0
    },
    {
      "x": 1,
      "y": 3,
      "z": -1,
      "name": "Empty",
      "level": 0
    },
    {
      "x": 1,
      "y": 0,
      "z": 0,
      "name": "Empty",
      "level": 0
    },
    {
      "x": 1,
      "y": 1,
      "z": 0,
      "name": "Empty",
      "level": 0
    },
    {
      "x": 1,
      "y": 2,
      "z": 0,
      "name": "Empty",
      "level": 0
    },
    {
      "x": 1,
      "y": 3,
      "z": 0,
      "name": "Empty",
      "level": 0
    },
    {
      "x": 1,
      "y": 4,
      "z": 0,
      "name": "Empty",
      "level": 0
    },
    {
      "x": 1,
      "y": 0,
      "z": 1,
      "name": "Empty",
      "level": 0
    },
    {
      "x": 1,
      "y": 1,
      "z": 1,
      "name": "Empty",
      "level": 0
    },
    {
      "x": 1,
      "y": 2,
      "z": 1,
      "name": "Empty",
      "level": 0
    },
    {
      "x": 1,
      "y": 3,
      "z": 1,
      "name": "Empty",
      "level": 0
    },
    {
      "x": 1,
      "y": 4,
      "z": 1,
      "name": "Empty",
      "level": 0
    },
    {
      "x": 1,
      "y": 5,
      "z": 1,
      "name": "Empty",
      "level": 0
    },
    {
      "x": 1,
      "y": 0,
      "z": 2,
      "name": "Empty",
      "level": 0
    },
    {
      "x": 1,
      "y": 1,
      "z": 2,
      "name": "Empty",
      "level": 0
    },
    {
      "x": 1,
      "y": 2,
      "z": 2,
      "name": "Empty",
      "level": 0
    },
    {
      "x": 1,
      "y": 3,
      "z": 2,
      "name": "Empty",
      "level": 0
    },
    {
      "x": 1,
      "y": 4,
      "z": 2,
      "name": "Empty",
      "level": 0
    },
    {
      "x": 1,
      "y": 0,
      "z": 3,
      "name": "Empty",
      "level": 0
    },
    {
      "x": 1,
      "y": 1,
      "z": 3,
      "name": "Empty",
      "level": 0
    },
    {
      "x": 1,
      "y": 2,
      "z": 3,
      "name": "Empty",
      "level": 0
    },
    {
      "x": 1,
      "y": 3,
      "z": 3,
      "name": "Empty",
      "level": 0
    },
    {
      "x": 1,
      "y": 4,
      "z": 3,
      "name": "Empty",
      "level": 0
    },
    {
      "x": 2,
      "y": 0,
      "z": -2,
      "name": "Empty",
      "level": 0
    },
    {
      "x": 2,
      "y": 1,
      "z": -2,
      "name": "Empty",
      "level": 0
    },
    {
      "x": 2,
      "y": 2,
      "z": -2,
      "name": "Empty",
      "level": 0
    },
    {
      "x": 2,
      "y": 0,
      "z": -1,
      "name": "Empty",
      "level": 0
    },
    {
      "x": 2,
      "y": 1,
      "z": -1,
      "name": "Empty",
      "level": 0
    },
    {
      "x": 2,
      "y": 2,
      "z": -1,
      "name": "Empty",
      "level": 0
    },
    {
      "x": 2,
      "y": 3,
      "z": -1,
      "name": "Empty",
      "level": 0
    },
    {
      "x": 2,
      "y": 4,
      "z": -1,
      "name": "Empty",
      "level": 0
    },
    {
      "x": 2,
      "y": 0,
      "z": 0,
      "name": "Empty",
      "level": 0
    },
    {
      "x": 2,
      "y": 1,
      "z": 0,
      "name": "Empty",
      "level": 0
    },
    {
      "x": 2,
      "y": 2,
      "z": 0,
      "name": "Empty",
      "level": 0
    },
    {
      "x": 2,
      "y": 3,
      "z": 0,
      "name": "Empty",
      "level": 0
    },
    {
      "x": 2,
      "y": 4,
      "z": 0,
      "name": "Empty",
      "level": 0
    },
    {
      "x": 2,
      "y": 0,
      "z": 1,
      "name": "Empty",
      "level": 0
    },
    {
      "x": 2,
      "y": 1,
      "z": 1,
      "name": "Empty",
      "level": 0
    },
    {
      "x": 2,
      "y": 2,
      "z": 1,
      "name": "Empty",
      "level": 0
    },
    {
      "x": 2,
      "y": 3,
      "z": 1,
      "name": "Empty",
      "level": 0
    },
    {
      "x": 2,
      "y": 4,
      "z": 1,
      "name": "Empty",
      "level": 0
    },
    {
      "x": 2,
      "y": 5,
      "z": 1,
      "name": "Empty",
      "level": 0
    },
    {
      "x": 2,
      "y": 0,
      "z": 2,
      "name": "Empty",
      "level": 0
    },
    {
      "x": 2,
      "y": 1,
      "z": 2,
      "name": "Empty",
      "level": 0
    },
    {
      "x": 2,
      "y": 2,
      "z": 2,
      "name": "Empty",
      "level": 0
    },
    {
      "x": 2,
      "y": 3,
      "z": 2,
      "name": "Empty",
      "level": 0
    },
    {
      "x": 2,
      "y": 4,
      "z": 2,
      "name": "Empty",
      "level": 0
    },
    {
      "x": 2,
      "y": 5,
      "z": 2,
      "name": "Empty",
      "level": 0
    },
    {
      "x": 3,
      "y": 0,
      "z": -1,
      "name": "Empty",
      "level": 0
    },
    {
      "x": 3,
      "y": 1,
      "z": -1,
      "name": "Empty",
      "level": 0
    },
    {
      "x": 3,
      "y": 2,
      "z": -1,
      "name": "Empty",
      "level": 0
    },
    {
      "x": 3,
      "y": 3,
      "z": -1,
      "name": "Empty",
      "level": 0
    },
    {
      "x": 3,
      "y": 0,
      "z": 0,
      "name": "Empty",
      "level": 0
    },
    {
      "x": 3,
      "y": 1,
      "z": 0,
      "name": "Empty",
      "level": 0
    },
    {
      "x": 3,
      "y": 2,
      "z": 0,
      "name": "Empty",
      "level": 0
    },
    {
      "x": 3,
      "y": 3,
      "z": 0,
      "name": "Empty",
      "level": 0
    },
    {
      "x": 3,
      "y": 0,
      "z": 1,
      "name": "Empty",
      "level": 0
    },
    {
      "x": 3,
      "y": 1,
      "z": 1,
      "name": "Empty",
      "level": 0
    },
    {
      "x": 3,
      "y": 2,
      "z": 1,
      "name": "Empty",
      "level": 0
    },
    {
      "x": 3,
      "y": 3,
      "z": 1,
      "name": "Empty",
      "level": 0
    }
  ]
}