{
  "version": 8,
  "blockIdVersion": 11,
  "anchorX": 0,
  "anchorY": 0,
  "anchorZ": 0,
  "blocks": [
    {
      "x": -11,
      "y": 1,
      "z": -8,
      "name": "Rock_Sandstone_Red",
      "rotation": 2
    },
    {
      "x": -11,
      "y": 1,
      "z": -7,
      "name": "Rock_Sandstone_Red",
      "rotation": 2
    },
    {
      "x": -11,
      "y": 1,
      "z": -6,
      "name": "Rock_Sandstone_Red",
      "rotation": 2
    },
    {
      "x": -11,
      "y": 1,
      "z": -5,
      "name": "Rock_Sandstone_Red",
      "rotation": 2
    },
    {
      "x": -11,
      "y": 1,
      "z": 5,
      "name": "Rock_Sandstone_Red",
      "rotation": 2
    },
    {
      "x": -11,
      "y": 1,
      "z": 6,
      "name": "Rock_Sandstone_Red",
      "rotation": 2
    },
    {
      "x": -10,
      "y": 0,
      "z": -9,
      "name": "Rock_Sandstone_Red",
      "rotation": 2
    },
    {
      "x": -10,
      "y": 1,
      "z": -9,
      "name": "Rock_Sandstone_Red",
      "rotation": 2
    },
    {
      "x": -10,
      "y": 0,
      "z": -8,
      "name": "Rock_Sandstone_Red",
      "rotation": 2
    },
    {
      "x": -10,
      "y": 1,
      "z": -8,
      "name": "Rock_Sandstone_Red",
      "rotation": 2
    },
    {
      "x": -10,
      "y": 0,
      "z": -7,
      "name": "Rock_Sandstone_Red",
      "rotation": 2
    },
    {
      "x": -10,
      "y": 1,
      "z": -7,
      "name": "Rock_Sandstone_Red",
      "rotation": 2
    },
    {
      "x": -10,
      "y": 2,
      "z": -7,
      "name": "Rock_Sandstone_Red",
      "rotation": 2
    },
    {
      "x": -10,
      "y": 0,
      "z": -6,
      "name": "Rock_Sandstone_Red",
      "rotation": 2
    },
    {
      "x": -10,
      "y": 1,
      "z": -6,
      "name": "Rock_Sandstone_Red",
      "rotation": 2
    },
    {
      "x": -10,
      "y": 2,
      "z": -6,
      "name": "Rock_Sandstone_Red",
      "rotation": 2
    },
    {
      "x": -10,
      "y": 0,
      "z": -5,
      "name": "Rock_Sandstone_Red",
      "rotation": 2
    },
    {
      "x": -10,
      "y": 1,
      "z": -5,
      "name": "Rock_Sandstone_Red",
      "rotation": 2
    },
    {
      "x": -10,
      "y": 2,
      "z": -5,
      "name": "Rock_Sandstone_Red",
      "rotation": 2
    },
    {
      "x": -10,
      "y": 1,
      "z": -4,
      "name": "Rock_Sandstone_Red",
      "rotation": 2
    },
    {
      "x": -10,
      "y": 1,
      "z": 4,
      "name": "Rock_Sandstone_Red",
      "rotation": 2
    },
    {
      "x": -10,
      "y": 2,
      "z": 4,
      "name": "Rock_Sandstone_Red",
      "rotation": 2
    },
    {
      "x": -10,
      "y": 0,
      "z": 5,
      "name": "Rock_Sandstone_Red",
      "rotation": 2
    },
    {
      "x": -10,
      "y": 1,
      "z": 5,
      "name": "Rock_Sandstone_Red",
      "rotation": 2
    },
    {
      "x": -10,
      "y": 2,
      "z": 5,
      "name": "Rock_Sandstone_Red",
      "rotation": 2
    },
    {
      "x": -10,
      "y": 0,
      "z": 6,
      "name": "Rock_Sandstone_Red",
      "rotation": 2
    },
    {
      "x": -10,
      "y": 1,
      "z": 6,
      "name": "Rock_Sandstone_Red",
      "rotation": 2
    },
    {
      "x": -10,
      "y": 0,
      "z": 7,
      "name": "Rock_Sandstone_Red",
      "rotation": 2
    },
    {
      "x": -10,
      "y": 1,
      "z": 7,
      "name": "Rock_Sandstone_Red",
      "rotation": 2
    },
    {
      "x": -10,
      "y": 1,
      "z": 8,
      "name": "Rock_Sandstone_Red",
      "rotation": 2
    },
    {
      "x": -9,
      "y": 0,
      "z": -9,
      "name": "Rock_Sandstone_Red",
      "rotation": 2
    },
    {
      "x": -9,
      "y": 1,
      "z": -9,
      "name": "Rock_Sandstone_Red",
      "rotation": 2
    },
    {
      "x": -9,
      "y": 0,
      "z": -8,
      "name": "Rock_Sandstone_Red",
      "rotation": 2
    },
    {
      "x": -9,
      "y": 1,
      "z": -8,
      "name": "Rock_Sandstone_Red",
      "rotation": 2
    },
    {
      "x": -9,
      "y": 2,
      "z": -8,
      "name": "Rock_Sandstone_Red",
      "rotation": 2
    },
    {
      "x": -9,
      "y": 0,
      "z": -7,
      "name": "Rock_Sandstone_Red",
      "rotation": 2
    },
    {
      "x": -9,
      "y": 1,
      "z": -7,
      "name": "Rock_Sandstone_Red",
      "rotation": 2
    },
    {
      "x": -9,
      "y": 2,
      "z": -7,
      "name": "Rock_Sandstone_Red",
      "rotation": 2
    },
    {
      "x": -9,
      "y": 0,
      "z": -6,
      "name": "Rock_Sandstone_Red",
      "rotation": 2
    },
    {
      "x": -9,
      "y": 1,
      "z": -6,
      "name": "Rock_Sandstone_Red",
      "rotation": 2
    },
    {
      "x": -9,
      "y": 2,
      "z": -6,
      "name": "Rock_Sandstone_Red",
      "rotation": 2
    },
    {
      "x": -9,
      "y": 0,
      "z": -5,
      "name": "Rock_Sandstone_Red",
      "rotation": 2
    },
    {
      "x": -9,
      "y": 1,
      "z": -5,
      "name": "Rock_Sandstone_Red",
      "rotation": 2
    },
    {
      "x": -9,
      "y": 2,
      "z": -5,
      "name": "Rock_Sandstone_Red",
      "rotation": 2
    },
    {
      "x": -9,
      "y": 3,
      "z": -5,
      "name": "Rubble_Sandstone_Red"
    },
    {
      "x": -9,
      "y": 0,
      "z": -4,
      "name": "Rock_Sandstone_Red",
      "rotation": 2
    },
    {
      "x": -9,
      "y": 1,
      "z": -4,
      "name": "Rock_Sandstone_Red",
      "rotation": 2
    },
    {
      "x": -9,
      "y": 2,
      "z": -4,
      "name": "Rock_Sandstone_Red",
      "rotation": 2
    },
    {
      "x": -9,
      "y": 3,
      "z": -4,
      "name": "Plant_Crop_Mushroom_Glowing_Red"
    },
    {
      "x": -9,
      "y": 0,
      "z": -3,
      "name": "Rock_Sandstone_Red",
      "rotation": 2
    },
    {
      "x": -9,
      "y": 1,
      "z": -3,
      "name": "Rock_Sandstone_Red",
      "rotation": 2
    },
    {
      "x": -9,
      "y": 1,
      "z": -2,
      "name": "Rock_Sandstone_Red",
      "rotation": 2
    },
    {
      "x": -9,
      "y": 1,
      "z": 2,
      "name": "Rock_Sandstone_Red",
      "rotation": 2
    },
    {
      "x": -9,
      "y": 2,
      "z": 2,
      "name": "Rock_Sandstone_Red",
      "rotation": 2
    },
    {
      "x": -9,
      "y": 0,
      "z": 3,
      "name": "Rock_Sandstone_Red",
      "rotation": 2
    },
    {
      "x": -9,
      "y": 1,
      "z": 3,
      "name": "Rock_Sandstone_Red",
      "rotation": 2
    },
    {
      "x": -9,
      "y": 2,
      "z": 3,
      "name": "Rock_Sandstone_Red",
      "rotation": 2
    },
    {
      "x": -9,
      "y": 0,
      "z": 4,
      "name": "Rock_Sandstone_Red",
      "rotation": 2
    },
    {
      "x": -9,
      "y": 1,
      "z": 4,
      "name": "Rock_Sandstone_Red",
      "rotation": 2
    },
    {
      "x": -9,
      "y": 2,
      "z": 4,
      "name": "Rock_Sandstone_Red",
      "rotation": 2
    },
    {
      "x": -9,
      "y": 0,
      "z": 5,
      "name": "Rock_Sandstone_Red",
      "rotation": 2
    },
    {
      "x": -9,
      "y": 1,
      "z": 5,
      "name": "Rock_Sandstone_Red",
      "rotation": 2
    },
    {
      "x": -9,
      "y": 2,
      "z": 5,
      "name": "Rock_Sandstone_Red",
      "rotation": 2
    },
    {
      "x": -9,
      "y": 0,
      "z": 6,
      "name": "Rock_Sandstone_Red",
      "rotation": 2
    },
    {
      "x": -9,
      "y": 1,
      "z": 6,
      "name": "Rock_Sandstone_Red",
      "rotation": 2
    },
    {
      "x": -9,
      "y": 2,
      "z": 6,
      "name": "Rock_Sandstone_Red",
      "rotation": 2
    },
    {
      "x": -9,
      "y": 0,
      "z": 7,
      "name": "Rock_Sandstone_Red",
      "rotation": 2
    },
    {
      "x": -9,
      "y": 1,
      "z": 7,
      "name": "Rock_Sandstone_Red",
      "rotation": 2
    },
    {
      "x": -9,
      "y": 2,
      "z": 7,
      "name": "Rock_Sandstone_Red",
      "rotation": 2
    },
    {
      "x": -9,
      "y": 0,
      "z": 8,
      "name": "Rock_Sandstone_Red",
      "rotation": 2
    },
    {
      "x": -9,
      "y": 1,
      "z": 8,
      "name": "Rock_Sandstone_Red",
      "rotation": 2
    },
    {
      "x": -9,
      "y": 0,
      "z": 9,
      "name": "Rock_Sandstone_Red",
      "rotation": 2
    },
    {
      "x": -9,
      "y": 1,
      "z": 9,
      "name": "Rock_Sandstone_Red",
      "rotation": 2
    },
    {
      "x": -9,
      "y": 1,
      "z": 10,
      "name": "Rock_Sandstone_Red",
      "rotation": 2
    },
    {
      "x": -9,
      "y": 2,
      "z": 10,
      "name": "Rubble_Sandstone_Red"
    },
    {
      "x": -8,
      "y": 1,
      "z": -10,
      "name": "Rock_Sandstone_Red",
      "rotation": 2
    },
    {
      "x": -8,
      "y": 0,
      "z": -9,
      "name": "Rock_Sandstone_Red",
      "rotation": 2
    },
    {
      "x": -8,
      "y": 1,
      "z": -9,
      "name": "Rock_Sandstone_Red",
      "rotation": 2
    },
    {
      "x": -8,
      "y": 0,
      "z": -8,
      "name": "Rock_Sandstone_Red",
      "rotation": 2
    },
    {
      "x": -8,
      "y": 1,
      "z": -8,
      "name": "Rock_Sandstone_Red",
      "rotation": 2
    },
    {
      "x": -8,
      "y": 2,
      "z": -8,
      "name": "Rock_Sandstone_Red",
      "rotation": 2
    },
    {
      "x": -8,
      "y": 0,
      "z": -7,
      "name": "Rock_Sandstone_Red",
      "rotation": 2
    },
    {
      "x": -8,
      "y": 1,
      "z": -7,
      "name": "Rock_Sandstone_Red",
      "rotation": 2
    },
    {
      "x": -8,
      "y": 2,
      "z": -7,
      "name": "Rock_Sandstone_Red",
      "rotation": 2
    },
    {
      "x": -8,
      "y": 0,
      "z": -6,
      "name": "Rock_Sandstone_Red",
      "rotation": 2
    },
    {
      "x": -8,
      "y": 1,
      "z": -6,
      "name": "Rock_Sandstone_Red",
      "rotation": 2
    },
    {
      "x": -8,
      "y": 2,
      "z": -6,
      "name": "Rock_Sandstone_Red",
      "rotation": 2
    },
    {
      "x": -8,
      "y": 0,
      "z": -5,
      "name": "Rock_Sandstone_Red",
      "rotation": 2
    },
    {
      "x": -8,
      "y": 1,
      "z": -5,
      "name": "Rock_Sandstone_Red",
      "rotation": 2
    },
    {
      "x": -8,
      "y": 2,
      "z": -5,
      "name": "Rock_Sandstone_Red",
      "rotation": 2
    },
    {
      "x": -8,
      "y": 0,
      "z": -4,
      "name": "Rock_Sandstone_Red",
      "rotation": 2
    },
    {
      "x": -8,
      "y": 1,
      "z": -4,
      "name": "Rock_Sandstone_Red",
      "rotation": 2
    },
    {
      "x": -8,
      "y": 2,
      "z": -4,
      "name": "Rock_Sandstone_Red",
      "rotation": 2
    },
    {
      "x": -8,
      "y": 3,
      "z": -4,
      "name": "Rubble_Sandstone_Red"
    },
    {
      "x": -8,
      "y": 0,
      "z": -3,
      "name": "Rock_Sandstone_Red",
      "rotation": 2
    },
    {
      "x": -8,
      "y": 1,
      "z": -3,
      "name": "Rock_Sandstone_Red",
      "rotation": 2
    },
    {
      "x": -8,
      "y": 2,
      "z": -3,
      "name": "Rock_Sandstone_Red",
      "rotation": 2
    },
    {
      "x": -8,
      "y": 0,
      "z": -2,
      "name": "Rock_Sandstone_Red",
      "rotation": 2
    },
    {
      "x": -8,
      "y": 1,
      "z": -2,
      "name": "Rock_Sandstone_Red",
      "rotation": 2
    },
    {
      "x": -8,
      "y": 2,
      "z": -2,
      "name": "Rock_Sandstone_Red",
      "rotation": 2
    },
    {
      "x": -8,
      "y": 0,
      "z": -1,
      "name": "Rock_Sandstone_Red",
      "rotation": 2
    },
    {
      "x": -8,
      "y": 1,
      "z": -1,
      "name": "Rock_Sandstone_Red",
      "rotation": 2
    },
    {
      "x": -8,
      "y": 0,
      "z": 0,
      "name": "Rock_Sandstone_Red",
      "rotation": 2
    },
    {
      "x": -8,
      "y": 1,
      "z": 0,
      "name": "Rock_Sandstone_Red",
      "rotation": 2
    },
    {
      "x": -8,
      "y": 0,
      "z": 1,
      "name": "Rock_Sandstone_Red",
      "rotation": 2
    },
    {
      "x": -8,
      "y": 1,
      "z": 1,
      "name": "Rock_Sandstone_Red",
      "rotation": 2
    },
    {
      "x": -8,
      "y": 2,
      "z": 1,
      "name": "Rock_Sandstone_Red",
      "rotation": 2
    },
    {
      "x": -8,
      "y": 0,
      "z": 2,
      "name": "Rock_Sandstone_Red",
      "rotation": 2
    },
    {
      "x": -8,
      "y": 1,
      "z": 2,
      "name": "Rock_Sandstone_Red",
      "rotation": 2
    },
    {
      "x": -8,
      "y": 2,
      "z": 2,
      "name": "Rock_Sandstone_Red",
      "rotation": 2
    },
    {
      "x": -8,
      "y": 3,
      "z": 2,
      "name": "Plant_Crop_Mushroom_Glowing_Red"
    },
    {
      "x": -8,
      "y": 0,
      "z": 3,
      "name": "Rock_Sandstone_Red",
      "rotation": 2
    },
    {
      "x": -8,
      "y": 1,
      "z": 3,
      "name": "Rock_Sandstone_Red",
      "rotation": 2
    },
    {
      "x": -8,
      "y": 2,
      "z": 3,
      "name": "Rock_Sandstone_Red",
      "rotation": 2
    },
    {
      "x": -8,
      "y": 0,
      "z": 4,
      "name": "Rock_Sandstone_Red",
      "rotation": 2
    },
    {
      "x": -8,
      "y": 1,
      "z": 4,
      "name": "Rock_Sandstone_Red",
      "rotation": 2
    },
    {
      "x": -8,
      "y": 2,
      "z": 4,
      "name": "Rock_Sandstone_Red",
      "rotation": 2
    },
    {
      "x": -8,
      "y": 0,
      "z": 5,
      "name": "Rock_Sandstone_Red",
      "rotation": 2
    },
    {
      "x": -8,
      "y": 1,
      "z": 5,
      "name": "Rock_Sandstone_Red",
      "rotation": 2
    },
    {
      "x": -8,
      "y": 2,
      "z": 5,
      "name": "Rock_Sandstone_Red",
      "rotation": 2
    },
    {
      "x": -8,
      "y": 0,
      "z": 6,
      "name": "Rock_Sandstone_Red",
      "rotation": 2
    },
    {
      "x": -8,
      "y": 1,
      "z": 6,
      "name": "Rock_Sandstone_Red",
      "rotation": 2
    },
    {
      "x": -8,
      "y": 2,
      "z": 6,
      "name": "Rock_Sandstone_Red",
      "rotation": 2
    },
    {
      "x": -8,
      "y": 0,
      "z": 7,
      "name": "Rock_Sandstone_Red",
      "rotation": 2
    },
    {
      "x": -8,
      "y": 1,
      "z": 7,
      "name": "Rock_Sandstone_Red",
      "rotation": 2
    },
    {
      "x": -8,
      "y": 2,
      "z": 7,
      "name": "Rock_Sandstone_Red",
      "rotation": 2
    },
    {
      "x": -8,
      "y": 0,
      "z": 8,
      "name": "Rock_Sandstone_Red",
      "rotation": 2
    },
    {
      "x": -8,
      "y": 1,
      "z": 8,
      "name": "Rock_Sandstone_Red",
      "rotation": 2
    },
    {
      "x": -8,
      "y": 2,
      "z": 8,
      "name": "Rock_Sandstone_Red",
      "rotation": 2
    },
    {
      "x": -8,
      "y": 0,
      "z": 9,
      "name": "Rock_Sandstone_Red",
      "rotation": 2
    },
    {
      "x": -8,
      "y": 1,
      "z": 9,
      "name": "Rock_Sandstone_Red",
      "rotation": 2
    },
    {
      "x": -8,
      "y": 1,
      "z": 10,
      "name": "Rock_Sandstone_Red",
      "rotation": 2
    },
    {
      "x": -7,
      "y": 0,
      "z": -10,
      "name": "Rock_Sandstone_Red",
      "rotation": 2
    },
    {
      "x": -7,
      "y": 1,
      "z": -10,
      "name": "Rock_Sandstone_Red",
      "rotation": 2
    },
    {
      "x": -7,
      "y": 0,
      "z": -9,
      "name": "Rock_Sandstone_Red",
      "rotation": 2
    },
    {
      "x": -7,
      "y": 1,
      "z": -9,
      "name": "Rock_Sandstone_Red",
      "rotation": 2
    },
    {
      "x": -7,
      "y": 2,
      "z": -9,
      "name": "Rock_Sandstone_Red",
      "rotation": 2
    },
    {
      "x": -7,
      "y": 0,
      "z": -8,
      "name": "Rock_Sandstone_Red",
      "rotation": 2
    },
    {
      "x": -7,
      "y": 1,
      "z": -8,
      "name": "Rock_Sandstone_Red",
      "rotation": 2
    },
    {
      "x": -7,
      "y": 2,
      "z": -8,
      "name": "Rock_Sandstone_Red",
      "rotation": 2
    },
    {
      "x": -7,
      "y": 0,
      "z": -7,
      "name": "Rock_Sandstone_Red",
      "rotation": 2
    },
    {
      "x": -7,
      "y": 1,
      "z": -7,
      "name": "Rock_Sandstone_Red",
      "rotation": 2
    },
    {
      "x": -7,
      "y": 2,
      "z": -7,
      "name": "Rock_Sandstone_Red",
      "rotation": 2
    },
    {
      "x": -7,
      "y": 0,
      "z": -6,
      "name": "Rock_Sandstone_Red",
      "rotation": 2
    },
    {
      "x": -7,
      "y": 1,
      "z": -6,
      "name": "Rock_Sandstone_Red",
      "rotation": 2
    },
    {
      "x": -7,
      "y": 2,
      "z": -6,
      "name": "Rock_Sandstone_Red",
      "rotation": 2
    },
    {
      "x": -7,
      "y": 0,
      "z": -5,
      "name": "Rock_Sandstone_Red",
      "rotation": 2
    },
    {
      "x": -7,
      "y": 1,
      "z": -5,
      "name": "Rock_Sandstone_Red",
      "rotation": 2
    },
    {
      "x": -7,
      "y": 2,
      "z": -5,
      "name": "Rock_Sandstone_Red",
      "rotation": 2
    },
    {
      "x": -7,
      "y": 0,
      "z": -4,
      "name": "Rock_Sandstone_Red",
      "rotation": 2
    },
    {
      "x": -7,
      "y": 1,
      "z": -4,
      "name": "Rock_Sandstone_Red",
      "rotation": 2
    },
    {
      "x": -7,
      "y": 2,
      "z": -4,
      "name": "Rock_Sandstone_Red",
      "rotation": 2
    },
    {
      "x": -7,
      "y": 0,
      "z": -3,
      "name": "Rock_Sandstone_Red",
      "rotation": 2
    },
    {
      "x": -7,
      "y": 1,
      "z": -3,
      "name": "Rock_Sandstone_Red",
      "rotation": 2
    },
    {
      "x": -7,
      "y": 2,
      "z": -3,
      "name": "Rock_Sandstone_Red",
      "rotation": 2
    },
    {
      "x": -7,
      "y": 0,
      "z": -2,
      "name": "Rock_Sandstone_Red",
      "rotation": 2
    },
    {
      "x": -7,
      "y": 1,
      "z": -2,
      "name": "Rock_Sandstone_Red",
      "rotation": 2
    },
    {
      "x": -7,
      "y": 2,
      "z": -2,
      "name": "Rock_Sandstone_Red",
      "rotation": 2
    },
    {
      "x": -7,
      "y": 0,
      "z": -1,
      "name": "Rock_Sandstone_Red",
      "rotation": 2
    },
    {
      "x": -7,
      "y": 1,
      "z": -1,
      "name": "Rock_Sandstone_Red",
      "rotation": 2
    },
    {
      "x": -7,
      "y": 2,
      "z": -1,
      "name": "Rock_Sandstone_Red",
      "rotation": 2
    },
    {
      "x": -7,
      "y": 3,
      "z": -1,
      "name": "Rubble_Sandstone_Red"
    },
    {
      "x": -7,
      "y": 0,
      "z": 0,
      "name": "Rock_Sandstone_Red",
      "rotation": 2
    },
    {
      "x": -7,
      "y": 1,
      "z": 0,
      "name": "Rock_Sandstone_Red",
      "rotation": 2
    },
    {
      "x": -7,
      "y": 2,
      "z": 0,
      "name": "Rock_Sandstone_Red",
      "rotation": 2
    },
    {
      "x": -7,
      "y": 0,
      "z": 1,
      "name": "Rock_Sandstone_Red",
      "rotation": 2
    },
    {
      "x": -7,
      "y": 1,
      "z": 1,
      "name": "Rock_Sandstone_Red",
      "rotation": 2
    },
    {
      "x": -7,
      "y": 2,
      "z": 1,
      "name": "Rock_Sandstone_Red",
      "rotation": 2
    },
    {
      "x": -7,
      "y": 0,
      "z": 2,
      "name": "Rock_Sandstone_Red",
      "rotation": 2
    },
    {
      "x": -7,
      "y": 1,
      "z": 2,
      "name": "Rock_Sandstone_Red",
      "rotation": 2
    },
    {
      "x": -7,
      "y": 2,
      "z": 2,
      "name": "Rock_Sandstone_Red",
      "rotation": 2
    },
    {
      "x": -7,
      "y": 0,
      "z": 3,
      "name": "Rock_Sandstone_Red",
      "rotation": 2
    },
    {
      "x": -7,
      "y": 1,
      "z": 3,
      "name": "Rock_Sandstone_Red",
      "rotation": 2
    },
    {
      "x": -7,
      "y": 2,
      "z": 3,
      "name": "Rock_Sandstone_Red",
      "rotation": 2
    },
    {
      "x": -7,
      "y": 3,
      "z": 3,
      "name": "Rubble_Sandstone_Red"
    },
    {
      "x": -7,
      "y": 0,
      "z": 4,
      "name": "Rock_Sandstone_Red",
      "rotation": 2
    },
    {
      "x": -7,
      "y": 1,
      "z": 4,
      "name": "Rock_Sandstone_Red",
      "rotation": 2
    },
    {
      "x": -7,
      "y": 2,
      "z": 4,
      "name": "Rock_Sandstone_Red",
      "rotation": 2
    },
    {
      "x": -7,
      "y": 0,
      "z": 5,
      "name": "Rock_Sandstone_Red",
      "rotation": 2
    },
    {
      "x": -7,
      "y": 1,
      "z": 5,
      "name": "Rock_Sandstone_Red",
      "rotation": 2
    },
    {
      "x": -7,
      "y": 2,
      "z": 5,
      "name": "Rock_Sandstone_Red",
      "rotation": 2
    },
    {
      "x": -7,
      "y": 0,
      "z": 6,
      "name": "Rock_Sandstone_Red",
      "rotation": 2
    },
    {
      "x": -7,
      "y": 1,
      "z": 6,
      "name": "Rock_Sandstone_Red",
      "rotation": 2
    },
    {
      "x": -7,
      "y": 2,
      "z": 6,
      "name": "Rock_Sandstone_Red",
      "rotation": 2
    },
    {
      "x": -7,
      "y": 0,
      "z": 7,
      "name": "Rock_Sandstone_Red",
      "rotation": 2
    },
    {
      "x": -7,
      "y": 1,
      "z": 7,
      "name": "Rock_Sandstone_Red",
      "rotation": 2
    },
    {
      "x": -7,
      "y": 2,
      "z": 7,
      "name": "Rock_Sandstone_Red",
      "rotation": 2
    },
    {
      "x": -7,
      "y": 0,
      "z": 8,
      "name": "Rock_Sandstone_Red",
      "rotation": 2
    },
    {
      "x": -7,
      "y": 1,
      "z": 8,
      "name": "Rock_Sandstone_Red",
      "rotation": 2
    },
    {
      "x": -7,
      "y": 2,
      "z": 8,
      "name": "Rock_Sandstone_Red",
      "rotation": 2
    },
    {
      "x": -7,
      "y": 0,
      "z": 9,
      "name": "Rock_Sandstone_Red",
      "rotation": 2
    },
    {
      "x": -7,
      "y": 1,
      "z": 9,
      "name": "Rock_Sandstone_Red",
      "rotation": 2
    },
    {
      "x": -7,
      "y": 2,
      "z": 9,
      "name": "Rock_Sandstone_Red",
      "rotation": 2
    },
    {
      "x": -7,
      "y": 1,
      "z": 10,
      "name": "Rock_Sandstone_Red",
      "rotation": 2
    },
    {
      "x": -6,
      "y": 0,
      "z": -10,
      "name": "Rock_Sandstone_Red",
      "rotation": 2
    },
    {
      "x": -6,
      "y": 1,
      "z": -10,
      "name": "Rock_Sandstone_Red",
      "rotation": 2
    },
    {
      "x": -6,
      "y": 0,
      "z": -9,
      "name": "Rock_Sandstone_Red",
      "rotation": 2
    },
    {
      "x": -6,
      "y": 1,
      "z": -9,
      "name": "Rock_Sandstone_Red",
      "rotation": 2
    },
    {
      "x": -6,
      "y": 2,
      "z": -9,
      "name": "Rock_Sandstone_Red",
      "rotation": 2
    },
    {
      "x": -6,
      "y": 0,
      "z": -8,
      "name": "Rock_Sandstone_Red",
      "rotation": 2
    },
    {
      "x": -6,
      "y": 1,
      "z": -8,
      "name": "Rock_Sandstone_Red",
      "rotation": 2
    },
    {
      "x": -6,
      "y": 2,
      "z": -8,
      "name": "Rock_Sandstone_Red",
      "rotation": 2
    },
    {
      "x": -6,
      "y": 0,
      "z": -7,
      "name": "Rock_Sandstone_Red",
      "rotation": 2
    },
    {
      "x": -6,
      "y": 1,
      "z": -7,
      "name": "Rock_Sandstone_Red",
      "rotation": 2
    },
    {
      "x": -6,
      "y": 2,
      "z": -7,
      "name": "Rock_Sandstone_Red",
      "rotation": 2
    },
    {
      "x": -6,
      "y": 0,
      "z": -6,
      "name": "Rock_Sandstone_Red",
      "rotation": 2
    },
    {
      "x": -6,
      "y": 1,
      "z": -6,
      "name": "Rock_Sandstone_Red",
      "rotation": 2
    },
    {
      "x": -6,
      "y": 2,
      "z": -6,
      "name": "Rock_Sandstone_Red",
      "rotation": 2
    },
    {
      "x": -6,
      "y": 3,
      "z": -6,
      "name": "Rock_Sandstone_Red_Brick_Smooth_Half"
    },
    {
      "x": -6,
      "y": 0,
      "z": -5,
      "name": "Rock_Sandstone_Red",
      "rotation": 2
    },
    {
      "x": -6,
      "y": 1,
      "z": -5,
      "name": "Rock_Sandstone_Red",
      "rotation": 2
    },
    {
      "x": -6,
      "y": 2,
      "z": -5,
      "name": "Rock_Sandstone_Red",
      "rotation": 2
    },
    {
      "x": -6,
      "y": 3,
      "z": -5,
      "name": "Rock_Sandstone_Red_Brick_Smooth_Half"
    },
    {
      "x": -6,
      "y": 4,
      "z": -5,
      "name": "Plant_Crop_Mushroom_Shelve_Brown"
    },
    {
      "x": -6,
      "y": 0,
      "z": -4,
      "name": "Rock_Sandstone_Red",
      "rotation": 2
    },
    {
      "x": -6,
      "y": 1,
      "z": -4,
      "name": "Rock_Sandstone_Red",
      "rotation": 2
    },
    {
      "x": -6,
      "y": 2,
      "z": -4,
      "name": "Rock_Sandstone_Red",
      "rotation": 2
    },
    {
      "x": -6,
      "y": 3,
      "z": -4,
      "name": "Rock_Sandstone_Red_Brick_Smooth_Half"
    },
    {
      "x": -6,
      "y": 0,
      "z": -3,
      "name": "Rock_Sandstone_Red",
      "rotation": 2
    },
    {
      "x": -6,
      "y": 1,
      "z": -3,
      "name": "Rock_Sandstone_Red",
      "rotation": 2
    },
    {
      "x": -6,
      "y": 2,
      "z": -3,
      "name": "Rock_Sandstone_Red",
      "rotation": 2
    },
    {
      "x": -6,
      "y": 3,
      "z": -3,
      "name": "Rock_Sandstone_Red_Brick_Smooth_Half"
    },
    {
      "x": -6,
      "y": 0,
      "z": -2,
      "name": "Rock_Sandstone_Red",
      "rotation": 2
    },
    {
      "x": -6,
      "y": 1,
      "z": -2,
      "name": "Rock_Sandstone_Red",
      "rotation": 2
    },
    {
      "x": -6,
      "y": 2,
      "z": -2,
      "name": "Rock_Sandstone_Red",
      "rotation": 2
    },
    {
      "x": -6,
      "y": 3,
      "z": -2,
      "name": "Rock_Sandstone_Red_Brick_Smooth_Half"
    },
    {
      "x": -6,
      "y": 0,
      "z": -1,
      "name": "Rock_Sandstone_Red",
      "rotation": 2
    },
    {
      "x": -6,
      "y": 1,
      "z": -1,
      "name": "Rock_Sandstone_Red",
      "rotation": 2
    },
    {
      "x": -6,
      "y": 2,
      "z": -1,
      "name": "Rock_Sandstone_Red",
      "rotation": 2
    },
    {
      "x": -6,
      "y": 3,
      "z": -1,
      "name": "Rock_Sandstone_Red_Brick_Smooth_Half"
    },
    {
      "x": -6,
      "y": 0,
      "z": 0,
      "name": "Rock_Sandstone_Red",
      "rotation": 2
    },
    {
      "x": -6,
      "y": 1,
      "z": 0,
      "name": "Rock_Sandstone_Red",
      "rotation": 2
    },
    {
      "x": -6,
      "y": 2,
      "z": 0,
      "name": "Rock_Sandstone_Red",
      "rotation": 2
    },
    {
      "x": -6,
      "y": 3,
      "z": 0,
      "name": "Rock_Sandstone_Red_Brick_Smooth_Half"
    },
    {
      "x": -6,
      "y": 0,
      "z": 1,
      "name": "Rock_Sandstone_Red",
      "rotation": 2
    },
    {
      "x": -6,
      "y": 1,
      "z": 1,
      "name": "Rock_Sandstone_Red",
      "rotation": 2
    },
    {
      "x": -6,
      "y": 2,
      "z": 1,
      "name": "Rock_Sandstone_Red",
      "rotation": 2
    },
    {
      "x": -6,
      "y": 3,
      "z": 1,
      "name": "Rock_Sandstone_Red_Brick_Smooth_Half"
    },
    {
      "x": -6,
      "y": 0,
      "z": 2,
      "name": "Rock_Sandstone_Red",
      "rotation": 2
    },
    {
      "x": -6,
      "y": 1,
      "z": 2,
      "name": "Rock_Sandstone_Red",
      "rotation": 2
    },
    {
      "x": -6,
      "y": 2,
      "z": 2,
      "name": "Rock_Sandstone_Red",
      "rotation": 2
    },
    {
      "x": -6,
      "y": 3,
      "z": 2,
      "name": "Rock_Sandstone_Red_Brick_Smooth_Half"
    },
    {
      "x": -6,
      "y": 0,
      "z": 3,
      "name": "Rock_Sandstone_Red",
      "rotation": 2
    },
    {
      "x": -6,
      "y": 1,
      "z": 3,
      "name": "Rock_Sandstone_Red",
      "rotation": 2
    },
    {
      "x": -6,
      "y": 2,
      "z": 3,
      "name": "Rock_Sandstone_Red",
      "rotation": 2
    },
    {
      "x": -6,
      "y": 3,
      "z": 3,
      "name": "Rock_Sandstone_Red_Brick_Smooth_Half"
    },
    {
      "x": -6,
      "y": 0,
      "z": 4,
      "name": "Rock_Sandstone_Red",
      "rotation": 2
    },
    {
      "x": -6,
      "y": 1,
      "z": 4,
      "name": "Rock_Sandstone_Red",
      "rotation": 2
    },
    {
      "x": -6,
      "y": 2,
      "z": 4,
      "name": "Rock_Sandstone_Red",
      "rotation": 2
    },
    {
      "x": -6,
      "y": 3,
      "z": 4,
      "name": "Rock_Sandstone_Red_Brick_Smooth_Half"
    },
    {
      "x": -6,
      "y": 0,
      "z": 5,
      "name": "Rock_Sandstone_Red",
      "rotation": 2
    },
    {
      "x": -6,
      "y": 1,
      "z": 5,
      "name": "Rock_Sandstone_Red",
      "rotation": 2
    },
    {
      "x": -6,
      "y": 2,
      "z": 5,
      "name": "Rock_Sandstone_Red",
      "rotation": 2
    },
    {
      "x": -6,
      "y": 3,
      "z": 5,
      "name": "Rock_Sandstone_Red_Brick_Smooth_Half"
    },
    {
      "x": -6,
      "y": 0,
      "z": 6,
      "name": "Rock_Sandstone_Red",
      "rotation": 2
    },
    {
      "x": -6,
      "y": 1,
      "z": 6,
      "name": "Rock_Sandstone_Red",
      "rotation": 2
    },
    {
      "x": -6,
      "y": 2,
      "z": 6,
      "name": "Rock_Sandstone_Red",
      "rotation": 2
    },
    {
      "x": -6,
      "y": 3,
      "z": 6,
      "name": "Rubble_Sandstone_Red"
    },
    {
      "x": -6,
      "y": 0,
      "z": 7,
      "name": "Rock_Sandstone_Red",
      "rotation": 2
    },
    {
      "x": -6,
      "y": 1,
      "z": 7,
      "name": "Rock_Sandstone_Red",
      "rotation": 2
    },
    {
      "x": -6,
      "y": 2,
      "z": 7,
      "name": "Rock_Sandstone_Red",
      "rotation": 2
    },
    {
      "x": -6,
      "y": 0,
      "z": 8,
      "name": "Rock_Sandstone_Red",
      "rotation": 2
    },
    {
      "x": -6,
      "y": 1,
      "z": 8,
      "name": "Rock_Sandstone_Red",
      "rotation": 2
    },
    {
      "x": -6,
      "y": 2,
      "z": 8,
      "name": "Rock_Sandstone_Red",
      "rotation": 2
    },
    {
      "x": -6,
      "y": 0,
      "z": 9,
      "name": "Rock_Sandstone_Red",
      "rotation": 2
    },
    {
      "x": -6,
      "y": 1,
      "z": 9,
      "name": "Rock_Sandstone_Red",
      "rotation": 2
    },
    {
      "x": -6,
      "y": 2,
      "z": 9,
      "name": "Rock_Sandstone_Red",
      "rotation": 2
    },
    {
      "x": -6,
      "y": 3,
      "z": 9,
      "name": "Plant_Crop_Mushroom_Glowing_Orange"
    },
    {
      "x": -6,
      "y": 1,
      "z": 10,
      "name": "Rock_Sandstone_Red",
      "rotation": 2
    },
    {
      "x": -5,
      "y": 1,
      "z": -10,
      "name": "Rock_Sandstone_Red",
      "rotation": 2
    },
    {
      "x": -5,
      "y": 0,
      "z": -9,
      "name": "Rock_Sandstone_Red",
      "rotation": 2
    },
    {
      "x": -5,
      "y": 1,
      "z": -9,
      "name": "Rock_Sandstone_Red",
      "rotation": 2
    },
    {
      "x": -5,
      "y": 2,
      "z": -9,
      "name": "Rock_Sandstone_Red",
      "rotation": 2
    },
    {
      "x": -5,
      "y": 0,
      "z": -8,
      "name": "Rock_Sandstone_Red",
      "rotation": 2
    },
    {
      "x": -5,
      "y": 1,
      "z": -8,
      "name": "Rock_Sandstone_Red",
      "rotation": 2
    },
    {
      "x": -5,
      "y": 2,
      "z": -8,
      "name": "Rock_Sandstone_Red",
      "rotation": 2
    },
    {
      "x": -5,
      "y": 0,
      "z": -7,
      "name": "Rock_Sandstone_Red",
      "rotation": 2
    },
    {
      "x": -5,
      "y": 1,
      "z": -7,
      "name": "Rock_Sandstone_Red",
      "rotation": 2
    },
    {
      "x": -5,
      "y": 2,
      "z": -7,
      "name": "Rock_Sandstone_Red",
      "rotation": 2
    },
    {
      "x": -5,
      "y": 0,
      "z": -6,
      "name": "Rock_Sandstone_Red",
      "rotation": 2
    },
    {
      "x": -5,
      "y": 1,
      "z": -6,
      "name": "Rock_Sandstone_Red",
      "rotation": 2
    },
    {
      "x": -5,
      "y": 2,
      "z": -6,
      "name": "Rock_Sandstone_Red",
      "rotation": 2
    },
    {
      "x": -5,
      "y": 3,
      "z": -6,
      "name": "Rock_Sandstone_Red_Brick_Smooth_Half"
    },
    {
      "x": -5,
      "y": 0,
      "z": -5,
      "name": "Rock_Sandstone_Red",
      "rotation": 2
    },
    {
      "x": -5,
      "y": 1,
      "z": -5,
      "name": "Rock_Sandstone_Red",
      "rotation": 2
    },
    {
      "x": -5,
      "y": 2,
      "z": -5,
      "name": "Rock_Sandstone_Red",
      "rotation": 2
    },
    {
      "x": -5,
      "y": 3,
      "z": -5,
      "name": "Rock_Sandstone_Red_Brick_Ornate"
    },
    {
      "x": -5,
      "y": 4,
      "z": -5,
      "name": "Rock_Sandstone_Red_Brick_Ornate"
    },
    {
      "x": -5,
      "y": 5,
      "z": -5,
      "name": "Rock_Sandstone_Red_Brick_Ornate"
    },
    {
      "x": -5,
      "y": 0,
      "z": -4,
      "name": "Rock_Sandstone_Red",
      "rotation": 2
    },
    {
      "x": -5,
      "y": 1,
      "z": -4,
      "name": "Rock_Sandstone_Red",
      "rotation": 2
    },
    {
      "x": -5,
      "y": 2,
      "z": -4,
      "name": "Rock_Sandstone_Red",
      "rotation": 2
    },
    {
      "x": -5,
      "y": 3,
      "z": -4,
      "name": "Rock_Sandstone_Red_Brick_Smooth"
    },
    {
      "x": -5,
      "y": 4,
      "z": -4,
      "name": "Rock_Sandstone_Red_Brick_Decorative"
    },
    {
      "x": -5,
      "y": 5,
      "z": -4,
      "name": "Rock_Sandstone_Red_Brick_Decorative"
    },
    {
      "x": -5,
      "y": 0,
      "z": -3,
      "name": "Rock_Sandstone_Red",
      "rotation": 2
    },
    {
      "x": -5,
      "y": 1,
      "z": -3,
      "name": "Rock_Sandstone_Red",
      "rotation": 2
    },
    {
      "x": -5,
      "y": 2,
      "z": -3,
      "name": "Rock_Sandstone_Red",
      "rotation": 2
    },
    {
      "x": -5,
      "y": 3,
      "z": -3,
      "name": "Rock_Sandstone_Red_Brick_Smooth"
    },
    {
      "x": -5,
      "y": 4,
      "z": -3,
      "name": "Rock_Sandstone_Red_Brick_Decorative"
    },
    {
      "x": -5,
      "y": 5,
      "z": -3,
      "name": "Deco_SpiderWeb_Full"
    },
    {
      "x": -5,
      "y": 0,
      "z": -2,
      "name": "Rock_Sandstone_Red",
      "rotation": 2
    },
    {
      "x": -5,
      "y": 1,
      "z": -2,
      "name": "Rock_Sandstone_Red",
      "rotation": 2
    },
    {
      "x": -5,
      "y": 2,
      "z": -2,
      "name": "Rock_Sandstone_Red",
      "rotation": 2
    },
    {
      "x": -5,
      "y": 3,
      "z": -2,
      "name": "Rock_Sandstone_Red_Brick_Smooth"
    },
    {
      "x": -5,
      "y": 4,
      "z": -2,
      "name": "Rock_Sandstone_Red_Brick_Decorative"
    },
    {
      "x": -5,
      "y": 5,
      "z": -2,
      "name": "Rock_Sandstone_Red_Brick_Decorative"
    },
    {
      "x": -5,
      "y": 0,
      "z": -1,
      "name": "Rock_Sandstone_Red",
      "rotation": 2
    },
    {
      "x": -5,
      "y": 1,
      "z": -1,
      "name": "Rock_Sandstone_Red",
      "rotation": 2
    },
    {
      "x": -5,
      "y": 2,
      "z": -1,
      "name": "Rock_Sandstone_Red",
      "rotation": 2
    },
    {
      "x": -5,
      "y": 3,
      "z": -1,
      "name": "Rock_Sandstone_Red_Brick_Smooth"
    },
    {
      "x": -5,
      "y": 4,
      "z": -1,
      "name": "Rock_Sandstone_Red_Brick_Decorative"
    },
    {
      "x": -5,
      "y": 5,
      "z": -1,
      "name": "Rock_Sandstone_Red_Brick_Decorative"
    },
    {
      "x": -5,
      "y": 6,
      "z": -1,
      "name": "Rock_Sandstone_Red_Brick_Decorative"
    },
    {
      "x": -5,
      "y": 7,
      "z": -1,
      "name": "Plant_Crop_Mushroom_Glowing_Orange"
    },
    {
      "x": -5,
      "y": 0,
      "z": 0,
      "name": "Rock_Sandstone_Red",
      "rotation": 2
    },
    {
      "x": -5,
      "y": 1,
      "z": 0,
      "name": "Rock_Sandstone_Red",
      "rotation": 2
    },
    {
      "x": -5,
      "y": 2,
      "z": 0,
      "name": "Rock_Sandstone_Red",
      "rotation": 2
    },
    {
      "x": -5,
      "y": 3,
      "z": 0,
      "name": "Rock_Sandstone_Red_Brick_Smooth"
    },
    {
      "x": -5,
      "y": 4,
      "z": 0,
      "name": "Rock_Sandstone_Red_Brick_Ornate"
    },
    {
      "x": -5,
      "y": 5,
      "z": 0,
      "name": "Rock_Sandstone_Red_Brick_Ornate"
    },
    {
      "x": -5,
      "y": 6,
      "z": 0,
      "name": "Rubble_Sandstone_Red"
    },
    {
      "x": -5,
      "y": 0,
      "z": 1,
      "name": "Rock_Sandstone_Red",
      "rotation": 2
    },
    {
      "x": -5,
      "y": 1,
      "z": 1,
      "name": "Rock_Sandstone_Red",
      "rotation": 2
    },
    {
      "x": -5,
      "y": 2,
      "z": 1,
      "name": "Rock_Sandstone_Red",
      "rotation": 2
    },
    {
      "x": -5,
      "y": 3,
      "z": 1,
      "name": "Rock_Sandstone_Red_Brick_Smooth"
    },
    {
      "x": -5,
      "y": 0,
      "z": 2,
      "name": "Rock_Sandstone_Red",
      "rotation": 2
    },
    {
      "x": -5,
      "y": 1,
      "z": 2,
      "name": "Rock_Sandstone_Red",
      "rotation": 2
    },
    {
      "x": -5,
      "y": 2,
      "z": 2,
      "name": "Rock_Sandstone_Red",
      "rotation": 2
    },
    {
      "x": -5,
      "y": 3,
      "z": 2,
      "name": "Rock_Sandstone_Red_Brick_Smooth"
    },
    {
      "x": -5,
      "y": 4,
      "z": 2,
      "name": "Rock_Sandstone_Red_Brick_Ornate"
    },
    {
      "x": -5,
      "y": 5,
      "z": 2,
      "name": "Rock_Sandstone_Red_Brick_Ornate"
    },
    {
      "x": -5,
      "y": 6,
      "z": 2,
      "name": "Plant_Crop_Mushroom_Glowing_Orange"
    },
    {
      "x": -5,
      "y": 0,
      "z": 3,
      "name": "Rock_Sandstone_Red",
      "rotation": 2
    },
    {
      "x": -5,
      "y": 1,
      "z": 3,
      "name": "Rock_Sandstone_Red",
      "rotation": 2
    },
    {
      "x": -5,
      "y": 2,
      "z": 3,
      "name": "Rock_Sandstone_Red",
      "rotation": 2
    },
    {
      "x": -5,
      "y": 3,
      "z": 3,
      "name": "Rock_Sandstone_Red_Brick_Smooth"
    },
    {
      "x": -5,
      "y": 4,
      "z": 3,
      "name": "Rock_Sandstone_Red_Brick_Decorative"
    },
    {
      "x": -5,
      "y": 5,
      "z": 3,
      "name": "Rock_Sandstone_Red_Brick_Decorative"
    },
    {
      "x": -5,
      "y": 0,
      "z": 4,
      "name": "Rock_Sandstone_Red",
      "rotation": 2
    },
    {
      "x": -5,
      "y": 1,
      "z": 4,
      "name": "Rock_Sandstone_Red",
      "rotation": 2
    },
    {
      "x": -5,
      "y": 2,
      "z": 4,
      "name": "Rock_Sandstone_Red",
      "rotation": 2
    },
    {
      "x": -5,
      "y": 3,
      "z": 4,
      "name": "Rock_Sandstone_Red_Brick_Ornate"
    },
    {
      "x": -5,
      "y": 4,
      "z": 4,
      "name": "Rock_Sandstone_Red_Brick_Ornate"
    },
    {
      "x": -5,
      "y": 5,
      "z": 4,
      "name": "Rock_Sandstone_Red_Brick_Ornate"
    },
    {
      "x": -5,
      "y": 6,
      "z": 4,
      "name": "Rubble_Sandstone_Red"
    },
    {
      "x": -5,
      "y": 0,
      "z": 5,
      "name": "Rock_Sandstone_Red",
      "rotation": 2
    },
    {
      "x": -5,
      "y": 1,
      "z": 5,
      "name": "Rock_Sandstone_Red",
      "rotation": 2
    },
    {
      "x": -5,
      "y": 2,
      "z": 5,
      "name": "Rock_Sandstone_Red",
      "rotation": 2
    },
    {
      "x": -5,
      "y": 3,
      "z": 5,
      "name": "Rock_Sandstone_Red_Brick_Smooth_Half"
    },
    {
      "x": -5,
      "y": 0,
      "z": 6,
      "name": "Rock_Sandstone_Red",
      "rotation": 2
    },
    {
      "x": -5,
      "y": 1,
      "z": 6,
      "name": "Rock_Sandstone_Red",
      "rotation": 2
    },
    {
      "x": -5,
      "y": 2,
      "z": 6,
      "name": "Rock_Sandstone_Red",
      "rotation": 2
    },
    {
      "x": -5,
      "y": 0,
      "z": 7,
      "name": "Rock_Sandstone_Red",
      "rotation": 2
    },
    {
      "x": -5,
      "y": 1,
      "z": 7,
      "name": "Rock_Sandstone_Red",
      "rotation": 2
    },
    {
      "x": -5,
      "y": 2,
      "z": 7,
      "name": "Rock_Sandstone_Red",
      "rotation": 2
    },
    {
      "x": -5,
      "y": 3,
      "z": 7,
      "name": "Plant_Crop_Mushroom_Glowing_Red"
    },
    {
      "x": -5,
      "y": 0,
      "z": 8,
      "name": "Rock_Sandstone_Red",
      "rotation": 2
    },
    {
      "x": -5,
      "y": 1,
      "z": 8,
      "name": "Rock_Sandstone_Red",
      "rotation": 2
    },
    {
      "x": -5,
      "y": 2,
      "z": 8,
      "name": "Rock_Sandstone_Red",
      "rotation": 2
    },
    {
      "x": -5,
      "y": 0,
      "z": 9,
      "name": "Rock_Sandstone_Red",
      "rotation": 2
    },
    {
      "x": -5,
      "y": 1,
      "z": 9,
      "name": "Rock_Sandstone_Red",
      "rotation": 2
    },
    {
      "x": -5,
      "y": 2,
      "z": 9,
      "name": "Rock_Sandstone_Red",
      "rotation": 2
    },
    {
      "x": -5,
      "y": 1,
      "z": 10,
      "name": "Rock_Sandstone_Red",
      "rotation": 2
    },
    {
      "x": -4,
      "y": 0,
      "z": -9,
      "name": "Rock_Sandstone_Red",
      "rotation": 2
    },
    {
      "x": -4,
      "y": 1,
      "z": -9,
      "name": "Rock_Sandstone_Red",
      "rotation": 2
    },
    {
      "x": -4,
      "y": 2,
      "z": -9,
      "name": "Rock_Sandstone_Red",
      "rotation": 2
    },
    {
      "x": -4,
      "y": 0,
      "z": -8,
      "name": "Rock_Sandstone_Red",
      "rotation": 2
    },
    {
      "x": -4,
      "y": 1,
      "z": -8,
      "name": "Rock_Sandstone_Red",
      "rotation": 2
    },
    {
      "x": -4,
      "y": 2,
      "z": -8,
      "name": "Rock_Sandstone_Red",
      "rotation": 2
    },
    {
      "x": -4,
      "y": 3,
      "z": -8,
      "name": "Plant_Crop_Mushroom_Glowing_Orange"
    },
    {
      "x": -4,
      "y": 0,
      "z": -7,
      "name": "Rock_Sandstone_Red",
      "rotation": 2
    },
    {
      "x": -4,
      "y": 1,
      "z": -7,
      "name": "Rock_Sandstone_Red",
      "rotation": 2
    },
    {
      "x": -4,
      "y": 2,
      "z": -7,
      "name": "Rock_Sandstone_Red",
      "rotation": 2
    },
    {
      "x": -4,
      "y": 0,
      "z": -6,
      "name": "Rock_Sandstone_Red",
      "rotation": 2
    },
    {
      "x": -4,
      "y": 1,
      "z": -6,
      "name": "Rock_Sandstone_Red",
      "rotation": 2
    },
    {
      "x": -4,
      "y": 2,
      "z": -6,
      "name": "Rock_Sandstone_Red",
      "rotation": 2
    },
    {
      "x": -4,
      "y": 3,
      "z": -6,
      "name": "Rock_Sandstone_Red_Brick_Smooth_Half"
    },
    {
      "x": -4,
      "y": 4,
      "z": -6,
      "name": "Plant_Crop_Mushroom_Shelve_Brown"
    },
    {
      "x": -4,
      "y": 0,
      "z": -5,
      "name": "Rock_Sandstone_Red",
      "rotation": 2
    },
    {
      "x": -4,
      "y": 1,
      "z": -5,
      "name": "Rock_Sandstone_Red",
      "rotation": 2
    },
    {
      "x": -4,
      "y": 2,
      "z": -5,
      "name": "Rock_Sandstone_Red",
      "rotation": 2
    },
    {
      "x": -4,
      "y": 3,
      "z": -5,
      "name": "Rock_Sandstone_Red_Brick_Smooth"
    },
    {
      "x": -4,
      "y": 4,
      "z": -5,
      "name": "Rock_Sandstone_Red_Brick_Decorative"
    },
    {
      "x": -4,
      "y": 5,
      "z": -5,
      "name": "Rock_Sandstone_Red_Brick_Decorative"
    },
    {
      "x": -4,
      "y": 6,
      "z": -5,
      "name": "Plant_Crop_Mushroom_Glowing_Orange"
    },
    {
      "x": -4,
      "y": 0,
      "z": -4,
      "name": "Rock_Sandstone_Red",
      "rotation": 2
    },
    {
      "x": -4,
      "y": 1,
      "z": -4,
      "name": "Rock_Sandstone_Red",
      "rotation": 2
    },
    {
      "x": -4,
      "y": 2,
      "z": -4,
      "name": "Rock_Sandstone_Red",
      "rotation": 2
    },
    {
      "x": -4,
      "y": 3,
      "z": -4,
      "name": "Rock_Sandstone_Red_Brick_Smooth"
    },
    {
      "x": -4,
      "y": 0,
      "z": -3,
      "name": "Rock_Sandstone_Red",
      "rotation": 2
    },
    {
      "x": -4,
      "y": 1,
      "z": -3,
      "name": "Rock_Sandstone_Red",
      "rotation": 2
    },
    {
      "x": -4,
      "y": 2,
      "z": -3,
      "name": "Rock_Sandstone_Red",
      "rotation": 2
    },
    {
      "x": -4,
      "y": 3,
      "z": -3,
      "name": "Rock_Sandstone_Red_Brick_Smooth"
    },
    {
      "x": -4,
      "y": 0,
      "z": -2,
      "name": "Rock_Sandstone_Red",
      "rotation": 2
    },
    {
      "x": -4,
      "y": 1,
      "z": -2,
      "name": "Rock_Sandstone_Red",
      "rotation": 2
    },
    {
      "x": -4,
      "y": 2,
      "z": -2,
      "name": "Rock_Sandstone_Red",
      "rotation": 2
    },
    {
      "x": -4,
      "y": 3,
      "z": -2,
      "name": "Rock_Sandstone_Red_Brick_Smooth"
    },
    {
      "x": -4,
      "y": 0,
      "z": -1,
      "name": "Rock_Sandstone_Red",
      "rotation": 2
    },
    {
      "x": -4,
      "y": 1,
      "z": -1,
      "name": "Rock_Sandstone_Red",
      "rotation": 2
    },
    {
      "x": -4,
      "y": 2,
      "z": -1,
      "name": "Rock_Sandstone_Red",
      "rotation": 2
    },
    {
      "x": -4,
      "y": 3,
      "z": -1,
      "name": "Rock_Sandstone_Red_Brick_Smooth"
    },
    {
      "x": -4,
      "y": 0,
      "z": 0,
      "name": "Rock_Sandstone_Red",
      "rotation": 2
    },
    {
      "x": -4,
      "y": 1,
      "z": 0,
      "name": "Rock_Sandstone_Red",
      "rotation": 2
    },
    {
      "x": -4,
      "y": 2,
      "z": 0,
      "name": "Rock_Sandstone_Red",
      "rotation": 2
    },
    {
      "x": -4,
      "y": 3,
      "z": 0,
      "name": "Rock_Sandstone_Red_Brick_Smooth"
    },
    {
      "x": -4,
      "y": 0,
      "z": 1,
      "name": "Rock_Sandstone_Red",
      "rotation": 2
    },
    {
      "x": -4,
      "y": 1,
      "z": 1,
      "name": "Rock_Sandstone_Red",
      "rotation": 2
    },
    {
      "x": -4,
      "y": 2,
      "z": 1,
      "name": "Rock_Sandstone_Red",
      "rotation": 2
    },
    {
      "x": -4,
      "y": 3,
      "z": 1,
      "name": "Rock_Sandstone_Red_Brick_Smooth"
    },
    {
      "x": -4,
      "y": 0,
      "z": 2,
      "name": "Rock_Sandstone_Red",
      "rotation": 2
    },
    {
      "x": -4,
      "y": 1,
      "z": 2,
      "name": "Rock_Sandstone_Red",
      "rotation": 2
    },
    {
      "x": -4,
      "y": 2,
      "z": 2,
      "name": "Rock_Sandstone_Red",
      "rotation": 2
    },
    {
      "x": -4,
      "y": 3,
      "z": 2,
      "name": "Rock_Sandstone_Red_Brick_Smooth"
    },
    {
      "x": -4,
      "y": 0,
      "z": 3,
      "name": "Rock_Sandstone_Red",
      "rotation": 2
    },
    {
      "x": -4,
      "y": 1,
      "z": 3,
      "name": "Rock_Sandstone_Red",
      "rotation": 2
    },
    {
      "x": -4,
      "y": 2,
      "z": 3,
      "name": "Rock_Sandstone_Red",
      "rotation": 2
    },
    {
      "x": -4,
      "y": 3,
      "z": 3,
      "name": "Rock_Sandstone_Red_Brick_Smooth"
    },
    {
      "x": -4,
      "y": 4,
      "z": 3,
      "name": "Deco_SpiderWeb_Full"
    },
    {
      "x": -4,
      "y": 0,
      "z": 4,
      "name": "Rock_Sandstone_Red",
      "rotation": 2
    },
    {
      "x": -4,
      "y": 1,
      "z": 4,
      "name": "Rock_Sandstone_Red",
      "rotation": 2
    },
    {
      "x": -4,
      "y": 2,
      "z": 4,
      "name": "Rock_Sandstone_Red",
      "rotation": 2
    },
    {
      "x": -4,
      "y": 3,
      "z": 4,
      "name": "Rock_Sandstone_Red_Brick_Smooth"
    },
    {
      "x": -4,
      "y": 4,
      "z": 4,
      "name": "Rock_Sandstone_Red_Brick_Decorative"
    },
    {
      "x": -4,
      "y": 5,
      "z": 4,
      "name": "Rock_Sandstone_Red_Brick_Decorative"
    },
    {
      "x": -4,
      "y": 0,
      "z": 5,
      "name": "Rock_Sandstone_Red",
      "rotation": 2
    },
    {
      "x": -4,
      "y": 1,
      "z": 5,
      "name": "Rock_Sandstone_Red",
      "rotation": 2
    },
    {
      "x": -4,
      "y": 2,
      "z": 5,
      "name": "Rock_Sandstone_Red",
      "rotation": 2
    },
    {
      "x": -4,
      "y": 3,
      "z": 5,
      "name": "Rock_Sandstone_Red_Brick_Smooth_Half"
    },
    {
      "x": -4,
      "y": 0,
      "z": 6,
      "name": "Rock_Sandstone_Red",
      "rotation": 2
    },
    {
      "x": -4,
      "y": 1,
      "z": 6,
      "name": "Rock_Sandstone_Red",
      "rotation": 2
    },
    {
      "x": -4,
      "y": 2,
      "z": 6,
      "name": "Rock_Sandstone_Red",
      "rotation": 2
    },
    {
      "x": -4,
      "y": 3,
      "z": 6,
      "name": "Rock_Sandstone_Red_Brick_Smooth_Half"
    },
    {
      "x": -4,
      "y": 0,
      "z": 7,
      "name": "Rock_Sandstone_Red",
      "rotation": 2
    },
    {
      "x": -4,
      "y": 1,
      "z": 7,
      "name": "Rock_Sandstone_Red",
      "rotation": 2
    },
    {
      "x": -4,
      "y": 2,
      "z": 7,
      "name": "Rock_Sandstone_Red",
      "rotation": 2
    },
    {
      "x": -4,
      "y": 3,
      "z": 7,
      "name": "Rock_Sandstone_Red_Brick_Smooth_Half"
    },
    {
      "x": -4,
      "y": 0,
      "z": 8,
      "name": "Rock_Sandstone_Red",
      "rotation": 2
    },
    {
      "x": -4,
      "y": 1,
      "z": 8,
      "name": "Rock_Sandstone_Red",
      "rotation": 2
    },
    {
      "x": -4,
      "y": 2,
      "z": 8,
      "name": "Rock_Sandstone_Red",
      "rotation": 2
    },
    {
      "x": -4,
      "y": 3,
      "z": 8,
      "name": "Rock_Sandstone_Red_Brick_Smooth_Half"
    },
    {
      "x": -4,
      "y": 0,
      "z": 9,
      "name": "Rock_Sandstone_Red",
      "rotation": 2
    },
    {
      "x": -4,
      "y": 1,
      "z": 9,
      "name": "Rock_Sandstone_Red",
      "rotation": 2
    },
    {
      "x": -4,
      "y": 2,
      "z": 9,
      "name": "Rock_Sandstone_Red",
      "rotation": 2
    },
    {
      "x": -4,
      "y": 3,
      "z": 9,
      "name": "Rock_Sandstone_Red_Brick_Smooth_Half"
    },
    {
      "x": -4,
      "y": 1,
      "z": 10,
      "name": "Rock_Sandstone_Red",
      "rotation": 2
    },
    {
      "x": -3,
      "y": 0,
      "z": -9,
      "name": "Rock_Sandstone_Red",
      "rotation": 2
    },
    {
      "x": -3,
      "y": 1,
      "z": -9,
      "name": "Rock_Sandstone_Red",
      "rotation": 2
    },
    {
      "x": -3,
      "y": 2,
      "z": -9,
      "name": "Rock_Sandstone_Red",
      "rotation": 2
    },
    {
      "x": -3,
      "y": 3,
      "z": -9,
      "name": "Plant_Crop_Mushroom_Glowing_Red"
    },
    {
      "x": -3,
      "y": 0,
      "z": -8,
      "name": "Rock_Sandstone_Red",
      "rotation": 2
    },
    {
      "x": -3,
      "y": 1,
      "z": -8,
      "name": "Rock_Sandstone_Red",
      "rotation": 2
    },
    {
      "x": -3,
      "y": 2,
      "z": -8,
      "name": "Rock_Sandstone_Red",
      "rotation": 2
    },
    {
      "x": -3,
      "y": 0,
      "z": -7,
      "name": "Rock_Sandstone_Red",
      "rotation": 2
    },
    {
      "x": -3,
      "y": 1,
      "z": -7,
      "name": "Rock_Sandstone_Red",
      "rotation": 2
    },
    {
      "x": -3,
      "y": 2,
      "z": -7,
      "name": "Rock_Sandstone_Red",
      "rotation": 2
    },
    {
      "x": -3,
      "y": 0,
      "z": -6,
      "name": "Rock_Sandstone_Red",
      "rotation": 2
    },
    {
      "x": -3,
      "y": 1,
      "z": -6,
      "name": "Rock_Sandstone_Red",
      "rotation": 2
    },
    {
      "x": -3,
      "y": 2,
      "z": -6,
      "name": "Rock_Sandstone_Red",
      "rotation": 2
    },
    {
      "x": -3,
      "y": 3,
      "z": -6,
      "name": "Rock_Sandstone_Red_Brick_Smooth_Half"
    },
    {
      "x": -3,
      "y": 0,
      "z": -5,
      "name": "Rock_Sandstone_Red",
      "rotation": 2
    },
    {
      "x": -3,
      "y": 1,
      "z": -5,
      "name": "Rock_Sandstone_Red",
      "rotation": 2
    },
    {
      "x": -3,
      "y": 2,
      "z": -5,
      "name": "Rock_Sandstone_Red",
      "rotation": 2
    },
    {
      "x": -3,
      "y": 3,
      "z": -5,
      "name": "Rock_Sandstone_Red_Brick_Smooth"
    },
    {
      "x": -3,
      "y": 4,
      "z": -5,
      "name": "Rock_Sandstone_Red_Brick_Decorative"
    },
    {
      "x": -3,
      "y": 5,
      "z": -5,
      "name": "Rock_Sandstone_Red_Brick_Decorative"
    },
    {
      "x": -3,
      "y": 6,
      "z": -5,
      "name": "Rock_Sandstone_Red_Brick_Decorative"
    },
    {
      "x": -3,
      "y": 7,
      "z": -5,
      "name": "Rock_Sandstone_Red_Brick_Decorative"
    },
    {
      "x": -3,
      "y": 8,
      "z": -5,
      "name": "Rubble_Sandstone_Red"
    },
    {
      "x": -3,
      "y": 0,
      "z": -4,
      "name": "Rock_Sandstone_Red",
      "rotation": 2
    },
    {
      "x": -3,
      "y": 1,
      "z": -4,
      "name": "Rock_Sandstone_Red",
      "rotation": 2
    },
    {
      "x": -3,
      "y": 2,
      "z": -4,
      "name": "Rock_Sandstone_Red",
      "rotation": 2
    },
    {
      "x": -3,
      "y": 3,
      "z": -4,
      "name": "Rock_Sandstone_Red_Brick_Smooth"
    },
    {
      "x": -3,
      "y": 0,
      "z": -3,
      "name": "Rock_Sandstone_Red",
      "rotation": 2
    },
    {
      "x": -3,
      "y": 1,
      "z": -3,
      "name": "Rock_Sandstone_Red",
      "rotation": 2
    },
    {
      "x": -3,
      "y": 2,
      "z": -3,
      "name": "Rock_Sandstone_Red",
      "rotation": 2
    },
    {
      "x": -3,
      "y": 3,
      "z": -3,
      "name": "Rock_Sandstone_Red_Brick_Smooth"
    },
    {
      "x": -3,
      "y": 0,
      "z": -2,
      "name": "Rock_Sandstone_Red",
      "rotation": 2
    },
    {
      "x": -3,
      "y": 1,
      "z": -2,
      "name": "Rock_Sandstone_Red",
      "rotation": 2
    },
    {
      "x": -3,
      "y": 2,
      "z": -2,
      "name": "Rock_Sandstone_Red",
      "rotation": 2
    },
    {
      "x": -3,
      "y": 3,
      "z": -2,
      "name": "Rock_Sandstone_Red_Brick_Smooth"
    },
    {
      "x": -3,
      "y": 0,
      "z": -1,
      "name": "Rock_Sandstone_Red",
      "rotation": 2
    },
    {
      "x": -3,
      "y": 1,
      "z": -1,
      "name": "Rock_Sandstone_Red",
      "rotation": 2
    },
    {
      "x": -3,
      "y": 2,
      "z": -1,
      "name": "Rock_Sandstone_Red",
      "rotation": 2
    },
    {
      "x": -3,
      "y": 3,
      "z": -1,
      "name": "Rock_Sandstone_Red_Brick_Smooth"
    },
    {
      "x": -3,
      "y": 0,
      "z": 0,
      "name": "Rock_Sandstone_Red",
      "rotation": 2
    },
    {
      "x": -3,
      "y": 1,
      "z": 0,
      "name": "Rock_Sandstone_Red",
      "rotation": 2
    },
    {
      "x": -3,
      "y": 2,
      "z": 0,
      "name": "Rock_Sandstone_Red",
      "rotation": 2
    },
    {
      "x": -3,
      "y": 3,
      "z": 0,
      "name": "Rock_Sandstone_Red_Brick_Smooth"
    },
    {
      "x": -3,
      "y": 0,
      "z": 1,
      "name": "Rock_Sandstone_Red",
      "rotation": 2
    },
    {
      "x": -3,
      "y": 1,
      "z": 1,
      "name": "Rock_Sandstone_Red",
      "rotation": 2
    },
    {
      "x": -3,
      "y": 2,
      "z": 1,
      "name": "Rock_Sandstone_Red",
      "rotation": 2
    },
    {
      "x": -3,
      "y": 3,
      "z": 1,
      "name": "Rock_Sandstone_Red_Brick_Smooth"
    },
    {
      "x": -3,
      "y": 4,
      "z": 1,
      "name": "Rubble_Sandstone_Red_Medium"
    },
    {
      "x": -3,
      "y": 0,
      "z": 2,
      "name": "Rock_Sandstone_Red",
      "rotation": 2
    },
    {
      "x": -3,
      "y": 1,
      "z": 2,
      "name": "Rock_Sandstone_Red",
      "rotation": 2
    },
    {
      "x": -3,
      "y": 2,
      "z": 2,
      "name": "Rock_Sandstone_Red",
      "rotation": 2
    },
    {
      "x": -3,
      "y": 3,
      "z": 2,
      "name": "Rock_Sandstone_Red_Brick_Smooth"
    },
    {
      "x": -3,
      "y": 4,
      "z": 2,
      "name": "Rubble_Sandstone_Red_Medium"
    },
    {
      "x": -3,
      "y": 0,
      "z": 3,
      "name": "Rock_Sandstone_Red",
      "rotation": 2
    },
    {
      "x": -3,
      "y": 1,
      "z": 3,
      "name": "Rock_Sandstone_Red",
      "rotation": 2
    },
    {
      "x": -3,
      "y": 2,
      "z": 3,
      "name": "Rock_Sandstone_Red",
      "rotation": 2
    },
    {
      "x": -3,
      "y": 3,
      "z": 3,
      "name": "Rock_Sandstone_Red_Brick_Smooth"
    },
    {
      "x": -3,
      "y": 4,
      "z": 3,
      "name": "Rock_Sandstone_Red_Cobble"
    },
    {
      "x": -3,
      "y": 0,
      "z": 4,
      "name": "Rock_Sandstone_Red",
      "rotation": 2
    },
    {
      "x": -3,
      "y": 1,
      "z": 4,
      "name": "Rock_Sandstone_Red",
      "rotation": 2
    },
    {
      "x": -3,
      "y": 2,
      "z": 4,
      "name": "Rock_Sandstone_Red",
      "rotation": 2
    },
    {
      "x": -3,
      "y": 3,
      "z": 4,
      "name": "Rock_Sandstone_Red_Brick_Ornate"
    },
    {
      "x": -3,
      "y": 4,
      "z": 4,
      "name": "Rock_Sandstone_Red_Brick_Ornate"
    },
    {
      "x": -3,
      "y": 5,
      "z": 4,
      "name": "Rock_Sandstone_Red_Brick_Ornate"
    },
    {
      "x": -3,
      "y": 6,
      "z": 4,
      "name": "Plant_Crop_Mushroom_Glowing_Orange"
    },
    {
      "x": -3,
      "y": 0,
      "z": 5,
      "name": "Rock_Sandstone_Red",
      "rotation": 2
    },
    {
      "x": -3,
      "y": 1,
      "z": 5,
      "name": "Rock_Sandstone_Red",
      "rotation": 2
    },
    {
      "x": -3,
      "y": 2,
      "z": 5,
      "name": "Rock_Sandstone_Red",
      "rotation": 2
    },
    {
      "x": -3,
      "y": 3,
      "z": 5,
      "name": "Rock_Sandstone_Red_Brick_Smooth"
    },
    {
      "x": -3,
      "y": 4,
      "z": 5,
      "name": "Rock_Sandstone_Red_Brick_Decorative"
    },
    {
      "x": -3,
      "y": 5,
      "z": 5,
      "name": "Rock_Sandstone_Red_Brick_Decorative"
    },
    {
      "x": -3,
      "y": 0,
      "z": 6,
      "name": "Rock_Sandstone_Red",
      "rotation": 2
    },
    {
      "x": -3,
      "y": 1,
      "z": 6,
      "name": "Rock_Sandstone_Red",
      "rotation": 2
    },
    {
      "x": -3,
      "y": 2,
      "z": 6,
      "name": "Rock_Sandstone_Red",
      "rotation": 2
    },
    {
      "x": -3,
      "y": 3,
      "z": 6,
      "name": "Rock_Sandstone_Red_Brick_Smooth"
    },
    {
      "x": -3,
      "y": 4,
      "z": 6,
      "name": "Rock_Sandstone_Red_Brick_Decorative"
    },
    {
      "x": -3,
      "y": 0,
      "z": 7,
      "name": "Rock_Sandstone_Red",
      "rotation": 2
    },
    {
      "x": -3,
      "y": 1,
      "z": 7,
      "name": "Rock_Sandstone_Red",
      "rotation": 2
    },
    {
      "x": -3,
      "y": 2,
      "z": 7,
      "name": "Rock_Sandstone_Red",
      "rotation": 2
    },
    {
      "x": -3,
      "y": 3,
      "z": 7,
      "name": "Rock_Sandstone_Red_Brick_Smooth"
    },
    {
      "x": -3,
      "y": 4,
      "z": 7,
      "name": "Rock_Sandstone_Red_Brick_Decorative"
    },
    {
      "x": -3,
      "y": 5,
      "z": 7,
      "name": "Rock_Sandstone_Red_Brick_Decorative"
    },
    {
      "x": -3,
      "y": 6,
      "z": 7,
      "name": "Rubble_Sandstone_Red_Medium"
    },
    {
      "x": -3,
      "y": 0,
      "z": 8,
      "name": "Rock_Sandstone_Red",
      "rotation": 2
    },
    {
      "x": -3,
      "y": 1,
      "z": 8,
      "name": "Rock_Sandstone_Red",
      "rotation": 2
    },
    {
      "x": -3,
      "y": 2,
      "z": 8,
      "name": "Rock_Sandstone_Red",
      "rotation": 2
    },
    {
      "x": -3,
      "y": 3,
      "z": 8,
      "name": "Rock_Sandstone_Red_Brick_Ornate"
    },
    {
      "x": -3,
      "y": 4,
      "z": 8,
      "name": "Rock_Sandstone_Red_Brick_Ornate"
    },
    {
      "x": -3,
      "y": 5,
      "z": 8,
      "name": "Rock_Sandstone_Red_Brick_Ornate"
    },
    {
      "x": -3,
      "y": 0,
      "z": 9,
      "name": "Rock_Sandstone_Red",
      "rotation": 2
    },
    {
      "x": -3,
      "y": 1,
      "z": 9,
      "name": "Rock_Sandstone_Red",
      "rotation": 2
    },
    {
      "x": -3,
      "y": 2,
      "z": 9,
      "name": "Rock_Sandstone_Red"
    },
    {
      "x": -3,
      "y": 3,
      "z": 9,
      "name": "Rock_Sandstone_Red_Brick_Smooth_Half"
    },
    {
      "x": -3,
      "y": 1,
      "z": 10,
      "name": "Rock_Sandstone_Red",
      "rotation": 2
    },
    {
      "x": -2,
      "y": 0,
      "z": -9,
      "name": "Rock_Sandstone_Red",
      "rotation": 2
    },
    {
      "x": -2,
      "y": 1,
      "z": -9,
      "name": "Rock_Sandstone_Red",
      "rotation": 2
    },
    {
      "x": -2,
      "y": 2,
      "z": -9,
      "name": "Rock_Sandstone_Red",
      "rotation": 2
    },
    {
      "x": -2,
      "y": 0,
      "z": -8,
      "name": "Rock_Sandstone_Red",
      "rotation": 2
    },
    {
      "x": -2,
      "y": 1,
      "z": -8,
      "name": "Rock_Sandstone_Red",
      "rotation": 2
    },
    {
      "x": -2,
      "y": 2,
      "z": -8,
      "name": "Rock_Sandstone_Red",
      "rotation": 2
    },
    {
      "x": -2,
      "y": 0,
      "z": -7,
      "name": "Rock_Sandstone_Red",
      "rotation": 2
    },
    {
      "x": -2,
      "y": 1,
      "z": -7,
      "name": "Rock_Sandstone_Red",
      "rotation": 2
    },
    {
      "x": -2,
      "y": 2,
      "z": -7,
      "name": "Rock_Sandstone_Red",
      "rotation": 2
    },
    {
      "x": -2,
      "y": 0,
      "z": -6,
      "name": "Rock_Sandstone_Red",
      "rotation": 2
    },
    {
      "x": -2,
      "y": 1,
      "z": -6,
      "name": "Rock_Sandstone_Red",
      "rotation": 2
    },
    {
      "x": -2,
      "y": 2,
      "z": -6,
      "name": "Rock_Sandstone_Red",
      "rotation": 2
    },
    {
      "x": -2,
      "y": 3,
      "z": -6,
      "name": "Rock_Sandstone_Red_Brick_Smooth_Half"
    },
    {
      "x": -2,
      "y": 5,
      "z": -6,
      "name": "Plant_Crop_Mushroom_Shelve_Brown"
    },
    {
      "x": -2,
      "y": 0,
      "z": -5,
      "name": "Rock_Sandstone_Red",
      "rotation": 2
    },
    {
      "x": -2,
      "y": 1,
      "z": -5,
      "name": "Rock_Sandstone_Red",
      "rotation": 2
    },
    {
      "x": -2,
      "y": 2,
      "z": -5,
      "name": "Rock_Sandstone_Red",
      "rotation": 2
    },
    {
      "x": -2,
      "y": 3,
      "z": -5,
      "name": "Rock_Sandstone_Red_Brick_Smooth"
    },
    {
      "x": -2,
      "y": 4,
      "z": -5,
      "name": "Rock_Sandstone_Red_Brick_Decorative"
    },
    {
      "x": -2,
      "y": 5,
      "z": -5,
      "name": "Rock_Sandstone_Red_Brick_Decorative"
    },
    {
      "x": -2,
      "y": 6,
      "z": -5,
      "name": "Rock_Sandstone_Red_Brick_Decorative"
    },
    {
      "x": -2,
      "y": 7,
      "z": -5,
      "name": "Rock_Sandstone_Red_Brick_Decorative"
    },
    {
      "x": -2,
      "y": 8,
      "z": -5,
      "name": "Rock_Sandstone_Red_Brick_Decorative"
    },
    {
      "x": -2,
      "y": 9,
      "z": -5,
      "name": "Plant_Crop_Mushroom_Glowing_Orange"
    },
    {
      "x": -2,
      "y": 0,
      "z": -4,
      "name": "Rock_Sandstone_Red",
      "rotation": 2
    },
    {
      "x": -2,
      "y": 1,
      "z": -4,
      "name": "Rock_Sandstone_Red",
      "rotation": 2
    },
    {
      "x": -2,
      "y": 2,
      "z": -4,
      "name": "Rock_Sandstone_Red",
      "rotation": 2
    },
    {
      "x": -2,
      "y": 3,
      "z": -4,
      "name": "Rock_Sandstone_Red_Brick_Smooth"
    },
    {
      "x": -2,
      "y": 6,
      "z": -4,
      "name": "Plant_Crop_Mushroom_Shelve_Brown"
    },
    {
      "x": -2,
      "y": 7,
      "z": -4,
      "name": "Plant_Crop_Mushroom_Shelve_Brown"
    },
    {
      "x": -2,
      "y": 8,
      "z": -4,
      "name": "Plant_Crop_Mushroom_Shelve_Brown"
    },
    {
      "x": -2,
      "y": 0,
      "z": -3,
      "name": "Rock_Sandstone_Red",
      "rotation": 2
    },
    {
      "x": -2,
      "y": 1,
      "z": -3,
      "name": "Rock_Sandstone_Red",
      "rotation": 2
    },
    {
      "x": -2,
      "y": 2,
      "z": -3,
      "name": "Rock_Sandstone_Red",
      "rotation": 2
    },
    {
      "x": -2,
      "y": 3,
      "z": -3,
      "name": "Rock_Sandstone_Red_Brick_Smooth"
    },
    {
      "x": -2,
      "y": 0,
      "z": -2,
      "name": "Rock_Sandstone_Red",
      "rotation": 2
    },
    {
      "x": -2,
      "y": 1,
      "z": -2,
      "name": "Rock_Sandstone_Red",
      "rotation": 2
    },
    {
      "x": -2,
      "y": 2,
      "z": -2,
      "name": "Rock_Sandstone_Red",
      "rotation": 2
    },
    {
      "x": -2,
      "y": 3,
      "z": -2,
      "name": "Rock_Sandstone_Red_Brick_Smooth"
    },
    {
      "x": -2,
      "y": 0,
      "z": -1,
      "name": "Rock_Sandstone_Red",
      "rotation": 2
    },
    {
      "x": -2,
      "y": 1,
      "z": -1,
      "name": "Rock_Sandstone_Red",
      "rotation": 2
    },
    {
      "x": -2,
      "y": 2,
      "z": -1,
      "name": "Rock_Sandstone_Red",
      "rotation": 2
    },
    {
      "x": -2,
      "y": 3,
      "z": -1,
      "name": "Rock_Sandstone_Red_Brick_Smooth"
    },
    {
      "x": -2,
      "y": 0,
      "z": 0,
      "name": "Rock_Sandstone_Red",
      "rotation": 2
    },
    {
      "x": -2,
      "y": 1,
      "z": 0,
      "name": "Rock_Sandstone_Red",
      "rotation": 2
    },
    {
      "x": -2,
      "y": 2,
      "z": 0,
      "name": "Rock_Sandstone_Red",
      "rotation": 2
    },
    {
      "x": -2,
      "y": 3,
      "z": 0,
      "name": "Rock_Sandstone_Red_Brick_Smooth"
    },
    {
      "x": -2,
      "y": 0,
      "z": 1,
      "name": "Rock_Sandstone_Red",
      "rotation": 2
    },
    {
      "x": -2,
      "y": 1,
      "z": 1,
      "name": "Rock_Sandstone_Red",
      "rotation": 2
    },
    {
      "x": -2,
      "y": 2,
      "z": 1,
      "name": "Rock_Sandstone_Red",
      "rotation": 2
    },
    {
      "x": -2,
      "y": 3,
      "z": 1,
      "name": "Rock_Sandstone_Red_Brick_Smooth"
    },
    {
      "x": -2,
      "y": 4,
      "z": 1,
      "name": "Rock_Sandstone_Red_Cobble"
    },
    {
      "x": -2,
      "y": 5,
      "z": 1,
      "name": "Rubble_Sandstone_Red_Medium"
    },
    {
      "x": -2,
      "y": 0,
      "z": 2,
      "name": "Rock_Sandstone_Red",
      "rotation": 2
    },
    {
      "x": -2,
      "y": 1,
      "z": 2,
      "name": "Rock_Sandstone_Red",
      "rotation": 2
    },
    {
      "x": -2,
      "y": 2,
      "z": 2,
      "name": "Rock_Sandstone_Red",
      "rotation": 2
    },
    {
      "x": -2,
      "y": 3,
      "z": 2,
      "name": "Rock_Sandstone_Red_Brick_Smooth"
    },
    {
      "x": -2,
      "y": 0,
      "z": 3,
      "name": "Rock_Sandstone_Red",
      "rotation": 2
    },
    {
      "x": -2,
      "y": 1,
      "z": 3,
      "name": "Rock_Sandstone_Red",
      "rotation": 2
    },
    {
      "x": -2,
      "y": 2,
      "z": 3,
      "name": "Rock_Sandstone_Red",
      "rotation": 2
    },
    {
      "x": -2,
      "y": 3,
      "z": 3,
      "name": "Rock_Sandstone_Red_Brick_Smooth"
    },
    {
      "x": -2,
      "y": 4,
      "z": 3,
      "name": "Rock_Sandstone_Red_Cobble"
    },
    {
      "x": -2,
      "y": 5,
      "z": 3,
      "name": "Rock_Sandstone_Red_Cobble"
    },
    {
      "x": -2,
      "y": 6,
      "z": 3,
      "name": "Rubble_Sandstone_Red_Medium"
    },
    {
      "x": -2,
      "y": 0,
      "z": 4,
      "name": "Rock_Sandstone_Red",
      "rotation": 2
    },
    {
      "x": -2,
      "y": 1,
      "z": 4,
      "name": "Rock_Sandstone_Red",
      "rotation": 2
    },
    {
      "x": -2,
      "y": 2,
      "z": 4,
      "name": "Rock_Sandstone_Red",
      "rotation": 2
    },
    {
      "x": -2,
      "y": 3,
      "z": 4,
      "name": "Rock_Sandstone_Red_Brick_Smooth"
    },
    {
      "x": -2,
      "y": 4,
      "z": 4,
      "name": "Rock_Sandstone_Red_Cobble"
    },
    {
      "x": -2,
      "y": 5,
      "z": 4,
      "name": "Rubble_Sandstone_Red"
    },
    {
      "x": -2,
      "y": 0,
      "z": 5,
      "name": "Rock_Sandstone_Red",
      "rotation": 2
    },
    {
      "x": -2,
      "y": 1,
      "z": 5,
      "name": "Rock_Sandstone_Red",
      "rotation": 2
    },
    {
      "x": -2,
      "y": 2,
      "z": 5,
      "name": "Rock_Sandstone_Red",
      "rotation": 2
    },
    {
      "x": -2,
      "y": 3,
      "z": 5,
      "name": "Rock_Sandstone_Red_Brick_Smooth"
    },
    {
      "x": -2,
      "y": 4,
      "z": 5,
      "name": "Rubble_Sandstone_Red_Medium"
    },
    {
      "x": -2,
      "y": 0,
      "z": 6,
      "name": "Rock_Sandstone_Red",
      "rotation": 2
    },
    {
      "x": -2,
      "y": 1,
      "z": 6,
      "name": "Rock_Sandstone_Red",
      "rotation": 2
    },
    {
      "x": -2,
      "y": 2,
      "z": 6,
      "name": "Rock_Sandstone_Red",
      "rotation": 2
    },
    {
      "x": -2,
      "y": 3,
      "z": 6,
      "name": "Rock_Sandstone_Red_Brick_Smooth"
    },
    {
      "x": -2,
      "y": 0,
      "z": 7,
      "name": "Rock_Sandstone_Red",
      "rotation": 2
    },
    {
      "x": -2,
      "y": 1,
      "z": 7,
      "name": "Rock_Sandstone_Red",
      "rotation": 2
    },
    {
      "x": -2,
      "y": 2,
      "z": 7,
      "name": "Rock_Sandstone_Red",
      "rotation": 2
    },
    {
      "x": -2,
      "y": 3,
      "z": 7,
      "name": "Rock_Sandstone_Red_Brick_Smooth"
    },
    {
      "x": -2,
      "y": 0,
      "z": 8,
      "name": "Rock_Sandstone_Red",
      "rotation": 2
    },
    {
      "x": -2,
      "y": 1,
      "z": 8,
      "name": "Rock_Sandstone_Red",
      "rotation": 2
    },
    {
      "x": -2,
      "y": 2,
      "z": 8,
      "name": "Rock_Sandstone_Red",
      "rotation": 2
    },
    {
      "x": -2,
      "y": 3,
      "z": 8,
      "name": "Rock_Sandstone_Red_Brick_Smooth"
    },
    {
      "x": -2,
      "y": 4,
      "z": 8,
      "name": "Rock_Sandstone_Red_Brick_Decorative"
    },
    {
      "x": -2,
      "y": 0,
      "z": 9,
      "name": "Rock_Sandstone_Red",
      "rotation": 2
    },
    {
      "x": -2,
      "y": 1,
      "z": 9,
      "name": "Rock_Sandstone_Red",
      "rotation": 2
    },
    {
      "x": -2,
      "y": 2,
      "z": 9,
      "name": "Rock_Sandstone_Red",
      "rotation": 2
    },
    {
      "x": -2,
      "y": 3,
      "z": 9,
      "name": "Rock_Sandstone_Red_Brick_Smooth_Half"
    },
    {
      "x": -2,
      "y": 1,
      "z": 10,
      "name": "Rock_Sandstone_Red",
      "rotation": 2
    },
    {
      "x": -1,
      "y": 1,
      "z": -10,
      "name": "Rock_Sandstone_Red",
      "rotation": 2
    },
    {
      "x": -1,
      "y": 0,
      "z": -9,
      "name": "Rock_Sandstone_Red",
      "rotation": 2
    },
    {
      "x": -1,
      "y": 1,
      "z": -9,
      "name": "Rock_Sandstone_Red",
      "rotation": 2
    },
    {
      "x": -1,
      "y": 2,
      "z": -9,
      "name": "Rock_Sandstone_Red",
      "rotation": 2
    },
    {
      "x": -1,
      "y": 0,
      "z": -8,
      "name": "Rock_Sandstone_Red",
      "rotation": 2
    },
    {
      "x": -1,
      "y": 1,
      "z": -8,
      "name": "Rock_Sandstone_Red",
      "rotation": 2
    },
    {
      "x": -1,
      "y": 2,
      "z": -8,
      "name": "Rock_Sandstone_Red",
      "rotation": 2
    },
    {
      "x": -1,
      "y": 3,
      "z": -8,
      "name": "Rubble_Sandstone_Red"
    },
    {
      "x": -1,
      "y": 0,
      "z": -7,
      "name": "Rock_Sandstone_Red",
      "rotation": 2
    },
    {
      "x": -1,
      "y": 1,
      "z": -7,
      "name": "Rock_Sandstone_Red",
      "rotation": 2
    },
    {
      "x": -1,
      "y": 2,
      "z": -7,
      "name": "Rock_Sandstone_Red",
      "rotation": 2
    },
    {
      "x": -1,
      "y": 0,
      "z": -6,
      "name": "Rock_Sandstone_Red",
      "rotation": 2
    },
    {
      "x": -1,
      "y": 1,
      "z": -6,
      "name": "Rock_Sandstone_Red",
      "rotation": 2
    },
    {
      "x": -1,
      "y": 2,
      "z": -6,
      "name": "Rock_Sandstone_Red",
      "rotation": 2
    },
    {
      "x": -1,
      "y": 3,
      "z": -6,
      "name": "Rock_Sandstone_Red_Brick_Smooth_Half"
    },
    {
      "x": -1,
      "y": 0,
      "z": -5,
      "name": "Rock_Sandstone_Red",
      "rotation": 2
    },
    {
      "x": -1,
      "y": 1,
      "z": -5,
      "name": "Rock_Sandstone_Red",
      "rotation": 2
    },
    {
      "x": -1,
      "y": 2,
      "z": -5,
      "name": "Rock_Sandstone_Red",
      "rotation": 2
    },
    {
      "x": -1,
      "y": 3,
      "z": -5,
      "name": "Rock_Sandstone_Red_Brick_Smooth"
    },
    {
      "x": -1,
      "y": 4,
      "z": -5,
      "name": "Rock_Sandstone_Red_Brick_Decorative"
    },
    {
      "x": -1,
      "y": 5,
      "z": -5,
      "name": "Rock_Sandstone_Red_Brick_Decorative"
    },
    {
      "x": -1,
      "y": 6,
      "z": -5,
      "name": "Plant_Crop_Mushroom_Glowing_Orange"
    },
    {
      "x": -1,
      "y": 8,
      "z": -5,
      "name": "Plant_Crop_Mushroom_Shelve_Brown"
    },
    {
      "x": -1,
      "y": 0,
      "z": -4,
      "name": "Rock_Sandstone_Red",
      "rotation": 2
    },
    {
      "x": -1,
      "y": 1,
      "z": -4,
      "name": "Rock_Sandstone_Red",
      "rotation": 2
    },
    {
      "x": -1,
      "y": 2,
      "z": -4,
      "name": "Rock_Sandstone_Red",
      "rotation": 2
    },
    {
      "x": -1,
      "y": 3,
      "z": -4,
      "name": "Rock_Sandstone_Red_Brick_Smooth"
    },
    {
      "x": -1,
      "y": 0,
      "z": -3,
      "name": "Rock_Sandstone_Red",
      "rotation": 2
    },
    {
      "x": -1,
      "y": 1,
      "z": -3,
      "name": "Rock_Sandstone_Red",
      "rotation": 2
    },
    {
      "x": -1,
      "y": 2,
      "z": -3,
      "name": "Rock_Sandstone_Red",
      "rotation": 2
    },
    {
      "x": -1,
      "y": 3,
      "z": -3,
      "name": "Rock_Sandstone_Red_Brick_Smooth"
    },
    {
      "x": -1,
      "y": 0,
      "z": -2,
      "name": "Rock_Sandstone_Red",
      "rotation": 2
    },
    {
      "x": -1,
      "y": 1,
      "z": -2,
      "name": "Rock_Sandstone_Red",
      "rotation": 2
    },
    {
      "x": -1,
      "y": 2,
      "z": -2,
      "name": "Rock_Sandstone_Red",
      "rotation": 2
    },
    {
      "x": -1,
      "y": 3,
      "z": -2,
      "name": "Rock_Sandstone_Red_Brick_Smooth"
    },
    {
      "x": -1,
      "y": 0,
      "z": -1,
      "name": "Rock_Sandstone_Red",
      "rotation": 2
    },
    {
      "x": -1,
      "y": 1,
      "z": -1,
      "name": "Rock_Sandstone_Red",
      "rotation": 2
    },
    {
      "x": -1,
      "y": 2,
      "z": -1,
      "name": "Rock_Sandstone_Red",
      "rotation": 2
    },
    {
      "x": -1,
      "y": 3,
      "z": -1,
      "name": "Rock_Sandstone_Red_Brick_Smooth"
    },
    {
      "x": -1,
      "y": 4,
      "z": -1,
      "name": "Rubble_Sandstone_Red_Medium"
    },
    {
      "x": -1,
      "y": 0,
      "z": 0,
      "name": "Rock_Sandstone_Red",
      "rotation": 2
    },
    {
      "x": -1,
      "y": 1,
      "z": 0,
      "name": "Rock_Sandstone_Red",
      "rotation": 2
    },
    {
      "x": -1,
      "y": 2,
      "z": 0,
      "name": "Rock_Sandstone_Red",
      "rotation": 2
    },
    {
      "x": -1,
      "y": 3,
      "z": 0,
      "name": "Rock_Sandstone_Red_Brick_Smooth"
    },
    {
      "x": -1,
      "y": 0,
      "z": 1,
      "name": "Rock_Sandstone_Red",
      "rotation": 2
    },
    {
      "x": -1,
      "y": 1,
      "z": 1,
      "name": "Rock_Sandstone_Red",
      "rotation": 2
    },
    {
      "x": -1,
      "y": 2,
      "z": 1,
      "name": "Rock_Sandstone_Red",
      "rotation": 2
    },
    {
      "x": -1,
      "y": 3,
      "z": 1,
      "name": "Rock_Sandstone_Red_Brick_Smooth"
    },
    {
      "x": -1,
      "y": 4,
      "z": 1,
      "name": "Rubble_Sandstone_Red_Medium"
    },
    {
      "x": -1,
      "y": 0,
      "z": 2,
      "name": "Rock_Sandstone_Red",
      "rotation": 2
    },
    {
      "x": -1,
      "y": 1,
      "z": 2,
      "name": "Rock_Sandstone_Red",
      "rotation": 2
    },
    {
      "x": -1,
      "y": 2,
      "z": 2,
      "name": "Rock_Sandstone_Red",
      "rotation": 2
    },
    {
      "x": -1,
      "y": 3,
      "z": 2,
      "name": "Rock_Sandstone_Red_Brick_Smooth"
    },
    {
      "x": -1,
      "y": 4,
      "z": 2,
      "name": "Rock_Sandstone_Red_Cobble"
    },
    {
      "x": -1,
      "y": 5,
      "z": 2,
      "name": "Rubble_Sandstone_Red_Medium"
    },
    {
      "x": -1,
      "y": 0,
      "z": 3,
      "name": "Rock_Sandstone_Red",
      "rotation": 2
    },
    {
      "x": -1,
      "y": 1,
      "z": 3,
      "name": "Rock_Sandstone_Red",
      "rotation": 2
    },
    {
      "x": -1,
      "y": 2,
      "z": 3,
      "name": "Rock_Sandstone_Red",
      "rotation": 2
    },
    {
      "x": -1,
      "y": 3,
      "z": 3,
      "name": "Rock_Sandstone_Red_Brick_Smooth"
    },
    {
      "x": -1,
      "y": 4,
      "z": 3,
      "name": "Rock_Sandstone_Red_Cobble"
    },
    {
      "x": -1,
      "y": 5,
      "z": 3,
      "name": "Rubble_Sandstone_Red"
    },
    {
      "x": -1,
      "y": 0,
      "z": 4,
      "name": "Rock_Sandstone_Red",
      "rotation": 2
    },
    {
      "x": -1,
      "y": 1,
      "z": 4,
      "name": "Rock_Sandstone_Red",
      "rotation": 2
    },
    {
      "x": -1,
      "y": 2,
      "z": 4,
      "name": "Rock_Sandstone_Red",
      "rotation": 2
    },
    {
      "x": -1,
      "y": 3,
      "z": 4,
      "name": "Rock_Sandstone_Red_Brick_Smooth"
    },
    {
      "x": -1,
      "y": 4,
      "z": 4,
      "name": "Rubble_Sandstone_Red_Medium"
    },
    {
      "x": -1,
      "y": 0,
      "z": 5,
      "name": "Rock_Sandstone_Red",
      "rotation": 2
    },
    {
      "x": -1,
      "y": 1,
      "z": 5,
      "name": "Rock_Sandstone_Red",
      "rotation": 2
    },
    {
      "x": -1,
      "y": 2,
      "z": 5,
      "name": "Rock_Sandstone_Red",
      "rotation": 2
    },
    {
      "x": -1,
      "y": 3,
      "z": 5,
      "name": "Rock_Sandstone_Red_Brick_Smooth"
    },
    {
      "x": -1,
      "y": 4,
      "z": 5,
      "name": "Rubble_Sandstone_Red_Medium"
    },
    {
      "x": -1,
      "y": 0,
      "z": 6,
      "name": "Rock_Sandstone_Red",
      "rotation": 2
    },
    {
      "x": -1,
      "y": 1,
      "z": 6,
      "name": "Rock_Sandstone_Red",
      "rotation": 2
    },
    {
      "x": -1,
      "y": 2,
      "z": 6,
      "name": "Rock_Sandstone_Red",
      "rotation": 2
    },
    {
      "x": -1,
      "y": 3,
      "z": 6,
      "name": "Rock_Sandstone_Red_Brick_Smooth"
    },
    {
      "x": -1,
      "y": 0,
      "z": 7,
      "name": "Rock_Sandstone_Red",
      "rotation": 2
    },
    {
      "x": -1,
      "y": 1,
      "z": 7,
      "name": "Rock_Sandstone_Red",
      "rotation": 2
    },
    {
      "x": -1,
      "y": 2,
      "z": 7,
      "name": "Rock_Sandstone_Red",
      "rotation": 2
    },
    {
      "x": -1,
      "y": 3,
      "z": 7,
      "name": "Rock_Sandstone_Red_Brick_Smooth"
    },
    {
      "x": -1,
      "y": 0,
      "z": 8,
      "name": "Rock_Sandstone_Red",
      "rotation": 2
    },
    {
      "x": -1,
      "y": 1,
      "z": 8,
      "name": "Rock_Sandstone_Red",
      "rotation": 2
    },
    {
      "x": -1,
      "y": 2,
      "z": 8,
      "name": "Rock_Sandstone_Red",
      "rotation": 2
    },
    {
      "x": -1,
      "y": 3,
      "z": 8,
      "name": "Rock_Sandstone_Red_Brick_Smooth"
    },
    {
      "x": -1,
      "y": 4,
      "z": 8,
      "name": "Rock_Sandstone_Red_Brick_Decorative"
    },
    {
      "x": -1,
      "y": 5,
      "z": 8,
      "name": "Rubble_Sandstone_Red_Medium"
    },
    {
      "x": -1,
      "y": 0,
      "z": 9,
      "name": "Rock_Sandstone_Red",
      "rotation": 2
    },
    {
      "x": -1,
      "y": 1,
      "z": 9,
      "name": "Rock_Sandstone_Red",
      "rotation": 2
    },
    {
      "x": -1,
      "y": 2,
      "z": 9,
      "name": "Rock_Sandstone_Red",
      "rotation": 2
    },
    {
      "x": -1,
      "y": 3,
      "z": 9,
      "name": "Rock_Sandstone_Red_Brick_Smooth_Half"
    },
    {
      "x": -1,
      "y": 0,
      "z": 10,
      "name": "Rock_Sandstone_Red",
      "rotation": 1
    },
    {
      "x": -1,
      "y": 1,
      "z": 10,
      "name": "Rock_Sandstone_Red",
      "rotation": 2
    },
    {
      "x": -1,
      "y": 2,
      "z": 10,
      "name": "Rock_Sandstone_Red",
      "rotation": 1
    },
    {
      "x": -1,
      "y": 1,
      "z": 11,
      "name": "Rock_Sandstone_Red",
      "rotation": 1
    },
    {
      "x": 0,
      "y": 0,
      "z": -10,
      "name": "Rock_Sandstone_Red",
      "rotation": 2
    },
    {
      "x": 0,
      "y": 1,
      "z": -10,
      "name": "Rock_Sandstone_Red",
      "rotation": 2
    },
    {
      "x": 0,
      "y": 0,
      "z": -9,
      "name": "Rock_Sandstone_Red",
      "rotation": 2
    },
    {
      "x": 0,
      "y": 1,
      "z": -9,
      "name": "Rock_Sandstone_Red",
      "rotation": 2
    },
    {
      "x": 0,
      "y": 2,
      "z": -9,
      "name": "Rock_Sandstone_Red",
      "rotation": 2
    },
    {
      "x": 0,
      "y": 0,
      "z": -8,
      "name": "Rock_Sandstone_Red",
      "rotation": 2
    },
    {
      "x": 0,
      "y": 1,
      "z": -8,
      "name": "Rock_Sandstone_Red",
      "rotation": 2
    },
    {
      "x": 0,
      "y": 2,
      "z": -8,
      "name": "Rock_Sandstone_Red",
      "rotation": 2
    },
    {
      "x": 0,
      "y": 0,
      "z": -7,
      "name": "Rock_Sandstone_Red",
      "rotation": 2
    },
    {
      "x": 0,
      "y": 1,
      "z": -7,
      "name": "Rock_Sandstone_Red",
      "rotation": 2
    },
    {
      "x": 0,
      "y": 2,
      "z": -7,
      "name": "Rock_Sandstone_Red",
      "rotation": 2
    },
    {
      "x": 0,
      "y": 0,
      "z": -6,
      "name": "Rock_Sandstone_Red",
      "rotation": 2
    },
    {
      "x": 0,
      "y": 1,
      "z": -6,
      "name": "Rock_Sandstone_Red",
      "rotation": 2
    },
    {
      "x": 0,
      "y": 2,
      "z": -6,
      "name": "Rock_Sandstone_Red",
      "rotation": 2
    },
    {
      "x": 0,
      "y": 3,
      "z": -6,
      "name": "Rock_Sandstone_Red_Brick_Smooth_Half"
    },
    {
      "x": 0,
      "y": 0,
      "z": -5,
      "name": "Rock_Sandstone_Red",
      "rotation": 2
    },
    {
      "x": 0,
      "y": 1,
      "z": -5,
      "name": "Rock_Sandstone_Red",
      "rotation": 2
    },
    {
      "x": 0,
      "y": 2,
      "z": -5,
      "name": "Rock_Sandstone_Red",
      "rotation": 2
    },
    {
      "x": 0,
      "y": 3,
      "z": -5,
      "name": "Rock_Sandstone_Red_Brick_Smooth"
    },
    {
      "x": 0,
      "y": 4,
      "z": -5,
      "name": "Rock_Sandstone_Red_Brick_Decorative"
    },
    {
      "x": 0,
      "y": 5,
      "z": -5,
      "name": "Deco_SpiderWeb_Full"
    },
    {
      "x": 0,
      "y": 0,
      "z": -4,
      "name": "Rock_Sandstone_Red",
      "rotation": 2
    },
    {
      "x": 0,
      "y": 1,
      "z": -4,
      "name": "Rock_Sandstone_Red",
      "rotation": 2
    },
    {
      "x": 0,
      "y": 2,
      "z": -4,
      "name": "Rock_Sandstone_Red",
      "rotation": 2
    },
    {
      "x": 0,
      "y": 3,
      "z": -4,
      "name": "Rock_Sandstone_Red_Brick_Smooth"
    },
    {
      "x": 0,
      "y": 0,
      "z": -3,
      "name": "Rock_Sandstone_Red",
      "rotation": 2
    },
    {
      "x": 0,
      "y": 1,
      "z": -3,
      "name": "Rock_Sandstone_Red",
      "rotation": 2
    },
    {
      "x": 0,
      "y": 2,
      "z": -3,
      "name": "Rock_Sandstone_Red",
      "rotation": 2
    },
    {
      "x": 0,
      "y": 3,
      "z": -3,
      "name": "Rock_Sandstone_Red_Brick_Smooth"
    },
    {
      "x": 0,
      "y": 0,
      "z": -2,
      "name": "Rock_Sandstone_Red",
      "rotation": 2
    },
    {
      "x": 0,
      "y": 1,
      "z": -2,
      "name": "Rock_Sandstone_Red",
      "rotation": 2
    },
    {
      "x": 0,
      "y": 2,
      "z": -2,
      "name": "Rock_Sandstone_Red",
      "rotation": 2
    },
    {
      "x": 0,
      "y": 3,
      "z": -2,
      "name": "Rock_Sandstone_Red_Brick_Smooth"
    },
    {
      "x": 0,
      "y": 0,
      "z": -1,
      "name": "Rock_Sandstone_Red",
      "rotation": 2
    },
    {
      "x": 0,
      "y": 1,
      "z": -1,
      "name": "Rock_Sandstone_Red",
      "rotation": 2
    },
    {
      "x": 0,
      "y": 2,
      "z": -1,
      "name": "Rock_Sandstone_Red",
      "rotation": 2
    },
    {
      "x": 0,
      "y": 3,
      "z": -1,
      "name": "Rock_Sandstone_Red_Brick_Smooth"
    },
    {
      "x": 0,
      "y": 0,
      "z": 0,
      "name": "Rock_Sandstone_Red",
      "rotation": 2
    },
    {
      "x": 0,
      "y": 1,
      "z": 0,
      "name": "Rock_Sandstone_Red",
      "rotation": 2
    },
    {
      "x": 0,
      "y": 2,
      "z": 0,
      "name": "Rock_Sandstone_Red",
      "rotation": 2
    },
    {
      "x": 0,
      "y": 3,
      "z": 0,
      "name": "Rock_Sandstone_Red_Brick_Smooth"
    },
    {
      "x": 0,
      "y": 4,
      "z": 0,
      "name": "Rubble_Sandstone_Red_Medium"
    },
    {
      "x": 0,
      "y": 0,
      "z": 1,
      "name": "Rock_Sandstone_Red",
      "rotation": 2
    },
    {
      "x": 0,
      "y": 1,
      "z": 1,
      "name": "Rock_Sandstone_Red",
      "rotation": 2
    },
    {
      "x": 0,
      "y": 2,
      "z": 1,
      "name": "Rock_Sandstone_Red",
      "rotation": 2
    },
    {
      "x": 0,
      "y": 3,
      "z": 1,
      "name": "Rock_Sandstone_Red_Brick_Smooth"
    },
    {
      "x": 0,
      "y": 0,
      "z": 2,
      "name": "Rock_Sandstone_Red",
      "rotation": 2
    },
    {
      "x": 0,
      "y": 1,
      "z": 2,
      "name": "Rock_Sandstone_Red",
      "rotation": 2
    },
    {
      "x": 0,
      "y": 2,
      "z": 2,
      "name": "Rock_Sandstone_Red",
      "rotation": 2
    },
    {
      "x": 0,
      "y": 3,
      "z": 2,
      "name": "Rock_Sandstone_Red_Brick_Smooth"
    },
    {
      "x": 0,
      "y": 4,
      "z": 2,
      "name": "Rubble_Sandstone_Red_Medium"
    },
    {
      "x": 0,
      "y": 0,
      "z": 3,
      "name": "Rock_Sandstone_Red",
      "rotation": 2
    },
    {
      "x": 0,
      "y": 1,
      "z": 3,
      "name": "Rock_Sandstone_Red",
      "rotation": 2
    },
    {
      "x": 0,
      "y": 2,
      "z": 3,
      "name": "Rock_Sandstone_Red",
      "rotation": 2
    },
    {
      "x": 0,
      "y": 3,
      "z": 3,
      "name": "Rock_Sandstone_Red_Brick_Smooth"
    },
    {
      "x": 0,
      "y": 0,
      "z": 4,
      "name": "Rock_Sandstone_Red",
      "rotation": 2
    },
    {
      "x": 0,
      "y": 1,
      "z": 4,
      "name": "Rock_Sandstone_Red",
      "rotation": 2
    },
    {
      "x": 0,
      "y": 2,
      "z": 4,
      "name": "Rock_Sandstone_Red",
      "rotation": 2
    },
    {
      "x": 0,
      "y": 3,
      "z": 4,
      "name": "Rock_Sandstone_Red_Brick_Smooth"
    },
    {
      "x": 0,
      "y": 0,
      "z": 5,
      "name": "Rock_Sandstone_Red",
      "rotation": 2
    },
    {
      "x": 0,
      "y": 1,
      "z": 5,
      "name": "Rock_Sandstone_Red",
      "rotation": 2
    },
    {
      "x": 0,
      "y": 2,
      "z": 5,
      "name": "Rock_Sandstone_Red",
      "rotation": 2
    },
    {
      "x": 0,
      "y": 3,
      "z": 5,
      "name": "Rock_Sandstone_Red_Brick_Smooth"
    },
    {
      "x": 0,
      "y": 5,
      "z": 5,
      "name": "Plant_Crop_Mushroom_Shelve_Brown"
    },
    {
      "x": 0,
      "y": 0,
      "z": 6,
      "name": "Rock_Sandstone_Red",
      "rotation": 2
    },
    {
      "x": 0,
      "y": 1,
      "z": 6,
      "name": "Rock_Sandstone_Red",
      "rotation": 2
    },
    {
      "x": 0,
      "y": 2,
      "z": 6,
      "name": "Rock_Sandstone_Red",
      "rotation": 2
    },
    {
      "x": 0,
      "y": 3,
      "z": 6,
      "name": "Rock_Sandstone_Red_Brick_Smooth"
    },
    {
      "x": 0,
      "y": 0,
      "z": 7,
      "name": "Rock_Sandstone_Red",
      "rotation": 2
    },
    {
      "x": 0,
      "y": 1,
      "z": 7,
      "name": "Rock_Sandstone_Red",
      "rotation": 2
    },
    {
      "x": 0,
      "y": 2,
      "z": 7,
      "name": "Rock_Sandstone_Red",
      "rotation": 2
    },
    {
      "x": 0,
      "y": 3,
      "z": 7,
      "name": "Rock_Sandstone_Red_Brick_Smooth"
    },
    {
      "x": 0,
      "y": 4,
      "z": 7,
      "name": "Deco_SpiderWeb_Full"
    },
    {
      "x": 0,
      "y": 0,
      "z": 8,
      "name": "Rock_Sandstone_Red",
      "rotation": 2
    },
    {
      "x": 0,
      "y": 1,
      "z": 8,
      "name": "Rock_Sandstone_Red",
      "rotation": 2
    },
    {
      "x": 0,
      "y": 2,
      "z": 8,
      "name": "Rock_Sandstone_Red",
      "rotation": 2
    },
    {
      "x": 0,
      "y": 3,
      "z": 8,
      "name": "Rock_Sandstone_Red_Brick_Smooth"
    },
    {
      "x": 0,
      "y": 4,
      "z": 8,
      "name": "Rock_Sandstone_Red_Brick_Decorative"
    },
    {
      "x": 0,
      "y": 5,
      "z": 8,
      "name": "Rock_Sandstone_Red_Brick_Decorative"
    },
    {
      "x": 0,
      "y": 6,
      "z": 8,
      "name": "Plant_Crop_Mushroom_Glowing_Orange"
    },
    {
      "x": 0,
      "y": 0,
      "z": 9,
      "name": "Rock_Sandstone_Red",
      "rotation": 2
    },
    {
      "x": 0,
      "y": 1,
      "z": 9,
      "name": "Rock_Sandstone_Red",
      "rotation": 2
    },
    {
      "x": 0,
      "y": 2,
      "z": 9,
      "name": "Rock_Sandstone_Red",
      "rotation": 2
    },
    {
      "x": 0,
      "y": 3,
      "z": 9,
      "name": "Rock_Sandstone_Red_Brick_Smooth_Half"
    },
    {
      "x": 0,
      "y": 0,
      "z": 10,
      "name": "Rock_Sandstone_Red",
      "rotation": 1
    },
    {
      "x": 0,
      "y": 1,
      "z": 10,
      "name": "Rock_Sandstone_Red",
      "rotation": 2
    },
    {
      "x": 0,
      "y": 2,
      "z": 10,
      "name": "Rock_Sandstone_Red",
      "rotation": 1
    },
    {
      "x": 0,
      "y": 1,
      "z": 11,
      "name": "Rock_Sandstone_Red",
      "rotation": 1
    },
    {
      "x": 1,
      "y": 0,
      "z": -10,
      "name": "Rock_Sandstone_Red",
      "rotation": 2
    },
    {
      "x": 1,
      "y": 1,
      "z": -10,
      "name": "Rock_Sandstone_Red",
      "rotation": 2
    },
    {
      "x": 1,
      "y": 0,
      "z": -9,
      "name": "Rock_Sandstone_Red",
      "rotation": 2
    },
    {
      "x": 1,
      "y": 1,
      "z": -9,
      "name": "Rock_Sandstone_Red",
      "rotation": 2
    },
    {
      "x": 1,
      "y": 2,
      "z": -9,
      "name": "Rock_Sandstone_Red",
      "rotation": 2
    },
    {
      "x": 1,
      "y": 0,
      "z": -8,
      "name": "Rock_Sandstone_Red",
      "rotation": 2
    },
    {
      "x": 1,
      "y": 1,
      "z": -8,
      "name": "Rock_Sandstone_Red",
      "rotation": 2
    },
    {
      "x": 1,
      "y": 2,
      "z": -8,
      "name": "Rock_Sandstone_Red",
      "rotation": 2
    },
    {
      "x": 1,
      "y": 3,
      "z": -8,
      "name": "Plant_Crop_Mushroom_Glowing_Orange"
    },
    {
      "x": 1,
      "y": 0,
      "z": -7,
      "name": "Rock_Sandstone_Red",
      "rotation": 2
    },
    {
      "x": 1,
      "y": 1,
      "z": -7,
      "name": "Rock_Sandstone_Red",
      "rotation": 2
    },
    {
      "x": 1,
      "y": 2,
      "z": -7,
      "name": "Rock_Sandstone_Red",
      "rotation": 2
    },
    {
      "x": 1,
      "y": 0,
      "z": -6,
      "name": "Rock_Sandstone_Red",
      "rotation": 2
    },
    {
      "x": 1,
      "y": 1,
      "z": -6,
      "name": "Rock_Sandstone_Red",
      "rotation": 2
    },
    {
      "x": 1,
      "y": 2,
      "z": -6,
      "name": "Rock_Sandstone_Red",
      "rotation": 2
    },
    {
      "x": 1,
      "y": 3,
      "z": -6,
      "name": "Rock_Sandstone_Red_Brick_Smooth_Half"
    },
    {
      "x": 1,
      "y": 0,
      "z": -5,
      "name": "Rock_Sandstone_Red",
      "rotation": 2
    },
    {
      "x": 1,
      "y": 1,
      "z": -5,
      "name": "Rock_Sandstone_Red",
      "rotation": 2
    },
    {
      "x": 1,
      "y": 2,
      "z": -5,
      "name": "Rock_Sandstone_Red",
      "rotation": 2
    },
    {
      "x": 1,
      "y": 3,
      "z": -5,
      "name": "Rock_Sandstone_Red_Brick_Smooth"
    },
    {
      "x": 1,
      "y": 4,
      "z": -5,
      "name": "Rock_Sandstone_Red_Brick_Decorative"
    },
    {
      "x": 1,
      "y": 5,
      "z": -5,
      "name": "Rock_Sandstone_Red_Brick_Decorative"
    },
    {
      "x": 1,
      "y": 0,
      "z": -4,
      "name": "Rock_Sandstone_Red",
      "rotation": 2
    },
    {
      "x": 1,
      "y": 1,
      "z": -4,
      "name": "Rock_Sandstone_Red",
      "rotation": 2
    },
    {
      "x": 1,
      "y": 2,
      "z": -4,
      "name": "Rock_Sandstone_Red",
      "rotation": 2
    },
    {
      "x": 1,
      "y": 3,
      "z": -4,
      "name": "Rock_Sandstone_Red_Brick_Smooth"
    },
    {
      "x": 1,
      "y": 0,
      "z": -3,
      "name": "Rock_Sandstone_Red",
      "rotation": 2
    },
    {
      "x": 1,
      "y": 1,
      "z": -3,
      "name": "Rock_Sandstone_Red",
      "rotation": 2
    },
    {
      "x": 1,
      "y": 2,
      "z": -3,
      "name": "Rock_Sandstone_Red",
      "rotation": 2
    },
    {
      "x": 1,
      "y": 3,
      "z": -3,
      "name": "Rock_Sandstone_Red_Brick_Smooth"
    },
    {
      "x": 1,
      "y": 4,
      "z": -3,
      "name": "Plant_Crop_Mushroom_Shelve_Brown"
    },
    {
      "x": 1,
      "y": 5,
      "z": -3,
      "name": "Plant_Crop_Mushroom_Shelve_Brown"
    },
    {
      "x": 1,
      "y": 0,
      "z": -2,
      "name": "Rock_Sandstone_Red",
      "rotation": 2
    },
    {
      "x": 1,
      "y": 1,
      "z": -2,
      "name": "Rock_Sandstone_Red",
      "rotation": 2
    },
    {
      "x": 1,
      "y": 2,
      "z": -2,
      "name": "Rock_Sandstone_Red",
      "rotation": 2
    },
    {
      "x": 1,
      "y": 3,
      "z": -2,
      "name": "Rock_Sandstone_Red_Brick_Smooth"
    },
    {
      "x": 1,
      "y": 0,
      "z": -1,
      "name": "Rock_Sandstone_Red",
      "rotation": 2
    },
    {
      "x": 1,
      "y": 1,
      "z": -1,
      "name": "Rock_Sandstone_Red",
      "rotation": 2
    },
    {
      "x": 1,
      "y": 2,
      "z": -1,
      "name": "Rock_Sandstone_Red_Cobble"
    },
    {
      "x": 1,
      "y": 3,
      "z": -1,
      "name": "Rubble_Sandstone_Red_Medium"
    },
    {
      "x": 1,
      "y": 0,
      "z": 0,
      "name": "Rock_Sandstone_Red",
      "rotation": 2
    },
    {
      "x": 1,
      "y": 1,
      "z": 0,
      "name": "Rock_Sandstone_Red",
      "rotation": 2
    },
    {
      "x": 1,
      "y": 2,
      "z": 0,
      "name": "Rock_Sandstone_Red",
      "rotation": 2
    },
    {
      "x": 1,
      "y": 3,
      "z": 0,
      "name": "Rock_Sandstone_Red_Brick_Smooth"
    },
    {
      "x": 1,
      "y": 4,
      "z": 0,
      "name": "Plant_Crop_Mushroom_Glowing_Orange"
    },
    {
      "x": 1,
      "y": 0,
      "z": 1,
      "name": "Rock_Sandstone_Red",
      "rotation": 2
    },
    {
      "x": 1,
      "y": 1,
      "z": 1,
      "name": "Rock_Sandstone_Red",
      "rotation": 2
    },
    {
      "x": 1,
      "y": 2,
      "z": 1,
      "name": "Rock_Sandstone_Red_Cobble"
    },
    {
      "x": 1,
      "y": 3,
      "z": 1,
      "name": "Rubble_Sandstone_Red"
    },
    {
      "x": 1,
      "y": 0,
      "z": 2,
      "name": "Rock_Sandstone_Red",
      "rotation": 2
    },
    {
      "x": 1,
      "y": 1,
      "z": 2,
      "name": "Rock_Sandstone_Red",
      "rotation": 2
    },
    {
      "x": 1,
      "y": 2,
      "z": 2,
      "name": "Rock_Sandstone_Red",
      "rotation": 2
    },
    {
      "x": 1,
      "y": 3,
      "z": 2,
      "name": "Rock_Sandstone_Red_Brick_Smooth"
    },
    {
      "x": 1,
      "y": 0,
      "z": 3,
      "name": "Rock_Sandstone_Red",
      "rotation": 2
    },
    {
      "x": 1,
      "y": 1,
      "z": 3,
      "name": "Rock_Sandstone_Red",
      "rotation": 2
    },
    {
      "x": 1,
      "y": 2,
      "z": 3,
      "name": "Rock_Sandstone_Red",
      "rotation": 2
    },
    {
      "x": 1,
      "y": 3,
      "z": 3,
      "name": "Rock_Sandstone_Red_Brick_Smooth"
    },
    {
      "x": 1,
      "y": 0,
      "z": 4,
      "name": "Rock_Sandstone_Red",
      "rotation": 2
    },
    {
      "x": 1,
      "y": 1,
      "z": 4,
      "name": "Rock_Sandstone_Red",
      "rotation": 2
    },
    {
      "x": 1,
      "y": 2,
      "z": 4,
      "name": "Rock_Sandstone_Red",
      "rotation": 2
    },
    {
      "x": 1,
      "y": 3,
      "z": 4,
      "name": "Rock_Sandstone_Red_Brick_Ornate"
    },
    {
      "x": 1,
      "y": 4,
      "z": 4,
      "name": "Rock_Sandstone_Red_Brick_Ornate"
    },
    {
      "x": 1,
      "y": 5,
      "z": 4,
      "name": "Rock_Sandstone_Red_Brick_Ornate"
    },
    {
      "x": 1,
      "y": 6,
      "z": 4,
      "name": "Plant_Crop_Mushroom_Shelve_Brown"
    },
    {
      "x": 1,
      "y": 0,
      "z": 5,
      "name": "Rock_Sandstone_Red",
      "rotation": 2
    },
    {
      "x": 1,
      "y": 1,
      "z": 5,
      "name": "Rock_Sandstone_Red",
      "rotation": 2
    },
    {
      "x": 1,
      "y": 2,
      "z": 5,
      "name": "Rock_Sandstone_Red",
      "rotation": 2
    },
    {
      "x": 1,
      "y": 3,
      "z": 5,
      "name": "Rock_Sandstone_Red_Brick_Smooth"
    },
    {
      "x": 1,
      "y": 4,
      "z": 5,
      "name": "Rock_Sandstone_Red_Brick_Decorative"
    },
    {
      "x": 1,
      "y": 5,
      "z": 5,
      "name": "Rock_Sandstone_Red_Brick_Decorative"
    },
    {
      "x": 1,
      "y": 0,
      "z": 6,
      "name": "Rock_Sandstone_Red",
      "rotation": 2
    },
    {
      "x": 1,
      "y": 1,
      "z": 6,
      "name": "Rock_Sandstone_Red",
      "rotation": 2
    },
    {
      "x": 1,
      "y": 2,
      "z": 6,
      "name": "Rock_Sandstone_Red",
      "rotation": 2
    },
    {
      "x": 1,
      "y": 3,
      "z": 6,
      "name": "Rock_Sandstone_Red_Brick_Smooth"
    },
    {
      "x": 1,
      "y": 4,
      "z": 6,
      "name": "Rock_Sandstone_Red_Brick_Decorative"
    },
    {
      "x": 1,
      "y": 0,
      "z": 7,
      "name": "Rock_Sandstone_Red",
      "rotation": 2
    },
    {
      "x": 1,
      "y": 1,
      "z": 7,
      "name": "Rock_Sandstone_Red",
      "rotation": 2
    },
    {
      "x": 1,
      "y": 2,
      "z": 7,
      "name": "Rock_Sandstone_Red",
      "rotation": 2
    },
    {
      "x": 1,
      "y": 3,
      "z": 7,
      "name": "Rock_Sandstone_Red_Brick_Smooth"
    },
    {
      "x": 1,
      "y": 4,
      "z": 7,
      "name": "Rock_Sandstone_Red_Brick_Decorative"
    },
    {
      "x": 1,
      "y": 5,
      "z": 7,
      "name": "Rock_Sandstone_Red_Brick_Decorative"
    },
    {
      "x": 1,
      "y": 0,
      "z": 8,
      "name": "Rock_Sandstone_Red",
      "rotation": 2
    },
    {
      "x": 1,
      "y": 1,
      "z": 8,
      "name": "Rock_Sandstone_Red",
      "rotation": 2
    },
    {
      "x": 1,
      "y": 2,
      "z": 8,
      "name": "Rock_Sandstone_Red",
      "rotation": 2
    },
    {
      "x": 1,
      "y": 3,
      "z": 8,
      "name": "Rock_Sandstone_Red_Brick_Ornate"
    },
    {
      "x": 1,
      "y": 4,
      "z": 8,
      "name": "Rock_Sandstone_Red_Brick_Ornate"
    },
    {
      "x": 1,
      "y": 5,
      "z": 8,
      "name": "Rock_Sandstone_Red_Brick_Ornate"
    },
    {
      "x": 1,
      "y": 6,
      "z": 8,
      "name": "Rubble_Sandstone_Red_Medium"
    },
    {
      "x": 1,
      "y": 0,
      "z": 9,
      "name": "Rock_Sandstone_Red",
      "rotation": 2
    },
    {
      "x": 1,
      "y": 1,
      "z": 9,
      "name": "Rock_Sandstone_Red",
      "rotation": 2
    },
    {
      "x": 1,
      "y": 2,
      "z": 9,
      "name": "Rock_Sandstone_Red",
      "rotation": 2
    },
    {
      "x": 1,
      "y": 3,
      "z": 9,
      "name": "Rock_Sandstone_Red_Brick_Smooth_Half"
    },
    {
      "x": 1,
      "y": 0,
      "z": 10,
